# Ancient Warfare Structure Template File
# Auto-generated structure template file. created on: 12/25/2018 at: 22:43:4
# Lines beginning with # denote comments

header:
version=2.8
name=BrigandLairStoneCircleDungeon
mods=
size=27,15,27
offset=16,9,26
:endheader

#### VALIDATION ####
validation:
type=ground
survival=false
worldGenEnabled=true
unique=false
preserveBlocks=false
selectionWeight=30
clusterValue=60
minDuplicateDistance=900
dimensionWhiteList=true
dimensionList=0
biomeWhiteList=true
biomeList=biomesoplenty:meadow,biomesoplenty:shrubland,biomesoplenty:woodland,biomesoplenty:dead_forest,traverse:woodlands,minecraft:forest,traverse:badlands,traverse:thicket,traverse:meadow,biomesoplenty:lavender_fields,biomesoplenty:pasture,traverse:rocky_plains,minecraft:birch_forest,biomesoplenty:steppe,minecraft:plains,biomesoplenty:orchard
leveling=6
fill=6
border=6
blockSwap=true
:endvalidation

#### LAYERS ####
layer: 0
1,1,1,1,1,1,1,1,1,1,1,1,1,1,1,1,1,1,1,1,1,1,1,1,1,1,1
1,1,1,1,1,1,1,1,1,1,1,1,1,1,1,1,1,1,1,1,1,1,1,1,1,1,1
1,1,1,2,2,2,2,2,2,2,2,2,2,2,2,2,2,2,2,2,2,2,2,2,1,1,1
1,1,1,2,2,2,2,2,2,2,2,2,2,2,2,2,2,2,2,2,2,2,2,2,1,1,1
1,1,1,2,2,2,2,2,2,2,2,2,2,2,2,2,2,2,2,2,2,2,2,2,1,1,1
1,1,1,2,2,2,2,2,2,2,2,2,2,2,2,2,2,2,2,2,2,2,2,2,1,1,1
1,1,1,2,2,2,2,2,2,2,2,2,2,2,2,2,2,2,2,2,2,2,2,2,1,1,1
1,1,1,2,2,2,2,2,2,2,2,2,2,2,2,2,2,2,2,2,2,2,2,2,1,1,1
1,1,1,2,2,2,2,2,2,2,2,2,2,2,2,2,2,2,2,2,2,2,2,2,1,1,1
1,1,1,2,2,2,2,2,2,2,2,2,2,2,2,2,2,2,2,2,2,2,2,2,1,1,1
1,1,1,2,2,2,2,2,6,2,2,2,2,2,2,2,2,2,2,2,2,2,2,2,1,1,1
1,1,1,2,2,2,2,2,2,2,2,2,2,2,2,2,2,2,2,2,2,2,2,2,1,1,1
1,1,1,2,2,2,2,2,2,2,2,2,2,2,2,2,2,2,2,2,2,2,2,2,1,1,1
1,1,1,2,2,2,2,2,2,2,2,2,2,5,2,2,2,2,2,2,2,2,2,2,1,1,1
1,1,1,2,2,2,2,2,2,2,2,2,2,2,2,2,2,2,2,2,2,2,2,2,1,1,1
1,1,1,2,2,2,2,2,2,2,2,2,2,2,2,2,2,2,2,2,3,2,2,2,1,1,1
1,1,1,2,2,2,2,2,2,2,2,2,2,2,2,2,2,2,2,2,2,2,2,2,1,1,1
1,1,1,2,2,2,2,2,2,2,2,2,2,2,2,2,2,2,2,2,2,2,2,2,1,1,1
1,1,1,2,2,2,2,2,2,2,2,2,2,2,2,2,2,2,2,2,2,2,2,2,1,1,1
1,1,1,2,2,2,2,2,2,2,2,2,2,4,4,2,2,2,2,2,2,2,2,2,1,1,1
1,1,1,2,2,2,2,2,2,2,2,2,2,4,2,2,2,2,2,2,2,2,2,1,1,1,1
1,1,1,2,2,2,2,2,2,2,2,2,2,2,2,2,2,2,2,2,2,2,2,1,1,1,1
1,1,1,2,2,2,2,2,2,2,2,2,2,2,2,2,2,2,2,2,2,2,2,2,1,1,1
1,1,1,2,2,2,2,2,2,2,2,2,2,2,2,2,2,2,2,2,2,2,2,2,1,1,1
1,1,1,1,1,1,1,1,1,1,1,1,1,1,1,1,1,1,1,1,1,1,1,1,1,1,1
1,1,1,1,1,1,1,1,1,1,1,1,1,1,1,1,1,1,1,1,1,1,1,1,1,1,1
1,1,1,1,1,1,1,1,1,1,1,1,1,1,1,1,1,1,1,1,1,1,1,1,1,1,1
:endlayer
layer: 1
1,1,1,1,1,1,1,1,1,1,1,1,1,1,1,1,1,1,1,1,1,1,1,1,1,1,1
1,1,1,1,1,1,1,1,1,1,1,1,1,1,1,1,1,1,1,1,1,1,1,1,1,1,1
1,1,1,2,2,2,2,2,2,2,0,0,0,0,0,0,0,0,0,0,0,0,0,2,1,1,1
1,1,1,2,2,2,2,2,2,2,2,2,2,2,2,2,2,2,2,2,2,0,0,2,1,1,1
1,1,1,2,2,2,2,2,2,2,2,2,2,2,2,2,2,2,2,2,2,0,0,2,1,1,1
1,1,1,2,2,2,2,2,2,2,2,2,2,2,2,2,2,2,2,2,2,0,0,2,1,1,1
1,1,1,2,2,2,2,2,2,2,2,2,2,2,2,2,2,2,2,2,2,0,0,7,1,1,1
1,1,1,2,2,2,2,2,2,2,2,2,2,2,2,2,2,2,2,2,2,0,0,2,1,1,1
1,1,1,2,2,2,2,2,2,2,2,2,2,2,2,2,2,2,2,2,2,0,0,2,1,1,1
1,1,1,2,2,2,2,2,2,2,0,2,2,2,2,2,2,2,2,2,2,0,0,2,1,1,1
1,1,1,2,2,2,16,0,0,2,0,0,0,0,2,2,2,2,2,0,0,0,0,2,1,1,1
1,1,1,2,2,2,15,15,0,2,0,0,0,0,0,2,2,2,2,2,2,7,7,2,1,1,1
1,1,1,2,2,2,17,0,14,2,0,0,0,0,0,2,2,2,2,0,0,10,9,8,1,1,1
1,1,1,2,2,2,15,15,0,2,0,0,0,0,0,0,2,2,2,2,2,0,0,8,1,1,1
1,1,1,2,2,2,18,0,0,11,2,0,0,0,0,0,2,2,2,2,2,2,2,2,1,1,1
1,1,1,2,2,2,15,15,0,2,2,2,0,0,0,0,2,2,2,2,11,2,2,2,1,1,1
1,1,1,2,2,2,19,0,0,2,2,2,2,0,0,2,2,2,2,2,3,2,2,2,1,1,1
1,1,1,2,2,2,15,15,0,13,2,2,2,0,0,2,2,12,2,2,2,2,2,2,1,1,1
1,1,1,2,2,2,0,0,0,13,2,2,2,2,2,2,2,12,2,2,2,2,2,2,1,1,1
1,1,1,2,2,2,2,2,2,2,2,2,2,2,4,2,2,2,2,2,2,2,2,2,1,1,1
1,1,1,2,2,2,2,2,2,2,2,2,2,2,2,2,2,2,2,2,2,2,2,2,1,1,1
1,1,1,2,2,2,2,2,2,2,2,2,2,2,2,2,2,2,2,2,2,2,2,2,1,1,1
1,1,1,2,2,2,2,2,2,2,2,2,2,2,2,2,2,2,2,2,2,2,2,2,1,1,1
1,1,1,2,2,2,2,2,2,2,2,2,2,2,2,2,2,2,2,2,2,2,2,2,1,1,1
1,1,1,1,1,1,1,1,1,1,1,1,1,1,1,1,1,1,1,1,1,1,1,1,1,1,1
1,1,1,1,1,1,1,1,1,1,1,1,1,1,1,1,1,1,1,1,1,1,1,1,1,1,1
1,1,1,1,1,1,1,1,1,1,1,1,1,1,1,1,1,1,1,1,1,1,1,1,1,1,1
:endlayer
layer: 2
1,1,1,1,1,1,1,1,1,1,1,1,1,1,1,1,1,1,1,1,1,1,1,1,1,1,1
1,1,1,1,1,1,1,1,1,1,1,1,1,1,1,1,1,1,1,1,1,1,1,1,1,1,1
1,1,1,2,2,2,2,2,2,0,0,0,0,0,0,0,0,0,0,0,0,0,0,2,1,1,1
1,1,1,2,2,2,2,2,2,0,2,2,2,0,2,0,2,2,0,2,2,0,0,2,1,1,1
1,1,1,2,2,2,2,2,2,0,0,0,0,0,0,0,0,0,0,0,0,0,0,2,1,1,1
1,1,1,2,2,2,2,2,2,0,2,2,2,0,2,0,2,2,0,2,2,0,0,2,1,1,1
1,1,1,2,2,2,2,2,2,0,0,0,0,0,0,0,0,0,0,0,0,0,0,2,1,1,1
1,1,1,2,31,2,2,0,2,0,2,2,2,0,2,0,2,2,0,2,2,0,0,2,1,1,1
1,1,1,0,0,0,0,0,0,0,0,0,0,0,0,0,0,0,0,0,0,0,0,2,1,1,1
1,1,1,2,0,2,2,2,2,0,2,2,2,0,2,0,2,2,0,2,2,0,0,2,1,1,1
1,1,1,2,2,2,0,0,0,2,0,0,2,0,2,0,2,2,2,2,2,0,0,2,1,1,1
1,1,1,2,2,2,0,0,0,2,0,0,0,0,0,2,2,2,2,2,2,7,7,2,1,1,1
1,1,1,2,2,2,0,0,0,2,2,0,0,0,0,2,2,2,2,2,2,0,0,20,1,1,1
1,1,1,2,2,2,0,0,0,30,2,0,0,0,0,0,2,2,2,2,2,0,0,0,1,1,1
1,1,1,2,2,2,0,0,0,0,2,0,0,0,0,0,2,28,0,0,0,0,0,8,1,1,1
1,1,1,2,2,2,0,0,0,2,2,0,0,0,0,0,2,28,8,24,25,24,0,8,1,1,1
1,1,1,2,2,2,0,0,0,12,12,12,0,0,0,2,12,12,0,26,0,0,0,21,1,1,1
1,1,1,2,2,2,0,0,0,0,13,2,2,0,0,2,29,0,0,0,0,0,0,22,1,1,1
1,1,1,2,2,2,0,0,0,0,13,2,2,0,0,2,29,0,0,27,8,8,0,8,1,1,1
1,1,1,2,2,2,2,2,2,12,12,2,2,2,2,2,12,12,2,2,2,2,23,8,1,1,1
1,1,1,2,2,2,2,2,2,2,2,2,2,2,2,2,2,2,2,2,2,2,2,2,1,1,1
1,1,1,2,2,2,2,2,2,2,2,2,2,2,2,2,2,2,2,2,2,2,2,2,1,1,1
1,1,1,2,2,2,2,2,2,2,2,2,2,2,2,2,2,2,2,2,2,2,2,2,1,1,1
1,1,1,2,2,2,2,2,2,2,2,2,2,2,2,2,2,2,2,2,2,2,2,2,1,1,1
1,1,1,1,1,1,1,1,1,1,1,1,1,1,1,1,1,1,1,1,1,1,1,1,1,1,1
1,1,1,1,1,1,1,1,1,1,1,1,1,1,1,1,1,1,1,1,1,1,1,1,1,1,1
1,1,1,1,1,1,1,1,1,1,1,1,1,1,1,1,1,1,1,1,1,1,1,1,1,1,1
:endlayer
layer: 3
1,1,1,1,1,1,1,1,1,1,1,1,1,1,1,1,1,1,1,1,1,1,1,1,1,1,1
1,1,1,1,1,1,1,1,1,1,1,1,1,1,1,1,1,1,1,1,1,1,1,1,1,1,1
1,1,1,2,34,34,2,2,2,0,0,0,0,0,0,0,0,0,0,0,0,0,0,2,1,1,1
1,1,1,2,34,2,2,2,2,0,2,2,2,2,2,2,2,2,2,2,2,0,0,2,1,1,1
1,1,1,2,2,2,2,2,2,0,0,0,0,0,0,0,0,0,0,0,0,0,0,2,1,1,1
1,1,1,2,2,2,2,2,2,0,2,2,2,2,2,2,2,2,2,2,2,0,0,2,1,1,1
1,1,1,2,2,2,2,2,2,0,0,0,0,0,0,0,0,0,0,0,0,0,0,2,1,1,1
1,1,1,2,0,2,2,2,2,0,2,2,2,2,2,2,2,2,2,2,2,0,0,2,1,1,1
1,1,1,0,0,0,0,0,0,0,0,0,0,0,0,0,0,0,0,0,0,0,0,2,1,1,1
1,1,1,2,2,2,2,2,2,0,2,2,2,2,2,2,2,2,2,2,2,0,0,2,1,1,1
1,1,1,2,2,2,33,0,32,2,2,2,2,2,2,2,2,2,2,2,2,0,0,2,1,1,1
1,1,1,2,2,2,0,0,0,2,2,0,0,0,0,2,2,2,0,2,2,0,7,2,1,1,1
1,1,1,2,2,2,0,0,0,2,2,0,0,0,0,2,2,2,0,1,2,0,0,0,1,1,1
1,1,1,2,2,2,0,0,0,0,2,0,0,0,0,2,2,2,2,2,2,0,0,0,1,1,1
1,1,1,2,2,2,0,0,0,0,2,0,0,0,0,2,2,28,0,0,0,0,0,0,1,1,1
1,1,1,2,2,2,0,0,0,2,2,0,0,0,0,0,2,28,0,0,0,0,0,0,1,1,1
1,1,1,2,2,2,33,0,0,12,12,12,0,0,0,12,12,12,0,0,0,0,0,0,1,1,1
1,1,1,2,2,2,0,0,0,0,0,13,2,0,0,29,0,0,0,0,0,0,0,0,1,1,1
1,1,1,2,2,2,0,0,0,0,0,13,2,0,0,29,0,0,0,0,0,0,0,0,1,1,1
1,1,1,2,2,2,2,2,2,12,12,12,2,2,2,12,12,12,2,2,2,2,0,0,1,1,1
1,1,1,2,2,2,2,2,2,2,2,2,2,2,2,2,2,2,2,2,2,2,2,2,1,1,1
1,1,1,2,2,2,2,2,2,2,2,2,2,2,2,2,2,2,2,2,2,2,2,2,1,1,1
1,1,1,2,2,2,2,2,2,2,2,2,2,2,2,2,2,2,2,2,2,2,2,2,1,1,1
1,1,1,2,2,2,2,2,2,2,2,2,2,2,2,2,2,2,2,2,2,2,2,2,1,1,1
1,1,1,1,1,1,1,1,1,1,1,1,1,1,1,1,1,1,1,1,1,1,1,1,1,1,1
1,1,1,1,1,1,1,1,1,1,1,1,1,1,1,1,1,1,1,1,1,1,1,1,1,1,1
1,1,1,1,1,1,1,1,1,1,1,1,1,1,1,1,1,1,1,1,1,1,1,1,1,1,1
:endlayer
layer: 4
1,1,1,1,1,1,1,1,1,1,1,1,1,1,1,1,1,1,1,1,1,1,1,1,1,1,1
1,1,1,1,1,1,1,1,1,1,1,1,1,1,1,1,1,1,1,1,1,1,1,1,1,1,1
1,1,1,34,34,34,2,2,2,0,0,0,0,0,0,0,0,0,0,0,0,0,0,2,1,1,1
1,1,1,34,34,2,2,2,2,0,2,2,2,2,2,2,2,2,2,2,2,0,0,2,1,1,1
1,1,1,34,2,2,2,2,2,0,0,0,0,0,0,0,0,0,0,0,0,0,0,2,1,1,1
1,1,1,2,2,2,2,2,2,0,2,2,2,2,2,2,2,2,2,2,2,0,0,2,1,1,1
1,1,1,2,2,2,2,2,2,0,0,0,0,0,0,0,0,0,0,0,0,0,0,2,1,1,1
1,1,1,2,0,2,2,2,2,0,2,2,2,2,2,2,2,2,2,2,2,0,0,2,1,1,1
1,1,1,2,2,2,2,2,2,0,2,2,2,2,2,2,0,0,0,0,0,0,0,2,1,1,1
1,1,1,2,2,2,2,2,2,0,2,2,2,2,2,2,2,2,2,2,2,0,0,2,1,1,1
1,1,1,2,2,2,2,2,2,12,34,2,2,2,2,2,2,2,2,2,2,0,0,2,1,1,1
1,1,1,2,2,2,2,2,2,34,34,2,2,2,2,2,2,2,2,1,2,7,0,2,1,1,1
1,1,1,2,2,2,2,2,2,34,2,2,2,2,2,2,2,2,2,1,2,0,0,0,1,1,1
1,1,1,2,2,2,2,2,2,2,2,2,0,0,2,2,2,2,2,2,2,0,0,0,1,1,1
1,1,1,2,2,2,2,2,2,2,2,2,0,0,2,2,2,28,0,0,36,0,0,0,1,1,1
1,1,1,2,2,2,2,2,2,2,2,2,0,0,2,2,2,2,0,0,0,0,0,0,1,1,1
1,1,1,2,2,2,2,2,2,12,12,12,12,12,12,12,12,12,0,0,0,0,0,0,1,1,1
1,1,1,2,2,2,2,2,2,0,0,0,13,12,29,0,0,0,0,0,0,0,0,0,1,1,1
1,1,1,2,2,2,2,2,2,0,0,0,13,12,29,0,0,0,0,0,0,0,0,35,1,1,1
1,1,1,2,2,2,2,2,2,12,12,12,12,2,12,12,12,12,2,2,2,2,2,2,1,1,1
1,1,1,2,2,2,2,2,2,2,2,2,2,2,2,2,2,2,2,2,2,2,2,2,1,1,1
1,1,1,2,2,2,2,2,2,2,2,2,2,2,2,2,2,2,2,2,2,2,2,2,1,1,1
1,1,1,2,2,2,2,2,2,2,2,2,2,2,2,2,2,2,2,2,2,2,2,2,1,1,1
1,1,1,2,2,2,2,2,2,2,2,2,2,2,2,2,2,2,2,2,2,2,2,2,1,1,1
1,1,1,1,1,1,1,1,1,1,1,1,1,1,1,1,1,1,1,1,1,1,1,1,1,1,1
1,1,1,1,1,1,1,1,1,1,1,1,1,1,1,1,1,1,1,1,1,1,1,1,1,1,1
1,1,1,1,1,1,1,1,1,1,1,1,1,1,1,1,1,1,1,1,1,1,1,1,1,1,1
:endlayer
layer: 5
1,1,1,1,1,1,1,1,1,1,1,1,1,1,1,1,1,1,1,1,1,1,1,1,1,1,1
1,1,1,1,1,1,1,1,1,1,1,1,1,1,1,1,1,1,1,1,1,1,1,1,1,1,1
1,1,1,1,1,1,1,1,1,1,1,1,1,1,1,1,1,1,1,1,2,2,2,1,1,1,1
1,1,1,1,1,1,1,1,1,1,1,1,1,1,1,1,1,1,1,1,1,2,2,1,1,1,1
1,1,1,1,1,1,1,1,1,1,1,1,1,1,1,1,1,1,1,1,2,2,2,1,1,1,1
1,1,1,1,1,1,1,1,1,1,1,1,1,1,1,1,1,1,2,2,1,2,2,1,1,1,1
1,1,1,1,1,1,1,1,1,1,1,1,1,1,1,1,1,1,1,2,2,2,2,1,1,1,1
1,1,1,1,1,1,1,1,1,1,1,1,1,1,1,1,1,1,2,2,2,2,2,1,1,1,1
1,1,1,1,1,1,1,1,1,1,1,1,1,1,1,1,1,1,2,2,2,2,2,1,1,1,1
1,1,1,1,1,1,1,1,12,1,1,1,1,1,1,1,1,1,12,2,2,2,2,1,1,1,1
1,1,1,1,1,1,1,1,5,12,1,1,1,1,1,1,1,12,5,2,1,2,2,1,1,1,1
1,1,1,1,1,1,1,12,5,5,12,1,1,1,1,1,12,5,5,12,1,2,2,2,1,1,1
1,1,1,1,1,1,1,1,5,5,5,12,1,1,1,12,5,5,5,1,1,2,2,2,1,1,1
1,1,1,1,1,1,1,12,5,5,5,5,2,2,2,5,5,5,5,12,1,2,2,2,1,1,1
1,1,1,1,1,1,1,1,1,5,5,1,2,2,1,1,5,5,2,2,2,2,2,2,1,1,1
1,1,1,1,1,1,1,12,0,1,1,12,37,37,37,12,1,1,2,2,2,2,2,2,1,1,1
1,1,1,1,1,1,1,1,1,1,12,12,0,0,0,12,12,12,2,2,2,2,2,2,1,1,1
1,1,1,1,1,1,1,1,1,12,0,0,0,0,0,0,0,0,12,2,2,2,2,2,1,1,1
1,1,1,1,1,1,1,1,1,12,0,0,0,0,0,0,0,0,12,2,2,2,2,2,1,1,1
1,1,1,1,1,1,1,1,1,1,12,12,12,12,12,12,12,12,2,2,2,2,2,2,1,1,1
1,1,1,1,1,1,1,1,1,1,1,1,1,1,1,1,1,1,2,2,2,2,2,2,1,1,1
1,1,1,1,1,1,1,1,1,1,1,1,1,1,1,1,1,1,2,2,2,2,2,2,1,1,1
1,1,1,1,1,1,1,1,1,1,1,1,1,1,1,1,1,1,2,2,2,2,2,2,1,1,1
1,1,1,1,1,1,1,1,1,1,1,1,1,1,1,1,1,1,2,2,2,2,2,2,1,1,1
1,1,1,1,1,1,1,1,1,1,1,1,1,1,1,1,1,1,1,1,1,1,1,1,1,1,1
1,1,1,1,1,1,1,1,1,1,1,1,1,1,1,1,1,1,1,1,1,1,1,1,1,1,1
1,1,1,1,1,1,1,1,1,1,1,1,1,1,1,1,1,1,1,1,1,1,1,1,1,1,1
:endlayer
layer: 6
1,1,1,1,1,1,1,1,1,1,1,1,1,1,1,1,1,1,1,1,1,1,1,1,1,1,1
1,1,1,1,1,1,1,1,1,1,1,1,1,1,1,1,1,1,1,1,1,1,1,1,1,1,1
1,1,1,1,1,1,1,1,1,1,1,1,1,1,1,1,1,1,1,1,1,1,1,1,1,1,1
1,1,1,1,1,1,1,1,1,1,1,1,1,1,1,1,1,1,1,1,1,1,1,1,1,1,1
1,1,1,1,1,1,1,1,1,1,1,1,1,1,1,1,1,1,1,1,1,1,1,1,1,1,1
1,1,1,1,1,1,1,1,1,1,1,1,1,1,1,1,1,1,1,1,1,1,1,1,1,1,1
1,1,1,1,1,1,1,1,1,1,1,1,1,1,1,1,1,1,1,1,1,1,1,1,1,1,1
1,1,1,1,1,1,1,1,1,1,1,1,1,1,1,1,1,1,1,1,1,1,1,1,1,1,1
1,1,1,1,1,1,1,1,1,1,1,1,1,1,1,1,1,1,1,1,1,1,1,1,1,1,1
1,1,1,1,1,1,1,1,12,1,1,1,1,1,1,1,1,1,12,1,1,1,1,1,1,1,1
1,1,1,1,1,1,1,1,0,12,1,1,1,1,1,1,1,12,0,1,1,1,1,1,1,1,1
1,1,1,1,1,1,1,12,0,0,12,1,1,1,1,0,12,0,0,12,1,1,1,1,1,1,1
1,1,1,1,1,1,1,1,0,0,0,12,1,1,1,12,0,0,0,1,1,1,1,1,1,1,1
1,1,1,1,1,1,1,12,0,0,0,0,12,12,12,0,0,0,0,12,1,1,1,1,1,1,1
1,1,1,1,1,1,1,1,38,0,0,38,37,37,37,38,0,0,38,1,1,1,1,1,1,1,1
1,1,1,1,1,1,1,12,38,38,38,38,0,0,0,38,38,38,38,12,1,1,1,1,1,1,1
1,1,1,1,1,1,1,1,38,38,38,38,0,0,0,38,38,38,1,1,1,1,1,1,1,1,1
1,1,1,1,1,1,1,1,1,38,38,0,0,0,0,0,38,1,1,1,1,1,1,1,1,1,1
1,1,1,1,1,1,1,1,1,1,12,0,0,0,0,0,12,1,1,1,1,1,1,1,1,1,1
1,1,1,1,1,1,1,1,1,1,1,1,12,1,12,1,1,1,1,1,1,1,1,1,1,1,1
1,1,1,1,1,1,1,1,1,1,1,1,1,1,1,1,1,1,1,1,1,1,1,1,1,1,1
1,1,1,1,1,1,1,1,1,1,1,1,1,1,1,1,1,1,1,1,1,1,1,1,1,1,1
1,1,1,1,1,1,1,1,1,1,1,1,1,1,1,1,1,1,1,1,1,1,1,1,1,1,1
1,1,1,1,1,1,1,1,1,1,1,1,1,1,1,1,1,1,1,1,1,1,1,1,1,1,1
1,1,1,1,1,1,1,1,1,1,1,1,1,1,1,1,1,1,1,1,1,1,1,1,1,1,1
1,1,1,1,1,1,1,1,1,1,1,1,1,1,1,1,1,1,1,1,1,1,1,1,1,1,1
1,1,1,1,1,1,1,1,1,1,1,1,1,1,1,1,1,1,1,1,1,1,1,1,1,1,1
:endlayer
layer: 7
1,1,1,1,1,1,1,1,1,1,1,1,1,1,1,1,1,1,1,1,1,1,1,1,1,1,1
1,1,1,1,1,1,1,1,1,1,1,1,1,1,1,1,1,1,1,1,1,1,1,1,1,1,1
1,1,1,1,1,1,1,1,1,1,1,1,1,1,1,1,1,1,1,1,1,1,1,1,1,1,1
1,1,1,1,1,1,1,1,1,1,1,1,1,1,1,1,1,1,1,1,1,1,1,1,1,1,1
1,1,1,1,1,1,1,1,1,1,1,1,1,1,1,1,1,1,1,1,1,1,1,1,1,1,1
1,1,1,1,1,1,1,1,1,1,1,1,1,1,1,1,1,1,1,1,1,1,1,1,1,1,1
1,1,1,1,1,1,1,1,1,1,1,1,1,1,1,1,1,1,1,1,1,1,1,1,1,1,1
1,1,1,1,1,1,1,1,1,1,1,1,1,1,1,1,1,1,1,1,1,1,1,1,1,1,1
1,1,1,1,1,1,1,1,1,1,1,38,1,1,1,38,1,1,1,1,1,1,1,1,1,1,1
1,1,1,1,1,1,1,38,12,1,38,38,40,40,40,38,38,1,12,1,1,1,1,1,1,1,1
1,1,1,1,1,1,1,38,0,12,38,38,40,40,40,38,38,12,0,1,1,1,1,1,1,1,1
1,1,1,1,1,1,1,12,0,0,12,38,12,12,12,38,12,0,0,12,1,1,1,1,1,1,1
1,1,1,1,1,1,1,1,0,0,0,12,41,41,41,12,0,0,0,1,1,1,1,1,1,1,1
1,1,1,1,1,1,1,12,0,0,0,0,0,0,0,0,0,0,0,12,1,1,1,1,1,1,1
1,1,1,1,1,1,1,1,0,0,0,39,0,0,0,39,0,0,0,1,1,1,1,1,1,1,1
1,1,1,1,1,1,1,12,0,0,39,39,0,0,0,39,39,0,0,12,1,1,1,1,1,1,1
1,1,1,1,1,1,1,1,39,39,39,0,0,0,0,0,39,0,1,1,1,1,1,1,1,1,1
1,1,1,1,1,1,1,1,12,39,39,0,0,0,0,0,0,1,1,1,1,1,1,1,1,1,1
1,1,1,1,1,1,1,1,1,1,12,0,0,0,0,0,12,1,1,1,1,1,1,1,1,1,1
1,1,1,1,1,1,1,1,1,1,1,1,12,1,12,1,1,1,1,1,1,1,1,1,1,1,1
1,1,1,1,1,1,1,1,1,1,1,1,1,1,1,1,1,1,1,1,1,1,1,1,1,1,1
1,1,1,1,1,1,1,1,1,1,1,1,1,1,1,1,1,1,1,1,1,1,1,1,1,1,1
1,1,1,1,1,1,1,1,1,1,1,1,1,1,1,1,1,1,1,1,1,1,1,1,1,1,1
1,1,1,1,1,1,1,1,1,1,1,1,1,1,1,1,1,1,1,1,1,1,1,1,1,1,1
1,1,1,1,1,1,1,1,1,1,1,1,1,1,1,1,1,1,1,1,1,1,1,1,1,1,1
1,1,1,1,1,1,1,1,1,1,1,1,1,1,1,1,1,1,1,1,1,1,1,1,1,1,1
1,1,1,1,1,1,1,1,1,1,1,1,1,1,1,1,1,1,1,1,1,1,1,1,1,1,1
:endlayer
layer: 8
38,38,38,38,38,38,38,38,38,38,38,38,40,40,40,38,38,38,38,38,38,38,38,38,38,38,38
38,38,38,38,38,38,38,38,38,38,38,38,40,40,40,38,38,38,38,38,38,38,38,38,38,38,38
38,38,38,38,38,38,38,38,38,38,1,1,40,40,40,1,1,38,38,38,38,38,38,38,38,38,38
38,38,38,38,38,38,38,38,38,38,38,38,40,40,40,38,38,38,38,38,38,38,38,38,38,38,38
38,38,38,38,38,38,38,1,38,38,38,38,40,40,40,38,38,38,38,1,38,38,38,38,38,38,38
38,38,38,38,38,38,38,38,38,40,40,40,40,40,40,40,40,40,38,38,38,38,38,38,38,38,38
38,38,38,38,38,38,38,40,40,40,38,38,40,40,40,38,38,40,40,40,38,38,38,38,38,38,38
38,38,38,38,1,38,40,40,38,38,38,12,40,40,40,12,38,38,38,40,38,38,1,38,38,38,38
38,38,38,38,38,38,40,38,38,38,12,0,37,37,37,0,12,38,38,40,40,38,38,38,38,38,38
38,38,38,38,38,40,40,0,12,38,39,39,0,0,0,39,39,38,12,38,40,40,38,38,38,38,38
38,38,38,38,40,40,38,0,0,0,39,39,0,0,0,39,39,0,0,38,38,40,40,38,38,38,38
38,38,1,38,40,38,38,12,0,0,0,0,0,0,0,39,0,0,0,12,38,38,40,38,1,38,38
38,38,38,38,40,38,38,38,0,0,0,0,0,0,0,0,0,0,0,38,38,38,40,38,38,38,38
38,38,38,38,40,38,38,12,0,0,0,0,0,0,0,0,0,0,0,12,38,38,40,38,38,38,38
38,38,38,38,40,38,38,38,0,0,0,0,0,0,0,0,0,0,0,38,38,38,40,38,38,38,38
38,38,1,38,40,38,38,12,0,0,0,0,0,0,0,0,0,0,0,12,38,38,40,38,1,38,38
38,38,38,38,40,38,38,38,0,0,0,0,0,0,0,0,0,0,38,38,38,40,40,38,38,38,38
38,38,38,38,40,40,40,38,12,0,0,0,0,0,0,0,0,38,1,38,40,40,38,38,38,38,38
38,38,38,38,38,38,40,38,38,38,12,0,0,0,0,0,12,38,38,38,40,38,38,38,38,38,38
38,38,38,38,1,38,40,40,38,38,38,38,12,38,12,38,38,38,38,38,40,38,1,38,38,38,38
38,38,38,38,38,38,38,40,40,40,38,38,38,38,38,38,40,40,40,40,40,38,38,38,38,38,38
38,38,38,38,38,38,38,38,38,40,40,40,40,40,38,38,40,38,38,38,38,38,38,38,38,38,38
38,38,38,38,38,38,38,1,38,38,38,38,38,40,40,40,40,38,38,1,38,38,38,38,38,38,38
38,38,38,38,38,38,38,38,38,38,38,38,38,38,38,38,38,38,38,38,38,38,38,38,38,38,38
38,38,38,38,38,38,38,38,38,38,38,1,38,38,38,1,38,38,38,38,38,38,38,38,38,38,38
38,38,38,38,38,38,38,38,38,38,38,38,38,38,38,38,38,38,38,38,38,38,38,38,38,38,38
38,38,38,38,38,38,38,38,38,38,38,38,38,38,38,38,38,38,38,38,38,38,38,38,38,38,38
:endlayer
layer: 9
0,0,0,0,0,0,0,0,0,0,0,0,0,0,0,0,0,0,0,0,0,0,0,0,0,0,0
0,0,0,0,0,0,0,0,0,0,0,0,0,0,0,0,0,0,0,0,0,0,0,0,0,0,0
0,0,0,0,0,39,0,0,39,0,28,28,0,0,0,28,28,0,39,0,39,0,0,0,0,0,0
0,0,0,39,0,39,39,0,0,39,39,39,0,0,0,39,39,0,0,0,0,39,0,0,0,0,0
0,0,39,0,39,39,0,12,39,0,0,39,0,0,0,0,39,39,39,12,39,0,39,39,39,0,0
0,0,39,39,39,39,39,39,39,0,0,0,0,0,0,0,0,0,0,39,0,42,39,0,39,0,0
0,0,39,39,39,39,0,0,0,0,39,0,0,0,0,39,39,0,0,0,39,39,39,39,39,0,0
0,0,0,39,12,39,47,0,39,39,0,28,0,44,0,28,0,39,39,0,39,39,12,39,39,0,0
0,0,39,39,0,0,0,0,39,39,12,0,0,0,0,0,12,39,0,0,0,39,39,39,39,0,0
0,0,0,39,39,0,0,0,12,39,0,0,0,0,0,0,0,0,12,39,0,0,39,39,39,0,0
0,0,39,0,0,0,39,0,0,0,0,0,0,0,0,0,0,0,0,39,39,0,0,39,39,0,0
0,0,28,0,0,39,39,12,0,0,0,0,0,0,0,0,0,0,0,12,39,39,0,39,12,0,0
0,0,39,0,0,39,39,0,0,0,0,0,0,0,0,0,0,0,0,0,39,39,0,0,39,0,0
0,0,0,39,0,39,39,12,0,0,0,0,0,0,0,0,0,0,0,12,0,39,0,39,39,0,0
0,0,0,39,0,39,39,39,0,0,0,0,0,0,0,0,0,0,0,0,39,0,0,39,39,0,0
0,0,12,0,0,39,0,12,0,0,0,0,0,0,0,0,0,0,0,12,39,39,0,39,12,0,0
0,0,39,39,0,39,0,39,0,0,0,0,0,0,0,0,0,0,39,39,0,0,0,39,39,0,0
0,0,39,39,0,0,0,39,12,0,0,0,0,0,0,0,0,0,12,39,0,0,0,39,39,0,0
0,0,39,39,39,39,0,39,0,39,12,0,0,0,0,0,12,0,39,39,0,39,39,39,39,0,0
0,0,0,39,12,39,0,0,39,39,39,0,12,0,12,39,39,0,39,39,0,39,12,39,39,0,0
0,0,0,39,39,39,39,46,0,0,39,39,39,39,39,39,0,0,0,0,43,39,39,39,39,0,0
0,0,39,0,0,39,39,39,0,0,0,0,0,0,0,0,0,39,0,39,39,0,39,0,39,0,0
0,0,39,39,39,39,0,28,0,39,39,39,0,0,0,0,0,39,0,28,39,39,39,0,39,0,0
0,0,0,0,39,0,39,39,39,39,39,39,0,45,39,39,39,39,39,0,0,0,0,0,0,0,0
0,0,0,0,0,39,39,0,0,39,39,12,39,39,39,12,39,0,39,39,0,39,0,0,0,0,0
0,0,0,0,0,0,0,0,0,0,0,0,0,0,0,0,0,0,0,0,0,0,0,0,0,0,0
0,0,0,0,0,0,0,0,0,0,0,0,0,0,0,0,0,0,0,0,0,0,0,0,0,0,0
:endlayer
layer: 10
0,0,0,0,0,0,0,0,0,0,0,0,0,0,0,0,0,0,0,0,0,0,0,0,0,0,0
0,0,0,0,0,0,0,0,0,0,0,0,0,0,0,0,0,0,0,0,0,0,0,0,0,0,0
0,0,0,0,0,0,0,0,0,0,28,28,0,0,0,28,28,0,0,0,0,0,0,0,0,0,0
0,0,0,0,0,0,0,0,0,0,0,0,0,0,0,0,0,0,0,0,0,0,0,0,0,0,0
0,0,0,0,0,0,0,12,0,0,0,0,0,0,0,0,0,0,0,28,0,0,0,0,0,0,0
0,0,0,0,0,0,0,0,0,0,0,0,0,0,0,0,0,0,0,0,0,0,0,0,0,0,0
0,0,0,0,0,0,0,0,0,0,0,0,0,0,0,0,0,0,0,0,0,0,0,0,0,0,0
0,0,0,0,12,0,0,0,0,0,0,28,0,0,0,28,0,0,0,0,0,0,12,0,0,0,0
0,0,0,0,0,0,0,0,0,0,12,0,0,0,0,0,12,0,0,0,0,0,0,0,0,0,0
0,0,0,0,0,0,0,0,12,0,0,0,0,0,0,0,0,0,12,0,0,0,0,0,0,0,0
0,0,0,0,0,0,0,0,0,0,0,0,0,0,0,0,0,0,0,0,0,0,0,0,0,0,0
0,0,28,0,0,0,0,12,0,0,0,0,0,0,0,0,0,0,0,12,0,0,0,0,28,0,0
0,0,0,0,0,0,0,0,0,0,0,0,0,0,0,0,0,0,0,0,0,0,0,0,0,0,0
0,0,0,0,0,0,0,12,0,0,0,0,0,0,0,0,0,0,0,12,0,0,0,0,0,0,0
0,0,0,0,0,0,0,0,0,0,0,0,0,0,0,0,0,0,0,0,0,0,0,0,0,0,0
0,0,12,0,0,0,0,0,0,0,0,0,0,0,0,0,0,0,0,12,0,0,0,0,12,0,0
0,0,0,0,0,0,0,0,0,0,0,0,0,0,0,0,0,0,0,0,0,0,0,0,0,0,0
0,0,0,0,0,0,0,0,12,0,0,0,0,0,0,0,0,0,0,0,0,0,0,0,0,0,0
0,0,0,0,0,0,0,0,0,0,12,0,0,0,0,0,12,0,0,0,0,0,0,0,0,0,0
0,0,0,0,12,0,0,0,0,0,0,0,12,0,12,0,0,0,0,0,0,0,12,0,0,0,0
0,0,0,0,0,0,0,0,0,0,0,0,0,0,0,0,0,0,0,0,0,0,0,0,0,0,0
0,0,0,0,0,0,0,0,0,0,0,0,0,0,0,0,0,0,0,0,0,0,0,0,0,0,0
0,0,0,0,0,0,0,12,0,0,0,0,0,0,0,0,0,0,0,12,0,0,0,0,0,0,0
0,0,0,0,0,0,0,0,0,0,0,0,0,0,0,0,0,0,0,0,0,0,0,0,0,0,0
0,0,0,0,0,0,0,0,0,0,0,28,0,0,0,12,0,0,0,0,0,0,0,0,0,0,0
0,0,0,0,0,0,0,0,0,0,0,0,0,0,0,0,0,0,0,0,0,0,0,0,0,0,0
0,0,0,0,0,0,0,0,0,0,0,0,0,0,0,0,0,0,0,0,0,0,0,0,0,0,0
:endlayer
layer: 11
0,0,0,0,0,0,0,0,0,0,0,0,0,0,0,0,0,0,0,0,0,0,0,0,0,0,0
0,0,0,0,0,0,0,0,0,0,0,0,0,0,0,0,0,0,0,0,0,0,0,0,0,0,0
0,0,0,0,0,0,0,0,0,0,12,12,0,0,0,12,28,0,0,0,0,0,0,0,0,0,0
0,0,0,0,0,0,0,0,0,0,0,0,0,0,0,0,0,0,0,0,0,0,0,0,0,0,0
0,0,0,0,0,0,0,28,0,0,0,0,0,0,0,0,0,0,0,0,0,0,0,0,0,0,0
0,0,0,0,0,0,0,0,0,0,0,0,0,0,0,0,0,0,0,0,0,0,0,0,0,0,0
0,0,0,0,0,0,0,0,0,0,0,0,0,0,0,0,0,0,0,0,0,0,0,0,0,0,0
0,0,0,0,28,0,0,0,0,0,0,12,0,0,0,28,0,0,0,0,0,0,28,0,0,0,0
0,0,0,0,0,0,0,0,0,0,0,0,0,0,0,0,0,0,0,0,0,0,0,0,0,0,0
0,0,0,0,0,0,0,0,28,0,0,0,0,0,0,0,0,0,28,0,0,0,0,0,0,0,0
0,0,0,0,0,0,0,0,0,0,0,0,0,0,0,0,0,0,0,0,0,0,0,0,0,0,0
0,0,28,0,0,0,0,0,0,0,0,0,0,0,0,0,0,0,0,28,0,0,0,0,0,0,0
0,0,0,0,0,0,0,0,0,0,0,0,0,0,0,0,0,0,0,0,0,0,0,0,0,0,0
0,0,0,0,0,0,0,28,0,0,0,0,0,0,0,0,0,0,0,28,0,0,0,0,0,0,0
0,0,0,0,0,0,0,0,0,0,0,0,0,0,0,0,0,0,0,0,0,0,0,0,0,0,0
0,0,28,0,0,0,0,0,0,0,0,0,0,0,0,0,0,0,0,0,0,0,0,0,28,0,0
0,0,0,0,0,0,0,0,0,0,0,0,0,0,0,0,0,0,0,0,0,0,0,0,0,0,0
0,0,0,0,0,0,0,0,28,0,0,0,0,0,0,0,0,0,0,0,0,0,0,0,0,0,0
0,0,0,0,0,0,0,0,0,0,28,0,0,0,0,0,28,0,0,0,0,0,0,0,0,0,0
0,0,0,0,28,0,0,0,0,0,0,0,28,0,28,0,0,0,0,0,0,0,28,0,0,0,0
0,0,0,0,0,0,0,0,0,0,0,0,0,0,0,0,0,0,0,0,0,0,0,0,0,0,0
0,0,0,0,0,0,0,0,0,0,0,0,0,0,0,0,0,0,0,0,0,0,0,0,0,0,0
0,0,0,0,0,0,0,28,0,0,0,0,0,0,0,0,0,0,0,28,0,0,0,0,0,0,0
0,0,0,0,0,0,0,0,0,0,0,0,0,0,0,0,0,0,0,0,0,0,0,0,0,0,0
0,0,0,0,0,0,0,0,0,0,0,0,0,0,0,28,0,0,0,0,0,0,0,0,0,0,0
0,0,0,0,0,0,0,0,0,0,0,0,0,0,0,0,0,0,0,0,0,0,0,0,0,0,0
0,0,0,0,0,0,0,0,0,0,0,0,0,0,0,0,0,0,0,0,0,0,0,0,0,0,0
:endlayer
layer: 12
0,0,0,0,0,0,0,0,0,0,0,0,0,0,0,0,0,0,0,0,0,0,0,0,0,0,0
0,0,0,0,0,0,0,0,0,0,0,0,0,0,0,0,0,0,0,0,0,0,0,0,0,0,0
0,0,0,0,0,0,0,0,0,0,12,12,0,0,0,12,12,0,0,0,0,0,0,0,0,0,0
0,0,0,0,0,0,0,0,0,0,0,0,0,0,0,0,0,0,0,0,0,0,0,0,0,0,0
0,0,0,0,0,0,0,28,0,0,0,0,0,0,0,0,0,0,0,0,0,0,0,0,0,0,0
0,0,0,0,0,0,0,0,0,0,0,0,0,0,0,0,0,0,0,0,0,0,0,0,0,0,0
0,0,0,0,0,0,0,0,0,0,0,0,0,0,0,0,0,0,0,0,0,0,0,0,0,0,0
0,0,0,0,28,0,0,0,0,0,0,12,0,0,0,12,0,0,0,0,0,0,28,0,0,0,0
0,0,0,0,0,0,0,0,0,0,0,0,0,0,0,0,0,0,0,0,0,0,0,0,0,0,0
0,0,0,0,0,0,0,0,0,0,0,0,0,0,0,0,0,0,28,0,0,0,0,0,0,0,0
0,0,0,0,0,0,0,0,0,0,0,0,0,0,0,0,0,0,0,0,0,0,0,0,0,0,0
0,0,28,0,0,0,0,0,0,0,0,0,0,0,0,0,0,0,0,0,0,0,0,0,0,0,0
0,0,0,0,0,0,0,0,0,0,0,0,0,0,0,0,0,0,0,0,0,0,0,0,0,0,0
0,0,0,0,0,0,0,28,0,0,0,0,0,0,0,0,0,0,0,0,0,0,0,0,0,0,0
0,0,0,0,0,0,0,0,0,0,0,0,0,0,0,0,0,0,0,0,0,0,0,0,0,0,0
0,0,0,0,0,0,0,0,0,0,0,0,0,0,0,0,0,0,0,0,0,0,0,0,28,0,0
0,0,0,0,0,0,0,0,0,0,0,0,0,0,0,0,0,0,0,0,0,0,0,0,0,0,0
0,0,0,0,0,0,0,0,0,0,0,0,0,0,0,0,0,0,0,0,0,0,0,0,0,0,0
0,0,0,0,0,0,0,0,0,0,28,0,0,0,0,0,28,0,0,0,0,0,0,0,0,0,0
0,0,0,0,28,0,0,0,0,0,0,0,0,0,28,0,0,0,0,0,0,0,28,0,0,0,0
0,0,0,0,0,0,0,0,0,0,0,0,0,0,0,0,0,0,0,0,0,0,0,0,0,0,0
0,0,0,0,0,0,0,0,0,0,0,0,0,0,0,0,0,0,0,0,0,0,0,0,0,0,0
0,0,0,0,0,0,0,0,0,0,0,0,0,0,0,0,0,0,0,28,0,0,0,0,0,0,0
0,0,0,0,0,0,0,0,0,0,0,0,0,0,0,0,0,0,0,0,0,0,0,0,0,0,0
0,0,0,0,0,0,0,0,0,0,0,0,0,0,0,28,0,0,0,0,0,0,0,0,0,0,0
0,0,0,0,0,0,0,0,0,0,0,0,0,0,0,0,0,0,0,0,0,0,0,0,0,0,0
0,0,0,0,0,0,0,0,0,0,0,0,0,0,0,0,0,0,0,0,0,0,0,0,0,0,0
:endlayer
layer: 13
0,0,0,0,0,0,0,0,0,0,0,0,0,0,0,0,0,0,0,0,0,0,0,0,0,0,0
0,0,0,0,0,0,0,0,0,0,0,0,0,0,0,0,0,0,0,0,0,0,0,0,0,0,0
0,0,0,0,0,0,0,0,0,0,0,0,0,0,0,0,0,0,0,0,0,0,0,0,0,0,0
0,0,0,0,0,0,0,0,0,0,0,0,0,0,0,0,0,0,0,0,0,0,0,0,0,0,0
0,0,0,0,0,0,0,28,0,0,0,0,0,0,0,0,0,0,0,0,0,0,0,0,0,0,0
0,0,0,0,0,0,0,0,0,0,0,0,0,0,0,0,0,0,0,0,0,0,0,0,0,0,0
0,0,0,0,0,0,0,0,0,0,0,0,0,0,0,0,0,0,0,0,0,0,0,0,0,0,0
0,0,0,0,28,0,0,0,0,0,0,0,0,0,0,0,0,0,0,0,0,0,0,0,0,0,0
0,0,0,0,0,0,0,0,0,0,0,0,0,0,0,0,0,0,0,0,0,0,0,0,0,0,0
0,0,0,0,0,0,0,0,0,0,0,0,0,0,0,0,0,0,0,0,0,0,0,0,0,0,0
0,0,0,0,0,0,0,0,0,0,0,0,0,0,0,0,0,0,0,0,0,0,0,0,0,0,0
0,0,0,0,0,0,0,0,0,0,0,0,0,0,0,0,0,0,0,0,0,0,0,0,0,0,0
0,0,0,0,0,0,0,0,0,0,0,0,0,0,0,0,0,0,0,0,0,0,0,0,0,0,0
0,0,0,0,0,0,0,0,0,0,0,0,0,0,0,0,0,0,0,0,0,0,0,0,0,0,0
0,0,0,0,0,0,0,0,0,0,0,0,0,0,0,0,0,0,0,0,0,0,0,0,0,0,0
0,0,0,0,0,0,0,0,0,0,0,0,0,0,0,0,0,0,0,0,0,0,0,0,0,0,0
0,0,0,0,0,0,0,0,0,0,0,0,0,0,0,0,0,0,0,0,0,0,0,0,0,0,0
0,0,0,0,0,0,0,0,0,0,0,0,0,0,0,0,0,0,0,0,0,0,0,0,0,0,0
0,0,0,0,0,0,0,0,0,0,0,0,0,0,0,0,28,0,0,0,0,0,0,0,0,0,0
0,0,0,0,28,0,0,0,0,0,0,0,0,0,0,0,0,0,0,0,0,0,0,0,0,0,0
0,0,0,0,0,0,0,0,0,0,0,0,0,0,0,0,0,0,0,0,0,0,0,0,0,0,0
0,0,0,0,0,0,0,0,0,0,0,0,0,0,0,0,0,0,0,0,0,0,0,0,0,0,0
0,0,0,0,0,0,0,0,0,0,0,0,0,0,0,0,0,0,0,0,0,0,0,0,0,0,0
0,0,0,0,0,0,0,0,0,0,0,0,0,0,0,0,0,0,0,0,0,0,0,0,0,0,0
0,0,0,0,0,0,0,0,0,0,0,0,0,0,0,28,0,0,0,0,0,0,0,0,0,0,0
0,0,0,0,0,0,0,0,0,0,0,0,0,0,0,0,0,0,0,0,0,0,0,0,0,0,0
0,0,0,0,0,0,0,0,0,0,0,0,0,0,0,0,0,0,0,0,0,0,0,0,0,0,0
:endlayer
layer: 14
0,0,0,0,0,0,0,0,0,0,0,0,0,0,0,0,0,0,0,0,0,0,0,0,0,0,0
0,0,0,0,0,0,0,0,0,0,0,0,0,0,0,0,0,0,0,0,0,0,0,0,0,0,0
0,0,0,0,0,0,0,0,0,0,0,0,0,0,0,0,0,0,0,0,0,0,0,0,0,0,0
0,0,0,0,0,0,0,0,0,0,0,0,0,0,0,0,0,0,0,0,0,0,0,0,0,0,0
0,0,0,0,0,0,0,0,0,0,0,0,0,0,0,0,0,0,0,0,0,0,0,0,0,0,0
0,0,0,0,0,0,0,0,0,0,0,0,0,0,0,0,0,0,0,0,0,0,0,0,0,0,0
0,0,0,0,0,0,0,0,0,0,0,0,0,0,0,0,0,0,0,0,0,0,0,0,0,0,0
0,0,0,0,0,0,0,0,0,0,0,0,0,0,0,0,0,0,0,0,0,0,0,0,0,0,0
0,0,0,0,0,0,0,0,0,0,0,0,0,0,0,0,0,0,0,0,0,0,0,0,0,0,0
0,0,0,0,0,0,0,0,0,0,0,0,0,0,0,0,0,0,0,0,0,0,0,0,0,0,0
0,0,0,0,0,0,0,0,0,0,0,0,0,0,0,0,0,0,0,0,0,0,0,0,0,0,0
0,0,0,0,0,0,0,0,0,0,0,0,0,0,0,0,0,0,0,0,0,0,0,0,0,0,0
0,0,0,0,0,0,0,0,0,0,0,0,0,0,0,0,0,0,0,0,0,0,0,0,0,0,0
0,0,0,0,0,0,0,0,0,0,0,0,0,0,0,0,0,0,0,0,0,0,0,0,0,0,0
0,0,0,0,0,0,0,0,0,0,0,0,0,0,0,0,0,0,0,0,0,0,0,0,0,0,0
0,0,0,0,0,0,0,0,0,0,0,0,0,0,0,0,0,0,0,0,0,0,0,0,0,0,0
0,0,0,0,0,0,0,0,0,0,0,0,0,0,0,0,0,0,0,0,0,0,0,0,0,0,0
0,0,0,0,0,0,0,0,0,0,0,0,0,0,0,0,0,0,0,0,0,0,0,0,0,0,0
0,0,0,0,0,0,0,0,0,0,0,0,0,0,0,0,28,0,0,0,0,0,0,0,0,0,0
0,0,0,0,0,0,0,0,0,0,0,0,0,0,0,0,0,0,0,0,0,0,0,0,0,0,0
0,0,0,0,0,0,0,0,0,0,0,0,0,0,0,0,0,0,0,0,0,0,0,0,0,0,0
0,0,0,0,0,0,0,0,0,0,0,0,0,0,0,0,0,0,0,0,0,0,0,0,0,0,0
0,0,0,0,0,0,0,0,0,0,0,0,0,0,0,0,0,0,0,0,0,0,0,0,0,0,0
0,0,0,0,0,0,0,0,0,0,0,0,0,0,0,0,0,0,0,0,0,0,0,0,0,0,0
0,0,0,0,0,0,0,0,0,0,0,0,0,0,0,0,0,0,0,0,0,0,0,0,0,0,0
0,0,0,0,0,0,0,0,0,0,0,0,0,0,0,0,0,0,0,0,0,0,0,0,0,0,0
0,0,0,0,0,0,0,0,0,0,0,0,0,0,0,0,0,0,0,0,0,0,0,0,0,0,0
:endlayer

#### RULES ####
rule:
plugin=vanillaBlocks
number=1
data:
JSON:{blockState:{blockName:"minecraft:dirt",properties:{variant:"dirt",snowy:"false"}}}
:enddata
:endrule

rule:
plugin=vanillaBlocks
number=2
data:
JSON:{blockState:{blockName:"minecraft:stone",properties:{variant:"stone"}}}
:enddata
:endrule

rule:
plugin=vanillaBlocks
number=3
data:
JSON:{blockState:{blockName:"minecraft:cobblestone"}}
:enddata
:endrule

rule:
plugin=vanillaBlocks
number=4
data:
JSON:{blockState:{blockName:"minecraft:iron_ore"}}
:enddata
:endrule

rule:
plugin=fluid
number=5
data:
JSON:{blockState:{blockName:"minecraft:water",properties:{level:"0"}}}
:enddata
:endrule

rule:
plugin=inventory
number=6
data:
JSON:{blockState:{blockName:"minecraft:chest",properties:{facing:"west"}},lootLevel:0,teData:{Items:[],id:"minecraft:chest",Lock:""},inventoryData:{length:0,inventoryContents:[]},legacyFeatures:1b}
:enddata
:endrule

rule:
plugin=vanillaBlocks
number=7
data:
JSON:{blockState:{blockName:"minecraft:monster_egg",properties:{variant:"stone"}}}
:enddata
:endrule

rule:
plugin=vanillaBlocks
number=8
data:
JSON:{blockState:{blockName:"minecraft:wooden_slab",properties:{half:"bottom",variant:"dark_oak"}}}
:enddata
:endrule

rule:
plugin=blockTile
number=9
data:
JSON:{blockState:{blockName:"ancientwarfarestructure:advanced_spawner",properties:{transparent:"true"}},teData:{id:"ancientwarfarestructure:advanced_spawner_tile",spawnerSettings:{minDelay:0,spawnDelay:0,lightSensitive:0b,spawnGroups:[{settingsList:[{remainingSpawnCount:1,hostile:1b,forced:1b,customTag:{factionName:"brigand"},maxToSpawn:1,entityId:"ancientwarfarenpc:faction.soldier",minToSpawn:1}],groupWeight:1}],playerRange:5,respondToRedstone:0b,inventory:{Size:9,Items:[]},spawnRange:0,transparent:1b,maxDelay:0,xpToDrop:0,mobRange:0,debugMode:0b,maxNearbyMonsters:0}}}
:enddata
:endrule

rule:
plugin=blockTile
number=10
data:
JSON:{blockState:{blockName:"ancientwarfarestructure:advanced_spawner",properties:{transparent:"true"}},teData:{id:"ancientwarfarestructure:advanced_spawner_tile",spawnerSettings:{minDelay:0,spawnDelay:0,lightSensitive:0b,spawnGroups:[{settingsList:[{remainingSpawnCount:1,hostile:1b,forced:1b,customTag:{factionName:"brigand"},maxToSpawn:1,entityId:"ancientwarfarenpc:faction.soldier",minToSpawn:1}],groupWeight:1}],playerRange:5,respondToRedstone:0b,inventory:{Size:9,Items:[]},spawnRange:0,transparent:1b,maxDelay:0,xpToDrop:0,mobRange:0,debugMode:0b,maxNearbyMonsters:0}}}
:enddata
:endrule

rule:
plugin=vanillaBlocks
number=11
data:
JSON:{blockState:{blockName:"ancientwarfarestructure:fire_pit",properties:{lit:"true",variant:"default"}}}
:enddata
:endrule

rule:
plugin=vanillaBlocks
number=12
data:
JSON:{blockState:{blockName:"minecraft:stonebrick",properties:{variant:"cracked_stonebrick"}}}
:enddata
:endrule

rule:
plugin=vanillaBlocks
number=13
data:
JSON:{blockState:{blockName:"minecraft:stone_brick_stairs",properties:{half:"bottom",shape:"straight",facing:"east"}}}
:enddata
:endrule

rule:
plugin=blockTile
number=14
data:
JSON:{blockState:{blockName:"ancientwarfarestructure:advanced_spawner",properties:{transparent:"true"}},teData:{id:"ancientwarfarestructure:advanced_spawner_tile",spawnerSettings:{minDelay:0,spawnDelay:0,lightSensitive:0b,spawnGroups:[{settingsList:[{remainingSpawnCount:1,hostile:1b,forced:1b,customTag:{factionName:"brigand"},maxToSpawn:1,entityId:"ancientwarfarenpc:faction.leader.elite",minToSpawn:1}],groupWeight:1}],playerRange:6,respondToRedstone:0b,inventory:{Size:9,Items:[]},spawnRange:0,transparent:1b,maxDelay:0,xpToDrop:0,mobRange:0,debugMode:0b,maxNearbyMonsters:0}}}
:enddata
:endrule

rule:
plugin=vanillaBlocks
number=15
data:
JSON:{blockState:{blockName:"minecraft:wooden_slab",properties:{half:"bottom",variant:"oak"}}}
:enddata
:endrule

rule:
plugin=blockTile
number=16
data:
JSON:{blockState:{blockName:"ancientwarfarestructure:advanced_spawner",properties:{transparent:"true"}},teData:{id:"ancientwarfarestructure:advanced_spawner_tile",spawnerSettings:{minDelay:0,spawnDelay:0,lightSensitive:0b,spawnGroups:[{settingsList:[{remainingSpawnCount:1,hostile:1b,forced:1b,customTag:{factionName:"brigand"},maxToSpawn:1,entityId:"ancientwarfarenpc:faction.soldier",minToSpawn:1}],groupWeight:1}],playerRange:5,respondToRedstone:0b,inventory:{Size:9,Items:[]},spawnRange:0,transparent:1b,maxDelay:0,xpToDrop:0,mobRange:0,debugMode:0b,maxNearbyMonsters:0}}}
:enddata
:endrule

rule:
plugin=blockTile
number=17
data:
JSON:{blockState:{blockName:"ancientwarfarestructure:advanced_spawner",properties:{transparent:"true"}},teData:{id:"ancientwarfarestructure:advanced_spawner_tile",spawnerSettings:{minDelay:0,spawnDelay:0,lightSensitive:0b,spawnGroups:[{settingsList:[{remainingSpawnCount:1,hostile:1b,forced:1b,customTag:{factionName:"brigand"},maxToSpawn:1,entityId:"ancientwarfarenpc:faction.soldier",minToSpawn:1}],groupWeight:1}],playerRange:4,respondToRedstone:0b,inventory:{Size:9,Items:[]},spawnRange:0,transparent:1b,maxDelay:0,xpToDrop:0,mobRange:0,debugMode:0b,maxNearbyMonsters:0}}}
:enddata
:endrule

rule:
plugin=blockTile
number=18
data:
JSON:{blockState:{blockName:"ancientwarfarestructure:advanced_spawner",properties:{transparent:"true"}},teData:{id:"ancientwarfarestructure:advanced_spawner_tile",spawnerSettings:{minDelay:0,spawnDelay:0,lightSensitive:0b,spawnGroups:[{settingsList:[{remainingSpawnCount:1,hostile:1b,forced:1b,customTag:{factionName:"brigand"},maxToSpawn:1,entityId:"ancientwarfarenpc:faction.soldier",minToSpawn:1}],groupWeight:1}],playerRange:4,respondToRedstone:0b,inventory:{Size:9,Items:[]},spawnRange:0,transparent:1b,maxDelay:0,xpToDrop:0,mobRange:0,debugMode:0b,maxNearbyMonsters:0}}}
:enddata
:endrule

rule:
plugin=blockTile
number=19
data:
JSON:{blockState:{blockName:"ancientwarfarestructure:advanced_spawner",properties:{transparent:"true"}},teData:{id:"ancientwarfarestructure:advanced_spawner_tile",spawnerSettings:{minDelay:0,spawnDelay:0,lightSensitive:0b,spawnGroups:[{settingsList:[{remainingSpawnCount:1,hostile:1b,forced:1b,customTag:{factionName:"brigand"},maxToSpawn:1,entityId:"ancientwarfarenpc:faction.soldier",minToSpawn:1}],groupWeight:1}],playerRange:4,respondToRedstone:0b,inventory:{Size:9,Items:[]},spawnRange:0,transparent:1b,maxDelay:0,xpToDrop:0,mobRange:0,debugMode:0b,maxNearbyMonsters:0}}}
:enddata
:endrule

rule:
plugin=blockTile
number=20
data:
JSON:{blockState:{blockName:"ancientwarfarestructure:advanced_spawner",properties:{transparent:"true"}},teData:{id:"ancientwarfarestructure:advanced_spawner_tile",spawnerSettings:{minDelay:0,spawnDelay:0,lightSensitive:0b,spawnGroups:[{settingsList:[{remainingSpawnCount:1,hostile:1b,forced:1b,customTag:{factionName:"brigand"},maxToSpawn:1,entityId:"ancientwarfarenpc:faction.leader",minToSpawn:1}],groupWeight:1}],playerRange:6,respondToRedstone:0b,inventory:{Size:9,Items:[]},spawnRange:0,transparent:1b,maxDelay:0,xpToDrop:0,mobRange:0,debugMode:0b,maxNearbyMonsters:0}}}
:enddata
:endrule

rule:
plugin=blockTile
number=21
data:
JSON:{blockState:{blockName:"ancientwarfarestructure:advanced_loot_chest",properties:{facing:"west"}},teData:{LootTable:"ancientwarfare:inject/chests/simple_dungeon",lootRolls:1b,id:"ancientwarfarestructure:advanced_loot_chest_tile",Lock:""}}
:enddata
:endrule

rule:
plugin=blockTile
number=22
data:
JSON:{blockState:{blockName:"ancientwarfarestructure:advanced_spawner",properties:{transparent:"true"}},teData:{id:"ancientwarfarestructure:advanced_spawner_tile",spawnerSettings:{minDelay:0,spawnDelay:0,lightSensitive:0b,spawnGroups:[{settingsList:[{remainingSpawnCount:1,hostile:1b,forced:1b,customTag:{},maxToSpawn:1,entityId:"minecraft:witch",minToSpawn:1}],groupWeight:1}],playerRange:6,respondToRedstone:0b,inventory:{Size:9,Items:[]},spawnRange:0,transparent:1b,maxDelay:0,xpToDrop:0,mobRange:0,debugMode:0b,maxNearbyMonsters:0}}}
:enddata
:endrule

rule:
plugin=blockTile
number=23
data:
JSON:{blockState:{blockName:"ancientwarfarestructure:advanced_loot_chest",properties:{facing:"north"}},teData:{LootTable:"ancientwarfare:inject/chests/simple_dungeon",lootRolls:1b,id:"ancientwarfarestructure:advanced_loot_chest_tile",Lock:""}}
:enddata
:endrule

rule:
plugin=vanillaBlocks
number=24
data:
JSON:{blockState:{blockName:"minecraft:nether_brick_fence",properties:{east:"false",south:"false",north:"false",west:"false"}}}
:enddata
:endrule

rule:
plugin=vanillaBlocks
number=25
data:
JSON:{blockState:{blockName:"minecraft:cauldron",properties:{level:"3"}}}
:enddata
:endrule

rule:
plugin=blockTile
number=26
data:
JSON:{blockState:{blockName:"ancientwarfarestructure:advanced_spawner",properties:{transparent:"true"}},teData:{id:"ancientwarfarestructure:advanced_spawner_tile",spawnerSettings:{minDelay:0,spawnDelay:0,lightSensitive:0b,spawnGroups:[{settingsList:[{remainingSpawnCount:1,hostile:1b,forced:1b,customTag:{factionName:"brigand"},maxToSpawn:1,entityId:"ancientwarfarenpc:faction.soldier",minToSpawn:1}],groupWeight:1}],playerRange:5,respondToRedstone:0b,inventory:{Size:9,Items:[]},spawnRange:0,transparent:1b,maxDelay:0,xpToDrop:0,mobRange:0,debugMode:0b,maxNearbyMonsters:0}}}
:enddata
:endrule

rule:
plugin=blockTile
number=27
data:
JSON:{blockState:{blockName:"ancientwarfarestructure:advanced_spawner",properties:{transparent:"true"}},teData:{id:"ancientwarfarestructure:advanced_spawner_tile",spawnerSettings:{minDelay:0,spawnDelay:0,lightSensitive:0b,spawnGroups:[{settingsList:[{remainingSpawnCount:1,hostile:1b,forced:1b,customTag:{factionName:"brigand"},maxToSpawn:1,entityId:"ancientwarfarenpc:faction.soldier",minToSpawn:1}],groupWeight:1}],playerRange:5,respondToRedstone:0b,inventory:{Size:9,Items:[]},spawnRange:0,transparent:1b,maxDelay:0,xpToDrop:0,mobRange:0,debugMode:0b,maxNearbyMonsters:0}}}
:enddata
:endrule

rule:
plugin=vanillaBlocks
number=28
data:
JSON:{blockState:{blockName:"minecraft:stonebrick",properties:{variant:"stonebrick"}}}
:enddata
:endrule

rule:
plugin=vanillaBlocks
number=29
data:
JSON:{blockState:{blockName:"minecraft:stone_brick_stairs",properties:{half:"bottom",shape:"straight",facing:"west"}}}
:enddata
:endrule

rule:
plugin=blockTile
number=30
data:
JSON:{blockState:{blockName:"ancientwarfarestructure:advanced_loot_chest",properties:{facing:"west"}},teData:{LootTable:"ancientwarfare:inject/chests/simple_dungeon",lootRolls:1b,id:"ancientwarfarestructure:advanced_loot_chest_tile",Lock:""}}
:enddata
:endrule

rule:
plugin=inventory
number=31
data:
JSON:{blockState:{blockName:"minecraft:chest",properties:{facing:"south"}},lootLevel:0,teData:{Items:[],id:"minecraft:chest",Lock:""},inventoryData:{length:0,inventoryContents:[]},legacyFeatures:1b}
:enddata
:endrule

rule:
plugin=vanillaBlocks
number=32
data:
JSON:{blockState:{blockName:"minecraft:torch",properties:{facing:"west"}}}
:enddata
:endrule

rule:
plugin=vanillaBlocks
number=33
data:
JSON:{blockState:{blockName:"minecraft:torch",properties:{facing:"east"}}}
:enddata
:endrule

rule:
plugin=vanillaBlocks
number=34
data:
JSON:{blockState:{blockName:"minecraft:coal_ore"}}
:enddata
:endrule

rule:
plugin=vanillaBlocks
number=35
data:
JSON:{blockState:{blockName:"minecraft:torch",properties:{facing:"north"}}}
:enddata
:endrule

rule:
plugin=vanillaBlocks
number=36
data:
JSON:{blockState:{blockName:"minecraft:torch",properties:{facing:"south"}}}
:enddata
:endrule

rule:
plugin=vanillaBlocks
number=37
data:
JSON:{blockState:{blockName:"minecraft:stone_brick_stairs",properties:{half:"bottom",shape:"straight",facing:"north"}}}
:enddata
:endrule

rule:
plugin=vanillaBlocks
number=38
data:
JSON:{blockState:{blockName:"minecraft:grass",properties:{snowy:"false"}}}
:enddata
:endrule

rule:
plugin=vanillaBlocks
number=39
data:
JSON:{blockState:{blockName:"minecraft:tallgrass",properties:{type:"tall_grass"}}}
:enddata
:endrule

rule:
plugin=vanillaBlocks
number=40
data:
JSON:{blockState:{blockName:"minecraft:gravel"}}
:enddata
:endrule

rule:
plugin=vanillaBlocks
number=41
data:
JSON:{blockState:{blockName:"minecraft:stone_slab",properties:{half:"bottom",variant:"stone_brick"}}}
:enddata
:endrule

rule:
plugin=blockTile
number=42
data:
JSON:{blockState:{blockName:"ancientwarfarestructure:advanced_spawner",properties:{transparent:"true"}},teData:{id:"ancientwarfarestructure:advanced_spawner_tile",spawnerSettings:{minDelay:0,spawnDelay:0,lightSensitive:0b,spawnGroups:[{settingsList:[{remainingSpawnCount:1,hostile:1b,forced:1b,customTag:{factionName:"brigand"},maxToSpawn:1,entityId:"ancientwarfarenpc:faction.archer",minToSpawn:1}],groupWeight:1}],playerRange:16,respondToRedstone:0b,inventory:{Size:9,Items:[]},spawnRange:0,transparent:1b,maxDelay:0,xpToDrop:0,mobRange:0,debugMode:0b,maxNearbyMonsters:0}}}
:enddata
:endrule

rule:
plugin=blockTile
number=43
data:
JSON:{blockState:{blockName:"ancientwarfarestructure:advanced_spawner",properties:{transparent:"true"}},teData:{id:"ancientwarfarestructure:advanced_spawner_tile",spawnerSettings:{minDelay:0,spawnDelay:0,lightSensitive:0b,spawnGroups:[{settingsList:[{remainingSpawnCount:1,hostile:1b,forced:1b,customTag:{factionName:"brigand"},maxToSpawn:1,entityId:"ancientwarfarenpc:faction.archer",minToSpawn:1}],groupWeight:1}],playerRange:16,respondToRedstone:0b,inventory:{Size:9,Items:[]},spawnRange:0,transparent:1b,maxDelay:0,xpToDrop:0,mobRange:0,debugMode:0b,maxNearbyMonsters:0}}}
:enddata
:endrule

rule:
plugin=blockTile
number=44
data:
JSON:{blockState:{blockName:"ancientwarfarestructure:advanced_spawner",properties:{transparent:"true"}},teData:{id:"ancientwarfarestructure:advanced_spawner_tile",spawnerSettings:{minDelay:0,spawnDelay:0,lightSensitive:0b,spawnGroups:[{settingsList:[{remainingSpawnCount:1,hostile:1b,forced:1b,customTag:{factionName:"brigand"},maxToSpawn:1,entityId:"ancientwarfarenpc:faction.soldier.elite",minToSpawn:1}],groupWeight:1}],playerRange:16,respondToRedstone:0b,inventory:{Size:9,Items:[]},spawnRange:0,transparent:1b,maxDelay:0,xpToDrop:0,mobRange:0,debugMode:0b,maxNearbyMonsters:0}}}
:enddata
:endrule

rule:
plugin=blockTile
number=45
data:
JSON:{blockState:{blockName:"ancientwarfarestructure:advanced_spawner",properties:{transparent:"true"}},teData:{id:"ancientwarfarestructure:advanced_spawner_tile",spawnerSettings:{minDelay:0,spawnDelay:0,lightSensitive:0b,spawnGroups:[{settingsList:[{remainingSpawnCount:1,hostile:1b,forced:1b,customTag:{factionName:"brigand"},maxToSpawn:1,entityId:"ancientwarfarenpc:faction.soldier.elite",minToSpawn:1}],groupWeight:1}],playerRange:16,respondToRedstone:0b,inventory:{Size:9,Items:[]},spawnRange:0,transparent:1b,maxDelay:0,xpToDrop:0,mobRange:0,debugMode:0b,maxNearbyMonsters:0}}}
:enddata
:endrule

rule:
plugin=blockTile
number=46
data:
JSON:{blockState:{blockName:"ancientwarfarestructure:advanced_spawner",properties:{transparent:"true"}},teData:{id:"ancientwarfarestructure:advanced_spawner_tile",spawnerSettings:{minDelay:0,spawnDelay:0,lightSensitive:0b,spawnGroups:[{settingsList:[{remainingSpawnCount:1,hostile:1b,forced:1b,customTag:{factionName:"brigand"},maxToSpawn:1,entityId:"ancientwarfarenpc:faction.archer",minToSpawn:1}],groupWeight:1}],playerRange:16,respondToRedstone:0b,inventory:{Size:9,Items:[]},spawnRange:0,transparent:1b,maxDelay:0,xpToDrop:0,mobRange:0,debugMode:0b,maxNearbyMonsters:0}}}
:enddata
:endrule

rule:
plugin=blockTile
number=47
data:
JSON:{blockState:{blockName:"ancientwarfarestructure:advanced_spawner",properties:{transparent:"true"}},teData:{id:"ancientwarfarestructure:advanced_spawner_tile",spawnerSettings:{minDelay:0,spawnDelay:0,lightSensitive:0b,spawnGroups:[{settingsList:[{remainingSpawnCount:1,hostile:1b,forced:1b,customTag:{factionName:"brigand"},maxToSpawn:1,entityId:"ancientwarfarenpc:faction.archer",minToSpawn:1}],groupWeight:1}],playerRange:16,respondToRedstone:0b,inventory:{Size:9,Items:[]},spawnRange:0,transparent:1b,maxDelay:0,xpToDrop:0,mobRange:0,debugMode:0b,maxNearbyMonsters:0}}}
:enddata
:endrule

#### ENTITIES ####
