# Ancient Warfare Structure Template File
# Auto-generated structure template file. created on: 12/25/2018 at: 22:43:5
# Lines beginning with # denote comments

header:
version=2.8
name=BrigandHideOakSmall
mods=
size=23,19,20
offset=13,4,19
:endheader

#### VALIDATION ####
validation:
type=ground
survival=false
worldGenEnabled=true
unique=false
preserveBlocks=false
selectionWeight=30
clusterValue=30
minDuplicateDistance=500
dimensionWhiteList=true
dimensionList=0
biomeWhiteList=true
biomeList=biomesoplenty:shrubland,biomesoplenty:woodland,traverse:woodlands,minecraft:forest,minecraft:forest_hills
leveling=3
fill=0
border=0
blockSwap=false
:endvalidation

#### LAYERS ####
layer: 0
1,1,1,1,1,1,1,1,1,1,1,1,1,1,1,1,1,1,1,1,1,1,1
1,1,1,1,1,1,1,1,1,1,1,1,1,1,1,1,1,1,1,1,1,1,1
1,1,1,1,1,1,1,1,1,1,1,1,1,1,1,1,1,1,1,1,1,1,1
1,1,1,1,1,1,1,1,1,1,1,1,1,1,1,1,1,1,1,1,1,1,1
1,1,1,1,1,1,1,1,1,1,1,1,1,1,1,1,1,1,1,1,1,1,1
1,1,1,1,1,1,1,1,1,1,1,1,1,1,1,1,1,1,1,1,1,1,1
1,1,1,1,1,1,1,1,1,1,1,1,1,1,1,1,1,1,1,1,1,1,1
1,1,1,1,1,1,1,1,1,1,1,1,1,1,1,1,1,1,1,1,1,1,1
1,1,1,1,1,1,1,1,1,1,1,1,1,1,1,1,1,1,1,1,1,1,1
1,1,1,1,1,1,1,1,1,1,1,1,1,1,1,1,1,1,1,1,1,1,1
1,1,1,1,1,1,1,1,1,1,1,1,1,1,1,1,1,1,1,1,1,1,1
1,1,1,1,1,1,1,1,1,1,1,1,1,1,1,1,1,1,1,1,1,1,1
1,1,1,1,1,1,1,1,1,1,1,1,1,1,1,1,1,1,1,1,1,1,1
1,1,1,1,1,1,1,1,1,1,1,1,1,1,1,1,1,1,1,1,1,1,1
1,1,1,1,1,1,1,1,1,1,1,1,1,1,1,1,1,1,1,1,1,1,1
1,1,1,1,1,1,1,1,1,1,1,1,1,1,1,1,1,1,1,1,1,1,1
1,1,1,1,1,1,1,1,1,1,1,1,1,1,1,1,1,1,1,1,1,1,1
1,1,1,1,1,1,1,1,1,1,1,1,1,1,1,1,1,1,1,1,1,1,1
1,1,1,1,1,1,1,1,1,1,1,1,1,1,1,1,1,1,1,1,1,1,1
1,1,1,1,1,1,1,1,1,1,1,1,1,1,1,1,1,1,1,1,1,1,1
:endlayer
layer: 1
1,1,1,1,1,1,1,1,1,1,1,1,1,1,1,1,1,1,1,1,1,1,1
1,1,1,1,1,1,1,1,1,1,1,1,1,1,1,1,1,1,1,1,1,1,1
1,1,1,1,1,1,1,1,1,1,1,1,1,1,1,1,1,1,1,1,1,1,1
1,1,1,1,1,1,1,1,1,1,1,1,1,1,1,1,1,1,1,1,1,1,1
1,1,1,1,1,1,1,1,1,1,1,1,1,1,1,1,1,1,1,1,1,1,1
1,1,1,1,1,1,1,1,1,1,1,1,1,1,1,1,1,1,1,1,1,1,1
1,1,1,1,1,1,1,1,1,1,1,1,1,1,1,1,1,1,1,1,1,1,1
1,1,1,1,1,1,1,1,1,1,1,1,1,1,1,1,1,1,1,1,1,1,1
1,1,1,1,1,1,1,1,1,1,1,1,1,1,1,1,1,1,1,1,1,1,1
1,1,1,1,1,1,1,1,1,1,1,1,1,1,1,1,1,1,1,1,1,1,1
1,1,1,1,1,1,1,1,1,1,1,1,1,1,1,1,1,1,1,1,1,1,1
1,1,1,1,1,1,1,1,1,1,1,1,1,1,1,1,1,1,1,1,1,1,1
1,1,1,1,1,1,1,1,1,1,1,1,1,1,1,1,1,1,1,1,1,1,1
1,1,1,1,1,1,1,1,1,1,1,1,1,1,1,1,1,1,1,1,1,1,1
1,1,1,1,1,1,1,1,1,1,1,1,1,1,1,1,1,1,1,1,1,1,1
1,1,1,1,1,1,1,1,1,1,1,1,1,1,1,1,1,1,1,1,1,1,1
1,1,1,1,1,1,1,1,1,1,1,1,1,1,1,1,1,1,1,1,1,1,1
1,1,1,1,1,1,1,1,1,1,1,1,1,1,1,1,1,1,1,1,1,1,1
1,1,1,1,1,1,1,1,1,1,1,1,1,1,1,1,1,1,1,1,1,1,1
1,1,1,1,1,1,1,1,1,1,1,1,1,1,1,1,1,1,1,1,1,1,1
:endlayer
layer: 2
1,1,1,1,1,1,1,1,1,1,1,1,1,1,1,1,1,1,1,1,1,1,1
1,1,1,1,1,1,1,1,1,1,1,1,1,1,1,1,1,1,1,1,1,1,1
1,1,1,1,1,1,1,1,1,1,1,1,1,1,1,1,1,1,1,1,1,1,1
1,1,1,1,1,1,1,1,1,1,1,1,1,1,1,1,1,1,1,1,1,1,1
1,1,1,1,1,1,1,1,1,1,1,1,1,1,1,1,1,1,1,1,1,1,1
1,1,1,1,1,1,1,1,1,1,1,1,1,1,1,1,1,1,1,1,1,1,1
1,1,1,1,1,1,1,1,1,1,1,1,1,1,1,1,1,1,1,1,1,1,1
1,1,1,1,1,1,1,1,1,1,1,1,1,1,1,1,1,1,1,1,1,1,1
1,1,1,1,1,1,1,1,1,1,1,1,1,1,1,1,1,1,1,1,1,1,1
1,1,1,1,1,1,1,1,1,1,1,1,1,1,1,1,1,1,1,1,1,1,1
1,1,1,1,1,1,1,1,1,1,1,1,1,1,1,1,1,1,1,1,1,1,1
1,1,1,1,1,1,1,1,1,1,1,1,1,1,1,1,1,1,1,1,1,1,1
1,1,1,1,1,1,1,1,1,1,1,1,1,1,1,1,1,1,1,1,1,1,1
1,1,1,1,1,1,1,1,1,2,1,1,1,1,1,1,1,1,1,1,1,1,1
1,1,1,1,1,1,1,1,1,1,1,1,1,1,1,1,1,1,1,1,1,1,1
1,1,1,1,1,1,1,1,1,1,1,1,1,1,1,1,1,1,1,1,1,1,1
1,1,1,1,1,1,1,1,1,1,1,1,1,1,1,1,1,1,1,1,1,1,1
1,1,1,1,1,1,1,1,1,1,1,1,1,1,1,1,1,1,1,1,1,1,1
1,1,1,1,1,1,1,1,1,1,1,1,1,1,1,1,1,1,1,1,1,1,1
1,1,1,1,1,1,1,1,1,1,1,1,1,1,1,1,1,1,1,1,1,1,1
:endlayer
layer: 3
3,3,3,3,3,3,3,3,3,3,3,3,3,3,3,3,3,3,3,3,3,3,3
3,1,1,1,1,1,1,1,1,1,1,1,1,1,1,1,1,1,1,1,3,3,3
3,1,5,1,1,1,1,1,1,5,5,1,1,1,1,1,1,4,1,1,1,3,3
3,1,1,1,1,1,1,1,1,1,1,1,1,1,1,1,1,1,1,1,1,1,3
3,1,1,1,1,1,1,1,1,1,1,1,1,1,1,1,1,1,1,1,1,1,3
3,1,1,1,1,1,1,1,1,1,1,1,1,1,1,1,1,1,1,1,1,1,3
3,1,1,1,1,1,1,1,1,1,1,1,1,1,1,1,1,1,1,1,1,1,3
3,1,1,1,1,1,1,1,1,1,1,1,1,1,1,1,1,1,1,1,1,1,3
3,1,1,1,1,1,1,1,1,1,1,1,1,1,1,1,1,1,1,1,1,1,3
3,1,7,1,1,1,1,1,1,5,5,1,1,1,1,1,1,5,1,1,1,1,3
3,1,5,1,1,1,1,1,1,5,5,1,1,1,1,1,1,6,1,1,1,1,3
3,1,1,1,1,1,1,1,1,1,1,1,1,1,1,1,1,1,1,1,1,1,3
3,3,1,1,1,1,1,1,2,2,2,1,1,1,1,1,1,1,1,1,1,1,3
3,3,1,1,1,1,1,1,2,2,2,1,1,1,1,1,1,1,1,1,1,1,3
3,3,3,1,1,1,1,1,2,2,1,1,1,1,1,1,1,1,1,1,1,1,3
3,3,3,3,1,1,1,1,1,1,1,1,1,1,1,1,1,1,1,1,1,1,3
3,3,3,3,1,1,1,1,1,1,1,1,1,1,1,1,1,1,1,1,1,1,3
3,3,4,3,3,1,1,1,1,4,4,1,1,1,1,1,1,6,1,1,1,3,3
3,3,3,3,3,1,1,1,1,1,1,1,1,1,1,1,1,1,1,1,1,3,3
3,3,3,3,3,3,3,3,3,3,3,3,3,3,3,3,3,3,3,3,3,3,3
:endlayer
layer: 4
0,0,0,0,0,0,0,0,0,0,0,0,0,0,0,0,0,0,0,0,0,0,0
0,7,3,3,3,3,3,3,3,3,3,3,3,3,3,3,3,3,3,3,0,0,0
0,1,4,1,1,1,1,1,1,5,6,1,1,1,1,1,1,6,1,3,7,0,0
0,3,3,1,1,1,1,1,1,1,1,1,1,1,1,1,1,1,1,1,3,3,0
0,3,3,3,3,3,1,1,1,1,1,1,1,1,1,1,1,1,1,1,1,3,0
0,3,3,3,3,3,3,3,1,1,1,1,1,1,1,1,1,1,1,1,1,3,0
0,3,1,3,3,3,3,3,1,1,1,1,1,1,1,1,1,1,1,1,1,3,0
0,3,3,3,3,3,3,3,3,1,1,1,1,1,1,1,1,1,1,1,1,3,0
0,3,3,3,3,3,3,3,3,1,1,1,1,1,1,1,1,1,1,1,1,3,0
0,3,5,3,3,3,3,3,3,5,5,1,1,1,1,1,1,5,1,1,1,3,0
0,3,5,3,3,3,3,3,3,5,5,1,1,1,1,1,1,5,1,1,1,3,0
0,3,3,3,3,3,1,1,1,1,3,1,1,1,1,1,1,1,1,1,1,3,0
0,0,3,3,3,1,1,1,2,2,2,3,1,1,1,1,1,1,1,1,1,3,0
0,0,3,3,3,1,1,1,2,8,2,3,1,1,1,1,1,1,1,1,1,3,0
0,0,0,3,3,1,1,1,2,2,2,3,1,1,1,1,1,1,1,1,1,3,0
0,0,9,0,3,3,3,1,1,1,1,1,1,1,1,1,1,1,1,1,1,3,0
0,0,0,0,3,1,3,1,1,1,1,1,1,1,1,1,1,1,1,1,3,3,0
0,0,7,0,0,3,3,3,3,4,6,1,1,3,3,1,1,4,1,3,3,0,0
0,0,0,0,0,7,3,3,3,3,3,3,3,3,3,3,3,3,3,3,7,0,0
0,0,0,0,0,0,0,0,0,0,0,0,0,0,0,0,0,0,0,0,0,0,0
:endlayer
layer: 5
0,0,0,0,0,0,0,0,0,0,0,0,0,0,0,0,0,0,0,0,0,0,0
0,7,0,0,0,0,0,0,0,0,0,0,0,0,0,0,0,0,0,0,0,0,0
0,3,4,3,3,3,3,3,3,6,4,3,3,3,3,3,3,4,3,0,0,0,0
0,0,0,3,3,3,3,3,3,3,3,3,3,3,3,3,3,3,3,3,0,0,0
0,0,0,0,0,0,3,3,3,3,3,3,3,3,3,3,3,3,3,3,3,0,0
0,0,0,0,0,0,0,0,3,3,3,3,3,3,3,3,3,3,3,3,3,0,0
0,0,13,0,0,0,0,0,3,3,3,3,3,3,3,3,3,3,3,3,3,0,0
0,0,0,0,0,0,0,0,0,3,3,3,1,3,3,3,3,3,3,3,3,0,0
0,0,0,0,0,0,9,0,0,3,3,3,3,3,3,3,3,3,3,3,3,0,0
0,0,5,0,0,0,0,0,0,3,5,3,3,3,3,3,3,5,3,3,3,0,0
0,0,6,0,0,0,0,0,0,5,1,1,1,1,3,3,3,6,3,3,3,0,0
0,0,0,0,9,0,3,13,3,3,10,2,1,1,1,3,3,3,3,3,3,0,0
0,0,9,0,9,3,3,3,12,0,0,0,1,1,1,3,3,3,3,3,3,0,0
0,0,9,9,9,3,3,1,0,11,0,0,3,3,1,3,1,3,3,3,3,0,0
0,0,0,9,9,3,3,1,0,0,0,0,3,3,1,3,3,3,3,3,3,0,0
0,0,0,0,0,9,0,1,1,3,3,3,1,1,1,3,3,3,3,3,3,0,0
0,0,0,0,0,13,9,3,3,1,1,1,1,1,7,1,3,3,3,3,0,0,0
0,0,5,0,0,9,0,0,9,6,4,3,3,0,9,3,3,6,3,0,0,0,0
0,0,0,0,0,7,0,9,0,0,0,0,0,0,9,0,0,0,0,0,7,0,0
0,0,0,0,0,0,0,0,0,0,0,0,0,0,0,0,0,0,0,0,0,0,0
:endlayer
layer: 6
0,0,0,0,0,0,0,0,0,0,0,0,0,0,0,0,0,0,0,0,0,0,0
0,6,0,0,0,0,0,0,0,0,0,0,0,0,0,0,0,0,0,0,0,0,0
0,0,0,0,0,9,9,9,9,4,4,0,9,0,9,9,0,5,9,0,0,0,0
0,0,0,0,0,0,9,9,9,9,9,9,0,9,9,0,9,0,0,0,0,0,0
0,20,20,20,20,0,0,9,0,9,0,0,9,9,9,9,0,0,0,0,0,0,0
0,20,20,20,20,0,0,0,0,0,9,9,9,9,9,0,0,0,0,0,0,0,0
0,20,13,20,20,0,0,0,0,0,0,0,0,9,0,9,0,0,0,0,0,0,0
0,20,20,20,20,0,0,0,0,9,0,9,13,0,0,9,9,9,0,0,0,0,0
0,20,20,20,20,0,0,0,0,0,0,9,9,9,9,0,0,0,0,0,0,0,0
0,0,4,0,0,0,0,0,0,0,5,0,9,9,9,9,9,5,9,0,0,0,0
0,0,6,0,0,0,0,0,0,5,1,3,14,14,9,9,9,6,0,0,0,0,0
0,0,0,0,0,0,0,13,0,0,0,18,1,1,14,9,0,0,9,0,0,0,0
0,0,0,0,0,0,0,0,0,0,0,0,15,15,1,0,0,9,0,0,0,0,0
0,0,0,0,0,0,0,3,0,0,0,0,17,16,1,0,13,0,0,0,0,0,0
0,0,0,0,0,0,0,3,0,0,0,0,15,15,1,0,0,0,0,0,0,0,0
0,0,0,0,0,0,0,3,3,19,0,0,1,1,14,0,0,0,0,0,0,0,0
0,0,0,0,0,13,0,0,0,3,3,3,14,14,0,13,0,0,0,0,0,0,0
0,0,5,0,0,0,0,0,0,4,6,0,0,0,0,0,0,4,0,0,0,0,0
0,0,0,0,0,0,0,0,0,0,0,0,0,0,0,0,0,0,0,0,7,0,0
0,0,0,0,0,0,0,0,0,0,0,0,0,0,0,0,0,0,0,0,0,0,0
:endlayer
layer: 7
0,0,0,0,0,0,0,0,0,0,0,0,0,0,0,0,0,0,0,0,0,0,0
0,0,0,0,0,0,0,0,0,0,0,0,0,0,0,0,0,0,0,0,0,0,0
0,0,0,0,0,0,0,0,0,6,5,0,0,0,0,0,0,5,0,0,0,0,0
0,0,0,0,0,0,0,0,0,0,0,0,0,0,0,0,0,0,0,0,0,0,0
0,20,20,20,0,0,0,0,0,0,0,0,0,0,0,0,0,0,0,0,0,0,0
0,20,20,20,20,0,0,0,0,0,0,0,0,0,0,0,0,0,0,0,0,0,0
0,20,13,20,20,0,0,0,0,0,0,0,0,0,0,0,0,0,0,0,0,0,0
0,20,20,20,20,0,0,0,0,0,0,0,13,0,0,0,0,0,0,0,0,0,0
0,20,20,20,20,0,0,0,0,0,0,0,0,0,0,0,0,0,0,0,0,0,0
0,0,6,0,0,0,0,0,0,0,5,0,0,0,0,0,0,5,0,0,0,0,0
0,0,4,0,0,0,0,0,0,6,5,0,0,0,0,0,0,4,0,0,0,0,0
0,0,0,0,0,0,0,13,0,0,0,0,14,14,0,0,0,0,0,0,0,0,0
0,0,0,0,0,0,0,0,0,0,0,0,0,0,14,0,0,0,0,0,0,0,0
0,0,0,0,0,0,0,0,0,0,0,0,0,0,14,0,13,0,0,0,0,0,0
0,0,0,0,0,0,0,0,0,0,0,0,0,0,14,0,0,0,0,0,0,0,0
0,0,0,0,0,0,0,0,0,0,0,0,14,14,0,0,0,0,0,0,0,0,0
0,0,0,0,0,13,0,0,0,0,0,0,0,0,0,13,0,0,0,0,0,0,0
0,0,7,0,0,0,0,0,0,4,4,0,0,0,0,0,0,6,0,0,0,0,0
0,0,0,0,0,0,0,0,0,0,0,0,0,0,0,0,0,0,0,0,0,0,0
0,0,0,0,0,0,0,0,0,0,0,0,0,0,0,0,0,0,0,0,0,0,0
:endlayer
layer: 8
0,0,0,0,0,0,0,0,0,0,0,0,0,0,0,0,0,0,0,0,0,0,0
0,0,0,0,0,0,0,0,0,0,0,0,0,0,0,0,0,0,0,0,0,0,0
0,0,0,0,0,0,0,0,0,6,5,0,0,0,0,0,0,5,0,0,0,0,0
0,0,0,0,0,0,0,0,0,0,0,0,0,0,0,0,0,0,0,0,0,0,0
0,0,0,0,0,0,0,0,0,0,0,0,0,0,0,0,0,0,0,0,0,0,0
0,0,20,20,0,0,0,0,0,0,0,0,0,0,0,0,0,0,0,0,0,0,0
0,20,13,20,0,0,0,0,0,0,0,0,0,0,0,0,0,0,0,0,0,0,0
0,20,20,0,0,0,0,0,0,0,0,0,13,0,0,0,0,0,0,0,0,0,0
0,0,0,0,0,0,0,0,0,0,0,20,20,20,0,0,0,0,0,0,0,0,0
0,0,5,0,0,20,20,20,20,0,4,0,20,0,0,0,0,5,0,0,0,0,0
0,0,4,0,0,20,20,20,20,4,4,0,0,0,0,0,0,4,0,0,0,0,0
0,0,0,0,0,20,20,13,0,0,0,0,0,0,0,0,0,0,0,0,0,0,0
0,0,0,0,0,20,20,0,0,0,0,0,14,14,14,0,0,0,0,0,0,0,0
0,0,0,0,0,20,20,20,0,0,0,0,0,0,14,0,13,0,0,0,0,0,0
0,0,0,0,20,20,20,0,0,0,0,0,14,14,14,0,0,0,0,0,0,0,0
0,0,0,20,20,20,20,20,0,0,0,0,0,0,0,0,0,0,0,0,0,0,0
0,0,0,20,20,13,20,20,0,0,0,0,0,0,0,13,0,0,0,0,0,0,0
0,0,21,20,20,20,20,20,0,5,5,0,0,0,0,0,0,5,0,0,0,0,0
0,0,0,20,20,20,20,0,0,0,0,0,0,0,0,0,0,0,0,0,0,0,0
0,0,0,0,0,0,0,0,0,0,0,0,0,0,0,0,0,0,0,0,0,0,0
:endlayer
layer: 9
0,0,0,0,0,0,0,0,0,0,0,0,0,0,0,0,0,0,0,0,0,0,0
0,0,0,0,0,0,0,0,0,0,0,0,0,0,0,0,0,0,0,0,0,0,0
0,0,0,0,0,0,0,0,0,6,5,0,0,0,0,0,0,5,0,0,0,0,0
0,0,0,0,0,0,0,0,0,0,0,0,0,0,0,0,0,0,0,0,0,0,0
0,0,0,0,0,0,0,0,0,0,0,0,0,0,0,0,0,0,0,0,0,0,0
0,0,20,0,0,0,0,0,0,0,0,0,0,0,0,0,0,0,0,0,0,0,0
0,20,20,20,0,0,0,0,0,0,0,20,20,20,0,0,0,0,0,0,0,0,0
0,0,20,0,0,0,0,0,0,0,20,20,13,20,20,0,0,0,0,0,0,0,0
0,0,0,0,0,0,0,0,0,0,20,22,20,20,20,0,0,0,0,0,0,0,0
0,0,6,0,0,20,20,20,20,0,4,20,20,20,20,0,0,5,0,0,0,0,0
0,0,4,0,0,20,20,20,20,4,4,20,20,20,0,0,0,4,0,0,0,0,0
0,0,0,0,0,20,20,13,20,20,0,0,0,0,0,0,0,0,0,0,0,0,0
0,0,0,0,0,20,20,20,0,0,0,0,0,0,0,0,0,0,0,0,0,0,0
0,0,0,0,0,0,20,20,20,0,0,0,14,14,14,0,13,0,0,0,0,0,0
0,0,0,0,20,20,20,20,0,0,0,0,0,0,0,0,20,0,20,0,0,0,0
0,0,0,20,20,20,20,20,0,0,0,0,0,0,0,20,20,20,20,20,0,0,0
0,0,0,20,20,13,20,20,0,0,0,0,20,0,0,13,20,0,20,0,0,0,0
0,0,5,20,20,20,20,20,0,5,4,0,0,20,0,0,0,6,0,0,0,0,0
0,0,0,20,20,20,20,20,0,0,0,0,0,0,20,0,0,0,0,0,0,0,0
0,0,0,0,0,0,0,0,0,0,0,0,0,0,0,0,0,0,0,0,0,0,0
:endlayer
layer: 10
0,0,0,0,0,0,0,0,0,0,0,0,0,0,0,0,0,0,0,0,0,0,0
0,0,0,0,0,0,0,0,0,0,0,0,0,0,0,0,0,0,0,0,0,0,0
0,0,0,0,0,0,0,0,0,7,6,0,0,0,0,0,0,5,0,0,0,0,0
0,0,0,0,0,0,0,0,0,0,0,0,0,0,0,0,0,0,0,0,0,0,0
0,0,0,0,0,0,0,0,0,0,0,0,0,0,0,0,0,0,0,0,0,0,0
0,0,0,0,0,0,0,0,0,0,0,0,0,0,0,0,0,0,0,0,0,0,0
0,0,0,0,0,0,0,0,0,0,20,20,20,20,0,0,0,0,0,0,0,0,0
0,0,0,0,0,0,0,0,0,20,20,20,13,20,20,0,0,0,0,0,0,0,0
0,0,0,0,0,0,0,0,0,20,20,20,20,22,20,0,0,0,0,0,0,0,0
0,0,4,0,0,0,0,0,0,20,5,20,20,23,20,0,0,5,0,0,0,0,0
0,0,4,0,0,0,20,20,20,6,6,20,20,20,0,0,0,5,0,0,0,0,0
0,0,0,0,0,0,20,13,20,0,0,0,0,0,0,0,0,0,0,0,0,0,0
0,0,0,0,0,0,0,20,0,0,0,0,0,0,0,20,0,0,0,0,0,0,0
0,0,0,0,0,0,0,24,24,0,0,0,0,0,20,22,13,22,22,20,0,0,0
0,0,0,0,0,0,0,0,0,0,0,20,20,0,20,20,20,20,22,20,20,0,0
0,0,0,0,0,20,0,0,0,0,0,0,20,20,20,20,22,20,20,20,20,0,0
0,0,0,0,20,13,20,0,0,0,0,20,20,20,20,13,20,20,20,20,20,0,0
0,0,5,0,20,20,0,0,0,5,5,0,20,20,20,20,20,4,20,20,0,0,0
0,0,0,0,0,0,0,0,0,0,0,0,0,20,20,20,0,0,0,0,0,0,0
0,0,0,0,0,0,0,0,0,0,0,0,0,0,0,0,0,0,0,0,0,0,0
:endlayer
layer: 11
0,0,0,0,0,0,0,0,0,0,0,0,0,0,0,0,0,0,0,0,0,0,0
0,0,0,0,0,0,0,0,0,0,0,0,0,0,0,0,0,0,0,0,0,0,0
0,0,0,0,0,0,0,0,0,0,6,0,0,0,0,0,0,5,0,0,0,0,0
0,0,0,0,0,0,0,0,0,0,0,0,0,0,0,0,0,0,0,0,0,0,0
0,0,0,0,0,0,0,0,0,0,0,0,0,0,0,0,0,0,0,0,0,0,0
0,0,0,0,0,0,0,0,0,0,0,0,0,0,0,0,0,0,0,0,0,0,0
0,0,0,0,0,0,0,0,0,0,20,20,20,0,0,0,0,0,0,0,0,0,0
0,0,0,0,0,0,0,0,0,20,20,20,13,20,20,0,0,0,0,0,0,0,0
0,0,0,0,0,0,0,0,0,20,20,20,20,20,20,20,0,0,0,0,0,0,0
0,0,0,0,0,0,0,0,0,20,5,20,20,20,20,20,0,5,0,0,0,0,0
0,0,6,0,0,0,0,20,0,5,5,20,20,20,20,20,0,5,0,0,0,0,0
0,0,0,0,0,0,20,20,20,0,0,0,20,20,20,20,20,0,0,0,0,0,0
0,0,0,0,0,0,0,20,0,0,0,0,0,20,20,20,20,20,0,20,0,0,0
0,0,0,0,0,0,0,24,24,0,0,0,0,20,20,20,13,20,20,22,20,0,0
0,0,0,0,0,0,0,0,0,0,20,20,20,20,23,23,20,20,20,22,20,0,0
0,0,0,0,0,20,0,0,0,0,0,20,20,20,20,23,22,20,20,20,20,0,0
0,0,0,0,20,20,20,0,0,0,0,20,20,20,20,13,20,20,20,20,20,0,0
0,0,4,0,0,20,0,0,0,4,5,0,20,20,20,20,20,4,20,20,0,0,0
0,0,0,0,0,0,0,0,0,0,0,0,0,20,20,20,0,0,0,0,0,0,0
0,0,0,0,0,0,0,0,0,0,0,0,0,0,0,0,0,0,0,0,0,0,0
:endlayer
layer: 12
0,0,0,0,0,0,0,0,0,0,0,0,0,0,0,0,0,0,0,0,0,0,0
0,0,0,0,0,0,0,0,0,0,0,0,0,0,0,0,0,0,0,0,0,0,0
0,0,0,0,0,0,0,0,0,0,5,0,0,0,0,0,0,5,0,0,0,0,0
0,0,0,0,0,0,0,0,0,0,0,0,0,0,0,0,0,0,0,0,0,0,0
0,0,0,0,0,0,0,0,0,0,0,0,0,0,0,0,0,0,0,0,0,0,0
0,0,0,0,0,0,0,0,0,0,0,0,0,0,0,0,0,0,0,0,0,0,0
0,0,0,0,0,0,0,0,0,0,0,0,20,0,0,0,0,0,0,0,0,0,0
0,0,0,0,0,0,0,0,0,0,0,20,13,20,20,0,0,0,0,0,0,0,0
0,0,0,0,0,0,0,0,0,0,20,20,20,20,20,20,0,0,0,0,0,0,0
0,0,0,0,0,0,0,0,0,0,5,20,20,20,20,20,0,4,0,0,0,0,0
0,0,6,0,0,0,0,0,0,5,5,20,20,20,20,20,0,4,0,0,0,0,0
0,0,0,0,0,0,0,0,0,24,24,24,20,20,20,20,20,0,20,20,20,0,0
0,0,0,0,0,0,0,0,24,24,0,24,24,20,20,20,20,20,20,20,20,20,0
0,0,0,0,0,0,0,24,24,24,24,24,20,20,20,23,13,20,20,20,20,20,0
0,0,0,0,0,0,0,24,24,24,0,0,20,20,20,20,20,20,20,20,20,20,0
0,0,0,0,0,0,0,0,24,24,24,20,20,20,20,23,20,22,20,20,20,20,0
0,0,0,0,0,0,0,0,0,0,0,20,20,20,20,13,22,20,20,20,20,0,0
0,0,6,0,0,0,0,0,0,4,4,0,20,20,20,20,20,5,0,0,0,0,0
0,0,0,0,0,0,0,0,0,0,0,0,0,20,20,20,0,0,0,0,0,0,0
0,0,0,0,0,0,0,0,0,0,0,0,0,0,0,0,0,0,0,0,0,0,0
:endlayer
layer: 13
0,0,0,0,0,0,0,0,0,0,0,0,0,0,0,0,0,0,0,0,0,0,0
0,0,0,0,0,0,0,0,0,0,0,0,0,0,0,0,0,0,0,0,0,0,0
0,0,0,0,0,0,0,0,0,0,5,28,0,0,0,0,27,4,0,0,0,0,0
0,0,0,0,0,0,0,0,0,0,25,0,0,0,0,0,0,25,0,0,0,0,0
0,0,0,0,0,0,0,0,0,0,0,0,0,0,0,0,0,0,0,0,0,0,0
0,0,0,0,0,0,0,0,0,0,0,20,20,20,0,0,0,0,0,0,0,0,0
0,0,0,0,0,0,0,0,0,0,20,20,20,20,20,0,0,0,0,0,0,0,0
0,0,0,0,0,0,0,0,0,0,20,20,20,20,20,0,0,0,0,0,0,0,0
0,0,0,0,0,0,0,0,0,0,26,20,20,20,20,0,0,26,0,0,0,0,0
0,0,0,0,0,0,0,0,0,0,5,28,20,20,20,0,27,5,0,0,0,0,0
0,0,6,28,0,0,0,0,27,5,5,28,0,20,0,0,27,7,0,0,0,0,0
0,0,25,0,0,0,0,0,0,25,25,0,0,0,20,20,20,25,20,20,20,0,0
0,0,0,0,0,0,0,0,0,0,0,0,0,20,20,20,20,20,20,20,20,20,0
0,0,0,0,0,0,0,0,0,29,0,0,20,20,20,20,13,20,20,20,20,20,0
0,0,0,0,0,0,0,0,0,0,0,0,20,20,20,20,20,20,20,20,20,20,0
0,0,0,0,0,0,0,0,0,0,0,0,20,22,22,20,20,20,22,20,20,20,0
0,0,26,0,0,0,0,0,0,26,26,0,0,20,20,13,22,26,20,20,20,0,0
0,0,7,28,0,0,0,0,27,4,6,28,0,0,20,20,27,5,0,0,0,0,0
0,0,0,0,0,0,0,0,0,0,0,0,0,0,0,0,0,0,0,0,0,0,0
0,0,0,0,0,0,0,0,0,0,0,0,0,0,0,0,0,0,0,0,0,0,0
:endlayer
layer: 14
0,0,0,0,0,0,0,0,0,0,0,0,0,0,0,0,0,0,0,0,0,0,0
0,0,0,0,0,0,0,0,0,0,0,0,0,0,0,0,0,0,0,0,0,0,0
0,0,0,0,0,0,0,0,0,0,4,5,28,0,0,27,6,4,0,0,0,0,0
0,0,0,0,0,0,0,0,0,0,6,0,0,0,0,0,0,6,0,0,0,0,0
0,0,0,0,0,0,0,0,0,0,25,0,0,0,0,0,0,25,0,0,0,0,0
0,0,0,0,0,0,0,0,0,0,0,20,20,20,0,0,0,0,0,0,0,0,0
0,0,0,0,0,0,0,0,0,0,20,20,20,20,20,0,0,0,0,0,0,0,0
0,0,0,0,0,0,0,0,0,0,26,20,20,20,20,0,0,26,0,0,0,0,0
0,0,0,0,0,0,0,0,0,0,5,20,20,20,20,0,0,5,0,0,0,0,0
0,0,0,0,0,0,0,0,0,0,7,4,28,20,0,27,5,7,0,0,0,0,0
0,0,4,7,28,0,0,27,4,6,4,6,28,0,0,27,5,5,0,0,0,0,0
0,0,5,0,0,0,0,0,0,5,4,0,0,0,0,20,20,5,0,0,0,0,0
0,0,25,0,0,0,0,0,0,25,25,0,0,20,20,20,20,25,20,20,0,0,0
0,0,0,0,0,0,0,0,0,0,0,0,20,20,20,20,20,20,20,20,20,0,0
0,0,0,0,0,0,0,0,0,0,0,20,22,20,20,20,20,20,20,20,20,0,0
0,0,26,0,0,0,0,0,0,26,26,0,20,22,20,20,20,26,20,20,20,0,0
0,0,5,0,0,0,0,0,0,6,4,0,0,20,22,13,20,5,20,20,20,0,0
0,0,5,6,28,0,0,27,5,4,6,4,28,0,20,27,5,5,20,20,0,0,0
0,0,0,0,0,0,0,0,0,0,0,0,0,0,0,20,20,0,0,0,0,0,0
0,0,0,0,0,0,0,0,0,0,0,0,0,0,0,0,0,0,0,0,0,0,0
:endlayer
layer: 15
0,0,0,0,0,0,0,0,0,0,0,0,0,0,0,0,0,0,0,0,0,0,0
0,0,0,0,0,0,0,0,0,0,0,0,0,0,0,0,0,0,0,0,0,0,0
0,0,0,0,0,0,0,0,0,0,30,0,31,0,0,31,0,30,0,0,0,0,0
0,0,0,0,0,0,0,0,0,0,0,0,0,0,0,0,0,30,0,0,0,0,0
0,0,0,0,0,0,0,0,0,0,31,0,0,0,0,0,0,31,0,0,0,0,0
0,0,0,0,0,0,0,0,0,0,31,0,0,0,0,0,0,0,0,0,0,0,0
0,0,0,0,0,0,0,0,0,0,0,0,20,0,0,0,0,31,0,0,0,0,0
0,0,0,0,0,0,0,0,0,0,30,20,20,20,0,0,0,31,0,0,0,0,0
0,0,0,0,0,0,0,0,0,0,31,0,20,0,0,0,0,31,0,0,0,0,0
0,0,0,0,0,0,0,0,0,0,5,31,0,31,0,0,31,31,0,0,0,0,0
0,0,21,0,30,31,31,0,0,31,31,0,31,0,0,0,31,30,0,0,0,0,0
0,0,0,0,0,0,0,0,0,31,31,0,0,0,0,0,20,0,0,0,0,0,0
0,0,0,0,0,0,0,0,0,31,31,20,20,20,0,20,20,20,0,0,0,0,0
0,0,0,0,0,0,0,0,0,0,30,20,20,20,20,20,20,20,20,20,0,0,0
0,0,0,0,0,0,0,0,0,0,30,20,20,20,20,20,20,20,20,20,20,0,0
0,0,0,0,0,0,0,0,0,0,20,20,20,20,20,20,20,20,20,20,20,0,0
0,0,0,0,0,0,0,0,0,31,31,20,20,20,20,13,20,31,20,20,0,0,0
0,0,31,30,31,0,0,0,0,4,31,30,20,20,31,20,20,31,20,0,0,0,0
0,0,0,0,0,0,0,0,0,0,0,0,0,0,0,20,20,20,0,0,0,0,0
0,0,0,0,0,0,0,0,0,0,0,0,0,0,0,0,0,0,0,0,0,0,0
:endlayer
layer: 16
0,0,0,0,0,0,0,0,0,0,0,0,0,0,0,0,0,0,0,0,0,0,0
0,0,0,0,0,0,0,0,0,0,0,0,0,0,0,0,0,0,0,0,0,0,0
0,0,0,0,0,0,0,0,0,0,0,0,0,0,0,0,0,0,0,0,0,0,0
0,0,0,0,0,0,0,0,0,0,0,0,0,0,0,0,0,0,0,0,0,0,0
0,0,0,0,0,0,0,0,0,0,0,0,0,0,0,0,0,0,0,0,0,0,0
0,0,0,0,0,0,0,0,0,0,0,0,0,0,0,0,0,0,0,0,0,0,0
0,0,0,0,0,0,0,0,0,0,0,0,0,0,0,0,0,0,0,0,0,0,0
0,0,0,0,0,0,0,0,0,0,0,0,0,0,0,0,0,0,0,0,0,0,0
0,0,0,0,0,0,0,0,0,0,0,0,0,0,0,0,0,0,0,0,0,0,0
0,0,0,0,0,0,0,0,0,0,0,0,0,0,0,0,0,0,0,0,0,0,0
0,0,0,0,0,0,0,0,0,0,0,0,0,0,0,0,0,0,0,0,0,0,0
0,0,0,0,0,0,0,0,0,0,32,0,0,0,0,0,0,0,0,0,0,0,0
0,0,0,0,0,0,0,0,0,0,0,0,20,0,0,0,20,0,0,0,0,0,0
0,0,0,0,0,0,0,0,0,0,0,20,20,20,0,20,20,20,0,0,0,0,0
0,0,0,0,0,0,0,0,0,0,20,20,20,20,20,20,20,0,20,0,0,0,0
0,0,0,0,0,0,0,0,0,0,0,20,20,20,20,20,20,20,20,20,0,0,0
0,0,0,0,0,0,0,0,0,0,0,0,20,20,20,20,20,20,20,0,0,0,0
0,0,0,0,0,0,0,0,0,0,0,0,0,20,20,20,20,20,0,0,0,0,0
0,0,0,0,0,0,0,0,0,0,0,0,0,0,20,20,20,0,0,0,0,0,0
0,0,0,0,0,0,0,0,0,0,0,0,0,0,0,0,0,0,0,0,0,0,0
:endlayer
layer: 17
0,0,0,0,0,0,0,0,0,0,0,0,0,0,0,0,0,0,0,0,0,0,0
0,0,0,0,0,0,0,0,0,0,0,0,0,0,0,0,0,0,0,0,0,0,0
0,0,0,0,0,0,0,0,0,0,0,0,0,0,0,0,0,0,0,0,0,0,0
0,0,0,0,0,0,0,0,0,0,0,0,0,0,0,0,0,0,0,0,0,0,0
0,0,0,0,0,0,0,0,0,0,0,0,0,0,0,0,0,0,0,0,0,0,0
0,0,0,0,0,0,0,0,0,0,0,0,0,0,0,0,0,0,0,0,0,0,0
0,0,0,0,0,0,0,0,0,0,0,0,0,0,0,0,0,0,0,0,0,0,0
0,0,0,0,0,0,0,0,0,0,0,0,0,0,0,0,0,0,0,0,0,0,0
0,0,0,0,0,0,0,0,0,0,0,0,0,0,0,0,0,0,0,0,0,0,0
0,0,0,0,0,0,0,0,0,0,0,0,0,0,0,0,0,0,0,0,0,0,0
0,0,0,0,0,0,0,0,0,0,0,0,0,0,0,0,0,0,0,0,0,0,0
0,0,0,0,0,0,0,0,0,0,0,0,0,0,0,0,0,0,0,0,0,0,0
0,0,0,0,0,0,0,0,0,0,0,0,0,0,0,0,0,0,0,0,0,0,0
0,0,0,0,0,0,0,0,0,0,0,0,20,0,0,0,0,0,0,0,0,0,0
0,0,0,0,0,0,0,0,0,0,0,20,20,20,0,20,0,0,0,0,0,0,0
0,0,0,0,0,0,0,0,0,0,0,0,20,20,20,20,20,0,0,0,0,0,0
0,0,0,0,0,0,0,0,0,0,0,0,0,20,20,20,20,20,0,0,0,0,0
0,0,0,0,0,0,0,0,0,0,0,0,0,0,20,20,20,0,0,0,0,0,0
0,0,0,0,0,0,0,0,0,0,0,0,0,0,0,20,0,0,0,0,0,0,0
0,0,0,0,0,0,0,0,0,0,0,0,0,0,0,0,0,0,0,0,0,0,0
:endlayer
layer: 18
0,0,0,0,0,0,0,0,0,0,0,0,0,0,0,0,0,0,0,0,0,0,0
0,0,0,0,0,0,0,0,0,0,0,0,0,0,0,0,0,0,0,0,0,0,0
0,0,0,0,0,0,0,0,0,0,0,0,0,0,0,0,0,0,0,0,0,0,0
0,0,0,0,0,0,0,0,0,0,0,0,0,0,0,0,0,0,0,0,0,0,0
0,0,0,0,0,0,0,0,0,0,0,0,0,0,0,0,0,0,0,0,0,0,0
0,0,0,0,0,0,0,0,0,0,0,0,0,0,0,0,0,0,0,0,0,0,0
0,0,0,0,0,0,0,0,0,0,0,0,0,0,0,0,0,0,0,0,0,0,0
0,0,0,0,0,0,0,0,0,0,0,0,0,0,0,0,0,0,0,0,0,0,0
0,0,0,0,0,0,0,0,0,0,0,0,0,0,0,0,0,0,0,0,0,0,0
0,0,0,0,0,0,0,0,0,0,0,0,0,0,0,0,0,0,0,0,0,0,0
0,0,0,0,0,0,0,0,0,0,0,0,0,0,0,0,0,0,0,0,0,0,0
0,0,0,0,0,0,0,0,0,0,0,0,0,0,0,0,0,0,0,0,0,0,0
0,0,0,0,0,0,0,0,0,0,0,0,0,0,0,0,0,0,0,0,0,0,0
0,0,0,0,0,0,0,0,0,0,0,0,0,0,0,0,0,0,0,0,0,0,0
0,0,0,0,0,0,0,0,0,0,0,0,0,0,0,0,0,0,0,0,0,0,0
0,0,0,0,0,0,0,0,0,0,0,0,0,0,0,20,0,0,0,0,0,0,0
0,0,0,0,0,0,0,0,0,0,0,0,0,0,20,20,20,0,0,0,0,0,0
0,0,0,0,0,0,0,0,0,0,0,0,0,0,0,20,0,0,0,0,0,0,0
0,0,0,0,0,0,0,0,0,0,0,0,0,0,0,0,0,0,0,0,0,0,0
0,0,0,0,0,0,0,0,0,0,0,0,0,0,0,0,0,0,0,0,0,0,0
:endlayer

#### RULES ####
rule:
plugin=vanillaBlocks
number=1
data:
JSON:{blockState:{blockName:"minecraft:dirt",properties:{variant:"dirt",snowy:"false"}}}
:enddata
:endrule

rule:
plugin=vanillaBlocks
number=2
data:
JSON:{blockState:{blockName:"minecraft:cobblestone"}}
:enddata
:endrule

rule:
plugin=vanillaBlocks
number=3
data:
JSON:{blockState:{blockName:"minecraft:grass",properties:{snowy:"false"}}}
:enddata
:endrule

rule:
plugin=vanillaBlocks
number=4
data:
JSON:{blockState:{blockName:"minecraft:monster_egg",properties:{variant:"stone_brick"}}}
:enddata
:endrule

rule:
plugin=vanillaBlocks
number=5
data:
JSON:{blockState:{blockName:"minecraft:stonebrick",properties:{variant:"mossy_stonebrick"}}}
:enddata
:endrule

rule:
plugin=vanillaBlocks
number=6
data:
JSON:{blockState:{blockName:"minecraft:stonebrick",properties:{variant:"stonebrick"}}}
:enddata
:endrule

rule:
plugin=vanillaBlocks
number=7
data:
JSON:{blockState:{blockName:"minecraft:stonebrick",properties:{variant:"cracked_stonebrick"}}}
:enddata
:endrule

rule:
plugin=vanillaBlocks
number=8
data:
JSON:{blockState:{blockName:"ancientwarfarestructure:fire_pit",properties:{lit:"true",variant:"default"}}}
:enddata
:endrule

rule:
plugin=vanillaBlocks
number=9
data:
JSON:{blockState:{blockName:"minecraft:tallgrass",properties:{type:"tall_grass"}}}
:enddata
:endrule

rule:
plugin=inventory
number=10
data:
JSON:{blockState:{blockName:"minecraft:chest",properties:{facing:"south"}},lootLevel:0,teData:{ForgeData:{},Items:[],id:"minecraft:chest",Lock:""},inventoryData:{length:0,inventoryContents:[]},legacyFeatures:1b}
:enddata
:endrule

rule:
plugin=vanillaBlocks
number=11
data:
JSON:{blockState:{blockName:"minecraft:cauldron",properties:{level:"3"}}}
:enddata
:endrule

rule:
plugin=blockTile
number=12
data:
JSON:{blockState:{blockName:"ancientwarfarestructure:advanced_spawner",properties:{transparent:"true"}},teData:{id:"ancientwarfarestructure:advanced_spawner_tile",spawnerSettings:{minDelay:0,spawnDelay:0,lightSensitive:0b,spawnGroups:[{settingsList:[{remainingSpawnCount:1,hostile:1b,forced:1b,customTag:{factionName:"brigand"},maxToSpawn:1,entityId:"ancientwarfarenpc:faction.soldier",minToSpawn:1}],groupWeight:1}],playerRange:16,respondToRedstone:0b,inventory:{Size:9,Items:[]},spawnRange:0,transparent:1b,maxDelay:0,xpToDrop:0,mobRange:0,debugMode:0b,maxNearbyMonsters:0}}}
:enddata
:endrule

rule:
plugin=vanillaBlocks
number=13
data:
JSON:{blockState:{blockName:"minecraft:log",properties:{variant:"oak",axis:"y"}}}
:enddata
:endrule

rule:
plugin=vanillaBlocks
number=14
data:
JSON:{blockState:{blockName:"minecraft:wool",properties:{color:"green"}}}
:enddata
:endrule

rule:
plugin=vanillaBlocks
number=15
data:
JSON:{blockState:{blockName:"minecraft:wooden_slab",properties:{half:"bottom",variant:"oak"}}}
:enddata
:endrule

rule:
plugin=blockTile
number=16
data:
JSON:{blockState:{blockName:"ancientwarfarestructure:advanced_spawner",properties:{transparent:"true"}},teData:{id:"ancientwarfarestructure:advanced_spawner_tile",spawnerSettings:{minDelay:0,spawnDelay:0,lightSensitive:0b,spawnGroups:[{settingsList:[{remainingSpawnCount:1,hostile:1b,forced:1b,customTag:{factionName:"brigand"},maxToSpawn:1,entityId:"ancientwarfarenpc:faction.soldier",minToSpawn:1}],groupWeight:1}],playerRange:16,respondToRedstone:0b,inventory:{Size:9,Items:[]},spawnRange:0,transparent:1b,maxDelay:0,xpToDrop:0,mobRange:0,debugMode:0b,maxNearbyMonsters:0}}}
:enddata
:endrule

rule:
plugin=blockTile
number=17
data:
JSON:{blockState:{blockName:"ancientwarfarestructure:advanced_spawner",properties:{transparent:"true"}},teData:{id:"ancientwarfarestructure:advanced_spawner_tile",spawnerSettings:{minDelay:0,spawnDelay:0,lightSensitive:0b,spawnGroups:[{settingsList:[{remainingSpawnCount:1,hostile:1b,forced:1b,customTag:{factionName:"brigand"},maxToSpawn:1,entityId:"ancientwarfarenpc:faction.soldier",minToSpawn:1}],groupWeight:1}],playerRange:16,respondToRedstone:0b,inventory:{Size:9,Items:[]},spawnRange:0,transparent:1b,maxDelay:0,xpToDrop:0,mobRange:0,debugMode:0b,maxNearbyMonsters:0}}}
:enddata
:endrule

rule:
plugin=blockTile
number=18
data:
JSON:{blockState:{blockName:"ancientwarfarestructure:advanced_loot_chest",properties:{facing:"south"}},teData:{LootTable:"ancientwarfare:inject/chests/simple_dungeon",lootRolls:1b,id:"ancientwarfarestructure:advanced_loot_chest_tile",Lock:"",LootTableSeed:-3690245904559431258L}}
:enddata
:endrule

rule:
plugin=blockTile
number=19
data:
JSON:{blockState:{blockName:"ancientwarfarestructure:advanced_spawner",properties:{transparent:"true"}},teData:{id:"ancientwarfarestructure:advanced_spawner_tile",spawnerSettings:{minDelay:0,spawnDelay:0,lightSensitive:0b,spawnGroups:[{settingsList:[{remainingSpawnCount:1,hostile:1b,forced:1b,customTag:{factionName:"brigand"},maxToSpawn:1,entityId:"ancientwarfarenpc:faction.soldier",minToSpawn:1}],groupWeight:1}],playerRange:16,respondToRedstone:0b,inventory:{Size:9,Items:[]},spawnRange:0,transparent:1b,maxDelay:0,xpToDrop:0,mobRange:0,debugMode:0b,maxNearbyMonsters:0}}}
:enddata
:endrule

rule:
plugin=vanillaBlocks
number=20
data:
JSON:{blockState:{blockName:"minecraft:leaves",properties:{check_decay:"false",decayable:"true",variant:"oak"}}}
:enddata
:endrule

rule:
plugin=vanillaBlocks
number=21
data:
JSON:{blockState:{blockName:"minecraft:stonebrick",properties:{variant:"chiseled_stonebrick"}}}
:enddata
:endrule

rule:
plugin=vanillaBlocks
number=22
data:
JSON:{blockState:{blockName:"minecraft:log",properties:{variant:"oak",axis:"x"}}}
:enddata
:endrule

rule:
plugin=vanillaBlocks
number=23
data:
JSON:{blockState:{blockName:"minecraft:log",properties:{variant:"oak",axis:"z"}}}
:enddata
:endrule

rule:
plugin=vanillaBlocks
number=24
data:
JSON:{blockState:{blockName:"minecraft:leaves",properties:{check_decay:"false",decayable:"false",variant:"oak"}}}
:enddata
:endrule

rule:
plugin=vanillaBlocks
number=25
data:
JSON:{blockState:{blockName:"minecraft:stone_brick_stairs",properties:{half:"top",shape:"straight",facing:"north"}}}
:enddata
:endrule

rule:
plugin=vanillaBlocks
number=26
data:
JSON:{blockState:{blockName:"minecraft:stone_brick_stairs",properties:{half:"top",shape:"straight",facing:"south"}}}
:enddata
:endrule

rule:
plugin=vanillaBlocks
number=27
data:
JSON:{blockState:{blockName:"minecraft:stone_brick_stairs",properties:{half:"top",shape:"straight",facing:"east"}}}
:enddata
:endrule

rule:
plugin=vanillaBlocks
number=28
data:
JSON:{blockState:{blockName:"minecraft:stone_brick_stairs",properties:{half:"top",shape:"straight",facing:"west"}}}
:enddata
:endrule

rule:
plugin=blockTile
number=29
data:
JSON:{blockState:{blockName:"ancientwarfarestructure:advanced_spawner",properties:{transparent:"true"}},teData:{id:"ancientwarfarestructure:advanced_spawner_tile",spawnerSettings:{minDelay:0,spawnDelay:0,lightSensitive:0b,spawnGroups:[{settingsList:[{remainingSpawnCount:1,hostile:1b,forced:1b,customTag:{factionName:"brigand"},maxToSpawn:1,entityId:"ancientwarfarenpc:faction.soldier.elite",minToSpawn:1}],groupWeight:1}],playerRange:16,respondToRedstone:0b,inventory:{Size:9,Items:[]},spawnRange:0,transparent:1b,maxDelay:0,xpToDrop:0,mobRange:0,debugMode:0b,maxNearbyMonsters:0}}}
:enddata
:endrule

rule:
plugin=vanillaBlocks
number=30
data:
JSON:{blockState:{blockName:"minecraft:stone_slab",properties:{half:"bottom",variant:"stone_brick"}}}
:enddata
:endrule

rule:
plugin=vanillaBlocks
number=31
data:
JSON:{blockState:{blockName:"minecraft:stone_slab",properties:{half:"bottom",variant:"cobblestone"}}}
:enddata
:endrule

rule:
plugin=blockTile
number=32
data:
JSON:{blockState:{blockName:"ancientwarfarestructure:advanced_spawner",properties:{transparent:"true"}},teData:{id:"ancientwarfarestructure:advanced_spawner_tile",spawnerSettings:{minDelay:0,spawnDelay:0,lightSensitive:0b,spawnGroups:[{settingsList:[{remainingSpawnCount:1,hostile:1b,forced:1b,customTag:{factionName:"brigand"},maxToSpawn:1,entityId:"ancientwarfarenpc:faction.archer",minToSpawn:1}],groupWeight:1}],playerRange:16,respondToRedstone:0b,inventory:{Size:9,Items:[]},spawnRange:0,transparent:1b,maxDelay:0,xpToDrop:0,mobRange:0,debugMode:0b,maxNearbyMonsters:0}}}
:enddata
:endrule

#### ENTITIES ####
