# Ancient Warfare Structure Template File
# Auto-generated structure template file. created on: 11/16/2018 at: 6:37:24
# Lines beginning with # denote comments

header:
version=2.7
name=BrigandRuinLargeMagicians
mods=
size=27,87,39
offset=14,9,38
:endheader

#### VALIDATION ####
validation:
type=ground
survival=false
worldGenEnabled=true
unique=false
preserveBlocks=false
selectionWeight=30
clusterValue=80
minDuplicateDistance=990
dimensionWhiteList=false
dimensionList=
biomeWhiteList=true
biomeList=minecraft:swampland,biomesoplenty:meadow,biomesoplenty:shrubland,biomesoplenty:woodland,biomesoplenty:dead_forest,traverse:woodlands,minecraft:forest,biomesoplenty:highland,traverse:meadow,traverse:rocky_plateau,biomesoplenty:pasture,minecraft:forest_hills,biomesoplenty:steppe,minecraft:plains,biomesoplenty:orchard
leveling=6
fill=6
border=6
blockSwap=true
data:
:enddata
:endvalidation

#### LAYERS ####
layer: 0
1,1,1,1,1,1,1,1,1,1,1,1,1,1,1,1,1,1,1,1,1,1,1,1,1,1,1
1,2,2,2,2,2,2,2,2,2,2,2,2,2,2,2,2,2,2,2,2,2,2,2,2,1,1
1,2,2,2,2,2,2,2,2,2,2,2,2,2,2,2,2,2,2,2,2,2,2,2,2,1,1
1,2,2,2,2,2,2,2,2,2,2,2,2,2,2,2,2,2,2,2,2,2,2,2,2,1,1
1,2,2,2,2,2,2,2,2,2,2,2,2,2,2,2,2,2,2,2,2,2,2,2,2,1,1
1,1,1,1,1,1,1,1,1,1,1,1,1,1,1,1,1,1,1,1,1,1,1,1,1,1,1
1,1,1,1,1,1,1,1,1,1,1,1,1,1,1,1,1,1,1,1,1,1,1,1,1,1,1
1,1,1,1,1,1,1,1,1,1,1,1,1,1,1,1,1,1,1,1,1,1,1,1,1,1,1
1,1,1,1,1,1,1,1,1,1,1,1,2,1,1,1,1,1,1,1,1,1,1,1,1,1,1
1,1,1,1,1,1,1,1,1,1,1,1,1,1,1,1,1,1,1,1,1,1,1,1,1,1,1
1,1,1,1,1,1,1,1,1,1,1,1,1,1,1,1,1,1,1,1,1,1,1,1,1,1,1
1,1,1,1,1,1,1,1,1,1,1,1,1,1,1,1,1,1,1,1,1,1,1,1,1,1,1
1,1,1,1,1,1,1,1,1,1,1,1,1,1,1,1,1,1,1,1,1,1,1,1,1,1,1
1,1,1,1,1,1,1,1,1,1,1,1,1,1,1,1,1,1,1,1,1,1,1,1,1,1,1
1,1,1,1,1,1,1,1,1,1,1,1,1,1,1,1,1,1,1,1,1,1,1,1,1,1,1
1,1,1,1,1,1,1,1,1,1,1,1,1,1,1,1,1,1,1,1,1,1,1,1,1,1,1
1,1,1,1,1,1,1,1,1,1,1,1,1,1,1,1,1,1,1,1,1,1,1,1,1,1,1
1,1,1,1,1,1,1,1,1,1,1,1,1,1,1,1,1,1,1,1,1,1,1,1,1,1,1
1,1,1,1,1,1,1,1,1,1,1,1,1,1,1,1,1,1,1,1,1,1,1,1,1,1,1
1,1,1,1,1,1,1,1,1,1,1,1,1,1,1,1,1,1,1,1,1,1,1,1,1,1,1
1,1,1,1,1,1,1,1,1,1,1,1,1,1,1,1,1,1,1,1,1,1,1,1,1,1,1
1,1,1,1,1,1,1,1,1,1,1,1,1,1,1,1,1,1,1,1,1,1,1,1,1,1,1
1,1,1,1,1,1,1,1,1,1,1,1,1,1,1,1,1,1,1,1,1,1,1,1,1,1,1
1,1,1,1,1,1,1,1,1,1,1,1,1,1,1,1,1,1,1,1,1,1,1,1,1,1,1
1,1,1,1,1,1,1,1,1,1,1,1,1,1,1,1,1,1,1,1,1,1,1,1,1,1,1
1,1,1,1,1,1,1,1,1,1,1,1,1,1,1,1,1,1,1,1,1,1,1,1,1,1,1
1,1,1,1,1,1,1,1,1,1,1,1,1,1,1,1,1,1,1,1,1,1,1,1,1,1,1
1,1,1,1,1,1,1,1,1,1,1,1,1,1,1,1,1,1,1,1,1,1,1,1,1,1,1
1,1,1,1,1,1,1,1,1,1,1,1,1,1,1,1,1,1,1,1,1,1,1,1,1,1,1
1,1,1,1,1,1,1,1,1,1,1,1,1,1,1,1,1,1,1,1,1,1,1,1,1,1,1
1,1,1,1,1,1,1,1,1,1,1,1,1,1,1,1,1,1,1,1,1,1,1,1,1,1,1
1,1,1,1,1,1,1,1,1,1,1,1,1,1,1,1,1,1,1,1,1,1,1,1,1,1,1
1,1,1,1,1,1,1,1,1,1,1,1,1,1,1,1,1,1,1,1,1,1,1,1,1,1,1
1,1,1,1,1,1,1,1,1,1,1,1,1,1,1,1,1,1,1,1,1,1,1,1,1,1,1
1,1,1,1,1,1,1,1,1,1,1,1,1,1,1,1,1,1,1,1,1,1,1,1,1,1,1
1,1,1,1,1,1,1,1,1,1,1,1,1,1,1,1,1,1,1,1,1,1,1,1,1,1,1
1,1,1,1,1,1,1,1,1,1,1,1,1,1,1,1,1,1,1,1,1,1,1,1,1,1,1
1,1,1,1,1,1,1,1,1,1,1,1,1,1,1,1,1,1,1,1,1,1,1,1,1,1,1
1,1,1,1,1,1,1,1,1,1,1,1,1,1,1,1,1,1,1,1,1,1,1,1,1,1,1
:endlayer
layer: 1
1,1,1,1,1,1,1,1,1,1,1,1,1,1,1,1,1,1,1,1,1,1,1,1,1,1,1
1,2,2,2,2,2,2,2,2,2,2,2,2,2,2,2,2,2,2,2,2,2,2,2,2,1,1
1,2,3,3,3,3,3,3,3,3,3,3,3,3,3,3,3,3,3,3,3,3,2,2,2,1,1
1,2,3,3,3,3,3,3,3,3,3,3,3,3,3,3,3,3,3,3,3,3,2,2,2,1,1
1,2,2,2,3,3,3,3,3,2,2,3,3,3,2,2,3,3,3,3,3,2,2,2,2,1,1
1,1,1,1,3,3,3,3,3,3,1,3,3,3,1,1,3,3,3,3,3,1,1,1,1,1,1
1,1,1,1,3,3,3,3,3,1,1,3,3,3,1,1,3,3,3,3,3,1,1,1,1,1,1
1,1,1,1,3,3,3,3,3,1,1,3,3,3,1,1,3,3,3,3,3,1,1,1,1,1,1
1,1,1,1,3,3,3,3,3,1,1,3,3,3,1,1,3,3,3,3,3,1,1,1,1,1,1
1,1,1,1,3,3,3,3,3,1,1,3,3,3,1,1,3,3,3,3,3,1,1,1,1,1,1
1,1,1,1,3,3,3,3,3,1,1,3,3,3,1,1,3,3,3,3,3,1,1,1,1,1,1
1,1,1,1,3,3,3,3,3,1,1,3,3,3,1,1,3,3,3,3,3,1,1,1,1,1,1
1,1,1,1,1,1,1,1,1,1,1,3,3,3,1,1,3,3,3,3,3,1,1,1,1,1,1
1,1,1,1,1,1,1,1,1,1,1,3,3,3,1,1,1,1,1,1,1,1,1,1,1,1,1
1,1,1,1,1,1,1,1,1,1,1,3,3,3,1,1,1,1,1,1,1,1,1,1,1,1,1
1,1,1,1,1,1,1,1,1,1,1,3,3,3,1,1,1,1,1,1,1,1,1,1,1,1,1
1,1,1,1,1,1,1,1,1,1,1,3,3,3,1,1,1,1,1,1,1,1,1,1,1,1,1
1,1,1,1,1,1,1,1,1,1,1,3,3,3,1,1,1,1,1,1,1,1,1,1,1,1,1
1,1,1,1,1,1,1,1,1,1,1,3,3,3,1,1,1,1,1,1,1,1,1,1,1,1,1
1,1,1,1,1,1,1,1,1,1,1,3,3,3,1,1,1,1,1,1,1,1,1,1,1,1,1
1,1,1,1,1,1,1,1,1,1,1,3,3,3,1,1,1,1,1,1,1,1,1,1,1,1,1
1,1,1,1,1,1,1,1,1,1,1,3,3,3,1,1,1,1,1,1,1,1,1,1,1,1,1
1,1,1,1,1,3,3,3,1,1,1,3,3,3,1,1,1,1,1,1,1,1,1,1,1,1,1
1,1,1,1,1,3,3,3,1,1,1,3,3,3,1,1,1,1,1,1,1,1,1,1,1,1,1
1,1,1,1,1,3,3,3,1,1,1,3,3,3,1,1,1,1,1,1,1,1,1,1,1,1,1
1,1,1,1,1,3,3,3,1,1,1,3,3,3,1,1,1,1,3,3,3,3,3,3,3,1,1
1,1,1,1,1,3,3,3,1,1,1,3,3,3,1,1,1,1,3,3,3,3,3,3,3,1,1
1,1,1,1,1,3,3,3,1,1,1,3,3,3,1,1,1,3,3,3,3,3,3,3,3,1,1
1,1,1,3,3,3,3,3,3,1,1,3,3,3,1,1,1,3,3,3,3,3,3,3,3,1,1
1,1,1,3,3,3,3,3,3,1,1,3,3,3,1,1,1,3,3,3,3,3,3,3,3,1,1
1,1,1,3,3,3,3,3,3,1,1,3,3,3,1,1,1,3,3,3,3,3,3,3,3,1,1
3,3,3,3,3,3,3,3,3,3,3,3,3,3,3,3,3,3,3,3,3,3,3,3,3,3,3
3,3,3,3,3,3,3,3,3,3,3,3,3,3,3,3,3,3,3,3,3,3,3,3,3,3,3
3,3,3,3,3,3,3,3,3,3,3,3,3,3,3,3,3,3,3,3,3,3,3,3,3,3,3
1,1,1,1,1,1,1,1,1,1,1,3,3,3,1,1,1,3,3,3,3,3,1,1,1,1,1
1,1,1,1,1,1,1,1,1,1,1,3,3,3,1,1,1,3,3,3,3,3,1,1,1,1,1
1,1,1,1,1,1,1,1,1,1,1,3,3,3,1,1,1,3,3,3,3,3,1,1,1,1,1
1,1,1,1,1,1,1,1,1,1,1,3,3,3,1,1,1,3,3,3,3,3,1,1,1,1,1
1,1,1,1,1,1,1,1,1,1,1,3,3,3,1,1,1,3,3,3,3,3,1,1,1,1,1
:endlayer
layer: 2
1,1,1,1,1,1,1,1,1,1,1,1,1,1,1,1,1,1,1,1,1,1,1,1,1,1,1
1,2,3,3,3,3,3,3,3,3,3,3,3,3,3,3,3,3,3,3,3,3,2,2,2,1,1
1,3,0,31,0,0,0,0,0,0,0,0,0,0,0,19,0,0,0,0,0,0,3,2,2,1,1
1,3,0,0,0,19,0,0,0,0,0,0,0,0,0,0,0,0,0,0,0,0,3,2,2,1,1
1,2,3,3,14,14,0,34,33,3,3,14,0,27,3,3,0,0,0,0,0,3,2,2,2,1,1
1,1,3,3,0,0,0,0,0,3,3,0,0,0,3,3,14,14,0,18,14,3,1,1,1,1,1
1,1,3,3,0,0,0,0,0,3,3,0,0,0,3,3,0,0,0,0,0,3,1,1,1,1,1
1,1,3,3,0,0,0,0,0,3,3,0,0,0,3,3,0,0,0,0,0,3,1,1,1,1,1
1,1,3,3,0,0,0,0,0,3,3,0,0,0,3,3,0,0,0,0,0,3,1,1,1,1,1
1,1,1,3,0,0,0,0,0,3,3,0,0,0,3,3,0,0,19,0,15,3,1,1,1,1,1
1,1,1,1,3,3,0,0,0,3,3,0,0,0,3,3,0,0,0,0,0,3,1,1,1,1,1
1,1,1,1,1,3,5,5,5,3,3,0,0,0,3,3,0,0,0,0,0,3,1,1,1,1,1
1,1,1,1,1,1,3,3,3,1,3,0,0,0,3,3,0,22,0,0,0,3,1,1,1,1,1
1,1,1,1,1,1,1,1,1,1,3,14,21,28,3,1,3,3,3,3,3,1,1,1,1,1,1
1,1,1,1,1,1,1,1,1,1,3,0,0,0,3,1,1,1,1,1,1,1,1,1,1,1,1
1,1,1,1,1,1,1,1,1,1,3,0,29,0,3,1,1,1,1,1,1,1,1,1,1,1,1
1,1,1,1,1,1,1,1,1,1,3,0,0,0,3,1,1,1,1,1,1,1,1,1,1,1,1
1,1,1,1,1,1,1,1,1,1,3,0,0,0,3,1,1,1,1,1,1,1,1,1,1,1,1
1,1,1,1,1,1,1,1,1,1,3,0,0,0,3,1,1,1,1,1,1,1,1,1,1,1,1
1,1,1,1,1,1,1,1,1,1,3,0,0,0,3,1,1,1,1,1,1,1,1,1,1,1,1
1,1,1,1,1,1,1,1,1,1,3,0,0,0,3,1,1,1,1,1,1,1,1,1,1,1,1
1,1,1,1,1,3,3,3,1,1,1,3,0,0,3,1,1,1,1,1,1,1,1,1,1,1,1
1,1,1,1,3,13,0,13,3,1,1,3,0,0,3,1,1,1,1,1,1,1,1,1,1,1,1
1,1,1,1,3,12,35,12,3,1,3,3,0,0,3,1,1,1,1,1,1,1,1,1,1,1,1
1,1,1,1,3,0,0,0,3,1,3,3,0,0,3,1,1,1,3,3,3,3,3,1,1,1,1
1,1,1,1,3,13,36,13,3,1,3,31,0,0,3,1,1,3,10,10,10,10,10,3,1,1,1
1,1,1,1,3,12,0,12,3,1,3,0,0,0,3,1,1,3,0,0,0,0,0,3,3,1,1
1,1,1,3,3,0,0,0,3,1,3,0,0,0,3,1,3,23,0,0,16,0,0,0,5,3,1
1,1,3,0,0,0,0,0,0,3,3,0,0,0,3,1,3,0,0,0,0,0,11,0,5,3,1
1,1,3,0,0,38,0,0,0,3,3,0,0,0,3,1,3,24,0,0,0,0,0,0,6,3,1
1,3,3,0,0,0,37,0,0,3,3,0,0,0,3,3,3,0,0,0,0,0,0,0,6,3,1
3,0,0,0,0,0,0,0,0,0,0,0,0,0,0,0,4,0,0,0,0,0,0,8,0,0,3
4,0,0,39,0,0,0,0,0,32,0,0,0,0,26,0,3,0,0,0,0,0,0,0,0,0,4
3,0,0,0,0,0,0,0,0,0,0,0,0,0,0,0,4,0,0,0,0,0,0,0,0,0,3
1,3,3,3,3,3,3,3,3,3,3,0,0,0,3,3,3,0,0,0,0,0,3,9,7,3,1
1,1,1,1,1,1,1,1,1,1,3,0,0,0,3,1,3,0,20,0,0,12,3,1,1,1,1
1,1,1,1,1,1,1,1,1,1,3,0,0,0,3,1,3,0,0,0,17,13,3,1,1,1,1
1,1,1,1,1,1,1,1,1,1,3,0,0,0,3,1,3,25,0,0,3,3,1,1,1,1,1
1,1,1,1,1,1,1,1,1,1,1,3,30,3,1,1,3,3,21,3,1,1,1,1,1,1,1
:endlayer
layer: 3
1,1,1,1,1,1,1,1,1,1,1,1,1,1,1,1,1,1,1,1,1,1,1,1,1,1,1
1,2,3,3,3,3,3,3,3,3,3,3,3,3,3,3,3,3,3,3,3,3,2,2,2,1,1
1,3,0,31,0,0,0,0,0,0,0,0,0,0,0,0,0,0,0,0,0,0,3,2,2,1,1
1,3,0,0,0,0,0,0,0,0,0,0,0,0,0,0,0,0,0,0,0,0,3,2,2,1,1
1,2,3,3,14,14,0,64,62,3,3,14,0,53,3,3,0,0,0,0,0,3,2,2,2,1,1
1,1,3,3,0,0,0,0,0,3,3,0,0,0,3,3,14,14,0,49,48,3,1,1,1,1,1
1,1,3,3,0,0,0,0,0,3,3,0,0,0,3,3,0,0,0,0,0,3,1,1,1,1,1
1,1,3,3,0,0,0,0,0,3,3,0,0,0,3,3,0,0,0,0,0,3,1,1,1,1,1
1,1,3,3,0,0,0,0,0,3,3,0,0,0,3,3,0,0,0,0,0,3,1,1,1,1,1
1,1,1,3,0,0,0,0,0,3,3,0,0,0,3,3,0,0,0,0,0,3,1,1,1,1,1
1,1,1,1,3,3,0,0,0,3,3,0,0,0,3,3,0,0,0,0,0,3,1,1,1,1,1
1,1,1,1,1,3,66,0,63,3,3,0,0,0,3,3,0,0,0,0,0,3,1,1,1,1,1
1,1,1,1,1,1,3,3,3,1,3,0,0,0,3,3,0,0,0,0,0,3,1,1,1,1,1
1,1,1,1,1,1,1,1,1,1,3,14,57,54,3,1,3,3,3,3,3,1,1,1,1,1,1
1,1,1,1,1,1,1,1,1,1,3,0,0,0,3,1,1,1,1,1,1,1,1,1,1,1,1
1,1,1,1,1,1,1,1,1,1,3,0,0,0,3,1,1,1,1,1,1,1,1,1,1,1,1
1,1,1,1,1,1,1,1,1,1,3,0,0,0,3,1,1,1,1,1,1,1,1,1,1,1,1
1,1,1,1,1,1,1,1,1,1,3,0,0,0,3,1,1,1,1,1,1,1,1,1,1,1,1
1,1,1,1,1,1,1,1,1,1,3,0,0,0,3,1,1,1,1,1,1,1,1,1,1,1,1
1,1,1,1,1,1,1,1,1,1,3,0,0,0,3,1,1,1,1,1,1,1,1,1,1,1,1
1,1,1,1,1,1,1,1,1,1,3,59,0,0,3,1,1,1,1,1,1,1,1,1,1,1,1
1,1,1,1,1,3,3,3,1,1,1,3,43,0,3,1,1,1,1,1,1,1,1,1,1,1,1
1,1,1,1,3,0,46,0,3,1,1,3,0,0,3,1,1,1,1,1,1,1,1,1,1,1,1
1,1,1,1,3,0,0,0,3,1,3,3,0,0,3,1,1,1,1,1,1,1,1,1,1,1,1
1,1,1,1,3,0,0,0,3,1,3,60,0,0,3,1,1,1,3,3,3,3,3,1,1,1,1
1,1,1,1,3,0,0,0,3,1,3,0,0,0,3,1,1,3,10,10,10,10,10,3,1,1,1
1,1,1,1,3,0,0,0,3,1,3,0,0,0,3,1,1,3,0,0,0,0,0,3,3,1,1
1,1,1,3,3,0,0,65,3,1,3,0,0,0,3,1,3,0,0,0,0,0,0,0,41,3,1
1,1,3,0,46,0,0,0,0,3,3,0,0,0,3,1,3,0,0,0,0,0,0,0,42,3,1
1,1,3,0,0,0,0,0,0,3,3,0,0,55,3,1,3,0,0,0,0,0,0,0,0,3,1
1,3,3,0,0,0,0,0,0,3,3,0,0,0,3,3,3,0,0,0,0,0,0,0,43,3,1
3,43,0,0,0,0,0,0,0,0,0,0,0,0,0,0,51,0,0,0,0,0,0,0,0,0,3
67,0,0,0,0,0,0,0,0,0,0,0,0,0,0,0,3,0,0,0,0,0,0,0,0,0,40
3,43,0,0,0,0,0,0,0,0,0,0,0,0,0,0,52,0,0,0,0,0,46,0,0,0,3
1,3,3,3,3,3,3,3,3,3,3,0,0,0,3,3,3,0,0,0,0,47,3,45,44,3,1
1,1,1,1,1,1,1,1,1,1,3,0,0,0,3,1,3,0,0,0,0,0,3,1,1,1,1
1,1,1,1,1,1,1,1,1,1,3,0,0,0,3,1,3,0,0,0,0,0,3,1,1,1,1
1,1,1,1,1,1,1,1,1,1,3,61,0,56,3,1,3,0,0,0,3,3,1,1,1,1,1
1,1,1,1,1,1,1,1,1,1,1,3,58,3,1,1,3,3,50,3,1,1,1,1,1,1,1
:endlayer
layer: 4
1,1,1,1,1,1,1,1,1,1,1,1,1,1,1,1,1,1,1,1,1,1,1,1,1,1,1
1,2,3,3,3,3,3,3,3,3,3,3,3,3,3,3,3,3,3,3,3,3,2,2,2,1,1
1,3,0,31,0,0,0,0,0,0,0,0,0,0,0,0,0,0,0,0,0,0,3,2,2,1,1
1,3,0,0,0,0,0,0,0,0,0,0,0,0,0,0,0,0,0,0,0,0,3,2,2,1,1
1,2,3,3,14,14,0,77,76,3,3,14,73,71,3,3,0,0,0,0,0,3,2,2,2,1,1
1,1,3,3,0,0,0,0,0,3,3,0,0,0,3,3,14,14,3,70,69,3,1,1,1,1,1
1,1,3,3,0,0,0,0,0,3,3,0,0,0,3,3,0,0,0,0,0,3,1,1,1,1,1
1,1,3,3,0,0,0,0,0,3,3,0,0,0,3,3,0,0,0,0,0,3,1,1,1,1,1
1,1,3,3,0,0,0,0,0,3,3,0,0,0,3,3,0,0,0,0,0,3,1,1,1,1,1
1,1,1,3,0,0,0,0,0,3,3,0,0,0,3,3,0,0,0,0,0,3,1,1,1,1,1
1,1,1,1,3,3,0,0,0,3,3,0,0,0,3,3,0,0,0,0,0,3,1,1,1,1,1
1,1,1,1,1,3,0,0,0,3,3,0,0,0,3,3,0,0,0,0,0,3,1,1,1,1,1
1,1,1,1,1,1,3,3,3,1,3,0,0,0,3,3,0,0,0,0,0,3,1,1,1,1,1
1,1,1,1,1,1,1,1,1,1,3,14,73,72,3,1,3,3,3,3,3,1,1,1,1,1,1
1,1,1,1,1,1,1,1,1,1,3,0,0,0,3,1,1,1,1,1,1,1,1,1,1,1,1
1,1,1,1,1,1,1,1,1,1,3,0,0,0,3,1,1,1,1,1,1,1,1,1,1,1,1
1,1,1,1,1,1,1,1,1,1,3,0,0,0,3,1,1,1,1,1,1,1,1,1,1,1,1
1,1,1,1,1,1,1,1,1,1,3,0,0,0,3,1,1,1,1,1,1,1,1,1,1,1,1
1,1,1,1,1,1,1,1,1,1,3,0,0,0,3,1,1,1,1,1,1,1,1,1,1,1,1
1,1,1,1,1,1,1,1,1,1,3,0,0,0,3,1,1,1,1,1,1,1,1,1,1,1,1
1,1,1,1,1,1,1,1,1,1,3,0,0,0,3,1,1,1,1,1,1,1,1,1,1,1,1
1,1,1,1,1,3,3,3,1,1,1,3,0,0,3,1,1,1,1,1,1,1,1,1,1,1,1
1,1,1,1,3,0,0,0,3,1,1,3,0,0,3,1,1,1,1,1,1,1,1,1,1,1,1
1,1,1,1,3,0,0,0,3,1,3,75,0,0,3,1,1,1,1,1,1,1,1,1,1,1,1
1,1,1,1,3,0,0,0,3,1,3,0,0,0,3,1,1,1,3,3,3,3,3,1,1,1,1
1,1,1,1,3,0,0,0,3,1,3,0,0,0,3,1,1,3,10,10,10,10,10,3,1,1,1
1,1,1,1,3,0,0,0,3,1,3,0,0,0,3,1,1,3,43,0,0,0,68,3,3,1,1
1,1,1,3,3,0,0,0,3,1,3,0,0,0,3,1,3,46,0,0,0,0,0,46,0,3,1
1,1,3,0,0,0,0,0,0,3,3,0,0,0,3,1,3,0,0,0,0,0,0,0,0,3,1
1,1,3,0,0,0,0,0,0,3,3,0,0,0,3,1,3,0,0,0,0,0,0,0,0,3,1
1,3,3,0,0,0,0,0,0,3,3,0,0,0,3,3,3,0,0,0,0,0,0,0,0,3,1
3,0,0,0,0,0,0,0,0,0,0,0,0,0,0,0,3,0,0,0,0,0,0,0,0,0,3
3,0,0,0,0,0,0,0,0,0,0,0,0,0,0,0,3,0,0,0,0,0,0,0,0,0,3
3,0,0,0,0,0,0,0,0,0,0,0,0,0,0,0,3,0,0,0,0,0,0,0,0,0,3
1,3,3,3,3,3,3,3,3,3,3,0,0,0,3,3,3,0,0,0,0,0,3,3,3,3,1
1,1,1,1,1,1,1,1,1,1,3,0,0,0,3,1,3,0,0,0,0,0,3,1,1,1,1
1,1,1,1,1,1,1,1,1,1,3,0,0,0,3,1,3,0,0,0,0,0,3,1,1,1,1
1,1,1,1,1,1,1,1,1,1,3,0,0,0,3,1,3,0,0,0,3,3,1,1,1,1,1
1,1,1,1,1,1,1,1,1,1,1,3,74,3,1,1,3,3,3,3,1,1,1,1,1,1,1
:endlayer
layer: 5
1,1,1,1,1,1,1,1,1,1,1,1,1,1,1,1,1,1,1,1,1,1,1,1,1,1,1
1,2,3,3,3,3,3,3,3,3,3,3,3,3,3,3,3,3,3,3,3,3,2,2,2,1,1
1,3,0,3,0,0,0,0,0,0,0,0,0,0,0,0,0,0,0,0,0,0,3,2,2,1,1
1,3,0,0,0,0,0,0,0,0,0,0,0,0,0,0,0,0,0,0,0,0,3,2,2,1,1
1,2,3,3,14,14,0,80,79,3,3,3,3,3,3,3,3,3,3,3,3,3,2,2,2,1,1
1,1,3,3,0,0,0,0,0,3,1,3,3,3,1,1,3,3,3,3,3,1,1,1,1,1,1
1,1,3,3,0,0,0,0,0,3,1,3,3,3,1,1,3,3,3,3,3,1,1,1,1,1,1
1,1,3,3,0,0,0,0,0,3,1,3,3,3,1,1,3,3,3,3,3,1,1,1,1,1,1
1,1,3,3,0,0,0,0,0,3,1,3,3,3,1,1,3,3,3,3,3,1,1,1,1,1,1
1,1,1,3,0,0,0,0,0,3,1,3,3,3,1,1,3,3,3,3,3,1,1,1,1,1,1
1,1,1,1,3,3,0,0,0,3,1,3,3,3,1,1,3,3,3,3,3,1,1,1,1,1,1
1,1,1,1,1,3,5,5,5,3,1,3,3,3,1,1,3,3,3,3,3,1,1,1,1,1,1
1,1,1,1,1,1,3,3,3,1,1,3,3,3,1,1,3,3,3,3,3,1,1,1,1,1,1
1,1,1,1,1,1,1,1,1,1,1,3,3,3,1,1,1,1,1,1,1,1,1,1,1,1,1
1,1,1,1,1,1,1,1,1,1,1,3,3,3,1,1,1,1,1,1,1,1,1,1,1,1,1
1,1,1,1,1,1,1,1,1,1,3,3,3,3,1,1,1,1,1,1,1,1,1,1,1,1,1
1,1,1,1,1,1,1,1,1,1,3,3,3,3,1,1,1,1,1,1,1,1,1,1,1,1,1
1,1,1,1,1,1,1,1,1,1,3,3,3,3,1,1,1,1,1,1,1,1,1,1,1,1,1
1,1,1,1,1,1,1,1,1,1,3,3,3,3,1,1,1,1,1,1,1,1,1,1,1,1,1
1,1,1,1,1,1,1,1,1,1,3,3,3,3,1,1,1,1,1,1,1,1,1,1,1,1,1
1,1,1,1,1,1,1,1,1,1,3,3,3,3,1,1,1,1,1,1,1,1,1,1,1,1,1
1,1,1,1,1,1,1,1,1,1,3,1,3,3,1,1,1,1,1,1,1,1,1,1,1,1,1
1,1,1,1,1,3,3,3,3,3,3,78,3,3,1,1,1,1,1,1,1,1,1,1,1,1,1
1,1,1,1,1,3,3,3,3,3,3,0,3,3,1,1,1,1,1,1,1,1,1,1,1,1,1
1,1,1,1,1,3,3,3,3,3,3,0,3,3,1,1,1,1,1,1,1,1,1,1,1,1,1
1,1,1,1,1,3,3,3,3,3,3,0,3,3,1,1,1,1,3,3,3,3,3,1,1,1,1
1,1,1,1,1,3,3,3,3,3,3,0,3,3,1,1,1,3,0,0,0,0,0,3,1,1,1
1,1,1,1,1,3,3,3,3,3,3,3,3,3,1,1,3,0,0,0,0,0,0,3,3,3,1
1,3,3,3,3,3,3,3,3,3,3,3,3,3,1,1,3,0,0,0,0,0,0,3,3,3,1
1,3,3,3,3,3,3,3,3,3,3,3,3,3,1,1,3,0,0,0,0,0,0,3,3,3,1
1,3,3,3,3,3,3,3,3,3,3,3,3,3,1,1,3,0,0,0,0,0,0,3,3,3,1
1,3,3,3,3,3,3,3,3,3,3,3,3,3,3,3,3,0,0,0,0,0,0,3,3,3,1
1,3,3,3,3,3,3,3,3,3,3,3,3,3,3,3,3,0,0,0,0,0,0,3,3,3,1
1,3,3,3,3,3,3,3,3,3,3,3,3,3,3,3,3,0,0,0,0,0,0,3,3,3,1
1,1,1,1,1,1,1,1,1,1,1,3,3,3,1,1,3,3,3,3,3,3,3,1,1,1,1
1,1,1,1,1,1,1,1,1,1,1,3,3,3,1,1,1,3,3,3,3,3,1,1,1,1,1
1,1,1,1,1,1,1,1,1,1,1,3,3,3,1,1,1,3,3,3,3,3,1,1,1,1,1
1,1,1,1,1,1,1,1,1,1,1,3,3,3,1,1,1,3,3,3,3,3,1,1,1,1,1
1,1,1,1,1,1,1,1,1,1,1,1,3,1,1,1,1,3,3,3,3,3,1,1,1,1,1
:endlayer
layer: 6
1,1,1,1,1,1,1,1,1,1,1,1,1,1,1,1,1,1,1,1,1,1,1,1,1,1,1
1,2,3,3,3,3,3,3,3,3,3,3,3,3,3,3,3,3,3,3,3,3,2,2,2,1,1
1,3,0,3,0,0,0,0,0,0,0,0,0,0,0,0,0,0,0,0,0,0,3,2,2,1,1
1,3,0,3,0,0,0,0,0,0,0,0,0,0,0,0,0,0,0,0,0,0,3,2,2,1,1
1,2,3,3,14,14,3,85,84,3,3,3,3,3,3,3,3,3,3,3,3,3,2,2,2,1,1
1,1,3,3,0,0,0,0,0,3,1,1,1,1,1,1,1,1,1,1,1,1,1,1,1,1,1
1,1,3,3,0,0,0,0,0,3,1,1,1,1,1,1,1,1,1,1,1,1,1,1,1,1,1
1,1,3,3,0,0,0,0,0,3,1,1,1,1,1,1,1,1,1,1,1,1,1,1,1,1,1
1,1,3,3,0,0,0,0,0,3,1,1,1,1,1,1,1,1,1,1,1,1,1,1,1,1,1
1,1,1,3,0,0,0,0,0,3,1,1,1,1,1,1,1,1,1,1,1,1,1,1,1,1,1
1,1,1,1,3,3,0,0,0,3,1,1,1,1,1,1,1,1,1,1,1,1,1,1,1,1,1
1,1,1,1,1,3,0,0,0,3,1,1,1,1,1,1,1,1,1,1,1,1,1,1,1,1,1
1,1,1,1,1,1,3,3,3,1,1,1,1,1,1,1,1,1,1,1,1,1,1,1,1,1,1
1,1,1,1,1,1,1,1,1,1,1,1,1,1,1,1,1,1,1,1,1,1,1,1,1,1,1
1,1,1,1,1,1,1,1,1,1,1,1,1,1,1,1,1,1,1,1,1,1,1,1,1,1,1
1,1,1,1,1,1,1,1,1,1,3,1,82,1,1,1,1,1,1,1,1,1,1,1,1,1,1
1,1,1,1,1,1,1,1,1,1,3,1,82,1,1,1,1,1,1,1,1,1,1,1,1,1,1
1,1,1,1,1,1,1,1,1,1,3,1,82,1,1,1,1,1,1,1,1,1,1,1,1,1,1
1,1,1,1,1,1,1,1,1,1,3,1,82,1,1,1,1,1,1,1,1,1,1,1,1,1,1
1,1,1,1,1,1,1,1,1,1,3,1,82,1,1,1,1,1,1,1,1,1,1,1,1,1,1
1,1,1,1,1,1,1,1,1,1,3,1,82,1,1,1,1,1,1,1,1,1,1,1,1,1,1
1,1,1,1,1,1,1,1,1,1,3,83,82,1,1,1,1,1,1,1,1,1,1,1,1,1,1
1,1,1,1,1,1,1,1,1,1,3,0,82,1,1,1,1,1,1,1,1,1,1,1,1,1,1
1,1,1,1,1,1,1,1,1,1,3,0,82,1,1,1,1,1,1,1,1,1,1,1,1,1,1
1,1,1,1,1,1,1,1,1,1,3,0,82,1,1,1,1,1,1,1,1,1,1,1,1,1,1
1,1,1,1,1,1,1,1,1,1,3,0,82,1,1,1,1,1,3,3,3,3,3,1,1,1,1
1,1,1,1,1,1,1,1,1,1,3,0,82,1,1,1,1,3,0,0,0,0,0,3,1,1,1
1,1,1,1,1,1,1,1,1,1,1,3,1,1,1,1,3,0,0,0,0,0,0,3,1,1,1
1,1,1,1,1,1,1,1,1,1,1,1,1,1,1,1,3,0,0,0,0,0,0,3,1,1,1
1,1,1,1,1,1,1,1,1,1,1,1,1,1,1,1,3,0,0,0,0,0,0,3,1,1,1
1,1,1,1,1,1,1,1,1,1,1,1,1,1,1,1,3,0,0,0,0,0,81,3,1,1,1
1,1,1,1,1,1,1,1,1,1,1,1,1,1,1,1,3,0,0,0,0,0,0,3,1,1,1
1,1,1,1,1,1,1,1,1,1,1,1,1,1,1,1,3,0,0,0,0,0,0,3,1,1,1
1,1,1,1,1,1,1,1,1,1,1,1,1,1,1,1,3,0,0,0,0,0,0,3,1,1,1
1,1,1,1,1,1,1,1,1,1,1,1,1,1,1,1,3,0,0,0,0,3,3,1,1,1,1
1,1,1,1,1,1,1,1,1,1,1,1,1,1,1,1,1,3,3,3,3,1,1,1,1,1,1
1,1,1,1,1,1,1,1,1,1,1,1,1,1,1,1,1,1,1,1,1,1,1,1,1,1,1
1,1,1,1,1,1,1,1,1,1,1,1,1,1,1,1,1,1,1,1,1,1,1,1,1,1,1
1,1,1,1,1,1,1,1,1,1,1,1,1,1,1,1,1,1,1,1,1,1,1,1,1,1,1
:endlayer
layer: 7
1,1,1,1,1,1,1,1,1,1,1,1,1,1,1,1,1,1,1,1,1,1,1,1,1,1,1
1,2,86,86,86,86,86,86,86,86,86,86,86,86,86,86,86,86,86,86,86,86,2,2,2,1,1
1,2,86,86,86,86,86,86,86,86,86,86,86,86,86,86,86,86,86,86,86,86,2,2,2,1,1
1,2,86,86,86,86,86,86,86,86,86,86,86,86,86,86,86,86,86,86,86,86,2,2,2,1,1
1,2,3,3,86,86,86,86,86,3,3,3,3,3,3,3,3,3,3,3,3,3,2,2,2,1,1
1,1,1,1,86,86,86,86,86,3,1,1,1,1,1,1,1,1,1,1,1,1,1,1,1,1,1
1,1,1,1,86,86,86,86,86,3,1,1,1,1,1,1,1,1,1,1,1,1,1,1,1,1,1
1,1,1,1,86,86,86,86,86,3,1,1,1,1,1,1,1,1,1,1,1,1,1,1,1,1,1
1,1,1,1,86,86,86,86,86,3,1,1,1,1,1,1,1,1,1,1,1,1,1,1,1,1,1
1,1,1,1,86,86,86,86,86,3,1,1,1,1,1,1,1,1,1,1,1,1,1,1,1,1,1
1,1,1,1,1,1,86,86,86,1,1,1,1,1,1,1,1,1,1,1,1,1,1,1,1,1,1
1,1,1,1,1,1,86,86,86,1,1,1,1,1,1,1,1,1,1,1,1,1,1,1,1,1,1
1,1,1,1,1,1,1,1,1,1,1,1,1,1,1,1,1,1,1,1,1,1,1,1,1,1,1
1,1,1,1,1,1,1,1,1,1,1,1,1,1,1,1,1,1,1,1,1,1,1,1,1,1,1
1,1,1,1,1,1,1,1,1,1,1,1,1,1,1,1,1,1,1,1,1,1,1,1,1,1,1
1,1,1,1,1,1,1,1,1,1,3,1,82,1,1,1,1,1,1,1,1,1,1,1,1,1,1
1,1,1,1,1,1,1,1,1,1,3,1,82,1,1,1,1,1,1,1,1,1,1,1,1,1,1
1,1,1,1,1,1,1,1,1,1,3,1,82,1,1,1,1,1,1,1,1,1,1,1,1,1,1
1,1,1,1,1,1,1,1,1,1,3,1,82,1,1,1,1,1,1,1,1,1,1,1,1,1,1
1,1,1,1,1,1,1,1,1,1,3,1,82,1,1,1,1,1,1,1,1,1,1,1,1,1,1
1,1,1,1,1,1,1,1,1,1,3,87,82,1,1,1,1,1,1,1,1,1,1,1,1,1,1
1,1,1,1,1,1,1,1,1,1,3,0,82,1,1,1,1,1,1,1,1,1,1,1,1,1,1
1,1,1,1,1,1,1,1,1,1,3,0,82,1,1,1,1,1,1,1,1,1,1,1,1,1,1
1,1,1,1,1,1,1,1,1,1,3,0,82,1,1,1,1,1,1,1,1,1,1,1,1,1,1
1,1,1,1,1,1,1,1,1,1,3,0,82,1,1,1,1,1,1,1,1,1,1,1,1,1,1
1,1,1,1,1,1,1,1,1,1,3,5,82,1,1,1,1,1,3,3,3,3,3,1,1,1,1
1,1,1,1,1,1,1,1,1,1,3,73,82,1,1,1,1,86,86,86,86,86,86,3,1,1,1
1,1,1,1,1,1,1,1,1,1,1,1,1,1,1,1,3,86,86,86,86,86,86,3,1,1,1
1,1,1,1,1,1,1,1,1,1,1,1,1,1,1,1,3,86,86,86,86,86,86,3,1,1,1
1,1,1,1,1,1,1,1,1,1,1,1,1,1,1,1,3,86,86,86,86,86,86,3,1,1,1
1,1,1,1,1,1,1,1,1,1,1,1,1,1,1,1,3,86,86,86,86,86,86,3,1,1,1
1,1,1,1,1,1,1,1,1,1,1,1,1,1,1,1,3,86,86,86,86,86,86,3,1,1,1
1,1,1,1,1,1,1,1,1,1,1,1,1,1,1,1,3,86,86,86,86,86,86,3,1,1,1
1,1,1,1,1,1,1,1,1,1,1,1,1,1,1,1,3,86,86,86,86,86,86,3,1,1,1
1,1,1,1,1,1,1,1,1,1,1,1,1,1,1,1,3,86,86,86,86,86,86,1,1,1,1
1,1,1,1,1,1,1,1,1,1,1,1,1,1,1,1,1,86,86,86,86,86,86,1,1,1,1
1,1,1,1,1,1,1,1,1,1,1,1,1,1,1,1,1,1,1,1,1,1,1,1,1,1,1
1,1,1,1,1,1,1,1,1,1,1,1,1,1,1,1,1,1,1,1,1,1,1,1,1,1,1
1,1,1,1,1,1,1,1,1,1,1,1,1,1,1,1,1,1,1,1,1,1,1,1,1,1,1
:endlayer
layer: 8
88,88,88,88,88,88,88,1,1,1,1,1,1,1,1,1,1,1,1,1,1,1,88,88,88,88,88
88,88,88,88,88,88,88,2,2,2,2,2,2,2,2,2,2,2,2,2,2,2,88,88,88,88,88
88,88,88,88,88,88,88,2,2,2,2,2,2,2,2,2,2,2,2,2,2,2,88,88,88,88,88
88,88,88,88,88,88,88,2,2,2,2,2,2,2,2,2,2,2,2,2,2,2,88,1,88,88,88
88,88,88,88,1,88,88,2,2,2,2,2,2,2,2,2,2,2,2,2,2,2,88,88,88,88,88
88,88,88,88,88,88,88,1,1,1,1,1,1,1,1,1,1,1,1,1,1,1,88,88,88,88,88
88,88,88,88,88,88,1,1,1,1,1,1,1,1,1,1,1,1,1,1,1,1,88,1,88,88,88
88,88,88,88,88,88,1,1,1,1,1,1,1,1,1,1,1,1,1,1,1,1,88,88,88,88,88
88,88,88,88,88,1,1,1,1,1,1,1,1,1,1,1,1,1,1,1,1,1,88,88,88,88,88
88,88,88,1,88,1,1,1,1,1,1,1,1,1,1,1,1,1,1,1,1,1,1,88,88,88,88
88,88,88,88,88,1,1,1,1,1,1,1,1,1,1,1,1,1,1,1,1,1,1,88,88,88,88
88,88,88,88,88,1,1,1,1,1,1,1,1,1,1,1,1,1,1,1,1,1,1,88,88,88,88
88,88,88,88,88,1,1,1,1,1,1,1,1,1,1,1,1,1,1,1,1,1,88,88,88,88,88
88,88,88,88,1,1,1,1,1,1,1,1,1,1,1,1,1,1,1,1,1,88,88,88,88,88,88
88,88,88,1,1,1,1,1,1,1,1,1,1,1,1,1,1,1,1,1,1,88,88,88,88,88,88
88,88,88,1,1,1,1,1,1,1,3,1,82,1,1,1,1,1,1,1,1,88,88,88,88,88,88
88,88,88,1,1,1,1,1,1,1,3,1,82,1,1,1,1,1,1,1,1,88,88,88,88,88,88
88,88,88,1,1,1,1,1,1,1,3,1,82,1,1,1,1,1,1,1,1,88,88,88,88,88,88
88,88,88,1,1,1,1,1,1,1,3,1,82,1,1,1,1,1,1,1,1,1,88,1,88,88,88
88,88,1,1,1,1,1,1,1,1,3,89,82,1,1,1,1,1,1,1,1,1,88,88,88,88,88
88,88,1,1,1,1,1,1,1,1,3,43,82,1,1,1,1,1,1,1,1,1,88,88,88,88,88
88,88,1,1,1,1,1,1,1,1,3,0,82,1,1,1,1,1,1,1,1,1,88,88,88,88,88
88,88,1,1,1,1,1,1,1,1,3,0,82,1,1,1,1,1,1,1,1,1,1,88,88,88,88
88,88,1,1,1,1,1,1,1,1,3,0,82,1,1,1,1,1,1,1,1,1,1,88,88,88,88
88,1,1,1,1,1,1,1,1,1,3,5,82,1,1,1,1,1,1,1,1,1,88,88,88,88,88
88,1,1,1,1,1,1,1,1,1,3,90,82,1,1,1,1,1,1,1,1,1,88,88,88,88,88
88,1,1,1,1,1,1,1,1,1,3,1,82,1,1,1,1,1,1,1,1,1,0,88,88,88,88
88,1,1,1,1,1,1,1,1,1,1,1,1,1,1,1,1,1,1,1,1,1,88,88,88,88,88
88,1,1,1,1,1,1,1,1,1,1,1,1,1,1,1,1,1,1,1,1,88,88,88,88,88,88
88,1,1,1,1,1,1,1,1,1,1,1,1,1,1,1,1,1,1,1,1,88,88,1,88,88,88
88,1,1,1,1,1,1,1,1,1,1,1,1,1,1,1,1,1,1,1,1,88,88,88,88,88,88
88,1,1,1,1,1,1,1,1,1,1,1,1,1,1,1,1,1,1,88,88,88,88,88,88,88,88
88,1,1,1,1,1,1,1,1,1,1,1,1,1,1,1,1,1,1,88,88,88,88,1,88,88,88
88,1,1,1,1,1,1,1,1,1,1,1,1,1,1,1,1,1,1,88,88,88,88,88,88,88,88
88,1,1,1,1,1,1,1,1,1,1,1,1,1,1,1,1,1,1,88,88,88,88,88,88,88,88
88,1,1,1,1,1,1,1,1,1,1,1,1,1,1,1,1,1,1,88,88,88,88,88,88,88,88
88,88,1,1,1,1,1,1,1,1,1,1,1,1,1,1,1,1,88,88,88,88,88,88,88,88,88
88,88,1,1,1,1,1,1,1,1,1,1,1,1,1,1,1,88,88,88,88,88,88,88,88,88,88
2,88,88,1,1,1,1,1,1,1,1,1,88,88,88,88,88,88,88,88,88,88,88,88,88,88,88
:endlayer
layer: 9
0,0,0,91,91,91,0,88,88,88,88,88,88,88,88,88,88,88,88,88,88,88,0,0,0,0,0
0,91,91,91,91,91,91,88,2,2,2,2,2,2,2,2,2,2,2,2,1,88,0,0,0,0,0
0,0,91,91,91,91,0,88,2,2,2,2,2,2,2,2,2,2,2,2,2,88,0,0,0,0,0
0,0,91,91,0,0,0,88,2,2,2,2,2,2,2,2,2,2,2,2,2,88,0,92,0,0,0
0,91,91,0,92,0,0,88,1,2,2,2,2,2,2,2,2,2,2,2,0,88,0,0,0,0,0
0,0,0,0,0,0,0,1,1,1,1,1,1,1,1,1,1,1,1,2,1,88,0,0,0,0,0
0,0,0,0,0,97,88,1,1,1,1,1,1,1,1,1,1,1,2,2,1,88,0,92,0,0,0
0,0,0,0,0,0,1,1,1,1,1,1,1,1,1,1,1,1,2,2,1,88,0,0,0,0,0
0,0,91,91,0,88,1,1,1,1,1,1,1,1,1,1,1,1,2,2,3,82,0,0,0,0,0
0,91,91,92,98,88,1,1,1,1,1,1,1,1,1,1,1,2,3,3,3,3,82,0,0,0,91
91,91,91,91,0,88,1,1,1,1,1,1,1,1,1,1,1,2,3,3,3,3,3,0,0,91,91
91,91,91,91,0,88,1,1,1,1,1,1,1,1,1,1,1,2,3,3,3,3,82,0,91,91,91
0,0,0,91,0,2,2,2,2,1,1,1,1,1,1,1,1,2,2,2,3,82,91,91,91,91,91
0,0,0,0,2,2,2,2,2,1,1,1,1,1,1,1,1,2,3,3,2,0,0,91,91,91,91
0,91,91,88,2,2,2,2,2,1,1,1,1,1,1,1,1,2,2,2,2,0,0,93,91,91,0
0,91,91,88,2,2,2,2,2,1,3,1,82,1,1,1,1,2,2,2,2,0,94,0,0,0,91
91,91,91,88,2,2,2,2,2,1,3,1,82,1,1,1,1,2,2,2,2,0,0,0,0,0,0
0,91,0,88,1,1,2,2,2,1,3,1,82,1,1,1,2,2,2,2,2,0,0,0,0,0,0
91,91,0,88,1,1,2,2,2,1,3,96,82,1,1,1,2,2,2,2,2,1,0,92,0,0,0
0,91,88,1,1,1,2,2,2,1,3,0,82,1,1,1,2,2,2,2,2,1,0,0,0,0,0
0,0,88,1,1,1,2,2,2,1,3,0,82,1,1,2,2,2,2,2,2,1,0,91,0,0,0
0,0,88,1,1,1,1,1,1,1,3,0,82,1,1,2,2,2,2,2,2,2,0,0,0,91,0
0,0,88,1,1,1,1,1,1,1,3,0,82,1,1,2,2,2,2,2,2,2,2,91,91,0,0
0,0,1,1,1,1,1,1,1,1,3,5,82,1,1,2,2,2,2,2,2,2,2,91,91,91,91
0,88,1,1,1,1,1,1,1,1,3,90,82,1,1,2,2,2,2,2,2,2,0,91,0,91,91
0,88,1,1,1,1,1,1,1,1,3,1,82,1,1,1,2,2,2,2,2,2,0,91,91,91,0
0,88,1,1,1,1,1,1,1,1,3,1,82,1,1,1,2,2,2,2,2,88,0,0,0,0,91
0,88,1,1,1,1,1,1,1,1,1,1,1,1,1,1,2,2,2,2,2,88,0,0,91,0,0
0,88,1,1,1,1,1,1,1,1,1,1,1,1,1,1,2,2,2,95,95,0,0,0,0,0,0
0,88,1,1,1,1,1,1,1,1,1,1,1,1,1,1,2,2,2,95,95,0,0,92,0,0,0
0,88,1,2,2,2,1,1,1,1,1,1,1,1,1,1,2,2,2,95,95,0,0,0,0,0,0
0,88,1,2,2,2,1,1,1,1,1,1,1,1,1,1,2,2,2,0,0,0,0,0,0,0,0
0,88,1,2,2,2,1,1,1,1,1,1,1,1,1,1,2,2,2,0,0,0,0,92,91,0,0
0,88,1,1,1,1,1,1,2,2,2,1,1,1,1,1,2,2,2,0,0,0,0,91,91,0,0
0,88,1,1,1,1,1,2,2,2,2,2,1,1,1,1,1,1,1,0,0,91,0,91,0,91,91
0,88,1,1,1,1,2,2,2,2,2,2,2,1,1,1,1,1,1,0,0,0,0,91,91,91,0
0,0,88,1,1,1,2,2,2,2,2,2,2,1,1,1,88,88,0,0,0,0,91,91,91,91,0
0,0,88,88,88,88,2,2,2,2,2,2,2,88,88,88,88,0,0,0,0,0,0,91,91,0,0
0,0,0,88,88,88,88,2,2,2,2,2,91,91,0,91,91,91,0,0,0,0,0,0,91,0,0
:endlayer
layer: 10
0,0,0,0,0,0,0,0,0,91,0,0,0,0,0,0,0,0,91,91,0,0,0,0,0,0,0
0,0,0,0,0,0,0,91,88,88,88,88,88,88,88,88,88,88,88,88,88,0,99,99,99,99,0
0,0,0,0,0,0,0,0,88,2,2,2,2,2,2,2,2,2,2,2,88,99,99,99,99,99,0
0,0,0,0,0,0,0,0,88,2,2,2,2,2,2,2,2,2,2,2,88,99,99,92,99,99,0
0,0,0,0,92,0,0,0,88,2,2,2,2,2,2,2,2,2,2,2,88,99,99,99,99,99,0
0,0,0,0,0,0,0,1,1,1,1,1,1,1,1,1,1,1,1,1,88,99,99,99,99,99,0
0,0,0,0,0,0,0,1,1,1,1,1,1,1,1,1,1,1,2,1,88,0,0,92,0,0,0
0,99,99,99,99,0,88,1,1,1,1,1,1,1,1,1,1,1,2,1,82,0,0,0,0,0,0
0,99,99,99,99,99,88,1,1,1,1,1,1,1,1,1,1,1,2,1,3,82,0,0,0,0,0
0,99,99,92,99,99,88,1,1,1,1,1,1,1,1,1,1,2,3,3,3,3,82,0,0,0,0
0,99,99,99,99,99,88,1,1,1,1,1,1,1,1,1,1,2,3,3,3,3,3,0,0,0,0
0,0,99,99,99,99,2,2,1,1,1,1,1,1,1,1,1,2,3,3,3,3,82,0,0,0,0
0,0,0,0,0,0,2,2,2,1,1,1,1,1,1,1,1,2,2,2,3,82,0,0,0,0,0
0,0,0,0,0,2,2,2,2,2,1,1,1,1,1,1,1,2,3,3,82,0,0,0,0,0,0
0,0,0,0,0,2,2,2,2,2,1,1,1,1,1,1,1,2,2,2,0,0,0,0,0,0,0
0,0,0,0,2,2,2,2,2,2,3,1,82,1,1,1,1,2,2,2,0,0,0,0,0,0,0
0,0,0,91,2,2,2,2,2,2,3,1,82,1,1,1,1,2,2,2,2,99,99,99,99,0,0
0,0,0,0,1,2,2,2,2,2,3,100,82,1,1,1,2,2,2,2,88,99,99,99,99,99,0
0,0,0,0,1,2,2,2,2,2,3,0,82,1,1,2,2,2,2,1,1,88,99,92,99,99,0
0,0,0,1,1,2,2,2,2,2,3,0,82,1,1,2,2,2,2,1,1,88,99,99,99,99,0
0,0,0,1,1,2,2,2,2,2,3,0,82,1,1,2,2,2,2,2,1,88,99,99,99,99,0
0,0,0,1,1,2,2,2,2,2,3,0,82,1,1,2,2,2,2,2,1,88,0,0,0,0,0
0,0,0,1,1,1,1,1,1,1,3,90,82,1,1,2,2,2,2,2,1,88,0,0,0,0,0
0,0,88,1,1,1,1,1,1,1,3,1,82,1,1,2,2,2,2,2,1,88,0,0,0,0,0
0,0,88,1,1,1,1,1,1,1,3,1,82,1,1,2,2,2,2,2,1,88,0,0,0,0,0
0,0,88,1,1,1,1,1,1,1,3,1,82,1,1,1,2,2,2,95,95,0,0,0,0,0,0
0,0,88,1,1,1,1,1,2,2,3,1,82,1,1,2,2,2,2,95,95,0,0,0,0,0,0
0,0,88,1,1,1,1,1,2,2,2,2,1,1,1,2,2,2,2,95,95,0,99,99,99,99,0
0,0,88,1,1,1,1,1,2,2,2,2,1,1,1,2,2,2,2,0,0,99,99,99,99,99,0
0,0,2,2,2,2,2,1,1,2,2,2,1,1,1,1,2,2,2,0,0,99,99,92,99,99,0
0,0,2,2,2,2,2,1,1,1,1,1,1,1,1,2,2,2,2,0,0,99,99,99,99,99,0
0,0,2,2,2,2,2,1,1,1,1,1,1,1,1,2,2,2,2,0,0,0,99,99,99,0,0
0,0,2,2,2,2,2,1,1,1,1,1,1,1,1,2,2,2,2,0,0,0,0,92,0,0,0
0,0,2,2,2,2,2,2,2,2,2,1,1,1,1,1,2,2,2,0,0,0,0,0,0,0,0
0,0,88,1,1,1,2,2,2,2,2,2,1,1,1,1,1,2,2,0,0,0,0,0,0,0,0
0,0,88,88,1,1,2,2,2,2,2,2,2,1,1,1,1,1,88,0,0,0,0,0,0,0,0
0,0,0,88,88,88,2,2,2,2,2,2,2,1,1,1,0,0,0,0,0,0,0,0,0,0,0
0,0,91,91,91,91,0,0,0,0,0,0,0,91,91,91,0,0,0,0,0,0,0,0,0,0,0
0,0,0,98,91,91,0,0,0,0,0,0,0,0,0,0,0,0,0,0,0,0,0,0,0,0,0
:endlayer
layer: 11
0,0,0,0,0,0,0,0,0,0,0,0,0,0,0,0,0,0,0,0,0,0,0,0,0,0,0
0,0,0,0,0,0,0,0,0,91,0,0,0,0,91,91,91,91,0,91,91,0,99,0,99,0,0
0,0,0,99,99,99,0,0,91,88,88,88,88,1,88,88,88,88,88,1,0,99,99,99,99,99,0
0,0,99,99,99,99,99,0,0,88,2,2,2,2,2,2,2,2,2,88,0,99,99,92,99,99,0
0,0,99,99,92,99,99,0,0,88,2,2,2,2,2,2,2,1,2,88,0,99,99,99,99,99,0
0,0,99,99,99,99,99,88,1,1,1,1,1,1,1,1,1,1,1,1,0,0,99,99,99,99,0
0,0,0,99,99,99,0,88,1,1,1,1,1,1,1,1,1,1,1,88,0,0,0,92,0,0,0
0,99,99,99,99,99,91,88,1,1,1,1,1,1,1,1,1,1,1,1,82,0,0,0,0,0,0
0,99,99,99,99,99,91,88,1,1,1,1,1,1,1,1,1,1,1,1,3,3,0,0,0,0,0
0,99,99,92,99,99,91,88,1,1,1,1,1,1,1,1,1,2,3,3,3,3,82,0,0,0,0
0,99,99,99,99,99,91,88,1,1,1,1,1,1,1,1,1,2,3,3,3,3,101,0,0,0,0
0,99,99,99,99,0,0,2,1,1,1,1,1,1,1,1,1,2,3,3,3,3,82,0,0,0,0
0,0,0,0,0,0,0,2,2,1,1,1,1,1,1,1,1,2,1,1,3,102,0,0,0,0,0
0,0,0,0,0,0,2,2,2,2,1,1,1,1,1,1,1,2,3,3,82,0,0,0,0,0,0
0,0,0,0,0,0,2,2,2,2,1,1,1,1,1,1,1,2,1,88,0,0,0,0,0,0,0
0,0,0,0,0,2,2,2,2,2,3,1,82,1,1,1,1,2,1,88,0,0,0,0,0,0,0
0,0,0,0,2,2,2,2,2,2,3,103,82,1,1,1,2,2,1,1,0,0,99,99,99,0,0
0,0,0,0,88,2,2,2,2,2,3,0,82,1,2,2,2,2,2,1,91,99,99,99,99,99,0
0,0,0,0,2,2,2,2,2,2,3,0,82,1,2,2,2,2,2,88,88,91,99,92,99,99,0
0,0,0,88,2,2,2,2,2,2,3,0,82,1,2,2,2,2,2,95,88,91,99,99,99,99,0
0,0,0,88,2,2,2,2,2,2,3,5,82,1,2,2,2,2,2,95,95,0,99,99,99,0,0
0,0,0,88,1,2,2,2,2,2,3,90,82,2,2,2,2,2,2,95,95,91,0,0,0,0,0
0,0,0,88,1,1,2,2,2,1,3,2,82,2,2,2,2,2,2,95,95,91,0,0,0,0,0
0,0,0,88,1,1,1,1,1,1,3,2,82,2,2,2,2,2,2,95,95,91,0,0,0,0,0
0,0,91,88,1,1,1,1,1,1,3,2,82,2,1,1,2,2,2,95,95,91,0,0,0,0,0
0,0,91,88,1,1,1,2,2,2,3,2,82,1,1,1,2,2,2,0,0,0,0,0,0,0,0
0,0,0,88,1,1,1,2,2,2,3,2,82,1,1,2,2,2,2,0,0,0,0,0,0,0,0
0,0,0,88,1,1,1,2,2,2,2,2,2,1,1,2,2,2,2,0,0,99,99,99,99,0,0
0,0,0,2,2,2,1,2,2,2,2,2,2,1,1,2,2,2,2,0,0,99,99,99,99,99,0
0,0,0,2,2,2,2,2,2,2,2,2,2,2,2,1,2,2,2,0,0,99,99,92,99,99,0
0,0,0,88,2,2,2,2,2,2,2,2,2,2,2,2,2,2,2,0,0,99,99,99,99,99,0
0,0,0,88,2,2,2,2,1,1,2,2,2,2,2,2,2,2,2,0,0,99,99,99,99,99,0
0,0,0,88,2,2,2,2,2,2,2,2,2,1,1,2,2,2,2,0,0,0,0,92,0,0,0
0,0,0,2,2,2,2,2,2,2,2,1,1,1,1,1,2,2,2,0,0,0,0,0,0,0,0
0,0,91,2,2,2,2,2,2,2,2,2,1,1,1,1,1,2,0,0,0,0,0,0,0,0,0
0,0,0,0,1,2,2,2,2,2,2,2,1,1,1,88,88,88,0,0,0,0,0,0,0,0,0
0,0,0,0,91,0,0,0,0,0,0,2,2,88,88,88,0,0,0,0,0,0,0,0,0,0,0
0,0,0,0,0,0,0,0,0,0,0,0,0,0,0,0,0,0,0,0,0,0,0,0,0,0,0
0,0,0,0,0,0,0,0,0,0,0,0,0,0,0,0,0,0,0,0,0,0,0,0,0,0,0
:endlayer
layer: 12
0,0,0,0,0,0,0,0,0,0,0,0,0,0,0,0,0,0,0,0,0,0,0,0,0,0,0
0,0,0,0,0,0,0,0,0,0,0,0,0,0,0,0,0,0,0,0,0,0,0,0,0,0,0
0,0,99,99,99,99,0,0,0,0,91,0,0,92,0,105,91,91,0,92,0,0,99,99,0,0,0
0,0,99,99,99,99,99,0,0,0,88,88,88,88,88,88,88,88,88,0,99,0,99,92,99,99,0
0,0,99,99,92,99,99,0,0,0,88,0,0,0,0,0,0,1,88,99,99,99,0,99,99,99,99
0,0,99,99,99,99,99,0,1,88,88,1,1,1,1,1,1,1,88,88,99,0,0,0,0,99,0
0,0,99,99,99,99,0,0,3,88,88,1,1,1,1,1,1,1,88,0,0,0,0,92,0,0,0
0,0,0,0,0,0,0,0,88,1,1,1,1,1,1,1,1,1,1,82,82,0,0,0,0,0,0
0,0,0,99,0,0,0,91,86,1,1,1,1,1,1,1,1,1,1,1,3,3,0,0,0,0,0
0,0,99,92,99,0,0,91,86,1,3,82,1,1,1,1,1,1,3,3,3,3,3,0,0,0,0
0,0,99,99,0,0,0,91,82,1,3,3,3,3,3,1,1,1,3,3,3,3,3,0,0,0,0
0,0,0,0,0,0,0,0,86,86,3,3,82,3,3,1,1,1,3,3,3,3,82,0,0,0,0
0,0,0,0,0,0,0,0,82,1,3,82,3,3,3,1,1,1,1,3,3,3,0,0,0,0,0
0,0,0,0,0,0,0,0,82,2,3,3,82,3,3,3,3,1,3,82,82,0,0,0,0,0,0
0,0,0,0,0,0,0,0,82,2,3,3,3,3,3,3,3,1,88,0,0,0,0,0,0,0,0
0,0,0,0,0,0,2,2,2,2,3,106,82,1,3,3,3,1,88,0,0,0,0,0,0,0,0
0,0,0,0,0,2,2,2,2,2,3,0,82,1,86,86,86,86,88,88,0,0,0,0,0,0,0
0,0,0,0,0,2,2,2,2,2,3,0,82,1,2,86,86,86,86,88,0,0,0,99,0,0,0
0,0,0,0,2,88,2,2,2,2,3,0,82,2,2,2,86,86,95,98,91,0,99,92,99,0,0
0,0,0,0,88,2,2,2,2,2,3,5,82,2,2,2,2,2,95,0,104,0,99,99,0,0,0
0,0,0,0,88,2,2,2,2,2,3,90,82,2,2,2,2,2,95,0,0,0,0,0,0,0,0
0,0,0,0,88,1,2,2,2,2,3,2,82,2,2,2,2,2,2,0,0,0,0,0,0,0,0
0,0,0,91,88,1,2,2,2,1,3,2,82,2,2,2,2,2,1,0,0,0,0,0,0,0,0
0,0,0,91,88,88,1,1,1,1,3,2,82,2,2,2,2,1,1,0,0,0,0,0,0,0,0
0,0,0,98,88,88,1,1,2,2,3,2,82,2,2,2,2,2,2,0,0,0,0,0,0,0,0
0,0,0,91,88,1,1,2,2,2,3,2,82,2,2,1,2,2,2,0,0,0,0,0,0,0,0
0,0,0,91,88,1,2,2,2,2,3,2,82,1,1,2,2,2,2,0,0,0,0,0,0,0,0
0,0,0,91,88,1,2,2,2,2,2,2,2,2,1,2,2,2,2,0,0,0,0,0,0,0,0
0,0,0,0,2,2,2,2,2,2,2,2,2,2,2,2,2,2,2,0,0,0,0,99,0,0,0
0,0,0,0,88,2,2,2,2,2,2,2,2,2,2,2,2,2,3,0,0,0,99,92,99,0,0
0,0,0,0,88,2,2,2,2,2,2,2,2,2,2,2,2,2,2,0,0,99,99,99,99,99,0
0,0,0,0,2,2,2,2,1,2,2,2,2,2,2,2,2,2,0,0,0,99,99,99,99,99,0
0,0,0,0,2,2,2,2,2,2,2,2,2,2,2,2,2,2,0,0,0,99,99,92,99,99,0
0,0,0,0,0,2,2,2,2,2,2,2,2,2,2,1,2,2,0,0,0,99,99,99,99,99,0
0,0,0,0,0,0,2,2,2,2,2,2,1,1,1,1,88,0,0,0,0,0,99,99,99,0,0
0,0,0,0,92,0,0,0,2,2,2,2,88,88,1,91,91,0,0,0,0,0,0,0,0,0,0
0,0,0,0,0,0,0,0,0,0,0,107,0,0,91,91,0,0,0,0,0,0,0,0,0,0,0
0,0,0,0,0,0,0,0,0,0,0,0,0,0,0,0,0,0,0,0,0,0,0,0,0,0,0
0,0,0,0,0,0,0,0,0,0,0,0,0,0,0,0,0,0,0,0,0,0,0,0,0,0,0
:endlayer
layer: 13
0,0,0,0,0,0,0,0,0,0,0,0,0,0,0,0,0,0,0,0,0,0,0,0,0,0,0
0,0,0,0,0,0,0,0,0,0,0,0,0,0,0,0,0,0,0,0,0,0,0,0,0,0,0
0,0,0,0,0,0,0,0,0,0,0,0,0,92,0,0,0,0,0,92,99,99,0,99,99,99,99
0,0,0,0,99,99,0,0,0,0,0,0,0,0,0,0,0,0,99,99,99,99,99,99,99,99,99
0,0,0,99,92,99,0,0,0,0,0,88,88,88,88,88,88,88,99,99,99,99,99,99,99,99,99
0,0,0,99,99,0,0,0,92,91,91,88,88,1,1,1,1,88,99,99,99,99,99,99,99,99,99
0,0,0,0,0,0,0,0,3,91,91,88,88,1,1,1,1,88,0,99,99,99,109,92,99,99,99
0,0,0,0,0,0,0,0,98,86,3,1,1,1,1,1,1,1,82,82,3,111,99,108,99,0,0
0,0,0,99,0,0,0,0,0,82,82,82,1,1,1,1,1,1,3,3,3,3,110,108,108,99,0
0,0,99,99,99,0,0,0,0,82,0,0,82,82,82,1,1,1,3,3,3,3,3,0,99,0,0
0,0,0,99,0,0,0,0,0,82,0,0,0,0,0,82,1,1,3,3,3,3,3,0,0,0,0
0,0,0,0,0,0,0,0,0,0,0,0,0,0,0,82,1,1,3,3,3,3,82,0,0,0,0
0,0,0,0,0,0,0,0,0,82,0,0,0,0,0,82,82,1,3,3,3,3,0,0,0,0,0
0,0,0,0,0,0,0,0,0,82,0,0,0,0,0,0,0,3,82,112,82,0,0,0,0,0,0
0,0,0,0,0,0,0,0,0,86,0,0,0,86,0,0,0,3,0,0,0,0,0,0,0,0,0
0,0,0,0,0,0,0,0,88,86,82,0,82,86,82,0,82,3,0,0,0,0,0,0,0,0,0
0,0,0,0,0,0,2,2,88,2,3,0,82,1,0,0,0,0,91,0,0,0,0,0,0,0,0
0,0,0,0,0,0,2,88,2,2,2,0,82,1,86,0,0,0,0,0,0,0,0,99,0,0,0
0,0,0,0,114,0,88,2,2,2,2,3,82,1,2,86,0,0,0,0,0,0,99,99,99,0,0
0,0,0,0,0,1,88,2,2,2,2,1,82,2,2,2,88,95,0,0,0,0,0,99,0,0,0
0,0,0,0,0,88,88,2,2,2,2,1,82,2,2,2,88,2,0,0,0,0,0,0,0,0,0
0,0,0,0,91,88,1,2,2,2,2,2,82,2,2,1,2,2,2,0,0,0,0,0,0,0,0
0,0,0,0,104,88,88,2,2,2,2,2,82,2,2,2,2,2,88,0,0,0,0,0,0,0,0
0,0,0,0,91,91,88,88,1,2,2,2,82,2,2,2,2,2,88,0,0,0,0,0,0,0,0
0,0,0,0,91,91,88,88,88,2,2,2,82,2,2,2,2,1,1,0,0,0,0,0,0,0,0
0,0,0,0,91,1,88,88,2,2,2,2,82,2,2,2,2,2,2,0,0,0,0,0,0,0,0
0,0,0,0,0,88,2,2,2,2,2,2,82,2,1,1,2,2,2,0,0,0,0,0,0,0,0
0,0,0,0,0,88,2,2,2,2,2,2,2,2,2,1,2,2,95,0,0,0,0,0,0,0,0
0,0,0,0,0,2,88,2,2,2,2,2,2,2,2,2,2,2,95,0,0,0,0,99,0,0,0
0,0,0,0,0,2,88,2,2,2,2,2,2,2,2,2,2,2,0,0,0,0,99,99,99,0,0
0,0,0,0,0,2,88,2,2,2,2,2,2,2,2,2,2,2,0,0,0,0,99,99,99,99,0
0,0,0,0,0,88,2,2,2,2,2,2,2,2,2,2,2,2,0,0,0,99,99,99,99,99,0
0,0,0,0,0,0,2,2,2,2,2,2,2,2,2,2,2,2,0,0,0,99,99,92,99,99,0
0,0,0,0,0,0,0,82,2,2,2,2,2,2,2,1,0,0,0,0,0,99,99,99,99,99,0
0,0,0,0,0,0,0,113,82,113,2,2,1,1,113,113,0,0,0,0,0,99,99,99,99,0,0
0,0,0,0,92,0,0,0,0,0,0,0,91,91,92,0,0,0,0,0,0,0,0,0,0,0,0
0,0,0,0,0,0,0,0,0,0,0,0,0,0,0,0,0,0,0,0,0,0,0,0,0,0,0
0,0,0,0,0,0,0,0,0,0,0,0,0,0,0,0,0,0,0,0,0,0,0,0,0,0,0
0,0,0,0,0,0,0,0,0,0,0,0,0,0,0,0,0,0,0,0,0,0,0,0,0,0,0
:endlayer
layer: 14
0,0,0,0,0,0,0,0,0,0,0,0,0,0,0,0,0,0,0,0,0,0,0,0,0,0,0
0,0,0,0,0,0,0,0,0,0,0,0,0,0,0,0,0,0,0,0,0,0,0,0,0,0,0
0,0,0,0,0,0,0,0,0,0,0,0,0,92,0,0,0,0,0,92,99,99,0,0,99,99,99
0,0,0,0,99,0,0,0,0,0,0,0,0,0,0,0,0,0,99,99,99,99,99,99,99,99,99
0,0,0,99,99,99,0,0,0,0,0,0,0,0,0,0,0,0,99,99,99,99,99,99,108,99,99
0,0,0,0,99,0,0,0,92,0,0,0,0,88,88,88,88,0,99,99,99,99,99,99,108,99,99
0,0,0,0,0,0,0,0,3,0,0,0,0,88,88,88,88,0,0,5,5,109,109,92,99,99,99
0,0,0,0,0,0,0,0,0,86,3,82,82,1,1,1,1,82,82,3,3,3,99,99,108,99,99
0,0,0,0,0,0,0,0,0,82,82,82,82,1,1,1,1,3,3,3,3,3,3,99,99,99,99
0,0,0,0,0,0,0,0,0,86,0,0,82,82,82,1,1,3,3,3,3,3,3,99,108,99,99
0,0,0,0,0,0,0,0,0,82,0,0,0,0,0,82,3,3,3,3,3,3,3,99,108,99,0
0,0,0,0,0,0,0,0,0,0,0,0,0,0,0,82,82,3,3,3,3,3,3,0,99,0,0
0,0,0,0,0,0,0,0,0,86,0,0,0,0,0,82,82,82,3,3,3,3,74,0,0,0,0
0,0,0,0,0,0,0,0,0,86,0,0,0,0,0,0,0,3,82,3,3,74,0,0,0,0,0
0,0,0,0,0,0,0,0,0,82,0,0,0,86,0,0,0,3,0,0,0,0,0,0,0,0,0
0,0,0,0,0,0,0,0,0,86,82,0,82,86,82,0,82,3,0,0,0,0,0,0,0,0,0
0,0,0,0,0,0,0,0,0,1,82,0,3,88,0,0,0,0,0,0,0,0,0,0,0,0,0
0,0,0,0,0,0,0,0,88,1,82,3,82,88,0,0,0,0,0,0,0,0,0,0,0,0,0
0,0,0,0,0,0,0,88,88,1,82,3,3,1,88,0,0,0,0,0,0,0,0,0,0,0,0
0,0,0,0,0,92,91,88,1,1,82,90,82,1,1,88,0,0,0,0,0,0,0,0,0,0,0
0,0,0,0,0,91,0,1,1,2,90,90,82,1,1,88,0,0,0,0,0,0,0,0,0,0,0
0,0,0,0,0,91,88,1,2,1,90,90,90,1,1,88,0,0,0,0,0,0,0,0,0,0,0
0,0,0,0,0,91,104,88,1,1,90,90,90,1,1,2,2,0,0,0,0,0,0,0,0,0,0
0,0,0,0,0,0,91,91,88,1,3,3,3,1,88,2,2,82,0,0,0,0,0,0,0,0,0
0,0,0,0,0,0,91,0,0,88,1,3,1,88,2,2,2,88,1,0,0,0,0,0,0,0,0
0,0,0,0,0,92,0,0,88,2,88,1,1,2,2,2,115,88,0,0,0,0,0,0,0,0,0
0,0,0,0,0,91,0,86,2,2,2,2,2,2,1,1,88,2,0,0,0,0,0,0,0,0,0
0,0,0,0,0,0,0,2,2,2,2,2,2,2,2,1,88,2,0,0,0,0,0,0,0,0,0
0,0,0,0,0,0,0,2,2,2,2,2,2,2,2,2,88,2,0,0,0,0,0,0,0,0,0
0,0,0,0,0,0,0,2,2,2,2,2,2,2,2,2,2,2,0,0,0,0,0,0,0,0,0
0,0,0,0,0,0,0,3,2,2,2,2,2,2,2,2,2,0,0,0,0,0,0,0,0,0,0
0,0,0,0,0,0,0,115,2,2,2,2,2,2,2,2,2,0,0,0,0,0,0,99,99,0,0
0,0,0,0,0,0,0,3,2,2,2,2,2,2,2,2,0,0,0,0,0,0,99,92,99,0,0
0,0,0,99,99,99,99,3,1,1,2,2,2,2,1,113,0,0,0,0,0,0,0,99,99,0,0
0,0,99,99,99,99,99,86,86,86,86,113,115,3,3,113,99,0,0,0,0,0,0,0,0,0,0
0,0,99,99,92,99,99,0,0,0,0,0,99,99,92,99,99,0,0,0,0,0,0,0,0,0,0
0,0,99,99,99,99,99,0,0,0,0,0,99,99,99,99,99,0,0,0,0,0,0,0,0,0,0
0,0,0,99,99,99,0,0,0,0,0,0,99,99,99,99,0,0,0,0,0,0,0,0,0,0,0
0,0,0,0,0,0,0,0,0,0,0,0,0,0,0,0,0,0,0,0,0,0,0,0,0,0,0
:endlayer
layer: 15
0,0,0,0,0,0,0,0,0,0,0,0,99,99,99,99,0,0,99,99,99,99,0,0,0,0,0
0,0,0,0,0,0,0,0,0,0,0,99,99,99,99,99,0,99,99,99,99,99,0,0,0,0,0
0,0,0,0,0,0,0,0,0,0,0,99,99,92,99,99,0,99,99,92,99,99,0,0,0,99,0
0,0,0,0,0,0,99,99,99,99,0,99,99,99,99,99,0,99,99,99,99,99,0,0,99,108,99
0,0,0,0,0,0,99,99,99,99,99,0,99,99,99,0,0,0,99,99,99,99,99,99,99,99,99
0,0,0,0,0,0,99,99,92,99,99,0,0,91,91,91,91,0,99,109,109,99,99,99,99,99,0
0,0,0,0,0,0,99,99,3,99,99,0,0,0,0,91,91,0,118,3,31,118,99,92,99,99,99
0,0,0,0,0,0,99,99,0,86,3,82,82,82,82,82,82,82,3,3,3,3,116,108,99,99,99
0,0,0,0,0,0,0,0,0,82,82,82,3,3,3,3,3,3,3,3,3,3,3,99,108,99,99
0,0,0,0,0,0,0,0,0,86,0,0,3,82,82,82,3,3,3,3,3,3,3,99,99,99,99
0,0,0,0,0,0,0,0,0,82,0,0,0,0,0,82,82,3,3,3,3,3,3,99,99,99,99
0,0,0,0,0,0,0,0,0,86,0,0,0,0,0,82,82,3,3,3,3,3,117,99,99,99,99
0,0,0,0,0,0,0,0,0,82,0,0,0,0,0,82,82,82,3,3,3,3,3,99,99,99,0
0,0,0,0,0,0,0,0,0,86,0,0,0,0,0,0,0,3,82,3,3,3,0,0,0,0,0
0,0,0,0,0,0,0,0,0,82,0,0,0,86,0,0,0,3,0,5,5,0,0,0,0,0,0
0,0,0,0,0,0,0,0,0,86,3,0,82,86,82,0,82,3,0,0,0,0,0,0,0,0,0
0,0,0,0,0,0,0,0,0,86,3,0,3,91,0,0,0,0,0,0,0,0,0,0,0,0,0
0,0,0,0,0,0,0,0,91,86,3,3,82,0,0,0,0,0,0,0,0,0,0,0,0,0,0
0,0,0,0,0,0,0,98,104,86,3,3,82,88,0,0,0,0,0,0,0,0,0,0,0,0,0
0,0,0,0,0,92,0,91,1,1,82,90,90,1,88,91,0,0,0,0,0,0,0,0,0,0,0
0,0,0,0,0,0,0,88,1,1,1,1,1,1,88,91,0,0,0,0,0,0,0,0,0,0,0
0,0,0,0,0,0,91,88,1,1,1,0,1,1,88,91,0,0,0,0,0,0,0,0,0,0,0
0,0,0,0,0,0,0,91,88,1,1,1,1,1,88,0,0,0,0,0,0,0,0,0,0,0,0
0,0,0,0,99,99,99,0,91,88,1,1,1,88,0,0,0,0,0,0,0,0,0,0,0,0,0
0,0,0,99,99,99,99,99,0,91,88,88,88,0,0,0,0,91,92,0,0,0,0,0,0,0,0
0,0,0,99,99,92,99,99,0,0,0,88,115,0,0,82,0,91,0,0,0,0,0,0,0,0,0
0,0,0,99,99,99,99,115,2,2,2,2,2,2,1,3,0,0,0,0,0,0,0,0,0,0,0
0,0,0,99,99,99,99,86,2,2,2,2,2,2,2,1,0,0,0,0,0,0,0,0,0,0,0
0,0,0,0,0,0,0,86,2,2,2,2,2,2,2,2,0,0,0,0,0,0,0,0,0,0,0
0,0,0,0,0,0,0,86,2,2,2,2,2,2,2,2,2,0,0,0,0,0,0,0,0,0,0
0,0,0,0,0,0,0,3,2,2,2,115,2,2,2,2,0,0,0,0,0,0,0,0,0,0,0
0,0,0,0,0,0,0,113,2,2,2,2,2,2,2,82,0,0,0,0,0,0,0,99,0,0,0
0,0,0,0,0,0,0,86,2,2,2,2,2,2,2,86,0,0,0,0,0,0,99,99,99,0,0
0,0,0,99,99,99,0,115,2,2,2,2,2,2,2,3,0,0,0,0,0,0,0,99,0,0,0
0,0,99,99,99,99,99,3,82,3,113,113,82,113,115,113,99,0,0,0,0,0,0,0,0,0,0
0,0,99,99,92,99,99,0,0,0,0,0,99,99,92,99,99,0,0,0,0,0,0,0,0,0,0
0,0,99,99,99,99,99,0,0,0,0,0,99,99,99,99,99,0,0,0,0,0,0,0,0,0,0
0,0,99,99,99,99,0,0,0,0,0,0,0,99,99,99,99,0,0,0,0,0,0,0,0,0,0
0,0,0,0,0,0,0,0,0,0,0,0,0,0,0,0,0,0,0,0,0,0,0,0,0,0,0
:endlayer
layer: 16
0,0,0,0,0,0,0,0,0,0,0,0,99,99,99,99,0,0,99,99,99,0,0,0,0,0,0
0,0,0,0,0,0,0,0,0,0,0,99,99,99,99,99,0,99,99,99,99,99,0,0,99,99,99
0,0,0,0,0,0,0,0,0,0,0,99,99,92,99,99,0,99,99,92,99,99,0,99,99,99,99
0,0,0,0,0,0,99,99,99,99,99,99,99,99,99,99,0,99,99,99,99,99,0,99,99,99,99
0,0,0,0,0,0,99,99,99,99,99,99,99,99,99,99,0,99,99,99,99,99,0,99,99,99,99
0,0,0,0,0,0,99,99,92,99,99,0,0,0,0,0,0,99,99,99,99,99,99,99,99,109,99
0,0,0,0,0,0,99,99,3,129,128,126,125,124,123,122,121,3,3,3,3,3,99,92,109,99,99
0,0,0,0,0,0,99,99,118,3,3,82,82,3,3,3,82,119,119,119,119,119,3,99,99,99,99
0,0,0,0,0,0,0,0,118,86,86,86,3,86,86,3,3,119,119,119,119,119,3,99,99,99,99
0,0,0,0,0,0,0,0,118,86,82,3,86,86,3,3,3,119,119,119,119,119,3,99,108,99,99
0,0,0,0,0,0,0,0,118,86,3,3,82,3,82,82,82,119,119,3,3,3,3,99,99,99,99
0,0,0,0,0,0,0,0,118,3,3,3,82,3,3,82,3,119,119,3,3,3,3,99,99,99,99
0,0,0,0,0,0,0,0,118,3,86,3,3,82,82,82,74,3,3,3,3,3,3,99,99,99,0
0,0,0,0,0,0,0,0,118,3,3,3,3,3,3,3,3,74,3,3,3,3,74,0,0,0,0
0,0,0,0,0,0,0,0,118,86,3,3,82,86,3,3,3,3,118,3,3,120,0,0,0,0,0
0,0,0,0,0,0,0,0,118,86,3,3,3,86,3,3,3,3,0,0,0,0,0,0,0,0,0
0,0,0,0,0,0,0,0,118,0,3,3,82,0,0,0,0,0,0,0,0,0,0,0,0,0,0
0,0,0,0,0,0,0,0,0,0,3,3,3,0,0,0,0,0,0,0,0,0,0,0,0,0,0
0,0,0,0,0,0,0,0,118,86,3,3,3,0,0,0,0,0,0,0,0,0,0,0,0,0,0
0,0,0,0,0,92,0,0,86,88,88,88,88,88,0,0,0,0,0,0,0,0,0,0,0,0,0
0,0,0,0,0,0,0,91,88,88,88,88,88,88,91,0,0,0,0,0,0,0,0,0,0,0,0
0,0,0,0,0,0,0,91,88,88,86,88,88,1,0,0,0,0,0,0,0,0,0,0,0,0,0
0,0,0,0,0,0,0,0,91,88,88,88,88,86,91,0,99,99,99,99,0,0,0,0,0,0,0
0,0,0,0,99,99,99,0,0,91,1,88,88,91,0,0,99,99,99,99,99,0,0,0,0,0,0
0,0,0,99,99,99,99,99,0,0,0,98,0,0,0,0,99,99,92,99,99,0,0,0,0,0,0
0,0,0,99,99,92,99,99,0,0,0,0,113,0,0,115,99,99,99,99,99,0,0,0,0,0,0
0,0,0,99,99,99,99,3,3,82,115,88,3,3,3,82,99,99,99,99,0,0,0,0,0,0,0
0,0,0,99,99,99,99,115,2,2,2,2,2,2,2,82,0,0,0,0,0,0,0,0,0,0,0
0,0,0,0,0,0,0,113,2,2,2,2,2,2,2,86,0,0,0,0,0,0,0,0,0,0,0
0,0,0,0,0,0,0,3,2,2,2,2,2,2,2,3,0,0,0,0,0,0,0,0,0,0,0
0,0,0,0,0,0,0,86,2,2,2,127,2,2,2,86,0,0,0,0,0,0,0,0,0,0,0
0,0,0,0,0,0,0,82,2,2,2,115,2,2,2,3,0,0,0,0,0,0,0,0,0,0,0
0,0,0,0,0,0,0,3,2,2,2,2,2,2,2,82,0,0,0,0,0,0,0,0,0,0,0
0,0,0,0,0,0,0,113,2,2,2,2,2,2,2,115,0,0,0,0,0,0,0,0,0,0,0
0,0,0,0,99,99,0,86,113,113,115,86,82,113,82,86,0,0,0,0,0,0,0,0,0,0,0
0,0,0,99,92,99,0,0,0,0,0,0,0,99,92,99,0,0,0,0,0,0,0,0,0,0,0
0,0,0,99,99,0,0,0,0,0,0,0,0,99,99,99,0,0,0,0,0,0,0,0,0,0,0
0,0,0,0,0,0,0,0,0,0,0,0,0,0,0,0,0,0,0,0,0,0,0,0,0,0,0
0,0,0,0,0,0,0,0,0,0,0,0,0,0,0,0,0,0,0,0,0,0,0,0,0,0,0
:endlayer
layer: 17
0,0,0,0,0,0,0,0,0,0,0,0,0,0,0,0,0,0,0,0,0,0,0,0,0,0,0
0,0,0,0,0,0,0,0,0,0,0,0,99,99,99,0,0,0,0,99,0,0,0,0,99,99,0
0,0,0,0,0,0,0,0,0,0,0,0,99,92,99,0,0,0,99,92,99,0,0,99,99,99,99
0,0,0,0,0,0,0,0,0,0,0,0,99,99,99,0,0,0,99,99,99,0,0,99,99,99,99
0,0,0,0,0,0,0,0,99,99,0,0,0,0,0,0,0,99,99,99,99,99,99,108,99,99,99
0,0,0,0,0,0,0,99,92,99,0,0,0,0,0,0,0,99,99,99,99,99,0,108,99,99,0
0,0,0,0,0,0,0,0,3,5,5,3,5,5,3,5,5,3,31,3,3,3,0,92,99,0,99
0,0,0,0,0,0,0,0,5,0,0,0,0,0,0,0,3,0,0,0,0,133,131,99,99,99,0
0,0,0,0,0,0,0,0,5,0,0,0,0,0,0,0,136,0,0,0,0,0,90,99,99,99,99
0,0,0,0,0,0,0,0,3,0,0,0,0,0,0,0,3,0,0,0,0,134,3,99,99,99,99
0,0,0,0,0,0,0,0,5,0,0,0,0,0,0,0,3,0,31,3,3,3,132,99,99,99,99
0,0,0,0,0,0,0,0,5,0,0,143,0,0,0,82,3,8,3,3,3,3,3,99,99,99,0
0,0,0,0,0,0,0,0,3,0,0,0,0,0,0,82,3,3,3,3,3,3,3,0,0,0,0
0,0,0,0,0,0,0,0,5,0,0,0,0,0,0,0,74,3,3,3,3,3,3,130,130,130,0
0,0,0,0,0,0,0,0,5,0,0,0,0,0,0,0,0,74,3,135,3,3,74,130,130,130,0
0,0,0,0,0,0,0,0,3,0,0,0,0,0,0,0,0,0,0,0,0,0,0,0,0,0,0
0,0,0,0,0,0,0,0,0,0,0,0,0,0,0,0,0,0,0,0,0,0,0,0,0,0,0
0,0,0,99,99,99,99,0,0,0,0,0,0,0,0,0,0,0,0,0,0,0,0,0,0,0,0
0,0,0,99,99,99,99,99,0,0,0,0,0,0,0,0,0,0,0,0,0,0,0,0,0,0,0
0,0,0,99,99,92,99,99,0,0,91,91,91,91,0,0,0,0,0,0,0,0,0,0,0,0,0
0,0,0,99,99,99,99,99,0,0,91,91,91,91,0,0,0,0,0,0,0,0,0,0,0,0,0
0,0,0,99,99,99,99,0,91,91,0,0,91,92,0,0,0,0,0,0,0,0,0,0,0,0,0
0,0,0,0,0,0,0,0,0,91,91,0,91,0,0,0,99,99,99,99,0,0,0,0,0,0,0
0,0,0,0,0,0,0,0,0,0,92,91,91,0,0,0,99,99,99,99,99,0,0,0,0,0,0
0,0,0,0,99,99,99,0,0,0,0,0,0,0,0,0,99,99,92,99,99,0,0,0,0,0,0
0,0,0,0,99,92,99,0,0,0,0,0,0,0,0,0,99,99,99,99,99,0,0,0,0,0,0
0,0,0,0,99,99,99,3,86,113,82,0,86,86,113,82,99,99,99,99,0,0,0,0,0,0,0
0,0,0,0,0,0,0,86,115,0,145,0,0,0,127,113,0,0,0,0,0,0,0,0,0,0,0
0,0,0,0,0,0,0,82,147,0,0,115,0,0,0,82,0,0,0,0,0,0,0,0,0,0,0
0,0,0,0,0,0,0,86,148,0,0,0,3,0,137,82,0,0,0,0,0,0,0,0,0,0,0
0,0,0,0,0,0,0,113,115,0,141,6,141,0,138,115,0,0,0,0,0,0,0,0,0,0,0
0,0,0,0,0,0,0,115,115,0,0,0,0,0,8,115,0,0,0,0,0,0,0,0,0,0,0
0,0,0,0,0,0,0,86,149,0,0,0,0,0,139,82,0,0,0,0,0,0,0,0,0,0,0
0,0,0,0,0,0,0,113,0,146,0,144,142,0,140,113,0,0,0,0,0,0,0,0,0,0,0
0,0,0,0,99,0,0,115,3,3,3,115,115,115,86,86,0,0,0,0,0,0,0,0,0,0,0
0,0,0,99,99,99,0,0,0,0,0,0,0,99,99,99,0,0,0,0,0,0,0,0,0,0,0
0,0,0,0,99,0,0,0,0,0,0,0,0,0,99,0,0,0,0,0,0,0,0,0,0,0,0
0,0,0,0,0,0,0,0,0,0,0,0,0,0,0,0,0,0,0,0,0,0,0,0,0,0,0
0,0,0,0,0,0,0,0,0,0,0,0,0,0,0,0,0,0,0,0,0,0,0,0,0,0,0
:endlayer
layer: 18
0,0,0,0,0,0,0,0,0,0,0,0,0,0,0,0,0,0,0,0,0,0,0,0,0,0,0
0,0,0,0,0,0,0,0,0,0,0,0,0,99,0,0,0,0,0,99,0,0,0,0,0,0,0
0,0,0,0,0,0,0,0,0,0,0,0,99,99,99,0,0,0,99,99,99,0,99,99,99,99,0
0,0,0,0,0,0,0,0,0,0,0,0,0,99,0,0,0,0,0,99,0,99,99,99,99,99,99
0,0,0,0,0,0,0,0,99,0,0,0,0,0,0,0,0,0,0,99,0,99,99,99,99,99,99
0,0,0,0,0,0,0,99,99,99,0,0,0,0,0,0,0,0,99,99,99,99,99,99,99,99,99
0,0,0,0,0,0,0,0,3,0,0,0,0,0,0,0,0,86,3,3,3,3,99,92,99,99,99
0,0,0,0,0,0,0,0,0,0,0,0,0,0,0,0,86,154,46,0,46,0,3,99,99,99,99
0,0,0,0,0,0,0,0,0,0,0,0,0,0,0,0,155,0,0,0,0,0,99,99,99,99,0
0,0,0,0,0,0,0,0,0,0,0,0,0,0,0,0,3,0,0,0,0,0,3,99,99,99,99
0,0,0,0,0,0,0,0,0,0,0,0,0,0,0,156,3,0,0,3,3,3,3,99,99,99,99
0,0,0,0,0,0,0,0,0,0,0,0,0,0,0,3,3,0,31,3,3,3,3,99,99,99,0
0,0,0,0,0,0,0,0,0,0,0,0,0,0,0,3,3,3,3,3,3,3,3,0,152,150,0
0,0,0,0,0,0,0,0,0,0,0,0,0,0,0,74,3,3,3,3,3,3,3,3,151,151,0
0,0,0,0,0,0,0,0,0,0,0,0,0,0,0,0,74,3,3,3,153,3,3,3,151,151,0
0,0,0,0,0,0,0,0,0,0,0,0,0,0,0,0,0,0,0,0,0,0,0,0,0,0,0
0,0,0,0,0,0,0,0,0,0,0,0,0,0,0,0,0,0,0,0,0,0,0,0,0,0,0
0,0,0,0,99,99,99,99,0,0,0,0,0,0,0,0,0,0,0,0,0,0,0,0,0,0,0
0,0,0,99,99,99,99,99,0,0,0,0,0,0,0,0,0,0,0,0,0,0,0,0,0,0,0
0,0,0,99,99,92,99,99,0,0,0,0,0,0,0,0,0,0,0,0,0,0,0,0,0,0,0
0,0,0,99,99,99,99,99,0,0,0,0,0,0,0,0,0,0,0,0,0,0,0,0,0,0,0
0,0,0,99,99,99,99,0,0,0,0,0,0,92,0,0,0,0,0,0,0,0,0,0,0,0,0
0,0,0,0,0,0,0,0,0,0,99,0,0,0,0,0,0,0,0,0,0,0,0,0,0,0,0
0,0,0,0,0,0,0,0,0,99,92,99,0,0,0,0,0,0,99,0,0,0,0,0,0,0,0
0,0,0,0,0,99,0,0,0,0,99,0,0,0,0,0,0,99,92,99,0,0,0,0,0,0,0
0,0,0,0,99,99,99,0,0,0,0,0,0,0,0,0,0,99,99,0,0,0,0,0,0,0,0
0,0,0,0,0,99,0,86,82,115,86,0,86,82,82,86,0,0,0,0,0,0,0,0,0,0,0
0,0,0,0,0,0,0,86,115,0,0,0,0,0,0,113,0,0,0,0,0,0,0,0,0,0,0
0,0,0,0,0,0,0,86,0,0,0,82,0,0,0,86,0,0,0,0,0,0,0,0,0,0,0
0,0,0,0,0,0,0,113,0,0,0,0,3,0,0,86,0,0,0,0,0,0,0,0,0,0,0
0,0,0,0,0,0,0,82,115,0,0,0,0,0,0,86,0,0,0,0,0,0,0,0,0,0,0
0,0,0,0,0,0,0,115,157,0,0,0,0,0,0,86,0,0,0,0,0,0,0,0,0,0,0
0,0,0,0,0,0,0,86,0,0,0,0,0,0,0,115,0,0,0,0,0,0,0,0,0,0,0
0,0,0,0,0,0,0,115,0,0,0,0,0,0,0,86,0,0,0,0,0,0,0,0,0,0,0
0,0,0,0,0,0,0,86,115,82,86,82,86,86,115,113,0,0,0,0,0,0,0,0,0,0,0
0,0,0,0,0,0,0,0,0,0,0,0,0,0,0,0,0,0,0,0,0,0,0,0,0,0,0
0,0,0,0,0,0,0,0,0,0,0,0,0,0,0,0,0,0,0,0,0,0,0,0,0,0,0
0,0,0,0,0,0,0,0,0,0,0,0,0,0,0,0,0,0,0,0,0,0,0,0,0,0,0
0,0,0,0,0,0,0,0,0,0,0,0,0,0,0,0,0,0,0,0,0,0,0,0,0,0,0
:endlayer
layer: 19
0,0,0,0,0,0,0,0,0,0,0,0,0,0,0,0,0,0,0,0,0,0,0,0,0,0,0
0,0,0,0,0,0,0,0,0,0,0,0,0,0,0,0,0,0,0,0,0,0,0,0,0,0,0
0,0,0,0,0,0,0,0,0,0,0,0,0,0,0,0,0,0,0,0,0,0,0,99,0,0,0
0,0,0,0,0,0,0,0,0,0,0,0,0,0,0,0,0,0,0,0,0,0,99,99,99,99,0
0,0,0,0,0,0,0,0,0,0,0,0,0,0,0,0,0,0,0,0,0,99,99,99,99,99,0
0,0,0,0,0,0,0,0,0,0,0,0,0,0,0,0,0,0,0,0,0,99,99,99,99,99,99
0,0,0,0,0,0,0,0,0,0,0,0,0,0,0,0,0,3,86,86,162,3,99,99,99,99,99
0,0,0,0,0,0,0,0,0,0,0,0,0,0,0,0,86,0,0,0,0,99,3,99,99,99,0
0,0,0,0,0,0,0,0,0,0,0,0,0,0,0,0,3,0,0,0,0,0,160,151,99,0,0
0,0,0,0,0,0,0,0,0,0,0,0,0,0,0,0,3,0,0,0,0,0,3,99,99,99,0
0,0,0,0,0,0,0,0,0,0,0,0,0,0,0,3,3,0,0,3,3,3,161,0,99,0,0
0,0,0,0,0,0,0,0,0,0,0,0,0,0,0,86,3,0,0,3,3,3,3,0,159,158,0
0,0,0,0,0,0,0,0,0,0,0,0,0,0,0,3,151,151,151,151,151,3,3,0,0,0,0
0,0,0,0,0,0,0,0,0,0,0,0,0,0,0,3,151,151,151,151,151,73,0,0,0,0,0
0,0,0,0,0,0,0,0,0,0,0,0,0,0,0,0,3,163,3,3,3,3,0,0,0,0,0
0,0,0,0,0,0,0,0,0,0,0,0,0,0,0,0,0,0,0,0,0,0,0,0,0,0,0
0,0,0,0,0,0,0,0,0,0,0,0,0,0,0,0,0,0,0,0,0,0,0,0,0,0,0
0,0,0,0,0,0,0,0,0,0,0,0,0,0,0,0,0,0,0,0,0,0,0,0,0,0,0
0,0,0,0,99,99,0,0,0,0,0,0,0,0,0,0,0,0,0,0,0,0,0,0,0,0,0
0,0,0,0,99,92,99,0,0,0,0,99,99,99,99,99,0,0,0,0,0,0,0,0,0,0,0
0,0,0,0,0,99,99,0,0,0,0,99,99,99,99,99,0,0,0,0,0,0,0,0,0,0,0
0,0,0,0,0,0,0,0,0,99,99,99,99,92,99,99,0,0,0,0,0,0,0,0,0,0,0
0,0,0,0,0,0,0,0,99,99,99,99,99,99,99,99,0,0,0,0,0,0,0,0,0,0,0
0,0,0,0,0,0,0,0,99,99,92,99,99,99,99,99,0,0,99,0,0,0,0,0,0,0,0
0,0,0,0,0,0,0,0,99,99,99,99,99,0,0,0,0,99,99,99,0,0,0,0,0,0,0
0,0,0,0,0,0,0,0,0,99,99,99,0,0,0,0,0,0,99,0,0,0,0,0,0,0,0
0,0,0,0,0,0,0,3,86,3,86,0,113,82,113,113,0,0,0,0,0,0,0,0,0,0,0
0,0,0,0,0,0,0,82,115,0,0,0,46,0,0,115,0,0,0,0,0,0,0,0,0,0,0
0,0,0,0,0,0,0,115,74,0,0,86,0,0,0,3,0,0,0,0,0,0,0,0,0,0,0
0,0,0,0,0,0,0,86,165,0,0,0,0,0,0,82,0,0,0,0,0,0,0,0,0,0,0
0,0,0,0,0,0,0,86,166,0,0,0,0,0,0,115,0,0,0,0,0,0,0,0,0,0,0
0,0,0,0,0,0,0,115,0,0,0,0,0,0,0,82,0,0,0,0,0,0,0,0,0,0,0
0,0,0,0,0,0,0,3,0,0,0,0,0,0,0,3,0,0,0,0,0,0,0,0,0,0,0
0,0,0,0,0,0,0,86,0,0,0,164,0,0,0,3,0,0,0,0,0,0,0,0,0,0,0
0,0,0,0,0,0,0,115,82,115,113,113,3,113,113,82,0,0,0,0,0,0,0,0,0,0,0
0,0,0,0,0,0,0,0,0,0,0,0,0,0,0,0,0,0,0,0,0,0,0,0,0,0,0
0,0,0,0,0,0,0,0,0,0,0,0,0,0,0,0,0,0,0,0,0,0,0,0,0,0,0
0,0,0,0,0,0,0,0,0,0,0,0,0,0,0,0,0,0,0,0,0,0,0,0,0,0,0
0,0,0,0,0,0,0,0,0,0,0,0,0,0,0,0,0,0,0,0,0,0,0,0,0,0,0
:endlayer
layer: 20
0,0,0,0,0,0,0,0,0,0,0,0,0,0,0,0,0,0,0,0,0,0,0,0,0,0,0
0,0,0,0,0,0,0,0,0,0,0,0,0,0,0,0,0,0,0,0,0,0,0,0,0,0,0
0,0,0,0,0,0,0,0,0,0,0,0,0,0,0,0,0,0,0,0,0,0,0,0,0,0,0
0,0,0,0,0,0,0,0,0,0,0,0,0,0,0,0,0,0,0,0,0,0,0,99,0,0,0
0,0,0,0,0,0,0,0,0,0,0,0,0,0,0,0,0,0,0,0,0,0,99,99,99,0,0
0,0,0,0,0,0,0,0,0,0,0,0,0,0,0,0,0,0,0,0,0,99,99,99,99,99,0
0,0,0,0,0,0,0,0,0,0,0,0,0,0,0,0,0,171,3,86,86,3,99,99,99,99,0
0,0,0,0,0,0,0,0,0,0,0,0,0,0,0,0,86,0,0,0,0,99,169,99,99,0,0
0,0,0,0,0,0,0,0,0,0,0,0,0,0,0,0,14,0,0,0,0,0,3,99,0,0,0
0,0,0,0,0,0,0,0,0,0,0,0,0,0,0,0,3,0,0,0,0,0,3,0,0,0,0
0,0,0,0,0,0,0,0,0,0,0,0,0,0,0,86,3,0,0,3,3,3,3,0,168,167,0
0,0,0,0,0,0,0,0,0,0,0,0,0,0,0,86,3,0,0,3,3,3,3,0,0,0,0
0,0,0,0,0,0,0,0,0,0,0,0,0,0,0,0,0,0,0,0,0,3,3,43,0,0,0
0,0,0,0,0,0,0,0,0,0,0,0,0,0,0,3,0,172,0,0,0,0,0,0,0,0,0
0,0,0,0,0,0,0,0,0,0,0,0,0,0,0,0,3,3,74,3,3,170,0,0,0,0,0
0,0,0,0,0,0,0,0,0,0,0,0,0,0,0,0,0,0,0,0,0,0,0,0,0,0,0
0,0,0,0,0,0,0,0,0,0,0,0,0,0,0,0,0,0,0,0,0,0,0,0,0,0,0
0,0,0,0,0,0,0,0,0,0,0,0,0,0,0,0,0,0,0,0,0,0,0,0,0,0,0
0,0,0,0,0,99,0,0,0,0,0,0,0,0,0,0,0,0,0,0,0,0,0,0,0,0,0
0,0,0,0,99,99,99,0,0,0,0,0,99,99,99,0,0,0,0,0,0,0,0,0,0,0,0
0,0,0,0,0,99,0,0,0,0,0,99,99,99,99,99,0,0,0,0,0,0,0,0,0,0,0
0,0,0,0,0,0,0,0,0,99,99,99,99,92,99,99,0,0,0,0,0,0,0,0,0,0,0
0,0,0,0,0,0,0,0,99,99,99,99,99,99,99,99,0,0,0,0,0,0,0,0,0,0,0
0,0,0,0,0,0,0,0,99,99,92,99,99,99,99,99,0,0,0,0,0,0,0,0,0,0,0
0,0,0,0,0,0,0,0,99,99,99,99,99,0,0,0,0,0,0,0,0,0,0,0,0,0,0
0,0,0,0,0,0,0,0,0,99,99,99,0,0,0,0,0,0,0,0,0,0,0,0,0,0,0
0,0,0,0,0,0,0,115,86,86,115,86,113,82,113,86,0,0,0,0,0,0,0,0,0,0,0
0,0,0,0,0,0,0,115,115,0,0,0,0,0,0,113,0,0,0,0,0,0,0,0,0,0,0
0,0,0,0,0,0,0,3,115,0,0,0,0,0,0,86,0,0,0,0,0,0,0,0,0,0,0
0,0,0,0,0,0,0,82,173,0,0,0,0,0,0,115,0,0,0,0,0,0,0,0,0,0,0
0,0,0,0,0,0,0,86,0,0,0,0,0,0,0,82,0,0,0,0,0,0,0,0,0,0,0
0,0,0,0,0,0,0,115,0,0,0,0,0,0,0,115,0,0,0,0,0,0,0,0,0,0,0
0,0,0,0,0,0,0,115,0,0,0,0,0,0,0,82,0,0,0,0,0,0,0,0,0,0,0
0,0,0,0,0,0,0,86,0,0,0,0,0,0,0,113,0,0,0,0,0,0,0,0,0,0,0
0,0,0,0,0,0,0,86,115,113,115,113,115,82,113,82,0,0,0,0,0,0,0,0,0,0,0
0,0,0,0,0,0,0,0,0,0,0,0,0,0,0,0,0,0,0,0,0,0,0,0,0,0,0
0,0,0,0,0,0,0,0,0,0,0,0,0,0,0,0,0,0,0,0,0,0,0,0,0,0,0
0,0,0,0,0,0,0,0,0,0,0,0,0,0,0,0,0,0,0,0,0,0,0,0,0,0,0
0,0,0,0,0,0,0,0,0,0,0,0,0,0,0,0,0,0,0,0,0,0,0,0,0,0,0
:endlayer
layer: 21
0,0,0,0,0,0,0,0,0,0,0,0,0,0,0,0,0,0,0,0,0,0,0,0,0,0,0
0,0,0,0,0,0,0,0,0,0,0,0,0,0,0,0,0,0,0,0,0,0,0,0,0,0,0
0,0,0,0,0,0,0,0,0,0,0,0,0,0,0,0,0,0,0,0,0,0,0,0,0,0,0
0,0,0,0,0,0,0,0,0,0,0,0,0,0,0,0,0,0,0,0,0,0,0,0,0,0,0
0,0,0,0,0,0,0,0,0,0,0,0,0,0,0,0,0,0,0,0,0,0,0,0,0,0,0
0,0,0,0,0,0,0,0,0,0,0,0,0,0,0,0,0,0,0,0,0,0,0,99,0,0,0
0,0,0,0,0,0,0,0,0,0,0,0,0,0,0,0,0,86,3,178,86,86,99,99,99,0,0
0,0,0,0,0,0,0,0,0,0,0,0,0,0,0,0,86,0,0,0,0,0,3,99,0,0,0
0,0,0,0,0,0,0,0,0,0,0,0,0,0,0,0,3,0,0,0,0,0,3,0,0,0,0
0,0,0,0,0,0,0,0,0,0,0,0,0,0,0,181,3,0,0,0,0,0,176,5,175,174,0
0,0,0,0,0,0,0,0,0,0,0,0,0,0,0,86,3,0,0,3,3,3,3,5,0,0,0
0,0,0,0,0,0,0,0,0,0,0,0,0,0,0,3,3,0,0,3,3,3,3,5,0,0,0
0,0,0,0,0,0,0,0,0,0,0,0,0,0,151,160,0,0,0,0,0,3,177,0,0,0,0
0,0,0,0,0,0,0,0,0,0,0,0,0,0,0,3,0,180,0,179,0,160,0,0,0,0,0
0,0,0,0,0,0,0,0,0,0,0,0,0,0,0,0,86,3,3,3,3,3,0,0,0,0,0
0,0,0,0,0,0,0,0,0,0,0,0,0,0,0,0,0,0,5,5,0,0,0,0,0,0,0
0,0,0,0,0,0,0,0,0,0,0,0,0,0,0,0,0,0,0,0,0,0,0,0,0,0,0
0,0,0,0,0,0,0,0,0,0,0,0,0,0,0,0,0,0,0,0,0,0,0,0,0,0,0
0,0,0,0,0,0,0,0,0,0,0,0,0,0,0,0,0,0,0,0,0,0,0,0,0,0,0
0,0,0,0,0,0,0,0,0,0,0,0,0,0,0,0,0,0,0,0,0,0,0,0,0,0,0
0,0,0,0,0,0,0,0,0,0,0,0,0,99,99,0,0,0,0,0,0,0,0,0,0,0,0
0,0,0,0,0,0,0,0,0,99,99,99,99,92,99,0,0,0,0,0,0,0,0,0,0,0,0
0,0,0,0,0,0,0,0,99,99,99,99,99,99,99,0,0,0,0,0,0,0,0,0,0,0,0
0,0,0,0,0,0,0,0,99,99,99,99,99,0,0,0,0,0,0,0,0,0,0,0,0,0,0
0,0,0,0,0,0,0,0,99,99,99,99,99,0,0,0,0,0,0,0,0,0,0,0,0,0,0
0,0,0,0,0,0,0,0,0,99,99,99,0,0,0,0,0,0,0,0,0,0,0,0,0,0,0
0,0,0,0,0,0,0,82,86,113,86,113,82,82,86,113,0,0,0,0,0,0,0,0,0,0,0
0,0,0,0,0,0,0,86,115,115,0,0,0,0,0,3,0,0,0,0,0,0,0,0,0,0,0
0,0,0,0,0,0,0,113,182,0,0,0,0,0,0,113,0,0,0,0,0,0,0,0,0,0,0
0,0,0,0,0,0,0,3,0,0,0,0,0,0,0,82,0,0,0,0,0,0,0,0,0,0,0
0,0,0,0,0,0,0,113,0,0,0,0,0,0,0,86,0,0,0,0,0,0,0,0,0,0,0
0,0,0,0,0,0,0,115,0,0,0,0,0,0,0,3,0,0,0,0,0,0,0,0,0,0,0
0,0,0,0,0,0,0,3,0,0,0,0,0,0,0,82,0,0,0,0,0,0,0,0,0,0,0
0,0,0,0,0,0,0,113,0,0,0,0,0,0,0,3,0,0,0,0,0,0,0,0,0,0,0
0,0,0,0,0,0,0,3,115,115,3,113,86,115,113,113,0,0,0,0,0,0,0,0,0,0,0
0,0,0,0,0,0,0,0,0,0,0,0,0,0,0,0,0,0,0,0,0,0,0,0,0,0,0
0,0,0,0,0,0,0,0,0,0,0,0,0,0,0,0,0,0,0,0,0,0,0,0,0,0,0
0,0,0,0,0,0,0,0,0,0,0,0,0,0,0,0,0,0,0,0,0,0,0,0,0,0,0
0,0,0,0,0,0,0,0,0,0,0,0,0,0,0,0,0,0,0,0,0,0,0,0,0,0,0
:endlayer
layer: 22
0,0,0,0,0,0,0,0,0,0,0,0,0,0,0,0,0,0,0,0,0,0,0,0,0,0,0
0,0,0,0,0,0,0,0,0,0,0,0,0,0,0,0,0,0,0,0,0,0,0,0,0,0,0
0,0,0,0,0,0,0,0,0,0,0,0,0,0,0,0,0,0,0,0,0,0,0,0,0,0,0
0,0,0,0,0,0,0,0,0,0,0,0,0,0,0,0,0,0,0,0,0,0,0,0,0,0,0
0,0,0,0,0,0,0,0,0,0,0,0,0,0,0,0,0,0,0,0,0,0,0,0,0,0,0
0,0,0,0,0,0,0,0,0,0,0,0,0,0,0,0,0,0,0,0,0,0,0,0,0,0,0
0,0,0,0,0,0,0,0,0,0,0,0,0,0,0,0,0,86,31,3,3,86,130,130,130,130,0
0,0,0,0,0,0,0,0,0,0,0,0,0,0,0,0,14,74,74,74,74,74,3,130,130,130,0
0,0,0,0,0,0,0,0,0,0,0,0,0,0,0,0,3,0,0,0,0,0,3,185,184,183,0
0,0,0,0,0,0,0,0,0,0,0,0,0,0,0,14,3,0,5,190,188,187,3,3,0,0,0
0,0,0,0,0,0,0,0,0,0,0,0,0,0,0,3,3,0,118,3,3,3,3,186,0,0,0
0,0,0,0,0,0,0,0,0,0,0,0,0,0,5,3,3,0,118,3,3,3,3,3,0,0,0
0,0,0,0,0,0,0,0,0,0,0,0,0,0,0,3,191,0,5,74,74,3,3,74,0,0,0
0,0,0,0,0,0,0,0,0,0,0,0,0,0,0,3,192,0,0,0,0,3,0,0,0,0,0
0,0,0,0,0,0,0,0,0,0,0,0,0,0,0,0,86,3,3,3,3,3,0,0,0,0,0
0,0,0,0,0,0,0,0,0,0,0,0,0,0,0,0,0,118,3,3,189,0,0,0,0,0,0
0,0,0,0,0,0,0,0,0,0,0,0,0,0,0,0,0,0,0,0,0,0,0,0,0,0,0
0,0,0,0,0,0,0,0,0,0,0,0,0,0,0,0,0,0,0,0,0,0,0,0,0,0,0
0,0,0,0,0,0,0,0,0,0,0,0,0,0,0,0,0,0,0,0,0,0,0,0,0,0,0
0,0,0,0,0,0,0,0,0,0,0,0,0,0,0,0,0,0,0,0,0,0,0,0,0,0,0
0,0,0,0,0,0,0,0,0,0,0,0,0,99,0,0,0,0,0,0,0,0,0,0,0,0,0
0,0,0,0,0,0,0,0,0,0,0,0,99,99,99,0,0,0,0,0,0,0,0,0,0,0,0
0,0,0,0,0,0,0,0,0,0,99,0,0,99,0,0,0,0,0,0,0,0,0,0,0,0,0
0,0,0,0,0,0,0,0,0,99,99,99,0,0,0,0,0,0,0,0,0,0,0,0,0,0,0
0,0,0,0,0,0,0,0,0,0,99,0,0,0,0,0,0,0,0,0,0,0,0,0,0,0,0
0,0,0,0,0,0,0,0,0,0,0,0,0,0,0,0,0,0,0,0,0,0,0,0,0,0,0
0,0,0,0,0,0,0,82,86,82,82,86,115,82,113,86,0,0,0,0,0,0,0,0,0,0,0
0,0,0,0,0,0,0,82,0,0,14,115,119,119,119,3,0,0,0,0,0,0,0,0,0,0,0
0,0,0,0,0,0,0,113,0,0,119,119,119,119,119,113,0,0,0,0,0,0,0,0,0,0,0
0,0,0,0,0,0,0,3,0,0,119,119,0,119,119,115,0,0,0,0,0,0,0,0,0,0,0
0,0,0,0,0,0,0,3,0,119,119,119,119,119,119,115,0,0,0,0,0,0,0,0,0,0,0
0,0,0,0,0,0,0,86,119,119,119,119,119,0,119,3,0,0,0,0,0,0,0,0,0,0,0
0,0,0,0,0,0,0,3,119,119,119,119,119,119,119,82,0,0,0,0,0,0,0,0,0,0,0
0,0,0,0,0,0,0,115,119,119,119,119,119,119,119,113,0,0,0,0,0,0,0,0,0,0,0
0,0,0,0,0,0,0,82,113,82,86,82,86,3,86,115,0,0,0,0,0,0,0,0,0,0,0
0,0,0,0,0,0,0,0,0,0,0,0,0,0,0,0,0,0,0,0,0,0,0,0,0,0,0
0,0,0,0,0,0,0,0,0,0,0,0,0,0,0,0,0,0,0,0,0,0,0,0,0,0,0
0,0,0,0,0,0,0,0,0,0,0,0,0,0,0,0,0,0,0,0,0,0,0,0,0,0,0
0,0,0,0,0,0,0,0,0,0,0,0,0,0,0,0,0,0,0,0,0,0,0,0,0,0,0
:endlayer
layer: 23
0,0,0,0,0,0,0,0,0,0,0,0,0,0,0,0,0,0,0,0,0,0,0,0,0,0,0
0,0,0,0,0,0,0,0,0,0,0,0,0,0,0,0,0,0,0,0,0,0,0,0,0,0,0
0,0,0,0,0,0,0,0,0,0,0,0,0,0,0,0,0,0,0,0,0,0,0,0,0,0,0
0,0,0,0,0,0,0,0,0,0,0,0,0,0,0,0,0,0,0,0,0,0,0,0,0,0,0
0,0,0,0,0,0,0,0,0,0,0,0,0,0,0,0,0,0,0,0,0,0,0,0,0,0,0
0,0,0,0,0,0,0,0,0,0,0,0,0,0,0,0,0,0,0,0,0,0,0,0,0,0,0
0,0,0,0,0,0,0,0,0,0,0,0,0,0,0,0,0,86,3,3,31,86,86,3,151,151,0
0,0,0,0,0,0,0,0,0,0,0,0,0,0,0,0,3,3,3,3,3,3,119,3,151,151,0
0,0,0,0,0,0,0,0,0,0,0,0,0,0,0,0,3,3,3,3,3,3,3,3,0,0,0
0,0,0,0,0,0,0,0,0,0,0,0,0,0,0,3,3,3,3,3,3,3,3,86,0,0,0
0,0,0,0,0,0,0,0,0,0,0,0,0,0,198,3,3,3,3,3,3,3,3,86,0,0,0
0,0,0,0,0,0,0,0,0,0,0,0,0,0,3,3,3,3,3,3,3,3,119,86,0,0,0
0,0,0,0,0,0,0,0,0,0,0,0,0,0,74,3,3,3,3,3,3,3,119,193,0,0,0
0,0,0,0,0,0,0,0,0,0,0,0,0,0,0,3,3,3,3,3,3,119,3,0,0,0,0
0,0,0,0,0,0,0,0,0,0,0,0,0,0,0,0,86,3,3,3,3,194,0,0,0,0,0
0,0,0,0,0,0,0,0,0,0,0,0,0,0,0,0,0,74,3,195,3,0,0,0,0,0,0
0,0,0,0,0,0,0,0,0,0,0,0,0,0,0,0,0,0,0,0,0,0,0,0,0,0,0
0,0,0,0,0,0,0,0,0,0,0,0,0,0,0,0,0,0,0,0,0,0,0,0,0,0,0
0,0,0,0,0,0,0,0,0,0,0,0,0,0,0,0,0,0,0,0,0,0,0,0,0,0,0
0,0,0,0,0,0,0,0,0,0,0,0,0,0,0,0,0,0,0,0,0,0,0,0,0,0,0
0,0,0,0,0,0,0,0,0,0,0,0,0,0,0,0,0,0,0,0,0,0,0,0,0,0,0
0,0,0,0,0,0,0,0,0,0,0,0,0,0,0,0,0,0,0,0,0,0,0,0,0,0,0
0,0,0,0,0,0,0,0,0,0,0,0,0,0,0,0,0,0,0,0,0,0,0,0,0,0,0
0,0,0,0,0,0,0,0,0,0,0,0,0,0,0,0,0,0,0,0,0,0,0,0,0,0,0
0,0,0,0,0,0,0,0,0,0,0,0,0,0,0,0,0,0,0,0,0,0,0,0,0,0,0
0,0,0,0,0,0,0,0,0,0,0,0,0,0,0,0,0,0,0,0,0,0,0,0,0,0,0
0,0,0,0,0,0,0,115,113,3,86,86,3,86,115,0,0,0,0,0,0,0,0,0,0,0,0
0,0,0,0,0,0,0,204,0,0,0,0,0,0,0,3,0,0,0,0,0,0,0,0,0,0,0
0,0,0,0,0,0,0,3,0,0,0,0,0,0,0,196,0,0,0,0,0,0,0,0,0,0,0
0,0,0,0,0,0,0,113,0,0,0,0,0,200,0,86,0,0,0,0,0,0,0,0,0,0,0
0,0,0,0,0,0,0,86,0,0,0,0,0,0,0,82,0,0,0,0,0,0,0,0,0,0,0
0,0,0,0,0,0,0,205,0,0,203,202,0,0,0,197,0,0,0,0,0,0,0,0,0,0,0
0,0,0,0,0,0,0,3,0,0,0,0,0,0,0,3,0,0,0,0,0,0,0,0,0,0,0
0,0,0,0,0,0,0,86,0,0,0,0,0,0,199,3,0,0,0,0,0,0,0,0,0,0,0
0,0,0,0,0,0,0,86,115,86,3,86,201,86,113,3,0,0,0,0,0,0,0,0,0,0,0
0,0,0,0,0,0,0,0,0,0,0,0,0,0,0,0,0,0,0,0,0,0,0,0,0,0,0
0,0,0,0,0,0,0,0,0,0,0,0,0,0,0,0,0,0,0,0,0,0,0,0,0,0,0
0,0,0,0,0,0,0,0,0,0,0,0,0,0,0,0,0,0,0,0,0,0,0,0,0,0,0
0,0,0,0,0,0,0,0,0,0,0,0,0,0,0,0,0,0,0,0,0,0,0,0,0,0,0
:endlayer
layer: 24
0,0,0,0,0,0,0,0,0,0,0,0,0,0,0,0,0,0,0,0,0,0,0,0,0,0,0
0,0,0,0,0,0,0,0,0,0,0,0,0,0,0,0,0,0,0,0,0,0,0,0,0,0,0
0,0,0,0,0,0,0,0,0,0,0,0,0,0,0,0,0,0,0,0,0,0,0,0,0,0,0
0,0,0,0,0,0,0,0,0,0,0,0,0,0,0,0,0,0,0,0,0,0,0,0,0,0,0
0,0,0,0,0,0,0,0,0,0,0,0,0,0,0,0,0,0,0,0,0,0,0,0,0,0,0
0,0,0,0,0,0,0,0,0,0,0,0,0,0,0,0,0,0,0,0,5,0,0,0,0,0,0
0,0,0,0,0,0,0,0,0,0,0,0,0,0,0,0,216,86,86,3,3,208,86,206,0,0,0
0,0,0,0,0,0,0,0,0,0,0,0,0,0,0,0,3,3,212,151,151,151,73,0,0,0,0
0,0,0,0,0,0,0,0,0,0,0,0,0,0,0,0,3,3,151,151,151,151,3,86,0,0,0
0,0,0,0,0,0,0,0,0,0,0,0,0,0,0,3,3,3,150,151,151,150,151,86,0,0,0
0,0,0,0,0,0,0,0,0,0,0,0,0,0,118,0,217,214,0,0,0,0,0,3,5,0,0
0,0,0,0,0,0,0,0,0,0,0,0,0,0,3,219,0,215,0,127,0,0,207,3,0,0,0
0,0,0,0,0,0,0,0,0,0,0,0,0,0,3,220,218,13,0,0,0,209,8,3,0,0,0
0,0,0,0,0,0,0,0,0,0,0,0,0,0,0,221,3,12,213,0,211,210,3,0,0,0,0
0,0,0,0,0,0,0,0,0,0,0,0,0,0,0,0,86,3,151,151,151,3,0,0,0,0,0
0,0,0,0,0,0,0,0,0,0,0,0,0,0,0,0,0,3,3,3,3,0,0,0,0,0,0
0,0,0,0,0,0,0,0,0,0,0,0,0,0,0,0,0,0,0,0,0,0,0,0,0,0,0
0,0,0,0,0,0,0,0,0,0,0,0,0,0,0,0,0,0,0,0,0,0,0,0,0,0,0
0,0,0,0,0,0,0,0,0,0,0,0,0,0,0,0,0,0,0,0,0,0,0,0,0,0,0
0,0,0,0,0,0,0,0,0,0,0,0,0,0,0,0,0,0,0,0,0,0,0,0,0,0,0
0,0,0,0,0,0,0,0,0,0,0,0,0,0,0,0,0,0,0,0,0,0,0,0,0,0,0
0,0,0,0,0,0,0,0,0,0,0,0,0,0,0,0,0,0,0,0,0,0,0,0,0,0,0
0,0,0,0,0,0,0,0,0,0,0,0,0,0,0,0,0,0,0,0,0,0,0,0,0,0,0
0,0,0,0,0,0,0,0,0,0,0,0,0,0,0,0,0,0,0,0,0,0,0,0,0,0,0
0,0,0,0,0,0,0,0,0,0,0,0,0,0,0,0,0,0,0,0,0,0,0,0,0,0,0
0,0,0,0,0,0,0,0,0,0,0,0,0,0,0,0,0,0,0,0,0,0,0,0,0,0,0
0,0,0,0,0,0,0,82,113,82,3,82,113,82,0,0,0,0,0,0,0,0,0,0,0,0,0
0,0,0,0,0,0,0,0,0,0,0,0,0,0,0,86,0,0,0,0,0,0,0,0,0,0,0
0,0,0,0,0,0,0,82,0,0,0,0,0,0,0,0,0,0,0,0,0,0,0,0,0,0,0
0,0,0,0,0,0,0,115,0,0,0,0,0,0,0,82,0,0,0,0,0,0,0,0,0,0,0
0,0,0,0,0,0,0,3,0,0,0,0,0,0,0,115,0,0,0,0,0,0,0,0,0,0,0
0,0,0,0,0,0,0,0,0,0,0,0,0,0,0,0,0,0,0,0,0,0,0,0,0,0,0
0,0,0,0,0,0,0,115,0,0,0,0,0,0,0,86,0,0,0,0,0,0,0,0,0,0,0
0,0,0,0,0,0,0,0,0,0,0,0,0,0,0,115,0,0,0,0,0,0,0,0,0,0,0
0,0,0,0,0,0,0,113,113,86,82,113,0,113,86,82,0,0,0,0,0,0,0,0,0,0,0
0,0,0,0,0,0,0,0,0,0,0,0,0,0,0,0,0,0,0,0,0,0,0,0,0,0,0
0,0,0,0,0,0,0,0,0,0,0,0,0,0,0,0,0,0,0,0,0,0,0,0,0,0,0
0,0,0,0,0,0,0,0,0,0,0,0,0,0,0,0,0,0,0,0,0,0,0,0,0,0,0
0,0,0,0,0,0,0,0,0,0,0,0,0,0,0,0,0,0,0,0,0,0,0,0,0,0,0
:endlayer
layer: 25
0,0,0,0,0,0,0,0,0,0,0,0,0,0,0,0,0,0,0,0,0,0,0,0,0,0,0
0,0,0,0,0,0,0,0,0,0,0,0,0,0,0,0,0,0,0,0,0,0,0,0,0,0,0
0,0,0,0,0,0,0,0,0,0,0,0,0,0,0,0,0,0,0,0,0,0,0,0,0,0,0
0,0,0,0,0,0,0,0,0,0,0,0,0,0,0,0,0,0,0,0,0,0,0,0,0,0,0
0,0,0,0,0,0,0,0,0,0,0,0,0,0,0,0,0,0,0,0,0,0,0,0,0,0,0
0,0,0,0,0,0,0,0,0,0,0,0,0,0,0,0,0,0,0,118,90,224,0,0,0,0,0
0,0,0,0,0,0,0,0,0,0,0,0,0,0,0,0,118,31,86,3,3,3,86,0,0,0,0
0,0,0,0,0,0,0,0,0,0,0,0,0,0,0,0,3,3,151,0,0,0,0,0,0,0,0
0,0,0,0,0,0,0,0,0,0,0,0,0,0,0,226,3,3,151,0,0,0,3,3,43,0,0
0,0,0,0,0,0,0,0,0,0,0,0,0,0,0,3,3,3,151,0,0,0,0,3,222,0,0
0,0,0,0,0,0,0,0,0,0,0,0,0,0,3,0,0,0,0,0,0,150,0,3,3,0,0
0,0,0,0,0,0,0,0,0,0,0,0,0,0,3,0,0,0,0,0,0,0,0,3,74,0,0
0,0,0,0,0,0,0,0,0,0,0,0,0,0,14,0,0,0,0,0,0,0,0,223,0,0,0
0,0,0,0,0,0,0,0,0,0,0,0,0,0,0,86,3,0,0,0,0,0,3,0,0,0,0
0,0,0,0,0,0,0,0,0,0,0,0,0,0,0,0,86,3,151,151,151,3,0,0,0,0,0
0,0,0,0,0,0,0,0,0,0,0,0,0,0,0,0,0,3,225,3,3,0,0,0,0,0,0
0,0,0,0,0,0,0,0,0,0,0,0,0,0,0,0,0,0,0,0,0,0,0,0,0,0,0
0,0,0,0,0,0,0,0,0,0,0,0,0,0,0,0,0,0,0,0,0,0,0,0,0,0,0
0,0,0,0,0,0,0,0,0,0,0,0,0,0,0,0,0,0,0,0,0,0,0,0,0,0,0
0,0,0,0,0,0,0,0,0,0,0,0,0,0,0,0,0,0,0,0,0,0,0,0,0,0,0
0,0,0,0,0,0,0,0,0,0,0,0,0,0,0,0,0,0,0,0,0,0,0,0,0,0,0
0,0,0,0,0,0,0,0,0,0,0,0,0,0,0,0,0,0,0,0,0,0,0,0,0,0,0
0,0,0,0,0,0,0,0,0,0,0,0,0,0,0,0,0,0,0,0,0,0,0,0,0,0,0
0,0,0,0,0,0,0,0,0,0,0,0,0,0,0,0,0,0,0,0,0,0,0,0,0,0,0
0,0,0,0,0,0,0,0,0,0,0,0,0,0,0,0,0,0,0,0,0,0,0,0,0,0,0
0,0,0,0,0,0,0,0,0,0,0,0,0,0,0,0,0,0,0,0,0,0,0,0,0,0,0
0,0,0,0,0,0,0,82,0,227,113,3,82,115,0,0,0,0,0,0,0,0,0,0,0,0,0
0,0,0,0,0,0,0,0,0,0,0,0,0,0,0,86,0,0,0,0,0,0,0,0,0,0,0
0,0,0,0,0,0,0,82,0,0,0,0,0,0,0,0,0,0,0,0,0,0,0,0,0,0,0
0,0,0,0,0,0,0,3,0,0,0,0,0,0,0,86,0,0,0,0,0,0,0,0,0,0,0
0,0,0,0,0,0,0,0,0,0,0,0,0,0,0,82,0,0,0,0,0,0,0,0,0,0,0
0,0,0,0,0,0,0,0,0,0,0,0,0,0,0,0,0,0,0,0,0,0,0,0,0,0,0
0,0,0,0,0,0,0,3,0,0,0,0,0,0,0,113,0,0,0,0,0,0,0,0,0,0,0
0,0,0,0,0,0,0,0,0,0,0,0,0,0,0,86,0,0,0,0,0,0,0,0,0,0,0
0,0,0,0,0,0,0,0,86,115,113,86,0,0,113,115,0,0,0,0,0,0,0,0,0,0,0
0,0,0,0,0,0,0,0,0,0,0,0,0,0,0,0,0,0,0,0,0,0,0,0,0,0,0
0,0,0,0,0,0,0,0,0,0,0,0,0,0,0,0,0,0,0,0,0,0,0,0,0,0,0
0,0,0,0,0,0,0,0,0,0,0,0,0,0,0,0,0,0,0,0,0,0,0,0,0,0,0
0,0,0,0,0,0,0,0,0,0,0,0,0,0,0,0,0,0,0,0,0,0,0,0,0,0,0
:endlayer
layer: 26
0,0,0,0,0,0,0,0,0,0,0,0,0,0,0,0,0,0,0,0,0,0,0,0,0,0,0
0,0,0,0,0,0,0,0,0,0,0,0,0,0,0,0,0,0,0,0,0,0,0,0,0,0,0
0,0,0,0,0,0,0,0,0,0,0,0,0,0,0,0,0,0,0,0,0,0,0,0,0,0,0
0,0,0,0,0,0,0,0,0,0,0,0,0,0,0,0,0,0,0,0,0,0,0,0,0,0,0
0,0,0,0,0,0,0,0,0,0,0,0,0,0,0,0,0,0,0,0,0,0,0,0,0,0,0
0,0,0,0,0,0,0,0,0,0,0,0,0,0,0,0,0,0,0,3,3,3,0,0,0,0,0
0,0,0,0,0,0,0,0,0,0,0,0,0,0,0,0,3,3,86,3,3,3,3,0,0,0,0
0,0,0,0,0,0,0,0,0,0,0,0,0,0,0,234,3,3,0,0,46,0,160,0,0,0,0
0,0,0,0,0,0,0,0,0,0,0,0,0,0,0,3,3,3,43,0,0,0,3,229,0,0,0
0,0,0,0,0,0,0,0,0,0,0,0,0,0,235,3,3,3,0,0,0,0,0,3,3,0,0
0,0,0,0,0,0,0,0,0,0,0,0,0,0,3,0,0,0,0,0,0,0,230,3,228,0,0
0,0,0,0,0,0,0,0,0,0,0,0,0,0,3,43,0,0,0,0,0,150,0,3,3,0,0
0,0,0,0,0,0,0,0,0,0,0,0,0,0,3,0,0,0,0,0,0,0,0,86,0,0,0
0,0,0,0,0,0,0,0,0,0,0,0,0,0,0,86,3,232,0,0,0,231,86,0,0,0,0
0,0,0,0,0,0,0,0,0,0,0,0,0,0,0,0,233,3,151,151,151,3,0,0,0,0,0
0,0,0,0,0,0,0,0,0,0,0,0,0,0,0,0,0,3,3,3,3,0,0,0,0,0,0
0,0,0,0,0,0,0,0,0,0,0,0,0,0,0,0,0,0,0,0,0,0,0,0,0,0,0
0,0,0,0,0,0,0,0,0,0,0,0,0,0,0,0,0,0,0,0,0,0,0,0,0,0,0
0,0,0,0,0,0,0,0,0,0,0,0,0,0,0,0,0,0,0,0,0,0,0,0,0,0,0
0,0,0,0,0,0,0,0,0,0,0,0,0,0,0,0,0,0,0,0,0,0,0,0,0,0,0
0,0,0,0,0,0,0,0,0,0,0,0,0,0,0,0,0,0,0,0,0,0,0,0,0,0,0
0,0,0,0,0,0,0,0,0,0,0,0,0,0,0,0,0,0,0,0,0,0,0,0,0,0,0
0,0,0,0,0,0,0,0,0,0,0,0,0,0,0,0,0,0,0,0,0,0,0,0,0,0,0
0,0,0,0,0,0,0,0,0,0,0,0,0,0,0,0,0,0,0,0,0,0,0,0,0,0,0
0,0,0,0,0,0,0,0,0,0,0,0,0,0,0,0,0,0,0,0,0,0,0,0,0,0,0
0,0,0,0,0,0,0,0,0,0,0,0,0,0,0,0,0,0,0,0,0,0,0,0,0,0,0
0,0,0,0,0,0,0,3,0,0,0,115,115,3,0,0,0,0,0,0,0,0,0,0,0,0,0
0,0,0,0,0,0,0,0,0,0,0,0,0,0,0,3,0,0,0,0,0,0,0,0,0,0,0
0,0,0,0,0,0,0,0,0,0,0,0,0,0,0,0,0,0,0,0,0,0,0,0,0,0,0
0,0,0,0,0,0,0,86,0,0,0,0,0,0,0,0,0,0,0,0,0,0,0,0,0,0,0
0,0,0,0,0,0,0,0,0,0,0,0,0,0,0,86,0,0,0,0,0,0,0,0,0,0,0
0,0,0,0,0,0,0,0,0,0,0,0,0,0,0,0,0,0,0,0,0,0,0,0,0,0,0
0,0,0,0,0,0,0,0,0,0,0,0,0,0,0,113,0,0,0,0,0,0,0,0,0,0,0
0,0,0,0,0,0,0,0,0,0,0,0,0,0,0,0,0,0,0,0,0,0,0,0,0,0,0
0,0,0,0,0,0,0,0,113,82,3,0,0,0,0,0,0,0,0,0,0,0,0,0,0,0,0
0,0,0,0,0,0,0,0,0,0,0,0,0,0,0,0,0,0,0,0,0,0,0,0,0,0,0
0,0,0,0,0,0,0,0,0,0,0,0,0,0,0,0,0,0,0,0,0,0,0,0,0,0,0
0,0,0,0,0,0,0,0,0,0,0,0,0,0,0,0,0,0,0,0,0,0,0,0,0,0,0
0,0,0,0,0,0,0,0,0,0,0,0,0,0,0,0,0,0,0,0,0,0,0,0,0,0,0
:endlayer
layer: 27
0,0,0,0,0,0,0,0,0,0,0,0,0,0,0,0,0,0,0,0,0,0,0,0,0,0,0
0,0,0,0,0,0,0,0,0,0,0,0,0,0,0,0,0,0,0,0,0,0,0,0,0,0,0
0,0,0,0,0,0,0,0,0,0,0,0,0,0,0,0,0,0,0,0,0,0,0,0,0,0,0
0,0,0,0,0,0,0,0,0,0,0,0,0,0,0,0,0,0,0,0,0,0,0,0,0,0,0
0,0,0,0,0,0,0,0,0,0,0,0,0,0,0,0,0,0,0,0,0,0,0,0,0,0,0
0,0,0,0,0,0,0,0,0,0,0,0,0,0,0,0,0,0,0,236,3,3,0,0,0,0,0
0,0,0,0,0,0,0,0,0,0,0,0,0,0,0,0,86,3,237,3,3,3,3,0,0,0,0
0,0,0,0,0,0,0,0,0,0,0,0,0,0,0,3,3,3,0,0,0,0,3,0,0,0,0
0,0,0,0,0,0,0,0,0,0,0,0,0,0,238,3,3,3,0,0,0,0,3,3,0,0,0
0,0,0,0,0,0,0,0,0,0,0,0,0,0,3,3,3,3,0,0,0,0,0,3,3,0,0
0,0,0,0,0,0,0,0,0,0,0,0,0,0,118,3,0,0,0,0,0,0,0,3,3,0,0
0,0,0,0,0,0,0,0,0,0,0,0,0,0,3,0,0,0,0,0,0,0,0,3,3,0,0
0,0,0,0,0,0,0,0,0,0,0,0,0,0,3,0,0,0,0,0,0,150,0,3,0,0,0
0,0,0,0,0,0,0,0,0,0,0,0,0,0,0,86,3,0,0,0,0,0,86,0,0,0,0
0,0,0,0,0,0,0,0,0,0,0,0,0,0,0,0,3,3,151,151,151,86,0,0,0,0,0
0,0,0,0,0,0,0,0,0,0,0,0,0,0,0,0,0,3,3,3,74,0,0,0,0,0,0
0,0,0,0,0,0,0,0,0,0,0,0,0,0,0,0,0,0,0,0,0,0,0,0,0,0,0
0,0,0,0,0,0,0,0,0,0,0,0,0,0,0,0,0,0,0,0,0,0,0,0,0,0,0
0,0,0,0,0,0,0,0,0,0,0,0,0,0,0,0,0,0,0,0,0,0,0,0,0,0,0
0,0,0,0,0,0,0,0,0,0,0,0,0,0,0,0,0,0,0,0,0,0,0,0,0,0,0
0,0,0,0,0,0,0,0,0,0,0,0,0,0,0,0,0,0,0,0,0,0,0,0,0,0,0
0,0,0,0,0,0,0,0,0,0,0,0,0,0,0,0,0,0,0,0,0,0,0,0,0,0,0
0,0,0,0,0,0,0,0,0,0,0,0,0,0,0,0,0,0,0,0,0,0,0,0,0,0,0
0,0,0,0,0,0,0,0,0,0,0,0,0,0,0,0,0,0,0,0,0,0,0,0,0,0,0
0,0,0,0,0,0,0,0,0,0,0,0,0,0,0,0,0,0,0,0,0,0,0,0,0,0,0
0,0,0,0,0,0,0,0,0,0,0,0,0,0,0,0,0,0,0,0,0,0,0,0,0,0,0
0,0,0,0,0,0,0,0,0,0,0,0,3,82,0,0,0,0,0,0,0,0,0,0,0,0,0
0,0,0,0,0,0,0,0,0,0,0,0,0,0,0,0,0,0,0,0,0,0,0,0,0,0,0
0,0,0,0,0,0,0,0,0,0,0,0,0,0,0,0,0,0,0,0,0,0,0,0,0,0,0
0,0,0,0,0,0,0,86,0,0,0,0,0,0,0,0,0,0,0,0,0,0,0,0,0,0,0
0,0,0,0,0,0,0,0,0,0,0,0,0,0,0,82,0,0,0,0,0,0,0,0,0,0,0
0,0,0,0,0,0,0,0,0,0,0,0,0,0,0,0,0,0,0,0,0,0,0,0,0,0,0
0,0,0,0,0,0,0,0,0,0,0,0,0,0,0,3,0,0,0,0,0,0,0,0,0,0,0
0,0,0,0,0,0,0,0,0,0,0,0,0,0,0,0,0,0,0,0,0,0,0,0,0,0,0
0,0,0,0,0,0,0,0,115,0,113,0,0,0,0,0,0,0,0,0,0,0,0,0,0,0,0
0,0,0,0,0,0,0,0,0,0,0,0,0,0,0,0,0,0,0,0,0,0,0,0,0,0,0
0,0,0,0,0,0,0,0,0,0,0,0,0,0,0,0,0,0,0,0,0,0,0,0,0,0,0
0,0,0,0,0,0,0,0,0,0,0,0,0,0,0,0,0,0,0,0,0,0,0,0,0,0,0
0,0,0,0,0,0,0,0,0,0,0,0,0,0,0,0,0,0,0,0,0,0,0,0,0,0,0
:endlayer
layer: 28
0,0,0,0,0,0,0,0,0,0,0,0,0,0,0,0,0,0,0,0,0,0,0,0,0,0,0
0,0,0,0,0,0,0,0,0,0,0,0,0,0,0,0,0,0,0,0,0,0,0,0,0,0,0
0,0,0,0,0,0,0,0,0,0,0,0,0,0,0,0,0,0,0,0,0,0,0,0,0,0,0
0,0,0,0,0,0,0,0,0,0,0,0,0,0,0,0,0,0,0,0,0,0,0,0,0,0,0
0,0,0,0,0,0,0,0,0,0,0,0,0,0,0,0,0,0,0,0,0,0,0,0,0,0,0
0,0,0,0,0,0,0,0,0,0,0,0,0,0,0,0,0,0,0,3,3,31,0,0,0,0,0
0,0,0,0,0,0,0,0,0,0,0,0,0,0,0,243,86,86,3,151,151,151,3,0,0,0,0
0,0,0,0,0,0,0,0,0,0,0,0,0,0,0,3,3,3,151,151,151,151,151,3,0,0,0
0,0,0,0,0,0,0,0,0,0,0,0,0,0,3,3,3,3,241,151,241,151,240,3,3,0,0
0,0,0,0,0,0,0,0,0,0,0,0,0,0,14,3,3,3,151,151,241,151,151,3,239,0,0
0,0,0,0,0,0,0,0,0,0,0,0,0,0,3,3,151,151,151,241,241,0,151,3,3,0,0
0,0,0,0,0,0,0,0,0,0,0,0,0,0,3,151,242,151,241,241,241,0,151,3,3,0,0
0,0,0,0,0,0,0,0,0,0,0,0,0,0,3,151,151,151,151,241,151,0,151,3,0,0,0
0,0,0,0,0,0,0,0,0,0,0,0,0,0,0,86,151,151,241,151,151,151,3,0,0,0,0
0,0,0,0,0,0,0,0,0,0,0,0,0,0,0,0,3,151,90,151,151,86,0,0,0,0,0
0,0,0,0,0,0,0,0,0,0,0,0,0,0,0,0,0,74,3,3,3,0,0,0,0,0,0
0,0,0,0,0,0,0,0,0,0,0,0,0,0,0,0,0,0,0,0,0,0,0,0,0,0,0
0,0,0,0,0,0,0,0,0,0,0,0,0,0,0,0,0,0,0,0,0,0,0,0,0,0,0
0,0,0,0,0,0,0,0,0,0,0,0,0,0,0,0,0,0,0,0,0,0,0,0,0,0,0
0,0,0,0,0,0,0,0,0,0,0,0,0,0,0,0,0,0,0,0,0,0,0,0,0,0,0
0,0,0,0,0,0,0,0,0,0,0,0,0,0,0,0,0,0,0,0,0,0,0,0,0,0,0
0,0,0,0,0,0,0,0,0,0,0,0,0,0,0,0,0,0,0,0,0,0,0,0,0,0,0
0,0,0,0,0,0,0,0,0,0,0,0,0,0,0,0,0,0,0,0,0,0,0,0,0,0,0
0,0,0,0,0,0,0,0,0,0,0,0,0,0,0,0,0,0,0,0,0,0,0,0,0,0,0
0,0,0,0,0,0,0,0,0,0,0,0,0,0,0,0,0,0,0,0,0,0,0,0,0,0,0
0,0,0,0,0,0,0,0,0,0,0,0,0,0,0,0,0,0,0,0,0,0,0,0,0,0,0
0,0,0,0,0,0,0,0,0,0,0,0,86,86,0,0,0,0,0,0,0,0,0,0,0,0,0
0,0,0,0,0,0,0,0,0,0,0,0,0,0,0,0,0,0,0,0,0,0,0,0,0,0,0
0,0,0,0,0,0,0,0,0,0,0,0,0,0,0,0,0,0,0,0,0,0,0,0,0,0,0
0,0,0,0,0,0,0,86,0,0,0,0,0,0,0,0,0,0,0,0,0,0,0,0,0,0,0
0,0,0,0,0,0,0,0,0,0,0,0,0,0,0,0,0,0,0,0,0,0,0,0,0,0,0
0,0,0,0,0,0,0,0,0,0,0,0,0,0,0,0,0,0,0,0,0,0,0,0,0,0,0
0,0,0,0,0,0,0,0,0,0,0,0,0,0,0,115,0,0,0,0,0,0,0,0,0,0,0
0,0,0,0,0,0,0,0,0,0,0,0,0,0,0,0,0,0,0,0,0,0,0,0,0,0,0
0,0,0,0,0,0,0,0,115,0,82,0,0,0,0,0,0,0,0,0,0,0,0,0,0,0,0
0,0,0,0,0,0,0,0,0,0,0,0,0,0,0,0,0,0,0,0,0,0,0,0,0,0,0
0,0,0,0,0,0,0,0,0,0,0,0,0,0,0,0,0,0,0,0,0,0,0,0,0,0,0
0,0,0,0,0,0,0,0,0,0,0,0,0,0,0,0,0,0,0,0,0,0,0,0,0,0,0
0,0,0,0,0,0,0,0,0,0,0,0,0,0,0,0,0,0,0,0,0,0,0,0,0,0,0
:endlayer
layer: 29
0,0,0,0,0,0,0,0,0,0,0,0,0,0,0,0,0,0,0,0,0,0,0,0,0,0,0
0,0,0,0,0,0,0,0,0,0,0,0,0,0,0,0,0,0,0,0,0,0,0,0,0,0,0
0,0,0,0,0,0,0,0,0,0,0,0,0,0,0,0,0,0,0,0,0,0,0,0,0,0,0
0,0,0,0,0,0,0,0,0,0,0,0,0,0,0,0,0,0,0,0,0,0,0,0,0,0,0
0,0,0,0,0,0,0,0,0,0,0,0,0,0,0,0,0,0,0,0,0,0,0,0,0,0,0
0,0,0,0,0,0,0,0,0,0,0,0,0,0,0,0,0,0,0,3,3,3,0,0,0,0,0
0,0,0,0,0,0,0,0,0,0,0,0,0,0,0,3,252,86,3,0,247,0,3,0,0,0,0
0,0,0,0,0,0,0,0,0,0,0,0,0,0,254,3,3,3,0,0,0,0,0,3,0,0,0
0,0,0,0,0,0,0,0,0,0,0,0,0,0,3,3,3,3,249,0,0,0,246,3,244,0,0
0,0,0,0,0,0,0,0,0,0,0,0,0,0,3,3,3,3,0,0,0,0,0,3,3,0,0
0,0,0,0,0,0,0,0,0,0,0,0,0,0,3,3,253,0,0,0,0,0,0,3,3,0,0
0,0,0,0,0,0,0,0,0,0,0,0,0,0,118,0,0,0,0,248,0,0,0,3,3,0,0
0,0,0,0,0,0,0,0,0,0,0,0,0,0,3,0,0,0,0,0,0,0,0,245,0,0,0
0,0,0,0,0,0,0,0,0,0,0,0,0,0,0,3,0,0,0,0,0,0,3,0,0,0,0
0,0,0,0,0,0,0,0,0,0,0,0,0,0,0,0,3,251,250,0,0,86,0,0,0,0,0
0,0,0,0,0,0,0,0,0,0,0,0,0,0,0,0,0,3,3,74,86,0,0,0,0,0,0
0,0,0,0,0,0,0,0,0,0,0,0,0,0,0,0,0,0,0,0,0,0,0,0,0,0,0
0,0,0,0,0,0,0,0,0,0,0,0,0,0,0,0,0,0,0,0,0,0,0,0,0,0,0
0,0,0,0,0,0,0,0,0,0,0,0,0,0,0,0,0,0,0,0,0,0,0,0,0,0,0
0,0,0,0,0,0,0,0,0,0,0,0,0,0,0,0,0,0,0,0,0,0,0,0,0,0,0
0,0,0,0,0,0,0,0,0,0,0,0,0,0,0,0,0,0,0,0,0,0,0,0,0,0,0
0,0,0,0,0,0,0,0,0,0,0,0,0,0,0,0,0,0,0,0,0,0,0,0,0,0,0
0,0,0,0,0,0,0,0,0,0,0,0,0,0,0,0,0,0,0,0,0,0,0,0,0,0,0
0,0,0,0,0,0,0,0,0,0,0,0,0,0,0,0,0,0,0,0,0,0,0,0,0,0,0
0,0,0,0,0,0,0,0,0,0,0,0,0,0,0,0,0,0,0,0,0,0,0,0,0,0,0
0,0,0,0,0,0,0,0,0,0,0,0,0,0,0,0,0,0,0,0,0,0,0,0,0,0,0
0,0,0,0,0,0,0,0,0,0,0,0,0,115,0,0,0,0,0,0,0,0,0,0,0,0,0
0,0,0,0,0,0,0,0,0,0,0,0,0,0,0,0,0,0,0,0,0,0,0,0,0,0,0
0,0,0,0,0,0,0,0,0,0,0,0,0,0,0,0,0,0,0,0,0,0,0,0,0,0,0
0,0,0,0,0,0,0,0,0,0,0,0,0,0,0,0,0,0,0,0,0,0,0,0,0,0,0
0,0,0,0,0,0,0,0,0,0,0,0,0,0,0,0,0,0,0,0,0,0,0,0,0,0,0
0,0,0,0,0,0,0,0,0,0,0,0,0,0,0,0,0,0,0,0,0,0,0,0,0,0,0
0,0,0,0,0,0,0,0,0,0,0,0,0,0,0,86,0,0,0,0,0,0,0,0,0,0,0
0,0,0,0,0,0,0,0,0,0,0,0,0,0,0,0,0,0,0,0,0,0,0,0,0,0,0
0,0,0,0,0,0,0,0,86,0,3,0,0,0,0,0,0,0,0,0,0,0,0,0,0,0,0
0,0,0,0,0,0,0,0,0,0,0,0,0,0,0,0,0,0,0,0,0,0,0,0,0,0,0
0,0,0,0,0,0,0,0,0,0,0,0,0,0,0,0,0,0,0,0,0,0,0,0,0,0,0
0,0,0,0,0,0,0,0,0,0,0,0,0,0,0,0,0,0,0,0,0,0,0,0,0,0,0
0,0,0,0,0,0,0,0,0,0,0,0,0,0,0,0,0,0,0,0,0,0,0,0,0,0,0
:endlayer
layer: 30
0,0,0,0,0,0,0,0,0,0,0,0,0,0,0,0,0,0,0,0,0,0,0,0,0,0,0
0,0,0,0,0,0,0,0,0,0,0,0,0,0,0,0,0,0,0,0,0,0,0,0,0,0,0
0,0,0,0,0,0,0,0,0,0,0,0,0,0,0,0,0,0,0,0,0,0,0,0,0,0,0
0,0,0,0,0,0,0,0,0,0,0,0,0,0,0,0,0,0,0,0,0,0,0,0,0,0,0
0,0,0,0,0,0,0,0,0,0,0,0,0,0,0,0,0,0,0,0,0,0,0,0,0,0,0
0,0,0,0,0,0,0,0,0,0,0,0,0,0,0,0,0,0,0,3,259,3,0,0,0,0,0
0,0,0,0,0,0,0,0,0,0,0,0,0,0,0,3,3,261,3,46,0,46,3,0,0,0,0
0,0,0,0,0,0,0,0,0,0,0,0,0,0,3,3,3,3,0,0,0,0,0,3,0,0,0
0,0,0,0,0,0,0,0,0,0,0,0,0,0,118,3,3,3,43,0,0,0,256,3,3,0,0
0,0,0,0,0,0,0,0,0,0,0,0,0,0,3,3,263,3,0,0,0,0,257,3,3,0,0
0,0,0,0,0,0,0,0,0,0,0,0,0,0,86,3,0,0,0,0,0,0,0,3,3,0,0
0,0,0,0,0,0,0,0,0,0,0,0,0,0,3,43,0,0,0,0,0,0,258,3,255,0,0
0,0,0,0,0,0,0,0,0,0,0,0,0,0,118,0,0,0,0,0,0,0,0,3,0,0,0
0,0,0,0,0,0,0,0,0,0,0,0,0,0,0,3,0,0,0,0,0,0,3,0,0,0,0
0,0,0,0,0,0,0,0,0,0,0,0,0,0,0,0,3,262,0,0,260,3,0,0,0,0,0
0,0,0,0,0,0,0,0,0,0,0,0,0,0,0,0,0,3,3,86,86,0,0,0,0,0,0
0,0,0,0,0,0,0,0,0,0,0,0,0,0,0,0,0,0,0,0,0,0,0,0,0,0,0
0,0,0,0,0,0,0,0,0,0,0,0,0,0,0,0,0,0,0,0,0,0,0,0,0,0,0
0,0,0,0,0,0,0,0,0,0,0,0,0,0,0,0,0,0,0,0,0,0,0,0,0,0,0
0,0,0,0,0,0,0,0,0,0,0,0,0,0,0,0,0,0,0,0,0,0,0,0,0,0,0
0,0,0,0,0,0,0,0,0,0,0,0,0,0,0,0,0,0,0,0,0,0,0,0,0,0,0
0,0,0,0,0,0,0,0,0,0,0,0,0,0,0,0,0,0,0,0,0,0,0,0,0,0,0
0,0,0,0,0,0,0,0,0,0,0,0,0,0,0,0,0,0,0,0,0,0,0,0,0,0,0
0,0,0,0,0,0,0,0,0,0,0,0,0,0,0,0,0,0,0,0,0,0,0,0,0,0,0
0,0,0,0,0,0,0,0,0,0,0,0,0,0,0,0,0,0,0,0,0,0,0,0,0,0,0
0,0,0,0,0,0,0,0,0,0,0,0,0,0,0,0,0,0,0,0,0,0,0,0,0,0,0
0,0,0,0,0,0,0,0,0,0,0,0,0,0,0,0,0,0,0,0,0,0,0,0,0,0,0
0,0,0,0,0,0,0,0,0,0,0,0,0,0,0,0,0,0,0,0,0,0,0,0,0,0,0
0,0,0,0,0,0,0,0,0,0,0,0,0,0,0,0,0,0,0,0,0,0,0,0,0,0,0
0,0,0,0,0,0,0,0,0,0,0,0,0,0,0,0,0,0,0,0,0,0,0,0,0,0,0
0,0,0,0,0,0,0,0,0,0,0,0,0,0,0,0,0,0,0,0,0,0,0,0,0,0,0
0,0,0,0,0,0,0,0,0,0,0,0,0,0,0,0,0,0,0,0,0,0,0,0,0,0,0
0,0,0,0,0,0,0,0,0,0,0,0,0,0,0,0,0,0,0,0,0,0,0,0,0,0,0
0,0,0,0,0,0,0,0,0,0,0,0,0,0,0,0,0,0,0,0,0,0,0,0,0,0,0
0,0,0,0,0,0,0,0,0,0,0,0,0,0,0,0,0,0,0,0,0,0,0,0,0,0,0
0,0,0,0,0,0,0,0,0,0,0,0,0,0,0,0,0,0,0,0,0,0,0,0,0,0,0
0,0,0,0,0,0,0,0,0,0,0,0,0,0,0,0,0,0,0,0,0,0,0,0,0,0,0
0,0,0,0,0,0,0,0,0,0,0,0,0,0,0,0,0,0,0,0,0,0,0,0,0,0,0
0,0,0,0,0,0,0,0,0,0,0,0,0,0,0,0,0,0,0,0,0,0,0,0,0,0,0
:endlayer
layer: 31
0,0,0,0,0,0,0,0,0,0,0,0,0,0,0,0,0,0,0,0,0,0,0,0,0,0,0
0,0,0,0,0,0,0,0,0,0,0,0,0,0,0,0,0,0,0,0,0,0,0,0,0,0,0
0,0,0,0,0,0,0,0,0,0,0,0,0,0,0,0,0,0,0,0,0,0,0,0,0,0,0
0,0,0,0,0,0,0,0,0,0,0,0,0,0,0,0,0,0,0,0,0,0,0,0,0,0,0
0,0,0,0,0,0,0,0,0,0,0,0,0,0,0,0,0,0,0,0,0,0,0,0,0,0,0
0,0,0,0,0,0,0,0,0,0,0,0,0,0,0,0,0,0,0,90,90,90,0,0,0,0,0
0,0,0,0,0,0,0,0,0,0,0,0,0,0,0,3,3,3,3,241,241,241,90,0,0,0,0
0,0,0,0,0,0,0,0,0,0,0,0,0,0,3,151,151,90,241,241,0,0,241,3,0,0,0
0,0,0,0,0,0,0,0,0,0,0,0,0,0,3,151,151,90,241,0,0,0,0,151,3,0,0
0,0,0,0,0,0,0,0,0,0,0,0,0,0,3,3,0,90,0,0,0,0,0,151,3,0,0
0,0,0,0,0,0,0,0,0,0,0,0,0,0,86,3,0,0,0,0,241,241,241,151,3,0,0
0,0,0,0,0,0,0,0,0,0,0,0,0,0,86,241,0,0,0,0,241,241,241,151,3,0,0
0,0,0,0,0,0,0,0,0,0,0,0,0,0,3,241,0,0,0,241,241,241,241,90,0,0,0
0,0,0,0,0,0,0,0,0,0,0,0,0,0,0,3,241,0,241,241,241,241,90,0,0,0,0
0,0,0,0,0,0,0,0,0,0,0,0,0,0,0,0,90,241,241,241,241,90,0,0,0,0,0
0,0,0,0,0,0,0,0,0,0,0,0,0,0,0,0,0,90,74,86,90,0,0,0,0,0,0
0,0,0,0,0,0,0,0,0,0,0,0,0,0,0,0,0,0,0,0,0,0,0,0,0,0,0
0,0,0,0,0,0,0,0,0,0,0,0,0,0,0,0,0,0,0,0,0,0,0,0,0,0,0
0,0,0,0,0,0,0,0,0,0,0,0,0,0,0,0,0,0,0,0,0,0,0,0,0,0,0
0,0,0,0,0,0,0,0,0,0,0,0,0,0,0,0,0,0,0,0,0,0,0,0,0,0,0
0,0,0,0,0,0,0,0,0,0,0,0,0,0,0,0,0,0,0,0,0,0,0,0,0,0,0
0,0,0,0,0,0,0,0,0,0,0,0,0,0,0,0,0,0,0,0,0,0,0,0,0,0,0
0,0,0,0,0,0,0,0,0,0,0,0,0,0,0,0,0,0,0,0,0,0,0,0,0,0,0
0,0,0,0,0,0,0,0,0,0,0,0,0,0,0,0,0,0,0,0,0,0,0,0,0,0,0
0,0,0,0,0,0,0,0,0,0,0,0,0,0,0,0,0,0,0,0,0,0,0,0,0,0,0
0,0,0,0,0,0,0,0,0,0,0,0,0,0,0,0,0,0,0,0,0,0,0,0,0,0,0
0,0,0,0,0,0,0,0,0,0,0,0,0,0,0,0,0,0,0,0,0,0,0,0,0,0,0
0,0,0,0,0,0,0,0,0,0,0,0,0,0,0,0,0,0,0,0,0,0,0,0,0,0,0
0,0,0,0,0,0,0,0,0,0,0,0,0,0,0,0,0,0,0,0,0,0,0,0,0,0,0
0,0,0,0,0,0,0,0,0,0,0,0,0,0,0,0,0,0,0,0,0,0,0,0,0,0,0
0,0,0,0,0,0,0,0,0,0,0,0,0,0,0,0,0,0,0,0,0,0,0,0,0,0,0
0,0,0,0,0,0,0,0,0,0,0,0,0,0,0,0,0,0,0,0,0,0,0,0,0,0,0
0,0,0,0,0,0,0,0,0,0,0,0,0,0,0,0,0,0,0,0,0,0,0,0,0,0,0
0,0,0,0,0,0,0,0,0,0,0,0,0,0,0,0,0,0,0,0,0,0,0,0,0,0,0
0,0,0,0,0,0,0,0,0,0,0,0,0,0,0,0,0,0,0,0,0,0,0,0,0,0,0
0,0,0,0,0,0,0,0,0,0,0,0,0,0,0,0,0,0,0,0,0,0,0,0,0,0,0
0,0,0,0,0,0,0,0,0,0,0,0,0,0,0,0,0,0,0,0,0,0,0,0,0,0,0
0,0,0,0,0,0,0,0,0,0,0,0,0,0,0,0,0,0,0,0,0,0,0,0,0,0,0
0,0,0,0,0,0,0,0,0,0,0,0,0,0,0,0,0,0,0,0,0,0,0,0,0,0,0
:endlayer
layer: 32
0,0,0,0,0,0,0,0,0,0,0,0,0,0,0,0,0,0,0,0,0,0,0,0,0,0,0
0,0,0,0,0,0,0,0,0,0,0,0,0,0,0,0,0,0,0,0,0,0,0,0,0,0,0
0,0,0,0,0,0,0,0,0,0,0,0,0,0,0,0,0,0,0,0,0,0,0,0,0,0,0
0,0,0,0,0,0,0,0,0,0,0,0,0,0,0,0,0,0,0,0,0,0,0,0,0,0,0
0,0,0,0,0,0,0,0,0,0,0,0,0,0,0,0,0,0,0,0,0,0,0,0,0,0,0
0,0,0,0,0,0,0,0,0,0,0,0,0,0,0,0,0,0,0,90,0,265,0,0,0,0,0
0,0,0,0,0,0,0,0,0,0,0,0,0,0,0,73,90,3,90,0,0,0,3,0,0,0,0
0,0,0,0,0,0,0,0,0,0,0,0,0,0,0,0,0,0,0,0,0,0,0,90,0,0,0
0,0,0,0,0,0,0,0,0,0,0,0,0,0,0,0,268,90,0,0,0,0,0,0,73,0,0
0,0,0,0,0,0,0,0,0,0,0,0,0,0,73,90,0,90,0,0,0,0,0,0,0,0,0
0,0,0,0,0,0,0,0,0,0,0,0,0,0,118,3,0,0,0,0,0,0,0,0,264,0,0
0,0,0,0,0,0,0,0,0,0,0,0,0,0,0,0,0,0,0,0,0,266,0,0,73,0,0
0,0,0,0,0,0,0,0,0,0,0,0,0,0,0,0,0,0,0,0,0,0,0,73,0,0,0
0,0,0,0,0,0,0,0,0,0,0,0,0,0,0,3,0,0,0,0,267,0,90,0,0,0,0
0,0,0,0,0,0,0,0,0,0,0,0,0,0,0,0,269,0,0,0,0,0,0,0,0,0,0
0,0,0,0,0,0,0,0,0,0,0,0,0,0,0,0,0,0,90,86,90,0,0,0,0,0,0
0,0,0,0,0,0,0,0,0,0,0,0,0,0,0,0,0,0,0,0,0,0,0,0,0,0,0
0,0,0,0,0,0,0,0,0,0,0,0,0,0,0,0,0,0,0,0,0,0,0,0,0,0,0
0,0,0,0,0,0,0,0,0,0,0,0,0,0,0,0,0,0,0,0,0,0,0,0,0,0,0
0,0,0,0,0,0,0,0,0,0,0,0,0,0,0,0,0,0,0,0,0,0,0,0,0,0,0
0,0,0,0,0,0,0,0,0,0,0,0,0,0,0,0,0,0,0,0,0,0,0,0,0,0,0
0,0,0,0,0,0,0,0,0,0,0,0,0,0,0,0,0,0,0,0,0,0,0,0,0,0,0
0,0,0,0,0,0,0,0,0,0,0,0,0,0,0,0,0,0,0,0,0,0,0,0,0,0,0
0,0,0,0,0,0,0,0,0,0,0,0,0,0,0,0,0,0,0,0,0,0,0,0,0,0,0
0,0,0,0,0,0,0,0,0,0,0,0,0,0,0,0,0,0,0,0,0,0,0,0,0,0,0
0,0,0,0,0,0,0,0,0,0,0,0,0,0,0,0,0,0,0,0,0,0,0,0,0,0,0
0,0,0,0,0,0,0,0,0,0,0,0,0,0,0,0,0,0,0,0,0,0,0,0,0,0,0
0,0,0,0,0,0,0,0,0,0,0,0,0,0,0,0,0,0,0,0,0,0,0,0,0,0,0
0,0,0,0,0,0,0,0,0,0,0,0,0,0,0,0,0,0,0,0,0,0,0,0,0,0,0
0,0,0,0,0,0,0,0,0,0,0,0,0,0,0,0,0,0,0,0,0,0,0,0,0,0,0
0,0,0,0,0,0,0,0,0,0,0,0,0,0,0,0,0,0,0,0,0,0,0,0,0,0,0
0,0,0,0,0,0,0,0,0,0,0,0,0,0,0,0,0,0,0,0,0,0,0,0,0,0,0
0,0,0,0,0,0,0,0,0,0,0,0,0,0,0,0,0,0,0,0,0,0,0,0,0,0,0
0,0,0,0,0,0,0,0,0,0,0,0,0,0,0,0,0,0,0,0,0,0,0,0,0,0,0
0,0,0,0,0,0,0,0,0,0,0,0,0,0,0,0,0,0,0,0,0,0,0,0,0,0,0
0,0,0,0,0,0,0,0,0,0,0,0,0,0,0,0,0,0,0,0,0,0,0,0,0,0,0
0,0,0,0,0,0,0,0,0,0,0,0,0,0,0,0,0,0,0,0,0,0,0,0,0,0,0
0,0,0,0,0,0,0,0,0,0,0,0,0,0,0,0,0,0,0,0,0,0,0,0,0,0,0
0,0,0,0,0,0,0,0,0,0,0,0,0,0,0,0,0,0,0,0,0,0,0,0,0,0,0
:endlayer
layer: 33
0,0,0,0,0,0,0,0,0,0,0,0,0,0,0,0,0,0,0,0,0,0,0,0,0,0,0
0,0,0,0,0,0,0,0,0,0,0,0,0,0,0,0,0,0,0,0,0,0,0,0,0,0,0
0,0,0,0,0,0,0,0,0,0,0,0,0,0,0,0,0,0,0,0,0,0,0,0,0,0,0
0,0,0,0,0,0,0,0,0,0,0,0,0,0,0,0,0,0,0,0,0,0,0,0,0,0,0
0,0,0,0,0,0,0,0,0,0,0,0,0,0,0,0,0,0,0,0,0,0,0,0,0,0,0
0,0,0,0,0,0,0,0,0,0,0,0,0,0,0,0,0,0,0,90,3,3,0,0,0,0,0
0,0,0,0,0,0,0,0,0,0,0,0,0,0,0,0,0,73,73,0,0,0,73,0,0,0,0
0,0,0,0,0,0,0,0,0,0,0,0,0,0,0,0,0,73,0,0,0,0,0,0,0,0,0
0,0,0,0,0,0,0,0,0,0,0,0,0,0,0,0,0,90,0,0,0,0,0,0,0,0,0
0,0,0,0,0,0,0,0,0,0,0,0,0,0,0,0,0,73,0,0,0,0,0,0,0,0,0
0,0,0,0,0,0,0,0,0,0,0,0,0,0,3,3,0,0,0,0,0,0,0,0,0,0,0
0,0,0,0,0,0,0,0,0,0,0,0,0,0,0,0,0,0,0,0,0,0,0,0,0,0,0
0,0,0,0,0,0,0,0,0,0,0,0,0,0,0,0,0,0,0,0,0,0,0,0,0,0,0
0,0,0,0,0,0,0,0,0,0,0,0,0,0,0,86,0,0,0,0,0,0,0,0,0,0,0
0,0,0,0,0,0,0,0,0,0,0,0,0,0,0,0,0,0,0,0,0,0,0,0,0,0,0
0,0,0,0,0,0,0,0,0,0,0,0,0,0,0,0,0,0,73,90,90,0,0,0,0,0,0
0,0,0,0,0,0,0,0,0,0,0,0,0,0,0,0,0,0,0,0,0,0,0,0,0,0,0
0,0,0,0,0,0,0,0,0,0,0,0,0,0,0,0,0,0,0,0,0,0,0,0,0,0,0
0,0,0,0,0,0,0,0,0,0,0,0,0,0,0,0,0,0,0,0,0,0,0,0,0,0,0
0,0,0,0,0,0,0,0,0,0,0,0,0,0,0,0,0,0,0,0,0,0,0,0,0,0,0
0,0,0,0,0,0,0,0,0,0,0,0,0,0,0,0,0,0,0,0,0,0,0,0,0,0,0
0,0,0,0,0,0,0,0,0,0,0,0,0,0,0,0,0,0,0,0,0,0,0,0,0,0,0
0,0,0,0,0,0,0,0,0,0,0,0,0,0,0,0,0,0,0,0,0,0,0,0,0,0,0
0,0,0,0,0,0,0,0,0,0,0,0,0,0,0,0,0,0,0,0,0,0,0,0,0,0,0
0,0,0,0,0,0,0,0,0,0,0,0,0,0,0,0,0,0,0,0,0,0,0,0,0,0,0
0,0,0,0,0,0,0,0,0,0,0,0,0,0,0,0,0,0,0,0,0,0,0,0,0,0,0
0,0,0,0,0,0,0,0,0,0,0,0,0,0,0,0,0,0,0,0,0,0,0,0,0,0,0
0,0,0,0,0,0,0,0,0,0,0,0,0,0,0,0,0,0,0,0,0,0,0,0,0,0,0
0,0,0,0,0,0,0,0,0,0,0,0,0,0,0,0,0,0,0,0,0,0,0,0,0,0,0
0,0,0,0,0,0,0,0,0,0,0,0,0,0,0,0,0,0,0,0,0,0,0,0,0,0,0
0,0,0,0,0,0,0,0,0,0,0,0,0,0,0,0,0,0,0,0,0,0,0,0,0,0,0
0,0,0,0,0,0,0,0,0,0,0,0,0,0,0,0,0,0,0,0,0,0,0,0,0,0,0
0,0,0,0,0,0,0,0,0,0,0,0,0,0,0,0,0,0,0,0,0,0,0,0,0,0,0
0,0,0,0,0,0,0,0,0,0,0,0,0,0,0,0,0,0,0,0,0,0,0,0,0,0,0
0,0,0,0,0,0,0,0,0,0,0,0,0,0,0,0,0,0,0,0,0,0,0,0,0,0,0
0,0,0,0,0,0,0,0,0,0,0,0,0,0,0,0,0,0,0,0,0,0,0,0,0,0,0
0,0,0,0,0,0,0,0,0,0,0,0,0,0,0,0,0,0,0,0,0,0,0,0,0,0,0
0,0,0,0,0,0,0,0,0,0,0,0,0,0,0,0,0,0,0,0,0,0,0,0,0,0,0
0,0,0,0,0,0,0,0,0,0,0,0,0,0,0,0,0,0,0,0,0,0,0,0,0,0,0
:endlayer
layer: 34
0,0,0,0,0,0,0,0,0,0,0,0,0,0,0,0,0,0,0,0,0,0,0,0,0,0,0
0,0,0,0,0,0,0,0,0,0,0,0,0,0,0,0,0,0,0,0,0,0,0,0,0,0,0
0,0,0,0,0,0,0,0,0,0,0,0,0,0,0,0,0,0,0,0,0,0,0,0,0,0,0
0,0,0,0,0,0,0,0,0,0,0,0,0,0,0,0,0,0,0,0,0,0,0,0,0,0,0
0,0,0,0,0,0,0,0,0,0,0,0,0,0,0,0,0,0,0,0,0,0,0,0,0,0,0
0,0,0,0,0,0,0,0,0,0,0,0,0,0,0,0,0,0,0,0,73,0,0,0,0,0,0
0,0,0,0,0,0,0,0,0,0,0,0,0,0,0,0,0,0,0,0,0,0,0,0,0,0,0
0,0,0,0,0,0,0,0,0,0,0,0,0,0,0,0,0,0,0,0,0,0,0,0,0,0,0
0,0,0,0,0,0,0,0,0,0,0,0,0,0,0,0,0,0,0,0,0,0,0,0,0,0,0
0,0,0,0,0,0,0,0,0,0,0,0,0,0,0,0,0,0,0,0,0,0,0,0,0,0,0
0,0,0,0,0,0,0,0,0,0,0,0,0,0,90,73,0,0,0,0,0,0,0,0,0,0,0
0,0,0,0,0,0,0,0,0,0,0,0,0,0,3,0,0,0,0,0,0,0,0,0,0,0,0
0,0,0,0,0,0,0,0,0,0,0,0,0,0,90,0,0,0,0,0,0,0,0,0,0,0,0
0,0,0,0,0,0,0,0,0,0,0,0,0,0,0,0,0,0,0,0,0,0,0,0,0,0,0
0,0,0,0,0,0,0,0,0,0,0,0,0,0,0,0,0,0,0,0,0,0,0,0,0,0,0
0,0,0,0,0,0,0,0,0,0,0,0,0,0,0,0,0,0,0,73,0,0,0,0,0,0,0
0,0,0,0,0,0,0,0,0,0,0,0,0,0,0,0,0,0,0,0,0,0,0,0,0,0,0
0,0,0,0,0,0,0,0,0,0,0,0,0,0,0,0,0,0,0,0,0,0,0,0,0,0,0
0,0,0,0,0,0,0,0,0,0,0,0,0,0,0,0,0,0,0,0,0,0,0,0,0,0,0
0,0,0,0,0,0,0,0,0,0,0,0,0,0,0,0,0,0,0,0,0,0,0,0,0,0,0
0,0,0,0,0,0,0,0,0,0,0,0,0,0,0,0,0,0,0,0,0,0,0,0,0,0,0
0,0,0,0,0,0,0,0,0,0,0,0,0,0,0,0,0,0,0,0,0,0,0,0,0,0,0
0,0,0,0,0,0,0,0,0,0,0,0,0,0,0,0,0,0,0,0,0,0,0,0,0,0,0
0,0,0,0,0,0,0,0,0,0,0,0,0,0,0,0,0,0,0,0,0,0,0,0,0,0,0
0,0,0,0,0,0,0,0,0,0,0,0,0,0,0,0,0,0,0,0,0,0,0,0,0,0,0
0,0,0,0,0,0,0,0,0,0,0,0,0,0,0,0,0,0,0,0,0,0,0,0,0,0,0
0,0,0,0,0,0,0,0,0,0,0,0,0,0,0,0,0,0,0,0,0,0,0,0,0,0,0
0,0,0,0,0,0,0,0,0,0,0,0,0,0,0,0,0,0,0,0,0,0,0,0,0,0,0
0,0,0,0,0,0,0,0,0,0,0,0,0,0,0,0,0,0,0,0,0,0,0,0,0,0,0
0,0,0,0,0,0,0,0,0,0,0,0,0,0,0,0,0,0,0,0,0,0,0,0,0,0,0
0,0,0,0,0,0,0,0,0,0,0,0,0,0,0,0,0,0,0,0,0,0,0,0,0,0,0
0,0,0,0,0,0,0,0,0,0,0,0,0,0,0,0,0,0,0,0,0,0,0,0,0,0,0
0,0,0,0,0,0,0,0,0,0,0,0,0,0,0,0,0,0,0,0,0,0,0,0,0,0,0
0,0,0,0,0,0,0,0,0,0,0,0,0,0,0,0,0,0,0,0,0,0,0,0,0,0,0
0,0,0,0,0,0,0,0,0,0,0,0,0,0,0,0,0,0,0,0,0,0,0,0,0,0,0
0,0,0,0,0,0,0,0,0,0,0,0,0,0,0,0,0,0,0,0,0,0,0,0,0,0,0
0,0,0,0,0,0,0,0,0,0,0,0,0,0,0,0,0,0,0,0,0,0,0,0,0,0,0
0,0,0,0,0,0,0,0,0,0,0,0,0,0,0,0,0,0,0,0,0,0,0,0,0,0,0
0,0,0,0,0,0,0,0,0,0,0,0,0,0,0,0,0,0,0,0,0,0,0,0,0,0,0
:endlayer
layer: 35
0,0,0,0,0,0,0,0,0,0,0,0,0,0,0,0,0,0,0,0,0,0,0,0,0,0,0
0,0,0,0,0,0,0,0,0,0,0,0,0,0,0,0,0,0,0,0,0,0,0,0,0,0,0
0,0,0,0,0,0,0,0,0,0,0,0,0,0,0,0,0,0,0,0,0,0,0,0,0,0,0
0,0,0,0,0,0,0,0,0,0,0,0,0,0,0,0,0,0,0,0,0,0,0,0,0,0,0
0,0,0,0,0,0,0,0,0,0,0,0,0,0,0,0,0,0,0,0,0,0,0,0,0,0,0
0,0,0,0,0,0,0,0,0,0,0,0,0,0,0,0,0,0,0,0,0,0,0,0,0,0,0
0,0,0,0,0,0,0,0,0,0,0,0,0,0,0,0,0,0,0,0,0,0,0,0,0,0,0
0,0,0,0,0,0,0,0,0,0,0,0,0,0,0,0,0,0,0,0,0,0,0,0,0,0,0
0,0,0,0,0,0,0,0,0,0,0,0,0,0,0,0,0,0,0,0,0,0,0,0,0,0,0
0,0,0,0,0,0,0,0,0,0,0,0,0,0,0,0,0,0,0,0,0,0,0,0,0,0,0
0,0,0,0,0,0,0,0,0,0,0,0,0,0,0,0,0,0,0,0,0,0,0,0,0,0,0
0,0,0,0,0,0,0,0,0,0,0,0,0,0,73,0,0,0,0,0,0,0,0,0,0,0,0
0,0,0,0,0,0,0,0,0,0,0,0,0,0,0,0,0,0,0,0,0,0,0,0,0,0,0
0,0,0,0,0,0,0,0,0,0,0,0,0,0,0,0,0,0,0,0,0,0,0,0,0,0,0
0,0,0,0,0,0,0,0,0,0,0,0,0,0,0,0,0,0,0,0,0,0,0,0,0,0,0
0,0,0,0,0,0,0,0,0,0,0,0,0,0,0,0,0,0,0,0,0,0,0,0,0,0,0
0,0,0,0,0,0,0,0,0,0,0,0,0,0,0,0,0,0,0,0,0,0,0,0,0,0,0
0,0,0,0,0,0,0,0,0,0,0,0,0,0,0,0,0,0,0,0,0,0,0,0,0,0,0
0,0,0,0,0,0,0,0,0,0,0,0,0,0,0,0,0,0,0,0,0,0,0,0,0,0,0
0,0,0,0,0,0,0,0,0,0,0,0,0,0,0,0,0,0,0,0,0,0,0,0,0,0,0
0,0,0,0,0,0,0,0,0,0,0,0,0,0,0,0,0,0,0,0,0,0,0,0,0,0,0
0,0,0,0,0,0,0,0,0,0,0,0,0,0,0,0,0,0,0,0,0,0,0,0,0,0,0
0,0,0,0,0,0,0,0,0,0,0,0,0,0,0,0,0,0,0,0,0,0,0,0,0,0,0
0,0,0,0,0,0,0,0,0,0,0,0,0,0,0,0,0,0,0,0,0,0,0,0,0,0,0
0,0,0,0,0,0,0,0,0,0,0,0,0,0,0,0,0,0,0,0,0,0,0,0,0,0,0
0,0,0,0,0,0,0,0,0,0,0,0,0,0,0,0,0,0,0,0,0,0,0,0,0,0,0
0,0,0,0,0,0,0,0,0,0,0,0,0,0,0,0,0,0,0,0,0,0,0,0,0,0,0
0,0,0,0,0,0,0,0,0,0,0,0,0,0,0,0,0,0,0,0,0,0,0,0,0,0,0
0,0,0,0,0,0,0,0,0,0,0,0,0,0,0,0,0,0,0,0,0,0,0,0,0,0,0
0,0,0,0,0,0,0,0,0,0,0,0,0,0,0,0,0,0,0,0,0,0,0,0,0,0,0
0,0,0,0,0,0,0,0,0,0,0,0,0,0,0,0,0,0,0,0,0,0,0,0,0,0,0
0,0,0,0,0,0,0,0,0,0,0,0,0,0,0,0,0,0,0,0,0,0,0,0,0,0,0
0,0,0,0,0,0,0,0,0,0,0,0,0,0,0,0,0,0,0,0,0,0,0,0,0,0,0
0,0,0,0,0,0,0,0,0,0,0,0,0,0,0,0,0,0,0,0,0,0,0,0,0,0,0
0,0,0,0,0,0,0,0,0,0,0,0,0,0,0,0,0,0,0,0,0,0,0,0,0,0,0
0,0,0,0,0,0,0,0,0,0,0,0,0,0,0,0,0,0,0,0,0,0,0,0,0,0,0
0,0,0,0,0,0,0,0,0,0,0,0,0,0,0,0,0,0,0,0,0,0,0,0,0,0,0
0,0,0,0,0,0,0,0,0,0,0,0,0,0,0,0,0,0,0,0,0,0,0,0,0,0,0
0,0,0,0,0,0,0,0,0,0,0,0,0,0,0,0,0,0,0,0,0,0,0,0,0,0,0
:endlayer
layer: 36
0,0,0,0,0,0,0,0,0,0,0,0,0,0,0,0,0,0,0,0,0,0,0,0,0,0,0
0,0,0,0,0,0,0,0,0,0,0,0,0,0,0,0,0,0,0,0,0,0,0,0,0,0,0
0,0,0,0,0,0,0,0,0,0,0,0,0,0,0,0,0,0,0,0,0,0,0,0,0,0,0
0,0,0,0,0,0,0,0,0,0,0,0,0,0,0,0,0,0,0,0,0,0,0,0,0,0,0
0,0,0,0,0,0,0,0,0,0,0,0,0,0,0,0,0,0,0,0,0,0,0,0,0,0,0
0,0,0,0,0,0,0,0,0,0,0,0,0,0,0,0,0,0,0,0,0,0,0,0,0,0,0
0,0,0,0,0,0,0,0,0,0,0,0,0,0,0,0,0,0,0,0,0,0,0,0,0,0,0
0,0,0,0,0,0,0,0,0,0,0,0,0,0,0,0,0,0,0,0,0,0,0,0,0,0,0
0,0,0,0,0,0,0,0,0,0,0,0,0,0,0,0,0,0,0,0,0,0,0,0,0,0,0
0,0,0,0,0,0,0,0,0,0,0,0,0,0,0,0,0,0,0,0,0,0,0,0,0,0,0
0,0,0,0,0,0,0,0,0,0,0,0,0,0,0,0,0,0,0,0,0,0,0,0,0,0,0
0,0,0,0,0,0,0,0,0,0,0,0,0,0,0,0,0,0,0,0,0,0,0,0,0,0,0
0,0,0,0,0,0,0,0,0,0,0,0,0,0,0,0,0,0,0,0,0,0,0,0,0,0,0
0,0,0,0,0,0,0,0,0,0,0,0,0,0,0,0,0,0,0,0,0,0,0,0,0,0,0
0,0,0,0,0,0,0,0,0,0,0,0,0,0,0,0,0,0,0,0,0,0,0,0,0,0,0
0,0,0,0,0,0,0,0,0,0,0,0,0,0,0,0,0,0,0,0,0,0,0,0,0,0,0
0,0,0,0,0,0,0,0,0,0,0,0,0,0,0,0,0,0,0,0,0,0,0,0,0,0,0
0,0,0,0,0,0,0,0,0,0,0,0,0,0,0,0,0,0,0,0,0,0,0,0,0,0,0
0,0,0,0,0,0,0,0,0,0,0,0,0,0,0,0,0,0,0,0,0,0,0,0,0,0,0
0,0,0,0,0,0,0,0,0,0,0,0,0,0,0,0,0,0,0,0,0,0,0,0,0,0,0
0,0,0,0,0,0,0,0,0,0,0,0,0,0,0,0,0,0,0,0,0,0,0,0,0,0,0
0,0,0,0,0,0,0,0,0,0,0,0,0,0,0,0,0,0,0,0,0,0,0,0,0,0,0
0,0,0,0,0,0,0,0,0,0,0,0,0,0,0,0,0,0,0,0,0,0,0,0,0,0,0
0,0,0,0,0,0,0,0,0,0,0,0,0,0,0,0,0,0,0,0,0,0,0,0,0,0,0
0,0,0,0,0,0,0,0,0,0,0,0,0,0,0,0,0,0,0,0,0,0,0,0,0,0,0
0,0,0,0,0,0,0,0,0,0,0,0,0,0,0,0,0,0,0,0,0,0,0,0,0,0,0
0,0,0,0,0,0,0,0,0,0,0,0,0,0,0,0,0,0,0,0,0,0,0,0,0,0,0
0,0,0,0,0,0,0,0,0,0,0,0,0,0,0,0,0,0,0,0,0,0,0,0,0,0,0
0,0,0,0,0,0,0,0,0,0,0,0,0,0,0,0,0,0,0,0,0,0,0,0,0,0,0
0,0,0,0,0,0,0,0,0,0,0,0,0,0,0,0,0,0,0,0,0,0,0,0,0,0,0
0,0,0,0,0,0,0,0,0,0,0,0,0,0,0,0,0,0,0,0,0,0,0,0,0,0,0
0,0,0,0,0,0,0,0,0,0,0,0,0,0,0,0,0,0,0,0,0,0,0,0,0,0,0
0,0,0,0,0,0,0,0,0,0,0,0,0,0,0,0,0,0,0,0,0,0,0,0,0,0,0
0,0,0,0,0,0,0,0,0,0,0,0,0,0,0,0,0,0,0,0,0,0,0,0,0,0,0
0,0,0,0,0,0,0,0,0,0,0,0,0,0,0,0,0,0,0,0,0,0,0,0,0,0,0
0,0,0,0,0,0,0,0,0,0,0,0,0,0,0,0,0,0,0,0,0,0,0,0,0,0,0
0,0,0,0,0,0,0,0,0,0,0,0,0,0,0,0,0,0,0,0,0,0,0,0,0,0,0
0,0,0,0,0,0,0,0,0,0,0,0,0,0,0,0,0,0,0,0,0,0,0,0,0,0,0
0,0,0,0,0,0,0,0,0,0,0,0,0,0,0,0,0,0,0,0,0,0,0,0,0,0,0
:endlayer
layer: 37
0,0,0,0,0,0,0,0,0,0,0,0,0,0,0,0,0,0,0,0,0,0,0,0,0,0,0
0,0,0,0,0,0,0,0,0,0,0,0,0,0,0,0,0,0,0,0,0,0,0,0,0,0,0
0,0,0,0,0,0,0,0,0,0,0,0,0,0,0,0,0,0,0,0,0,0,0,0,0,0,0
0,0,0,0,0,0,0,0,0,0,0,0,0,0,0,0,0,0,0,0,0,0,0,0,0,0,0
0,0,0,0,0,0,0,0,0,0,0,0,0,0,0,0,0,0,0,0,0,0,0,0,0,0,0
0,0,0,0,0,0,0,0,0,0,0,0,0,0,0,0,0,0,0,0,0,0,0,0,0,0,0
0,0,0,0,0,0,0,0,0,0,0,0,0,0,0,0,0,0,0,0,0,0,0,0,0,0,0
0,0,0,0,0,0,0,0,0,0,0,0,0,0,0,0,0,0,0,0,0,0,0,0,0,0,0
0,0,0,0,0,0,0,0,0,0,0,0,0,0,0,0,0,0,0,0,0,0,0,0,0,0,0
0,0,0,0,0,0,0,0,0,0,0,0,0,0,0,0,0,0,0,0,0,0,0,0,0,0,0
0,0,0,0,0,0,0,0,0,0,0,0,0,0,0,0,0,0,0,0,0,0,0,0,0,0,0
0,0,0,0,0,0,0,0,0,0,0,0,0,0,0,0,0,0,0,0,0,0,0,0,0,0,0
0,0,0,0,0,0,0,0,0,0,0,0,0,0,0,0,0,0,0,0,0,0,0,0,0,0,0
0,0,0,0,0,0,0,0,0,0,0,0,0,0,0,0,0,0,0,0,0,0,0,0,0,0,0
0,0,0,0,0,0,0,0,0,0,0,0,0,0,0,0,0,0,0,0,0,0,0,0,0,0,0
0,0,0,0,0,0,0,0,0,0,0,0,0,0,0,0,0,0,0,0,0,0,0,0,0,0,0
0,0,0,0,0,0,0,0,0,0,0,0,0,0,0,0,0,0,0,0,0,0,0,0,0,0,0
0,0,0,0,0,0,0,0,0,0,0,0,0,0,0,0,0,0,0,0,0,0,0,0,0,0,0
0,0,0,0,0,0,0,0,0,0,0,0,0,0,0,0,0,0,0,0,0,0,0,0,0,0,0
0,0,0,0,0,0,0,0,0,0,0,0,0,0,0,0,0,0,0,0,0,0,0,0,0,0,0
0,0,0,0,0,0,0,0,0,0,0,0,0,0,0,0,0,0,0,0,0,0,0,0,0,0,0
0,0,0,0,0,0,0,0,0,0,0,0,0,0,0,0,0,0,0,0,0,0,0,0,0,0,0
0,0,0,0,0,0,0,0,0,0,0,0,0,0,0,0,0,0,0,0,0,0,0,0,0,0,0
0,0,0,0,0,0,0,0,0,0,0,0,0,0,0,0,0,0,0,0,0,0,0,0,0,0,0
0,0,0,0,0,0,0,0,0,0,0,0,0,0,0,0,0,0,0,0,0,0,0,0,0,0,0
0,0,0,0,0,0,0,0,0,0,0,0,0,0,0,0,0,0,0,0,0,0,0,0,0,0,0
0,0,0,0,0,0,0,0,0,0,0,0,0,0,0,0,0,0,0,0,0,0,0,0,0,0,0
0,0,0,0,0,0,0,0,0,0,0,0,0,0,0,0,0,0,0,0,0,0,0,0,0,0,0
0,0,0,0,0,0,0,0,0,0,0,0,0,0,0,0,0,0,0,0,0,0,0,0,0,0,0
0,0,0,0,0,0,0,0,0,0,0,0,0,0,0,0,0,0,0,0,0,0,0,0,0,0,0
0,0,0,0,0,0,0,0,0,0,0,0,0,0,0,0,0,0,0,0,0,0,0,0,0,0,0
0,0,0,0,0,0,0,0,0,0,0,0,0,0,0,0,0,0,0,0,0,0,0,0,0,0,0
0,0,0,0,0,0,0,0,0,0,0,0,0,0,0,0,0,0,0,0,0,0,0,0,0,0,0
0,0,0,0,0,0,0,0,0,0,0,0,0,0,0,0,0,0,0,0,0,0,0,0,0,0,0
0,0,0,0,0,0,0,0,0,0,0,0,0,0,0,0,0,0,0,0,0,0,0,0,0,0,0
0,0,0,0,0,0,0,0,0,0,0,0,0,0,0,0,0,0,0,0,0,0,0,0,0,0,0
0,0,0,0,0,0,0,0,0,0,0,0,0,0,0,0,0,0,0,0,0,0,0,0,0,0,0
0,0,0,0,0,0,0,0,0,0,0,0,0,0,0,0,0,0,0,0,0,0,0,0,0,0,0
0,0,0,0,0,0,0,0,0,0,0,0,0,0,0,0,0,0,0,0,0,0,0,0,0,0,0
:endlayer
layer: 38
0,0,0,0,0,0,0,0,0,0,0,0,0,0,0,0,0,0,0,0,0,0,0,0,0,0,0
0,0,0,0,0,0,0,0,0,0,0,0,0,0,0,0,0,0,0,0,0,0,0,0,0,0,0
0,0,0,0,0,0,0,0,0,0,0,0,0,0,0,0,0,0,0,0,0,0,0,0,0,0,0
0,0,0,0,0,0,0,0,0,0,0,0,0,0,0,0,0,0,0,0,0,0,0,0,0,0,0
0,0,0,0,0,0,0,0,0,0,0,0,0,0,0,0,0,0,0,0,0,0,0,0,0,0,0
0,0,0,0,0,0,0,0,0,0,0,0,0,0,0,0,0,0,0,0,0,0,0,0,0,0,0
0,0,0,0,0,0,0,0,0,0,0,0,0,0,0,0,0,0,0,0,0,0,0,0,0,0,0
0,0,0,0,0,0,0,0,0,0,0,0,0,0,0,0,0,0,0,0,0,0,0,0,0,0,0
0,0,0,0,0,0,0,0,0,0,0,0,0,0,0,0,0,0,0,0,0,0,0,0,0,0,0
0,0,0,0,0,0,0,0,0,0,0,0,0,0,0,0,0,0,0,0,0,0,0,0,0,0,0
0,0,0,0,0,0,0,0,0,0,0,0,0,0,0,0,0,0,0,0,0,0,0,0,0,0,0
0,0,0,0,0,0,0,0,0,0,0,0,0,0,0,0,0,0,0,0,0,0,0,0,0,0,0
0,0,0,0,0,0,0,0,0,0,0,0,0,0,0,0,0,0,0,0,0,0,0,0,0,0,0
0,0,0,0,0,0,0,0,0,0,0,0,0,0,0,0,0,0,0,0,0,0,0,0,0,0,0
0,0,0,0,0,0,0,0,0,0,0,0,0,0,0,0,0,0,0,0,0,0,0,0,0,0,0
0,0,0,0,0,0,0,0,0,0,0,0,0,0,0,0,0,0,0,0,0,0,0,0,0,0,0
0,0,0,0,0,0,0,0,0,0,0,0,0,0,0,0,0,0,0,0,0,0,0,0,0,0,0
0,0,0,0,0,0,0,0,0,0,0,0,0,0,0,0,0,0,0,0,0,0,0,0,0,0,0
0,0,0,0,0,0,0,0,0,0,0,0,0,0,0,0,0,0,0,0,0,0,0,0,0,0,0
0,0,0,0,0,0,0,0,0,0,0,0,0,0,0,0,0,0,0,0,0,0,0,0,0,0,0
0,0,0,0,0,0,0,0,0,0,0,0,0,0,0,0,0,0,0,0,0,0,0,0,0,0,0
0,0,0,0,0,0,0,0,0,0,0,0,0,0,0,0,0,0,0,0,0,0,0,0,0,0,0
0,0,0,0,0,0,0,0,0,0,0,0,0,0,0,0,0,0,0,0,0,0,0,0,0,0,0
0,0,0,0,0,0,0,0,0,0,0,0,0,0,0,0,0,0,0,0,0,0,0,0,0,0,0
0,0,0,0,0,0,0,0,0,0,0,0,0,0,0,0,0,0,0,0,0,0,0,0,0,0,0
0,0,0,0,0,0,0,0,0,0,0,0,0,0,0,0,0,0,0,0,0,0,0,0,0,0,0
0,0,0,0,0,0,0,0,0,0,0,0,0,0,0,0,0,0,0,0,0,0,0,0,0,0,0
0,0,0,0,0,0,0,0,0,0,0,0,0,0,0,0,0,0,0,0,0,0,0,0,0,0,0
0,0,0,0,0,0,0,0,0,0,0,0,0,0,0,0,0,0,0,0,0,0,0,0,0,0,0
0,0,0,0,0,0,0,0,0,0,0,0,0,0,0,0,0,0,0,0,0,0,0,0,0,0,0
0,0,0,0,0,0,0,0,0,0,0,0,0,0,0,0,0,0,0,0,0,0,0,0,0,0,0
0,0,0,0,0,0,0,0,0,0,0,0,0,0,0,0,0,0,0,0,0,0,0,0,0,0,0
0,0,0,0,0,0,0,0,0,0,0,0,0,0,0,0,0,0,0,0,0,0,0,0,0,0,0
0,0,0,0,0,0,0,0,0,0,0,0,0,0,0,0,0,0,0,0,0,0,0,0,0,0,0
0,0,0,0,0,0,0,0,0,0,0,0,0,0,0,0,0,0,0,0,0,0,0,0,0,0,0
0,0,0,0,0,0,0,0,0,0,0,0,0,0,0,0,0,0,0,0,0,0,0,0,0,0,0
0,0,0,0,0,0,0,0,0,0,0,0,0,0,0,0,0,0,0,0,0,0,0,0,0,0,0
0,0,0,0,0,0,0,0,0,0,0,0,0,0,0,0,0,0,0,0,0,0,0,0,0,0,0
0,0,0,0,0,0,0,0,0,0,0,0,0,0,0,0,0,0,0,0,0,0,0,0,0,0,0
:endlayer
layer: 39
0,0,0,0,0,0,0,0,0,0,0,0,0,0,0,0,0,0,0,0,0,0,0,0,0,0,0
0,0,0,0,0,0,0,0,0,0,0,0,0,0,0,0,0,0,0,0,0,0,0,0,0,0,0
0,0,0,0,0,0,0,0,0,0,0,0,0,0,0,0,0,0,0,0,0,0,0,0,0,0,0
0,0,0,0,0,0,0,0,0,0,0,0,0,0,0,0,0,0,0,0,0,0,0,0,0,0,0
0,0,0,0,0,0,0,0,0,0,0,0,0,0,0,0,0,0,0,0,0,0,0,0,0,0,0
0,0,0,0,0,0,0,0,0,0,0,0,0,0,0,0,0,0,0,0,0,0,0,0,0,0,0
0,0,0,0,0,0,0,0,0,0,0,0,0,0,0,0,0,0,0,0,0,0,0,0,0,0,0
0,0,0,0,0,0,0,0,0,0,0,0,0,0,0,0,0,0,0,0,0,0,0,0,0,0,0
0,0,0,0,0,0,0,0,0,0,0,0,0,0,0,0,0,0,0,0,0,0,0,0,0,0,0
0,0,0,0,0,0,0,0,0,0,0,0,0,0,0,0,0,0,0,0,0,0,0,0,0,0,0
0,0,0,0,0,0,0,0,0,0,0,0,0,0,0,0,0,0,0,0,0,0,0,0,0,0,0
0,0,0,0,0,0,0,0,0,0,0,0,0,0,0,0,0,0,0,0,0,0,0,0,0,0,0
0,0,0,0,0,0,0,0,0,0,0,0,0,0,0,0,0,0,0,0,0,0,0,0,0,0,0
0,0,0,0,0,0,0,0,0,0,0,0,0,0,0,0,0,0,0,0,0,0,0,0,0,0,0
0,0,0,0,0,0,0,0,0,0,0,0,0,0,0,0,0,0,0,0,0,0,0,0,0,0,0
0,0,0,0,0,0,0,0,0,0,0,0,0,0,0,0,0,0,0,0,0,0,0,0,0,0,0
0,0,0,0,0,0,0,0,0,0,0,0,0,0,0,0,0,0,0,0,0,0,0,0,0,0,0
0,0,0,0,0,0,0,0,0,0,0,0,0,0,0,0,0,0,0,0,0,0,0,0,0,0,0
0,0,0,0,0,0,0,0,0,0,0,0,0,0,0,0,0,0,0,0,0,0,0,0,0,0,0
0,0,0,0,0,0,0,0,0,0,0,0,0,0,0,0,0,0,0,0,0,0,0,0,0,0,0
0,0,0,0,0,0,0,0,0,0,0,0,0,0,0,0,0,0,0,0,0,0,0,0,0,0,0
0,0,0,0,0,0,0,0,0,0,0,0,0,0,0,0,0,0,0,0,0,0,0,0,0,0,0
0,0,0,0,0,0,0,0,0,0,0,0,0,0,0,0,0,0,0,0,0,0,0,0,0,0,0
0,0,0,0,0,0,0,0,0,0,0,0,0,0,0,0,0,0,0,0,0,0,0,0,0,0,0
0,0,0,0,0,0,0,0,0,0,0,0,0,0,0,0,0,0,0,0,0,0,0,0,0,0,0
0,0,0,0,0,0,0,0,0,0,0,0,0,0,0,0,0,0,0,0,0,0,0,0,0,0,0
0,0,0,0,0,0,0,0,0,0,0,0,0,0,0,0,0,0,0,0,0,0,0,0,0,0,0
0,0,0,0,0,0,0,0,0,0,0,0,0,0,0,0,0,0,0,0,0,0,0,0,0,0,0
0,0,0,0,0,0,0,0,0,0,0,0,0,0,0,0,0,0,0,0,0,0,0,0,0,0,0
0,0,0,0,0,0,0,0,0,0,0,0,0,0,0,0,0,0,0,0,0,0,0,0,0,0,0
0,0,0,0,0,0,0,0,0,0,0,0,0,0,0,0,0,0,0,0,0,0,0,0,0,0,0
0,0,0,0,0,0,0,0,0,0,0,0,0,0,0,0,0,0,0,0,0,0,0,0,0,0,0
0,0,0,0,0,0,0,0,0,0,0,0,0,0,0,0,0,0,0,0,0,0,0,0,0,0,0
0,0,0,0,0,0,0,0,0,0,0,0,0,0,0,0,0,0,0,0,0,0,0,0,0,0,0
0,0,0,0,0,0,0,0,0,0,0,0,0,0,0,0,0,0,0,0,0,0,0,0,0,0,0
0,0,0,0,0,0,0,0,0,0,0,0,0,0,0,0,0,0,0,0,0,0,0,0,0,0,0
0,0,0,0,0,0,0,0,0,0,0,0,0,0,0,0,0,0,0,0,0,0,0,0,0,0,0
0,0,0,0,0,0,0,0,0,0,0,0,0,0,0,0,0,0,0,0,0,0,0,0,0,0,0
0,0,0,0,0,0,0,0,0,0,0,0,0,0,0,0,0,0,0,0,0,0,0,0,0,0,0
:endlayer
layer: 40
0,0,0,0,0,0,0,0,0,0,0,0,0,0,0,0,0,0,0,0,0,0,0,0,0,0,0
0,0,0,0,0,0,0,0,0,0,0,0,0,0,0,0,0,0,0,0,0,0,0,0,0,0,0
0,0,0,0,0,0,0,0,0,0,0,0,0,0,0,0,0,0,0,0,0,0,0,0,0,0,0
0,0,0,0,0,0,0,0,0,0,0,0,0,0,0,0,0,0,0,0,0,0,0,0,0,0,0
0,0,0,0,0,0,0,0,0,0,0,0,0,0,0,0,0,0,0,0,0,0,0,0,0,0,0
0,0,0,0,0,0,0,0,0,0,0,0,0,0,0,0,0,0,0,0,0,0,0,0,0,0,0
0,0,0,0,0,0,0,0,0,0,0,0,0,0,0,0,0,0,0,0,0,0,0,0,0,0,0
0,0,0,0,0,0,0,0,0,0,0,0,0,0,0,0,0,0,0,0,0,0,0,0,0,0,0
0,0,0,0,0,0,0,0,0,0,0,0,0,0,0,0,0,0,0,0,0,0,0,0,0,0,0
0,0,0,0,0,0,0,0,0,0,0,0,0,0,0,0,0,0,0,0,0,0,0,0,0,0,0
0,0,0,0,0,0,0,0,0,0,0,0,0,0,0,0,0,0,0,0,0,0,0,0,0,0,0
0,0,0,0,0,0,0,0,0,0,0,0,0,0,0,0,0,0,0,0,0,0,0,0,0,0,0
0,0,0,0,0,0,0,0,0,0,0,0,0,0,0,0,0,0,0,0,0,0,0,0,0,0,0
0,0,0,0,0,0,0,0,0,0,0,0,0,0,0,0,0,0,0,0,0,0,0,0,0,0,0
0,0,0,0,0,0,0,0,0,0,0,0,0,0,0,0,0,0,0,0,0,0,0,0,0,0,0
0,0,0,0,0,0,0,0,0,0,0,0,0,0,0,0,0,0,0,0,0,0,0,0,0,0,0
0,0,0,0,0,0,0,0,0,0,0,0,0,0,0,0,0,0,0,0,0,0,0,0,0,0,0
0,0,0,0,0,0,0,0,0,0,0,0,0,0,0,0,0,0,0,0,0,0,0,0,0,0,0
0,0,0,0,0,0,0,0,0,0,0,0,0,0,0,0,0,0,0,0,0,0,0,0,0,0,0
0,0,0,0,0,0,0,0,0,0,0,0,0,0,0,0,0,0,0,0,0,0,0,0,0,0,0
0,0,0,0,0,0,0,0,0,0,0,0,0,0,0,0,0,0,0,0,0,0,0,0,0,0,0
0,0,0,0,0,0,0,0,0,0,0,0,0,0,0,0,0,0,0,0,0,0,0,0,0,0,0
0,0,0,0,0,0,0,0,0,0,0,0,0,0,0,0,0,0,0,0,0,0,0,0,0,0,0
0,0,0,0,0,0,0,0,0,0,0,0,0,0,0,0,0,0,0,0,0,0,0,0,0,0,0
0,0,0,0,0,0,0,0,0,0,0,0,0,0,0,0,0,0,0,0,0,0,0,0,0,0,0
0,0,0,0,0,0,0,0,0,0,0,0,0,0,0,0,0,0,0,0,0,0,0,0,0,0,0
0,0,0,0,0,0,0,0,0,0,0,0,0,0,0,0,0,0,0,0,0,0,0,0,0,0,0
0,0,0,0,0,0,0,0,0,0,0,0,0,0,0,0,0,0,0,0,0,0,0,0,0,0,0
0,0,0,0,0,0,0,0,0,0,0,0,0,0,0,0,0,0,0,0,0,0,0,0,0,0,0
0,0,0,0,0,0,0,0,0,0,0,0,0,0,0,0,0,0,0,0,0,0,0,0,0,0,0
0,0,0,0,0,0,0,0,0,0,0,0,0,0,0,0,0,0,0,0,0,0,0,0,0,0,0
0,0,0,0,0,0,0,0,0,0,0,0,0,0,0,0,0,0,0,0,0,0,0,0,0,0,0
0,0,0,0,0,0,0,0,0,0,0,0,0,0,0,0,0,0,0,0,0,0,0,0,0,0,0
0,0,0,0,0,0,0,0,0,0,0,0,0,0,0,0,0,0,0,0,0,0,0,0,0,0,0
0,0,0,0,0,0,0,0,0,0,0,0,0,0,0,0,0,0,0,0,0,0,0,0,0,0,0
0,0,0,0,0,0,0,0,0,0,0,0,0,0,0,0,0,0,0,0,0,0,0,0,0,0,0
0,0,0,0,0,0,0,0,0,0,0,0,0,0,0,0,0,0,0,0,0,0,0,0,0,0,0
0,0,0,0,0,0,0,0,0,0,0,0,0,0,0,0,0,0,0,0,0,0,0,0,0,0,0
0,0,0,0,0,0,0,0,0,0,0,0,0,0,0,0,0,0,0,0,0,0,0,0,0,0,0
:endlayer
layer: 41
0,0,0,0,0,0,0,0,0,0,0,0,0,0,0,0,0,0,0,0,0,0,0,0,0,0,0
0,0,0,0,0,0,0,0,0,0,0,0,0,0,0,0,0,0,0,0,0,0,0,0,0,0,0
0,0,0,0,0,0,0,0,0,0,0,0,0,0,0,0,0,0,0,0,0,0,0,0,0,0,0
0,0,0,0,0,0,0,0,0,0,0,0,0,0,0,0,0,0,0,0,0,0,0,0,0,0,0
0,0,0,0,0,0,0,0,0,0,0,0,0,0,0,0,0,0,0,0,0,0,0,0,0,0,0
0,0,0,0,0,0,0,0,0,0,0,0,0,0,0,0,0,0,0,0,0,0,0,0,0,0,0
0,0,0,0,0,0,0,0,0,0,0,0,0,0,0,0,0,0,0,0,0,0,0,0,0,0,0
0,0,0,0,0,0,0,0,0,0,0,0,0,0,0,0,0,0,0,0,0,0,0,0,0,0,0
0,0,0,0,0,0,0,0,0,0,0,0,0,0,0,0,0,0,0,0,0,0,0,0,0,0,0
0,0,0,0,0,0,0,0,0,0,0,0,0,0,0,0,0,0,0,0,0,0,0,0,0,0,0
0,0,0,0,0,0,0,0,0,0,0,0,0,0,0,0,0,0,0,0,0,0,0,0,0,0,0
0,0,0,0,0,0,0,0,0,0,0,0,0,0,0,0,0,0,0,0,0,0,0,0,0,0,0
0,0,0,0,0,0,0,0,0,0,0,0,0,0,0,0,0,0,0,0,0,0,0,0,0,0,0
0,0,0,0,0,0,0,0,0,0,0,0,0,0,0,0,0,0,0,0,0,0,0,0,0,0,0
0,0,0,0,0,0,0,0,0,0,0,0,0,0,0,0,0,0,0,0,0,0,0,0,0,0,0
0,0,0,0,0,0,0,0,0,0,0,0,0,0,0,0,0,0,0,0,0,0,0,0,0,0,0
0,0,0,0,0,0,0,0,0,0,0,0,0,0,0,0,0,0,0,0,0,0,0,0,0,0,0
0,0,0,0,0,0,0,0,0,0,0,0,0,0,0,0,0,0,0,0,0,0,0,0,0,0,0
0,0,0,0,0,0,0,0,0,0,0,0,0,0,0,0,0,0,0,0,0,0,0,0,0,0,0
0,0,0,0,0,0,0,0,0,0,0,0,0,0,0,0,0,0,0,0,0,0,0,0,0,0,0
0,0,0,0,0,0,0,0,0,0,0,0,0,0,0,0,0,0,0,0,0,0,0,0,0,0,0
0,0,0,0,0,0,0,0,0,0,0,0,0,0,0,0,0,0,0,0,0,0,0,0,0,0,0
0,0,0,0,0,0,0,0,0,0,0,0,0,0,0,0,0,0,0,0,0,0,0,0,0,0,0
0,0,0,0,0,0,0,0,0,0,0,0,0,0,0,0,0,0,0,0,0,0,0,0,0,0,0
0,0,0,0,0,0,0,0,0,0,0,0,0,0,0,0,0,0,0,0,0,0,0,0,0,0,0
0,0,0,0,0,0,0,0,0,0,0,0,0,0,0,0,0,0,0,0,0,0,0,0,0,0,0
0,0,0,0,0,0,0,0,0,0,0,0,0,0,0,0,0,0,0,0,0,0,0,0,0,0,0
0,0,0,0,0,0,0,0,0,0,0,0,0,0,0,0,0,0,0,0,0,0,0,0,0,0,0
0,0,0,0,0,0,0,0,0,0,0,0,0,0,0,0,0,0,0,0,0,0,0,0,0,0,0
0,0,0,0,0,0,0,0,0,0,0,0,0,0,0,0,0,0,0,0,0,0,0,0,0,0,0
0,0,0,0,0,0,0,0,0,0,0,0,0,0,0,0,0,0,0,0,0,0,0,0,0,0,0
0,0,0,0,0,0,0,0,0,0,0,0,0,0,0,0,0,0,0,0,0,0,0,0,0,0,0
0,0,0,0,0,0,0,0,0,0,0,0,0,0,0,0,0,0,0,0,0,0,0,0,0,0,0
0,0,0,0,0,0,0,0,0,0,0,0,0,0,0,0,0,0,0,0,0,0,0,0,0,0,0
0,0,0,0,0,0,0,0,0,0,0,0,0,0,0,0,0,0,0,0,0,0,0,0,0,0,0
0,0,0,0,0,0,0,0,0,0,0,0,0,0,0,0,0,0,0,0,0,0,0,0,0,0,0
0,0,0,0,0,0,0,0,0,0,0,0,0,0,0,0,0,0,0,0,0,0,0,0,0,0,0
0,0,0,0,0,0,0,0,0,0,0,0,0,0,0,0,0,0,0,0,0,0,0,0,0,0,0
0,0,0,0,0,0,0,0,0,0,0,0,0,0,0,0,0,0,0,0,0,0,0,0,0,0,0
:endlayer
layer: 42
0,0,0,0,0,0,0,0,0,0,0,0,0,0,0,0,0,0,0,0,0,0,0,0,0,0,0
0,0,0,0,0,0,0,0,0,0,0,0,0,0,0,0,0,0,0,0,0,0,0,0,0,0,0
0,0,0,0,0,0,0,0,0,0,0,0,0,0,0,0,0,0,0,0,0,0,0,0,0,0,0
0,0,0,0,0,0,0,0,0,0,0,0,0,0,0,0,0,0,0,0,0,0,0,0,0,0,0
0,0,0,0,0,0,0,0,0,0,0,0,0,0,0,0,0,0,0,0,0,0,0,0,0,0,0
0,0,0,0,0,0,0,0,0,0,0,0,0,0,0,0,0,0,0,0,0,0,0,0,0,0,0
0,0,0,0,0,0,0,0,0,0,0,0,0,0,0,0,0,0,0,0,0,0,0,0,0,0,0
0,0,0,0,0,0,0,0,0,0,0,0,0,0,0,0,0,0,0,0,0,0,0,0,0,0,0
0,0,0,0,0,0,0,0,0,0,0,0,0,0,0,0,0,0,0,0,0,0,0,0,0,0,0
0,0,0,0,0,0,0,0,0,0,0,0,0,0,0,0,0,0,0,0,0,0,0,0,0,0,0
0,0,0,0,0,0,0,0,0,0,0,0,0,0,0,0,0,0,0,0,0,0,0,0,0,0,0
0,0,0,0,0,0,0,0,0,0,0,0,0,0,0,0,0,0,0,0,0,0,0,0,0,0,0
0,0,0,0,0,0,0,0,0,0,0,0,0,0,0,0,0,0,0,0,0,0,0,0,0,0,0
0,0,0,0,0,0,0,0,0,0,0,0,0,0,0,0,0,0,0,0,0,0,0,0,0,0,0
0,0,0,0,0,0,0,0,0,0,0,0,0,0,0,0,0,0,0,0,0,0,0,0,0,0,0
0,0,0,0,0,0,0,0,0,0,0,0,0,0,0,0,0,0,0,0,0,0,0,0,0,0,0
0,0,0,0,0,0,0,0,0,0,0,0,0,0,0,0,0,0,0,0,0,0,0,0,0,0,0
0,0,0,0,0,0,0,0,0,0,0,0,0,0,0,0,0,0,0,0,0,0,0,0,0,0,0
0,0,0,0,0,0,0,0,0,0,0,0,0,0,0,0,0,0,0,0,0,0,0,0,0,0,0
0,0,0,0,0,0,0,0,0,0,0,0,0,0,0,0,0,0,0,0,0,0,0,0,0,0,0
0,0,0,0,0,0,0,0,0,0,0,0,0,0,0,0,0,0,0,0,0,0,0,0,0,0,0
0,0,0,0,0,0,0,0,0,0,0,0,0,0,0,0,0,0,0,0,0,0,0,0,0,0,0
0,0,0,0,0,0,0,0,0,0,0,0,0,0,0,0,0,0,0,0,0,0,0,0,0,0,0
0,0,0,0,0,0,0,0,0,0,0,0,0,0,0,0,0,0,0,0,0,0,0,0,0,0,0
0,0,0,0,0,0,0,0,0,0,0,0,0,0,0,0,0,0,0,0,0,0,0,0,0,0,0
0,0,0,0,0,0,0,0,0,0,0,0,0,0,0,0,0,0,0,0,0,0,0,0,0,0,0
0,0,0,0,0,0,0,0,0,0,0,0,0,0,0,0,0,0,0,0,0,0,0,0,0,0,0
0,0,0,0,0,0,0,0,0,0,0,0,0,0,0,0,0,0,0,0,0,0,0,0,0,0,0
0,0,0,0,0,0,0,0,0,0,0,0,0,0,0,0,0,0,0,0,0,0,0,0,0,0,0
0,0,0,0,0,0,0,0,0,0,0,0,0,0,0,0,0,0,0,0,0,0,0,0,0,0,0
0,0,0,0,0,0,0,0,0,0,0,0,0,0,0,0,0,0,0,0,0,0,0,0,0,0,0
0,0,0,0,0,0,0,0,0,0,0,0,0,0,0,0,0,0,0,0,0,0,0,0,0,0,0
0,0,0,0,0,0,0,0,0,0,0,0,0,0,0,0,0,0,0,0,0,0,0,0,0,0,0
0,0,0,0,0,0,0,0,0,0,0,0,0,0,0,0,0,0,0,0,0,0,0,0,0,0,0
0,0,0,0,0,0,0,0,0,0,0,0,0,0,0,0,0,0,0,0,0,0,0,0,0,0,0
0,0,0,0,0,0,0,0,0,0,0,0,0,0,0,0,0,0,0,0,0,0,0,0,0,0,0
0,0,0,0,0,0,0,0,0,0,0,0,0,0,0,0,0,0,0,0,0,0,0,0,0,0,0
0,0,0,0,0,0,0,0,0,0,0,0,0,0,0,0,0,0,0,0,0,0,0,0,0,0,0
0,0,0,0,0,0,0,0,0,0,0,0,0,0,0,0,0,0,0,0,0,0,0,0,0,0,0
:endlayer
layer: 43
0,0,0,0,0,0,0,0,0,0,0,0,0,0,0,0,0,0,0,0,0,0,0,0,0,0,0
0,0,0,0,0,0,0,0,0,0,0,0,0,0,0,0,0,0,0,0,0,0,0,0,0,0,0
0,0,0,0,0,0,0,0,0,0,0,0,0,0,0,0,0,0,0,0,0,0,0,0,0,0,0
0,0,0,0,0,0,0,0,0,0,0,0,0,0,0,0,0,0,0,0,0,0,0,0,0,0,0
0,0,0,0,0,0,0,0,0,0,0,0,0,0,0,0,0,0,0,0,0,0,0,0,0,0,0
0,0,0,0,0,0,0,0,0,0,0,0,0,0,0,0,0,0,0,0,0,0,0,0,0,0,0
0,0,0,0,0,0,0,0,0,0,0,0,0,0,0,0,0,0,0,0,0,0,0,0,0,0,0
0,0,0,0,0,0,0,0,0,0,0,0,0,0,0,0,0,0,0,0,0,0,0,0,0,0,0
0,0,0,0,0,0,0,0,0,0,0,0,0,0,0,0,0,0,0,0,0,0,0,0,0,0,0
0,0,0,0,0,0,0,0,0,0,0,0,0,0,0,0,0,0,0,0,0,0,0,0,0,0,0
0,0,0,0,0,0,0,0,0,0,0,0,0,0,0,0,0,0,0,0,0,0,0,0,0,0,0
0,0,0,0,0,0,0,0,0,0,0,0,0,0,0,0,0,0,0,0,0,0,0,0,0,0,0
0,0,0,0,0,0,0,0,0,0,0,0,0,0,0,0,0,0,0,0,0,0,0,0,0,0,0
0,0,0,0,0,0,0,0,0,0,0,0,0,0,0,0,0,0,0,0,0,0,0,0,0,0,0
0,0,0,0,0,0,0,0,0,0,0,0,0,0,0,0,0,0,0,0,0,0,0,0,0,0,0
0,0,0,0,0,0,0,0,0,0,0,0,0,0,0,0,0,0,0,0,0,0,0,0,0,0,0
0,0,0,0,0,0,0,0,0,0,0,0,0,0,0,0,0,0,0,0,0,0,0,0,0,0,0
0,0,0,0,0,0,0,0,0,0,0,0,0,0,0,0,0,0,0,0,0,0,0,0,0,0,0
0,0,0,0,0,0,0,0,0,0,0,0,0,0,0,0,0,0,0,0,0,0,0,0,0,0,0
0,0,0,0,0,0,0,0,0,0,0,0,0,0,0,0,0,0,0,0,0,0,0,0,0,0,0
0,0,0,0,0,0,0,0,0,0,0,0,0,0,0,0,0,0,0,0,0,0,0,0,0,0,0
0,0,0,0,0,0,0,0,0,0,0,0,0,0,0,0,0,0,0,0,0,0,0,0,0,0,0
0,0,0,0,0,0,0,0,0,0,0,0,0,0,0,0,0,0,0,0,0,0,0,0,0,0,0
0,0,0,0,0,0,0,0,0,0,0,0,0,0,0,0,0,0,0,0,0,0,0,0,0,0,0
0,0,0,0,0,0,0,0,0,0,0,0,0,0,0,0,0,0,0,0,0,0,0,0,0,0,0
0,0,0,0,0,0,0,0,0,0,0,0,0,0,0,0,0,0,0,0,0,0,0,0,0,0,0
0,0,0,0,0,0,0,0,0,0,0,0,0,0,0,0,0,0,0,0,0,0,0,0,0,0,0
0,0,0,0,0,0,0,0,0,0,0,0,0,0,0,0,0,0,0,0,0,0,0,0,0,0,0
0,0,0,0,0,0,0,0,0,0,0,0,0,0,0,0,0,0,0,0,0,0,0,0,0,0,0
0,0,0,0,0,0,0,0,0,0,0,0,0,0,0,0,0,0,0,0,0,0,0,0,0,0,0
0,0,0,0,0,0,0,0,0,0,0,0,0,0,0,0,0,0,0,0,0,0,0,0,0,0,0
0,0,0,0,0,0,0,0,0,0,0,0,0,0,0,0,0,0,0,0,0,0,0,0,0,0,0
0,0,0,0,0,0,0,0,0,0,0,0,0,0,0,0,0,0,0,0,0,0,0,0,0,0,0
0,0,0,0,0,0,0,0,0,0,0,0,0,0,0,0,0,0,0,0,0,0,0,0,0,0,0
0,0,0,0,0,0,0,0,0,0,0,0,0,0,0,0,0,0,0,0,0,0,0,0,0,0,0
0,0,0,0,0,0,0,0,0,0,0,0,0,0,0,0,0,0,0,0,0,0,0,0,0,0,0
0,0,0,0,0,0,0,0,0,0,0,0,0,0,0,0,0,0,0,0,0,0,0,0,0,0,0
0,0,0,0,0,0,0,0,0,0,0,0,0,0,0,0,0,0,0,0,0,0,0,0,0,0,0
0,0,0,0,0,0,0,0,0,0,0,0,0,0,0,0,0,0,0,0,0,0,0,0,0,0,0
:endlayer
layer: 44
0,0,0,0,0,0,0,0,0,0,0,0,0,0,0,0,0,0,0,0,0,0,0,0,0,0,0
0,0,0,0,0,0,0,0,0,0,0,0,0,0,0,0,0,0,0,0,0,0,0,0,0,0,0
0,0,0,0,0,0,0,0,0,0,0,0,0,0,0,0,0,0,0,0,0,0,0,0,0,0,0
0,0,0,0,0,0,0,0,0,0,0,0,0,0,0,0,0,0,0,0,0,0,0,0,0,0,0
0,0,0,0,0,0,0,0,0,0,0,0,0,0,0,0,0,0,0,0,0,0,0,0,0,0,0
0,0,0,0,0,0,0,0,0,0,0,0,0,0,0,0,0,0,0,0,0,0,0,0,0,0,0
0,0,0,0,0,0,0,0,0,0,0,0,0,0,0,0,0,0,0,0,0,0,0,0,0,0,0
0,0,0,0,0,0,0,0,0,0,0,0,0,0,0,0,0,0,0,0,0,0,0,0,0,0,0
0,0,0,0,0,0,0,0,0,0,0,0,0,0,0,0,0,0,0,0,0,0,0,0,0,0,0
0,0,0,0,0,0,0,0,0,0,0,0,0,0,0,0,0,0,0,0,0,0,0,0,0,0,0
0,0,0,0,0,0,0,0,0,0,0,0,0,0,0,0,0,0,0,0,0,0,0,0,0,0,0
0,0,0,0,0,0,0,0,0,0,0,0,0,0,0,0,0,0,0,0,0,0,0,0,0,0,0
0,0,0,0,0,0,0,0,0,0,0,0,0,0,0,0,0,0,0,0,0,0,0,0,0,0,0
0,0,0,0,0,0,0,0,0,0,0,0,0,0,0,0,0,0,0,0,0,0,0,0,0,0,0
0,0,0,0,0,0,0,0,0,0,0,0,0,0,0,0,0,0,0,0,0,0,0,0,0,0,0
0,0,0,0,0,0,0,0,0,0,0,0,0,0,0,0,0,0,0,0,0,0,0,0,0,0,0
0,0,0,0,0,0,0,0,0,0,0,0,0,0,0,0,0,0,0,0,0,0,0,0,0,0,0
0,0,0,0,0,0,0,0,0,0,0,0,0,0,0,0,0,0,0,0,0,0,0,0,0,0,0
0,0,0,0,0,0,0,0,0,0,0,0,0,0,0,0,0,0,0,0,0,0,0,0,0,0,0
0,0,0,0,0,0,0,0,0,0,0,0,0,0,0,0,0,0,0,0,0,0,0,0,0,0,0
0,0,0,0,0,0,0,0,0,0,0,0,0,0,0,0,0,0,0,0,0,0,0,0,0,0,0
0,0,0,0,0,0,0,0,0,0,0,0,0,0,0,0,0,0,0,0,0,0,0,0,0,0,0
0,0,0,0,0,0,0,0,0,0,0,0,0,0,0,0,0,0,0,0,0,0,0,0,0,0,0
0,0,0,0,0,0,0,0,0,0,0,0,0,0,0,0,0,0,0,0,0,0,0,0,0,0,0
