# Ancient Warfare Structure Template File
# Auto-generated structure template file. created on: 12/25/2018 at: 22:42:58
# Lines beginning with # denote comments

header:
version=2.8
name=BrigandRuinLargeMagicians
mods=
size=27,36,39
offset=14,9,38
:endheader

#### VALIDATION ####
validation:
type=ground
survival=false
worldGenEnabled=true
unique=false
preserveBlocks=false
selectionWeight=30
clusterValue=80
minDuplicateDistance=990
dimensionWhiteList=true
dimensionList=0
biomeWhiteList=true
biomeList=minecraft:swampland,biomesoplenty:meadow,biomesoplenty:shrubland,biomesoplenty:woodland,biomesoplenty:dead_forest,traverse:woodlands,minecraft:forest,biomesoplenty:highland,traverse:meadow,traverse:rocky_plateau,biomesoplenty:pasture,minecraft:forest_hills,biomesoplenty:steppe,minecraft:plains,biomesoplenty:orchard
leveling=6
fill=6
border=6
blockSwap=true
:endvalidation

#### LAYERS ####
layer: 0
1,1,1,1,1,1,1,1,1,1,1,1,1,1,1,1,1,1,1,1,1,1,1,1,1,1,1
1,2,2,2,2,2,2,2,2,2,2,2,2,2,2,2,2,2,2,2,2,2,2,2,2,1,1
1,2,2,2,2,2,2,2,2,2,2,2,2,2,2,2,2,2,2,2,2,2,2,2,2,1,1
1,2,2,2,2,2,2,2,2,2,2,2,2,2,2,2,2,2,2,2,2,2,2,2,2,1,1
1,2,2,2,2,2,2,2,2,2,2,2,2,2,2,2,2,2,2,2,2,2,2,2,2,1,1
1,1,1,1,1,1,1,1,1,1,1,1,1,1,1,1,1,1,1,1,1,1,1,1,1,1,1
1,1,1,1,1,1,1,1,1,1,1,1,1,1,1,1,1,1,1,1,1,1,1,1,1,1,1
1,1,1,1,1,1,1,1,1,1,1,1,1,1,1,1,1,1,1,1,1,1,1,1,1,1,1
1,1,1,1,1,1,1,1,1,1,1,1,2,1,1,1,1,1,1,1,1,1,1,1,1,1,1
1,1,1,1,1,1,1,1,1,1,1,1,1,1,1,1,1,1,1,1,1,1,1,1,1,1,1
1,1,1,1,1,1,1,1,1,1,1,1,1,1,1,1,1,1,1,1,1,1,1,1,1,1,1
1,1,1,1,1,1,1,1,1,1,1,1,1,1,1,1,1,1,1,1,1,1,1,1,1,1,1
1,1,1,1,1,1,1,1,1,1,1,1,1,1,1,1,1,1,1,1,1,1,1,1,1,1,1
1,1,1,1,1,1,1,1,1,1,1,1,1,1,1,1,1,1,1,1,1,1,1,1,1,1,1
1,1,1,1,1,1,1,1,1,1,1,1,1,1,1,1,1,1,1,1,1,1,1,1,1,1,1
1,1,1,1,1,1,1,1,1,1,1,1,1,1,1,1,1,1,1,1,1,1,1,1,1,1,1
1,1,1,1,1,1,1,1,1,1,1,1,1,1,1,1,1,1,1,1,1,1,1,1,1,1,1
1,1,1,1,1,1,1,1,1,1,1,1,1,1,1,1,1,1,1,1,1,1,1,1,1,1,1
1,1,1,1,1,1,1,1,1,1,1,1,1,1,1,1,1,1,1,1,1,1,1,1,1,1,1
1,1,1,1,1,1,1,1,1,1,1,1,1,1,1,1,1,1,1,1,1,1,1,1,1,1,1
1,1,1,1,1,1,1,1,1,1,1,1,1,1,1,1,1,1,1,1,1,1,1,1,1,1,1
1,1,1,1,1,1,1,1,1,1,1,1,1,1,1,1,1,1,1,1,1,1,1,1,1,1,1
1,1,1,1,1,1,1,1,1,1,1,1,1,1,1,1,1,1,1,1,1,1,1,1,1,1,1
1,1,1,1,1,1,1,1,1,1,1,1,1,1,1,1,1,1,1,1,1,1,1,1,1,1,1
1,1,1,1,1,1,1,1,1,1,1,1,1,1,1,1,1,1,1,1,1,1,1,1,1,1,1
1,1,1,1,1,1,1,1,1,1,1,1,1,1,1,1,1,1,1,1,1,1,1,1,1,1,1
1,1,1,1,1,1,1,1,1,1,1,1,1,1,1,1,1,1,1,1,1,1,1,1,1,1,1
1,1,1,1,1,1,1,1,1,1,1,1,1,1,1,1,1,1,1,1,1,1,1,1,1,1,1
1,1,1,1,1,1,1,1,1,1,1,1,1,1,1,1,1,1,1,1,1,1,1,1,1,1,1
1,1,1,1,1,1,1,1,1,1,1,1,1,1,1,1,1,1,1,1,1,1,1,1,1,1,1
1,1,1,1,1,1,1,1,1,1,1,1,1,1,1,1,1,1,1,1,1,1,1,1,1,1,1
1,1,1,1,1,1,1,1,1,1,1,1,1,1,1,1,1,1,1,1,1,1,1,1,1,1,1
1,1,1,1,1,1,1,1,1,1,1,1,1,1,1,1,1,1,1,1,1,1,1,1,1,1,1
1,1,1,1,1,1,1,1,1,1,1,1,1,1,1,1,1,1,1,1,1,1,1,1,1,1,1
1,1,1,1,1,1,1,1,1,1,1,1,1,1,1,1,1,1,1,1,1,1,1,1,1,1,1
1,1,1,1,1,1,1,1,1,1,1,1,1,1,1,1,1,1,1,1,1,1,1,1,1,1,1
1,1,1,1,1,1,1,1,1,1,1,1,1,1,1,1,1,1,1,1,1,1,1,1,1,1,1
1,1,1,1,1,1,1,1,1,1,1,1,1,1,1,1,1,1,1,1,1,1,1,1,1,1,1
1,1,1,1,1,1,1,1,1,1,1,1,1,1,1,1,1,1,1,1,1,1,1,1,1,1,1
:endlayer
layer: 1
1,1,1,1,1,1,1,1,1,1,1,1,1,1,1,1,1,1,1,1,1,1,1,1,1,1,1
1,2,2,2,2,2,2,2,2,2,2,2,2,2,2,2,2,2,2,2,2,2,2,2,2,1,1
1,2,3,3,3,3,3,3,3,3,3,3,3,3,3,3,3,3,3,3,3,3,2,2,2,1,1
1,2,3,3,3,3,3,3,3,3,3,3,3,3,3,3,3,3,3,3,3,3,2,2,2,1,1
1,2,2,2,3,3,3,3,3,2,2,3,3,3,2,2,3,3,3,3,3,2,2,2,2,1,1
1,1,1,1,3,3,3,3,3,3,1,3,3,3,1,1,3,3,3,3,3,1,1,1,1,1,1
1,1,1,1,3,3,3,3,3,1,1,3,3,3,1,1,3,3,3,3,3,1,1,1,1,1,1
1,1,1,1,3,3,3,3,3,1,1,3,3,3,1,1,3,3,3,3,3,1,1,1,1,1,1
1,1,1,1,3,3,3,3,3,1,1,3,3,3,1,1,3,3,3,3,3,1,1,1,1,1,1
1,1,1,1,3,3,3,3,3,1,1,3,3,3,1,1,3,3,3,3,3,1,1,1,1,1,1
1,1,1,1,3,3,3,3,3,1,1,3,3,3,1,1,3,3,3,3,3,1,1,1,1,1,1
1,1,1,1,3,3,3,3,3,1,1,3,3,3,1,1,3,3,3,3,3,1,1,1,1,1,1
1,1,1,1,1,1,1,1,1,1,1,3,3,3,1,1,3,3,3,3,3,1,1,1,1,1,1
1,1,1,1,1,1,1,1,1,1,1,3,3,3,1,1,1,1,1,1,1,1,1,1,1,1,1
1,1,1,1,1,1,1,1,1,1,1,3,3,3,1,1,1,1,1,1,1,1,1,1,1,1,1
1,1,1,1,1,1,1,1,1,1,1,3,3,3,1,1,1,1,1,1,1,1,1,1,1,1,1
1,1,1,1,1,1,1,1,1,1,1,3,3,3,1,1,1,1,1,1,1,1,1,1,1,1,1
1,1,1,1,1,1,1,1,1,1,1,3,3,3,1,1,1,1,1,1,1,1,1,1,1,1,1
1,1,1,1,1,1,1,1,1,1,1,3,3,3,1,1,1,1,1,1,1,1,1,1,1,1,1
1,1,1,1,1,1,1,1,1,1,1,3,3,3,1,1,1,1,1,1,1,1,1,1,1,1,1
1,1,1,1,1,1,1,1,1,1,1,3,3,3,1,1,1,1,1,1,1,1,1,1,1,1,1
1,1,1,1,1,1,1,1,1,1,1,3,3,3,1,1,1,1,1,1,1,1,1,1,1,1,1
1,1,1,1,1,3,3,3,1,1,1,3,3,3,1,1,1,1,1,1,1,1,1,1,1,1,1
1,1,1,1,1,3,3,3,1,1,1,3,3,3,1,1,1,1,1,1,1,1,1,1,1,1,1
1,1,1,1,1,3,3,3,1,1,1,3,3,3,1,1,1,1,1,1,1,1,1,1,1,1,1
1,1,1,1,1,3,3,3,1,1,1,3,3,3,1,1,1,1,3,3,3,3,3,3,3,1,1
1,1,1,1,1,3,3,3,1,1,1,3,3,3,1,1,1,1,3,3,3,3,3,3,3,1,1
1,1,1,1,1,3,3,3,1,1,1,3,3,3,1,1,1,3,3,3,3,3,3,3,3,1,1
1,1,1,3,3,3,3,3,3,1,1,3,3,3,1,1,1,3,3,3,3,3,3,3,3,1,1
1,1,1,3,3,3,3,3,3,1,1,3,3,3,1,1,1,3,3,3,3,3,3,3,3,1,1
1,1,1,3,3,3,3,3,3,1,1,3,3,3,1,1,1,3,3,3,3,3,3,3,3,1,1
3,3,3,3,3,3,3,3,3,3,3,3,3,3,3,3,3,3,3,3,3,3,3,3,3,3,3
3,3,3,3,3,3,3,3,3,3,3,3,3,3,3,3,3,3,3,3,3,3,3,3,3,3,3
3,3,3,3,3,3,3,3,3,3,3,3,3,3,3,3,3,3,3,3,3,3,3,3,3,3,3
1,1,1,1,1,1,1,1,1,1,1,3,3,3,1,1,1,3,3,3,3,3,1,1,1,1,1
1,1,1,1,1,1,1,1,1,1,1,3,3,3,1,1,1,3,3,3,3,3,1,1,1,1,1
1,1,1,1,1,1,1,1,1,1,1,3,3,3,1,1,1,3,3,3,3,3,1,1,1,1,1
1,1,1,1,1,1,1,1,1,1,1,3,3,3,1,1,1,3,3,3,3,3,1,1,1,1,1
1,1,1,1,1,1,1,1,1,1,1,3,3,3,1,1,1,3,3,3,3,3,1,1,1,1,1
:endlayer
layer: 2
1,1,1,1,1,1,1,1,1,1,1,1,1,1,1,1,1,1,1,1,1,1,1,1,1,1,1
1,2,3,3,3,3,3,3,3,3,3,3,3,3,3,3,3,3,3,3,3,3,2,2,2,1,1
1,3,0,38,0,0,0,0,0,0,0,0,0,0,0,18,0,0,0,0,0,0,3,2,2,1,1
1,3,0,0,0,18,0,0,0,0,0,0,0,0,0,0,0,0,0,0,0,0,3,2,2,1,1
1,2,3,3,21,21,0,14,14,3,3,21,0,14,3,3,0,0,0,0,0,3,2,2,2,1,1
1,1,3,3,0,0,0,0,0,3,3,0,0,0,3,3,21,21,0,14,14,3,1,1,1,1,1
1,1,3,3,0,0,0,0,0,3,3,0,0,0,3,3,0,0,0,0,0,3,1,1,1,1,1
1,1,3,3,0,0,0,0,0,3,3,0,0,0,3,3,0,0,0,0,0,3,1,1,1,1,1
1,1,3,3,0,0,0,0,0,3,3,0,0,0,3,3,0,0,0,0,0,3,1,1,1,1,1
1,1,1,3,0,0,0,0,0,3,3,0,0,0,3,3,0,0,18,0,15,3,1,1,1,1,1
1,1,1,1,3,3,0,0,0,3,3,0,0,0,3,3,0,0,0,0,0,3,1,1,1,1,1
1,1,1,1,1,3,5,5,5,3,3,0,0,0,3,3,0,0,0,0,0,3,1,1,1,1,1
1,1,1,1,1,1,3,3,3,1,3,0,0,0,3,3,0,22,0,0,0,3,1,1,1,1,1
1,1,1,1,1,1,1,1,1,1,3,21,28,14,3,1,3,3,3,3,3,1,1,1,1,1,1
1,1,1,1,1,1,1,1,1,1,3,0,0,0,3,1,1,1,1,1,1,1,1,1,1,1,1
1,1,1,1,1,1,1,1,1,1,3,0,29,0,3,1,1,1,1,1,1,1,1,1,1,1,1
1,1,1,1,1,1,1,1,1,1,3,0,0,0,3,1,1,1,1,1,1,1,1,1,1,1,1
1,1,1,1,1,1,1,1,1,1,3,0,0,0,3,1,1,1,1,1,1,1,1,1,1,1,1
1,1,1,1,1,1,1,1,1,1,3,0,0,0,3,1,1,1,1,1,1,1,1,1,1,1,1
1,1,1,1,1,1,1,1,1,1,3,0,0,0,3,1,1,1,1,1,1,1,1,1,1,1,1
1,1,1,1,1,1,1,1,1,1,3,0,0,0,3,1,1,1,1,1,1,1,1,1,1,1,1
1,1,1,1,1,3,3,3,1,1,1,3,0,0,3,1,1,1,1,1,1,1,1,1,1,1,1
1,1,1,1,3,32,0,32,3,1,1,3,0,0,3,1,1,1,1,1,1,1,1,1,1,1,1
1,1,1,1,3,33,34,33,3,1,3,3,0,0,3,1,1,1,1,1,1,1,1,1,1,1,1
1,1,1,1,3,0,0,0,3,1,3,3,0,0,3,1,1,1,3,3,3,3,3,1,1,1,1
1,1,1,1,3,32,35,32,3,1,3,30,0,0,3,1,1,3,10,10,10,10,10,3,1,1,1
1,1,1,1,3,33,0,33,3,1,3,0,0,0,3,1,1,3,0,0,0,0,0,3,3,1,1
1,1,1,3,3,0,0,0,3,1,3,0,0,0,3,1,3,23,0,0,16,0,0,0,5,3,1
1,1,3,0,0,0,0,0,0,3,3,0,0,0,3,1,3,0,0,0,0,0,11,0,5,3,1
1,1,3,0,0,37,0,0,0,3,3,0,0,0,3,1,3,24,0,0,0,0,0,0,6,3,1
1,3,3,0,0,0,36,0,0,3,3,0,0,0,3,3,3,0,0,0,0,0,0,0,6,3,1
3,0,0,0,0,0,0,0,0,0,0,0,0,0,0,0,26,0,0,0,0,0,0,8,0,0,3
26,0,0,39,0,0,0,0,0,31,0,0,0,0,27,0,3,0,0,0,0,0,0,0,0,0,4
3,0,0,0,0,0,0,0,0,0,0,0,0,0,0,0,26,0,0,0,0,0,0,0,0,0,3
1,3,3,3,3,3,3,3,3,3,3,0,0,0,3,3,3,0,0,0,0,0,3,9,7,3,1
1,1,1,1,1,1,1,1,1,1,3,0,0,0,3,1,3,0,19,0,0,12,3,1,1,1,1
1,1,1,1,1,1,1,1,1,1,3,0,0,0,3,1,3,0,0,0,17,13,3,1,1,1,1
1,1,1,1,1,1,1,1,1,1,3,0,0,0,3,1,3,25,0,0,3,3,1,1,1,1,1
1,1,1,1,1,1,1,1,1,1,1,3,20,3,1,1,3,3,20,3,1,1,1,1,1,1,1
:endlayer
layer: 3
1,1,1,1,1,1,1,1,1,1,1,1,1,1,1,1,1,1,1,1,1,1,1,1,1,1,1
1,2,3,3,3,3,3,3,3,3,3,3,3,3,3,3,3,3,3,3,3,3,2,2,2,1,1
1,3,0,38,0,0,0,0,0,0,0,0,0,0,0,0,0,0,0,0,0,0,3,2,2,1,1
1,3,0,0,0,0,0,0,0,0,0,0,0,0,0,0,0,0,0,0,0,0,3,2,2,1,1
1,2,3,3,21,21,0,14,14,3,3,21,0,14,3,3,0,0,0,0,0,3,2,2,2,1,1
1,1,3,3,0,0,0,0,0,3,3,0,0,0,3,3,21,21,0,14,14,3,1,1,1,1,1
1,1,3,3,0,0,0,0,0,3,3,0,0,0,3,3,0,0,0,0,0,3,1,1,1,1,1
1,1,3,3,0,0,0,0,0,3,3,0,0,0,3,3,0,0,0,0,0,3,1,1,1,1,1
1,1,3,3,0,0,0,0,0,3,3,0,0,0,3,3,0,0,0,0,0,3,1,1,1,1,1
1,1,1,3,0,0,0,0,0,3,3,0,0,0,3,3,0,0,0,0,0,3,1,1,1,1,1
1,1,1,1,3,3,0,0,0,3,3,0,0,0,3,3,0,0,0,0,0,3,1,1,1,1,1
1,1,1,1,1,3,50,0,49,3,3,0,0,0,3,3,0,0,0,0,0,3,1,1,1,1,1
1,1,1,1,1,1,3,3,3,1,3,0,0,0,3,3,0,0,0,0,0,3,1,1,1,1,1
1,1,1,1,1,1,1,1,1,1,3,21,40,14,3,1,3,3,3,3,3,1,1,1,1,1,1
1,1,1,1,1,1,1,1,1,1,3,0,0,0,3,1,1,1,1,1,1,1,1,1,1,1,1
1,1,1,1,1,1,1,1,1,1,3,0,0,0,3,1,1,1,1,1,1,1,1,1,1,1,1
1,1,1,1,1,1,1,1,1,1,3,0,0,0,3,1,1,1,1,1,1,1,1,1,1,1,1
1,1,1,1,1,1,1,1,1,1,3,0,0,0,3,1,1,1,1,1,1,1,1,1,1,1,1
1,1,1,1,1,1,1,1,1,1,3,0,0,0,3,1,1,1,1,1,1,1,1,1,1,1,1
1,1,1,1,1,1,1,1,1,1,3,0,0,0,3,1,1,1,1,1,1,1,1,1,1,1,1
1,1,1,1,1,1,1,1,1,1,3,46,0,0,3,1,1,1,1,1,1,1,1,1,1,1,1
1,1,1,1,1,3,3,3,1,1,1,3,48,0,3,1,1,1,1,1,1,1,1,1,1,1,1
1,1,1,1,3,0,51,0,3,1,1,3,0,0,3,1,1,1,1,1,1,1,1,1,1,1,1
1,1,1,1,3,0,0,0,3,1,3,3,0,0,3,1,1,1,1,1,1,1,1,1,1,1,1
1,1,1,1,3,0,0,0,3,1,3,30,0,0,3,1,1,1,3,3,3,3,3,1,1,1,1
1,1,1,1,3,0,0,0,3,1,3,0,0,0,3,1,1,3,10,10,10,10,10,3,1,1,1
1,1,1,1,3,0,0,0,3,1,3,0,0,0,3,1,1,3,0,0,0,0,0,3,3,1,1
1,1,1,3,3,0,0,43,3,1,3,0,0,0,3,1,3,0,0,0,0,0,0,0,41,3,1
1,1,3,0,51,0,0,0,0,3,3,0,0,0,3,1,3,0,0,0,0,0,0,0,42,3,1
1,1,3,0,0,0,0,0,0,3,3,0,0,43,3,1,3,0,0,0,0,0,0,0,0,3,1
1,3,3,0,0,0,0,0,0,3,3,0,0,0,3,3,3,0,0,0,0,0,0,0,43,3,1
3,48,0,0,0,0,0,0,0,0,0,0,0,0,0,0,40,0,0,0,0,0,0,0,0,0,3
40,0,0,0,0,0,0,0,0,0,0,0,0,0,0,0,3,0,0,0,0,0,0,0,0,0,40
3,48,0,0,0,0,0,0,0,0,0,0,0,0,0,0,40,0,0,0,0,0,46,0,0,0,3
1,3,3,3,3,3,3,3,3,3,3,0,0,0,3,3,3,0,0,0,0,43,3,45,44,3,1
1,1,1,1,1,1,1,1,1,1,3,0,0,0,3,1,3,0,0,0,0,0,3,1,1,1,1
1,1,1,1,1,1,1,1,1,1,3,0,0,0,3,1,3,0,0,0,0,0,3,1,1,1,1
1,1,1,1,1,1,1,1,1,1,3,46,0,46,3,1,3,0,0,0,3,3,1,1,1,1,1
1,1,1,1,1,1,1,1,1,1,1,3,40,3,1,1,3,3,47,3,1,1,1,1,1,1,1
:endlayer
layer: 4
1,1,1,1,1,1,1,1,1,1,1,1,1,1,1,1,1,1,1,1,1,1,1,1,1,1,1
1,2,3,3,3,3,3,3,3,3,3,3,3,3,3,3,3,3,3,3,3,3,2,2,2,1,1
1,3,0,38,0,0,0,0,0,0,0,0,0,0,0,0,0,0,0,0,0,0,3,2,2,1,1
1,3,0,0,0,0,0,0,0,0,0,0,0,0,0,0,0,0,0,0,0,0,3,2,2,1,1
1,2,3,3,21,21,0,14,14,3,3,21,52,14,3,3,0,0,0,0,0,3,2,2,2,1,1
1,1,3,3,0,0,0,0,0,3,3,0,0,0,3,3,21,21,3,14,14,3,1,1,1,1,1
1,1,3,3,0,0,0,0,0,3,3,0,0,0,3,3,0,0,0,0,0,3,1,1,1,1,1
1,1,3,3,0,0,0,0,0,3,3,0,0,0,3,3,0,0,0,0,0,3,1,1,1,1,1
1,1,3,3,0,0,0,0,0,3,3,0,0,0,3,3,0,0,0,0,0,3,1,1,1,1,1
1,1,1,3,0,0,0,0,0,3,3,0,0,0,3,3,0,0,0,0,0,3,1,1,1,1,1
1,1,1,1,3,3,0,0,0,3,3,0,0,0,3,3,0,0,0,0,0,3,1,1,1,1,1
1,1,1,1,1,3,0,0,0,3,3,0,0,0,3,3,0,0,0,0,0,3,1,1,1,1,1
1,1,1,1,1,1,3,3,3,1,3,0,0,0,3,3,0,0,0,0,0,3,1,1,1,1,1
1,1,1,1,1,1,1,1,1,1,3,21,52,14,3,1,3,3,3,3,3,1,1,1,1,1,1
1,1,1,1,1,1,1,1,1,1,3,0,0,0,3,1,1,1,1,1,1,1,1,1,1,1,1
1,1,1,1,1,1,1,1,1,1,3,0,0,0,3,1,1,1,1,1,1,1,1,1,1,1,1
1,1,1,1,1,1,1,1,1,1,3,0,0,0,3,1,1,1,1,1,1,1,1,1,1,1,1
1,1,1,1,1,1,1,1,1,1,3,0,0,0,3,1,1,1,1,1,1,1,1,1,1,1,1
1,1,1,1,1,1,1,1,1,1,3,0,0,0,3,1,1,1,1,1,1,1,1,1,1,1,1
1,1,1,1,1,1,1,1,1,1,3,0,0,0,3,1,1,1,1,1,1,1,1,1,1,1,1
1,1,1,1,1,1,1,1,1,1,3,0,0,0,3,1,1,1,1,1,1,1,1,1,1,1,1
1,1,1,1,1,3,3,3,1,1,1,3,0,0,3,1,1,1,1,1,1,1,1,1,1,1,1
1,1,1,1,3,0,0,0,3,1,1,3,0,0,3,1,1,1,1,1,1,1,1,1,1,1,1
1,1,1,1,3,0,0,0,3,1,3,30,0,0,3,1,1,1,1,1,1,1,1,1,1,1,1
1,1,1,1,3,0,0,0,3,1,3,0,0,0,3,1,1,1,3,3,3,3,3,1,1,1,1
1,1,1,1,3,0,0,0,3,1,3,0,0,0,3,1,1,3,10,10,10,10,10,3,1,1,1
1,1,1,1,3,0,0,0,3,1,3,0,0,0,3,1,1,3,48,0,0,0,43,3,3,1,1
1,1,1,3,3,0,0,0,3,1,3,0,0,0,3,1,3,51,0,0,0,0,0,51,0,3,1
1,1,3,0,0,0,0,0,0,3,3,0,0,0,3,1,3,0,0,0,0,0,0,0,0,3,1
1,1,3,0,0,0,0,0,0,3,3,0,0,0,3,1,3,0,0,0,0,0,0,0,0,3,1
1,3,3,0,0,0,0,0,0,3,3,0,0,0,3,3,3,0,0,0,0,0,0,0,0,3,1
3,0,0,0,0,0,0,0,0,0,0,0,0,0,0,0,3,0,0,0,0,0,0,0,0,0,3
3,0,0,0,0,0,0,0,0,0,0,0,0,0,0,0,3,0,0,0,0,0,0,0,0,0,3
3,0,0,0,0,0,0,0,0,0,0,0,0,0,0,0,3,0,0,0,0,0,0,0,0,0,3
1,3,3,3,3,3,3,3,3,3,3,0,0,0,3,3,3,0,0,0,0,0,3,3,3,3,1
1,1,1,1,1,1,1,1,1,1,3,0,0,0,3,1,3,0,0,0,0,0,3,1,1,1,1
1,1,1,1,1,1,1,1,1,1,3,0,0,0,3,1,3,0,0,0,0,0,3,1,1,1,1
1,1,1,1,1,1,1,1,1,1,3,0,0,0,3,1,3,0,0,0,3,3,1,1,1,1,1
1,1,1,1,1,1,1,1,1,1,1,3,53,3,1,1,3,3,3,3,1,1,1,1,1,1,1
:endlayer
layer: 5
1,1,1,1,1,1,1,1,1,1,1,1,1,1,1,1,1,1,1,1,1,1,1,1,1,1,1
1,2,3,3,3,3,3,3,3,3,3,3,3,3,3,3,3,3,3,3,3,3,2,2,2,1,1
1,3,0,3,0,0,0,0,0,0,0,0,0,0,0,0,0,0,0,0,0,0,3,2,2,1,1
1,3,0,0,0,0,0,0,0,0,0,0,0,0,0,0,0,0,0,0,0,0,3,2,2,1,1
1,2,3,3,21,21,0,14,14,3,3,3,3,3,3,3,3,3,3,3,3,3,2,2,2,1,1
1,1,3,3,0,0,0,0,0,3,1,3,3,3,1,1,3,3,3,3,3,1,1,1,1,1,1
1,1,3,3,0,0,0,0,0,3,1,3,3,3,1,1,3,3,3,3,3,1,1,1,1,1,1
1,1,3,3,0,0,0,0,0,3,1,3,3,3,1,1,3,3,3,3,3,1,1,1,1,1,1
1,1,3,3,0,0,0,0,0,3,1,3,3,3,1,1,3,3,3,3,3,1,1,1,1,1,1
1,1,1,3,0,0,0,0,0,3,1,3,3,3,1,1,3,3,3,3,3,1,1,1,1,1,1
1,1,1,1,3,3,0,0,0,3,1,3,3,3,1,1,3,3,3,3,3,1,1,1,1,1,1
1,1,1,1,1,3,5,5,5,3,1,3,3,3,1,1,3,3,3,3,3,1,1,1,1,1,1
1,1,1,1,1,1,3,3,3,1,1,3,3,3,1,1,3,3,3,3,3,1,1,1,1,1,1
1,1,1,1,1,1,1,1,1,1,1,3,3,3,1,1,1,1,1,1,1,1,1,1,1,1,1
1,1,1,1,1,1,1,1,1,1,1,3,3,3,1,1,1,1,1,1,1,1,1,1,1,1,1
1,1,1,1,1,1,1,1,1,1,3,3,3,3,1,1,1,1,1,1,1,1,1,1,1,1,1
1,1,1,1,1,1,1,1,1,1,3,3,3,3,1,1,1,1,1,1,1,1,1,1,1,1,1
1,1,1,1,1,1,1,1,1,1,3,3,3,3,1,1,1,1,1,1,1,1,1,1,1,1,1
1,1,1,1,1,1,1,1,1,1,3,3,3,3,1,1,1,1,1,1,1,1,1,1,1,1,1
1,1,1,1,1,1,1,1,1,1,3,3,3,3,1,1,1,1,1,1,1,1,1,1,1,1,1
1,1,1,1,1,1,1,1,1,1,3,3,3,3,1,1,1,1,1,1,1,1,1,1,1,1,1
1,1,1,1,1,1,1,1,1,1,3,1,3,3,1,1,1,1,1,1,1,1,1,1,1,1,1
1,1,1,1,1,3,3,3,3,3,3,30,3,3,1,1,1,1,1,1,1,1,1,1,1,1,1
1,1,1,1,1,3,3,3,3,3,3,0,3,3,1,1,1,1,1,1,1,1,1,1,1,1,1
1,1,1,1,1,3,3,3,3,3,3,0,3,3,1,1,1,1,1,1,1,1,1,1,1,1,1
1,1,1,1,1,3,3,3,3,3,3,0,3,3,1,1,1,1,3,3,3,3,3,1,1,1,1
1,1,1,1,1,3,3,3,3,3,3,0,3,3,1,1,1,3,0,0,0,0,0,3,1,1,1
1,1,1,1,1,3,3,3,3,3,3,3,3,3,1,1,3,0,0,0,0,0,0,3,3,3,1
1,3,3,3,3,3,3,3,3,3,3,3,3,3,1,1,3,0,0,0,0,0,0,3,3,3,1
1,3,3,3,3,3,3,3,3,3,3,3,3,3,1,1,3,0,0,0,0,0,0,3,3,3,1
1,3,3,3,3,3,3,3,3,3,3,3,3,3,1,1,3,0,0,0,0,0,0,3,3,3,1
1,3,3,3,3,3,3,3,3,3,3,3,3,3,3,3,3,0,0,0,0,0,0,3,3,3,1
1,3,3,3,3,3,3,3,3,3,3,3,3,3,3,3,3,0,0,0,0,0,0,3,3,3,1
1,3,3,3,3,3,3,3,3,3,3,3,3,3,3,3,3,0,0,0,0,0,0,3,3,3,1
1,1,1,1,1,1,1,1,1,1,1,3,3,3,1,1,3,3,3,3,3,3,3,1,1,1,1
1,1,1,1,1,1,1,1,1,1,1,3,3,3,1,1,1,3,3,3,3,3,1,1,1,1,1
1,1,1,1,1,1,1,1,1,1,1,3,3,3,1,1,1,3,3,3,3,3,1,1,1,1,1
1,1,1,1,1,1,1,1,1,1,1,3,3,3,1,1,1,3,3,3,3,3,1,1,1,1,1
1,1,1,1,1,1,1,1,1,1,1,1,3,1,1,1,1,3,3,3,3,3,1,1,1,1,1
:endlayer
layer: 6
1,1,1,1,1,1,1,1,1,1,1,1,1,1,1,1,1,1,1,1,1,1,1,1,1,1,1
1,2,3,3,3,3,3,3,3,3,3,3,3,3,3,3,3,3,3,3,3,3,2,2,2,1,1
1,3,0,3,0,0,0,0,0,0,0,0,0,0,0,0,0,0,0,0,0,0,3,2,2,1,1
1,3,0,3,0,0,0,0,0,0,0,0,0,0,0,0,0,0,0,0,0,0,3,2,2,1,1
1,2,3,3,21,21,3,14,14,3,3,3,3,3,3,3,3,3,3,3,3,3,2,2,2,1,1
1,1,3,3,0,0,0,0,0,3,1,1,1,1,1,1,1,1,1,1,1,1,1,1,1,1,1
1,1,3,3,0,0,0,0,0,3,1,1,1,1,1,1,1,1,1,1,1,1,1,1,1,1,1
1,1,3,3,0,0,0,0,0,3,1,1,1,1,1,1,1,1,1,1,1,1,1,1,1,1,1
1,1,3,3,0,0,0,0,0,3,1,1,1,1,1,1,1,1,1,1,1,1,1,1,1,1,1
1,1,1,3,0,0,0,0,0,3,1,1,1,1,1,1,1,1,1,1,1,1,1,1,1,1,1
1,1,1,1,3,3,0,0,0,3,1,1,1,1,1,1,1,1,1,1,1,1,1,1,1,1,1
1,1,1,1,1,3,0,0,0,3,1,1,1,1,1,1,1,1,1,1,1,1,1,1,1,1,1
1,1,1,1,1,1,3,3,3,1,1,1,1,1,1,1,1,1,1,1,1,1,1,1,1,1,1
1,1,1,1,1,1,1,1,1,1,1,1,1,1,1,1,1,1,1,1,1,1,1,1,1,1,1
1,1,1,1,1,1,1,1,1,1,1,1,1,1,1,1,1,1,1,1,1,1,1,1,1,1,1
1,1,1,1,1,1,1,1,1,1,3,1,54,1,1,1,1,1,1,1,1,1,1,1,1,1,1
1,1,1,1,1,1,1,1,1,1,3,1,54,1,1,1,1,1,1,1,1,1,1,1,1,1,1
1,1,1,1,1,1,1,1,1,1,3,1,54,1,1,1,1,1,1,1,1,1,1,1,1,1,1
1,1,1,1,1,1,1,1,1,1,3,1,54,1,1,1,1,1,1,1,1,1,1,1,1,1,1
1,1,1,1,1,1,1,1,1,1,3,1,54,1,1,1,1,1,1,1,1,1,1,1,1,1,1
1,1,1,1,1,1,1,1,1,1,3,1,54,1,1,1,1,1,1,1,1,1,1,1,1,1,1
1,1,1,1,1,1,1,1,1,1,3,30,54,1,1,1,1,1,1,1,1,1,1,1,1,1,1
1,1,1,1,1,1,1,1,1,1,3,0,54,1,1,1,1,1,1,1,1,1,1,1,1,1,1
1,1,1,1,1,1,1,1,1,1,3,0,54,1,1,1,1,1,1,1,1,1,1,1,1,1,1
1,1,1,1,1,1,1,1,1,1,3,0,54,1,1,1,1,1,1,1,1,1,1,1,1,1,1
1,1,1,1,1,1,1,1,1,1,3,0,54,1,1,1,1,1,3,3,3,3,3,1,1,1,1
1,1,1,1,1,1,1,1,1,1,3,0,54,1,1,1,1,3,0,0,0,0,0,3,1,1,1
1,1,1,1,1,1,1,1,1,1,1,3,1,1,1,1,3,0,0,0,0,0,0,3,1,1,1
1,1,1,1,1,1,1,1,1,1,1,1,1,1,1,1,3,0,0,0,0,0,0,3,1,1,1
1,1,1,1,1,1,1,1,1,1,1,1,1,1,1,1,3,0,0,0,0,0,0,3,1,1,1
1,1,1,1,1,1,1,1,1,1,1,1,1,1,1,1,3,0,0,0,0,0,43,3,1,1,1
1,1,1,1,1,1,1,1,1,1,1,1,1,1,1,1,3,0,0,0,0,0,0,3,1,1,1
1,1,1,1,1,1,1,1,1,1,1,1,1,1,1,1,3,0,0,0,0,0,0,3,1,1,1
1,1,1,1,1,1,1,1,1,1,1,1,1,1,1,1,3,0,0,0,0,0,0,3,1,1,1
1,1,1,1,1,1,1,1,1,1,1,1,1,1,1,1,3,0,0,0,0,3,3,1,1,1,1
1,1,1,1,1,1,1,1,1,1,1,1,1,1,1,1,1,3,3,3,3,1,1,1,1,1,1
1,1,1,1,1,1,1,1,1,1,1,1,1,1,1,1,1,1,1,1,1,1,1,1,1,1,1
1,1,1,1,1,1,1,1,1,1,1,1,1,1,1,1,1,1,1,1,1,1,1,1,1,1,1
1,1,1,1,1,1,1,1,1,1,1,1,1,1,1,1,1,1,1,1,1,1,1,1,1,1,1
:endlayer
layer: 7
1,1,1,1,1,1,1,1,1,1,1,1,1,1,1,1,1,1,1,1,1,1,1,1,1,1,1
1,2,55,55,55,55,55,55,55,55,55,55,55,55,55,55,55,55,55,55,55,55,2,2,2,1,1
1,2,55,55,55,55,55,55,55,55,55,55,55,55,55,55,55,55,55,55,55,55,2,2,2,1,1
1,2,55,55,55,55,55,55,55,55,55,55,55,55,55,55,55,55,55,55,55,55,2,2,2,1,1
1,2,3,3,55,55,55,55,55,3,3,3,3,3,3,3,3,3,3,3,3,3,2,2,2,1,1
1,1,1,1,55,55,55,55,55,3,1,1,1,1,1,1,1,1,1,1,1,1,1,1,1,1,1
1,1,1,1,55,55,55,55,55,3,1,1,1,1,1,1,1,1,1,1,1,1,1,1,1,1,1
1,1,1,1,55,55,55,55,55,3,1,1,1,1,1,1,1,1,1,1,1,1,1,1,1,1,1
1,1,1,1,55,55,55,55,55,3,1,1,1,1,1,1,1,1,1,1,1,1,1,1,1,1,1
1,1,1,1,55,55,55,55,55,3,1,1,1,1,1,1,1,1,1,1,1,1,1,1,1,1,1
1,1,1,1,1,1,55,55,55,1,1,1,1,1,1,1,1,1,1,1,1,1,1,1,1,1,1
1,1,1,1,1,1,55,55,55,1,1,1,1,1,1,1,1,1,1,1,1,1,1,1,1,1,1
1,1,1,1,1,1,1,1,1,1,1,1,1,1,1,1,1,1,1,1,1,1,1,1,1,1,1
1,1,1,1,1,1,1,1,1,1,1,1,1,1,1,1,1,1,1,1,1,1,1,1,1,1,1
1,1,1,1,1,1,1,1,1,1,1,1,1,1,1,1,1,1,1,1,1,1,1,1,1,1,1
1,1,1,1,1,1,1,1,1,1,3,1,54,1,1,1,1,1,1,1,1,1,1,1,1,1,1
1,1,1,1,1,1,1,1,1,1,3,1,54,1,1,1,1,1,1,1,1,1,1,1,1,1,1
1,1,1,1,1,1,1,1,1,1,3,1,54,1,1,1,1,1,1,1,1,1,1,1,1,1,1
1,1,1,1,1,1,1,1,1,1,3,1,54,1,1,1,1,1,1,1,1,1,1,1,1,1,1
1,1,1,1,1,1,1,1,1,1,3,1,54,1,1,1,1,1,1,1,1,1,1,1,1,1,1
1,1,1,1,1,1,1,1,1,1,3,30,54,1,1,1,1,1,1,1,1,1,1,1,1,1,1
1,1,1,1,1,1,1,1,1,1,3,0,54,1,1,1,1,1,1,1,1,1,1,1,1,1,1
1,1,1,1,1,1,1,1,1,1,3,0,54,1,1,1,1,1,1,1,1,1,1,1,1,1,1
1,1,1,1,1,1,1,1,1,1,3,0,54,1,1,1,1,1,1,1,1,1,1,1,1,1,1
1,1,1,1,1,1,1,1,1,1,3,0,54,1,1,1,1,1,1,1,1,1,1,1,1,1,1
1,1,1,1,1,1,1,1,1,1,3,5,54,1,1,1,1,1,3,3,3,3,3,1,1,1,1
1,1,1,1,1,1,1,1,1,1,3,52,54,1,1,1,1,55,55,55,55,55,55,3,1,1,1
1,1,1,1,1,1,1,1,1,1,1,1,1,1,1,1,3,55,55,55,55,55,55,3,1,1,1
1,1,1,1,1,1,1,1,1,1,1,1,1,1,1,1,3,55,55,55,55,55,55,3,1,1,1
1,1,1,1,1,1,1,1,1,1,1,1,1,1,1,1,3,55,55,55,55,55,55,3,1,1,1
1,1,1,1,1,1,1,1,1,1,1,1,1,1,1,1,3,55,55,55,55,55,55,3,1,1,1
1,1,1,1,1,1,1,1,1,1,1,1,1,1,1,1,3,55,55,55,55,55,55,3,1,1,1
1,1,1,1,1,1,1,1,1,1,1,1,1,1,1,1,3,55,55,55,55,55,55,3,1,1,1
1,1,1,1,1,1,1,1,1,1,1,1,1,1,1,1,3,55,55,55,55,55,55,3,1,1,1
1,1,1,1,1,1,1,1,1,1,1,1,1,1,1,1,3,55,55,55,55,55,55,1,1,1,1
1,1,1,1,1,1,1,1,1,1,1,1,1,1,1,1,1,55,55,55,55,55,55,1,1,1,1
1,1,1,1,1,1,1,1,1,1,1,1,1,1,1,1,1,1,1,1,1,1,1,1,1,1,1
1,1,1,1,1,1,1,1,1,1,1,1,1,1,1,1,1,1,1,1,1,1,1,1,1,1,1
1,1,1,1,1,1,1,1,1,1,1,1,1,1,1,1,1,1,1,1,1,1,1,1,1,1,1
:endlayer
layer: 8
56,56,56,56,56,56,56,1,1,1,1,1,1,1,1,1,1,1,1,1,1,1,56,56,56,56,56
56,56,56,56,56,56,56,2,2,2,2,2,2,2,2,2,2,2,2,2,2,2,56,56,56,56,56
56,56,56,56,56,56,56,2,2,2,2,2,2,2,2,2,2,2,2,2,2,2,56,56,56,56,56
56,56,56,56,56,56,56,2,2,2,2,2,2,2,2,2,2,2,2,2,2,2,56,1,56,56,56
56,56,56,56,1,56,56,2,2,2,2,2,2,2,2,2,2,2,2,2,2,2,56,56,56,56,56
56,56,56,56,56,56,56,1,1,1,1,1,1,1,1,1,1,1,1,1,1,1,56,56,56,56,56
56,56,56,56,56,56,1,1,1,1,1,1,1,1,1,1,1,1,1,1,1,1,56,1,56,56,56
56,56,56,56,56,56,1,1,1,1,1,1,1,1,1,1,1,1,1,1,1,1,56,56,56,56,56
56,56,56,56,56,1,1,1,1,1,1,1,1,1,1,1,1,1,1,1,1,1,56,56,56,56,56
56,56,56,1,56,1,1,1,1,1,1,1,1,1,1,1,1,1,1,1,1,1,1,56,56,56,56
56,56,56,56,56,1,1,1,1,1,1,1,1,1,1,1,1,1,1,1,1,1,1,56,56,56,56
56,56,56,56,56,1,1,1,1,1,1,1,1,1,1,1,1,1,1,1,1,1,1,56,56,56,56
56,56,56,56,56,1,1,1,1,1,1,1,1,1,1,1,1,1,1,1,1,1,56,56,56,56,56
56,56,56,56,1,1,1,1,1,1,1,1,1,1,1,1,1,1,1,1,1,56,56,56,56,56,56
56,56,56,1,1,1,1,1,1,1,1,1,1,1,1,1,1,1,1,1,1,56,56,56,56,56,56
56,56,56,1,1,1,1,1,1,1,3,1,54,1,1,1,1,1,1,1,1,56,56,56,56,56,56
56,56,56,1,1,1,1,1,1,1,3,1,54,1,1,1,1,1,1,1,1,56,56,56,56,56,56
56,56,56,1,1,1,1,1,1,1,3,1,54,1,1,1,1,1,1,1,1,56,56,56,56,56,56
56,56,56,1,1,1,1,1,1,1,3,1,54,1,1,1,1,1,1,1,1,1,56,1,56,56,56
56,56,1,1,1,1,1,1,1,1,3,30,54,1,1,1,1,1,1,1,1,1,56,56,56,56,56
56,56,1,1,1,1,1,1,1,1,3,48,54,1,1,1,1,1,1,1,1,1,56,56,56,56,56
56,56,1,1,1,1,1,1,1,1,3,0,54,1,1,1,1,1,1,1,1,1,56,56,56,56,56
56,56,1,1,1,1,1,1,1,1,3,0,54,1,1,1,1,1,1,1,1,1,1,56,56,56,56
56,56,1,1,1,1,1,1,1,1,3,0,54,1,1,1,1,1,1,1,1,1,1,56,56,56,56
56,1,1,1,1,1,1,1,1,1,3,5,54,1,1,1,1,1,1,1,1,1,56,56,56,56,56
56,1,1,1,1,1,1,1,1,1,3,57,54,1,1,1,1,1,1,1,1,1,56,56,56,56,56
56,1,1,1,1,1,1,1,1,1,3,1,54,1,1,1,1,1,1,1,1,1,0,56,56,56,56
56,1,1,1,1,1,1,1,1,1,1,1,1,1,1,1,1,1,1,1,1,1,56,56,56,56,56
56,1,1,1,1,1,1,1,1,1,1,1,1,1,1,1,1,1,1,1,1,56,56,56,56,56,56
56,1,1,1,1,1,1,1,1,1,1,1,1,1,1,1,1,1,1,1,1,56,56,1,56,56,56
56,1,1,1,1,1,1,1,1,1,1,1,1,1,1,1,1,1,1,1,1,56,56,56,56,56,56
56,1,1,1,1,1,1,1,1,1,1,1,1,1,1,1,1,1,1,56,56,56,56,56,56,56,56
56,1,1,1,1,1,1,1,1,1,1,1,1,1,1,1,1,1,1,56,56,56,56,1,56,56,56
56,1,1,1,1,1,1,1,1,1,1,1,1,1,1,1,1,1,1,56,56,56,56,56,56,56,56
56,1,1,1,1,1,1,1,1,1,1,1,1,1,1,1,1,1,1,56,56,56,56,56,56,56,56
56,1,1,1,1,1,1,1,1,1,1,1,1,1,1,1,1,1,1,56,56,56,56,56,56,56,56
56,56,1,1,1,1,1,1,1,1,1,1,1,1,1,1,1,1,56,56,56,56,56,56,56,56,56
56,56,1,1,1,1,1,1,1,1,1,1,1,1,1,1,1,56,56,56,56,56,56,56,56,56,56
2,56,56,1,1,1,1,1,1,1,1,1,56,56,56,56,56,56,56,56,56,56,56,56,56,56,56
:endlayer
layer: 9
0,0,0,58,58,58,0,56,56,56,56,56,56,56,56,56,56,56,56,56,56,56,0,0,0,0,0
0,58,58,58,58,58,58,56,2,2,2,2,2,2,2,2,2,2,2,2,1,56,0,0,0,0,0
0,0,58,58,58,58,0,56,2,2,2,2,2,2,2,2,2,2,2,2,2,56,0,0,0,0,0
0,0,58,58,0,0,0,56,2,2,2,2,2,2,2,2,2,2,2,2,2,56,0,59,0,0,0
0,58,58,0,59,0,0,56,1,2,2,2,2,2,2,2,2,2,2,2,0,56,0,0,0,0,0
0,0,0,0,0,0,0,1,1,1,1,1,1,1,1,1,1,1,1,2,1,56,0,0,0,0,0
0,0,0,0,0,63,56,1,1,1,1,1,1,1,1,1,1,1,2,2,1,56,0,59,0,0,0
0,0,0,0,0,0,1,1,1,1,1,1,1,1,1,1,1,1,2,2,1,56,0,0,0,0,0
0,0,58,58,0,56,1,1,1,1,1,1,1,1,1,1,1,1,2,2,3,54,0,0,0,0,0
0,58,58,59,64,56,1,1,1,1,1,1,1,1,1,1,1,2,3,3,3,3,54,0,0,0,58
58,58,58,58,0,56,1,1,1,1,1,1,1,1,1,1,1,2,3,3,3,3,3,0,0,58,58
58,58,58,58,0,56,1,1,1,1,1,1,1,1,1,1,1,2,3,3,3,3,54,0,58,58,58
0,0,0,58,0,2,2,2,2,1,1,1,1,1,1,1,1,2,2,2,3,54,58,58,58,58,58
0,0,0,0,2,2,2,2,2,1,1,1,1,1,1,1,1,2,3,3,2,0,0,58,58,58,58
0,58,58,56,2,2,2,2,2,1,1,1,1,1,1,1,1,2,2,2,2,0,0,60,58,58,0
0,58,58,56,2,2,2,2,2,1,3,1,54,1,1,1,1,2,2,2,2,0,61,0,0,0,58
58,58,58,56,2,2,2,2,2,1,3,1,54,1,1,1,1,2,2,2,2,0,0,0,0,0,0
0,58,0,56,1,1,2,2,2,1,3,1,54,1,1,1,2,2,2,2,2,0,0,0,0,0,0
58,58,0,56,1,1,2,2,2,1,3,30,54,1,1,1,2,2,2,2,2,1,0,59,0,0,0
0,58,56,1,1,1,2,2,2,1,3,0,54,1,1,1,2,2,2,2,2,1,0,0,0,0,0
0,0,56,1,1,1,2,2,2,1,3,0,54,1,1,2,2,2,2,2,2,1,0,58,0,0,0
0,0,56,1,1,1,1,1,1,1,3,0,54,1,1,2,2,2,2,2,2,2,0,0,0,58,0
0,0,56,1,1,1,1,1,1,1,3,0,54,1,1,2,2,2,2,2,2,2,2,58,58,0,0
0,0,1,1,1,1,1,1,1,1,3,5,54,1,1,2,2,2,2,2,2,2,2,58,58,58,58
0,56,1,1,1,1,1,1,1,1,3,57,54,1,1,2,2,2,2,2,2,2,0,58,0,58,58
0,56,1,1,1,1,1,1,1,1,3,1,54,1,1,1,2,2,2,2,2,2,0,58,58,58,0
0,56,1,1,1,1,1,1,1,1,3,1,54,1,1,1,2,2,2,2,2,56,0,0,0,0,58
0,56,1,1,1,1,1,1,1,1,1,1,1,1,1,1,2,2,2,2,2,56,0,0,58,0,0
0,56,1,1,1,1,1,1,1,1,1,1,1,1,1,1,2,2,2,62,62,0,0,0,0,0,0
0,56,1,1,1,1,1,1,1,1,1,1,1,1,1,1,2,2,2,62,62,0,0,59,0,0,0
0,56,1,2,2,2,1,1,1,1,1,1,1,1,1,1,2,2,2,62,62,0,0,0,0,0,0
0,56,1,2,2,2,1,1,1,1,1,1,1,1,1,1,2,2,2,0,0,0,0,0,0,0,0
0,56,1,2,2,2,1,1,1,1,1,1,1,1,1,1,2,2,2,0,0,0,0,59,58,0,0
0,56,1,1,1,1,1,1,2,2,2,1,1,1,1,1,2,2,2,0,0,0,0,58,58,0,0
0,56,1,1,1,1,1,2,2,2,2,2,1,1,1,1,1,1,1,0,0,58,0,58,0,58,58
0,56,1,1,1,1,2,2,2,2,2,2,2,1,1,1,1,1,1,0,0,0,0,58,58,58,0
0,0,56,1,1,1,2,2,2,2,2,2,2,1,1,1,56,56,0,0,0,0,58,58,58,58,0
0,0,56,56,56,56,2,2,2,2,2,2,2,56,56,56,56,0,0,0,0,0,0,58,58,0,0
0,0,0,56,56,56,56,2,2,2,2,2,58,58,0,58,58,58,0,0,0,0,0,0,58,0,0
:endlayer
layer: 10
0,0,0,0,0,0,0,0,0,58,0,0,0,0,0,0,0,0,58,58,0,0,0,0,0,0,0
0,0,0,0,0,0,0,58,56,56,56,56,56,56,56,56,56,56,56,56,56,0,65,65,65,65,0
0,0,0,0,0,0,0,0,56,2,2,2,2,2,2,2,2,2,2,2,56,65,65,65,65,65,0
0,0,0,0,0,0,0,0,56,2,2,2,2,2,2,2,2,2,2,2,56,65,65,59,65,65,0
0,0,0,0,59,0,0,0,56,2,2,2,2,2,2,2,2,2,2,2,56,65,65,65,65,65,0
0,0,0,0,0,0,0,1,1,1,1,1,1,1,1,1,1,1,1,1,56,65,65,65,65,65,0
0,0,0,0,0,0,0,1,1,1,1,1,1,1,1,1,1,1,2,1,56,0,0,59,0,0,0
0,65,65,65,65,0,56,1,1,1,1,1,1,1,1,1,1,1,2,1,54,0,0,0,0,0,0
0,65,65,65,65,65,56,1,1,1,1,1,1,1,1,1,1,1,2,1,3,54,0,0,0,0,0
0,65,65,59,65,65,56,1,1,1,1,1,1,1,1,1,1,2,3,3,3,3,54,0,0,0,0
0,65,65,65,65,65,56,1,1,1,1,1,1,1,1,1,1,2,3,3,3,3,3,0,0,0,0
0,0,65,65,65,65,2,2,1,1,1,1,1,1,1,1,1,2,3,3,3,3,54,0,0,0,0
0,0,0,0,0,0,2,2,2,1,1,1,1,1,1,1,1,2,2,2,3,54,0,0,0,0,0
0,0,0,0,0,2,2,2,2,2,1,1,1,1,1,1,1,2,3,3,54,0,0,0,0,0,0
0,0,0,0,0,2,2,2,2,2,1,1,1,1,1,1,1,2,2,2,0,0,0,0,0,0,0
0,0,0,0,2,2,2,2,2,2,3,1,54,1,1,1,1,2,2,2,0,0,0,0,0,0,0
0,0,0,58,2,2,2,2,2,2,3,1,54,1,1,1,1,2,2,2,2,65,65,65,65,0,0
0,0,0,0,1,2,2,2,2,2,3,30,54,1,1,1,2,2,2,2,56,65,65,65,65,65,0
0,0,0,0,1,2,2,2,2,2,3,0,54,1,1,2,2,2,2,1,1,56,65,59,65,65,0
0,0,0,1,1,2,2,2,2,2,3,0,54,1,1,2,2,2,2,1,1,56,65,65,65,65,0
0,0,0,1,1,2,2,2,2,2,3,0,54,1,1,2,2,2,2,2,1,56,65,65,65,65,0
0,0,0,1,1,2,2,2,2,2,3,0,54,1,1,2,2,2,2,2,1,56,0,0,0,0,0
0,0,0,1,1,1,1,1,1,1,3,57,54,1,1,2,2,2,2,2,1,56,0,0,0,0,0
0,0,56,1,1,1,1,1,1,1,3,1,54,1,1,2,2,2,2,2,1,56,0,0,0,0,0
0,0,56,1,1,1,1,1,1,1,3,1,54,1,1,2,2,2,2,2,1,56,0,0,0,0,0
0,0,56,1,1,1,1,1,1,1,3,1,54,1,1,1,2,2,2,62,62,0,0,0,0,0,0
0,0,56,1,1,1,1,1,2,2,3,1,54,1,1,2,2,2,2,62,62,0,0,0,0,0,0
0,0,56,1,1,1,1,1,2,2,2,2,1,1,1,2,2,2,2,62,62,0,65,65,65,65,0
0,0,56,1,1,1,1,1,2,2,2,2,1,1,1,2,2,2,2,0,0,65,65,65,65,65,0
0,0,2,2,2,2,2,1,1,2,2,2,1,1,1,1,2,2,2,0,0,65,65,59,65,65,0
0,0,2,2,2,2,2,1,1,1,1,1,1,1,1,2,2,2,2,0,0,65,65,65,65,65,0
0,0,2,2,2,2,2,1,1,1,1,1,1,1,1,2,2,2,2,0,0,0,65,65,65,0,0
0,0,2,2,2,2,2,1,1,1,1,1,1,1,1,2,2,2,2,0,0,0,0,59,0,0,0
0,0,2,2,2,2,2,2,2,2,2,1,1,1,1,1,2,2,2,0,0,0,0,0,0,0,0
0,0,56,1,1,1,2,2,2,2,2,2,1,1,1,1,1,2,2,0,0,0,0,0,0,0,0
0,0,56,56,1,1,2,2,2,2,2,2,2,1,1,1,1,1,56,0,0,0,0,0,0,0,0
0,0,0,56,56,56,2,2,2,2,2,2,2,1,1,1,0,0,0,0,0,0,0,0,0,0,0
0,0,58,58,58,58,0,0,0,0,0,0,0,58,58,58,0,0,0,0,0,0,0,0,0,0,0
0,0,0,64,58,58,0,0,0,0,0,0,0,0,0,0,0,0,0,0,0,0,0,0,0,0,0
:endlayer
layer: 11
0,0,0,0,0,0,0,0,0,0,0,0,0,0,0,0,0,0,0,0,0,0,0,0,0,0,0
0,0,0,0,0,0,0,0,0,58,0,0,0,0,58,58,58,58,0,58,58,0,65,0,65,0,0
0,0,0,65,65,65,0,0,58,56,56,56,56,1,56,56,56,56,56,1,0,65,65,65,65,65,0
0,0,65,65,65,65,65,0,0,56,2,2,2,2,2,2,2,2,2,56,0,65,65,59,65,65,0
0,0,65,65,59,65,65,0,0,56,2,2,2,2,2,2,2,1,2,56,0,65,65,65,65,65,0
0,0,65,65,65,65,65,56,1,1,1,1,1,1,1,1,1,1,1,1,0,0,65,65,65,65,0
0,0,0,65,65,65,0,56,1,1,1,1,1,1,1,1,1,1,1,56,0,0,0,59,0,0,0
0,65,65,65,65,65,58,56,1,1,1,1,1,1,1,1,1,1,1,1,54,0,0,0,0,0,0
0,65,65,65,65,65,58,56,1,1,1,1,1,1,1,1,1,1,1,1,3,3,0,0,0,0,0
0,65,65,59,65,65,58,56,1,1,1,1,1,1,1,1,1,2,3,3,3,3,54,0,0,0,0
0,65,65,65,65,65,58,56,1,1,1,1,1,1,1,1,1,2,3,3,3,3,14,0,0,0,0
0,65,65,65,65,0,0,2,1,1,1,1,1,1,1,1,1,2,3,3,3,3,54,0,0,0,0
0,0,0,0,0,0,0,2,2,1,1,1,1,1,1,1,1,2,1,1,3,14,0,0,0,0,0
0,0,0,0,0,0,2,2,2,2,1,1,1,1,1,1,1,2,3,3,54,0,0,0,0,0,0
0,0,0,0,0,0,2,2,2,2,1,1,1,1,1,1,1,2,1,56,0,0,0,0,0,0,0
0,0,0,0,0,2,2,2,2,2,3,1,54,1,1,1,1,2,1,56,0,0,0,0,0,0,0
0,0,0,0,2,2,2,2,2,2,3,30,54,1,1,1,2,2,1,1,0,0,65,65,65,0,0
0,0,0,0,56,2,2,2,2,2,3,0,54,1,2,2,2,2,2,1,58,65,65,65,65,65,0
0,0,0,0,2,2,2,2,2,2,3,0,54,1,2,2,2,2,2,56,56,58,65,59,65,65,0
0,0,0,56,2,2,2,2,2,2,3,0,54,1,2,2,2,2,2,62,56,58,65,65,65,65,0
0,0,0,56,2,2,2,2,2,2,3,5,54,1,2,2,2,2,2,62,62,0,65,65,65,0,0
0,0,0,56,1,2,2,2,2,2,3,57,54,2,2,2,2,2,2,62,62,58,0,0,0,0,0
0,0,0,56,1,1,2,2,2,1,3,2,54,2,2,2,2,2,2,62,62,58,0,0,0,0,0
0,0,0,56,1,1,1,1,1,1,3,2,54,2,2,2,2,2,2,62,62,58,0,0,0,0,0
0,0,58,56,1,1,1,1,1,1,3,2,54,2,1,1,2,2,2,62,62,58,0,0,0,0,0
0,0,58,56,1,1,1,2,2,2,3,2,54,1,1,1,2,2,2,0,0,0,0,0,0,0,0
0,0,0,56,1,1,1,2,2,2,3,2,54,1,1,2,2,2,2,0,0,0,0,0,0,0,0
0,0,0,56,1,1,1,2,2,2,2,2,2,1,1,2,2,2,2,0,0,65,65,65,65,0,0
0,0,0,2,2,2,1,2,2,2,2,2,2,1,1,2,2,2,2,0,0,65,65,65,65,65,0
0,0,0,2,2,2,2,2,2,2,2,2,2,2,2,1,2,2,2,0,0,65,65,59,65,65,0
0,0,0,56,2,2,2,2,2,2,2,2,2,2,2,2,2,2,2,0,0,65,65,65,65,65,0
0,0,0,56,2,2,2,2,1,1,2,2,2,2,2,2,2,2,2,0,0,65,65,65,65,65,0
0,0,0,56,2,2,2,2,2,2,2,2,2,1,1,2,2,2,2,0,0,0,0,59,0,0,0
0,0,0,2,2,2,2,2,2,2,2,1,1,1,1,1,2,2,2,0,0,0,0,0,0,0,0
0,0,58,2,2,2,2,2,2,2,2,2,1,1,1,1,1,2,0,0,0,0,0,0,0,0,0
0,0,0,0,1,2,2,2,2,2,2,2,1,1,1,56,56,56,0,0,0,0,0,0,0,0,0
0,0,0,0,58,0,0,0,0,0,0,2,2,56,56,56,0,0,0,0,0,0,0,0,0,0,0
0,0,0,0,0,0,0,0,0,0,0,0,0,0,0,0,0,0,0,0,0,0,0,0,0,0,0
0,0,0,0,0,0,0,0,0,0,0,0,0,0,0,0,0,0,0,0,0,0,0,0,0,0,0
:endlayer
layer: 12
0,0,0,0,0,0,0,0,0,0,0,0,0,0,0,0,0,0,0,0,0,0,0,0,0,0,0
0,0,0,0,0,0,0,0,0,0,0,0,0,0,0,0,0,0,0,0,0,0,0,0,0,0,0
0,0,65,65,65,65,0,0,0,0,58,0,0,59,0,67,58,58,0,59,0,0,65,65,0,0,0
0,0,65,65,65,65,65,0,0,0,56,56,56,56,56,56,56,56,56,0,65,0,65,59,65,65,0
0,0,65,65,59,65,65,0,0,0,56,0,0,0,0,0,0,1,56,65,65,65,0,65,65,65,65
0,0,65,65,65,65,65,0,1,56,56,1,1,1,1,1,1,1,56,56,65,0,0,0,0,65,0
0,0,65,65,65,65,0,0,3,56,56,1,1,1,1,1,1,1,56,0,0,0,0,59,0,0,0
0,0,0,0,0,0,0,0,56,1,1,1,1,1,1,1,1,1,1,54,54,0,0,0,0,0,0
0,0,0,65,0,0,0,58,55,1,1,1,1,1,1,1,1,1,1,1,3,3,0,0,0,0,0
0,0,65,59,65,0,0,58,55,1,3,54,1,1,1,1,1,1,3,3,3,3,3,0,0,0,0
0,0,65,65,0,0,0,58,54,1,3,3,3,3,3,1,1,1,3,3,3,3,3,0,0,0,0
0,0,0,0,0,0,0,0,55,55,3,3,54,3,3,1,1,1,3,3,3,3,54,0,0,0,0
0,0,0,0,0,0,0,0,54,1,3,54,3,3,3,1,1,1,1,3,3,3,0,0,0,0,0
0,0,0,0,0,0,0,0,54,2,3,3,54,3,3,3,3,1,3,54,54,0,0,0,0,0,0
0,0,0,0,0,0,0,0,54,2,3,3,3,3,3,3,3,1,56,0,0,0,0,0,0,0,0
0,0,0,0,0,0,2,2,2,2,3,30,54,1,3,3,3,1,56,0,0,0,0,0,0,0,0
0,0,0,0,0,2,2,2,2,2,3,0,54,1,55,55,55,55,56,56,0,0,0,0,0,0,0
0,0,0,0,0,2,2,2,2,2,3,0,54,1,2,55,55,55,55,56,0,0,0,65,0,0,0
0,0,0,0,2,56,2,2,2,2,3,0,54,2,2,2,55,55,62,64,58,0,65,59,65,0,0
0,0,0,0,56,2,2,2,2,2,3,5,54,2,2,2,2,2,62,0,66,0,65,65,0,0,0
0,0,0,0,56,2,2,2,2,2,3,57,54,2,2,2,2,2,62,0,0,0,0,0,0,0,0
0,0,0,0,56,1,2,2,2,2,3,2,54,2,2,2,2,2,2,0,0,0,0,0,0,0,0
0,0,0,58,56,1,2,2,2,1,3,2,54,2,2,2,2,2,1,0,0,0,0,0,0,0,0
0,0,0,58,56,56,1,1,1,1,3,2,54,2,2,2,2,1,1,0,0,0,0,0,0,0,0
0,0,0,64,56,56,1,1,2,2,3,2,54,2,2,2,2,2,2,0,0,0,0,0,0,0,0
0,0,0,58,56,1,1,2,2,2,3,2,54,2,2,1,2,2,2,0,0,0,0,0,0,0,0
0,0,0,58,56,1,2,2,2,2,3,2,54,1,1,2,2,2,2,0,0,0,0,0,0,0,0
0,0,0,58,56,1,2,2,2,2,2,2,2,2,1,2,2,2,2,0,0,0,0,0,0,0,0
0,0,0,0,2,2,2,2,2,2,2,2,2,2,2,2,2,2,2,0,0,0,0,65,0,0,0
0,0,0,0,56,2,2,2,2,2,2,2,2,2,2,2,2,2,3,0,0,0,65,59,65,0,0
0,0,0,0,56,2,2,2,2,2,2,2,2,2,2,2,2,2,2,0,0,65,65,65,65,65,0
0,0,0,0,2,2,2,2,1,2,2,2,2,2,2,2,2,2,0,0,0,65,65,65,65,65,0
0,0,0,0,2,2,2,2,2,2,2,2,2,2,2,2,2,2,0,0,0,65,65,59,65,65,0
0,0,0,0,0,2,2,2,2,2,2,2,2,2,2,1,2,2,0,0,0,65,65,65,65,65,0
0,0,0,0,0,0,2,2,2,2,2,2,1,1,1,1,56,0,0,0,0,0,65,65,65,0,0
0,0,0,0,59,0,0,0,2,2,2,2,56,56,1,58,58,0,0,0,0,0,0,0,0,0,0
0,0,0,0,0,0,0,0,0,0,0,68,0,0,58,58,0,0,0,0,0,0,0,0,0,0,0
0,0,0,0,0,0,0,0,0,0,0,0,0,0,0,0,0,0,0,0,0,0,0,0,0,0,0
0,0,0,0,0,0,0,0,0,0,0,0,0,0,0,0,0,0,0,0,0,0,0,0,0,0,0
:endlayer
layer: 13
0,0,0,0,0,0,0,0,0,0,0,0,0,0,0,0,0,0,0,0,0,0,0,0,0,0,0
0,0,0,0,0,0,0,0,0,0,0,0,0,0,0,0,0,0,0,0,0,0,0,0,0,0,0
0,0,0,0,0,0,0,0,0,0,0,0,0,59,0,0,0,0,0,59,65,65,0,65,65,65,65
0,0,0,0,65,65,0,0,0,0,0,0,0,0,0,0,0,0,65,65,65,65,65,65,65,65,65
0,0,0,65,59,65,0,0,0,0,0,56,56,56,56,56,56,56,65,65,65,65,65,65,65,65,65
0,0,0,65,65,0,0,0,59,58,58,56,56,1,1,1,1,56,65,65,65,65,65,65,65,65,65
0,0,0,0,0,0,0,0,3,58,58,56,56,1,1,1,1,56,0,65,65,65,70,59,65,65,65
0,0,0,0,0,0,0,0,64,55,3,1,1,1,1,1,1,1,54,54,3,53,65,69,65,0,0
0,0,0,65,0,0,0,0,0,54,54,54,1,1,1,1,1,1,3,3,3,3,53,69,69,65,0
0,0,65,65,65,0,0,0,0,54,0,0,54,54,54,1,1,1,3,3,3,3,3,0,65,0,0
0,0,0,65,0,0,0,0,0,54,0,0,0,0,0,54,1,1,3,3,3,3,3,0,0,0,0
0,0,0,0,0,0,0,0,0,0,0,0,0,0,0,54,1,1,3,3,3,3,54,0,0,0,0
0,0,0,0,0,0,0,0,0,54,0,0,0,0,0,54,54,1,3,3,3,3,0,0,0,0,0
0,0,0,0,0,0,0,0,0,54,0,0,0,0,0,0,0,3,54,30,54,0,0,0,0,0,0
0,0,0,0,0,0,0,0,0,55,0,0,0,55,0,0,0,3,0,0,0,0,0,0,0,0,0
0,0,0,0,0,0,0,0,56,55,54,0,54,55,54,0,54,3,0,0,0,0,0,0,0,0,0
0,0,0,0,0,0,2,2,56,2,3,0,54,1,0,0,0,0,58,0,0,0,0,0,0,0,0
0,0,0,0,0,0,2,56,2,2,2,0,54,1,55,0,0,0,0,0,0,0,0,65,0,0,0
0,0,0,0,72,0,56,2,2,2,2,3,54,1,2,55,0,0,0,0,0,0,65,65,65,0,0
0,0,0,0,0,1,56,2,2,2,2,1,54,2,2,2,56,62,0,0,0,0,0,65,0,0,0
0,0,0,0,0,56,56,2,2,2,2,1,54,2,2,2,56,2,0,0,0,0,0,0,0,0,0
0,0,0,0,58,56,1,2,2,2,2,2,54,2,2,1,2,2,2,0,0,0,0,0,0,0,0
0,0,0,0,66,56,56,2,2,2,2,2,54,2,2,2,2,2,56,0,0,0,0,0,0,0,0
0,0,0,0,58,58,56,56,1,2,2,2,54,2,2,2,2,2,56,0,0,0,0,0,0,0,0
0,0,0,0,58,58,56,56,56,2,2,2,54,2,2,2,2,1,1,0,0,0,0,0,0,0,0
0,0,0,0,58,1,56,56,2,2,2,2,54,2,2,2,2,2,2,0,0,0,0,0,0,0,0
0,0,0,0,0,56,2,2,2,2,2,2,54,2,1,1,2,2,2,0,0,0,0,0,0,0,0
0,0,0,0,0,56,2,2,2,2,2,2,2,2,2,1,2,2,62,0,0,0,0,0,0,0,0
0,0,0,0,0,2,56,2,2,2,2,2,2,2,2,2,2,2,62,0,0,0,0,65,0,0,0
0,0,0,0,0,2,56,2,2,2,2,2,2,2,2,2,2,2,0,0,0,0,65,65,65,0,0
0,0,0,0,0,2,56,2,2,2,2,2,2,2,2,2,2,2,0,0,0,0,65,65,65,65,0
0,0,0,0,0,56,2,2,2,2,2,2,2,2,2,2,2,2,0,0,0,65,65,65,65,65,0
0,0,0,0,0,0,2,2,2,2,2,2,2,2,2,2,2,2,0,0,0,65,65,59,65,65,0
0,0,0,0,0,0,0,54,2,2,2,2,2,2,2,1,0,0,0,0,0,65,65,65,65,65,0
0,0,0,0,0,0,0,71,54,71,2,2,1,1,71,71,0,0,0,0,0,65,65,65,65,0,0
0,0,0,0,59,0,0,0,0,0,0,0,58,58,59,0,0,0,0,0,0,0,0,0,0,0,0
0,0,0,0,0,0,0,0,0,0,0,0,0,0,0,0,0,0,0,0,0,0,0,0,0,0,0
0,0,0,0,0,0,0,0,0,0,0,0,0,0,0,0,0,0,0,0,0,0,0,0,0,0,0
0,0,0,0,0,0,0,0,0,0,0,0,0,0,0,0,0,0,0,0,0,0,0,0,0,0,0
:endlayer
layer: 14
0,0,0,0,0,0,0,0,0,0,0,0,0,0,0,0,0,0,0,0,0,0,0,0,0,0,0
0,0,0,0,0,0,0,0,0,0,0,0,0,0,0,0,0,0,0,0,0,0,0,0,0,0,0
0,0,0,0,0,0,0,0,0,0,0,0,0,59,0,0,0,0,0,59,65,65,0,0,65,65,65
0,0,0,0,65,0,0,0,0,0,0,0,0,0,0,0,0,0,65,65,65,65,65,65,65,65,65
0,0,0,65,65,65,0,0,0,0,0,0,0,0,0,0,0,0,65,65,65,65,65,65,69,65,65
0,0,0,0,65,0,0,0,59,0,0,0,0,56,56,56,56,0,65,65,65,65,65,65,69,65,65
0,0,0,0,0,0,0,0,3,0,0,0,0,56,56,56,56,0,0,5,5,70,70,59,65,65,65
0,0,0,0,0,0,0,0,0,55,3,54,54,1,1,1,1,54,54,3,3,3,65,65,69,65,65
0,0,0,0,0,0,0,0,0,54,54,54,54,1,1,1,1,3,3,3,3,3,3,65,65,65,65
0,0,0,0,0,0,0,0,0,55,0,0,54,54,54,1,1,3,3,3,3,3,3,65,69,65,65
0,0,0,0,0,0,0,0,0,54,0,0,0,0,0,54,3,3,3,3,3,3,3,65,69,65,0
0,0,0,0,0,0,0,0,0,0,0,0,0,0,0,54,54,3,3,3,3,3,3,0,65,0,0
0,0,0,0,0,0,0,0,0,55,0,0,0,0,0,54,54,54,3,3,3,3,73,0,0,0,0
0,0,0,0,0,0,0,0,0,55,0,0,0,0,0,0,0,3,54,3,3,73,0,0,0,0,0
0,0,0,0,0,0,0,0,0,54,0,0,0,55,0,0,0,3,0,0,0,0,0,0,0,0,0
0,0,0,0,0,0,0,0,0,55,54,0,54,55,54,0,54,3,0,0,0,0,0,0,0,0,0
0,0,0,0,0,0,0,0,0,1,54,0,3,56,0,0,0,0,0,0,0,0,0,0,0,0,0
0,0,0,0,0,0,0,0,56,1,54,3,54,56,0,0,0,0,0,0,0,0,0,0,0,0,0
0,0,0,0,0,0,0,56,56,1,54,3,3,1,56,0,0,0,0,0,0,0,0,0,0,0,0
0,0,0,0,0,59,58,56,1,1,54,57,54,1,1,56,0,0,0,0,0,0,0,0,0,0,0
0,0,0,0,0,58,0,1,1,2,57,57,54,1,1,56,0,0,0,0,0,0,0,0,0,0,0
0,0,0,0,0,58,56,1,2,1,57,57,57,1,1,56,0,0,0,0,0,0,0,0,0,0,0
0,0,0,0,0,58,66,56,1,1,57,57,57,1,1,2,2,0,0,0,0,0,0,0,0,0,0
0,0,0,0,0,0,58,58,56,1,3,3,3,1,56,2,2,54,0,0,0,0,0,0,0,0,0
0,0,0,0,0,0,58,0,0,56,1,3,1,56,2,2,2,56,1,0,0,0,0,0,0,0,0
0,0,0,0,0,59,0,0,56,2,56,1,1,2,2,2,74,56,0,0,0,0,0,0,0,0,0
0,0,0,0,0,58,0,55,2,2,2,2,2,2,1,1,56,2,0,0,0,0,0,0,0,0,0
0,0,0,0,0,0,0,2,2,2,2,2,2,2,2,1,56,2,0,0,0,0,0,0,0,0,0
0,0,0,0,0,0,0,2,2,2,2,2,2,2,2,2,56,2,0,0,0,0,0,0,0,0,0
0,0,0,0,0,0,0,2,2,2,2,2,2,2,2,2,2,2,0,0,0,0,0,0,0,0,0
0,0,0,0,0,0,0,3,2,2,2,2,2,2,2,2,2,0,0,0,0,0,0,0,0,0,0
0,0,0,0,0,0,0,74,2,2,2,2,2,2,2,2,2,0,0,0,0,0,0,65,65,0,0
0,0,0,0,0,0,0,3,2,2,2,2,2,2,2,2,0,0,0,0,0,0,65,59,65,0,0
0,0,0,65,65,65,65,3,1,1,2,2,2,2,1,71,0,0,0,0,0,0,0,65,65,0,0
0,0,65,65,65,65,65,55,55,55,55,71,74,3,3,71,65,0,0,0,0,0,0,0,0,0,0
0,0,65,65,59,65,65,0,0,0,0,0,65,65,59,65,65,0,0,0,0,0,0,0,0,0,0
0,0,65,65,65,65,65,0,0,0,0,0,65,65,65,65,65,0,0,0,0,0,0,0,0,0,0
0,0,0,65,65,65,0,0,0,0,0,0,65,65,65,65,0,0,0,0,0,0,0,0,0,0,0
0,0,0,0,0,0,0,0,0,0,0,0,0,0,0,0,0,0,0,0,0,0,0,0,0,0,0
:endlayer
layer: 15
0,0,0,0,0,0,0,0,0,0,0,0,65,65,65,65,0,0,65,65,65,65,0,0,0,0,0
0,0,0,0,0,0,0,0,0,0,0,65,65,65,65,65,0,65,65,65,65,65,0,0,0,0,0
0,0,0,0,0,0,0,0,0,0,0,65,65,59,65,65,0,65,65,59,65,65,0,0,0,65,0
0,0,0,0,0,0,65,65,65,65,0,65,65,65,65,65,0,65,65,65,65,65,0,0,65,69,65
0,0,0,0,0,0,65,65,65,65,65,0,65,65,65,0,0,0,65,65,65,65,65,65,65,65,65
0,0,0,0,0,0,65,65,59,65,65,0,0,58,58,58,58,0,65,70,70,65,65,65,65,65,0
0,0,0,0,0,0,65,65,3,65,65,0,0,0,0,58,58,0,76,3,38,75,65,59,65,65,65
0,0,0,0,0,0,65,65,0,55,3,54,54,54,54,54,54,54,3,3,3,3,53,69,65,65,65
0,0,0,0,0,0,0,0,0,54,54,54,3,3,3,3,3,3,3,3,3,3,3,65,69,65,65
0,0,0,0,0,0,0,0,0,55,0,0,3,54,54,54,3,3,3,3,3,3,3,65,65,65,65
0,0,0,0,0,0,0,0,0,54,0,0,0,0,0,54,54,3,3,3,3,3,3,65,65,65,65
0,0,0,0,0,0,0,0,0,55,0,0,0,0,0,54,54,3,3,3,3,3,14,65,65,65,65
0,0,0,0,0,0,0,0,0,54,0,0,0,0,0,54,54,54,3,3,3,3,3,65,65,65,0
0,0,0,0,0,0,0,0,0,55,0,0,0,0,0,0,0,3,54,3,3,3,0,0,0,0,0
0,0,0,0,0,0,0,0,0,54,0,0,0,55,0,0,0,3,0,5,5,0,0,0,0,0,0
0,0,0,0,0,0,0,0,0,55,3,0,54,55,54,0,54,3,0,0,0,0,0,0,0,0,0
0,0,0,0,0,0,0,0,0,55,3,0,3,58,0,0,0,0,0,0,0,0,0,0,0,0,0
0,0,0,0,0,0,0,0,58,55,3,3,54,0,0,0,0,0,0,0,0,0,0,0,0,0,0
0,0,0,0,0,0,0,64,66,55,3,3,54,56,0,0,0,0,0,0,0,0,0,0,0,0,0
0,0,0,0,0,59,0,58,1,1,54,57,57,1,56,58,0,0,0,0,0,0,0,0,0,0,0
0,0,0,0,0,0,0,56,1,1,1,1,1,1,56,58,0,0,0,0,0,0,0,0,0,0,0
0,0,0,0,0,0,58,56,1,1,1,0,1,1,56,58,0,0,0,0,0,0,0,0,0,0,0
0,0,0,0,0,0,0,58,56,1,1,1,1,1,56,0,0,0,0,0,0,0,0,0,0,0,0
0,0,0,0,65,65,65,0,58,56,1,1,1,56,0,0,0,0,0,0,0,0,0,0,0,0,0
0,0,0,65,65,65,65,65,0,58,56,56,56,0,0,0,0,58,59,0,0,0,0,0,0,0,0
0,0,0,65,65,59,65,65,0,0,0,56,74,0,0,54,0,58,0,0,0,0,0,0,0,0,0
0,0,0,65,65,65,65,74,2,2,2,2,2,2,1,3,0,0,0,0,0,0,0,0,0,0,0
0,0,0,65,65,65,65,55,2,2,2,2,2,2,2,1,0,0,0,0,0,0,0,0,0,0,0
0,0,0,0,0,0,0,55,2,2,2,2,2,2,2,2,0,0,0,0,0,0,0,0,0,0,0
0,0,0,0,0,0,0,55,2,2,2,2,2,2,2,2,2,0,0,0,0,0,0,0,0,0,0
0,0,0,0,0,0,0,3,2,2,2,74,2,2,2,2,0,0,0,0,0,0,0,0,0,0,0
0,0,0,0,0,0,0,71,2,2,2,2,2,2,2,54,0,0,0,0,0,0,0,65,0,0,0
0,0,0,0,0,0,0,55,2,2,2,2,2,2,2,55,0,0,0,0,0,0,65,65,65,0,0
0,0,0,65,65,65,0,74,2,2,2,2,2,2,2,3,0,0,0,0,0,0,0,65,0,0,0
0,0,65,65,65,65,65,3,54,3,71,71,54,71,74,71,65,0,0,0,0,0,0,0,0,0,0
0,0,65,65,59,65,65,0,0,0,0,0,65,65,59,65,65,0,0,0,0,0,0,0,0,0,0
0,0,65,65,65,65,65,0,0,0,0,0,65,65,65,65,65,0,0,0,0,0,0,0,0,0,0
0,0,65,65,65,65,0,0,0,0,0,0,0,65,65,65,65,0,0,0,0,0,0,0,0,0,0
0,0,0,0,0,0,0,0,0,0,0,0,0,0,0,0,0,0,0,0,0,0,0,0,0,0,0
:endlayer
layer: 16
0,0,0,0,0,0,0,0,0,0,0,0,65,65,65,65,0,0,65,65,65,0,0,0,0,0,0
0,0,0,0,0,0,0,0,0,0,0,65,65,65,65,65,0,65,65,65,65,65,0,0,65,65,65
0,0,0,0,0,0,0,0,0,0,0,65,65,59,65,65,0,65,65,59,65,65,0,65,65,65,65
0,0,0,0,0,0,65,65,65,65,65,65,65,65,65,65,0,65,65,65,65,65,0,65,65,65,65
0,0,0,0,0,0,65,65,65,65,65,65,65,65,65,65,0,65,65,65,65,65,0,65,65,65,65
0,0,0,0,0,0,65,65,59,65,65,0,0,0,0,0,0,65,65,65,65,65,65,65,65,70,65
0,0,0,0,0,0,65,65,3,53,53,53,53,53,53,53,53,3,3,3,3,3,65,59,70,65,65
0,0,0,0,0,0,65,65,76,3,3,54,54,3,3,3,54,77,77,77,77,77,3,65,65,65,65
0,0,0,0,0,0,0,0,76,55,55,55,3,55,55,3,3,77,77,77,77,77,3,65,65,65,65
0,0,0,0,0,0,0,0,76,55,54,3,55,55,3,3,3,77,77,77,77,77,3,65,69,65,65
0,0,0,0,0,0,0,0,76,55,3,3,54,3,54,54,54,77,77,3,3,3,3,65,65,65,65
0,0,0,0,0,0,0,0,76,3,3,3,54,3,3,54,3,77,77,3,3,3,3,65,65,65,65
0,0,0,0,0,0,0,0,76,3,55,3,3,54,54,54,73,3,3,3,3,3,3,65,65,65,0
0,0,0,0,0,0,0,0,76,3,3,3,3,3,3,3,3,73,3,3,3,3,73,0,0,0,0
0,0,0,0,0,0,0,0,76,55,3,3,54,55,3,3,3,3,76,3,3,75,0,0,0,0,0
0,0,0,0,0,0,0,0,76,55,3,3,3,55,3,3,3,3,0,0,0,0,0,0,0,0,0
0,0,0,0,0,0,0,0,76,0,3,3,54,0,0,0,0,0,0,0,0,0,0,0,0,0,0
0,0,0,0,0,0,0,0,0,0,3,3,3,0,0,0,0,0,0,0,0,0,0,0,0,0,0
0,0,0,0,0,0,0,0,76,55,3,3,3,0,0,0,0,0,0,0,0,0,0,0,0,0,0
0,0,0,0,0,59,0,0,55,56,56,56,56,56,0,0,0,0,0,0,0,0,0,0,0,0,0
0,0,0,0,0,0,0,58,56,56,56,56,56,56,58,0,0,0,0,0,0,0,0,0,0,0,0
0,0,0,0,0,0,0,58,56,56,55,56,56,1,0,0,0,0,0,0,0,0,0,0,0,0,0
0,0,0,0,0,0,0,0,58,56,56,56,56,55,58,0,65,65,65,65,0,0,0,0,0,0,0
0,0,0,0,65,65,65,0,0,58,1,56,56,58,0,0,65,65,65,65,65,0,0,0,0,0,0
0,0,0,65,65,65,65,65,0,0,0,64,0,0,0,0,65,65,59,65,65,0,0,0,0,0,0
0,0,0,65,65,59,65,65,0,0,0,0,71,0,0,74,65,65,65,65,65,0,0,0,0,0,0
0,0,0,65,65,65,65,3,3,54,74,56,3,3,3,54,65,65,65,65,0,0,0,0,0,0,0
0,0,0,65,65,65,65,74,2,2,2,2,2,2,2,54,0,0,0,0,0,0,0,0,0,0,0
0,0,0,0,0,0,0,71,2,2,2,2,2,2,2,55,0,0,0,0,0,0,0,0,0,0,0
0,0,0,0,0,0,0,3,2,2,2,2,2,2,2,3,0,0,0,0,0,0,0,0,0,0,0
0,0,0,0,0,0,0,55,2,2,2,78,2,2,2,55,0,0,0,0,0,0,0,0,0,0,0
0,0,0,0,0,0,0,54,2,2,2,74,2,2,2,3,0,0,0,0,0,0,0,0,0,0,0
0,0,0,0,0,0,0,3,2,2,2,2,2,2,2,54,0,0,0,0,0,0,0,0,0,0,0
0,0,0,0,0,0,0,71,2,2,2,2,2,2,2,74,0,0,0,0,0,0,0,0,0,0,0
0,0,0,0,65,65,0,55,71,71,74,55,54,71,54,55,0,0,0,0,0,0,0,0,0,0,0
0,0,0,65,59,65,0,0,0,0,0,0,0,65,59,65,0,0,0,0,0,0,0,0,0,0,0
0,0,0,65,65,0,0,0,0,0,0,0,0,65,65,65,0,0,0,0,0,0,0,0,0,0,0
0,0,0,0,0,0,0,0,0,0,0,0,0,0,0,0,0,0,0,0,0,0,0,0,0,0,0
0,0,0,0,0,0,0,0,0,0,0,0,0,0,0,0,0,0,0,0,0,0,0,0,0,0,0
:endlayer
layer: 17
0,0,0,0,0,0,0,0,0,0,0,0,0,0,0,0,0,0,0,0,0,0,0,0,0,0,0
0,0,0,0,0,0,0,0,0,0,0,0,65,65,65,0,0,0,0,65,0,0,0,0,65,65,0
0,0,0,0,0,0,0,0,0,0,0,0,65,59,65,0,0,0,65,59,65,0,0,65,65,65,65
0,0,0,0,0,0,0,0,0,0,0,0,65,65,65,0,0,0,65,65,65,0,0,65,65,65,65
0,0,0,0,0,0,0,0,65,65,0,0,0,0,0,0,0,65,65,65,65,65,65,69,65,65,65
0,0,0,0,0,0,0,65,59,65,0,0,0,0,0,0,0,65,65,65,65,65,0,69,65,65,0
0,0,0,0,0,0,0,0,3,5,5,3,5,5,3,5,5,3,38,3,3,3,0,59,65,0,65
0,0,0,0,0,0,0,0,5,0,0,0,0,0,0,0,3,0,0,0,0,80,75,65,65,65,0
0,0,0,0,0,0,0,0,5,0,0,0,0,0,0,0,82,0,0,0,0,0,57,65,65,65,65
0,0,0,0,0,0,0,0,3,0,0,0,0,0,0,0,3,0,0,0,0,81,3,65,65,65,65
0,0,0,0,0,0,0,0,5,0,0,0,0,0,0,0,3,0,38,3,3,3,75,65,65,65,65
0,0,0,0,0,0,0,0,5,0,0,89,0,0,0,54,3,8,3,3,3,3,3,65,65,65,0
0,0,0,0,0,0,0,0,3,0,0,0,0,0,0,54,3,3,3,3,3,3,3,0,0,0,0
0,0,0,0,0,0,0,0,5,0,0,0,0,0,0,0,73,3,3,3,3,3,3,79,79,79,0
0,0,0,0,0,0,0,0,5,0,0,0,0,0,0,0,0,73,3,30,3,3,73,79,79,79,0
0,0,0,0,0,0,0,0,3,0,0,0,0,0,0,0,0,0,0,0,0,0,0,0,0,0,0
0,0,0,0,0,0,0,0,0,0,0,0,0,0,0,0,0,0,0,0,0,0,0,0,0,0,0
0,0,0,65,65,65,65,0,0,0,0,0,0,0,0,0,0,0,0,0,0,0,0,0,0,0,0
0,0,0,65,65,65,65,65,0,0,0,0,0,0,0,0,0,0,0,0,0,0,0,0,0,0,0
0,0,0,65,65,59,65,65,0,0,58,58,58,58,0,0,0,0,0,0,0,0,0,0,0,0,0
0,0,0,65,65,65,65,65,0,0,58,58,58,58,0,0,0,0,0,0,0,0,0,0,0,0,0
0,0,0,65,65,65,65,0,58,58,0,0,58,59,0,0,0,0,0,0,0,0,0,0,0,0,0
0,0,0,0,0,0,0,0,0,58,58,0,58,0,0,0,65,65,65,65,0,0,0,0,0,0,0
0,0,0,0,0,0,0,0,0,0,59,58,58,0,0,0,65,65,65,65,65,0,0,0,0,0,0
0,0,0,0,65,65,65,0,0,0,0,0,0,0,0,0,65,65,59,65,65,0,0,0,0,0,0
0,0,0,0,65,59,65,0,0,0,0,0,0,0,0,0,65,65,65,65,65,0,0,0,0,0,0
0,0,0,0,65,65,65,3,55,71,54,0,55,55,71,54,65,65,65,65,0,0,0,0,0,0,0
0,0,0,0,0,0,0,55,74,0,91,0,0,0,78,71,0,0,0,0,0,0,0,0,0,0,0
0,0,0,0,0,0,0,54,93,0,0,74,0,0,0,54,0,0,0,0,0,0,0,0,0,0,0
0,0,0,0,0,0,0,55,94,0,0,0,3,0,83,54,0,0,0,0,0,0,0,0,0,0,0
0,0,0,0,0,0,0,71,74,0,87,6,87,0,84,74,0,0,0,0,0,0,0,0,0,0,0
0,0,0,0,0,0,0,74,74,0,0,0,0,0,8,74,0,0,0,0,0,0,0,0,0,0,0
0,0,0,0,0,0,0,55,30,0,0,0,0,0,85,54,0,0,0,0,0,0,0,0,0,0,0
0,0,0,0,0,0,0,71,0,92,0,90,88,0,86,71,0,0,0,0,0,0,0,0,0,0,0
0,0,0,0,65,0,0,74,3,3,3,74,74,74,55,55,0,0,0,0,0,0,0,0,0,0,0
0,0,0,65,65,65,0,0,0,0,0,0,0,65,65,65,0,0,0,0,0,0,0,0,0,0,0
0,0,0,0,65,0,0,0,0,0,0,0,0,0,65,0,0,0,0,0,0,0,0,0,0,0,0
0,0,0,0,0,0,0,0,0,0,0,0,0,0,0,0,0,0,0,0,0,0,0,0,0,0,0
0,0,0,0,0,0,0,0,0,0,0,0,0,0,0,0,0,0,0,0,0,0,0,0,0,0,0
:endlayer
layer: 18
0,0,0,0,0,0,0,0,0,0,0,0,0,0,0,0,0,0,0,0,0,0,0,0,0,0,0
0,0,0,0,0,0,0,0,0,0,0,0,0,65,0,0,0,0,0,65,0,0,0,0,0,0,0
0,0,0,0,0,0,0,0,0,0,0,0,65,65,65,0,0,0,65,65,65,0,65,65,65,65,0
0,0,0,0,0,0,0,0,0,0,0,0,0,65,0,0,0,0,0,65,0,65,65,65,65,65,65
0,0,0,0,0,0,0,0,65,0,0,0,0,0,0,0,0,0,0,65,0,65,65,65,65,65,65
0,0,0,0,0,0,0,65,65,65,0,0,0,0,0,0,0,0,65,65,65,65,65,65,65,65,65
0,0,0,0,0,0,0,0,3,0,0,0,0,0,0,0,0,55,3,3,3,3,65,59,65,65,65
0,0,0,0,0,0,0,0,0,0,0,0,0,0,0,0,55,97,51,0,51,0,3,65,65,65,65
0,0,0,0,0,0,0,0,0,0,0,0,0,0,0,0,98,0,0,0,0,0,65,65,65,65,0
0,0,0,0,0,0,0,0,0,0,0,0,0,0,0,0,3,0,0,0,0,0,3,65,65,65,65
0,0,0,0,0,0,0,0,0,0,0,0,0,0,0,53,3,0,0,3,3,3,3,65,65,65,65
0,0,0,0,0,0,0,0,0,0,0,0,0,0,0,3,3,0,38,3,3,3,3,65,65,65,0
0,0,0,0,0,0,0,0,0,0,0,0,0,0,0,3,3,3,3,3,3,3,3,0,95,95,0
0,0,0,0,0,0,0,0,0,0,0,0,0,0,0,73,3,3,3,3,3,3,3,3,96,96,0
0,0,0,0,0,0,0,0,0,0,0,0,0,0,0,0,73,3,3,3,30,3,3,3,96,96,0
0,0,0,0,0,0,0,0,0,0,0,0,0,0,0,0,0,0,0,0,0,0,0,0,0,0,0
0,0,0,0,0,0,0,0,0,0,0,0,0,0,0,0,0,0,0,0,0,0,0,0,0,0,0
0,0,0,0,65,65,65,65,0,0,0,0,0,0,0,0,0,0,0,0,0,0,0,0,0,0,0
0,0,0,65,65,65,65,65,0,0,0,0,0,0,0,0,0,0,0,0,0,0,0,0,0,0,0
0,0,0,65,65,59,65,65,0,0,0,0,0,0,0,0,0,0,0,0,0,0,0,0,0,0,0
0,0,0,65,65,65,65,65,0,0,0,0,0,0,0,0,0,0,0,0,0,0,0,0,0,0,0
0,0,0,65,65,65,65,0,0,0,0,0,0,59,0,0,0,0,0,0,0,0,0,0,0,0,0
0,0,0,0,0,0,0,0,0,0,65,0,0,0,0,0,0,0,0,0,0,0,0,0,0,0,0
0,0,0,0,0,0,0,0,0,65,59,65,0,0,0,0,0,0,65,0,0,0,0,0,0,0,0
0,0,0,0,0,65,0,0,0,0,65,0,0,0,0,0,0,65,59,65,0,0,0,0,0,0,0
0,0,0,0,65,65,65,0,0,0,0,0,0,0,0,0,0,65,65,0,0,0,0,0,0,0,0
0,0,0,0,0,65,0,55,54,74,55,0,55,54,54,55,0,0,0,0,0,0,0,0,0,0,0
0,0,0,0,0,0,0,55,74,0,0,0,0,0,0,71,0,0,0,0,0,0,0,0,0,0,0
0,0,0,0,0,0,0,55,0,0,0,54,0,0,0,55,0,0,0,0,0,0,0,0,0,0,0
0,0,0,0,0,0,0,71,0,0,0,0,3,0,0,55,0,0,0,0,0,0,0,0,0,0,0
0,0,0,0,0,0,0,54,74,0,0,0,0,0,0,55,0,0,0,0,0,0,0,0,0,0,0
0,0,0,0,0,0,0,74,30,0,0,0,0,0,0,55,0,0,0,0,0,0,0,0,0,0,0
0,0,0,0,0,0,0,55,0,0,0,0,0,0,0,74,0,0,0,0,0,0,0,0,0,0,0
0,0,0,0,0,0,0,74,0,0,0,0,0,0,0,55,0,0,0,0,0,0,0,0,0,0,0
0,0,0,0,0,0,0,55,74,54,55,54,55,55,74,71,0,0,0,0,0,0,0,0,0,0,0
0,0,0,0,0,0,0,0,0,0,0,0,0,0,0,0,0,0,0,0,0,0,0,0,0,0,0
0,0,0,0,0,0,0,0,0,0,0,0,0,0,0,0,0,0,0,0,0,0,0,0,0,0,0
0,0,0,0,0,0,0,0,0,0,0,0,0,0,0,0,0,0,0,0,0,0,0,0,0,0,0
0,0,0,0,0,0,0,0,0,0,0,0,0,0,0,0,0,0,0,0,0,0,0,0,0,0,0
:endlayer
layer: 19
0,0,0,0,0,0,0,0,0,0,0,0,0,0,0,0,0,0,0,0,0,0,0,0,0,0,0
0,0,0,0,0,0,0,0,0,0,0,0,0,0,0,0,0,0,0,0,0,0,0,0,0,0,0
0,0,0,0,0,0,0,0,0,0,0,0,0,0,0,0,0,0,0,0,0,0,0,65,0,0,0
0,0,0,0,0,0,0,0,0,0,0,0,0,0,0,0,0,0,0,0,0,0,65,65,65,65,0
0,0,0,0,0,0,0,0,0,0,0,0,0,0,0,0,0,0,0,0,0,65,65,65,65,65,0
0,0,0,0,0,0,0,0,0,0,0,0,0,0,0,0,0,0,0,0,0,65,65,65,65,65,65
0,0,0,0,0,0,0,0,0,0,0,0,0,0,0,0,0,3,55,55,53,3,65,65,65,65,65
0,0,0,0,0,0,0,0,0,0,0,0,0,0,0,0,55,0,0,0,0,65,3,65,65,65,0
0,0,0,0,0,0,0,0,0,0,0,0,0,0,0,0,3,0,0,0,0,0,99,96,65,0,0
0,0,0,0,0,0,0,0,0,0,0,0,0,0,0,0,3,0,0,0,0,0,3,65,65,65,0
0,0,0,0,0,0,0,0,0,0,0,0,0,0,0,3,3,0,0,3,3,3,75,0,65,0,0
0,0,0,0,0,0,0,0,0,0,0,0,0,0,0,55,3,0,0,3,3,3,3,0,95,95,0
0,0,0,0,0,0,0,0,0,0,0,0,0,0,0,3,96,96,96,96,96,3,3,0,0,0,0
0,0,0,0,0,0,0,0,0,0,0,0,0,0,0,3,96,96,96,96,96,52,0,0,0,0,0
0,0,0,0,0,0,0,0,0,0,0,0,0,0,0,0,3,30,3,3,3,3,0,0,0,0,0
0,0,0,0,0,0,0,0,0,0,0,0,0,0,0,0,0,0,0,0,0,0,0,0,0,0,0
0,0,0,0,0,0,0,0,0,0,0,0,0,0,0,0,0,0,0,0,0,0,0,0,0,0,0
0,0,0,0,0,0,0,0,0,0,0,0,0,0,0,0,0,0,0,0,0,0,0,0,0,0,0
0,0,0,0,65,65,0,0,0,0,0,0,0,0,0,0,0,0,0,0,0,0,0,0,0,0,0
0,0,0,0,65,59,65,0,0,0,0,65,65,65,65,65,0,0,0,0,0,0,0,0,0,0,0
0,0,0,0,0,65,65,0,0,0,0,65,65,65,65,65,0,0,0,0,0,0,0,0,0,0,0
0,0,0,0,0,0,0,0,0,65,65,65,65,59,65,65,0,0,0,0,0,0,0,0,0,0,0
0,0,0,0,0,0,0,0,65,65,65,65,65,65,65,65,0,0,0,0,0,0,0,0,0,0,0
0,0,0,0,0,0,0,0,65,65,59,65,65,65,65,65,0,0,65,0,0,0,0,0,0,0,0
0,0,0,0,0,0,0,0,65,65,65,65,65,0,0,0,0,65,65,65,0,0,0,0,0,0,0
0,0,0,0,0,0,0,0,0,65,65,65,0,0,0,0,0,0,65,0,0,0,0,0,0,0,0
0,0,0,0,0,0,0,3,55,3,55,0,71,54,71,71,0,0,0,0,0,0,0,0,0,0,0
0,0,0,0,0,0,0,54,74,0,0,0,51,0,0,74,0,0,0,0,0,0,0,0,0,0,0
0,0,0,0,0,0,0,74,73,0,0,55,0,0,0,3,0,0,0,0,0,0,0,0,0,0,0
0,0,0,0,0,0,0,55,53,0,0,0,0,0,0,54,0,0,0,0,0,0,0,0,0,0,0
0,0,0,0,0,0,0,55,30,0,0,0,0,0,0,74,0,0,0,0,0,0,0,0,0,0,0
0,0,0,0,0,0,0,74,0,0,0,0,0,0,0,54,0,0,0,0,0,0,0,0,0,0,0
0,0,0,0,0,0,0,3,0,0,0,0,0,0,0,3,0,0,0,0,0,0,0,0,0,0,0
0,0,0,0,0,0,0,55,0,0,0,46,0,0,0,3,0,0,0,0,0,0,0,0,0,0,0
0,0,0,0,0,0,0,74,54,74,71,71,3,71,71,54,0,0,0,0,0,0,0,0,0,0,0
0,0,0,0,0,0,0,0,0,0,0,0,0,0,0,0,0,0,0,0,0,0,0,0,0,0,0
0,0,0,0,0,0,0,0,0,0,0,0,0,0,0,0,0,0,0,0,0,0,0,0,0,0,0
0,0,0,0,0,0,0,0,0,0,0,0,0,0,0,0,0,0,0,0,0,0,0,0,0,0,0
0,0,0,0,0,0,0,0,0,0,0,0,0,0,0,0,0,0,0,0,0,0,0,0,0,0,0
:endlayer
layer: 20
0,0,0,0,0,0,0,0,0,0,0,0,0,0,0,0,0,0,0,0,0,0,0,0,0,0,0
0,0,0,0,0,0,0,0,0,0,0,0,0,0,0,0,0,0,0,0,0,0,0,0,0,0,0
0,0,0,0,0,0,0,0,0,0,0,0,0,0,0,0,0,0,0,0,0,0,0,0,0,0,0
0,0,0,0,0,0,0,0,0,0,0,0,0,0,0,0,0,0,0,0,0,0,0,65,0,0,0
0,0,0,0,0,0,0,0,0,0,0,0,0,0,0,0,0,0,0,0,0,0,65,65,65,0,0
0,0,0,0,0,0,0,0,0,0,0,0,0,0,0,0,0,0,0,0,0,65,65,65,65,65,0
0,0,0,0,0,0,0,0,0,0,0,0,0,0,0,0,0,53,3,55,55,3,65,65,65,65,0
0,0,0,0,0,0,0,0,0,0,0,0,0,0,0,0,55,0,0,0,0,65,75,65,65,0,0
0,0,0,0,0,0,0,0,0,0,0,0,0,0,0,0,21,0,0,0,0,0,3,65,0,0,0
0,0,0,0,0,0,0,0,0,0,0,0,0,0,0,0,3,0,0,0,0,0,3,0,0,0,0
0,0,0,0,0,0,0,0,0,0,0,0,0,0,0,55,3,0,0,3,3,3,3,0,95,95,0
0,0,0,0,0,0,0,0,0,0,0,0,0,0,0,55,3,0,0,3,3,3,3,0,0,0,0
0,0,0,0,0,0,0,0,0,0,0,0,0,0,0,0,0,0,0,0,0,3,3,48,0,0,0
0,0,0,0,0,0,0,0,0,0,0,0,0,0,0,3,0,100,0,0,0,0,0,0,0,0,0
0,0,0,0,0,0,0,0,0,0,0,0,0,0,0,0,3,3,73,3,3,30,0,0,0,0,0
0,0,0,0,0,0,0,0,0,0,0,0,0,0,0,0,0,0,0,0,0,0,0,0,0,0,0
0,0,0,0,0,0,0,0,0,0,0,0,0,0,0,0,0,0,0,0,0,0,0,0,0,0,0
0,0,0,0,0,0,0,0,0,0,0,0,0,0,0,0,0,0,0,0,0,0,0,0,0,0,0
0,0,0,0,0,65,0,0,0,0,0,0,0,0,0,0,0,0,0,0,0,0,0,0,0,0,0
0,0,0,0,65,65,65,0,0,0,0,0,65,65,65,0,0,0,0,0,0,0,0,0,0,0,0
0,0,0,0,0,65,0,0,0,0,0,65,65,65,65,65,0,0,0,0,0,0,0,0,0,0,0
0,0,0,0,0,0,0,0,0,65,65,65,65,59,65,65,0,0,0,0,0,0,0,0,0,0,0
0,0,0,0,0,0,0,0,65,65,65,65,65,65,65,65,0,0,0,0,0,0,0,0,0,0,0
0,0,0,0,0,0,0,0,65,65,59,65,65,65,65,65,0,0,0,0,0,0,0,0,0,0,0
0,0,0,0,0,0,0,0,65,65,65,65,65,0,0,0,0,0,0,0,0,0,0,0,0,0,0
0,0,0,0,0,0,0,0,0,65,65,65,0,0,0,0,0,0,0,0,0,0,0,0,0,0,0
0,0,0,0,0,0,0,74,55,55,74,55,71,54,71,55,0,0,0,0,0,0,0,0,0,0,0
0,0,0,0,0,0,0,74,74,0,0,0,0,0,0,71,0,0,0,0,0,0,0,0,0,0,0
0,0,0,0,0,0,0,3,74,0,0,0,0,0,0,55,0,0,0,0,0,0,0,0,0,0,0
0,0,0,0,0,0,0,54,30,0,0,0,0,0,0,74,0,0,0,0,0,0,0,0,0,0,0
0,0,0,0,0,0,0,55,0,0,0,0,0,0,0,54,0,0,0,0,0,0,0,0,0,0,0
0,0,0,0,0,0,0,74,0,0,0,0,0,0,0,74,0,0,0,0,0,0,0,0,0,0,0
0,0,0,0,0,0,0,74,0,0,0,0,0,0,0,54,0,0,0,0,0,0,0,0,0,0,0
0,0,0,0,0,0,0,55,0,0,0,0,0,0,0,71,0,0,0,0,0,0,0,0,0,0,0
0,0,0,0,0,0,0,55,74,71,74,71,74,54,71,54,0,0,0,0,0,0,0,0,0,0,0
0,0,0,0,0,0,0,0,0,0,0,0,0,0,0,0,0,0,0,0,0,0,0,0,0,0,0
0,0,0,0,0,0,0,0,0,0,0,0,0,0,0,0,0,0,0,0,0,0,0,0,0,0,0
0,0,0,0,0,0,0,0,0,0,0,0,0,0,0,0,0,0,0,0,0,0,0,0,0,0,0
0,0,0,0,0,0,0,0,0,0,0,0,0,0,0,0,0,0,0,0,0,0,0,0,0,0,0
:endlayer
layer: 21
0,0,0,0,0,0,0,0,0,0,0,0,0,0,0,0,0,0,0,0,0,0,0,0,0,0,0
0,0,0,0,0,0,0,0,0,0,0,0,0,0,0,0,0,0,0,0,0,0,0,0,0,0,0
0,0,0,0,0,0,0,0,0,0,0,0,0,0,0,0,0,0,0,0,0,0,0,0,0,0,0
0,0,0,0,0,0,0,0,0,0,0,0,0,0,0,0,0,0,0,0,0,0,0,0,0,0,0
0,0,0,0,0,0,0,0,0,0,0,0,0,0,0,0,0,0,0,0,0,0,0,0,0,0,0
0,0,0,0,0,0,0,0,0,0,0,0,0,0,0,0,0,0,0,0,0,0,0,65,0,0,0
0,0,0,0,0,0,0,0,0,0,0,0,0,0,0,0,0,55,3,53,55,55,65,65,65,0,0
0,0,0,0,0,0,0,0,0,0,0,0,0,0,0,0,55,0,0,0,0,0,3,65,0,0,0
0,0,0,0,0,0,0,0,0,0,0,0,0,0,0,0,3,0,0,0,0,0,3,0,0,0,0
0,0,0,0,0,0,0,0,0,0,0,0,0,0,0,53,3,0,0,0,0,0,75,5,95,95,0
0,0,0,0,0,0,0,0,0,0,0,0,0,0,0,55,3,0,0,3,3,3,3,5,0,0,0
0,0,0,0,0,0,0,0,0,0,0,0,0,0,0,3,3,0,0,3,3,3,3,5,0,0,0
0,0,0,0,0,0,0,0,0,0,0,0,0,0,96,99,0,0,0,0,0,3,75,0,0,0,0
0,0,0,0,0,0,0,0,0,0,0,0,0,0,0,3,0,46,0,46,0,99,0,0,0,0,0
0,0,0,0,0,0,0,0,0,0,0,0,0,0,0,0,55,3,3,3,3,3,0,0,0,0,0
0,0,0,0,0,0,0,0,0,0,0,0,0,0,0,0,0,0,5,5,0,0,0,0,0,0,0
0,0,0,0,0,0,0,0,0,0,0,0,0,0,0,0,0,0,0,0,0,0,0,0,0,0,0
0,0,0,0,0,0,0,0,0,0,0,0,0,0,0,0,0,0,0,0,0,0,0,0,0,0,0
0,0,0,0,0,0,0,0,0,0,0,0,0,0,0,0,0,0,0,0,0,0,0,0,0,0,0
0,0,0,0,0,0,0,0,0,0,0,0,0,0,0,0,0,0,0,0,0,0,0,0,0,0,0
0,0,0,0,0,0,0,0,0,0,0,0,0,65,65,0,0,0,0,0,0,0,0,0,0,0,0
0,0,0,0,0,0,0,0,0,65,65,65,65,59,65,0,0,0,0,0,0,0,0,0,0,0,0
0,0,0,0,0,0,0,0,65,65,65,65,65,65,65,0,0,0,0,0,0,0,0,0,0,0,0
0,0,0,0,0,0,0,0,65,65,65,65,65,0,0,0,0,0,0,0,0,0,0,0,0,0,0
0,0,0,0,0,0,0,0,65,65,65,65,65,0,0,0,0,0,0,0,0,0,0,0,0,0,0
0,0,0,0,0,0,0,0,0,65,65,65,0,0,0,0,0,0,0,0,0,0,0,0,0,0,0
0,0,0,0,0,0,0,54,55,71,55,71,54,54,55,71,0,0,0,0,0,0,0,0,0,0,0
0,0,0,0,0,0,0,55,74,74,0,0,0,0,0,3,0,0,0,0,0,0,0,0,0,0,0
0,0,0,0,0,0,0,71,30,0,0,0,0,0,0,71,0,0,0,0,0,0,0,0,0,0,0
0,0,0,0,0,0,0,3,0,0,0,0,0,0,0,54,0,0,0,0,0,0,0,0,0,0,0
0,0,0,0,0,0,0,71,0,0,0,0,0,0,0,55,0,0,0,0,0,0,0,0,0,0,0
0,0,0,0,0,0,0,74,0,0,0,0,0,0,0,3,0,0,0,0,0,0,0,0,0,0,0
0,0,0,0,0,0,0,3,0,0,0,0,0,0,0,54,0,0,0,0,0,0,0,0,0,0,0
0,0,0,0,0,0,0,71,0,0,0,0,0,0,0,3,0,0,0,0,0,0,0,0,0,0,0
0,0,0,0,0,0,0,3,74,74,3,71,55,74,71,71,0,0,0,0,0,0,0,0,0,0,0
0,0,0,0,0,0,0,0,0,0,0,0,0,0,0,0,0,0,0,0,0,0,0,0,0,0,0
0,0,0,0,0,0,0,0,0,0,0,0,0,0,0,0,0,0,0,0,0,0,0,0,0,0,0
0,0,0,0,0,0,0,0,0,0,0,0,0,0,0,0,0,0,0,0,0,0,0,0,0,0,0
0,0,0,0,0,0,0,0,0,0,0,0,0,0,0,0,0,0,0,0,0,0,0,0,0,0,0
:endlayer
layer: 22
0,0,0,0,0,0,0,0,0,0,0,0,0,0,0,0,0,0,0,0,0,0,0,0,0,0,0
0,0,0,0,0,0,0,0,0,0,0,0,0,0,0,0,0,0,0,0,0,0,0,0,0,0,0
0,0,0,0,0,0,0,0,0,0,0,0,0,0,0,0,0,0,0,0,0,0,0,0,0,0,0
0,0,0,0,0,0,0,0,0,0,0,0,0,0,0,0,0,0,0,0,0,0,0,0,0,0,0
0,0,0,0,0,0,0,0,0,0,0,0,0,0,0,0,0,0,0,0,0,0,0,0,0,0,0
0,0,0,0,0,0,0,0,0,0,0,0,0,0,0,0,0,0,0,0,0,0,0,0,0,0,0
0,0,0,0,0,0,0,0,0,0,0,0,0,0,0,0,0,55,38,3,3,55,79,79,79,79,0
0,0,0,0,0,0,0,0,0,0,0,0,0,0,0,0,21,73,73,73,73,73,3,79,79,79,0
0,0,0,0,0,0,0,0,0,0,0,0,0,0,0,0,3,0,0,0,0,0,3,53,95,95,0
0,0,0,0,0,0,0,0,0,0,0,0,0,0,0,21,3,0,5,53,53,53,3,3,0,0,0
0,0,0,0,0,0,0,0,0,0,0,0,0,0,0,3,3,0,76,3,3,3,3,75,0,0,0
0,0,0,0,0,0,0,0,0,0,0,0,0,0,5,3,3,0,76,3,3,3,3,3,0,0,0
0,0,0,0,0,0,0,0,0,0,0,0,0,0,0,3,75,0,5,73,73,3,3,73,0,0,0
0,0,0,0,0,0,0,0,0,0,0,0,0,0,0,3,75,0,0,0,0,3,0,0,0,0,0
0,0,0,0,0,0,0,0,0,0,0,0,0,0,0,0,55,3,3,3,3,3,0,0,0,0,0
0,0,0,0,0,0,0,0,0,0,0,0,0,0,0,0,0,76,3,3,75,0,0,0,0,0,0
0,0,0,0,0,0,0,0,0,0,0,0,0,0,0,0,0,0,0,0,0,0,0,0,0,0,0
0,0,0,0,0,0,0,0,0,0,0,0,0,0,0,0,0,0,0,0,0,0,0,0,0,0,0
0,0,0,0,0,0,0,0,0,0,0,0,0,0,0,0,0,0,0,0,0,0,0,0,0,0,0
0,0,0,0,0,0,0,0,0,0,0,0,0,0,0,0,0,0,0,0,0,0,0,0,0,0,0
0,0,0,0,0,0,0,0,0,0,0,0,0,65,0,0,0,0,0,0,0,0,0,0,0,0,0
0,0,0,0,0,0,0,0,0,0,0,0,65,65,65,0,0,0,0,0,0,0,0,0,0,0,0
0,0,0,0,0,0,0,0,0,0,65,0,0,65,0,0,0,0,0,0,0,0,0,0,0,0,0
0,0,0,0,0,0,0,0,0,65,65,65,0,0,0,0,0,0,0,0,0,0,0,0,0,0,0
0,0,0,0,0,0,0,0,0,0,65,0,0,0,0,0,0,0,0,0,0,0,0,0,0,0,0
0,0,0,0,0,0,0,0,0,0,0,0,0,0,0,0,0,0,0,0,0,0,0,0,0,0,0
0,0,0,0,0,0,0,54,55,54,54,55,74,54,71,55,0,0,0,0,0,0,0,0,0,0,0
0,0,0,0,0,0,0,54,0,0,21,74,77,77,77,3,0,0,0,0,0,0,0,0,0,0,0
0,0,0,0,0,0,0,71,0,0,77,77,77,77,77,71,0,0,0,0,0,0,0,0,0,0,0
0,0,0,0,0,0,0,3,0,0,77,77,0,77,77,74,0,0,0,0,0,0,0,0,0,0,0
0,0,0,0,0,0,0,3,0,77,77,77,77,77,77,74,0,0,0,0,0,0,0,0,0,0,0
0,0,0,0,0,0,0,55,77,77,77,77,77,0,77,3,0,0,0,0,0,0,0,0,0,0,0
0,0,0,0,0,0,0,3,77,77,77,77,77,77,77,54,0,0,0,0,0,0,0,0,0,0,0
0,0,0,0,0,0,0,74,77,77,77,77,77,77,77,71,0,0,0,0,0,0,0,0,0,0,0
0,0,0,0,0,0,0,54,71,54,55,54,55,3,55,74,0,0,0,0,0,0,0,0,0,0,0
0,0,0,0,0,0,0,0,0,0,0,0,0,0,0,0,0,0,0,0,0,0,0,0,0,0,0
0,0,0,0,0,0,0,0,0,0,0,0,0,0,0,0,0,0,0,0,0,0,0,0,0,0,0
0,0,0,0,0,0,0,0,0,0,0,0,0,0,0,0,0,0,0,0,0,0,0,0,0,0,0
0,0,0,0,0,0,0,0,0,0,0,0,0,0,0,0,0,0,0,0,0,0,0,0,0,0,0
:endlayer
layer: 23
0,0,0,0,0,0,0,0,0,0,0,0,0,0,0,0,0,0,0,0,0,0,0,0,0,0,0
0,0,0,0,0,0,0,0,0,0,0,0,0,0,0,0,0,0,0,0,0,0,0,0,0,0,0
0,0,0,0,0,0,0,0,0,0,0,0,0,0,0,0,0,0,0,0,0,0,0,0,0,0,0
0,0,0,0,0,0,0,0,0,0,0,0,0,0,0,0,0,0,0,0,0,0,0,0,0,0,0
0,0,0,0,0,0,0,0,0,0,0,0,0,0,0,0,0,0,0,0,0,0,0,0,0,0,0
0,0,0,0,0,0,0,0,0,0,0,0,0,0,0,0,0,0,0,0,0,0,0,0,0,0,0
0,0,0,0,0,0,0,0,0,0,0,0,0,0,0,0,0,55,3,3,38,55,55,3,96,96,0
0,0,0,0,0,0,0,0,0,0,0,0,0,0,0,0,3,3,3,3,3,3,77,3,96,96,0
0,0,0,0,0,0,0,0,0,0,0,0,0,0,0,0,3,3,3,3,3,3,3,3,0,0,0
0,0,0,0,0,0,0,0,0,0,0,0,0,0,0,3,3,3,3,3,3,3,3,55,0,0,0
0,0,0,0,0,0,0,0,0,0,0,0,0,0,53,3,3,3,3,3,3,3,3,55,0,0,0
0,0,0,0,0,0,0,0,0,0,0,0,0,0,3,3,3,3,3,3,3,3,77,55,0,0,0
0,0,0,0,0,0,0,0,0,0,0,0,0,0,73,3,3,3,3,3,3,3,77,75,0,0,0
0,0,0,0,0,0,0,0,0,0,0,0,0,0,0,3,3,3,3,3,3,77,3,0,0,0,0
0,0,0,0,0,0,0,0,0,0,0,0,0,0,0,0,55,3,3,3,3,30,0,0,0,0,0
0,0,0,0,0,0,0,0,0,0,0,0,0,0,0,0,0,73,3,30,3,0,0,0,0,0,0
0,0,0,0,0,0,0,0,0,0,0,0,0,0,0,0,0,0,0,0,0,0,0,0,0,0,0
0,0,0,0,0,0,0,0,0,0,0,0,0,0,0,0,0,0,0,0,0,0,0,0,0,0,0
0,0,0,0,0,0,0,0,0,0,0,0,0,0,0,0,0,0,0,0,0,0,0,0,0,0,0
0,0,0,0,0,0,0,0,0,0,0,0,0,0,0,0,0,0,0,0,0,0,0,0,0,0,0
0,0,0,0,0,0,0,0,0,0,0,0,0,0,0,0,0,0,0,0,0,0,0,0,0,0,0
0,0,0,0,0,0,0,0,0,0,0,0,0,0,0,0,0,0,0,0,0,0,0,0,0,0,0
0,0,0,0,0,0,0,0,0,0,0,0,0,0,0,0,0,0,0,0,0,0,0,0,0,0,0
0,0,0,0,0,0,0,0,0,0,0,0,0,0,0,0,0,0,0,0,0,0,0,0,0,0,0
0,0,0,0,0,0,0,0,0,0,0,0,0,0,0,0,0,0,0,0,0,0,0,0,0,0,0
0,0,0,0,0,0,0,0,0,0,0,0,0,0,0,0,0,0,0,0,0,0,0,0,0,0,0
0,0,0,0,0,0,0,74,71,3,55,55,3,55,74,0,0,0,0,0,0,0,0,0,0,0,0
0,0,0,0,0,0,0,108,0,0,0,0,0,0,0,3,0,0,0,0,0,0,0,0,0,0,0
0,0,0,0,0,0,0,3,0,0,0,0,0,0,0,101,0,0,0,0,0,0,0,0,0,0,0
0,0,0,0,0,0,0,71,0,0,0,0,0,104,0,55,0,0,0,0,0,0,0,0,0,0,0
0,0,0,0,0,0,0,55,0,0,0,0,0,0,0,54,0,0,0,0,0,0,0,0,0,0,0
0,0,0,0,0,0,0,109,0,0,107,106,0,0,0,102,0,0,0,0,0,0,0,0,0,0,0
0,0,0,0,0,0,0,3,0,0,0,0,0,0,0,3,0,0,0,0,0,0,0,0,0,0,0
0,0,0,0,0,0,0,55,0,0,0,0,0,0,103,3,0,0,0,0,0,0,0,0,0,0,0
0,0,0,0,0,0,0,55,74,55,3,55,105,55,71,3,0,0,0,0,0,0,0,0,0,0,0
0,0,0,0,0,0,0,0,0,0,0,0,0,0,0,0,0,0,0,0,0,0,0,0,0,0,0
0,0,0,0,0,0,0,0,0,0,0,0,0,0,0,0,0,0,0,0,0,0,0,0,0,0,0
0,0,0,0,0,0,0,0,0,0,0,0,0,0,0,0,0,0,0,0,0,0,0,0,0,0,0
0,0,0,0,0,0,0,0,0,0,0,0,0,0,0,0,0,0,0,0,0,0,0,0,0,0,0
:endlayer
layer: 24
0,0,0,0,0,0,0,0,0,0,0,0,0,0,0,0,0,0,0,0,0,0,0,0,0,0,0
0,0,0,0,0,0,0,0,0,0,0,0,0,0,0,0,0,0,0,0,0,0,0,0,0,0,0
0,0,0,0,0,0,0,0,0,0,0,0,0,0,0,0,0,0,0,0,0,0,0,0,0,0,0
0,0,0,0,0,0,0,0,0,0,0,0,0,0,0,0,0,0,0,0,0,0,0,0,0,0,0
0,0,0,0,0,0,0,0,0,0,0,0,0,0,0,0,0,0,0,0,0,0,0,0,0,0,0
0,0,0,0,0,0,0,0,0,0,0,0,0,0,0,0,0,0,0,0,5,0,0,0,0,0,0
0,0,0,0,0,0,0,0,0,0,0,0,0,0,0,0,53,55,55,3,3,53,55,110,0,0,0
0,0,0,0,0,0,0,0,0,0,0,0,0,0,0,0,3,3,95,96,96,96,52,0,0,0,0
0,0,0,0,0,0,0,0,0,0,0,0,0,0,0,0,3,3,96,96,96,96,3,55,0,0,0
0,0,0,0,0,0,0,0,0,0,0,0,0,0,0,3,3,3,112,96,96,112,96,55,0,0,0
0,0,0,0,0,0,0,0,0,0,0,0,0,0,76,0,119,117,0,0,0,0,0,3,5,0,0
0,0,0,0,0,0,0,0,0,0,0,0,0,0,3,12,0,118,0,78,0,0,111,3,0,0,0
0,0,0,0,0,0,0,0,0,0,0,0,0,0,3,13,120,32,0,0,0,113,8,3,0,0,0
0,0,0,0,0,0,0,0,0,0,0,0,0,0,0,30,3,33,116,0,115,114,3,0,0,0,0
0,0,0,0,0,0,0,0,0,0,0,0,0,0,0,0,55,3,96,96,96,3,0,0,0,0,0
0,0,0,0,0,0,0,0,0,0,0,0,0,0,0,0,0,3,3,3,3,0,0,0,0,0,0
0,0,0,0,0,0,0,0,0,0,0,0,0,0,0,0,0,0,0,0,0,0,0,0,0,0,0
0,0,0,0,0,0,0,0,0,0,0,0,0,0,0,0,0,0,0,0,0,0,0,0,0,0,0
0,0,0,0,0,0,0,0,0,0,0,0,0,0,0,0,0,0,0,0,0,0,0,0,0,0,0
0,0,0,0,0,0,0,0,0,0,0,0,0,0,0,0,0,0,0,0,0,0,0,0,0,0,0
0,0,0,0,0,0,0,0,0,0,0,0,0,0,0,0,0,0,0,0,0,0,0,0,0,0,0
0,0,0,0,0,0,0,0,0,0,0,0,0,0,0,0,0,0,0,0,0,0,0,0,0,0,0
0,0,0,0,0,0,0,0,0,0,0,0,0,0,0,0,0,0,0,0,0,0,0,0,0,0,0
0,0,0,0,0,0,0,0,0,0,0,0,0,0,0,0,0,0,0,0,0,0,0,0,0,0,0
0,0,0,0,0,0,0,0,0,0,0,0,0,0,0,0,0,0,0,0,0,0,0,0,0,0,0
0,0,0,0,0,0,0,0,0,0,0,0,0,0,0,0,0,0,0,0,0,0,0,0,0,0,0
0,0,0,0,0,0,0,54,71,54,3,54,71,54,0,0,0,0,0,0,0,0,0,0,0,0,0
0,0,0,0,0,0,0,0,0,0,0,0,0,0,0,55,0,0,0,0,0,0,0,0,0,0,0
0,0,0,0,0,0,0,54,0,0,0,0,0,0,0,0,0,0,0,0,0,0,0,0,0,0,0
0,0,0,0,0,0,0,74,0,0,0,0,0,0,0,54,0,0,0,0,0,0,0,0,0,0,0
0,0,0,0,0,0,0,3,0,0,0,0,0,0,0,74,0,0,0,0,0,0,0,0,0,0,0
0,0,0,0,0,0,0,0,0,0,0,0,0,0,0,0,0,0,0,0,0,0,0,0,0,0,0
0,0,0,0,0,0,0,74,0,0,0,0,0,0,0,55,0,0,0,0,0,0,0,0,0,0,0
0,0,0,0,0,0,0,0,0,0,0,0,0,0,0,74,0,0,0,0,0,0,0,0,0,0,0
0,0,0,0,0,0,0,71,71,55,54,71,0,71,55,54,0,0,0,0,0,0,0,0,0,0,0
0,0,0,0,0,0,0,0,0,0,0,0,0,0,0,0,0,0,0,0,0,0,0,0,0,0,0
0,0,0,0,0,0,0,0,0,0,0,0,0,0,0,0,0,0,0,0,0,0,0,0,0,0,0
0,0,0,0,0,0,0,0,0,0,0,0,0,0,0,0,0,0,0,0,0,0,0,0,0,0,0
0,0,0,0,0,0,0,0,0,0,0,0,0,0,0,0,0,0,0,0,0,0,0,0,0,0,0
:endlayer
layer: 25
0,0,0,0,0,0,0,0,0,0,0,0,0,0,0,0,0,0,0,0,0,0,0,0,0,0,0
0,0,0,0,0,0,0,0,0,0,0,0,0,0,0,0,0,0,0,0,0,0,0,0,0,0,0
0,0,0,0,0,0,0,0,0,0,0,0,0,0,0,0,0,0,0,0,0,0,0,0,0,0,0
0,0,0,0,0,0,0,0,0,0,0,0,0,0,0,0,0,0,0,0,0,0,0,0,0,0,0
0,0,0,0,0,0,0,0,0,0,0,0,0,0,0,0,0,0,0,0,0,0,0,0,0,0,0
0,0,0,0,0,0,0,0,0,0,0,0,0,0,0,0,0,0,0,76,57,75,0,0,0,0,0
0,0,0,0,0,0,0,0,0,0,0,0,0,0,0,0,76,38,55,3,3,3,55,0,0,0,0
0,0,0,0,0,0,0,0,0,0,0,0,0,0,0,0,3,3,96,0,0,0,0,0,0,0,0
0,0,0,0,0,0,0,0,0,0,0,0,0,0,0,53,3,3,96,0,0,0,3,3,48,0,0
0,0,0,0,0,0,0,0,0,0,0,0,0,0,0,3,3,3,96,0,0,0,0,3,53,0,0
0,0,0,0,0,0,0,0,0,0,0,0,0,0,3,0,0,0,0,0,0,112,0,3,3,0,0
0,0,0,0,0,0,0,0,0,0,0,0,0,0,3,0,0,0,0,0,0,0,0,3,73,0,0
0,0,0,0,0,0,0,0,0,0,0,0,0,0,21,0,0,0,0,0,0,0,0,75,0,0,0
0,0,0,0,0,0,0,0,0,0,0,0,0,0,0,55,3,0,0,0,0,0,3,0,0,0,0
0,0,0,0,0,0,0,0,0,0,0,0,0,0,0,0,55,3,96,96,96,3,0,0,0,0,0
0,0,0,0,0,0,0,0,0,0,0,0,0,0,0,0,0,3,30,3,3,0,0,0,0,0,0
0,0,0,0,0,0,0,0,0,0,0,0,0,0,0,0,0,0,0,0,0,0,0,0,0,0,0
0,0,0,0,0,0,0,0,0,0,0,0,0,0,0,0,0,0,0,0,0,0,0,0,0,0,0
0,0,0,0,0,0,0,0,0,0,0,0,0,0,0,0,0,0,0,0,0,0,0,0,0,0,0
0,0,0,0,0,0,0,0,0,0,0,0,0,0,0,0,0,0,0,0,0,0,0,0,0,0,0
0,0,0,0,0,0,0,0,0,0,0,0,0,0,0,0,0,0,0,0,0,0,0,0,0,0,0
0,0,0,0,0,0,0,0,0,0,0,0,0,0,0,0,0,0,0,0,0,0,0,0,0,0,0
0,0,0,0,0,0,0,0,0,0,0,0,0,0,0,0,0,0,0,0,0,0,0,0,0,0,0
0,0,0,0,0,0,0,0,0,0,0,0,0,0,0,0,0,0,0,0,0,0,0,0,0,0,0
0,0,0,0,0,0,0,0,0,0,0,0,0,0,0,0,0,0,0,0,0,0,0,0,0,0,0
0,0,0,0,0,0,0,0,0,0,0,0,0,0,0,0,0,0,0,0,0,0,0,0,0,0,0
0,0,0,0,0,0,0,54,0,121,71,3,54,74,0,0,0,0,0,0,0,0,0,0,0,0,0
0,0,0,0,0,0,0,0,0,0,0,0,0,0,0,55,0,0,0,0,0,0,0,0,0,0,0
0,0,0,0,0,0,0,54,0,0,0,0,0,0,0,0,0,0,0,0,0,0,0,0,0,0,0
0,0,0,0,0,0,0,3,0,0,0,0,0,0,0,55,0,0,0,0,0,0,0,0,0,0,0
0,0,0,0,0,0,0,0,0,0,0,0,0,0,0,54,0,0,0,0,0,0,0,0,0,0,0
0,0,0,0,0,0,0,0,0,0,0,0,0,0,0,0,0,0,0,0,0,0,0,0,0,0,0
0,0,0,0,0,0,0,3,0,0,0,0,0,0,0,71,0,0,0,0,0,0,0,0,0,0,0
0,0,0,0,0,0,0,0,0,0,0,0,0,0,0,55,0,0,0,0,0,0,0,0,0,0,0
0,0,0,0,0,0,0,0,55,74,71,55,0,0,71,74,0,0,0,0,0,0,0,0,0,0,0
0,0,0,0,0,0,0,0,0,0,0,0,0,0,0,0,0,0,0,0,0,0,0,0,0,0,0
0,0,0,0,0,0,0,0,0,0,0,0,0,0,0,0,0,0,0,0,0,0,0,0,0,0,0
0,0,0,0,0,0,0,0,0,0,0,0,0,0,0,0,0,0,0,0,0,0,0,0,0,0,0
0,0,0,0,0,0,0,0,0,0,0,0,0,0,0,0,0,0,0,0,0,0,0,0,0,0,0
:endlayer
layer: 26
0,0,0,0,0,0,0,0,0,0,0,0,0,0,0,0,0,0,0,0,0,0,0,0,0,0,0
0,0,0,0,0,0,0,0,0,0,0,0,0,0,0,0,0,0,0,0,0,0,0,0,0,0,0
0,0,0,0,0,0,0,0,0,0,0,0,0,0,0,0,0,0,0,0,0,0,0,0,0,0,0
0,0,0,0,0,0,0,0,0,0,0,0,0,0,0,0,0,0,0,0,0,0,0,0,0,0,0
0,0,0,0,0,0,0,0,0,0,0,0,0,0,0,0,0,0,0,0,0,0,0,0,0,0,0
0,0,0,0,0,0,0,0,0,0,0,0,0,0,0,0,0,0,0,3,3,3,0,0,0,0,0
0,0,0,0,0,0,0,0,0,0,0,0,0,0,0,0,3,3,55,3,3,3,3,0,0,0,0
0,0,0,0,0,0,0,0,0,0,0,0,0,0,0,53,3,3,0,0,51,0,99,0,0,0,0
0,0,0,0,0,0,0,0,0,0,0,0,0,0,0,3,3,3,48,0,0,0,3,75,0,0,0
0,0,0,0,0,0,0,0,0,0,0,0,0,0,53,3,3,3,0,0,0,0,0,3,3,0,0
0,0,0,0,0,0,0,0,0,0,0,0,0,0,3,0,0,0,0,0,0,0,43,3,14,0,0
0,0,0,0,0,0,0,0,0,0,0,0,0,0,3,48,0,0,0,0,0,112,0,3,3,0,0
0,0,0,0,0,0,0,0,0,0,0,0,0,0,3,0,0,0,0,0,0,0,0,55,0,0,0
0,0,0,0,0,0,0,0,0,0,0,0,0,0,0,55,3,46,0,0,0,46,55,0,0,0,0
0,0,0,0,0,0,0,0,0,0,0,0,0,0,0,0,30,3,96,96,96,3,0,0,0,0,0
0,0,0,0,0,0,0,0,0,0,0,0,0,0,0,0,0,3,3,3,3,0,0,0,0,0,0
0,0,0,0,0,0,0,0,0,0,0,0,0,0,0,0,0,0,0,0,0,0,0,0,0,0,0
0,0,0,0,0,0,0,0,0,0,0,0,0,0,0,0,0,0,0,0,0,0,0,0,0,0,0
0,0,0,0,0,0,0,0,0,0,0,0,0,0,0,0,0,0,0,0,0,0,0,0,0,0,0
0,0,0,0,0,0,0,0,0,0,0,0,0,0,0,0,0,0,0,0,0,0,0,0,0,0,0
0,0,0,0,0,0,0,0,0,0,0,0,0,0,0,0,0,0,0,0,0,0,0,0,0,0,0
0,0,0,0,0,0,0,0,0,0,0,0,0,0,0,0,0,0,0,0,0,0,0,0,0,0,0
0,0,0,0,0,0,0,0,0,0,0,0,0,0,0,0,0,0,0,0,0,0,0,0,0,0,0
0,0,0,0,0,0,0,0,0,0,0,0,0,0,0,0,0,0,0,0,0,0,0,0,0,0,0
0,0,0,0,0,0,0,0,0,0,0,0,0,0,0,0,0,0,0,0,0,0,0,0,0,0,0
0,0,0,0,0,0,0,0,0,0,0,0,0,0,0,0,0,0,0,0,0,0,0,0,0,0,0
0,0,0,0,0,0,0,3,0,0,0,74,74,3,0,0,0,0,0,0,0,0,0,0,0,0,0
0,0,0,0,0,0,0,0,0,0,0,0,0,0,0,3,0,0,0,0,0,0,0,0,0,0,0
0,0,0,0,0,0,0,0,0,0,0,0,0,0,0,0,0,0,0,0,0,0,0,0,0,0,0
0,0,0,0,0,0,0,55,0,0,0,0,0,0,0,0,0,0,0,0,0,0,0,0,0,0,0
0,0,0,0,0,0,0,0,0,0,0,0,0,0,0,55,0,0,0,0,0,0,0,0,0,0,0
0,0,0,0,0,0,0,0,0,0,0,0,0,0,0,0,0,0,0,0,0,0,0,0,0,0,0
0,0,0,0,0,0,0,0,0,0,0,0,0,0,0,71,0,0,0,0,0,0,0,0,0,0,0
0,0,0,0,0,0,0,0,0,0,0,0,0,0,0,0,0,0,0,0,0,0,0,0,0,0,0
0,0,0,0,0,0,0,0,71,54,3,0,0,0,0,0,0,0,0,0,0,0,0,0,0,0,0
0,0,0,0,0,0,0,0,0,0,0,0,0,0,0,0,0,0,0,0,0,0,0,0,0,0,0
0,0,0,0,0,0,0,0,0,0,0,0,0,0,0,0,0,0,0,0,0,0,0,0,0,0,0
0,0,0,0,0,0,0,0,0,0,0,0,0,0,0,0,0,0,0,0,0,0,0,0,0,0,0
0,0,0,0,0,0,0,0,0,0,0,0,0,0,0,0,0,0,0,0,0,0,0,0,0,0,0
:endlayer
layer: 27
0,0,0,0,0,0,0,0,0,0,0,0,0,0,0,0,0,0,0,0,0,0,0,0,0,0,0
0,0,0,0,0,0,0,0,0,0,0,0,0,0,0,0,0,0,0,0,0,0,0,0,0,0,0
0,0,0,0,0,0,0,0,0,0,0,0,0,0,0,0,0,0,0,0,0,0,0,0,0,0,0
0,0,0,0,0,0,0,0,0,0,0,0,0,0,0,0,0,0,0,0,0,0,0,0,0,0,0
0,0,0,0,0,0,0,0,0,0,0,0,0,0,0,0,0,0,0,0,0,0,0,0,0,0,0
0,0,0,0,0,0,0,0,0,0,0,0,0,0,0,0,0,0,0,53,3,3,0,0,0,0,0
0,0,0,0,0,0,0,0,0,0,0,0,0,0,0,0,55,3,53,3,3,3,3,0,0,0,0
0,0,0,0,0,0,0,0,0,0,0,0,0,0,0,3,3,3,0,0,0,0,3,0,0,0,0
0,0,0,0,0,0,0,0,0,0,0,0,0,0,53,3,3,3,0,0,0,0,3,3,0,0,0
0,0,0,0,0,0,0,0,0,0,0,0,0,0,3,3,3,3,0,0,0,0,0,3,3,0,0
0,0,0,0,0,0,0,0,0,0,0,0,0,0,76,3,0,0,0,0,0,0,0,3,3,0,0
0,0,0,0,0,0,0,0,0,0,0,0,0,0,3,0,0,0,0,0,0,0,0,3,3,0,0
0,0,0,0,0,0,0,0,0,0,0,0,0,0,3,0,0,0,0,0,0,112,0,3,0,0,0
0,0,0,0,0,0,0,0,0,0,0,0,0,0,0,55,3,0,0,0,0,0,55,0,0,0,0
0,0,0,0,0,0,0,0,0,0,0,0,0,0,0,0,3,3,96,96,96,55,0,0,0,0,0
0,0,0,0,0,0,0,0,0,0,0,0,0,0,0,0,0,3,3,3,73,0,0,0,0,0,0
0,0,0,0,0,0,0,0,0,0,0,0,0,0,0,0,0,0,0,0,0,0,0,0,0,0,0
0,0,0,0,0,0,0,0,0,0,0,0,0,0,0,0,0,0,0,0,0,0,0,0,0,0,0
0,0,0,0,0,0,0,0,0,0,0,0,0,0,0,0,0,0,0,0,0,0,0,0,0,0,0
0,0,0,0,0,0,0,0,0,0,0,0,0,0,0,0,0,0,0,0,0,0,0,0,0,0,0
0,0,0,0,0,0,0,0,0,0,0,0,0,0,0,0,0,0,0,0,0,0,0,0,0,0,0
0,0,0,0,0,0,0,0,0,0,0,0,0,0,0,0,0,0,0,0,0,0,0,0,0,0,0
0,0,0,0,0,0,0,0,0,0,0,0,0,0,0,0,0,0,0,0,0,0,0,0,0,0,0
0,0,0,0,0,0,0,0,0,0,0,0,0,0,0,0,0,0,0,0,0,0,0,0,0,0,0
0,0,0,0,0,0,0,0,0,0,0,0,0,0,0,0,0,0,0,0,0,0,0,0,0,0,0
0,0,0,0,0,0,0,0,0,0,0,0,0,0,0,0,0,0,0,0,0,0,0,0,0,0,0
0,0,0,0,0,0,0,0,0,0,0,0,3,54,0,0,0,0,0,0,0,0,0,0,0,0,0
0,0,0,0,0,0,0,0,0,0,0,0,0,0,0,0,0,0,0,0,0,0,0,0,0,0,0
0,0,0,0,0,0,0,0,0,0,0,0,0,0,0,0,0,0,0,0,0,0,0,0,0,0,0
0,0,0,0,0,0,0,55,0,0,0,0,0,0,0,0,0,0,0,0,0,0,0,0,0,0,0
0,0,0,0,0,0,0,0,0,0,0,0,0,0,0,54,0,0,0,0,0,0,0,0,0,0,0
0,0,0,0,0,0,0,0,0,0,0,0,0,0,0,0,0,0,0,0,0,0,0,0,0,0,0
0,0,0,0,0,0,0,0,0,0,0,0,0,0,0,3,0,0,0,0,0,0,0,0,0,0,0
0,0,0,0,0,0,0,0,0,0,0,0,0,0,0,0,0,0,0,0,0,0,0,0,0,0,0
0,0,0,0,0,0,0,0,74,0,71,0,0,0,0,0,0,0,0,0,0,0,0,0,0,0,0
0,0,0,0,0,0,0,0,0,0,0,0,0,0,0,0,0,0,0,0,0,0,0,0,0,0,0
0,0,0,0,0,0,0,0,0,0,0,0,0,0,0,0,0,0,0,0,0,0,0,0,0,0,0
0,0,0,0,0,0,0,0,0,0,0,0,0,0,0,0,0,0,0,0,0,0,0,0,0,0,0
0,0,0,0,0,0,0,0,0,0,0,0,0,0,0,0,0,0,0,0,0,0,0,0,0,0,0
:endlayer
layer: 28
0,0,0,0,0,0,0,0,0,0,0,0,0,0,0,0,0,0,0,0,0,0,0,0,0,0,0
0,0,0,0,0,0,0,0,0,0,0,0,0,0,0,0,0,0,0,0,0,0,0,0,0,0,0
0,0,0,0,0,0,0,0,0,0,0,0,0,0,0,0,0,0,0,0,0,0,0,0,0,0,0
0,0,0,0,0,0,0,0,0,0,0,0,0,0,0,0,0,0,0,0,0,0,0,0,0,0,0
0,0,0,0,0,0,0,0,0,0,0,0,0,0,0,0,0,0,0,0,0,0,0,0,0,0,0
0,0,0,0,0,0,0,0,0,0,0,0,0,0,0,0,0,0,0,3,3,38,0,0,0,0,0
0,0,0,0,0,0,0,0,0,0,0,0,0,0,0,53,55,55,3,96,96,96,3,0,0,0,0
0,0,0,0,0,0,0,0,0,0,0,0,0,0,0,3,3,3,96,96,96,96,96,3,0,0,0
0,0,0,0,0,0,0,0,0,0,0,0,0,0,3,3,3,3,123,96,123,96,122,3,3,0,0
0,0,0,0,0,0,0,0,0,0,0,0,0,0,21,3,3,3,96,96,123,96,96,3,75,0,0
0,0,0,0,0,0,0,0,0,0,0,0,0,0,3,3,96,96,96,123,123,0,96,3,3,0,0
0,0,0,0,0,0,0,0,0,0,0,0,0,0,3,96,95,96,123,123,123,0,96,3,3,0,0
0,0,0,0,0,0,0,0,0,0,0,0,0,0,3,96,96,96,96,123,96,0,96,3,0,0,0
0,0,0,0,0,0,0,0,0,0,0,0,0,0,0,55,96,96,123,96,96,96,3,0,0,0,0
0,0,0,0,0,0,0,0,0,0,0,0,0,0,0,0,3,96,57,96,96,55,0,0,0,0,0
0,0,0,0,0,0,0,0,0,0,0,0,0,0,0,0,0,73,3,3,3,0,0,0,0,0,0
0,0,0,0,0,0,0,0,0,0,0,0,0,0,0,0,0,0,0,0,0,0,0,0,0,0,0
0,0,0,0,0,0,0,0,0,0,0,0,0,0,0,0,0,0,0,0,0,0,0,0,0,0,0
0,0,0,0,0,0,0,0,0,0,0,0,0,0,0,0,0,0,0,0,0,0,0,0,0,0,0
0,0,0,0,0,0,0,0,0,0,0,0,0,0,0,0,0,0,0,0,0,0,0,0,0,0,0
0,0,0,0,0,0,0,0,0,0,0,0,0,0,0,0,0,0,0,0,0,0,0,0,0,0,0
0,0,0,0,0,0,0,0,0,0,0,0,0,0,0,0,0,0,0,0,0,0,0,0,0,0,0
0,0,0,0,0,0,0,0,0,0,0,0,0,0,0,0,0,0,0,0,0,0,0,0,0,0,0
0,0,0,0,0,0,0,0,0,0,0,0,0,0,0,0,0,0,0,0,0,0,0,0,0,0,0
0,0,0,0,0,0,0,0,0,0,0,0,0,0,0,0,0,0,0,0,0,0,0,0,0,0,0
0,0,0,0,0,0,0,0,0,0,0,0,0,0,0,0,0,0,0,0,0,0,0,0,0,0,0
0,0,0,0,0,0,0,0,0,0,0,0,55,55,0,0,0,0,0,0,0,0,0,0,0,0,0
0,0,0,0,0,0,0,0,0,0,0,0,0,0,0,0,0,0,0,0,0,0,0,0,0,0,0
0,0,0,0,0,0,0,0,0,0,0,0,0,0,0,0,0,0,0,0,0,0,0,0,0,0,0
0,0,0,0,0,0,0,55,0,0,0,0,0,0,0,0,0,0,0,0,0,0,0,0,0,0,0
0,0,0,0,0,0,0,0,0,0,0,0,0,0,0,0,0,0,0,0,0,0,0,0,0,0,0
0,0,0,0,0,0,0,0,0,0,0,0,0,0,0,0,0,0,0,0,0,0,0,0,0,0,0
0,0,0,0,0,0,0,0,0,0,0,0,0,0,0,74,0,0,0,0,0,0,0,0,0,0,0
0,0,0,0,0,0,0,0,0,0,0,0,0,0,0,0,0,0,0,0,0,0,0,0,0,0,0
0,0,0,0,0,0,0,0,74,0,54,0,0,0,0,0,0,0,0,0,0,0,0,0,0,0,0
0,0,0,0,0,0,0,0,0,0,0,0,0,0,0,0,0,0,0,0,0,0,0,0,0,0,0
0,0,0,0,0,0,0,0,0,0,0,0,0,0,0,0,0,0,0,0,0,0,0,0,0,0,0
0,0,0,0,0,0,0,0,0,0,0,0,0,0,0,0,0,0,0,0,0,0,0,0,0,0,0
0,0,0,0,0,0,0,0,0,0,0,0,0,0,0,0,0,0,0,0,0,0,0,0,0,0,0
:endlayer
layer: 29
0,0,0,0,0,0,0,0,0,0,0,0,0,0,0,0,0,0,0,0,0,0,0,0,0,0,0
0,0,0,0,0,0,0,0,0,0,0,0,0,0,0,0,0,0,0,0,0,0,0,0,0,0,0
0,0,0,0,0,0,0,0,0,0,0,0,0,0,0,0,0,0,0,0,0,0,0,0,0,0,0
0,0,0,0,0,0,0,0,0,0,0,0,0,0,0,0,0,0,0,0,0,0,0,0,0,0,0
0,0,0,0,0,0,0,0,0,0,0,0,0,0,0,0,0,0,0,0,0,0,0,0,0,0,0
0,0,0,0,0,0,0,0,0,0,0,0,0,0,0,0,0,0,0,3,3,3,0,0,0,0,0
0,0,0,0,0,0,0,0,0,0,0,0,0,0,0,3,53,55,3,0,125,0,3,0,0,0,0
0,0,0,0,0,0,0,0,0,0,0,0,0,0,53,3,3,3,0,0,0,0,0,3,0,0,0
0,0,0,0,0,0,0,0,0,0,0,0,0,0,3,3,3,3,127,0,0,0,124,3,75,0,0
0,0,0,0,0,0,0,0,0,0,0,0,0,0,3,3,3,3,0,0,0,0,0,3,3,0,0
0,0,0,0,0,0,0,0,0,0,0,0,0,0,3,3,95,0,0,0,0,0,0,3,3,0,0
0,0,0,0,0,0,0,0,0,0,0,0,0,0,76,0,0,0,0,126,0,0,0,3,3,0,0
0,0,0,0,0,0,0,0,0,0,0,0,0,0,3,0,0,0,0,0,0,0,0,75,0,0,0
0,0,0,0,0,0,0,0,0,0,0,0,0,0,0,3,0,0,0,0,0,0,3,0,0,0,0
0,0,0,0,0,0,0,0,0,0,0,0,0,0,0,0,3,129,128,0,0,55,0,0,0,0,0
0,0,0,0,0,0,0,0,0,0,0,0,0,0,0,0,0,3,3,73,55,0,0,0,0,0,0
0,0,0,0,0,0,0,0,0,0,0,0,0,0,0,0,0,0,0,0,0,0,0,0,0,0,0
0,0,0,0,0,0,0,0,0,0,0,0,0,0,0,0,0,0,0,0,0,0,0,0,0,0,0
0,0,0,0,0,0,0,0,0,0,0,0,0,0,0,0,0,0,0,0,0,0,0,0,0,0,0
0,0,0,0,0,0,0,0,0,0,0,0,0,0,0,0,0,0,0,0,0,0,0,0,0,0,0
0,0,0,0,0,0,0,0,0,0,0,0,0,0,0,0,0,0,0,0,0,0,0,0,0,0,0
0,0,0,0,0,0,0,0,0,0,0,0,0,0,0,0,0,0,0,0,0,0,0,0,0,0,0
0,0,0,0,0,0,0,0,0,0,0,0,0,0,0,0,0,0,0,0,0,0,0,0,0,0,0
0,0,0,0,0,0,0,0,0,0,0,0,0,0,0,0,0,0,0,0,0,0,0,0,0,0,0
0,0,0,0,0,0,0,0,0,0,0,0,0,0,0,0,0,0,0,0,0,0,0,0,0,0,0
0,0,0,0,0,0,0,0,0,0,0,0,0,0,0,0,0,0,0,0,0,0,0,0,0,0,0
0,0,0,0,0,0,0,0,0,0,0,0,0,74,0,0,0,0,0,0,0,0,0,0,0,0,0
0,0,0,0,0,0,0,0,0,0,0,0,0,0,0,0,0,0,0,0,0,0,0,0,0,0,0
0,0,0,0,0,0,0,0,0,0,0,0,0,0,0,0,0,0,0,0,0,0,0,0,0,0,0
0,0,0,0,0,0,0,0,0,0,0,0,0,0,0,0,0,0,0,0,0,0,0,0,0,0,0
0,0,0,0,0,0,0,0,0,0,0,0,0,0,0,0,0,0,0,0,0,0,0,0,0,0,0
0,0,0,0,0,0,0,0,0,0,0,0,0,0,0,0,0,0,0,0,0,0,0,0,0,0,0
0,0,0,0,0,0,0,0,0,0,0,0,0,0,0,55,0,0,0,0,0,0,0,0,0,0,0
0,0,0,0,0,0,0,0,0,0,0,0,0,0,0,0,0,0,0,0,0,0,0,0,0,0,0
0,0,0,0,0,0,0,0,55,0,3,0,0,0,0,0,0,0,0,0,0,0,0,0,0,0,0
0,0,0,0,0,0,0,0,0,0,0,0,0,0,0,0,0,0,0,0,0,0,0,0,0,0,0
0,0,0,0,0,0,0,0,0,0,0,0,0,0,0,0,0,0,0,0,0,0,0,0,0,0,0
0,0,0,0,0,0,0,0,0,0,0,0,0,0,0,0,0,0,0,0,0,0,0,0,0,0,0
0,0,0,0,0,0,0,0,0,0,0,0,0,0,0,0,0,0,0,0,0,0,0,0,0,0,0
:endlayer
layer: 30
0,0,0,0,0,0,0,0,0,0,0,0,0,0,0,0,0,0,0,0,0,0,0,0,0,0,0
0,0,0,0,0,0,0,0,0,0,0,0,0,0,0,0,0,0,0,0,0,0,0,0,0,0,0
0,0,0,0,0,0,0,0,0,0,0,0,0,0,0,0,0,0,0,0,0,0,0,0,0,0,0
0,0,0,0,0,0,0,0,0,0,0,0,0,0,0,0,0,0,0,0,0,0,0,0,0,0,0
0,0,0,0,0,0,0,0,0,0,0,0,0,0,0,0,0,0,0,0,0,0,0,0,0,0,0
0,0,0,0,0,0,0,0,0,0,0,0,0,0,0,0,0,0,0,3,53,3,0,0,0,0,0
0,0,0,0,0,0,0,0,0,0,0,0,0,0,0,3,3,53,3,51,0,51,3,0,0,0,0
0,0,0,0,0,0,0,0,0,0,0,0,0,0,3,3,3,3,0,0,0,0,0,3,0,0,0
0,0,0,0,0,0,0,0,0,0,0,0,0,0,76,3,3,3,48,0,0,0,124,3,3,0,0
0,0,0,0,0,0,0,0,0,0,0,0,0,0,3,3,95,3,0,0,0,0,43,3,3,0,0
0,0,0,0,0,0,0,0,0,0,0,0,0,0,55,3,0,0,0,0,0,0,0,3,3,0,0
0,0,0,0,0,0,0,0,0,0,0,0,0,0,3,48,0,0,0,0,0,0,43,3,75,0,0
0,0,0,0,0,0,0,0,0,0,0,0,0,0,76,0,0,0,0,0,0,0,0,3,0,0,0
0,0,0,0,0,0,0,0,0,0,0,0,0,0,0,3,0,0,0,0,0,0,3,0,0,0,0
0,0,0,0,0,0,0,0,0,0,0,0,0,0,0,0,3,46,0,0,46,3,0,0,0,0,0
0,0,0,0,0,0,0,0,0,0,0,0,0,0,0,0,0,3,3,55,55,0,0,0,0,0,0
0,0,0,0,0,0,0,0,0,0,0,0,0,0,0,0,0,0,0,0,0,0,0,0,0,0,0
0,0,0,0,0,0,0,0,0,0,0,0,0,0,0,0,0,0,0,0,0,0,0,0,0,0,0
0,0,0,0,0,0,0,0,0,0,0,0,0,0,0,0,0,0,0,0,0,0,0,0,0,0,0
0,0,0,0,0,0,0,0,0,0,0,0,0,0,0,0,0,0,0,0,0,0,0,0,0,0,0
0,0,0,0,0,0,0,0,0,0,0,0,0,0,0,0,0,0,0,0,0,0,0,0,0,0,0
0,0,0,0,0,0,0,0,0,0,0,0,0,0,0,0,0,0,0,0,0,0,0,0,0,0,0
0,0,0,0,0,0,0,0,0,0,0,0,0,0,0,0,0,0,0,0,0,0,0,0,0,0,0
0,0,0,0,0,0,0,0,0,0,0,0,0,0,0,0,0,0,0,0,0,0,0,0,0,0,0
0,0,0,0,0,0,0,0,0,0,0,0,0,0,0,0,0,0,0,0,0,0,0,0,0,0,0
0,0,0,0,0,0,0,0,0,0,0,0,0,0,0,0,0,0,0,0,0,0,0,0,0,0,0
0,0,0,0,0,0,0,0,0,0,0,0,0,0,0,0,0,0,0,0,0,0,0,0,0,0,0
0,0,0,0,0,0,0,0,0,0,0,0,0,0,0,0,0,0,0,0,0,0,0,0,0,0,0
0,0,0,0,0,0,0,0,0,0,0,0,0,0,0,0,0,0,0,0,0,0,0,0,0,0,0
0,0,0,0,0,0,0,0,0,0,0,0,0,0,0,0,0,0,0,0,0,0,0,0,0,0,0
0,0,0,0,0,0,0,0,0,0,0,0,0,0,0,0,0,0,0,0,0,0,0,0,0,0,0
0,0,0,0,0,0,0,0,0,0,0,0,0,0,0,0,0,0,0,0,0,0,0,0,0,0,0
0,0,0,0,0,0,0,0,0,0,0,0,0,0,0,0,0,0,0,0,0,0,0,0,0,0,0
0,0,0,0,0,0,0,0,0,0,0,0,0,0,0,0,0,0,0,0,0,0,0,0,0,0,0
0,0,0,0,0,0,0,0,0,0,0,0,0,0,0,0,0,0,0,0,0,0,0,0,0,0,0
0,0,0,0,0,0,0,0,0,0,0,0,0,0,0,0,0,0,0,0,0,0,0,0,0,0,0
0,0,0,0,0,0,0,0,0,0,0,0,0,0,0,0,0,0,0,0,0,0,0,0,0,0,0
0,0,0,0,0,0,0,0,0,0,0,0,0,0,0,0,0,0,0,0,0,0,0,0,0,0,0
0,0,0,0,0,0,0,0,0,0,0,0,0,0,0,0,0,0,0,0,0,0,0,0,0,0,0
:endlayer
layer: 31
0,0,0,0,0,0,0,0,0,0,0,0,0,0,0,0,0,0,0,0,0,0,0,0,0,0,0
0,0,0,0,0,0,0,0,0,0,0,0,0,0,0,0,0,0,0,0,0,0,0,0,0,0,0
0,0,0,0,0,0,0,0,0,0,0,0,0,0,0,0,0,0,0,0,0,0,0,0,0,0,0
0,0,0,0,0,0,0,0,0,0,0,0,0,0,0,0,0,0,0,0,0,0,0,0,0,0,0
0,0,0,0,0,0,0,0,0,0,0,0,0,0,0,0,0,0,0,0,0,0,0,0,0,0,0
0,0,0,0,0,0,0,0,0,0,0,0,0,0,0,0,0,0,0,57,57,57,0,0,0,0,0
0,0,0,0,0,0,0,0,0,0,0,0,0,0,0,3,3,3,3,123,123,123,57,0,0,0,0
0,0,0,0,0,0,0,0,0,0,0,0,0,0,3,96,96,57,123,123,0,0,123,3,0,0,0
0,0,0,0,0,0,0,0,0,0,0,0,0,0,3,96,96,57,123,0,0,0,0,96,3,0,0
0,0,0,0,0,0,0,0,0,0,0,0,0,0,3,3,0,57,0,0,0,0,0,96,3,0,0
0,0,0,0,0,0,0,0,0,0,0,0,0,0,55,3,0,0,0,0,123,123,123,96,3,0,0
0,0,0,0,0,0,0,0,0,0,0,0,0,0,55,123,0,0,0,0,123,123,123,96,3,0,0
0,0,0,0,0,0,0,0,0,0,0,0,0,0,3,123,0,0,0,123,123,123,123,57,0,0,0
0,0,0,0,0,0,0,0,0,0,0,0,0,0,0,3,123,0,123,123,123,123,57,0,0,0,0
0,0,0,0,0,0,0,0,0,0,0,0,0,0,0,0,57,123,123,123,123,57,0,0,0,0,0
0,0,0,0,0,0,0,0,0,0,0,0,0,0,0,0,0,57,73,55,57,0,0,0,0,0,0
0,0,0,0,0,0,0,0,0,0,0,0,0,0,0,0,0,0,0,0,0,0,0,0,0,0,0
0,0,0,0,0,0,0,0,0,0,0,0,0,0,0,0,0,0,0,0,0,0,0,0,0,0,0
0,0,0,0,0,0,0,0,0,0,0,0,0,0,0,0,0,0,0,0,0,0,0,0,0,0,0
0,0,0,0,0,0,0,0,0,0,0,0,0,0,0,0,0,0,0,0,0,0,0,0,0,0,0
0,0,0,0,0,0,0,0,0,0,0,0,0,0,0,0,0,0,0,0,0,0,0,0,0,0,0
0,0,0,0,0,0,0,0,0,0,0,0,0,0,0,0,0,0,0,0,0,0,0,0,0,0,0
0,0,0,0,0,0,0,0,0,0,0,0,0,0,0,0,0,0,0,0,0,0,0,0,0,0,0
0,0,0,0,0,0,0,0,0,0,0,0,0,0,0,0,0,0,0,0,0,0,0,0,0,0,0
0,0,0,0,0,0,0,0,0,0,0,0,0,0,0,0,0,0,0,0,0,0,0,0,0,0,0
0,0,0,0,0,0,0,0,0,0,0,0,0,0,0,0,0,0,0,0,0,0,0,0,0,0,0
0,0,0,0,0,0,0,0,0,0,0,0,0,0,0,0,0,0,0,0,0,0,0,0,0,0,0
0,0,0,0,0,0,0,0,0,0,0,0,0,0,0,0,0,0,0,0,0,0,0,0,0,0,0
0,0,0,0,0,0,0,0,0,0,0,0,0,0,0,0,0,0,0,0,0,0,0,0,0,0,0
0,0,0,0,0,0,0,0,0,0,0,0,0,0,0,0,0,0,0,0,0,0,0,0,0,0,0
0,0,0,0,0,0,0,0,0,0,0,0,0,0,0,0,0,0,0,0,0,0,0,0,0,0,0
0,0,0,0,0,0,0,0,0,0,0,0,0,0,0,0,0,0,0,0,0,0,0,0,0,0,0
0,0,0,0,0,0,0,0,0,0,0,0,0,0,0,0,0,0,0,0,0,0,0,0,0,0,0
0,0,0,0,0,0,0,0,0,0,0,0,0,0,0,0,0,0,0,0,0,0,0,0,0,0,0
0,0,0,0,0,0,0,0,0,0,0,0,0,0,0,0,0,0,0,0,0,0,0,0,0,0,0
0,0,0,0,0,0,0,0,0,0,0,0,0,0,0,0,0,0,0,0,0,0,0,0,0,0,0
0,0,0,0,0,0,0,0,0,0,0,0,0,0,0,0,0,0,0,0,0,0,0,0,0,0,0
0,0,0,0,0,0,0,0,0,0,0,0,0,0,0,0,0,0,0,0,0,0,0,0,0,0,0
0,0,0,0,0,0,0,0,0,0,0,0,0,0,0,0,0,0,0,0,0,0,0,0,0,0,0
:endlayer
layer: 32
0,0,0,0,0,0,0,0,0,0,0,0,0,0,0,0,0,0,0,0,0,0,0,0,0,0,0
0,0,0,0,0,0,0,0,0,0,0,0,0,0,0,0,0,0,0,0,0,0,0,0,0,0,0
0,0,0,0,0,0,0,0,0,0,0,0,0,0,0,0,0,0,0,0,0,0,0,0,0,0,0
0,0,0,0,0,0,0,0,0,0,0,0,0,0,0,0,0,0,0,0,0,0,0,0,0,0,0
0,0,0,0,0,0,0,0,0,0,0,0,0,0,0,0,0,0,0,0,0,0,0,0,0,0,0
0,0,0,0,0,0,0,0,0,0,0,0,0,0,0,0,0,0,0,57,0,53,0,0,0,0,0
0,0,0,0,0,0,0,0,0,0,0,0,0,0,0,52,57,3,57,0,0,0,3,0,0,0,0
0,0,0,0,0,0,0,0,0,0,0,0,0,0,0,0,0,0,0,0,0,0,0,57,0,0,0
0,0,0,0,0,0,0,0,0,0,0,0,0,0,0,0,43,57,0,0,0,0,0,0,52,0,0
0,0,0,0,0,0,0,0,0,0,0,0,0,0,52,57,0,57,0,0,0,0,0,0,0,0,0
0,0,0,0,0,0,0,0,0,0,0,0,0,0,76,3,0,0,0,0,0,0,0,0,130,0,0
0,0,0,0,0,0,0,0,0,0,0,0,0,0,0,0,0,0,0,0,0,131,0,0,52,0,0
0,0,0,0,0,0,0,0,0,0,0,0,0,0,0,0,0,0,0,0,0,0,0,52,0,0,0
0,0,0,0,0,0,0,0,0,0,0,0,0,0,0,3,0,0,0,0,132,0,57,0,0,0,0
0,0,0,0,0,0,0,0,0,0,0,0,0,0,0,0,133,0,0,0,0,0,0,0,0,0,0
0,0,0,0,0,0,0,0,0,0,0,0,0,0,0,0,0,0,57,55,57,0,0,0,0,0,0
0,0,0,0,0,0,0,0,0,0,0,0,0,0,0,0,0,0,0,0,0,0,0,0,0,0,0
0,0,0,0,0,0,0,0,0,0,0,0,0,0,0,0,0,0,0,0,0,0,0,0,0,0,0
0,0,0,0,0,0,0,0,0,0,0,0,0,0,0,0,0,0,0,0,0,0,0,0,0,0,0
0,0,0,0,0,0,0,0,0,0,0,0,0,0,0,0,0,0,0,0,0,0,0,0,0,0,0
0,0,0,0,0,0,0,0,0,0,0,0,0,0,0,0,0,0,0,0,0,0,0,0,0,0,0
0,0,0,0,0,0,0,0,0,0,0,0,0,0,0,0,0,0,0,0,0,0,0,0,0,0,0
0,0,0,0,0,0,0,0,0,0,0,0,0,0,0,0,0,0,0,0,0,0,0,0,0,0,0
0,0,0,0,0,0,0,0,0,0,0,0,0,0,0,0,0,0,0,0,0,0,0,0,0,0,0
0,0,0,0,0,0,0,0,0,0,0,0,0,0,0,0,0,0,0,0,0,0,0,0,0,0,0
0,0,0,0,0,0,0,0,0,0,0,0,0,0,0,0,0,0,0,0,0,0,0,0,0,0,0
0,0,0,0,0,0,0,0,0,0,0,0,0,0,0,0,0,0,0,0,0,0,0,0,0,0,0
0,0,0,0,0,0,0,0,0,0,0,0,0,0,0,0,0,0,0,0,0,0,0,0,0,0,0
0,0,0,0,0,0,0,0,0,0,0,0,0,0,0,0,0,0,0,0,0,0,0,0,0,0,0
0,0,0,0,0,0,0,0,0,0,0,0,0,0,0,0,0,0,0,0,0,0,0,0,0,0,0
0,0,0,0,0,0,0,0,0,0,0,0,0,0,0,0,0,0,0,0,0,0,0,0,0,0,0
0,0,0,0,0,0,0,0,0,0,0,0,0,0,0,0,0,0,0,0,0,0,0,0,0,0,0
0,0,0,0,0,0,0,0,0,0,0,0,0,0,0,0,0,0,0,0,0,0,0,0,0,0,0
0,0,0,0,0,0,0,0,0,0,0,0,0,0,0,0,0,0,0,0,0,0,0,0,0,0,0
0,0,0,0,0,0,0,0,0,0,0,0,0,0,0,0,0,0,0,0,0,0,0,0,0,0,0
0,0,0,0,0,0,0,0,0,0,0,0,0,0,0,0,0,0,0,0,0,0,0,0,0,0,0
0,0,0,0,0,0,0,0,0,0,0,0,0,0,0,0,0,0,0,0,0,0,0,0,0,0,0
0,0,0,0,0,0,0,0,0,0,0,0,0,0,0,0,0,0,0,0,0,0,0,0,0,0,0
0,0,0,0,0,0,0,0,0,0,0,0,0,0,0,0,0,0,0,0,0,0,0,0,0,0,0
:endlayer
layer: 33
0,0,0,0,0,0,0,0,0,0,0,0,0,0,0,0,0,0,0,0,0,0,0,0,0,0,0
0,0,0,0,0,0,0,0,0,0,0,0,0,0,0,0,0,0,0,0,0,0,0,0,0,0,0
0,0,0,0,0,0,0,0,0,0,0,0,0,0,0,0,0,0,0,0,0,0,0,0,0,0,0
0,0,0,0,0,0,0,0,0,0,0,0,0,0,0,0,0,0,0,0,0,0,0,0,0,0,0
0,0,0,0,0,0,0,0,0,0,0,0,0,0,0,0,0,0,0,0,0,0,0,0,0,0,0
0,0,0,0,0,0,0,0,0,0,0,0,0,0,0,0,0,0,0,57,3,3,0,0,0,0,0
0,0,0,0,0,0,0,0,0,0,0,0,0,0,0,0,0,52,52,0,0,0,52,0,0,0,0
0,0,0,0,0,0,0,0,0,0,0,0,0,0,0,0,0,52,0,0,0,0,0,0,0,0,0
0,0,0,0,0,0,0,0,0,0,0,0,0,0,0,0,0,57,0,0,0,0,0,0,0,0,0
0,0,0,0,0,0,0,0,0,0,0,0,0,0,0,0,0,52,0,0,0,0,0,0,0,0,0
0,0,0,0,0,0,0,0,0,0,0,0,0,0,3,3,0,0,0,0,0,0,0,0,0,0,0
0,0,0,0,0,0,0,0,0,0,0,0,0,0,0,0,0,0,0,0,0,0,0,0,0,0,0
0,0,0,0,0,0,0,0,0,0,0,0,0,0,0,0,0,0,0,0,0,0,0,0,0,0,0
0,0,0,0,0,0,0,0,0,0,0,0,0,0,0,55,0,0,0,0,0,0,0,0,0,0,0
0,0,0,0,0,0,0,0,0,0,0,0,0,0,0,0,0,0,0,0,0,0,0,0,0,0,0
0,0,0,0,0,0,0,0,0,0,0,0,0,0,0,0,0,0,52,57,57,0,0,0,0,0,0
0,0,0,0,0,0,0,0,0,0,0,0,0,0,0,0,0,0,0,0,0,0,0,0,0,0,0
0,0,0,0,0,0,0,0,0,0,0,0,0,0,0,0,0,0,0,0,0,0,0,0,0,0,0
0,0,0,0,0,0,0,0,0,0,0,0,0,0,0,0,0,0,0,0,0,0,0,0,0,0,0
0,0,0,0,0,0,0,0,0,0,0,0,0,0,0,0,0,0,0,0,0,0,0,0,0,0,0
0,0,0,0,0,0,0,0,0,0,0,0,0,0,0,0,0,0,0,0,0,0,0,0,0,0,0
0,0,0,0,0,0,0,0,0,0,0,0,0,0,0,0,0,0,0,0,0,0,0,0,0,0,0
0,0,0,0,0,0,0,0,0,0,0,0,0,0,0,0,0,0,0,0,0,0,0,0,0,0,0
0,0,0,0,0,0,0,0,0,0,0,0,0,0,0,0,0,0,0,0,0,0,0,0,0,0,0
0,0,0,0,0,0,0,0,0,0,0,0,0,0,0,0,0,0,0,0,0,0,0,0,0,0,0
0,0,0,0,0,0,0,0,0,0,0,0,0,0,0,0,0,0,0,0,0,0,0,0,0,0,0
0,0,0,0,0,0,0,0,0,0,0,0,0,0,0,0,0,0,0,0,0,0,0,0,0,0,0
0,0,0,0,0,0,0,0,0,0,0,0,0,0,0,0,0,0,0,0,0,0,0,0,0,0,0
0,0,0,0,0,0,0,0,0,0,0,0,0,0,0,0,0,0,0,0,0,0,0,0,0,0,0
0,0,0,0,0,0,0,0,0,0,0,0,0,0,0,0,0,0,0,0,0,0,0,0,0,0,0
0,0,0,0,0,0,0,0,0,0,0,0,0,0,0,0,0,0,0,0,0,0,0,0,0,0,0
0,0,0,0,0,0,0,0,0,0,0,0,0,0,0,0,0,0,0,0,0,0,0,0,0,0,0
0,0,0,0,0,0,0,0,0,0,0,0,0,0,0,0,0,0,0,0,0,0,0,0,0,0,0
0,0,0,0,0,0,0,0,0,0,0,0,0,0,0,0,0,0,0,0,0,0,0,0,0,0,0
0,0,0,0,0,0,0,0,0,0,0,0,0,0,0,0,0,0,0,0,0,0,0,0,0,0,0
0,0,0,0,0,0,0,0,0,0,0,0,0,0,0,0,0,0,0,0,0,0,0,0,0,0,0
0,0,0,0,0,0,0,0,0,0,0,0,0,0,0,0,0,0,0,0,0,0,0,0,0,0,0
0,0,0,0,0,0,0,0,0,0,0,0,0,0,0,0,0,0,0,0,0,0,0,0,0,0,0
0,0,0,0,0,0,0,0,0,0,0,0,0,0,0,0,0,0,0,0,0,0,0,0,0,0,0
:endlayer
layer: 34
0,0,0,0,0,0,0,0,0,0,0,0,0,0,0,0,0,0,0,0,0,0,0,0,0,0,0
0,0,0,0,0,0,0,0,0,0,0,0,0,0,0,0,0,0,0,0,0,0,0,0,0,0,0
0,0,0,0,0,0,0,0,0,0,0,0,0,0,0,0,0,0,0,0,0,0,0,0,0,0,0
0,0,0,0,0,0,0,0,0,0,0,0,0,0,0,0,0,0,0,0,0,0,0,0,0,0,0
0,0,0,0,0,0,0,0,0,0,0,0,0,0,0,0,0,0,0,0,0,0,0,0,0,0,0
0,0,0,0,0,0,0,0,0,0,0,0,0,0,0,0,0,0,0,0,52,0,0,0,0,0,0
0,0,0,0,0,0,0,0,0,0,0,0,0,0,0,0,0,0,0,0,0,0,0,0,0,0,0
0,0,0,0,0,0,0,0,0,0,0,0,0,0,0,0,0,0,0,0,0,0,0,0,0,0,0
0,0,0,0,0,0,0,0,0,0,0,0,0,0,0,0,0,0,0,0,0,0,0,0,0,0,0
0,0,0,0,0,0,0,0,0,0,0,0,0,0,0,0,0,0,0,0,0,0,0,0,0,0,0
0,0,0,0,0,0,0,0,0,0,0,0,0,0,57,52,0,0,0,0,0,0,0,0,0,0,0
0,0,0,0,0,0,0,0,0,0,0,0,0,0,3,0,0,0,0,0,0,0,0,0,0,0,0
0,0,0,0,0,0,0,0,0,0,0,0,0,0,57,0,0,0,0,0,0,0,0,0,0,0,0
0,0,0,0,0,0,0,0,0,0,0,0,0,0,0,0,0,0,0,0,0,0,0,0,0,0,0
0,0,0,0,0,0,0,0,0,0,0,0,0,0,0,0,0,0,0,0,0,0,0,0,0,0,0
0,0,0,0,0,0,0,0,0,0,0,0,0,0,0,0,0,0,0,52,0,0,0,0,0,0,0
0,0,0,0,0,0,0,0,0,0,0,0,0,0,0,0,0,0,0,0,0,0,0,0,0,0,0
0,0,0,0,0,0,0,0,0,0,0,0,0,0,0,0,0,0,0,0,0,0,0,0,0,0,0
0,0,0,0,0,0,0,0,0,0,0,0,0,0,0,0,0,0,0,0,0,0,0,0,0,0,0
0,0,0,0,0,0,0,0,0,0,0,0,0,0,0,0,0,0,0,0,0,0,0,0,0,0,0
0,0,0,0,0,0,0,0,0,0,0,0,0,0,0,0,0,0,0,0,0,0,0,0,0,0,0
0,0,0,0,0,0,0,0,0,0,0,0,0,0,0,0,0,0,0,0,0,0,0,0,0,0,0
0,0,0,0,0,0,0,0,0,0,0,0,0,0,0,0,0,0,0,0,0,0,0,0,0,0,0
0,0,0,0,0,0,0,0,0,0,0,0,0,0,0,0,0,0,0,0,0,0,0,0,0,0,0
0,0,0,0,0,0,0,0,0,0,0,0,0,0,0,0,0,0,0,0,0,0,0,0,0,0,0
0,0,0,0,0,0,0,0,0,0,0,0,0,0,0,0,0,0,0,0,0,0,0,0,0,0,0
0,0,0,0,0,0,0,0,0,0,0,0,0,0,0,0,0,0,0,0,0,0,0,0,0,0,0
0,0,0,0,0,0,0,0,0,0,0,0,0,0,0,0,0,0,0,0,0,0,0,0,0,0,0
0,0,0,0,0,0,0,0,0,0,0,0,0,0,0,0,0,0,0,0,0,0,0,0,0,0,0
0,0,0,0,0,0,0,0,0,0,0,0,0,0,0,0,0,0,0,0,0,0,0,0,0,0,0
0,0,0,0,0,0,0,0,0,0,0,0,0,0,0,0,0,0,0,0,0,0,0,0,0,0,0
0,0,0,0,0,0,0,0,0,0,0,0,0,0,0,0,0,0,0,0,0,0,0,0,0,0,0
0,0,0,0,0,0,0,0,0,0,0,0,0,0,0,0,0,0,0,0,0,0,0,0,0,0,0
0,0,0,0,0,0,0,0,0,0,0,0,0,0,0,0,0,0,0,0,0,0,0,0,0,0,0
0,0,0,0,0,0,0,0,0,0,0,0,0,0,0,0,0,0,0,0,0,0,0,0,0,0,0
0,0,0,0,0,0,0,0,0,0,0,0,0,0,0,0,0,0,0,0,0,0,0,0,0,0,0
0,0,0,0,0,0,0,0,0,0,0,0,0,0,0,0,0,0,0,0,0,0,0,0,0,0,0
0,0,0,0,0,0,0,0,0,0,0,0,0,0,0,0,0,0,0,0,0,0,0,0,0,0,0
0,0,0,0,0,0,0,0,0,0,0,0,0,0,0,0,0,0,0,0,0,0,0,0,0,0,0
:endlayer
layer: 35
0,0,0,0,0,0,0,0,0,0,0,0,0,0,0,0,0,0,0,0,0,0,0,0,0,0,0
0,0,0,0,0,0,0,0,0,0,0,0,0,0,0,0,0,0,0,0,0,0,0,0,0,0,0
0,0,0,0,0,0,0,0,0,0,0,0,0,0,0,0,0,0,0,0,0,0,0,0,0,0,0
0,0,0,0,0,0,0,0,0,0,0,0,0,0,0,0,0,0,0,0,0,0,0,0,0,0,0
0,0,0,0,0,0,0,0,0,0,0,0,0,0,0,0,0,0,0,0,0,0,0,0,0,0,0
0,0,0,0,0,0,0,0,0,0,0,0,0,0,0,0,0,0,0,0,0,0,0,0,0,0,0
0,0,0,0,0,0,0,0,0,0,0,0,0,0,0,0,0,0,0,0,0,0,0,0,0,0,0
0,0,0,0,0,0,0,0,0,0,0,0,0,0,0,0,0,0,0,0,0,0,0,0,0,0,0
0,0,0,0,0,0,0,0,0,0,0,0,0,0,0,0,0,0,0,0,0,0,0,0,0,0,0
0,0,0,0,0,0,0,0,0,0,0,0,0,0,0,0,0,0,0,0,0,0,0,0,0,0,0
0,0,0,0,0,0,0,0,0,0,0,0,0,0,0,0,0,0,0,0,0,0,0,0,0,0,0
0,0,0,0,0,0,0,0,0,0,0,0,0,0,52,0,0,0,0,0,0,0,0,0,0,0,0
0,0,0,0,0,0,0,0,0,0,0,0,0,0,0,0,0,0,0,0,0,0,0,0,0,0,0
0,0,0,0,0,0,0,0,0,0,0,0,0,0,0,0,0,0,0,0,0,0,0,0,0,0,0
0,0,0,0,0,0,0,0,0,0,0,0,0,0,0,0,0,0,0,0,0,0,0,0,0,0,0
0,0,0,0,0,0,0,0,0,0,0,0,0,0,0,0,0,0,0,0,0,0,0,0,0,0,0
0,0,0,0,0,0,0,0,0,0,0,0,0,0,0,0,0,0,0,0,0,0,0,0,0,0,0
0,0,0,0,0,0,0,0,0,0,0,0,0,0,0,0,0,0,0,0,0,0,0,0,0,0,0
0,0,0,0,0,0,0,0,0,0,0,0,0,0,0,0,0,0,0,0,0,0,0,0,0,0,0
0,0,0,0,0,0,0,0,0,0,0,0,0,0,0,0,0,0,0,0,0,0,0,0,0,0,0
0,0,0,0,0,0,0,0,0,0,0,0,0,0,0,0,0,0,0,0,0,0,0,0,0,0,0
0,0,0,0,0,0,0,0,0,0,0,0,0,0,0,0,0,0,0,0,0,0,0,0,0,0,0
0,0,0,0,0,0,0,0,0,0,0,0,0,0,0,0,0,0,0,0,0,0,0,0,0,0,0
0,0,0,0,0,0,0,0,0,0,0,0,0,0,0,0,0,0,0,0,0,0,0,0,0,0,0
0,0,0,0,0,0,0,0,0,0,0,0,0,0,0,0,0,0,0,0,0,0,0,0,0,0,0
0,0,0,0,0,0,0,0,0,0,0,0,0,0,0,0,0,0,0,0,0,0,0,0,0,0,0
0,0,0,0,0,0,0,0,0,0,0,0,0,0,0,0,0,0,0,0,0,0,0,0,0,0,0
0,0,0,0,0,0,0,0,0,0,0,0,0,0,0,0,0,0,0,0,0,0,0,0,0,0,0
0,0,0,0,0,0,0,0,0,0,0,0,0,0,0,0,0,0,0,0,0,0,0,0,0,0,0
0,0,0,0,0,0,0,0,0,0,0,0,0,0,0,0,0,0,0,0,0,0,0,0,0,0,0
0,0,0,0,0,0,0,0,0,0,0,0,0,0,0,0,0,0,0,0,0,0,0,0,0,0,0
0,0,0,0,0,0,0,0,0,0,0,0,0,0,0,0,0,0,0,0,0,0,0,0,0,0,0
0,0,0,0,0,0,0,0,0,0,0,0,0,0,0,0,0,0,0,0,0,0,0,0,0,0,0
0,0,0,0,0,0,0,0,0,0,0,0,0,0,0,0,0,0,0,0,0,0,0,0,0,0,0
0,0,0,0,0,0,0,0,0,0,0,0,0,0,0,0,0,0,0,0,0,0,0,0,0,0,0
0,0,0,0,0,0,0,0,0,0,0,0,0,0,0,0,0,0,0,0,0,0,0,0,0,0,0
0,0,0,0,0,0,0,0,0,0,0,0,0,0,0,0,0,0,0,0,0,0,0,0,0,0,0
0,0,0,0,0,0,0,0,0,0,0,0,0,0,0,0,0,0,0,0,0,0,0,0,0,0,0
0,0,0,0,0,0,0,0,0,0,0,0,0,0,0,0,0,0,0,0,0,0,0,0,0,0,0
:endlayer

#### RULES ####
rule:
plugin=vanillaBlocks
number=1
data:
JSON:{blockState:{blockName:"minecraft:dirt",properties:{variant:"dirt",snowy:"false"}}}
:enddata
:endrule

rule:
plugin=vanillaBlocks
number=2
data:
JSON:{blockState:{blockName:"minecraft:stone",properties:{variant:"stone"}}}
:enddata
:endrule

rule:
plugin=vanillaBlocks
number=3
data:
JSON:{blockState:{blockName:"minecraft:stonebrick",properties:{variant:"stonebrick"}}}
:enddata
:endrule

rule:
plugin=doors
number=4
data:
JSON:{blockState:{blockName:"minecraft:dark_oak_door",properties:{hinge:"left",half:"lower",powered:"false",facing:"east",open:"false"}}}
:enddata
:endrule

rule:
plugin=vanillaBlocks
number=5
data:
JSON:{blockState:{blockName:"minecraft:stone_slab",properties:{half:"top",variant:"stone_brick"}}}
:enddata
:endrule

rule:
plugin=vanillaBlocks
number=6
data:
JSON:{blockState:{blockName:"minecraft:cauldron",properties:{level:"3"}}}
:enddata
:endrule

rule:
plugin=inventory
number=7
data:
JSON:{blockState:{blockName:"minecraft:furnace",properties:{facing:"north"}},lootLevel:0,teData:{CookTime:0,BurnTime:0,Items:[],id:"minecraft:furnace",CookTimeTotal:0,Lock:""},inventoryData:{length:0,inventoryContents:[]},legacyFeatures:0b}
:enddata
:endrule

rule:
plugin=vanillaBlocks
number=8
data:
JSON:{blockState:{blockName:"minecraft:crafting_table"}}
:enddata
:endrule

rule:
plugin=inventory
number=9
data:
JSON:{blockState:{blockName:"minecraft:furnace",properties:{facing:"north"}},lootLevel:0,teData:{CookTime:0,BurnTime:0,Items:[],id:"minecraft:furnace",CookTimeTotal:0,Lock:""},inventoryData:{length:0,inventoryContents:[]},legacyFeatures:0b}
:enddata
:endrule

rule:
plugin=vanillaBlocks
number=10
data:
JSON:{blockState:{blockName:"minecraft:bookshelf"}}
:enddata
:endrule

rule:
plugin=blockTile
number=11
data:
JSON:{blockState:{blockName:"ancientwarfarestructure:advanced_spawner",properties:{transparent:"true"}},teData:{id:"ancientwarfarestructure:advanced_spawner_tile",spawnerSettings:{minDelay:0,spawnDelay:0,lightSensitive:0b,spawnGroups:[{settingsList:[{remainingSpawnCount:1,hostile:1b,forced:1b,customTag:{},maxToSpawn:1,entityId:"minecraft:vindication_illager",minToSpawn:1}],groupWeight:1}],playerRange:6,respondToRedstone:0b,inventory:{Size:9,Items:[]},spawnRange:0,transparent:1b,maxDelay:0,xpToDrop:0,mobRange:0,debugMode:0b,maxNearbyMonsters:0}}}
:enddata
:endrule

rule:
plugin=bed
number=12
data:
JSON:{blockState:{blockName:"minecraft:bed",properties:{part:"foot",facing:"south",occupied:"false"}},bedColor:14}
:enddata
:endrule

rule:
plugin=bed
number=13
data:
JSON:{blockState:{blockName:"minecraft:bed",properties:{part:"head",facing:"south",occupied:"false"}},bedColor:14}
:enddata
:endrule

rule:
plugin=vanillaBlocks
number=14
data:
JSON:{blockState:{blockName:"minecraft:stone_brick_stairs",properties:{half:"bottom",shape:"straight",facing:"west"}}}
:enddata
:endrule

rule:
plugin=blockTile
number=15
data:
JSON:{blockState:{blockName:"ancientwarfarestructure:advanced_loot_chest",properties:{facing:"west"}},teData:{LootTable:"ancientwarfare:inject/chests/simple_dungeon",lootRolls:1b,id:"ancientwarfarestructure:advanced_loot_chest_tile",Lock:"",LootTableSeed:-2542299641376180122L}}
:enddata
:endrule

rule:
plugin=blockTile
number=16
data:
JSON:{blockState:{blockName:"minecraft:enchanting_table"},teData:{id:"minecraft:enchanting_table"}}
:enddata
:endrule

rule:
plugin=blockTile
number=17
data:
JSON:{blockState:{blockName:"ancientwarfarestructure:advanced_loot_chest",properties:{facing:"north"}},teData:{LootTable:"ancientwarfare:inject/chests/simple_dungeon",lootRolls:1b,id:"ancientwarfarestructure:advanced_loot_chest_tile",Lock:"",LootTableSeed:4357214988908853350L}}
:enddata
:endrule

rule:
plugin=vanillaBlocks
number=18
data:
JSON:{blockState:{blockName:"minecraft:torch",properties:{facing:"up"}}}
:enddata
:endrule

rule:
plugin=blockTile
number=19
data:
JSON:{blockState:{blockName:"ancientwarfarestructure:advanced_spawner",properties:{transparent:"true"}},teData:{id:"ancientwarfarestructure:advanced_spawner_tile",spawnerSettings:{minDelay:0,spawnDelay:0,lightSensitive:0b,spawnGroups:[{settingsList:[{remainingSpawnCount:1,hostile:1b,forced:1b,customTag:{},maxToSpawn:1,entityId:"minecraft:evocation_illager",minToSpawn:1}],groupWeight:1}],playerRange:5,respondToRedstone:0b,inventory:{Size:9,Items:[]},spawnRange:0,transparent:1b,maxDelay:0,xpToDrop:0,mobRange:0,debugMode:0b,maxNearbyMonsters:0}}}
:enddata
:endrule

rule:
plugin=doors
number=20
data:
JSON:{blockState:{blockName:"minecraft:dark_oak_door",properties:{hinge:"left",half:"lower",powered:"false",facing:"south",open:"false"}}}
:enddata
:endrule

rule:
plugin=vanillaBlocks
number=21
data:
JSON:{blockState:{blockName:"minecraft:stone_brick_stairs",properties:{half:"bottom",shape:"straight",facing:"east"}}}
:enddata
:endrule

rule:
plugin=blockTile
number=22
data:
JSON:{blockState:{blockName:"ancientwarfarestructure:advanced_loot_chest",properties:{facing:"north"}},teData:{LootTable:"ancientwarfare:inject/chests/simple_dungeon",lootRolls:1b,id:"ancientwarfarestructure:advanced_loot_chest_tile",Lock:"",LootTableSeed:-5886530753268381242L}}
:enddata
:endrule

rule:
plugin=blockTile
number=23
data:
JSON:{blockState:{blockName:"ancientwarfarestructure:advanced_loot_chest",properties:{facing:"south"}},teData:{LootTable:"minecraft:chests/stronghold_library",lootRolls:1b,id:"ancientwarfarestructure:advanced_loot_chest_tile",Lock:"",LootTableSeed:-4103105300666086970L}}
:enddata
:endrule

rule:
plugin=inventory
number=24
data:
JSON:{blockState:{blockName:"minecraft:chest",properties:{facing:"east"}},lootLevel:0,teData:{ForgeData:{},Items:[{Slot:0b,id:"minecraft:speckled_melon",Count:12b,Damage:0s},{Slot:3b,id:"minecraft:magma_cream",Count:5b,Damage:0s},{Slot:4b,id:"minecraft:ghast_tear",Count:5b,Damage:0s},{Slot:7b,id:"minecraft:diamond",Count:1b,Damage:0s},{Slot:8b,id:"minecraft:diamond",Count:1b,Damage:0s},{Slot:10b,id:"minecraft:fermented_spider_eye",Count:6b,Damage:0s},{Slot:14b,id:"minecraft:lava_bucket",Count:1b,Damage:0s},{Slot:15b,id:"minecraft:blaze_powder",Count:5b,Damage:0s},{Slot:17b,id:"minecraft:glowstone_dust",Count:10b,Damage:0s},{Slot:18b,id:"minecraft:gunpowder",Count:14b,Damage:0s},{Slot:20b,id:"minecraft:emerald",Count:6b,Damage:0s},{Slot:21b,id:"minecraft:emerald",Count:1b,Damage:0s},{Slot:23b,id:"minecraft:dye",Count:8b,Damage:0s},{Slot:25b,id:"minecraft:gold_ingot",Count:16b,Damage:0s}],id:"minecraft:chest",Lock:""},inventoryData:{length:14,inventoryContents:[{id:"minecraft:speckled_melon",Count:12b,slot:0,Damage:0s},{id:"minecraft:magma_cream",Count:5b,slot:1,Damage:0s},{id:"minecraft:ghast_tear",Count:5b,slot:2,Damage:0s},{id:"minecraft:diamond",Count:1b,slot:3,Damage:0s},{id:"minecraft:diamond",Count:1b,slot:4,Damage:0s},{id:"minecraft:fermented_spider_eye",Count:6b,slot:5,Damage:0s},{id:"minecraft:lava_bucket",Count:1b,slot:6,Damage:0s},{id:"minecraft:blaze_powder",Count:5b,slot:7,Damage:0s},{id:"minecraft:glowstone_dust",Count:10b,slot:8,Damage:0s},{id:"minecraft:gunpowder",Count:14b,slot:9,Damage:0s},{id:"minecraft:emerald",Count:6b,slot:10,Damage:0s},{id:"minecraft:emerald",Count:1b,slot:11,Damage:0s},{id:"minecraft:dye",Count:8b,slot:12,Damage:0s},{id:"minecraft:gold_ingot",Count:16b,slot:13,Damage:0s}]},legacyFeatures:1b}
:enddata
:endrule

rule:
plugin=blockTile
number=25
data:
JSON:{blockState:{blockName:"ancientwarfarestructure:advanced_loot_chest",properties:{facing:"north"}},teData:{LootTable:"minecraft:chests/stronghold_library",lootRolls:1b,id:"ancientwarfarestructure:advanced_loot_chest_tile",Lock:"",LootTableSeed:-2914154998931224122L}}
:enddata
:endrule

rule:
plugin=doors
number=26
data:
JSON:{blockState:{blockName:"minecraft:dark_oak_door",properties:{hinge:"left",half:"lower",powered:"false",facing:"west",open:"false"}}}
:enddata
:endrule

rule:
plugin=blockTile
number=27
data:
JSON:{blockState:{blockName:"ancientwarfarestructure:advanced_spawner",properties:{transparent:"true"}},teData:{id:"ancientwarfarestructure:advanced_spawner_tile",spawnerSettings:{minDelay:0,spawnDelay:0,lightSensitive:0b,spawnGroups:[{settingsList:[{remainingSpawnCount:1,hostile:1b,forced:1b,customTag:{factionName:"brigand"},maxToSpawn:1,entityId:"ancientwarfarenpc:faction.soldier.elite",minToSpawn:1}],groupWeight:1}],playerRange:6,respondToRedstone:0b,inventory:{Size:9,Items:[]},spawnRange:0,transparent:1b,maxDelay:0,xpToDrop:0,mobRange:0,debugMode:0b,maxNearbyMonsters:0}}}
:enddata
:endrule

rule:
plugin=doors
number=28
data:
JSON:{blockState:{blockName:"minecraft:dark_oak_door",properties:{hinge:"left",half:"lower",powered:"false",facing:"north",open:"false"}}}
:enddata
:endrule

rule:
plugin=blockTile
number=29
data:
JSON:{blockState:{blockName:"ancientwarfarestructure:advanced_spawner",properties:{transparent:"true"}},teData:{id:"ancientwarfarestructure:advanced_spawner_tile",spawnerSettings:{minDelay:0,spawnDelay:0,lightSensitive:0b,spawnGroups:[{settingsList:[{remainingSpawnCount:1,hostile:1b,forced:1b,customTag:{factionName:"brigand"},maxToSpawn:1,entityId:"ancientwarfarenpc:faction.soldier.elite",minToSpawn:1}],groupWeight:1}],playerRange:6,respondToRedstone:0b,inventory:{Size:9,Items:[]},spawnRange:0,transparent:1b,maxDelay:0,xpToDrop:0,mobRange:0,debugMode:0b,maxNearbyMonsters:0}}}
:enddata
:endrule

rule:
plugin=vanillaBlocks
number=30
data:
JSON:{blockState:{blockName:"minecraft:stone_brick_stairs",properties:{half:"bottom",shape:"straight",facing:"north"}}}
:enddata
:endrule

rule:
plugin=blockTile
number=31
data:
JSON:{blockState:{blockName:"ancientwarfarestructure:advanced_spawner",properties:{transparent:"true"}},teData:{id:"ancientwarfarestructure:advanced_spawner_tile",spawnerSettings:{minDelay:0,spawnDelay:0,lightSensitive:0b,spawnGroups:[{settingsList:[{remainingSpawnCount:20,hostile:1b,forced:1b,customTag:{},maxToSpawn:20,entityId:"minecraft:bat",minToSpawn:10}],groupWeight:1}],playerRange:3,respondToRedstone:0b,inventory:{Size:9,Items:[]},spawnRange:0,transparent:1b,maxDelay:0,xpToDrop:0,mobRange:0,debugMode:0b,maxNearbyMonsters:0}}}
:enddata
:endrule

rule:
plugin=bed
number=32
data:
JSON:{blockState:{blockName:"minecraft:bed",properties:{part:"head",facing:"north",occupied:"false"}},bedColor:14}
:enddata
:endrule

rule:
plugin=bed
number=33
data:
JSON:{blockState:{blockName:"minecraft:bed",properties:{part:"foot",facing:"north",occupied:"false"}},bedColor:14}
:enddata
:endrule

rule:
plugin=blockTile
number=34
data:
JSON:{blockState:{blockName:"ancientwarfarestructure:advanced_spawner",properties:{transparent:"true"}},teData:{id:"ancientwarfarestructure:advanced_spawner_tile",spawnerSettings:{minDelay:0,spawnDelay:0,lightSensitive:0b,spawnGroups:[{settingsList:[{remainingSpawnCount:1,hostile:1b,forced:1b,customTag:{},maxToSpawn:1,entityId:"minecraft:witch",minToSpawn:1}],groupWeight:1}],playerRange:6,respondToRedstone:0b,inventory:{Size:9,Items:[]},spawnRange:0,transparent:1b,maxDelay:0,xpToDrop:0,mobRange:0,debugMode:0b,maxNearbyMonsters:0}}}
:enddata
:endrule

rule:
plugin=blockTile
number=35
data:
JSON:{blockState:{blockName:"ancientwarfarestructure:advanced_spawner",properties:{transparent:"true"}},teData:{id:"ancientwarfarestructure:advanced_spawner_tile",spawnerSettings:{minDelay:0,spawnDelay:0,lightSensitive:0b,spawnGroups:[{settingsList:[{remainingSpawnCount:1,hostile:1b,forced:1b,customTag:{},maxToSpawn:1,entityId:"minecraft:witch",minToSpawn:1}],groupWeight:1}],playerRange:6,respondToRedstone:0b,inventory:{Size:9,Items:[]},spawnRange:0,transparent:1b,maxDelay:0,xpToDrop:0,mobRange:0,debugMode:0b,maxNearbyMonsters:0}}}
:enddata
:endrule

rule:
plugin=vanillaBlocks
number=36
data:
JSON:{blockState:{blockName:"minecraft:cauldron",properties:{level:"0"}}}
:enddata
:endrule

rule:
plugin=blockTile
number=37
data:
JSON:{blockState:{blockName:"ancientwarfarestructure:advanced_spawner",properties:{transparent:"true"}},teData:{id:"ancientwarfarestructure:advanced_spawner_tile",spawnerSettings:{minDelay:0,spawnDelay:0,lightSensitive:0b,spawnGroups:[{settingsList:[{remainingSpawnCount:1,hostile:1b,forced:1b,customTag:{},maxToSpawn:1,entityId:"minecraft:witch",minToSpawn:1}],groupWeight:1}],playerRange:8,respondToRedstone:0b,inventory:{Size:9,Items:[]},spawnRange:0,transparent:1b,maxDelay:0,xpToDrop:0,mobRange:0,debugMode:0b,maxNearbyMonsters:0}}}
:enddata
:endrule

rule:
plugin=vanillaBlocks
number=38
data:
JSON:{blockState:{blockName:"minecraft:stone_brick_stairs",properties:{half:"bottom",shape:"straight",facing:"south"}}}
:enddata
:endrule

rule:
plugin=blockTile
number=39
data:
JSON:{blockState:{blockName:"ancientwarfarestructure:advanced_spawner",properties:{transparent:"true"}},teData:{id:"ancientwarfarestructure:advanced_spawner_tile",spawnerSettings:{minDelay:0,spawnDelay:0,lightSensitive:0b,spawnGroups:[{settingsList:[{remainingSpawnCount:1,hostile:1b,forced:1b,customTag:{},maxToSpawn:1,entityId:"minecraft:witch",minToSpawn:1}],groupWeight:1}],playerRange:8,respondToRedstone:0b,inventory:{Size:9,Items:[]},spawnRange:0,transparent:1b,maxDelay:0,xpToDrop:0,mobRange:0,debugMode:0b,maxNearbyMonsters:0}}}
:enddata
:endrule

rule:
plugin=doors
number=40
data:
JSON:{blockState:{blockName:"minecraft:dark_oak_door",properties:{hinge:"right",half:"upper",powered:"false",facing:"east",open:"false"}}}
:enddata
:endrule

rule:
plugin=inventory
number=41
data:
JSON:{blockState:{blockName:"minecraft:brewing_stand",properties:{has_bottle_0:"false",has_bottle_1:"false",has_bottle_2:"false"}},lootLevel:0,teData:{Fuel:0b,Items:[],id:"minecraft:brewing_stand",BrewTime:0s,Lock:""},inventoryData:{length:0,inventoryContents:[]},legacyFeatures:0b}
:enddata
:endrule

rule:
plugin=inventory
number=42
data:
JSON:{blockState:{blockName:"minecraft:brewing_stand",properties:{has_bottle_0:"false",has_bottle_1:"false",has_bottle_2:"false"}},lootLevel:0,teData:{Fuel:0b,Items:[],id:"minecraft:brewing_stand",BrewTime:0s,Lock:""},inventoryData:{length:0,inventoryContents:[]},legacyFeatures:0b}
:enddata
:endrule

rule:
plugin=vanillaBlocks
number=43
data:
JSON:{blockState:{blockName:"minecraft:torch",properties:{facing:"west"}}}
:enddata
:endrule

rule:
plugin=inventory
number=44
data:
JSON:{blockState:{blockName:"minecraft:furnace",properties:{facing:"north"}},lootLevel:0,teData:{CookTime:0,BurnTime:0,Items:[],id:"minecraft:furnace",CookTimeTotal:0,Lock:""},inventoryData:{length:0,inventoryContents:[]},legacyFeatures:0b}
:enddata
:endrule

rule:
plugin=inventory
number=45
data:
JSON:{blockState:{blockName:"minecraft:furnace",properties:{facing:"north"}},lootLevel:0,teData:{CookTime:0,BurnTime:0,Items:[],id:"minecraft:furnace",CookTimeTotal:0,Lock:""},inventoryData:{length:0,inventoryContents:[]},legacyFeatures:0b}
:enddata
:endrule

rule:
plugin=vanillaBlocks
number=46
data:
JSON:{blockState:{blockName:"minecraft:torch",properties:{facing:"north"}}}
:enddata
:endrule

rule:
plugin=doors
number=47
data:
JSON:{blockState:{blockName:"minecraft:dark_oak_door",properties:{hinge:"left",half:"upper",powered:"false",facing:"east",open:"false"}}}
:enddata
:endrule

rule:
plugin=vanillaBlocks
number=48
data:
JSON:{blockState:{blockName:"minecraft:torch",properties:{facing:"east"}}}
:enddata
:endrule

rule:
plugin=blockTile
number=49
data:
JSON:{blockState:{blockName:"ancientwarfarestructure:advanced_loot_chest",properties:{facing:"north"}},teData:{LootTable:"ancientwarfare:inject/chests/simple_dungeon",lootRolls:1b,id:"ancientwarfarestructure:advanced_loot_chest_tile",Lock:"",LootTableSeed:6923060071325756391L}}
:enddata
:endrule

rule:
plugin=blockTile
number=50
data:
JSON:{blockState:{blockName:"ancientwarfarestructure:advanced_loot_chest",properties:{facing:"north"}},teData:{LootTable:"ancientwarfare:inject/chests/simple_dungeon",lootRolls:1b,id:"ancientwarfarestructure:advanced_loot_chest_tile",Lock:"",LootTableSeed:6913145167730684326L}}
:enddata
:endrule

rule:
plugin=vanillaBlocks
number=51
data:
JSON:{blockState:{blockName:"minecraft:torch",properties:{facing:"south"}}}
:enddata
:endrule

rule:
plugin=vanillaBlocks
number=52
data:
JSON:{blockState:{blockName:"minecraft:stone_slab",properties:{half:"bottom",variant:"stone_brick"}}}
:enddata
:endrule

rule:
plugin=vanillaBlocks
number=53
data:
JSON:{blockState:{blockName:"minecraft:stone_brick_stairs",properties:{half:"top",shape:"straight",facing:"south"}}}
:enddata
:endrule

rule:
plugin=vanillaBlocks
number=54
data:
JSON:{blockState:{blockName:"minecraft:stonebrick",properties:{variant:"mossy_stonebrick"}}}
:enddata
:endrule

rule:
plugin=vanillaBlocks
number=55
data:
JSON:{blockState:{blockName:"minecraft:stonebrick",properties:{variant:"cracked_stonebrick"}}}
:enddata
:endrule

rule:
plugin=vanillaBlocks
number=56
data:
JSON:{blockState:{blockName:"minecraft:grass",properties:{snowy:"false"}}}
:enddata
:endrule

rule:
plugin=vanillaBlocks
number=57
data:
JSON:{blockState:{blockName:"minecraft:double_stone_slab",properties:{seamless:"false",variant:"stone_brick"}}}
:enddata
:endrule

rule:
plugin=vanillaBlocks
number=58
data:
JSON:{blockState:{blockName:"minecraft:tallgrass",properties:{type:"tall_grass"}}}
:enddata
:endrule

rule:
plugin=vanillaBlocks
number=59
data:
JSON:{blockState:{blockName:"minecraft:log",properties:{variant:"oak",axis:"y"}}}
:enddata
:endrule

rule:
plugin=blockTile
number=60
data:
JSON:{blockState:{blockName:"ancientwarfarestructure:advanced_spawner",properties:{transparent:"true"}},teData:{id:"ancientwarfarestructure:advanced_spawner_tile",spawnerSettings:{minDelay:0,spawnDelay:0,lightSensitive:0b,spawnGroups:[{settingsList:[{remainingSpawnCount:1,hostile:1b,forced:1b,customTag:{factionName:"brigand"},maxToSpawn:1,entityId:"ancientwarfarenpc:faction.archer",minToSpawn:1}],groupWeight:1}],playerRange:16,respondToRedstone:0b,inventory:{Size:9,Items:[]},spawnRange:0,transparent:1b,maxDelay:0,xpToDrop:0,mobRange:0,debugMode:0b,maxNearbyMonsters:0}}}
:enddata
:endrule

rule:
plugin=blockTile
number=61
data:
JSON:{blockState:{blockName:"ancientwarfarestructure:advanced_spawner",properties:{transparent:"true"}},teData:{id:"ancientwarfarestructure:advanced_spawner_tile",spawnerSettings:{minDelay:0,spawnDelay:0,lightSensitive:0b,spawnGroups:[{settingsList:[{remainingSpawnCount:1,hostile:1b,forced:1b,customTag:{factionName:"brigand"},maxToSpawn:1,entityId:"ancientwarfarenpc:faction.archer",minToSpawn:1}],groupWeight:1}],playerRange:16,respondToRedstone:0b,inventory:{Size:9,Items:[]},spawnRange:0,transparent:1b,maxDelay:0,xpToDrop:0,mobRange:0,debugMode:0b,maxNearbyMonsters:0}}}
:enddata
:endrule

rule:
plugin=vanillaBlocks
number=62
data:
JSON:{blockState:{blockName:"minecraft:gravel"}}
:enddata
:endrule

rule:
plugin=vanillaBlocks
number=63
data:
JSON:{blockState:{blockName:"minecraft:red_flower",properties:{type:"houstonia"}}}
:enddata
:endrule

rule:
plugin=vanillaBlocks
