# Ancient Warfare Structure Template File
# Auto-generated structure template file. created on: 12/25/2018 at: 22:43:5
# Lines beginning with # denote comments

header:
version=2.8
name=BrigandHideBirchSmall
mods=
size=18,17,21
offset=9,5,20
:endheader

#### VALIDATION ####
validation:
type=ground
survival=false
worldGenEnabled=true
unique=false
preserveBlocks=false
selectionWeight=30
clusterValue=30
minDuplicateDistance=500
dimensionWhiteList=true
dimensionList=0
biomeWhiteList=true
biomeList=minecraft:birch_forest,minecraft:birch_forest_hills
leveling=3
fill=0
border=0
blockSwap=false
:endvalidation

#### LAYERS ####
layer: 0
1,1,1,1,1,1,1,1,1,1,1,1,1,1,1,1,1,1
1,1,1,1,1,1,1,1,1,1,1,1,1,1,1,1,1,1
1,1,1,1,1,1,1,1,1,1,1,1,1,1,1,1,1,1
1,1,1,1,1,1,1,1,1,1,1,1,1,1,1,1,1,1
1,1,1,1,1,1,1,1,1,1,1,1,1,1,1,1,1,1
1,1,1,1,1,1,1,1,1,1,1,1,1,1,1,1,1,1
1,1,1,1,1,1,1,1,1,1,1,1,1,1,1,1,1,1
1,1,1,1,1,1,1,1,1,1,1,1,1,1,1,1,1,1
1,1,1,1,1,1,1,1,1,1,1,1,1,1,1,1,1,1
1,1,1,1,1,1,1,1,1,1,1,1,1,1,1,1,1,1
1,1,1,1,1,1,1,1,1,1,1,1,1,1,1,1,1,1
1,1,1,1,1,1,1,1,1,1,1,1,1,1,1,1,1,1
1,1,1,1,1,1,1,1,1,1,1,1,1,1,1,1,1,1
1,1,1,1,1,1,1,1,1,1,1,1,1,1,1,1,1,1
1,1,1,1,1,1,1,1,1,1,1,1,1,1,1,1,1,1
1,1,1,1,1,1,1,1,1,1,1,1,1,1,1,1,1,1
1,1,1,1,1,1,1,1,1,1,1,1,1,1,1,1,1,1
1,1,1,1,1,1,1,1,1,1,1,1,1,1,1,1,1,1
1,1,1,1,1,1,1,1,1,1,1,1,1,1,1,1,1,1
1,1,1,1,1,1,1,1,1,1,1,1,1,1,1,1,1,1
1,1,1,1,1,1,1,1,1,1,1,1,1,1,1,1,1,1
:endlayer
layer: 1
1,1,1,1,1,1,1,1,1,1,1,1,1,1,1,1,1,1
1,1,1,1,1,1,1,1,1,1,1,1,1,1,1,1,1,1
1,1,1,1,1,1,1,1,1,1,1,1,1,1,1,1,1,1
1,1,1,1,1,1,1,1,1,1,1,1,1,1,1,1,1,1
1,1,1,1,1,1,1,1,1,1,1,1,1,1,1,1,1,1
1,1,1,1,1,1,1,1,1,1,1,1,1,1,1,1,1,1
1,1,1,1,1,1,1,1,1,1,1,1,1,1,1,1,1,1
1,1,1,1,1,1,1,1,1,1,1,1,1,1,1,1,1,1
1,1,1,1,1,1,1,1,1,1,1,1,1,1,1,1,1,1
1,1,1,1,1,1,1,1,1,1,1,1,1,1,1,1,1,1
1,1,1,1,1,1,1,1,1,1,1,1,1,1,1,1,1,1
1,1,1,1,1,1,1,1,1,1,1,1,1,1,1,1,1,1
1,1,1,1,1,1,1,1,1,1,1,1,1,1,1,1,1,1
1,1,1,1,1,1,1,1,1,1,1,1,1,1,1,1,1,1
1,1,1,1,1,1,1,1,1,1,1,1,1,1,1,1,1,1
1,1,1,1,1,1,1,1,1,1,1,1,1,1,1,1,1,1
1,1,1,1,1,1,1,1,1,1,1,1,1,1,1,1,1,1
1,1,1,1,1,1,1,1,1,1,1,1,1,1,1,1,1,1
1,1,1,1,1,1,1,1,1,1,1,1,1,1,1,1,1,1
1,1,1,1,1,1,1,1,1,1,1,1,1,1,1,1,1,1
1,1,1,1,1,1,1,1,1,1,1,1,1,1,1,1,1,1
:endlayer
layer: 2
1,1,1,1,1,1,1,1,1,1,1,1,1,1,1,1,1,1
1,1,1,1,1,1,1,1,1,1,1,1,1,1,1,1,1,1
1,1,1,1,1,1,1,1,1,1,1,1,1,1,1,1,1,1
1,1,1,1,1,1,1,1,1,1,1,1,1,1,1,1,1,1
1,1,1,1,1,1,1,1,1,1,1,1,1,1,1,1,1,1
1,1,1,1,1,1,1,1,1,1,1,1,1,1,1,1,1,1
1,1,1,1,1,1,1,1,1,1,1,1,1,1,1,1,1,1
1,1,1,1,1,1,1,1,1,1,1,1,1,1,1,1,1,1
1,1,1,1,1,1,1,1,1,1,1,1,1,1,1,1,1,1
1,1,1,1,1,1,1,1,1,1,1,1,1,1,1,1,1,1
1,1,1,1,1,1,1,1,1,1,1,1,1,1,1,1,1,1
1,1,1,1,1,1,1,1,1,1,1,1,1,1,1,1,1,1
1,1,1,1,1,1,1,1,1,1,1,1,2,1,1,1,1,1
1,1,1,1,1,1,1,1,1,1,1,1,1,1,1,1,1,1
1,1,1,1,1,1,1,1,1,1,1,1,1,1,1,1,1,1
1,1,1,1,1,1,1,1,1,1,1,1,1,1,1,1,1,1
1,1,1,1,1,1,1,1,1,1,1,1,1,1,1,1,1,1
1,1,1,1,1,1,1,1,1,1,1,1,1,1,1,1,1,1
1,1,1,1,1,1,1,1,1,1,1,1,1,1,1,1,1,1
1,1,1,1,1,1,1,1,1,1,1,1,1,1,1,1,1,1
1,1,1,1,1,1,1,1,1,1,1,1,1,1,1,1,1,1
:endlayer
layer: 3
1,1,1,1,1,1,1,1,1,1,1,1,1,1,1,1,1,1
1,1,1,1,1,1,1,1,1,1,1,1,1,1,1,1,1,1
1,1,1,1,1,1,1,1,1,1,1,1,1,1,1,1,1,1
1,1,1,1,1,1,1,1,1,1,1,1,1,1,1,1,1,1
1,4,1,1,1,1,1,1,5,3,1,1,1,1,1,1,3,1
1,1,1,1,1,1,1,1,1,1,1,1,1,1,1,1,1,1
1,1,1,1,1,1,1,1,1,1,1,1,1,1,1,1,1,1
1,1,1,1,1,1,1,1,1,1,1,1,1,1,1,1,1,1
1,1,1,1,1,1,1,1,1,1,1,1,1,1,1,1,1,1
1,1,1,1,1,1,1,1,1,1,1,1,1,1,1,1,1,1
1,1,1,1,1,1,1,1,1,1,1,1,1,1,1,1,1,1
1,5,1,1,1,1,1,1,5,5,1,2,2,1,1,1,4,1
1,5,1,1,1,1,1,1,5,5,1,2,2,2,1,1,4,1
1,1,1,1,1,1,1,1,1,1,1,2,2,2,1,1,1,1
1,1,1,1,1,1,1,1,1,1,1,1,1,1,1,1,1,1
1,1,1,1,1,1,1,1,1,1,1,1,1,1,1,1,1,1
1,1,1,1,1,1,1,1,1,1,1,1,1,1,1,1,1,1
1,1,1,1,1,1,1,1,1,1,1,1,1,1,1,1,1,1
1,1,1,1,1,1,1,1,1,1,1,1,1,1,1,1,1,1
1,5,1,1,1,1,1,1,6,5,1,1,1,1,1,1,4,1
1,1,1,1,1,1,1,1,1,1,1,1,1,1,1,1,1,1
:endlayer
layer: 4
7,7,7,7,7,7,7,6,7,7,7,7,7,7,7,7,7,7
1,1,1,1,7,7,7,6,6,7,7,7,7,7,7,7,7,7
1,1,1,1,7,7,7,1,1,7,7,7,7,1,1,1,1,1
1,1,1,1,1,1,1,1,1,1,1,1,1,1,1,1,1,1
1,3,1,1,1,1,1,1,5,5,1,1,1,1,1,1,4,1
1,1,1,1,1,1,1,1,1,1,1,1,1,1,1,1,1,1
1,1,1,1,1,1,1,1,1,1,1,1,1,1,1,1,1,1
1,1,1,1,1,1,1,1,1,1,1,1,1,1,1,7,7,7
1,1,1,1,1,1,1,1,1,1,1,7,7,7,1,1,7,7
1,1,1,1,1,1,1,1,1,1,1,7,7,7,1,1,1,7
1,1,1,1,1,1,1,1,1,1,1,7,7,7,1,1,1,7
1,3,1,1,1,1,1,1,5,5,7,2,2,2,1,1,3,7
1,5,1,1,1,1,1,1,5,5,7,2,8,2,1,1,4,7
1,1,1,1,1,1,7,7,7,7,7,2,2,2,1,1,7,7
1,1,1,1,7,7,7,7,7,7,7,7,1,1,1,1,7,7
1,1,1,1,7,7,7,7,7,7,7,1,1,1,1,7,7,7
1,1,1,7,7,7,7,7,7,7,7,1,1,1,7,7,7,6
1,1,1,7,1,7,7,7,7,7,7,7,7,7,7,7,6,6
1,1,1,7,7,7,7,7,7,7,7,7,7,7,6,6,6,6
1,4,7,7,7,7,7,7,5,5,7,7,7,6,6,6,6,6
6,1,7,7,7,7,7,7,7,7,7,6,6,6,6,6,6,6
:endlayer
layer: 5
0,0,0,0,0,0,0,0,0,0,0,0,0,0,0,0,0,0
6,7,6,6,0,0,0,0,0,0,0,0,0,0,0,0,0,0
6,7,1,1,0,0,0,6,7,0,0,0,0,6,6,7,6,6
6,7,7,7,7,7,7,7,7,7,7,6,6,6,7,7,7,6
6,4,7,7,7,6,6,7,5,3,7,7,7,7,7,7,3,6
6,7,7,7,7,7,6,6,7,7,7,7,7,1,7,7,7,6
6,7,7,7,1,7,7,6,7,7,7,7,7,7,7,7,7,6
6,7,7,7,7,7,7,7,7,7,1,6,6,6,1,0,9,9
6,7,7,7,7,7,7,7,7,1,6,10,13,10,6,1,0,0
6,7,7,7,7,7,7,7,7,1,6,11,14,11,6,1,7,0
6,7,7,7,7,7,7,7,7,1,2,0,0,12,6,1,7,0
6,4,7,7,7,1,7,7,5,6,16,0,0,0,6,6,4,0
6,3,7,7,7,7,7,7,7,5,0,0,15,0,6,6,3,0
6,7,7,7,7,7,0,0,0,0,0,0,0,0,1,7,9,0
6,7,7,7,0,0,0,0,0,0,0,0,1,1,1,7,0,9
6,7,7,7,0,0,0,9,0,0,0,7,1,1,6,9,0,0
6,1,7,0,0,0,0,0,0,0,0,7,7,7,9,0,9,0
6,6,7,0,17,0,0,0,0,0,9,9,9,9,0,0,0,0
6,6,7,0,0,0,0,0,0,0,0,0,9,9,0,0,0,0
6,4,0,0,0,0,0,0,5,3,0,9,9,0,0,0,5,0
6,7,0,0,0,0,0,0,0,0,0,0,0,0,0,0,0,0
:endlayer
layer: 6
0,0,0,0,0,0,0,0,0,0,0,0,0,0,0,0,0,0
0,0,6,6,0,0,0,0,0,0,0,0,0,0,0,0,0,0
0,0,6,6,0,0,0,0,0,0,0,0,0,0,0,0,0,0
0,9,0,0,0,0,0,0,9,0,9,0,0,6,0,0,0,0
0,5,0,0,0,0,0,0,5,3,0,9,0,0,0,0,4,0
0,0,9,0,0,0,0,0,9,9,0,0,0,17,0,0,0,0
0,9,0,9,17,9,9,0,9,9,9,0,0,0,0,0,0,0
0,9,9,9,9,0,0,9,9,9,18,6,6,6,18,0,0,0
0,0,9,9,9,9,0,9,9,18,6,0,0,0,6,18,0,0
0,9,0,9,9,0,0,9,9,18,6,0,0,0,6,18,0,0
0,0,9,0,9,0,9,9,0,7,20,0,0,0,0,6,0,0
0,4,9,0,9,17,0,0,5,6,0,0,0,0,0,6,3,0
0,4,9,9,0,0,9,0,0,5,0,0,0,0,19,6,4,0
0,9,9,0,0,0,0,0,0,0,0,0,0,0,7,0,0,0
0,9,9,9,0,0,0,0,0,0,0,0,7,7,7,0,0,0
0,9,9,0,0,0,0,0,0,0,0,0,1,7,6,0,0,0
0,6,0,0,0,0,0,0,0,0,0,0,0,0,0,0,0,0
0,6,0,0,17,0,0,0,0,0,0,0,0,0,0,0,0,0
0,6,0,0,0,0,0,0,0,0,0,0,0,0,0,0,0,0
0,6,0,0,0,0,0,0,4,3,0,0,0,0,0,0,5,0
3,0,0,0,0,0,0,0,0,0,0,0,0,0,0,0,0,0
:endlayer
layer: 7
0,0,0,0,0,0,0,0,0,0,0,0,0,0,0,0,0,0
0,0,6,0,0,0,0,0,0,0,0,0,0,0,0,0,0,0
0,0,0,6,0,0,0,0,0,0,0,0,0,0,0,0,0,0
0,0,0,0,0,0,0,0,0,0,0,0,0,6,0,0,0,0
0,5,0,0,0,0,0,0,5,4,0,0,0,0,0,0,3,0
0,0,0,0,0,0,0,0,0,0,0,0,0,17,0,0,0,0
0,0,0,0,17,0,0,0,0,0,0,0,0,0,0,0,0,0
0,0,0,0,0,0,0,0,0,0,0,18,18,18,0,0,0,0
0,0,0,0,0,0,0,0,0,0,18,0,0,0,18,0,0,0
0,0,0,0,0,0,0,0,0,0,18,0,0,0,18,0,0,0
0,0,0,0,0,0,0,0,0,0,0,0,0,0,0,0,0,0
0,5,0,0,0,17,0,0,5,5,0,0,0,0,0,0,4,0
0,3,0,0,0,0,0,0,0,3,0,0,0,0,0,0,4,0
0,0,0,0,0,0,0,0,0,0,0,0,0,0,0,0,0,0
0,0,0,0,0,0,0,0,0,0,0,0,0,0,0,0,0,0
0,0,0,0,0,0,0,0,0,0,0,0,17,0,0,0,0,0
0,0,0,0,0,0,0,0,0,0,0,0,0,0,0,0,0,0
0,6,0,0,17,0,0,0,0,0,0,0,0,0,0,0,0,0
0,6,0,0,0,0,0,0,0,0,0,0,0,0,0,0,0,0
0,6,0,0,0,0,0,0,3,4,0,0,0,0,0,0,6,0
0,0,0,0,0,0,0,0,0,0,0,0,0,0,0,0,0,0
:endlayer
layer: 8
0,0,0,0,0,0,0,0,0,0,0,0,0,0,0,0,0,0
0,0,0,0,0,0,0,0,0,0,0,0,0,0,0,0,0,0
0,0,0,0,0,0,0,0,0,0,0,0,0,0,0,0,0,0
0,0,0,0,0,0,0,0,0,0,0,22,22,22,22,0,0,0
0,5,22,22,22,22,22,0,5,4,0,22,22,22,22,22,5,0
0,0,22,22,22,22,22,0,0,0,0,22,22,17,22,22,0,0
0,0,22,22,17,22,22,0,0,0,0,22,22,22,22,22,0,0
0,0,22,22,22,22,22,0,0,0,0,18,18,18,22,0,0,0
0,0,22,22,22,22,22,0,0,0,0,18,0,18,0,0,0,0
0,0,0,22,22,22,22,0,0,0,0,18,0,18,0,0,0,0
0,0,0,22,22,22,22,22,0,0,0,0,0,0,0,0,0,0
0,5,0,22,22,17,22,22,4,4,0,0,0,0,0,0,5,0
0,3,0,22,22,22,22,22,0,4,0,0,0,0,0,0,5,0
0,0,0,22,22,22,22,0,0,0,0,0,0,0,0,0,0,0
0,0,0,0,0,0,0,0,0,0,0,0,0,0,0,0,0,0
0,0,0,0,0,0,0,0,0,0,0,0,17,0,0,0,0,0
0,0,0,0,0,0,0,0,0,0,0,0,0,0,0,0,0,0
0,0,0,0,17,0,0,0,0,0,0,0,0,0,0,0,0,0
0,6,0,0,0,0,0,0,0,0,0,0,0,0,0,0,0,0
0,6,0,0,0,0,0,0,5,4,0,0,0,0,0,0,21,0
0,0,0,0,0,0,0,0,0,0,0,0,0,0,0,0,0,0
:endlayer
layer: 9
0,0,0,0,0,0,0,0,0,0,0,0,0,0,0,0,0,0
0,0,0,0,0,0,0,0,0,0,0,0,0,0,0,0,0,0
0,0,0,0,0,0,0,0,0,0,0,0,0,0,0,0,0,0
0,0,0,0,0,0,0,0,0,0,0,0,22,22,22,22,0,0
0,5,22,22,22,22,22,0,5,4,0,22,22,22,22,22,3,0
0,0,22,22,22,22,22,0,0,0,0,22,22,17,22,22,0,0
0,0,22,22,17,22,22,0,0,0,0,22,22,22,22,22,0,0
0,0,22,22,22,22,22,0,0,0,0,22,18,22,22,0,0,0
0,0,0,22,22,22,22,0,0,0,0,0,18,0,0,0,0,0
0,0,0,0,22,22,22,0,0,0,0,0,18,0,0,0,0,0
0,0,0,22,22,22,22,22,0,0,0,0,0,0,0,0,0,0
0,5,0,22,22,17,22,22,4,4,0,0,0,0,0,0,4,0
0,3,0,22,22,22,22,22,0,4,0,0,0,0,0,0,5,0
0,0,0,0,22,22,22,0,0,0,0,0,0,0,0,0,0,0
0,0,0,0,0,0,0,0,0,0,0,0,0,0,0,0,0,0
0,0,0,22,22,22,0,0,0,0,0,0,17,0,0,0,0,0
0,0,22,22,22,22,22,0,0,0,0,0,0,0,0,0,0,0
0,0,22,22,17,22,22,0,0,0,0,0,0,0,0,0,0,0
0,0,22,22,22,22,22,0,0,0,0,0,0,0,0,0,0,0
0,6,22,22,22,22,0,0,3,4,0,0,0,0,0,0,5,0
0,0,0,0,0,0,0,0,0,0,0,0,0,0,0,0,0,0
:endlayer
layer: 10
0,0,0,0,0,0,0,0,0,0,0,0,0,0,0,0,0,0
0,0,0,0,0,0,0,0,0,0,0,0,0,0,0,0,0,0
0,0,0,0,0,0,0,0,0,0,0,0,0,0,0,0,0,0
0,0,0,0,0,0,0,0,0,0,0,0,23,23,23,0,0,0
0,5,0,0,0,0,0,0,5,5,0,0,22,22,22,0,4,0
0,0,0,0,22,0,0,0,0,0,0,23,22,17,22,23,0,0
0,0,0,22,17,22,0,0,0,0,0,0,22,22,23,0,0,0
0,0,0,22,22,0,0,0,0,0,0,0,23,23,23,0,0,0
0,0,0,0,0,0,0,0,0,0,0,0,0,0,0,0,0,0
0,0,0,0,0,0,0,0,0,0,0,0,0,0,0,0,0,0
0,0,0,0,22,22,22,0,0,0,0,0,0,0,0,0,0,0
0,3,0,0,22,17,22,24,5,3,0,0,0,0,0,0,5,0
0,6,0,0,0,22,0,0,0,3,0,0,0,0,0,0,5,0
0,0,0,0,0,0,0,0,0,0,0,22,22,22,22,0,0,0
0,0,0,0,0,0,0,0,0,0,22,22,22,22,22,0,0,0
0,0,22,22,22,22,22,0,0,0,22,22,17,22,22,0,0,0
0,0,22,22,22,22,22,0,0,0,22,22,22,22,22,0,0,0
0,0,22,22,17,22,22,0,0,0,22,22,22,22,22,0,0,0
0,0,22,22,22,22,22,0,0,0,0,0,0,0,0,0,0,0
0,6,0,22,22,22,22,0,4,4,0,0,0,0,0,0,5,0
0,0,0,0,0,0,0,0,0,0,0,0,0,0,0,0,0,0
:endlayer
layer: 11
0,0,0,0,0,0,0,0,0,0,0,0,0,0,0,0,0,0
0,0,0,0,0,0,0,0,0,0,0,0,0,0,0,0,0,0
0,0,0,0,0,0,0,0,0,0,0,0,0,0,0,0,0,0
0,0,0,0,0,0,0,0,0,0,0,0,0,23,0,0,0,0
0,5,0,0,0,0,0,0,5,5,0,0,23,22,23,0,4,0
0,0,0,0,22,0,0,0,0,0,0,23,22,17,22,23,0,0
0,0,0,22,22,22,0,0,0,0,0,0,23,22,23,0,0,0
0,0,0,0,22,0,0,0,0,0,0,0,0,23,0,0,0,0
0,0,0,0,0,0,0,0,0,0,0,0,0,0,0,0,0,0
0,0,0,0,0,0,0,0,0,0,0,0,0,0,0,0,0,0
0,0,0,0,0,22,0,0,0,0,0,0,0,0,0,0,0,0
0,3,0,0,22,22,22,0,5,5,0,0,0,0,0,0,5,0
0,0,0,0,0,22,0,0,0,5,0,0,0,0,0,0,4,0
0,0,0,0,0,0,0,0,0,0,22,22,22,22,22,0,0,0
0,0,0,0,0,0,0,0,0,0,22,22,22,22,22,0,0,0
0,0,0,0,0,0,0,0,0,0,22,22,17,22,22,0,0,0
0,0,0,22,22,0,0,0,0,0,22,22,22,22,22,0,0,0
0,0,0,22,17,22,0,0,0,0,22,22,22,22,22,0,0,0
0,0,0,0,22,22,0,0,0,0,0,0,0,0,0,0,0,0
0,6,0,0,0,0,0,0,0,3,0,0,0,0,0,0,4,0
0,0,0,0,0,0,0,0,0,0,0,0,0,0,0,0,0,0
:endlayer
layer: 12
0,0,0,0,0,0,0,0,0,0,0,0,0,0,0,0,0,0
0,0,0,0,0,0,0,0,0,0,0,0,0,0,0,0,0,0
0,0,0,0,0,0,0,0,0,0,0,0,0,0,0,0,0,0
0,0,0,0,0,0,0,0,0,0,0,0,0,23,23,0,0,0
0,5,0,0,0,0,0,0,4,4,0,0,23,23,23,0,5,0
0,0,0,0,0,0,0,0,0,0,0,23,23,17,23,23,0,0
0,0,0,0,0,0,0,0,0,0,0,0,23,23,23,0,0,0
0,0,0,0,0,0,0,0,0,0,0,0,0,23,0,0,0,0
0,0,0,0,0,0,0,0,0,0,0,0,0,0,0,0,0,0
0,0,0,0,0,0,0,0,0,0,0,0,0,0,0,0,0,0
0,0,0,0,0,0,0,0,0,0,0,0,0,0,0,0,0,0
0,5,0,0,0,0,0,0,5,5,0,0,0,0,0,0,4,0
0,0,0,0,0,0,0,0,0,5,0,0,0,0,0,0,4,0
0,0,0,0,0,0,0,0,0,0,0,0,0,0,0,0,0,0
0,0,0,0,0,0,0,0,0,0,0,22,22,22,0,0,0,0
0,0,0,0,0,0,0,0,0,0,0,22,17,22,0,0,0,0
0,0,0,0,22,0,0,0,0,0,0,0,22,22,0,0,0,0
0,0,0,22,22,22,0,0,0,0,0,0,0,0,0,0,0,0
0,0,0,0,22,0,0,0,0,0,0,0,0,0,0,0,0,0
0,6,0,0,0,0,0,0,0,3,0,0,0,0,0,0,3,0
0,0,0,0,0,0,0,0,0,0,0,0,0,0,0,0,0,0
:endlayer
layer: 13
0,0,0,0,0,0,0,0,0,0,0,0,0,0,0,0,0,0
0,0,0,0,0,0,0,0,0,0,0,0,0,0,0,0,0,0
0,0,0,0,0,0,0,0,0,0,0,0,0,0,0,0,0,0
0,0,0,0,0,0,0,0,0,0,0,0,0,23,0,0,0,0
0,4,28,0,0,0,0,27,5,6,28,0,23,23,23,0,5,0
0,25,0,0,0,0,0,0,25,25,0,23,23,17,23,0,25,0
0,0,0,0,0,0,0,0,0,0,0,0,23,23,23,0,0,0
0,0,0,0,0,0,0,0,0,0,0,0,0,0,0,0,0,0
0,0,0,0,0,0,0,0,0,0,0,0,0,0,0,0,0,0
0,0,0,0,0,0,0,0,0,0,0,0,0,0,0,0,0,0
0,26,0,0,0,0,0,0,26,26,0,0,0,0,0,0,26,0
0,5,28,0,0,0,0,27,5,5,28,0,0,0,0,27,3,0
0,0,0,0,0,0,0,0,0,5,28,0,0,0,0,27,4,0
0,0,0,0,0,0,0,0,0,25,0,0,0,0,0,0,25,0
0,0,0,0,0,0,0,0,0,0,0,0,22,0,0,0,0,0
0,0,0,0,0,0,0,0,0,0,0,22,22,22,0,0,0,0
0,0,0,0,0,0,0,0,0,0,0,0,22,0,0,0,0,0
0,0,0,0,0,0,0,0,0,0,0,0,0,0,0,0,0,0
0,0,0,0,0,0,0,0,0,26,0,0,0,0,0,0,26,0
0,0,0,0,0,0,0,0,0,3,28,0,0,0,0,27,6,0
0,0,0,0,0,0,0,0,0,0,0,0,0,0,0,0,0,0
:endlayer
layer: 14
0,0,0,0,0,0,0,0,0,0,0,0,0,0,0,0,0,0
0,0,0,0,0,0,0,0,0,0,0,0,0,0,0,0,0,0
0,0,0,0,0,0,0,0,0,0,0,0,0,0,0,0,0,0
0,0,0,0,0,0,0,0,0,0,0,0,0,0,0,0,0,0
0,4,3,28,0,0,27,5,6,5,5,28,23,23,23,5,5,0
0,3,0,0,0,0,0,0,5,5,0,0,23,17,23,0,5,0
0,25,0,0,0,0,0,0,25,25,0,0,0,23,0,0,0,0
0,0,0,0,0,0,0,0,0,0,0,0,0,0,0,0,0,0
0,0,0,0,0,0,0,0,0,0,0,0,0,0,0,0,0,0
0,26,0,0,0,0,0,0,26,26,0,0,0,0,0,0,26,0
0,5,0,0,0,0,0,0,4,3,0,0,0,0,0,0,4,0
0,4,3,28,0,0,27,5,6,4,4,28,0,0,27,4,3,0
0,0,0,0,0,0,0,0,0,3,5,28,0,0,27,3,4,0
0,0,0,0,0,0,0,0,0,4,0,0,0,0,0,0,5,0
0,0,0,0,0,0,0,0,0,25,0,0,0,0,0,0,25,0
0,0,0,0,0,0,0,0,0,0,0,0,0,0,0,0,0,0
0,0,0,0,0,0,0,0,0,0,0,0,0,0,0,0,0,0
0,0,0,0,0,0,0,0,0,26,0,0,0,0,0,0,26,0
0,0,0,0,0,0,0,0,0,6,0,0,0,0,0,0,3,0
0,0,0,0,0,0,0,0,0,4,5,28,0,0,27,5,5,0
0,0,0,0,0,0,0,0,0,0,0,0,0,0,0,0,0,0
:endlayer
layer: 15
0,0,0,0,0,0,0,0,0,0,0,0,0,0,0,0,0,0
0,0,0,0,0,0,0,0,0,0,0,0,0,0,0,0,0,0
0,0,0,0,0,0,0,0,0,0,0,0,0,0,0,0,0,0
0,0,0,0,0,0,0,0,0,0,0,0,0,0,0,0,0,0
0,30,30,29,0,29,29,29,29,30,0,0,0,0,0,29,29,0
0,0,0,0,0,0,0,0,29,29,0,0,0,23,0,0,6,0
0,29,0,0,0,0,0,0,0,0,0,0,0,0,0,0,6,0
0,0,0,0,0,0,0,0,0,0,0,0,0,0,0,0,29,0
0,0,0,0,0,0,0,0,29,0,0,0,0,0,0,0,0,0
0,29,0,0,0,0,0,0,0,29,0,0,0,0,0,0,0,0
0,0,0,0,0,0,0,0,29,0,0,0,0,0,0,0,30,0
0,30,0,29,29,0,30,29,5,29,29,29,30,30,0,29,29,0
0,0,0,0,0,0,0,0,0,29,29,29,0,0,0,29,4,0
0,0,0,0,0,0,0,0,0,0,0,0,0,0,0,0,0,0
0,0,0,0,0,0,0,0,0,0,0,0,0,0,0,0,0,0
0,0,0,0,0,0,0,0,0,29,0,0,0,0,0,0,0,0
0,0,0,0,0,0,0,0,0,29,0,0,0,0,0,0,0,0
0,0,0,0,0,0,0,0,0,30,0,0,0,0,0,0,29,0
0,0,0,0,0,0,0,0,0,0,0,0,0,0,0,0,30,0
0,0,0,0,0,0,0,0,0,21,0,0,0,0,0,0,29,0
0,0,0,0,0,0,0,0,0,0,0,0,0,0,0,0,0,0
:endlayer
layer: 16
0,0,0,0,0,0,0,0,0,0,0,0,0,0,0,0,0,0
0,0,0,0,0,0,0,0,0,0,0,0,0,0,0,0,0,0
0,0,0,0,0,0,0,0,0,0,0,0,0,0,0,0,0,0
0,0,0,0,0,0,0,0,0,0,0,0,0,0,0,0,0,0
0,0,0,0,0,0,0,0,0,0,0,0,0,0,0,0,0,0
0,0,0,0,0,0,0,0,0,0,0,0,0,0,0,0,0,0
0,0,0,0,0,0,0,0,0,0,0,0,0,0,0,0,0,0
0,0,0,0,0,0,0,0,0,0,0,0,0,0,0,0,0,0
0,0,0,0,0,0,0,0,0,0,0,0,0,0,0,0,0,0
0,0,0,0,0,0,0,0,0,0,0,0,0,0,0,0,0,0
0,0,0,0,0,0,0,0,0,0,0,0,0,0,0,0,0,0
0,0,0,0,0,0,0,0,0,31,0,0,0,0,0,0,0,0
0,0,0,0,0,0,0,0,0,0,0,0,0,0,0,0,0,0
0,0,0,0,0,0,0,0,0,0,0,0,0,0,0,0,0,0
0,0,0,0,0,0,0,0,0,0,0,0,0,0,0,0,0,0
0,0,0,0,0,0,0,0,0,0,0,0,0,0,0,0,0,0
0,0,0,0,0,0,0,0,0,0,0,0,0,0,0,0,0,0
0,0,0,0,0,0,0,0,0,0,0,0,0,0,0,0,0,0
0,0,0,0,0,0,0,0,0,0,0,0,0,0,0,0,0,0
0,0,0,0,0,0,0,0,0,0,0,0,0,0,0,0,0,0
0,0,0,0,0,0,0,0,0,0,0,0,0,0,0,0,0,0
:endlayer

#### RULES ####
rule:
plugin=vanillaBlocks
number=1
data:
JSON:{blockState:{blockName:"minecraft:dirt",properties:{variant:"dirt",snowy:"false"}}}
:enddata
:endrule

rule:
plugin=vanillaBlocks
number=2
data:
JSON:{blockState:{blockName:"minecraft:cobblestone"}}
:enddata
:endrule

rule:
plugin=vanillaBlocks
number=3
data:
JSON:{blockState:{blockName:"minecraft:stonebrick",properties:{variant:"stonebrick"}}}
:enddata
:endrule

rule:
plugin=vanillaBlocks
number=4
data:
JSON:{blockState:{blockName:"minecraft:monster_egg",properties:{variant:"stone_brick"}}}
:enddata
:endrule

rule:
plugin=vanillaBlocks
number=5
data:
JSON:{blockState:{blockName:"minecraft:stonebrick",properties:{variant:"mossy_stonebrick"}}}
:enddata
:endrule

rule:
plugin=vanillaBlocks
number=6
data:
JSON:{blockState:{blockName:"minecraft:stonebrick",properties:{variant:"cracked_stonebrick"}}}
:enddata
:endrule

rule:
plugin=vanillaBlocks
number=7
data:
JSON:{blockState:{blockName:"minecraft:grass",properties:{snowy:"false"}}}
:enddata
:endrule

rule:
plugin=vanillaBlocks
number=8
data:
JSON:{blockState:{blockName:"ancientwarfarestructure:fire_pit",properties:{lit:"true",variant:"default"}}}
:enddata
:endrule

rule:
plugin=vanillaBlocks
number=9
data:
JSON:{blockState:{blockName:"minecraft:tallgrass",properties:{type:"tall_grass"}}}
:enddata
:endrule

rule:
plugin=bed
number=10
data:
JSON:{blockState:{blockName:"minecraft:bed",properties:{part:"head",facing:"north",occupied:"false"}},bedColor:14}
:enddata
:endrule

rule:
plugin=bed
number=11
data:
JSON:{blockState:{blockName:"minecraft:bed",properties:{part:"foot",facing:"north",occupied:"false"}},bedColor:14}
:enddata
:endrule

rule:
plugin=blockTile
number=12
data:
JSON:{blockState:{blockName:"ancientwarfarestructure:advanced_loot_chest",properties:{facing:"west"}},teData:{LootTable:"ancientwarfare:inject/chests/simple_dungeon",lootRolls:1b,id:"ancientwarfarestructure:advanced_loot_chest_tile",Lock:"",LootTableSeed:7139961484241697672L}}
:enddata
:endrule

rule:
plugin=blockTile
number=13
data:
JSON:{blockState:{blockName:"ancientwarfarestructure:advanced_spawner",properties:{transparent:"true"}},teData:{id:"ancientwarfarestructure:advanced_spawner_tile",spawnerSettings:{minDelay:0,spawnDelay:0,lightSensitive:0b,spawnGroups:[{settingsList:[{remainingSpawnCount:1,hostile:1b,forced:1b,customTag:{factionName:"brigand"},maxToSpawn:1,entityId:"ancientwarfarenpc:faction.soldier",minToSpawn:1}],groupWeight:1}],playerRange:16,respondToRedstone:0b,inventory:{Size:9,Items:[]},spawnRange:0,transparent:1b,maxDelay:0,xpToDrop:0,mobRange:0,debugMode:0b,maxNearbyMonsters:0}}}
:enddata
:endrule

rule:
plugin=blockTile
number=14
data:
JSON:{blockState:{blockName:"ancientwarfarestructure:advanced_spawner",properties:{transparent:"true"}},teData:{id:"ancientwarfarestructure:advanced_spawner_tile",spawnerSettings:{minDelay:0,spawnDelay:0,lightSensitive:0b,spawnGroups:[{settingsList:[{remainingSpawnCount:1,hostile:1b,forced:1b,customTag:{factionName:"brigand"},maxToSpawn:1,entityId:"ancientwarfarenpc:faction.soldier",minToSpawn:1}],groupWeight:1}],playerRange:16,respondToRedstone:0b,inventory:{Size:9,Items:[]},spawnRange:0,transparent:1b,maxDelay:0,xpToDrop:0,mobRange:0,debugMode:0b,maxNearbyMonsters:0}}}
:enddata
:endrule

rule:
plugin=vanillaBlocks
number=15
data:
JSON:{blockState:{blockName:"minecraft:cauldron",properties:{level:"3"}}}
:enddata
:endrule

rule:
plugin=inventory
number=16
data:
JSON:{blockState:{blockName:"minecraft:chest",properties:{facing:"east"}},lootLevel:0,teData:{ForgeData:{},Items:[],id:"minecraft:chest",Lock:""},inventoryData:{length:0,inventoryContents:[]},legacyFeatures:1b}
:enddata
:endrule

rule:
plugin=vanillaBlocks
number=17
data:
JSON:{blockState:{blockName:"minecraft:log",properties:{variant:"birch",axis:"y"}}}
:enddata
:endrule

rule:
plugin=vanillaBlocks
number=18
data:
JSON:{blockState:{blockName:"minecraft:wool",properties:{color:"green"}}}
:enddata
:endrule

rule:
plugin=blockTile
number=19
data:
JSON:{blockState:{blockName:"ancientwarfarestructure:advanced_spawner",properties:{transparent:"true"}},teData:{id:"ancientwarfarestructure:advanced_spawner_tile",spawnerSettings:{minDelay:0,spawnDelay:0,lightSensitive:0b,spawnGroups:[{settingsList:[{remainingSpawnCount:1,hostile:1b,forced:1b,customTag:{factionName:"brigand"},maxToSpawn:1,entityId:"ancientwarfarenpc:faction.soldier",minToSpawn:1}],groupWeight:1}],playerRange:16,respondToRedstone:0b,inventory:{Size:9,Items:[]},spawnRange:0,transparent:1b,maxDelay:0,xpToDrop:0,mobRange:0,debugMode:0b,maxNearbyMonsters:0}}}
:enddata
:endrule

rule:
plugin=blockTile
number=20
data:
JSON:{blockState:{blockName:"ancientwarfarestructure:advanced_spawner",properties:{transparent:"true"}},teData:{id:"ancientwarfarestructure:advanced_spawner_tile",spawnerSettings:{minDelay:0,spawnDelay:0,lightSensitive:0b,spawnGroups:[{settingsList:[{remainingSpawnCount:1,hostile:1b,forced:1b,customTag:{factionName:"brigand"},maxToSpawn:1,entityId:"ancientwarfarenpc:faction.soldier",minToSpawn:1}],groupWeight:1}],playerRange:16,respondToRedstone:0b,inventory:{Size:9,Items:[]},spawnRange:0,transparent:1b,maxDelay:0,xpToDrop:0,mobRange:0,debugMode:0b,maxNearbyMonsters:0}}}
:enddata
:endrule

rule:
plugin=vanillaBlocks
number=21
data:
JSON:{blockState:{blockName:"minecraft:stonebrick",properties:{variant:"chiseled_stonebrick"}}}
:enddata
:endrule

rule:
plugin=vanillaBlocks
number=22
data:
JSON:{blockState:{blockName:"minecraft:leaves",properties:{check_decay:"false",decayable:"true",variant:"birch"}}}
:enddata
:endrule

rule:
plugin=vanillaBlocks
number=23
data:
JSON:{blockState:{blockName:"minecraft:leaves",properties:{check_decay:"false",decayable:"false",variant:"birch"}}}
:enddata
:endrule

rule:
plugin=blockTile
number=24
data:
JSON:{blockState:{blockName:"ancientwarfarestructure:advanced_spawner",properties:{transparent:"true"}},teData:{id:"ancientwarfarestructure:advanced_spawner_tile",spawnerSettings:{minDelay:0,spawnDelay:0,lightSensitive:0b,spawnGroups:[{settingsList:[{remainingSpawnCount:1,hostile:1b,forced:1b,customTag:{factionName:"brigand"},maxToSpawn:1,entityId:"ancientwarfarenpc:faction.soldier.elite",minToSpawn:1}],groupWeight:1}],playerRange:16,respondToRedstone:0b,inventory:{Size:9,Items:[]},spawnRange:0,transparent:1b,maxDelay:0,xpToDrop:0,mobRange:0,debugMode:0b,maxNearbyMonsters:0}}}
:enddata
:endrule

rule:
plugin=vanillaBlocks
number=25
data:
JSON:{blockState:{blockName:"minecraft:stone_brick_stairs",properties:{half:"top",shape:"straight",facing:"north"}}}
:enddata
:endrule

rule:
plugin=vanillaBlocks
number=26
data:
JSON:{blockState:{blockName:"minecraft:stone_brick_stairs",properties:{half:"top",shape:"straight",facing:"south"}}}
:enddata
:endrule

rule:
plugin=vanillaBlocks
number=27
data:
JSON:{blockState:{blockName:"minecraft:stone_brick_stairs",properties:{half:"top",shape:"straight",facing:"east"}}}
:enddata
:endrule

rule:
plugin=vanillaBlocks
number=28
data:
JSON:{blockState:{blockName:"minecraft:stone_brick_stairs",properties:{half:"top",shape:"straight",facing:"west"}}}
:enddata
:endrule

rule:
plugin=vanillaBlocks
number=29
data:
JSON:{blockState:{blockName:"minecraft:stone_slab",properties:{half:"bottom",variant:"cobblestone"}}}
:enddata
:endrule

rule:
plugin=vanillaBlocks
number=30
data:
JSON:{blockState:{blockName:"minecraft:stone_slab",properties:{half:"bottom",variant:"stone_brick"}}}
:enddata
:endrule

rule:
plugin=blockTile
number=31
data:
JSON:{blockState:{blockName:"ancientwarfarestructure:advanced_spawner",properties:{transparent:"true"}},teData:{id:"ancientwarfarestructure:advanced_spawner_tile",spawnerSettings:{minDelay:0,spawnDelay:0,lightSensitive:0b,spawnGroups:[{settingsList:[{remainingSpawnCount:1,hostile:1b,forced:1b,customTag:{factionName:"brigand"},maxToSpawn:1,entityId:"ancientwarfarenpc:faction.archer",minToSpawn:1}],groupWeight:1}],playerRange:16,respondToRedstone:0b,inventory:{Size:9,Items:[]},spawnRange:0,transparent:1b,maxDelay:0,xpToDrop:0,mobRange:0,debugMode:0b,maxNearbyMonsters:0}}}
:enddata
:endrule

#### ENTITIES ####
