# Ancient Warfare Structure Template File
# Auto-generated structure template file. created on: 8/19/2019 at: 10:23:19
# Lines beginning with # denote comments

header:
version=2.9
name=GOGYetiSpireCave
mods=grimoireofgaia
size=13,74,12
offset=5,7,11
:endheader

#### VALIDATION ####
validation:
type=ground
survival=false
worldGenEnabled=true
unique=false
preserveBlocks=false
selectionWeight=30
clusterValue=40
minDuplicateDistance=1000
dimensionWhiteList=true
dimensionList=0
biomeWhiteList=true
biomeList=minecraft:taiga_cold,minecraft:mutated_ice_flats,minecraft:mutated_taiga_cold,minecraft:ice_mountains,minecraft:ice_flats,minecraft:taiga_cold_hills,minecraft:cold_beach
leveling=4
fill=4
border=4
blockSwap=false
:endvalidation

#### LAYERS ####
layer: 0
3,3,3,3,3,3,0,1,1,1,1,1,1
3,3,3,3,1,1,1,0,1,1,1,1,1
1,1,1,1,1,1,1,1,0,1,1,1,1
1,1,1,1,1,1,1,1,1,1,1,1,1
2,1,1,1,1,1,1,1,1,1,1,1,1
1,1,1,1,1,1,1,1,1,1,1,1,0
1,1,1,1,1,1,1,1,1,1,1,1,1
1,1,1,1,1,1,1,1,1,1,1,1,1
1,1,1,1,1,1,1,1,1,1,1,1,1
1,1,1,1,1,1,1,1,1,1,1,1,1
1,1,1,1,1,1,1,1,1,1,1,1,1
1,1,1,1,1,1,1,1,1,1,1,1,1
:endlayer
layer: 1
3,3,3,3,3,1,1,1,1,1,1,1,1
3,3,3,1,1,1,1,1,1,1,1,1,1
1,1,1,1,1,1,1,1,1,1,1,1,1
1,1,1,1,1,1,1,1,1,1,1,1,1
1,1,1,1,1,1,1,1,1,1,1,1,1
1,1,1,1,1,1,1,1,1,1,1,0,0
1,1,1,0,1,1,1,1,1,1,1,0,0
1,1,0,1,1,1,1,1,1,1,1,1,1
1,1,1,1,1,1,1,1,1,1,1,1,1
1,1,1,1,1,1,1,1,1,1,1,1,1
1,1,1,1,1,1,4,4,1,1,1,1,1
1,1,1,1,1,1,1,1,1,1,1,1,1
:endlayer
layer: 2
1,3,3,1,1,1,1,1,1,1,1,1,1
1,1,2,2,1,1,1,1,1,1,1,1,1
5,1,2,2,1,1,1,1,1,1,1,1,1
1,1,1,1,1,1,1,1,1,1,1,1,1
1,1,1,1,1,1,1,1,1,1,1,1,1
1,1,1,1,1,1,1,1,1,1,1,1,1
1,1,1,0,1,1,1,1,1,1,1,0,1
1,1,0,2,1,1,1,1,1,1,1,1,1
1,1,1,1,1,1,1,1,1,1,1,1,1
1,1,1,1,1,1,1,1,1,1,1,1,1
1,1,1,1,1,1,1,1,1,1,1,1,1
1,1,1,1,1,1,0,0,1,1,1,1,1
:endlayer
layer: 3
3,3,3,3,3,3,1,1,1,3,3,3,3
3,3,3,3,3,1,6,0,8,1,3,3,3
3,3,3,3,3,1,0,7,0,1,3,3,3
3,3,3,3,3,1,0,0,0,1,3,3,3
3,3,3,3,3,1,1,1,1,1,3,3,3
3,3,3,3,3,3,3,3,3,3,3,3,3
3,3,3,3,3,3,3,3,3,3,3,3,3
3,3,3,3,3,3,3,3,3,3,3,3,3
3,3,3,3,3,3,3,3,3,3,3,3,3
3,3,3,3,3,3,3,3,3,3,3,3,3
3,3,3,3,3,3,3,3,3,3,3,3,3
3,3,3,3,3,3,3,3,3,3,3,3,3
:endlayer
layer: 4
3,3,3,3,3,3,1,1,1,3,3,3,3
3,3,3,3,3,1,0,0,0,1,3,3,3
3,3,3,3,3,1,0,0,0,1,3,3,3
3,3,3,3,3,1,0,0,0,1,3,3,3
3,3,3,3,3,1,0,0,0,1,3,3,3
3,3,3,3,3,3,1,1,1,3,3,3,3
3,3,3,3,3,3,3,3,3,3,3,3,3
3,3,3,3,3,3,3,3,3,3,3,3,3
3,3,3,3,3,3,3,3,3,3,3,3,3
3,3,3,3,3,3,3,3,3,3,3,3,3
3,3,3,3,3,3,3,3,3,3,3,3,3
3,3,3,3,3,3,3,3,3,3,3,3,3
:endlayer
layer: 5
3,3,3,3,3,3,1,1,1,3,3,3,3
3,3,3,3,3,1,0,0,0,1,3,3,3
3,3,3,3,3,1,0,0,0,1,3,3,3
3,3,3,3,3,1,0,0,0,1,3,3,3
3,3,3,3,3,1,0,0,0,1,3,3,3
3,3,3,3,3,1,0,0,0,1,3,3,3
3,3,3,3,3,3,1,1,1,3,3,3,3
3,3,3,3,3,3,3,3,3,3,3,3,3
3,3,3,3,3,3,3,3,3,3,3,3,3
3,3,3,3,3,3,3,3,3,3,3,3,3
3,3,3,3,3,3,3,3,3,3,3,3,3
3,3,3,3,3,3,3,3,3,3,3,3,3
:endlayer
layer: 6
9,9,9,9,9,9,3,3,3,3,9,9,9
9,9,9,3,3,3,1,1,1,1,3,9,9
9,9,3,3,3,1,0,0,0,1,3,3,9
9,9,3,3,3,1,0,0,0,1,3,3,9
9,9,3,3,3,1,0,0,0,1,3,9,9
9,9,3,3,3,1,0,0,0,1,9,9,9
9,9,9,9,3,1,0,0,0,1,9,9,9
9,9,9,9,3,3,1,1,1,3,9,9,9
9,9,9,9,9,9,3,3,3,9,9,9,9
9,9,9,9,9,9,3,3,3,9,9,9,9
9,9,9,9,9,9,9,9,9,9,9,9,9
9,9,9,9,9,9,9,9,9,9,9,9,9
:endlayer
layer: 7
10,10,10,10,10,10,9,3,9,9,10,10,10
10,10,10,9,3,3,3,3,3,3,3,10,10
11,11,9,3,3,3,1,1,1,3,3,9,10
10,10,3,3,9,9,1,1,1,3,9,9,10
10,10,3,3,1,1,0,0,0,1,9,10,10
10,10,9,9,1,1,0,0,0,1,10,10,10
10,10,10,11,1,1,0,0,0,1,10,10,10
10,10,10,10,1,9,1,0,1,1,10,10,10
10,11,11,10,10,10,1,1,1,10,10,10,10
10,10,11,10,10,10,1,1,1,10,10,10,10
11,10,10,10,10,10,10,10,10,10,10,10,10
10,10,10,10,10,10,10,10,10,10,10,10,10
:endlayer
layer: 8
0,0,0,0,0,0,10,9,10,10,0,0,0
0,0,0,10,9,9,3,3,3,9,9,0,0
0,0,10,9,9,9,1,1,1,3,9,10,0
0,0,9,3,10,10,1,1,1,1,10,10,0
0,0,9,3,1,1,1,1,1,0,10,0,0
0,0,10,10,1,1,1,1,1,0,0,0,0
0,0,0,0,1,1,1,0,1,1,0,0,0
0,0,12,0,1,10,1,0,1,0,0,0,0
0,0,0,0,0,0,1,0,1,0,0,0,0
0,0,0,0,0,0,0,0,0,0,0,0,0
0,0,0,0,0,0,0,0,0,0,0,0,0
0,0,0,0,0,0,0,0,0,0,0,0,0
:endlayer
layer: 9
0,0,0,0,0,0,0,11,0,0,0,0,0
0,0,0,0,10,10,3,9,9,10,10,0,0
0,0,0,10,10,10,1,0,0,9,10,0,0
0,0,10,9,0,1,1,1,1,1,0,0,0
0,0,10,9,1,1,1,1,1,1,0,0,0
0,0,0,0,1,1,1,1,1,1,0,0,0
0,0,0,0,1,1,1,1,1,1,0,0,0
0,0,0,0,1,1,1,0,1,0,0,0,0
0,0,0,0,0,0,1,0,1,0,0,0,0
0,0,0,0,0,0,0,0,0,0,0,0,0
0,0,0,0,0,0,0,0,0,0,0,0,0
0,0,0,0,0,0,0,0,0,0,0,0,0
:endlayer
layer: 10
0,0,0,0,0,0,0,0,0,0,0,0,0
0,0,0,0,0,0,9,10,11,0,0,0,0
0,0,0,0,0,0,1,1,9,10,0,0,0
0,0,0,10,0,1,1,1,1,1,0,0,0
0,0,0,10,1,1,1,1,1,1,0,0,0
0,0,0,0,1,1,1,1,1,1,1,0,0
0,0,0,0,1,1,1,1,1,1,1,0,0
0,0,0,0,1,1,1,1,1,0,0,0,0
0,0,0,0,0,0,1,1,1,0,0,0,0
0,0,0,0,0,0,0,0,0,0,0,0,0
0,0,0,0,0,0,0,0,0,0,0,0,0
0,0,0,0,0,0,0,0,0,0,0,0,0
:endlayer
layer: 11
0,0,0,0,0,0,0,0,0,0,0,0,0
0,0,0,0,0,0,10,0,0,0,0,0,0
0,0,0,0,0,0,1,9,10,0,0,0,0
0,0,0,0,0,1,1,1,1,1,0,0,0
0,0,0,0,1,1,1,1,1,1,1,0,0
0,0,0,0,1,1,1,1,1,1,1,0,0
0,0,0,0,9,1,1,1,1,1,9,0,0
0,0,0,0,0,1,1,1,1,1,0,0,0
0,0,0,0,0,0,1,1,9,0,0,0,0
0,0,0,0,0,0,0,0,0,0,0,0,0
0,0,0,0,0,0,0,0,0,0,0,0,0
0,0,0,0,0,0,0,0,0,0,0,0,0
:endlayer
layer: 12
0,0,0,0,0,0,0,0,0,0,0,0,0
0,0,0,0,0,0,0,0,0,0,0,0,0
0,0,0,0,0,0,9,10,0,0,0,0,0
0,0,0,0,0,1,1,1,1,1,0,0,0
0,0,0,0,9,1,1,1,1,1,9,0,0
0,0,0,0,9,1,1,1,1,1,1,0,0
0,0,0,0,10,1,1,1,1,1,10,0,0
0,0,0,0,0,1,1,1,1,1,0,0,0
0,0,0,0,0,0,9,9,10,0,0,0,0
0,0,0,0,0,0,0,0,0,0,0,0,0
0,0,0,0,0,0,0,0,0,0,0,0,0
0,0,0,0,0,0,0,0,0,0,0,0,0
:endlayer
layer: 13
0,0,0,0,0,0,0,0,0,0,0,0,0
0,0,0,0,0,0,0,0,0,0,0,0,0
0,0,0,0,0,0,10,0,0,0,0,0,0
0,0,0,0,0,1,1,1,1,1,0,0,0
0,0,0,0,10,1,1,1,1,1,10,0,0
0,0,0,0,10,1,1,1,1,1,9,0,0
0,0,0,0,0,1,1,1,1,1,0,0,0
0,0,0,0,0,1,1,1,1,1,0,0,0
0,0,0,0,0,0,10,10,0,0,0,0,0
0,0,0,0,0,0,0,0,0,0,0,0,0
0,0,0,0,0,0,0,0,0,0,0,0,0
0,0,0,0,0,0,0,0,0,0,0,0,0
:endlayer
layer: 14
0,0,0,0,0,0,0,0,0,0,0,0,0
0,0,0,0,0,0,0,0,0,0,0,0,0
0,0,0,0,0,0,0,0,0,0,0,0,0
0,0,0,0,0,1,1,1,1,1,0,0,0
0,0,0,0,1,1,1,1,1,1,0,0,0
0,0,0,0,1,1,1,1,1,1,10,0,0
0,0,0,0,1,1,1,1,1,1,1,0,0
0,0,0,0,0,1,1,1,1,1,0,0,0
0,0,0,0,0,0,0,1,0,0,0,0,0
0,0,0,0,0,0,0,0,0,0,0,0,0
0,0,0,0,0,0,0,0,0,0,0,0,0
0,0,0,0,0,0,0,0,0,0,0,0,0
:endlayer
layer: 15
0,0,0,0,0,0,0,0,0,0,0,0,0
0,0,0,0,0,0,0,0,0,0,0,0,0
0,0,0,0,0,0,0,0,0,0,0,0,0
0,0,0,0,0,1,1,1,1,1,0,0,0
0,0,0,0,1,1,1,1,1,1,1,0,0
0,0,0,0,1,1,1,1,1,1,1,0,0
0,0,0,0,1,1,1,1,1,1,9,0,0
0,0,0,0,0,1,1,1,1,1,0,0,0
0,0,0,0,0,0,0,1,1,0,0,0,0
0,0,0,0,0,0,0,0,0,0,0,0,0
0,0,0,0,0,0,0,0,0,0,0,0,0
0,0,0,0,0,0,0,0,0,0,0,0,0
:endlayer
layer: 16
0,0,0,0,0,0,0,0,0,0,0,0,0
0,0,0,0,0,0,0,0,0,0,0,0,0
0,0,0,0,0,0,0,0,0,0,0,0,0
0,0,0,0,1,1,1,1,1,9,0,0,0
0,0,0,0,1,1,1,1,1,1,9,0,0
0,0,0,0,1,1,1,1,1,1,1,0,0
0,0,0,0,1,1,1,1,1,1,10,0,0
0,0,0,0,1,1,1,1,1,1,0,0,0
0,0,0,0,0,0,1,1,9,0,0,0,0
0,0,0,0,0,0,0,0,0,0,0,0,0
0,0,0,0,0,0,0,0,0,0,0,0,0
0,0,0,0,0,0,0,0,0,0,0,0,0
:endlayer
layer: 17
0,0,0,0,0,0,0,0,0,0,0,0,0
0,0,0,0,0,0,0,0,0,0,0,0,0
0,0,0,0,0,1,0,0,0,0,0,0,0
0,0,0,0,1,1,1,1,1,10,0,0,0
0,0,0,0,1,1,1,1,1,1,10,0,0
0,0,0,0,1,1,1,1,1,1,9,0,0
0,0,0,0,1,1,1,1,1,1,0,0,0
0,0,0,0,1,1,1,1,1,9,0,0,0
0,0,0,0,0,1,1,1,10,0,0,0,0
0,0,0,0,0,0,0,0,0,0,0,0,0
0,0,0,0,0,0,0,0,0,0,0,0,0
0,0,0,0,0,0,0,0,0,0,0,0,0
:endlayer
layer: 18
0,0,0,0,0,0,0,0,0,0,0,0,0
0,0,0,0,0,0,0,0,0,0,0,0,0
0,0,0,0,0,9,0,0,0,0,0,0,0
0,0,0,0,1,1,1,1,1,0,0,0,0
0,0,0,0,1,1,1,1,1,1,0,0,0
0,0,0,1,1,1,1,1,1,1,10,0,0
0,0,0,0,1,1,1,1,1,1,0,0,0
0,0,0,0,1,1,1,1,1,10,0,0,0
0,0,0,0,0,1,1,1,0,0,0,0,0
0,0,0,0,0,0,0,0,0,0,0,0,0
0,0,0,0,0,0,0,0,0,0,0,0,0
0,0,0,0,0,0,0,0,0,0,0,0,0
:endlayer
layer: 19
0,0,0,0,0,0,0,0,0,0,0,0,0
0,0,0,0,0,0,0,0,0,0,0,0,0
0,0,0,0,0,10,0,0,0,0,0,0,0
0,0,0,0,1,1,1,1,1,0,0,0,0
0,0,0,0,1,1,1,1,1,1,0,0,0
0,0,0,1,1,1,1,1,1,1,0,0,0
0,0,0,1,1,1,1,1,1,1,0,0,0
0,0,0,0,1,1,1,1,1,0,0,0,0
0,0,0,0,1,1,1,1,1,0,0,0,0
0,0,0,0,0,0,0,0,0,0,0,0,0
0,0,0,0,0,0,0,0,0,0,0,0,0
0,0,0,0,0,0,0,0,0,0,0,0,0
:endlayer
layer: 20
0,0,0,0,0,0,0,0,0,0,0,0,0
0,0,0,0,0,0,0,0,0,0,0,0,0
0,0,0,0,0,0,9,9,0,0,0,0,0
0,0,0,0,1,1,1,1,1,0,0,0,0
0,0,0,0,1,1,1,1,1,9,0,0,0
0,0,0,9,1,1,1,1,1,1,0,0,0
0,0,0,1,1,1,1,1,1,1,0,0,0
0,0,0,1,1,1,1,1,1,0,0,0,0
0,0,0,0,1,1,1,1,1,0,0,0,0
0,0,0,0,0,1,1,0,0,0,0,0,0
0,0,0,0,0,0,0,0,0,0,0,0,0
0,0,0,0,0,0,0,0,0,0,0,0,0
:endlayer
layer: 21
0,0,0,0,0,0,0,0,0,0,0,0,0
0,0,0,0,0,0,0,0,0,0,0,0,0
0,0,0,0,0,0,10,10,0,0,0,0,0
0,0,0,0,9,1,1,1,9,0,0,0,0
0,0,0,0,1,1,1,1,1,10,0,0,0
0,0,0,10,1,1,1,1,1,1,0,0,0
0,0,0,1,1,1,1,1,1,1,0,0,0
0,0,0,1,1,1,1,1,1,1,0,0,0
0,0,0,0,1,1,1,1,1,0,0,0,0
0,0,0,0,0,9,1,1,0,0,0,0,0
0,0,0,0,0,0,0,0,0,0,0,0,0
0,0,0,0,0,0,0,0,0,0,0,0,0
:endlayer
layer: 22
0,0,0,0,0,0,0,0,0,0,0,0,0
0,0,0,0,0,0,0,0,0,0,0,0,0
0,0,0,0,0,0,0,0,0,0,0,0,0
0,0,0,0,10,9,1,1,10,0,0,0,0
0,0,0,0,1,1,1,1,1,0,0,0,0
0,0,0,0,1,1,1,1,1,1,0,0,0
0,0,0,9,1,1,1,1,1,1,0,0,0
0,0,0,1,1,1,1,1,1,1,0,0,0
0,0,0,0,1,1,1,1,1,1,0,0,0
0,0,0,0,0,10,9,1,1,0,0,0,0
0,0,0,0,0,0,0,0,0,0,0,0,0
0,0,0,0,0,0,0,0,0,0,0,0,0
:endlayer
layer: 23
0,0,0,0,0,0,0,0,0,0,0,0,0
0,0,0,0,0,0,0,0,0,0,0,0,0
0,0,0,0,0,0,0,0,0,0,0,0,0
0,0,0,0,0,10,9,9,0,0,0,0,0
0,0,0,0,9,1,1,1,1,0,0,0,0
0,0,0,0,1,1,1,1,1,1,0,0,0
0,0,0,10,1,1,1,1,1,1,1,0,0
0,0,0,9,1,1,1,1,1,1,1,0,0
0,0,0,0,1,1,1,1,1,1,1,0,0
0,0,0,0,0,0,10,1,1,1,0,0,0
0,0,0,0,0,0,0,0,1,0,0,0,0
0,0,0,0,0,0,0,0,0,0,0,0,0
:endlayer
layer: 24
0,0,0,0,0,0,0,0,0,0,0,0,0
0,0,0,0,0,0,0,0,0,0,0,0,0
0,0,0,0,0,0,0,0,0,0,0,0,0
0,0,0,0,0,0,10,10,0,0,0,0,0
0,0,0,0,10,9,1,1,1,0,0,0,0
0,0,0,0,9,1,1,1,1,1,0,0,0
0,0,0,0,1,1,1,1,1,1,1,0,0
0,0,0,10,1,1,1,1,1,1,1,0,0
0,0,0,0,9,1,1,1,1,1,1,0,0
0,0,0,0,0,0,1,1,1,1,0,0,0
0,0,0,0,0,0,0,1,9,0,0,0,0
0,0,0,0,0,0,0,0,0,0,0,0,0
:endlayer
layer: 25
0,0,0,0,0,0,0,0,0,0,0,0,0
0,0,0,0,0,0,0,0,0,0,0,0,0
0,0,0,0,0,0,0,0,0,0,0,0,0
0,0,0,0,0,0,0,0,0,0,0,0,0
0,0,0,0,0,10,1,1,1,1,1,0,0
0,0,0,0,10,1,1,1,1,1,1,0,0
0,0,0,0,1,1,1,1,1,1,1,0,0
0,0,0,0,9,1,1,1,1,1,1,0,0
0,0,0,0,10,1,1,1,1,1,1,0,0
0,0,0,0,0,0,1,1,1,1,0,0,0
0,0,0,0,0,0,1,9,10,0,0,0,0
0,0,0,0,0,0,0,0,0,0,0,0,0
:endlayer
layer: 26
0,0,0,0,0,0,0,0,0,0,0,0,0
0,0,0,0,0,0,0,0,0,0,0,0,0
0,0,0,0,0,0,0,0,0,0,0,0,0
0,0,0,0,0,0,0,1,1,1,0,0,0
0,0,0,0,0,0,1,1,1,1,1,0,0
0,0,0,0,0,1,1,1,1,1,1,1,0
0,0,0,0,9,1,1,1,1,1,1,0,0
0,0,0,0,10,1,1,1,1,1,1,0,0
0,0,0,0,0,9,1,1,1,1,1,0,0
0,0,0,0,0,0,9,1,1,1,0,0,0
0,0,0,0,0,0,9,10,0,0,0,0,0
0,0,0,0,0,0,0,0,0,0,0,0,0
:endlayer
layer: 27
0,0,0,0,0,0,0,0,0,0,0,0,0
0,0,0,0,0,0,0,0,0,0,0,0,0
0,0,0,0,0,0,0,0,1,0,0,0,0
0,0,0,0,0,0,0,1,1,1,1,0,0
0,0,0,0,0,0,1,1,1,1,1,1,0
0,0,0,0,0,1,1,1,1,1,1,1,0
0,0,0,0,10,1,1,1,1,1,1,0,0
0,0,0,0,0,1,1,1,1,1,1,0,0
0,0,0,0,0,10,1,1,1,1,1,0,0
0,0,0,0,0,0,10,1,1,1,0,0,0
0,0,0,0,0,0,10,0,0,0,0,0,0
0,0,0,0,0,0,0,0,0,0,0,0,0
:endlayer
layer: 28
0,0,0,0,0,0,0,0,0,0,0,0,0
0,0,0,0,0,0,0,0,0,0,0,0,0
0,0,0,0,0,0,0,1,1,1,0,0,0
0,0,0,0,0,0,1,1,1,1,1,0,0
0,0,0,0,0,1,1,1,1,1,1,1,0
0,0,0,0,1,1,1,1,1,1,1,1,0
0,0,0,0,0,1,1,1,1,1,1,1,0
0,0,0,0,0,1,1,1,1,1,1,0,0
0,0,0,0,0,1,1,1,1,1,1,0,0
0,0,0,0,0,0,1,1,1,1,0,0,0
0,0,0,0,0,0,0,0,1,1,0,0,0
0,0,0,0,0,0,0,0,0,0,0,0,0
:endlayer
layer: 29
0,0,0,0,0,0,0,0,0,0,0,0,0
0,0,0,0,0,0,0,0,0,1,0,0,0
0,0,0,0,0,0,1,1,1,1,1,0,0
0,0,0,0,0,1,1,1,1,1,1,1,0
0,0,0,0,1,1,1,1,1,1,1,1,0
0,0,0,0,1,1,1,1,1,1,1,1,0
0,0,0,1,1,1,1,1,1,1,1,1,0
0,0,0,0,1,1,1,1,1,1,1,1,0
0,0,0,0,0,1,1,1,1,1,1,1,0
0,0,0,0,0,1,1,1,1,1,1,0,0
0,0,0,0,0,0,1,1,1,9,0,0,0
0,0,0,0,0,0,0,0,0,0,0,0,0
:endlayer
layer: 30
0,0,0,0,0,0,0,0,0,0,0,0,0
0,0,0,0,0,0,0,0,1,1,1,0,0
0,0,0,0,0,0,1,1,1,1,1,1,0
0,0,0,0,1,1,1,1,1,1,1,1,1
0,0,0,0,1,1,1,1,1,1,1,1,1
0,0,0,0,1,1,1,1,1,1,1,1,0
0,0,0,1,1,1,1,1,1,1,1,1,1
0,0,0,1,1,1,1,1,1,1,1,1,1
0,0,0,0,1,1,1,1,1,1,1,1,0
0,0,0,0,0,1,1,1,1,1,1,0,0
0,0,0,0,0,0,1,9,9,10,0,0,0
0,0,0,0,0,0,0,0,0,0,0,0,0
:endlayer
layer: 31
0,0,0,0,0,0,0,0,0,0,0,0,0
0,0,0,0,0,0,0,0,1,1,9,0,0
0,0,0,0,0,1,1,1,1,1,1,1,0
0,0,0,0,1,1,1,1,1,1,1,1,9
0,0,0,0,1,1,1,1,1,1,1,1,1
0,0,0,1,1,1,1,1,1,1,1,1,0
0,0,0,1,1,1,1,1,1,1,1,1,1
0,0,0,1,1,1,1,1,1,1,1,1,9
0,0,0,0,1,1,1,1,1,1,1,1,0
0,0,0,0,1,1,1,1,1,1,9,0,0
0,0,0,0,0,9,9,10,10,0,0,0,0
0,0,0,0,0,0,0,0,0,0,0,0,0
:endlayer
layer: 32
0,0,0,0,0,0,0,0,0,0,0,0,0
0,0,0,0,0,0,0,1,1,1,10,0,0
0,0,0,0,0,9,1,1,1,1,1,1,0
0,0,0,0,1,1,1,1,1,1,1,1,10
0,0,0,0,1,1,1,1,1,1,1,1,1
0,0,0,1,1,1,1,1,1,1,1,1,1
0,0,0,1,1,1,1,1,1,1,1,1,1
0,0,0,1,1,1,1,1,1,1,1,1,10
0,0,0,0,1,1,1,1,1,1,1,1,0
0,0,0,0,1,1,1,9,9,9,10,0,0
0,0,0,0,0,10,10,0,0,0,0,0,0
0,0,0,0,0,0,0,0,0,0,0,0,0
:endlayer
layer: 33
0,0,0,0,0,0,0,0,0,0,0,0,0
0,0,0,0,0,0,0,9,9,9,0,0,0
0,0,0,0,0,10,9,1,1,1,1,9,0
0,0,0,0,1,9,1,1,1,1,1,1,0
0,0,0,0,1,1,1,1,1,1,1,1,1
0,0,0,1,1,1,1,1,1,1,1,1,1
0,0,0,1,1,1,1,1,1,1,1,1,9
0,0,0,9,1,1,1,1,1,1,1,1,0
0,0,0,0,1,1,1,1,1,1,1,1,0
0,0,0,0,9,1,9,10,10,10,0,0,0
0,0,0,0,0,0,0,0,0,0,0,0,0
0,0,0,0,0,0,0,0,0,0,0,0,0
:endlayer
layer: 34
0,0,0,0,0,0,0,0,0,0,0,0,0
0,0,0,0,0,0,0,10,10,10,0,0,0
0,0,0,0,1,0,10,1,1,1,1,10,0
0,0,0,0,1,0,1,1,1,1,1,1,0
0,0,0,1,1,1,1,1,1,1,1,1,9
0,0,0,1,1,1,1,1,1,1,1,1,1
0,0,0,1,1,1,1,1,1,1,1,1,10
0,0,0,10,1,1,1,1,1,1,1,1,0
0,0,0,1,1,1,1,1,1,3,1,1,0
0,0,0,0,10,9,10,0,0,0,9,0,0
0,0,0,0,0,0,0,0,0,0,0,0,0
0,0,0,0,0,0,0,0,0,0,0,0,0
:endlayer
layer: 35
0,0,0,0,0,0,0,0,0,0,0,0,0
0,0,0,0,0,1,1,1,1,1,1,0,0
0,0,0,0,9,1,1,1,1,1,1,1,0
0,0,0,0,1,1,1,1,1,1,1,1,0
0,0,0,1,1,1,1,1,1,1,1,1,10
0,0,0,1,1,1,1,1,1,1,1,1,9
0,0,1,1,1,1,1,1,1,1,1,1,0
0,0,0,1,1,1,1,1,1,1,1,9,0
0,0,0,9,1,9,9,9,9,9,1,9,0
0,0,0,0,0,10,0,0,0,0,10,0,0
0,0,0,0,0,0,0,0,0,0,0,0,0
0,0,0,0,0,0,0,0,0,0,0,0,0
:endlayer
layer: 36
0,0,0,0,0,0,0,0,0,1,0,0,0
0,0,0,0,0,9,9,1,1,1,1,0,0
0,0,0,0,10,1,1,1,1,1,1,1,0
0,0,0,0,1,1,1,1,1,1,1,1,1
0,0,0,1,1,1,1,1,1,1,1,1,0
0,0,0,1,1,1,1,1,1,1,1,1,10
0,0,9,9,1,1,1,1,1,1,1,1,0
0,0,0,9,1,1,9,9,1,1,1,10,0
0,0,0,10,9,10,10,10,10,10,9,10,0
0,0,0,0,0,0,0,0,0,0,0,0,0
0,0,0,0,0,0,0,0,0,0,0,0,0
0,0,0,0,0,0,0,0,0,0,0,0,0
:endlayer
layer: 37
0,0,0,0,0,0,0,1,1,9,0,0,0
0,0,0,0,0,10,10,1,1,1,9,0,0
0,0,0,0,0,1,1,1,1,1,1,9,0
0,0,0,1,1,1,1,1,1,1,1,1,9
0,0,1,1,1,1,1,1,1,1,1,1,1
0,0,0,3,1,1,1,1,1,1,1,1,0
0,0,10,10,3,1,1,1,1,1,1,1,0
0,0,0,10,3,1,10,10,1,1,1,1,0
0,0,0,0,10,0,0,0,0,0,10,0,0
0,0,0,0,0,0,0,0,0,0,0,0,0
0,0,0,0,0,0,0,0,0,0,0,0,0
0,0,0,0,0,0,0,0,0,0,0,0,0
:endlayer
layer: 38
0,0,0,0,0,0,9,9,9,10,0,0,0
0,0,0,0,0,1,1,1,1,9,10,0,0
0,0,0,0,1,1,1,1,1,1,9,10,0
0,0,0,1,1,1,1,1,1,1,1,9,10
0,0,1,1,1,1,1,1,1,1,1,1,9
0,0,1,1,1,1,1,1,1,1,1,1,1
0,0,1,1,1,1,1,1,1,1,1,1,1
0,0,1,1,1,1,1,1,3,3,3,9,9
0,0,0,0,1,0,0,0,0,0,0,9,0
0,0,0,0,0,0,0,0,0,0,0,0,0
0,0,0,0,0,0,0,0,0,0,0,0,0
0,0,0,0,0,0,0,0,0,0,0,0,0
:endlayer
layer: 39
0,0,0,0,0,1,10,10,10,0,0,0,0
0,0,0,0,1,1,1,1,1,10,0,0,0
0,0,0,0,1,1,1,1,1,10,10,0,0
0,0,1,1,1,1,1,1,1,1,9,10,0
0,0,1,1,1,1,1,1,1,1,1,9,10
0,0,9,1,1,1,1,1,1,1,3,1,1
0,0,9,1,1,1,1,1,1,1,1,9,9
0,0,9,1,1,1,1,1,1,1,9,11,10
0,0,0,1,1,1,9,9,9,9,3,10,0
0,0,0,0,1,0,0,0,0,0,0,0,0
0,0,0,0,0,0,0,0,0,0,0,0,0
0,0,0,0,0,0,0,0,0,0,0,0,0
:endlayer
layer: 40
0,0,0,0,0,9,0,0,0,0,0,0,0
0,0,0,0,1,1,9,9,9,0,0,0,0
0,0,0,0,1,1,1,1,1,0,0,0,0
0,0,1,1,1,1,1,1,1,9,10,0,0
0,0,9,1,1,1,1,1,1,9,9,10,0
0,0,10,1,1,1,1,1,1,1,1,1,9
0,0,10,9,1,1,1,1,9,9,9,10,10
0,0,10,9,1,1,1,1,9,9,10,0,0
0,0,0,9,1,1,10,10,10,10,13,0,0
0,0,0,0,1,0,0,0,0,0,0,0,0
0,0,0,0,0,0,0,0,0,0,0,0,0
0,0,0,0,0,0,0,0,0,0,0,0,0
:endlayer
layer: 41
0,0,0,0,0,10,0,0,0,0,0,0,0
0,0,0,0,9,9,10,10,10,0,0,0,0
0,0,0,9,9,9,9,9,9,0,0,0,0
0,0,9,1,1,1,1,1,1,10,0,0,0
0,0,10,9,1,1,1,1,1,10,10,0,0
0,0,0,9,1,1,9,9,1,1,9,9,10
0,0,0,10,9,1,14,9,0,15,15,15,0
0,0,0,10,9,1,9,14,15,15,15,15,15
0,0,0,10,9,9,0,0,15,15,13,15,15
0,0,0,0,1,0,0,0,15,15,15,15,15
0,0,0,0,0,0,0,0,0,15,15,15,0
0,0,0,0,0,0,0,0,0,0,0,0,0
:endlayer
layer: 42
0,0,0,0,0,0,0,0,0,0,0,0,0
0,0,0,0,10,10,0,0,0,0,0,0,0
0,0,0,10,10,11,10,10,10,0,0,0,0
0,0,10,3,9,9,9,14,1,0,0,0,0
0,0,0,10,9,9,16,1,1,0,0,0,0
0,0,0,10,9,9,10,10,1,14,10,10,0
0,0,0,0,10,9,10,10,0,0,10,10,0
0,0,0,0,10,9,10,10,0,0,15,10,10
0,0,0,0,10,10,0,0,10,15,13,15,0
0,0,0,0,1,0,0,0,10,10,15,0,0
0,0,0,0,0,0,0,0,0,10,10,10,0
0,0,0,0,0,0,0,0,0,0,0,0,0
:endlayer
layer: 43
0,0,0,0,0,0,0,0,0,0,0,0,0
0,0,0,0,0,0,0,0,0,0,0,0,0
0,0,0,0,0,0,0,0,0,0,0,0,0
0,0,0,13,10,10,10,10,3,0,0,0,0
0,0,0,0,10,17,0,3,1,0,0,0,0
0,0,0,0,10,17,0,0,1,1,0,0,0
0,0,0,0,0,10,0,0,0,15,15,15,0
0,0,0,0,0,11,0,0,15,15,15,15,15
0,0,0,0,0,0,0,0,15,15,13,15,15
0,0,0,0,3,0,0,0,15,15,15,15,15
0,0,0,0,0,0,0,0,0,15,15,15,0
0,0,0,0,0,0,0,0,0,0,0,0,0
:endlayer
layer: 44
0,15,15,15,15,15,0,0,0,0,0,0,0
15,15,15,15,15,15,15,0,0,0,0,0,0
15,15,15,15,15,15,15,0,0,0,0,0,0
15,15,15,13,15,15,15,14,9,0,0,0,0
15,15,15,15,15,15,15,9,9,0,0,0,0
15,15,15,15,15,15,15,0,9,9,0,0,0
0,15,15,15,15,15,0,0,0,0,0,0,0
0,0,0,0,0,0,0,0,0,0,15,0,0
0,0,0,0,0,0,0,0,10,15,13,15,0
0,0,0,0,13,0,0,0,10,0,15,0,10
0,0,0,0,0,0,0,0,0,10,10,10,0
0,0,0,0,0,0,0,0,0,0,0,0,0
:endlayer
layer: 45
0,10,10,11,11,10,0,0,0,0,0,0,0
10,0,15,15,15,0,10,0,0,0,0,0,0
10,15,15,15,15,15,10,0,0,0,0,0,0
11,15,15,13,15,15,10,9,10,0,0,0,0
0,15,15,15,15,15,10,10,17,0,0,0,0
10,10,15,15,15,10,10,0,10,10,0,0,0
0,10,10,10,0,10,0,0,0,15,15,15,0
0,0,0,0,0,0,0,0,15,15,15,15,15
0,0,0,0,15,0,0,0,15,15,13,15,15
0,0,0,15,13,15,0,0,15,15,15,15,15
0,0,0,0,15,0,0,0,0,15,15,15,0
0,0,0,0,0,0,0,0,0,0,0,0,0
:endlayer
layer: 46
0,0,0,0,0,0,0,0,0,0,0,0,0
0,0,10,0,10,0,0,0,0,0,0,0,0
0,0,0,15,0,0,0,0,0,0,0,0,0
0,10,15,13,15,10,0,10,0,0,0,0,0
0,10,0,15,0,10,0,0,0,0,0,0,0
0,0,10,10,10,0,0,0,0,0,0,0,0
0,0,0,0,0,0,0,0,0,10,10,10,0
0,0,0,15,15,15,0,0,0,0,15,10,10
0,0,15,15,15,15,15,0,10,15,13,15,10
0,0,15,15,13,15,15,0,10,10,15,10,10
0,0,15,15,15,15,15,0,0,10,10,10,0
0,0,0,15,15,15,0,0,0,0,0,0,0
:endlayer
layer: 47
0,0,0,0,0,0,0,0,0,0,0,0,0
0,0,15,15,15,0,0,0,0,0,0,0,0
0,15,15,15,15,15,0,0,0,0,0,0,0
0,15,15,13,15,15,0,0,0,0,0,0,0
0,15,15,15,15,15,0,0,0,0,0,0,0
0,0,15,15,15,0,0,0,0,0,0,0,0
0,0,0,0,0,0,0,0,0,0,0,0,0
0,0,0,10,10,10,0,0,0,0,10,0,0
0,0,10,0,15,0,10,0,0,0,13,10,0
0,0,10,15,13,15,10,0,0,0,10,0,0
0,0,10,0,15,0,10,0,0,0,0,0,0
0,0,0,10,10,10,0,0,0,0,0,0,0
:endlayer
layer: 48
0,0,0,0,0,0,0,0,0,0,0,0,0
0,0,10,10,10,0,0,0,0,0,0,0,0
0,10,10,15,10,10,0,0,0,0,0,0,0
0,10,15,13,15,10,0,0,0,0,0,0,0
0,10,10,15,10,10,0,0,0,0,0,0,0
0,0,10,10,0,0,0,0,0,0,0,0,0
0,0,0,0,0,0,0,0,0,0,0,0,0
0,0,0,15,15,15,0,0,0,0,15,0,0
0,0,15,15,15,15,15,0,0,15,15,15,0
0,0,15,15,13,15,15,0,0,0,15,0,0
0,0,15,15,15,15,15,0,0,0,0,0,0
0,0,0,15,15,15,0,0,0,0,0,0,0
:endlayer
layer: 49
0,0,0,0,0,0,0,0,0,0,0,0,0
0,0,0,0,0,0,0,0,0,0,0,0,0
0,0,0,10,0,0,0,0,0,0,0,0,0
0,0,10,13,10,0,0,0,0,0,0,0,0
0,0,0,10,0,0,0,0,0,0,0,0,0
0,0,0,0,0,0,0,0,0,0,0,0,0
0,0,0,0,0,0,0,0,0,0,0,0,0
0,0,0,10,10,10,0,0,0,0,10,0,0
0,0,10,11,15,10,10,0,0,10,10,10,0
0,0,10,15,13,15,10,0,0,0,10,0,0
0,0,10,10,15,11,10,0,0,0,0,0,0
0,0,0,10,10,10,0,0,0,0,0,0,0
:endlayer
layer: 50
0,0,0,0,0,0,0,0,0,0,0,0,0
0,0,0,0,0,0,0,0,0,0,0,0,0
0,0,0,15,0,0,0,0,0,0,0,0,0
0,0,15,13,15,0,0,0,0,0,0,0,0
0,0,0,15,0,0,0,0,0,0,0,0,0
0,0,0,0,0,0,0,0,0,0,0,0,0
0,0,0,0,0,0,0,0,0,0,0,0,0
0,0,0,0,0,0,0,0,0,0,0,0,0
0,0,0,0,10,0,0,0,0,0,0,0,0
0,0,0,10,13,10,0,0,0,0,0,0,0
0,0,0,0,10,0,0,0,0,0,0,0,0
0,0,0,0,0,0,0,0,0,0,0,0,0
:endlayer
layer: 51
0,0,0,0,0,0,0,0,0,0,0,0,0
0,0,0,0,0,0,0,0,0,0,0,0,0
0,0,0,10,0,0,0,0,0,0,0,0,0
0,0,10,15,10,0,0,0,0,0,0,0,0
0,0,0,10,0,0,0,0,0,0,0,0,0
0,0,0,0,0,0,0,0,0,0,0,0,0
0,0,0,0,0,0,0,0,0,0,0,0,0
0,0,0,0,0,0,0,0,0,0,0,0,0
0,0,0,0,15,0,0,0,0,0,0,0,0
0,0,0,15,15,15,0,0,0,0,0,0,0
0,0,0,0,15,0,0,0,0,0,0,0,0
0,0,0,0,0,0,0,0,0,0,0,0,0
:endlayer
layer: 52
0,0,0,0,0,0,0,0,0,0,0,0,0
0,0,0,0,0,0,0,0,0,0,0,0,0
0,0,0,0,0,0,0,0,0,0,0,0,0
0,0,0,10,0,0,0,0,0,0,0,0,0
0,0,0,0,0,0,0,0,0,0,0,0,0
0,0,0,0,0,0,0,0,0,0,0,0,0
0,0,0,0,0,0,0,0,0,0,0,0,0
0,0,0,0,0,0,0,0,0,0,0,0,0
0,0,0,0,10,0,0,0,0,0,0,0,0
0,0,0,10,15,10,0,0,0,0,0,0,0
0,0,0,0,10,0,0,0,0,0,0,0,0
0,0,0,0,0,0,0,0,0,0,0,0,0
:endlayer
layer: 53
0,0,0,0,0,0,0,0,0,0,0,0,0
0,0,0,0,0,0,0,0,0,0,0,0,0
0,0,0,0,0,0,0,0,0,0,0,0,0
0,0,0,0,0,0,0,0,0,0,0,0,0
0,0,0,0,0,0,0,0,0,0,0,0,0
0,0,0,0,0,0,0,0,0,0,0,0,0
0,0,0,0,0,0,0,0,0,0,0,0,0
0,0,0,0,0,0,0,0,0,0,0,0,0
0,0,0,0,0,0,0,0,0,0,0,0,0
0,0,0,0,10,0,0,0,0,0,0,0,0
0,0,0,0,0,0,0,0,0,0,0,0,0
0,0,0,0,0,0,0,0,0,0,0,0,0
:endlayer
layer: 54
0,0,0,0,0,0,0,0,0,0,0,0,0
0,0,0,0,0,0,0,0,0,0,0,0,0
0,0,0,0,0,0,0,0,0,0,0,0,0
0,0,0,0,0,0,0,0,0,0,0,0,0
0,0,0,0,0,0,0,0,0,0,0,0,0
0,0,0,0,0,0,0,0,0,0,0,0,0
0,0,0,0,0,0,0,0,0,0,0,0,0
0,0,0,0,0,0,0,0,0,0,0,0,0
0,0,0,0,0,0,0,0,0,0,0,0,0
0,0,0,0,0,0,0,0,0,0,0,0,0
0,0,0,0,0,0,0,0,0,0,0,0,0
0,0,0,0,0,0,0,0,0,0,0,0,0
:endlayer
layer: 55
0,0,0,0,0,0,0,0,0,0,0,0,0
0,0,0,0,0,0,0,0,0,0,0,0,0
0,0,0,0,0,0,0,0,0,0,0,0,0
0,0,0,0,0,0,0,0,0,0,0,0,0
0,0,0,0,0,0,0,0,0,0,0,0,0
0,0,0,0,0,0,0,0,0,0,0,0,0
0,0,0,0,0,0,0,0,0,0,0,0,0
0,0,0,0,0,0,0,0,0,0,0,0,0
0,0,0,0,0,0,0,0,0,0,0,0,0
0,0,0,0,0,0,0,0,0,0,0,0,0
0,0,0,0,0,0,0,0,0,0,0,0,0
0,0,0,0,0,0,0,0,0,0,0,0,0
:endlayer
layer: 56
0,0,0,0,0,0,0,0,0,0,0,0,0
0,0,0,0,0,0,0,0,0,0,0,0,0
0,0,0,0,0,0,0,0,0,0,0,0,0
0,0,0,0,0,0,0,0,0,0,0,0,0
0,0,0,0,0,0,0,0,0,0,0,0,0
0,0,0,0,0,0,0,0,0,0,0,0,0
0,0,0,0,0,0,0,0,0,0,0,0,0
0,0,0,0,0,0,0,0,0,0,0,0,0
0,0,0,0,0,0,0,0,0,0,0,0,0
0,0,0,0,0,0,0,0,0,0,0,0,0
0,0,0,0,0,0,0,0,0,0,0,0,0
0,0,0,0,0,0,0,0,0,0,0,0,0
:endlayer
layer: 57
0,0,0,0,0,0,0,0,0,0,0,0,0
0,0,0,0,0,0,0,0,0,0,0,0,0
0,0,0,0,0,0,0,0,0,0,0,0,0
0,0,0,0,0,0,0,0,0,0,0,0,0
0,0,0,0,0,0,0,0,0,0,0,0,0
0,0,0,0,0,0,0,0,0,0,0,0,0
0,0,0,0,0,0,0,0,0,0,0,0,0
0,0,0,0,0,0,0,0,0,0,0,0,0
0,0,0,0,0,0,0,0,0,0,0,0,0
0,0,0,0,0,0,0,0,0,0,0,0,0
0,0,0,0,0,0,0,0,0,0,0,0,0
0,0,0,0,0,0,0,0,0,0,0,0,0
:endlayer
layer: 58
0,0,0,0,0,0,0,0,0,0,0,0,0
0,0,0,0,0,0,0,0,0,0,0,0,0
0,0,0,0,0,0,0,0,0,0,0,0,0
0,0,0,0,0,0,0,0,0,0,0,0,0
0,0,0,0,0,0,0,0,0,0,0,0,0
0,0,0,0,0,0,0,0,0,0,0,0,0
0,0,0,0,0,0,0,0,0,0,0,0,0
0,0,0,0,0,0,0,0,0,0,0,0,0
0,0,0,0,0,0,0,0,0,0,0,0,0
0,0,0,0,0,0,0,0,0,0,0,0,0
0,0,0,0,0,0,0,0,0,0,0,0,0
0,0,0,0,0,0,0,0,0,0,0,0,0
:endlayer
layer: 59
0,0,0,0,0,0,0,0,0,0,0,0,0
0,0,0,0,0,0,0,0,0,0,0,0,0
0,0,0,0,0,0,0,0,0,0,0,0,0
0,0,0,0,0,0,0,0,0,0,0,0,0
0,0,0,0,0,0,0,0,0,0,0,0,0
0,0,0,0,0,0,0,0,0,0,0,0,0
0,0,0,0,0,0,0,0,0,0,0,0,0
0,0,0,0,0,0,0,0,0,0,0,0,0
0,0,0,0,0,0,0,0,0,0,0,0,0
0,0,0,0,0,0,0,0,0,0,0,0,0
0,0,0,0,0,0,0,0,0,0,0,0,0
0,0,0,0,0,0,0,0,0,0,0,0,0
:endlayer
layer: 60
0,0,0,0,0,0,0,0,0,0,0,0,0
0,0,0,0,0,0,0,0,0,0,0,0,0
0,0,0,0,0,0,0,0,0,0,0,0,0
0,0,0,0,0,0,0,0,0,0,0,0,0
0,0,0,0,0,0,0,0,0,0,0,0,0
0,0,0,0,0,0,0,0,0,0,0,0,0
0,0,0,0,0,0,0,0,0,0,0,0,0
0,0,0,0,0,0,0,0,0,0,0,0,0
0,0,0,0,0,0,0,0,0,0,0,0,0
0,0,0,0,0,0,0,0,0,0,0,0,0
0,0,0,0,0,0,0,0,0,0,0,0,0
0,0,0,0,0,0,0,0,0,0,0,0,0
:endlayer
layer: 61
0,0,0,0,0,0,0,0,0,0,0,0,0
0,0,0,0,0,0,0,0,0,0,0,0,0
0,0,0,0,0,0,0,0,0,0,0,0,0
0,0,0,0,0,0,0,0,0,0,0,0,0
0,0,0,0,0,0,0,0,0,0,0,0,0
0,0,0,0,0,0,0,0,0,0,0,0,0
0,0,0,0,0,0,0,0,0,0,0,0,0
0,0,0,0,0,0,0,0,0,0,0,0,0
0,0,0,0,0,0,0,0,0,0,0,0,0
0,0,0,0,0,0,0,0,0,0,0,0,0
0,0,0,0,0,0,0,0,0,0,0,0,0
0,0,0,0,0,0,0,0,0,0,0,0,0
:endlayer
layer: 62
0,0,0,0,0,0,0,0,0,0,0,0,0
0,0,0,0,0,0,0,0,0,0,0,0,0
0,0,0,0,0,0,0,0,0,0,0,0,0
0,0,0,0,0,0,0,0,0,0,0,0,0
0,0,0,0,0,0,0,0,0,0,0,0,0
0,0,0,0,0,0,0,0,0,0,0,0,0
0,0,0,0,0,0,0,0,0,0,0,0,0
0,0,0,0,0,0,0,0,0,0,0,0,0
0,0,0,0,0,0,0,0,0,0,0,0,0
0,0,0,0,0,0,0,0,0,0,0,0,0
0,0,0,0,0,0,0,0,0,0,0,0,0
0,0,0,0,0,0,0,0,0,0,0,0,0
:endlayer
layer: 63
0,0,0,0,0,0,0,0,0,0,0,0,0
0,0,0,0,0,0,0,0,0,0,0,0,0
0,0,0,0,0,0,0,0,0,0,0,0,0
0,0,0,0,0,0,0,0,0,0,0,0,0
0,0,0,0,0,0,0,0,0,0,0,0,0
0,0,0,0,0,0,0,0,0,0,0,0,0
0,0,0,0,0,0,0,0,0,0,0,0,0
0,0,0,0,0,0,0,0,0,0,0,0,0
0,0,0,0,0,0,0,0,0,0,0,0,0
0,0,0,0,0,0,0,0,0,0,0,0,0
0,0,0,0,0,0,0,0,0,0,0,0,0
0,0,0,0,0,0,0,0,0,0,0,0,0
:endlayer
layer: 64
0,0,0,0,0,0,0,0,0,0,0,0,0
0,0,0,0,0,0,0,0,0,0,0,0,0
0,0,0,0,0,0,0,0,0,0,0,0,0
0,0,0,0,0,0,0,0,0,0,0,0,0
0,0,0,0,0,0,0,0,0,0,0,0,0
0,0,0,0,0,0,0,0,0,0,0,0,0
0,0,0,0,0,0,0,0,0,0,0,0,0
0,0,0,0,0,0,0,0,0,0,0,0,0
0,0,0,0,0,0,0,0,0,0,0,0,0
0,0,0,0,0,0,0,0,0,0,0,0,0
0,0,0,0,0,0,0,0,0,0,0,0,0
0,0,0,0,0,0,0,0,0,0,0,0,0
:endlayer
layer: 65
0,0,0,0,0,0,0,0,0,0,0,0,0
0,0,0,0,0,0,0,0,0,0,0,0,0
0,0,0,0,0,0,0,0,0,0,0,0,0
0,0,0,0,0,0,0,0,0,0,0,0,0
0,0,0,0,0,0,0,0,0,0,0,0,0
0,0,0,0,0,0,0,0,0,0,0,0,0
0,0,0,0,0,0,0,0,0,0,0,0,0
0,0,0,0,0,0,0,0,0,0,0,0,0
0,0,0,0,0,0,0,0,0,0,0,0,0
0,0,0,0,0,0,0,0,0,0,0,0,0
0,0,0,0,0,0,0,0,0,0,0,0,0
0,0,0,0,0,0,0,0,0,0,0,0,0
:endlayer
layer: 66
0,0,0,0,0,0,0,0,0,0,0,0,0
0,0,0,0,0,0,0,0,0,0,0,0,0
0,0,0,0,0,0,0,0,0,0,0,0,0
0,0,0,0,0,0,0,0,0,0,0,0,0
0,0,0,0,0,0,0,0,0,0,0,0,0
0,0,0,0,0,0,0,0,0,0,0,0,0
0,0,0,0,0,0,0,0,0,0,0,0,0
0,0,0,0,0,0,0,0,0,0,0,0,0
0,0,0,0,0,0,0,0,0,0,0,0,0
0,0,0,0,0,0,0,0,0,0,0,0,0
0,0,0,0,0,0,0,0,0,0,0,0,0
0,0,0,0,0,0,0,0,0,0,0,0,0
:endlayer
layer: 67
0,0,0,0,0,0,0,0,0,0,0,0,0
0,0,0,0,0,0,0,0,0,0,0,0,0
0,0,0,0,0,0,0,0,0,0,0,0,0
0,0,0,0,0,0,0,0,0,0,0,0,0
0,0,0,0,0,0,0,0,0,0,0,0,0
0,0,0,0,0,0,0,0,0,0,0,0,0
0,0,0,0,0,0,0,0,0,0,0,0,0
0,0,0,0,0,0,0,0,0,0,0,0,0
0,0,0,0,0,0,0,0,0,0,0,0,0
0,0,0,0,0,0,0,0,0,0,0,0,0
0,0,0,0,0,0,0,0,0,0,0,0,0
0,0,0,0,0,0,0,0,0,0,0,0,0
:endlayer
layer: 68
0,0,0,0,0,0,0,0,0,0,0,0,0
0,0,0,0,0,0,0,0,0,0,0,0,0
0,0,0,0,0,0,0,0,0,0,0,0,0
0,0,0,0,0,0,0,0,0,0,0,0,0
0,0,0,0,0,0,0,0,0,0,0,0,0
0,0,0,0,0,0,0,0,0,0,0,0,0
0,0,0,0,0,0,0,0,0,0,0,0,0
0,0,0,0,0,0,0,0,0,0,0,0,0
0,0,0,0,0,0,0,0,0,0,0,0,0
0,0,0,0,0,0,0,0,0,0,0,0,0
0,0,0,0,0,0,0,0,0,0,0,0,0
0,0,0,0,0,0,0,0,0,0,0,0,0
:endlayer
layer: 69
0,0,0,0,0,0,0,0,0,0,0,0,0
0,0,0,0,0,0,0,0,0,0,0,0,0
0,0,0,0,0,0,0,0,0,0,0,0,0
0,0,0,0,0,0,0,0,0,0,0,0,0
0,0,0,0,0,0,0,0,0,0,0,0,0
0,0,0,0,0,0,0,0,0,0,0,0,0
0,0,0,0,0,0,0,0,0,0,0,0,0
0,0,0,0,0,0,0,0,0,0,0,0,0
0,0,0,0,0,0,0,0,0,0,0,0,0
0,0,0,0,0,0,0,0,0,0,0,0,0
0,0,0,0,0,0,0,0,0,0,0,0,0
0,0,0,0,0,0,0,0,0,0,0,0,0
:endlayer
layer: 70
0,0,0,0,0,0,0,0,0,0,0,0,0
0,0,0,0,0,0,0,0,0,0,0,0,0
0,0,0,0,0,0,0,0,0,0,0,0,0
0,0,0,0,0,0,0,0,0,0,0,0,0
0,0,0,0,0,0,0,0,0,0,0,0,0
0,0,0,0,0,0,0,0,0,0,0,0,0
0,0,0,0,0,0,0,0,0,0,0,0,0
0,0,0,0,0,0,0,0,0,0,0,0,0
0,0,0,0,0,0,0,0,0,0,0,0,0
0,0,0,0,0,0,0,0,0,0,0,0,0
0,0,0,0,0,0,0,0,0,0,0,0,0
0,0,0,0,0,0,0,0,0,0,0,0,0
:endlayer
layer: 71
0,0,0,0,0,0,0,0,0,0,0,0,0
0,0,0,0,0,0,0,0,0,0,0,0,0
0,0,0,0,0,0,0,0,0,0,0,0,0
0,0,0,0,0,0,0,0,0,0,0,0,0
0,0,0,0,0,0,0,0,0,0,0,0,0
0,0,0,0,0,0,0,0,0,0,0,0,0
0,0,0,0,0,0,0,0,0,0,0,0,0
0,0,0,0,0,0,0,0,0,0,0,0,0
0,0,0,0,0,0,0,0,0,0,0,0,0
0,0,0,0,0,0,0,0,0,0,0,0,0
0,0,0,0,0,0,0,0,0,0,0,0,0
0,0,0,0,0,0,0,0,0,0,0,0,0
:endlayer
layer: 72
0,0,0,0,0,0,0,0,0,0,0,0,0
0,0,0,0,0,0,0,0,0,0,0,0,0
0,0,0,0,0,0,0,0,0,0,0,0,0
0,0,0,0,0,0,0,0,0,0,0,0,0
0,0,0,0,0,0,0,0,0,0,0,0,0
0,0,0,0,0,0,0,0,0,0,0,0,0
0,0,0,0,0,0,0,0,0,0,0,0,0
0,0,0,0,0,0,0,0,0,0,0,0,0
0,0,0,0,0,0,0,0,0,0,0,0,0
0,0,0,0,0,0,0,0,0,0,0,0,0
0,0,0,0,0,0,0,0,0,0,0,0,0
0,0,0,0,0,0,0,0,0,0,0,0,0
:endlayer
layer: 73
0,0,0,0,0,0,0,0,0,0,0,0,0
0,0,0,0,0,0,0,0,0,0,0,0,0
0,0,0,0,0,0,0,0,0,0,0,0,0
0,0,0,0,0,0,0,0,0,0,0,0,0
0,0,0,0,0,0,0,0,0,0,0,0,0
0,0,0,0,0,0,0,0,0,0,0,0,0
0,0,0,0,0,0,0,0,0,0,0,0,0
0,0,0,0,0,0,0,0,0,0,0,0,0
0,0,0,0,0,0,0,0,0,0,0,0,0
0,0,0,0,0,0,0,0,0,0,0,0,0
0,0,0,0,0,0,0,0,0,0,0,0,0
0,0,0,0,0,0,0,0,0,0,0,0,0
:endlayer

#### RULES ####
rule:
plugin=vanillaBlocks
number=1
data:
JSON:{blockState:{blockName:"minecraft:stone",properties:{variant:"stone"}}}
:enddata
:endrule

rule:
plugin=vanillaBlocks
number=2
data:
JSON:{blockState:{blockName:"minecraft:iron_ore"}}
:enddata
:endrule

rule:
plugin=vanillaBlocks
number=3
data:
JSON:{blockState:{blockName:"minecraft:dirt",properties:{variant:"dirt",snowy:"false"}}}
:enddata
:endrule

rule:
plugin=vanillaBlocks
number=4
data:
JSON:{blockState:{blockName:"twilightforest:trollber"}}
:enddata
:endrule

rule:
plugin=vanillaBlocks
number=5
data:
JSON:{blockState:{blockName:"harvestcraft:pamdragonfruit",properties:{age:"2"}}}
:enddata
:endrule

rule:
plugin=inventory
number=6
data:
JSON:{blockState:{blockName:"minecraft:chest",properties:{facing:"south"}},lootLevel:0,teData:{ForgeData:{},Items:[{Slot:1b,id:"minecraft:leather",Count:1b,Damage:0s},{Slot:2b,id:"minecraft:leather",Count:1b,Damage:0s},{Slot:3b,id:"minecraft:beef",Count:3b,Damage:0s},{Slot:5b,id:"minecraft:snowball",Count:2b,Damage:0s},{Slot:6b,id:"minecraft:snowball",Count:1b,Damage:0s},{Slot:7b,id:"minecraft:snowball",Count:1b,Damage:0s},{Slot:8b,id:"minecraft:snowball",Count:1b,Damage:0s},{Slot:10b,id:"minecraft:leather",Count:1b,Damage:0s},{Slot:11b,id:"minecraft:leather",Count:1b,Damage:0s},{Slot:12b,id:"minecraft:leather",Count:2b,Damage:0s},{Slot:13b,id:"minecraft:beef",Count:2b,Damage:0s},{Slot:14b,id:"minecraft:snowball",Count:1b,Damage:0s},{Slot:15b,id:"minecraft:snowball",Count:1b,Damage:0s},{Slot:16b,id:"minecraft:snowball",Count:2b,Damage:0s},{Slot:17b,id:"minecraft:snowball",Count:2b,Damage:0s},{Slot:18b,id:"ebwizardry:spell_book",Count:1b,Damage:19s},{Slot:19b,id:"minecraft:beef",Count:2b,Damage:0s},{Slot:20b,id:"minecraft:leather",Count:2b,Damage:0s},{Slot:21b,id:"minecraft:leather",Count:2b,Damage:0s},{Slot:22b,id:"minecraft:beef",Count:3b,Damage:0s},{Slot:23b,id:"minecraft:snowball",Count:2b,Damage:0s},{Slot:24b,id:"minecraft:snowball",Count:2b,Damage:0s},{Slot:25b,id:"minecraft:snowball",Count:1b,Damage:0s}],id:"minecraft:chest",Lock:""},inventoryData:{length:23,inventoryContents:[{id:"minecraft:leather",Count:1b,slot:0,Damage:0s},{id:"minecraft:leather",Count:1b,slot:1,Damage:0s},{id:"minecraft:beef",Count:3b,slot:2,Damage:0s},{id:"minecraft:snowball",Count:2b,slot:3,Damage:0s},{id:"minecraft:snowball",Count:1b,slot:4,Damage:0s},{id:"minecraft:snowball",Count:1b,slot:5,Damage:0s},{id:"minecraft:snowball",Count:1b,slot:6,Damage:0s},{id:"minecraft:leather",Count:1b,slot:7,Damage:0s},{id:"minecraft:leather",Count:1b,slot:8,Damage:0s},{id:"minecraft:leather",Count:2b,slot:9,Damage:0s},{id:"minecraft:beef",Count:2b,slot:10,Damage:0s},{id:"minecraft:snowball",Count:1b,slot:11,Damage:0s},{id:"minecraft:snowball",Count:1b,slot:12,Damage:0s},{id:"minecraft:snowball",Count:2b,slot:13,Damage:0s},{id:"minecraft:snowball",Count:2b,slot:14,Damage:0s},{id:"ebwizardry:spell_book",Count:1b,slot:15,Damage:19s},{id:"minecraft:beef",Count:2b,slot:16,Damage:0s},{id:"minecraft:leather",Count:2b,slot:17,Damage:0s},{id:"minecraft:leather",Count:2b,slot:18,Damage:0s},{id:"minecraft:beef",Count:3b,slot:19,Damage:0s},{id:"minecraft:snowball",Count:2b,slot:20,Damage:0s},{id:"minecraft:snowball",Count:2b,slot:21,Damage:0s},{id:"minecraft:snowball",Count:1b,slot:22,Damage:0s}]},legacyFeatures:1b}
:enddata
:endrule

rule:
plugin=blockTile
number=7
data:
JSON:{blockState:{blockName:"ancientwarfarestructure:advanced_spawner",properties:{transparent:"true"}},teData:{id:"ancientwarfarestructure:advanced_spawner_tile",spawnerSettings:{minDelay:0,spawnDelay:0,lightSensitive:0b,spawnGroups:[{settingsList:[{remainingSpawnCount:1,hostile:1b,forced:1b,customTag:{},maxToSpawn:1,entityId:"grimoireofgaia:yeti",minToSpawn:1}],groupWeight:1}],playerRange:5,respondToRedstone:0b,inventory:{Size:9,Items:[]},spawnRange:0,transparent:1b,maxDelay:0,xpToDrop:0,mobRange:0,debugMode:0b,maxNearbyMonsters:0}}}
:enddata
:endrule

rule:
plugin=blockTile
number=8
data:
JSON:{blockState:{blockName:"ancientwarfarestructure:advanced_loot_chest",properties:{facing:"south"}},teData:{LootTable:"minecraft:chests/simple_dungeon",lootRolls:1b,lootSettings:{lootRolls:1,splashPotion:0b,hasLoot:1b,lootTableName:"minecraft:chests/simple_dungeon",spawnEntity:0b},id:"ancientwarfarestructure:advanced_loot_chest_tile",Lock:"",LootTableSeed:6722224575231245963L}}
:enddata
:endrule

rule:
plugin=vanillaBlocks
number=9
data:
JSON:{blockState:{blockName:"minecraft:grass",properties:{snowy:"false"}}}
:enddata
:endrule

rule:
plugin=vanillaBlocks
number=10
data:
JSON:{blockState:{blockName:"minecraft:snow_layer",properties:{layers:"1"}}}
:enddata
:endrule

rule:
plugin=vanillaBlocks
number=11
data:
JSON:{blockState:{blockName:"minecraft:snow_layer",properties:{layers:"2"}}}
:enddata
:endrule

rule:
plugin=blockTile
number=12
data:
JSON:{blockState:{blockName:"ancientwarfarestructure:advanced_spawner",properties:{transparent:"true"}},teData:{id:"ancientwarfarestructure:advanced_spawner_tile",spawnerSettings:{minDelay:0,spawnDelay:0,lightSensitive:0b,spawnGroups:[{settingsList:[{remainingSpawnCount:1,hostile:1b,forced:1b,customTag:{},maxToSpawn:1,entityId:"grimoireofgaia:yeti",minToSpawn:1}],groupWeight:1}],playerRange:9,respondToRedstone:0b,inventory:{Size:9,Items:[]},spawnRange:0,transparent:1b,maxDelay:0,xpToDrop:0,mobRange:0,debugMode:0b,maxNearbyMonsters:0}}}
:enddata
:endrule

rule:
plugin=vanillaBlocks
number=13
data:
JSON:{blockState:{blockName:"minecraft:log",properties:{variant:"spruce",axis:"y"}}}
:enddata
:endrule

rule:
plugin=vanillaBlocks
number=14
data:
JSON:{blockState:{blockName:"minecraft:stonebrick",properties:{variant:"cracked_stonebrick"}}}
:enddata
:endrule

rule:
plugin=vanillaBlocks
number=15
data:
JSON:{blockState:{blockName:"minecraft:leaves",properties:{check_decay:"false",decayable:"true",variant:"spruce"}}}
:enddata
:endrule

rule:
plugin=vanillaBlocks
number=16
data:
JSON:{blockState:{blockName:"minecraft:stone_slab",properties:{half:"bottom",variant:"stone_brick"}}}
:enddata
:endrule

rule:
plugin=vanillaBlocks
number=17
data:
JSON:{blockState:{blockName:"minecraft:tallgrass",properties:{type:"tall_grass"}}}
:enddata
:endrule

#### ENTITIES ####
