# Ancient Warfare Structure Template File
# Auto-generated structure template file. created on: 9/22/2018 at: 16:7:2
# Lines beginning with # denote comments

header:
version=2.6
name=jungle_fortress
size=25,33,21
offset=10,1,20
:endheader

#### VALIDATION ####
validation:
type=ground
survival=false
worldGenEnabled=true
unique=false
preserveBlocks=false
selectionWeight=10
clusterValue=125
minDuplicateDistance=40
dimensionWhiteList=true
dimensionList=0
biomeWhiteList=true
biomeList=minecraft:mutated_jungle_edge,biomesoplenty:tropical_rainforest,minecraft:jungle,minecraft:mutated_jungle,minecraft:jungle_hills,biomesoplenty:bamboo_forest
leveling=5
fill=5
border=5
blockSwap=false
data:
:enddata
:endvalidation

#### LAYERS ####
layer: 0
1,1,1,1,1,1,1,1,1,1,1,1,1,1,1,1,1,1,1,1,1,1,1,1,1
1,1,1,1,1,1,1,1,1,1,1,1,1,1,1,1,1,1,2,1,1,1,1,1,1
1,2,1,2,2,1,1,1,1,1,1,1,1,1,1,1,1,1,1,1,1,2,1,1,1
1,1,2,2,2,2,2,2,2,2,2,1,1,1,1,1,1,2,2,2,2,2,1,1,1
1,2,2,2,2,2,2,2,2,2,2,2,2,1,1,2,1,1,2,2,2,2,2,1,1
1,1,2,2,2,2,2,2,2,2,2,2,2,2,2,2,2,2,2,2,2,2,2,1,1
1,1,1,2,2,2,2,2,2,2,2,2,2,2,2,2,2,2,2,2,2,2,2,1,1
1,1,1,2,2,2,2,2,2,2,2,2,2,2,2,2,2,2,2,2,2,2,2,2,1
1,1,1,2,2,2,2,2,2,2,2,2,2,2,2,2,2,2,2,2,2,2,2,2,1
1,1,1,1,2,2,2,2,2,2,2,2,2,2,2,2,2,2,2,2,2,2,2,2,1
1,1,1,2,2,2,2,2,2,2,2,2,2,2,2,2,2,2,2,2,2,2,2,2,1
1,1,1,2,2,2,2,2,2,2,2,2,2,2,2,2,2,2,2,2,2,2,2,2,1
1,1,1,2,2,2,2,2,2,2,2,2,2,2,2,2,2,2,2,2,2,2,1,1,1
1,1,2,2,2,2,2,2,2,2,2,2,2,2,2,2,2,2,2,1,1,1,1,1,1
1,2,2,2,2,2,2,2,2,2,2,2,2,2,2,2,2,2,2,1,1,1,1,1,1
1,2,2,2,2,2,2,2,2,2,2,2,2,2,2,2,1,1,1,1,1,1,1,1,1
1,1,2,2,2,2,2,2,2,2,2,2,2,1,1,1,1,1,1,1,1,1,1,1,1
1,1,1,2,2,2,2,2,1,2,2,1,1,1,1,1,1,1,1,1,1,1,1,1,1
1,1,1,1,1,1,1,1,1,1,1,1,1,1,1,1,1,2,1,1,1,2,1,1,1
1,1,1,1,1,1,1,1,1,1,1,1,1,1,1,1,1,1,1,1,1,1,1,1,1
1,1,1,1,1,1,1,1,1,1,1,1,1,1,1,1,1,1,1,1,1,1,1,1,1
:endlayer
layer: 1
0,3,3,5,0,3,5,0,5,0,0,3,5,0,3,3,4,3,4,4,3,3,0,0,0
13,13,0,0,3,3,3,4,3,3,3,0,3,3,0,5,4,4,7,4,4,0,3,0,5
4,7,4,1,1,0,4,4,4,3,3,5,0,5,3,8,3,4,4,13,13,1,0,3,0
0,4,1,1,1,1,1,12,1,1,1,3,3,5,0,3,3,1,1,1,1,1,0,0,5
3,1,1,1,1,1,1,1,1,2,1,1,1,3,0,1,0,3,1,1,1,1,1,3,0
3,0,1,1,1,1,2,2,2,1,1,1,1,1,1,1,1,1,1,2,1,1,1,0,3
0,3,0,1,1,7,2,2,2,2,2,1,1,1,1,1,1,1,7,7,2,1,1,0,0
3,0,3,1,1,1,2,7,7,2,2,2,1,2,1,1,1,1,7,7,2,1,1,1,3
5,0,0,1,1,1,2,7,7,2,2,2,2,1,1,1,1,1,2,1,2,1,1,1,0
0,4,4,4,1,1,2,2,2,2,2,2,2,2,1,1,1,1,1,1,1,1,1,1,4
3,4,4,7,1,1,1,2,1,2,2,2,7,7,1,1,2,1,1,2,1,1,1,1,4
0,0,4,1,1,2,1,1,1,2,2,2,7,7,1,1,1,1,1,1,1,1,1,11,4
5,4,4,2,1,1,1,1,1,1,1,2,2,2,1,1,1,1,1,1,1,1,8,4,4
0,4,1,1,1,1,2,1,2,1,1,1,2,2,1,1,1,7,7,3,0,3,3,4,0
5,1,1,1,1,1,2,7,7,1,1,1,1,2,1,1,1,7,7,3,0,3,0,0,0
0,1,1,1,1,2,2,7,7,1,2,1,1,1,1,1,0,10,10,3,0,5,5,3,0
5,3,1,1,1,1,1,1,1,1,1,1,1,4,4,4,5,4,3,3,5,3,3,0,3
0,3,3,1,1,1,7,1,4,1,1,4,4,5,8,4,4,4,4,5,0,9,5,3,0
3,3,8,3,3,4,4,4,3,0,3,5,4,0,5,4,4,7,4,4,0,7,6,5,3
3,3,3,0,3,3,4,0,3,0,0,0,3,3,0,5,4,4,4,4,0,3,5,5,0
0,0,0,0,0,0,4,0,0,0,0,3,3,0,3,0,5,4,4,0,0,3,3,0,3
:endlayer
layer: 2
0,0,0,0,0,0,0,0,0,0,0,0,0,0,0,0,0,0,0,0,0,0,0,0,0
0,0,0,0,0,0,0,0,0,0,0,0,0,0,0,0,0,4,4,4,0,0,0,0,0
0,4,0,0,0,0,0,4,0,0,0,0,0,0,0,0,0,4,4,13,0,8,0,0,0
0,0,8,5,0,3,8,4,4,3,8,0,0,0,0,0,0,4,4,3,0,5,0,0,0
0,0,5,3,0,4,4,4,3,1,0,3,5,0,0,5,0,0,3,3,3,0,5,0,0
0,0,0,3,13,13,1,1,1,0,0,3,3,5,3,3,5,3,3,1,0,5,0,0,0
0,0,0,4,13,4,1,1,2,2,1,4,4,5,0,5,0,3,7,7,1,3,5,0,0
0,0,0,5,4,13,1,7,7,1,1,2,4,1,3,13,13,14,7,7,1,0,5,8,0
0,0,0,8,3,4,1,7,7,2,1,1,1,4,4,13,13,13,1,10,1,3,5,3,0
0,0,0,4,4,0,1,1,2,1,1,1,1,1,13,13,13,13,3,0,0,5,3,3,0
0,0,4,4,4,4,4,1,13,1,2,1,7,7,13,13,7,13,0,1,3,0,4,4,4
0,0,0,4,4,1,4,3,13,7,1,1,7,7,13,13,13,13,3,3,5,4,4,4,4
0,0,4,7,4,4,4,0,13,13,13,1,1,7,13,13,0,9,9,5,0,4,0,0,0
0,0,4,4,4,4,1,3,1,13,13,13,1,7,4,4,3,7,7,6,0,0,0,0,0
0,8,4,4,4,0,1,7,7,13,13,13,13,1,4,4,14,7,7,6,0,0,0,0,0
0,3,0,4,3,1,1,7,7,13,7,13,13,5,3,4,0,10,10,0,0,0,0,0,0
0,0,3,0,3,13,13,13,3,13,13,13,4,4,0,0,0,0,0,0,0,0,0,0,0
0,0,0,0,4,4,4,4,0,8,4,4,0,0,0,0,0,4,0,0,0,9,0,0,0
0,0,0,0,0,0,4,0,0,0,0,0,0,0,0,0,4,4,4,0,0,7,6,0,0
0,0,0,0,0,0,0,0,0,0,0,0,0,0,0,0,0,0,4,0,0,10,0,0,0
0,0,0,0,0,0,0,0,0,0,0,0,0,0,0,0,0,0,0,0,0,0,0,0,0
:endlayer
layer: 3
0,0,0,0,0,0,0,0,0,0,0,0,0,0,0,0,0,0,0,0,0,0,0,0,0
0,0,0,0,0,0,0,0,0,0,0,0,0,0,0,0,0,0,0,0,0,0,0,0,0
0,0,0,0,0,0,0,0,0,0,0,0,0,0,0,0,0,0,0,0,0,0,0,0,0
0,0,0,0,0,0,0,0,0,0,0,0,0,0,0,0,0,0,0,0,0,0,0,0,0
0,0,0,0,0,0,0,0,0,3,0,0,0,0,0,0,0,0,0,0,0,0,0,0,0
0,0,0,0,0,0,3,0,0,0,0,0,0,0,0,0,0,0,9,3,0,0,0,0,0
0,0,0,0,0,4,4,9,1,1,4,4,0,0,0,0,0,14,7,7,3,0,0,0,0
0,0,0,0,0,0,14,7,7,4,4,7,4,0,0,0,0,14,7,7,6,0,0,0,0
0,0,0,0,0,0,14,7,7,1,13,13,13,0,0,0,0,0,3,10,0,0,0,0,0
0,0,0,0,0,0,3,3,1,0,13,13,5,13,13,13,0,0,0,0,0,0,0,0,0
0,0,0,0,4,0,0,3,0,13,7,13,7,7,11,13,13,0,0,5,0,0,0,0,0
0,0,0,4,4,4,0,0,0,4,13,13,7,7,13,13,0,0,0,0,0,0,0,4,0
0,0,4,4,4,0,0,0,0,0,0,0,5,19,18,13,0,9,9,0,0,0,0,0,0
0,0,0,4,0,0,0,9,5,0,0,0,4,13,13,13,14,7,7,6,0,0,0,0,0
0,0,0,0,0,0,3,7,7,6,4,0,0,13,4,0,14,7,7,6,0,0,0,0,0
0,0,0,0,0,0,5,7,7,4,13,0,0,0,0,0,0,10,10,0,0,0,0,0,0
0,0,0,0,0,0,0,10,17,0,4,0,0,0,0,0,0,0,0,0,0,0,0,0,0
0,0,0,0,0,0,4,0,0,0,0,0,0,0,0,0,0,0,0,0,0,9,0,0,0
0,0,0,0,0,0,0,0,0,0,0,0,0,0,0,0,0,0,0,0,16,7,15,0,0
0,0,0,0,0,0,0,0,0,0,0,0,0,0,0,0,0,0,0,0,0,10,0,0,0
0,0,0,0,0,0,0,0,0,0,0,0,0,0,0,0,0,0,0,0,0,0,0,0,0
:endlayer
layer: 4
0,0,0,0,0,0,0,0,0,0,0,0,0,0,0,0,0,0,0,0,0,0,0,0,0
0,0,0,0,0,0,0,0,0,0,0,0,0,0,0,0,0,0,0,0,0,0,0,0,0
0,0,0,0,0,0,0,0,0,0,0,0,0,0,0,0,0,0,0,0,0,0,0,0,0
0,0,0,0,0,0,0,0,0,0,0,0,0,0,0,0,0,0,0,0,0,0,0,0,0
0,0,0,0,0,0,0,0,0,0,0,0,0,0,0,0,0,0,0,0,0,0,0,0,0
0,0,0,0,0,4,4,4,0,0,0,0,0,0,0,0,0,0,9,22,0,0,0,0,0
0,0,0,0,0,0,0,9,9,3,0,0,0,0,0,0,0,14,7,7,6,0,0,0,0
0,0,0,0,0,0,14,7,7,15,0,4,0,0,0,0,0,16,7,7,6,0,0,0,0
0,0,0,0,0,0,14,7,7,3,13,13,13,0,0,0,0,0,10,10,0,0,0,0,0
0,0,0,0,0,0,0,10,10,0,0,0,13,13,13,13,0,0,0,0,0,0,0,0,0
0,0,0,0,0,0,0,0,0,0,13,13,7,7,13,13,13,0,0,0,0,0,0,0,0
0,0,0,0,0,0,0,0,0,0,0,13,7,7,21,13,0,0,0,0,0,0,0,0,0
0,0,0,4,0,0,0,0,0,0,0,0,0,0,0,13,0,9,20,0,0,0,0,0,0
0,0,0,0,0,0,0,9,20,0,0,0,4,13,13,13,4,7,7,4,0,0,0,0,0
0,0,0,0,0,0,14,7,7,6,0,0,0,0,4,0,14,7,7,6,0,0,0,0,0
0,0,0,0,0,0,14,7,7,6,0,0,0,0,0,0,0,17,10,0,0,0,0,0,0
0,0,0,0,0,0,0,10,10,0,0,0,0,0,0,0,0,0,0,0,0,0,0,0,0
0,0,0,0,0,0,0,0,0,0,0,0,0,0,0,0,0,0,0,0,0,0,0,0,0
0,0,0,0,0,0,0,0,0,0,0,0,0,0,0,0,0,0,0,0,14,7,0,0,0
0,0,0,0,0,0,0,0,0,0,0,0,0,0,0,0,0,0,0,0,0,10,0,0,0
0,0,0,0,0,0,0,0,0,0,0,0,0,0,0,0,0,0,0,0,0,0,0,0,0
:endlayer
layer: 5
0,0,0,0,0,0,0,0,0,0,0,0,0,0,0,0,0,0,0,0,0,0,0,0,0
0,0,0,0,0,0,0,0,0,0,0,0,0,0,0,0,0,0,0,0,0,0,0,0,0
0,0,0,0,0,0,0,0,0,0,0,0,0,0,0,0,0,0,0,0,0,0,0,0,0
0,0,0,0,0,0,0,0,0,0,0,0,0,0,0,0,0,0,0,0,0,0,0,0,0
0,0,0,0,0,4,4,4,4,0,0,0,0,0,0,0,0,0,0,0,0,0,0,0,0
0,0,0,0,4,11,11,12,4,0,0,0,0,0,0,0,0,0,9,22,0,0,0,0,0
0,0,0,0,4,4,4,12,4,0,0,0,0,0,0,0,0,14,7,7,6,0,0,0,0
0,0,0,0,0,0,14,7,7,6,0,0,0,0,0,0,0,0,7,7,6,0,0,0,0
0,0,0,0,0,0,14,7,7,6,0,13,0,13,13,13,0,0,10,10,0,0,0,0,0
0,0,0,0,0,0,0,10,10,0,0,13,13,12,18,13,0,0,0,0,0,0,0,0,0
0,0,0,0,0,0,0,0,0,0,13,13,7,7,21,13,13,0,0,0,0,0,0,0,0
0,0,0,0,0,0,0,0,0,0,13,11,7,7,0,13,0,0,0,13,0,0,0,0,0
0,0,0,0,0,0,0,0,0,0,0,0,0,0,0,4,0,9,4,4,13,0,0,0,0
0,0,0,0,0,0,0,9,9,0,0,0,13,13,4,0,4,7,7,4,4,0,0,0,0
0,0,0,0,0,0,14,7,7,6,0,0,0,0,0,0,13,7,7,4,0,0,0,0,0
0,0,0,0,0,0,14,7,7,6,0,0,0,0,0,0,0,0,10,0,0,0,0,0,0
0,0,0,0,0,0,0,10,10,0,0,0,0,0,0,0,0,0,0,0,0,0,0,0,0
0,0,0,0,0,0,0,0,0,0,0,0,0,0,0,0,0,0,0,0,0,0,0,0,0
0,0,0,0,0,0,0,0,0,0,0,0,0,0,0,0,0,0,0,0,14,7,23,0,0
0,0,0,0,0,0,0,0,0,0,0,0,0,0,0,0,0,0,0,0,0,10,0,0,0
0,0,0,0,0,0,0,0,0,0,0,0,0,0,0,0,0,0,0,0,0,0,0,0,0
:endlayer
layer: 6
0,0,0,0,0,0,0,0,0,0,0,0,0,0,0,0,0,0,0,0,0,0,0,0,0
0,0,0,0,0,0,0,0,0,0,0,0,0,0,0,0,0,0,0,0,0,0,0,0,0
0,0,0,0,0,0,0,0,0,0,0,0,0,0,0,0,0,0,0,0,0,0,0,0,0
0,0,0,0,0,0,4,4,0,0,0,0,0,0,0,0,0,0,0,0,0,0,0,0,0
0,0,0,0,4,4,4,4,4,0,0,0,0,0,0,0,0,0,0,0,0,0,0,0,0
0,0,0,4,11,7,4,4,0,0,0,0,0,0,0,0,0,0,9,9,0,0,0,0,0
0,0,0,4,12,4,4,4,4,0,0,0,0,0,0,0,4,14,7,7,6,0,0,0,0
0,0,0,13,4,4,14,7,7,4,0,0,0,0,0,4,4,4,7,7,6,0,0,0,0
0,0,0,0,0,0,14,7,7,6,0,0,13,13,13,13,0,0,0,10,0,0,0,0,0
0,0,0,0,0,0,0,26,10,0,0,13,12,25,0,13,0,0,0,0,0,0,0,0,0
0,0,0,0,0,0,0,0,0,0,13,13,7,7,0,13,0,0,0,0,0,0,0,0,0
0,0,0,0,0,0,0,0,0,0,13,13,7,7,0,13,0,0,0,13,13,0,0,0,0
0,0,0,0,0,0,0,0,0,0,0,13,0,0,0,13,0,9,4,4,13,0,0,0,0
0,0,0,0,0,0,0,9,9,0,0,4,13,4,4,0,14,7,7,4,4,4,0,0,0
0,0,0,0,0,0,14,7,7,6,0,0,0,0,0,0,13,7,7,4,4,0,0,0,0
0,0,0,0,0,0,14,7,7,24,0,0,0,0,0,0,4,13,13,4,0,0,0,0,0
0,0,0,0,0,0,0,10,10,0,0,0,0,0,0,0,0,0,0,0,13,13,13,0,0
0,0,0,0,0,0,0,0,0,0,0,0,0,0,0,0,0,0,0,4,13,7,13,4,0
0,0,0,0,0,0,0,0,0,0,0,0,0,0,0,0,0,0,0,4,13,7,13,0,0
0,0,0,0,0,0,0,0,0,0,0,0,0,0,0,0,0,0,0,0,4,4,4,0,0
0,0,0,0,0,0,0,0,0,0,0,0,0,0,0,0,0,0,0,0,0,0,0,0,0
:endlayer
layer: 7
0,0,0,0,0,0,0,0,0,0,0,0,0,0,0,0,0,0,0,0,0,0,0,0,0
0,0,0,0,0,0,0,0,0,0,0,0,0,0,0,0,0,0,0,0,0,0,0,0,0
0,0,0,0,0,0,0,0,0,0,0,0,0,0,0,0,0,0,0,0,0,0,0,0,0
0,0,0,0,0,4,0,0,0,0,0,0,0,0,0,0,0,0,0,0,0,0,0,0,0
0,0,0,13,13,4,4,4,0,0,0,0,0,0,0,0,0,0,0,0,0,0,0,0,0
0,0,0,13,13,4,4,4,4,0,0,0,0,0,0,4,4,0,9,9,0,0,0,0,0
0,0,0,13,13,4,4,4,4,4,0,0,0,0,0,4,4,4,7,7,6,0,0,0,0
0,0,13,13,4,0,14,7,7,4,0,0,0,0,0,4,11,11,7,7,6,0,0,0,0
0,0,0,13,0,0,14,7,7,6,13,13,13,13,13,4,4,4,4,10,0,0,0,0,0
0,0,0,0,0,0,0,26,10,0,13,18,25,0,0,13,0,4,4,0,0,0,0,0,0
0,0,0,0,0,0,0,0,0,0,13,11,7,7,0,13,0,0,0,0,0,0,0,0,0
0,0,0,0,0,0,0,0,0,0,0,13,7,7,0,13,0,0,0,0,0,0,0,0,0
0,0,0,0,0,0,0,0,0,0,0,4,4,12,4,13,0,9,9,4,0,0,0,0,0
0,0,0,0,0,0,0,9,9,0,0,0,4,4,13,0,14,7,7,4,0,0,0,0,0
0,0,0,0,4,4,14,7,7,6,0,0,0,0,0,0,14,7,7,6,0,4,4,0,0
0,0,0,0,4,4,4,7,7,6,0,0,0,0,0,0,0,10,4,0,4,4,4,4,0
0,0,0,0,0,0,4,4,4,0,0,0,0,0,0,0,0,0,0,0,4,7,4,4,0
0,0,0,0,0,0,0,0,4,0,0,0,0,0,0,0,0,0,0,0,13,4,13,4,0
0,0,0,0,0,0,0,0,4,4,0,0,0,0,0,0,0,0,0,0,0,7,6,0,0
0,0,0,0,0,0,0,0,0,0,0,0,0,0,0,0,0,0,0,0,0,10,0,0,0
0,0,0,0,0,0,0,0,0,0,0,0,0,0,0,0,0,0,0,0,0,0,0,0,0
:endlayer
layer: 8
0,0,0,0,0,0,0,0,0,0,0,0,0,0,0,0,0,0,0,0,0,0,0,0,0
0,0,0,0,0,0,0,0,0,0,0,0,0,0,0,0,0,0,0,0,0,0,0,0,0
0,0,0,0,0,0,0,0,0,0,0,0,0,0,0,0,0,0,0,4,0,4,0,0,0
0,0,0,0,0,0,0,0,0,0,0,0,0,0,0,0,0,0,4,4,4,4,0,0,0
0,0,0,0,0,0,0,0,0,0,0,0,0,0,0,0,0,0,4,12,11,4,4,0,0
0,0,0,0,4,4,0,0,0,0,0,0,0,0,0,0,0,4,4,12,4,4,0,0,0
0,0,13,13,13,0,0,9,4,0,0,0,0,0,0,0,4,14,7,7,6,0,0,0,0
0,4,13,13,0,0,14,7,7,6,0,0,0,4,0,4,4,4,7,7,23,0,0,0,0
0,0,13,0,0,0,14,7,7,6,13,13,13,13,13,13,0,4,10,10,0,0,0,0,0
0,0,0,0,0,0,0,10,10,0,13,0,0,0,0,13,0,0,0,0,0,0,0,0,0
0,0,0,0,0,0,0,0,0,4,13,28,7,7,0,13,0,0,0,0,0,0,0,0,0
0,0,0,0,0,0,0,0,0,0,13,13,7,7,4,13,0,0,0,0,0,0,0,0,0
0,0,0,0,0,4,0,0,0,0,0,13,13,13,4,13,0,9,9,0,0,0,0,0,0
0,0,0,0,4,4,4,9,9,0,0,4,4,4,13,13,14,7,7,6,0,0,0,0,0
0,0,0,4,4,11,11,7,7,6,0,0,0,0,13,0,14,7,7,6,0,0,0,0,0
0,0,0,4,11,12,4,7,7,6,0,0,0,0,0,0,0,10,10,0,0,4,4,0,0
0,0,4,4,4,4,4,4,12,4,4,0,0,0,0,0,0,0,0,0,4,4,4,4,0
0,0,0,0,0,4,4,4,12,4,4,4,0,0,0,0,0,0,0,0,0,0,4,0,0
0,0,0,0,0,0,0,4,12,11,4,4,0,0,0,0,0,0,0,0,27,7,6,0,0
0,0,0,0,0,0,0,4,4,4,0,0,0,0,0,0,0,0,0,0,0,0,0,0,0
0,0,0,0,0,0,0,0,0,0,0,0,0,0,0,0,0,0,0,0,0,0,0,0,0
:endlayer
layer: 9
0,0,0,0,0,0,0,0,0,0,0,0,0,0,0,0,0,0,0,0,0,0,0,0,0
0,0,0,0,0,0,0,0,0,0,0,0,0,0,0,0,0,0,0,0,0,0,0,0,0
0,0,0,0,0,0,0,0,0,0,0,0,0,0,0,0,0,0,0,0,0,0,0,0,0
0,0,0,0,0,0,0,0,0,0,0,0,0,0,0,0,0,0,4,4,4,4,0,0,0
0,0,0,0,0,0,0,0,0,0,0,0,0,0,0,0,0,0,0,4,4,0,0,0,0
0,0,0,0,0,0,0,0,0,0,0,0,0,0,0,0,0,0,9,4,0,0,0,0,0
0,0,0,0,0,0,0,9,9,0,0,0,0,0,0,0,0,14,7,7,6,0,0,0,0
0,0,4,0,0,0,27,7,7,6,0,0,0,4,0,0,0,14,7,7,6,0,0,0,0
0,0,0,0,0,0,14,7,7,6,0,13,13,13,13,13,0,0,10,10,0,0,0,0,0
0,0,0,0,0,0,0,10,10,4,13,0,0,0,0,13,0,0,0,0,0,0,0,0,0
0,0,0,0,0,0,0,0,4,4,13,0,7,7,4,13,0,0,0,0,0,0,0,0,0
0,0,0,0,0,0,0,0,0,4,13,28,7,7,11,13,0,0,0,0,0,0,0,0,0
0,0,0,0,0,0,0,0,0,0,13,18,12,13,12,13,0,9,9,0,0,0,0,0,0
0,0,0,0,0,0,0,9,9,0,13,13,13,4,12,4,14,7,7,6,0,0,0,0,0
0,0,0,0,0,4,4,7,7,6,0,0,0,4,4,4,14,7,7,6,0,0,0,0,0
0,0,0,0,4,4,4,7,7,6,0,0,0,0,4,0,0,0,10,0,0,0,0,0,0
0,0,0,0,0,0,0,4,4,0,0,0,0,0,0,0,0,0,0,0,0,0,0,0,0
0,0,0,0,0,0,0,0,4,4,4,0,0,0,0,0,0,0,0,0,0,0,0,0,0
0,0,0,0,0,0,0,4,4,7,4,0,0,0,0,0,0,0,0,0,0,7,4,0,0
0,0,0,0,0,0,0,0,4,12,4,4,0,0,0,0,0,0,0,0,0,0,0,0,0
0,0,0,0,0,0,0,0,4,4,4,0,0,0,0,0,0,0,0,0,0,0,0,0,0
:endlayer
layer: 10
0,0,0,0,0,0,0,0,0,0,0,0,0,0,0,0,0,0,0,0,0,0,0,0,0
0,0,0,0,0,0,0,0,0,0,0,0,0,0,0,0,0,0,0,0,0,0,0,0,0
0,0,0,0,0,0,0,0,0,0,0,0,0,0,0,0,0,0,0,0,0,0,0,0,0
0,0,0,0,0,0,0,0,0,0,0,0,0,0,0,0,0,0,0,0,0,0,0,0,0
0,0,0,0,0,0,0,0,4,4,4,4,0,0,0,0,0,0,0,0,4,0,0,0,0
0,0,0,0,0,0,0,0,4,0,0,0,0,0,0,0,0,4,9,9,0,0,0,0,0
0,0,0,0,0,4,4,9,9,0,0,0,0,0,0,4,0,14,7,7,6,4,0,0,0
0,0,0,0,0,0,4,7,7,6,4,0,4,4,4,4,4,4,7,7,4,4,0,0,0
0,0,0,0,0,0,14,7,7,0,13,13,13,13,13,13,0,0,10,10,0,0,0,0,0
0,0,0,0,0,0,0,10,10,4,13,0,0,20,4,13,0,0,0,0,0,0,0,0,0
0,0,0,0,0,0,0,4,4,4,13,0,7,7,4,13,13,0,4,0,0,0,0,0,0
0,0,0,0,0,0,4,4,4,4,13,0,7,7,13,13,13,0,4,4,4,0,0,0,0
0,0,0,0,0,4,4,0,0,4,13,0,19,12,13,0,0,4,4,4,0,0,0,0,0
0,0,0,0,0,0,0,9,9,0,13,13,13,13,4,0,14,7,7,6,0,0,0,0,0
0,0,0,0,0,0,14,7,7,4,4,4,0,4,4,0,14,7,7,24,0,0,0,0,0
0,0,0,0,0,4,14,7,7,6,0,4,0,0,4,4,0,4,10,0,0,0,0,0,0
0,0,0,0,0,4,0,10,10,0,0,4,0,0,4,4,4,4,4,4,0,4,0,0,0
0,0,0,0,0,0,0,0,0,0,0,0,0,0,0,0,0,4,0,4,0,4,4,4,0
0,0,0,0,0,0,0,0,0,4,0,0,0,0,0,0,0,0,0,0,0,7,7,4,0
0,0,0,0,0,0,0,0,0,4,0,0,0,0,0,0,0,0,0,0,0,4,4,4,0
0,0,0,0,0,0,0,0,0,0,0,0,0,0,0,0,0,0,0,0,0,0,0,0,0
:endlayer
layer: 11
0,0,0,0,0,0,0,0,0,0,0,0,0,0,0,0,0,0,0,0,0,0,0,0,0
0,0,0,0,0,0,0,0,0,0,0,0,0,0,0,0,0,0,0,0,0,0,0,0,0
0,0,0,0,0,0,0,0,4,0,4,0,0,0,0,4,4,0,0,0,0,0,0,0,0
0,0,0,0,0,0,0,4,13,13,13,13,4,0,0,4,4,4,0,0,0,0,0,0,0
0,0,0,0,0,4,0,4,12,11,11,11,4,0,0,0,4,4,4,0,0,0,0,0,0
0,0,0,0,4,4,4,4,12,4,4,4,4,0,0,4,4,7,4,0,0,4,4,0,0
0,0,0,0,4,11,12,4,12,4,4,0,0,0,4,12,4,4,7,7,4,12,4,0,0
0,0,0,0,4,4,11,7,7,4,12,4,4,4,11,11,11,11,7,7,11,11,4,0,0
0,0,0,0,0,0,4,7,7,11,11,13,11,12,13,12,13,4,10,4,4,4,4,0,0
0,0,0,0,0,0,4,12,13,13,13,13,13,12,13,13,0,0,4,4,4,4,4,0,0
0,0,0,0,0,0,4,12,13,13,13,0,7,7,13,12,13,4,12,4,4,4,4,0,0
0,0,0,0,4,4,11,12,11,11,13,0,7,7,11,11,11,4,12,11,11,4,4,0,0
0,0,0,4,4,11,12,4,13,12,13,0,0,19,13,13,13,9,12,4,4,4,4,0,0
0,0,0,4,4,4,4,9,9,13,13,4,4,13,13,0,13,7,7,4,0,0,0,0,0
0,0,0,4,4,4,14,7,7,11,11,11,13,4,4,0,13,7,7,4,0,4,0,0,0
0,0,0,4,4,11,11,7,7,6,13,12,13,4,4,13,13,12,4,4,4,4,0,0,0
0,0,0,4,4,12,4,4,10,0,13,12,13,0,13,11,11,12,11,11,4,12,4,0,0
0,0,0,0,4,4,4,0,0,0,4,13,4,0,4,4,4,12,4,12,4,12,4,4,0
0,0,0,0,0,4,0,0,0,0,0,4,0,0,0,4,4,4,4,4,4,7,4,4,4
0,0,0,0,0,0,0,0,0,0,0,0,0,0,0,0,4,0,4,0,0,4,4,4,0
0,0,0,0,0,0,0,0,0,0,0,0,0,0,0,0,0,0,0,0,0,0,0,0,0
:endlayer
layer: 12
0,0,0,0,0,0,0,0,0,0,0,0,0,0,0,0,34,0,0,0,0,0,0,0,0
0,0,0,0,0,0,0,0,0,0,0,0,0,0,34,34,34,34,34,0,0,0,0,0,0
0,0,0,0,0,0,0,0,4,4,0,0,0,0,34,34,34,34,34,0,0,0,0,0,0
0,0,0,0,0,0,0,4,33,33,33,33,33,33,33,32,7,13,4,0,0,0,0,0,0
0,0,0,0,0,0,30,33,30,32,32,32,32,32,32,32,32,7,33,33,31,0,0,0,0
0,0,0,0,0,33,30,32,32,32,32,32,32,32,32,32,32,32,32,32,33,31,0,0,0
0,0,0,0,4,30,32,32,32,32,32,32,32,32,32,32,32,32,7,7,32,31,4,0,0
0,0,0,0,33,30,32,7,7,32,32,32,32,32,32,32,32,32,7,7,32,33,31,0,0
0,0,0,0,30,32,32,7,7,32,32,32,32,32,32,32,32,32,32,32,32,32,31,0,0
0,0,0,0,30,32,32,32,32,32,32,32,32,32,32,32,32,32,32,32,32,32,31,0,0
0,0,0,0,30,32,32,32,32,32,32,29,7,7,32,32,32,32,32,32,32,32,31,0,0
0,0,0,0,30,32,32,32,32,32,32,18,7,7,32,32,32,32,32,32,32,32,31,0,0
0,0,0,0,30,32,32,32,32,32,32,0,0,10,19,32,32,32,32,32,32,32,31,0,0
0,0,0,0,30,32,32,32,32,32,32,32,32,32,32,32,32,7,7,32,32,32,31,0,0
0,0,0,0,30,32,32,7,7,32,32,32,32,32,32,32,32,7,7,32,32,32,31,0,0
0,0,0,0,30,29,32,7,7,32,32,32,32,32,32,32,32,32,32,32,32,32,31,0,0
0,0,0,4,4,30,32,32,32,32,32,32,32,32,32,32,32,32,32,32,32,32,4,0,0
0,0,0,0,4,30,32,32,32,32,32,32,32,32,32,32,32,32,32,32,32,32,4,0,0
0,0,0,0,0,4,30,29,30,32,32,32,32,32,32,32,32,32,31,29,30,7,6,4,0
0,0,0,0,0,0,0,0,29,29,29,29,29,29,29,29,29,29,29,0,4,4,0,0,0
0,0,0,0,0,0,0,0,0,0,0,0,0,0,0,0,0,0,0,0,0,0,0,0,0
:endlayer
layer: 13
0,0,0,0,0,0,0,0,0,0,0,0,0,0,0,0,0,0,0,0,0,0,0,0,0
0,0,0,0,0,0,0,0,0,0,0,0,0,0,0,4,34,0,0,0,0,0,0,0,0
0,0,0,0,0,0,0,0,4,4,0,0,0,0,0,34,34,34,4,0,0,0,0,0,0
0,0,0,0,0,0,0,4,32,32,32,32,32,32,4,13,7,34,13,4,0,0,0,0,0
0,0,0,0,0,0,32,32,0,0,0,48,32,51,0,0,50,32,32,32,32,0,0,0,0
0,0,0,0,0,32,0,0,0,0,0,47,32,49,0,0,0,0,9,9,0,32,0,0,0
0,0,0,0,0,32,7,8,9,0,0,44,32,32,32,32,32,32,7,7,6,32,4,0,0
0,0,0,0,32,32,8,7,7,6,0,0,46,47,45,46,47,45,7,7,6,32,32,0,0
0,0,0,0,32,0,14,7,7,6,0,0,0,0,0,0,0,0,10,10,0,48,32,0,0
0,0,0,0,32,0,0,10,10,0,0,4,4,9,0,0,0,0,0,0,47,45,32,0,0
0,0,0,0,32,0,0,0,0,0,0,4,7,7,6,47,47,47,0,0,47,45,32,0,0
0,0,0,0,32,0,8,0,0,0,13,13,7,7,46,44,44,44,45,0,8,44,32,0,0
0,0,0,0,32,0,19,31,0,0,4,13,0,10,0,0,0,9,9,0,0,0,32,0,0
0,0,0,0,32,0,43,0,0,0,0,0,0,8,0,0,14,7,7,0,0,0,32,0,0
0,0,0,0,32,0,42,7,7,41,0,0,0,0,0,0,14,7,7,6,0,0,32,0,0
0,0,0,0,32,0,40,7,7,39,0,0,0,0,0,0,0,10,10,0,0,0,32,0,0
0,0,0,0,4,32,38,37,36,35,0,0,0,0,0,0,0,0,0,0,8,32,0,0,0
0,0,0,0,0,32,8,0,0,0,0,0,0,8,0,0,0,0,0,0,0,32,0,0,0
0,0,0,0,0,4,32,32,0,0,0,0,0,0,0,19,31,0,0,32,32,7,6,0,0
0,0,0,0,0,0,0,0,32,32,32,32,32,32,32,32,32,32,32,0,0,10,0,0,0
0,0,0,0,0,0,0,0,0,0,0,0,0,0,0,0,0,0,0,0,0,0,0,0,0
:endlayer
layer: 14
0,0,0,0,0,0,0,0,0,0,0,0,0,0,0,0,0,0,0,0,0,0,0,0,0
0,0,0,0,0,0,0,0,0,0,0,0,0,0,0,0,0,0,0,0,0,0,0,0,0
0,0,0,0,0,0,0,0,4,0,0,0,0,0,0,4,34,13,0,0,0,0,0,0,0
0,0,0,0,0,0,0,0,4,4,4,0,0,0,4,34,34,34,4,4,0,0,0,0,0
0,0,0,0,0,4,4,4,0,0,0,0,0,0,0,0,0,13,13,13,4,0,0,0,0
0,0,0,0,4,7,0,0,0,0,0,52,0,0,0,0,0,0,9,9,0,4,0,0,0
0,0,0,0,4,7,0,9,9,0,0,0,8,0,0,0,0,14,7,7,6,4,4,0,0
0,0,0,0,4,0,14,7,7,6,0,0,0,52,0,0,52,14,7,7,6,0,13,0,0
0,0,0,0,4,0,14,7,7,6,0,0,0,0,0,0,0,0,10,10,0,0,4,0,0
0,0,0,0,0,0,0,10,10,0,0,4,9,9,0,0,0,0,0,0,52,0,4,0,0
0,0,0,0,0,0,0,0,0,0,0,4,7,7,6,52,52,52,0,0,52,0,4,0,0
0,0,0,0,0,0,0,0,0,0,13,7,7,7,6,0,0,0,0,0,0,0,4,0,0
0,0,0,0,0,0,0,19,31,0,4,7,0,10,0,0,0,0,0,0,0,0,4,0,0
0,0,0,0,0,0,0,9,0,0,0,13,0,0,0,0,0,7,7,0,0,0,4,0,0
0,0,0,0,0,0,14,7,7,0,0,0,0,0,0,0,14,7,7,6,0,0,4,0,0
0,0,0,0,0,0,14,7,7,6,0,0,0,0,0,0,0,10,0,0,0,0,4,0,0
0,0,0,0,0,0,0,10,10,0,0,0,0,0,0,0,0,0,0,0,0,4,0,0,0
0,0,0,0,0,0,0,0,0,0,0,0,0,0,0,0,0,0,0,0,0,0,0,0,0
0,0,0,0,0,0,0,0,0,0,0,0,0,0,0,0,19,31,0,0,14,7,6,0,0
0,0,0,0,0,0,0,0,0,0,0,0,0,0,0,0,0,0,0,0,0,10,0,0,0
0,0,0,0,0,0,0,0,0,0,0,0,0,0,0,0,0,0,0,0,0,0,0,0,0
:endlayer
layer: 15
0,0,0,0,0,0,0,0,0,0,0,0,0,0,0,0,0,0,0,0,0,0,0,0,0
0,0,0,0,0,0,0,0,0,0,0,0,0,0,0,0,0,0,0,0,0,0,0,0,0
0,0,0,0,0,0,0,0,0,0,0,0,0,0,0,0,13,0,0,0,0,0,0,0,0
0,0,0,0,34,4,0,0,4,4,4,0,0,0,0,13,13,4,4,0,0,0,0,0,0
0,0,0,34,34,34,4,4,0,0,0,0,0,0,0,0,0,13,13,13,4,0,0,0,0
0,0,34,34,7,34,34,0,0,0,0,0,0,0,0,0,0,0,9,0,0,4,0,0,0
0,0,0,34,34,34,0,7,9,0,0,0,0,0,0,0,0,14,7,7,6,4,0,0,0
0,0,0,0,34,0,14,7,7,6,0,0,0,0,0,0,0,16,7,7,6,0,13,0,0
0,0,0,0,4,0,14,7,7,6,0,0,0,0,0,0,0,0,10,10,0,0,4,0,0
0,0,0,0,0,0,0,10,10,0,0,0,9,9,0,0,0,0,0,0,0,0,4,0,0
0,0,0,0,0,0,0,0,0,0,0,14,7,7,6,0,0,0,0,0,34,0,4,0,0
0,0,0,0,0,0,0,0,0,0,0,34,7,7,6,0,0,0,34,34,34,34,4,0,0
0,0,0,0,0,0,0,0,19,31,13,34,34,10,0,0,0,0,34,34,34,34,34,0,0
0,0,0,0,0,0,0,9,0,0,0,13,34,34,0,0,0,7,7,7,34,34,34,34,0
0,0,0,0,0,0,14,7,7,0,0,0,34,0,0,0,14,7,7,34,34,34,34,0,0
0,0,0,0,0,0,14,7,7,6,0,0,0,0,0,0,0,10,34,34,34,34,34,0,0
0,0,0,0,0,0,0,10,10,0,0,0,0,0,0,0,0,0,0,0,34,4,0,0,0
0,0,0,0,0,0,0,0,0,0,0,0,0,0,0,0,0,0,0,0,0,0,0,0,0
0,0,0,0,0,0,0,0,0,0,0,0,0,0,0,0,0,19,31,0,14,7,6,0,0
0,0,0,0,0,0,0,0,0,0,0,0,0,0,0,0,0,0,0,0,0,10,0,0,0
0,0,0,0,0,0,0,0,0,0,0,0,0,0,0,0,0,0,0,0,0,0,0,0,0
:endlayer
layer: 16
0,0,0,0,0,0,0,34,0,0,0,0,0,0,0,0,0,0,0,0,0,0,0,0,0
0,0,0,0,0,34,34,34,34,34,0,0,0,0,0,0,0,0,0,0,0,0,0,0,0
0,0,0,0,0,34,34,34,34,34,0,0,0,0,0,0,0,0,0,0,0,0,0,0,0
0,0,0,0,34,34,34,34,34,34,34,0,0,0,0,0,4,4,0,0,0,0,0,0,0
0,0,0,0,34,34,34,7,34,34,0,0,0,0,0,0,30,32,32,32,32,0,0,0,0
0,0,0,34,34,34,34,7,34,34,0,0,0,0,0,30,33,32,32,32,32,32,0,0,0
0,0,0,0,34,33,33,31,9,0,0,0,0,0,0,30,32,32,7,7,32,32,0,0,0
0,0,0,0,32,30,32,7,7,4,0,0,0,0,0,30,32,7,7,7,32,32,32,0,0
0,0,0,0,32,32,32,7,7,6,0,0,0,0,0,30,32,32,32,32,32,32,32,0,0
0,0,0,0,30,32,32,32,32,31,0,0,9,9,0,30,32,32,32,32,32,32,32,0,0
0,0,0,0,30,32,32,32,32,31,33,14,7,7,6,30,32,32,32,32,32,32,32,0,0
0,0,0,0,30,32,32,32,32,32,31,13,7,7,33,30,32,32,32,32,34,4,0,0,0
0,0,0,0,30,31,0,0,0,19,31,13,13,13,32,32,32,32,32,32,34,34,4,0,0
0,0,0,0,29,30,32,32,32,32,31,13,34,4,32,32,32,7,7,32,7,34,34,0,0
0,0,0,0,0,30,32,7,7,32,31,0,0,0,30,32,32,7,7,32,34,34,0,0,0
0,0,0,0,0,30,32,7,7,32,31,0,0,0,30,32,32,32,32,31,34,0,0,0,0
0,0,0,0,0,29,30,32,32,31,29,0,0,0,30,29,32,32,32,31,0,0,0,0,0
0,0,0,0,0,0,29,29,29,29,0,0,0,0,0,30,29,29,29,29,0,0,0,0,0
0,0,0,0,0,0,0,0,0,0,0,0,0,0,0,0,0,0,19,31,14,7,6,0,0
0,0,0,0,0,0,0,0,0,0,0,0,0,0,0,0,0,0,0,0,0,10,0,0,0
0,0,0,0,0,0,0,0,0,0,0,0,0,0,0,0,0,0,0,0,0,0,0,0,0
:endlayer
layer: 17
0,0,0,0,0,0,0,0,0,0,0,0,0,0,0,0,0,0,0,0,0,0,0,0,0
0,0,0,0,0,0,0,34,0,0,0,0,0,0,0,0,0,0,0,0,0,0,0,0,0
0,0,0,0,0,0,34,34,34,0,0,0,0,0,0,0,0,0,0,0,0,0,0,0,0
0,0,0,0,0,34,34,7,34,34,0,0,0,0,0,0,0,0,0,0,0,0,0,0,0
0,0,0,0,0,0,34,34,34,0,0,0,0,0,0,0,0,0,0,0,0,0,0,0,0
0,0,0,0,0,0,0,34,0,0,0,0,0,0,0,0,0,0,72,71,8,0,0,0,0
0,0,0,0,0,8,0,70,4,4,0,0,0,0,0,13,13,4,7,7,69,0,0,0,0
0,0,0,0,0,0,42,7,7,4,0,0,0,0,0,4,7,7,7,7,68,0,0,0,0
0,0,0,0,0,0,40,7,7,6,0,0,0,0,0,4,4,4,67,66,0,0,0,0,0
0,0,0,0,0,0,0,37,36,65,0,0,9,9,0,0,0,0,0,0,0,0,0,0,0
0,0,0,0,0,0,0,0,0,0,0,14,7,7,6,0,0,0,0,0,0,0,8,0,0
0,0,0,0,0,0,0,0,0,0,0,14,7,7,6,0,0,0,0,33,0,0,0,0,0
0,0,0,0,0,0,0,0,0,0,0,0,13,7,13,0,0,64,63,21,34,4,0,0,0
0,0,0,0,0,0,0,62,61,8,28,0,13,13,13,8,60,7,7,6,34,34,0,0,0
0,0,0,0,0,0,59,7,7,0,29,0,0,13,0,0,58,7,7,6,34,0,0,0,0
0,0,0,0,0,0,57,7,7,6,0,0,0,0,0,0,0,56,55,0,0,0,0,0,0
0,0,0,0,0,0,8,54,53,0,0,0,0,0,0,0,0,8,0,0,0,0,0,0,0
0,0,0,0,0,0,0,0,0,0,0,0,0,0,0,0,0,0,0,0,0,0,0,0,0
0,0,0,0,0,0,0,0,0,0,0,0,0,0,0,0,0,0,0,0,14,7,6,0,0
0,0,0,0,0,0,0,0,0,0,0,0,0,0,0,0,0,0,0,0,0,10,0,0,0
0,0,0,0,0,0,0,0,0,0,0,0,0,0,0,0,0,0,0,0,0,0,0,0,0
:endlayer
layer: 18
0,0,0,0,0,0,0,0,0,0,0,0,0,0,0,0,0,0,0,0,0,0,0,0,0
0,0,0,0,0,0,0,0,0,0,0,0,0,0,0,0,0,0,0,0,0,0,0,0,0
0,0,0,0,0,0,0,34,0,0,0,0,4,4,0,0,0,0,0,0,0,0,0,0,0
0,0,0,0,0,0,34,34,34,0,4,4,4,4,4,0,0,0,0,0,0,0,0,0,0
0,0,0,0,0,0,0,34,4,4,34,4,4,4,13,0,0,0,0,0,0,0,0,0,0
0,0,0,0,0,0,0,0,34,34,34,34,4,4,13,4,0,0,0,9,0,0,0,0,0
0,0,0,0,0,0,0,9,34,34,34,34,34,4,0,4,34,14,7,7,6,0,0,0,0
0,0,0,0,0,0,0,7,7,7,34,34,34,34,0,34,34,34,7,7,6,0,0,0,0
0,0,0,0,0,0,14,7,7,34,34,34,34,0,0,0,0,0,0,10,0,0,0,0,0
0,0,0,0,0,0,0,10,10,0,34,34,34,9,0,0,0,0,0,0,0,0,0,0,0
0,0,0,0,0,0,0,0,0,0,34,14,7,7,6,0,0,0,0,33,0,0,0,0,0
0,0,0,0,0,0,0,0,0,0,0,14,7,7,6,0,0,0,0,21,0,0,0,0,0
0,0,0,0,0,0,0,0,0,0,0,0,34,34,34,0,0,9,9,0,0,0,0,0,0
0,0,0,0,0,0,0,9,0,0,0,34,34,7,34,0,14,7,7,6,0,0,0,0,0
0,0,0,0,0,0,14,7,7,0,28,0,34,34,34,0,14,7,7,0,0,0,0,0,0
0,0,0,0,0,0,14,7,7,6,29,0,0,34,0,0,0,10,0,0,0,0,0,0,0
0,0,0,0,0,0,0,10,0,0,0,0,0,0,0,0,0,0,0,0,0,0,0,0,0
0,0,0,0,0,0,0,0,0,0,0,0,0,0,0,0,0,0,0,0,0,0,0,0,0
0,0,0,0,0,0,0,0,0,0,0,0,0,0,0,0,0,0,0,0,27,7,0,0,0
0,0,0,0,0,0,0,0,0,0,0,0,0,0,0,0,0,0,0,0,0,10,0,0,0
0,0,0,0,0,0,0,0,0,0,0,0,0,0,0,0,0,0,0,0,0,0,0,0,0
:endlayer
layer: 19
0,0,0,0,0,0,0,0,0,0,0,0,0,0,0,0,0,0,0,0,0,0,0,0,0
0,0,0,0,0,0,0,0,0,0,0,0,0,0,0,0,0,0,0,0,0,0,0,0,0
0,0,0,0,0,0,0,0,0,0,0,0,0,0,0,0,0,0,0,0,0,0,0,0,0
0,0,0,0,0,0,0,0,0,0,0,0,4,0,0,0,0,0,0,0,0,0,0,0,0
0,0,0,0,0,0,0,0,0,0,0,4,4,4,0,0,33,33,33,33,4,0,0,0,0
0,0,0,0,0,0,0,4,4,13,34,13,4,4,33,33,30,32,32,31,33,4,0,0,0
0,0,0,0,13,13,4,4,9,34,34,34,13,4,30,32,32,32,7,7,31,0,0,0,0
0,0,0,0,4,0,0,7,7,34,7,34,34,33,33,32,32,32,7,7,33,31,0,0,0
0,0,0,0,0,0,14,7,7,34,34,34,33,30,32,32,32,32,32,32,32,31,0,0,0
0,0,0,0,0,0,0,10,10,13,34,4,30,32,32,32,32,32,32,32,32,31,0,0,0
0,0,0,0,0,0,0,0,0,0,13,13,7,7,32,32,32,32,32,21,32,31,0,0,0
0,0,0,0,0,0,30,33,33,33,0,14,7,7,32,32,32,32,32,0,32,31,0,0,0
0,0,0,0,0,30,33,32,32,31,0,13,13,34,30,32,32,32,32,0,32,31,0,0,0
0,0,0,0,0,30,32,32,32,31,0,4,34,34,30,32,32,7,7,0,29,31,0,0,0
0,0,0,0,0,30,32,7,7,33,0,0,4,34,30,32,32,7,7,33,31,0,0,0,0
0,0,0,0,0,30,32,7,7,32,28,0,0,0,29,30,32,32,32,31,29,0,0,0,0
0,0,0,0,0,29,30,32,32,29,31,0,0,0,0,29,30,31,29,29,0,0,0,0,0
0,0,0,0,0,0,29,29,29,31,0,0,0,0,0,0,29,29,0,0,0,0,0,0,0
0,0,0,0,0,0,0,0,0,0,0,0,0,0,0,0,0,0,0,0,14,7,0,0,0
0,0,0,0,0,0,0,0,0,0,0,0,0,0,0,0,0,0,0,0,73,10,0,0,0
0,0,0,0,0,0,0,0,0,0,0,0,0,0,0,0,0,0,0,0,0,0,0,0,0
:endlayer
layer: 20
0,0,0,0,0,0,0,0,0,0,0,0,0,0,0,0,0,0,0,0,0,0,0,0,0
0,0,0,0,0,0,0,0,0,0,0,0,0,0,0,0,0,0,0,0,0,0,0,0,0
0,0,0,0,0,0,0,0,0,0,0,0,0,0,0,0,0,0,0,0,0,0,0,0,0
0,0,0,34,0,0,0,0,0,0,0,0,0,0,0,0,0,0,0,0,0,13,0,0,0
0,34,34,34,34,34,0,0,0,0,0,0,4,0,0,0,0,0,0,4,4,13,0,0,0
0,34,34,34,34,34,4,4,4,0,0,4,4,0,0,0,0,0,88,4,7,4,0,0,0
34,34,34,34,7,7,11,12,13,0,4,4,0,0,87,42,8,86,7,7,4,0,0,0,0
0,34,34,34,34,34,4,7,7,6,13,4,0,0,0,40,0,85,7,7,6,0,0,0,0
0,34,34,34,34,34,14,7,7,6,34,13,0,8,0,0,0,0,84,83,0,0,0,0,0
0,0,0,34,0,0,0,10,10,0,13,4,4,9,37,36,0,0,0,8,0,0,0,0,0
0,0,0,0,0,0,0,0,0,0,13,7,7,7,82,0,0,0,0,0,0,0,0,0,0
0,0,0,0,0,0,81,0,80,0,13,14,7,7,6,8,0,0,0,0,0,0,0,0,0
0,0,0,0,0,0,0,0,0,8,13,0,10,10,0,0,0,79,78,0,0,0,0,0,0
0,0,0,0,0,0,0,77,76,0,0,4,0,0,0,0,41,7,7,34,0,0,0,0,0
0,0,0,0,0,0,42,7,7,7,0,0,0,0,0,0,39,7,7,34,34,4,0,0,0
0,0,0,0,0,0,40,7,7,75,0,0,0,0,0,0,8,74,34,7,34,34,0,0,0
0,0,0,0,0,0,8,37,36,0,0,0,0,0,0,0,0,0,34,34,34,13,4,0,0
0,0,0,0,0,0,0,0,0,0,0,0,0,0,0,0,0,0,13,34,13,4,4,4,0
0,0,0,0,0,0,0,0,0,0,0,0,0,0,0,0,4,4,4,4,4,7,4,4,0
0,0,0,0,0,0,0,0,0,0,0,0,0,0,0,0,0,4,4,13,13,13,4,0,0
0,0,0,0,0,0,0,0,0,0,0,0,0,0,0,0,0,0,0,4,4,4,0,0,0
:endlayer
layer: 21
0,0,0,0,0,0,0,0,0,0,0,0,0,0,0,0,0,0,0,0,0,0,0,0,0
0,0,0,0,0,0,0,0,0,0,0,0,0,0,0,0,0,0,0,0,0,0,0,0,0
0,0,0,0,0,0,0,0,0,0,0,0,0,0,0,0,0,0,0,0,0,0,0,0,0
0,0,0,0,0,0,0,0,0,0,0,0,0,0,0,0,0,0,0,0,4,34,0,0,0
0,0,0,34,0,0,0,0,0,0,0,0,0,0,0,0,0,0,0,4,34,34,34,0,0
0,0,34,34,34,4,4,4,0,0,0,4,0,0,0,0,0,0,9,34,34,7,34,34,0
0,34,34,7,34,34,4,4,9,0,0,0,0,0,0,0,0,14,7,7,34,34,34,0,0
0,0,34,34,34,0,4,7,7,6,0,0,0,0,0,0,0,14,7,7,6,34,0,0,0
0,0,0,34,0,0,14,7,7,6,34,0,0,0,0,0,0,0,0,10,0,0,0,0,0
0,0,0,0,0,0,34,10,10,0,34,4,4,9,0,0,0,0,0,0,0,0,0,0,0
0,0,0,0,0,34,34,34,34,7,7,34,7,7,23,0,0,0,0,0,0,0,0,0,0
0,0,0,0,0,0,0,0,0,34,34,14,7,7,6,0,0,0,0,0,0,0,0,0,0
0,0,0,0,0,0,0,0,0,0,34,0,10,10,0,0,0,9,9,0,0,0,0,0,0
0,0,0,0,0,0,0,9,9,0,34,34,0,0,0,0,0,7,7,6,0,0,0,0,0
0,0,0,0,0,0,14,7,7,34,0,34,0,0,0,0,14,7,7,34,0,0,0,0,0
0,0,0,0,0,0,14,7,7,34,0,0,0,0,0,0,0,10,34,34,34,0,0,0,0
0,0,0,0,0,0,0,10,10,0,0,0,0,0,0,0,0,0,13,34,0,0,0,0,0
0,0,0,0,0,0,0,0,0,0,0,0,0,0,0,0,0,0,0,0,0,13,0,0,0
0,0,0,0,0,0,0,0,0,0,0,0,0,0,0,0,0,0,0,4,13,13,13,0,0
0,0,0,0,0,0,0,0,0,0,0,0,0,0,0,0,0,0,0,0,13,13,0,0,0
0,0,0,0,0,0,0,0,0,0,0,0,0,0,0,0,0,0,0,0,0,0,0,0,0
:endlayer
layer: 22
0,0,0,0,0,0,0,0,0,0,0,0,0,0,0,0,0,0,0,0,0,0,0,0,0
0,0,0,0,0,0,0,0,0,0,0,0,0,0,0,0,0,0,0,0,0,0,0,0,0
0,0,0,0,0,0,0,0,0,0,0,0,0,0,0,0,0,0,34,34,0,34,0,0,0
0,0,0,0,0,0,0,34,34,0,0,0,0,0,0,0,4,34,34,34,34,34,34,0,0
0,0,0,34,34,34,34,34,34,34,0,0,0,0,4,4,34,34,34,34,34,34,34,34,0
0,0,0,34,34,34,34,34,34,34,34,0,0,4,4,34,34,34,34,34,34,34,34,34,0
0,0,34,34,34,34,34,34,34,34,34,34,34,4,34,34,34,34,7,7,34,34,34,34,34
0,0,34,34,34,34,34,7,7,34,34,34,34,34,34,34,34,34,7,7,34,34,34,34,34
0,0,34,34,34,34,34,7,7,34,34,34,34,34,34,34,34,34,34,34,34,34,34,34,0
0,0,0,34,34,34,34,34,34,34,34,34,34,9,34,34,34,34,34,34,34,34,34,34,0
0,0,0,0,34,34,34,34,7,34,34,34,7,7,34,34,34,34,34,34,34,34,34,34,0
0,0,0,0,13,34,34,34,34,34,34,34,7,7,6,34,34,34,34,34,34,34,34,0,0
0,0,0,0,4,34,34,34,34,34,34,34,10,10,0,0,0,9,34,34,0,0,0,0,0
0,0,0,0,0,0,0,34,34,0,34,4,0,0,0,0,0,7,7,0,0,0,0,0,0
0,0,0,0,0,0,14,7,7,34,34,34,0,0,0,0,14,7,7,6,0,0,0,0,0
0,0,0,0,0,0,14,7,7,6,34,0,0,0,0,0,0,10,10,0,0,0,0,0,0
0,0,0,0,0,0,0,10,10,0,0,0,0,0,0,0,0,0,0,0,0,0,0,0,0
0,0,0,0,0,0,0,0,0,0,0,0,0,0,0,0,0,0,0,0,0,0,0,0,0
0,0,0,0,0,0,0,0,0,0,0,0,0,0,0,0,0,0,0,0,0,0,0,0,0
0,0,0,0,0,0,0,0,0,0,0,0,0,0,0,0,0,0,0,0,0,0,0,0,0
0,0,0,0,0,0,0,0,0,0,0,0,0,0,0,0,0,0,0,0,0,0,0,0,0
:endlayer
layer: 23
0,0,0,0,0,0,0,0,0,0,0,0,0,0,0,0,0,0,0,0,0,0,0,0,0
0,0,0,0,0,0,0,0,0,0,0,0,0,0,0,0,0,0,0,0,0,0,0,0,0
0,0,0,0,0,0,0,0,0,0,0,0,0,0,0,0,0,0,0,0,0,0,0,0,0
0,0,0,0,0,0,0,0,0,0,0,0,0,0,0,0,0,0,34,34,0,34,0,0,0
0,0,0,0,0,0,0,34,34,0,0,0,0,0,0,0,4,34,34,34,34,34,34,0,0
0,0,0,0,34,34,34,34,34,34,0,0,0,0,0,4,34,34,34,34,34,34,34,0,0
0,0,0,0,34,34,34,34,34,34,34,0,0,0,0,34,34,34,34,34,34,34,34,34,0
0,0,0,34,34,34,34,34,34,34,34,34,34,0,0,34,34,34,34,7,34,34,34,34,0
0,0,0,34,34,34,34,34,7,34,34,34,34,0,0,0,34,34,34,34,34,34,34,0,0
0,0,0,0,13,34,34,34,34,34,34,34,0,0,0,34,0,34,34,34,34,34,34,0,0
0,0,0,0,0,34,34,34,34,34,34,34,7,7,0,0,34,34,34,34,34,34,0,0,0
0,0,0,0,0,13,34,34,34,34,34,4,7,7,6,0,0,0,34,34,34,0,0,0,0
0,0,0,0,0,0,0,34,34,0,4,4,10,10,0,0,0,9,34,34,34,34,34,0,0
0,0,0,0,0,0,0,9,9,0,0,0,0,0,0,0,27,7,7,34,34,34,34,0,0
0,0,0,0,0,0,14,7,7,6,0,0,0,0,0,0,0,7,7,7,34,34,34,34,0
0,0,0,0,0,0,0,7,7,6,0,0,0,0,0,0,0,10,34,34,34,34,34,0,0
0,0,0,0,0,0,0,10,10,0,0,0,0,0,0,0,0,0,34,34,34,34,34,0,0
0,0,0,0,0,0,0,0,0,0,0,0,0,0,0,0,0,0,0,0,34,0,0,0,0
0,0,0,0,0,0,0,0,0,0,0,0,0,0,0,0,0,0,0,0,0,0,0,0,0
0,0,0,0,0,0,0,0,0,0,0,0,0,0,0,0,0,0,0,0,0,0,0,0,0
0,0,0,0,0,0,0,0,0,0,0,0,0,0,0,0,0,0,0,0,0,0,0,0,0
:endlayer
layer: 24
0,0,0,0,0,0,0,0,0,0,0,0,0,0,0,0,0,0,0,0,0,0,0,0,0
0,0,0,0,0,0,0,0,0,0,0,0,0,0,0,0,0,0,0,0,0,0,0,0,0
0,0,0,0,0,0,0,0,0,0,0,0,0,0,0,0,0,0,0,0,0,0,0,0,0
0,0,0,0,0,0,0,0,0,0,0,0,0,0,0,0,0,0,0,0,0,0,0,0,0
0,0,0,0,0,0,0,0,0,0,0,0,0,0,0,0,0,0,34,34,0,34,0,0,0
0,0,0,0,0,0,0,34,34,0,0,0,0,0,0,0,0,34,34,34,34,34,0,0,0
0,0,0,0,0,34,34,34,34,34,0,0,34,34,0,0,34,34,34,34,34,34,34,0,0
0,0,0,0,0,34,34,34,34,34,34,34,34,34,34,0,34,34,34,34,34,34,34,0,0
0,0,0,0,0,34,34,34,34,34,34,34,34,34,34,34,0,34,34,34,34,34,0,0,0
0,0,0,0,0,13,34,34,34,34,34,34,34,34,34,34,34,34,34,34,34,34,0,0,0
0,0,0,0,0,0,34,34,34,34,34,34,7,7,34,34,34,34,34,34,0,0,0,0,0
0,0,0,0,0,0,0,34,34,34,34,34,7,7,34,34,34,34,34,0,0,0,0,0,0
0,0,0,0,0,0,0,0,34,34,34,34,34,34,34,34,34,34,9,0,34,0,0,0,0
0,0,0,0,0,0,0,9,9,0,34,34,34,34,34,34,34,7,7,34,34,34,0,0,0
0,0,0,0,0,0,0,7,7,6,0,34,34,34,34,34,34,7,7,34,7,34,34,0,0
0,0,0,0,0,0,0,7,7,6,0,0,34,34,34,34,34,10,10,34,34,34,0,0,0
0,0,0,0,0,0,0,0,10,0,0,0,4,4,4,0,0,0,0,0,34,0,0,0,0
0,0,0,0,0,0,0,0,0,0,0,0,0,4,0,0,0,0,0,0,0,0,0,0,0
0,0,0,0,0,0,0,0,0,0,0,0,0,0,0,0,0,0,0,0,0,0,0,0,0
0,0,0,0,0,0,0,0,0,0,0,0,0,0,0,0,0,0,0,0,0,0,0,0,0
0,0,0,0,0,0,0,0,0,0,0,0,0,0,0,0,0,0,0,0,0,0,0,0,0
:endlayer
layer: 25
0,0,0,0,0,0,0,0,0,0,0,0,0,0,0,0,0,0,0,0,0,0,0,0,0
0,0,0,0,0,0,0,0,0,0,0,0,0,0,0,0,0,0,0,0,0,0,0,0,0
0,0,0,0,0,0,0,0,0,0,0,0,0,0,0,0,0,0,0,0,0,0,0,0,0
0,0,0,0,0,0,0,0,0,0,0,0,0,0,0,0,0,0,0,0,0,0,0,0,0
0,0,0,0,0,0,0,0,0,0,0,0,0,0,0,0,0,0,0,0,0,0,0,0,0
0,0,0,0,0,0,0,0,0,0,0,0,0,0,0,0,0,0,0,0,0,0,0,0,0
0,0,0,0,0,0,0,0,0,0,0,0,0,0,0,0,0,0,0,0,0,0,0,0,0
0,0,0,0,0,0,0,0,0,0,0,0,34,34,0,0,0,0,0,0,0,0,0,0,0
0,0,0,0,0,0,0,0,0,34,34,34,34,34,34,0,0,0,0,0,0,0,0,0,0
0,0,0,0,0,0,0,0,0,34,34,34,34,34,34,34,0,0,0,0,0,0,0,0,0
0,0,0,0,0,0,0,0,34,34,34,34,34,34,34,34,34,34,0,0,0,0,0,0,0
0,0,0,0,0,0,0,0,34,34,34,34,34,7,34,34,34,34,0,0,0,0,0,0,0
0,0,0,0,0,0,0,0,0,0,34,34,34,34,34,34,34,9,9,0,0,0,0,0,0
0,0,0,0,0,0,0,9,9,0,0,34,34,34,34,34,34,7,7,6,34,0,0,0,0
0,0,0,0,0,0,4,7,7,6,0,0,34,34,34,34,14,7,7,34,34,34,0,0,0
0,0,0,0,0,34,34,7,7,34,0,0,0,34,0,0,0,10,10,0,34,0,0,0,0
0,0,0,0,0,34,34,7,34,34,0,0,0,0,0,0,0,0,0,0,0,0,0,0,0
0,0,0,0,34,34,34,34,34,34,34,0,0,0,0,0,0,0,0,0,0,0,0,0,0
0,0,0,0,0,34,34,34,34,34,4,0,0,0,0,0,0,0,0,0,0,0,0,0,0
0,0,0,0,0,34,34,34,34,34,0,0,0,0,0,0,0,0,0,0,0,0,0,0,0
0,0,0,0,0,0,0,34,4,0,0,0,0,0,0,0,0,0,0,0,0,0,0,0,0
:endlayer
layer: 26
0,0,0,0,0,0,0,0,0,0,0,0,0,0,0,0,0,0,0,0,0,0,0,0,0
0,0,0,0,0,0,0,0,0,0,0,0,0,0,0,0,0,0,0,0,0,0,0,0,0
0,0,0,0,0,0,0,0,0,0,0,0,0,0,0,0,0,0,0,0,0,0,0,0,0
0,0,0,0,0,0,0,0,0,0,0,0,0,0,0,0,0,0,0,0,0,0,0,0,0
0,0,0,0,0,0,0,0,0,0,0,0,0,0,0,0,0,0,0,0,0,0,0,0,0
0,0,0,0,0,0,0,0,0,0,0,0,0,0,0,0,0,0,0,0,0,0,0,0,0
0,0,0,0,0,0,0,0,0,0,0,0,0,0,0,0,0,0,0,0,0,0,0,0,0
0,0,0,0,0,0,0,0,0,0,0,0,0,0,0,0,0,0,0,0,0,0,0,0,0
0,0,0,0,0,0,0,0,0,0,0,0,34,34,0,0,0,0,0,0,0,0,0,0,0
0,0,0,0,0,0,0,0,0,0,0,34,34,34,34,0,0,0,0,0,0,0,0,0,0
0,0,0,0,0,0,0,0,0,0,34,34,34,34,34,34,0,0,0,0,0,0,0,0,0
0,0,0,0,0,0,0,0,0,0,34,34,34,34,34,34,34,0,0,0,0,0,0,0,0
0,0,0,0,0,0,0,0,0,0,0,34,34,34,34,34,0,9,9,0,0,0,0,0,0
0,0,0,0,0,4,4,9,9,0,0,0,34,34,34,34,14,7,7,0,0,0,0,0,0
0,0,0,0,0,4,7,7,7,6,0,0,0,34,0,0,14,7,7,6,0,0,0,0,0
0,0,0,0,0,0,4,7,7,6,0,0,0,0,0,0,0,10,10,0,0,0,0,0,0
0,0,0,0,0,0,34,34,34,0,0,0,0,0,0,0,0,0,0,0,0,0,0,0,0
0,0,0,0,0,34,34,7,34,34,0,0,0,0,0,0,0,0,0,0,0,0,0,0,0
0,0,0,0,0,0,34,34,34,0,0,0,0,0,0,0,0,0,0,0,0,0,0,0,0
0,0,0,0,0,0,0,34,0,0,0,0,0,0,0,0,0,0,0,0,0,0,0,0,0
0,0,0,0,0,0,0,0,0,0,0,0,0,0,0,0,0,0,0,0,0,0,0,0,0
:endlayer
layer: 27
0,0,0,0,0,0,0,0,0,0,0,0,0,0,0,0,0,0,0,0,0,0,0,0,0
0,0,0,0,0,0,0,0,0,0,0,0,0,0,0,0,0,0,0,0,0,0,0,0,0
0,0,0,0,0,0,0,0,0,0,0,0,0,0,0,0,0,0,0,0,0,0,0,0,0
0,0,0,0,0,0,0,0,0,0,0,0,0,0,0,0,0,0,0,0,0,0,0,0,0
0,0,0,0,0,0,0,0,0,0,0,0,0,0,0,0,0,0,0,0,0,0,0,0,0
0,0,0,0,0,0,0,0,0,0,0,0,0,0,0,0,0,0,0,0,0,0,0,0,0
0,0,0,0,0,0,0,0,0,0,0,0,0,0,0,0,0,0,0,0,0,0,0,0,0
0,0,0,0,0,0,0,0,0,0,0,0,0,0,0,0,0,0,0,0,0,0,0,0,0
0,0,0,0,0,0,0,0,0,0,0,0,0,0,0,0,0,0,0,0,0,0,0,0,0
0,0,0,0,0,0,0,0,0,0,0,0,0,0,0,0,0,34,34,0,0,0,0,0,0
0,0,0,0,0,0,0,0,0,0,0,0,0,34,34,0,34,34,34,34,0,0,0,0,0
0,0,0,0,0,0,0,0,0,0,0,0,0,34,34,34,34,34,34,34,34,0,0,0,0
0,0,0,0,4,0,0,0,0,0,0,0,4,34,34,34,34,34,34,34,34,34,0,0,0
0,0,0,0,4,4,4,9,9,0,0,0,4,34,34,34,34,7,7,34,34,34,34,0,0
0,0,0,0,4,4,4,7,7,6,0,0,4,34,34,34,34,7,7,34,34,34,34,0,0
0,0,0,0,7,7,4,7,7,6,0,0,4,4,34,34,34,34,34,34,34,34,4,0,0
0,0,0,0,4,4,4,34,10,0,0,0,4,4,4,34,34,34,34,34,34,4,4,0,0
0,0,0,0,4,4,34,34,34,0,0,0,0,4,4,4,34,34,34,34,4,4,0,0,0
0,0,0,0,0,0,4,34,0,0,0,0,0,4,4,4,4,34,34,4,4,0,0,0,0
0,0,0,0,0,0,0,0,0,0,0,0,0,0,4,4,4,4,4,4,0,0,0,0,0
0,0,0,0,0,0,0,0,0,0,0,0,0,0,0,0,0,0,0,0,0,0,0,0,0
:endlayer
layer: 28
0,0,0,0,0,0,0,0,0,0,0,0,0,0,0,0,0,0,0,0,0,0,0,0,0
0,0,0,0,0,0,0,0,0,0,0,0,0,0,0,0,0,0,0,0,0,0,0,0,0
0,0,0,0,0,0,0,0,0,0,0,0,0,0,0,0,0,0,0,0,0,0,0,0,0
0,0,0,0,0,0,0,0,0,0,0,0,0,0,0,0,0,0,0,0,0,0,0,0,0
0,0,0,0,0,0,0,0,0,0,0,0,0,0,0,0,0,0,0,0,0,0,0,0,0
0,0,0,0,0,0,0,0,0,0,0,0,0,0,0,0,0,0,0,0,0,0,0,0,0
0,0,0,0,0,0,0,0,0,0,0,0,0,0,0,0,0,0,0,0,0,0,0,0,0
0,0,0,0,0,0,0,0,0,0,0,0,0,0,0,0,0,0,0,0,0,0,0,0,0
0,0,0,0,0,0,0,0,0,0,0,0,0,0,0,0,0,0,0,0,0,0,0,0,0
0,0,0,0,0,0,0,0,0,0,0,0,0,0,0,0,0,0,0,0,0,0,0,0,0
0,0,0,0,0,0,0,0,0,0,0,0,0,0,0,0,0,34,34,0,0,0,0,0,0
0,0,0,0,0,0,0,0,0,0,0,0,0,0,34,0,34,34,34,34,0,0,0,0,0
0,0,0,0,4,0,0,0,0,0,0,0,0,0,0,34,34,34,34,34,34,0,0,0,0
0,0,0,34,4,0,0,9,9,0,0,0,0,0,34,34,34,34,34,34,34,34,0,0,0
0,0,34,34,34,0,14,7,7,6,0,0,0,4,34,34,34,34,7,34,34,34,34,0,0
0,34,34,7,34,34,14,7,7,6,0,0,0,4,4,34,34,34,34,34,34,34,4,0,0
0,0,34,34,34,4,0,10,10,0,0,0,0,4,4,4,34,34,34,34,34,4,0,0,0
0,0,0,34,4,4,4,0,0,0,0,0,0,0,4,4,4,34,34,34,4,0,0,0,0
0,0,0,0,0,4,0,0,0,0,0,0,0,0,0,4,4,4,34,4,0,0,0,0,0
0,0,0,0,0,0,0,0,0,0,0,0,0,0,0,0,0,0,0,0,0,0,0,0,0
0,0,0,0,0,0,0,0,0,0,0,0,0,0,0,0,0,0,0,0,0,0,0,0,0
:endlayer
layer: 29
0,0,0,0,0,0,0,0,0,0,0,0,0,0,0,0,0,0,0,0,0,0,0,0,0
0,0,0,0,0,0,0,0,0,0,0,0,0,0,0,0,0,0,0,0,0,0,0,0,0
0,0,0,0,0,0,0,0,0,0,0,0,0,0,0,0,0,0,0,0,0,0,0,0,0
0,0,0,0,0,0,0,0,0,0,0,0,0,0,0,0,0,0,0,0,0,0,0,0,0
0,0,0,0,0,0,0,0,0,0,0,0,0,0,0,0,0,0,0,0,0,0,0,0,0
0,0,0,0,0,0,0,0,0,0,0,0,0,0,0,0,0,0,0,0,0,0,0,0,0
0,0,0,0,0,0,0,0,0,0,0,0,0,0,0,0,0,0,0,0,0,0,0,0,0
0,0,0,0,0,0,0,0,0,0,0,0,0,0,0,0,0,0,0,0,0,0,0,0,0
0,0,0,0,0,0,0,0,0,0,0,0,0,0,0,0,0,0,0,0,0,0,0,0,0
0,0,0,0,0,0,0,0,0,0,0,0,0,0,0,0,0,0,0,0,0,0,0,0,0
0,0,0,0,0,0,0,0,0,0,0,0,0,0,0,0,0,0,0,0,0,0,0,0,0
0,0,0,0,0,0,0,0,0,0,0,0,0,0,0,0,0,34,34,0,0,0,0,0,0
0,0,0,0,0,0,0,0,0,0,0,0,0,0,0,0,34,34,34,34,0,0,0,0,0
0,0,0,4,0,0,0,9,9,0,0,0,0,0,0,34,34,34,34,34,34,0,0,0,0
0,0,0,34,0,0,0,7,7,6,0,0,0,0,4,34,34,34,34,34,34,34,0,0,0
0,0,34,34,34,0,14,7,7,0,0,0,0,0,4,4,34,34,34,34,34,0,0,0,0
0,0,0,34,13,0,0,0,10,0,0,0,0,0,0,4,13,34,34,34,0,0,0,0,0
0,0,0,0,0,0,0,0,0,0,0,0,0,0,0,0,13,13,34,0,0,0,0,0,0
0,0,0,0,0,0,0,0,0,0,0,0,0,0,0,0,0,0,0,0,0,0,0,0,0
0,0,0,0,0,0,0,0,0,0,0,0,0,0,0,0,0,0,0,0,0,0,0,0,0
0,0,0,0,0,0,0,0,0,0,0,0,0,0,0,0,0,0,0,0,0,0,0,0,0
:endlayer
layer: 30
0,0,0,0,0,0,0,0,0,0,0,0,0,0,0,0,0,0,0,0,0,0,0,0,0
0,0,0,0,0,0,0,0,0,0,0,0,0,0,0,0,0,0,0,0,0,0,0,0,0
0,0,0,0,0,0,0,0,0,0,0,0,0,0,0,0,0,0,0,0,0,0,0,0,0
0,0,0,0,0,0,0,0,0,0,0,0,0,0,0,0,0,0,0,0,0,0,0,0,0
0,0,0,0,0,0,0,0,0,0,0,0,0,0,0,0,0,0,0,0,0,0,0,0,0
0,0,0,0,0,0,0,0,0,0,0,0,0,0,0,0,0,0,0,0,0,0,0,0,0
0,0,0,0,0,0,0,0,0,0,0,0,0,0,0,0,0,0,0,0,0,0,0,0,0
0,0,0,0,0,0,0,0,0,0,0,0,0,0,0,0,0,0,0,0,0,0,0,0,0
0,0,0,0,0,0,0,0,0,0,0,0,0,0,0,0,0,0,0,0,0,0,0,0,0
0,0,0,0,0,0,0,0,0,0,0,0,0,0,0,0,0,0,0,0,0,0,0,0,0
0,0,0,0,0,0,4,34,34,4,0,0,0,0,0,0,0,0,0,0,0,0,0,0,0
0,0,0,0,0,4,34,34,34,34,4,4,0,0,0,0,0,0,0,0,0,0,0,0,0
0,0,0,0,4,34,34,34,34,34,34,4,4,0,0,0,0,0,0,0,0,0,0,0,0
0,0,0,34,34,34,34,34,34,34,34,34,4,4,0,0,0,0,0,0,0,0,0,0,0
0,0,34,34,34,34,34,7,7,34,34,34,34,4,4,0,0,0,0,0,0,0,0,0,0
0,0,34,34,34,34,34,7,7,34,34,34,34,4,4,0,0,0,0,0,0,0,0,0,0
0,0,0,34,0,34,34,34,34,34,34,34,4,4,4,0,0,0,0,0,0,0,0,0,0
0,0,0,0,0,0,0,34,34,34,34,4,4,4,4,0,0,0,0,0,0,0,0,0,0
0,0,0,0,0,0,0,34,34,34,4,4,4,4,4,0,0,0,0,0,0,0,0,0,0
0,0,0,0,0,0,13,34,34,4,4,4,4,4,0,0,0,0,0,0,0,0,0,0,0
0,0,0,0,0,0,0,4,4,4,4,4,4,0,0,0,0,0,0,0,0,0,0,0,0
:endlayer
layer: 31
0,0,0,0,0,0,0,0,0,0,0,0,0,0,0,0,0,0,0,0,0,0,0,0,0
0,0,0,0,0,0,0,0,0,0,0,0,0,0,0,0,0,0,0,0,0,0,0,0,0
0,0,0,0,0,0,0,0,0,0,0,0,0,0,0,0,0,0,0,0,0,0,0,0,0
0,0,0,0,0,0,0,0,0,0,0,0,0,0,0,0,0,0,0,0,0,0,0,0,0
0,0,0,0,0,0,0,0,0,0,0,0,0,0,0,0,0,0,0,0,0,0,0,0,0
0,0,0,0,0,0,0,0,0,0,0,0,0,0,0,0,0,0,0,0,0,0,0,0,0
0,0,0,0,0,0,0,0,0,0,0,0,0,0,0,0,0,0,0,0,0,0,0,0,0
0,0,0,0,0,0,0,0,0,0,0,0,0,0,0,0,0,0,0,0,0,0,0,0,0
0,0,0,0,0,0,0,0,0,0,0,0,0,0,0,0,0,0,0,0,0,0,0,0,0
0,0,0,0,0,0,0,0,0,0,0,0,0,0,0,0,0,0,0,0,0,0,0,0,0
0,0,0,0,0,0,0,0,0,0,0,0,0,0,0,0,0,0,0,0,0,0,0,0,0
0,0,0,0,0,0,4,34,34,4,0,0,0,0,0,0,0,0,0,0,0,0,0,0,0
0,0,0,0,0,4,34,34,34,34,4,4,0,0,0,0,0,0,0,0,0,0,0,0,0
0,0,0,0,4,34,34,34,34,34,34,4,4,0,0,0,0,0,0,0,0,0,0,0,0
0,0,0,34,34,34,34,34,34,34,34,34,4,0,0,0,0,0,0,0,0,0,0,0,0
0,0,0,34,34,34,34,34,7,34,34,34,34,4,0,0,0,0,0,0,0,0,0,0,0
0,0,0,0,0,34,34,34,34,34,34,34,4,4,0,0,0,0,0,0,0,0,0,0,0
0,0,0,0,0,0,34,34,34,34,34,4,4,4,0,0,0,0,0,0,0,0,0,0,0
0,0,0,0,0,0,0,34,34,34,4,4,4,4,0,0,0,0,0,0,0,0,0,0,0
0,0,0,0,0,0,0,0,34,4,4,4,4,0,0,0,0,0,0,0,0,0,0,0,0
0,0,0,0,0,0,0,0,0,0,4,0,0,0,0,0,0,0,0,0,0,0,0,0,0
:endlayer
layer: 32
0,0,0,0,0,0,0,0,0,0,0,0,0,0,0,0,0,0,0,0,0,0,0,0,0
0,0,0,0,0,0,0,0,0,0,0,0,0,0,0,0,0,0,0,0,0,0,0,0,0
0,0,0,0,0,0,0,0,0,0,0,0,0,0,0,0,0,0,0,0,0,0,0,0,0
0,0,0,0,0,0,0,0,0,0,0,0,0,0,0,0,0,0,0,0,0,0,0,0,0
0,0,0,0,0,0,0,0,0,0,0,0,0,0,0,0,0,0,0,0,0,0,0,0,0
0,0,0,0,0,0,0,0,0,0,0,0,0,0,0,0,0,0,0,0,0,0,0,0,0
0,0,0,0,0,0,0,0,0,0,0,0,0,0,0,0,0,0,0,0,0,0,0,0,0
0,0,0,0,0,0,0,0,0,0,0,0,0,0,0,0,0,0,0,0,0,0,0,0,0
0,0,0,0,0,0,0,0,0,0,0,0,0,0,0,0,0,0,0,0,0,0,0,0,0
0,0,0,0,0,0,0,0,0,0,0,0,0,0,0,0,0,0,0,0,0,0,0,0,0
0,0,0,0,0,0,0,0,0,0,0,0,0,0,0,0,0,0,0,0,0,0,0,0,0
0,0,0,0,0,0,0,4,4,0,0,0,0,0,0,0,0,0,0,0,0,0,0,0,0
0,0,0,0,0,0,4,34,34,4,0,0,0,0,0,0,0,0,0,0,0,0,0,0,0
0,0,0,0,0,4,34,34,34,34,4,4,0,0,0,0,0,0,0,0,0,0,0,0,0
0,0,0,0,4,34,34,34,34,34,34,4,0,0,0,0,0,0,0,0,0,0,0,0,0
0,0,0,0,0,34,34,34,34,34,34,34,4,0,0,0,0,0,0,0,0,0,0,0,0
0,0,0,0,0,0,34,34,34,34,34,4,4,0,0,0,0,0,0,0,0,0,0,0,0
0,0,0,0,0,0,0,34,34,34,4,4,4,0,0,0,0,0,0,0,0,0,0,0,0
0,0,0,0,0,0,0,0,34,4,4,4,0,0,0,0,0,0,0,0,0,0,0,0,0
0,0,0,0,0,0,0,0,0,0,4,0,0,0,0,0,0,0,0,0,0,0,0,0,0
0,0,0,0,0,0,0,0,0,0,0,0,0,0,0,0,0,0,0,0,0,0,0,0,0
:endlayer

#### RULES ####
rule:
plugin=vanillaBlocks
number=1
data:
JSON:{blockState:{blockName:"minecraft:grass",properties:{snowy:"false"}},buildPass:0}
:enddata
:endrule

rule:
plugin=vanillaBlocks
number=2
data:
JSON:{blockState:{blockName:"minecraft:dirt",properties:{variant:"dirt",snowy:"false"}},buildPass:0}
:enddata
:endrule

rule:
plugin=vanillaBlocks
number=3
data:
JSON:{blockState:{blockName:"minecraft:tallgrass",properties:{type:"tall_grass"}},buildPass:2}
:enddata
:endrule

rule:
plugin=vanillaBlocks
number=4
data:
JSON:{blockState:{blockName:"minecraft:leaves",properties:{check_decay:"false",decayable:"false",variant:"jungle"}},buildPass:0}
:enddata
:endrule

rule:
plugin=vanillaBlocks
number=5
data:
JSON:{blockState:{blockName:"minecraft:tallgrass",properties:{type:"fern"}},buildPass:2}
:enddata
:endrule

rule:
plugin=vanillaBlocks
number=6
data:
JSON:{blockState:{blockName:"minecraft:vine",properties:{east:"false",south:"false",north:"false",west:"true",up:"false"}},buildPass:2}
:enddata
:endrule

rule:
plugin=vanillaBlocks
number=7
data:
JSON:{blockState:{blockName:"minecraft:log",properties:{variant:"jungle",axis:"y"}},buildPass:0}
:enddata
:endrule

rule:
plugin=vanillaBlocks
number=8
data:
JSON:{blockState:{blockName:"minecraft:torch",properties:{facing:"up"}},buildPass:2}
:enddata
:endrule

rule:
plugin=vanillaBlocks
number=9
data:
JSON:{blockState:{blockName:"minecraft:vine",properties:{east:"false",south:"true",north:"false",west:"false",up:"false"}},buildPass:2}
:enddata
:endrule

rule:
plugin=vanillaBlocks
number=10
data:
JSON:{blockState:{blockName:"minecraft:vine",properties:{east:"false",south:"false",north:"true",west:"false",up:"false"}},buildPass:2}
:enddata
:endrule

rule:
plugin=vanillaBlocks
number=11
data:
JSON:{blockState:{blockName:"minecraft:log",properties:{variant:"jungle",axis:"x"}},buildPass:0}
:enddata
:endrule

rule:
plugin=vanillaBlocks
number=12
data:
JSON:{blockState:{blockName:"minecraft:log",properties:{variant:"jungle",axis:"z"}},buildPass:0}
:enddata
:endrule

rule:
plugin=vanillaBlocks
number=13
data:
JSON:{blockState:{blockName:"minecraft:leaves",properties:{check_decay:"true",decayable:"false",variant:"jungle"}},buildPass:0}
:enddata
:endrule

rule:
plugin=vanillaBlocks
number=14
data:
JSON:{blockState:{blockName:"minecraft:vine",properties:{east:"true",south:"false",north:"false",west:"false",up:"false"}},buildPass:2}
:enddata
:endrule

rule:
plugin=vanillaBlocks
number=15
data:
JSON:{blockState:{blockName:"minecraft:torch",properties:{facing:"east"}},buildPass:2}
:enddata
:endrule

rule:
plugin=vanillaBlocks
number=16
data:
JSON:{blockState:{blockName:"minecraft:torch",properties:{facing:"west"}},buildPass:2}
:enddata
:endrule

rule:
plugin=vanillaBlocks
number=17
data:
JSON:{blockState:{blockName:"minecraft:torch",properties:{facing:"south"}},buildPass:2}
:enddata
:endrule

rule:
plugin=vanillaBlocks
number=18
data:
JSON:{blockState:{blockName:"minecraft:wooden_slab",properties:{half:"top",variant:"jungle"}},buildPass:0}
:enddata
:endrule

rule:
plugin=vanillaBlocks
number=19
data:
JSON:{blockState:{blockName:"minecraft:jungle_stairs",properties:{half:"bottom",shape:"straight",facing:"east"}},buildPass:0}
:enddata
:endrule

rule:
plugin=vanillaBlocks
number=20
data:
JSON:{blockState:{blockName:"minecraft:torch",properties:{facing:"north"}},buildPass:2}
:enddata
:endrule

rule:
plugin=vanillaBlocks
number=21
data:
JSON:{blockState:{blockName:"minecraft:jungle_stairs",properties:{half:"bottom",shape:"straight",facing:"north"}},buildPass:0}
:enddata
:endrule

rule:
plugin=vanillaBlocks
number=22
data:
JSON:{blockState:{blockName:"minecraft:cocoa",properties:{facing:"south",age:"1"}},buildPass:2}
:enddata
:endrule

rule:
plugin=vanillaBlocks
number=23
data:
JSON:{blockState:{blockName:"minecraft:cocoa",properties:{facing:"west",age:"0"}},buildPass:2}
:enddata
:endrule

rule:
plugin=vanillaBlocks
number=24
data:
JSON:{blockState:{blockName:"minecraft:cocoa",properties:{facing:"west",age:"1"}},buildPass:2}
:enddata
:endrule

rule:
plugin=vanillaBlocks
number=25
data:
JSON:{blockState:{blockName:"minecraft:jungle_stairs",properties:{half:"bottom",shape:"straight",facing:"west"}},buildPass:0}
:enddata
:endrule

rule:
plugin=vanillaBlocks
number=26
data:
JSON:{blockState:{blockName:"minecraft:cocoa",properties:{facing:"north",age:"0"}},buildPass:2}
:enddata
:endrule

rule:
plugin=vanillaBlocks
number=27
data:
JSON:{blockState:{blockName:"minecraft:cocoa",properties:{facing:"east",age:"0"}},buildPass:2}
:enddata
:endrule

rule:
plugin=vanillaBlocks
number=28
data:
JSON:{blockState:{blockName:"minecraft:jungle_stairs",properties:{half:"bottom",shape:"straight",facing:"south"}},buildPass:0}
:enddata
:endrule

rule:
plugin=vanillaBlocks
number=29
data:
JSON:{blockState:{blockName:"minecraft:jungle_stairs",properties:{half:"top",shape:"straight",facing:"north"}},buildPass:0}
:enddata
:endrule

rule:
plugin=vanillaBlocks
number=30
data:
JSON:{blockState:{blockName:"minecraft:jungle_stairs",properties:{half:"top",shape:"straight",facing:"east"}},buildPass:0}
:enddata
:endrule

rule:
plugin=vanillaBlocks
number=31
data:
JSON:{blockState:{blockName:"minecraft:jungle_stairs",properties:{half:"top",shape:"straight",facing:"west"}},buildPass:0}
:enddata
:endrule

rule:
plugin=vanillaBlocks
number=32
data:
JSON:{blockState:{blockName:"minecraft:planks",properties:{variant:"jungle"}},buildPass:0}
:enddata
:endrule

rule:
plugin=vanillaBlocks
number=33
data:
JSON:{blockState:{blockName:"minecraft:jungle_stairs",properties:{half:"top",shape:"straight",facing:"south"}},buildPass:0}
:enddata
:endrule

rule:
plugin=vanillaBlocks
number=34
data:
JSON:{blockState:{blockName:"minecraft:leaves",properties:{check_decay:"false",decayable:"true",variant:"jungle"}},buildPass:0}
:enddata
:endrule

rule:
plugin=inventory
number=35
data:
JSON:{blockState:{blockName:"minecraft:chest",properties:{facing:"east"}},buildPass:0,lootLevel:0,teData:{x:-163,y:117,Items:[{Slot:0b,id:298s,Count:1b,Damage:0s},{Slot:1b,id:300s,Count:1b,Damage:0s},{Slot:2b,id:373s,Count:1b,Damage:0s},{Slot:11b,id:31s,Count:1b,Damage:2s},{Slot:21b,id:280s,Count:1b,Damage:0s},{Slot:22b,id:280s,Count:1b,Damage:0s}],z:213,id:"Chest"},inventoryData:{length:27,inventoryContents:[{id:"minecraft:leather_helmet",Count:1b,slot:0,Damage:0s},{id:"minecraft:leather_leggings",Count:1b,slot:1,Damage:0s},{id:"minecraft:potion",Count:1b,tag:{Potion:"minecraft:water"},slot:2,Damage:0s},{id:"minecraft:tallgrass",Count:1b,slot:11,Damage:2s},{id:"minecraft:stick",Count:1b,slot:21,Damage:0s},{id:"minecraft:stick",Count:1b,slot:22,Damage:0s}]}}
:enddata
:endrule

rule:
plugin=vanillaBlocks
number=36
data:
JSON:{blockState:{blockName:"minecraft:bed",properties:{part:"foot",facing:"west",occupied:"false"}},buildPass:2}
:enddata
:endrule

rule:
plugin=vanillaBlocks
number=37
data:
JSON:{blockState:{blockName:"minecraft:bed",properties:{part:"head",facing:"west",occupied:"false"}},buildPass:2}
:enddata
:endrule

rule:
plugin=inventory
number=38
data:
JSON:{blockState:{blockName:"minecraft:chest",properties:{facing:"south"}},buildPass:0,lootLevel:0,teData:{x:-160,y:117,Items:[{Slot:0b,id:299s,Count:1b,Damage:0s},{Slot:1b,id:301s,Count:1b,Damage:0s},{Slot:9b,id:38s,Count:1b,Damage:4s},{Slot:12b,id:296s,Count:2b,Damage:0s},{Slot:13b,id:296s,Count:1b,Damage:0s},{Slot:19b,id:351s,Count:1b,Damage:3s},{Slot:20b,id:351s,Count:1b,Damage:3s}],z:213,id:"Chest"},inventoryData:{length:27,inventoryContents:[{id:"minecraft:leather_chestplate",Count:1b,slot:0,Damage:0s},{id:"minecraft:leather_boots",Count:1b,slot:1,Damage:0s},{id:"minecraft:red_flower",Count:1b,slot:9,Damage:4s},{id:"minecraft:wheat",Count:2b,slot:12,Damage:0s},{id:"minecraft:wheat",Count:1b,slot:13,Damage:0s},{id:"minecraft:dye",Count:1b,slot:19,Damage:3s},{id:"minecraft:dye",Count:1b,slot:20,Damage:3s}]}}
:enddata
:endrule

rule:
plugin=vanillaBlocks
number=39
data:
JSON:{blockState:{blockName:"minecraft:bed",properties:{part:"head",facing:"south",occupied:"false"}},buildPass:2}
:enddata
:endrule

rule:
plugin=vanillaBlocks
number=40
data:
JSON:{blockState:{blockName:"minecraft:bed",properties:{part:"foot",facing:"north",occupied:"false"}},buildPass:2}
:enddata
:endrule

rule:
plugin=vanillaBlocks
number=41
data:
JSON:{blockState:{blockName:"minecraft:bed",properties:{part:"foot",facing:"south",occupied:"false"}},buildPass:2}
:enddata
:endrule

rule:
plugin=vanillaBlocks
number=42
data:
JSON:{blockState:{blockName:"minecraft:bed",properties:{part:"head",facing:"north",occupied:"false"}},buildPass:2}
:enddata
:endrule

rule:
plugin=inventory
number=43
data:
JSON:{blockState:{blockName:"minecraft:chest",properties:{facing:"west"}},buildPass:0,lootLevel:0,teData:{x:-160,y:117,Items:[{Slot:0b,id:298s,Count:1b,Damage:0s},{Slot:1b,id:299s,Count:1b,Damage:0s},{Slot:2b,id:296s,Count:1b,Damage:0s},{Slot:3b,id:296s,Count:1b,Damage:0s},{Slot:11b,id:296s,Count:1b,Damage:0s},{Slot:12b,id:280s,Count:2b,Damage:0s}],z:216,id:"Chest"},inventoryData:{length:27,inventoryContents:[{id:"minecraft:leather_helmet",Count:1b,slot:0,Damage:0s},{id:"minecraft:leather_chestplate",Count:1b,slot:1,Damage:0s},{id:"minecraft:wheat",Count:1b,slot:2,Damage:0s},{id:"minecraft:wheat",Count:1b,slot:3,Damage:0s},{id:"minecraft:wheat",Count:1b,slot:11,Damage:0s},{id:"minecraft:stick",Count:2b,slot:12,Damage:0s}]}}
:enddata
:endrule

rule:
plugin=vanillaBlocks
number=44
data:
JSON:{blockState:{blockName:"minecraft:birch_stairs",properties:{half:"bottom",shape:"straight",facing:"south"}},buildPass:0}
:enddata
:endrule

rule:
plugin=vanillaBlocks
number=45
data:
JSON:{blockState:{blockName:"minecraft:birch_stairs",properties:{half:"bottom",shape:"straight",facing:"east"}},buildPass:0}
:enddata
:endrule

rule:
plugin=vanillaBlocks
number=46
data:
JSON:{blockState:{blockName:"minecraft:birch_stairs",properties:{half:"bottom",shape:"straight",facing:"west"}},buildPass:0}
:enddata
:endrule

rule:
plugin=vanillaBlocks
number=47
data:
JSON:{blockState:{blockName:"minecraft:fence",properties:{east:"false",south:"false",north:"false",west:"false"}},buildPass:0}
:enddata
:endrule

rule:
plugin=vanillaBlocks
number=48
data:
JSON:{blockState:{blockName:"minecraft:birch_stairs",properties:{half:"bottom",shape:"straight",facing:"north"}},buildPass:0}
:enddata
:endrule

rule:
plugin=blockTile
number=49
data:
JSON:{blockState:{blockName:"minecraft:furnace",properties:{facing:"east"}},buildPass:0,teData:{CookTime:0s,BurnTime:0s,x:-167,y:117,Items:[],z:224,id:"Furnace"}}
:enddata
:endrule

rule:
plugin=inventory
number=50
data:
JSON:{blockState:{blockName:"minecraft:chest",properties:{facing:"west"}},buildPass:0,lootLevel:0,teData:{x:-170,y:117,Items:[{Slot:0b,id:373s,Count:1b,Damage:0s},{Slot:2b,id:392s,Count:9b,Damage:0s},{Slot:5b,id:373s,Count:1b,Damage:8230s},{Slot:7b,id:373s,Count:1b,Damage:0s},{Slot:8b,id:373s,Count:1b,Damage:8201s},{Slot:9b,id:373s,Count:1b,Damage:8193s},{Slot:11b,id:364s,Count:12b,Damage:0s},{Slot:12b,id:373s,Count:1b,Damage:8227s},{Slot:15b,id:296s,Count:26b,Damage:0s},{Slot:19b,id:373s,Count:1b,Damage:0s},{Slot:21b,id:373s,Count:1b,Damage:0s},{Slot:23b,id:320s,Count:12b,Damage:0s},{Slot:25b,id:351s,Count:27b,Damage:3s}],z:225,id:"Chest"},inventoryData:{length:27,inventoryContents:[{id:"minecraft:potion",Count:1b,tag:{Potion:"minecraft:water"},slot:0,Damage:0s},{id:"minecraft:potato",Count:9b,slot:2,Damage:0s},{id:"minecraft:potion",Count:1b,tag:{Potion:"minecraft:night_vision"},slot:5,Damage:0s},{id:"minecraft:potion",Count:1b,tag:{Potion:"minecraft:water"},slot:7,Damage:0s},{id:"minecraft:potion",Count:1b,tag:{Potion:"minecraft:strength"},slot:8,Damage:0s},{id:"minecraft:potion",Count:1b,tag:{Potion:"minecraft:regeneration"},slot:9,Damage:0s},{id:"minecraft:cooked_beef",Count:12b,slot:11,Damage:0s},{id:"minecraft:potion",Count:1b,tag:{Potion:"minecraft:fire_resistance"},slot:12,Damage:0s},{id:"minecraft:wheat",Count:26b,slot:15,Damage:0s},{id:"minecraft:potion",Count:1b,tag:{Potion:"minecraft:water"},slot:19,Damage:0s},{id:"minecraft:potion",Count:1b,tag:{Potion:"minecraft:water"},slot:21,Damage:0s},{id:"minecraft:cooked_porkchop",Count:12b,slot:23,Damage:0s},{id:"minecraft:dye",Count:27b,slot:25,Damage:3s}]}}
:enddata
:endrule

rule:
plugin=blockTile
number=51
data:
JSON:{blockState:{blockName:"minecraft:furnace",properties:{facing:"east"}},buildPass:0,teData:{CookTime:0s,BurnTime:0s,x:-167,y:117,Items:[],z:225,id:"Furnace"}}
:enddata
:endrule

rule:
plugin=vanillaBlocks
number=52
data:
JSON:{blockState:{blockName:"minecraft:carpet",properties:{color:"green"}},buildPass:2}
:enddata
:endrule

rule:
plugin=inventory
number=53
data:
JSON:{blockState:{blockName:"minecraft:chest",properties:{facing:"south"}},buildPass:0,lootLevel:1,teData:{x:-162,y:121,Items:[{Slot:0b,id:266s,Count:1b,Damage:0s}],z:213,id:"Chest"},inventoryData:{length:27,inventoryContents:[{id:"minecraft:gold_ingot",Count:1b,slot:0,Damage:0s}]}}
:enddata
:endrule

rule:
plugin=inventory
number=54
data:
JSON:{blockState:{blockName:"minecraft:chest",properties:{facing:"south"}},buildPass:0,lootLevel:2,teData:{x:-161,y:121,Items:[{Slot:0b,id:264s,Count:1b,Damage:0s}],z:213,id:"Chest"},inventoryData:{length:27,inventoryContents:[{id:"minecraft:diamond",Count:1b,slot:0,Damage:0s}]}}
:enddata
:endrule

rule:
plugin=inventory
number=55
data:
JSON:{blockState:{blockName:"minecraft:chest",properties:{facing:"south"}},buildPass:0,lootLevel:2,teData:{x:-172,y:121,Items:[{Slot:0b,id:264s,Count:1b,Damage:0s}],z:214,id:"Chest"},inventoryData:{length:27,inventoryContents:[{id:"minecraft:diamond",Count:1b,slot:0,Damage:0s}]}}
:enddata
:endrule

rule:
plugin=inventory
number=56
data:
JSON:{blockState:{blockName:"minecraft:chest",properties:{facing:"south"}},buildPass:0,lootLevel:2,teData:{x:-171,y:121,Items:[{Slot:0b,id:264s,Count:1b,Damage:0s}],z:214,id:"Chest"},inventoryData:{length:27,inventoryContents:[{id:"minecraft:diamond",Count:1b,slot:0,Damage:0s}]}}
:enddata
:endrule

rule:
plugin=inventory
number=57
data:
JSON:{blockState:{blockName:"minecraft:chest",properties:{facing:"west"}},buildPass:0,lootLevel:1,teData:{x:-160,y:121,Items:[{Slot:0b,id:266s,Count:1b,Damage:0s}],z:214,id:"Chest"},inventoryData:{length:27,inventoryContents:[{id:"minecraft:gold_ingot",Count:1b,slot:0,Damage:0s}]}}
:enddata
:endrule

rule:
plugin=inventory
number=58
data:
JSON:{blockState:{blockName:"minecraft:chest",properties:{facing:"west"}},buildPass:0,lootLevel:3,teData:{x:-170,y:121,Items:[{Slot:0b,id:388s,Count:1b,Damage:0s}],z:215,id:"Chest"},inventoryData:{length:27,inventoryContents:[{id:"minecraft:emerald",Count:1b,slot:0,Damage:0s}]}}
:enddata
:endrule

rule:
plugin=inventory
number=59
data:
JSON:{blockState:{blockName:"minecraft:chest",properties:{facing:"west"}},buildPass:0,lootLevel:1,teData:{x:-160,y:121,Items:[{Slot:0b,id:266s,Count:1b,Damage:0s}],z:215,id:"Chest"},inventoryData:{length:27,inventoryContents:[{id:"minecraft:gold_ingot",Count:1b,slot:0,Damage:0s}]}}
:enddata
:endrule

rule:
plugin=inventory
number=60
data:
JSON:{blockState:{blockName:"minecraft:chest",properties:{facing:"west"}},buildPass:0,lootLevel:3,teData:{x:-170,y:121,Items:[{Slot:0b,id:388s,Count:1b,Damage:0s}],z:216,id:"Chest"},inventoryData:{length:27,inventoryContents:[{id:"minecraft:emerald",Count:1b,slot:0,Damage:0s}]}}
:enddata
:endrule

rule:
plugin=inventory
number=61
data:
JSON:{blockState:{blockName:"minecraft:chest",properties:{facing:"north"}},buildPass:0,lootLevel:3,teData:{x:-162,y:121,Items:[{Slot:0b,id:388s,Count:1b,Damage:0s}],z:216,id:"Chest"},inventoryData:{length:27,inventoryContents:[{id:"minecraft:emerald",Count:1b,slot:0,Damage:0s}]}}
:enddata
:endrule

rule:
plugin=inventory
number=62
data:
JSON:{blockState:{blockName:"minecraft:chest",properties:{facing:"north"}},buildPass:0,lootLevel:2,teData:{x:-161,y:121,Items:[{Slot:0b,id:264s,Count:1b,Damage:0s}],z:216,id:"Chest"},inventoryData:{length:27,inventoryContents:[{id:"minecraft:diamond",Count:1b,slot:0,Damage:0s}]}}
:enddata
:endrule

rule:
plugin=inventory
number=63
data:
JSON:{blockState:{blockName:"minecraft:chest",properties:{facing:"north"}},buildPass:0,lootLevel:1,teData:{x:-172,y:121,Items:[{Slot:0b,id:266s,Count:1b,Damage:0s}],z:217,id:"Chest"},inventoryData:{length:27,inventoryContents:[{id:"minecraft:gold_ingot",Count:1b,slot:0,Damage:0s}]}}
:enddata
:endrule

rule:
plugin=inventory
number=64
data:
JSON:{blockState:{blockName:"minecraft:chest",properties:{facing:"north"}},buildPass:0,lootLevel:1,teData:{x:-171,y:121,Items:[{Slot:0b,id:266s,Count:1b,Damage:0s}],z:217,id:"Chest"},inventoryData:{length:27,inventoryContents:[{id:"minecraft:gold_ingot",Count:1b,slot:0,Damage:0s}]}}
:enddata
:endrule

rule:
plugin=inventory
number=65
data:
JSON:{blockState:{blockName:"minecraft:chest",properties:{facing:"south"}},buildPass:0,lootLevel:0,teData:{x:-163,y:121,Items:[{Slot:0b,id:300s,Count:1b,Damage:0s},{Slot:1b,id:299s,Count:1b,Damage:0s},{Slot:3b,id:38s,Count:1b,Damage:7s},{Slot:12b,id:296s,Count:2b,Damage:0s},{Slot:20b,id:351s,Count:1b,Damage:3s},{Slot:21b,id:351s,Count:1b,Damage:3s},{Slot:22b,id:351s,Count:5b,Damage:3s}],z:220,id:"Chest"},inventoryData:{length:27,inventoryContents:[{id:"minecraft:leather_leggings",Count:1b,slot:0,Damage:0s},{id:"minecraft:leather_chestplate",Count:1b,slot:1,Damage:0s},{id:"minecraft:red_flower",Count:1b,slot:3,Damage:7s},{id:"minecraft:wheat",Count:2b,slot:12,Damage:0s},{id:"minecraft:dye",Count:1b,slot:20,Damage:3s},{id:"minecraft:dye",Count:1b,slot:21,Damage:3s},{id:"minecraft:dye",Count:5b,slot:22,Damage:3s}]}}
:enddata
:endrule

rule:
plugin=inventory
number=66
data:
JSON:{blockState:{blockName:"minecraft:chest",properties:{facing:"south"}},buildPass:0,lootLevel:1,teData:{x:-173,y:121,Items:[{Slot:0b,id:266s,Count:1b,Damage:0s}],z:221,id:"Chest"},inventoryData:{length:27,inventoryContents:[{id:"minecraft:gold_ingot",Count:1b,slot:0,Damage:0s}]}}
:enddata
:endrule

rule:
plugin=inventory
number=67
data:
JSON:{blockState:{blockName:"minecraft:chest",properties:{facing:"south"}},buildPass:0,lootLevel:3,teData:{x:-172,y:121,Items:[{Slot:0b,id:388s,Count:1b,Damage:0s}],z:221,id:"Chest"},inventoryData:{length:27,inventoryContents:[{id:"minecraft:emerald",Count:1b,slot:0,Damage:0s}]}}
:enddata
:endrule

rule:
plugin=inventory
number=68
data:
JSON:{blockState:{blockName:"minecraft:chest",properties:{facing:"east"}},buildPass:0,lootLevel:1,teData:{x:-174,y:121,Items:[{Slot:0b,id:266s,Count:1b,Damage:0s}],z:222,id:"Chest"},inventoryData:{length:27,inventoryContents:[{id:"minecraft:gold_ingot",Count:1b,slot:0,Damage:0s}]}}
:enddata
:endrule

rule:
plugin=inventory
number=69
data:
JSON:{blockState:{blockName:"minecraft:chest",properties:{facing:"east"}},buildPass:0,lootLevel:2,teData:{x:-174,y:121,Items:[{Slot:0b,id:264s,Count:1b,Damage:0s}],z:223,id:"Chest"},inventoryData:{length:27,inventoryContents:[{id:"minecraft:diamond",Count:1b,slot:0,Damage:0s}]}}
:enddata
:endrule

rule:
plugin=inventory
number=70
data:
JSON:{blockState:{blockName:"minecraft:chest",properties:{facing:"west"}},buildPass:0,lootLevel:0,teData:{x:-161,y:121,Items:[{Slot:0b,id:300s,Count:1b,Damage:0s},{Slot:1b,id:301s,Count:1b,Damage:0s},{Slot:2b,id:296s,Count:13b,Damage:0s},{Slot:3b,id:373s,Count:1b,Damage:0s}],z:223,id:"Chest"},inventoryData:{length:27,inventoryContents:[{id:"minecraft:leather_leggings",Count:1b,slot:0,Damage:0s},{id:"minecraft:leather_boots",Count:1b,slot:1,Damage:0s},{id:"minecraft:wheat",Count:13b,slot:2,Damage:0s},{id:"minecraft:potion",Count:1b,tag:{Potion:"minecraft:water"},slot:3,Damage:0s}]}}
:enddata
:endrule

rule:
plugin=inventory
number=71
data:
JSON:{blockState:{blockName:"minecraft:chest",properties:{facing:"north"}},buildPass:0,lootLevel:1,teData:{x:-173,y:121,Items:[{Slot:0b,id:266s,Count:1b,Damage:0s}],z:224,id:"Chest"},inventoryData:{length:27,inventoryContents:[{id:"minecraft:gold_ingot",Count:1b,slot:0,Damage:0s}]}}
:enddata
:endrule

rule:
plugin=inventory
number=72
data:
JSON:{blockState:{blockName:"minecraft:chest",properties:{facing:"north"}},buildPass:0,lootLevel:1,teData:{x:-172,y:121,Items:[{Slot:0b,id:266s,Count:1b,Damage:0s}],z:224,id:"Chest"},inventoryData:{length:27,inventoryContents:[{id:"minecraft:gold_ingot",Count:1b,slot:0,Damage:0s}]}}
:enddata
:endrule

rule:
plugin=vanillaBlocks
number=73
data:
JSON:{blockState:{blockName:"minecraft:vine",properties:{east:"false",south:"false",north:"false",west:"false",up:"false"}},buildPass:2}
:enddata
:endrule

rule:
plugin=inventory
number=74
data:
JSON:{blockState:{blockName:"minecraft:chest",properties:{facing:"west"}},buildPass:0,lootLevel:0,teData:{x:-171,y:124,Items:[{Slot:0b,id:302s,Count:1b,Damage:0s},{Slot:1b,id:304s,Count:1b,Damage:0s},{Slot:2b,id:305s,Count:1b,Damage:0s},{Slot:3b,id:106s,Count:4b,Damage:0s},{Slot:4b,id:297s,Count:3b,Damage:0s},{Slot:13b,id:280s,Count:1b,Damage:0s},{Slot:14b,id:280s,Count:1b,Damage:0s},{Slot:20b,id:296s,Count:1b,Damage:0s},{Slot:21b,id:351s,Count:2b,Damage:3s}],z:214,id:"Chest"},inventoryData:{length:27,inventoryContents:[{id:"minecraft:chainmail_helmet",Count:1b,slot:0,Damage:0s},{id:"minecraft:chainmail_leggings",Count:1b,slot:1,Damage:0s},{id:"minecraft:chainmail_boots",Count:1b,slot:2,Damage:0s},{id:"minecraft:vine",Count:4b,slot:3,Damage:0s},{id:"minecraft:bread",Count:3b,slot:4,Damage:0s},{id:"minecraft:stick",Count:1b,slot:13,Damage:0s},{id:"minecraft:stick",Count:1b,slot:14,Damage:0s},{id:"minecraft:wheat",Count:1b,slot:20,Damage:0s},{id:"minecraft:dye",Count:2b,slot:21,Damage:3s}]}}
:enddata
:endrule

rule:
plugin=inventory
number=75
data:
JSON:{blockState:{blockName:"minecraft:chest",properties:{facing:"south"}},buildPass:0,lootLevel:0,teData:{x:-163,y:124,Items:[{Slot:0b,id:301s,Count:1b,Damage:0s},{Slot:1b,id:298s,Count:1b,Damage:0s},{Slot:13b,id:280s,Count:1b,Damage:0s},{Slot:14b,id:280s,Count:1b,Damage:0s},{Slot:19b,id:351s,Count:1b,Damage:3s},{Slot:21b,id:373s,Count:1b,Damage:0s},{Slot:22b,id:296s,Count:2b,Damage:0s},{Slot:23b,id:280s,Count:1b,Damage:0s},{Slot:24b,id:280s,Count:1b,Damage:0s}],z:214,id:"Chest"},inventoryData:{length:27,inventoryContents:[{id:"minecraft:leather_boots",Count:1b,slot:0,Damage:0s},{id:"minecraft:leather_helmet",Count:1b,slot:1,Damage:0s},{id:"minecraft:stick",Count:1b,slot:13,Damage:0s},{id:"minecraft:stick",Count:1b,slot:14,Damage:0s},{id:"minecraft:dye",Count:1b,slot:19,Damage:3s},{id:"minecraft:potion",Count:1b,tag:{Potion:"minecraft:water"},slot:21,Damage:0s},{id:"minecraft:wheat",Count:2b,slot:22,Damage:0s},{id:"minecraft:stick",Count:1b,slot:23,Damage:0s},{id:"minecraft:stick",Count:1b,slot:24,Damage:0s}]}}
:enddata
:endrule

rule:
plugin=vanillaBlocks
number=76
data:
JSON:{blockState:{blockName:"minecraft:bed",properties:{part:"head",facing:"east",occupied:"false"}},buildPass:2}
:enddata
:endrule

rule:
plugin=vanillaBlocks
number=77
data:
JSON:{blockState:{blockName:"minecraft:bed",properties:{part:"foot",facing:"east",occupied:"false"}},buildPass:2}
:enddata
:endrule

rule:
plugin=inventory
number=78
data:
JSON:{blockState:{blockName:"minecraft:chest",properties:{facing:"north"}},buildPass:0,lootLevel:0,teData:{x:-172,y:124,Items:[{Slot:0b,id:307s,Count:1b,Damage:0s},{Slot:1b,id:280s,Count:2b,Damage:0s},{Slot:2b,id:306s,Count:1b,Damage:0s},{Slot:3b,id:365s,Count:1b,Damage:0s},{Slot:4b,id:350s,Count:4b,Damage:0s},{Slot:5b,id:364s,Count:5b,Damage:0s},{Slot:10b,id:296s,Count:3b,Damage:0s},{Slot:11b,id:351s,Count:1b,Damage:3s}],z:217,id:"Chest"},inventoryData:{length:27,inventoryContents:[{id:"minecraft:iron_chestplate",Count:1b,slot:0,Damage:0s},{id:"minecraft:stick",Count:2b,slot:1,Damage:0s},{id:"minecraft:iron_helmet",Count:1b,slot:2,Damage:0s},{id:"minecraft:chicken",Count:1b,slot:3,Damage:0s},{id:"minecraft:cooked_fish",Count:4b,slot:4,Damage:0s},{id:"minecraft:cooked_beef",Count:5b,slot:5,Damage:0s},{id:"minecraft:wheat",Count:3b,slot:10,Damage:0s},{id:"minecraft:dye",Count:1b,slot:11,Damage:3s}]}}
:enddata
:endrule

rule:
plugin=inventory
number=79
data:
JSON:{blockState:{blockName:"minecraft:chest",properties:{facing:"north"}},buildPass:0,lootLevel:0,teData:{x:-171,y:124,Items:[],z:217,id:"Chest"},inventoryData:{length:27,inventoryContents:[]}}
:enddata
:endrule

rule:
plugin=inventory
number=80
data:
JSON:{blockState:{blockName:"minecraft:chest",properties:{facing:"south"}},buildPass:0,lootLevel:0,teData:{x:-162,y:124,Items:[{Slot:0b,id:299s,Count:1b,Damage:0s},{Slot:1b,id:298s,Count:1b,Damage:0s},{Slot:21b,id:351s,Count:2b,Damage:3s},{Slot:23b,id:373s,Count:1b,Damage:0s}],z:218,id:"Chest"},inventoryData:{length:27,inventoryContents:[{id:"minecraft:leather_chestplate",Count:1b,slot:0,Damage:0s},{id:"minecraft:leather_helmet",Count:1b,slot:1,Damage:0s},{id:"minecraft:dye",Count:2b,slot:21,Damage:3s},{id:"minecraft:potion",Count:1b,tag:{Potion:"minecraft:water"},slot:23,Damage:0s}]}}
:enddata
:endrule

rule:
plugin=inventory
number=81
data:
JSON:{blockState:{blockName:"minecraft:chest",properties:{facing:"south"}},buildPass:0,lootLevel:0,teData:{x:-160,y:124,Items:[{Slot:0b,id:300s,Count:1b,Damage:0s},{Slot:1b,id:301s,Count:1b,Damage:0s},{Slot:5b,id:373s,Count:1b,Damage:0s},{Slot:12b,id:280s,Count:1b,Damage:0s},{Slot:13b,id:280s,Count:1b,Damage:0s}],z:218,id:"Chest"},inventoryData:{length:27,inventoryContents:[{id:"minecraft:leather_leggings",Count:1b,slot:0,Damage:0s},{id:"minecraft:leather_boots",Count:1b,slot:1,Damage:0s},{id:"minecraft:potion",Count:1b,tag:{Potion:"minecraft:water"},slot:5,Damage:0s},{id:"minecraft:stick",Count:1b,slot:12,Damage:0s},{id:"minecraft:stick",Count:1b,slot:13,Damage:0s}]}}
:enddata
:endrule

rule:
plugin=inventory
number=82
data:
JSON:{blockState:{blockName:"minecraft:chest",properties:{facing:"east"}},buildPass:0,lootLevel:0,teData:{x:-168,y:124,Items:[{Slot:0b,id:305s,Count:1b,Damage:0s},{Slot:1b,id:303s,Count:1b,Damage:0s},{Slot:2b,id:297s,Count:3b,Damage:0s},{Slot:13b,id:39s,Count:1b,Damage:0s},{Slot:20b,id:106s,Count:2b,Damage:0s},{Slot:24b,id:38s,Count:1b,Damage:4s}],z:219,id:"Chest"},inventoryData:{length:27,inventoryContents:[{id:"minecraft:chainmail_boots",Count:1b,slot:0,Damage:0s},{id:"minecraft:chainmail_chestplate",Count:1b,slot:1,Damage:0s},{id:"minecraft:bread",Count:3b,slot:2,Damage:0s},{id:"minecraft:brown_mushroom",Count:1b,slot:13,Damage:0s},{id:"minecraft:vine",Count:2b,slot:20,Damage:0s},{id:"minecraft:red_flower",Count:1b,slot:24,Damage:4s}]}}
:enddata
:endrule

rule:
plugin=inventory
number=83
data:
JSON:{blockState:{blockName:"minecraft:chest",properties:{facing:"south"}},buildPass:0,lootLevel:1,teData:{x:-173,y:124,Items:[{Slot:0b,id:266s,Count:1b,Damage:0s}],z:221,id:"Chest"},inventoryData:{length:27,inventoryContents:[{id:"minecraft:gold_ingot",Count:1b,slot:0,Damage:0s}]}}
:enddata
:endrule

rule:
plugin=inventory
number=84
data:
JSON:{blockState:{blockName:"minecraft:chest",properties:{facing:"south"}},buildPass:0,lootLevel:1,teData:{x:-172,y:124,Items:[{Slot:0b,id:266s,Count:1b,Damage:0s}],z:221,id:"Chest"},inventoryData:{length:27,inventoryContents:[{id:"minecraft:gold_ingot",Count:1b,slot:0,Damage:0s}]}}
:enddata
:endrule

rule:
plugin=inventory
number=85
data:
JSON:{blockState:{blockName:"minecraft:chest",properties:{facing:"west"}},buildPass:0,lootLevel:1,teData:{x:-171,y:124,Items:[{Slot:0b,id:266s,Count:1b,Damage:0s}],z:222,id:"Chest"},inventoryData:{length:27,inventoryContents:[{id:"minecraft:gold_ingot",Count:1b,slot:0,Damage:0s}]}}
:enddata
:endrule

rule:
plugin=inventory
number=86
data:
JSON:{blockState:{blockName:"minecraft:chest",properties:{facing:"west"}},buildPass:0,lootLevel:1,teData:{x:-171,y:124,Items:[{Slot:0b,id:266s,Count:1b,Damage:0s}],z:223,id:"Chest"},inventoryData:{length:27,inventoryContents:[{id:"minecraft:gold_ingot",Count:1b,slot:0,Damage:0s}]}}
:enddata
:endrule

rule:
plugin=inventory
number=87
data:
JSON:{blockState:{blockName:"minecraft:chest",properties:{facing:"south"}},buildPass:0,lootLevel:0,teData:{x:-168,y:124,Items:[{Slot:0b,id:304s,Count:1b,Damage:0s},{Slot:1b,id:303s,Count:1b,Damage:0s},{Slot:2b,id:302s,Count:1b,Damage:0s},{Slot:3b,id:267s,Count:1b,Damage:0s},{Slot:4b,id:262s,Count:3b,Damage:0s},{Slot:12b,id:351s,Count:1b,Damage:3s}],z:223,id:"Chest"},inventoryData:{length:27,inventoryContents:[{id:"minecraft:chainmail_leggings",Count:1b,slot:0,Damage:0s},{id:"minecraft:chainmail_chestplate",Count:1b,slot:1,Damage:0s},{id:"minecraft:chainmail_helmet",Count:1b,slot:2,Damage:0s},{id:"minecraft:iron_sword",Count:1b,slot:3,Damage:0s},{id:"minecraft:arrow",Count:3b,slot:4,Damage:0s},{id:"minecraft:dye",Count:1b,slot:12,Damage:3s}]}}
:enddata
:endrule

rule:
plugin=inventory
number=88
data:
JSON:{blockState:{blockName:"minecraft:chest",properties:{facing:"north"}},buildPass:0,lootLevel:1,teData:{x:-172,y:124,Items:[{Slot:0b,id:266s,Count:1b,Damage:0s}],z:224,id:"Chest"},inventoryData:{length:27,inventoryContents:[{id:"minecraft:gold_ingot",Count:1b,slot:0,Damage:0s}]}}
:enddata
:endrule

#### ENTITIES ####
entity:
plugin=AWNpc
number=0
data:
JSON:{xOffset:0.5f,equipmentData:{equipmentContents:[{id:"minecraft:iron_sword",Count:1b,slot:0,Damage:0s}]},rotation:184.11517f,mobID:"ancientwarfarenpc:faction.soldier",zOffset:0.5f,position:3024529391631L,entityData:{Attributes:[{Base:20.0d,Name:"generic.maxHealth"},{Base:0.0d,Name:"generic.knockbackResistance"},{Base:0.325d,Name:"generic.movementSpeed"},{Base:60.0d,Name:"generic.followRange"},{Base:2.0d,Name:"generic.attackDamage"}],Invulnerable:0b,AbsorptionAmount:0.0f,PortalCooldown:0,FallDistance:0.0f,levelingStats:{level:0,xp:0,entryList:[]},DeathTime:0s,DropChances:[1.0f,1.0f,1.0f,1.0f,1.0f],PersistenceRequired:1b,HealF:20.0f,owner:"shadowmage4513",Motion:[0.0d,-0.0784000015258789d,0.0d],armorValueOverride:-1,Leashed:0b,Health:20s,OnGround:1b,Dimension:0,Air:300s,Rotation:[4.115172f,0.0f],CustomName:"",Pos:[-164.5d,117.0d,214.5d],Fire:-1s,attackDamageOverride:-1,customTex:"",CanPickUpLoot:0b,factionName:"kong",HurtTime:0s,AttackTime:0s,CustomNameVisible:0b}}
:enddata
:endentity

entity:
plugin=AWNpc
number=1
data:
JSON:{xOffset:0.58192474f,equipmentData:{equipmentContents:[{id:"minecraft:iron_sword",Count:1b,slot:0,Damage:0s}]},rotation:185.71799f,mobID:"ancientwarfarenpc:faction.soldier",zOffset:0.41244215f,position:4124041019407L,entityData:{Attributes:[{Base:20.0d,Name:"generic.maxHealth"},{Base:0.0d,Name:"generic.knockbackResistance"},{Base:0.325d,Name:"generic.movementSpeed"},{Base:60.0d,Name:"generic.followRange"},{Base:2.0d,Name:"generic.attackDamage"}],Invulnerable:0b,AbsorptionAmount:0.0f,PortalCooldown:0,FallDistance:0.0f,levelingStats:{level:0,xp:0,entryList:[]},DeathTime:0s,DropChances:[1.0f,1.0f,1.0f,1.0f,1.0f],PersistenceRequired:1b,HealF:20.0f,owner:"shadowmage4513",Motion:[0.0d,-0.0784000015258789d,0.0d],armorValueOverride:-1,Leashed:0b,Health:20s,OnGround:1b,Dimension:0,Air:300s,Rotation:[5.717983f,0.0f],CustomName:"",Pos:[-168.58192473558535d,117.0d,214.5875578687931d],Fire:-1s,attackDamageOverride:-1,customTex:"",CanPickUpLoot:0b,factionName:"kong",HurtTime:0s,AttackTime:0s,CustomNameVisible:0b}}
:enddata
:endentity

entity:
plugin=AWNpc
number=2
data:
JSON:{xOffset:0.27141052f,equipmentData:{equipmentContents:[{id:"minecraft:iron_sword",Count:1b,slot:0,Damage:0s}]},rotation:183.86162f,mobID:"ancientwarfarenpc:faction.soldier",zOffset:0.3f,position:4124041019400L,entityData:{Attributes:[{Base:20.0d,Name:"generic.maxHealth"},{Base:0.0d,Name:"generic.knockbackResistance"},{Base:0.325d,Name:"generic.movementSpeed"},{Base:60.0d,Name:"generic.followRange"},{Base:2.0d,Name:"generic.attackDamage"}],Invulnerable:0b,AbsorptionAmount:0.0f,PortalCooldown:0,FallDistance:0.0f,levelingStats:{level:0,xp:0,entryList:[]},DeathTime:0s,DropChances:[1.0f,1.0f,1.0f,1.0f,1.0f],PersistenceRequired:1b,HealF:20.0f,owner:"shadowmage4513",Motion:[0.0d,-0.0784000015258789d,0.0d],armorValueOverride:-1,Leashed:0b,Health:20s,OnGround:1b,Dimension:0,Air:300s,Rotation:[3.8616195f,0.0f],CustomName:"",Pos:[-168.27141053494634d,117.0d,221.69999998807907d],Fire:-1s,attackDamageOverride:-1,customTex:"",CanPickUpLoot:0b,factionName:"kong",HurtTime:0s,AttackTime:0s,CustomNameVisible:0b}}
:enddata
:endentity

entity:
plugin=AWNpc
number=3
data:
JSON:{xOffset:0.5f,equipmentData:{equipmentContents:[{id:"minecraft:iron_sword",Count:1b,slot:0,Damage:0s}]},rotation:185.97284f,mobID:"ancientwarfarenpc:faction.soldier",zOffset:0.5f,position:2199895670790L,entityData:{Attributes:[{Base:20.0d,Name:"generic.maxHealth"},{Base:0.0d,Name:"generic.knockbackResistance"},{Base:0.325d,Name:"generic.movementSpeed"},{Base:60.0d,Name:"generic.followRange"},{Base:2.0d,Name:"generic.attackDamage"}],Invulnerable:0b,AbsorptionAmount:0.0f,PortalCooldown:0,FallDistance:0.0f,levelingStats:{level:0,xp:0,entryList:[]},DeathTime:0s,DropChances:[1.0f,1.0f,1.0f,1.0f,1.0f],PersistenceRequired:1b,HealF:20.0f,owner:"shadowmage4513",Motion:[0.0d,-0.0784000015258789d,0.0d],armorValueOverride:-1,Leashed:0b,Health:20s,OnGround:1b,Dimension:0,Air:300s,Rotation:[5.972842f,0.0f],CustomName:"",Pos:[-161.5d,117.0d,223.5d],Fire:-1s,attackDamageOverride:-1,customTex:"",CanPickUpLoot:0b,factionName:"kong",HurtTime:0s,AttackTime:0s,CustomNameVisible:0b}}
:enddata
:endentity

entity:
plugin=AWNpc
number=4
data:
JSON:{xOffset:0.040388584f,equipmentData:{equipmentContents:[{id:"minecraft:bow",Count:1b,slot:0,Damage:0s}]},rotation:180.01993f,mobID:"ancientwarfarenpc:faction.archer",zOffset:0.28667837f,position:4399187361802L,entityData:{Attributes:[{Base:20.0d,Name:"generic.maxHealth"},{Base:0.0d,Name:"generic.knockbackResistance"},{Base:0.325d,Name:"generic.movementSpeed"},{Base:60.0d,Name:"generic.followRange"},{Base:2.0d,Name:"generic.attackDamage"}],Invulnerable:0b,AbsorptionAmount:0.0f,PortalCooldown:0,FallDistance:0.0f,levelingStats:{level:0,xp:0,entryList:[]},DeathTime:0s,DropChances:[1.0f,1.0f,1.0f,1.0f,1.0f],PersistenceRequired:1b,HealF:20.0f,owner:"shadowmage4513",Motion:[0.0d,-0.0784000015258789d,0.0d],armorValueOverride:-1,Leashed:0b,Health:20s,OnGround:1b,Dimension:0,Air:300s,Rotation:[0.019935248f,0.0f],CustomName:"",Pos:[-169.0403885822807d,121.0d,219.71332161688858d],Fire:-1s,attackDamageOverride:-1,customTex:"",CanPickUpLoot:0b,factionName:"kong",HurtTime:0s,AttackTime:0s,CustomNameVisible:0b}}
:enddata
:endentity

entity:
plugin=AWNpc
number=5
data:
JSON:{xOffset:0.5f,equipmentData:{equipmentContents:[{id:"minecraft:bow",Count:1b,slot:0,Damage:0s}]},rotation:184.20688f,mobID:"ancientwarfarenpc:faction.archer",zOffset:0.5f,position:1925487525900L,entityData:{Attributes:[{Base:20.0d,Name:"generic.maxHealth"},{Base:0.0d,Name:"generic.knockbackResistance"},{Base:0.325d,Name:"generic.movementSpeed"},{Base:60.0d,Name:"generic.followRange"},{Base:2.0d,Name:"generic.attackDamage"}],Invulnerable:0b,AbsorptionAmount:0.0f,PortalCooldown:0,FallDistance:0.0f,levelingStats:{level:0,xp:0,entryList:[]},DeathTime:0s,DropChances:[1.0f,1.0f,1.0f,1.0f,1.0f],PersistenceRequired:1b,HealF:20.0f,owner:"shadowmage4513",Motion:[0.0d,-0.0784000015258789d,0.0d],armorValueOverride:-1,Leashed:0b,Health:20s,OnGround:1b,Dimension:0,Air:300s,Rotation:[4.206884f,0.0f],CustomName:"",Pos:[-160.5d,124.0d,217.5d],Fire:-1s,attackDamageOverride:-1,customTex:"",CanPickUpLoot:0b,factionName:"kong",HurtTime:0s,AttackTime:0s,CustomNameVisible:0b}}
:enddata
:endentity

entity:
plugin=AWNpc
number=6
data:
JSON:{xOffset:0.10149157f,equipmentData:{equipmentContents:[{id:"minecraft:bow",Count:1b,slot:0,Damage:0s}]},rotation:180.51746f,mobID:"ancientwarfarenpc:faction.archer",zOffset:0.95823956f,position:2474773577738L,entityData:{Attributes:[{Base:20.0d,Name:"generic.maxHealth"},{Base:0.0d,Name:"generic.knockbackResistance"},{Base:0.325d,Name:"generic.movementSpeed"},{Base:60.0d,Name:"generic.followRange"},{Base:2.0d,Name:"generic.attackDamage"}],Invulnerable:0b,AbsorptionAmount:0.0f,PortalCooldown:0,FallDistance:0.0f,levelingStats:{level:0,xp:0,entryList:[]},DeathTime:0s,DropChances:[1.0f,1.0f,1.0f,1.0f,1.0f],PersistenceRequired:1b,HealF:20.0f,owner:"shadowmage4513",Motion:[0.0d,-0.0784000015258789d,0.0d],armorValueOverride:-1,Leashed:0b,Health:20s,OnGround:1b,Dimension:0,Air:300s,Rotation:[0.5174574f,0.0f],CustomName:"",Pos:[-162.10149154865292d,117.0d,219.04176041464535d],Fire:-1s,attackDamageOverride:-1,customTex:"",CanPickUpLoot:0b,factionName:"kong",HurtTime:0s,AttackTime:0s,CustomNameVisible:0b}}
:enddata
:endentity

entity:
plugin=AWNpc
number=7
data:
JSON:{xOffset:0.6785683f,equipmentData:{equipmentContents:[{id:"minecraft:bow",Count:1b,slot:0,Damage:0s}]},rotation:182.31392f,mobID:"ancientwarfarenpc:faction.archer",zOffset:0.3213377f,position:5223552647177L,entityData:{Attributes:[{Base:20.0d,Name:"generic.maxHealth"},{Base:0.0d,Name:"generic.knockbackResistance"},{Base:0.325d,Name:"generic.movementSpeed"},{Base:60.0d,Name:"generic.followRange"},{Base:2.0d,Name:"generic.attackDamage"}],Invulnerable:0b,AbsorptionAmount:0.0f,PortalCooldown:0,FallDistance:0.0f,levelingStats:{level:0,xp:0,entryList:[]},DeathTime:0s,DropChances:[1.0f,1.0f,1.0f,1.0f,1.0f],PersistenceRequired:1b,HealF:20.0f,owner:"shadowmage4513",Motion:[0.0d,-0.0784000015258789d,0.0d],armorValueOverride:-1,Leashed:0b,Health:20s,OnGround:1b,Dimension:0,Air:300s,Rotation:[2.313913f,0.0f],CustomName:"",Pos:[-172.67856830681913d,117.0d,220.67866229314617d],Fire:-1s,attackDamageOverride:-1,customTex:"",CanPickUpLoot:0b,factionName:"kong",HurtTime:0s,AttackTime:0s,CustomNameVisible:0b}}
:enddata
:endentity

entity:
plugin=AWNpc
number=8
data:
JSON:{xOffset:0.2635628f,equipmentData:{equipmentContents:[{id:"minecraft:bow",Count:1b,slot:0,Damage:0s}]},rotation:225.76738f,mobID:"ancientwarfarenpc:faction.archer",zOffset:0.72980905f,position:5223552647183L,entityData:{Attributes:[{Base:20.0d,Name:"generic.maxHealth"},{Base:0.0d,Name:"generic.knockbackResistance"},{Base:0.325d,Name:"generic.movementSpeed"},{Base:60.0d,Name:"generic.followRange"},{Base:2.0d,Name:"generic.attackDamage"}],Invulnerable:0b,AbsorptionAmount:0.0f,PortalCooldown:0,FallDistance:0.0f,levelingStats:{level:0,xp:0,entryList:[]},DeathTime:0s,DropChances:[1.0f,1.0f,1.0f,1.0f,1.0f],PersistenceRequired:1b,HealF:20.0f,owner:"shadowmage4513",Motion:[0.0d,-0.0784000015258789d,0.0d],armorValueOverride:-1,Leashed:0b,Health:20s,OnGround:1b,Dimension:0,Air:300s,Rotation:[45.76738f,0.0f],CustomName:"",Pos:[-172.2635627709988d,117.0d,214.2701909554635d],Fire:-1s,attackDamageOverride:-1,customTex:"",CanPickUpLoot:0b,factionName:"kong",HurtTime:0s,AttackTime:0s,CustomNameVisible:0b}}
:enddata
:endentity

entity:
plugin=AWNpc
number=9
data:
JSON:{xOffset:0.5f,equipmentData:{equipmentContents:[{id:"minecraft:bow",Count:1b,slot:0,Damage:0s}]},rotation:182.53403f,mobID:"ancientwarfarenpc:faction.archer",zOffset:0.5f,position:3299407298577L,entityData:{Attributes:[{Base:20.0d,Name:"generic.maxHealth"},{Base:0.0d,Name:"generic.knockbackResistance"},{Base:0.325d,Name:"generic.movementSpeed"},{Base:60.0d,Name:"generic.followRange"},{Base:2.0d,Name:"generic.attackDamage"}],Invulnerable:0b,AbsorptionAmount:0.0f,PortalCooldown:0,FallDistance:0.0f,levelingStats:{level:0,xp:0,entryList:[]},DeathTime:0s,DropChances:[1.0f,1.0f,1.0f,1.0f,1.0f],PersistenceRequired:1b,HealF:20.0f,owner:"shadowmage4513",Motion:[0.0d,-0.0784000015258789d,0.0d],armorValueOverride:-1,Leashed:0b,Health:20s,OnGround:1b,Dimension:0,Air:300s,Rotation:[2.5340326f,0.0f],CustomName:"",Pos:[-165.5d,117.0d,212.5d],Fire:-1s,attackDamageOverride:-1,customTex:"",CanPickUpLoot:0b,factionName:"kong",HurtTime:0s,AttackTime:0s,CustomNameVisible:0b}}
:enddata
:endentity

entity:
plugin=AWNpc
number=10
data:
JSON:{xOffset:0.5f,equipmentData:{equipmentContents:[{id:"minecraft:book",Count:1b,slot:0,Damage:0s}]},rotation:182.53102f,mobID:"ancientwarfarenpc:faction.priest",zOffset:0.5f,position:4124041019397L,entityData:{Attributes:[{Base:20.0d,Name:"generic.maxHealth"},{Base:0.0d,Name:"generic.knockbackResistance"},{Base:0.325d,Name:"generic.movementSpeed"},{Base:60.0d,Name:"generic.followRange"},{Base:2.0d,Name:"generic.attackDamage"}],Invulnerable:0b,AbsorptionAmount:0.0f,PortalCooldown:0,FallDistance:0.0f,levelingStats:{level:0,xp:0,entryList:[]},DeathTime:0s,DropChances:[1.0f,1.0f,1.0f,1.0f,1.0f],PersistenceRequired:1b,HealF:20.0f,owner:"shadowmage4513",Motion:[0.0d,-0.0784000015258789d,0.0d],armorValueOverride:-1,Leashed:0b,Health:20s,OnGround:1b,Dimension:0,Air:300s,Rotation:[2.5310278f,0.0f],CustomName:"",Pos:[-168.5d,117.0d,224.5d],Fire:-1s,attackDamageOverride:-1,customTex:"",CanPickUpLoot:0b,factionName:"kong",HurtTime:0s,AttackTime:0s,CustomNameVisible:0b}}
:enddata
:endentity

entity:
plugin=AWNpc
number=11
data:
JSON:{xOffset:0.5f,equipmentData:{equipmentContents:[{id:"minecraft:bow",Count:1b,slot:0,Damage:0s}]},rotation:180.49515f,mobID:"ancientwarfarenpc:faction.archer",zOffset:0.5f,position:2474773577733L,entityData:{Attributes:[{Base:20.0d,Name:"generic.maxHealth"},{Base:0.0d,Name:"generic.knockbackResistance"},{Base:0.325d,Name:"generic.movementSpeed"},{Base:60.0d,Name:"generic.followRange"},{Base:2.0d,Name:"generic.attackDamage"}],Invulnerable:0b,AbsorptionAmount:0.0f,PortalCooldown:0,FallDistance:0.0f,levelingStats:{level:0,xp:0,entryList:[]},DeathTime:0s,DropChances:[1.0f,1.0f,1.0f,1.0f,1.0f],PersistenceRequired:1b,HealF:20.0f,owner:"shadowmage4513",Motion:[0.0d,-0.0784000015258789d,0.0d],armorValueOverride:-1,Leashed:0b,Health:20s,OnGround:1b,Dimension:0,Air:300s,Rotation:[0.49514148f,0.0f],CustomName:"",Pos:[-162.5d,117.0d,224.5d],Fire:-1s,attackDamageOverride:-1,customTex:"",CanPickUpLoot:0b,factionName:"kong",HurtTime:0s,AttackTime:0s,CustomNameVisible:0b}}
:enddata
:endentity

entity:
plugin=AWNpc
number=12
data:
JSON:{xOffset:0.5f,equipmentData:{equipmentContents:[{id:"minecraft:bow",Count:1b,slot:0,Damage:0s}]},rotation:183.4039f,mobID:"ancientwarfarenpc:faction.archer",zOffset:0.5f,position:1375530385417L,entityData:{Attributes:[{Base:20.0d,Name:"generic.maxHealth"},{Base:0.0d,Name:"generic.knockbackResistance"},{Base:0.325d,Name:"generic.movementSpeed"},{Base:60.0d,Name:"generic.followRange"},{Base:2.0d,Name:"generic.attackDamage"}],Invulnerable:0b,AbsorptionAmount:0.0f,PortalCooldown:0,FallDistance:0.0f,levelingStats:{level:0,xp:0,entryList:[]},DeathTime:0s,DropChances:[1.0f,1.0f,1.0f,1.0f,1.0f],PersistenceRequired:1b,HealF:20.0f,owner:"shadowmage4513",Motion:[0.0d,-0.0784000015258789d,0.0d],armorValueOverride:-1,Leashed:0b,Health:20s,OnGround:1b,Dimension:0,Air:300s,Rotation:[3.4038937f,0.0f],CustomName:"",Pos:[-158.5d,121.0d,220.5d],Fire:-1s,attackDamageOverride:-1,customTex:"",CanPickUpLoot:0b,factionName:"kong",HurtTime:0s,AttackTime:0s,CustomNameVisible:0b}}
:enddata
:endentity

entity:
plugin=AWNpc
number=13
data:
JSON:{xOffset:0.5f,equipmentData:{equipmentContents:[{id:"minecraft:bow",Count:1b,slot:0,Damage:0s}]},rotation:186.20679f,mobID:"ancientwarfarenpc:faction.archer",zOffset:0.5f,position:1650408292365L,entityData:{Attributes:[{Base:20.0d,Name:"generic.maxHealth"},{Base:0.0d,Name:"generic.knockbackResistance"},{Base:0.325d,Name:"generic.movementSpeed"},{Base:60.0d,Name:"generic.followRange"},{Base:2.0d,Name:"generic.attackDamage"}],Invulnerable:0b,AbsorptionAmount:0.0f,PortalCooldown:0,FallDistance:0.0f,levelingStats:{level:0,xp:0,entryList:[]},DeathTime:0s,DropChances:[1.0f,1.0f,1.0f,1.0f,1.0f],PersistenceRequired:1b,HealF:20.0f,owner:"shadowmage4513",Motion:[0.0d,-0.0784000015258789d,0.0d],armorValueOverride:-1,Leashed:0b,Health:20s,OnGround:1b,Dimension:0,Air:300s,Rotation:[6.2067857f,0.0f],CustomName:"",Pos:[-159.5d,121.0d,216.5d],Fire:-1s,attackDamageOverride:-1,customTex:"",CanPickUpLoot:0b,factionName:"kong",HurtTime:0s,AttackTime:0s,CustomNameVisible:0b}}
:enddata
:endentity

