# Ancient Warfare Structure Template File
# Auto-generated structure template file. created on: 8/28/2018 at: 17:29:59
# Lines beginning with # denote comments

header:
version=2.3
name=pirate_fortress
size=27,16,27
offset=13,1,26
:endheader

#### VALIDATION ####
validation:
type=ground
survival=false
worldGenEnabled=true
unique=false
preserveBlocks=false
selectionWeight=10
clusterValue=125
minDuplicateDistance=40
dimensionWhiteList=true
dimensionList=0
biomeWhiteList=true
biomeList=minecraft:taiga,minecraft:desert_hills,biomesoplenty:ominous_woods,biomesoplenty:mountain,minecraft:desert,minecraft:mutated_desert,biomesoplenty:wasteland,biomesoplenty:outback,minecraft:mutated_taiga,biomesoplenty:chaparral,biomesoplenty:lush_desert,minecraft:forest_hills,biomesoplenty:maple_woods,biomesoplenty:steppe,minecraft:plains,biomesoplenty:grassland,biomesoplenty:seasonal_forest
leveling=5
fill=5
border=5
blockSwap=false
data:
:enddata
:endvalidation

#### LAYERS ####
layer: 0
1,1,1,1,1,1,1,1,1,1,1,1,1,1,1,1,1,1,1,1,1,1,1,1,1,1,1
1,2,2,2,2,2,1,1,1,1,1,1,1,1,1,1,1,1,1,1,1,2,2,2,2,2,1
1,2,2,2,2,2,1,1,1,1,1,1,1,1,1,1,1,1,1,1,1,2,2,2,2,2,1
1,2,2,2,2,2,2,2,2,2,2,2,2,2,2,2,2,2,2,2,2,2,2,2,2,2,1
1,2,2,2,2,2,3,3,3,3,3,3,3,3,3,3,3,3,3,3,3,2,2,2,2,2,1
1,2,2,2,2,2,4,4,4,3,3,4,4,4,4,4,3,3,4,4,4,2,2,2,2,2,1
1,1,1,2,3,4,4,4,4,3,3,4,4,4,4,4,3,3,4,4,4,4,3,2,1,1,1
1,1,1,2,3,4,4,4,4,3,3,4,4,4,4,4,3,3,4,4,4,4,3,2,1,1,1
1,1,1,2,3,4,4,4,4,3,3,4,4,4,4,4,3,3,4,4,4,4,3,2,1,1,1
1,1,1,2,3,3,3,3,3,2,2,3,3,3,3,3,2,2,3,3,3,3,3,2,1,1,1
1,1,1,2,3,3,3,3,3,2,2,3,3,3,3,3,2,2,3,3,3,3,3,2,1,1,1
1,1,1,2,3,4,4,4,4,3,3,4,4,4,4,4,3,3,4,4,4,4,3,2,1,1,1
1,1,1,2,3,4,4,4,4,3,3,4,4,4,4,4,3,3,4,4,4,4,3,2,1,1,1
1,1,1,2,3,4,4,4,4,3,3,4,4,4,4,4,3,3,4,4,4,4,3,2,1,1,1
1,1,1,2,3,4,4,4,4,3,3,4,4,4,4,4,3,3,4,4,4,4,3,2,1,1,1
1,1,1,2,3,4,4,4,4,3,3,4,4,4,4,4,3,3,4,4,4,4,3,2,1,1,1
1,1,1,2,3,3,3,3,3,2,2,3,3,3,3,3,2,2,3,3,3,3,3,2,1,1,1
1,1,1,2,3,3,3,3,3,2,2,3,3,3,3,3,2,2,3,3,3,3,3,2,1,1,1
1,1,1,2,3,4,4,4,4,3,3,4,4,4,4,4,3,3,4,4,4,4,3,2,1,1,1
1,1,1,2,3,4,4,4,4,3,3,4,4,4,4,4,3,3,4,4,4,4,3,2,1,1,1
1,1,1,2,3,4,4,4,4,3,3,4,4,4,4,4,3,3,4,4,4,4,3,2,1,1,1
1,2,2,2,2,2,4,4,4,2,2,3,3,3,3,3,2,2,4,4,4,2,2,2,2,2,1
1,2,2,2,2,2,3,3,3,2,2,3,3,3,3,3,2,2,3,3,3,2,2,2,2,2,1
1,2,2,2,2,2,2,2,2,2,2,3,3,3,3,3,2,2,2,2,2,2,2,2,2,2,1
1,2,2,2,2,2,1,1,1,1,1,1,1,1,1,1,1,1,1,1,1,2,2,2,2,2,1
1,2,2,2,2,2,1,1,1,1,1,1,1,1,1,1,1,1,1,1,1,2,2,2,2,2,1
1,1,1,1,1,1,1,1,1,1,1,1,1,1,1,1,1,1,1,1,1,1,1,1,1,1,1
:endlayer
layer: 1
0,0,5,0,0,5,0,0,0,0,0,0,0,6,0,5,0,5,5,5,0,0,5,0,5,0,5
0,2,2,2,2,2,0,0,5,0,5,5,0,5,5,5,5,5,0,5,5,2,2,2,2,2,0
0,2,0,0,0,2,0,0,0,0,0,0,0,0,0,0,5,5,0,0,0,2,0,0,0,2,0
5,2,0,0,7,2,2,2,2,2,2,2,2,14,2,2,2,2,2,2,2,2,7,0,0,2,5
0,2,0,9,10,9,0,0,0,0,0,0,0,0,0,0,0,0,0,0,0,9,10,9,0,2,0
0,2,2,2,9,2,0,0,0,0,0,0,0,0,0,0,0,0,0,0,0,2,9,2,2,2,0
0,0,0,2,0,0,0,0,0,0,0,0,0,0,0,0,0,0,0,0,0,0,0,2,0,0,0
5,0,0,2,0,0,0,0,0,0,0,0,0,0,0,0,0,0,0,0,0,0,0,2,0,5,0
6,5,0,2,0,0,0,0,0,0,0,0,13,13,13,0,0,0,0,0,0,0,0,2,5,5,0
0,5,0,2,9,0,0,0,0,2,2,0,12,12,12,0,2,2,0,0,0,0,0,2,0,5,0
5,0,0,2,0,0,0,0,0,2,2,0,0,0,0,0,2,2,0,0,0,0,0,2,5,5,5
0,5,0,2,0,0,0,0,0,0,0,0,0,0,0,0,0,0,0,0,0,0,0,2,0,5,0
0,0,5,2,0,0,0,0,0,0,0,0,0,0,0,0,0,0,0,0,0,0,0,2,5,0,0
0,5,5,2,0,0,0,0,0,0,0,0,0,0,0,0,0,0,0,0,0,0,0,2,0,0,0
0,0,0,2,0,0,0,0,0,0,0,0,0,0,0,0,0,0,0,0,0,0,0,2,0,5,0
0,0,0,2,0,0,0,0,0,0,0,0,0,0,0,0,0,0,0,0,0,0,0,2,0,0,5
0,0,5,2,0,0,0,0,0,2,2,0,0,0,0,0,2,2,0,0,0,0,0,2,0,0,0
0,5,0,2,9,0,0,0,0,2,2,0,0,0,0,0,2,2,0,0,0,0,9,2,5,5,0
0,0,0,2,0,0,0,0,0,0,0,0,0,0,0,0,0,0,0,0,0,0,0,2,0,5,0
0,5,0,2,0,0,0,0,0,0,0,0,0,0,0,0,0,0,0,0,0,0,0,2,0,5,5
0,0,0,2,0,0,0,0,0,0,0,0,0,0,0,0,0,0,0,0,0,0,0,2,5,0,0
6,2,2,2,9,2,0,0,0,2,2,0,0,0,0,11,2,2,0,0,0,2,9,2,2,2,0
0,2,0,9,10,9,0,9,0,2,2,0,0,0,0,0,2,2,0,9,0,9,10,9,0,2,0
5,2,0,0,7,2,2,2,2,2,2,0,0,0,0,8,2,2,2,2,2,2,7,0,0,2,5
0,2,0,0,0,2,0,0,0,0,0,0,0,0,0,0,5,6,0,0,0,2,0,0,0,2,0
0,2,2,2,2,2,5,5,5,5,5,0,0,0,0,5,0,0,0,5,0,2,2,2,2,2,0
5,0,0,5,0,5,0,0,0,0,0,0,5,0,5,0,0,0,0,0,0,0,0,5,0,0,5
:endlayer
layer: 2
0,0,0,0,0,0,0,0,0,0,0,0,0,0,0,0,0,0,0,0,0,0,0,0,0,0,0
0,2,2,2,2,2,0,0,0,0,0,0,0,0,0,0,0,0,0,0,0,2,2,2,2,2,0
0,2,0,7,10,2,0,0,0,0,0,0,20,0,0,0,0,0,0,0,0,2,10,7,0,2,0
0,2,0,0,9,2,2,2,2,2,2,2,2,19,2,2,2,2,2,2,2,2,9,0,0,2,0
0,2,0,0,0,0,0,0,0,0,0,0,0,0,18,0,0,0,0,0,0,0,0,0,0,2,0
0,2,2,2,0,2,0,0,0,0,0,0,0,0,0,0,0,0,0,0,0,2,0,2,2,2,0
0,0,0,2,0,0,0,0,0,0,0,0,0,0,0,0,0,0,0,0,0,0,0,2,0,0,0
0,0,0,2,0,0,0,0,0,0,0,0,13,13,13,0,0,0,0,0,0,0,0,2,0,0,0
0,0,0,2,0,0,0,0,0,0,0,0,12,12,12,0,0,0,0,0,0,0,0,2,0,0,0
0,0,0,17,0,0,0,0,0,2,2,0,0,0,0,0,2,2,0,0,0,0,0,16,0,0,0
0,0,0,2,0,0,0,0,0,2,2,0,0,0,0,0,2,2,0,0,0,0,0,2,0,0,0
0,0,0,2,0,0,0,0,0,0,0,0,0,0,0,0,0,0,0,0,0,0,0,2,0,0,0
0,0,0,2,0,0,0,0,0,0,0,0,0,0,0,0,0,0,0,0,0,0,0,2,0,0,0
0,0,0,2,0,0,0,0,0,0,0,0,0,0,0,0,0,0,0,0,0,0,0,2,0,0,0
0,0,0,2,0,0,0,0,0,0,0,0,0,0,0,0,0,0,0,0,0,0,0,2,0,0,0
0,0,0,2,0,0,0,0,0,0,0,0,0,0,0,0,0,0,0,0,0,0,0,2,0,0,0
0,0,0,2,0,0,0,0,0,2,2,0,0,0,0,0,2,2,0,0,0,0,0,2,0,0,0
0,0,0,17,0,0,0,0,0,2,2,0,0,0,0,0,2,2,0,0,0,0,0,16,0,0,0
0,0,0,2,0,0,0,0,0,0,0,0,0,0,0,0,0,0,0,0,0,0,0,2,0,0,0
0,0,0,2,0,0,0,0,0,0,0,0,0,0,0,0,0,0,0,0,0,0,0,2,0,0,0
0,0,0,2,0,0,0,0,0,0,0,0,0,0,0,0,0,0,0,0,0,0,0,2,0,0,0
0,2,2,2,0,2,0,0,0,2,2,0,0,0,0,0,2,2,0,0,0,2,0,2,2,2,0
0,2,0,0,0,0,0,0,0,2,2,0,0,0,0,0,2,2,0,0,0,0,0,0,0,2,0
0,2,0,0,9,2,2,15,2,2,2,0,0,0,0,0,2,2,2,15,2,2,9,0,0,2,0
0,2,0,7,10,2,0,0,0,0,0,0,0,0,0,0,0,0,0,0,0,2,10,7,0,2,0
0,2,2,2,2,2,0,0,0,0,0,0,0,0,0,0,0,0,0,0,0,2,2,2,2,2,0
0,0,0,0,0,0,0,0,0,0,0,0,0,0,0,0,0,0,0,0,0,0,0,0,0,0,0
:endlayer
layer: 3
0,0,0,0,0,0,0,0,0,0,0,0,0,0,0,0,0,0,0,0,0,0,0,0,0,0,0
0,2,2,2,2,2,0,0,0,0,0,0,0,0,0,0,0,0,0,0,0,2,2,2,2,2,0
0,2,10,9,0,2,0,0,0,0,0,0,0,0,0,0,0,0,0,0,0,2,0,9,10,2,0
0,2,7,0,0,2,2,2,2,2,2,2,2,2,2,2,2,2,2,2,2,2,0,0,7,2,0
0,2,0,24,0,0,0,0,0,23,0,25,0,23,0,25,0,23,0,0,0,0,0,24,0,2,0
0,2,2,2,0,2,22,0,0,0,0,7,0,0,0,7,0,0,0,0,21,2,0,2,2,2,0
0,0,0,2,0,23,0,0,0,0,0,7,13,13,13,7,0,0,0,0,0,23,0,2,0,0,0
0,0,0,2,0,0,0,0,0,0,0,0,12,12,12,0,0,0,0,0,0,0,0,2,0,0,0
0,0,0,2,0,0,0,0,0,24,24,0,0,0,0,0,0,24,0,0,0,0,0,2,0,0,0
0,0,0,0,0,0,0,0,21,2,2,0,0,0,0,0,2,2,0,0,0,0,0,0,0,0,0
0,0,0,2,22,0,0,0,21,2,2,0,0,0,0,0,2,2,22,0,0,0,21,2,0,0,0
0,0,0,2,0,0,0,0,0,0,0,0,0,0,0,0,0,23,0,0,0,0,0,2,0,0,0
0,0,0,2,0,0,0,0,0,0,0,0,0,0,0,0,0,0,0,0,0,0,0,2,0,0,0
0,0,0,2,0,0,0,0,0,0,0,0,0,0,0,0,0,0,0,0,0,0,0,2,0,0,0
0,0,0,2,0,0,0,0,0,0,0,0,0,0,0,0,0,0,0,0,0,0,0,2,0,0,0
0,0,0,2,0,0,0,0,0,24,0,0,0,0,0,0,0,24,0,0,0,0,0,2,0,0,0
0,0,0,2,22,0,0,0,21,2,2,0,0,0,0,0,2,2,22,0,0,0,21,2,0,0,0
0,0,0,0,0,0,0,0,0,2,2,0,0,0,0,0,2,2,0,0,0,0,0,0,0,0,0
0,0,0,2,0,0,0,0,0,23,0,0,0,0,0,0,0,23,0,0,0,0,0,2,0,0,0
0,0,0,2,0,0,0,0,0,0,0,0,0,0,0,0,0,0,0,0,0,0,0,2,0,0,0
0,0,0,2,0,24,0,0,0,24,0,0,0,0,0,0,0,24,0,0,0,24,0,2,0,0,0
0,2,2,2,0,2,22,0,21,2,2,22,0,0,0,21,2,2,22,0,21,2,0,2,2,2,0
0,2,0,23,0,0,0,0,0,2,2,0,0,0,0,0,2,2,24,0,0,0,0,23,0,2,0
0,2,7,0,0,2,2,0,2,2,2,22,0,0,0,21,2,2,2,0,2,2,0,0,7,2,0
0,2,10,9,0,2,0,0,0,0,0,0,0,0,0,0,0,0,0,0,0,2,0,9,10,2,0
0,2,2,2,2,2,0,0,0,0,0,0,0,0,0,0,0,0,0,0,0,2,2,2,2,2,0
0,0,0,0,0,0,0,0,0,0,0,0,0,0,0,0,0,0,0,0,0,0,0,0,0,0,0
:endlayer
layer: 4
0,0,0,0,0,0,0,0,0,0,0,0,0,0,0,0,0,0,0,0,0,0,0,0,0,0,0
0,2,2,26,2,2,0,0,0,0,0,0,0,0,0,0,0,0,0,0,0,2,2,26,2,2,0
0,2,0,0,0,2,0,0,0,0,0,0,0,0,0,0,0,0,0,0,0,2,0,0,0,2,0
0,26,9,0,0,2,2,2,2,2,2,2,2,2,2,2,2,2,2,2,2,2,0,0,9,26,0
0,2,10,7,0,2,0,0,0,31,10,34,9,9,9,33,10,31,0,0,0,2,0,7,10,2,0
0,2,2,2,2,2,0,0,0,0,35,34,9,9,9,33,32,0,0,0,0,2,2,2,2,2,0
0,0,0,2,0,0,0,0,0,0,35,34,9,9,9,33,32,0,0,0,0,0,0,2,0,0,0
0,0,0,2,0,0,0,0,0,0,0,0,0,0,0,0,0,0,0,0,0,0,0,2,0,0,0
0,0,0,2,0,0,0,0,0,30,0,0,0,0,0,0,0,30,0,0,0,0,0,2,0,0,0
0,0,0,27,0,0,0,0,0,2,2,0,0,0,0,0,2,2,0,0,0,0,0,27,0,0,0
0,0,0,2,28,0,0,0,29,2,2,0,0,0,0,0,2,2,28,0,0,0,29,2,0,0,0
0,0,0,2,0,0,0,0,0,31,0,0,0,0,0,0,0,31,0,0,0,0,0,2,0,0,0
0,0,0,2,0,0,0,0,0,0,0,0,0,0,0,0,0,0,0,0,0,0,0,2,0,0,0
0,0,0,2,0,0,0,0,0,0,0,0,0,0,0,0,0,0,0,0,0,0,0,2,0,0,0
0,0,0,2,0,0,0,0,0,0,0,0,0,0,0,0,0,0,0,0,0,0,0,2,0,0,0
0,0,0,2,0,0,0,0,0,30,0,0,0,0,0,0,0,30,0,0,0,0,0,2,0,0,0
0,0,0,2,28,0,0,0,29,2,2,0,0,0,0,0,2,2,28,0,0,0,29,2,0,0,0
0,0,0,27,0,0,0,0,0,2,2,0,0,0,0,0,2,2,0,0,0,0,0,27,0,0,0
0,0,0,2,0,0,0,0,0,31,0,0,0,0,0,0,0,31,0,0,0,0,0,2,0,0,0
0,0,0,2,0,0,0,0,0,0,0,0,0,0,0,0,0,0,0,0,0,0,0,2,0,0,0
0,0,0,2,0,0,0,0,0,30,0,0,0,0,0,0,0,30,0,0,0,0,0,2,0,0,0
0,2,2,2,2,2,0,0,29,2,2,0,0,0,0,0,2,2,28,0,0,2,2,2,2,2,0
0,2,10,7,0,2,0,0,29,2,2,0,0,0,0,0,2,2,28,0,0,2,0,7,10,2,0
0,26,9,0,0,2,2,27,2,2,2,0,0,0,0,0,2,2,2,27,2,2,0,0,9,26,0
0,2,0,0,0,2,0,0,0,0,0,0,0,0,0,0,0,0,0,0,0,2,0,0,0,2,0
0,2,2,26,2,2,0,0,0,0,0,0,0,0,0,0,0,0,0,0,0,2,2,26,2,2,0
0,0,0,0,0,0,0,0,0,0,0,0,0,0,0,0,0,0,0,0,0,0,0,0,0,0,0
:endlayer
layer: 5
0,0,0,0,0,0,0,0,0,0,0,0,0,0,0,0,0,0,0,0,0,0,0,0,0,0,0
0,2,2,0,2,2,0,0,0,0,0,0,0,0,0,0,0,0,0,0,0,2,2,0,2,2,0
0,2,0,0,0,2,0,0,0,0,0,0,0,0,0,0,0,0,0,0,0,2,0,0,0,2,0
0,0,0,0,7,2,2,2,2,2,2,2,2,2,2,2,2,2,2,2,2,2,7,0,0,0,0
0,2,0,9,10,2,7,7,7,37,34,0,0,0,0,0,33,37,7,7,7,2,10,9,0,2,0
0,2,2,2,2,2,7,7,7,37,34,0,0,0,0,0,33,37,7,7,7,2,2,2,2,2,0
0,0,0,2,7,7,7,7,7,37,34,0,0,0,0,0,33,37,7,7,7,7,7,2,0,0,0
0,0,0,2,7,7,7,7,7,37,32,0,0,0,0,0,35,37,7,7,7,7,7,2,0,0,0
0,0,0,2,7,7,7,7,7,37,32,0,0,0,0,0,35,37,7,7,7,7,7,2,0,0,0
0,0,0,2,7,7,7,7,7,2,2,0,0,0,0,0,2,2,7,7,7,7,7,2,0,0,0
0,0,0,2,38,38,38,38,38,2,2,38,38,38,38,38,2,2,38,38,38,38,38,2,0,0,0
0,0,0,2,7,7,7,7,7,37,7,7,7,7,7,7,7,37,7,7,7,7,7,2,0,0,0
0,0,0,2,7,7,7,7,7,37,38,38,38,38,38,38,38,37,7,7,7,7,7,2,0,0,0
0,0,0,2,7,7,7,7,7,37,0,0,0,0,0,0,0,37,7,7,7,7,7,2,0,0,0
0,0,0,2,7,7,7,7,7,37,0,0,0,0,0,0,0,37,7,7,7,7,7,2,0,0,0
0,0,0,2,7,7,7,7,7,37,0,0,0,0,0,0,0,37,7,7,7,7,7,2,0,0,0
0,0,0,2,38,38,38,38,38,2,2,0,0,0,0,0,2,2,38,38,38,38,38,2,0,0,0
0,0,0,2,7,7,7,7,7,2,2,0,0,0,0,0,2,2,7,7,7,7,7,2,0,0,0
0,0,0,2,7,7,7,7,7,37,0,0,0,0,0,0,0,37,7,7,7,7,7,2,0,0,0
0,0,0,2,7,7,7,7,7,37,0,0,0,0,0,0,0,37,7,7,7,7,7,2,0,0,0
0,0,0,2,7,7,7,7,7,37,0,0,0,0,0,0,0,37,7,7,7,7,7,2,0,0,0
0,2,2,2,2,2,7,7,10,2,2,2,2,2,2,2,2,2,10,7,7,2,2,2,2,2,0
0,2,0,9,10,2,7,7,10,2,2,2,2,2,2,2,2,2,10,7,7,2,10,9,0,2,0
0,0,0,0,7,2,2,2,2,2,2,2,2,2,2,2,2,2,2,36,2,2,7,0,0,0,0
0,2,0,0,0,2,0,0,0,0,0,0,0,0,0,0,0,0,0,0,0,2,0,0,0,2,0
0,2,2,0,2,2,0,0,0,0,0,0,0,0,0,0,0,0,0,0,0,2,2,0,2,2,0
0,0,0,0,0,0,0,0,0,0,0,0,0,0,0,0,0,0,0,0,0,0,0,0,0,0,0
:endlayer
layer: 6
0,0,0,0,0,0,0,0,0,0,0,0,0,0,0,0,0,0,0,0,0,0,0,0,0,0,0
0,2,2,31,2,2,0,0,0,0,0,0,0,0,0,0,0,0,0,0,0,2,2,31,2,2,0
0,2,0,7,10,2,0,0,0,0,0,0,0,0,0,0,0,0,0,0,0,2,10,7,0,2,0
0,28,0,0,9,2,2,26,2,2,2,26,2,2,2,26,2,2,2,26,2,2,9,0,0,29,0
0,2,0,0,0,0,0,0,0,0,0,0,0,0,0,0,0,0,0,0,0,0,0,0,0,2,0
0,2,2,2,0,2,0,0,0,0,0,0,0,0,0,0,0,0,0,0,0,2,0,2,2,2,0
0,0,0,2,0,0,0,0,0,0,0,0,0,0,0,0,0,0,0,0,0,0,0,2,0,0,0
0,0,0,26,0,0,0,0,0,0,33,32,0,0,0,35,34,0,0,0,0,0,0,26,0,0,0
0,0,0,2,0,0,0,0,0,0,33,32,0,0,0,35,34,0,0,0,0,0,0,2,0,0,0
0,0,0,2,0,0,0,0,0,2,2,0,0,0,0,0,2,2,0,0,0,0,0,2,0,0,0
0,0,0,2,0,0,0,0,0,2,2,39,39,39,39,39,2,2,0,0,0,0,0,2,0,0,0
0,0,0,26,0,0,0,0,0,0,0,0,0,0,0,0,0,0,0,0,0,0,0,26,0,0,0
0,0,0,2,0,0,0,0,0,39,39,39,39,39,39,39,39,39,0,0,0,0,0,2,0,0,0
0,0,0,36,41,0,0,0,0,39,0,0,0,0,0,0,0,39,0,0,0,0,40,2,0,0,0
0,0,0,2,0,0,0,0,0,39,0,0,0,0,0,0,0,39,0,0,0,0,0,2,0,0,0
0,0,0,26,0,0,0,0,0,39,0,0,0,0,0,0,0,39,0,0,0,0,0,26,0,0,0
0,0,0,2,0,0,0,0,0,2,2,0,0,0,0,0,2,2,0,0,0,0,0,2,0,0,0
0,0,0,2,0,0,0,0,0,2,2,0,0,0,0,0,2,2,0,0,0,0,0,2,0,0,0
0,0,0,2,0,0,0,0,0,39,0,0,0,0,0,0,0,39,0,0,0,0,0,2,0,0,0
0,0,0,26,0,0,0,0,0,39,0,0,0,0,0,0,0,39,0,0,0,0,0,26,0,0,0
0,0,0,2,0,0,0,0,0,39,0,0,0,0,0,0,0,39,0,0,0,0,0,2,0,0,0
0,2,2,2,0,2,0,0,0,2,2,36,26,36,26,36,2,2,0,0,0,2,0,2,2,2,0
0,2,0,0,0,0,0,0,0,26,0,0,0,0,0,0,0,26,0,0,0,0,0,0,0,2,0
0,28,0,0,9,2,2,26,2,2,2,26,2,2,2,26,2,2,2,26,2,2,9,0,0,29,0
0,2,0,7,10,2,0,0,0,0,0,0,0,0,0,0,0,0,0,0,0,2,10,7,0,2,0
0,2,2,30,2,2,0,0,0,0,0,0,0,0,0,0,0,0,0,0,0,2,2,30,2,2,0
0,0,0,0,0,0,0,0,0,0,0,0,0,0,0,0,0,0,0,0,0,0,0,0,0,0,0
:endlayer
layer: 7
0,0,0,0,0,0,0,0,0,0,0,0,0,0,0,0,0,0,0,0,0,0,0,0,0,0,0
0,2,2,2,2,2,0,0,0,0,0,0,0,0,0,0,0,0,0,0,0,2,2,2,2,2,0
0,2,10,9,0,2,0,0,0,0,0,0,0,0,0,0,0,0,0,0,0,2,0,9,10,2,0
0,2,7,0,0,2,2,27,2,2,2,27,2,2,2,27,2,2,2,27,2,2,0,0,7,2,0
0,2,0,24,0,0,0,0,0,23,23,0,0,0,0,0,23,23,0,0,0,0,0,24,0,2,0
0,2,2,2,0,2,22,0,0,0,0,0,0,0,0,0,0,0,0,0,21,2,0,2,2,2,0
0,0,0,2,0,23,0,0,0,0,0,0,0,0,0,0,0,0,0,0,0,23,0,2,0,0,0
0,0,0,27,0,0,0,0,0,0,0,33,32,0,35,34,0,0,0,0,0,0,0,27,0,0,0
0,0,0,2,0,0,0,0,0,24,24,33,32,0,35,34,24,24,0,0,0,0,0,2,0,0,0
0,0,0,2,22,0,0,0,21,2,2,22,0,0,0,21,2,2,22,0,0,0,21,2,0,0,0
0,0,0,2,22,0,0,0,21,2,2,22,0,0,0,21,2,2,22,0,0,0,21,2,0,0,0
0,0,0,27,0,0,0,0,0,23,23,0,0,0,0,0,23,23,0,0,0,0,0,27,0,0,0
0,0,0,2,0,0,0,0,0,0,0,0,0,0,0,0,0,0,0,0,0,0,0,2,0,0,0
0,0,0,2,0,0,0,0,0,0,0,0,0,0,0,0,0,0,0,0,0,0,0,2,0,0,0
0,0,0,2,0,0,0,0,0,0,0,0,0,0,0,0,0,0,0,0,0,0,0,2,0,0,0
0,0,0,27,0,0,0,0,0,24,24,0,0,0,0,0,24,24,0,0,0,0,0,27,0,0,0
0,0,0,2,22,0,0,0,21,2,2,22,0,0,0,21,2,2,22,0,0,0,21,2,0,0,0
0,0,0,2,22,0,0,0,21,2,2,22,0,0,0,21,2,2,22,0,0,0,21,2,0,0,0
0,0,0,2,0,0,0,0,0,23,23,0,0,0,0,0,23,23,0,0,0,0,0,2,0,0,0
0,0,0,27,0,0,0,0,0,0,0,0,0,0,0,0,0,0,0,0,0,0,0,27,0,0,0
0,0,0,2,0,24,0,0,0,24,24,0,0,0,0,0,24,24,0,0,0,0,0,2,0,0,0
0,2,2,2,0,2,22,0,21,2,2,36,0,36,0,36,2,2,22,0,0,2,0,2,2,2,0
0,2,0,23,0,0,0,0,0,0,0,0,0,0,0,0,0,0,0,0,0,0,0,23,0,2,0
0,2,7,0,0,2,2,27,2,2,2,27,2,2,2,27,2,2,2,27,2,2,0,0,7,2,0
0,2,10,9,0,2,0,0,0,0,0,0,0,0,0,0,0,0,0,0,0,2,0,9,10,2,0
0,2,2,2,2,2,0,0,0,0,0,0,0,0,0,0,0,0,0,0,0,2,2,2,2,2,0
0,0,0,0,0,0,0,0,0,0,0,0,0,0,0,0,0,0,0,0,0,0,0,0,0,0,0
:endlayer
layer: 8
0,0,0,0,0,0,0,0,0,0,0,0,0,0,0,0,0,0,0,0,0,0,0,0,0,0,0
0,2,2,2,2,2,0,0,0,0,0,0,0,0,0,0,0,0,0,0,0,2,2,2,2,2,0
0,2,0,0,0,2,30,0,30,0,30,0,30,0,30,0,30,0,30,0,30,2,0,0,0,2,0
0,2,9,0,0,2,4,4,4,4,4,4,4,4,4,4,4,4,4,4,4,2,0,0,9,2,0
0,2,10,7,0,2,0,0,0,31,31,0,0,0,0,0,31,31,0,0,0,2,0,7,10,2,0
0,2,2,2,2,2,28,27,27,27,27,27,27,27,27,27,27,27,27,27,29,2,2,2,2,2,0
0,0,29,4,0,31,0,0,0,0,0,0,10,10,10,0,0,0,0,0,0,31,0,4,28,0,0
0,0,0,4,0,27,0,0,0,0,0,0,9,9,9,0,0,0,0,0,0,27,0,4,0,0,0
0,0,29,4,0,27,0,0,0,0,0,0,9,9,9,0,0,0,0,0,0,27,0,4,28,0,0
0,0,0,4,28,27,0,0,29,2,2,28,0,0,0,29,2,2,28,0,0,27,29,4,0,0,0
0,0,29,4,28,27,0,0,29,2,2,28,0,0,0,29,2,2,28,0,0,27,29,4,28,0,0
0,0,0,4,0,27,0,0,0,31,31,0,0,0,0,0,31,31,0,0,0,27,0,4,0,0,0
0,0,29,4,0,27,0,0,0,0,0,0,0,0,0,0,0,0,0,0,0,27,0,4,28,0,0
0,0,0,4,0,27,0,0,0,0,0,0,0,0,0,0,0,0,0,0,0,27,0,4,0,0,0
0,0,29,4,0,27,0,0,0,0,0,0,0,0,0,0,0,0,0,0,0,27,0,4,28,0,0
0,0,0,4,0,27,0,0,0,30,30,0,0,0,0,0,30,30,0,0,0,27,0,4,0,0,0
0,0,29,4,28,27,0,0,29,2,2,28,0,0,0,29,2,2,28,0,0,27,29,4,28,0,0
0,0,0,4,28,27,0,0,29,2,2,28,0,0,0,29,2,2,28,0,0,27,29,4,0,0,0
0,0,29,4,0,27,0,0,0,31,31,0,0,0,0,0,31,31,0,0,0,27,0,4,28,0,0
0,0,0,4,0,27,0,0,0,0,0,0,0,0,0,0,0,0,0,0,0,27,0,4,0,0,0
0,0,29,4,0,30,0,0,0,30,30,0,0,0,0,0,30,30,0,0,0,30,0,4,28,0,0
0,2,2,2,2,2,28,27,29,2,2,2,2,2,2,2,2,2,28,27,29,2,2,2,2,2,0
0,2,10,7,0,2,0,0,0,27,0,0,0,0,0,0,0,27,0,0,0,2,0,7,10,2,0
0,2,9,0,0,2,4,4,4,4,4,4,4,4,4,4,4,4,4,4,4,2,0,0,9,2,0
0,2,0,0,0,2,31,0,31,0,31,0,31,0,31,0,31,0,31,0,31,2,0,0,0,2,0
0,2,2,2,2,2,0,0,0,0,0,0,0,0,0,0,0,0,0,0,0,2,2,2,2,2,0
0,0,0,0,0,0,0,0,0,0,0,0,0,0,0,0,0,0,0,0,0,0,0,0,0,0,0
:endlayer
layer: 9
0,0,0,0,0,0,0,0,0,0,0,0,0,0,0,0,0,0,0,0,0,0,0,0,0,0,0
0,2,2,2,2,2,0,0,0,0,0,0,0,0,0,0,0,0,0,0,0,2,2,2,2,2,0
0,2,0,0,0,2,2,2,2,2,2,2,2,2,2,2,2,2,2,2,2,2,0,0,0,2,0
0,2,0,0,7,2,4,4,4,2,4,4,4,4,4,4,4,2,4,4,4,2,7,0,0,2,0
0,2,0,9,10,2,4,4,4,2,2,2,2,2,2,2,2,2,4,4,4,2,10,9,0,2,0
0,2,2,2,2,2,4,4,4,2,2,2,9,9,9,2,2,2,4,4,4,2,2,2,2,2,0
0,0,2,4,4,4,42,42,4,2,31,2,0,0,0,2,31,2,4,42,42,4,4,4,2,0,0
0,0,2,4,4,4,42,42,4,28,0,0,0,0,0,0,0,29,4,42,42,4,4,4,2,0,0
0,0,2,4,4,4,42,42,4,28,0,0,0,0,0,0,0,29,4,42,42,4,4,4,2,0,0
0,0,2,2,2,2,2,2,2,2,2,2,2,2,2,2,2,2,2,2,2,2,2,2,2,0,0
0,0,2,2,2,2,2,2,2,2,2,2,2,2,2,2,2,2,2,2,2,2,2,2,2,0,0
0,0,2,4,4,4,42,42,42,2,2,0,0,0,0,0,2,2,42,42,42,4,4,4,2,0,0
0,0,2,4,4,4,42,42,42,2,2,0,0,0,0,0,2,2,42,42,42,4,4,4,2,0,0
0,0,2,4,4,4,42,42,42,2,2,0,0,0,0,0,2,2,42,42,42,4,4,4,2,0,0
0,0,2,4,4,4,42,42,42,2,2,0,0,0,0,0,2,2,42,42,42,4,4,4,2,0,0
0,0,2,4,4,4,42,42,42,2,2,0,0,0,0,0,2,2,42,42,42,4,4,4,2,0,0
0,0,2,2,2,2,2,2,2,2,2,2,2,2,2,2,2,2,2,2,2,2,2,2,2,0,0
0,0,2,2,2,2,2,2,2,2,2,2,2,2,2,2,2,2,2,2,2,2,2,2,2,0,0
0,0,2,4,4,4,42,42,42,2,2,42,42,42,42,42,2,2,42,42,42,4,4,4,2,0,0
0,0,2,4,4,4,42,42,42,2,2,42,42,42,42,42,2,2,42,42,42,4,4,4,2,0,0
0,0,2,4,4,4,42,42,42,2,2,42,42,42,42,42,2,2,42,42,42,4,4,4,2,0,0
0,2,2,2,2,4,4,4,4,2,2,4,4,4,4,4,2,2,4,4,4,4,2,2,2,2,0
0,2,0,9,10,2,4,4,4,2,2,4,4,4,4,4,2,2,4,4,4,2,10,9,0,2,0
0,2,0,0,7,2,4,4,4,2,2,4,4,4,4,4,2,2,4,4,4,2,7,0,0,2,0
0,2,0,0,0,2,2,2,2,2,2,2,2,2,2,2,2,2,2,2,2,2,0,0,0,2,0
0,2,2,2,2,2,0,0,0,0,0,0,0,0,0,0,0,0,0,0,0,2,2,2,2,2,0
0,0,0,0,0,0,0,0,0,0,0,0,0,0,0,0,0,0,0,0,0,0,0,0,0,0,0
:endlayer
layer: 10
0,0,0,0,0,0,0,0,0,0,0,0,0,0,0,0,0,0,0,0,0,0,0,0,0,0,0
0,2,2,2,2,2,0,0,0,0,0,0,0,0,0,0,0,0,0,0,0,2,2,2,2,2,0
0,2,0,7,10,2,2,2,2,2,2,2,2,2,2,2,2,2,2,2,2,2,10,7,0,2,0
0,2,0,0,9,2,2,2,2,2,2,2,2,2,2,2,2,2,2,2,2,2,9,0,0,2,0
0,2,0,0,0,0,0,26,26,26,26,26,0,0,0,26,26,26,26,26,0,0,0,0,0,2,0
0,2,2,2,0,2,0,0,0,0,0,0,0,0,0,0,0,0,0,0,0,2,0,2,2,2,0
0,0,2,2,0,0,0,0,0,0,0,0,0,0,0,0,0,0,0,0,0,0,0,2,2,0,0
0,0,2,2,26,0,0,0,0,0,0,0,0,0,0,0,0,0,0,0,0,0,26,2,2,0,0
0,0,2,2,26,0,0,0,0,0,0,0,0,0,0,0,0,0,0,0,0,0,26,2,2,0,0
0,0,2,2,26,0,0,0,0,26,26,26,26,26,26,26,26,26,0,0,0,0,26,2,2,0,0
0,0,2,2,26,0,0,0,0,26,2,2,2,2,2,2,2,26,0,0,0,0,26,2,2,0,0
0,0,2,2,26,0,0,0,0,26,2,0,0,0,0,0,2,26,0,0,0,0,26,2,2,0,0
0,0,2,2,26,0,0,0,0,26,2,0,0,0,0,0,2,26,0,0,0,0,26,2,2,0,0
0,0,2,2,26,0,0,0,0,26,2,0,0,0,0,0,2,26,0,0,0,0,26,2,2,0,0
0,0,2,2,26,0,0,0,0,26,2,0,0,0,0,0,2,26,0,0,0,0,26,2,2,0,0
0,0,2,2,26,0,0,0,0,26,2,0,0,0,0,0,2,26,0,0,0,0,26,2,2,0,0
0,0,2,2,26,0,0,0,0,26,2,2,2,2,2,2,2,26,0,0,0,0,26,2,2,0,0
0,0,36,2,26,0,0,0,0,26,26,26,26,26,26,26,26,26,0,0,0,0,26,2,2,0,0
0,0,2,2,26,0,0,0,0,0,0,0,0,0,0,0,0,0,0,0,0,0,26,2,2,0,0
0,0,2,2,26,0,0,0,0,0,0,0,0,0,0,0,0,0,0,0,0,0,26,2,2,0,0
0,0,2,2,0,0,0,0,0,0,0,0,0,0,0,0,0,0,0,0,0,0,0,2,2,0,0
0,2,2,2,0,2,0,0,0,0,0,0,0,0,0,0,0,0,0,0,0,2,0,2,2,2,0
0,2,0,0,0,0,0,26,26,26,26,26,26,26,26,26,26,26,26,26,0,0,0,0,0,2,0
0,2,0,0,9,2,2,2,2,2,2,2,2,2,2,2,2,2,2,2,2,2,9,0,0,2,0
0,2,0,7,10,2,2,2,2,2,2,2,2,2,2,2,2,2,2,2,2,2,10,7,0,2,0
0,2,2,2,2,2,0,0,0,0,0,0,0,0,0,0,0,0,0,0,0,2,2,2,2,2,0
0,0,0,0,0,0,0,0,0,0,0,0,0,0,0,0,0,0,0,0,0,0,0,0,0,0,0
:endlayer
layer: 11
0,0,0,0,0,0,0,0,0,0,0,0,0,0,0,0,0,0,0,0,0,0,0,0,0,0,0
0,2,2,2,2,2,0,0,0,0,0,0,0,0,0,0,0,0,0,0,0,2,2,2,2,2,0
0,2,10,9,0,2,36,26,36,26,2,26,36,26,36,26,2,26,36,26,36,2,0,9,10,2,0
0,2,7,0,0,2,0,0,23,0,0,0,23,0,23,0,0,0,23,0,0,2,0,0,7,2,0
0,2,0,24,0,0,0,0,0,0,0,0,0,0,0,0,0,0,0,0,0,0,0,24,0,2,0
0,2,2,2,0,2,22,0,0,0,0,0,0,0,0,0,0,0,0,0,21,2,0,2,2,2,0
0,0,36,0,0,23,0,0,0,0,0,0,0,0,0,0,0,0,0,0,0,23,0,0,2,0,0
0,0,26,0,0,0,0,0,0,0,0,0,0,0,0,0,0,0,0,0,0,0,0,0,26,0,0
0,0,36,22,0,0,0,0,0,0,0,0,0,0,0,0,0,0,0,0,0,0,0,21,2,0,0
0,0,26,0,0,0,0,0,0,0,24,0,0,0,0,0,24,0,0,0,0,0,0,0,26,0,0
0,0,2,0,0,0,0,0,0,21,2,2,2,2,2,2,2,22,0,0,0,0,0,0,2,0,0
0,0,26,0,0,0,0,0,0,0,2,0,0,0,0,0,2,0,0,0,0,0,0,0,26,0,0
0,0,36,22,0,0,0,0,0,0,2,0,0,0,0,0,2,0,0,0,0,0,0,21,36,0,0
0,0,26,0,0,0,0,0,0,0,2,0,0,0,0,0,2,0,0,0,0,0,0,0,26,0,0
0,0,36,22,0,0,0,0,0,0,2,0,0,0,0,0,2,0,0,0,0,0,0,21,36,0,0
0,0,26,0,0,0,0,0,0,0,2,0,0,0,0,0,2,0,0,0,0,0,0,0,26,0,0
0,0,2,0,0,0,0,0,0,21,2,2,2,2,2,2,2,22,0,0,0,0,0,0,2,0,0
0,0,26,0,0,0,0,0,0,0,23,0,0,0,0,0,23,0,0,0,0,0,0,0,26,0,0
0,0,36,22,0,0,0,0,0,0,0,0,0,0,0,0,0,0,0,0,0,0,0,21,36,0,0
0,0,26,0,0,0,0,0,0,0,0,0,0,0,0,0,0,0,0,0,0,0,0,0,26,0,0
0,0,36,0,0,24,0,0,0,0,0,0,0,0,0,0,0,0,0,0,0,24,0,0,36,0,0
0,2,2,2,0,2,22,0,0,0,0,0,0,0,0,0,0,0,0,0,21,2,0,2,2,2,0
0,2,0,23,0,0,0,0,0,0,0,0,0,0,0,0,0,0,0,0,0,0,0,23,0,2,0
0,2,7,0,0,2,0,0,24,0,0,0,24,0,24,0,0,0,24,0,0,2,0,0,7,2,0
0,2,10,9,0,2,36,26,36,26,2,26,36,26,36,26,2,26,36,26,36,2,0,9,10,2,0
0,2,2,2,2,2,0,0,0,0,0,0,0,0,0,0,0,0,0,0,0,2,2,2,2,2,0
0,0,0,0,0,0,0,0,0,0,0,0,0,0,0,0,0,0,0,0,0,0,0,0,0,0,0
:endlayer
layer: 12
0,30,27,30,27,30,0,0,0,0,0,0,0,0,0,0,0,0,0,0,0,30,27,30,27,30,0
29,4,4,4,4,4,28,0,0,0,0,0,0,0,0,0,0,0,0,0,29,4,4,4,4,4,28
27,4,0,0,0,4,27,0,0,0,0,0,0,0,0,0,0,0,0,0,27,4,0,0,0,4,27
29,4,9,0,0,4,28,0,0,0,0,0,0,0,0,0,0,0,0,0,29,4,0,0,9,4,28
27,4,10,7,0,4,27,0,0,0,0,0,0,0,0,0,0,0,0,0,27,4,0,7,10,4,27
29,4,4,4,4,4,28,0,0,0,0,0,0,0,0,0,0,0,0,0,29,4,4,4,4,4,28
0,31,27,31,27,31,0,0,0,0,0,0,0,0,0,0,0,0,0,0,0,31,27,31,27,31,0
0,0,0,0,0,0,0,0,0,0,0,0,0,0,0,0,0,0,0,0,0,0,0,0,0,0,0
0,0,0,0,0,0,0,0,0,0,0,0,0,0,0,0,0,0,0,0,0,0,0,0,0,0,0
0,0,0,0,0,0,0,0,0,0,0,0,0,0,0,0,0,0,0,0,0,0,0,0,0,0,0
0,0,0,0,0,0,0,0,0,0,0,0,0,0,0,0,0,0,0,0,0,0,0,0,0,0,0
0,0,0,0,0,0,0,0,0,0,0,0,0,0,0,0,0,0,0,0,0,0,0,0,0,0,0
0,0,0,0,0,0,0,0,0,0,0,0,0,0,0,0,0,0,0,0,0,0,0,0,0,0,0
0,0,0,0,0,0,0,0,0,0,0,0,0,0,0,0,0,0,0,0,0,0,0,0,0,0,0
0,0,0,0,0,0,0,0,0,0,0,0,0,0,0,0,0,0,0,0,0,0,0,0,0,0,0
0,0,0,0,0,0,0,0,0,0,0,0,0,0,0,0,0,0,0,0,0,0,0,0,0,0,0
0,0,0,0,0,0,0,0,0,0,0,0,0,0,0,0,0,0,0,0,0,0,0,0,0,0,0
0,0,0,0,0,0,0,0,0,0,0,0,0,0,0,0,0,0,0,0,0,0,0,0,0,0,0
0,0,0,0,0,0,0,0,0,0,0,0,0,0,0,0,0,0,0,0,0,0,0,0,0,0,0
0,0,0,0,0,0,0,0,0,0,0,0,0,0,0,0,0,0,0,0,0,0,0,0,0,0,0
0,30,27,30,27,30,0,0,0,0,0,0,0,0,0,0,0,0,0,0,0,30,27,30,27,30,0
29,4,4,4,4,4,28,0,0,0,0,0,0,0,0,0,0,0,0,0,29,4,4,4,4,4,28
27,4,10,7,0,4,27,0,0,0,0,0,0,0,0,0,0,0,0,0,27,4,0,7,10,4,27
29,4,9,0,0,4,28,0,0,0,0,0,0,0,0,0,0,0,0,0,29,4,0,0,9,4,28
27,4,0,0,0,4,27,0,0,0,0,0,0,0,0,0,0,0,0,0,27,4,0,0,0,4,27
29,4,4,4,4,4,28,0,0,0,0,0,0,0,0,0,0,0,0,0,29,4,4,4,4,4,28
0,31,27,31,27,31,0,0,0,0,0,0,0,0,0,0,0,0,0,0,0,31,27,31,27,31,0
:endlayer
layer: 13
2,2,2,2,2,2,2,0,0,0,0,0,0,0,0,0,0,0,0,0,2,2,2,2,2,2,2
2,2,2,2,2,2,2,0,0,0,0,0,0,0,0,0,0,0,0,0,2,2,2,2,2,2,2
2,2,0,0,7,2,2,0,0,0,0,0,0,0,0,0,0,0,0,0,2,2,7,0,0,2,2
2,2,0,7,7,2,2,0,0,0,0,0,0,0,0,0,0,0,0,0,2,2,7,7,0,2,2
2,2,0,9,10,2,2,0,0,0,0,0,0,0,0,0,0,0,0,0,2,2,10,9,0,2,2
2,2,2,2,2,2,2,0,0,0,0,0,0,0,0,0,0,0,0,0,2,2,2,2,2,2,2
2,2,2,2,2,2,2,0,0,0,0,0,0,0,0,0,0,0,0,0,2,2,2,2,2,2,2
0,0,0,0,0,0,0,0,0,0,0,0,0,0,0,0,0,0,0,0,0,0,0,0,0,0,0
0,0,0,0,0,0,0,0,0,0,0,0,0,0,0,0,0,0,0,0,0,0,0,0,0,0,0
0,0,0,0,0,0,0,0,0,0,0,0,0,0,0,0,0,0,0,0,0,0,0,0,0,0,0
0,0,0,0,0,0,0,0,0,0,0,0,0,0,0,0,0,0,0,0,0,0,0,0,0,0,0
0,0,0,0,0,0,0,0,0,0,0,0,0,0,0,0,0,0,0,0,0,0,0,0,0,0,0
0,0,0,0,0,0,0,0,0,0,0,0,0,0,0,0,0,0,0,0,0,0,0,0,0,0,0
0,0,0,0,0,0,0,0,0,0,0,0,0,0,0,0,0,0,0,0,0,0,0,0,0,0,0
0,0,0,0,0,0,0,0,0,0,0,0,0,0,0,0,0,0,0,0,0,0,0,0,0,0,0
0,0,0,0,0,0,0,0,0,0,0,0,0,0,0,0,0,0,0,0,0,0,0,0,0,0,0
0,0,0,0,0,0,0,0,0,0,0,0,0,0,0,0,0,0,0,0,0,0,0,0,0,0,0
0,0,0,0,0,0,0,0,0,0,0,0,0,0,0,0,0,0,0,0,0,0,0,0,0,0,0
0,0,0,0,0,0,0,0,0,0,0,0,0,0,0,0,0,0,0,0,0,0,0,0,0,0,0
0,0,0,0,0,0,0,0,0,0,0,0,0,0,0,0,0,0,0,0,0,0,0,0,0,0,0
2,2,2,2,2,2,2,0,0,0,0,0,0,0,0,0,0,0,0,0,2,2,2,2,2,2,2
2,2,2,2,2,2,2,0,0,0,0,0,0,0,0,0,0,0,0,0,2,2,2,2,2,2,2
2,2,0,9,10,2,2,0,0,0,0,0,0,0,0,0,0,0,0,0,2,2,10,9,0,2,2
2,2,0,7,7,2,2,0,0,0,0,0,0,0,0,0,0,0,0,0,2,2,7,7,0,2,2
2,2,0,0,7,2,2,0,0,0,0,0,0,0,0,0,0,0,0,0,2,2,7,0,0,2,2
2,2,2,2,2,2,2,0,0,0,0,0,0,0,0,0,0,0,0,0,2,2,2,2,2,2,2
2,2,2,2,2,2,2,0,0,0,0,0,0,0,0,0,0,0,0,0,2,2,2,2,2,2,2
:endlayer
layer: 14
2,2,2,2,2,2,2,0,0,0,0,0,0,0,0,0,0,0,0,0,2,2,2,2,2,2,2
2,0,0,0,0,0,2,0,0,0,0,0,0,0,0,0,0,0,0,0,2,0,0,0,0,0,2
2,0,0,0,0,0,2,0,0,0,0,0,0,0,0,0,0,0,0,0,2,0,0,0,0,0,2
2,0,0,43,0,0,2,0,0,0,0,0,0,0,0,0,0,0,0,0,2,0,0,43,0,0,2
2,0,0,0,0,0,2,0,0,0,0,0,0,0,0,0,0,0,0,0,2,0,0,0,0,0,2
2,0,0,0,0,0,2,0,0,0,0,0,0,0,0,0,0,0,0,0,2,0,0,0,0,0,2
2,2,2,2,2,2,2,0,0,0,0,0,0,0,0,0,0,0,0,0,2,2,2,2,2,2,2
0,0,0,0,0,0,0,0,0,0,0,0,0,0,0,0,0,0,0,0,0,0,0,0,0,0,0
0,0,0,0,0,0,0,0,0,0,0,0,0,0,0,0,0,0,0,0,0,0,0,0,0,0,0
0,0,0,0,0,0,0,0,0,0,0,0,0,0,0,0,0,0,0,0,0,0,0,0,0,0,0
0,0,0,0,0,0,0,0,0,0,0,0,0,0,0,0,0,0,0,0,0,0,0,0,0,0,0
0,0,0,0,0,0,0,0,0,0,0,0,0,0,0,0,0,0,0,0,0,0,0,0,0,0,0
0,0,0,0,0,0,0,0,0,0,0,0,0,0,0,0,0,0,0,0,0,0,0,0,0,0,0
0,0,0,0,0,0,0,0,0,0,0,0,0,0,0,0,0,0,0,0,0,0,0,0,0,0,0
0,0,0,0,0,0,0,0,0,0,0,0,0,0,0,0,0,0,0,0,0,0,0,0,0,0,0
0,0,0,0,0,0,0,0,0,0,0,0,0,0,0,0,0,0,0,0,0,0,0,0,0,0,0
0,0,0,0,0,0,0,0,0,0,0,0,0,0,0,0,0,0,0,0,0,0,0,0,0,0,0
0,0,0,0,0,0,0,0,0,0,0,0,0,0,0,0,0,0,0,0,0,0,0,0,0,0,0
0,0,0,0,0,0,0,0,0,0,0,0,0,0,0,0,0,0,0,0,0,0,0,0,0,0,0
0,0,0,0,0,0,0,0,0,0,0,0,0,0,0,0,0,0,0,0,0,0,0,0,0,0,0
2,2,2,2,2,2,2,0,0,0,0,0,0,0,0,0,0,0,0,0,2,2,2,2,2,2,2
2,0,0,0,0,0,2,0,0,0,0,0,0,0,0,0,0,0,0,0,2,0,0,0,0,0,2
2,0,0,0,0,0,2,0,0,0,0,0,0,0,0,0,0,0,0,0,2,0,0,0,0,0,2
2,0,0,43,0,0,2,0,0,0,0,0,0,0,0,0,0,0,0,0,2,0,0,43,0,0,2
2,0,0,0,0,0,2,0,0,0,0,0,0,0,0,0,0,0,0,0,2,0,0,0,0,0,2
2,0,0,0,0,0,2,0,0,0,0,0,0,0,0,0,0,0,0,0,2,0,0,0,0,0,2
2,2,2,2,2,2,2,0,0,0,0,0,0,0,0,0,0,0,0,0,2,2,2,2,2,2,2
:endlayer
layer: 15
2,26,2,26,2,26,2,0,0,0,0,0,0,0,0,0,0,0,0,0,2,26,2,26,2,26,2
26,0,0,0,0,0,26,0,0,0,0,0,0,0,0,0,0,0,0,0,26,0,0,0,0,0,26
2,0,0,0,0,0,2,0,0,0,0,0,0,0,0,0,0,0,0,0,2,0,0,0,0,0,2
26,0,0,0,0,0,26,0,0,0,0,0,0,0,0,0,0,0,0,0,26,0,0,0,0,0,26
2,0,0,0,0,0,2,0,0,0,0,0,0,0,0,0,0,0,0,0,2,0,0,0,0,0,2
26,0,0,0,0,0,26,0,0,0,0,0,0,0,0,0,0,0,0,0,26,0,0,0,0,0,26
2,26,2,26,2,26,2,0,0,0,0,0,0,0,0,0,0,0,0,0,2,26,2,26,2,26,2
0,0,0,0,0,0,0,0,0,0,0,0,0,0,0,0,0,0,0,0,0,0,0,0,0,0,0
0,0,0,0,0,0,0,0,0,0,0,0,0,0,0,0,0,0,0,0,0,0,0,0,0,0,0
0,0,0,0,0,0,0,0,0,0,0,0,0,0,0,0,0,0,0,0,0,0,0,0,0,0,0
0,0,0,0,0,0,0,0,0,0,0,0,0,0,0,0,0,0,0,0,0,0,0,0,0,0,0
0,0,0,0,0,0,0,0,0,0,0,0,0,0,0,0,0,0,0,0,0,0,0,0,0,0,0
0,0,0,0,0,0,0,0,0,0,0,0,0,0,0,0,0,0,0,0,0,0,0,0,0,0,0
0,0,0,0,0,0,0,0,0,0,0,0,0,0,0,0,0,0,0,0,0,0,0,0,0,0,0
0,0,0,0,0,0,0,0,0,0,0,0,0,0,0,0,0,0,0,0,0,0,0,0,0,0,0
0,0,0,0,0,0,0,0,0,0,0,0,0,0,0,0,0,0,0,0,0,0,0,0,0,0,0
0,0,0,0,0,0,0,0,0,0,0,0,0,0,0,0,0,0,0,0,0,0,0,0,0,0,0
0,0,0,0,0,0,0,0,0,0,0,0,0,0,0,0,0,0,0,0,0,0,0,0,0,0,0
0,0,0,0,0,0,0,0,0,0,0,0,0,0,0,0,0,0,0,0,0,0,0,0,0,0,0
0,0,0,0,0,0,0,0,0,0,0,0,0,0,0,0,0,0,0,0,0,0,0,0,0,0,0
2,26,2,26,2,26,2,0,0,0,0,0,0,0,0,0,0,0,0,0,2,26,2,26,2,26,2
26,0,0,0,0,0,26,0,0,0,0,0,0,0,0,0,0,0,0,0,26,0,0,0,0,0,26
2,0,0,0,0,0,2,0,0,0,0,0,0,0,0,0,0,0,0,0,2,0,0,0,0,0,2
26,0,0,0,0,0,26,0,0,0,0,0,0,0,0,0,0,0,0,0,26,0,0,0,0,0,26
2,0,0,0,0,0,2,0,0,0,0,0,0,0,0,0,0,0,0,0,2,0,0,0,0,0,2
26,0,0,0,0,0,26,0,0,0,0,0,0,0,0,0,0,0,0,0,26,0,0,0,0,0,26
2,26,2,26,2,26,2,0,0,0,0,0,0,0,0,0,0,0,0,0,2,26,2,26,2,26,2
:endlayer

#### RULES ####
rule:
plugin=vanillaBlocks
number=1
data:
JSON:{buildPass:0,blockName:"minecraft:grass",meta:0}
:enddata
:endrule

rule:
plugin=vanillaBlocks
number=2
data:
JSON:{buildPass:0,blockName:"minecraft:stonebrick",meta:0}
:enddata
:endrule

rule:
plugin=vanillaBlocks
number=3
data:
JSON:{buildPass:0,blockName:"minecraft:stone",meta:0}
:enddata
:endrule

rule:
plugin=vanillaBlocks
number=4
data:
JSON:{buildPass:0,blockName:"minecraft:double_stone_slab",meta:0}
:enddata
:endrule

rule:
plugin=vanillaBlocks
number=5
data:
JSON:{buildPass:2,blockName:"minecraft:tallgrass",meta:1}
:enddata
:endrule

rule:
plugin=vanillaBlocks
number=6
data:
JSON:{buildPass:2,blockName:"minecraft:yellow_flower",meta:0}
:enddata
:endrule

rule:
plugin=vanillaBlocks
number=7
data:
JSON:{buildPass:0,blockName:"minecraft:wooden_slab",meta:8}
:enddata
:endrule

rule:
plugin=vanillaBlocks
number=8
data:
JSON:{buildPass:2,blockName:"minecraft:stone_button",meta:2}
:enddata
:endrule

rule:
plugin=vanillaBlocks
number=9
data:
JSON:{buildPass:0,blockName:"minecraft:wooden_slab",meta:0}
:enddata
:endrule

rule:
plugin=vanillaBlocks
number=10
data:
JSON:{buildPass:0,blockName:"minecraft:double_wooden_slab",meta:0}
:enddata
:endrule

rule:
plugin=vanillaBlocks
number=11
data:
JSON:{buildPass:2,blockName:"minecraft:lever",meta:2}
:enddata
:endrule

rule:
plugin=vanillaBlocks
number=12
data:
JSON:{buildPass:0,blockName:"minecraft:oak_stairs",meta:3}
:enddata
:endrule

rule:
plugin=vanillaBlocks
number=13
data:
JSON:{buildPass:0,blockName:"minecraft:oak_stairs",meta:6}
:enddata
:endrule

rule:
plugin=vanillaDoors
number=14
data:
JSON:{buildPass:2,blockName:"minecraft:iron_door",meta:1,sideFlag:0b}
:enddata
:endrule

rule:
plugin=vanillaBlocks
number=15
data:
JSON:{buildPass:0,blockName:"minecraft:stone_brick_stairs",meta:2}
:enddata
:endrule

rule:
plugin=vanillaBlocks
number=16
data:
JSON:{buildPass:0,blockName:"minecraft:stone_brick_stairs",meta:0}
:enddata
:endrule

rule:
plugin=vanillaBlocks
number=17
data:
JSON:{buildPass:0,blockName:"minecraft:stone_brick_stairs",meta:1}
:enddata
:endrule

rule:
plugin=vanillaBlocks
number=18
data:
JSON:{buildPass:2,blockName:"minecraft:stone_button",meta:3}
:enddata
:endrule

rule:
plugin=vanillaDoors
number=19
data:
JSON:{buildPass:2,blockName:"minecraft:iron_door",meta:8,sideFlag:0b}
:enddata
:endrule

rule:
plugin=vanillaBlocks
number=20
data:
JSON:{buildPass:2,blockName:"minecraft:stone_button",meta:4}
:enddata
:endrule

rule:
plugin=vanillaBlocks
number=21
data:
JSON:{buildPass:2,blockName:"minecraft:torch",meta:2}
:enddata
:endrule

rule:
plugin=vanillaBlocks
number=22
data:
JSON:{buildPass:2,blockName:"minecraft:torch",meta:1}
:enddata
:endrule

rule:
plugin=vanillaBlocks
number=23
data:
JSON:{buildPass:2,blockName:"minecraft:torch",meta:3}
:enddata
:endrule

rule:
plugin=vanillaBlocks
number=24
data:
JSON:{buildPass:2,blockName:"minecraft:torch",meta:4}
:enddata
:endrule

rule:
plugin=vanillaBlocks
number=25
data:
JSON:{buildPass:0,blockName:"minecraft:oak_stairs",meta:7}
:enddata
:endrule

rule:
plugin=vanillaBlocks
number=26
data:
JSON:{buildPass:0,blockName:"minecraft:stone_slab",meta:5}
:enddata
:endrule

rule:
plugin=vanillaBlocks
number=27
data:
JSON:{buildPass:0,blockName:"minecraft:stone_slab",meta:13}
:enddata
:endrule

rule:
plugin=vanillaBlocks
number=28
data:
JSON:{buildPass:0,blockName:"minecraft:stone_brick_stairs",meta:5}
:enddata
:endrule

rule:
plugin=vanillaBlocks
number=29
data:
JSON:{buildPass:0,blockName:"minecraft:stone_brick_stairs",meta:4}
:enddata
:endrule

rule:
plugin=vanillaBlocks
number=30
data:
JSON:{buildPass:0,blockName:"minecraft:stone_brick_stairs",meta:6}
:enddata
:endrule

rule:
plugin=vanillaBlocks
number=31
data:
JSON:{buildPass:0,blockName:"minecraft:stone_brick_stairs",meta:7}
:enddata
:endrule

rule:
plugin=vanillaBlocks
number=32
data:
JSON:{buildPass:0,blockName:"minecraft:oak_stairs",meta:5}
:enddata
:endrule

rule:
plugin=vanillaBlocks
number=33
data:
JSON:{buildPass:0,blockName:"minecraft:oak_stairs",meta:0}
:enddata
:endrule

rule:
plugin=vanillaBlocks
number=34
data:
JSON:{buildPass:0,blockName:"minecraft:oak_stairs",meta:1}
:enddata
:endrule

rule:
plugin=vanillaBlocks
number=35
data:
JSON:{buildPass:0,blockName:"minecraft:oak_stairs",meta:4}
:enddata
:endrule

rule:
plugin=vanillaBlocks
number=36
data:
JSON:{buildPass:0,blockName:"minecraft:double_stone_slab",meta:5}
:enddata
:endrule

rule:
plugin=vanillaBlocks
number=37
data:
JSON:{buildPass:0,blockName:"minecraft:log",meta:8}
:enddata
:endrule

rule:
plugin=vanillaBlocks
number=38
data:
JSON:{buildPass:0,blockName:"minecraft:log",meta:4}
:enddata
:endrule

rule:
plugin=vanillaBlocks
number=39
data:
JSON:{buildPass:0,blockName:"minecraft:fence",meta:0}
:enddata
:endrule

rule:
plugin=vanillaInventory
number=40
data:
JSON:{buildPass:0,blockName:"minecraft:chest",meta:4,lootLevel:2,teData:{x:488,y:31,Items:[{Slot:0b,id:264s,Count:1b,Damage:0s}],z:-1275,id:"Chest"},inventoryData:{length:27,inventoryContents:[{id:"minecraft:diamond",Count:1b,slot:0,Damage:0s}]}}
:enddata
:endrule

rule:
plugin=vanillaInventory
number=41
data:
JSON:{buildPass:0,blockName:"minecraft:chest",meta:5,lootLevel:2,teData:{x:506,y:31,Items:[{Slot:0b,id:264s,Count:1b,Damage:0s}],z:-1275,id:"Chest"},inventoryData:{length:27,inventoryContents:[{id:"minecraft:diamond",Count:1b,slot:0,Damage:0s}]}}
:enddata
:endrule

rule:
plugin=vanillaBlocks
number=42
data:
JSON:{buildPass:0,blockName:"minecraft:stone_slab",meta:8}
:enddata
:endrule

rule:
plugin=vanillaBlocks
number=43
data:
JSON:{buildPass:2,blockName:"minecraft:torch",meta:5}
:enddata
:endrule

#### ENTITIES ####
entity:
plugin=AWNpc
number=0
data:
position=17,11,23
JSON:{xOffset:0.5f,equipmentData:{equipmentContents:[{id:"minecraft:bow",Count:1b,slot:0,Damage:0s}]},rotation:185.78548f,mobID:"ancientwarfarenpc:faction.archer",zOffset:0.5f,entityData:{Attributes:[{Base:20.0d,Name:"generic.maxHealth"},{Base:0.0d,Name:"generic.knockbackResistance"},{Base:0.325d,Name:"generic.movementSpeed"},{Base:60.0d,Name:"generic.followRange"},{Base:2.0d,Name:"generic.attackDamage"}],Invulnerable:0b,AbsorptionAmount:0.0f,PortalCooldown:0,FallDistance:0.0f,levelingStats:{level:0,xp:0,entryList:[]},DeathTime:0s,DropChances:[1.0f,1.0f,1.0f,1.0f,1.0f],PersistenceRequired:1b,HealF:20.0f,owner:"shadowmage4513",Motion:[0.0d,-0.0784000015258789d,0.0d],armorValueOverride:-1,Leashed:0b,Health:20s,OnGround:1b,Dimension:0,Air:300s,Rotation:[5.7854743f,0.0f],CustomName:"",Pos:[493.5d,36.0d,-1284.5d],Fire:-1s,attackDamageOverride:-1,customTex:"",CanPickUpLoot:0b,factionName:"pirate",HurtTime:0s,AttackTime:0s,CustomNameVisible:0b}}
:enddata
:endentity

entity:
plugin=AWNpc
number=1
data:
position=20,1,18
JSON:{xOffset:0.7777721f,equipmentData:{equipmentContents:[{id:"minecraft:bow",Count:1b,slot:0,Damage:0s}]},rotation:184.39438f,mobID:"ancientwarfarenpc:faction.archer",zOffset:0.8766365f,entityData:{Attributes:[{Base:20.0d,Name:"generic.maxHealth"},{Base:0.0d,Name:"generic.knockbackResistance"},{Base:0.325d,Name:"generic.movementSpeed"},{Base:60.0d,Name:"generic.followRange"},{Base:2.0d,Name:"generic.attackDamage"}],Invulnerable:0b,AbsorptionAmount:0.0f,PortalCooldown:0,FallDistance:0.0f,levelingStats:{level:0,xp:0,entryList:[]},DeathTime:0s,DropChances:[1.0f,1.0f,1.0f,1.0f,1.0f],PersistenceRequired:1b,HealF:20.0f,owner:"shadowmage4513",Motion:[0.0d,-0.0784000015258789d,0.0d],armorValueOverride:-1,Leashed:0b,Health:20s,OnGround:1b,Dimension:0,Air:300s,Rotation:[4.3943763f,0.0f],CustomName:"",Pos:[490.22222787410533d,26.0d,-1279.8766364831956d],Fire:-1s,attackDamageOverride:-1,customTex:"",CanPickUpLoot:0b,factionName:"pirate",HurtTime:0s,AttackTime:0s,CustomNameVisible:0b}}
:enddata
:endentity

entity:
plugin=AWNpc
number=2
data:
position=19,1,7
JSON:{xOffset:0.5f,equipmentData:{equipmentContents:[{id:"minecraft:bow",Count:1b,slot:0,Damage:0s}]},rotation:184.37422f,mobID:"ancientwarfarenpc:faction.archer",zOffset:0.5f,entityData:{Attributes:[{Base:20.0d,Name:"generic.maxHealth"},{Base:0.0d,Name:"generic.knockbackResistance"},{Base:0.325d,Name:"generic.movementSpeed"},{Base:60.0d,Name:"generic.followRange"},{Base:2.0d,Name:"generic.attackDamage"}],Invulnerable:0b,AbsorptionAmount:0.0f,PortalCooldown:0,FallDistance:0.0f,levelingStats:{level:0,xp:0,entryList:[]},DeathTime:0s,DropChances:[1.0f,1.0f,1.0f,1.0f,1.0f],PersistenceRequired:1b,HealF:20.0f,owner:"shadowmage4513",Motion:[0.0d,-0.0784000015258789d,0.0d],armorValueOverride:-1,Leashed:0b,Health:20s,OnGround:1b,Dimension:0,Air:300s,Rotation:[4.374221f,0.0f],CustomName:"",Pos:[491.5d,26.0d,-1268.5d],Fire:-1s,attackDamageOverride:-1,customTex:"",CanPickUpLoot:0b,factionName:"pirate",HurtTime:0s,AttackTime:0s,CustomNameVisible:0b}}
:enddata
:endentity

entity:
plugin=AWNpc
number=3
data:
position=20,6,7
JSON:{xOffset:0.5f,equipmentData:{equipmentContents:[{id:"minecraft:bow",Count:1b,slot:0,Damage:0s}]},rotation:185.00085f,mobID:"ancientwarfarenpc:faction.archer",zOffset:0.5f,entityData:{Attributes:[{Base:20.0d,Name:"generic.maxHealth"},{Base:0.0d,Name:"generic.knockbackResistance"},{Base:0.325d,Name:"generic.movementSpeed"},{Base:60.0d,Name:"generic.followRange"},{Base:2.0d,Name:"generic.attackDamage"}],Invulnerable:0b,AbsorptionAmount:0.0f,PortalCooldown:0,FallDistance:0.0f,levelingStats:{level:0,xp:0,entryList:[]},DeathTime:0s,DropChances:[1.0f,1.0f,1.0f,1.0f,1.0f],PersistenceRequired:1b,HealF:20.0f,owner:"shadowmage4513",Motion:[0.0d,-0.0784000015258789d,0.0d],armorValueOverride:-1,Leashed:0b,Health:20s,OnGround:1b,Dimension:0,Air:300s,Rotation:[5.0008535f,0.0f],CustomName:"",Pos:[490.5d,31.0d,-1268.5d],Fire:-1s,attackDamageOverride:-1,customTex:"",CanPickUpLoot:0b,factionName:"pirate",HurtTime:0s,AttackTime:0s,CustomNameVisible:0b}}
:enddata
:endentity

entity:
plugin=AWNpc
number=4
data:
position=20,6,18
JSON:{xOffset:0.50153995f,equipmentData:{equipmentContents:[{id:"minecraft:bow",Count:1b,slot:0,Damage:0s}]},rotation:182.91026f,mobID:"ancientwarfarenpc:faction.archer",zOffset:0.8233843f,entityData:{Attributes:[{Base:20.0d,Name:"generic.maxHealth"},{Base:0.0d,Name:"generic.knockbackResistance"},{Base:0.325d,Name:"generic.movementSpeed"},{Base:60.0d,Name:"generic.followRange"},{Base:2.0d,Name:"generic.attackDamage"}],Invulnerable:0b,AbsorptionAmount:0.0f,PortalCooldown:0,FallDistance:0.0f,levelingStats:{level:0,xp:0,entryList:[]},DeathTime:0s,DropChances:[1.0f,1.0f,1.0f,1.0f,1.0f],PersistenceRequired:1b,HealF:20.0f,owner:"shadowmage4513",Motion:[0.0d,-0.0784000015258789d,0.0d],armorValueOverride:-1,Leashed:0b,Health:20s,OnGround:1b,Dimension:0,Air:300s,Rotation:[2.910264f,0.0f],CustomName:"",Pos:[490.4984600555097d,31.0d,-1279.8233842836187d],Fire:-1s,attackDamageOverride:-1,customTex:"",CanPickUpLoot:0b,factionName:"pirate",HurtTime:0s,AttackTime:0s,CustomNameVisible:0b}}
:enddata
:endentity

entity:
plugin=AWNpc
number=5
data:
position=15,1,17
JSON:{xOffset:0.329584f,equipmentData:{equipmentContents:[{id:"minecraft:iron_sword",Count:1b,slot:0,Damage:0s}]},rotation:199.20416f,mobID:"ancientwarfarenpc:faction.soldier",zOffset:0.96805227f,entityData:{Attributes:[{Base:20.0d,Name:"generic.maxHealth"},{Base:0.0d,Name:"generic.knockbackResistance"},{Base:0.325d,Name:"generic.movementSpeed"},{Base:60.0d,Name:"generic.followRange"},{Base:2.0d,Name:"generic.attackDamage"}],Invulnerable:0b,AbsorptionAmount:0.0f,PortalCooldown:0,FallDistance:0.0f,levelingStats:{level:0,xp:0,entryList:[]},DeathTime:0s,DropChances:[1.0f,1.0f,1.0f,1.0f,1.0f],PersistenceRequired:1b,HealF:20.0f,owner:"shadowmage4513",Motion:[0.0d,-0.0784000015258789d,0.0d],armorValueOverride:-1,Leashed:0b,Health:20s,OnGround:1b,Dimension:0,Air:300s,Rotation:[739.20416f,0.0f],CustomName:"",Pos:[495.6704159964061d,26.0d,-1278.9680522846024d],Fire:-1s,attackDamageOverride:-1,customTex:"",CanPickUpLoot:0b,factionName:"pirate",HurtTime:0s,AttackTime:0s,CustomNameVisible:0b}}
:enddata
:endentity

entity:
plugin=AWNpc
number=6
data:
position=18,6,11
JSON:{xOffset:0.86097527f,equipmentData:{equipmentContents:[{id:"minecraft:iron_sword",Count:1b,slot:0,Damage:0s}]},rotation:-20.763992f,mobID:"ancientwarfarenpc:faction.soldier",zOffset:0.23125488f,entityData:{Attributes:[{Base:20.0d,Name:"generic.maxHealth"},{Base:0.0d,Name:"generic.knockbackResistance"},{Base:0.325d,Name:"generic.movementSpeed"},{Base:60.0d,Name:"generic.followRange"},{Base:2.0d,Name:"generic.attackDamage"}],Invulnerable:0b,AbsorptionAmount:0.0f,PortalCooldown:0,FallDistance:0.0f,levelingStats:{level:0,xp:0,entryList:[]},DeathTime:0s,DropChances:[1.0f,1.0f,1.0f,1.0f,1.0f],PersistenceRequired:1b,HealF:20.0f,owner:"shadowmage4513",Motion:[0.0d,-0.0784000015258789d,0.0d],armorValueOverride:-1,Leashed:0b,Health:20s,OnGround:1b,Dimension:0,Air:300s,Rotation:[-200.76399f,0.0f],CustomName:"",Pos:[492.1390247499272d,31.0d,-1272.2312548691746d],Fire:-1s,attackDamageOverride:-1,customTex:"",CanPickUpLoot:0b,factionName:"pirate",HurtTime:0s,AttackTime:0s,CustomNameVisible:0b}}
:enddata
:endentity

entity:
plugin=AWNpc
number=7
data:
position=23,11,17
JSON:{xOffset:0.5f,equipmentData:{equipmentContents:[{id:"minecraft:bow",Count:1b,slot:0,Damage:0s}]},rotation:185.19815f,mobID:"ancientwarfarenpc:faction.archer",zOffset:0.5f,entityData:{Attributes:[{Base:20.0d,Name:"generic.maxHealth"},{Base:0.0d,Name:"generic.knockbackResistance"},{Base:0.325d,Name:"generic.movementSpeed"},{Base:60.0d,Name:"generic.followRange"},{Base:2.0d,Name:"generic.attackDamage"}],Invulnerable:0b,AbsorptionAmount:0.0f,PortalCooldown:0,FallDistance:0.0f,levelingStats:{level:0,xp:0,entryList:[]},DeathTime:0s,DropChances:[1.0f,1.0f,1.0f,1.0f,1.0f],PersistenceRequired:1b,HealF:20.0f,owner:"shadowmage4513",Motion:[0.0d,-0.0784000015258789d,0.0d],armorValueOverride:-1,Leashed:0b,Health:20s,OnGround:1b,Dimension:0,Air:300s,Rotation:[5.1981483f,0.0f],CustomName:"",Pos:[487.5d,36.0d,-1278.5d],Fire:-1s,attackDamageOverride:-1,customTex:"",CanPickUpLoot:0b,factionName:"pirate",HurtTime:0s,AttackTime:0s,CustomNameVisible:0b}}
:enddata
:endentity

entity:
plugin=AWNpc
number=8
data:
position=23,11,9
JSON:{xOffset:0.5f,equipmentData:{equipmentContents:[{id:"minecraft:bow",Count:1b,slot:0,Damage:0s}]},rotation:184.07074f,mobID:"ancientwarfarenpc:faction.archer",zOffset:0.5f,entityData:{Attributes:[{Base:20.0d,Name:"generic.maxHealth"},{Base:0.0d,Name:"generic.knockbackResistance"},{Base:0.325d,Name:"generic.movementSpeed"},{Base:60.0d,Name:"generic.followRange"},{Base:2.0d,Name:"generic.attackDamage"}],Invulnerable:0b,AbsorptionAmount:0.0f,PortalCooldown:0,FallDistance:0.0f,levelingStats:{level:0,xp:0,entryList:[]},DeathTime:0s,DropChances:[1.0f,1.0f,1.0f,1.0f,1.0f],PersistenceRequired:1b,HealF:20.0f,owner:"shadowmage4513",Motion:[0.0d,-0.0784000015258789d,0.0d],armorValueOverride:-1,Leashed:0b,Health:20s,OnGround:1b,Dimension:0,Air:300s,Rotation:[4.070733f,0.0f],CustomName:"",Pos:[487.5d,36.0d,-1270.5d],Fire:-1s,attackDamageOverride:-1,customTex:"",CanPickUpLoot:0b,factionName:"pirate",HurtTime:0s,AttackTime:0s,CustomNameVisible:0b}}
:enddata
:endentity

entity:
plugin=awGate
number=9
data:
position=13,1,22
JSON:{owner:"shadowmage4513",orientation:0b,pos1:{x:2,y:0,z:0},pos2:{x:-2,y:3,z:0},gateType:"gate.verticalIron"}
:enddata
:endentity

entity:
plugin=AWNpc
number=10
data:
position=6,6,19
JSON:{xOffset:0.102713645f,equipmentData:{equipmentContents:[{id:"minecraft:bow",Count:1b,slot:0,Damage:0s}]},rotation:180.57768f,mobID:"ancientwarfarenpc:faction.archer",zOffset:0.12679768f,entityData:{Attributes:[{Base:20.0d,Name:"generic.maxHealth"},{Base:0.0d,Name:"generic.knockbackResistance"},{Base:0.325d,Name:"generic.movementSpeed"},{Base:60.0d,Name:"generic.followRange"},{Base:2.0d,Name:"generic.attackDamage"}],Invulnerable:0b,AbsorptionAmount:0.0f,PortalCooldown:0,FallDistance:0.0f,levelingStats:{level:0,xp:0,entryList:[]},DeathTime:0s,DropChances:[1.0f,1.0f,1.0f,1.0f,1.0f],PersistenceRequired:1b,HealF:20.0f,owner:"shadowmage4513",Motion:[0.0d,-0.0784000015258789d,0.0d],armorValueOverride:-1,Leashed:0b,Health:20s,OnGround:1b,Dimension:0,Air:300s,Rotation:[0.5776777f,0.0f],CustomName:"",Pos:[504.8972863530099d,31.0d,-1280.1267976752065d],Fire:-1s,attackDamageOverride:-1,customTex:"",CanPickUpLoot:0b,factionName:"pirate",HurtTime:0s,AttackTime:0s,CustomNameVisible:0b}}
:enddata
:endentity

entity:
plugin=AWNpc
number=11
data:
position=6,1,22
JSON:{xOffset:0.33103764f,equipmentData:{equipmentContents:[{id:"minecraft:iron_sword",Count:1b,slot:0,Damage:0s}]},rotation:261.15552f,mobID:"ancientwarfarenpc:faction.soldier",zOffset:0.5420802f,entityData:{Attributes:[{Base:20.0d,Name:"generic.maxHealth"},{Base:0.0d,Name:"generic.knockbackResistance"},{Base:0.325d,Name:"generic.movementSpeed"},{Base:60.0d,Name:"generic.followRange"},{Base:2.0d,Name:"generic.attackDamage"}],Invulnerable:0b,AbsorptionAmount:0.0f,PortalCooldown:0,FallDistance:0.0f,levelingStats:{level:0,xp:0,entryList:[]},DeathTime:0s,DropChances:[1.0f,1.0f,1.0f,1.0f,1.0f],PersistenceRequired:1b,HealF:20.0f,owner:"shadowmage4513",Motion:[0.0d,-0.0784000015258789d,0.0d],armorValueOverride:-1,Leashed:0b,Health:20s,OnGround:1b,Dimension:0,Air:300s,Rotation:[441.15552f,0.0f],CustomName:"",Pos:[504.6689623716087d,26.0d,-1283.54208024235d],Fire:-1s,attackDamageOverride:-1,customTex:"",CanPickUpLoot:0b,factionName:"pirate",HurtTime:0s,AttackTime:0s,CustomNameVisible:0b}}
:enddata
:endentity

entity:
plugin=AWNpc
number=12
data:
position=9,11,23
JSON:{xOffset:0.5f,equipmentData:{equipmentContents:[{id:"minecraft:bow",Count:1b,slot:0,Damage:0s}]},rotation:182.3021f,mobID:"ancientwarfarenpc:faction.archer",zOffset:0.5f,entityData:{Attributes:[{Base:20.0d,Name:"generic.maxHealth"},{Base:0.0d,Name:"generic.knockbackResistance"},{Base:0.325d,Name:"generic.movementSpeed"},{Base:60.0d,Name:"generic.followRange"},{Base:2.0d,Name:"generic.attackDamage"}],Invulnerable:0b,AbsorptionAmount:0.0f,PortalCooldown:0,FallDistance:0.0f,levelingStats:{level:0,xp:0,entryList:[]},DeathTime:0s,DropChances:[1.0f,1.0f,1.0f,1.0f,1.0f],PersistenceRequired:1b,HealF:20.0f,owner:"shadowmage4513",Motion:[0.0d,-0.0784000015258789d,0.0d],armorValueOverride:-1,Leashed:0b,Health:20s,OnGround:1b,Dimension:0,Air:300s,Rotation:[2.3020954f,0.0f],CustomName:"",Pos:[501.5d,36.0d,-1284.5d],Fire:-1s,attackDamageOverride:-1,customTex:"",CanPickUpLoot:0b,factionName:"pirate",HurtTime:0s,AttackTime:0s,CustomNameVisible:0b}}
:enddata
:endentity

entity:
plugin=AWNpc
number=13
data:
position=6,1,17
JSON:{xOffset:0.31565267f,equipmentData:{equipmentContents:[{id:"minecraft:bow",Count:1b,slot:0,Damage:0s}]},rotation:182.94646f,mobID:"ancientwarfarenpc:faction.archer",zOffset:0.6854217f,entityData:{Attributes:[{Base:20.0d,Name:"generic.maxHealth"},{Base:0.0d,Name:"generic.knockbackResistance"},{Base:0.325d,Name:"generic.movementSpeed"},{Base:60.0d,Name:"generic.followRange"},{Base:2.0d,Name:"generic.attackDamage"}],Invulnerable:0b,AbsorptionAmount:0.0f,PortalCooldown:0,FallDistance:0.0f,levelingStats:{level:0,xp:0,entryList:[]},DeathTime:0s,DropChances:[1.0f,1.0f,1.0f,1.0f,1.0f],PersistenceRequired:1b,HealF:20.0f,owner:"shadowmage4513",Motion:[0.0d,-0.0784000015258789d,0.0d],armorValueOverride:-1,Leashed:0b,Health:20s,OnGround:1b,Dimension:0,Air:300s,Rotation:[2.946457f,0.0f],CustomName:"",Pos:[504.6843473478998d,26.0d,-1278.6854217041623d],Fire:-1s,attackDamageOverride:-1,customTex:"",CanPickUpLoot:0b,factionName:"pirate",HurtTime:0s,AttackTime:0s,CustomNameVisible:0b}}
:enddata
:endentity

entity:
plugin=AWNpc
number=14
data:
position=7,1,7
JSON:{xOffset:0.67604476f,equipmentData:{equipmentContents:[{id:"minecraft:bow",Count:1b,slot:0,Damage:0s}]},rotation:186.27713f,mobID:"ancientwarfarenpc:faction.archer",zOffset:0.4973153f,entityData:{Attributes:[{Base:20.0d,Name:"generic.maxHealth"},{Base:0.0d,Name:"generic.knockbackResistance"},{Base:0.325d,Name:"generic.movementSpeed"},{Base:60.0d,Name:"generic.followRange"},{Base:2.0d,Name:"generic.attackDamage"}],Invulnerable:0b,AbsorptionAmount:0.0f,PortalCooldown:0,FallDistance:0.0f,levelingStats:{level:0,xp:0,entryList:[]},DeathTime:0s,DropChances:[1.0f,1.0f,1.0f,1.0f,1.0f],PersistenceRequired:1b,HealF:20.0f,owner:"shadowmage4513",Motion:[0.0d,-0.0784000015258789d,0.0d],armorValueOverride:-1,Leashed:0b,Health:20s,OnGround:1b,Dimension:0,Air:300s,Rotation:[6.2771363f,0.0f],CustomName:"",Pos:[503.3239552487899d,26.0d,-1268.497315264185d],Fire:-1s,attackDamageOverride:-1,customTex:"",CanPickUpLoot:0b,factionName:"pirate",HurtTime:0s,AttackTime:0s,CustomNameVisible:0b}}
:enddata
:endentity

entity:
plugin=AWNpc
number=15
data:
position=6,6,8
JSON:{xOffset:0.5f,equipmentData:{equipmentContents:[{id:"minecraft:bow",Count:1b,slot:0,Damage:0s}]},rotation:181.37439f,mobID:"ancientwarfarenpc:faction.archer",zOffset:0.5f,entityData:{Attributes:[{Base:20.0d,Name:"generic.maxHealth"},{Base:0.0d,Name:"generic.knockbackResistance"},{Base:0.325d,Name:"generic.movementSpeed"},{Base:60.0d,Name:"generic.followRange"},{Base:2.0d,Name:"generic.attackDamage"}],Invulnerable:0b,AbsorptionAmount:0.0f,PortalCooldown:0,FallDistance:0.0f,levelingStats:{level:0,xp:0,entryList:[]},DeathTime:0s,DropChances:[1.0f,1.0f,1.0f,1.0f,1.0f],PersistenceRequired:1b,HealF:20.0f,owner:"shadowmage4513",Motion:[0.0d,-0.0784000015258789d,0.0d],armorValueOverride:-1,Leashed:0b,Health:20s,OnGround:1b,Dimension:0,Air:300s,Rotation:[1.3743935f,0.0f],CustomName:"",Pos:[504.5d,31.0d,-1269.5d],Fire:-1s,attackDamageOverride:-1,customTex:"",CanPickUpLoot:0b,factionName:"pirate",HurtTime:0s,AttackTime:0s,CustomNameVisible:0b}}
:enddata
:endentity

entity:
plugin=AWNpc
number=16
data:
position=8,6,10
JSON:{xOffset:0.27908897f,equipmentData:{equipmentContents:[{id:"minecraft:iron_sword",Count:1b,slot:0,Damage:0s}]},rotation:-23.409042f,mobID:"ancientwarfarenpc:faction.soldier",zOffset:0.10921645f,entityData:{Attributes:[{Base:20.0d,Name:"generic.maxHealth"},{Base:0.0d,Name:"generic.knockbackResistance"},{Base:0.325d,Name:"generic.movementSpeed"},{Base:60.0d,Name:"generic.followRange"},{Base:2.0d,Name:"generic.attackDamage"}],Invulnerable:0b,AbsorptionAmount:0.0f,PortalCooldown:0,FallDistance:0.0f,levelingStats:{level:0,xp:0,entryList:[]},DeathTime:0s,DropChances:[1.0f,1.0f,1.0f,1.0f,1.0f],PersistenceRequired:1b,HealF:20.0f,owner:"shadowmage4513",Motion:[0.0d,-0.0784000015258789d,0.0d],armorValueOverride:-1,Leashed:0b,Health:20s,OnGround:1b,Dimension:0,Air:300s,Rotation:[-203.40904f,0.0f],CustomName:"",Pos:[502.72091101256393d,31.0d,-1271.1092164632241d],Fire:-1s,attackDamageOverride:-1,customTex:"",CanPickUpLoot:0b,factionName:"pirate",HurtTime:0s,AttackTime:0s,CustomNameVisible:0b}}
:enddata
:endentity

entity:
plugin=AWNpc
number=17
data:
position=3,11,7
JSON:{xOffset:0.63918686f,equipmentData:{equipmentContents:[{id:"minecraft:bow",Count:1b,slot:0,Damage:0s}]},rotation:183.55817f,mobID:"ancientwarfarenpc:faction.archer",zOffset:0.3f,entityData:{Attributes:[{Base:20.0d,Name:"generic.maxHealth"},{Base:0.0d,Name:"generic.knockbackResistance"},{Base:0.325d,Name:"generic.movementSpeed"},{Base:60.0d,Name:"generic.followRange"},{Base:2.0d,Name:"generic.attackDamage"}],Invulnerable:0b,AbsorptionAmount:0.0f,PortalCooldown:0,FallDistance:0.0f,levelingStats:{level:0,xp:0,entryList:[]},DeathTime:0s,DropChances:[1.0f,1.0f,1.0f,1.0f,1.0f],PersistenceRequired:1b,HealF:20.0f,owner:"shadowmage4513",Motion:[0.0d,-0.0784000015258789d,0.0d],armorValueOverride:-1,Leashed:0b,Health:20s,OnGround:1b,Dimension:0,Air:300s,Rotation:[3.5581698f,0.0f],CustomName:"",Pos:[507.3608131185237d,36.0d,-1268.300000011921d],Fire:-1s,attackDamageOverride:-1,customTex:"",CanPickUpLoot:0b,factionName:"pirate",HurtTime:0s,AttackTime:0s,CustomNameVisible:0b}}
:enddata
:endentity

entity:
plugin=AWNpc
number=18
data:
position=3,11,17
JSON:{xOffset:0.5f,equipmentData:{equipmentContents:[{id:"minecraft:bow",Count:1b,slot:0,Damage:0s}]},rotation:181.71623f,mobID:"ancientwarfarenpc:faction.archer",zOffset:0.5f,entityData:{Attributes:[{Base:20.0d,Name:"generic.maxHealth"},{Base:0.0d,Name:"generic.knockbackResistance"},{Base:0.325d,Name:"generic.movementSpeed"},{Base:60.0d,Name:"generic.followRange"},{Base:2.0d,Name:"generic.attackDamage"}],Invulnerable:0b,AbsorptionAmount:0.0f,PortalCooldown:0,FallDistance:0.0f,levelingStats:{level:0,xp:0,entryList:[]},DeathTime:0s,DropChances:[1.0f,1.0f,1.0f,1.0f,1.0f],PersistenceRequired:1b,HealF:20.0f,owner:"shadowmage4513",Motion:[0.0d,-0.0784000015258789d,0.0d],armorValueOverride:-1,Leashed:0b,Health:20s,OnGround:1b,Dimension:0,Air:300s,Rotation:[1.7162256f,0.0f],CustomName:"",Pos:[507.5d,36.0d,-1278.5d],Fire:-1s,attackDamageOverride:-1,customTex:"",CanPickUpLoot:0b,factionName:"pirate",HurtTime:0s,AttackTime:0s,CustomNameVisible:0b}}
:enddata
:endentity

