# Ancient Warfare Structure Template File
# Auto-generated structure template file. created on: 8/28/2018 at: 17:29:59
# Lines beginning with # denote comments

header:
version=2.3
name=village_house
size=9,7,12
offset=2,0,11
:endheader

#### VALIDATION ####
validation:
type=ground
survival=true
worldGenEnabled=false
unique=false
preserveBlocks=false
selectionWeight=0
clusterValue=0
minDuplicateDistance=0
dimensionWhiteList=false
dimensionList=
biomeWhiteList=false
biomeList=
leveling=0
fill=0
border=0
blockSwap=true
data:
:enddata
:endvalidation

#### LAYERS ####
layer: 0
0,0,1,1,1,1,1,1,1
0,0,1,2,2,2,2,2,1
0,0,1,2,2,2,2,2,1
0,0,1,2,2,2,2,2,1
0,0,1,2,2,2,2,2,1
1,1,1,2,2,2,2,2,1
1,2,2,2,2,2,2,2,1
1,2,2,2,2,2,2,2,1
1,2,2,2,2,2,2,2,1
1,2,2,2,2,2,2,2,1
1,1,1,1,1,1,1,1,1
0,0,3,0,0,0,0,0,0
:endlayer
layer: 1
0,0,1,1,1,1,1,1,1
0,0,1,0,0,0,0,0,1
0,0,1,0,0,0,0,0,1
0,0,1,0,0,0,0,0,1
0,0,1,0,0,0,0,0,1
1,1,1,0,0,0,0,0,1
1,0,0,0,0,0,0,0,1
1,0,0,0,0,0,0,0,1
1,0,0,0,0,0,0,0,1
1,0,0,0,0,0,0,0,1
1,1,4,1,1,1,1,1,1
0,0,0,0,0,0,0,0,0
:endlayer
layer: 2
0,0,1,1,1,1,1,1,1
0,0,5,0,0,0,0,0,5
0,0,6,0,0,0,0,0,6
0,0,6,0,0,0,0,0,6
0,0,5,0,0,0,0,0,5
1,2,2,0,0,0,0,0,2
5,0,0,0,0,0,0,0,5
6,0,0,0,0,0,0,0,6
6,0,0,0,0,0,0,0,6
5,0,0,0,0,0,0,0,5
1,2,7,2,5,6,5,2,1
0,0,0,0,0,0,0,0,0
:endlayer
layer: 3
0,10,1,1,1,1,1,1,1
0,10,1,0,0,0,0,0,1
0,10,1,0,0,0,0,0,1
0,10,1,0,0,0,0,0,1
9,2,1,0,0,0,0,0,1
1,2,2,0,0,0,0,0,1
1,0,0,0,0,0,0,0,1
1,0,0,0,0,0,0,0,1
1,0,0,0,0,0,0,0,1
1,0,11,0,0,0,0,0,1
1,2,2,2,2,2,2,2,1
8,8,8,8,8,8,8,8,8
:endlayer
layer: 4
0,0,10,2,5,6,5,2,12
0,0,10,2,0,0,0,2,12
0,0,10,2,0,0,0,2,12
0,0,10,2,0,0,0,2,12
0,0,10,2,0,0,0,2,12
9,9,2,2,0,0,0,2,12
2,2,2,2,0,0,0,2,2
2,0,0,0,0,0,0,2,2
2,0,0,0,0,0,0,2,2
2,2,2,2,2,2,2,2,2
8,8,8,8,8,8,8,8,8
0,0,0,0,0,0,0,0,0
:endlayer
layer: 5
0,0,0,10,2,2,2,12,0
0,0,0,10,2,0,2,12,0
0,0,0,10,2,0,2,12,0
0,0,0,10,2,0,2,12,0
0,0,0,10,2,0,2,12,0
0,0,0,10,2,0,2,12,0
9,9,9,2,2,0,2,2,9
2,2,2,2,2,2,2,2,2
2,2,2,2,2,2,2,2,2
8,8,8,8,8,8,8,8,8
0,0,0,0,0,0,0,0,0
0,0,0,0,0,0,0,0,0
:endlayer
layer: 6
0,0,0,0,10,2,12,0,0
0,0,0,0,10,2,12,0,0
0,0,0,0,10,2,12,0,0
0,0,0,0,10,2,12,0,0
0,0,0,0,10,2,12,0,0
0,0,0,0,10,2,12,0,0
0,0,0,0,10,2,12,0,0
9,9,9,9,2,2,2,9,9
8,8,8,8,8,8,8,8,8
0,0,0,0,0,0,0,0,0
0,0,0,0,0,0,0,0,0
0,0,0,0,0,0,0,0,0
:endlayer

#### RULES ####
rule:
plugin=vanillaBlocks
number=1
data:
JSON:{buildPass:0,blockName:"minecraft:cobblestone",meta:0}
:enddata
:endrule

rule:
plugin=vanillaBlocks
number=2
data:
JSON:{buildPass:0,blockName:"minecraft:planks",meta:0}
:enddata
:endrule

rule:
plugin=vanillaBlocks
number=3
data:
JSON:{buildPass:0,blockName:"minecraft:stone_stairs",meta:3}
:enddata
:endrule

rule:
plugin=vanillaDoors
number=4
data:
JSON:{buildPass:2,blockName:"minecraft:wooden_door",meta:3,sideFlag:0b}
:enddata
:endrule

rule:
plugin=vanillaBlocks
number=5
data:
JSON:{buildPass:0,blockName:"minecraft:log",meta:0}
:enddata
:endrule

rule:
plugin=vanillaBlocks
number=6
data:
JSON:{buildPass:0,blockName:"minecraft:glass_pane",meta:0}
:enddata
:endrule

rule:
plugin=vanillaDoors
number=7
data:
JSON:{buildPass:2,blockName:"minecraft:wooden_door",meta:8,sideFlag:0b}
:enddata
:endrule

rule:
plugin=vanillaBlocks
number=8
data:
JSON:{buildPass:0,blockName:"minecraft:oak_stairs",meta:3}
:enddata
:endrule

rule:
plugin=vanillaBlocks
number=9
data:
JSON:{buildPass:0,blockName:"minecraft:oak_stairs",meta:2}
:enddata
:endrule

rule:
plugin=vanillaBlocks
number=10
data:
JSON:{buildPass:0,blockName:"minecraft:oak_stairs",meta:0}
:enddata
:endrule

rule:
plugin=vanillaBlocks
number=11
data:
JSON:{buildPass:2,blockName:"minecraft:torch",meta:4}
:enddata
:endrule

rule:
plugin=vanillaBlocks
number=12
data:
JSON:{buildPass:0,blockName:"minecraft:oak_stairs",meta:1}
:enddata
:endrule

#### ENTITIES ####
