# Ancient Warfare Structure Template File
# Auto-generated structure template file. created on: 8/19/2019 at: 10:23:11
# Lines beginning with # denote comments

header:
version=2.9
name=EmpireVillageChapel
mods=
size=16,13,38
offset=6,2,37
:endheader

#### VALIDATION ####
validation:
type=ground
survival=false
worldGenEnabled=true
unique=false
preserveBlocks=false
selectionWeight=50
clusterValue=30
minDuplicateDistance=1000
dimensionWhiteList=true
dimensionList=0
biomeWhiteList=true
biomeList=biomesoplenty:meadow,traverse:meadow,minecraft:plains
leveling=6
fill=6
border=5
blockSwap=false
:endvalidation

#### LAYERS ####
layer: 0
1,1,1,1,1,1,1,1,1,1,1,1,1,1,1,1
1,1,1,1,1,1,1,1,1,1,1,1,1,1,1,1
1,1,1,1,1,1,1,1,1,1,1,1,1,1,1,1
1,1,1,1,1,1,1,1,1,1,1,1,1,1,1,1
1,1,1,1,1,1,1,1,1,1,1,1,1,1,1,1
1,1,1,1,1,1,1,1,1,1,1,1,1,1,1,1
1,1,1,1,1,1,1,1,1,1,1,1,1,1,1,1
1,1,1,1,1,1,1,1,1,1,1,1,1,1,1,1
1,1,1,1,1,1,1,1,1,1,1,1,1,1,1,1
1,1,1,1,1,1,1,1,1,1,1,1,1,1,1,1
1,1,1,1,1,1,1,1,1,1,1,1,1,1,1,1
1,1,1,1,1,1,1,1,1,1,1,1,1,1,1,1
1,1,1,1,1,1,1,1,1,1,1,1,1,1,1,1
1,1,1,1,1,1,1,1,1,1,1,1,1,1,1,1
1,1,1,1,1,1,1,1,1,1,1,1,1,1,1,1
1,1,1,1,1,1,1,1,1,1,1,1,1,1,1,1
1,1,1,1,1,1,1,1,1,1,1,1,1,1,1,1
1,1,1,1,1,1,1,1,1,1,1,1,1,1,1,1
1,1,1,1,1,1,1,1,1,1,1,1,1,1,1,1
1,1,1,1,1,1,1,1,1,1,1,1,1,1,1,1
1,1,1,1,1,1,1,1,1,1,1,1,1,1,1,1
1,1,1,1,1,1,1,1,1,1,1,1,1,1,1,1
1,1,1,1,1,1,1,1,1,1,1,1,1,1,1,1
1,1,1,1,1,1,1,1,1,1,1,1,1,1,1,1
1,1,1,1,1,1,1,1,1,1,1,1,1,1,1,1
1,1,1,1,1,1,1,1,1,1,1,1,1,1,1,1
1,1,1,1,1,1,1,1,1,1,1,1,1,1,1,1
1,1,1,1,1,1,1,1,1,1,1,1,1,1,1,1
1,1,1,1,1,1,1,1,1,1,1,1,1,1,1,1
1,1,1,1,1,1,1,1,1,1,1,1,1,1,1,1
1,1,1,1,1,1,1,1,1,1,1,1,1,1,1,1
1,1,1,1,1,1,1,1,1,1,1,1,1,1,1,1
1,1,1,1,1,1,1,1,1,1,1,1,1,1,1,1
1,1,1,1,1,1,1,1,1,1,1,1,1,1,1,1
1,1,1,1,1,1,1,1,1,1,1,1,1,1,1,1
1,1,1,1,1,1,1,1,1,1,1,1,1,1,1,1
1,1,1,1,1,1,1,1,1,1,1,1,1,1,1,1
1,1,1,1,1,1,1,1,1,1,1,1,1,1,1,1
:endlayer
layer: 1
2,2,2,2,2,2,2,2,2,2,2,2,2,2,2,2
2,2,2,2,2,2,2,2,2,2,2,2,2,2,2,2
2,2,2,2,2,2,2,2,1,1,1,1,2,2,2,2
2,2,2,3,3,3,3,3,3,3,3,3,3,2,2,2
2,2,2,1,1,1,1,1,1,1,1,1,4,2,2,2
2,2,2,1,1,1,1,1,1,1,1,1,4,2,2,2
2,2,2,1,1,1,1,1,1,1,1,1,4,2,2,2
2,2,2,1,1,1,1,1,1,1,1,1,4,2,2,2
2,2,2,1,1,1,1,1,1,1,1,1,4,2,2,2
2,2,2,1,1,1,1,1,1,1,1,1,4,2,2,2
2,2,2,3,5,5,5,5,5,5,5,5,4,2,2,2
2,2,2,3,5,5,5,5,5,5,5,5,4,2,2,2
2,2,2,2,2,2,2,2,2,2,2,2,2,2,2,2
2,2,2,2,2,2,2,2,2,2,2,2,2,2,2,2
2,2,2,2,2,2,2,2,2,2,2,2,2,2,2,2
2,2,2,2,2,2,2,2,2,2,2,2,2,2,2,2
2,2,2,2,2,2,2,2,2,2,2,2,2,2,2,2
2,2,2,2,2,2,2,2,2,2,2,2,2,2,2,2
2,2,2,2,2,2,2,2,2,2,2,2,2,2,2,2
2,2,1,2,2,1,2,2,1,2,2,1,2,2,2,2
2,1,1,1,1,1,1,1,1,1,1,1,1,2,2,2
2,2,1,6,6,5,7,7,5,6,6,1,2,2,2,2
2,2,1,6,6,5,7,7,5,6,6,1,2,2,2,2
2,2,1,6,6,6,8,8,6,6,6,1,2,2,2,2
2,2,1,6,6,6,8,8,6,6,6,1,2,2,2,2
2,2,1,6,5,5,8,8,5,5,6,1,2,2,2,2
2,2,1,6,6,6,8,8,6,6,6,1,2,2,2,2
2,2,1,6,5,5,8,8,5,5,6,1,2,2,2,2
2,2,1,6,6,6,8,8,6,6,6,1,2,2,2,2
2,1,1,1,1,6,8,8,6,1,1,1,1,2,2,2
2,2,1,1,1,6,8,8,6,1,1,1,2,2,2,2
2,2,2,1,1,6,8,8,6,1,1,2,2,2,2,2
2,2,2,1,1,6,8,8,6,1,1,2,2,2,2,2
2,2,2,1,1,6,8,8,6,1,1,2,2,2,2,2
2,2,2,1,1,1,8,8,1,1,1,2,2,2,2,2
2,2,2,2,2,1,8,8,1,2,2,2,2,2,2,2
2,1,2,2,2,2,9,9,2,2,2,2,1,2,2,2
2,2,2,2,2,2,9,9,2,2,2,2,2,2,2,2
:endlayer
layer: 2
0,0,0,0,0,0,10,0,0,10,0,0,0,0,0,0
0,0,0,0,11,12,10,10,10,0,0,0,0,0,0,0
0,0,10,0,10,10,10,10,3,3,3,3,10,0,0,0
0,0,0,3,3,3,3,3,3,3,3,3,3,10,0,0
0,0,0,3,3,3,3,3,3,3,3,3,4,0,0,0
10,0,0,3,3,3,3,3,3,3,3,3,4,0,0,0
0,0,0,3,3,3,3,3,3,3,3,3,4,10,0,0
12,10,0,3,3,3,3,3,3,3,3,3,4,10,0,0
10,10,10,3,3,3,3,3,3,3,3,3,4,0,0,0
10,10,0,3,3,3,3,3,3,3,3,3,4,0,0,0
10,0,13,3,3,3,3,3,3,3,3,3,4,0,0,0
0,10,0,3,14,14,14,14,14,14,14,14,4,0,0,0
10,0,0,0,10,0,0,0,0,0,0,0,0,10,0,0
0,10,10,10,10,0,0,0,0,0,0,0,0,0,10,0
10,0,10,10,10,10,0,0,0,0,0,0,10,10,0,10
10,10,10,10,10,10,10,0,0,0,0,0,10,10,10,0
0,0,15,10,10,0,0,0,0,0,0,0,10,10,15,10
0,0,10,10,10,0,0,0,0,0,15,0,10,0,11,0
10,10,10,10,10,0,0,0,10,10,10,10,0,0,16,0
0,10,3,10,0,3,0,0,3,10,10,3,0,0,0,0
0,3,3,3,3,3,3,3,3,3,3,3,3,0,0,0
0,0,3,0,0,17,18,18,17,0,0,3,0,0,0,0
10,0,3,0,0,17,18,18,17,19,0,3,10,10,0,0
10,0,3,0,0,20,17,17,20,0,0,3,10,10,0,0
10,10,3,0,21,0,0,0,0,22,0,3,10,10,0,0
10,10,3,0,23,23,0,0,23,23,0,3,0,0,0,0
10,0,3,0,24,0,0,0,0,25,0,3,10,0,0,0
0,0,3,0,23,23,0,0,23,23,0,3,10,10,0,0
10,0,3,0,0,0,0,0,0,0,0,3,10,10,0,0
0,3,3,3,3,0,0,0,0,3,3,3,3,10,0,0
0,0,3,3,3,26,0,0,0,3,3,3,0,0,0,0
0,0,0,3,3,0,0,0,0,3,3,0,0,0,0,0
0,0,10,3,3,0,0,0,0,3,3,0,0,0,0,0
0,10,0,3,3,0,0,0,0,3,3,0,0,0,0,0
10,10,10,3,3,3,27,27,3,3,3,10,0,0,0,0
10,10,10,0,0,3,0,0,3,10,10,10,10,0,0,0
10,3,0,0,0,0,0,0,10,0,10,10,3,10,0,0
0,10,10,10,0,0,0,0,0,10,10,10,10,0,0,0
:endlayer
layer: 3
0,0,0,0,0,0,0,0,0,0,0,0,0,0,0,0
0,0,0,0,0,0,0,0,0,0,0,0,0,0,0,0
0,0,0,0,0,0,0,0,3,3,3,3,0,0,0,0
0,0,0,3,3,3,3,3,3,28,28,3,3,0,0,0
0,0,0,3,29,30,31,3,0,0,0,32,4,0,0,0
0,0,0,3,0,0,0,33,0,34,0,0,4,0,0,0
0,0,0,3,35,0,0,3,0,0,36,37,4,0,0,0
0,0,0,3,0,0,38,3,0,0,0,0,4,0,0,0
0,0,0,3,0,0,23,3,39,39,39,39,4,0,0,0
0,0,0,3,3,33,3,3,3,3,3,3,4,0,0,0
0,0,0,0,0,0,0,40,0,0,0,0,0,0,0,0
0,0,0,0,0,0,0,0,0,0,0,0,0,0,0,0
0,0,0,0,0,0,0,0,0,0,0,0,0,0,0,0
0,0,0,0,0,0,0,0,0,0,0,0,0,0,0,0
0,0,0,0,0,0,0,0,0,0,0,0,0,0,0,0
0,0,0,0,0,0,0,0,0,0,0,0,0,0,0,0
0,0,0,0,0,0,0,0,0,0,0,0,0,0,0,0
0,0,0,0,0,0,0,0,0,0,0,0,0,0,0,0
0,0,0,0,0,0,0,0,0,0,0,0,0,0,0,0
0,0,3,0,0,3,0,0,3,0,0,3,0,0,0,0
0,3,3,3,3,3,41,41,3,3,3,3,3,0,0,0
0,0,3,0,0,0,42,0,0,0,0,3,0,0,0,0
0,0,3,0,0,0,43,44,0,0,0,3,0,0,0,0
0,0,41,0,0,0,0,0,0,0,0,41,0,0,0,0
0,0,3,0,0,0,0,0,0,0,0,3,0,0,0,0
0,0,3,0,0,0,0,0,0,0,0,3,0,0,0,0
0,0,41,0,0,0,0,0,0,0,0,41,0,0,0,0
0,0,3,0,0,0,0,0,0,0,0,3,0,0,0,0
0,0,3,0,0,0,0,0,0,0,0,3,0,0,0,0
0,3,3,3,3,0,0,0,0,3,3,3,3,0,0,0
0,0,3,45,3,0,0,0,0,3,46,3,0,0,0,0
0,0,0,45,3,0,0,0,0,3,46,0,0,0,0,0
0,0,0,45,3,0,0,0,0,3,46,0,0,0,0,0
0,0,0,45,3,0,0,0,0,3,46,0,0,0,0,0
0,0,0,47,3,3,48,49,3,3,50,0,0,0,0,0
0,0,0,0,51,3,0,0,3,52,0,0,0,0,0,0
0,28,0,0,0,53,0,0,0,0,0,0,28,0,0,0
0,0,0,0,0,0,0,0,0,0,0,0,0,0,0,0
:endlayer
layer: 4
0,0,0,0,0,0,0,0,0,0,0,0,0,0,0,0
0,0,0,0,0,0,0,0,0,0,0,0,0,0,0,0
0,0,0,0,0,0,0,0,3,3,3,3,0,0,0,0
0,0,0,3,3,54,3,3,3,0,0,3,3,0,0,0
0,0,0,3,0,0,0,3,0,0,0,0,3,0,0,0
0,0,0,54,0,0,0,48,0,0,0,0,54,0,0,0
0,0,0,3,0,0,0,3,0,0,0,0,3,0,0,0
0,0,0,54,0,0,55,3,0,0,0,0,54,0,0,0
0,0,0,3,0,0,0,3,39,39,20,39,3,0,0,0
0,0,0,3,3,48,3,3,3,3,54,3,3,0,0,0
0,0,0,0,0,0,0,0,0,0,0,0,0,0,0,0
0,0,0,0,0,0,0,0,0,0,0,0,0,0,0,0
0,0,0,0,0,0,0,0,0,0,0,0,0,0,0,0
0,0,0,0,0,0,0,0,0,0,0,0,0,0,0,0
0,0,0,0,0,0,0,0,0,0,0,0,0,0,0,0
0,0,0,0,0,0,0,0,0,0,0,0,0,0,0,0
0,0,0,0,0,0,0,0,0,0,0,0,0,0,0,0
0,0,0,0,0,0,0,0,0,0,0,0,0,0,0,0
0,0,0,0,0,0,0,0,0,0,0,0,0,0,0,0
0,0,3,0,0,3,0,0,3,0,0,3,0,0,0,0
0,3,3,3,3,3,41,41,3,3,3,3,3,0,0,0
0,0,3,0,0,0,0,0,0,0,0,3,0,0,0,0
0,0,3,0,0,0,0,0,0,0,0,3,0,0,0,0
0,0,56,0,0,0,0,0,0,0,0,56,0,0,0,0
0,0,3,0,0,0,0,0,0,0,0,3,0,0,0,0
0,0,3,0,0,0,0,0,0,0,0,3,0,0,0,0
0,0,56,0,0,0,0,0,0,0,0,56,0,0,0,0
0,0,3,0,0,0,0,0,0,0,0,3,0,0,0,0
0,0,3,0,0,0,0,0,0,0,0,3,0,0,0,0
0,3,3,3,3,52,0,0,51,3,3,3,3,0,0,0
0,0,3,0,45,0,0,0,0,46,0,3,0,0,0,0
0,0,0,0,45,52,0,0,51,46,0,0,0,0,0,0
0,0,0,0,45,0,0,0,0,46,0,0,0,0,0,0
0,0,0,0,45,52,0,0,51,46,0,0,0,0,0,0
0,0,0,0,47,3,57,57,3,50,0,0,0,0,0,0
0,0,0,0,0,14,14,14,14,0,0,0,0,0,0,0
0,0,0,0,0,0,0,0,0,0,0,0,0,0,0,0
0,0,0,0,0,0,0,0,0,0,0,0,0,0,0,0
:endlayer
layer: 5
0,0,0,0,0,0,0,0,0,0,0,0,0,0,0,0
0,0,0,0,0,0,0,0,0,0,0,0,0,0,0,0
0,0,0,0,0,0,0,0,3,3,3,3,0,0,0,0
0,0,51,3,3,54,3,3,3,0,0,3,3,52,0,0
0,0,0,3,58,0,51,3,0,0,0,0,3,0,0,0
0,0,0,54,0,0,0,3,0,0,0,0,54,0,0,0
0,0,0,3,0,0,0,3,0,0,0,0,3,0,0,0
0,0,0,54,0,0,0,3,0,0,0,0,54,0,0,0
0,0,0,3,59,0,59,3,39,39,0,39,3,0,0,0
0,0,51,3,3,3,3,3,3,3,54,3,3,52,0,0
0,0,0,58,0,0,58,0,0,0,0,0,58,0,0,0
0,0,0,0,0,0,0,0,0,0,0,0,0,0,0,0
0,0,0,0,0,0,0,0,0,0,0,0,0,0,0,0
0,0,0,0,0,0,0,0,0,0,0,0,0,0,0,0
0,0,0,0,0,0,0,0,0,0,0,0,0,0,0,0
0,0,0,0,0,0,0,0,0,0,0,0,0,0,0,0
0,0,0,0,0,0,0,0,0,0,0,0,0,0,0,0
0,0,0,0,0,0,0,0,0,0,0,0,0,0,0,0
0,0,0,0,0,0,0,0,0,0,0,0,0,0,0,0
0,51,3,52,0,60,0,0,60,0,51,3,59,0,0,0
0,3,3,3,3,3,61,61,3,3,3,3,3,0,0,0
0,58,3,52,0,0,0,0,0,0,51,3,58,0,0,0
0,0,3,52,0,0,0,0,0,0,51,3,0,0,0,0
0,0,41,0,0,0,0,0,0,0,0,41,0,0,0,0
0,0,3,52,0,0,0,0,0,0,51,3,0,0,0,0
0,0,3,52,0,0,0,0,0,0,51,3,0,0,0,0
0,0,41,0,0,0,0,0,0,0,0,41,0,0,0,0
0,0,3,52,0,0,0,0,0,0,51,3,0,0,0,0
0,59,3,52,0,0,0,0,0,0,51,3,59,0,0,0
0,3,3,3,3,3,0,0,3,3,3,3,3,0,0,0
0,58,3,0,0,45,0,0,46,0,0,3,58,0,0,0
0,0,0,0,0,45,0,0,46,0,0,0,0,0,0,0
0,0,0,0,0,45,0,0,46,0,0,0,0,0,0,0
0,0,0,0,0,45,0,0,46,0,0,0,0,0,0,0
0,0,0,0,0,47,3,3,50,0,0,0,0,0,0,0
0,0,0,0,0,0,0,58,0,0,0,0,0,0,0,0
0,0,0,0,0,0,0,0,0,0,0,0,0,0,0,0
0,0,0,0,0,0,0,0,0,0,0,0,0,0,0,0
:endlayer
layer: 6
0,0,0,0,0,0,0,0,0,0,0,0,0,0,0,0
0,0,0,0,0,0,0,0,0,0,0,0,0,0,0,0
0,0,23,23,23,23,23,23,23,3,3,23,23,23,0,0
0,0,0,3,3,3,3,3,3,62,62,3,3,0,0,0
0,0,0,3,0,0,0,3,52,0,0,51,3,0,0,0
0,0,0,3,0,0,0,3,0,0,0,0,3,0,0,0
0,0,0,3,0,0,0,3,0,0,0,0,3,0,0,0
0,0,0,3,0,0,0,3,0,0,0,0,3,0,0,0
0,0,0,3,0,0,0,3,39,39,39,39,3,0,0,0
0,0,0,3,3,3,3,3,3,3,3,3,3,0,0,0
0,0,63,63,63,63,63,63,63,63,63,63,63,63,0,0
0,0,0,0,0,0,0,0,0,0,0,0,0,0,0,0
0,0,0,0,0,0,0,0,0,0,0,0,0,0,0,0
0,0,0,0,0,0,0,0,0,0,0,0,0,0,0,0
0,0,0,0,0,0,0,0,0,0,0,0,0,0,0,0
0,0,0,0,0,0,0,0,0,0,0,0,0,0,0,0
0,0,0,0,0,0,0,0,0,0,0,0,0,0,0,0
0,0,0,0,0,0,0,0,0,0,0,0,0,0,0,0
0,0,0,0,0,0,0,0,0,0,0,0,0,0,0,0
0,0,3,0,0,0,0,0,0,0,0,3,0,0,0,0
0,47,3,3,41,41,61,61,41,41,3,3,50,0,0,0
0,45,3,0,0,0,0,0,0,0,0,3,46,0,0,0
0,45,3,0,0,0,0,0,0,0,0,3,46,0,0,0
0,45,3,0,0,0,0,0,0,0,0,3,46,0,0,0
0,45,3,0,0,0,0,0,0,0,0,3,46,0,0,0
0,45,3,0,0,0,0,0,0,0,0,3,46,0,0,0
0,45,3,0,0,0,0,0,0,0,0,3,46,0,0,0
0,45,3,0,0,0,0,0,0,0,0,3,46,0,0,0
0,45,3,0,0,59,0,0,59,0,0,3,46,0,0,0
0,47,3,3,3,3,3,3,3,3,3,3,50,0,0,0
0,0,14,0,0,0,45,46,0,0,0,14,0,0,0,0
0,0,0,0,0,0,45,46,0,0,0,0,0,0,0,0
0,0,0,0,0,0,45,46,0,0,0,0,0,0,0,0
0,0,0,0,0,0,45,46,0,0,0,0,0,0,0,0
0,0,0,0,0,0,47,50,0,0,0,0,0,0,0,0
0,0,0,0,0,0,0,0,0,0,0,0,0,0,0,0
0,0,0,0,0,0,0,0,0,0,0,0,0,0,0,0
0,0,0,0,0,0,0,0,0,0,0,0,0,0,0,0
:endlayer
layer: 7
0,0,0,0,0,0,0,0,0,0,0,0,0,0,0,0
0,0,0,0,0,0,0,0,0,0,0,0,0,0,0,0
0,0,0,0,0,0,0,0,0,3,3,0,0,0,0,0
0,0,23,23,23,23,23,23,23,23,23,23,23,23,0,0
0,0,0,3,0,0,0,3,62,62,62,62,3,0,0,0
0,0,0,3,0,0,0,3,0,0,0,0,3,0,0,0
0,0,0,3,0,0,0,3,0,0,0,0,3,0,0,0
0,0,0,3,0,0,0,3,52,0,0,51,3,0,0,0
0,0,0,3,0,0,0,3,39,39,39,39,3,0,0,0
0,0,63,63,63,63,63,63,63,63,63,63,63,63,0,0
0,0,0,0,0,0,0,0,0,0,0,0,0,0,0,0
0,0,0,0,0,0,0,0,0,0,0,0,0,0,0,0
0,0,0,0,0,0,0,0,0,0,0,0,0,0,0,0
0,0,0,0,0,0,0,0,0,0,0,0,0,0,0,0
0,0,0,0,0,0,0,0,0,0,0,0,0,0,0,0
0,0,0,0,0,0,0,0,0,0,0,0,0,0,0,0
0,0,0,0,0,0,0,0,0,0,0,0,0,0,0,0
0,0,0,0,0,0,0,0,0,0,0,0,0,0,0,0
0,0,0,0,0,0,0,0,0,0,0,0,0,0,0,0
0,0,60,0,0,0,0,0,0,0,0,60,0,0,0,0
0,0,47,3,41,41,61,61,41,41,3,50,0,0,0,0
0,0,45,0,0,0,0,0,0,0,0,46,0,0,0,0
0,0,45,0,0,0,0,0,0,0,0,46,0,0,0,0
0,0,45,0,0,0,0,0,0,0,0,46,0,0,0,0
0,0,45,0,0,0,0,0,0,0,0,46,0,0,0,0
0,0,45,0,0,0,0,0,0,0,0,46,0,0,0,0
0,0,45,0,0,0,0,0,0,0,0,46,0,0,0,0
0,0,45,0,0,0,0,0,0,0,0,46,0,0,0,0
0,0,45,0,0,0,0,0,0,0,0,46,0,0,0,0
0,0,47,3,3,3,61,61,3,3,3,50,0,0,0,0
0,0,0,0,0,0,0,0,0,0,0,0,0,0,0,0
0,0,0,0,0,0,0,0,0,0,0,0,0,0,0,0
0,0,0,0,0,0,0,0,0,0,0,0,0,0,0,0
0,0,0,0,0,0,0,0,0,0,0,0,0,0,0,0
0,0,0,0,0,0,0,0,0,0,0,0,0,0,0,0
0,0,0,0,0,0,0,0,0,0,0,0,0,0,0,0
0,0,0,0,0,0,0,0,0,0,0,0,0,0,0,0
0,0,0,0,0,0,0,0,0,0,0,0,0,0,0,0
:endlayer
layer: 8
0,0,0,0,0,0,0,0,0,0,0,0,0,0,0,0
0,0,0,0,0,0,0,0,0,0,0,0,0,0,0,0
0,0,0,0,0,0,0,0,0,0,3,0,0,0,0,0
0,0,0,0,0,0,0,0,0,0,0,0,0,0,0,0
0,0,23,23,23,23,23,23,23,23,23,23,23,23,0,0
0,0,0,3,0,0,0,3,0,0,0,0,3,0,0,0
0,0,51,3,0,0,0,3,0,0,0,0,3,52,0,0
0,0,0,3,0,0,0,3,64,64,64,64,3,0,0,0
0,0,63,63,63,63,63,63,63,63,63,63,63,63,0,0
0,0,0,0,0,0,0,0,0,0,0,0,0,0,0,0
0,0,0,0,0,0,0,0,0,0,0,0,0,0,0,0
0,0,0,0,0,0,0,0,0,0,0,0,0,0,0,0
0,0,0,0,0,0,0,0,0,0,0,0,0,0,0,0
0,0,0,0,0,0,0,0,0,0,0,0,0,0,0,0
0,0,0,0,0,0,0,0,0,0,0,0,0,0,0,0
0,0,0,0,0,0,0,0,0,0,0,0,0,0,0,0
0,0,0,0,0,0,0,0,0,0,0,0,0,0,0,0
0,0,0,0,0,0,0,0,0,0,0,0,0,0,0,0
0,0,0,0,0,0,0,0,0,0,0,0,0,0,0,0
0,0,0,0,0,0,0,0,0,0,0,0,0,0,0,0
0,0,0,47,3,3,41,41,3,3,50,0,0,0,0,0
0,0,0,45,0,0,0,0,0,0,46,0,0,0,0,0
0,0,0,45,0,0,0,0,0,0,46,0,0,0,0,0
0,0,0,45,0,0,0,0,0,0,46,0,0,0,0,0
0,0,0,45,0,0,0,0,0,0,46,0,0,0,0,0
0,0,0,45,0,0,0,0,0,0,46,0,0,0,0,0
0,0,0,45,0,0,0,0,0,0,46,0,0,0,0,0
0,0,0,45,0,0,0,0,0,0,46,0,0,0,0,0
0,0,0,45,0,0,0,0,0,0,46,0,0,0,0,0
0,0,0,3,3,3,61,61,3,3,50,0,0,0,0,0
0,0,0,0,0,0,0,0,0,0,0,0,0,0,0,0
0,0,0,0,0,0,0,0,0,0,0,0,0,0,0,0
0,0,0,0,0,0,0,0,0,0,0,0,0,0,0,0
0,0,0,0,0,0,0,0,0,0,0,0,0,0,0,0
0,0,0,0,0,0,0,0,0,0,0,0,0,0,0,0
0,0,0,0,0,0,0,0,0,0,0,0,0,0,0,0
0,0,0,0,0,0,0,0,0,0,0,0,0,0,0,0
0,0,0,0,0,0,0,0,0,0,0,0,0,0,0,0
:endlayer
layer: 9
0,0,0,0,0,0,0,0,0,0,0,0,0,0,0,0
0,0,0,0,0,0,0,0,0,0,0,0,0,0,0,0
0,0,0,0,0,0,0,0,0,0,3,0,0,0,0,0
0,0,0,0,0,0,0,0,0,0,0,0,0,0,0,0
0,0,0,0,0,0,0,0,0,0,0,0,0,0,0,0
0,0,23,23,23,23,23,23,23,23,23,23,23,23,0,0
0,0,65,3,57,57,57,3,57,57,57,57,3,65,0,0
0,0,63,63,63,63,63,63,63,63,63,63,63,63,0,0
0,0,0,0,0,0,0,0,0,0,0,0,0,0,0,0
0,0,0,0,0,0,0,0,0,0,0,0,0,0,0,0
0,0,0,0,0,0,0,0,0,0,0,0,0,0,0,0
0,0,0,0,0,0,0,0,0,0,0,0,0,0,0,0
0,0,0,0,0,0,0,0,0,0,0,0,0,0,0,0
0,0,0,0,0,0,0,0,0,0,0,0,0,0,0,0
0,0,0,0,0,0,0,0,0,0,0,0,0,0,0,0
0,0,0,0,0,0,0,0,0,0,0,0,0,0,0,0
0,0,0,0,0,0,0,0,0,0,0,0,0,0,0,0
0,0,0,0,0,0,0,0,0,0,0,0,0,0,0,0
0,0,0,0,0,0,0,0,0,0,0,0,0,0,0,0
0,0,0,0,0,0,0,0,0,0,0,0,0,0,0,0
0,0,0,0,47,3,3,3,3,50,0,0,0,0,0,0
0,0,0,0,45,0,0,0,0,46,0,0,0,0,0,0
0,0,0,0,45,0,0,0,0,46,0,0,0,0,0,0
0,0,0,0,45,0,0,0,0,46,0,0,0,0,0,0
0,0,0,0,45,0,0,0,0,46,0,0,0,0,0,0
0,0,0,0,45,0,0,0,0,46,0,0,0,0,0,0
0,0,0,0,45,0,0,0,0,46,0,0,0,0,0,0
0,0,0,0,45,0,0,0,0,46,0,0,0,0,0,0
0,0,0,0,45,0,0,0,0,46,0,0,0,0,0,0
0,0,0,0,47,3,3,3,3,50,0,0,0,0,0,0
0,0,0,0,0,0,0,0,0,0,0,0,0,0,0,0
0,0,0,0,0,0,0,0,0,0,0,0,0,0,0,0
0,0,0,0,0,0,0,0,0,0,0,0,0,0,0,0
0,0,0,0,0,0,0,0,0,0,0,0,0,0,0,0
0,0,0,0,0,0,0,0,0,0,0,0,0,0,0,0
0,0,0,0,0,0,0,0,0,0,0,0,0,0,0,0
0,0,0,0,0,0,0,0,0,0,0,0,0,0,0,0
0,0,0,0,0,0,0,0,0,0,0,0,0,0,0,0
:endlayer
layer: 10
0,0,0,0,0,0,0,0,0,0,0,0,0,0,0,0
0,0,0,0,0,0,0,0,0,0,0,0,0,0,0,0
0,0,0,0,0,0,0,0,0,0,66,0,0,0,0,0
0,0,0,0,0,0,0,0,0,0,0,0,0,0,0,0
0,0,0,0,0,0,0,0,0,0,0,0,0,0,0,0
0,0,0,0,0,0,0,0,0,0,0,0,0,0,0,0
0,0,0,3,67,67,67,3,67,67,67,67,3,0,0,0
0,0,0,0,0,0,0,0,0,0,0,0,0,0,0,0
0,0,0,0,0,0,0,0,0,0,0,0,0,0,0,0
0,0,0,0,0,0,0,0,0,0,0,0,0,0,0,0
0,0,0,0,0,0,0,0,0,0,0,0,0,0,0,0
0,0,0,0,0,0,0,0,0,0,0,0,0,0,0,0
0,0,0,0,0,0,0,0,0,0,0,0,0,0,0,0
0,0,0,0,0,0,0,0,0,0,0,0,0,0,0,0
0,0,0,0,0,0,0,0,0,0,0,0,0,0,0,0
0,0,0,0,0,0,0,0,0,0,0,0,0,0,0,0
0,0,0,0,0,0,0,0,0,0,0,0,0,0,0,0
0,0,0,0,0,0,0,0,0,0,0,0,0,0,0,0
0,0,0,0,0,0,0,0,0,0,0,0,0,0,0,0
0,0,0,0,0,0,0,0,0,0,0,0,0,0,0,0
0,0,0,0,0,47,3,3,50,0,0,0,0,0,0,0
0,0,0,0,0,45,0,0,46,0,0,0,0,0,0,0
0,0,0,0,0,45,0,0,46,0,0,0,0,0,0,0
0,0,0,0,0,45,0,0,46,0,0,0,0,0,0,0
0,0,0,0,0,45,0,0,46,0,0,0,0,0,0,0
0,0,0,0,0,45,0,0,46,0,0,0,0,0,0,0
0,0,0,0,0,45,0,0,46,0,0,0,0,0,0,0
0,0,0,0,0,45,0,0,46,0,0,0,0,0,0,0
0,0,0,0,0,45,0,0,46,0,0,0,0,0,0,0
0,0,0,0,0,47,3,3,3,0,0,0,0,0,0,0
0,0,0,0,0,0,0,0,0,0,0,0,0,0,0,0
0,0,0,0,0,0,0,0,0,0,0,0,0,0,0,0
0,0,0,0,0,0,0,0,0,0,0,0,0,0,0,0
0,0,0,0,0,0,0,0,0,0,0,0,0,0,0,0
0,0,0,0,0,0,0,0,0,0,0,0,0,0,0,0
0,0,0,0,0,0,0,0,0,0,0,0,0,0,0,0
0,0,0,0,0,0,0,0,0,0,0,0,0,0,0,0
0,0,0,0,0,0,0,0,0,0,0,0,0,0,0,0
:endlayer
layer: 11
0,0,0,0,0,0,0,0,0,0,0,0,0,0,0,0
0,0,0,0,0,0,0,0,0,0,0,0,0,0,0,0
0,0,0,0,0,0,0,0,0,0,0,0,0,0,0,0
0,0,0,0,0,0,0,0,0,0,0,0,0,0,0,0
0,0,0,0,0,0,0,0,0,0,0,0,0,0,0,0
0,0,0,0,0,0,0,0,0,0,0,0,0,0,0,0
0,0,0,3,0,0,0,3,0,0,0,0,3,0,0,0
0,0,0,0,0,0,0,0,0,0,0,0,0,0,0,0
0,0,0,0,0,0,0,0,0,0,0,0,0,0,0,0
0,0,0,0,0,0,0,0,0,0,0,0,0,0,0,0
0,0,0,0,0,0,0,0,0,0,0,0,0,0,0,0
0,0,0,0,0,0,0,0,0,0,0,0,0,0,0,0
0,0,0,0,0,0,0,0,0,0,0,0,0,0,0,0
0,0,0,0,0,0,0,0,0,0,0,0,0,0,0,0
0,0,0,0,0,0,0,0,0,0,0,0,0,0,0,0
0,0,0,0,0,0,0,0,0,0,0,0,0,0,0,0
0,0,0,0,0,0,0,0,0,0,0,0,0,0,0,0
0,0,0,0,0,0,0,0,0,0,0,0,0,0,0,0
0,0,0,0,0,0,0,0,0,0,0,0,0,0,0,0
0,0,0,0,0,0,0,0,0,0,0,0,0,0,0,0
0,0,0,0,0,0,47,50,0,0,0,0,0,0,0,0
0,0,0,0,0,0,45,46,0,0,0,0,0,0,0,0
0,0,0,0,0,0,45,46,0,0,0,0,0,0,0,0
0,0,0,0,0,0,45,46,0,0,0,0,0,0,0,0
0,0,0,0,0,0,45,46,0,0,0,0,0,0,0,0
0,0,0,0,0,0,45,46,0,0,0,0,0,0,0,0
0,0,0,0,0,0,45,46,0,0,0,0,0,0,0,0
0,0,0,0,0,0,45,46,0,0,0,0,0,0,0,0
0,0,0,0,0,0,45,46,0,0,0,0,0,0,0,0
0,0,0,0,0,0,47,50,0,0,0,0,0,0,0,0
0,0,0,0,0,0,0,0,0,0,0,0,0,0,0,0
0,0,0,0,0,0,0,0,0,0,0,0,0,0,0,0
0,0,0,0,0,0,0,0,0,0,0,0,0,0,0,0
0,0,0,0,0,0,0,0,0,0,0,0,0,0,0,0
0,0,0,0,0,0,0,0,0,0,0,0,0,0,0,0
0,0,0,0,0,0,0,0,0,0,0,0,0,0,0,0
0,0,0,0,0,0,0,0,0,0,0,0,0,0,0,0
0,0,0,0,0,0,0,0,0,0,0,0,0,0,0,0
:endlayer
layer: 12
0,0,0,0,0,0,0,0,0,0,0,0,0,0,0,0
0,0,0,0,0,0,0,0,0,0,0,0,0,0,0,0
0,0,0,0,0,0,0,0,0,0,0,0,0,0,0,0
0,0,0,0,0,0,0,0,0,0,0,0,0,0,0,0
0,0,0,0,0,0,0,0,0,0,0,0,0,0,0,0
0,0,0,0,0,0,0,0,0,0,0,0,0,0,0,0
0,0,0,20,0,0,0,20,0,0,0,0,20,0,0,0
0,0,0,0,0,0,0,0,0,0,0,0,0,0,0,0
0,0,0,0,0,0,0,0,0,0,0,0,0,0,0,0
0,0,0,0,0,0,0,0,0,0,0,0,0,0,0,0
0,0,0,0,0,0,0,0,0,0,0,0,0,0,0,0
0,0,0,0,0,0,0,0,0,0,0,0,0,0,0,0
0,0,0,0,0,0,0,0,0,0,0,0,0,0,0,0
0,0,0,0,0,0,0,0,0,0,0,0,0,0,0,0
0,0,0,0,0,0,0,0,0,0,0,0,0,0,0,0
0,0,0,0,0,0,0,0,0,0,0,0,0,0,0,0
0,0,0,0,0,0,0,0,0,0,0,0,0,0,0,0
0,0,0,0,0,0,0,0,0,0,0,0,0,0,0,0
0,0,0,0,0,0,0,0,0,0,0,0,0,0,0,0
0,0,0,0,0,0,0,0,0,0,0,0,0,0,0,0
0,0,0,0,0,0,0,0,0,0,0,0,0,0,0,0
0,0,0,0,0,0,0,0,0,0,0,0,0,0,0,0
0,0,0,0,0,0,0,0,0,0,0,0,0,0,0,0
0,0,0,0,0,0,0,0,0,0,0,0,0,0,0,0
0,0,0,0,0,0,0,0,0,0,0,0,0,0,0,0
0,0,0,0,0,0,0,0,0,0,0,0,0,0,0,0
0,0,0,0,0,0,0,0,0,0,0,0,0,0,0,0
0,0,0,0,0,0,0,0,0,0,0,0,0,0,0,0
0,0,0,0,0,0,0,0,0,0,0,0,0,0,0,0
0,0,0,0,0,0,0,0,0,0,0,0,0,0,0,0
0,0,0,0,0,0,0,0,0,0,0,0,0,0,0,0
0,0,0,0,0,0,0,0,0,0,0,0,0,0,0,0
0,0,0,0,0,0,0,0,0,0,0,0,0,0,0,0
0,0,0,0,0,0,0,0,0,0,0,0,0,0,0,0
0,0,0,0,0,0,0,0,0,0,0,0,0,0,0,0
0,0,0,0,0,0,0,0,0,0,0,0,0,0,0,0
0,0,0,0,0,0,0,0,0,0,0,0,0,0,0,0
0,0,0,0,0,0,0,0,0,0,0,0,0,0,0,0
:endlayer

#### RULES ####
rule:
plugin=vanillaBlocks
number=1
data:
JSON:{blockState:{blockName:"minecraft:dirt",properties:{variant:"dirt",snowy:"false"}}}
:enddata
:endrule

rule:
plugin=vanillaBlocks
number=2
data:
JSON:{blockState:{blockName:"minecraft:grass",properties:{snowy:"false"}}}
:enddata
:endrule

rule:
plugin=vanillaBlocks
number=3
data:
JSON:{blockState:{blockName:"minecraft:stonebrick",properties:{variant:"stonebrick"}}}
:enddata
:endrule

rule:
plugin=vanillaBlocks
number=4
data:
JSON:{blockState:{blockName:"minecraft:double_stone_slab",properties:{seamless:"false",variant:"stone_brick"}}}
:enddata
:endrule

rule:
plugin=vanillaBlocks
number=5
data:
JSON:{blockState:{blockName:"minecraft:stone",properties:{variant:"stone"}}}
:enddata
:endrule

rule:
plugin=vanillaBlocks
number=6
data:
JSON:{blockState:{blockName:"minecraft:stone_slab",properties:{half:"top",variant:"stone"}}}
:enddata
:endrule

rule:
plugin=vanillaBlocks
number=7
data:
JSON:{blockState:{blockName:"minecraft:wool",properties:{color:"red"}}}
:enddata
:endrule

rule:
plugin=vanillaBlocks
number=8
data:
JSON:{blockState:{blockName:"minecraft:cobblestone"}}
:enddata
:endrule

rule:
plugin=vanillaBlocks
number=9
data:
JSON:{blockState:{blockName:"minecraft:gravel"}}
:enddata
:endrule

rule:
plugin=vanillaBlocks
number=10
data:
JSON:{blockState:{blockName:"minecraft:tallgrass",properties:{type:"tall_grass"}}}
:enddata
:endrule

rule:
plugin=vanillaBlocks
number=11
data:
JSON:{blockState:{blockName:"minecraft:red_flower",properties:{type:"orange_tulip"}}}
:enddata
:endrule

rule:
plugin=vanillaBlocks
number=12
data:
JSON:{blockState:{blockName:"minecraft:yellow_flower",properties:{type:"dandelion"}}}
:enddata
:endrule

rule:
plugin=vanillaBlocks
number=13
data:
JSON:{blockState:{blockName:"minecraft:red_flower",properties:{type:"oxeye_daisy"}}}
:enddata
:endrule

rule:
plugin=vanillaBlocks
number=14
data:
JSON:{blockState:{blockName:"minecraft:stone_brick_stairs",properties:{half:"bottom",shape:"straight",facing:"north"}}}
:enddata
:endrule

rule:
plugin=vanillaBlocks
number=15
data:
JSON:{blockState:{blockName:"minecraft:red_flower",properties:{type:"houstonia"}}}
:enddata
:endrule

rule:
plugin=vanillaBlocks
number=16
data:
JSON:{blockState:{blockName:"minecraft:red_flower",properties:{type:"pink_tulip"}}}
:enddata
:endrule

rule:
plugin=vanillaBlocks
number=17
data:
JSON:{blockState:{blockName:"minecraft:stone_slab",properties:{half:"bottom",variant:"stone"}}}
:enddata
:endrule

rule:
plugin=vanillaBlocks
number=18
data:
JSON:{blockState:{blockName:"minecraft:double_stone_slab",properties:{seamless:"false",variant:"stone"}}}
:enddata
:endrule

rule:
plugin=vanillaBlocks
number=19
data:
JSON:{blockState:{blockName:"minecraft:cauldron",properties:{level:"3"}}}
:enddata
:endrule

rule:
plugin=vanillaBlocks
number=20
data:
JSON:{blockState:{blockName:"minecraft:torch",properties:{facing:"up"}}}
:enddata
:endrule

rule:
plugin=blockTile
number=21
data:
JSON:{blockState:{blockName:"ancientwarfarestructure:advanced_spawner",properties:{transparent:"true"}},teData:{id:"ancientwarfarestructure:advanced_spawner_tile",spawnerSettings:{minDelay:0,spawnDelay:0,lightSensitive:0b,spawnGroups:[{settingsList:[{remainingSpawnCount:1,hostile:1b,forced:1b,customTag:{ArmorDropChances:[1.0f,1.0f,1.0f,1.0f],ArmorItems:[{},{},{},{}],HandDropChances:[1.0f,1.0f],factionName:"empire",HandItems:[{},{}]},maxToSpawn:1,entityId:"ancientwarfarenpc:faction.civilian.male",minToSpawn:1}],groupWeight:1}],playerRange:16,respondToRedstone:0b,inventory:{Size:9,Items:[]},spawnRange:0,transparent:1b,maxDelay:0,xpToDrop:0,mobRange:0,debugMode:0b,maxNearbyMonsters:0}}}
:enddata
:endrule

rule:
plugin=blockTile
number=22
data:
JSON:{blockState:{blockName:"ancientwarfarestructure:advanced_spawner",properties:{transparent:"true"}},teData:{id:"ancientwarfarestructure:advanced_spawner_tile",spawnerSettings:{minDelay:0,spawnDelay:0,lightSensitive:0b,spawnGroups:[{settingsList:[{remainingSpawnCount:1,hostile:1b,forced:1b,customTag:{ArmorDropChances:[1.0f,1.0f,1.0f,1.0f],ArmorItems:[{},{},{},{}],HandDropChances:[1.0f,1.0f],factionName:"empire",HandItems:[{},{}]},maxToSpawn:1,entityId:"ancientwarfarenpc:faction.civilian.male",minToSpawn:1}],groupWeight:1}],playerRange:16,respondToRedstone:0b,inventory:{Size:9,Items:[]},spawnRange:0,transparent:1b,maxDelay:0,xpToDrop:0,mobRange:0,debugMode:0b,maxNearbyMonsters:0}}}
:enddata
:endrule

rule:
plugin=vanillaBlocks
number=23
data:
JSON:{blockState:{blockName:"minecraft:oak_stairs",properties:{half:"bottom",shape:"straight",facing:"south"}}}
:enddata
:endrule

rule:
plugin=blockTile
number=24
data:
JSON:{blockState:{blockName:"ancientwarfarestructure:advanced_spawner",properties:{transparent:"true"}},teData:{id:"ancientwarfarestructure:advanced_spawner_tile",spawnerSettings:{minDelay:0,spawnDelay:0,lightSensitive:0b,spawnGroups:[{settingsList:[{remainingSpawnCount:1,hostile:1b,forced:1b,customTag:{ArmorDropChances:[1.0f,1.0f,1.0f,1.0f],ArmorItems:[{},{},{},{}],HandDropChances:[1.0f,1.0f],factionName:"empire",HandItems:[{},{}]},maxToSpawn:1,entityId:"ancientwarfarenpc:faction.civilian.female",minToSpawn:1}],groupWeight:1}],playerRange:16,respondToRedstone:0b,inventory:{Size:9,Items:[]},spawnRange:0,transparent:1b,maxDelay:0,xpToDrop:0,mobRange:0,debugMode:0b,maxNearbyMonsters:0}}}
:enddata
:endrule

rule:
plugin=blockTile
number=25
data:
JSON:{blockState:{blockName:"ancientwarfarestructure:advanced_spawner",properties:{transparent:"true"}},teData:{id:"ancientwarfarestructure:advanced_spawner_tile",spawnerSettings:{minDelay:0,spawnDelay:0,lightSensitive:0b,spawnGroups:[{settingsList:[{remainingSpawnCount:1,hostile:1b,forced:1b,customTag:{ArmorDropChances:[1.0f,1.0f,1.0f,1.0f],ArmorItems:[{},{},{},{}],HandDropChances:[1.0f,1.0f],factionName:"empire",HandItems:[{},{}]},maxToSpawn:1,entityId:"ancientwarfarenpc:faction.civilian.female",minToSpawn:1}],groupWeight:1}],playerRange:16,respondToRedstone:0b,inventory:{Size:9,Items:[]},spawnRange:0,transparent:1b,maxDelay:0,xpToDrop:0,mobRange:0,debugMode:0b,maxNearbyMonsters:0}}}
:enddata
:endrule

rule:
plugin=blockTile
number=26
data:
JSON:{blockState:{blockName:"ancientwarfarestructure:advanced_spawner",properties:{transparent:"true"}},teData:{id:"ancientwarfarestructure:advanced_spawner_tile",spawnerSettings:{minDelay:0,spawnDelay:0,lightSensitive:0b,spawnGroups:[{settingsList:[{remainingSpawnCount:1,hostile:1b,forced:1b,customTag:{ArmorDropChances:[1.0f,1.0f,1.0f,1.0f],ArmorItems:[{},{},{},{}],HandDropChances:[1.0f,1.0f],factionName:"empire",HandItems:[{id:"minecraft:book",Count:1b,Damage:0s},{}]},maxToSpawn:1,entityId:"ancientwarfarenpc:faction.priest",minToSpawn:1}],groupWeight:1}],playerRange:6,respondToRedstone:0b,inventory:{Size:9,Items:[]},spawnRange:0,transparent:1b,maxDelay:0,xpToDrop:0,mobRange:0,debugMode:0b,maxNearbyMonsters:0}}}
:enddata
:endrule

rule:
plugin=doors
number=27
data:
JSON:{blockState:{blockName:"minecraft:wooden_door",properties:{hinge:"left",half:"lower",powered:"false",facing:"north",open:"false"}}}
:enddata
:endrule

rule:
plugin=vanillaBlocks
number=28
data:
JSON:{blockState:{blockName:"ancientwarfarestructure:fire_pit",properties:{lit:"true",variant:"square"}}}
:enddata
:endrule

rule:
plugin=inventory
number=29
data:
JSON:{blockState:{blockName:"minecraft:furnace",properties:{facing:"south"}},lootLevel:0,teData:{CookTime:0,BurnTime:0,Items:[],id:"minecraft:furnace",CookTimeTotal:0,Lock:""},inventoryData:{length:0,inventoryContents:[]},legacyFeatures:0b}
:enddata
:endrule

rule:
plugin=vanillaBlocks
number=30
data:
JSON:{blockState:{blockName:"minecraft:crafting_table"}}
:enddata
:endrule

rule:
plugin=inventory
number=31
data:
JSON:{blockState:{blockName:"minecraft:chest",properties:{facing:"south"}},lootLevel:0,teData:{ForgeData:{},Items:[{Slot:2b,id:"minecraft:bread",Count:3b,Damage:0s},{Slot:7b,id:"minecraft:cooked_chicken",Count:1b,Damage:0s},{Slot:9b,id:"minecraft:cooked_rabbit",Count:2b,Damage:0s},{Slot:12b,id:"minecraft:bread",Count:3b,Damage:0s},{Slot:16b,id:"minecraft:cooked_chicken",Count:2b,Damage:0s},{Slot:18b,id:"minecraft:cooked_rabbit",Count:2b,Damage:0s},{Slot:21b,id:"minecraft:bread",Count:1b,Damage:0s},{Slot:23b,id:"minecraft:torch",Count:10b,Damage:0s},{Slot:25b,id:"minecraft:cooked_chicken",Count:1b,Damage:0s}],id:"minecraft:chest",Lock:""},inventoryData:{length:9,inventoryContents:[{id:"minecraft:bread",Count:3b,slot:0,Damage:0s},{id:"minecraft:cooked_chicken",Count:1b,slot:1,Damage:0s},{id:"minecraft:cooked_rabbit",Count:2b,slot:2,Damage:0s},{id:"minecraft:bread",Count:3b,slot:3,Damage:0s},{id:"minecraft:cooked_chicken",Count:2b,slot:4,Damage:0s},{id:"minecraft:cooked_rabbit",Count:2b,slot:5,Damage:0s},{id:"minecraft:bread",Count:1b,slot:6,Damage:0s},{id:"minecraft:torch",Count:10b,slot:7,Damage:0s},{id:"minecraft:cooked_chicken",Count:1b,slot:8,Damage:0s}]},legacyFeatures:1b}
:enddata
:endrule

rule:
plugin=inventory
number=32
data:
JSON:{blockState:{blockName:"minecraft:chest",properties:{facing:"south"}},lootLevel:0,teData:{ForgeData:{},Items:[{Slot:3b,id:"ancientwarfarenpc:coin",Count:1b,tag:{metal:"silver"},Damage:0s},{Slot:10b,id:"ancientwarfarenpc:coin",Count:1b,tag:{metal:"silver"},Damage:0s},{Slot:12b,id:"ancientwarfarenpc:coin",Count:1b,tag:{metal:"silver"},Damage:0s},{Slot:21b,id:"ancientwarfarenpc:coin",Count:1b,tag:{metal:"silver"},Damage:0s},{Slot:23b,id:"ancientwarfarenpc:coin",Count:4b,tag:{metal:"silver"},Damage:0s}],id:"minecraft:chest",Lock:""},inventoryData:{length:5,inventoryContents:[{id:"ancientwarfarenpc:coin",Count:1b,tag:{metal:"silver"},slot:0,Damage:0s},{id:"ancientwarfarenpc:coin",Count:1b,tag:{metal:"silver"},slot:1,Damage:0s},{id:"ancientwarfarenpc:coin",Count:1b,tag:{metal:"silver"},slot:2,Damage:0s},{id:"ancientwarfarenpc:coin",Count:1b,tag:{metal:"silver"},slot:3,Damage:0s},{id:"ancientwarfarenpc:coin",Count:4b,tag:{metal:"silver"},slot:4,Damage:0s}]},legacyFeatures:1b}
:enddata
:endrule

rule:
plugin=doors
number=33
data:
JSON:{blockState:{blockName:"minecraft:wooden_door",properties:{hinge:"left",half:"lower",powered:"false",facing:"west",open:"false"}}}
:enddata
:endrule

rule:
plugin=blockTile
number=34
data:
JSON:{blockState:{blockName:"ancientwarfarestructure:advanced_spawner",properties:{transparent:"true"}},teData:{id:"ancientwarfarestructure:advanced_spawner_tile",spawnerSettings:{minDelay:0,spawnDelay:0,lightSensitive:0b,spawnGroups:[{settingsList:[{remainingSpawnCount:1,hostile:1b,forced:1b,customTag:{ArmorDropChances:[1.0f,1.0f,1.0f,1.0f],ArmorItems:[{},{},{},{}],HandDropChances:[1.0f,1.0f],factionName:"empire",HandItems:[{id:"minecraft:book",Count:1b,Damage:0s},{}]},maxToSpawn:1,entityId:"ancientwarfarenpc:faction.priest",minToSpawn:1}],groupWeight:1}],playerRange:6,respondToRedstone:0b,inventory:{Size:9,Items:[]},spawnRange:0,transparent:1b,maxDelay:0,xpToDrop:0,mobRange:0,debugMode:0b,maxNearbyMonsters:0}}}
:enddata
:endrule

rule:
plugin=blockTile
number=35
data:
JSON:{blockState:{blockName:"ancientwarfarestructure:advanced_spawner",properties:{transparent:"true"}},teData:{id:"ancientwarfarestructure:advanced_spawner_tile",spawnerSettings:{minDelay:0,spawnDelay:0,lightSensitive:0b,spawnGroups:[{settingsList:[{remainingSpawnCount:1,hostile:1b,forced:1b,customTag:{ArmorDropChances:[1.0f,1.0f,1.0f,1.0f],ArmorItems:[{},{},{},{}],HandDropChances:[1.0f,1.0f],factionName:"witchbane",HandItems:[{id:"ancientwarfarenpc:iron_spear",Count:1b,Damage:0s},{id:"ancientwarfarenpc:iron_shield",Count:1b,Damage:0s}]},maxToSpawn:1,entityId:"ancientwarfarenpc:faction.soldier",minToSpawn:1}],groupWeight:1}],playerRange:6,respondToRedstone:0b,inventory:{Size:9,Items:[]},spawnRange:0,transparent:1b,maxDelay:0,xpToDrop:0,mobRange:0,debugMode:0b,maxNearbyMonsters:0}}}
:enddata
:endrule

rule:
plugin=bed
number=36
data:
JSON:{blockState:{blockName:"minecraft:bed",properties:{part:"foot",facing:"east",occupied:"false"}},bedColor:14}
:enddata
:endrule

rule:
plugin=bed
number=37
data:
JSON:{blockState:{blockName:"minecraft:bed",properties:{part:"head",facing:"east",occupied:"false"}},bedColor:14}
:enddata
:endrule

rule:
plugin=vanillaBlocks
number=38
data:
JSON:{blockState:{blockName:"minecraft:fence",properties:{east:"false",south:"false",north:"false",west:"false"}}}
:enddata
:endrule

rule:
plugin=vanillaBlocks
number=39
data:
JSON:{blockState:{blockName:"minecraft:bookshelf"}}
:enddata
:endrule

rule:
plugin=blockTile
number=40
data:
JSON:{blockState:{blockName:"ancientwarfarestructure:advanced_spawner",properties:{transparent:"true"}},teData:{id:"ancientwarfarestructure:advanced_spawner_tile",spawnerSettings:{minDelay:0,spawnDelay:0,lightSensitive:0b,spawnGroups:[{settingsList:[{remainingSpawnCount:1,hostile:1b,forced:1b,customTag:{ArmorDropChances:[1.0f,1.0f,1.0f,1.0f],ArmorItems:[{},{},{},{}],HandDropChances:[1.0f,1.0f],factionName:"witchbane",HandItems:[{id:"minecraft:bow",Count:1b,Damage:0s},{}]},maxToSpawn:1,entityId:"ancientwarfarenpc:faction.archer.elite",minToSpawn:1}],groupWeight:1}],playerRange:16,respondToRedstone:0b,inventory:{Size:9,Items:[]},spawnRange:0,transparent:1b,maxDelay:0,xpToDrop:0,mobRange:0,debugMode:0b,maxNearbyMonsters:0}}}
:enddata
:endrule

rule:
plugin=vanillaBlocks
number=41
data:
JSON:{blockState:{blockName:"minecraft:stained_glass_pane",properties:{east:"false",color:"light_blue",south:"false",north:"false",west:"false"}}}
:enddata
:endrule

rule:
plugin=blockTile
number=42
data:
JSON:{blockState:{blockName:"ancientwarfarestructure:advanced_spawner",properties:{transparent:"true"}},teData:{id:"ancientwarfarestructure:advanced_spawner_tile",spawnerSettings:{minDelay:0,spawnDelay:0,lightSensitive:0b,spawnGroups:[{settingsList:[{remainingSpawnCount:1,hostile:1b,forced:1b,customTag:{ArmorDropChances:[1.0f,1.0f,1.0f,1.0f],ArmorItems:[{},{},{},{}],HandDropChances:[1.0f,1.0f],factionName:"empire",HandItems:[{id:"minecraft:book",Count:1b,Damage:0s},{}]},maxToSpawn:1,entityId:"ancientwarfarenpc:faction.priest",minToSpawn:1}],groupWeight:1}],playerRange:8,respondToRedstone:0b,inventory:{Size:9,Items:[]},spawnRange:0,transparent:1b,maxDelay:0,xpToDrop:0,mobRange:0,debugMode:0b,maxNearbyMonsters:0}}}
:enddata
:endrule

rule:
plugin=vanillaBlocks
number=43
data:
JSON:{blockState:{blockName:"minecraft:dark_oak_stairs",properties:{half:"bottom",shape:"straight",facing:"east"}}}
:enddata
:endrule

rule:
plugin=vanillaBlocks
number=44
data:
JSON:{blockState:{blockName:"minecraft:dark_oak_stairs",properties:{half:"bottom",shape:"straight",facing:"west"}}}
:enddata
:endrule

rule:
plugin=vanillaBlocks
number=45
data:
JSON:{blockState:{blockName:"minecraft:oak_stairs",properties:{half:"bottom",shape:"straight",facing:"east"}}}
:enddata
:endrule

rule:
plugin=vanillaBlocks
number=46
data:
JSON:{blockState:{blockName:"minecraft:oak_stairs",properties:{half:"bottom",shape:"straight",facing:"west"}}}
:enddata
:endrule

rule:
plugin=vanillaBlocks
number=47
data:
JSON:{blockState:{blockName:"minecraft:stone_brick_stairs",properties:{half:"bottom",shape:"straight",facing:"east"}}}
:enddata
:endrule

rule:
plugin=doors
number=48
data:
JSON:{blockState:{blockName:"minecraft:wooden_door",properties:{hinge:"left",half:"upper",powered:"false",facing:"north",open:"false"}}}
:enddata
:endrule

rule:
plugin=doors
number=49
data:
JSON:{blockState:{blockName:"minecraft:wooden_door",properties:{hinge:"right",half:"upper",powered:"false",facing:"north",open:"false"}}}
:enddata
:endrule

rule:
plugin=vanillaBlocks
number=50
data:
JSON:{blockState:{blockName:"minecraft:stone_brick_stairs",properties:{half:"bottom",shape:"straight",facing:"west"}}}
:enddata
:endrule

rule:
plugin=vanillaBlocks
number=51
data:
JSON:{blockState:{blockName:"minecraft:torch",properties:{facing:"west"}}}
:enddata
:endrule

rule:
plugin=vanillaBlocks
number=52
data:
JSON:{blockState:{blockName:"minecraft:torch",properties:{facing:"east"}}}
:enddata
:endrule

rule:
plugin=vanillaSign
number=53
data:
JSON:{signContents0:"",blockState:{blockName:"minecraft:wall_sign",properties:{facing:"south"}},signContents2:"Chapel§r§r",signContents1:"Goodly§r§r",signContents3:"",rotation:0}
:enddata
:endrule

rule:
plugin=vanillaBlocks
number=54
data:
JSON:{blockState:{blockName:"minecraft:glass_pane",properties:{east:"false",south:"false",north:"false",west:"false"}}}
:enddata
:endrule

rule:
plugin=vanillaBlocks
number=55
data:
JSON:{blockState:{blockName:"minecraft:wooden_pressure_plate",properties:{powered:"false"}}}
:enddata
:endrule

rule:
plugin=vanillaBlocks
number=56
data:
JSON:{blockState:{blockName:"minecraft:stained_glass_pane",properties:{east:"false",color:"cyan",south:"false",north:"false",west:"false"}}}
:enddata
:endrule

rule:
plugin=vanillaBlocks
number=57
data:
JSON:{blockState:{blockName:"minecraft:planks",properties:{variant:"oak"}}}
:enddata
:endrule

rule:
plugin=vanillaBlocks
number=58
data:
JSON:{blockState:{blockName:"minecraft:torch",properties:{facing:"south"}}}
:enddata
:endrule

rule:
plugin=vanillaBlocks
number=59
data:
JSON:{blockState:{blockName:"minecraft:torch",properties:{facing:"north"}}}
:enddata
:endrule

rule:
plugin=vanillaBlocks
number=60
data:
JSON:{blockState:{blockName:"minecraft:stone_brick_stairs",properties:{half:"bottom",shape:"straight",facing:"south"}}}
:enddata
:endrule

rule:
plugin=vanillaBlocks
number=61
data:
JSON:{blockState:{blockName:"minecraft:stained_glass_pane",properties:{east:"false",color:"yellow",south:"false",north:"false",west:"false"}}}
:enddata
:endrule

rule:
plugin=vanillaBlocks
number=62
data:
JSON:{blockState:{blockName:"minecraft:stone_brick_stairs",properties:{half:"top",shape:"straight",facing:"north"}}}
:enddata
:endrule

rule:
plugin=vanillaBlocks
number=63
data:
JSON:{blockState:{blockName:"minecraft:oak_stairs",properties:{half:"bottom",shape:"straight",facing:"north"}}}
:enddata
:endrule

rule:
plugin=vanillaBlocks
number=64
data:
JSON:{blockState:{blockName:"minecraft:wooden_slab",properties:{half:"top",variant:"jungle"}}}
:enddata
:endrule

rule:
plugin=vanillaBlocks
number=65
data:
JSON:{blockState:{blockName:"minecraft:wooden_slab",properties:{half:"top",variant:"oak"}}}
:enddata
:endrule

rule:
plugin=vanillaBlocks
number=66
data:
JSON:{blockState:{blockName:"minecraft:cobblestone_wall",properties:{east:"false",south:"false",north:"false",variant:"cobblestone",west:"false",up:"false"}}}
:enddata
:endrule

rule:
plugin=vanillaBlocks
number=67
data:
JSON:{blockState:{blockName:"minecraft:wooden_slab",properties:{half:"bottom",variant:"oak"}}}
:enddata
:endrule

#### ENTITIES ####
