# Ancient Warfare Structure Template File
# Auto-generated structure template file. created on: 8/19/2019 at: 10:23:10
# Lines beginning with # denote comments

header:
version=2.9
name=EmpireMarquisCastle
mods=
size=31,42,31
offset=10,8,30
:endheader

#### VALIDATION ####
validation:
type=ground
survival=false
worldGenEnabled=true
unique=false
preserveBlocks=false
selectionWeight=300
clusterValue=251
minDuplicateDistance=1000
dimensionWhiteList=true
dimensionList=0
biomeWhiteList=true
biomeList=biomesoplenty:meadow,minecraft:forest,traverse:meadow,minecraft:birch_forest,minecraft:plains,minecraft:birch_forest_hills,minecraft:smaller_extreme_hills
leveling=12
fill=12
border=12
blockSwap=false
:endvalidation

#### LAYERS ####
layer: 0
1,1,1,1,1,1,1,1,1,1,1,1,1,1,1,1,1,1,1,1,1,1,1,1,1,1,1,1,1,1,1
1,1,1,1,1,1,1,1,1,1,1,1,1,1,1,1,1,1,1,1,1,1,1,1,1,1,1,1,1,1,1
1,1,1,1,1,1,1,1,1,1,1,1,1,1,1,1,1,1,1,1,1,1,1,1,1,1,1,1,1,1,1
1,1,1,1,1,1,1,1,1,1,1,1,1,1,1,1,1,1,1,1,1,1,1,1,1,1,1,1,1,1,1
1,1,1,1,1,1,1,1,1,1,1,1,1,1,1,1,1,1,1,1,1,1,1,1,1,1,1,1,1,1,1
1,1,1,1,1,1,1,1,1,1,1,1,1,1,1,1,1,1,1,1,1,1,1,1,1,1,1,1,1,1,1
1,1,1,1,1,1,1,1,1,1,1,1,1,1,1,1,1,1,1,1,1,1,1,1,1,1,1,1,1,1,1
1,1,1,1,1,1,1,1,1,1,1,1,1,1,1,1,1,1,1,1,1,1,1,1,1,1,1,1,1,1,1
1,1,1,1,1,1,1,1,1,1,1,1,1,1,1,1,1,1,1,1,1,1,1,1,1,1,1,1,1,1,1
1,1,1,1,1,1,1,1,1,1,1,1,1,1,1,1,1,1,1,1,1,1,1,1,1,1,1,1,1,1,1
1,1,1,1,1,1,1,1,1,1,1,1,1,1,1,1,1,1,1,1,1,1,1,1,1,1,1,1,1,1,1
1,1,1,1,1,1,1,1,1,1,1,1,1,1,1,1,1,1,1,1,1,1,1,1,1,1,1,1,1,1,1
1,1,1,1,1,1,1,1,1,1,1,1,1,1,1,1,1,1,1,1,1,1,1,1,1,1,1,1,1,1,1
1,1,1,1,1,1,1,1,1,1,1,1,1,1,1,1,1,1,1,1,1,1,1,1,1,1,1,1,1,1,1
1,1,1,1,1,1,1,1,1,1,1,1,1,1,1,1,1,1,1,1,1,1,1,1,1,1,1,1,1,1,1
1,1,1,1,1,1,1,1,1,1,1,1,1,1,1,1,1,1,1,1,1,1,1,1,1,1,1,1,1,1,1
1,1,1,1,1,1,1,1,1,1,1,1,1,1,1,1,1,1,1,1,1,1,1,1,1,1,1,1,1,1,1
1,1,1,1,1,1,1,1,1,1,1,1,1,1,1,1,1,1,1,1,1,1,1,1,1,1,1,1,1,1,1
1,1,1,1,1,1,1,1,1,1,1,1,1,1,1,1,1,1,1,1,1,1,1,1,1,1,1,1,1,1,1
1,1,1,1,1,1,1,1,1,1,1,1,1,1,1,1,1,1,1,1,1,1,1,1,1,1,1,1,1,1,1
1,1,1,1,1,1,1,1,1,1,1,1,1,1,1,1,1,1,1,1,1,1,1,1,1,1,1,1,1,1,1
1,1,1,1,1,1,1,1,1,1,1,1,1,1,1,1,1,1,1,1,1,1,1,1,1,1,1,1,1,1,1
1,1,1,1,1,1,1,1,1,1,1,1,1,1,1,1,1,1,1,1,1,1,1,1,1,1,1,1,1,1,1
1,1,1,1,1,1,1,1,1,1,1,1,1,1,1,1,1,1,1,1,1,1,1,1,1,1,1,1,1,1,1
1,1,1,1,1,1,1,1,1,1,1,1,1,1,1,1,1,1,1,1,1,1,1,1,1,1,1,1,1,1,1
1,1,1,1,1,1,1,1,1,1,1,1,1,1,1,1,1,1,1,1,1,1,1,1,1,1,1,1,1,1,1
1,1,1,1,1,1,1,1,1,1,1,1,1,1,1,1,1,1,1,1,1,1,1,1,1,1,1,1,1,1,1
1,1,1,1,1,1,1,1,1,1,1,1,1,1,1,1,1,1,1,1,1,1,1,1,1,1,1,1,1,1,1
1,1,1,1,1,1,1,1,1,1,1,1,1,1,1,1,1,1,1,1,1,1,1,1,1,1,1,1,1,1,1
1,1,1,1,1,1,1,1,1,1,1,1,1,1,1,1,1,1,1,1,1,1,1,1,1,1,1,1,1,1,1
1,1,1,1,1,1,1,1,1,1,1,1,1,1,1,1,1,1,1,1,1,1,1,1,1,1,1,1,1,1,1
:endlayer
layer: 1
1,1,1,1,1,1,1,1,1,1,1,1,1,1,1,1,1,1,1,1,1,1,1,1,1,1,1,1,1,1,1
1,1,1,1,1,1,1,1,1,1,1,1,1,1,1,1,1,1,1,1,1,1,1,1,1,1,1,1,1,1,1
1,1,1,1,1,1,1,1,1,1,1,1,1,1,1,1,1,1,1,1,1,1,1,1,1,1,1,1,1,1,1
1,1,1,1,1,1,1,1,1,1,1,1,1,1,1,1,1,1,1,1,1,1,1,1,1,1,1,1,1,1,1
1,1,1,1,1,1,1,1,1,1,1,1,1,1,1,1,1,1,1,1,1,1,1,1,1,1,1,1,1,1,1
1,1,1,1,1,1,1,1,1,1,1,1,1,1,1,1,1,1,1,1,1,1,1,1,1,1,1,1,1,1,1
1,1,1,1,1,1,1,1,1,1,1,1,1,1,1,1,1,1,1,1,1,1,1,1,1,1,1,1,1,1,1
1,1,1,1,1,1,1,1,1,1,1,1,1,1,1,1,1,1,1,1,1,1,1,1,1,1,1,1,1,1,1
1,1,1,1,1,1,1,1,1,1,1,1,1,1,1,1,1,1,1,1,1,1,1,1,1,1,1,1,1,1,1
1,1,1,1,1,1,1,1,1,1,1,1,1,1,1,1,1,1,1,1,1,1,1,1,1,1,1,1,1,1,1
1,1,1,1,1,1,1,1,1,1,1,1,1,1,1,1,1,1,1,1,1,1,1,1,1,1,1,1,1,1,1
1,1,1,1,1,1,1,1,1,1,1,1,1,1,1,1,1,1,1,1,1,1,1,1,1,1,1,1,1,1,1
1,1,1,1,1,1,1,1,1,1,1,1,1,1,1,1,1,1,1,1,1,1,1,1,1,1,1,1,1,1,1
1,1,1,1,1,1,1,1,1,1,1,1,1,1,1,1,1,1,1,1,1,1,1,1,1,1,1,1,1,1,1
1,1,1,1,1,1,1,1,1,1,1,1,1,1,1,1,1,1,1,1,1,1,1,1,1,1,1,1,1,1,1
1,1,1,1,1,1,1,1,1,1,1,1,1,1,1,1,1,1,1,1,1,1,1,1,1,1,1,1,1,1,1
1,1,1,1,1,1,1,1,1,1,1,1,1,1,1,1,1,1,1,1,1,1,1,1,1,1,1,1,1,1,1
1,1,1,1,1,1,1,1,1,1,1,1,1,1,1,1,1,1,1,1,1,1,1,1,1,1,1,1,1,1,1
1,1,1,1,1,1,1,1,1,1,1,1,1,1,1,1,1,1,1,1,1,1,1,1,1,1,1,1,1,1,1
1,1,1,1,1,1,1,1,1,1,1,1,1,1,1,1,1,1,1,1,1,1,1,1,1,1,1,1,1,1,1
1,1,1,1,1,1,1,1,1,1,1,1,1,1,1,1,1,1,1,1,1,1,1,1,1,1,1,1,1,1,1
1,1,1,1,1,1,1,1,1,1,1,1,1,1,1,1,1,1,1,1,1,1,1,1,1,1,1,1,1,1,1
1,1,1,1,1,1,1,1,1,1,1,1,1,1,1,1,1,1,1,1,1,1,1,1,1,1,1,1,1,1,1
1,1,1,1,1,1,1,1,1,1,1,1,1,1,1,1,1,1,1,1,1,1,1,1,1,1,1,1,1,1,1
1,1,1,1,1,1,1,1,1,1,1,1,1,1,1,1,1,1,1,1,1,1,1,1,1,1,1,1,1,1,1
1,1,1,1,1,1,1,1,1,1,1,1,1,1,1,1,1,1,1,1,1,1,1,1,1,1,1,1,1,1,1
1,1,1,1,1,1,1,1,1,1,1,1,1,1,1,1,1,1,1,1,1,1,1,1,1,1,1,1,1,1,1
1,1,1,1,1,1,1,1,1,1,1,1,1,1,1,1,1,1,1,1,1,1,1,1,1,1,1,1,1,1,1
1,1,1,1,1,1,1,1,1,1,1,1,1,1,1,1,1,1,1,1,1,1,1,1,1,1,1,1,1,1,1
1,1,1,1,1,1,1,1,1,1,1,1,1,1,1,1,1,1,1,1,1,1,1,1,1,1,1,1,1,1,1
1,1,1,1,1,1,1,1,1,1,1,1,1,1,1,1,1,1,1,1,1,1,1,1,1,1,1,1,1,1,1
:endlayer
layer: 2
1,1,1,1,1,1,1,1,1,1,1,1,1,1,1,1,1,1,1,1,1,1,1,1,1,1,1,1,1,1,1
1,1,1,1,1,1,1,1,1,1,1,1,1,1,1,1,1,1,1,1,1,1,1,1,1,1,1,1,1,1,1
1,1,1,1,1,1,1,1,1,1,1,1,1,1,1,1,1,1,1,1,1,1,1,1,1,1,1,1,1,1,1
1,1,1,1,1,1,1,1,1,1,1,1,1,1,1,1,1,1,1,1,1,1,1,1,1,1,1,1,1,1,1
1,1,1,1,1,1,1,1,1,1,1,1,1,1,1,1,1,1,1,1,1,1,1,1,1,1,1,1,1,1,1
1,1,1,1,1,1,1,1,1,1,1,1,1,1,1,1,1,1,1,1,1,1,1,1,1,1,1,1,1,1,1
1,1,1,1,1,1,1,1,1,1,1,1,1,1,1,1,1,1,1,1,1,1,1,1,1,1,1,1,1,1,1
1,1,1,1,1,1,1,1,1,1,1,1,1,1,1,1,1,1,1,1,1,1,1,1,1,1,1,1,1,1,1
1,1,1,1,1,1,1,1,1,1,1,1,1,1,1,1,1,1,1,1,1,1,1,1,1,1,1,1,1,1,1
1,1,1,1,1,1,1,1,1,1,1,1,1,1,1,1,1,1,1,1,1,1,1,1,1,1,1,1,1,1,1
1,1,1,1,1,1,1,1,1,1,1,1,1,1,1,1,1,1,1,1,1,1,1,1,1,1,1,1,1,1,1
1,1,1,1,1,1,1,1,1,1,1,1,1,1,1,1,1,1,1,1,1,1,1,1,1,1,1,1,1,1,1
1,1,1,1,1,1,1,1,1,1,1,1,1,1,1,1,1,1,1,1,1,1,1,1,1,1,1,1,1,1,1
1,1,1,1,1,1,1,1,1,1,1,1,1,1,1,1,1,1,1,1,1,1,1,1,1,1,1,1,1,1,1
1,1,1,1,1,1,1,1,1,1,1,1,1,1,1,1,1,1,1,1,1,1,1,1,1,1,1,1,1,1,1
1,1,1,1,1,1,1,1,1,1,1,1,1,1,1,1,1,1,1,1,1,1,1,1,1,1,1,1,1,1,1
1,1,1,1,1,1,1,1,1,1,1,1,1,1,1,1,1,1,1,1,1,1,1,1,1,1,1,1,1,1,1
1,1,1,1,1,1,1,1,1,1,1,1,1,1,1,1,1,1,1,1,1,1,1,1,1,1,1,1,1,1,1
1,1,1,1,1,1,1,1,1,1,1,1,1,1,1,1,1,1,1,1,1,1,1,1,1,1,1,1,1,1,1
1,1,1,1,1,1,1,1,1,1,1,1,1,1,1,1,1,1,1,1,1,1,1,1,1,1,1,1,1,1,1
1,1,1,1,1,1,1,1,1,1,1,1,1,1,1,1,1,1,1,1,1,1,1,1,1,1,1,1,1,1,1
1,1,1,1,1,1,1,1,1,1,1,1,1,1,1,1,1,1,1,1,1,1,1,1,1,1,1,1,1,1,1
1,1,1,1,1,1,1,1,1,1,1,1,1,1,1,1,1,1,1,1,1,1,1,1,1,1,1,1,1,1,1
1,1,1,1,1,1,1,1,1,1,1,1,1,1,1,1,1,1,1,1,1,1,1,1,1,1,1,1,1,1,1
1,1,1,1,1,1,1,1,1,1,1,1,1,1,1,1,1,1,1,1,1,1,1,1,1,1,1,1,1,1,1
1,1,1,1,1,1,1,1,1,1,1,1,1,1,1,1,1,1,1,1,1,1,1,1,1,1,1,1,1,1,1
1,1,1,1,1,1,1,1,1,1,1,1,1,1,1,1,1,1,1,1,1,1,1,1,1,1,1,1,1,1,1
1,1,1,1,1,1,1,1,1,1,1,1,1,1,1,1,1,1,1,1,1,1,1,1,1,1,1,1,1,1,1
1,1,1,1,1,1,1,1,1,1,1,1,1,1,1,1,1,1,1,1,1,1,1,1,1,1,1,1,1,1,1
1,1,1,1,1,1,1,1,1,1,1,1,1,1,1,1,1,1,1,1,1,1,1,1,1,1,1,1,1,1,1
1,1,1,1,1,1,1,1,1,1,1,1,1,1,1,1,1,1,1,1,1,1,1,1,1,1,1,1,1,1,1
:endlayer
layer: 3
1,1,1,1,1,1,1,1,1,1,1,1,1,1,1,1,1,1,1,1,1,1,1,1,1,1,1,1,1,1,1
1,1,1,1,1,1,1,1,1,1,1,1,1,1,1,1,1,1,1,1,1,1,1,1,1,1,1,1,1,1,1
1,1,1,1,1,1,1,1,1,1,1,1,1,1,1,1,1,1,1,1,1,1,1,1,1,1,1,1,1,1,1
1,1,1,1,1,1,1,1,1,1,1,1,1,1,1,1,1,1,1,1,1,1,1,1,1,1,1,1,1,1,1
1,1,1,1,1,1,1,1,1,1,1,1,1,1,1,1,1,1,1,1,1,1,1,1,1,1,1,1,1,1,1
1,1,1,1,1,1,1,1,1,1,1,1,1,1,1,1,1,1,1,1,1,1,1,1,1,1,1,1,1,1,1
1,1,1,1,1,1,1,1,1,1,1,1,1,1,1,1,1,1,1,1,1,1,1,1,1,1,1,1,1,1,1
1,1,1,1,1,1,1,1,1,1,1,1,1,1,1,1,1,1,1,1,1,1,1,1,1,1,1,1,1,1,1
1,1,1,1,1,1,1,1,1,1,1,1,1,1,1,1,1,1,1,1,1,1,1,1,1,1,1,1,1,1,1
1,1,1,1,1,1,1,1,1,1,1,1,1,1,1,1,1,1,1,1,1,1,1,1,1,1,1,1,1,1,1
1,1,1,1,1,1,1,1,1,1,1,1,1,1,1,1,1,1,1,1,1,1,1,1,1,1,1,1,1,1,1
1,1,1,1,1,1,1,1,1,1,2,2,2,2,2,2,2,2,2,2,2,2,2,1,1,1,1,1,1,1,1
1,1,1,1,1,1,1,1,1,1,2,2,2,2,3,2,2,2,2,2,2,2,2,1,1,1,1,1,1,1,1
1,1,1,1,1,1,1,1,1,1,2,2,2,2,3,4,4,4,3,2,2,2,2,1,1,1,1,1,1,1,1
1,1,1,1,1,1,1,1,1,1,2,2,2,2,3,4,4,4,3,3,2,2,2,1,1,1,1,1,1,1,1
1,1,1,1,1,1,1,1,1,1,2,2,3,3,0,0,0,0,0,3,3,2,2,1,1,1,1,1,1,1,1
1,1,1,1,1,1,1,1,1,1,2,2,3,0,0,0,0,0,0,0,3,3,2,1,1,1,1,1,1,1,1
1,1,1,1,1,1,1,1,1,1,2,3,0,0,0,0,0,0,0,0,0,3,2,1,1,1,1,1,1,1,1
1,1,1,1,1,1,1,1,1,1,2,3,5,0,0,6,0,0,7,0,8,3,2,1,1,1,1,1,1,1,1
1,1,1,1,1,1,1,1,1,1,2,3,0,0,0,0,0,0,0,0,0,3,2,1,1,1,1,1,1,1,1
1,1,1,1,1,1,1,1,1,1,2,2,3,0,0,0,0,0,0,0,3,2,2,1,1,1,1,1,1,1,1
1,1,1,1,1,1,1,1,1,1,2,2,2,3,0,0,9,0,0,3,2,2,2,1,1,1,1,1,1,1,1
1,1,1,1,1,1,1,1,1,1,2,2,2,2,3,10,0,11,3,2,2,2,2,1,1,1,1,1,1,1,1
1,1,1,1,1,1,1,1,1,1,2,2,2,2,2,3,3,3,2,2,2,2,2,1,1,1,1,1,1,1,1
1,1,1,1,1,1,1,1,1,1,2,2,2,2,2,2,2,2,2,2,2,2,2,1,1,1,1,1,1,1,1
1,1,1,1,1,1,1,1,1,1,1,1,1,1,1,1,1,1,1,1,1,1,1,1,1,1,1,1,1,1,1
1,1,1,1,1,1,1,1,1,1,1,1,1,1,1,1,1,1,1,1,1,1,1,1,1,1,1,1,1,1,1
1,1,1,1,1,1,1,1,1,1,1,1,1,1,1,1,1,1,1,1,1,1,1,1,1,1,1,1,1,1,1
1,1,1,1,1,1,1,1,1,1,1,1,1,1,1,1,1,1,1,1,1,1,1,1,1,1,1,1,1,1,1
1,1,1,1,1,1,1,1,1,1,1,1,1,1,1,1,1,1,1,1,1,1,1,1,1,1,1,1,1,1,1
1,1,1,1,1,1,1,1,1,1,1,1,1,1,1,1,1,1,1,1,1,1,1,1,1,1,1,1,1,1,1
:endlayer
layer: 4
2,2,2,2,2,2,2,2,2,2,2,2,2,2,2,2,2,2,2,2,2,2,2,2,2,2,2,2,2,2,2
2,2,2,2,2,2,2,2,2,2,2,2,2,2,2,2,2,2,2,2,2,2,2,2,2,2,2,2,2,2,2
2,2,2,2,2,2,2,2,2,2,2,2,2,2,2,2,2,2,2,2,2,2,2,2,2,2,2,2,2,2,2
2,2,2,2,2,2,2,2,2,2,2,2,2,2,2,2,2,2,2,2,2,2,2,2,2,2,2,2,2,2,2
2,2,2,2,2,2,2,2,2,2,2,2,2,2,2,2,2,2,2,2,2,2,2,2,2,2,2,2,2,2,2
2,2,2,2,2,2,2,2,2,2,2,2,2,2,2,2,2,2,2,2,2,2,2,2,2,2,2,2,2,2,2
2,2,2,2,2,2,2,2,2,2,2,2,2,2,2,2,2,2,2,2,2,2,2,2,2,2,2,2,2,2,2
2,2,2,2,2,2,2,2,2,2,2,2,2,2,2,2,2,2,2,2,2,2,2,2,2,2,2,2,2,2,2
2,2,2,2,2,2,2,2,2,2,2,2,2,2,2,2,2,2,2,2,2,2,2,2,2,2,2,2,2,2,2
2,2,2,2,2,2,2,2,2,2,2,2,2,2,2,2,2,2,2,2,2,2,2,2,2,2,2,2,2,2,2
2,2,2,2,2,2,2,2,2,2,2,2,2,2,2,2,2,2,2,2,2,2,2,2,2,2,2,2,2,2,2
2,2,2,2,2,2,2,2,2,2,2,2,2,2,3,2,2,2,3,2,2,2,2,2,2,2,2,2,2,2,2
2,2,2,2,2,2,2,2,2,2,2,2,2,2,3,4,4,4,3,2,2,2,2,2,2,2,2,2,2,2,2
2,2,2,2,2,2,2,2,2,2,2,2,2,2,3,4,4,4,3,2,2,2,2,2,2,2,2,2,2,2,2
2,2,2,2,2,2,2,2,2,2,2,2,2,2,3,0,0,0,3,2,2,2,2,2,2,2,2,2,2,2,2
2,2,2,2,2,2,2,2,2,2,2,2,3,3,0,0,0,0,0,3,3,2,2,2,2,2,2,2,2,2,2
2,2,2,2,2,2,2,2,2,2,2,2,3,0,0,0,0,0,0,0,3,3,2,2,2,2,2,2,2,2,2
2,2,2,2,2,2,2,2,2,2,2,3,0,0,0,0,0,0,0,0,0,3,2,2,2,2,2,2,2,2,2
2,2,2,2,2,2,2,2,2,2,2,3,0,0,0,0,0,0,0,0,0,3,2,2,2,2,2,2,2,2,2
2,2,2,2,2,2,2,2,2,2,2,3,0,0,0,0,0,0,0,0,0,3,2,2,2,2,2,2,2,2,2
2,2,2,2,2,2,2,2,2,2,2,2,3,0,0,0,0,0,0,0,3,2,2,2,2,2,2,2,2,2,2
2,2,2,2,2,2,2,2,2,2,2,2,2,3,0,0,0,0,0,3,2,2,2,2,2,2,2,2,2,2,2
2,2,2,2,2,2,2,2,2,2,2,2,2,2,3,0,0,0,3,2,2,2,2,2,2,2,2,2,2,2,2
2,2,2,2,2,2,2,2,2,2,2,2,2,2,2,3,3,3,2,2,2,2,2,2,2,2,2,2,2,2,2
2,2,2,2,2,2,2,2,2,2,2,2,2,2,2,2,2,2,2,2,2,2,2,2,2,2,2,2,2,2,2
2,2,2,2,2,2,2,2,2,2,2,2,2,2,2,2,2,2,2,2,2,2,2,2,2,2,2,2,2,2,2
2,2,2,2,2,2,2,2,2,2,2,2,2,2,2,2,2,2,2,2,2,2,2,2,2,2,2,2,2,2,2
2,2,2,2,2,2,2,2,2,2,2,2,2,2,2,2,2,2,2,2,2,2,2,2,2,2,2,2,2,2,2
2,2,2,2,2,2,2,2,2,2,2,2,2,2,2,2,2,2,2,2,2,2,2,2,2,2,2,2,2,2,2
2,2,2,2,2,2,2,2,2,2,2,2,2,2,2,2,2,2,2,2,2,2,2,2,2,2,2,2,2,2,2
2,2,2,2,2,2,2,2,2,2,2,2,2,2,2,2,2,2,2,2,2,2,2,2,2,2,2,2,2,2,2
:endlayer
layer: 5
2,2,2,2,2,2,2,2,2,2,2,2,2,2,2,2,2,2,2,2,2,2,2,2,2,2,2,2,2,2,2
2,12,12,12,12,12,12,12,12,12,12,12,12,12,12,12,12,12,12,12,12,12,12,12,12,12,12,12,12,12,2
2,12,12,12,12,12,12,12,12,12,12,12,13,12,12,12,12,12,12,14,12,12,12,12,12,12,12,12,12,12,2
2,12,12,2,2,2,2,2,2,2,2,2,2,2,2,2,2,2,2,2,2,2,2,2,2,2,2,2,12,12,2
2,12,12,2,2,2,2,2,2,2,2,2,2,2,2,2,2,2,2,2,2,2,2,2,2,2,2,2,12,12,2
2,12,12,2,2,2,2,2,2,2,2,2,2,2,2,2,2,2,2,2,2,2,2,2,2,2,2,2,12,12,2
2,12,12,2,2,2,2,2,2,2,2,2,2,2,2,2,2,2,2,2,2,2,2,2,2,2,2,2,12,12,2
2,12,12,2,2,2,2,2,2,2,2,2,2,2,2,2,2,2,2,2,2,2,2,2,2,2,2,2,12,12,2
2,12,12,2,2,2,2,2,2,2,2,2,2,2,2,2,2,2,2,2,2,2,2,2,2,2,2,2,12,12,2
2,12,12,2,2,2,2,2,2,2,2,2,2,2,2,2,2,2,2,2,2,2,2,2,2,2,2,2,12,12,2
2,12,12,2,2,2,2,2,2,2,2,2,2,2,3,2,2,2,3,2,2,2,2,2,2,2,2,2,12,12,2
2,12,15,2,2,2,2,2,2,2,2,2,2,2,3,4,4,4,3,2,2,2,2,2,2,2,2,2,12,12,2
2,12,12,2,2,2,2,2,2,2,2,2,2,2,3,4,4,4,3,2,2,2,2,2,2,2,2,2,12,12,2
2,12,12,2,2,2,2,2,2,2,2,2,2,2,3,0,0,0,3,2,2,2,2,2,2,2,2,2,16,12,2
2,12,12,2,2,2,2,2,2,2,2,2,2,2,3,0,0,0,3,2,2,2,2,2,2,2,2,2,12,12,2
2,12,12,2,2,2,2,2,2,2,2,2,3,3,17,0,0,0,18,3,3,2,2,2,2,2,2,2,12,12,2
2,12,12,2,2,2,2,2,2,2,2,2,3,0,0,0,0,0,0,0,3,3,2,2,2,2,2,2,12,12,2
2,12,12,2,2,2,2,2,2,2,2,3,0,0,0,0,0,0,0,0,0,3,2,2,2,2,2,2,12,12,2
2,12,19,2,2,2,2,2,2,2,2,3,17,0,0,0,0,0,0,0,18,3,2,2,2,2,2,2,12,12,2
2,12,12,2,2,2,2,2,2,2,2,3,0,0,0,0,0,0,0,0,0,3,2,2,2,2,2,2,12,12,2
2,12,12,2,2,2,2,2,2,2,2,2,3,0,0,0,0,0,0,0,3,2,2,2,2,2,2,2,20,12,2
2,12,12,2,2,2,2,2,2,2,2,2,2,3,0,0,0,0,0,3,2,2,2,2,2,2,2,2,12,12,2
2,12,12,2,2,2,2,2,2,2,2,2,2,2,3,0,21,0,3,2,2,2,2,2,2,2,2,2,12,12,2
2,12,12,2,2,2,2,2,2,2,2,2,2,2,2,3,3,3,2,2,2,2,2,2,2,2,2,2,12,12,2
2,12,12,2,2,2,2,2,2,2,2,2,2,2,2,2,2,2,2,2,2,2,2,2,2,2,2,2,12,12,2
2,12,12,2,2,2,2,2,2,2,2,2,2,2,2,2,2,2,2,2,2,2,2,2,2,2,2,2,12,12,2
2,12,12,2,2,2,2,2,2,2,2,2,2,2,2,2,2,2,2,2,2,2,2,2,2,2,2,2,12,12,2
2,12,12,2,2,2,2,2,12,12,12,12,12,12,12,12,12,12,12,12,12,12,12,2,2,2,2,2,12,12,2
2,12,12,12,12,12,12,12,12,12,22,12,12,12,12,12,12,12,12,12,12,23,12,12,12,12,12,12,12,12,2
2,12,12,12,12,12,12,12,12,12,12,12,12,24,24,24,24,24,12,12,12,12,12,12,12,12,12,12,12,12,2
2,2,2,2,2,2,2,2,2,2,2,2,2,2,2,2,2,2,2,2,2,2,2,2,2,2,2,2,2,2,2
:endlayer
layer: 6
2,2,2,2,2,2,2,2,2,2,2,2,2,2,2,2,2,2,2,2,2,2,2,2,2,2,2,2,2,2,2
2,12,12,12,12,12,12,12,12,12,12,12,12,12,12,12,12,12,12,12,12,12,12,12,12,12,12,12,12,12,2
2,12,12,12,12,12,12,12,12,12,12,12,12,12,12,12,12,12,12,12,12,12,12,12,12,12,12,12,12,12,2
2,12,12,2,2,2,2,2,12,12,12,12,12,12,12,12,12,12,12,12,12,12,12,2,2,2,2,2,12,12,2
2,12,12,2,2,2,2,2,2,2,2,2,2,2,2,2,2,2,2,2,2,2,2,2,2,2,2,2,12,12,2
2,12,12,2,2,2,2,2,2,2,2,2,2,2,2,2,2,2,2,2,2,2,2,2,2,2,2,2,12,12,2
2,12,12,2,2,2,2,2,2,2,2,2,2,2,2,2,2,2,2,2,2,2,2,2,2,2,2,2,12,12,2
2,12,12,2,2,2,2,2,2,2,2,2,2,2,2,2,2,2,2,2,2,2,2,2,2,2,2,2,12,12,2
2,12,12,12,2,2,2,2,2,2,2,2,2,2,2,2,2,2,2,2,2,2,2,2,2,2,2,12,12,12,2
2,12,12,12,2,2,2,2,2,2,2,2,2,2,3,2,2,2,3,2,2,2,2,2,2,2,2,12,12,12,2
2,12,12,12,2,2,2,2,2,2,2,2,2,2,3,4,4,4,3,2,2,2,2,2,2,2,2,12,12,12,2
2,12,12,12,2,2,2,2,2,2,2,2,2,2,3,4,4,4,3,2,2,2,2,2,2,2,2,12,12,12,2
2,12,12,12,2,2,2,2,2,2,2,2,2,2,3,0,0,0,3,2,2,2,2,2,2,2,2,12,12,12,2
2,12,12,12,2,2,2,2,2,2,2,2,2,2,3,0,0,0,3,2,2,2,2,2,2,2,2,12,12,12,2
2,12,12,12,2,2,2,2,2,2,2,2,2,2,3,0,0,0,3,2,2,2,2,2,2,2,2,12,12,12,2
2,12,12,12,2,2,2,2,2,2,2,2,3,3,3,25,25,25,3,3,3,2,2,2,2,2,2,12,12,12,2
2,12,12,12,2,2,2,2,2,2,2,2,3,3,3,3,3,3,3,3,3,3,2,2,2,2,2,12,12,12,2
2,12,12,12,2,2,2,2,2,2,2,3,3,3,3,3,3,3,3,3,3,3,2,2,2,2,2,12,12,12,2
2,12,12,12,2,2,2,2,2,2,2,3,3,3,3,3,3,3,3,3,3,3,2,2,2,2,2,12,12,12,2
2,12,12,12,2,2,2,2,2,2,2,3,3,3,3,3,3,3,3,3,3,3,2,2,2,2,2,12,12,12,2
2,12,12,12,2,2,2,2,2,2,2,2,3,3,3,3,3,3,3,3,3,2,2,2,2,2,2,12,12,12,2
2,12,12,12,2,2,2,2,2,2,2,2,2,3,3,3,3,3,3,3,2,2,2,2,2,2,2,12,12,12,2
2,12,12,12,2,2,2,2,2,2,2,2,2,2,3,3,3,3,3,2,2,2,2,2,2,2,2,12,12,12,2
2,12,12,2,2,2,2,2,2,2,2,2,2,2,2,3,3,3,2,2,2,2,2,2,2,2,2,2,12,12,2
2,12,12,2,2,2,2,2,2,2,2,2,2,2,2,2,2,2,2,2,2,2,2,2,2,2,2,2,12,12,2
2,12,12,2,2,2,2,2,2,2,2,2,2,2,2,2,2,2,2,2,2,2,2,2,2,2,2,2,12,12,2
2,12,12,2,2,2,2,2,2,2,2,2,2,2,2,2,2,2,2,2,2,2,2,2,2,2,2,2,12,12,2
2,12,12,2,2,2,2,2,12,12,12,12,12,12,12,12,12,12,12,12,12,12,12,2,2,2,2,2,12,12,2
2,12,12,12,12,12,12,12,12,12,12,12,12,12,12,12,12,12,12,12,12,12,12,12,12,12,12,12,12,12,2
2,12,12,12,12,12,12,12,12,12,12,12,12,26,26,26,26,26,12,12,12,12,12,12,12,12,12,12,12,12,2
2,2,2,2,2,2,2,2,2,2,2,2,2,2,2,2,2,2,2,2,2,2,2,2,2,2,2,2,2,2,2
:endlayer
layer: 7
2,2,2,2,2,2,2,2,2,2,2,2,2,2,2,2,2,2,2,2,2,2,2,2,2,2,2,2,2,2,2
2,27,27,27,27,27,27,27,27,27,27,27,27,27,27,27,27,27,27,27,27,27,27,27,27,27,27,27,27,27,2
2,27,27,27,27,27,27,27,27,27,27,27,27,27,27,27,27,27,27,27,27,27,27,27,27,27,27,27,27,27,2
2,27,27,3,3,3,3,3,27,27,27,27,27,27,27,27,27,27,27,27,27,27,27,3,3,3,3,3,27,27,2
2,27,27,3,3,3,3,3,27,27,27,27,27,27,27,27,27,27,27,27,27,27,27,3,3,3,3,3,27,27,2
2,27,27,3,3,3,3,3,3,3,3,3,3,3,3,3,3,3,3,3,3,3,3,3,3,3,3,3,27,27,2
2,27,27,3,3,3,3,3,3,3,3,3,3,3,3,3,3,3,3,3,3,3,3,3,3,3,3,3,27,27,2
2,27,27,3,3,3,3,3,3,3,3,3,3,3,3,3,3,3,3,3,3,3,3,3,3,3,3,3,27,27,2
2,27,27,27,27,3,3,3,3,3,3,3,3,3,3,3,3,3,3,3,3,3,3,3,3,3,27,27,27,27,2
2,27,27,27,27,3,3,3,3,3,3,3,3,3,3,3,3,3,3,3,3,3,3,3,3,3,27,27,27,27,2
2,27,27,27,27,3,3,3,3,3,3,3,3,3,3,4,4,4,3,3,3,3,3,3,3,3,27,27,27,27,2
2,27,27,27,27,3,3,3,3,3,3,3,3,3,3,0,0,0,3,3,3,3,3,3,3,3,27,27,27,27,2
2,27,27,27,27,3,3,3,3,3,3,3,3,3,3,0,0,0,3,3,3,3,3,3,3,3,27,27,27,27,2
2,27,27,27,27,3,3,3,3,3,3,3,3,3,3,0,28,0,3,3,3,3,3,3,3,3,27,27,27,27,2
2,27,27,27,27,3,3,3,3,3,3,3,3,3,3,3,3,3,3,3,3,3,3,3,3,3,27,27,27,27,2
2,27,27,27,27,3,3,3,3,3,3,3,3,3,3,3,3,3,3,3,3,3,3,3,3,3,27,27,27,27,2
2,27,27,27,27,3,3,3,3,3,3,3,3,3,3,3,3,3,3,3,3,3,3,3,3,3,27,27,27,27,2
2,27,27,27,27,3,3,3,3,3,3,3,3,3,3,3,3,3,3,3,3,3,3,3,3,3,27,27,27,27,2
2,27,27,27,27,3,3,3,3,3,3,3,3,3,3,3,3,3,3,3,3,3,3,3,3,3,27,27,27,27,2
2,27,27,27,27,3,3,3,3,3,3,3,3,3,3,3,3,3,3,3,3,3,3,3,3,3,27,27,27,27,2
2,27,27,27,27,3,3,3,3,3,3,3,3,3,3,3,3,3,3,3,3,3,3,3,3,3,27,27,27,27,2
2,27,27,27,27,3,3,3,3,3,3,3,3,3,3,3,3,3,3,3,3,3,3,3,3,3,27,27,27,27,2
2,27,27,27,27,3,3,3,3,3,3,3,3,3,3,3,3,3,3,3,3,3,3,3,3,3,27,27,27,27,2
2,27,27,3,3,3,3,3,3,3,3,3,3,3,3,3,3,3,3,3,3,3,3,3,3,3,3,3,27,27,2
2,27,27,3,3,3,3,3,3,3,3,3,3,3,3,3,3,3,3,3,3,3,3,3,3,3,3,3,27,27,2
2,27,27,3,3,3,3,3,3,3,3,3,3,3,3,3,3,3,3,3,3,3,3,3,3,3,3,3,27,27,2
2,27,27,3,3,3,3,3,2,2,2,2,2,2,2,2,2,2,2,2,2,2,2,3,3,3,3,3,27,27,2
2,27,27,3,3,3,3,3,27,27,27,27,27,27,27,27,27,27,27,27,27,27,27,3,3,3,3,3,27,27,2
2,27,27,27,27,27,27,27,27,27,27,27,27,27,27,27,27,27,27,27,27,27,27,27,27,27,27,27,27,27,2
2,27,27,27,27,27,27,27,27,27,27,27,27,2,2,2,2,2,27,27,27,27,27,27,27,27,27,27,27,27,2
2,2,2,2,2,2,2,2,2,2,2,2,2,2,2,2,2,2,2,2,2,2,2,2,2,2,2,2,2,2,2
:endlayer
layer: 8
29,0,0,0,0,0,0,0,0,0,0,0,0,0,0,0,0,0,0,0,0,0,0,0,0,0,0,0,0,0,29
0,0,0,0,0,30,0,30,0,0,0,0,0,0,0,0,0,0,0,0,0,0,0,0,0,0,0,0,0,0,0
0,0,0,0,0,0,0,0,0,0,30,0,0,0,0,0,0,0,0,30,0,0,0,30,0,0,0,0,30,0,0
0,0,0,3,3,3,3,3,0,0,0,0,0,30,0,0,0,0,0,0,30,0,0,3,3,3,3,3,0,0,0
0,0,0,3,3,3,3,3,0,30,0,0,0,0,0,0,0,0,0,0,0,0,0,3,3,3,3,3,0,0,0
0,30,0,3,4,3,4,3,3,3,3,3,3,3,3,3,3,3,3,3,3,3,3,3,4,3,0,3,0,0,0
0,0,0,3,0,0,0,3,3,3,3,3,3,31,0,0,0,0,0,3,32,33,34,3,0,0,0,3,0,30,0
0,0,0,3,3,3,35,3,36,37,0,0,0,0,0,0,0,0,0,35,0,0,0,3,38,3,3,3,0,0,0
0,0,30,0,0,3,0,0,0,0,0,0,0,0,0,0,0,0,0,3,0,0,0,0,0,3,0,0,0,0,0
0,0,0,0,0,3,0,0,3,39,40,3,0,0,3,3,41,3,3,3,42,0,0,0,0,3,0,0,0,0,0
0,0,0,30,0,3,0,0,0,0,0,43,0,0,3,0,0,0,3,3,3,0,0,44,0,3,0,0,0,0,0
0,0,0,0,0,3,45,45,45,45,0,0,0,0,3,0,0,0,3,3,46,0,0,0,47,3,30,0,30,0,0
0,0,0,0,0,3,0,48,0,49,0,0,0,0,3,0,0,0,3,3,46,0,0,0,50,3,0,0,0,0,0
0,0,30,0,0,3,45,45,45,45,0,0,0,0,3,0,0,0,3,3,3,0,0,0,51,3,0,0,0,0,0
0,0,0,0,0,3,0,0,52,49,0,0,0,0,3,3,3,3,3,3,53,0,0,0,54,3,0,0,0,0,0
0,0,0,30,0,3,45,45,45,45,0,0,0,0,0,0,0,0,0,3,0,0,55,0,54,3,0,0,0,0,0
0,30,0,0,0,3,0,0,56,49,0,0,0,0,0,0,0,0,0,35,0,0,57,0,54,3,0,30,0,0,0
0,0,0,0,0,3,45,45,45,45,0,0,58,0,59,0,60,0,0,3,0,0,0,0,61,3,0,0,0,0,0
0,0,0,0,0,3,62,0,0,0,0,0,0,0,0,0,0,0,0,3,0,0,0,0,63,3,0,0,0,0,0
0,0,0,0,0,3,64,0,0,0,0,0,0,0,0,0,0,0,0,3,0,0,0,0,0,3,0,30,0,0,0
0,0,0,30,0,3,3,3,3,38,3,3,65,0,0,0,0,0,0,3,3,38,3,3,3,3,0,0,0,0,0
0,0,30,0,0,3,66,0,0,0,0,3,3,67,68,69,70,71,3,3,0,0,0,0,3,3,0,0,30,0,0
0,0,0,0,0,3,0,46,0,0,0,3,0,0,0,0,0,0,72,3,0,0,0,73,3,3,0,0,0,0,0
0,0,0,3,3,3,3,3,0,0,0,3,0,0,0,0,0,0,0,3,0,0,0,3,3,3,3,3,0,0,0
0,0,0,3,3,31,0,35,0,0,0,3,65,74,74,74,74,74,0,3,0,0,0,35,0,75,3,3,0,0,0
0,0,0,3,3,3,0,3,3,3,3,3,3,76,77,78,79,80,3,3,3,3,3,3,0,3,3,3,0,0,0
0,30,0,3,3,0,0,3,0,0,0,0,0,0,0,0,0,0,72,0,0,0,0,3,0,0,3,3,0,0,0
0,0,0,3,3,3,3,3,0,0,0,30,0,0,0,0,0,0,0,0,0,0,0,3,3,3,3,3,0,30,0
0,0,0,0,0,0,0,30,0,0,0,0,0,0,0,0,0,0,0,0,0,30,0,0,30,0,0,0,0,0,0
0,0,0,0,30,0,0,0,0,0,0,0,0,2,2,2,2,2,0,30,0,0,0,0,0,0,0,30,0,0,0
29,0,0,0,0,0,0,0,0,0,0,0,3,81,81,81,81,81,3,0,0,0,0,0,0,0,0,0,0,0,29
:endlayer
layer: 9
0,0,0,0,0,0,0,0,0,0,0,0,0,0,0,0,0,0,0,0,0,0,0,0,0,0,0,0,0,0,0
0,0,0,0,0,0,0,0,0,0,0,0,0,0,0,0,0,0,0,0,0,0,0,0,0,0,0,0,0,0,0
0,0,0,0,0,0,0,0,0,0,0,0,0,0,0,0,0,0,0,0,0,0,0,0,0,0,0,0,0,0,0
0,0,0,3,3,3,3,3,0,0,0,0,0,0,0,0,0,0,0,0,0,0,0,3,3,3,3,3,0,0,0
0,0,0,3,3,31,0,3,0,0,0,0,0,0,0,0,0,0,0,0,0,0,0,3,0,75,3,3,0,0,0
0,0,0,3,82,3,0,3,3,3,3,3,3,3,3,3,3,3,3,3,3,3,3,3,0,3,82,3,0,0,0
0,0,0,3,0,21,0,3,3,3,3,3,31,0,0,0,0,0,0,3,0,0,0,3,0,0,0,3,0,0,0
0,0,0,3,3,3,83,3,0,0,0,0,0,0,0,0,0,0,0,83,0,0,0,3,83,3,3,3,0,0,0
0,0,0,0,0,3,0,0,0,0,0,0,0,0,0,0,0,0,0,3,0,0,0,0,0,3,0,0,0,0,0
0,0,0,0,0,3,0,0,3,84,85,3,0,0,3,3,86,3,3,3,87,0,0,0,0,3,0,0,0,0,0
0,0,0,0,0,3,0,0,0,0,0,0,0,0,3,0,0,0,3,3,3,0,0,0,0,3,0,0,0,0,0
0,0,0,0,0,3,45,45,45,45,0,0,0,0,3,0,0,0,3,3,0,0,0,0,0,3,0,0,0,0,0
0,0,0,0,0,3,0,0,0,0,0,0,0,0,3,0,0,0,3,3,0,0,0,0,0,3,0,0,0,0,0
0,0,0,0,0,3,45,45,45,45,0,0,0,0,3,0,0,0,3,3,3,0,0,0,0,3,0,0,0,0,0
0,0,0,0,0,3,0,0,0,0,0,0,0,0,3,3,3,3,3,3,88,0,0,0,89,3,0,0,0,0,0
0,0,0,0,0,3,45,45,45,45,0,0,0,0,0,0,0,0,0,3,0,0,0,0,0,3,0,0,0,0,0
0,0,0,0,0,3,0,0,0,0,0,0,0,0,0,0,0,0,0,83,0,0,0,0,0,3,0,0,0,0,0
0,0,0,0,0,3,45,45,45,45,0,0,0,0,0,0,0,0,0,3,0,0,0,0,0,3,0,0,0,0,0
0,0,0,0,0,3,0,0,0,0,0,0,0,0,0,0,0,0,0,3,0,0,0,0,0,3,0,0,0,0,0
0,0,0,0,0,3,0,0,0,0,0,0,0,0,0,0,0,0,0,3,0,0,0,0,0,3,0,0,0,0,0
0,0,0,0,0,3,3,3,3,83,3,3,0,0,0,0,0,0,0,3,3,83,3,3,3,3,0,0,0,0,0
0,0,0,0,0,3,0,0,0,0,0,3,3,90,91,92,93,94,3,3,0,0,0,0,3,3,0,0,0,0,0
0,0,0,0,0,3,0,0,0,0,0,3,0,0,0,0,0,0,0,3,0,0,0,0,3,3,0,0,0,0,0
0,0,0,3,3,3,3,3,0,0,0,3,0,0,0,0,0,0,0,3,0,0,0,3,3,3,3,3,0,0,0
0,0,0,3,0,95,0,83,0,0,0,3,0,0,0,0,0,0,0,3,0,0,0,83,0,0,0,3,0,0,0
0,0,0,3,74,3,0,3,3,3,3,3,3,96,97,98,99,100,3,3,3,3,3,3,0,3,74,3,0,0,0
0,0,0,3,3,101,0,3,0,0,0,0,0,0,0,0,0,0,0,0,0,0,0,3,0,0,3,3,0,0,0
0,0,0,3,3,3,3,3,0,0,0,0,0,0,0,0,0,0,0,0,0,0,0,3,3,3,3,3,0,0,0
0,0,0,0,0,0,0,0,0,0,0,0,0,0,0,0,0,0,0,0,0,0,0,0,0,0,0,0,0,0,0
0,0,0,0,0,0,0,0,0,0,0,0,0,0,0,0,0,0,0,0,0,0,0,0,0,0,0,0,0,0,0
0,0,0,0,0,0,0,0,0,0,0,0,102,0,0,0,0,0,102,0,0,0,0,0,0,0,0,0,0,0,0
:endlayer
layer: 10
0,0,0,0,0,0,0,0,0,0,0,0,0,0,0,0,0,0,0,0,0,0,0,0,0,0,0,0,0,0,0
0,0,0,0,0,0,0,0,0,0,0,0,0,0,0,0,0,0,0,0,0,0,0,0,0,0,0,0,0,0,0
0,0,0,21,0,0,0,21,0,0,0,0,0,0,0,0,0,0,0,0,0,0,0,21,0,0,0,21,0,0,0
0,0,18,3,3,3,3,3,17,0,0,0,0,0,0,0,0,0,0,0,0,0,18,3,3,3,3,3,17,0,0
0,0,0,3,0,0,0,3,0,0,0,0,0,0,0,0,0,0,0,0,0,0,0,3,0,0,0,3,0,0,0
0,0,0,3,74,3,18,3,3,3,3,3,3,3,3,3,3,3,3,3,3,3,3,3,17,3,74,3,0,0,0
0,0,0,3,3,101,0,3,3,3,3,31,0,0,0,0,0,0,0,3,0,0,0,3,0,103,3,3,0,0,0
0,0,18,3,3,3,3,3,0,0,95,0,0,0,0,0,0,0,0,3,0,0,0,3,3,3,3,3,17,0,0
0,0,0,95,0,3,0,0,0,0,0,0,0,0,0,0,0,0,0,3,0,0,0,0,0,3,0,95,0,0,0
0,0,0,0,0,3,0,0,3,104,105,3,0,0,3,3,106,3,3,3,107,0,0,0,0,3,0,0,0,0,0
0,0,0,0,0,3,0,0,0,0,0,0,0,0,3,0,0,0,3,3,3,0,0,0,18,3,0,0,0,0,0
0,0,0,0,0,3,0,45,0,45,0,0,0,0,3,0,0,0,3,3,3,0,0,0,0,3,0,0,0,0,0
0,0,0,0,0,3,0,0,0,0,0,0,0,0,3,0,0,0,3,3,3,0,0,0,0,3,0,0,0,0,0
0,0,0,0,0,3,0,45,0,45,0,0,0,0,3,0,0,0,3,3,3,0,0,0,0,3,0,0,0,0,0
0,0,0,0,0,3,0,0,0,0,0,0,0,0,3,3,3,3,3,3,108,0,0,0,18,3,0,0,0,0,0
0,0,0,0,0,3,0,45,0,45,0,0,0,0,0,0,0,0,0,3,0,0,0,0,0,3,0,0,0,0,0
0,0,0,0,0,3,0,0,0,0,0,0,0,0,0,0,0,0,0,3,0,0,0,0,0,3,0,0,0,0,0
0,0,0,0,0,3,0,45,0,45,0,0,0,0,0,0,0,0,0,3,0,0,0,0,0,3,0,0,0,0,0
0,0,0,0,0,3,0,0,0,0,0,0,0,0,0,0,0,0,0,3,0,0,0,0,18,3,0,0,0,0,0
0,0,0,0,0,3,0,0,0,0,0,0,0,0,0,0,0,0,0,3,17,0,0,0,0,3,0,0,0,0,0
0,0,0,0,0,3,3,3,3,3,3,3,0,0,0,0,0,0,0,3,3,3,3,3,3,3,0,0,0,0,0
0,0,0,0,0,3,0,0,0,0,0,3,3,109,110,111,112,113,3,3,0,0,0,18,3,3,0,0,0,0,0
0,0,0,21,0,3,0,0,0,0,0,3,0,0,0,0,0,0,0,3,0,0,0,0,3,3,0,21,0,0,0
0,0,18,3,3,3,3,3,0,0,0,3,0,0,0,0,0,0,0,3,0,0,0,3,3,3,3,3,17,0,0
0,0,0,3,0,0,0,3,0,0,0,3,0,0,0,0,0,0,0,3,21,0,0,3,0,95,0,3,0,0,0
0,0,0,3,0,3,0,3,3,3,3,3,3,114,115,116,117,118,3,3,3,3,3,3,25,3,0,3,0,0,0
0,0,0,3,0,75,3,3,0,0,0,0,0,0,0,0,0,0,119,0,0,0,0,3,3,31,0,3,0,0,0
0,0,18,3,3,3,3,3,17,0,0,0,0,0,0,0,0,0,0,0,0,0,18,3,3,3,3,3,17,0,0
0,0,0,95,0,0,0,95,0,0,0,0,0,0,0,0,0,0,0,0,0,0,0,95,0,0,0,95,0,0,0
0,0,0,0,0,0,0,0,0,0,0,0,0,0,0,0,0,0,0,0,0,0,0,0,0,0,0,0,0,0,0
0,0,0,0,0,0,0,0,0,0,0,0,46,0,0,0,0,0,46,0,0,0,0,0,0,0,0,0,0,0,0
:endlayer
layer: 11
0,0,0,0,0,0,0,0,0,0,0,0,0,0,0,0,0,0,0,0,0,0,0,0,0,0,0,0,0,0,0
0,0,0,0,0,0,0,0,0,0,0,0,0,0,0,0,0,0,0,0,0,0,0,0,0,0,0,0,0,0,0
0,0,0,0,0,0,0,0,0,0,0,0,0,0,0,0,0,0,0,0,0,0,0,0,0,0,0,0,0,0,0
0,0,0,3,3,3,3,3,0,0,0,0,0,0,0,0,0,0,0,0,0,0,0,3,3,3,3,3,0,0,0
0,0,0,3,0,0,0,3,0,0,0,0,0,0,0,0,0,0,0,0,0,0,0,3,0,0,0,3,0,0,0
0,0,0,3,0,3,25,3,3,3,3,3,3,3,3,3,3,3,3,3,3,3,3,3,25,3,0,3,0,0,0
0,0,0,3,0,75,3,3,3,3,31,0,0,0,0,95,0,0,0,3,17,0,18,3,3,31,0,3,0,0,0
0,0,0,3,3,3,3,3,3,0,0,0,0,0,0,0,0,0,18,3,0,0,0,3,3,3,3,3,0,0,0
0,0,0,0,0,3,17,0,3,17,0,0,0,0,21,0,21,0,0,3,0,0,0,0,0,3,0,0,0,0,0
0,0,0,0,0,3,0,0,3,3,3,3,3,3,3,3,3,3,3,3,120,0,0,0,0,3,0,0,0,0,0
0,0,0,0,0,3,0,0,95,0,0,95,0,0,3,0,0,0,3,3,3,0,0,0,0,3,0,0,0,0,0
0,0,0,0,0,3,0,45,0,45,0,0,0,0,3,0,0,0,3,3,3,0,0,0,0,3,0,0,0,0,0
0,0,0,0,0,3,17,0,0,0,0,0,0,0,3,0,0,0,3,3,3,0,0,0,0,3,0,0,0,0,0
0,0,0,0,0,3,0,45,0,45,0,0,0,0,3,0,0,0,3,3,3,0,0,0,0,3,0,0,0,0,0
0,0,0,0,0,3,17,0,0,0,0,0,0,18,3,3,3,3,3,3,121,0,0,0,0,3,0,0,0,0,0
0,0,0,0,0,3,0,45,0,45,0,0,0,0,95,0,0,0,0,3,0,0,0,0,0,3,0,0,0,0,0
0,0,0,0,0,3,17,0,0,0,0,0,0,0,0,0,0,0,18,3,0,0,0,0,0,3,0,0,0,0,0
0,0,0,0,0,3,0,45,0,45,0,0,0,0,0,0,0,0,0,3,0,0,0,0,0,3,0,0,0,0,0
0,0,0,0,0,3,0,0,0,0,0,0,0,0,0,0,0,0,0,3,0,0,0,0,0,3,0,0,0,0,0
0,0,0,0,0,3,17,0,0,0,0,21,0,0,0,0,0,0,0,3,0,0,0,0,0,3,0,0,0,0,0
0,0,0,0,0,3,3,3,3,3,3,3,17,0,0,0,0,0,18,3,3,3,3,3,3,3,0,0,0,0,0
0,0,0,0,0,3,0,0,0,0,0,3,3,122,123,124,125,126,3,3,0,0,0,0,3,3,0,0,0,0,0
0,0,0,0,0,3,0,0,0,0,0,3,0,0,0,0,0,0,0,3,0,0,0,0,3,3,0,0,0,0,0
0,0,0,3,3,3,3,3,0,0,0,3,17,0,0,0,0,0,18,3,0,0,0,3,3,3,3,3,0,0,0
0,0,0,3,0,103,3,3,0,0,0,3,0,0,0,0,0,0,0,3,0,0,0,3,3,101,0,3,0,0,0
0,0,0,3,17,3,4,3,3,3,3,3,3,127,128,129,130,131,3,3,3,3,3,3,4,3,0,3,0,0,0
0,0,0,3,0,0,0,3,0,0,0,95,0,0,0,0,0,0,0,95,0,0,0,3,0,0,0,3,0,0,0
0,0,0,3,3,3,3,3,0,0,0,0,0,0,0,0,0,0,0,0,0,0,0,3,3,3,3,3,0,0,0
0,0,0,0,0,0,0,0,0,0,0,0,0,0,0,0,0,0,0,0,0,0,0,0,0,0,0,0,0,0,0
0,0,0,0,0,0,0,0,0,0,0,0,0,0,0,0,0,0,0,0,0,0,0,0,0,0,0,0,0,0,0
0,0,0,0,0,0,0,0,0,0,0,0,0,0,0,0,0,0,0,0,0,0,0,0,0,0,0,0,0,0,0
:endlayer
layer: 12
0,0,0,0,0,0,0,0,0,0,0,0,0,0,0,0,0,0,0,0,0,0,0,0,0,0,0,0,0,0,0
0,0,0,0,0,0,0,0,0,0,0,0,0,0,0,0,0,0,0,0,0,0,0,0,0,0,0,0,0,0,0
0,0,0,0,0,0,0,0,0,0,0,0,0,0,0,0,0,0,0,0,0,0,0,0,0,0,0,0,0,0,0
0,0,0,3,3,3,3,3,0,0,0,0,0,0,0,0,0,0,0,0,0,0,0,3,3,3,3,3,0,0,0
0,0,0,3,0,103,3,3,0,0,0,0,0,0,0,0,0,0,0,0,0,0,0,3,3,101,0,3,0,0,0
0,0,0,3,0,3,4,3,3,3,3,3,3,3,3,3,3,3,3,3,3,3,3,3,4,3,18,3,0,0,0
0,0,0,3,17,0,0,75,3,31,0,0,0,0,3,3,3,3,3,3,3,3,3,31,0,0,0,3,0,0,0
0,0,0,3,3,3,3,3,3,3,3,3,3,3,3,3,3,3,3,3,3,3,3,3,3,3,3,3,0,0,0
0,0,0,0,0,3,3,3,3,3,3,3,3,3,3,3,3,3,3,3,3,3,3,3,3,3,0,0,0,0,0
0,0,0,0,0,3,3,3,3,3,3,3,3,3,3,3,3,3,3,3,3,3,3,3,3,3,0,0,0,0,0
0,0,0,0,0,3,3,3,3,3,3,3,3,3,3,3,3,3,3,3,3,3,3,3,3,3,0,0,0,0,0
0,0,0,0,0,3,3,3,3,3,3,3,3,3,3,3,3,3,3,3,3,3,3,3,3,3,0,0,0,0,0
0,0,0,0,0,3,3,3,3,3,3,3,3,3,3,3,3,3,3,3,3,3,3,3,3,3,0,0,0,0,0
0,0,0,0,0,3,3,3,3,3,3,3,3,3,3,3,3,3,3,3,3,3,3,3,3,3,0,0,0,0,0
0,0,0,0,0,3,3,3,3,3,3,3,3,3,3,3,3,3,3,3,3,3,3,3,3,3,0,0,0,0,0
0,0,0,0,0,3,3,3,3,3,3,3,3,3,3,3,3,3,3,3,3,3,3,3,3,3,0,0,0,0,0
0,0,0,0,0,3,3,3,3,3,3,3,3,3,3,3,3,3,3,3,3,3,3,3,3,3,0,0,0,0,0
0,0,0,0,0,3,3,3,3,3,3,3,3,3,3,3,3,3,3,3,3,3,3,3,3,3,0,0,0,0,0
0,0,0,0,0,3,3,3,3,3,3,3,3,3,3,3,3,3,3,3,3,3,3,3,3,3,0,0,0,0,0
0,0,0,0,0,3,3,3,3,3,3,3,3,3,3,3,3,3,3,3,3,3,3,3,3,3,0,0,0,0,0
0,0,0,0,0,3,3,3,3,3,3,3,3,3,3,3,3,3,3,3,3,3,3,3,3,3,0,0,0,0,0
0,0,0,0,0,3,3,3,3,3,3,3,3,3,3,3,3,3,3,3,3,3,3,3,3,3,0,0,0,0,0
0,0,0,0,0,3,3,3,3,3,3,3,3,3,3,3,3,3,3,3,3,3,3,3,3,3,0,0,0,0,0
0,0,0,3,3,3,4,3,3,3,3,3,3,3,3,3,3,3,3,3,3,3,3,3,4,3,3,3,0,0,0
0,0,0,3,3,31,0,3,3,3,3,3,3,3,3,3,3,3,3,3,3,3,3,3,0,75,3,3,0,0,0
0,0,0,3,82,3,0,3,3,3,3,3,3,82,82,82,82,82,3,3,3,3,3,3,0,3,82,3,0,0,0
0,0,0,3,0,0,0,3,0,0,0,0,0,0,0,0,0,0,0,0,0,0,0,3,0,21,0,3,0,0,0
0,0,0,3,3,3,3,3,0,0,0,0,0,0,0,0,0,0,0,0,0,0,0,3,3,3,3,3,0,0,0
0,0,0,0,0,0,0,0,0,0,0,0,0,0,0,0,0,0,0,0,0,0,0,0,0,0,0,0,0,0,0
0,0,0,0,0,0,0,0,0,0,0,0,0,0,0,0,0,0,0,0,0,0,0,0,0,0,0,0,0,0,0
0,0,0,0,0,0,0,0,0,0,0,0,0,0,0,0,0,0,0,0,0,0,0,0,0,0,0,0,0,0,0
:endlayer
layer: 13
0,0,0,0,0,0,0,0,0,0,0,0,0,0,0,0,0,0,0,0,0,0,0,0,0,0,0,0,0,0,0
0,0,0,0,0,0,0,0,0,0,0,0,0,0,0,0,0,0,0,0,0,0,0,0,0,0,0,0,0,0,0
0,0,0,0,0,0,0,0,0,0,0,0,0,0,0,0,0,0,0,0,0,0,0,0,0,0,0,0,0,0,0
0,0,0,3,3,3,3,3,0,0,0,0,0,0,0,0,0,0,0,0,0,0,0,3,3,3,3,3,0,0,0
0,0,0,3,3,31,0,3,0,0,0,0,0,0,0,0,0,0,0,0,0,0,0,3,0,75,3,3,0,0,0
0,0,0,3,82,3,0,3,3,3,3,3,3,3,3,3,3,3,3,3,3,3,3,3,0,3,82,3,0,0,0
0,0,0,3,0,0,0,0,0,0,0,0,0,0,0,3,132,0,0,0,0,0,38,0,0,0,0,3,0,0,0
0,0,0,3,3,3,3,3,0,0,0,0,0,0,0,3,133,0,0,0,0,0,3,3,3,3,3,3,0,0,0
0,0,0,0,0,3,134,3,74,0,0,0,0,0,0,3,135,0,0,0,0,0,0,0,132,3,0,0,0,0,0
0,0,0,0,0,3,0,3,3,0,0,0,0,0,0,3,3,3,3,3,0,0,0,0,0,3,0,0,0,0,0
0,0,0,0,0,3,136,3,3,3,3,35,35,3,3,3,132,0,0,0,0,0,0,0,0,3,0,0,0,0,0
0,0,0,0,0,3,0,3,3,3,0,0,0,0,132,3,0,0,0,0,0,0,0,0,137,3,0,0,0,0,0
0,0,0,0,0,3,41,3,3,3,138,0,0,139,0,3,0,140,140,140,140,140,0,0,0,3,0,0,0,0,0
0,0,0,0,0,3,0,0,0,3,0,0,0,0,0,3,0,140,140,140,140,140,0,75,74,3,0,0,0,0,0
0,0,0,0,0,3,0,0,0,3,0,0,0,0,0,0,0,140,140,140,140,140,0,75,3,3,0,0,0,0,0
0,0,0,0,0,3,0,141,0,3,0,0,0,0,0,0,0,140,140,140,140,140,0,142,46,3,0,0,0,0,0
0,0,0,0,0,3,0,0,0,3,0,0,0,0,0,0,0,140,140,140,140,140,0,142,46,3,0,0,0,0,0
0,0,0,0,0,3,0,0,0,3,0,0,0,0,0,3,143,140,140,140,140,140,0,142,46,3,0,0,0,0,0
0,0,0,0,0,3,3,38,3,3,0,0,0,0,0,3,0,140,140,140,140,140,0,75,3,3,0,0,0,0,0
0,0,0,0,0,3,0,0,0,3,0,0,0,0,0,0,0,140,140,140,140,140,0,75,4,3,0,0,0,0,0
0,0,0,0,0,3,0,0,0,144,0,0,0,0,0,0,0,140,140,140,140,140,0,0,0,3,0,0,0,0,0
0,0,0,0,0,3,0,0,0,3,0,0,0,0,0,0,0,0,0,0,0,0,0,0,145,3,0,0,0,0,0
0,0,0,0,0,3,0,0,0,3,0,0,0,0,0,3,0,0,0,0,0,0,0,0,0,3,0,0,0,0,0
0,0,0,3,3,3,0,3,146,3,147,0,0,0,0,3,148,0,0,0,0,0,0,3,0,3,3,3,0,0,0
0,0,0,3,0,0,0,3,0,3,0,0,0,0,132,3,132,0,0,0,0,0,132,3,0,0,0,3,0,0,0
0,0,0,3,74,3,18,3,3,3,3,3,3,3,3,3,3,3,3,3,3,3,3,3,0,3,74,3,0,0,0
0,0,0,3,3,101,0,3,0,0,0,0,0,0,95,0,95,0,0,0,0,0,0,3,0,103,3,3,0,0,0
0,0,0,3,3,3,3,3,0,0,0,0,0,0,0,0,0,0,0,0,0,0,0,3,3,3,3,3,0,0,0
0,0,0,0,0,0,0,0,0,0,0,0,0,0,0,0,0,0,0,0,0,0,0,0,0,0,0,0,0,0,0
0,0,0,0,0,0,0,0,0,0,0,0,0,0,0,0,0,0,0,0,0,0,0,0,0,0,0,0,0,0,0
0,0,0,0,0,0,0,0,0,0,0,0,0,0,0,0,0,0,0,0,0,0,0,0,0,0,0,0,0,0,0
:endlayer
layer: 14
0,0,0,0,0,0,0,0,0,0,0,0,0,0,0,0,0,0,0,0,0,0,0,0,0,0,0,0,0,0,0
0,0,0,0,0,0,0,0,0,0,0,0,0,0,0,0,0,0,0,0,0,0,0,0,0,0,0,0,0,0,0
0,0,0,0,0,0,0,0,0,0,0,0,0,0,0,0,0,0,0,0,0,0,0,0,0,0,0,0,0,0,0
0,0,0,3,3,3,3,3,0,0,0,0,0,0,0,0,0,0,0,0,0,0,0,3,3,3,3,3,0,0,0
0,0,0,3,0,0,0,3,0,0,0,0,0,0,0,0,0,0,0,0,0,0,0,3,0,0,0,3,0,0,0
0,0,0,3,74,3,18,3,3,3,3,3,3,3,3,3,3,3,3,3,3,3,3,3,0,3,74,3,0,0,0
0,0,0,3,3,101,0,0,0,0,0,95,0,0,0,3,132,0,0,0,0,0,83,0,0,103,3,3,0,0,0
0,0,0,3,3,3,3,3,0,0,0,0,0,0,0,3,17,0,0,0,0,0,3,3,3,3,3,3,0,0,0
0,0,0,0,0,3,0,3,0,0,0,0,0,0,18,3,0,0,0,0,0,0,95,0,132,3,0,0,0,0,0
0,0,0,0,0,3,0,3,74,0,0,0,0,0,0,3,3,3,3,3,0,0,0,0,18,3,0,0,0,0,0
0,0,0,0,0,3,0,3,3,3,3,83,149,3,3,3,132,0,0,95,0,0,0,0,0,3,0,0,0,0,0
0,0,0,0,0,3,0,3,3,3,95,0,0,95,132,3,0,0,0,0,0,0,0,0,0,3,0,0,0,0,0
0,0,0,0,0,3,86,3,3,3,0,0,0,0,0,3,0,0,0,0,0,0,0,0,18,3,0,0,0,0,0
0,0,0,0,0,3,0,0,0,3,0,0,0,0,0,3,0,0,0,0,0,0,0,0,0,3,0,0,0,0,0
0,0,0,0,0,3,0,0,0,3,0,0,0,0,0,0,0,0,0,0,0,0,0,0,3,3,0,0,0,0,0
0,0,0,0,0,3,0,0,0,3,0,0,0,0,0,0,0,0,0,0,0,0,0,0,0,3,0,0,0,0,0
0,0,0,0,0,3,0,0,0,3,0,0,0,0,0,0,0,0,0,0,0,0,0,0,0,3,0,0,0,0,0
0,0,0,0,0,3,0,0,0,3,0,0,0,0,0,3,0,0,0,0,0,0,0,0,0,3,0,0,0,0,0
0,0,0,0,0,3,3,83,3,3,0,0,0,0,0,3,0,0,0,0,0,0,0,0,3,3,0,0,0,0,0
0,0,0,0,0,3,0,0,0,3,17,0,0,0,0,0,0,0,0,0,0,0,0,0,0,3,0,0,0,0,0
0,0,0,0,0,3,0,0,0,149,0,0,0,0,0,0,0,0,0,0,0,0,0,0,18,3,0,0,0,0,0
0,0,0,0,0,3,0,0,0,3,17,0,0,0,0,0,0,0,0,0,0,0,0,0,0,3,0,0,0,0,0
0,0,0,0,0,3,0,0,0,3,0,0,0,0,0,3,0,0,0,0,0,0,0,0,0,3,0,0,0,0,0
0,0,0,3,3,3,0,3,149,3,0,0,0,0,0,3,0,0,0,0,0,0,18,3,0,3,3,3,0,0,0
0,0,0,3,0,0,0,3,0,3,21,0,0,0,132,3,132,0,0,0,21,0,132,3,0,0,0,3,0,0,0
0,0,0,3,0,3,25,3,3,3,3,3,3,3,3,3,3,3,3,3,3,3,3,3,25,3,18,3,0,0,0
0,0,0,3,0,75,3,3,0,0,0,0,0,0,0,0,0,0,0,0,0,0,0,3,3,31,0,3,0,0,0
0,0,0,3,3,3,3,3,0,0,0,0,0,0,0,0,0,0,0,0,0,0,0,3,3,3,3,3,0,0,0
0,0,0,0,0,0,0,0,0,0,0,0,0,0,0,0,0,0,0,0,0,0,0,0,0,0,0,0,0,0,0
0,0,0,0,0,0,0,0,0,0,0,0,0,0,0,0,0,0,0,0,0,0,0,0,0,0,0,0,0,0,0
0,0,0,0,0,0,0,0,0,0,0,0,0,0,0,0,0,0,0,0,0,0,0,0,0,0,0,0,0,0,0
:endlayer
layer: 15
0,0,0,0,0,0,0,0,0,0,0,0,0,0,0,0,0,0,0,0,0,0,0,0,0,0,0,0,0,0,0
0,0,0,0,0,0,0,0,0,0,0,0,0,0,0,0,0,0,0,0,0,0,0,0,0,0,0,0,0,0,0
0,0,0,0,0,0,0,0,0,0,0,0,0,0,0,0,0,0,0,0,0,0,0,0,0,0,0,0,0,0,0
0,0,0,3,3,3,3,3,0,0,0,0,0,0,0,0,0,0,0,0,0,0,0,3,3,3,3,3,0,0,0
0,0,0,3,0,0,0,3,0,0,0,0,0,0,0,0,0,0,0,0,0,0,0,3,0,95,0,3,0,0,0
0,0,0,3,0,3,25,3,3,3,3,3,3,3,3,3,3,3,3,3,3,3,3,3,25,3,0,3,0,0,0
0,0,0,3,0,75,3,101,0,0,0,0,0,0,0,3,132,0,0,95,0,0,3,103,3,31,0,3,0,0,0
0,0,0,3,3,3,3,3,0,0,0,0,0,0,0,3,0,0,0,0,0,0,3,3,3,3,3,3,0,0,0
0,0,0,0,0,3,0,3,0,0,0,0,0,0,0,3,0,0,0,0,0,0,0,0,132,3,0,0,0,0,0
0,0,0,0,0,3,0,3,0,0,0,0,0,0,0,3,3,3,3,3,0,0,0,0,0,3,0,0,0,0,0
0,0,0,0,0,3,0,3,74,3,3,3,3,3,3,3,132,0,0,0,0,0,0,0,0,3,0,0,0,0,0
0,0,0,0,0,3,17,3,3,3,0,0,0,0,132,3,0,0,0,0,0,0,0,0,0,3,0,0,0,0,0
0,0,0,0,0,3,106,3,3,3,0,0,0,0,0,3,0,0,0,0,0,0,0,0,0,3,0,0,0,0,0
0,0,0,0,0,3,0,0,95,3,0,0,0,0,18,3,17,0,0,0,0,0,0,0,25,3,0,0,0,0,0
0,0,0,0,0,3,0,0,0,3,0,0,0,0,0,95,0,0,0,0,0,0,0,103,3,3,0,0,0,0,0
0,0,0,0,0,3,0,0,0,3,0,0,0,0,0,0,0,0,0,0,0,0,0,0,103,3,0,0,0,0,0
0,0,0,0,0,3,17,0,0,3,0,0,0,0,0,21,0,0,0,0,0,0,0,0,0,3,0,0,0,0,0
0,0,0,0,0,3,0,21,0,3,0,0,0,0,18,3,17,0,0,0,0,0,0,0,103,3,0,0,0,0,0
0,0,0,0,0,3,3,3,3,3,0,0,0,0,18,3,17,0,0,0,0,0,0,103,3,3,0,0,0,0,0
0,0,0,0,0,3,0,0,0,3,0,0,0,0,0,95,0,0,0,0,0,0,0,0,82,3,0,0,0,0,0
0,0,0,0,0,3,17,0,0,3,0,0,0,0,0,0,0,0,0,0,0,0,0,0,0,3,0,0,0,0,0
0,0,0,0,0,3,0,0,0,3,0,0,0,0,0,21,0,0,0,0,0,0,0,0,0,3,0,0,0,0,0
0,0,0,0,0,3,0,0,21,3,0,0,0,0,18,3,17,0,0,0,0,0,0,0,0,3,0,0,0,0,0
0,0,0,3,3,3,25,3,3,3,0,0,0,0,0,3,0,0,0,0,0,0,0,3,25,3,3,3,0,0,0
0,0,0,3,0,103,3,3,21,3,0,0,0,0,132,3,132,0,0,0,0,0,132,3,3,101,0,3,0,0,0
0,0,0,3,17,3,4,3,3,3,3,3,3,3,3,3,3,3,3,3,3,3,3,3,4,3,0,3,0,0,0
0,0,0,3,0,0,0,3,82,82,82,82,82,82,82,82,82,82,82,82,82,82,82,3,0,0,0,3,0,0,0
0,0,0,3,3,3,3,3,0,0,0,0,0,0,0,0,0,0,0,0,0,0,0,3,3,3,3,3,0,0,0
0,0,0,0,0,0,0,0,0,0,0,0,0,0,0,0,0,0,0,0,0,0,0,0,0,0,0,0,0,0,0
0,0,0,0,0,0,0,0,0,0,0,0,0,0,0,0,0,0,0,0,0,0,0,0,0,0,0,0,0,0,0
0,0,0,0,0,0,0,0,0,0,0,0,0,0,0,0,0,0,0,0,0,0,0,0,0,0,0,0,0,0,0
:endlayer
layer: 16
0,0,0,0,0,0,0,0,0,0,0,0,0,0,0,0,0,0,0,0,0,0,0,0,0,0,0,0,0,0,0
0,0,0,0,0,0,0,0,0,0,0,0,0,0,0,0,0,0,0,0,0,0,0,0,0,0,0,0,0,0,0
0,0,0,0,0,0,0,0,0,0,0,0,0,0,0,0,0,0,0,0,0,0,0,0,0,0,0,0,0,0,0
0,0,0,3,3,3,3,3,0,0,0,0,0,0,0,0,0,0,0,0,0,0,0,3,3,3,3,3,0,0,0
0,0,0,3,0,103,3,3,3,3,3,3,3,3,3,3,3,3,3,3,3,3,3,3,3,101,0,3,0,0,0
0,0,0,3,17,3,4,3,3,3,3,3,3,3,3,3,3,3,3,3,3,3,3,3,4,3,0,3,0,0,0
0,0,0,3,0,0,0,75,3,3,3,3,3,3,3,3,3,3,3,3,3,3,3,31,0,0,0,3,0,0,0
0,0,0,3,3,3,3,3,82,3,3,3,3,3,3,3,3,3,3,3,3,3,3,3,3,3,3,3,0,0,0
0,0,0,0,3,3,3,3,0,3,3,3,3,3,3,3,3,3,3,3,3,3,3,3,3,3,3,0,0,0,0
0,0,0,0,3,3,3,3,0,3,3,3,3,3,3,3,3,3,3,3,3,3,3,3,3,3,3,0,0,0,0
0,0,0,0,3,3,3,3,0,3,3,3,3,3,3,3,3,3,3,3,3,3,3,3,3,3,3,0,0,0,0
0,0,0,0,3,3,3,3,74,3,3,3,3,3,3,3,3,3,3,3,3,3,3,3,3,3,3,0,0,0,0
0,0,0,0,3,3,3,3,3,3,3,3,3,3,3,3,3,3,3,3,3,3,3,3,3,3,3,0,0,0,0
0,0,0,0,3,3,3,3,3,3,3,3,3,3,3,3,3,3,3,3,3,3,3,3,3,3,3,0,0,0,0
0,0,0,0,3,3,3,3,3,3,3,3,3,3,3,3,3,3,3,3,3,3,3,3,3,3,3,0,0,0,0
0,0,0,0,3,3,3,3,3,3,3,3,3,3,3,3,3,3,3,3,3,3,3,3,3,3,3,0,0,0,0
0,0,0,0,3,3,3,3,3,3,3,3,3,3,3,3,3,3,3,3,3,3,3,3,103,3,3,0,0,0,0
0,0,0,0,3,3,3,3,3,3,3,3,3,3,3,3,3,3,3,3,3,3,3,3,3,3,3,0,0,0,0
0,0,0,0,3,3,3,3,3,3,3,3,3,3,3,3,3,3,3,3,3,3,3,3,3,3,3,0,0,0,0
0,0,0,0,3,3,3,3,3,3,3,3,3,3,3,3,3,3,3,3,3,3,3,3,3,3,3,0,0,0,0
0,0,0,0,3,3,3,3,3,3,3,3,3,3,3,3,3,3,3,3,3,3,3,3,3,3,3,0,0,0,0
0,0,0,0,3,3,3,3,3,3,3,3,3,3,3,3,3,3,3,3,3,3,3,3,3,3,3,0,0,0,0
0,0,0,0,3,3,3,3,3,3,3,3,3,3,3,3,3,3,3,3,3,3,3,3,3,3,3,0,0,0,0
0,0,0,3,3,3,3,3,3,3,3,3,3,3,3,3,3,3,3,3,3,3,3,3,3,3,3,3,0,0,0
0,0,0,3,3,31,0,150,3,3,3,3,3,3,3,3,3,3,3,3,3,3,3,3,0,75,3,3,0,0,0
0,0,0,3,82,3,0,3,3,3,3,3,3,3,3,3,3,3,3,3,3,3,3,3,0,3,82,3,0,0,0
0,0,0,3,0,0,0,3,3,3,3,3,3,3,3,3,3,3,3,3,3,3,3,3,0,0,0,3,0,0,0
0,0,0,3,3,3,3,3,0,0,0,0,0,0,0,0,0,0,0,0,0,0,0,3,3,3,3,3,0,0,0
0,0,0,0,0,0,0,0,0,0,0,0,0,0,0,0,0,0,0,0,0,0,0,0,0,0,0,0,0,0,0
0,0,0,0,0,0,0,0,0,0,0,0,0,0,0,0,0,0,0,0,0,0,0,0,0,0,0,0,0,0,0
0,0,0,0,0,0,0,0,0,0,0,0,0,0,0,0,0,0,0,0,0,0,0,0,0,0,0,0,0,0,0
:endlayer
layer: 17
0,0,0,0,0,0,0,0,0,0,0,0,0,0,0,0,0,0,0,0,0,0,0,0,0,0,0,0,0,0,0
0,0,0,0,0,0,0,0,0,0,0,0,0,0,0,0,0,0,0,0,0,0,0,0,0,0,0,0,0,0,0
0,0,0,0,0,0,0,0,0,0,0,0,0,0,0,0,0,0,0,0,0,0,0,0,0,0,0,0,0,0,0
0,0,0,3,3,3,3,3,0,0,0,0,0,0,0,0,0,0,0,0,0,0,0,3,3,3,3,3,0,0,0
0,0,0,3,3,31,0,3,3,3,3,3,3,3,3,3,3,3,3,3,3,3,3,3,0,75,3,3,0,0,0
0,0,0,3,82,3,0,3,151,151,151,151,152,151,151,151,151,151,152,151,151,151,151,3,0,3,82,3,0,0,0
0,0,0,3,0,0,0,0,151,151,151,151,151,151,151,151,151,151,151,151,151,151,151,0,0,21,0,3,0,0,0
0,0,0,3,3,3,3,3,3,151,151,151,151,151,151,151,151,151,151,151,151,151,3,3,3,3,3,3,0,0,0
0,0,0,0,3,151,151,3,0,3,3,3,3,0,3,3,3,3,3,3,3,3,3,3,151,151,3,0,0,0,0
0,0,0,0,3,151,151,3,0,3,3,153,0,0,0,0,0,0,0,0,0,154,3,3,151,151,3,0,0,0,0
0,0,0,0,3,151,151,3,0,3,3,0,0,0,0,0,0,0,0,0,0,0,3,3,151,151,3,0,0,0,0
0,0,0,0,3,151,151,0,0,0,3,0,0,0,0,0,0,0,0,0,0,0,3,4,151,151,3,0,0,0,0
0,0,0,0,3,152,151,0,0,0,0,0,0,0,0,0,0,0,0,0,0,0,0,0,151,152,3,0,0,0,0
0,0,0,0,3,151,151,0,3,3,3,0,0,0,0,155,0,0,0,0,0,0,3,0,151,151,3,0,0,0,0
0,0,0,0,3,151,151,0,0,3,3,3,3,3,3,3,3,3,3,3,3,3,0,0,151,151,3,0,0,0,0
0,0,0,0,3,151,151,0,0,3,2,2,2,2,2,2,2,2,2,2,2,3,0,0,151,151,3,0,0,0,0
0,0,0,0,3,151,151,0,0,3,2,2,2,2,2,2,2,2,2,2,2,3,0,0,0,151,3,0,0,0,0
0,0,0,0,3,151,151,0,0,3,2,2,2,2,2,2,2,2,2,2,2,3,0,0,151,151,3,0,0,0,0
0,0,0,0,3,152,151,0,0,3,2,2,2,2,2,2,2,2,2,2,2,3,0,0,151,152,3,0,0,0,0
0,0,0,0,3,151,151,0,0,3,2,2,2,2,2,2,2,2,2,2,2,3,0,0,151,151,3,0,0,0,0
0,0,0,0,3,151,151,0,0,3,2,2,2,2,2,2,2,2,2,2,2,3,0,0,151,151,3,0,0,0,0
0,0,0,0,3,151,151,0,0,3,2,2,2,2,2,2,2,2,2,2,2,3,0,0,151,151,3,0,0,0,0
0,0,0,0,3,151,151,0,0,3,3,3,3,3,3,3,3,3,3,3,3,3,0,0,151,151,3,0,0,0,0
0,0,0,3,3,3,3,0,3,151,151,151,151,75,3,3,3,31,151,151,151,151,3,3,3,3,3,3,0,0,0
0,0,0,3,0,0,0,0,151,151,151,151,151,75,3,3,3,31,151,151,151,151,151,3,95,0,0,3,0,0,0
0,0,0,3,74,3,18,3,151,151,151,151,151,75,151,3,151,31,151,151,151,151,151,3,0,3,74,3,0,0,0
0,0,0,3,3,101,0,3,3,3,3,152,3,3,3,3,3,3,3,152,3,3,3,3,0,103,3,3,0,0,0
0,0,0,3,3,3,3,3,0,0,0,0,0,0,0,0,0,0,0,0,0,0,0,3,3,3,3,3,0,0,0
0,0,0,0,0,0,0,0,0,0,0,0,0,0,0,0,0,0,0,0,0,0,0,0,0,0,0,0,0,0,0
0,0,0,0,0,0,0,0,0,0,0,0,0,0,0,0,0,0,0,0,0,0,0,0,0,0,0,0,0,0,0
0,0,0,0,0,0,0,0,0,0,0,0,0,0,0,0,0,0,0,0,0,0,0,0,0,0,0,0,0,0,0
:endlayer
layer: 18
0,0,0,0,0,0,0,0,0,0,0,0,0,0,0,0,0,0,0,0,0,0,0,0,0,0,0,0,0,0,0
0,0,0,0,0,0,0,0,0,0,0,0,0,0,0,0,0,0,0,0,0,0,0,0,0,0,0,0,0,0,0
0,0,0,0,0,0,0,0,0,0,0,0,0,0,0,0,0,0,0,0,0,0,0,0,0,0,0,0,0,0,0
0,0,0,3,3,3,3,3,0,0,0,0,0,0,0,0,0,0,0,0,0,0,0,3,3,3,3,3,0,0,0
0,0,0,3,0,0,0,3,0,3,0,0,0,0,0,3,0,0,0,0,0,3,0,3,0,0,0,3,0,0,0
0,0,0,3,74,3,18,3,0,0,156,0,0,0,0,0,0,0,0,0,157,0,0,3,0,3,74,3,0,0,0
0,0,0,3,3,101,0,0,0,0,0,0,0,0,0,0,0,0,0,0,0,0,0,0,0,103,3,3,0,0,0
0,0,0,3,3,3,3,3,3,0,0,0,0,0,0,0,0,0,0,0,0,0,3,3,3,3,3,3,0,0,0
0,0,0,0,0,0,0,3,0,3,3,3,3,0,3,3,3,3,3,3,3,3,3,3,0,0,0,0,0,0,0
0,0,0,0,3,0,0,3,0,3,3,0,0,0,0,0,0,0,0,0,0,0,3,3,0,0,3,0,0,0,0
0,0,0,0,0,0,0,4,0,4,3,0,0,0,0,0,0,0,0,0,0,0,3,4,0,158,0,0,0,0,0
0,0,0,0,0,0,0,0,0,0,3,0,0,0,0,0,0,0,0,0,0,0,3,0,0,0,0,0,0,0,0
0,0,0,0,0,0,0,0,0,0,0,0,0,0,0,0,0,0,0,0,0,0,0,0,0,0,0,0,0,0,0
0,0,0,0,0,0,0,0,3,3,3,0,0,0,0,0,0,0,0,0,0,0,3,0,0,0,0,0,0,0,0
0,0,0,0,0,159,0,0,0,3,3,3,3,3,3,3,3,3,3,3,3,3,0,0,0,0,0,0,0,0,0
0,0,0,0,3,0,0,0,0,3,0,0,160,161,51,3,162,163,3,31,0,3,0,0,0,0,3,0,0,0,0
0,0,0,0,0,164,0,0,0,3,0,165,0,0,0,0,0,0,0,0,0,3,0,0,0,0,0,0,0,0,0
0,0,0,0,0,0,0,0,0,3,0,0,0,0,0,0,0,0,0,0,0,3,0,0,0,0,0,0,0,0,0
0,0,0,0,0,0,0,0,0,3,0,0,0,0,0,0,0,0,166,0,0,3,0,0,0,0,0,0,0,0,0
0,0,0,0,0,0,0,0,0,3,0,0,0,0,0,0,0,0,0,0,0,3,0,0,0,0,0,0,0,0,0
0,0,0,0,0,0,0,0,0,3,167,0,0,0,0,0,0,0,0,0,0,3,0,0,0,168,0,0,0,0,0
0,0,0,0,3,0,0,0,0,3,169,0,0,0,74,74,74,0,0,170,171,3,0,0,0,0,3,0,0,0,0
0,0,0,0,0,0,0,0,0,3,3,3,3,3,3,3,3,3,3,3,3,3,0,0,0,0,0,0,0,0,0
0,0,0,3,3,3,3,0,3,0,0,0,0,0,75,3,31,0,0,0,0,0,3,3,3,3,3,3,0,0,0
0,0,0,3,0,0,0,0,0,0,0,172,0,0,75,3,31,0,0,173,0,0,0,3,0,0,0,3,0,0,0
0,0,0,3,0,3,25,3,0,0,0,0,0,0,75,3,31,0,0,0,0,0,0,3,25,3,0,3,0,0,0
0,0,0,3,0,75,3,3,0,3,0,0,0,3,3,3,3,3,0,0,0,3,0,3,3,31,0,3,0,0,0
0,0,0,3,3,3,3,3,0,0,0,0,0,0,0,0,0,0,0,0,0,0,0,3,3,3,3,3,0,0,0
0,0,0,0,0,0,0,0,0,0,0,0,0,0,0,0,0,0,0,0,0,0,0,0,0,0,0,0,0,0,0
0,0,0,0,0,0,0,0,0,0,0,0,0,0,0,0,0,0,0,0,0,0,0,0,0,0,0,0,0,0,0
0,0,0,0,0,0,0,0,0,0,0,0,0,0,0,0,0,0,0,0,0,0,0,0,0,0,0,0,0,0,0
:endlayer
layer: 19
0,0,0,0,0,0,0,0,0,0,0,0,0,0,0,0,0,0,0,0,0,0,0,0,0,0,0,0,0,0,0
0,0,0,0,0,0,0,0,0,0,0,0,0,0,0,0,0,0,0,0,0,0,0,0,0,0,0,0,0,0,0
0,0,0,0,0,0,0,0,0,0,0,0,0,0,0,0,0,0,0,0,0,0,0,0,0,0,0,0,0,0,0
0,0,0,3,3,3,3,3,0,0,0,0,0,0,0,0,0,0,0,0,0,0,0,3,3,3,3,3,0,0,0
0,0,0,3,0,0,0,3,0,45,0,0,0,0,0,45,0,0,0,0,0,45,0,3,0,0,0,3,0,0,0
0,0,0,3,0,3,25,3,17,0,0,0,0,0,0,0,0,0,0,0,0,0,18,3,25,3,0,3,0,0,0
0,0,0,3,0,75,3,0,0,0,0,0,0,0,0,0,0,0,0,0,0,0,0,0,3,31,0,3,0,0,0
0,0,0,3,3,3,3,3,3,0,0,0,21,0,21,0,0,0,0,0,0,0,3,3,3,3,3,3,0,0,0
0,0,0,0,0,95,0,3,3,3,3,3,3,0,3,3,3,3,3,3,3,3,3,3,0,95,0,0,0,0,0
0,0,0,0,45,0,0,4,3,4,3,0,0,0,0,0,0,0,0,0,0,0,3,4,0,0,45,0,0,0,0
0,0,0,0,0,0,0,0,0,0,3,0,0,0,0,0,0,0,0,0,0,0,3,0,0,0,0,0,0,0,0
0,0,0,0,0,0,0,0,0,18,3,0,0,0,0,0,0,0,0,0,0,0,3,0,0,0,0,0,0,0,0
0,0,0,0,0,0,0,0,0,0,0,0,0,0,0,0,0,0,0,0,0,0,0,0,0,0,0,0,0,0,0
0,0,0,0,0,0,0,18,3,3,3,0,0,0,0,0,0,0,0,0,0,0,3,17,0,0,0,0,0,0,0
0,0,0,0,0,0,0,0,95,3,3,3,3,3,3,3,3,3,3,3,3,3,95,0,0,0,0,0,0,0,0
0,0,0,0,45,0,0,0,0,3,0,0,0,0,0,3,174,103,31,0,0,3,0,0,0,0,45,0,0,0,0
0,0,0,0,0,0,0,0,0,3,0,0,0,0,0,0,0,0,0,0,0,3,0,0,0,0,0,0,0,0,0
0,0,0,0,0,0,0,0,0,3,0,0,0,0,0,0,0,0,0,0,0,3,0,0,0,0,0,0,0,0,0
0,0,0,0,0,0,0,0,0,3,0,0,0,0,0,0,0,0,0,0,0,3,0,0,0,0,0,0,0,0,0
0,0,0,0,0,0,0,0,0,3,0,0,0,0,0,0,0,0,0,0,0,3,0,0,0,0,0,0,0,0,0
0,0,0,0,0,0,0,0,0,3,0,0,0,0,0,0,0,0,0,0,0,3,0,0,0,0,0,0,0,0,0
0,0,0,0,45,0,0,0,0,3,0,0,0,0,0,0,0,0,0,0,0,3,0,0,0,0,45,0,0,0,0
0,0,0,0,0,21,0,0,21,3,3,3,3,3,3,41,3,3,3,3,3,3,0,0,0,21,0,0,0,0,0
0,0,0,3,3,3,3,0,3,0,0,0,0,0,0,0,0,0,0,0,0,18,3,3,3,3,3,3,0,0,0
0,0,0,3,0,103,3,0,0,0,0,0,0,0,0,0,0,0,0,0,0,0,0,3,3,101,0,3,0,0,0
0,0,0,3,0,3,4,3,0,0,0,0,0,0,0,0,0,0,0,0,0,0,0,3,4,3,0,3,0,0,0
0,0,0,3,0,0,0,3,0,45,0,0,0,0,3,3,3,0,0,0,0,45,0,3,0,0,0,3,0,0,0
0,0,0,3,3,3,3,3,0,0,0,0,0,0,0,0,0,0,0,0,0,0,0,3,3,3,3,3,0,0,0
0,0,0,0,0,0,0,0,0,0,0,0,0,0,0,0,0,0,0,0,0,0,0,0,0,0,0,0,0,0,0
0,0,0,0,0,0,0,0,0,0,0,0,0,0,0,0,0,0,0,0,0,0,0,0,0,0,0,0,0,0,0
0,0,0,0,0,0,0,0,0,0,0,0,0,0,0,0,0,0,0,0,0,0,0,0,0,0,0,0,0,0,0
:endlayer
layer: 20
0,0,0,0,0,0,0,0,0,0,0,0,0,0,0,0,0,0,0,0,0,0,0,0,0,0,0,0,0,0,0
0,0,0,0,0,0,0,0,0,0,0,0,0,0,0,0,0,0,0,0,0,0,0,0,0,0,0,0,0,0,0
0,0,3,3,3,3,3,3,3,0,0,0,0,0,0,0,0,0,0,0,0,0,3,3,3,3,3,3,3,0,0
0,0,3,3,3,3,3,3,3,0,0,0,0,0,0,0,0,0,0,0,0,0,3,3,3,3,3,3,3,0,0
0,0,3,3,0,3,3,3,3,45,0,0,0,0,0,45,0,0,0,0,0,45,3,3,3,3,0,3,3,0,0
0,0,3,3,0,3,4,3,3,0,0,0,0,0,0,0,0,0,0,0,0,0,3,3,4,3,0,3,3,0,0
0,0,3,3,0,0,0,3,3,0,0,0,0,0,0,0,0,0,0,0,0,0,3,3,0,0,0,3,3,0,0
0,0,3,3,3,3,3,3,3,17,0,0,0,0,0,0,0,0,0,0,0,18,3,3,3,3,3,3,3,0,0
0,0,3,3,3,3,3,3,3,3,3,3,3,3,3,3,3,3,3,3,3,3,3,4,3,3,3,3,3,0,0
0,0,0,0,45,0,0,0,3,3,3,95,0,0,0,0,0,95,0,0,0,95,3,0,0,0,45,0,0,0,0
0,0,0,0,0,0,0,0,3,0,3,0,0,0,0,0,0,0,0,0,0,0,3,0,0,0,0,0,0,0,0
0,0,0,0,0,0,0,0,3,0,3,0,0,0,0,0,0,0,0,0,0,0,3,0,0,0,0,0,0,0,0
0,0,0,0,0,0,0,0,3,0,3,17,0,0,0,0,0,0,0,0,0,18,3,0,0,0,0,0,0,0,0
0,0,0,0,0,0,0,0,3,3,3,0,0,0,0,0,21,0,0,0,0,0,3,0,0,0,0,0,0,0,0
0,0,0,0,0,0,0,0,0,3,3,3,3,3,3,3,3,3,3,3,3,3,0,0,0,0,0,0,0,0,0
0,0,0,0,45,0,0,0,0,3,95,0,0,0,0,3,103,31,0,0,95,3,0,0,0,0,45,0,0,0,0
0,0,0,0,0,0,0,0,0,3,0,0,0,0,0,95,0,0,0,0,0,3,0,0,0,0,0,0,0,0,0
0,0,0,0,0,0,0,0,0,3,0,0,0,0,0,0,0,0,0,0,0,3,0,0,0,0,0,0,0,0,0
0,0,0,0,0,0,0,0,0,3,0,0,0,0,0,0,0,0,0,0,0,3,0,0,0,0,0,0,0,0,0
0,0,0,0,0,0,0,0,0,3,0,0,0,0,0,0,0,0,0,0,0,3,0,0,0,0,0,0,0,0,0
0,0,0,0,0,0,0,0,0,3,0,0,0,0,0,0,0,0,0,0,0,3,0,0,0,0,0,0,0,0,0
0,0,0,0,45,0,0,0,0,3,21,0,0,0,21,0,21,0,0,0,21,3,0,0,0,0,45,0,0,0,0
0,0,3,3,3,3,3,3,3,3,3,3,3,3,3,86,3,3,3,3,3,3,3,3,3,3,3,3,3,0,0
0,0,3,3,3,3,3,3,3,0,0,0,0,0,0,0,0,0,0,0,0,0,3,3,3,3,3,3,3,0,0
0,0,3,3,3,31,0,0,3,17,0,0,0,0,0,0,0,0,0,0,0,0,3,3,0,75,3,3,3,0,0
0,0,3,3,3,3,0,3,3,0,0,0,0,0,0,0,0,0,0,0,0,0,3,3,0,3,3,3,3,0,0
0,0,3,3,0,0,0,3,3,45,0,0,0,0,45,0,45,0,0,0,0,45,3,3,0,0,0,3,3,0,0
0,0,3,3,3,3,3,3,3,0,0,0,0,0,0,0,0,0,0,0,0,0,3,3,3,3,3,3,3,0,0
0,0,3,3,3,3,3,3,3,17,0,0,0,0,0,0,0,0,0,0,0,18,3,3,3,3,3,3,3,0,0
0,0,0,0,0,0,0,0,0,0,0,0,0,0,0,0,0,0,0,0,0,0,0,0,0,0,0,0,0,0,0
0,0,0,0,0,0,0,0,0,0,0,0,0,0,0,0,0,0,0,0,0,0,0,0,0,0,0,0,0,0,0
:endlayer
layer: 21
0,0,0,0,0,0,0,0,0,0,0,0,0,0,0,0,0,0,0,0,0,0,0,0,0,0,0,0,0,0,0
0,0,0,0,0,0,0,0,0,0,0,0,0,0,0,0,0,0,0,0,0,0,0,0,0,0,0,0,0,0,0
0,0,3,3,3,3,3,3,3,0,0,0,0,0,0,0,0,0,0,0,0,0,3,3,3,3,3,3,3,0,0
0,0,3,151,151,151,151,151,3,0,0,0,0,0,0,0,0,0,0,0,0,0,3,151,151,151,151,151,3,0,0
0,0,3,151,151,151,151,151,3,175,175,175,175,175,175,175,175,175,175,175,175,175,3,151,151,151,151,151,3,0,0
0,0,3,151,0,3,0,151,3,54,54,54,54,54,54,54,54,54,54,54,54,54,3,151,0,3,0,151,3,0,0
0,0,3,151,0,0,0,151,3,0,0,0,0,0,0,0,0,0,0,0,0,0,3,151,0,0,0,151,3,0,0
0,0,3,151,151,151,151,151,3,0,0,0,0,0,0,0,0,0,0,0,0,0,3,151,151,151,151,151,3,0,0
0,0,3,3,3,3,3,3,3,3,3,3,3,3,3,3,3,3,3,3,3,3,3,0,3,3,3,3,3,0,0
0,0,0,0,176,176,177,0,3,3,3,3,3,3,3,3,3,3,3,3,3,3,3,0,176,176,176,0,0,0,0
0,0,0,0,176,176,177,0,3,3,3,3,3,3,3,3,3,3,3,3,3,3,3,0,176,176,176,0,0,0,0
0,0,0,0,176,176,177,0,3,3,3,3,3,3,3,3,3,3,3,3,3,151,3,0,176,176,176,0,0,0,0
0,0,0,0,176,176,177,0,3,3,3,3,3,3,3,3,3,3,3,3,3,151,3,178,179,176,176,0,0,0,0
0,0,0,0,176,176,177,0,3,3,3,3,3,3,3,3,3,3,3,3,3,3,3,0,179,176,176,0,0,0,0
0,0,0,0,176,176,177,178,18,3,3,3,3,3,3,3,3,3,3,3,3,3,0,0,179,176,176,0,0,0,0
0,0,0,0,176,176,177,0,0,3,0,0,0,0,0,3,31,0,0,0,0,3,17,0,179,176,176,0,0,0,0
0,0,0,0,176,176,177,0,0,3,0,0,0,0,0,0,0,0,0,0,0,3,0,0,179,176,176,0,0,0,0
0,0,0,0,176,176,177,0,0,3,0,0,0,0,0,0,0,0,0,0,0,3,0,0,179,176,176,0,0,0,0
0,0,0,0,176,176,177,0,0,3,0,0,0,0,0,0,0,0,0,0,0,3,0,0,179,176,176,0,0,0,0
0,0,0,0,176,176,177,0,18,3,0,0,0,0,0,0,0,0,0,0,0,3,17,0,179,176,176,0,0,0,0
0,0,0,0,176,176,177,0,0,3,0,0,0,0,0,0,0,0,0,0,0,3,0,0,179,176,176,0,0,0,0
0,0,0,0,176,176,177,0,0,3,0,0,0,0,0,0,0,0,0,0,0,3,0,0,179,176,176,0,0,0,0
0,0,3,3,3,3,3,3,3,3,3,3,3,3,3,106,3,3,3,3,3,3,3,3,3,3,3,3,3,0,0
0,0,3,151,151,151,151,0,3,95,0,0,0,0,95,0,95,0,0,0,0,95,3,0,151,151,151,151,3,0,0
0,0,3,151,151,0,0,0,3,0,0,0,0,0,0,0,0,0,0,0,0,0,3,0,0,0,151,151,3,0,0
0,0,3,151,151,3,0,151,3,180,180,180,180,180,180,180,180,180,180,180,180,180,3,151,0,3,151,151,3,0,0
0,0,3,151,151,0,0,151,3,176,176,176,176,176,176,176,176,176,176,176,176,176,3,151,0,0,151,151,3,0,0
0,0,3,151,151,151,151,151,3,0,0,0,0,0,0,0,0,0,0,0,0,0,3,151,151,151,151,151,3,0,0
0,0,3,3,3,3,3,3,3,0,0,0,0,0,0,0,0,0,0,0,0,0,3,3,3,3,3,3,3,0,0
0,0,0,0,0,0,0,0,0,0,0,0,0,0,0,0,0,0,0,0,0,0,0,0,0,0,0,0,0,0,0
0,0,0,0,0,0,0,0,0,0,0,0,0,0,0,0,0,0,0,0,0,0,0,0,0,0,0,0,0,0,0
:endlayer
layer: 22
0,0,0,0,0,0,0,0,0,0,0,0,0,0,0,0,0,0,0,0,0,0,0,0,0,0,0,0,0,0,0
0,0,0,0,0,0,0,0,0,0,0,0,0,0,0,0,0,0,0,0,0,0,0,0,0,0,0,0,0,0,0
0,0,3,0,3,181,3,0,3,0,0,0,0,0,0,0,0,0,0,0,0,0,3,0,3,182,3,0,3,0,0
0,0,0,0,0,0,0,0,0,0,0,0,0,0,0,0,0,0,0,0,0,0,0,0,0,0,0,0,0,0,0
0,0,3,0,0,0,0,0,3,0,0,0,0,0,0,0,0,0,0,0,0,0,3,0,0,0,0,0,3,0,0
0,0,183,0,0,29,0,0,0,0,0,0,0,0,0,0,0,0,0,0,0,0,0,0,0,29,0,0,184,0,0
0,0,3,0,0,0,0,0,3,175,175,175,175,175,175,175,175,175,175,175,175,175,3,0,0,0,0,0,3,0,0
0,0,0,0,0,0,0,0,3,54,54,54,54,54,54,54,54,54,54,54,54,54,3,0,0,0,0,0,0,0,0
0,0,3,0,3,0,3,0,3,3,3,3,3,3,3,3,3,3,3,3,3,3,3,0,3,0,3,0,3,0,0
0,0,0,0,0,0,0,177,3,151,151,151,151,151,151,151,151,151,151,151,151,151,3,0,0,0,0,0,0,0,0
0,0,0,0,0,0,0,177,3,151,0,0,0,0,0,0,0,0,0,0,0,151,3,0,0,0,0,0,0,0,0
0,0,0,0,0,0,0,177,3,151,0,0,185,0,0,0,0,186,0,0,0,151,3,0,0,0,0,0,0,0,0
0,0,0,0,0,0,0,177,3,151,0,0,0,0,0,74,0,0,0,0,0,151,3,179,0,0,0,0,0,0,0
0,0,0,0,0,0,0,177,3,3,3,3,3,3,3,3,3,3,3,3,3,3,3,179,0,0,0,0,0,0,0
0,0,0,0,0,0,0,177,0,3,3,3,3,3,3,3,3,3,3,3,3,3,0,179,0,0,0,0,0,0,0
0,0,0,0,0,0,0,177,0,3,3,3,3,3,3,31,0,0,0,103,3,3,0,179,0,0,0,0,0,0,0
0,0,0,0,0,0,0,177,0,3,3,3,3,3,3,3,3,3,3,3,3,3,0,179,0,0,0,0,0,0,0
0,0,0,0,0,0,0,177,0,3,3,3,3,3,3,3,3,3,3,3,3,3,0,179,0,0,0,0,0,0,0
0,0,0,0,0,0,0,177,0,3,3,3,3,3,3,3,3,3,3,3,3,3,0,179,0,0,0,0,0,0,0
0,0,0,0,0,0,0,177,0,3,3,3,3,3,3,3,3,3,3,3,3,3,0,179,0,0,0,0,0,0,0
0,0,0,0,0,0,0,177,0,3,3,3,3,3,3,3,3,3,3,3,3,3,0,179,0,0,0,0,0,0,0
0,0,0,0,0,0,0,177,0,3,3,3,3,3,3,3,3,3,3,3,3,3,0,179,0,0,0,0,0,0,0
0,0,3,0,3,0,3,3,3,3,3,3,3,3,3,3,3,3,3,3,3,3,3,3,3,0,3,0,3,0,0
0,0,0,0,0,0,0,0,3,0,0,0,0,0,0,0,0,0,0,0,0,0,3,0,0,0,0,0,0,0,0
0,0,3,0,0,0,0,0,3,180,180,180,180,180,180,180,180,180,180,180,180,180,3,0,0,0,0,0,3,0,0
0,0,187,0,0,29,0,0,0,0,0,0,0,0,0,0,0,0,0,0,0,0,0,0,0,29,0,0,188,0,0
0,0,3,0,0,0,0,0,3,0,0,0,0,0,0,0,0,0,0,0,0,0,3,0,0,0,0,0,3,0,0
0,0,0,0,0,0,0,0,0,0,0,0,0,0,0,0,0,0,0,0,0,0,0,0,0,0,0,0,0,0,0
0,0,3,0,3,189,3,0,3,0,0,0,0,0,0,0,0,0,0,0,0,0,3,0,3,190,3,0,3,0,0
0,0,0,0,0,0,0,0,0,0,0,0,0,0,0,0,0,0,0,0,0,0,0,0,0,0,0,0,0,0,0
0,0,0,0,0,0,0,0,0,0,0,0,0,0,0,0,0,0,0,0,0,0,0,0,0,0,0,0,0,0,0
:endlayer
layer: 23
0,0,0,0,0,0,0,0,0,0,0,0,0,0,0,0,0,0,0,0,0,0,0,0,0,0,0,0,0,0,0
0,0,0,0,0,0,0,0,0,0,0,0,0,0,0,0,0,0,0,0,0,0,0,0,0,0,0,0,0,0,0
0,0,3,0,3,0,3,0,3,0,0,0,0,0,0,0,0,0,0,0,0,0,3,0,3,0,3,0,3,0,0
0,0,0,0,0,0,0,0,0,0,0,0,0,0,0,0,0,0,0,0,0,0,0,0,0,0,0,0,0,0,0
0,0,3,0,0,0,0,0,3,17,0,0,0,0,0,0,0,0,0,0,0,18,3,0,0,0,0,0,3,0,0
0,0,0,0,0,0,0,0,0,0,0,0,0,0,0,0,0,0,0,0,0,0,0,0,0,0,0,0,0,0,0
0,0,3,0,0,0,0,0,3,0,0,0,0,0,0,0,0,0,0,0,0,0,3,0,0,0,0,0,3,0,0
0,0,0,0,0,0,0,0,0,0,0,0,0,0,0,0,0,0,0,0,0,0,0,0,0,0,0,0,0,0,0
0,0,3,0,3,0,3,0,3,3,0,3,0,3,191,3,0,3,192,3,0,3,3,0,3,0,3,0,3,0,0
0,0,0,0,95,0,0,0,3,0,0,0,0,0,0,0,0,0,0,0,0,0,3,0,0,0,95,0,0,0,0
0,0,0,0,0,0,0,0,0,0,0,0,0,0,0,0,0,0,0,0,0,0,0,0,0,0,0,0,0,0,0
0,0,0,0,0,0,0,0,3,0,0,0,0,0,0,0,0,0,0,0,0,0,3,0,0,0,0,0,0,0,0
0,0,0,0,0,0,0,0,0,0,0,0,0,0,0,0,0,0,0,0,0,0,0,0,0,0,0,0,0,0,0
0,0,0,0,0,0,0,0,3,3,3,3,3,3,3,38,3,3,3,3,3,3,3,0,0,0,0,0,0,0,0
0,0,0,0,0,0,0,0,3,0,0,0,0,0,0,0,0,0,0,0,193,3,3,0,0,0,0,0,0,0,0
0,0,0,0,0,0,0,0,3,0,0,0,0,0,0,0,0,0,0,0,194,3,3,0,0,0,0,0,0,0,0
0,0,0,0,0,0,0,0,3,0,0,0,0,0,0,0,45,45,45,0,0,4,3,0,0,0,0,0,0,0,0
0,0,0,0,0,0,0,0,3,0,0,0,0,0,0,0,0,0,0,0,0,0,3,0,0,0,0,0,0,0,0
0,0,0,0,0,0,0,0,3,0,0,195,0,0,0,0,0,0,0,0,0,0,3,0,0,0,0,0,0,0,0
0,0,0,0,0,0,0,0,3,0,0,0,0,0,0,0,0,0,0,0,0,0,3,0,0,0,0,0,0,0,0
0,0,0,0,0,0,0,0,3,0,196,0,196,0,196,0,196,0,196,0,197,0,3,0,0,0,0,0,0,0,0
0,0,0,0,21,0,0,0,3,0,198,199,198,200,198,201,198,202,198,203,0,0,3,0,0,0,21,0,0,0,0
0,0,3,0,3,0,3,3,3,0,0,0,0,0,0,0,0,0,0,0,0,0,3,3,3,0,3,0,3,0,0
0,0,0,0,0,0,0,0,3,3,3,3,3,3,3,3,3,3,3,3,3,3,3,0,0,0,0,0,0,0,0
0,0,3,0,0,0,0,0,3,0,0,0,0,0,0,0,0,0,0,0,0,0,3,0,0,0,0,0,3,0,0
0,0,0,0,0,0,0,0,0,0,0,0,0,0,0,0,0,0,0,0,0,0,0,0,0,0,0,0,0,0,0
0,0,3,0,0,0,0,0,3,17,0,0,0,0,0,0,0,0,0,0,0,18,3,0,0,0,0,0,3,0,0
0,0,0,0,0,0,0,0,0,0,0,0,0,0,0,0,0,0,0,0,0,0,0,0,0,0,0,0,0,0,0
0,0,3,0,3,0,3,0,3,0,0,0,0,0,0,0,0,0,0,0,0,0,3,0,3,0,3,0,3,0,0
0,0,0,0,0,0,0,0,0,0,0,0,0,0,0,0,0,0,0,0,0,0,0,0,0,0,0,0,0,0,0
0,0,0,0,0,0,0,0,0,0,0,0,0,0,0,0,0,0,0,0,0,0,0,0,0,0,0,0,0,0,0
:endlayer
layer: 24
0,0,0,0,0,0,0,0,0,0,0,0,0,0,0,0,0,0,0,0,0,0,0,0,0,0,0,0,0,0,0
0,0,0,0,0,0,0,0,0,0,0,0,0,0,0,0,0,0,0,0,0,0,0,0,0,0,0,0,0,0,0
0,0,3,0,3,0,3,0,3,0,0,0,0,0,0,0,0,0,0,0,0,0,3,0,3,0,3,0,3,0,0
0,0,0,0,0,0,0,0,0,0,0,0,0,0,0,0,0,0,0,0,0,0,0,0,0,0,0,0,0,0,0
0,0,3,0,0,0,0,0,3,0,0,0,0,0,0,0,0,0,0,0,0,0,3,0,0,0,0,0,3,0,0
0,0,0,0,0,0,0,0,0,0,0,0,0,0,0,0,0,0,0,0,0,0,0,0,0,0,0,0,0,0,0
0,0,3,0,0,0,0,0,3,0,0,0,0,0,0,0,0,0,0,0,0,0,3,0,0,0,0,0,3,0,0
0,0,0,0,0,0,0,0,0,0,0,0,0,0,0,0,0,0,0,0,0,0,0,0,0,0,0,0,0,0,0
0,0,3,0,3,0,3,0,3,0,0,0,0,29,0,0,0,29,0,0,0,0,3,0,3,0,3,0,3,0,0
0,0,0,0,0,0,0,0,0,0,0,0,0,0,0,0,0,0,0,0,0,0,0,0,0,0,0,0,0,0,0
0,0,0,0,0,0,0,0,0,0,0,0,0,0,0,0,0,0,0,0,0,0,0,0,0,0,0,0,0,0,0
0,0,0,0,0,0,0,0,29,0,0,0,0,0,0,0,0,0,0,0,0,0,29,0,0,0,0,0,0,0,0
0,0,0,0,0,0,0,0,0,0,0,0,0,0,0,0,0,0,0,0,0,0,0,0,0,0,0,0,0,0,0
0,0,0,0,0,0,0,0,3,204,3,204,3,204,3,83,3,3,3,3,3,3,3,0,0,0,0,0,0,0,0
0,0,0,0,0,0,0,0,204,0,0,0,0,0,0,0,0,0,0,0,103,3,3,0,0,0,0,0,0,0,0
0,0,0,0,0,0,0,0,3,0,0,0,0,0,0,0,0,0,0,0,0,4,3,0,0,0,0,0,0,0,0
0,0,0,0,0,0,0,0,204,0,0,0,0,0,0,0,29,0,29,0,0,0,204,0,0,0,0,0,0,0,0
0,0,0,0,0,0,0,0,3,0,0,0,0,0,0,0,0,0,0,0,0,0,3,0,0,0,0,0,0,0,0
0,0,0,0,0,0,0,0,204,0,0,0,0,0,0,0,0,0,0,0,0,0,204,0,0,0,0,0,0,0,0
0,0,0,0,0,0,0,0,3,0,0,0,0,0,0,0,0,0,0,0,0,0,3,0,0,0,0,0,0,0,0
0,0,0,0,0,0,0,0,204,0,0,0,0,0,0,0,0,0,0,0,0,0,204,0,0,0,0,0,0,0,0
0,0,0,0,0,0,0,0,3,0,0,0,0,0,0,0,0,0,0,0,0,0,3,0,0,0,0,0,0,0,0
0,0,3,0,3,0,3,3,3,0,0,0,0,0,0,0,0,0,0,0,0,0,3,3,3,0,3,0,3,0,0
0,0,0,0,0,0,0,0,3,204,3,204,3,204,3,204,3,204,3,204,3,204,3,0,0,0,0,0,0,0,0
0,0,3,0,0,0,0,0,3,0,0,0,0,0,0,0,0,0,0,0,0,0,3,0,0,0,0,0,3,0,0
0,0,0,0,0,0,0,0,0,0,0,0,0,0,0,0,0,0,0,0,0,0,0,0,0,0,0,0,0,0,0
0,0,3,0,0,0,0,0,3,0,0,0,0,0,0,0,0,0,0,0,0,0,3,0,0,0,0,0,3,0,0
0,0,0,0,0,0,0,0,0,0,0,0,0,0,0,0,0,0,0,0,0,0,0,0,0,0,0,0,0,0,0
0,0,3,0,3,0,3,0,3,0,0,0,0,0,0,0,0,0,0,0,0,0,3,0,3,0,3,0,3,0,0
0,0,0,0,0,0,0,0,0,0,0,0,0,0,0,0,0,0,0,0,0,0,0,0,0,0,0,0,0,0,0
0,0,0,0,0,0,0,0,0,0,0,0,0,0,0,0,0,0,0,0,0,0,0,0,0,0,0,0,0,0,0
:endlayer
layer: 25
0,0,0,0,0,0,0,0,0,0,0,0,0,0,0,0,0,0,0,0,0,0,0,0,0,0,0,0,0,0,0
0,175,175,175,175,175,175,175,175,175,0,0,0,0,0,0,0,0,0,0,0,177,175,175,175,175,175,175,175,179,0
0,177,3,3,3,3,3,3,3,179,0,0,0,0,0,0,0,0,0,0,0,177,3,3,3,3,3,3,3,179,0
0,177,3,0,0,0,0,0,3,179,0,0,0,0,0,0,0,0,0,0,0,177,3,0,0,0,0,0,3,179,0
0,177,3,0,0,0,0,0,3,179,0,0,0,0,0,0,0,0,0,0,0,177,3,0,0,0,0,0,3,179,0
0,177,3,0,0,0,0,0,3,179,0,0,0,0,0,0,0,0,0,0,0,177,3,0,0,0,0,0,3,179,0
0,177,3,0,0,0,0,0,3,179,0,0,0,0,0,0,0,0,0,0,0,177,3,0,0,0,0,0,3,179,0
0,177,3,0,0,0,0,0,3,179,0,0,0,0,0,0,0,0,0,0,0,177,3,0,0,0,0,0,3,179,0
0,177,3,3,3,3,3,3,3,179,0,0,0,0,0,0,0,0,0,0,0,177,3,3,3,3,3,3,3,179,0
0,180,180,180,180,180,180,180,180,179,0,0,0,0,0,0,0,0,0,0,0,180,180,180,180,180,180,180,180,179,0
0,0,0,0,0,0,0,0,0,0,0,0,0,0,0,0,0,0,0,0,0,0,0,0,0,0,0,0,0,0,0
0,0,0,0,0,0,0,0,0,0,0,0,0,0,0,0,0,0,0,0,0,0,0,0,0,0,0,0,0,0,0
0,0,0,0,0,0,0,0,0,0,0,0,0,0,0,21,0,0,0,0,0,0,0,0,0,0,0,0,0,0,0
0,0,0,0,0,0,0,0,3,204,3,204,3,204,3,3,3,3,3,3,3,3,3,0,0,0,0,0,0,0,0
0,0,0,0,0,0,0,0,204,0,0,0,0,0,0,0,0,0,95,103,31,0,3,0,0,0,0,0,0,0,0
0,0,0,0,0,0,0,0,3,0,0,0,0,0,0,0,0,0,0,0,0,0,3,0,0,0,0,0,0,0,0
0,0,0,0,0,0,0,0,204,0,0,0,0,0,0,0,0,0,0,0,0,0,204,0,0,0,0,0,0,0,0
0,0,0,0,0,0,0,0,3,0,0,0,0,0,0,0,0,0,0,0,0,0,3,0,0,0,0,0,0,0,0
0,0,0,0,0,0,0,0,204,0,0,0,0,0,0,0,0,0,0,0,0,0,204,0,0,0,0,0,0,0,0
0,0,0,0,0,0,0,0,3,0,0,0,0,0,0,0,0,0,0,0,0,0,3,0,0,0,0,0,0,0,0
0,0,0,0,0,0,0,0,204,0,0,0,0,0,0,0,0,0,0,0,0,0,204,0,0,0,0,0,0,0,0
0,177,175,175,175,175,175,175,3,0,0,0,0,0,0,0,0,0,0,0,0,0,3,175,175,175,175,175,175,175,0
0,177,3,3,3,3,3,3,3,0,0,0,0,0,0,0,0,0,0,0,0,0,3,3,3,3,3,3,3,179,0
0,177,3,0,0,0,0,0,3,204,3,204,3,204,3,204,3,204,3,204,3,204,3,0,0,0,0,0,3,179,0
0,177,3,0,0,0,0,0,3,179,0,0,0,0,0,0,0,0,0,0,0,177,3,0,0,0,0,0,3,179,0
0,177,3,0,0,0,0,0,3,179,0,0,0,0,0,0,0,0,0,0,0,177,3,0,0,0,0,0,3,179,0
0,177,3,0,0,0,0,0,3,179,0,0,0,0,0,0,0,0,0,0,0,177,3,0,0,0,0,0,3,179,0
0,177,3,0,0,0,0,0,3,179,0,0,0,0,0,0,0,0,0,0,0,177,3,0,0,0,0,0,3,179,0
0,177,3,3,3,3,3,3,3,179,0,0,0,0,0,0,0,0,0,0,0,177,3,3,3,3,3,3,3,179,0
0,180,180,180,180,180,180,180,180,179,0,0,0,0,0,0,0,0,0,0,0,180,180,180,180,180,180,180,180,180,0
0,0,0,0,0,0,0,0,0,0,0,0,0,0,0,0,0,0,0,0,0,0,0,0,0,0,0,0,0,0,0
:endlayer
layer: 26
0,0,0,0,0,0,0,0,0,0,0,0,0,0,0,0,0,0,0,0,0,0,0,0,0,0,0,0,0,0,0
0,0,0,0,0,0,0,0,0,0,0,0,0,0,0,0,0,0,0,0,0,0,0,0,0,0,0,0,0,0,0
0,0,175,175,175,175,175,175,175,0,0,0,0,0,0,0,0,0,0,0,0,0,177,175,175,175,175,175,179,0,0
0,0,177,205,0,0,0,205,179,0,0,0,0,0,0,0,0,0,0,0,0,0,177,205,0,0,0,205,179,0,0
0,0,177,0,0,0,0,0,179,0,0,0,0,0,0,0,0,0,0,0,0,0,177,0,0,0,0,0,179,0,0
0,0,177,0,0,0,0,0,179,0,0,0,0,0,0,0,0,0,0,0,0,0,177,0,0,0,0,0,179,0,0
0,0,177,0,0,0,0,0,179,0,0,0,0,0,0,0,0,0,0,0,0,0,177,0,0,0,0,0,179,0,0
0,0,177,205,0,0,0,205,179,0,0,0,0,0,0,0,0,0,0,0,0,0,177,205,0,0,0,205,179,0,0
0,0,180,180,180,180,180,180,179,0,0,0,0,0,0,0,0,0,0,0,0,0,180,180,180,180,180,180,180,0,0
0,0,0,0,0,0,0,0,0,0,0,0,0,0,0,0,0,0,0,0,0,0,0,0,0,0,0,0,0,0,0
0,0,0,0,0,0,0,0,0,0,0,0,0,0,0,0,0,0,0,0,0,0,0,0,0,0,0,0,0,0,0
0,0,0,0,0,0,0,0,0,0,0,0,0,0,0,0,0,0,0,0,0,0,0,0,0,0,0,0,0,0,0
0,0,0,0,0,0,0,0,0,0,0,0,0,0,0,0,0,0,0,0,0,0,0,0,0,0,0,0,0,0,0
0,0,0,0,0,0,0,0,3,204,3,204,3,204,3,3,3,3,3,3,3,3,3,0,0,0,0,0,0,0,0
0,0,0,0,0,0,0,0,204,0,0,0,0,0,0,0,0,0,103,31,0,0,3,0,0,0,0,0,0,0,0
0,0,0,0,0,0,0,0,3,0,0,0,0,0,0,0,0,0,0,0,0,0,3,0,0,0,0,0,0,0,0
0,0,0,0,0,0,0,0,204,0,0,0,0,0,0,0,0,0,0,0,0,0,204,0,0,0,0,0,0,0,0
0,0,0,0,0,0,0,0,3,0,0,0,0,0,0,0,0,0,0,0,0,0,3,0,0,0,0,0,0,0,0
0,0,0,0,0,0,0,0,204,0,0,0,0,0,0,0,0,0,0,0,0,0,204,0,0,0,0,0,0,0,0
0,0,0,0,0,0,0,0,3,0,0,0,0,0,0,0,0,0,0,0,0,0,3,0,0,0,0,0,0,0,0
0,0,0,0,0,0,0,0,204,0,0,0,0,0,0,0,0,0,0,0,0,0,204,0,0,0,0,0,0,0,0
0,0,0,0,0,0,0,0,3,0,0,0,0,0,0,0,0,0,0,0,0,0,3,0,0,0,0,0,0,0,0
0,0,175,175,175,175,175,175,3,0,0,0,0,0,0,0,0,0,0,0,0,0,3,175,175,175,175,175,179,0,0
0,0,177,3,0,0,0,3,3,204,3,204,3,204,3,204,3,204,3,204,3,204,3,3,0,0,0,3,179,0,0
0,0,177,0,0,0,0,0,179,0,0,0,0,0,0,0,0,0,0,0,0,0,177,0,0,0,0,0,179,0,0
0,0,177,0,0,0,0,0,179,0,0,0,0,0,0,0,0,0,0,0,0,0,177,0,0,0,0,0,179,0,0
0,0,177,0,0,0,0,0,179,0,0,0,0,0,0,0,0,0,0,0,0,0,177,0,0,0,0,0,179,0,0
0,0,177,3,0,0,0,3,179,0,0,0,0,0,0,0,0,0,0,0,0,0,177,3,0,0,0,3,179,0,0
0,0,180,180,180,180,180,180,179,0,0,0,0,0,0,0,0,0,0,0,0,0,177,180,180,180,180,180,180,0,0
0,0,0,0,0,0,0,0,0,0,0,0,0,0,0,0,0,0,0,0,0,0,0,0,0,0,0,0,0,0,0
0,0,0,0,0,0,0,0,0,0,0,0,0,0,0,0,0,0,0,0,0,0,0,0,0,0,0,0,0,0,0
:endlayer
layer: 27
0,0,0,0,0,0,0,0,0,0,0,0,0,0,0,0,0,0,0,0,0,0,0,0,0,0,0,0,0,0,0
0,0,0,0,0,0,0,0,0,0,0,0,0,0,0,0,0,0,0,0,0,0,0,0,0,0,0,0,0,0,0
0,0,0,0,0,0,0,0,0,0,0,0,0,0,0,0,0,0,0,0,0,0,0,0,0,0,0,0,0,0,0
0,0,0,175,175,175,175,175,0,0,0,0,0,0,0,0,0,0,0,0,0,0,0,175,175,175,175,175,0,0,0
0,0,0,177,205,205,205,179,0,0,0,0,0,0,0,0,0,0,0,0,0,0,0,177,205,205,205,179,0,0,0
0,0,0,177,205,205,205,179,0,0,0,0,0,0,0,0,0,0,0,0,0,0,0,177,205,205,205,179,0,0,0
0,0,0,177,205,205,205,179,0,0,0,0,0,0,0,0,0,0,0,0,0,0,0,177,205,205,205,179,0,0,0
0,0,0,177,180,180,180,180,0,0,0,0,0,0,0,0,0,0,0,0,0,0,0,177,180,180,180,180,0,0,0
0,0,0,0,0,0,0,0,0,0,0,0,0,0,0,0,0,0,0,0,0,0,0,0,0,0,0,0,0,0,0
0,0,0,0,0,0,0,0,0,0,0,0,0,0,0,0,0,0,0,0,0,0,0,0,0,0,0,0,0,0,0
0,0,0,0,0,0,0,0,0,0,0,0,0,0,0,0,0,0,0,0,0,0,0,0,0,0,0,0,0,0,0
0,0,0,0,0,0,0,0,0,0,0,0,0,0,0,0,0,0,0,0,0,0,0,0,0,0,0,0,0,0,0
0,0,0,0,0,0,0,0,21,0,0,0,0,0,0,0,0,0,0,0,0,0,21,0,0,0,0,0,0,0,0
0,0,0,0,0,0,0,18,3,3,3,3,3,3,3,3,3,3,3,3,3,3,3,17,0,0,0,0,0,0,0
0,0,0,0,0,0,0,0,3,95,0,0,95,0,0,95,0,103,31,0,0,18,3,0,0,0,0,0,0,0,0
0,0,0,0,0,0,0,0,3,0,0,0,0,0,0,0,0,0,0,0,0,0,3,0,0,0,0,0,0,0,0
0,0,0,0,0,0,0,0,3,0,0,0,0,0,0,0,0,0,0,0,0,0,3,0,0,0,0,0,0,0,0
0,0,0,0,0,0,0,0,3,0,0,0,0,0,0,0,0,0,0,0,0,0,3,0,0,0,0,0,0,0,0
0,0,0,0,0,0,0,0,3,0,0,0,0,0,0,0,0,0,0,0,0,18,3,0,0,0,0,0,0,0,0
0,0,0,0,0,0,0,0,3,17,0,0,0,0,0,0,0,0,0,0,0,0,3,0,0,0,0,0,0,0,0
0,0,0,0,0,0,0,0,3,0,0,0,0,0,0,0,0,0,0,0,0,0,3,0,0,0,0,0,0,0,0
0,0,0,0,0,0,0,0,3,0,0,0,0,0,0,0,0,0,0,0,0,0,3,0,0,0,0,0,0,0,0
0,0,0,0,0,0,0,0,3,21,0,0,21,0,0,21,0,0,21,0,0,21,3,0,0,0,0,0,0,0,0
0,0,0,175,175,175,175,175,3,3,3,3,3,3,3,3,3,3,3,3,3,3,3,175,175,175,175,179,0,0,0
0,0,0,177,205,205,205,179,95,0,0,0,0,0,0,0,0,0,0,0,0,0,95,177,205,205,205,179,0,0,0
0,0,0,177,205,205,205,179,0,0,0,0,0,0,0,0,0,0,0,0,0,0,0,177,205,205,205,179,0,0,0
0,0,0,177,205,205,205,179,0,0,0,0,0,0,0,0,0,0,0,0,0,0,0,177,205,205,205,179,0,0,0
0,0,0,177,180,180,180,180,0,0,0,0,0,0,0,0,0,0,0,0,0,0,0,180,180,180,180,179,0,0,0
0,0,0,0,0,0,0,0,0,0,0,0,0,0,0,0,0,0,0,0,0,0,0,0,0,0,0,0,0,0,0
0,0,0,0,0,0,0,0,0,0,0,0,0,0,0,0,0,0,0,0,0,0,0,0,0,0,0,0,0,0,0
0,0,0,0,0,0,0,0,0,0,0,0,0,0,0,0,0,0,0,0,0,0,0,0,0,0,0,0,0,0,0
:endlayer
layer: 28
0,0,0,0,0,0,0,0,0,0,0,0,0,0,0,0,0,0,0,0,0,0,0,0,0,0,0,0,0,0,0
0,0,0,0,0,0,0,0,0,0,0,0,0,0,0,0,0,0,0,0,0,0,0,0,0,0,0,0,0,0,0
0,0,0,0,0,0,0,0,0,0,0,0,0,0,0,0,0,0,0,0,0,0,0,0,0,0,0,0,0,0,0
0,0,0,0,0,0,0,0,0,0,0,0,0,0,0,0,0,0,0,0,0,0,0,0,0,0,0,0,0,0,0
0,0,0,0,177,175,179,0,0,0,0,0,0,0,0,0,0,0,0,0,0,0,0,0,175,175,179,0,0,0,0
0,0,0,0,177,205,179,0,0,0,0,0,0,0,0,0,0,0,0,0,0,0,0,0,177,205,179,0,0,0,0
0,0,0,0,180,180,180,0,0,0,0,0,0,0,0,0,0,0,0,0,0,0,0,0,177,180,179,0,0,0,0
0,0,0,0,0,0,0,0,0,0,0,0,0,0,0,0,0,0,0,0,0,0,0,0,0,0,0,0,0,0,0
0,0,0,0,0,0,0,0,0,0,0,0,0,0,0,0,0,0,0,0,0,0,0,0,0,0,0,0,0,0,0
0,0,0,0,0,0,0,0,0,0,0,0,0,0,0,0,0,0,0,0,0,0,0,0,0,0,0,0,0,0,0
0,0,0,0,0,0,0,0,0,0,0,0,0,0,0,0,0,0,0,0,0,0,0,0,0,0,0,0,0,0,0
0,0,0,0,0,0,0,0,0,0,0,0,0,0,0,0,0,0,0,0,0,0,0,0,0,0,0,0,0,0,0
0,0,0,0,0,0,0,103,25,25,25,25,25,25,25,25,25,25,25,25,25,25,25,25,0,0,0,0,0,0,0
0,0,0,0,0,0,0,103,3,3,3,3,3,3,3,3,3,3,3,3,3,3,3,101,0,0,0,0,0,0,0
0,0,0,0,0,0,0,103,3,3,3,3,3,3,3,3,3,31,0,0,0,103,3,101,0,0,0,0,0,0,0
0,0,0,0,0,0,0,103,3,3,3,3,3,3,3,3,3,3,3,3,3,3,3,101,0,0,0,0,0,0,0
0,0,0,0,0,0,0,103,3,3,3,3,3,3,3,3,3,3,3,3,3,3,3,101,0,0,0,0,0,0,0
0,0,0,0,0,0,0,103,3,3,3,3,3,3,3,3,3,3,3,3,3,3,3,101,0,0,0,0,0,0,0
0,0,0,0,0,0,0,103,3,3,3,3,3,3,3,3,3,3,3,3,3,3,3,101,0,0,0,0,0,0,0
0,0,0,0,0,0,0,103,3,3,3,3,3,3,3,3,3,3,3,3,3,3,3,101,0,0,0,0,0,0,0
0,0,0,0,0,0,0,103,3,3,3,3,3,3,3,3,3,3,3,3,3,3,3,101,0,0,0,0,0,0,0
0,0,0,0,0,0,0,103,3,3,3,3,3,3,3,3,3,3,3,3,3,3,3,101,0,0,0,0,0,0,0
0,0,0,0,0,0,0,103,3,3,3,3,3,3,3,3,3,3,3,3,3,3,3,101,0,0,0,0,0,0,0
0,0,0,0,0,0,0,103,3,3,3,3,3,3,3,3,3,3,3,3,3,3,3,101,0,0,0,0,0,0,0
0,0,0,0,177,175,175,103,82,82,82,82,82,82,82,82,82,82,82,82,82,82,82,101,177,175,179,0,0,0,0
0,0,0,0,177,205,179,0,0,0,0,0,0,0,0,0,0,0,0,0,0,0,0,0,177,205,179,0,0,0,0
0,0,0,0,177,180,180,0,0,0,0,0,0,0,0,0,0,0,0,0,0,0,0,0,177,180,180,0,0,0,0
0,0,0,0,0,0,0,0,0,0,0,0,0,0,0,0,0,0,0,0,0,0,0,0,0,0,0,0,0,0,0
0,0,0,0,0,0,0,0,0,0,0,0,0,0,0,0,0,0,0,0,0,0,0,0,0,0,0,0,0,0,0
0,0,0,0,0,0,0,0,0,0,0,0,0,0,0,0,0,0,0,0,0,0,0,0,0,0,0,0,0,0,0
0,0,0,0,0,0,0,0,0,0,0,0,0,0,0,0,0,0,0,0,0,0,0,0,0,0,0,0,0,0,0
:endlayer
layer: 29
0,0,0,0,0,0,0,0,0,0,0,0,0,0,0,0,0,0,0,0,0,0,0,0,0,0,0,0,0,0,0
0,0,0,0,0,0,0,0,0,0,0,0,0,0,0,0,0,0,0,0,0,0,0,0,0,0,0,0,0,0,0
0,0,0,0,0,0,0,0,0,0,0,0,0,0,0,0,0,0,0,0,0,0,0,0,0,0,0,0,0,0,0
0,0,0,0,0,0,0,0,0,0,0,0,0,0,0,0,0,0,0,0,0,0,0,0,0,0,0,0,0,0,0
0,0,0,0,0,0,0,0,0,0,0,0,0,0,0,0,0,0,0,0,0,0,0,0,0,0,0,0,0,0,0
0,0,0,0,0,29,0,0,0,0,0,0,0,0,0,0,0,0,0,0,0,0,0,0,0,29,0,0,0,0,0
0,0,0,0,0,0,0,0,0,0,0,0,0,0,0,0,0,0,0,0,0,0,0,0,0,0,0,0,0,0,0
0,0,0,0,0,0,0,0,0,0,0,0,0,0,0,0,0,0,0,0,0,0,0,0,0,0,0,0,0,0,0
0,0,0,0,0,0,0,0,0,0,0,0,0,0,0,0,0,0,0,0,0,0,0,0,0,0,0,0,0,0,0
0,0,0,0,0,0,0,0,0,0,0,0,0,0,0,0,0,0,0,0,0,0,0,0,0,0,0,0,0,0,0
0,0,0,0,0,0,0,0,0,0,0,0,0,0,0,0,0,0,0,0,0,0,0,0,0,0,0,0,0,0,0
0,0,0,0,0,0,0,0,0,0,0,0,0,0,0,0,0,0,0,0,0,0,0,0,0,0,0,0,0,0,0
0,0,0,0,0,0,0,3,3,3,3,3,3,3,3,3,3,3,3,3,3,3,3,3,0,0,0,0,0,0,0
0,0,0,0,0,0,0,3,0,0,0,0,0,0,0,3,0,0,0,0,0,45,206,3,0,0,0,0,0,0,0
0,0,0,0,0,0,0,3,0,207,0,0,0,208,0,35,209,0,0,0,0,45,210,3,0,0,0,0,0,0,0
0,0,0,0,0,0,0,3,0,0,0,0,0,0,0,3,0,0,45,45,45,45,0,3,0,0,0,0,0,0,0
0,0,0,0,0,0,0,3,0,0,0,0,0,0,74,3,3,0,0,0,0,0,0,3,0,0,0,0,0,0,0
0,0,0,0,0,0,0,3,211,0,0,0,0,0,3,3,46,0,0,0,0,0,0,3,0,0,0,0,0,0,0
0,0,0,0,0,0,0,3,0,0,0,0,0,212,3,3,3,0,213,213,213,213,0,3,0,0,0,0,0,0,0
0,0,0,0,0,0,0,3,0,0,0,0,0,214,3,3,0,0,0,215,215,216,0,3,0,0,0,0,0,0,0
0,0,0,0,0,0,0,3,0,0,0,0,0,0,35,0,0,0,0,217,217,218,0,3,0,0,0,0,0,0,0
0,0,0,0,0,0,0,3,0,0,0,219,0,0,3,3,0,0,213,213,213,213,0,3,0,0,0,0,0,0,0
0,0,0,0,0,0,0,3,0,220,0,0,0,0,221,3,222,0,0,0,0,0,0,3,0,0,0,0,0,0,0
0,0,0,0,0,0,0,3,0,0,0,0,0,0,223,3,224,0,0,0,0,0,0,3,0,0,0,0,0,0,0
0,0,0,0,0,0,0,3,3,3,3,3,3,3,3,3,3,3,3,3,3,3,3,3,0,0,0,0,0,0,0
0,0,0,0,0,29,0,0,0,0,0,0,0,0,0,0,0,0,0,0,0,0,0,0,0,29,0,0,0,0,0
0,0,0,0,0,0,0,0,0,0,0,0,0,0,0,0,0,0,0,0,0,0,0,0,0,0,0,0,0,0,0
0,0,0,0,0,0,0,0,0,0,0,0,0,0,0,0,0,0,0,0,0,0,0,0,0,0,0,0,0,0,0
0,0,0,0,0,0,0,0,0,0,0,0,0,0,0,0,0,0,0,0,0,0,0,0,0,0,0,0,0,0,0
0,0,0,0,0,0,0,0,0,0,0,0,0,0,0,0,0,0,0,0,0,0,0,0,0,0,0,0,0,0,0
0,0,0,0,0,0,0,0,0,0,0,0,0,0,0,0,0,0,0,0,0,0,0,0,0,0,0,0,0,0,0
:endlayer
layer: 30
0,0,0,0,0,0,0,0,0,0,0,0,0,0,0,0,0,0,0,0,0,0,0,0,0,0,0,0,0,0,0
0,0,0,0,0,0,0,0,0,0,0,0,0,0,0,0,0,0,0,0,0,0,0,0,0,0,0,0,0,0,0
0,0,0,0,0,0,0,0,0,0,0,0,0,0,0,0,0,0,0,0,0,0,0,0,0,0,0,0,0,0,0
0,0,0,0,0,0,0,0,0,0,0,0,0,0,0,0,0,0,0,0,0,0,0,0,0,0,0,0,0,0,0
0,0,0,0,0,0,0,0,0,0,0,0,0,0,0,0,0,0,0,0,0,0,0,0,0,0,0,0,0,0,0
0,0,0,0,0,0,0,0,0,0,0,0,0,0,0,0,0,0,0,0,0,0,0,0,0,0,0,0,0,0,0
0,0,0,0,0,0,0,0,0,0,0,0,0,0,0,0,0,0,0,0,0,0,0,0,0,0,0,0,0,0,0
0,0,0,0,0,0,0,0,0,0,0,0,0,0,0,0,0,0,0,0,0,0,0,0,0,0,0,0,0,0,0
0,0,0,0,0,0,0,0,0,0,0,0,0,0,0,0,0,0,0,0,0,0,0,0,0,0,0,0,0,0,0
0,0,0,0,0,0,0,0,0,0,0,0,0,0,0,0,0,0,0,0,0,0,0,0,0,0,0,0,0,0,0
0,0,0,0,0,0,0,0,0,0,0,0,0,0,0,0,0,0,0,0,0,0,0,0,0,0,0,0,0,0,0
0,0,0,0,0,0,0,0,0,0,0,0,0,0,0,0,0,0,0,0,0,0,0,0,0,0,0,0,0,0,0
0,0,0,0,0,0,0,3,204,3,204,3,204,3,204,3,204,3,204,3,204,3,204,3,0,0,0,0,0,0,0
0,0,0,0,0,0,0,204,0,0,0,0,0,0,0,3,0,0,0,0,0,0,0,204,0,0,0,0,0,0,0
0,0,0,0,0,0,0,3,0,0,0,0,0,0,0,83,0,0,0,0,0,0,0,3,0,0,0,0,0,0,0
0,0,0,0,0,0,0,204,0,0,0,0,0,0,0,3,0,0,0,0,0,0,0,204,0,0,0,0,0,0,0
0,0,0,0,0,0,0,3,0,0,0,0,0,0,0,3,3,0,0,0,0,0,0,3,0,0,0,0,0,0,0
0,0,0,0,0,0,0,204,0,0,0,0,0,0,74,3,0,0,0,0,0,0,0,204,0,0,0,0,0,0,0
0,0,0,0,0,0,0,3,0,0,0,0,0,0,3,3,3,0,225,0,0,225,0,3,0,0,0,0,0,0,0
0,0,0,0,0,0,0,204,0,0,0,0,0,0,3,3,0,0,0,0,0,0,0,204,0,0,0,0,0,0,0
0,0,0,0,0,0,0,3,0,0,0,0,0,0,83,0,0,0,0,0,0,0,0,3,0,0,0,0,0,0,0
0,0,0,0,0,0,0,204,0,0,0,0,0,0,3,3,0,0,225,0,0,225,0,204,0,0,0,0,0,0,0
0,0,0,0,0,0,0,3,0,0,0,0,0,0,0,3,0,0,0,0,0,0,0,3,0,0,0,0,0,0,0
0,0,0,0,0,0,0,204,0,0,0,0,0,0,0,3,0,0,0,0,0,0,0,204,0,0,0,0,0,0,0
0,0,0,0,0,0,0,3,204,3,204,3,204,3,204,3,204,3,204,3,204,3,204,3,0,0,0,0,0,0,0
0,0,0,0,0,0,0,0,0,0,0,0,0,0,0,0,0,0,0,0,0,0,0,0,0,0,0,0,0,0,0
0,0,0,0,0,0,0,0,0,0,0,0,0,0,0,0,0,0,0,0,0,0,0,0,0,0,0,0,0,0,0
0,0,0,0,0,0,0,0,0,0,0,0,0,0,0,0,0,0,0,0,0,0,0,0,0,0,0,0,0,0,0
0,0,0,0,0,0,0,0,0,0,0,0,0,0,0,0,0,0,0,0,0,0,0,0,0,0,0,0,0,0,0
0,0,0,0,0,0,0,0,0,0,0,0,0,0,0,0,0,0,0,0,0,0,0,0,0,0,0,0,0,0,0
0,0,0,0,0,0,0,0,0,0,0,0,0,0,0,0,0,0,0,0,0,0,0,0,0,0,0,0,0,0,0
:endlayer
layer: 31
0,0,0,0,0,0,0,0,0,0,0,0,0,0,0,0,0,0,0,0,0,0,0,0,0,0,0,0,0,0,0
0,0,0,0,0,0,0,0,0,0,0,0,0,0,0,0,0,0,0,0,0,0,0,0,0,0,0,0,0,0,0
0,0,0,0,0,0,0,0,0,0,0,0,0,0,0,0,0,0,0,0,0,0,0,0,0,0,0,0,0,0,0
0,0,0,0,0,0,0,0,0,0,0,0,0,0,0,0,0,0,0,0,0,0,0,0,0,0,0,0,0,0,0
0,0,0,0,0,0,0,0,0,0,0,0,0,0,0,0,0,0,0,0,0,0,0,0,0,0,0,0,0,0,0
0,0,0,0,0,0,0,0,0,0,0,0,0,0,0,0,0,0,0,0,0,0,0,0,0,0,0,0,0,0,0
0,0,0,0,0,0,0,0,0,0,0,0,0,0,0,0,0,0,0,0,0,0,0,0,0,0,0,0,0,0,0
0,0,0,0,0,0,0,0,0,0,0,0,0,0,0,0,0,0,0,0,0,0,0,0,0,0,0,0,0,0,0
0,0,0,0,0,0,0,0,0,0,0,0,0,0,0,0,0,0,0,0,0,0,0,0,0,0,0,0,0,0,0
0,0,0,0,0,0,0,0,0,0,0,0,0,0,0,0,0,0,0,0,0,0,0,0,0,0,0,0,0,0,0
0,0,0,0,0,0,0,0,0,0,0,0,0,0,0,0,0,0,0,0,0,0,0,0,0,0,0,0,0,0,0
0,0,0,0,0,0,0,0,0,0,0,0,0,0,0,0,0,0,0,0,0,0,0,0,0,0,0,0,0,0,0
0,0,0,0,0,0,0,3,204,3,204,3,204,3,204,3,204,3,204,3,204,3,204,3,0,0,0,0,0,0,0
0,0,0,0,0,0,0,204,0,0,0,0,0,0,0,3,0,0,0,0,0,0,0,204,0,0,0,0,0,0,0
0,0,0,0,0,0,0,3,0,0,0,0,0,0,0,3,17,0,0,0,0,0,0,3,0,0,0,0,0,0,0
0,0,0,0,0,0,0,204,0,0,0,0,0,0,0,3,0,0,0,0,0,0,0,204,0,0,0,0,0,0,0
0,0,0,0,0,0,0,3,0,0,0,0,0,0,0,3,3,0,0,0,0,0,0,3,0,0,0,0,0,0,0
0,0,0,0,0,0,0,204,0,0,0,0,0,0,0,3,31,0,0,0,0,0,0,204,0,0,0,0,0,0,0
0,0,0,0,0,0,0,3,0,0,0,0,0,0,74,3,3,0,225,0,0,225,0,3,0,0,0,0,0,0,0
0,0,0,0,0,0,0,204,0,0,0,0,0,0,3,3,0,0,0,0,0,0,0,204,0,0,0,0,0,0,0
0,0,0,0,0,0,0,3,0,0,0,0,0,18,3,3,17,0,0,0,0,0,0,3,0,0,0,0,0,0,0
0,0,0,0,0,0,0,204,0,0,0,0,0,0,3,3,0,0,225,0,0,225,0,204,0,0,0,0,0,0,0
0,0,0,0,0,0,0,3,0,0,0,0,0,0,0,3,0,0,0,0,0,0,0,3,0,0,0,0,0,0,0
0,0,0,0,0,0,0,204,0,0,0,0,0,0,0,3,0,0,0,0,0,0,0,204,0,0,0,0,0,0,0
0,0,0,0,0,0,0,3,204,3,204,3,204,3,204,3,204,3,204,3,204,3,204,3,0,0,0,0,0,0,0
0,0,0,0,0,0,0,0,0,0,0,0,0,0,0,0,0,0,0,0,0,0,0,0,0,0,0,0,0,0,0
0,0,0,0,0,0,0,0,0,0,0,0,0,0,0,0,0,0,0,0,0,0,0,0,0,0,0,0,0,0,0
0,0,0,0,0,0,0,0,0,0,0,0,0,0,0,0,0,0,0,0,0,0,0,0,0,0,0,0,0,0,0
0,0,0,0,0,0,0,0,0,0,0,0,0,0,0,0,0,0,0,0,0,0,0,0,0,0,0,0,0,0,0
0,0,0,0,0,0,0,0,0,0,0,0,0,0,0,0,0,0,0,0,0,0,0,0,0,0,0,0,0,0,0
0,0,0,0,0,0,0,0,0,0,0,0,0,0,0,0,0,0,0,0,0,0,0,0,0,0,0,0,0,0,0
:endlayer
layer: 32
0,0,0,0,0,0,0,0,0,0,0,0,0,0,0,0,0,0,0,0,0,0,0,0,0,0,0,0,0,0,0
0,0,0,0,0,0,0,0,0,0,0,0,0,0,0,0,0,0,0,0,0,0,0,0,0,0,0,0,0,0,0
0,0,0,0,0,0,0,0,0,0,0,0,0,0,0,0,0,0,0,0,0,0,0,0,0,0,0,0,0,0,0
0,0,0,0,0,0,0,0,0,0,0,0,0,0,0,0,0,0,0,0,0,0,0,0,0,0,0,0,0,0,0
0,0,0,0,0,0,0,0,0,0,0,0,0,0,0,0,0,0,0,0,0,0,0,0,0,0,0,0,0,0,0
0,0,0,0,0,0,0,0,0,0,0,0,0,0,0,0,0,0,0,0,0,0,0,0,0,0,0,0,0,0,0
0,0,0,0,0,0,0,0,0,0,0,0,0,0,0,0,0,0,0,0,0,0,0,0,0,0,0,0,0,0,0
0,0,0,0,0,0,0,0,0,0,0,0,0,0,0,0,0,0,0,0,0,0,0,0,0,0,0,0,0,0,0
0,0,0,0,0,0,0,0,0,0,0,0,0,0,0,0,0,0,0,0,0,0,0,0,0,0,0,0,0,0,0
0,0,0,0,0,0,0,0,0,0,0,0,0,0,0,0,0,0,0,0,0,0,0,0,0,0,0,0,0,0,0
0,0,0,0,0,0,0,0,0,0,0,0,0,0,0,0,0,0,0,0,0,0,0,0,0,0,0,0,0,0,0
0,0,0,0,0,0,0,0,0,0,0,0,0,0,0,0,0,0,0,0,0,0,0,0,0,0,0,0,0,0,0
0,0,0,0,0,0,0,3,3,3,3,3,3,3,3,3,3,3,3,3,3,3,3,3,0,0,0,0,0,0,0
0,0,0,0,0,0,0,3,17,0,0,0,0,0,18,3,95,0,0,95,0,0,95,3,0,0,0,0,0,0,0
0,0,0,0,0,0,0,3,0,0,0,0,0,0,0,3,0,0,0,0,0,0,0,3,0,0,0,0,0,0,0
0,0,0,0,0,0,0,3,0,0,0,0,0,0,0,3,0,0,0,0,0,0,0,3,0,0,0,0,0,0,0
0,0,0,0,0,0,0,3,0,0,0,0,0,0,0,3,3,0,0,0,0,0,0,3,0,0,0,0,0,0,0
0,0,0,0,0,0,0,3,0,0,0,0,0,0,0,3,101,0,0,0,0,0,0,3,0,0,0,0,0,0,0
0,0,0,0,0,0,0,3,17,0,0,0,0,0,0,3,3,0,225,0,0,225,18,3,0,0,0,0,0,0,0
0,0,0,0,0,0,0,3,0,0,0,0,0,0,74,3,0,0,0,0,0,0,0,3,0,0,0,0,0,0,0
0,0,0,0,0,0,0,3,0,0,0,0,0,0,3,3,0,0,0,0,0,0,18,3,0,0,0,0,0,0,0
0,0,0,0,0,0,0,3,0,0,0,0,0,0,3,3,0,0,225,0,0,225,0,3,0,0,0,0,0,0,0
0,0,0,0,0,0,0,3,0,0,0,0,0,0,0,3,0,0,0,0,0,0,0,3,0,0,0,0,0,0,0
0,0,0,0,0,0,0,3,21,0,0,0,0,0,21,3,21,0,0,0,0,0,21,3,0,0,0,0,0,0,0
0,0,0,0,0,0,0,3,3,3,3,3,3,3,3,3,3,3,3,3,3,3,3,3,0,0,0,0,0,0,0
0,0,0,0,0,0,0,0,0,0,0,0,0,0,0,0,0,0,0,0,0,0,0,0,0,0,0,0,0,0,0
0,0,0,0,0,0,0,0,0,0,0,0,0,0,0,0,0,0,0,0,0,0,0,0,0,0,0,0,0,0,0
0,0,0,0,0,0,0,0,0,0,0,0,0,0,0,0,0,0,0,0,0,0,0,0,0,0,0,0,0,0,0
0,0,0,0,0,0,0,0,0,0,0,0,0,0,0,0,0,0,0,0,0,0,0,0,0,0,0,0,0,0,0
0,0,0,0,0,0,0,0,0,0,0,0,0,0,0,0,0,0,0,0,0,0,0,0,0,0,0,0,0,0,0
0,0,0,0,0,0,0,0,0,0,0,0,0,0,0,0,0,0,0,0,0,0,0,0,0,0,0,0,0,0,0
:endlayer
layer: 33
0,0,0,0,0,0,0,0,0,0,0,0,0,0,0,0,0,0,0,0,0,0,0,0,0,0,0,0,0,0,0
0,0,0,0,0,0,0,0,0,0,0,0,0,0,0,0,0,0,0,0,0,0,0,0,0,0,0,0,0,0,0
0,0,0,0,0,0,0,0,0,0,0,0,0,0,0,0,0,0,0,0,0,0,0,0,0,0,0,0,0,0,0
0,0,0,0,0,0,0,0,0,0,0,0,0,0,0,0,0,0,0,0,0,0,0,0,0,0,0,0,0,0,0
0,0,0,0,0,0,0,0,0,0,0,0,0,0,0,0,0,0,0,0,0,0,0,0,0,0,0,0,0,0,0
0,0,0,0,0,0,0,0,0,0,0,0,0,0,0,0,0,0,0,0,0,0,0,0,0,0,0,0,0,0,0
0,0,0,0,0,0,0,0,0,0,0,0,0,0,0,0,0,0,0,0,0,0,0,0,0,0,0,0,0,0,0
0,0,0,0,0,0,0,0,0,0,0,0,0,0,0,0,0,0,0,0,0,0,0,0,0,0,0,0,0,0,0
0,0,0,0,0,0,0,0,0,0,0,0,0,0,0,0,0,0,0,0,0,0,0,0,0,0,0,0,0,0,0
0,0,0,0,0,0,0,0,0,0,0,0,0,0,0,0,0,0,0,0,0,0,0,0,0,0,0,0,0,0,0
0,0,0,0,0,0,0,0,0,0,0,0,0,0,0,0,0,0,0,0,0,0,0,0,0,0,0,0,0,0,0
0,0,0,0,0,0,177,175,175,175,175,175,175,175,175,175,175,175,175,175,175,175,175,175,179,0,0,0,0,0,0
0,0,0,0,0,0,177,3,3,3,3,3,3,3,3,3,3,3,3,3,3,3,3,3,179,0,0,0,0,0,0
0,0,0,0,0,0,177,3,0,0,0,0,0,0,0,3,0,0,0,0,0,0,0,3,179,0,0,0,0,0,0
0,0,0,0,0,0,177,3,0,0,0,0,0,0,0,3,0,0,0,0,0,0,0,3,179,0,0,0,0,0,0
0,0,0,0,0,0,177,3,0,0,0,0,0,0,0,3,0,0,0,0,0,0,0,3,179,0,0,0,0,0,0
0,0,0,0,0,0,177,3,0,0,0,0,0,0,0,3,3,0,0,0,0,0,0,3,179,0,0,0,0,0,0
0,0,0,0,0,0,177,3,0,0,0,0,0,0,0,3,3,0,0,0,0,0,0,3,179,0,0,0,0,0,0
0,0,0,0,0,0,177,3,0,0,0,0,0,0,0,3,3,0,213,213,213,213,0,3,179,0,0,0,0,0,0
0,0,0,0,0,0,177,3,0,0,0,0,0,0,0,3,0,0,213,0,0,213,0,3,179,0,0,0,0,0,0
0,0,0,0,0,0,177,3,0,0,0,0,0,0,74,3,0,0,213,0,0,213,0,3,179,0,0,0,0,0,0
0,0,0,0,0,0,177,3,0,0,0,0,0,0,3,3,0,0,213,213,213,213,0,3,179,0,0,0,0,0,0
0,0,0,0,0,0,177,3,0,0,0,0,0,0,0,3,0,0,0,0,0,0,0,3,179,0,0,0,0,0,0
0,0,0,0,0,0,177,3,0,0,0,0,0,0,0,3,0,0,0,0,0,0,0,3,179,0,0,0,0,0,0
0,0,0,0,0,0,177,3,3,3,3,3,3,3,3,3,3,3,3,3,3,3,3,3,179,0,0,0,0,0,0
0,0,0,0,0,0,177,180,180,180,180,180,180,180,180,180,180,180,180,180,180,180,180,180,180,0,0,0,0,0,0
0,0,0,0,0,0,0,0,0,0,0,0,0,0,0,0,0,0,0,0,0,0,0,0,0,0,0,0,0,0,0
0,0,0,0,0,0,0,0,0,0,0,0,0,0,0,0,0,0,0,0,0,0,0,0,0,0,0,0,0,0,0
0,0,0,0,0,0,0,0,0,0,0,0,0,0,0,0,0,0,0,0,0,0,0,0,0,0,0,0,0,0,0
0,0,0,0,0,0,0,0,0,0,0,0,0,0,0,0,0,0,0,0,0,0,0,0,0,0,0,0,0,0,0
0,0,0,0,0,0,0,0,0,0,0,0,0,0,0,0,0,0,0,0,0,0,0,0,0,0,0,0,0,0,0
:endlayer
layer: 34
0,0,0,0,0,0,0,0,0,0,0,0,0,0,0,0,0,0,0,0,0,0,0,0,0,0,0,0,0,0,0
0,0,0,0,0,0,0,0,0,0,0,0,0,0,0,0,0,0,0,0,0,0,0,0,0,0,0,0,0,0,0
0,0,0,0,0,0,0,0,0,0,0,0,0,0,0,0,0,0,0,0,0,0,0,0,0,0,0,0,0,0,0
0,0,0,0,0,0,0,0,0,0,0,0,0,0,0,0,0,0,0,0,0,0,0,0,0,0,0,0,0,0,0
0,0,0,0,0,0,0,0,0,0,0,0,0,0,0,0,0,0,0,0,0,0,0,0,0,0,0,0,0,0,0
0,0,0,0,0,0,0,0,0,0,0,0,0,0,0,0,0,0,0,0,0,0,0,0,0,0,0,0,0,0,0
0,0,0,0,0,0,0,0,0,0,0,0,0,0,0,0,0,0,0,0,0,0,0,0,0,0,0,0,0,0,0
0,0,0,0,0,0,0,0,0,0,0,0,0,0,0,0,0,0,0,0,0,0,0,0,0,0,0,0,0,0,0
0,0,0,0,0,0,0,0,0,0,0,0,0,0,0,0,0,0,0,0,0,0,0,0,0,0,0,0,0,0,0
0,0,0,0,0,0,0,0,0,0,0,0,0,0,0,0,0,0,0,0,0,0,0,0,0,0,0,0,0,0,0
0,0,0,0,0,0,0,0,0,0,0,0,0,0,0,0,0,0,0,0,0,0,0,0,0,0,0,0,0,0,0
0,0,0,0,0,0,0,0,0,0,0,0,0,0,0,0,0,0,0,0,0,0,0,0,0,0,0,0,0,0,0
0,0,0,0,0,0,0,205,175,175,175,175,175,175,175,175,175,175,175,175,175,175,175,205,0,0,0,0,0,0,0
0,0,0,0,0,0,0,177,205,205,205,205,205,205,205,205,205,205,205,205,205,205,205,179,0,0,0,0,0,0,0
0,0,0,0,0,0,0,177,205,205,205,205,205,205,205,205,205,205,205,205,205,205,205,179,0,0,0,0,0,0,0
0,0,0,0,0,0,0,177,205,205,205,205,205,205,205,205,205,205,205,205,205,205,205,179,0,0,0,0,0,0,0
0,0,0,0,0,0,0,177,205,205,205,205,205,205,205,205,205,205,205,205,205,205,205,179,0,0,0,0,0,0,0
0,0,0,0,0,0,0,177,205,205,205,205,205,205,0,205,205,205,205,205,205,205,205,179,0,0,0,0,0,0,0
0,0,0,0,0,0,0,177,205,205,205,205,205,205,0,205,205,205,205,205,205,205,205,179,0,0,0,0,0,0,0
0,0,0,0,0,0,0,177,205,205,205,205,205,205,0,205,205,205,205,205,205,205,205,179,0,0,0,0,0,0,0
0,0,0,0,0,0,0,177,205,205,205,205,205,205,0,205,205,205,205,205,205,205,205,179,0,0,0,0,0,0,0
0,0,0,0,0,0,0,177,205,205,205,205,205,205,175,205,205,205,205,205,205,205,205,179,0,0,0,0,0,0,0
0,0,0,0,0,0,0,177,205,205,205,205,205,205,205,205,205,205,205,205,205,205,205,179,0,0,0,0,0,0,0
0,0,0,0,0,0,0,177,205,205,205,205,205,205,205,205,205,205,205,205,205,205,205,179,0,0,0,0,0,0,0
0,0,0,0,0,0,0,205,180,180,180,180,180,180,180,180,180,180,180,180,180,180,180,205,0,0,0,0,0,0,0
0,0,0,0,0,0,0,0,0,0,0,0,0,0,0,0,0,0,0,0,0,0,0,0,0,0,0,0,0,0,0
0,0,0,0,0,0,0,0,0,0,0,0,0,0,0,0,0,0,0,0,0,0,0,0,0,0,0,0,0,0,0
0,0,0,0,0,0,0,0,0,0,0,0,0,0,0,0,0,0,0,0,0,0,0,0,0,0,0,0,0,0,0
0,0,0,0,0,0,0,0,0,0,0,0,0,0,0,0,0,0,0,0,0,0,0,0,0,0,0,0,0,0,0
0,0,0,0,0,0,0,0,0,0,0,0,0,0,0,0,0,0,0,0,0,0,0,0,0,0,0,0,0,0,0
0,0,0,0,0,0,0,0,0,0,0,0,0,0,0,0,0,0,0,0,0,0,0,0,0,0,0,0,0,0,0
:endlayer
layer: 35
0,0,0,0,0,0,0,0,0,0,0,0,0,0,0,0,0,0,0,0,0,0,0,0,0,0,0,0,0,0,0
0,0,0,0,0,0,0,0,0,0,0,0,0,0,0,0,0,0,0,0,0,0,0,0,0,0,0,0,0,0,0
0,0,0,0,0,0,0,0,0,0,0,0,0,0,0,0,0,0,0,0,0,0,0,0,0,0,0,0,0,0,0
0,0,0,0,0,0,0,0,0,0,0,0,0,0,0,0,0,0,0,0,0,0,0,0,0,0,0,0,0,0,0
0,0,0,0,0,0,0,0,0,0,0,0,0,0,0,0,0,0,0,0,0,0,0,0,0,0,0,0,0,0,0
0,0,0,0,0,0,0,0,0,0,0,0,0,0,0,0,0,0,0,0,0,0,0,0,0,0,0,0,0,0,0
0,0,0,0,0,0,0,0,0,0,0,0,0,0,0,0,0,0,0,0,0,0,0,0,0,0,0,0,0,0,0
0,0,0,0,0,0,0,0,0,0,0,0,0,0,0,0,0,0,0,0,0,0,0,0,0,0,0,0,0,0,0
0,0,0,0,0,0,0,0,0,0,0,0,0,0,0,0,0,0,0,0,0,0,0,0,0,0,0,0,0,0,0
0,0,0,0,0,0,0,0,0,0,0,0,0,0,0,0,0,0,0,0,0,0,0,0,0,0,0,0,0,0,0
0,0,0,0,0,0,0,0,0,0,0,0,0,0,0,0,0,0,0,0,0,0,0,0,0,0,0,0,0,0,0
0,0,0,0,0,0,0,0,0,0,0,0,0,0,0,0,0,0,0,0,0,0,0,0,0,0,0,0,0,0,0
0,0,0,0,0,0,0,29,0,0,0,0,0,0,0,0,0,0,0,0,0,0,0,29,0,0,0,0,0,0,0
0,0,0,0,0,0,0,0,175,175,175,175,175,175,175,175,175,175,175,175,175,175,179,0,0,0,0,0,0,0,0
0,0,0,0,0,0,0,0,177,205,0,0,0,0,0,0,0,0,0,0,0,205,179,0,0,0,0,0,0,0,0
0,0,0,0,0,0,0,0,177,0,205,0,0,0,0,0,0,0,0,0,205,0,179,0,0,0,0,0,0,0,0
0,0,0,0,0,0,0,0,177,0,0,0,0,45,45,45,0,0,0,0,226,0,179,0,0,0,0,0,0,0,0
0,0,0,0,0,0,0,0,177,0,0,0,0,45,0,45,0,0,0,0,0,0,179,0,0,0,0,0,0,0,0
0,0,0,0,0,0,0,0,177,0,0,0,0,45,0,45,0,0,0,0,0,0,179,0,0,0,0,0,0,0,0
0,0,0,0,0,0,0,0,177,0,0,0,0,45,0,45,0,0,0,0,0,0,179,0,0,0,0,0,0,0,0
0,0,0,0,0,0,0,0,177,0,0,0,0,45,0,45,0,0,0,0,0,0,179,0,0,0,0,0,0,0,0
0,0,0,0,0,0,0,0,177,0,205,0,0,0,0,0,0,0,0,0,205,0,179,0,0,0,0,0,0,0,0
0,0,0,0,0,0,0,0,177,205,0,0,0,0,0,0,0,0,0,0,0,205,179,0,0,0,0,0,0,0,0
0,0,0,0,0,0,0,0,180,180,180,180,180,180,180,180,180,180,180,180,180,180,180,0,0,0,0,0,0,0,0
0,0,0,0,0,0,0,29,0,0,0,0,0,0,0,0,0,0,0,0,0,0,0,29,0,0,0,0,0,0,0
0,0,0,0,0,0,0,0,0,0,0,0,0,0,0,0,0,0,0,0,0,0,0,0,0,0,0,0,0,0,0
0,0,0,0,0,0,0,0,0,0,0,0,0,0,0,0,0,0,0,0,0,0,0,0,0,0,0,0,0,0,0
0,0,0,0,0,0,0,0,0,0,0,0,0,0,0,0,0,0,0,0,0,0,0,0,0,0,0,0,0,0,0
0,0,0,0,0,0,0,0,0,0,0,0,0,0,0,0,0,0,0,0,0,0,0,0,0,0,0,0,0,0,0
0,0,0,0,0,0,0,0,0,0,0,0,0,0,0,0,0,0,0,0,0,0,0,0,0,0,0,0,0,0,0
0,0,0,0,0,0,0,0,0,0,0,0,0,0,0,0,0,0,0,0,0,0,0,0,0,0,0,0,0,0,0
:endlayer
layer: 36
0,0,0,0,0,0,0,0,0,0,0,0,0,0,0,0,0,0,0,0,0,0,0,0,0,0,0,0,0,0,0
0,0,0,0,0,0,0,0,0,0,0,0,0,0,0,0,0,0,0,0,0,0,0,0,0,0,0,0,0,0,0
0,0,0,0,0,0,0,0,0,0,0,0,0,0,0,0,0,0,0,0,0,0,0,0,0,0,0,0,0,0,0
0,0,0,0,0,0,0,0,0,0,0,0,0,0,0,0,0,0,0,0,0,0,0,0,0,0,0,0,0,0,0
0,0,0,0,0,0,0,0,0,0,0,0,0,0,0,0,0,0,0,0,0,0,0,0,0,0,0,0,0,0,0
0,0,0,0,0,0,0,0,0,0,0,0,0,0,0,0,0,0,0,0,0,0,0,0,0,0,0,0,0,0,0
0,0,0,0,0,0,0,0,0,0,0,0,0,0,0,0,0,0,0,0,0,0,0,0,0,0,0,0,0,0,0
0,0,0,0,0,0,0,0,0,0,0,0,0,0,0,0,0,0,0,0,0,0,0,0,0,0,0,0,0,0,0
0,0,0,0,0,0,0,0,0,0,0,0,0,0,0,0,0,0,0,0,0,0,0,0,0,0,0,0,0,0,0
0,0,0,0,0,0,0,0,0,0,0,0,0,0,0,0,0,0,0,0,0,0,0,0,0,0,0,0,0,0,0
0,0,0,0,0,0,0,0,0,0,0,0,0,0,0,0,0,0,0,0,0,0,0,0,0,0,0,0,0,0,0
0,0,0,0,0,0,0,0,0,0,0,0,0,0,0,0,0,0,0,0,0,0,0,0,0,0,0,0,0,0,0
0,0,0,0,0,0,0,0,0,0,0,0,0,0,0,0,0,0,0,0,0,0,0,0,0,0,0,0,0,0,0
0,0,0,0,0,0,0,0,0,0,0,0,0,0,0,0,0,0,0,0,0,0,0,0,0,0,0,0,0,0,0
0,0,0,0,0,0,0,0,0,177,175,175,175,175,175,175,175,175,175,175,175,179,0,0,0,0,0,0,0,0,0
0,0,0,0,0,0,0,0,0,177,205,17,0,0,0,0,0,0,0,18,205,179,0,0,0,0,0,0,0,0,0
0,0,0,0,0,0,0,0,0,177,95,0,0,29,0,29,0,0,0,0,95,179,0,0,0,0,0,0,0,0,0
0,0,0,0,0,0,0,0,0,177,0,0,0,0,0,0,0,0,0,0,0,179,0,0,0,0,0,0,0,0,0
0,0,0,0,0,0,0,0,0,177,0,0,0,0,0,0,0,0,0,0,0,179,0,0,0,0,0,0,0,0,0
0,0,0,0,0,0,0,0,0,177,0,0,0,29,0,29,0,0,0,0,0,179,0,0,0,0,0,0,0,0,0
0,0,0,0,0,0,0,0,0,177,21,0,0,0,0,0,0,0,0,0,21,179,0,0,0,0,0,0,0,0,0
0,0,0,0,0,0,0,0,0,177,205,17,0,0,0,0,0,0,0,18,205,179,0,0,0,0,0,0,0,0,0
0,0,0,0,0,0,0,0,0,180,180,180,180,180,180,180,180,180,180,180,180,179,0,0,0,0,0,0,0,0,0
0,0,0,0,0,0,0,0,0,0,0,0,0,0,0,0,0,0,0,0,0,0,0,0,0,0,0,0,0,0,0
0,0,0,0,0,0,0,0,0,0,0,0,0,0,0,0,0,0,0,0,0,0,0,0,0,0,0,0,0,0,0
0,0,0,0,0,0,0,0,0,0,0,0,0,0,0,0,0,0,0,0,0,0,0,0,0,0,0,0,0,0,0
0,0,0,0,0,0,0,0,0,0,0,0,0,0,0,0,0,0,0,0,0,0,0,0,0,0,0,0,0,0,0
0,0,0,0,0,0,0,0,0,0,0,0,0,0,0,0,0,0,0,0,0,0,0,0,0,0,0,0,0,0,0
0,0,0,0,0,0,0,0,0,0,0,0,0,0,0,0,0,0,0,0,0,0,0,0,0,0,0,0,0,0,0
0,0,0,0,0,0,0,0,0,0,0,0,0,0,0,0,0,0,0,0,0,0,0,0,0,0,0,0,0,0,0
0,0,0,0,0,0,0,0,0,0,0,0,0,0,0,0,0,0,0,0,0,0,0,0,0,0,0,0,0,0,0
:endlayer
layer: 37
0,0,0,0,0,0,0,0,0,0,0,0,0,0,0,0,0,0,0,0,0,0,0,0,0,0,0,0,0,0,0
0,0,0,0,0,0,0,0,0,0,0,0,0,0,0,0,0,0,0,0,0,0,0,0,0,0,0,0,0,0,0
0,0,0,0,0,0,0,0,0,0,0,0,0,0,0,0,0,0,0,0,0,0,0,0,0,0,0,0,0,0,0
0,0,0,0,0,0,0,0,0,0,0,0,0,0,0,0,0,0,0,0,0,0,0,0,0,0,0,0,0,0,0
0,0,0,0,0,0,0,0,0,0,0,0,0,0,0,0,0,0,0,0,0,0,0,0,0,0,0,0,0,0,0
0,0,0,0,0,0,0,0,0,0,0,0,0,0,0,0,0,0,0,0,0,0,0,0,0,0,0,0,0,0,0
0,0,0,0,0,0,0,0,0,0,0,0,0,0,0,0,0,0,0,0,0,0,0,0,0,0,0,0,0,0,0
0,0,0,0,0,0,0,0,0,0,0,0,0,0,0,0,0,0,0,0,0,0,0,0,0,0,0,0,0,0,0
0,0,0,0,0,0,0,0,0,0,0,0,0,0,0,0,0,0,0,0,0,0,0,0,0,0,0,0,0,0,0
0,0,0,0,0,0,0,0,0,0,0,0,0,0,0,0,0,0,0,0,0,0,0,0,0,0,0,0,0,0,0
0,0,0,0,0,0,0,0,0,0,0,0,0,0,0,0,0,0,0,0,0,0,0,0,0,0,0,0,0,0,0
0,0,0,0,0,0,0,0,0,0,0,0,0,0,0,0,0,0,0,0,0,0,0,0,0,0,0,0,0,0,0
0,0,0,0,0,0,0,0,0,0,0,0,0,0,0,0,0,0,0,0,0,0,0,0,0,0,0,0,0,0,0
0,0,0,0,0,0,0,0,0,0,0,0,0,0,0,0,0,0,0,0,0,0,0,0,0,0,0,0,0,0,0
0,0,0,0,0,0,0,0,0,0,0,0,0,0,0,0,0,0,0,0,0,0,0,0,0,0,0,0,0,0,0
0,0,0,0,0,0,0,0,0,0,177,175,175,175,175,175,175,175,175,175,179,0,0,0,0,0,0,0,0,0,0
0,0,0,0,0,0,0,0,0,0,177,205,0,0,0,0,0,0,0,205,179,0,0,0,0,0,0,0,0,0,0
0,0,0,0,0,0,0,0,0,0,177,0,0,0,0,0,0,0,0,0,179,0,0,0,0,0,0,0,0,0,0
0,0,0,0,0,0,0,0,0,0,177,0,0,0,0,0,0,0,0,0,179,0,0,0,0,0,0,0,0,0,0
0,0,0,0,0,0,0,0,0,0,177,0,0,0,0,0,0,0,0,0,179,0,0,0,0,0,0,0,0,0,0
0,0,0,0,0,0,0,0,0,0,177,205,0,0,0,0,0,0,0,205,179,0,0,0,0,0,0,0,0,0,0
0,0,0,0,0,0,0,0,0,0,180,180,180,180,180,180,180,180,180,180,179,0,0,0,0,0,0,0,0,0,0
0,0,0,0,0,0,0,0,0,0,0,0,0,0,0,0,0,0,0,0,0,0,0,0,0,0,0,0,0,0,0
0,0,0,0,0,0,0,0,0,0,0,0,0,0,0,0,0,0,0,0,0,0,0,0,0,0,0,0,0,0,0
0,0,0,0,0,0,0,0,0,0,0,0,0,0,0,0,0,0,0,0,0,0,0,0,0,0,0,0,0,0,0
0,0,0,0,0,0,0,0,0,0,0,0,0,0,0,0,0,0,0,0,0,0,0,0,0,0,0,0,0,0,0
0,0,0,0,0,0,0,0,0,0,0,0,0,0,0,0,0,0,0,0,0,0,0,0,0,0,0,0,0,0,0
0,0,0,0,0,0,0,0,0,0,0,0,0,0,0,0,0,0,0,0,0,0,0,0,0,0,0,0,0,0,0
0,0,0,0,0,0,0,0,0,0,0,0,0,0,0,0,0,0,0,0,0,0,0,0,0,0,0,0,0,0,0
0,0,0,0,0,0,0,0,0,0,0,0,0,0,0,0,0,0,0,0,0,0,0,0,0,0,0,0,0,0,0
0,0,0,0,0,0,0,0,0,0,0,0,0,0,0,0,0,0,0,0,0,0,0,0,0,0,0,0,0,0,0
:endlayer
layer: 38
0,0,0,0,0,0,0,0,0,0,0,0,0,0,0,0,0,0,0,0,0,0,0,0,0,0,0,0,0,0,0
0,0,0,0,0,0,0,0,0,0,0,0,0,0,0,0,0,0,0,0,0,0,0,0,0,0,0,0,0,0,0
0,0,0,0,0,0,0,0,0,0,0,0,0,0,0,0,0,0,0,0,0,0,0,0,0,0,0,0,0,0,0
0,0,0,0,0,0,0,0,0,0,0,0,0,0,0,0,0,0,0,0,0,0,0,0,0,0,0,0,0,0,0
0,0,0,0,0,0,0,0,0,0,0,0,0,0,0,0,0,0,0,0,0,0,0,0,0,0,0,0,0,0,0
0,0,0,0,0,0,0,0,0,0,0,0,0,0,0,0,0,0,0,0,0,0,0,0,0,0,0,0,0,0,0
0,0,0,0,0,0,0,0,0,0,0,0,0,0,0,0,0,0,0,0,0,0,0,0,0,0,0,0,0,0,0
0,0,0,0,0,0,0,0,0,0,0,0,0,0,0,0,0,0,0,0,0,0,0,0,0,0,0,0,0,0,0
0,0,0,0,0,0,0,0,0,0,0,0,0,0,0,0,0,0,0,0,0,0,0,0,0,0,0,0,0,0,0
0,0,0,0,0,0,0,0,0,0,0,0,0,0,0,0,0,0,0,0,0,0,0,0,0,0,0,0,0,0,0
0,0,0,0,0,0,0,0,0,0,0,0,0,0,0,0,0,0,0,0,0,0,0,0,0,0,0,0,0,0,0
0,0,0,0,0,0,0,0,0,0,0,0,0,0,0,0,0,0,0,0,0,0,0,0,0,0,0,0,0,0,0
0,0,0,0,0,0,0,0,0,0,0,0,0,0,0,0,0,0,0,0,0,0,0,0,0,0,0,0,0,0,0
0,0,0,0,0,0,0,0,0,0,0,0,0,0,0,0,0,0,0,0,0,0,0,0,0,0,0,0,0,0,0
0,0,0,0,0,0,0,0,0,0,0,0,0,0,0,0,0,0,0,0,0,0,0,0,0,0,0,0,0,0,0
0,0,0,0,0,0,0,0,0,0,0,0,0,0,0,0,0,0,0,0,0,0,0,0,0,0,0,0,0,0,0
0,0,0,0,0,0,0,0,0,0,0,177,175,175,175,175,175,175,175,179,0,0,0,0,0,0,0,0,0,0,0
0,0,0,0,0,0,0,0,0,0,0,177,205,205,205,205,205,205,205,179,0,0,0,0,0,0,0,0,0,0,0
0,0,0,0,0,0,0,0,0,0,0,177,205,0,0,0,0,0,205,179,0,0,0,0,0,0,0,0,0,0,0
0,0,0,0,0,0,0,0,0,0,0,177,205,205,205,205,205,205,205,179,0,0,0,0,0,0,0,0,0,0,0
0,0,0,0,0,0,0,0,0,0,0,177,180,180,180,180,180,180,180,179,0,0,0,0,0,0,0,0,0,0,0
0,0,0,0,0,0,0,0,0,0,0,0,0,0,0,0,0,0,0,0,0,0,0,0,0,0,0,0,0,0,0
0,0,0,0,0,0,0,0,0,0,0,0,0,0,0,0,0,0,0,0,0,0,0,0,0,0,0,0,0,0,0
0,0,0,0,0,0,0,0,0,0,0,0,0,0,0,0,0,0,0,0,0,0,0,0,0,0,0,0,0,0,0
0,0,0,0,0,0,0,0,0,0,0,0,0,0,0,0,0,0,0,0,0,0,0,0,0,0,0,0,0,0,0
0,0,0,0,0,0,0,0,0,0,0,0,0,0,0,0,0,0,0,0,0,0,0,0,0,0,0,0,0,0,0
0,0,0,0,0,0,0,0,0,0,0,0,0,0,0,0,0,0,0,0,0,0,0,0,0,0,0,0,0,0,0
0,0,0,0,0,0,0,0,0,0,0,0,0,0,0,0,0,0,0,0,0,0,0,0,0,0,0,0,0,0,0
0,0,0,0,0,0,0,0,0,0,0,0,0,0,0,0,0,0,0,0,0,0,0,0,0,0,0,0,0,0,0
0,0,0,0,0,0,0,0,0,0,0,0,0,0,0,0,0,0,0,0,0,0,0,0,0,0,0,0,0,0,0
0,0,0,0,0,0,0,0,0,0,0,0,0,0,0,0,0,0,0,0,0,0,0,0,0,0,0,0,0,0,0
:endlayer
layer: 39
0,0,0,0,0,0,0,0,0,0,0,0,0,0,0,0,0,0,0,0,0,0,0,0,0,0,0,0,0,0,0
0,0,0,0,0,0,0,0,0,0,0,0,0,0,0,0,0,0,0,0,0,0,0,0,0,0,0,0,0,0,0
0,0,0,0,0,0,0,0,0,0,0,0,0,0,0,0,0,0,0,0,0,0,0,0,0,0,0,0,0,0,0
0,0,0,0,0,0,0,0,0,0,0,0,0,0,0,0,0,0,0,0,0,0,0,0,0,0,0,0,0,0,0
0,0,0,0,0,0,0,0,0,0,0,0,0,0,0,0,0,0,0,0,0,0,0,0,0,0,0,0,0,0,0
0,0,0,0,0,0,0,0,0,0,0,0,0,0,0,0,0,0,0,0,0,0,0,0,0,0,0,0,0,0,0
0,0,0,0,0,0,0,0,0,0,0,0,0,0,0,0,0,0,0,0,0,0,0,0,0,0,0,0,0,0,0
0,0,0,0,0,0,0,0,0,0,0,0,0,0,0,0,0,0,0,0,0,0,0,0,0,0,0,0,0,0,0
0,0,0,0,0,0,0,0,0,0,0,0,0,0,0,0,0,0,0,0,0,0,0,0,0,0,0,0,0,0,0
0,0,0,0,0,0,0,0,0,0,0,0,0,0,0,0,0,0,0,0,0,0,0,0,0,0,0,0,0,0,0
0,0,0,0,0,0,0,0,0,0,0,0,0,0,0,0,0,0,0,0,0,0,0,0,0,0,0,0,0,0,0
0,0,0,0,0,0,0,0,0,0,0,0,0,0,0,0,0,0,0,0,0,0,0,0,0,0,0,0,0,0,0
0,0,0,0,0,0,0,0,0,0,0,0,0,0,0,0,0,0,0,0,0,0,0,0,0,0,0,0,0,0,0
0,0,0,0,0,0,0,0,0,0,0,0,0,0,0,0,0,0,0,0,0,0,0,0,0,0,0,0,0,0,0
0,0,0,0,0,0,0,0,0,0,0,0,0,0,0,0,0,0,0,0,0,0,0,0,0,0,0,0,0,0,0
0,0,0,0,0,0,0,0,0,0,0,0,0,0,0,0,0,0,0,0,0,0,0,0,0,0,0,0,0,0,0
0,0,0,0,0,0,0,0,0,0,0,0,0,0,0,0,0,0,0,0,0,0,0,0,0,0,0,0,0,0,0
0,0,0,0,0,0,0,0,0,0,0,0,175,175,175,175,175,175,179,0,0,0,0,0,0,0,0,0,0,0,0
0,0,0,0,0,0,0,0,0,0,0,0,177,205,205,205,205,205,179,0,0,0,0,0,0,0,0,0,0,0,0
0,0,0,0,0,0,0,0,0,0,0,0,177,180,180,180,180,180,179,0,0,0,0,0,0,0,0,0,0,0,0
0,0,0,0,0,0,0,0,0,0,0,0,0,0,0,0,0,0,0,0,0,0,0,0,0,0,0,0,0,0,0
0,0,0,0,0,0,0,0,0,0,0,0,0,0,0,0,0,0,0,0,0,0,0,0,0,0,0,0,0,0,0
0,0,0,0,0,0,0,0,0,0,0,0,0,0,0,0,0,0,0,0,0,0,0,0,0,0,0,0,0,0,0
0,0,0,0,0,0,0,0,0,0,0,0,0,0,0,0,0,0,0,0,0,0,0,0,0,0,0,0,0,0,0
0,0,0,0,0,0,0,0,0,0,0,0,0,0,0,0,0,0,0,0,0,0,0,0,0,0,0,0,0,0,0
0,0,0,0,0,0,0,0,0,0,0,0,0,0,0,0,0,0,0,0,0,0,0,0,0,0,0,0,0,0,0
0,0,0,0,0,0,0,0,0,0,0,0,0,0,0,0,0,0,0,0,0,0,0,0,0,0,0,0,0,0,0
0,0,0,0,0,0,0,0,0,0,0,0,0,0,0,0,0,0,0,0,0,0,0,0,0,0,0,0,0,0,0
0,0,0,0,0,0,0,0,0,0,0,0,0,0,0,0,0,0,0,0,0,0,0,0,0,0,0,0,0,0,0
0,0,0,0,0,0,0,0,0,0,0,0,0,0,0,0,0,0,0,0,0,0,0,0,0,0,0,0,0,0,0
0,0,0,0,0,0,0,0,0,0,0,0,0,0,0,0,0,0,0,0,0,0,0,0,0,0,0,0,0,0,0
:endlayer
layer: 40
0,0,0,0,0,0,0,0,0,0,0,0,0,0,0,0,0,0,0,0,0,0,0,0,0,0,0,0,0,0,0
0,0,0,0,0,0,0,0,0,0,0,0,0,0,0,0,0,0,0,0,0,0,0,0,0,0,0,0,0,0,0
0,0,0,0,0,0,0,0,0,0,0,0,0,0,0,0,0,0,0,0,0,0,0,0,0,0,0,0,0,0,0
0,0,0,0,0,0,0,0,0,0,0,0,0,0,0,0,0,0,0,0,0,0,0,0,0,0,0,0,0,0,0
0,0,0,0,0,0,0,0,0,0,0,0,0,0,0,0,0,0,0,0,0,0,0,0,0,0,0,0,0,0,0
0,0,0,0,0,0,0,0,0,0,0,0,0,0,0,0,0,0,0,0,0,0,0,0,0,0,0,0,0,0,0
0,0,0,0,0,0,0,0,0,0,0,0,0,0,0,0,0,0,0,0,0,0,0,0,0,0,0,0,0,0,0
0,0,0,0,0,0,0,0,0,0,0,0,0,0,0,0,0,0,0,0,0,0,0,0,0,0,0,0,0,0,0
0,0,0,0,0,0,0,0,0,0,0,0,0,0,0,0,0,0,0,0,0,0,0,0,0,0,0,0,0,0,0
0,0,0,0,0,0,0,0,0,0,0,0,0,0,0,0,0,0,0,0,0,0,0,0,0,0,0,0,0,0,0
0,0,0,0,0,0,0,0,0,0,0,0,0,0,0,0,0,0,0,0,0,0,0,0,0,0,0,0,0,0,0
0,0,0,0,0,0,0,0,0,0,0,0,0,0,0,0,0,0,0,0,0,0,0,0,0,0,0,0,0,0,0
0,0,0,0,0,0,0,0,0,0,0,0,0,0,0,0,0,0,0,0,0,0,0,0,0,0,0,0,0,0,0
0,0,0,0,0,0,0,0,0,0,0,0,0,0,0,0,0,0,0,0,0,0,0,0,0,0,0,0,0,0,0
0,0,0,0,0,0,0,0,0,0,0,0,0,0,0,0,0,0,0,0,0,0,0,0,0,0,0,0,0,0,0
0,0,0,0,0,0,0,0,0,0,0,0,0,0,0,0,0,0,0,0,0,0,0,0,0,0,0,0,0,0,0
0,0,0,0,0,0,0,0,0,0,0,0,0,0,0,0,0,0,0,0,0,0,0,0,0,0,0,0,0,0,0
0,0,0,0,0,0,0,0,0,0,0,0,0,0,0,0,0,0,0,0,0,0,0,0,0,0,0,0,0,0,0
0,0,0,0,0,0,0,0,0,0,0,0,0,29,176,205,176,29,0,0,0,0,0,0,0,0,0,0,0,0,0
0,0,0,0,0,0,0,0,0,0,0,0,0,0,0,0,0,0,0,0,0,0,0,0,0,0,0,0,0,0,0
0,0,0,0,0,0,0,0,0,0,0,0,0,0,0,0,0,0,0,0,0,0,0,0,0,0,0,0,0,0,0
0,0,0,0,0,0,0,0,0,0,0,0,0,0,0,0,0,0,0,0,0,0,0,0,0,0,0,0,0,0,0
0,0,0,0,0,0,0,0,0,0,0,0,0,0,0,0,0,0,0,0,0,0,0,0,0,0,0,0,0,0,0
0,0,0,0,0,0,0,0,0,0,0,0,0,0,0,0,0,0,0,0,0,0,0,0,0,0,0,0,0,0,0
0,0,0,0,0,0,0,0,0,0,0,0,0,0,0,0,0,0,0,0,0,0,0,0,0,0,0,0,0,0,0
0,0,0,0,0,0,0,0,0,0,0,0,0,0,0,0,0,0,0,0,0,0,0,0,0,0,0,0,0,0,0
0,0,0,0,0,0,0,0,0,0,0,0,0,0,0,0,0,0,0,0,0,0,0,0,0,0,0,0,0,0,0
0,0,0,0,0,0,0,0,0,0,0,0,0,0,0,0,0,0,0,0,0,0,0,0,0,0,0,0,0,0,0
0,0,0,0,0,0,0,0,0,0,0,0,0,0,0,0,0,0,0,0,0,0,0,0,0,0,0,0,0,0,0
0,0,0,0,0,0,0,0,0,0,0,0,0,0,0,0,0,0,0,0,0,0,0,0,0,0,0,0,0,0,0
0,0,0,0,0,0,0,0,0,0,0,0,0,0,0,0,0,0,0,0,0,0,0,0,0,0,0,0,0,0,0
:endlayer
layer: 41
0,0,0,0,0,0,0,0,0,0,0,0,0,0,0,0,0,0,0,0,0,0,0,0,0,0,0,0,0,0,0
0,0,0,0,0,0,0,0,0,0,0,0,0,0,0,0,0,0,0,0,0,0,0,0,0,0,0,0,0,0,0
0,0,0,0,0,0,0,0,0,0,0,0,0,0,0,0,0,0,0,0,0,0,0,0,0,0,0,0,0,0,0
0,0,0,0,0,0,0,0,0,0,0,0,0,0,0,0,0,0,0,0,0,0,0,0,0,0,0,0,0,0,0
0,0,0,0,0,0,0,0,0,0,0,0,0,0,0,0,0,0,0,0,0,0,0,0,0,0,0,0,0,0,0
0,0,0,0,0,0,0,0,0,0,0,0,0,0,0,0,0,0,0,0,0,0,0,0,0,0,0,0,0,0,0
0,0,0,0,0,0,0,0,0,0,0,0,0,0,0,0,0,0,0,0,0,0,0,0,0,0,0,0,0,0,0
0,0,0,0,0,0,0,0,0,0,0,0,0,0,0,0,0,0,0,0,0,0,0,0,0,0,0,0,0,0,0
0,0,0,0,0,0,0,0,0,0,0,0,0,0,0,0,0,0,0,0,0,0,0,0,0,0,0,0,0,0,0
0,0,0,0,0,0,0,0,0,0,0,0,0,0,0,0,0,0,0,0,0,0,0,0,0,0,0,0,0,0,0
0,0,0,0,0,0,0,0,0,0,0,0,0,0,0,0,0,0,0,0,0,0,0,0,0,0,0,0,0,0,0
0,0,0,0,0,0,0,0,0,0,0,0,0,0,0,0,0,0,0,0,0,0,0,0,0,0,0,0,0,0,0
0,0,0,0,0,0,0,0,0,0,0,0,0,0,0,0,0,0,0,0,0,0,0,0,0,0,0,0,0,0,0
0,0,0,0,0,0,0,0,0,0,0,0,0,0,0,0,0,0,0,0,0,0,0,0,0,0,0,0,0,0,0
0,0,0,0,0,0,0,0,0,0,0,0,0,0,0,0,0,0,0,0,0,0,0,0,0,0,0,0,0,0,0
0,0,0,0,0,0,0,0,0,0,0,0,0,0,0,0,0,0,0,0,0,0,0,0,0,0,0,0,0,0,0
0,0,0,0,0,0,0,0,0,0,0,0,0,0,0,0,0,0,0,0,0,0,0,0,0,0,0,0,0,0,0
0,0,0,0,0,0,0,0,0,0,0,0,0,0,0,0,0,0,0,0,0,0,0,0,0,0,0,0,0,0,0
0,0,0,0,0,0,0,0,0,0,0,0,0,0,0,29,0,0,0,0,0,0,0,0,0,0,0,0,0,0,0
0,0,0,0,0,0,0,0,0,0,0,0,0,0,0,0,0,0,0,0,0,0,0,0,0,0,0,0,0,0,0
0,0,0,0,0,0,0,0,0,0,0,0,0,0,0,0,0,0,0,0,0,0,0,0,0,0,0,0,0,0,0
0,0,0,0,0,0,0,0,0,0,0,0,0,0,0,0,0,0,0,0,0,0,0,0,0,0,0,0,0,0,0
0,0,0,0,0,0,0,0,0,0,0,0,0,0,0,0,0,0,0,0,0,0,0,0,0,0,0,0,0,0,0
0,0,0,0,0,0,0,0,0,0,0,0,0,0,0,0,0,0,0,0,0,0,0,0,0,0,0,0,0,0,0
0,0,0,0,0,0,0,0,0,0,0,0,0,0,0,0,0,0,0,0,0,0,0,0,0,0,0,0,0,0,0
0,0,0,0,0,0,0,0,0,0,0,0,0,0,0,0,0,0,0,0,0,0,0,0,0,0,0,0,0,0,0
0,0,0,0,0,0,0,0,0,0,0,0,0,0,0,0,0,0,0,0,0,0,0,0,0,0,0,0,0,0,0
0,0,0,0,0,0,0,0,0,0,0,0,0,0,0,0,0,0,0,0,0,0,0,0,0,0,0,0,0,0,0
0,0,0,0,0,0,0,0,0,0,0,0,0,0,0,0,0,0,0,0,0,0,0,0,0,0,0,0,0,0,0
0,0,0,0,0,0,0,0,0,0,0,0,0,0,0,0,0,0,0,0,0,0,0,0,0,0,0,0,0,0,0
0,0,0,0,0,0,0,0,0,0,0,0,0,0,0,0,0,0,0,0,0,0,0,0,0,0,0,0,0,0,0
:endlayer

#### RULES ####
rule:
plugin=vanillaBlocks
number=1
data:
JSON:{blockState:{blockName:"minecraft:stone",properties:{variant:"stone"}}}
:enddata
:endrule

rule:
plugin=vanillaBlocks
number=2
data:
JSON:{blockState:{blockName:"minecraft:cobblestone"}}
:enddata
:endrule

rule:
plugin=vanillaBlocks
number=3
data:
JSON:{blockState:{blockName:"minecraft:stonebrick",properties:{variant:"stonebrick"}}}
:enddata
:endrule

rule:
plugin=vanillaBlocks
number=4
data:
JSON:{blockState:{blockName:"minecraft:stone_brick_stairs",properties:{half:"bottom",shape:"straight",facing:"north"}}}
:enddata
:endrule

rule:
plugin=blockTile
number=5
data:
JSON:{blockState:{blockName:"ancientwarfarestructure:advanced_loot_chest",properties:{facing:"east"}},teData:{LootTable:"minecraft:chests/village_blacksmith",lootRolls:1b,lootSettings:{lootRolls:1,splashPotion:0b,hasLoot:1b,lootTableName:"minecraft:chests/village_blacksmith",spawnEntity:0b},id:"ancientwarfarestructure:advanced_loot_chest_tile",Lock:"",LootTableSeed:-6636206649127190503L}}
:enddata
:endrule

rule:
plugin=blockTile
number=6
data:
JSON:{blockState:{blockName:"ancientwarfarestructure:advanced_spawner",properties:{transparent:"true"}},teData:{id:"ancientwarfarestructure:advanced_spawner_tile",spawnerSettings:{minDelay:0,spawnDelay:0,lightSensitive:0b,spawnGroups:[{settingsList:[{remainingSpawnCount:1,hostile:1b,forced:1b,customTag:{ArmorDropChances:[0.085f,0.085f,0.085f,0.085f],ArmorItems:[{},{},{},{}],HandDropChances:[0.085f,0.085f],HandItems:[{},{}]},maxToSpawn:1,entityId:"dungeonmobs:dmrustmonster",minToSpawn:1}],groupWeight:1}],playerRange:4,respondToRedstone:0b,inventory:{Size:9,Items:[]},spawnRange:0,transparent:1b,maxDelay:0,xpToDrop:0,mobRange:0,debugMode:0b,maxNearbyMonsters:0}}}
:enddata
:endrule

rule:
plugin=blockTile
number=7
data:
JSON:{blockState:{blockName:"ancientwarfarestructure:advanced_spawner",properties:{transparent:"true"}},teData:{id:"ancientwarfarestructure:advanced_spawner_tile",spawnerSettings:{minDelay:0,spawnDelay:0,lightSensitive:0b,spawnGroups:[{settingsList:[{remainingSpawnCount:1,hostile:1b,forced:1b,customTag:{ArmorDropChances:[0.085f,0.085f,0.085f,0.085f],ArmorItems:[{},{},{},{}],HandDropChances:[0.085f,0.085f],HandItems:[{},{}]},maxToSpawn:1,entityId:"dungeonmobs:dmrustmonster",minToSpawn:1}],groupWeight:1}],playerRange:4,respondToRedstone:0b,inventory:{Size:9,Items:[]},spawnRange:0,transparent:1b,maxDelay:0,xpToDrop:0,mobRange:0,debugMode:0b,maxNearbyMonsters:0}}}
:enddata
:endrule

rule:
plugin=blockTile
number=8
data:
JSON:{blockState:{blockName:"ancientwarfarestructure:advanced_loot_chest",properties:{facing:"west"}},teData:{LootTable:"minecraft:chests/village_blacksmith",lootRolls:1b,lootSettings:{lootRolls:1,splashPotion:0b,hasLoot:1b,lootTableName:"minecraft:chests/village_blacksmith",spawnEntity:0b},id:"ancientwarfarestructure:advanced_loot_chest_tile",Lock:"",LootTableSeed:9072348850369347609L}}
:enddata
:endrule

rule:
plugin=blockTile
number=9
data:
JSON:{blockState:{blockName:"ancientwarfarestructure:advanced_spawner",properties:{transparent:"true"}},teData:{id:"ancientwarfarestructure:advanced_spawner_tile",spawnerSettings:{minDelay:0,spawnDelay:0,lightSensitive:0b,spawnGroups:[{settingsList:[{remainingSpawnCount:1,hostile:1b,forced:1b,customTag:{ArmorDropChances:[0.085f,0.085f,0.085f,0.085f],ArmorItems:[{},{},{},{}],HandDropChances:[0.085f,0.085f],HandItems:[{},{}]},maxToSpawn:1,entityId:"dungeonmobs:dmillithid",minToSpawn:1}],groupWeight:1}],playerRange:3,respondToRedstone:0b,inventory:{Size:9,Items:[]},spawnRange:0,transparent:1b,maxDelay:0,xpToDrop:0,mobRange:0,debugMode:0b,maxNearbyMonsters:0}}}
:enddata
:endrule

rule:
plugin=inventory
number=10
data:
JSON:{blockState:{blockName:"minecraft:chest",properties:{facing:"north"}},lootLevel:0,teData:{ForgeData:{},Items:[{Slot:0b,id:"minecraft:string",Count:1b,Damage:0s},{Slot:1b,id:"minecraft:gunpowder",Count:15b,Damage:0s},{Slot:2b,id:"minecraft:bone",Count:7b,Damage:0s},{Slot:3b,id:"minecraft:golden_horse_armor",Count:1b,Damage:0s},{Slot:4b,id:"ebwizardry:poison_bomb",Count:1b,Damage:0s},{Slot:5b,id:"minecraft:name_tag",Count:1b,Damage:0s},{Slot:6b,id:"minecraft:redstone",Count:2b,Damage:0s},{Slot:7b,id:"ebwizardry:basic_lightning_wand",Count:1b,Damage:0s},{Slot:8b,id:"ebwizardry:magic_wand",Count:1b,Damage:0s},{Slot:9b,id:"ebwizardry:wizard_boots_necromancy",Count:1b,Damage:0s},{Slot:10b,id:"ebwizardry:basic_fire_wand",Count:1b,Damage:0s},{Slot:11b,id:"minecraft:coal",Count:5b,Damage:0s},{Slot:12b,id:"ebwizardry:identification_scroll",Count:2b,Damage:0s},{Slot:13b,id:"minecraft:enchanted_book",Count:1b,tag:{StoredEnchantments:[{lvl:1s,id:25s}]},Damage:0s},{Slot:14b,id:"minecraft:redstone",Count:1b,Damage:0s},{Slot:15b,id:"dungeontactics:magic_tether",Count:1b,Damage:0s},{Slot:16b,id:"minecraft:bread",Count:1b,Damage:0s},{Slot:17b,id:"minecraft:saddle",Count:1b,Damage:0s},{Slot:18b,id:"minecraft:pumpkin_seeds",Count:2b,Damage:0s},{Slot:19b,id:"dungeontactics:ducttape",Count:1b,Damage:0s},{Slot:20b,id:"minecraft:beetroot_seeds",Count:2b,Damage:0s},{Slot:21b,id:"ebwizardry:spell_book",Count:1b,Damage:27s},{Slot:22b,id:"minecraft:redstone",Count:3b,Damage:0s},{Slot:23b,id:"ebwizardry:spell_book",Count:1b,Damage:29s},{Slot:24b,id:"minecraft:beetroot_seeds",Count:2b,Damage:0s},{Slot:25b,id:"ebwizardry:magic_crystal",Count:1b,Damage:0s},{Slot:26b,id:"ebwizardry:basic_earth_wand",Count:1b,Damage:0s}],id:"minecraft:chest",Lock:""},inventoryData:{length:27,inventoryContents:[{id:"minecraft:string",Count:1b,slot:0,Damage:0s},{id:"minecraft:gunpowder",Count:15b,slot:1,Damage:0s},{id:"minecraft:bone",Count:7b,slot:2,Damage:0s},{id:"minecraft:golden_horse_armor",Count:1b,slot:3,Damage:0s},{id:"ebwizardry:poison_bomb",Count:1b,slot:4,Damage:0s},{id:"minecraft:name_tag",Count:1b,slot:5,Damage:0s},{id:"minecraft:redstone",Count:2b,slot:6,Damage:0s},{id:"ebwizardry:basic_lightning_wand",Count:1b,slot:7,Damage:0s},{id:"ebwizardry:magic_wand",Count:1b,slot:8,Damage:0s},{id:"ebwizardry:wizard_boots_necromancy",Count:1b,slot:9,Damage:0s},{id:"ebwizardry:basic_fire_wand",Count:1b,slot:10,Damage:0s},{id:"minecraft:coal",Count:5b,slot:11,Damage:0s},{id:"ebwizardry:identification_scroll",Count:2b,slot:12,Damage:0s},{id:"minecraft:enchanted_book",Count:1b,tag:{StoredEnchantments:[{lvl:1s,id:25s}]},slot:13,Damage:0s},{id:"minecraft:redstone",Count:1b,slot:14,Damage:0s},{id:"minecraft:bread",Count:1b,slot:16,Damage:0s},{id:"minecraft:saddle",Count:1b,slot:17,Damage:0s},{id:"minecraft:pumpkin_seeds",Count:2b,slot:18,Damage:0s},{id:"minecraft:beetroot_seeds",Count:2b,slot:20,Damage:0s},{id:"ebwizardry:spell_book",Count:1b,slot:21,Damage:27s},{id:"minecraft:redstone",Count:3b,slot:22,Damage:0s},{id:"ebwizardry:spell_book",Count:1b,slot:23,Damage:29s},{id:"minecraft:beetroot_seeds",Count:2b,slot:24,Damage:0s},{id:"ebwizardry:magic_crystal",Count:1b,slot:25,Damage:0s},{id:"ebwizardry:basic_earth_wand",Count:1b,slot:26,Damage:0s}]},legacyFeatures:1b}
:enddata
:endrule

rule:
plugin=inventory
number=11
data:
JSON:{blockState:{blockName:"minecraft:chest",properties:{facing:"north"}},lootLevel:0,teData:{ForgeData:{},Items:[{Slot:0b,id:"ebwizardry:spell_book",Count:1b,Damage:4s},{Slot:1b,id:"minecraft:rotten_flesh",Count:1b,Damage:0s},{Slot:2b,id:"minecraft:rotten_flesh",Count:7b,Damage:0s},{Slot:3b,id:"ebwizardry:armour_upgrade",Count:1b,Damage:0s},{Slot:4b,id:"ebwizardry:spell_book",Count:1b,Damage:90s},{Slot:5b,id:"minecraft:golden_apple",Count:1b,Damage:1s},{Slot:6b,id:"minecraft:rotten_flesh",Count:5b,Damage:0s},{Slot:7b,id:"ebwizardry:spell_book",Count:1b,Damage:122s},{Slot:8b,id:"minecraft:bucket",Count:1b,Damage:0s},{Slot:9b,id:"minecraft:iron_horse_armor",Count:1b,Damage:0s},{Slot:10b,id:"minecraft:rotten_flesh",Count:3b,Damage:0s},{Slot:11b,id:"minecraft:golden_apple",Count:1b,Damage:0s},{Slot:12b,id:"dungeontactics:heart_jar",Count:2b,Damage:0s},{Slot:13b,id:"minecraft:iron_ingot",Count:2b,Damage:0s},{Slot:14b,id:"minecraft:gunpowder",Count:2b,Damage:0s},{Slot:15b,id:"minecraft:rotten_flesh",Count:1b,Damage:0s},{Slot:16b,id:"ebwizardry:firebomb",Count:1b,Damage:0s},{Slot:17b,id:"minecraft:bone",Count:3b,Damage:0s},{Slot:18b,id:"ebwizardry:wizard_hat",Count:1b,Damage:0s},{Slot:19b,id:"minecraft:redstone",Count:2b,Damage:0s},{Slot:20b,id:"minecraft:pumpkin_seeds",Count:2b,Damage:0s},{Slot:21b,id:"dungeontactics:heart_jar",Count:1b,Damage:0s},{Slot:22b,id:"minecraft:redstone",Count:2b,Damage:0s},{Slot:23b,id:"ebwizardry:armour_upgrade",Count:1b,Damage:0s},{Slot:24b,id:"minecraft:name_tag",Count:1b,Damage:0s},{Slot:25b,id:"minecraft:bone",Count:2b,Damage:0s},{Slot:26b,id:"ebwizardry:wizard_boots_lightning",Count:1b,Damage:0s}],id:"minecraft:chest",Lock:""},inventoryData:{length:27,inventoryContents:[{id:"ebwizardry:spell_book",Count:1b,slot:0,Damage:4s},{id:"minecraft:rotten_flesh",Count:1b,slot:1,Damage:0s},{id:"minecraft:rotten_flesh",Count:7b,slot:2,Damage:0s},{id:"ebwizardry:armour_upgrade",Count:1b,slot:3,Damage:0s},{id:"ebwizardry:spell_book",Count:1b,slot:4,Damage:90s},{id:"minecraft:golden_apple",Count:1b,slot:5,Damage:1s},{id:"minecraft:rotten_flesh",Count:5b,slot:6,Damage:0s},{id:"ebwizardry:spell_book",Count:1b,slot:7,Damage:122s},{id:"minecraft:bucket",Count:1b,slot:8,Damage:0s},{id:"minecraft:iron_horse_armor",Count:1b,slot:9,Damage:0s},{id:"minecraft:rotten_flesh",Count:3b,slot:10,Damage:0s},{id:"minecraft:golden_apple",Count:1b,slot:11,Damage:0s},{id:"minecraft:iron_ingot",Count:2b,slot:13,Damage:0s},{id:"minecraft:gunpowder",Count:2b,slot:14,Damage:0s},{id:"minecraft:rotten_flesh",Count:1b,slot:15,Damage:0s},{id:"ebwizardry:firebomb",Count:1b,slot:16,Damage:0s},{id:"minecraft:bone",Count:3b,slot:17,Damage:0s},{id:"ebwizardry:wizard_hat",Count:1b,slot:18,Damage:0s},{id:"minecraft:redstone",Count:2b,slot:19,Damage:0s},{id:"minecraft:pumpkin_seeds",Count:2b,slot:20,Damage:0s},{id:"minecraft:redstone",Count:2b,slot:22,Damage:0s},{id:"ebwizardry:armour_upgrade",Count:1b,slot:23,Damage:0s},{id:"minecraft:name_tag",Count:1b,slot:24,Damage:0s},{id:"minecraft:bone",Count:2b,slot:25,Damage:0s},{id:"ebwizardry:wizard_boots_lightning",Count:1b,slot:26,Damage:0s}]},legacyFeatures:1b}
:enddata
:endrule

rule:
plugin=fluid
number=12
data:
JSON:{blockState:{blockName:"minecraft:water",properties:{level:"8"}}}
:enddata
:endrule

rule:
plugin=blockTile
number=13
data:
JSON:{blockState:{blockName:"ancientwarfarestructure:advanced_spawner",properties:{transparent:"true"}},teData:{id:"ancientwarfarestructure:advanced_spawner_tile",spawnerSettings:{minDelay:0,spawnDelay:0,lightSensitive:0b,spawnGroups:[{settingsList:[{remainingSpawnCount:1,hostile:0b,forced:1b,customTag:{ArmorDropChances:[0.085f,0.085f,0.085f,0.085f],ArmorItems:[{},{},{},{}],HandDropChances:[0.085f,0.085f],HandItems:[{},{}]},maxToSpawn:1,entityId:"reptilemod:largecroc",minToSpawn:1}],groupWeight:1}],playerRange:16,respondToRedstone:0b,inventory:{Size:9,Items:[]},spawnRange:0,transparent:1b,maxDelay:0,xpToDrop:0,mobRange:0,debugMode:0b,maxNearbyMonsters:0}}}
:enddata
:endrule

rule:
plugin=blockTile
number=14
data:
JSON:{blockState:{blockName:"ancientwarfarestructure:advanced_spawner",properties:{transparent:"true"}},teData:{id:"ancientwarfarestructure:advanced_spawner_tile",spawnerSettings:{minDelay:0,spawnDelay:0,lightSensitive:0b,spawnGroups:[{settingsList:[{remainingSpawnCount:1,hostile:0b,forced:1b,customTag:{ArmorDropChances:[0.085f,0.085f,0.085f,0.085f],ArmorItems:[{},{},{},{}],HandDropChances:[0.085f,0.085f],HandItems:[{},{}]},maxToSpawn:1,entityId:"reptilemod:largecroc",minToSpawn:1}],groupWeight:1}],playerRange:16,respondToRedstone:0b,inventory:{Size:9,Items:[]},spawnRange:0,transparent:1b,maxDelay:0,xpToDrop:0,mobRange:0,debugMode:0b,maxNearbyMonsters:0}}}
:enddata
:endrule

rule:
plugin=blockTile
number=15
data:
JSON:{blockState:{blockName:"ancientwarfarestructure:advanced_spawner",properties:{transparent:"true"}},teData:{id:"ancientwarfarestructure:advanced_spawner_tile",spawnerSettings:{minDelay:0,spawnDelay:0,lightSensitive:0b,spawnGroups:[{settingsList:[{remainingSpawnCount:1,hostile:0b,forced:1b,customTag:{ArmorDropChances:[0.085f,0.085f,0.085f,0.085f],ArmorItems:[{},{},{},{}],HandDropChances:[0.085f,0.085f],HandItems:[{},{}]},maxToSpawn:1,entityId:"reptilemod:largecroc",minToSpawn:1}],groupWeight:1}],playerRange:16,respondToRedstone:0b,inventory:{Size:9,Items:[]},spawnRange:0,transparent:1b,maxDelay:0,xpToDrop:0,mobRange:0,debugMode:0b,maxNearbyMonsters:0}}}
:enddata
:endrule

rule:
plugin=blockTile
number=16
data:
