# Ancient Warfare Structure Template File
# Auto-generated structure template file. created on: 8/19/2019 at: 10:23:10
# Lines beginning with # denote comments

header:
version=2.9
name=EmpireLordsCastle
mods=
size=33,42,37
offset=15,6,36
:endheader

#### VALIDATION ####
validation:
type=ground
survival=false
worldGenEnabled=true
unique=false
preserveBlocks=false
selectionWeight=300
clusterValue=251
minDuplicateDistance=1000
dimensionWhiteList=true
dimensionList=0
biomeWhiteList=true
biomeList=biomesoplenty:meadow,minecraft:forest,traverse:meadow,minecraft:birch_forest,minecraft:plains,minecraft:birch_forest_hills,minecraft:smaller_extreme_hills
leveling=12
fill=12
border=12
blockSwap=false
:endvalidation

#### LAYERS ####
layer: 0
1,1,1,1,1,1,1,1,1,1,1,1,1,1,1,1,1,1,1,1,1,1,1,1,1,1,1,1,1,1,1,1,1
1,1,1,1,1,1,1,1,1,1,1,1,1,1,1,1,1,1,1,1,1,1,1,1,1,1,1,1,1,1,1,1,1
1,1,1,1,1,1,1,1,1,1,1,1,1,1,1,1,1,1,1,1,1,1,1,1,1,1,1,1,1,1,1,1,1
1,1,1,1,1,1,1,1,1,1,1,1,1,1,1,1,1,1,1,1,1,1,1,1,1,1,1,1,1,1,1,1,1
1,1,1,1,1,1,1,1,1,1,1,1,1,1,1,1,1,1,1,1,1,1,1,1,1,1,1,1,1,1,1,1,1
1,1,1,1,1,1,1,1,1,1,1,1,1,1,1,1,1,1,1,1,1,1,1,1,1,1,1,1,1,1,1,1,1
1,1,1,1,1,1,1,1,1,1,1,1,1,1,1,1,1,1,1,1,1,1,1,1,1,1,1,1,1,1,1,1,1
1,1,1,1,1,1,1,1,1,1,1,1,1,1,1,1,1,1,1,1,1,1,1,1,1,1,1,1,1,1,1,1,1
1,1,1,1,1,1,1,1,1,1,1,1,1,1,1,1,1,1,1,1,1,1,1,1,1,1,1,1,1,1,1,1,1
1,1,1,1,1,1,1,1,1,1,1,1,1,1,1,1,1,1,1,1,1,1,1,1,1,1,1,1,1,1,1,1,1
1,1,1,1,1,1,1,1,1,1,1,1,1,1,1,1,1,1,1,1,1,1,1,1,1,1,1,1,1,1,1,1,1
1,1,1,1,1,1,1,1,1,1,1,1,1,1,1,1,1,1,1,1,1,1,1,1,1,1,1,1,1,1,1,1,1
1,1,1,1,1,1,1,1,1,1,1,1,1,1,1,1,1,1,1,1,1,1,1,1,1,1,1,1,1,1,1,1,1
1,1,1,1,1,1,1,1,1,1,1,1,1,1,1,1,1,1,1,1,1,1,1,1,1,1,1,1,1,1,1,1,1
1,1,1,1,1,1,1,1,1,1,1,1,1,1,1,1,1,1,1,1,1,1,1,1,1,1,1,1,1,1,1,1,1
1,1,1,1,1,1,1,1,1,1,1,1,1,1,1,1,1,1,1,1,1,1,1,1,1,1,1,1,1,1,1,1,1
1,1,1,1,1,1,1,1,1,1,1,1,1,1,1,1,1,1,1,1,1,1,1,1,1,1,1,1,1,1,1,1,1
1,1,1,1,1,1,1,1,1,1,1,1,1,1,1,1,1,1,1,1,1,1,1,1,1,1,1,1,1,1,1,1,1
1,1,1,1,1,1,1,1,1,1,1,1,1,1,1,1,1,1,1,1,1,1,1,1,1,1,1,1,1,1,1,1,1
1,1,1,1,1,1,1,1,1,1,1,1,1,1,1,1,1,1,1,1,1,1,1,1,1,1,1,1,1,1,1,1,1
1,1,1,1,1,1,1,1,1,1,1,1,1,1,1,1,1,1,1,1,1,1,1,1,1,1,1,1,1,1,1,1,1
1,1,1,1,1,1,1,1,1,1,1,1,1,1,1,1,1,1,1,1,1,1,1,1,1,1,1,1,1,1,1,1,1
1,1,1,1,1,1,1,1,1,1,1,1,1,1,1,1,1,1,1,1,1,1,1,1,1,1,1,1,1,1,1,1,1
1,1,1,1,1,1,1,1,1,1,1,1,1,1,1,1,1,1,1,1,1,1,1,1,1,1,1,1,1,1,1,1,1
1,1,1,1,1,1,1,1,1,1,1,1,1,1,1,1,1,1,1,1,1,1,1,1,1,1,1,1,1,1,1,1,1
1,1,1,1,1,1,1,1,1,1,1,1,1,1,1,1,1,1,1,1,1,1,1,1,1,1,1,1,1,1,1,1,1
1,1,1,1,1,1,1,1,1,1,1,1,1,1,1,1,1,1,1,1,1,1,1,1,1,1,1,1,1,1,1,1,1
1,1,1,1,1,1,1,1,1,1,1,1,1,1,1,1,1,1,1,1,1,1,1,1,1,1,1,1,1,1,1,1,1
1,1,1,1,1,1,1,1,1,1,1,1,1,1,1,1,1,1,1,1,1,1,1,1,1,1,1,1,1,1,1,1,1
1,1,1,1,1,1,1,1,1,1,1,1,1,1,1,1,1,1,1,1,1,1,1,1,1,1,1,1,1,1,1,1,1
1,1,1,1,1,1,1,1,1,1,1,1,1,1,1,1,1,1,1,1,1,1,1,1,1,1,1,1,1,1,1,1,1
1,1,1,1,1,1,1,1,1,1,1,1,1,1,1,1,1,1,1,1,1,1,1,1,1,1,1,1,1,1,1,1,1
1,1,1,1,1,1,1,1,1,1,1,1,1,1,1,1,1,1,1,1,1,1,1,1,1,1,1,1,1,1,1,1,1
1,1,1,1,1,1,1,1,1,1,1,1,1,1,1,1,1,1,1,1,1,1,1,1,1,1,1,1,1,1,1,1,1
1,1,1,1,1,1,1,1,1,1,1,1,1,1,1,1,1,1,1,1,1,1,1,1,1,1,1,1,1,1,1,1,1
1,1,1,1,1,1,1,1,1,1,1,1,1,1,1,1,1,1,1,1,1,1,1,1,1,1,1,1,1,1,1,1,1
1,1,1,1,1,1,1,1,1,1,1,1,1,1,1,1,1,1,1,1,1,1,1,1,1,1,1,1,1,1,1,1,1
:endlayer
layer: 1
1,1,1,1,1,1,1,1,1,1,1,1,1,1,1,1,1,1,1,1,1,1,1,1,1,1,1,1,1,1,1,1,1
1,1,1,1,1,1,1,1,1,1,1,1,1,1,1,1,1,1,1,1,1,1,1,1,1,1,1,1,1,1,1,1,1
1,1,1,1,1,1,1,1,1,1,1,1,1,1,1,1,1,1,1,1,1,1,1,1,1,1,1,1,1,1,1,1,1
1,1,1,1,1,1,1,1,1,1,1,1,1,1,1,1,1,1,1,1,1,1,1,1,1,1,1,1,1,1,1,1,1
1,1,1,1,1,1,1,1,1,1,1,1,1,1,1,1,1,1,1,1,1,1,1,1,1,1,1,1,1,1,1,1,1
1,1,1,1,1,1,1,1,1,1,1,1,1,1,1,1,1,1,1,1,1,1,1,1,1,1,1,1,1,1,1,1,1
1,1,1,1,1,1,1,1,1,1,1,1,1,1,1,1,1,1,1,1,1,1,1,1,1,1,1,1,1,1,1,1,1
1,1,1,1,1,1,1,1,1,1,1,1,1,1,1,1,1,1,1,1,1,1,1,1,1,1,1,1,1,1,1,1,1
1,1,1,1,1,1,1,1,1,1,1,1,1,1,1,1,1,1,1,1,1,1,1,1,1,1,1,1,1,1,1,1,1
1,1,1,1,1,1,1,1,1,1,1,1,1,1,1,1,1,1,1,1,1,1,1,1,1,1,1,1,1,1,1,1,1
1,1,1,1,1,1,1,1,1,1,1,1,1,1,1,1,1,1,1,1,1,1,1,1,1,1,1,1,1,1,1,1,1
1,1,1,1,1,1,1,1,1,1,1,1,1,1,1,1,1,1,1,1,1,1,1,1,1,1,1,1,1,1,1,1,1
1,1,1,1,1,1,1,1,1,1,1,1,1,1,1,1,1,1,1,1,1,1,1,1,1,1,1,1,1,1,1,1,1
1,1,1,1,1,1,1,1,1,1,1,1,1,1,1,1,1,1,1,1,1,1,1,1,1,1,1,1,1,1,1,1,1
1,1,1,1,1,1,1,1,1,1,1,1,1,1,1,1,1,1,1,1,1,1,1,1,1,1,1,1,1,1,1,1,1
1,1,1,1,1,1,1,1,1,1,1,1,1,1,1,1,1,1,1,1,1,1,1,1,1,1,1,1,1,1,1,1,1
1,1,1,1,1,1,1,1,1,1,1,1,1,1,1,1,1,1,1,1,1,1,1,1,1,1,1,1,1,1,1,1,1
1,1,1,1,1,1,1,1,1,1,1,1,1,1,1,1,1,1,1,1,1,1,1,1,1,1,1,1,1,1,1,1,1
1,1,1,1,1,1,1,1,1,1,1,1,1,1,1,1,1,1,1,1,1,1,1,1,1,1,1,1,1,1,1,1,1
1,1,1,1,1,1,1,1,1,1,1,1,1,1,1,1,1,1,1,1,1,1,1,1,1,1,1,1,1,1,1,1,1
1,1,1,1,1,1,1,1,1,1,1,1,1,1,1,1,1,1,1,1,1,1,1,1,1,1,1,1,1,1,1,1,1
1,1,1,1,1,1,1,1,1,1,1,1,1,1,1,1,1,1,1,1,1,1,1,1,1,1,1,1,1,1,1,1,1
1,1,1,1,1,1,1,1,1,1,1,1,1,1,1,1,1,1,1,1,1,1,1,1,1,1,1,1,1,1,1,1,1
1,1,1,1,1,1,1,1,1,1,1,1,1,1,1,1,1,1,1,1,1,1,1,1,1,1,1,1,1,1,1,1,1
1,1,1,1,1,1,1,1,1,1,1,1,1,1,1,1,1,1,1,1,1,1,1,1,1,1,1,1,1,1,1,1,1
1,1,1,1,1,1,1,1,1,1,1,1,1,1,1,1,1,1,1,1,1,1,1,1,1,1,1,1,1,1,1,1,1
1,1,1,1,1,1,1,1,1,1,1,1,1,1,1,1,1,1,1,1,1,1,1,1,1,1,1,1,1,1,1,1,1
1,1,1,1,1,1,1,1,1,1,1,1,1,1,1,1,1,1,1,1,1,1,1,1,1,1,1,1,1,1,1,1,1
1,1,1,1,1,1,1,1,1,1,1,1,1,1,1,1,1,1,1,1,1,1,1,1,1,1,1,1,1,1,1,1,1
1,1,1,1,1,1,1,1,1,1,1,1,1,1,1,1,1,1,1,1,1,1,1,1,1,1,1,1,1,1,1,1,1
1,1,1,1,1,1,1,1,1,1,1,1,1,1,1,1,1,1,1,1,1,1,1,1,1,1,1,1,1,1,1,1,1
1,1,1,1,1,1,1,1,1,1,1,1,1,1,1,1,1,1,1,1,1,1,1,1,1,1,1,1,1,1,1,1,1
1,1,1,1,1,1,1,1,1,1,1,1,1,1,1,1,1,1,1,1,1,1,1,1,1,1,1,1,1,1,1,1,1
1,1,1,1,1,1,1,1,1,1,1,1,1,1,1,1,1,1,1,1,1,1,1,1,1,1,1,1,1,1,1,1,1
1,1,1,1,1,1,1,1,1,1,1,1,1,1,1,1,1,1,1,1,1,1,1,1,1,1,1,1,1,1,1,1,1
1,1,1,1,1,1,1,1,1,1,1,1,1,1,1,1,1,1,1,1,1,1,1,1,1,1,1,1,1,1,1,1,1
1,1,1,1,1,1,1,1,1,1,1,1,1,1,1,1,1,1,1,1,1,1,1,1,1,1,1,1,1,1,1,1,1
:endlayer
layer: 2
2,2,2,2,2,2,2,2,2,2,2,2,2,2,2,2,2,2,2,2,2,2,2,2,2,2,2,2,2,2,2,2,2
2,2,2,2,2,2,2,2,2,2,2,2,2,2,2,2,2,2,2,2,2,2,2,2,2,2,2,2,2,2,2,2,2
2,2,2,2,2,2,2,2,2,2,2,2,2,2,2,2,2,2,2,2,2,2,2,2,2,2,2,2,2,2,2,2,2
2,2,2,2,2,2,2,2,2,2,2,2,2,2,2,2,2,2,2,2,2,2,2,2,2,2,2,2,2,2,2,2,2
2,2,2,2,2,2,2,2,2,2,2,2,2,2,2,2,2,2,2,2,2,2,2,2,2,2,2,2,2,2,2,2,2
2,2,2,2,2,2,2,2,2,2,2,2,2,2,2,2,2,2,2,2,2,2,2,2,2,2,2,2,2,2,2,2,2
2,2,2,2,2,2,2,2,2,2,2,2,2,2,2,2,2,2,2,2,2,2,2,2,2,2,2,2,2,2,2,2,2
2,2,2,2,2,2,2,2,2,2,2,2,2,2,2,2,2,2,2,2,2,2,2,2,2,2,2,2,2,2,2,2,2
2,2,2,2,2,2,2,2,2,2,2,2,2,2,2,2,2,2,2,2,2,2,2,2,2,2,2,2,2,2,2,2,2
2,2,2,2,2,2,2,2,2,2,2,2,2,2,2,2,2,2,2,2,2,2,2,2,2,2,2,2,2,2,2,2,2
2,2,2,2,2,2,2,2,2,2,2,2,2,2,2,2,2,2,2,2,2,2,2,2,2,2,2,2,2,2,2,2,2
2,2,2,2,2,2,2,2,2,2,2,2,2,2,2,2,2,2,2,2,2,2,2,2,2,2,2,2,2,2,2,2,2
2,2,2,2,2,2,2,2,2,2,2,2,2,2,2,2,2,2,2,2,2,2,2,2,2,2,2,2,2,2,2,2,2
2,2,2,2,2,2,2,2,2,2,2,2,2,2,2,2,2,2,2,2,2,2,2,2,2,2,2,2,2,2,2,2,2
2,2,2,2,2,2,2,2,2,2,2,2,2,2,2,2,2,2,2,2,2,2,2,2,2,2,2,2,2,2,2,2,2
2,2,2,2,2,2,2,2,2,2,2,2,2,2,2,2,2,2,2,2,2,2,2,2,2,2,2,2,2,2,2,2,2
2,2,2,2,2,2,2,2,2,2,2,2,2,2,2,2,2,2,2,2,2,2,2,2,2,2,2,2,2,2,2,2,2
2,2,2,2,2,2,2,2,2,2,2,2,2,2,2,2,2,2,2,2,2,2,2,2,2,2,2,2,2,2,2,2,2
2,2,2,2,2,2,2,2,2,2,2,2,2,2,2,2,2,2,2,2,2,2,2,2,2,2,2,2,2,2,2,2,2
2,2,2,2,2,2,2,2,2,2,2,2,2,2,2,2,2,2,2,2,2,2,2,2,2,2,2,2,2,2,2,2,2
2,2,2,2,2,2,2,2,2,2,2,2,2,2,2,2,2,2,2,2,2,2,2,2,2,2,2,2,2,2,2,2,2
2,2,2,2,2,2,2,2,2,2,2,2,2,2,2,2,2,1,1,1,1,1,1,1,1,1,1,1,1,1,1,1,1
2,2,2,2,2,2,2,2,2,2,2,2,2,2,2,2,2,1,1,1,1,1,1,1,1,1,1,1,1,1,1,1,1
2,2,2,2,2,2,2,2,2,2,2,2,2,2,2,2,2,1,1,1,1,1,1,1,1,1,1,1,1,1,1,1,1
2,2,2,2,2,2,2,2,2,2,2,2,2,2,2,2,2,2,2,2,2,2,2,2,2,2,2,2,2,2,2,2,2
2,2,2,2,2,2,2,2,2,2,2,2,2,2,2,2,2,2,2,2,2,2,2,2,2,2,2,2,2,2,2,2,2
2,2,2,2,2,2,2,2,2,2,2,2,2,2,2,2,2,2,2,2,2,2,2,2,2,2,2,2,2,2,2,2,2
2,2,2,2,2,2,2,2,2,2,2,2,2,2,2,2,2,2,2,2,2,2,2,2,2,2,2,2,2,2,2,2,2
2,2,2,2,2,2,2,2,2,2,2,2,2,2,2,2,2,2,2,2,2,2,2,2,2,2,2,2,2,2,2,2,2
2,2,2,2,2,2,2,2,2,2,2,2,2,2,2,2,2,2,2,2,2,2,2,2,2,2,2,2,2,2,2,2,2
2,2,2,2,2,2,2,2,2,2,2,2,2,2,2,2,2,2,2,2,2,2,2,2,2,2,2,2,2,2,2,2,2
2,2,2,2,2,2,2,2,2,2,2,2,2,2,2,2,2,2,2,2,2,2,2,2,2,2,2,2,2,2,2,2,2
2,2,2,2,2,2,2,2,2,2,2,2,2,2,2,2,2,2,2,2,2,2,2,2,2,2,2,2,2,2,2,2,2
2,2,2,2,2,2,2,2,2,2,2,2,2,2,2,2,2,2,2,2,2,2,2,2,2,2,2,2,2,2,2,2,2
2,2,2,2,2,2,2,2,2,2,2,2,2,2,2,2,2,2,2,2,2,2,2,2,2,2,2,2,2,2,2,2,2
2,2,2,2,2,2,2,2,2,2,2,2,2,2,2,2,2,2,2,2,2,2,2,2,2,2,2,2,2,2,2,2,2
2,2,2,2,2,2,2,2,2,2,2,2,2,2,2,2,2,2,2,2,2,2,2,2,2,2,2,2,2,2,2,2,2
:endlayer
layer: 3
2,2,2,2,2,2,2,2,2,2,2,2,2,2,2,2,2,2,2,2,2,2,2,2,2,2,2,2,2,2,2,2,2
2,2,2,2,2,2,2,2,2,2,2,2,2,2,2,2,2,2,2,2,2,2,2,2,2,2,2,2,2,2,2,2,2
2,2,2,2,2,2,2,2,2,2,2,2,2,2,2,2,2,2,2,2,2,2,2,2,2,2,2,2,2,2,2,2,2
2,2,2,2,2,2,2,2,2,2,2,2,2,2,2,2,2,2,2,2,2,2,2,2,2,2,2,2,2,2,2,2,2
2,2,2,2,2,2,2,2,2,2,2,2,2,2,2,2,2,2,2,2,2,2,2,2,2,2,2,2,2,2,2,2,2
2,2,2,2,2,2,2,2,2,2,2,2,2,2,2,2,2,2,2,2,2,2,2,2,2,2,2,2,2,2,2,2,2
2,2,2,2,2,2,2,2,2,2,2,2,2,2,2,2,2,2,2,2,2,2,2,2,2,2,2,2,2,2,2,2,2
2,2,2,2,2,2,2,2,2,2,2,2,2,2,2,2,2,2,2,2,2,2,2,2,2,2,2,2,2,2,2,2,2
2,2,2,2,2,2,2,2,2,2,2,2,2,2,2,2,2,2,2,2,2,2,2,2,2,2,2,2,2,2,2,2,2
2,2,2,2,2,2,2,2,2,2,2,2,2,2,2,2,2,2,2,2,2,2,2,2,2,2,2,2,2,2,2,2,2
2,2,2,2,2,2,2,2,2,2,2,2,2,2,2,2,2,2,2,2,2,2,2,2,2,2,2,2,2,2,2,2,2
2,2,2,2,2,2,2,2,2,2,2,2,2,2,2,2,2,2,2,2,2,2,2,2,2,2,2,2,2,2,2,2,2
2,2,2,2,2,2,2,2,2,2,2,2,2,2,2,2,2,2,2,2,2,2,2,2,2,2,2,2,2,2,2,2,2
2,2,2,2,2,2,2,2,2,2,2,2,2,2,2,2,2,2,2,2,2,2,2,2,2,2,2,2,2,2,2,2,2
2,2,2,2,2,2,2,2,2,2,2,2,2,2,2,2,2,2,2,2,2,2,2,2,2,2,2,2,2,2,2,2,2
2,2,2,2,2,2,2,2,2,2,2,2,2,2,2,2,2,2,2,2,2,2,2,2,2,2,2,2,2,2,2,2,2
2,2,2,2,2,2,2,2,2,2,2,2,2,2,2,2,2,2,2,2,2,2,2,2,2,2,2,2,2,2,2,2,2
2,2,2,2,2,2,2,2,2,2,2,2,2,2,2,2,2,2,2,2,2,2,2,2,2,2,2,2,2,2,2,2,2
2,2,2,2,2,2,2,2,2,2,2,2,2,2,2,2,2,2,2,2,2,2,2,2,2,2,2,2,2,2,2,2,2
2,2,2,2,2,2,2,2,2,2,2,2,2,2,2,2,2,2,2,2,2,2,2,2,2,2,2,2,2,2,2,2,2
2,2,2,2,2,2,2,2,2,2,2,2,2,2,2,2,2,2,2,2,2,2,2,2,2,2,2,2,2,2,2,2,2
2,2,2,2,2,2,2,2,2,2,2,2,2,2,2,2,2,2,2,2,2,2,2,2,2,2,2,2,2,2,1,1,1
2,2,2,2,2,2,2,2,2,2,2,2,2,2,2,2,2,2,2,2,2,2,2,2,2,2,2,2,2,2,1,1,1
2,2,2,2,2,2,2,2,2,2,2,2,2,2,2,2,2,2,2,2,2,2,2,2,2,2,2,2,2,2,1,1,1
2,2,2,2,2,2,2,2,2,2,2,2,2,2,2,2,2,2,2,2,2,2,2,2,2,2,2,2,2,2,2,2,2
2,2,2,2,2,2,2,2,2,2,2,2,2,2,2,2,2,2,2,2,2,2,2,2,2,2,2,2,2,2,2,2,2
2,2,2,2,2,2,2,2,2,2,2,2,2,2,2,2,2,2,2,2,2,2,2,2,2,2,2,2,2,2,2,2,2
2,2,2,2,2,2,2,2,2,2,2,2,2,2,2,2,2,2,2,2,2,2,2,2,2,2,2,2,2,2,2,2,2
2,2,2,2,2,2,2,2,2,2,2,2,2,2,2,2,2,2,2,2,2,2,2,2,2,2,2,2,2,2,2,2,2
2,2,2,2,2,2,2,2,2,2,2,2,2,2,2,2,2,2,2,2,2,2,2,2,2,2,2,2,2,2,2,2,2
2,2,2,2,2,2,2,2,2,2,2,2,2,2,2,2,2,2,2,2,2,2,2,2,2,2,2,2,2,2,2,2,2
2,2,2,2,2,2,2,2,2,2,2,2,2,2,2,2,2,2,2,2,2,2,2,2,2,2,2,2,2,2,2,2,2
2,2,2,2,2,2,2,2,2,2,2,2,2,2,2,2,2,2,2,2,2,2,2,2,2,2,2,2,2,2,2,2,2
2,2,2,2,2,2,2,2,2,2,2,2,2,2,2,2,2,2,2,2,2,2,2,2,2,2,2,2,2,2,2,2,2
2,2,2,2,2,2,2,2,2,2,2,2,2,2,2,2,2,2,2,2,2,2,2,2,2,2,2,2,2,2,2,2,2
2,2,2,2,2,2,2,2,2,2,2,2,2,2,2,2,2,2,2,2,2,2,2,2,2,2,2,2,2,2,2,2,2
2,2,2,2,2,2,2,2,2,2,2,2,2,2,2,2,2,2,2,2,2,2,2,2,2,2,2,2,2,2,2,2,2
:endlayer
layer: 4
2,2,2,2,2,2,2,2,2,2,2,2,2,2,2,2,2,2,2,2,2,2,2,2,2,2,2,2,2,2,2,2,2
2,2,2,2,2,2,2,2,2,2,2,2,2,2,2,2,2,2,2,2,2,2,2,2,2,2,2,2,2,2,2,2,2
2,2,2,2,2,2,2,2,2,2,2,2,2,2,2,2,2,2,2,2,2,2,2,2,2,2,2,2,2,2,2,2,2
2,2,2,2,2,2,2,2,2,2,2,2,2,2,2,2,2,2,2,2,2,2,2,2,2,2,2,2,2,2,2,2,2
2,2,2,2,2,2,2,2,2,2,2,2,2,2,2,2,2,2,2,2,2,2,2,2,2,2,2,2,2,2,2,2,2
2,2,2,2,2,2,2,2,2,2,2,2,2,2,2,2,2,2,2,2,2,2,2,2,2,2,2,2,2,2,2,2,2
2,2,2,2,2,2,2,2,2,2,2,2,2,2,2,2,2,2,2,2,2,2,2,2,2,2,2,2,2,2,2,2,2
2,2,2,2,2,2,2,2,2,2,2,2,2,2,2,2,2,2,2,2,2,2,2,2,2,2,2,2,2,2,2,2,2
2,2,2,2,2,2,2,2,2,2,2,2,2,2,2,2,2,2,2,2,2,2,2,2,2,2,2,2,2,2,2,2,2
2,2,2,2,2,2,2,2,2,2,2,2,2,2,2,2,2,2,2,2,2,2,2,2,2,2,2,2,2,2,2,2,2
2,2,2,2,2,2,2,2,2,2,2,2,2,2,2,2,2,2,2,2,2,2,2,2,2,2,2,2,2,2,2,2,2
2,2,2,2,2,2,2,3,3,3,3,3,2,2,2,2,2,3,3,3,3,3,3,3,2,2,2,2,2,2,2,2,2
2,2,2,2,2,2,3,3,3,3,3,3,3,2,2,2,2,3,3,3,3,3,3,3,3,2,2,2,2,2,2,2,2
2,2,2,2,2,2,3,3,3,3,3,3,3,3,3,3,3,3,3,3,3,3,3,3,3,2,2,2,2,2,2,2,2
2,2,2,2,2,2,3,3,3,3,3,3,3,3,3,3,3,3,3,3,3,3,3,3,3,2,2,2,2,2,2,2,2
2,2,2,2,2,2,3,3,3,3,3,3,3,3,3,3,3,3,3,3,3,3,3,3,3,2,2,2,2,2,2,2,2
2,2,2,2,2,2,3,3,3,3,3,3,3,3,3,3,3,3,3,3,3,3,3,3,3,2,2,2,2,2,2,2,2
2,2,2,2,2,2,3,3,3,3,3,3,3,3,3,3,3,3,3,3,3,3,3,3,2,2,2,2,2,2,2,2,2
2,2,2,2,2,2,2,2,3,3,3,3,3,3,3,3,3,3,3,3,3,3,3,3,2,2,2,2,2,2,2,2,2
2,2,2,2,2,2,2,2,3,3,3,3,3,3,3,3,3,3,3,3,3,3,3,3,2,2,2,2,2,2,2,2,2
2,2,2,2,2,2,2,3,3,3,3,3,3,3,3,3,3,3,2,2,2,2,3,2,2,2,2,2,2,2,2,2,2
2,2,2,2,2,2,2,3,3,3,3,3,2,3,3,3,3,3,2,2,2,3,3,2,2,2,2,2,2,2,2,2,2
2,2,2,2,2,2,2,3,3,3,3,3,2,3,3,3,3,3,2,3,3,3,3,2,2,2,2,2,2,2,2,2,2
2,2,2,2,2,2,2,3,3,3,3,3,2,3,3,3,3,3,2,3,3,3,3,3,4,2,2,2,2,2,2,2,2
2,2,2,2,2,2,3,3,3,3,3,3,2,3,3,3,3,3,2,3,3,3,3,3,3,2,2,2,2,2,2,2,2
2,2,2,2,2,2,3,3,3,3,3,3,2,2,2,2,2,2,2,3,3,3,3,3,3,2,2,2,2,2,2,2,2
2,2,2,2,2,2,3,3,3,3,3,3,2,2,2,2,2,2,2,3,3,3,3,3,3,2,2,2,2,2,2,2,2
2,2,2,2,2,2,3,3,3,3,3,3,2,2,2,2,2,2,2,3,3,3,3,3,3,2,2,2,2,2,2,2,2
2,2,2,2,2,2,2,3,3,3,3,3,2,2,2,2,2,2,2,3,3,3,3,3,2,2,2,2,2,2,2,2,2
2,2,2,2,2,2,2,2,2,2,2,2,2,2,2,2,2,2,2,2,2,2,2,2,2,2,2,2,2,2,2,2,2
2,2,2,2,2,2,2,2,2,2,2,2,2,2,2,2,2,2,2,2,2,2,2,2,2,2,2,2,2,2,2,2,2
2,2,2,2,2,2,2,2,2,2,2,2,2,2,2,2,2,2,2,2,2,2,2,2,2,2,2,2,2,2,2,2,2
2,2,2,2,2,2,2,2,2,2,2,2,2,2,2,2,2,2,2,2,2,2,2,2,2,2,2,2,2,2,2,2,2
2,2,2,2,2,2,2,2,2,2,2,2,2,2,2,2,2,2,2,2,2,2,2,2,2,2,2,2,2,2,2,2,2
2,2,2,2,2,2,2,2,2,2,2,2,2,2,2,2,2,2,2,2,2,2,2,2,2,2,2,2,2,2,2,2,2
2,2,2,2,2,2,2,2,2,2,2,2,2,2,2,2,2,2,2,2,2,2,2,2,2,2,2,2,2,2,2,2,2
2,2,2,2,2,2,2,2,2,2,2,2,2,2,2,2,2,2,2,2,2,2,2,2,2,2,2,2,2,2,2,2,2
:endlayer
layer: 5
5,5,5,5,5,5,5,5,5,5,5,5,5,5,5,5,5,5,5,5,5,5,5,5,5,5,5,5,5,5,5,5,5
5,5,5,5,5,5,5,5,5,5,5,5,5,5,5,5,5,5,5,5,5,5,5,5,5,5,5,5,5,5,5,5,5
5,5,5,5,5,5,5,5,5,5,5,5,5,5,5,5,5,5,5,5,5,5,5,5,5,5,5,5,5,5,5,5,5
5,5,5,5,5,5,5,5,5,5,5,5,5,5,5,5,5,5,5,5,5,5,5,5,5,5,5,5,5,5,5,5,5
5,5,5,5,5,5,5,5,5,5,5,5,5,5,5,5,5,5,5,5,5,5,5,5,5,5,5,5,5,5,5,5,5
5,5,5,5,5,5,5,5,5,5,5,5,5,5,5,5,5,5,5,5,5,5,5,5,5,5,5,5,5,5,5,5,5
5,5,5,5,5,5,5,5,5,5,5,5,5,5,5,5,5,5,5,5,5,5,5,5,5,5,5,5,5,5,5,5,5
5,5,5,5,5,5,5,5,5,5,5,5,5,5,5,5,5,5,5,5,5,5,5,5,5,5,5,5,5,5,5,5,5
5,5,5,5,5,5,5,5,5,5,5,5,5,5,5,5,5,5,5,5,5,5,5,5,5,5,5,5,5,5,5,5,5
5,5,5,5,5,5,5,2,2,2,2,2,5,5,5,5,5,5,5,2,2,2,2,2,5,5,5,5,5,5,5,5,5
5,5,5,5,5,5,5,4,4,4,4,4,2,5,5,5,5,5,2,4,4,4,4,4,5,5,5,5,5,5,5,5,5
5,5,5,5,5,5,4,0,60,0,60,0,4,2,2,2,2,2,4,31,27,0,17,13,4,5,5,5,5,5,5,5,5
5,5,5,5,5,4,0,0,60,0,60,0,0,4,4,4,4,4,3,0,0,0,0,0,6,4,5,5,5,5,5,5,5
5,5,5,5,5,4,0,73,60,63,60,55,0,3,0,0,0,0,3,32,0,21,18,0,7,4,5,5,5,5,5,5,5
5,5,5,5,5,4,60,56,60,56,60,56,22,3,47,0,42,0,22,33,0,22,0,0,0,4,5,5,5,5,5,5,5
5,5,5,5,5,4,0,0,69,0,0,0,20,50,0,0,0,0,3,0,0,0,19,0,8,4,5,5,5,5,5,5,5
5,5,5,5,5,4,0,36,0,0,0,0,54,0,0,0,0,0,38,0,0,0,0,0,9,4,5,5,5,5,5,5,5
5,5,5,5,5,5,4,74,0,64,0,0,0,0,0,0,0,0,38,0,0,0,0,0,4,5,5,5,5,5,5,5,5
5,5,5,5,5,5,5,4,0,0,0,0,0,0,0,0,0,0,3,0,0,0,0,4,5,5,5,5,5,5,5,5,5
5,5,5,5,5,5,5,4,16,65,0,0,0,51,0,0,0,0,3,34,28,23,0,4,5,5,5,5,5,5,5,5,5
5,5,5,5,5,5,5,4,3,22,57,57,22,52,48,0,43,40,22,3,3,22,0,4,5,5,5,5,5,5,5,5,5
5,5,5,5,5,5,5,4,70,66,0,0,4,22,0,0,0,22,4,3,3,24,0,4,5,5,5,5,5,5,5,5,5
5,5,5,5,5,5,5,4,71,0,0,0,4,53,49,46,44,41,4,35,0,0,0,4,5,5,5,5,5,5,5,5,5
5,5,5,5,5,5,4,75,0,67,0,58,4,0,0,0,0,0,4,3,29,0,0,14,4,5,5,5,5,5,5,5,5
5,5,5,5,5,4,79,76,0,68,0,36,4,0,0,0,0,0,4,36,30,0,0,0,10,4,5,5,5,5,5,5,5
5,5,5,5,5,4,0,77,0,22,0,58,4,4,45,45,45,4,4,36,30,0,0,0,0,4,5,5,5,5,5,5,5
5,5,5,5,5,4,0,0,0,0,0,0,4,4,4,4,4,4,4,3,29,25,0,15,11,4,5,5,5,5,5,5,5
5,5,5,5,5,4,79,76,72,0,61,59,4,4,4,4,4,4,4,37,0,0,0,0,12,4,5,5,5,5,5,5,5
5,5,5,5,5,5,4,78,0,0,62,4,4,4,4,4,4,4,4,4,16,26,20,16,4,5,5,5,5,5,5,5,5
5,5,5,5,5,5,5,4,4,4,4,4,4,4,4,4,4,4,4,4,4,4,4,4,5,5,5,5,5,5,5,5,5
5,5,5,5,5,5,5,5,5,5,5,5,39,39,39,39,39,39,39,5,5,5,5,5,5,5,5,5,5,5,5,5,5
5,5,5,5,5,5,5,5,5,5,5,5,2,39,39,39,39,39,2,5,5,5,5,5,5,5,5,5,5,5,5,5,5
5,5,5,5,5,5,5,5,5,5,5,5,5,5,39,39,39,5,5,5,5,5,5,5,5,5,5,5,5,5,5,5,5
5,5,5,5,5,5,5,5,5,5,5,5,5,5,5,5,5,5,5,5,5,5,5,5,5,5,5,5,5,5,5,5,5
5,5,5,5,5,5,5,5,5,5,5,5,5,5,5,5,5,5,5,5,5,5,5,5,5,5,5,5,5,5,5,5,5
5,5,5,5,5,5,5,5,5,5,5,5,5,5,5,5,5,5,5,5,5,5,5,5,5,5,5,5,5,5,5,5,5
5,5,5,5,5,5,5,5,5,5,5,5,5,5,5,5,5,5,5,5,5,5,5,5,5,5,5,5,5,5,5,5,5
:endlayer
layer: 6
0,0,0,0,0,0,0,0,0,0,0,0,0,0,0,0,0,0,0,0,0,0,0,0,0,0,0,0,0,0,0,0,0
0,0,0,0,0,0,0,0,0,0,0,0,0,0,0,0,0,0,0,0,0,0,0,0,0,0,0,0,0,0,0,0,0
0,0,106,0,0,0,0,0,0,0,0,0,0,0,0,0,0,82,0,0,0,0,0,0,0,0,0,0,0,0,81,0,0
0,0,0,0,0,0,0,0,0,0,0,0,0,0,0,0,0,0,0,0,0,0,0,0,0,0,0,0,0,0,0,0,0
0,0,0,0,0,82,82,82,0,82,0,0,0,0,0,0,0,0,0,0,0,0,0,0,0,0,0,0,0,82,0,0,0
0,0,0,82,0,82,0,82,0,0,0,0,0,0,82,0,0,82,0,0,0,0,0,84,82,84,82,0,82,82,0,0,0
0,82,0,0,82,82,82,82,82,0,0,0,82,0,82,0,82,82,0,0,0,0,0,82,0,82,0,0,0,0,0,0,0
82,0,82,0,82,82,82,82,82,0,0,0,82,82,82,82,0,0,82,0,0,0,82,0,82,82,82,83,0,0,0,0,0
0,0,82,82,82,82,82,84,0,0,0,0,82,82,82,82,83,82,0,0,0,0,0,0,82,82,82,82,0,0,0,0,0
0,82,82,82,82,82,0,4,4,4,4,4,82,82,82,82,0,82,0,4,4,4,4,4,82,82,0,0,0,0,0,0,0
0,82,84,82,0,82,0,4,4,4,4,4,4,0,0,0,82,0,4,4,4,4,4,4,82,82,82,0,0,0,0,0,0
0,0,83,82,82,82,4,0,60,0,60,0,4,4,4,4,4,4,4,85,85,0,85,85,4,0,0,82,0,0,0,0,0
0,0,82,0,82,4,0,0,60,0,60,0,0,4,4,4,4,4,3,0,0,0,0,0,85,4,0,0,0,0,0,0,0
0,0,0,82,0,4,0,0,60,0,60,0,0,3,0,0,0,0,3,85,0,0,0,0,85,4,0,82,0,0,0,0,0
0,0,0,0,0,4,60,0,60,0,60,0,22,3,0,0,0,0,22,85,0,22,0,0,0,4,82,0,0,0,0,0,0
0,0,82,0,0,4,0,0,0,0,0,0,20,50,0,0,0,0,3,0,0,0,0,0,85,4,0,0,0,0,0,0,0
0,0,0,82,82,4,0,0,0,0,0,0,0,0,0,0,0,0,89,0,0,0,0,0,85,4,0,82,0,0,0,0,0
0,0,82,82,0,82,4,105,0,0,0,0,0,0,0,0,0,0,90,0,0,0,0,0,4,0,0,82,0,0,0,0,0
0,0,0,82,82,82,0,4,0,0,0,0,0,0,0,0,0,0,3,0,0,0,0,4,0,84,83,82,0,0,0,0,0
0,0,82,82,82,82,0,4,0,0,0,0,0,0,0,0,0,0,3,0,0,0,0,4,0,0,0,82,0,0,0,0,0
82,0,0,82,0,0,82,4,3,22,90,89,22,0,0,0,0,0,22,34,3,22,0,4,0,0,0,82,0,0,0,0,0
0,0,82,0,0,82,0,4,0,0,0,0,4,22,0,0,0,22,4,3,3,0,0,4,0,0,0,0,0,0,0,0,0
82,82,82,82,82,0,0,4,0,0,0,0,4,102,99,97,94,91,4,86,0,0,0,4,0,0,82,82,0,82,0,0,0
83,82,82,82,82,0,4,0,0,0,0,58,4,0,0,0,0,0,4,3,0,0,0,0,4,82,82,82,82,82,0,0,0
82,82,82,0,0,4,0,0,0,68,0,0,4,52,0,0,0,0,4,0,0,0,0,0,0,4,0,82,82,82,0,0,0
82,82,82,0,0,4,0,0,0,22,0,58,4,92,0,0,0,92,4,0,0,0,0,0,0,4,0,0,0,82,0,0,0
0,0,82,0,0,4,0,0,0,0,0,0,4,103,100,98,95,93,4,3,0,0,0,0,0,4,0,82,82,82,0,0,0
0,82,82,0,82,4,0,0,0,0,0,0,4,92,0,0,0,92,4,87,0,0,0,0,0,4,82,82,82,0,0,0,0
0,82,0,82,82,82,4,0,0,0,0,4,0,0,0,0,0,0,0,4,0,0,0,0,4,82,82,82,82,82,0,0,0
0,0,82,82,82,0,0,4,4,4,4,104,0,0,101,0,96,0,0,88,4,4,4,4,82,0,82,82,0,0,0,0,0
0,0,82,82,82,82,0,0,0,82,82,0,0,0,0,0,0,0,0,0,0,82,82,82,82,82,0,82,0,0,0,0,0
0,0,82,82,82,0,0,0,82,82,82,82,4,0,0,0,0,0,4,0,0,82,82,82,82,0,82,0,0,0,0,0,0
0,0,0,0,0,0,0,0,0,0,0,0,0,0,0,0,0,0,0,82,82,82,82,0,0,0,82,0,0,0,0,0,0
0,0,0,0,0,0,0,0,0,0,0,0,0,0,0,0,0,0,0,0,0,0,0,0,0,0,0,0,0,0,0,0,0
0,0,0,0,0,0,0,0,0,0,0,0,0,0,0,0,0,0,0,0,0,0,0,0,0,0,0,0,0,0,0,0,0
0,107,0,0,0,0,0,0,0,0,0,0,0,0,0,0,0,0,0,0,0,0,0,0,0,0,0,0,0,0,0,80,0
0,0,0,0,0,0,0,0,0,0,0,0,0,0,0,0,0,0,0,0,0,0,0,0,0,0,0,0,0,0,0,0,0
:endlayer
layer: 7
0,0,0,0,0,0,0,0,0,0,0,0,0,0,0,0,0,0,0,0,0,0,0,0,0,0,0,0,0,0,0,0,0
0,0,0,0,0,0,0,0,0,0,0,0,0,0,0,0,0,0,0,0,0,0,0,0,0,0,0,0,0,0,0,0,0
0,0,0,0,0,0,0,0,0,0,0,0,0,0,0,0,0,0,0,0,0,0,0,0,0,0,0,0,0,0,0,0,0
0,0,0,0,0,0,0,0,0,0,0,0,0,0,0,0,0,0,0,0,0,0,0,0,0,0,0,0,0,0,0,0,0
0,0,0,0,0,0,0,0,0,0,0,0,0,0,0,0,0,0,0,0,0,0,0,0,0,0,0,0,0,0,0,0,0
0,0,0,0,0,0,0,0,0,0,0,0,0,0,0,0,0,0,0,0,0,0,0,0,0,0,0,0,0,0,0,0,0
0,0,0,0,0,0,0,0,0,0,0,0,0,0,0,0,0,0,0,0,0,0,0,0,0,0,0,0,0,0,0,0,0
0,0,0,0,0,0,0,0,0,0,0,0,0,0,0,0,0,0,0,0,0,0,0,0,0,0,0,0,0,0,0,0,0
0,0,0,0,0,0,0,0,0,0,0,0,0,0,0,0,0,0,0,0,0,0,0,0,0,0,0,0,0,0,0,0,0
0,0,0,0,0,0,0,4,4,4,4,4,0,0,0,0,0,0,0,4,4,4,4,4,0,0,0,0,0,0,0,0,0
0,0,0,0,0,0,0,4,4,4,4,4,4,0,0,0,0,0,4,4,4,4,4,4,0,0,0,0,0,0,0,0,0
0,0,0,0,0,0,4,117,0,115,0,110,4,4,4,129,4,4,4,118,116,115,114,113,4,0,0,0,0,0,0,0,0
0,0,0,0,0,4,115,0,0,0,0,0,115,4,4,0,4,4,3,117,0,0,0,0,108,4,0,0,0,0,0,0,0
0,0,0,0,0,4,0,0,0,0,0,0,0,3,0,0,0,0,3,119,0,0,0,0,109,4,0,0,0,0,0,0,0
0,0,0,0,0,4,0,0,0,0,0,0,22,3,0,0,0,0,22,120,0,22,0,0,110,4,0,0,0,0,0,0,0
0,0,0,0,0,4,0,0,0,0,0,110,20,50,0,0,0,0,3,0,0,0,0,0,111,4,0,0,0,0,0,0,0
0,0,0,0,0,4,0,0,0,0,0,0,115,0,0,0,0,110,20,117,0,0,0,0,112,4,0,0,0,0,0,0,0
0,0,0,0,0,0,4,140,0,0,0,0,0,0,0,0,0,110,20,117,0,0,0,110,4,0,0,0,0,0,0,0,0
0,0,0,0,0,0,0,4,0,0,0,0,0,0,0,0,0,0,3,0,0,0,0,4,0,0,0,0,0,0,0,0,0
0,0,0,0,0,0,0,4,139,0,137,137,0,0,0,0,0,0,3,0,0,0,0,4,0,0,0,0,0,0,0,0,0
0,0,0,0,0,0,0,4,3,22,20,20,22,0,0,0,0,0,22,0,3,22,0,4,0,0,0,0,0,0,0,0,0
0,0,0,0,0,0,0,4,0,0,115,115,4,22,0,0,0,22,4,34,3,0,0,4,0,0,0,0,0,0,0,0,0
0,0,0,0,0,0,0,4,0,0,0,0,4,134,132,130,127,125,4,121,0,0,0,4,0,0,0,0,0,0,0,0,0
0,0,0,0,0,0,4,117,0,0,0,138,4,0,0,0,0,0,4,3,117,0,0,0,4,0,0,0,0,0,0,0,0
0,0,0,0,0,4,115,0,0,68,0,138,4,117,0,0,0,110,4,122,0,0,0,0,0,4,0,0,0,0,0,0,0
0,0,0,0,0,4,0,0,110,22,117,138,4,58,0,0,0,58,4,122,0,0,0,0,0,4,0,0,0,0,0,0,0
0,0,0,0,0,4,0,0,0,115,0,0,4,135,133,131,128,126,4,3,117,0,0,0,0,4,0,0,0,0,0,0,0
0,0,0,0,0,4,137,0,0,0,0,137,4,58,0,0,0,58,4,123,0,0,0,0,0,4,0,0,0,0,0,0,0
0,0,0,0,0,0,4,117,0,0,110,4,136,0,0,0,0,0,0,4,117,0,0,110,4,0,0,0,0,0,0,0,0
0,0,0,0,0,0,0,4,4,4,4,0,0,0,0,0,0,0,0,0,4,4,4,4,0,0,0,0,0,0,0,0,0
0,0,0,0,0,0,0,0,0,0,0,0,0,0,0,0,0,0,0,0,0,0,0,0,0,0,0,0,0,0,0,0,0
0,0,0,0,0,0,0,0,0,0,0,0,124,0,0,0,0,0,124,0,0,0,0,0,0,0,0,0,0,0,0,0,0
0,0,0,0,0,0,0,0,0,0,0,0,0,0,0,0,0,0,0,0,0,0,0,0,0,0,0,0,0,0,0,0,0
0,0,0,0,0,0,0,0,0,0,0,0,0,0,0,0,0,0,0,0,0,0,0,0,0,0,0,0,0,0,0,0,0
0,0,0,0,0,0,0,0,0,0,0,0,0,0,0,0,0,0,0,0,0,0,0,0,0,0,0,0,0,0,0,0,0
0,0,0,0,0,0,0,0,0,0,0,0,0,0,0,0,0,0,0,0,0,0,0,0,0,0,0,0,0,0,0,0,0
0,0,0,0,0,0,0,0,0,0,0,0,0,0,0,0,0,0,0,0,0,0,0,0,0,0,0,0,0,0,0,0,0
:endlayer
layer: 8
0,0,0,0,0,0,0,0,0,0,0,0,0,0,0,0,0,0,0,0,0,0,0,0,0,0,0,0,0,0,0,0,0
0,0,0,0,0,0,0,0,0,0,0,0,0,0,0,0,0,0,0,0,0,0,0,0,0,0,0,0,0,0,0,0,0
0,0,0,0,0,0,0,0,0,0,0,0,0,0,0,0,0,0,0,0,0,0,0,0,0,0,0,0,0,0,0,0,0
0,0,0,0,0,0,0,0,0,0,0,0,0,0,0,0,0,0,0,0,0,0,0,0,0,0,0,0,0,0,0,0,0
0,0,0,0,0,0,0,0,0,0,0,0,0,0,0,0,0,0,0,0,0,0,0,0,0,0,0,0,0,0,0,0,0
0,0,0,0,0,0,0,0,0,0,0,0,0,0,0,0,0,0,0,0,0,0,0,0,0,0,0,0,0,0,0,0,0
0,0,0,0,0,0,0,0,0,0,0,0,0,0,0,0,0,0,0,0,0,0,0,0,0,0,0,0,0,0,0,0,0
0,0,0,0,0,0,0,0,0,0,0,0,0,0,0,0,0,0,0,0,0,0,0,0,0,0,0,0,0,0,0,0,0
0,0,0,0,0,0,0,137,0,0,0,137,0,0,0,0,0,0,0,137,0,0,0,137,0,0,0,0,0,0,0,0,0
0,0,0,0,0,0,110,4,4,129,4,4,117,0,0,0,0,0,110,4,4,129,4,4,117,0,0,0,0,0,0,0,0
0,0,0,0,0,0,0,4,4,0,4,4,4,0,0,0,0,0,4,4,4,0,4,4,0,0,0,0,0,0,0,0,0
0,0,0,0,0,137,4,0,0,0,0,0,4,4,4,129,4,4,4,0,0,0,0,0,4,137,0,0,0,0,0,0,0
0,0,0,0,110,4,0,0,0,0,0,0,0,4,4,0,4,4,3,0,0,0,0,0,0,4,117,0,0,0,0,0,0
0,0,0,0,0,4,0,0,0,0,0,0,0,3,0,0,0,0,3,0,0,137,0,0,0,4,0,0,0,0,0,0,0
0,0,0,0,0,4,0,0,0,0,0,0,22,3,0,0,0,110,22,0,110,22,117,0,0,4,0,0,0,0,0,0,0
0,0,0,0,0,4,0,0,0,0,0,0,20,50,0,0,0,0,3,0,0,115,0,0,0,4,0,0,0,0,0,0,0
0,0,0,0,110,4,0,0,0,0,0,0,0,0,0,0,0,0,3,0,0,0,0,0,0,4,117,0,0,0,0,0,0
0,0,0,0,0,115,4,152,0,0,0,0,0,0,0,0,0,0,3,0,0,0,0,0,4,115,0,0,0,0,0,0,0
0,0,0,0,0,0,0,4,117,0,0,0,0,0,0,0,0,0,3,0,0,0,0,4,0,0,0,0,0,0,0,0,0
0,0,0,0,0,0,0,4,151,0,0,0,137,0,0,0,0,0,3,0,0,137,0,4,0,0,0,0,0,0,0,0,0
0,0,0,0,0,0,0,4,3,22,20,20,22,137,0,0,0,137,22,0,3,22,3,4,0,0,0,0,0,0,0,0,0
0,0,0,0,0,0,0,4,0,0,0,0,4,22,117,0,110,22,4,0,3,3,3,4,0,0,0,0,0,0,0,0,0
0,0,0,0,0,0,0,4,0,0,0,0,4,149,147,145,143,141,4,34,3,3,3,4,0,0,0,0,0,0,0,0,0
0,0,0,0,0,137,4,0,0,0,0,0,4,0,0,0,0,0,4,3,3,3,3,3,4,137,0,0,0,0,0,0,0
0,0,0,0,110,4,0,0,0,68,0,0,4,0,0,0,0,0,4,3,3,3,3,3,3,4,117,0,0,0,0,0,0
0,0,0,0,0,4,0,0,0,22,0,0,4,58,0,0,0,58,4,3,3,3,3,3,3,4,0,0,0,0,0,0,0
0,0,0,0,0,4,0,0,0,0,0,0,4,150,148,146,144,142,4,3,3,3,3,3,3,4,0,0,0,0,0,0,0
0,0,0,0,110,4,0,0,0,0,0,0,4,58,0,0,0,58,4,3,3,3,3,3,3,4,117,0,0,0,0,0,0
0,0,0,0,0,115,4,0,0,0,0,4,115,0,0,0,0,0,115,4,3,3,3,3,4,115,0,0,0,0,0,0,0
0,0,0,0,0,0,0,4,4,4,4,117,0,0,0,0,0,0,0,110,4,4,4,4,117,0,0,0,0,0,0,0,0
0,0,0,0,0,0,0,0,0,0,115,0,0,0,0,0,0,0,0,0,115,0,0,115,0,0,0,0,0,0,0,0,0
0,0,0,0,0,0,0,0,0,0,0,0,0,0,0,0,0,0,0,0,0,0,0,0,0,0,0,0,0,0,0,0,0
0,0,0,0,0,0,0,0,0,0,0,0,0,0,0,0,0,0,0,0,0,0,0,0,0,0,0,0,0,0,0,0,0
0,0,0,0,0,0,0,0,0,0,0,0,0,0,0,0,0,0,0,0,0,0,0,0,0,0,0,0,0,0,0,0,0
0,0,0,0,0,0,0,0,0,0,0,0,0,0,0,0,0,0,0,0,0,0,0,0,0,0,0,0,0,0,0,0,0
0,0,0,0,0,0,0,0,0,0,0,0,0,0,0,0,0,0,0,0,0,0,0,0,0,0,0,0,0,0,0,0,0
0,0,0,0,0,0,0,0,0,0,0,0,0,0,0,0,0,0,0,0,0,0,0,0,0,0,0,0,0,0,0,0,0
:endlayer
layer: 9
0,0,0,0,0,0,0,0,0,0,0,0,0,0,0,0,0,0,0,0,0,0,0,0,0,0,0,0,0,0,0,0,0
0,0,0,0,0,0,0,0,0,0,0,0,0,0,0,0,0,0,0,0,0,0,0,0,0,0,0,0,0,0,0,0,0
0,0,0,0,0,0,0,0,0,0,0,0,0,0,0,0,0,0,0,0,0,0,0,0,0,0,0,0,0,0,0,0,0
0,0,0,0,0,0,0,0,0,0,0,0,0,0,0,0,0,0,0,0,0,0,0,0,0,0,0,0,0,0,0,0,0
0,0,0,0,0,0,0,0,0,0,0,0,0,0,0,0,0,0,0,0,0,0,0,0,0,0,0,0,0,0,0,0,0
0,0,0,0,0,0,0,0,0,0,0,0,0,0,0,0,0,0,0,0,0,0,0,0,0,0,0,0,0,0,0,0,0
0,0,0,0,0,0,0,0,0,0,0,0,0,0,0,0,0,0,0,0,0,0,0,0,0,0,0,0,0,0,0,0,0
0,0,0,0,0,0,0,0,0,0,0,0,0,0,0,0,0,0,0,0,0,0,0,0,0,0,0,0,0,0,0,0,0
0,0,0,0,0,0,0,0,0,0,0,0,0,0,0,0,0,0,0,0,0,0,0,0,0,0,0,0,0,0,0,0,0
0,0,0,0,0,0,0,3,3,3,3,3,0,0,0,0,0,0,0,3,3,3,3,3,0,0,0,0,0,0,0,0,0
0,0,0,0,0,0,0,3,3,0,3,3,3,0,0,0,0,0,3,4,0,0,0,3,0,0,0,0,0,0,0,0,0
0,0,0,0,0,0,3,20,20,20,20,20,3,3,3,3,3,3,3,0,0,0,0,0,3,0,0,0,0,0,0,0,0
0,0,0,0,0,3,20,20,20,20,20,20,20,3,3,0,3,3,3,0,0,0,0,0,0,3,0,0,0,0,0,0,0
0,0,0,0,0,3,20,20,20,20,20,20,20,3,0,0,0,0,3,0,0,0,0,0,0,3,0,0,0,0,0,0,0
0,0,0,0,0,3,157,157,157,157,157,157,22,3,117,0,0,0,22,0,0,22,0,0,0,3,0,0,0,0,0,0,0
0,0,0,0,0,3,20,20,20,20,20,20,168,50,0,0,0,0,3,0,0,0,0,0,0,3,0,0,0,0,0,0,0
0,0,0,0,0,3,0,0,0,0,0,0,168,0,0,0,0,0,3,0,0,0,0,0,0,3,0,0,0,0,0,0,0
0,0,0,0,0,0,3,0,0,0,0,0,168,0,0,0,0,0,3,0,0,0,0,0,3,0,0,0,0,0,0,0,0
0,0,0,0,0,0,0,3,0,0,0,0,168,0,0,0,0,0,3,0,0,0,0,3,0,0,0,0,0,0,0,0,0
0,0,0,0,0,0,0,3,0,0,0,0,168,157,157,157,157,157,3,0,0,0,0,3,0,0,0,0,0,0,0,0,0
0,0,0,0,0,0,0,3,3,22,157,157,22,0,0,0,0,0,22,0,3,22,153,3,0,0,0,0,0,0,0,0,0
0,0,0,0,0,0,0,3,20,20,20,20,156,22,0,0,0,22,156,0,3,0,0,3,0,0,0,0,0,0,0,0,0
0,0,0,0,0,0,0,3,20,20,20,20,156,166,164,162,160,158,156,0,3,0,0,3,0,0,0,0,0,0,0,0,0
0,0,0,0,0,0,3,20,20,20,20,20,156,0,0,0,0,0,156,0,155,0,0,0,3,0,0,0,0,0,0,0,0
0,0,0,0,0,3,20,20,20,68,20,20,156,0,0,0,0,0,156,0,0,0,0,0,0,3,0,0,0,0,0,0,0
0,0,0,0,0,3,20,20,20,22,20,20,4,58,0,0,0,58,4,0,0,22,0,0,0,3,0,0,0,0,0,0,0
0,0,0,0,0,3,20,20,20,20,20,20,4,167,165,163,161,159,4,0,0,0,154,0,0,3,0,0,0,0,0,0,0
0,0,0,0,0,3,20,20,20,20,20,20,3,58,0,0,0,58,3,0,0,0,0,0,0,3,0,0,0,0,0,0,0
0,0,0,0,0,0,3,20,20,20,20,3,0,0,0,0,0,0,0,3,0,0,0,0,3,0,0,0,0,0,0,0,0
0,0,0,0,0,0,0,3,3,3,3,0,0,0,0,0,0,0,0,0,3,3,3,3,0,0,0,0,0,0,0,0,0
0,0,0,0,0,0,0,0,0,0,0,0,0,0,0,0,0,0,0,0,0,0,0,0,0,0,0,0,0,0,0,0,0
0,0,0,0,0,0,0,0,0,0,0,0,0,0,0,0,0,0,0,0,0,0,0,0,0,0,0,0,0,0,0,0,0
0,0,0,0,0,0,0,0,0,0,0,0,0,0,0,0,0,0,0,0,0,0,0,0,0,0,0,0,0,0,0,0,0
0,0,0,0,0,0,0,0,0,0,0,0,0,0,0,0,0,0,0,0,0,0,0,0,0,0,0,0,0,0,0,0,0
0,0,0,0,0,0,0,0,0,0,0,0,0,0,0,0,0,0,0,0,0,0,0,0,0,0,0,0,0,0,0,0,0
0,0,0,0,0,0,0,0,0,0,0,0,0,0,0,0,0,0,0,0,0,0,0,0,0,0,0,0,0,0,0,0,0
0,0,0,0,0,0,0,0,0,0,0,0,0,0,0,0,0,0,0,0,0,0,0,0,0,0,0,0,0,0,0,0,0
:endlayer
layer: 10
0,0,0,0,0,0,0,0,0,0,0,0,0,0,0,0,0,0,0,0,0,0,0,0,0,0,0,0,0,0,0,0,0
0,0,0,0,0,0,0,0,0,0,0,0,0,0,0,0,0,0,0,0,0,0,0,0,0,0,0,0,0,0,0,0,0
0,0,0,0,0,0,0,0,0,0,0,0,0,0,0,0,0,0,0,0,0,0,0,0,0,0,0,0,0,0,0,0,0
0,0,0,0,0,0,0,0,0,0,0,0,0,0,0,0,0,0,0,0,0,0,0,0,0,0,0,0,0,0,0,0,0
0,0,0,0,0,0,0,0,0,0,0,0,0,0,0,0,0,0,0,0,0,0,0,0,0,0,0,0,0,0,0,0,0
0,0,0,0,0,0,0,0,0,0,0,0,0,0,0,0,0,0,0,0,0,0,0,0,0,0,0,0,0,0,0,0,0
0,0,0,0,0,0,0,0,0,0,0,0,0,0,0,0,0,0,0,0,0,0,0,0,0,0,0,0,0,0,0,0,0
0,0,0,0,0,0,0,0,0,0,0,0,0,0,0,0,0,0,0,0,0,0,0,0,0,0,0,0,0,0,0,0,0
0,0,0,0,0,0,0,0,0,0,0,0,0,0,0,0,0,0,0,0,0,0,0,0,0,0,0,0,0,0,0,0,0
0,0,0,0,0,0,0,4,4,4,4,4,0,0,0,0,0,0,0,4,4,4,4,4,0,0,0,0,0,0,0,0,0
0,0,0,0,0,0,0,4,4,4,4,4,4,0,0,0,0,0,4,4,4,4,4,4,0,0,0,0,0,0,0,0,0
0,0,0,0,0,0,4,0,54,182,54,176,4,4,4,4,4,4,4,0,115,0,115,0,4,0,0,0,0,0,0,0,0
0,0,0,0,0,4,54,0,0,54,0,177,176,4,4,4,4,4,3,0,0,0,0,0,0,4,0,0,0,0,0,0,0
0,0,0,0,0,4,54,0,54,0,54,0,0,3,0,0,0,0,3,0,0,0,0,0,110,4,0,0,0,0,0,0,0
0,0,0,0,0,129,0,0,0,22,0,0,22,3,0,0,0,0,22,117,0,22,0,0,0,129,0,0,0,0,0,0,0
0,0,0,0,0,4,187,0,0,0,0,0,0,0,0,0,0,0,3,0,0,0,0,0,110,4,0,0,0,0,0,0,0
0,0,0,0,0,4,0,0,0,0,0,0,0,0,0,0,0,0,3,0,0,0,0,0,0,4,0,0,0,0,0,0,0
0,0,0,0,0,0,4,0,0,0,0,0,0,0,0,0,0,0,3,0,0,0,0,0,4,0,0,0,0,0,0,0,0
0,0,0,0,0,0,0,4,0,0,0,0,0,0,0,0,0,0,3,0,0,0,0,4,0,0,0,0,0,0,0,0,0
0,0,0,0,0,0,0,4,0,0,0,0,0,0,0,0,0,0,3,0,0,0,0,4,0,0,0,0,0,0,0,0,0
0,0,0,0,0,0,0,4,3,22,3,3,22,169,169,169,169,169,22,0,3,22,0,129,0,0,0,0,0,0,0,0,0
0,0,0,0,0,0,0,4,70,183,180,70,156,22,157,157,157,22,156,0,3,0,0,4,0,0,0,0,0,0,0,0,0
0,0,0,0,0,0,0,4,71,0,0,71,156,157,157,157,157,157,156,0,155,0,0,4,0,0,0,0,0,0,0,0,0
0,0,0,0,0,0,4,185,0,0,0,0,156,0,0,0,0,0,156,0,0,0,0,0,4,0,0,0,0,0,0,0,0
0,0,0,0,0,4,79,76,0,68,0,178,156,0,0,0,0,0,156,0,0,0,0,0,0,4,0,0,0,0,0,0,0
0,0,0,0,0,4,0,0,0,22,0,179,4,4,0,0,0,4,4,0,0,22,0,0,0,4,0,0,0,0,0,0,0
0,0,0,0,0,4,0,0,0,0,0,61,4,175,174,173,172,170,4,0,0,0,0,0,0,129,0,0,0,0,0,0,0
0,0,0,0,0,4,79,76,184,61,0,62,4,171,0,0,0,171,4,0,0,0,0,0,0,4,0,0,0,0,0,0,0
0,0,0,0,0,0,4,186,0,62,181,4,0,0,0,0,0,0,0,4,0,0,0,0,4,0,0,0,0,0,0,0,0
0,0,0,0,0,0,0,4,4,129,4,0,0,0,0,0,0,0,0,0,4,129,4,4,0,0,0,0,0,0,0,0,0
0,0,0,0,0,0,0,0,0,0,0,0,0,0,0,0,0,0,0,0,0,0,0,0,0,0,0,0,0,0,0,0,0
0,0,0,0,0,0,0,0,0,0,0,0,0,0,0,0,0,0,0,0,0,0,0,0,0,0,0,0,0,0,0,0,0
0,0,0,0,0,0,0,0,0,0,0,0,0,0,0,0,0,0,0,0,0,0,0,0,0,0,0,0,0,0,0,0,0
0,0,0,0,0,0,0,0,0,0,0,0,0,0,0,0,0,0,0,0,0,0,0,0,0,0,0,0,0,0,0,0,0
0,0,0,0,0,0,0,0,0,0,0,0,0,0,0,0,0,0,0,0,0,0,0,0,0,0,0,0,0,0,0,0,0
0,0,0,0,0,0,0,0,0,0,0,0,0,0,0,0,0,0,0,0,0,0,0,0,0,0,0,0,0,0,0,0,0
0,0,0,0,0,0,0,0,0,0,0,0,0,0,0,0,0,0,0,0,0,0,0,0,0,0,0,0,0,0,0,0,0
:endlayer
layer: 11
0,0,0,0,0,0,0,0,0,0,0,0,0,0,0,0,0,0,0,0,0,0,0,0,0,0,0,0,0,0,0,0,0
0,0,0,0,0,0,0,0,0,0,0,0,0,0,0,0,0,0,0,0,0,0,0,0,0,0,0,0,0,0,0,0,0
0,0,0,0,0,0,0,0,0,0,0,0,0,0,0,0,0,0,0,0,0,0,0,0,0,0,0,0,0,0,0,0,0
0,0,0,0,0,0,0,0,0,0,0,0,0,0,0,0,0,0,0,0,0,0,0,0,0,0,0,0,0,0,0,0,0
0,0,0,0,0,0,0,0,0,0,0,0,0,0,0,0,0,0,0,0,0,0,0,0,0,0,0,0,0,0,0,0,0
0,0,0,0,0,0,0,0,0,0,0,0,0,0,0,0,0,0,0,0,0,0,0,0,0,0,0,0,0,0,0,0,0
0,0,0,0,0,0,0,0,0,0,0,0,0,0,0,0,0,0,0,0,0,0,0,0,0,0,0,0,0,0,0,0,0
0,0,0,0,0,0,0,0,0,0,0,0,0,0,0,0,0,0,0,0,0,0,0,0,0,0,0,0,0,0,0,0,0
0,0,0,0,0,0,0,188,188,188,188,188,0,0,0,0,0,0,0,188,188,188,188,188,0,0,0,0,0,0,0,0,0
0,0,0,0,0,0,0,4,3,3,3,3,188,0,0,0,0,0,188,4,3,3,3,4,0,0,0,0,0,0,0,0,0
0,0,0,0,0,0,0,4,4,4,4,4,3,188,0,188,0,188,3,4,4,4,4,4,0,0,0,0,0,0,0,0,0
0,0,0,0,0,0,4,0,182,0,0,176,4,3,3,3,3,3,4,0,0,0,0,0,4,0,0,0,0,0,0,0,0
0,0,0,0,0,4,182,0,0,0,0,0,0,4,4,4,4,4,3,0,0,0,0,0,0,4,0,0,0,0,0,0,0
0,0,0,0,0,4,0,0,0,0,0,0,0,3,0,0,115,0,3,0,0,0,0,0,0,4,0,0,0,0,0,0,0
0,0,0,0,0,4,0,0,0,22,0,0,22,3,0,0,0,0,22,0,0,22,0,0,0,4,0,0,0,0,0,0,0
0,0,0,0,0,4,0,0,0,0,0,0,0,0,0,0,0,0,3,0,0,0,0,0,0,4,0,0,0,0,0,0,0
0,0,0,0,0,4,0,0,0,0,0,0,0,0,0,0,0,0,3,0,0,0,0,0,0,4,0,0,0,0,0,0,0
0,0,0,0,0,0,4,117,0,0,0,0,0,0,0,0,0,110,3,0,0,0,0,0,4,0,0,0,0,0,0,0,0
0,0,0,0,0,0,0,4,0,0,0,0,0,0,0,0,0,0,3,0,0,0,0,4,0,0,0,0,0,0,0,0,0
0,0,0,0,0,0,0,4,0,0,0,0,0,0,0,0,0,0,3,0,0,0,0,4,0,0,0,0,0,0,0,0,0
0,0,0,0,0,0,0,4,3,22,3,3,22,0,0,0,0,0,22,0,3,22,0,4,0,0,0,0,0,0,0,0,0
0,0,0,0,0,0,0,4,115,0,0,0,156,22,0,0,0,22,156,0,155,0,110,4,0,0,0,0,0,0,0,0,0
0,0,0,0,0,0,0,4,0,0,0,0,156,0,194,0,190,0,156,0,0,0,0,4,0,0,0,0,0,0,0,0,0
0,0,0,0,0,0,4,0,0,0,0,110,156,0,0,0,0,0,156,0,0,0,0,0,4,0,0,0,0,0,0,0,0
0,0,0,0,0,4,117,0,0,68,0,0,156,0,0,0,0,0,156,0,0,0,0,0,110,4,0,0,0,0,0,0,0
0,0,0,0,0,4,0,0,0,22,0,0,4,4,4,192,4,4,4,0,0,22,0,0,0,4,0,0,0,0,0,0,0
0,0,0,0,0,4,0,0,0,0,0,110,4,196,195,193,191,189,4,0,0,0,0,0,0,4,0,0,0,0,0,0,0
0,0,0,0,0,4,0,0,0,0,0,0,4,4,4,192,4,4,4,0,0,0,0,0,0,4,0,0,0,0,0,0,0
0,0,0,0,0,0,4,0,137,0,137,4,0,0,115,0,115,0,0,4,137,0,0,137,4,0,0,0,0,0,0,0,0
0,0,0,0,0,0,0,4,4,4,4,0,0,0,0,0,0,0,0,0,4,4,4,4,0,0,0,0,0,0,0,0,0
0,0,0,0,0,0,0,0,0,0,0,0,0,0,0,0,0,0,0,0,0,0,0,0,0,0,0,0,0,0,0,0,0
0,0,0,0,0,0,0,0,0,0,0,0,0,0,0,0,0,0,0,0,0,0,0,0,0,0,0,0,0,0,0,0,0
0,0,0,0,0,0,0,0,0,0,0,0,0,0,0,0,0,0,0,0,0,0,0,0,0,0,0,0,0,0,0,0,0
0,0,0,0,0,0,0,0,0,0,0,0,0,0,0,0,0,0,0,0,0,0,0,0,0,0,0,0,0,0,0,0,0
0,0,0,0,0,0,0,0,0,0,0,0,0,0,0,0,0,0,0,0,0,0,0,0,0,0,0,0,0,0,0,0,0
0,0,0,0,0,0,0,0,0,0,0,0,0,0,0,0,0,0,0,0,0,0,0,0,0,0,0,0,0,0,0,0,0
0,0,0,0,0,0,0,0,0,0,0,0,0,0,0,0,0,0,0,0,0,0,0,0,0,0,0,0,0,0,0,0,0
:endlayer
layer: 12
0,0,0,0,0,0,0,0,0,0,0,0,0,0,0,0,0,0,0,0,0,0,0,0,0,0,0,0,0,0,0,0,0
0,0,0,0,0,0,0,0,0,0,0,0,0,0,0,0,0,0,0,0,0,0,0,0,0,0,0,0,0,0,0,0,0
0,0,0,0,0,0,0,0,0,0,0,0,0,0,0,0,0,0,0,0,0,0,0,0,0,0,0,0,0,0,0,0,0
0,0,0,0,0,0,0,0,0,0,0,0,0,0,0,0,0,0,0,0,0,0,0,0,0,0,0,0,0,0,0,0,0
0,0,0,0,0,0,0,0,0,0,0,0,0,0,0,0,0,0,0,0,0,0,0,0,0,0,0,0,0,0,0,0,0
0,0,0,0,0,0,0,0,0,0,0,0,0,0,0,0,0,0,0,0,0,0,0,0,0,0,0,0,0,0,0,0,0
0,0,0,0,0,0,0,0,0,0,0,0,0,0,0,0,0,0,0,0,0,0,0,0,0,0,0,0,0,0,0,0,0
0,0,0,0,0,0,0,188,139,188,139,188,0,0,0,0,0,0,0,188,139,188,139,188,0,0,0,0,0,0,0,0,0
0,0,0,0,0,0,202,198,198,198,198,198,188,0,0,0,0,0,188,198,198,198,198,198,197,0,0,0,0,0,0,0,0
0,0,0,0,0,0,139,198,198,198,198,198,198,188,139,188,139,188,198,198,198,198,198,198,139,0,0,0,0,0,0,0,0
0,0,0,0,0,0,202,4,4,4,4,4,198,198,198,198,198,198,198,4,4,4,4,4,197,0,0,0,0,0,0,0,0
0,0,0,0,0,0,4,115,182,168,0,115,4,198,198,198,198,198,4,0,0,168,0,0,4,0,0,0,0,0,0,0,0
0,0,0,0,0,4,0,0,0,168,0,0,168,4,4,4,4,4,3,0,0,168,0,0,0,4,0,0,0,0,0,0,0
0,0,0,0,0,4,0,0,0,168,0,0,168,3,0,0,0,0,3,0,0,168,0,0,0,4,0,0,0,0,0,0,0
0,0,0,0,0,4,157,157,157,22,157,157,157,157,157,157,157,157,157,157,157,22,157,157,157,4,0,0,0,0,0,0,0
0,0,0,0,0,4,0,0,0,168,0,0,168,0,0,0,0,0,168,0,0,168,0,0,0,4,0,0,0,0,0,0,0
0,0,0,0,0,4,0,0,0,168,0,0,168,0,0,0,0,0,168,0,0,168,0,0,0,4,0,0,0,0,0,0,0
0,0,0,0,0,0,4,0,0,168,0,0,168,0,0,0,0,0,168,0,0,168,0,0,4,0,0,0,0,0,0,0,0
0,0,0,0,0,0,0,4,0,168,0,0,168,0,0,0,0,0,168,0,0,168,0,4,0,0,0,0,0,0,0,0,0
0,0,0,0,0,0,0,4,0,168,0,0,168,0,0,0,0,0,168,0,0,168,0,4,0,0,0,0,0,0,0,0,0
0,0,0,0,0,0,0,4,157,168,157,157,168,0,0,0,0,0,168,0,155,168,157,4,0,0,0,0,0,0,0,0,0
0,0,0,0,0,0,0,4,0,168,0,0,168,22,0,0,0,22,168,0,0,168,0,4,0,0,0,0,0,0,0,0,0
0,0,0,0,0,0,0,4,0,168,0,0,168,201,0,0,0,199,168,0,0,168,0,4,0,0,0,0,0,0,0,0,0
0,0,0,0,0,0,4,0,0,168,0,0,168,201,0,0,0,199,168,0,0,168,0,0,4,0,0,0,0,0,0,0,0
0,0,0,0,0,4,0,0,0,168,0,0,168,201,200,200,200,199,168,0,0,168,0,0,0,4,0,0,0,0,0,0,0
0,0,0,0,0,4,157,157,157,168,157,157,157,157,157,157,157,157,157,157,157,168,157,157,157,4,0,0,0,0,0,0,0
0,0,0,0,0,4,0,0,0,168,0,0,4,4,4,4,4,4,4,0,0,168,0,0,0,4,0,0,0,0,0,0,0
0,0,0,0,0,4,0,0,0,168,0,0,4,4,4,4,4,4,4,0,0,168,0,0,0,4,0,0,0,0,0,0,0
0,0,0,0,0,0,4,0,0,168,0,4,0,0,0,0,0,0,0,4,0,168,0,0,4,0,0,0,0,0,0,0,0
0,0,0,0,0,0,0,4,4,4,4,0,0,0,0,0,0,0,0,0,4,4,4,4,0,0,0,0,0,0,0,0,0
0,0,0,0,0,0,0,0,0,0,0,0,0,0,0,0,0,0,0,0,0,0,0,0,0,0,0,0,0,0,0,0,0
0,0,0,0,0,0,0,0,0,0,0,0,0,0,0,0,0,0,0,0,0,0,0,0,0,0,0,0,0,0,0,0,0
0,0,0,0,0,0,0,0,0,0,0,0,0,0,0,0,0,0,0,0,0,0,0,0,0,0,0,0,0,0,0,0,0
0,0,0,0,0,0,0,0,0,0,0,0,0,0,0,0,0,0,0,0,0,0,0,0,0,0,0,0,0,0,0,0,0
0,0,0,0,0,0,0,0,0,0,0,0,0,0,0,0,0,0,0,0,0,0,0,0,0,0,0,0,0,0,0,0,0
0,0,0,0,0,0,0,0,0,0,0,0,0,0,0,0,0,0,0,0,0,0,0,0,0,0,0,0,0,0,0,0,0
0,0,0,0,0,0,0,0,0,0,0,0,0,0,0,0,0,0,0,0,0,0,0,0,0,0,0,0,0,0,0,0,0
:endlayer
layer: 13
0,0,0,0,0,0,0,0,0,0,0,0,0,0,0,0,0,0,0,0,0,0,0,0,0,0,0,0,0,0,0,0,0
0,0,0,0,0,0,0,0,0,0,0,0,0,0,0,0,0,0,0,0,0,0,0,0,0,0,0,0,0,0,0,0,0
0,0,0,0,0,0,0,0,0,0,0,0,0,0,0,0,0,0,0,0,0,0,0,0,0,0,0,0,0,0,0,0,0
0,0,0,0,0,0,0,0,0,0,0,0,0,0,0,0,0,0,0,0,0,0,0,0,0,0,0,0,0,0,0,0,0
0,0,0,0,0,0,0,0,0,0,0,0,0,0,0,0,0,0,0,0,0,0,0,0,0,0,0,0,0,0,0,0,0
0,0,0,0,0,0,0,0,0,0,0,0,0,0,0,0,0,0,0,0,0,0,0,0,0,0,0,0,0,0,0,0,0
0,0,0,0,0,0,0,137,0,0,0,137,0,0,0,0,0,0,0,137,0,0,0,137,0,0,0,0,0,0,0,0,0
0,0,0,0,0,0,0,3,58,3,209,3,0,0,0,0,0,0,0,3,207,3,58,3,0,0,0,0,0,0,0,0,0
0,0,0,0,0,0,3,0,210,0,0,0,3,0,0,0,0,0,3,0,0,0,0,0,3,0,0,0,0,0,0,0,0
0,0,0,0,0,0,58,0,0,0,0,0,0,3,58,3,58,3,0,0,0,206,0,0,58,0,0,0,0,0,0,0,0
0,0,0,0,0,0,3,4,45,45,45,4,0,0,0,0,0,0,0,4,45,45,45,4,3,0,0,0,0,0,0,0,0
0,0,0,0,0,0,4,3,3,3,3,3,4,0,0,0,0,0,4,3,3,3,3,3,4,0,0,0,0,0,0,0,0
0,0,0,0,0,138,3,3,3,3,3,3,3,4,34,34,34,4,3,3,3,3,3,3,3,203,0,0,0,0,0,0,0
0,0,0,0,0,204,3,3,3,3,3,3,3,3,3,3,3,3,3,3,3,3,3,3,3,204,0,0,0,0,0,0,0
0,0,0,0,0,138,3,3,3,22,3,3,3,3,3,3,3,3,3,3,3,22,3,3,3,203,0,0,0,0,0,0,0
0,0,0,0,0,204,3,3,3,3,3,3,3,3,3,3,3,3,3,3,3,3,3,3,3,204,0,0,0,0,0,0,0
0,0,0,0,0,138,3,3,3,3,3,3,3,3,3,3,3,3,3,3,3,3,3,3,3,203,0,0,0,0,0,0,0
0,0,0,0,0,0,138,3,3,3,3,3,3,3,3,3,3,3,3,3,3,3,3,3,203,0,0,0,0,0,0,0,0
0,0,0,0,0,0,0,138,3,3,3,3,3,3,3,3,3,3,3,3,3,3,3,203,0,0,0,0,0,0,0,0,0
0,0,0,0,0,0,0,204,3,3,3,3,3,3,3,3,3,3,3,3,155,3,3,204,0,0,0,0,0,0,0,0,0
0,0,0,0,0,0,0,138,3,3,3,3,3,3,3,3,3,3,3,3,0,3,3,203,0,0,0,0,0,0,0,0,0
0,0,0,0,0,0,0,204,3,3,3,3,3,3,3,3,3,3,3,3,0,3,3,204,0,0,0,0,0,0,0,0,0
0,0,0,0,0,0,0,138,3,3,3,3,3,3,3,3,3,3,3,3,0,3,3,203,0,0,0,0,0,0,0,0,0
0,0,0,0,0,0,138,3,3,3,3,3,3,3,3,3,3,3,3,3,208,3,3,3,203,0,0,0,0,0,0,0,0
0,0,0,0,0,138,3,3,3,3,3,3,3,3,3,3,3,3,3,3,3,3,3,3,3,203,0,0,0,0,0,0,0
0,0,0,0,0,204,3,3,3,3,3,3,3,3,3,3,3,3,3,3,3,3,3,3,3,204,0,0,0,0,0,0,0
0,0,0,0,0,204,3,3,3,3,3,3,3,3,3,3,3,3,3,3,3,3,3,3,3,204,0,0,0,0,0,0,0
0,0,0,0,0,138,3,3,3,3,3,3,205,204,205,204,205,204,205,3,3,3,3,3,3,203,0,0,0,0,0,0,0
0,0,0,0,0,0,138,3,3,3,3,203,0,0,0,0,0,0,0,205,3,3,3,3,203,0,0,0,0,0,0,0,0
0,0,0,0,0,0,0,205,204,204,205,0,0,0,0,0,0,0,0,0,205,204,204,205,0,0,0,0,0,0,0,0,0
0,0,0,0,0,0,0,0,0,0,0,0,0,0,0,0,0,0,0,0,0,0,0,0,0,0,0,0,0,0,0,0,0
0,0,0,0,0,0,0,0,0,0,0,0,0,0,0,0,0,0,0,0,0,0,0,0,0,0,0,0,0,0,0,0,0
0,0,0,0,0,0,0,0,0,0,0,0,0,0,0,0,0,0,0,0,0,0,0,0,0,0,0,0,0,0,0,0,0
0,0,0,0,0,0,0,0,0,0,0,0,0,0,0,0,0,0,0,0,0,0,0,0,0,0,0,0,0,0,0,0,0
0,0,0,0,0,0,0,0,0,0,0,0,0,0,0,0,0,0,0,0,0,0,0,0,0,0,0,0,0,0,0,0,0
0,0,0,0,0,0,0,0,0,0,0,0,0,0,0,0,0,0,0,0,0,0,0,0,0,0,0,0,0,0,0,0,0
0,0,0,0,0,0,0,0,0,0,0,0,0,0,0,0,0,0,0,0,0,0,0,0,0,0,0,0,0,0,0,0,0
:endlayer
layer: 14
0,0,0,0,0,0,0,0,0,0,0,0,0,0,0,0,0,0,0,0,0,0,0,0,0,0,0,0,0,0,0,0,0
0,0,0,0,0,0,0,0,0,0,0,0,0,0,0,0,0,0,0,0,0,0,0,0,0,0,0,0,0,0,0,0,0
0,0,0,0,0,0,0,0,0,0,0,0,0,0,0,0,0,0,0,0,0,0,0,0,0,0,0,0,0,0,0,0,0
0,0,0,0,0,0,0,0,0,0,0,0,0,0,0,0,0,0,0,0,0,0,0,0,0,0,0,0,0,0,0,0,0
0,0,0,0,0,0,0,0,0,0,0,0,0,0,0,0,0,0,0,0,0,0,0,0,0,0,0,0,0,0,0,0,0
0,0,0,0,0,0,0,0,0,0,0,0,0,0,0,0,0,0,0,0,0,0,0,0,0,0,0,0,0,0,0,0,0
0,0,0,0,0,0,0,0,0,0,0,0,0,0,0,0,0,0,0,0,0,0,0,0,0,0,0,0,0,0,0,0,0
0,0,0,0,0,0,0,58,0,58,0,58,0,0,0,0,0,0,0,58,0,58,0,58,0,0,0,0,0,0,0,0,0
0,0,0,0,0,0,58,0,0,0,0,0,58,0,0,0,0,0,58,0,0,0,0,0,58,0,0,0,0,0,0,0,0
0,0,0,0,0,0,0,0,0,0,0,0,0,58,0,58,0,58,0,0,0,0,0,0,0,0,0,0,0,0,0,0,0
0,0,0,0,0,0,58,4,0,0,0,4,0,0,0,0,0,0,0,4,0,0,0,4,58,0,0,0,0,0,0,0,0
0,0,0,0,0,0,4,3,3,3,3,3,4,0,0,0,0,0,4,3,3,3,3,3,4,0,0,0,0,0,0,0,0
0,0,0,0,0,0,3,229,226,0,225,222,3,4,0,0,0,4,3,0,0,0,0,0,3,0,0,0,0,0,0,0,0
0,0,0,0,0,0,3,0,0,0,0,223,222,3,3,219,3,3,0,0,0,0,211,0,3,0,0,0,0,0,0,0,0
0,0,0,0,0,0,3,229,226,22,0,0,223,4,0,0,0,4,0,0,0,22,0,0,3,0,0,0,0,0,0,0,0
0,0,0,0,0,0,3,0,227,0,0,0,0,221,0,0,0,0,0,0,0,0,0,0,3,0,0,0,0,0,0,0,0
0,0,0,0,0,0,3,229,226,0,0,0,0,4,0,0,0,4,0,0,0,0,0,0,3,0,0,0,0,0,0,0,0
0,0,0,0,0,0,0,3,0,0,0,0,4,0,0,0,0,22,4,0,0,0,0,3,0,0,0,0,0,0,0,0,0
0,0,0,0,0,0,0,0,3,0,0,4,0,0,0,0,216,213,213,4,0,0,3,0,0,0,0,0,0,0,0,0,0
0,0,0,0,0,0,0,0,3,0,0,4,0,0,0,0,0,22,213,4,0,3,3,0,0,0,0,0,0,0,0,0,0
0,0,0,0,0,0,0,0,3,0,0,4,224,0,0,0,0,0,156,4,0,3,3,0,0,0,0,0,0,0,0,0,0
0,0,0,0,0,0,0,0,3,0,0,0,4,0,0,0,0,214,4,60,0,3,3,0,0,0,0,0,0,0,0,0,0
0,0,0,0,0,0,0,0,3,0,0,0,0,4,0,0,0,4,0,60,0,3,3,0,0,0,0,0,0,0,0,0,0
0,0,0,0,0,0,0,3,228,0,0,0,0,215,0,0,0,215,0,60,212,60,0,3,0,0,0,0,0,0,0,0,0
0,0,0,0,0,0,3,79,76,0,0,0,0,4,0,0,0,4,0,0,0,0,0,0,3,0,0,0,0,0,0,0,0
0,0,0,0,0,0,3,79,76,0,0,0,0,22,220,0,217,22,0,0,0,0,0,0,3,0,0,0,0,0,0,0,0
0,0,0,0,0,0,3,0,0,0,0,0,3,3,218,218,218,3,3,0,0,0,0,0,3,0,0,0,0,0,0,0,0
0,0,0,0,0,0,3,0,0,0,0,3,0,0,0,0,0,0,0,3,0,0,0,0,3,0,0,0,0,0,0,0,0
0,0,0,0,0,0,0,3,3,3,3,0,0,0,0,0,0,0,0,0,3,3,3,3,0,0,0,0,0,0,0,0,0
0,0,0,0,0,0,0,0,0,0,0,0,0,0,0,0,0,0,0,0,0,0,0,0,0,0,0,0,0,0,0,0,0
0,0,0,0,0,0,0,0,0,0,0,0,0,0,0,0,0,0,0,0,0,0,0,0,0,0,0,0,0,0,0,0,0
0,0,0,0,0,0,0,0,0,0,0,0,0,0,0,0,0,0,0,0,0,0,0,0,0,0,0,0,0,0,0,0,0
0,0,0,0,0,0,0,0,0,0,0,0,0,0,0,0,0,0,0,0,0,0,0,0,0,0,0,0,0,0,0,0,0
0,0,0,0,0,0,0,0,0,0,0,0,0,0,0,0,0,0,0,0,0,0,0,0,0,0,0,0,0,0,0,0,0
0,0,0,0,0,0,0,0,0,0,0,0,0,0,0,0,0,0,0,0,0,0,0,0,0,0,0,0,0,0,0,0,0
0,0,0,0,0,0,0,0,0,0,0,0,0,0,0,0,0,0,0,0,0,0,0,0,0,0,0,0,0,0,0,0,0
0,0,0,0,0,0,0,0,0,0,0,0,0,0,0,0,0,0,0,0,0,0,0,0,0,0,0,0,0,0,0,0,0
:endlayer
layer: 15
0,0,0,0,0,0,0,0,0,0,0,0,0,0,0,0,0,0,0,0,0,0,0,0,0,0,0,0,0,0,0,0,0
0,0,0,0,0,0,0,0,0,0,0,0,0,0,0,0,0,0,0,0,0,0,0,0,0,0,0,0,0,0,0,0,0
0,0,0,0,0,0,0,0,0,0,0,0,0,0,0,0,0,0,0,0,0,0,0,0,0,0,0,0,0,0,0,0,0
0,0,0,0,0,0,0,0,0,0,0,0,0,0,0,0,0,0,0,0,0,0,0,0,0,0,0,0,0,0,0,0,0
0,0,0,0,0,0,0,0,0,0,0,0,0,0,0,0,0,0,0,0,0,0,0,0,0,0,0,0,0,0,0,0,0
0,0,0,0,0,0,0,0,0,0,0,0,0,0,0,0,0,0,0,0,0,0,0,0,0,0,0,0,0,0,0,0,0
0,0,0,0,0,0,0,0,0,0,0,0,0,0,0,0,0,0,0,0,0,0,0,0,0,0,0,0,0,0,0,0,0
0,0,0,0,0,0,0,60,0,60,0,60,0,0,0,0,0,0,0,60,0,60,0,60,0,0,0,0,0,0,0,0,0
0,0,0,0,0,0,60,0,0,0,0,0,60,0,0,0,0,0,60,0,0,0,0,0,60,0,0,0,0,0,0,0,0
0,0,0,0,0,0,0,137,0,0,0,0,0,60,0,60,0,60,0,0,0,0,0,137,0,0,0,0,0,0,0,0,0
0,0,0,0,0,0,60,4,0,137,0,4,0,0,0,0,0,0,0,4,0,137,0,4,60,0,0,0,0,0,0,0,0
0,0,0,0,0,0,4,3,3,3,3,3,4,0,0,0,0,0,4,3,3,3,3,3,4,0,0,0,0,0,0,0,0
0,0,0,0,0,0,3,0,115,0,0,0,3,4,0,0,0,4,3,0,0,115,0,0,3,0,0,0,0,0,0,0,0
0,0,0,0,0,0,3,0,0,0,0,0,0,3,3,230,3,3,115,0,0,0,0,0,3,0,0,0,0,0,0,0,0
0,0,0,0,0,0,3,0,0,22,0,0,110,4,117,0,0,4,0,0,0,22,0,0,3,0,0,0,0,0,0,0,0
0,0,0,0,0,0,3,117,0,0,0,0,0,230,0,0,0,0,0,0,0,0,0,110,3,0,0,0,0,0,0,0,0
0,0,0,0,0,0,3,0,0,0,0,0,0,4,0,0,0,4,0,0,0,0,0,0,3,0,0,0,0,0,0,0,0
0,0,0,0,0,0,0,3,0,0,0,0,4,0,0,0,0,22,4,0,0,0,0,3,0,0,0,0,0,0,0,0,0
0,0,0,0,0,0,0,0,3,0,0,4,0,0,0,0,0,216,213,4,0,0,3,0,0,0,0,0,0,0,0,0,0
0,0,0,0,0,0,0,0,3,0,0,4,117,0,0,0,0,22,213,4,117,3,3,0,0,0,0,0,0,0,0,0,0
0,0,0,0,0,0,0,0,3,117,0,4,0,0,0,0,0,0,156,4,0,3,3,0,0,0,0,0,0,0,0,0,0
0,0,0,0,0,0,0,0,3,0,0,0,4,0,0,0,0,0,4,0,0,3,3,0,0,0,0,0,0,0,0,0,0
0,0,0,0,0,0,0,0,3,0,0,0,0,4,0,0,0,4,0,0,0,3,3,0,0,0,0,0,0,0,0,0,0
0,0,0,0,0,0,0,3,0,0,0,0,0,230,0,0,0,230,0,0,0,0,0,3,0,0,0,0,0,0,0,0,0
0,0,0,0,0,0,3,0,0,0,0,0,0,4,117,0,110,4,117,0,0,0,0,0,3,0,0,0,0,0,0,0,0
0,0,0,0,0,0,3,0,0,0,0,0,0,22,0,0,0,22,0,0,0,0,0,110,3,0,0,0,0,0,0,0,0
0,0,0,0,0,0,3,117,0,0,0,0,3,3,0,0,0,3,3,0,0,0,0,0,3,0,0,0,0,0,0,0,0
0,0,0,0,0,0,3,0,0,0,0,3,0,0,0,0,0,0,0,3,0,137,0,0,3,0,0,0,0,0,0,0,0
0,0,0,0,0,0,0,3,129,3,3,0,0,0,0,0,0,0,0,0,3,3,3,3,0,0,0,0,0,0,0,0,0
0,0,0,0,0,0,0,0,0,0,0,0,0,0,0,0,0,0,0,0,0,0,0,0,0,0,0,0,0,0,0,0,0
0,0,0,0,0,0,0,0,0,0,0,0,0,0,0,0,0,0,0,0,0,0,0,0,0,0,0,0,0,0,0,0,0
0,0,0,0,0,0,0,0,0,0,0,0,0,0,0,0,0,0,0,0,0,0,0,0,0,0,0,0,0,0,0,0,0
0,0,0,0,0,0,0,0,0,0,0,0,0,0,0,0,0,0,0,0,0,0,0,0,0,0,0,0,0,0,0,0,0
0,0,0,0,0,0,0,0,0,0,0,0,0,0,0,0,0,0,0,0,0,0,0,0,0,0,0,0,0,0,0,0,0
0,0,0,0,0,0,0,0,0,0,0,0,0,0,0,0,0,0,0,0,0,0,0,0,0,0,0,0,0,0,0,0,0
0,0,0,0,0,0,0,0,0,0,0,0,0,0,0,0,0,0,0,0,0,0,0,0,0,0,0,0,0,0,0,0,0
0,0,0,0,0,0,0,0,0,0,0,0,0,0,0,0,0,0,0,0,0,0,0,0,0,0,0,0,0,0,0,0,0
:endlayer
layer: 16
0,0,0,0,0,0,0,0,0,0,0,0,0,0,0,0,0,0,0,0,0,0,0,0,0,0,0,0,0,0,0,0,0
0,0,0,0,0,0,0,0,0,0,0,0,0,0,0,0,0,0,0,0,0,0,0,0,0,0,0,0,0,0,0,0,0
0,0,0,0,0,0,0,0,0,0,0,0,0,0,0,0,0,0,0,0,0,0,0,0,0,0,0,0,0,0,0,0,0
0,0,0,0,0,0,0,0,0,0,0,0,0,0,0,0,0,0,0,0,0,0,0,0,0,0,0,0,0,0,0,0,0
0,0,0,0,0,0,0,0,0,0,0,0,0,0,0,0,0,0,0,0,0,0,0,0,0,0,0,0,0,0,0,0,0
0,0,0,0,0,0,0,0,0,0,0,0,0,0,0,0,0,0,0,0,0,0,0,0,0,0,0,0,0,0,0,0,0
0,0,0,0,0,0,0,0,0,0,0,0,0,0,0,0,0,0,0,0,0,0,0,0,0,0,0,0,0,0,0,0,0
0,0,0,0,0,0,0,60,0,60,0,60,0,0,0,0,0,0,0,60,0,60,0,60,0,0,0,0,0,0,0,0,0
0,0,0,0,0,0,60,0,0,0,0,0,60,0,0,0,0,0,60,0,0,0,0,0,60,0,0,0,0,0,0,0,0
0,0,0,0,0,0,0,0,0,0,0,0,0,60,0,60,0,60,0,0,0,0,0,0,0,0,0,0,0,0,0,0,0
0,0,0,0,0,0,60,4,0,0,0,4,0,0,0,0,0,0,0,4,0,0,0,4,60,0,0,0,0,0,0,0,0
0,0,0,0,0,0,4,3,3,3,3,3,4,0,0,0,0,0,4,3,3,3,3,3,4,0,0,0,0,0,0,0,0
0,0,0,0,0,0,3,0,0,0,0,0,3,4,122,137,232,4,3,0,0,0,0,0,3,0,0,0,0,0,0,0,0
0,0,0,0,0,0,3,0,0,0,0,0,0,3,3,3,3,3,0,0,0,0,0,0,3,0,0,0,0,0,0,0,0
0,0,0,0,0,0,3,0,0,22,0,0,0,4,0,0,0,4,0,0,0,22,0,0,3,0,0,0,0,0,0,0,0
0,0,0,0,0,0,3,0,0,0,0,0,0,4,0,0,0,4,0,0,0,0,0,0,3,0,0,0,0,0,0,0,0
0,0,0,0,0,0,3,0,0,0,0,0,0,4,0,0,0,4,0,0,0,0,0,0,3,0,0,0,0,0,0,0,0
0,0,0,0,0,0,0,3,0,0,0,0,4,0,0,0,0,22,4,0,0,0,0,3,0,0,0,0,0,0,0,0,0
0,0,0,0,0,0,0,0,3,0,0,4,0,0,0,0,0,0,0,4,0,0,3,0,0,0,0,0,0,0,0,0,0
0,0,0,0,0,0,0,0,3,0,0,4,0,0,0,0,0,22,231,4,0,3,3,0,0,0,0,0,0,0,0,0,0
0,0,0,0,0,0,0,0,3,0,0,4,0,0,0,0,0,0,156,4,0,3,3,0,0,0,0,0,0,0,0,0,0
0,0,0,0,0,0,0,0,3,0,0,0,4,0,0,0,0,0,4,0,0,3,3,0,0,0,0,0,0,0,0,0,0
0,0,0,0,0,0,0,0,3,0,0,0,0,4,0,0,0,4,0,0,110,3,3,0,0,0,0,0,0,0,0,0,0
0,0,0,0,0,0,0,3,0,0,0,0,0,4,0,0,0,4,0,0,0,115,0,3,0,0,0,0,0,0,0,0,0
0,0,0,0,0,0,3,0,0,0,0,0,0,4,0,0,0,4,0,0,0,0,0,0,3,0,0,0,0,0,0,0,0
0,0,0,0,0,0,3,0,0,0,0,0,0,22,0,0,0,22,0,0,0,0,0,0,3,0,0,0,0,0,0,0,0
0,0,0,0,0,0,3,0,0,0,0,0,3,3,3,3,3,3,3,0,0,0,0,0,3,0,0,0,0,0,0,0,0
0,0,0,0,0,0,3,0,0,0,0,3,0,0,0,0,0,0,0,3,0,0,0,0,3,0,0,0,0,0,0,0,0
0,0,0,0,0,0,0,3,3,3,3,0,0,0,0,0,0,0,0,0,3,3,3,3,0,0,0,0,0,0,0,0,0
0,0,0,0,0,0,0,0,0,0,0,0,0,0,0,0,0,0,0,0,0,0,0,0,0,0,0,0,0,0,0,0,0
0,0,0,0,0,0,0,0,0,0,0,0,0,0,0,0,0,0,0,0,0,0,0,0,0,0,0,0,0,0,0,0,0
0,0,0,0,0,0,0,0,0,0,0,0,0,0,0,0,0,0,0,0,0,0,0,0,0,0,0,0,0,0,0,0,0
0,0,0,0,0,0,0,0,0,0,0,0,0,0,0,0,0,0,0,0,0,0,0,0,0,0,0,0,0,0,0,0,0
0,0,0,0,0,0,0,0,0,0,0,0,0,0,0,0,0,0,0,0,0,0,0,0,0,0,0,0,0,0,0,0,0
0,0,0,0,0,0,0,0,0,0,0,0,0,0,0,0,0,0,0,0,0,0,0,0,0,0,0,0,0,0,0,0,0
0,0,0,0,0,0,0,0,0,0,0,0,0,0,0,0,0,0,0,0,0,0,0,0,0,0,0,0,0,0,0,0,0
0,0,0,0,0,0,0,0,0,0,0,0,0,0,0,0,0,0,0,0,0,0,0,0,0,0,0,0,0,0,0,0,0
:endlayer
layer: 17
0,0,0,0,0,0,0,0,0,0,0,0,0,0,0,0,0,0,0,0,0,0,0,0,0,0,0,0,0,0,0,0,0
0,0,0,0,0,0,0,0,0,0,0,0,0,0,0,0,0,0,0,0,0,0,0,0,0,0,0,0,0,0,0,0,0
0,0,0,0,0,0,0,0,0,0,0,0,0,0,0,0,0,0,0,0,0,0,0,0,0,0,0,0,0,0,0,0,0
0,0,0,0,0,0,0,0,0,0,0,0,0,0,0,0,0,0,0,0,0,0,0,0,0,0,0,0,0,0,0,0,0
0,0,0,0,0,0,0,0,0,0,0,0,0,0,0,0,0,0,0,0,0,0,0,0,0,0,0,0,0,0,0,0,0
0,0,0,0,0,0,0,0,0,0,0,0,0,0,0,0,0,0,0,0,0,0,0,0,0,0,0,0,0,0,0,0,0
0,0,0,0,0,231,231,231,231,231,231,231,231,231,231,231,231,231,231,231,231,231,231,231,231,231,0,0,0,0,0,0,0
0,0,0,0,0,216,198,198,198,198,198,198,198,198,198,198,198,198,198,198,198,198,198,198,198,233,0,0,0,0,0,0,0
0,0,0,0,0,216,60,0,0,0,0,0,60,0,0,0,0,0,60,0,0,0,0,0,60,233,0,0,0,0,0,0,0
0,0,0,0,0,216,0,0,0,0,0,0,0,60,0,60,0,60,0,0,0,0,0,0,0,233,0,0,0,0,0,0,0
0,0,0,0,0,216,213,4,0,0,0,4,0,0,0,0,0,0,0,4,0,0,0,4,213,233,0,0,0,0,0,0,0
0,0,0,0,0,216,4,3,3,3,3,3,4,0,0,0,0,0,4,3,3,3,3,3,4,233,0,0,0,0,0,0,0
0,0,0,0,0,202,3,0,0,0,0,0,3,4,0,0,0,4,3,0,0,0,0,0,3,197,0,0,0,0,0,0,0
0,0,0,0,0,202,3,0,0,0,0,0,0,3,157,157,157,3,0,0,0,0,0,0,3,197,0,0,0,0,0,0,0
0,0,0,0,0,202,3,0,0,22,0,0,0,4,213,213,213,4,0,0,0,22,0,0,3,197,0,0,0,0,0,0,0
0,0,0,0,0,202,3,0,0,0,0,0,0,4,213,213,213,4,0,0,0,0,0,0,3,197,0,0,0,0,0,0,0
0,0,0,0,0,202,3,0,0,0,0,0,0,4,213,213,213,4,0,0,0,0,0,0,3,197,0,0,0,0,0,0,0
0,0,0,0,0,0,202,3,0,0,0,0,4,213,213,237,235,22,4,0,0,0,0,3,197,0,0,0,0,0,0,0,0
0,0,0,0,0,0,0,202,3,0,0,4,213,213,213,237,0,0,0,4,0,0,3,197,0,0,0,0,0,0,0,0,0
0,0,0,0,0,0,0,202,3,0,0,4,213,213,213,236,236,22,0,4,0,3,3,197,0,0,0,0,0,0,0,0,0
0,0,0,0,0,0,0,202,3,0,0,4,213,213,213,213,213,213,204,4,0,3,3,197,0,0,0,0,0,0,0,0,0
0,0,0,0,0,0,0,202,3,0,0,0,4,213,213,213,213,213,4,0,0,3,3,197,0,0,0,0,0,0,0,0,0
0,0,0,0,0,0,0,202,3,0,0,0,0,4,213,213,213,4,0,0,0,3,3,197,0,0,0,0,0,0,0,0,0
0,0,0,0,0,0,202,3,0,0,0,0,0,4,198,198,198,4,0,0,0,0,0,3,197,0,0,0,0,0,0,0,0
0,0,0,0,0,202,3,0,0,0,0,0,0,4,0,0,0,4,0,0,0,0,0,0,3,197,0,0,0,0,0,0,0
0,0,0,0,0,202,3,0,0,0,0,0,0,22,0,0,0,22,0,0,0,0,0,0,3,197,0,0,0,0,0,0,0
0,0,0,0,0,202,3,0,0,0,0,0,3,3,3,3,3,3,3,0,0,0,0,0,3,197,0,0,0,0,0,0,0
0,0,0,0,0,202,3,0,0,0,0,3,234,234,234,234,234,234,234,3,0,0,0,0,3,197,0,0,0,0,0,0,0
0,0,0,0,0,0,202,3,3,3,3,197,0,0,0,0,0,0,0,202,3,3,3,3,197,0,0,0,0,0,0,0,0
0,0,0,0,0,0,0,234,234,234,234,0,0,0,0,0,0,0,0,0,234,234,234,234,0,0,0,0,0,0,0,0,0
0,0,0,0,0,0,0,0,0,0,0,0,0,0,0,0,0,0,0,0,0,0,0,0,0,0,0,0,0,0,0,0,0
0,0,0,0,0,0,0,0,0,0,0,0,0,0,0,0,0,0,0,0,0,0,0,0,0,0,0,0,0,0,0,0,0
0,0,0,0,0,0,0,0,0,0,0,0,0,0,0,0,0,0,0,0,0,0,0,0,0,0,0,0,0,0,0,0,0
0,0,0,0,0,0,0,0,0,0,0,0,0,0,0,0,0,0,0,0,0,0,0,0,0,0,0,0,0,0,0,0,0
0,0,0,0,0,0,0,0,0,0,0,0,0,0,0,0,0,0,0,0,0,0,0,0,0,0,0,0,0,0,0,0,0
0,0,0,0,0,0,0,0,0,0,0,0,0,0,0,0,0,0,0,0,0,0,0,0,0,0,0,0,0,0,0,0,0
0,0,0,0,0,0,0,0,0,0,0,0,0,0,0,0,0,0,0,0,0,0,0,0,0,0,0,0,0,0,0,0,0
:endlayer
layer: 18
0,0,0,0,0,0,0,0,0,0,0,0,0,0,0,0,0,0,0,0,0,0,0,0,0,0,0,0,0,0,0,0,0
0,0,0,0,0,0,0,0,0,0,0,0,0,0,0,0,0,0,0,0,0,0,0,0,0,0,0,0,0,0,0,0,0
0,0,0,0,0,0,0,0,0,0,0,0,0,0,0,0,0,0,0,0,0,0,0,0,0,0,0,0,0,0,0,0,0
0,0,0,0,0,0,0,0,0,0,0,0,0,0,0,0,0,0,0,0,0,0,0,0,0,0,0,0,0,0,0,0,0
0,0,0,0,0,0,0,0,0,0,0,0,0,0,0,0,0,0,0,0,0,0,0,0,0,0,0,0,0,0,0,0,0
0,0,0,0,0,0,0,0,0,0,0,0,0,0,0,0,0,0,0,0,0,0,0,0,0,0,0,0,0,0,0,0,0
0,0,0,0,0,0,0,0,0,0,0,0,0,0,0,0,0,0,0,0,0,0,0,0,0,0,0,0,0,0,0,0,0
0,0,0,0,0,0,216,231,231,231,231,231,231,231,231,231,231,231,231,231,231,231,231,231,231,0,0,0,0,0,0,0,0
0,0,0,0,0,0,216,198,198,198,198,198,198,198,198,198,198,198,198,198,198,198,198,198,233,0,0,0,0,0,0,0,0
0,0,0,0,0,0,216,198,198,198,198,198,198,198,198,198,198,198,198,198,198,198,198,198,233,0,0,0,0,0,0,0,0
0,0,0,0,0,0,216,4,4,4,4,4,198,198,198,198,198,198,198,4,4,4,4,4,233,0,0,0,0,0,0,0,0
0,0,0,0,0,0,4,198,198,198,198,198,4,198,198,198,198,198,4,198,198,198,198,198,4,0,0,0,0,0,0,0,0
0,0,0,0,0,4,198,198,198,198,198,198,198,4,4,155,4,4,198,198,198,198,198,198,198,4,0,0,0,0,0,0,0
0,0,0,0,0,4,198,198,198,198,198,198,198,4,0,0,0,4,198,198,198,198,198,198,198,4,0,0,0,0,0,0,0
0,0,0,0,0,4,198,198,198,22,198,198,198,233,0,0,0,216,238,198,198,22,198,198,198,4,0,0,0,0,0,0,0
0,0,0,0,0,4,198,198,198,198,198,198,198,4,0,0,0,4,198,198,198,198,198,198,198,4,0,0,0,0,0,0,0
0,0,0,0,0,4,198,198,198,198,198,198,198,4,0,0,0,4,198,198,198,198,198,198,198,4,0,0,0,0,0,0,0
0,0,0,0,0,0,4,198,198,198,198,198,4,0,0,60,60,22,4,198,198,198,198,198,4,0,0,0,0,0,0,0,0
0,0,0,0,0,0,0,4,198,198,198,4,239,0,0,60,0,0,0,4,198,198,4,4,0,0,0,0,0,0,0,0,0
0,0,0,0,0,0,0,4,198,198,198,4,0,0,0,60,60,22,0,4,198,198,198,4,0,0,0,0,0,0,0,0,0
0,0,0,0,0,0,0,4,198,198,198,4,240,0,0,0,0,0,0,4,198,198,198,4,0,0,0,0,0,0,0,0,0
0,0,0,0,0,0,0,4,198,198,198,198,4,0,0,0,0,0,4,198,198,198,198,4,0,0,0,0,0,0,0,0,0
0,0,0,0,0,0,0,4,198,198,198,198,198,4,0,0,0,4,198,198,198,198,198,4,0,0,0,0,0,0,0,0,0
0,0,0,0,0,0,4,198,198,198,198,198,198,4,231,231,231,4,198,198,198,198,198,198,4,0,0,0,0,0,0,0,0
0,0,0,0,0,4,198,198,198,198,198,198,198,4,198,198,198,4,198,198,198,198,198,198,198,4,0,0,0,0,0,0,0
0,0,0,0,0,4,198,198,198,198,198,198,198,22,198,198,198,22,198,198,198,198,198,198,198,4,0,0,0,0,0,0,0
0,0,0,0,0,4,198,198,198,198,198,198,198,198,198,198,198,198,198,198,198,198,198,198,198,4,0,0,0,0,0,0,0
0,0,0,0,0,4,198,198,198,198,198,198,4,4,4,4,4,4,4,198,198,198,198,198,198,4,0,0,0,0,0,0,0
0,0,0,0,0,0,4,198,198,198,198,4,0,0,0,0,0,0,0,4,198,198,198,198,4,0,0,0,0,0,0,0,0
0,0,0,0,0,0,0,4,4,4,4,0,0,0,0,0,0,0,0,0,4,4,4,4,0,0,0,0,0,0,0,0,0
0,0,0,0,0,0,0,0,0,0,0,0,0,0,0,0,0,0,0,0,0,0,0,0,0,0,0,0,0,0,0,0,0
0,0,0,0,0,0,0,0,0,0,0,0,0,0,0,0,0,0,0,0,0,0,0,0,0,0,0,0,0,0,0,0,0
0,0,0,0,0,0,0,0,0,0,0,0,0,0,0,0,0,0,0,0,0,0,0,0,0,0,0,0,0,0,0,0,0
0,0,0,0,0,0,0,0,0,0,0,0,0,0,0,0,0,0,0,0,0,0,0,0,0,0,0,0,0,0,0,0,0
0,0,0,0,0,0,0,0,0,0,0,0,0,0,0,0,0,0,0,0,0,0,0,0,0,0,0,0,0,0,0,0,0
0,0,0,0,0,0,0,0,0,0,0,0,0,0,0,0,0,0,0,0,0,0,0,0,0,0,0,0,0,0,0,0,0
0,0,0,0,0,0,0,0,0,0,0,0,0,0,0,0,0,0,0,0,0,0,0,0,0,0,0,0,0,0,0,0,0
:endlayer
layer: 19
0,0,0,0,0,0,0,0,0,0,0,0,0,0,0,0,0,0,0,0,0,0,0,0,0,0,0,0,0,0,0,0,0
0,0,0,0,0,0,0,0,0,0,0,0,0,0,0,0,0,0,0,0,0,0,0,0,0,0,0,0,0,0,0,0,0
0,0,0,0,0,0,0,0,0,0,0,0,0,0,0,0,0,0,0,0,0,0,0,0,0,0,0,0,0,0,0,0,0
0,0,0,0,0,0,0,0,0,0,0,0,0,0,0,0,0,0,0,0,0,0,0,0,0,0,0,0,0,0,0,0,0
0,0,0,0,0,0,0,0,0,0,0,0,0,0,0,0,0,0,0,0,0,0,0,0,0,0,0,0,0,0,0,0,0
0,0,0,0,0,0,0,0,0,0,0,0,0,0,0,0,0,0,0,0,0,0,0,0,0,0,0,0,0,0,0,0,0
0,0,0,0,0,0,0,0,0,0,0,0,0,0,0,0,0,0,0,0,0,0,0,0,0,0,0,0,0,0,0,0,0
0,0,0,0,0,0,0,0,0,0,0,0,0,0,0,0,0,0,0,0,0,0,0,0,0,0,0,0,0,0,0,0,0
0,0,0,0,0,0,0,60,60,60,60,60,0,0,0,0,0,0,0,60,60,60,60,60,0,0,0,0,0,0,0,0,0
0,0,0,0,0,0,0,262,0,0,0,0,0,0,0,0,0,0,0,0,0,0,0,243,0,0,0,0,0,0,0,0,0
0,0,0,0,0,0,0,4,4,4,4,4,0,255,0,0,0,252,0,4,4,4,4,4,0,0,0,0,0,0,0,0,0
0,0,0,0,0,0,4,0,0,259,0,0,4,0,0,0,0,0,4,0,0,0,0,244,4,0,0,0,0,0,0,0,0
0,0,0,0,0,4,263,0,0,0,0,0,256,4,58,0,58,4,249,0,0,0,0,245,242,4,0,0,0,0,0,0,0
0,0,0,0,0,4,79,76,260,68,0,0,4,4,0,0,0,4,250,0,0,0,0,246,0,4,0,0,0,0,0,0,0
0,0,0,0,0,4,79,76,0,22,0,0,251,0,0,0,0,0,251,0,0,22,0,245,242,4,0,0,0,0,0,0,0
0,0,0,0,0,4,258,0,0,0,0,0,4,4,0,0,0,4,0,0,0,0,0,247,0,4,0,0,0,0,0,0,0
0,0,0,0,0,4,258,0,261,0,0,0,257,4,0,0,110,4,4,0,0,45,0,245,242,4,0,0,0,0,0,0,0
0,0,0,0,0,0,4,258,258,258,258,258,4,0,0,0,0,253,4,4,4,0,4,248,4,0,0,0,0,0,0,0,0
0,0,0,0,0,0,202,4,4,4,4,4,0,0,0,254,0,0,0,4,4,4,4,4,197,0,0,0,0,0,0,0,0
0,0,0,0,0,0,241,4,0,0,0,4,117,0,0,0,0,253,0,4,0,0,0,4,241,0,0,0,0,0,0,0,0
0,0,0,0,0,0,202,4,0,0,0,4,0,0,0,0,0,0,0,4,0,0,0,4,197,0,0,0,0,0,0,0,0
0,0,0,0,0,0,241,4,0,0,0,0,4,0,0,0,0,0,4,0,0,0,0,4,241,0,0,0,0,0,0,0,0
0,0,0,0,0,0,188,4,0,0,0,0,0,4,0,0,0,4,0,0,0,0,0,4,188,0,0,0,0,0,0,0,0
0,0,0,0,0,202,4,0,0,0,0,0,0,4,0,0,0,4,0,0,0,0,0,0,4,197,0,0,0,0,0,0,0
0,0,0,0,202,4,0,0,0,0,0,0,0,4,231,231,231,4,0,0,0,0,0,0,0,4,197,0,0,0,0,0,0
0,0,0,0,241,4,0,0,0,0,0,0,0,22,0,198,198,22,0,0,0,0,0,0,0,4,241,0,0,0,0,0,0
0,0,0,0,241,4,0,0,0,0,0,0,0,0,0,0,0,0,0,0,0,0,0,0,0,4,241,0,0,0,0,0,0
0,0,0,0,202,4,0,0,0,0,0,0,4,4,4,4,4,4,4,0,0,0,0,0,0,4,197,0,0,0,0,0,0
0,0,0,0,0,202,4,0,0,0,0,4,197,241,234,241,234,241,202,4,0,0,0,0,4,197,0,0,0,0,0,0,0
0,0,0,0,0,0,234,4,4,4,4,234,0,0,0,0,0,0,0,234,4,4,4,4,234,0,0,0,0,0,0,0,0
0,0,0,0,0,0,0,234,241,241,234,0,0,0,0,0,0,0,0,0,234,241,241,234,0,0,0,0,0,0,0,0,0
0,0,0,0,0,0,0,0,0,0,0,0,0,0,0,0,0,0,0,0,0,0,0,0,0,0,0,0,0,0,0,0,0
0,0,0,0,0,0,0,0,0,0,0,0,0,0,0,0,0,0,0,0,0,0,0,0,0,0,0,0,0,0,0,0,0
0,0,0,0,0,0,0,0,0,0,0,0,0,0,0,0,0,0,0,0,0,0,0,0,0,0,0,0,0,0,0,0,0
0,0,0,0,0,0,0,0,0,0,0,0,0,0,0,0,0,0,0,0,0,0,0,0,0,0,0,0,0,0,0,0,0
0,0,0,0,0,0,0,0,0,0,0,0,0,0,0,0,0,0,0,0,0,0,0,0,0,0,0,0,0,0,0,0,0
0,0,0,0,0,0,0,0,0,0,0,0,0,0,0,0,0,0,0,0,0,0,0,0,0,0,0,0,0,0,0,0,0
:endlayer
layer: 20
0,0,0,0,0,0,0,0,0,0,0,0,0,0,0,0,0,0,0,0,0,0,0,0,0,0,0,0,0,0,0,0,0
0,0,0,0,0,0,0,0,0,0,0,0,0,0,0,0,0,0,0,0,0,0,0,0,0,0,0,0,0,0,0,0,0
0,0,0,0,0,0,0,0,0,0,0,0,0,0,0,0,0,0,0,0,0,0,0,0,0,0,0,0,0,0,0,0,0
0,0,0,0,0,0,0,0,0,0,0,0,0,0,0,0,0,0,0,0,0,0,0,0,0,0,0,0,0,0,0,0,0
0,0,0,0,0,0,0,0,0,0,0,0,0,0,0,0,0,0,0,0,0,0,0,0,0,0,0,0,0,0,0,0,0
0,0,0,0,0,0,0,0,0,0,0,0,0,0,0,0,0,0,0,0,0,0,0,0,0,0,0,0,0,0,0,0,0
0,0,0,0,0,0,0,0,0,0,0,0,0,0,0,0,0,0,0,0,0,0,0,0,0,0,0,0,0,0,0,0,0
0,0,0,0,0,0,0,0,0,0,0,0,0,0,0,0,0,0,0,0,0,0,0,0,0,0,0,0,0,0,0,0,0
0,0,0,0,0,0,0,254,0,0,0,0,0,0,0,0,0,0,0,0,0,0,0,254,0,0,0,0,0,0,0,0,0
0,0,0,0,0,0,0,0,0,0,0,0,0,0,0,0,0,0,0,0,0,0,0,0,0,0,0,0,0,0,0,0,0
0,0,0,0,0,0,110,4,4,129,4,4,137,0,0,0,0,0,137,4,4,129,4,4,117,0,0,0,0,0,0,0,0
0,0,0,0,0,0,4,0,0,0,0,0,4,0,0,0,0,0,4,0,0,0,0,0,4,0,0,0,0,0,0,0,0
0,0,0,0,0,4,0,0,0,0,0,0,0,4,58,0,58,4,0,0,0,0,0,0,0,4,0,0,0,0,0,0,0
0,0,0,0,0,4,0,0,0,68,0,0,4,4,0,0,0,4,0,0,0,137,0,0,0,4,0,0,0,0,0,0,0
0,0,0,0,0,129,0,0,110,22,0,0,230,0,0,0,0,0,230,0,0,22,117,0,0,129,0,0,0,0,0,0,0
0,0,0,0,0,4,258,0,0,0,0,0,4,4,0,0,0,4,0,0,0,0,0,0,0,264,0,0,0,0,0,0,0
0,0,0,0,0,4,258,0,0,0,0,0,0,4,0,0,0,4,4,0,0,0,0,0,0,4,0,0,0,0,0,0,0
0,0,0,0,0,0,4,258,258,258,258,258,4,0,0,0,0,0,4,4,4,45,4,0,4,0,0,0,0,0,0,0,0
0,0,0,0,0,0,4,4,4,4,4,4,0,0,0,0,0,0,0,4,4,4,4,4,4,0,0,0,0,0,0,0,0
0,0,0,0,0,0,232,198,198,198,198,4,0,0,0,0,0,0,0,4,198,198,198,198,122,0,0,0,0,0,0,0,0
0,0,0,0,0,0,4,198,198,198,198,4,0,0,0,0,0,0,0,4,198,198,198,198,4,0,0,0,0,0,0,0,0
0,0,0,0,0,0,232,198,198,198,198,198,4,137,0,0,0,137,4,4,198,198,198,198,122,0,0,0,0,0,0,0,0
0,0,0,0,0,0,4,198,198,198,198,198,198,4,0,0,0,4,198,4,198,198,198,198,4,0,0,0,0,0,0,0,0
0,0,0,0,0,4,198,198,198,198,198,198,198,197,0,0,0,202,198,198,198,198,198,198,198,4,0,0,0,0,0,0,0
0,0,0,0,4,198,198,198,198,198,198,198,198,197,0,0,0,202,198,198,198,198,198,198,198,198,4,0,0,0,0,0,0
0,0,0,0,232,198,198,198,198,198,198,198,198,3,231,231,231,3,198,198,198,198,198,198,198,198,122,0,0,0,0,0,0
0,0,0,0,232,198,198,198,198,198,198,198,198,198,198,198,198,198,198,198,198,198,198,213,198,198,122,0,0,0,0,0,0
0,0,0,0,4,198,198,198,198,198,198,198,198,198,198,198,198,198,198,198,198,198,198,198,198,198,4,0,0,0,0,0,0
0,0,0,0,0,4,198,198,198,198,198,198,4,265,4,265,4,265,4,198,198,198,198,198,198,4,0,0,0,0,0,0,0
0,0,0,0,0,0,4,198,198,198,198,4,0,0,0,0,0,0,0,4,198,198,198,198,4,0,0,0,0,0,0,0,0
0,0,0,0,0,0,0,4,265,265,4,0,0,0,0,0,0,0,0,0,4,265,265,4,0,0,0,0,0,0,0,0,0
0,0,0,0,0,0,0,0,0,0,0,0,0,0,0,0,0,0,0,0,0,0,0,0,0,0,0,0,0,0,0,0,0
0,0,0,0,0,0,0,0,0,0,0,0,0,0,0,0,0,0,0,0,0,0,0,0,0,0,0,0,0,0,0,0,0
0,0,0,0,0,0,0,0,0,0,0,0,0,0,0,0,0,0,0,0,0,0,0,0,0,0,0,0,0,0,0,0,0
0,0,0,0,0,0,0,0,0,0,0,0,0,0,0,0,0,0,0,0,0,0,0,0,0,0,0,0,0,0,0,0,0
0,0,0,0,0,0,0,0,0,0,0,0,0,0,0,0,0,0,0,0,0,0,0,0,0,0,0,0,0,0,0,0,0
0,0,0,0,0,0,0,0,0,0,0,0,0,0,0,0,0,0,0,0,0,0,0,0,0,0,0,0,0,0,0,0,0
:endlayer
layer: 21
0,0,0,0,0,0,0,0,0,0,0,0,0,0,0,0,0,0,0,0,0,0,0,0,0,0,0,0,0,0,0,0,0
0,0,0,0,0,0,0,0,0,0,0,0,0,0,0,0,0,0,0,0,0,0,0,0,0,0,0,0,0,0,0,0,0
0,0,0,0,0,0,0,0,0,0,0,0,0,0,0,0,0,0,0,0,0,0,0,0,0,0,0,0,0,0,0,0,0
0,0,0,0,0,0,0,0,0,0,0,0,0,0,0,0,0,0,0,0,0,0,0,0,0,0,0,0,0,0,0,0,0
0,0,0,0,0,0,0,0,0,0,0,0,0,0,0,0,0,0,0,0,0,0,0,0,0,0,0,0,0,0,0,0,0
0,0,0,0,0,0,0,0,0,0,0,0,0,0,0,0,0,0,0,0,0,0,0,0,0,0,0,0,0,0,0,0,0
0,0,0,0,0,0,0,0,0,0,0,0,0,0,0,0,0,0,0,0,0,0,0,0,0,0,0,0,0,0,0,0,0
0,0,0,0,0,0,0,0,0,0,0,0,0,0,0,0,0,0,0,0,0,0,0,0,0,0,0,0,0,0,0,0,0
0,0,0,0,0,0,0,0,0,0,0,0,0,0,0,0,0,0,0,0,0,0,0,0,0,0,0,0,0,0,0,0,0
0,0,0,0,0,0,0,0,0,0,0,0,0,0,0,0,0,0,0,0,0,0,0,0,0,0,0,0,0,0,0,0,0
0,0,0,0,0,0,0,4,4,4,4,4,0,0,0,0,0,0,0,4,4,4,4,4,0,0,0,0,0,0,0,0,0
0,0,0,0,0,0,4,234,234,234,234,234,4,0,0,0,0,0,4,234,234,234,234,234,4,0,0,0,0,0,0,0,0
0,0,0,0,0,4,197,0,0,0,0,0,202,4,58,0,58,4,197,0,0,0,0,0,202,4,0,0,0,0,0,0,0
0,0,0,0,0,4,197,0,0,68,0,110,4,4,117,0,110,4,197,0,0,0,0,0,202,4,0,0,0,0,0,0,0
0,0,0,0,0,4,197,0,0,22,0,0,202,4,0,0,0,4,4,0,0,22,0,0,202,4,0,0,0,0,0,0,0
0,0,0,0,0,4,197,0,0,0,0,110,4,4,0,0,0,4,197,0,0,0,0,0,202,4,0,0,0,0,0,0,0
0,0,0,0,0,4,197,0,0,0,0,0,202,4,0,0,0,4,4,0,0,0,0,0,202,4,0,0,0,0,0,0,0
0,0,0,0,0,0,4,188,188,188,188,188,4,0,0,0,0,0,4,4,4,0,4,188,4,0,0,0,0,0,0,0,0
0,0,0,0,0,0,4,4,4,4,4,4,197,0,0,0,0,0,202,4,4,251,4,4,4,0,0,0,0,0,0,0,0
0,0,0,0,0,0,276,0,4,0,0,4,197,0,0,0,0,0,202,4,0,0,0,0,58,0,0,0,0,0,0,0,0
0,0,0,0,0,0,4,0,0,0,0,4,197,0,0,0,0,0,202,4,0,0,0,0,4,0,0,0,0,0,0,0,0
0,0,0,0,0,0,58,0,0,0,0,0,4,197,0,0,0,202,4,4,0,0,0,0,266,0,0,0,0,0,0,0,0
0,0,0,0,0,0,4,0,0,0,0,0,0,4,197,0,202,4,4,4,0,0,0,0,4,0,0,0,0,0,0,0,0
0,0,0,0,0,4,0,0,0,0,0,273,0,58,0,0,0,58,0,0,0,0,0,0,0,4,0,0,0,0,0,0,0
0,0,0,0,4,0,0,0,0,274,0,0,0,58,0,0,0,58,0,0,269,0,267,0,0,0,4,0,0,0,0,0,0
0,0,0,0,58,0,0,0,0,0,0,0,0,3,0,0,0,3,0,0,0,0,0,0,0,0,58,0,0,0,0,0,0
0,0,0,0,58,0,0,0,0,0,0,0,0,0,0,0,0,0,0,0,0,0,0,0,0,0,58,0,0,0,0,0,0
0,0,0,0,4,0,0,0,275,0,0,0,0,0,0,0,0,0,0,0,0,0,268,0,0,0,4,0,0,0,0,0,0
0,0,0,0,0,4,0,0,0,0,0,0,270,272,270,58,270,271,270,0,0,0,0,0,0,4,0,0,0,0,0,0,0
0,0,0,0,0,0,4,0,0,0,0,270,0,0,0,0,0,0,0,270,0,0,0,0,4,0,0,0,0,0,0,0,0
0,0,0,0,0,0,0,0,0,0,0,0,0,0,0,0,0,0,0,0,0,0,0,0,0,0,0,0,0,0,0,0,0
0,0,0,0,0,0,0,0,0,0,0,0,0,0,0,0,0,0,0,0,0,0,0,0,0,0,0,0,0,0,0,0,0
0,0,0,0,0,0,0,0,0,0,0,0,0,0,0,0,0,0,0,0,0,0,0,0,0,0,0,0,0,0,0,0,0
0,0,0,0,0,0,0,0,0,0,0,0,0,0,0,0,0,0,0,0,0,0,0,0,0,0,0,0,0,0,0,0,0
0,0,0,0,0,0,0,0,0,0,0,0,0,0,0,0,0,0,0,0,0,0,0,0,0,0,0,0,0,0,0,0,0
0,0,0,0,0,0,0,0,0,0,0,0,0,0,0,0,0,0,0,0,0,0,0,0,0,0,0,0,0,0,0,0,0
0,0,0,0,0,0,0,0,0,0,0,0,0,0,0,0,0,0,0,0,0,0,0,0,0,0,0,0,0,0,0,0,0
:endlayer
layer: 22
0,0,0,0,0,0,0,0,0,0,0,0,0,0,0,0,0,0,0,0,0,0,0,0,0,0,0,0,0,0,0,0,0
0,0,0,0,0,0,0,0,0,0,0,0,0,0,0,0,0,0,0,0,0,0,0,0,0,0,0,0,0,0,0,0,0
0,0,0,0,0,0,0,0,0,0,0,0,0,0,0,0,0,0,0,0,0,0,0,0,0,0,0,0,0,0,0,0,0
0,0,0,0,0,0,0,0,0,0,0,0,0,0,0,0,0,0,0,0,0,0,0,0,0,0,0,0,0,0,0,0,0
0,0,0,0,0,0,0,0,0,0,0,0,0,0,0,0,0,0,0,0,0,0,0,0,0,0,0,0,0,0,0,0,0
0,0,0,0,0,0,0,0,0,0,0,0,0,0,0,0,0,0,0,0,0,0,0,0,0,0,0,0,0,0,0,0,0
0,0,0,0,0,0,0,0,0,0,0,0,0,0,0,0,0,0,0,0,0,0,0,0,0,0,0,0,0,0,0,0,0
0,0,0,0,0,0,0,0,0,0,0,0,0,0,0,0,0,0,0,0,0,0,0,0,0,0,0,0,0,0,0,0,0
0,0,0,0,0,0,0,0,0,0,0,0,0,0,0,0,0,0,0,0,0,0,0,0,0,0,0,0,0,0,0,0,0
0,0,0,0,0,0,0,0,0,0,0,0,0,0,0,0,0,0,0,0,0,0,0,0,0,0,0,0,0,0,0,0,0
0,0,0,0,0,0,0,4,4,4,4,4,0,0,0,0,0,0,0,45,45,45,45,45,0,0,0,0,0,0,0,0,0
0,0,0,0,0,0,4,4,4,4,4,4,203,0,0,0,0,0,138,4,4,4,4,4,203,0,0,0,0,0,0,0,0
0,0,0,0,0,4,4,0,0,0,0,0,4,156,58,0,58,156,4,0,0,0,0,0,4,203,0,0,0,0,0,0,0
0,0,0,0,0,4,4,0,0,68,0,0,4,156,0,0,0,156,4,117,0,0,0,0,4,203,0,0,0,0,0,0,0
0,0,0,0,0,4,4,0,0,22,0,0,4,156,0,0,0,156,4,0,0,22,0,0,4,203,0,0,0,0,0,0,0
0,0,0,0,0,4,4,0,0,0,0,0,4,156,0,0,0,156,4,117,0,0,0,0,4,203,0,0,0,0,0,0,0
0,0,0,0,0,4,4,0,0,0,0,0,4,156,0,0,0,156,4,0,0,0,0,0,4,203,0,0,0,0,0,0,0
0,0,0,0,0,0,4,4,4,4,4,4,4,0,0,0,0,0,4,4,4,0,4,4,203,0,0,0,0,0,0,0,0
0,0,0,0,0,0,0,4,4,205,205,205,4,0,0,0,0,0,4,203,254,230,254,205,60,0,0,0,0,0,0,0,0
0,0,0,0,0,0,0,0,4,0,0,138,4,0,0,0,0,0,4,203,0,0,0,0,0,0,0,0,0,0,0,0,0
0,0,0,0,0,0,0,0,0,0,0,138,4,0,0,0,0,0,4,203,0,0,0,0,60,0,0,0,0,0,0,0,0
0,0,0,0,0,0,0,0,0,0,0,0,138,4,4,4,4,4,203,0,0,0,0,0,0,0,0,0,0,0,0,0,0
0,0,0,0,0,0,0,0,0,0,0,0,0,205,4,205,4,205,0,60,0,0,0,0,60,0,0,0,0,0,0,0,0
0,0,0,0,0,0,0,0,0,0,0,0,0,0,0,0,0,0,0,0,0,0,0,0,0,0,0,0,0,0,0,0,0
0,0,0,0,254,0,0,0,0,0,0,0,0,0,0,0,0,0,0,0,0,0,0,0,0,0,254,0,0,0,0,0,0
0,0,0,0,0,0,0,0,0,0,0,0,0,124,0,0,0,124,0,0,0,0,0,0,0,0,0,0,0,0,0,0,0
0,0,0,0,0,0,0,0,0,0,0,0,0,0,0,0,0,0,0,0,0,0,0,0,0,0,0,0,0,0,0,0,0
0,0,0,0,254,0,0,0,0,0,0,0,0,0,0,0,0,0,0,0,0,0,0,0,0,0,254,0,0,0,0,0,0
0,0,0,0,0,0,0,0,0,0,0,0,0,0,0,0,0,0,0,0,0,0,0,0,0,0,0,0,0,0,0,0,0
0,0,0,0,0,0,0,0,0,0,0,0,0,0,0,0,0,0,0,0,0,0,0,0,0,0,0,0,0,0,0,0,0
0,0,0,0,0,0,0,0,0,0,0,0,0,0,0,0,0,0,0,0,0,0,0,0,0,0,0,0,0,0,0,0,0
0,0,0,0,0,0,0,0,0,0,0,0,0,0,0,0,0,0,0,0,0,0,0,0,0,0,0,0,0,0,0,0,0
0,0,0,0,0,0,0,0,0,0,0,0,0,0,0,0,0,0,0,0,0,0,0,0,0,0,0,0,0,0,0,0,0
0,0,0,0,0,0,0,0,0,0,0,0,0,0,0,0,0,0,0,0,0,0,0,0,0,0,0,0,0,0,0,0,0
0,0,0,0,0,0,0,0,0,0,0,0,0,0,0,0,0,0,0,0,0,0,0,0,0,0,0,0,0,0,0,0,0
0,0,0,0,0,0,0,0,0,0,0,0,0,0,0,0,0,0,0,0,0,0,0,0,0,0,0,0,0,0,0,0,0
0,0,0,0,0,0,0,0,0,0,0,0,0,0,0,0,0,0,0,0,0,0,0,0,0,0,0,0,0,0,0,0,0
:endlayer
layer: 23
0,0,0,0,0,0,0,0,0,0,0,0,0,0,0,0,0,0,0,0,0,0,0,0,0,0,0,0,0,0,0,0,0
0,0,0,0,0,0,0,0,0,0,0,0,0,0,0,0,0,0,0,0,0,0,0,0,0,0,0,0,0,0,0,0,0
0,0,0,0,0,0,0,0,0,0,0,0,0,0,0,0,0,0,0,0,0,0,0,0,0,0,0,0,0,0,0,0,0
0,0,0,0,0,0,0,0,0,0,0,0,0,0,0,0,0,0,0,0,0,0,0,0,0,0,0,0,0,0,0,0,0
0,0,0,0,0,0,0,0,0,0,0,0,0,0,0,0,0,0,0,0,0,0,0,0,0,0,0,0,0,0,0,0,0
0,0,0,0,0,0,0,0,0,0,0,0,0,0,0,0,0,0,0,0,0,0,0,0,0,0,0,0,0,0,0,0,0
0,0,0,0,0,0,0,0,0,0,0,0,0,0,0,0,0,0,0,0,0,0,0,0,0,0,0,0,0,0,0,0,0
0,0,0,0,0,0,0,0,0,0,0,0,0,0,0,0,0,0,0,0,0,0,0,0,0,0,0,0,0,0,0,0,0
0,0,0,0,0,0,0,0,0,0,0,0,0,0,0,0,0,0,0,0,0,0,0,0,0,0,0,0,0,0,0,0,0
0,0,0,0,0,0,192,0,188,0,188,0,192,0,0,0,0,0,0,0,0,0,0,0,0,0,0,0,0,0,0,0,0
0,0,0,0,0,0,192,4,4,4,4,4,192,0,0,0,0,0,0,188,188,188,188,188,0,0,0,0,0,0,0,0,0
0,0,0,0,192,192,4,4,4,4,4,4,4,192,192,0,0,0,202,4,4,4,4,4,197,0,0,0,0,0,0,0,0
0,0,0,0,0,4,4,3,3,3,3,3,4,156,4,188,4,156,4,0,0,0,0,0,4,197,0,0,0,0,0,0,0
0,0,0,0,202,4,4,3,3,68,3,3,4,156,198,198,198,156,4,0,0,0,0,0,4,197,0,0,0,0,0,0,0
0,0,0,0,0,4,4,3,3,22,3,3,4,156,198,198,198,156,4,0,0,22,0,0,4,197,0,0,0,0,0,0,0
0,0,0,0,202,4,4,3,3,3,3,3,4,156,198,198,198,156,4,0,0,0,0,0,4,197,0,0,0,0,0,0,0
0,0,0,0,0,4,4,3,3,3,3,3,4,156,198,198,198,156,4,0,0,0,0,0,4,197,0,0,0,0,0,0,0
0,0,0,0,192,192,4,4,4,4,4,4,4,198,198,198,198,198,4,4,4,4,4,4,197,0,0,0,0,0,0,0,0
0,0,0,0,0,0,192,4,4,234,234,234,156,198,198,198,198,198,156,234,234,234,234,234,60,0,0,0,0,0,0,0,0
0,0,0,0,0,0,192,0,4,0,0,202,156,198,198,198,198,198,156,197,0,0,0,0,0,0,0,0,0,0,0,0,0
0,0,0,0,0,0,0,0,115,0,0,202,156,198,198,198,198,198,156,197,0,0,0,0,60,0,0,0,0,0,0,0,0
0,0,0,0,0,0,0,0,0,0,0,0,202,156,156,156,156,156,4,0,0,0,0,0,0,0,0,0,0,0,0,0,0
0,0,0,0,0,0,0,0,0,0,0,0,0,234,3,234,3,234,0,60,0,0,0,0,60,0,0,0,0,0,0,0,0
0,0,0,0,0,0,0,0,0,0,0,0,0,0,0,0,0,0,0,0,0,0,0,0,0,0,0,0,0,0,0,0,0
0,0,0,0,0,0,0,0,0,0,0,0,0,0,0,0,0,0,0,0,0,0,0,0,0,0,0,0,0,0,0,0,0
0,0,0,0,0,0,0,0,0,0,0,0,0,0,0,0,0,0,0,0,0,0,0,0,0,0,0,0,0,0,0,0,0
0,0,0,0,0,0,0,0,0,0,0,0,0,0,0,0,0,0,0,0,0,0,0,0,0,0,0,0,0,0,0,0,0
0,0,0,0,0,0,0,0,0,0,0,0,0,0,0,0,0,0,0,0,0,0,0,0,0,0,0,0,0,0,0,0,0
0,0,0,0,0,0,0,0,0,0,0,0,0,0,0,0,0,0,0,0,0,0,0,0,0,0,0,0,0,0,0,0,0
0,0,0,0,0,0,0,0,0,0,0,0,0,0,0,0,0,0,0,0,0,0,0,0,0,0,0,0,0,0,0,0,0
0,0,0,0,0,0,0,0,0,0,0,0,0,0,0,0,0,0,0,0,0,0,0,0,0,0,0,0,0,0,0,0,0
0,0,0,0,0,0,0,0,0,0,0,0,0,0,0,0,0,0,0,0,0,0,0,0,0,0,0,0,0,0,0,0,0
0,0,0,0,0,0,0,0,0,0,0,0,0,0,0,0,0,0,0,0,0,0,0,0,0,0,0,0,0,0,0,0,0
0,0,0,0,0,0,0,0,0,0,0,0,0,0,0,0,0,0,0,0,0,0,0,0,0,0,0,0,0,0,0,0,0
0,0,0,0,0,0,0,0,0,0,0,0,0,0,0,0,0,0,0,0,0,0,0,0,0,0,0,0,0,0,0,0,0
0,0,0,0,0,0,0,0,0,0,0,0,0,0,0,0,0,0,0,0,0,0,0,0,0,0,0,0,0,0,0,0,0
0,0,0,0,0,0,0,0,0,0,0,0,0,0,0,0,0,0,0,0,0,0,0,0,0,0,0,0,0,0,0,0,0
:endlayer
layer: 24
0,0,0,0,0,0,0,0,0,0,0,0,0,0,0,0,0,0,0,0,0,0,0,0,0,0,0,0,0,0,0,0,0
0,0,0,0,0,0,0,0,0,0,0,0,0,0,0,0,0,0,0,0,0,0,0,0,0,0,0,0,0,0,0,0,0
0,0,0,0,0,0,0,0,0,0,0,0,0,0,0,0,0,0,0,0,0,0,0,0,0,0,0,0,0,0,0,0,0
0,0,0,0,0,0,0,0,0,0,0,0,0,0,0,0,0,0,0,0,0,0,0,0,0,0,0,0,0,0,0,0,0
0,0,0,0,0,0,0,0,0,0,0,0,0,0,0,0,0,0,0,0,0,0,0,0,0,0,0,0,0,0,0,0,0
0,0,0,0,0,0,0,0,0,0,0,0,0,0,0,0,0,0,0,0,0,0,0,0,0,0,0,0,0,0,0,0,0
0,0,0,0,0,0,0,0,0,0,0,0,0,0,0,0,0,0,0,0,0,0,0,0,0,0,0,0,0,0,0,0,0
0,0,0,0,0,0,0,0,0,0,0,0,0,0,0,0,0,0,0,0,0,0,0,0,0,0,0,0,0,0,0,0,0
0,0,0,0,0,0,188,241,188,241,188,241,188,0,0,0,0,0,0,0,0,0,0,0,0,0,0,0,0,0,0,0,0
0,0,0,0,0,188,198,198,198,198,198,198,198,188,0,0,0,0,0,0,0,0,0,0,0,0,0,0,0,0,0,0,0
0,0,0,0,202,198,198,4,4,4,4,4,198,198,197,0,0,0,0,4,4,4,4,4,0,0,0,0,0,0,0,0,0
0,0,0,202,198,198,4,0,0,0,0,0,4,198,204,197,188,188,4,4,4,4,4,4,4,0,0,0,0,0,0,0,0
0,0,0,241,198,4,0,0,0,0,0,0,0,4,204,204,204,4,4,0,0,0,0,0,4,4,0,0,0,0,0,0,0
0,0,0,202,198,4,0,0,0,68,0,0,0,4,0,0,0,4,4,0,0,0,0,0,4,4,0,0,0,0,0,0,0
0,0,0,241,198,4,281,0,0,22,0,0,0,0,0,0,0,3,3,0,0,22,0,0,4,4,0,0,0,0,0,0,0
0,0,0,202,198,4,0,0,0,0,0,0,0,4,0,0,0,4,4,0,0,0,0,0,4,4,0,0,0,0,0,0,0
0,0,0,241,198,4,0,0,0,0,0,0,0,4,0,0,0,4,4,0,0,0,0,0,4,4,0,0,0,0,0,0,0
0,0,0,202,198,198,4,0,0,0,0,0,4,0,0,0,0,0,4,4,4,4,4,4,4,204,0,0,0,0,0,0,0
0,0,0,0,202,198,198,4,4,4,4,4,218,0,0,0,0,0,218,4,4,4,4,4,198,204,0,0,0,0,0,0,0
0,0,0,0,0,234,198,198,198,198,198,198,204,0,280,0,279,0,218,4,0,0,0,0,198,204,0,0,0,0,0,0,0
0,0,0,0,0,0,234,241,234,241,202,3,218,0,0,0,0,0,218,278,0,0,0,0,198,204,0,0,0,0,0,0,0
0,0,0,0,0,0,0,0,0,0,0,202,3,218,218,218,218,218,3,197,0,0,0,0,198,204,0,0,0,0,0,0,0
0,0,0,0,0,0,0,0,0,0,0,0,234,3,3,278,278,278,234,277,277,277,277,277,277,204,0,0,0,0,0,0,0
0,0,0,0,0,0,0,0,0,0,0,0,0,234,241,234,241,234,0,0,0,0,0,0,0,0,0,0,0,0,0,0,0
0,0,0,0,0,0,0,0,0,0,0,0,0,0,0,0,0,0,0,0,0,0,0,0,0,0,0,0,0,0,0,0,0
0,0,0,0,0,0,0,0,0,0,0,0,0,0,0,0,0,0,0,0,0,0,0,0,0,0,0,0,0,0,0,0,0
0,0,0,0,0,0,0,0,0,0,0,0,0,0,0,0,0,0,0,0,0,0,0,0,0,0,0,0,0,0,0,0,0
0,0,0,0,0,0,0,0,0,0,0,0,0,0,0,0,0,0,0,0,0,0,0,0,0,0,0,0,0,0,0,0,0
0,0,0,0,0,0,0,0,0,0,0,0,0,0,0,0,0,0,0,0,0,0,0,0,0,0,0,0,0,0,0,0,0
0,0,0,0,0,0,0,0,0,0,0,0,0,0,0,0,0,0,0,0,0,0,0,0,0,0,0,0,0,0,0,0,0
0,0,0,0,0,0,0,0,0,0,0,0,0,0,0,0,0,0,0,0,0,0,0,0,0,0,0,0,0,0,0,0,0
0,0,0,0,0,0,0,0,0,0,0,0,0,0,0,0,0,0,0,0,0,0,0,0,0,0,0,0,0,0,0,0,0
0,0,0,0,0,0,0,0,0,0,0,0,0,0,0,0,0,0,0,0,0,0,0,0,0,0,0,0,0,0,0,0,0
0,0,0,0,0,0,0,0,0,0,0,0,0,0,0,0,0,0,0,0,0,0,0,0,0,0,0,0,0,0,0,0,0
0,0,0,0,0,0,0,0,0,0,0,0,0,0,0,0,0,0,0,0,0,0,0,0,0,0,0,0,0,0,0,0,0
0,0,0,0,0,0,0,0,0,0,0,0,0,0,0,0,0,0,0,0,0,0,0,0,0,0,0,0,0,0,0,0,0
0,0,0,0,0,0,0,0,0,0,0,0,0,0,0,0,0,0,0,0,0,0,0,0,0,0,0,0,0,0,0,0,0
:endlayer
layer: 25
0,0,0,0,0,0,0,0,0,0,0,0,0,0,0,0,0,0,0,0,0,0,0,0,0,0,0,0,0,0,0,0,0
0,0,0,0,0,0,0,0,0,0,0,0,0,0,0,0,0,0,0,0,0,0,0,0,0,0,0,0,0,0,0,0,0
0,0,0,0,0,0,0,0,0,0,0,0,0,0,0,0,0,0,0,0,0,0,0,0,0,0,0,0,0,0,0,0,0
0,0,0,0,0,0,0,0,0,0,0,0,0,0,0,0,0,0,0,0,0,0,0,0,0,0,0,0,0,0,0,0,0
0,0,0,0,0,0,0,0,0,0,0,0,0,0,0,0,0,0,0,0,0,0,0,0,0,0,0,0,0,0,0,0,0
0,0,0,0,0,0,0,0,0,0,0,0,0,0,0,0,0,0,0,0,0,0,0,0,0,0,0,0,0,0,0,0,0
0,0,0,0,0,0,0,0,0,0,0,0,0,0,0,0,0,0,0,0,0,0,0,0,0,0,0,0,0,0,0,0,0
0,0,0,0,0,0,0,0,0,0,0,0,0,0,0,0,0,0,0,0,0,0,0,0,0,0,0,0,0,0,0,0,0
0,0,0,0,0,0,4,58,4,58,4,58,4,0,0,0,0,0,0,0,0,0,0,0,0,0,0,0,0,0,0,0,0
0,0,0,0,0,4,0,0,0,0,0,0,0,4,0,0,0,0,0,0,0,0,0,0,0,0,0,0,0,0,0,0,0
0,0,0,0,4,0,0,4,4,4,4,4,282,0,4,0,0,0,0,4,4,4,4,4,0,0,0,0,0,0,0,0,0
0,0,0,4,0,0,4,117,0,0,0,110,4,0,0,4,58,4,4,20,20,20,20,20,4,0,0,0,0,0,0,0,0
0,0,0,58,0,4,115,0,0,0,0,0,115,4,0,0,0,4,20,20,20,20,20,20,20,4,0,0,0,0,0,0,0
0,0,0,4,0,4,0,0,0,68,0,0,0,4,117,0,110,4,20,20,20,20,20,20,20,4,0,0,0,0,0,0,0
0,0,0,58,0,4,0,0,0,22,0,0,0,0,0,0,0,3,20,20,20,22,20,20,20,4,0,0,0,0,0,0,0
0,0,0,4,0,4,0,0,0,0,0,0,0,4,117,0,110,4,20,20,20,20,20,20,20,4,0,0,0,0,0,0,0
0,0,0,58,0,4,137,0,0,0,0,0,137,4,0,0,0,4,20,20,20,20,20,20,20,4,0,0,0,0,0,0,0
0,0,0,4,0,0,4,117,0,0,0,110,4,0,0,0,0,0,4,20,20,4,4,4,4,0,0,0,0,0,0,0,0
0,0,0,0,4,0,0,4,4,4,4,4,0,0,0,0,0,0,0,4,4,198,4,4,198,0,0,0,0,0,0,0,0
0,0,0,0,0,4,0,0,0,0,0,0,0,0,0,0,0,0,0,0,198,198,198,198,198,0,0,0,0,0,0,0,0
0,0,0,0,0,0,4,58,4,58,4,0,0,0,0,0,0,0,0,0,198,198,198,198,198,117,0,0,0,0,0,0,0
0,0,0,0,0,0,0,0,0,0,0,4,0,0,0,0,0,0,0,4,277,277,277,277,277,0,0,0,0,0,0,0,0
0,0,0,0,0,0,0,0,0,0,0,0,4,0,0,0,0,0,4,0,0,0,0,0,0,0,0,0,0,0,0,0,0
0,0,0,0,0,0,0,0,0,0,0,0,0,4,58,4,58,4,0,0,0,0,0,0,0,0,0,0,0,0,0,0,0
0,0,0,0,0,0,0,0,0,0,0,0,0,0,0,0,0,0,0,0,0,0,0,0,0,0,0,0,0,0,0,0,0
0,0,0,0,0,0,0,0,0,0,0,0,0,0,0,0,0,0,0,0,0,0,0,0,0,0,0,0,0,0,0,0,0
0,0,0,0,0,0,0,0,0,0,0,0,0,0,0,0,0,0,0,0,0,0,0,0,0,0,0,0,0,0,0,0,0
0,0,0,0,0,0,0,0,0,0,0,0,0,0,0,0,0,0,0,0,0,0,0,0,0,0,0,0,0,0,0,0,0
0,0,0,0,0,0,0,0,0,0,0,0,0,0,0,0,0,0,0,0,0,0,0,0,0,0,0,0,0,0,0,0,0
0,0,0,0,0,0,0,0,0,0,0,0,0,0,0,0,0,0,0,0,0,0,0,0,0,0,0,0,0,0,0,0,0
0,0,0,0,0,0,0,0,0,0,0,0,0,0,0,0,0,0,0,0,0,0,0,0,0,0,0,0,0,0,0,0,0
0,0,0,0,0,0,0,0,0,0,0,0,0,0,0,0,0,0,0,0,0,0,0,0,0,0,0,0,0,0,0,0,0
0,0,0,0,0,0,0,0,0,0,0,0,0,0,0,0,0,0,0,0,0,0,0,0,0,0,0,0,0,0,0,0,0
0,0,0,0,0,0,0,0,0,0,0,0,0,0,0,0,0,0,0,0,0,0,0,0,0,0,0,0,0,0,0,0,0
0,0,0,0,0,0,0,0,0,0,0,0,0,0,0,0,0,0,0,0,0,0,0,0,0,0,0,0,0,0,0,0,0
0,0,0,0,0,0,0,0,0,0,0,0,0,0,0,0,0,0,0,0,0,0,0,0,0,0,0,0,0,0,0,0,0
0,0,0,0,0,0,0,0,0,0,0,0,0,0,0,0,0,0,0,0,0,0,0,0,0,0,0,0,0,0,0,0,0
:endlayer
layer: 26
0,0,0,0,0,0,0,0,0,0,0,0,0,0,0,0,0,0,0,0,0,0,0,0,0,0,0,0,0,0,0,0,0
0,0,0,0,0,0,0,0,0,0,0,0,0,0,0,0,0,0,0,0,0,0,0,0,0,0,0,0,0,0,0,0,0
0,0,0,0,0,0,0,0,0,0,0,0,0,0,0,0,0,0,0,0,0,0,0,0,0,0,0,0,0,0,0,0,0
0,0,0,0,0,0,0,0,0,0,0,0,0,0,0,0,0,0,0,0,0,0,0,0,0,0,0,0,0,0,0,0,0
0,0,0,0,0,0,0,0,0,0,0,0,0,0,0,0,0,0,0,0,0,0,0,0,0,0,0,0,0,0,0,0,0
0,0,0,0,0,0,0,0,0,0,0,0,0,0,0,0,0,0,0,0,0,0,0,0,0,0,0,0,0,0,0,0,0
0,0,0,0,0,0,0,0,0,0,0,0,0,0,0,0,0,0,0,0,0,0,0,0,0,0,0,0,0,0,0,0,0
0,0,0,0,0,0,0,0,0,0,0,0,0,0,0,0,0,0,0,0,0,0,0,0,0,0,0,0,0,0,0,0,0
0,0,0,0,0,0,0,0,0,0,0,0,0,0,0,0,0,0,0,0,0,0,0,0,0,0,0,0,0,0,0,0,0
0,0,0,0,0,0,0,0,0,0,0,0,0,0,0,0,0,0,0,0,0,0,0,0,0,0,0,0,0,0,0,0,0
0,0,0,0,293,0,0,4,4,4,4,4,0,0,0,0,0,0,0,45,45,45,45,45,0,0,0,0,0,0,0,0,0
0,0,0,0,0,0,4,20,20,20,20,20,4,0,0,0,0,0,138,4,4,4,4,4,203,0,0,0,0,0,0,0,0
0,0,0,0,0,4,20,20,20,20,20,20,20,4,0,0,0,138,4,290,287,0,0,283,4,203,0,0,0,0,0,0,0
0,0,0,0,0,4,20,20,20,68,20,20,20,4,197,192,202,4,203,0,0,0,0,284,4,203,0,0,0,0,0,0,0
0,0,0,0,0,4,20,20,20,22,20,20,20,156,197,192,202,4,203,0,288,22,0,0,4,203,0,0,0,0,0,0,0
0,0,0,0,0,4,20,20,20,20,20,20,20,4,197,192,202,4,203,0,0,0,0,285,4,203,0,0,0,0,0,0,0
0,0,0,0,0,4,20,20,20,20,20,20,20,4,0,0,0,138,4,0,289,0,0,286,4,203,0,0,0,0,0,0,0
0,0,0,0,0,0,4,20,20,20,20,20,4,115,0,0,0,0,205,4,4,129,4,4,203,0,0,0,0,0,0,0,0
0,0,0,0,0,0,0,4,4,4,4,4,0,0,0,0,0,0,0,205,205,204,205,205,0,0,0,0,0,0,0,0,0
0,0,0,0,0,0,0,0,0,0,0,0,0,0,0,0,0,0,0,0,204,204,204,204,0,0,0,0,0,0,0,0,0
0,0,0,0,0,0,0,0,0,0,254,0,0,0,0,0,0,0,0,0,204,204,204,204,0,0,0,0,0,0,0,0,0
0,0,0,0,0,0,0,0,0,0,0,0,0,0,0,0,0,0,0,254,0,0,0,0,0,0,0,0,0,0,0,0,0
0,0,0,0,0,0,0,0,0,0,0,0,292,0,0,0,0,0,291,0,0,0,0,0,0,0,0,0,0,0,0,0,0
0,0,0,0,0,0,0,0,0,0,0,0,0,254,0,0,0,254,0,0,0,0,0,0,0,0,0,0,0,0,0,0,0
0,0,0,0,0,0,0,0,0,0,0,0,0,0,0,0,0,0,0,0,0,0,0,0,0,0,0,0,0,0,0,0,0
0,0,0,0,0,0,0,0,0,0,0,0,0,0,0,0,0,0,0,0,0,0,0,0,0,0,0,0,0,0,0,0,0
0,0,0,0,0,0,0,0,0,0,0,0,0,0,0,0,0,0,0,0,0,0,0,0,0,0,0,0,0,0,0,0,0
0,0,0,0,0,0,0,0,0,0,0,0,0,0,0,0,0,0,0,0,0,0,0,0,0,0,0,0,0,0,0,0,0
0,0,0,0,0,0,0,0,0,0,0,0,0,0,0,0,0,0,0,0,0,0,0,0,0,0,0,0,0,0,0,0,0
0,0,0,0,0,0,0,0,0,0,0,0,0,0,0,0,0,0,0,0,0,0,0,0,0,0,0,0,0,0,0,0,0
0,0,0,0,0,0,0,0,0,0,0,0,0,0,0,0,0,0,0,0,0,0,0,0,0,0,0,0,0,0,0,0,0
0,0,0,0,0,0,0,0,0,0,0,0,0,0,0,0,0,0,0,0,0,0,0,0,0,0,0,0,0,0,0,0,0
0,0,0,0,0,0,0,0,0,0,0,0,0,0,0,0,0,0,0,0,0,0,0,0,0,0,0,0,0,0,0,0,0
0,0,0,0,0,0,0,0,0,0,0,0,0,0,0,0,0,0,0,0,0,0,0,0,0,0,0,0,0,0,0,0,0
0,0,0,0,0,0,0,0,0,0,0,0,0,0,0,0,0,0,0,0,0,0,0,0,0,0,0,0,0,0,0,0,0
0,0,0,0,0,0,0,0,0,0,0,0,0,0,0,0,0,0,0,0,0,0,0,0,0,0,0,0,0,0,0,0,0
0,0,0,0,0,0,0,0,0,0,0,0,0,0,0,0,0,0,0,0,0,0,0,0,0,0,0,0,0,0,0,0,0
:endlayer
layer: 27
0,0,0,0,0,0,0,0,0,0,0,0,0,0,0,0,0,0,0,0,0,0,0,0,0,0,0,0,0,0,0,0,0
0,0,0,0,0,0,0,0,0,0,0,0,0,0,0,0,0,0,0,0,0,0,0,0,0,0,0,0,0,0,0,0,0
0,0,0,0,0,0,0,0,0,0,0,0,0,0,0,0,0,0,0,0,0,0,0,0,0,0,0,0,0,0,0,0,0
0,0,0,0,0,0,0,0,0,0,0,0,0,0,0,0,0,0,0,0,0,0,0,0,0,0,0,0,0,0,0,0,0
0,0,0,0,0,0,0,0,0,0,0,0,0,0,0,0,0,0,0,0,0,0,0,0,0,0,0,0,0,0,0,0,0
0,0,0,0,0,0,0,0,0,0,0,0,0,0,0,0,0,0,0,0,0,0,0,0,0,0,0,0,0,0,0,0,0
0,0,0,0,0,0,0,0,0,0,0,0,0,0,0,0,0,0,0,0,0,0,0,0,0,0,0,0,0,0,0,0,0
0,0,0,0,0,0,0,0,0,0,0,0,0,0,0,0,0,0,0,0,0,0,0,0,0,0,0,0,0,0,0,0,0
0,0,0,0,0,0,0,0,0,0,0,0,0,0,0,0,0,0,0,0,0,0,0,0,0,0,0,0,0,0,0,0,0
0,0,0,0,0,0,0,137,0,0,0,137,0,0,0,0,0,0,0,0,0,0,0,0,0,0,0,0,0,0,0,0,0
0,0,0,0,0,0,110,4,4,4,4,4,117,0,0,0,0,0,0,188,188,188,188,188,0,0,0,0,0,0,0,0,0
0,0,0,0,0,137,4,156,0,0,0,156,4,137,0,0,0,0,202,4,4,4,4,4,197,0,0,0,0,0,0,0,0
0,0,0,0,110,4,156,0,0,0,0,0,156,4,0,0,0,202,4,0,192,192,0,0,4,197,0,0,0,0,0,0,0
0,0,0,0,0,4,0,296,0,68,0,0,0,171,58,58,58,171,0,0,0,0,0,192,4,197,0,0,0,0,0,0,0
0,0,0,0,0,4,0,0,288,22,0,0,295,221,0,0,0,294,0,0,288,22,0,192,4,197,0,0,0,0,0,0,0
0,0,0,0,0,4,0,0,0,0,0,0,0,171,58,58,58,171,0,0,0,0,0,0,4,197,0,0,0,0,0,0,0
0,0,0,0,110,4,156,0,0,0,0,0,4,4,117,0,0,202,4,0,0,0,0,0,4,197,0,0,0,0,0,0,0
0,0,0,0,0,115,4,156,4,156,4,156,4,0,0,0,0,0,234,4,4,129,4,4,197,0,0,0,0,0,0,0,0
0,0,0,0,0,0,110,4,205,156,205,4,117,0,0,0,0,0,0,234,234,0,234,234,0,0,0,0,0,0,0,0,0
0,0,0,0,0,0,0,115,0,0,0,115,0,0,0,0,0,0,0,0,0,0,0,0,0,0,0,0,0,0,0,0,0
0,0,0,0,0,0,0,0,0,0,0,0,0,0,0,0,0,0,0,0,0,0,0,0,0,0,0,0,0,0,0,0,0
0,0,0,0,0,0,0,0,0,0,0,0,0,0,0,0,0,0,0,0,0,0,0,0,0,0,0,0,0,0,0,0,0
0,0,0,0,0,0,0,0,0,0,0,0,0,0,0,0,0,0,0,0,0,0,0,0,0,0,0,0,0,0,0,0,0
0,0,0,0,0,0,0,0,0,0,0,0,0,0,0,0,0,0,0,0,0,0,0,0,0,0,0,0,0,0,0,0,0
0,0,0,0,0,0,0,0,0,0,0,0,0,0,0,0,0,0,0,0,0,0,0,0,0,0,0,0,0,0,0,0,0
0,0,0,0,0,0,0,0,0,0,0,0,0,0,0,0,0,0,0,0,0,0,0,0,0,0,0,0,0,0,0,0,0
0,0,0,0,0,0,0,0,0,0,0,0,0,0,0,0,0,0,0,0,0,0,0,0,0,0,0,0,0,0,0,0,0
0,0,0,0,0,0,0,0,0,0,0,0,0,0,0,0,0,0,0,0,0,0,0,0,0,0,0,0,0,0,0,0,0
0,0,0,0,0,0,0,0,0,0,0,0,0,0,0,0,0,0,0,0,0,0,0,0,0,0,0,0,0,0,0,0,0
0,0,0,0,0,0,0,0,0,0,0,0,0,0,0,0,0,0,0,0,0,0,0,0,0,0,0,0,0,0,0,0,0
0,0,0,0,0,0,0,0,0,0,0,0,0,0,0,0,0,0,0,0,0,0,0,0,0,0,0,0,0,0,0,0,0
0,0,0,0,0,0,0,0,0,0,0,0,0,0,0,0,0,0,0,0,0,0,0,0,0,0,0,0,0,0,0,0,0
0,0,0,0,0,0,0,0,0,0,0,0,0,0,0,0,0,0,0,0,0,0,0,0,0,0,0,0,0,0,0,0,0
0,0,0,0,0,0,0,0,0,0,0,0,0,0,0,0,0,0,0,0,0,0,0,0,0,0,0,0,0,0,0,0,0
0,0,0,0,0,0,0,0,0,0,0,0,0,0,0,0,0,0,0,0,0,0,0,0,0,0,0,0,0,0,0,0,0
0,0,0,0,0,0,0,0,0,0,0,0,0,0,0,0,0,0,0,0,0,0,0,0,0,0,0,0,0,0,0,0,0
0,0,0,0,0,0,0,0,0,0,0,0,0,0,0,0,0,0,0,0,0,0,0,0,0,0,0,0,0,0,0,0,0
:endlayer
layer: 28
0,0,0,0,0,0,0,0,0,0,0,0,0,0,0,0,0,0,0,0,0,0,0,0,0,0,0,0,0,0,0,0,0
0,0,0,0,0,0,0,0,0,0,0,0,0,0,0,0,0,0,0,0,0,0,0,0,0,0,0,0,0,0,0,0,0
0,0,0,0,0,0,0,0,0,0,0,0,0,0,0,0,0,0,0,0,0,0,0,0,0,0,0,0,0,0,0,0,0
0,0,0,0,0,0,0,0,0,0,0,0,0,0,0,0,0,0,0,0,0,0,0,0,0,0,0,0,0,0,0,0,0
0,0,0,0,0,0,0,0,0,0,0,0,0,0,0,0,0,0,0,0,0,0,0,0,0,0,0,0,0,0,0,0,0
0,0,0,0,0,0,0,0,0,0,0,0,0,0,0,0,0,0,0,0,0,0,0,0,0,0,0,0,0,0,0,0,0
0,0,0,0,0,0,0,0,0,0,0,0,0,0,0,0,0,0,0,0,0,0,0,0,0,0,0,0,0,0,0,0,0
0,0,0,0,0,0,0,0,0,0,0,0,0,0,0,0,0,0,0,0,0,0,0,0,0,0,0,0,0,0,0,0,0
0,0,0,0,0,0,0,0,0,0,0,0,0,0,0,0,0,0,0,0,0,0,0,0,0,0,0,0,0,0,0,0,0
0,0,0,0,0,0,0,0,0,0,0,0,0,0,0,0,0,0,0,0,0,0,0,0,0,0,0,0,0,0,0,0,0
0,0,0,0,0,0,0,45,45,45,45,45,0,0,0,0,0,0,0,4,4,4,4,4,0,0,0,0,0,0,0,0,0
0,0,0,0,0,0,138,156,0,0,0,156,203,0,0,0,0,0,4,4,4,4,4,4,4,0,0,0,0,0,0,0,0
0,0,0,0,0,138,156,0,0,0,0,0,156,203,0,0,110,4,4,117,300,299,0,110,4,4,0,0,0,0,0,0,0
0,0,0,0,0,138,0,0,0,68,0,0,0,156,254,0,0,58,0,0,0,137,0,297,4,4,0,0,0,0,0,0,0
0,0,0,0,0,138,0,0,288,22,0,0,0,230,0,0,0,301,0,0,288,22,117,298,4,4,0,0,0,0,0,0,0
0,0,0,0,0,138,0,0,0,0,0,0,0,156,254,0,0,58,0,0,0,115,0,0,4,4,0,0,0,0,0,0,0
0,0,0,0,0,138,156,0,0,0,0,0,156,203,0,0,110,4,4,117,0,0,0,110,4,4,0,0,0,0,0,0,0
0,0,0,0,0,0,138,156,129,156,129,156,203,0,0,0,0,110,4,4,4,4,4,4,4,0,0,0,0,0,0,0,0
0,0,0,0,0,0,0,205,0,205,0,205,0,0,0,0,0,0,0,4,4,234,4,4,115,0,0,0,0,0,0,0,0
0,0,0,0,0,0,0,0,0,0,0,0,0,0,0,0,0,0,0,0,115,0,115,0,0,0,0,0,0,0,0,0,0
0,0,0,0,0,0,0,0,0,0,0,0,0,0,0,0,0,0,0,0,0,0,0,0,0,0,0,0,0,0,0,0,0
0,0,0,0,0,0,0,0,0,0,0,0,0,0,0,0,0,0,0,0,0,0,0,0,0,0,0,0,0,0,0,0,0
0,0,0,0,0,0,0,0,0,0,0,0,0,0,0,0,0,0,0,0,0,0,0,0,0,0,0,0,0,0,0,0,0
0,0,0,0,0,0,0,0,0,0,0,0,0,0,0,0,0,0,0,0,0,0,0,0,0,0,0,0,0,0,0,0,0
0,0,0,0,0,0,0,0,0,0,0,0,0,0,0,0,0,0,0,0,0,0,0,0,0,0,0,0,0,0,0,0,0
0,0,0,0,0,0,0,0,0,0,0,0,0,0,0,0,0,0,0,0,0,0,0,0,0,0,0,0,0,0,0,0,0
0,0,0,0,0,0,0,0,0,0,0,0,0,0,0,0,0,0,0,0,0,0,0,0,0,0,0,0,0,0,0,0,0
0,0,0,0,0,0,0,0,0,0,0,0,0,0,0,0,0,0,0,0,0,0,0,0,0,0,0,0,0,0,0,0,0
0,0,0,0,0,0,0,0,0,0,0,0,0,0,0,0,0,0,0,0,0,0,0,0,0,0,0,0,0,0,0,0,0
0,0,0,0,0,0,0,0,0,0,0,0,0,0,0,0,0,0,0,0,0,0,0,0,0,0,0,0,0,0,0,0,0
0,0,0,0,0,0,0,0,0,0,0,0,0,0,0,0,0,0,0,0,0,0,0,0,0,0,0,0,0,0,0,0,0
0,0,0,0,0,0,0,0,0,0,0,0,0,0,0,0,0,0,0,0,0,0,0,0,0,0,0,0,0,0,0,0,0
0,0,0,0,0,0,0,0,0,0,0,0,0,0,0,0,0,0,0,0,0,0,0,0,0,0,0,0,0,0,0,0,0
0,0,0,0,0,0,0,0,0,0,0,0,0,0,0,0,0,0,0,0,0,0,0,0,0,0,0,0,0,0,0,0,0
0,0,0,0,0,0,0,0,0,0,0,0,0,0,0,0,0,0,0,0,0,0,0,0,0,0,0,0,0,0,0,0,0
0,0,0,0,0,0,0,0,0,0,0,0,0,0,0,0,0,0,0,0,0,0,0,0,0,0,0,0,0,0,0,0,0
0,0,0,0,0,0,0,0,0,0,0,0,0,0,0,0,0,0,0,0,0,0,0,0,0,0,0,0,0,0,0,0,0
:endlayer
layer: 29
0,0,0,0,0,0,0,0,0,0,0,0,0,0,0,0,0,0,0,0,0,0,0,0,0,0,0,0,0,0,0,0,0
0,0,0,0,0,0,0,0,0,0,0,0,0,0,0,0,0,0,0,0,0,0,0,0,0,0,0,0,0,0,0,0,0
0,0,0,0,0,0,0,0,0,0,0,0,0,0,0,0,0,0,0,0,0,0,0,0,0,0,0,0,0,0,0,0,0
0,0,0,0,0,0,0,0,0,0,0,0,0,0,0,0,0,0,0,0,0,0,0,0,0,0,0,0,0,0,0,0,0
0,0,0,0,0,0,0,0,0,0,0,0,0,0,0,0,0,0,0,0,0,0,0,0,0,0,0,0,0,0,0,0,0
0,0,0,0,0,0,0,0,0,0,0,0,0,0,0,0,0,0,0,0,0,0,0,0,0,0,0,0,0,0,0,0,0
0,0,0,0,0,0,0,0,0,0,0,0,0,0,0,0,0,0,0,0,0,0,0,0,0,0,0,0,0,0,0,0,0
0,0,0,0,0,0,0,0,0,0,0,0,0,0,0,0,0,0,0,0,0,0,0,0,0,0,0,0,0,0,0,0,0
0,0,0,0,0,0,0,0,0,0,0,0,0,0,0,0,0,0,0,0,0,0,0,0,0,0,0,0,0,0,0,0,0
0,0,0,0,0,0,0,0,0,0,0,0,0,0,0,0,0,0,0,188,241,188,241,188,0,0,0,0,0,0,0,0,0
0,0,0,0,0,0,0,188,188,188,188,188,0,0,0,0,0,0,188,4,4,4,4,4,188,0,0,0,0,0,0,0,0
0,0,0,0,0,0,202,156,0,0,110,156,197,0,0,0,0,202,4,4,4,4,4,4,4,197,0,0,0,0,0,0,0
0,0,0,0,0,202,156,117,0,0,0,115,156,197,0,0,202,4,4,0,0,0,0,0,4,4,197,0,0,0,0,0,0
0,0,0,0,0,202,115,0,0,0,0,0,0,156,0,0,241,4,0,0,0,0,0,0,4,4,241,0,0,0,0,0,0
0,0,0,0,0,202,0,0,288,22,117,0,0,197,0,0,302,4,0,0,288,22,0,0,4,4,197,0,0,0,0,0,0
0,0,0,0,0,202,137,0,0,115,0,0,137,156,0,0,241,4,0,0,0,0,0,0,4,4,241,0,0,0,0,0,0
0,0,0,0,0,202,156,117,0,0,0,110,156,197,0,0,202,4,4,0,0,0,0,0,4,4,197,0,0,0,0,0,0
0,0,0,0,0,0,202,156,129,156,129,156,197,0,0,0,0,202,4,4,4,4,4,4,4,197,0,0,0,0,0,0,0
0,0,0,0,0,0,0,234,0,234,0,234,0,0,0,0,0,0,234,4,4,4,4,4,234,0,0,0,0,0,0,0,0
0,0,0,0,0,0,0,0,0,0,0,0,0,0,0,0,0,0,0,234,241,234,241,234,0,0,0,0,0,0,0,0,0
0,0,0,0,0,0,0,0,0,0,0,0,0,0,0,0,0,0,0,0,0,0,0,0,0,0,0,0,0,0,0,0,0
0,0,0,0,0,0,0,0,0,0,0,0,0,0,0,0,0,0,0,0,0,0,0,0,0,0,0,0,0,0,0,0,0
0,0,0,0,0,0,0,0,0,0,0,0,0,0,0,0,0,0,0,0,0,0,0,0,0,0,0,0,0,0,0,0,0
0,0,0,0,0,0,0,0,0,0,0,0,0,0,0,0,0,0,0,0,0,0,0,0,0,0,0,0,0,0,0,0,0
0,0,0,0,0,0,0,0,0,0,0,0,0,0,0,0,0,0,0,0,0,0,0,0,0,0,0,0,0,0,0,0,0
0,0,0,0,0,0,0,0,0,0,0,0,0,0,0,0,0,0,0,0,0,0,0,0,0,0,0,0,0,0,0,0,0
0,0,0,0,0,0,0,0,0,0,0,0,0,0,0,0,0,0,0,0,0,0,0,0,0,0,0,0,0,0,0,0,0
0,0,0,0,0,0,0,0,0,0,0,0,0,0,0,0,0,0,0,0,0,0,0,0,0,0,0,0,0,0,0,0,0
0,0,0,0,0,0,0,0,0,0,0,0,0,0,0,0,0,0,0,0,0,0,0,0,0,0,0,0,0,0,0,0,0
0,0,0,0,0,0,0,0,0,0,0,0,0,0,0,0,0,0,0,0,0,0,0,0,0,0,0,0,0,0,0,0,0
0,0,0,0,0,0,0,0,0,0,0,0,0,0,0,0,0,0,0,0,0,0,0,0,0,0,0,0,0,0,0,0,0
0,0,0,0,0,0,0,0,0,0,0,0,0,0,0,0,0,0,0,0,0,0,0,0,0,0,0,0,0,0,0,0,0
0,0,0,0,0,0,0,0,0,0,0,0,0,0,0,0,0,0,0,0,0,0,0,0,0,0,0,0,0,0,0,0,0
0,0,0,0,0,0,0,0,0,0,0,0,0,0,0,0,0,0,0,0,0,0,0,0,0,0,0,0,0,0,0,0,0
0,0,0,0,0,0,0,0,0,0,0,0,0,0,0,0,0,0,0,0,0,0,0,0,0,0,0,0,0,0,0,0,0
0,0,0,0,0,0,0,0,0,0,0,0,0,0,0,0,0,0,0,0,0,0,0,0,0,0,0,0,0,0,0,0,0
0,0,0,0,0,0,0,0,0,0,0,0,0,0,0,0,0,0,0,0,0,0,0,0,0,0,0,0,0,0,0,0,0
:endlayer
layer: 30
0,0,0,0,0,0,0,0,0,0,0,0,0,0,0,0,0,0,0,0,0,0,0,0,0,0,0,0,0,0,0,0,0
0,0,0,0,0,0,0,0,0,0,0,0,0,0,0,0,0,0,0,0,0,0,0,0,0,0,0,0,0,0,0,0,0
0,0,0,0,0,0,0,0,0,0,0,0,0,0,0,0,0,0,0,0,0,0,0,0,0,0,0,0,0,0,0,0,0
0,0,0,0,0,0,0,0,0,0,0,0,0,0,0,0,0,0,0,0,0,0,0,0,0,0,0,0,0,0,0,0,0
0,0,0,0,0,0,0,0,0,0,0,0,0,0,0,0,0,0,0,0,0,0,0,0,0,0,0,0,0,0,0,0,0
0,0,0,0,0,0,0,0,0,0,0,0,0,0,0,0,0,0,0,0,0,0,0,0,0,0,0,0,0,0,0,0,0
0,0,0,0,0,0,0,0,0,0,0,0,0,0,0,0,0,0,0,0,0,0,0,0,0,0,0,0,0,0,0,0,0
0,0,0,0,0,0,0,0,0,0,0,0,0,0,0,0,0,0,0,0,0,0,0,0,0,0,0,0,0,0,0,0,0
0,0,0,0,0,0,0,0,0,0,0,0,0,0,0,0,0,0,0,0,0,0,0,0,0,0,0,0,0,0,0,0,0
0,0,0,0,0,0,0,0,0,0,0,0,0,0,0,0,0,0,0,4,208,4,208,4,0,0,0,0,0,0,0,0,0
0,0,0,0,0,0,0,4,4,4,4,4,0,0,0,0,0,0,4,198,198,198,198,198,4,0,0,0,0,0,0,0,0
0,0,0,0,0,0,4,4,0,0,0,4,4,0,0,0,0,4,198,198,198,198,198,198,198,4,0,0,0,0,0,0,0
0,0,0,0,0,4,4,0,0,0,0,0,4,4,0,0,4,198,198,198,198,198,198,198,198,198,4,0,0,0,0,0,0
0,0,0,0,0,4,0,0,0,0,0,0,0,4,0,0,232,198,198,198,198,198,198,198,198,198,122,0,0,0,0,0,0
0,0,0,0,0,4,0,0,288,22,0,0,110,4,117,110,4,198,198,198,288,213,198,198,198,198,4,0,0,0,0,0,0
0,0,0,0,0,4,0,0,0,0,0,0,0,4,0,0,232,198,198,198,198,198,198,198,198,198,122,0,0,0,0,0,0
0,0,0,0,0,4,4,0,0,0,0,0,4,4,0,0,4,198,198,198,198,198,198,198,198,198,4,0,0,0,0,0,0
0,0,0,0,0,0,4,4,4,4,4,4,4,0,0,0,0,4,198,198,198,198,198,198,198,4,0,0,0,0,0,0,0
0,0,0,0,0,0,0,4,234,156,234,156,0,0,0,0,0,0,4,198,198,198,198,198,4,0,0,0,0,0,0,0,0
0,0,0,0,0,0,0,0,0,0,0,0,0,0,0,0,0,0,0,4,265,4,265,4,0,0,0,0,0,0,0,0,0
0,0,0,0,0,0,0,0,0,0,0,0,0,0,0,0,0,0,0,0,0,0,0,0,0,0,0,0,0,0,0,0,0
0,0,0,0,0,0,0,0,0,0,0,0,0,0,0,0,0,0,0,0,0,0,0,0,0,0,0,0,0,0,0,0,0
0,0,0,0,0,0,0,0,0,0,0,0,0,0,0,0,0,0,0,0,0,0,0,0,0,0,0,0,0,0,0,0,0
0,0,0,0,0,0,0,0,0,0,0,0,0,0,0,0,0,0,0,0,0,0,0,0,0,0,0,0,0,0,0,0,0
0,0,0,0,0,0,0,0,0,0,0,0,0,0,0,0,0,0,0,0,0,0,0,0,0,0,0,0,0,0,0,0,0
0,0,0,0,0,0,0,0,0,0,0,0,0,0,0,0,0,0,0,0,0,0,0,0,0,0,0,0,0,0,0,0,0
0,0,0,0,0,0,0,0,0,0,0,0,0,0,0,0,0,0,0,0,0,0,0,0,0,0,0,0,0,0,0,0,0
0,0,0,0,0,0,0,0,0,0,0,0,0,0,0,0,0,0,0,0,0,0,0,0,0,0,0,0,0,0,0,0,0
0,0,0,0,0,0,0,0,0,0,0,0,0,0,0,0,0,0,0,0,0,0,0,0,0,0,0,0,0,0,0,0,0
0,0,0,0,0,0,0,0,0,0,0,0,0,0,0,0,0,0,0,0,0,0,0,0,0,0,0,0,0,0,0,0,0
0,0,0,0,0,0,0,0,0,0,0,0,0,0,0,0,0,0,0,0,0,0,0,0,0,0,0,0,0,0,0,0,0
0,0,0,0,0,0,0,0,0,0,0,0,0,0,0,0,0,0,0,0,0,0,0,0,0,0,0,0,0,0,0,0,0
0,0,0,0,0,0,0,0,0,0,0,0,0,0,0,0,0,0,0,0,0,0,0,0,0,0,0,0,0,0,0,0,0
0,0,0,0,0,0,0,0,0,0,0,0,0,0,0,0,0,0,0,0,0,0,0,0,0,0,0,0,0,0,0,0,0
0,0,0,0,0,0,0,0,0,0,0,0,0,0,0,0,0,0,0,0,0,0,0,0,0,0,0,0,0,0,0,0,0
0,0,0,0,0,0,0,0,0,0,0,0,0,0,0,0,0,0,0,0,0,0,0,0,0,0,0,0,0,0,0,0,0
0,0,0,0,0,0,0,0,0,0,0,0,0,0,0,0,0,0,0,0,0,0,0,0,0,0,0,0,0,0,0,0,0
:endlayer
layer: 31
0,0,0,0,0,0,0,0,0,0,0,0,0,0,0,0,0,0,0,0,0,0,0,0,0,0,0,0,0,0,0,0,0
0,0,0,0,0,0,0,0,0,0,0,0,0,0,0,0,0,0,0,0,0,0,0,0,0,0,0,0,0,0,0,0,0
0,0,0,0,0,0,0,0,0,0,0,0,0,0,0,0,0,0,0,0,0,0,0,0,0,0,0,0,0,0,0,0,0
0,0,0,0,0,0,0,0,0,0,0,0,0,0,0,0,0,0,0,0,0,0,0,0,0,0,0,0,0,0,0,0,0
0,0,0,0,0,0,0,0,0,0,0,0,0,0,0,0,0,0,0,0,0,0,0,0,0,0,0,0,0,0,0,0,0
0,0,0,0,0,0,0,0,0,0,0,0,0,0,0,0,0,0,0,0,0,0,0,0,0,0,0,0,0,0,0,0,0
0,0,0,0,0,0,0,0,0,0,0,0,0,0,0,0,0,0,0,0,0,0,0,0,0,0,0,0,0,0,0,0,0
0,0,0,0,0,0,0,0,0,0,0,0,0,0,0,0,0,0,0,0,0,0,0,0,0,0,0,0,0,0,0,0,0
0,0,0,0,0,0,0,0,0,0,0,0,0,0,0,0,0,0,0,0,0,0,0,0,0,0,0,0,0,0,0,0,0
0,0,0,0,0,0,0,0,0,0,0,0,0,0,0,0,0,0,0,4,58,4,58,4,0,0,0,0,0,0,0,0,0
0,0,0,0,0,0,0,4,4,4,4,4,0,0,0,0,0,0,305,0,0,0,0,0,4,0,0,0,0,0,0,0,0
0,0,0,0,0,0,4,4,0,0,0,4,4,0,0,0,0,4,0,0,0,0,0,0,0,4,0,0,0,0,0,0,0
0,0,0,0,0,4,4,0,0,0,0,0,4,4,0,0,4,0,0,0,0,0,0,0,0,0,0,0,0,0,0,0,0
0,0,0,0,0,4,0,0,0,137,0,0,0,4,0,0,58,0,0,0,0,304,0,0,0,0,0,0,0,0,0,0,0
0,0,0,0,0,4,0,0,288,22,117,0,0,4,0,0,4,0,0,20,0,0,0,303,0,0,0,0,0,0,0,0,0
0,0,0,0,0,4,0,0,0,115,0,0,0,4,0,0,58,0,0,0,0,0,0,0,0,0,0,0,0,0,0,0,0
0,0,0,0,0,4,4,0,0,0,0,0,4,4,0,0,4,0,0,0,0,0,0,0,0,0,0,0,0,0,0,0,0
0,0,0,0,0,0,4,4,4,4,4,4,4,0,0,0,0,4,0,0,0,0,0,0,0,4,0,0,0,0,0,0,0
0,0,0,0,0,0,0,4,4,4,4,4,0,0,0,0,0,0,306,0,0,0,0,0,4,0,0,0,0,0,0,0,0
0,0,0,0,0,0,0,0,0,0,0,0,0,0,0,0,0,0,0,4,58,4,58,4,0,0,0,0,0,0,0,0,0
0,0,0,0,0,0,0,0,0,0,0,0,0,0,0,0,0,0,0,0,0,0,0,0,0,0,0,0,0,0,0,0,0
0,0,0,0,0,0,0,0,0,0,0,0,0,0,0,0,0,0,0,0,0,0,0,0,0,0,0,0,0,0,0,0,0
0,0,0,0,0,0,0,0,0,0,0,0,0,0,0,0,0,0,0,0,0,0,0,0,0,0,0,0,0,0,0,0,0
0,0,0,0,0,0,0,0,0,0,0,0,0,0,0,0,0,0,0,0,0,0,0,0,0,0,0,0,0,0,0,0,0
0,0,0,0,0,0,0,0,0,0,0,0,0,0,0,0,0,0,0,0,0,0,0,0,0,0,0,0,0,0,0,0,0
0,0,0,0,0,0,0,0,0,0,0,0,0,0,0,0,0,0,0,0,0,0,0,0,0,0,0,0,0,0,0,0,0
0,0,0,0,0,0,0,0,0,0,0,0,0,0,0,0,0,0,0,0,0,0,0,0,0,0,0,0,0,0,0,0,0
0,0,0,0,0,0,0,0,0,0,0,0,0,0,0,0,0,0,0,0,0,0,0,0,0,0,0,0,0,0,0,0,0
0,0,0,0,0,0,0,0,0,0,0,0,0,0,0,0,0,0,0,0,0,0,0,0,0,0,0,0,0,0,0,0,0
0,0,0,0,0,0,0,0,0,0,0,0,0,0,0,0,0,0,0,0,0,0,0,0,0,0,0,0,0,0,0,0,0
0,0,0,0,0,0,0,0,0,0,0,0,0,0,0,0,0,0,0,0,0,0,0,0,0,0,0,0,0,0,0,0,0
0,0,0,0,0,0,0,0,0,0,0,0,0,0,0,0,0,0,0,0,0,0,0,0,0,0,0,0,0,0,0,0,0
0,0,0,0,0,0,0,0,0,0,0,0,0,0,0,0,0,0,0,0,0,0,0,0,0,0,0,0,0,0,0,0,0
0,0,0,0,0,0,0,0,0,0,0,0,0,0,0,0,0,0,0,0,0,0,0,0,0,0,0,0,0,0,0,0,0
0,0,0,0,0,0,0,0,0,0,0,0,0,0,0,0,0,0,0,0,0,0,0,0,0,0,0,0,0,0,0,0,0
0,0,0,0,0,0,0,0,0,0,0,0,0,0,0,0,0,0,0,0,0,0,0,0,0,0,0,0,0,0,0,0,0
0,0,0,0,0,0,0,0,0,0,0,0,0,0,0,0,0,0,0,0,0,0,0,0,0,0,0,0,0,0,0,0,0
:endlayer
layer: 32
0,0,0,0,0,0,0,0,0,0,0,0,0,0,0,0,0,0,0,0,0,0,0,0,0,0,0,0,0,0,0,0,0
0,0,0,0,0,0,0,0,0,0,0,0,0,0,0,0,0,0,0,0,0,0,0,0,0,0,0,0,0,0,0,0,0
0,0,0,0,0,0,0,0,0,0,0,0,0,0,0,0,0,0,0,0,0,0,0,0,0,0,0,0,0,0,0,0,0
0,0,0,0,0,0,0,0,0,0,0,0,0,0,0,0,0,0,0,0,0,0,0,0,0,0,0,0,0,0,0,0,0
0,0,0,0,0,0,0,0,0,0,0,0,0,0,0,0,0,0,0,0,0,0,0,0,0,0,0,0,0,0,0,0,0
0,0,0,0,0,0,0,0,0,0,0,0,0,0,0,0,0,0,0,0,0,0,0,0,0,0,0,0,0,0,0,0,0
0,0,0,0,0,0,0,0,0,0,0,0,0,0,0,0,0,0,0,0,0,0,0,0,0,0,0,0,0,0,0,0,0
0,0,0,0,0,0,0,0,0,0,0,0,0,0,0,0,0,0,0,0,0,0,0,0,0,0,0,0,0,0,0,0,0
0,0,0,0,0,0,0,0,0,0,0,0,0,0,0,0,0,0,0,0,0,0,0,0,0,0,0,0,0,0,0,0,0
0,0,0,0,0,0,0,188,0,188,0,188,0,0,0,0,0,0,0,0,0,254,0,0,0,0,0,0,0,0,0,0,0
0,0,0,0,0,0,188,4,4,4,4,4,188,0,0,0,0,0,0,0,0,0,0,0,0,0,0,0,0,0,0,0,0
0,0,0,0,0,202,4,4,0,0,0,4,4,197,0,0,0,0,0,0,0,0,0,0,0,307,0,0,0,0,0,0,0
0,0,0,0,202,4,4,0,0,0,0,0,4,4,197,0,0,0,0,0,0,0,0,0,0,0,0,0,0,0,0,0,0
0,0,0,0,0,4,0,0,0,0,0,0,0,4,0,0,0,0,0,0,0,0,0,0,0,0,0,0,0,0,0,0,0
0,0,0,0,202,4,0,0,288,22,0,0,0,4,197,0,254,0,0,124,0,0,0,0,0,0,0,0,0,0,0,0,0
0,0,0,0,0,4,0,0,0,0,0,0,0,4,0,0,0,0,0,0,0,0,0,0,0,0,0,0,0,0,0,0,0
0,0,0,0,202,4,4,0,0,0,0,0,4,4,197,0,0,0,0,0,0,0,0,0,0,0,0,0,0,0,0,0,0
0,0,0,0,0,202,4,4,4,4,4,4,4,197,0,0,0,0,0,0,0,0,0,0,0,0,0,0,0,0,0,0,0
0,0,0,0,0,0,234,4,4,4,4,4,234,0,0,0,0,0,0,0,0,0,0,0,308,0,0,0,0,0,0,0,0
0,0,0,0,0,0,0,234,0,234,0,234,0,0,0,0,0,0,0,0,0,254,0,0,0,0,0,0,0,0,0,0,0
0,0,0,0,0,0,0,0,0,0,0,0,0,0,0,0,0,0,0,0,0,0,0,0,0,0,0,0,0,0,0,0,0
0,0,0,0,0,0,0,0,0,0,0,0,0,0,0,0,0,0,0,0,0,0,0,0,0,0,0,0,0,0,0,0,0
0,0,0,0,0,0,0,0,0,0,0,0,0,0,0,0,0,0,0,0,0,0,0,0,0,0,0,0,0,0,0,0,0
0,0,0,0,0,0,0,0,0,0,0,0,0,0,0,0,0,0,0,0,0,0,0,0,0,0,0,0,0,0,0,0,0
0,0,0,0,0,0,0,0,0,0,0,0,0,0,0,0,0,0,0,0,0,0,0,0,0,0,0,0,0,0,0,0,0
0,0,0,0,0,0,0,0,0,0,0,0,0,0,0,0,0,0,0,0,0,0,0,0,0,0,0,0,0,0,0,0,0
0,0,0,0,0,0,0,0,0,0,0,0,0,0,0,0,0,0,0,0,0,0,0,0,0,0,0,0,0,0,0,0,0
0,0,0,0,0,0,0,0,0,0,0,0,0,0,0,0,0,0,0,0,0,0,0,0,0,0,0,0,0,0,0,0,0
0,0,0,0,0,0,0,0,0,0,0,0,0,0,0,0,0,0,0,0,0,0,0,0,0,0,0,0,0,0,0,0,0
0,0,0,0,0,0,0,0,0,0,0,0,0,0,0,0,0,0,0,0,0,0,0,0,0,0,0,0,0,0,0,0,0
0,0,0,0,0,0,0,0,0,0,0,0,0,0,0,0,0,0,0,0,0,0,0,0,0,0,0,0,0,0,0,0,0
0,0,0,0,0,0,0,0,0,0,0,0,0,0,0,0,0,0,0,0,0,0,0,0,0,0,0,0,0,0,0,0,0
0,0,0,0,0,0,0,0,0,0,0,0,0,0,0,0,0,0,0,0,0,0,0,0,0,0,0,0,0,0,0,0,0
0,0,0,0,0,0,0,0,0,0,0,0,0,0,0,0,0,0,0,0,0,0,0,0,0,0,0,0,0,0,0,0,0
0,0,0,0,0,0,0,0,0,0,0,0,0,0,0,0,0,0,0,0,0,0,0,0,0,0,0,0,0,0,0,0,0
0,0,0,0,0,0,0,0,0,0,0,0,0,0,0,0,0,0,0,0,0,0,0,0,0,0,0,0,0,0,0,0,0
0,0,0,0,0,0,0,0,0,0,0,0,0,0,0,0,0,0,0,0,0,0,0,0,0,0,0,0,0,0,0,0,0
:endlayer
layer: 33
0,0,0,0,0,0,0,0,0,0,0,0,0,0,0,0,0,0,0,0,0,0,0,0,0,0,0,0,0,0,0,0,0
0,0,0,0,0,0,0,0,0,0,0,0,0,0,0,0,0,0,0,0,0,0,0,0,0,0,0,0,0,0,0,0,0
0,0,0,0,0,0,0,0,0,0,0,0,0,0,0,0,0,0,0,0,0,0,0,0,0,0,0,0,0,0,0,0,0
0,0,0,0,0,0,0,0,0,0,0,0,0,0,0,0,0,0,0,0,0,0,0,0,0,0,0,0,0,0,0,0,0
0,0,0,0,0,0,0,0,0,0,0,0,0,0,0,0,0,0,0,0,0,0,0,0,0,0,0,0,0,0,0,0,0
0,0,0,0,0,0,0,0,0,0,0,0,0,0,0,0,0,0,0,0,0,0,0,0,0,0,0,0,0,0,0,0,0
0,0,0,0,0,0,0,0,0,0,0,0,0,0,0,0,0,0,0,0,0,0,0,0,0,0,0,0,0,0,0,0,0
0,0,0,0,0,0,0,0,0,0,0,0,0,0,0,0,0,0,0,0,0,0,0,0,0,0,0,0,0,0,0,0,0
0,0,0,0,0,0,0,188,241,188,241,188,0,0,0,0,0,0,0,0,0,0,0,0,0,0,0,0,0,0,0,0,0
0,0,0,0,0,0,188,4,208,4,208,4,188,0,0,0,0,0,0,0,0,0,0,0,0,0,0,0,0,0,0,0,0
0,0,0,0,0,188,4,198,198,198,198,198,4,197,0,0,0,0,0,0,0,0,0,0,0,0,0,0,0,0,0,0,0
0,0,0,0,202,4,198,198,198,198,198,198,198,4,197,0,0,0,0,0,0,0,0,0,0,0,0,0,0,0,0,0,0
0,0,0,202,4,198,198,198,198,198,198,198,198,198,4,197,0,0,0,0,0,0,0,0,0,0,0,0,0,0,0,0,0
0,0,0,241,232,198,198,198,198,198,198,198,198,198,4,241,0,0,0,0,0,0,0,0,0,0,0,0,0,0,0,0,0
0,0,0,202,4,198,198,198,288,198,198,198,198,198,4,197,0,0,0,0,0,0,0,0,0,0,0,0,0,0,0,0,0
0,0,0,241,232,198,198,198,198,198,198,198,198,198,4,241,0,0,0,0,0,0,0,0,0,0,0,0,0,0,0,0,0
0,0,0,202,4,198,198,198,198,198,198,198,198,198,4,197,0,0,0,0,0,0,0,0,0,0,0,0,0,0,0,0,0
0,0,0,0,202,4,198,198,198,198,198,198,198,4,197,0,0,0,0,0,0,0,0,0,0,0,0,0,0,0,0,0,0
0,0,0,0,0,234,4,198,198,198,198,198,4,234,0,0,0,0,0,0,0,0,0,0,0,0,0,0,0,0,0,0,0
0,0,0,0,0,0,234,4,4,4,4,4,234,0,0,0,0,0,0,0,0,0,0,0,0,0,0,0,0,0,0,0,0
0,0,0,0,0,0,0,234,241,234,241,234,0,0,0,0,0,0,0,0,0,0,0,0,0,0,0,0,0,0,0,0,0
0,0,0,0,0,0,0,0,0,0,0,0,0,0,0,0,0,0,0,0,0,0,0,0,0,0,0,0,0,0,0,0,0
0,0,0,0,0,0,0,0,0,0,0,0,0,0,0,0,0,0,0,0,0,0,0,0,0,0,0,0,0,0,0,0,0
0,0,0,0,0,0,0,0,0,0,0,0,0,0,0,0,0,0,0,0,0,0,0,0,0,0,0,0,0,0,0,0,0
0,0,0,0,0,0,0,0,0,0,0,0,0,0,0,0,0,0,0,0,0,0,0,0,0,0,0,0,0,0,0,0,0
0,0,0,0,0,0,0,0,0,0,0,0,0,0,0,0,0,0,0,0,0,0,0,0,0,0,0,0,0,0,0,0,0
0,0,0,0,0,0,0,0,0,0,0,0,0,0,0,0,0,0,0,0,0,0,0,0,0,0,0,0,0,0,0,0,0
0,0,0,0,0,0,0,0,0,0,0,0,0,0,0,0,0,0,0,0,0,0,0,0,0,0,0,0,0,0,0,0,0
0,0,0,0,0,0,0,0,0,0,0,0,0,0,0,0,0,0,0,0,0,0,0,0,0,0,0,0,0,0,0,0,0
0,0,0,0,0,0,0,0,0,0,0,0,0,0,0,0,0,0,0,0,0,0,0,0,0,0,0,0,0,0,0,0,0
0,0,0,0,0,0,0,0,0,0,0,0,0,0,0,0,0,0,0,0,0,0,0,0,0,0,0,0,0,0,0,0,0
0,0,0,0,0,0,0,0,0,0,0,0,0,0,0,0,0,0,0,0,0,0,0,0,0,0,0,0,0,0,0,0,0
0,0,0,0,0,0,0,0,0,0,0,0,0,0,0,0,0,0,0,0,0,0,0,0,0,0,0,0,0,0,0,0,0
0,0,0,0,0,0,0,0,0,0,0,0,0,0,0,0,0,0,0,0,0,0,0,0,0,0,0,0,0,0,0,0,0
0,0,0,0,0,0,0,0,0,0,0,0,0,0,0,0,0,0,0,0,0,0,0,0,0,0,0,0,0,0,0,0,0
0,0,0,0,0,0,0,0,0,0,0,0,0,0,0,0,0,0,0,0,0,0,0,0,0,0,0,0,0,0,0,0,0
0,0,0,0,0,0,0,0,0,0,0,0,0,0,0,0,0,0,0,0,0,0,0,0,0,0,0,0,0,0,0,0,0
:endlayer
layer: 34
0,0,0,0,0,0,0,0,0,0,0,0,0,0,0,0,0,0,0,0,0,0,0,0,0,0,0,0,0,0,0,0,0
0,0,0,0,0,0,0,0,0,0,0,0,0,0,0,0,0,0,0,0,0,0,0,0,0,0,0,0,0,0,0,0,0
0,0,0,0,0,0,0,0,0,0,0,0,0,0,0,0,0,0,0,0,0,0,0,0,0,0,0,0,0,0,0,0,0
0,0,0,0,0,0,0,0,0,0,0,0,0,0,0,0,0,0,0,0,0,0,0,0,0,0,0,0,0,0,0,0,0
0,0,0,0,0,0,0,0,0,0,0,0,0,0,0,0,0,0,0,0,0,0,0,0,0,0,0,0,0,0,0,0,0
0,0,0,0,0,0,0,0,0,0,0,0,0,0,0,0,0,0,0,0,0,0,0,0,0,0,0,0,0,0,0,0,0
0,0,0,0,0,0,0,0,0,0,0,0,0,0,0,0,0,0,0,0,0,0,0,0,0,0,0,0,0,0,0,0,0
0,0,0,0,0,0,0,0,0,0,0,0,0,0,0,0,0,0,0,0,0,0,0,0,0,0,0,0,0,0,0,0,0
0,0,0,0,0,0,0,156,208,4,208,156,0,0,0,0,0,0,0,0,0,0,0,0,0,0,0,0,0,0,0,0,0
0,0,0,0,0,0,156,198,198,198,198,198,156,0,0,0,0,0,0,0,0,0,0,0,0,0,0,0,0,0,0,0,0
0,0,0,0,0,156,198,198,198,198,198,198,198,156,0,0,0,0,0,0,0,0,0,0,0,0,0,0,0,0,0,0,0
0,0,0,0,156,198,198,198,198,198,198,198,198,198,156,0,0,0,0,0,0,0,0,0,0,0,0,0,0,0,0,0,0
0,0,0,156,198,198,198,198,198,198,198,198,198,198,198,156,0,0,0,0,0,0,0,0,0,0,0,0,0,0,0,0,0
0,0,0,232,198,198,198,198,198,198,198,198,198,198,198,122,0,0,0,0,0,0,0,0,0,0,0,0,0,0,0,0,0
0,0,0,156,198,198,198,198,288,198,198,198,198,198,198,156,0,0,0,0,0,0,0,0,0,0,0,0,0,0,0,0,0
0,0,0,232,198,198,198,198,213,198,198,198,198,198,198,122,0,0,0,0,0,0,0,0,0,0,0,0,0,0,0,0,0
0,0,0,156,198,198,198,198,198,198,198,198,198,198,198,156,0,0,0,0,0,0,0,0,0,0,0,0,0,0,0,0,0
0,0,0,0,156,198,198,198,198,198,198,198,198,198,156,0,0,0,0,0,0,0,0,0,0,0,0,0,0,0,0,0,0
0,0,0,0,0,156,198,198,198,198,198,198,198,156,0,0,0,0,0,0,0,0,0,0,0,0,0,0,0,0,0,0,0
0,0,0,0,0,0,156,198,198,198,198,198,156,0,0,0,0,0,0,0,0,0,0,0,0,0,0,0,0,0,0,0,0
0,0,0,0,0,0,0,156,265,156,265,156,0,0,0,0,0,0,0,0,0,0,0,0,0,0,0,0,0,0,0,0,0
0,0,0,0,0,0,0,0,0,0,0,0,0,0,0,0,0,0,0,0,0,0,0,0,0,0,0,0,0,0,0,0,0
0,0,0,0,0,0,0,0,0,0,0,0,0,0,0,0,0,0,0,0,0,0,0,0,0,0,0,0,0,0,0,0,0
0,0,0,0,0,0,0,0,0,0,0,0,0,0,0,0,0,0,0,0,0,0,0,0,0,0,0,0,0,0,0,0,0
0,0,0,0,0,0,0,0,0,0,0,0,0,0,0,0,0,0,0,0,0,0,0,0,0,0,0,0,0,0,0,0,0
0,0,0,0,0,0,0,0,0,0,0,0,0,0,0,0,0,0,0,0,0,0,0,0,0,0,0,0,0,0,0,0,0
0,0,0,0,0,0,0,0,0,0,0,0,0,0,0,0,0,0,0,0,0,0,0,0,0,0,0,0,0,0,0,0,0
0,0,0,0,0,0,0,0,0,0,0,0,0,0,0,0,0,0,0,0,0,0,0,0,0,0,0,0,0,0,0,0,0
0,0,0,0,0,0,0,0,0,0,0,0,0,0,0,0,0,0,0,0,0,0,0,0,0,0,0,0,0,0,0,0,0
0,0,0,0,0,0,0,0,0,0,0,0,0,0,0,0,0,0,0,0,0,0,0,0,0,0,0,0,0,0,0,0,0
0,0,0,0,0,0,0,0,0,0,0,0,0,0,0,0,0,0,0,0,0,0,0,0,0,0,0,0,0,0,0,0,0
0,0,0,0,0,0,0,0,0,0,0,0,0,0,0,0,0,0,0,0,0,0,0,0,0,0,0,0,0,0,0,0,0
0,0,0,0,0,0,0,0,0,0,0,0,0,0,0,0,0,0,0,0,0,0,0,0,0,0,0,0,0,0,0,0,0
0,0,0,0,0,0,0,0,0,0,0,0,0,0,0,0,0,0,0,0,0,0,0,0,0,0,0,0,0,0,0,0,0
0,0,0,0,0,0,0,0,0,0,0,0,0,0,0,0,0,0,0,0,0,0,0,0,0,0,0,0,0,0,0,0,0
0,0,0,0,0,0,0,0,0,0,0,0,0,0,0,0,0,0,0,0,0,0,0,0,0,0,0,0,0,0,0,0,0
0,0,0,0,0,0,0,0,0,0,0,0,0,0,0,0,0,0,0,0,0,0,0,0,0,0,0,0,0,0,0,0,0
:endlayer
layer: 35
0,0,0,0,0,0,0,0,0,0,0,0,0,0,0,0,0,0,0,0,0,0,0,0,0,0,0,0,0,0,0,0,0
0,0,0,0,0,0,0,0,0,0,0,0,0,0,0,0,0,0,0,0,0,0,0,0,0,0,0,0,0,0,0,0,0
0,0,0,0,0,0,0,0,0,0,0,0,0,0,0,0,0,0,0,0,0,0,0,0,0,0,0,0,0,0,0,0,0
0,0,0,0,0,0,0,0,0,0,0,0,0,0,0,0,0,0,0,0,0,0,0,0,0,0,0,0,0,0,0,0,0
0,0,0,0,0,0,0,0,0,0,0,0,0,0,0,0,0,0,0,0,0,0,0,0,0,0,0,0,0,0,0,0,0
0,0,0,0,0,0,0,0,0,0,0,0,0,0,0,0,0,0,0,0,0,0,0,0,0,0,0,0,0,0,0,0,0
0,0,0,0,0,0,0,0,0,0,0,0,0,0,0,0,0,0,0,0,0,0,0,0,0,0,0,0,0,0,0,0,0
0,0,0,0,0,0,0,0,0,0,0,0,0,0,0,0,0,0,0,0,0,0,0,0,0,0,0,0,0,0,0,0,0
0,0,0,0,0,0,0,156,58,156,58,156,0,0,0,0,0,0,0,0,0,0,0,0,0,0,0,0,0,0,0,0,0
0,0,0,0,0,0,156,0,0,0,0,0,156,0,0,0,0,0,0,0,0,0,0,0,0,0,0,0,0,0,0,0,0
0,0,0,0,0,156,0,0,0,0,0,0,0,156,0,0,0,0,0,0,0,0,0,0,0,0,0,0,0,0,0,0,0
0,0,0,0,156,0,0,0,0,0,0,0,0,0,156,0,0,0,0,0,0,0,0,0,0,0,0,0,0,0,0,0,0
0,0,0,0,0,0,0,213,0,0,0,0,0,0,0,156,0,0,0,0,0,0,0,0,0,0,0,0,0,0,0,0,0
0,0,0,0,0,0,0,0,0,0,0,309,0,0,0,58,0,0,0,0,0,0,0,0,0,0,0,0,0,0,0,0,0
0,0,0,0,0,310,0,198,0,0,0,0,0,0,0,156,0,0,0,0,0,0,0,0,0,0,0,0,0,0,0,0,0
0,0,0,0,0,0,0,0,0,0,0,0,0,0,0,58,0,0,0,0,0,0,0,0,0,0,0,0,0,0,0,0,0
0,0,0,0,0,0,0,0,0,0,0,0,0,0,0,156,0,0,0,0,0,0,0,0,0,0,0,0,0,0,0,0,0
0,0,0,0,156,0,0,0,0,0,0,0,0,0,156,0,0,0,0,0,0,0,0,0,0,0,0,0,0,0,0,0,0
0,0,0,0,0,156,0,0,0,0,0,0,0,156,0,0,0,0,0,0,0,0,0,0,0,0,0,0,0,0,0,0,0
0,0,0,0,0,0,156,0,0,0,0,0,156,0,0,0,0,0,0,0,0,0,0,0,0,0,0,0,0,0,0,0,0
0,0,0,0,0,0,0,156,58,156,58,156,0,0,0,0,0,0,0,0,0,0,0,0,0,0,0,0,0,0,0,0,0
0,0,0,0,0,0,0,0,0,0,0,0,0,0,0,0,0,0,0,0,0,0,0,0,0,0,0,0,0,0,0,0,0
0,0,0,0,0,0,0,0,0,0,0,0,0,0,0,0,0,0,0,0,0,0,0,0,0,0,0,0,0,0,0,0,0
0,0,0,0,0,0,0,0,0,0,0,0,0,0,0,0,0,0,0,0,0,0,0,0,0,0,0,0,0,0,0,0,0
0,0,0,0,0,0,0,0,0,0,0,0,0,0,0,0,0,0,0,0,0,0,0,0,0,0,0,0,0,0,0,0,0
0,0,0,0,0,0,0,0,0,0,0,0,0,0,0,0,0,0,0,0,0,0,0,0,0,0,0,0,0,0,0,0,0
0,0,0,0,0,0,0,0,0,0,0,0,0,0,0,0,0,0,0,0,0,0,0,0,0,0,0,0,0,0,0,0,0
0,0,0,0,0,0,0,0,0,0,0,0,0,0,0,0,0,0,0,0,0,0,0,0,0,0,0,0,0,0,0,0,0
0,0,0,0,0,0,0,0,0,0,0,0,0,0,0,0,0,0,0,0,0,0,0,0,0,0,0,0,0,0,0,0,0
0,0,0,0,0,0,0,0,0,0,0,0,0,0,0,0,0,0,0,0,0,0,0,0,0,0,0,0,0,0,0,0,0
0,0,0,0,0,0,0,0,0,0,0,0,0,0,0,0,0,0,0,0,0,0,0,0,0,0,0,0,0,0,0,0,0
0,0,0,0,0,0,0,0,0,0,0,0,0,0,0,0,0,0,0,0,0,0,0,0,0,0,0,0,0,0,0,0,0
0,0,0,0,0,0,0,0,0,0,0,0,0,0,0,0,0,0,0,0,0,0,0,0,0,0,0,0,0,0,0,0,0
0,0,0,0,0,0,0,0,0,0,0,0,0,0,0,0,0,0,0,0,0,0,0,0,0,0,0,0,0,0,0,0,0
0,0,0,0,0,0,0,0,0,0,0,0,0,0,0,0,0,0,0,0,0,0,0,0,0,0,0,0,0,0,0,0,0
0,0,0,0,0,0,0,0,0,0,0,0,0,0,0,0,0,0,0,0,0,0,0,0,0,0,0,0,0,0,0,0,0
0,0,0,0,0,0,0,0,0,0,0,0,0,0,0,0,0,0,0,0,0,0,0,0,0,0,0,0,0,0,0,0,0
:endlayer
layer: 36
0,0,0,0,0,0,0,0,0,0,0,0,0,0,0,0,0,0,0,0,0,0,0,0,0,0,0,0,0,0,0,0,0
0,0,0,0,0,0,0,0,0,0,0,0,0,0,0,0,0,0,0,0,0,0,0,0,0,0,0,0,0,0,0,0,0
0,0,0,0,0,0,0,0,0,0,0,0,0,0,0,0,0,0,0,0,0,0,0,0,0,0,0,0,0,0,0,0,0
0,0,0,0,0,0,0,0,0,0,0,0,0,0,0,0,0,0,0,0,0,0,0,0,0,0,0,0,0,0,0,0,0
0,0,0,0,0,0,0,0,0,0,0,0,0,0,0,0,0,0,0,0,0,0,0,0,0,0,0,0,0,0,0,0,0
0,0,0,0,0,0,0,0,0,0,0,0,0,0,0,0,0,0,0,0,0,0,0,0,0,0,0,0,0,0,0,0,0
0,0,0,0,0,0,0,0,0,0,0,0,0,0,0,0,0,0,0,0,0,0,0,0,0,0,0,0,0,0,0,0,0
0,0,0,0,0,0,0,0,0,0,0,0,0,0,0,0,0,0,0,0,0,0,0,0,0,0,0,0,0,0,0,0,0
0,0,0,0,0,0,0,0,0,254,0,0,0,0,0,0,0,0,0,0,0,0,0,0,0,0,0,0,0,0,0,0,0
0,0,0,0,0,0,0,0,0,0,0,0,0,0,0,0,0,0,0,0,0,0,0,0,0,0,0,0,0,0,0,0,0
0,0,0,0,0,254,0,0,0,0,0,0,0,254,0,0,0,0,0,0,0,0,0,0,0,0,0,0,0,0,0,0,0
0,0,0,0,0,0,0,0,0,0,0,0,0,0,0,0,0,0,0,0,0,0,0,0,0,0,0,0,0,0,0,0,0
0,0,0,0,0,0,0,60,0,0,0,0,0,0,0,0,0,0,0,0,0,0,0,0,0,0,0,0,0,0,0,0,0
0,0,0,0,0,0,0,0,0,0,0,0,0,0,0,0,0,0,0,0,0,0,0,0,0,0,0,0,0,0,0,0,0
0,0,0,0,0,0,0,124,0,0,0,0,0,0,0,254,0,0,0,0,0,0,0,0,0,0,0,0,0,0,0,0,0
0,0,0,0,0,0,0,0,0,0,0,0,0,0,0,0,0,0,0,0,0,0,0,0,0,0,0,0,0,0,0,0,0
0,0,0,0,0,0,0,0,0,0,0,0,0,0,0,311,0,0,0,0,0,0,0,0,0,0,0,0,0,0,0,0,0
0,0,0,0,312,0,0,0,0,0,0,0,0,0,0,0,0,0,0,0,0,0,0,0,0,0,0,0,0,0,0,0,0
0,0,0,0,0,254,0,0,0,0,0,0,0,254,0,0,0,0,0,0,0,0,0,0,0,0,0,0,0,0,0,0,0
0,0,0,0,0,0,0,0,0,0,0,0,0,0,0,0,0,0,0,0,0,0,0,0,0,0,0,0,0,0,0,0,0
0,0,0,0,0,0,0,0,0,254,0,0,0,0,0,0,0,0,0,0,0,0,0,0,0,0,0,0,0,0,0,0,0
0,0,0,0,0,0,0,0,0,0,0,0,0,0,0,0,0,0,0,0,0,0,0,0,0,0,0,0,0,0,0,0,0
0,0,0,0,0,0,0,0,0,0,0,0,0,0,0,0,0,0,0,0,0,0,0,0,0,0,0,0,0,0,0,0,0
0,0,0,0,0,0,0,0,0,0,0,0,0,0,0,0,0,0,0,0,0,0,0,0,0,0,0,0,0,0,0,0,0
0,0,0,0,0,0,0,0,0,0,0,0,0,0,0,0,0,0,0,0,0,0,0,0,0,0,0,0,0,0,0,0,0
0,0,0,0,0,0,0,0,0,0,0,0,0,0,0,0,0,0,0,0,0,0,0,0,0,0,0,0,0,0,0,0,0
0,0,0,0,0,0,0,0,0,0,0,0,0,0,0,0,0,0,0,0,0,0,0,0,0,0,0,0,0,0,0,0,0
0,0,0,0,0,0,0,0,0,0,0,0,0,0,0,0,0,0,0,0,0,0,0,0,0,0,0,0,0,0,0,0,0
0,0,0,0,0,0,0,0,0,0,0,0,0,0,0,0,0,0,0,0,0,0,0,0,0,0,0,0,0,0,0,0,0
0,0,0,0,0,0,0,0,0,0,0,0,0,0,0,0,0,0,0,0,0,0,0,0,0,0,0,0,0,0,0,0,0
0,0,0,0,0,0,0,0,0,0,0,0,0,0,0,0,0,0,0,0,0,0,0,0,0,0,0,0,0,0,0,0,0
0,0,0,0,0,0,0,0,0,0,0,0,0,0,0,0,0,0,0,0,0,0,0,0,0,0,0,0,0,0,0,0,0
0,0,0,0,0,0,0,0,0,0,0,0,0,0,0,0,0,0,0,0,0,0,0,0,0,0,0,0,0,0,0,0,0
0,0,0,0,0,0,0,0,0,0,0,0,0,0,0,0,0,0,0,0,0,0,0,0,0,0,0,0,0,0,0,0,0
0,0,0,0,0,0,0,0,0,0,0,0,0,0,0,0,0,0,0,0,0,0,0,0,0,0,0,0,0,0,0,0,0
0,0,0,0,0,0,0,0,0,0,0,0,0,0,0,0,0,0,0,0,0,0,0,0,0,0,0,0,0,0,0,0,0
0,0,0,0,0,0,0,0,0,0,0,0,0,0,0,0,0,0,0,0,0,0,0,0,0,0,0,0,0,0,0,0,0
:endlayer
layer: 37
0,0,0,0,0,0,0,0,0,0,0,0,0,0,0,0,0,0,0,0,0,0,0,0,0,0,0,0,0,0,0,0,0
0,0,0,0,0,0,0,0,0,0,0,0,0,0,0,0,0,0,0,0,0,0,0,0,0,0,0,0,0,0,0,0,0
0,0,0,0,0,0,0,0,0,0,0,0,0,0,0,0,0,0,0,0,0,0,0,0,0,0,0,0,0,0,0,0,0
0,0,0,0,0,0,0,0,0,0,0,0,0,0,0,0,0,0,0,0,0,0,0,0,0,0,0,0,0,0,0,0,0
0,0,0,0,0,0,0,0,0,0,0,0,0,0,0,0,0,0,0,0,0,0,0,0,0,0,0,0,0,0,0,0,0
0,0,0,0,0,0,0,0,0,0,0,0,0,0,0,0,0,0,0,0,0,0,0,0,0,0,0,0,0,0,0,0,0
0,0,0,0,0,0,0,0,0,0,0,0,0,0,0,0,0,0,0,0,0,0,0,0,0,0,0,0,0,0,0,0,0
0,0,0,0,0,0,0,0,0,0,0,0,0,0,0,0,0,0,0,0,0,0,0,0,0,0,0,0,0,0,0,0,0
0,0,0,0,0,0,0,0,0,0,0,0,0,0,0,0,0,0,0,0,0,0,0,0,0,0,0,0,0,0,0,0,0
0,0,0,0,0,0,0,0,0,0,0,0,0,0,0,0,0,0,0,0,0,0,0,0,0,0,0,0,0,0,0,0,0
0,0,0,0,0,0,0,0,0,0,0,0,0,0,0,0,0,0,0,0,0,0,0,0,0,0,0,0,0,0,0,0,0
0,0,0,0,0,0,0,0,0,0,0,0,0,0,0,0,0,0,0,0,0,0,0,0,0,0,0,0,0,0,0,0,0
0,0,0,0,0,0,0,60,0,0,0,0,0,0,0,0,0,0,0,0,0,0,0,0,0,0,0,0,0,0,0,0,0
0,0,0,0,0,0,0,0,0,0,0,0,0,0,0,0,0,0,0,0,0,0,0,0,0,0,0,0,0,0,0,0,0
0,0,0,0,0,0,0,0,0,0,0,0,0,0,0,0,0,0,0,0,0,0,0,0,0,0,0,0,0,0,0,0,0
0,0,0,0,0,0,0,0,0,0,0,0,0,0,0,0,0,0,0,0,0,0,0,0,0,0,0,0,0,0,0,0,0
0,0,0,0,0,0,0,0,0,0,0,0,0,0,0,0,0,0,0,0,0,0,0,0,0,0,0,0,0,0,0,0,0
0,0,0,0,0,0,0,0,0,0,0,0,0,0,0,0,0,0,0,0,0,0,0,0,0,0,0,0,0,0,0,0,0
0,0,0,0,0,0,0,0,0,0,0,0,0,0,0,0,0,0,0,0,0,0,0,0,0,0,0,0,0,0,0,0,0
0,0,0,0,0,0,0,0,0,0,0,0,0,0,0,0,0,0,0,0,0,0,0,0,0,0,0,0,0,0,0,0,0
0,0,0,0,0,0,0,0,0,0,0,0,0,0,0,0,0,0,0,0,0,0,0,0,0,0,0,0,0,0,0,0,0
0,0,0,0,0,0,0,0,0,0,0,0,0,0,0,0,0,0,0,0,0,0,0,0,0,0,0,0,0,0,0,0,0
0,0,0,0,0,0,0,0,0,0,0,0,0,0,0,0,0,0,0,0,0,0,0,0,0,0,0,0,0,0,0,0,0
0,0,0,0,0,0,0,0,0,0,0,0,0,0,0,0,0,0,0,0,0,0,0,0,0,0,0,0,0,0,0,0,0
0,0,0,0,0,0,0,0,0,0,0,0,0,0,0,0,0,0,0,0,0,0,0,0,0,0,0,0,0,0,0,0,0
0,0,0,0,0,0,0,0,0,0,0,0,0,0,0,0,0,0,0,0,0,0,0,0,0,0,0,0,0,0,0,0,0
0,0,0,0,0,0,0,0,0,0,0,0,0,0,0,0,0,0,0,0,0,0,0,0,0,0,0,0,0,0,0,0,0
0,0,0,0,0,0,0,0,0,0,0,0,0,0,0,0,0,0,0,0,0,0,0,0,0,0,0,0,0,0,0,0,0
0,0,0,0,0,0,0,0,0,0,0,0,0,0,0,0,0,0,0,0,0,0,0,0,0,0,0,0,0,0,0,0,0
0,0,0,0,0,0,0,0,0,0,0,0,0,0,0,0,0,0,0,0,0,0,0,0,0,0,0,0,0,0,0,0,0
0,0,0,0,0,0,0,0,0,0,0,0,0,0,0,0,0,0,0,0,0,0,0,0,0,0,0,0,0,0,0,0,0
0,0,0,0,0,0,0,0,0,0,0,0,0,0,0,0,0,0,0,0,0,0,0,0,0,0,0,0,0,0,0,0,0
0,0,0,0,0,0,0,0,0,0,0,0,0,0,0,0,0,0,0,0,0,0,0,0,0,0,0,0,0,0,0,0,0
0,0,0,0,0,0,0,0,0,0,0,0,0,0,0,0,0,0,0,0,0,0,0,0,0,0,0,0,0,0,0,0,0
0,0,0,0,0,0,0,0,0,0,0,0,0,0,0,0,0,0,0,0,0,0,0,0,0,0,0,0,0,0,0,0,0
0,0,0,0,0,0,0,0,0,0,0,0,0,0,0,0,0,0,0,0,0,0,0,0,0,0,0,0,0,0,0,0,0
0,0,0,0,0,0,0,0,0,0,0,0,0,0,0,0,0,0,0,0,0,0,0,0,0,0,0,0,0,0,0,0,0
:endlayer
layer: 38
0,0,0,0,0,0,0,0,0,0,0,0,0,0,0,0,0,0,0,0,0,0,0,0,0,0,0,0,0,0,0,0,0
0,0,0,0,0,0,0,0,0,0,0,0,0,0,0,0,0,0,0,0,0,0,0,0,0,0,0,0,0,0,0,0,0
0,0,0,0,0,0,0,0,0,0,0,0,0,0,0,0,0,0,0,0,0,0,0,0,0,0,0,0,0,0,0,0,0
0,0,0,0,0,0,0,0,0,0,0,0,0,0,0,0,0,0,0,0,0,0,0,0,0,0,0,0,0,0,0,0,0
0,0,0,0,0,0,0,0,0,0,0,0,0,0,0,0,0,0,0,0,0,0,0,0,0,0,0,0,0,0,0,0,0
