# Ancient Warfare Structure Template File
# Auto-generated structure template file. created on: 8/19/2019 at: 10:23:10
# Lines beginning with # denote comments

header:
version=2.9
name=EmpireMillTraditional
mods=
size=27,24,25
offset=13,4,24
:endheader

#### VALIDATION ####
validation:
type=ground
survival=false
worldGenEnabled=true
unique=false
preserveBlocks=false
selectionWeight=30
clusterValue=20
minDuplicateDistance=600
dimensionWhiteList=true
dimensionList=0
biomeWhiteList=true
biomeList=biomesoplenty:meadow,traverse:meadow,minecraft:plains
leveling=5
fill=5
border=5
blockSwap=false
:endvalidation

#### LAYERS ####
layer: 0
1,1,1,1,1,1,1,1,1,1,1,1,1,1,1,1,1,1,1,1,1,1,1,1,1,1,1
1,1,1,1,1,1,1,1,1,1,1,1,1,1,1,1,1,1,1,1,1,1,1,1,1,1,1
1,1,1,1,1,1,1,1,1,1,1,1,1,1,1,1,1,1,1,1,1,1,1,1,1,1,1
1,1,1,1,1,1,1,1,1,1,1,1,1,1,1,1,1,1,1,1,1,1,1,1,1,1,1
1,1,1,1,1,1,1,1,1,1,1,1,1,1,1,1,1,1,1,1,1,1,1,1,1,1,1
1,1,1,1,1,1,1,1,1,1,1,1,1,1,1,1,1,1,1,1,1,1,1,1,1,1,1
1,1,1,1,1,1,1,1,1,1,1,1,1,1,1,1,1,1,1,1,1,1,1,1,1,1,1
1,1,1,1,1,1,1,1,1,1,1,1,1,1,1,1,1,1,1,1,1,1,1,1,1,1,1
1,1,1,1,1,1,1,1,1,1,1,1,1,1,1,1,1,1,1,1,1,1,1,1,1,1,1
1,1,1,1,1,1,1,1,1,1,1,1,1,1,1,1,1,1,1,1,1,1,1,1,1,1,1
1,1,1,1,1,1,1,1,1,1,1,1,1,1,1,1,1,1,1,1,1,1,1,1,1,1,1
1,1,1,1,1,1,1,1,1,1,1,1,1,1,1,1,1,1,1,1,1,1,1,1,1,1,1
1,1,1,1,1,1,1,1,1,1,1,1,1,1,1,1,1,1,1,1,1,1,1,1,1,1,1
1,1,1,1,1,1,1,1,1,1,1,1,1,1,1,1,1,1,1,1,1,1,1,1,1,1,1
1,1,1,1,1,1,1,1,1,1,1,1,1,1,1,1,1,1,1,1,1,1,1,1,1,1,1
1,1,1,1,1,1,1,1,1,1,1,1,1,1,1,1,1,1,1,1,1,1,1,1,1,1,1
1,1,1,1,1,1,1,1,1,1,1,1,1,1,1,1,1,1,1,1,1,1,1,1,1,1,1
1,1,1,1,1,1,1,1,1,1,1,1,1,1,1,1,1,1,1,1,1,1,1,1,1,1,1
1,1,1,1,1,1,1,1,1,1,1,1,1,1,1,1,1,1,1,1,1,1,1,1,1,1,1
1,1,1,1,1,1,1,1,1,1,1,1,1,1,1,1,1,1,1,1,1,1,1,1,1,1,1
1,1,1,1,1,1,1,1,1,1,1,1,1,1,1,1,1,1,1,1,1,1,1,1,1,1,1
1,1,1,1,1,1,1,1,1,1,1,1,1,1,1,1,1,1,1,1,1,1,1,1,1,1,1
1,1,1,1,1,1,1,1,1,1,1,1,1,1,1,1,1,1,1,1,1,1,1,1,1,1,1
1,1,1,1,1,1,1,1,1,1,1,1,1,1,1,1,1,1,1,1,1,1,1,1,1,1,1
1,1,1,1,1,1,1,1,1,1,1,1,1,1,1,1,1,1,1,1,1,1,1,1,1,1,1
:endlayer
layer: 1
1,1,1,1,1,1,1,1,1,1,1,1,1,1,1,1,1,1,1,1,1,1,1,1,1,1,1
1,1,1,1,1,1,1,1,1,1,1,1,1,1,1,1,1,1,1,1,1,1,1,1,1,1,1
1,1,1,1,1,1,1,1,1,1,1,1,1,1,1,1,1,1,1,1,1,1,1,1,1,1,1
1,1,1,1,1,1,1,1,1,1,1,1,1,1,1,1,1,1,1,1,1,1,1,1,1,1,1
1,1,1,1,1,1,1,1,1,1,1,1,1,1,1,1,1,1,1,1,1,1,1,1,1,1,1
1,1,1,1,1,1,1,1,1,1,1,1,1,1,1,1,1,1,1,1,1,1,1,1,1,1,1
1,1,1,1,1,1,1,1,1,1,1,1,1,1,1,1,1,1,1,1,1,1,1,1,1,1,1
1,1,1,1,1,1,1,1,1,1,1,1,1,1,1,1,1,1,1,1,1,1,1,1,1,1,1
1,1,1,1,1,1,1,1,1,1,1,1,1,1,1,1,1,1,1,1,1,1,1,1,1,1,1
1,1,1,1,1,1,1,1,1,1,1,1,1,1,1,1,1,1,1,1,1,1,1,1,1,1,1
1,1,1,1,1,1,1,1,1,1,1,1,1,1,1,1,1,1,1,1,1,1,1,1,1,1,1
1,1,1,1,1,1,1,1,1,1,1,1,1,1,1,1,1,1,1,1,1,1,1,1,1,1,1
1,1,1,1,1,1,1,1,1,1,1,1,1,1,1,1,1,1,1,1,1,1,1,1,1,1,1
1,1,1,1,1,1,1,1,1,1,1,1,1,1,1,1,1,1,1,1,1,1,1,1,1,1,1
1,1,1,1,1,1,1,1,1,1,1,1,1,1,1,1,1,1,1,1,1,1,1,1,1,1,1
1,1,1,1,1,1,1,1,1,1,1,1,1,1,1,1,1,1,1,1,1,1,1,1,1,1,1
1,1,1,1,1,1,1,1,1,1,1,1,1,1,1,1,1,1,1,1,1,1,1,1,1,1,1
1,1,1,1,1,1,1,1,1,1,1,1,1,1,1,1,1,1,1,1,1,1,1,1,1,1,1
1,1,1,1,1,1,1,1,1,1,1,1,1,1,1,1,1,1,1,1,1,1,1,1,1,1,1
1,1,1,1,1,1,1,1,1,1,1,1,1,1,1,1,1,1,1,1,1,1,1,1,1,1,1
1,1,1,1,1,1,1,1,1,1,1,1,1,1,1,1,1,1,1,1,1,1,1,1,1,1,1
1,1,1,1,1,1,1,1,1,1,1,1,1,1,1,1,1,1,1,1,1,1,1,1,1,1,1
1,1,1,1,1,1,1,1,1,1,1,1,1,1,1,1,1,1,1,1,1,1,1,1,1,1,1
1,1,1,1,1,1,1,1,1,1,1,1,1,1,1,1,1,1,1,1,1,1,1,1,1,1,1
1,1,1,1,1,1,1,1,1,1,1,1,1,1,1,1,1,1,1,1,1,1,1,1,1,1,1
:endlayer
layer: 2
1,1,1,1,1,1,1,1,1,1,1,1,1,1,1,1,1,1,1,1,1,1,1,1,1,1,1
1,1,1,1,1,1,1,1,1,1,1,1,1,1,1,1,1,1,1,1,1,1,1,1,1,1,1
1,1,1,1,1,1,1,1,1,1,1,1,1,1,1,1,1,1,1,1,1,1,1,1,1,1,1
1,1,1,1,1,1,1,1,1,1,1,1,1,1,1,1,1,1,1,1,1,1,1,1,1,1,1
1,1,1,1,1,1,1,1,1,1,1,1,1,1,1,1,1,1,1,1,1,1,1,1,1,1,1
1,1,1,1,1,1,1,1,1,1,1,1,1,1,1,1,1,1,1,1,1,1,1,1,1,1,1
1,1,1,1,1,1,1,1,1,1,1,1,1,1,1,1,1,1,1,1,1,1,1,1,1,1,1
1,1,1,1,1,1,1,1,1,1,1,1,1,1,1,1,1,1,1,1,1,1,1,1,1,1,1
1,1,1,1,1,1,1,1,1,1,1,1,1,1,1,1,1,1,1,1,1,1,1,1,1,1,1
1,1,1,1,1,1,1,1,1,1,1,1,1,1,1,1,1,1,1,1,1,1,1,1,1,1,1
1,1,1,1,1,1,1,1,1,1,1,1,1,1,1,1,1,1,1,1,1,1,1,1,1,1,1
1,1,1,1,1,1,1,1,1,1,1,1,1,1,1,1,1,1,1,1,1,1,1,1,1,1,1
1,1,1,1,1,1,1,1,1,1,1,1,1,1,1,1,1,1,1,1,1,1,1,1,1,1,1
1,1,1,1,1,1,1,1,1,1,1,1,1,1,1,1,1,1,1,1,1,1,1,1,1,1,1
1,1,1,1,1,1,1,1,1,1,1,1,1,1,1,1,1,1,1,1,1,1,1,1,1,1,1
1,1,1,1,1,1,1,1,1,1,1,1,1,1,1,1,1,1,1,1,1,1,1,1,1,1,1
1,1,1,1,1,1,1,1,1,1,1,2,1,1,1,1,1,1,1,1,1,1,1,1,1,1,1
1,1,1,1,1,1,1,1,1,1,1,1,1,1,1,1,1,1,1,1,1,1,1,1,1,1,1
1,1,1,1,1,1,1,1,1,1,1,2,1,1,1,1,1,1,1,1,1,1,1,1,1,1,1
1,1,1,1,1,1,1,1,1,1,1,1,1,1,1,1,1,1,1,1,1,1,1,1,1,1,1
1,1,1,1,1,1,1,1,1,1,2,1,1,1,1,1,1,1,1,1,1,1,1,1,1,1,1
1,1,1,1,1,1,1,1,1,1,1,2,1,1,1,1,1,1,1,1,1,1,1,1,1,1,1
1,1,1,1,1,1,1,1,1,1,1,1,1,1,1,1,1,1,1,1,1,1,1,1,1,1,1
1,1,1,1,1,1,1,1,1,1,1,1,1,1,1,1,1,1,1,1,1,1,1,1,1,1,1
1,1,1,1,1,1,1,1,1,1,1,1,1,1,1,1,1,1,1,1,1,1,1,1,1,1,1
:endlayer
layer: 3
2,2,2,2,2,2,2,2,2,2,2,3,2,2,2,2,2,2,2,2,2,2,2,2,2,2,2
2,2,2,2,2,2,2,2,2,2,2,3,2,2,2,2,2,2,2,2,2,2,2,2,2,2,2
2,2,2,2,2,2,2,2,2,2,2,3,2,2,2,2,2,1,8,8,8,8,8,8,1,2,2
2,2,2,2,2,2,2,2,2,2,3,3,3,3,2,2,2,1,10,10,10,10,10,10,12,2,2
2,2,2,2,2,2,2,2,2,2,3,3,3,3,3,3,2,1,10,10,10,10,10,10,10,2,2
2,2,2,2,3,3,3,3,11,3,3,3,3,3,3,3,2,10,10,10,10,10,10,10,10,2,2
2,2,2,2,2,2,2,2,11,11,3,3,3,3,3,3,3,1,10,10,10,10,10,10,10,2,2
2,2,2,2,2,2,2,2,3,2,2,2,3,3,3,3,3,1,1,1,10,10,10,10,12,2,2
2,2,2,2,2,2,9,8,11,1,1,2,3,3,3,3,3,10,10,10,10,10,10,10,10,2,2
2,2,2,2,2,9,8,8,8,8,8,1,2,3,3,3,3,10,10,10,10,10,10,10,10,2,2
2,2,2,2,2,8,8,8,8,8,8,1,2,3,3,3,3,10,10,10,10,10,10,10,10,2,2
2,2,2,2,2,8,8,8,8,8,8,1,2,3,3,3,3,10,10,10,10,10,10,10,10,2,2
2,2,2,2,2,8,8,8,8,8,8,1,2,3,3,3,3,1,10,10,10,10,10,10,1,2,2
2,2,2,2,2,9,8,8,8,8,8,1,2,3,3,3,3,3,3,3,3,3,3,3,3,3,3
2,2,2,2,2,2,1,1,1,1,1,2,2,3,3,3,3,2,2,2,2,2,2,2,2,2,2
2,2,2,2,2,2,2,2,2,2,2,2,2,3,3,3,3,1,2,2,2,2,2,2,1,2,2
2,2,2,2,2,2,2,2,2,2,2,4,1,3,3,3,3,2,2,2,2,2,2,2,2,2,2
2,2,2,2,2,2,2,2,2,2,2,2,2,3,3,3,3,2,2,2,2,2,2,2,2,2,2
2,2,2,2,2,2,2,2,1,2,2,7,1,3,3,3,1,2,2,2,2,2,2,2,2,2,2
2,2,2,2,2,2,2,2,6,1,1,2,2,3,3,3,1,2,2,2,2,2,2,2,2,2,2
2,2,2,2,2,2,2,2,2,2,5,2,2,3,3,3,3,2,2,2,2,2,2,2,2,2,2
2,2,2,2,2,2,2,2,2,1,2,4,1,3,3,3,3,2,2,2,2,2,2,2,2,2,2
2,2,2,2,2,2,2,2,2,2,2,2,2,3,3,3,3,1,2,2,2,2,2,2,1,2,2
2,2,2,2,2,2,2,2,2,2,2,2,2,2,2,3,2,2,2,2,2,2,2,2,2,2,2
2,2,2,2,2,2,2,2,2,2,2,2,2,2,2,3,2,2,2,2,2,2,2,2,2,2,2
:endlayer
layer: 4
0,13,13,13,0,13,13,13,0,0,0,0,0,13,13,13,13,13,0,0,0,0,0,13,13,13,13
13,13,13,13,13,13,0,13,13,0,0,0,0,0,13,13,13,13,13,0,0,0,0,0,13,13,13
37,14,14,14,14,14,14,14,14,14,14,36,14,14,14,14,14,12,8,8,8,8,8,8,12,13,13
0,14,0,0,0,14,0,0,0,0,0,0,0,0,13,0,0,8,35,14,34,0,0,0,8,13,13
0,14,0,0,0,14,0,0,0,0,0,0,0,0,0,0,0,8,35,14,34,0,0,0,8,13,13
13,14,0,33,0,23,0,0,0,0,0,0,0,0,0,0,0,8,0,0,0,0,0,32,8,13,13
0,14,0,0,0,14,0,0,0,0,0,0,0,0,0,0,0,8,0,0,0,0,0,8,8,13,13
13,14,0,0,0,14,0,32,0,32,0,0,0,0,0,0,0,12,8,8,28,8,8,8,12,0,0
0,14,0,0,0,14,9,8,28,8,9,14,0,0,0,0,0,8,0,0,0,0,0,31,8,0,0
0,14,0,0,0,9,9,0,0,0,9,9,0,0,0,0,0,8,0,0,0,30,0,29,8,13,13
0,14,0,0,0,8,0,0,0,0,0,8,0,0,0,0,0,28,0,0,0,0,0,27,8,13,13
13,14,0,13,0,8,0,0,14,0,0,8,0,0,0,0,0,8,0,0,0,0,0,26,8,13,0
13,14,0,13,13,8,0,0,0,0,0,8,0,0,0,0,0,12,8,8,8,8,8,8,12,0,13
13,14,13,0,0,9,9,25,0,24,9,9,0,0,0,0,0,0,0,0,0,0,0,0,23,0,0
13,14,0,22,0,14,9,8,8,8,9,14,0,0,0,0,0,0,0,0,0,0,0,0,14,0,0
0,14,13,0,0,0,14,0,0,0,0,0,0,0,0,0,0,10,0,0,0,0,0,0,10,14,0
0,14,0,0,0,0,14,0,0,0,0,17,16,0,0,0,0,0,0,0,0,0,0,0,0,14,0
0,14,13,0,0,13,14,0,0,0,0,0,0,0,0,0,0,0,0,0,0,0,0,13,0,14,0
0,14,0,13,13,0,14,0,18,0,0,17,16,0,0,20,10,0,0,0,0,0,0,0,0,14,0
13,14,13,13,13,0,14,0,21,18,16,0,0,0,0,20,10,0,0,0,0,0,0,0,0,14,13
13,14,0,19,13,0,14,0,0,0,17,0,0,0,0,0,0,0,0,0,0,13,13,0,13,14,13
0,14,13,13,0,0,14,0,0,18,0,17,16,0,0,0,0,0,0,0,0,0,0,13,0,14,0
13,14,0,13,0,13,14,0,13,13,13,0,13,0,0,0,0,10,0,0,0,0,13,0,10,14,0
0,14,14,14,14,14,14,14,14,14,14,14,14,14,14,15,14,14,14,14,14,14,14,14,14,14,0
13,13,13,13,0,0,0,13,13,13,13,0,0,0,0,0,0,0,0,0,0,13,13,13,0,0,0
:endlayer
layer: 5
0,0,0,0,0,0,0,0,0,0,0,0,0,0,0,0,0,0,0,0,0,0,0,0,0,0,0
0,0,0,0,0,0,0,0,0,0,0,0,0,0,0,0,0,0,0,0,0,0,0,0,0,0,0
0,38,0,0,0,38,0,0,0,0,0,0,0,38,0,0,0,12,8,8,8,42,8,8,12,0,0
0,0,0,0,0,0,0,0,0,0,0,0,0,0,0,0,0,8,0,49,0,0,0,0,8,0,0
0,0,0,0,0,38,0,0,0,0,0,0,0,0,0,0,0,8,0,48,0,0,0,0,8,0,0
0,0,0,0,0,0,0,0,0,0,0,0,0,0,0,0,0,47,0,0,0,0,0,0,47,0,0
0,0,0,0,0,38,0,0,0,0,0,0,0,0,0,0,0,8,0,0,0,0,0,32,8,0,0
0,0,0,0,0,0,0,0,0,46,0,0,0,0,0,0,0,12,8,8,45,8,8,8,12,0,0
0,0,0,0,0,14,9,8,45,8,9,14,0,0,0,0,0,8,0,0,0,0,0,0,8,0,0
0,0,0,0,0,9,9,0,0,0,9,9,0,0,0,0,0,8,0,0,0,0,0,0,42,0,0
0,0,0,0,0,8,0,0,0,0,0,8,0,0,0,0,0,45,0,0,0,0,0,0,8,0,0
0,38,0,0,0,44,0,0,43,0,0,8,0,0,0,0,0,8,0,0,0,0,0,0,8,0,0
0,0,0,0,0,8,0,0,0,0,0,8,0,0,0,0,0,12,8,8,42,8,8,8,12,0,0
0,0,0,0,0,9,9,0,0,0,9,9,0,0,0,0,0,0,0,0,0,0,0,0,0,0,0
0,0,0,0,0,14,9,8,8,8,9,14,0,0,0,0,0,0,0,0,0,0,0,0,0,0,0
0,0,0,0,0,0,0,0,0,0,0,0,0,0,0,0,0,12,39,39,39,39,39,39,12,38,0
0,0,0,0,0,0,0,0,0,0,0,0,0,0,0,0,0,40,41,41,41,41,41,41,40,0,0
0,0,0,0,0,0,0,0,0,0,0,0,0,0,0,0,0,40,41,41,41,41,41,41,40,0,0
0,0,0,0,0,0,0,0,0,0,0,0,0,0,0,0,20,40,41,41,41,41,41,41,40,0,0
0,0,0,0,0,0,0,0,0,0,0,0,0,0,0,0,20,40,41,41,41,41,41,41,40,0,0
0,0,0,0,0,0,0,0,0,0,0,0,0,0,0,0,0,40,41,41,41,41,41,41,40,0,0
0,0,0,0,0,0,0,0,0,0,0,0,0,0,0,0,0,40,41,41,41,41,41,41,40,0,0
0,0,0,0,0,0,0,0,0,0,0,0,0,0,0,0,0,12,39,39,39,39,39,39,12,0,0
0,38,0,0,0,0,38,0,0,0,0,0,0,0,38,0,38,0,0,0,0,0,0,0,0,38,0
0,0,0,0,0,0,0,0,0,0,0,0,0,0,0,0,0,0,0,0,0,0,0,0,0,0,0
:endlayer
layer: 6
0,0,0,0,0,0,0,0,0,0,0,0,0,0,0,0,0,0,0,0,0,0,0,0,0,0,0
0,0,0,0,0,0,0,0,0,0,0,0,0,0,0,0,0,67,0,0,0,0,0,0,67,0,0
0,0,0,0,0,0,0,0,0,0,0,0,0,0,0,0,66,12,8,8,8,8,8,8,12,65,0
0,0,0,0,0,0,0,0,0,0,0,0,0,0,0,0,0,8,63,0,0,0,0,63,8,0,0
0,0,0,0,0,0,0,0,0,0,0,0,0,0,0,0,0,8,0,0,0,0,0,0,8,0,0
0,0,0,0,0,0,0,0,0,0,0,0,0,0,0,0,0,8,0,0,0,0,0,0,8,0,0
0,0,0,0,0,0,0,0,0,0,0,0,0,0,0,0,0,8,0,67,0,0,0,0,8,0,0
0,0,0,0,0,0,0,0,67,0,0,0,0,0,0,0,66,12,8,8,8,8,8,32,12,65,0
0,0,0,0,0,0,34,8,8,8,35,0,0,0,0,0,0,8,63,0,0,0,0,63,8,0,0
0,0,0,0,0,70,9,0,0,0,9,70,0,0,0,0,0,8,0,0,0,0,0,0,8,0,0
0,0,0,0,0,8,0,0,0,0,0,8,0,0,0,0,69,8,0,0,0,0,0,0,8,0,0
0,0,0,14,0,8,65,0,68,0,66,8,0,0,0,0,0,8,67,0,0,0,0,66,8,0,0
0,0,0,14,0,8,0,0,0,0,0,8,0,0,0,0,66,12,8,8,8,8,8,8,12,65,0
0,0,0,14,0,64,9,0,0,0,9,64,0,0,0,0,0,63,0,0,0,0,0,0,63,0,0
0,0,0,0,0,0,34,8,8,8,35,0,0,0,0,0,0,0,0,0,0,0,0,0,0,0,0
0,0,0,0,0,0,0,0,0,0,0,0,0,0,0,0,0,12,41,41,41,41,41,41,12,0,0
0,0,0,0,0,0,0,0,0,0,0,0,0,0,0,0,0,41,62,0,61,60,0,59,41,0,0
0,0,0,0,0,0,0,0,0,0,0,0,0,0,0,0,0,41,58,0,0,0,0,57,41,0,0
0,0,0,0,0,0,0,0,0,0,0,0,0,0,0,0,0,56,0,0,0,0,0,0,41,0,0
0,0,0,0,0,0,0,0,0,0,0,0,0,0,0,0,0,56,0,0,0,0,0,0,41,0,0
0,0,0,0,0,0,0,0,0,0,0,0,0,0,0,0,0,41,55,0,0,0,0,54,41,0,0
0,0,0,0,0,0,0,0,0,0,0,0,0,0,0,0,0,41,53,0,52,51,0,50,41,0,0
0,0,0,0,0,0,0,0,0,0,0,0,0,0,0,0,0,12,41,41,41,41,41,41,12,0,0
0,0,0,0,0,0,0,0,0,0,0,0,0,0,0,0,0,0,0,0,0,0,0,0,0,0,0
0,0,0,0,0,0,0,0,0,0,0,0,0,0,0,0,0,0,0,0,0,0,0,0,0,0,0
:endlayer
layer: 7
0,0,0,0,0,0,0,0,0,0,0,0,0,0,0,0,0,0,0,0,0,0,0,0,0,0,0
0,0,0,0,0,0,0,0,0,0,0,0,0,0,0,0,74,74,74,74,74,74,74,74,74,74,0
0,0,0,0,0,0,0,0,0,0,0,0,0,0,0,0,70,70,70,70,70,70,70,70,70,70,0
0,0,0,0,0,0,0,0,0,0,0,0,0,0,0,0,0,12,10,10,10,10,10,10,12,0,0
0,0,0,0,0,0,0,0,0,0,0,0,0,0,0,0,0,12,10,10,10,10,10,0,12,0,0
0,0,0,0,0,0,0,0,0,0,0,0,0,0,0,0,0,12,10,10,10,10,10,0,12,0,0
0,0,0,0,0,0,0,0,0,0,0,0,0,0,0,0,0,12,10,10,10,10,10,0,12,0,0
0,0,0,0,0,0,0,74,74,74,0,0,0,0,0,0,0,12,10,10,10,10,10,0,12,0,0
0,0,0,0,0,0,0,70,70,70,0,0,0,0,0,0,0,12,10,10,10,10,10,32,12,0,0
0,0,0,0,0,0,9,10,10,10,9,0,0,0,0,0,0,12,10,10,10,10,10,10,12,0,0
0,0,0,0,0,74,8,0,0,0,8,74,0,0,0,0,0,12,10,10,10,10,10,10,12,0,0
0,0,0,14,0,34,8,0,14,0,8,35,0,0,0,0,0,12,10,10,10,10,10,10,12,0,0
0,0,0,14,0,74,8,0,0,0,8,74,0,0,0,0,0,12,12,12,12,12,12,12,12,0,0
0,0,0,14,0,0,9,8,8,8,9,0,0,0,0,0,71,71,71,71,71,71,71,71,71,71,0
0,0,0,0,0,0,0,74,64,74,0,0,0,0,0,0,0,0,0,0,0,0,0,0,0,0,0
0,0,0,0,0,0,0,0,0,0,0,0,0,0,0,0,0,12,41,14,41,41,14,41,12,0,0
0,0,0,0,0,0,0,0,0,0,0,0,0,0,0,0,66,41,65,0,0,0,0,66,41,65,0
0,0,0,0,0,0,0,0,0,0,0,0,0,0,0,0,73,41,0,0,0,0,0,0,14,0,0
0,0,0,0,0,0,0,0,0,0,0,0,0,0,0,0,0,45,0,0,0,0,0,71,41,0,0
0,0,0,0,0,0,0,0,0,0,0,0,0,0,0,0,0,72,0,0,0,0,0,71,41,0,0
0,0,0,0,0,0,0,0,0,0,0,0,0,0,0,0,0,41,0,0,0,0,0,0,14,0,0
0,0,0,0,0,0,0,0,0,0,0,0,0,0,0,0,66,41,65,0,0,0,0,66,41,65,0
0,0,0,0,0,0,0,0,0,0,0,0,0,0,0,0,0,12,41,14,41,41,14,41,12,0,0
0,0,0,0,0,0,0,0,0,0,0,0,0,0,0,0,64,64,64,0,64,64,0,64,64,64,0
0,0,0,0,0,0,0,0,0,0,0,0,0,0,0,0,0,0,0,0,0,0,0,0,0,0,0
:endlayer
layer: 8
0,0,0,0,0,0,0,0,0,0,0,0,0,0,0,0,0,0,0,0,0,0,0,0,0,0,0
0,0,0,0,0,0,0,0,0,0,0,0,0,0,0,0,0,0,0,0,0,0,0,0,0,0,0
0,0,0,0,0,0,0,0,0,0,0,0,0,0,0,0,0,0,0,0,0,0,0,0,0,0,0
0,0,0,0,0,0,0,0,0,0,0,0,0,0,0,0,70,70,70,70,70,70,70,70,70,70,0
0,0,0,0,0,0,0,0,0,0,0,0,0,0,0,0,74,8,0,0,0,0,10,0,8,0,0
0,0,0,0,0,0,0,0,0,0,0,0,0,0,0,0,74,8,82,81,0,0,14,0,8,0,0
0,0,0,0,0,0,0,0,0,0,0,0,0,0,0,0,74,8,0,0,0,0,14,0,8,0,0
0,0,0,0,0,0,0,0,0,0,0,0,0,0,0,0,74,8,0,0,0,0,0,0,8,0,0
0,0,0,0,0,0,0,0,0,0,0,0,0,0,0,0,74,8,35,0,0,0,0,0,8,0,0
0,0,0,0,0,0,9,8,8,8,9,0,0,0,0,0,74,8,0,0,80,80,0,0,8,0,0
0,0,0,0,0,0,8,0,0,0,8,0,0,0,0,0,74,8,79,0,78,78,0,77,8,0,0
0,0,0,14,0,0,8,0,14,0,8,0,0,0,0,0,74,8,8,8,8,8,8,8,8,0,0
0,0,0,14,0,0,8,0,0,0,8,0,0,0,0,0,64,64,64,64,64,64,64,64,64,64,0
0,0,0,14,0,0,9,8,8,8,9,0,0,0,0,0,0,0,0,0,0,0,0,0,0,0,0
0,0,0,0,0,0,0,0,0,0,0,0,0,0,0,0,74,74,74,74,74,74,74,74,74,74,0
0,0,0,0,0,0,0,0,0,0,0,0,0,0,0,0,70,70,70,70,70,70,70,70,70,70,0
0,0,0,0,0,0,0,0,0,0,0,0,0,0,0,0,0,41,0,0,0,0,0,0,41,0,0
0,0,0,0,0,0,0,0,0,0,0,0,0,0,0,0,0,41,0,0,0,0,0,0,41,0,0
0,0,0,0,0,0,0,0,0,0,0,0,0,0,0,0,0,74,0,0,0,0,0,76,41,0,0
0,0,0,0,0,0,0,0,0,0,0,0,0,0,0,0,0,74,0,0,0,0,0,75,41,0,0
0,0,0,0,0,0,0,0,0,0,0,0,0,0,0,0,0,41,0,0,0,0,0,0,41,0,0
0,0,0,0,0,0,0,0,0,0,0,0,0,0,0,0,0,41,0,0,0,0,0,0,41,0,0
0,0,0,0,0,0,0,0,0,0,0,0,0,0,0,0,64,64,64,64,64,64,64,64,64,64,0
0,0,0,0,0,0,0,0,0,0,0,0,0,0,0,0,0,0,0,0,0,0,0,0,0,0,0
0,0,0,0,0,0,0,0,0,0,0,0,0,0,0,0,0,0,0,0,0,0,0,0,0,0,0
:endlayer
layer: 9
0,0,0,0,0,0,0,0,0,0,0,0,0,0,0,0,0,0,0,0,0,0,0,0,0,0,0
0,0,0,0,0,0,0,0,0,0,0,0,0,0,0,0,0,0,0,0,0,0,0,0,0,0,0
0,0,0,0,0,0,0,0,0,0,0,0,0,0,0,0,0,0,0,0,0,0,0,0,0,0,0
0,0,0,0,0,0,0,0,0,0,0,0,0,0,0,0,0,0,0,0,0,0,0,0,0,0,0
0,0,0,0,0,0,0,0,0,0,0,0,0,0,0,0,70,70,70,70,70,70,70,70,70,70,0
0,0,0,0,0,0,0,0,0,0,0,0,0,0,0,0,0,8,0,0,0,0,0,0,8,0,0
0,0,0,0,0,0,0,0,0,0,0,0,0,0,0,0,0,8,0,0,0,0,0,0,8,0,0
0,0,0,0,0,0,0,0,0,0,0,0,0,0,0,0,0,47,0,0,0,0,0,0,47,0,0
0,0,0,0,0,0,0,0,0,0,0,0,0,0,0,0,0,47,0,0,0,0,0,0,47,0,0
0,0,0,0,0,0,9,8,44,8,9,0,0,0,0,0,0,8,0,0,0,0,0,0,8,0,0
0,0,0,0,0,0,8,0,0,0,8,0,0,0,0,0,0,8,65,0,0,0,0,66,8,0,0
0,0,0,14,0,0,44,0,14,0,44,0,0,0,0,0,64,64,64,64,8,8,64,64,64,64,0
0,0,0,14,0,0,8,0,0,0,8,0,0,0,0,0,0,0,0,0,63,63,0,0,0,0,0
0,0,0,14,0,0,9,8,44,8,9,0,0,0,0,0,0,0,0,0,0,0,0,0,0,0,0
0,0,0,0,0,0,0,0,0,0,0,0,0,0,0,0,0,0,0,0,0,0,0,0,0,0,0
0,0,0,0,0,0,0,0,0,0,0,0,0,0,0,0,0,0,0,0,0,0,0,0,0,0,0
0,0,0,0,0,0,0,0,0,0,0,0,0,0,0,0,70,70,70,70,70,70,70,70,70,70,0
0,0,0,0,0,0,0,0,0,0,0,0,0,0,0,0,0,41,0,0,0,0,0,0,41,0,0
0,0,0,0,0,0,0,0,0,0,0,0,0,0,0,0,0,41,0,0,0,0,0,0,41,0,0
0,0,0,0,0,0,0,0,0,0,0,0,0,0,0,0,0,41,0,0,0,0,0,0,41,0,0
0,0,0,0,0,0,0,0,0,0,0,0,0,0,0,0,0,41,0,0,0,0,0,0,41,0,0
0,0,0,0,0,0,0,0,0,0,0,0,0,0,0,0,64,64,64,64,64,64,64,64,64,64,0
0,0,0,0,0,0,0,0,0,0,0,0,0,0,0,0,0,0,0,0,0,0,0,0,0,0,0
0,0,0,0,0,0,0,0,0,0,0,0,0,0,0,0,0,0,0,0,0,0,0,0,0,0,0
0,0,0,0,0,0,0,0,0,0,0,0,0,0,0,0,0,0,0,0,0,0,0,0,0,0,0
:endlayer
layer: 10
0,0,0,0,0,0,0,0,0,0,0,0,0,0,0,0,0,0,0,0,0,0,0,0,0,0,0
0,0,0,0,0,0,0,0,0,0,0,0,0,0,0,0,0,0,0,0,0,0,0,0,0,0,0
0,0,0,0,0,0,0,0,0,0,0,0,0,0,0,0,0,0,0,0,0,0,0,0,0,0,0
0,0,0,0,0,0,0,0,0,0,0,0,0,0,0,0,0,0,0,0,0,0,0,0,0,0,0
0,0,0,0,0,0,0,0,0,0,0,0,0,0,0,0,0,0,0,0,0,0,0,0,0,0,0
0,0,0,0,0,0,0,0,0,0,0,0,0,0,0,0,70,70,70,70,70,70,70,70,70,70,0
0,0,0,0,0,0,0,0,0,0,0,0,0,0,0,0,0,8,65,0,0,0,0,0,8,0,0
0,0,0,0,0,0,0,0,0,0,0,0,0,0,0,0,0,8,0,0,0,0,0,0,8,65,0
0,0,0,0,0,0,0,0,0,0,0,0,0,0,0,0,0,8,0,0,0,0,0,0,8,65,0
0,0,0,0,0,0,9,8,86,8,9,0,0,0,0,0,0,8,0,0,0,0,0,0,8,0,0
0,0,0,0,0,0,8,0,0,0,8,0,0,0,0,0,64,64,64,64,64,64,64,64,64,64,0
0,0,0,14,0,0,85,0,14,0,84,0,0,0,0,0,0,0,0,0,8,8,0,0,0,0,0
0,0,0,14,0,0,8,0,0,0,8,0,0,0,0,0,0,0,0,0,0,0,0,0,0,0,0
0,0,0,14,0,0,9,8,83,8,9,0,0,0,0,0,0,0,0,0,0,0,0,0,0,0,0
0,0,0,0,0,0,0,0,0,0,0,0,0,0,0,0,0,0,0,0,0,0,0,0,0,0,0
0,0,0,0,0,0,0,0,0,0,0,0,0,0,0,0,0,0,0,0,0,0,0,0,0,0,0
0,0,0,0,0,0,0,0,0,0,0,0,0,0,0,0,0,0,0,0,0,0,0,0,0,0,0
0,0,0,0,0,0,0,0,0,0,0,0,0,0,0,0,70,70,70,70,70,70,70,70,70,70,0
0,0,0,0,0,0,0,0,0,0,0,0,0,0,0,0,0,41,0,0,0,0,0,0,41,0,0
0,0,0,0,0,0,0,0,0,0,0,0,0,0,0,0,0,41,0,0,0,0,0,0,41,0,0
0,0,0,0,0,0,0,0,0,0,0,0,0,0,0,0,64,64,64,64,64,64,64,64,64,64,0
0,0,0,0,0,0,0,0,0,0,0,0,0,0,0,0,0,0,0,0,0,0,0,0,0,0,0
0,0,0,0,0,0,0,0,0,0,0,0,0,0,0,0,0,0,0,0,0,0,0,0,0,0,0
0,0,0,0,0,0,0,0,0,0,0,0,0,0,0,0,0,0,0,0,0,0,0,0,0,0,0
0,0,0,0,0,0,0,0,0,0,0,0,0,0,0,0,0,0,0,0,0,0,0,0,0,0,0
:endlayer
layer: 11
0,0,0,0,0,0,0,0,0,0,0,0,0,0,0,0,0,0,0,0,0,0,0,0,0,0,0
0,0,0,0,0,0,0,0,0,0,0,0,0,0,0,0,0,0,0,0,0,0,0,0,0,0,0
0,0,0,0,0,0,0,0,0,0,0,0,0,0,0,0,0,0,0,0,0,0,0,0,0,0,0
0,0,0,0,0,0,0,0,0,0,0,0,0,0,0,0,0,0,0,0,0,0,0,0,0,0,0
0,0,0,0,0,0,0,0,0,0,0,0,0,0,0,0,0,0,0,0,0,0,0,0,0,0,0
0,0,0,0,0,0,0,0,0,0,0,0,0,0,0,0,0,0,0,0,0,0,0,0,0,0,0
0,0,0,0,0,0,0,0,0,0,0,0,0,0,0,0,92,92,92,92,92,92,92,92,92,92,0
0,0,0,0,0,0,0,0,0,0,0,0,0,0,0,0,70,70,70,70,70,70,70,70,70,70,0
0,0,0,0,0,0,93,0,0,0,93,0,0,0,0,0,64,64,64,64,64,64,64,64,64,64,0
0,0,0,0,0,90,9,89,89,89,9,88,0,0,0,0,92,92,92,92,92,92,92,92,92,92,0
0,0,0,0,0,0,91,10,10,10,91,0,0,0,0,0,0,0,0,0,67,67,0,0,0,0,0
0,0,0,14,0,0,91,10,10,10,91,0,0,0,0,0,0,0,0,0,8,8,0,0,0,0,0
0,0,0,14,0,0,91,10,10,10,91,0,0,0,0,0,0,0,0,0,0,0,0,0,0,0,0
0,0,0,14,0,90,9,89,89,89,9,88,0,0,0,0,0,0,0,0,0,0,0,0,0,0,0
0,0,0,0,0,0,87,0,0,0,87,0,0,0,0,0,0,0,0,0,0,0,0,0,0,0,0
0,0,0,0,0,0,0,0,0,0,0,0,0,0,0,0,0,0,0,0,0,0,0,0,0,0,0
0,0,0,0,0,0,0,0,0,0,0,0,0,0,0,0,0,0,0,0,0,0,0,0,0,0,0
0,0,0,0,0,0,0,0,0,0,0,0,0,0,0,0,0,0,0,0,0,0,0,0,0,0,0
0,0,0,0,0,0,0,0,0,0,0,0,0,0,0,0,70,70,70,70,70,70,70,70,70,70,0
0,0,0,0,0,0,0,0,0,0,0,0,0,0,0,0,64,64,64,64,64,64,64,64,64,64,0
0,0,0,0,0,0,0,0,0,0,0,0,0,0,0,0,0,0,0,0,0,0,0,0,0,0,0
0,0,0,0,0,0,0,0,0,0,0,0,0,0,0,0,0,0,0,0,0,0,0,0,0,0,0
0,0,0,0,0,0,0,0,0,0,0,0,0,0,0,0,0,0,0,0,0,0,0,0,0,0,0
0,0,0,0,0,0,0,0,0,0,0,0,0,0,0,0,0,0,0,0,0,0,0,0,0,0,0
0,0,0,0,0,0,0,0,0,0,0,0,0,0,0,0,0,0,0,0,0,0,0,0,0,0,0
:endlayer
layer: 12
0,0,0,0,0,0,0,0,0,0,0,0,0,0,0,0,0,0,0,0,0,0,0,0,0,0,0
0,0,0,0,0,0,0,0,0,0,0,0,0,0,0,0,0,0,0,0,0,0,0,0,0,0,0
0,0,0,0,0,0,0,0,0,0,0,0,0,0,0,0,0,0,0,0,0,0,0,0,0,0,0
0,0,0,0,0,0,0,0,0,0,0,0,0,0,0,0,0,0,0,0,0,0,0,0,0,0,0
0,0,0,0,0,0,0,0,0,0,0,0,0,0,0,0,0,0,0,0,0,0,0,0,0,0,0
0,0,0,0,0,0,0,0,0,0,0,0,0,0,0,0,0,0,0,0,0,0,0,0,0,0,0
0,0,0,0,0,0,0,0,0,0,0,0,0,0,0,0,0,0,0,0,0,0,0,0,0,0,0
0,0,0,0,0,0,0,0,0,0,0,0,0,0,0,0,0,0,0,0,0,0,0,0,0,0,0
0,0,0,0,0,0,0,0,0,0,0,0,0,0,0,0,0,0,0,0,0,0,0,0,0,0,0
0,0,0,0,0,0,34,70,70,70,70,0,0,0,0,0,0,0,0,0,0,0,0,0,0,0,0
0,0,0,0,0,0,34,10,10,10,35,0,0,0,0,0,0,0,0,0,0,0,0,0,0,0,0
0,0,0,14,0,0,34,10,0,10,35,0,0,0,0,0,0,0,0,0,94,94,0,0,0,0,0
0,0,0,14,0,0,34,10,10,10,35,0,0,0,0,0,0,0,0,0,0,0,0,0,0,0,0
0,0,0,14,0,0,64,64,64,64,64,0,0,0,0,0,0,0,0,0,0,0,0,0,0,0,0
0,0,0,0,0,0,0,0,0,0,0,0,0,0,0,0,0,0,0,0,0,0,0,0,0,0,0
0,0,0,0,0,0,0,0,0,0,0,0,0,0,0,0,0,0,0,0,0,0,0,0,0,0,0
0,0,0,0,0,0,0,0,0,0,0,0,0,0,0,0,0,0,0,0,0,0,0,0,0,0,0
0,0,0,0,0,0,0,0,0,0,0,0,0,0,0,0,0,0,0,0,0,0,0,0,0,0,0
0,0,0,0,0,0,0,0,0,0,0,0,0,0,0,0,0,0,0,0,0,0,0,0,0,0,0
0,0,0,0,0,0,0,0,0,0,0,0,0,0,0,0,0,0,0,0,0,0,0,0,0,0,0
0,0,0,0,0,0,0,0,0,0,0,0,0,0,0,0,0,0,0,0,0,0,0,0,0,0,0
0,0,0,0,0,0,0,0,0,0,0,0,0,0,0,0,0,0,0,0,0,0,0,0,0,0,0
0,0,0,0,0,0,0,0,0,0,0,0,0,0,0,0,0,0,0,0,0,0,0,0,0,0,0
0,0,0,0,0,0,0,0,0,0,0,0,0,0,0,0,0,0,0,0,0,0,0,0,0,0,0
0,0,0,0,0,0,0,0,0,0,0,0,0,0,0,0,0,0,0,0,0,0,0,0,0,0,0
:endlayer
layer: 13
0,0,0,0,0,0,0,0,0,0,0,0,0,0,0,0,0,0,0,0,0,0,0,0,0,0,0
0,0,0,0,0,0,0,0,0,0,0,0,0,0,0,0,0,0,0,0,0,0,0,0,0,0,0
0,0,0,0,0,0,0,0,0,0,0,0,0,0,0,0,0,0,0,0,0,0,0,0,0,0,0
0,0,0,0,0,0,0,0,0,0,0,0,0,0,0,0,0,0,0,0,0,0,0,0,0,0,0
0,0,0,0,0,0,0,0,0,0,0,0,0,0,0,0,0,0,0,0,0,0,0,0,0,0,0
0,0,0,0,0,0,0,0,0,0,0,0,0,0,0,0,0,0,0,0,0,0,0,0,0,0,0
0,0,0,0,0,0,0,0,0,0,0,0,0,0,0,0,0,0,0,0,0,0,0,0,0,0,0
0,0,0,0,0,0,0,0,0,0,0,0,0,0,0,0,0,0,0,0,0,0,0,0,0,0,0
0,0,0,0,0,0,0,0,0,0,0,0,0,0,0,0,0,0,0,0,0,0,0,0,0,0,0
0,0,0,0,0,0,0,0,0,0,0,0,0,0,0,0,0,0,0,0,0,0,0,0,0,0,0
0,0,0,0,0,0,0,8,10,8,0,0,0,0,0,0,0,0,0,0,0,0,0,0,0,0,0
0,0,0,14,0,0,0,10,0,10,0,0,0,0,0,0,0,0,0,0,0,94,0,0,0,0,0
0,0,0,0,0,0,0,8,10,8,0,0,0,0,0,0,0,0,0,0,0,0,0,0,0,0,0
0,0,0,0,0,0,0,0,0,0,0,0,0,0,0,0,0,0,0,0,0,0,0,0,0,0,0
0,0,0,0,0,0,0,0,0,0,0,0,0,0,0,0,0,0,0,0,0,0,0,0,0,0,0
0,0,0,0,0,0,0,0,0,0,0,0,0,0,0,0,0,0,0,0,0,0,0,0,0,0,0
0,0,0,0,0,0,0,0,0,0,0,0,0,0,0,0,0,0,0,0,0,0,0,0,0,0,0
0,0,0,0,0,0,0,0,0,0,0,0,0,0,0,0,0,0,0,0,0,0,0,0,0,0,0
0,0,0,0,0,0,0,0,0,0,0,0,0,0,0,0,0,0,0,0,0,0,0,0,0,0,0
0,0,0,0,0,0,0,0,0,0,0,0,0,0,0,0,0,0,0,0,0,0,0,0,0,0,0
0,0,0,0,0,0,0,0,0,0,0,0,0,0,0,0,0,0,0,0,0,0,0,0,0,0,0
0,0,0,0,0,0,0,0,0,0,0,0,0,0,0,0,0,0,0,0,0,0,0,0,0,0,0
0,0,0,0,0,0,0,0,0,0,0,0,0,0,0,0,0,0,0,0,0,0,0,0,0,0,0
0,0,0,0,0,0,0,0,0,0,0,0,0,0,0,0,0,0,0,0,0,0,0,0,0,0,0
0,0,0,0,0,0,0,0,0,0,0,0,0,0,0,0,0,0,0,0,0,0,0,0,0,0,0
:endlayer
layer: 14
0,0,0,0,0,0,0,0,0,0,0,0,0,0,0,0,0,0,0,0,0,0,0,0,0,0,0
0,0,0,0,0,0,0,0,0,0,0,0,0,0,0,0,0,0,0,0,0,0,0,0,0,0,0
0,0,0,14,0,0,0,0,0,0,0,0,0,0,0,0,0,0,0,0,0,0,0,0,0,0,0
0,0,0,14,0,0,0,0,0,0,0,0,0,0,0,0,0,0,0,0,0,0,0,0,0,0,0
0,0,0,14,0,0,0,0,0,0,0,0,0,0,0,0,0,0,0,0,0,0,0,0,0,0,0
0,0,0,14,0,0,0,0,0,0,0,0,0,0,0,0,0,0,0,0,0,0,0,0,0,0,0
0,0,0,14,0,0,0,0,0,0,0,0,0,0,0,0,0,0,0,0,0,0,0,0,0,0,0
0,0,0,14,0,0,0,0,0,0,0,0,0,0,0,0,0,0,0,0,0,0,0,0,0,0,0
0,0,0,14,0,0,0,0,0,0,0,0,0,0,0,0,0,0,0,0,0,0,0,0,0,0,0
0,0,0,14,0,0,0,0,93,0,0,0,0,0,0,0,0,0,0,0,0,0,0,0,0,0,0
0,0,0,0,0,0,0,8,10,8,0,0,0,0,0,0,0,0,0,0,0,0,0,0,0,0,0
0,0,0,14,0,0,90,10,41,10,88,0,0,0,0,0,0,0,0,0,0,95,0,0,0,0,0
0,0,0,0,0,0,0,8,10,8,0,0,0,0,0,0,0,0,0,0,0,0,0,0,0,0,0
0,0,0,0,0,0,0,0,87,0,0,0,0,0,0,0,0,0,0,0,0,0,0,0,0,0,0
0,0,0,0,0,0,0,0,0,0,0,0,0,0,0,0,0,0,0,0,0,0,0,0,0,0,0
0,0,0,0,0,0,0,0,0,0,0,0,0,0,0,0,0,0,0,0,0,0,0,0,0,0,0
0,0,0,0,0,0,0,0,0,0,0,0,0,0,0,0,0,0,0,0,0,0,0,0,0,0,0
0,0,0,0,0,0,0,0,0,0,0,0,0,0,0,0,0,0,0,0,0,0,0,0,0,0,0
0,0,0,0,0,0,0,0,0,0,0,0,0,0,0,0,0,0,0,0,0,0,0,0,0,0,0
0,0,0,0,0,0,0,0,0,0,0,0,0,0,0,0,0,0,0,0,0,0,0,0,0,0,0
0,0,0,0,0,0,0,0,0,0,0,0,0,0,0,0,0,0,0,0,0,0,0,0,0,0,0
0,0,0,0,0,0,0,0,0,0,0,0,0,0,0,0,0,0,0,0,0,0,0,0,0,0,0
0,0,0,0,0,0,0,0,0,0,0,0,0,0,0,0,0,0,0,0,0,0,0,0,0,0,0
0,0,0,0,0,0,0,0,0,0,0,0,0,0,0,0,0,0,0,0,0,0,0,0,0,0,0
0,0,0,0,0,0,0,0,0,0,0,0,0,0,0,0,0,0,0,0,0,0,0,0,0,0,0
:endlayer
layer: 15
0,0,0,0,0,0,0,0,0,0,0,0,0,0,0,0,0,0,0,0,0,0,0,0,0,0,0
0,0,0,0,0,0,0,0,0,0,0,0,0,0,0,0,0,0,0,0,0,0,0,0,0,0,0
0,0,0,14,0,0,0,0,0,0,0,0,0,0,0,0,0,0,0,0,0,0,0,0,0,0,0
0,0,0,14,0,0,0,0,0,0,0,0,0,0,0,0,0,0,0,0,0,0,0,0,0,0,0
0,0,0,14,0,0,0,0,0,0,0,0,0,0,0,0,0,0,0,0,0,0,0,0,0,0,0
0,0,0,14,0,0,0,0,0,0,0,0,0,0,0,0,0,0,0,0,0,0,0,0,0,0,0
0,0,0,14,0,0,0,0,0,0,0,0,0,0,0,0,0,0,0,0,0,0,0,0,0,0,0
0,0,0,14,0,0,0,0,0,0,0,0,0,0,0,0,0,0,0,0,0,0,0,0,0,0,0
0,0,0,14,0,0,0,0,0,0,0,0,0,0,0,0,0,0,0,0,0,0,0,0,0,0,0
0,0,0,14,0,0,34,70,70,70,35,0,0,0,0,0,0,0,0,0,0,0,0,0,0,0,0
0,0,0,14,0,0,34,41,41,41,35,0,0,0,0,0,0,0,0,0,0,0,0,0,0,0,0
0,0,0,14,89,89,89,89,89,89,89,89,88,0,0,0,0,0,0,0,0,0,0,0,0,0,0
0,0,0,14,0,0,34,41,41,41,35,0,0,0,0,0,0,0,0,0,0,0,0,0,0,0,0
0,0,0,14,0,0,34,64,64,64,35,0,0,0,0,0,0,0,0,0,0,0,0,0,0,0,0
0,0,0,14,0,0,0,0,0,0,0,0,0,0,0,0,0,0,0,0,0,0,0,0,0,0,0
0,0,0,14,0,0,0,0,0,0,0,0,0,0,0,0,0,0,0,0,0,0,0,0,0,0,0
0,0,0,14,0,0,0,0,0,0,0,0,0,0,0,0,0,0,0,0,0,0,0,0,0,0,0
0,0,0,14,0,0,0,0,0,0,0,0,0,0,0,0,0,0,0,0,0,0,0,0,0,0,0
0,0,0,14,0,0,0,0,0,0,0,0,0,0,0,0,0,0,0,0,0,0,0,0,0,0,0
0,0,0,14,0,0,0,0,0,0,0,0,0,0,0,0,0,0,0,0,0,0,0,0,0,0,0
0,0,0,14,0,0,0,0,0,0,0,0,0,0,0,0,0,0,0,0,0,0,0,0,0,0,0
0,0,0,0,0,0,0,0,0,0,0,0,0,0,0,0,0,0,0,0,0,0,0,0,0,0,0
0,0,0,0,0,0,0,0,0,0,0,0,0,0,0,0,0,0,0,0,0,0,0,0,0,0,0
0,0,0,0,0,0,0,0,0,0,0,0,0,0,0,0,0,0,0,0,0,0,0,0,0,0,0
0,0,0,0,0,0,0,0,0,0,0,0,0,0,0,0,0,0,0,0,0,0,0,0,0,0,0
:endlayer
layer: 16
0,0,0,0,0,0,0,0,0,0,0,0,0,0,0,0,0,0,0,0,0,0,0,0,0,0,0
0,0,0,0,0,0,0,0,0,0,0,0,0,0,0,0,0,0,0,0,0,0,0,0,0,0,0
0,0,0,0,0,0,0,0,0,0,0,0,0,0,0,0,0,0,0,0,0,0,0,0,0,0,0
0,0,0,0,0,0,0,0,0,0,0,0,0,0,0,0,0,0,0,0,0,0,0,0,0,0,0
0,0,0,0,0,0,0,0,0,0,0,0,0,0,0,0,0,0,0,0,0,0,0,0,0,0,0
0,0,0,0,0,0,0,0,0,0,0,0,0,0,0,0,0,0,0,0,0,0,0,0,0,0,0
0,0,0,0,0,0,0,0,0,0,0,0,0,0,0,0,0,0,0,0,0,0,0,0,0,0,0
0,0,0,0,0,0,0,0,0,0,0,0,0,0,0,0,0,0,0,0,0,0,0,0,0,0,0
0,0,0,0,0,0,0,0,0,0,0,0,0,0,0,0,0,0,0,0,0,0,0,0,0,0,0
0,0,0,0,0,0,0,0,0,0,0,0,0,0,0,0,0,0,0,0,0,0,0,0,0,0,0
0,0,0,0,0,0,0,70,70,70,0,0,0,0,0,0,0,0,0,0,0,0,0,0,0,0,0
0,0,0,14,0,0,0,34,96,35,0,0,0,0,0,0,0,0,0,0,0,0,0,0,0,0,0
0,0,0,0,0,0,0,64,64,64,0,0,0,0,0,0,0,0,0,0,0,0,0,0,0,0,0
0,0,0,14,0,0,0,0,0,0,0,0,0,0,0,0,0,0,0,0,0,0,0,0,0,0,0
0,0,0,14,0,0,0,0,0,0,0,0,0,0,0,0,0,0,0,0,0,0,0,0,0,0,0
0,0,0,14,0,0,0,0,0,0,0,0,0,0,0,0,0,0,0,0,0,0,0,0,0,0,0
0,0,0,14,0,0,0,0,0,0,0,0,0,0,0,0,0,0,0,0,0,0,0,0,0,0,0
0,0,0,14,0,0,0,0,0,0,0,0,0,0,0,0,0,0,0,0,0,0,0,0,0,0,0
0,0,0,14,0,0,0,0,0,0,0,0,0,0,0,0,0,0,0,0,0,0,0,0,0,0,0
0,0,0,14,0,0,0,0,0,0,0,0,0,0,0,0,0,0,0,0,0,0,0,0,0,0,0
0,0,0,14,0,0,0,0,0,0,0,0,0,0,0,0,0,0,0,0,0,0,0,0,0,0,0
0,0,0,0,0,0,0,0,0,0,0,0,0,0,0,0,0,0,0,0,0,0,0,0,0,0,0
0,0,0,0,0,0,0,0,0,0,0,0,0,0,0,0,0,0,0,0,0,0,0,0,0,0,0
0,0,0,0,0,0,0,0,0,0,0,0,0,0,0,0,0,0,0,0,0,0,0,0,0,0,0
0,0,0,0,0,0,0,0,0,0,0,0,0,0,0,0,0,0,0,0,0,0,0,0,0,0,0
:endlayer
layer: 17
0,0,0,0,0,0,0,0,0,0,0,0,0,0,0,0,0,0,0,0,0,0,0,0,0,0,0
0,0,0,0,0,0,0,0,0,0,0,0,0,0,0,0,0,0,0,0,0,0,0,0,0,0,0
0,0,0,0,0,0,0,0,0,0,0,0,0,0,0,0,0,0,0,0,0,0,0,0,0,0,0
0,0,0,0,0,0,0,0,0,0,0,0,0,0,0,0,0,0,0,0,0,0,0,0,0,0,0
0,0,0,0,0,0,0,0,0,0,0,0,0,0,0,0,0,0,0,0,0,0,0,0,0,0,0
0,0,0,0,0,0,0,0,0,0,0,0,0,0,0,0,0,0,0,0,0,0,0,0,0,0,0
0,0,0,0,0,0,0,0,0,0,0,0,0,0,0,0,0,0,0,0,0,0,0,0,0,0,0
0,0,0,0,0,0,0,0,0,0,0,0,0,0,0,0,0,0,0,0,0,0,0,0,0,0,0
0,0,0,0,0,0,0,0,0,0,0,0,0,0,0,0,0,0,0,0,0,0,0,0,0,0,0
0,0,0,14,0,0,0,0,0,0,0,0,0,0,0,0,0,0,0,0,0,0,0,0,0,0,0
0,0,0,14,0,0,0,0,0,0,0,0,0,0,0,0,0,0,0,0,0,0,0,0,0,0,0
0,0,0,14,0,0,0,0,9,0,0,0,0,0,0,0,0,0,0,0,0,0,0,0,0,0,0
0,0,0,0,0,0,0,0,0,0,0,0,0,0,0,0,0,0,0,0,0,0,0,0,0,0,0
0,0,0,0,0,0,0,0,0,0,0,0,0,0,0,0,0,0,0,0,0,0,0,0,0,0,0
0,0,0,0,0,0,0,0,0,0,0,0,0,0,0,0,0,0,0,0,0,0,0,0,0,0,0
0,0,0,0,0,0,0,0,0,0,0,0,0,0,0,0,0,0,0,0,0,0,0,0,0,0,0
0,0,0,0,0,0,0,0,0,0,0,0,0,0,0,0,0,0,0,0,0,0,0,0,0,0,0
0,0,0,0,0,0,0,0,0,0,0,0,0,0,0,0,0,0,0,0,0,0,0,0,0,0,0
0,0,0,0,0,0,0,0,0,0,0,0,0,0,0,0,0,0,0,0,0,0,0,0,0,0,0
0,0,0,0,0,0,0,0,0,0,0,0,0,0,0,0,0,0,0,0,0,0,0,0,0,0,0
0,0,0,0,0,0,0,0,0,0,0,0,0,0,0,0,0,0,0,0,0,0,0,0,0,0,0
0,0,0,0,0,0,0,0,0,0,0,0,0,0,0,0,0,0,0,0,0,0,0,0,0,0,0
0,0,0,0,0,0,0,0,0,0,0,0,0,0,0,0,0,0,0,0,0,0,0,0,0,0,0
0,0,0,0,0,0,0,0,0,0,0,0,0,0,0,0,0,0,0,0,0,0,0,0,0,0,0
0,0,0,0,0,0,0,0,0,0,0,0,0,0,0,0,0,0,0,0,0,0,0,0,0,0,0
:endlayer
layer: 18
0,0,0,0,0,0,0,0,0,0,0,0,0,0,0,0,0,0,0,0,0,0,0,0,0,0,0
0,0,0,0,0,0,0,0,0,0,0,0,0,0,0,0,0,0,0,0,0,0,0,0,0,0,0
0,0,0,0,0,0,0,0,0,0,0,0,0,0,0,0,0,0,0,0,0,0,0,0,0,0,0
0,0,0,0,0,0,0,0,0,0,0,0,0,0,0,0,0,0,0,0,0,0,0,0,0,0,0
0,0,0,0,0,0,0,0,0,0,0,0,0,0,0,0,0,0,0,0,0,0,0,0,0,0,0
0,0,0,0,0,0,0,0,0,0,0,0,0,0,0,0,0,0,0,0,0,0,0,0,0,0,0
0,0,0,0,0,0,0,0,0,0,0,0,0,0,0,0,0,0,0,0,0,0,0,0,0,0,0
0,0,0,0,0,0,0,0,0,0,0,0,0,0,0,0,0,0,0,0,0,0,0,0,0,0,0
0,0,0,0,0,0,0,0,0,0,0,0,0,0,0,0,0,0,0,0,0,0,0,0,0,0,0
0,0,0,14,0,0,0,0,0,0,0,0,0,0,0,0,0,0,0,0,0,0,0,0,0,0,0
0,0,0,14,0,0,0,0,0,0,0,0,0,0,0,0,0,0,0,0,0,0,0,0,0,0,0
0,0,0,14,0,0,0,0,38,0,0,0,0,0,0,0,0,0,0,0,0,0,0,0,0,0,0
0,0,0,0,0,0,0,0,0,0,0,0,0,0,0,0,0,0,0,0,0,0,0,0,0,0,0
0,0,0,0,0,0,0,0,0,0,0,0,0,0,0,0,0,0,0,0,0,0,0,0,0,0,0
0,0,0,0,0,0,0,0,0,0,0,0,0,0,0,0,0,0,0,0,0,0,0,0,0,0,0
0,0,0,0,0,0,0,0,0,0,0,0,0,0,0,0,0,0,0,0,0,0,0,0,0,0,0
0,0,0,0,0,0,0,0,0,0,0,0,0,0,0,0,0,0,0,0,0,0,0,0,0,0,0
0,0,0,0,0,0,0,0,0,0,0,0,0,0,0,0,0,0,0,0,0,0,0,0,0,0,0
0,0,0,0,0,0,0,0,0,0,0,0,0,0,0,0,0,0,0,0,0,0,0,0,0,0,0
0,0,0,0,0,0,0,0,0,0,0,0,0,0,0,0,0,0,0,0,0,0,0,0,0,0,0
0,0,0,0,0,0,0,0,0,0,0,0,0,0,0,0,0,0,0,0,0,0,0,0,0,0,0
0,0,0,0,0,0,0,0,0,0,0,0,0,0,0,0,0,0,0,0,0,0,0,0,0,0,0
0,0,0,0,0,0,0,0,0,0,0,0,0,0,0,0,0,0,0,0,0,0,0,0,0,0,0
0,0,0,0,0,0,0,0,0,0,0,0,0,0,0,0,0,0,0,0,0,0,0,0,0,0,0
0,0,0,0,0,0,0,0,0,0,0,0,0,0,0,0,0,0,0,0,0,0,0,0,0,0,0
:endlayer
layer: 19
0,0,0,0,0,0,0,0,0,0,0,0,0,0,0,0,0,0,0,0,0,0,0,0,0,0,0
0,0,0,0,0,0,0,0,0,0,0,0,0,0,0,0,0,0,0,0,0,0,0,0,0,0,0
0,0,0,0,0,0,0,0,0,0,0,0,0,0,0,0,0,0,0,0,0,0,0,0,0,0,0
0,0,0,0,0,0,0,0,0,0,0,0,0,0,0,0,0,0,0,0,0,0,0,0,0,0,0
0,0,0,0,0,0,0,0,0,0,0,0,0,0,0,0,0,0,0,0,0,0,0,0,0,0,0
0,0,0,0,0,0,0,0,0,0,0,0,0,0,0,0,0,0,0,0,0,0,0,0,0,0,0
0,0,0,0,0,0,0,0,0,0,0,0,0,0,0,0,0,0,0,0,0,0,0,0,0,0,0
0,0,0,0,0,0,0,0,0,0,0,0,0,0,0,0,0,0,0,0,0,0,0,0,0,0,0
0,0,0,0,0,0,0,0,0,0,0,0,0,0,0,0,0,0,0,0,0,0,0,0,0,0,0
0,0,0,14,0,0,0,0,0,0,0,0,0,0,0,0,0,0,0,0,0,0,0,0,0,0,0
0,0,0,14,0,0,0,0,0,0,0,0,0,0,0,0,0,0,0,0,0,0,0,0,0,0,0
0,0,0,14,0,0,0,0,0,0,0,0,0,0,0,0,0,0,0,0,0,0,0,0,0,0,0
0,0,0,0,0,0,0,0,0,0,0,0,0,0,0,0,0,0,0,0,0,0,0,0,0,0,0
0,0,0,0,0,0,0,0,0,0,0,0,0,0,0,0,0,0,0,0,0,0,0,0,0,0,0
0,0,0,0,0,0,0,0,0,0,0,0,0,0,0,0,0,0,0,0,0,0,0,0,0,0,0
0,0,0,0,0,0,0,0,0,0,0,0,0,0,0,0,0,0,0,0,0,0,0,0,0,0,0
0,0,0,0,0,0,0,0,0,0,0,0,0,0,0,0,0,0,0,0,0,0,0,0,0,0,0
0,0,0,0,0,0,0,0,0,0,0,0,0,0,0,0,0,0,0,0,0,0,0,0,0,0,0
0,0,0,0,0,0,0,0,0,0,0,0,0,0,0,0,0,0,0,0,0,0,0,0,0,0,0
0,0,0,0,0,0,0,0,0,0,0,0,0,0,0,0,0,0,0,0,0,0,0,0,0,0,0
0,0,0,0,0,0,0,0,0,0,0,0,0,0,0,0,0,0,0,0,0,0,0,0,0,0,0
0,0,0,0,0,0,0,0,0,0,0,0,0,0,0,0,0,0,0,0,0,0,0,0,0,0,0
0,0,0,0,0,0,0,0,0,0,0,0,0,0,0,0,0,0,0,0,0,0,0,0,0,0,0
0,0,0,0,0,0,0,0,0,0,0,0,0,0,0,0,0,0,0,0,0,0,0,0,0,0,0
0,0,0,0,0,0,0,0,0,0,0,0,0,0,0,0,0,0,0,0,0,0,0,0,0,0,0
:endlayer
layer: 20
0,0,0,0,0,0,0,0,0,0,0,0,0,0,0,0,0,0,0,0,0,0,0,0,0,0,0
0,0,0,0,0,0,0,0,0,0,0,0,0,0,0,0,0,0,0,0,0,0,0,0,0,0,0
0,0,0,0,0,0,0,0,0,0,0,0,0,0,0,0,0,0,0,0,0,0,0,0,0,0,0
0,0,0,0,0,0,0,0,0,0,0,0,0,0,0,0,0,0,0,0,0,0,0,0,0,0,0
0,0,0,0,0,0,0,0,0,0,0,0,0,0,0,0,0,0,0,0,0,0,0,0,0,0,0
0,0,0,0,0,0,0,0,0,0,0,0,0,0,0,0,0,0,0,0,0,0,0,0,0,0,0
0,0,0,0,0,0,0,0,0,0,0,0,0,0,0,0,0,0,0,0,0,0,0,0,0,0,0
0,0,0,0,0,0,0,0,0,0,0,0,0,0,0,0,0,0,0,0,0,0,0,0,0,0,0
0,0,0,0,0,0,0,0,0,0,0,0,0,0,0,0,0,0,0,0,0,0,0,0,0,0,0
0,0,0,14,0,0,0,0,0,0,0,0,0,0,0,0,0,0,0,0,0,0,0,0,0,0,0
0,0,0,14,0,0,0,0,0,0,0,0,0,0,0,0,0,0,0,0,0,0,0,0,0,0,0
0,0,0,14,0,0,0,0,0,0,0,0,0,0,0,0,0,0,0,0,0,0,0,0,0,0,0
0,0,0,0,0,0,0,0,0,0,0,0,0,0,0,0,0,0,0,0,0,0,0,0,0,0,0
0,0,0,0,0,0,0,0,0,0,0,0,0,0,0,0,0,0,0,0,0,0,0,0,0,0,0
0,0,0,0,0,0,0,0,0,0,0,0,0,0,0,0,0,0,0,0,0,0,0,0,0,0,0
0,0,0,0,0,0,0,0,0,0,0,0,0,0,0,0,0,0,0,0,0,0,0,0,0,0,0
0,0,0,0,0,0,0,0,0,0,0,0,0,0,0,0,0,0,0,0,0,0,0,0,0,0,0
0,0,0,0,0,0,0,0,0,0,0,0,0,0,0,0,0,0,0,0,0,0,0,0,0,0,0
0,0,0,0,0,0,0,0,0,0,0,0,0,0,0,0,0,0,0,0,0,0,0,0,0,0,0
0,0,0,0,0,0,0,0,0,0,0,0,0,0,0,0,0,0,0,0,0,0,0,0,0,0,0
0,0,0,0,0,0,0,0,0,0,0,0,0,0,0,0,0,0,0,0,0,0,0,0,0,0,0
0,0,0,0,0,0,0,0,0,0,0,0,0,0,0,0,0,0,0,0,0,0,0,0,0,0,0
0,0,0,0,0,0,0,0,0,0,0,0,0,0,0,0,0,0,0,0,0,0,0,0,0,0,0
0,0,0,0,0,0,0,0,0,0,0,0,0,0,0,0,0,0,0,0,0,0,0,0,0,0,0
0,0,0,0,0,0,0,0,0,0,0,0,0,0,0,0,0,0,0,0,0,0,0,0,0,0,0
:endlayer
layer: 21
0,0,0,0,0,0,0,0,0,0,0,0,0,0,0,0,0,0,0,0,0,0,0,0,0,0,0
0,0,0,0,0,0,0,0,0,0,0,0,0,0,0,0,0,0,0,0,0,0,0,0,0,0,0
0,0,0,0,0,0,0,0,0,0,0,0,0,0,0,0,0,0,0,0,0,0,0,0,0,0,0
0,0,0,0,0,0,0,0,0,0,0,0,0,0,0,0,0,0,0,0,0,0,0,0,0,0,0
0,0,0,0,0,0,0,0,0,0,0,0,0,0,0,0,0,0,0,0,0,0,0,0,0,0,0
0,0,0,0,0,0,0,0,0,0,0,0,0,0,0,0,0,0,0,0,0,0,0,0,0,0,0
0,0,0,0,0,0,0,0,0,0,0,0,0,0,0,0,0,0,0,0,0,0,0,0,0,0,0
0,0,0,0,0,0,0,0,0,0,0,0,0,0,0,0,0,0,0,0,0,0,0,0,0,0,0
0,0,0,0,0,0,0,0,0,0,0,0,0,0,0,0,0,0,0,0,0,0,0,0,0,0,0
0,0,0,14,0,0,0,0,0,0,0,0,0,0,0,0,0,0,0,0,0,0,0,0,0,0,0
0,0,0,14,0,0,0,0,0,0,0,0,0,0,0,0,0,0,0,0,0,0,0,0,0,0,0
0,0,0,14,0,0,0,0,0,0,0,0,0,0,0,0,0,0,0,0,0,0,0,0,0,0,0
0,0,0,0,0,0,0,0,0,0,0,0,0,0,0,0,0,0,0,0,0,0,0,0,0,0,0
0,0,0,0,0,0,0,0,0,0,0,0,0,0,0,0,0,0,0,0,0,0,0,0,0,0,0
0,0,0,0,0,0,0,0,0,0,0,0,0,0,0,0,0,0,0,0,0,0,0,0,0,0,0
0,0,0,0,0,0,0,0,0,0,0,0,0,0,0,0,0,0,0,0,0,0,0,0,0,0,0
0,0,0,0,0,0,0,0,0,0,0,0,0,0,0,0,0,0,0,0,0,0,0,0,0,0,0
0,0,0,0,0,0,0,0,0,0,0,0,0,0,0,0,0,0,0,0,0,0,0,0,0,0,0
0,0,0,0,0,0,0,0,0,0,0,0,0,0,0,0,0,0,0,0,0,0,0,0,0,0,0
0,0,0,0,0,0,0,0,0,0,0,0,0,0,0,0,0,0,0,0,0,0,0,0,0,0,0
0,0,0,0,0,0,0,0,0,0,0,0,0,0,0,0,0,0,0,0,0,0,0,0,0,0,0
0,0,0,0,0,0,0,0,0,0,0,0,0,0,0,0,0,0,0,0,0,0,0,0,0,0,0
0,0,0,0,0,0,0,0,0,0,0,0,0,0,0,0,0,0,0,0,0,0,0,0,0,0,0
0,0,0,0,0,0,0,0,0,0,0,0,0,0,0,0,0,0,0,0,0,0,0,0,0,0,0
0,0,0,0,0,0,0,0,0,0,0,0,0,0,0,0,0,0,0,0,0,0,0,0,0,0,0
:endlayer
layer: 22
0,0,0,0,0,0,0,0,0,0,0,0,0,0,0,0,0,0,0,0,0,0,0,0,0,0,0
0,0,0,0,0,0,0,0,0,0,0,0,0,0,0,0,0,0,0,0,0,0,0,0,0,0,0
0,0,0,0,0,0,0,0,0,0,0,0,0,0,0,0,0,0,0,0,0,0,0,0,0,0,0
0,0,0,0,0,0,0,0,0,0,0,0,0,0,0,0,0,0,0,0,0,0,0,0,0,0,0
0,0,0,0,0,0,0,0,0,0,0,0,0,0,0,0,0,0,0,0,0,0,0,0,0,0,0
0,0,0,0,0,0,0,0,0,0,0,0,0,0,0,0,0,0,0,0,0,0,0,0,0,0,0
0,0,0,0,0,0,0,0,0,0,0,0,0,0,0,0,0,0,0,0,0,0,0,0,0,0,0
0,0,0,0,0,0,0,0,0,0,0,0,0,0,0,0,0,0,0,0,0,0,0,0,0,0,0
0,0,0,0,0,0,0,0,0,0,0,0,0,0,0,0,0,0,0,0,0,0,0,0,0,0,0
0,0,0,14,0,0,0,0,0,0,0,0,0,0,0,0,0,0,0,0,0,0,0,0,0,0,0
0,0,0,14,0,0,0,0,0,0,0,0,0,0,0,0,0,0,0,0,0,0,0,0,0,0,0
0,0,0,14,0,0,0,0,0,0,0,0,0,0,0,0,0,0,0,0,0,0,0,0,0,0,0
0,0,0,0,0,0,0,0,0,0,0,0,0,0,0,0,0,0,0,0,0,0,0,0,0,0,0
0,0,0,0,0,0,0,0,0,0,0,0,0,0,0,0,0,0,0,0,0,0,0,0,0,0,0
0,0,0,0,0,0,0,0,0,0,0,0,0,0,0,0,0,0,0,0,0,0,0,0,0,0,0
0,0,0,0,0,0,0,0,0,0,0,0,0,0,0,0,0,0,0,0,0,0,0,0,0,0,0
0,0,0,0,0,0,0,0,0,0,0,0,0,0,0,0,0,0,0,0,0,0,0,0,0,0,0
0,0,0,0,0,0,0,0,0,0,0,0,0,0,0,0,0,0,0,0,0,0,0,0,0,0,0
0,0,0,0,0,0,0,0,0,0,0,0,0,0,0,0,0,0,0,0,0,0,0,0,0,0,0
0,0,0,0,0,0,0,0,0,0,0,0,0,0,0,0,0,0,0,0,0,0,0,0,0,0,0
0,0,0,0,0,0,0,0,0,0,0,0,0,0,0,0,0,0,0,0,0,0,0,0,0,0,0
0,0,0,0,0,0,0,0,0,0,0,0,0,0,0,0,0,0,0,0,0,0,0,0,0,0,0
0,0,0,0,0,0,0,0,0,0,0,0,0,0,0,0,0,0,0,0,0,0,0,0,0,0,0
0,0,0,0,0,0,0,0,0,0,0,0,0,0,0,0,0,0,0,0,0,0,0,0,0,0,0
0,0,0,0,0,0,0,0,0,0,0,0,0,0,0,0,0,0,0,0,0,0,0,0,0,0,0
:endlayer
layer: 23
0,0,0,0,0,0,0,0,0,0,0,0,0,0,0,0,0,0,0,0,0,0,0,0,0,0,0
0,0,0,0,0,0,0,0,0,0,0,0,0,0,0,0,0,0,0,0,0,0,0,0,0,0,0
0,0,0,0,0,0,0,0,0,0,0,0,0,0,0,0,0,0,0,0,0,0,0,0,0,0,0
0,0,0,0,0,0,0,0,0,0,0,0,0,0,0,0,0,0,0,0,0,0,0,0,0,0,0
0,0,0,0,0,0,0,0,0,0,0,0,0,0,0,0,0,0,0,0,0,0,0,0,0,0,0
0,0,0,0,0,0,0,0,0,0,0,0,0,0,0,0,0,0,0,0,0,0,0,0,0,0,0
0,0,0,0,0,0,0,0,0,0,0,0,0,0,0,0,0,0,0,0,0,0,0,0,0,0,0
0,0,0,0,0,0,0,0,0,0,0,0,0,0,0,0,0,0,0,0,0,0,0,0,0,0,0
0,0,0,0,0,0,0,0,0,0,0,0,0,0,0,0,0,0,0,0,0,0,0,0,0,0,0
0,0,0,14,0,0,0,0,0,0,0,0,0,0,0,0,0,0,0,0,0,0,0,0,0,0,0
0,0,0,14,0,0,0,0,0,0,0,0,0,0,0,0,0,0,0,0,0,0,0,0,0,0,0
0,0,0,14,0,0,0,0,0,0,0,0,0,0,0,0,0,0,0,0,0,0,0,0,0,0,0
0,0,0,0,0,0,0,0,0,0,0,0,0,0,0,0,0,0,0,0,0,0,0,0,0,0,0
0,0,0,0,0,0,0,0,0,0,0,0,0,0,0,0,0,0,0,0,0,0,0,0,0,0,0
0,0,0,0,0,0,0,0,0,0,0,0,0,0,0,0,0,0,0,0,0,0,0,0,0,0,0
0,0,0,0,0,0,0,0,0,0,0,0,0,0,0,0,0,0,0,0,0,0,0,0,0,0,0
0,0,0,0,0,0,0,0,0,0,0,0,0,0,0,0,0,0,0,0,0,0,0,0,0,0,0
0,0,0,0,0,0,0,0,0,0,0,0,0,0,0,0,0,0,0,0,0,0,0,0,0,0,0
0,0,0,0,0,0,0,0,0,0,0,0,0,0,0,0,0,0,0,0,0,0,0,0,0,0,0
0,0,0,0,0,0,0,0,0,0,0,0,0,0,0,0,0,0,0,0,0,0,0,0,0,0,0
0,0,0,0,0,0,0,0,0,0,0,0,0,0,0,0,0,0,0,0,0,0,0,0,0,0,0
0,0,0,0,0,0,0,0,0,0,0,0,0,0,0,0,0,0,0,0,0,0,0,0,0,0,0
0,0,0,0,0,0,0,0,0,0,0,0,0,0,0,0,0,0,0,0,0,0,0,0,0,0,0
0,0,0,0,0,0,0,0,0,0,0,0,0,0,0,0,0,0,0,0,0,0,0,0,0,0,0
0,0,0,0,0,0,0,0,0,0,0,0,0,0,0,0,0,0,0,0,0,0,0,0,0,0,0
:endlayer

#### RULES ####
rule:
plugin=vanillaBlocks
number=1
data:
JSON:{blockState:{blockName:"minecraft:dirt",properties:{variant:"dirt",snowy:"false"}}}
:enddata
:endrule

rule:
plugin=vanillaBlocks
number=2
data:
JSON:{blockState:{blockName:"minecraft:grass",properties:{snowy:"false"}}}
:enddata
:endrule

rule:
plugin=vanillaBlocks
number=3
data:
JSON:{blockState:{blockName:"minecraft:gravel"}}
:enddata
:endrule

rule:
plugin=vanillaBlocks
number=4
data:
JSON:{blockState:{blockName:"minecraft:farmland",properties:{moisture:"7"}}}
:enddata
:endrule

rule:
plugin=vanillaBlocks
number=5
data:
JSON:{blockState:{blockName:"minecraft:farmland",properties:{moisture:"0"}}}
:enddata
:endrule

rule:
plugin=vanillaBlocks
number=6
data:
JSON:{blockState:{blockName:"minecraft:farmland",properties:{moisture:"6"}}}
:enddata
:endrule

rule:
plugin=vanillaBlocks
number=7
data:
JSON:{blockState:{blockName:"minecraft:farmland",properties:{moisture:"5"}}}
:enddata
:endrule

rule:
plugin=vanillaBlocks
number=8
data:
JSON:{blockState:{blockName:"minecraft:stonebrick",properties:{variant:"stonebrick"}}}
:enddata
:endrule

rule:
plugin=vanillaBlocks
number=9
data:
JSON:{blockState:{blockName:"minecraft:log",properties:{variant:"spruce",axis:"y"}}}
:enddata
:endrule

rule:
plugin=vanillaBlocks
number=10
data:
JSON:{blockState:{blockName:"minecraft:cobblestone"}}
:enddata
:endrule

rule:
plugin=vanillaBlocks
number=11
data:
JSON:{blockState:{blockName:"minecraft:mossy_cobblestone"}}
:enddata
:endrule

rule:
plugin=vanillaBlocks
number=12
data:
JSON:{blockState:{blockName:"minecraft:log",properties:{variant:"oak",axis:"y"}}}
:enddata
:endrule

rule:
plugin=vanillaBlocks
number=13
data:
JSON:{blockState:{blockName:"minecraft:tallgrass",properties:{type:"tall_grass"}}}
:enddata
:endrule

rule:
plugin=vanillaBlocks
number=14
data:
JSON:{blockState:{blockName:"minecraft:fence",properties:{east:"false",south:"false",north:"false",west:"false"}}}
:enddata
:endrule

rule:
plugin=vanillaBlocks
number=15
data:
JSON:{blockState:{blockName:"minecraft:fence_gate",properties:{in_wall:"false",powered:"false",facing:"north",open:"false"}}}
:enddata
:endrule

rule:
plugin=vanillaBlocks
number=16
data:
JSON:{blockState:{blockName:"minecraft:melon_block"}}
:enddata
:endrule

rule:
plugin=vanillaBlocks
number=17
data:
JSON:{blockState:{blockName:"minecraft:melon_stem",properties:{facing:"up",age:"7"}}}
:enddata
:endrule

rule:
plugin=vanillaBlocks
number=18
data:
JSON:{blockState:{blockName:"minecraft:pumpkin",properties:{facing:"north"}}}
:enddata
:endrule

rule:
plugin=blockTile
number=19
data:
JSON:{blockState:{blockName:"ancientwarfarestructure:advanced_spawner",properties:{transparent:"true"}},teData:{id:"ancientwarfarestructure:advanced_spawner_tile",spawnerSettings:{minDelay:0,spawnDelay:0,lightSensitive:0b,spawnGroups:[{settingsList:[{remainingSpawnCount:1,hostile:0b,forced:1b,customTag:{ArmorDropChances:[0.085f,0.085f,0.085f,0.085f],ArmorItems:[{},{},{},{}],HandDropChances:[0.085f,0.085f],HandItems:[{},{}]},maxToSpawn:1,entityId:"minecraft:cow",minToSpawn:1}],groupWeight:1}],playerRange:16,respondToRedstone:0b,inventory:{Size:9,Items:[]},spawnRange:0,transparent:1b,maxDelay:0,xpToDrop:0,mobRange:0,debugMode:0b,maxNearbyMonsters:0}}}
:enddata
:endrule

rule:
plugin=vanillaBlocks
number=20
data:
JSON:{blockState:{blockName:"minecraft:stone_stairs",properties:{half:"bottom",shape:"straight",facing:"east"}}}
:enddata
:endrule

rule:
plugin=vanillaBlocks
number=21
data:
JSON:{blockState:{blockName:"minecraft:pumpkin_stem",properties:{facing:"up",age:"7"}}}
:enddata
:endrule

rule:
plugin=blockTile
number=22
data:
JSON:{blockState:{blockName:"ancientwarfarestructure:advanced_spawner",properties:{transparent:"true"}},teData:{id:"ancientwarfarestructure:advanced_spawner_tile",spawnerSettings:{minDelay:0,spawnDelay:0,lightSensitive:0b,spawnGroups:[{settingsList:[{remainingSpawnCount:1,hostile:0b,forced:1b,customTag:{ArmorDropChances:[0.085f,0.085f,0.085f,0.085f],ArmorItems:[{},{},{},{}],HandDropChances:[0.085f,0.085f],HandItems:[{},{}]},maxToSpawn:1,entityId:"minecraft:cow",minToSpawn:1}],groupWeight:1}],playerRange:16,respondToRedstone:0b,inventory:{Size:9,Items:[]},spawnRange:0,transparent:1b,maxDelay:0,xpToDrop:0,mobRange:0,debugMode:0b,maxNearbyMonsters:0}}}
:enddata
:endrule

rule:
plugin=vanillaBlocks
number=23
data:
JSON:{blockState:{blockName:"minecraft:fence_gate",properties:{in_wall:"false",powered:"false",facing:"west",open:"false"}}}
:enddata
:endrule

rule:
plugin=inventory
number=24
data:
JSON:{blockState:{blockName:"minecraft:chest",properties:{facing:"north"}},lootLevel:0,teData:{ForgeData:{},Items:[{Slot:1b,id:"minecraft:wheat",Count:1b,Damage:0s},{Slot:3b,id:"minecraft:wheat",Count:1b,Damage:0s},{Slot:4b,id:"minecraft:wheat",Count:1b,Damage:0s},{Slot:6b,id:"minecraft:wheat",Count:1b,Damage:0s},{Slot:7b,id:"minecraft:wheat",Count:1b,Damage:0s},{Slot:9b,id:"minecraft:wheat",Count:1b,Damage:0s},{Slot:10b,id:"minecraft:wheat",Count:1b,Damage:0s},{Slot:11b,id:"minecraft:wheat",Count:1b,Damage:0s},{Slot:12b,id:"minecraft:wheat",Count:1b,Damage:0s},{Slot:14b,id:"minecraft:wheat",Count:1b,Damage:0s},{Slot:15b,id:"minecraft:wheat",Count:1b,Damage:0s},{Slot:17b,id:"minecraft:wheat",Count:1b,Damage:0s},{Slot:21b,id:"minecraft:wheat",Count:1b,Damage:0s},{Slot:22b,id:"minecraft:wheat",Count:1b,Damage:0s},{Slot:25b,id:"minecraft:wheat",Count:1b,Damage:0s}],id:"minecraft:chest",Lock:""},inventoryData:{length:15,inventoryContents:[{id:"minecraft:wheat",Count:1b,slot:0,Damage:0s},{id:"minecraft:wheat",Count:1b,slot:1,Damage:0s},{id:"minecraft:wheat",Count:1b,slot:2,Damage:0s},{id:"minecraft:wheat",Count:1b,slot:3,Damage:0s},{id:"minecraft:wheat",Count:1b,slot:4,Damage:0s},{id:"minecraft:wheat",Count:1b,slot:5,Damage:0s},{id:"minecraft:wheat",Count:1b,slot:6,Damage:0s},{id:"minecraft:wheat",Count:1b,slot:7,Damage:0s},{id:"minecraft:wheat",Count:1b,slot:8,Damage:0s},{id:"minecraft:wheat",Count:1b,slot:9,Damage:0s},{id:"minecraft:wheat",Count:1b,slot:10,Damage:0s},{id:"minecraft:wheat",Count:1b,slot:11,Damage:0s},{id:"minecraft:wheat",Count:1b,slot:12,Damage:0s},{id:"minecraft:wheat",Count:1b,slot:13,Damage:0s},{id:"minecraft:wheat",Count:1b,slot:14,Damage:0s}]},legacyFeatures:1b}
:enddata
:endrule

rule:
plugin=inventory
number=25
data:
JSON:{blockState:{blockName:"minecraft:chest",properties:{facing:"north"}},lootLevel:0,teData:{ForgeData:{},Items:[{Slot:1b,id:"minecraft:wheat",Count:2b,Damage:0s},{Slot:2b,id:"minecraft:wheat",Count:2b,Damage:0s},{Slot:3b,id:"minecraft:wheat",Count:1b,Damage:0s},{Slot:6b,id:"minecraft:wheat",Count:1b,Damage:0s},{Slot:7b,id:"minecraft:wheat",Count:2b,Damage:0s},{Slot:8b,id:"minecraft:wheat",Count:1b,Damage:0s},{Slot:10b,id:"minecraft:wheat",Count:1b,Damage:0s},{Slot:11b,id:"minecraft:wheat",Count:3b,Damage:0s},{Slot:12b,id:"minecraft:wheat",Count:2b,Damage:0s},{Slot:14b,id:"minecraft:wheat",Count:1b,Damage:0s},{Slot:17b,id:"minecraft:wheat",Count:1b,Damage:0s},{Slot:22b,id:"minecraft:wheat",Count:1b,Damage:0s},{Slot:24b,id:"minecraft:wheat",Count:1b,Damage:0s},{Slot:26b,id:"minecraft:wheat",Count:1b,Damage:0s}],id:"minecraft:chest",Lock:""},inventoryData:{length:14,inventoryContents:[{id:"minecraft:wheat",Count:2b,slot:0,Damage:0s},{id:"minecraft:wheat",Count:2b,slot:1,Damage:0s},{id:"minecraft:wheat",Count:1b,slot:2,Damage:0s},{id:"minecraft:wheat",Count:1b,slot:3,Damage:0s},{id:"minecraft:wheat",Count:2b,slot:4,Damage:0s},{id:"minecraft:wheat",Count:1b,slot:5,Damage:0s},{id:"minecraft:wheat",Count:1b,slot:6,Damage:0s},{id:"minecraft:wheat",Count:3b,slot:7,Damage:0s},{id:"minecraft:wheat",Count:2b,slot:8,Damage:0s},{id:"minecraft:wheat",Count:1b,slot:9,Damage:0s},{id:"minecraft:wheat",Count:1b,slot:10,Damage:0s},{id:"minecraft:wheat",Count:1b,slot:11,Damage:0s},{id:"minecraft:wheat",Count:1b,slot:12,Damage:0s},{id:"minecraft:wheat",Count:1b,slot:13,Damage:0s}]},legacyFeatures:1b}
:enddata
:endrule

rule:
plugin=vanillaBlocks
number=26
data:
JSON:{blockState:{blockName:"minecraft:cauldron",properties:{level:"3"}}}
:enddata
:endrule

rule:
plugin=inventory
number=27
data:
JSON:{blockState:{blockName:"minecraft:furnace",properties:{facing:"west"}},lootLevel:0,teData:{CookTime:0,BurnTime:0,Items:[{Slot:1b,id:"minecraft:coal",Count:4b,Damage:0s}],id:"minecraft:furnace",CookTimeTotal:0,Lock:""},inventoryData:{length:1,inventoryContents:[{id:"minecraft:coal",Count:4b,slot:0,Damage:0s}]},legacyFeatures:0b}
:enddata
:endrule

rule:
plugin=doors
number=28
data:
JSON:{blockState:{blockName:"minecraft:wooden_door",properties:{hinge:"left",half:"lower",powered:"false",facing:"south",open:"false"}}}
:enddata
:endrule

rule:
plugin=vanillaBlocks
number=29
data:
JSON:{blockState:{blockName:"minecraft:crafting_table"}}
:enddata
:endrule

rule:
plugin=blockTile
number=30
data:
JSON:{blockState:{blockName:"ancientwarfarestructure:advanced_spawner",properties:{transparent:"true"}},teData:{id:"ancientwarfarestructure:advanced_spawner_tile",spawnerSettings:{minDelay:0,spawnDelay:0,lightSensitive:0b,spawnGroups:[{settingsList:[{remainingSpawnCount:1,hostile:1b,forced:1b,customTag:{ArmorDropChances:[1.0f,1.0f,1.0f,1.0f],ArmorItems:[{},{},{},{}],HandDropChances:[1.0f,1.0f],factionName:"empire",HandItems:[{},{}]},maxToSpawn:1,entityId:"ancientwarfarenpc:faction.civilian.female",minToSpawn:1}],groupWeight:1}],playerRange:6,respondToRedstone:0b,inventory:{Size:9,Items:[]},spawnRange:0,transparent:1b,maxDelay:0,xpToDrop:0,mobRange:0,debugMode:0b,maxNearbyMonsters:0}}}
:enddata
:endrule

rule:
plugin=inventory
number=31
data:
JSON:{blockState:{blockName:"minecraft:chest",properties:{facing:"west"}},lootLevel:0,teData:{ForgeData:{},Items:[{Slot:2b,id:"minecraft:chicken",Count:2b,Damage:0s},{Slot:7b,id:"minecraft:apple",Count:1b,Damage:0s},{Slot:9b,id:"minecraft:beef",Count:3b,Damage:0s},{Slot:16b,id:"minecraft:porkchop",Count:3b,Damage:0s},{Slot:21b,id:"minecraft:apple",Count:1b,Damage:0s},{Slot:22b,id:"minecraft:bread",Count:6b,Damage:0s},{Slot:24b,id:"minecraft:porkchop",Count:1b,Damage:0s},{Slot:25b,id:"minecraft:porkchop",Count:1b,Damage:0s}],id:"minecraft:chest",Lock:""},inventoryData:{length:8,inventoryContents:[{id:"minecraft:chicken",Count:2b,slot:0,Damage:0s},{id:"minecraft:apple",Count:1b,slot:1,Damage:0s},{id:"minecraft:beef",Count:3b,slot:2,Damage:0s},{id:"minecraft:porkchop",Count:3b,slot:3,Damage:0s},{id:"minecraft:apple",Count:1b,slot:4,Damage:0s},{id:"minecraft:bread",Count:6b,slot:5,Damage:0s},{id:"minecraft:porkchop",Count:1b,slot:6,Damage:0s},{id:"minecraft:porkchop",Count:1b,slot:7,Damage:0s}]},legacyFeatures:1b}
:enddata
:endrule

rule:
plugin=vanillaBlocks
number=32
data:
JSON:{blockState:{blockName:"minecraft:stone_brick_stairs",properties:{half:"bottom",shape:"straight",facing:"south"}}}
:enddata
:endrule

rule:
plugin=blockTile
number=33
data:
JSON:{blockState:{blockName:"ancientwarfarestructure:advanced_spawner",properties:{transparent:"true"}},teData:{id:"ancientwarfarestructure:advanced_spawner_tile",spawnerSettings:{minDelay:0,spawnDelay:0,lightSensitive:0b,spawnGroups:[{settingsList:[{remainingSpawnCount:1,hostile:0b,forced:1b,customTag:{ArmorDropChances:[0.085f,0.085f,0.085f,0.085f],ArmorItems:[{},{},{},{}],HandDropChances:[0.085f,0.085f],HandItems:[{},{}]},maxToSpawn:1,entityId:"minecraft:cow",minToSpawn:1}],groupWeight:1}],playerRange:16,respondToRedstone:0b,inventory:{Size:9,Items:[]},spawnRange:0,transparent:1b,maxDelay:0,xpToDrop:0,mobRange:0,debugMode:0b,maxNearbyMonsters:0}}}
:enddata
:endrule

rule:
plugin=vanillaBlocks
number=34
data:
JSON:{blockState:{blockName:"minecraft:oak_stairs",properties:{half:"bottom",shape:"straight",facing:"east"}}}
:enddata
:endrule

rule:
plugin=vanillaBlocks
number=35
data:
JSON:{blockState:{blockName:"minecraft:oak_stairs",properties:{half:"bottom",shape:"straight",facing:"west"}}}
:enddata
:endrule

rule:
plugin=vanillaBlocks
number=36
data:
JSON:{blockState:{blockName:"minecraft:fence_gate",properties:{in_wall:"false",powered:"false",facing:"south",open:"false"}}}
:enddata
:endrule

rule:
plugin=vanillaBlocks
number=37
data:
JSON:{blockState:{blockName:"minecraft:yellow_flower",properties:{type:"dandelion"}}}
:enddata
:endrule

rule:
plugin=vanillaBlocks
number=38
data:
JSON:{blockState:{blockName:"minecraft:torch",properties:{facing:"up"}}}
:enddata
:endrule

rule:
plugin=vanillaBlocks
number=39
data:
JSON:{blockState:{blockName:"minecraft:log",properties:{variant:"oak",axis:"x"}}}
:enddata
:endrule

rule:
plugin=vanillaBlocks
number=40
data:
JSON:{blockState:{blockName:"minecraft:log",properties:{variant:"oak",axis:"z"}}}
:enddata
:endrule

rule:
plugin=vanillaBlocks
number=41
data:
JSON:{blockState:{blockName:"minecraft:planks",properties:{variant:"oak"}}}
:enddata
:endrule

rule:
plugin=vanillaBlocks
number=42
data:
JSON:{blockState:{blockName:"minecraft:glass_pane",properties:{east:"false",south:"false",north:"false",west:"false"}}}
:enddata
:endrule

rule:
plugin=vanillaBlocks
number=43
data:
JSON:{blockState:{blockName:"minecraft:stone_slab",properties:{half:"bottom",variant:"stone"}}}
:enddata
:endrule

rule:
plugin=vanillaBlocks
number=44
data:
JSON:{blockState:{blockName:"minecraft:iron_bars",properties:{east:"false",south:"false",north:"false",west:"false"}}}
:enddata
:endrule

rule:
plugin=doors
number=45
data:
JSON:{blockState:{blockName:"minecraft:wooden_door",properties:{hinge:"left",half:"upper",powered:"false",facing:"south",open:"false"}}}
:enddata
:endrule

rule:
plugin=vanillaSign
number=46
data:
JSON:{signContents0:"",blockState:{blockName:"minecraft:wall_sign",properties:{facing:"north"}},signContents2:"Mill§r§r",signContents1:"Traditional§r§r",signContents3:"",rotation:0}
:enddata
:endrule

rule:
plugin=vanillaBlocks
number=47
data:
JSON:{blockState:{blockName:"minecraft:glass"}}
:enddata
:endrule

rule:
plugin=vanillaBlocks
number=48
data:
JSON:{blockState:{blockName:"minecraft:wooden_pressure_plate",properties:{powered:"false"}}}
:enddata
:endrule

rule:
plugin=vanillaBlocks
number=49
data:
JSON:{blockState:{blockName:"minecraft:wooden_pressure_plate",properties:{powered:"true"}}}
:enddata
:endrule

rule:
plugin=inventory
number=50
data:
JSON:{blockState:{blockName:"minecraft:chest",properties:{facing:"west"}},lootLevel:0,teData:{Items:[{Slot:1b,id:"minecraft:wheat",Count:1b,Damage:0s},{Slot:9b,id:"minecraft:wheat",Count:1b,Damage:0s},{Slot:11b,id:"minecraft:wheat",Count:1b,Damage:0s},{Slot:12b,id:"minecraft:wheat",Count:1b,Damage:0s},{Slot:13b,id:"minecraft:wheat",Count:1b,Damage:0s},{Slot:14b,id:"minecraft:wheat",Count:1b,Damage:0s},{Slot:15b,id:"minecraft:wheat",Count:1b,Damage:0s},{Slot:17b,id:"minecraft:wheat",Count:1b,Damage:0s},{Slot:20b,id:"minecraft:wheat",Count:2b,Damage:0s},{Slot:22b,id:"minecraft:wheat",Count:1b,Damage:0s},{Slot:24b,id:"minecraft:wheat",Count:1b,Damage:0s}],id:"minecraft:chest",Lock:""},inventoryData:{length:11,inventoryContents:[{id:"minecraft:wheat",Count:1b,slot:0,Damage:0s},{id:"minecraft:wheat",Count:1b,slot:1,Damage:0s},{id:"minecraft:wheat",Count:1b,slot:2,Damage:0s},{id:"minecraft:wheat",Count:1b,slot:3,Damage:0s},{id:"minecraft:wheat",Count:1b,slot:4,Damage:0s},{id:"minecraft:wheat",Count:1b,slot:5,Damage:0s},{id:"minecraft:wheat",Count:1b,slot:6,Damage:0s},{id:"minecraft:wheat",Count:1b,slot:7,Damage:0s},{id:"minecraft:wheat",Count:2b,slot:8,Damage:0s},{id:"minecraft:wheat",Count:1b,slot:9,Damage:0s},{id:"minecraft:wheat",Count:1b,slot:10,Damage:0s}]},legacyFeatures:1b}
:enddata
:endrule

rule:
plugin=inventory
number=51
data:
JSON:{blockState:{blockName:"minecraft:chest",properties:{facing:"north"}},lootLevel:0,teData:{Items:[],id:"minecraft:chest",Lock:""},inventoryData:{length:0,inventoryContents:[]},legacyFeatures:1b}
:enddata
:endrule

rule:
plugin=inventory
number=52
data:
JSON:{blockState:{blockName:"minecraft:chest",properties:{facing:"north"}},lootLevel:0,teData:{Items:[],id:"minecraft:chest",Lock:""},inventoryData:{length:0,inventoryContents:[]},legacyFeatures:1b}
:enddata
:endrule

rule:
plugin=inventory
number=53
data:
JSON:{blockState:{blockName:"minecraft:chest",properties:{facing:"east"}},lootLevel:0,teData:{Items:[{Slot:2b,id:"minecraft:melon_seeds",Count:1b,Damage:0s},{Slot:5b,id:"minecraft:melon_seeds",Count:1b,Damage:0s},{Slot:6b,id:"minecraft:melon_seeds",Count:1b,Damage:0s},{Slot:7b,id:"minecraft:melon_seeds",Count:2b,Damage:0s},{Slot:9b,id:"minecraft:melon_seeds",Count:1b,Damage:0s},{Slot:11b,id:"minecraft:melon_seeds",Count:1b,Damage:0s},{Slot:12b,id:"minecraft:melon_seeds",Count:2b,Damage:0s},{Slot:13b,id:"minecraft:melon_seeds",Count:1b,Damage:0s},{Slot:14b,id:"minecraft:melon_seeds",Count:1b,Damage:0s},{Slot:15b,id:"minecraft:melon_seeds",Count:1b,Damage:0s},{Slot:16b,id:"minecraft:melon_seeds",Count:2b,Damage:0s},{Slot:18b,id:"minecraft:melon_seeds",Count:1b,Damage:0s},{Slot:19b,id:"minecraft:melon_seeds",Count:1b,Damage:0s},{Slot:20b,id:"minecraft:melon_seeds",Count:1b,Damage:0s},{Slot:21b,id:"minecraft:melon_seeds",Count:2b,Damage:0s},{Slot:24b,id:"minecraft:melon_seeds",Count:1b,Damage:0s},{Slot:25b,id:"minecraft:melon_seeds",Count:1b,Damage:0s}],id:"minecraft:chest",Lock:""},inventoryData:{length:17,inventoryContents:[{id:"minecraft:melon_seeds",Count:1b,slot:0,Damage:0s},{id:"minecraft:melon_seeds",Count:1b,slot:1,Damage:0s},{id:"minecraft:melon_seeds",Count:1b,slot:2,Damage:0s},{id:"minecraft:melon_seeds",Count:2b,slot:3,Damage:0s},{id:"minecraft:melon_seeds",Count:1b,slot:4,Damage:0s},{id:"minecraft:melon_seeds",Count:1b,slot:5,Damage:0s},{id:"minecraft:melon_seeds",Count:2b,slot:6,Damage:0s},{id:"minecraft:melon_seeds",Count:1b,slot:7,Damage:0s},{id:"minecraft:melon_seeds",Count:1b,slot:8,Damage:0s},{id:"minecraft:melon_seeds",Count:1b,slot:9,Damage:0s},{id:"minecraft:melon_seeds",Count:2b,slot:10,Damage:0s},{id:"minecraft:melon_seeds",Count:1b,slot:11,Damage:0s},{id:"minecraft:melon_seeds",Count:1b,slot:12,Damage:0s},{id:"minecraft:melon_seeds",Count:1b,slot:13,Damage:0s},{id:"minecraft:melon_seeds",Count:2b,slot:14,Damage:0s},{id:"minecraft:melon_seeds",Count:1b,slot:15,Damage:0s},{id:"minecraft:melon_seeds",Count:1b,slot:16,Damage:0s}]},legacyFeatures:1b}
:enddata
:endrule

rule:
plugin=inventory
number=54
data:
JSON:{blockState:{blockName:"minecraft:chest",properties:{facing:"west"}},lootLevel:0,teData:{ForgeData:{},Items:[{Slot:0b,id:"minecraft:wheat",Count:1b,Damage:0s},{Slot:2b,id:"minecraft:wheat",Count:2b,Damage:0s},{Slot:3b,id:"minecraft:wheat",Count:1b,Damage:0s},{Slot:4b,id:"minecraft:wheat",Count:1b,Damage:0s},{Slot:5b,id:"minecraft:wheat",Count:1b,Damage:0s},{Slot:6b,id:"minecraft:wheat",Count:1b,Damage:0s},{Slot:7b,id:"minecraft:wheat",Count:1b,Damage:0s},{Slot:9b,id:"minecraft:wheat",Count:1b,Damage:0s},{Slot:10b,id:"minecraft:wheat",Count:1b,Damage:0s},{Slot:11b,id:"minecraft:wheat",Count:1b,Damage:0s},{Slot:12b,id:"minecraft:wheat",Count:2b,Damage:0s},{Slot:14b,id:"minecraft:wheat",Count:1b,Damage:0s},{Slot:15b,id:"minecraft:wheat",Count:1b,Damage:0s},{Slot:16b,id:"minecraft:wheat",Count:1b,Damage:0s},{Slot:20b,id:"minecraft:wheat",Count:1b,Damage:0s}],id:"minecraft:chest",Lock:""},inventoryData:{length:15,inventoryContents:[{id:"minecraft:wheat",Count:1b,slot:0,Damage:0s},{id:"minecraft:wheat",Count:2b,slot:1,Damage:0s},{id:"minecraft:wheat",Count:1b,slot:2,Damage:0s},{id:"minecraft:wheat",Count:1b,slot:3,Damage:0s},{id:"minecraft:wheat",Count:1b,slot:4,Damage:0s},{id:"minecraft:wheat",Count:1b,slot:5,Damage:0s},{id:"minecraft:wheat",Count:1b,slot:6,Damage:0s},{id:"minecraft:wheat",Count:1b,slot:7,Damage:0s},{id:"minecraft:wheat",Count:1b,slot:8,Damage:0s},{id:"minecraft:wheat",Count:1b,slot:9,Damage:0s},{id:"minecraft:wheat",Count:2b,slot:10,Damage:0s},{id:"minecraft:wheat",Count:1b,slot:11,Damage:0s},{id:"minecraft:wheat",Count:1b,slot:12,Damage:0s},{id:"minecraft:wheat",Count:1b,slot:13,Damage:0s},{id:"minecraft:wheat",Count:1b,slot:14,Damage:0s}]},legacyFeatures:1b}
:enddata
:endrule

rule:
plugin=inventory
number=55
data:
JSON:{blockState:{blockName:"minecraft:chest",properties:{facing:"east"}},lootLevel:0,teData:{ForgeData:{},Items:[{Slot:1b,id:"minecraft:melon_seeds",Count:1b,Damage:0s},{Slot:2b,id:"minecraft:melon_seeds",Count:1b,Damage:0s},{Slot:3b,id:"minecraft:melon_seeds",Count:2b,Damage:0s},{Slot:4b,id:"minecraft:melon_seeds",Count:1b,Damage:0s},{Slot:5b,id:"minecraft:melon_seeds",Count:1b,Damage:0s},{Slot:8b,id:"minecraft:melon_seeds",Count:1b,Damage:0s},{Slot:9b,id:"minecraft:melon_seeds",Count:1b,Damage:0s},{Slot:10b,id:"minecraft:melon_seeds",Count:2b,Damage:0s},{Slot:11b,id:"minecraft:melon_seeds",Count:1b,Damage:0s},{Slot:14b,id:"minecraft:melon_seeds",Count:1b,Damage:0s},{Slot:15b,id:"minecraft:melon_seeds",Count:1b,Damage:0s},{Slot:16b,id:"minecraft:melon_seeds",Count:2b,Damage:0s},{Slot:18b,id:"minecraft:melon_seeds",Count:2b,Damage:0s},{Slot:19b,id:"minecraft:melon_seeds",Count:1b,Damage:0s},{Slot:20b,id:"minecraft:melon_seeds",Count:1b,Damage:0s},{Slot:22b,id:"minecraft:melon_seeds",Count:1b,Damage:0s},{Slot:23b,id:"minecraft:melon_seeds",Count:1b,Damage:0s},{Slot:25b,id:"minecraft:melon_seeds",Count:1b,Damage:0s}],id:"minecraft:chest",Lock:""},inventoryData:{length:18,inventoryContents:[{id:"minecraft:melon_seeds",Count:1b,slot:0,Damage:0s},{id:"minecraft:melon_seeds",Count:1b,slot:1,Damage:0s},{id:"minecraft:melon_seeds",Count:2b,slot:2,Damage:0s},{id:"minecraft:melon_seeds",Count:1b,slot:3,Damage:0s},{id:"minecraft:melon_seeds",Count:1b,slot:4,Damage:0s},{id:"minecraft:melon_seeds",Count:1b,slot:5,Damage:0s},{id:"minecraft:melon_seeds",Count:1b,slot:6,Damage:0s},{id:"minecraft:melon_seeds",Count:2b,slot:7,Damage:0s},{id:"minecraft:melon_seeds",Count:1b,slot:8,Damage:0s},{id:"minecraft:melon_seeds",Count:1b,slot:9,Damage:0s},{id:"minecraft:melon_seeds",Count:1b,slot:10,Damage:0s},{id:"minecraft:melon_seeds",Count:2b,slot:11,Damage:0s},{id:"minecraft:melon_seeds",Count:2b,slot:12,Damage:0s},{id:"minecraft:melon_seeds",Count:1b,slot:13,Damage:0s},{id:"minecraft:melon_seeds",Count:1b,slot:14,Damage:0s},{id:"minecraft:melon_seeds",Count:1b,slot:15,Damage:0s},{id:"minecraft:melon_seeds",Count:1b,slot:16,Damage:0s},{id:"minecraft:melon_seeds",Count:1b,slot:17,Damage:0s}]},legacyFeatures:1b}
:enddata
:endrule

rule:
plugin=doors
number=56
data:
JSON:{blockState:{blockName:"minecraft:wooden_door",properties:{hinge:"left",half:"lower",powered:"false",facing:"east",open:"false"}}}
:enddata
:endrule

rule:
plugin=inventory
number=57
data:
JSON:{blockState:{blockName:"minecraft:chest",properties:{facing:"west"}},lootLevel:0,teData:{ForgeData:{},Items:[{Slot:3b,id:"minecraft:wheat",Count:1b,Damage:0s},{Slot:4b,id:"minecraft:wheat",Count:1b,Damage:0s},{Slot:11b,id:"minecraft:wheat",Count:1b,Damage:0s},{Slot:12b,id:"minecraft:wheat",Count:1b,Damage:0s},{Slot:14b,id:"minecraft:wheat",Count:1b,Damage:0s},{Slot:15b,id:"minecraft:wheat",Count:2b,Damage:0s},{Slot:16b,id:"minecraft:wheat",Count:1b,Damage:0s},{Slot:20b,id:"minecraft:wheat",Count:1b,Damage:0s},{Slot:24b,id:"minecraft:wheat",Count:1b,Damage:0s},{Slot:25b,id:"minecraft:wheat",Count:1b,Damage:0s}],id:"minecraft:chest",Lock:""},inventoryData:{length:10,inventoryContents:[{id:"minecraft:wheat",Count:1b,slot:0,Damage:0s},{id:"minecraft:wheat",Count:1b,slot:1,Damage:0s},{id:"minecraft:wheat",Count:1b,slot:2,Damage:0s},{id:"minecraft:wheat",Count:1b,slot:3,Damage:0s},{id:"minecraft:wheat",Count:1b,slot:4,Damage:0s},{id:"minecraft:wheat",Count:2b,slot:5,Damage:0s},{id:"minecraft:wheat",Count:1b,slot:6,Damage:0s},{id:"minecraft:wheat",Count:1b,slot:7,Damage:0s},{id:"minecraft:wheat",Count:1b,slot:8,Damage:0s},{id:"minecraft:wheat",Count:1b,slot:9,Damage:0s}]},legacyFeatures:1b}
:enddata
:endrule

rule:
plugin=inventory
number=58
data:
JSON:{blockState:{blockName:"minecraft:chest",properties:{facing:"east"}},lootLevel:0,teData:{Items:[],id:"minecraft:chest",Lock:""},inventoryData:{length:0,inventoryContents:[]},legacyFeatures:1b}
:enddata
:endrule

rule:
plugin=inventory
number=59
data:
JSON:{blockState:{blockName:"minecraft:chest",properties:{facing:"west"}},lootLevel:0,teData:{Items:[{Slot:2b,id:"minecraft:wheat",Count:1b,Damage:0s},{Slot:4b,id:"minecraft:wheat",Count:1b,Damage:0s},{Slot:10b,id:"minecraft:wheat",Count:1b,Damage:0s},{Slot:14b,id:"minecraft:wheat",Count:1b,Damage:0s},{Slot:15b,id:"minecraft:wheat",Count:1b,Damage:0s},{Slot:16b,id:"minecraft:wheat",Count:1b,Damage:0s},{Slot:19b,id:"minecraft:wheat",Count:1b,Damage:0s},{Slot:23b,id:"minecraft:wheat",Count:1b,Damage:0s},{Slot:25b,id:"minecraft:wheat",Count:1b,Damage:0s}],id:"minecraft:chest",Lock:""},inventoryData:{length:9,inventoryContents:[{id:"minecraft:wheat",Count:1b,slot:0,Damage:0s},{id:"minecraft:wheat",Count:1b,slot:1,Damage:0s},{id:"minecraft:wheat",Count:1b,slot:2,Damage:0s},{id:"minecraft:wheat",Count:1b,slot:3,Damage:0s},{id:"minecraft:wheat",Count:1b,slot:4,Damage:0s},{id:"minecraft:wheat",Count:1b,slot:5,Damage:0s},{id:"minecraft:wheat",Count:1b,slot:6,Damage:0s},{id:"minecraft:wheat",Count:1b,slot:7,Damage:0s},{id:"minecraft:wheat",Count:1b,slot:8,Damage:0s}]},legacyFeatures:1b}
:enddata
:endrule

rule:
plugin=inventory
number=60
data:
JSON:{blockState:{blockName:"minecraft:chest",properties:{facing:"south"}},lootLevel:0,teData:{Items:[{Slot:4b,id:"minecraft:melon",Count:1b,Damage:0s},{Slot:5b,id:"minecraft:melon",Count:1b,Damage:0s},{Slot:6b,id:"minecraft:melon",Count:1b,Damage:0s},{Slot:7b,id:"minecraft:melon",Count:1b,Damage:0s},{Slot:10b,id:"minecraft:melon",Count:2b,Damage:0s},{Slot:11b,id:"minecraft:melon",Count:1b,Damage:0s},{Slot:12b,id:"minecraft:melon",Count:2b,Damage:0s},{Slot:13b,id:"minecraft:melon",Count:1b,Damage:0s},{Slot:20b,id:"minecraft:melon",Count:1b,Damage:0s},{Slot:21b,id:"minecraft:melon",Count:1b,Damage:0s},{Slot:22b,id:"minecraft:melon",Count:2b,Damage:0s},{Slot:23b,id:"minecraft:melon",Count:1b,Damage:0s},{Slot:25b,id:"minecraft:melon",Count:1b,Damage:0s}],id:"minecraft:chest",Lock:""},inventoryData:{length:13,inventoryContents:[{id:"minecraft:melon",Count:1b,slot:0,Damage:0s},{id:"minecraft:melon",Count:1b,slot:1,Damage:0s},{id:"minecraft:melon",Count:1b,slot:2,Damage:0s},{id:"minecraft:melon",Count:1b,slot:3,Damage:0s},{id:"minecraft:melon",Count:2b,slot:4,Damage:0s},{id:"minecraft:melon",Count:1b,slot:5,Damage:0s},{id:"minecraft:melon",Count:2b,slot:6,Damage:0s},{id:"minecraft:melon",Count:1b,slot:7,Damage:0s},{id:"minecraft:melon",Count:1b,slot:8,Damage:0s},{id:"minecraft:melon",Count:1b,slot:9,Damage:0s},{id:"minecraft:melon",Count:2b,slot:10,Damage:0s},{id:"minecraft:melon",Count:1b,slot:11,Damage:0s},{id:"minecraft:melon",Count:1b,slot:12,Damage:0s}]},legacyFeatures:1b}
:enddata
:endrule

rule:
plugin=inventory
number=61
data:
JSON:{blockState:{blockName:"minecraft:chest",properties:{facing:"south"}},lootLevel:0,teData:{ForgeData:{},Items:[{Slot:1b,id:"minecraft:melon",Count:1b,Damage:0s},{Slot:2b,id:"minecraft:melon",Count:1b,Damage:0s},{Slot:4b,id:"minecraft:melon",Count:1b,Damage:0s},{Slot:7b,id:"minecraft:melon",Count:1b,Damage:0s},{Slot:11b,id:"minecraft:melon",Count:1b,Damage:0s},{Slot:14b,id:"minecraft:melon",Count:1b,Damage:0s},{Slot:15b,id:"minecraft:melon",Count:2b,Damage:0s},{Slot:20b,id:"minecraft:melon",Count:1b,Damage:0s}],id:"minecraft:chest",Lock:""},inventoryData:{length:8,inventoryContents:[{id:"minecraft:melon",Count:1b,slot:0,Damage:0s},{id:"minecraft:melon",Count:1b,slot:1,Damage:0s},{id:"minecraft:melon",Count:1b,slot:2,Damage:0s},{id:"minecraft:melon",Count:1b,slot:3,Damage:0s},{id:"minecraft:melon",Count:1b,slot:4,Damage:0s},{id:"minecraft:melon",Count:1b,slot:5,Damage:0s},{id:"minecraft:melon",Count:2b,slot:6,Damage:0s},{id:"minecraft:melon",Count:1b,slot:7,Damage:0s}]},legacyFeatures:1b}
:enddata
:endrule

rule:
plugin=inventory
number=62
data:
JSON:{blockState:{blockName:"minecraft:chest",properties:{facing:"east"}},lootLevel:0,teData:{Items:[],id:"minecraft:chest",Lock:""},inventoryData:{length:0,inventoryContents:[]},legacyFeatures:1b}
:enddata
:endrule

rule:
plugin=vanillaBlocks
number=63
data:
JSON:{blockState:{blockName:"minecraft:torch",properties:{facing:"south"}}}
:enddata
:endrule

rule:
plugin=vanillaBlocks
number=64
data:
JSON:{blockState:{blockName:"minecraft:oak_stairs",properties:{half:"bottom",shape:"straight",facing:"north"}}}
:enddata
:endrule

rule:
plugin=vanillaBlocks
number=65
data:
JSON:{blockState:{blockName:"minecraft:torch",properties:{facing:"east"}}}
:enddata
:endrule

rule:
plugin=vanillaBlocks
number=66
data:
JSON:{blockState:{blockName:"minecraft:torch",properties:{facing:"west"}}}
:enddata
:endrule

rule:
plugin=vanillaBlocks
number=67
data:
JSON:{blockState:{blockName:"minecraft:torch",properties:{facing:"north"}}}
:enddata
:endrule

rule:
plugin=vanillaBlocks
number=68
data:
JSON:{blockState:{blockName:"minecraft:stone_slab",properties:{half:"top",variant:"stone"}}}
:enddata
:endrule

rule:
plugin=vanillaSign
number=69
data:
JSON:{signContents0:"",blockState:{blockName:"minecraft:wall_sign",properties:{facing:"west"}},signContents2:"Miller§r§r",signContents1:"Windy§r§r",signContents3:"",rotation:0}
:enddata
:endrule

rule:
plugin=vanillaBlocks
number=70
data:
JSON:{blockState:{blockName:"minecraft:oak_stairs",properties:{half:"bottom",shape:"straight",facing:"south"}}}
:enddata
:endrule

rule:
plugin=vanillaBlocks
number=71
data:
JSON:{blockState:{blockName:"minecraft:wooden_slab",properties:{half:"top",variant:"oak"}}}
:enddata
:endrule

rule:
plugin=doors
number=72
data:
JSON:{blockState:{blockName:"minecraft:wooden_door",properties:{hinge:"right",half:"upper",powered:"false",facing:"south",open:"false"}}}
:enddata
:endrule

rule:
plugin=vanillaSign
number=73
data:
JSON:{signContents0:"",blockState:{blockName:"minecraft:wall_sign",properties:{facing:"west"}},signContents2:"Store§r§r",signContents1:"Grain§r§r",signContents3:"",rotation:0}
:enddata
:endrule

rule:
plugin=vanillaBlocks
number=74
data:
JSON:{blockState:{blockName:"minecraft:wooden_slab",properties:{half:"bottom",variant:"oak"}}}
:enddata
:endrule

rule:
plugin=inventory
number=75
data:
JSON:{blockState:{blockName:"minecraft:chest",properties:{facing:"west"}},lootLevel:0,teData:{ForgeData:{},Items:[{Slot:1b,id:"minecraft:wheat_seeds",Count:1b,Damage:0s},{Slot:2b,id:"minecraft:wheat_seeds",Count:1b,Damage:0s},{Slot:3b,id:"minecraft:wheat_seeds",Count:1b,Damage:0s},{Slot:4b,id:"minecraft:wheat_seeds",Count:2b,Damage:0s},{Slot:11b,id:"minecraft:wheat_seeds",Count:1b,Damage:0s},{Slot:12b,id:"minecraft:wheat_seeds",Count:1b,Damage:0s},{Slot:13b,id:"minecraft:wheat_seeds",Count:1b,Damage:0s},{Slot:14b,id:"minecraft:wheat_seeds",Count:2b,Damage:0s},{Slot:15b,id:"minecraft:wheat_seeds",Count:1b,Damage:0s},{Slot:16b,id:"minecraft:wheat_seeds",Count:1b,Damage:0s},{Slot:17b,id:"minecraft:wheat_seeds",Count:1b,Damage:0s},{Slot:18b,id:"minecraft:wheat_seeds",Count:1b,Damage:0s},{Slot:19b,id:"minecraft:wheat_seeds",Count:1b,Damage:0s},{Slot:21b,id:"minecraft:wheat_seeds",Count:1b,Damage:0s},{Slot:23b,id:"minecraft:wheat_seeds",Count:1b,Damage:0s},{Slot:24b,id:"minecraft:wheat_seeds",Count:1b,Damage:0s},{Slot:25b,id:"minecraft:wheat_seeds",Count:1b,Damage:0s},{Slot:26b,id:"minecraft:wheat_seeds",Count:1b,Damage:0s}],id:"minecraft:chest",Lock:""},inventoryData:{length:18,inventoryContents:[{id:"minecraft:wheat_seeds",Count:1b,slot:0,Damage:0s},{id:"minecraft:wheat_seeds",Count:1b,slot:1,Damage:0s},{id:"minecraft:wheat_seeds",Count:1b,slot:2,Damage:0s},{id:"minecraft:wheat_seeds",Count:2b,slot:3,Damage:0s},{id:"minecraft:wheat_seeds",Count:1b,slot:4,Damage:0s},{id:"minecraft:wheat_seeds",Count:1b,slot:5,Damage:0s},{id:"minecraft:wheat_seeds",Count:1b,slot:6,Damage:0s},{id:"minecraft:wheat_seeds",Count:2b,slot:7,Damage:0s},{id:"minecraft:wheat_seeds",Count:1b,slot:8,Damage:0s},{id:"minecraft:wheat_seeds",Count:1b,slot:9,Damage:0s},{id:"minecraft:wheat_seeds",Count:1b,slot:10,Damage:0s},{id:"minecraft:wheat_seeds",Count:1b,slot:11,Damage:0s},{id:"minecraft:wheat_seeds",Count:1b,slot:12,Damage:0s},{id:"minecraft:wheat_seeds",Count:1b,slot:13,Damage:0s},{id:"minecraft:wheat_seeds",Count:1b,slot:14,Damage:0s},{id:"minecraft:wheat_seeds",Count:1b,slot:15,Damage:0s},{id:"minecraft:wheat_seeds",Count:1b,slot:16,Damage:0s},{id:"minecraft:wheat_seeds",Count:1b,slot:17,Damage:0s}]},legacyFeatures:1b}
:enddata
:endrule

rule:
plugin=inventory
number=76
data:
JSON:{blockState:{blockName:"minecraft:chest",properties:{facing:"west"}},lootLevel:0,teData:{Items:[{Slot:1b,id:"minecraft:wheat_seeds",Count:1b,Damage:0s},{Slot:3b,id:"minecraft:wheat_seeds",Count:1b,Damage:0s},{Slot:4b,id:"minecraft:wheat_seeds",Count:1b,Damage:0s},{Slot:6b,id:"minecraft:wheat_seeds",Count:2b,Damage:0s},{Slot:7b,id:"minecraft:wheat_seeds",Count:2b,Damage:0s},{Slot:10b,id:"minecraft:wheat_seeds",Count:2b,Damage:0s},{Slot:12b,id:"minecraft:wheat_seeds",Count:1b,Damage:0s},{Slot:14b,id:"minecraft:wheat_seeds",Count:1b,Damage:0s},{Slot:16b,id:"minecraft:wheat_seeds",Count:1b,Damage:0s},{Slot:17b,id:"minecraft:wheat_seeds",Count:1b,Damage:0s},{Slot:19b,id:"minecraft:wheat_seeds",Count:1b,Damage:0s},{Slot:20b,id:"minecraft:wheat_seeds",Count:2b,Damage:0s},{Slot:21b,id:"minecraft:wheat_seeds",Count:2b,Damage:0s},{Slot:22b,id:"minecraft:wheat_seeds",Count:1b,Damage:0s},{Slot:23b,id:"minecraft:wheat_seeds",Count:1b,Damage:0s}],id:"minecraft:chest",Lock:""},inventoryData:{length:15,inventoryContents:[{id:"minecraft:wheat_seeds",Count:1b,slot:0,Damage:0s},{id:"minecraft:wheat_seeds",Count:1b,slot:1,Damage:0s},{id:"minecraft:wheat_seeds",Count:1b,slot:2,Damage:0s},{id:"minecraft:wheat_seeds",Count:2b,slot:3,Damage:0s},{id:"minecraft:wheat_seeds",Count:2b,slot:4,Damage:0s},{id:"minecraft:wheat_seeds",Count:2b,slot:5,Damage:0s},{id:"minecraft:wheat_seeds",Count:1b,slot:6,Damage:0s},{id:"minecraft:wheat_seeds",Count:1b,slot:7,Damage:0s},{id:"minecraft:wheat_seeds",Count:1b,slot:8,Damage:0s},{id:"minecraft:wheat_seeds",Count:1b,slot:9,Damage:0s},{id:"minecraft:wheat_seeds",Count:1b,slot:10,Damage:0s},{id:"minecraft:wheat_seeds",Count:2b,slot:11,Damage:0s},{id:"minecraft:wheat_seeds",Count:2b,slot:12,Damage:0s},{id:"minecraft:wheat_seeds",Count:1b,slot:13,Damage:0s},{id:"minecraft:wheat_seeds",Count:1b,slot:14,Damage:0s}]},legacyFeatures:1b}
:enddata
:endrule

rule:
plugin=inventory
number=77
data:
JSON:{blockState:{blockName:"minecraft:chest",properties:{facing:"north"}},lootLevel:0,teData:{ForgeData:{},Items:[{Slot:7b,id:"ancientwarfarenpc:coin",Count:1b,tag:{metal:"silver"},Damage:0s},{Slot:8b,id:"ancientwarfarenpc:coin",Count:1b,tag:{metal:"silver"},Damage:0s},{Slot:15b,id:"ancientwarfarenpc:coin",Count:2b,tag:{metal:"silver"},Damage:0s}],id:"minecraft:chest",Lock:""},inventoryData:{length:3,inventoryContents:[{id:"ancientwarfarenpc:coin",Count:1b,tag:{metal:"silver"},slot:0,Damage:0s},{id:"ancientwarfarenpc:coin",Count:1b,tag:{metal:"silver"},slot:1,Damage:0s},{id:"ancientwarfarenpc:coin",Count:2b,tag:{metal:"silver"},slot:2,Damage:0s}]},legacyFeatures:1b}
:enddata
:endrule

rule:
plugin=bed
number=78
data:
JSON:{blockState:{blockName:"minecraft:bed",properties:{part:"head",facing:"south",occupied:"false"}},bedColor:14}
:enddata
:endrule

rule:
plugin=inventory
number=79
data:
JSON:{blockState:{blockName:"minecraft:chest",properties:{facing:"north"}},lootLevel:0,teData:{ForgeData:{},Items:[{Slot:6b,id:"ancientwarfarenpc:coin",Count:2b,tag:{metal:"silver"},Damage:0s},{Slot:7b,id:"ancientwarfarenpc:coin",Count:1b,tag:{metal:"silver"},Damage:0s},{Slot:14b,id:"ancientwarfarenpc:coin",Count:1b,tag:{metal:"silver"},Damage:0s},{Slot:15b,id:"ancientwarfarenpc:coin",Count:1b,tag:{metal:"silver"},Damage:0s},{Slot:16b,id:"ancientwarfarenpc:coin",Count:1b,tag:{metal:"silver"},Damage:0s},{Slot:17b,id:"ancientwarfarenpc:coin",Count:1b,tag:{metal:"silver"},Damage:0s},{Slot:23b,id:"ancientwarfarenpc:coin",Count:1b,tag:{metal:"silver"},Damage:0s},{Slot:26b,id:"ancientwarfarenpc:coin",Count:1b,tag:{metal:"silver"},Damage:0s}],id:"minecraft:chest",Lock:""},inventoryData:{length:8,inventoryContents:[{id:"ancientwarfarenpc:coin",Count:2b,tag:{metal:"silver"},slot:0,Damage:0s},{id:"ancientwarfarenpc:coin",Count:1b,tag:{metal:"silver"},slot:1,Damage:0s},{id:"ancientwarfarenpc:coin",Count:1b,tag:{metal:"silver"},slot:2,Damage:0s},{id:"ancientwarfarenpc:coin",Count:1b,tag:{metal:"silver"},slot:3,Damage:0s},{id:"ancientwarfarenpc:coin",Count:1b,tag:{metal:"silver"},slot:4,Damage:0s},{id:"ancientwarfarenpc:coin",Count:1b,tag:{metal:"silver"},slot:5,Damage:0s},{id:"ancientwarfarenpc:coin",Count:1b,tag:{metal:"silver"},slot:6,Damage:0s},{id:"ancientwarfarenpc:coin",Count:1b,tag:{metal:"silver"},slot:7,Damage:0s}]},legacyFeatures:1b}
:enddata
:endrule

rule:
plugin=bed
number=80
data:
JSON:{blockState:{blockName:"minecraft:bed",properties:{part:"foot",facing:"south",occupied:"false"}},bedColor:14}
:enddata
:endrule

rule:
plugin=bed
number=81
data:
JSON:{blockState:{blockName:"minecraft:bed",properties:{part:"foot",facing:"west",occupied:"false"}},bedColor:14}
:enddata
:endrule

rule:
plugin=bed
number=82
data:
JSON:{blockState:{blockName:"minecraft:bed",properties:{part:"head",facing:"west",occupied:"false"}},bedColor:14}
:enddata
:endrule

rule:
plugin=vanillaBlocks
number=83
data:
JSON:{blockState:{blockName:"minecraft:stone_stairs",properties:{half:"top",shape:"straight",facing:"north"}}}
:enddata
:endrule

rule:
plugin=vanillaBlocks
number=84
data:
JSON:{blockState:{blockName:"minecraft:stone_stairs",properties:{half:"top",shape:"straight",facing:"west"}}}
:enddata
:endrule

rule:
plugin=vanillaBlocks
number=85
data:
JSON:{blockState:{blockName:"minecraft:stone_stairs",properties:{half:"top",shape:"straight",facing:"east"}}}
:enddata
:endrule

rule:
plugin=vanillaBlocks
number=86
data:
JSON:{blockState:{blockName:"minecraft:stone_stairs",properties:{half:"top",shape:"straight",facing:"south"}}}
:enddata
:endrule

rule:
plugin=vanillaBlocks
number=87
data:
JSON:{blockState:{blockName:"minecraft:oak_stairs",properties:{half:"top",shape:"straight",facing:"north"}}}
:enddata
:endrule

rule:
plugin=vanillaBlocks
number=88
data:
JSON:{blockState:{blockName:"minecraft:oak_stairs",properties:{half:"top",shape:"straight",facing:"west"}}}
:enddata
:endrule

rule:
plugin=vanillaBlocks
number=89
data:
JSON:{blockState:{blockName:"minecraft:log",properties:{variant:"spruce",axis:"x"}}}
:enddata
:endrule

rule:
plugin=vanillaBlocks
number=90
data:
JSON:{blockState:{blockName:"minecraft:oak_stairs",properties:{half:"top",shape:"straight",facing:"east"}}}
:enddata
:endrule

rule:
plugin=vanillaBlocks
number=91
data:
JSON:{blockState:{blockName:"minecraft:log",properties:{variant:"spruce",axis:"z"}}}
:enddata
:endrule

rule:
plugin=vanillaBlocks
number=92
data:
JSON:{blockState:{blockName:"minecraft:stone_slab",properties:{half:"bottom",variant:"wood_old"}}}
:enddata
:endrule

rule:
plugin=vanillaBlocks
number=93
data:
JSON:{blockState:{blockName:"minecraft:oak_stairs",properties:{half:"top",shape:"straight",facing:"south"}}}
:enddata
:endrule

rule:
plugin=vanillaBlocks
number=94
data:
JSON:{blockState:{blockName:"minecraft:stonebrick",properties:{variant:"cracked_stonebrick"}}}
:enddata
:endrule

rule:
plugin=vanillaBlocks
number=95
data:
JSON:{blockState:{blockName:"minecraft:cobblestone_wall",properties:{east:"false",south:"false",north:"false",variant:"cobblestone",west:"false",up:"false"}}}
:enddata
:endrule

rule:
plugin=vanillaBlocks
number=96
data:
JSON:{blockState:{blockName:"minecraft:planks",properties:{variant:"spruce"}}}
:enddata
:endrule

#### ENTITIES ####
