# Ancient Warfare Structure Template File
# Auto-generated structure template file. created on: 8/19/2019 at: 10:23:10
# Lines beginning with # denote comments

header:
version=2.9
name=EmpireMillNewFangled
mods=
size=19,28,19
offset=9,4,18
:endheader

#### VALIDATION ####
validation:
type=ground
survival=false
worldGenEnabled=true
unique=false
preserveBlocks=false
selectionWeight=30
clusterValue=20
minDuplicateDistance=600
dimensionWhiteList=true
dimensionList=0
biomeWhiteList=true
biomeList=biomesoplenty:meadow,traverse:meadow,minecraft:plains
leveling=5
fill=5
border=5
blockSwap=false
:endvalidation

#### LAYERS ####
layer: 0
1,1,1,1,1,1,1,1,1,1,1,1,1,1,1,1,1,1,1
1,1,1,1,1,1,1,1,1,1,1,1,1,1,1,1,1,1,1
1,1,1,1,1,1,1,1,1,1,1,1,1,1,1,1,1,1,1
1,1,1,1,1,1,1,1,1,1,1,1,1,1,1,1,1,1,1
1,1,1,1,1,1,1,1,1,1,1,1,1,1,1,1,1,1,1
1,1,1,1,1,1,1,1,1,1,1,1,1,1,1,1,1,1,1
1,1,1,1,1,1,1,1,1,1,1,1,1,1,1,1,1,1,1
1,1,1,1,1,1,1,1,1,1,1,1,1,1,1,1,1,1,1
1,1,1,1,1,1,1,1,1,1,1,1,1,1,1,1,1,1,1
1,1,1,1,1,1,1,1,1,1,1,1,1,1,1,1,1,1,1
1,1,1,1,1,1,1,1,1,1,1,1,1,1,1,1,1,1,1
1,1,1,1,1,1,1,1,1,1,1,1,1,1,1,1,1,1,1
1,1,1,1,1,1,1,1,1,1,1,1,1,1,1,1,1,1,1
1,1,1,1,1,1,1,1,1,1,1,1,1,1,1,1,1,1,1
1,1,1,1,1,1,1,1,1,1,1,1,1,1,1,1,1,1,1
1,1,1,1,1,1,1,1,1,1,1,1,1,1,1,1,1,1,1
1,1,1,1,1,1,1,1,1,1,1,1,1,1,1,1,1,1,1
1,1,1,1,1,1,1,1,1,1,1,1,1,1,1,1,1,1,1
1,1,1,1,1,1,1,1,1,1,1,1,1,1,1,1,1,1,1
:endlayer
layer: 1
1,1,1,1,1,1,1,1,1,1,1,1,1,1,1,1,1,1,1
1,1,1,1,1,1,1,1,1,1,1,1,1,1,1,1,1,1,1
1,1,1,1,1,1,1,1,1,1,1,1,1,1,1,1,1,1,1
1,1,1,1,1,1,1,1,1,1,1,1,1,1,1,1,1,1,1
1,1,1,1,1,1,1,1,1,1,1,1,1,1,1,1,1,1,1
1,1,1,1,1,1,1,1,1,1,1,1,1,1,1,1,1,1,1
1,1,1,1,1,1,1,1,1,1,1,1,1,1,1,1,1,1,1
1,1,1,1,1,1,1,1,1,1,1,1,1,1,1,1,1,1,1
1,1,1,1,1,1,1,1,1,1,1,1,1,1,1,1,1,1,1
1,1,1,1,1,1,1,1,1,1,1,1,1,1,1,1,1,1,1
1,1,1,1,1,1,1,1,1,1,1,1,1,1,1,1,1,1,1
1,1,1,1,1,1,1,1,1,1,1,1,1,1,1,1,1,1,1
1,1,1,1,1,1,1,1,1,1,1,1,1,1,1,1,1,1,1
1,1,1,1,1,1,1,1,1,1,1,1,1,1,1,1,1,1,1
1,1,1,1,1,1,1,1,1,1,1,1,1,1,1,1,1,1,1
1,1,1,1,1,1,1,1,1,1,1,1,1,1,1,1,1,1,1
1,1,1,1,1,1,1,1,1,1,1,1,1,1,1,1,1,1,1
1,1,1,1,1,1,1,1,1,1,1,1,1,1,1,1,1,1,1
1,1,1,1,1,1,1,1,1,1,1,1,1,1,1,1,1,1,1
:endlayer
layer: 2
1,1,1,1,1,1,1,1,1,1,1,1,1,1,1,1,1,1,1
1,1,1,1,1,1,1,1,1,1,1,1,1,1,1,1,1,1,1
1,1,2,2,2,2,2,2,2,2,2,2,2,2,2,2,2,1,1
1,1,2,2,2,2,2,2,2,2,2,2,2,2,2,2,2,1,1
1,1,2,2,2,2,2,2,2,2,2,2,2,2,2,2,2,1,1
1,1,2,2,2,2,2,2,2,2,2,2,2,2,2,2,2,1,1
1,1,2,2,2,2,2,2,2,2,2,2,2,2,2,2,2,1,1
1,1,2,2,2,2,2,2,2,2,2,2,2,2,2,2,2,1,1
1,1,2,2,2,2,2,2,2,2,2,2,2,2,2,2,2,1,1
1,1,2,2,2,2,2,2,2,2,2,2,2,2,2,2,2,1,1
1,1,2,2,2,2,2,2,2,2,2,2,2,2,2,2,2,1,1
1,1,2,2,2,2,2,2,2,2,2,2,2,2,2,2,2,1,1
1,1,2,2,2,2,2,2,2,2,2,2,2,2,2,2,2,1,1
1,1,2,2,2,2,2,2,2,2,2,2,2,2,2,2,2,1,1
1,1,2,2,2,2,2,2,2,2,2,2,2,2,2,2,2,1,1
1,1,2,2,2,2,2,2,2,2,2,2,2,2,2,2,2,1,1
1,1,2,2,2,2,2,2,2,2,2,2,2,2,2,2,2,1,1
1,1,1,1,1,1,1,1,1,1,1,1,1,1,1,1,1,1,1
1,1,1,1,1,1,1,1,1,1,1,1,1,1,1,1,1,1,1
:endlayer
layer: 3
3,3,3,3,3,3,3,3,3,3,3,3,3,3,3,3,3,3,3
3,3,3,3,3,3,3,3,3,3,3,3,3,2,3,3,3,3,3
3,3,3,3,3,3,3,3,3,3,3,3,3,2,3,3,3,3,3
3,3,3,2,2,2,4,4,4,2,2,2,2,2,2,2,3,3,3
3,3,3,2,2,2,2,2,2,2,2,2,2,2,2,2,3,3,3
3,3,3,2,2,2,2,2,2,2,2,2,2,2,2,4,3,3,3
3,3,3,2,2,2,2,2,2,2,2,2,2,2,2,4,3,3,3
3,3,3,2,2,2,2,2,2,2,2,2,2,2,2,4,3,3,3
3,3,3,2,2,2,2,2,2,2,2,2,2,2,2,2,3,3,3
3,3,3,2,2,2,2,2,2,2,2,2,2,2,2,2,3,3,3
3,3,3,2,2,2,2,2,2,2,2,2,2,2,2,2,3,3,3
3,3,3,4,2,2,2,2,2,2,2,2,2,2,2,2,3,3,3
3,3,3,4,2,2,2,2,2,2,2,2,2,2,2,2,3,3,3
3,3,3,4,2,2,2,2,2,2,2,2,2,2,2,2,3,3,3
3,3,3,2,2,2,2,2,2,2,2,2,2,2,2,2,3,3,3
3,3,3,2,2,2,2,2,2,2,2,2,2,2,2,2,3,3,3
3,3,3,3,3,3,3,3,3,2,3,3,3,3,3,3,3,3,3
3,3,3,3,3,3,3,3,3,2,3,3,3,3,3,3,3,3,3
3,3,3,3,3,3,3,3,3,3,3,3,3,3,3,3,3,3,3
:endlayer
layer: 4
5,0,0,0,0,0,5,5,5,0,5,0,0,0,0,0,0,0,0
0,6,6,6,6,6,6,6,6,6,6,6,6,25,6,6,6,6,0
5,6,0,0,0,5,0,0,5,0,5,0,0,0,0,0,5,6,5
5,6,5,8,8,8,6,6,6,8,8,8,8,9,8,8,5,6,5
0,6,0,8,24,0,0,0,0,0,0,0,0,0,0,8,5,6,5
0,6,0,8,6,0,0,0,0,0,21,21,21,0,0,6,0,6,0
5,6,5,8,23,0,0,0,0,0,21,8,21,0,0,6,0,6,0
5,6,0,8,22,0,0,0,0,0,21,21,21,0,0,6,0,6,0
5,6,0,8,6,0,0,20,19,0,0,0,0,0,0,8,0,6,0
5,6,5,8,8,0,0,8,8,8,8,0,18,0,8,8,0,6,0
0,6,0,8,0,0,0,6,17,16,6,0,0,0,15,8,0,6,0
0,6,0,6,0,0,14,0,0,0,0,0,0,0,13,8,5,6,5
0,6,0,6,0,0,0,0,0,0,0,0,0,0,0,12,5,6,0
0,6,0,6,0,0,0,0,0,0,0,11,8,8,8,8,5,6,0
0,6,0,8,0,0,0,0,0,0,0,8,8,8,8,8,0,6,0
5,6,5,8,8,10,8,8,8,9,8,8,8,8,8,8,0,6,0
5,6,0,0,0,0,0,0,0,0,0,0,5,5,0,0,0,6,0
5,6,6,6,6,6,6,6,6,7,6,6,6,6,6,6,6,6,0
5,0,0,5,0,0,0,0,0,0,0,0,5,5,5,0,0,0,0
:endlayer
layer: 5
0,0,0,0,0,0,0,0,0,0,0,0,0,0,0,0,0,0,0
0,26,0,0,0,0,0,0,0,0,0,0,0,0,0,0,0,26,0
0,0,0,0,0,0,0,0,0,0,0,0,0,0,31,0,0,0,0
0,0,0,2,2,4,6,6,6,4,2,2,2,28,2,2,0,0,0
0,0,0,2,0,0,0,0,0,0,0,0,0,0,0,4,0,0,0
0,0,0,2,6,0,0,0,0,0,0,0,0,0,0,6,0,0,0
0,0,0,2,6,0,0,0,0,0,0,2,0,0,0,6,0,0,0
0,0,0,2,6,0,0,0,0,0,0,0,0,0,0,6,0,0,0
0,0,0,2,6,0,0,6,6,0,0,0,0,0,0,4,0,0,0
0,0,0,2,2,0,0,2,2,2,4,0,0,0,4,2,0,0,0
0,0,0,4,30,0,0,6,6,6,6,0,0,0,6,2,0,0,0
0,0,0,6,0,0,0,0,0,0,0,0,0,0,6,2,0,0,0
0,0,0,6,0,0,0,0,0,0,0,0,0,29,0,6,0,0,0
0,0,0,6,0,0,0,0,0,0,0,0,11,2,2,2,0,0,0
0,0,0,4,0,0,0,0,0,0,0,2,2,2,2,2,0,0,0
0,0,0,2,2,6,2,2,2,28,2,2,2,2,2,2,0,0,0
0,0,0,0,0,0,0,0,27,0,0,0,0,0,0,0,0,0,0
0,26,0,0,0,0,0,0,0,0,0,0,0,0,0,0,0,26,0
0,0,0,0,0,0,0,0,0,0,0,0,0,0,0,0,0,0,0
:endlayer
layer: 6
0,0,0,0,0,0,0,0,0,0,0,0,0,0,0,0,0,0,0
0,0,0,0,0,0,0,0,0,0,0,0,0,0,0,0,0,0,0
0,0,0,0,0,0,0,0,0,0,0,29,0,0,0,0,0,0,0
0,0,0,8,8,8,6,6,6,8,8,8,8,6,8,8,0,0,0
0,0,0,8,33,0,0,0,0,0,0,0,0,0,0,8,0,0,0
0,0,0,8,6,0,0,0,0,0,0,39,0,0,0,6,0,0,0
0,0,42,8,41,0,0,0,0,0,39,2,39,0,0,6,0,0,0
0,0,0,8,40,0,0,0,0,0,0,39,0,0,0,6,0,0,0
0,0,0,8,6,0,0,38,37,0,0,0,0,0,0,8,0,0,0
0,0,0,8,8,6,6,8,8,8,8,0,0,0,8,8,0,0,0
0,0,0,8,0,0,0,6,36,35,6,0,0,0,34,8,33,0,0
0,0,0,6,0,0,0,0,0,0,0,0,0,0,32,8,0,0,0
0,0,0,6,0,0,0,0,0,0,0,0,0,0,0,6,0,0,0
0,0,0,6,0,0,0,0,0,0,0,0,0,11,8,8,0,0,0
0,0,0,8,0,0,0,0,0,0,0,8,8,8,8,8,0,0,0
0,0,0,8,8,6,8,8,8,6,8,8,8,8,8,8,0,0,0
0,0,0,0,0,0,0,30,0,0,0,0,30,0,0,0,0,0,0
0,0,0,0,0,0,0,0,0,0,0,0,0,0,0,0,0,0,0
0,0,0,0,0,0,0,0,0,0,0,0,0,0,0,0,0,0,0
:endlayer
layer: 7
0,0,0,0,0,0,0,0,0,0,0,0,0,0,0,0,0,0,0
0,0,0,0,0,0,0,0,0,0,0,0,0,0,0,0,0,0,0
0,0,0,0,0,0,0,0,0,0,0,0,0,0,0,0,0,0,0
0,0,0,2,2,2,8,8,8,2,2,2,2,8,2,2,0,0,0
0,0,0,2,0,30,0,0,0,0,0,0,30,0,30,2,0,0,0
0,0,0,2,6,0,0,0,0,0,0,51,0,0,0,8,0,0,0
0,0,0,2,6,0,0,0,0,0,50,2,49,0,0,8,0,0,0
0,0,0,2,6,0,0,0,0,0,0,48,0,0,0,8,0,0,0
0,0,46,2,6,0,0,6,6,0,29,0,0,0,29,2,0,0,0
0,0,0,2,2,8,8,2,2,2,2,8,8,8,2,2,0,0,0
0,0,0,2,0,0,0,6,6,6,6,0,0,0,6,2,47,0,0
0,0,0,8,0,0,0,0,0,0,0,0,0,0,6,2,0,0,0
0,0,46,8,0,0,0,0,0,0,0,0,0,0,0,8,0,0,0
0,0,0,8,0,0,0,0,0,0,0,0,0,0,0,2,0,0,0
0,0,0,2,0,0,0,0,29,0,29,2,2,45,0,2,0,0,0
0,0,0,2,2,8,2,2,2,8,2,2,2,2,2,2,0,0,0
0,0,43,0,0,0,44,0,0,0,0,0,44,0,0,0,43,0,0
0,0,0,0,0,0,0,0,0,0,0,0,0,0,0,0,0,0,0
0,0,0,0,0,0,0,0,0,0,0,0,0,0,0,0,0,0,0
:endlayer
layer: 8
0,0,0,0,0,0,0,0,0,0,0,0,0,0,0,0,0,0,0
0,0,0,0,0,0,0,0,0,0,0,0,0,0,0,0,0,0,0
0,0,0,0,0,0,0,0,0,0,0,0,0,0,0,0,0,0,0
0,0,0,52,52,52,52,52,52,52,52,52,52,52,52,52,0,0,0
0,0,0,52,54,54,54,54,54,54,54,54,54,54,54,52,0,0,0
0,0,0,52,54,54,54,54,54,54,8,8,8,54,54,52,0,0,0
0,0,0,52,54,54,54,54,54,54,8,57,8,54,54,52,0,0,0
0,0,0,52,56,54,54,54,54,54,8,8,8,54,54,52,0,0,0
0,0,52,2,2,2,2,2,52,0,55,55,55,0,54,52,0,0,0
0,0,0,2,53,53,53,53,53,54,54,54,54,54,54,52,0,0,0
0,0,0,2,53,53,53,53,53,53,2,2,2,2,2,2,52,0,0
0,0,0,2,53,53,53,53,53,53,53,53,53,53,53,2,0,0,0
0,0,52,2,53,53,53,53,53,53,53,2,2,2,2,2,0,0,0
0,0,0,2,53,53,53,53,53,53,53,2,0,0,0,2,0,0,0
0,0,0,2,53,53,53,53,53,53,53,2,45,0,0,2,0,0,0
0,0,0,2,2,2,2,2,2,2,2,2,2,2,2,2,0,0,0
0,0,52,0,0,0,52,0,0,0,0,0,52,0,0,0,52,0,0
0,0,0,0,0,0,0,0,0,0,0,0,0,0,0,0,0,0,0
0,0,0,0,0,0,0,0,0,0,0,0,0,0,0,0,0,0,0
:endlayer
layer: 9
0,0,0,0,0,0,0,0,0,0,0,0,0,0,0,0,0,0,0
0,0,0,0,0,0,0,0,0,0,0,0,0,0,0,0,0,0,0
0,0,0,0,0,0,0,0,0,0,0,0,0,0,0,0,0,0,0
0,0,0,6,6,6,6,6,6,6,6,6,6,6,6,6,0,0,0
0,0,0,6,0,0,0,0,0,0,0,0,0,0,0,6,0,0,0
0,0,0,6,0,0,0,0,0,0,8,8,8,0,0,6,0,0,0
0,0,0,6,0,0,0,0,0,0,8,52,8,0,0,6,0,0,0
0,0,0,6,0,0,0,0,0,0,8,8,8,0,0,6,0,0,0
0,0,52,8,65,8,2,8,52,55,0,55,0,55,0,6,0,0,0
0,0,8,64,0,0,0,0,8,0,0,0,0,0,0,6,0,0,0
0,0,8,63,0,0,39,39,8,8,0,0,0,8,8,8,52,0,0
0,0,8,62,0,0,39,2,39,55,55,55,0,61,60,0,8,0,0
0,0,52,24,0,0,39,39,39,0,0,0,0,0,0,0,8,0,0
0,0,8,0,0,0,52,0,0,0,0,6,0,0,0,0,8,0,0
0,0,8,59,58,0,0,0,0,0,0,0,0,0,0,0,8,0,0
0,0,8,59,58,0,0,0,0,0,0,0,0,0,0,0,8,0,0
0,0,52,8,8,8,52,8,8,8,8,8,52,8,8,8,52,0,0
0,0,0,0,0,0,0,0,0,0,0,0,0,0,0,0,0,0,0
0,0,0,0,0,0,0,0,0,0,0,0,0,0,0,0,0,0,0
:endlayer
layer: 10
0,0,0,0,0,0,0,0,0,0,0,0,0,0,0,0,0,0,0
0,0,0,0,0,0,0,0,0,0,0,0,0,0,0,0,0,0,0
0,0,0,0,0,0,0,0,0,0,0,0,0,0,0,0,0,0,0
0,0,0,26,0,0,0,0,0,0,0,0,0,0,0,26,0,0,0
0,0,0,0,0,0,0,0,0,0,0,29,0,0,0,0,0,0,0
0,0,0,0,0,0,0,0,0,0,8,8,8,0,0,0,0,0,0
0,0,0,0,0,0,0,0,0,42,8,52,8,33,0,0,0,0,0
0,0,0,0,0,29,0,0,0,0,8,8,8,0,0,0,0,0,0
0,0,52,2,28,2,66,2,52,55,55,8,55,55,0,0,0,0,0
0,0,2,0,0,30,0,0,2,0,0,8,0,0,0,0,0,0,0
0,0,66,0,0,0,0,21,52,2,0,6,0,2,2,2,52,0,0
0,0,2,0,0,0,21,0,21,0,0,6,0,0,0,0,2,0,0
0,0,52,0,0,0,0,21,0,0,0,6,0,0,0,0,66,0,0
0,0,2,0,0,0,52,0,0,0,0,6,0,0,0,0,2,0,0
0,0,66,0,0,0,0,0,0,0,0,0,0,0,0,0,66,0,0
0,0,2,0,0,0,0,0,0,0,0,0,0,0,0,0,2,0,0
0,0,52,2,66,2,52,2,66,2,66,2,52,2,66,2,52,0,0
0,0,0,0,0,0,0,0,0,0,0,0,0,0,0,0,0,0,0
0,0,0,0,0,0,0,0,0,0,0,0,0,0,0,0,0,0,0
:endlayer
layer: 11
0,0,0,0,0,0,0,0,0,0,0,0,0,0,0,0,0,0,0
0,0,0,0,0,0,0,0,0,0,0,0,0,0,0,0,0,0,0
0,0,0,0,0,0,0,0,0,0,0,0,0,0,0,0,0,0,0
0,0,0,0,0,0,0,0,0,0,0,0,0,0,0,0,0,0,0
0,0,0,0,0,0,0,0,0,0,0,0,0,0,0,0,0,0,0
0,0,0,0,0,0,0,0,0,0,0,67,0,0,0,0,0,0,0
0,0,0,0,0,0,0,0,0,0,67,52,67,0,0,0,0,0,0
0,0,0,0,0,0,0,0,0,0,0,67,0,0,0,0,0,0,0
0,0,52,8,6,8,66,8,52,55,0,55,0,55,0,0,0,0,0
0,0,8,0,0,0,0,0,8,0,0,0,0,0,29,0,0,0,0
0,0,66,0,0,0,0,42,52,8,0,0,0,8,8,8,52,0,0
0,0,8,0,0,0,0,0,30,0,0,0,0,0,0,0,8,0,0
0,0,52,33,0,0,0,0,0,0,0,0,0,0,0,0,66,0,0
0,0,8,0,0,42,52,33,0,0,0,0,0,0,0,0,8,0,0
0,0,66,0,0,0,0,0,0,0,0,0,0,0,0,0,66,0,0
0,0,8,0,0,0,29,0,0,0,0,0,29,0,0,0,8,0,0
0,0,52,8,66,8,52,8,66,8,66,8,52,8,66,8,52,0,0
0,0,0,0,0,0,0,0,0,0,0,0,0,0,0,0,0,0,0
0,0,0,0,0,0,0,0,0,0,0,0,0,0,0,0,0,0,0
:endlayer
layer: 12
0,0,0,0,0,0,0,0,0,0,0,0,0,0,0,0,0,0,0
0,0,0,0,0,0,0,0,0,0,0,0,0,0,0,0,0,0,0
0,0,0,0,0,0,0,0,0,0,0,0,0,0,0,0,0,0,0
0,0,0,0,0,0,0,0,0,0,0,0,0,0,0,0,0,0,0
0,0,0,0,0,0,0,0,0,0,0,0,0,0,0,0,0,0,0
0,0,0,0,0,0,0,0,0,0,0,54,0,0,0,0,0,0,0
0,0,0,0,0,0,0,0,0,0,54,52,54,0,0,0,0,0,0
0,0,0,0,0,0,0,0,0,0,0,54,0,0,0,0,0,0,0
0,0,52,2,8,2,8,2,52,0,55,55,55,0,0,0,0,0,0
0,0,2,0,0,0,0,0,2,0,0,0,0,0,0,0,0,0,0
0,0,8,0,0,0,0,0,52,2,8,8,8,2,2,2,52,0,0
0,0,2,33,0,0,0,0,0,30,0,0,0,30,0,0,2,0,0
0,0,52,0,0,0,0,0,0,0,0,0,0,0,0,0,8,0,0
0,0,2,33,0,0,52,0,0,0,0,0,0,0,0,42,2,0,0
0,0,8,0,0,0,0,0,0,0,0,0,0,0,0,0,8,0,0
0,0,2,0,0,0,0,0,29,0,29,0,0,0,0,0,2,0,0
0,0,52,2,8,2,52,2,8,2,8,2,52,2,8,2,52,0,0
0,0,0,0,0,0,0,0,0,0,0,0,0,0,0,0,0,0,0
0,0,0,0,0,0,0,0,0,0,0,0,0,0,0,0,0,0,0
:endlayer
layer: 13
0,0,0,0,0,0,0,0,0,0,0,0,0,0,0,0,0,0,0
0,0,0,0,0,0,0,0,0,0,0,0,0,0,0,0,0,0,0
0,0,0,0,0,0,0,0,0,0,0,0,0,0,0,0,0,0,0
0,0,0,0,0,0,0,0,0,0,0,0,0,0,0,0,0,0,0
0,0,0,0,0,0,0,0,0,0,0,0,0,0,0,0,0,0,0
0,0,0,0,0,0,0,0,0,0,0,0,0,0,0,0,0,0,0
0,0,0,0,0,0,0,0,0,0,0,52,0,0,0,0,0,0,0
0,54,54,54,54,54,54,54,54,0,0,0,0,0,0,0,0,0,0
0,54,55,55,55,55,55,55,49,0,0,0,0,0,0,0,0,0,0
0,54,55,52,0,0,0,0,49,0,0,0,0,0,54,54,54,54,0
0,54,55,0,52,0,0,0,53,51,51,51,51,51,55,55,55,54,0
0,54,55,0,0,52,0,52,0,0,0,0,52,0,0,52,55,54,0
0,54,55,52,52,52,52,0,0,0,0,0,52,0,52,0,55,54,0
0,54,55,0,0,52,52,52,52,52,52,52,52,52,0,0,55,54,0
0,54,55,0,52,0,52,0,0,0,0,0,52,0,52,0,55,54,0
0,54,55,52,0,0,52,0,0,0,0,0,52,0,0,52,55,54,0
0,54,55,55,55,55,55,55,55,55,55,55,55,55,55,55,53,54,0
0,54,54,54,54,54,54,54,54,54,54,54,54,54,54,54,54,54,0
0,0,0,0,0,0,0,0,0,0,0,0,0,0,0,0,0,0,0
:endlayer
layer: 14
0,0,0,0,0,0,0,0,0,0,0,0,0,0,0,0,0,0,0
0,0,0,0,0,0,0,0,0,0,0,0,0,0,0,0,0,0,0
0,0,0,0,0,0,0,0,0,0,0,0,0,0,0,0,0,0,0
0,0,0,0,0,0,0,0,0,0,0,0,0,0,0,0,0,0,0
0,0,0,0,0,0,0,0,0,0,0,0,0,0,0,0,0,0,0
0,0,0,0,0,0,0,0,0,0,0,0,0,0,0,0,0,0,0
0,0,0,0,0,0,0,0,0,0,0,57,0,0,0,0,0,0,0
0,0,0,0,0,0,0,0,0,0,0,0,0,0,0,0,0,0,0
0,0,0,0,0,0,0,0,0,0,0,0,0,0,0,0,0,0,0
0,0,0,54,54,54,54,54,0,0,0,0,0,0,0,0,0,0,0
0,0,0,54,55,55,55,54,0,0,0,0,0,0,0,0,0,0,0
0,0,0,54,55,52,55,54,54,54,54,54,54,54,54,54,0,0,0
0,0,0,54,55,52,55,55,55,55,55,55,55,55,55,54,0,0,0
0,0,0,54,55,52,52,55,55,55,55,55,52,52,55,54,0,0,0
0,0,0,54,55,55,55,55,55,55,55,55,55,55,55,54,0,0,0
0,0,0,54,54,54,54,54,54,54,54,54,54,54,54,54,0,0,0
0,0,0,0,0,0,0,0,0,0,0,0,0,0,0,0,0,0,0
0,0,0,0,0,0,0,0,0,0,0,0,0,0,0,0,0,0,0
0,0,0,0,0,0,0,0,0,0,0,0,0,0,0,0,0,0,0
:endlayer
layer: 15
0,0,0,0,0,0,0,0,0,0,0,0,0,0,0,0,0,0,0
0,0,0,0,0,0,0,0,0,0,0,0,0,0,0,0,0,0,0
0,0,0,0,0,0,0,0,0,0,0,0,0,0,0,0,0,0,0
0,0,0,0,0,0,0,0,6,6,0,0,0,0,6,0,0,0,0
0,0,0,0,0,0,0,0,0,6,6,0,0,6,6,0,0,0,0
0,0,0,0,0,0,0,0,0,0,6,6,6,6,0,0,0,0,0
0,0,0,0,0,0,0,0,0,0,6,4,6,0,0,0,0,0,0
0,0,0,0,0,0,0,0,0,6,6,6,6,0,0,0,0,0,0
0,0,0,0,0,0,0,0,6,6,0,0,6,6,0,0,0,0,0
0,0,0,0,0,0,0,0,6,0,0,0,0,6,6,0,0,0,0
0,0,0,0,0,0,0,0,0,0,0,0,0,0,0,0,0,0,0
0,0,0,0,0,54,0,0,0,0,0,0,0,0,0,0,0,0,0
0,0,0,0,0,54,0,0,0,0,0,0,0,0,0,0,0,0,0
0,0,0,0,0,54,54,54,54,54,54,54,54,54,0,0,0,0,0
0,0,0,0,0,0,0,0,0,0,0,0,0,0,0,0,0,0,0
0,0,0,0,0,0,0,0,0,0,0,0,0,0,0,0,0,0,0
0,0,0,0,0,0,0,0,0,0,0,0,0,0,0,0,0,0,0
0,0,0,0,0,0,0,0,0,0,0,0,0,0,0,0,0,0,0
0,0,0,0,0,0,0,0,0,0,0,0,0,0,0,0,0,0,0
:endlayer
layer: 16
0,0,0,0,0,0,0,0,0,0,0,0,0,0,0,0,0,0,0
0,0,0,0,0,0,0,0,0,0,0,0,0,0,0,0,0,0,0
0,0,0,0,0,0,0,0,0,0,0,0,0,0,0,0,0,0,0
0,0,0,0,0,0,0,0,68,0,0,0,0,0,68,0,0,0,0
0,0,0,0,0,0,0,0,0,68,0,0,0,68,0,0,0,0,0
0,0,0,0,0,0,0,0,0,0,68,0,68,0,0,0,0,0,0
0,0,0,0,0,0,0,0,0,0,0,52,0,0,0,0,0,0,0
0,0,0,0,0,0,0,0,0,0,68,0,68,0,0,0,0,0,0
0,0,0,0,0,0,0,0,0,68,0,0,0,68,0,0,0,0,0
0,0,0,0,0,0,0,0,68,0,0,0,0,0,68,0,0,0,0
0,0,0,0,0,0,0,0,0,0,0,0,0,0,0,0,0,0,0
0,0,0,0,0,0,0,0,0,0,0,0,0,0,0,0,0,0,0
0,0,0,0,0,0,0,0,0,0,0,0,0,0,0,0,0,0,0
0,0,0,0,0,0,0,0,0,0,0,0,0,0,0,0,0,0,0
0,0,0,0,0,0,0,0,0,0,0,0,0,0,0,0,0,0,0
0,0,0,0,0,0,0,0,0,0,0,0,0,0,0,0,0,0,0
0,0,0,0,0,0,0,0,0,0,0,0,0,0,0,0,0,0,0
0,0,0,0,0,0,0,0,0,0,0,0,0,0,0,0,0,0,0
0,0,0,0,0,0,0,0,0,0,0,0,0,0,0,0,0,0,0
:endlayer
layer: 17
0,0,0,0,0,0,0,0,0,0,0,0,0,0,0,0,0,0,0
0,0,0,0,0,0,0,0,0,0,0,0,0,0,0,0,0,0,0
0,0,0,0,0,0,0,0,0,0,0,0,0,0,0,0,0,0,0
0,0,0,0,0,0,0,0,68,0,0,0,0,0,68,0,0,0,0
0,0,0,0,0,0,0,0,0,68,0,0,0,68,0,0,0,0,0
0,0,0,0,0,0,0,0,0,0,68,0,68,0,0,0,0,0,0
0,0,0,0,0,0,0,0,0,0,0,52,0,0,0,0,0,0,0
0,0,0,0,0,0,0,0,0,0,68,0,68,0,0,0,0,0,0
0,0,0,0,0,0,0,0,0,68,0,0,0,68,0,0,0,0,0
0,0,0,0,0,0,0,0,68,0,0,0,0,0,68,0,0,0,0
0,0,0,0,0,0,0,0,0,0,0,0,0,0,0,0,0,0,0
0,0,0,0,0,0,0,0,0,0,0,0,0,0,0,0,0,0,0
0,0,0,0,0,0,0,0,0,0,0,0,0,0,0,0,0,0,0
0,0,0,0,0,0,0,0,0,0,0,0,0,0,0,0,0,0,0
0,0,0,0,0,0,0,0,0,0,0,0,0,0,0,0,0,0,0
0,0,0,0,0,0,0,0,0,0,0,0,0,0,0,0,0,0,0
0,0,0,0,0,0,0,0,0,0,0,0,0,0,0,0,0,0,0
0,0,0,0,0,0,0,0,0,0,0,0,0,0,0,0,0,0,0
0,0,0,0,0,0,0,0,0,0,0,0,0,0,0,0,0,0,0
:endlayer
layer: 18
0,0,0,0,0,0,0,0,0,0,0,0,0,0,0,0,0,0,0
0,0,0,0,0,0,0,0,0,0,0,0,0,0,0,0,0,0,0
0,0,0,0,0,0,0,0,0,0,0,0,0,0,0,0,0,0,0
0,0,0,0,0,0,0,0,68,0,0,0,0,0,68,0,0,0,0
0,0,0,0,0,0,0,0,0,68,0,0,0,68,0,0,0,0,0
0,0,0,0,0,0,0,0,0,0,68,0,68,0,0,0,0,0,0
0,0,0,0,0,0,0,0,0,0,0,52,0,0,0,0,0,0,0
0,0,0,0,0,0,0,0,0,0,68,0,68,0,0,0,0,0,0
0,0,0,0,0,0,0,0,0,68,0,0,0,68,0,0,0,0,0
0,0,0,0,0,0,0,0,68,0,0,0,0,0,68,0,0,0,0
0,0,0,0,0,0,0,0,0,0,0,0,0,0,0,0,0,0,0
0,0,0,0,0,0,0,0,0,0,0,0,0,0,0,0,0,0,0
0,0,0,0,0,0,0,0,0,0,0,0,0,0,0,0,0,0,0
0,0,0,0,0,0,0,0,0,0,0,0,0,0,0,0,0,0,0
0,0,0,0,0,0,0,0,0,0,0,0,0,0,0,0,0,0,0
0,0,0,0,0,0,0,0,0,0,0,0,0,0,0,0,0,0,0
0,0,0,0,0,0,0,0,0,0,0,0,0,0,0,0,0,0,0
0,0,0,0,0,0,0,0,0,0,0,0,0,0,0,0,0,0,0
0,0,0,0,0,0,0,0,0,0,0,0,0,0,0,0,0,0,0
:endlayer
layer: 19
0,0,0,0,0,0,0,0,0,0,0,0,0,0,0,0,0,0,0
0,0,0,0,0,0,0,0,0,0,0,0,0,0,0,0,0,0,0
0,0,0,0,0,0,0,0,0,0,0,0,0,0,0,0,0,0,0
0,0,0,0,0,0,0,0,6,6,0,0,0,0,6,0,0,0,0
0,0,0,0,0,0,0,0,0,6,6,0,0,6,6,0,0,0,0
0,0,0,0,0,0,0,0,0,0,6,6,6,6,0,0,0,0,0
0,0,0,0,0,0,0,0,0,0,6,4,6,0,0,0,0,0,0
0,0,0,0,0,0,0,0,0,6,6,6,6,0,0,0,0,0,0
0,0,0,0,0,0,0,0,6,6,0,0,6,6,0,0,0,0,0
0,0,0,0,0,0,0,0,6,0,0,0,0,6,6,0,0,0,0
0,0,0,0,0,0,0,0,0,0,0,0,0,0,0,0,0,0,0
0,0,0,0,0,0,0,0,0,0,0,0,0,0,0,0,0,0,0
0,0,0,0,0,0,0,0,0,0,0,0,0,0,0,0,0,0,0
0,0,0,0,0,0,0,0,0,0,0,0,0,0,0,0,0,0,0
0,0,0,0,0,0,0,0,0,0,0,0,0,0,0,0,0,0,0
0,0,0,0,0,0,0,0,0,0,0,0,0,0,0,0,0,0,0
0,0,0,0,0,0,0,0,0,0,0,0,0,0,0,0,0,0,0
0,0,0,0,0,0,0,0,0,0,0,0,0,0,0,0,0,0,0
0,0,0,0,0,0,0,0,0,0,0,0,0,0,0,0,0,0,0
:endlayer
layer: 20
0,0,0,0,0,0,0,0,0,0,0,0,0,0,0,0,0,0,0
0,0,0,0,0,0,0,0,0,0,0,0,0,0,0,0,0,0,0
0,0,0,0,0,0,0,0,0,0,0,0,0,0,0,0,0,0,0
0,0,0,0,0,0,0,0,68,0,0,0,0,0,68,0,0,0,0
0,0,0,0,0,0,0,0,0,68,0,0,0,68,0,0,0,0,0
0,0,0,0,0,0,0,0,0,0,68,0,68,0,0,0,0,0,0
0,0,0,0,0,0,0,0,0,0,0,52,0,0,0,0,0,0,0
0,0,0,0,0,0,0,0,0,0,68,0,68,0,0,0,0,0,0
0,0,0,0,0,0,0,0,0,68,0,0,0,68,0,0,0,0,0
0,0,0,0,0,0,0,0,68,0,0,0,0,0,68,0,0,0,0
0,0,0,0,0,0,0,0,0,0,0,0,0,0,0,0,0,0,0
0,0,0,0,0,0,0,0,0,0,0,0,0,0,0,0,0,0,0
0,0,0,0,0,0,0,0,0,0,0,0,0,0,0,0,0,0,0
0,0,0,0,0,0,0,0,0,0,0,0,0,0,0,0,0,0,0
0,0,0,0,0,0,0,0,0,0,0,0,0,0,0,0,0,0,0
0,0,0,0,0,0,0,0,0,0,0,0,0,0,0,0,0,0,0
0,0,0,0,0,0,0,0,0,0,0,0,0,0,0,0,0,0,0
0,0,0,0,0,0,0,0,0,0,0,0,0,0,0,0,0,0,0
0,0,0,0,0,0,0,0,0,0,0,0,0,0,0,0,0,0,0
:endlayer
layer: 21
0,0,0,0,0,0,0,0,0,0,0,0,0,0,0,0,0,0,0
0,0,0,0,0,0,0,0,0,0,0,0,0,0,0,0,0,0,0
0,0,0,0,0,0,0,0,0,0,0,0,0,0,0,0,0,0,0
0,0,0,0,0,0,0,0,68,0,0,0,0,0,68,0,0,0,0
0,0,0,0,0,0,0,0,0,68,0,0,0,68,0,0,0,0,0
0,0,0,0,0,0,0,0,0,0,68,0,68,0,0,0,0,0,0
0,0,0,0,0,0,0,0,0,0,0,52,0,0,0,0,0,0,0
0,0,0,0,0,0,0,0,0,0,68,0,68,0,0,0,0,0,0
0,0,0,0,0,0,0,0,0,68,0,0,0,68,0,0,0,0,0
0,0,0,0,0,0,0,0,68,0,0,0,0,0,68,0,0,0,0
0,0,0,0,0,0,0,0,0,0,0,0,0,0,0,0,0,0,0
0,0,0,0,0,0,0,0,0,0,0,0,0,0,0,0,0,0,0
0,0,0,0,0,0,0,0,0,0,0,0,0,0,0,0,0,0,0
0,0,0,0,0,0,0,0,0,0,0,0,0,0,0,0,0,0,0
0,0,0,0,0,0,0,0,0,0,0,0,0,0,0,0,0,0,0
0,0,0,0,0,0,0,0,0,0,0,0,0,0,0,0,0,0,0
0,0,0,0,0,0,0,0,0,0,0,0,0,0,0,0,0,0,0
0,0,0,0,0,0,0,0,0,0,0,0,0,0,0,0,0,0,0
0,0,0,0,0,0,0,0,0,0,0,0,0,0,0,0,0,0,0
:endlayer
layer: 22
0,0,0,0,0,0,0,0,0,0,0,0,0,0,0,0,0,0,0
0,0,0,0,0,0,0,0,0,0,0,0,0,0,0,0,0,0,0
0,0,0,0,0,0,0,0,0,0,0,0,0,0,0,0,0,0,0
0,0,0,0,0,0,0,0,68,0,0,0,0,0,68,0,0,0,0
0,0,0,0,0,0,0,0,0,68,0,0,0,68,0,0,0,0,0
0,0,0,0,0,0,0,0,0,0,68,0,68,0,0,0,0,0,0
0,0,0,0,0,0,0,0,0,0,0,52,0,0,0,0,0,0,0
0,0,0,0,0,0,0,0,0,0,68,0,68,0,0,0,0,0,0
0,0,0,0,0,0,0,0,0,68,0,0,0,68,0,0,0,0,0
0,0,0,0,0,0,0,0,68,0,0,0,0,0,68,0,0,0,0
0,0,0,0,0,0,0,0,0,0,0,0,0,0,0,0,0,0,0
0,0,0,0,0,0,0,0,0,0,0,0,0,0,0,0,0,0,0
0,0,0,0,0,0,0,0,0,0,0,0,0,0,0,0,0,0,0
0,0,0,0,0,0,0,0,0,0,0,0,0,0,0,0,0,0,0
0,0,0,0,0,0,0,0,0,0,0,0,0,0,0,0,0,0,0
0,0,0,0,0,0,0,0,0,0,0,0,0,0,0,0,0,0,0
0,0,0,0,0,0,0,0,0,0,0,0,0,0,0,0,0,0,0
0,0,0,0,0,0,0,0,0,0,0,0,0,0,0,0,0,0,0
0,0,0,0,0,0,0,0,0,0,0,0,0,0,0,0,0,0,0
:endlayer
layer: 23
0,0,0,0,0,0,0,0,0,0,0,0,0,0,0,0,0,0,0
0,0,0,0,0,0,0,0,0,0,0,0,0,0,0,0,0,0,0
0,0,0,0,0,0,0,0,0,0,0,0,0,0,0,0,0,0,0
0,0,0,0,0,0,0,0,6,6,0,0,0,0,6,0,0,0,0
0,0,0,0,0,0,0,0,0,6,6,0,0,6,6,0,0,0,0
0,0,0,0,0,0,0,0,0,0,6,6,6,6,0,0,0,0,0
0,0,0,0,0,0,0,0,0,0,6,4,6,0,0,0,0,0,0
0,0,0,0,0,0,0,0,0,6,6,6,6,0,0,0,0,0,0
0,0,0,0,0,0,0,0,6,6,0,0,6,6,0,0,0,0,0
0,0,0,0,0,0,0,0,6,0,0,0,0,6,6,0,0,0,0
0,0,0,0,0,0,0,0,0,0,0,0,0,0,0,0,0,0,0
0,0,0,0,0,0,0,0,0,0,0,0,0,0,0,0,0,0,0
0,0,0,0,0,0,0,0,0,0,0,0,0,0,0,0,0,0,0
0,0,0,0,0,0,0,0,0,0,0,0,0,0,0,0,0,0,0
0,0,0,0,0,0,0,0,0,0,0,0,0,0,0,0,0,0,0
0,0,0,0,0,0,0,0,0,0,0,0,0,0,0,0,0,0,0
0,0,0,0,0,0,0,0,0,0,0,0,0,0,0,0,0,0,0
0,0,0,0,0,0,0,0,0,0,0,0,0,0,0,0,0,0,0
0,0,0,0,0,0,0,0,0,0,0,0,0,0,0,0,0,0,0
:endlayer
layer: 24
0,0,0,0,0,0,0,0,0,0,0,0,0,0,0,0,0,0,0
0,0,0,0,0,0,0,0,0,0,0,0,0,0,0,0,0,0,0
0,0,0,0,0,0,0,0,0,0,0,0,0,0,0,0,0,0,0
0,0,0,0,0,0,0,0,68,0,0,0,0,0,68,0,0,0,0
0,0,0,0,0,0,0,0,0,68,0,0,0,68,0,0,0,0,0
0,0,0,0,0,0,0,0,0,0,68,0,68,0,0,0,0,0,0
0,0,0,0,0,0,0,0,0,0,0,52,0,0,0,0,0,0,0
0,0,0,0,0,0,0,0,0,0,68,0,68,0,0,0,0,0,0
0,0,0,0,0,0,0,0,0,68,0,0,0,68,0,0,0,0,0
0,0,0,0,0,0,0,0,68,0,0,0,0,0,68,0,0,0,0
0,0,0,0,0,0,0,0,0,0,0,0,0,0,0,0,0,0,0
0,0,0,0,0,0,0,0,0,0,0,0,0,0,0,0,0,0,0
0,0,0,0,0,0,0,0,0,0,0,0,0,0,0,0,0,0,0
0,0,0,0,0,0,0,0,0,0,0,0,0,0,0,0,0,0,0
0,0,0,0,0,0,0,0,0,0,0,0,0,0,0,0,0,0,0
0,0,0,0,0,0,0,0,0,0,0,0,0,0,0,0,0,0,0
0,0,0,0,0,0,0,0,0,0,0,0,0,0,0,0,0,0,0
0,0,0,0,0,0,0,0,0,0,0,0,0,0,0,0,0,0,0
0,0,0,0,0,0,0,0,0,0,0,0,0,0,0,0,0,0,0
:endlayer
layer: 25
0,0,0,0,0,0,0,0,0,0,0,0,0,0,0,0,0,0,0
0,0,0,0,0,0,0,0,0,0,0,0,0,0,0,0,0,0,0
0,0,0,0,0,0,0,0,0,0,0,0,0,0,0,0,0,0,0
0,0,0,0,0,0,0,0,68,0,0,0,0,0,68,0,0,0,0
0,0,0,0,0,0,0,0,0,68,0,0,0,68,0,0,0,0,0
0,0,0,0,0,0,0,0,0,0,68,0,68,0,0,0,0,0,0
0,0,0,0,0,0,0,0,0,0,0,52,0,0,0,0,0,0,0
0,0,0,0,0,0,0,0,0,0,68,0,68,0,0,0,0,0,0
0,0,0,0,0,0,0,0,0,68,0,0,0,68,0,0,0,0,0
0,0,0,0,0,0,0,0,68,0,0,0,0,0,68,0,0,0,0
0,0,0,0,0,0,0,0,0,0,0,0,0,0,0,0,0,0,0
0,0,0,0,0,0,0,0,0,0,0,0,0,0,0,0,0,0,0
0,0,0,0,0,0,0,0,0,0,0,0,0,0,0,0,0,0,0
0,0,0,0,0,0,0,0,0,0,0,0,0,0,0,0,0,0,0
0,0,0,0,0,0,0,0,0,0,0,0,0,0,0,0,0,0,0
0,0,0,0,0,0,0,0,0,0,0,0,0,0,0,0,0,0,0
0,0,0,0,0,0,0,0,0,0,0,0,0,0,0,0,0,0,0
0,0,0,0,0,0,0,0,0,0,0,0,0,0,0,0,0,0,0
0,0,0,0,0,0,0,0,0,0,0,0,0,0,0,0,0,0,0
:endlayer
layer: 26
0,0,0,0,0,0,0,0,0,0,0,0,0,0,0,0,0,0,0
0,0,0,0,0,0,0,0,0,0,0,0,0,0,0,0,0,0,0
0,0,0,0,0,0,0,0,0,0,0,0,0,0,0,0,0,0,0
0,0,0,0,0,0,0,0,68,0,0,0,0,0,68,0,0,0,0
0,0,0,0,0,0,0,0,0,68,0,0,0,68,0,0,0,0,0
0,0,0,0,0,0,0,0,0,0,68,0,68,0,0,0,0,0,0
0,0,0,0,0,0,0,0,0,0,0,52,0,0,0,0,0,0,0
0,0,0,0,0,0,0,0,0,0,68,0,68,0,0,0,0,0,0
0,0,0,0,0,0,0,0,0,68,0,0,0,68,0,0,0,0,0
0,0,0,0,0,0,0,0,68,0,0,0,0,0,68,0,0,0,0
0,0,0,0,0,0,0,0,0,0,0,0,0,0,0,0,0,0,0
0,0,0,0,0,0,0,0,0,0,0,0,0,0,0,0,0,0,0
0,0,0,0,0,0,0,0,0,0,0,0,0,0,0,0,0,0,0
0,0,0,0,0,0,0,0,0,0,0,0,0,0,0,0,0,0,0
0,0,0,0,0,0,0,0,0,0,0,0,0,0,0,0,0,0,0
0,0,0,0,0,0,0,0,0,0,0,0,0,0,0,0,0,0,0
0,0,0,0,0,0,0,0,0,0,0,0,0,0,0,0,0,0,0
0,0,0,0,0,0,0,0,0,0,0,0,0,0,0,0,0,0,0
0,0,0,0,0,0,0,0,0,0,0,0,0,0,0,0,0,0,0
:endlayer
layer: 27
0,0,0,0,0,0,0,0,0,0,0,0,0,0,0,0,0,0,0
0,0,0,0,0,0,0,0,0,0,0,0,0,0,0,0,0,0,0
0,0,0,0,0,0,0,0,0,0,0,0,0,0,0,0,0,0,0
0,0,0,0,0,0,0,0,54,0,0,0,0,0,54,0,0,0,0
0,0,0,0,0,0,0,0,0,54,0,0,0,54,0,0,0,0,0
0,0,0,0,0,0,0,0,0,0,54,0,54,0,0,0,0,0,0
0,0,0,0,0,0,0,0,0,0,0,4,0,0,0,0,0,0,0
0,0,0,0,0,0,0,0,0,0,54,0,54,0,0,0,0,0,0
0,0,0,0,0,0,0,0,0,54,0,0,0,54,0,0,0,0,0
0,0,0,0,0,0,0,0,54,0,0,0,0,0,54,0,0,0,0
0,0,0,0,0,0,0,0,0,0,0,0,0,0,0,0,0,0,0
0,0,0,0,0,0,0,0,0,0,0,0,0,0,0,0,0,0,0
0,0,0,0,0,0,0,0,0,0,0,0,0,0,0,0,0,0,0
0,0,0,0,0,0,0,0,0,0,0,0,0,0,0,0,0,0,0
0,0,0,0,0,0,0,0,0,0,0,0,0,0,0,0,0,0,0
0,0,0,0,0,0,0,0,0,0,0,0,0,0,0,0,0,0,0
0,0,0,0,0,0,0,0,0,0,0,0,0,0,0,0,0,0,0
0,0,0,0,0,0,0,0,0,0,0,0,0,0,0,0,0,0,0
0,0,0,0,0,0,0,0,0,0,0,0,0,0,0,0,0,0,0
:endlayer

#### RULES ####
rule:
plugin=vanillaBlocks
number=1
data:
JSON:{blockState:{blockName:"minecraft:dirt",properties:{variant:"dirt",snowy:"false"}}}
:enddata
:endrule

rule:
plugin=vanillaBlocks
number=2
data:
JSON:{blockState:{blockName:"minecraft:cobblestone"}}
:enddata
:endrule

rule:
plugin=vanillaBlocks
number=3
data:
JSON:{blockState:{blockName:"minecraft:grass",properties:{snowy:"false"}}}
:enddata
:endrule

rule:
plugin=vanillaBlocks
number=4
data:
JSON:{blockState:{blockName:"minecraft:double_stone_slab",properties:{seamless:"false",variant:"stone"}}}
:enddata
:endrule

rule:
plugin=vanillaBlocks
number=5
data:
JSON:{blockState:{blockName:"minecraft:tallgrass",properties:{type:"tall_grass"}}}
:enddata
:endrule

rule:
plugin=vanillaBlocks
number=6
data:
JSON:{blockState:{blockName:"minecraft:fence",properties:{east:"false",south:"false",north:"false",west:"false"}}}
:enddata
:endrule

rule:
plugin=vanillaBlocks
number=7
data:
JSON:{blockState:{blockName:"minecraft:fence_gate",properties:{in_wall:"false",powered:"false",facing:"north",open:"false"}}}
:enddata
:endrule

rule:
plugin=vanillaBlocks
number=8
data:
JSON:{blockState:{blockName:"minecraft:stonebrick",properties:{variant:"stonebrick"}}}
:enddata
:endrule

rule:
plugin=doors
number=9
data:
JSON:{blockState:{blockName:"minecraft:wooden_door",properties:{hinge:"left",half:"lower",powered:"false",facing:"north",open:"true"}}}
:enddata
:endrule

rule:
plugin=vanillaBlocks
number=10
data:
JSON:{blockState:{blockName:"minecraft:stone_brick_stairs",properties:{half:"bottom",shape:"straight",facing:"north"}}}
:enddata
:endrule

rule:
plugin=vanillaBlocks
number=11
data:
JSON:{blockState:{blockName:"minecraft:stone_stairs",properties:{half:"bottom",shape:"straight",facing:"east"}}}
:enddata
:endrule

rule:
plugin=vanillaBlocks
number=12
data:
JSON:{blockState:{blockName:"minecraft:stone_brick_stairs",properties:{half:"bottom",shape:"straight",facing:"west"}}}
:enddata
:endrule

rule:
plugin=inventory
number=13
data:
JSON:{blockState:{blockName:"minecraft:chest",properties:{facing:"west"}},lootLevel:0,teData:{ForgeData:{},Items:[{Slot:3b,id:"minecraft:wheat_seeds",Count:1b,Damage:0s},{Slot:6b,id:"minecraft:wheat_seeds",Count:1b,Damage:0s},{Slot:12b,id:"minecraft:wheat_seeds",Count:1b,Damage:0s},{Slot:14b,id:"minecraft:wheat_seeds",Count:1b,Damage:0s},{Slot:20b,id:"minecraft:wheat_seeds",Count:1b,Damage:0s},{Slot:23b,id:"minecraft:wheat_seeds",Count:1b,Damage:0s},{Slot:25b,id:"minecraft:wheat_seeds",Count:1b,Damage:0s}],id:"minecraft:chest",Lock:""},inventoryData:{length:7,inventoryContents:[{id:"minecraft:wheat_seeds",Count:1b,slot:0,Damage:0s},{id:"minecraft:wheat_seeds",Count:1b,slot:1,Damage:0s},{id:"minecraft:wheat_seeds",Count:1b,slot:2,Damage:0s},{id:"minecraft:wheat_seeds",Count:1b,slot:3,Damage:0s},{id:"minecraft:wheat_seeds",Count:1b,slot:4,Damage:0s},{id:"minecraft:wheat_seeds",Count:1b,slot:5,Damage:0s},{id:"minecraft:wheat_seeds",Count:1b,slot:6,Damage:0s}]},legacyFeatures:1b}
:enddata
:endrule

rule:
plugin=blockTile
number=14
data:
JSON:{blockState:{blockName:"ancientwarfarestructure:advanced_spawner",properties:{transparent:"true"}},teData:{id:"ancientwarfarestructure:advanced_spawner_tile",spawnerSettings:{minDelay:0,spawnDelay:0,lightSensitive:0b,spawnGroups:[{settingsList:[{remainingSpawnCount:1,hostile:1b,forced:1b,customTag:{ArmorDropChances:[1.0f,1.0f,1.0f,1.0f],ArmorItems:[{},{},{},{}],HandDropChances:[1.0f,1.0f],factionName:"empire",HandItems:[{},{}]},maxToSpawn:1,entityId:"ancientwarfarenpc:faction.civilian.female",minToSpawn:1}],groupWeight:1}],playerRange:6,respondToRedstone:0b,inventory:{Size:9,Items:[]},spawnRange:0,transparent:1b,maxDelay:0,xpToDrop:0,mobRange:0,debugMode:0b,maxNearbyMonsters:0}}}
:enddata
:endrule

rule:
plugin=inventory
number=15
data:
JSON:{blockState:{blockName:"minecraft:chest",properties:{facing:"west"}},lootLevel:0,teData:{Items:[{Slot:2b,id:"minecraft:wheat_seeds",Count:1b,Damage:0s},{Slot:5b,id:"minecraft:wheat_seeds",Count:1b,Damage:0s},{Slot:6b,id:"minecraft:wheat_seeds",Count:1b,Damage:0s},{Slot:10b,id:"minecraft:wheat_seeds",Count:1b,Damage:0s},{Slot:11b,id:"minecraft:wheat_seeds",Count:1b,Damage:0s},{Slot:13b,id:"minecraft:wheat_seeds",Count:1b,Damage:0s},{Slot:14b,id:"minecraft:wheat_seeds",Count:1b,Damage:0s},{Slot:15b,id:"minecraft:wheat_seeds",Count:1b,Damage:0s},{Slot:19b,id:"minecraft:wheat_seeds",Count:1b,Damage:0s}],id:"minecraft:chest",Lock:""},inventoryData:{length:9,inventoryContents:[{id:"minecraft:wheat_seeds",Count:1b,slot:0,Damage:0s},{id:"minecraft:wheat_seeds",Count:1b,slot:1,Damage:0s},{id:"minecraft:wheat_seeds",Count:1b,slot:2,Damage:0s},{id:"minecraft:wheat_seeds",Count:1b,slot:3,Damage:0s},{id:"minecraft:wheat_seeds",Count:1b,slot:4,Damage:0s},{id:"minecraft:wheat_seeds",Count:1b,slot:5,Damage:0s},{id:"minecraft:wheat_seeds",Count:1b,slot:6,Damage:0s},{id:"minecraft:wheat_seeds",Count:1b,slot:7,Damage:0s},{id:"minecraft:wheat_seeds",Count:1b,slot:8,Damage:0s}]},legacyFeatures:1b}
:enddata
:endrule

rule:
plugin=inventory
number=16
data:
JSON:{blockState:{blockName:"minecraft:chest",properties:{facing:"south"}},lootLevel:0,teData:{ForgeData:{},Items:[{Slot:3b,id:"minecraft:wheat",Count:1b,Damage:0s},{Slot:4b,id:"minecraft:wheat",Count:1b,Damage:0s},{Slot:5b,id:"minecraft:wheat",Count:1b,Damage:0s},{Slot:11b,id:"minecraft:wheat",Count:1b,Damage:0s},{Slot:14b,id:"minecraft:wheat",Count:1b,Damage:0s},{Slot:15b,id:"minecraft:wheat",Count:1b,Damage:0s},{Slot:16b,id:"minecraft:wheat",Count:1b,Damage:0s},{Slot:25b,id:"minecraft:wheat",Count:1b,Damage:0s}],id:"minecraft:chest",Lock:""},inventoryData:{length:8,inventoryContents:[{id:"minecraft:wheat",Count:1b,slot:0,Damage:0s},{id:"minecraft:wheat",Count:1b,slot:1,Damage:0s},{id:"minecraft:wheat",Count:1b,slot:2,Damage:0s},{id:"minecraft:wheat",Count:1b,slot:3,Damage:0s},{id:"minecraft:wheat",Count:1b,slot:4,Damage:0s},{id:"minecraft:wheat",Count:1b,slot:5,Damage:0s},{id:"minecraft:wheat",Count:1b,slot:6,Damage:0s},{id:"minecraft:wheat",Count:1b,slot:7,Damage:0s}]},legacyFeatures:1b}
:enddata
:endrule

rule:
plugin=inventory
number=17
data:
JSON:{blockState:{blockName:"minecraft:chest",properties:{facing:"south"}},lootLevel:0,teData:{ForgeData:{},Items:[{Slot:1b,id:"minecraft:wheat",Count:1b,Damage:0s},{Slot:3b,id:"minecraft:wheat",Count:1b,Damage:0s},{Slot:10b,id:"minecraft:wheat",Count:1b,Damage:0s},{Slot:12b,id:"minecraft:wheat",Count:1b,Damage:0s}],id:"minecraft:chest",Lock:""},inventoryData:{length:4,inventoryContents:[{id:"minecraft:wheat",Count:1b,slot:0,Damage:0s},{id:"minecraft:wheat",Count:1b,slot:1,Damage:0s},{id:"minecraft:wheat",Count:1b,slot:2,Damage:0s},{id:"minecraft:wheat",Count:1b,slot:3,Damage:0s}]},legacyFeatures:1b}
:enddata
:endrule

rule:
plugin=blockTile
number=18
data:
JSON:{blockState:{blockName:"ancientwarfarestructure:advanced_spawner",properties:{transparent:"true"}},teData:{id:"ancientwarfarestructure:advanced_spawner_tile",spawnerSettings:{minDelay:0,spawnDelay:0,lightSensitive:0b,spawnGroups:[{settingsList:[{remainingSpawnCount:1,hostile:1b,forced:1b,customTag:{ArmorDropChances:[1.0f,1.0f,1.0f,1.0f],ArmorItems:[{},{},{},{}],HandDropChances:[1.0f,1.0f],factionName:"empire",HandItems:[{},{}]},maxToSpawn:1,entityId:"ancientwarfarenpc:faction.civilian.female",minToSpawn:1}],groupWeight:1}],playerRange:6,respondToRedstone:0b,inventory:{Size:9,Items:[]},spawnRange:0,transparent:1b,maxDelay:0,xpToDrop:0,mobRange:0,debugMode:0b,maxNearbyMonsters:0}}}
:enddata
:endrule

rule:
plugin=inventory
number=19
data:
JSON:{blockState:{blockName:"minecraft:chest",properties:{facing:"north"}},lootLevel:0,teData:{ForgeData:{},Items:[{Slot:10b,id:"minecraft:bone",Count:2b,Damage:0s},{Slot:11b,id:"minecraft:bone",Count:1b,Damage:0s},{Slot:12b,id:"minecraft:bone",Count:1b,Damage:0s},{Slot:19b,id:"minecraft:bone",Count:2b,Damage:0s},{Slot:20b,id:"minecraft:bone",Count:1b,Damage:0s}],id:"minecraft:chest",Lock:""},inventoryData:{length:5,inventoryContents:[{id:"minecraft:bone",Count:2b,slot:0,Damage:0s},{id:"minecraft:bone",Count:1b,slot:1,Damage:0s},{id:"minecraft:bone",Count:1b,slot:2,Damage:0s},{id:"minecraft:bone",Count:2b,slot:3,Damage:0s},{id:"minecraft:bone",Count:1b,slot:4,Damage:0s}]},legacyFeatures:1b}
:enddata
:endrule

rule:
plugin=inventory
number=20
data:
JSON:{blockState:{blockName:"minecraft:chest",properties:{facing:"north"}},lootLevel:0,teData:{ForgeData:{},Items:[{Slot:1b,id:"minecraft:bone",Count:1b,Damage:0s},{Slot:3b,id:"minecraft:bone",Count:1b,Damage:0s},{Slot:10b,id:"minecraft:bone",Count:1b,Damage:0s},{Slot:12b,id:"minecraft:bone",Count:1b,Damage:0s},{Slot:20b,id:"minecraft:bone",Count:2b,Damage:0s},{Slot:21b,id:"minecraft:bone",Count:1b,Damage:0s}],id:"minecraft:chest",Lock:""},inventoryData:{length:6,inventoryContents:[{id:"minecraft:bone",Count:1b,slot:0,Damage:0s},{id:"minecraft:bone",Count:1b,slot:1,Damage:0s},{id:"minecraft:bone",Count:1b,slot:2,Damage:0s},{id:"minecraft:bone",Count:1b,slot:3,Damage:0s},{id:"minecraft:bone",Count:2b,slot:4,Damage:0s},{id:"minecraft:bone",Count:1b,slot:5,Damage:0s}]},legacyFeatures:1b}
:enddata
:endrule

rule:
plugin=vanillaBlocks
number=21
data:
JSON:{blockState:{blockName:"minecraft:stone_slab",properties:{half:"bottom",variant:"stone"}}}
:enddata
:endrule

rule:
plugin=inventory
number=22
data:
JSON:{blockState:{blockName:"minecraft:chest",properties:{facing:"east"}},lootLevel:0,teData:{Items:[{Slot:12b,id:"minecraft:bread",Count:1b,Damage:0s},{Slot:15b,id:"minecraft:bread",Count:2b,Damage:0s},{Slot:23b,id:"minecraft:bread",Count:1b,Damage:0s},{Slot:24b,id:"minecraft:bread",Count:1b,Damage:0s}],id:"minecraft:chest",Lock:""},inventoryData:{length:4,inventoryContents:[{id:"minecraft:bread",Count:1b,slot:0,Damage:0s},{id:"minecraft:bread",Count:2b,slot:1,Damage:0s},{id:"minecraft:bread",Count:1b,slot:2,Damage:0s},{id:"minecraft:bread",Count:1b,slot:3,Damage:0s}]},legacyFeatures:1b}
:enddata
:endrule

rule:
plugin=inventory
number=23
data:
JSON:{blockState:{blockName:"minecraft:chest",properties:{facing:"east"}},lootLevel:0,teData:{ForgeData:{},Items:[{Slot:6b,id:"minecraft:bread",Count:1b,Damage:0s},{Slot:15b,id:"minecraft:bread",Count:1b,Damage:0s},{Slot:24b,id:"minecraft:bread",Count:1b,Damage:0s}],id:"minecraft:chest",Lock:""},inventoryData:{length:3,inventoryContents:[{id:"minecraft:bread",Count:1b,slot:0,Damage:0s},{id:"minecraft:bread",Count:1b,slot:1,Damage:0s},{id:"minecraft:bread",Count:1b,slot:2,Damage:0s}]},legacyFeatures:1b}
:enddata
:endrule

rule:
plugin=vanillaBlocks
number=24
data:
JSON:{blockState:{blockName:"minecraft:crafting_table"}}
:enddata
:endrule

rule:
plugin=vanillaBlocks
number=25
data:
JSON:{blockState:{blockName:"minecraft:fence_gate",properties:{in_wall:"false",powered:"false",facing:"south",open:"false"}}}
:enddata
:endrule

rule:
plugin=vanillaBlocks
number=26
data:
JSON:{blockState:{blockName:"minecraft:torch",properties:{facing:"up"}}}
:enddata
:endrule

rule:
plugin=vanillaSign
number=27
data:
JSON:{signContents0:"",blockState:{blockName:"minecraft:wall_sign",properties:{facing:"south"}},signContents2:"Mill§r§r",signContents1:"New Fangled§r§r",signContents3:"",rotation:0}
:enddata
:endrule

rule:
plugin=doors
number=28
data:
JSON:{blockState:{blockName:"minecraft:wooden_door",properties:{hinge:"left",half:"upper",powered:"false",facing:"south",open:"false"}}}
:enddata
:endrule

rule:
plugin=vanillaBlocks
number=29
data:
JSON:{blockState:{blockName:"minecraft:torch",properties:{facing:"north"}}}
:enddata
:endrule

rule:
plugin=vanillaBlocks
number=30
data:
JSON:{blockState:{blockName:"minecraft:torch",properties:{facing:"south"}}}
:enddata
:endrule

rule:
plugin=vanillaSign
number=31
data:
JSON:{signContents0:"",blockState:{blockName:"minecraft:wall_sign",properties:{facing:"north"}},signContents2:"Mill§r§r",signContents1:"New Fangled§r§r",signContents3:"",rotation:0}
:enddata
:endrule

rule:
plugin=inventory
number=32
data:
JSON:{blockState:{blockName:"minecraft:chest",properties:{facing:"west"}},lootLevel:0,teData:{ForgeData:{},Items:[{Slot:15b,id:"minecraft:wheat_seeds",Count:1b,Damage:0s},{Slot:16b,id:"minecraft:wheat_seeds",Count:1b,Damage:0s},{Slot:22b,id:"minecraft:wheat_seeds",Count:1b,Damage:0s},{Slot:23b,id:"minecraft:wheat_seeds",Count:1b,Damage:0s}],id:"minecraft:chest",Lock:""},inventoryData:{length:4,inventoryContents:[{id:"minecraft:wheat_seeds",Count:1b,slot:0,Damage:0s},{id:"minecraft:wheat_seeds",Count:1b,slot:1,Damage:0s},{id:"minecraft:wheat_seeds",Count:1b,slot:2,Damage:0s},{id:"minecraft:wheat_seeds",Count:1b,slot:3,Damage:0s}]},legacyFeatures:1b}
:enddata
:endrule

rule:
plugin=vanillaBlocks
number=33
data:
JSON:{blockState:{blockName:"minecraft:torch",properties:{facing:"east"}}}
:enddata
:endrule

rule:
plugin=inventory
number=34
data:
JSON:{blockState:{blockName:"minecraft:chest",properties:{facing:"west"}},lootLevel:0,teData:{ForgeData:{},Items:[{Slot:3b,id:"minecraft:wheat_seeds",Count:1b,Damage:0s},{Slot:6b,id:"minecraft:wheat_seeds",Count:1b,Damage:0s},{Slot:19b,id:"minecraft:wheat_seeds",Count:1b,Damage:0s},{Slot:23b,id:"minecraft:wheat_seeds",Count:1b,Damage:0s}],id:"minecraft:chest",Lock:""},inventoryData:{length:4,inventoryContents:[{id:"minecraft:wheat_seeds",Count:1b,slot:0,Damage:0s},{id:"minecraft:wheat_seeds",Count:1b,slot:1,Damage:0s},{id:"minecraft:wheat_seeds",Count:1b,slot:2,Damage:0s},{id:"minecraft:wheat_seeds",Count:1b,slot:3,Damage:0s}]},legacyFeatures:1b}
:enddata
:endrule

rule:
plugin=inventory
number=35
data:
JSON:{blockState:{blockName:"minecraft:chest",properties:{facing:"south"}},lootLevel:0,teData:{Items:[{Slot:13b,id:"minecraft:wheat",Count:1b,Damage:0s},{Slot:14b,id:"minecraft:wheat",Count:1b,Damage:0s},{Slot:15b,id:"minecraft:wheat",Count:1b,Damage:0s},{Slot:22b,id:"minecraft:wheat",Count:1b,Damage:0s},{Slot:25b,id:"minecraft:wheat",Count:1b,Damage:0s}],id:"minecraft:chest",Lock:""},inventoryData:{length:5,inventoryContents:[{id:"minecraft:wheat",Count:1b,slot:0,Damage:0s},{id:"minecraft:wheat",Count:1b,slot:1,Damage:0s},{id:"minecraft:wheat",Count:1b,slot:2,Damage:0s},{id:"minecraft:wheat",Count:1b,slot:3,Damage:0s},{id:"minecraft:wheat",Count:1b,slot:4,Damage:0s}]},legacyFeatures:1b}
:enddata
:endrule

rule:
plugin=inventory
number=36
data:
JSON:{blockState:{blockName:"minecraft:chest",properties:{facing:"south"}},lootLevel:0,teData:{ForgeData:{},Items:[{Slot:4b,id:"minecraft:wheat",Count:1b,Damage:0s},{Slot:7b,id:"minecraft:wheat",Count:1b,Damage:0s},{Slot:10b,id:"minecraft:wheat",Count:1b,Damage:0s},{Slot:14b,id:"minecraft:wheat",Count:1b,Damage:0s},{Slot:15b,id:"minecraft:wheat",Count:1b,Damage:0s},{Slot:16b,id:"minecraft:wheat",Count:1b,Damage:0s},{Slot:19b,id:"minecraft:wheat",Count:1b,Damage:0s}],id:"minecraft:chest",Lock:""},inventoryData:{length:7,inventoryContents:[{id:"minecraft:wheat",Count:1b,slot:0,Damage:0s},{id:"minecraft:wheat",Count:1b,slot:1,Damage:0s},{id:"minecraft:wheat",Count:1b,slot:2,Damage:0s},{id:"minecraft:wheat",Count:1b,slot:3,Damage:0s},{id:"minecraft:wheat",Count:1b,slot:4,Damage:0s},{id:"minecraft:wheat",Count:1b,slot:5,Damage:0s},{id:"minecraft:wheat",Count:1b,slot:6,Damage:0s}]},legacyFeatures:1b}
:enddata
:endrule

rule:
plugin=inventory
number=37
data:
JSON:{blockState:{blockName:"minecraft:chest",properties:{facing:"north"}},lootLevel:0,teData:{ForgeData:{},Items:[{Slot:13b,id:"minecraft:wheat",Count:1b,Damage:0s},{Slot:15b,id:"minecraft:wheat",Count:1b,Damage:0s},{Slot:17b,id:"minecraft:wheat",Count:1b,Damage:0s},{Slot:21b,id:"minecraft:wheat",Count:1b,Damage:0s},{Slot:26b,id:"minecraft:wheat",Count:1b,Damage:0s}],id:"minecraft:chest",Lock:""},inventoryData:{length:5,inventoryContents:[{id:"minecraft:wheat",Count:1b,slot:0,Damage:0s},{id:"minecraft:wheat",Count:1b,slot:1,Damage:0s},{id:"minecraft:wheat",Count:1b,slot:2,Damage:0s},{id:"minecraft:wheat",Count:1b,slot:3,Damage:0s},{id:"minecraft:wheat",Count:1b,slot:4,Damage:0s}]},legacyFeatures:1b}
:enddata
:endrule

rule:
plugin=inventory
number=38
data:
JSON:{blockState:{blockName:"minecraft:chest",properties:{facing:"north"}},lootLevel:0,teData:{ForgeData:{},Items:[{Slot:2b,id:"minecraft:wheat",Count:1b,Damage:0s},{Slot:3b,id:"minecraft:wheat",Count:1b,Damage:0s},{Slot:8b,id:"minecraft:wheat",Count:1b,Damage:0s},{Slot:11b,id:"minecraft:wheat",Count:1b,Damage:0s},{Slot:15b,id:"minecraft:wheat",Count:1b,Damage:0s},{Slot:16b,id:"minecraft:wheat",Count:1b,Damage:0s},{Slot:17b,id:"minecraft:wheat",Count:1b,Damage:0s},{Slot:20b,id:"minecraft:wheat",Count:1b,Damage:0s}],id:"minecraft:chest",Lock:""},inventoryData:{length:8,inventoryContents:[{id:"minecraft:wheat",Count:1b,slot:0,Damage:0s},{id:"minecraft:wheat",Count:1b,slot:1,Damage:0s},{id:"minecraft:wheat",Count:1b,slot:2,Damage:0s},{id:"minecraft:wheat",Count:1b,slot:3,Damage:0s},{id:"minecraft:wheat",Count:1b,slot:4,Damage:0s},{id:"minecraft:wheat",Count:1b,slot:5,Damage:0s},{id:"minecraft:wheat",Count:1b,slot:6,Damage:0s},{id:"minecraft:wheat",Count:1b,slot:7,Damage:0s}]},legacyFeatures:1b}
:enddata
:endrule

rule:
plugin=vanillaBlocks
number=39
data:
JSON:{blockState:{blockName:"minecraft:stone",properties:{variant:"stone"}}}
:enddata
:endrule

rule:
plugin=inventory
number=40
data:
JSON:{blockState:{blockName:"minecraft:chest",properties:{facing:"east"}},lootLevel:0,teData:{ForgeData:{},Items:[{Slot:14b,id:"minecraft:wheat",Count:1b,Damage:0s},{Slot:15b,id:"minecraft:wheat",Count:1b,Damage:0s},{Slot:20b,id:"minecraft:wheat",Count:1b,Damage:0s},{Slot:22b,id:"minecraft:wheat",Count:1b,Damage:0s},{Slot:25b,id:"minecraft:wheat",Count:1b,Damage:0s}],id:"minecraft:chest",Lock:""},inventoryData:{length:5,inventoryContents:[{id:"minecraft:wheat",Count:1b,slot:0,Damage:0s},{id:"minecraft:wheat",Count:1b,slot:1,Damage:0s},{id:"minecraft:wheat",Count:1b,slot:2,Damage:0s},{id:"minecraft:wheat",Count:1b,slot:3,Damage:0s},{id:"minecraft:wheat",Count:1b,slot:4,Damage:0s}]},legacyFeatures:1b}
:enddata
:endrule

rule:
plugin=inventory
number=41
data:
JSON:{blockState:{blockName:"minecraft:chest",properties:{facing:"east"}},lootLevel:0,teData:{ForgeData:{},Items:[{Slot:4b,id:"minecraft:wheat",Count:1b,Damage:0s},{Slot:7b,id:"minecraft:wheat",Count:1b,Damage:0s},{Slot:11b,id:"minecraft:wheat",Count:1b,Damage:0s},{Slot:13b,id:"minecraft:wheat",Count:1b,Damage:0s},{Slot:16b,id:"minecraft:wheat",Count:1b,Damage:0s},{Slot:20b,id:"minecraft:wheat",Count:1b,Damage:0s},{Slot:23b,id:"minecraft:wheat",Count:1b,Damage:0s},{Slot:24b,id:"minecraft:wheat",Count:1b,Damage:0s},{Slot:25b,id:"minecraft:wheat",Count:1b,Damage:0s}],id:"minecraft:chest",Lock:""},inventoryData:{length:9,inventoryContents:[{id:"minecraft:wheat",Count:1b,slot:0,Damage:0s},{id:"minecraft:wheat",Count:1b,slot:1,Damage:0s},{id:"minecraft:wheat",Count:1b,slot:2,Damage:0s},{id:"minecraft:wheat",Count:1b,slot:3,Damage:0s},{id:"minecraft:wheat",Count:1b,slot:4,Damage:0s},{id:"minecraft:wheat",Count:1b,slot:5,Damage:0s},{id:"minecraft:wheat",Count:1b,slot:6,Damage:0s},{id:"minecraft:wheat",Count:1b,slot:7,Damage:0s},{id:"minecraft:wheat",Count:1b,slot:8,Damage:0s}]},legacyFeatures:1b}
:enddata
:endrule

rule:
plugin=vanillaBlocks
number=42
data:
JSON:{blockState:{blockName:"minecraft:torch",properties:{facing:"west"}}}
:enddata
:endrule

rule:
plugin=vanillaBlocks
number=43
data:
JSON:{blockState:{blockName:"minecraft:wooden_slab",properties:{half:"top",variant:"oak"}}}
:enddata
:endrule

rule:
plugin=vanillaBlocks
number=44
data:
JSON:{blockState:{blockName:"minecraft:oak_stairs",properties:{half:"top",shape:"straight",facing:"north"}}}
:enddata
:endrule

rule:
plugin=vanillaBlocks
number=45
data:
JSON:{blockState:{blockName:"minecraft:stone_stairs",properties:{half:"bottom",shape:"straight",facing:"west"}}}
:enddata
:endrule

rule:
plugin=vanillaBlocks
number=46
data:
JSON:{blockState:{blockName:"minecraft:oak_stairs",properties:{half:"top",shape:"straight",facing:"east"}}}
:enddata
:endrule

rule:
plugin=vanillaBlocks
number=47
data:
JSON:{blockState:{blockName:"minecraft:oak_stairs",properties:{half:"top",shape:"straight",facing:"west"}}}
:enddata
:endrule

rule:
plugin=vanillaBlocks
number=48
data:
JSON:{blockState:{blockName:"minecraft:oak_stairs",properties:{half:"bottom",shape:"straight",facing:"north"}}}
:enddata
:endrule

rule:
plugin=vanillaBlocks
number=49
data:
JSON:{blockState:{blockName:"minecraft:oak_stairs",properties:{half:"bottom",shape:"straight",facing:"west"}}}
:enddata
:endrule

rule:
plugin=vanillaBlocks
number=50
data:
JSON:{blockState:{blockName:"minecraft:oak_stairs",properties:{half:"bottom",shape:"straight",facing:"east"}}}
:enddata
:endrule

rule:
plugin=vanillaBlocks
number=51
data:
JSON:{blockState:{blockName:"minecraft:oak_stairs",properties:{half:"bottom",shape:"straight",facing:"south"}}}
:enddata
:endrule

rule:
plugin=vanillaBlocks
number=52
data:
JSON:{blockState:{blockName:"minecraft:log",properties:{variant:"oak",axis:"y"}}}
:enddata
:endrule

rule:
plugin=vanillaBlocks
number=53
data:
JSON:{blockState:{blockName:"minecraft:double_stone_slab",properties:{seamless:"false",variant:"wood_old"}}}
:enddata
:endrule

rule:
plugin=vanillaBlocks
number=54
data:
JSON:{blockState:{blockName:"minecraft:stone_slab",properties:{half:"bottom",variant:"wood_old"}}}
:enddata
:endrule

rule:
plugin=vanillaBlocks
number=55
data:
JSON:{blockState:{blockName:"minecraft:planks",properties:{variant:"oak"}}}
:enddata
:endrule

rule:
plugin=vanillaBlocks
number=56
data:
JSON:{blockState:{blockName:"minecraft:stone_stairs",properties:{half:"bottom",shape:"straight",facing:"south"}}}
:enddata
:endrule

rule:
plugin=vanillaBlocks
number=57
data:
JSON:{blockState:{blockName:"minecraft:iron_block"}}
:enddata
:endrule

rule:
plugin=bed
number=58
data:
JSON:{blockState:{blockName:"minecraft:bed",properties:{part:"foot",facing:"west",occupied:"false"}},bedColor:14}
:enddata
:endrule

rule:
plugin=bed
number=59
data:
JSON:{blockState:{blockName:"minecraft:bed",properties:{part:"head",facing:"west",occupied:"false"}},bedColor:14}
:enddata
:endrule

rule:
plugin=inventory
number=60
data:
JSON:{blockState:{blockName:"minecraft:chest",properties:{facing:"south"}},lootLevel:0,teData:{ForgeData:{},Items:[{Slot:23b,id:"minecraft:rotten_flesh",Count:12b,Damage:0s}],id:"minecraft:chest",Lock:""},inventoryData:{length:1,inventoryContents:[{id:"minecraft:rotten_flesh",Count:12b,slot:0,Damage:0s}]},legacyFeatures:1b}
:enddata
:endrule

rule:
plugin=inventory
number=61
data:
JSON:{blockState:{blockName:"minecraft:chest",properties:{facing:"south"}},lootLevel:0,teData:{Items:[],id:"minecraft:chest",Lock:""},inventoryData:{length:0,inventoryContents:[]},legacyFeatures:1b}
:enddata
:endrule

rule:
plugin=inventory
number=62
data:
JSON:{blockState:{blockName:"minecraft:furnace",properties:{facing:"east"}},lootLevel:0,teData:{CookTime:0,BurnTime:0,Items:[],id:"minecraft:furnace",CookTimeTotal:0,Lock:""},inventoryData:{length:0,inventoryContents:[]},legacyFeatures:0b}
:enddata
:endrule

rule:
plugin=inventory
number=63
data:
JSON:{blockState:{blockName:"minecraft:chest",properties:{facing:"east"}},lootLevel:0,teData:{ForgeData:{},Items:[{Slot:4b,id:"minecraft:beef",Count:1b,Damage:0s},{Slot:5b,id:"minecraft:beef",Count:1b,Damage:0s},{Slot:10b,id:"minecraft:melon",Count:3b,Damage:0s},{Slot:14b,id:"minecraft:beef",Count:2b,Damage:0s}],id:"minecraft:chest",Lock:""},inventoryData:{length:4,inventoryContents:[{id:"minecraft:beef",Count:1b,slot:0,Damage:0s},{id:"minecraft:beef",Count:1b,slot:1,Damage:0s},{id:"minecraft:melon",Count:3b,slot:2,Damage:0s},{id:"minecraft:beef",Count:2b,slot:3,Damage:0s}]},legacyFeatures:1b}
:enddata
:endrule

rule:
plugin=inventory
number=64
data:
JSON:{blockState:{blockName:"minecraft:chest",properties:{facing:"east"}},lootLevel:0,teData:{Items:[{Slot:1b,id:"minecraft:porkchop",Count:2b,Damage:0s},{Slot:4b,id:"minecraft:bread",Count:2b,Damage:0s},{Slot:9b,id:"minecraft:porkchop",Count:1b,Damage:0s},{Slot:10b,id:"minecraft:porkchop",Count:1b,Damage:0s},{Slot:13b,id:"minecraft:bread",Count:1b,Damage:0s},{Slot:16b,id:"minecraft:chicken",Count:2b,Damage:0s}],id:"minecraft:chest",Lock:""},inventoryData:{length:6,inventoryContents:[{id:"minecraft:porkchop",Count:2b,slot:0,Damage:0s},{id:"minecraft:bread",Count:2b,slot:1,Damage:0s},{id:"minecraft:porkchop",Count:1b,slot:2,Damage:0s},{id:"minecraft:porkchop",Count:1b,slot:3,Damage:0s},{id:"minecraft:bread",Count:1b,slot:4,Damage:0s},{id:"minecraft:chicken",Count:2b,slot:5,Damage:0s}]},legacyFeatures:1b}
:enddata
:endrule

rule:
plugin=doors
number=65
data:
JSON:{blockState:{blockName:"minecraft:wooden_door",properties:{hinge:"left",half:"lower",powered:"false",facing:"north",open:"false"}}}
:enddata
:endrule

rule:
plugin=vanillaBlocks
number=66
data:
JSON:{blockState:{blockName:"minecraft:glass_pane",properties:{east:"false",south:"false",north:"false",west:"false"}}}
:enddata
:endrule

rule:
plugin=vanillaBlocks
number=67
data:
JSON:{blockState:{blockName:"minecraft:stone_slab",properties:{half:"bottom",variant:"stone_brick"}}}
:enddata
:endrule

rule:
plugin=vanillaBlocks
number=68
data:
JSON:{blockState:{blockName:"minecraft:wool",properties:{color:"white"}}}
:enddata
:endrule

#### ENTITIES ####
