# Ancient Warfare Structure Template File
# Auto-generated structure template file. created on: 8/19/2019 at: 10:23:11
# Lines beginning with # denote comments

header:
version=2.9
name=EmpireStoneMason
mods=
size=18,12,19
offset=10,7,18
:endheader

#### VALIDATION ####
validation:
type=ground
survival=false
worldGenEnabled=true
unique=false
preserveBlocks=false
selectionWeight=30
clusterValue=20
minDuplicateDistance=600
dimensionWhiteList=true
dimensionList=0
biomeWhiteList=true
biomeList=biomesoplenty:meadow,minecraft:extreme_hills,traverse:meadow,minecraft:plains
leveling=5
fill=5
border=5
blockSwap=false
:endvalidation

#### LAYERS ####
layer: 0
1,1,1,1,1,1,1,1,1,1,1,1,1,1,1,1,1,1
1,1,1,1,1,1,1,1,1,1,1,1,1,1,1,1,1,1
1,1,1,1,1,1,1,1,1,1,1,1,1,1,1,1,1,1
1,1,1,1,1,1,1,1,1,1,1,1,1,1,1,1,1,1
1,1,1,1,1,1,1,1,1,1,1,1,1,1,1,1,1,1
1,1,1,1,1,1,1,1,1,1,1,1,1,1,1,1,1,1
1,1,1,1,1,1,1,1,1,1,1,1,1,1,1,1,1,1
1,1,1,1,1,1,1,1,1,1,1,1,1,1,1,1,1,1
1,1,1,1,1,1,1,1,1,1,1,1,1,1,1,1,1,1
1,1,1,1,1,1,1,1,1,1,1,1,1,1,1,1,1,1
1,1,1,1,1,1,1,1,1,1,1,1,1,1,1,1,1,1
1,1,1,1,1,1,1,1,1,1,1,1,1,1,1,1,1,1
1,1,1,1,1,1,1,1,1,1,1,1,1,1,1,1,1,1
1,1,1,1,1,1,1,1,1,1,1,1,1,1,1,1,1,1
1,1,1,1,1,1,1,1,1,1,1,1,1,1,1,1,1,1
1,1,1,1,1,1,1,1,1,1,1,1,1,1,1,1,1,1
1,1,1,1,1,1,1,1,1,1,1,1,1,1,1,1,1,1
1,1,1,1,1,1,1,1,1,1,1,1,1,1,1,1,1,1
1,1,1,1,1,1,1,1,1,1,1,1,1,1,1,1,1,1
:endlayer
layer: 1
1,1,1,1,1,1,1,1,1,1,1,1,1,1,1,1,1,1
1,1,1,1,1,1,1,1,1,1,1,1,1,1,1,1,1,1
1,1,1,1,1,1,1,1,1,1,1,1,1,1,1,1,1,1
1,1,1,1,1,1,1,1,1,1,1,1,1,1,1,1,1,1
1,1,1,1,1,1,1,1,1,1,1,1,1,1,1,1,1,1
1,1,1,1,1,1,1,1,1,1,1,1,1,1,1,1,1,1
1,1,1,1,1,1,1,1,1,1,1,1,1,1,1,1,1,1
1,1,1,1,1,1,1,1,1,1,1,1,1,1,1,1,1,1
1,1,1,1,1,1,1,1,1,1,1,1,1,1,1,1,1,1
1,1,1,1,1,1,1,1,1,1,1,1,1,1,1,1,1,1
1,1,1,1,1,1,1,1,1,1,1,1,1,1,1,1,1,1
1,1,1,1,1,1,1,1,1,1,1,1,1,1,1,1,1,1
1,1,1,1,1,1,1,1,1,1,1,1,1,1,1,1,1,1
1,1,1,1,1,1,1,1,1,1,1,1,1,1,1,1,1,1
1,1,1,1,1,1,1,1,1,1,1,1,1,1,1,1,1,1
1,1,1,1,1,1,1,1,1,1,1,1,1,1,1,1,1,1
1,1,1,1,1,1,1,1,1,1,1,1,1,1,1,1,1,1
1,1,1,1,1,1,1,1,1,1,1,1,1,1,1,1,1,1
1,1,1,1,1,1,1,1,1,1,1,1,1,1,1,1,1,1
:endlayer
layer: 2
1,1,1,1,1,1,1,1,1,1,1,1,1,1,1,1,1,1
1,1,1,1,1,1,1,1,1,1,1,1,1,1,1,1,1,1
1,1,1,1,1,1,1,1,1,1,1,1,1,1,1,1,1,1
1,1,1,1,1,1,1,1,1,1,1,1,1,1,1,1,1,1
1,1,1,1,1,1,1,1,1,1,1,1,1,1,1,1,1,1
1,1,1,1,1,1,1,1,1,1,1,1,1,1,1,1,1,1
1,1,1,1,1,1,1,1,1,1,1,1,1,1,1,1,1,1
1,1,1,1,1,1,1,1,1,1,1,1,1,1,1,1,1,1
1,1,1,1,1,1,1,1,1,1,1,1,1,1,1,1,1,1
1,1,1,1,1,1,1,1,1,1,1,1,1,1,1,1,1,1
1,1,1,1,1,1,1,1,1,1,1,1,1,1,1,1,1,1
1,1,1,1,1,1,1,1,1,1,1,1,1,1,1,1,1,1
1,1,1,1,1,1,1,1,1,1,1,1,1,1,1,1,1,1
1,1,1,1,1,1,1,1,1,1,1,1,1,1,1,1,1,1
1,1,1,1,1,1,1,1,1,1,1,1,1,1,1,1,1,1
1,1,1,1,1,1,1,1,1,1,1,1,1,1,1,1,1,1
1,1,1,1,1,1,1,1,1,1,1,1,1,1,1,1,1,1
1,1,1,1,1,1,1,1,1,1,1,1,1,1,1,1,1,1
1,1,1,1,1,1,1,1,1,1,1,1,1,1,1,1,1,1
:endlayer
layer: 3
1,1,1,1,1,1,1,1,1,1,1,1,1,1,1,1,1,1
1,1,1,1,1,1,1,1,1,1,1,1,1,1,1,1,1,1
1,1,1,1,1,1,1,1,1,1,1,1,1,1,1,1,1,1
1,1,1,1,1,1,1,1,1,1,1,1,1,1,1,1,1,1
1,1,1,1,1,1,1,1,1,1,1,1,1,1,1,1,1,1
1,1,1,1,1,1,1,1,1,1,1,1,1,1,1,1,1,1
1,1,1,1,1,1,1,1,1,1,1,1,1,1,1,1,1,1
1,1,1,1,1,1,1,1,1,1,1,1,1,1,1,1,1,1
1,1,1,1,1,1,1,1,1,1,1,1,1,1,1,1,1,1
1,1,1,1,1,1,1,1,1,1,1,1,1,1,1,1,1,1
1,1,1,1,1,1,1,1,1,1,1,1,1,1,1,1,1,1
1,1,1,1,1,1,1,1,1,1,1,1,1,1,1,1,1,1
1,1,1,1,1,1,1,1,1,1,1,1,1,1,1,1,1,1
1,1,1,1,1,1,1,1,1,1,1,1,1,1,1,1,1,1
1,1,1,1,1,1,1,1,1,1,1,1,1,1,1,1,1,1
1,1,1,1,1,1,1,1,1,1,1,1,1,1,1,1,1,1
1,1,1,1,1,1,1,1,1,1,1,1,1,1,1,1,1,1
1,1,1,1,1,1,1,1,1,1,1,1,1,1,1,1,1,1
1,1,1,1,1,1,1,1,1,1,1,1,1,1,1,1,1,1
:endlayer
layer: 4
1,1,1,1,1,1,1,1,1,1,1,1,1,1,1,1,1,1
1,1,1,1,1,1,1,1,1,1,1,1,1,1,1,1,1,1
1,1,1,1,1,1,1,1,1,1,1,1,1,1,1,1,1,1
1,1,1,1,1,1,1,1,1,1,1,1,1,1,1,1,1,1
1,1,1,1,1,1,1,1,1,1,1,1,1,1,1,1,1,1
1,1,1,1,1,1,1,1,1,1,1,1,1,1,1,1,1,1
1,1,1,1,1,1,1,1,1,1,1,1,1,1,1,1,1,1
1,1,1,1,1,1,1,1,1,1,1,1,1,1,1,1,1,1
1,1,1,1,1,1,1,1,1,1,1,1,1,1,1,1,1,1
1,1,1,1,1,1,1,1,1,1,1,1,1,1,1,1,1,1
1,1,1,1,1,1,1,1,1,1,1,1,1,1,1,1,1,1
1,1,1,1,1,1,1,1,1,1,1,1,1,1,1,1,1,1
1,1,1,1,1,1,1,1,1,1,1,1,1,1,1,1,1,1
1,1,1,1,1,1,1,1,1,1,1,1,1,1,1,1,1,1
1,1,1,1,1,1,1,1,1,1,1,1,1,1,1,1,1,1
1,1,1,1,1,1,1,1,1,1,1,1,1,1,1,1,1,1
1,1,1,1,1,1,1,1,1,1,1,1,1,1,1,1,1,1
1,1,1,1,1,1,1,1,1,1,1,1,1,1,1,1,1,1
1,1,1,1,1,1,1,1,1,1,1,1,1,1,1,1,1,1
:endlayer
layer: 5
1,1,1,1,1,1,1,1,1,1,1,1,1,1,1,1,1,1
1,1,1,1,1,1,1,1,1,1,1,1,1,1,1,1,1,1
1,1,1,1,1,1,1,1,1,1,1,1,1,1,1,1,1,1
1,1,1,1,1,1,1,1,1,1,1,1,1,1,1,1,1,1
1,1,1,1,1,1,1,1,1,1,1,1,1,1,1,1,1,1
1,1,1,1,1,1,1,1,1,1,1,1,1,1,1,1,1,1
1,1,1,1,1,1,1,1,1,1,1,1,1,1,1,1,1,1
1,1,1,1,1,1,1,1,1,1,1,1,1,1,1,1,1,1
1,1,1,1,1,1,1,1,1,1,1,1,1,1,1,1,1,1
1,1,1,1,1,1,1,1,1,1,1,1,1,1,1,1,1,1
1,1,1,1,1,1,1,1,1,1,1,1,1,1,1,1,1,1
1,1,1,1,1,1,1,1,1,1,1,1,1,1,1,1,1,1
1,1,1,1,1,1,1,1,1,1,1,1,1,1,1,1,1,1
1,1,1,1,1,1,1,1,1,1,1,1,1,1,1,1,1,1
1,1,1,1,1,1,1,1,1,1,1,1,1,1,1,1,1,1
1,1,1,1,1,1,1,1,1,1,1,1,1,1,1,1,1,1
1,1,1,1,1,1,1,1,1,1,1,1,1,1,1,1,1,1
1,1,1,1,1,1,1,1,1,1,1,1,1,1,1,1,1,1
1,1,1,1,1,1,1,1,1,1,1,1,1,1,1,1,1,1
:endlayer
layer: 6
2,2,2,2,2,2,2,2,2,2,2,2,2,2,2,2,2,2
2,1,1,1,1,1,1,1,1,1,1,1,2,2,2,2,2,2
2,1,4,4,4,4,4,4,4,4,4,1,2,2,2,2,2,2
2,1,4,4,4,4,4,4,4,4,4,1,2,1,1,1,2,2
2,1,4,4,4,4,4,4,4,4,4,1,2,1,1,1,2,2
2,1,4,4,4,4,4,4,4,4,4,1,2,1,1,1,2,2
2,1,4,4,4,4,4,4,4,4,4,1,2,2,2,2,2,2
2,1,4,4,4,4,4,4,4,4,4,1,2,2,2,2,2,2
2,3,4,4,4,4,4,4,4,4,4,2,3,2,2,2,2,2
2,2,1,3,2,2,2,2,2,2,2,2,2,2,3,2,2,2
2,2,3,2,1,2,2,2,2,3,2,2,2,3,2,2,2,2
2,2,2,3,2,2,1,1,2,2,2,2,2,2,1,2,2,2
2,3,2,2,1,2,1,1,1,2,2,3,2,1,1,1,2,2
2,1,2,1,1,2,2,1,2,3,2,2,2,1,1,1,2,2
2,1,2,1,2,2,2,2,2,2,2,2,3,1,1,1,2,2
2,1,1,1,2,2,2,2,2,2,2,1,2,1,1,1,2,2
2,2,2,2,2,2,2,2,2,2,1,1,2,1,1,1,2,2
2,2,2,2,2,2,2,2,2,2,1,1,2,2,2,2,2,2
2,2,2,2,2,2,2,2,2,2,2,2,2,2,2,2,2,2
:endlayer
layer: 7
0,0,0,0,0,0,0,0,0,0,0,0,0,0,0,0,0,0
0,13,17,17,16,16,13,16,17,16,17,13,0,8,0,8,0,0
0,14,15,0,20,19,19,19,0,0,0,17,0,8,0,8,0,0
0,17,0,0,0,19,19,0,0,16,16,16,0,7,7,7,0,5
0,13,0,0,0,0,18,0,0,0,0,13,0,7,7,7,0,5
0,17,0,0,0,0,0,0,0,0,0,16,11,7,7,7,10,0
0,14,0,0,0,0,15,0,0,0,0,14,0,9,9,9,5,5
0,13,0,0,0,0,13,0,9,9,0,13,5,5,12,5,5,5
0,0,0,0,0,0,0,0,0,0,0,5,0,0,5,0,5,0
0,5,7,0,5,5,0,0,0,0,5,0,5,0,0,0,0,0
5,0,7,5,7,5,5,0,0,0,5,5,5,0,0,0,0,0
0,0,5,0,0,5,7,7,0,0,0,5,5,0,7,0,0,5
5,0,5,0,7,0,7,7,7,5,0,0,0,7,7,7,5,5
0,7,5,7,7,5,11,7,10,0,5,5,5,7,7,7,5,5
0,7,5,7,8,5,8,9,8,5,5,5,0,7,7,7,0,5
0,7,7,7,5,5,8,0,8,5,5,6,0,7,7,7,0,5
0,0,0,5,5,0,5,0,5,0,6,6,0,7,7,7,5,5
0,0,0,0,0,5,0,0,5,0,6,6,0,0,0,5,0,0
0,0,0,0,5,5,0,0,0,0,0,0,0,0,0,0,0,0
:endlayer
layer: 8
0,0,0,0,0,0,0,0,0,0,0,0,0,0,0,0,0,0
0,13,16,17,17,17,13,17,17,16,17,13,0,0,0,0,0,0
0,17,0,0,0,19,19,19,0,0,0,16,0,0,0,0,0,0
0,14,0,0,0,0,19,0,0,0,0,17,0,0,0,0,0,0
0,13,0,0,0,0,0,0,0,0,0,13,0,0,0,0,0,0
0,16,0,0,0,0,0,0,0,0,0,14,0,0,0,0,0,0
0,17,0,0,0,0,0,0,0,0,0,17,0,0,0,0,0,0
0,13,0,0,0,0,13,0,0,0,0,13,0,0,0,0,0,0
0,0,0,0,0,0,0,0,0,0,0,0,0,0,0,0,0,0
0,0,0,0,0,0,0,0,0,0,0,0,0,0,0,0,0,0
0,0,0,0,0,0,0,0,0,0,0,0,0,0,0,0,0,0
0,0,0,0,0,0,0,0,0,0,0,0,0,0,0,0,0,0
0,0,0,0,0,0,0,21,0,0,0,0,0,0,7,0,0,0
0,0,0,7,0,0,0,0,0,0,0,0,0,7,7,0,0,0
0,7,0,7,8,0,0,0,0,0,0,0,0,7,7,0,0,0
0,7,7,0,0,0,0,0,0,0,0,0,0,7,7,7,0,0
0,0,0,0,0,0,0,0,0,0,6,6,0,0,7,7,0,0
0,0,0,0,0,0,0,0,0,0,6,6,0,0,0,0,0,0
0,0,0,0,0,0,0,0,0,0,0,0,0,0,0,0,0,0
:endlayer
layer: 9
0,0,0,0,0,0,0,0,0,0,0,0,0,0,0,0,0,0
0,13,17,16,17,16,13,17,16,17,16,13,0,0,0,0,0,0
0,16,0,0,0,19,19,19,0,0,0,17,0,0,0,0,0,0
0,17,0,0,0,0,0,0,0,0,0,16,0,0,0,0,0,0
0,13,0,0,0,0,0,0,0,0,0,14,0,0,0,0,0,0
0,17,0,0,0,0,0,0,0,0,0,17,0,0,0,0,0,0
0,16,0,0,0,0,0,0,0,0,0,16,0,0,0,0,0,0
0,13,0,0,0,0,13,0,0,0,0,13,0,0,0,0,0,0
0,22,0,0,0,0,22,0,0,0,0,22,0,0,0,0,0,0
0,0,0,0,0,0,0,0,0,0,0,0,0,0,0,0,0,0
0,0,0,0,0,0,0,0,0,0,0,0,0,0,0,0,0,0
0,0,0,0,0,0,0,0,0,0,0,0,0,0,0,0,0,0
0,0,0,0,0,0,0,0,0,0,0,0,0,0,0,0,0,0
0,0,0,0,0,0,0,0,0,0,0,0,0,0,0,0,0,0
0,0,0,0,0,0,0,0,0,0,0,0,0,0,0,0,0,0
0,0,0,0,0,0,0,0,0,0,0,0,0,0,0,0,0,0
0,0,0,0,0,0,0,0,0,0,6,0,0,0,0,0,0,0
0,0,0,0,0,0,0,0,0,0,0,0,0,0,0,0,0,0
0,0,0,0,0,0,0,0,0,0,0,0,0,0,0,0,0,0
:endlayer
layer: 10
0,0,0,0,0,0,0,0,0,0,0,0,0,0,0,0,0,0
0,13,23,23,23,23,23,23,23,23,23,13,0,0,0,0,0,0
0,14,0,0,0,0,22,0,0,0,0,14,0,0,0,0,0,0
0,14,0,0,0,0,0,0,0,0,0,14,0,0,0,0,0,0
0,14,26,0,0,0,0,0,0,0,25,14,0,0,0,0,0,0
0,14,0,0,0,0,0,0,0,0,0,14,0,0,0,0,0,0
0,14,0,0,0,0,24,0,0,0,0,14,0,0,0,0,0,0
0,13,23,23,23,23,23,23,23,23,23,13,0,0,0,0,0,0
0,12,12,12,12,12,12,12,12,12,12,12,0,0,0,0,0,0
0,0,0,0,0,0,0,0,0,0,0,0,0,0,0,0,0,0
0,0,0,0,0,0,0,0,0,0,0,0,0,0,0,0,0,0
0,0,0,0,0,0,0,0,0,0,0,0,0,0,0,0,0,0
0,0,0,0,0,0,0,0,0,0,0,0,0,0,0,0,0,0
0,0,0,0,0,0,0,0,0,0,0,0,0,0,0,0,0,0
0,0,0,0,0,0,0,0,0,0,0,0,0,0,0,0,0,0
0,0,0,0,0,0,0,0,0,0,0,0,0,0,0,0,0,0
0,0,0,0,0,0,0,0,0,0,0,0,0,0,0,0,0,0
0,0,0,0,0,0,0,0,0,0,0,0,0,0,0,0,0,0
0,0,0,0,0,0,0,0,0,0,0,0,0,0,0,0,0,0
:endlayer
layer: 11
0,0,0,0,0,0,0,0,0,0,0,0,0,0,0,0,0,0
0,29,29,29,29,29,29,29,29,29,29,29,0,0,0,0,0,0
0,17,17,17,17,17,17,17,17,17,17,29,0,0,0,0,0,0
0,28,28,28,28,28,28,28,28,28,28,28,0,0,0,0,0,0
0,27,27,27,27,27,27,27,27,27,27,27,0,0,0,0,0,0
0,27,27,27,27,27,27,27,27,27,27,27,0,0,0,0,0,0
0,27,27,27,27,27,27,27,27,27,27,27,0,0,0,0,0,0
0,27,27,27,27,27,27,27,27,27,27,27,0,0,0,0,0,0
0,0,0,0,0,0,0,0,0,0,0,0,0,0,0,0,0,0
0,0,0,0,0,0,0,0,0,0,0,0,0,0,0,0,0,0
0,0,0,0,0,0,0,0,0,0,0,0,0,0,0,0,0,0
0,0,0,0,0,0,0,0,0,0,0,0,0,0,0,0,0,0
0,0,0,0,0,0,0,0,0,0,0,0,0,0,0,0,0,0
0,0,0,0,0,0,0,0,0,0,0,0,0,0,0,0,0,0
0,0,0,0,0,0,0,0,0,0,0,0,0,0,0,0,0,0
0,0,0,0,0,0,0,0,0,0,0,0,0,0,0,0,0,0
0,0,0,0,0,0,0,0,0,0,0,0,0,0,0,0,0,0
0,0,0,0,0,0,0,0,0,0,0,0,0,0,0,0,0,0
0,0,0,0,0,0,0,0,0,0,0,0,0,0,0,0,0,0
:endlayer

#### RULES ####
rule:
plugin=vanillaBlocks
number=1
data:
JSON:{blockState:{blockName:"minecraft:dirt",properties:{variant:"dirt",snowy:"false"}}}
:enddata
:endrule

rule:
plugin=vanillaBlocks
number=2
data:
JSON:{blockState:{blockName:"minecraft:grass",properties:{snowy:"false"}}}
:enddata
:endrule

rule:
plugin=vanillaBlocks
number=3
data:
JSON:{blockState:{blockName:"minecraft:cobblestone"}}
:enddata
:endrule

rule:
plugin=vanillaBlocks
number=4
data:
JSON:{blockState:{blockName:"minecraft:gravel"}}
:enddata
:endrule

rule:
plugin=vanillaBlocks
number=5
data:
JSON:{blockState:{blockName:"minecraft:tallgrass",properties:{type:"tall_grass"}}}
:enddata
:endrule

rule:
plugin=vanillaBlocks
number=6
data:
JSON:{blockState:{blockName:"minecraft:sandstone",properties:{type:"sandstone"}}}
:enddata
:endrule

rule:
plugin=vanillaBlocks
number=7
data:
JSON:{blockState:{blockName:"minecraft:stone",properties:{variant:"stone"}}}
:enddata
:endrule

rule:
plugin=vanillaBlocks
number=8
data:
JSON:{blockState:{blockName:"minecraft:fence",properties:{east:"false",south:"false",north:"false",west:"false"}}}
:enddata
:endrule

rule:
plugin=vanillaBlocks
number=9
data:
JSON:{blockState:{blockName:"minecraft:oak_stairs",properties:{half:"top",shape:"straight",facing:"north"}}}
:enddata
:endrule

rule:
plugin=vanillaBlocks
number=10
data:
JSON:{blockState:{blockName:"minecraft:oak_stairs",properties:{half:"top",shape:"straight",facing:"west"}}}
:enddata
:endrule

rule:
plugin=vanillaBlocks
number=11
data:
JSON:{blockState:{blockName:"minecraft:oak_stairs",properties:{half:"top",shape:"straight",facing:"east"}}}
:enddata
:endrule

rule:
plugin=vanillaBlocks
number=12
data:
JSON:{blockState:{blockName:"minecraft:wooden_slab",properties:{half:"top",variant:"oak"}}}
:enddata
:endrule

rule:
plugin=vanillaBlocks
number=13
data:
JSON:{blockState:{blockName:"minecraft:log",properties:{variant:"oak",axis:"y"}}}
:enddata
:endrule

rule:
plugin=vanillaBlocks
number=14
data:
JSON:{blockState:{blockName:"minecraft:log",properties:{variant:"oak",axis:"z"}}}
:enddata
:endrule

rule:
plugin=vanillaBlocks
number=15
data:
JSON:{blockState:{blockName:"minecraft:crafting_table"}}
:enddata
:endrule

rule:
plugin=vanillaBlocks
number=16
data:
JSON:{blockState:{blockName:"minecraft:planks",properties:{variant:"spruce"}}}
:enddata
:endrule

rule:
plugin=vanillaBlocks
number=17
data:
JSON:{blockState:{blockName:"minecraft:planks",properties:{variant:"oak"}}}
:enddata
:endrule

rule:
plugin=blockTile
number=18
data:
JSON:{blockState:{blockName:"ancientwarfarestructure:advanced_spawner",properties:{transparent:"true"}},teData:{id:"ancientwarfarestructure:advanced_spawner_tile",spawnerSettings:{minDelay:0,spawnDelay:0,lightSensitive:0b,spawnGroups:[{settingsList:[{remainingSpawnCount:1,hostile:1b,forced:1b,customTag:{ArmorDropChances:[1.0f,1.0f,1.0f,1.0f],ArmorItems:[{},{},{},{}],HandDropChances:[1.0f,1.0f],factionName:"empire",HandItems:[{id:"minecraft:bow",Count:1b,Damage:0s},{}]},maxToSpawn:1,entityId:"ancientwarfarenpc:faction.archer",minToSpawn:1}],groupWeight:1}],playerRange:6,respondToRedstone:0b,inventory:{Size:9,Items:[]},spawnRange:0,transparent:1b,maxDelay:0,xpToDrop:0,mobRange:0,debugMode:0b,maxNearbyMonsters:0}}}
:enddata
:endrule

rule:
plugin=vanillaBlocks
number=19
data:
JSON:{blockState:{blockName:"minecraft:quartz_block",properties:{variant:"default"}}}
:enddata
:endrule

rule:
plugin=inventory
number=20
data:
JSON:{blockState:{blockName:"minecraft:chest",properties:{facing:"south"}},lootLevel:0,teData:{ForgeData:{},Items:[{Slot:0b,id:"minecraft:stone",Count:4b,Damage:5s},{Slot:1b,id:"minecraft:stone",Count:3b,Damage:5s},{Slot:2b,id:"minecraft:stone",Count:3b,Damage:0s},{Slot:3b,id:"minecraft:stone",Count:3b,Damage:0s},{Slot:4b,id:"minecraft:stone",Count:4b,Damage:1s},{Slot:5b,id:"minecraft:stone",Count:3b,Damage:1s},{Slot:6b,id:"minecraft:stone",Count:2b,Damage:3s},{Slot:7b,id:"minecraft:stone",Count:4b,Damage:3s},{Slot:8b,id:"minecraft:stone",Count:3b,Damage:3s},{Slot:9b,id:"minecraft:stone",Count:5b,Damage:5s},{Slot:10b,id:"minecraft:stone",Count:5b,Damage:5s},{Slot:11b,id:"minecraft:stone",Count:4b,Damage:0s},{Slot:12b,id:"minecraft:stone",Count:3b,Damage:0s},{Slot:13b,id:"minecraft:stone",Count:8b,Damage:1s},{Slot:14b,id:"minecraft:stone",Count:3b,Damage:1s},{Slot:15b,id:"minecraft:stone",Count:5b,Damage:3s},{Slot:16b,id:"minecraft:stone",Count:6b,Damage:3s},{Slot:17b,id:"minecraft:stone",Count:3b,Damage:3s},{Slot:18b,id:"minecraft:stone",Count:4b,Damage:5s},{Slot:19b,id:"minecraft:stone",Count:4b,Damage:5s},{Slot:20b,id:"minecraft:stone",Count:3b,Damage:0s},{Slot:21b,id:"minecraft:stone",Count:4b,Damage:0s},{Slot:22b,id:"minecraft:stone",Count:3b,Damage:1s},{Slot:23b,id:"minecraft:stone",Count:3b,Damage:1s},{Slot:24b,id:"minecraft:stone",Count:2b,Damage:3s},{Slot:25b,id:"minecraft:stone",Count:2b,Damage:3s},{Slot:26b,id:"minecraft:stone",Count:2b,Damage:3s}],id:"minecraft:chest",Lock:""},inventoryData:{length:27,inventoryContents:[{id:"minecraft:stone",Count:4b,slot:0,Damage:5s},{id:"minecraft:stone",Count:3b,slot:1,Damage:5s},{id:"minecraft:stone",Count:3b,slot:2,Damage:0s},{id:"minecraft:stone",Count:3b,slot:3,Damage:0s},{id:"minecraft:stone",Count:4b,slot:4,Damage:1s},{id:"minecraft:stone",Count:3b,slot:5,Damage:1s},{id:"minecraft:stone",Count:2b,slot:6,Damage:3s},{id:"minecraft:stone",Count:4b,slot:7,Damage:3s},{id:"minecraft:stone",Count:3b,slot:8,Damage:3s},{id:"minecraft:stone",Count:5b,slot:9,Damage:5s},{id:"minecraft:stone",Count:5b,slot:10,Damage:5s},{id:"minecraft:stone",Count:4b,slot:11,Damage:0s},{id:"minecraft:stone",Count:3b,slot:12,Damage:0s},{id:"minecraft:stone",Count:8b,slot:13,Damage:1s},{id:"minecraft:stone",Count:3b,slot:14,Damage:1s},{id:"minecraft:stone",Count:5b,slot:15,Damage:3s},{id:"minecraft:stone",Count:6b,slot:16,Damage:3s},{id:"minecraft:stone",Count:3b,slot:17,Damage:3s},{id:"minecraft:stone",Count:4b,slot:18,Damage:5s},{id:"minecraft:stone",Count:4b,slot:19,Damage:5s},{id:"minecraft:stone",Count:3b,slot:20,Damage:0s},{id:"minecraft:stone",Count:4b,slot:21,Damage:0s},{id:"minecraft:stone",Count:3b,slot:22,Damage:1s},{id:"minecraft:stone",Count:3b,slot:23,Damage:1s},{id:"minecraft:stone",Count:2b,slot:24,Damage:3s},{id:"minecraft:stone",Count:2b,slot:25,Damage:3s},{id:"minecraft:stone",Count:2b,slot:26,Damage:3s}]},legacyFeatures:1b}
:enddata
:endrule

rule:
plugin=blockTile
number=21
data:
JSON:{blockState:{blockName:"ancientwarfarestructure:advanced_spawner",properties:{transparent:"true"}},teData:{id:"ancientwarfarestructure:advanced_spawner_tile",spawnerSettings:{minDelay:0,spawnDelay:0,lightSensitive:0b,spawnGroups:[{settingsList:[{remainingSpawnCount:1,hostile:1b,forced:1b,customTag:{ArmorDropChances:[1.0f,1.0f,1.0f,1.0f],ArmorItems:[{},{},{},{}],HandDropChances:[1.0f,1.0f],factionName:"empire",HandItems:[{id:"minecraft:bow",Count:1b,Damage:0s},{}]},maxToSpawn:1,entityId:"ancientwarfarenpc:faction.archer",minToSpawn:1}],groupWeight:1}],playerRange:16,respondToRedstone:0b,inventory:{Size:9,Items:[]},spawnRange:0,transparent:1b,maxDelay:0,xpToDrop:0,mobRange:0,debugMode:0b,maxNearbyMonsters:0}}}
:enddata
:endrule

rule:
plugin=vanillaBlocks
number=22
data:
JSON:{blockState:{blockName:"minecraft:torch",properties:{facing:"south"}}}
:enddata
:endrule

rule:
plugin=vanillaBlocks
number=23
data:
JSON:{blockState:{blockName:"minecraft:log",properties:{variant:"oak",axis:"x"}}}
:enddata
:endrule

rule:
plugin=vanillaBlocks
number=24
data:
JSON:{blockState:{blockName:"minecraft:torch",properties:{facing:"north"}}}
:enddata
:endrule

rule:
plugin=vanillaBlocks
number=25
data:
JSON:{blockState:{blockName:"minecraft:torch",properties:{facing:"west"}}}
:enddata
:endrule

rule:
plugin=vanillaBlocks
number=26
data:
JSON:{blockState:{blockName:"minecraft:torch",properties:{facing:"east"}}}
:enddata
:endrule

rule:
plugin=vanillaBlocks
number=27
data:
JSON:{blockState:{blockName:"minecraft:wooden_slab",properties:{half:"bottom",variant:"oak"}}}
:enddata
:endrule

rule:
plugin=vanillaBlocks
number=28
data:
JSON:{blockState:{blockName:"minecraft:oak_stairs",properties:{half:"bottom",shape:"straight",facing:"north"}}}
:enddata
:endrule

rule:
plugin=vanillaBlocks
number=29
data:
JSON:{blockState:{blockName:"minecraft:double_wooden_slab",properties:{variant:"oak"}}}
:enddata
:endrule

#### ENTITIES ####
