# Ancient Warfare Structure Template File
# Auto-generated structure template file. created on: 8/19/2019 at: 10:23:9
# Lines beginning with # denote comments

header:
version=2.9
name=EmpireBaronsCastle
mods=
size=39,65,42
offset=19,5,41
:endheader

#### VALIDATION ####
validation:
type=ground
survival=false
worldGenEnabled=true
unique=false
preserveBlocks=false
selectionWeight=120
clusterValue=50
minDuplicateDistance=1000
dimensionWhiteList=true
dimensionList=0
biomeWhiteList=true
biomeList=biomesoplenty:meadow,minecraft:forest,traverse:meadow,minecraft:birch_forest,minecraft:plains,minecraft:birch_forest_hills,minecraft:smaller_extreme_hills
leveling=12
fill=12
border=12
blockSwap=false
:endvalidation

#### LAYERS ####
layer: 0
1,1,1,1,1,1,1,1,1,1,1,1,1,1,1,1,1,1,1,1,1,1,1,1,1,1,1,1,1,1,1,1,1,1,1,1,1,1,1
1,2,2,2,2,2,2,2,2,2,2,2,2,2,2,2,2,2,2,2,2,2,2,2,2,2,2,2,2,2,2,2,2,2,2,2,2,2,1
1,2,2,2,2,2,2,2,2,2,2,2,2,2,2,2,2,2,2,2,2,2,2,2,2,2,2,2,2,2,2,2,2,2,2,2,2,2,1
1,2,2,2,2,2,2,2,2,2,2,2,2,2,2,2,2,2,2,2,2,2,2,2,2,2,2,2,2,2,2,2,2,2,2,2,2,2,1
1,2,2,2,3,3,3,3,3,3,3,3,3,3,3,3,3,3,3,3,3,3,3,3,3,3,3,3,3,3,3,3,3,3,3,2,2,2,1
1,2,2,2,3,3,3,3,3,3,3,3,3,3,3,3,3,3,3,3,3,3,3,3,3,3,3,3,3,3,3,3,3,3,3,2,2,2,1
1,2,2,2,3,3,3,3,3,3,3,3,3,3,3,3,3,3,3,3,3,3,3,3,3,3,3,3,3,3,3,3,3,3,3,2,2,2,1
1,2,2,2,3,3,3,3,3,3,3,3,3,3,3,3,3,3,3,3,3,3,3,3,3,3,3,3,3,3,3,3,3,3,3,2,2,2,1
1,2,2,2,3,3,3,3,3,3,3,3,3,3,3,3,3,3,3,3,3,3,3,3,3,3,3,3,3,3,3,3,3,3,3,2,2,2,1
1,2,2,2,3,3,3,3,3,3,3,3,3,3,3,3,3,3,3,3,3,3,3,3,3,3,3,3,3,3,3,3,3,3,3,2,2,2,1
1,2,2,2,3,3,3,3,3,3,3,3,3,3,3,3,3,3,3,3,3,3,3,3,3,3,3,3,3,3,3,3,3,3,3,2,2,2,1
1,2,2,2,3,3,3,3,3,3,3,3,3,3,3,3,3,3,3,3,3,3,3,3,3,3,3,3,3,3,3,3,3,3,3,2,2,2,1
1,2,2,2,3,3,3,3,3,3,3,3,3,3,3,3,3,3,3,3,3,3,3,3,3,3,3,3,3,3,3,3,3,3,3,2,2,2,1
1,2,2,2,3,3,3,3,3,3,3,3,3,3,3,3,3,3,3,3,3,3,3,3,3,3,3,3,3,3,3,3,3,3,3,2,2,2,1
1,2,2,2,3,3,3,3,3,3,3,3,3,3,3,3,3,3,3,3,3,3,3,3,3,3,3,3,3,3,3,3,3,3,3,2,2,2,1
1,2,2,2,3,3,3,3,3,3,3,3,3,3,3,3,3,3,3,3,3,3,3,3,3,3,3,3,3,3,3,3,3,3,3,2,2,2,1
1,2,2,2,3,3,3,3,3,3,3,3,3,3,3,3,3,3,3,3,3,3,3,3,3,3,3,3,3,3,3,3,3,3,3,2,2,2,1
1,2,2,2,3,3,3,3,3,3,3,3,3,3,3,3,3,3,3,3,3,3,3,3,3,3,3,3,3,3,3,3,3,3,3,2,2,2,1
1,2,2,2,3,3,3,3,3,3,3,3,3,3,3,3,3,3,3,3,3,3,3,3,3,3,3,3,3,3,3,3,3,3,3,2,2,2,1
1,2,2,2,3,3,3,3,3,3,3,3,3,3,3,3,3,3,3,3,3,3,3,3,3,3,3,3,3,3,3,3,3,3,3,2,2,2,1
1,2,2,2,3,3,3,3,3,3,3,3,3,3,3,3,3,3,3,3,3,3,3,3,3,3,3,3,3,3,3,3,3,3,3,2,2,2,1
1,2,2,2,3,3,3,3,3,3,3,3,3,3,3,3,3,3,3,3,3,3,3,3,3,3,3,3,3,3,3,3,3,3,3,2,2,2,1
1,2,2,2,3,3,3,3,3,3,3,3,3,3,3,3,3,3,3,3,3,3,3,3,3,3,3,3,3,3,3,3,3,3,3,2,2,2,1
1,2,2,2,3,3,3,3,3,3,3,3,3,3,3,3,3,3,3,3,3,3,3,3,3,3,3,3,3,3,3,3,3,3,3,2,2,2,1
1,2,2,2,3,3,3,3,3,3,3,3,3,3,3,3,3,3,3,3,3,3,3,3,3,3,3,3,3,3,3,3,3,3,3,2,2,2,1
1,2,2,2,3,3,3,3,3,3,3,3,3,3,3,3,3,3,3,3,3,3,3,3,3,3,3,3,3,3,3,3,3,3,3,2,2,2,1
1,2,2,2,3,3,3,3,3,3,3,3,3,3,3,3,3,3,3,3,3,3,3,3,3,3,3,3,3,3,3,3,3,3,3,2,2,2,1
1,2,2,2,3,3,3,3,3,3,3,3,3,3,3,3,3,3,3,3,3,3,3,3,3,3,3,3,3,3,3,3,3,3,3,2,2,2,1
1,2,2,2,3,3,3,3,3,3,3,3,3,3,3,3,3,3,3,3,3,3,3,3,3,3,3,3,3,3,3,3,3,3,3,2,2,2,1
1,2,2,2,3,3,3,3,3,3,3,3,3,3,3,3,3,3,3,3,3,3,3,3,3,3,3,3,3,3,3,3,3,3,3,2,2,2,1
1,2,2,2,3,3,3,3,3,3,3,3,3,3,3,3,3,3,3,3,3,3,3,3,3,3,3,3,3,3,3,3,3,3,3,2,2,2,1
1,2,2,2,3,3,3,3,3,3,3,3,3,3,3,3,3,3,3,3,3,3,3,3,3,3,3,3,3,3,3,3,3,3,3,2,2,2,1
1,2,2,2,3,3,3,3,3,3,3,3,3,3,3,3,3,3,3,3,3,3,3,3,3,3,3,3,3,3,3,3,3,3,3,2,2,2,1
1,2,2,2,3,3,3,3,3,3,3,3,3,3,3,3,3,3,3,3,3,3,3,3,3,3,3,3,3,3,3,3,3,3,3,2,2,2,1
1,2,2,2,3,3,3,3,3,3,3,3,3,3,3,3,3,3,3,3,3,3,3,3,3,3,3,3,3,3,3,3,3,3,3,2,2,2,1
1,2,2,2,2,2,2,2,2,2,2,2,2,2,2,2,2,2,2,2,2,2,2,2,2,2,2,2,2,2,2,2,2,2,2,2,2,2,1
1,2,2,2,2,2,2,2,2,2,2,2,2,2,2,2,2,2,2,2,2,2,2,2,2,2,2,2,2,2,2,2,2,2,2,2,2,2,1
1,2,2,2,2,2,2,2,2,2,2,2,2,2,2,2,2,2,2,2,2,2,2,2,2,2,2,2,2,2,2,2,2,2,2,2,2,2,1
1,1,1,1,1,1,1,1,1,1,1,1,1,1,1,1,1,1,1,1,1,1,1,1,1,1,1,1,1,1,1,1,1,1,1,1,1,1,1
1,1,1,1,1,1,1,1,1,1,1,1,1,1,1,1,1,1,1,1,1,1,1,1,1,1,1,1,1,1,1,1,1,1,1,1,1,1,1
1,1,1,1,1,1,1,1,1,1,1,1,1,1,1,1,1,1,1,1,1,1,1,1,1,1,1,1,1,1,1,1,1,1,1,1,1,1,1
1,1,1,1,1,1,1,1,1,1,1,1,1,1,1,1,1,1,1,1,1,1,1,1,1,1,1,1,1,1,1,1,1,1,1,1,1,1,1
:endlayer
layer: 1
1,1,1,1,1,1,1,1,1,1,1,1,1,1,1,1,1,1,1,1,1,1,1,1,1,1,1,1,1,1,1,1,1,1,1,1,1,1,1
1,2,2,2,2,2,2,2,2,2,2,2,2,2,2,2,2,2,2,2,2,2,2,2,2,2,2,2,2,2,2,2,2,2,2,2,2,2,1
1,2,2,2,2,2,2,2,2,2,2,2,2,2,2,2,2,2,2,2,2,2,2,2,2,2,2,2,2,2,2,2,2,2,2,2,2,2,1
1,2,2,2,2,2,2,2,2,2,2,2,2,2,2,2,2,2,2,2,2,2,2,2,2,2,2,2,2,2,2,2,2,2,2,2,2,2,1
1,2,2,2,4,4,4,4,4,4,4,4,4,4,4,4,4,4,4,4,4,4,4,4,4,4,4,4,4,4,4,4,4,4,4,2,2,2,1
1,2,2,2,4,3,3,3,3,3,3,3,3,3,3,3,3,3,3,3,3,3,3,3,3,3,3,3,3,3,3,3,3,3,4,2,2,2,1
1,2,2,2,4,3,0,0,0,0,0,0,0,0,0,0,0,0,0,0,0,0,0,0,0,0,0,0,0,0,0,0,0,3,4,2,2,2,1
1,2,2,2,4,3,0,3,3,3,3,3,0,0,0,3,0,3,5,3,6,3,7,3,8,3,9,3,10,3,11,3,0,3,4,2,2,2,1
1,2,2,2,4,3,0,3,0,0,12,3,0,0,0,3,13,3,3,3,3,3,3,3,3,3,3,3,3,3,3,3,0,3,4,2,2,2,1
1,2,2,2,4,3,0,3,0,14,0,3,0,0,0,3,3,3,3,3,3,3,3,3,3,3,3,3,3,3,3,15,0,3,4,2,2,2,1
1,2,2,2,4,3,0,3,0,0,0,3,0,0,0,16,0,0,0,0,0,0,17,3,3,3,3,3,3,3,3,3,0,3,4,2,2,2,1
1,2,2,2,4,3,0,3,18,0,0,16,0,0,0,3,3,3,3,3,3,3,3,3,3,3,3,3,3,3,3,19,0,3,4,2,2,2,1
1,2,2,2,4,3,0,3,0,0,0,3,0,0,0,3,0,3,20,3,0,3,0,3,0,3,0,3,0,3,21,3,0,3,4,2,2,2,1
1,2,2,2,4,3,0,3,22,23,0,3,0,0,0,0,0,0,0,0,0,0,0,0,0,0,0,0,0,0,0,0,0,3,4,2,2,2,1
1,2,2,2,4,3,0,3,3,3,3,3,24,25,26,3,3,3,3,3,3,3,3,3,3,3,3,3,3,3,3,3,0,3,4,2,2,2,1
1,2,2,2,4,3,0,0,27,0,16,0,0,0,0,24,3,3,3,3,3,3,3,3,3,3,3,3,3,3,3,3,0,3,4,2,2,2,1
1,2,2,2,4,3,0,0,0,0,16,0,0,0,0,24,3,3,3,3,3,3,3,3,3,3,3,3,3,3,3,3,0,3,4,2,2,2,1
1,2,2,2,4,3,0,3,3,3,3,3,24,28,26,3,3,3,3,3,3,3,3,3,3,3,3,3,3,3,3,3,0,3,4,2,2,2,1
1,2,2,2,4,3,0,3,0,0,0,3,0,0,0,0,0,0,0,0,0,0,0,0,0,0,0,0,0,0,0,0,0,3,4,2,2,2,1
1,2,2,2,4,3,0,3,0,0,0,16,0,0,0,3,16,3,16,3,16,3,16,3,16,3,16,3,16,3,16,3,0,3,4,2,2,2,1
1,2,2,2,4,3,0,3,29,0,0,3,0,0,0,3,0,3,0,3,0,3,0,3,0,3,30,3,0,3,0,3,0,3,4,2,2,2,1
1,2,2,2,4,3,0,3,3,3,3,3,0,0,0,3,3,3,3,3,3,3,3,3,3,3,3,3,3,3,3,3,0,3,4,2,2,2,1
1,2,2,2,4,3,0,3,0,0,0,3,0,0,0,0,0,0,0,0,0,0,0,0,0,0,0,0,0,0,0,0,0,3,4,2,2,2,1
1,2,2,2,4,3,0,3,0,0,0,3,0,0,0,3,16,3,16,3,16,3,16,3,16,3,16,3,16,3,16,3,0,3,4,2,2,2,1
1,2,2,2,4,3,0,3,0,0,0,16,0,0,0,3,0,3,0,3,0,3,31,3,0,3,0,3,0,3,0,3,0,3,4,2,2,2,1
1,2,2,2,4,3,0,3,0,0,0,3,0,0,0,3,3,3,3,3,3,3,3,3,3,3,3,3,3,3,3,3,0,3,4,2,2,2,1
1,2,2,2,4,3,0,3,32,0,0,3,0,0,0,0,0,0,0,0,0,0,0,0,0,0,0,0,0,0,0,0,0,3,4,2,2,2,1
1,2,2,2,4,3,0,3,3,3,3,3,0,0,0,3,33,3,16,3,16,3,33,3,16,3,33,3,33,3,16,3,0,3,4,2,2,2,1
1,2,2,2,4,3,0,3,0,0,0,3,0,0,0,3,0,3,0,3,0,3,34,3,0,3,0,3,0,3,0,3,0,3,4,2,2,2,1
1,2,2,2,4,3,0,3,0,0,0,16,0,0,0,3,3,3,3,3,3,3,3,3,3,3,3,3,3,3,3,3,0,3,4,2,2,2,1
1,2,2,2,4,3,0,3,0,0,0,3,0,0,0,0,35,0,0,0,0,0,0,0,0,0,0,0,0,0,0,0,0,3,4,2,2,2,1
1,2,2,2,4,3,0,3,3,3,3,3,0,0,0,3,33,3,33,3,33,3,33,3,33,3,16,3,33,3,16,3,0,3,4,2,2,2,1
1,2,2,2,4,3,36,0,0,0,0,0,0,0,0,3,37,3,38,3,0,3,0,3,0,3,0,3,0,3,0,3,39,3,4,2,2,2,1
1,2,2,2,4,3,3,3,3,3,3,3,3,3,3,3,3,3,3,3,3,3,3,3,3,3,3,3,3,3,3,3,3,3,4,2,2,2,1
1,2,2,2,4,4,4,4,4,4,4,4,4,4,4,4,4,4,4,4,4,4,4,4,4,4,4,4,4,4,4,4,4,4,4,2,2,2,1
1,2,2,2,2,2,2,2,2,2,2,2,2,2,2,2,2,2,2,2,2,2,2,2,2,2,2,2,2,2,2,2,2,2,2,2,2,2,1
1,2,2,2,2,2,2,2,2,2,2,2,2,2,2,2,2,2,2,2,2,2,2,2,2,2,2,2,2,2,2,2,2,2,2,2,2,2,1
1,2,2,2,2,2,2,2,2,2,2,2,2,2,2,2,2,2,2,2,2,2,2,2,2,2,2,2,2,2,2,2,2,2,2,2,2,2,1
1,1,1,1,1,1,1,1,1,1,1,1,1,1,1,1,1,1,1,1,1,1,1,1,1,1,1,1,1,1,1,1,1,1,1,1,1,1,1
1,1,1,1,1,1,1,1,1,1,1,1,1,1,1,1,1,1,1,1,1,1,1,1,1,1,1,1,1,1,1,1,1,1,1,1,1,1,1
1,1,1,1,1,1,1,1,1,1,1,1,1,1,1,1,1,1,1,1,1,1,1,1,1,1,1,1,1,1,1,1,1,1,1,1,1,1,1
1,1,1,1,1,1,1,1,1,1,1,1,1,1,1,1,1,1,1,1,1,1,1,1,1,1,1,1,1,1,1,1,1,1,1,1,1,1,1
:endlayer
layer: 2
1,1,1,1,1,1,1,1,1,1,1,1,1,1,1,1,1,1,1,1,1,1,1,1,1,1,1,1,1,1,1,1,1,1,1,1,1,1,1
1,2,2,2,2,2,2,2,2,2,2,2,2,2,2,2,2,2,2,2,2,2,2,2,2,2,2,2,2,2,2,2,2,2,2,2,2,2,1
1,2,2,2,2,2,2,2,2,2,2,2,2,2,2,2,2,2,2,2,2,2,2,2,2,2,2,2,2,2,2,2,2,2,2,2,2,2,1
1,2,2,2,2,2,2,2,2,2,2,2,2,2,2,2,2,2,2,2,2,2,2,2,2,2,2,2,2,2,2,2,2,2,2,2,2,2,1
1,2,2,2,4,4,4,4,4,4,4,4,4,4,4,4,4,4,4,4,4,4,4,4,4,4,4,4,4,4,4,4,4,4,4,2,2,2,1
1,2,2,2,4,3,3,3,3,3,3,3,3,3,3,3,3,3,3,3,3,3,3,3,3,3,3,3,3,3,3,3,3,3,4,2,2,2,1
1,2,2,2,4,3,0,0,0,0,0,0,0,0,0,0,0,0,0,0,0,0,0,0,0,0,0,0,0,0,0,0,0,3,4,2,2,2,1
1,2,2,2,4,3,0,3,3,3,3,3,0,0,0,3,0,3,0,3,0,3,0,3,0,3,0,3,0,3,0,3,0,3,4,2,2,2,1
1,2,2,2,4,3,0,3,0,0,0,3,0,0,0,3,0,3,3,3,3,3,3,3,3,3,3,3,3,3,3,3,0,3,4,2,2,2,1
1,2,2,2,4,3,0,3,0,0,0,3,0,0,0,3,3,3,3,3,3,3,3,3,3,3,3,3,3,3,3,0,0,3,4,2,2,2,1
1,2,2,2,4,3,0,3,0,0,0,3,0,0,0,40,0,0,0,0,0,0,0,3,3,3,3,3,3,3,3,3,0,3,4,2,2,2,1
1,2,2,2,4,3,0,3,0,0,0,40,0,0,0,3,3,3,3,3,3,3,3,3,3,3,3,3,3,3,3,0,0,3,4,2,2,2,1
1,2,2,2,4,3,0,3,0,0,0,3,0,0,0,3,0,3,0,3,0,3,0,3,0,3,0,3,0,3,0,3,0,3,4,2,2,2,1
1,2,2,2,4,3,0,3,0,0,0,3,0,0,0,0,0,0,0,0,0,0,0,0,0,0,0,0,0,0,0,0,41,3,4,2,2,2,1
1,2,2,2,4,3,0,3,3,3,3,3,24,40,26,3,3,3,3,3,3,3,3,3,3,3,3,3,3,3,3,3,0,3,4,2,2,2,1
1,2,2,2,4,3,0,0,0,0,42,0,0,0,0,0,24,3,3,3,3,3,3,3,3,3,3,3,3,3,3,3,0,3,4,2,2,2,1
1,2,2,2,4,3,0,0,0,0,40,0,0,0,0,0,24,3,3,3,3,3,3,3,3,3,3,3,3,3,3,3,0,3,4,2,2,2,1
1,2,2,2,4,3,0,3,3,3,3,3,24,40,26,3,3,3,3,3,3,3,3,3,3,3,3,3,3,3,3,3,0,3,4,2,2,2,1
1,2,2,2,4,3,0,3,0,0,0,3,0,0,0,0,0,0,0,0,0,0,0,0,0,0,0,0,0,0,0,0,41,3,4,2,2,2,1
1,2,2,2,4,3,0,3,0,0,0,40,0,0,0,3,40,3,40,3,40,3,40,3,40,3,40,3,40,3,40,3,0,3,4,2,2,2,1
1,2,2,2,4,3,0,3,0,0,0,3,0,0,0,3,0,3,0,3,0,3,0,3,0,3,0,3,0,3,0,3,0,3,4,2,2,2,1
1,2,2,2,4,3,0,3,3,3,3,3,0,0,0,3,3,3,3,3,3,3,3,3,3,3,3,3,3,3,3,3,0,3,4,2,2,2,1
1,2,2,2,4,3,0,3,0,0,0,3,0,0,0,0,0,0,0,0,0,0,0,0,0,0,0,0,0,0,0,0,41,3,4,2,2,2,1
1,2,2,2,4,3,0,3,0,0,0,3,0,0,0,3,40,3,40,3,40,3,40,3,40,3,40,3,40,3,40,3,0,3,4,2,2,2,1
1,2,2,2,4,3,0,3,0,0,0,40,0,0,0,3,0,3,0,3,0,3,0,3,0,3,0,3,0,3,0,3,0,3,4,2,2,2,1
1,2,2,2,4,3,0,3,0,0,0,3,0,0,0,3,3,3,3,3,3,3,3,3,3,3,3,3,3,3,3,3,0,3,4,2,2,2,1
1,2,2,2,4,3,0,3,0,0,0,3,0,0,0,0,0,0,0,0,0,0,0,0,0,0,0,0,0,0,0,0,41,3,4,2,2,2,1
1,2,2,2,4,3,0,3,3,3,3,3,0,0,0,3,43,3,40,3,40,3,43,3,40,3,43,3,43,3,40,3,0,3,4,2,2,2,1
1,2,2,2,4,3,0,3,0,0,0,3,0,0,0,3,0,3,0,3,0,3,0,3,0,3,0,3,0,3,0,3,0,3,4,2,2,2,1
1,2,2,2,4,3,0,3,0,0,0,40,0,0,0,3,3,3,3,3,3,3,3,3,3,3,3,3,3,3,3,3,0,3,4,2,2,2,1
1,2,2,2,4,3,0,3,0,0,0,3,0,0,0,44,0,44,0,44,0,44,0,44,0,44,0,44,0,44,0,44,41,3,4,2,2,2,1
1,2,2,2,4,3,0,3,3,3,3,3,0,0,0,3,43,3,43,3,43,3,43,3,43,3,40,3,43,3,40,3,0,3,4,2,2,2,1
1,2,2,2,4,3,0,0,0,0,0,0,0,0,0,3,0,3,0,3,0,3,0,3,0,3,0,3,0,3,0,3,0,3,4,2,2,2,1
1,2,2,2,4,3,3,3,3,3,3,3,3,3,3,3,3,3,3,3,3,3,3,3,3,3,3,3,3,3,3,3,3,3,4,2,2,2,1
1,2,2,2,4,4,4,4,4,4,4,4,4,4,4,4,4,4,4,4,4,4,4,4,4,4,4,4,4,4,4,4,4,4,4,2,2,2,1
1,2,2,2,2,2,2,2,2,2,2,2,2,2,2,2,2,2,2,2,2,2,2,2,2,2,2,2,2,2,2,2,2,2,2,2,2,2,1
1,2,2,2,2,2,2,2,2,2,2,2,2,2,2,2,2,2,2,2,2,2,2,2,2,2,2,2,2,2,2,2,2,2,2,2,2,2,1
1,2,2,2,2,2,2,2,2,2,2,2,2,2,2,2,2,2,2,2,2,2,2,2,2,2,2,2,2,2,2,2,2,2,2,2,2,2,1
1,1,1,1,1,1,1,1,1,1,1,1,1,1,1,1,1,1,1,1,1,1,1,1,1,1,1,1,1,1,1,1,1,1,1,1,1,1,1
1,1,1,1,1,1,1,1,1,1,1,1,1,1,1,1,1,1,1,1,1,1,1,1,1,1,1,1,1,1,1,1,1,1,1,1,1,1,1
1,1,1,1,1,1,1,1,1,1,1,1,1,1,1,1,1,1,1,1,1,1,1,1,1,1,1,1,1,1,1,1,1,1,1,1,1,1,1
1,1,1,1,1,1,1,1,1,1,1,1,1,1,1,1,1,1,1,1,1,1,1,1,1,1,1,1,1,1,1,1,1,1,1,1,1,1,1
:endlayer
layer: 3
1,1,1,1,1,1,1,1,1,1,1,1,1,1,1,1,1,1,1,1,1,1,1,1,1,1,1,1,1,1,1,1,1,1,1,1,1,1,1
1,2,2,2,2,2,2,2,2,2,2,2,2,2,2,2,2,2,2,2,2,2,2,2,2,2,2,2,2,2,2,2,2,2,2,2,2,2,1
1,2,2,2,2,2,2,2,2,2,2,2,2,2,2,2,2,2,2,2,2,2,2,2,2,2,2,2,2,2,2,2,2,2,2,2,2,2,1
1,2,2,2,2,2,2,2,2,2,2,2,2,2,2,2,2,2,2,2,2,2,2,2,2,2,2,2,2,2,2,2,2,2,2,2,2,2,1
1,2,2,2,3,3,3,3,3,3,3,3,3,3,3,3,3,3,3,3,3,3,3,3,3,3,3,3,3,3,3,3,3,3,3,2,2,2,1
1,2,2,2,3,3,3,3,3,3,3,3,3,3,3,3,3,3,3,3,3,3,3,3,3,3,3,3,3,3,3,3,3,3,3,2,2,2,1
1,2,2,2,3,3,45,0,0,0,0,0,0,46,0,0,0,0,0,0,0,0,0,0,0,0,0,0,0,0,0,0,41,3,3,2,2,2,1
1,2,2,2,3,3,0,3,3,3,3,3,45,0,41,3,3,3,3,3,3,3,3,3,3,3,3,3,3,3,3,3,0,3,3,2,2,2,1
1,2,2,2,3,3,0,3,0,0,0,3,0,0,0,3,3,3,3,3,3,3,3,3,3,3,3,3,3,3,3,3,0,3,3,2,2,2,1
1,2,2,2,3,3,0,3,0,0,0,3,0,0,0,3,3,3,3,3,3,3,3,3,3,3,3,3,3,3,3,3,0,3,3,2,2,2,1
1,2,2,2,3,3,0,3,0,0,0,3,0,0,47,3,3,3,3,3,3,3,3,3,3,3,3,3,3,3,3,3,0,3,3,2,2,2,1
1,2,2,2,3,3,0,3,0,0,0,3,48,0,0,3,3,3,3,3,3,3,3,3,3,3,3,3,3,3,3,3,0,3,3,2,2,2,1
1,2,2,2,3,3,0,3,0,0,0,3,0,0,0,3,3,3,3,3,3,3,3,3,3,3,3,3,3,3,3,3,0,3,3,2,2,2,1
1,2,2,2,3,3,0,3,0,0,0,3,0,0,0,3,3,3,3,3,3,3,3,3,3,3,3,3,3,3,3,3,0,3,3,2,2,2,1
1,2,2,2,3,3,41,3,3,3,3,3,24,49,26,3,3,3,3,3,3,3,3,3,3,3,3,3,3,3,3,3,0,3,3,2,2,2,1
1,2,2,2,3,3,0,46,0,0,50,0,0,0,0,0,0,24,3,3,3,3,3,3,3,3,3,3,3,3,3,3,0,3,3,2,2,2,1
1,2,2,2,3,3,0,44,0,0,50,0,0,0,0,0,0,24,3,3,3,3,3,3,3,3,3,3,3,3,3,3,0,3,3,2,2,2,1
1,2,2,2,3,3,41,3,3,3,3,3,24,49,26,3,3,3,3,3,3,3,3,3,3,3,3,3,3,3,3,3,0,3,3,2,2,2,1
1,2,2,2,3,3,0,3,3,3,3,3,0,0,0,3,51,3,51,3,51,3,51,3,51,3,51,3,51,3,51,3,0,3,3,2,2,2,1
1,2,2,2,3,3,0,3,3,3,3,3,48,0,0,3,3,3,3,3,3,3,3,3,3,3,3,3,3,3,3,3,0,3,3,2,2,2,1
1,2,2,2,3,3,0,3,3,3,3,3,0,0,41,3,3,3,3,3,3,3,3,3,3,3,3,3,3,3,3,3,0,3,3,2,2,2,1
1,2,2,2,3,3,0,3,3,3,3,3,0,0,0,3,3,3,3,3,3,3,3,3,3,3,3,3,3,3,3,3,0,3,3,2,2,2,1
1,2,2,2,3,3,0,3,3,3,3,3,45,0,0,3,51,3,51,3,51,3,51,3,51,3,51,3,51,3,51,3,0,3,3,2,2,2,1
1,2,2,2,3,3,0,3,3,3,3,3,0,0,0,3,3,3,3,3,3,3,3,3,3,3,3,3,3,3,3,3,0,3,3,2,2,2,1
1,2,2,2,3,3,0,3,3,3,3,3,48,0,41,3,3,3,3,3,3,3,3,3,3,3,3,3,3,3,3,3,0,3,3,2,2,2,1
1,2,2,2,3,3,0,3,3,3,3,3,0,0,0,3,3,3,3,3,3,3,3,3,3,3,3,3,3,3,3,3,0,3,3,2,2,2,1
1,2,2,2,3,3,0,3,3,3,3,3,0,0,0,3,52,3,51,3,51,3,52,3,51,3,52,3,52,3,51,3,0,3,3,2,2,2,1
1,2,2,2,3,3,0,3,3,3,3,3,45,0,0,3,3,3,3,3,3,3,3,3,3,3,3,3,3,3,3,3,0,3,3,2,2,2,1
1,2,2,2,3,3,0,3,3,3,3,3,0,0,41,3,3,3,3,3,3,3,3,3,3,3,3,3,3,3,3,3,0,3,3,2,2,2,1
1,2,2,2,3,3,0,3,3,3,3,3,48,0,0,3,3,3,3,3,3,3,3,3,3,3,3,3,3,3,3,3,0,3,3,2,2,2,1
1,2,2,2,3,3,0,3,3,3,3,3,0,0,0,3,52,3,52,3,52,3,52,3,52,3,51,3,52,3,51,3,0,3,3,2,2,2,1
1,2,2,2,3,3,0,3,3,3,3,3,45,0,41,3,3,3,3,3,3,3,3,3,3,3,3,3,3,3,3,3,0,3,3,2,2,2,1
1,2,2,2,0,3,44,0,0,0,0,46,0,0,0,3,3,3,3,3,3,3,3,3,3,3,3,3,3,3,3,3,41,3,3,2,2,2,1
1,2,2,2,3,3,3,3,3,3,3,3,3,3,3,3,3,3,3,3,3,3,3,3,3,3,3,3,3,3,3,3,3,3,3,2,2,2,1
1,2,2,2,3,3,3,3,3,3,3,3,3,3,3,3,3,3,3,3,3,3,3,3,3,3,3,3,3,3,3,3,3,3,3,2,2,2,1
1,2,2,2,2,2,2,2,2,2,2,2,2,2,2,2,2,2,2,2,2,2,2,2,2,2,2,2,2,2,2,2,2,2,2,2,2,2,1
1,2,2,2,2,2,2,2,2,2,2,2,2,2,2,2,2,2,2,2,2,2,2,2,2,2,2,2,2,2,2,2,2,2,2,2,2,2,1
1,2,2,2,2,2,2,2,2,2,2,2,2,2,2,2,2,2,2,2,2,2,2,2,2,2,2,2,2,2,2,2,2,2,2,2,2,2,1
1,1,1,1,1,1,1,1,1,1,1,1,1,1,1,1,1,1,1,1,1,1,1,1,1,1,1,1,1,1,1,1,1,1,1,1,1,1,1
1,1,1,1,1,1,1,1,1,1,1,1,1,1,1,1,1,1,1,1,1,1,1,1,1,1,1,1,1,1,1,1,1,1,1,1,1,1,1
1,1,1,1,1,1,1,1,1,1,1,1,1,1,1,1,1,1,1,1,1,1,1,1,1,1,1,1,1,1,1,1,1,1,1,1,1,1,1
1,1,1,1,1,1,1,1,1,1,1,1,1,1,1,1,1,1,1,1,1,1,1,1,1,1,1,1,1,1,1,1,1,1,1,1,1,1,1
:endlayer
layer: 4
53,53,53,53,53,53,53,53,53,53,53,53,53,53,53,53,53,53,53,53,53,53,53,53,53,53,53,53,53,53,53,53,53,53,53,53,53,53,53
53,53,53,53,53,2,2,2,2,2,2,2,2,2,2,2,2,2,2,2,2,2,2,2,2,2,2,2,2,2,2,2,2,2,53,53,53,53,53
53,53,53,53,2,2,2,2,2,2,2,2,2,2,2,2,2,2,2,2,2,2,2,2,2,2,2,2,2,2,2,2,2,2,2,53,53,53,53
53,53,53,2,2,2,2,2,2,2,2,2,2,2,2,2,2,2,2,2,2,2,2,2,2,2,2,2,2,2,2,2,2,2,2,2,53,53,53
53,53,2,2,3,3,3,3,3,3,3,3,3,3,3,3,3,3,3,3,3,3,3,3,3,3,3,3,3,3,3,3,3,3,3,2,2,53,53
53,2,2,2,3,3,3,3,3,3,3,3,3,3,3,3,3,3,3,3,3,3,3,3,3,3,3,3,3,3,3,3,3,3,3,2,2,2,53
53,2,2,2,3,3,3,3,3,3,3,3,3,3,3,3,3,3,3,3,3,3,3,3,3,3,3,3,3,3,3,3,3,3,3,2,2,2,53
53,2,2,2,3,3,3,3,3,3,3,3,3,3,3,3,3,3,3,3,3,3,3,3,3,3,3,3,3,3,3,3,3,3,3,2,2,2,53
53,2,2,2,3,3,3,3,3,3,3,3,3,3,3,3,3,3,3,3,3,3,3,3,3,3,3,3,3,3,3,3,3,3,3,2,2,2,53
53,2,2,2,3,3,3,3,3,3,3,3,3,3,3,3,3,3,3,3,3,3,3,3,3,3,3,3,3,3,3,3,3,3,3,2,2,2,53
53,2,2,2,3,3,3,3,3,3,3,3,3,3,3,3,3,3,3,3,3,3,3,3,3,3,3,3,3,3,3,3,3,3,3,2,2,2,53
53,2,2,2,3,3,3,3,3,3,3,3,3,3,3,3,3,3,3,3,3,3,3,3,3,3,3,3,3,3,3,3,3,3,3,2,2,2,53
53,2,2,2,3,3,3,3,3,3,3,3,3,3,3,3,3,3,3,3,3,3,3,3,3,3,3,3,3,3,3,3,3,3,3,2,2,2,53
53,2,2,2,3,3,3,3,3,3,3,3,3,3,3,3,3,3,3,3,3,3,3,3,3,3,3,3,3,3,3,3,3,3,3,2,2,2,53
53,2,2,2,3,3,3,3,3,3,3,3,3,3,3,3,3,3,3,3,3,3,3,3,3,3,3,3,3,3,3,3,3,3,3,2,2,2,53
53,2,2,2,3,3,3,3,3,3,3,3,3,3,3,0,0,0,24,3,3,3,3,3,3,3,3,3,3,3,3,3,3,3,3,2,2,2,53
53,2,2,2,3,3,3,3,3,3,3,3,3,3,3,0,0,0,24,3,3,3,3,3,3,3,3,3,3,3,3,3,3,3,3,2,2,2,53
53,2,2,2,3,3,3,3,3,3,3,3,3,3,3,3,3,3,3,3,3,3,3,3,3,3,3,3,3,3,3,3,3,3,3,2,2,2,53
53,2,2,2,3,3,3,3,3,3,3,3,3,3,3,3,3,3,3,3,3,3,3,3,3,3,3,3,3,3,3,3,3,3,3,2,2,2,53
53,2,2,2,3,3,3,3,3,3,3,3,3,3,3,3,3,3,3,3,3,3,3,3,3,3,3,3,3,3,3,3,3,3,3,2,2,2,53
53,2,2,2,3,3,3,3,3,3,3,3,3,3,3,3,3,3,3,3,3,3,3,3,3,3,3,3,3,3,3,3,3,3,3,2,2,2,53
53,2,2,2,3,3,3,3,3,3,3,3,3,3,3,3,3,3,3,3,3,3,3,3,3,3,3,3,3,3,3,3,3,3,3,2,2,2,53
53,2,2,2,3,3,3,3,3,3,3,3,3,3,3,3,3,3,3,3,3,3,3,3,3,3,3,3,3,3,3,3,3,3,3,2,2,2,53
53,2,2,2,3,3,3,3,3,3,3,3,3,3,3,3,3,3,3,3,3,3,3,3,3,3,3,3,3,3,3,3,3,3,3,2,2,2,53
53,2,2,2,3,3,3,3,3,3,3,3,3,3,3,3,3,3,3,3,3,3,3,3,3,3,3,3,3,3,3,3,3,3,3,2,2,2,53
53,2,2,2,3,3,3,3,3,3,3,3,3,3,3,3,3,3,3,3,3,3,3,3,3,3,3,3,3,3,3,3,3,3,3,2,2,2,53
53,2,2,2,3,3,3,3,3,3,3,3,3,3,3,3,3,3,3,3,3,3,3,3,3,3,3,3,3,3,3,3,3,3,3,2,2,2,53
53,2,2,2,3,3,3,3,3,3,3,3,3,3,3,3,3,3,3,3,3,3,3,3,3,3,3,3,3,3,3,3,3,3,3,2,2,2,53
53,2,2,2,3,3,3,3,3,3,3,3,3,3,3,3,3,3,3,3,3,3,3,3,3,3,3,3,3,3,3,3,3,3,3,2,2,2,53
53,2,2,2,3,3,3,3,3,3,3,3,3,3,3,3,3,3,3,3,3,3,3,3,3,3,3,3,3,3,3,3,3,3,3,2,2,2,53
53,2,2,2,3,3,3,3,3,3,3,3,3,3,3,3,3,3,3,3,3,3,3,3,3,3,3,3,3,3,3,3,3,3,3,2,2,2,53
53,2,2,2,3,3,3,3,3,3,3,3,3,3,3,3,3,3,3,3,3,3,3,3,3,3,3,3,3,3,3,3,3,3,3,2,2,2,53
53,2,2,2,0,3,3,3,3,3,3,3,3,3,3,3,3,3,3,3,3,3,3,3,3,3,3,3,3,3,3,3,3,3,3,2,2,2,53
53,2,2,2,3,3,3,3,3,3,3,3,3,3,3,3,3,3,3,3,3,3,3,3,3,3,3,3,3,3,3,3,3,3,3,2,2,2,53
53,53,2,2,3,3,3,3,3,3,3,3,3,3,3,3,3,3,3,3,3,3,3,3,3,3,3,3,3,3,3,3,3,3,3,2,2,53,53
53,53,53,2,2,2,2,2,2,2,2,2,2,2,2,2,2,2,2,2,3,2,2,2,2,2,2,2,2,2,2,2,2,2,2,2,53,53,53
53,53,53,53,2,2,2,2,2,2,2,2,2,2,2,2,2,3,3,3,3,2,2,2,2,2,2,2,2,2,2,2,2,2,2,53,53,53,53
53,53,53,53,53,2,2,2,2,2,2,2,2,2,2,2,2,2,3,3,3,2,2,2,2,2,2,2,2,2,2,2,2,2,53,53,53,53,53
53,53,53,53,53,53,53,53,53,53,53,53,53,53,53,53,53,3,54,54,54,3,53,53,53,53,53,53,53,53,53,53,53,53,53,53,53,53,53
53,53,53,53,53,53,53,53,53,53,53,53,53,53,53,53,53,53,54,54,54,53,53,53,53,53,53,53,53,53,53,53,53,53,53,53,53,53,53
53,53,53,53,53,53,53,53,53,53,53,53,53,53,53,53,55,53,54,54,54,53,55,53,53,53,53,53,53,53,53,53,53,53,53,53,53,53,53
53,53,53,53,53,53,53,53,53,53,53,53,53,53,53,53,53,53,54,54,54,53,53,53,53,53,53,53,53,53,53,53,53,53,53,53,53,53,53
:endlayer
layer: 5
0,0,0,0,0,0,0,0,0,0,0,0,0,0,0,0,0,0,0,0,0,0,0,0,0,0,0,0,0,0,0,0,0,0,0,0,0,0,0
0,0,0,0,0,0,0,0,0,0,0,0,0,0,0,0,0,0,0,0,0,0,0,0,0,0,0,0,0,0,0,0,0,0,0,0,0,0,0
0,0,56,0,0,0,0,0,0,0,0,0,0,0,0,0,0,0,0,0,0,0,0,0,0,0,0,0,0,0,0,0,0,0,0,0,57,0,0
0,0,0,0,0,0,0,3,3,3,3,3,3,3,3,3,3,3,3,3,3,3,3,3,3,3,3,3,3,3,3,3,0,0,0,0,0,0,0
0,0,0,0,0,0,3,3,3,4,4,4,4,4,4,4,3,3,3,3,3,3,3,4,4,4,4,4,4,4,3,3,3,0,0,0,0,0,0
0,0,0,0,0,3,3,3,4,4,4,4,58,4,4,4,3,3,3,3,3,3,3,4,4,4,59,4,4,4,4,3,3,3,0,0,0,0,0
0,0,0,0,3,3,3,4,4,4,3,3,3,3,3,3,3,3,3,3,3,3,3,3,3,3,3,3,3,4,4,4,3,3,3,0,0,0,0
0,0,0,3,3,3,4,4,4,3,3,3,3,3,3,3,3,3,3,3,3,3,3,3,3,3,3,3,3,3,4,4,4,3,3,3,0,0,0
0,0,0,3,3,4,4,4,3,3,3,3,3,3,3,3,3,3,3,3,3,3,3,3,3,3,3,3,3,3,3,4,4,4,3,3,0,0,0
0,0,0,3,4,4,4,3,3,3,3,3,3,3,3,3,3,3,3,3,3,3,3,3,3,3,3,3,3,3,3,3,4,4,4,3,0,0,0
0,0,0,3,4,4,3,3,3,3,3,3,3,3,3,3,3,3,3,3,3,3,3,3,3,3,3,3,3,3,3,3,3,4,4,3,0,0,0
0,0,0,3,4,4,3,3,3,3,3,3,3,3,3,3,3,3,3,3,3,3,3,3,3,3,3,3,3,3,3,3,3,4,4,3,0,0,0
0,0,0,3,60,4,3,3,3,3,3,3,3,3,3,3,3,3,3,3,3,3,3,3,3,3,3,3,3,3,3,3,3,61,4,3,0,0,0
0,0,0,3,4,4,3,3,3,3,3,3,3,3,3,3,3,3,3,3,3,3,3,3,3,3,3,3,3,3,3,3,3,4,4,3,0,0,0
0,0,0,3,4,4,3,3,3,3,3,3,3,3,3,3,3,3,3,3,3,3,3,3,3,3,3,3,3,3,3,3,3,4,4,3,0,0,0
0,0,0,3,4,4,3,3,3,3,3,3,3,3,3,3,0,0,0,24,3,3,3,3,3,3,3,3,3,3,3,3,3,4,4,3,0,0,0
0,0,0,3,3,3,3,3,3,3,3,3,3,3,3,3,0,0,0,24,3,3,3,3,3,3,3,3,3,3,3,3,3,3,3,3,0,0,0
0,0,0,3,3,3,3,3,3,3,3,3,3,3,3,3,3,3,3,3,3,3,3,3,3,3,3,3,3,3,3,3,3,3,3,3,0,0,0
0,0,0,3,3,3,3,3,3,3,3,3,3,3,3,3,3,3,3,3,3,3,3,3,3,3,3,3,3,3,3,3,3,3,3,3,0,0,0
0,0,0,3,3,3,3,3,3,3,3,3,3,3,3,3,3,3,3,3,3,3,3,3,3,3,3,3,3,3,3,3,3,3,3,3,0,0,0
0,0,0,3,3,3,3,3,3,3,3,3,3,3,3,3,3,3,3,3,3,3,3,3,3,3,3,3,3,3,3,3,3,3,3,3,0,0,0
0,0,0,3,3,3,3,3,3,3,3,3,3,3,3,3,3,3,3,3,3,3,3,3,3,3,3,3,3,3,3,3,3,3,3,3,0,0,0
0,0,0,3,3,3,3,3,3,3,3,3,3,3,3,3,3,3,3,3,3,3,3,3,3,3,3,3,3,3,3,3,3,3,3,3,0,0,0
0,0,0,3,4,4,3,3,3,3,3,3,3,3,3,3,3,3,3,3,3,3,3,3,3,3,3,3,3,3,3,3,3,4,4,3,0,0,0
0,0,0,3,4,4,3,3,3,3,3,3,3,3,3,3,3,3,3,3,3,3,3,3,3,3,3,3,3,3,3,3,3,4,4,3,0,0,0
0,0,0,3,4,62,3,3,3,3,3,3,3,3,3,3,3,3,3,3,3,3,3,3,3,3,3,3,3,3,3,3,3,4,4,3,0,0,0
0,0,0,3,4,4,3,3,3,3,3,3,3,3,3,3,3,3,3,3,3,3,3,3,3,3,3,3,3,3,3,3,3,63,4,3,0,0,0
0,0,0,3,4,4,3,3,3,3,3,3,3,3,3,3,3,3,3,3,3,3,3,3,3,3,3,3,3,3,3,3,3,4,4,3,0,0,0
0,0,0,3,4,4,3,3,3,3,3,3,3,3,3,3,3,3,3,3,3,3,3,3,3,3,3,3,3,3,3,3,3,4,4,3,0,0,0
0,0,0,3,4,4,4,3,3,3,3,3,3,3,3,3,3,3,3,3,3,3,3,3,3,3,3,3,3,3,3,3,4,4,4,3,0,0,0
0,0,0,3,3,4,4,4,3,3,3,3,3,3,3,3,3,64,64,64,64,64,3,3,3,3,3,3,3,3,3,4,4,4,3,3,0,0,0
0,0,0,3,3,3,4,4,4,3,3,3,3,3,3,3,3,0,0,0,0,0,3,3,3,3,3,3,3,3,4,4,4,3,3,3,0,0,0
0,0,0,0,3,3,3,4,4,4,3,3,3,3,3,3,3,0,0,0,0,0,3,3,3,3,3,3,3,4,4,4,3,3,3,0,0,0,0
0,0,0,0,0,3,3,3,4,4,4,4,4,4,4,4,3,65,66,67,68,69,3,4,4,4,4,70,4,4,4,3,3,3,0,0,0,0,0
0,0,0,0,0,0,3,3,3,4,4,71,4,4,4,4,3,0,0,0,0,0,3,4,4,4,4,4,4,4,3,3,3,0,0,0,0,0,0
0,0,0,0,0,0,0,3,3,3,3,3,3,3,3,3,3,0,0,0,0,0,3,3,3,3,3,3,3,3,3,3,0,0,0,0,0,0,0
0,0,0,0,0,0,0,0,0,0,0,0,0,0,0,3,51,0,0,0,0,0,0,3,0,0,0,0,0,0,0,0,0,0,0,0,0,0,0
0,0,0,0,0,0,0,0,0,0,0,0,0,0,0,0,3,72,73,74,75,76,3,0,0,0,0,0,0,0,0,0,0,0,0,0,0,0,0
0,0,0,0,0,0,0,0,0,0,0,0,0,0,0,0,77,77,0,0,0,77,77,0,0,0,0,0,0,0,0,0,0,0,0,0,0,0,0
0,0,0,0,0,0,0,0,0,0,0,0,0,0,0,0,0,0,0,0,0,0,0,0,0,0,0,0,0,0,0,0,0,0,0,0,0,0,0
0,78,0,0,0,0,0,0,0,0,0,0,0,0,0,0,55,0,0,0,0,0,55,0,0,0,0,0,0,0,0,0,0,0,0,0,0,79,0
0,0,0,0,0,0,0,0,0,0,0,0,0,0,0,0,0,0,0,0,0,0,0,0,0,0,0,0,0,0,0,0,0,0,0,0,0,0,0
:endlayer
layer: 6
0,0,0,0,0,0,0,0,0,0,0,0,0,0,0,0,0,0,0,0,0,0,0,0,0,0,0,0,0,0,0,0,0,0,0,0,0,0,0
0,0,0,0,0,0,0,0,0,0,0,0,0,0,0,0,0,0,0,0,0,0,0,0,0,0,0,0,0,0,0,0,0,0,0,0,0,0,0
0,0,0,0,0,0,0,0,0,0,0,0,0,0,0,0,0,0,0,0,0,0,0,0,0,0,0,0,0,0,0,0,0,0,0,0,0,0,0
0,0,0,0,0,0,0,0,3,3,3,3,3,3,3,3,3,3,3,3,3,3,3,3,3,3,3,3,3,3,3,0,0,0,0,0,0,0,0
0,0,0,0,0,0,0,3,3,4,4,4,4,4,4,4,3,3,3,3,3,3,3,4,4,4,4,4,4,4,3,3,0,0,0,0,0,0,0
0,0,0,0,0,0,3,3,4,4,4,4,4,4,4,4,3,3,3,3,3,3,3,4,4,4,4,4,4,4,4,3,3,0,0,0,0,0,0
0,0,0,0,0,3,3,4,4,4,3,3,3,3,3,3,3,3,3,3,3,3,3,3,3,3,3,3,3,4,4,4,3,3,0,0,0,0,0
0,0,0,0,3,3,4,4,4,3,3,3,3,3,3,3,3,3,3,3,3,3,3,3,3,3,3,3,3,3,4,4,4,3,3,0,0,0,0
0,0,0,3,3,4,4,4,3,3,3,3,3,3,3,3,3,3,3,3,3,3,3,3,3,3,3,3,3,3,3,4,4,4,3,3,0,0,0
0,0,0,3,4,4,4,3,3,3,3,3,3,3,3,3,3,3,3,3,3,3,3,3,3,3,3,3,3,3,3,3,4,4,4,3,0,0,0
0,0,0,3,4,4,3,3,3,3,3,3,3,3,3,3,3,3,3,3,3,3,3,3,3,3,3,3,3,3,3,3,3,4,4,3,0,0,0
0,0,0,3,4,4,3,3,3,3,3,3,3,3,3,3,3,3,3,3,3,3,3,3,3,3,3,3,3,3,3,3,3,4,4,3,0,0,0
0,0,0,3,4,4,3,3,3,3,3,3,3,3,3,3,3,3,3,3,3,3,3,3,3,3,3,3,3,3,3,3,3,4,4,3,0,0,0
0,0,0,3,4,4,3,3,3,3,3,3,3,3,3,3,3,3,3,3,3,3,3,3,3,3,3,3,3,3,3,3,3,4,4,3,0,0,0
0,0,0,3,4,4,3,3,3,3,3,3,3,3,3,3,3,3,3,3,3,3,3,3,3,3,3,3,3,3,3,3,3,4,4,3,0,0,0
0,0,0,3,4,4,3,3,3,3,3,3,3,3,3,3,3,0,0,0,24,3,3,3,3,3,3,3,3,3,3,3,3,4,4,3,0,0,0
0,0,0,3,3,3,3,3,3,3,3,3,3,3,3,3,3,0,0,0,24,3,3,3,3,3,3,3,3,3,3,3,3,3,3,3,0,0,0
0,0,0,3,3,3,3,3,3,3,3,3,3,3,3,3,3,3,3,3,3,3,3,3,3,3,3,3,3,3,3,3,3,3,3,3,0,0,0
0,0,0,3,3,3,3,3,3,3,3,3,3,3,3,3,3,3,3,3,3,3,3,3,3,3,3,3,3,3,3,3,3,3,3,3,0,0,0
0,0,0,3,3,3,3,3,3,3,3,3,3,3,3,3,3,3,3,3,3,3,3,3,3,3,3,3,3,3,3,3,3,3,3,3,0,0,0
0,0,0,3,3,3,3,3,3,3,3,3,3,3,3,3,3,3,3,3,3,3,3,3,3,3,3,3,3,3,3,3,3,3,3,3,0,0,0
0,0,0,3,3,3,3,3,3,3,3,3,3,3,3,3,3,3,3,3,3,3,3,3,3,3,3,3,3,3,3,3,3,3,3,3,0,0,0
0,0,0,3,3,3,3,3,3,3,3,3,3,3,3,3,3,3,3,3,3,3,3,3,3,3,3,3,3,3,3,3,3,3,3,3,0,0,0
0,0,0,3,4,4,3,3,3,3,3,3,3,3,3,3,3,3,3,3,3,3,3,3,3,3,3,3,3,3,3,3,3,4,4,3,0,0,0
0,0,0,3,4,4,3,3,3,3,3,3,3,3,3,3,3,3,3,3,3,3,3,3,3,3,3,3,3,3,3,3,3,4,4,3,0,0,0
0,0,0,3,4,4,3,3,3,3,3,3,3,3,3,3,3,3,3,3,3,3,3,3,3,3,3,3,3,3,3,3,3,4,4,3,0,0,0
0,0,0,3,4,4,3,3,3,3,3,3,3,3,3,3,3,3,3,3,3,3,3,3,3,3,3,3,3,3,3,3,3,4,4,3,0,0,0
0,0,0,3,4,4,3,3,3,3,3,3,3,3,3,3,3,3,3,3,3,3,3,3,3,3,3,3,3,3,3,3,3,4,4,3,0,0,0
0,0,0,3,4,4,3,3,3,3,3,3,3,3,3,3,3,3,3,3,3,3,3,3,3,3,3,3,3,3,3,3,3,4,4,3,0,0,0
0,0,0,3,4,4,4,3,3,3,3,3,3,3,3,3,3,3,64,64,64,3,3,3,3,3,3,3,3,3,3,3,4,4,4,3,0,0,0
0,0,0,3,3,4,4,4,3,3,3,3,3,3,3,3,3,0,0,0,0,0,3,3,3,3,3,3,3,3,3,4,4,4,3,3,0,0,0
0,0,0,0,3,3,4,4,4,3,3,3,3,3,3,3,3,0,0,0,0,0,3,3,3,3,3,3,3,3,4,4,4,3,3,0,0,0,0
0,0,0,0,0,3,3,4,4,4,3,3,3,3,3,3,3,0,0,0,0,0,3,3,3,3,3,3,3,4,4,4,3,3,0,0,0,0,0
0,0,0,0,0,0,3,3,4,4,4,4,4,4,4,4,3,0,0,0,0,0,3,4,4,4,4,4,4,4,4,3,3,0,0,0,0,0,0
0,0,0,0,0,0,0,3,3,4,4,4,4,4,4,4,3,0,0,0,0,0,3,4,4,4,4,4,4,4,3,3,0,0,0,0,0,0,0
0,0,0,0,0,0,0,0,3,3,3,3,3,3,3,3,3,0,0,0,0,0,3,3,3,3,3,3,3,3,3,0,0,0,0,0,0,0,0
0,0,0,0,0,0,0,0,0,0,0,0,0,0,0,3,0,0,0,0,0,0,0,3,0,0,0,0,0,0,0,0,0,0,0,0,0,0,0
0,0,0,0,0,0,0,0,0,0,0,0,0,0,0,0,3,80,81,82,83,84,3,0,0,0,0,0,0,0,0,0,0,0,0,0,0,0,0
0,0,0,0,0,0,0,0,0,0,0,0,0,0,0,0,77,77,0,0,0,77,77,0,0,0,0,0,0,0,0,0,0,0,0,0,0,0,0
0,0,0,0,0,0,0,0,0,0,0,0,0,0,0,0,0,0,0,0,0,0,0,0,0,0,0,0,0,0,0,0,0,0,0,0,0,0,0
0,0,0,0,0,0,0,0,0,0,0,0,0,0,0,0,85,0,0,0,0,0,85,0,0,0,0,0,0,0,0,0,0,0,0,0,0,0,0
0,0,0,0,0,0,0,0,0,0,0,0,0,0,0,0,0,0,0,0,0,0,0,0,0,0,0,0,0,0,0,0,0,0,0,0,0,0,0
:endlayer
layer: 7
0,0,0,0,0,0,0,0,0,0,0,0,0,0,0,0,0,0,0,0,0,0,0,0,0,0,0,0,0,0,0,0,0,0,0,0,0,0,0
0,0,0,0,0,0,0,0,0,0,0,0,0,0,0,0,0,0,0,0,0,0,0,0,0,0,0,0,0,0,0,0,0,0,0,0,0,0,0
0,0,0,0,0,0,0,0,0,0,0,0,0,0,0,0,0,0,0,0,0,0,0,0,0,0,0,0,0,0,0,0,0,0,0,0,0,0,0
0,0,0,0,0,0,0,0,86,0,0,0,0,0,0,0,3,3,3,3,3,3,3,0,0,0,0,0,0,0,86,0,0,0,0,0,0,0,0
0,0,0,0,0,0,0,0,0,0,0,0,87,0,0,0,3,88,0,88,0,88,3,0,87,0,0,0,0,0,0,0,0,0,0,0,0,0,0
0,0,0,0,0,0,0,0,0,0,0,0,0,0,87,0,3,89,90,89,0,89,3,0,0,0,87,0,0,0,87,0,0,0,0,0,0,0,0
0,0,0,0,0,0,0,87,87,0,3,3,3,3,3,3,3,0,0,0,91,0,3,3,3,3,3,3,3,0,87,0,0,0,0,0,0,0,0
0,0,0,0,0,0,0,0,0,3,3,3,3,3,3,3,3,92,0,0,0,92,3,3,3,3,3,3,3,3,0,0,0,0,0,0,0,0,0
0,0,0,86,0,0,0,0,3,3,3,3,3,3,3,3,3,93,0,0,0,93,3,3,3,3,3,3,3,3,3,0,0,0,0,86,0,0,0
0,0,0,0,0,87,0,3,3,3,3,3,3,3,3,3,3,3,3,0,3,3,3,3,3,3,3,3,3,3,3,3,87,0,0,0,0,0,0
0,0,0,0,0,0,3,3,3,3,3,94,3,85,3,95,3,0,0,0,0,0,3,96,0,0,97,98,3,3,3,3,3,0,87,0,0,0,0
0,0,0,0,0,87,3,3,3,3,0,0,99,0,0,0,0,0,0,0,0,0,0,0,0,0,100,0,88,3,3,3,3,0,0,0,0,0,0
0,0,0,0,0,0,3,3,3,3,0,101,0,0,0,0,3,3,3,3,3,0,3,0,0,0,0,0,89,3,3,3,3,87,0,0,0,0,0
0,0,0,0,87,0,3,3,3,3,0,0,0,102,0,103,3,3,3,3,3,0,3,0,0,0,0,0,0,3,3,3,3,0,0,0,0,0,0
0,0,0,0,0,0,3,3,3,3,0,0,0,0,104,0,3,3,3,3,3,0,3,92,0,92,105,92,0,3,3,3,3,0,0,0,0,0,0
0,0,0,0,0,0,3,3,3,3,0,0,0,106,107,108,3,0,0,0,0,0,3,93,0,93,0,93,0,3,3,3,3,0,0,0,0,0,0
0,0,0,3,3,3,3,3,3,3,0,3,3,3,3,3,3,0,0,0,0,0,109,3,3,3,3,3,3,3,3,3,3,3,3,3,0,0,0
0,0,0,3,110,110,110,110,110,3,0,0,0,0,0,0,0,3,3,3,26,0,0,0,3,3,3,0,0,3,111,112,0,97,98,3,0,0,0
0,0,0,3,110,0,0,0,0,3,0,0,3,3,3,0,0,3,3,3,26,0,0,0,3,3,3,0,0,3,0,0,0,113,0,3,0,0,0
0,0,0,3,110,0,114,0,0,0,0,0,3,3,3,0,0,115,0,0,0,0,0,0,0,0,0,0,0,0,0,0,0,97,98,3,0,0,0
0,0,0,3,110,0,0,0,0,3,0,0,3,3,3,0,0,0,0,0,0,0,0,0,3,3,3,0,0,3,0,0,0,116,0,3,0,0,0
0,0,0,3,110,110,110,110,110,3,0,0,3,3,3,0,0,3,0,0,0,3,0,0,3,3,3,0,0,3,111,112,0,97,98,3,0,0,0
0,0,0,3,3,3,3,3,3,3,3,3,3,3,3,3,0,0,0,0,0,0,0,3,3,3,3,3,3,3,3,3,3,3,3,3,0,0,0
0,0,0,0,0,0,3,3,3,3,117,118,0,0,119,120,3,0,0,0,0,0,3,117,118,0,0,119,120,3,3,3,3,0,0,0,0,0,0
0,0,0,0,0,0,3,3,3,3,0,0,121,0,0,0,3,3,0,0,0,3,3,0,0,0,0,0,0,3,3,3,3,0,0,0,0,0,0
0,0,0,0,0,87,3,3,3,3,117,118,0,0,119,120,3,3,0,0,0,3,3,117,118,122,123,119,120,3,3,3,3,0,0,0,0,0,0
0,0,0,0,0,0,3,3,3,3,0,0,0,124,0,0,3,3,0,0,0,3,3,0,0,0,0,0,0,3,3,3,3,0,87,0,0,0,0
0,0,0,0,0,0,3,3,3,3,117,118,0,0,0,0,3,0,0,0,0,0,3,0,0,0,0,119,120,3,3,3,3,0,0,0,0,0,0
0,0,0,0,87,0,3,3,3,3,3,0,0,0,0,0,0,0,0,0,0,0,0,0,0,0,0,0,3,3,3,3,3,0,87,0,0,0,0
0,0,0,0,0,0,0,3,3,3,3,3,3,3,3,3,3,3,0,0,0,3,3,3,3,3,3,3,3,3,3,3,0,87,0,0,0,0,0
0,0,0,86,0,0,0,0,3,3,3,3,3,3,3,3,3,125,0,0,0,126,3,3,3,3,3,3,3,3,3,0,0,0,0,86,0,0,0
0,0,0,0,0,0,0,87,0,3,3,3,3,3,3,3,3,0,0,0,0,0,3,3,3,3,3,3,3,3,0,87,0,0,0,0,0,0,0
0,0,0,0,0,0,0,0,0,0,3,3,3,3,3,3,3,0,0,0,0,0,3,3,3,3,3,3,3,0,0,0,0,0,0,0,0,0,0
0,0,0,0,0,0,0,0,0,0,87,0,0,87,0,0,3,0,0,0,0,0,3,0,0,0,0,0,0,0,0,0,0,0,0,0,0,0,0
0,0,0,0,0,0,0,0,0,0,0,0,0,0,0,0,3,0,0,0,0,0,3,0,0,0,87,0,87,0,0,0,0,0,0,0,0,0,0
0,0,0,0,0,0,0,0,86,0,0,0,0,0,0,0,3,0,0,0,0,0,3,0,0,0,0,0,0,0,86,0,0,0,0,0,0,0,0
0,0,0,0,0,0,0,0,0,0,0,0,0,0,0,3,0,0,0,0,0,0,0,3,0,0,0,0,0,0,0,0,0,0,0,0,0,0,0
0,0,0,0,0,0,0,0,0,0,0,0,0,0,0,0,3,127,128,129,130,131,3,0,0,0,0,0,0,0,0,0,0,0,0,0,0,0,0
0,0,0,0,0,0,0,0,0,0,0,0,0,0,0,0,77,77,0,0,0,77,77,0,0,0,0,0,0,0,0,0,0,0,0,0,0,0,0
0,0,0,0,0,0,0,0,0,0,0,0,0,0,0,0,0,0,0,0,0,0,0,0,0,0,0,0,0,0,0,0,0,0,0,0,0,0,0
0,0,0,0,0,0,0,0,0,0,0,0,0,0,0,0,0,0,0,0,0,0,0,0,0,0,0,0,0,0,0,0,0,0,0,0,0,0,0
0,0,0,0,0,0,0,0,0,0,0,0,0,0,0,0,0,0,0,0,0,0,0,0,0,0,0,0,0,0,0,0,0,0,0,0,0,0,0
:endlayer
layer: 8
0,0,0,0,0,0,0,0,0,0,0,0,0,0,0,0,0,0,0,0,0,0,0,0,0,0,0,0,0,0,0,0,0,0,0,0,0,0,0
0,0,0,0,0,0,0,0,0,0,0,0,0,0,0,0,0,0,0,0,0,0,0,0,0,0,0,0,0,0,0,0,0,0,0,0,0,0,0
0,0,0,0,0,0,0,0,0,0,0,0,0,0,0,0,0,0,0,44,0,0,0,0,0,0,0,0,0,0,0,0,0,0,0,0,0,0,0
0,0,0,0,0,0,0,0,0,0,0,0,0,0,0,0,3,3,3,3,3,3,3,0,0,0,0,0,0,0,0,0,0,0,0,0,0,0,0
0,0,0,0,0,0,0,0,0,0,0,0,0,0,0,0,3,0,0,0,0,0,3,0,0,0,0,0,0,0,0,0,0,0,0,0,0,0,0
0,0,0,0,0,0,0,0,0,0,0,0,0,0,0,0,3,0,0,0,0,0,3,0,0,0,0,0,0,0,0,0,0,0,0,0,0,0,0
0,0,0,0,0,0,0,0,0,0,3,3,3,3,3,3,3,0,0,0,0,0,3,3,3,3,3,3,3,0,0,0,0,0,0,0,0,0,0
0,0,0,0,0,0,0,0,0,3,3,3,3,3,3,3,3,0,0,0,0,0,3,3,3,3,3,3,3,3,0,0,0,0,0,0,0,0,0
0,0,0,0,0,0,0,0,3,3,3,3,3,3,3,3,3,0,0,0,0,0,3,3,3,3,3,3,3,3,3,0,0,0,0,0,0,0,0
0,0,0,0,0,0,0,3,3,3,3,3,3,3,3,3,3,3,3,0,3,3,3,3,3,3,3,3,3,3,3,3,0,0,0,0,0,0,0
0,0,0,0,0,0,3,3,3,3,3,132,3,0,3,133,3,46,0,0,0,46,3,0,0,0,0,0,3,3,3,3,3,0,0,0,0,0,0
0,0,0,0,0,0,3,3,3,3,0,0,0,0,0,0,0,0,0,0,0,0,0,0,0,0,0,0,0,3,3,3,3,0,0,0,0,0,0
0,0,0,0,0,0,3,3,3,3,0,0,0,0,0,0,3,3,3,3,3,0,3,0,0,0,0,0,0,3,3,3,3,0,0,0,0,0,0
0,0,0,0,0,0,3,3,3,3,0,0,0,0,0,0,3,3,3,3,3,0,3,0,0,0,0,0,0,3,3,3,3,0,0,0,0,0,0
0,0,0,0,0,0,3,3,3,3,0,0,0,0,0,0,3,3,3,3,3,0,3,0,0,0,0,0,0,3,3,3,3,0,0,0,0,0,0
0,0,0,0,0,0,3,3,3,3,0,0,0,0,0,0,3,0,0,0,0,0,3,0,0,0,0,0,0,3,3,3,3,0,0,0,0,0,0
0,0,0,3,3,3,3,3,3,3,0,3,3,3,3,3,3,0,0,0,0,0,0,3,3,3,3,3,3,3,3,3,3,3,3,3,0,0,0
0,0,0,3,110,110,110,110,110,3,0,0,0,0,0,0,0,3,3,26,0,0,0,0,3,3,3,0,0,3,0,0,0,0,0,3,0,0,0
0,0,0,3,110,0,0,0,41,3,0,0,3,3,3,0,0,3,3,26,0,0,0,0,3,3,3,0,0,3,0,0,0,0,0,3,0,0,0
0,0,41,3,110,0,0,0,0,0,0,0,3,3,3,0,0,0,0,0,0,0,0,0,0,0,0,0,0,0,0,0,0,0,0,3,45,0,0
0,0,0,3,110,0,0,0,41,3,0,0,3,3,3,0,0,0,0,0,0,0,0,0,3,3,3,0,0,3,0,0,0,0,0,3,0,0,0
0,0,0,3,110,110,110,110,110,3,44,0,3,3,3,0,0,3,0,0,0,3,0,0,3,3,3,44,0,3,0,0,0,0,0,3,0,0,0
0,0,0,3,3,3,3,3,3,3,3,3,3,3,3,3,0,0,0,0,0,0,0,3,3,3,3,3,3,3,3,3,3,3,3,3,0,0,0
0,0,0,0,0,0,3,3,3,3,0,0,0,0,0,0,3,0,0,0,0,0,3,0,0,0,0,0,0,3,3,3,3,0,0,0,0,0,0
0,0,0,0,0,0,3,3,3,3,0,0,0,0,0,0,3,3,0,0,0,3,3,0,0,0,0,0,0,3,3,3,3,0,0,0,0,0,0
0,0,0,0,0,0,3,3,3,3,0,0,0,0,0,0,3,3,0,0,0,3,3,0,0,0,0,0,0,3,3,3,3,0,0,0,0,0,0
0,0,0,0,0,0,3,3,3,3,0,0,0,0,0,0,3,3,0,0,0,3,3,0,0,0,0,0,0,3,3,3,3,0,0,0,0,0,0
0,0,0,0,0,0,3,3,3,3,0,0,0,0,0,0,3,0,0,0,0,0,3,0,0,0,0,0,0,3,3,3,3,0,0,0,0,0,0
0,0,0,0,0,0,3,3,3,3,3,0,0,0,0,0,0,0,0,0,0,0,0,0,0,0,0,0,3,3,3,3,3,0,0,0,0,0,0
0,0,0,0,0,0,0,3,3,3,3,3,3,3,3,3,3,3,0,0,0,3,3,3,3,3,3,3,3,3,3,3,0,0,0,0,0,0,0
0,0,0,0,0,0,0,0,3,3,3,3,3,3,3,3,3,0,0,0,0,0,3,3,3,3,3,3,3,3,3,0,0,0,0,0,0,0,0
0,0,0,0,0,0,0,0,0,3,3,3,3,3,3,3,3,0,0,0,0,0,3,3,3,3,3,3,3,3,0,0,0,0,0,0,0,0,0
0,0,0,0,0,0,0,0,0,0,3,3,3,3,3,3,3,0,0,0,0,0,3,3,3,3,3,3,3,0,0,0,0,0,0,0,0,0,0
0,0,0,0,0,0,0,0,0,0,0,0,0,0,0,0,3,0,0,0,0,0,3,0,0,0,0,0,0,0,0,0,0,0,0,0,0,0,0
0,0,0,0,0,0,0,0,0,0,0,0,0,0,0,0,3,0,0,0,0,0,3,0,0,0,0,0,0,0,0,0,0,0,0,0,0,0,0
0,0,0,0,0,0,0,0,0,0,0,0,0,0,0,0,3,45,0,0,0,41,3,0,0,0,0,0,0,0,0,0,0,0,0,0,0,0,0
0,0,0,0,0,0,0,0,0,0,0,0,0,0,41,3,0,0,0,0,0,0,0,3,45,0,0,0,0,0,0,0,0,0,0,0,0,0,0
0,0,0,0,0,0,0,0,0,0,0,0,0,0,0,0,3,134,135,136,137,138,3,0,0,0,0,0,0,0,0,0,0,0,0,0,0,0,0
0,0,0,0,0,0,0,0,0,0,0,0,0,0,0,0,77,77,77,77,77,77,77,0,0,0,0,0,0,0,0,0,0,0,0,0,0,0,0
0,0,0,0,0,0,0,0,0,0,0,0,0,0,0,0,0,0,0,0,0,0,0,0,0,0,0,0,0,0,0,0,0,0,0,0,0,0,0
0,0,0,0,0,0,0,0,0,0,0,0,0,0,0,0,0,0,0,0,0,0,0,0,0,0,0,0,0,0,0,0,0,0,0,0,0,0,0
0,0,0,0,0,0,0,0,0,0,0,0,0,0,0,0,0,0,0,0,0,0,0,0,0,0,0,0,0,0,0,0,0,0,0,0,0,0,0
:endlayer
layer: 9
0,0,0,0,0,0,0,0,0,0,0,0,0,0,0,0,0,0,0,0,0,0,0,0,0,0,0,0,0,0,0,0,0,0,0,0,0,0,0
0,0,0,0,0,0,0,0,0,0,0,0,0,0,0,0,0,0,0,0,0,0,0,0,0,0,0,0,0,0,0,0,0,0,0,0,0,0,0
0,0,0,0,0,0,0,0,0,0,0,0,0,0,0,0,0,0,0,0,0,0,0,0,0,0,0,0,0,0,0,0,0,0,0,0,0,0,0
0,0,0,0,0,0,0,0,0,0,0,0,0,0,0,0,3,3,3,3,3,3,3,0,0,0,0,0,0,0,0,0,0,0,0,0,0,0,0
0,0,0,0,0,0,0,0,0,0,0,0,0,0,0,0,3,0,0,46,0,0,3,0,0,0,0,0,0,0,0,0,0,0,0,0,0,0,0
0,0,0,0,0,0,0,0,0,0,0,0,0,0,0,0,3,0,0,0,0,0,3,0,0,0,0,0,0,0,0,0,0,0,0,0,0,0,0
0,0,0,0,0,0,0,0,0,0,3,3,3,3,3,3,3,45,0,0,0,41,3,3,3,3,3,3,3,0,0,0,0,0,0,0,0,0,0
0,0,0,0,0,0,0,0,0,3,3,3,3,3,3,3,3,0,0,0,0,0,3,3,3,3,3,3,3,3,0,0,0,0,0,0,0,0,0
0,0,0,0,0,0,0,0,3,3,3,3,3,3,3,3,3,0,0,44,0,0,3,3,3,3,3,3,3,3,3,0,0,0,0,0,0,0,0
0,0,0,0,0,0,0,3,3,3,3,3,3,3,3,3,3,3,3,3,3,3,3,3,3,3,3,3,3,3,3,3,0,0,0,0,0,0,0
0,0,0,0,0,0,3,3,3,3,3,139,3,140,3,141,3,0,0,0,0,0,3,46,0,0,0,41,3,3,3,3,3,0,0,0,0,0,0
0,0,0,0,0,0,3,3,3,3,46,0,46,0,46,0,3,0,0,0,0,0,3,0,0,0,0,0,0,3,3,3,3,0,0,0,0,0,0
0,0,0,0,0,0,3,3,3,3,0,0,0,0,0,0,3,3,3,3,3,3,3,0,0,0,0,0,0,3,3,3,3,0,0,0,0,0,0
0,0,0,0,0,0,3,3,3,3,0,0,0,0,0,0,3,3,3,3,3,3,3,0,0,0,0,0,0,3,3,3,3,0,0,0,0,0,0
0,0,0,0,0,0,3,3,3,3,0,0,0,0,0,0,3,3,3,3,3,3,3,0,0,0,0,0,0,3,3,3,3,0,0,0,0,0,0
0,0,0,0,0,0,3,3,3,3,45,0,0,0,0,44,3,0,0,46,0,0,3,45,0,0,0,0,44,3,3,3,3,0,0,0,0,0,0
0,0,0,3,3,3,3,3,3,3,3,3,3,3,3,3,3,0,0,0,0,0,0,3,3,3,3,3,3,3,3,3,3,3,3,3,0,0,0
0,0,0,3,110,110,110,110,110,3,0,0,3,3,3,0,0,3,26,0,0,0,0,0,3,3,3,0,0,3,0,0,46,0,0,3,0,0,0
0,0,0,3,110,0,0,0,0,3,0,0,3,3,3,0,0,3,26,0,0,0,0,0,3,3,3,0,0,3,0,0,0,0,0,3,0,0,0
0,0,0,3,110,0,0,0,0,3,0,0,3,3,3,45,0,0,0,0,0,0,0,41,3,3,3,0,0,3,45,0,0,0,41,3,0,0,0
0,0,0,3,110,0,0,0,0,3,0,0,3,3,3,0,0,44,0,0,0,44,0,0,3,3,3,0,0,3,0,0,0,0,0,3,0,0,0
0,0,0,3,110,110,110,110,110,3,0,0,3,3,3,0,0,3,0,0,0,3,0,0,3,3,3,0,0,3,0,0,44,0,0,3,0,0,0
0,0,0,3,3,3,3,3,3,3,3,3,3,3,3,3,0,0,0,0,0,0,0,3,3,3,3,3,3,3,3,3,3,3,3,3,0,0,0
0,0,0,0,0,0,3,3,3,3,46,0,0,0,0,41,3,45,0,0,0,41,3,46,0,0,0,0,41,3,3,3,3,0,0,0,0,0,0
0,0,0,0,0,0,3,3,3,3,0,0,0,0,0,0,3,3,0,0,0,3,3,0,0,0,0,0,0,3,3,3,3,0,0,0,0,0,0
0,0,0,0,0,0,3,3,3,3,0,0,0,0,0,0,3,3,0,0,0,3,3,0,0,0,0,0,0,3,3,3,3,0,0,0,0,0,0
0,0,0,0,0,0,3,3,3,3,0,0,0,0,0,0,3,3,0,0,0,3,3,0,0,0,0,0,0,3,3,3,3,0,0,0,0,0,0
0,0,0,0,0,0,3,3,3,3,0,0,0,0,0,0,3,0,0,0,0,0,3,0,0,0,0,0,44,3,3,3,3,0,0,0,0,0,0
0,0,0,0,0,0,3,3,3,3,3,45,0,0,0,44,3,45,0,0,0,41,3,45,0,0,0,0,3,3,3,3,3,0,0,0,0,0,0
0,0,0,0,0,0,0,3,3,3,3,3,3,3,3,3,3,3,0,0,0,3,3,3,3,3,3,3,3,3,3,3,0,0,0,0,0,0,0
0,0,0,0,0,0,0,0,3,3,3,3,3,3,3,3,3,0,0,0,0,0,3,3,3,3,3,3,3,3,3,0,0,0,0,0,0,0,0
0,0,0,0,0,0,0,0,0,3,3,3,3,3,3,3,3,0,0,0,0,0,3,3,3,3,3,3,3,3,0,0,0,0,0,0,0,0,0
0,0,0,0,0,0,0,0,0,0,3,3,3,3,3,3,3,45,0,0,0,41,3,3,3,3,3,3,3,0,0,0,0,0,0,0,0,0,0
0,0,0,0,0,0,0,0,0,0,0,0,0,0,0,0,3,0,0,0,0,0,3,0,0,0,0,0,0,0,0,0,0,0,0,0,0,0,0
0,0,0,0,0,0,0,0,0,0,0,0,0,0,0,0,3,0,0,0,0,0,3,0,0,0,0,0,0,0,0,0,0,0,0,0,0,0,0
0,0,0,0,0,0,0,0,0,0,0,0,0,0,0,0,3,0,0,0,0,0,3,0,0,0,0,0,0,0,0,0,0,0,0,0,0,0,0
0,0,0,0,0,0,0,0,0,0,0,0,0,0,0,3,3,0,0,0,0,0,3,3,0,0,0,0,0,0,0,0,0,0,0,0,0,0,0
0,0,0,0,0,0,0,0,0,0,0,0,0,0,0,0,3,3,3,3,3,3,3,0,0,0,0,0,0,0,0,0,0,0,0,0,0,0,0
0,0,0,0,0,0,0,0,0,0,0,0,0,0,0,0,0,77,0,0,0,77,0,0,0,0,0,0,0,0,0,0,0,0,0,0,0,0,0
0,0,0,0,0,0,0,0,0,0,0,0,0,0,0,0,0,0,0,0,0,0,0,0,0,0,0,0,0,0,0,0,0,0,0,0,0,0,0
0,0,0,0,0,0,0,0,0,0,0,0,0,0,0,0,0,0,0,0,0,0,0,0,0,0,0,0,0,0,0,0,0,0,0,0,0,0,0
0,0,0,0,0,0,0,0,0,0,0,0,0,0,0,0,0,0,0,0,0,0,0,0,0,0,0,0,0,0,0,0,0,0,0,0,0,0,0
:endlayer
layer: 10
0,0,0,0,0,0,0,0,0,0,0,0,0,0,0,0,0,0,0,0,0,0,0,0,0,0,0,0,0,0,0,0,0,0,0,0,0,0,0
0,0,0,0,0,0,0,0,0,0,0,0,0,0,0,0,0,0,0,0,0,0,0,0,0,0,0,0,0,0,0,0,0,0,0,0,0,0,0
0,0,0,0,0,0,0,0,0,0,0,0,0,0,0,0,0,0,0,0,0,0,0,0,0,0,0,0,0,0,0,0,0,0,0,0,0,0,0
0,0,0,0,0,0,0,0,0,0,0,0,0,0,0,0,3,3,3,3,3,3,3,0,0,0,0,0,0,0,0,0,0,0,0,0,0,0,0
0,0,0,0,0,0,0,0,0,0,0,0,0,0,0,0,3,3,3,3,3,3,3,0,0,0,0,0,0,0,0,0,0,0,0,0,0,0,0
0,0,0,0,0,0,0,0,0,0,3,3,3,3,3,3,3,3,3,3,3,3,3,3,3,3,3,3,3,0,0,0,0,0,0,0,0,0,0
0,0,0,0,0,0,0,0,0,3,3,3,3,3,3,3,3,3,3,3,3,3,3,3,3,3,3,3,3,3,0,0,0,0,0,0,0,0,0
0,0,0,0,0,0,0,0,3,3,3,3,3,3,3,3,3,3,3,3,3,3,3,3,3,3,3,3,3,3,3,0,0,0,0,0,0,0,0
0,0,0,0,0,0,0,3,3,3,3,3,3,3,3,3,3,3,3,3,3,3,3,3,3,3,3,3,3,3,3,3,0,0,0,0,0,0,0
0,0,0,0,0,0,3,3,3,3,3,3,3,3,3,3,3,3,3,3,3,3,3,3,3,3,3,3,3,3,3,3,3,0,0,0,0,0,0
0,0,0,0,0,3,3,3,3,3,3,142,3,3,3,143,3,3,3,3,3,3,3,0,0,0,0,0,3,3,3,3,3,3,0,0,0,0,0
0,0,0,0,0,3,3,3,3,3,0,0,0,0,0,0,3,3,3,3,3,3,3,0,0,0,0,0,0,3,3,3,3,3,0,0,0,0,0
0,0,0,0,0,3,3,3,3,3,0,0,0,0,0,0,3,3,3,3,3,3,3,0,0,0,0,0,0,3,3,3,3,3,0,0,0,0,0
0,0,0,0,0,3,3,3,3,3,0,0,0,0,0,0,3,3,3,3,3,3,3,0,0,0,0,0,0,3,3,3,3,3,0,0,0,0,0
0,0,0,0,0,3,3,3,3,3,0,0,0,0,0,0,3,3,3,3,3,3,3,0,0,0,0,0,0,3,3,3,3,3,0,0,0,0,0
0,0,0,0,0,3,3,3,3,3,0,0,0,0,0,0,3,3,0,0,0,0,3,0,0,0,0,0,0,3,3,3,3,3,0,0,0,0,0
0,0,0,3,3,3,3,3,3,3,3,3,3,3,3,3,3,3,0,0,0,0,0,3,3,3,3,3,3,3,3,3,3,3,3,3,0,0,0
0,0,0,3,3,3,3,3,3,3,3,3,3,3,3,3,3,26,0,0,0,0,0,0,3,3,3,3,3,3,3,3,3,3,3,3,0,0,0
0,0,0,3,3,3,3,3,3,3,3,3,3,3,3,3,3,26,0,0,0,0,0,0,3,3,3,3,3,3,3,3,3,3,3,3,0,0,0
0,0,0,3,3,3,3,3,3,3,3,3,3,3,3,0,0,0,0,0,0,0,0,0,3,3,3,3,3,3,3,3,3,3,3,3,0,0,0
0,0,0,3,3,3,3,3,3,3,3,3,3,3,3,0,0,0,0,0,0,0,0,0,3,3,3,3,3,3,3,3,3,3,3,3,0,0,0
0,0,0,3,3,3,3,3,3,3,3,3,3,3,3,0,0,3,0,0,0,3,0,0,3,3,3,3,3,3,3,3,3,3,3,3,0,0,0
0,0,0,3,3,3,3,3,3,3,3,3,3,3,3,3,0,0,0,0,0,0,0,3,3,3,3,3,3,3,3,3,3,3,3,3,0,0,0
0,0,0,0,0,3,3,3,3,3,0,0,0,0,0,0,3,0,0,0,0,0,3,0,0,0,0,0,0,3,3,3,3,3,0,0,0,0,0
0,0,0,0,0,3,3,3,3,3,0,0,0,0,0,0,3,3,3,3,3,3,3,0,0,0,0,0,0,3,3,3,3,3,0,0,0,0,0
0,0,0,0,0,3,3,3,3,3,0,0,0,0,0,0,3,3,3,3,3,3,3,0,0,0,0,0,0,3,3,3,3,3,0,0,0,0,0
0,0,0,0,0,3,3,3,3,3,0,0,0,0,0,0,3,3,3,3,3,3,3,0,0,0,0,0,0,3,3,3,3,3,0,0,0,0,0
0,0,0,0,0,3,3,3,3,3,0,0,0,0,0,0,3,3,3,3,3,3,3,0,0,0,0,0,0,3,3,3,3,3,0,0,0,0,0
0,0,0,0,0,3,3,3,3,3,3,0,0,0,0,0,3,3,3,3,3,3,3,0,0,0,0,0,3,3,3,3,3,3,0,0,0,0,0
0,0,0,0,0,0,3,3,3,3,3,3,3,3,3,3,3,3,3,3,3,3,3,3,3,3,3,3,3,3,3,3,3,0,0,0,0,0,0
0,0,0,0,0,0,0,3,3,3,3,3,3,3,3,3,3,3,3,3,3,3,3,3,3,3,3,3,3,3,3,3,0,0,0,0,0,0,0
0,0,0,0,0,0,0,0,3,3,3,3,3,3,3,3,3,3,3,3,3,3,3,3,3,3,3,3,3,3,3,0,0,0,0,0,0,0,0
0,0,0,0,0,0,0,0,0,3,3,3,3,3,3,3,3,3,3,3,3,3,3,3,3,3,3,3,3,3,0,0,0,0,0,0,0,0,0
0,0,0,0,0,0,0,0,0,0,3,3,3,3,3,3,3,3,3,3,3,3,3,3,3,3,3,3,3,0,0,0,0,0,0,0,0,0,0
0,0,0,0,0,0,0,0,0,0,0,0,0,0,0,0,3,3,3,3,3,3,3,0,0,0,0,0,0,0,0,0,0,0,0,0,0,0,0
0,0,0,0,0,0,0,0,0,0,0,0,0,0,0,0,3,3,3,3,3,3,3,0,0,0,0,0,0,0,0,0,0,0,0,0,0,0,0
0,0,0,0,0,0,0,0,0,0,0,0,0,0,0,24,3,3,3,3,3,3,3,26,0,0,0,0,0,0,0,0,0,0,0,0,0,0,0
0,0,0,0,0,0,0,0,0,0,0,0,0,0,0,0,3,3,3,3,3,3,3,0,0,0,0,0,0,0,0,0,0,0,0,0,0,0,0
0,0,0,0,0,0,0,0,0,0,0,0,0,0,0,0,0,86,0,144,0,86,0,0,0,0,0,0,0,0,0,0,0,0,0,0,0,0,0
0,0,0,0,0,0,0,0,0,0,0,0,0,0,0,0,0,0,0,0,0,0,0,0,0,0,0,0,0,0,0,0,0,0,0,0,0,0,0
0,0,0,0,0,0,0,0,0,0,0,0,0,0,0,0,0,0,0,0,0,0,0,0,0,0,0,0,0,0,0,0,0,0,0,0,0,0,0
0,0,0,0,0,0,0,0,0,0,0,0,0,0,0,0,0,0,0,0,0,0,0,0,0,0,0,0,0,0,0,0,0,0,0,0,0,0,0
:endlayer
layer: 11
0,0,0,0,0,0,0,0,0,0,0,0,0,0,0,0,0,0,0,0,0,0,0,0,0,0,0,0,0,0,0,0,0,0,0,0,0,0,0
0,0,0,0,0,0,0,0,0,0,0,0,0,0,0,0,0,0,0,0,0,0,0,0,0,0,0,0,0,0,0,0,0,0,0,0,0,0,0
0,0,0,0,0,0,0,0,0,0,0,0,0,0,0,0,0,0,0,0,0,0,0,0,0,0,0,0,0,0,0,0,0,0,0,0,0,0,0
0,0,0,0,0,0,0,0,0,0,0,0,0,0,0,0,3,3,3,3,3,3,3,0,0,0,0,0,0,0,0,0,0,0,0,0,0,0,0
0,0,0,0,0,0,0,0,0,0,0,0,0,0,0,0,3,0,0,0,0,0,3,0,0,0,0,0,0,0,0,0,0,0,0,0,0,0,0
0,0,0,0,0,0,0,0,0,0,3,3,3,3,3,3,3,0,0,0,0,0,3,3,3,3,3,3,3,0,0,0,0,0,0,0,0,0,0
0,0,0,0,0,0,0,0,0,3,145,145,145,145,145,145,3,0,0,146,0,0,3,145,145,145,145,145,145,3,0,0,0,0,0,0,0,0,0
0,0,0,0,0,0,0,0,3,145,0,0,0,0,0,0,0,0,0,0,0,0,0,0,0,0,0,0,0,145,3,0,0,0,0,0,0,0,0
0,0,0,0,0,0,0,3,145,0,0,0,0,0,0,0,3,0,0,0,0,0,3,0,0,0,0,0,0,0,145,3,0,0,0,0,0,0,0
0,0,0,0,0,0,3,145,0,0,0,3,3,3,3,3,3,0,0,147,0,0,3,3,3,3,3,3,0,0,0,145,3,0,0,0,0,0,0
0,0,0,0,0,3,145,0,0,0,3,3,3,3,3,3,3,0,0,0,0,0,3,3,3,3,3,3,3,0,0,0,145,3,0,0,0,0,0
0,0,0,0,0,3,145,0,0,3,3,3,3,3,3,3,26,0,0,0,0,0,24,3,3,3,3,3,3,3,0,0,145,3,0,0,0,0,0
0,0,0,0,0,3,145,0,0,3,3,3,3,3,3,3,3,0,3,3,3,3,3,3,3,3,3,3,3,3,0,0,145,3,0,0,0,0,0
0,0,0,0,0,3,145,0,0,3,3,3,3,3,3,3,3,0,3,3,3,3,3,3,3,3,3,3,3,3,0,0,145,3,0,0,0,0,0
0,0,0,0,0,3,145,0,0,3,3,3,3,3,3,3,3,148,3,3,3,3,3,3,3,3,3,3,3,3,0,0,145,3,0,0,0,0,0
0,0,0,0,0,3,145,0,0,3,3,3,3,3,3,3,3,3,3,3,3,3,3,3,3,3,3,3,3,3,0,0,145,3,0,0,0,0,0
0,0,0,3,3,3,3,0,3,3,3,64,3,3,3,3,3,3,3,3,3,3,3,3,3,3,3,64,3,3,3,0,3,3,3,3,0,0,0
0,0,0,3,0,0,0,0,0,0,0,0,3,3,3,3,26,0,0,0,3,3,3,3,26,0,0,0,0,0,0,0,0,0,0,3,0,0,0
0,0,0,3,0,0,0,0,0,0,0,0,3,3,3,3,26,0,0,0,3,3,3,3,3,3,3,0,0,0,0,0,149,0,0,3,0,0,0
0,0,0,3,0,0,150,0,0,151,0,0,3,3,3,3,3,3,3,3,3,3,3,3,3,3,3,0,0,152,0,0,0,0,0,3,0,0,0
0,0,0,3,0,0,0,0,0,0,0,0,3,3,3,3,3,3,3,3,3,3,3,3,3,3,3,0,0,0,0,0,0,0,0,3,0,0,0
0,0,0,3,0,0,0,0,0,0,0,0,0,0,24,3,3,3,3,3,3,3,3,3,3,3,3,0,0,0,0,0,0,0,0,3,0,0,0
0,0,0,3,3,3,3,0,3,3,3,148,3,3,3,3,3,3,3,3,3,3,3,3,3,3,3,148,3,3,3,0,3,3,3,3,0,0,0
0,0,0,0,0,3,145,0,0,3,3,3,3,3,3,3,3,3,3,3,3,3,3,3,3,3,3,3,3,3,0,0,145,3,0,0,0,0,0
0,0,0,0,0,3,145,0,0,3,3,3,3,3,3,3,3,64,3,3,3,3,3,3,3,3,3,3,3,3,0,0,145,3,0,0,0,0,0
0,0,0,0,0,3,145,0,0,3,3,3,3,3,3,3,3,0,3,3,3,3,3,3,3,3,3,3,3,3,0,0,145,3,0,0,0,0,0
0,0,0,0,0,3,145,0,0,3,3,3,3,3,3,3,3,0,3,3,3,3,3,3,3,3,3,3,3,3,0,0,145,3,0,0,0,0,0
0,0,0,0,0,3,145,0,0,3,3,3,3,3,3,3,26,0,0,0,0,0,24,3,3,3,3,3,3,3,0,0,145,3,0,0,0,0,0
0,0,0,0,0,3,145,0,0,0,3,3,3,3,3,3,3,0,0,0,0,0,3,3,3,3,3,3,3,0,0,0,145,3,0,0,0,0,0
0,0,0,0,0,0,3,145,0,0,0,3,3,3,3,3,3,0,0,153,0,0,3,3,3,3,3,3,0,0,0,145,3,0,0,0,0,0,0
0,0,0,0,0,0,0,3,145,0,0,0,0,0,0,0,3,0,0,0,0,0,3,0,0,0,0,0,0,0,145,3,0,0,0,0,0,0,0
0,0,0,0,0,0,0,0,3,145,0,0,0,0,0,0,0,0,0,0,0,0,0,0,0,0,0,0,0,145,3,0,0,0,0,0,0,0,0
0,0,0,0,0,0,0,0,0,3,145,145,145,145,145,145,3,0,0,0,0,0,3,145,145,145,145,145,145,3,0,0,0,0,0,0,0,0,0
0,0,0,0,0,0,0,0,0,0,3,3,3,3,3,3,3,0,0,154,0,0,3,3,3,3,3,3,3,0,0,0,0,0,0,0,0,0,0
0,0,0,0,0,0,0,0,0,0,0,0,0,0,0,0,3,0,0,0,0,0,3,0,0,0,0,0,0,0,0,0,0,0,0,0,0,0,0
0,0,0,0,0,0,0,0,0,0,0,0,0,0,0,0,3,3,3,0,3,3,3,0,0,0,0,0,0,0,0,0,0,0,0,0,0,0,0
0,0,0,0,0,0,0,0,0,0,0,0,0,0,0,0,3,145,0,0,0,145,3,0,0,0,0,0,0,0,0,0,0,0,0,0,0,0,0
0,0,0,0,0,0,0,0,0,0,0,0,0,0,0,0,3,3,3,3,3,3,3,0,0,0,0,0,0,0,0,0,0,0,0,0,0,0,0
0,0,0,0,0,0,0,0,0,0,0,0,0,0,0,0,0,0,0,0,0,0,0,0,0,0,0,0,0,0,0,0,0,0,0,0,0,0,0
0,0,0,0,0,0,0,0,0,0,0,0,0,0,0,0,0,0,0,0,0,0,0,0,0,0,0,0,0,0,0,0,0,0,0,0,0,0,0
0,0,0,0,0,0,0,0,0,0,0,0,0,0,0,0,0,0,0,0,0,0,0,0,0,0,0,0,0,0,0,0,0,0,0,0,0,0,0
0,0,0,0,0,0,0,0,0,0,0,0,0,0,0,0,0,0,0,0,0,0,0,0,0,0,0,0,0,0,0,0,0,0,0,0,0,0,0
:endlayer
layer: 12
0,0,0,0,0,0,0,0,0,0,0,0,0,0,0,0,0,0,0,0,0,0,0,0,0,0,0,0,0,0,0,0,0,0,0,0,0,0,0
0,0,0,0,0,0,0,0,0,0,0,0,0,0,0,0,0,0,0,0,0,0,0,0,0,0,0,0,0,0,0,0,0,0,0,0,0,0,0
0,0,0,0,0,0,0,0,0,0,0,0,0,0,0,0,0,0,0,0,0,0,0,0,0,0,0,0,0,0,0,0,0,0,0,0,0,0,0
0,0,0,0,0,0,0,0,0,0,0,0,0,0,0,0,3,3,3,0,3,3,3,0,0,0,0,0,0,0,0,0,0,0,0,0,0,0,0
0,0,0,0,0,0,0,0,0,0,0,0,0,0,0,0,3,0,0,0,0,0,3,0,0,0,0,0,0,0,0,0,0,0,0,0,0,0,0
0,0,0,0,0,0,0,0,0,0,86,0,0,0,0,0,3,0,0,0,0,0,3,0,0,0,0,0,86,0,0,0,0,0,0,0,0,0,0
0,0,0,0,0,0,0,0,0,0,0,0,155,0,0,0,3,0,0,0,0,0,3,0,0,156,0,0,0,0,0,0,0,0,0,0,0,0,0
0,0,0,0,0,0,0,0,0,0,0,0,0,0,0,0,0,0,0,0,0,0,0,0,0,0,0,0,0,0,0,0,0,0,0,0,0,0,0
0,0,0,0,0,0,0,0,157,0,0,0,0,0,0,0,3,0,0,0,0,0,3,0,0,0,0,0,0,0,158,0,0,0,0,0,0,0,0
0,0,0,0,0,0,0,0,0,0,0,3,3,3,3,3,3,0,0,0,0,0,3,3,3,3,3,3,0,0,0,0,0,0,0,0,0,0,0
0,0,0,0,0,86,0,0,0,0,3,3,3,3,3,3,3,0,0,0,0,0,3,3,3,3,3,3,3,0,0,0,0,86,0,0,0,0,0
0,0,0,0,0,0,0,0,0,3,3,3,3,3,3,26,0,0,0,0,0,0,0,24,3,3,3,3,3,3,0,0,0,0,0,0,0,0,0
0,0,0,0,0,0,159,0,0,3,3,3,3,3,3,3,3,0,3,3,3,3,3,3,3,3,3,3,3,3,0,0,160,0,0,0,0,0,0
0,0,0,0,0,0,0,0,0,3,3,3,3,3,3,3,3,0,3,3,3,3,3,3,3,3,3,3,3,3,0,0,0,0,0,0,0,0,0
0,0,0,0,0,0,0,0,0,3,3,3,3,3,3,3,3,0,3,64,3,3,3,3,3,3,3,3,3,3,0,0,0,0,0,0,0,0,0
0,0,0,0,0,0,0,0,0,3,3,64,3,3,3,3,0,0,0,0,0,0,0,3,3,3,3,64,3,3,0,0,0,0,0,0,0,0,0
0,0,0,3,3,3,3,0,3,3,3,0,3,3,3,0,0,0,0,0,0,0,0,0,3,3,3,0,3,3,3,0,3,3,3,3,0,0,0
0,0,0,3,0,0,0,0,0,0,0,0,3,3,3,0,0,0,0,0,0,0,0,0,0,0,0,0,0,0,0,0,0,0,0,3,0,0,0
0,0,0,3,0,0,0,0,0,0,0,0,3,3,3,0,0,0,0,0,0,0,0,0,3,3,3,0,0,0,0,0,0,0,0,3,0,0,0
0,0,0,0,0,0,0,0,0,0,0,0,3,3,26,0,0,24,3,3,161,3,0,0,24,3,3,0,0,0,0,0,0,0,0,0,0,0,0
0,0,0,3,0,0,0,0,0,0,0,0,3,3,3,0,0,24,3,3,162,3,0,0,3,3,3,0,0,0,0,0,0,0,0,3,0,0,0
0,0,0,3,0,0,0,0,0,0,0,0,0,0,0,0,0,0,0,0,0,0,0,0,3,3,3,0,0,0,0,0,0,0,0,3,0,0,0
0,0,0,3,3,3,3,0,3,3,3,0,3,3,3,0,0,0,0,0,0,0,0,0,3,3,3,0,3,3,3,0,3,3,3,3,0,0,0
0,0,0,0,0,0,0,0,0,3,3,148,3,3,3,3,0,0,0,0,0,0,0,3,3,3,3,148,3,3,0,0,0,0,0,0,0,0,0
0,0,0,0,0,0,0,0,0,3,3,3,3,3,3,3,3,0,3,148,3,3,3,3,3,3,3,3,3,3,0,0,0,0,0,0,0,0,0
0,0,0,0,0,0,0,0,0,3,3,3,3,3,3,3,3,0,3,3,3,3,3,3,3,3,3,3,3,3,0,0,163,0,0,0,0,0,0
0,0,0,0,0,0,164,0,0,3,3,3,3,3,3,3,3,0,3,3,3,3,3,3,3,3,3,3,3,3,0,0,0,0,0,0,0,0,0
0,0,0,0,0,0,0,0,0,3,3,3,3,3,3,26,0,0,0,0,0,0,0,24,3,3,3,3,3,3,0,0,0,0,0,0,0,0,0
0,0,0,0,0,86,0,0,0,0,3,3,3,3,3,3,3,0,0,0,0,0,3,3,3,3,3,3,3,0,0,0,0,86,0,0,0,0,0
0,0,0,0,0,0,0,0,0,0,0,3,3,3,3,3,3,0,0,0,0,0,3,3,3,3,3,3,0,0,0,0,0,0,0,0,0,0,0
0,0,0,0,0,0,0,0,165,0,0,0,0,0,0,0,3,0,0,0,0,0,3,0,0,0,0,0,0,0,166,0,0,0,0,0,0,0,0
0,0,0,0,0,0,0,0,0,0,0,0,0,0,0,0,0,0,0,0,0,0,0,0,0,0,0,0,0,0,0,0,0,0,0,0,0,0,0
0,0,0,0,0,0,0,0,0,0,0,0,0,167,0,0,3,0,0,0,0,0,3,0,0,0,168,0,0,0,0,0,0,0,0,0,0,0,0
0,0,0,0,0,0,0,0,0,0,86,0,0,0,0,0,3,0,0,0,0,0,3,0,0,0,0,0,86,0,0,0,0,0,0,0,0,0,0
0,0,0,0,0,0,0,0,0,0,0,0,0,0,0,0,3,0,0,0,0,0,3,0,0,0,0,0,0,0,0,0,0,0,0,0,0,0,0
0,0,0,0,0,0,0,0,0,0,0,0,0,0,0,0,3,3,3,0,3,3,3,0,0,0,0,0,0,0,0,0,0,0,0,0,0,0,0
0,0,0,0,0,0,0,0,0,0,0,0,0,0,0,0,0,169,0,0,0,170,0,0,0,0,0,0,0,0,0,0,0,0,0,0,0,0,0
0,0,0,0,0,0,0,0,0,0,0,0,0,0,0,0,3,0,0,0,0,0,3,0,0,0,0,0,0,0,0,0,0,0,0,0,0,0,0
0,0,0,0,0,0,0,0,0,0,0,0,0,0,0,0,0,0,0,0,0,0,0,0,0,0,0,0,0,0,0,0,0,0,0,0,0,0,0
0,0,0,0,0,0,0,0,0,0,0,0,0,0,0,0,0,0,0,0,0,0,0,0,0,0,0,0,0,0,0,0,0,0,0,0,0,0,0
0,0,0,0,0,0,0,0,0,0,0,0,0,0,0,0,0,0,0,0,0,0,0,0,0,0,0,0,0,0,0,0,0,0,0,0,0,0,0
0,0,0,0,0,0,0,0,0,0,0,0,0,0,0,0,0,0,0,0,0,0,0,0,0,0,0,0,0,0,0,0,0,0,0,0,0,0,0
:endlayer
layer: 13
0,0,0,0,0,0,0,0,0,0,0,0,0,0,0,0,0,0,0,0,0,0,0,0,0,0,0,0,0,0,0,0,0,0,0,0,0,0,0
0,0,0,0,0,0,0,0,0,0,0,0,0,0,0,0,0,0,0,0,0,0,0,0,0,0,0,0,0,0,0,0,0,0,0,0,0,0,0
0,0,0,0,0,0,0,0,0,0,0,0,0,0,0,0,0,0,0,0,0,0,0,0,0,0,0,0,0,0,0,0,0,0,0,0,0,0,0
0,0,0,0,0,0,0,0,0,0,0,0,0,0,0,0,3,3,3,3,3,3,3,0,0,0,0,0,0,0,0,0,0,0,0,0,0,0,0
0,0,0,0,0,0,0,0,0,0,0,0,0,0,0,0,3,0,0,46,0,0,3,0,0,0,0,0,0,0,0,0,0,0,0,0,0,0,0
0,0,0,0,0,0,0,0,0,0,0,0,0,0,0,0,3,0,0,0,0,0,3,0,0,0,0,0,0,0,0,0,0,0,0,0,0,0,0
0,0,0,0,0,0,0,0,0,0,0,0,0,0,0,0,3,0,0,0,0,0,3,0,0,0,0,0,0,0,0,0,0,0,0,0,0,0,0
0,0,0,0,0,0,0,0,0,0,0,0,0,0,0,41,3,45,0,0,0,41,3,45,0,0,0,0,0,0,0,0,0,0,0,0,0,0,0
0,0,0,0,0,0,0,0,0,0,0,0,0,0,0,0,3,0,0,0,0,0,3,0,0,0,0,0,0,0,0,0,0,0,0,0,0,0,0
0,0,0,0,0,0,0,0,0,0,44,3,3,3,3,3,3,0,0,0,0,0,3,3,3,3,3,3,44,0,0,0,0,0,0,0,0,0,0
0,0,0,0,0,0,0,0,0,41,3,3,3,3,3,3,3,0,0,0,0,0,3,3,3,3,3,3,3,45,0,0,0,0,0,0,0,0,0
0,0,0,0,0,0,0,0,0,3,3,3,3,3,26,0,0,0,0,44,0,0,0,0,24,3,3,3,3,3,0,0,0,0,0,0,0,0,0
0,0,0,0,0,0,0,0,0,3,3,3,3,3,3,3,3,3,3,3,3,3,3,3,3,3,3,3,3,3,0,0,0,0,0,0,0,0,0
0,0,0,0,0,0,0,0,0,3,3,3,3,3,3,3,3,46,3,64,3,3,3,3,3,3,3,3,3,3,0,0,0,0,0,0,0,0,0
0,0,0,0,0,0,0,0,0,3,3,64,3,3,3,3,3,0,3,0,3,3,3,3,3,3,3,64,3,3,0,0,0,0,0,0,0,0,0
0,0,0,0,0,0,0,0,0,3,3,0,3,3,3,3,0,0,0,0,0,0,0,3,3,3,3,0,3,3,0,44,0,0,0,0,0,0,0
0,0,0,3,3,3,3,3,3,3,3,0,3,3,3,0,0,0,0,0,0,0,0,0,3,3,3,0,3,3,3,3,3,3,3,3,0,0,0
0,0,0,3,0,0,0,46,0,0,0,0,3,3,3,0,0,0,0,0,0,0,0,0,0,41,3,0,0,0,0,46,0,0,0,3,0,0,0
0,0,0,3,0,0,0,0,0,0,0,0,3,3,3,0,0,0,0,0,0,0,0,0,3,3,3,0,0,0,0,0,0,0,0,3,0,0,0
0,0,0,3,45,0,0,0,0,0,0,41,3,26,0,0,0,0,24,3,0,3,0,0,0,24,3,45,0,0,0,0,0,0,41,3,0,0,0
0,0,0,3,0,0,0,0,0,0,0,0,3,3,3,0,0,0,24,3,0,3,0,0,3,3,3,0,0,0,0,0,0,0,0,3,0,0,0
0,0,0,3,0,0,0,44,0,0,0,0,3,45,0,0,0,0,0,0,0,0,0,0,3,3,3,0,0,0,0,44,0,0,0,3,0,0,0
0,0,0,3,3,3,3,3,3,3,3,0,3,3,3,0,0,0,0,0,0,0,0,0,3,3,3,0,3,3,3,3,3,3,3,3,0,0,0
0,0,0,0,0,0,0,46,0,3,3,0,3,3,3,3,0,0,0,0,0,0,0,3,3,3,3,0,3,3,0,46,0,0,0,0,0,0,0
0,0,0,0,0,0,0,0,0,3,3,148,3,3,3,3,3,0,3,0,3,3,3,3,3,3,3,148,3,3,0,0,0,0,0,0,0,0,0
0,0,0,0,0,0,0,0,0,3,3,3,3,3,3,3,3,44,3,148,3,3,3,3,3,3,3,3,3,3,0,0,0,0,0,0,0,0,0
0,0,0,0,0,0,0,0,0,3,3,3,3,3,3,3,3,3,3,3,3,3,3,3,3,3,3,3,3,3,0,0,0,0,0,0,0,0,0
0,0,0,0,0,0,0,0,0,3,3,3,3,3,26,0,0,0,0,46,0,0,0,0,24,3,3,3,3,3,0,0,0,0,0,0,0,0,0
0,0,0,0,0,0,0,0,0,41,3,3,3,3,3,3,3,0,0,0,0,0,3,3,3,3,3,3,3,45,0,0,0,0,0,0,0,0,0
0,0,0,0,0,0,0,0,0,0,46,3,3,3,3,3,3,0,0,0,0,0,3,3,3,3,3,3,46,0,0,0,0,0,0,0,0,0,0
0,0,0,0,0,0,0,0,0,0,0,0,0,0,0,0,3,0,0,0,0,0,3,0,0,0,0,0,0,0,0,0,0,0,0,0,0,0,0
0,0,0,0,0,0,0,0,0,0,0,0,0,0,0,41,3,45,0,0,0,0,3,45,0,0,0,0,0,0,0,0,0,0,0,0,0,0,0
0,0,0,0,0,0,0,0,0,0,0,0,0,0,0,0,3,0,0,0,0,41,3,0,0,0,0,0,0,0,0,0,0,0,0,0,0,0,0
0,0,0,0,0,0,0,0,0,0,0,0,0,0,0,0,3,0,0,0,0,0,3,0,0,0,0,0,0,0,0,0,0,0,0,0,0,0,0
0,0,0,0,0,0,0,0,0,0,0,0,0,0,0,0,3,0,0,44,0,0,3,0,0,0,0,0,0,0,0,0,0,0,0,0,0,0,0
0,0,0,0,0,0,0,0,0,0,0,0,0,0,0,0,3,3,3,3,3,3,3,0,0,0,0,0,0,0,0,0,0,0,0,0,0,0,0
0,0,0,0,0,0,0,0,0,0,0,0,0,0,0,0,0,0,46,0,46,0,0,0,0,0,0,0,0,0,0,0,0,0,0,0,0,0,0
0,0,0,0,0,0,0,0,0,0,0,0,0,0,0,0,3,0,0,0,0,0,3,0,0,0,0,0,0,0,0,0,0,0,0,0,0,0,0
0,0,0,0,0,0,0,0,0,0,0,0,0,0,0,0,0,0,0,0,0,0,0,0,0,0,0,0,0,0,0,0,0,0,0,0,0,0,0
0,0,0,0,0,0,0,0,0,0,0,0,0,0,0,0,0,0,0,0,0,0,0,0,0,0,0,0,0,0,0,0,0,0,0,0,0,0,0
0,0,0,0,0,0,0,0,0,0,0,0,0,0,0,0,0,0,0,0,0,0,0,0,0,0,0,0,0,0,0,0,0,0,0,0,0,0,0
0,0,0,0,0,0,0,0,0,0,0,0,0,0,0,0,0,0,0,0,0,0,0,0,0,0,0,0,0,0,0,0,0,0,0,0,0,0,0
:endlayer
layer: 14
0,0,0,0,0,0,0,0,0,0,0,0,0,0,0,0,0,0,0,0,0,0,0,0,0,0,0,0,0,0,0,0,0,0,0,0,0,0,0
0,0,0,0,0,0,0,0,0,0,0,0,0,0,0,0,0,0,0,0,0,0,0,0,0,0,0,0,0,0,0,0,0,0,0,0,0,0,0
0,0,0,0,0,0,0,0,0,0,0,0,0,0,0,0,0,0,0,0,0,0,0,0,0,0,0,0,0,0,0,0,0,0,0,0,0,0,0
0,0,0,0,0,0,0,0,0,0,0,0,0,0,0,0,3,3,3,3,3,3,3,0,0,0,0,0,0,0,0,0,0,0,0,0,0,0,0
0,0,0,0,0,0,0,0,0,0,0,0,0,0,0,0,3,3,3,3,3,3,3,0,0,0,0,0,0,0,0,0,0,0,0,0,0,0,0
0,0,0,0,0,0,0,0,0,0,0,0,0,0,0,0,3,3,3,3,3,3,3,0,0,0,0,0,0,0,0,0,0,0,0,0,0,0,0
0,0,0,0,0,0,0,0,0,0,0,0,0,0,0,0,3,3,3,3,3,3,3,0,0,0,0,0,0,0,0,0,0,0,0,0,0,0,0
0,0,0,0,0,0,0,0,0,0,0,0,0,0,0,0,3,3,3,3,3,3,3,0,0,0,0,0,0,0,0,0,0,0,0,0,0,0,0
0,0,0,0,0,0,0,0,0,0,0,3,3,3,3,3,3,3,3,3,3,3,3,3,3,3,3,3,0,0,0,0,0,0,0,0,0,0,0
0,0,0,0,0,0,0,0,0,0,3,3,145,145,145,145,3,3,3,3,3,3,3,145,145,145,145,3,3,0,0,0,0,0,0,0,0,0,0
0,0,0,0,0,0,0,0,0,3,3,3,0,0,0,0,3,3,3,3,3,3,3,0,0,0,0,3,3,3,0,0,0,0,0,0,0,0,0
0,0,0,0,0,0,0,0,3,3,3,145,0,0,0,0,41,3,3,3,3,3,45,0,0,0,0,145,3,3,3,0,0,0,0,0,0,0,0
0,0,0,0,0,0,0,0,3,145,0,0,171,0,0,0,3,3,3,64,3,3,3,0,0,0,172,0,0,145,3,0,0,0,0,0,0,0,0
0,0,0,0,0,0,0,0,3,145,0,0,0,0,0,0,3,3,3,0,3,3,3,0,0,0,0,0,0,145,3,0,0,0,0,0,0,0,0
0,0,0,0,0,0,0,0,3,145,0,0,0,0,0,0,3,3,3,0,3,3,3,0,0,0,0,0,0,145,3,0,0,0,0,0,0,0,0
0,0,0,0,0,0,0,0,3,145,0,0,0,0,0,0,3,0,46,0,46,0,3,0,0,0,0,0,0,145,3,0,0,0,0,0,0,0,0
0,0,0,3,3,3,3,3,3,3,3,44,3,3,3,3,0,0,0,0,0,0,0,3,3,3,3,44,3,3,3,3,3,3,3,3,0,0,0
0,0,0,3,3,3,3,3,3,3,3,3,3,3,3,0,0,0,0,0,0,0,0,0,3,3,3,3,3,3,3,3,3,3,3,3,0,0,0
0,0,0,3,3,3,3,3,3,3,3,3,3,3,3,45,0,0,0,0,0,0,0,41,3,3,3,3,3,3,3,3,3,3,3,3,0,0,0
0,0,0,3,3,3,3,3,3,3,3,3,26,0,0,0,0,0,0,24,3,3,0,0,0,0,24,3,3,3,3,3,3,3,3,3,0,0,0
0,0,0,3,3,3,3,3,3,3,3,3,3,3,3,45,0,0,0,24,3,3,0,41,3,3,3,3,3,3,3,3,3,3,3,3,0,0,0
0,0,0,3,3,3,3,3,3,3,3,0,3,3,55,0,0,0,0,0,0,0,0,0,3,3,3,0,3,3,3,3,3,3,3,3,0,0,0
0,0,0,3,3,3,3,3,3,3,3,0,3,3,3,3,0,0,0,0,0,0,0,3,3,3,3,0,3,3,3,3,3,3,3,3,0,0,0
0,0,0,0,0,0,0,0,3,145,0,0,0,0,0,0,3,0,44,0,44,0,3,0,0,0,0,0,0,145,3,0,0,0,0,0,0,0,0
0,0,0,0,0,0,0,0,3,145,0,0,0,0,0,0,3,3,3,0,3,3,3,0,0,0,0,0,0,145,3,0,0,0,0,0,0,0,0
0,0,0,0,0,0,0,0,3,145,0,0,0,0,0,0,3,3,3,0,3,3,3,0,0,0,0,0,0,145,3,0,0,0,0,0,0,0,0
0,0,0,0,0,0,0,0,3,145,0,0,173,0,0,0,3,3,3,148,3,3,3,0,0,0,174,0,0,145,3,0,0,0,0,0,0,0,0
0,0,0,0,0,0,0,0,3,3,3,145,0,0,0,0,0,0,3,3,3,45,0,0,0,0,0,145,3,3,3,0,0,0,0,0,0,0,0
0,0,0,0,0,0,0,0,0,3,3,3,0,0,0,0,3,3,3,3,3,3,3,0,0,0,0,3,3,3,0,0,0,0,0,0,0,0,0
0,0,0,0,0,0,0,0,0,0,3,3,145,145,145,145,3,3,3,3,3,3,3,145,145,145,145,3,3,0,0,0,0,0,0,0,0,0,0
0,0,0,0,0,0,0,0,0,0,0,3,3,3,3,3,3,3,3,3,3,3,3,3,3,3,3,3,0,0,0,0,0,0,0,0,0,0,0
0,0,0,0,0,0,0,0,0,0,0,0,0,0,0,175,3,3,3,3,3,3,3,176,0,0,0,0,0,0,0,0,0,0,0,0,0,0,0
0,0,0,0,0,0,0,0,0,0,0,0,0,0,0,175,3,3,3,3,3,3,3,176,0,0,0,0,0,0,0,0,0,0,0,0,0,0,0
0,0,0,0,0,0,0,0,0,0,0,0,0,0,0,175,3,3,3,3,3,3,3,176,0,0,0,0,0,0,0,0,0,0,0,0,0,0,0
0,0,0,0,0,0,0,0,0,0,0,0,0,0,0,175,3,3,3,3,3,3,3,176,0,0,0,0,0,0,0,0,0,0,0,0,0,0,0
0,0,0,0,0,0,0,0,0,0,0,0,0,0,0,175,3,3,3,3,3,3,3,176,0,0,0,0,0,0,0,0,0,0,0,0,0,0,0
0,0,0,0,0,0,0,0,0,0,0,0,0,0,0,175,177,0,0,0,0,0,177,176,0,0,0,0,0,0,0,0,0,0,0,0,0,0,0
0,0,0,0,0,0,0,0,0,0,0,0,0,0,0,175,177,177,177,177,177,177,177,176,0,0,0,0,0,0,0,0,0,0,0,0,0,0,0
0,0,0,0,0,0,0,0,0,0,0,0,0,0,0,178,178,178,178,178,178,178,178,176,0,0,0,0,0,0,0,0,0,0,0,0,0,0,0
0,0,0,0,0,0,0,0,0,0,0,0,0,0,0,0,0,0,0,0,0,0,0,0,0,0,0,0,0,0,0,0,0,0,0,0,0,0,0
0,0,0,0,0,0,0,0,0,0,0,0,0,0,0,0,0,0,0,0,0,0,0,0,0,0,0,0,0,0,0,0,0,0,0,0,0,0,0
0,0,0,0,0,0,0,0,0,0,0,0,0,0,0,0,0,0,0,0,0,0,0,0,0,0,0,0,0,0,0,0,0,0,0,0,0,0,0
:endlayer
layer: 15
0,0,0,0,0,0,0,0,0,0,0,0,0,0,0,0,0,0,0,0,0,0,0,0,0,0,0,0,0,0,0,0,0,0,0,0,0,0,0
0,0,0,0,0,0,0,0,0,0,0,0,0,0,0,0,0,0,0,0,0,0,0,0,0,0,0,0,0,0,0,0,0,0,0,0,0,0,0
0,0,0,0,0,0,0,0,0,0,0,0,0,0,0,0,44,0,0,0,0,0,44,0,0,0,0,0,0,0,0,0,0,0,0,0,0,0,0
0,0,0,0,0,0,0,0,0,0,0,0,0,0,0,41,3,3,3,3,3,3,3,45,0,0,0,0,0,0,0,0,0,0,0,0,0,0,0
0,0,0,0,0,0,0,0,0,0,0,0,0,0,0,0,3,179,0,0,0,179,3,0,0,0,0,0,0,0,0,0,0,0,0,0,0,0,0
0,0,0,0,0,0,0,0,0,0,0,0,0,0,0,0,3,180,0,0,0,180,3,0,0,0,0,0,0,0,0,0,0,0,0,0,0,0,0
0,0,0,0,0,0,0,0,0,0,0,0,0,0,0,0,3,0,0,181,0,0,3,0,0,0,0,0,0,0,0,0,0,0,0,0,0,0,0
0,0,0,0,0,0,0,0,0,0,0,0,0,0,0,0,3,0,0,0,0,0,3,0,0,0,0,0,0,0,0,0,0,0,0,0,0,0,0
0,0,0,0,0,0,0,0,0,0,0,86,0,0,0,0,3,0,0,0,0,0,3,0,0,0,0,86,0,0,0,0,0,0,0,0,0,0,0
0,0,0,0,0,0,0,0,0,0,0,0,0,0,0,0,3,0,0,0,0,182,3,0,0,0,0,0,0,0,0,0,0,0,0,0,0,0,0
0,0,0,0,0,0,0,0,0,0,0,0,0,0,0,0,3,183,0,0,0,184,3,0,0,0,0,0,0,0,0,0,0,0,0,0,0,0,0
0,0,0,0,0,0,0,0,86,0,0,0,0,0,0,41,3,3,0,0,0,3,3,45,0,0,0,0,0,0,86,0,0,0,0,0,0,0,0
0,0,0,0,0,0,0,0,0,0,0,0,0,0,0,0,3,3,3,0,3,3,3,0,0,0,0,0,0,0,0,0,0,0,0,0,0,0,0
0,0,0,0,0,0,0,0,0,0,0,0,0,0,0,0,3,3,3,0,3,3,3,0,0,0,0,0,0,0,0,0,0,0,0,0,0,0,0
0,0,0,0,0,0,0,0,0,0,0,0,0,0,0,0,3,3,3,0,3,3,3,0,0,0,0,0,0,0,0,0,0,0,0,0,0,0,0
0,0,0,44,0,0,0,0,0,0,0,44,0,0,0,44,3,0,0,0,0,0,3,45,0,0,0,44,0,0,0,0,0,0,0,44,0,0,0
0,0,41,3,3,3,3,3,3,3,3,3,3,3,3,3,0,0,0,0,0,0,0,3,3,3,3,3,3,3,3,3,3,3,3,3,45,0,0
0,0,0,3,179,0,0,0,0,119,120,3,3,3,3,0,0,0,0,0,0,0,0,0,3,3,3,3,117,118,0,0,0,119,120,3,0,0,0
0,0,0,3,180,0,0,0,0,0,0,0,3,3,55,0,0,0,0,0,0,0,0,0,3,3,3,0,0,0,0,0,0,0,0,3,0,0,0
0,0,0,3,0,0,0,185,0,0,0,0,0,0,0,0,0,0,0,0,24,3,0,0,0,0,0,0,0,0,0,0,186,0,0,3,0,0,0
0,0,0,3,182,0,0,0,0,0,0,0,3,3,55,0,0,0,0,0,24,3,0,0,3,3,3,0,0,0,0,0,0,0,0,3,0,0,0
0,0,0,3,184,0,0,0,0,119,120,3,3,3,55,0,0,0,0,0,0,0,0,0,3,3,3,3,187,0,0,0,0,119,120,3,0,0,0
0,0,41,3,3,3,3,3,3,3,3,46,3,3,3,3,0,0,0,0,0,0,0,3,3,3,3,46,3,3,3,3,3,3,3,3,45,0,0
0,0,0,46,0,0,0,0,0,0,0,0,0,0,0,41,3,0,0,0,0,0,3,46,0,0,0,0,0,0,0,0,0,0,0,46,0,0,0
0,0,0,0,0,0,0,0,0,0,0,0,0,0,0,0,3,3,3,0,3,3,3,0,0,0,0,0,0,0,0,0,0,0,0,0,0,0,0
0,0,0,0,0,0,0,0,0,0,0,0,0,0,0,0,3,3,3,0,3,3,3,0,0,0,0,0,0,0,0,0,0,0,0,0,0,0,0
0,0,0,0,0,0,0,0,0,0,0,0,0,0,0,0,3,3,3,0,3,3,3,0,0,0,0,0,0,0,0,0,0,0,0,0,0,0,0
0,0,0,0,0,0,0,0,86,0,0,0,0,0,0,0,41,3,0,0,0,3,0,0,0,0,0,0,0,0,86,0,0,0,0,0,0,0,0
0,0,0,0,0,0,0,0,0,0,0,0,0,0,0,0,3,188,0,0,0,0,3,0,0,0,0,0,0,0,0,0,0,0,0,0,0,0,0
0,0,0,0,0,0,0,0,0,0,0,0,0,0,0,0,3,0,0,0,0,0,3,0,0,0,0,0,0,0,0,0,0,0,0,0,0,0,0
0,0,0,0,0,0,0,0,0,0,0,86,0,0,0,0,3,0,0,0,0,0,3,0,0,0,0,86,0,0,0,0,0,0,0,0,0,0,0
0,0,0,0,0,0,0,0,0,0,0,0,0,0,0,0,3,0,0,0,0,0,3,0,0,0,0,0,0,0,0,0,0,0,0,0,0,0,0
0,0,0,0,0,0,0,0,0,0,0,0,0,0,0,0,3,0,0,0,0,0,3,0,0,0,0,0,0,0,0,0,0,0,0,0,0,0,0
0,0,0,0,0,0,0,0,0,0,0,0,0,0,0,0,3,0,0,189,0,0,3,0,0,0,0,0,0,0,0,0,0,0,0,0,0,0,0
0,0,0,0,0,0,0,0,0,0,0,0,0,0,0,0,3,117,118,0,119,120,3,0,0,0,0,0,0,0,0,0,0,0,0,0,0,0,0
0,0,0,0,0,0,0,0,0,0,0,0,0,0,0,41,3,3,3,3,3,3,3,45,0,0,0,0,0,0,0,0,0,0,0,0,0,0,0
0,0,0,0,0,0,0,0,0,0,0,0,0,0,0,0,175,0,0,0,0,0,176,0,0,0,0,0,0,0,0,0,0,0,0,0,0,0,0
0,0,0,0,0,0,0,0,0,0,0,0,0,0,0,0,175,178,178,178,178,178,176,0,0,0,0,0,0,0,0,0,0,0,0,0,0,0,0
0,0,0,0,0,0,0,0,0,0,0,0,0,0,0,0,0,0,0,0,0,0,0,0,0,0,0,0,0,0,0,0,0,0,0,0,0,0,0
0,0,0,0,0,0,0,0,0,0,0,0,0,0,0,0,0,0,0,0,0,0,0,0,0,0,0,0,0,0,0,0,0,0,0,0,0,0,0
0,0,0,0,0,0,0,0,0,0,0,0,0,0,0,0,0,0,0,0,0,0,0,0,0,0,0,0,0,0,0,0,0,0,0,0,0,0,0
0,0,0,0,0,0,0,0,0,0,0,0,0,0,0,0,0,0,0,0,0,0,0,0,0,0,0,0,0,0,0,0,0,0,0,0,0,0,0
:endlayer
layer: 16
0,0,0,0,0,0,0,0,0,0,0,0,0,0,0,0,0,0,0,0,0,0,0,0,0,0,0,0,0,0,0,0,0,0,0,0,0,0,0
0,0,0,0,0,0,0,0,0,0,0,0,0,0,0,0,0,0,0,0,0,0,0,0,0,0,0,0,0,0,0,0,0,0,0,0,0,0,0
0,0,0,0,0,0,0,0,0,0,0,0,0,0,0,0,0,0,0,0,0,0,0,0,0,0,0,0,0,0,0,0,0,0,0,0,0,0,0
0,0,0,0,0,0,0,0,0,0,0,0,0,0,0,0,3,3,3,0,3,3,3,0,0,0,0,0,0,0,0,0,0,0,0,0,0,0,0
0,0,0,0,0,0,0,0,0,0,0,0,0,0,0,0,3,0,0,0,0,0,3,0,0,0,0,0,0,0,0,0,0,0,0,0,0,0,0
0,0,0,0,0,0,0,0,0,0,0,0,0,0,0,0,3,0,0,0,0,0,3,0,0,0,0,0,0,0,0,0,0,0,0,0,0,0,0
0,0,0,0,0,0,0,0,0,0,0,0,0,0,0,0,0,0,0,0,0,0,0,0,0,0,0,0,0,0,0,0,0,0,0,0,0,0,0
0,0,0,0,0,0,0,0,0,0,0,0,0,0,0,0,3,0,0,0,0,0,3,0,0,0,0,0,0,0,0,0,0,0,0,0,0,0,0
0,0,0,0,0,0,0,0,0,0,0,0,0,0,0,0,3,0,0,0,0,0,3,0,0,0,0,0,0,0,0,0,0,0,0,0,0,0,0
0,0,0,0,0,0,0,0,0,0,0,0,0,0,0,0,3,0,0,0,0,0,3,0,0,0,0,0,0,0,0,0,0,0,0,0,0,0,0
0,0,0,0,0,0,0,0,0,0,0,0,0,0,0,0,3,0,0,0,0,0,3,0,0,0,0,0,0,0,0,0,0,0,0,0,0,0,0
0,0,0,0,0,0,0,0,0,0,0,0,0,0,0,0,3,3,0,0,0,3,3,0,0,0,0,0,0,0,0,0,0,0,0,0,0,0,0
0,0,0,0,0,0,0,0,0,0,0,0,0,0,0,0,3,3,3,0,3,3,3,0,0,0,0,0,0,0,0,0,0,0,0,0,0,0,0
0,0,0,0,0,0,0,0,0,0,0,0,0,0,0,0,3,3,3,0,3,3,3,0,0,0,0,0,0,0,0,0,0,0,0,0,0,0,0
0,0,0,0,0,0,0,0,0,0,0,0,0,0,0,0,3,3,3,0,3,3,3,0,0,0,0,0,0,0,0,0,0,0,0,0,0,0,0
0,0,0,0,0,0,0,0,0,0,0,0,0,0,0,0,3,0,0,0,0,0,3,0,0,0,0,0,0,0,0,0,0,0,0,0,0,0,0
0,0,0,3,3,3,0,3,3,3,3,3,3,3,3,3,0,0,0,0,0,0,0,3,3,3,3,3,3,3,3,3,0,3,3,3,0,0,0
0,0,0,3,0,0,0,0,0,0,0,3,3,3,3,0,0,0,0,0,0,0,0,0,3,3,3,3,0,0,0,0,0,0,0,3,0,0,0
0,0,0,3,0,0,0,0,0,0,0,0,3,3,3,0,0,0,0,0,0,0,0,0,3,3,3,0,0,0,0,0,0,0,0,3,0,0,0
0,0,0,0,0,0,0,0,0,0,0,0,0,0,0,0,0,0,0,0,0,24,3,3,3,0,0,0,0,0,0,0,0,0,0,0,0,0,0
0,0,0,3,0,0,0,0,0,0,0,0,3,3,3,0,0,0,0,0,0,24,3,3,3,3,3,0,0,0,0,0,0,0,0,3,0,0,0
0,0,0,3,0,0,0,0,0,0,0,3,3,3,3,0,0,0,0,0,0,0,0,0,3,3,3,3,0,0,0,0,0,0,0,3,0,0,0
0,0,0,3,3,3,0,3,3,3,3,3,3,3,3,3,0,0,0,0,0,0,0,3,3,3,3,3,3,3,3,3,0,3,3,3,0,0,0
0,0,0,0,0,0,0,0,0,0,0,46,0,0,0,0,3,0,0,0,0,0,3,0,0,0,0,46,0,0,0,0,0,0,0,0,0,0,0
0,0,0,0,0,0,0,0,0,0,0,0,0,0,0,0,3,3,3,0,3,3,3,0,0,0,0,0,0,0,0,0,0,0,0,0,0,0,0
0,0,0,0,0,0,0,0,0,0,0,0,0,0,0,0,3,3,3,0,3,3,3,0,0,0,0,0,0,0,0,0,0,0,0,0,0,0,0
0,0,0,0,0,0,0,0,0,0,0,0,0,0,0,0,3,3,3,0,3,3,3,0,0,0,0,0,0,0,0,0,0,0,0,0,0,0,0
0,0,0,0,0,0,0,0,0,0,0,0,0,0,0,41,3,3,0,0,0,3,3,45,0,0,0,0,0,0,0,0,0,0,0,0,0,0,0
0,0,0,0,0,0,0,0,0,0,0,0,0,0,0,0,3,0,0,0,0,0,3,0,0,0,0,0,0,0,0,0,0,0,0,0,0,0,0
0,0,0,0,0,0,0,0,0,0,0,0,0,0,0,0,3,0,0,0,0,0,3,0,0,0,0,0,0,0,0,0,0,0,0,0,0,0,0
0,0,0,0,0,0,0,0,0,0,0,0,0,0,0,0,3,0,0,0,0,0,3,0,0,0,0,0,0,0,0,0,0,0,0,0,0,0,0
0,0,0,0,0,0,0,0,0,0,0,0,0,0,0,0,3,0,0,0,0,0,3,0,0,0,0,0,0,0,0,0,0,0,0,0,0,0,0
0,0,0,0,0,0,0,0,0,0,0,0,0,0,0,0,0,0,0,0,0,0,0,0,0,0,0,0,0,0,0,0,0,0,0,0,0,0,0
0,0,0,0,0,0,0,0,0,0,0,0,0,0,0,0,3,0,0,0,0,0,3,0,0,0,0,0,0,0,0,0,0,0,0,0,0,0,0
0,0,0,0,0,0,0,0,0,0,0,0,0,0,0,0,3,0,0,0,0,0,3,0,0,0,0,0,0,0,0,0,0,0,0,0,0,0,0
0,0,0,0,0,0,0,0,0,0,0,0,0,0,0,0,3,3,3,3,3,3,3,0,0,0,0,0,0,0,0,0,0,0,0,0,0,0,0
0,0,0,0,0,0,0,0,0,0,0,0,0,0,0,0,0,178,178,178,178,178,0,0,0,0,0,0,0,0,0,0,0,0,0,0,0,0,0
0,0,0,0,0,0,0,0,0,0,0,0,0,0,0,0,0,0,0,0,0,0,0,0,0,0,0,0,0,0,0,0,0,0,0,0,0,0,0
0,0,0,0,0,0,0,0,0,0,0,0,0,0,0,0,0,0,0,0,0,0,0,0,0,0,0,0,0,0,0,0,0,0,0,0,0,0,0
0,0,0,0,0,0,0,0,0,0,0,0,0,0,0,0,0,0,0,0,0,0,0,0,0,0,0,0,0,0,0,0,0,0,0,0,0,0,0
0,0,0,0,0,0,0,0,0,0,0,0,0,0,0,0,0,0,0,0,0,0,0,0,0,0,0,0,0,0,0,0,0,0,0,0,0,0,0
0,0,0,0,0,0,0,0,0,0,0,0,0,0,0,0,0,0,0,0,0,0,0,0,0,0,0,0,0,0,0,0,0,0,0,0,0,0,0
:endlayer
layer: 17
0,0,0,0,0,0,0,0,0,0,0,0,0,0,0,0,0,0,0,0,0,0,0,0,0,0,0,0,0,0,0,0,0,0,0,0,0,0,0
0,0,0,0,0,0,0,0,0,0,0,0,0,0,0,0,0,0,0,0,0,0,0,0,0,0,0,0,0,0,0,0,0,0,0,0,0,0,0
0,0,0,0,0,0,0,0,0,0,0,0,0,0,0,0,0,0,0,0,0,0,0,0,0,0,0,0,0,0,0,0,0,0,0,0,0,0,0
0,0,0,0,0,0,0,0,0,0,0,0,0,0,0,0,3,3,3,3,3,3,3,0,0,0,0,0,0,0,0,0,0,0,0,0,0,0,0
0,0,0,0,0,0,0,0,0,0,0,0,0,0,0,0,3,0,0,46,0,0,3,0,0,0,0,0,0,0,0,0,0,0,0,0,0,0,0
0,0,0,0,0,0,0,0,0,0,0,0,0,0,0,0,3,0,0,0,0,0,3,0,0,0,0,0,0,0,0,0,0,0,0,0,0,0,0
0,0,0,0,0,0,0,0,0,0,0,0,0,0,0,0,3,45,0,0,0,41,3,0,0,0,0,0,0,0,0,0,0,0,0,0,0,0,0
0,0,0,0,0,0,0,0,0,0,0,0,0,0,0,0,3,0,0,0,0,0,3,0,0,0,0,0,0,0,0,0,0,0,0,0,0,0,0
0,0,0,0,0,0,0,0,0,0,0,0,0,0,0,0,3,0,0,0,0,0,3,0,0,0,0,0,0,0,0,0,0,0,0,0,0,0,0
0,0,0,0,0,0,0,0,0,0,0,0,0,0,0,0,3,0,0,0,0,0,3,0,0,0,0,0,0,0,0,0,0,0,0,0,0,0,0
0,0,0,0,0,0,0,0,0,0,0,0,0,0,0,0,3,0,0,0,0,0,3,0,0,0,0,0,0,0,0,0,0,0,0,0,0,0,0
0,0,0,0,0,0,0,0,0,0,0,0,0,0,0,0,3,3,0,44,0,3,3,0,0,0,0,0,0,0,0,0,0,0,0,0,0,0,0
0,0,0,0,0,0,0,0,0,0,0,0,0,0,0,0,3,3,3,3,3,3,3,0,0,0,0,0,0,0,0,0,0,0,0,0,0,0,0
0,0,0,0,0,0,0,0,0,0,0,0,0,0,0,0,3,3,3,3,3,3,3,0,0,0,0,0,0,0,0,0,0,0,0,0,0,0,0
0,0,0,0,0,0,0,0,0,0,0,0,0,0,0,0,3,3,3,3,3,3,3,0,0,0,0,0,0,0,0,0,0,0,0,0,0,0,0
0,0,0,0,0,0,0,0,0,0,0,0,0,0,0,0,3,0,0,46,0,0,3,0,0,0,0,0,0,0,0,0,0,0,0,0,0,0,0
0,0,0,3,3,3,3,3,3,3,3,3,3,3,3,3,0,0,0,0,0,0,0,3,3,3,3,3,3,3,3,3,3,3,3,3,0,0,0
0,0,0,3,0,0,46,0,0,0,0,3,3,3,3,0,0,0,0,0,0,0,0,0,3,3,3,3,0,0,0,0,46,0,0,3,0,0,0
0,0,0,3,0,0,0,0,0,0,0,0,3,3,3,0,0,0,0,0,0,0,0,0,3,3,3,0,0,0,0,0,0,0,0,3,0,0,0
0,0,0,3,45,0,0,0,0,0,0,41,3,3,3,45,0,0,0,0,0,0,24,3,3,3,3,45,0,0,0,0,0,0,41,3,0,0,0
0,0,0,3,0,0,0,0,0,0,0,0,3,3,3,0,0,0,0,0,0,0,24,3,3,3,3,0,0,0,0,0,0,0,0,3,0,0,0
0,0,0,3,0,0,44,0,0,0,0,3,3,3,3,0,0,0,0,0,0,0,0,0,3,3,3,3,0,0,0,0,44,0,0,3,0,0,0
0,0,0,3,3,3,3,3,3,3,3,3,3,3,3,3,0,0,0,0,0,0,0,3,3,3,3,3,3,3,3,3,3,3,3,3,0,0,0
0,0,0,0,0,0,0,0,0,0,0,0,0,0,0,0,3,0,0,44,0,0,3,0,0,0,0,0,0,0,0,0,0,0,0,0,0,0,0
0,0,0,0,0,0,0,0,0,0,0,0,0,0,0,0,3,3,3,3,3,3,3,0,0,0,0,0,0,0,0,0,0,0,0,0,0,0,0
0,0,0,0,0,0,0,0,0,0,0,0,0,0,0,0,3,3,3,3,3,3,3,0,0,0,0,0,0,0,0,0,0,0,0,0,0,0,0
0,0,0,0,0,0,0,0,0,0,0,0,0,0,0,0,3,3,3,3,3,3,3,0,0,0,0,0,0,0,0,0,0,0,0,0,0,0,0
0,0,0,0,0,0,0,0,0,0,0,0,0,0,0,0,3,3,0,46,0,3,3,0,0,0,0,0,0,0,0,0,0,0,0,0,0,0,0
0,0,0,0,0,0,0,0,0,0,0,0,0,0,0,0,3,0,0,0,0,0,3,0,0,0,0,0,0,0,0,0,0,0,0,0,0,0,0
0,0,0,0,0,0,0,0,0,0,0,0,0,0,0,0,3,0,0,0,0,0,3,0,0,0,0,0,0,0,0,0,0,0,0,0,0,0,0
0,0,0,0,0,0,0,0,0,0,0,0,0,0,0,0,3,0,0,0,0,0,3,0,0,0,0,0,0,0,0,0,0,0,0,0,0,0,0
0,0,0,0,0,0,0,0,0,0,0,0,0,0,0,0,3,0,0,0,0,0,3,0,0,0,0,0,0,0,0,0,0,0,0,0,0,0,0
0,0,0,0,0,0,0,0,0,0,0,0,0,0,0,0,3,45,0,0,0,41,3,0,0,0,0,0,0,0,0,0,0,0,0,0,0,0,0
0,0,0,0,0,0,0,0,0,0,0,0,0,0,0,0,3,0,0,0,0,0,3,0,0,0,0,0,0,0,0,0,0,0,0,0,0,0,0
0,0,0,0,0,0,0,0,0,0,0,0,0,0,0,0,3,0,0,44,0,0,3,0,0,0,0,0,0,0,0,0,0,0,0,0,0,0,0
0,0,0,0,0,0,0,0,0,0,0,0,0,0,0,0,3,3,3,3,3,3,3,0,0,0,0,0,0,0,0,0,0,0,0,0,0,0,0
0,0,0,0,0,0,0,0,0,0,0,0,0,0,0,0,0,0,0,0,0,0,0,0,0,0,0,0,0,0,0,0,0,0,0,0,0,0,0
0,0,0,0,0,0,0,0,0,0,0,0,0,0,0,0,0,0,0,0,0,0,0,0,0,0,0,0,0,0,0,0,0,0,0,0,0,0,0
0,0,0,0,0,0,0,0,0,0,0,0,0,0,0,0,0,0,0,0,0,0,0,0,0,0,0,0,0,0,0,0,0,0,0,0,0,0,0
0,0,0,0,0,0,0,0,0,0,0,0,0,0,0,0,0,0,0,0,0,0,0,0,0,0,0,0,0,0,0,0,0,0,0,0,0,0,0
0,0,0,0,0,0,0,0,0,0,0,0,0,0,0,0,0,0,0,0,0,0,0,0,0,0,0,0,0,0,0,0,0,0,0,0,0,0,0
0,0,0,0,0,0,0,0,0,0,0,0,0,0,0,0,0,0,0,0,0,0,0,0,0,0,0,0,0,0,0,0,0,0,0,0,0,0,0
:endlayer
layer: 18
0,0,0,0,0,0,0,0,0,0,0,0,0,0,0,0,0,0,0,0,0,0,0,0,0,0,0,0,0,0,0,0,0,0,0,0,0,0,0
0,0,0,0,0,0,0,0,0,0,0,0,0,0,0,0,0,0,0,0,0,0,0,0,0,0,0,0,0,0,0,0,0,0,0,0,0,0,0
0,0,0,0,0,0,0,0,0,0,0,0,0,0,0,3,3,3,3,3,3,3,3,3,0,0,0,0,0,0,0,0,0,0,0,0,0,0,0
0,0,0,0,0,0,0,0,0,0,0,0,0,0,0,3,3,3,3,3,3,3,3,3,0,0,0,0,0,0,0,0,0,0,0,0,0,0,0
0,0,0,0,0,0,0,0,0,0,0,0,0,0,0,3,3,3,3,3,3,3,3,3,0,0,0,0,0,0,0,0,0,0,0,0,0,0,0
0,0,0,0,0,0,0,0,0,0,0,0,0,0,0,3,3,3,3,3,3,3,3,3,0,0,0,0,0,0,0,0,0,0,0,0,0,0,0
0,0,0,0,0,0,0,0,0,0,0,0,0,0,0,3,3,3,3,3,3,3,3,3,0,0,0,0,0,0,0,0,0,0,0,0,0,0,0
0,0,0,0,0,0,0,0,0,0,0,0,0,0,0,3,3,3,3,3,3,3,3,3,0,0,0,0,0,0,0,0,0,0,0,0,0,0,0
0,0,0,0,0,0,0,0,0,0,0,0,0,0,0,3,3,3,3,3,3,3,3,3,0,0,0,0,0,0,0,0,0,0,0,0,0,0,0
0,0,0,0,0,0,0,0,0,0,0,0,0,0,0,3,3,3,3,3,3,3,3,3,0,0,0,0,0,0,0,0,0,0,0,0,0,0,0
0,0,0,0,0,0,0,0,0,0,0,0,0,0,0,3,3,3,3,3,3,3,3,3,0,0,0,0,0,0,0,0,0,0,0,0,0,0,0
0,0,0,0,0,0,0,0,0,0,0,0,0,0,0,3,3,3,3,3,3,3,3,3,0,0,0,0,0,0,0,0,0,0,0,0,0,0,0
0,0,0,0,0,0,0,0,0,0,0,0,0,0,0,3,3,3,3,3,3,3,3,3,0,0,0,0,0,0,0,0,0,0,0,0,0,0,0
0,0,0,0,0,0,0,0,0,0,0,0,0,0,0,3,3,3,3,3,3,3,3,3,0,0,0,0,0,0,0,0,0,0,0,0,0,0,0
0,0,0,0,0,0,0,0,0,0,0,0,0,0,0,3,3,3,3,3,3,3,3,3,0,0,0,0,0,0,0,0,0,0,0,0,0,0,0
0,0,3,3,3,3,3,3,3,3,3,3,3,3,3,3,3,3,3,3,3,3,3,3,3,3,3,3,3,3,3,3,3,3,3,3,3,0,0
0,0,3,3,3,3,3,3,3,3,3,3,3,3,3,3,3,3,3,3,3,3,3,3,3,3,3,3,3,3,3,3,3,3,3,3,3,0,0
0,0,3,3,3,3,3,3,3,3,3,3,3,3,3,3,3,3,3,3,3,3,3,3,3,3,3,3,3,3,3,3,3,3,3,3,3,0,0
0,0,3,3,3,3,3,3,3,3,3,3,3,3,3,3,3,3,3,3,3,3,3,3,3,3,3,3,3,3,3,3,3,3,3,3,3,0,0
0,0,3,3,3,3,3,3,3,3,3,3,3,3,3,3,3,3,3,0,0,0,0,24,3,3,3,3,3,3,3,3,3,3,3,3,3,0,0
0,0,3,3,3,3,3,3,3,3,3,3,3,3,3,3,3,3,3,0,0,0,0,24,3,3,3,3,3,3,3,3,3,3,3,3,3,0,0
0,0,3,3,3,3,3,3,3,3,3,3,3,3,3,3,3,3,3,3,3,3,3,3,3,3,3,3,3,3,3,3,3,3,3,3,3,0,0
0,0,3,3,3,3,3,3,3,3,3,3,3,3,3,3,3,3,3,3,3,3,3,3,3,3,3,3,3,3,3,3,3,3,3,3,3,0,0
0,0,3,3,3,3,3,3,3,3,3,3,3,3,3,3,3,3,3,3,3,3,3,3,3,3,3,3,3,3,3,3,3,3,3,3,3,0,0
0,0,0,0,0,0,0,0,0,0,0,0,0,0,0,3,3,3,3,3,3,3,3,3,0,0,0,0,0,0,0,0,0,0,0,0,0,0,0
0,0,0,0,0,0,0,0,0,0,0,0,0,0,0,3,3,3,3,3,3,3,3,3,0,0,0,0,0,0,0,0,0,0,0,0,0,0,0
0,0,0,0,0,0,0,0,0,0,0,0,0,0,0,3,3,3,3,3,3,3,3,3,0,0,0,0,0,0,0,0,0,0,0,0,0,0,0
0,0,0,0,0,0,0,0,0,0,0,0,0,0,0,3,3,3,3,3,3,3,3,3,0,0,0,0,0,0,0,0,0,0,0,0,0,0,0
0,0,0,0,0,0,0,0,0,0,0,0,0,0,0,3,3,3,3,3,3,3,3,3,0,0,0,0,0,0,0,0,0,0,0,0,0,0,0
0,0,0,0,0,0,0,0,0,0,0,0,0,0,0,3,3,3,3,3,3,3,3,3,0,0,0,0,0,0,0,0,0,0,0,0,0,0,0
0,0,0,0,0,0,0,0,0,0,0,0,0,0,0,3,3,3,3,3,3,3,3,3,0,0,0,0,0,0,0,0,0,0,0,0,0,0,0
0,0,0,0,0,0,0,0,0,0,0,0,0,0,0,3,3,3,3,3,3,3,3,3,0,0,0,0,0,0,0,0,0,0,0,0,0,0,0
0,0,0,0,0,0,0,0,0,0,0,0,0,0,0,3,3,3,3,3,3,3,3,3,0,0,0,0,0,0,0,0,0,0,0,0,0,0,0
0,0,0,0,0,0,0,0,0,0,0,0,0,0,0,3,3,3,3,3,3,3,3,3,0,0,0,0,0,0,0,0,0,0,0,0,0,0,0
0,0,0,0,0,0,0,0,0,0,0,0,0,0,0,3,3,3,3,3,3,3,3,3,0,0,0,0,0,0,0,0,0,0,0,0,0,0,0
0,0,0,0,0,0,0,0,0,0,0,0,0,0,0,3,3,3,3,3,3,3,3,3,0,0,0,0,0,0,0,0,0,0,0,0,0,0,0
0,0,0,0,0,0,0,0,0,0,0,0,0,0,0,3,3,3,3,3,3,3,3,3,0,0,0,0,0,0,0,0,0,0,0,0,0,0,0
0,0,0,0,0,0,0,0,0,0,0,0,0,0,0,0,0,0,0,0,0,0,0,0,0,0,0,0,0,0,0,0,0,0,0,0,0,0,0
0,0,0,0,0,0,0,0,0,0,0,0,0,0,0,0,0,0,0,0,0,0,0,0,0,0,0,0,0,0,0,0,0,0,0,0,0,0,0
0,0,0,0,0,0,0,0,0,0,0,0,0,0,0,0,0,0,0,0,0,0,0,0,0,0,0,0,0,0,0,0,0,0,0,0,0,0,0
0,0,0,0,0,0,0,0,0,0,0,0,0,0,0,0,0,0,0,0,0,0,0,0,0,0,0,0,0,0,0,0,0,0,0,0,0,0,0
0,0,0,0,0,0,0,0,0,0,0,0,0,0,0,0,0,0,0,0,0,0,0,0,0,0,0,0,0,0,0,0,0,0,0,0,0,0,0
:endlayer
layer: 19
0,0,0,0,0,0,0,0,0,0,0,0,0,0,0,0,0,0,0,0,0,0,0,0,0,0,0,0,0,0,0,0,0,0,0,0,0,0,0
0,0,0,0,0,0,0,0,0,0,0,0,0,0,0,0,0,0,0,0,0,0,0,0,0,0,0,0,0,0,0,0,0,0,0,0,0,0,0
0,0,0,0,0,0,0,0,0,0,0,0,0,0,0,3,3,3,3,3,3,3,3,3,0,0,0,0,0,0,0,0,0,0,0,0,0,0,0
0,0,0,0,0,0,0,0,0,0,0,0,0,0,0,3,0,0,0,0,0,0,0,3,0,0,0,0,0,0,0,0,0,0,0,0,0,0,0
0,0,0,0,0,0,0,0,0,0,0,0,0,0,0,3,0,0,0,0,0,0,0,3,0,0,0,0,0,0,0,0,0,0,0,0,0,0,0
0,0,0,0,0,0,0,0,0,0,0,0,0,0,0,3,0,0,0,190,0,0,0,3,0,0,0,0,0,0,0,0,0,0,0,0,0,0,0
0,0,0,0,0,0,0,0,0,0,0,0,0,0,0,3,0,0,3,191,0,0,0,3,0,0,0,0,0,0,0,0,0,0,0,0,0,0,0
0,0,0,0,0,0,0,0,0,0,0,0,0,0,0,3,0,0,0,0,0,0,0,3,0,0,0,0,0,0,0,0,0,0,0,0,0,0,0
0,0,0,0,0,0,0,0,0,0,0,0,0,0,0,3,0,0,0,192,0,0,0,3,0,0,0,0,0,0,0,0,0,0,0,0,0,0,0
0,0,0,0,0,0,0,0,0,0,0,0,0,0,0,3,0,0,0,0,0,0,0,3,0,0,0,0,0,0,0,0,0,0,0,0,0,0,0
0,0,0,0,0,0,0,0,0,0,0,0,0,0,0,3,0,0,0,0,0,0,0,3,0,0,0,0,0,0,0,0,0,0,0,0,0,0,0
0,0,0,0,0,0,0,0,0,0,0,0,0,0,0,3,0,0,3,85,3,0,0,3,0,0,0,0,0,0,0,0,0,0,0,0,0,0,0
0,0,0,0,0,0,0,0,0,0,0,0,0,0,0,3,0,3,3,3,3,3,0,3,0,0,0,0,0,0,0,0,0,0,0,0,0,0,0
0,0,0,0,0,0,0,0,0,0,0,0,0,0,0,3,0,3,3,3,3,3,0,3,0,0,0,0,0,0,0,0,0,0,0,0,0,0,0
0,0,0,0,0,0,0,0,0,0,0,0,0,0,0,3,0,3,3,3,3,3,0,3,0,0,0,0,0,0,0,0,0,0,0,0,0,0,0
0,0,3,3,3,3,3,3,3,3,3,3,3,3,3,3,0,3,0,0,0,3,0,3,3,3,3,3,3,3,3,3,3,3,3,3,3,0,0
0,0,3,0,0,0,0,0,0,0,0,0,0,0,0,0,0,0,0,0,0,0,0,0,0,0,0,0,0,0,0,0,0,0,0,0,3,0,0
0,0,3,0,0,0,0,0,0,0,0,0,3,3,3,3,0,0,0,0,0,0,0,3,3,0,0,0,0,0,0,0,0,0,0,0,3,0,0
0,0,3,0,0,0,0,0,0,0,0,3,3,3,3,0,0,0,0,3,3,3,3,3,3,0,0,0,0,0,0,0,0,0,0,0,3,0,0
0,0,3,0,193,3,191,0,194,0,0,85,3,3,3,0,0,24,3,3,0,0,0,0,195,0,0,0,0,0,0,3,191,196,0,0,3,0,0
0,0,3,0,0,0,0,0,0,0,0,3,3,3,3,0,0,24,3,3,0,0,0,197,0,0,0,198,0,0,0,0,0,0,0,0,3,0,0
0,0,3,0,0,0,0,0,0,0,0,0,3,3,3,3,0,0,0,3,3,3,3,3,3,0,0,0,0,0,0,0,0,0,0,0,3,0,0
0,0,3,0,0,0,0,0,0,0,0,0,0,0,0,0,0,0,0,0,0,0,0,0,0,0,0,0,0,0,0,0,0,0,0,0,3,0,0
0,0,3,3,3,3,3,3,3,3,3,3,3,3,3,3,0,3,0,0,0,3,0,3,3,3,3,3,3,3,3,3,3,3,3,3,3,0,0
0,0,0,0,0,0,0,0,0,0,0,0,0,0,0,3,0,3,3,3,3,3,0,3,0,0,0,0,0,0,0,0,0,0,0,0,0,0,0
0,0,0,0,0,0,0,0,0,0,0,0,0,0,0,3,0,3,3,3,3,3,0,3,0,0,0,0,0,0,0,0,0,0,0,0,0,0,0
0,0,0,0,0,0,0,0,0,0,0,0,0,0,0,3,0,3,3,3,3,3,0,3,0,0,0,0,0,0,0,0,0,0,0,0,0,0,0
0,0,0,0,0,0,0,0,0,0,0,0,0,0,0,3,0,0,3,85,3,0,0,3,0,0,0,0,0,0,0,0,0,0,0,0,0,0,0
0,0,0,0,0,0,0,0,0,0,0,0,0,0,0,3,0,0,0,0,0,0,0,3,0,0,0,0,0,0,0,0,0,0,0,0,0,0,0
0,0,0,0,0,0,0,0,0,0,0,0,0,0,0,3,0,0,0,199,0,0,0,3,0,0,0,0,0,0,0,0,0,0,0,0,0,0,0
0,0,0,0,0,0,0,0,0,0,0,0,0,0,0,3,0,0,0,0,0,0,0,3,0,0,0,0,0,0,0,0,0,0,0,0,0,0,0
0,0,0,0,0,0,0,0,0,0,0,0,0,0,0,3,0,0,0,0,0,0,0,3,0,0,0,0,0,0,0,0,0,0,0,0,0,0,0
0,0,0,0,0,0,0,0,0,0,0,0,0,0,0,3,0,0,3,191,200,0,0,3,0,0,0,0,0,0,0,0,0,0,0,0,0,0,0
0,0,0,0,0,0,0,0,0,0,0,0,0,0,0,3,0,0,0,0,0,0,0,3,0,0,0,0,0,0,0,0,0,0,0,0,0,0,0
0,0,0,0,0,0,0,0,0,0,0,0,0,0,0,3,0,0,0,0,0,0,0,3,0,0,0,0,0,0,0,0,0,0,0,0,0,0,0
0,0,0,0,0,0,0,0,0,0,0,0,0,0,0,3,0,0,0,0,0,0,0,3,0,0,0,0,0,0,0,0,0,0,0,0,0,0,0
0,0,0,0,0,0,0,0,0,0,0,0,0,0,0,3,3,3,3,3,3,3,3,3,0,0,0,0,0,0,0,0,0,0,0,0,0,0,0
0,0,0,0,0,0,0,0,0,0,0,0,0,0,0,0,0,0,0,0,0,0,0,0,0,0,0,0,0,0,0,0,0,0,0,0,0,0,0
0,0,0,0,0,0,0,0,0,0,0,0,0,0,0,0,0,0,0,0,0,0,0,0,0,0,0,0,0,0,0,0,0,0,0,0,0,0,0
0,0,0,0,0,0,0,0,0,0,0,0,0,0,0,0,0,0,0,0,0,0,0,0,0,0,0,0,0,0,0,0,0,0,0,0,0,0,0
0,0,0,0,0,0,0,0,0,0,0,0,0,0,0,0,0,0,0,0,0,0,0,0,0,0,0,0,0,0,0,0,0,0,0,0,0,0,0
0,0,0,0,0,0,0,0,0,0,0,0,0,0,0,0,0,0,0,0,0,0,0,0,0,0,0,0,0,0,0,0,0,0,0,0,0,0,0
:endlayer
layer: 20
0,0,0,0,0,0,0,0,0,0,0,0,0,0,0,0,0,0,0,0,0,0,0,0,0,0,0,0,0,0,0,0,0,0,0,0,0,0,0
0,0,0,0,0,0,0,0,0,0,0,0,0,0,0,0,0,0,0,0,0,0,0,0,0,0,0,0,0,0,0,0,0,0,0,0,0,0,0
0,0,0,0,0,0,0,0,0,0,0,0,0,0,0,3,0,3,201,3,0,3,0,3,0,0,0,0,0,0,0,0,0,0,0,0,0,0,0
0,0,0,0,0,0,0,0,0,0,0,0,0,0,0,0,0,0,0,0,0,0,0,0,0,0,0,0,0,0,0,0,0,0,0,0,0,0,0
0,0,0,0,0,0,0,0,0,0,0,0,0,0,0,3,0,0,0,0,0,0,0,3,0,0,0,0,0,0,0,0,0,0,0,0,0,0,0
0,0,0,0,0,0,0,0,0,0,0,0,0,0,0,0,0,0,0,0,0,0,0,0,0,0,0,0,0,0,0,0,0,0,0,0,0,0,0
0,0,0,0,0,0,0,0,0,0,0,0,0,0,0,3,0,0,3,191,0,0,0,3,0,0,0,0,0,0,0,0,0,0,0,0,0,0,0
0,0,0,0,0,0,0,0,0,0,0,0,0,0,0,0,0,0,0,0,0,0,0,0,0,0,0,0,0,0,0,0,0,0,0,0,0,0,0
0,0,0,0,0,0,0,0,0,0,0,0,0,0,0,3,0,0,0,0,0,0,0,3,0,0,0,0,0,0,0,0,0,0,0,0,0,0,0
0,0,0,0,0,0,0,0,0,0,0,0,0,0,0,0,0,0,0,0,0,0,0,0,0,0,0,0,0,0,0,0,0,0,0,0,0,0,0
0,0,0,0,0,0,0,0,0,0,0,0,0,0,0,3,0,0,0,0,0,0,0,3,0,0,0,0,0,0,0,0,0,0,0,0,0,0,0
0,0,0,0,0,0,0,0,0,0,0,0,0,0,0,0,0,0,3,0,3,0,0,0,0,0,0,0,0,0,0,0,0,0,0,0,0,0,0
0,0,0,0,0,0,0,0,0,0,0,0,0,0,0,3,0,3,3,3,3,3,0,3,0,0,0,0,0,0,0,0,0,0,0,0,0,0,0
0,0,0,0,0,0,0,0,0,0,0,0,0,0,0,0,0,3,3,3,3,3,0,0,0,0,0,0,0,0,0,0,0,0,0,0,0,0,0
0,0,0,0,0,0,0,0,0,0,0,0,0,0,0,3,0,3,3,3,3,3,0,3,0,0,0,0,0,0,0,0,0,0,0,0,0,0,0
0,0,3,0,3,0,3,0,3,0,3,0,3,0,3,3,0,3,0,0,0,3,0,3,3,0,3,0,3,0,3,0,3,0,3,0,3,0,0
0,0,0,0,0,0,0,0,0,0,0,0,0,0,0,0,0,0,0,0,0,0,0,0,0,0,0,0,0,0,0,0,0,0,0,0,0,0,0
0,0,3,0,0,0,0,0,0,0,0,0,3,3,3,3,0,0,0,0,0,0,0,3,3,0,0,0,0,0,0,0,0,0,0,0,3,0,0
0,0,0,0,0,0,0,0,0,0,0,3,3,3,3,0,0,0,0,3,3,3,3,3,3,45,0,0,0,0,0,0,0,0,0,0,202,0,0
0,0,3,0,0,3,191,0,0,0,0,0,3,3,3,0,0,0,24,3,0,0,0,0,0,0,0,0,0,0,0,3,191,0,0,0,3,0,0
0,0,203,0,0,0,0,0,0,0,0,3,3,3,3,0,0,0,24,3,0,0,0,0,0,0,0,0,0,0,0,0,0,0,0,0,0,0,0
0,0,3,0,0,0,0,0,0,0,0,0,3,3,3,3,0,0,0,3,3,3,3,3,3,45,0,0,0,0,0,0,0,0,0,0,3,0,0
0,0,0,0,0,0,0,0,0,0,0,0,0,0,0,0,0,0,0,0,0,0,0,0,0,0,0,0,0,0,0,0,0,0,0,0,0,0,0
0,0,3,0,3,0,3,0,3,0,3,0,3,0,3,3,0,3,0,0,0,3,0,3,3,0,3,0,3,0,3,0,3,0,3,0,3,0,0
0,0,0,0,0,0,0,0,0,0,0,0,0,0,0,3,0,3,3,3,3,3,0,3,0,0,0,0,0,0,0,0,0,0,0,0,0,0,0
0,0,0,0,0,0,0,0,0,0,0,0,0,0,0,0,0,3,3,3,3,3,0,0,0,0,0,0,0,0,0,0,0,0,0,0,0,0,0
0,0,0,0,0,0,0,0,0,0,0,0,0,0,0,3,0,3,3,3,3,3,0,3,0,0,0,0,0,0,0,0,0,0,0,0,0,0,0
0,0,0,0,0,0,0,0,0,0,0,0,0,0,0,0,0,0,3,0,3,0,0,0,0,0,0,0,0,0,0,0,0,0,0,0,0,0,0
0,0,0,0,0,0,0,0,0,0,0,0,0,0,0,3,0,0,0,0,0,0,0,3,0,0,0,0,0,0,0,0,0,0,0,0,0,0,0
0,0,0,0,0,0,0,0,0,0,0,0,0,0,0,0,0,0,0,0,0,0,0,0,0,0,0,0,0,0,0,0,0,0,0,0,0,0,0
0,0,0,0,0,0,0,0,0,0,0,0,0,0,0,3,0,0,0,0,0,0,0,3,0,0,0,0,0,0,0,0,0,0,0,0,0,0,0
0,0,0,0,0,0,0,0,0,0,0,0,0,0,0,0,0,0,0,0,0,0,0,0,0,0,0,0,0,0,0,0,0,0,0,0,0,0,0
0,0,0,0,0,0,0,0,0,0,0,0,0,0,0,3,0,0,3,191,0,0,0,3,0,0,0,0,0,0,0,0,0,0,0,0,0,0,0
0,0,0,0,0,0,0,0,0,0,0,0,0,0,0,0,0,0,0,0,0,0,0,0,0,0,0,0,0,0,0,0,0,0,0,0,0,0,0
0,0,0,0,0,0,0,0,0,0,0,0,0,0,0,3,0,0,0,0,0,0,0,3,0,0,0,0,0,0,0,0,0,0,0,0,0,0,0
0,0,0,0,0,0,0,0,0,0,0,0,0,0,0,0,0,0,0,0,0,0,0,0,0,0,0,0,0,0,0,0,0,0,0,0,0,0,0
0,0,0,0,0,0,0,0,0,0,0,0,0,0,0,3,0,3,0,3,204,3,0,3,0,0,0,0,0,0,0,0,0,0,0,0,0,0,0
0,0,0,0,0,0,0,0,0,0,0,0,0,0,0,0,0,0,0,0,0,0,0,0,0,0,0,0,0,0,0,0,0,0,0,0,0,0,0
0,0,0,0,0,0,0,0,0,0,0,0,0,0,0,0,0,0,0,0,0,0,0,0,0,0,0,0,0,0,0,0,0,0,0,0,0,0,0
0,0,0,0,0,0,0,0,0,0,0,0,0,0,0,0,0,0,0,0,0,0,0,0,0,0,0,0,0,0,0,0,0,0,0,0,0,0,0
0,0,0,0,0,0,0,0,0,0,0,0,0,0,0,0,0,0,0,0,0,0,0,0,0,0,0,0,0,0,0,0,0,0,0,0,0,0,0
0,0,0,0,0,0,0,0,0,0,0,0,0,0,0,0,0,0,0,0,0,0,0,0,0,0,0,0,0,0,0,0,0,0,0,0,0,0,0
:endlayer
layer: 21
0,0,0,0,0,0,0,0,0,0,0,0,0,0,0,0,0,0,0,0,0,0,0,0,0,0,0,0,0,0,0,0,0,0,0,0,0,0,0
0,0,0,0,0,0,0,0,0,0,0,0,0,0,0,44,0,0,0,0,0,0,0,44,0,0,0,0,0,0,0,0,0,0,0,0,0,0,0
0,0,0,0,0,0,0,0,0,0,0,0,0,0,41,3,0,3,0,3,0,3,0,3,45,0,0,0,0,0,0,0,0,0,0,0,0,0,0
0,0,0,0,0,0,0,0,0,0,0,0,0,0,0,0,0,0,0,0,0,0,0,0,0,0,0,0,0,0,0,0,0,0,0,0,0,0,0
0,0,0,0,0,0,0,0,0,0,0,0,0,0,0,3,0,0,0,0,0,0,0,3,0,0,0,0,0,0,0,0,0,0,0,0,0,0,0
0,0,0,0,0,0,0,0,0,0,0,0,0,0,0,0,0,0,0,0,0,0,0,0,0,0,0,0,0,0,0,0,0,0,0,0,0,0,0
0,0,0,0,0,0,0,0,0,0,0,0,0,0,0,3,0,0,3,191,0,0,0,3,0,0,0,0,0,0,0,0,0,0,0,0,0,0,0
0,0,0,0,0,0,0,0,0,0,0,0,0,0,0,0,0,0,0,0,0,0,0,0,0,0,0,0,0,0,0,0,0,0,0,0,0,0,0
0,0,0,0,0,0,0,0,0,0,0,0,0,0,0,3,0,0,0,0,0,0,0,3,0,0,0,0,0,0,0,0,0,0,0,0,0,0,0
0,0,0,0,0,0,0,0,0,0,0,0,0,0,0,0,0,0,0,0,0,0,0,0,0,0,0,0,0,0,0,0,0,0,0,0,0,0,0
0,0,0,0,0,0,0,0,0,0,0,0,0,0,41,3,0,0,0,0,0,0,0,3,45,0,0,0,0,0,0,0,0,0,0,0,0,0,0
0,0,0,0,0,0,0,0,0,0,0,0,0,0,0,46,0,0,3,3,3,0,0,46,0,0,0,0,0,0,0,0,0,0,0,0,0,0,0
0,0,0,0,0,0,0,0,0,0,0,0,0,0,0,3,0,3,3,3,3,3,0,3,0,0,0,0,0,0,0,0,0,0,0,0,0,0,0
0,0,0,0,0,0,0,0,0,0,0,0,0,0,0,0,0,3,3,3,3,3,0,0,0,0,0,0,0,0,0,0,0,0,0,0,0,0,0
0,0,44,0,0,0,0,0,0,0,44,0,0,0,0,3,0,3,3,3,3,3,0,3,0,0,0,0,44,0,0,0,0,0,0,0,44,0,0
0,41,3,0,3,0,3,0,3,0,3,45,3,0,3,3,0,3,0,46,0,3,0,3,3,0,3,41,3,0,3,0,3,0,3,0,3,45,0
0,0,0,0,0,0,0,0,0,0,0,0,0,0,0,0,0,0,0,0,0,0,0,0,0,0,0,0,0,0,0,0,0,0,0,0,0,0,0
0,0,3,0,0,0,0,0,0,0,0,0,3,3,3,3,0,0,0,0,0,0,41,3,3,0,0,0,0,0,0,0,0,0,0,0,3,0,0
0,0,0,0,0,44,0,0,0,0,0,3,3,3,55,0,0,0,0,3,3,3,3,3,3,0,0,0,0,0,0,0,0,0,0,0,0,0,0
0,0,3,0,0,3,191,0,0,0,0,3,3,3,55,45,0,0,0,24,0,0,0,0,3,0,0,0,0,0,41,3,191,0,0,0,3,0,0
0,0,0,0,0,46,0,0,0,0,0,3,3,3,55,0,0,0,0,24,0,0,0,0,3,0,0,0,0,0,0,0,0,0,0,0,0,0,0
0,0,3,0,0,0,0,0,0,0,0,0,3,3,55,3,0,0,0,3,3,3,3,3,3,0,0,0,0,0,0,0,0,0,0,0,3,0,0
0,0,0,0,0,0,0,0,0,0,0,0,0,0,0,0,0,0,0,0,0,0,0,0,0,0,0,0,0,0,0,0,0,0,0,0,0,0,0
0,41,3,0,3,0,3,0,3,0,3,45,3,0,3,3,0,3,0,44,0,3,0,3,3,0,3,0,3,0,3,0,3,0,3,0,3,45,0
0,0,46,0,0,0,0,0,0,0,46,0,0,0,0,3,0,3,3,3,3,3,0,3,0,0,0,0,46,0,0,0,0,0,0,0,46,0,0
0,0,0,0,0,0,0,0,0,0,0,0,0,0,0,0,0,3,3,3,3,3,0,0,0,0,0,0,0,0,0,0,0,0,0,0,0,0,0
0,0,0,0,0,0,0,0,0,0,0,0,0,0,0,3,0,3,3,3,3,3,0,3,0,0,0,0,0,0,0,0,0,0,0,0,0,0,0
0,0,0,0,0,0,0,0,0,0,0,0,0,0,0,44,0,0,3,3,3,0,0,0,0,0,0,0,0,0,0,0,0,0,0,0,0,0,0
0,0,0,0,0,0,0,0,0,0,0,0,0,0,41,3,0,0,0,0,0,0,0,3,45,0,0,0,0,0,0,0,0,0,0,0,0,0,0
0,0,0,0,0,0,0,0,0,0,0,0,0,0,0,0,0,0,0,0,0,0,0,0,0,0,0,0,0,0,0,0,0,0,0,0,0,0,0
0,0,0,0,0,0,0,0,0,0,0,0,0,0,0,3,0,0,0,0,0,0,0,3,0,0,0,0,0,0,0,0,0,0,0,0,0,0,0
0,0,0,0,0,0,0,0,0,0,0,0,0,0,0,0,0,0,44,0,0,0,0,0,0,0,0,0,0,0,0,0,0,0,0,0,0,0,0
0,0,0,0,0,0,0,0,0,0,0,0,0,0,0,3,0,0,3,191,0,0,0,3,0,0,0,0,0,0,0,0,0,0,0,0,0,0,0
0,0,0,0,0,0,0,0,0,0,0,0,0,0,0,0,0,0,0,0,0,0,0,0,0,0,0,0,0,0,0,0,0,0,0,0,0,0,0
0,0,0,0,0,0,0,0,0,0,0,0,0,0,0,3,0,0,0,0,0,0,0,3,0,0,0,0,0,0,0,0,0,0,0,0,0,0,0
0,0,0,0,0,0,0,0,0,0,0,0,0,0,0,0,0,0,0,0,0,0,0,0,0,0,0,0,0,0,0,0,0,0,0,0,0,0,0
0,0,0,0,0,0,0,0,0,0,0,0,0,0,41,3,0,3,0,3,0,3,0,3,45,0,0,0,0,0,0,0,0,0,0,0,0,0,0
0,0,0,0,0,0,0,0,0,0,0,0,0,0,0,46,0,0,0,0,0,0,0,46,0,0,0,0,0,0,0,0,0,0,0,0,0,0,0
0,0,0,0,0,0,0,0,0,0,0,0,0,0,0,0,0,0,0,0,0,0,0,0,0,0,0,0,0,0,0,0,0,0,0,0,0,0,0
0,0,0,0,0,0,0,0,0,0,0,0,0,0,0,0,0,0,0,0,0,0,0,0,0,0,0,0,0,0,0,0,0,0,0,0,0,0,0
0,0,0,0,0,0,0,0,0,0,0,0,0,0,0,0,0,0,0,0,0,0,0,0,0,0,0,0,0,0,0,0,0,0,0,0,0,0,0
0,0,0,0,0,0,0,0,0,0,0,0,0,0,0,0,0,0,0,0,0,0,0,0,0,0,0,0,0,0,0,0,0,0,0,0,0,0,0
:endlayer
layer: 22
0,0,0,0,0,0,0,0,0,0,0,0,0,0,0,0,0,0,0,0,0,0,0,0,0,0,0,0,0,0,0,0,0,0,0,0,0,0,0
0,0,0,0,0,0,0,0,0,0,0,0,0,0,205,206,206,206,206,206,206,206,206,206,205,0,0,0,0,0,0,0,0,0,0,0,0,0,0
0,0,0,0,0,0,0,0,0,0,0,0,0,0,175,3,3,3,3,3,3,3,3,3,176,0,0,0,0,0,0,0,0,0,0,0,0,0,0
0,0,0,0,0,0,0,0,0,0,0,0,0,0,175,3,0,0,0,46,0,0,0,3,176,0,0,0,0,0,0,0,0,0,0,0,0,0,0
0,0,0,0,0,0,0,0,0,0,0,0,0,0,175,3,0,0,0,0,0,0,0,3,176,0,0,0,0,0,0,0,0,0,0,0,0,0,0
0,0,0,0,0,0,0,0,0,0,0,0,0,0,175,3,0,0,0,0,0,0,0,3,176,0,0,0,0,0,0,0,0,0,0,0,0,0,0
0,0,0,0,0,0,0,0,0,0,0,0,0,0,175,3,45,0,3,191,0,0,41,3,176,0,0,0,0,0,0,0,0,0,0,0,0,0,0
0,0,0,0,0,0,0,0,0,0,0,0,0,0,175,3,0,0,0,0,0,0,0,3,176,0,0,0,0,0,0,0,0,0,0,0,0,0,0
0,0,0,0,0,0,0,0,0,0,0,0,0,0,175,3,0,0,0,0,0,0,0,3,176,0,0,0,0,0,0,0,0,0,0,0,0,0,0
0,0,0,0,0,0,0,0,0,0,0,0,0,0,175,3,0,0,0,44,0,0,0,3,176,0,0,0,0,0,0,0,0,0,0,0,0,0,0
0,0,0,0,0,0,0,0,0,0,0,0,0,0,3,3,3,3,3,3,3,3,3,3,3,0,0,0,0,0,0,0,0,0,0,0,0,0,0
0,0,0,0,0,0,0,0,0,0,0,0,0,0,3,3,3,3,3,3,3,3,3,3,3,0,0,0,0,0,0,0,0,0,0,0,0,0,0
0,0,0,0,0,0,0,0,0,0,0,0,0,0,3,3,3,3,3,3,3,3,3,3,3,0,0,0,0,0,0,0,0,0,0,0,0,0,0
0,0,0,0,0,0,0,0,0,0,0,0,0,3,3,3,3,3,3,3,3,3,3,3,3,3,0,0,0,0,0,0,0,0,0,0,0,0,0
0,205,206,206,206,206,206,206,206,206,3,3,3,3,3,3,3,3,3,3,3,3,3,3,3,3,3,3,3,206,206,206,206,206,206,206,206,205,0
0,175,3,3,3,3,3,3,3,3,3,3,3,3,3,3,3,3,3,3,3,3,3,3,3,3,3,3,3,3,3,3,3,3,3,3,3,176,0
0,175,3,0,0,0,46,0,0,0,3,3,3,3,3,3,3,3,3,3,3,3,3,3,3,3,3,3,3,0,0,0,46,0,0,0,3,176,0
0,175,3,0,0,0,0,0,0,0,3,3,3,3,3,3,3,3,3,3,3,3,3,3,3,3,3,3,3,0,0,0,0,0,0,0,3,176,0
0,175,3,0,0,0,0,0,0,0,3,3,3,3,55,3,3,3,3,3,3,3,3,3,3,3,3,3,3,0,0,0,0,0,0,0,3,176,0
0,175,3,45,0,3,191,0,0,41,3,3,3,3,55,3,3,0,0,0,24,3,3,3,3,3,3,3,3,45,0,3,191,0,0,41,3,176,0
0,175,3,0,0,0,0,0,0,0,3,3,3,3,55,3,3,0,0,0,24,3,3,3,3,3,3,3,3,0,0,0,0,0,0,0,3,176,0
0,175,3,0,0,0,0,0,0,0,3,3,3,3,55,3,3,3,3,3,3,3,3,3,3,3,3,3,3,0,0,0,0,0,0,0,3,176,0
0,175,3,0,0,0,44,0,0,0,3,3,3,3,3,3,3,3,3,3,3,3,3,3,3,3,3,3,3,0,0,0,44,0,0,0,3,176,0
0,175,3,3,3,3,3,3,3,3,3,3,3,3,3,3,3,3,3,3,3,3,3,3,3,3,3,3,3,3,3,3,3,3,3,3,3,176,0
0,205,178,178,178,178,178,178,178,178,3,3,3,3,3,3,3,3,3,3,3,3,3,3,3,3,3,3,3,178,178,178,178,178,178,178,178,205,0
0,0,0,0,0,0,0,0,0,0,0,0,0,3,3,3,3,3,3,3,3,3,3,3,3,3,0,0,0,0,0,0,0,0,0,0,0,0,0
0,0,0,0,0,0,0,0,0,0,0,0,0,0,3,3,3,3,3,3,3,3,3,3,3,0,0,0,0,0,0,0,0,0,0,0,0,0,0
0,0,0,0,0,0,0,0,0,0,0,0,0,0,3,3,3,3,3,3,3,3,3,3,3,0,0,0,0,0,0,0,0,0,0,0,0,0,0
0,0,0,0,0,0,0,0,0,0,0,0,0,0,3,3,3,3,3,3,3,3,3,3,3,0,0,0,0,0,0,0,0,0,0,0,0,0,0
0,0,0,0,0,0,0,0,0,0,0,0,0,0,175,3,0,0,0,46,0,0,0,3,176,0,0,0,0,0,0,0,0,0,0,0,0,0,0
0,0,0,0,0,0,0,0,0,0,0,0,0,0,175,3,0,0,0,0,0,0,0,3,176,0,0,0,0,0,0,0,0,0,0,0,0,0,0
0,0,0,0,0,0,0,0,0,0,0,0,0,0,175,3,0,0,0,0,0,0,0,3,176,0,0,0,0,0,0,0,0,0,0,0,0,0,0
0,0,0,0,0,0,0,0,0,0,0,0,0,0,175,3,45,0,3,191,0,0,41,3,176,0,0,0,0,0,0,0,0,0,0,0,0,0,0
0,0,0,0,0,0,0,0,0,0,0,0,0,0,175,3,0,0,0,0,0,0,0,3,176,0,0,0,0,0,0,0,0,0,0,0,0,0,0
0,0,0,0,0,0,0,0,0,0,0,0,0,0,175,3,0,0,0,0,0,0,0,3,176,0,0,0,0,0,0,0,0,0,0,0,0,0,0
0,0,0,0,0,0,0,0,0,0,0,0,0,0,175,3,0,0,0,44,0,0,0,3,176,0,0,0,0,0,0,0,0,0,0,0,0,0,0
0,0,0,0,0,0,0,0,0,0,0,0,0,0,175,3,3,3,3,3,3,3,3,3,176,0,0,0,0,0,0,0,0,0,0,0,0,0,0
0,0,0,0,0,0,0,0,0,0,0,0,0,0,205,178,178,178,178,178,178,178,178,178,205,0,0,0,0,0,0,0,0,0,0,0,0,0,0
0,0,0,0,0,0,0,0,0,0,0,0,0,0,0,0,0,0,0,0,0,0,0,0,0,0,0,0,0,0,0,0,0,0,0,0,0,0,0
0,0,0,0,0,0,0,0,0,0,0,0,0,0,0,0,0,0,0,0,0,0,0,0,0,0,0,0,0,0,0,0,0,0,0,0,0,0,0
0,0,0,0,0,0,0,0,0,0,0,0,0,0,0,0,0,0,0,0,0,0,0,0,0,0,0,0,0,0,0,0,0,0,0,0,0,0,0
0,0,0,0,0,0,0,0,0,0,0,0,0,0,0,0,0,0,0,0,0,0,0,0,0,0,0,0,0,0,0,0,0,0,0,0,0,0,0
:endlayer
layer: 23
0,0,0,0,0,0,0,0,0,0,0,0,0,0,0,0,0,0,0,0,0,0,0,0,0,0,0,0,0,0,0,0,0,0,0,0,0,0,0
0,0,0,0,0,0,0,0,0,0,0,0,0,0,0,0,0,0,0,0,0,0,0,0,0,0,0,0,0,0,0,0,0,0,0,0,0,0,0
0,0,0,0,0,0,0,0,0,0,0,0,0,0,0,205,206,206,206,206,206,206,206,205,0,0,0,0,0,0,0,0,0,0,0,0,0,0,0
0,0,0,0,0,0,0,0,0,0,0,0,0,0,0,175,0,0,0,0,0,0,0,176,0,0,0,0,0,0,0,0,0,0,0,0,0,0,0
0,0,0,0,0,0,0,0,0,0,0,0,0,0,0,175,0,0,0,0,0,0,0,176,0,0,0,0,0,0,0,0,0,0,0,0,0,0,0
0,0,0,0,0,0,0,0,0,0,0,0,0,0,0,175,0,0,0,0,0,0,0,176,0,0,0,0,0,0,0,0,0,0,0,0,0,0,0
0,0,0,0,0,0,0,0,0,0,0,0,0,0,0,175,0,0,3,191,0,0,0,176,0,0,0,0,0,0,0,0,0,0,0,0,0,0,0
0,0,0,0,0,0,0,0,0,0,0,0,0,0,0,175,0,0,0,0,0,0,0,176,0,0,0,0,0,0,0,0,0,0,0,0,0,0,0
0,0,0,0,0,0,0,0,0,0,0,0,0,0,0,175,0,0,0,0,0,0,0,176,0,0,0,0,0,0,0,0,0,0,0,0,0,0,0
0,0,0,0,0,0,0,0,0,0,0,0,0,0,0,175,0,0,0,0,0,0,0,176,0,0,0,0,0,0,0,0,0,0,0,0,0,0,0
0,0,0,0,0,0,0,0,0,0,0,0,0,0,3,3,3,3,3,3,3,3,3,3,3,0,0,0,0,0,0,0,0,0,0,0,0,0,0
0,0,0,0,0,0,0,0,0,0,0,0,0,0,3,145,145,145,145,145,145,145,145,145,3,0,0,0,0,0,0,0,0,0,0,0,0,0,0
0,0,0,0,0,0,0,0,0,0,0,0,3,3,3,145,145,3,3,3,3,3,145,145,3,3,3,0,0,0,0,0,0,0,0,0,0,0,0
0,0,0,0,0,0,0,0,0,0,0,0,3,145,145,145,145,3,3,3,3,3,145,145,145,145,3,0,0,0,0,0,0,0,0,0,0,0,0
0,0,0,0,0,0,0,0,0,0,3,3,3,145,145,145,145,3,3,3,3,3,145,145,145,145,3,3,3,0,0,0,0,0,0,0,0,0,0
0,0,205,206,206,206,206,206,206,206,3,145,145,145,145,145,3,3,3,3,26,0,3,145,145,145,145,145,3,206,206,206,206,206,206,206,205,0,0
0,0,175,0,0,0,0,0,0,0,3,145,145,145,145,3,3,3,3,3,26,0,0,3,145,145,145,145,3,0,0,0,0,0,0,0,176,0,0
0,0,175,0,0,0,0,0,0,0,3,145,3,3,3,0,0,0,0,0,0,0,0,0,3,3,3,145,3,0,0,0,0,0,0,0,176,0,0
0,0,175,0,0,0,0,0,0,0,3,145,3,3,55,0,0,0,0,0,0,0,0,0,3,3,3,145,3,0,0,0,0,0,0,0,176,0,0
0,0,175,0,0,3,191,0,0,0,3,145,3,0,0,0,0,0,0,0,0,207,0,0,0,0,3,145,3,0,0,3,191,0,0,0,176,0,0
0,0,175,0,0,0,0,0,0,0,3,145,3,3,55,0,0,0,0,0,0,208,0,0,3,3,3,145,3,0,0,0,0,0,0,0,176,0,0
0,0,175,0,0,0,0,0,0,0,3,145,3,3,55,0,0,0,0,0,0,0,0,0,3,3,3,145,3,0,0,0,0,0,0,0,176,0,0
0,0,175,0,0,0,0,0,0,0,3,145,145,145,145,3,0,0,0,0,0,0,0,3,145,145,145,145,3,0,0,0,0,0,0,0,176,0,0
0,0,205,178,178,178,178,178,178,178,3,145,145,145,145,145,3,0,0,0,0,0,3,145,145,145,145,145,3,178,178,178,178,178,178,178,205,0,0
0,0,0,0,0,0,0,0,0,0,3,3,3,145,145,145,145,3,3,0,3,3,145,145,145,145,3,3,3,0,0,0,0,0,0,0,0,0,0
0,0,0,0,0,0,0,0,0,0,0,0,3,145,145,145,145,3,3,209,3,3,145,145,145,145,3,0,0,0,0,0,0,0,0,0,0,0,0
0,0,0,0,0,0,0,0,0,0,0,0,3,3,3,145,145,3,3,0,3,3,145,145,3,3,3,0,0,0,0,0,0,0,0,0,0,0,0
0,0,0,0,0,0,0,0,0,0,0,0,0,0,3,145,145,145,145,145,145,145,145,145,3,0,0,0,0,0,0,0,0,0,0,0,0,0,0
0,0,0,0,0,0,0,0,0,0,0,0,0,0,3,3,3,3,3,3,3,3,3,3,3,0,0,0,0,0,0,0,0,0,0,0,0,0,0
0,0,0,0,0,0,0,0,0,0,0,0,0,0,0,175,0,0,0,0,0,0,0,176,0,0,0,0,0,0,0,0,0,0,0,0,0,0,0
0,0,0,0,0,0,0,0,0,0,0,0,0,0,0,175,0,0,0,0,0,0,0,176,0,0,0,0,0,0,0,0,0,0,0,0,0,0,0
0,0,0,0,0,0,0,0,0,0,0,0,0,0,0,175,0,0,0,0,0,0,0,176,0,0,0,0,0,0,0,0,0,0,0,0,0,0,0
0,0,0,0,0,0,0,0,0,0,0,0,0,0,0,175,0,0,3,191,0,0,0,176,0,0,0,0,0,0,0,0,0,0,0,0,0,0,0
0,0,0,0,0,0,0,0,0,0,0,0,0,0,0,175,0,0,0,0,0,0,0,176,0,0,0,0,0,0,0,0,0,0,0,0,0,0,0
0,0,0,0,0,0,0,0,0,0,0,0,0,0,0,175,0,0,0,0,0,0,0,176,0,0,0,0,0,0,0,0,0,0,0,0,0,0,0
0,0,0,0,0,0,0,0,0,0,0,0,0,0,0,175,0,0,0,0,0,0,0,176,0,0,0,0,0,0,0,0,0,0,0,0,0,0,0
0,0,0,0,0,0,0,0,0,0,0,0,0,0,0,205,178,178,178,178,178,178,178,205,0,0,0,0,0,0,0,0,0,0,0,0,0,0,0
0,0,0,0,0,0,0,0,0,0,0,0,0,0,0,0,0,0,0,0,0,0,0,0,0,0,0,0,0,0,0,0,0,0,0,0,0,0,0
0,0,0,0,0,0,0,0,0,0,0,0,0,0,0,0,0,0,0,0,0,0,0,0,0,0,0,0,0,0,0,0,0,0,0,0,0,0,0
0,0,0,0,0,0,0,0,0,0,0,0,0,0,0,0,0,0,0,0,0,0,0,0,0,0,0,0,0,0,0,0,0,0,0,0,0,0,0
0,0,0,0,0,0,0,0,0,0,0,0,0,0,0,0,0,0,0,0,0,0,0,0,0,0,0,0,0,0,0,0,0,0,0,0,0,0,0
0,0,0,0,0,0,0,0,0,0,0,0,0,0,0,0,0,0,0,0,0,0,0,0,0,0,0,0,0,0,0,0,0,0,0,0,0,0,0
:endlayer
layer: 24
0,0,0,0,0,0,0,0,0,0,0,0,0,0,0,0,0,0,0,0,0,0,0,0,0,0,0,0,0,0,0,0,0,0,0,0,0,0,0
0,0,0,0,0,0,0,0,0,0,0,0,0,0,0,0,0,0,0,0,0,0,0,0,0,0,0,0,0,0,0,0,0,0,0,0,0,0,0
0,0,0,0,0,0,0,0,0,0,0,0,0,0,0,0,0,0,0,0,0,0,0,0,0,0,0,0,0,0,0,0,0,0,0,0,0,0,0
0,0,0,0,0,0,0,0,0,0,0,0,0,0,0,0,205,206,206,206,206,206,205,0,0,0,0,0,0,0,0,0,0,0,0,0,0,0,0
0,0,0,0,0,0,0,0,0,0,0,0,0,0,0,0,175,0,0,0,0,0,176,0,0,0,0,0,0,0,0,0,0,0,0,0,0,0,0
0,0,0,0,0,0,0,0,0,0,0,0,0,0,0,0,175,0,0,0,0,0,176,0,0,0,0,0,0,0,0,0,0,0,0,0,0,0,0
0,0,0,0,0,0,0,0,0,0,0,0,0,0,0,0,175,0,3,191,0,0,176,0,0,0,0,0,0,0,0,0,0,0,0,0,0,0,0
0,0,0,0,0,0,0,0,0,0,0,0,0,0,0,0,175,0,0,0,0,0,176,0,0,0,0,0,0,0,0,0,0,0,0,0,0,0,0
0,0,0,0,0,0,0,0,0,0,0,0,0,0,0,0,175,0,0,0,0,0,176,0,0,0,0,0,0,0,0,0,0,0,0,0,0,0,0
0,0,0,0,0,0,0,0,0,0,0,0,0,0,0,0,205,178,178,178,178,178,205,0,0,0,0,0,0,0,0,0,0,0,0,0,0,0,0
0,0,0,0,0,0,0,0,0,0,0,0,0,0,86,0,0,0,0,0,0,0,0,0,86,0,0,0,0,0,0,0,0,0,0,0,0,0,0
0,0,0,0,0,0,0,0,0,0,0,0,0,0,0,0,0,0,0,0,0,0,0,0,0,0,0,0,0,0,0,0,0,0,0,0,0,0,0
0,0,0,0,0,0,0,0,0,0,0,0,0,0,0,0,0,3,3,3,3,3,0,0,0,0,0,0,0,0,0,0,0,0,0,0,0,0,0
0,0,0,0,0,0,0,0,0,0,0,0,0,210,0,0,0,3,3,3,3,3,0,0,0,211,0,0,0,0,0,0,0,0,0,0,0,0,0
0,0,0,0,0,0,0,0,0,0,86,0,0,0,0,0,0,3,3,3,3,3,0,0,0,0,0,0,86,0,0,0,0,0,0,0,0,0,0
0,0,0,0,0,0,0,0,0,0,0,0,0,0,0,0,3,3,3,26,0,0,3,0,0,0,0,0,0,0,0,0,0,0,0,0,0,0,0
0,0,0,205,206,206,206,206,206,205,0,0,0,0,0,3,3,3,3,26,0,0,0,3,0,0,0,0,0,205,206,206,206,206,206,205,0,0,0
0,0,0,175,0,0,0,0,0,212,0,0,3,3,3,0,0,0,0,0,0,0,0,0,3,3,3,0,0,175,0,0,0,0,0,176,0,0,0
0,0,0,175,0,0,0,0,0,212,0,0,3,3,55,0,0,0,0,0,0,0,0,0,3,3,3,0,0,175,0,0,0,0,0,176,0,0,0
0,0,0,175,0,3,191,0,0,212,0,0,213,0,0,0,0,0,0,0,0,0,0,0,0,0,213,0,0,175,0,3,191,0,0,176,0,0,0
0,0,0,175,0,0,0,0,0,212,0,0,3,3,55,0,0,0,0,0,0,0,0,0,3,3,3,0,0,175,0,0,0,0,0,176,0,0,0
0,0,0,175,0,0,0,0,0,176,0,0,3,3,55,0,0,0,0,0,0,0,0,0,3,3,3,0,0,175,0,0,0,0,0,176,0,0,0
0,0,0,205,178,178,178,178,178,205,0,0,0,0,0,3,0,0,0,0,0,0,0,3,0,0,0,0,0,205,178,178,178,178,178,205,0,0,0
0,0,0,0,0,0,0,0,0,0,0,0,0,0,0,0,3,0,0,0,0,0,3,0,0,0,0,0,0,0,0,0,0,0,0,0,0,0,0
0,0,0,0,0,0,0,0,0,0,86,0,0,0,0,0,0,3,3,0,3,3,0,0,0,0,0,0,86,0,0,0,0,0,0,0,0,0,0
0,0,0,0,0,0,0,0,0,0,0,0,0,214,0,0,0,3,3,215,3,3,0,0,0,216,0,0,0,0,0,0,0,0,0,0,0,0,0
0,0,0,0,0,0,0,0,0,0,0,0,0,0,0,0,0,3,3,0,3,3,0,0,0,0,0,0,0,0,0,0,0,0,0,0,0,0,0
0,0,0,0,0,0,0,0,0,0,0,0,0,0,0,0,0,0,0,0,0,0,0,0,0,0,0,0,0,0,0,0,0,0,0,0,0,0,0
0,0,0,0,0,0,0,0,0,0,0,0,0,0,86,0,0,0,0,0,0,0,0,0,86,0,0,0,0,0,0,0,0,0,0,0,0,0,0
0,0,0,0,0,0,0,0,0,0,0,0,0,0,0,0,205,206,206,206,206,206,205,0,0,0,0,0,0,0,0,0,0,0,0,0,0,0,0
0,0,0,0,0,0,0,0,0,0,0,0,0,0,0,0,175,0,0,0,0,0,176,0,0,0,0,0,0,0,0,0,0,0,0,0,0,0,0
0,0,0,0,0,0,0,0,0,0,0,0,0,0,0,0,175,0,0,0,0,0,176,0,0,0,0,0,0,0,0,0,0,0,0,0,0,0,0
0,0,0,0,0,0,0,0,0,0,0,0,0,0,0,0,175,0,3,191,0,0,176,0,0,0,0,0,0,0,0,0,0,0,0,0,0,0,0
0,0,0,0,0,0,0,0,0,0,0,0,0,0,0,0,175,0,0,0,0,0,176,0,0,0,0,0,0,0,0,0,0,0,0,0,0,0,0
0,0,0,0,0,0,0,0,0,0,0,0,0,0,0,0,175,0,0,0,0,0,176,0,0,0,0,0,0,0,0,0,0,0,0,0,0,0,0
0,0,0,0,0,0,0,0,0,0,0,0,0,0,0,0,205,178,178,178,178,178,205,0,0,0,0,0,0,0,0,0,0,0,0,0,0,0,0
0,0,0,0,0,0,0,0,0,0,0,0,0,0,0,0,0,0,0,0,0,0,0,0,0,0,0,0,0,0,0,0,0,0,0,0,0,0,0
0,0,0,0,0,0,0,0,0,0,0,0,0,0,0,0,0,0,0,0,0,0,0,0,0,0,0,0,0,0,0,0,0,0,0,0,0,0,0
0,0,0,0,0,0,0,0,0,0,0,0,0,0,0,0,0,0,0,0,0,0,0,0,0,0,0,0,0,0,0,0,0,0,0,0,0,0,0
0,0,0,0,0,0,0,0,0,0,0,0,0,0,0,0,0,0,0,0,0,0,0,0,0,0,0,0,0,0,0,0,0,0,0,0,0,0,0
0,0,0,0,0,0,0,0,0,0,0,0,0,0,0,0,0,0,0,0,0,0,0,0,0,0,0,0,0,0,0,0,0,0,0,0,0,0,0
0,0,0,0,0,0,0,0,0,0,0,0,0,0,0,0,0,0,0,0,0,0,0,0,0,0,0,0,0,0,0,0,0,0,0,0,0,0,0
:endlayer
layer: 25
0,0,0,0,0,0,0,0,0,0,0,0,0,0,0,0,0,0,0,0,0,0,0,0,0,0,0,0,0,0,0,0,0,0,0,0,0,0,0
0,0,0,0,0,0,0,0,0,0,0,0,0,0,0,0,0,0,0,0,0,0,0,0,0,0,0,0,0,0,0,0,0,0,0,0,0,0,0
0,0,0,0,0,0,0,0,0,0,0,0,0,0,0,0,0,0,0,0,0,0,0,0,0,0,0,0,0,0,0,0,0,0,0,0,0,0,0
0,0,0,0,0,0,0,0,0,0,0,0,0,0,0,0,0,0,0,0,0,0,0,0,0,0,0,0,0,0,0,0,0,0,0,0,0,0,0
0,0,0,0,0,0,0,0,0,0,0,0,0,0,0,0,0,205,206,206,206,205,0,0,0,0,0,0,0,0,0,0,0,0,0,0,0,0,0
0,0,0,0,0,0,0,0,0,0,0,0,0,0,0,0,0,175,0,0,0,176,0,0,0,0,0,0,0,0,0,0,0,0,0,0,0,0,0
0,0,0,0,0,0,0,0,0,0,0,0,0,0,0,0,0,175,3,191,0,176,0,0,0,0,0,0,0,0,0,0,0,0,0,0,0,0,0
0,0,0,0,0,0,0,0,0,0,0,0,0,0,0,0,0,175,0,0,0,176,0,0,0,0,0,0,0,0,0,0,0,0,0,0,0,0,0
0,0,0,0,0,0,0,0,0,0,0,0,0,0,0,0,0,205,178,178,178,205,0,0,0,0,0,0,0,0,0,0,0,0,0,0,0,0,0
0,0,0,0,0,0,0,0,0,0,0,0,0,0,0,0,0,0,0,0,0,0,0,0,0,0,0,0,0,0,0,0,0,0,0,0,0,0,0
0,0,0,0,0,0,0,0,0,0,0,0,0,0,0,0,0,0,0,0,0,0,0,0,0,0,0,0,0,0,0,0,0,0,0,0,0,0,0
0,0,0,0,0,0,0,0,0,0,0,0,0,0,0,0,0,0,0,0,0,0,0,0,0,0,0,0,0,0,0,0,0,0,0,0,0,0,0
0,0,0,0,0,0,0,0,0,0,0,0,0,0,0,0,0,3,3,3,3,3,0,0,0,0,0,0,0,0,0,0,0,0,0,0,0,0,0
0,0,0,0,0,0,0,0,0,0,0,0,0,0,0,0,0,3,3,3,3,3,0,0,0,0,0,0,0,0,0,0,0,0,0,0,0,0,0
0,0,0,0,0,0,0,0,0,0,0,0,0,0,0,0,41,3,3,3,3,3,45,0,0,0,0,0,0,0,0,0,0,0,0,0,0,0,0
0,0,0,0,0,0,0,0,0,0,0,0,0,0,0,0,3,3,26,0,0,0,3,0,0,0,0,0,0,0,0,0,0,0,0,0,0,0,0
0,0,0,0,0,0,0,0,0,0,0,0,0,0,44,3,3,3,26,0,0,0,0,3,44,0,0,0,0,0,0,0,0,0,0,0,0,0,0
0,0,0,0,205,206,206,206,205,0,0,0,3,3,3,45,0,0,0,0,0,0,0,46,3,3,3,0,0,0,205,206,206,206,205,0,0,0,0
0,0,0,0,175,0,0,0,212,0,0,0,3,3,3,0,0,0,0,0,0,0,0,0,3,3,3,0,0,0,175,0,0,0,176,0,0,0,0
0,0,0,0,175,3,191,0,212,0,0,0,213,0,0,0,0,0,0,0,0,0,0,0,0,0,213,0,0,0,175,3,191,0,176,0,0,0,0
0,0,0,0,175,0,0,0,176,0,0,0,3,3,3,0,0,0,0,0,0,0,0,0,3,3,3,0,0,0,175,0,0,0,176,0,0,0,0
0,0,0,0,205,178,178,178,205,0,0,0,3,3,3,0,0,0,0,0,0,0,0,0,3,3,3,0,0,0,205,178,178,178,205,0,0,0,0
0,0,0,0,0,0,0,0,0,0,0,0,0,0,46,3,45,0,0,0,0,0,44,3,46,0,0,0,0,0,0,0,0,0,0,0,0,0,0
0,0,0,0,0,0,0,0,0,0,0,0,0,0,0,0,3,0,0,0,0,0,3,0,0,0,0,0,0,0,0,0,0,0,0,0,0,0,0
0,0,0,0,0,0,0,0,0,0,0,0,0,0,0,0,41,3,3,44,3,3,45,0,0,0,0,0,0,0,0,0,0,0,0,0,0,0,0
0,0,0,0,0,0,0,0,0,0,0,0,0,0,0,0,0,3,3,3,3,3,0,0,0,0,0,0,0,0,0,0,0,0,0,0,0,0,0
0,0,0,0,0,0,0,0,0,0,0,0,0,0,0,0,0,3,3,46,3,3,0,0,0,0,0,0,0,0,0,0,0,0,0,0,0,0,0
0,0,0,0,0,0,0,0,0,0,0,0,0,0,0,0,0,0,0,0,0,0,0,0,0,0,0,0,0,0,0,0,0,0,0,0,0,0,0
0,0,0,0,0,0,0,0,0,0,0,0,0,0,0,0,0,0,0,0,0,0,0,0,0,0,0,0,0,0,0,0,0,0,0,0,0,0,0
0,0,0,0,0,0,0,0,0,0,0,0,0,0,0,0,0,0,0,0,0,0,0,0,0,0,0,0,0,0,0,0,0,0,0,0,0,0,0
0,0,0,0,0,0,0,0,0,0,0,0,0,0,0,0,0,205,206,206,206,205,0,0,0,0,0,0,0,0,0,0,0,0,0,0,0,0,0
0,0,0,0,0,0,0,0,0,0,0,0,0,0,0,0,0,175,0,0,0,176,0,0,0,0,0,0,0,0,0,0,0,0,0,0,0,0,0
0,0,0,0,0,0,0,0,0,0,0,0,0,0,0,0,0,175,3,191,0,176,0,0,0,0,0,0,0,0,0,0,0,0,0,0,0,0,0
0,0,0,0,0,0,0,0,0,0,0,0,0,0,0,0,0,175,0,0,0,176,0,0,0,0,0,0,0,0,0,0,0,0,0,0,0,0,0
0,0,0,0,0,0,0,0,0,0,0,0,0,0,0,0,0,205,178,178,178,205,0,0,0,0,0,0,0,0,0,0,0,0,0,0,0,0,0
0,0,0,0,0,0,0,0,0,0,0,0,0,0,0,0,0,0,0,0,0,0,0,0,0,0,0,0,0,0,0,0,0,0,0,0,0,0,0
0,0,0,0,0,0,0,0,0,0,0,0,0,0,0,0,0,0,0,0,0,0,0,0,0,0,0,0,0,0,0,0,0,0,0,0,0,0,0
0,0,0,0,0,0,0,0,0,0,0,0,0,0,0,0,0,0,0,0,0,0,0,0,0,0,0,0,0,0,0,0,0,0,0,0,0,0,0
0,0,0,0,0,0,0,0,0,0,0,0,0,0,0,0,0,0,0,0,0,0,0,0,0,0,0,0,0,0,0,0,0,0,0,0,0,0,0
0,0,0,0,0,0,0,0,0,0,0,0,0,0,0,0,0,0,0,0,0,0,0,0,0,0,0,0,0,0,0,0,0,0,0,0,0,0,0
0,0,0,0,0,0,0,0,0,0,0,0,0,0,0,0,0,0,0,0,0,0,0,0,0,0,0,0,0,0,0,0,0,0,0,0,0,0,0
0,0,0,0,0,0,0,0,0,0,0,0,0,0,0,0,0,0,0,0,0,0,0,0,0,0,0,0,0,0,0,0,0,0,0,0,0,0,0
:endlayer
layer: 26
0,0,0,0,0,0,0,0,0,0,0,0,0,0,0,0,0,0,0,0,0,0,0,0,0,0,0,0,0,0,0,0,0,0,0,0,0,0,0
0,0,0,0,0,0,0,0,0,0,0,0,0,0,0,0,0,0,0,0,0,0,0,0,0,0,0,0,0,0,0,0,0,0,0,0,0,0,0
0,0,0,0,0,0,0,0,0,0,0,0,0,0,0,0,0,0,0,0,0,0,0,0,0,0,0,0,0,0,0,0,0,0,0,0,0,0,0
0,0,0,0,0,0,0,0,0,0,0,0,0,0,0,0,0,0,0,0,0,0,0,0,0,0,0,0,0,0,0,0,0,0,0,0,0,0,0
0,0,0,0,0,0,0,0,0,0,0,0,0,0,0,0,0,0,0,0,0,0,0,0,0,0,0,0,0,0,0,0,0,0,0,0,0,0,0
0,0,0,0,0,0,0,0,0,0,0,0,0,0,0,0,0,0,206,206,206,0,0,0,0,0,0,0,0,0,0,0,0,0,0,0,0,0,0
0,0,0,0,0,0,0,0,0,0,0,0,0,0,0,0,0,0,175,0,176,0,0,0,0,0,0,0,0,0,0,0,0,0,0,0,0,0,0
0,0,0,0,0,0,0,0,0,0,0,0,0,0,0,0,0,0,175,177,176,0,0,0,0,0,0,0,0,0,0,0,0,0,0,0,0,0,0
0,0,0,0,0,0,0,0,0,0,0,0,0,0,0,0,0,0,0,0,0,0,0,0,0,0,0,0,0,0,0,0,0,0,0,0,0,0,0
0,0,0,0,0,0,0,0,0,0,0,0,0,0,0,0,0,0,0,0,0,0,0,0,0,0,0,0,0,0,0,0,0,0,0,0,0,0,0
0,0,0,0,0,0,0,0,0,0,0,0,0,0,0,0,0,0,0,0,0,0,0,0,0,0,0,0,0,0,0,0,0,0,0,0,0,0,0
0,0,0,0,0,0,0,0,0,0,0,0,0,0,0,0,0,0,0,0,0,0,0,0,0,0,0,0,0,0,0,0,0,0,0,0,0,0,0
0,0,0,0,0,0,0,0,0,0,0,0,0,0,0,0,0,3,3,3,3,3,0,0,0,0,0,0,0,0,0,0,0,0,0,0,0,0,0
0,0,0,0,0,0,0,0,0,0,0,0,0,0,0,0,0,3,3,3,3,3,0,0,0,0,0,0,0,0,0,0,0,0,0,0,0,0,0
0,0,0,0,0,0,0,0,0,0,0,0,0,0,0,0,3,3,3,3,3,3,0,0,0,0,0,0,0,0,0,0,0,0,0,0,0,0,0
0,0,0,0,0,0,0,0,0,0,0,0,0,0,0,3,3,26,0,0,0,0,3,3,0,0,0,0,0,0,0,0,0,0,0,0,0,0,0
0,0,0,0,0,0,0,0,0,0,0,0,0,0,3,3,3,26,0,0,0,0,3,3,3,0,0,0,0,0,0,0,0,0,0,0,0,0,0
0,0,0,0,0,0,0,0,0,0,0,0,3,3,3,3,3,3,3,3,3,3,3,3,3,3,3,0,0,0,0,0,0,0,0,0,0,0,0
0,0,0,0,0,205,206,206,0,0,0,0,3,3,3,3,3,3,3,3,3,3,3,3,3,3,3,0,0,0,0,205,206,205,0,0,0,0,0
0,0,0,0,0,175,0,176,0,0,0,0,3,3,3,3,3,3,3,3,3,3,3,3,3,3,3,0,0,0,0,175,0,176,0,0,0,0,0
0,0,0,0,0,175,177,176,0,0,0,0,3,3,3,3,3,3,3,3,3,3,3,3,3,3,3,0,0,0,0,175,177,176,0,0,0,0,0
0,0,0,0,0,0,0,0,0,0,0,0,3,3,3,3,3,3,3,3,3,3,3,3,3,3,3,0,0,0,0,0,0,0,0,0,0,0,0
0,0,0,0,0,0,0,0,0,0,0,0,0,0,3,3,3,3,3,3,3,3,3,3,3,0,0,0,0,0,0,0,0,0,0,0,0,0,0
0,0,0,0,0,0,0,0,0,0,0,0,0,0,0,3,3,3,3,3,3,3,3,3,0,0,0,0,0,0,0,0,0,0,0,0,0,0,0
0,0,0,0,0,0,0,0,0,0,0,0,0,0,0,0,3,3,3,3,3,3,3,0,0,0,0,0,0,0,0,0,0,0,0,0,0,0,0
0,0,0,0,0,0,0,0,0,0,0,0,0,0,0,0,0,3,3,3,3,3,0,0,0,0,0,0,0,0,0,0,0,0,0,0,0,0,0
0,0,0,0,0,0,0,0,0,0,0,0,0,0,0,0,0,3,3,3,3,3,0,0,0,0,0,0,0,0,0,0,0,0,0,0,0,0,0
0,0,0,0,0,0,0,0,0,0,0,0,0,0,0,0,0,0,0,46,0,0,0,0,0,0,0,0,0,0,0,0,0,0,0,0,0,0,0
0,0,0,0,0,0,0,0,0,0,0,0,0,0,0,0,0,0,0,0,0,0,0,0,0,0,0,0,0,0,0,0,0,0,0,0,0,0,0
0,0,0,0,0,0,0,0,0,0,0,0,0,0,0,0,0,0,0,0,0,0,0,0,0,0,0,0,0,0,0,0,0,0,0,0,0,0,0
0,0,0,0,0,0,0,0,0,0,0,0,0,0,0,0,0,0,0,0,0,0,0,0,0,0,0,0,0,0,0,0,0,0,0,0,0,0,0
0,0,0,0,0,0,0,0,0,0,0,0,0,0,0,0,0,0,175,206,205,0,0,0,0,0,0,0,0,0,0,0,0,0,0,0,0,0,0
0,0,0,0,0,0,0,0,0,0,0,0,0,0,0,0,0,0,175,0,176,0,0,0,0,0,0,0,0,0,0,0,0,0,0,0,0,0,0
0,0,0,0,0,0,0,0,0,0,0,0,0,0,0,0,0,0,175,177,176,0,0,0,0,0,0,0,0,0,0,0,0,0,0,0,0,0,0
0,0,0,0,0,0,0,0,0,0,0,0,0,0,0,0,0,0,0,0,0,0,0,0,0,0,0,0,0,0,0,0,0,0,0,0,0,0,0
0,0,0,0,0,0,0,0,0,0,0,0,0,0,0,0,0,0,0,0,0,0,0,0,0,0,0,0,0,0,0,0,0,0,0,0,0,0,0
0,0,0,0,0,0,0,0,0,0,0,0,0,0,0,0,0,0,0,0,0,0,0,0,0,0,0,0,0,0,0,0,0,0,0,0,0,0,0
0,0,0,0,0,0,0,0,0,0,0,0,0,0,0,0,0,0,0,0,0,0,0,0,0,0,0,0,0,0,0,0,0,0,0,0,0,0,0
0,0,0,0,0,0,0,0,0,0,0,0,0,0,0,0,0,0,0,0,0,0,0,0,0,0,0,0,0,0,0,0,0,0,0,0,0,0,0
0,0,0,0,0,0,0,0,0,0,0,0,0,0,0,0,0,0,0,0,0,0,0,0,0,0,0,0,0,0,0,0,0,0,0,0,0,0,0
0,0,0,0,0,0,0,0,0,0,0,0,0,0,0,0,0,0,0,0,0,0,0,0,0,0,0,0,0,0,0,0,0,0,0,0,0,0,0
0,0,0,0,0,0,0,0,0,0,0,0,0,0,0,0,0,0,0,0,0,0,0,0,0,0,0,0,0,0,0,0,0,0,0,0,0,0,0
:endlayer
layer: 27
0,0,0,0,0,0,0,0,0,0,0,0,0,0,0,0,0,0,0,0,0,0,0,0,0,0,0,0,0,0,0,0,0,0,0,0,0,0,0
0,0,0,0,0,0,0,0,0,0,0,0,0,0,0,0,0,0,0,0,0,0,0,0,0,0,0,0,0,0,0,0,0,0,0,0,0,0,0
0,0,0,0,0,0,0,0,0,0,0,0,0,0,0,0,0,0,0,0,0,0,0,0,0,0,0,0,0,0,0,0,0,0,0,0,0,0,0
0,0,0,0,0,0,0,0,0,0,0,0,0,0,0,0,0,0,0,0,0,0,0,0,0,0,0,0,0,0,0,0,0,0,0,0,0,0,0
0,0,0,0,0,0,0,0,0,0,0,0,0,0,0,0,0,0,0,0,0,0,0,0,0,0,0,0,0,0,0,0,0,0,0,0,0,0,0
0,0,0,0,0,0,0,0,0,0,0,0,0,0,0,0,0,0,0,0,0,0,0,0,0,0,0,0,0,0,0,0,0,0,0,0,0,0,0
0,0,0,0,0,0,0,0,0,0,0,0,0,0,0,0,0,0,0,217,0,0,0,0,0,0,0,0,0,0,0,0,0,0,0,0,0,0,0
0,0,0,0,0,0,0,0,0,0,0,0,0,0,0,0,0,0,41,177,45,0,0,0,0,0,0,0,0,0,0,0,0,0,0,0,0,0,0
0,0,0,0,0,0,0,0,0,0,0,0,0,0,0,0,0,0,0,46,0,0,0,0,0,0,0,0,0,0,0,0,0,0,0,0,0,0,0
0,0,0,0,0,0,0,0,0,0,0,0,0,0,0,0,0,0,0,0,0,0,0,0,0,0,0,0,0,0,0,0,0,0,0,0,0,0,0
0,0,0,0,0,0,0,0,0,0,0,0,0,0,0,0,0,0,0,0,0,0,0,0,0,0,0,0,0,0,0,0,0,0,0,0,0,0,0
0,0,0,0,0,0,0,0,0,0,0,0,0,0,0,0,0,148,148,148,148,148,0,0,0,0,0,0,0,0,0,0,0,0,0,0,0,0,0
0,0,0,0,0,0,0,0,0,0,0,0,0,0,0,0,0,3,3,3,3,3,0,0,0,0,0,0,0,0,0,0,0,0,0,0,0,0,0
0,0,0,0,0,0,0,0,0,0,0,0,0,0,0,0,3,0,0,218,3,3,3,0,0,0,0,0,0,0,0,0,0,0,0,0,0,0,0
0,0,0,0,0,0,0,0,0,0,0,0,0,0,0,3,0,0,0,0,3,3,3,3,0,0,0,0,0,0,0,0,0,0,0,0,0,0,0
0,0,0,0,0,0,0,0,0,0,0,0,0,0,3,0,0,0,0,0,0,3,26,0,3,0,0,0,0,0,0,0,0,0,0,0,0,0,0
0,0,0,0,0,0,0,0,0,0,0,0,0,3,0,0,0,0,0,0,0,3,26,0,0,3,0,0,0,0,0,0,0,0,0,0,0,0,0
0,0,0,0,0,0,0,0,0,0,0,24,3,0,0,0,0,3,3,3,3,3,3,16,3,219,3,26,0,0,0,0,0,0,0,0,0,0,0
0,0,0,0,0,0,0,0,0,0,0,24,3,0,0,0,0,0,3,85,3,0,0,0,0,0,3,26,0,0,0,0,0,0,0,0,0,0,0
0,0,0,0,0,0,217,0,0,0,0,24,3,0,0,0,0,0,64,220,64,0,0,0,0,221,3,26,0,0,0,0,217,0,0,0,0,0,0
0,0,0,0,0,41,177,45,0,0,0,24,3,0,0,0,0,0,222,222,222,0,0,0,0,221,3,26,0,0,0,41,177,45,0,0,0,0,0
0,0,0,0,0,0,46,0,0,0,0,24,3,0,0,0,0,223,222,222,222,221,0,0,0,0,3,26,0,0,0,0,46,0,0,0,0,0,0
0,0,0,0,0,0,0,0,0,0,0,0,0,3,0,0,0,223,222,222,222,221,0,0,224,3,0,0,0,0,0,0,0,0,0,0,0,0,0
0,0,0,0,0,0,0,0,0,0,0,0,0,0,3,0,0,0,222,222,222,0,0,225,3,0,0,0,0,0,0,0,0,0,0,0,0,0,0
0,0,0,0,0,0,0,0,0,0,0,0,0,0,0,3,0,0,222,222,222,226,227,3,0,0,0,0,0,0,0,0,0,0,0,0,0,0,0
0,0,0,0,0,0,0,0,0,0,0,0,0,0,0,0,3,0,228,0,228,0,3,0,0,0,0,0,0,0,0,0,0,0,0,0,0,0,0
0,0,0,0,0,0,0,0,0,0,0,0,0,0,0,0,0,3,3,3,3,3,0,0,0,0,0,0,0,0,0,0,0,0,0,0,0,0,0
0,0,0,0,0,0,0,0,0,0,0,0,0,0,0,0,0,64,64,64,64,64,0,0,0,0,0,0,0,0,0,0,0,0,0,0,0,0,0
0,0,0,0,0,0,0,0,0,0,0,0,0,0,0,0,0,0,0,0,0,0,0,0,0,0,0,0,0,0,0,0,0,0,0,0,0,0,0
0,0,0,0,0,0,0,0,0,0,0,0,0,0,0,0,0,0,0,0,0,0,0,0,0,0,0,0,0,0,0,0,0,0,0,0,0,0,0
0,0,0,0,0,0,0,0,0,0,0,0,0,0,0,0,0,0,0,0,0,0,0,0,0,0,0,0,0,0,0,0,0,0,0,0,0,0,0
0,0,0,0,0,0,0,0,0,0,0,0,0,0,0,0,0,0,0,0,0,0,0,0,0,0,0,0,0,0,0,0,0,0,0,0,0,0,0
0,0,0,0,0,0,0,0,0,0,0,0,0,0,0,0,0,0,0,217,0,0,0,0,0,0,0,0,0,0,0,0,0,0,0,0,0,0,0
0,0,0,0,0,0,0,0,0,0,0,0,0,0,0,0,0,0,41,177,45,0,0,0,0,0,0,0,0,0,0,0,0,0,0,0,0,0,0
0,0,0,0,0,0,0,0,0,0,0,0,0,0,0,0,0,0,0,46,0,0,0,0,0,0,0,0,0,0,0,0,0,0,0,0,0,0,0
0,0,0,0,0,0,0,0,0,0,0,0,0,0,0,0,0,0,0,0,0,0,0,0,0,0,0,0,0,0,0,0,0,0,0,0,0,0,0
0,0,0,0,0,0,0,0,0,0,0,0,0,0,0,0,0,0,0,0,0,0,0,0,0,0,0,0,0,0,0,0,0,0,0,0,0,0,0
0,0,0,0,0,0,0,0,0,0,0,0,0,0,0,0,0,0,0,0,0,0,0,0,0,0,0,0,0,0,0,0,0,0,0,0,0,0,0
0,0,0,0,0,0,0,0,0,0,0,0,0,0,0,0,0,0,0,0,0,0,0,0,0,0,0,0,0,0,0,0,0,0,0,0,0,0,0
0,0,0,0,0,0,0,0,0,0,0,0,0,0,0,0,0,0,0,0,0,0,0,0,0,0,0,0,0,0,0,0,0,0,0,0,0,0,0
0,0,0,0,0,0,0,0,0,0,0,0,0,0,0,0,0,0,0,0,0,0,0,0,0,0,0,0,0,0,0,0,0,0,0,0,0,0,0
0,0,0,0,0,0,0,0,0,0,0,0,0,0,0,0,0,0,0,0,0,0,0,0,0,0,0,0,0,0,0,0,0,0,0,0,0,0,0
:endlayer
layer: 28
0,0,0,0,0,0,0,0,0,0,0,0,0,0,0,0,0,0,0,0,0,0,0,0,0,0,0,0,0,0,0,0,0,0,0,0,0,0,0
0,0,0,0,0,0,0,0,0,0,0,0,0,0,0,0,0,0,0,0,0,0,0,0,0,0,0,0,0,0,0,0,0,0,0,0,0,0,0
0,0,0,0,0,0,0,0,0,0,0,0,0,0,0,0,0,0,0,0,0,0,0,0,0,0,0,0,0,0,0,0,0,0,0,0,0,0,0
0,0,0,0,0,0,0,0,0,0,0,0,0,0,0,0,0,0,0,0,0,0,0,0,0,0,0,0,0,0,0,0,0,0,0,0,0,0,0
0,0,0,0,0,0,0,0,0,0,0,0,0,0,0,0,0,0,0,0,0,0,0,0,0,0,0,0,0,0,0,0,0,0,0,0,0,0,0
0,0,0,0,0,0,0,0,0,0,0,0,0,0,0,0,0,0,0,0,0,0,0,0,0,0,0,0,0,0,0,0,0,0,0,0,0,0,0
0,0,0,0,0,0,0,0,0,0,0,0,0,0,0,0,0,0,0,0,0,0,0,0,0,0,0,0,0,0,0,0,0,0,0,0,0,0,0
0,0,0,0,0,0,0,0,0,0,0,0,0,0,0,0,0,0,0,86,0,0,0,0,0,0,0,0,0,0,0,0,0,0,0,0,0,0,0
0,0,0,0,0,0,0,0,0,0,0,0,0,0,0,0,0,0,0,0,0,0,0,0,0,0,0,0,0,0,0,0,0,0,0,0,0,0,0
0,0,0,0,0,0,0,0,0,0,0,0,0,0,0,0,0,0,0,0,0,0,0,0,0,0,0,0,0,0,0,0,0,0,0,0,0,0,0
0,0,0,0,0,0,0,0,0,0,0,0,0,0,0,0,0,0,0,0,0,0,0,0,0,0,0,0,0,0,0,0,0,0,0,0,0,0,0
0,0,0,0,0,0,0,0,0,0,0,0,0,0,0,0,0,0,0,0,0,0,0,0,0,0,0,0,0,0,0,0,0,0,0,0,0,0,0
0,0,0,0,0,0,0,0,0,0,0,0,0,0,0,0,0,3,213,3,3,3,0,0,0,0,0,0,0,0,0,0,0,0,0,0,0,0,0
0,0,0,0,0,0,0,0,0,0,0,0,0,0,0,0,177,0,0,0,3,3,177,0,0,0,0,0,0,0,0,0,0,0,0,0,0,0,0
0,0,0,0,0,0,0,0,0,0,0,0,0,0,0,177,0,0,0,0,3,3,3,177,0,0,0,0,0,0,0,0,0,0,0,0,0,0,0
0,0,0,0,0,0,0,0,0,0,0,0,0,0,177,0,0,0,0,0,3,26,0,0,177,0,0,0,0,0,0,0,0,0,0,0,0,0,0
0,0,0,0,0,0,0,0,0,0,0,0,0,177,0,0,0,0,0,0,3,26,0,0,0,177,0,0,0,0,0,0,0,0,0,0,0,0,0
0,0,0,0,0,0,0,0,0,0,0,0,3,0,0,0,0,3,3,3,3,3,3,40,3,0,3,0,0,0,0,0,0,0,0,0,0,0,0
0,0,0,0,0,0,0,0,0,0,0,0,3,0,0,0,0,46,3,0,3,46,0,0,0,0,3,0,0,0,0,0,0,0,0,0,0,0,0
0,0,0,0,0,0,0,0,0,0,0,0,213,0,0,0,0,0,0,0,0,0,0,0,0,0,213,0,0,0,0,0,0,0,0,0,0,0,0
0,0,0,0,0,0,86,0,0,0,0,0,3,0,0,0,0,0,0,0,0,0,0,0,0,0,3,0,0,0,0,0,86,0,0,0,0,0,0
0,0,0,0,0,0,0,0,0,0,0,0,3,0,0,0,0,0,0,0,0,0,0,0,0,0,3,0,0,0,0,0,0,0,0,0,0,0,0
0,0,0,0,0,0,0,0,0,0,0,0,0,177,0,0,0,0,0,229,0,0,0,0,0,177,0,0,0,0,0,0,0,0,0,0,0,0,0
0,0,0,0,0,0,0,0,0,0,0,0,0,0,177,0,0,0,0,0,0,0,0,0,177,0,0,0,0,0,0,0,0,0,0,0,0,0,0
0,0,0,0,0,0,0,0,0,0,0,0,0,0,0,177,0,0,230,0,0,0,0,177,0,0,0,0,0,0,0,0,0,0,0,0,0,0,0
0,0,0,0,0,0,0,0,0,0,0,0,0,0,0,0,177,0,0,0,0,0,177,0,0,0,0,0,0,0,0,0,0,0,0,0,0,0,0
0,0,0,0,0,0,0,0,0,0,0,0,0,0,0,0,0,3,3,213,3,3,0,0,0,0,0,0,0,0,0,0,0,0,0,0,0,0,0
0,0,0,0,0,0,0,0,0,0,0,0,0,0,0,0,0,0,0,0,0,0,0,0,0,0,0,0,0,0,0,0,0,0,0,0,0,0,0
0,0,0,0,0,0,0,0,0,0,0,0,0,0,0,0,0,0,0,0,0,0,0,0,0,0,0,0,0,0,0,0,0,0,0,0,0,0,0
0,0,0,0,0,0,0,0,0,0,0,0,0,0,0,0,0,0,0,0,0,0,0,0,0,0,0,0,0,0,0,0,0,0,0,0,0,0,0
0,0,0,0,0,0,0,0,0,0,0,0,0,0,0,0,0,0,0,0,0,0,0,0,0,0,0,0,0,0,0,0,0,0,0,0,0,0,0
0,0,0,0,0,0,0,0,0,0,0,0,0,0,0,0,0,0,0,0,0,0,0,0,0,0,0,0,0,0,0,0,0,0,0,0,0,0,0
0,0,0,0,0,0,0,0,0,0,0,0,0,0,0,0,0,0,0,0,0,0,0,0,0,0,0,0,0,0,0,0,0,0,0,0,0,0,0
0,0,0,0,0,0,0,0,0,0,0,0,0,0,0,0,0,0,0,86,0,0,0,0,0,0,0,0,0,0,0,0,0,0,0,0,0,0,0
0,0,0,0,0,0,0,0,0,0,0,0,0,0,0,0,0,0,0,0,0,0,0,0,0,0,0,0,0,0,0,0,0,0,0,0,0,0,0
0,0,0,0,0,0,0,0,0,0,0,0,0,0,0,0,0,0,0,0,0,0,0,0,0,0,0,0,0,0,0,0,0,0,0,0,0,0,0
0,0,0,0,0,0,0,0,0,0,0,0,0,0,0,0,0,0,0,0,0,0,0,0,0,0,0,0,0,0,0,0,0,0,0,0,0,0,0
0,0,0,0,0,0,0,0,0,0,0,0,0,0,0,0,0,0,0,0,0,0,0,0,0,0,0,0,0,0,0,0,0,0,0,0,0,0,0
0,0,0,0,0,0,0,0,0,0,0,0,0,0,0,0,0,0,0,0,0,0,0,0,0,0,0,0,0,0,0,0,0,0,0,0,0,0,0
0,0,0,0,0,0,0,0,0,0,0,0,0,0,0,0,0,0,0,0,0,0,0,0,0,0,0,0,0,0,0,0,0,0,0,0,0,0,0
0,0,0,0,0,0,0,0,0,0,0,0,0,0,0,0,0,0,0,0,0,0,0,0,0,0,0,0,0,0,0,0,0,0,0,0,0,0,0
0,0,0,0,0,0,0,0,0,0,0,0,0,0,0,0,0,0,0,0,0,0,0,0,0,0,0,0,0,0,0,0,0,0,0,0,0,0,0
:endlayer
layer: 29
0,0,0,0,0,0,0,0,0,0,0,0,0,0,0,0,0,0,0,0,0,0,0,0,0,0,0,0,0,0,0,0,0,0,0,0,0,0,0
0,0,0,0,0,0,0,0,0,0,0,0,0,0,0,0,0,0,0,0,0,0,0,0,0,0,0,0,0,0,0,0,0,0,0,0,0,0,0
0,0,0,0,0,0,0,0,0,0,0,0,0,0,0,0,0,0,0,0,0,0,0,0,0,0,0,0,0,0,0,0,0,0,0,0,0,0,0
0,0,0,0,0,0,0,0,0,0,0,0,0,0,0,0,0,0,0,0,0,0,0,0,0,0,0,0,0,0,0,0,0,0,0,0,0,0,0
0,0,0,0,0,0,0,0,0,0,0,0,0,0,0,0,0,0,0,0,0,0,0,0,0,0,0,0,0,0,0,0,0,0,0,0,0,0,0
0,0,0,0,0,0,0,0,0,0,0,0,0,0,0,0,0,0,0,0,0,0,0,0,0,0,0,0,0,0,0,0,0,0,0,0,0,0,0
0,0,0,0,0,0,0,0,0,0,0,0,0,0,0,0,0,0,0,0,0,0,0,0,0,0,0,0,0,0,0,0,0,0,0,0,0,0,0
0,0,0,0,0,0,0,0,0,0,0,0,0,0,0,0,0,0,0,0,0,0,0,0,0,0,0,0,0,0,0,0,0,0,0,0,0,0,0
0,0,0,0,0,0,0,0,0,0,0,0,0,0,0,0,0,0,0,0,0,0,0,0,0,0,0,0,0,0,0,0,0,0,0,0,0,0,0
0,0,0,0,0,0,0,0,0,0,0,0,0,0,0,0,0,0,0,0,0,0,0,0,0,0,0,0,0,0,0,0,0,0,0,0,0,0,0
