# Ancient Warfare Structure Template File
# Auto-generated structure template file. created on: 8/19/2019 at: 10:23:10
# Lines beginning with # denote comments

header:
version=2.9
name=EmpireCoachingInn
mods=
size=41,26,51
offset=12,3,50
:endheader

#### VALIDATION ####
validation:
type=ground
survival=false
worldGenEnabled=true
unique=false
preserveBlocks=false
selectionWeight=30
clusterValue=20
minDuplicateDistance=600
dimensionWhiteList=true
dimensionList=0
biomeWhiteList=true
biomeList=biomesoplenty:meadow,traverse:meadow,minecraft:birch_forest,minecraft:plains,minecraft:birch_forest_hills
leveling=15
fill=15
border=15
blockSwap=false
:endvalidation

#### LAYERS ####
layer: 0
1,1,1,1,1,1,1,1,1,1,1,1,1,1,1,1,1,1,1,1,1,1,1,1,1,1,1,1,1,1,1,1,1,1,1,1,1,1,1,1,1
1,1,1,1,1,1,1,1,1,1,1,1,1,1,1,1,1,1,1,1,1,1,1,1,1,1,1,1,1,1,1,1,1,1,1,1,1,1,1,1,1
1,1,1,1,1,1,1,1,1,1,1,1,1,1,1,1,1,1,1,1,1,1,1,1,1,1,1,1,1,1,1,1,1,1,1,1,1,1,1,1,1
1,1,1,1,1,1,1,1,1,1,1,1,1,1,1,1,1,1,1,1,1,1,1,1,1,1,1,1,1,1,1,1,1,1,1,1,1,1,1,1,1
1,1,1,1,1,1,1,1,1,1,1,1,1,1,1,1,1,1,1,1,1,1,1,1,1,1,1,1,1,1,1,1,1,1,1,1,1,1,1,1,1
1,1,1,1,1,1,1,1,1,1,1,1,1,1,1,1,1,1,1,1,1,1,1,1,1,1,1,1,1,1,1,1,1,1,1,1,1,1,1,1,1
1,1,1,1,1,1,1,1,1,1,1,1,1,1,1,1,1,1,1,1,1,1,1,1,1,1,1,1,1,1,1,1,1,1,1,1,1,1,1,1,1
1,1,1,1,1,1,1,1,1,1,1,1,1,1,1,1,1,1,1,1,1,1,1,1,1,1,1,1,1,1,1,1,1,1,1,1,1,1,1,1,1
1,1,1,1,1,1,1,1,1,1,1,1,1,1,1,1,1,1,1,1,1,1,1,1,1,1,1,1,1,1,1,1,1,1,1,1,1,1,1,1,1
1,1,1,1,1,1,1,1,1,1,1,1,1,1,1,1,1,1,1,1,1,1,1,1,1,1,1,1,1,1,1,1,1,1,1,1,1,1,1,1,1
1,1,1,1,1,1,1,1,1,1,1,1,1,1,1,1,1,1,1,1,1,1,1,1,1,1,1,1,1,1,1,1,1,1,1,1,1,1,1,1,1
1,1,1,1,1,1,1,1,1,1,1,1,1,1,1,1,1,1,1,1,1,1,1,1,1,1,1,1,1,1,1,1,1,1,1,1,1,1,1,1,1
1,1,1,1,1,1,1,1,1,1,1,1,1,1,1,1,1,1,1,1,1,1,1,1,1,1,1,1,1,1,1,1,1,1,1,1,1,1,1,1,1
1,1,1,1,1,1,1,1,1,1,1,1,1,1,1,1,1,1,1,1,1,1,1,1,1,1,1,1,1,1,1,1,1,1,1,1,1,1,1,1,1
1,1,1,1,1,1,1,1,1,1,1,1,1,1,1,1,1,1,1,1,1,1,1,1,1,1,1,1,1,1,1,1,1,1,1,1,1,1,1,1,1
1,1,1,1,1,1,1,1,1,1,1,1,1,1,1,1,1,1,1,1,1,1,1,1,1,1,1,1,1,1,1,1,1,1,1,1,1,1,1,1,1
1,1,1,1,1,1,1,1,1,1,1,1,1,1,1,1,1,1,1,1,1,1,1,1,1,1,1,1,1,1,1,1,1,1,1,1,1,1,1,1,1
1,1,1,1,1,1,1,1,1,1,1,1,1,1,1,1,1,1,1,1,1,1,1,1,1,1,1,1,1,1,1,1,1,1,1,1,1,1,1,1,1
1,1,1,1,1,1,1,1,1,1,1,1,1,1,1,1,1,1,1,1,1,1,1,1,1,1,1,1,1,1,1,1,1,1,1,1,1,1,1,1,1
1,1,1,1,1,1,1,1,1,1,1,1,1,1,1,1,1,1,1,1,1,1,1,1,1,1,1,1,1,1,1,1,1,1,1,1,1,1,1,1,1
1,1,1,1,1,1,1,1,1,1,1,1,1,1,1,1,1,1,1,1,1,1,1,1,1,1,1,1,1,1,1,1,1,1,1,1,1,1,1,1,1
1,1,1,1,1,1,1,1,1,1,1,1,1,1,1,1,1,1,1,1,1,1,1,1,1,1,1,1,1,1,1,1,1,1,1,1,1,1,1,1,1
1,1,1,1,1,1,1,1,1,1,1,1,1,1,1,1,1,1,1,1,1,1,1,1,1,1,1,1,1,1,1,1,1,1,1,1,1,1,1,1,1
1,1,1,1,1,1,1,1,1,1,1,1,1,1,1,1,1,1,1,1,1,1,1,1,1,1,1,1,1,1,1,1,1,1,1,1,1,1,1,1,1
1,1,1,1,1,1,1,1,1,1,1,1,1,1,1,1,1,1,1,1,1,1,1,1,1,1,1,1,1,1,1,1,1,1,1,1,1,1,1,1,1
1,1,1,1,1,1,1,1,1,1,1,1,1,1,1,1,1,1,1,1,1,1,1,1,1,1,1,1,1,1,1,1,1,1,1,1,1,1,1,1,1
1,1,1,1,1,1,1,1,1,1,1,1,1,1,1,1,1,1,1,1,1,1,1,1,1,1,1,1,1,1,1,1,1,1,1,1,1,1,1,1,1
1,1,1,1,1,1,1,1,1,1,1,1,1,1,1,1,1,1,1,1,1,1,1,1,1,1,1,1,1,1,1,1,1,1,1,1,1,1,1,1,1
1,1,1,1,1,1,1,1,1,1,1,1,1,1,1,1,1,1,1,1,1,1,1,1,1,1,1,1,1,1,1,1,1,1,1,1,1,1,1,1,1
1,1,1,1,1,1,1,1,1,1,1,1,1,1,1,1,1,1,1,1,1,1,1,1,1,1,1,1,1,1,1,1,1,1,1,1,1,1,1,1,1
1,1,1,1,1,1,1,1,1,1,1,1,1,1,1,1,1,1,1,1,1,1,1,1,1,1,1,1,1,1,1,1,1,1,1,1,1,1,1,1,1
1,1,1,1,1,1,1,1,1,1,1,1,1,1,1,1,1,1,1,1,1,1,1,1,1,1,1,1,1,1,1,1,1,1,1,1,1,1,1,1,1
1,1,1,1,1,1,1,1,1,1,1,1,1,1,1,1,1,1,1,1,1,1,1,1,1,1,1,1,1,1,1,1,1,1,1,1,1,1,1,1,1
1,1,1,1,1,1,1,1,1,1,1,1,1,1,1,1,1,1,1,1,1,1,1,1,1,1,1,1,1,1,1,1,1,1,1,1,1,1,1,1,1
1,1,1,1,1,1,1,1,1,1,1,1,1,1,1,1,1,1,1,1,1,1,1,1,1,1,1,1,1,1,1,1,1,1,1,1,1,1,1,1,1
1,1,1,1,1,1,1,1,1,1,1,1,1,1,1,1,1,1,1,1,1,1,1,1,1,1,1,1,1,1,1,1,1,1,1,1,1,1,1,1,1
1,1,1,1,1,1,1,1,1,1,1,1,1,1,1,1,1,1,1,1,1,1,1,1,1,1,1,1,1,1,1,1,1,1,1,1,1,1,1,1,1
1,1,1,1,1,1,1,1,1,1,1,1,1,1,1,1,1,1,1,1,1,1,1,1,1,1,1,1,1,1,1,1,1,1,1,1,1,1,1,1,1
1,1,1,1,1,1,1,1,1,1,1,1,1,1,1,1,1,1,1,1,1,1,1,1,1,1,1,1,1,1,1,1,1,1,1,1,1,1,1,1,1
1,1,1,1,1,1,1,1,1,1,1,1,1,1,1,1,1,1,1,1,1,1,1,1,1,1,1,1,1,1,1,1,1,1,1,1,1,1,1,1,1
1,1,1,1,1,1,1,1,1,1,1,1,1,1,1,1,1,1,1,1,1,1,1,1,1,1,1,1,1,1,1,1,1,1,1,1,1,1,1,1,1
1,1,1,1,1,1,1,1,1,1,1,1,1,1,1,1,1,1,1,1,1,1,1,1,1,1,1,1,1,1,1,1,1,1,1,1,1,1,1,1,1
1,1,1,1,1,1,1,1,1,1,1,1,1,1,1,1,1,1,1,1,1,1,1,1,1,1,1,1,1,1,1,1,1,1,1,1,1,1,1,1,1
1,1,1,1,1,1,1,1,1,1,1,1,1,1,1,1,1,1,1,1,1,1,1,1,1,1,1,1,1,1,1,1,1,1,1,1,1,1,1,1,1
1,1,1,1,1,1,1,1,1,1,1,1,1,1,1,1,1,1,1,1,1,1,1,1,1,1,1,1,1,1,1,1,1,1,1,1,1,1,1,1,1
1,1,1,1,1,1,1,1,1,1,1,1,1,1,1,1,1,1,1,1,1,1,1,1,1,1,1,1,1,1,1,1,1,1,1,1,1,1,1,1,1
1,1,1,1,1,1,1,1,1,1,1,1,1,1,1,1,1,1,1,1,1,1,1,1,1,1,1,1,1,1,1,1,1,1,1,1,1,1,1,1,1
1,1,1,1,1,1,1,1,1,1,1,1,1,1,1,1,1,1,1,1,1,1,1,1,1,1,1,1,1,1,1,1,1,1,1,1,1,1,1,1,1
1,1,1,1,1,1,1,1,1,1,1,1,1,1,1,1,1,1,1,1,1,1,1,1,1,1,1,1,1,1,1,1,1,1,1,1,1,1,1,1,1
1,1,1,1,1,1,1,1,1,1,1,1,1,1,1,1,1,1,1,1,1,1,1,1,1,1,1,1,1,1,1,1,1,1,1,1,1,1,1,1,1
1,1,1,1,1,1,1,1,1,1,1,1,1,1,1,1,0,1,1,1,1,1,1,1,1,1,1,1,1,1,1,1,1,1,1,1,1,1,1,1,1
:endlayer
layer: 1
1,1,1,1,1,1,1,1,1,1,1,1,1,1,1,1,1,1,1,1,1,1,1,1,1,1,1,1,1,1,1,1,1,1,1,1,1,1,1,1,1
1,1,1,1,1,1,1,1,1,1,1,1,1,1,1,1,1,1,1,1,1,1,1,1,1,1,1,1,1,1,1,1,1,1,1,1,1,1,1,1,1
1,1,1,1,1,1,1,1,1,1,1,1,1,1,1,1,1,1,1,1,1,1,1,1,1,1,1,1,1,1,1,1,1,1,1,1,1,1,1,1,1
1,1,1,1,1,1,1,1,1,1,1,1,1,1,1,1,1,1,1,1,1,1,1,1,1,1,1,1,1,1,1,1,1,1,1,1,1,1,1,1,1
1,1,1,1,1,1,1,1,1,1,1,1,1,1,1,1,1,1,1,1,1,1,1,1,1,1,1,1,1,1,1,1,1,1,1,1,1,1,1,1,1
1,1,1,1,1,1,1,1,1,1,1,1,1,1,1,1,1,1,1,1,1,1,1,1,1,1,1,1,1,1,1,1,1,1,1,1,1,1,1,1,1
1,1,1,1,1,1,1,1,1,1,1,1,1,1,1,1,1,1,1,1,1,1,1,1,1,1,1,1,1,1,1,1,1,1,1,1,1,1,1,1,1
1,1,1,1,1,1,1,1,1,1,1,1,1,1,1,1,1,1,1,1,1,1,1,1,1,1,1,1,1,1,1,1,1,1,1,1,1,1,1,1,1
1,1,1,1,1,1,1,1,1,1,1,1,1,1,1,1,1,1,1,1,1,1,1,1,1,1,1,1,1,1,1,1,1,1,1,1,1,1,1,1,1
1,1,1,1,1,1,1,1,1,1,1,1,1,1,1,1,1,1,1,1,1,1,1,1,1,1,1,1,1,1,1,1,1,1,1,1,1,1,1,1,1
1,1,1,1,1,1,1,1,1,1,1,1,1,1,1,1,1,1,1,1,1,1,1,1,1,1,1,1,1,1,1,1,1,1,1,1,1,1,1,1,1
1,1,1,1,1,1,1,1,1,1,1,1,1,1,1,1,1,1,1,1,1,1,1,1,1,1,1,1,1,1,1,1,1,1,1,1,1,1,1,1,1
1,1,1,1,1,1,1,1,1,1,1,1,1,1,1,1,1,1,1,1,1,1,1,1,1,1,1,1,1,1,1,1,1,1,1,1,1,1,1,1,1
1,1,1,1,1,1,1,1,1,1,1,1,1,1,1,1,1,1,1,1,1,1,1,1,1,1,1,1,1,1,1,1,1,1,1,1,1,1,1,1,1
1,1,1,1,1,1,1,1,1,1,1,1,1,1,1,1,1,1,1,1,1,1,1,1,1,1,1,1,1,1,1,1,1,1,1,1,1,1,1,1,1
1,1,1,1,1,1,1,1,1,1,1,1,1,1,1,1,1,1,1,1,1,1,1,1,1,1,1,1,1,1,1,1,1,1,1,1,1,1,1,1,1
1,1,1,1,1,1,1,1,1,1,1,1,1,1,1,1,1,1,1,1,1,1,1,1,1,1,1,1,1,1,1,1,1,1,1,1,1,1,1,1,1
1,1,1,1,1,1,1,1,1,1,1,1,1,1,1,1,1,1,1,1,1,1,1,1,1,1,1,1,1,1,1,1,1,1,1,1,1,1,1,1,1
1,1,1,1,1,1,1,1,1,1,1,1,1,1,1,1,1,1,2,2,1,1,1,1,1,1,1,1,1,1,1,1,1,1,1,1,1,1,1,1,1
1,1,1,1,1,1,1,1,1,1,1,1,1,1,1,1,1,2,3,3,2,1,1,1,1,1,1,1,1,1,1,1,1,1,1,1,1,1,1,1,1
1,1,1,1,1,1,1,1,1,1,1,1,1,1,1,1,1,2,3,3,2,1,1,1,1,1,1,1,1,1,1,1,1,1,1,1,1,1,1,1,1
1,1,1,1,1,1,1,1,1,1,1,1,1,1,1,1,1,1,2,2,1,1,1,1,1,1,1,1,1,1,1,1,1,1,1,1,1,1,1,1,1
1,1,1,1,1,1,1,1,1,1,1,1,1,1,1,1,1,1,1,1,1,1,1,1,1,1,1,1,1,1,1,1,1,1,1,1,1,1,1,1,1
1,1,1,1,1,1,1,1,1,1,1,1,1,1,1,1,1,1,1,1,1,1,1,1,1,1,1,1,1,1,1,1,1,1,1,1,1,1,1,1,1
1,1,1,1,1,1,1,1,1,1,1,1,1,1,1,1,1,1,1,1,1,1,1,1,1,1,1,1,1,1,1,1,1,1,1,1,1,1,1,1,1
1,1,1,1,1,1,1,1,1,1,1,1,1,1,1,1,1,1,1,1,1,1,1,1,1,1,1,1,1,1,1,1,1,1,1,1,1,1,1,1,1
1,1,1,1,1,1,1,1,1,1,1,1,1,1,1,1,1,1,1,1,1,1,1,1,1,1,1,1,1,1,1,1,1,1,1,1,1,1,1,1,1
1,1,1,1,1,1,1,1,1,1,1,1,1,1,1,1,1,1,1,1,1,1,1,1,1,1,1,1,1,1,1,1,1,1,1,1,1,1,1,1,1
1,1,1,1,1,1,1,1,1,1,1,1,1,1,1,1,1,1,1,1,1,1,1,1,1,1,1,1,1,1,1,1,1,1,1,1,1,1,1,1,1
1,1,1,1,1,1,1,1,1,1,1,1,1,1,1,1,1,1,1,1,1,1,1,1,1,1,1,1,1,1,1,1,1,1,1,1,1,1,1,1,1
1,1,1,1,1,1,1,1,1,1,1,1,1,1,1,1,1,1,1,1,1,1,1,1,1,1,1,1,1,1,1,1,1,1,1,1,1,1,1,1,1
1,1,1,1,1,1,1,1,1,1,1,1,1,1,1,1,1,1,1,1,1,1,1,1,1,1,1,1,1,1,1,1,1,1,1,1,1,1,1,1,1
1,1,1,1,1,1,1,1,1,1,1,1,1,1,1,1,1,1,1,1,1,1,1,1,1,1,1,1,1,1,1,1,1,1,1,1,1,1,1,1,1
1,1,1,1,1,1,1,1,1,1,1,1,1,1,1,1,1,1,1,1,1,1,1,1,1,1,1,1,1,1,1,1,1,1,1,1,1,1,1,1,1
1,1,1,1,1,1,1,1,1,1,1,1,1,1,1,1,1,1,1,1,1,1,1,1,1,1,1,1,1,1,1,1,1,1,1,1,1,1,1,1,1
1,1,1,1,1,1,1,1,1,1,1,1,1,1,1,1,1,1,1,1,1,1,1,1,1,1,1,1,1,1,1,1,1,1,1,1,1,1,1,1,1
1,1,1,1,1,1,1,1,1,1,1,1,1,1,1,1,1,1,1,1,1,1,1,1,1,1,1,1,1,1,1,1,1,1,1,1,1,1,1,1,1
1,1,1,1,1,1,1,1,1,1,1,1,1,1,1,1,1,1,1,1,1,1,1,1,1,1,1,1,1,1,1,1,1,1,1,1,1,1,1,1,1
1,1,1,1,1,1,1,1,1,1,1,1,1,1,1,1,1,1,1,1,1,1,1,1,1,1,1,1,1,1,1,1,1,1,1,1,1,1,1,1,1
1,1,1,1,1,1,1,1,1,1,1,1,1,1,1,1,1,1,1,1,1,1,1,1,1,1,1,1,1,1,1,1,1,1,1,1,1,1,1,1,1
1,1,1,1,1,1,1,1,1,1,1,1,1,1,1,1,1,1,1,1,1,1,1,1,1,1,1,1,1,1,1,1,1,1,1,1,1,1,1,1,1
1,1,1,1,1,1,1,1,1,1,1,1,1,1,1,1,1,1,1,1,1,1,1,1,1,1,1,1,1,1,1,1,1,1,1,1,1,1,1,1,1
1,1,1,1,1,1,1,1,1,1,1,1,1,1,1,1,1,1,1,1,1,1,1,1,1,1,1,1,1,1,1,1,1,1,1,1,1,1,1,1,1
1,1,1,1,1,1,1,1,1,1,1,1,1,1,1,1,1,1,1,1,1,1,1,1,1,1,1,1,1,1,1,1,1,1,1,1,1,1,1,1,1
1,1,1,1,1,1,1,1,1,1,1,1,1,1,1,1,1,1,1,1,1,1,1,1,1,1,1,1,1,1,1,1,1,1,1,1,1,1,1,1,1
1,1,1,1,1,1,1,1,1,1,1,1,1,1,1,1,1,1,1,1,1,1,1,1,1,1,1,1,1,1,1,1,1,1,1,1,1,1,1,1,1
1,1,1,1,1,1,1,1,1,1,1,1,1,1,1,1,1,1,1,1,1,1,1,1,1,1,1,1,1,1,1,1,1,1,1,1,1,1,1,1,1
1,1,1,1,1,1,1,1,1,1,1,1,1,1,1,1,1,1,1,1,1,1,1,1,1,1,1,1,1,1,1,1,1,1,1,1,1,1,1,1,1
1,1,1,1,1,1,1,1,1,1,1,1,1,1,1,1,1,1,1,1,1,1,1,1,1,1,1,1,1,1,1,1,1,1,1,1,1,1,1,1,1
1,1,1,1,1,1,1,1,1,1,1,1,1,1,1,1,1,1,1,1,1,1,1,1,1,1,1,1,1,1,1,1,1,1,1,1,1,1,1,1,1
1,1,1,1,1,1,1,1,1,1,1,1,1,1,1,1,0,1,1,1,1,1,1,1,1,1,1,1,1,1,1,1,1,1,1,1,1,1,1,1,1
:endlayer
layer: 2
4,4,4,4,4,4,4,4,4,4,4,4,4,4,4,4,4,4,4,4,4,4,4,4,4,4,4,4,4,4,4,4,4,4,4,4,4,4,4,4,4
4,4,4,4,4,4,4,4,4,4,4,4,4,4,4,4,4,4,4,4,4,4,4,4,4,4,4,4,4,4,4,4,4,4,4,4,4,4,4,4,4
4,4,4,4,4,4,4,4,4,4,4,4,4,4,4,4,4,4,4,4,4,4,4,4,4,4,4,4,4,4,4,4,4,4,4,4,4,4,4,4,4
4,4,4,4,4,4,6,6,6,6,6,6,6,6,6,6,6,6,6,6,6,6,6,6,6,6,6,6,6,6,6,6,6,6,6,6,6,6,4,4,4
4,4,4,4,4,4,6,2,2,2,2,2,2,2,2,2,2,2,2,2,6,2,2,2,2,2,2,2,2,2,2,2,2,2,2,2,2,6,4,4,4
4,4,4,4,4,4,6,2,2,2,2,2,2,2,2,2,2,2,2,2,1,2,2,2,2,2,2,2,2,2,2,2,2,2,2,2,2,6,4,4,4
4,4,4,4,4,4,6,2,2,2,2,2,2,2,2,2,2,2,2,2,1,2,2,2,2,2,2,2,2,2,2,2,2,2,2,2,2,6,4,4,4
7,7,7,7,7,7,6,2,2,2,2,2,2,2,2,2,2,2,2,2,6,2,2,2,2,2,2,2,2,2,2,2,2,2,2,2,2,6,4,4,4
7,7,7,7,7,7,6,2,2,2,2,2,2,2,2,2,2,2,2,2,6,2,2,2,2,2,2,2,2,2,2,2,2,2,2,2,2,6,4,4,4
7,7,7,7,7,7,6,2,2,2,2,2,2,2,2,2,2,2,2,2,6,2,2,2,2,2,2,2,2,2,2,2,2,2,2,2,2,6,4,4,4
7,7,7,7,7,7,6,2,2,2,2,2,2,2,2,2,2,2,2,2,6,2,2,2,2,2,2,2,2,2,2,2,2,2,2,2,2,6,4,4,4
4,4,7,7,7,4,6,2,2,2,2,2,2,2,2,2,2,2,2,2,6,2,2,2,2,2,2,2,2,2,2,2,2,2,2,2,2,6,4,4,4
4,4,7,7,7,4,6,2,2,2,2,2,2,2,2,2,2,2,2,2,6,6,6,6,6,6,6,6,6,6,6,6,6,6,6,6,6,6,4,4,4
4,4,7,7,7,4,6,2,2,2,2,2,2,2,2,2,2,2,2,2,6,4,4,4,4,4,4,2,2,2,2,2,2,2,2,2,2,6,4,4,4
4,4,7,7,7,4,6,2,2,2,2,2,2,2,2,2,2,2,2,2,6,4,4,4,4,4,4,2,2,2,2,2,2,2,2,2,2,6,4,4,4
4,1,7,7,7,4,6,6,2,2,2,2,6,6,6,6,6,6,6,6,6,4,4,4,4,4,4,1,1,1,1,1,1,1,1,1,1,1,4,4,4
4,4,7,7,7,4,1,6,2,2,2,2,2,2,2,2,2,2,2,2,2,2,2,2,2,2,4,1,1,1,1,1,1,1,1,1,1,1,4,4,4
4,4,7,7,7,4,1,6,2,2,2,2,2,2,2,2,2,2,2,2,2,2,2,2,2,2,4,1,1,1,1,1,1,1,1,1,1,1,4,4,4
4,4,7,7,7,4,1,6,2,2,2,2,2,2,2,2,2,6,6,6,6,2,2,2,2,2,4,1,1,1,1,1,1,1,1,1,1,1,4,4,4
7,7,7,7,7,7,4,1,2,2,2,2,2,2,2,2,2,6,8,8,6,2,2,2,2,2,4,1,1,1,1,1,1,1,1,1,1,1,4,4,4
7,7,7,7,7,7,2,2,2,2,2,2,2,2,2,2,2,6,8,8,6,2,2,2,2,2,4,1,1,1,1,1,1,1,1,1,1,1,4,4,4
7,7,7,7,7,7,2,2,2,2,2,2,2,2,2,2,2,6,6,6,6,2,2,2,2,2,1,1,1,1,1,1,1,1,1,1,1,1,4,4,4
7,7,7,7,7,7,4,1,2,2,2,2,2,2,2,2,2,2,2,2,2,2,2,2,2,2,4,1,1,1,1,1,1,4,4,1,4,1,4,4,4
4,4,4,4,4,4,1,1,1,1,1,2,2,2,2,2,2,2,2,2,2,2,2,2,2,2,4,1,1,1,1,1,1,4,4,2,4,1,4,4,4
4,4,4,4,4,4,1,1,1,1,1,2,2,2,2,2,2,2,2,2,2,2,2,2,2,2,4,1,1,1,1,1,1,4,4,2,4,1,4,4,4
4,4,4,4,4,4,1,1,1,1,1,1,2,2,2,2,2,2,2,2,2,2,2,2,2,2,4,1,1,1,1,1,1,4,4,2,4,1,4,4,4
4,4,4,4,4,4,1,1,1,1,1,2,2,2,2,2,2,2,2,2,2,2,2,2,2,2,1,1,1,1,1,1,1,4,4,2,4,1,4,1,4
4,4,4,4,4,4,1,1,1,1,1,2,2,2,2,1,2,2,2,1,4,2,2,2,2,2,4,1,1,1,1,1,1,4,2,2,2,6,2,2,2
4,4,4,4,4,4,1,1,1,1,1,2,2,2,2,1,1,2,1,1,1,2,2,2,2,2,4,1,1,1,1,1,1,4,2,2,2,6,2,2,2
4,4,4,4,4,4,1,1,1,1,1,1,1,6,6,2,2,2,2,1,4,2,2,2,2,2,4,1,1,1,1,1,1,4,2,2,2,1,4,1,4
4,4,4,4,4,4,1,2,2,2,2,2,2,2,2,2,2,2,2,1,4,2,2,2,2,2,4,1,1,1,1,1,1,4,2,2,2,1,4,4,4
4,4,4,4,4,4,1,2,2,2,2,2,2,2,2,2,2,2,2,1,4,2,2,2,2,2,4,1,1,1,1,1,1,4,2,2,2,1,4,4,4
4,4,4,4,4,4,1,2,2,2,2,2,2,2,2,2,2,2,2,1,4,2,2,2,2,2,4,1,1,1,1,1,1,4,2,2,2,1,4,4,4
4,4,4,4,4,4,1,2,2,2,2,2,2,2,2,2,2,2,2,1,4,2,2,2,2,2,4,4,4,4,4,4,4,4,2,2,2,1,4,4,4
4,4,4,4,4,4,1,2,2,2,2,2,2,2,2,2,2,2,2,1,4,2,2,2,2,2,2,2,2,2,2,2,2,2,2,2,2,1,4,4,4
4,1,4,4,4,4,1,2,2,2,2,2,2,2,2,2,2,2,2,1,4,2,2,2,2,2,2,2,2,2,2,2,2,2,2,2,2,1,4,4,4
4,4,4,4,4,4,1,2,2,2,2,2,2,2,2,1,2,2,2,2,4,2,2,2,2,2,2,2,2,2,2,2,2,2,2,2,2,1,4,4,4
4,4,4,4,4,4,1,2,2,2,2,2,2,2,2,1,2,2,2,2,1,2,2,2,2,2,2,2,2,2,2,4,4,4,4,4,4,1,4,4,4
4,4,4,4,4,4,1,2,2,2,2,2,2,2,2,6,2,2,2,2,2,2,2,2,2,2,1,2,2,2,2,1,1,2,1,1,1,1,4,4,4
4,4,4,4,4,4,1,2,2,2,2,2,2,2,2,1,2,2,2,2,2,2,2,2,2,2,2,2,2,2,2,1,2,2,2,2,2,1,4,4,4
4,4,4,4,4,4,1,2,2,2,2,2,1,1,1,1,1,1,1,1,1,4,2,2,2,2,2,2,2,2,2,1,2,2,2,2,2,1,4,4,4
4,4,4,4,4,4,1,2,2,2,2,2,1,1,1,1,1,1,1,1,1,4,2,2,2,2,2,2,2,2,2,2,2,2,2,2,2,1,4,4,4
4,4,4,4,4,4,1,2,2,2,2,2,1,1,1,1,1,1,1,1,1,4,2,2,2,2,2,2,2,2,2,2,2,2,2,2,2,1,4,4,4
4,4,4,4,4,4,1,2,2,2,2,2,1,1,1,1,1,1,1,1,1,4,2,2,2,2,2,2,2,2,2,2,2,2,2,2,2,1,4,4,4
4,4,4,4,4,4,1,2,2,2,2,2,1,1,1,1,1,1,1,1,1,4,2,2,2,2,2,2,2,2,2,2,2,2,2,2,2,1,4,4,4
4,4,4,4,4,4,1,1,1,1,1,1,1,1,1,1,1,1,1,1,1,4,2,2,2,2,1,2,2,2,2,5,2,2,2,5,1,1,4,4,4
4,4,4,4,4,4,1,1,1,1,1,1,1,1,1,1,1,1,1,1,1,4,2,2,2,2,2,2,2,2,2,2,2,2,2,2,4,1,4,4,4
4,4,4,4,4,4,1,1,1,1,1,1,1,1,1,1,1,1,1,1,1,1,2,2,1,1,4,4,4,4,4,4,4,4,4,4,4,1,4,4,4
4,4,4,4,4,4,1,1,1,1,1,1,1,1,1,1,1,1,1,1,1,4,2,2,4,1,1,1,1,1,1,1,1,1,1,1,1,1,4,4,4
4,4,4,4,4,4,4,4,4,4,4,4,4,4,4,4,4,4,4,4,4,4,2,2,4,4,4,4,4,4,4,4,4,4,4,4,4,4,4,4,4
4,4,4,4,4,4,4,4,4,4,4,4,4,4,4,4,4,4,4,4,4,4,2,2,4,4,4,4,4,4,4,4,4,4,4,4,4,4,4,4,4
:endlayer
layer: 3
0,9,9,9,0,9,0,9,0,9,9,9,9,0,9,9,0,9,0,9,0,0,9,0,0,9,9,9,9,9,9,9,9,0,9,9,9,9,9,0,0
9,9,0,9,0,9,9,9,9,9,9,9,9,0,9,9,9,9,9,0,9,9,9,9,9,9,9,9,9,9,9,9,0,0,0,9,0,0,0,0,0
9,9,9,0,9,9,9,9,9,9,9,0,0,9,9,0,9,0,0,0,9,9,9,9,0,9,9,9,9,9,9,9,0,0,9,0,9,0,9,0,0
9,12,12,12,12,12,6,6,6,6,6,6,6,6,6,6,6,6,6,6,6,6,6,6,6,6,6,6,6,6,6,6,6,6,6,6,6,6,9,0,0
9,12,0,9,9,0,6,0,0,0,0,85,0,0,0,0,0,84,80,84,6,0,0,12,0,0,12,0,0,12,0,0,12,83,0,82,81,6,9,9,0
0,12,0,0,0,0,6,0,0,0,0,0,0,0,0,0,0,0,80,79,6,0,78,12,0,77,12,76,0,12,0,0,12,0,0,0,0,6,9,0,0
0,12,0,0,0,75,6,0,0,0,0,0,0,0,0,0,0,0,0,0,6,0,0,12,0,0,12,0,0,12,74,0,12,0,0,0,0,6,0,9,0
0,0,0,0,0,0,73,0,0,0,0,0,0,72,0,0,0,0,0,0,6,12,13,12,13,12,12,13,12,12,13,12,12,0,0,0,71,6,0,0,0
0,0,0,0,0,70,69,0,0,0,0,0,0,0,0,0,0,0,0,0,0,0,0,0,0,68,0,0,0,0,0,0,0,0,67,0,66,6,9,0,0
0,0,0,0,0,0,65,0,0,0,0,0,0,0,0,0,0,0,0,0,0,0,0,0,0,0,0,0,0,0,0,0,0,0,0,0,29,6,9,9,0
0,0,0,0,0,0,64,0,0,0,63,0,0,0,0,0,0,0,0,0,6,0,0,12,0,0,12,0,0,12,0,0,12,0,0,0,0,6,9,9,0
0,12,0,0,0,0,62,0,0,0,0,0,0,0,0,0,0,0,0,0,6,0,0,12,0,0,12,0,0,12,0,0,12,0,0,27,0,6,9,0,0
0,12,0,0,0,0,6,61,0,0,0,0,0,0,0,0,0,0,0,0,6,6,6,6,6,6,6,6,6,6,6,6,6,6,6,6,6,6,9,9,0
0,12,0,0,0,0,6,6,6,0,0,6,6,0,0,0,0,0,0,0,6,0,9,9,9,58,0,6,35,35,35,35,35,35,35,35,35,6,9,0,0
9,12,0,0,0,9,6,6,60,0,0,59,6,0,0,0,0,0,0,0,6,0,9,9,9,58,57,6,35,35,35,35,35,35,35,35,35,6,0,9,0
0,6,0,0,0,9,6,6,6,6,0,0,6,6,6,6,6,6,32,6,6,0,9,9,9,9,46,6,35,35,35,35,35,35,35,35,35,6,9,9,0
0,12,0,0,0,0,6,6,55,15,0,56,6,0,0,0,0,0,0,0,0,0,0,0,0,0,0,6,35,35,35,35,35,35,35,35,35,6,0,9,0
0,12,0,0,0,9,6,6,55,15,0,29,6,0,0,0,0,0,0,0,0,0,0,54,0,0,0,6,35,35,35,35,35,35,35,35,35,6,0,0,0
0,12,0,0,0,0,6,6,6,6,0,0,6,0,0,0,0,6,6,6,6,0,0,0,0,0,0,6,35,35,35,35,35,35,35,35,35,6,9,0,0
0,0,0,0,0,0,53,6,0,0,0,0,0,0,0,0,0,6,0,0,6,0,0,0,0,0,0,6,35,35,35,35,35,35,35,35,35,6,9,9,0
0,0,0,0,0,0,0,45,0,0,0,0,0,0,0,0,0,6,0,0,6,0,0,0,0,0,0,6,35,35,35,35,35,35,35,35,35,6,9,9,0
0,0,0,0,0,0,0,45,0,0,0,0,0,0,0,0,0,6,6,6,6,0,0,0,0,0,48,6,35,35,35,35,6,6,6,6,6,6,0,9,0
0,0,0,0,0,0,52,6,0,0,0,0,0,0,0,0,0,0,0,0,0,0,0,0,0,0,0,6,35,35,35,35,6,9,0,51,0,6,9,0,0
9,12,12,50,12,12,6,6,6,6,6,0,0,0,0,0,0,0,0,0,0,0,0,0,0,0,9,6,6,6,6,6,6,0,9,0,0,6,9,9,0
9,12,0,9,0,0,6,6,6,6,6,0,0,0,0,0,0,0,0,0,0,0,0,0,0,0,9,6,6,6,6,6,6,9,0,0,0,6,9,9,0
9,12,9,0,0,0,6,6,6,6,6,15,0,0,0,0,0,0,0,0,0,0,0,0,0,0,9,6,6,6,6,6,6,9,9,0,0,6,9,9,0
9,12,0,0,0,0,6,6,6,6,6,0,0,0,0,0,0,0,0,0,0,0,0,0,49,0,48,6,6,6,6,6,6,9,9,0,0,6,9,6,0
0,12,9,0,0,0,6,6,6,6,6,0,0,0,0,6,0,0,0,6,0,0,0,0,0,0,9,6,6,6,6,6,6,0,0,0,0,45,0,47,0
0,12,0,0,0,0,6,6,6,6,6,0,0,0,6,6,6,32,6,6,6,0,0,0,0,0,46,6,6,6,6,6,6,0,0,0,0,45,0,44,0
9,12,0,9,0,0,6,6,6,6,6,6,6,6,6,21,0,0,0,6,15,0,0,0,0,0,43,6,6,6,6,6,6,0,0,0,0,6,0,6,0
9,12,0,0,0,0,6,6,20,20,6,35,35,41,0,0,0,0,0,6,15,0,0,0,0,0,0,6,6,6,6,6,6,9,0,0,0,6,0,0,0
9,12,9,0,0,0,6,0,0,0,0,21,0,0,0,0,0,0,37,6,15,0,0,0,0,0,0,6,6,6,6,6,6,9,0,0,0,6,0,0,0
9,12,0,0,0,0,6,41,12,42,0,12,0,0,0,21,0,0,37,6,15,0,0,0,0,0,0,6,6,6,6,6,6,9,0,0,0,6,9,9,0
9,12,0,0,0,0,6,0,0,0,17,17,0,0,41,12,37,0,37,6,15,0,0,0,0,0,9,0,9,9,0,0,0,9,0,0,0,6,9,9,0
0,12,0,0,9,0,6,0,0,0,0,0,0,0,0,17,0,0,37,6,15,0,0,0,0,0,0,0,0,0,0,0,0,0,0,0,0,6,0,0,0
0,6,0,0,0,0,6,0,0,0,0,0,0,0,0,0,0,40,37,6,15,0,0,0,0,0,0,0,0,0,0,39,0,0,0,0,0,6,0,0,0
0,12,0,0,9,0,6,0,0,0,0,0,38,38,38,6,17,17,37,6,15,0,0,0,0,0,0,0,0,0,0,0,0,0,0,0,0,6,0,0,0
0,12,0,0,0,0,6,36,35,35,35,35,2,2,2,6,6,6,6,6,6,0,0,0,0,0,0,0,0,0,0,0,0,9,9,9,0,6,9,9,0
0,12,0,0,0,0,6,0,34,0,0,0,2,2,2,6,15,0,0,33,0,0,0,0,0,0,5,6,32,6,6,5,6,6,6,6,5,6,9,9,0
9,12,0,0,0,0,6,29,31,0,0,0,2,2,2,6,15,0,0,30,0,0,0,0,0,0,6,0,0,0,0,6,29,0,21,0,28,6,9,9,0
9,12,0,0,0,0,6,6,6,6,27,6,6,2,6,2,6,6,6,6,6,27,0,0,0,0,6,26,0,0,0,6,0,0,0,0,25,6,0,0,0
9,12,9,0,0,0,6,2,2,2,2,2,2,2,2,2,2,2,2,2,6,15,0,0,0,0,6,24,0,0,0,23,0,0,22,0,6,6,0,0,0
9,12,0,0,9,0,6,2,2,2,2,2,2,2,2,2,2,2,2,2,6,15,0,0,0,0,6,21,21,21,0,6,18,0,0,0,20,6,0,0,0
9,12,0,9,0,0,6,2,2,2,2,2,6,2,2,2,2,2,2,2,6,15,0,0,0,0,6,12,12,12,19,6,18,0,0,0,6,6,0,0,0
0,12,0,0,0,0,6,2,2,2,2,2,6,2,2,2,2,2,2,2,6,15,0,0,0,0,6,17,17,17,0,6,6,15,0,0,16,6,0,0,0
9,12,0,0,0,0,6,2,2,2,2,2,6,6,6,6,6,6,6,6,6,15,0,0,0,0,5,6,6,6,6,5,6,6,6,6,5,6,0,0,0
0,12,9,0,0,0,6,2,2,2,2,2,2,2,2,2,2,2,2,2,6,15,0,0,0,0,0,0,0,0,0,0,0,0,0,0,0,6,0,0,0
9,12,0,0,0,0,6,2,2,2,2,2,2,2,2,2,2,2,2,2,6,6,14,14,6,6,0,0,0,0,0,0,0,0,0,0,0,6,0,0,0
0,12,12,13,12,12,6,6,6,6,6,6,6,6,6,6,6,6,6,6,6,0,11,0,10,6,6,6,6,6,6,6,6,6,6,6,6,6,0,9,0
9,9,0,9,0,0,0,0,9,9,9,0,0,0,9,9,9,9,0,0,0,0,0,0,9,9,0,9,0,9,9,9,9,0,0,0,9,9,9,0,0
0,9,9,9,0,0,0,9,9,9,9,9,0,0,9,9,0,0,0,0,0,0,0,0,9,9,9,0,0,0,9,9,0,0,0,9,9,9,9,9,0
:endlayer
layer: 4
0,0,0,0,0,0,0,0,0,0,0,0,0,0,0,0,0,0,0,0,0,0,0,0,0,0,0,0,0,0,0,0,0,0,0,0,0,0,0,0,0
0,0,0,0,0,0,0,0,0,0,0,0,0,0,0,0,0,0,0,0,0,0,0,0,0,0,0,0,0,0,0,0,0,0,0,0,0,0,0,0,0
0,0,0,0,0,0,0,0,0,0,0,0,0,0,0,0,0,0,0,0,0,0,0,0,0,0,0,0,0,0,0,0,0,0,0,0,0,0,0,0,0
0,87,0,0,0,0,5,6,6,6,6,6,6,5,6,6,6,6,6,6,5,6,6,6,6,6,6,6,6,6,6,6,6,6,6,6,6,5,0,0,0
0,0,0,0,0,0,6,0,0,0,0,85,0,0,0,0,0,0,80,79,6,0,0,0,0,0,0,0,0,0,0,0,0,0,0,0,0,6,0,0,0
0,0,0,0,0,0,6,0,0,0,0,0,0,0,0,0,0,0,0,79,6,0,0,0,0,0,0,0,0,0,0,0,0,0,0,0,0,6,0,0,0
0,87,0,0,0,0,5,0,0,0,0,0,0,0,0,0,0,0,0,0,6,0,0,0,0,0,12,0,0,12,0,0,12,0,0,0,0,6,0,0,0
0,0,0,0,0,0,128,0,0,0,0,0,0,0,0,0,0,0,0,0,6,12,0,12,0,12,12,0,12,12,0,12,12,0,0,0,0,6,0,0,0
0,0,0,0,0,0,127,0,0,0,0,0,0,0,0,0,0,0,0,0,0,0,0,0,0,0,0,0,0,0,0,0,0,0,0,0,66,6,0,0,0
0,0,0,0,0,0,126,0,0,0,0,0,0,0,0,0,0,0,0,0,0,0,0,0,0,0,0,0,0,0,0,0,0,0,0,0,0,6,0,0,0
0,0,0,0,0,0,125,0,0,0,0,0,0,0,0,0,0,0,0,0,6,0,0,12,0,0,12,0,0,12,0,0,12,0,0,0,0,6,0,0,0
0,87,0,0,0,0,124,0,0,0,0,0,0,0,0,0,0,0,0,0,6,0,0,0,0,0,0,0,0,0,0,0,0,0,0,0,0,6,0,0,0
0,0,0,0,0,0,5,0,0,0,0,0,0,0,0,0,0,0,0,0,6,6,6,6,6,6,6,6,6,6,6,6,6,6,6,32,6,5,0,0,0
0,0,0,0,0,0,6,6,6,0,0,6,6,0,0,0,0,0,0,0,6,0,0,0,0,0,0,6,0,0,0,0,123,35,35,0,0,6,0,0,0
0,0,0,0,0,0,6,6,0,0,0,0,6,0,0,0,0,0,0,0,6,0,0,0,0,0,0,6,0,0,0,0,37,35,35,0,0,6,0,0,0
0,6,0,0,0,0,5,6,6,6,0,0,6,6,5,6,122,6,101,6,5,0,0,0,0,0,0,6,35,32,35,35,35,35,35,32,35,6,0,0,0
0,0,0,0,0,0,6,6,0,0,0,0,6,0,0,0,0,0,0,121,0,0,0,0,0,0,0,6,120,0,119,0,0,119,0,0,118,6,0,0,0
0,0,0,0,0,0,6,6,0,0,0,0,6,0,0,0,0,0,0,0,0,0,0,0,0,0,0,6,0,0,116,0,0,116,0,0,0,6,0,0,0
0,87,0,0,0,0,5,6,6,6,0,0,6,0,0,0,0,12,0,0,12,0,0,0,0,0,0,6,114,114,114,0,0,116,0,0,0,6,0,0,0
0,0,0,0,0,0,0,6,0,0,0,0,0,0,0,0,0,0,0,0,0,0,0,0,0,0,0,6,0,0,117,0,0,116,0,0,29,6,0,0,0
0,0,0,0,0,0,0,88,0,0,0,0,0,0,0,0,0,0,0,0,0,0,0,0,0,0,0,6,0,0,0,0,0,116,0,0,115,6,0,0,0
0,0,0,0,0,0,0,89,0,0,0,0,0,0,0,0,0,12,0,0,12,0,0,0,0,0,0,23,0,0,0,0,6,6,6,32,6,5,0,0,0
0,0,0,0,0,0,0,6,0,0,0,0,0,0,0,0,0,0,0,0,0,0,0,0,0,0,0,6,114,114,114,113,6,0,0,0,0,6,0,0,0
0,87,0,0,0,0,5,35,35,35,5,0,0,0,0,0,0,0,0,0,0,0,0,0,0,0,0,6,112,0,0,0,6,0,0,0,0,6,0,0,0
0,0,0,0,0,0,6,12,0,0,35,0,0,0,0,0,0,0,0,0,0,0,0,0,0,0,0,6,6,6,6,6,6,0,0,0,0,6,0,0,0
0,0,0,0,0,0,6,111,0,0,23,0,0,0,0,0,0,0,0,0,0,0,0,0,0,0,0,6,0,0,0,0,6,0,0,0,0,6,0,0,0
0,0,0,0,0,0,6,110,0,0,35,0,0,0,0,0,0,0,0,0,0,0,0,0,0,0,0,32,0,0,0,0,6,0,0,0,0,6,109,20,0
0,0,0,0,0,0,6,108,0,108,35,0,0,0,0,6,0,0,0,6,0,0,0,0,0,0,0,6,0,0,0,0,6,0,0,0,0,89,0,0,0
0,0,0,0,0,0,6,107,0,107,5,0,0,0,6,6,6,101,6,6,6,0,0,0,0,0,0,6,0,0,0,0,6,0,0,0,0,88,0,0,0
0,0,0,0,0,0,5,6,6,6,6,6,6,5,6,0,0,0,0,6,0,0,0,0,0,0,0,6,106,0,0,105,6,0,0,0,0,6,0,20,0
0,0,0,0,0,0,6,6,0,0,6,35,41,0,0,0,0,0,0,6,0,0,0,0,0,0,0,6,104,0,0,104,6,0,0,0,0,6,0,0,0
0,0,0,0,0,0,6,0,0,0,0,0,0,0,0,0,0,0,0,6,0,0,0,0,0,0,0,6,103,94,94,103,6,0,0,0,0,6,0,0,0
0,0,0,0,0,0,6,0,98,0,0,98,0,0,0,0,0,0,0,6,0,0,0,0,0,0,0,6,6,6,6,6,6,0,0,0,0,6,0,0,0
0,0,0,0,0,0,6,0,0,0,0,0,0,0,0,98,0,0,0,6,0,0,0,0,0,0,0,0,0,0,0,0,0,0,0,0,0,6,0,0,0
0,0,0,0,0,0,6,0,0,0,0,0,0,0,0,0,0,0,0,6,0,0,0,0,0,0,0,0,0,0,0,0,0,0,0,0,0,6,0,0,0
0,6,0,0,0,0,6,0,0,0,0,0,0,0,0,0,0,0,0,6,0,0,0,0,0,0,0,0,0,0,0,0,0,0,0,0,0,6,0,0,0
0,0,0,0,0,0,6,0,0,0,0,0,0,0,0,6,0,0,0,6,0,0,0,0,0,0,0,0,0,0,0,0,0,0,0,0,0,6,0,0,0
0,0,0,0,0,0,6,0,0,0,0,0,35,0,0,6,6,6,6,6,6,0,0,0,0,0,0,0,0,0,0,0,0,0,0,0,0,6,0,0,0
0,0,0,0,0,0,6,0,0,0,0,0,35,0,0,32,0,0,0,0,0,0,0,0,0,0,5,6,101,6,6,5,6,92,6,6,5,6,0,0,0
0,0,0,0,0,0,6,0,0,0,0,0,35,0,0,32,0,0,0,0,0,0,0,0,0,0,6,0,0,0,0,6,0,0,0,0,0,6,0,0,0
0,0,0,0,0,0,5,6,6,6,0,6,6,32,6,6,6,6,6,6,5,0,0,0,0,0,6,0,0,0,0,6,0,0,0,0,0,6,0,0,0
0,0,0,0,0,0,6,102,0,0,23,0,6,0,0,0,0,0,12,37,6,0,0,0,0,0,93,0,0,0,0,101,0,0,0,0,6,6,0,0,0
0,0,0,0,0,0,6,16,0,100,0,0,23,0,0,0,99,0,12,37,6,0,0,0,0,0,6,0,0,0,0,6,0,0,0,0,0,6,0,0,0
0,0,0,0,0,0,6,29,0,0,0,0,6,17,0,0,0,0,0,0,6,0,0,0,0,0,6,98,98,98,0,6,0,0,0,0,6,6,0,0,0
0,0,0,0,0,0,6,18,97,96,0,0,6,35,35,35,94,94,95,94,6,0,0,0,0,0,6,0,0,0,0,6,15,0,0,0,0,6,0,0,0
0,0,0,0,0,0,5,6,6,6,23,6,6,6,6,6,6,6,6,6,5,0,0,0,0,0,5,6,6,93,6,5,6,92,6,6,5,6,0,0,0
0,0,0,0,0,0,6,0,0,0,0,0,0,0,0,0,0,0,0,0,91,0,0,0,0,0,0,0,0,0,0,0,0,0,0,90,0,6,0,0,0
0,0,0,0,0,0,6,0,0,0,0,0,0,0,0,0,0,0,0,0,6,6,89,88,6,6,0,0,0,0,0,0,0,0,0,0,0,6,0,0,0
0,87,0,0,0,0,6,6,6,6,6,6,6,6,6,6,6,6,6,6,6,86,0,0,0,6,6,6,6,6,6,6,6,6,6,6,6,6,0,0,0
0,0,0,0,0,0,0,0,0,0,0,0,0,0,0,0,0,0,0,0,0,0,0,0,0,0,0,0,0,0,0,0,0,0,0,0,0,0,0,0,0
0,0,0,0,0,0,0,0,0,0,0,0,0,0,0,0,0,0,0,0,0,0,0,0,0,0,0,0,0,0,0,0,0,0,0,0,0,0,0,0,0
:endlayer
layer: 5
0,0,0,0,0,0,0,0,0,0,0,0,0,0,0,0,0,0,0,0,0,0,0,0,0,0,0,0,0,0,0,0,0,0,0,0,0,0,0,0,0
0,0,0,0,0,0,0,0,0,0,0,0,0,0,0,0,0,0,0,0,0,0,0,0,0,0,0,0,0,0,0,0,0,0,0,0,0,0,0,0,0
0,0,0,0,0,0,0,0,0,0,0,0,0,0,0,0,0,0,0,0,0,0,0,0,0,0,0,0,0,0,0,0,0,0,0,0,0,0,0,0,0
0,0,0,0,0,0,5,6,6,6,6,6,6,5,6,6,6,6,6,6,5,6,93,6,6,93,6,6,93,6,6,93,6,6,93,6,6,5,0,0,0
0,0,0,0,0,0,6,0,0,0,0,85,0,90,0,0,0,0,0,80,6,90,0,12,90,0,12,90,0,12,90,0,12,0,0,0,90,6,0,0,0
0,0,0,0,0,0,6,132,0,0,0,0,0,0,0,0,0,0,0,80,6,0,0,12,0,0,12,0,0,12,0,0,12,0,0,0,0,6,0,0,0
0,0,0,0,0,0,5,0,0,0,0,0,0,0,0,0,0,0,0,0,6,0,0,12,0,0,12,0,0,12,0,0,12,0,0,0,0,6,0,0,0
0,0,0,0,0,0,144,0,0,0,0,0,0,0,0,0,0,0,0,130,6,12,0,12,0,12,12,0,12,12,0,12,12,0,0,0,0,6,0,0,0
0,0,0,0,0,0,143,0,0,0,0,0,0,0,0,0,0,0,0,0,0,0,0,0,0,0,0,0,0,0,0,0,0,0,0,0,66,6,0,0,0
0,0,0,0,0,0,142,0,0,0,0,0,0,0,0,0,0,0,0,0,0,0,0,0,0,0,0,0,0,0,0,0,0,0,0,0,0,6,0,0,0
0,0,0,0,0,0,141,0,0,0,0,0,0,0,0,0,0,0,0,130,6,0,0,12,0,0,12,0,0,12,0,0,12,0,0,0,0,6,0,0,0
0,0,0,0,0,0,140,0,0,0,0,0,0,0,0,0,0,0,0,0,6,0,0,12,0,131,12,0,131,12,0,131,12,0,0,0,131,6,0,0,0
0,0,0,0,0,139,5,0,131,0,0,131,0,0,0,0,0,0,0,0,6,6,6,6,93,6,6,6,6,6,6,6,6,6,6,101,6,5,0,0,0
0,0,0,0,0,0,6,6,6,0,0,6,6,0,0,0,0,0,0,0,6,0,90,0,0,0,0,6,0,0,0,0,0,35,35,0,0,6,0,0,0
0,0,0,0,0,0,6,6,132,0,0,90,6,0,131,0,0,0,131,0,6,0,0,0,0,0,130,6,132,0,0,0,0,37,35,0,130,6,0,0,0
0,20,0,0,0,0,5,6,6,6,0,0,6,6,5,6,6,6,6,6,5,132,0,0,0,0,0,6,35,101,35,35,35,35,35,101,35,6,132,0,0
0,0,0,0,0,0,6,6,0,122,0,0,122,0,90,0,0,0,0,0,90,0,0,0,0,0,0,35,0,0,0,0,0,0,0,0,0,6,0,0,0
0,0,0,0,0,0,6,6,0,122,0,0,122,0,0,0,0,0,0,0,0,0,0,0,0,0,0,5,0,0,0,0,0,0,0,0,0,6,0,0,0
0,0,0,0,0,138,5,6,6,6,122,122,6,132,0,0,0,12,0,0,12,0,0,0,0,0,0,93,0,0,0,0,0,0,0,0,0,6,0,0,0
0,0,0,0,0,0,130,6,132,0,0,0,90,0,0,0,0,0,0,0,0,0,0,0,0,0,0,5,0,0,0,0,0,0,0,0,0,6,0,0,0
0,0,0,0,0,0,0,135,0,0,0,0,0,0,0,0,0,0,0,0,0,0,0,0,0,0,137,35,0,0,0,0,0,0,0,0,0,6,0,0,0
0,0,0,0,0,0,0,135,0,0,0,0,0,0,0,0,0,12,0,0,12,0,0,0,0,0,0,101,0,0,0,0,35,6,6,101,6,5,0,0,0
0,0,0,0,0,0,130,6,132,0,0,0,0,0,0,0,0,0,0,0,0,0,0,0,0,0,130,35,0,0,0,0,6,0,0,0,90,6,0,0,0
0,0,0,0,0,136,5,35,93,35,5,132,0,0,0,0,0,0,0,0,0,0,0,0,0,0,0,6,0,0,0,0,6,0,0,0,0,12,0,0,0
0,0,0,0,0,0,6,98,0,0,35,0,0,0,0,0,0,0,0,0,0,0,0,0,0,0,0,6,35,35,35,35,6,132,0,0,0,12,0,0,0
0,0,0,0,0,0,6,0,0,0,101,0,0,0,0,0,0,0,0,0,0,0,0,0,0,0,0,35,0,0,0,0,35,0,0,0,0,12,0,0,0
0,0,0,0,0,0,6,0,0,0,35,132,0,0,0,0,0,0,0,0,0,0,0,0,0,0,0,101,0,0,0,0,93,0,0,0,130,6,132,0,0
0,0,0,0,0,0,6,0,0,0,35,0,0,0,0,6,131,0,131,6,0,0,0,0,0,0,0,35,0,0,0,0,93,0,0,0,0,135,0,0,0
0,0,0,0,0,0,6,0,0,0,5,0,0,0,6,6,6,6,6,6,6,0,0,0,0,0,0,93,0,0,0,0,35,0,0,0,0,135,0,0,0
0,0,0,0,0,0,5,6,6,6,6,6,6,5,6,0,0,0,0,6,0,0,0,0,0,0,0,93,0,0,0,0,93,0,0,0,130,6,132,0,0
0,0,0,0,0,0,6,6,6,6,6,41,0,0,0,0,0,0,0,93,0,0,0,0,0,0,0,93,0,0,0,0,93,0,0,0,0,12,0,0,0
0,0,0,0,0,0,6,0,0,0,0,0,0,0,0,0,0,0,0,6,0,0,0,0,0,0,0,35,0,0,0,0,35,0,0,0,0,12,0,0,0
0,0,0,0,0,0,6,0,0,0,0,0,0,0,0,0,0,0,0,6,0,0,0,0,0,0,0,6,35,93,93,35,6,0,0,0,0,12,0,0,0
0,0,0,0,0,0,93,0,0,0,0,0,0,0,0,0,0,0,0,6,0,0,0,0,0,0,0,0,0,0,0,0,0,0,0,0,0,12,0,0,0
0,0,0,0,0,0,6,0,0,0,0,0,0,0,0,0,0,0,0,93,0,0,0,0,0,0,0,0,0,0,0,0,0,0,0,0,0,12,0,0,0
0,20,0,0,0,0,93,0,0,0,0,0,0,0,0,0,0,0,0,6,0,0,0,0,0,0,0,0,0,0,0,0,0,0,0,0,0,12,0,0,0
0,0,0,0,0,0,6,0,0,0,0,0,0,0,0,6,0,0,0,6,0,0,0,0,0,0,0,0,0,0,0,0,0,0,0,0,0,12,0,0,0
0,0,0,0,0,0,93,0,0,0,0,0,35,0,0,6,6,93,6,6,6,0,0,0,0,0,131,0,0,0,0,131,0,0,0,0,0,41,0,0,0
0,0,0,0,0,0,6,0,0,0,0,0,12,0,0,101,0,0,0,0,0,0,0,0,0,130,5,6,6,6,6,5,6,6,6,6,5,41,0,0,0
0,0,0,0,0,0,6,0,131,0,0,0,12,0,0,134,0,0,0,0,0,0,0,0,0,0,6,132,0,0,90,6,0,0,0,0,130,41,0,0,0
0,0,0,0,0,0,5,6,6,6,0,6,6,101,6,6,35,93,93,35,5,0,0,0,0,0,6,0,0,0,0,6,132,0,0,0,0,41,0,0,0
0,0,0,0,0,0,6,133,0,90,101,0,6,0,0,90,0,0,98,0,35,0,0,0,0,0,6,0,0,0,0,6,0,0,0,0,6,41,0,0,0
0,0,0,0,0,0,6,0,0,0,0,0,101,0,0,0,0,0,98,0,93,0,0,0,0,0,6,0,0,0,0,6,0,0,0,0,6,41,0,0,0
0,0,0,0,0,0,93,0,0,0,0,0,6,0,0,0,0,0,0,0,93,0,0,0,0,0,6,0,0,0,0,6,132,0,0,0,6,41,0,0,0
0,0,0,0,0,0,6,0,0,0,0,0,6,0,37,35,94,94,0,94,35,0,0,0,0,0,6,131,0,0,131,15,0,0,0,0,131,41,0,0,0
0,0,0,0,0,0,5,6,93,6,101,6,6,6,35,35,35,35,93,35,5,0,0,0,0,130,5,6,6,6,6,5,6,6,6,6,5,41,0,0,0
0,0,0,0,0,0,0,0,0,0,0,0,0,0,0,0,0,0,0,0,0,0,0,0,0,0,90,0,0,0,0,90,0,0,0,0,0,41,0,0,0
0,0,0,0,0,0,0,0,0,0,0,0,0,0,0,0,0,0,0,0,0,6,129,129,6,0,0,0,0,0,0,0,0,0,0,0,0,0,0,0,0
0,0,0,0,0,0,87,0,0,0,0,87,0,0,0,0,87,0,0,0,0,90,0,0,90,87,0,0,0,0,0,0,0,0,0,0,0,87,0,0,0
0,0,0,0,0,0,0,0,0,0,0,0,0,0,0,0,0,0,0,0,0,0,0,0,0,0,0,0,0,0,0,0,0,0,0,0,0,0,0,0,0
0,0,0,0,0,0,0,0,0,0,0,0,0,0,0,0,0,0,0,0,0,0,0,0,0,0,0,0,0,0,0,0,0,0,0,0,0,0,0,0,0
:endlayer
layer: 6
0,0,0,0,0,0,0,0,0,0,0,0,0,0,0,0,0,0,0,0,0,0,0,0,0,0,0,0,0,0,0,0,0,0,0,0,0,0,0,0,0
0,0,0,0,0,0,0,0,0,0,0,0,0,0,0,0,0,0,0,0,0,0,0,0,0,0,0,0,0,0,0,0,0,0,0,0,0,0,0,0,0
0,0,0,0,0,0,0,0,0,0,0,0,0,0,0,0,0,0,0,0,0,0,0,131,0,0,0,0,0,131,0,0,0,0,0,0,0,131,0,0,0
0,0,0,0,0,0,5,6,6,6,6,6,6,5,6,6,6,6,6,6,5,6,6,6,6,6,6,6,6,6,6,6,6,6,6,6,6,5,132,0,0
0,0,0,0,0,0,6,0,0,0,0,85,0,0,0,0,0,0,0,0,6,35,35,35,35,35,35,35,35,35,35,35,35,35,35,35,35,6,0,0,0
0,0,0,0,0,130,6,0,0,0,0,0,0,0,0,0,0,0,0,80,6,35,35,35,35,35,35,35,35,35,35,35,35,35,35,35,35,6,0,0,0
0,0,0,0,0,0,5,0,0,0,0,0,0,0,0,0,0,0,0,0,6,35,35,35,35,35,35,35,35,35,35,35,35,35,35,35,35,6,0,0,0
0,0,0,0,0,0,157,0,0,0,0,0,0,0,0,0,0,0,0,0,6,35,35,35,35,35,35,35,35,35,35,35,35,35,35,35,35,6,0,0,0
0,0,0,0,0,0,156,0,0,0,0,0,0,0,0,0,0,0,0,0,6,35,35,0,0,0,0,0,0,0,0,0,0,0,35,35,66,6,0,0,0
0,0,0,0,0,0,155,0,0,0,0,0,0,0,0,0,0,0,0,0,6,35,35,0,0,0,0,0,0,0,0,0,0,0,35,35,35,6,0,0,0
0,0,0,0,0,0,154,0,0,0,0,0,0,0,0,0,0,0,0,0,6,35,35,35,35,35,35,35,35,35,35,35,35,35,35,35,35,6,0,0,0
0,0,0,0,0,0,153,0,0,0,0,0,0,0,0,0,0,0,0,0,6,35,35,35,35,35,35,35,35,35,35,35,35,35,35,35,35,6,0,0,0
0,0,0,0,0,0,5,0,0,0,0,0,0,0,0,0,0,0,0,0,6,6,6,6,6,6,6,6,6,6,6,6,6,6,6,6,6,5,0,0,0
0,0,0,0,0,130,6,6,6,6,6,6,6,0,0,0,0,0,0,0,6,0,0,0,0,0,37,6,0,0,0,0,0,35,35,35,35,5,0,0,0
0,0,0,0,0,0,6,6,6,6,6,6,6,0,0,0,0,0,0,0,6,0,0,0,0,0,37,6,0,0,0,0,0,0,37,35,35,5,0,0,0
0,0,0,0,0,0,5,6,6,6,6,6,6,6,5,6,6,6,6,6,5,0,0,0,0,0,37,6,35,35,35,35,35,35,35,35,35,5,0,0,0
0,0,0,0,0,0,6,6,0,122,0,0,6,0,0,0,0,0,0,0,0,0,0,0,0,0,37,35,132,0,12,0,0,12,0,0,90,5,0,0,0
0,0,0,0,0,0,6,6,0,122,0,0,6,0,0,0,0,0,0,0,0,0,0,0,0,0,37,35,0,0,12,0,0,12,0,0,152,5,0,0,0
0,0,0,0,0,0,5,6,6,6,6,6,6,0,0,0,0,6,6,6,6,132,0,0,0,0,37,35,12,12,12,0,151,12,0,0,150,5,0,0,0
0,0,0,0,0,0,0,6,0,0,0,18,0,0,0,0,0,6,6,6,6,0,0,0,0,0,37,35,0,149,0,0,0,12,0,0,148,5,0,0,0
0,0,0,0,0,0,0,6,0,0,0,18,0,0,0,0,0,6,6,6,6,0,0,0,0,0,37,35,0,0,0,0,0,12,0,0,131,5,0,0,0
0,0,0,0,0,0,0,6,0,0,0,18,0,0,0,0,0,6,6,6,6,132,0,0,0,0,37,35,132,147,0,0,35,6,6,6,6,5,0,0,0
0,0,0,0,0,0,0,6,0,0,131,18,0,0,0,0,0,90,0,0,90,0,0,0,0,0,37,35,12,12,12,12,6,21,21,21,21,21,21,0,0
0,0,0,0,0,0,5,35,35,35,5,18,0,0,0,0,0,0,0,0,0,0,0,0,0,0,37,6,0,0,0,0,6,0,0,0,0,0,0,0,0
0,0,0,0,0,0,6,0,0,0,35,18,0,0,0,0,0,0,0,0,0,0,0,0,0,0,0,6,35,35,35,35,6,0,0,0,0,0,0,0,0
0,0,0,0,0,0,6,0,0,130,35,18,0,0,0,0,0,0,0,0,0,0,0,0,0,0,0,35,0,0,0,0,35,0,0,0,0,17,0,0,0
0,0,0,0,0,0,6,0,0,0,35,18,0,0,0,0,0,0,0,0,0,0,0,0,0,0,130,35,0,0,0,0,35,0,0,0,37,6,41,0,0
0,0,0,0,0,0,6,0,0,0,35,18,0,0,0,6,0,0,0,6,0,0,0,0,0,0,0,35,0,0,0,0,35,0,0,0,37,6,41,0,0
0,0,0,0,0,0,6,0,131,0,5,18,0,0,6,6,6,6,6,6,6,0,0,0,0,0,0,93,0,0,0,0,35,0,0,0,37,6,41,0,0
0,0,0,0,0,0,5,6,6,6,6,6,6,5,6,132,0,90,0,6,0,0,0,0,0,0,0,93,0,0,0,0,35,0,0,0,37,6,41,0,0
0,0,0,0,0,0,6,35,35,35,41,0,0,0,90,0,0,0,0,93,0,0,0,0,0,0,0,93,0,0,0,0,35,0,0,0,0,21,0,0,0
0,0,0,0,0,130,6,0,0,0,0,0,0,0,0,0,0,0,0,6,0,0,0,0,0,0,0,35,0,0,0,0,35,0,0,0,0,0,0,0,0
0,0,0,0,0,0,6,132,0,0,0,0,0,0,0,0,0,0,0,6,132,0,0,0,0,0,130,6,35,93,93,35,6,0,0,0,0,0,0,0,0
0,0,0,0,0,0,93,0,0,0,0,0,0,0,0,0,0,0,0,6,0,0,0,0,0,0,0,90,0,0,0,0,0,0,0,0,0,0,0,0,0
0,0,0,0,0,0,6,132,0,0,0,0,0,0,0,0,0,0,0,93,0,0,0,0,0,0,0,0,0,0,0,0,0,0,0,0,0,0,0,0,0
0,0,0,0,0,0,93,0,0,0,0,0,0,0,0,131,0,0,130,6,0,0,0,0,0,0,0,0,0,0,0,0,0,0,0,0,0,0,0,0,0
0,0,0,0,0,0,6,132,0,0,0,0,0,0,130,6,0,0,0,6,132,0,0,0,0,0,0,0,0,0,0,0,0,0,0,0,0,0,0,0,0
0,0,0,0,0,0,93,0,0,0,0,130,35,0,0,6,6,93,6,6,6,0,0,0,0,145,0,0,0,0,0,0,0,0,0,0,41,0,0,0,0
0,0,0,0,0,0,6,132,0,0,0,0,12,0,130,6,132,0,0,0,0,0,0,0,0,145,5,5,5,5,5,5,5,5,5,5,41,0,0,0,0
0,0,0,0,0,0,6,0,0,0,0,0,12,131,0,6,132,0,0,0,131,0,0,0,0,145,5,2,2,2,2,2,2,2,2,2,41,0,0,0,0
0,0,0,0,0,130,5,6,6,6,6,6,6,6,6,6,35,93,93,35,5,132,0,0,0,145,5,2,2,2,2,2,2,2,2,2,41,0,0,0,0
0,0,0,0,0,0,6,146,0,0,0,0,6,0,0,0,0,0,0,130,35,0,0,0,0,145,5,2,2,2,2,2,2,2,2,2,41,0,0,0,0
0,0,0,0,0,0,6,0,0,0,0,0,6,0,0,0,0,0,0,0,93,0,0,0,0,145,5,2,2,2,2,2,2,2,2,2,41,0,0,0,0
0,0,0,0,0,0,93,0,0,0,0,130,6,0,0,0,0,0,0,0,93,0,0,0,0,145,5,2,2,2,2,2,2,2,2,2,41,0,0,0,0
0,0,0,0,0,0,6,132,0,0,131,0,6,0,0,37,94,94,0,94,35,0,0,0,0,145,5,2,2,2,15,0,0,0,0,2,41,0,0,0,0
0,0,0,0,0,0,5,6,93,6,6,6,6,6,35,35,35,35,93,35,5,0,0,0,0,145,5,5,5,5,5,5,5,5,5,5,41,0,0,0,0
0,0,0,0,0,0,0,0,0,0,90,0,0,0,0,0,0,0,0,0,0,17,17,17,17,145,0,0,0,0,0,0,0,0,0,0,41,0,0,0,0
0,0,0,0,0,0,0,0,0,0,0,0,0,0,0,0,0,0,0,0,37,6,6,6,6,41,0,0,0,0,0,0,0,0,0,0,0,0,0,0,0
0,0,0,0,0,0,0,0,0,0,0,0,0,0,0,0,0,0,0,0,0,21,21,21,21,0,0,0,0,0,0,0,0,0,0,0,0,0,0,0,0
0,0,0,0,0,0,0,0,0,0,0,0,0,0,0,0,0,0,0,0,0,0,0,0,0,0,0,0,0,0,0,0,0,0,0,0,0,0,0,0,0
0,0,0,0,0,0,0,0,0,0,0,0,0,0,0,0,0,0,0,0,0,0,0,0,0,0,0,0,0,0,0,0,0,0,0,0,0,0,0,0,0
:endlayer
layer: 7
0,0,0,0,0,0,0,0,0,0,0,0,0,0,0,0,0,0,0,0,0,0,0,0,0,0,0,0,0,0,0,0,0,0,0,0,0,0,0,0,0
0,0,0,0,0,0,0,0,0,0,0,0,0,0,0,0,0,0,0,0,0,0,0,0,0,0,0,0,0,0,0,0,0,0,0,0,0,0,0,0,0
0,0,0,0,0,0,131,0,0,0,0,0,0,131,0,0,0,0,0,0,131,17,17,17,17,17,17,17,17,17,17,17,17,17,17,17,17,17,17,0,0
0,0,0,0,0,130,5,6,6,6,6,6,6,5,6,6,6,6,6,6,5,6,6,6,6,6,6,6,6,6,6,6,6,6,6,6,6,5,0,0,0
0,0,0,0,0,0,6,0,0,0,0,85,0,0,0,0,0,0,0,0,6,0,0,0,0,0,0,0,0,0,0,0,0,0,0,0,0,5,0,0,0
0,0,0,0,0,0,6,0,0,0,0,0,0,0,0,0,0,0,0,80,41,0,0,0,0,0,0,0,0,0,0,0,0,0,0,0,0,5,0,0,0
0,0,0,0,0,0,5,0,0,0,0,0,0,0,0,0,0,0,0,0,6,0,0,0,0,0,0,0,0,0,174,0,0,0,0,0,0,5,0,0,0
0,0,0,0,0,0,173,0,0,0,0,0,0,0,0,0,0,0,0,0,6,0,12,12,12,12,12,12,12,12,12,12,12,12,12,0,0,5,0,0,0
0,0,0,0,0,0,172,0,0,0,0,0,0,0,0,0,0,0,0,0,6,0,0,0,0,0,0,0,0,0,0,0,0,0,0,0,66,5,0,0,0
0,0,0,0,0,0,171,0,0,0,0,0,0,0,0,0,0,0,0,0,6,0,12,0,0,0,0,0,0,0,0,0,0,0,12,0,0,5,0,0,0
0,0,0,0,0,0,170,0,0,0,0,0,0,0,0,0,0,0,0,0,6,0,12,12,12,12,12,12,12,12,12,12,12,12,12,0,0,5,0,0,0
0,0,0,0,0,0,169,0,0,0,0,0,0,0,0,0,0,0,0,0,6,0,0,0,0,0,0,0,0,0,0,0,0,0,0,0,0,5,0,0,0
0,0,0,0,0,0,5,0,0,0,0,0,0,0,0,0,0,0,0,0,6,6,6,6,6,6,6,6,6,6,6,6,6,6,6,6,6,5,0,0,0
0,0,0,0,0,0,6,6,6,6,6,6,6,0,0,0,0,0,0,0,6,21,21,21,21,21,21,35,0,0,0,0,0,0,0,0,0,35,0,0,0
0,0,0,0,0,0,6,6,6,6,6,6,6,0,0,0,0,0,0,0,6,0,0,0,0,0,0,37,0,0,0,0,0,0,0,0,0,35,0,0,0
0,0,0,0,0,130,5,6,6,6,6,6,6,6,5,6,6,6,6,6,5,0,0,0,0,0,0,37,35,35,35,35,35,35,35,17,35,35,0,0,0
0,0,0,0,0,0,48,6,0,6,6,6,15,0,0,0,0,0,0,0,0,0,0,0,0,0,0,37,0,0,12,0,0,12,0,0,0,35,0,0,0
0,0,0,0,0,0,48,6,0,6,6,6,15,0,0,0,0,0,0,0,0,0,0,0,0,0,0,37,0,0,12,0,0,12,0,0,0,35,0,0,0
0,0,0,0,0,0,48,6,6,6,6,6,15,0,0,0,0,87,0,0,87,0,0,0,0,0,0,37,12,12,12,0,168,12,0,0,0,93,0,0,0
0,0,0,0,0,0,37,6,6,6,41,0,0,0,0,0,0,0,0,0,0,0,0,0,0,0,0,37,0,0,0,0,0,12,0,0,0,35,0,0,0
0,0,0,0,0,0,37,6,6,6,41,0,0,0,0,0,0,0,0,0,0,0,0,0,0,0,0,37,0,0,0,0,0,12,0,0,0,35,0,0,0
0,0,0,0,0,0,37,6,6,6,41,0,0,0,0,0,0,87,0,0,87,0,0,0,0,0,0,37,0,0,0,0,35,21,21,21,21,21,21,0,0
0,0,0,0,0,0,37,6,6,6,41,0,0,0,0,0,0,0,0,0,0,0,0,0,0,0,0,37,12,12,12,12,41,0,0,0,0,0,0,0,0
0,0,0,0,0,0,37,5,5,5,41,0,0,0,0,0,0,0,0,0,0,0,0,0,0,0,0,6,0,0,0,130,6,0,0,0,0,0,0,0,0
0,0,0,0,0,0,37,0,0,0,41,0,0,0,0,0,0,0,0,0,0,0,0,0,0,0,0,6,35,35,35,35,6,0,0,0,0,0,0,0,0
0,0,0,0,0,0,37,0,0,0,41,0,0,0,0,0,0,0,0,0,0,0,0,0,0,0,0,35,132,0,0,130,35,0,0,0,0,0,0,0,0
0,0,0,0,0,0,37,0,0,0,41,0,0,0,0,167,167,167,167,167,0,0,0,0,0,0,0,35,0,0,0,0,35,0,0,0,0,158,0,0,0
0,0,0,0,0,0,37,0,0,0,41,0,0,0,0,6,6,6,6,6,0,0,0,0,0,0,0,35,0,0,0,0,35,0,0,0,0,158,0,0,0
0,0,0,0,0,0,37,0,0,0,41,0,0,0,6,6,6,6,6,6,6,0,0,0,0,0,0,35,0,0,0,0,35,0,0,0,0,158,0,0,0
0,0,0,0,0,0,5,6,6,6,6,6,6,5,6,166,6,6,6,6,0,0,0,0,0,0,0,35,0,0,0,0,35,0,0,0,0,158,0,0,0
0,0,0,0,0,0,6,35,35,41,0,0,0,0,0,166,6,6,6,6,0,0,0,0,0,0,0,35,0,0,0,0,35,0,0,0,0,0,0,0,0
0,0,0,0,0,0,6,0,0,0,0,0,0,0,0,166,6,6,6,6,0,0,0,0,0,0,0,35,132,0,0,130,35,0,0,0,0,0,0,0,0
0,0,0,0,0,0,6,0,0,0,0,0,0,0,0,166,165,165,165,6,0,0,0,0,0,0,0,6,35,35,35,35,6,132,0,0,0,0,0,0,0
0,0,0,0,0,0,93,0,0,0,0,0,0,0,0,166,0,0,0,6,0,0,0,0,0,0,0,0,0,0,0,0,90,0,0,0,0,0,0,0,0
0,0,0,0,0,0,6,0,0,0,0,0,0,0,0,166,0,0,0,6,0,0,0,0,0,0,0,0,0,0,0,0,0,0,0,0,0,0,0,0,0
0,0,0,0,0,0,93,0,0,0,0,0,0,0,0,166,0,0,0,6,0,0,0,0,0,0,0,0,0,0,0,0,0,0,0,0,0,0,0,0,0
0,0,0,0,0,0,6,0,0,0,0,0,0,0,0,6,165,165,165,6,0,0,0,0,0,0,0,0,0,0,0,0,0,0,0,0,0,0,0,0,0
0,0,0,0,0,0,93,0,0,0,0,0,35,0,0,6,6,6,6,6,6,0,0,0,0,0,37,158,158,158,158,158,158,158,158,41,0,0,0,0,0
0,0,0,0,0,0,6,0,0,0,0,0,12,0,0,6,0,0,0,6,0,0,0,0,0,0,37,6,6,6,6,6,6,6,6,41,0,0,0,0,0
0,0,0,0,0,0,6,0,0,0,0,0,12,0,0,6,0,0,0,6,0,0,0,0,0,0,37,6,164,0,21,0,0,163,0,41,0,0,0,0,0
0,0,0,0,0,0,5,6,6,6,6,6,6,35,35,6,35,35,35,35,5,0,0,0,0,0,37,6,0,0,0,0,0,162,0,41,0,0,0,0,0
0,0,0,0,0,0,6,35,35,35,35,35,6,35,35,35,35,35,35,35,35,0,0,0,0,0,37,6,161,160,0,0,0,0,0,41,0,0,0,0,0
0,0,0,0,0,0,6,35,35,35,35,35,6,35,35,35,35,35,35,35,35,0,0,0,0,0,37,6,161,160,0,0,0,0,0,41,0,0,0,0,0
0,0,0,0,0,0,6,35,35,35,35,35,6,0,0,35,35,35,35,35,35,0,0,0,0,0,37,6,0,0,0,0,12,12,2,41,0,0,0,0,0
0,0,0,0,0,0,6,35,35,35,35,35,6,0,0,0,37,35,35,35,35,0,0,0,0,0,37,6,159,0,0,0,0,0,0,41,0,0,0,0,0
0,0,0,0,0,0,5,6,6,6,6,6,6,6,35,35,35,35,35,35,5,132,0,0,0,0,37,6,6,6,6,6,6,6,6,41,0,0,0,0,0
0,0,0,0,0,0,0,0,0,0,0,0,0,0,0,0,0,0,0,0,90,0,0,0,0,0,37,0,0,0,0,0,0,0,0,41,0,0,0,0,0
0,0,0,0,0,0,0,0,0,0,0,0,0,0,0,0,0,0,0,0,0,158,158,158,158,0,0,0,0,0,0,0,0,0,0,0,0,0,0,0,0
0,0,0,0,0,0,0,0,0,0,0,0,0,0,0,0,0,0,0,0,0,0,0,0,0,0,0,0,0,0,0,0,0,0,0,0,0,0,0,0,0
0,0,0,0,0,0,0,0,0,0,0,0,0,0,0,0,0,0,0,0,0,0,0,0,0,0,0,0,0,0,0,0,0,0,0,0,0,0,0,0,0
0,0,0,0,0,0,0,0,0,0,0,0,0,0,0,0,0,0,0,0,0,0,0,0,0,0,0,0,0,0,0,0,0,0,0,0,0,0,0,0,0
:endlayer
layer: 8
0,0,0,0,0,0,0,0,0,0,0,0,0,0,0,0,0,0,0,0,0,0,0,0,0,0,0,0,0,0,0,0,0,0,0,0,0,0,0,0,0
0,0,0,0,0,0,0,0,0,0,0,0,0,0,0,0,0,0,0,0,0,0,0,0,0,0,0,0,0,0,0,0,0,0,0,0,0,0,0,0,0
0,0,0,0,0,0,0,0,0,0,0,0,0,0,0,0,0,0,0,0,0,0,0,0,0,0,0,0,0,0,0,0,0,0,0,0,0,0,0,0,0
0,0,0,0,0,0,5,5,5,5,5,5,5,5,5,5,5,5,5,5,5,17,17,17,17,17,17,17,17,17,17,17,17,17,17,17,17,17,17,0,0
0,0,0,0,0,0,5,35,35,35,35,85,35,35,35,35,35,35,35,35,6,0,0,0,0,0,0,90,0,0,0,0,0,0,0,0,0,35,0,0,0
0,0,0,0,0,0,5,35,35,35,35,35,35,35,35,35,35,35,35,41,0,0,0,0,0,0,0,0,0,0,0,0,0,0,0,0,130,35,0,0,0
0,0,0,0,0,0,116,35,35,0,0,0,0,0,0,35,35,35,35,35,6,0,0,0,0,0,0,0,0,0,0,0,0,0,0,0,0,35,0,0,0
0,0,0,0,0,0,116,35,35,0,0,0,0,0,0,35,35,35,35,35,6,0,0,0,0,0,0,0,0,0,0,0,0,0,0,0,0,35,0,0,0
0,0,0,0,0,0,116,35,35,0,0,0,0,0,0,35,35,35,35,35,6,0,0,0,0,0,0,0,0,0,0,0,0,0,0,0,0,35,0,0,0
0,0,0,0,0,145,116,35,35,0,0,0,0,0,0,35,35,35,35,35,6,0,0,0,0,0,0,0,0,0,0,0,0,0,0,0,0,35,0,0,0
0,0,0,0,0,0,116,35,35,0,0,0,0,0,0,35,35,35,35,35,6,132,0,0,0,0,0,0,0,0,0,0,0,0,0,0,130,35,0,0,0
0,0,0,0,0,0,116,35,35,0,0,0,0,0,0,35,35,35,35,35,6,0,0,0,0,0,0,131,0,0,0,0,0,0,0,0,0,35,0,0,0
0,0,0,0,0,0,116,35,35,0,0,0,0,0,0,35,35,35,35,35,5,21,21,21,21,21,21,21,35,35,35,35,35,35,35,35,35,35,0,0,0
0,0,0,0,0,0,5,35,35,35,35,35,35,35,35,35,35,35,35,35,5,0,0,0,0,0,0,0,37,35,35,35,35,132,0,0,0,35,0,0,0
0,0,0,0,0,0,5,35,35,35,35,35,35,35,35,35,35,35,35,35,5,0,0,0,0,0,0,0,37,35,35,35,35,0,0,0,0,93,0,0,0
0,0,0,0,0,0,5,5,5,5,5,5,5,5,5,5,5,5,5,5,5,0,0,0,0,0,0,0,37,35,35,35,35,35,35,0,35,35,0,0,0
0,0,0,0,0,0,0,48,6,15,0,0,0,0,0,0,0,0,0,0,0,0,0,0,0,0,0,0,37,35,35,35,35,35,35,17,35,35,0,0,0
0,0,0,0,0,0,0,6,0,6,0,0,0,0,0,0,0,0,0,0,0,0,0,0,0,0,0,0,37,35,35,35,35,35,35,35,35,35,0,0,0
0,0,0,0,0,0,0,48,6,15,0,0,0,0,0,0,0,0,0,0,0,0,0,0,0,0,0,0,37,35,35,35,35,35,35,35,35,35,0,0,0
0,0,0,0,0,0,0,37,35,41,0,0,0,0,0,0,0,0,0,0,0,0,0,0,0,0,0,0,37,35,35,35,35,35,35,35,35,35,0,0,0
0,0,0,0,0,0,0,37,35,41,0,0,0,0,0,0,0,0,0,0,0,0,0,0,0,0,0,0,37,35,35,35,21,21,21,21,21,21,21,0,0
0,0,0,0,0,0,0,37,35,41,0,0,0,0,0,0,0,0,0,0,0,0,0,0,0,0,0,0,37,35,35,41,0,0,0,0,0,0,0,0,0
0,0,0,0,0,0,0,37,35,41,0,0,0,0,0,0,0,0,0,0,0,0,0,0,0,0,0,0,37,35,35,41,0,0,0,0,0,0,0,0,0
0,0,0,0,0,0,0,37,35,41,0,0,0,0,0,0,0,0,0,0,0,0,0,0,0,0,37,0,37,35,35,41,0,41,0,0,0,0,0,0,0
0,0,0,0,0,0,0,37,35,41,0,0,0,0,0,0,0,0,0,0,0,0,0,0,0,0,37,6,6,6,6,6,6,41,0,0,0,0,0,0,0
0,0,0,0,0,0,0,37,35,41,0,0,0,0,0,0,0,0,0,0,0,0,0,0,0,0,37,6,6,6,6,6,6,41,0,0,0,0,0,0,0
0,0,0,0,0,0,0,37,35,41,0,0,0,0,0,0,0,0,0,0,0,0,0,0,0,0,37,6,6,6,6,6,6,41,0,0,0,0,0,0,0
0,0,0,0,0,0,0,37,35,41,0,0,0,0,179,27,27,27,27,27,179,0,0,0,0,0,37,6,6,6,6,6,6,41,0,0,0,0,0,0,0
0,0,0,0,0,179,27,35,35,35,27,27,27,27,27,6,6,6,6,6,15,0,0,0,0,0,37,6,6,6,6,6,6,41,0,0,0,0,0,0,0
0,0,0,0,0,48,5,6,6,6,6,6,6,5,6,6,0,0,0,6,15,0,0,0,0,0,37,6,6,6,6,6,6,41,0,0,0,0,0,0,0
0,0,0,0,0,48,6,35,41,0,0,0,0,166,6,0,0,0,0,6,15,0,0,0,0,0,37,6,6,6,6,6,6,41,0,0,0,0,0,0,0
0,0,0,0,0,48,6,166,165,165,165,165,165,166,6,6,178,0,0,6,15,0,0,0,0,0,37,6,6,6,6,6,6,41,0,0,0,0,0,0,0
0,0,0,0,0,48,6,166,0,0,166,0,0,166,6,6,6,6,6,6,15,0,0,0,0,0,37,6,6,6,6,6,6,41,0,0,0,0,0,0,0
0,0,0,0,0,48,6,166,0,0,166,0,0,166,6,6,6,6,6,6,15,0,0,0,0,0,37,0,0,0,0,0,0,41,0,0,0,0,0,0,0
0,0,0,0,0,48,6,166,132,130,166,132,0,166,6,6,6,6,6,6,15,0,0,0,0,0,0,0,0,0,0,0,0,0,0,0,0,0,0,0,0
0,0,0,0,0,48,6,166,0,0,166,0,0,166,6,6,6,6,6,6,15,0,0,0,0,0,0,0,0,0,0,0,0,0,0,0,0,0,0,0,0
0,0,0,0,0,48,6,166,0,130,166,132,0,166,6,6,6,6,6,6,15,0,0,0,0,0,0,0,0,0,0,0,0,0,0,0,0,0,0,0,0
0,0,0,0,0,48,6,166,132,0,166,0,35,166,6,6,6,6,6,6,15,0,0,0,0,0,0,37,0,0,0,0,0,0,41,0,0,0,0,0,0
0,0,0,0,0,48,6,166,0,0,166,0,12,166,6,6,6,6,6,6,15,0,0,0,0,0,0,37,6,6,92,92,6,6,41,0,0,0,0,0,0
0,0,0,0,0,48,6,166,0,0,166,0,12,166,6,6,6,6,6,6,15,0,0,0,0,0,0,37,90,0,0,0,0,0,41,0,0,0,0,0,0
0,0,0,0,0,6,5,6,6,6,6,6,6,6,6,6,6,6,6,5,5,0,0,0,0,0,0,37,0,0,0,0,0,0,41,0,0,0,0,0,0
0,0,0,0,0,48,6,0,0,0,0,0,23,0,0,0,0,0,0,37,6,0,0,0,0,0,0,6,0,0,0,0,0,0,41,0,0,0,0,0,0
0,0,0,0,0,48,6,0,177,0,0,0,6,12,12,12,0,0,0,37,6,0,0,0,0,0,0,6,0,0,0,0,0,0,41,0,0,0,0,0,0
0,0,0,0,0,48,6,0,0,104,104,0,6,0,0,12,0,0,0,0,6,0,0,0,0,0,0,37,0,0,0,0,0,0,41,0,0,0,0,0,0
0,0,0,0,0,48,6,176,94,103,103,94,6,132,0,0,0,0,0,175,6,0,0,0,0,0,0,37,131,0,0,0,0,0,41,0,0,0,0,0,0
0,0,0,0,0,35,6,6,6,6,6,6,6,35,35,35,35,35,35,35,5,0,0,0,0,0,0,37,6,6,92,92,6,6,41,0,0,0,0,0,0
0,0,0,0,0,21,21,21,21,21,21,21,21,21,21,21,21,21,21,21,21,21,0,0,0,0,0,37,0,0,0,0,0,0,41,0,0,0,0,0,0
0,0,0,0,0,0,0,0,0,0,0,0,0,0,0,0,0,0,0,0,0,0,0,0,0,0,0,0,0,0,0,0,0,0,0,0,0,0,0,0,0
0,0,0,0,0,0,0,0,0,0,0,0,0,0,0,0,0,0,0,0,0,0,0,0,0,0,0,0,0,0,0,0,0,0,0,0,0,0,0,0,0
0,0,0,0,0,0,0,0,0,0,0,0,0,0,0,0,0,0,0,0,0,0,0,0,0,0,0,0,0,0,0,0,0,0,0,0,0,0,0,0,0
0,0,0,0,0,0,0,0,0,0,0,0,0,0,0,0,0,0,0,0,0,0,0,0,0,0,0,0,0,0,0,0,0,0,0,0,0,0,0,0,0
:endlayer
layer: 9
0,0,0,0,0,0,0,0,0,0,0,0,0,0,0,0,0,0,0,0,0,0,0,0,0,0,0,0,0,0,0,0,0,0,0,0,0,0,0,0,0
0,0,0,0,0,0,0,0,0,0,0,0,0,0,0,0,0,0,0,0,0,0,0,0,0,0,0,0,0,0,0,0,0,0,0,0,0,0,0,0,0
0,0,0,0,0,0,0,0,0,0,0,0,0,0,0,0,0,0,0,0,0,0,0,0,0,0,0,0,0,0,0,0,0,0,0,0,0,0,0,0,0
0,0,0,0,0,0,35,35,35,35,35,35,35,35,35,35,35,35,35,35,35,0,0,0,0,0,0,0,0,0,0,0,0,0,0,0,0,0,0,0,0
0,0,0,0,0,0,35,0,0,0,0,85,0,0,0,0,0,84,84,84,35,35,35,35,35,35,35,35,35,35,35,35,35,35,35,35,35,35,35,0,0
0,0,0,0,0,0,35,0,12,12,12,12,12,12,12,12,0,0,0,0,0,0,0,0,0,0,0,0,0,0,0,0,0,0,0,0,0,35,0,0,0
0,0,0,0,0,0,35,0,12,0,0,0,0,0,0,12,0,0,0,184,35,132,0,0,0,0,0,0,0,0,0,0,0,0,0,0,0,93,0,0,0
0,0,0,0,0,0,35,0,12,0,0,0,0,0,0,12,0,84,84,0,35,0,0,0,0,0,0,0,0,0,0,0,0,0,0,0,0,35,0,0,0
0,0,0,0,0,0,35,0,12,0,0,0,0,0,0,12,0,84,80,0,35,0,0,0,0,0,0,0,0,0,0,0,0,0,0,0,0,35,0,0,0
0,0,0,0,0,0,0,0,0,0,0,0,0,0,0,0,0,0,0,0,35,0,0,0,0,0,0,0,0,0,0,0,0,0,0,0,0,93,0,0,0
0,0,0,0,0,0,35,0,12,0,0,0,0,0,0,12,0,0,80,79,35,0,0,0,0,0,0,0,0,0,0,0,0,0,0,0,0,35,0,0,0
0,0,0,0,0,0,35,0,12,0,0,0,0,0,0,12,79,0,0,79,35,35,35,35,35,35,35,35,35,35,35,35,35,35,35,35,35,35,35,0,0
0,0,0,0,0,0,35,0,12,0,0,0,0,0,0,12,84,0,0,84,35,0,0,0,0,0,0,0,0,35,35,35,35,35,35,35,35,35,183,0,0
0,0,0,0,0,0,35,0,12,12,12,12,12,12,12,12,0,0,182,0,35,0,0,0,0,0,0,0,0,5,0,0,12,0,0,0,0,5,158,0,0
0,0,0,0,0,0,35,0,0,0,0,0,0,0,0,0,0,0,0,0,35,132,0,0,0,0,0,0,0,35,0,0,12,0,0,0,130,35,158,0,0
0,0,0,0,0,0,35,35,35,35,35,35,35,35,35,35,35,35,35,35,35,0,0,0,0,0,0,0,0,35,0,181,12,12,12,0,12,35,158,0,0
0,0,0,0,0,0,0,0,6,0,0,0,0,0,0,0,0,0,0,0,0,0,0,0,0,0,0,0,0,35,0,0,0,0,0,0,0,35,158,0,0
0,0,0,0,0,0,0,6,0,6,0,0,0,0,0,0,0,0,0,0,0,0,0,0,0,0,0,0,0,35,161,160,0,0,0,0,0,35,158,0,0
0,0,0,0,0,0,0,0,6,0,0,0,0,0,0,0,0,0,0,0,0,0,0,0,0,0,0,0,0,35,161,160,0,0,0,0,180,35,158,0,0
0,0,0,0,0,0,0,0,0,0,0,0,0,0,0,0,0,0,0,0,0,0,0,0,0,0,0,0,0,5,35,35,35,35,35,35,35,5,158,0,0
0,0,0,0,0,0,0,0,0,0,0,0,0,0,0,0,0,0,0,0,0,0,0,0,0,0,0,0,0,37,41,0,0,0,0,0,0,0,0,0,0
0,0,0,0,0,0,0,0,0,0,0,0,0,0,0,0,0,0,0,0,0,0,0,0,0,0,0,0,0,37,41,0,0,0,0,0,0,0,0,0,0
0,0,0,0,0,0,0,0,0,0,0,0,0,0,0,0,0,0,0,0,0,0,0,0,0,0,0,0,0,37,41,0,0,0,0,0,0,0,0,0,0
0,0,0,0,0,0,0,0,0,0,0,0,0,0,0,0,0,0,0,0,0,0,0,0,0,0,0,37,0,37,41,0,41,0,0,0,0,0,0,0,0
0,0,0,0,0,0,0,0,0,0,0,0,0,0,0,0,0,0,0,0,0,0,0,0,0,0,0,37,6,6,6,6,41,0,0,0,0,0,0,0,0
0,0,0,0,0,0,0,0,0,0,0,0,0,0,0,0,0,0,0,0,0,0,0,0,0,0,0,37,6,6,6,6,41,0,0,0,0,0,0,0,0
0,0,0,0,0,0,0,0,0,0,0,0,0,0,0,0,0,0,0,0,0,0,0,0,0,0,0,37,6,6,6,6,41,0,0,0,0,0,0,0,0
0,0,0,0,0,0,0,0,87,0,0,0,0,0,0,0,0,0,0,0,0,0,0,0,0,0,0,37,6,6,6,6,41,0,0,0,0,0,0,0,0
0,0,0,0,0,0,0,0,0,0,0,0,0,0,0,5,6,93,6,5,0,0,0,0,0,0,0,37,6,6,6,6,41,0,0,0,0,0,0,0,0
0,0,0,0,0,0,5,6,6,6,6,6,6,5,6,6,0,0,0,6,0,0,0,0,0,0,0,37,6,6,6,6,41,0,0,0,0,0,0,0,0
0,0,0,0,0,0,6,0,0,0,0,6,41,0,0,0,0,0,0,93,0,0,0,0,0,0,0,37,6,6,6,6,41,0,0,0,0,0,0,0,0
0,0,0,0,0,0,6,17,35,35,35,6,35,6,6,6,178,0,0,6,0,0,0,0,0,0,0,37,6,6,6,6,41,0,0,0,0,0,0,0,0
0,0,0,0,0,0,6,35,35,35,35,35,35,35,35,35,6,6,6,6,0,0,0,0,0,0,0,37,6,6,6,6,41,0,0,0,0,0,0,0,0
0,0,0,0,0,0,6,35,35,35,35,35,35,35,35,35,35,35,35,6,0,0,0,0,0,0,0,37,0,0,0,0,41,0,0,0,0,0,0,0,0
0,0,0,0,0,0,6,35,35,35,35,35,35,35,35,35,35,35,35,6,0,0,0,0,0,0,0,0,0,0,0,0,0,0,0,0,0,0,0,0,0
0,0,0,0,0,0,6,35,35,35,35,35,35,35,35,35,35,35,35,6,0,0,0,0,0,0,0,0,0,0,0,0,0,0,0,0,0,0,0,0,0
0,0,0,0,0,0,6,35,35,35,35,35,35,35,35,35,35,35,35,6,0,0,0,0,0,0,0,0,0,0,0,0,0,0,0,0,0,0,0,0,0
0,0,0,0,0,0,6,35,35,35,35,35,35,35,35,35,35,35,35,6,0,0,0,0,0,0,0,0,37,0,0,0,0,41,0,0,0,0,0,0,0
0,0,0,0,0,0,6,35,35,35,35,35,35,35,35,35,35,35,35,6,0,0,0,0,0,0,0,0,37,6,6,6,6,41,0,0,0,0,0,0,0
0,0,0,0,0,0,6,35,35,35,35,35,35,35,35,35,35,35,35,6,0,0,0,0,0,0,0,0,37,0,0,0,90,41,0,0,0,0,0,0,0
0,0,0,0,0,17,5,6,6,6,6,6,6,6,6,6,6,6,6,5,17,17,0,0,0,0,0,0,37,0,0,0,0,41,0,0,0,0,0,0,0
0,0,0,0,0,0,6,132,0,0,0,0,101,0,0,0,0,0,0,0,6,0,0,0,0,0,0,6,37,0,0,0,0,41,0,0,0,0,0,0,0
0,0,0,0,0,0,93,0,0,0,0,0,6,0,0,0,0,0,0,0,93,0,0,0,0,0,0,6,37,0,0,0,0,41,0,0,0,0,0,0,0
0,0,0,0,0,0,93,0,0,0,0,0,6,0,0,0,0,0,0,0,93,0,0,0,0,0,0,0,37,0,0,0,0,41,0,0,0,0,0,0,0
0,0,0,0,0,0,6,0,87,0,0,87,6,0,0,0,0,0,0,0,6,0,0,0,0,0,0,0,37,0,0,0,0,41,0,0,0,0,0,0,0
0,0,0,0,0,21,21,21,21,21,21,21,21,21,21,21,21,21,21,21,21,21,0,0,0,0,0,0,37,6,6,6,6,41,0,0,0,0,0,0,0
0,0,0,0,0,0,0,0,0,0,0,0,0,0,0,0,0,0,0,0,0,0,0,0,0,0,0,0,37,0,90,90,0,41,0,0,0,0,0,0,0
0,0,0,0,0,0,0,0,0,0,0,0,0,0,0,0,0,0,0,0,0,0,0,0,0,0,0,0,0,0,0,0,0,0,0,0,0,0,0,0,0
0,0,0,0,0,0,0,0,0,0,0,0,0,0,0,0,0,0,0,0,0,0,0,0,0,0,0,0,0,0,0,0,0,0,0,0,0,0,0,0,0
0,0,0,0,0,0,0,0,0,0,0,0,0,0,0,0,0,0,0,0,0,0,0,0,0,0,0,0,0,0,0,0,0,0,0,0,0,0,0,0,0
0,0,0,0,0,0,0,0,0,0,0,0,0,0,0,0,0,0,0,0,0,0,0,0,0,0,0,0,0,0,0,0,0,0,0,0,0,0,0,0,0
:endlayer
layer: 10
0,0,0,0,0,0,0,0,0,0,0,0,0,0,0,0,0,0,0,0,0,0,0,0,0,0,0,0,0,0,0,0,0,0,0,0,0,0,0,0,0
0,0,0,0,0,0,0,0,0,0,0,0,0,0,0,0,0,0,0,0,0,0,0,0,0,0,0,0,0,0,0,0,0,0,0,0,0,0,0,0,0
0,0,0,0,0,17,17,17,17,17,17,17,17,17,17,17,17,17,17,17,17,0,0,0,0,0,0,0,0,0,0,0,0,0,0,0,0,0,0,0,0
0,0,0,0,0,0,35,35,35,35,35,35,35,35,35,35,35,35,35,35,35,0,0,0,0,0,0,0,0,0,0,0,0,0,0,0,0,0,0,0,0
0,0,0,0,0,0,35,0,0,0,0,85,0,0,0,0,0,0,84,84,35,17,17,17,17,17,17,17,17,17,17,17,17,17,17,17,17,17,17,0,0
0,0,0,0,0,0,35,0,0,0,0,0,0,0,0,0,0,0,0,0,0,0,0,0,0,0,0,0,0,0,0,0,0,0,0,0,0,35,0,0,0
0,0,0,0,0,0,35,0,0,0,0,0,0,0,0,0,0,0,0,0,35,0,0,0,0,0,0,0,0,0,0,0,0,0,0,0,0,35,0,0,0
0,0,0,0,0,0,35,0,0,0,0,0,0,0,0,0,0,84,84,0,35,0,0,0,0,0,0,0,0,0,0,0,0,0,0,0,0,35,0,0,0
0,0,0,0,0,0,35,0,0,0,0,0,0,0,0,0,0,84,84,0,35,0,0,0,0,0,0,0,0,0,0,0,0,0,0,0,0,35,0,0,0
0,0,0,0,0,0,0,0,0,0,0,0,0,0,0,0,0,0,0,0,35,0,0,0,0,0,0,0,0,0,0,0,0,0,0,0,0,35,0,0,0
0,0,0,0,0,0,35,0,0,0,0,0,0,0,0,0,0,0,84,79,35,0,0,0,0,0,0,0,0,0,0,0,0,0,0,0,0,35,0,0,0
0,0,0,0,0,0,35,0,0,0,0,0,0,0,0,0,84,0,0,79,35,21,21,21,21,21,21,21,21,21,21,21,21,21,21,21,21,21,21,0,0
0,0,0,0,0,0,35,0,0,0,0,0,0,0,0,0,84,0,0,84,35,0,0,0,0,0,0,0,0,35,35,35,35,35,35,35,35,35,0,0,0
0,0,0,0,0,0,35,0,0,0,0,0,0,0,0,0,0,0,0,0,35,0,0,0,0,0,0,0,0,5,0,0,0,0,0,0,0,5,0,0,0
0,0,0,0,0,0,35,0,0,0,0,0,0,0,0,0,0,0,0,0,35,0,0,0,0,0,0,0,0,35,0,0,0,0,0,0,0,35,0,0,0
0,0,0,0,0,0,35,35,35,35,35,35,35,35,35,35,35,35,35,35,35,0,0,0,0,0,0,0,0,93,0,0,0,0,0,0,0,35,0,0,0
0,0,0,0,0,21,21,21,6,21,21,21,21,21,21,21,21,21,21,21,21,21,0,0,0,0,0,0,130,35,0,0,0,0,0,0,0,35,0,0,0
0,0,0,0,0,0,0,6,0,6,0,0,0,0,0,0,0,0,0,0,0,0,0,0,0,0,0,0,0,93,0,0,0,0,0,0,0,93,0,0,0
0,0,0,0,0,0,0,0,6,0,0,0,0,0,0,0,0,0,0,0,0,0,0,0,0,0,0,0,0,35,0,0,0,0,0,0,0,35,0,0,0
0,0,0,0,0,0,0,0,0,0,0,0,0,0,0,0,0,0,0,0,0,0,0,0,0,0,0,0,0,5,35,93,35,35,93,35,35,5,0,0,0
0,0,0,0,0,0,0,0,0,0,0,0,0,0,0,0,0,0,0,0,0,0,0,0,0,0,0,0,0,0,0,0,0,0,0,0,0,0,0,0,0
0,0,0,0,0,0,0,0,0,0,0,0,0,0,0,0,0,0,0,0,0,0,0,0,0,0,0,0,0,0,0,0,0,0,0,0,0,0,0,0,0
0,0,0,0,0,0,0,0,0,0,0,0,0,0,0,0,0,0,0,0,0,0,0,0,0,0,0,0,0,0,0,0,0,0,0,0,0,0,0,0,0
0,0,0,0,0,0,0,0,0,0,0,0,0,0,0,0,0,0,0,0,0,0,0,0,0,0,0,0,37,131,0,41,0,0,0,0,0,0,0,0,0
0,0,0,0,0,0,0,0,0,0,0,0,0,0,0,0,0,0,0,0,0,0,0,0,0,0,0,0,37,6,6,41,0,0,0,0,0,0,0,0,0
0,0,0,0,0,0,0,0,0,0,0,0,0,0,0,0,0,0,0,0,0,0,0,0,0,0,0,0,37,6,6,41,0,0,0,0,0,0,0,0,0
0,0,0,0,0,0,0,0,0,0,0,0,0,0,0,0,0,0,0,0,0,0,0,0,0,0,0,0,37,6,6,41,0,0,0,0,0,0,0,0,0
0,0,0,0,0,0,0,0,0,0,0,0,0,0,0,0,0,0,0,0,0,0,0,0,0,0,0,0,37,6,6,41,0,0,0,0,0,0,0,0,0
0,0,0,0,0,0,0,0,0,0,0,0,0,0,0,5,6,93,6,5,0,0,0,0,0,0,0,0,37,6,6,41,0,0,0,0,0,0,0,0,0
0,0,0,0,0,0,5,6,6,6,6,6,6,5,0,6,0,0,0,6,0,0,0,0,0,0,0,0,37,6,6,41,0,0,0,0,0,0,0,0,0
0,0,0,0,0,0,6,0,0,0,0,6,0,0,0,0,0,0,0,93,0,0,0,0,0,0,0,0,37,6,6,41,0,0,0,0,0,0,0,0,0
0,0,0,0,0,0,6,0,12,12,12,6,32,6,6,6,178,0,0,6,0,0,0,0,0,0,0,0,37,6,6,41,0,0,0,0,0,0,0,0,0
0,0,0,0,0,0,6,0,0,0,0,0,0,0,0,35,6,6,6,6,0,0,0,0,0,0,0,0,37,6,6,41,0,0,0,0,0,0,0,0,0
0,0,0,0,0,0,6,0,0,0,0,0,0,0,0,35,0,189,188,6,0,0,0,0,0,0,0,0,37,0,0,41,0,0,0,0,0,0,0,0,0
0,0,0,0,0,0,6,0,0,0,0,0,0,0,0,23,0,0,0,6,0,0,0,0,0,0,0,0,0,0,0,0,0,0,0,0,0,0,0,0,0
0,0,0,0,0,0,6,35,32,35,32,35,35,35,0,35,0,0,191,6,0,0,0,0,0,0,0,0,0,0,0,0,0,0,0,0,0,0,0,0,0
0,0,0,0,0,0,6,0,0,35,0,0,190,35,0,35,35,35,35,6,0,0,0,0,0,0,0,0,0,0,0,0,0,0,0,0,0,0,0,0,0
0,0,0,0,0,0,6,0,0,35,0,189,188,35,0,35,0,189,188,6,0,0,0,0,0,0,0,0,0,185,37,41,185,0,0,0,0,0,0,0,0
0,0,0,0,0,0,6,104,0,35,0,189,188,35,0,23,0,0,0,6,0,0,0,0,0,0,0,0,0,185,37,41,185,0,0,0,0,0,0,0,0
0,0,0,0,0,0,6,103,187,35,0,0,0,35,0,35,0,0,186,6,0,0,0,0,0,0,0,0,0,185,37,41,185,0,0,0,0,0,0,0,0
0,0,0,0,0,0,5,6,6,6,6,6,6,6,6,6,6,6,6,5,0,0,0,0,0,0,0,0,0,185,37,41,185,0,0,0,0,0,0,0,0
0,0,0,0,0,17,35,0,0,0,0,0,35,0,0,0,0,0,0,0,35,17,0,0,0,0,0,6,132,185,37,41,185,0,0,0,0,0,0,0,0
0,0,0,0,0,0,6,0,0,0,0,0,6,0,0,0,0,0,0,130,6,0,0,0,0,0,0,6,132,185,37,41,185,0,0,0,0,0,0,0,0
0,0,0,0,0,0,6,0,0,0,0,0,6,132,0,0,0,0,0,0,6,0,0,0,0,0,0,0,0,185,37,41,185,0,0,0,0,0,0,0,0
0,0,0,0,0,21,21,21,21,21,21,21,21,21,21,21,21,21,21,21,21,21,0,0,0,0,0,0,0,185,37,41,185,0,0,0,0,0,0,0,0
0,0,0,0,0,0,0,0,0,0,0,0,0,0,0,0,0,0,0,0,0,0,0,0,0,0,0,0,0,185,37,41,185,0,0,0,0,0,0,0,0
0,0,0,0,0,0,0,0,0,0,0,0,0,0,0,0,0,0,0,0,0,0,0,0,0,0,0,0,0,185,37,41,185,0,0,0,0,0,0,0,0
0,0,0,0,0,0,0,0,0,0,0,0,0,0,0,0,0,0,0,0,0,0,0,0,0,0,0,0,0,0,0,0,0,0,0,0,0,0,0,0,0
0,0,0,0,0,0,0,0,0,0,0,0,0,0,0,0,0,0,0,0,0,0,0,0,0,0,0,0,0,0,0,0,0,0,0,0,0,0,0,0,0
0,0,0,0,0,0,0,0,0,0,0,0,0,0,0,0,0,0,0,0,0,0,0,0,0,0,0,0,0,0,0,0,0,0,0,0,0,0,0,0,0
0,0,0,0,0,0,0,0,0,0,0,0,0,0,0,0,0,0,0,0,0,0,0,0,0,0,0,0,0,0,0,0,0,0,0,0,0,0,0,0,0
:endlayer
layer: 11
0,0,0,0,0,0,0,0,0,0,0,0,0,0,0,0,0,0,0,0,0,0,0,0,0,0,0,0,0,0,0,0,0,0,0,0,0,0,0,0,0
0,0,0,0,0,0,0,0,0,0,0,0,0,0,0,0,0,0,0,0,0,0,0,0,0,0,0,0,0,0,0,0,0,0,0,0,0,0,0,0,0
0,0,0,0,0,0,0,0,0,0,0,0,0,0,0,0,0,0,0,0,0,0,0,0,0,0,0,0,0,0,0,0,0,0,0,0,0,0,0,0,0
0,0,0,0,0,17,17,17,17,17,17,17,17,17,17,17,17,17,17,17,17,0,0,0,0,0,0,0,0,0,0,0,0,0,0,0,0,0,0,0,0
0,0,0,0,0,0,35,0,0,0,0,90,0,0,0,0,0,0,84,0,35,0,0,0,0,0,0,0,0,0,0,0,0,0,0,0,0,0,0,0,0
0,0,0,0,0,0,35,0,0,0,0,0,0,0,0,0,0,0,0,130,35,35,35,35,35,35,35,35,35,35,35,35,35,35,35,35,35,35,35,0,0
0,0,0,0,0,0,35,0,0,0,0,0,0,0,0,0,0,0,0,0,35,0,0,0,0,0,0,0,0,0,0,0,0,0,0,0,0,35,0,0,0
0,0,0,0,0,0,35,0,0,0,0,0,0,0,0,0,0,0,0,0,35,0,0,0,0,0,0,0,0,0,0,0,0,0,0,0,0,35,0,0,0
0,0,0,0,0,0,35,132,0,0,0,0,0,0,0,0,0,0,0,0,35,0,0,0,0,0,0,0,0,0,0,0,0,0,0,0,0,35,0,0,0
0,0,0,0,0,12,35,0,0,0,0,0,0,0,0,0,0,0,0,0,35,0,0,0,0,0,0,0,0,0,0,0,0,0,0,0,0,35,0,0,0
0,0,0,0,0,0,35,132,0,0,0,0,0,0,0,0,0,0,0,80,35,35,35,35,35,35,35,35,35,35,35,35,35,35,35,35,35,35,35,0,0
0,0,0,0,0,0,35,0,0,0,0,0,0,0,0,0,0,0,0,80,35,35,0,0,0,0,0,0,0,0,0,0,0,0,0,0,0,0,0,0,0
0,0,0,0,0,0,35,0,0,0,0,0,0,0,0,0,0,0,0,80,35,35,0,0,0,0,0,0,17,17,17,17,17,17,17,17,17,17,0,0,0
0,0,0,0,0,0,35,0,0,0,0,0,0,0,0,0,0,0,0,130,35,35,0,0,0,0,0,0,0,5,35,35,35,35,35,35,35,5,0,0,0
0,0,0,0,0,0,35,0,0,0,0,131,0,0,0,0,0,0,0,0,35,35,0,0,0,0,0,0,0,5,0,0,90,0,0,0,0,5,0,0,0
0,0,0,0,0,21,21,21,21,21,21,21,21,21,21,21,21,21,21,21,21,21,0,0,0,0,0,0,0,5,0,0,0,0,0,0,0,5,0,0,0
0,0,0,0,0,0,0,0,6,0,0,0,0,0,0,0,0,0,0,0,0,0,0,0,0,0,0,0,0,5,0,0,0,0,0,0,0,5,0,0,0
0,0,0,0,0,0,130,6,0,6,132,0,0,0,0,0,0,0,0,0,0,0,0,0,0,0,0,0,0,5,0,0,0,0,0,0,130,5,0,0,0
0,0,0,0,0,0,0,0,6,0,0,0,0,0,0,0,0,0,0,0,0,0,0,0,0,0,0,0,0,5,132,0,0,0,0,0,0,5,0,0,0
0,0,0,0,0,0,0,0,90,0,0,0,0,0,0,0,0,0,0,0,0,0,0,0,0,0,0,0,0,5,35,35,35,35,35,35,35,5,0,0,0
0,0,0,0,0,0,0,0,0,0,0,0,0,0,0,0,0,0,0,0,0,0,0,0,0,0,0,0,21,21,21,21,21,21,21,21,21,21,21,0,0
0,0,0,0,0,0,0,0,0,0,0,0,0,0,0,0,0,0,0,0,0,0,0,0,0,0,0,0,0,0,0,0,0,0,0,0,0,0,0,0,0
0,0,0,0,0,0,0,0,0,0,0,0,0,0,0,0,0,0,0,0,0,0,0,0,0,0,0,0,0,0,0,0,0,0,0,0,0,0,0,0,0
0,0,0,0,0,0,0,0,0,0,0,0,0,0,0,0,0,0,0,0,0,0,0,0,0,0,0,0,0,37,41,0,0,0,0,0,0,0,0,0,0
0,0,0,0,0,0,0,0,0,0,0,0,0,0,0,0,0,0,0,0,0,0,0,0,0,0,0,0,0,37,41,0,0,0,0,0,0,0,0,0,0
0,0,0,0,0,0,0,0,0,0,0,0,0,0,0,0,0,0,0,0,0,0,0,0,0,0,0,0,0,37,41,0,0,0,0,0,0,0,0,0,0
0,0,0,0,0,0,0,0,0,0,0,0,0,0,0,0,0,0,0,0,0,0,0,0,0,0,0,0,0,37,41,0,0,0,0,0,0,0,0,0,0
0,0,0,0,0,0,0,0,0,0,0,0,0,0,0,0,0,0,0,0,0,0,0,0,0,0,0,0,0,37,41,0,0,0,0,0,0,0,0,0,0
0,0,0,0,0,0,0,0,0,0,0,0,0,0,0,5,6,6,6,5,0,0,0,0,0,0,0,0,0,37,41,0,0,0,0,0,0,0,0,0,0
0,0,0,0,0,0,5,6,93,93,6,6,6,5,0,6,0,90,0,6,0,0,0,0,0,0,0,0,0,37,41,0,0,0,0,0,0,0,0,0,0
0,0,0,0,0,0,6,0,0,0,0,6,0,0,130,6,0,0,0,6,0,0,0,0,0,0,0,0,0,37,41,0,0,0,0,0,0,0,0,0,0
0,0,0,0,0,0,6,0,0,0,0,6,101,6,6,6,178,0,0,6,0,0,0,0,0,0,0,0,0,37,41,0,0,0,0,0,0,0,0,0,0
0,0,0,0,0,0,93,0,0,0,0,0,0,0,0,35,6,6,6,6,0,0,0,0,0,0,0,0,0,37,41,0,0,0,0,0,0,0,0,0,0
0,0,0,0,0,0,6,0,0,0,0,0,0,0,0,35,0,90,0,6,0,0,0,0,0,0,0,0,0,37,41,0,0,0,0,0,0,0,0,0,0
0,0,0,0,0,0,93,0,0,0,0,0,0,0,0,101,0,0,0,93,0,0,0,0,0,0,0,0,0,0,0,0,0,0,0,0,0,0,0,0,0
0,0,0,0,0,0,6,35,101,35,101,35,35,35,0,35,0,0,0,6,0,0,0,0,0,0,0,0,0,0,0,0,0,0,0,0,0,0,0,0,0
0,0,0,0,0,0,93,0,0,35,0,0,0,35,0,35,35,35,35,6,0,0,0,0,0,0,0,0,0,0,0,0,0,0,0,0,0,0,0,0,0
0,0,0,0,0,0,6,0,0,35,0,0,0,35,0,35,0,0,0,6,0,0,0,0,0,0,0,0,0,0,0,0,0,0,0,0,0,0,0,0,0
0,0,0,0,0,0,93,0,0,35,0,0,0,35,0,101,0,0,0,93,0,0,0,0,0,0,0,0,0,0,0,0,0,0,0,0,0,0,0,0,0
0,0,0,0,0,0,6,0,0,35,0,0,0,35,0,35,0,0,0,6,0,0,0,0,0,0,0,0,0,0,0,0,0,0,0,0,0,0,0,0,0
0,0,0,0,0,0,5,6,6,6,93,6,93,6,6,6,6,93,6,5,0,0,0,0,0,0,0,0,0,0,0,0,0,0,0,0,0,0,0,0,0
0,0,0,0,0,0,0,158,158,158,158,158,158,158,158,158,158,158,158,158,0,0,0,0,0,0,0,6,0,0,0,0,0,0,0,0,0,0,0,0,0
0,0,0,0,0,17,17,17,17,17,17,17,17,17,17,17,17,17,17,17,17,17,0,0,0,0,0,6,0,0,0,0,0,0,0,0,0,0,0,0,0
0,0,0,0,0,21,21,21,21,21,21,21,21,21,21,21,21,21,21,21,21,21,0,0,0,0,0,0,0,0,0,0,0,0,0,0,0,0,0,0,0
0,0,0,0,0,0,0,0,0,0,0,0,0,0,0,0,0,0,0,0,0,0,0,0,0,0,0,0,0,0,0,0,0,0,0,0,0,0,0,0,0
0,0,0,0,0,0,0,0,0,0,0,0,0,0,0,0,0,0,0,0,0,0,0,0,0,0,0,0,0,0,0,0,0,0,0,0,0,0,0,0,0
0,0,0,0,0,0,0,0,0,0,0,0,0,0,0,0,0,0,0,0,0,0,0,0,0,0,0,0,0,0,0,0,0,0,0,0,0,0,0,0,0
0,0,0,0,0,0,0,0,0,0,0,0,0,0,0,0,0,0,0,0,0,0,0,0,0,0,0,0,0,0,0,0,0,0,0,0,0,0,0,0,0
0,0,0,0,0,0,0,0,0,0,0,0,0,0,0,0,0,0,0,0,0,0,0,0,0,0,0,0,0,0,0,0,0,0,0,0,0,0,0,0,0
0,0,0,0,0,0,0,0,0,0,0,0,0,0,0,0,0,0,0,0,0,0,0,0,0,0,0,0,0,0,0,0,0,0,0,0,0,0,0,0,0
0,0,0,0,0,0,0,0,0,0,0,0,0,0,0,0,0,0,0,0,0,0,0,0,0,0,0,0,0,0,0,0,0,0,0,0,0,0,0,0,0
:endlayer
layer: 12
0,0,0,0,0,0,0,0,0,0,0,0,0,0,0,0,0,0,0,0,0,0,0,0,0,0,0,0,0,0,0,0,0,0,0,0,0,0,0,0,0
0,0,0,0,0,0,0,0,0,0,0,0,0,0,0,0,0,0,0,0,0,0,0,0,0,0,0,0,0,0,0,0,0,0,0,0,0,0,0,0,0
0,0,0,0,0,0,0,0,0,0,0,0,0,0,0,0,0,0,0,0,0,0,0,0,0,0,0,0,0,0,0,0,0,0,0,0,0,0,0,0,0
0,0,0,0,0,0,0,0,0,0,0,0,0,0,0,0,0,0,0,0,0,0,0,0,0,0,0,0,0,0,0,0,0,0,0,0,0,0,0,0,0
0,0,0,0,0,17,35,35,35,35,35,35,35,35,35,35,35,35,35,35,35,0,0,0,0,0,0,0,0,0,0,0,0,0,0,0,0,0,0,0,0
0,0,0,0,0,0,35,0,0,0,0,0,0,0,0,0,0,0,0,0,35,0,0,0,0,0,0,0,0,0,0,0,0,0,0,0,0,0,0,0,0
0,0,0,0,0,0,35,0,0,0,0,0,0,0,0,0,0,0,0,0,35,17,17,17,17,17,17,17,17,17,17,17,17,17,17,17,17,17,17,0,0
0,0,0,0,0,0,35,0,0,0,0,0,0,0,0,0,0,0,0,0,35,0,0,0,0,0,0,0,0,0,0,0,0,0,0,0,0,35,0,0,0
0,0,0,0,0,0,35,0,0,0,0,0,0,0,0,0,0,0,0,0,35,0,0,0,0,0,0,0,0,0,0,0,0,0,0,0,0,35,0,0,0
0,0,0,0,0,0,35,0,0,0,0,0,0,0,0,0,0,0,0,0,35,21,21,21,21,21,21,21,21,21,21,21,21,21,21,21,21,21,21,0,0
0,0,0,0,0,0,35,0,0,0,0,0,0,0,0,0,0,0,0,84,35,0,0,0,0,0,0,0,0,0,0,0,0,0,0,0,0,0,0,0,0
0,0,0,0,0,0,35,0,0,0,0,0,0,0,0,0,0,0,0,80,35,0,0,0,0,0,0,0,0,0,0,0,0,0,0,0,0,0,0,0,0
0,0,0,0,0,0,35,0,0,0,0,0,0,0,0,0,0,0,0,0,35,0,0,0,0,0,0,0,0,0,0,0,0,0,0,0,0,0,0,0,0
0,0,0,0,0,0,35,0,0,0,0,0,0,0,0,0,0,0,0,0,35,0,0,0,0,0,0,0,17,17,17,17,17,17,17,17,17,17,0,0,0
0,0,0,0,0,21,35,35,35,35,35,35,35,35,35,35,35,35,35,35,35,0,0,0,0,0,0,0,0,35,0,0,0,0,0,0,0,35,0,0,0
0,0,0,0,0,0,0,0,0,0,0,0,0,0,0,0,0,0,0,0,0,0,0,0,0,0,0,0,0,35,0,0,0,0,0,0,0,35,0,0,0
0,0,0,0,0,0,0,0,6,0,0,0,0,0,0,0,0,0,0,0,0,0,0,0,0,0,0,0,0,35,0,0,0,0,0,0,0,35,0,0,0
0,0,0,0,0,0,0,6,0,6,0,0,0,0,0,0,0,0,0,0,0,0,0,0,0,0,0,0,0,35,0,0,0,0,0,0,0,35,0,0,0
0,0,0,0,0,0,0,0,6,0,0,0,0,0,0,0,0,0,0,0,0,0,0,0,0,0,0,0,0,35,0,0,0,0,0,0,0,35,0,0,0
0,0,0,0,0,0,0,0,0,0,0,0,0,0,0,0,0,0,0,0,0,0,0,0,0,0,0,0,21,21,21,21,21,21,21,21,21,21,21,0,0
0,0,0,0,0,0,0,0,0,0,0,0,0,0,0,0,0,0,0,0,0,0,0,0,0,0,0,0,0,0,0,0,0,0,0,0,0,0,0,0,0
0,0,0,0,0,0,0,0,0,0,0,0,0,0,0,0,0,0,0,0,0,0,0,0,0,0,0,0,0,0,0,0,0,0,0,0,0,0,0,0,0
0,0,0,0,0,0,0,0,0,0,0,0,0,0,0,0,0,0,0,0,0,0,0,0,0,0,0,0,0,0,0,0,0,0,0,0,0,0,0,0,0
0,0,0,0,0,0,0,0,0,0,0,0,0,0,0,0,0,0,0,0,0,0,0,0,0,0,0,0,0,0,0,0,0,0,0,0,0,0,0,0,0
0,0,0,0,0,0,0,0,0,0,0,0,0,0,0,0,0,0,0,0,0,0,0,0,0,0,0,0,0,0,0,0,0,0,0,0,0,0,0,0,0
0,0,0,0,0,0,0,0,0,0,0,0,0,0,0,0,0,0,0,0,0,0,0,0,0,0,0,0,0,0,0,0,0,0,0,0,0,0,0,0,0
0,0,0,0,0,0,0,0,0,0,0,0,0,0,0,0,0,0,0,0,0,0,0,0,0,0,0,0,0,0,0,0,0,0,0,0,0,0,0,0,0
0,0,0,0,0,0,0,0,0,0,0,0,0,0,0,0,0,0,0,0,0,0,0,0,0,0,0,0,0,0,0,0,0,0,0,0,0,0,0,0,0
0,0,0,0,0,0,0,0,0,0,0,0,0,0,0,5,6,6,6,5,0,0,0,0,0,0,0,0,0,0,0,0,0,0,0,0,0,0,0,0,0
0,0,0,0,0,0,5,6,93,93,6,6,6,5,6,6,6,6,6,6,0,0,0,0,0,0,0,0,0,0,0,0,0,0,0,0,0,0,0,0,0
0,0,0,0,0,0,6,0,0,0,130,6,132,6,6,6,6,6,6,6,0,0,0,0,0,0,0,0,0,0,0,0,0,0,0,0,0,0,0,0,0
0,0,0,0,0,0,6,132,0,0,0,6,6,6,6,6,178,6,6,6,0,0,0,0,0,0,0,0,0,0,0,0,0,0,0,0,0,0,0,0,0
0,0,0,0,0,0,93,0,0,0,0,0,90,0,0,35,6,6,6,6,0,0,0,0,0,0,0,0,0,0,0,0,0,0,0,0,0,0,0,0,0
0,0,0,0,0,0,6,132,0,0,0,0,0,0,0,35,0,0,0,6,0,0,0,0,0,0,0,0,0,0,0,0,0,0,0,0,0,0,0,0,0
0,0,0,0,0,0,93,0,0,0,0,0,0,0,0,35,0,0,0,93,0,0,0,0,0,0,0,0,0,0,0,0,0,0,0,0,0,0,0,0,0
0,0,0,0,0,0,6,35,35,35,35,35,35,35,0,35,0,0,0,6,0,0,0,0,0,0,0,0,0,0,0,0,0,0,0,0,0,0,0,0,0
0,0,0,0,0,0,93,0,0,35,0,0,0,35,0,35,35,35,35,6,0,0,0,0,0,0,0,0,0,0,0,0,0,0,0,0,0,0,0,0,0
0,0,0,0,0,0,6,0,0,35,0,0,0,35,0,35,0,0,0,6,0,0,0,0,0,0,0,0,0,0,0,0,0,0,0,0,0,0,0,0,0
0,0,0,0,0,0,93,0,0,35,0,0,0,35,0,35,0,0,0,93,0,0,0,0,0,0,0,0,0,0,0,0,0,0,0,0,0,0,0,0,0
0,0,0,0,0,0,6,132,0,35,0,0,0,35,131,35,0,0,0,6,0,0,0,0,0,0,0,0,0,0,0,0,0,0,0,0,0,0,0,0,0
0,0,0,0,0,130,5,6,6,6,93,6,93,6,6,6,6,93,6,5,0,0,0,0,0,0,0,0,0,0,0,0,0,0,0,0,0,0,0,0,0
0,0,0,0,0,0,90,0,0,0,0,0,0,90,0,0,0,0,0,0,0,0,0,0,0,0,0,6,0,0,0,0,0,0,0,0,0,0,0,0,0
0,0,0,0,0,0,0,0,0,0,0,0,0,0,0,0,0,0,0,0,0,0,0,0,0,0,0,0,0,0,0,0,0,0,0,0,0,0,0,0,0
0,0,0,0,0,0,0,0,0,0,0,0,0,0,0,0,0,0,0,0,0,0,0,0,0,0,0,0,0,0,0,0,0,0,0,0,0,0,0,0,0
0,0,0,0,0,0,0,0,0,0,0,0,0,0,0,0,0,0,0,0,0,0,0,0,0,0,0,0,0,0,0,0,0,0,0,0,0,0,0,0,0
0,0,0,0,0,0,0,0,0,0,0,0,0,0,0,0,0,0,0,0,0,0,0,0,0,0,0,0,0,0,0,0,0,0,0,0,0,0,0,0,0
0,0,0,0,0,0,0,0,0,0,0,0,0,0,0,0,0,0,0,0,0,0,0,0,0,0,0,0,0,0,0,0,0,0,0,0,0,0,0,0,0
0,0,0,0,0,0,0,0,0,0,0,0,0,0,0,0,0,0,0,0,0,0,0,0,0,0,0,0,0,0,0,0,0,0,0,0,0,0,0,0,0
0,0,0,0,0,0,0,0,0,0,0,0,0,0,0,0,0,0,0,0,0,0,0,0,0,0,0,0,0,0,0,0,0,0,0,0,0,0,0,0,0
0,0,0,0,0,0,0,0,0,0,0,0,0,0,0,0,0,0,0,0,0,0,0,0,0,0,0,0,0,0,0,0,0,0,0,0,0,0,0,0,0
0,0,0,0,0,0,0,0,0,0,0,0,0,0,0,0,0,0,0,0,0,0,0,0,0,0,0,0,0,0,0,0,0,0,0,0,0,0,0,0,0
:endlayer
layer: 13
0,0,0,0,0,0,0,0,0,0,0,0,0,0,0,0,0,0,0,0,0,0,0,0,0,0,0,0,0,0,0,0,0,0,0,0,0,0,0,0,0
0,0,0,0,0,0,0,0,0,0,0,0,0,0,0,0,0,0,0,0,0,0,0,0,0,0,0,0,0,0,0,0,0,0,0,0,0,0,0,0,0
0,0,0,0,0,0,0,0,0,0,0,0,0,0,0,0,0,0,0,0,0,0,0,0,0,0,0,0,0,0,0,0,0,0,0,0,0,0,0,0,0
0,0,0,0,0,0,0,0,0,0,0,0,0,0,0,0,0,0,0,0,0,0,0,0,0,0,0,0,0,0,0,0,0,0,0,0,0,0,0,0,0
0,0,0,0,0,0,0,0,0,0,0,0,0,0,0,0,0,0,0,0,0,0,0,0,0,0,0,0,0,0,0,0,0,0,0,0,0,0,0,0,0
0,0,0,0,0,17,17,17,17,17,17,17,17,17,17,17,17,17,17,17,17,0,0,0,0,0,0,0,0,0,0,0,0,0,0,0,0,0,0,0,0
0,0,0,0,0,0,35,0,0,0,0,0,0,0,0,0,0,0,0,0,35,0,0,0,0,0,0,0,0,0,0,0,0,0,0,0,0,0,0,0,0
0,0,0,0,0,0,35,0,0,0,0,0,0,0,0,0,0,0,0,0,35,17,17,17,17,17,17,17,17,17,17,17,17,17,17,17,17,17,35,0,0
0,0,0,0,0,0,35,0,0,0,0,0,0,0,0,0,0,0,0,0,35,21,21,21,21,21,21,21,21,21,21,21,21,21,21,21,21,21,35,0,0
0,0,0,0,0,0,93,0,0,0,0,0,0,0,0,0,0,0,0,0,93,0,0,0,0,0,0,0,0,0,0,0,0,0,0,0,0,0,0,0,0
0,0,0,0,0,0,35,0,0,0,0,0,0,0,0,0,0,0,0,80,35,0,0,0,0,0,0,0,0,0,0,0,0,0,0,0,0,0,0,0,0
0,0,0,0,0,0,35,0,0,0,0,0,0,0,0,0,0,0,0,0,35,0,0,0,0,0,0,0,0,0,0,0,0,0,0,0,0,0,0,0,0
0,0,0,0,0,0,35,0,0,0,0,0,0,0,0,0,0,0,0,0,35,0,0,0,0,0,0,0,0,0,0,0,0,0,0,0,0,0,0,0,0
0,0,0,0,0,21,21,21,21,21,21,21,21,21,21,21,21,21,21,21,21,0,0,0,0,0,0,0,0,0,0,0,0,0,0,0,0,0,0,0,0
0,0,0,0,0,0,0,0,0,0,0,0,0,0,0,0,0,0,0,0,0,0,0,0,0,0,0,0,17,17,17,17,17,17,17,17,17,17,17,0,0
0,0,0,0,0,0,0,0,0,0,0,0,0,0,0,0,0,0,0,0,0,0,0,0,0,0,0,0,0,35,0,0,0,0,0,0,0,35,0,0,0
0,0,0,0,0,0,0,0,0,0,0,0,0,0,0,0,0,0,0,0,0,0,0,0,0,0,0,0,0,35,0,0,0,0,0,0,0,35,0,0,0
0,0,0,0,0,0,0,0,0,0,0,0,0,0,0,0,0,0,0,0,0,0,0,0,0,0,0,0,0,35,0,0,0,0,0,0,0,35,0,0,0
0,0,0,0,0,0,0,0,0,0,0,0,0,0,0,0,0,0,0,0,0,0,0,0,0,0,0,0,21,21,21,21,21,21,21,21,21,21,21,0,0
0,0,0,0,0,0,0,0,0,0,0,0,0,0,0,0,0,0,0,0,0,0,0,0,0,0,0,0,0,0,0,0,0,0,0,0,0,0,0,0,0
0,0,0,0,0,0,0,0,0,0,0,0,0,0,0,0,0,0,0,0,0,0,0,0,0,0,0,0,0,0,0,0,0,0,0,0,0,0,0,0,0
0,0,0,0,0,0,0,0,0,0,0,0,0,0,0,0,0,0,0,0,0,0,0,0,0,0,0,0,0,0,0,0,0,0,0,0,0,0,0,0,0
0,0,0,0,0,0,0,0,0,0,0,0,0,0,0,0,0,0,0,0,0,0,0,0,0,0,0,0,0,0,0,0,0,0,0,0,0,0,0,0,0
0,0,0,0,0,0,0,0,0,0,0,0,0,0,0,0,0,0,0,0,0,0,0,0,0,0,0,0,0,0,0,0,0,0,0,0,0,0,0,0,0
0,0,0,0,0,0,0,0,0,0,0,0,0,0,0,0,0,0,0,0,0,0,0,0,0,0,0,0,0,0,0,0,0,0,0,0,0,0,0,0,0
0,0,0,0,0,0,0,0,0,0,0,0,0,0,0,0,0,0,0,0,0,0,0,0,0,0,0,0,0,0,0,0,0,0,0,0,0,0,0,0,0
0,0,0,0,0,0,0,0,0,0,0,0,0,0,0,0,0,0,0,0,0,0,0,0,0,0,0,0,0,0,0,0,0,0,0,0,0,0,0,0,0
0,0,0,0,0,0,0,0,0,0,0,0,0,0,158,17,17,17,17,17,158,0,0,0,0,0,0,0,0,0,0,0,0,0,0,0,0,0,0,0,0
0,0,0,0,0,158,17,17,17,17,17,17,17,17,17,6,6,6,6,6,41,0,0,0,0,0,0,0,0,0,0,0,0,0,0,0,0,0,0,0,0
0,0,0,0,0,37,6,6,6,6,6,6,6,6,0,0,0,0,0,6,41,0,0,0,0,0,0,0,0,0,0,0,0,0,0,0,0,0,0,0,0
0,0,0,0,0,37,6,0,0,0,0,6,6,6,0,6,0,0,0,6,41,0,0,0,0,0,0,0,0,0,0,0,0,0,0,0,0,0,0,0,0
0,0,0,0,0,37,6,0,0,0,0,6,6,6,6,0,0,0,0,6,41,0,0,0,0,0,0,0,0,0,0,0,0,0,0,0,0,0,0,0,0
0,0,0,0,0,37,6,0,0,0,0,0,0,0,0,6,6,6,6,6,41,0,0,0,0,0,0,0,0,0,0,0,0,0,0,0,0,0,0,0,0
0,0,0,0,0,37,6,0,0,0,0,0,0,0,0,35,0,0,0,6,41,0,0,0,0,0,0,0,0,0,0,0,0,0,0,0,0,0,0,0,0
0,0,0,0,0,37,6,0,0,0,0,0,0,0,0,35,0,0,0,6,41,0,0,0,0,0,0,0,0,0,0,0,0,0,0,0,0,0,0,0,0
0,0,0,0,0,37,6,35,35,35,35,35,35,35,165,35,0,0,0,6,41,0,0,0,0,0,0,0,0,0,0,0,0,0,0,0,0,0,0,0,0
0,0,0,0,0,37,6,0,0,35,0,0,0,35,0,35,35,35,35,6,41,0,0,0,0,0,0,0,0,0,0,0,0,0,0,0,0,0,0,0,0
0,0,0,0,0,37,6,0,0,35,0,0,0,35,0,35,0,0,0,6,41,0,0,0,0,0,0,0,0,0,0,0,0,0,0,0,0,0,0,0,0
0,0,0,0,0,37,6,0,0,35,0,0,0,35,165,35,0,0,0,6,41,0,0,0,0,0,0,0,0,0,0,0,0,0,0,0,0,0,0,0,0
0,0,0,0,0,37,6,0,0,35,0,0,0,35,0,35,0,0,0,6,41,0,0,0,0,0,0,0,0,0,0,0,0,0,0,0,0,0,0,0,0
0,0,0,0,0,37,6,6,6,6,6,6,6,6,6,6,6,6,6,6,41,0,0,0,0,0,0,0,0,0,0,0,0,0,0,0,0,0,0,0,0
0,0,0,0,0,158,21,21,21,21,21,21,21,21,21,21,21,21,21,21,158,0,0,0,0,0,0,192,0,0,0,0,0,0,0,0,0,0,0,0,0
0,0,0,0,0,0,0,0,0,0,0,0,0,0,0,0,0,0,0,0,0,0,0,0,0,0,0,0,0,0,0,0,0,0,0,0,0,0,0,0,0
0,0,0,0,0,0,0,0,0,0,0,0,0,0,0,0,0,0,0,0,0,0,0,0,0,0,0,0,0,0,0,0,0,0,0,0,0,0,0,0,0
0,0,0,0,0,0,0,0,0,0,0,0,0,0,0,0,0,0,0,0,0,0,0,0,0,0,0,0,0,0,0,0,0,0,0,0,0,0,0,0,0
0,0,0,0,0,0,0,0,0,0,0,0,0,0,0,0,0,0,0,0,0,0,0,0,0,0,0,0,0,0,0,0,0,0,0,0,0,0,0,0,0
0,0,0,0,0,0,0,0,0,0,0,0,0,0,0,0,0,0,0,0,0,0,0,0,0,0,0,0,0,0,0,0,0,0,0,0,0,0,0,0,0
0,0,0,0,0,0,0,0,0,0,0,0,0,0,0,0,0,0,0,0,0,0,0,0,0,0,0,0,0,0,0,0,0,0,0,0,0,0,0,0,0
0,0,0,0,0,0,0,0,0,0,0,0,0,0,0,0,0,0,0,0,0,0,0,0,0,0,0,0,0,0,0,0,0,0,0,0,0,0,0,0,0
0,0,0,0,0,0,0,0,0,0,0,0,0,0,0,0,0,0,0,0,0,0,0,0,0,0,0,0,0,0,0,0,0,0,0,0,0,0,0,0,0
0,0,0,0,0,0,0,0,0,0,0,0,0,0,0,0,0,0,0,0,0,0,0,0,0,0,0,0,0,0,0,0,0,0,0,0,0,0,0,0,0
:endlayer
layer: 14
0,0,0,0,0,0,0,0,0,0,0,0,0,0,0,0,0,0,0,0,0,0,0,0,0,0,0,0,0,0,0,0,0,0,0,0,0,0,0,0,0
0,0,0,0,0,0,0,0,0,0,0,0,0,0,0,0,0,0,0,0,0,0,0,0,0,0,0,0,0,0,0,0,0,0,0,0,0,0,0,0,0
0,0,0,0,0,0,0,0,0,0,0,0,0,0,0,0,0,0,0,0,0,0,0,0,0,0,0,0,0,0,0,0,0,0,0,0,0,0,0,0,0
0,0,0,0,0,0,0,0,0,0,0,0,0,0,0,0,0,0,0,0,0,0,0,0,0,0,0,0,0,0,0,0,0,0,0,0,0,0,0,0,0
0,0,0,0,0,0,0,0,0,0,0,0,0,0,0,0,0,0,0,0,0,0,0,0,0,0,0,0,0,0,0,0,0,0,0,0,0,0,0,0,0
0,0,0,0,0,0,0,0,0,0,0,0,0,0,0,0,0,0,0,0,0,0,0,0,0,0,0,0,0,0,0,0,0,0,0,0,0,0,0,0,0
0,0,0,0,0,17,35,35,35,35,35,35,35,35,35,35,35,35,35,35,35,0,0,0,0,0,0,0,0,0,0,0,0,0,0,0,0,0,0,0,0
0,0,0,0,0,145,35,35,35,35,35,35,35,35,35,35,35,35,35,35,35,0,0,0,0,0,0,0,0,0,0,0,0,0,0,0,0,0,87,0,0
0,0,0,0,0,145,35,35,0,0,0,0,0,0,0,0,0,0,0,35,35,0,0,0,0,0,0,0,0,0,0,0,0,0,0,0,0,0,87,0,0
0,0,0,0,0,0,35,0,0,0,0,0,0,0,0,0,0,0,0,0,35,0,0,0,0,0,0,0,0,0,0,0,0,0,0,0,0,0,0,0,0
0,0,0,0,0,145,35,35,0,0,0,0,0,0,0,0,0,0,0,35,35,0,0,0,0,0,0,0,0,0,0,0,0,0,0,0,0,0,0,0,0
0,0,0,0,0,145,35,35,35,35,35,35,35,35,35,35,35,35,35,35,35,0,0,0,0,0,0,0,0,0,0,0,0,0,0,0,0,0,0,0,0
0,0,0,0,0,21,35,35,35,35,35,35,35,35,35,35,35,35,35,35,35,0,0,0,0,0,0,0,0,0,0,0,0,0,0,0,0,0,0,0,0
0,0,0,0,0,0,0,0,0,0,0,0,0,0,0,0,0,0,0,0,0,0,0,0,0,0,0,0,0,0,0,0,0,0,0,0,0,0,0,0,0
0,0,0,0,0,0,0,0,0,0,0,0,0,0,0,0,0,0,0,0,0,0,0,0,0,0,0,0,0,0,0,0,0,0,0,0,0,0,0,0,0
0,0,0,0,0,0,0,0,0,0,0,0,0,0,0,0,0,0,0,0,0,0,0,0,0,0,0,0,17,17,17,17,17,17,17,17,17,17,17,0,0
0,0,0,0,0,0,0,0,0,0,0,0,0,0,0,0,0,0,0,0,0,0,0,0,0,0,0,0,35,35,35,35,35,35,35,35,35,35,35,0,0
0,0,0,0,0,0,0,0,0,0,0,0,0,0,0,0,0,0,0,0,0,0,0,0,0,0,0,0,21,21,21,21,21,21,21,21,21,21,21,0,0
0,0,0,0,0,0,0,0,0,0,0,0,0,0,0,0,0,0,0,0,0,0,0,0,0,0,0,0,0,0,0,0,0,0,0,0,0,0,0,0,0
0,0,0,0,0,0,0,0,0,0,0,0,0,0,0,0,0,0,0,0,0,0,0,0,0,0,0,0,0,0,0,0,0,0,0,0,0,0,0,0,0
0,0,0,0,0,0,0,0,0,0,0,0,0,0,0,0,0,0,0,0,0,0,0,0,0,0,0,0,0,0,0,0,0,0,0,0,0,0,0,0,0
0,0,0,0,0,0,0,0,0,0,0,0,0,0,0,0,0,0,0,0,0,0,0,0,0,0,0,0,0,0,0,0,0,0,0,0,0,0,0,0,0
0,0,0,0,0,0,0,0,0,0,0,0,0,0,0,0,0,0,0,0,0,0,0,0,0,0,0,0,0,0,0,0,0,0,0,0,0,0,0,0,0
0,0,0,0,0,0,0,0,0,0,0,0,0,0,0,0,0,0,0,0,0,0,0,0,0,0,0,0,0,0,0,0,0,0,0,0,0,0,0,0,0
0,0,0,0,0,0,0,0,0,0,0,0,0,0,0,0,0,0,0,0,0,0,0,0,0,0,0,0,0,0,0,0,0,0,0,0,0,0,0,0,0
0,0,0,0,0,0,0,0,0,0,0,0,0,0,0,0,0,0,0,0,0,0,0,0,0,0,0,0,0,0,0,0,0,0,0,0,0,0,0,0,0
0,0,0,0,0,0,0,0,0,0,0,0,0,0,0,0,0,0,0,0,0,0,0,0,0,0,0,0,0,0,0,0,0,0,0,0,0,0,0,0,0
0,0,0,0,0,0,0,0,0,0,0,0,0,0,0,0,0,0,0,0,0,0,0,0,0,0,0,0,0,0,0,0,0,0,0,0,0,0,0,0,0
0,0,0,0,0,0,0,0,0,0,0,0,0,0,0,6,0,6,0,6,0,0,0,0,0,0,0,0,0,0,0,0,0,0,0,0,0,0,0,0,0
0,0,0,0,0,0,158,17,17,17,17,17,17,158,0,0,0,0,0,0,0,0,0,0,0,0,0,0,0,0,0,0,0,0,0,0,0,0,0,0,0
0,0,0,0,0,0,37,35,35,35,35,35,35,41,0,6,0,0,0,6,0,0,0,0,0,0,0,0,0,0,0,0,0,0,0,0,0,0,0,0,0
0,0,0,0,0,0,37,35,166,0,0,6,35,41,0,0,0,0,0,0,0,0,0,0,0,0,0,0,0,0,0,0,0,0,0,0,0,0,0,0,0
0,0,0,0,0,0,37,35,166,0,0,166,35,41,6,6,0,6,0,6,0,0,0,0,0,0,0,0,0,0,0,0,0,0,0,0,0,0,0,0,0
0,0,0,0,0,0,37,35,166,0,0,166,35,41,158,158,158,158,158,158,0,0,0,0,0,0,0,0,0,0,0,0,0,0,0,0,0,0,0,0,0
0,0,0,0,0,0,37,35,166,0,0,166,35,41,158,158,158,158,158,158,0,0,0,0,0,0,0,0,0,0,0,0,0,0,0,0,0,0,0,0,0
0,0,0,0,0,0,37,35,35,35,35,35,35,41,158,158,158,158,158,158,0,0,0,0,0,0,0,0,0,0,0,0,0,0,0,0,0,0,0,0,0
0,0,0,0,0,0,37,35,0,35,0,0,35,41,158,158,158,158,158,158,0,0,0,0,0,0,0,0,0,0,0,0,0,0,0,0,0,0,0,0,0
0,0,0,0,0,0,37,35,0,35,0,0,35,41,158,158,158,158,158,158,0,0,0,0,0,0,0,0,0,0,0,0,0,0,0,0,0,0,0,0,0
0,0,0,0,0,0,37,35,0,35,0,0,35,41,158,158,158,158,158,158,0,0,0,0,0,0,0,0,0,0,0,0,0,0,0,0,0,0,0,0,0
0,0,0,0,0,0,37,35,35,35,35,35,35,41,158,158,158,158,158,158,0,0,0,0,0,0,0,0,0,0,0,0,0,0,0,0,0,0,0,0,0
0,0,0,0,0,0,158,21,21,21,21,21,21,41,158,158,158,158,158,35,0,0,0,0,0,0,0,0,0,0,0,0,0,0,0,0,0,0,0,0,0
0,0,0,0,0,0,0,0,0,0,0,0,0,0,0,0,0,0,0,0,0,0,0,0,0,0,0,0,0,0,0,0,0,0,0,0,0,0,0,0,0
0,0,0,0,0,0,0,0,0,0,0,0,0,0,0,0,0,0,0,0,0,0,0,0,0,0,0,0,0,0,0,0,0,0,0,0,0,0,0,0,0
0,0,0,0,0,0,0,0,0,0,0,0,0,0,0,0,0,0,0,0,0,0,0,0,0,0,0,0,0,0,0,0,0,0,0,0,0,0,0,0,0
0,0,0,0,0,0,0,0,0,0,0,0,0,0,0,0,0,0,0,0,0,0,0,0,0,0,0,0,0,0,0,0,0,0,0,0,0,0,0,0,0
0,0,0,0,0,0,0,0,0,0,0,0,0,0,0,0,0,0,0,0,0,0,0,0,0,0,0,0,0,0,0,0,0,0,0,0,0,0,0,0,0
0,0,0,0,0,0,0,0,0,0,0,0,0,0,0,0,0,0,0,0,0,0,0,0,0,0,0,0,0,0,0,0,0,0,0,0,0,0,0,0,0
0,0,0,0,0,0,0,0,0,0,0,0,0,0,0,0,0,0,0,0,0,0,0,0,0,0,0,0,0,0,0,0,0,0,0,0,0,0,0,0,0
0,0,0,0,0,0,0,0,0,0,0,0,0,0,0,0,0,0,0,0,0,0,0,0,0,0,0,0,0,0,0,0,0,0,0,0,0,0,0,0,0
0,0,0,0,0,0,0,0,0,0,0,0,0,0,0,0,0,0,0,0,0,0,0,0,0,0,0,0,0,0,0,0,0,0,0,0,0,0,0,0,0
0,0,0,0,0,0,0,0,0,0,0,0,0,0,0,0,0,0,0,0,0,0,0,0,0,0,0,0,0,0,0,0,0,0,0,0,0,0,0,0,0
:endlayer
layer: 15
0,0,0,0,0,0,0,0,0,0,0,0,0,0,0,0,0,0,0,0,0,0,0,0,0,0,0,0,0,0,0,0,0,0,0,0,0,0,0,0,0
0,0,0,0,0,0,0,0,0,0,0,0,0,0,0,0,0,0,0,0,0,0,0,0,0,0,0,0,0,0,0,0,0,0,0,0,0,0,0,0,0
0,0,0,0,0,0,0,0,0,0,0,0,0,0,0,0,0,0,0,0,0,0,0,0,0,0,0,0,0,0,0,0,0,0,0,0,0,0,0,0,0
0,0,0,0,0,0,0,0,0,0,0,0,0,0,0,0,0,0,0,0,0,0,0,0,0,0,0,0,0,0,0,0,0,0,0,0,0,0,0,0,0
0,0,0,0,0,0,0,0,0,0,0,0,0,0,0,0,0,0,0,0,0,0,0,0,0,0,0,0,0,0,0,0,0,0,0,0,0,0,0,0,0
0,0,0,0,0,0,0,0,0,0,0,0,0,0,0,0,0,0,0,0,0,0,0,0,0,0,0,0,0,0,0,0,0,0,0,0,0,0,0,0,0
0,0,0,0,0,0,0,0,0,0,0,0,0,0,0,0,0,0,0,0,0,0,0,0,0,0,0,0,0,0,0,0,0,0,0,0,0,0,0,0,0
0,0,0,0,0,0,0,0,0,0,0,0,0,0,0,0,0,0,0,0,0,0,0,0,0,0,0,0,0,0,0,0,0,0,0,0,0,0,0,0,0
0,0,0,0,0,158,158,17,17,17,17,17,17,17,17,17,17,17,17,17,158,0,0,0,0,0,0,0,0,0,0,0,0,0,0,0,0,0,0,0,0
0,0,0,0,0,35,35,35,35,35,35,35,35,35,35,35,35,35,35,35,35,0,0,0,0,0,0,0,0,0,0,0,0,0,0,0,0,0,0,0,0
0,0,0,0,0,158,158,21,21,21,21,21,21,21,21,21,21,21,21,21,158,0,0,0,0,0,0,0,0,0,0,0,0,0,0,0,0,0,0,0,0
0,0,0,0,0,0,0,0,0,0,0,0,0,0,0,0,0,0,0,0,0,0,0,0,0,0,0,0,0,0,0,0,0,0,0,0,0,0,0,0,0
0,0,0,0,0,0,0,0,0,0,0,0,0,0,0,0,0,0,0,0,0,0,0,0,0,0,0,0,0,0,0,0,0,0,0,0,0,0,0,0,0
0,0,0,0,0,0,0,0,0,0,0,0,0,0,0,0,0,0,0,0,0,0,0,0,0,0,0,0,0,0,0,0,0,0,0,0,0,0,0,0,0
0,0,0,0,0,0,0,0,0,0,0,0,0,0,0,0,0,0,0,0,0,0,0,0,0,0,0,0,0,0,0,0,0,0,0,0,0,0,0,0,0
0,0,0,0,0,0,0,0,0,0,0,0,0,0,0,0,0,0,0,0,0,0,0,0,0,0,0,0,0,0,0,0,0,0,0,0,0,0,0,0,0
0,0,0,0,0,0,0,0,0,0,0,0,0,0,0,0,0,0,0,0,0,0,0,0,0,0,0,0,87,0,0,0,0,0,0,0,0,0,87,0,0
0,0,0,0,0,0,0,0,0,0,0,0,0,0,0,0,0,0,0,0,0,0,0,0,0,0,0,0,0,0,0,0,0,0,0,0,0,0,0,0,0
0,0,0,0,0,0,0,0,0,0,0,0,0,0,0,0,0,0,0,0,0,0,0,0,0,0,0,0,0,0,0,0,0,0,0,0,0,0,0,0,0
0,0,0,0,0,0,0,0,0,0,0,0,0,0,0,0,0,0,0,0,0,0,0,0,0,0,0,0,0,0,0,0,0,0,0,0,0,0,0,0,0
0,0,0,0,0,0,0,0,0,0,0,0,0,0,0,0,0,0,0,0,0,0,0,0,0,0,0,0,0,0,0,0,0,0,0,0,0,0,0,0,0
0,0,0,0,0,0,0,0,0,0,0,0,0,0,0,0,0,0,0,0,0,0,0,0,0,0,0,0,0,0,0,0,0,0,0,0,0,0,0,0,0
0,0,0,0,0,0,0,0,0,0,0,0,0,0,0,0,0,0,0,0,0,0,0,0,0,0,0,0,0,0,0,0,0,0,0,0,0,0,0,0,0
0,0,0,0,0,0,0,0,0,0,0,0,0,0,0,0,0,0,0,0,0,0,0,0,0,0,0,0,0,0,0,0,0,0,0,0,0,0,0,0,0
0,0,0,0,0,0,0,0,0,0,0,0,0,0,0,0,0,0,0,0,0,0,0,0,0,0,0,0,0,0,0,0,0,0,0,0,0,0,0,0,0
0,0,0,0,0,0,0,0,0,0,0,0,0,0,0,0,0,0,0,0,0,0,0,0,0,0,0,0,0,0,0,0,0,0,0,0,0,0,0,0,0
0,0,0,0,0,0,0,0,0,0,0,0,0,0,0,0,0,0,0,0,0,0,0,0,0,0,0,0,0,0,0,0,0,0,0,0,0,0,0,0,0
0,0,0,0,0,0,0,0,0,0,0,0,0,0,0,0,0,0,0,0,0,0,0,0,0,0,0,0,0,0,0,0,0,0,0,0,0,0,0,0,0
0,0,0,0,0,0,0,0,0,0,0,0,0,0,0,6,0,6,0,6,0,0,0,0,0,0,0,0,0,0,0,0,0,0,0,0,0,0,0,0,0
0,0,0,0,0,0,0,0,0,0,0,0,0,0,0,0,0,0,0,0,0,0,0,0,0,0,0,0,0,0,0,0,0,0,0,0,0,0,0,0,0
0,0,0,0,0,0,0,158,17,17,17,17,158,0,0,6,0,0,0,6,0,0,0,0,0,0,0,0,0,0,0,0,0,0,0,0,0,0,0,0,0
0,0,0,0,0,0,0,37,35,35,35,35,41,0,0,0,0,0,0,0,0,0,0,0,0,0,0,0,0,0,0,0,0,0,0,0,0,0,0,0,0
0,0,0,0,0,0,0,37,35,0,0,35,41,0,0,6,0,6,0,6,0,0,0,0,0,0,0,0,0,0,0,0,0,0,0,0,0,0,0,0,0
0,0,0,0,0,0,0,37,35,0,0,35,41,0,0,0,0,0,0,0,0,0,0,0,0,0,0,0,0,0,0,0,0,0,0,0,0,0,0,0,0
0,0,0,0,0,0,0,37,35,35,35,35,41,0,0,0,0,0,0,0,0,0,0,0,0,0,0,0,0,0,0,0,0,0,0,0,0,0,0,0,0
0,0,0,0,0,0,0,37,35,35,35,35,41,0,0,0,0,0,0,0,0,0,0,0,0,0,0,0,0,0,0,0,0,0,0,0,0,0,0,0,0
0,0,0,0,0,0,0,37,35,35,35,35,41,0,0,0,0,0,0,0,0,0,0,0,0,0,0,0,0,0,0,0,0,0,0,0,0,0,0,0,0
0,0,0,0,0,0,0,37,35,35,35,35,41,0,0,0,0,0,0,0,0,0,0,0,0,0,0,0,0,0,0,0,0,0,0,0,0,0,0,0,0
0,0,0,0,0,0,0,37,35,35,35,35,41,0,0,0,0,0,0,0,0,0,0,0,0,0,0,0,0,0,0,0,0,0,0,0,0,0,0,0,0
0,0,0,0,0,0,0,158,21,21,21,21,21,0,0,0,0,0,0,0,0,0,0,0,0,0,0,0,0,0,0,0,0,0,0,0,0,0,0,0,0
0,0,0,0,0,0,0,0,0,0,0,0,0,0,0,0,0,0,0,87,0,0,0,0,0,0,0,0,0,0,0,0,0,0,0,0,0,0,0,0,0
0,0,0,0,0,0,0,0,0,0,0,0,0,0,0,0,0,0,0,0,0,0,0,0,0,0,0,0,0,0,0,0,0,0,0,0,0,0,0,0,0
0,0,0,0,0,0,0,0,0,0,0,0,0,0,0,0,0,0,0,0,0,0,0,0,0,0,0,0,0,0,0,0,0,0,0,0,0,0,0,0,0
0,0,0,0,0,0,0,0,0,0,0,0,0,0,0,0,0,0,0,0,0,0,0,0,0,0,0,0,0,0,0,0,0,0,0,0,0,0,0,0,0
0,0,0,0,0,0,0,0,0,0,0,0,0,0,0,0,0,0,0,0,0,0,0,0,0,0,0,0,0,0,0,0,0,0,0,0,0,0,0,0,0
0,0,0,0,0,0,0,0,0,0,0,0,0,0,0,0,0,0,0,0,0,0,0,0,0,0,0,0,0,0,0,0,0,0,0,0,0,0,0,0,0
0,0,0,0,0,0,0,0,0,0,0,0,0,0,0,0,0,0,0,0,0,0,0,0,0,0,0,0,0,0,0,0,0,0,0,0,0,0,0,0,0
0,0,0,0,0,0,0,0,0,0,0,0,0,0,0,0,0,0,0,0,0,0,0,0,0,0,0,0,0,0,0,0,0,0,0,0,0,0,0,0,0
0,0,0,0,0,0,0,0,0,0,0,0,0,0,0,0,0,0,0,0,0,0,0,0,0,0,0,0,0,0,0,0,0,0,0,0,0,0,0,0,0
0,0,0,0,0,0,0,0,0,0,0,0,0,0,0,0,0,0,0,0,0,0,0,0,0,0,0,0,0,0,0,0,0,0,0,0,0,0,0,0,0
0,0,0,0,0,0,0,0,0,0,0,0,0,0,0,0,0,0,0,0,0,0,0,0,0,0,0,0,0,0,0,0,0,0,0,0,0,0,0,0,0
:endlayer
layer: 16
0,0,0,0,0,0,0,0,0,0,0,0,0,0,0,0,0,0,0,0,0,0,0,0,0,0,0,0,0,0,0,0,0,0,0,0,0,0,0,0,0
0,0,0,0,0,0,0,0,0,0,0,0,0,0,0,0,0,0,0,0,0,0,0,0,0,0,0,0,0,0,0,0,0,0,0,0,0,0,0,0,0
0,0,0,0,0,0,0,0,0,0,0,0,0,0,0,0,0,0,0,0,0,0,0,0,0,0,0,0,0,0,0,0,0,0,0,0,0,0,0,0,0
0,0,0,0,0,0,0,0,0,0,0,0,0,0,0,0,0,0,0,0,0,0,0,0,0,0,0,0,0,0,0,0,0,0,0,0,0,0,0,0,0
0,0,0,0,0,0,0,0,0,0,0,0,0,0,0,0,0,0,0,0,0,0,0,0,0,0,0,0,0,0,0,0,0,0,0,0,0,0,0,0,0
0,0,0,0,0,0,0,0,0,0,0,0,0,0,0,0,0,0,0,0,0,0,0,0,0,0,0,0,0,0,0,0,0,0,0,0,0,0,0,0,0
0,0,0,0,0,0,0,0,0,0,0,0,0,0,0,0,0,0,0,0,0,0,0,0,0,0,0,0,0,0,0,0,0,0,0,0,0,0,0,0,0
0,0,0,0,0,0,0,0,0,0,0,0,0,0,0,0,0,0,0,0,0,0,0,0,0,0,0,0,0,0,0,0,0,0,0,0,0,0,0,0,0
0,0,0,0,0,0,0,0,0,0,0,0,0,0,0,0,0,0,0,0,0,0,0,0,0,0,0,0,0,0,0,0,0,0,0,0,0,0,0,0,0
0,0,0,0,0,87,0,0,0,0,0,0,0,0,0,0,0,0,0,0,87,0,0,0,0,0,0,0,0,0,0,0,0,0,0,0,0,0,0,0,0
0,0,0,0,0,0,0,0,0,0,0,0,0,0,0,0,0,0,0,0,0,0,0,0,0,0,0,0,0,0,0,0,0,0,0,0,0,0,0,0,0
0,0,0,0,0,0,0,0,0,0,0,0,0,0,0,0,0,0,0,0,0,0,0,0,0,0,0,0,0,0,0,0,0,0,0,0,0,0,0,0,0
0,0,0,0,0,0,0,0,0,0,0,0,0,0,0,0,0,0,0,0,0,0,0,0,0,0,0,0,0,0,0,0,0,0,0,0,0,0,0,0,0
0,0,0,0,0,0,0,0,0,0,0,0,0,0,0,0,0,0,0,0,0,0,0,0,0,0,0,0,0,0,0,0,0,0,0,0,0,0,0,0,0
0,0,0,0,0,0,0,0,0,0,0,0,0,0,0,0,0,0,0,0,0,0,0,0,0,0,0,0,0,0,0,0,0,0,0,0,0,0,0,0,0
0,0,0,0,0,0,0,0,0,0,0,0,0,0,0,0,0,0,0,0,0,0,0,0,0,0,0,0,0,0,0,0,0,0,0,0,0,0,0,0,0
0,0,0,0,0,0,0,0,0,0,0,0,0,0,0,0,0,0,0,0,0,0,0,0,0,0,0,0,0,0,0,0,0,0,0,0,0,0,0,0,0
0,0,0,0,0,0,0,0,0,0,0,0,0,0,0,0,0,0,0,0,0,0,0,0,0,0,0,0,0,0,0,0,0,0,0,0,0,0,0,0,0
0,0,0,0,0,0,0,0,0,0,0,0,0,0,0,0,0,0,0,0,0,0,0,0,0,0,0,0,0,0,0,0,0,0,0,0,0,0,0,0,0
0,0,0,0,0,0,0,0,0,0,0,0,0,0,0,0,0,0,0,0,0,0,0,0,0,0,0,0,0,0,0,0,0,0,0,0,0,0,0,0,0
0,0,0,0,0,0,0,0,0,0,0,0,0,0,0,0,0,0,0,0,0,0,0,0,0,0,0,0,0,0,0,0,0,0,0,0,0,0,0,0,0
0,0,0,0,0,0,0,0,0,0,0,0,0,0,0,0,0,0,0,0,0,0,0,0,0,0,0,0,0,0,0,0,0,0,0,0,0,0,0,0,0
0,0,0,0,0,0,0,0,0,0,0,0,0,0,0,0,0,0,0,0,0,0,0,0,0,0,0,0,0,0,0,0,0,0,0,0,0,0,0,0,0
0,0,0,0,0,0,0,0,0,0,0,0,0,0,0,0,0,0,0,0,0,0,0,0,0,0,0,0,0,0,0,0,0,0,0,0,0,0,0,0,0
0,0,0,0,0,0,0,0,0,0,0,0,0,0,0,0,0,0,0,0,0,0,0,0,0,0,0,0,0,0,0,0,0,0,0,0,0,0,0,0,0
0,0,0,0,0,0,0,0,0,0,0,0,0,0,0,0,0,0,0,0,0,0,0,0,0,0,0,0,0,0,0,0,0,0,0,0,0,0,0,0,0
0,0,0,0,0,0,0,0,0,0,0,0,0,0,0,0,0,0,0,0,0,0,0,0,0,0,0,0,0,0,0,0,0,0,0,0,0,0,0,0,0
0,0,0,0,0,0,0,0,0,0,0,0,0,0,17,17,17,17,17,17,17,0,0,0,0,0,0,0,0,0,0,0,0,0,0,0,0,0,0,0,0
0,0,0,0,0,0,0,0,0,0,0,0,0,0,37,6,6,6,6,6,41,0,0,0,0,0,0,0,0,0,0,0,0,0,0,0,0,0,0,0,0
0,0,0,0,0,0,0,0,0,0,0,0,0,0,37,6,0,90,0,6,41,0,0,0,0,0,0,0,0,0,0,0,0,0,0,0,0,0,0,0,0
0,0,0,0,0,0,0,0,0,0,0,0,0,0,37,6,132,0,0,6,41,0,0,0,0,0,0,0,0,0,0,0,0,0,0,0,0,0,0,0,0
0,0,0,0,0,0,0,0,158,17,17,158,0,0,37,6,0,0,0,6,41,0,0,0,0,0,0,0,0,0,0,0,0,0,0,0,0,0,0,0,0
0,0,0,0,0,0,0,0,37,35,35,41,0,0,37,6,6,6,6,6,41,0,0,0,0,0,0,0,0,0,0,0,0,0,0,0,0,0,0,0,0
0,0,0,0,0,0,0,0,37,35,35,41,0,0,21,21,21,21,21,21,21,0,0,0,0,0,0,0,0,0,0,0,0,0,0,0,0,0,0,0,0
0,0,0,0,0,0,0,0,37,35,35,41,0,0,0,0,0,0,0,0,0,0,0,0,0,0,0,0,0,0,0,0,0,0,0,0,0,0,0,0,0
0,0,0,0,0,0,0,0,37,35,35,41,0,0,0,0,0,0,0,0,0,0,0,0,0,0,0,0,0,0,0,0,0,0,0,0,0,0,0,0,0
0,0,0,0,0,0,0,0,37,35,35,41,0,0,0,0,0,0,0,0,0,0,0,0,0,0,0,0,0,0,0,0,0,0,0,0,0,0,0,0,0
0,0,0,0,0,0,0,0,37,35,35,41,0,0,0,0,0,0,0,0,0,0,0,0,0,0,0,0,0,0,0,0,0,0,0,0,0,0,0,0,0
0,0,0,0,0,0,0,0,158,21,21,21,0,0,0,0,0,0,0,0,0,0,0,0,0,0,0,0,0,0,0,0,0,0,0,0,0,0,0,0,0
0,0,0,0,0,0,0,0,0,0,0,0,0,0,0,0,0,0,0,0,0,0,0,0,0,0,0,0,0,0,0,0,0,0,0,0,0,0,0,0,0
0,0,0,0,0,0,0,0,0,0,0,0,0,0,0,0,0,0,0,0,0,0,0,0,0,0,0,0,0,0,0,0,0,0,0,0,0,0,0,0,0
0,0,0,0,0,0,0,0,0,0,0,0,0,0,0,0,0,0,0,0,0,0,0,0,0,0,0,0,0,0,0,0,0,0,0,0,0,0,0,0,0
0,0,0,0,0,0,0,0,0,0,0,0,0,0,0,0,0,0,0,0,0,0,0,0,0,0,0,0,0,0,0,0,0,0,0,0,0,0,0,0,0
0,0,0,0,0,0,0,0,0,0,0,0,0,0,0,0,0,0,0,0,0,0,0,0,0,0,0,0,0,0,0,0,0,0,0,0,0,0,0,0,0
0,0,0,0,0,0,0,0,0,0,0,0,0,0,0,0,0,0,0,0,0,0,0,0,0,0,0,0,0,0,0,0,0,0,0,0,0,0,0,0,0
0,0,0,0,0,0,0,0,0,0,0,0,0,0,0,0,0,0,0,0,0,0,0,0,0,0,0,0,0,0,0,0,0,0,0,0,0,0,0,0,0
0,0,0,0,0,0,0,0,0,0,0,0,0,0,0,0,0,0,0,0,0,0,0,0,0,0,0,0,0,0,0,0,0,0,0,0,0,0,0,0,0
0,0,0,0,0,0,0,0,0,0,0,0,0,0,0,0,0,0,0,0,0,0,0,0,0,0,0,0,0,0,0,0,0,0,0,0,0,0,0,0,0
0,0,0,0,0,0,0,0,0,0,0,0,0,0,0,0,0,0,0,0,0,0,0,0,0,0,0,0,0,0,0,0,0,0,0,0,0,0,0,0,0
0,0,0,0,0,0,0,0,0,0,0,0,0,0,0,0,0,0,0,0,0,0,0,0,0,0,0,0,0,0,0,0,0,0,0,0,0,0,0,0,0
0,0,0,0,0,0,0,0,0,0,0,0,0,0,0,0,0,0,0,0,0,0,0,0,0,0,0,0,0,0,0,0,0,0,0,0,0,0,0,0,0
:endlayer
layer: 17
0,0,0,0,0,0,0,0,0,0,0,0,0,0,0,0,0,0,0,0,0,0,0,0,0,0,0,0,0,0,0,0,0,0,0,0,0,0,0,0,0
0,0,0,0,0,0,0,0,0,0,0,0,0,0,0,0,0,0,0,0,0,0,0,0,0,0,0,0,0,0,0,0,0,0,0,0,0,0,0,0,0
0,0,0,0,0,0,0,0,0,0,0,0,0,0,0,0,0,0,0,0,0,0,0,0,0,0,0,0,0,0,0,0,0,0,0,0,0,0,0,0,0
0,0,0,0,0,0,0,0,0,0,0,0,0,0,0,0,0,0,0,0,0,0,0,0,0,0,0,0,0,0,0,0,0,0,0,0,0,0,0,0,0
0,0,0,0,0,0,0,0,0,0,0,0,0,0,0,0,0,0,0,0,0,0,0,0,0,0,0,0,0,0,0,0,0,0,0,0,0,0,0,0,0
0,0,0,0,0,0,0,0,0,0,0,0,0,0,0,0,0,0,0,0,0,0,0,0,0,0,0,0,0,0,0,0,0,0,0,0,0,0,0,0,0
0,0,0,0,0,0,0,0,0,0,0,0,0,0,0,0,0,0,0,0,0,0,0,0,0,0,0,0,0,0,0,0,0,0,0,0,0,0,0,0,0
0,0,0,0,0,0,0,0,0,0,0,0,0,0,0,0,0,0,0,0,0,0,0,0,0,0,0,0,0,0,0,0,0,0,0,0,0,0,0,0,0
0,0,0,0,0,0,0,0,0,0,0,0,0,0,0,0,0,0,0,0,0,0,0,0,0,0,0,0,0,0,0,0,0,0,0,0,0,0,0,0,0
0,0,0,0,0,0,0,0,0,0,0,0,0,0,0,0,0,0,0,0,0,0,0,0,0,0,0,0,0,0,0,0,0,0,0,0,0,0,0,0,0
0,0,0,0,0,0,0,0,0,0,0,0,0,0,0,0,0,0,0,0,0,0,0,0,0,0,0,0,0,0,0,0,0,0,0,0,0,0,0,0,0
0,0,0,0,0,0,0,0,0,0,0,0,0,0,0,0,0,0,0,0,0,0,0,0,0,0,0,0,0,0,0,0,0,0,0,0,0,0,0,0,0
0,0,0,0,0,0,0,0,0,0,0,0,0,0,0,0,0,0,0,0,0,0,0,0,0,0,0,0,0,0,0,0,0,0,0,0,0,0,0,0,0
0,0,0,0,0,0,0,0,0,0,0,0,0,0,0,0,0,0,0,0,0,0,0,0,0,0,0,0,0,0,0,0,0,0,0,0,0,0,0,0,0
0,0,0,0,0,0,0,0,0,0,0,0,0,0,0,0,0,0,0,0,0,0,0,0,0,0,0,0,0,0,0,0,0,0,0,0,0,0,0,0,0
0,0,0,0,0,0,0,0,0,0,0,0,0,0,0,0,0,0,0,0,0,0,0,0,0,0,0,0,0,0,0,0,0,0,0,0,0,0,0,0,0
0,0,0,0,0,0,0,0,0,0,0,0,0,0,0,0,0,0,0,0,0,0,0,0,0,0,0,0,0,0,0,0,0,0,0,0,0,0,0,0,0
0,0,0,0,0,0,0,0,0,0,0,0,0,0,0,0,0,0,0,0,0,0,0,0,0,0,0,0,0,0,0,0,0,0,0,0,0,0,0,0,0
0,0,0,0,0,0,0,0,0,0,0,0,0,0,0,0,0,0,0,0,0,0,0,0,0,0,0,0,0,0,0,0,0,0,0,0,0,0,0,0,0
0,0,0,0,0,0,0,0,0,0,0,0,0,0,0,0,0,0,0,0,0,0,0,0,0,0,0,0,0,0,0,0,0,0,0,0,0,0,0,0,0
0,0,0,0,0,0,0,0,0,0,0,0,0,0,0,0,0,0,0,0,0,0,0,0,0,0,0,0,0,0,0,0,0,0,0,0,0,0,0,0,0
0,0,0,0,0,0,0,0,0,0,0,0,0,0,0,0,0,0,0,0,0,0,0,0,0,0,0,0,0,0,0,0,0,0,0,0,0,0,0,0,0
0,0,0,0,0,0,0,0,0,0,0,0,0,0,0,0,0,0,0,0,0,0,0,0,0,0,0,0,0,0,0,0,0,0,0,0,0,0,0,0,0
0,0,0,0,0,0,0,0,0,0,0,0,0,0,0,0,0,0,0,0,0,0,0,0,0,0,0,0,0,0,0,0,0,0,0,0,0,0,0,0,0
0,0,0,0,0,0,0,0,0,0,0,0,0,0,0,0,0,0,0,0,0,0,0,0,0,0,0,0,0,0,0,0,0,0,0,0,0,0,0,0,0
0,0,0,0,0,0,0,0,0,0,0,0,0,0,0,0,0,0,0,0,0,0,0,0,0,0,0,0,0,0,0,0,0,0,0,0,0,0,0,0,0
0,0,0,0,0,0,0,0,0,0,0,0,0,0,0,0,0,0,0,0,0,0,0,0,0,0,0,0,0,0,0,0,0,0,0,0,0,0,0,0,0
0,0,0,0,0,0,0,0,0,0,0,0,0,0,0,0,0,0,0,0,0,0,0,0,0,0,0,0,0,0,0,0,0,0,0,0,0,0,0,0,0
0,0,0,0,0,0,0,0,0,0,0,0,0,0,0,17,17,17,17,41,0,0,0,0,0,0,0,0,0,0,0,0,0,0,0,0,0,0,0,0,0
0,0,0,0,0,0,0,0,0,0,0,0,0,0,0,37,35,0,35,41,0,0,0,0,0,0,0,0,0,0,0,0,0,0,0,0,0,0,0,0,0
0,0,0,0,0,0,0,0,0,0,0,0,0,0,0,37,0,0,0,41,0,0,0,0,0,0,0,0,0,0,0,0,0,0,0,0,0,0,0,0,0
0,0,0,0,0,0,0,0,0,0,0,0,0,0,0,37,35,0,35,41,0,0,0,0,0,0,0,0,0,0,0,0,0,0,0,0,0,0,0,0,0
0,0,0,0,0,0,0,0,0,158,158,0,0,0,0,37,21,21,21,21,0,0,0,0,0,0,0,0,0,0,0,0,0,0,0,0,0,0,0,0,0
0,0,0,0,0,0,0,0,0,37,41,0,0,0,0,0,0,0,0,0,0,0,0,0,0,0,0,0,0,0,0,0,0,0,0,0,0,0,0,0,0
0,0,0,0,0,0,0,0,0,37,41,0,0,0,0,0,0,0,0,0,0,0,0,0,0,0,0,0,0,0,0,0,0,0,0,0,0,0,0,0,0
0,0,0,0,0,0,0,0,0,37,41,0,0,0,0,0,0,0,0,0,0,0,0,0,0,0,0,0,0,0,0,0,0,0,0,0,0,0,0,0,0
0,0,0,0,0,0,0,0,0,37,41,0,0,0,0,0,0,0,0,0,0,0,0,0,0,0,0,0,0,0,0,0,0,0,0,0,0,0,0,0,0
0,0,0,0,0,0,0,0,0,158,158,0,0,0,0,0,0,0,0,0,0,0,0,0,0,0,0,0,0,0,0,0,0,0,0,0,0,0,0,0,0
0,0,0,0,0,0,0,0,0,0,0,0,0,0,0,0,0,0,0,0,0,0,0,0,0,0,0,0,0,0,0,0,0,0,0,0,0,0,0,0,0
0,0,0,0,0,0,0,0,0,0,0,0,0,0,0,0,0,0,0,0,0,0,0,0,0,0,0,0,0,0,0,0,0,0,0,0,0,0,0,0,0
0,0,0,0,0,0,0,0,0,0,0,0,0,0,0,0,0,0,0,0,0,0,0,0,0,0,0,0,0,0,0,0,0,0,0,0,0,0,0,0,0
0,0,0,0,0,0,0,0,0,0,0,0,0,0,0,0,0,0,0,0,0,0,0,0,0,0,0,0,0,0,0,0,0,0,0,0,0,0,0,0,0
0,0,0,0,0,0,0,0,0,0,0,0,0,0,0,0,0,0,0,0,0,0,0,0,0,0,0,0,0,0,0,0,0,0,0,0,0,0,0,0,0
0,0,0,0,0,0,0,0,0,0,0,0,0,0,0,0,0,0,0,0,0,0,0,0,0,0,0,0,0,0,0,0,0,0,0,0,0,0,0,0,0
0,0,0,0,0,0,0,0,0,0,0,0,0,0,0,0,0,0,0,0,0,0,0,0,0,0,0,0,0,0,0,0,0,0,0,0,0,0,0,0,0
0,0,0,0,0,0,0,0,0,0,0,0,0,0,0,0,0,0,0,0,0,0,0,0,0,0,0,0,0,0,0,0,0,0,0,0,0,0,0,0,0
0,0,0,0,0,0,0,0,0,0,0,0,0,0,0,0,0,0,0,0,0,0,0,0,0,0,0,0,0,0,0,0,0,0,0,0,0,0,0,0,0
0,0,0,0,0,0,0,0,0,0,0,0,0,0,0,0,0,0,0,0,0,0,0,0,0,0,0,0,0,0,0,0,0,0,0,0,0,0,0,0,0
0,0,0,0,0,0,0,0,0,0,0,0,0,0,0,0,0,0,0,0,0,0,0,0,0,0,0,0,0,0,0,0,0,0,0,0,0,0,0,0,0
0,0,0,0,0,0,0,0,0,0,0,0,0,0,0,0,0,0,0,0,0,0,0,0,0,0,0,0,0,0,0,0,0,0,0,0,0,0,0,0,0
0,0,0,0,0,0,0,0,0,0,0,0,0,0,0,0,0,0,0,0,0,0,0,0,0,0,0,0,0,0,0,0,0,0,0,0,0,0,0,0,0
:endlayer
layer: 18
0,0,0,0,0,0,0,0,0,0,0,0,0,0,0,0,0,0,0,0,0,0,0,0,0,0,0,0,0,0,0,0,0,0,0,0,0,0,0,0,0
0,0,0,0,0,0,0,0,0,0,0,0,0,0,0,0,0,0,0,0,0,0,0,0,0,0,0,0,0,0,0,0,0,0,0,0,0,0,0,0,0
0,0,0,0,0,0,0,0,0,0,0,0,0,0,0,0,0,0,0,0,0,0,0,0,0,0,0,0,0,0,0,0,0,0,0,0,0,0,0,0,0
0,0,0,0,0,0,0,0,0,0,0,0,0,0,0,0,0,0,0,0,0,0,0,0,0,0,0,0,0,0,0,0,0,0,0,0,0,0,0,0,0
0,0,0,0,0,0,0,0,0,0,0,0,0,0,0,0,0,0,0,0,0,0,0,0,0,0,0,0,0,0,0,0,0,0,0,0,0,0,0,0,0
0,0,0,0,0,0,0,0,0,0,0,0,0,0,0,0,0,0,0,0,0,0,0,0,0,0,0,0,0,0,0,0,0,0,0,0,0,0,0,0,0
0,0,0,0,0,0,0,0,0,0,0,0,0,0,0,0,0,0,0,0,0,0,0,0,0,0,0,0,0,0,0,0,0,0,0,0,0,0,0,0,0
0,0,0,0,0,0,0,0,0,0,0,0,0,0,0,0,0,0,0,0,0,0,0,0,0,0,0,0,0,0,0,0,0,0,0,0,0,0,0,0,0
0,0,0,0,0,0,0,0,0,0,0,0,0,0,0,0,0,0,0,0,0,0,0,0,0,0,0,0,0,0,0,0,0,0,0,0,0,0,0,0,0
0,0,0,0,0,0,0,0,0,0,0,0,0,0,0,0,0,0,0,0,0,0,0,0,0,0,0,0,0,0,0,0,0,0,0,0,0,0,0,0,0
0,0,0,0,0,0,0,0,0,0,0,0,0,0,0,0,0,0,0,0,0,0,0,0,0,0,0,0,0,0,0,0,0,0,0,0,0,0,0,0,0
0,0,0,0,0,0,0,0,0,0,0,0,0,0,0,0,0,0,0,0,0,0,0,0,0,0,0,0,0,0,0,0,0,0,0,0,0,0,0,0,0
0,0,0,0,0,0,0,0,0,0,0,0,0,0,0,0,0,0,0,0,0,0,0,0,0,0,0,0,0,0,0,0,0,0,0,0,0,0,0,0,0
0,0,0,0,0,0,0,0,0,0,0,0,0,0,0,0,0,0,0,0,0,0,0,0,0,0,0,0,0,0,0,0,0,0,0,0,0,0,0,0,0
0,0,0,0,0,0,0,0,0,0,0,0,0,0,0,0,0,0,0,0,0,0,0,0,0,0,0,0,0,0,0,0,0,0,0,0,0,0,0,0,0
0,0,0,0,0,0,0,0,0,0,0,0,0,0,0,0,0,0,0,0,0,0,0,0,0,0,0,0,0,0,0,0,0,0,0,0,0,0,0,0,0
0,0,0,0,0,0,0,0,0,0,0,0,0,0,0,0,0,0,0,0,0,0,0,0,0,0,0,0,0,0,0,0,0,0,0,0,0,0,0,0,0
0,0,0,0,0,0,0,0,0,0,0,0,0,0,0,0,0,0,0,0,0,0,0,0,0,0,0,0,0,0,0,0,0,0,0,0,0,0,0,0,0
0,0,0,0,0,0,0,0,0,0,0,0,0,0,0,0,0,0,0,0,0,0,0,0,0,0,0,0,0,0,0,0,0,0,0,0,0,0,0,0,0
0,0,0,0,0,0,0,0,0,0,0,0,0,0,0,0,0,0,0,0,0,0,0,0,0,0,0,0,0,0,0,0,0,0,0,0,0,0,0,0,0
0,0,0,0,0,0,0,0,0,0,0,0,0,0,0,0,0,0,0,0,0,0,0,0,0,0,0,0,0,0,0,0,0,0,0,0,0,0,0,0,0
0,0,0,0,0,0,0,0,0,0,0,0,0,0,0,0,0,0,0,0,0,0,0,0,0,0,0,0,0,0,0,0,0,0,0,0,0,0,0,0,0
0,0,0,0,0,0,0,0,0,0,0,0,0,0,0,0,0,0,0,0,0,0,0,0,0,0,0,0,0,0,0,0,0,0,0,0,0,0,0,0,0
0,0,0,0,0,0,0,0,0,0,0,0,0,0,0,0,0,0,0,0,0,0,0,0,0,0,0,0,0,0,0,0,0,0,0,0,0,0,0,0,0
0,0,0,0,0,0,0,0,0,0,0,0,0,0,0,0,0,0,0,0,0,0,0,0,0,0,0,0,0,0,0,0,0,0,0,0,0,0,0,0,0
0,0,0,0,0,0,0,0,0,0,0,0,0,0,0,0,0,0,0,0,0,0,0,0,0,0,0,0,0,0,0,0,0,0,0,0,0,0,0,0,0
0,0,0,0,0,0,0,0,0,0,0,0,0,0,0,0,0,0,0,0,0,0,0,0,0,0,0,0,0,0,0,0,0,0,0,0,0,0,0,0,0
0,0,0,0,0,0,0,0,0,0,0,0,0,0,0,0,0,0,0,0,0,0,0,0,0,0,0,0,0,0,0,0,0,0,0,0,0,0,0,0,0
0,0,0,0,0,0,0,0,0,0,0,0,0,0,0,0,0,0,0,0,0,0,0,0,0,0,0,0,0,0,0,0,0,0,0,0,0,0,0,0,0
0,0,0,0,0,0,0,0,0,0,0,0,0,0,0,0,37,17,41,0,0,0,0,0,0,0,0,0,0,0,0,0,0,0,0,0,0,0,0,0,0
0,0,0,0,0,0,0,0,0,0,0,0,0,0,0,0,37,35,41,0,0,0,0,0,0,0,0,0,0,0,0,0,0,0,0,0,0,0,0,0,0
0,0,0,0,0,0,0,0,0,0,0,0,0,0,0,0,37,21,41,0,0,0,0,0,0,0,0,0,0,0,0,0,0,0,0,0,0,0,0,0,0
0,0,0,0,0,0,0,0,0,0,0,0,0,0,0,0,0,0,0,0,0,0,0,0,0,0,0,0,0,0,0,0,0,0,0,0,0,0,0,0,0
0,0,0,0,0,0,0,0,0,0,0,0,0,0,0,0,0,0,0,0,0,0,0,0,0,0,0,0,0,0,0,0,0,0,0,0,0,0,0,0,0
0,0,0,0,0,0,0,0,0,0,0,0,0,0,0,0,0,0,0,0,0,0,0,0,0,0,0,0,0,0,0,0,0,0,0,0,0,0,0,0,0
0,0,0,0,0,0,0,0,0,0,0,0,0,0,0,0,0,0,0,0,0,0,0,0,0,0,0,0,0,0,0,0,0,0,0,0,0,0,0,0,0
0,0,0,0,0,0,0,0,0,0,0,0,0,0,0,0,0,0,0,0,0,0,0,0,0,0,0,0,0,0,0,0,0,0,0,0,0,0,0,0,0
0,0,0,0,0,0,0,0,0,0,0,0,0,0,0,0,0,0,0,0,0,0,0,0,0,0,0,0,0,0,0,0,0,0,0,0,0,0,0,0,0
0,0,0,0,0,0,0,0,0,0,0,0,0,0,0,0,0,0,0,0,0,0,0,0,0,0,0,0,0,0,0,0,0,0,0,0,0,0,0,0,0
0,0,0,0,0,0,0,0,0,0,0,0,0,0,0,0,0,0,0,0,0,0,0,0,0,0,0,0,0,0,0,0,0,0,0,0,0,0,0,0,0
0,0,0,0,0,0,0,0,0,0,0,0,0,0,0,0,0,0,0,0,0,0,0,0,0,0,0,0,0,0,0,0,0,0,0,0,0,0,0,0,0
0,0,0,0,0,0,0,0,0,0,0,0,0,0,0,0,0,0,0,0,0,0,0,0,0,0,0,0,0,0,0,0,0,0,0,0,0,0,0,0,0
0,0,0,0,0,0,0,0,0,0,0,0,0,0,0,0,0,0,0,0,0,0,0,0,0,0,0,0,0,0,0,0,0,0,0,0,0,0,0,0,0
0,0,0,0,0,0,0,0,0,0,0,0,0,0,0,0,0,0,0,0,0,0,0,0,0,0,0,0,0,0,0,0,0,0,0,0,0,0,0,0,0
0,0,0,0,0,0,0,0,0,0,0,0,0,0,0,0,0,0,0,0,0,0,0,0,0,0,0,0,0,0,0,0,0,0,0,0,0,0,0,0,0
0,0,0,0,0,0,0,0,0,0,0,0,0,0,0,0,0,0,0,0,0,0,0,0,0,0,0,0,0,0,0,0,0,0,0,0,0,0,0,0,0
0,0,0,0,0,0,0,0,0,0,0,0,0,0,0,0,0,0,0,0,0,0,0,0,0,0,0,0,0,0,0,0,0,0,0,0,0,0,0,0,0
0,0,0,0,0,0,0,0,0,0,0,0,0,0,0,0,0,0,0,0,0,0,0,0,0,0,0,0,0,0,0,0,0,0,0,0,0,0,0,0,0
0,0,0,0,0,0,0,0,0,0,0,0,0,0,0,0,0,0,0,0,0,0,0,0,0,0,0,0,0,0,0,0,0,0,0,0,0,0,0,0,0
0,0,0,0,0,0,0,0,0,0,0,0,0,0,0,0,0,0,0,0,0,0,0,0,0,0,0,0,0,0,0,0,0,0,0,0,0,0,0,0,0
0,0,0,0,0,0,0,0,0,0,0,0,0,0,0,0,0,0,0,0,0,0,0,0,0,0,0,0,0,0,0,0,0,0,0,0,0,0,0,0,0
:endlayer
layer: 19
0,0,0,0,0,0,0,0,0,0,0,0,0,0,0,0,0,0,0,0,0,0,0,0,0,0,0,0,0,0,0,0,0,0,0,0,0,0,0,0,0
0,0,0,0,0,0,0,0,0,0,0,0,0,0,0,0,0,0,0,0,0,0,0,0,0,0,0,0,0,0,0,0,0,0,0,0,0,0,0,0,0
0,0,0,0,0,0,0,0,0,0,0,0,0,0,0,0,0,0,0,0,0,0,0,0,0,0,0,0,0,0,0,0,0,0,0,0,0,0,0,0,0
0,0,0,0,0,0,0,0,0,0,0,0,0,0,0,0,0,0,0,0,0,0,0,0,0,0,0,0,0,0,0,0,0,0,0,0,0,0,0,0,0
0,0,0,0,0,0,0,0,0,0,0,0,0,0,0,0,0,0,0,0,0,0,0,0,0,0,0,0,0,0,0,0,0,0,0,0,0,0,0,0,0
0,0,0,0,0,0,0,0,0,0,0,0,0,0,0,0,0,0,0,0,0,0,0,0,0,0,0,0,0,0,0,0,0,0,0,0,0,0,0,0,0
0,0,0,0,0,0,0,0,0,0,0,0,0,0,0,0,0,0,0,0,0,0,0,0,0,0,0,0,0,0,0,0,0,0,0,0,0,0,0,0,0
0,0,0,0,0,0,0,0,0,0,0,0,0,0,0,0,0,0,0,0,0,0,0,0,0,0,0,0,0,0,0,0,0,0,0,0,0,0,0,0,0
0,0,0,0,0,0,0,0,0,0,0,0,0,0,0,0,0,0,0,0,0,0,0,0,0,0,0,0,0,0,0,0,0,0,0,0,0,0,0,0,0
0,0,0,0,0,0,0,0,0,0,0,0,0,0,0,0,0,0,0,0,0,0,0,0,0,0,0,0,0,0,0,0,0,0,0,0,0,0,0,0,0
0,0,0,0,0,0,0,0,0,0,0,0,0,0,0,0,0,0,0,0,0,0,0,0,0,0,0,0,0,0,0,0,0,0,0,0,0,0,0,0,0
0,0,0,0,0,0,0,0,0,0,0,0,0,0,0,0,0,0,0,0,0,0,0,0,0,0,0,0,0,0,0,0,0,0,0,0,0,0,0,0,0
0,0,0,0,0,0,0,0,0,0,0,0,0,0,0,0,0,0,0,0,0,0,0,0,0,0,0,0,0,0,0,0,0,0,0,0,0,0,0,0,0
0,0,0,0,0,0,0,0,0,0,0,0,0,0,0,0,0,0,0,0,0,0,0,0,0,0,0,0,0,0,0,0,0,0,0,0,0,0,0,0,0
0,0,0,0,0,0,0,0,0,0,0,0,0,0,0,0,0,0,0,0,0,0,0,0,0,0,0,0,0,0,0,0,0,0,0,0,0,0,0,0,0
0,0,0,0,0,0,0,0,0,0,0,0,0,0,0,0,0,0,0,0,0,0,0,0,0,0,0,0,0,0,0,0,0,0,0,0,0,0,0,0,0
0,0,0,0,0,0,0,0,0,0,0,0,0,0,0,0,0,0,0,0,0,0,0,0,0,0,0,0,0,0,0,0,0,0,0,0,0,0,0,0,0
0,0,0,0,0,0,0,0,0,0,0,0,0,0,0,0,0,0,0,0,0,0,0,0,0,0,0,0,0,0,0,0,0,0,0,0,0,0,0,0,0
0,0,0,0,0,0,0,0,0,0,0,0,0,0,0,0,0,0,0,0,0,0,0,0,0,0,0,0,0,0,0,0,0,0,0,0,0,0,0,0,0
0,0,0,0,0,0,0,0,0,0,0,0,0,0,0,0,0,0,0,0,0,0,0,0,0,0,0,0,0,0,0,0,0,0,0,0,0,0,0,0,0
0,0,0,0,0,0,0,0,0,0,0,0,0,0,0,0,0,0,0,0,0,0,0,0,0,0,0,0,0,0,0,0,0,0,0,0,0,0,0,0,0
0,0,0,0,0,0,0,0,0,0,0,0,0,0,0,0,0,0,0,0,0,0,0,0,0,0,0,0,0,0,0,0,0,0,0,0,0,0,0,0,0
0,0,0,0,0,0,0,0,0,0,0,0,0,0,0,0,0,0,0,0,0,0,0,0,0,0,0,0,0,0,0,0,0,0,0,0,0,0,0,0,0
0,0,0,0,0,0,0,0,0,0,0,0,0,0,0,0,0,0,0,0,0,0,0,0,0,0,0,0,0,0,0,0,0,0,0,0,0,0,0,0,0
0,0,0,0,0,0,0,0,0,0,0,0,0,0,0,0,0,0,0,0,0,0,0,0,0,0,0,0,0,0,0,0,0,0,0,0,0,0,0,0,0
0,0,0,0,0,0,0,0,0,0,0,0,0,0,0,0,0,0,0,0,0,0,0,0,0,0,0,0,0,0,0,0,0,0,0,0,0,0,0,0,0
0,0,0,0,0,0,0,0,0,0,0,0,0,0,0,0,0,0,0,0,0,0,0,0,0,0,0,0,0,0,0,0,0,0,0,0,0,0,0,0,0
0,0,0,0,0,0,0,0,0,0,0,0,0,0,0,0,0,0,0,0,0,0,0,0,0,0,0,0,0,0,0,0,0,0,0,0,0,0,0,0,0
0,0,0,0,0,0,0,0,0,0,0,0,0,0,0,0,0,0,0,0,0,0,0,0,0,0,0,0,0,0,0,0,0,0,0,0,0,0,0,0,0
0,0,0,0,0,0,0,0,0,0,0,0,0,0,0,0,0,0,0,0,0,0,0,0,0,0,0,0,0,0,0,0,0,0,0,0,0,0,0,0,0
0,0,0,0,0,0,0,0,0,0,0,0,0,0,0,0,0,35,0,0,0,0,0,0,0,0,0,0,0,0,0,0,0,0,0,0,0,0,0,0,0
0,0,0,0,0,0,0,0,0,0,0,0,0,0,0,0,0,0,0,0,0,0,0,0,0,0,0,0,0,0,0,0,0,0,0,0,0,0,0,0,0
0,0,0,0,0,0,0,0,0,0,0,0,0,0,0,0,0,0,0,0,0,0,0,0,0,0,0,0,0,0,0,0,0,0,0,0,0,0,0,0,0
0,0,0,0,0,0,0,0,0,0,0,0,0,0,0,0,0,0,0,0,0,0,0,0,0,0,0,0,0,0,0,0,0,0,0,0,0,0,0,0,0
0,0,0,0,0,0,0,0,0,0,0,0,0,0,0,0,0,0,0,0,0,0,0,0,0,0,0,0,0,0,0,0,0,0,0,0,0,0,0,0,0
0,0,0,0,0,0,0,0,0,0,0,0,0,0,0,0,0,0,0,0,0,0,0,0,0,0,0,0,0,0,0,0,0,0,0,0,0,0,0,0,0
0,0,0,0,0,0,0,0,0,0,0,0,0,0,0,0,0,0,0,0,0,0,0,0,0,0,0,0,0,0,0,0,0,0,0,0,0,0,0,0,0
0,0,0,0,0,0,0,0,0,0,0,0,0,0,0,0,0,0,0,0,0,0,0,0,0,0,0,0,0,0,0,0,0,0,0,0,0,0,0,0,0
0,0,0,0,0,0,0,0,0,0,0,0,0,0,0,0,0,0,0,0,0,0,0,0,0,0,0,0,0,0,0,0,0,0,0,0,0,0,0,0,0
0,0,0,0,0,0,0,0,0,0,0,0,0,0,0,0,0,0,0,0,0,0,0,0,0,0,0,0,0,0,0,0,0,0,0,0,0,0,0,0,0
0,0,0,0,0,0,0,0,0,0,0,0,0,0,0,0,0,0,0,0,0,0,0,0,0,0,0,0,0,0,0,0,0,0,0,0,0,0,0,0,0
0,0,0,0,0,0,0,0,0,0,0,0,0,0,0,0,0,0,0,0,0,0,0,0,0,0,0,0,0,0,0,0,0,0,0,0,0,0,0,0,0
0,0,0,0,0,0,0,0,0,0,0,0,0,0,0,0,0,0,0,0,0,0,0,0,0,0,0,0,0,0,0,0,0,0,0,0,0,0,0,0,0
0,0,0,0,0,0,0,0,0,0,0,0,0,0,0,0,0,0,0,0,0,0,0,0,0,0,0,0,0,0,0,0,0,0,0,0,0,0,0,0,0
0,0,0,0,0,0,0,0,0,0,0,0,0,0,0,0,0,0,0,0,0,0,0,0,0,0,0,0,0,0,0,0,0,0,0,0,0,0,0,0,0
0,0,0,0,0,0,0,0,0,0,0,0,0,0,0,0,0,0,0,0,0,0,0,0,0,0,0,0,0,0,0,0,0,0,0,0,0,0,0,0,0
0,0,0,0,0,0,0,0,0,0,0,0,0,0,0,0,0,0,0,0,0,0,0,0,0,0,0,0,0,0,0,0,0,0,0,0,0,0,0,0,0
0,0,0,0,0,0,0,0,0,0,0,0,0,0,0,0,0,0,0,0,0,0,0,0,0,0,0,0,0,0,0,0,0,0,0,0,0,0,0,0,0
0,0,0,0,0,0,0,0,0,0,0,0,0,0,0,0,0,0,0,0,0,0,0,0,0,0,0,0,0,0,0,0,0,0,0,0,0,0,0,0,0
0,0,0,0,0,0,0,0,0,0,0,0,0,0,0,0,0,0,0,0,0,0,0,0,0,0,0,0,0,0,0,0,0,0,0,0,0,0,0,0,0
0,0,0,0,0,0,0,0,0,0,0,0,0,0,0,0,0,0,0,0,0,0,0,0,0,0,0,0,0,0,0,0,0,0,0,0,0,0,0,0,0
:endlayer
layer: 20
0,0,0,0,0,0,0,0,0,0,0,0,0,0,0,0,0,0,0,0,0,0,0,0,0,0,0,0,0,0,0,0,0,0,0,0,0,0,0,0,0
0,0,0,0,0,0,0,0,0,0,0,0,0,0,0,0,0,0,0,0,0,0,0,0,0,0,0,0,0,0,0,0,0,0,0,0,0,0,0,0,0
0,0,0,0,0,0,0,0,0,0,0,0,0,0,0,0,0,0,0,0,0,0,0,0,0,0,0,0,0,0,0,0,0,0,0,0,0,0,0,0,0
0,0,0,0,0,0,0,0,0,0,0,0,0,0,0,0,0,0,0,0,0,0,0,0,0,0,0,0,0,0,0,0,0,0,0,0,0,0,0,0,0
0,0,0,0,0,0,0,0,0,0,0,0,0,0,0,0,0,0,0,0,0,0,0,0,0,0,0,0,0,0,0,0,0,0,0,0,0,0,0,0,0
0,0,0,0,0,0,0,0,0,0,0,0,0,0,0,0,0,0,0,0,0,0,0,0,0,0,0,0,0,0,0,0,0,0,0,0,0,0,0,0,0
0,0,0,0,0,0,0,0,0,0,0,0,0,0,0,0,0,0,0,0,0,0,0,0,0,0,0,0,0,0,0,0,0,0,0,0,0,0,0,0,0
0,0,0,0,0,0,0,0,0,0,0,0,0,0,0,0,0,0,0,0,0,0,0,0,0,0,0,0,0,0,0,0,0,0,0,0,0,0,0,0,0
0,0,0,0,0,0,0,0,0,0,0,0,0,0,0,0,0,0,0,0,0,0,0,0,0,0,0,0,0,0,0,0,0,0,0,0,0,0,0,0,0
0,0,0,0,0,0,0,0,0,0,0,0,0,0,0,0,0,0,0,0,0,0,0,0,0,0,0,0,0,0,0,0,0,0,0,0,0,0,0,0,0
0,0,0,0,0,0,0,0,0,0,0,0,0,0,0,0,0,0,0,0,0,0,0,0,0,0,0,0,0,0,0,0,0,0,0,0,0,0,0,0,0
0,0,0,0,0,0,0,0,0,0,0,0,0,0,0,0,0,0,0,0,0,0,0,0,0,0,0,0,0,0,0,0,0,0,0,0,0,0,0,0,0
0,0,0,0,0,0,0,0,0,0,0,0,0,0,0,0,0,0,0,0,0,0,0,0,0,0,0,0,0,0,0,0,0,0,0,0,0,0,0,0,0
0,0,0,0,0,0,0,0,0,0,0,0,0,0,0,0,0,0,0,0,0,0,0,0,0,0,0,0,0,0,0,0,0,0,0,0,0,0,0,0,0
0,0,0,0,0,0,0,0,0,0,0,0,0,0,0,0,0,0,0,0,0,0,0,0,0,0,0,0,0,0,0,0,0,0,0,0,0,0,0,0,0
0,0,0,0,0,0,0,0,0,0,0,0,0,0,0,0,0,0,0,0,0,0,0,0,0,0,0,0,0,0,0,0,0,0,0,0,0,0,0,0,0
0,0,0,0,0,0,0,0,0,0,0,0,0,0,0,0,0,0,0,0,0,0,0,0,0,0,0,0,0,0,0,0,0,0,0,0,0,0,0,0,0
0,0,0,0,0,0,0,0,0,0,0,0,0,0,0,0,0,0,0,0,0,0,0,0,0,0,0,0,0,0,0,0,0,0,0,0,0,0,0,0,0
0,0,0,0,0,0,0,0,0,0,0,0,0,0,0,0,0,0,0,0,0,0,0,0,0,0,0,0,0,0,0,0,0,0,0,0,0,0,0,0,0
0,0,0,0,0,0,0,0,0,0,0,0,0,0,0,0,0,0,0,0,0,0,0,0,0,0,0,0,0,0,0,0,0,0,0,0,0,0,0,0,0
0,0,0,0,0,0,0,0,0,0,0,0,0,0,0,0,0,0,0,0,0,0,0,0,0,0,0,0,0,0,0,0,0,0,0,0,0,0,0,0,0
0,0,0,0,0,0,0,0,0,0,0,0,0,0,0,0,0,0,0,0,0,0,0,0,0,0,0,0,0,0,0,0,0,0,0,0,0,0,0,0,0
0,0,0,0,0,0,0,0,0,0,0,0,0,0,0,0,0,0,0,0,0,0,0,0,0,0,0,0,0,0,0,0,0,0,0,0,0,0,0,0,0
0,0,0,0,0,0,0,0,0,0,0,0,0,0,0,0,0,0,0,0,0,0,0,0,0,0,0,0,0,0,0,0,0,0,0,0,0,0,0,0,0
0,0,0,0,0,0,0,0,0,0,0,0,0,0,0,0,0,0,0,0,0,0,0,0,0,0,0,0,0,0,0,0,0,0,0,0,0,0,0,0,0
0,0,0,0,0,0,0,0,0,0,0,0,0,0,0,0,0,0,0,0,0,0,0,0,0,0,0,0,0,0,0,0,0,0,0,0,0,0,0,0,0
0,0,0,0,0,0,0,0,0,0,0,0,0,0,0,0,0,0,0,0,0,0,0,0,0,0,0,0,0,0,0,0,0,0,0,0,0,0,0,0,0
0,0,0,0,0,0,0,0,0,0,0,0,0,0,0,0,0,0,0,0,0,0,0,0,0,0,0,0,0,0,0,0,0,0,0,0,0,0,0,0,0
0,0,0,0,0,0,0,0,0,0,0,0,0,0,0,0,0,0,0,0,0,0,0,0,0,0,0,0,0,0,0,0,0,0,0,0,0,0,0,0,0
0,0,0,0,0,0,0,0,0,0,0,0,0,0,0,0,0,0,0,0,0,0,0,0,0,0,0,0,0,0,0,0,0,0,0,0,0,0,0,0,0
0,0,0,0,0,0,0,0,0,0,0,0,0,0,0,0,0,35,132,0,0,0,0,0,0,0,0,0,0,0,0,0,0,0,0,0,0,0,0,0,0
0,0,0,0,0,0,0,0,0,0,0,0,0,0,0,0,0,90,0,0,0,0,0,0,0,0,0,0,0,0,0,0,0,0,0,0,0,0,0,0,0
0,0,0,0,0,0,0,0,0,0,0,0,0,0,0,0,0,0,0,0,0,0,0,0,0,0,0,0,0,0,0,0,0,0,0,0,0,0,0,0,0
0,0,0,0,0,0,0,0,0,0,0,0,0,0,0,0,0,0,0,0,0,0,0,0,0,0,0,0,0,0,0,0,0,0,0,0,0,0,0,0,0
0,0,0,0,0,0,0,0,0,0,0,0,0,0,0,0,0,0,0,0,0,0,0,0,0,0,0,0,0,0,0,0,0,0,0,0,0,0,0,0,0
0,0,0,0,0,0,0,0,0,0,0,0,0,0,0,0,0,0,0,0,0,0,0,0,0,0,0,0,0,0,0,0,0,0,0,0,0,0,0,0,0
0,0,0,0,0,0,0,0,0,0,0,0,0,0,0,0,0,0,0,0,0,0,0,0,0,0,0,0,0,0,0,0,0,0,0,0,0,0,0,0,0
0,0,0,0,0,0,0,0,0,0,0,0,0,0,0,0,0,0,0,0,0,0,0,0,0,0,0,0,0,0,0,0,0,0,0,0,0,0,0,0,0
0,0,0,0,0,0,0,0,0,0,0,0,0,0,0,0,0,0,0,0,0,0,0,0,0,0,0,0,0,0,0,0,0,0,0,0,0,0,0,0,0
0,0,0,0,0,0,0,0,0,0,0,0,0,0,0,0,0,0,0,0,0,0,0,0,0,0,0,0,0,0,0,0,0,0,0,0,0,0,0,0,0
0,0,0,0,0,0,0,0,0,0,0,0,0,0,0,0,0,0,0,0,0,0,0,0,0,0,0,0,0,0,0,0,0,0,0,0,0,0,0,0,0
0,0,0,0,0,0,0,0,0,0,0,0,0,0,0,0,0,0,0,0,0,0,0,0,0,0,0,0,0,0,0,0,0,0,0,0,0,0,0,0,0
0,0,0,0,0,0,0,0,0,0,0,0,0,0,0,0,0,0,0,0,0,0,0,0,0,0,0,0,0,0,0,0,0,0,0,0,0,0,0,0,0
0,0,0,0,0,0,0,0,0,0,0,0,0,0,0,0,0,0,0,0,0,0,0,0,0,0,0,0,0,0,0,0,0,0,0,0,0,0,0,0,0
0,0,0,0,0,0,0,0,0,0,0,0,0,0,0,0,0,0,0,0,0,0,0,0,0,0,0,0,0,0,0,0,0,0,0,0,0,0,0,0,0
0,0,0,0,0,0,0,0,0,0,0,0,0,0,0,0,0,0,0,0,0,0,0,0,0,0,0,0,0,0,0,0,0,0,0,0,0,0,0,0,0
0,0,0,0,0,0,0,0,0,0,0,0,0,0,0,0,0,0,0,0,0,0,0,0,0,0,0,0,0,0,0,0,0,0,0,0,0,0,0,0,0
0,0,0,0,0,0,0,0,0,0,0,0,0,0,0,0,0,0,0,0,0,0,0,0,0,0,0,0,0,0,0,0,0,0,0,0,0,0,0,0,0
0,0,0,0,0,0,0,0,0,0,0,0,0,0,0,0,0,0,0,0,0,0,0,0,0,0,0,0,0,0,0,0,0,0,0,0,0,0,0,0,0
0,0,0,0,0,0,0,0,0,0,0,0,0,0,0,0,0,0,0,0,0,0,0,0,0,0,0,0,0,0,0,0,0,0,0,0,0,0,0,0,0
0,0,0,0,0,0,0,0,0,0,0,0,0,0,0,0,0,0,0,0,0,0,0,0,0,0,0,0,0,0,0,0,0,0,0,0,0,0,0,0,0
:endlayer
layer: 21
0,0,0,0,0,0,0,0,0,0,0,0,0,0,0,0,0,0,0,0,0,0,0,0,0,0,0,0,0,0,0,0,0,0,0,0,0,0,0,0,0
0,0,0,0,0,0,0,0,0,0,0,0,0,0,0,0,0,0,0,0,0,0,0,0,0,0,0,0,0,0,0,0,0,0,0,0,0,0,0,0,0
0,0,0,0,0,0,0,0,0,0,0,0,0,0,0,0,0,0,0,0,0,0,0,0,0,0,0,0,0,0,0,0,0,0,0,0,0,0,0,0,0
0,0,0,0,0,0,0,0,0,0,0,0,0,0,0,0,0,0,0,0,0,0,0,0,0,0,0,0,0,0,0,0,0,0,0,0,0,0,0,0,0
0,0,0,0,0,0,0,0,0,0,0,0,0,0,0,0,0,0,0,0,0,0,0,0,0,0,0,0,0,0,0,0,0,0,0,0,0,0,0,0,0
0,0,0,0,0,0,0,0,0,0,0,0,0,0,0,0,0,0,0,0,0,0,0,0,0,0,0,0,0,0,0,0,0,0,0,0,0,0,0,0,0
0,0,0,0,0,0,0,0,0,0,0,0,0,0,0,0,0,0,0,0,0,0,0,0,0,0,0,0,0,0,0,0,0,0,0,0,0,0,0,0,0
0,0,0,0,0,0,0,0,0,0,0,0,0,0,0,0,0,0,0,0,0,0,0,0,0,0,0,0,0,0,0,0,0,0,0,0,0,0,0,0,0
0,0,0,0,0,0,0,0,0,0,0,0,0,0,0,0,0,0,0,0,0,0,0,0,0,0,0,0,0,0,0,0,0,0,0,0,0,0,0,0,0
0,0,0,0,0,0,0,0,0,0,0,0,0,0,0,0,0,0,0,0,0,0,0,0,0,0,0,0,0,0,0,0,0,0,0,0,0,0,0,0,0
0,0,0,0,0,0,0,0,0,0,0,0,0,0,0,0,0,0,0,0,0,0,0,0,0,0,0,0,0,0,0,0,0,0,0,0,0,0,0,0,0
0,0,0,0,0,0,0,0,0,0,0,0,0,0,0,0,0,0,0,0,0,0,0,0,0,0,0,0,0,0,0,0,0,0,0,0,0,0,0,0,0
0,0,0,0,0,0,0,0,0,0,0,0,0,0,0,0,0,0,0,0,0,0,0,0,0,0,0,0,0,0,0,0,0,0,0,0,0,0,0,0,0
0,0,0,0,0,0,0,0,0,0,0,0,0,0,0,0,0,0,0,0,0,0,0,0,0,0,0,0,0,0,0,0,0,0,0,0,0,0,0,0,0
0,0,0,0,0,0,0,0,0,0,0,0,0,0,0,0,0,0,0,0,0,0,0,0,0,0,0,0,0,0,0,0,0,0,0,0,0,0,0,0,0
0,0,0,0,0,0,0,0,0,0,0,0,0,0,0,0,0,0,0,0,0,0,0,0,0,0,0,0,0,0,0,0,0,0,0,0,0,0,0,0,0
0,0,0,0,0,0,0,0,0,0,0,0,0,0,0,0,0,0,0,0,0,0,0,0,0,0,0,0,0,0,0,0,0,0,0,0,0,0,0,0,0
0,0,0,0,0,0,0,0,0,0,0,0,0,0,0,0,0,0,0,0,0,0,0,0,0,0,0,0,0,0,0,0,0,0,0,0,0,0,0,0,0
0,0,0,0,0,0,0,0,0,0,0,0,0,0,0,0,0,0,0,0,0,0,0,0,0,0,0,0,0,0,0,0,0,0,0,0,0,0,0,0,0
0,0,0,0,0,0,0,0,0,0,0,0,0,0,0,0,0,0,0,0,0,0,0,0,0,0,0,0,0,0,0,0,0,0,0,0,0,0,0,0,0
0,0,0,0,0,0,0,0,0,0,0,0,0,0,0,0,0,0,0,0,0,0,0,0,0,0,0,0,0,0,0,0,0,0,0,0,0,0,0,0,0
0,0,0,0,0,0,0,0,0,0,0,0,0,0,0,0,0,0,0,0,0,0,0,0,0,0,0,0,0,0,0,0,0,0,0,0,0,0,0,0,0
0,0,0,0,0,0,0,0,0,0,0,0,0,0,0,0,0,0,0,0,0,0,0,0,0,0,0,0,0,0,0,0,0,0,0,0,0,0,0,0,0
0,0,0,0,0,0,0,0,0,0,0,0,0,0,0,0,0,0,0,0,0,0,0,0,0,0,0,0,0,0,0,0,0,0,0,0,0,0,0,0,0
0,0,0,0,0,0,0,0,0,0,0,0,0,0,0,0,0,0,0,0,0,0,0,0,0,0,0,0,0,0,0,0,0,0,0,0,0,0,0,0,0
0,0,0,0,0,0,0,0,0,0,0,0,0,0,0,0,0,0,0,0,0,0,0,0,0,0,0,0,0,0,0,0,0,0,0,0,0,0,0,0,0
0,0,0,0,0,0,0,0,0,0,0,0,0,0,0,0,0,0,0,0,0,0,0,0,0,0,0,0,0,0,0,0,0,0,0,0,0,0,0,0,0
0,0,0,0,0,0,0,0,0,0,0,0,0,0,0,0,0,0,0,0,0,0,0,0,0,0,0,0,0,0,0,0,0,0,0,0,0,0,0,0,0
0,0,0,0,0,0,0,0,0,0,0,0,0,0,0,0,0,0,0,0,0,0,0,0,0,0,0,0,0,0,0,0,0,0,0,0,0,0,0,0,0
0,0,0,0,0,0,0,0,0,0,0,0,0,0,0,0,0,0,0,0,0,0,0,0,0,0,0,0,0,0,0,0,0,0,0,0,0,0,0,0,0
0,0,0,0,0,0,0,0,0,0,0,0,0,0,0,0,0,12,0,0,0,0,0,0,0,0,0,0,0,0,0,0,0,0,0,0,0,0,0,0,0
0,0,0,0,0,0,0,0,0,0,0,0,0,0,0,0,0,0,0,0,0,0,0,0,0,0,0,0,0,0,0,0,0,0,0,0,0,0,0,0,0
0,0,0,0,0,0,0,0,0,0,0,0,0,0,0,0,0,0,0,0,0,0,0,0,0,0,0,0,0,0,0,0,0,0,0,0,0,0,0,0,0
0,0,0,0,0,0,0,0,0,0,0,0,0,0,0,0,0,0,0,0,0,0,0,0,0,0,0,0,0,0,0,0,0,0,0,0,0,0,0,0,0
0,0,0,0,0,0,0,0,0,0,0,0,0,0,0,0,0,0,0,0,0,0,0,0,0,0,0,0,0,0,0,0,0,0,0,0,0,0,0,0,0
0,0,0,0,0,0,0,0,0,0,0,0,0,0,0,0,0,0,0,0,0,0,0,0,0,0,0,0,0,0,0,0,0,0,0,0,0,0,0,0,0
0,0,0,0,0,0,0,0,0,0,0,0,0,0,0,0,0,0,0,0,0,0,0,0,0,0,0,0,0,0,0,0,0,0,0,0,0,0,0,0,0
0,0,0,0,0,0,0,0,0,0,0,0,0,0,0,0,0,0,0,0,0,0,0,0,0,0,0,0,0,0,0,0,0,0,0,0,0,0,0,0,0
0,0,0,0,0,0,0,0,0,0,0,0,0,0,0,0,0,0,0,0,0,0,0,0,0,0,0,0,0,0,0,0,0,0,0,0,0,0,0,0,0
0,0,0,0,0,0,0,0,0,0,0,0,0,0,0,0,0,0,0,0,0,0,0,0,0,0,0,0,0,0,0,0,0,0,0,0,0,0,0,0,0
0,0,0,0,0,0,0,0,0,0,0,0,0,0,0,0,0,0,0,0,0,0,0,0,0,0,0,0,0,0,0,0,0,0,0,0,0,0,0,0,0
0,0,0,0,0,0,0,0,0,0,0,0,0,0,0,0,0,0,0,0,0,0,0,0,0,0,0,0,0,0,0,0,0,0,0,0,0,0,0,0,0
0,0,0,0,0,0,0,0,0,0,0,0,0,0,0,0,0,0,0,0,0,0,0,0,0,0,0,0,0,0,0,0,0,0,0,0,0,0,0,0,0
0,0,0,0,0,0,0,0,0,0,0,0,0,0,0,0,0,0,0,0,0,0,0,0,0,0,0,0,0,0,0,0,0,0,0,0,0,0,0,0,0
0,0,0,0,0,0,0,0,0,0,0,0,0,0,0,0,0,0,0,0,0,0,0,0,0,0,0,0,0,0,0,0,0,0,0,0,0,0,0,0,0
0,0,0,0,0,0,0,0,0,0,0,0,0,0,0,0,0,0,0,0,0,0,0,0,0,0,0,0,0,0,0,0,0,0,0,0,0,0,0,0,0
0,0,0,0,0,0,0,0,0,0,0,0,0,0,0,0,0,0,0,0,0,0,0,0,0,0,0,0,0,0,0,0,0,0,0,0,0,0,0,0,0
0,0,0,0,0,0,0,0,0,0,0,0,0,0,0,0,0,0,0,0,0,0,0,0,0,0,0,0,0,0,0,0,0,0,0,0,0,0,0,0,0
0,0,0,0,0,0,0,0,0,0,0,0,0,0,0,0,0,0,0,0,0,0,0,0,0,0,0,0,0,0,0,0,0,0,0,0,0,0,0,0,0
0,0,0,0,0,0,0,0,0,0,0,0,0,0,0,0,0,0,0,0,0,0,0,0,0,0,0,0,0,0,0,0,0,0,0,0,0,0,0,0,0
0,0,0,0,0,0,0,0,0,0,0,0,0,0,0,0,0,0,0,0,0,0,0,0,0,0,0,0,0,0,0,0,0,0,0,0,0,0,0,0,0
:endlayer
layer: 22
0,0,0,0,0,0,0,0,0,0,0,0,0,0,0,0,0,0,0,0,0,0,0,0,0,0,0,0,0,0,0,0,0,0,0,0,0,0,0,0,0
0,0,0,0,0,0,0,0,0,0,0,0,0,0,0,0,0,0,0,0,0,0,0,0,0,0,0,0,0,0,0,0,0,0,0,0,0,0,0,0,0
0,0,0,0,0,0,0,0,0,0,0,0,0,0,0,0,0,0,0,0,0,0,0,0,0,0,0,0,0,0,0,0,0,0,0,0,0,0,0,0,0
0,0,0,0,0,0,0,0,0,0,0,0,0,0,0,0,0,0,0,0,0,0,0,0,0,0,0,0,0,0,0,0,0,0,0,0,0,0,0,0,0
0,0,0,0,0,0,0,0,0,0,0,0,0,0,0,0,0,0,0,0,0,0,0,0,0,0,0,0,0,0,0,0,0,0,0,0,0,0,0,0,0
0,0,0,0,0,0,0,0,0,0,0,0,0,0,0,0,0,0,0,0,0,0,0,0,0,0,0,0,0,0,0,0,0,0,0,0,0,0,0,0,0
0,0,0,0,0,0,0,0,0,0,0,0,0,0,0,0,0,0,0,0,0,0,0,0,0,0,0,0,0,0,0,0,0,0,0,0,0,0,0,0,0
0,0,0,0,0,0,0,0,0,0,0,0,0,0,0,0,0,0,0,0,0,0,0,0,0,0,0,0,0,0,0,0,0,0,0,0,0,0,0,0,0
0,0,0,0,0,0,0,0,0,0,0,0,0,0,0,0,0,0,0,0,0,0,0,0,0,0,0,0,0,0,0,0,0,0,0,0,0,0,0,0,0
0,0,0,0,0,0,0,0,0,0,0,0,0,0,0,0,0,0,0,0,0,0,0,0,0,0,0,0,0,0,0,0,0,0,0,0,0,0,0,0,0
0,0,0,0,0,0,0,0,0,0,0,0,0,0,0,0,0,0,0,0,0,0,0,0,0,0,0,0,0,0,0,0,0,0,0,0,0,0,0,0,0
0,0,0,0,0,0,0,0,0,0,0,0,0,0,0,0,0,0,0,0,0,0,0,0,0,0,0,0,0,0,0,0,0,0,0,0,0,0,0,0,0
0,0,0,0,0,0,0,0,0,0,0,0,0,0,0,0,0,0,0,0,0,0,0,0,0,0,0,0,0,0,0,0,0,0,0,0,0,0,0,0,0
0,0,0,0,0,0,0,0,0,0,0,0,0,0,0,0,0,0,0,0,0,0,0,0,0,0,0,0,0,0,0,0,0,0,0,0,0,0,0,0,0
0,0,0,0,0,0,0,0,0,0,0,0,0,0,0,0,0,0,0,0,0,0,0,0,0,0,0,0,0,0,0,0,0,0,0,0,0,0,0,0,0
0,0,0,0,0,0,0,0,0,0,0,0,0,0,0,0,0,0,0,0,0,0,0,0,0,0,0,0,0,0,0,0,0,0,0,0,0,0,0,0,0
0,0,0,0,0,0,0,0,0,0,0,0,0,0,0,0,0,0,0,0,0,0,0,0,0,0,0,0,0,0,0,0,0,0,0,0,0,0,0,0,0
0,0,0,0,0,0,0,0,0,0,0,0,0,0,0,0,0,0,0,0,0,0,0,0,0,0,0,0,0,0,0,0,0,0,0,0,0,0,0,0,0
0,0,0,0,0,0,0,0,0,0,0,0,0,0,0,0,0,0,0,0,0,0,0,0,0,0,0,0,0,0,0,0,0,0,0,0,0,0,0,0,0
0,0,0,0,0,0,0,0,0,0,0,0,0,0,0,0,0,0,0,0,0,0,0,0,0,0,0,0,0,0,0,0,0,0,0,0,0,0,0,0,0
0,0,0,0,0,0,0,0,0,0,0,0,0,0,0,0,0,0,0,0,0,0,0,0,0,0,0,0,0,0,0,0,0,0,0,0,0,0,0,0,0
0,0,0,0,0,0,0,0,0,0,0,0,0,0,0,0,0,0,0,0,0,0,0,0,0,0,0,0,0,0,0,0,0,0,0,0,0,0,0,0,0
0,0,0,0,0,0,0,0,0,0,0,0,0,0,0,0,0,0,0,0,0,0,0,0,0,0,0,0,0,0,0,0,0,0,0,0,0,0,0,0,0
0,0,0,0,0,0,0,0,0,0,0,0,0,0,0,0,0,0,0,0,0,0,0,0,0,0,0,0,0,0,0,0,0,0,0,0,0,0,0,0,0
0,0,0,0,0,0,0,0,0,0,0,0,0,0,0,0,0,0,0,0,0,0,0,0,0,0,0,0,0,0,0,0,0,0,0,0,0,0,0,0,0
0,0,0,0,0,0,0,0,0,0,0,0,0,0,0,0,0,0,0,0,0,0,0,0,0,0,0,0,0,0,0,0,0,0,0,0,0,0,0,0,0
0,0,0,0,0,0,0,0,0,0,0,0,0,0,0,0,0,0,0,0,0,0,0,0,0,0,0,0,0,0,0,0,0,0,0,0,0,0,0,0,0
0,0,0,0,0,0,0,0,0,0,0,0,0,0,0,0,0,0,0,0,0,0,0,0,0,0,0,0,0,0,0,0,0,0,0,0,0,0,0,0,0
0,0,0,0,0,0,0,0,0,0,0,0,0,0,0,0,0,0,0,0,0,0,0,0,0,0,0,0,0,0,0,0,0,0,0,0,0,0,0,0,0
0,0,0,0,0,0,0,0,0,0,0,0,0,0,0,0,0,0,0,0,0,0,0,0,0,0,0,0,0,0,0,0,0,0,0,0,0,0,0,0,0
0,0,0,0,0,0,0,0,0,0,0,0,0,0,0,0,0,12,0,0,0,0,0,0,0,0,0,0,0,0,0,0,0,0,0,0,0,0,0,0,0
0,0,0,0,0,0,0,0,0,0,0,0,0,0,0,0,0,0,0,0,0,0,0,0,0,0,0,0,0,0,0,0,0,0,0,0,0,0,0,0,0
0,0,0,0,0,0,0,0,0,0,0,0,0,0,0,0,0,0,0,0,0,0,0,0,0,0,0,0,0,0,0,0,0,0,0,0,0,0,0,0,0
0,0,0,0,0,0,0,0,0,0,0,0,0,0,0,0,0,0,0,0,0,0,0,0,0,0,0,0,0,0,0,0,0,0,0,0,0,0,0,0,0
