# Ancient Warfare Structure Template File
# Auto-generated structure template file. created on: 8/19/2019 at: 10:23:10
# Lines beginning with # denote comments

header:
version=2.9
name=EmpireMineOpenCastHuge
mods=
size=54,106,54
offset=26,69,53
:endheader

#### VALIDATION ####
validation:
type=ground
survival=false
worldGenEnabled=true
unique=false
preserveBlocks=false
selectionWeight=100
clusterValue=50
minDuplicateDistance=1000
dimensionWhiteList=true
dimensionList=0
biomeWhiteList=true
biomeList=biomesoplenty:meadow,minecraft:extreme_hills,traverse:meadow,minecraft:forest_hills,minecraft:plains
leveling=12
fill=12
border=12
blockSwap=false
:endvalidation

#### LAYERS ####
layer: 0
1,1,1,1,1,1,1,1,1,1,1,1,1,1,1,1,1,1,1,1,1,1,1,1,1,1,1,1,1,1,1,1,1,1,1,1,1,1,1,1,1,1,1,1,1,1,1,1,1,1,1,1,1,1
1,1,1,1,1,1,1,1,1,1,1,1,1,1,1,1,1,1,1,1,1,1,1,1,1,1,1,1,1,1,1,1,1,1,1,1,1,1,1,1,1,1,1,1,1,1,1,1,1,1,1,1,1,1
1,1,1,1,1,1,1,1,1,1,1,1,1,1,1,1,1,1,1,1,1,1,1,1,1,1,1,1,1,1,1,1,1,1,1,1,1,1,1,1,1,1,1,1,1,1,1,1,1,1,1,1,1,1
1,1,1,1,1,1,1,1,1,1,1,1,1,1,1,1,1,1,1,1,1,1,1,1,1,1,1,1,1,1,1,1,1,1,1,1,1,1,1,1,1,1,1,1,1,1,1,1,1,1,1,1,1,1
1,1,1,1,1,1,1,1,1,1,1,1,1,1,1,1,1,1,1,1,1,1,1,1,1,1,1,1,1,1,1,1,1,1,1,1,1,1,1,1,1,1,1,1,1,1,1,1,1,1,1,1,1,1
1,1,1,1,1,1,1,1,1,1,1,1,1,1,1,1,1,1,1,1,1,1,1,1,1,1,1,1,1,1,1,1,1,1,1,1,1,1,1,1,1,1,1,1,1,1,1,1,1,1,1,1,1,1
1,1,1,1,1,1,1,1,1,1,1,1,1,1,1,1,1,1,1,1,1,1,1,1,1,1,1,1,1,1,1,1,1,1,1,1,1,1,1,1,1,1,1,1,1,1,1,1,1,1,1,1,1,1
1,1,1,1,1,1,1,1,1,1,1,1,1,1,1,1,1,1,1,1,1,1,1,1,1,1,1,1,1,1,1,1,1,1,1,1,1,1,1,1,1,1,1,1,1,1,1,1,1,1,1,1,1,1
1,1,1,1,1,1,1,1,1,1,1,1,1,1,1,1,1,1,1,1,1,1,1,1,1,1,1,1,1,1,1,1,1,1,1,1,1,1,1,1,1,1,1,1,1,1,1,1,1,1,1,1,1,1
1,1,1,1,1,1,1,1,1,1,1,1,1,1,1,1,1,1,1,1,1,1,1,1,1,1,1,1,1,1,1,1,1,1,1,1,1,1,1,1,1,1,1,1,1,1,1,1,1,1,1,1,1,1
1,1,1,1,1,1,1,1,1,1,1,1,1,1,1,1,1,1,1,1,1,1,1,1,1,1,1,1,1,1,1,1,1,1,1,1,1,1,1,1,1,1,1,1,1,1,1,1,1,1,1,1,1,1
1,1,1,1,1,1,1,1,1,1,1,1,1,1,1,1,1,1,1,1,1,1,1,1,1,1,1,1,1,1,1,1,1,1,1,1,1,1,1,1,1,1,1,1,1,1,1,1,1,1,1,1,1,1
1,1,1,1,1,1,1,1,1,1,1,1,1,1,1,1,1,1,1,1,1,1,1,1,1,1,1,1,1,1,1,1,1,1,1,1,1,1,1,1,1,1,1,1,1,1,1,1,1,1,1,1,1,1
1,1,1,1,1,1,1,1,1,1,1,1,1,1,1,1,1,1,1,1,1,1,1,1,1,1,1,1,1,1,1,1,1,1,1,1,1,1,1,1,1,1,1,1,1,1,1,1,1,1,1,1,1,1
1,1,1,1,1,1,1,1,1,1,1,1,1,1,1,1,1,1,1,1,1,1,1,1,1,1,1,1,1,1,1,1,1,1,1,1,1,1,1,1,1,1,1,1,1,1,1,1,1,1,1,1,1,1
1,1,1,1,1,1,1,1,1,1,1,1,1,1,1,1,1,1,1,1,1,1,1,1,1,1,1,1,1,1,1,1,1,1,1,1,1,1,1,1,1,1,1,1,1,1,1,1,1,1,1,1,1,1
1,1,1,1,1,1,1,1,1,1,1,1,1,1,1,1,1,1,1,1,1,1,1,1,1,1,1,1,1,1,1,1,1,1,1,1,1,1,1,1,1,1,1,1,1,1,1,1,1,1,1,1,1,1
1,1,1,1,1,1,1,1,1,1,1,1,1,1,1,1,1,1,1,1,1,1,1,1,1,1,1,1,1,1,1,1,1,1,1,1,1,1,1,1,1,1,1,1,1,1,1,1,1,1,1,1,1,1
1,1,1,1,1,1,1,1,1,1,1,1,1,1,1,1,1,1,1,1,1,1,1,1,1,1,1,1,1,1,1,1,1,1,1,1,1,1,1,1,1,1,1,1,1,1,1,1,1,1,1,1,1,1
1,1,1,1,1,1,1,1,1,1,1,1,1,1,1,1,1,1,1,1,1,1,1,1,1,1,1,1,1,1,1,1,1,1,1,1,1,1,1,1,1,1,1,1,1,1,1,1,1,1,1,1,1,1
1,1,1,1,1,1,1,1,1,1,1,1,1,1,1,1,1,1,1,1,1,1,1,1,1,1,1,1,1,1,1,1,1,1,1,1,1,1,1,1,1,1,1,1,1,1,1,1,1,1,1,1,1,1
1,1,1,1,1,1,1,1,1,1,1,1,1,1,1,1,1,1,1,1,1,1,1,1,1,1,1,1,1,1,1,1,1,1,1,1,1,1,1,1,1,1,1,1,1,1,1,1,1,1,1,1,1,1
1,1,1,1,1,1,1,1,1,1,1,1,1,1,1,1,1,1,1,1,1,1,1,1,1,1,1,1,1,1,1,1,1,1,1,1,1,1,1,1,1,1,1,1,1,1,1,1,1,1,1,1,1,1
1,1,1,1,1,1,1,1,1,1,1,1,1,1,1,1,1,1,1,1,1,1,1,1,1,1,1,1,1,1,1,1,1,1,1,1,1,1,1,1,1,1,1,1,1,1,1,1,1,1,1,1,1,1
1,1,1,1,1,1,1,1,1,1,1,1,1,1,1,1,1,1,1,1,1,1,1,1,1,1,1,1,1,1,1,1,1,1,1,1,1,1,1,1,1,1,1,1,1,1,1,1,1,1,1,1,1,1
1,1,1,1,1,1,1,1,1,1,1,1,1,1,1,1,1,1,1,1,1,1,1,1,1,1,1,1,1,1,1,1,1,1,1,1,1,1,1,1,1,1,1,1,1,1,1,1,1,1,1,1,1,1
1,1,1,1,1,1,1,1,1,1,1,1,1,1,1,1,1,1,1,1,1,1,1,1,1,1,1,1,1,1,1,1,1,1,1,1,1,1,1,1,1,1,1,1,1,1,1,1,1,1,1,1,1,1
1,1,1,1,1,1,1,1,1,1,1,1,1,1,1,1,1,1,1,1,1,1,1,1,1,1,1,1,1,1,1,1,1,1,1,1,1,1,1,1,1,1,1,1,1,1,1,1,1,1,1,1,1,1
1,1,1,1,1,1,1,1,1,1,1,1,1,1,1,1,1,1,1,1,1,1,1,1,1,1,1,1,1,1,1,1,1,1,1,1,1,1,1,1,1,1,1,1,1,1,1,1,1,1,1,1,1,1
1,1,1,1,1,1,1,1,1,1,1,1,1,1,1,1,1,1,1,1,1,1,1,1,1,1,1,1,1,1,1,1,1,1,1,1,1,1,1,1,1,1,1,1,1,1,1,1,1,1,1,1,1,1
1,1,1,1,1,1,1,1,1,1,1,1,1,1,1,1,1,1,1,1,1,1,1,1,1,1,1,1,1,1,1,1,1,1,1,1,1,1,1,1,1,1,1,1,1,1,1,1,1,1,1,1,1,1
1,1,1,1,1,1,1,1,1,1,1,1,1,1,1,1,1,1,1,1,1,1,1,1,1,1,1,1,1,1,1,1,1,1,1,1,1,1,1,1,1,1,1,1,1,1,1,1,1,1,1,1,1,1
1,1,1,1,1,1,1,1,1,1,1,1,1,1,1,1,1,1,1,1,1,1,1,1,1,1,1,1,1,1,1,1,1,1,1,1,1,1,1,1,1,1,1,1,1,1,1,1,1,1,1,1,1,1
1,1,1,1,1,1,1,1,1,1,1,1,1,1,1,1,1,1,1,1,1,1,1,1,1,1,1,1,1,1,1,1,1,1,1,1,1,1,1,1,1,1,1,1,1,1,1,1,1,1,1,1,1,1
1,1,1,1,1,1,1,1,1,1,1,1,1,1,1,1,1,1,1,1,1,1,1,1,1,1,1,1,1,1,1,1,1,1,1,1,1,1,1,1,1,1,1,1,1,1,1,1,1,1,1,1,1,1
1,1,1,1,1,1,1,1,1,1,1,1,1,1,1,1,1,1,1,1,1,1,1,1,1,1,1,1,1,1,1,1,1,1,1,1,1,1,1,1,1,1,1,1,1,1,1,1,1,1,1,1,1,1
1,1,1,1,1,1,1,1,1,1,1,1,1,1,1,1,1,1,1,1,1,1,1,1,1,1,1,1,1,1,1,1,1,1,1,1,1,1,1,1,1,1,1,1,1,1,1,1,1,1,1,1,1,1
1,1,1,1,1,1,1,1,1,1,1,1,1,1,1,1,1,1,1,1,1,1,1,1,1,1,1,1,1,1,1,1,1,1,1,1,1,1,1,1,1,1,1,1,1,1,1,1,1,1,1,1,1,1
1,1,1,1,1,1,1,1,1,1,1,1,1,1,1,1,1,1,1,1,1,1,1,1,1,1,1,1,1,1,1,1,1,1,1,1,1,1,1,1,1,1,1,1,1,1,1,1,1,1,1,1,1,1
1,1,1,1,1,1,1,1,1,1,1,1,1,1,1,1,1,1,1,1,1,1,1,1,1,1,1,1,1,1,1,1,1,1,1,1,1,1,1,1,1,1,1,1,1,1,1,1,1,1,1,1,1,1
1,1,1,1,1,1,1,1,1,1,1,1,1,1,1,1,1,1,1,1,1,1,1,1,1,1,1,1,1,1,1,1,1,1,1,1,1,1,1,1,1,1,1,1,1,1,1,1,1,1,1,1,1,1
1,1,1,1,1,1,1,1,1,1,1,1,1,1,1,1,1,1,1,1,1,1,1,1,1,1,1,1,1,1,1,1,1,1,1,1,1,1,1,1,1,1,1,1,1,1,1,1,1,1,1,1,1,1
1,1,1,1,1,1,1,1,1,1,1,1,1,1,1,1,1,1,1,1,1,1,1,1,1,1,1,1,1,1,1,1,1,1,1,1,1,1,1,1,1,1,1,1,1,1,1,1,1,1,1,1,1,1
1,1,1,1,1,1,1,1,1,1,1,1,1,1,1,1,1,1,1,1,1,1,1,1,1,1,1,1,1,1,1,1,1,1,1,1,1,1,1,1,1,1,1,1,1,1,1,1,1,1,1,1,1,1
1,1,1,1,1,1,1,1,1,1,1,1,1,1,1,1,1,1,1,1,1,1,1,1,1,1,1,1,1,1,1,1,1,1,1,1,1,1,1,1,1,1,1,1,1,1,1,1,1,1,1,1,1,1
1,1,1,1,1,1,1,1,1,1,1,1,1,1,1,1,1,1,1,1,1,1,1,1,1,1,1,1,1,1,1,1,1,1,1,1,1,1,1,1,1,1,1,1,1,1,1,1,1,1,1,1,1,1
1,1,1,1,1,1,1,1,1,1,1,1,1,1,1,1,1,1,1,1,1,1,1,1,1,1,1,1,1,1,1,1,1,1,1,1,1,1,1,1,1,1,1,1,1,1,1,1,1,1,1,1,1,1
1,1,1,1,1,1,1,1,1,1,1,1,1,1,1,1,1,1,1,1,1,1,1,1,1,1,1,1,1,1,1,1,1,1,1,1,1,1,1,1,1,1,1,1,1,1,1,1,1,1,1,1,1,1
1,1,1,1,1,1,1,1,1,1,1,1,1,1,1,1,1,1,1,1,1,1,1,1,1,1,1,1,1,1,1,1,1,1,1,1,1,1,1,1,1,1,1,1,1,1,1,1,1,1,1,1,1,1
1,1,1,1,1,1,1,1,1,1,1,1,1,1,1,1,1,1,1,1,1,1,1,1,1,1,1,1,1,1,1,1,1,1,1,1,1,1,1,1,1,1,1,1,1,1,1,1,1,1,1,1,1,1
1,1,1,1,1,1,1,1,1,1,1,1,1,1,1,1,1,1,1,1,1,1,1,1,1,1,1,1,1,1,1,1,1,1,1,1,1,1,1,1,1,1,1,1,1,1,1,1,1,1,1,1,1,1
1,1,1,1,1,1,1,1,1,1,1,1,1,1,1,1,1,1,1,1,1,1,1,1,1,1,1,1,1,1,1,1,1,1,1,1,1,1,1,1,1,1,1,1,1,1,1,1,1,1,1,1,1,1
1,1,1,1,1,1,1,1,1,1,1,1,1,1,1,1,1,1,1,1,1,1,1,1,1,1,1,1,1,1,1,1,1,1,1,1,1,1,1,1,1,1,1,1,1,1,1,1,1,1,1,1,1,1
1,1,1,1,1,1,1,1,1,1,1,1,1,1,1,1,1,1,1,1,1,1,1,1,1,1,1,1,1,1,1,1,1,1,1,1,1,1,1,1,1,1,1,1,1,1,1,1,1,1,1,1,1,1
:endlayer
layer: 1
1,1,1,1,1,1,1,1,1,1,1,1,1,1,1,1,1,1,1,1,1,1,1,1,1,1,1,1,1,1,1,1,1,1,1,1,1,1,1,1,1,1,1,1,1,1,1,1,1,1,1,1,1,1
1,1,1,1,1,1,1,1,1,1,1,1,1,1,1,1,1,1,1,1,1,1,1,1,1,1,1,1,1,1,1,1,1,1,1,1,1,1,1,1,1,1,1,1,1,1,1,1,1,1,1,1,1,1
1,1,1,1,1,1,1,1,1,1,1,1,1,1,1,1,1,1,1,1,1,1,1,1,1,1,1,1,1,1,1,1,1,1,1,1,1,1,1,1,1,1,1,1,1,1,1,1,1,1,1,1,1,1
1,1,1,1,1,1,1,1,1,1,1,1,1,1,1,1,1,1,1,1,1,1,1,1,1,1,1,1,1,1,1,1,1,1,1,1,1,1,1,1,1,1,1,1,1,1,1,1,1,1,1,1,1,1
1,1,1,1,1,1,1,1,1,1,1,1,1,1,1,1,1,1,1,1,1,1,1,1,1,1,1,1,1,1,1,1,1,1,1,1,1,1,1,1,1,1,1,1,1,1,1,1,1,1,1,1,1,1
1,1,1,1,1,1,1,1,1,1,1,1,1,1,1,1,1,1,1,1,1,1,1,1,1,1,1,1,1,1,1,1,1,1,1,1,1,1,1,1,1,1,1,1,1,1,1,1,1,1,1,1,1,1
1,1,1,1,1,1,1,1,1,1,1,1,1,1,1,1,1,1,1,1,1,1,1,1,1,1,1,1,1,1,1,1,1,1,1,1,1,1,1,1,1,1,1,1,1,1,1,1,1,1,1,1,1,1
1,1,1,1,1,1,1,1,1,1,1,1,1,1,1,1,1,1,1,1,1,1,1,1,1,1,1,1,1,1,1,1,1,1,1,1,1,1,1,1,1,1,1,1,1,1,1,1,1,1,1,1,1,1
1,1,1,1,1,1,1,1,1,1,1,1,1,1,1,1,1,1,1,1,1,1,1,1,1,1,1,1,1,1,1,1,1,1,1,1,1,1,1,1,1,1,1,1,1,1,1,1,1,1,1,1,1,1
1,1,1,1,1,1,1,1,1,1,1,1,1,1,1,1,1,1,1,1,1,1,1,1,1,1,1,1,1,1,1,1,1,1,1,1,1,1,1,1,1,1,1,1,1,1,1,1,1,1,1,1,1,1
1,1,1,1,1,1,1,1,1,1,1,1,1,1,1,1,1,1,1,1,1,1,1,1,1,1,1,1,1,1,1,1,1,1,1,1,1,1,1,1,1,1,1,1,1,1,1,1,1,1,1,1,1,1
1,1,1,1,1,1,1,1,1,1,1,1,1,1,1,1,1,1,1,1,1,1,1,1,1,1,1,1,1,1,1,1,1,1,1,1,1,1,1,1,1,1,1,1,1,1,1,1,1,1,1,1,1,1
1,1,1,1,1,1,1,1,1,1,1,1,1,1,1,1,1,1,1,1,1,1,1,1,1,1,1,1,1,1,1,1,1,1,1,1,1,1,1,1,1,1,1,1,1,1,1,1,1,1,1,1,1,1
1,1,1,1,1,1,1,1,1,1,1,1,1,1,1,1,1,1,1,1,1,1,1,1,1,1,1,1,1,1,1,1,1,1,1,1,1,1,1,1,1,1,1,1,1,1,1,1,1,1,1,1,1,1
1,1,1,1,1,1,1,1,1,1,1,1,1,1,1,1,1,1,1,1,1,1,1,1,1,1,1,1,1,1,1,1,1,1,1,1,1,1,1,1,1,1,1,1,1,1,1,1,1,1,1,1,1,1
1,1,1,1,1,1,1,1,1,1,1,1,1,1,1,1,1,1,1,1,1,1,1,1,1,1,1,1,1,1,1,1,1,1,1,1,1,1,1,1,1,1,1,1,1,1,1,1,1,1,1,1,1,1
1,1,1,1,1,1,1,1,1,1,1,1,1,1,1,1,1,1,1,1,1,1,1,1,1,1,1,1,1,1,1,1,1,1,1,1,1,1,1,1,1,1,1,1,1,1,1,1,1,1,1,1,1,1
1,1,1,1,1,1,1,1,1,1,1,1,1,1,1,1,1,1,1,1,1,1,1,1,1,1,1,1,1,1,1,1,1,1,1,1,1,1,1,1,1,1,1,1,1,1,1,1,1,1,1,1,1,1
1,1,1,1,1,1,1,1,1,1,1,1,1,1,1,1,1,1,1,1,1,1,1,1,1,1,1,1,1,1,1,1,1,1,1,1,1,1,1,1,1,1,1,1,1,1,1,1,1,1,1,1,1,1
1,1,1,1,1,1,1,1,1,1,1,1,1,1,1,1,1,1,1,1,1,1,1,1,1,1,1,1,1,1,1,1,1,1,1,1,1,1,1,1,1,1,1,1,1,1,1,1,1,1,1,1,1,1
1,1,1,1,1,1,1,1,1,1,1,1,1,1,1,1,1,1,1,1,1,1,1,1,1,1,1,1,1,1,1,1,1,1,1,1,1,1,1,1,1,1,1,1,1,1,1,1,1,1,1,1,1,1
1,1,1,1,1,1,1,1,1,1,1,1,1,1,1,1,1,1,1,1,1,1,1,1,1,1,1,1,1,1,1,1,1,1,1,1,1,1,1,1,1,1,1,1,1,1,1,1,1,1,1,1,1,1
1,1,1,1,1,1,1,1,1,1,1,1,1,1,1,1,1,1,1,1,1,1,1,1,1,1,1,1,1,1,1,1,1,1,1,1,1,1,1,1,1,1,1,1,1,1,1,1,1,1,1,1,1,1
1,1,1,1,1,1,1,1,1,1,1,1,1,1,1,1,1,1,1,1,1,1,1,1,1,1,1,1,1,1,1,1,1,1,1,1,1,1,1,1,1,1,1,1,1,1,1,1,1,1,1,1,1,1
1,1,1,1,1,1,1,1,1,1,1,1,1,1,1,1,1,1,1,1,1,1,1,1,1,1,1,1,1,1,1,1,1,1,1,1,1,1,1,1,1,1,1,1,1,1,1,1,1,1,1,1,1,1
1,1,1,1,1,1,1,1,1,1,1,1,1,1,1,1,1,1,1,1,1,1,1,1,1,1,1,1,1,1,1,1,1,1,1,1,1,1,1,1,1,1,1,1,1,1,1,1,1,1,1,1,1,1
1,1,1,1,1,1,1,1,1,1,1,1,1,1,1,1,1,1,1,1,1,1,1,1,1,1,1,1,1,1,1,1,1,1,1,1,1,1,1,1,1,1,1,1,1,1,1,1,1,1,1,1,1,1
1,1,1,1,1,1,1,1,1,1,1,1,1,1,1,1,1,1,1,1,1,1,1,1,1,1,1,1,1,1,1,1,1,1,1,1,1,1,1,1,1,1,1,1,1,1,1,1,1,1,1,1,1,1
1,1,1,1,1,1,1,1,1,1,1,1,1,1,1,1,1,1,1,1,1,1,1,1,1,1,1,1,1,1,1,1,1,1,1,1,1,1,1,1,1,1,1,1,1,1,1,1,1,1,1,1,1,1
1,1,1,1,1,1,1,1,1,1,1,1,1,1,1,1,1,1,1,1,1,1,1,1,1,1,1,1,1,1,1,1,1,1,1,1,1,1,1,1,1,1,1,1,1,1,1,1,1,1,1,1,1,1
1,1,1,1,1,1,1,1,1,1,1,1,1,1,1,1,1,1,1,1,1,1,1,1,1,1,1,1,1,1,1,1,1,1,1,1,1,1,1,1,1,1,1,1,1,1,1,1,1,1,1,1,1,1
1,1,1,1,1,1,1,1,1,1,1,1,1,1,1,1,1,1,1,1,1,1,1,1,1,1,1,1,1,1,1,1,1,1,1,1,1,1,1,1,1,1,1,1,1,1,1,1,1,1,1,1,1,1
1,1,1,1,1,1,1,1,1,1,1,1,1,1,1,1,1,1,1,1,1,1,1,1,1,1,1,1,1,1,1,1,1,1,1,1,1,1,1,1,1,1,1,1,1,1,1,1,1,1,1,1,1,1
1,1,1,1,1,1,1,1,1,1,1,1,1,1,1,1,1,1,1,1,1,1,1,1,1,1,1,1,1,1,1,1,1,1,1,1,1,1,1,1,1,1,1,1,1,1,1,1,1,1,1,1,1,1
1,1,1,1,1,1,1,1,1,1,1,1,1,1,1,1,1,1,1,1,1,1,1,1,1,1,1,1,1,1,1,1,1,1,1,1,1,1,1,1,1,1,1,1,1,1,1,1,1,1,1,1,1,1
1,1,1,1,1,1,1,1,1,1,1,1,1,1,1,1,1,1,1,1,1,1,1,1,1,1,1,1,1,1,1,1,1,1,1,1,1,1,1,1,1,1,1,1,1,1,1,1,1,1,1,1,1,1
1,1,1,1,1,1,1,1,1,1,1,1,1,1,1,1,1,1,1,1,1,1,1,1,1,1,1,1,1,1,1,1,1,1,1,1,1,1,1,1,1,1,1,1,1,1,1,1,1,1,1,1,1,1
1,1,1,1,1,1,1,1,1,1,1,1,1,1,1,1,1,1,1,1,1,1,1,1,1,1,1,1,1,1,1,1,1,1,1,1,1,1,1,1,1,1,1,1,1,1,1,1,1,1,1,1,1,1
1,1,1,1,1,1,1,1,1,1,1,1,1,1,1,1,1,1,1,1,1,1,1,1,1,1,1,1,1,1,1,1,1,1,1,1,1,1,1,1,1,1,1,1,1,1,1,1,1,1,1,1,1,1
1,1,1,1,1,1,1,1,1,1,1,1,1,1,1,1,1,1,1,1,1,1,1,1,1,1,1,1,1,1,1,1,1,1,1,1,1,1,1,1,1,1,1,1,1,1,1,1,1,1,1,1,1,1
1,1,1,1,1,1,1,1,1,1,1,1,1,1,1,1,1,1,1,1,1,1,1,1,1,1,1,1,1,1,1,1,1,1,1,1,1,1,1,1,1,1,1,1,1,1,1,1,1,1,1,1,1,1
1,1,1,1,1,1,1,1,1,1,1,1,1,1,1,1,1,1,1,1,1,1,1,1,1,1,1,1,1,1,1,1,1,1,1,1,1,1,1,1,1,1,1,1,1,1,1,1,1,1,1,1,1,1
1,1,1,1,1,1,1,1,1,1,1,1,1,1,1,1,1,1,1,1,1,1,1,1,1,1,1,1,1,1,1,1,1,1,1,1,1,1,1,1,1,1,1,1,1,1,1,1,1,1,1,1,1,1
1,1,1,1,1,1,1,1,1,1,1,1,1,1,1,1,1,1,1,1,1,1,1,1,1,1,1,1,1,1,1,1,1,1,1,1,1,1,1,1,1,1,1,1,1,1,1,1,1,1,1,1,1,1
1,1,1,1,1,1,1,1,1,1,1,1,1,1,1,1,1,1,1,1,1,1,1,1,1,1,1,1,1,1,1,1,1,1,1,1,1,1,1,1,1,1,1,1,1,1,1,1,1,1,1,1,1,1
1,1,1,1,1,1,1,1,1,1,1,1,1,1,1,1,1,1,1,1,1,1,1,1,1,1,1,1,1,1,1,1,1,1,1,1,1,1,1,1,1,1,1,1,1,1,1,1,1,1,1,1,1,1
1,1,1,1,1,1,1,1,1,1,1,1,1,1,1,1,1,1,1,1,1,1,1,1,1,1,1,1,1,1,1,1,1,1,1,1,1,1,1,1,1,1,1,1,1,1,1,1,1,1,1,1,1,1
1,1,1,1,1,1,1,1,1,1,1,1,1,1,1,1,1,1,1,1,1,1,1,1,1,1,1,1,1,1,1,1,1,1,1,1,1,1,1,1,1,1,1,1,1,1,1,1,1,1,1,1,1,1
1,1,1,1,1,1,1,1,1,1,1,1,1,1,1,1,1,1,1,1,1,1,1,1,1,1,1,1,1,1,1,1,1,1,1,1,1,1,1,1,1,1,1,0,1,1,1,1,1,1,1,1,1,1
1,1,1,1,1,1,1,1,1,1,1,1,1,1,1,1,1,1,1,1,1,1,1,1,1,1,1,1,1,1,1,1,1,1,1,1,1,1,1,1,1,1,1,1,1,1,1,1,1,1,1,1,1,1
1,1,1,1,1,1,1,1,1,1,1,1,1,1,1,1,1,1,1,1,1,1,1,1,1,1,1,1,1,1,1,1,1,1,1,1,1,1,1,1,1,1,1,1,1,1,1,1,1,1,1,1,1,1
1,1,1,1,1,1,1,1,1,1,1,1,1,1,1,1,1,1,1,1,1,1,1,1,1,1,1,1,1,1,1,1,1,1,1,1,1,1,1,1,1,1,1,1,1,1,1,1,1,1,1,1,1,1
1,1,1,1,1,1,1,1,1,1,1,1,1,1,1,1,1,1,1,1,1,1,1,1,1,1,1,1,1,1,1,1,1,1,1,1,1,1,1,1,1,1,1,1,1,1,1,1,1,1,1,1,1,1
1,1,1,1,1,1,1,1,1,1,1,1,1,1,1,1,1,1,1,1,1,1,1,1,1,1,1,1,1,1,1,1,1,1,1,1,1,1,1,1,1,1,1,1,1,1,1,1,1,1,1,1,1,1
:endlayer
layer: 2
1,1,1,1,1,2,2,2,2,2,1,1,2,1,2,1,1,2,2,2,2,3,2,1,1,1,1,1,1,2,1,2,1,3,2,1,2,2,1,2,1,1,2,1,2,2,2,2,2,2,1,2,1,1
1,1,1,1,1,2,1,1,1,2,2,1,2,2,2,2,2,1,1,2,1,1,2,2,2,1,1,2,1,1,1,2,1,3,2,1,2,1,2,2,2,2,1,2,1,2,2,1,2,1,1,1,1,2
1,1,1,1,1,1,2,2,2,1,2,1,2,1,1,1,2,2,2,2,1,2,1,2,1,2,1,2,2,2,1,1,2,1,2,2,1,2,1,1,2,2,2,2,1,1,2,1,1,1,2,1,1,1
1,1,1,1,1,1,2,2,1,2,1,2,2,1,2,2,2,2,1,1,2,2,1,1,1,2,2,2,2,1,1,2,1,1,1,2,1,1,2,1,2,2,2,2,2,1,1,2,1,2,2,4,4,1
1,1,1,1,1,1,2,2,2,1,1,1,1,1,2,2,2,2,2,2,2,1,1,1,2,1,1,2,1,2,2,1,2,2,2,1,1,2,2,1,2,1,2,1,2,2,2,1,1,1,1,4,4,2
1,1,1,1,1,5,6,1,1,1,5,1,1,6,6,6,1,6,1,1,2,1,1,1,2,1,1,1,2,2,1,1,2,2,6,6,6,1,7,1,7,1,2,1,2,1,2,1,1,2,2,1,1,2
1,1,1,1,1,1,5,1,1,5,1,1,1,6,6,1,6,6,1,1,6,1,1,2,2,2,2,1,2,2,2,2,2,2,6,6,6,7,1,1,7,1,7,1,1,2,2,2,1,2,2,1,1,1
1,1,1,1,1,5,1,2,5,5,1,5,6,1,1,6,1,1,1,1,6,6,1,6,2,2,1,2,2,2,2,1,2,1,6,6,6,7,7,1,7,7,7,7,2,1,2,1,1,1,1,2,2,2
1,1,1,1,1,2,1,1,1,1,1,1,1,6,2,6,1,6,6,1,1,6,6,1,1,6,1,1,1,1,1,6,6,1,6,6,1,7,1,1,1,7,7,2,2,1,2,2,2,1,2,1,1,1
1,1,1,1,1,1,1,2,1,1,2,2,1,1,2,1,1,2,2,6,6,6,1,6,6,1,6,1,6,6,6,1,6,6,6,1,6,1,6,2,1,2,1,1,2,1,2,1,2,2,2,2,2,1
1,1,1,1,1,2,2,1,1,2,2,1,2,1,1,2,2,1,1,2,2,1,6,6,6,6,6,1,6,1,6,6,6,6,6,1,6,6,6,1,2,2,2,2,2,1,1,2,1,1,2,2,2,2
1,1,1,1,1,2,1,2,1,2,1,2,1,2,1,1,1,2,2,2,1,2,1,2,1,1,2,6,6,6,1,6,6,1,6,6,6,6,4,6,1,2,2,2,2,1,1,1,2,1,2,2,2,1
1,1,1,1,1,1,1,2,2,1,2,2,2,1,1,2,2,1,2,2,1,2,2,2,2,2,2,2,2,2,2,2,2,1,1,6,6,6,4,1,6,6,2,2,1,1,1,2,2,2,1,2,2,1
1,1,1,1,1,1,1,2,2,1,1,2,1,1,2,1,1,2,2,2,2,2,2,2,2,1,2,1,2,1,2,2,2,1,1,1,6,6,1,2,1,6,6,2,2,1,1,1,1,2,1,2,2,1
1,1,1,1,1,2,2,2,2,1,2,1,2,1,1,1,2,1,1,1,2,2,1,1,2,2,1,1,1,2,1,1,2,2,6,6,6,6,2,2,2,2,1,1,2,1,2,2,1,1,2,2,1,1
1,1,1,1,1,1,1,2,2,1,2,2,2,1,1,2,2,2,1,1,2,2,2,1,2,1,2,2,1,2,1,2,1,1,1,1,6,1,6,2,1,2,2,1,1,2,1,1,1,2,1,2,1,2
1,1,1,1,1,2,2,2,2,2,2,1,2,2,2,2,1,1,2,1,2,1,1,2,2,1,1,2,1,1,1,2,2,2,2,6,1,6,6,2,1,1,1,6,1,2,1,2,2,2,1,2,2,2
1,1,1,1,1,2,2,2,2,2,2,2,2,1,1,2,2,2,2,1,2,1,1,1,2,2,1,1,1,2,2,2,2,2,2,6,1,1,6,2,2,2,1,2,1,1,2,1,2,2,2,1,1,2
1,1,1,1,1,1,1,1,2,2,2,2,2,2,1,2,1,1,1,1,2,2,1,2,1,2,2,1,1,1,2,2,2,2,2,2,6,1,6,1,2,1,1,2,2,2,2,1,1,2,2,2,2,1
1,1,1,1,1,1,2,1,1,1,2,2,1,1,2,2,1,1,2,2,1,2,2,1,2,2,2,2,2,1,2,2,1,2,2,2,6,6,1,2,1,2,1,4,1,6,4,2,6,1,1,2,2,1
1,1,1,1,1,8,1,1,1,1,2,1,2,1,1,2,1,1,2,1,1,2,2,2,1,2,2,1,1,2,1,2,1,2,3,3,2,2,2,2,2,1,1,1,4,4,4,2,1,1,1,2,2,2
1,1,1,1,1,1,6,6,9,2,1,2,2,10,2,2,2,1,2,1,1,2,1,2,2,1,2,2,1,4,1,7,1,1,3,3,2,2,1,2,1,2,2,2,1,1,2,1,1,6,1,2,1,2
1,1,1,1,1,6,1,6,1,2,2,2,2,2,1,1,1,1,2,1,2,1,2,1,2,2,2,2,1,7,7,1,7,2,1,2,2,2,2,1,2,1,2,1,6,1,1,1,3,2,2,3,2,2
1,1,1,1,1,6,2,1,2,2,2,1,2,2,1,1,1,2,1,2,1,1,2,2,1,2,2,2,2,1,1,7,1,1,2,2,1,2,2,2,1,1,2,1,1,6,2,3,3,1,2,2,2,1
1,1,1,1,1,6,1,2,1,2,1,1,2,2,1,2,2,1,2,2,1,1,1,1,2,2,1,1,1,7,1,7,7,2,2,1,2,2,2,2,2,1,1,2,6,6,1,2,2,2,2,2,1,1
1,1,1,1,1,1,2,2,2,1,1,2,2,2,1,2,2,2,1,1,2,1,2,2,2,2,2,2,2,7,7,7,1,1,2,2,1,1,2,2,6,1,6,6,6,6,1,2,2,1,2,2,6,6
1,1,1,1,1,1,2,2,1,2,1,1,1,2,1,2,2,2,2,1,2,2,1,2,1,2,2,1,2,1,7,1,1,2,2,2,2,2,1,6,6,1,6,1,2,1,2,1,2,6,6,1,1,1
1,1,1,1,1,3,2,1,2,2,2,1,2,2,1,2,1,2,1,2,2,2,1,1,1,2,2,1,1,7,7,7,1,2,1,1,2,2,1,6,1,1,6,1,2,2,1,2,1,6,1,6,6,1
1,1,1,1,1,3,1,1,1,1,2,1,2,2,2,2,1,1,2,2,1,2,1,1,3,2,1,2,1,7,7,1,7,2,2,1,1,1,2,1,1,1,6,1,1,2,2,2,6,6,6,6,1,2
1,1,1,1,1,2,2,2,2,2,6,1,2,2,1,2,2,2,2,2,2,7,2,3,3,1,1,1,2,2,1,7,2,1,2,2,2,2,2,1,6,6,1,6,2,1,1,1,1,6,6,1,2,2
1,1,1,1,1,2,1,1,1,6,6,1,1,2,2,2,2,2,2,2,1,7,7,7,2,1,2,1,2,2,2,2,1,2,2,2,1,2,6,2,2,6,6,1,2,1,2,1,1,1,1,2,2,2
1,1,1,1,1,2,2,2,2,1,6,1,1,1,2,2,1,2,1,2,2,7,1,1,7,2,2,1,2,2,1,2,2,2,1,1,2,6,1,1,2,2,1,1,2,2,2,1,1,2,2,2,2,1
1,1,1,1,1,1,1,1,1,6,1,6,2,1,1,1,2,1,1,1,1,7,7,1,7,2,1,2,2,1,1,2,2,1,2,2,1,6,1,1,2,1,1,1,2,2,1,2,2,1,2,2,2,1
1,1,1,1,1,1,1,2,1,2,2,2,1,1,1,1,1,2,2,2,1,1,7,1,7,1,2,1,1,1,2,2,2,1,1,2,1,6,6,2,1,2,2,2,2,2,3,2,1,1,1,1,2,2
1,1,1,1,1,1,1,2,2,2,2,2,2,2,2,1,2,2,2,2,2,1,2,2,1,1,2,2,2,2,1,2,2,2,2,1,6,1,6,2,2,2,2,2,2,1,1,1,1,2,1,2,2,2
1,1,1,1,1,2,2,2,1,2,2,1,2,1,2,2,1,2,2,1,1,2,2,1,1,4,1,1,1,1,2,1,2,2,1,2,6,1,6,1,2,2,1,2,2,2,2,2,1,1,2,2,2,2
1,1,1,1,1,2,1,1,2,2,2,2,2,2,1,1,1,2,1,1,2,1,2,2,4,4,2,1,2,2,1,9,1,2,1,1,1,6,1,6,2,1,2,1,1,2,2,1,2,2,5,1,1,5
1,1,1,1,1,1,1,2,1,1,2,1,1,2,2,1,1,2,2,2,1,1,2,1,1,1,2,1,1,2,2,2,2,1,2,2,1,2,2,2,2,2,2,2,2,2,2,5,1,5,1,1,5,5
1,1,1,1,1,1,2,1,1,2,1,1,2,2,1,2,1,2,2,2,2,1,2,1,1,1,2,1,2,1,1,2,2,2,2,1,2,1,2,1,2,2,1,1,1,1,2,5,5,5,5,5,5,3
1,1,1,1,1,2,2,2,2,2,2,2,2,2,2,1,2,1,2,2,2,1,2,2,2,1,2,1,1,2,2,2,2,1,1,1,2,1,2,1,2,1,2,2,2,2,2,7,1,1,1,7,2,2
1,1,1,1,1,1,2,2,1,1,1,2,8,2,8,2,2,2,2,2,1,1,2,2,2,1,1,1,1,7,1,1,2,1,2,2,1,2,1,2,2,2,2,1,1,7,1,7,7,7,1,1,1,2
1,1,1,1,1,2,2,2,2,1,2,2,2,1,2,2,2,2,2,1,1,2,2,7,1,7,7,7,7,7,7,7,2,1,1,4,1,2,1,2,2,2,1,2,1,1,7,1,1,1,7,1,1,2
1,1,1,1,1,2,1,1,1,2,1,2,2,1,2,2,1,2,2,1,1,1,1,1,7,7,7,7,7,1,1,2,2,1,4,4,2,1,1,1,1,2,2,1,1,1,7,1,7,1,1,1,1,2
1,1,1,1,1,2,2,2,1,2,2,2,2,1,1,2,1,1,1,2,2,1,2,1,7,1,7,1,7,1,1,2,1,1,4,4,2,2,2,2,2,2,1,1,7,1,1,1,1,1,2,1,2,2
1,1,1,1,1,2,1,1,2,1,2,2,2,2,1,1,2,2,2,2,2,2,1,2,7,7,2,1,2,2,1,2,1,2,2,2,1,2,1,2,1,2,2,2,2,2,1,2,2,2,1,1,1,2
1,1,1,1,1,2,2,2,1,1,2,1,2,1,2,2,1,2,2,2,1,1,2,1,2,2,2,2,2,1,1,2,1,1,1,2,1,2,1,1,2,1,1,2,1,1,2,1,1,2,1,2,2,2
1,1,1,1,1,1,1,1,2,1,2,2,1,2,1,1,2,1,2,2,2,1,2,1,2,2,2,2,2,1,2,1,1,2,1,1,1,2,2,1,2,1,2,1,1,1,2,2,2,2,2,2,2,2
1,1,1,1,1,2,2,1,2,2,1,2,1,2,2,2,1,2,2,2,2,2,5,5,5,2,2,2,2,2,2,1,2,2,1,1,2,2,2,2,2,2,2,1,2,1,1,2,1,1,1,2,2,2
1,1,1,1,1,2,2,2,2,2,2,1,1,2,1,1,1,1,2,1,2,2,1,1,5,2,2,1,2,2,2,2,1,1,1,1,1,2,2,3,2,2,2,0,2,1,2,1,1,2,1,2,2,2
1,1,1,1,1,1,2,2,2,1,1,2,1,1,1,1,2,1,2,2,2,2,2,5,5,2,2,2,1,1,2,2,2,1,1,2,2,1,1,2,1,2,1,2,2,1,2,2,1,1,2,2,2,2
1,1,1,1,1,2,2,2,1,1,2,2,2,2,2,1,2,2,1,1,2,2,1,5,1,1,2,2,2,2,2,1,1,1,1,2,1,2,1,2,2,1,1,2,1,2,1,1,2,1,1,2,1,2
1,1,1,1,1,1,1,1,1,1,1,1,1,1,1,1,1,1,1,1,1,1,1,1,1,1,1,1,1,1,1,1,1,1,1,1,1,1,1,1,1,1,1,1,1,1,1,1,1,1,1,1,1,1
1,1,1,1,1,1,1,1,1,1,1,1,1,1,1,1,1,1,1,1,1,1,1,1,1,1,1,1,1,1,1,1,1,1,1,1,1,1,1,1,1,1,1,1,1,1,1,1,1,1,1,1,1,1
1,1,1,1,1,1,1,1,1,1,1,1,1,1,1,1,1,1,1,1,1,1,1,1,1,1,1,1,1,1,1,1,1,1,1,1,1,1,1,1,1,1,1,1,1,1,1,1,1,1,1,1,1,1
:endlayer
layer: 3
2,2,2,2,2,2,2,2,2,2,2,2,2,2,2,2,2,1,1,2,2,2,2,2,2,2,2,2,2,2,2,2,1,2,2,2,5,5,5,5,5,2,2,2,2,2,2,1,1,1,1,2,2,2
2,2,2,2,2,2,2,2,2,2,2,1,2,2,1,1,2,2,2,2,1,2,1,2,2,2,2,3,2,2,1,2,2,2,2,2,5,5,5,2,2,2,1,1,1,1,2,1,2,2,2,4,4,2
2,2,2,2,2,2,2,2,2,2,1,2,2,2,2,2,2,1,2,2,2,2,2,2,2,1,2,1,6,1,2,2,1,2,1,1,2,2,2,2,2,2,1,2,1,2,2,1,2,1,2,4,4,2
2,2,2,2,2,1,1,2,1,2,2,2,2,2,2,1,2,2,2,2,2,1,2,2,2,2,2,2,1,1,1,1,2,2,2,1,1,2,2,2,2,2,2,2,2,2,2,2,2,2,2,4,1,1
2,2,2,2,1,2,2,2,1,2,2,1,2,1,1,1,1,1,1,2,2,2,2,2,2,2,2,2,6,6,2,2,1,2,2,2,2,1,2,2,2,1,2,2,2,2,2,1,2,1,1,4,4,2
2,2,2,2,6,6,6,6,6,5,5,5,6,6,6,6,6,1,1,2,2,2,1,2,1,2,2,2,2,2,2,2,2,2,2,2,2,2,2,2,2,2,2,1,2,2,2,2,1,1,1,1,1,2
2,2,2,2,6,6,5,1,6,5,5,1,1,6,1,6,6,6,6,6,6,1,1,2,2,2,2,2,2,2,2,2,1,2,2,2,2,1,7,1,7,2,2,2,1,2,1,2,2,2,2,4,1,2
2,2,2,2,5,1,5,5,6,5,1,5,6,6,1,6,6,6,6,6,6,6,2,2,1,2,2,2,2,2,2,2,2,2,1,2,2,1,1,7,7,7,2,2,2,2,2,1,2,2,2,8,8,2
2,2,2,2,1,5,5,5,5,2,2,1,2,1,1,1,2,2,2,6,6,6,6,6,2,2,2,1,2,2,2,1,2,2,2,2,2,4,1,2,2,2,2,2,2,2,1,2,2,1,1,2,2,1
2,2,2,2,2,2,2,2,2,2,2,2,2,1,2,2,2,2,2,2,2,6,6,6,6,6,2,6,2,2,2,2,2,1,2,2,2,1,4,1,1,1,2,2,2,1,1,1,2,2,2,2,1,2
2,2,2,2,2,2,2,2,1,2,2,1,1,2,2,2,2,2,1,2,1,2,2,1,3,3,2,1,2,3,2,2,1,2,2,6,2,4,4,2,2,2,2,2,2,2,2,2,2,2,2,1,2,2
2,2,2,2,2,2,2,2,2,2,1,2,2,1,2,2,2,2,2,2,2,2,2,1,2,1,2,2,1,3,2,1,1,1,2,2,2,2,2,1,1,1,2,2,1,1,2,1,2,2,1,2,2,2
2,2,2,2,2,1,2,1,2,2,1,2,2,2,2,2,2,2,2,2,1,2,2,2,1,2,2,2,1,1,1,1,2,2,2,1,1,2,2,2,2,2,2,2,2,2,2,1,2,2,2,2,2,2
2,2,2,2,2,2,2,2,1,1,2,2,2,2,2,2,2,2,2,2,2,2,1,2,1,2,2,2,2,2,2,1,2,2,2,6,6,6,2,2,2,2,2,1,2,2,2,2,2,2,2,2,2,2
2,2,2,2,2,1,2,2,2,2,2,2,2,2,2,2,2,2,2,1,2,2,2,2,2,2,2,2,2,2,2,2,2,2,2,6,6,6,2,2,2,2,2,2,1,2,2,2,1,1,2,2,2,1
2,2,2,2,1,2,2,2,2,2,2,2,1,2,2,2,1,2,2,2,2,2,2,2,1,2,2,2,1,2,1,2,1,2,2,6,6,1,1,2,2,2,2,2,2,2,6,6,2,2,1,2,2,2
2,2,2,2,2,1,2,1,2,1,1,2,2,2,2,2,1,2,2,2,2,1,1,2,1,2,2,2,2,2,2,2,2,2,1,1,6,1,6,2,2,1,1,2,6,6,1,6,6,2,2,2,2,2
2,2,2,2,1,2,2,2,2,2,1,2,1,2,2,2,2,2,2,2,2,2,1,2,2,2,2,2,2,1,2,2,2,2,2,1,6,6,6,1,2,2,2,2,6,6,6,6,6,2,1,1,2,1
2,2,2,2,1,1,2,2,2,2,2,2,2,1,2,2,2,2,1,2,2,2,2,1,2,2,2,2,2,2,2,2,2,1,2,6,6,6,1,2,2,2,2,2,6,6,6,6,6,2,2,2,2,1
2,2,2,2,2,2,2,2,2,2,2,1,2,2,2,1,1,2,1,2,2,2,2,2,2,2,2,1,2,1,2,2,2,2,2,6,6,6,6,2,2,2,2,4,6,6,6,2,2,2,2,2,2,1
2,2,0,0,2,1,1,9,2,2,2,2,1,2,1,1,2,2,1,2,2,2,2,2,2,2,2,2,2,2,2,1,2,2,2,2,5,6,6,2,2,2,2,1,6,4,1,4,2,2,1,2,1,2
2,2,0,0,6,6,6,6,9,2,2,2,2,2,2,2,2,2,2,2,2,2,2,2,2,1,2,1,2,4,4,4,2,2,2,3,2,2,1,2,1,2,2,2,6,6,6,1,2,2,2,2,1,2
2,2,0,0,1,6,6,6,2,2,2,1,2,2,2,1,2,2,1,2,2,2,1,2,2,1,2,2,2,4,4,4,2,2,1,2,1,1,2,1,1,2,2,2,6,6,6,2,2,2,2,2,1,2
2,2,0,11,6,6,6,1,1,2,2,2,2,2,2,2,2,2,2,1,1,2,2,2,1,2,3,2,2,1,2,1,2,1,2,2,2,2,2,1,2,2,1,2,6,6,1,2,3,2,2,1,2,1
2,2,0,11,6,6,2,1,2,2,2,1,2,2,2,2,2,2,2,2,1,2,2,2,2,2,3,3,1,7,7,7,2,2,2,1,2,2,2,2,2,2,2,2,6,6,2,2,2,2,2,1,2,2
2,2,0,12,5,2,1,1,2,2,2,2,2,2,2,2,2,2,2,2,9,1,1,2,2,2,1,2,2,7,7,7,7,2,2,1,2,2,2,2,1,2,2,6,1,2,1,2,2,2,2,2,2,1
2,2,0,0,2,2,2,2,2,1,2,1,2,2,2,2,2,1,1,1,2,2,2,2,2,2,1,2,2,7,7,1,1,2,1,2,1,1,2,2,6,6,6,6,2,2,2,2,1,1,6,6,6,1
2,2,0,0,3,2,2,2,2,2,2,2,1,1,2,2,2,1,1,2,2,2,2,2,3,1,2,2,2,7,1,7,1,1,2,2,2,2,2,2,6,6,6,6,2,2,2,6,6,6,6,6,6,6
2,2,0,0,2,1,2,2,2,2,2,2,2,2,1,1,2,1,2,2,2,2,2,2,3,3,2,2,2,7,7,7,7,2,2,2,2,2,2,2,6,6,6,6,2,2,6,6,6,6,6,6,6,6
2,2,0,0,2,1,2,2,2,6,1,6,2,2,2,2,1,2,2,2,2,1,7,2,2,1,2,2,1,2,7,7,2,2,2,2,1,2,2,2,6,6,6,6,2,1,6,6,6,6,6,2,6,6
2,2,0,0,2,2,1,2,2,1,6,6,6,2,2,1,2,1,2,2,2,1,7,7,7,2,2,2,2,2,2,2,1,2,2,2,2,2,2,2,1,2,2,1,1,2,6,6,6,6,2,1,2,2
2,2,2,2,2,2,1,1,2,6,1,6,6,1,1,2,2,2,1,2,2,7,7,7,7,7,2,2,1,2,1,2,2,2,2,2,1,2,2,2,2,2,2,2,2,2,2,2,2,2,2,1,2,2
2,2,2,2,2,2,2,1,2,6,1,6,2,2,2,2,2,2,2,2,2,7,7,7,7,1,2,1,2,1,2,10,1,2,2,2,2,2,2,2,2,2,2,2,2,1,2,1,1,2,1,2,2,2
2,2,2,2,2,2,2,2,2,1,1,2,1,2,2,2,1,2,2,2,2,2,7,1,7,7,1,1,1,2,2,10,10,2,2,2,2,2,2,2,2,2,2,2,2,2,3,2,2,2,1,1,2,2
2,2,2,2,2,1,2,2,1,1,2,2,2,2,2,1,2,2,2,2,2,2,1,1,7,7,7,1,8,2,1,1,2,2,1,2,1,1,2,1,1,2,2,2,1,2,2,3,2,2,1,2,2,2
2,2,2,2,2,2,2,2,2,2,1,1,1,2,1,2,2,2,2,2,2,1,2,7,1,7,7,8,8,1,2,9,2,1,2,2,2,1,2,2,2,2,2,2,1,2,2,1,2,2,2,2,2,2
2,2,2,2,2,2,2,2,2,2,2,3,1,2,2,2,2,2,2,2,2,2,2,1,1,4,2,2,2,2,2,9,2,1,2,2,2,2,2,2,1,2,2,2,1,2,2,2,2,1,1,2,2,2
2,2,2,2,2,2,1,1,2,2,2,1,2,1,2,2,2,2,2,2,2,2,2,2,4,1,2,2,2,2,2,2,2,1,1,2,2,2,2,1,1,1,6,6,6,1,2,2,2,2,3,3,2,1
2,2,2,2,2,2,2,2,2,2,1,2,2,2,2,2,1,2,2,1,2,2,2,2,2,2,2,1,2,2,2,2,2,2,2,2,2,2,2,2,2,6,6,6,6,1,2,2,2,2,3,2,2,2
2,2,2,2,1,4,2,2,1,1,2,8,8,8,1,2,2,2,2,2,1,1,2,2,2,1,2,1,2,1,2,2,2,2,1,2,2,2,2,2,2,2,1,6,6,6,2,2,2,1,2,1,3,2
2,2,2,2,1,4,2,2,1,2,2,8,8,8,8,2,2,2,2,2,2,2,2,2,2,1,7,7,7,1,7,7,2,2,2,1,2,2,2,1,2,2,2,2,2,2,2,2,7,7,1,2,2,2
2,2,2,2,2,1,2,1,1,1,2,2,1,2,2,2,2,2,2,1,2,1,1,2,7,7,7,1,7,7,1,7,2,2,1,4,1,2,1,2,2,2,2,2,1,2,7,1,7,7,1,1,2,2
2,2,2,2,2,2,2,2,2,2,2,1,2,1,2,2,2,2,2,2,2,1,2,7,7,7,7,7,7,7,2,2,2,1,4,4,2,2,2,2,2,2,2,2,2,2,2,2,2,2,1,2,2,1
2,2,2,2,2,2,1,2,2,2,2,2,2,2,1,2,2,2,2,2,2,2,2,2,7,7,1,7,1,2,1,2,2,2,4,4,2,2,2,2,1,2,1,2,1,2,2,1,2,2,2,2,2,2
2,2,2,2,2,1,1,2,1,2,2,2,2,2,2,1,2,2,2,2,2,2,2,2,2,2,2,2,1,2,2,2,1,2,4,4,2,2,2,1,1,2,2,2,2,1,2,1,2,2,2,1,2,2
2,2,2,2,1,7,1,2,2,1,2,1,1,1,2,2,2,1,2,1,1,1,2,5,2,2,2,2,1,1,2,2,2,2,4,2,2,2,1,2,2,2,2,2,1,2,13,2,1,1,2,2,2,2
2,2,2,2,1,7,7,7,1,2,1,2,2,2,2,2,2,2,2,2,2,2,5,5,5,2,2,1,2,1,2,1,1,8,1,2,2,2,1,2,2,2,2,2,2,1,2,2,2,2,2,2,2,2
2,2,2,2,7,1,7,7,1,2,2,2,2,2,2,2,2,2,1,2,2,1,5,5,5,5,2,2,2,2,2,1,2,8,1,2,2,2,1,2,2,2,2,2,2,2,1,2,2,1,2,2,2,1
2,2,2,2,7,7,7,7,7,1,1,2,2,2,2,1,1,2,2,2,2,1,5,5,1,5,2,2,2,2,1,2,2,2,1,2,2,2,2,2,1,2,2,0,2,2,2,2,2,1,2,2,2,1
2,2,2,2,2,2,2,2,1,2,2,2,2,1,2,2,1,2,2,2,2,2,1,5,1,5,2,2,2,2,2,2,2,2,2,2,2,2,1,1,2,2,2,2,1,2,2,2,2,2,2,1,2,1
2,2,2,2,1,2,2,2,2,2,2,1,2,1,1,2,2,2,2,2,2,2,5,1,5,5,2,2,2,2,2,2,2,2,1,2,2,2,2,2,2,2,2,2,2,1,2,2,2,2,2,2,2,2
2,2,2,2,2,2,2,2,2,2,2,2,2,2,2,2,2,2,2,2,2,2,2,2,2,2,2,2,2,2,2,2,2,2,2,2,2,2,2,2,2,2,2,2,2,2,2,2,2,2,2,2,2,2
2,2,2,2,2,2,2,2,2,2,2,2,2,2,2,2,2,2,2,2,2,2,2,2,2,2,2,2,2,2,2,2,2,2,2,2,2,2,2,2,2,2,2,2,2,2,2,2,2,2,2,2,2,2
2,2,2,2,2,2,2,2,2,2,2,2,2,2,2,2,2,2,2,2,2,2,2,2,2,2,2,2,2,2,2,2,2,2,2,2,2,2,2,2,2,2,2,2,2,2,2,2,2,2,2,2,2,2
:endlayer
layer: 4
2,2,2,2,2,2,2,2,2,2,2,2,2,2,2,2,2,2,2,2,2,2,2,2,2,2,2,2,2,2,2,2,2,2,2,5,5,5,5,5,5,5,2,2,2,2,2,2,2,2,2,2,2,2
2,2,2,2,2,2,2,2,2,2,2,2,2,2,2,2,2,2,2,2,2,2,2,2,2,2,2,3,3,2,2,2,2,2,5,5,5,5,5,5,2,2,2,2,2,2,2,2,2,2,2,2,2,2
2,2,2,2,2,2,2,2,2,2,2,2,2,2,2,2,2,2,2,2,2,2,2,2,2,2,2,3,6,2,2,2,2,2,5,5,5,5,9,2,2,2,2,3,3,2,2,2,2,2,2,2,2,2
2,2,2,2,2,2,2,2,2,2,2,2,2,2,2,2,2,2,2,2,2,2,2,2,2,2,2,2,6,6,2,2,2,2,2,2,2,2,2,2,2,2,2,3,3,2,2,2,2,2,2,4,4,2
2,2,2,2,5,2,2,2,2,2,2,2,2,2,2,2,2,2,2,2,2,2,2,2,2,2,2,2,6,6,2,2,2,2,2,2,2,2,2,2,2,2,2,2,2,2,2,2,2,2,2,4,4,2
2,2,2,2,6,6,6,6,6,5,5,5,6,6,3,2,2,2,2,2,2,2,2,2,2,2,2,2,2,2,2,2,2,2,2,2,2,2,2,2,2,2,2,2,2,2,2,2,2,2,2,4,4,5
2,2,2,2,6,6,6,6,6,5,5,5,6,6,2,2,2,2,2,2,2,2,2,2,2,2,2,2,2,2,2,2,2,2,2,2,2,2,2,2,2,2,2,2,2,2,2,2,2,2,2,4,5,5
2,2,2,2,5,5,5,5,6,5,5,5,6,2,2,2,2,2,2,2,2,2,2,2,2,2,2,2,2,2,2,2,2,2,8,8,2,2,2,2,2,2,2,2,2,2,2,2,2,2,2,8,8,5
2,2,2,2,5,5,5,5,5,5,2,2,2,2,2,2,2,2,2,2,2,2,2,2,2,2,2,2,2,2,2,2,2,8,8,8,2,2,2,2,2,2,2,2,2,2,2,2,2,2,2,2,2,2
2,2,2,2,2,2,2,5,5,2,2,2,2,2,2,2,2,2,2,2,2,2,2,2,3,2,2,2,2,2,2,6,2,2,2,2,2,2,2,2,2,2,2,2,2,2,2,2,2,2,2,2,2,2
2,2,2,2,2,2,2,2,2,2,2,2,2,2,2,2,2,2,2,2,2,2,2,2,2,2,2,2,2,2,6,6,6,2,2,2,2,2,2,2,2,2,2,2,2,2,2,2,2,2,2,2,2,2
2,2,2,2,2,2,2,2,2,2,2,2,2,2,2,2,2,2,2,2,2,2,2,2,2,2,2,2,2,2,6,6,6,2,2,2,2,2,2,2,2,2,2,2,2,2,2,2,2,2,2,2,2,2
2,2,2,2,2,2,2,2,2,2,2,2,2,2,2,2,2,2,2,2,2,2,2,2,2,2,2,2,2,2,2,2,2,2,2,2,2,2,2,2,2,2,2,2,2,2,2,2,2,2,2,2,2,2
2,2,2,2,2,2,2,2,2,2,2,2,2,2,2,2,2,2,2,2,2,2,2,2,2,2,2,2,2,2,2,2,2,2,2,2,2,2,2,2,2,2,2,2,2,2,2,2,2,2,2,2,2,2
2,2,2,2,2,2,2,2,2,2,2,2,2,2,2,2,2,2,2,2,2,2,2,2,2,2,2,2,2,2,2,2,2,2,2,2,2,2,2,2,2,2,2,2,2,2,2,2,2,2,2,2,2,2
2,2,2,2,2,2,2,2,2,2,2,2,2,2,2,2,2,2,2,2,2,2,2,2,2,2,2,2,2,2,2,2,2,2,2,2,6,6,2,2,2,2,2,2,2,6,6,6,6,6,6,2,2,2
2,2,2,2,2,2,2,2,2,2,2,2,2,2,2,2,2,2,2,2,2,2,2,2,2,2,2,2,2,2,2,2,2,2,2,2,6,6,2,2,2,2,2,2,6,6,6,6,6,6,6,2,2,2
2,2,2,2,2,2,2,2,2,2,2,2,2,2,2,2,2,2,2,2,2,2,2,2,2,2,2,2,2,2,2,2,2,2,2,6,6,6,6,2,2,2,2,2,6,6,6,6,6,6,6,2,2,2
2,2,2,2,4,2,2,2,2,2,2,2,2,2,2,2,2,2,2,2,2,2,2,2,2,2,2,2,2,2,2,2,2,2,2,6,6,6,6,2,2,2,2,2,6,6,6,6,6,6,6,2,2,2
2,2,2,2,2,2,2,3,3,2,2,2,2,2,2,2,2,2,2,2,2,2,2,2,2,2,2,2,2,2,2,2,2,2,2,6,6,6,6,2,2,2,2,2,6,6,6,6,2,2,2,2,2,2
2,2,2,2,2,2,2,3,3,2,2,2,2,2,2,2,2,2,2,2,2,2,2,2,2,2,2,2,2,2,2,2,2,2,2,6,5,6,6,2,2,2,2,2,6,6,4,4,2,2,2,2,2,2
2,2,2,2,6,6,6,6,2,2,2,2,2,2,2,2,2,2,2,2,2,2,2,2,14,2,2,2,2,2,2,2,2,2,2,2,6,5,6,2,2,2,2,2,6,6,6,6,2,2,2,2,2,2
2,2,2,2,6,6,6,6,2,2,2,2,2,2,2,2,2,2,2,2,2,2,2,2,15,2,2,2,2,2,2,2,2,2,2,2,2,5,2,2,2,2,2,2,6,6,6,6,6,6,6,6,2,2
2,2,2,2,6,6,6,2,2,2,2,2,2,2,2,2,2,2,2,2,2,2,2,2,2,2,3,2,2,2,2,2,2,2,2,2,2,2,2,2,2,2,2,2,6,6,6,6,6,6,6,6,6,2
2,2,2,2,6,6,2,2,2,2,2,2,2,2,2,2,2,2,2,2,9,8,2,2,2,2,3,3,2,2,2,2,2,2,2,2,2,2,2,2,2,2,2,2,6,6,6,6,6,6,6,6,6,6
2,2,2,2,5,2,2,2,2,2,2,2,2,2,2,2,2,2,2,2,9,9,2,2,2,2,2,2,2,2,2,3,2,2,2,2,2,2,2,2,2,2,2,2,2,2,6,6,6,6,6,2,2,6
2,2,2,2,8,8,2,2,2,2,2,2,2,2,2,2,2,2,2,2,2,2,2,2,2,2,2,2,2,2,2,2,3,2,2,2,2,2,2,2,2,2,2,6,2,2,2,2,2,6,6,6,6,6
2,2,2,2,8,8,2,2,2,2,2,2,2,2,2,2,2,2,2,2,2,2,2,2,2,2,2,2,2,2,2,2,2,2,2,2,2,2,2,2,2,2,6,6,2,2,2,6,6,6,6,6,6,6
2,2,2,2,2,2,2,2,2,2,2,2,2,2,2,2,2,2,2,2,2,2,2,2,3,2,2,2,2,2,2,2,2,2,2,2,2,2,2,2,2,2,6,6,2,2,6,6,6,6,6,6,6,6
2,2,2,2,2,2,2,2,2,6,6,6,2,2,2,2,2,2,2,2,2,2,2,2,2,2,2,2,2,2,2,2,2,2,2,2,2,2,2,2,2,2,6,6,2,6,6,6,6,6,6,2,6,6
2,2,2,2,2,2,2,2,2,6,6,6,6,2,2,16,17,2,2,2,2,7,7,7,7,2,2,2,2,2,2,2,2,2,2,2,2,2,2,2,2,2,2,6,2,6,6,6,6,6,2,2,2,2
2,2,2,2,2,2,2,2,2,6,6,6,6,2,12,18,16,2,2,2,2,7,7,7,7,7,5,5,2,2,2,2,2,2,2,2,2,2,2,2,2,2,2,2,2,2,6,6,2,2,2,2,2,2
2,2,2,2,2,2,2,2,2,2,6,6,2,2,2,2,2,2,2,2,2,7,7,7,7,7,5,5,5,2,2,10,10,2,2,2,2,2,2,2,2,2,2,2,2,2,2,2,2,2,2,2,2,2
2,2,2,2,2,2,2,2,2,2,2,2,2,2,2,2,2,2,2,2,2,2,7,7,7,7,7,2,5,5,2,10,10,2,2,2,2,2,2,2,2,2,2,2,2,2,2,2,2,2,2,2,2,2
2,2,2,2,2,2,2,2,2,2,2,2,2,2,2,2,2,2,2,2,2,2,2,7,7,7,7,2,8,2,2,2,2,2,2,2,2,2,2,2,2,2,2,2,2,2,2,2,2,2,2,2,2,2
2,2,2,2,2,2,2,2,2,2,2,2,2,2,2,2,2,2,2,2,2,2,2,7,7,7,7,2,2,2,2,2,2,2,2,2,2,2,2,2,2,2,2,2,2,2,2,2,2,2,2,2,2,2
2,2,2,2,2,2,2,2,2,2,2,3,2,2,2,2,2,2,2,2,2,2,2,2,4,7,7,2,2,2,2,2,2,2,2,2,2,2,2,2,2,2,2,2,2,2,2,2,2,2,2,2,2,2
2,2,2,2,2,2,2,2,2,2,2,2,3,2,2,2,2,2,2,2,2,2,2,2,4,4,2,2,2,2,2,2,2,2,2,2,2,2,2,2,2,6,6,6,6,6,2,2,2,2,2,3,2,2
2,2,2,2,4,2,2,2,2,2,2,2,2,2,2,2,2,2,2,2,2,2,2,2,2,2,2,2,2,2,2,2,2,2,2,2,2,2,2,2,2,6,6,6,6,6,6,2,2,2,2,3,2,2
2,2,2,2,4,4,2,2,2,2,2,8,2,8,2,2,2,2,2,2,2,2,2,2,2,2,2,2,2,2,2,2,2,2,2,2,2,2,2,2,2,2,6,6,6,6,6,6,2,2,2,2,3,2
2,2,2,2,4,4,2,2,2,2,2,2,2,2,2,2,2,2,2,2,2,2,2,2,2,2,2,2,7,2,2,2,2,2,2,2,2,2,2,2,2,2,2,6,6,6,6,2,2,2,2,2,2,2
2,2,2,2,2,2,2,2,2,2,2,5,5,2,2,2,2,2,2,2,2,2,2,2,2,2,7,7,7,7,2,2,2,2,2,2,2,2,2,2,2,2,2,2,2,2,2,2,2,2,2,2,2,2
2,2,2,2,2,2,2,2,5,5,5,5,5,2,2,2,2,2,2,2,2,2,2,2,2,2,7,7,7,2,2,2,2,16,18,19,2,2,2,2,2,2,2,2,2,2,2,2,2,2,2,2,2,2
2,2,2,2,2,2,2,2,5,5,5,5,2,2,2,2,2,2,2,2,2,2,2,2,2,2,2,2,2,2,2,2,2,2,4,4,2,2,2,2,2,2,2,2,2,2,2,2,2,2,2,2,2,2
2,2,2,2,7,2,2,2,2,5,2,2,2,2,2,2,2,2,2,2,2,2,2,2,2,2,2,2,2,2,2,2,2,2,4,4,2,2,2,2,2,2,2,2,2,2,2,13,2,2,2,2,2,2
2,2,2,2,7,7,7,7,5,2,2,2,2,2,2,2,2,2,2,2,2,2,2,5,2,2,2,2,2,2,2,2,2,2,2,2,2,2,2,2,2,2,2,2,2,2,13,2,2,2,2,2,2,2
2,2,2,2,7,7,7,7,7,5,2,2,2,2,2,2,2,2,2,2,2,2,5,5,5,2,2,3,2,2,2,2,2,2,8,2,2,2,2,2,2,2,2,2,2,2,2,2,2,2,2,2,2,2
2,2,2,2,7,7,7,7,7,7,2,2,2,2,2,2,2,2,2,2,2,2,5,5,5,5,2,2,3,2,2,2,2,2,8,2,2,2,2,4,2,2,2,2,2,2,2,2,2,2,2,2,2,2
2,2,2,2,7,7,7,7,7,7,2,2,2,2,2,2,2,2,2,2,2,2,5,5,5,5,2,2,2,2,2,2,2,2,2,2,2,2,2,4,4,2,2,0,2,2,2,2,2,2,2,2,2,2
2,2,2,2,2,2,4,4,4,2,2,2,2,2,2,2,2,2,2,2,2,2,5,5,5,5,2,2,2,2,2,2,2,2,2,2,2,2,2,4,4,2,2,2,2,2,2,2,2,2,2,2,2,2
2,2,2,2,2,2,4,4,2,2,2,2,2,2,2,2,2,2,2,2,2,2,5,5,5,5,2,2,2,2,2,2,2,2,2,2,2,2,2,4,4,2,2,2,2,2,2,2,2,2,2,2,2,2
2,2,2,2,2,2,2,2,2,2,2,2,2,2,2,2,2,2,2,2,2,2,2,2,2,2,2,2,2,2,2,2,2,2,2,2,2,2,2,2,2,2,2,2,2,2,2,2,2,2,2,2,2,2
2,2,2,2,2,2,2,2,2,2,2,2,2,2,2,2,2,2,2,2,2,2,2,2,2,2,2,2,2,2,2,2,2,2,2,2,2,2,2,2,2,2,2,2,2,2,2,2,2,2,2,2,2,2
2,2,2,2,2,2,2,2,2,2,2,2,2,2,2,2,2,2,2,2,2,2,2,2,2,2,2,2,2,2,2,2,2,2,2,2,2,2,2,2,2,2,2,2,2,2,2,2,2,2,2,2,2,2
:endlayer
layer: 5
2,2,2,2,2,2,2,2,2,2,2,2,2,2,2,2,2,2,2,2,2,2,2,2,2,2,2,2,2,2,2,2,2,2,2,5,5,5,5,5,5,5,2,2,2,2,2,2,2,2,2,2,2,2
2,2,2,2,2,2,2,2,2,2,2,2,2,2,2,2,2,2,2,2,2,2,2,2,2,2,2,2,2,2,2,3,2,2,5,5,5,5,5,5,2,2,2,2,2,2,2,2,2,2,2,2,2,2
2,2,2,2,2,2,2,2,2,2,2,2,2,2,2,2,2,2,2,2,2,2,2,2,2,2,2,2,6,2,2,2,2,2,5,5,5,5,9,2,2,2,2,2,2,2,2,2,2,2,2,2,2,2
2,2,2,2,2,2,2,2,2,2,2,2,2,2,2,2,2,2,2,2,2,2,2,2,2,2,2,2,6,2,2,2,2,2,2,2,2,2,2,2,2,2,2,3,2,2,2,2,2,2,2,2,2,2
2,2,2,2,2,2,2,2,2,2,5,5,2,2,2,2,2,2,2,2,2,2,2,2,2,2,2,2,6,6,2,2,2,2,2,2,2,2,2,2,2,2,2,2,2,2,2,2,2,2,2,2,5,5
2,2,2,2,6,6,3,6,6,5,5,5,2,2,2,2,2,2,2,2,2,2,2,2,2,2,2,2,2,2,2,2,2,2,2,2,2,2,2,2,2,2,2,2,2,2,2,2,2,2,2,2,5,5
2,2,2,2,6,6,18,6,6,6,5,5,2,2,2,2,2,2,2,2,2,2,2,2,2,2,2,2,2,2,2,2,2,2,2,2,2,2,2,2,2,2,2,2,2,2,2,2,2,2,2,2,5,5
2,2,2,2,5,5,5,0,18,5,5,5,2,2,2,2,2,2,2,2,2,2,2,2,2,2,2,2,2,2,2,2,2,8,8,2,2,2,2,2,2,2,2,2,2,2,2,2,2,2,2,5,5,5
2,2,2,2,5,5,5,5,5,5,5,5,2,2,2,2,2,2,2,2,2,2,2,2,2,2,2,2,2,2,2,2,2,2,2,2,2,2,2,2,2,2,2,2,2,2,2,2,2,2,2,5,5,5
2,2,2,2,2,2,2,5,2,2,2,2,2,2,2,2,2,2,2,2,2,2,2,2,2,2,2,2,2,2,6,6,2,2,2,2,2,2,2,2,2,2,2,2,2,2,2,2,2,2,2,5,5,5
2,2,2,2,2,2,2,2,2,2,2,2,2,2,2,2,2,2,2,2,2,2,2,2,2,2,2,2,2,2,6,6,6,2,2,2,2,2,2,2,2,2,2,2,2,2,2,2,2,2,2,2,2,2
2,2,2,2,2,2,2,2,2,2,2,2,2,2,2,2,2,2,2,2,2,2,2,2,2,2,2,2,2,2,6,6,6,6,2,2,2,2,2,2,2,2,2,2,2,2,2,2,2,2,2,2,2,2
2,2,2,2,2,2,2,2,2,2,2,2,2,2,2,2,2,2,2,2,2,2,2,2,2,2,2,2,2,2,2,6,6,6,6,6,2,2,2,2,2,3,3,2,2,2,2,2,2,2,2,2,2,2
2,2,2,2,2,2,2,2,2,2,2,2,2,2,2,2,2,2,2,2,2,2,2,2,2,7,7,2,2,2,2,2,2,6,6,6,2,2,2,2,2,3,3,2,2,2,2,2,2,2,2,2,2,2
2,2,2,2,2,2,2,2,2,2,2,2,2,2,2,2,2,2,2,2,2,2,2,2,2,7,7,2,2,2,2,2,2,2,2,2,2,2,2,2,2,2,2,2,2,2,2,2,6,6,2,2,6,6
2,2,2,2,2,2,2,2,2,2,2,2,2,2,2,2,2,2,2,2,2,2,2,2,7,7,7,7,2,2,2,2,2,2,2,2,2,2,2,2,2,2,2,2,2,2,6,6,6,6,6,6,6,6
2,2,2,2,2,2,2,2,2,2,2,2,2,2,2,2,2,2,2,2,2,2,2,2,7,7,7,7,2,2,2,2,2,2,2,2,2,2,2,2,2,2,2,2,6,6,6,6,6,6,6,6,6,6
2,2,2,2,4,2,2,2,2,2,2,2,2,2,2,2,2,2,2,2,2,2,2,2,2,7,7,7,2,2,2,2,2,2,2,2,6,6,2,2,2,2,2,2,6,6,6,6,6,6,6,6,6,6
2,2,2,2,4,2,2,2,2,2,2,2,2,2,2,2,2,2,2,2,2,2,2,2,2,7,7,2,2,2,2,2,2,2,2,2,6,6,6,2,2,2,2,2,6,6,6,6,6,6,6,6,6,2
2,2,2,2,2,2,2,2,3,2,2,2,2,2,2,2,2,2,2,2,2,2,2,2,2,2,2,2,2,2,2,2,3,3,2,2,6,6,6,2,2,2,2,2,6,6,6,6,2,2,2,2,2,2
2,2,2,2,2,2,2,2,2,2,2,2,2,2,2,2,2,2,2,2,2,2,2,2,2,20,21,21,22,22,22,2,3,3,2,6,5,6,6,2,2,2,2,2,6,6,2,2,2,2,2,2,2,2
2,2,2,2,6,6,6,6,2,2,2,2,2,2,2,2,2,2,2,2,2,2,2,2,2,20,21,21,22,2,20,20,20,2,2,2,6,5,6,2,2,2,2,9,6,6,6,6,2,2,2,6,6,6
2,2,2,2,6,6,6,2,2,2,2,2,2,2,2,2,2,2,2,2,2,2,2,2,15,20,21,21,22,2,20,20,20,20,2,2,6,5,6,6,2,2,2,9,6,6,6,6,6,6,6,6,6,6
2,2,2,2,6,6,2,2,2,2,2,2,2,2,2,2,2,2,2,2,2,2,2,2,20,20,21,21,22,2,20,20,20,20,2,2,6,6,6,6,2,2,2,2,6,6,6,6,6,6,6,6,6,6
2,2,2,2,6,18,2,2,2,2,2,2,2,2,2,2,2,2,2,2,2,9,2,20,20,20,21,21,22,2,20,20,20,20,22,2,6,6,6,2,2,2,2,2,6,6,6,6,6,6,6,6,6,6
2,9,2,2,5,5,2,2,2,2,2,2,2,2,2,2,2,2,2,2,2,2,8,21,21,21,21,21,22,2,20,20,20,20,20,2,2,2,2,2,2,2,2,2,2,2,6,6,6,6,6,6,6,6
2,2,2,2,2,2,2,2,2,2,2,2,2,2,2,2,2,2,2,2,2,2,2,21,21,21,21,21,22,2,20,20,20,20,20,2,2,2,2,3,3,2,2,2,2,2,2,2,2,2,2,2,6,6
2,2,2,2,2,0,2,2,2,2,2,2,2,2,2,2,2,2,2,2,2,2,2,2,21,21,21,21,22,2,2,20,20,20,22,2,2,2,2,3,3,2,2,6,2,2,2,2,6,6,6,6,6,6
2,2,2,2,2,2,2,2,2,2,2,6,2,2,2,2,2,2,2,2,2,2,2,2,0,0,0,0,23,0,2,20,20,20,2,2,2,2,2,2,2,2,2,6,2,2,6,6,6,6,6,2,6,6
2,2,2,2,2,2,2,2,2,2,6,6,6,2,2,2,2,0,0,0,0,24,0,0,0,0,0,0,25,0,2,2,20,20,2,2,2,2,2,2,2,2,2,6,2,6,6,6,6,6,2,2,2,6
2,2,2,2,2,2,2,2,2,6,6,6,6,2,0,0,0,0,26,26,26,26,26,26,26,26,22,0,25,0,2,2,2,2,2,2,2,2,2,2,2,2,2,2,2,6,6,6,6,2,2,2,2,2
2,2,2,2,2,2,2,2,2,2,6,6,6,18,16,0,0,0,0,0,0,24,0,0,0,0,0,0,25,0,2,2,2,2,2,2,2,2,2,2,2,2,2,2,6,6,6,6,6,2,2,2,2,2
2,2,2,2,2,2,2,2,2,2,2,2,2,2,2,2,2,2,2,2,2,2,7,0,0,0,5,0,25,0,5,2,2,2,2,2,2,2,2,2,2,2,2,2,2,6,6,2,2,2,2,2,2,2
2,2,2,2,2,2,2,2,2,2,2,2,2,2,2,2,2,2,2,2,2,2,2,7,7,7,7,0,25,0,5,2,2,2,2,2,2,2,2,2,2,2,2,2,2,2,2,2,2,2,2,2,2,2
2,2,2,2,2,2,2,2,2,2,2,2,2,2,2,2,2,2,2,2,2,2,2,7,7,7,7,24,25,24,5,2,2,2,2,2,2,2,2,2,2,2,2,2,2,2,2,2,2,2,2,2,2,2
2,2,2,2,2,2,2,2,2,2,2,2,2,2,2,2,2,2,2,2,2,2,2,2,7,7,7,0,25,0,2,2,2,2,2,2,2,2,2,2,2,2,2,2,2,2,2,2,2,2,2,2,2,2
2,2,2,2,2,2,2,2,2,2,2,3,3,2,2,2,2,2,2,2,2,2,2,2,2,7,7,0,25,0,2,2,2,2,2,2,2,2,2,2,2,2,2,6,2,2,2,2,2,2,2,2,2,2
2,2,2,2,2,2,2,2,2,2,2,3,3,2,2,2,2,2,2,2,2,2,2,2,2,2,2,0,25,0,2,2,2,2,2,2,2,3,2,2,2,6,6,6,6,6,6,6,6,2,2,2,2,0
2,2,2,2,2,2,2,2,2,2,2,2,2,2,2,2,2,2,2,2,2,2,2,2,2,2,2,0,0,0,2,2,2,2,2,2,2,2,2,2,2,2,6,6,6,6,6,6,6,6,2,2,2,0
2,2,2,2,4,2,2,2,2,2,2,2,2,2,2,2,2,2,2,2,2,2,2,2,2,2,2,0,0,0,2,2,2,2,2,2,2,2,2,2,2,2,6,6,6,6,6,6,6,6,2,2,2,0
2,2,2,2,4,2,2,2,2,2,2,5,2,2,2,2,2,2,2,2,2,2,2,2,2,2,2,0,0,0,2,2,2,2,2,2,2,2,2,2,2,2,2,2,6,6,6,6,6,2,2,2,2,0
2,2,2,2,2,2,2,2,5,5,5,5,5,5,5,2,2,2,2,2,2,2,2,2,2,2,2,24,0,24,2,2,2,2,2,2,2,2,2,5,5,5,5,5,5,2,2,2,2,2,2,2,2,0
0,0,24,0,0,0,0,0,0,0,0,0,0,24,0,0,0,0,0,0,0,0,0,0,0,0,24,0,0,0,0,0,0,0,0,17,16,18,11,5,5,5,5,5,5,2,2,2,2,2,2,2,2,0
0,0,0,0,0,0,0,0,0,0,0,0,0,0,0,0,0,0,0,0,0,0,0,0,0,0,0,0,0,0,2,2,2,2,2,2,2,2,2,2,5,5,5,5,5,2,2,2,2,2,2,2,2,0
0,0,24,0,0,0,0,0,0,0,0,0,0,24,0,0,0,0,0,0,0,0,0,0,0,0,24,0,0,0,2,2,2,2,2,2,2,2,2,2,2,2,2,5,2,2,2,2,2,2,2,2,2,0
2,2,2,2,7,7,7,7,5,5,5,2,2,2,2,2,3,3,2,2,2,2,2,2,2,2,2,24,0,24,2,2,2,2,2,2,2,2,2,2,2,2,2,2,2,2,2,2,2,2,2,2,2,0
2,2,2,2,7,7,7,7,7,5,5,2,2,2,2,2,2,2,2,2,2,2,2,5,2,2,2,0,0,0,2,2,2,2,2,2,2,2,2,2,2,2,2,2,2,2,2,2,2,2,2,2,2,0
2,2,2,2,7,7,7,7,7,7,5,2,2,2,2,2,2,2,2,2,2,2,5,5,5,2,2,0,0,0,2,2,2,2,2,2,2,2,2,4,2,2,2,2,2,2,2,2,2,2,2,2,2,0
2,2,2,2,7,7,7,7,7,7,2,2,2,2,2,2,2,3,3,2,2,2,5,5,5,2,2,0,0,0,0,0,0,0,0,0,0,0,0,0,0,0,0,0,0,0,0,0,0,0,0,0,0,0
2,2,2,2,2,2,4,4,4,2,2,2,2,2,2,2,2,3,3,2,2,2,2,5,5,2,2,0,0,0,2,2,2,2,2,2,2,2,2,4,4,2,2,2,2,3,7,7,7,7,2,2,2,2
2,2,2,2,2,2,4,4,2,2,2,2,2,2,2,2,2,2,2,2,2,2,2,5,5,2,2,0,0,0,2,2,2,2,2,2,2,2,2,4,4,2,2,2,2,7,7,7,7,7,2,2,2,2
2,2,2,2,2,2,2,2,2,2,2,2,2,2,2,2,2,2,2,2,2,2,2,2,2,2,2,24,0,24,2,2,2,2,2,2,2,2,2,2,2,2,2,2,2,2,2,2,2,2,2,2,2,2
2,2,2,2,2,2,2,2,2,2,2,2,2,2,2,2,2,2,2,2,2,2,2,2,2,2,2,0,0,0,2,2,2,2,2,2,2,2,2,2,2,2,2,2,2,2,2,2,2,2,2,2,2,2
2,2,2,2,2,2,2,2,2,2,2,2,2,2,2,2,2,2,2,2,2,2,2,2,2,2,2,0,0,0,2,2,2,2,2,2,2,2,2,2,2,2,2,2,2,2,2,2,2,2,2,2,2,2
:endlayer
layer: 6
2,2,2,2,2,2,2,2,2,2,2,2,2,2,2,2,2,2,2,2,2,2,2,2,2,2,2,2,2,2,2,2,2,2,2,2,5,5,5,5,5,2,2,2,6,2,2,2,2,2,2,2,2,2
2,2,2,2,2,2,2,2,2,2,2,2,2,2,2,2,2,2,2,2,2,2,2,2,2,2,2,2,2,2,2,3,2,2,2,2,5,5,5,2,2,2,2,2,6,6,6,6,6,2,2,2,2,2
2,2,2,2,2,2,2,2,2,2,5,5,2,2,2,2,2,2,2,2,2,2,2,2,2,2,2,2,2,2,2,3,2,2,2,2,2,2,2,2,2,2,2,2,6,6,6,6,6,6,6,6,2,2
2,2,2,2,2,2,2,2,2,5,5,5,2,2,2,2,3,2,2,2,2,2,2,2,2,2,2,13,2,2,2,2,2,2,2,2,2,2,2,2,2,2,2,2,2,6,6,6,6,6,6,6,2,5
2,2,2,2,2,2,2,2,2,5,5,5,5,2,2,2,2,2,2,2,2,2,2,2,2,2,2,2,2,2,2,2,2,2,2,2,2,2,2,2,2,2,2,2,2,2,2,2,2,2,6,6,6,6
2,9,2,2,6,2,2,2,2,0,0,5,5,2,2,2,2,2,2,2,2,2,2,2,2,2,2,2,2,2,2,2,2,2,2,2,2,2,2,2,2,2,2,2,2,3,2,2,2,2,2,6,6,6
2,9,2,2,2,2,2,2,2,0,5,5,5,2,2,2,2,2,2,2,2,2,2,2,2,2,2,2,2,2,2,2,2,2,2,2,2,2,2,2,2,2,2,2,3,2,2,2,2,2,2,6,6,6
2,2,2,2,2,2,2,0,2,5,5,5,5,3,2,2,2,2,2,2,2,2,2,2,2,2,2,2,2,2,2,2,2,2,2,2,2,2,2,2,2,2,2,2,2,2,2,2,2,2,6,6,6,6
2,2,2,2,2,2,2,2,2,5,5,5,5,3,3,2,2,2,2,2,2,2,2,2,2,2,2,2,2,2,2,2,2,2,2,2,2,2,2,2,8,8,2,2,2,2,2,2,2,2,6,6,6,6
2,2,2,2,2,2,2,2,2,2,5,5,5,2,2,2,2,2,2,2,2,2,2,2,2,2,2,2,2,2,2,2,2,2,2,2,2,2,2,2,8,8,8,2,2,2,2,2,3,3,6,6,6,6
2,2,2,2,2,2,2,2,2,2,5,5,2,2,2,2,2,2,2,2,2,2,2,2,2,2,2,2,2,2,2,6,6,2,2,2,2,2,2,2,2,8,8,2,2,2,2,2,3,3,6,6,6,6
2,2,2,2,2,2,2,2,2,2,2,2,2,2,2,2,2,2,2,2,2,2,2,2,2,2,2,2,2,2,2,6,6,2,6,9,2,2,2,2,2,2,2,2,2,2,2,2,2,2,2,6,6,6
2,2,2,2,2,2,2,2,2,2,2,2,2,2,2,2,2,2,2,2,2,2,2,2,2,7,7,2,2,2,2,2,2,6,6,6,2,2,2,2,2,2,3,2,2,2,2,2,2,2,2,6,6,6
2,2,2,2,2,2,2,2,2,2,2,2,2,2,2,2,2,2,2,2,2,2,2,2,2,7,7,7,2,2,2,2,2,6,6,6,6,2,2,2,2,2,2,2,2,2,2,2,2,2,2,2,6,6
2,2,2,2,2,2,2,2,2,2,2,2,2,2,2,2,2,2,2,2,2,2,7,2,7,7,7,7,2,2,2,2,2,2,6,6,6,2,2,2,2,2,2,2,2,2,2,2,2,2,2,6,6,6
2,2,2,2,2,2,2,2,2,2,2,2,2,2,2,2,2,2,2,2,2,2,7,2,7,7,7,7,2,2,2,2,2,2,6,6,6,6,2,2,2,2,2,2,2,2,2,6,6,6,6,6,6,6
2,2,2,2,2,2,2,2,2,2,2,2,2,2,2,2,2,2,2,2,2,2,2,2,7,7,7,7,2,2,2,2,2,2,2,6,6,6,2,2,2,2,2,2,2,6,6,6,6,6,6,6,6,6
2,2,2,2,2,2,2,2,2,2,2,2,2,2,2,2,2,2,2,2,2,2,2,2,7,7,21,21,2,2,2,2,2,2,2,2,2,2,2,2,2,2,2,2,6,6,6,6,6,6,6,6,6,6
2,2,2,2,2,2,2,2,2,2,2,2,2,2,2,2,2,2,2,2,2,2,2,2,2,2,21,21,2,2,2,2,2,2,2,2,2,2,2,2,2,2,2,2,6,6,6,6,6,6,6,6,6,6
2,2,2,2,2,2,2,2,2,2,2,2,2,2,2,2,2,2,2,2,2,2,2,2,2,2,21,21,2,2,2,2,3,3,2,2,2,6,2,2,2,2,2,2,2,2,2,2,6,6,6,6,6,6
2,2,2,2,2,2,2,2,2,2,2,2,2,2,2,2,2,2,2,2,2,14,2,2,2,0,27,27,22,22,22,2,3,3,2,2,5,6,6,2,2,2,2,2,2,2,2,2,2,2,2,2,2,2
2,2,2,2,2,2,2,2,2,2,2,2,2,2,2,2,2,2,2,2,2,20,2,2,2,0,0,0,22,0,0,0,28,2,2,6,6,5,6,7,7,7,2,2,6,6,6,6,2,2,2,6,6,6
2,2,2,2,2,2,2,2,2,2,2,2,2,2,2,2,2,2,2,2,2,20,14,29,30,0,0,0,22,0,0,0,0,0,2,6,6,5,6,6,7,7,7,9,6,6,6,6,6,6,6,6,6,6
2,2,2,2,0,0,0,2,2,2,2,2,2,2,2,2,2,2,2,2,31,14,2,2,0,0,0,0,22,0,0,0,0,0,2,6,6,6,6,6,7,7,7,2,6,6,6,6,6,6,6,6,6,6
2,2,2,2,0,0,0,0,2,2,2,2,2,2,2,2,2,2,2,2,2,2,2,0,0,0,0,0,22,0,0,0,0,0,22,2,6,6,6,6,7,7,7,2,6,6,6,6,6,6,6,6,6,6
2,9,2,2,0,0,0,0,2,2,2,2,2,2,2,2,2,2,2,2,2,2,0,0,0,0,0,0,23,0,0,0,0,0,0,21,21,6,6,6,2,2,2,2,2,2,6,6,6,6,6,6,6,6
2,2,2,2,0,0,0,2,2,2,2,2,2,2,2,2,2,2,2,2,2,2,0,0,0,0,0,0,25,0,0,0,0,0,0,2,6,6,6,6,3,2,2,2,2,2,2,2,2,2,2,2,2,3
2,2,2,2,2,0,2,2,2,2,2,2,2,2,2,2,2,2,2,2,2,2,2,2,0,0,0,0,25,0,0,0,0,0,22,2,6,5,6,3,3,2,2,2,2,2,2,2,2,2,2,2,2,2
2,2,2,2,2,2,2,2,2,2,2,6,2,2,2,2,2,2,2,2,2,2,2,2,0,0,0,0,0,0,0,0,0,0,2,2,6,6,6,6,2,2,2,2,2,2,2,2,2,2,2,2,2,2
2,2,2,2,2,2,2,2,2,2,6,6,6,2,2,2,2,0,0,0,0,24,0,0,0,0,0,0,0,0,0,0,0,28,2,2,2,6,6,6,2,2,2,2,2,6,6,6,6,2,2,2,2,2
2,2,2,2,9,2,2,2,2,6,6,6,6,2,0,0,0,0,0,0,0,0,0,0,0,0,0,0,0,0,0,0,0,2,2,2,2,6,6,6,2,2,2,2,6,6,6,6,6,2,2,2,2,2
2,2,2,2,9,2,2,2,2,2,6,6,6,2,0,0,0,0,0,0,0,24,0,0,0,0,0,0,0,0,0,2,2,2,2,2,2,2,2,2,2,2,2,2,6,6,6,6,2,2,2,2,2,2
2,2,2,2,2,8,2,2,2,2,2,2,2,2,2,2,2,2,2,2,2,2,2,0,0,0,5,0,0,0,5,2,2,2,2,2,2,2,2,2,2,2,2,2,6,6,6,6,2,2,2,2,2,2
2,2,2,2,2,2,2,2,2,2,2,2,2,2,2,2,2,2,2,2,2,2,2,2,2,5,5,0,0,0,5,2,2,2,2,2,2,2,2,2,2,2,2,2,6,6,2,2,2,2,2,2,2,2
2,2,2,2,2,2,2,2,2,2,2,2,2,2,2,2,2,2,2,2,2,2,2,2,2,2,2,24,0,24,5,2,2,2,2,2,2,2,2,2,2,2,2,2,2,2,2,2,2,2,2,2,2,2
2,2,2,2,2,2,2,2,2,2,2,2,2,2,2,2,2,2,2,2,2,2,2,2,2,2,2,0,0,0,2,2,2,2,2,2,2,2,2,2,2,2,2,2,2,2,2,2,2,2,2,2,2,2
2,2,2,2,2,2,2,2,2,2,2,2,2,2,2,2,2,2,2,2,2,2,2,2,2,2,2,0,0,0,2,2,2,2,2,2,2,2,2,2,2,2,2,6,2,2,2,2,2,2,2,2,2,2
2,2,2,2,2,2,2,2,2,2,2,2,3,2,2,2,2,2,2,2,2,2,2,2,2,2,2,0,0,0,2,2,2,2,2,2,2,3,3,2,2,2,2,2,2,2,6,6,6,6,6,2,2,0
2,2,2,2,2,2,2,2,2,2,2,2,2,2,2,2,2,2,2,2,2,2,2,2,2,2,2,0,0,0,2,2,2,2,2,2,2,3,3,2,2,2,2,6,6,6,6,6,6,6,2,2,2,0
2,2,2,2,2,2,2,2,2,2,2,2,2,2,2,2,2,2,2,2,2,2,2,2,2,2,2,0,0,0,2,2,2,2,2,2,2,2,2,2,2,2,2,2,6,6,6,6,6,6,2,2,2,0
2,2,2,2,2,2,2,2,2,2,2,5,5,5,2,2,2,2,2,2,2,2,2,2,2,2,2,0,0,0,2,2,2,2,2,2,2,2,2,2,2,2,2,2,2,6,6,6,6,2,2,2,2,0
2,2,2,2,2,2,2,2,5,5,5,5,5,5,5,2,2,2,2,2,2,2,2,2,2,2,2,24,0,24,2,2,2,2,2,2,2,2,2,5,5,5,5,5,5,2,2,2,2,2,2,2,2,0
0,0,24,0,0,0,0,0,0,0,0,0,0,24,0,0,0,0,0,0,0,0,0,0,0,0,24,0,0,0,0,0,0,0,0,0,0,0,18,32,5,5,5,5,5,5,5,5,2,2,2,2,2,0
0,0,0,0,0,0,0,0,0,0,0,0,0,0,0,0,0,0,0,0,0,0,0,0,0,0,0,0,0,0,2,2,2,2,2,2,2,2,2,2,5,5,5,5,5,5,5,5,2,2,2,2,2,0
0,0,24,0,0,0,0,0,0,0,0,0,0,24,0,0,0,0,0,0,0,0,0,0,0,0,24,0,0,0,2,2,2,2,2,2,2,2,2,2,2,2,5,5,5,5,5,5,2,2,2,2,2,0
0,2,2,2,7,7,5,5,5,5,5,8,2,2,2,2,2,2,2,2,2,2,2,2,2,2,2,24,0,24,2,2,2,2,2,2,2,2,2,2,2,2,2,2,2,2,2,2,2,2,2,2,2,0
2,2,2,2,7,7,7,7,5,5,5,2,2,2,2,2,2,2,2,2,2,2,2,2,2,2,2,0,0,0,2,2,2,2,2,2,2,2,2,2,2,2,2,2,2,2,2,2,2,2,2,2,2,0
2,2,2,2,7,7,7,7,7,5,5,2,2,2,2,2,2,2,2,2,2,2,2,2,2,2,2,0,0,0,2,2,2,2,2,2,2,2,2,2,2,2,2,2,2,2,2,7,7,7,7,2,2,0
2,2,2,2,7,7,7,7,7,2,2,2,2,2,2,2,2,3,3,2,2,2,2,4,2,2,2,0,0,0,0,0,0,0,0,0,0,0,0,0,0,0,0,0,0,0,0,0,0,0,0,0,0,0
2,2,2,2,2,2,2,2,2,2,2,2,2,2,2,2,2,3,3,2,2,2,2,4,2,2,2,0,0,0,2,2,2,2,2,2,2,2,2,2,2,2,2,2,2,2,7,7,7,7,7,2,2,2
2,2,2,2,2,2,2,2,2,2,2,2,2,2,2,2,2,2,2,2,2,2,2,4,4,2,2,0,0,0,2,2,2,2,2,2,2,2,2,2,2,2,2,2,2,7,7,7,7,7,7,2,2,2
2,2,2,2,2,2,2,2,2,2,2,2,2,2,2,2,2,2,2,2,2,2,2,2,2,2,2,24,0,24,2,2,2,2,2,2,2,2,2,2,2,2,2,2,2,2,2,2,2,2,2,2,2,2
2,2,2,2,2,2,2,2,2,2,2,2,2,2,2,2,2,2,2,2,2,2,2,2,2,2,0,0,0,0,2,2,2,2,2,2,2,2,2,2,2,2,2,2,2,2,2,2,2,2,2,2,2,2
2,2,2,2,2,2,2,2,2,2,2,2,2,2,2,2,2,2,2,2,2,2,2,2,2,2,2,0,0,0,2,2,2,2,2,2,2,2,2,2,2,2,2,2,2,2,2,2,2,2,2,2,2,2
:endlayer
layer: 7
2,2,2,2,2,2,2,2,2,2,2,2,2,2,2,2,2,2,2,2,2,2,2,2,0,0,0,2,2,2,2,2,2,2,2,2,2,2,2,2,2,2,2,2,6,2,2,2,2,2,2,2,2,2
2,2,2,2,2,2,2,2,2,2,2,2,2,2,2,2,2,2,2,2,2,2,2,2,0,0,0,2,2,2,3,2,2,2,2,2,2,2,2,2,2,2,2,2,6,6,6,6,6,6,2,2,2,2
2,2,2,2,2,2,2,2,2,2,5,5,2,2,2,2,2,2,2,2,2,2,2,2,0,0,0,2,2,2,3,2,2,2,2,2,2,2,2,2,2,2,2,2,6,6,6,6,6,6,6,6,2,2
9,2,2,2,2,2,2,2,2,5,5,5,2,2,2,2,3,3,2,2,2,2,2,2,0,0,0,13,13,2,2,2,2,2,2,2,2,2,2,2,2,2,2,2,2,6,6,6,6,6,6,6,6,6
2,2,9,2,2,2,2,2,8,5,5,5,5,2,2,2,3,3,2,2,2,2,2,2,0,0,0,2,13,2,2,2,2,2,2,2,2,2,2,2,2,2,2,2,2,2,2,2,6,6,6,6,6,6
2,9,2,2,2,2,2,2,2,0,0,0,5,2,2,2,2,2,2,2,2,2,2,2,24,0,24,2,2,2,2,2,2,2,2,2,2,2,2,2,2,2,2,2,2,3,2,2,2,2,6,6,6,6
9,9,2,2,2,2,2,2,2,0,5,5,5,2,2,2,2,2,2,2,2,2,2,2,0,0,0,2,2,2,2,2,2,2,2,2,2,2,2,2,2,2,2,2,3,2,2,2,2,2,6,6,6,6
2,2,9,2,2,2,2,2,2,0,5,0,5,3,2,2,4,4,4,2,2,2,2,2,0,0,0,2,2,2,2,2,2,2,2,2,2,2,2,2,2,2,2,2,2,2,2,2,2,2,6,6,6,6
2,9,2,2,2,2,2,2,2,5,5,5,5,3,3,2,4,4,2,2,2,2,2,2,0,0,0,2,2,2,2,2,2,2,2,2,2,2,2,2,8,8,2,2,2,3,3,2,2,6,6,6,6,6
2,2,2,2,2,2,2,2,2,5,5,5,5,2,2,4,4,4,2,2,2,2,2,2,0,0,0,2,2,2,2,2,2,2,2,2,2,2,2,2,8,8,8,2,2,3,3,2,2,6,6,6,6,6
2,2,2,2,2,2,2,2,2,2,5,5,5,2,2,4,4,4,2,2,2,2,2,2,0,0,0,2,2,2,2,2,2,2,2,2,2,2,2,2,2,8,8,2,2,2,2,2,2,3,6,6,6,6
2,9,2,2,2,2,2,2,2,2,2,5,2,2,2,2,2,2,2,2,2,2,2,2,0,0,0,2,2,2,2,2,2,2,2,2,2,2,2,2,2,2,2,2,2,2,2,2,2,2,6,6,6,6
2,2,2,2,2,2,2,2,2,2,2,2,2,2,2,2,2,2,2,2,2,2,2,2,0,0,0,7,7,2,2,2,2,6,6,6,2,2,2,2,2,2,2,2,2,2,2,2,2,2,6,6,6,6
2,2,2,2,2,2,2,2,2,2,2,2,2,2,2,2,2,2,2,2,2,7,7,7,0,0,0,7,7,2,2,2,2,6,6,6,6,2,2,2,2,2,2,2,2,2,2,2,2,2,2,6,6,6
2,2,2,2,2,2,3,3,2,2,2,2,2,2,2,2,2,2,2,2,7,7,7,7,0,0,0,7,2,2,2,2,2,2,6,6,6,6,2,2,2,2,2,2,2,2,2,2,2,2,2,6,6,6
9,2,2,2,7,2,3,3,2,2,2,2,2,2,2,2,2,2,2,2,7,7,7,7,0,0,0,7,2,2,2,2,2,2,6,6,6,6,2,2,2,2,2,2,2,2,2,2,6,6,6,6,6,6
2,2,2,2,7,2,2,2,2,2,2,2,2,2,2,2,2,2,2,2,2,7,7,2,24,0,24,7,2,2,2,2,2,2,2,6,6,6,2,2,2,2,2,2,2,2,2,6,6,6,6,6,6,6
2,9,2,2,7,2,2,2,2,2,2,2,2,2,2,2,2,2,2,2,2,2,2,2,0,0,0,0,33,2,2,2,2,2,2,6,6,6,6,2,2,2,2,2,2,2,2,6,6,6,6,6,6,6
2,2,2,2,2,2,2,2,2,2,2,2,2,2,2,2,2,2,2,2,2,2,2,2,0,0,0,0,33,2,2,2,2,2,2,6,6,6,6,2,2,2,2,2,2,2,2,6,6,6,6,6,6,6
9,2,2,2,2,2,2,2,2,2,2,2,2,2,2,2,2,2,2,2,2,2,2,0,0,0,0,0,33,2,2,2,2,2,2,6,6,6,6,2,2,2,2,2,2,2,6,6,6,6,6,6,6,6
2,2,9,2,2,2,2,2,2,2,2,2,2,2,2,2,2,2,2,2,2,2,0,0,0,0,0,0,22,22,22,21,20,2,2,6,5,6,6,2,2,2,2,2,2,2,6,6,6,6,6,2,6,6
2,2,2,2,2,2,2,2,2,2,3,2,2,2,2,2,2,2,2,2,2,0,0,0,0,0,0,0,22,0,0,0,14,2,2,6,6,5,6,7,7,7,7,2,2,6,6,6,2,2,2,2,6,6
2,2,2,2,2,2,2,2,2,2,3,2,2,2,2,2,2,2,2,2,2,0,0,0,0,0,0,0,22,0,0,0,0,0,21,6,6,5,6,7,7,7,7,7,6,6,6,6,6,6,6,6,6,6
2,2,2,2,0,0,0,0,0,0,0,0,0,0,0,0,0,0,0,0,31,0,0,0,0,0,0,0,23,0,0,0,0,0,2,6,6,6,6,6,7,7,7,7,7,6,6,6,6,6,6,6,6,6
2,2,2,2,0,0,0,0,0,0,0,0,0,0,0,0,0,0,0,0,0,0,0,0,0,0,0,0,25,0,0,0,0,0,22,2,6,6,6,6,7,7,7,7,7,7,6,6,6,6,6,6,6,6
9,9,2,2,0,0,0,0,0,0,2,2,2,2,2,2,2,2,2,2,0,0,0,0,0,0,0,0,0,0,0,0,0,0,22,21,6,6,6,6,6,2,2,2,2,2,7,6,6,6,6,7,2,6
2,2,2,2,0,0,0,2,2,2,2,2,2,2,2,2,2,2,2,2,2,0,0,0,0,0,0,0,0,0,0,0,0,0,22,7,6,6,6,6,6,6,2,2,2,2,2,7,7,7,2,2,2,2
2,2,2,2,0,8,8,2,2,2,2,2,2,2,2,2,2,2,2,2,2,2,2,2,0,0,0,0,0,0,0,0,0,0,22,7,6,5,6,6,6,6,6,2,2,2,2,2,2,2,2,2,2,2
2,2,2,2,2,8,8,2,2,2,2,6,6,2,2,2,2,2,2,2,2,2,2,2,0,0,0,0,0,0,0,0,0,0,2,2,6,6,6,6,6,6,6,6,2,2,2,2,2,2,2,2,2,2
2,2,2,2,2,2,2,2,2,2,6,6,6,2,2,2,2,0,0,0,0,22,0,0,0,0,0,0,0,0,0,0,0,28,2,2,6,6,6,6,6,6,6,6,2,2,2,2,2,2,2,2,2,2
2,2,2,2,9,2,2,2,2,2,6,6,6,2,2,2,2,0,0,0,0,22,0,0,0,0,0,0,0,0,0,0,0,2,2,2,2,6,6,6,6,6,6,6,6,6,6,6,2,2,2,2,2,2
9,2,2,2,8,8,2,2,2,2,6,6,6,2,2,2,2,0,0,0,0,22,0,0,0,0,0,0,0,0,0,2,2,2,2,2,2,2,6,6,6,6,6,6,6,6,6,6,2,2,2,2,2,2
2,9,2,2,8,8,2,2,2,2,2,2,2,2,2,2,2,2,2,2,2,2,2,0,0,0,5,0,0,0,2,2,2,2,2,2,2,2,6,6,6,6,6,6,6,6,6,2,2,2,2,2,2,2
2,2,9,2,2,2,2,2,2,2,2,2,2,2,2,2,2,2,2,2,2,2,2,2,2,5,5,0,0,0,5,2,2,2,2,6,6,6,6,6,6,6,6,6,6,6,6,2,2,2,2,2,2,2
2,2,2,2,2,2,2,2,2,2,2,2,2,2,2,2,2,2,2,2,2,2,2,2,2,2,2,22,22,22,8,2,2,2,2,6,6,6,6,6,6,6,6,6,6,6,2,2,2,2,2,2,2,2
9,2,2,2,2,2,2,2,2,2,2,2,2,2,2,2,2,2,2,2,2,2,2,2,2,2,2,0,0,0,2,2,2,2,6,6,6,6,6,2,6,6,6,6,6,2,2,2,2,2,2,2,2,2
2,2,2,2,2,2,2,2,2,2,2,2,2,2,2,2,2,2,2,2,2,2,2,2,2,2,2,0,0,0,2,2,2,2,2,6,6,6,2,2,2,6,6,6,2,2,2,2,2,2,2,2,2,2
2,9,2,2,2,2,2,2,2,2,2,2,2,2,2,2,2,2,2,2,2,2,2,2,2,2,2,0,0,0,2,2,2,2,2,2,2,2,2,2,6,6,6,6,6,2,2,6,6,6,6,2,2,10
2,9,2,2,2,2,2,2,2,2,2,2,2,2,2,2,2,2,2,2,2,2,2,2,2,2,2,0,0,0,2,2,2,2,2,2,2,2,3,2,6,6,6,6,2,2,6,6,6,6,6,2,2,2
2,9,2,2,2,2,2,2,2,2,2,2,2,2,2,2,2,2,2,2,2,2,2,2,2,2,2,0,0,0,2,2,2,2,2,2,2,2,2,6,6,6,6,6,2,2,6,6,6,6,2,2,2,2
2,2,2,2,2,2,2,2,2,2,2,2,2,2,2,2,2,2,2,2,2,2,2,2,2,2,2,0,0,0,2,2,2,2,2,2,2,2,2,6,6,6,6,2,2,2,2,2,2,2,2,2,2,2
2,2,2,2,2,2,2,2,5,5,5,5,5,2,2,2,2,2,2,2,2,2,2,2,2,2,2,22,22,22,2,2,2,2,2,2,2,2,2,6,6,6,5,5,5,2,2,2,2,2,2,2,2,2
0,0,22,0,0,0,0,0,0,0,0,0,0,22,0,0,0,0,0,0,0,0,0,0,0,0,22,0,0,0,2,2,2,2,2,2,2,2,2,6,6,5,5,5,5,5,5,5,2,2,2,2,2,2
0,0,22,0,0,0,0,0,0,0,0,0,0,22,0,0,0,0,0,0,0,0,0,0,0,0,22,0,0,0,2,2,2,2,2,2,2,2,2,2,2,5,5,5,5,5,5,5,5,2,2,2,2,2
0,0,22,0,0,0,0,0,0,0,0,0,0,22,0,0,0,0,0,0,0,0,0,0,0,0,22,0,0,0,2,2,2,2,2,2,2,2,2,2,2,2,5,5,5,5,5,5,5,2,2,2,2,2
0,2,2,2,5,5,5,5,5,2,2,2,2,2,2,2,2,2,2,2,2,2,2,2,8,2,2,22,22,22,2,2,2,2,2,2,2,2,2,2,2,2,2,2,2,2,5,2,2,2,2,2,2,2
0,2,2,2,5,5,5,5,5,5,2,2,2,2,2,2,2,2,2,2,2,2,2,2,2,2,2,0,0,0,2,2,2,2,2,2,2,2,2,2,2,2,2,2,2,2,2,2,2,7,7,7,2,2
2,2,2,2,5,5,5,5,5,2,2,2,2,2,2,2,2,2,2,2,2,2,2,2,2,2,2,0,0,0,2,2,2,2,2,2,2,2,2,2,2,2,2,2,2,2,2,7,7,7,7,7,2,2
2,2,2,2,2,2,2,2,2,2,2,2,2,2,2,2,2,2,2,2,2,2,2,2,2,2,2,0,0,0,2,2,2,2,2,2,2,2,2,2,2,2,2,2,2,2,7,7,7,7,7,7,2,2
20,20,2,2,2,2,2,2,2,2,2,2,2,2,2,2,2,2,2,2,2,2,2,2,2,2,2,0,0,0,2,2,2,2,2,2,2,2,2,2,2,2,2,2,2,2,7,7,7,7,7,2,2,2
20,20,2,2,2,2,2,2,2,2,2,2,2,2,2,2,2,2,2,2,2,2,2,2,2,2,2,0,0,0,2,2,2,2,2,2,2,2,2,2,2,2,2,2,2,7,7,7,7,7,7,2,2,2
2,2,2,2,2,2,2,2,2,2,2,2,2,2,2,2,2,2,2,2,2,2,2,2,2,2,2,22,22,22,2,2,2,2,2,2,2,2,2,2,2,2,2,2,2,2,2,2,2,2,2,2,2,2
2,2,2,2,2,2,2,2,2,2,2,2,2,2,2,2,2,2,2,2,2,2,2,2,2,0,0,0,0,0,2,2,2,2,2,2,2,2,2,2,2,2,2,2,2,2,2,2,2,2,2,2,2,2
2,2,2,2,2,2,2,2,2,2,2,2,2,2,2,2,2,2,2,2,2,2,2,2,2,2,2,0,0,0,2,2,2,2,2,2,2,2,2,2,2,2,2,2,2,2,2,2,2,2,2,2,2,2
:endlayer
layer: 8
2,2,2,2,2,2,2,2,2,2,2,2,2,2,2,2,2,2,2,2,2,2,2,0,0,0,0,2,6,2,2,2,2,2,2,2,2,2,2,2,2,2,2,2,2,2,2,2,2,2,2,2,2,2
2,9,2,2,2,2,2,2,2,2,2,2,2,2,2,2,2,2,2,2,2,2,2,2,0,0,0,2,6,6,2,2,2,2,2,2,2,2,2,2,2,2,2,2,2,6,6,6,6,2,2,2,2,2
2,2,2,2,2,2,2,2,2,2,2,2,2,2,2,2,2,2,2,2,2,2,2,2,0,0,0,2,6,2,3,2,2,2,2,2,2,2,2,2,2,2,2,2,2,6,6,6,6,6,6,6,2,2
0,5,5,2,2,2,2,2,2,8,5,5,2,2,2,2,2,2,2,2,2,2,2,2,0,0,0,2,2,2,2,2,2,2,2,2,2,2,2,2,2,2,2,2,2,2,6,6,6,6,6,6,6,6
5,5,0,9,2,2,2,2,8,5,5,5,2,2,2,2,2,3,2,2,2,2,2,2,0,0,0,2,13,2,2,2,2,2,2,2,2,2,2,2,2,2,2,2,2,2,2,2,2,2,6,6,6,6
5,5,0,2,2,2,2,2,2,0,0,0,2,2,2,2,2,2,2,2,2,2,2,2,24,0,24,2,2,2,2,3,2,2,2,2,2,2,2,2,2,2,2,2,2,2,2,2,2,2,6,6,6,6
24,0,24,2,2,2,2,2,2,0,0,5,5,2,2,2,2,2,2,2,2,2,2,2,0,0,0,2,2,2,2,2,2,2,2,2,2,2,2,2,2,2,2,2,2,2,2,2,2,2,6,6,6,6
0,0,0,2,2,2,2,2,2,0,5,0,5,2,2,2,4,4,4,2,2,2,2,2,0,0,0,2,2,2,2,2,2,2,2,2,2,2,2,8,2,2,2,2,2,2,2,2,2,2,6,6,6,6
0,0,0,2,2,2,2,2,2,5,5,5,5,2,2,2,4,4,2,2,2,2,2,2,0,0,0,2,2,2,2,2,2,2,2,2,2,2,2,8,2,2,2,2,2,2,2,2,2,6,6,6,6,6
0,0,0,2,2,2,2,2,2,5,5,5,5,2,2,4,4,4,2,2,2,2,2,2,0,0,0,2,2,2,2,2,2,2,2,2,2,2,2,2,2,2,2,2,2,2,2,2,2,6,6,6,6,6
0,0,0,2,2,2,2,2,2,2,5,5,5,2,2,4,4,4,2,2,2,2,2,2,0,0,0,2,2,2,2,2,2,2,2,2,2,2,2,2,2,2,2,2,2,2,2,2,2,2,6,6,6,6
0,0,0,9,2,2,2,2,2,2,2,5,2,2,2,2,2,2,2,2,2,2,2,2,0,0,0,7,7,2,2,2,2,2,2,2,2,2,2,2,2,2,2,2,2,2,2,2,2,2,6,6,6,6
0,0,0,2,2,2,2,2,2,2,2,2,2,2,2,2,2,2,2,2,2,2,2,2,0,0,0,7,7,2,2,2,2,2,2,2,2,2,2,2,2,2,2,2,2,2,2,2,2,2,6,6,6,6
0,0,0,2,7,2,2,2,2,2,2,2,2,2,2,2,2,2,2,2,2,7,7,7,0,0,0,7,7,2,5,2,2,2,2,6,2,2,2,2,2,2,2,2,2,2,2,2,2,2,2,6,6,6
0,0,0,2,7,2,3,3,2,2,2,2,2,2,2,2,2,2,2,2,7,7,7,7,0,0,0,7,7,2,2,2,2,2,2,6,6,2,2,2,2,2,2,2,2,2,2,2,2,2,2,2,6,6
0,0,0,2,7,7,3,3,2,2,2,2,2,2,2,2,2,2,2,2,7,7,7,7,0,0,0,7,2,2,2,2,2,2,2,6,6,6,2,2,2,2,2,2,2,2,2,2,2,6,6,6,6,2
24,0,24,2,7,7,2,2,2,2,2,2,2,2,2,2,2,2,2,2,2,7,7,7,24,0,24,7,2,2,2,2,2,2,2,6,6,6,2,2,2,2,2,2,2,2,2,2,6,6,6,6,6,6
0,0,0,2,7,7,2,2,2,2,2,2,2,2,2,2,2,2,2,2,2,2,2,2,0,0,0,0,0,33,21,2,2,2,2,6,6,6,6,2,2,2,2,2,2,2,2,6,6,6,6,6,6,6
0,0,5,2,7,2,2,2,2,2,2,2,2,2,2,2,2,2,2,2,2,2,2,2,0,0,0,0,0,33,21,2,2,2,2,6,6,6,6,2,2,2,2,2,2,2,2,6,6,6,6,6,6,6
0,0,0,2,7,2,2,2,2,2,2,2,2,2,2,2,2,2,2,2,2,2,2,0,0,0,0,0,0,33,21,2,2,2,2,6,6,6,6,2,2,2,2,2,2,2,6,6,6,6,6,6,6,6
0,0,0,2,2,2,2,2,2,2,2,2,2,2,2,2,2,2,2,2,2,2,0,0,0,0,0,0,22,22,22,2,2,2,2,34,5,6,6,2,2,2,2,2,2,2,6,6,6,6,6,10,6,6
5,0,5,2,2,2,2,2,2,2,2,3,2,2,2,2,2,2,2,2,2,0,0,0,0,0,0,0,23,0,0,0,0,2,2,34,34,5,6,7,7,7,7,2,6,6,6,6,8,2,2,7,7,6
5,5,0,2,2,2,2,2,2,2,2,3,2,2,2,2,2,2,2,2,2,0,0,0,0,0,0,0,25,0,0,0,0,0,2,34,34,5,6,7,7,7,7,7,6,6,6,6,8,3,7,7,7,7
0,5,5,2,0,0,0,0,0,0,0,0,0,0,0,0,0,0,0,0,31,0,0,0,0,0,0,0,0,0,0,0,0,0,2,34,34,34,6,7,7,7,7,7,6,6,6,6,7,7,7,7,7,6
0,0,5,9,0,0,0,0,0,0,0,0,0,0,0,0,0,0,0,0,0,0,0,0,0,0,0,0,0,0,0,0,0,0,22,2,34,34,6,6,7,7,7,7,6,6,6,6,7,7,7,7,7,6
0,0,0,2,0,0,0,0,0,0,2,2,2,2,2,2,2,2,2,0,0,0,0,0,0,0,0,0,0,0,0,0,0,0,0,2,34,34,6,6,6,2,2,6,6,6,6,7,7,7,7,7,7,6
0,0,0,2,0,0,0,0,2,2,2,2,2,2,2,2,2,2,2,2,0,0,0,0,0,0,0,0,0,0,0,0,0,0,22,7,6,6,6,6,6,6,2,6,6,6,6,7,7,7,2,2,2,2
0,0,0,2,0,0,8,0,0,7,2,2,2,2,2,2,2,2,2,2,2,2,2,2,0,0,0,0,0,0,0,0,0,0,22,21,6,5,6,6,6,6,6,6,6,6,6,2,2,2,2,2,2,2
24,0,24,2,0,0,8,0,0,7,6,6,6,2,2,2,2,2,2,2,2,2,2,2,0,0,0,0,0,0,0,0,0,0,2,2,6,6,6,6,6,6,6,6,6,6,6,2,2,2,2,2,2,2
0,0,0,2,0,0,0,0,0,7,6,6,6,6,2,2,2,2,2,8,2,2,0,0,0,0,0,0,0,0,0,0,0,28,2,2,6,6,6,6,6,6,6,6,6,6,6,2,2,2,2,2,2,2
0,0,0,5,0,0,0,0,0,2,6,6,6,6,2,2,2,2,2,2,2,2,0,0,0,0,0,0,0,0,0,0,0,2,2,2,2,6,6,6,6,6,6,6,6,6,2,2,2,2,2,2,2,2
0,0,0,2,0,0,0,0,2,2,2,6,6,2,2,2,2,2,2,2,2,2,0,0,0,0,0,0,0,0,0,2,2,2,2,2,2,6,6,6,6,6,6,6,6,6,6,2,2,2,2,2,2,2
0,0,0,5,2,2,0,2,2,2,2,2,2,2,2,2,2,2,2,2,2,2,2,0,0,0,5,0,2,2,2,2,2,2,2,2,6,6,6,6,6,6,6,6,6,6,6,2,2,2,2,2,2,2
0,0,0,2,2,2,2,2,2,2,2,2,2,2,2,2,2,2,2,2,2,2,2,2,2,2,2,3,2,8,8,2,2,2,6,6,6,6,6,6,6,6,6,6,6,6,6,2,2,2,2,2,2,2
0,0,0,2,2,2,2,2,2,2,2,2,2,2,2,7,7,2,2,2,2,2,2,2,2,2,2,2,2,8,8,2,2,2,6,6,6,6,6,6,6,6,6,6,6,6,2,2,2,2,2,2,2,2
0,0,0,2,2,2,2,2,2,2,2,2,2,2,7,7,7,2,2,2,2,2,2,2,2,2,2,2,2,2,2,2,2,6,6,6,6,6,6,6,6,6,6,6,6,2,2,2,2,2,2,2,2,2
24,0,24,2,2,2,2,2,2,2,2,2,2,2,7,7,7,2,2,2,2,2,2,2,2,2,2,2,2,2,2,2,6,6,6,6,6,6,6,6,6,6,6,6,6,6,2,2,2,2,2,2,2,2
0,0,0,2,2,2,2,2,2,2,2,2,2,2,7,7,2,2,2,2,2,2,2,2,3,2,2,2,2,2,2,2,6,6,6,6,6,6,2,2,6,6,6,6,6,6,2,2,6,6,6,2,2,6
0,0,0,2,2,2,2,2,2,2,2,2,2,2,7,2,2,2,2,2,2,2,2,2,2,2,2,2,2,2,2,2,6,6,6,6,6,2,2,6,6,6,6,6,6,6,2,2,6,6,2,2,2,2
0,0,0,2,2,2,2,2,2,2,2,2,2,7,2,2,2,2,2,2,2,2,2,2,2,2,2,2,2,2,2,6,6,6,6,6,2,2,2,6,6,6,6,6,6,2,2,2,2,2,2,2,2,2
2,2,2,2,2,2,2,2,2,2,2,2,2,2,2,2,2,2,2,2,2,2,2,2,2,2,2,2,2,2,2,6,6,6,6,6,2,2,6,6,6,6,6,6,6,2,2,2,2,2,2,2,2,2
2,2,2,2,2,2,2,2,2,2,2,2,2,2,2,2,2,2,2,2,2,2,2,2,2,2,2,2,2,2,6,6,6,6,6,6,2,6,6,6,6,6,6,6,2,2,2,2,2,2,2,2,2,2
0,2,2,2,2,2,2,2,5,5,5,2,2,2,2,2,2,2,2,2,2,2,2,2,2,2,2,2,2,2,6,6,6,6,6,6,6,6,6,6,6,6,6,6,5,5,5,5,2,2,2,2,2,2
0,2,2,2,3,2,2,5,5,5,5,2,2,2,2,2,2,2,2,2,2,2,2,2,2,2,2,2,2,2,6,6,6,6,6,6,6,6,6,6,6,6,6,5,5,5,5,5,5,2,2,2,2,2
0,2,2,2,5,2,5,5,2,5,2,2,2,2,2,2,2,2,2,2,2,2,2,2,8,8,2,2,2,2,6,6,6,6,6,6,6,6,6,6,6,6,2,2,2,5,5,5,5,2,2,2,2,2
0,2,2,2,5,5,5,5,2,2,2,2,2,2,2,2,2,2,2,2,2,2,2,2,8,8,2,2,2,2,2,2,2,2,6,6,6,6,6,2,2,2,2,2,2,2,2,2,2,2,2,2,2,2
0,2,2,2,5,5,5,5,9,2,2,2,2,2,2,2,2,2,2,2,2,2,2,2,2,2,2,2,2,2,2,2,2,2,2,2,2,2,2,2,2,2,2,2,2,2,2,2,2,7,7,7,2,2
0,2,2,2,4,4,2,9,9,2,2,2,2,2,2,2,2,2,2,2,2,2,2,2,2,2,2,2,2,2,2,2,2,2,2,2,2,2,2,2,2,2,2,2,2,2,2,2,7,7,7,7,2,2
0,2,2,2,4,2,2,2,2,2,2,2,2,2,2,2,2,2,2,2,2,2,2,2,2,2,2,2,2,2,2,2,2,2,2,2,2,2,2,2,2,2,2,2,2,2,2,7,7,7,7,7,2,2
0,0,2,2,2,2,2,2,2,2,2,2,2,2,2,2,2,2,2,2,2,2,2,2,2,2,2,2,2,2,2,2,2,2,2,2,2,2,2,2,2,2,2,2,2,2,7,7,7,7,7,2,2,2
0,0,2,2,2,2,2,34,6,2,2,2,2,2,2,2,2,2,2,2,2,2,2,2,2,2,2,2,2,2,2,2,2,2,2,2,2,2,2,2,2,2,2,2,2,2,7,7,7,7,2,2,2,2
0,2,2,2,2,2,2,2,2,2,2,2,2,2,2,2,2,2,2,2,2,2,2,2,2,2,2,2,2,2,2,2,2,2,2,2,2,2,2,2,2,2,2,2,2,2,2,2,2,2,2,2,2,2
2,2,0,0,0,0,0,0,0,0,0,0,0,0,0,0,0,0,0,0,0,0,0,0,0,0,0,0,2,2,2,2,2,2,2,2,2,2,2,2,2,2,2,2,2,2,2,2,2,2,2,2,2,2
2,2,0,0,0,0,0,0,0,0,0,0,0,0,0,0,0,0,0,0,0,0,0,0,0,0,0,0,2,2,2,2,2,2,2,2,2,2,2,2,2,2,2,2,2,2,2,2,2,2,2,2,2,2
:endlayer
layer: 9
5,5,2,2,2,2,2,2,2,2,2,2,2,2,2,2,2,2,2,2,2,2,0,0,0,0,0,2,6,6,6,6,4,4,2,2,2,2,2,2,2,2,2,2,2,2,2,2,2,2,2,2,2,2
24,24,2,2,2,2,2,2,2,2,2,2,2,2,2,2,2,2,2,2,2,2,2,2,0,0,0,2,6,6,6,4,4,4,8,8,2,2,2,2,2,2,2,2,2,2,2,2,2,2,2,2,2,2
0,0,9,2,2,2,2,2,2,2,2,2,2,2,2,2,2,2,2,2,2,2,2,2,0,0,0,2,6,6,2,2,2,2,8,8,2,2,2,2,2,2,2,2,2,2,2,2,2,2,2,2,2,2
0,0,5,2,2,2,2,2,2,2,2,2,2,2,2,2,2,2,2,2,2,2,2,2,0,0,0,2,6,2,2,2,2,2,2,2,2,2,2,2,2,2,2,2,2,2,2,2,2,2,3,2,2,2
0,5,0,9,9,2,2,2,2,2,2,2,2,2,2,2,2,2,2,2,2,2,2,2,0,0,0,2,2,2,2,2,2,2,2,2,2,2,2,2,2,2,2,2,2,2,2,2,2,2,2,3,6,6
0,0,0,2,2,2,2,2,2,2,2,2,2,2,2,2,2,2,7,7,7,2,2,2,22,22,22,2,2,2,2,3,2,2,2,2,2,2,2,2,2,2,2,2,2,2,2,2,2,2,2,6,6,6
24,0,24,2,2,2,2,2,2,2,0,0,2,2,2,2,2,2,7,7,7,2,2,2,0,0,0,2,2,2,2,2,2,2,2,2,2,2,2,2,2,2,2,2,2,2,2,2,2,2,2,6,6,6
0,0,0,2,2,2,2,2,2,2,0,0,2,2,2,2,2,2,7,7,2,2,2,2,0,0,0,2,2,2,2,2,2,2,2,2,2,2,2,2,2,2,2,2,2,2,2,2,2,2,6,6,6,6
0,0,0,2,2,2,2,2,2,2,5,5,2,2,2,2,2,2,7,7,2,2,2,2,0,0,0,2,2,2,2,2,2,2,2,2,2,2,2,2,2,2,2,2,2,2,2,2,2,2,6,6,6,6
0,0,0,9,2,2,2,2,2,2,5,5,2,2,2,2,2,2,2,2,2,2,2,2,0,0,0,2,2,2,2,2,2,2,2,2,2,2,2,2,2,2,2,2,2,2,2,2,2,2,6,6,6,6
0,0,0,9,34,2,2,2,2,2,2,2,2,2,2,2,2,8,2,2,2,2,2,2,0,0,0,5,5,2,2,2,2,2,2,2,2,2,2,2,2,2,2,2,2,2,2,2,2,2,6,6,6,6
0,0,0,2,34,2,2,2,2,2,2,2,2,2,2,2,2,2,2,2,2,2,2,2,0,0,0,7,7,5,5,2,2,2,2,2,2,2,2,2,2,2,2,2,2,2,2,2,2,2,2,6,6,6
0,0,0,9,34,2,2,2,2,2,2,2,2,2,2,2,2,2,2,2,2,2,2,2,0,0,0,7,7,5,5,5,2,2,2,2,2,2,2,2,2,2,2,2,2,2,2,2,2,2,2,6,6,6
0,0,0,0,0,0,2,2,2,2,2,2,2,2,2,2,2,2,2,2,2,2,2,7,0,0,0,7,7,5,5,5,5,2,2,2,2,2,2,2,2,2,2,2,2,2,2,2,2,2,2,2,6,6
0,0,0,0,0,0,2,2,2,2,2,2,2,2,2,2,2,2,2,2,2,7,7,7,0,0,0,7,2,5,5,5,5,2,2,2,2,2,2,2,2,2,2,2,2,2,2,2,2,2,2,2,2,2
0,0,0,9,9,7,2,2,2,2,2,2,2,2,2,2,2,2,2,2,2,7,7,7,0,0,0,2,34,34,34,5,5,2,2,2,2,2,2,2,2,2,2,2,2,2,2,2,2,2,2,2,2,2
24,0,24,2,7,7,2,2,2,2,2,2,2,2,2,2,2,2,2,2,2,2,2,2,22,22,22,2,34,34,34,34,34,2,2,2,2,2,2,2,2,2,2,2,2,2,2,2,2,6,6,2,2,0
0,0,0,2,7,7,2,2,2,2,2,2,2,2,2,2,2,2,2,2,2,2,2,2,0,0,0,0,0,0,0,0,2,2,2,2,6,6,2,2,2,2,2,2,2,2,2,2,6,0,0,0,0,0
0,0,0,2,7,2,2,2,2,2,2,2,2,2,2,2,2,2,2,2,2,2,2,2,0,0,0,0,0,0,0,0,2,2,2,2,6,6,2,2,2,2,2,2,2,2,2,0,0,0,0,0,0,0
0,0,0,2,7,2,2,2,2,2,2,2,2,2,2,2,2,2,2,2,2,2,2,0,0,0,0,0,0,0,0,0,0,0,0,2,6,6,2,2,2,2,2,2,2,2,6,18,0,0,0,0,0,0
0,0,0,2,2,2,2,2,2,2,2,2,2,2,2,2,2,2,2,2,2,2,0,0,0,0,0,0,35,26,26,26,26,36,0,0,5,6,2,2,2,2,2,2,2,2,10,10,0,0,0,0,0,0
0,0,0,9,2,2,2,2,2,2,2,2,2,2,2,2,2,2,2,2,2,0,0,0,0,0,0,0,0,0,0,0,0,37,36,0,0,5,7,7,7,7,2,2,6,6,6,6,2,2,2,2,7,0
0,0,0,2,2,2,2,2,2,2,2,2,2,2,2,2,2,2,2,2,2,0,0,0,0,0,0,0,0,0,0,0,0,0,25,0,0,5,7,7,7,7,7,2,6,6,6,6,2,2,2,7,7,0
0,0,0,2,0,0,0,0,0,0,0,0,0,0,0,0,0,0,0,0,31,0,0,0,0,0,0,0,0,0,0,0,0,0,25,0,0,0,7,7,7,7,7,2,6,6,6,6,7,7,7,7,7,0
0,0,0,2,0,0,0,0,0,0,0,0,0,0,0,0,0,0,0,0,0,0,0,0,0,0,0,0,0,0,0,0,0,0,0,0,0,0,2,2,7,7,7,6,6,6,6,6,7,7,7,7,7,0
0,0,0,2,0,0,0,0,2,2,2,2,2,2,2,2,2,2,2,2,0,0,0,0,0,0,0,0,0,0,0,0,0,0,0,38,38,38,7,6,2,2,2,6,6,6,6,6,7,7,7,2,2,2
0,0,0,2,0,0,0,0,7,7,7,2,2,2,2,2,2,2,2,2,0,0,0,0,0,0,0,0,0,0,0,0,0,0,22,2,34,34,6,6,6,2,2,6,6,6,6,2,2,2,2,2,2,2
0,0,0,2,0,0,0,0,0,7,7,2,2,2,2,2,2,2,2,2,2,2,2,2,0,0,0,0,0,0,0,0,0,0,22,2,2,5,6,6,6,6,2,6,6,6,6,2,2,2,2,2,2,2
24,0,24,2,0,0,0,0,0,7,2,34,34,6,2,2,2,2,8,8,2,2,2,2,0,0,0,0,0,0,0,0,0,0,2,2,2,6,6,6,6,6,6,6,6,6,6,2,2,2,2,2,2,2
0,0,0,2,0,0,0,0,0,7,34,34,34,34,2,2,2,2,8,8,2,0,0,0,0,0,0,0,0,0,0,0,0,14,20,2,2,6,6,6,6,6,6,6,6,6,6,2,2,2,2,2,2,2
0,0,0,5,0,0,0,0,0,7,6,34,34,34,2,2,2,2,2,2,2,2,0,0,0,0,0,0,0,0,0,0,0,2,2,2,2,6,6,6,6,6,6,6,6,6,2,2,2,2,2,2,2,2
0,0,0,2,0,0,0,0,0,2,2,6,34,2,2,2,2,2,2,2,2,2,0,0,0,0,0,0,0,0,0,2,2,2,2,2,2,6,6,6,6,6,6,6,6,6,2,2,2,2,2,2,2,2
0,0,0,5,0,0,0,0,2,2,2,2,2,2,2,2,7,2,2,2,2,2,2,0,0,0,2,2,2,2,2,2,2,2,2,2,6,6,6,6,6,6,6,6,6,6,2,2,2,2,2,2,2,2
0,0,0,2,0,0,2,2,2,2,2,2,2,2,2,7,7,7,2,2,2,2,2,2,2,2,2,3,2,2,2,2,2,2,6,6,6,6,6,6,6,6,6,6,6,6,2,2,2,2,2,2,2,2
0,0,0,2,2,2,2,2,2,2,2,2,2,2,7,7,7,7,2,2,2,2,2,2,2,2,2,3,2,2,2,2,2,6,6,6,6,6,6,6,6,6,6,6,6,6,2,2,2,2,2,2,2,2
0,0,0,2,2,2,2,2,2,2,2,2,2,2,7,7,7,7,2,2,2,2,2,2,2,2,2,2,2,2,2,2,2,6,6,6,6,6,6,6,6,6,6,6,6,6,2,2,2,2,2,2,2,2
24,0,24,2,2,2,2,2,2,2,2,2,2,7,7,7,7,2,2,2,2,2,2,3,3,2,2,2,2,2,2,2,6,6,6,6,6,6,6,6,6,6,6,6,6,6,2,2,2,2,2,2,2,2
0,0,0,2,2,2,2,2,2,6,6,6,2,7,7,7,7,2,3,3,2,2,2,3,3,2,2,2,2,2,2,2,6,6,6,6,6,6,2,2,2,6,6,6,6,6,2,2,2,2,2,2,2,6
0,0,0,9,2,2,2,2,2,2,6,6,2,7,7,7,2,2,3,3,2,2,2,2,2,2,2,2,2,2,2,6,6,6,6,6,6,2,2,2,6,6,6,6,6,6,2,2,2,2,2,2,2,2
0,0,0,2,2,2,2,2,2,6,6,6,7,7,7,2,2,2,2,2,2,2,2,2,2,2,2,2,2,2,2,6,6,6,6,6,5,2,2,6,6,6,6,6,6,6,2,2,2,2,2,2,2,2
5,5,5,2,2,2,2,2,6,6,6,6,2,7,7,2,2,2,2,2,2,2,2,2,2,2,2,2,2,2,2,6,6,6,6,6,9,9,6,6,6,6,6,6,6,6,2,2,2,2,2,2,2,2
24,24,24,2,2,2,2,6,6,6,6,6,2,7,2,2,2,2,2,2,2,2,2,2,6,6,6,6,6,6,6,6,6,6,6,6,6,6,6,6,6,6,6,6,6,6,2,2,2,2,2,2,2,2
0,0,5,2,3,3,6,6,6,6,6,2,2,2,2,2,2,2,2,2,2,2,2,5,6,6,6,6,6,6,6,6,6,6,6,6,6,6,6,6,6,6,6,6,6,2,2,2,2,2,2,2,2,2
0,0,0,2,3,3,6,6,6,6,2,2,2,2,2,2,2,2,3,2,2,2,2,2,6,6,6,6,6,6,6,6,6,6,6,6,6,6,6,6,6,6,6,6,2,2,5,2,2,2,2,2,2,2
0,0,0,2,2,2,6,34,34,34,2,2,2,2,2,2,2,2,2,2,2,2,2,2,8,8,6,6,6,6,6,6,7,7,6,6,6,6,6,6,6,6,6,2,2,2,2,2,2,2,2,2,2,2
0,0,0,2,2,2,34,5,34,34,2,2,2,2,2,2,2,2,2,2,2,2,2,2,8,8,2,2,2,2,2,2,7,7,7,6,6,6,6,6,2,2,2,2,2,2,2,2,2,2,2,2,2,2
0,0,0,2,4,4,5,5,5,5,2,2,2,2,2,2,2,2,2,2,2,2,2,2,2,2,2,2,2,2,2,2,2,2,2,8,8,2,2,2,2,2,2,2,2,2,2,2,2,2,2,2,2,2
0,0,0,2,4,4,5,5,34,34,2,2,2,2,2,2,2,2,2,2,2,2,2,2,2,2,2,2,2,2,2,2,2,2,2,8,8,2,2,2,2,2,2,2,2,2,2,2,2,7,7,2,2,2
0,24,24,2,4,2,34,34,34,34,2,2,2,2,2,2,2,2,2,2,2,2,2,2,2,2,2,2,2,2,2,2,2,2,2,2,2,2,2,2,2,2,2,2,2,2,2,2,2,7,2,2,2,2
0,0,0,2,2,2,34,34,34,34,2,2,2,2,2,2,2,2,2,2,2,2,2,2,2,2,2,2,2,2,2,2,2,2,2,2,2,2,2,2,2,2,2,2,2,2,2,2,7,7,2,2,2,2
0,0,2,2,2,2,2,34,34,34,2,2,2,2,2,2,2,2,2,2,2,2,2,2,2,2,2,2,2,2,2,2,2,2,2,2,2,2,2,2,2,2,2,2,2,2,2,2,2,2,2,2,2,2
0,0,2,2,2,2,2,2,2,2,2,2,2,2,2,2,2,2,2,2,2,2,2,2,2,2,2,2,2,2,2,2,2,2,2,2,2,2,2,2,2,2,2,2,2,2,2,2,2,2,2,2,2,2
0,0,0,0,0,0,0,0,0,0,0,0,0,0,0,0,0,0,0,0,0,0,0,0,0,0,0,0,2,2,2,2,2,2,2,2,2,2,2,2,2,2,2,2,2,2,2,2,2,2,2,2,2,2
0,0,0,0,0,0,0,0,0,0,0,0,0,0,0,0,0,0,0,0,0,0,0,0,0,0,0,0,2,2,2,2,2,2,2,2,2,2,2,2,2,2,2,2,2,2,2,2,2,2,2,2,2,2
:endlayer
layer: 10
5,5,24,0,0,0,0,0,0,0,0,0,0,0,0,0,0,0,0,0,0,0,0,0,0,0,0,0,0,0,0,0,4,4,2,2,2,2,2,2,2,2,2,2,2,2,2,2,2,2,2,2,2,2
24,24,2,2,2,2,2,2,2,2,2,2,2,2,2,2,2,2,2,2,2,2,2,2,4,2,2,2,0,0,0,0,4,4,8,2,2,2,2,2,2,2,2,2,2,2,2,2,2,2,2,2,2,2
0,0,9,2,2,2,2,2,2,2,2,2,2,2,8,2,2,2,2,2,2,2,2,2,4,4,4,2,0,0,2,2,4,2,10,2,2,2,2,2,2,2,2,2,2,2,2,2,2,2,2,2,2,2
0,0,5,2,2,2,2,2,2,2,2,2,2,8,2,2,2,2,2,7,7,2,2,2,2,4,4,4,2,2,2,2,2,10,2,2,2,2,2,2,2,2,2,2,2,2,2,2,2,2,2,2,2,2
0,5,0,9,9,9,2,2,2,2,2,2,2,2,2,2,2,2,7,7,7,2,2,2,2,2,4,4,2,2,2,2,2,2,2,2,2,2,2,2,2,2,2,2,2,2,2,2,2,2,2,2,2,2
0,0,0,2,2,2,2,2,2,2,2,2,2,2,2,2,2,2,7,7,7,2,2,2,2,2,2,2,2,2,2,2,2,2,2,2,2,2,2,2,2,2,2,2,2,2,2,2,2,2,2,2,2,0
22,22,22,2,2,2,2,2,2,2,2,2,2,2,0,0,2,7,7,7,7,7,2,2,2,2,2,2,2,2,2,2,3,2,2,2,2,2,2,2,2,2,2,2,2,2,2,2,2,2,2,2,0,0
0,0,0,2,2,2,2,2,2,2,2,2,2,0,0,0,0,0,0,7,7,2,2,2,2,2,2,2,2,2,2,2,2,2,2,2,2,2,2,2,2,2,2,2,2,2,2,2,2,2,2,2,0,0
0,0,0,9,2,2,2,0,0,0,2,2,2,0,0,0,0,0,0,0,7,2,2,2,2,2,2,2,2,2,2,2,2,2,2,2,2,2,2,2,2,2,2,2,0,2,2,2,2,2,2,2,0,0
0,0,0,2,0,0,0,0,39,0,0,0,2,2,0,0,0,0,0,0,0,2,2,2,2,2,2,2,2,2,2,2,2,2,2,2,2,2,2,2,2,2,2,2,0,2,2,2,2,2,2,0,0,0
0,0,0,2,0,40,0,0,0,0,0,0,0,2,2,0,0,0,0,0,2,2,2,2,2,5,5,5,5,5,2,2,2,2,2,2,2,2,2,2,2,2,2,2,0,0,2,2,2,2,2,0,0,0
0,0,0,2,0,0,0,0,0,0,0,0,2,2,2,2,0,0,0,2,2,2,2,2,2,5,5,5,5,5,5,5,2,2,2,2,2,2,2,2,2,2,2,2,0,0,2,2,2,2,2,0,10,10
0,0,0,9,0,0,41,0,0,42,0,2,2,2,2,2,2,2,2,2,2,2,2,2,2,2,7,7,5,5,5,5,5,2,2,2,2,2,2,2,2,2,2,2,0,2,2,2,2,2,2,2,10,0
0,0,0,0,0,0,0,0,0,0,2,2,2,2,2,2,2,2,2,2,2,2,2,2,2,7,7,7,5,5,5,0,0,5,2,2,2,2,2,2,2,2,2,2,2,2,2,2,2,2,2,2,2,2
0,0,0,0,0,0,0,2,2,2,2,2,2,2,2,2,2,2,2,2,2,2,2,2,2,2,7,2,2,5,5,0,0,5,2,2,2,2,2,2,2,2,2,2,2,2,0,0,2,2,2,2,2,2
0,0,0,9,9,2,2,2,2,2,2,2,2,2,2,2,2,2,2,2,2,2,2,2,2,2,2,2,0,0,0,0,0,5,2,2,2,2,2,2,2,2,2,2,2,0,0,0,0,2,2,2,2,2
22,22,22,2,7,7,2,2,2,2,2,2,2,2,2,2,2,2,2,2,2,2,2,2,2,2,2,2,0,0,0,0,0,2,2,2,2,2,2,2,2,2,2,2,2,0,0,0,0,0,2,2,2,10
0,0,0,2,7,2,2,2,2,3,2,2,2,2,2,2,2,2,2,2,0,0,0,2,2,2,0,0,0,0,0,0,2,2,2,2,2,2,2,2,2,2,2,2,2,0,0,0,0,0,0,0,0,0
0,0,0,2,7,2,2,2,2,2,2,2,2,2,2,2,2,2,2,2,0,0,0,2,0,0,0,0,0,0,0,0,2,2,2,2,2,2,2,2,2,2,2,2,2,2,0,0,0,0,0,0,0,0
0,0,0,9,7,2,2,2,2,2,2,2,2,2,2,2,2,2,2,2,0,0,2,0,0,0,0,0,0,0,0,0,0,0,0,2,2,2,2,2,2,2,2,2,2,2,2,0,0,0,0,0,0,0
0,0,0,2,2,2,2,2,2,2,2,2,2,2,2,2,2,2,2,2,2,2,0,0,0,0,0,0,0,0,0,0,0,0,0,0,2,2,2,2,2,2,2,2,2,2,0,0,0,0,0,0,0,0
0,0,0,2,2,2,2,2,2,2,2,2,2,2,2,2,2,2,2,2,2,0,0,0,0,0,0,0,0,0,0,0,0,0,0,0,0,2,2,2,2,2,2,2,2,0,0,8,2,2,2,2,2,0
0,0,0,2,2,2,2,2,2,2,2,2,2,2,2,2,2,2,2,2,2,0,0,0,0,0,0,0,0,0,0,0,0,0,0,0,0,2,2,2,2,2,2,2,0,0,0,2,2,2,2,2,7,0
0,0,0,2,0,0,2,2,2,2,2,2,2,2,2,2,2,2,2,2,31,0,0,0,0,0,0,0,0,0,0,0,0,0,0,0,0,0,2,2,2,2,2,2,0,0,0,2,2,2,2,7,7,0
0,0,0,9,0,0,2,2,2,2,2,2,2,2,2,2,2,2,2,2,0,0,0,0,0,0,0,0,0,0,0,0,0,0,0,0,0,0,2,2,2,2,2,2,0,0,0,2,2,2,2,2,7,0
0,0,0,2,0,0,2,2,2,2,2,2,2,2,2,2,2,2,2,2,0,0,0,0,0,0,0,0,0,0,0,0,0,0,0,0,0,0,2,2,2,2,2,2,0,0,0,2,2,2,2,2,2,0
0,0,0,2,0,0,2,2,7,7,7,2,2,2,2,2,2,2,2,2,0,0,0,0,0,0,0,0,0,0,0,0,0,0,0,38,38,38,2,2,2,2,2,0,0,0,0,2,2,2,2,2,2,10
0,0,0,2,0,0,0,0,0,7,7,0,21,19,2,2,2,2,2,2,2,2,2,0,0,0,0,0,0,0,0,0,0,0,22,2,2,2,2,2,2,2,2,0,0,0,0,2,2,2,2,2,2,2
22,22,22,2,0,0,0,0,0,7,2,0,0,21,0,0,2,2,8,2,2,2,2,0,0,0,0,0,0,0,0,0,0,0,2,2,2,2,2,2,2,2,2,0,0,0,0,2,2,2,2,2,2,2
0,0,0,2,0,0,0,0,0,7,0,0,0,0,0,0,2,2,2,2,2,0,0,0,0,0,0,0,0,0,0,0,0,0,2,2,2,2,2,2,2,2,2,0,0,0,0,2,2,2,2,2,2,2
0,0,0,2,0,0,0,0,0,7,2,0,0,0,0,2,2,2,2,2,2,0,0,0,0,0,0,0,0,0,0,0,0,2,2,2,2,2,2,0,0,0,0,0,0,0,2,2,2,2,2,2,2,2
0,0,0,2,0,0,0,0,0,2,2,2,0,2,2,2,2,2,2,2,2,2,0,0,0,0,0,0,0,0,0,2,2,2,2,2,2,2,0,0,0,0,0,0,0,0,2,2,2,2,2,2,2,2
0,0,0,2,0,0,0,0,2,2,2,2,2,2,2,2,7,2,2,2,2,2,2,22,22,22,2,2,2,2,2,2,2,2,2,2,0,0,0,0,0,0,0,0,2,2,2,2,2,2,2,2,2,2
0,0,0,2,0,0,2,2,2,2,2,2,2,2,2,7,7,7,2,2,2,2,2,2,2,2,2,2,2,2,2,2,2,2,2,0,0,0,0,0,0,0,0,0,0,2,2,2,2,2,2,2,2,2
0,0,0,2,2,2,2,2,2,2,2,2,2,2,7,7,7,7,2,2,2,2,2,2,2,2,5,2,2,2,2,2,2,2,0,0,0,0,0,0,0,0,0,0,0,2,2,2,2,2,2,2,2,2
0,0,0,2,2,2,2,2,2,2,2,2,2,2,7,7,7,7,2,2,2,2,2,2,2,2,5,2,2,2,2,2,2,0,0,0,0,0,0,0,0,0,0,0,0,2,2,2,2,2,2,2,2,2
22,22,22,2,2,2,2,2,2,2,2,2,2,7,7,7,7,2,2,2,2,2,2,3,2,2,2,2,2,2,2,2,0,0,0,0,0,0,0,0,0,0,0,0,0,2,2,2,2,2,2,2,2,2
0,0,0,2,2,2,2,2,2,0,0,0,2,7,7,7,7,2,2,2,2,2,2,2,2,2,2,2,2,2,2,2,0,0,0,0,0,0,2,2,2,2,0,0,0,0,2,2,2,2,2,2,2,2
0,0,0,2,2,2,2,2,2,0,0,0,2,7,7,7,2,2,2,2,2,2,2,2,2,2,2,2,2,2,2,0,0,0,0,0,0,2,2,10,2,2,0,0,0,0,2,2,2,2,2,2,2,2
0,0,0,9,2,2,2,2,2,0,0,0,7,7,7,2,2,2,2,2,2,2,2,2,2,2,2,2,2,2,2,0,0,0,0,0,5,10,10,2,0,0,0,0,0,0,2,2,2,2,2,2,2,2
5,5,5,9,2,2,2,2,0,0,0,0,2,7,7,0,0,2,2,2,2,0,2,2,0,0,2,2,2,2,2,0,0,0,0,0,9,9,2,0,0,0,0,0,0,0,2,2,2,2,2,2,2,2
24,24,24,9,2,2,2,0,0,0,0,0,2,7,2,2,2,2,2,0,0,5,5,0,0,0,0,0,0,0,0,0,0,0,0,0,0,0,0,0,0,0,0,0,0,0,2,2,2,2,2,2,2,2
0,0,5,2,2,3,0,0,0,0,0,0,0,0,2,2,2,2,2,0,0,5,5,5,0,0,0,0,0,0,0,0,0,0,0,0,0,0,0,0,0,0,0,0,0,2,2,2,2,2,2,2,2,2
0,0,0,2,2,2,0,0,0,0,0,0,0,0,2,2,2,2,2,0,0,5,5,5,0,0,0,0,0,0,0,0,0,0,0,0,0,0,0,0,0,0,0,0,2,2,2,2,2,2,2,2,2,2
0,0,0,2,2,2,0,0,0,0,0,2,0,0,2,2,2,2,2,2,2,0,0,0,0,0,0,0,0,0,0,0,0,0,0,0,0,0,0,0,0,0,0,2,2,2,2,2,2,2,2,2,2,2
0,0,0,2,2,2,0,0,0,0,0,2,0,0,2,2,2,2,2,2,2,0,0,0,0,0,0,0,2,2,2,2,7,7,0,0,0,0,0,0,2,2,2,2,2,2,2,2,2,2,2,2,2,2
0,0,0,2,2,2,0,0,0,0,0,2,0,0,0,2,2,2,2,2,2,0,0,0,0,0,0,0,2,2,2,2,2,0,0,43,0,0,7,0,2,2,2,2,2,2,2,2,2,2,2,2,2,2
0,0,0,2,2,2,0,0,0,0,0,2,0,0,0,2,2,2,2,2,2,2,2,2,0,0,0,0,2,2,2,2,2,2,2,2,2,2,2,0,0,0,0,0,0,0,0,0,0,0,0,0,0,0
0,24,24,2,2,2,0,0,0,0,0,2,0,0,0,2,2,2,2,2,2,2,2,2,2,0,0,0,2,2,2,2,2,2,2,2,2,2,2,2,2,2,0,2,2,2,2,2,0,2,2,2,2,2
0,0,0,2,2,2,0,0,0,0,0,2,2,0,2,2,2,2,2,2,2,2,2,3,3,0,0,0,2,2,2,2,2,2,2,2,2,2,2,2,2,2,0,2,2,2,2,2,0,2,2,2,2,2
0,0,2,2,2,2,2,0,0,0,0,2,2,2,2,2,2,2,2,2,2,2,2,2,2,2,0,0,44,2,2,2,2,2,45,0,2,2,2,2,2,2,0,2,2,2,2,2,0,2,2,2,2,2
0,0,2,2,2,2,2,2,2,2,2,2,2,2,2,2,2,2,2,2,2,2,2,2,2,2,2,2,2,2,2,2,2,2,2,2,2,2,2,2,2,2,2,2,2,2,2,2,2,2,2,2,2,2
0,0,0,0,0,0,0,0,0,0,0,0,0,0,0,0,0,0,0,0,0,0,0,0,0,0,0,0,2,2,2,2,2,2,2,2,2,2,2,2,2,2,2,2,2,2,2,2,2,2,2,2,2,2
0,0,0,0,0,0,0,0,0,0,0,0,0,0,0,0,0,0,0,0,0,0,0,0,0,0,0,0,2,2,2,2,2,2,2,2,2,2,2,2,2,2,2,2,2,2,2,2,2,2,2,2,2,2
:endlayer
layer: 11
5,5,24,0,0,0,0,0,0,0,0,0,0,0,0,0,0,0,0,0,0,0,0,0,0,0,0,0,7,0,0,0,4,2,2,2,2,2,2,2,2,2,2,2,2,2,2,2,2,2,2,2,2,2
2,2,2,2,2,2,2,2,2,2,2,2,2,2,2,2,2,2,2,2,2,2,2,2,2,2,2,2,0,0,0,7,4,2,2,2,2,2,2,2,2,2,2,2,2,2,2,2,2,2,2,2,2,2
2,2,2,2,2,2,2,2,2,2,2,2,2,2,8,2,2,2,2,2,2,2,2,2,2,2,2,2,2,2,2,2,2,2,10,2,2,2,2,2,2,2,2,2,2,2,2,2,2,2,2,2,2,2
2,2,2,2,2,2,2,2,2,2,2,2,2,8,2,2,2,2,2,7,7,2,2,2,2,2,4,4,2,2,2,2,2,10,2,2,2,2,2,2,2,2,2,2,2,2,2,2,2,2,2,2,2,2
2,5,2,2,2,2,2,2,2,2,2,2,2,2,2,2,2,2,7,7,7,2,2,2,2,2,2,4,2,2,2,2,2,2,2,2,2,2,2,2,2,2,2,2,2,2,2,2,2,2,2,2,2,2
2,2,2,2,2,2,2,2,2,2,2,0,0,0,0,0,2,7,7,7,7,7,0,2,2,2,2,2,2,2,2,2,2,2,2,2,2,2,2,2,2,2,2,2,2,2,2,2,2,2,2,2,2,10
2,2,2,2,2,2,2,2,2,2,2,2,0,0,0,0,0,7,0,0,0,0,0,0,0,2,2,2,2,2,2,2,3,2,2,2,2,2,2,2,2,2,2,2,2,2,2,2,2,2,2,2,0,0
2,2,2,2,2,2,2,2,2,2,2,2,0,0,0,0,0,0,0,0,0,0,0,0,0,2,2,2,2,2,2,2,2,2,2,2,2,2,2,2,2,2,2,2,0,2,2,2,2,2,2,10,0,0
2,2,2,2,0,0,0,0,0,0,0,0,2,0,0,0,0,0,0,0,0,0,0,0,0,2,2,2,2,2,2,2,2,2,2,2,2,2,2,2,2,2,2,2,0,2,2,2,2,2,2,2,0,0
2,2,2,2,0,0,0,0,0,0,0,0,2,0,0,0,0,0,0,0,0,0,0,0,2,2,2,2,2,2,2,2,2,2,2,2,2,2,2,2,2,2,2,2,0,0,2,2,8,8,10,0,0,0
2,2,2,2,0,0,0,0,0,0,0,0,0,2,0,0,0,0,0,0,0,2,2,2,2,2,2,5,5,2,2,2,2,2,2,2,2,2,2,2,2,2,2,2,0,0,2,2,8,8,2,0,0,0
2,2,2,2,0,0,0,0,0,0,0,0,2,2,2,0,0,0,0,0,2,2,2,2,2,2,5,5,5,5,5,2,2,2,2,2,2,2,2,2,2,2,2,2,0,0,0,2,2,2,2,0,0,0
2,2,2,2,0,0,0,0,0,0,0,0,2,2,2,0,0,0,0,0,2,2,2,2,2,2,5,5,5,5,5,0,0,2,2,2,2,2,2,2,2,2,2,2,0,0,0,2,2,2,2,0,0,0
2,2,0,0,0,0,0,0,0,0,0,0,2,2,2,2,0,0,0,0,0,2,2,2,2,2,2,2,5,5,5,0,0,0,2,2,2,2,2,2,2,2,2,2,0,0,0,2,2,7,2,2,0,0
2,2,0,0,0,0,0,0,0,0,2,2,2,2,2,2,0,0,0,0,0,2,2,2,2,2,2,2,2,5,5,0,0,0,2,2,2,2,2,2,2,2,2,2,0,0,0,0,2,7,7,7,2,2
2,2,2,2,2,2,2,2,2,2,2,2,2,2,2,2,2,0,0,0,0,0,2,2,2,2,2,2,0,0,0,0,0,5,2,2,2,2,2,2,2,2,2,2,0,0,0,0,0,7,7,7,7,2
2,2,2,2,2,2,2,2,2,2,2,2,2,2,2,2,2,2,0,0,0,0,0,2,2,2,2,2,0,0,0,0,0,2,2,2,2,2,2,2,2,3,2,2,0,0,0,0,0,0,0,7,7,2
2,2,2,2,2,2,2,2,2,3,3,2,2,2,2,2,2,2,2,0,0,0,0,2,2,2,0,0,0,0,0,0,2,2,2,2,2,2,2,2,2,2,2,2,2,0,0,0,0,0,0,0,0,0
2,2,2,2,2,2,2,2,2,3,3,2,2,2,2,2,2,2,2,0,0,0,0,2,0,0,0,0,0,0,0,0,2,2,2,2,2,2,2,2,2,2,2,2,2,5,0,0,0,0,0,0,0,0
2,2,2,2,2,2,2,2,2,2,2,2,2,2,2,2,2,2,2,0,0,0,5,0,0,0,0,0,0,0,0,0,0,0,0,2,2,2,2,2,2,2,2,2,2,2,2,2,0,0,0,0,0,0
2,2,2,2,2,2,2,2,2,2,2,2,2,2,2,2,2,2,2,0,0,5,0,0,0,0,0,0,0,0,0,0,0,0,0,0,2,2,2,2,2,2,2,2,2,2,2,2,0,0,0,0,0,0
2,2,2,2,2,2,2,2,2,2,2,2,2,2,2,2,2,2,2,2,2,0,0,0,0,0,0,0,0,0,0,0,0,0,0,0,0,2,2,2,2,2,2,2,2,2,2,2,2,2,2,2,2,0
2,2,2,2,2,2,2,2,2,2,2,2,2,2,2,2,2,2,2,2,2,0,0,0,0,0,0,0,0,0,0,0,0,0,0,0,0,2,2,2,2,2,2,2,0,2,2,2,2,2,2,2,2,0
2,2,2,2,0,0,2,2,2,2,2,2,2,2,2,2,2,2,28,14,29,0,0,0,0,0,0,0,0,0,0,0,0,0,0,0,0,0,2,2,2,2,2,0,2,2,2,2,2,2,2,2,2,0
2,2,2,2,0,0,2,2,2,2,2,2,0,11,2,2,2,2,2,2,0,0,0,0,0,0,0,0,0,0,0,0,0,0,0,0,0,0,2,2,2,2,2,0,0,2,2,2,2,2,2,2,2,0
2,2,2,2,0,0,2,2,2,2,2,2,0,18,2,2,2,2,2,21,0,0,0,0,0,0,0,0,0,0,0,0,0,0,0,0,0,0,2,2,2,2,0,0,0,2,2,2,2,2,2,2,2,0
2,2,2,2,0,0,2,2,2,2,2,2,0,16,2,2,2,2,2,21,0,0,0,0,0,0,0,0,0,0,0,0,0,0,0,0,0,0,0,0,0,0,0,0,0,0,2,2,2,2,2,2,2,10
2,2,2,2,0,0,2,0,7,7,2,0,0,17,0,0,7,5,5,2,0,2,2,0,0,0,0,0,0,0,0,0,0,0,25,0,0,0,0,0,0,0,0,0,0,2,2,2,2,2,2,2,2,2
2,2,2,2,0,0,0,0,0,7,2,0,0,0,0,0,7,5,5,5,0,2,2,0,0,0,0,0,0,0,0,0,0,0,25,0,0,0,24,0,0,0,0,0,0,0,2,2,2,4,2,2,2,2
2,2,2,2,0,0,0,0,7,7,2,0,0,0,0,0,7,5,5,5,5,0,0,0,0,0,0,0,0,0,0,0,0,0,25,0,0,2,2,2,2,0,0,0,0,0,2,2,2,4,10,2,2,2
2,2,2,2,0,0,0,0,7,2,2,0,0,0,0,0,7,5,2,2,2,0,0,0,0,0,0,0,0,0,0,0,0,35,46,0,0,2,2,2,2,2,2,0,0,0,2,2,4,4,2,10,2,2
2,2,2,2,0,0,0,0,2,2,2,2,0,0,2,2,2,2,2,2,2,2,0,0,0,0,0,0,0,0,0,35,26,46,0,0,2,2,2,2,0,0,0,0,0,2,2,2,2,2,2,2,2,2
2,2,2,2,2,2,0,2,2,2,2,2,2,2,2,2,2,2,2,2,2,2,2,0,0,22,22,22,22,47,26,46,0,0,0,2,2,2,2,0,0,0,3,3,2,2,2,2,2,2,2,2,2,2
2,2,2,2,2,2,2,2,2,2,2,2,2,2,2,2,2,2,2,2,2,2,2,2,2,5,2,48,0,0,0,0,0,0,2,2,2,2,2,0,2,2,2,2,2,2,2,2,2,2,2,2,2,2
2,2,2,2,2,2,2,2,2,2,2,2,2,2,2,7,7,2,2,2,2,2,2,5,5,5,5,48,0,0,0,0,2,2,2,0,0,0,2,0,0,0,0,0,2,2,2,2,2,2,2,2,2,2
2,2,2,2,2,2,2,2,2,2,2,2,2,2,7,7,7,2,2,2,2,2,5,5,5,2,5,2,2,24,0,0,2,2,0,0,0,0,0,0,0,0,0,0,2,2,2,2,2,2,2,2,2,2
2,2,2,2,2,2,2,2,2,2,2,2,2,2,7,7,7,2,2,2,2,2,2,5,2,2,2,2,2,0,0,0,2,0,0,0,0,0,0,0,0,0,0,0,2,2,2,2,2,2,2,2,2,2
2,2,2,2,2,2,2,2,2,0,0,0,2,2,7,7,2,2,2,2,2,2,2,2,2,2,2,2,2,0,0,0,0,0,0,0,0,2,2,2,2,2,0,0,0,2,2,2,2,2,2,2,2,2
2,2,2,2,2,2,2,2,2,0,0,0,2,2,7,2,2,2,2,2,2,2,2,2,2,2,2,2,2,0,0,0,0,0,0,0,2,10,10,10,2,2,0,0,0,2,2,2,2,2,2,2,2,2
2,2,2,2,2,2,2,2,2,0,0,0,2,7,0,0,0,2,2,2,2,2,2,2,2,2,2,2,0,0,0,0,0,0,0,0,5,10,10,10,2,2,0,0,0,0,2,2,2,2,2,2,2,2
2,2,2,2,2,2,2,2,0,0,0,0,2,0,0,0,0,0,0,0,0,0,2,0,0,2,2,2,5,38,38,0,0,0,0,0,5,2,2,2,2,2,0,0,0,2,2,2,2,2,2,2,2,2
2,2,2,2,2,2,2,0,0,0,0,0,0,0,0,0,2,0,0,0,0,5,5,0,0,0,0,0,2,49,49,0,0,0,0,0,0,2,0,2,0,0,0,0,0,2,2,2,2,2,2,2,2,2
2,2,2,2,2,2,2,0,0,0,0,0,0,0,0,2,2,0,0,0,0,5,5,5,0,0,0,0,0,49,49,0,0,0,0,0,0,0,0,0,0,0,0,0,2,2,2,2,2,2,2,2,2,2
2,2,2,2,2,2,0,0,0,0,0,0,0,0,0,2,2,0,0,0,0,5,5,5,0,0,0,0,0,49,49,0,0,0,0,0,0,0,0,0,0,0,0,0,2,2,2,2,2,2,2,2,2,2
2,2,2,2,2,2,0,0,0,0,0,2,0,0,0,2,0,0,0,0,0,0,0,0,0,0,0,0,2,49,49,0,0,0,0,0,0,0,0,0,0,0,2,2,2,2,2,2,2,2,2,2,2,2
2,2,2,2,2,2,0,0,0,0,0,2,0,0,0,0,0,0,0,0,0,0,0,0,0,0,0,0,2,27,27,0,7,7,0,0,0,0,0,0,2,2,2,2,2,2,2,2,2,2,2,2,2,2
2,2,2,2,2,2,0,0,0,0,0,2,0,0,0,0,0,0,0,0,0,0,0,0,0,0,0,0,2,0,0,0,2,0,0,0,0,7,0,0,2,2,2,2,2,2,2,2,2,2,2,2,2,2
2,2,2,2,2,2,0,0,0,0,0,2,0,0,0,2,2,2,2,2,2,2,2,2,0,0,0,0,2,0,0,0,7,7,2,2,2,2,2,0,0,0,0,0,0,0,0,0,0,0,0,0,0,0
2,2,2,2,2,2,0,0,0,0,0,2,0,0,0,2,2,2,2,2,2,2,2,2,2,0,0,0,2,0,0,0,45,45,2,2,2,2,2,2,2,2,0,2,2,2,2,2,0,2,2,2,2,2
0,0,2,2,2,2,2,0,0,0,0,2,2,43,9,2,2,2,2,2,2,2,2,2,2,0,0,0,2,0,0,0,45,45,45,45,2,2,2,2,2,2,0,2,2,2,2,2,0,2,2,2,2,2
0,0,2,2,2,2,2,0,0,0,0,2,2,2,2,2,2,2,2,2,2,2,2,3,3,2,0,0,0,0,0,0,45,45,0,0,45,2,2,2,2,2,0,2,2,2,2,2,0,2,2,2,2,2
2,2,2,2,2,2,2,2,2,2,2,2,2,2,2,2,2,2,2,2,2,2,2,2,2,2,2,2,2,0,0,0,0,2,2,2,2,2,2,2,2,2,2,2,2,2,2,2,2,2,2,2,2,2
2,2,2,2,2,2,2,2,2,2,2,2,2,2,2,2,2,2,2,2,2,2,2,2,2,2,2,2,2,0,0,0,0,2,2,2,2,2,2,2,2,2,2,2,2,2,2,2,2,2,2,2,2,2
2,2,2,2,2,2,2,2,2,2,2,2,2,2,2,2,2,2,2,2,2,2,2,2,2,2,2,2,2,0,0,0,0,2,2,2,2,2,2,2,2,2,2,2,2,2,2,2,2,2,2,2,2,2
:endlayer
layer: 12
2,5,2,2,2,2,0,2,2,2,0,2,2,2,2,2,2,0,2,2,0,2,2,2,2,2,2,0,0,0,0,0,0,0,0,0,0,0,0,0,0,0,0,0,0,0,2,2,2,2,2,2,2,2
2,2,2,2,2,2,2,2,2,2,2,2,2,2,2,2,2,2,2,2,2,2,2,2,2,2,2,2,2,7,7,7,0,0,0,0,0,0,0,0,0,0,0,0,2,2,2,2,2,2,2,2,2,2
2,2,2,2,2,2,2,2,2,2,2,2,2,2,2,2,2,2,2,2,2,2,2,2,2,2,2,2,2,2,2,2,2,2,2,2,2,2,2,2,2,2,2,2,2,2,2,2,2,2,2,2,2,2
2,2,2,2,2,2,2,2,2,3,3,2,2,2,2,2,2,2,2,2,2,2,2,2,2,2,2,2,2,2,2,2,2,2,2,2,2,2,2,2,2,2,2,2,2,2,2,2,2,2,2,2,2,2
2,5,2,2,2,2,2,2,2,3,3,2,2,2,2,2,2,2,2,7,2,2,2,2,2,2,2,2,2,2,2,2,2,2,2,2,3,2,2,2,2,2,2,2,2,2,2,2,2,2,2,2,2,2
2,2,2,2,2,2,2,2,2,2,0,0,0,0,0,0,2,2,7,7,7,0,0,0,2,2,2,2,2,2,2,2,2,2,2,2,2,2,8,8,2,2,2,2,2,2,2,2,2,2,2,2,2,2
2,2,2,2,2,2,2,2,2,2,2,0,0,0,0,0,0,2,0,0,0,0,0,0,0,2,2,2,2,2,2,2,2,2,2,2,2,2,8,8,2,2,2,2,2,2,2,2,2,2,2,2,2,0
2,2,2,2,2,2,2,2,0,0,0,0,0,0,0,0,0,0,0,0,0,0,0,0,0,0,0,2,0,0,2,2,2,2,2,2,2,2,2,2,2,2,2,2,0,2,2,2,2,2,2,2,0,0
2,2,2,2,0,0,0,0,0,0,0,0,2,0,0,0,0,0,0,0,0,0,0,0,0,0,0,0,0,0,0,2,2,2,2,2,2,2,2,2,2,2,2,2,0,2,2,2,2,2,2,2,0,0
2,2,2,2,0,0,0,0,0,0,0,0,2,0,0,0,0,0,0,0,0,0,0,0,0,0,0,0,0,0,0,0,0,2,2,2,2,2,2,2,2,2,2,2,0,0,2,2,8,8,2,2,0,0
2,2,2,2,0,0,0,0,0,0,0,0,2,2,0,0,0,0,0,0,0,0,2,2,0,0,0,0,0,0,0,0,0,0,0,2,2,2,2,2,2,2,2,2,0,0,2,2,8,4,2,0,0,0
2,2,2,2,0,0,0,0,0,0,0,0,2,2,2,0,0,0,0,0,2,2,2,2,0,0,0,0,0,0,0,0,0,0,0,0,2,2,2,2,2,7,7,7,0,0,0,4,4,4,0,0,0,0
2,2,2,2,0,0,0,0,0,0,0,0,2,2,2,0,0,0,0,0,2,2,2,2,2,2,0,0,2,0,0,0,0,0,0,0,2,2,2,2,2,7,7,7,0,0,0,4,7,0,0,0,0,0
2,2,2,2,0,0,0,0,0,0,0,0,2,2,2,2,0,0,0,0,0,2,8,2,2,2,2,2,2,5,5,0,0,0,0,2,2,2,2,2,2,2,7,7,0,0,0,0,7,0,0,0,0,0
2,2,2,2,0,0,0,0,0,0,0,2,2,2,2,2,0,0,0,0,0,2,2,2,2,2,2,2,2,2,2,0,0,2,2,2,2,2,2,2,2,2,2,7,0,0,0,0,0,0,0,0,0,7
2,2,2,2,2,2,2,2,2,2,2,2,2,2,2,2,0,0,0,0,0,0,2,2,2,2,2,2,2,0,0,2,2,2,2,2,2,2,2,2,2,2,2,2,0,0,0,0,0,7,7,7,7,7
2,2,2,2,2,2,2,2,2,2,2,2,2,2,2,2,2,2,0,0,0,0,0,2,2,2,2,2,0,0,0,0,2,2,2,2,2,2,2,2,2,3,2,2,0,0,0,0,0,0,7,7,7,7
2,2,2,2,2,2,2,2,2,2,2,2,2,2,2,2,2,2,0,0,0,0,0,2,2,2,0,0,0,0,0,0,2,2,2,2,2,2,2,2,2,2,3,2,0,0,0,0,0,0,0,0,7,7
2,2,2,2,2,2,2,2,2,2,3,2,2,2,2,2,2,2,2,0,0,0,0,2,0,0,0,0,0,0,0,0,2,2,2,2,2,2,2,2,2,2,2,2,2,5,0,0,0,0,0,0,0,7
2,2,2,2,2,2,2,2,2,2,2,2,2,2,2,2,2,2,2,0,0,0,5,0,0,0,0,0,0,0,0,0,0,0,0,2,2,2,2,2,2,2,2,2,2,2,2,2,0,0,0,0,0,7
2,2,2,2,2,2,2,2,2,2,2,2,2,2,2,2,2,2,2,0,0,5,0,0,0,0,0,0,0,0,0,0,0,0,0,0,2,2,2,2,2,2,2,2,2,2,2,2,2,0,0,0,2,0
2,2,2,2,2,2,2,2,2,2,2,2,2,2,2,2,2,2,2,2,2,0,0,0,0,0,0,0,0,0,0,0,0,0,0,0,0,2,2,2,2,2,2,2,2,2,2,2,2,2,2,2,2,0
2,2,2,2,2,2,2,2,2,2,2,2,2,2,2,2,2,2,2,2,2,0,0,0,0,0,0,0,0,0,0,0,0,0,0,0,0,2,2,2,2,2,2,2,0,2,2,2,2,2,2,2,2,0
2,2,2,2,2,2,2,2,2,2,2,2,0,11,2,2,2,31,14,0,0,0,0,0,0,0,0,0,0,0,0,0,0,0,0,0,0,0,2,2,2,2,2,0,2,2,2,2,2,2,2,2,2,0
2,2,2,2,0,2,2,2,2,2,2,2,0,18,0,2,2,2,2,2,0,0,0,0,0,0,0,0,0,0,0,0,0,0,0,0,0,0,2,2,2,2,2,0,0,2,2,2,2,2,2,2,2,0
2,2,2,2,0,2,2,2,2,2,2,2,0,0,0,2,2,2,2,2,0,0,0,0,0,0,0,0,0,0,0,0,0,0,0,0,0,0,2,2,2,2,0,0,0,2,2,2,2,2,2,2,2,2
2,2,2,2,0,2,2,2,2,2,2,2,0,0,0,2,2,2,2,2,0,0,0,0,0,0,0,0,0,0,0,0,0,0,0,0,0,0,0,0,0,24,0,0,0,2,2,2,2,2,2,2,2,2
2,2,2,2,0,2,2,2,2,2,2,0,0,0,0,0,7,7,7,7,0,2,2,0,0,0,0,0,0,0,0,0,0,0,0,0,0,0,0,0,0,0,0,0,0,2,2,2,2,2,2,2,2,7
2,2,2,2,2,2,2,2,2,2,2,0,0,0,0,0,7,5,5,5,0,2,2,0,0,0,0,0,0,0,0,0,0,0,0,0,0,0,24,0,0,24,0,0,0,13,2,2,4,4,2,2,7,7
2,2,2,2,0,2,0,7,2,2,2,0,0,0,0,0,7,5,5,5,5,0,0,0,0,0,0,0,0,0,0,0,0,0,0,0,0,2,2,2,2,0,0,2,2,13,2,2,4,4,10,7,7,7
2,2,2,2,2,0,0,7,7,2,2,2,0,0,0,0,7,5,5,5,5,0,0,0,0,0,0,0,0,0,0,0,0,0,0,0,0,2,2,2,2,2,2,2,2,2,2,4,4,4,2,7,7,7
2,2,2,2,2,0,0,7,7,2,2,2,0,2,2,2,7,2,2,2,2,2,0,0,0,0,0,0,0,0,0,0,0,0,0,0,2,2,2,2,2,2,2,2,2,2,2,2,4,4,2,2,2,2
2,2,2,2,2,0,0,7,7,2,2,2,2,2,2,7,7,2,2,2,2,2,2,0,0,22,22,47,26,0,0,0,0,0,0,2,2,2,2,2,2,2,2,3,2,2,2,2,4,2,2,2,2,2
2,2,2,2,2,0,0,7,2,2,2,2,2,2,7,7,7,2,2,2,2,2,2,5,5,5,48,0,0,0,0,0,0,0,2,2,2,2,2,2,2,2,2,2,2,2,2,2,3,3,2,2,2,2
2,2,2,2,2,0,0,7,2,2,2,2,2,2,7,7,7,2,2,2,2,2,5,5,5,5,48,0,0,0,0,0,2,2,2,2,2,2,2,2,2,2,2,2,2,2,2,2,3,3,2,2,2,2
2,2,2,2,2,2,2,2,2,2,2,2,2,2,7,7,2,2,2,2,2,5,5,5,5,5,48,2,2,24,0,0,2,2,2,2,2,2,2,2,2,2,2,2,2,3,3,2,2,2,2,2,2,2
0,2,2,2,2,2,2,2,2,2,2,2,2,2,2,2,2,2,2,2,2,5,5,5,5,2,2,2,2,0,0,0,2,2,2,2,0,0,2,2,2,2,2,2,2,2,3,2,2,2,2,2,2,2
0,50,0,0,0,2,2,2,2,0,0,0,2,2,2,2,2,0,2,2,2,5,5,5,2,2,2,2,2,0,0,0,2,2,2,2,2,2,2,2,2,2,2,2,2,2,2,2,2,2,2,2,2,2
0,0,0,2,2,2,2,2,2,2,0,0,2,2,0,0,0,0,0,2,2,2,2,2,2,2,2,2,0,0,0,0,2,2,2,2,2,10,10,10,2,2,2,2,2,2,2,2,2,2,2,2,2,2
0,2,2,2,2,2,2,2,2,2,0,0,2,0,0,0,0,0,0,2,2,2,2,2,2,2,2,2,0,0,0,0,2,2,2,0,0,10,10,10,2,2,2,2,2,2,2,2,2,2,2,2,2,2
2,2,2,2,2,2,2,2,2,0,0,0,2,0,0,0,0,0,0,0,0,0,2,2,2,2,2,2,5,0,0,0,2,2,2,0,0,2,2,2,2,2,2,2,2,2,2,2,2,2,2,2,2,2
2,2,2,2,2,2,2,2,0,0,0,0,0,0,0,0,0,0,0,0,0,0,5,0,0,0,2,2,0,0,0,0,0,0,0,0,0,2,2,2,2,2,2,2,2,2,2,2,2,2,2,2,2,2
2,2,2,2,2,2,2,0,0,0,2,0,0,0,0,2,2,0,0,0,0,0,5,0,0,0,0,0,0,0,0,0,0,0,0,0,0,2,2,2,2,2,2,2,2,2,2,2,2,2,2,2,2,2
2,2,2,2,2,2,2,0,0,2,2,0,0,0,0,0,0,0,0,0,0,0,0,0,0,0,0,0,0,0,0,0,0,0,0,0,0,0,2,2,2,2,2,2,2,2,2,2,2,2,2,2,2,2
2,2,2,2,2,2,2,2,2,2,2,2,0,0,0,0,0,0,0,0,0,0,0,0,0,0,0,2,0,0,0,0,0,0,0,0,0,2,2,2,2,2,2,2,2,2,2,2,2,2,2,2,2,2
2,2,2,2,2,2,2,0,2,2,2,2,2,0,0,0,0,0,0,0,0,0,0,0,0,0,0,0,0,0,0,0,0,0,2,2,0,0,0,0,2,2,2,2,2,2,2,2,2,2,2,2,2,2
2,2,2,2,2,0,0,2,0,2,2,2,2,0,0,0,0,0,0,0,0,0,0,0,0,0,0,0,0,0,0,0,0,2,2,2,2,0,0,0,2,2,2,2,2,2,2,2,2,2,2,2,2,2
2,2,2,2,2,0,0,0,2,2,2,2,2,43,2,2,2,2,2,2,2,2,2,2,0,0,0,0,2,0,0,0,45,45,2,2,2,2,2,2,2,2,2,2,2,2,2,2,2,2,2,2,2,2
2,2,2,2,2,2,0,4,2,2,2,2,2,2,2,2,2,2,2,2,2,2,2,2,2,0,0,0,2,0,0,0,0,0,45,2,2,2,2,2,2,2,2,2,2,2,2,2,2,2,2,2,2,2
0,0,2,2,2,2,2,2,2,2,2,2,2,2,9,2,2,2,2,2,2,2,2,2,2,2,0,0,2,0,0,0,0,0,0,0,2,2,2,2,2,2,2,2,2,2,2,2,2,2,2,2,2,2
0,0,2,2,2,2,2,2,2,2,2,2,2,2,2,2,2,2,2,2,2,2,2,2,2,2,0,0,0,0,0,0,0,0,0,0,0,2,2,2,2,2,2,2,2,2,2,2,2,2,2,2,2,2
2,2,2,2,2,2,2,2,2,2,2,2,2,2,2,2,2,2,2,2,2,2,2,2,2,2,2,2,0,0,0,0,0,0,2,2,2,2,2,2,2,2,2,2,2,2,2,2,2,2,2,2,2,2
2,2,2,2,2,2,2,2,2,2,2,2,2,2,2,2,2,2,2,2,2,2,2,2,2,2,2,2,0,0,0,0,0,0,2,2,2,2,2,2,2,2,2,2,2,2,2,2,2,2,2,2,2,2
2,2,2,2,2,2,2,2,2,2,2,2,2,2,2,2,2,2,2,2,2,2,2,2,2,2,2,2,0,0,0,0,0,0,2,2,2,2,2,2,2,2,2,2,2,2,2,2,2,2,2,2,2,2
:endlayer
layer: 13
2,5,2,2,2,2,0,2,2,2,0,2,2,2,2,2,2,0,2,0,0,2,2,2,2,2,2,0,0,0,0,0,0,0,0,0,0,0,0,0,0,0,0,0,0,0,2,2,2,2,2,2,2,2
2,2,2,2,2,2,2,2,2,2,2,2,2,2,2,2,2,2,2,2,2,2,2,2,2,2,2,2,2,2,2,2,0,0,0,0,0,0,0,0,0,0,0,0,2,2,2,2,2,2,2,2,2,2
2,2,2,2,2,2,2,2,2,2,2,2,2,2,2,2,2,2,2,2,2,2,2,2,2,2,2,2,2,2,2,2,2,2,2,2,2,2,2,2,2,2,2,2,2,2,2,2,2,2,2,2,2,2
2,2,2,2,2,2,2,2,2,2,2,2,2,2,2,2,2,2,2,2,2,2,2,2,2,2,2,0,2,2,2,2,2,2,2,2,2,2,2,2,2,2,2,2,2,2,2,2,2,2,2,2,2,2
2,51,2,2,2,2,2,2,2,2,3,2,2,2,2,2,2,2,2,2,2,2,2,2,2,0,0,0,2,2,2,2,2,2,2,3,3,2,2,2,2,2,2,2,2,2,2,2,2,2,2,2,2,2
2,2,2,2,2,2,2,2,2,2,0,0,0,0,0,0,2,2,2,2,2,0,0,0,0,2,2,2,2,2,2,2,2,2,2,3,3,2,8,8,2,2,2,2,2,2,2,2,2,2,2,2,2,2
2,2,2,2,2,2,2,2,2,2,2,0,0,0,0,0,2,2,0,0,0,0,0,0,0,2,2,2,0,2,2,2,2,2,2,2,2,2,8,8,2,2,2,2,2,2,2,2,2,2,2,2,2,2
2,2,2,2,2,2,2,2,0,0,0,0,0,0,0,0,0,0,0,0,0,0,0,0,0,0,0,2,0,0,0,2,2,2,2,2,2,2,2,2,2,2,2,2,0,2,2,2,2,2,2,2,2,2
2,2,2,2,0,0,0,0,0,0,0,0,2,0,0,0,0,0,0,0,0,0,0,0,0,0,0,0,0,0,0,0,2,2,2,2,2,2,2,2,2,2,2,2,0,2,2,2,2,2,2,2,2,2
2,2,2,2,0,0,0,0,0,0,0,0,2,0,0,0,0,0,0,0,0,0,0,0,0,0,0,0,0,0,0,0,0,0,0,2,0,2,2,2,2,2,2,2,0,0,2,2,2,2,2,2,2,2
2,2,2,2,0,0,0,0,0,0,0,0,2,2,0,0,0,0,0,0,0,2,2,0,0,0,0,0,0,0,0,0,0,0,0,0,0,0,0,2,7,7,7,7,0,0,2,2,2,4,2,0,0,0
2,2,2,2,0,0,0,0,0,0,0,0,2,2,2,0,0,0,0,0,2,2,2,2,0,0,0,0,0,0,0,0,0,0,0,0,0,0,0,0,7,7,7,7,0,0,0,4,4,4,0,0,0,0
2,2,2,2,0,0,0,0,0,0,0,0,2,2,2,2,0,0,0,0,2,2,2,2,2,0,0,0,0,0,0,0,0,0,0,0,0,0,0,0,2,7,7,7,0,0,0,4,0,0,0,0,0,0
2,2,2,2,0,0,0,0,0,0,0,0,2,2,2,2,2,0,0,0,2,2,8,8,2,2,2,2,2,2,5,0,0,0,0,0,0,0,0,2,2,7,7,7,0,0,0,0,0,0,0,0,0,0
2,2,2,2,0,0,0,0,0,0,0,0,2,2,3,2,2,0,0,0,0,2,8,8,2,2,2,2,2,2,2,2,2,0,2,2,2,2,0,0,0,5,7,7,0,0,0,0,0,0,0,0,0,0
2,2,2,2,2,2,2,2,2,2,2,2,2,2,2,2,2,2,0,0,0,2,2,2,2,2,2,2,2,2,2,2,2,2,2,2,2,2,0,5,0,5,5,7,0,0,0,0,0,0,0,0,7,7
2,2,2,2,2,2,2,2,2,2,2,2,2,2,2,2,2,2,0,0,0,0,2,2,2,2,2,2,2,0,0,0,2,2,2,2,2,2,2,5,5,5,5,5,0,0,0,0,0,7,7,7,7,7
2,2,2,2,2,2,2,2,2,2,2,2,2,2,2,2,2,2,2,0,0,0,0,2,2,2,0,0,0,0,0,0,2,2,2,2,2,2,2,2,5,5,5,5,0,0,0,0,0,2,7,7,7,7
2,2,2,2,2,2,2,2,2,2,2,2,2,2,2,2,2,2,2,2,0,0,0,2,0,0,0,0,0,0,0,0,2,2,2,2,2,2,2,2,2,5,5,5,5,5,0,0,0,0,7,7,7,7
2,2,2,2,2,2,2,2,2,2,2,2,2,2,2,2,2,2,2,2,0,0,5,0,0,0,0,0,0,0,0,0,0,0,0,2,2,2,2,2,2,2,0,0,5,5,2,2,2,2,2,7,7,7
2,2,2,2,2,2,2,2,2,2,2,2,2,2,2,2,2,2,2,2,0,5,0,0,0,0,0,0,0,0,0,0,0,0,0,0,2,2,2,3,2,2,2,2,0,0,0,8,8,2,2,2,2,0
2,2,2,2,2,2,2,2,2,2,2,2,2,2,2,2,2,2,2,2,2,0,0,0,0,0,0,0,0,0,0,0,0,0,0,0,0,2,3,2,2,2,2,2,2,0,0,0,8,2,2,2,2,0
2,2,2,2,2,2,2,2,2,2,2,2,2,2,2,2,2,2,2,2,2,0,0,0,0,0,0,0,0,0,0,0,0,0,0,0,0,2,2,2,2,2,2,2,2,2,0,2,2,2,2,2,2,0
2,2,2,2,2,2,2,2,2,2,2,2,0,11,0,2,2,31,2,2,0,0,0,0,0,0,0,0,0,0,0,0,0,0,0,0,0,0,2,2,2,2,2,2,2,2,2,2,2,2,2,2,2,0
2,2,2,2,2,2,2,2,2,2,2,2,0,0,0,0,2,2,2,2,0,0,0,0,0,0,0,0,0,0,0,0,0,0,0,0,0,0,2,2,2,2,2,2,2,2,2,2,2,2,2,2,2,2
2,2,2,2,2,2,2,2,2,2,2,2,0,0,0,0,7,2,2,2,0,0,0,0,0,0,0,0,0,0,0,0,0,0,0,0,0,0,2,2,2,2,2,2,2,2,2,2,2,2,2,2,2,2
2,2,2,2,2,2,2,2,2,2,2,2,0,0,0,0,7,52,52,22,0,0,0,0,0,0,0,0,0,0,0,0,0,0,0,0,0,0,22,0,0,22,0,0,0,2,2,2,2,2,2,2,2,2
2,2,2,2,2,2,2,7,7,2,2,0,0,0,0,0,7,0,0,23,0,2,2,0,0,0,0,0,0,0,0,0,0,0,0,0,0,0,0,0,0,22,0,0,0,2,2,2,2,2,2,2,7,7
2,2,2,2,2,2,2,7,7,2,2,0,0,0,0,0,7,0,0,25,0,2,2,0,0,0,0,0,0,0,0,0,0,0,0,0,0,0,22,0,0,22,0,0,0,2,2,2,2,2,2,7,7,7
2,2,2,2,2,2,0,7,7,2,2,0,0,0,0,0,0,7,0,37,36,0,0,0,0,0,0,0,0,0,0,0,0,0,0,0,0,2,2,2,2,2,2,2,13,2,2,2,4,2,7,7,7,7
2,2,2,2,2,0,0,7,7,7,2,2,0,0,2,7,7,7,0,0,25,0,0,0,0,0,0,0,0,0,0,0,0,0,0,0,0,2,2,2,2,2,2,2,2,2,2,2,4,4,7,7,7,7
2,2,2,2,2,0,0,7,7,7,2,2,2,2,7,7,7,7,0,0,37,36,0,0,0,0,0,0,0,0,0,0,0,0,0,0,2,2,2,2,2,2,2,2,2,2,2,2,4,7,7,7,7,7
2,2,2,2,0,0,0,7,7,2,2,2,2,2,7,7,7,7,7,0,0,37,36,0,0,35,26,0,0,0,0,0,0,0,0,2,2,2,2,2,2,2,2,2,2,2,2,2,4,2,7,2,2,2
2,2,2,2,0,0,0,7,7,2,2,2,2,2,7,7,7,7,7,7,0,0,37,26,26,46,0,0,0,0,0,0,0,0,2,2,2,2,2,2,2,2,2,2,2,2,2,2,3,3,2,2,2,2
2,2,2,2,2,0,0,7,2,2,2,2,2,7,7,7,7,7,2,2,2,0,0,0,0,0,0,0,0,0,0,0,2,2,2,2,0,0,2,2,2,2,2,2,2,2,2,2,3,3,2,2,2,2
0,0,2,2,2,0,0,2,2,2,2,2,2,7,7,7,7,2,2,2,2,5,0,0,0,0,0,0,2,22,22,22,2,2,2,2,0,0,0,2,2,2,2,2,2,3,3,2,2,2,2,2,2,2
0,0,0,0,0,0,7,2,2,2,2,2,2,7,7,7,0,2,2,2,5,5,5,0,0,0,0,2,2,0,0,0,2,2,2,2,0,0,0,2,2,2,2,2,2,2,3,2,2,2,2,2,2,2
0,0,0,0,0,0,2,2,2,2,0,0,2,2,7,2,0,0,0,2,5,5,5,5,5,2,2,2,2,0,0,0,2,2,2,2,2,2,2,2,2,2,2,2,2,2,2,2,2,2,2,2,2,2
0,0,0,0,0,0,2,2,2,2,2,0,2,2,2,0,0,0,0,0,5,5,2,2,2,2,2,2,0,0,0,0,2,2,2,2,2,2,2,2,2,2,2,2,2,2,2,2,2,2,2,2,2,2
0,0,0,0,2,2,2,2,2,2,2,2,2,2,0,0,0,0,0,0,0,0,2,2,2,2,2,2,0,0,0,0,2,2,2,2,2,2,2,2,2,2,2,2,2,2,2,2,2,2,2,2,2,2
0,0,2,2,2,2,2,2,2,2,2,2,2,0,0,0,0,0,0,0,0,0,2,2,2,2,2,2,0,0,0,0,2,2,2,2,2,2,2,2,2,2,2,2,2,2,2,2,2,2,2,2,2,2
0,0,2,2,2,2,2,2,2,2,2,2,2,0,0,0,0,0,0,0,0,0,0,2,2,2,2,2,0,0,0,0,0,2,2,2,2,2,2,2,2,2,2,2,2,2,2,2,2,2,2,2,2,2
0,0,2,2,2,2,2,2,2,2,2,2,2,0,2,2,0,0,0,0,0,0,0,0,2,2,0,0,0,0,0,0,0,0,0,2,2,2,2,2,2,2,2,2,2,2,2,2,2,2,2,2,2,2
2,2,2,2,2,2,2,2,2,2,2,2,2,2,0,0,0,0,0,0,0,0,0,0,2,2,0,0,0,0,0,0,0,0,0,2,2,2,2,2,2,2,2,2,2,2,2,2,2,2,2,2,2,2
2,2,2,2,2,2,2,2,2,2,2,2,2,0,0,0,0,0,0,0,0,0,0,0,0,0,0,2,0,0,0,0,0,0,2,2,2,2,2,2,2,2,2,2,2,2,2,2,2,2,2,2,2,2
2,2,2,2,4,4,2,2,2,2,2,2,2,0,0,0,0,0,0,0,0,0,0,0,0,0,0,0,0,0,0,0,0,2,2,2,0,0,2,2,2,2,2,2,2,2,2,2,2,2,2,2,2,2
2,2,2,2,2,0,0,2,2,2,2,2,0,2,0,0,0,0,0,0,0,0,0,0,0,0,0,0,0,0,0,0,0,0,0,0,0,0,0,2,2,2,2,2,2,2,2,2,2,2,2,2,2,2
2,2,2,2,2,0,0,2,2,2,2,2,2,2,2,2,2,2,2,2,2,2,2,2,0,0,0,0,2,0,0,0,0,0,2,2,2,2,2,2,2,2,2,2,2,2,2,2,2,2,2,2,2,2
2,2,2,2,2,2,2,2,2,2,2,2,7,7,2,2,2,2,2,2,2,2,2,2,2,2,0,0,2,0,0,0,0,0,0,2,2,2,2,2,2,2,2,2,2,2,2,2,2,2,2,2,2,2
24,24,2,2,2,2,2,2,2,2,2,2,7,7,2,2,2,2,2,2,2,2,2,2,2,2,2,0,2,0,0,0,0,0,0,0,2,2,2,2,2,2,2,2,2,2,2,2,2,2,2,2,2,2
24,24,2,2,2,2,2,2,2,2,2,2,2,7,7,2,2,2,2,2,2,2,2,2,2,2,2,2,0,0,0,0,0,0,0,0,2,2,2,2,2,2,2,2,2,2,2,2,2,2,2,2,2,2
2,2,2,2,2,2,2,2,2,2,2,2,2,2,2,2,2,2,2,2,2,2,2,2,2,2,2,0,0,0,0,0,0,0,0,2,2,2,2,2,2,2,2,2,2,2,2,2,2,2,2,2,2,2
2,2,2,2,2,2,2,2,2,2,2,2,2,2,2,2,2,2,2,2,2,2,2,2,2,2,2,0,0,0,0,0,0,0,0,2,2,2,2,2,2,2,2,2,2,2,2,2,2,2,2,2,2,2
2,2,2,2,2,2,2,2,2,2,2,2,2,2,2,2,2,2,2,2,2,2,2,2,2,2,2,0,0,0,0,0,0,0,0,2,2,2,2,2,2,2,2,2,2,2,2,2,2,2,2,2,2,2
:endlayer
layer: 14
0,0,0,2,2,2,0,7,7,7,0,2,2,2,2,2,2,0,2,0,0,2,2,2,2,2,7,0,0,0,0,0,0,0,0,0,0,0,0,0,0,0,0,0,0,0,2,2,2,2,0,0,2,2
0,53,0,0,0,0,0,0,0,0,0,2,2,2,2,2,2,2,2,0,0,2,2,2,2,2,4,4,4,4,2,2,0,0,0,0,0,0,0,0,0,0,0,0,5,2,2,2,2,2,0,0,54,2
0,0,0,0,0,0,0,0,0,0,0,2,2,2,2,2,2,2,2,2,2,2,2,2,2,2,4,0,4,2,2,2,2,2,2,2,2,2,2,2,2,5,5,5,5,3,2,2,2,55,56,0,0,2
0,0,0,2,7,7,7,7,2,2,2,2,2,2,2,2,2,2,2,2,2,2,2,2,2,2,0,0,2,2,2,2,2,2,2,2,2,2,2,2,2,2,5,5,5,2,2,2,2,0,57,58,59,2
0,0,0,2,7,2,2,2,2,2,2,2,2,2,2,2,2,2,2,2,2,2,2,2,2,0,0,0,2,2,2,2,2,2,2,2,2,2,2,2,2,2,2,5,5,5,2,2,2,0,0,0,2,2
0,0,0,2,2,2,2,2,2,2,2,0,0,0,0,2,2,2,2,2,2,2,0,0,2,2,2,2,2,2,2,2,2,2,2,3,2,2,2,2,2,2,2,2,5,2,2,2,2,2,0,0,2,2
0,0,0,2,2,2,2,2,2,2,2,2,0,0,0,0,2,2,2,0,0,0,0,0,0,2,2,2,0,2,2,2,2,2,2,2,2,2,2,2,2,2,2,2,2,2,2,2,0,0,0,0,0,0
24,0,24,2,2,2,2,2,2,0,0,0,0,0,0,0,2,2,0,0,0,0,0,0,0,0,0,2,0,0,0,2,2,2,2,2,2,2,2,2,2,2,2,2,2,2,2,0,0,0,0,0,0,0
0,0,0,2,2,0,0,0,0,0,0,0,2,2,0,0,0,0,0,0,0,0,0,0,0,0,0,0,0,0,0,0,0,2,2,2,2,2,2,2,0,0,2,2,0,2,0,0,0,0,0,0,0,0
0,0,0,2,0,0,0,0,0,0,0,0,2,2,2,0,0,0,0,0,0,0,0,0,0,0,0,0,0,0,0,0,0,0,0,0,0,0,0,0,0,0,0,2,0,2,0,0,0,0,0,0,0,0
0,0,0,2,0,0,0,0,0,0,0,0,2,2,2,2,0,0,0,0,2,2,2,0,0,0,0,0,0,0,0,0,0,0,0,0,0,0,0,0,0,0,0,7,0,0,0,0,0,2,2,2,0,0
0,0,0,2,0,0,0,0,0,0,0,0,2,2,2,2,2,0,0,2,2,2,2,2,0,0,0,0,0,0,0,0,0,0,0,0,0,0,0,0,0,0,0,0,0,0,2,4,0,2,2,0,0,2
0,0,0,2,0,0,0,0,0,0,0,0,2,2,2,2,2,0,0,0,2,2,2,2,2,0,0,0,0,0,0,0,0,0,0,0,0,0,0,0,0,0,7,7,0,0,0,0,0,0,0,0,0,0
0,0,0,2,0,0,0,0,0,0,0,0,2,2,2,2,2,2,0,0,2,2,2,2,2,2,2,2,2,2,5,0,0,0,0,0,0,0,0,0,0,7,7,7,0,0,0,0,0,0,0,0,0,0
0,0,0,2,0,0,0,0,0,0,0,0,2,2,3,2,2,2,2,0,2,2,2,8,2,2,2,2,2,2,2,2,2,0,0,0,0,0,0,0,0,0,7,7,0,0,0,0,0,0,0,0,0,2
0,0,0,2,2,2,2,2,2,2,2,2,2,2,2,2,2,2,2,0,0,2,2,2,2,2,2,2,2,2,2,2,2,2,2,2,2,0,0,0,0,5,5,7,0,0,0,0,0,0,0,0,7,2
0,0,0,2,2,2,2,2,2,2,2,2,2,2,2,2,2,2,2,0,0,2,2,2,2,2,2,2,2,2,0,2,2,2,2,2,2,2,0,5,5,5,5,5,7,7,0,0,2,7,7,7,7,2
0,0,0,2,2,2,2,2,2,2,2,2,2,2,2,2,2,2,2,2,0,8,8,2,2,2,0,0,0,0,0,0,2,2,2,2,2,2,2,5,5,5,5,5,0,7,7,7,2,2,7,7,7,2
0,0,0,2,2,2,2,2,2,2,2,2,2,2,2,2,2,2,2,2,0,8,8,2,0,0,0,0,0,0,0,0,2,2,2,2,2,2,2,2,2,5,5,5,5,0,2,2,2,2,2,7,7,2
24,0,24,2,2,2,2,2,2,2,2,2,2,2,2,4,4,2,2,2,0,2,2,0,0,0,0,0,0,0,0,0,0,0,0,2,2,2,2,2,2,2,0,0,5,5,2,2,2,2,2,2,2,2
0,0,0,2,2,2,2,2,2,2,2,2,2,2,2,4,4,2,2,2,2,2,0,0,0,0,0,0,0,0,0,0,0,0,0,0,2,2,2,3,2,2,2,0,0,0,0,8,8,2,2,2,2,0
0,0,0,2,2,2,2,8,8,2,2,2,2,2,2,4,4,2,2,2,2,0,0,0,0,0,0,0,0,0,0,0,0,0,0,0,0,2,5,5,2,2,2,2,2,0,0,0,8,2,2,2,2,0
0,0,0,2,2,2,2,8,8,2,2,2,2,2,2,2,2,2,2,2,2,0,0,0,0,0,0,0,0,0,0,0,0,0,0,0,0,2,5,5,5,0,0,2,2,2,0,2,2,2,2,2,2,0
0,0,0,2,2,2,2,2,2,2,2,2,0,11,0,2,2,31,2,2,0,0,0,0,0,0,0,0,0,0,0,0,0,0,0,0,0,0,5,5,0,0,0,0,2,2,2,2,2,2,2,2,2,0
0,0,0,2,2,2,2,2,2,2,2,2,0,0,0,0,2,5,5,2,0,0,0,0,0,0,0,0,0,0,0,0,0,0,0,0,0,0,2,0,0,60,0,0,2,2,2,2,2,2,2,2,2,2
0,0,0,2,2,2,2,2,2,2,2,2,0,0,0,0,7,52,52,22,0,0,0,0,0,0,0,0,0,0,0,0,0,0,0,0,0,0,2,2,0,0,0,2,2,2,2,2,2,2,2,2,2,2
0,0,0,2,2,2,2,2,2,2,2,2,0,0,0,0,7,0,0,23,0,0,0,0,0,0,0,0,0,0,0,0,0,0,0,0,0,0,2,2,2,2,2,2,2,2,2,2,2,2,2,2,2,2
0,0,0,2,2,2,2,7,7,2,2,2,0,0,0,0,7,0,0,0,0,2,2,0,0,0,0,0,0,0,0,0,0,0,0,0,0,0,2,2,2,2,2,2,2,2,2,2,2,2,2,2,7,7
0,0,0,2,2,2,2,7,7,2,2,0,0,0,0,0,7,0,0,0,0,2,2,0,0,0,0,0,0,0,0,0,0,0,0,0,0,0,2,2,2,2,2,2,2,2,2,2,2,2,2,7,7,7
0,0,0,2,2,2,7,7,7,2,2,2,0,0,0,0,7,7,0,0,0,0,0,0,0,0,0,0,0,0,0,0,0,0,0,0,0,2,2,2,2,2,2,2,2,2,2,2,2,2,7,7,7,7
0,0,0,2,2,7,7,7,7,7,2,2,2,2,2,0,7,7,0,0,0,0,0,0,0,0,0,0,0,0,0,0,0,0,0,0,0,2,2,2,2,2,2,2,2,2,2,2,2,2,7,7,7,7
24,0,24,2,2,0,0,7,7,7,2,2,2,2,7,7,7,7,0,0,0,0,0,0,0,0,0,0,0,0,0,0,0,0,0,0,2,2,2,2,2,2,2,2,2,2,2,2,2,7,7,7,7,7
0,0,0,2,0,0,0,7,7,2,2,2,2,2,7,7,7,7,7,0,0,0,0,0,0,0,0,0,0,0,0,0,0,0,0,2,0,0,0,2,2,2,2,2,2,2,2,2,2,2,7,2,2,2
0,0,0,2,0,0,0,7,7,2,2,2,2,7,7,7,7,7,7,7,0,0,0,0,0,0,0,0,0,0,0,0,0,0,2,2,0,0,0,2,2,2,2,2,2,2,2,2,2,2,2,2,2,2
0,0,0,2,2,0,0,7,2,2,2,2,2,7,7,7,7,7,7,7,2,0,0,0,0,0,0,0,0,0,0,0,2,2,2,2,0,0,0,2,2,2,2,2,2,2,2,2,2,2,2,2,2,2
0,0,0,0,0,0,0,2,2,2,2,2,2,7,7,7,7,7,2,2,2,5,0,0,0,0,0,0,2,2,2,2,2,2,2,2,0,0,0,2,2,2,2,2,2,2,2,2,2,2,2,2,2,2
0,0,0,0,0,0,0,2,2,2,2,2,2,7,7,7,7,2,2,2,5,5,5,0,0,0,0,2,2,2,2,2,2,2,2,2,0,0,0,2,2,2,2,2,2,2,2,2,2,2,2,2,2,2
0,0,0,0,0,0,2,2,2,2,2,2,2,2,7,7,3,2,2,2,5,5,5,5,7,7,0,2,2,2,2,2,2,2,2,2,2,2,2,2,2,2,2,2,2,2,2,2,2,2,2,2,2,2
0,0,0,0,0,0,0,0,2,2,2,2,2,2,2,0,0,0,0,0,5,7,7,7,7,7,7,7,2,2,2,2,2,2,2,2,2,2,2,2,2,2,2,2,2,2,2,2,2,2,2,2,2,2
0,0,0,0,0,0,0,0,0,0,2,2,2,2,2,0,0,0,0,0,0,0,7,7,7,7,7,7,0,4,4,4,4,4,2,2,2,2,2,2,2,2,2,2,2,2,2,2,2,2,2,2,2,2
0,0,0,2,2,2,0,58,0,0,0,2,2,2,2,0,0,0,0,0,0,0,2,7,7,7,2,2,0,0,4,4,4,4,2,2,2,2,2,2,2,2,2,2,2,2,2,2,2,2,2,2,2,2
0,0,0,2,2,2,2,0,61,0,0,2,2,2,2,0,0,0,0,0,0,0,0,5,5,5,2,2,0,0,0,2,2,2,2,2,2,2,2,2,2,2,2,2,2,2,2,2,2,2,2,2,2,2
0,0,0,2,2,2,8,2,0,0,0,2,2,2,2,2,2,0,0,0,0,0,0,0,5,2,2,0,0,0,0,0,2,2,2,2,2,2,2,2,2,2,2,2,2,2,2,2,2,2,2,2,2,2
0,0,0,2,2,2,2,2,2,0,0,2,2,2,2,2,2,2,2,2,0,0,0,0,0,0,2,0,0,0,0,0,0,2,2,2,2,2,2,2,2,2,2,2,2,2,2,2,2,2,2,2,2,2
0,0,0,2,2,2,2,2,2,0,62,2,2,2,0,0,0,0,0,2,2,0,0,0,0,0,2,2,0,0,0,0,2,2,2,2,2,2,2,2,2,2,2,2,2,2,2,2,2,2,2,2,2,2
0,0,0,2,4,4,2,2,2,2,2,2,0,2,0,0,0,0,0,2,8,4,0,0,0,0,0,0,0,0,0,0,2,2,2,2,0,2,2,2,2,2,2,2,2,2,2,2,2,2,2,2,2,2
24,0,24,2,2,2,2,2,2,2,2,7,0,2,0,0,0,2,2,8,8,4,0,0,0,0,0,0,0,0,0,0,0,0,0,0,0,0,2,2,2,2,2,2,2,2,2,2,2,2,2,2,2,2
0,0,0,2,2,2,2,2,2,2,2,7,7,7,2,2,2,2,2,2,2,2,4,4,0,0,0,0,2,0,0,0,0,0,2,2,2,2,2,2,2,2,2,2,2,2,2,2,2,2,2,2,2,2
0,0,0,2,2,2,2,2,2,2,2,7,7,7,7,2,2,2,2,2,2,2,2,4,4,2,0,0,2,2,2,0,0,0,2,2,2,2,2,2,2,2,2,2,2,2,2,2,2,2,2,2,2,2
0,0,0,2,2,2,2,2,2,2,2,7,7,7,7,2,2,2,2,2,2,2,2,2,2,2,2,2,2,2,2,0,0,0,2,2,2,2,2,2,2,2,2,2,2,2,2,2,2,2,2,2,2,2
0,0,0,2,2,2,2,2,2,2,2,7,7,7,7,7,2,2,2,2,2,2,2,2,2,2,2,2,2,0,0,0,0,2,0,8,2,2,2,2,2,2,2,2,2,2,2,2,2,2,2,0,0,2
0,0,0,24,0,0,0,0,0,0,0,0,0,24,0,0,0,0,0,0,0,0,0,0,0,24,0,0,0,0,0,0,0,0,0,0,24,0,0,0,0,0,0,0,0,0,0,0,0,0,24,0,0,0
0,0,0,0,0,0,0,0,0,0,0,0,0,0,0,0,0,63,0,0,0,0,0,0,0,0,0,0,0,0,0,0,0,0,0,0,0,0,0,0,0,0,0,0,0,0,0,0,0,0,0,0,0,0
0,0,0,24,0,0,0,0,0,0,0,0,0,24,0,0,0,0,0,0,0,0,0,0,0,24,0,0,0,0,0,0,0,0,0,0,24,0,0,0,0,0,0,0,0,0,0,0,0,0,24,0,0,0
:endlayer
layer: 15
0,0,0,2,2,7,0,7,7,7,0,7,2,2,2,2,2,0,2,0,0,5,5,5,5,7,7,7,7,7,5,5,2,2,2,2,2,2,2,2,5,5,5,5,0,0,0,2,2,2,0,0,2,2
0,0,0,0,0,0,0,0,0,0,0,0,0,0,0,0,0,0,0,0,0,0,0,5,5,7,7,7,7,5,5,2,2,2,2,2,2,2,2,2,5,5,5,5,0,0,2,2,2,2,0,0,0,2
0,0,0,0,0,0,0,0,0,0,0,0,0,0,0,0,0,0,0,0,0,0,0,5,5,2,4,0,5,2,2,2,2,2,2,2,2,2,2,2,2,5,5,5,0,5,2,2,2,0,0,0,0,2
0,0,0,2,0,0,7,7,7,2,2,2,2,2,2,2,2,2,2,2,2,2,5,5,5,2,0,0,2,2,2,2,2,2,2,2,2,2,2,2,2,5,5,5,0,5,2,2,2,0,0,0,0,2
0,0,0,2,0,0,7,2,2,2,2,2,2,2,2,2,2,2,2,2,2,2,2,5,2,0,0,0,2,2,2,2,2,2,2,2,2,7,2,2,2,2,5,5,5,5,2,2,2,0,0,0,2,2
0,0,0,2,2,2,2,2,2,2,2,2,2,2,2,2,2,2,2,2,2,2,2,2,2,2,2,2,2,2,2,2,2,2,2,2,7,7,2,2,2,2,2,5,5,5,2,2,2,2,0,0,2,2
0,0,0,2,2,2,2,2,2,2,2,2,2,2,2,2,2,2,2,2,2,2,0,0,2,2,2,2,2,2,2,2,2,2,2,2,7,7,2,2,2,2,2,2,0,0,2,0,0,0,0,0,0,0
24,0,24,2,2,2,2,2,2,2,2,0,2,2,2,2,2,2,2,2,2,0,0,0,2,2,2,2,0,0,2,2,2,2,2,7,7,7,7,2,2,0,0,0,0,0,0,0,0,0,0,0,0,0
0,0,0,2,2,2,2,2,0,0,0,0,2,2,2,2,2,2,2,2,2,2,0,0,0,0,0,0,0,0,0,0,2,2,2,2,7,7,2,0,0,0,0,0,0,0,0,0,0,0,0,0,0,0
0,0,0,2,0,0,0,0,0,0,0,0,2,2,2,2,2,2,2,2,2,2,2,0,0,0,0,0,0,0,0,0,0,0,0,0,0,0,0,0,0,0,0,0,0,0,0,0,0,0,0,0,0,0
0,0,0,2,0,0,0,0,0,0,0,0,2,2,2,2,2,2,2,2,2,2,2,0,0,0,0,0,0,0,0,0,0,0,0,0,0,0,0,0,0,0,0,0,0,0,0,0,0,0,2,2,0,0
0,0,0,2,0,0,0,0,0,0,0,0,2,2,2,2,2,2,2,2,2,2,2,0,0,0,0,0,0,0,0,0,0,0,0,0,0,0,0,0,0,0,0,0,0,0,0,0,0,2,2,2,2,2
0,0,0,2,0,0,0,0,0,0,0,0,2,2,2,2,2,2,2,2,2,2,2,0,0,0,0,0,0,0,0,0,0,0,0,0,0,0,0,0,0,0,0,7,0,0,0,0,0,0,0,2,2,2
0,0,0,2,0,0,0,0,0,0,0,0,2,3,2,2,2,2,2,2,2,2,2,24,24,24,2,2,5,5,5,0,7,0,0,0,0,0,0,0,0,2,7,7,0,0,0,0,0,0,0,0,2,2
0,0,0,2,2,2,2,2,2,2,2,2,2,2,2,2,2,2,2,2,2,2,2,0,0,0,0,0,64,7,7,0,7,0,0,0,0,0,0,0,0,0,2,7,0,0,0,0,0,0,0,0,2,2
0,0,0,2,2,2,2,2,2,2,2,2,2,2,2,2,2,2,2,2,2,2,2,0,0,0,0,0,64,7,7,0,2,2,2,2,0,0,0,0,0,0,5,2,7,7,0,0,0,0,0,2,2,2
0,0,0,2,2,2,2,2,2,2,2,2,2,2,2,2,2,2,2,2,2,2,0,35,26,26,26,65,22,2,2,2,2,2,2,2,2,2,0,0,0,5,5,5,2,2,2,2,2,2,2,2,2,2
0,0,0,2,2,2,2,2,2,2,2,2,2,2,2,2,2,2,2,2,2,0,0,25,0,0,0,0,0,0,0,0,2,2,2,2,2,2,2,5,0,5,5,0,2,2,2,2,2,2,2,2,2,2
0,0,0,2,2,2,2,2,2,2,2,2,2,2,2,2,2,2,2,2,0,35,26,46,0,0,0,0,0,0,0,0,2,2,2,2,2,5,2,2,2,5,0,0,5,0,2,2,2,2,2,2,2,2
24,0,24,2,2,2,2,2,2,2,2,2,2,2,2,4,4,2,2,0,0,25,0,0,0,0,0,0,0,0,0,0,0,0,0,2,2,5,5,2,2,2,2,2,0,0,2,2,2,2,2,2,2,0
0,0,0,2,2,2,2,2,2,2,2,2,2,2,2,4,4,2,0,35,26,46,0,0,0,0,0,0,0,0,0,0,0,0,0,0,2,5,5,5,2,2,2,2,2,2,2,2,2,2,2,2,2,0
0,0,0,2,2,2,2,2,2,2,2,2,2,2,2,4,4,2,0,25,0,0,0,0,0,0,0,0,0,0,0,0,0,0,0,0,0,5,5,7,7,7,7,7,2,2,2,2,2,2,2,2,2,0
0,0,0,2,2,2,2,8,2,2,2,2,2,6,2,4,4,2,0,25,0,0,0,0,0,0,0,0,0,0,0,0,0,0,0,0,0,5,7,7,7,0,0,7,7,2,2,2,2,2,2,2,2,0
0,0,0,2,2,2,2,2,2,2,2,2,0,18,2,2,2,31,0,25,0,0,0,0,0,0,0,0,0,0,0,0,0,0,0,0,0,0,7,0,0,0,0,0,2,2,2,2,2,2,2,2,2,0
0,0,0,2,2,2,2,2,2,2,2,2,0,0,0,0,7,0,0,25,0,0,0,0,0,0,0,0,0,0,0,0,0,0,0,0,0,0,7,0,0,0,0,0,2,2,2,2,2,2,2,2,2,2
0,0,0,2,2,2,2,2,2,2,2,2,0,0,0,0,7,0,0,25,0,0,0,0,0,0,0,0,0,0,0,0,0,0,0,0,0,0,2,0,0,0,0,2,2,2,2,2,2,2,2,2,2,2
0,0,0,2,2,2,2,2,2,2,2,2,0,0,0,0,7,0,0,0,0,0,0,0,0,0,0,0,0,0,0,0,0,0,0,0,0,0,2,0,0,0,2,2,2,2,2,2,2,2,2,2,2,2
0,0,0,2,2,2,2,2,2,2,2,2,0,0,0,0,7,0,0,0,0,2,2,0,0,0,0,0,0,0,0,0,0,0,0,0,0,0,2,2,2,2,2,2,2,2,2,2,2,2,2,2,2,7
0,0,0,2,2,2,2,2,2,2,2,2,0,0,0,0,7,0,0,0,0,2,2,0,0,0,0,0,0,0,0,0,0,0,0,0,0,0,2,2,2,2,2,2,2,2,2,2,2,2,2,2,7,7
0,0,0,2,2,2,7,7,2,2,2,2,0,0,0,0,0,7,0,0,0,0,0,0,0,0,0,0,0,0,0,0,0,0,0,0,0,2,2,2,2,2,2,2,2,2,2,2,2,2,2,7,7,7
0,0,0,2,2,2,7,7,7,2,2,2,2,0,0,0,0,7,0,0,0,0,0,0,0,0,0,0,0,0,0,0,0,0,0,0,0,2,2,2,2,2,2,2,2,2,2,2,2,2,2,7,7,7
24,0,24,2,2,7,7,7,7,2,2,2,2,2,7,7,7,7,0,0,0,0,0,0,0,0,0,0,0,0,0,0,0,0,0,0,2,2,2,2,2,2,2,2,2,2,2,2,2,2,2,2,2,2
0,0,0,2,2,7,7,7,7,2,2,2,2,2,7,7,7,7,7,0,0,0,0,0,0,0,0,0,0,0,0,0,0,0,0,2,0,0,0,2,2,2,2,2,2,2,2,2,2,2,2,2,2,2
0,0,0,2,2,7,7,7,2,2,2,2,2,2,7,7,7,7,7,7,0,0,0,0,0,0,0,0,0,0,0,0,0,0,2,2,0,0,0,2,2,2,2,2,2,2,2,2,2,2,2,2,2,2
0,0,0,2,2,0,0,7,2,2,2,2,2,7,7,7,7,7,7,7,2,0,0,0,0,0,0,0,0,0,0,0,2,2,2,2,0,0,0,2,2,2,2,4,4,2,2,2,2,2,2,2,2,2
0,0,0,0,0,0,0,2,2,2,2,2,7,7,7,7,7,7,2,2,2,2,0,0,0,0,0,0,2,2,2,2,2,2,2,2,0,0,2,2,2,2,2,4,4,2,2,2,2,2,2,8,8,8
0,0,0,0,0,0,0,2,2,2,2,2,7,7,0,0,2,2,2,2,2,5,5,0,0,0,0,2,2,2,2,2,2,3,3,2,2,0,2,2,2,2,2,4,4,2,0,0,0,2,2,8,8,8
0,0,0,0,0,0,0,2,2,2,2,2,2,0,0,0,0,2,2,2,2,5,7,7,7,7,7,7,7,2,2,2,2,3,3,2,2,2,2,2,2,2,2,2,2,2,0,0,0,2,2,8,8,8
0,0,0,0,0,0,0,0,2,2,2,2,2,0,0,0,0,0,2,2,2,7,7,7,7,7,7,7,7,7,2,2,2,2,2,2,2,2,2,2,2,2,2,2,2,2,0,0,0,0,2,2,2,2
0,0,0,0,0,0,0,0,0,0,2,2,2,2,0,0,0,0,0,2,0,7,7,7,7,7,7,7,7,7,13,13,4,2,2,2,2,2,2,2,2,2,2,2,2,2,0,0,0,0,2,2,2,2
0,0,0,0,0,0,0,0,0,0,0,2,2,2,2,0,0,0,0,0,0,0,7,7,7,7,7,7,0,2,13,13,4,4,2,2,2,2,2,2,2,2,2,2,2,2,0,0,0,0,2,2,2,2
0,0,0,0,2,8,8,0,0,0,0,2,2,2,2,2,0,0,2,2,0,0,0,5,5,5,5,2,2,2,2,2,2,2,2,2,2,2,2,2,2,2,2,2,2,2,2,0,0,0,0,2,2,2
0,0,0,2,2,8,8,2,0,0,0,2,2,2,2,2,2,2,2,2,2,0,0,0,5,5,5,0,2,0,0,2,2,2,2,2,2,2,2,2,2,2,2,2,2,2,2,0,0,0,0,2,2,2
0,0,0,2,2,2,2,2,66,0,0,2,2,2,2,2,2,2,2,2,2,0,0,0,2,0,0,0,2,0,0,2,2,2,2,2,2,2,2,2,2,2,2,2,2,2,2,0,0,0,0,0,0,0
0,0,0,2,2,2,2,2,2,0,0,7,2,2,2,2,2,2,2,2,2,0,0,0,0,0,7,2,2,0,0,0,2,2,2,2,2,2,2,2,2,2,2,2,2,2,2,2,0,0,0,0,0,0
0,0,0,2,2,2,2,2,2,2,2,7,7,2,2,2,2,2,2,2,8,4,0,0,0,0,0,0,0,0,0,0,2,2,2,2,2,2,2,2,2,2,2,2,2,2,2,2,2,0,0,0,0,0
24,0,24,2,2,2,2,2,2,2,2,7,7,7,2,2,2,2,2,8,8,4,4,0,0,0,0,0,0,0,0,0,0,0,0,0,0,2,2,2,2,2,2,2,2,2,2,2,2,2,2,0,2,2
0,0,0,2,2,2,2,2,2,2,2,7,7,7,7,2,2,2,2,2,2,2,4,4,4,0,0,2,2,2,2,2,2,2,2,2,2,2,2,2,2,2,2,2,2,2,2,2,2,2,2,2,2,2
0,0,0,2,2,2,2,2,2,2,2,7,7,7,7,2,2,2,2,2,2,2,2,4,4,2,2,2,2,2,2,2,2,2,2,2,2,2,2,2,2,2,2,2,2,2,2,2,2,2,2,2,2,2
0,0,0,2,2,2,2,2,2,2,2,7,7,7,7,2,2,2,2,2,2,2,2,2,2,2,2,2,2,2,2,2,2,2,2,2,2,2,2,2,2,2,2,2,2,2,2,2,2,2,2,0,0,2
0,0,0,2,2,2,2,2,2,2,2,7,7,7,7,7,2,2,2,2,2,2,2,2,2,2,2,3,3,2,0,0,2,2,2,2,2,2,2,2,2,2,2,2,2,2,2,2,2,2,2,0,0,2
0,0,0,24,0,0,0,0,0,0,0,0,0,24,0,0,0,0,0,0,0,0,0,0,0,24,0,0,0,0,0,0,0,0,0,0,24,0,0,0,0,0,0,0,0,0,0,0,0,0,24,0,0,0
0,0,0,0,0,0,0,0,0,0,0,0,0,0,0,0,0,0,0,0,0,0,0,0,0,0,0,0,0,0,0,0,0,0,0,0,0,0,0,0,0,0,0,0,0,0,0,0,0,0,0,0,0,0
0,0,0,24,0,0,0,0,0,0,0,0,0,24,0,0,0,0,0,0,0,0,0,0,0,24,0,0,0,0,0,0,0,0,0,0,24,0,0,0,0,0,0,0,0,0,0,0,0,0,24,0,0,0
:endlayer
layer: 16
0,0,0,2,2,7,0,7,7,7,0,7,2,2,2,2,2,0,2,0,0,5,5,5,7,7,7,7,7,7,5,5,2,2,2,2,2,2,2,2,5,5,5,5,0,0,0,0,0,0,0,0,2,2
0,0,0,0,0,0,0,0,0,0,0,0,0,0,0,0,0,0,0,0,0,0,0,0,7,7,7,7,7,5,5,2,2,2,2,2,2,2,2,2,5,5,5,5,0,0,4,4,2,2,0,0,0,2
0,0,0,0,0,0,0,0,0,0,0,0,0,0,0,0,0,0,0,0,0,0,0,0,7,7,7,0,5,5,2,2,2,2,2,2,2,2,2,2,2,5,5,5,0,0,4,4,2,0,0,0,0,2
0,0,0,2,0,0,7,7,7,2,2,2,2,2,2,2,2,2,2,2,2,5,5,5,5,2,0,0,5,2,2,2,2,2,2,2,7,7,2,2,2,5,5,5,0,0,4,4,2,0,0,0,0,2
0,0,0,2,0,0,0,2,2,2,2,2,2,2,2,2,2,2,2,2,2,2,5,5,5,2,0,0,2,2,2,0,2,2,2,2,7,7,7,2,2,2,5,5,0,0,4,4,2,0,0,0,2,2
0,0,0,2,0,0,0,2,2,2,2,2,2,2,2,2,2,2,2,2,2,2,2,5,5,2,2,2,2,2,2,2,2,2,2,7,7,7,7,2,2,2,2,5,0,5,4,2,2,2,0,0,0,2
0,0,0,2,0,0,0,2,2,2,2,2,2,2,2,2,2,2,2,2,2,2,2,2,2,2,2,2,2,2,2,2,2,2,2,7,7,7,7,2,2,2,2,0,0,0,2,0,0,0,0,0,0,0
22,22,22,2,0,0,13,2,2,2,2,2,2,2,2,2,2,2,2,2,2,2,2,2,2,2,2,2,2,2,2,2,2,2,2,7,7,7,7,2,0,0,0,0,0,0,0,0,0,0,0,0,0,0
0,0,0,2,2,2,2,2,2,2,0,0,2,2,2,2,2,2,2,2,2,2,2,0,0,2,2,2,0,0,2,2,2,2,2,7,7,7,7,0,0,0,0,0,0,0,0,0,0,0,0,0,0,0
0,0,0,2,2,2,2,2,0,0,0,0,2,2,2,2,2,2,2,2,2,2,2,0,0,2,2,2,0,0,0,7,2,2,2,7,7,0,0,0,0,0,0,0,0,0,0,0,0,0,0,0,0,0
0,0,0,2,2,2,2,0,0,0,0,0,2,2,2,2,2,2,2,2,2,2,2,0,0,0,0,2,0,0,0,7,7,7,0,0,0,0,0,0,0,0,0,0,0,0,0,0,0,0,2,2,2,0
0,0,0,2,2,2,2,0,0,0,0,0,2,2,2,2,2,2,2,2,2,8,8,0,0,0,2,0,2,7,7,7,7,7,0,0,0,0,0,0,0,0,0,0,0,0,0,0,2,2,2,2,2,2
0,0,0,2,2,2,2,2,0,0,0,0,2,2,2,2,2,2,2,2,2,2,8,0,0,0,2,2,0,7,7,7,7,7,0,0,0,0,0,0,0,0,0,2,0,0,0,0,0,2,2,2,2,2
0,0,0,2,2,2,2,2,2,2,2,2,2,3,2,2,2,2,2,2,2,2,2,24,24,24,2,5,5,5,5,0,7,7,0,0,0,0,0,0,0,2,2,2,0,0,0,0,0,0,2,2,2,2
0,0,0,2,2,2,2,2,2,2,2,2,2,2,2,2,2,2,2,2,2,2,2,0,0,0,0,0,0,64,7,7,7,7,7,0,0,0,0,0,0,0,2,2,0,0,0,0,0,0,2,2,2,2
0,0,0,2,2,2,2,2,2,2,2,2,2,2,2,2,2,2,2,2,2,2,2,0,0,0,0,0,0,64,7,7,7,2,2,2,2,0,0,0,0,0,0,5,0,0,0,0,0,2,2,2,2,2
0,0,0,2,2,2,2,2,2,2,2,2,2,2,2,2,2,2,2,2,2,2,0,0,0,0,0,0,65,22,7,2,2,2,2,2,2,2,2,0,0,0,0,0,2,2,2,2,2,2,2,2,2,2
0,0,0,2,2,2,2,2,2,2,2,2,2,2,2,2,2,2,2,2,2,0,0,0,0,0,0,0,0,0,0,0,2,2,2,2,2,5,2,0,0,0,0,0,5,5,2,2,2,2,2,2,2,2
0,0,0,2,2,2,2,2,2,2,2,2,2,2,2,2,2,2,2,2,0,0,0,0,0,0,0,0,0,0,0,0,2,2,2,2,5,5,5,2,5,0,0,0,0,0,2,2,2,2,2,2,2,2
22,22,22,2,2,2,2,2,2,2,2,2,2,2,2,2,2,2,2,0,0,0,0,0,0,0,0,0,0,0,0,0,0,0,0,2,5,5,5,5,2,2,2,5,0,0,2,2,2,2,2,2,2,2
0,0,0,2,2,2,2,2,2,2,2,2,2,2,2,4,4,2,0,0,0,0,0,0,0,0,0,0,0,0,0,0,0,0,0,0,5,5,5,5,2,2,2,2,2,2,2,2,2,2,2,2,2,0
0,0,0,2,2,2,2,2,2,2,2,0,2,2,2,4,4,2,0,0,0,0,0,0,0,0,0,0,0,0,0,0,0,0,0,0,0,5,7,7,7,7,7,7,7,2,2,2,2,2,2,2,2,0
0,0,0,2,2,2,2,2,2,2,2,2,2,2,2,4,4,2,0,0,0,0,0,0,0,0,0,0,0,0,0,0,0,0,0,0,0,7,7,7,7,7,7,7,7,7,2,2,2,2,2,2,2,0
0,0,0,2,2,2,2,2,2,2,2,2,2,2,2,2,2,31,0,0,0,0,0,0,0,0,0,0,0,0,0,0,0,0,0,0,0,0,7,7,7,0,0,7,7,2,2,2,2,2,2,2,2,2
0,0,0,2,2,2,2,2,2,2,2,2,0,0,0,0,7,0,0,0,0,0,0,0,0,0,0,0,0,0,0,0,0,0,0,0,0,0,7,7,7,0,0,2,2,2,2,2,2,2,2,2,2,2
0,0,0,2,2,2,2,2,2,2,2,2,0,0,0,0,7,0,0,0,0,0,0,0,0,0,0,0,0,0,0,0,0,0,0,0,0,0,22,0,0,0,0,2,2,2,2,2,2,2,2,2,2,2
0,0,0,2,2,2,2,2,2,2,2,2,0,0,0,0,7,0,0,0,0,0,0,0,0,0,0,0,0,0,0,0,0,0,0,0,0,0,7,0,0,0,2,2,2,2,2,2,2,2,2,2,2,2
0,0,0,2,2,2,2,2,2,2,2,2,0,0,0,0,7,0,0,0,0,2,2,0,0,0,0,0,0,0,0,0,0,0,0,0,0,0,7,0,0,2,2,2,2,2,2,2,2,2,2,2,2,2
0,0,0,2,2,3,3,2,2,2,2,2,0,0,0,0,7,0,0,0,0,2,2,0,0,0,0,0,0,0,0,0,0,0,0,0,0,0,7,2,2,2,2,2,2,2,2,2,2,2,2,2,2,2
0,0,0,2,2,3,3,2,2,2,2,2,0,0,0,0,0,7,0,0,0,0,0,0,0,0,0,0,0,0,0,0,0,0,0,0,0,2,2,2,2,2,2,2,2,2,2,2,2,2,2,2,2,2
0,0,0,2,2,2,2,2,2,2,2,2,2,0,0,0,0,7,0,0,0,0,0,0,0,0,0,0,0,0,0,0,0,0,0,0,0,2,2,2,2,2,2,2,2,2,2,2,2,2,2,2,2,2
22,22,22,2,2,2,2,2,2,2,2,2,2,2,2,7,7,2,0,0,0,0,0,0,0,0,0,0,0,0,0,0,0,0,0,0,2,2,2,2,2,2,2,2,2,2,2,2,2,2,2,2,2,2
0,0,0,2,2,2,2,2,2,2,2,2,2,2,2,7,7,7,7,0,0,0,0,0,0,0,0,0,0,0,0,0,0,0,0,2,2,2,2,2,2,2,2,2,2,2,0,2,2,2,2,7,7,7
0,0,0,2,2,2,2,2,2,2,2,2,2,2,7,7,7,7,7,7,0,0,0,0,0,0,0,0,0,0,0,0,0,0,2,2,2,2,2,2,2,2,2,4,4,0,0,0,2,2,7,7,7,67
0,0,0,0,2,2,2,2,2,2,2,2,2,7,7,7,7,7,7,7,2,0,0,0,0,0,0,0,0,0,0,0,2,2,2,2,2,2,2,2,2,2,2,4,4,0,0,0,2,2,2,7,0,68
0,0,0,0,0,0,0,2,2,2,2,2,7,7,7,7,7,7,2,2,2,2,0,0,0,0,0,0,2,5,5,5,2,2,2,2,2,2,2,2,2,2,2,4,4,0,0,0,0,2,2,8,8,8
0,0,0,0,0,0,0,2,2,2,2,2,7,7,0,0,2,2,2,2,2,2,2,0,0,0,0,2,2,2,0,0,2,2,2,2,2,2,3,2,2,2,2,4,4,0,0,0,0,2,2,8,8,8
0,0,0,0,0,0,0,2,2,2,2,2,2,0,0,0,0,2,2,2,2,2,7,7,7,7,7,7,7,2,2,2,2,2,2,2,2,3,2,2,2,2,2,4,4,0,0,0,0,2,2,8,8,8
0,0,0,0,0,0,0,0,2,2,2,2,2,0,0,0,0,2,2,2,2,7,7,7,7,7,7,7,7,7,2,2,2,2,2,2,2,2,2,2,2,2,2,2,2,2,0,0,0,0,2,2,0,0
0,0,0,0,0,0,0,0,0,0,2,2,2,0,0,0,0,2,2,2,2,7,7,7,7,7,7,7,7,7,13,2,2,2,2,2,2,2,2,2,2,2,2,2,2,2,0,0,0,0,2,2,0,0
0,0,0,0,0,0,0,0,0,0,0,2,2,2,2,2,2,2,2,2,2,7,7,7,7,7,7,7,0,2,2,2,2,2,2,2,2,2,2,2,2,2,2,2,2,2,0,0,0,0,2,2,0,0
0,0,0,2,2,8,2,0,0,0,0,2,2,2,2,2,2,2,2,2,2,0,0,5,5,5,5,2,2,2,2,2,2,2,2,2,2,2,2,2,2,2,2,2,2,2,2,0,0,0,0,2,0,0
0,0,0,2,2,2,2,2,0,0,0,2,2,2,2,2,2,2,2,2,5,0,0,0,5,5,5,2,2,2,2,2,2,2,2,2,2,2,2,2,2,2,2,2,2,2,2,0,0,0,0,0,0,0
0,0,0,2,2,2,2,2,0,0,0,2,2,2,2,2,2,2,2,2,5,0,0,0,5,0,0,2,2,2,2,2,2,2,2,2,2,2,2,2,2,2,2,2,2,2,2,0,0,0,0,0,0,0
0,0,0,2,2,2,2,2,2,0,0,7,2,2,2,2,2,2,2,2,2,2,2,2,2,0,7,0,0,2,2,13,2,2,2,2,2,2,2,2,2,2,2,2,2,2,2,2,0,0,0,0,0,0
0,0,0,2,2,2,2,2,2,2,2,7,7,2,2,2,2,2,2,2,2,2,2,2,2,2,7,0,0,2,2,2,13,2,2,2,2,2,2,2,2,2,2,2,2,2,2,2,0,0,0,0,0,0
