# Ancient Warfare Structure Template File
# Auto-generated structure template file. created on: 12/21/2018 at: 1:1:31
# Lines beginning with # denote comments

header:
version=2.8
name=EmpireCountsCastle
mods=
size=43,72,39
offset=15,4,38
:endheader

#### VALIDATION ####
validation:
type=ground
survival=false
worldGenEnabled=true
unique=false
preserveBlocks=false
selectionWeight=120
clusterValue=50
minDuplicateDistance=1000
dimensionWhiteList=false
dimensionList=
biomeWhiteList=true
biomeList=minecraft:plains,traverse:meadow,biomesoplenty:meadow,minecraft:forest,minecraft:birch_forest,minecraft:birch_forest_hills,minecraft:smaller_extreme_hills
leveling=12
fill=12
border=12
blockSwap=false
:endvalidation

#### LAYERS ####
layer: 0
1,1,1,1,1,1,1,1,1,1,1,1,1,1,1,1,1,1,1,1,1,1,1,1,1,1,1,1,1,1,1,1,1,1,1,1,1,1,1,1,1,1,1
1,1,1,1,1,1,1,1,1,1,1,1,1,1,1,1,1,1,1,1,1,1,1,1,1,1,1,1,1,1,1,1,1,1,1,1,1,1,1,1,1,1,1
1,1,1,1,1,1,1,1,1,1,1,1,1,1,1,1,1,1,1,1,1,1,1,1,1,1,1,1,1,1,1,1,1,1,1,1,1,1,1,1,1,1,1
1,1,1,1,1,1,1,1,1,1,1,1,1,1,1,1,1,1,1,1,1,1,1,1,1,1,1,1,1,1,1,1,1,1,1,1,1,1,1,1,1,1,1
1,1,1,1,1,1,1,1,1,1,1,1,1,1,1,1,1,1,1,1,1,1,1,1,1,1,1,1,1,1,1,1,1,1,1,1,1,1,1,1,1,1,1
1,1,1,1,1,1,1,1,1,1,1,1,1,1,1,1,1,1,1,1,1,1,1,1,1,1,1,1,1,1,1,1,1,1,1,1,1,1,1,1,1,1,1
1,1,1,1,1,1,1,1,1,1,1,1,1,1,1,1,1,1,1,1,1,1,1,1,1,1,1,1,1,1,1,1,1,1,1,1,1,1,1,1,1,1,1
1,1,1,1,1,1,1,1,1,1,1,1,1,1,1,1,1,1,1,1,1,1,1,1,1,1,1,1,1,1,1,1,1,1,1,1,1,1,1,1,1,1,1
1,1,1,1,1,1,1,1,1,1,1,1,1,1,1,1,1,1,1,1,1,1,1,1,1,1,1,1,1,1,1,1,1,1,1,1,1,1,1,1,1,1,1
1,1,1,1,1,1,1,1,1,1,1,1,1,1,1,1,1,1,1,1,1,1,1,1,1,1,1,1,1,1,1,1,1,1,1,1,1,1,1,1,1,1,1
1,1,1,1,1,1,1,1,1,1,1,1,1,1,1,1,1,1,1,1,1,1,1,1,1,1,1,1,1,1,1,1,1,1,1,1,1,1,1,1,1,1,1
1,1,1,1,1,1,1,1,1,1,1,1,1,1,1,1,1,1,1,1,1,1,1,1,1,1,1,1,1,1,1,1,1,1,1,1,1,1,1,1,1,1,1
1,1,1,1,1,1,1,1,1,1,1,1,1,1,1,1,1,1,1,1,1,1,1,1,1,1,1,1,1,1,1,1,1,1,1,1,1,1,1,1,1,1,1
1,1,1,1,1,1,1,1,1,1,1,1,1,1,1,1,1,1,1,1,1,1,1,1,1,1,1,1,1,1,1,1,1,1,1,1,1,1,1,1,1,1,1
1,1,1,1,1,1,1,1,1,1,1,1,1,1,1,1,1,1,1,1,1,1,1,1,1,1,1,1,1,1,1,1,1,1,1,1,1,1,1,1,1,1,1
1,1,1,1,1,1,1,1,1,1,1,1,1,1,1,1,1,1,1,1,1,1,1,1,1,1,1,1,1,1,1,1,1,1,1,1,1,1,1,1,1,1,1
1,1,1,1,1,1,1,1,1,1,1,1,1,1,1,1,1,1,1,1,1,1,1,1,1,1,1,1,1,1,1,1,1,1,1,1,1,1,1,1,1,1,1
1,1,1,1,1,1,1,1,1,1,1,1,1,1,1,1,1,1,1,1,1,1,1,1,1,1,1,1,1,1,1,1,1,1,1,1,1,1,1,1,1,1,1
1,1,1,1,1,1,1,1,1,1,1,1,1,1,1,1,1,1,1,1,1,1,1,1,1,1,1,1,1,1,1,1,1,1,1,1,1,1,1,1,1,1,1
1,1,1,1,1,1,1,1,1,1,1,1,1,1,1,1,1,1,1,1,1,1,1,1,1,1,1,1,1,1,1,1,1,1,1,1,1,1,1,1,1,1,1
1,1,1,1,1,1,1,1,1,1,1,1,1,1,1,1,1,1,1,1,1,1,1,1,1,1,1,1,1,1,1,1,1,1,1,1,1,1,1,1,1,1,1
1,1,1,1,1,1,1,1,1,1,1,1,1,1,1,1,1,1,1,1,1,1,1,1,1,1,1,1,1,1,1,1,1,1,1,1,1,1,1,1,1,1,1
1,1,1,1,1,1,1,1,1,1,1,1,1,1,1,1,1,1,1,1,1,1,1,1,1,1,1,1,1,1,1,1,1,1,1,1,1,1,1,1,1,1,1
1,1,1,1,1,1,1,1,1,1,1,1,1,1,1,1,2,2,2,2,2,1,1,1,2,2,2,2,2,1,1,1,1,1,1,1,1,1,1,1,1,1,1
1,1,1,1,1,1,1,1,1,1,1,1,1,1,1,2,2,1,2,2,2,1,1,1,2,2,2,1,2,1,1,1,1,1,1,1,1,1,1,1,1,1,1
1,1,1,1,1,1,1,1,1,1,1,1,1,1,1,2,2,2,2,2,2,2,2,2,2,2,2,2,2,2,1,1,1,1,1,1,1,1,1,1,1,1,1
1,1,1,1,1,1,1,1,1,1,1,1,1,1,1,2,2,2,2,2,2,2,2,2,2,2,2,2,2,2,2,2,2,2,2,2,2,1,1,1,1,1,1
1,1,1,1,1,1,1,1,1,1,1,1,1,1,1,2,2,2,2,2,2,2,2,2,2,2,2,2,2,2,2,1,1,1,1,1,1,1,1,1,1,1,1
1,1,1,1,1,1,1,1,1,1,1,1,1,1,1,1,2,1,2,2,2,1,1,1,2,2,2,1,2,1,1,1,1,1,1,1,1,1,1,1,1,1,1
1,1,1,1,1,1,1,1,1,1,1,1,1,1,1,1,2,2,2,2,2,1,1,1,2,2,2,2,2,1,1,1,1,1,1,1,1,1,1,1,1,1,1
1,1,1,1,1,1,1,1,1,1,1,1,1,1,1,1,1,1,1,1,1,1,1,1,1,1,1,1,1,1,1,1,1,1,1,1,1,1,1,1,1,1,1
1,1,1,1,1,1,1,1,1,1,1,1,1,1,1,1,1,1,1,1,1,1,1,1,1,1,1,1,1,1,1,1,1,1,1,1,1,1,1,1,1,1,1
1,1,1,1,1,1,1,1,1,1,1,1,1,1,1,1,1,1,1,1,1,1,1,1,1,1,1,1,1,1,1,1,1,1,1,1,1,1,1,1,1,1,1
1,1,1,1,1,1,1,1,1,1,1,1,1,1,1,1,1,1,1,1,1,1,1,1,1,1,1,1,1,1,1,1,1,1,1,1,1,1,1,1,1,1,1
1,1,1,1,1,1,1,1,1,1,1,1,1,1,1,1,1,1,1,1,1,1,1,1,1,1,1,1,1,1,1,1,1,1,1,1,1,1,1,1,1,1,1
1,1,1,1,1,1,1,1,1,1,1,1,1,1,1,1,1,1,1,1,1,1,1,1,1,1,1,1,1,1,1,1,1,1,1,1,1,1,1,1,1,1,1
1,1,1,1,1,1,1,1,1,1,1,1,1,1,1,1,1,1,1,1,1,1,1,1,1,1,1,1,1,1,1,1,1,1,1,1,1,1,1,1,1,1,1
1,1,1,1,1,1,1,1,1,1,1,1,1,1,1,1,1,1,1,1,1,1,1,1,1,1,1,1,1,1,1,1,1,1,1,1,1,1,1,1,1,1,1
1,1,1,1,1,1,1,1,1,1,1,1,1,1,1,1,1,1,1,1,1,1,1,1,1,1,1,1,1,1,1,1,1,1,1,1,1,1,1,1,1,1,1
:endlayer
layer: 1
1,1,1,1,1,1,1,1,1,1,1,1,1,1,1,1,1,1,1,1,1,1,1,1,1,1,1,1,1,1,1,1,1,1,1,1,1,1,1,1,1,1,1
1,1,1,1,1,1,1,1,1,1,1,1,1,1,1,1,1,1,1,1,1,1,1,1,1,1,1,1,1,1,1,1,1,1,1,1,1,1,1,1,1,1,1
1,1,1,1,1,1,1,1,1,1,1,1,1,1,1,1,1,1,1,1,1,1,1,1,1,1,1,1,1,1,1,1,1,1,1,1,1,1,1,1,1,1,1
1,1,1,1,1,1,1,1,1,1,1,1,1,1,1,1,1,1,1,1,1,1,1,1,1,1,1,1,1,1,1,1,1,1,1,1,1,1,1,1,1,1,1
1,1,1,1,1,1,1,1,1,1,1,1,1,1,1,1,1,1,1,1,1,1,1,1,1,1,1,1,1,1,1,1,1,1,1,1,1,1,1,1,1,1,1
1,1,1,1,1,1,1,1,1,1,1,1,1,1,1,1,1,1,1,1,1,1,1,1,1,1,1,1,1,1,1,1,1,1,1,1,1,1,1,1,1,1,1
1,1,1,1,1,1,1,1,1,1,1,1,1,1,1,1,1,1,1,1,1,1,1,1,1,1,1,1,1,1,1,1,1,1,1,1,1,1,1,1,1,1,1
1,1,1,1,1,1,1,1,1,1,1,1,1,1,1,1,1,1,1,1,1,1,1,1,1,1,1,1,1,1,1,1,1,1,1,1,1,1,1,1,1,1,1
1,1,1,1,1,1,1,1,1,1,1,1,1,1,1,1,1,1,1,1,1,1,1,1,1,1,1,1,1,1,1,1,1,1,1,1,1,1,1,1,1,1,1
1,1,1,1,1,1,1,1,1,1,1,1,1,1,1,1,1,1,1,1,1,1,1,1,1,1,1,1,1,1,1,1,1,1,1,1,1,1,1,1,1,1,1
1,1,1,1,1,1,1,1,1,1,1,1,1,1,1,1,1,1,1,1,1,1,1,1,1,1,1,1,1,1,1,1,1,1,1,1,1,1,1,1,1,1,1
1,1,1,1,1,1,1,1,1,1,1,1,1,1,1,1,1,1,1,1,1,1,1,1,1,1,1,1,1,1,1,1,1,1,1,1,1,1,1,1,1,1,1
1,1,1,1,1,1,1,1,1,1,1,1,1,1,1,1,1,1,1,1,1,1,1,1,1,1,1,1,1,1,1,1,1,1,1,1,1,1,1,1,1,1,1
1,1,1,1,1,1,1,1,1,1,1,1,1,1,1,1,1,1,1,1,1,1,1,1,1,1,1,1,1,1,1,1,1,1,1,1,1,1,1,1,1,1,1
1,1,1,1,1,1,1,1,1,1,1,1,1,1,1,1,1,1,1,1,1,1,1,1,1,1,1,1,1,1,1,1,1,1,1,1,1,1,1,1,1,1,1
1,1,1,1,1,1,1,1,1,1,1,1,1,1,1,1,1,1,1,1,1,1,1,1,1,1,1,1,1,1,1,1,1,1,1,1,1,1,1,1,1,1,1
1,1,1,2,2,2,2,2,2,2,2,2,1,1,1,1,1,1,1,1,1,1,1,1,1,1,1,1,1,1,1,1,1,1,1,1,1,1,1,1,1,1,1
1,1,1,2,2,2,2,2,2,2,2,2,1,1,1,1,1,1,1,1,1,1,1,1,1,1,1,1,1,1,1,1,1,1,1,1,1,1,1,1,1,1,1
1,1,1,2,2,2,2,2,2,2,2,2,1,1,1,1,1,1,1,1,1,1,1,1,1,1,1,1,1,1,1,1,1,1,1,1,1,1,1,1,1,1,1
1,1,1,2,2,2,2,2,2,2,2,2,1,1,1,1,1,1,1,1,1,1,1,1,1,1,1,1,1,1,1,1,1,1,1,1,1,1,1,1,1,1,1
1,1,1,2,2,2,2,2,2,2,2,2,1,1,1,1,1,1,1,1,1,1,1,1,1,1,1,1,1,1,1,1,1,1,1,1,1,1,1,1,1,1,1
1,1,1,2,2,2,2,2,2,2,2,2,1,1,1,1,1,1,1,1,1,1,1,1,1,1,1,1,1,1,1,1,1,1,1,1,1,1,1,1,1,1,1
1,1,1,1,1,1,1,1,1,1,1,1,1,1,1,2,2,2,2,2,2,1,1,2,2,2,2,2,2,1,1,1,1,1,1,1,1,1,1,1,1,1,1
1,1,1,1,1,1,1,1,1,1,1,1,1,1,1,2,3,0,0,4,4,2,2,2,4,4,0,0,3,2,1,1,1,1,1,1,1,1,1,1,1,1,1
1,1,1,1,1,1,1,1,1,1,1,1,1,1,2,5,0,2,0,6,0,2,2,2,0,7,0,2,0,8,1,1,1,1,1,1,1,1,1,1,1,1,1
1,1,1,1,1,1,1,1,1,1,1,1,1,1,2,9,0,10,10,10,10,10,0,10,10,10,10,10,0,8,9,2,2,2,2,2,2,1,1,1,1,1,1
1,1,1,1,1,1,1,1,1,1,1,1,1,1,2,11,0,0,0,0,0,0,0,0,0,0,0,0,0,0,0,12,0,13,0,0,0,2,1,1,1,1,1
1,1,1,1,1,1,1,1,1,1,1,1,1,1,2,14,0,10,10,10,10,10,0,10,10,10,10,10,0,8,14,2,2,2,2,2,15,2,1,1,1,1,1
1,1,1,1,1,1,1,1,1,1,1,1,1,1,2,5,0,2,0,16,0,2,2,2,17,18,0,2,0,8,2,1,1,2,2,2,19,2,1,1,1,1,1
1,1,1,1,1,1,1,1,1,1,1,1,1,1,1,2,12,0,0,4,4,2,2,2,4,4,0,0,12,2,1,1,1,2,2,2,2,2,1,1,1,1,1
1,1,1,1,1,1,1,1,1,1,1,1,1,1,1,2,2,2,2,2,2,1,1,2,2,2,2,2,2,1,1,1,1,1,1,1,1,1,1,1,1,1,1
1,1,1,1,1,1,1,1,1,1,1,1,1,1,1,1,1,1,1,1,1,1,1,1,1,1,1,1,1,1,1,1,1,1,1,1,1,1,1,1,1,1,1
1,1,1,1,1,1,1,1,1,1,1,1,1,1,1,1,1,1,1,1,1,1,1,1,1,1,1,1,1,1,1,1,1,1,1,1,1,1,1,1,1,1,1
1,1,1,1,1,1,1,1,1,1,1,1,1,1,1,1,1,1,1,1,1,1,1,1,1,1,1,1,1,1,1,1,1,1,1,1,1,1,1,1,1,1,1
1,1,1,1,1,1,1,1,1,1,1,1,1,1,1,1,1,1,1,1,1,1,1,1,1,1,1,1,1,1,1,1,1,1,1,1,1,1,1,1,1,1,1
1,1,1,1,1,1,1,1,1,1,1,1,1,1,1,1,1,1,1,1,1,1,1,1,1,1,1,1,1,1,1,1,1,1,1,1,1,1,1,1,1,1,1
1,1,1,1,1,1,1,1,1,1,1,1,1,1,1,1,1,1,1,1,1,1,1,1,1,1,1,1,1,1,1,1,1,1,1,1,1,1,1,1,1,1,1
1,1,1,1,1,1,1,1,1,1,1,1,1,1,1,1,1,1,1,1,1,1,1,1,1,1,1,1,1,1,1,1,1,1,1,1,1,1,1,1,1,1,1
1,1,1,1,1,1,1,1,1,1,1,1,1,1,1,1,1,1,1,1,1,1,1,1,1,1,1,1,1,1,1,1,1,1,1,1,1,1,1,1,1,1,1
:endlayer
layer: 2
1,1,1,1,1,1,1,1,1,1,1,1,1,1,1,1,1,1,1,1,1,1,1,1,1,1,1,1,1,1,1,1,1,1,1,1,1,1,1,1,1,1,1
1,1,1,1,1,1,1,1,1,1,1,1,1,1,1,1,1,1,1,1,1,1,1,1,1,1,1,1,1,1,1,1,1,1,1,1,1,1,1,1,1,1,1
1,1,1,1,1,1,1,1,1,1,1,1,1,1,1,1,1,1,1,1,1,1,1,1,1,1,1,1,1,1,1,1,1,1,1,1,1,1,1,1,1,1,1
1,1,1,1,1,1,1,1,1,1,1,1,1,1,1,1,1,1,1,1,1,1,1,1,1,1,1,1,1,1,1,1,1,1,1,1,1,1,1,1,1,1,1
1,1,1,1,1,1,1,1,1,1,1,1,1,1,1,1,1,1,1,1,1,1,1,1,1,1,1,1,1,1,1,1,1,1,1,1,1,1,1,1,1,1,1
1,1,1,1,1,1,1,1,1,1,1,1,1,1,1,1,1,1,1,1,1,1,1,1,1,1,1,1,1,1,1,1,1,1,1,1,1,1,1,1,1,1,1
1,1,1,1,1,1,1,1,1,1,1,1,1,1,1,1,1,1,1,1,1,1,1,1,1,1,1,1,1,1,1,1,1,1,1,1,1,1,1,1,1,1,1
1,1,1,1,1,1,1,1,1,1,1,1,1,1,1,1,1,1,1,1,1,1,1,1,1,1,1,1,1,1,1,1,1,1,1,1,1,1,1,1,1,1,1
1,1,1,1,1,1,1,1,1,1,1,1,1,1,1,1,1,1,1,1,1,1,1,1,1,1,1,1,1,1,1,1,1,1,1,1,1,1,1,1,1,1,1
1,1,1,1,1,1,1,1,1,1,1,1,1,1,1,1,1,1,1,1,1,1,1,1,1,1,1,1,1,1,1,1,1,1,1,1,1,1,1,1,1,1,1
1,1,1,1,1,1,1,1,1,1,1,1,1,1,1,1,1,1,1,1,1,1,1,1,1,1,1,1,1,1,1,1,1,1,1,1,1,1,1,1,1,1,1
1,1,1,1,1,1,1,1,1,1,1,1,1,1,1,1,1,1,1,1,1,1,1,1,1,1,1,1,1,1,1,1,1,1,1,1,1,1,1,1,1,1,1
1,1,1,1,1,1,1,1,1,1,1,1,1,1,1,1,1,1,1,1,1,1,1,1,1,1,1,1,1,1,1,1,1,1,1,1,1,1,1,1,1,1,1
1,1,1,1,1,1,1,1,1,1,1,1,1,1,1,1,1,1,1,1,1,1,1,1,1,1,1,1,1,1,1,1,1,1,1,1,1,1,1,1,1,1,1
1,1,1,1,1,1,1,1,1,1,1,1,1,1,1,1,1,1,1,1,1,1,1,1,1,1,1,1,1,1,1,1,1,1,1,1,1,1,1,1,1,1,1
1,1,2,2,2,2,2,2,2,2,2,2,1,1,1,1,1,1,1,1,1,1,1,1,1,1,1,1,1,1,1,1,1,1,1,1,1,1,1,1,1,1,1
1,1,2,20,20,20,20,20,20,20,20,20,2,1,1,1,1,1,1,1,1,1,1,1,1,1,1,1,1,1,1,1,1,1,1,1,1,1,1,1,1,1,1
1,1,2,20,20,20,20,20,20,20,20,20,2,1,1,1,1,1,1,1,1,1,1,1,1,1,1,1,1,1,1,1,1,1,1,1,1,1,1,1,1,1,1
1,1,2,20,21,20,22,20,20,23,20,20,2,1,1,1,1,1,1,1,1,1,1,1,1,1,1,1,1,1,1,1,1,1,1,1,1,1,1,1,1,1,1
1,1,2,20,20,20,20,20,20,20,20,20,2,1,1,1,1,1,1,1,1,1,1,1,1,1,1,1,1,1,1,1,1,1,1,1,1,1,1,1,1,1,1
1,1,2,20,20,20,20,20,20,20,20,20,2,1,1,1,1,1,1,1,1,1,1,1,1,1,1,1,1,1,1,1,1,1,1,1,1,1,1,1,1,1,1
1,1,2,20,20,20,19,20,20,20,19,20,2,1,1,1,1,1,1,1,1,1,1,1,1,1,1,1,1,1,1,1,1,1,1,1,1,1,1,1,1,1,1
1,1,2,2,2,2,2,2,2,2,2,2,1,1,1,2,2,2,2,2,2,1,1,2,2,2,2,2,2,1,1,1,1,1,1,1,1,1,1,1,1,1,1
1,1,1,1,1,1,1,1,1,1,1,1,1,1,1,2,24,0,0,0,0,2,2,2,0,0,0,0,25,2,1,1,1,1,1,1,1,1,1,1,1,1,1
1,1,1,1,1,1,1,1,1,1,1,1,1,1,2,26,0,2,0,0,0,2,2,2,0,0,0,2,0,26,2,1,2,1,1,1,1,1,1,1,1,1,1
1,1,1,1,1,1,1,1,1,1,1,1,1,1,2,27,0,10,10,10,10,10,28,10,10,10,10,10,0,0,29,2,27,2,2,2,2,1,1,1,1,1,1
1,1,1,1,1,1,1,1,1,1,1,1,1,1,2,0,0,0,0,0,0,0,0,0,0,0,0,0,0,0,0,30,0,0,0,0,0,2,1,1,1,1,1
1,1,1,1,1,1,1,1,1,1,1,1,1,1,2,27,0,10,10,10,10,10,31,10,10,10,10,10,0,0,32,2,33,2,2,2,0,2,1,1,1,1,1
1,1,1,1,1,1,1,1,1,1,1,1,1,1,2,34,0,2,0,0,0,2,2,2,0,0,0,2,0,34,2,1,2,2,19,35,0,2,1,1,1,1,1
1,1,1,1,1,1,1,1,1,1,1,1,1,1,1,2,36,0,0,0,0,2,2,2,0,0,0,0,30,2,1,1,1,2,2,2,2,2,1,1,1,1,1
1,1,1,1,1,1,1,1,1,1,1,1,1,1,1,2,2,2,2,2,2,1,1,2,2,2,2,2,2,1,1,1,1,1,1,1,1,1,1,1,1,1,1
1,1,1,1,1,1,1,1,1,1,1,1,1,1,1,1,1,1,1,1,1,1,1,1,1,1,1,1,1,1,1,1,1,1,1,1,1,1,1,1,1,1,1
1,1,1,1,1,1,1,1,1,1,1,1,1,1,1,1,1,1,1,1,1,1,1,1,1,1,1,1,1,1,1,1,1,1,1,1,1,1,1,1,1,1,1
1,1,1,1,1,1,1,1,1,1,1,1,1,1,1,1,1,1,1,1,1,1,1,1,1,1,1,1,1,1,1,1,1,1,1,1,1,1,1,1,1,1,1
1,1,1,1,1,1,1,1,1,1,1,1,1,1,1,1,1,1,1,1,1,1,1,1,1,1,1,1,1,1,1,1,1,1,1,1,1,1,1,1,1,1,1
1,1,1,1,1,1,1,1,1,1,1,1,1,1,1,1,1,1,1,1,1,1,1,1,1,1,1,1,1,1,1,1,1,1,1,1,1,1,1,1,1,1,1
1,1,1,1,1,1,1,1,1,1,1,1,1,1,1,1,1,1,1,1,1,1,1,1,1,1,1,1,1,1,1,1,1,1,1,1,1,1,1,1,1,1,1
1,1,1,1,1,1,1,1,1,1,1,1,1,1,1,1,1,1,1,1,1,1,1,1,1,1,1,1,1,1,1,1,1,1,1,1,1,1,1,1,1,1,1
1,1,1,1,1,1,1,1,1,1,1,1,1,1,1,1,1,1,1,1,1,1,1,1,1,1,1,1,1,1,1,1,1,1,1,1,1,1,1,1,1,1,1
:endlayer
layer: 3
37,37,37,37,37,37,37,37,37,37,37,37,37,37,37,37,37,37,37,37,37,37,37,37,37,37,37,37,37,37,37,37,37,37,37,37,37,37,37,37,37,37,37
37,37,37,37,37,37,37,37,37,37,37,37,37,37,37,37,37,37,37,37,37,37,37,37,37,37,37,37,37,37,37,37,37,37,37,37,37,37,37,37,37,37,37
37,37,37,37,37,37,37,37,37,37,37,37,37,37,37,37,37,37,37,37,37,37,37,37,37,37,37,37,37,37,37,37,37,37,37,37,37,37,37,37,37,37,37
37,37,37,37,37,37,37,37,37,37,37,1,1,1,1,1,1,1,1,1,37,37,37,37,37,37,37,37,37,37,37,1,1,1,1,1,1,1,1,1,37,37,37
37,37,37,1,1,1,1,1,1,1,1,1,1,1,1,1,1,1,1,1,37,37,37,37,37,37,37,37,37,37,37,1,1,1,1,1,1,1,1,1,37,37,37
37,37,37,1,1,1,1,1,1,1,1,1,1,2,2,2,2,2,1,1,1,1,1,1,1,1,1,1,1,1,1,1,1,2,2,2,2,2,1,1,37,37,37
37,37,37,1,1,1,1,1,1,1,1,1,1,2,2,2,2,2,1,1,1,1,1,1,1,1,1,1,1,1,1,1,1,2,2,2,2,2,1,1,37,37,37
37,37,37,1,1,1,1,1,1,1,1,1,1,2,2,2,2,2,2,2,2,2,2,2,2,2,2,2,2,2,2,2,2,2,2,2,2,2,1,1,37,37,37
37,37,37,1,1,1,1,1,1,1,1,1,1,2,2,2,2,2,2,2,2,2,2,2,2,2,2,2,2,2,2,2,2,2,2,2,2,2,1,1,37,37,37
37,37,37,1,1,1,1,1,1,1,1,1,1,2,2,2,2,1,1,1,1,1,1,1,1,1,1,1,1,1,2,2,2,2,2,2,2,2,1,1,37,37,37
37,37,37,1,1,1,1,1,1,1,1,1,1,2,2,2,2,1,2,2,2,2,2,2,2,2,2,2,2,38,2,2,2,2,2,2,2,1,1,1,37,37,37
37,37,37,1,1,1,1,1,1,1,1,1,1,2,2,2,2,1,2,2,2,2,2,2,2,2,2,2,2,1,2,2,2,1,2,2,1,1,1,1,37,37,37
37,37,37,1,1,1,1,1,1,1,1,1,1,2,2,2,2,1,37,37,37,2,2,2,2,2,2,2,2,1,1,1,1,1,2,2,1,1,37,37,37,37,37
37,37,37,1,1,1,1,1,1,1,1,1,1,1,1,2,2,1,1,1,37,2,2,2,2,2,2,2,2,1,37,37,1,1,2,2,1,1,37,37,37,37,37
37,37,37,1,1,1,1,1,1,1,1,1,1,1,1,2,2,1,1,1,37,2,2,2,2,2,2,2,2,2,2,2,2,1,2,2,1,1,37,37,37,37,37
37,37,2,2,2,2,2,2,2,2,2,2,37,1,1,2,2,1,1,1,1,2,2,2,2,2,2,2,2,2,2,2,2,1,2,2,1,1,37,37,37,37,37
37,37,2,39,39,39,39,39,39,39,39,39,2,1,1,2,2,1,1,1,1,2,2,2,2,2,2,2,2,2,2,2,2,1,2,2,1,1,37,37,37,37,37
37,37,2,39,39,39,39,39,39,39,39,39,2,1,1,2,2,1,1,1,1,2,2,2,2,2,2,2,2,2,2,2,2,1,2,2,1,1,37,37,37,37,37
37,37,2,39,39,39,39,39,39,39,39,39,2,1,1,2,2,1,1,1,37,2,2,2,2,2,2,2,2,2,2,2,2,1,2,2,1,1,37,37,37,37,37
37,37,2,39,39,39,39,39,39,39,39,39,2,1,1,2,2,1,1,37,37,2,2,2,2,2,2,2,2,2,2,2,2,1,2,2,1,1,37,37,37,37,37
37,37,2,39,39,39,39,39,39,39,39,39,2,1,1,2,2,1,1,1,37,2,2,2,2,2,2,2,2,2,2,2,2,1,2,2,1,1,37,37,37,37,37
37,37,2,39,39,39,19,39,39,39,19,39,2,1,1,2,2,1,1,37,1,2,2,2,2,2,2,2,2,2,2,2,2,1,2,2,1,1,37,37,37,37,37
37,37,2,2,2,2,2,2,2,2,2,2,37,1,1,2,2,1,40,40,37,2,2,2,2,2,2,2,2,2,2,2,2,1,2,2,1,1,37,37,37,37,37
37,37,2,37,1,1,1,1,1,1,1,1,1,1,1,2,2,2,2,2,2,2,2,2,2,2,2,2,2,2,37,37,2,1,2,2,1,1,1,1,37,37,37
37,37,2,37,1,1,1,1,1,1,1,1,1,1,1,2,2,1,2,2,2,2,2,2,2,2,2,2,19,19,19,1,2,1,2,2,1,1,1,1,37,37,37
37,37,2,37,1,1,1,1,1,1,1,1,2,2,2,2,2,2,2,2,2,2,2,2,2,2,2,1,2,2,2,1,2,2,2,2,2,2,1,1,37,37,37
37,37,2,37,1,1,1,1,1,1,1,1,2,2,2,2,2,2,2,2,2,2,2,2,2,2,2,2,2,2,2,2,2,2,19,2,0,2,1,1,37,37,37
37,37,2,37,1,1,1,1,1,1,1,1,2,2,2,2,2,2,2,2,2,2,2,2,2,2,2,2,2,2,2,2,2,2,41,2,0,2,1,1,37,37,37
37,37,2,37,1,1,1,1,1,1,1,1,2,2,2,2,2,2,2,2,2,2,2,2,2,2,2,2,2,2,1,1,1,2,0,0,0,2,1,1,37,37,37
37,37,2,37,1,1,1,1,1,1,1,1,2,2,2,2,2,2,2,2,2,2,2,2,2,2,2,2,2,1,1,1,1,2,2,2,2,2,1,1,37,37,37
37,37,2,37,1,1,1,1,1,1,1,1,1,2,2,2,2,2,2,2,2,2,2,2,1,1,37,37,37,37,37,1,1,1,1,1,1,1,1,1,37,37,37
37,37,2,37,37,1,19,19,19,19,19,1,1,1,2,2,2,2,2,2,2,2,2,1,1,1,37,37,37,37,37,1,1,1,1,1,1,1,1,1,37,37,37
37,37,2,2,2,2,2,19,19,19,2,1,1,1,1,2,2,2,2,2,2,2,2,1,1,37,37,37,37,37,37,37,37,37,37,37,37,37,37,37,37,37,37
37,37,37,37,37,37,19,42,42,42,19,37,1,1,1,1,2,2,2,2,2,1,1,1,1,37,37,37,37,37,37,37,37,37,37,37,37,37,37,37,37,37,37
37,37,37,37,37,37,42,42,42,42,42,37,37,1,1,1,1,1,1,1,1,1,1,1,37,37,37,37,37,37,37,37,37,37,37,37,37,37,37,37,37,37,37
37,37,37,37,37,37,42,42,42,42,42,37,37,37,37,1,1,1,1,1,1,1,37,37,37,37,37,37,37,37,37,37,37,37,37,37,37,37,37,37,37,37,37
37,37,37,37,37,37,42,42,42,42,42,37,37,37,37,37,37,37,37,37,37,37,37,37,37,37,37,37,37,37,37,37,37,37,37,37,37,37,37,37,37,37,37
37,37,37,37,37,1,42,42,42,42,42,1,37,37,37,37,37,37,37,37,37,37,37,37,37,37,37,37,37,37,37,37,37,37,37,37,37,37,37,37,37,37,37
37,37,37,37,37,37,42,42,42,42,42,37,37,37,37,37,37,37,37,37,37,37,37,37,37,37,37,37,37,37,37,37,37,37,37,37,37,37,37,37,37,37,37
:endlayer
layer: 4
43,43,43,0,43,43,0,43,0,0,43,43,43,43,0,0,0,43,43,43,43,0,0,0,0,43,0,43,0,43,43,43,0,0,0,0,43,43,43,0,0,0,0
43,43,43,44,0,43,43,43,43,43,43,43,0,43,45,0,43,43,43,0,43,0,0,0,0,43,43,0,0,43,0,43,43,43,0,43,43,43,43,43,0,46,0
0,43,43,0,0,43,43,43,43,0,47,47,47,47,47,47,47,47,47,47,47,0,0,43,43,43,43,43,0,0,47,47,47,47,47,47,47,47,47,47,47,0,0
0,43,47,47,47,47,47,47,47,47,47,2,2,2,2,2,2,2,2,2,47,43,43,0,0,43,43,43,43,43,47,2,2,2,2,2,2,2,2,2,47,0,43
0,43,47,2,2,2,2,2,2,2,2,2,19,19,19,19,19,19,19,2,47,47,47,47,47,47,47,47,47,47,47,2,19,19,19,19,19,19,19,2,47,43,43
43,43,47,2,19,19,19,19,19,19,19,19,19,19,19,19,19,19,19,2,2,2,2,2,2,2,2,2,2,2,2,2,19,48,49,50,48,48,19,2,47,43,43
43,43,47,2,19,19,19,19,19,19,19,19,19,19,19,51,52,0,19,19,19,19,19,19,19,19,19,19,19,19,19,19,19,0,0,0,0,53,19,2,47,0,0
43,43,47,2,19,19,19,19,19,19,19,19,19,19,54,0,0,0,55,0,0,0,0,0,0,0,0,0,0,55,0,0,0,56,57,57,0,58,19,2,47,0,43
43,43,47,2,19,19,19,19,19,19,19,19,19,19,59,0,0,0,19,0,0,0,0,0,0,0,0,0,0,19,60,0,0,0,57,57,0,61,19,2,47,0,43
0,0,47,2,19,19,19,19,19,19,19,19,19,19,62,0,0,19,19,19,19,19,19,19,19,19,19,19,19,19,0,0,0,0,63,0,0,48,19,2,47,0,43
0,0,47,2,19,19,19,19,19,19,19,19,19,19,0,0,0,19,64,0,0,0,0,0,0,0,0,65,0,55,0,0,0,0,0,0,66,19,19,2,47,43,43
0,43,47,2,19,19,19,19,19,19,19,19,19,19,67,0,0,19,0,0,0,0,0,0,0,68,0,0,0,19,57,57,0,19,69,19,19,2,2,2,47,43,43
0,0,47,2,19,19,19,19,19,19,19,19,19,19,70,0,71,19,40,40,40,0,57,57,0,0,0,0,0,19,19,19,19,19,0,0,19,2,47,47,47,43,43
0,43,47,2,19,19,19,19,19,19,19,19,19,19,19,55,19,19,19,15,40,0,57,57,0,72,0,0,0,19,41,41,19,19,0,0,19,2,47,0,0,43,0
0,0,47,2,2,2,2,2,2,2,2,2,2,2,19,0,0,19,19,73,40,0,57,57,0,0,0,0,0,0,0,0,0,19,0,0,19,2,47,0,0,0,0
43,0,47,47,47,47,47,47,47,47,47,47,47,2,19,0,0,19,19,41,40,74,57,57,0,72,0,0,0,0,0,0,0,19,0,0,19,2,47,0,0,0,0
0,0,0,0,0,0,0,0,0,0,0,0,47,2,19,0,0,19,19,19,40,0,57,57,0,0,0,0,0,0,0,0,0,19,0,0,19,2,47,0,43,43,0
0,0,0,0,0,0,0,0,75,0,0,0,47,2,19,0,0,19,19,76,40,0,57,57,0,72,0,0,0,0,0,0,0,19,0,0,19,2,47,43,0,43,0
43,43,0,0,0,0,0,0,0,0,75,0,47,2,19,0,0,19,19,19,40,0,57,57,0,0,0,0,0,0,0,0,0,19,0,0,19,2,47,43,43,43,43
43,43,0,0,0,75,0,0,75,0,0,0,47,2,19,0,0,19,19,15,40,77,57,57,0,72,0,0,0,78,0,0,0,19,0,0,19,2,47,43,43,43,0
43,43,0,0,0,0,31,0,0,0,31,0,47,2,19,0,0,19,19,73,40,0,57,57,0,0,0,0,0,0,0,0,0,19,0,0,19,2,47,0,43,0,0
0,0,0,0,0,0,19,0,0,0,19,0,47,2,19,0,0,19,19,41,40,0,57,57,0,72,0,0,0,0,0,0,0,19,0,0,19,2,47,0,0,0,0
0,0,0,47,47,47,47,47,47,47,47,47,47,2,19,0,0,19,40,40,40,0,57,57,0,0,0,0,79,0,80,0,0,19,0,0,19,2,47,47,47,0,0
0,0,0,47,2,2,2,2,2,2,2,2,2,2,19,0,0,19,0,0,0,0,0,0,81,0,0,15,40,40,40,15,0,19,0,0,19,2,2,2,47,0,0
0,0,0,47,2,19,19,19,19,19,19,19,19,19,19,55,19,19,82,0,0,0,0,0,0,0,0,19,83,83,83,19,84,19,69,19,19,19,19,2,47,43,0
0,0,0,47,2,19,19,19,19,19,19,19,85,0,0,0,0,19,19,19,19,19,19,19,19,19,19,19,19,19,19,19,19,0,0,0,0,0,19,2,47,0,0
43,43,0,47,2,19,19,19,19,19,19,19,0,0,0,0,0,0,0,86,0,0,0,0,69,0,0,0,0,0,0,0,55,0,0,87,88,0,19,2,47,43,43
43,43,0,47,2,19,19,19,19,19,19,19,0,0,0,0,0,0,0,0,0,0,0,0,19,0,0,0,0,0,0,0,19,0,0,19,89,0,19,2,47,43,0
43,43,0,47,2,19,19,19,19,19,19,19,19,3,19,19,19,19,19,19,19,19,19,19,19,19,19,19,19,19,19,19,19,0,0,0,0,0,19,2,47,43,43
43,0,0,47,2,19,19,19,19,19,19,19,0,0,0,0,90,0,91,0,0,92,93,19,19,2,2,2,2,2,2,2,19,0,0,0,0,0,19,2,47,43,0
0,0,0,47,2,19,41,41,41,41,41,19,19,0,0,0,0,0,0,0,0,0,94,19,19,2,47,47,47,47,47,2,19,19,19,19,19,19,19,2,47,0,0
0,0,0,47,9,19,95,0,0,0,0,19,2,19,0,0,0,0,0,0,0,96,19,19,2,2,47,43,43,43,47,2,2,2,2,2,2,2,2,2,47,0,0
0,0,0,0,0,19,19,97,98,99,19,19,2,19,19,100,101,102,103,104,0,105,19,19,2,47,47,43,43,43,47,47,47,47,47,47,47,47,47,47,47,0,0
0,43,0,0,0,106,107,0,0,0,107,106,2,2,19,19,19,19,19,19,19,19,19,2,2,47,0,43,43,43,43,0,0,0,0,0,0,0,0,0,0,0,0
43,43,43,0,43,0,0,0,0,0,0,0,47,2,2,2,19,19,19,19,19,2,2,2,47,47,0,0,43,0,0,0,0,0,0,0,0,0,0,43,43,0,0
0,43,43,0,43,0,0,0,0,0,0,0,47,47,47,2,2,2,2,2,2,2,47,47,47,0,0,0,0,0,43,0,0,0,0,0,0,0,0,0,0,43,0
0,43,43,43,43,0,0,108,0,109,0,0,43,43,47,47,47,47,47,47,47,47,47,43,0,0,0,0,0,0,0,0,0,0,0,0,0,0,0,43,110,43,43
0,0,43,43,0,19,0,0,0,0,0,19,43,43,0,0,43,43,43,43,0,43,0,0,0,0,43,0,0,0,43,0,0,0,0,0,0,0,0,0,0,0,0
0,0,0,43,43,43,0,0,0,0,0,45,43,43,0,0,43,43,43,43,43,0,0,0,0,0,0,43,43,0,43,0,0,0,0,0,0,0,0,43,43,0,0
:endlayer
layer: 5
0,0,0,0,0,0,0,0,0,0,0,0,0,0,0,0,0,0,0,0,0,0,0,0,0,0,0,0,0,0,0,0,0,0,0,0,0,0,0,0,0,0,0
0,0,0,0,0,0,0,0,0,0,0,0,0,0,0,0,0,0,0,0,0,0,0,0,0,0,0,0,0,0,0,0,0,0,0,0,0,0,0,0,0,0,0
0,0,0,0,0,0,0,0,0,0,0,0,0,0,0,0,0,0,0,0,0,0,0,0,0,0,0,0,0,0,0,0,0,0,0,0,0,0,0,0,0,0,0
0,0,0,0,0,0,0,0,0,0,0,8,14,14,14,14,14,14,14,5,0,0,0,0,0,0,0,0,0,0,0,14,14,14,14,14,14,14,14,14,0,0,0
0,0,0,14,14,14,14,14,14,14,14,8,19,19,19,19,19,19,19,5,0,0,0,0,0,0,0,0,0,0,0,8,19,19,19,19,19,19,19,5,0,0,0
0,0,0,8,19,19,19,19,19,19,19,19,19,19,35,111,112,0,19,5,14,14,14,14,14,14,14,14,14,14,14,14,19,57,0,28,0,57,19,5,0,0,0
0,0,0,8,19,19,19,19,19,19,19,19,19,41,35,0,0,0,19,19,19,19,19,19,19,19,19,19,19,19,19,19,19,0,0,0,0,0,19,5,0,0,0
0,0,0,8,19,19,19,19,19,19,19,19,19,113,0,0,0,0,114,0,0,0,0,0,0,0,0,0,0,114,0,0,0,0,4,4,0,32,19,5,0,0,0
0,0,0,8,19,19,19,19,19,19,19,19,19,115,0,0,0,32,19,27,0,0,0,0,0,0,0,0,32,19,0,0,0,0,4,4,0,0,19,5,0,0,0
0,0,0,8,19,19,19,19,19,19,19,19,19,0,0,0,0,19,19,19,19,19,19,19,19,19,19,19,19,19,27,0,0,0,0,0,0,57,19,5,0,0,0
0,0,0,8,19,19,19,19,19,19,19,19,19,0,0,0,0,19,0,0,0,0,0,0,0,0,0,0,0,114,0,0,0,0,0,31,0,19,19,5,0,0,0
0,0,0,8,19,19,19,19,19,19,19,19,19,116,0,0,0,19,27,0,0,0,0,0,0,0,0,0,32,19,4,4,0,19,114,19,19,9,9,9,0,0,0
0,0,0,8,19,19,19,19,19,19,19,19,19,117,0,0,31,19,118,0,0,0,4,4,0,0,0,0,0,19,41,41,19,19,0,28,19,5,0,0,0,0,0
0,0,0,8,19,19,19,19,19,19,19,19,19,19,19,114,19,19,15,0,0,0,4,4,0,0,0,0,0,0,0,0,0,19,0,0,19,5,0,0,0,0,0
0,0,0,8,9,9,9,9,9,9,9,9,9,8,19,0,28,19,73,119,0,0,4,4,0,0,0,0,0,0,0,0,0,19,0,0,19,5,0,0,0,0,0
0,0,0,0,0,0,0,0,0,0,0,0,0,8,19,0,0,19,41,0,0,0,4,4,0,0,0,0,0,0,0,0,32,19,0,0,19,5,0,0,0,0,0
0,0,0,0,0,0,0,0,0,0,0,0,0,8,19,0,0,19,19,41,0,0,4,4,0,0,0,0,0,0,0,0,0,19,0,0,19,5,0,0,0,0,0
0,0,0,0,0,0,0,0,0,0,0,0,0,8,19,0,0,19,76,120,0,0,4,4,0,0,0,0,0,0,0,0,0,19,0,0,19,5,0,0,0,0,0
0,0,0,0,0,0,0,0,0,0,0,0,0,8,19,0,0,19,19,15,0,0,4,4,0,0,0,0,0,0,0,0,0,19,0,0,19,5,0,0,0,0,0
0,0,0,0,0,0,0,0,0,0,0,0,0,8,19,0,0,19,15,0,0,0,4,4,0,0,0,0,0,0,0,0,0,19,0,0,19,5,0,0,0,0,0
0,0,0,0,0,0,0,0,0,0,0,0,0,8,19,0,0,19,73,121,0,0,4,4,0,0,0,0,0,0,0,0,32,19,0,0,19,5,0,0,0,0,0
0,0,0,0,0,0,19,0,0,0,19,0,0,8,19,0,0,19,41,0,0,0,4,4,0,0,0,0,0,0,0,0,0,19,0,0,19,5,0,0,0,0,0
0,0,0,0,0,0,0,0,0,0,0,0,0,8,19,0,0,19,122,0,0,0,4,4,0,0,0,0,0,0,0,0,0,19,0,0,19,5,0,0,0,0,0
0,0,0,0,8,14,14,14,14,14,14,14,14,8,19,0,31,19,27,0,0,0,0,0,0,0,0,0,0,0,0,0,0,19,0,31,19,5,14,5,0,0,0
0,0,0,0,8,19,19,19,19,19,19,19,19,19,19,114,19,19,0,0,0,0,0,0,0,0,0,19,0,0,0,19,0,19,114,19,19,19,19,5,0,0,0
0,0,0,0,8,19,19,19,19,19,19,19,0,0,0,0,0,19,19,19,19,19,19,19,19,19,19,19,19,19,19,19,19,0,0,0,0,0,19,5,0,0,0
0,0,0,0,8,19,19,19,19,19,19,19,27,0,0,0,0,0,0,0,0,0,0,0,114,0,0,0,0,0,0,0,114,0,0,0,0,0,19,5,0,0,0
0,0,0,0,8,19,19,19,19,19,19,19,123,0,0,0,0,0,0,0,0,0,0,32,19,27,0,0,0,0,0,32,19,0,32,19,15,0,19,5,0,0,0
0,0,0,0,8,19,19,19,19,19,19,19,19,24,19,10,0,19,0,10,19,0,10,19,19,19,19,19,19,19,19,19,19,0,0,124,89,0,19,5,0,0,0
0,0,0,0,8,19,40,40,40,40,40,19,0,0,28,0,0,28,0,0,28,0,0,125,19,9,9,9,9,9,9,8,19,0,0,0,0,0,19,5,0,0,0
0,0,0,0,9,19,0,0,0,0,0,19,19,0,0,0,0,0,0,0,0,0,0,126,19,5,0,0,0,0,0,8,19,19,19,19,19,19,19,5,0,0,0
0,0,0,0,0,19,0,0,0,0,0,19,19,19,0,0,0,0,0,0,0,0,127,19,5,9,0,0,0,0,0,8,9,9,9,9,9,9,9,5,0,0,0
0,0,0,0,0,19,19,128,129,130,19,19,19,19,19,0,0,0,0,0,0,0,131,19,5,0,0,0,0,0,0,0,0,0,0,0,0,0,0,0,0,0,0
0,0,0,0,0,106,106,0,0,0,106,106,8,9,19,19,132,133,0,134,135,19,19,5,9,0,0,0,0,0,0,0,0,0,0,0,0,0,0,0,0,0,0
0,0,0,0,0,0,0,0,0,0,0,0,0,8,9,9,19,19,19,19,19,5,9,9,0,0,0,0,0,0,0,0,0,0,0,0,0,0,0,0,0,0,0
0,0,0,0,0,0,0,0,0,0,0,0,0,0,0,8,9,9,9,9,9,9,0,0,0,0,0,0,0,0,0,0,0,0,0,0,0,0,0,0,0,0,0
0,0,0,0,0,0,0,0,0,0,0,0,0,0,0,0,0,0,0,0,0,0,0,0,0,0,0,0,0,0,0,0,0,0,0,0,0,0,0,0,0,0,0
0,0,0,0,0,83,0,0,0,0,0,83,0,0,0,0,0,0,0,0,0,0,0,0,0,0,0,0,0,0,0,0,0,0,0,0,0,0,0,0,0,0,0
0,0,0,0,0,0,0,0,0,0,0,0,0,0,0,0,0,0,0,0,0,0,0,0,0,0,0,0,0,0,0,0,0,0,0,0,0,0,0,0,0,0,0
:endlayer
layer: 6
0,0,0,0,0,0,0,0,0,0,0,0,0,0,0,0,0,0,0,0,0,0,0,0,0,0,0,0,0,0,0,0,0,0,0,0,0,0,0,0,0,0,0
0,0,0,0,0,0,0,0,0,0,0,0,0,0,0,0,0,0,0,0,0,0,0,0,0,0,0,0,0,0,0,0,0,0,0,0,0,0,0,0,0,0,0
0,0,0,0,0,0,0,0,0,0,0,0,0,0,0,0,0,0,0,0,0,0,0,0,0,0,0,0,0,0,0,0,0,0,0,0,0,0,0,0,0,0,0
0,0,0,0,0,0,0,0,0,0,0,0,0,0,0,0,0,0,0,0,0,0,0,0,0,0,0,0,0,0,0,0,0,0,0,0,0,0,0,0,0,0,0
0,0,0,0,0,0,0,0,0,0,0,0,19,19,19,19,19,19,19,0,0,0,0,0,0,0,0,0,0,0,0,0,19,19,19,19,19,19,19,0,0,0,0
0,0,0,0,19,19,19,19,19,19,19,19,19,19,27,0,0,0,19,0,0,0,0,0,0,0,0,0,0,0,0,0,19,136,137,137,137,136,19,0,0,0,0
0,0,0,0,19,19,19,19,19,19,19,19,19,28,0,0,0,0,19,19,19,19,19,19,19,19,19,19,19,19,19,19,19,0,0,0,0,137,19,0,0,0,0
0,0,0,0,19,19,19,19,19,19,19,19,19,0,0,0,0,0,19,138,0,0,0,0,0,0,0,0,139,19,0,0,0,0,0,0,0,137,19,0,0,0,0
0,0,0,0,19,19,19,19,19,19,19,19,19,0,0,0,0,0,19,0,0,0,0,0,0,0,0,0,0,19,0,0,0,0,0,0,0,137,19,0,0,0,0
0,0,0,0,19,19,19,19,19,19,19,19,19,0,0,0,0,19,19,19,19,19,19,19,19,19,19,19,19,19,0,0,0,0,0,0,0,136,19,0,0,0,0
0,0,0,0,19,19,19,19,19,19,19,19,19,0,0,0,0,19,0,0,0,0,0,0,0,0,0,0,0,19,0,0,0,0,0,0,0,19,19,0,0,0,0
0,0,0,0,19,19,19,19,19,19,19,19,19,0,0,0,0,19,0,0,0,0,0,0,0,0,0,0,0,19,41,41,19,19,19,19,19,0,0,0,0,0,0
0,0,0,0,19,19,19,19,19,19,19,19,19,0,0,0,0,19,0,0,0,0,0,0,0,0,0,0,0,0,0,0,0,19,140,0,19,0,0,0,0,0,0
0,0,0,0,19,19,19,19,19,19,19,19,19,19,19,19,19,19,0,0,0,0,0,0,0,0,0,0,0,0,0,0,0,19,0,0,19,0,0,0,0,0,0
0,0,0,0,0,89,0,0,0,0,0,89,0,32,19,141,0,19,40,0,0,0,0,0,0,0,0,0,0,0,0,0,0,19,0,0,19,0,0,0,0,0,0
0,0,0,0,0,0,0,0,0,0,0,0,0,0,19,0,0,19,0,0,0,0,0,0,0,0,0,0,0,0,0,0,0,19,0,0,19,0,0,0,0,0,0
0,0,0,0,0,0,0,0,0,0,0,0,0,0,19,0,0,19,15,0,0,0,0,0,0,0,0,0,0,0,0,0,0,19,0,0,19,0,0,0,0,0,0
0,0,0,0,0,0,0,0,0,0,0,0,0,0,19,0,0,19,76,0,0,0,0,0,0,0,0,0,0,0,0,0,0,19,0,0,19,0,0,0,0,0,0
0,0,0,0,0,0,0,0,0,0,0,0,0,0,19,0,0,19,41,0,0,0,0,0,0,0,0,0,0,0,0,0,0,19,0,0,19,0,0,0,0,0,0
0,0,0,0,0,0,0,0,0,0,0,0,0,0,19,0,0,19,0,0,0,0,0,0,0,0,0,0,0,0,0,0,0,19,0,0,19,0,0,0,0,0,0
0,0,0,0,0,0,0,0,0,0,0,0,0,0,19,0,0,19,40,0,0,0,0,0,0,0,0,0,0,0,0,0,0,19,0,0,19,0,0,0,0,0,0
0,0,0,0,0,0,19,0,0,0,19,0,0,0,19,0,0,19,0,0,0,0,0,0,0,0,0,0,0,0,0,0,0,19,0,0,19,0,0,0,0,0,0
0,0,0,0,0,0,0,0,0,0,0,0,0,0,19,0,0,19,0,0,0,0,0,0,0,0,0,0,0,0,0,0,0,19,0,0,19,0,0,0,0,0,0
0,0,0,0,0,142,142,142,142,142,142,142,0,32,19,143,0,19,0,0,0,0,0,0,0,0,0,87,15,15,15,35,0,19,144,0,19,0,0,0,0,0,0
0,0,0,0,0,19,19,19,19,19,19,19,19,19,19,19,19,19,0,0,0,0,0,0,0,0,0,87,19,19,19,35,0,19,19,19,19,19,19,0,0,0,0
0,0,0,0,0,19,19,19,19,19,19,19,0,0,0,0,0,19,19,19,19,19,19,19,19,19,19,19,19,19,19,19,19,0,0,0,0,0,19,0,0,0,0
0,0,0,0,0,19,19,19,19,19,19,19,0,0,0,0,0,0,0,0,0,0,0,0,19,145,0,0,0,0,0,146,19,0,0,0,0,0,19,0,0,0,0
0,0,0,0,0,19,19,40,40,40,19,19,0,0,0,0,0,0,0,0,0,0,0,0,19,0,0,0,0,0,0,0,19,0,142,19,0,0,19,0,0,0,0
0,0,0,0,0,19,0,0,0,0,0,19,19,19,19,19,19,19,19,19,19,19,19,19,19,19,19,19,19,19,19,19,19,0,124,35,0,0,19,0,0,0,0
0,0,0,0,0,19,147,0,0,0,148,19,0,0,0,0,0,0,0,0,0,0,0,32,19,0,0,0,0,0,0,0,19,0,0,0,0,0,19,0,0,0,0
0,0,0,0,0,19,27,0,0,0,32,19,19,0,0,0,0,0,0,0,0,0,0,0,19,0,0,0,0,0,0,0,19,19,19,19,19,19,19,0,0,0,0
0,0,0,0,0,19,0,0,0,0,0,19,19,19,0,0,0,0,0,0,0,0,0,19,0,0,0,0,0,0,0,0,0,0,0,0,0,0,0,0,0,0,0
0,0,0,0,0,19,19,149,150,151,19,19,19,19,19,0,0,0,0,0,0,0,32,19,0,0,0,0,0,0,0,0,0,0,0,0,0,0,0,0,0,0,0
0,0,0,0,0,0,106,0,0,0,106,152,0,0,19,19,31,0,0,0,31,19,19,0,0,0,0,0,0,0,0,0,0,0,0,0,0,0,0,0,0,0,0
0,0,0,0,0,0,0,0,0,0,0,0,0,0,0,0,19,19,19,19,19,0,0,0,0,0,0,0,0,0,0,0,0,0,0,0,0,0,0,0,0,0,0
0,0,0,0,0,0,0,0,0,0,0,0,0,0,0,0,0,0,0,0,0,0,0,0,0,0,0,0,0,0,0,0,0,0,0,0,0,0,0,0,0,0,0
0,0,0,0,0,0,0,0,0,0,0,0,0,0,0,0,0,0,0,0,0,0,0,0,0,0,0,0,0,0,0,0,0,0,0,0,0,0,0,0,0,0,0
0,0,0,0,0,0,0,0,0,0,0,0,0,0,0,0,0,0,0,0,0,0,0,0,0,0,0,0,0,0,0,0,0,0,0,0,0,0,0,0,0,0,0
0,0,0,0,0,0,0,0,0,0,0,0,0,0,0,0,0,0,0,0,0,0,0,0,0,0,0,0,0,0,0,0,0,0,0,0,0,0,0,0,0,0,0
:endlayer
layer: 7
0,0,0,0,0,0,0,0,0,0,0,0,0,0,0,0,0,0,0,0,0,0,0,0,0,0,0,0,0,0,0,0,0,0,0,0,0,0,0,0,0,0,0
0,0,0,0,0,0,0,0,0,0,0,0,0,0,0,0,0,0,0,0,0,0,0,0,0,0,0,0,0,0,0,0,0,0,0,0,0,0,0,0,0,0,0
0,0,0,0,0,0,0,0,0,0,0,0,0,0,0,0,0,0,0,0,0,0,0,0,0,0,0,0,0,0,0,0,0,0,0,0,0,0,0,0,0,0,0
0,0,0,0,0,0,0,0,0,0,0,0,31,0,0,0,0,0,31,0,0,0,0,0,0,0,0,0,0,0,0,0,31,0,0,0,0,0,31,0,0,0,0
0,0,0,0,31,0,0,0,0,0,0,32,19,19,19,19,19,19,19,27,0,0,0,0,0,0,0,0,0,0,0,32,19,19,19,19,19,19,19,27,0,0,0
0,0,0,32,19,19,19,19,19,19,19,19,19,19,19,19,19,19,19,0,0,0,0,0,0,0,0,0,0,0,0,0,19,19,19,19,19,19,19,0,0,0,0
0,0,0,0,19,136,136,136,136,136,136,136,19,19,19,19,19,19,19,19,19,19,19,19,19,19,19,19,19,19,19,19,19,19,19,19,19,19,19,0,0,0,0
0,0,0,0,19,136,136,136,136,136,136,136,19,19,19,19,19,19,19,19,19,19,19,19,19,19,19,19,19,19,19,19,19,19,19,19,19,19,19,0,0,0,0
0,0,0,0,19,136,136,136,136,136,136,136,19,19,19,19,19,19,19,19,19,19,19,19,19,19,19,19,19,19,19,19,19,19,19,19,19,19,19,0,0,0,0
0,0,0,0,19,136,136,136,136,136,136,136,19,19,19,19,19,19,19,19,19,19,19,19,19,19,19,19,19,19,19,19,19,19,19,19,19,19,19,0,0,0,0
0,0,0,0,19,136,136,136,136,136,136,136,19,19,19,19,19,19,0,0,0,0,0,0,0,0,0,0,0,19,41,41,19,19,19,19,19,19,19,27,0,0,0
0,0,0,0,19,136,136,136,136,136,136,136,19,19,19,19,19,19,0,0,0,0,0,0,0,0,0,0,0,0,0,0,0,19,19,19,19,0,28,0,0,0,0
0,0,0,0,19,95,19,19,19,19,19,95,19,19,19,19,19,19,0,0,0,0,0,0,0,0,0,0,0,0,0,0,0,19,19,19,19,0,0,0,0,0,0
0,0,0,32,19,19,153,154,155,156,157,19,19,19,19,19,19,19,0,0,0,137,0,0,0,0,0,0,0,0,0,0,0,19,19,19,19,0,0,0,0,0,0
0,0,0,0,28,106,0,0,0,0,0,106,0,0,19,19,19,19,73,0,0,0,0,0,0,0,0,0,0,0,0,0,0,19,19,19,19,0,0,0,0,0,0
0,0,0,0,0,0,0,0,0,0,0,0,0,0,19,19,19,19,0,0,0,0,0,0,0,0,0,0,0,0,0,0,0,19,19,19,19,0,0,0,0,0,0
0,0,0,0,0,0,0,0,0,0,0,0,0,0,19,19,19,19,0,0,0,0,0,0,0,0,0,0,0,0,0,0,0,19,19,19,19,0,0,0,0,0,0
0,0,0,0,0,0,0,0,0,0,0,0,0,0,19,19,19,19,40,0,0,0,0,0,0,0,0,0,0,0,0,0,0,19,19,19,19,0,0,0,0,0,0
0,0,0,0,0,0,0,0,0,0,0,0,0,0,19,19,19,19,0,0,0,0,0,0,0,0,0,0,0,0,0,0,0,19,19,19,19,0,0,0,0,0,0
0,0,0,0,0,0,0,0,0,0,0,0,0,0,19,19,19,19,0,0,0,0,0,0,0,0,0,0,0,0,0,0,0,19,19,19,19,0,0,0,0,0,0
0,0,0,0,0,0,0,0,0,0,0,0,0,0,19,19,19,19,73,0,0,0,0,0,0,0,0,0,0,0,0,0,0,19,19,19,19,0,0,0,0,0,0
0,0,0,0,0,0,19,19,19,19,19,0,0,0,19,19,19,19,0,0,0,137,0,0,0,0,0,0,0,137,0,0,0,19,19,19,19,0,0,0,0,0,0
0,0,0,0,0,0,19,19,19,19,19,0,0,0,19,19,19,19,0,0,0,0,0,0,0,0,0,0,0,0,0,0,0,19,19,19,19,0,0,0,0,0,0
0,0,0,0,0,106,19,19,19,19,19,106,0,0,19,19,19,19,0,0,0,0,0,0,0,0,0,0,0,0,0,0,0,19,19,19,19,0,31,0,0,0,0
0,0,0,0,32,19,19,19,19,19,19,19,19,19,19,19,19,19,0,0,0,0,0,0,0,0,0,0,87,15,35,0,0,19,19,19,19,19,19,27,0,0,0
0,0,0,0,0,19,40,40,40,40,40,19,19,19,19,19,19,19,19,19,19,19,19,19,19,19,19,19,19,19,19,19,19,19,19,19,19,19,19,0,0,0,0
0,0,0,0,0,19,0,0,0,0,0,19,19,19,19,19,19,19,19,19,19,19,19,19,19,19,19,19,19,19,19,19,19,19,142,88,0,19,19,0,0,0,0
0,0,0,0,0,19,0,0,0,0,0,19,19,19,19,19,19,19,19,19,19,19,19,19,19,19,19,19,19,19,19,19,19,19,41,19,27,19,19,0,0,0,0
0,0,0,0,0,87,0,0,0,0,0,19,19,19,19,19,19,19,19,19,19,19,19,19,19,19,19,19,19,19,19,19,19,19,0,0,0,19,19,0,0,0,0
0,0,0,0,0,19,0,0,0,0,0,19,19,19,19,19,19,19,19,19,19,19,19,19,19,0,0,0,0,0,0,0,19,19,19,19,19,19,19,0,0,0,0
0,0,0,0,0,19,0,0,0,0,0,19,19,19,19,19,19,19,19,19,19,19,19,19,19,27,0,0,0,0,0,32,19,19,19,19,19,19,19,27,0,0,0
0,0,0,0,0,19,0,0,0,0,0,19,19,19,19,19,19,19,19,19,19,19,19,19,28,0,0,0,0,0,0,0,28,0,0,0,0,0,28,0,0,0,0
0,0,0,0,32,19,19,158,159,160,19,19,19,19,19,19,19,19,19,19,19,19,19,19,0,0,0,0,0,0,0,0,0,0,0,0,0,0,0,0,0,0,0
0,0,0,0,0,28,106,0,0,0,106,28,0,0,19,19,19,19,19,19,19,19,19,0,0,0,0,0,0,0,0,0,0,0,0,0,0,0,0,0,0,0,0
0,0,0,0,0,0,0,0,0,0,0,0,0,0,0,32,19,19,19,19,19,27,0,0,0,0,0,0,0,0,0,0,0,0,0,0,0,0,0,0,0,0,0
0,0,0,0,0,0,0,0,0,0,0,0,0,0,0,0,28,0,0,0,28,0,0,0,0,0,0,0,0,0,0,0,0,0,0,0,0,0,0,0,0,0,0
0,0,0,0,0,0,0,0,0,0,0,0,0,0,0,0,0,0,0,0,0,0,0,0,0,0,0,0,0,0,0,0,0,0,0,0,0,0,0,0,0,0,0
0,0,0,0,0,0,0,0,0,0,0,0,0,0,0,0,0,0,0,0,0,0,0,0,0,0,0,0,0,0,0,0,0,0,0,0,0,0,0,0,0,0,0
0,0,0,0,0,0,0,0,0,0,0,0,0,0,0,0,0,0,0,0,0,0,0,0,0,0,0,0,0,0,0,0,0,0,0,0,0,0,0,0,0,0,0
:endlayer
layer: 8
0,0,0,0,0,0,0,0,0,0,0,0,0,0,0,0,0,0,0,0,0,0,0,0,0,0,0,0,0,0,0,0,0,0,0,0,0,0,0,0,0,0,0
0,0,0,0,0,0,0,0,0,0,0,0,0,0,0,0,0,0,0,0,0,0,0,0,0,0,0,0,0,0,0,0,0,0,0,0,0,0,0,0,0,0,0
0,0,0,0,0,0,0,0,0,0,0,0,0,0,0,0,0,0,0,0,0,0,0,0,0,0,0,0,0,0,0,0,0,0,0,0,0,0,0,0,0,0,0
0,0,0,0,0,0,0,0,0,0,0,0,0,0,0,0,0,0,0,0,0,0,0,0,0,0,0,0,0,0,0,0,0,0,0,0,0,0,0,0,0,0,0
0,0,0,0,0,0,0,0,0,0,0,0,19,19,19,19,19,19,19,0,0,0,0,0,0,0,0,0,0,0,0,0,19,19,19,19,19,19,19,0,0,0,0
0,0,0,0,19,19,15,19,19,15,19,19,19,0,0,0,0,0,19,0,0,0,0,0,0,0,0,0,0,0,0,0,19,0,0,0,0,0,19,0,0,0,0
0,0,0,0,19,0,0,0,0,0,0,0,19,19,19,19,19,19,19,19,19,19,19,19,19,19,19,19,19,19,19,19,19,0,0,87,88,0,19,0,0,0,0
0,0,0,0,87,0,0,0,0,0,0,0,161,162,0,0,0,0,0,0,0,0,0,0,0,0,0,0,0,0,0,0,69,0,0,19,89,0,19,0,0,0,0
0,0,0,0,19,0,0,0,0,0,0,0,161,162,0,0,0,0,0,0,0,0,0,0,0,0,0,0,0,0,0,0,19,0,0,0,0,0,19,0,0,0,0
0,0,0,0,19,0,0,0,0,0,0,0,19,0,0,0,0,19,19,19,19,19,19,19,19,19,19,19,19,19,0,0,19,0,0,0,0,0,19,0,0,0,0
0,0,0,0,19,0,163,0,0,164,165,0,19,0,19,69,19,19,0,0,0,0,0,0,0,0,0,0,0,19,0,0,19,19,55,19,19,19,19,0,0,0,0
0,0,0,0,87,0,0,166,0,0,0,0,19,0,19,0,0,19,0,0,0,0,0,0,0,0,0,0,0,0,0,0,0,19,0,0,19,0,0,0,0,0,0
0,0,0,0,19,0,0,0,0,0,0,0,19,19,19,0,0,19,0,0,0,167,0,0,0,0,0,0,0,0,0,0,0,19,0,0,19,0,0,0,0,0,0
0,0,0,0,19,19,168,169,170,171,172,19,19,19,19,0,0,19,73,0,167,173,167,0,0,0,0,0,0,0,0,0,0,19,0,0,19,0,0,0,0,0,0
0,0,0,0,0,106,0,0,0,0,0,106,0,0,19,0,0,19,76,0,0,167,0,0,0,0,0,0,0,0,0,0,0,19,0,0,19,0,0,0,0,0,0
0,0,0,0,0,0,0,0,0,0,0,0,0,0,19,0,0,19,73,0,0,0,0,0,0,0,0,0,0,0,0,0,0,19,0,0,19,0,0,0,0,0,0
0,0,0,0,0,0,0,0,0,0,0,0,0,0,19,0,0,19,0,0,0,0,0,0,0,0,0,0,0,0,0,0,0,19,0,0,19,0,0,0,0,0,0
0,0,0,0,0,0,0,0,0,0,0,0,0,0,40,174,0,19,27,0,0,0,0,0,0,0,0,0,0,0,0,0,0,19,0,0,19,0,0,0,0,0,0
0,0,0,0,0,0,0,0,0,0,0,0,0,0,19,0,0,19,0,0,0,0,0,0,0,0,0,0,0,0,0,0,0,19,0,0,19,0,0,0,0,0,0
0,0,0,0,0,0,0,0,0,0,0,0,0,0,19,0,0,19,73,0,0,0,0,0,0,0,0,0,0,0,0,0,0,19,0,0,19,0,0,0,0,0,0
0,0,0,0,0,0,0,0,0,0,0,0,0,0,40,175,0,19,76,0,0,167,0,0,0,0,0,0,0,167,0,0,0,19,0,0,19,0,0,0,0,0,0
0,0,0,0,0,0,0,0,0,0,0,0,0,0,19,0,0,19,73,0,167,173,167,0,0,0,0,0,167,173,167,0,0,19,0,0,19,0,0,0,0,0,0
0,0,0,0,0,0,0,0,0,0,0,0,0,0,19,0,0,19,0,0,0,167,0,0,0,0,0,0,0,167,0,0,0,19,0,0,19,0,0,0,0,0,0
0,0,0,0,0,106,0,0,0,0,0,106,0,0,19,0,0,19,0,0,0,0,0,0,0,0,0,0,0,0,0,0,0,19,0,0,19,0,0,0,0,0,0
0,0,0,0,0,19,0,0,0,0,0,19,19,19,19,69,19,19,0,0,0,0,0,0,0,0,0,0,0,0,0,0,0,19,55,19,19,19,19,0,0,0,0
0,0,0,0,0,19,0,0,0,0,0,19,136,176,0,0,0,19,19,19,19,19,19,19,19,19,19,19,19,19,19,19,19,0,0,0,0,0,19,0,0,0,0
0,0,0,0,0,87,0,0,0,0,0,19,177,178,0,0,0,0,0,0,0,0,0,0,55,0,0,0,0,0,0,0,55,0,0,87,88,0,19,0,0,0,0
0,0,0,0,0,19,0,0,0,0,0,19,136,179,0,0,0,0,0,0,0,0,0,0,19,0,0,0,0,0,0,0,19,0,0,19,89,0,19,0,0,0,0
0,0,0,0,0,10,0,0,0,0,0,19,177,178,0,0,0,0,19,0,180,0,181,136,19,19,19,19,19,19,19,19,19,0,0,0,0,0,19,0,0,0,0
0,0,0,0,0,19,0,0,0,0,0,19,136,182,0,183,0,0,0,0,0,0,184,185,19,0,0,0,0,0,0,0,19,0,0,0,0,0,19,0,0,0,0
0,0,0,0,0,19,88,0,0,0,124,19,19,0,0,0,0,0,186,0,0,0,187,136,19,0,0,0,0,0,0,0,19,19,19,19,19,19,19,0,0,0,0
0,0,0,0,0,19,0,0,0,0,0,19,19,19,188,189,190,0,0,0,191,189,136,19,0,0,0,0,0,0,0,0,0,0,0,0,0,0,0,0,0,0,0
0,0,0,0,0,19,19,192,193,194,19,19,19,19,136,195,136,189,196,189,136,195,136,19,0,0,0,0,0,0,0,0,0,0,0,0,0,0,0,0,0,0,0
0,0,0,0,0,0,106,0,0,0,106,0,0,0,19,19,136,195,136,195,136,19,19,0,0,0,0,0,0,0,0,0,0,0,0,0,0,0,0,0,0,0,0
0,0,0,0,0,0,0,0,0,0,0,0,0,0,0,0,19,19,19,19,19,0,0,0,0,0,0,0,0,0,0,0,0,0,0,0,0,0,0,0,0,0,0
0,0,0,0,0,0,0,0,0,0,0,0,0,0,0,0,0,0,0,0,0,0,0,0,0,0,0,0,0,0,0,0,0,0,0,0,0,0,0,0,0,0,0
0,0,0,0,0,0,0,0,0,0,0,0,0,0,0,0,0,0,0,0,0,0,0,0,0,0,0,0,0,0,0,0,0,0,0,0,0,0,0,0,0,0,0
0,0,0,0,0,0,0,0,0,0,0,0,0,0,0,0,0,0,0,0,0,0,0,0,0,0,0,0,0,0,0,0,0,0,0,0,0,0,0,0,0,0,0
0,0,0,0,0,0,0,0,0,0,0,0,0,0,0,0,0,0,0,0,0,0,0,0,0,0,0,0,0,0,0,0,0,0,0,0,0,0,0,0,0,0,0
:endlayer
layer: 9
0,0,0,0,0,0,0,0,0,0,0,0,0,0,0,0,0,0,0,0,0,0,0,0,0,0,0,0,0,0,0,0,0,0,0,0,0,0,0,0,0,0,0
0,0,0,0,0,0,0,0,0,0,0,0,0,0,0,0,0,0,0,0,0,0,0,0,0,0,0,0,0,0,0,0,0,0,0,0,0,0,0,0,0,0,0
0,0,0,0,0,0,0,0,0,0,0,0,0,0,0,0,0,0,0,0,0,0,0,0,0,0,0,0,0,0,0,0,0,0,0,0,0,0,0,0,0,0,0
0,0,0,0,0,0,0,0,0,0,0,0,0,0,0,0,0,0,0,0,0,0,0,0,0,0,0,0,0,0,0,0,0,0,0,0,0,0,0,0,0,0,0
0,0,0,0,0,0,0,0,0,0,0,0,19,19,19,19,19,19,19,0,0,0,0,0,0,0,0,0,0,0,0,0,19,19,19,19,19,19,19,0,0,0,0
0,0,0,0,19,19,10,19,19,10,19,19,19,0,0,0,0,0,19,0,0,0,0,0,0,0,0,0,0,0,0,0,19,0,0,0,0,0,19,0,0,0,0
0,0,0,0,19,0,0,0,0,0,0,29,19,19,19,19,19,19,19,19,19,19,19,19,19,19,19,19,19,19,19,19,19,0,0,0,0,0,19,0,0,0,0
0,0,0,0,10,0,0,0,0,0,0,0,24,0,28,0,0,0,0,0,28,0,0,0,0,0,28,0,0,0,0,0,114,0,32,19,15,0,19,0,0,0,0
0,0,0,0,19,0,0,0,0,0,0,0,25,0,0,0,0,0,0,0,31,0,0,0,0,0,31,0,0,0,0,32,19,0,0,124,89,0,19,0,0,0,0
0,0,0,0,19,0,0,0,0,0,0,29,19,0,0,0,197,19,19,10,19,10,19,10,19,10,19,10,19,19,0,0,19,0,0,0,0,0,19,0,0,0,0
0,0,0,0,19,0,0,0,0,0,0,0,19,0,19,114,19,19,0,0,0,0,0,0,0,0,0,0,0,19,0,0,19,19,114,19,19,19,19,0,0,0,0
0,0,0,0,10,0,0,0,0,0,0,0,19,0,19,0,28,19,0,0,0,0,0,0,0,0,0,0,0,0,0,0,0,19,0,28,19,0,0,0,0,0,0
0,0,0,0,19,0,0,0,0,0,0,0,19,19,19,0,0,19,0,0,0,57,0,0,0,0,0,0,0,0,0,0,0,19,0,0,19,0,0,0,0,0,0
0,0,0,0,19,19,198,199,200,201,202,19,19,19,19,0,0,19,73,0,57,57,57,0,0,0,0,0,0,0,0,0,0,19,0,0,19,0,0,0,0,0,0
0,0,0,0,0,106,0,0,0,0,0,106,0,0,19,0,0,19,76,0,0,57,0,0,0,0,0,0,0,0,0,0,0,19,0,0,19,0,0,0,0,0,0
0,0,0,0,0,0,0,0,0,0,0,0,0,0,19,0,0,19,73,0,0,0,0,0,0,0,0,0,0,0,0,0,0,19,0,0,19,0,0,0,0,0,0
0,0,0,0,0,0,0,0,0,0,0,0,0,0,19,0,0,19,0,0,0,0,0,0,0,0,0,0,0,0,0,0,0,19,0,0,19,0,0,0,0,0,0
0,0,0,0,0,0,0,0,0,0,0,0,0,0,0,0,0,19,0,0,0,0,0,0,0,0,0,0,0,0,0,0,0,19,0,0,19,0,0,0,0,0,0
0,0,0,0,0,0,0,0,0,0,0,0,0,0,19,0,0,19,0,0,0,0,0,0,0,0,0,0,0,0,0,0,0,19,0,0,19,0,0,0,0,0,0
0,0,0,0,0,0,0,0,0,0,0,0,0,0,19,0,0,19,73,0,0,0,0,0,0,0,0,0,0,0,0,0,0,19,0,0,19,0,0,0,0,0,0
0,0,0,0,0,0,0,0,0,0,0,0,0,0,0,0,0,19,76,0,0,57,0,0,0,0,0,0,0,57,0,0,0,19,0,0,19,0,0,0,0,0,0
0,0,0,0,0,0,0,0,0,0,0,0,0,0,19,0,0,19,73,0,57,57,57,0,0,0,0,0,57,57,57,0,0,19,0,0,19,0,0,0,0,0,0
0,0,0,0,0,0,0,0,0,0,0,0,0,0,19,0,0,19,0,0,0,57,0,0,0,0,0,0,0,57,0,0,0,19,0,0,19,0,0,0,0,0,0
0,0,0,0,0,106,0,0,0,0,0,106,0,0,19,0,31,19,0,0,0,0,0,0,0,0,0,0,0,0,0,0,0,19,0,31,19,0,0,0,0,0,0
0,0,0,0,0,19,27,0,0,0,32,19,19,19,19,114,19,19,0,0,0,0,0,0,0,0,0,0,0,0,0,0,0,19,114,19,19,19,19,0,0,0,0
0,0,0,0,0,19,0,0,0,0,0,19,136,27,0,0,28,19,19,19,19,19,19,19,19,19,19,19,19,19,19,19,19,0,0,28,0,0,19,0,0,0,0
0,0,0,0,0,10,0,0,0,0,0,19,0,0,0,0,0,0,0,0,0,0,0,0,114,0,0,0,0,0,0,0,114,0,0,0,0,0,19,0,0,0,0
0,0,0,0,0,19,0,0,0,0,0,19,136,27,0,0,0,0,0,0,0,0,0,32,19,27,0,0,0,0,0,0,19,27,32,19,15,0,19,0,0,0,0
0,0,0,0,0,10,0,0,0,0,0,19,0,0,0,0,0,0,19,0,0,0,32,136,19,19,19,19,19,19,19,19,19,0,0,124,89,0,19,0,0,0,0
0,0,0,0,0,19,0,0,0,0,0,19,136,27,0,0,0,0,0,0,0,0,0,0,19,0,0,0,0,0,0,0,19,0,0,0,0,0,19,0,0,0,0
0,0,0,0,0,19,19,19,19,19,19,19,19,0,0,0,0,0,0,0,0,0,32,136,19,0,0,0,0,0,0,0,19,19,19,19,19,19,19,0,0,0,0
0,0,0,0,0,19,19,19,19,19,19,19,19,19,31,0,31,0,0,0,31,0,136,19,0,0,0,0,0,0,0,0,0,0,0,0,0,0,0,0,0,0,0
0,0,0,0,0,19,19,19,19,19,19,19,19,19,136,0,136,0,31,0,136,0,136,19,0,0,0,0,0,0,0,0,0,0,0,0,0,0,0,0,0,0,0
0,0,0,0,0,106,106,106,106,106,106,106,0,0,19,19,136,0,136,0,136,19,19,0,0,0,0,0,0,0,0,0,0,0,0,0,0,0,0,0,0,0,0
0,0,0,0,0,0,0,0,0,0,0,0,0,0,0,0,19,19,19,19,19,0,0,0,0,0,0,0,0,0,0,0,0,0,0,0,0,0,0,0,0,0,0
0,0,0,0,0,0,0,0,0,0,0,0,0,0,0,0,0,0,0,0,0,0,0,0,0,0,0,0,0,0,0,0,0,0,0,0,0,0,0,0,0,0,0
0,0,0,0,0,0,0,0,0,0,0,0,0,0,0,0,0,0,0,0,0,0,0,0,0,0,0,0,0,0,0,0,0,0,0,0,0,0,0,0,0,0,0
0,0,0,0,0,0,0,0,0,0,0,0,0,0,0,0,0,0,0,0,0,0,0,0,0,0,0,0,0,0,0,0,0,0,0,0,0,0,0,0,0,0,0
0,0,0,0,0,0,0,0,0,0,0,0,0,0,0,0,0,0,0,0,0,0,0,0,0,0,0,0,0,0,0,0,0,0,0,0,0,0,0,0,0,0,0
:endlayer
layer: 10
0,0,0,0,0,0,0,0,0,0,0,0,0,0,0,0,0,0,0,0,0,0,0,0,0,0,0,0,0,0,0,0,0,0,0,0,0,0,0,0,0,0,0
0,0,0,0,0,0,0,0,0,0,0,0,0,0,0,0,0,0,0,0,0,0,0,0,0,0,0,0,0,0,0,0,0,0,0,0,0,0,0,0,0,0,0
0,0,0,0,0,0,0,0,0,0,0,0,0,0,0,0,0,0,0,0,0,0,0,0,0,0,0,0,0,0,0,0,0,0,0,0,0,0,0,0,0,0,0
0,0,0,0,0,0,0,0,0,0,0,0,0,0,0,0,0,0,0,0,0,0,0,0,0,0,0,0,0,0,0,0,0,0,0,0,0,0,0,0,0,0,0
0,0,0,0,0,0,0,0,0,0,0,0,19,19,19,19,19,19,19,0,0,0,0,0,0,0,0,0,0,0,0,0,19,19,19,19,19,19,19,0,0,0,0
0,0,0,0,19,19,10,19,19,10,19,19,19,0,0,0,0,0,19,0,0,0,0,0,0,0,0,0,0,0,0,0,19,0,0,0,0,0,19,0,0,0,0
0,0,0,0,19,27,0,0,28,0,0,32,19,19,19,19,19,19,19,19,19,19,19,19,19,19,19,19,19,19,19,19,19,0,0,0,0,0,19,0,0,0,0
0,0,0,0,10,0,0,0,0,0,0,0,19,0,0,0,0,0,0,0,0,0,0,0,0,0,0,0,0,0,0,0,19,0,142,19,0,0,19,0,0,0,0
0,0,0,0,19,0,0,0,0,0,0,0,19,0,0,0,0,0,0,0,0,0,0,0,0,0,0,0,0,0,0,0,19,0,124,35,0,0,19,0,0,0,0
0,0,0,0,19,27,0,0,0,0,0,0,19,0,0,0,0,19,19,19,19,19,19,19,19,19,19,19,19,19,0,0,19,0,0,0,0,0,19,0,0,0,0
0,0,0,0,19,0,0,0,0,0,0,32,19,0,19,19,19,19,0,0,0,0,0,0,0,203,0,0,0,19,0,0,19,19,19,19,19,19,19,0,0,0,0
0,0,0,0,10,0,0,0,0,0,0,0,19,0,19,204,0,19,0,0,0,0,0,0,0,203,0,0,0,0,0,0,0,19,205,0,19,0,0,0,0,0,0
0,0,0,0,19,31,0,0,0,0,0,31,19,19,19,0,0,19,0,0,0,0,0,0,0,203,0,0,0,0,0,0,0,19,0,0,19,0,0,0,0,0,0
0,0,0,0,19,19,206,207,208,209,210,19,19,19,19,0,0,19,73,0,0,57,0,0,0,203,0,0,0,0,0,0,0,19,0,0,19,0,0,0,0,0,0
0,0,0,0,0,106,0,0,0,0,0,106,0,0,19,0,0,19,76,0,0,0,0,0,0,203,0,0,0,0,0,0,0,19,0,0,19,0,0,0,0,0,0
0,0,0,0,0,0,0,0,0,0,0,0,0,0,19,0,0,19,73,0,0,0,0,0,0,203,0,0,0,0,0,0,0,19,0,0,19,0,0,0,0,0,0
0,0,0,0,0,0,0,0,0,0,0,0,0,0,19,0,0,19,0,0,0,0,0,0,0,203,0,0,0,0,0,0,0,19,0,0,19,0,0,0,0,0,0
0,0,0,0,0,0,0,0,0,0,0,0,0,0,19,0,0,19,203,203,203,203,203,203,203,203,203,203,203,203,203,203,203,19,0,0,19,0,0,0,0,0,0
0,0,0,0,0,0,0,0,0,0,0,0,0,0,19,0,0,19,0,0,0,0,0,0,0,203,0,0,0,0,0,0,0,19,0,0,19,0,0,0,0,0,0
0,0,0,0,0,0,0,0,0,0,0,0,0,0,19,0,0,19,73,0,0,0,0,0,0,203,0,0,0,0,0,0,0,19,0,0,19,0,0,0,0,0,0
0,0,0,0,0,0,0,0,0,0,0,0,0,0,19,0,0,19,76,0,0,0,0,0,0,203,0,0,0,0,0,0,0,19,0,0,19,0,0,0,0,0,0
0,0,0,0,0,0,0,0,0,0,0,0,0,0,19,0,0,19,73,0,0,57,0,0,0,203,0,0,0,57,0,0,0,19,0,0,19,0,0,0,0,0,0
0,0,0,0,0,0,0,0,0,0,0,0,0,0,19,0,0,19,0,0,0,0,0,0,0,203,0,0,0,0,0,0,0,19,0,0,19,0,0,0,0,0,0
0,0,0,0,0,106,0,0,0,0,0,106,0,0,19,211,0,19,0,0,0,0,0,0,0,203,0,0,0,0,0,0,0,19,212,0,19,0,0,0,0,0,0
0,0,0,0,0,19,0,0,0,0,0,19,19,19,19,19,19,19,0,0,0,0,0,0,0,203,0,0,0,0,0,0,0,19,19,19,19,19,19,0,0,0,0
0,0,0,0,0,19,0,0,0,0,0,19,136,0,0,0,0,19,19,19,19,19,19,19,19,19,19,19,19,19,19,19,19,0,0,0,0,0,19,0,0,0,0
0,0,0,0,0,10,0,0,0,0,0,19,213,0,0,0,0,0,0,0,0,0,0,0,19,214,0,0,0,0,0,215,19,0,0,0,0,0,19,0,0,0,0
0,0,0,0,0,19,142,0,142,0,142,19,136,0,0,0,0,0,0,0,0,0,0,0,19,0,0,0,0,0,0,0,19,0,142,19,0,0,19,0,0,0,0
0,0,0,0,0,19,19,19,19,19,19,19,213,0,0,0,0,0,19,0,0,0,0,136,19,19,19,19,19,19,19,19,19,0,124,35,0,0,19,0,0,0,0
0,0,0,0,0,19,19,19,19,19,19,19,136,0,0,0,0,0,0,0,0,0,0,216,19,0,0,0,0,0,0,0,19,0,0,0,0,0,19,0,0,0,0
0,0,0,0,0,19,19,19,19,19,19,19,19,0,0,0,0,0,0,0,0,0,0,136,19,0,0,0,0,0,0,0,19,19,19,19,19,19,19,0,0,0,0
0,0,0,0,0,41,41,41,41,41,41,41,41,19,0,0,0,0,0,0,0,0,136,19,0,0,0,0,0,0,0,0,0,0,0,0,0,0,0,0,0,0,0
0,0,0,0,0,0,0,0,0,0,0,0,0,19,136,217,136,0,0,0,136,217,136,19,0,0,0,0,0,0,0,0,0,0,0,0,0,0,0,0,0,0,0
0,0,0,0,0,218,0,0,218,0,0,218,0,0,19,19,136,217,136,217,136,19,19,0,0,0,0,0,0,0,0,0,0,0,0,0,0,0,0,0,0,0,0
0,0,0,0,0,0,0,0,0,0,0,0,0,0,0,0,19,19,19,19,19,0,0,0,0,0,0,0,0,0,0,0,0,0,0,0,0,0,0,0,0,0,0
0,0,0,0,0,0,0,0,0,0,0,0,0,0,0,0,0,0,0,0,0,0,0,0,0,0,0,0,0,0,0,0,0,0,0,0,0,0,0,0,0,0,0
0,0,0,0,0,0,0,0,0,0,0,0,0,0,0,0,0,0,0,0,0,0,0,0,0,0,0,0,0,0,0,0,0,0,0,0,0,0,0,0,0,0,0
0,0,0,0,0,0,0,0,0,0,0,0,0,0,0,0,0,0,0,0,0,0,0,0,0,0,0,0,0,0,0,0,0,0,0,0,0,0,0,0,0,0,0
0,0,0,0,0,0,0,0,0,0,0,0,0,0,0,0,0,0,0,0,0,0,0,0,0,0,0,0,0,0,0,0,0,0,0,0,0,0,0,0,0,0,0
:endlayer
layer: 11
0,0,0,0,0,0,0,0,0,0,0,0,0,0,0,0,0,0,0,0,0,0,0,0,0,0,0,0,0,0,0,0,0,0,0,0,0,0,0,0,0,0,0
0,0,0,0,0,0,0,0,0,0,0,0,0,0,0,0,0,0,0,0,0,0,0,0,0,0,0,0,0,0,0,0,0,0,0,0,0,0,0,0,0,0,0
0,0,0,0,0,0,0,0,0,0,0,0,0,0,0,0,0,0,0,0,0,0,0,0,0,0,0,0,0,0,0,0,0,0,0,0,0,0,0,0,0,0,0
0,0,0,0,0,0,0,0,0,0,0,0,0,0,0,0,0,0,0,0,0,0,0,0,0,0,0,0,0,0,0,0,0,0,0,0,0,0,0,0,0,0,0
0,0,0,0,0,0,0,0,0,0,0,0,19,19,19,19,19,19,19,0,0,0,0,0,0,0,0,0,0,0,0,0,19,19,19,19,19,19,19,0,0,0,0
0,0,0,0,19,19,19,19,19,19,19,19,19,19,19,19,19,19,19,0,0,0,0,0,0,0,0,0,0,0,0,0,19,19,19,19,19,19,19,0,0,0,0
0,0,0,0,19,0,0,0,0,0,0,0,19,19,19,19,19,19,19,19,19,19,19,19,19,19,19,19,19,19,19,19,19,19,142,88,0,19,19,0,0,0,0
0,0,0,0,19,0,0,0,0,0,0,0,19,19,89,89,89,89,89,89,89,89,89,89,89,89,89,89,89,89,89,124,19,19,41,19,27,19,19,0,0,0,0
0,0,0,0,19,0,0,0,0,0,0,0,19,19,142,88,124,142,142,142,142,142,142,142,142,142,142,142,142,142,88,124,19,19,0,0,0,19,19,0,0,0,0
0,0,0,0,19,0,0,0,0,0,0,0,19,19,19,142,124,19,19,19,19,19,19,19,19,19,19,19,19,19,88,124,19,19,19,19,19,19,19,0,0,0,0
0,0,0,0,19,0,0,0,0,0,0,0,19,19,19,19,19,19,19,89,89,89,89,89,89,19,88,89,89,19,88,124,19,19,19,19,19,19,19,0,0,0,0
0,0,0,0,19,0,0,0,0,0,0,0,19,19,19,19,19,19,19,203,203,203,203,203,124,19,88,203,124,89,89,89,89,19,19,19,19,0,0,0,0,0,0
0,0,0,0,19,0,0,0,0,0,0,0,19,19,19,19,19,19,19,203,203,203,203,203,124,19,88,203,203,203,203,203,124,19,19,19,19,0,0,0,0,0,0
0,0,0,0,19,19,219,220,221,222,223,19,19,19,19,19,19,19,19,203,203,19,203,203,124,19,88,203,203,203,203,203,124,19,19,19,19,0,0,0,0,0,0
0,0,0,0,0,106,0,0,0,0,0,106,0,0,19,19,19,19,19,203,203,203,203,203,124,19,88,203,203,203,203,203,124,19,19,19,19,0,0,0,0,0,0
0,0,0,0,0,0,0,0,0,0,0,0,0,0,19,19,19,19,19,203,203,203,203,203,124,19,88,203,203,203,203,203,124,19,19,19,19,0,0,0,0,0,0
0,0,0,0,0,0,0,0,0,0,0,0,0,0,19,19,19,19,19,142,142,142,142,142,142,19,88,142,142,142,142,142,124,19,19,19,19,0,0,0,0,0,0
0,0,0,0,0,0,0,0,0,0,0,0,0,0,19,19,19,19,19,19,19,19,19,19,19,19,19,19,19,19,19,19,19,19,19,19,19,0,0,0,0,0,0
0,0,0,0,0,0,0,0,0,0,0,0,0,0,19,19,19,19,19,89,89,89,89,89,89,19,88,89,89,89,89,89,124,19,19,19,19,0,0,0,0,0,0
0,0,0,0,0,0,0,0,0,0,0,0,0,0,19,19,19,19,19,203,203,203,203,203,124,19,88,203,203,203,203,203,124,19,19,19,19,0,0,0,0,0,0
0,0,0,0,0,0,0,0,0,0,0,0,0,0,19,19,19,19,19,203,203,203,203,203,124,19,88,203,203,203,203,203,124,19,19,19,19,0,0,0,0,0,0
0,0,0,0,0,0,0,0,0,0,0,0,0,0,19,19,19,19,19,203,203,19,203,203,124,19,88,203,203,19,203,203,124,19,19,19,19,0,0,0,0,0,0
0,0,0,0,0,0,0,0,0,0,0,0,0,0,19,19,19,19,19,203,203,203,203,203,124,19,88,203,203,203,203,203,124,19,19,19,19,0,0,0,0,0,0
0,0,0,0,0,106,106,0,0,0,106,106,0,0,19,19,19,19,19,203,203,203,203,203,124,19,88,203,203,203,203,203,124,19,19,19,19,0,0,0,0,0,0
0,0,0,0,0,19,88,0,0,0,124,19,19,19,19,19,19,19,19,142,142,142,142,142,124,19,142,142,142,142,142,142,124,19,19,19,19,19,19,0,0,0,0
0,0,0,0,0,19,0,0,0,0,0,19,19,19,19,19,19,19,19,19,19,19,19,19,19,19,19,19,19,19,19,19,19,19,19,19,19,19,19,0,0,0,0
0,0,0,0,0,19,0,0,0,0,0,19,19,19,19,19,19,19,19,19,19,19,19,19,19,19,19,19,19,19,19,19,19,19,142,88,0,19,19,0,0,0,0
0,0,0,0,0,19,19,0,19,0,19,19,19,19,19,19,19,19,19,19,19,19,19,19,19,19,19,19,19,19,19,19,19,19,41,19,27,19,19,0,0,0,0
0,0,0,0,0,19,0,224,0,225,0,87,19,19,19,19,19,19,19,19,19,19,19,19,19,19,19,19,19,19,19,19,19,19,0,0,0,19,19,0,0,0,0
0,0,0,0,0,19,0,0,0,0,0,19,19,19,19,19,19,19,19,19,19,19,19,19,19,0,0,0,0,0,0,0,19,19,19,19,19,19,19,0,0,0,0
0,0,0,0,0,19,19,19,19,19,19,19,19,19,19,19,19,19,19,19,19,19,19,19,19,0,0,0,0,0,0,0,19,19,19,19,19,19,19,0,0,0,0
0,0,0,0,0,0,0,0,0,0,0,0,0,19,19,19,19,19,19,19,19,19,19,19,0,0,0,0,0,0,0,0,0,0,0,0,0,0,0,0,0,0,0
0,0,0,0,0,0,0,0,0,0,0,0,0,19,19,19,19,19,19,19,19,19,19,19,0,0,0,0,0,0,0,0,0,0,0,0,0,0,0,0,0,0,0
0,0,0,0,0,0,0,0,0,0,0,0,0,0,19,19,19,19,19,19,19,19,19,0,0,0,0,0,0,0,0,0,0,0,0,0,0,0,0,0,0,0,0
0,0,0,0,0,0,0,0,0,0,0,0,0,0,0,0,19,19,19,19,19,0,0,0,0,0,0,0,0,0,0,0,0,0,0,0,0,0,0,0,0,0,0
0,0,0,0,0,0,0,0,0,0,0,0,0,0,0,0,0,0,0,0,0,0,0,0,0,0,0,0,0,0,0,0,0,0,0,0,0,0,0,0,0,0,0
0,0,0,0,0,0,0,0,0,0,0,0,0,0,0,0,0,0,0,0,0,0,0,0,0,0,0,0,0,0,0,0,0,0,0,0,0,0,0,0,0,0,0
0,0,0,0,0,0,0,0,0,0,0,0,0,0,0,0,0,0,0,0,0,0,0,0,0,0,0,0,0,0,0,0,0,0,0,0,0,0,0,0,0,0,0
0,0,0,0,0,0,0,0,0,0,0,0,0,0,0,0,0,0,0,0,0,0,0,0,0,0,0,0,0,0,0,0,0,0,0,0,0,0,0,0,0,0,0
:endlayer
layer: 12
0,0,0,0,0,0,0,0,0,0,0,0,0,0,0,0,0,0,0,0,0,0,0,0,0,0,0,0,0,0,0,0,0,0,0,0,0,0,0,0,0,0,0
0,0,0,0,0,0,0,0,0,0,0,0,0,0,0,0,0,0,0,0,0,0,0,0,0,0,0,0,0,0,0,0,0,0,0,0,0,0,0,0,0,0,0
0,0,0,0,0,0,0,0,0,0,0,0,0,0,0,0,0,0,0,0,0,0,0,0,0,0,0,0,0,0,0,0,0,0,0,0,0,0,0,0,0,0,0
0,0,0,0,0,0,0,0,0,0,0,0,0,0,0,0,0,0,0,0,0,0,0,0,0,0,0,0,0,0,0,0,0,0,0,0,0,0,0,0,0,0,0
0,0,0,0,0,0,0,0,0,0,0,0,19,19,19,15,19,19,19,0,0,0,0,0,0,0,0,0,0,0,0,0,19,19,19,15,19,19,19,0,0,0,0
0,0,0,0,19,19,19,19,19,19,19,19,19,0,0,0,0,0,19,0,0,0,0,0,0,0,0,0,0,0,0,0,19,0,0,0,0,0,19,0,0,0,0
0,0,0,0,19,0,0,0,0,0,0,0,19,0,0,0,0,0,19,19,19,15,19,19,19,15,19,19,19,15,19,19,19,0,0,0,0,0,19,0,0,0,0
0,0,0,0,19,0,0,0,0,0,0,0,19,0,142,19,0,0,55,0,0,0,0,0,0,0,0,0,0,0,0,0,55,0,0,19,0,0,35,0,0,0,0
0,0,0,0,19,0,0,0,0,0,0,0,19,0,124,35,0,0,19,0,0,0,0,0,0,0,0,0,0,0,0,0,19,0,0,0,0,0,19,0,0,0,0
0,0,0,0,19,0,0,0,0,0,0,0,19,0,0,0,0,0,19,19,19,19,19,19,19,69,19,19,19,19,19,19,19,0,0,0,0,0,19,0,0,0,0
0,0,0,0,19,0,0,0,0,0,0,0,19,19,19,19,19,19,19,226,19,83,83,19,227,0,228,229,229,229,229,229,19,19,19,19,19,19,19,0,0,0,0
0,0,0,0,19,0,0,0,0,0,0,0,19,230,0,0,0,0,0,0,41,231,231,41,0,0,0,0,0,0,0,0,0,0,0,229,19,0,0,0,0,0,0
0,0,0,0,19,0,0,0,0,0,0,0,19,232,0,0,0,0,0,0,0,233,0,0,0,0,0,0,0,0,0,0,0,0,0,0,19,0,0,0,0,0,0
0,0,0,0,19,19,234,235,236,237,238,19,19,19,19,0,0,0,0,239,239,239,239,239,239,0,240,0,0,241,57,57,242,0,243,0,35,0,0,0,0,0,0
0,0,0,0,28,106,0,0,0,0,0,106,28,0,19,241,0,0,244,239,241,239,239,239,242,0,0,0,0,0,57,57,0,0,0,0,19,0,0,0,0,0,0
0,0,0,0,0,0,0,0,0,0,0,0,0,0,19,241,0,0,0,239,241,239,239,239,242,0,0,0,0,241,57,57,242,0,0,245,19,0,0,0,0,0,0
0,0,0,0,0,0,0,0,0,0,0,0,0,0,19,0,0,0,0,239,239,239,239,239,239,0,0,0,0,0,57,57,0,0,0,0,19,0,0,0,0,0,0
0,0,0,0,0,0,0,0,0,0,0,0,0,0,87,0,0,0,0,239,239,246,246,239,239,0,0,247,0,241,57,57,242,0,0,0,35,0,0,0,0,0,0
0,0,0,0,0,0,0,0,0,0,0,0,0,0,19,0,0,0,0,239,239,239,239,239,239,0,240,0,0,0,57,57,0,0,0,0,19,0,0,0,0,0,0
0,0,0,0,0,0,0,0,0,0,0,0,0,0,19,0,0,248,0,0,0,0,0,0,0,0,0,0,0,241,57,57,242,0,0,249,19,0,0,0,0,0,0
0,0,0,0,0,0,0,0,0,0,0,0,0,0,87,0,0,0,0,0,0,0,0,0,0,0,0,0,0,0,57,57,0,0,0,0,19,0,0,0,0,0,0
0,0,0,0,0,0,0,0,0,0,0,0,0,0,19,0,0,0,0,0,0,0,0,0,0,0,0,0,0,0,0,0,0,0,0,0,35,0,0,0,0,0,0
0,0,0,0,0,0,0,0,0,0,0,0,0,0,19,0,19,19,69,19,19,229,0,0,0,0,0,0,0,0,0,0,0,0,0,0,19,0,0,0,0,0,0
0,0,0,0,0,31,106,106,106,106,106,31,0,0,19,19,250,0,0,0,0,19,19,0,0,0,240,0,251,0,0,240,0,229,229,229,19,0,0,0,0,0,0
0,0,0,0,0,19,19,19,19,19,19,19,19,19,241,0,0,0,0,0,0,0,0,19,0,0,0,0,0,0,0,0,19,19,19,19,19,19,19,0,0,0,0
0,0,0,0,0,19,0,0,0,0,0,19,19,19,241,0,0,0,0,0,0,0,242,19,241,0,0,0,0,0,0,0,19,0,0,0,0,0,19,0,0,0,0
0,0,0,0,0,19,0,0,0,0,0,19,19,0,0,0,0,0,0,0,0,0,0,252,19,0,0,0,0,0,0,0,19,0,0,87,88,0,19,0,0,0,0
0,0,0,0,0,19,0,0,0,0,0,19,19,0,0,0,0,0,0,0,253,254,255,253,19,229,246,0,0,0,0,0,55,0,0,19,89,0,35,0,0,0,0
0,0,0,0,0,19,0,0,0,0,0,0,12,0,0,0,256,0,0,0,253,254,255,253,19,19,41,19,19,19,41,19,19,0,0,0,0,0,19,0,0,0,0
0,0,0,0,0,19,0,0,0,0,0,19,19,0,0,0,0,0,0,0,253,254,255,253,19,0,0,0,0,0,0,0,19,0,0,0,0,0,19,0,0,0,0
0,0,0,0,0,19,19,19,19,19,19,19,19,0,0,0,0,0,257,258,0,0,0,259,19,0,0,0,0,0,0,0,19,19,19,41,19,19,19,0,0,0,0
0,0,0,0,0,0,0,0,0,0,0,0,0,19,241,0,0,0,57,0,0,0,0,19,0,0,0,0,0,0,0,0,0,0,0,0,0,0,0,0,0,0,0
0,0,0,0,0,0,0,0,0,0,0,0,0,19,241,0,0,0,246,0,0,0,246,19,0,0,0,0,0,0,0,0,0,0,0,0,0,0,0,0,0,0,0
0,0,0,0,0,0,0,0,0,0,0,0,0,0,19,19,260,0,0,0,0,19,19,0,0,0,0,0,0,0,0,0,0,0,0,0,0,0,0,0,0,0,0
0,0,0,0,0,0,0,0,0,0,0,0,0,0,0,0,19,19,41,19,19,0,0,0,0,0,0,0,0,0,0,0,0,0,0,0,0,0,0,0,0,0,0
0,0,0,0,0,0,0,0,0,0,0,0,0,0,0,0,0,0,0,0,0,0,0,0,0,0,0,0,0,0,0,0,0,0,0,0,0,0,0,0,0,0,0
0,0,0,0,0,0,0,0,0,0,0,0,0,0,0,0,0,0,0,0,0,0,0,0,0,0,0,0,0,0,0,0,0,0,0,0,0,0,0,0,0,0,0
0,0,0,0,0,0,0,0,0,0,0,0,0,0,0,0,0,0,0,0,0,0,0,0,0,0,0,0,0,0,0,0,0,0,0,0,0,0,0,0,0,0,0
0,0,0,0,0,0,0,0,0,0,0,0,0,0,0,0,0,0,0,0,0,0,0,0,0,0,0,0,0,0,0,0,0,0,0,0,0,0,0,0,0,0,0
:endlayer
layer: 13
0,0,0,0,0,0,0,0,0,0,0,0,0,0,0,0,0,0,0,0,0,0,0,0,0,0,0,0,0,0,0,0,0,0,0,0,0,0,0,0,0,0,0
0,0,0,0,0,0,0,0,0,0,0,0,0,0,0,0,0,0,0,0,0,0,0,0,0,0,0,0,0,0,0,0,0,0,0,0,0,0,0,0,0,0,0
0,0,0,0,0,0,0,0,0,0,0,0,0,0,0,0,0,0,0,0,0,0,0,0,0,0,0,0,0,0,0,0,0,0,0,0,0,0,0,0,0,0,0
0,0,0,0,0,0,0,0,0,0,0,0,0,0,0,0,0,0,0,0,0,0,0,0,0,0,0,0,0,0,0,0,0,0,0,0,0,0,0,0,0,0,0
0,0,0,0,0,0,0,0,0,0,0,0,19,19,19,10,19,19,19,0,0,0,0,0,0,0,0,0,0,0,0,0,19,19,19,10,19,19,19,0,0,0,0
0,0,0,0,19,19,19,19,19,19,19,19,19,0,0,0,0,0,19,0,0,0,0,0,0,0,0,0,0,0,0,0,19,0,0,0,0,0,19,0,0,0,0
0,0,0,0,19,0,0,0,0,0,0,0,19,0,142,88,0,0,19,19,19,10,19,19,19,10,19,19,19,10,19,19,19,0,0,0,0,0,19,0,0,0,0
0,0,0,0,19,0,0,0,0,0,0,0,19,0,41,19,27,0,114,0,0,0,0,0,0,0,0,0,0,0,0,0,114,0,32,19,0,0,10,0,0,0,0
0,0,0,0,19,0,0,0,0,0,0,0,19,0,0,0,0,0,19,0,0,0,0,0,31,0,31,0,0,0,0,0,19,0,0,0,0,0,19,0,0,0,0
0,0,0,0,19,0,0,0,0,0,0,0,19,0,0,0,0,0,19,19,19,19,19,19,19,114,19,19,19,19,19,19,19,0,0,0,0,0,19,0,0,0,0
0,0,0,0,19,0,0,0,0,0,0,0,19,19,19,19,19,19,19,0,19,0,0,19,0,0,0,229,229,229,229,229,19,19,19,19,19,19,19,0,0,0,0
0,0,0,0,19,0,0,0,0,0,0,0,19,0,0,0,0,0,0,0,0,0,0,0,0,0,0,0,0,0,0,0,0,0,0,229,19,0,0,0,0,0,0
0,0,0,0,19,0,0,0,0,0,0,0,19,0,0,0,0,0,0,0,0,0,0,0,0,0,31,0,0,0,0,0,0,0,0,0,19,0,0,0,0,0,0
0,0,0,0,19,19,261,262,263,264,265,19,19,19,19,0,0,0,0,0,0,0,0,0,0,32,240,27,0,0,266,266,0,0,0,0,10,0,0,0,0,0,0
0,0,0,0,0,106,0,0,0,0,0,106,0,0,19,0,0,0,0,0,0,0,0,0,0,0,28,0,0,0,266,266,0,0,0,0,19,0,0,0,0,0,0
0,0,0,0,0,0,0,0,0,0,0,0,0,0,19,0,0,0,0,0,0,0,0,0,0,0,0,0,0,0,266,266,0,0,0,0,19,0,0,0,0,0,0
0,0,0,0,0,0,0,0,0,0,0,0,0,0,19,0,0,0,0,0,0,0,0,0,0,0,0,0,0,0,266,266,0,0,0,0,19,0,0,0,0,0,0
0,0,0,0,0,0,0,0,0,0,0,0,0,0,10,0,0,0,0,0,0,0,0,0,0,0,31,0,0,0,266,266,0,0,0,0,10,0,0,0,0,0,0
0,0,0,0,0,0,0,0,0,0,0,0,0,0,19,0,0,0,0,0,0,0,0,0,0,32,240,27,0,0,266,266,0,0,0,0,19,0,0,0,0,0,0
0,0,0,0,0,0,0,0,0,0,0,0,0,0,19,0,0,0,0,0,0,0,0,0,0,0,28,0,0,0,266,266,0,0,0,0,19,0,0,0,0,0,0
0,0,0,0,0,0,0,0,0,0,0,0,0,0,10,0,0,0,0,0,0,0,0,0,0,0,0,0,0,0,266,266,0,0,0,0,19,0,0,0,0,0,0
0,0,0,0,0,0,0,0,0,0,0,0,0,0,19,0,0,31,0,31,0,0,0,0,0,0,0,0,0,0,0,0,0,0,0,0,10,0,0,0,0,0,0
0,0,0,0,0,0,0,0,0,0,0,0,0,0,19,0,19,19,114,19,19,229,0,0,0,0,31,0,0,0,0,31,0,0,0,0,19,0,0,0,0,0,0
0,0,0,0,0,142,0,142,0,142,0,142,0,142,19,19,27,0,0,0,32,19,19,0,0,32,240,27,0,0,32,240,0,229,229,229,19,0,0,0,0,0,0
0,0,0,0,124,19,19,19,19,19,19,19,19,19,0,0,0,0,0,0,0,0,0,19,0,0,28,0,0,0,0,28,19,19,19,19,19,19,19,0,0,0,0
0,0,0,0,0,19,0,0,0,0,0,19,19,19,0,0,0,0,0,0,0,0,0,19,0,0,0,0,0,0,0,0,19,0,0,0,0,0,19,0,0,0,0
0,0,0,0,124,19,0,0,0,0,0,19,19,28,0,0,0,0,0,0,0,0,0,28,19,0,0,0,0,0,0,0,19,0,0,0,0,0,19,0,0,0,0
0,0,0,0,0,19,0,0,0,0,0,19,19,0,0,0,0,0,0,0,57,0,0,57,19,229,0,0,0,0,0,0,114,0,32,19,15,0,10,0,0,0,0
0,0,0,0,124,19,0,0,0,0,0,0,30,0,0,0,0,0,0,0,0,0,0,0,19,19,10,19,19,19,10,19,19,0,0,124,89,0,19,0,0,0,0
0,0,0,0,0,19,27,0,0,0,32,19,19,0,0,0,0,0,0,0,57,0,0,57,19,0,0,0,0,0,0,0,19,0,0,0,0,0,19,0,0,0,0
0,0,0,0,124,19,19,19,19,19,19,19,19,31,0,0,0,0,0,0,0,0,0,31,19,0,0,0,0,0,0,0,19,19,19,10,19,19,19,0,0,0,0
0,0,0,0,89,89,0,89,0,89,0,89,0,19,0,0,0,0,267,0,0,0,0,19,0,0,0,0,0,0,0,0,0,0,0,0,0,0,0,0,0,0,0
0,0,0,0,0,0,0,0,0,0,0,0,0,19,0,0,0,0,0,0,0,0,0,19,0,0,0,0,0,0,0,0,0,0,0,0,0,0,0,0,0,0,0
0,0,0,0,0,0,0,0,0,0,0,0,0,0,19,19,27,0,0,0,32,19,19,0,0,0,0,0,0,0,0,0,0,0,0,0,0,0,0,0,0,0,0
0,0,0,0,0,0,0,0,0,0,0,0,0,0,0,0,19,19,10,19,19,0,0,0,0,0,0,0,0,0,0,0,0,0,0,0,0,0,0,0,0,0,0
0,0,0,0,0,0,0,0,0,0,0,0,0,0,0,0,0,0,0,0,0,0,0,0,0,0,0,0,0,0,0,0,0,0,0,0,0,0,0,0,0,0,0
0,0,0,0,0,0,0,0,0,0,0,0,0,0,0,0,0,0,0,0,0,0,0,0,0,0,0,0,0,0,0,0,0,0,0,0,0,0,0,0,0,0,0
0,0,0,0,0,0,0,0,0,0,0,0,0,0,0,0,0,0,0,0,0,0,0,0,0,0,0,0,0,0,0,0,0,0,0,0,0,0,0,0,0,0,0
0,0,0,0,0,0,0,0,0,0,0,0,0,0,0,0,0,0,0,0,0,0,0,0,0,0,0,0,0,0,0,0,0,0,0,0,0,0,0,0,0,0,0
:endlayer
layer: 14
0,0,0,0,0,0,0,0,0,0,0,0,0,0,0,0,0,0,0,0,0,0,0,0,0,0,0,0,0,0,0,0,0,0,0,0,0,0,0,0,0,0,0
0,0,0,0,0,0,0,0,0,0,0,0,0,0,0,0,0,0,0,0,0,0,0,0,0,0,0,0,0,0,0,0,0,0,0,0,0,0,0,0,0,0,0
0,0,0,0,0,0,0,0,0,0,0,0,0,0,0,0,0,0,0,0,0,0,0,0,0,0,0,0,0,0,0,0,0,0,0,0,0,0,0,0,0,0,0
0,0,0,0,0,0,0,0,0,0,0,0,0,0,0,0,0,0,0,0,0,0,0,0,0,0,0,0,0,0,0,0,0,0,0,0,0,0,0,0,0,0,0
0,0,0,0,0,0,0,0,0,0,0,0,19,19,19,10,19,19,19,0,0,0,0,0,0,0,0,0,0,0,0,0,19,19,19,10,19,19,19,0,0,0,0
0,0,0,0,19,19,19,19,19,19,19,19,19,0,0,0,0,0,19,0,0,0,0,0,0,0,0,0,0,0,0,0,19,0,0,0,0,0,19,0,0,0,0
0,0,0,0,19,0,0,0,0,0,0,0,19,0,0,87,88,0,19,19,19,10,19,19,19,10,19,19,19,10,19,19,19,0,0,0,0,0,19,0,0,0,0
0,0,0,0,19,0,0,0,0,0,0,0,19,0,0,19,89,0,19,0,0,0,0,0,0,0,0,0,0,0,0,0,19,0,0,19,0,0,10,0,0,0,0
0,0,0,0,19,0,0,0,0,0,0,0,19,0,0,0,0,0,19,0,0,0,0,0,0,0,0,0,0,0,0,0,19,0,0,0,0,0,19,0,0,0,0
0,0,0,0,19,0,0,0,0,0,0,0,19,0,0,0,0,0,19,19,19,19,19,19,19,19,19,19,19,19,19,19,19,0,0,0,0,0,19,0,0,0,0
0,0,0,0,19,0,0,0,0,0,0,0,19,19,19,19,19,19,19,27,19,0,0,19,28,0,28,229,229,229,229,229,19,19,19,19,19,19,19,0,0,0,0
0,0,0,0,19,0,0,0,0,0,0,0,19,0,0,0,0,0,28,0,89,268,268,89,0,0,0,0,0,0,0,0,28,0,0,229,19,0,0,0,0,0,0
0,0,0,0,19,31,0,0,0,0,0,31,19,0,31,0,0,0,0,0,0,0,0,0,0,0,0,0,0,0,0,0,0,0,0,0,19,0,0,0,0,0,0
0,0,0,0,19,19,269,270,271,272,273,19,19,19,19,27,0,0,0,0,0,0,0,0,0,0,240,0,0,0,0,0,0,0,0,0,10,0,0,0,0,0,0
0,0,0,0,0,8,0,0,0,0,0,5,0,0,19,0,0,0,0,0,0,0,0,0,0,0,0,0,0,0,0,0,0,0,0,0,19,0,0,0,0,0,0
0,0,0,0,0,106,0,0,0,0,0,106,0,0,19,0,0,0,0,0,0,0,0,0,0,0,0,0,0,0,0,0,0,0,0,32,19,0,0,0,0,0,0
0,0,0,0,0,0,0,0,0,0,0,0,0,0,19,0,0,0,0,0,0,0,0,0,0,0,0,0,0,0,0,0,0,0,0,0,19,0,0,0,0,0,0
0,0,0,0,0,0,0,0,0,0,0,0,0,0,10,0,0,0,0,0,0,0,0,0,0,0,0,0,0,0,0,0,0,0,0,0,10,0,0,0,0,0,0
0,0,0,0,0,0,0,0,0,0,0,0,0,0,19,27,0,0,0,0,0,0,0,0,0,0,240,0,0,0,0,0,0,0,0,0,19,0,0,0,0,0,0
0,0,0,0,0,0,0,0,0,0,0,0,0,0,19,0,0,0,0,0,0,0,0,0,0,0,0,0,0,0,0,0,0,0,0,32,19,0,0,0,0,0,0
0,0,0,0,0,0,0,0,0,0,0,0,0,0,10,0,0,0,0,0,0,0,0,0,0,0,0,0,0,0,0,0,0,0,0,0,19,0,0,0,0,0,0
0,0,0,0,0,0,0,0,0,0,0,0,0,0,19,0,0,0,0,0,0,0,0,0,0,0,0,0,0,0,0,0,0,0,0,0,10,0,0,0,0,0,0
0,0,0,0,0,0,0,0,0,0,0,0,0,0,19,0,19,19,19,19,19,229,31,0,0,0,0,0,0,0,0,0,0,0,0,32,19,0,0,0,0,0,0
0,0,0,0,19,15,19,15,19,15,19,15,19,15,19,19,0,0,0,0,0,19,19,27,0,0,240,0,0,0,0,240,31,229,229,229,19,0,0,0,0,0,0
0,0,0,0,87,136,136,136,136,136,136,136,136,19,0,0,0,0,0,0,0,0,0,19,0,0,0,0,0,0,0,0,19,19,19,19,19,19,19,0,0,0,0
0,0,0,0,19,136,136,136,136,136,136,136,136,19,0,0,0,0,0,0,0,0,0,19,31,0,0,0,0,0,0,0,19,0,0,0,0,0,19,0,0,0,0
0,0,0,0,87,136,136,136,136,136,136,136,19,0,0,0,0,0,0,0,0,0,0,0,19,27,0,0,0,0,0,0,19,0,0,0,0,0,19,0,0,0,0
0,0,0,0,19,136,136,136,136,136,136,136,19,0,0,0,0,0,0,0,253,0,0,253,19,229,0,0,0,0,0,31,19,0,142,19,0,0,10,0,0,0,0
0,0,0,0,87,136,136,136,136,136,136,136,19,33,0,0,0,0,0,0,0,0,0,0,19,19,10,19,19,19,10,19,19,0,124,35,0,0,19,0,0,0,0
0,0,0,0,19,136,136,136,136,136,136,136,19,0,0,0,0,0,0,0,253,0,0,253,19,0,0,0,0,0,0,0,19,0,0,0,0,0,19,0,0,0,0
0,0,0,0,87,136,136,136,136,136,136,136,19,0,0,0,0,0,0,0,0,0,0,0,19,0,0,0,0,0,0,0,19,19,19,10,19,19,19,0,0,0,0
0,0,0,0,19,41,19,41,19,41,19,41,19,19,0,0,0,0,0,0,0,0,0,19,0,0,0,0,0,0,0,0,0,0,0,0,0,0,0,0,0,0,0
0,0,0,0,0,0,0,0,0,0,0,0,0,19,0,0,0,0,0,0,0,0,0,19,0,0,0,0,0,0,0,0,0,0,0,0,0,0,0,0,0,0,0
0,0,0,0,0,0,0,0,0,0,0,0,0,0,19,19,0,0,0,0,0,19,19,0,0,0,0,0,0,0,0,0,0,0,0,0,0,0,0,0,0,0,0
0,0,0,0,0,0,0,0,0,0,0,0,0,0,0,0,19,19,10,19,19,0,0,0,0,0,0,0,0,0,0,0,0,0,0,0,0,0,0,0,0,0,0
0,0,0,0,0,0,0,0,0,0,0,0,0,0,0,0,0,0,0,0,0,0,0,0,0,0,0,0,0,0,0,0,0,0,0,0,0,0,0,0,0,0,0
0,0,0,0,0,0,0,0,0,0,0,0,0,0,0,0,0,0,0,0,0,0,0,0,0,0,0,0,0,0,0,0,0,0,0,0,0,0,0,0,0,0,0
0,0,0,0,0,0,0,0,0,0,0,0,0,0,0,0,0,0,0,0,0,0,0,0,0,0,0,0,0,0,0,0,0,0,0,0,0,0,0,0,0,0,0
0,0,0,0,0,0,0,0,0,0,0,0,0,0,0,0,0,0,0,0,0,0,0,0,0,0,0,0,0,0,0,0,0,0,0,0,0,0,0,0,0,0,0
:endlayer
layer: 15
0,0,0,0,0,0,0,0,0,0,0,0,0,0,0,0,0,0,0,0,0,0,0,0,0,0,0,0,0,0,0,0,0,0,0,0,0,0,0,0,0,0,0
0,0,0,0,0,0,0,0,0,0,0,0,0,0,0,0,0,0,0,0,0,0,0,0,0,0,0,0,0,0,0,0,0,0,0,0,0,0,0,0,0,0,0
0,0,0,0,0,0,0,0,0,0,0,0,0,0,0,0,0,0,0,0,0,0,0,0,0,0,0,0,0,0,0,0,0,0,0,0,0,0,0,0,0,0,0
0,0,0,0,0,0,0,0,0,0,0,0,0,0,0,0,0,0,0,0,0,0,0,0,0,0,0,0,0,0,0,0,0,0,0,0,0,0,0,0,0,0,0
0,0,0,0,142,0,142,0,142,0,142,0,19,19,19,19,19,19,19,0,0,0,0,0,0,0,0,0,0,0,0,0,19,19,19,19,19,19,19,0,0,0,0
0,0,0,124,19,19,19,19,19,19,19,19,19,19,19,19,19,19,19,0,0,0,0,0,0,0,0,0,0,0,0,0,19,19,19,19,19,19,19,0,0,0,0
0,0,0,0,19,274,274,274,274,274,274,274,19,19,0,0,0,19,19,19,19,19,19,19,19,19,19,19,19,19,19,19,19,19,19,19,19,19,19,0,0,0,0
0,0,0,124,19,274,274,274,274,274,274,274,19,19,32,19,15,19,19,19,19,19,19,19,19,19,19,19,19,19,19,19,19,19,19,19,19,19,19,0,0,0,0
0,0,0,0,19,274,274,274,274,274,274,274,19,19,0,0,89,19,19,19,19,19,19,19,19,19,19,19,19,19,19,19,19,19,19,19,19,19,19,0,0,0,0
0,0,0,124,19,274,274,274,274,274,274,274,19,19,19,19,19,19,19,19,19,19,19,19,19,19,19,19,19,19,19,19,19,19,19,19,19,19,19,0,0,0,0
0,0,0,0,19,274,274,274,274,274,274,274,19,19,19,19,19,19,19,19,19,19,19,19,19,19,19,19,19,19,19,19,19,19,19,19,19,19,19,0,0,0,0
0,0,0,124,19,274,274,274,274,274,274,274,19,19,19,19,19,19,19,19,19,19,19,19,19,19,19,19,19,19,19,19,19,19,19,19,19,0,0,0,0,0,0
0,0,0,0,19,274,274,274,274,274,274,274,19,19,19,19,19,19,19,19,19,19,19,19,19,19,19,19,19,19,19,19,19,19,19,19,19,0,0,0,0,0,0
0,0,0,124,19,19,19,19,19,19,19,19,19,19,19,19,19,19,19,19,19,19,19,19,19,19,19,19,19,19,19,19,19,19,19,19,19,0,0,0,0,0,0
0,0,0,0,89,0,89,0,89,0,89,0,89,0,19,19,19,19,19,19,19,19,19,19,19,19,19,19,19,19,19,19,19,19,19,19,19,0,0,0,0,0,0
0,0,0,0,0,106,106,106,106,106,106,106,0,0,19,19,19,19,19,19,19,19,19,19,19,19,19,19,19,19,19,19,19,19,19,19,19,0,0,0,0,0,0
0,0,0,0,0,0,0,0,0,0,0,0,0,0,19,19,19,19,19,19,19,19,19,19,19,19,19,19,19,19,19,19,19,19,19,19,19,0,0,0,0,0,0
0,0,0,0,0,0,0,0,0,0,0,0,0,0,19,19,19,19,19,19,19,19,19,19,19,19,19,19,19,19,19,19,19,19,19,19,19,0,0,0,0,0,0
0,0,0,0,0,0,0,0,0,0,0,0,0,0,19,19,19,19,19,19,19,19,19,19,19,19,19,19,19,19,19,19,19,19,19,19,19,0,0,0,0,0,0
0,0,0,0,0,0,0,0,0,0,0,0,0,0,19,19,19,19,19,19,19,19,19,19,19,19,19,19,19,19,19,19,19,19,19,19,19,0,0,0,0,0,0
0,0,0,0,0,0,0,0,0,0,0,0,0,0,19,19,19,19,19,19,19,19,19,19,19,19,19,19,19,19,19,19,19,19,19,19,19,0,0,0,0,0,0
0,0,0,0,0,0,0,0,0,0,0,0,0,0,19,19,19,19,19,19,19,19,19,19,19,19,19,19,19,19,19,19,19,19,19,19,19,0,0,0,0,0,0
0,0,0,0,0,0,0,0,0,0,0,0,0,0,19,19,19,19,19,19,19,19,19,19,19,19,19,19,19,19,19,19,19,19,19,19,19,0,0,0,0,0,0
0,0,0,0,19,240,19,240,19,240,19,240,19,240,19,19,19,19,19,19,19,19,19,19,19,19,19,19,19,19,19,19,19,19,19,19,19,0,0,0,0,0,0
0,0,0,0,240,19,19,19,19,19,19,19,19,19,19,19,19,19,19,19,19,19,19,19,19,19,19,19,19,19,19,19,19,19,19,19,19,19,19,0,0,0,0
0,0,0,0,19,19,19,19,19,19,19,19,19,19,19,19,19,19,19,19,19,19,19,19,19,19,19,19,19,19,19,19,19,19,19,19,19,19,19,0,0,0,0
0,0,0,0,240,19,19,19,19,19,19,19,19,19,19,19,19,19,19,19,19,19,19,19,19,19,19,19,19,19,19,19,19,19,142,88,0,19,19,0,0,0,0
0,0,0,0,19,19,19,19,19,19,19,19,19,19,19,19,19,19,19,19,19,19,19,19,19,19,19,19,19,19,19,19,19,19,41,19,27,19,19,0,0,0,0
0,0,0,0,240,19,19,19,19,19,19,19,19,19,19,19,19,19,19,19,19,19,19,19,19,19,19,19,19,19,19,19,19,19,0,0,0,19,19,0,0,0,0
0,0,0,0,19,19,19,19,19,19,19,19,19,19,19,19,19,19,19,19,19,19,19,19,19,0,0,0,0,0,0,0,19,19,19,19,19,19,19,0,0,0,0
0,0,0,0,240,19,19,19,19,19,19,19,19,19,19,19,19,19,19,19,19,19,19,19,19,0,0,0,0,0,0,0,19,19,19,19,19,19,19,0,0,0,0
0,0,0,0,19,240,19,240,19,240,19,240,19,19,19,19,19,19,19,19,19,19,19,19,0,0,0,0,0,0,0,0,0,0,0,0,0,0,0,0,0,0,0
0,0,0,0,0,0,0,0,0,0,0,0,0,19,19,19,19,19,19,19,19,19,19,19,0,0,0,0,0,0,0,0,0,0,0,0,0,0,0,0,0,0,0
0,0,0,0,0,0,0,0,0,0,0,0,0,0,19,19,19,19,19,19,19,19,19,0,0,0,0,0,0,0,0,0,0,0,0,0,0,0,0,0,0,0,0
0,0,0,0,0,0,0,0,0,0,0,0,0,0,0,0,19,19,19,19,19,0,0,0,0,0,0,0,0,0,0,0,0,0,0,0,0,0,0,0,0,0,0
0,0,0,0,0,0,0,0,0,0,0,0,0,0,0,0,0,0,0,0,0,0,0,0,0,0,0,0,0,0,0,0,0,0,0,0,0,0,0,0,0,0,0
0,0,0,0,0,0,0,0,0,0,0,0,0,0,0,0,0,0,0,0,0,0,0,0,0,0,0,0,0,0,0,0,0,0,0,0,0,0,0,0,0,0,0
0,0,0,0,0,0,0,0,0,0,0,0,0,0,0,0,0,0,0,0,0,0,0,0,0,0,0,0,0,0,0,0,0,0,0,0,0,0,0,0,0,0,0
0,0,0,0,0,0,0,0,0,0,0,0,0,0,0,0,0,0,0,0,0,0,0,0,0,0,0,0,0,0,0,0,0,0,0,0,0,0,0,0,0,0,0
:endlayer
layer: 16
0,0,0,0,0,0,0,0,0,0,0,0,0,0,0,0,0,0,0,0,0,0,0,0,0,0,0,0,0,0,0,0,0,0,0,0,0,0,0,0,0,0,0
0,0,0,0,0,0,0,0,0,0,0,0,0,0,0,0,0,0,0,0,0,0,0,0,0,0,0,0,0,0,0,0,0,0,0,0,0,0,0,0,0,0,0
0,0,0,0,0,0,0,0,0,0,0,0,0,0,0,0,0,0,0,0,0,0,0,0,0,0,0,0,0,0,0,0,0,0,0,0,0,0,0,0,0,0,0
0,0,0,0,0,0,0,0,0,0,0,0,0,0,0,0,0,0,0,0,0,0,0,0,0,0,0,0,0,0,0,0,0,0,0,0,0,0,0,0,0,0,0
0,0,0,19,15,19,15,19,15,19,15,19,19,19,19,15,19,19,19,0,0,0,0,0,0,0,0,0,0,0,0,0,19,19,19,15,19,19,19,0,0,0,0
0,0,0,87,136,136,136,136,136,136,136,136,19,0,0,0,0,0,19,0,0,0,0,0,0,0,0,0,0,0,0,0,19,0,0,0,0,275,19,0,0,0,0
0,0,0,19,136,136,136,136,136,136,136,136,19,0,0,0,0,0,19,19,19,15,19,19,19,15,19,19,19,15,19,19,19,0,0,276,0,0,19,0,0,0,0
0,0,0,87,136,136,136,136,19,19,19,19,35,0,142,19,0,0,55,0,0,0,0,0,0,0,0,0,0,0,0,277,19,0,0,0,184,185,35,0,0,0,0
0,0,0,19,136,136,136,136,136,136,136,136,19,0,124,35,0,0,19,0,0,0,0,0,0,0,0,0,0,0,0,0,55,0,0,0,0,0,19,0,0,0,0
0,0,0,87,136,136,136,136,136,136,136,136,19,0,0,0,0,0,19,0,0,0,0,0,0,0,0,0,0,0,0,0,19,0,0,0,0,278,19,0,0,0,0
0,0,0,19,136,136,136,136,136,136,136,136,19,19,19,69,19,19,19,19,69,19,19,19,19,19,19,279,0,280,19,19,19,19,19,19,19,19,19,0,0,0,0
0,0,0,87,136,136,136,136,136,136,136,136,136,136,19,0,19,281,0,0,0,0,0,282,0,283,19,0,0,0,19,0,0,0,0,0,19,0,0,0,0,0,0
0,0,0,19,136,136,136,136,136,136,136,136,136,136,19,0,19,0,0,0,0,0,0,0,0,284,19,0,0,0,19,0,0,0,184,185,19,0,0,0,0,0,0
0,0,0,87,136,136,136,136,136,136,136,136,136,136,19,0,19,285,0,0,0,0,0,0,0,0,19,0,0,0,19,0,0,0,286,0,35,0,0,0,0,0,0
0,0,0,19,41,19,41,19,41,19,41,19,41,19,19,0,19,0,0,287,288,0,289,0,0,0,19,0,0,0,19,0,0,0,0,290,19,0,0,0,0,0,0
0,0,0,0,0,218,0,0,0,0,0,218,0,0,19,0,19,19,19,19,19,19,19,19,19,69,19,0,0,0,19,69,19,19,19,19,19,0,0,0,0,0,0
0,0,0,0,0,0,0,0,0,0,0,0,0,0,19,0,19,0,0,0,0,0,0,0,0,0,0,0,0,0,0,0,0,0,0,0,19,0,0,0,0,0,0
0,0,0,0,0,0,0,0,0,0,0,0,0,0,87,0,19,0,0,0,0,0,0,0,0,0,0,0,0,0,0,0,0,0,0,291,35,0,0,0,0,0,0
0,0,0,0,0,0,0,0,0,0,0,0,0,0,19,0,19,0,0,0,0,0,0,0,0,0,0,0,0,0,0,0,0,0,0,0,19,0,0,0,0,0,0
0,0,0,0,0,0,0,0,0,0,0,0,0,0,19,0,19,0,0,0,19,19,19,19,19,69,19,0,0,0,19,69,19,19,19,19,19,0,0,0,0,0,0
0,0,0,0,0,0,0,0,0,0,0,0,0,0,87,0,19,292,0,293,19,0,0,0,0,0,19,0,0,0,19,0,0,0,0,0,19,0,0,0,0,0,0
0,0,0,0,0,0,0,0,0,0,0,0,0,0,19,294,19,0,0,0,19,177,178,0,0,0,19,0,0,0,19,0,0,0,0,0,35,0,0,0,0,0,0
0,0,0,0,0,0,0,0,0,0,0,0,0,0,19,19,19,19,0,19,19,295,0,0,0,0,19,0,0,0,19,0,0,296,0,189,19,0,0,0,0,0,0
0,0,0,0,19,142,19,142,19,142,19,142,19,142,19,19,229,0,0,0,229,19,19,0,0,0,19,0,0,0,19,0,0,0,0,195,19,0,0,0,0,0,0
0,0,0,0,124,40,40,19,19,40,40,40,40,19,229,229,0,0,0,0,0,229,229,19,297,298,19,0,0,0,19,299,19,19,19,19,19,19,19,0,0,0,0
0,0,0,0,19,40,0,0,0,0,0,0,0,19,229,0,0,0,0,0,0,0,300,19,19,19,19,0,0,0,19,19,19,0,0,0,0,0,19,0,0,0,0
0,0,0,0,124,40,0,0,0,0,0,0,19,229,0,0,229,229,0,0,0,301,0,229,19,0,0,0,0,0,0,0,19,0,0,87,88,0,19,0,0,0,0
0,0,0,0,19,40,0,0,0,0,302,0,19,0,0,0,229,0,0,0,0,0,0,229,19,303,0,0,0,0,0,0,69,0,0,19,89,0,35,0,0,0,0
0,0,0,0,124,40,0,0,0,0,0,0,55,0,0,304,229,0,305,306,0,0,307,229,19,19,41,19,19,19,41,19,19,0,0,0,0,0,19,0,0,0,0
0,0,0,0,19,40,0,0,0,0,0,0,19,0,0,0,229,0,0,0,0,0,0,229,19,0,0,0,0,0,0,0,19,0,0,0,0,0,19,0,0,0,0
0,0,0,0,124,40,40,19,19,40,40,40,19,229,0,0,229,229,229,229,229,0,0,229,19,0,0,0,0,0,0,0,19,19,19,41,19,19,19,0,0,0,0
0,0,0,0,19,89,19,89,19,89,19,89,19,19,0,0,0,0,0,0,0,0,0,19,0,0,0,0,0,0,0,0,0,0,0,0,0,0,0,0,0,0,0
0,0,0,0,0,0,0,0,0,0,0,0,0,87,308,0,0,0,0,0,0,0,309,35,0,0,0,0,0,0,0,0,0,0,0,0,0,0,0,0,0,0,0
0,0,0,0,0,0,0,0,0,0,0,0,0,87,41,19,229,229,229,229,229,19,41,41,0,0,0,0,0,0,0,0,0,0,0,0,0,0,0,0,0,0,0
0,0,0,0,0,0,0,0,0,0,0,0,0,0,0,0,19,19,19,19,19,0,0,0,0,0,0,0,0,0,0,0,0,0,0,0,0,0,0,0,0,0,0
0,0,0,0,0,0,0,0,0,0,0,0,0,0,0,0,0,0,0,0,0,0,0,0,0,0,0,0,0,0,0,0,0,0,0,0,0,0,0,0,0,0,0
0,0,0,0,0,0,0,0,0,0,0,0,0,0,0,0,0,0,0,0,0,0,0,0,0,0,0,0,0,0,0,0,0,0,0,0,0,0,0,0,0,0,0
0,0,0,0,0,0,0,0,0,0,0,0,0,0,0,0,0,0,0,0,0,0,0,0,0,0,0,0,0,0,0,0,0,0,0,0,0,0,0,0,0,0,0
0,0,0,0,0,0,0,0,0,0,0,0,0,0,0,0,0,0,0,0,0,0,0,0,0,0,0,0,0,0,0,0,0,0,0,0,0,0,0,0,0,0,0
:endlayer
layer: 17
0,0,0,0,0,0,0,0,0,0,0,0,0,0,0,0,0,0,0,0,0,0,0,0,0,0,0,0,0,0,0,0,0,0,0,0,0,0,0,0,0,0,0
0,0,0,0,0,0,0,0,0,0,0,0,0,0,0,0,0,0,0,0,0,0,0,0,0,0,0,0,0,0,0,0,0,0,0,0,0,0,0,0,0,0,0
0,0,0,0,0,0,0,0,0,0,0,0,0,0,0,0,0,0,0,0,0,0,0,0,0,0,0,0,0,0,0,0,0,0,0,0,0,0,0,0,0,0,0
0,0,0,0,0,0,0,0,0,0,0,0,0,0,0,0,0,0,0,0,0,0,0,0,0,0,0,0,0,0,0,0,0,0,0,0,0,0,0,0,0,0,0
0,0,0,19,240,19,240,19,240,19,240,19,19,19,19,10,19,19,19,0,0,0,0,0,0,0,0,0,0,0,0,0,19,19,19,10,19,19,19,0,0,0,0
0,0,0,240,19,19,19,19,19,19,19,19,19,0,0,0,0,0,19,0,0,0,0,0,0,0,0,0,0,0,0,0,19,28,0,0,0,28,19,0,0,0,0
0,0,0,19,19,19,19,19,19,19,19,19,19,0,142,88,0,0,19,19,19,10,19,19,19,10,19,19,19,10,19,19,19,0,0,0,0,0,19,0,0,0,0
0,0,0,240,19,19,19,19,35,0,0,0,0,0,41,19,27,0,114,0,0,0,0,28,0,0,0,28,0,0,0,0,19,0,0,0,0,0,10,0,0,0,0
0,0,0,19,19,19,19,19,19,19,19,19,19,0,0,0,0,0,19,27,0,0,0,0,0,0,0,0,0,0,0,0,114,0,0,0,0,0,19,0,0,0,0
0,0,0,240,19,19,19,19,19,19,19,19,19,0,0,0,0,0,19,0,0,31,0,0,0,0,0,0,0,0,0,32,19,31,0,0,0,31,19,0,0,0,0
0,0,0,19,19,19,19,19,19,19,19,19,19,19,19,114,19,19,19,19,114,19,19,19,19,19,19,0,0,0,19,19,19,19,19,19,19,19,19,0,0,0,0
0,0,0,240,19,19,19,19,19,19,19,19,19,19,19,0,19,0,0,0,0,28,0,0,0,32,19,0,0,0,19,28,0,0,0,32,19,0,0,0,0,0,0
0,0,0,19,19,19,19,19,19,19,19,19,19,19,19,0,19,0,0,0,0,0,0,0,0,0,19,0,0,0,19,0,0,0,0,0,19,0,0,0,0,0,0
0,0,0,240,19,19,19,19,19,19,19,19,19,19,19,0,19,0,0,0,0,0,0,0,0,0,19,0,0,0,19,0,0,0,0,0,10,0,0,0,0,0,0
0,0,0,19,240,19,240,19,240,19,240,19,240,19,19,0,19,27,0,0,0,0,0,0,31,0,19,0,0,0,19,0,31,0,0,32,19,0,0,0,0,0,0
0,0,0,0,0,0,0,0,0,0,0,0,0,0,19,0,19,19,19,19,19,19,19,19,19,114,19,0,0,0,19,114,19,19,19,19,19,0,0,0,0,0,0
0,0,0,0,0,0,0,0,0,0,0,0,0,0,19,27,19,0,28,0,0,0,0,0,0,0,28,0,0,0,28,0,0,0,0,0,19,0,0,0,0,0,0
0,0,0,0,0,0,0,0,0,0,0,0,0,0,10,0,19,0,0,0,0,0,0,0,0,0,0,0,0,0,0,0,0,0,0,0,10,0,0,0,0,0,0
0,0,0,0,0,0,0,0,0,0,0,0,0,0,19,0,19,0,0,0,0,0,0,0,0,0,31,0,0,0,31,0,0,0,0,0,19,0,0,0,0,0,0
0,0,0,0,0,0,0,0,0,0,0,0,0,0,19,0,19,0,0,0,19,19,19,19,19,114,19,0,0,0,19,114,19,19,19,19,19,0,0,0,0,0,0
0,0,0,0,0,0,0,0,0,0,0,0,0,0,10,0,19,0,0,0,19,0,0,0,28,0,19,0,0,0,19,0,28,0,0,32,19,0,0,0,0,0,0
0,0,0,0,0,0,0,0,0,0,0,0,0,0,19,27,19,31,0,31,19,0,0,0,0,0,19,0,0,0,19,0,0,0,0,0,10,0,0,0,0,0,0
0,0,0,0,0,0,0,0,0,0,0,0,0,0,19,19,19,19,0,19,19,0,31,0,0,0,19,0,0,0,19,0,0,0,0,0,19,0,0,0,0,0,0
0,0,0,0,19,0,19,310,0,19,0,19,0,19,19,19,229,28,0,28,229,19,19,0,0,0,19,0,0,0,19,0,0,0,0,32,19,0,0,0,0,0,0
0,0,0,0,0,0,0,0,0,0,0,0,0,19,229,229,0,0,0,0,0,229,229,19,27,0,19,0,0,0,19,31,19,19,19,19,19,19,19,0,0,0,0
0,0,0,0,19,0,0,0,0,0,0,0,0,19,229,0,0,0,0,0,0,0,32,19,19,19,19,0,0,0,19,19,19,0,0,0,0,0,19,0,0,0,0
0,0,0,0,0,0,0,0,0,0,0,0,19,229,0,0,229,229,0,0,0,0,0,229,19,0,0,0,0,0,0,32,19,0,0,0,0,0,19,0,0,0,0
0,0,0,0,311,0,0,0,0,0,0,0,19,27,0,0,229,28,0,0,0,0,0,229,19,0,0,0,31,0,0,0,114,0,32,19,15,0,10,0,0,0,0
0,0,0,0,0,0,0,0,0,0,0,0,114,0,0,0,229,0,0,0,0,0,0,229,19,19,10,19,19,19,10,19,19,0,0,124,89,0,19,0,0,0,0
0,0,0,0,19,0,0,0,0,0,0,0,19,27,0,0,229,0,0,0,0,0,0,229,19,0,0,0,0,0,0,0,19,0,0,0,0,0,19,0,0,0,0
0,0,0,0,0,0,0,0,0,0,0,0,19,229,0,0,229,229,229,229,229,0,0,229,19,0,0,0,0,0,0,0,19,19,19,10,19,19,19,0,0,0,0
0,0,0,0,19,0,19,0,312,19,0,19,0,19,27,0,0,0,0,0,0,0,32,19,0,0,0,0,0,0,0,0,0,0,0,0,0,0,0,0,0,0,0
0,0,0,0,0,0,0,0,0,0,0,0,0,10,0,31,0,0,0,0,0,31,0,10,0,0,0,0,0,0,0,0,0,0,0,0,0,0,0,0,0,0,0
0,0,0,0,0,0,0,0,0,0,0,0,0,10,10,19,229,229,229,229,229,19,10,10,0,0,0,0,0,0,0,0,0,0,0,0,0,0,0,0,0,0,0
0,0,0,0,0,0,0,0,0,0,0,0,0,0,0,0,19,19,19,19,19,0,0,0,0,0,0,0,0,0,0,0,0,0,0,0,0,0,0,0,0,0,0
0,0,0,0,0,0,0,0,0,0,0,0,0,0,0,0,0,0,0,0,0,0,0,0,0,0,0,0,0,0,0,0,0,0,0,0,0,0,0,0,0,0,0
0,0,0,0,0,0,0,0,0,0,0,0,0,0,0,0,0,0,0,0,0,0,0,0,0,0,0,0,0,0,0,0,0,0,0,0,0,0,0,0,0,0,0
0,0,0,0,0,0,0,0,0,0,0,0,0,0,0,0,0,0,0,0,0,0,0,0,0,0,0,0,0,0,0,0,0,0,0,0,0,0,0,0,0,0,0
0,0,0,0,0,0,0,0,0,0,0,0,0,0,0,0,0,0,0,0,0,0,0,0,0,0,0,0,0,0,0,0,0,0,0,0,0,0,0,0,0,0,0
:endlayer
layer: 18
0,0,0,0,0,0,0,0,0,0,0,0,0,0,0,0,0,0,0,0,0,0,0,0,0,0,0,0,0,0,0,0,0,0,0,0,0,0,0,0,0,0,0
0,0,0,0,0,0,0,0,0,0,0,0,0,0,0,0,0,0,0,0,0,0,0,0,0,0,0,0,0,0,0,0,0,0,0,0,0,0,0,0,0,0,0
0,0,0,0,0,0,0,0,0,0,0,0,0,0,0,0,0,0,0,0,0,0,0,0,0,0,0,0,0,0,0,0,0,0,0,0,0,0,0,0,0,0,0
0,0,0,0,0,0,0,0,0,0,0,0,0,0,0,0,0,0,0,0,0,0,0,0,0,0,0,0,0,0,0,0,0,0,0,0,0,0,0,0,0,0,0
0,0,0,19,142,19,142,19,142,19,142,19,19,19,19,10,19,19,19,0,0,0,0,0,0,0,0,0,0,0,0,0,19,19,19,10,19,19,19,0,0,0,0
0,0,0,124,40,40,40,40,40,40,40,40,19,0,0,0,0,0,19,0,0,0,0,0,0,0,0,0,0,0,0,0,19,0,0,0,0,0,19,0,0,0,0
0,0,0,19,40,0,0,0,0,0,32,19,19,0,0,87,88,0,19,19,19,10,19,19,19,10,19,19,19,10,19,19,19,0,0,0,0,0,19,0,0,0,0
0,0,0,124,40,0,0,0,0,0,0,0,0,0,0,19,89,0,19,0,0,0,0,0,0,0,0,0,0,0,0,0,19,0,0,0,0,0,10,0,0,0,0
0,0,0,19,40,0,0,0,0,0,32,19,19,0,0,0,0,0,19,0,0,0,0,0,0,0,0,0,0,0,0,0,19,0,0,0,0,0,19,0,0,0,0
0,0,0,124,40,0,0,313,0,0,0,0,19,0,0,314,0,0,19,0,0,0,0,0,0,0,0,0,0,0,0,0,19,0,0,0,0,0,19,0,0,0,0
0,0,0,19,40,0,0,0,0,0,0,0,19,19,19,19,19,19,19,19,19,19,19,19,19,19,19,0,0,0,19,19,19,19,19,19,19,19,19,0,0,0,0
0,0,0,124,40,0,0,0,0,0,315,0,0,0,19,0,19,0,0,0,0,0,0,0,0,0,19,0,0,0,19,0,0,0,0,0,19,0,0,0,0,0,0
0,0,0,19,40,0,0,0,0,0,0,0,0,0,19,0,19,0,0,0,0,0,0,0,0,0,19,0,0,0,19,0,0,0,0,0,19,0,0,0,0,0,0
0,0,0,124,40,40,40,40,40,40,40,40,40,40,19,0,19,0,0,0,0,0,0,0,0,0,19,0,0,0,19,0,0,0,0,0,10,0,0,0,0,0,0
0,0,0,19,89,19,89,19,89,19,89,19,89,19,19,0,19,0,0,0,0,0,0,0,0,0,19,0,0,0,19,0,0,0,0,0,19,0,0,0,0,0,0
0,0,0,0,0,0,0,0,0,0,0,0,0,0,19,0,19,19,19,19,19,19,19,19,19,19,19,0,0,0,19,19,19,19,19,19,19,0,0,0,0,0,0
0,0,0,0,0,0,0,0,0,0,0,0,0,0,19,0,19,0,0,0,0,0,0,0,0,0,0,0,0,0,0,0,0,0,0,0,19,0,0,0,0,0,0
0,0,0,0,0,0,0,0,0,0,0,0,0,0,10,0,19,0,0,0,0,0,0,0,0,0,0,0,0,0,0,0,0,0,0,0,10,0,0,0,0,0,0
0,0,0,0,0,0,0,0,0,0,0,0,0,0,19,0,19,0,0,0,0,0,0,0,0,0,0,0,0,0,0,0,0,0,0,0,19,0,0,0,0,0,0
0,0,0,0,0,0,0,0,0,0,0,0,0,0,19,0,19,0,0,0,19,19,19,19,19,19,19,0,0,0,19,19,19,19,19,19,19,0,0,0,0,0,0
0,0,0,0,0,0,0,0,0,0,0,0,0,0,10,0,19,0,0,0,19,0,0,0,0,0,19,0,0,0,19,0,0,0,0,0,19,0,0,0,0,0,0
0,0,0,0,0,0,0,0,0,0,0,0,0,0,19,0,19,0,0,0,19,0,0,0,0,0,19,0,0,0,19,0,0,0,0,0,10,0,0,0,0,0,0
0,0,0,0,0,0,0,0,0,0,0,0,0,0,19,19,19,19,19,19,19,0,0,0,0,0,19,0,0,0,19,0,0,0,0,0,19,0,0,0,0,0,0
0,0,0,0,218,0,0,0,0,0,0,0,0,0,19,19,229,0,0,0,229,19,19,0,0,0,19,0,0,0,19,0,0,0,0,0,19,0,0,0,0,0,0
0,0,0,0,0,0,0,0,0,0,0,0,0,19,229,229,0,0,0,0,0,229,229,19,0,0,19,0,0,0,19,0,19,19,19,19,19,19,19,0,0,0,0
0,0,0,0,0,0,0,0,0,0,0,0,0,19,229,0,0,0,0,0,0,0,0,19,19,19,19,0,0,0,19,19,19,0,0,0,0,0,19,0,0,0,0
0,0,0,0,0,0,0,0,0,0,0,0,19,229,0,0,229,229,0,0,0,0,0,229,19,0,0,0,0,0,0,0,19,0,0,0,0,0,19,0,0,0,0
0,0,0,0,0,0,0,0,0,0,0,0,19,0,0,0,229,0,0,0,0,0,0,229,19,0,0,0,0,0,0,0,19,0,142,19,0,0,10,0,0,0,0
0,0,0,0,0,0,0,0,0,0,0,0,124,0,0,0,229,0,0,0,0,0,0,229,19,19,10,19,19,19,10,19,19,0,124,35,0,0,19,0,0,0,0
0,0,0,0,0,0,0,0,0,0,0,0,19,0,0,0,229,0,0,0,0,0,0,229,19,0,0,0,0,0,0,0,19,0,0,0,0,0,19,0,0,0,0
0,0,0,0,0,0,0,0,0,0,0,0,19,229,0,0,229,229,229,229,229,0,0,229,19,0,0,0,0,0,0,0,19,19,19,10,19,19,19,0,0,0,0
0,0,0,0,218,0,0,0,0,0,0,218,0,19,0,0,0,0,0,0,0,0,0,19,0,0,0,0,0,0,0,0,0,0,0,0,0,0,0,0,0,0,0
0,0,0,0,0,0,0,0,0,0,0,0,0,10,0,0,0,0,0,0,0,0,0,10,0,0,0,0,0,0,0,0,0,0,0,0,0,0,0,0,0,0,0
0,0,0,0,0,0,0,0,0,0,0,0,0,10,10,19,229,229,229,229,229,19,10,10,0,0,0,0,0,0,0,0,0,0,0,0,0,0,0,0,0,0,0
0,0,0,0,0,0,0,0,0,0,0,0,0,0,0,0,19,19,19,19,19,0,0,0,0,0,0,0,0,0,0,0,0,0,0,0,0,0,0,0,0,0,0
0,0,0,0,0,0,0,0,0,0,0,0,0,0,0,0,0,0,0,0,0,0,0,0,0,0,0,0,0,0,0,0,0,0,0,0,0,0,0,0,0,0,0
0,0,0,0,0,0,0,0,0,0,0,0,0,0,0,0,0,0,0,0,0,0,0,0,0,0,0,0,0,0,0,0,0,0,0,0,0,0,0,0,0,0,0
0,0,0,0,0,0,0,0,0,0,0,0,0,0,0,0,0,0,0,0,0,0,0,0,0,0,0,0,0,0,0,0,0,0,0,0,0,0,0,0,0,0,0
0,0,0,0,0,0,0,0,0,0,0,0,0,0,0,0,0,0,0,0,0,0,0,0,0,0,0,0,0,0,0,0,0,0,0,0,0,0,0,0,0,0,0
:endlayer
layer: 19
0,0,0,0,0,0,0,0,0,0,0,0,0,0,0,0,0,0,0,0,0,0,0,0,0,0,0,0,0,0,0,0,0,0,0,0,0,0,0,0,0,0,0
0,0,0,0,0,0,0,0,0,0,0,0,0,0,0,0,0,0,0,0,0,0,0,0,0,0,0,0,0,0,0,0,0,0,0,0,0,0,0,0,0,0,0
0,0,0,0,0,0,0,0,0,0,0,0,0,0,0,0,0,0,0,0,0,0,0,0,0,0,0,0,0,0,0,0,0,0,0,0,0,0,0,0,0,0,0
0,0,0,0,0,0,0,0,0,0,0,0,0,0,0,0,0,0,0,0,0,0,0,0,0,0,0,0,0,0,0,0,0,0,0,0,0,0,0,0,0,0,0
0,0,0,19,19,0,19,19,316,19,19,0,19,19,19,19,19,19,19,0,0,0,0,0,0,0,0,0,0,0,0,0,19,19,19,19,19,19,19,0,0,0,0
0,0,0,19,0,0,0,0,0,0,0,0,19,19,19,19,19,19,19,0,0,0,0,0,0,0,0,0,0,0,0,0,19,19,19,19,19,19,19,0,0,0,0
0,0,0,0,0,0,0,0,0,0,0,15,19,19,0,0,0,19,19,19,19,19,19,19,19,19,19,19,19,19,19,19,19,19,19,19,19,19,19,0,0,0,0
0,0,0,19,0,0,0,0,0,0,0,19,19,19,32,19,15,19,19,19,19,19,19,19,19,19,19,19,19,19,19,19,19,19,19,19,19,19,19,0,0,0,0
0,0,0,19,0,0,0,0,0,0,0,41,19,19,0,0,89,19,19,19,19,19,19,19,19,19,19,19,19,19,19,19,19,19,19,19,19,19,19,0,0,0,0
0,0,0,317,0,0,0,0,0,0,0,0,19,19,19,19,19,19,19,19,19,19,19,19,19,19,19,19,19,19,19,19,19,19,19,19,19,19,19,0,0,0,0
0,0,0,19,0,0,0,0,0,0,0,0,19,19,19,19,19,19,19,19,19,19,19,19,19,19,19,19,19,19,19,19,19,19,19,19,19,19,19,0,0,0,0
0,0,0,19,0,0,0,0,0,0,0,0,0,0,19,19,19,19,19,19,19,19,19,19,19,19,19,19,19,19,19,19,19,19,19,19,19,0,0,0,0,0,0
0,0,0,0,0,0,0,0,0,0,0,0,0,0,19,19,19,19,19,19,19,19,19,19,19,19,19,19,19,19,19,19,19,19,19,19,19,0,0,0,0,0,0
0,0,0,19,0,0,0,0,0,0,0,0,0,0,19,19,19,19,19,19,19,19,19,19,19,19,19,19,19,19,19,19,19,19,19,19,19,0,0,0,0,0,0
0,0,0,19,19,0,19,19,318,19,19,0,19,19,19,19,19,19,19,19,19,19,19,19,19,19,19,19,19,19,19,19,19,19,19,19,19,0,0,0,0,0,0
0,0,0,0,0,0,0,0,0,0,0,0,0,0,19,19,19,19,19,19,19,19,19,19,19,19,19,19,19,19,19,19,19,19,19,19,19,0,0,0,0,0,0
0,0,0,0,0,0,0,0,0,0,0,0,0,0,19,19,19,19,19,19,19,19,19,19,19,19,19,19,19,19,19,19,19,19,19,19,19,0,0,0,0,0,0
0,0,0,0,0,0,0,0,0,0,0,0,0,0,19,19,19,19,19,19,19,19,19,19,19,19,19,19,19,19,19,19,19,19,19,19,19,0,0,0,0,0,0
0,0,0,0,0,0,0,0,0,0,0,0,0,0,19,19,19,19,19,19,19,19,19,19,19,19,19,19,19,19,19,19,19,19,19,19,19,0,0,0,0,0,0
0,0,0,0,0,0,0,0,0,0,0,0,0,0,19,19,19,19,19,19,19,19,19,19,19,19,19,19,19,19,19,19,19,19,19,19,19,0,0,0,0,0,0
0,0,0,0,0,0,0,0,0,0,0,0,0,0,19,19,19,19,19,19,19,19,19,19,19,19,19,19,19,19,19,19,19,19,19,19,19,0,0,0,0,0,0
0,0,0,0,0,0,0,0,0,0,0,0,0,0,19,19,19,19,19,19,19,19,19,19,19,19,19,19,19,19,19,19,19,19,19,19,19,0,0,0,0,0,0
0,0,0,0,0,0,0,0,0,0,0,0,0,0,19,19,19,19,19,19,19,19,19,19,19,19,19,19,19,19,19,19,19,19,19,19,19,0,0,0,0,0,0
0,0,0,0,0,0,0,0,0,0,0,0,0,0,19,19,19,19,19,19,19,19,19,19,19,19,19,19,19,19,19,19,19,19,19,19,19,0,0,0,0,0,0
0,0,0,0,0,0,0,0,0,0,0,0,0,19,19,19,19,19,19,19,19,19,19,19,19,19,19,19,19,19,19,19,19,19,19,19,19,19,19,0,0,0,0
0,0,0,0,0,0,0,0,0,0,0,0,0,19,19,19,19,19,19,19,19,19,19,19,19,19,19,19,19,19,19,19,19,19,19,19,19,19,19,0,0,0,0
0,0,0,0,0,0,0,0,0,0,0,0,19,19,19,19,19,19,19,19,19,19,19,19,19,19,19,19,19,19,19,19,19,19,142,88,0,19,19,0,0,0,0
0,0,0,0,0,0,0,0,0,0,0,0,19,19,19,19,19,19,19,19,19,19,19,19,19,19,19,19,19,19,19,19,19,19,41,19,27,19,19,0,0,0,0
0,0,0,0,0,0,0,0,0,0,0,32,19,19,19,19,19,19,19,19,19,19,19,19,19,19,19,19,19,19,19,19,19,19,0,0,0,19,19,0,0,0,0
0,0,0,0,0,0,0,0,0,0,0,0,19,19,19,19,19,19,19,19,19,19,19,19,19,0,0,0,0,0,0,0,19,19,19,19,19,19,19,0,0,0,0
0,0,0,0,0,0,0,0,0,0,0,0,19,19,19,19,19,19,19,19,19,19,19,19,19,0,0,0,0,0,0,0,19,19,19,19,19,19,19,0,0,0,0
0,0,0,0,0,0,0,0,0,0,0,0,0,19,19,19,19,19,19,19,19,19,19,19,0,0,0,0,0,0,0,0,0,0,0,0,0,0,0,0,0,0,0
0,0,0,0,0,0,0,0,0,0,0,0,0,19,19,19,19,19,19,19,19,19,19,19,0,0,0,0,0,0,0,0,0,0,0,0,0,0,0,0,0,0,0
0,0,0,0,0,0,0,0,0,0,0,0,0,40,19,19,19,19,19,19,19,19,19,40,0,0,0,0,0,0,0,0,0,0,0,0,0,0,0,0,0,0,0
0,0,0,0,0,0,0,0,0,0,0,0,0,0,0,0,19,19,19,19,19,0,0,0,0,0,0,0,0,0,0,0,0,0,0,0,0,0,0,0,0,0,0
0,0,0,0,0,0,0,0,0,0,0,0,0,0,0,0,0,0,0,0,0,0,0,0,0,0,0,0,0,0,0,0,0,0,0,0,0,0,0,0,0,0,0
0,0,0,0,0,0,0,0,0,0,0,0,0,0,0,0,0,0,0,0,0,0,0,0,0,0,0,0,0,0,0,0,0,0,0,0,0,0,0,0,0,0,0
0,0,0,0,0,0,0,0,0,0,0,0,0,0,0,0,0,0,0,0,0,0,0,0,0,0,0,0,0,0,0,0,0,0,0,0,0,0,0,0,0,0,0
0,0,0,0,0,0,0,0,0,0,0,0,0,0,0,0,0,0,0,0,0,0,0,0,0,0,0,0,0,0,0,0,0,0,0,0,0,0,0,0,0,0,0
:endlayer
layer: 20
0,0,0,0,0,0,0,0,0,0,0,0,0,0,0,0,0,0,0,0,0,0,0,0,0,0,0,0,0,0,0,0,0,0,0,0,0,0,0,0,0,0,0
0,0,0,0,0,0,0,0,0,0,0,0,0,0,0,0,0,0,0,0,0,0,0,0,0,0,0,0,0,0,0,0,0,0,0,0,0,0,0,0,0,0,0
0,0,0,0,0,0,0,0,0,0,0,0,0,0,0,0,0,0,0,0,0,0,0,0,0,0,0,0,0,0,0,0,0,0,0,0,0,0,0,0,0,0,0
0,0,0,0,0,0,0,0,0,0,0,0,0,0,0,0,0,0,0,0,0,0,0,0,0,0,0,0,0,0,0,0,0,0,0,0,0,0,0,0,0,0,0
0,0,0,218,40,0,0,0,0,0,218,0,19,19,19,19,19,19,19,0,0,0,0,0,0,0,0,0,0,0,0,0,19,19,19,19,19,19,19,0,0,0,0
0,0,0,40,0,0,0,0,0,0,0,0,19,0,0,0,0,0,19,0,0,0,0,0,0,0,0,0,0,0,0,0,19,19,19,319,320,321,19,0,0,0,0
0,0,0,0,0,0,0,0,0,0,0,0,19,0,0,0,0,0,19,19,19,19,19,19,19,19,19,19,19,19,19,19,19,19,0,0,0,0,19,0,0,0,0
0,0,0,0,0,0,0,0,0,0,0,0,87,0,142,19,0,0,3,0,0,0,0,0,0,0,0,0,0,0,0,0,19,322,0,0,0,0,19,0,0,0,0
0,0,0,0,0,0,0,0,0,0,0,0,19,0,124,35,0,0,19,0,0,0,0,0,0,0,0,0,0,0,0,0,19,323,0,0,0,0,19,0,0,0,0
0,0,0,0,0,0,0,0,0,0,0,0,19,0,0,0,0,0,19,0,0,0,0,0,0,0,0,0,0,0,0,0,19,324,0,0,0,325,19,0,0,0,0
0,0,0,0,0,0,0,0,0,0,0,0,19,19,19,19,19,19,19,0,0,0,0,0,0,0,0,0,0,0,0,0,19,19,19,19,19,19,19,0,0,0,0
0,0,0,0,0,0,0,0,0,0,0,0,0,0,19,0,0,0,0,0,0,0,0,0,0,0,0,0,0,0,0,0,0,0,0,0,19,0,0,0,0,0,0
0,0,0,0,0,0,0,0,0,0,0,0,0,0,19,0,0,0,0,0,0,0,0,0,0,0,0,0,0,0,0,0,0,0,0,0,19,0,0,0,0,0,0
0,0,0,40,0,0,0,0,0,0,0,0,0,0,19,0,0,0,0,0,0,0,0,0,326,326,326,326,326,326,326,326,326,0,15,15,19,0,0,0,0,0,0
0,0,0,218,40,0,0,0,0,0,0,0,218,0,19,0,0,0,0,0,0,0,0,0,326,19,327,327,19,327,327,19,326,0,87,19,19,0,0,0,0,0,0
0,0,0,0,0,0,0,0,0,0,0,0,0,0,19,0,0,0,0,0,0,0,0,0,326,328,328,328,328,328,328,328,326,0,231,0,19,0,0,0,0,0,0
0,0,0,0,0,0,0,0,0,0,0,0,0,0,19,0,0,0,0,0,0,0,0,0,326,328,57,57,328,57,57,328,326,0,231,0,19,0,0,0,0,0,0
0,0,0,0,0,0,0,0,0,0,0,0,0,0,19,0,0,0,0,0,0,0,0,0,326,328,328,328,328,328,328,328,326,0,231,0,19,0,0,0,0,0,0
0,0,0,0,0,0,0,0,0,0,0,0,0,0,19,0,0,0,0,0,0,0,0,0,326,19,329,329,19,329,329,19,326,0,87,19,19,0,0,0,0,0,0
0,0,0,0,0,0,0,0,0,0,0,0,0,0,19,0,0,0,0,0,0,0,0,0,326,326,326,326,326,326,326,326,326,0,41,41,19,0,0,0,0,0,0
0,0,0,0,0,0,0,0,0,0,0,0,0,0,19,0,0,0,0,0,0,0,0,0,0,0,0,0,0,0,0,0,0,0,0,0,19,0,0,0,0,0,0
0,0,0,0,0,0,0,0,0,0,0,0,0,0,19,0,0,0,0,0,0,0,0,0,0,0,0,0,0,0,0,0,0,0,0,0,19,0,0,0,0,0,0
0,0,0,0,0,0,0,0,0,0,0,0,0,0,19,19,19,19,3,19,19,0,0,0,0,0,19,15,15,15,19,0,0,0,0,0,19,0,0,0,0,0,0
0,0,0,0,0,0,0,0,0,0,0,0,0,0,19,19,330,0,0,0,331,19,19,0,0,0,87,76,76,76,35,0,0,0,0,0,19,0,0,0,0,0,0
0,0,0,0,0,0,0,0,0,0,0,0,0,19,0,0,0,0,0,0,0,0,0,19,19,0,87,76,76,76,35,0,19,19,19,19,19,19,19,0,0,0,0
0,0,0,0,0,0,0,0,0,0,0,0,0,19,0,0,0,0,0,0,0,0,0,19,19,0,87,76,76,76,35,0,19,0,0,0,0,0,19,0,0,0,0
0,0,0,0,0,0,0,0,0,0,0,0,19,332,0,0,0,0,0,0,0,0,0,333,19,0,87,76,76,76,35,0,19,0,0,87,88,0,19,0,0,0,0
0,0,0,0,0,0,0,0,0,0,0,0,19,334,0,0,0,0,0,0,0,0,0,335,19,0,19,76,76,76,19,0,19,0,0,19,89,0,19,0,0,0,0
0,0,0,0,0,0,0,0,0,0,0,0,87,0,0,0,0,0,0,0,0,0,0,0,19,19,19,19,19,19,19,19,19,0,0,0,0,0,19,0,0,0,0
0,0,0,0,0,0,0,0,0,0,0,0,19,0,0,0,0,0,0,0,0,0,0,336,19,0,0,0,0,0,0,0,19,0,0,0,0,0,19,0,0,0,0
0,0,0,0,0,0,0,0,0,0,0,0,19,0,0,0,0,0,0,0,0,0,0,337,19,0,0,0,0,0,0,0,19,19,19,19,19,19,19,0,0,0,0
0,0,0,0,0,0,0,0,0,0,0,0,0,19,338,0,0,0,0,0,0,0,0,19,0,0,0,0,0,0,0,0,0,0,0,0,0,0,0,0,0,0,0
0,0,0,0,0,0,0,0,0,0,0,0,0,19,339,0,0,0,0,0,0,340,341,19,0,0,0,0,0,0,0,0,0,0,0,0,0,0,0,0,0,0,0
0,0,0,0,0,0,0,0,0,0,0,0,0,0,19,19,342,0,343,0,344,19,19,0,0,0,0,0,0,0,0,0,0,0,0,0,0,0,0,0,0,0,0
0,0,0,0,0,0,0,0,0,0,0,0,0,0,0,0,19,19,41,19,19,0,0,0,0,0,0,0,0,0,0,0,0,0,0,0,0,0,0,0,0,0,0
0,0,0,0,0,0,0,0,0,0,0,0,0,0,0,0,0,0,0,0,0,0,0,0,0,0,0,0,0,0,0,0,0,0,0,0,0,0,0,0,0,0,0
0,0,0,0,0,0,0,0,0,0,0,0,0,0,0,0,0,0,0,0,0,0,0,0,0,0,0,0,0,0,0,0,0,0,0,0,0,0,0,0,0,0,0
0,0,0,0,0,0,0,0,0,0,0,0,0,0,0,0,0,0,0,0,0,0,0,0,0,0,0,0,0,0,0,0,0,0,0,0,0,0,0,0,0,0,0
0,0,0,0,0,0,0,0,0,0,0,0,0,0,0,0,0,0,0,0,0,0,0,0,0,0,0,0,0,0,0,0,0,0,0,0,0,0,0,0,0,0,0
:endlayer
layer: 21
0,0,0,0,0,0,0,0,0,0,0,0,0,0,0,0,0,0,0,0,0,0,0,0,0,0,0,0,0,0,0,0,0,0,0,0,0,0,0,0,0,0,0
0,0,0,0,0,0,0,0,0,0,0,0,0,0,0,0,0,0,0,0,0,0,0,0,0,0,0,0,0,0,0,0,0,0,0,0,0,0,0,0,0,0,0
0,0,0,0,0,0,0,0,0,0,0,0,0,0,0,0,0,0,0,0,0,0,0,0,0,0,0,0,0,0,0,0,0,0,0,0,0,0,0,0,0,0,0
0,0,0,0,0,0,0,0,0,0,0,0,0,0,0,0,0,0,0,0,0,0,0,0,0,0,0,0,0,0,0,0,0,0,0,0,0,0,0,0,0,0,0
0,0,0,0,0,0,0,0,0,0,0,0,19,19,19,19,19,19,19,0,0,0,0,0,0,0,0,0,0,0,0,0,19,19,19,19,19,19,19,0,0,0,0
0,0,0,0,0,0,0,0,0,0,0,0,19,0,0,0,0,0,19,0,142,0,142,0,142,0,142,0,142,0,142,0,19,218,0,0,0,32,19,0,0,0,0
0,0,0,0,0,0,0,0,0,0,0,0,19,0,142,88,0,0,19,19,19,19,19,19,19,19,19,19,19,19,19,19,19,0,0,0,0,0,19,0,0,0,0
0,0,0,0,0,0,0,0,0,0,0,0,10,0,41,19,27,0,24,0,0,0,28,0,0,0,28,0,0,0,0,28,19,0,0,0,0,0,19,0,0,0,0
0,0,0,0,0,0,0,0,0,0,0,0,19,0,0,0,0,0,19,27,0,0,0,0,0,0,0,0,0,0,0,0,19,0,0,0,0,0,19,0,0,0,0
0,0,0,0,0,0,0,0,0,0,0,0,19,0,0,0,0,0,19,0,0,0,0,0,0,0,0,0,0,0,0,0,19,27,0,0,0,325,19,0,0,0,0
0,0,0,0,0,0,0,0,0,0,0,0,19,19,19,19,19,19,19,0,0,0,0,0,0,0,0,0,0,0,0,32,19,19,19,19,19,19,19,0,0,0,0
0,0,0,0,0,0,0,0,0,0,0,0,0,0,19,0,0,0,28,0,0,0,0,0,0,0,0,0,0,0,0,0,0,0,0,0,19,0,0,0,0,0,0
0,0,0,0,0,0,0,0,0,0,0,0,0,124,19,27,0,0,0,0,0,0,0,0,0,0,0,0,0,0,0,0,0,0,0,0,19,88,0,0,0,0,0
0,0,0,0,0,0,0,0,0,0,0,0,0,0,19,0,0,0,0,0,0,0,0,0,0,0,0,0,0,0,0,0,0,0,0,0,19,0,0,0,0,0,0
0,0,0,0,0,0,0,0,0,0,0,0,0,124,19,27,0,0,0,0,0,0,0,0,0,218,0,0,218,0,0,218,0,0,0,19,19,88,0,0,0,0,0
0,0,0,0,0,0,0,0,0,0,0,0,0,0,19,0,0,0,0,0,0,0,0,0,0,0,0,0,0,0,0,0,0,0,0,0,19,0,0,0,0,0,0
0,0,0,0,0,0,0,0,0,0,0,0,0,124,19,27,0,0,0,0,0,0,0,0,0,0,4,4,0,4,4,0,0,0,0,0,19,88,0,0,0,0,0
0,0,0,0,0,0,0,0,0,0,0,0,0,0,19,0,0,0,0,0,0,0,0,0,0,0,0,0,0,0,0,0,0,0,0,0,19,0,0,0,0,0,0
0,0,0,0,0,0,0,0,0,0,0,0,0,124,19,27,0,0,0,0,0,0,0,0,0,218,0,0,218,0,0,218,0,0,0,19,19,88,0,0,0,0,0
0,0,0,0,0,0,0,0,0,0,0,0,0,0,19,0,0,0,0,0,0,0,0,0,0,0,0,0,0,0,0,0,0,0,0,0,19,0,0,0,0,0,0
0,0,0,0,0,0,0,0,0,0,0,0,0,124,19,27,0,0,0,0,0,0,0,0,0,0,0,0,0,0,0,0,0,0,0,0,19,88,0,0,0,0,0
0,0,0,0,0,0,0,0,0,0,0,0,0,0,19,0,0,31,0,31,0,0,0,0,0,0,0,0,0,0,0,0,0,0,0,32,19,0,0,0,0,0,0
0,0,0,0,0,0,0,0,0,0,0,0,0,124,19,19,19,19,24,19,19,27,0,0,0,0,57,0,0,0,57,0,0,0,0,0,19,88,0,0,0,0,0
0,0,0,0,0,0,0,0,0,0,0,0,0,0,19,19,27,0,0,0,32,19,19,0,31,0,0,328,328,328,0,0,31,0,0,0,19,0,0,0,0,0,0
0,0,0,0,0,0,0,0,0,0,0,0,0,19,0,0,0,0,0,0,0,0,0,19,19,0,0,328,328,328,0,0,19,19,19,19,19,19,19,0,0,0,0
0,0,0,0,0,0,0,0,0,0,0,0,0,19,0,0,0,0,0,0,0,0,0,19,19,0,0,328,328,328,0,0,19,0,0,0,0,0,19,0,0,0,0
0,0,0,0,0,0,0,0,0,0,0,0,19,28,0,0,0,0,0,0,0,0,0,28,19,27,0,0,0,0,0,32,19,0,0,0,0,0,19,0,0,0,0
0,0,0,0,0,0,0,0,0,0,0,0,19,0,0,0,0,0,0,0,0,0,0,0,19,0,57,345,345,345,57,0,19,0,32,19,15,0,19,0,0,0,0
0,0,0,0,0,0,0,0,0,0,0,0,10,0,0,0,0,0,0,0,0,0,0,0,19,19,19,19,19,19,19,19,19,0,0,124,89,0,19,0,0,0,0
0,0,0,0,0,0,0,0,0,0,0,0,19,0,0,0,0,0,0,0,0,0,0,0,19,0,89,0,89,0,89,0,19,0,0,0,0,0,19,0,0,0,0
0,0,0,0,0,0,0,0,0,0,0,0,19,31,0,0,0,0,0,0,0,0,0,31,19,0,0,0,0,0,0,0,19,19,19,19,19,19,19,0,0,0,0
0,0,0,0,0,0,0,0,0,0,0,0,0,19,0,0,0,0,0,0,0,0,0,19,0,0,0,0,0,0,0,0,0,0,0,0,0,0,0,0,0,0,0
0,0,0,0,0,0,0,0,0,0,0,0,0,19,0,0,0,0,0,0,0,0,0,19,0,0,0,0,0,0,0,0,0,0,0,0,0,0,0,0,0,0,0
0,0,0,0,0,0,0,0,0,0,0,0,0,0,19,19,27,0,0,0,32,19,19,0,0,0,0,0,0,0,0,0,0,0,0,0,0,0,0,0,0,0,0
0,0,0,0,0,0,0,0,0,0,0,0,0,0,0,0,19,19,10,19,19,0,0,0,0,0,0,0,0,0,0,0,0,0,0,0,0,0,0,0,0,0,0
0,0,0,0,0,0,0,0,0,0,0,0,0,0,0,0,0,0,0,0,0,0,0,0,0,0,0,0,0,0,0,0,0,0,0,0,0,0,0,0,0,0,0
0,0,0,0,0,0,0,0,0,0,0,0,0,0,0,0,0,0,0,0,0,0,0,0,0,0,0,0,0,0,0,0,0,0,0,0,0,0,0,0,0,0,0
0,0,0,0,0,0,0,0,0,0,0,0,0,0,0,0,0,0,0,0,0,0,0,0,0,0,0,0,0,0,0,0,0,0,0,0,0,0,0,0,0,0,0
0,0,0,0,0,0,0,0,0,0,0,0,0,0,0,0,0,0,0,0,0,0,0,0,0,0,0,0,0,0,0,0,0,0,0,0,0,0,0,0,0,0,0
:endlayer
layer: 22
0,0,0,0,0,0,0,0,0,0,0,0,0,0,0,0,0,0,0,0,0,0,0,0,0,0,0,0,0,0,0,0,0,0,0,0,0,0,0,0,0,0,0
0,0,0,0,0,0,0,0,0,0,0,0,0,0,0,0,0,0,0,0,0,0,0,0,0,0,0,0,0,0,0,0,0,0,0,0,0,0,0,0,0,0,0
0,0,0,0,0,0,0,0,0,0,0,0,0,0,0,0,0,0,0,0,0,0,0,0,0,0,0,0,0,0,0,0,0,0,0,0,0,0,0,0,0,0,0
0,0,0,0,0,0,0,0,0,0,0,0,0,0,0,0,0,0,0,0,0,0,0,0,0,0,0,0,0,0,0,0,0,0,0,0,0,0,0,0,0,0,0
0,0,0,0,0,0,0,0,0,0,0,0,19,19,19,19,19,19,19,0,0,0,0,0,0,0,0,0,0,0,0,0,19,19,19,19,19,19,19,0,0,0,0
0,0,0,0,0,0,0,0,0,0,0,0,19,0,0,0,0,0,19,19,15,19,15,19,15,19,15,19,15,19,15,19,19,0,0,0,0,0,19,0,0,0,0
0,0,0,0,0,0,0,0,0,0,0,0,19,0,0,87,88,0,19,19,19,19,19,19,19,19,19,19,19,19,19,19,19,0,0,0,0,0,19,0,0,0,0
0,0,0,0,0,0,0,0,0,0,0,0,10,0,0,19,89,346,19,347,0,0,0,0,0,0,0,0,0,0,0,0,19,0,0,0,0,0,19,0,0,0,0
0,0,0,0,0,0,0,0,0,0,0,0,19,0,0,0,0,0,19,0,0,0,0,0,0,0,0,0,0,0,0,0,19,0,0,0,0,0,19,0,0,0,0
0,0,0,0,0,0,0,0,0,0,0,0,19,0,0,0,0,0,19,0,0,0,0,0,0,0,0,0,0,0,0,0,19,0,0,0,0,325,19,0,0,0,0
0,0,0,0,0,0,0,0,0,0,0,0,19,19,19,19,19,19,19,0,0,0,0,0,0,0,0,0,0,0,0,0,19,19,19,19,19,19,19,0,0,0,0
0,0,0,0,0,0,0,0,0,0,0,0,0,19,19,0,0,0,0,0,0,0,0,0,0,0,0,0,0,0,0,0,0,0,0,0,19,19,0,0,0,0,0
0,0,0,0,0,0,0,0,0,0,0,0,0,87,19,0,0,0,0,0,0,0,0,0,0,0,0,0,0,0,0,0,0,0,0,0,19,35,0,0,0,0,0
0,0,0,0,0,0,0,0,0,0,0,0,0,19,19,0,0,0,0,0,0,0,0,0,0,0,0,0,0,0,0,0,0,0,0,0,19,19,0,0,0,0,0
0,0,0,0,0,0,0,0,0,0,0,0,0,87,19,0,0,0,0,0,0,0,0,0,0,0,0,0,0,0,0,0,0,0,87,19,19,35,0,0,0,0,0
0,0,0,0,0,0,0,0,0,0,0,0,0,19,19,0,0,0,0,0,0,0,0,0,0,0,0,0,0,0,0,0,0,0,87,0,19,19,0,0,0,0,0
0,0,0,0,0,0,0,0,0,0,0,0,0,87,19,0,0,0,0,0,0,0,0,0,0,0,0,0,0,0,0,0,0,0,87,0,19,35,0,0,0,0,0
0,0,0,0,0,0,0,0,0,0,0,0,0,19,19,0,0,0,0,0,0,0,0,0,0,0,0,0,0,0,0,0,0,0,87,0,19,19,0,0,0,0,0
0,0,0,0,0,0,0,0,0,0,0,0,0,87,19,0,0,0,0,0,0,0,0,0,0,0,0,0,0,0,0,0,0,0,87,19,19,35,0,0,0,0,0
0,0,0,0,0,0,0,0,0,0,0,0,0,19,19,0,0,0,0,0,0,0,0,0,0,0,0,0,0,0,0,0,0,0,0,0,19,19,0,0,0,0,0
0,0,0,0,0,0,0,0,0,0,0,0,0,87,19,0,0,0,0,0,0,0,0,0,0,0,0,0,0,0,0,0,0,0,0,0,19,35,0,0,0,0,0
0,0,0,0,0,0,0,0,0,0,0,0,0,19,19,0,0,0,34,0,0,0,0,0,0,0,0,0,0,0,0,0,0,0,0,0,19,19,0,0,0,0,0
0,0,0,0,0,0,0,0,0,0,0,0,0,87,19,19,19,19,19,19,19,0,0,0,0,0,57,0,0,0,57,0,0,0,0,0,19,35,0,0,0,0,0
0,0,0,0,0,0,0,0,0,0,0,0,0,19,19,19,0,0,348,0,0,19,19,0,0,0,0,0,0,0,0,0,0,0,0,0,19,19,0,0,0,0,0
0,0,0,0,0,0,0,0,0,0,0,0,0,19,0,0,0,0,0,0,0,0,0,19,19,0,0,0,0,0,0,0,19,19,19,19,19,19,19,0,0,0,0
0,0,0,0,0,0,0,0,0,0,0,0,0,19,0,0,0,0,0,0,0,0,0,19,19,0,0,0,0,0,0,0,19,0,0,0,0,0,19,0,0,0,0
0,0,0,0,0,0,0,0,0,0,0,0,19,0,0,0,0,0,0,0,0,0,0,0,19,0,0,0,0,0,0,0,19,0,0,0,0,0,19,0,0,0,0
0,0,0,0,0,0,0,0,0,0,0,0,19,0,0,0,0,0,0,0,0,0,0,0,19,124,19,88,31,124,19,88,19,0,142,19,0,0,19,0,0,0,0
0,0,0,0,0,0,0,0,0,0,0,0,10,0,0,0,0,0,0,0,0,0,0,0,19,19,19,19,19,19,19,19,19,0,124,35,0,0,19,0,0,0,0
0,0,0,0,0,0,0,0,0,0,0,0,19,0,0,0,0,0,0,0,0,0,0,0,19,19,41,19,41,19,41,19,19,0,0,0,0,0,19,0,0,0,0
0,0,0,0,0,0,0,0,0,0,0,0,19,0,0,0,0,0,0,0,0,0,0,0,19,0,0,0,0,0,0,0,19,19,19,19,19,19,19,0,0,0,0
0,0,0,0,0,0,0,0,0,0,0,0,0,19,0,0,0,0,0,0,0,0,0,19,0,0,0,0,0,0,0,0,0,0,0,0,0,0,0,0,0,0,0
0,0,0,0,0,0,0,0,0,0,0,0,0,19,0,0,0,0,0,0,0,0,0,19,0,0,0,0,0,0,0,0,0,0,0,0,0,0,0,0,0,0,0
0,0,0,0,0,0,0,0,0,0,0,0,0,0,19,19,0,0,0,0,0,19,19,0,0,0,0,0,0,0,0,0,0,0,0,0,0,0,0,0,0,0,0
0,0,0,0,0,0,0,0,0,0,0,0,0,0,0,0,19,19,10,19,19,0,0,0,0,0,0,0,0,0,0,0,0,0,0,0,0,0,0,0,0,0,0
0,0,0,0,0,0,0,0,0,0,0,0,0,0,0,0,0,0,0,0,0,0,0,0,0,0,0,0,0,0,0,0,0,0,0,0,0,0,0,0,0,0,0
0,0,0,0,0,0,0,0,0,0,0,0,0,0,0,0,0,0,0,0,0,0,0,0,0,0,0,0,0,0,0,0,0,0,0,0,0,0,0,0,0,0,0
0,0,0,0,0,0,0,0,0,0,0,0,0,0,0,0,0,0,0,0,0,0,0,0,0,0,0,0,0,0,0,0,0,0,0,0,0,0,0,0,0,0,0
0,0,0,0,0,0,0,0,0,0,0,0,0,0,0,0,0,0,0,0,0,0,0,0,0,0,0,0,0,0,0,0,0,0,0,0,0,0,0,0,0,0,0
:endlayer
layer: 23
0,0,0,0,0,0,0,0,0,0,0,0,0,0,0,0,0,0,0,0,0,0,0,0,0,0,0,0,0,0,0,0,0,0,0,0,0,0,0,0,0,0,0
0,0,0,0,0,0,0,0,0,0,0,0,0,0,0,0,0,0,0,0,0,0,0,0,0,0,0,0,0,0,0,0,0,0,0,0,0,0,0,0,0,0,0
0,0,0,0,0,0,0,0,0,0,0,0,0,0,0,0,0,0,0,0,0,0,0,0,0,0,0,0,0,0,0,0,0,0,0,0,0,0,0,0,0,0,0
0,0,0,0,0,0,0,0,0,0,0,0,0,0,0,0,0,0,0,0,0,0,0,0,0,0,0,0,0,0,0,0,0,0,0,0,0,0,0,0,0,0,0
0,0,0,0,0,0,0,0,0,0,0,0,19,19,19,19,19,19,19,0,0,0,0,0,0,0,0,0,0,0,0,0,19,19,19,19,19,19,19,0,0,0,0
0,0,0,0,0,0,0,0,0,0,0,0,19,136,136,136,136,136,19,19,240,19,240,19,240,19,240,19,240,19,240,19,19,136,136,136,0,136,19,0,0,0,0
0,0,0,0,0,0,0,0,0,0,0,0,19,136,0,0,0,136,19,19,19,19,19,19,19,19,19,19,19,19,19,19,19,136,136,136,136,136,19,0,0,0,0
0,0,0,0,0,0,0,0,0,0,0,0,19,136,32,136,329,136,19,19,19,19,19,19,19,19,19,19,19,19,19,19,19,136,136,136,136,136,19,0,0,0,0
0,0,0,0,0,0,0,0,0,0,0,0,19,136,0,136,136,136,19,19,19,19,19,19,19,19,19,19,19,19,19,19,19,136,136,136,136,136,19,0,0,0,0
0,0,0,0,0,0,0,0,0,0,0,0,19,136,136,136,136,136,19,19,19,19,19,19,19,19,19,19,19,19,19,19,19,136,136,136,136,325,19,0,0,0,0
0,0,0,0,0,0,0,0,0,0,0,0,19,19,19,19,19,19,19,19,19,19,19,19,19,19,19,19,19,19,19,19,19,19,19,19,19,19,19,0,0,0,0
0,0,0,0,0,0,0,0,0,0,0,0,0,19,19,19,19,19,19,19,19,19,19,19,19,19,19,19,19,19,19,19,19,19,19,19,19,19,0,0,0,0,0
0,0,0,0,0,0,0,0,0,0,0,0,0,240,19,19,19,19,19,19,19,19,19,19,19,19,19,19,19,19,19,19,19,19,19,19,19,240,0,0,0,0,0
0,0,0,0,0,0,0,0,0,0,0,0,0,19,19,19,19,19,0,0,0,0,0,0,0,0,0,0,0,0,0,0,0,19,19,19,19,19,0,0,0,0,0
0,0,0,0,0,0,0,0,0,0,0,0,0,240,19,19,19,19,0,0,0,0,0,0,0,0,0,0,0,0,0,0,0,19,19,19,19,240,0,0,0,0,0
0,0,0,0,0,0,0,0,0,0,0,0,0,19,19,19,19,19,0,0,0,0,0,0,0,0,0,0,0,0,0,0,0,19,19,19,19,19,0,0,0,0,0
0,0,0,0,0,0,0,0,0,0,0,0,0,240,19,19,19,19,0,0,0,0,0,0,0,0,0,0,0,0,0,0,0,19,19,19,19,240,0,0,0,0,0
0,0,0,0,0,0,0,0,0,0,0,0,0,19,19,19,19,19,0,0,0,0,0,0,0,0,0,0,0,0,0,0,0,19,19,19,19,19,0,0,0,0,0
0,0,0,0,0,0,0,0,0,0,0,0,0,240,19,19,19,19,0,0,0,0,0,0,0,0,0,0,0,0,0,0,0,19,19,19,19,240,0,0,0,0,0
0,0,0,0,0,0,0,0,0,0,0,0,0,19,19,19,19,19,19,19,19,19,19,19,19,19,19,19,19,19,19,19,19,19,19,19,19,19,0,0,0,0,0
0,0,0,0,0,0,0,0,0,0,0,0,0,240,19,19,19,19,19,19,19,19,19,19,19,19,19,19,19,19,19,19,19,19,19,19,19,240,0,0,0,0,0
0,0,0,0,0,0,0,0,0,0,0,0,0,19,19,19,19,19,19,19,19,19,19,19,19,19,19,19,19,19,19,19,19,19,19,19,19,19,0,0,0,0,0
0,0,0,0,0,0,0,0,0,0,0,0,0,240,19,19,19,19,19,19,19,19,19,19,19,19,19,19,19,19,19,19,19,19,19,19,19,240,0,0,0,0,0
0,0,0,0,0,0,0,0,0,0,0,0,0,19,19,19,0,0,0,0,0,19,19,19,19,19,19,19,19,19,19,19,19,19,19,19,19,19,0,0,0,0,0
0,0,0,0,0,0,0,0,0,0,0,0,0,19,0,0,0,0,0,0,0,0,0,19,19,19,19,19,19,19,19,19,19,19,19,19,19,19,19,0,0,0,0
0,0,0,0,0,0,0,0,0,0,0,0,0,19,0,0,0,0,0,0,0,0,0,19,19,19,19,19,19,19,19,19,19,136,136,136,136,136,19,0,0,0,0
0,0,0,0,0,0,0,0,0,0,0,0,19,0,0,0,0,0,0,0,0,0,0,0,19,19,19,19,19,19,19,19,19,136,136,136,0,136,19,0,0,0,0
0,0,0,0,0,0,0,0,0,0,0,0,19,0,0,0,0,0,0,0,0,0,0,0,19,19,19,19,19,19,19,19,19,136,327,136,27,136,19,0,0,0,0
0,0,0,0,0,0,0,0,0,0,0,0,19,0,0,0,0,0,0,0,0,0,0,0,19,19,19,19,19,19,19,19,19,136,0,0,0,136,19,0,0,0,0
0,0,0,0,0,0,0,0,0,0,0,0,19,0,0,0,0,0,0,0,0,0,0,0,19,19,240,19,240,19,240,19,19,136,136,136,136,136,19,0,0,0,0
0,0,0,0,0,0,0,0,0,0,0,0,19,0,0,0,0,0,0,0,0,0,0,0,19,0,0,0,0,0,0,0,19,19,19,19,19,19,19,0,0,0,0
0,0,0,0,0,0,0,0,0,0,0,0,0,19,0,0,0,0,0,0,0,0,0,19,0,0,0,0,0,0,0,0,0,0,0,0,0,0,0,0,0,0,0
0,0,0,0,0,0,0,0,0,0,0,0,0,19,0,0,0,0,0,0,0,0,0,19,0,0,0,0,0,0,0,0,0,0,0,0,0,0,0,0,0,0,0
0,0,0,0,0,0,0,0,0,0,0,0,0,0,19,19,0,0,0,0,0,19,19,0,0,0,0,0,0,0,0,0,0,0,0,0,0,0,0,0,0,0,0
0,0,0,0,0,0,0,0,0,0,0,0,0,0,0,0,19,19,19,19,19,0,0,0,0,0,0,0,0,0,0,0,0,0,0,0,0,0,0,0,0,0,0
0,0,0,0,0,0,0,0,0,0,0,0,0,0,0,0,0,0,0,0,0,0,0,0,0,0,0,0,0,0,0,0,0,0,0,0,0,0,0,0,0,0,0
0,0,0,0,0,0,0,0,0,0,0,0,0,0,0,0,0,0,0,0,0,0,0,0,0,0,0,0,0,0,0,0,0,0,0,0,0,0,0,0,0,0,0
0,0,0,0,0,0,0,0,0,0,0,0,0,0,0,0,0,0,0,0,0,0,0,0,0,0,0,0,0,0,0,0,0,0,0,0,0,0,0,0,0,0,0
0,0,0,0,0,0,0,0,0,0,0,0,0,0,0,0,0,0,0,0,0,0,0,0,0,0,0,0,0,0,0,0,0,0,0,0,0,0,0,0,0,0,0
:endlayer
layer: 24
0,0,0,0,0,0,0,0,0,0,0,0,0,0,0,0,0,0,0,0,0,0,0,0,0,0,0,0,0,0,0,0,0,0,0,0,0,0,0,0,0,0,0
0,0,0,0,0,0,0,0,0,0,0,0,0,0,0,0,0,0,0,0,0,0,0,0,0,0,0,0,0,0,0,0,0,0,0,0,0,0,0,0,0,0,0
0,0,0,0,0,0,0,0,0,0,0,0,0,0,0,0,0,0,0,0,0,0,0,0,0,0,0,0,0,0,0,0,0,0,0,0,0,0,0,0,0,0,0
0,0,0,0,0,0,0,0,0,0,0,0,0,0,0,0,0,0,0,0,0,0,0,0,0,0,0,0,0,0,0,0,0,0,0,0,0,0,0,0,0,0,0
0,0,0,0,0,0,0,0,0,0,0,0,19,19,19,15,19,19,19,0,0,0,0,0,0,0,0,0,0,0,0,0,19,19,19,15,19,19,19,0,0,0,0
0,0,0,0,0,0,0,0,0,0,0,0,19,0,0,0,0,0,19,19,142,19,142,19,142,19,142,19,142,19,142,19,19,0,0,0,0,0,19,0,0,0,0
0,0,0,0,0,0,0,0,0,0,0,0,19,0,0,0,0,0,19,0,0,0,0,0,19,19,19,0,0,0,0,0,19,0,0,0,0,0,19,0,0,0,0
0,0,0,0,0,0,0,0,0,0,0,0,87,0,0,0,0,0,0,0,0,0,0,0,41,41,41,0,0,0,0,0,0,0,0,349,0,0,35,0,0,0,0
0,0,0,0,0,0,0,0,0,0,0,0,19,0,0,350,0,0,0,0,0,0,0,0,0,0,0,0,0,0,0,0,0,0,0,0,0,0,19,0,0,0,0
0,0,0,0,0,0,0,0,0,0,0,0,19,351,0,0,0,0,19,0,0,0,0,0,0,0,0,0,0,0,0,0,19,0,0,0,0,325,19,0,0,0,0
0,0,0,0,0,0,0,0,0,0,0,0,19,19,19,0,0,19,19,0,0,218,0,0,0,218,0,0,0,218,0,0,19,19,0,0,19,19,19,0,0,0,0
0,0,0,0,0,0,0,0,0,0,0,0,0,19,0,0,0,0,0,0,0,0,0,0,0,0,0,0,0,0,0,0,0,0,0,0,0,19,0,0,0,0,0
0,0,0,0,0,0,0,0,0,0,0,0,0,124,0,0,0,0,0,0,0,0,0,0,0,0,0,0,0,0,0,0,0,0,0,0,0,88,0,0,0,0,0
0,0,0,0,0,0,0,0,0,0,0,0,0,19,0,0,0,15,15,15,15,15,15,15,15,15,15,15,15,15,15,15,15,15,0,0,0,19,0,0,0,0,0
0,0,0,0,0,0,0,0,0,0,0,0,0,124,0,0,0,87,38,38,38,38,38,38,38,38,38,38,38,38,38,38,38,35,0,0,0,88,0,0,0,0,0
0,0,0,0,0,0,0,0,0,0,0,0,0,19,0,0,0,87,38,38,38,38,38,38,38,38,38,38,38,38,38,38,38,35,0,0,0,19,0,0,0,0,0
0,0,0,0,0,0,0,0,0,0,0,0,0,124,19,35,0,87,0,0,0,0,0,0,0,0,0,0,0,0,0,0,0,35,0,87,19,88,0,0,0,0,0
0,0,0,0,0,0,0,0,0,0,0,0,0,19,19,35,0,87,38,38,38,38,38,38,38,38,38,38,38,38,38,38,38,35,0,87,19,19,0,0,0,0,0
0,0,0,0,0,0,0,0,0,0,0,0,0,124,19,35,0,87,38,38,38,38,38,38,38,38,38,38,38,38,38,38,38,35,0,87,19,88,0,0,0,0,0
0,0,0,0,0,0,0,0,0,0,0,0,0,19,0,0,0,87,41,41,41,41,41,41,41,41,41,41,41,41,41,41,41,41,0,0,0,19,0,0,0,0,0
0,0,0,0,0,0,0,0,0,0,0,0,0,124,0,0,0,0,0,0,0,0,0,0,0,0,0,0,0,0,0,0,0,0,0,0,0,88,0,0,0,0,0
0,0,0,0,0,0,0,0,0,0,0,0,0,19,0,0,0,0,0,0,0,0,0,0,0,0,0,0,0,0,0,0,0,0,0,0,0,19,0,0,0,0,0
0,0,0,0,0,0,0,0,0,0,0,0,0,124,0,0,19,19,19,19,19,0,0,0,0,0,0,0,218,0,0,0,0,0,0,0,0,88,0,0,0,0,0
0,0,0,0,0,0,0,0,0,0,0,0,0,19,19,19,40,40,40,40,40,19,40,0,0,0,0,0,0,0,0,0,0,0,0,0,0,19,0,0,0,0,0
0,0,0,0,0,0,0,0,0,0,0,0,0,19,352,40,40,40,40,40,40,40,40,40,0,0,0,0,0,0,0,0,19,19,0,0,19,19,19,0,0,0,0
0,0,0,0,0,0,0,0,0,0,0,0,0,19,40,40,40,40,40,40,40,40,40,19,0,0,0,0,0,0,0,0,19,0,0,0,0,325,19,0,0,0,0
0,0,0,0,0,0,0,0,0,0,0,0,19,40,40,40,40,40,40,40,40,40,40,40,19,0,0,0,0,0,0,0,0,0,0,353,0,0,19,0,0,0,0
0,0,0,0,0,0,0,0,0,0,0,0,19,40,40,40,40,40,40,40,40,40,40,40,19,0,0,15,15,15,0,0,0,0,0,0,0,0,35,0,0,0,0
0,0,0,0,0,0,0,0,0,0,0,0,19,40,40,40,40,40,40,40,40,40,40,40,19,0,0,19,19,19,0,0,19,0,0,0,0,0,19,0,0,0,0
0,0,0,0,0,0,0,0,0,0,0,0,19,40,40,40,40,40,40,40,40,40,40,40,19,19,89,19,89,19,89,19,19,0,0,0,0,0,19,0,0,0,0
0,0,0,0,0,0,0,0,0,0,0,0,19,40,40,40,40,40,40,40,40,40,40,40,19,0,0,0,0,0,0,0,19,19,19,41,19,19,19,0,0,0,0
0,0,0,0,0,0,0,0,0,0,0,0,0,19,40,40,40,40,40,40,40,40,40,19,0,0,0,0,0,0,0,0,0,0,0,0,0,0,0,0,0,0,0
0,0,0,0,0,0,0,0,0,0,0,0,0,19,40,40,40,40,40,40,40,40,40,19,0,0,0,0,0,0,0,0,0,0,0,0,0,0,0,0,0,0,0
0,0,0,0,0,0,0,0,0,0,0,0,0,0,19,19,40,40,40,40,40,19,19,0,0,0,0,0,0,0,0,0,0,0,0,0,0,0,0,0,0,0,0
0,0,0,0,0,0,0,0,0,0,0,0,0,0,0,0,19,19,19,19,19,0,0,0,0,0,0,0,0,0,0,0,0,0,0,0,0,0,0,0,0,0,0
0,0,0,0,0,0,0,0,0,0,0,0,0,0,0,0,0,0,0,0,0,0,0,0,0,0,0,0,0,0,0,0,0,0,0,0,0,0,0,0,0,0,0
0,0,0,0,0,0,0,0,0,0,0,0,0,0,0,0,0,0,0,0,0,0,0,0,0,0,0,0,0,0,0,0,0,0,0,0,0,0,0,0,0,0,0
0,0,0,0,0,0,0,0,0,0,0,0,0,0,0,0,0,0,0,0,0,0,0,0,0,0,0,0,0,0,0,0,0,0,0,0,0,0,0,0,0,0,0
0,0,0,0,0,0,0,0,0,0,0,0,0,0,0,0,0,0,0,0,0,0,0,0,0,0,0,0,0,0,0,0,0,0,0,0,0,0,0,0,0,0,0
:endlayer
layer: 25
0,0,0,0,0,0,0,0,0,0,0,0,0,0,0,0,0,0,0,0,0,0,0,0,0,0,0,0,0,0,0,0,0,0,0,0,0,0,0,0,0,0,0
0,0,0,0,0,0,0,0,0,0,0,0,0,0,0,0,0,0,0,0,0,0,0,0,0,0,0,0,0,0,0,0,0,0,0,0,0,0,0,0,0,0,0
0,0,0,0,0,0,0,0,0,0,0,0,0,0,0,0,0,0,0,0,0,0,0,0,0,0,0,0,0,0,0,0,0,0,0,0,0,0,0,0,0,0,0
0,0,0,0,0,0,0,0,0,0,0,0,0,0,0,0,0,0,0,0,0,0,0,0,0,0,0,0,0,0,0,0,0,0,0,0,0,0,0,0,0,0,0
0,0,0,0,0,0,0,0,0,0,0,0,19,19,19,10,19,19,19,0,0,0,0,0,0,0,0,0,0,0,0,0,19,19,19,10,19,19,19,0,0,0,0
0,0,0,0,0,0,0,0,0,0,0,0,19,0,0,0,0,0,19,0,19,19,0,19,0,0,0,19,0,19,19,0,19,0,0,0,0,0,19,0,0,0,0
0,0,0,0,0,0,0,0,0,0,0,0,19,0,0,0,0,32,19,27,0,0,0,28,0,0,0,28,0,0,0,32,19,0,0,0,0,0,19,0,0,0,0
0,0,0,0,0,0,0,0,0,0,0,0,10,0,0,0,0,0,0,0,0,0,0,0,0,354,0,0,0,0,0,0,0,0,0,0,0,0,10,0,0,0,0
0,0,0,0,0,0,0,0,0,0,0,0,19,0,0,0,0,0,0,0,0,0,0,0,0,0,0,0,0,0,0,0,0,0,0,0,0,0,19,0,0,0,0
0,0,0,0,0,0,0,0,0,0,0,0,19,351,31,0,0,0,19,27,0,0,0,0,0,0,0,0,0,0,0,32,19,0,0,0,0,325,19,0,0,0,0
0,0,0,0,0,0,0,0,0,0,0,0,19,19,19,0,0,19,19,0,0,0,0,0,0,0,0,0,0,0,0,0,19,19,0,0,19,19,19,0,0,0,0
0,0,0,0,0,0,0,0,0,0,0,0,0,0,28,0,0,28,0,0,0,0,0,0,0,0,0,0,0,0,0,0,0,28,0,0,28,0,0,0,0,0,0
0,0,0,0,0,0,0,0,0,0,0,0,0,19,0,0,0,0,0,0,0,0,0,0,0,0,0,0,0,0,0,0,0,0,0,0,0,19,0,0,0,0,0
0,0,0,0,0,0,0,0,0,0,0,0,0,19,0,0,0,0,0,0,0,0,0,0,0,0,0,0,0,0,0,0,0,0,0,0,0,19,0,0,0,0,0
0,0,0,0,0,0,0,0,0,0,0,0,0,0,0,0,0,0,0,0,0,0,0,0,0,0,0,0,0,0,0,0,0,0,0,0,0,0,0,0,0,0,0
0,0,0,0,0,0,0,0,0,0,0,0,0,19,27,0,0,0,355,355,355,355,355,355,355,355,355,355,355,355,355,355,355,0,0,0,32,19,0,0,0,0,0
0,0,0,0,0,0,0,0,0,0,0,0,0,0,0,0,0,0,38,38,38,38,38,38,38,38,38,38,38,38,38,38,38,0,0,0,0,0,0,0,0,0,0
0,0,0,0,0,0,0,0,0,0,0,0,0,0,0,356,0,0,357,357,357,357,357,357,357,357,357,357,357,357,357,357,357,0,0,358,0,0,0,0,0,0,0
0,0,0,0,0,0,0,0,0,0,0,0,0,0,0,0,0,0,0,0,0,0,0,0,0,0,0,0,0,0,0,0,0,0,0,0,0,0,0,0,0,0,0
0,0,0,0,0,0,0,0,0,0,0,0,0,19,27,0,0,0,0,0,0,0,0,0,0,0,0,0,0,0,0,0,0,0,0,0,32,19,0,0,0,0,0
0,0,0,0,0,0,0,0,0,0,0,0,0,0,0,0,0,0,0,0,0,0,0,0,0,0,0,0,0,0,0,0,0,0,0,0,0,0,0,0,0,0,0
0,0,0,0,0,0,0,0,0,0,0,0,0,19,0,0,0,0,0,0,0,0,0,0,0,0,0,0,0,0,0,0,0,0,0,0,0,19,0,0,0,0,0
0,0,0,0,0,0,0,0,0,0,0,0,0,19,0,0,19,19,19,19,19,0,0,0,0,0,0,0,0,0,0,0,0,0,0,0,0,19,0,0,0,0,0
0,0,0,0,0,0,0,0,0,0,0,0,0,0,19,19,27,0,0,0,32,19,27,0,0,0,0,0,0,0,0,0,0,31,0,0,31,0,0,0,0,0,0
0,0,0,0,0,0,0,0,0,0,0,0,0,19,351,0,0,0,0,0,0,0,0,31,0,0,0,0,0,0,0,0,19,19,0,0,19,19,19,0,0,0,0
0,0,0,0,0,0,0,0,0,0,0,0,0,19,0,0,0,0,0,0,0,0,0,19,0,0,0,0,0,0,0,32,19,0,0,0,28,325,19,0,0,0,0
0,0,0,0,0,0,0,0,0,0,0,0,19,28,0,0,0,0,0,0,0,0,0,28,19,0,0,0,0,0,0,0,0,0,0,0,0,0,19,0,0,0,0
0,0,0,0,0,0,0,0,0,0,0,0,19,0,0,0,0,0,0,0,359,0,0,0,19,0,0,0,360,0,0,0,0,0,0,0,0,0,10,0,0,0,0
0,0,0,0,0,0,0,0,0,0,0,0,19,0,0,0,0,0,0,0,0,0,0,0,19,0,31,0,0,0,31,32,19,27,0,0,0,0,19,0,0,0,0
0,0,0,0,0,0,0,0,0,0,0,0,19,0,0,0,0,0,0,0,0,0,0,0,19,0,19,0,0,0,19,0,19,0,0,0,0,0,19,0,0,0,0
0,0,0,0,0,0,0,0,0,0,0,0,19,31,0,0,0,0,0,0,0,0,0,31,19,0,0,0,0,0,0,0,19,19,19,10,19,19,19,0,0,0,0
0,0,0,0,0,0,0,0,0,0,0,0,0,19,0,361,0,0,0,0,0,0,0,19,0,0,0,0,0,0,0,0,0,0,0,0,0,0,0,0,0,0,0
0,0,0,0,0,0,0,0,0,0,0,0,0,19,0,0,0,0,0,0,0,0,0,19,0,0,0,0,0,0,0,0,0,0,0,0,0,0,0,0,0,0,0
0,0,0,0,0,0,0,0,0,0,0,0,0,0,19,19,27,0,0,0,32,19,19,0,0,0,0,0,0,0,0,0,0,0,0,0,0,0,0,0,0,0,0
