# Ancient Warfare Structure Template File
# Auto-generated structure template file. created on: 8/19/2019 at: 10:23:11
# Lines beginning with # denote comments

header:
version=2.9
name=EmpireVillageChurch
mods=
size=23,23,18
offset=9,8,17
:endheader

#### VALIDATION ####
validation:
type=ground
survival=false
worldGenEnabled=true
unique=false
preserveBlocks=false
selectionWeight=50
clusterValue=30
minDuplicateDistance=1000
dimensionWhiteList=true
dimensionList=0
biomeWhiteList=true
biomeList=biomesoplenty:meadow,traverse:meadow,minecraft:plains
leveling=6
fill=6
border=5
blockSwap=false
:endvalidation

#### LAYERS ####
layer: 0
1,1,1,1,1,1,1,1,1,1,1,1,1,1,1,1,1,1,1,1,1,1,1
1,1,1,1,1,1,1,1,1,1,1,1,1,1,1,1,1,1,1,1,1,1,1
1,1,1,1,1,1,1,1,1,1,1,1,1,1,1,1,1,1,1,1,1,1,1
1,1,1,1,1,1,1,1,1,1,1,1,1,1,2,2,3,3,2,2,1,1,1
1,1,1,1,1,1,1,1,1,1,1,1,1,1,2,2,2,2,2,2,1,1,1
1,1,1,1,1,1,1,1,1,1,1,1,1,1,2,2,2,2,2,2,1,1,1
1,1,1,1,1,1,1,1,1,1,1,1,1,1,2,2,2,2,2,2,1,1,1
1,1,1,1,1,1,1,1,1,1,1,1,1,1,2,2,2,3,2,2,1,1,1
1,1,1,1,1,1,1,1,1,1,1,1,1,1,2,2,2,2,2,2,1,1,1
1,1,1,1,1,1,1,1,1,1,1,1,1,1,2,2,4,2,2,2,1,1,1
1,1,1,1,1,1,1,1,1,1,1,1,1,1,2,2,2,2,2,2,1,1,1
1,1,1,1,1,1,1,1,1,1,1,1,1,1,2,2,2,2,2,2,1,1,1
1,1,1,1,1,1,1,1,1,1,1,1,1,1,1,1,1,1,1,1,1,1,1
1,1,1,1,1,1,1,1,1,1,1,1,1,1,1,1,1,1,1,1,1,1,1
1,1,1,1,1,1,1,1,1,1,1,1,1,1,1,1,1,1,1,1,1,1,1
1,1,1,1,1,1,1,1,1,1,1,1,1,1,1,1,1,1,1,1,1,1,1
1,1,1,1,1,1,1,1,1,1,1,1,1,1,1,1,1,1,1,1,1,1,1
1,1,1,1,1,1,1,1,1,1,1,1,1,1,1,1,1,1,1,1,1,1,1
:endlayer
layer: 1
1,1,1,1,1,1,1,1,1,1,1,1,1,1,1,1,1,1,1,1,1,1,1
1,1,1,1,1,1,1,1,1,1,1,1,1,1,1,1,1,1,1,1,1,1,1
1,1,1,1,1,1,1,1,1,1,1,1,1,1,1,1,1,1,1,1,1,1,1
1,1,1,1,1,1,1,1,1,1,1,1,1,1,3,3,3,3,3,3,1,1,1
1,1,1,1,1,1,1,1,1,1,1,1,1,1,3,5,5,5,6,3,1,1,1
1,1,1,1,1,1,1,1,1,1,1,1,1,1,3,0,0,0,5,3,1,1,1
1,1,1,1,1,1,1,1,1,1,1,1,1,1,3,0,0,0,0,3,1,1,1
1,1,1,1,1,1,1,1,1,1,1,1,1,1,3,7,0,0,0,3,1,1,1
1,1,1,1,1,1,1,1,1,1,1,1,1,1,3,0,0,0,0,3,1,1,1
1,1,1,1,1,1,1,1,1,1,1,1,1,1,3,5,0,0,0,3,1,1,1
1,1,1,1,1,1,1,1,1,1,1,1,1,1,3,8,5,5,5,3,1,1,1
1,1,1,1,1,1,1,1,1,1,1,1,1,1,3,3,3,3,3,3,1,1,1
1,1,1,1,1,1,1,1,1,1,1,1,1,1,1,1,1,1,1,1,1,1,1
1,1,1,1,1,1,1,1,1,1,1,1,1,1,1,1,1,1,1,1,1,1,1
1,1,1,1,1,1,1,1,1,1,1,1,1,1,1,1,1,1,1,1,1,1,1
1,1,1,1,1,1,1,1,1,1,1,1,1,1,1,1,1,1,1,1,1,1,1
1,1,1,1,1,1,1,1,1,1,1,1,1,1,1,1,1,1,1,1,1,1,1
1,1,1,1,1,1,1,1,1,1,1,1,1,1,1,1,1,1,1,1,1,1,1
:endlayer
layer: 2
1,1,1,1,1,1,1,1,1,1,1,1,1,1,1,1,1,1,1,1,1,1,1
1,1,1,1,1,1,1,1,1,1,1,1,1,1,1,1,1,1,1,1,1,1,1
1,1,1,1,1,1,1,1,1,1,1,1,1,1,1,1,1,1,1,1,1,1,1
1,1,1,1,1,1,1,1,1,1,1,1,1,1,3,2,3,3,2,3,1,1,1
1,1,1,1,1,1,1,1,1,1,1,1,1,1,3,5,0,9,5,3,1,1,1
1,1,1,1,1,1,1,1,1,1,1,1,1,1,3,10,0,0,10,2,1,1,1
1,1,1,1,1,1,1,1,1,1,1,1,1,1,3,10,0,0,10,3,1,1,1
1,1,1,1,1,1,1,1,1,1,1,1,1,1,2,10,0,0,10,3,1,1,1
1,1,1,1,1,1,1,1,1,1,1,1,1,1,3,10,0,0,10,3,1,1,1
1,1,1,1,1,1,1,1,1,1,1,1,1,1,2,10,0,0,10,3,1,1,1
1,1,1,1,1,1,1,1,1,1,1,1,1,1,3,5,11,12,5,3,1,1,1
1,1,1,1,1,1,1,1,1,1,1,1,1,1,3,3,3,2,3,3,1,1,1
1,1,1,1,1,1,1,1,1,1,1,1,1,1,1,1,1,1,1,1,1,1,1
1,1,1,1,1,1,1,1,1,1,1,1,1,1,1,1,1,1,1,1,1,1,1
1,1,1,1,1,1,1,1,1,1,1,1,1,1,1,1,1,1,1,1,1,1,1
1,1,1,1,1,1,1,1,1,1,1,1,1,1,1,1,1,1,1,1,1,1,1
1,1,1,1,1,1,1,1,1,1,1,1,1,1,1,1,1,1,1,1,1,1,1
1,1,1,1,1,1,1,1,1,1,1,1,1,1,1,1,1,1,1,1,1,1,1
:endlayer
layer: 3
1,1,1,1,1,1,1,1,1,1,1,1,1,1,1,1,1,1,1,1,1,1,1
1,1,1,1,1,1,1,1,1,1,1,1,1,1,1,1,1,1,1,1,1,1,1
1,1,1,1,1,1,1,1,1,1,1,1,1,1,1,1,1,1,1,1,1,1,1
1,1,1,1,1,1,1,1,1,1,1,1,1,1,3,3,3,3,2,3,1,1,1
1,1,1,1,1,1,1,1,1,1,1,1,1,1,3,0,0,0,13,3,1,1,1
1,1,1,1,1,1,1,1,1,1,1,1,1,1,3,14,0,0,0,3,1,1,1
1,1,1,1,1,1,1,1,1,1,1,1,1,1,4,0,0,0,0,3,1,1,1
1,1,1,1,1,1,1,1,1,1,1,1,1,1,3,15,0,0,16,3,1,1,1
1,1,1,1,1,1,1,1,1,1,1,1,1,1,2,0,0,0,0,3,1,1,1
1,1,1,1,1,1,1,1,1,1,1,1,1,1,3,0,0,0,0,3,1,1,1
1,1,1,1,1,1,1,1,1,1,1,1,1,1,3,17,0,0,18,3,1,1,1
1,1,1,1,1,1,1,1,1,1,1,1,1,1,3,3,2,3,3,3,1,1,1
1,1,1,1,1,1,1,1,1,1,1,1,1,1,1,1,1,1,1,1,1,1,1
1,1,1,1,1,1,1,1,1,1,1,1,1,1,1,1,1,1,1,1,1,1,1
1,1,1,1,1,1,1,1,1,1,1,1,1,1,1,1,1,1,1,1,1,1,1
1,1,1,1,1,1,1,1,1,1,1,1,1,1,1,1,1,1,1,1,1,1,1
1,1,1,1,1,1,1,1,1,1,1,1,1,1,1,1,1,1,1,1,1,1,1
1,1,1,1,1,1,1,1,1,1,1,1,1,1,1,1,1,1,1,1,1,1,1
:endlayer
layer: 4
1,1,1,1,1,1,1,1,1,1,1,1,1,1,1,1,1,1,1,1,1,1,1
1,1,1,1,1,1,1,1,1,1,1,1,1,1,1,1,1,1,1,1,1,1,1
1,1,1,1,1,1,1,1,1,1,1,1,1,1,1,1,1,1,1,1,1,1,1
1,1,1,1,1,1,1,1,1,1,1,1,1,1,3,3,3,3,3,3,1,1,1
1,1,1,1,1,1,1,1,1,1,1,1,1,1,3,3,3,3,3,3,1,1,1
1,1,1,1,1,1,1,1,1,1,1,1,1,1,4,4,3,3,3,3,1,1,1
1,1,1,1,1,1,1,1,1,1,1,1,1,1,4,3,3,4,3,3,1,1,1
1,1,1,1,1,1,1,1,1,1,1,1,1,1,3,3,3,3,3,3,1,1,1
1,1,1,1,1,1,1,1,1,1,1,1,1,1,3,3,3,4,3,3,1,1,1
1,1,1,1,1,1,1,1,1,1,1,1,1,1,3,3,3,19,3,3,1,1,1
1,1,1,1,1,1,1,1,1,1,1,1,1,1,3,3,3,3,3,3,1,1,1
1,1,1,1,1,1,1,1,1,1,1,1,1,1,3,3,3,3,3,3,1,1,1
1,1,1,1,1,1,1,1,1,1,1,1,1,1,1,1,1,1,1,1,1,1,1
1,1,1,1,1,1,1,1,1,1,1,1,1,1,1,1,1,1,1,1,1,1,1
1,1,1,1,1,1,1,1,1,1,1,1,1,1,1,1,1,1,1,1,1,1,1
1,1,1,1,1,1,1,1,1,1,1,1,1,1,1,1,1,1,1,1,1,1,1
1,1,1,1,1,1,1,1,1,1,1,1,1,1,1,1,1,1,1,1,1,1,1
1,1,1,1,1,1,1,1,1,1,1,1,1,1,1,1,1,1,1,1,1,1,1
:endlayer
layer: 5
20,20,20,20,20,20,20,20,20,20,20,20,20,20,20,20,20,20,20,20,20,20,20
20,20,20,20,20,20,20,20,20,20,20,20,20,20,20,20,20,20,20,20,20,20,20
20,20,20,20,20,20,20,20,20,20,20,20,20,20,20,20,20,20,20,20,20,20,20
20,20,20,20,20,20,20,20,20,20,20,20,20,20,3,3,3,3,3,3,20,20,20
20,20,20,20,20,20,20,20,20,20,20,20,20,20,3,10,10,10,10,3,20,20,20
20,20,20,20,20,20,20,20,20,20,20,20,20,20,3,0,0,0,10,3,20,20,20
20,20,20,20,20,20,20,20,20,20,20,20,20,20,3,0,21,0,10,3,20,20,20
20,20,20,20,20,20,20,20,20,20,20,20,20,20,3,0,0,0,10,3,20,20,20
20,20,20,20,20,20,20,20,20,20,20,20,20,20,3,0,0,0,10,3,20,20,20
20,20,20,20,20,20,20,20,20,20,20,20,20,20,3,22,3,10,3,3,20,20,20
20,20,20,20,20,20,20,20,20,20,20,20,20,20,3,0,3,3,3,3,20,20,20
20,20,20,20,20,20,20,20,20,20,20,20,20,20,3,23,3,3,3,3,20,20,20
20,20,20,20,20,20,20,20,20,20,20,20,20,20,3,20,20,20,20,20,20,20,20
20,20,20,20,20,20,20,20,20,20,20,20,20,20,20,20,20,20,20,20,20,20,20
20,20,20,20,20,20,20,20,20,20,20,20,20,20,20,20,20,20,20,20,20,20,20
20,20,20,20,20,20,20,20,20,20,20,20,20,20,20,20,20,20,20,20,20,20,20
20,20,20,20,20,20,20,20,20,20,20,20,20,20,20,20,20,20,20,20,20,20,20
20,20,20,20,20,20,20,20,20,20,20,20,20,20,20,20,20,20,20,20,20,20,20
:endlayer
layer: 6
20,20,20,20,20,20,20,20,20,20,20,20,20,20,20,20,20,20,20,20,20,20,20
20,20,20,20,20,20,20,20,20,20,20,20,20,20,20,20,20,20,20,20,20,20,20
20,20,20,20,20,20,20,20,20,20,20,20,20,20,20,20,20,20,20,20,20,20,20
20,20,20,20,20,20,20,20,20,20,20,20,20,20,3,3,3,3,3,3,20,20,20
20,20,20,20,20,20,20,20,20,20,20,20,20,20,3,24,25,0,26,3,20,20,20
20,20,20,20,20,20,20,20,20,20,20,20,20,20,3,0,0,0,0,3,20,20,20
20,20,20,20,20,20,20,20,20,20,20,20,20,20,3,0,0,0,0,3,20,20,20
20,20,20,20,20,20,20,20,20,20,20,20,20,20,3,0,0,0,27,3,20,20,20
20,20,20,20,20,20,20,20,20,20,20,20,20,20,3,0,0,0,0,3,20,20,20
20,20,20,20,20,20,20,20,20,20,20,20,20,20,3,28,3,29,3,3,20,20,20
20,20,20,20,20,20,20,20,20,20,20,20,20,20,3,0,3,3,3,3,20,20,20
20,20,20,20,20,20,20,20,20,20,20,20,20,20,3,0,3,3,3,3,20,20,20
20,20,20,20,20,20,20,20,20,20,20,20,20,20,3,23,3,20,20,20,20,20,20
20,20,20,20,20,20,20,20,20,20,20,20,20,20,20,20,3,20,20,20,20,20,20
20,20,20,20,20,20,20,20,20,20,20,20,20,20,20,20,20,20,20,20,20,20,20
20,20,20,20,20,20,20,20,20,20,20,20,20,20,20,20,20,20,20,20,20,20,20
20,20,20,20,20,20,20,20,20,20,20,20,20,20,20,20,20,20,20,20,20,20,20
20,20,20,20,20,20,20,20,20,20,20,20,20,20,20,20,20,20,20,20,20,20,20
:endlayer
layer: 7
30,30,30,30,30,30,30,30,30,30,30,30,30,30,30,30,30,30,30,30,30,30,30
30,30,30,30,30,30,30,30,30,30,30,30,30,30,30,3,30,30,30,20,30,30,30
30,30,30,20,30,30,30,20,30,30,30,31,30,30,3,3,3,3,3,3,3,30,30
30,30,30,30,30,30,30,30,30,30,30,31,30,20,3,3,3,3,3,3,20,20,30
30,30,30,30,30,30,30,30,30,30,30,31,30,30,3,0,0,0,0,3,20,30,30
30,30,30,30,30,30,30,30,30,30,30,31,30,30,3,0,0,0,0,3,20,30,30
30,30,30,30,30,30,30,30,30,30,30,31,30,20,3,0,0,0,0,3,20,20,30
30,30,30,30,30,30,30,30,30,30,30,31,31,30,3,0,0,0,0,3,20,30,30
30,30,30,30,30,30,30,30,30,30,30,31,31,30,3,32,0,0,0,3,20,30,30
30,30,30,30,30,30,30,30,30,30,30,30,31,20,3,3,3,3,3,3,20,20,30
30,30,30,30,30,30,30,30,30,30,30,30,31,30,3,33,3,3,3,3,20,30,30
30,30,30,30,30,30,30,30,30,30,30,30,31,30,3,0,3,3,3,3,20,30,30
30,30,30,30,30,30,30,30,30,30,30,30,31,20,3,0,3,20,20,3,20,20,30
30,30,30,30,30,30,30,30,30,30,30,30,31,30,3,23,3,20,20,31,20,30,30
30,30,30,30,20,30,30,30,30,30,30,30,31,30,30,31,3,20,20,31,30,30,30
30,30,20,30,30,30,30,30,30,30,30,30,31,31,31,31,20,20,20,31,30,30,30
30,30,30,30,30,30,30,30,30,30,30,30,30,30,30,31,30,30,30,31,30,20,30
30,30,30,30,30,30,30,30,30,30,30,30,30,30,30,31,31,31,31,31,30,30,30
:endlayer
layer: 8
34,0,34,0,0,0,0,0,0,0,0,34,0,34,34,0,0,0,0,0,34,0,0
0,34,34,34,34,0,0,0,0,0,0,0,34,34,34,3,0,0,0,3,0,0,0
0,34,34,35,0,0,0,35,0,0,0,0,34,34,3,3,3,3,3,3,3,0,0
0,36,36,36,36,36,36,37,36,37,36,38,36,3,3,3,3,3,3,3,3,3,0
0,37,0,0,0,0,0,0,0,0,34,0,34,34,3,3,3,3,3,3,3,0,0
0,37,34,0,34,34,34,0,0,0,34,0,0,34,3,3,3,3,3,3,3,0,0
0,36,34,34,34,0,34,0,0,0,34,0,34,3,3,3,3,3,3,3,3,3,34
0,37,34,37,39,39,0,37,39,39,34,0,0,34,3,3,3,3,3,3,3,34,34
34,36,0,37,39,39,0,37,39,39,0,0,0,0,3,3,3,3,3,3,3,34,34
34,37,0,0,34,0,0,0,0,0,0,0,0,3,3,3,3,3,3,3,3,3,0
34,36,0,37,39,39,0,0,34,0,0,0,0,0,3,40,3,3,3,3,3,0,0
34,37,34,37,39,39,0,37,39,39,34,0,0,0,3,0,3,3,3,3,3,0,0
0,36,34,0,34,0,34,37,39,39,34,0,0,3,3,0,3,3,3,3,3,3,0
0,36,0,37,39,39,0,34,34,0,0,41,0,0,3,0,3,3,3,0,3,0,0
0,36,0,37,39,39,34,36,39,39,0,34,0,0,36,0,3,3,3,0,34,34,34
0,37,42,0,0,0,0,34,0,34,34,34,0,0,43,0,3,3,3,0,0,34,34
0,37,37,36,37,36,36,37,37,36,37,36,36,36,36,0,44,44,44,0,0,3,34
0,0,0,0,0,0,0,34,0,0,34,34,34,34,0,0,0,0,0,0,0,0,0
:endlayer
layer: 9
0,0,0,0,0,0,0,0,0,0,0,0,0,0,0,0,0,0,0,0,0,0,0
0,0,0,0,0,0,0,0,0,0,0,0,0,0,0,3,0,0,0,3,0,0,0
0,0,0,35,0,0,0,35,0,0,0,0,0,0,3,3,3,3,3,3,3,0,0
0,45,0,0,0,0,0,0,0,0,45,0,45,3,3,3,3,3,3,3,3,3,0
0,0,0,0,0,0,0,0,0,0,0,0,0,0,3,3,3,3,3,3,3,0,0
0,0,0,0,0,0,0,0,0,0,0,0,0,0,3,3,3,3,3,3,3,0,0
0,0,0,0,0,0,0,0,0,0,0,0,0,3,3,3,3,3,3,3,3,3,0
0,0,0,36,0,0,0,36,0,0,0,0,0,0,3,3,3,3,3,3,3,0,0
0,0,0,36,0,0,0,36,0,0,0,0,0,0,3,3,3,3,3,3,3,0,0
0,0,0,0,0,0,0,0,0,0,0,0,0,3,3,3,3,3,3,3,3,3,0
0,0,0,36,0,0,0,0,0,0,0,0,0,0,3,3,3,3,3,3,3,0,0
0,0,0,36,0,0,0,36,0,0,0,0,0,0,3,40,3,3,3,3,3,0,0
0,0,0,0,0,0,0,36,0,0,0,0,0,3,3,0,3,3,3,3,3,3,0
0,0,0,36,0,0,0,0,0,0,0,0,0,0,3,0,3,3,3,0,3,0,0
0,0,0,37,0,0,0,36,0,0,0,0,0,0,45,0,3,3,3,0,0,0,0
0,0,42,0,0,0,0,0,0,0,0,0,0,0,0,0,44,44,44,0,0,0,0
0,45,0,0,0,0,0,0,0,0,0,0,0,0,45,0,0,0,0,0,0,46,0
0,0,0,0,0,0,0,0,0,0,0,0,0,0,0,0,0,0,0,0,0,0,0
:endlayer
layer: 10
0,0,47,47,47,47,47,47,47,47,0,0,0,0,0,0,0,0,0,0,0,0,0
0,47,47,47,47,47,47,47,47,47,0,0,0,0,0,3,0,0,0,3,0,0,0
0,47,47,35,47,47,47,35,47,47,0,0,0,0,3,3,3,3,3,3,3,0,0
0,0,47,47,47,47,47,47,47,47,0,0,0,3,3,3,3,3,3,3,3,3,0
0,0,47,47,47,47,47,47,47,47,0,0,0,0,3,3,3,3,3,3,3,0,0
0,0,0,0,0,0,0,0,0,0,0,0,0,0,3,3,3,3,3,3,3,0,0
0,0,0,0,0,0,0,0,0,0,0,0,0,3,3,3,3,3,3,3,3,3,0
0,0,0,0,0,0,0,0,0,0,0,0,0,0,3,3,3,3,3,3,3,0,0
0,0,0,0,0,0,0,0,0,0,0,0,0,0,3,3,3,3,3,3,3,0,0
0,0,0,0,0,0,0,0,0,0,0,0,0,3,3,3,3,3,3,3,3,3,0
0,0,0,0,0,0,0,0,0,0,0,0,0,0,3,3,3,3,3,3,3,0,0
0,0,0,0,0,0,0,0,0,0,0,0,0,0,3,3,3,3,3,3,3,0,0
0,0,0,0,0,0,0,0,0,0,0,0,0,3,3,3,3,3,3,3,3,3,0
0,0,0,0,0,0,0,0,0,0,0,0,0,0,3,40,3,3,3,40,3,0,0
0,0,0,0,0,0,0,0,0,0,0,0,0,0,0,0,44,44,44,0,0,0,0
0,0,42,0,0,0,0,0,0,0,0,0,0,0,0,0,0,0,0,0,0,0,0
0,0,0,0,0,0,0,0,0,0,0,0,0,0,0,0,0,0,0,0,0,0,0
0,0,0,0,0,0,0,0,0,0,0,0,0,0,0,0,0,0,0,0,0,0,0
:endlayer
layer: 11
0,47,47,47,47,47,47,47,47,47,0,0,0,0,0,0,0,0,0,0,0,0,0
0,47,47,47,47,47,47,47,47,47,0,0,0,0,0,48,0,0,0,48,0,0,0
0,47,47,35,47,47,47,35,47,47,0,0,0,0,3,3,3,3,3,3,3,0,0
0,47,47,47,47,47,47,47,47,47,0,0,0,49,3,50,0,1,0,51,3,52,0
0,0,47,47,47,47,47,47,47,47,0,0,0,0,3,0,0,53,0,0,3,0,0
0,0,0,0,0,0,0,0,0,0,0,0,0,0,3,54,54,0,54,54,3,0,0
0,0,0,0,0,0,0,0,0,0,0,0,0,49,3,55,0,0,0,56,3,52,0
0,0,0,0,0,0,0,0,0,0,0,0,0,0,3,54,54,0,54,54,3,0,0
0,0,0,0,0,0,0,0,0,0,0,0,0,0,3,57,0,0,0,58,3,0,0
0,0,0,0,0,0,0,0,0,0,0,0,0,49,3,54,54,0,54,54,3,52,0
0,0,0,0,0,0,0,0,0,0,0,0,0,0,3,3,3,0,4,4,3,0,0
0,0,0,0,0,0,0,0,0,0,0,0,0,0,3,59,0,0,49,4,3,0,0
0,0,0,0,0,0,0,0,0,0,0,0,0,49,3,3,3,60,3,3,3,52,0
0,61,61,61,0,0,0,0,0,0,0,0,0,0,44,37,3,0,3,37,44,0,0
61,61,61,61,61,0,0,0,0,0,0,0,0,0,0,0,0,0,0,0,0,0,0
61,61,42,61,61,0,0,0,0,0,0,0,0,0,0,0,0,0,0,0,0,0,0
61,61,61,61,61,0,0,0,0,0,0,0,0,0,0,0,0,0,0,0,0,0,0
0,61,61,61,0,0,0,0,0,0,0,0,0,0,0,0,0,0,0,0,0,0,0
:endlayer
layer: 12
0,0,0,0,0,0,0,0,0,0,0,0,0,0,0,0,0,0,0,0,0,0,0
0,0,47,47,0,0,47,47,47,0,0,0,0,0,0,0,0,0,0,0,0,0,0
0,0,47,35,47,0,47,35,47,0,0,0,0,0,3,3,62,62,62,3,3,0,0
0,0,47,47,47,0,47,47,0,0,0,0,0,0,3,0,0,63,0,0,3,0,0
0,0,0,0,0,0,0,0,0,0,0,0,0,0,3,0,0,0,0,0,3,0,0
0,0,0,0,0,0,0,0,0,0,0,0,0,0,64,0,0,0,0,0,64,0,0
0,0,0,0,0,0,0,0,0,0,0,0,0,0,3,0,0,0,0,0,3,0,0
0,0,0,0,0,0,0,0,0,0,0,0,0,0,64,0,0,0,0,0,64,0,0
0,0,0,0,0,0,0,0,0,0,0,0,0,0,3,0,0,0,0,0,3,0,0
0,0,0,0,0,0,0,0,0,0,0,0,0,0,64,0,0,0,0,0,64,0,0
0,0,0,0,0,0,0,0,0,0,0,0,0,0,3,3,3,0,3,4,3,0,0
0,0,0,0,0,0,0,0,0,0,0,0,0,0,3,0,0,0,0,49,3,0,0
0,0,0,0,0,0,0,0,0,0,0,0,0,0,3,3,3,65,3,3,3,0,0
0,61,61,61,61,0,0,0,0,0,0,0,0,0,0,45,3,0,3,45,0,0,0
61,61,61,61,61,0,0,0,0,0,0,0,0,0,0,0,0,0,0,0,0,0,0
61,61,42,61,61,0,0,0,0,0,0,0,0,0,0,0,0,0,0,0,0,0,0
61,61,61,61,61,0,0,0,0,0,0,0,0,0,0,0,0,0,0,0,0,0,0
0,61,61,61,61,0,0,0,0,0,0,0,0,0,0,0,0,0,0,0,0,0,0
:endlayer
layer: 13
0,0,0,0,0,0,0,0,0,0,0,0,0,0,0,0,0,0,0,0,0,0,0
0,0,0,47,0,0,0,47,0,0,0,0,0,0,0,0,0,0,0,0,0,0,0
0,0,47,47,47,0,47,47,47,0,0,0,0,0,3,3,62,66,62,3,3,0,0
0,0,0,47,0,0,0,47,0,0,0,0,0,0,3,0,0,0,0,0,3,0,0
0,0,0,0,0,0,0,0,0,0,0,0,0,0,3,0,0,0,0,0,3,0,0
0,0,0,0,0,0,0,0,0,0,0,0,0,0,64,0,0,0,0,0,64,0,0
0,0,0,0,0,0,0,0,0,0,0,0,0,0,3,0,0,0,0,0,3,0,0
0,0,0,0,0,0,0,0,0,0,0,0,0,0,64,0,0,0,0,0,64,0,0
0,0,0,0,0,0,0,0,0,0,0,0,0,0,3,0,0,0,0,0,3,0,0
0,0,0,0,0,0,0,0,0,0,0,0,0,0,64,0,0,0,0,0,64,0,0
0,0,0,0,0,0,0,0,0,0,0,0,0,0,3,3,3,0,3,44,3,0,0
0,0,0,0,0,0,0,0,0,0,0,0,0,0,3,0,0,0,0,0,3,0,0
0,0,0,0,0,0,0,0,0,0,0,0,0,0,3,3,3,3,3,3,3,0,0
0,0,0,0,0,0,0,0,0,0,0,0,0,0,0,0,3,3,3,0,0,0,0
0,0,61,61,0,0,0,0,0,0,0,0,0,0,0,0,67,0,67,0,0,0,0
0,61,42,61,0,0,0,0,0,0,0,0,0,0,0,0,0,0,0,0,0,0,0
0,0,61,61,0,0,0,0,0,0,0,0,0,0,0,0,0,0,0,0,0,0,0
0,0,0,0,0,0,0,0,0,0,0,0,0,0,0,0,0,0,0,0,0,0,0
:endlayer
layer: 14
0,0,0,0,0,0,0,0,0,0,0,0,0,0,0,0,0,0,0,0,0,0,0
0,0,0,0,0,0,0,0,0,0,0,0,0,68,0,0,0,0,0,0,0,69,0
0,0,0,0,0,0,0,0,0,0,0,0,0,68,3,3,62,62,62,3,3,69,0
0,0,0,0,0,0,0,0,0,0,0,0,0,68,3,67,0,0,0,67,3,69,0
0,0,0,0,0,0,0,0,0,0,0,0,0,68,3,0,0,0,0,0,3,69,0
0,0,0,0,0,0,0,0,0,0,0,0,0,68,3,0,0,0,0,0,3,69,0
0,0,0,0,0,0,0,0,0,0,0,0,0,68,3,70,0,0,0,71,3,69,0
0,0,0,0,0,0,0,0,0,0,0,0,0,68,3,0,0,0,0,0,3,69,0
0,0,0,0,0,0,0,0,0,0,0,0,0,68,3,72,72,72,72,72,3,69,0
0,0,0,0,0,0,0,0,0,0,0,0,0,68,3,3,3,3,3,44,3,69,0
0,0,0,0,0,0,0,0,0,0,0,0,0,68,3,3,3,4,3,0,3,69,0
0,0,0,0,0,0,0,0,0,0,0,0,0,68,3,3,3,3,0,0,3,69,0
0,0,0,0,0,0,0,0,0,0,0,0,0,68,3,3,3,3,3,3,3,69,0
0,0,0,0,0,0,0,0,0,0,0,0,0,73,73,73,3,3,3,73,73,73,0
0,0,61,0,0,0,0,0,0,0,0,0,0,0,0,68,73,73,73,69,0,0,0
0,61,61,61,0,0,0,0,0,0,0,0,0,0,0,0,0,0,0,0,0,0,0
0,0,61,0,0,0,0,0,0,0,0,0,0,0,0,0,0,0,0,0,0,0,0
0,0,0,0,0,0,0,0,0,0,0,0,0,0,0,0,0,0,0,0,0,0,0
:endlayer
layer: 15
0,0,0,0,0,0,0,0,0,0,0,0,0,0,0,0,0,0,0,0,0,0,0
0,0,0,0,0,0,0,0,0,0,0,0,0,0,68,0,0,0,0,0,69,0,0
0,0,0,0,0,0,0,0,0,0,0,0,0,0,68,3,3,74,3,3,69,0,0
0,0,0,0,0,0,0,0,0,0,0,0,0,0,68,75,0,0,0,75,69,0,0
0,0,0,0,0,0,0,0,0,0,0,0,0,0,68,75,0,0,0,75,69,0,0
0,0,0,0,0,0,0,0,0,0,0,0,0,0,68,75,0,0,0,75,69,0,0
0,0,0,0,0,0,0,0,0,0,0,0,0,0,68,75,0,0,0,75,69,0,0
0,0,0,0,0,0,0,0,0,0,0,0,0,0,68,75,0,0,0,75,69,0,0
0,0,0,0,0,0,0,0,0,0,0,0,0,0,3,3,76,76,76,3,3,0,0
0,0,0,0,0,0,0,0,0,0,0,0,0,0,3,0,0,0,0,0,3,0,0
0,0,0,0,0,0,0,0,0,0,0,0,0,0,3,0,77,0,0,0,3,0,0
0,0,0,0,0,0,0,0,0,0,0,0,0,0,3,0,0,0,0,0,3,0,0
0,0,0,0,0,0,0,0,0,0,0,0,0,0,3,3,0,0,78,3,3,0,0
0,0,0,0,0,0,0,0,0,0,0,0,0,0,0,0,3,3,3,0,0,0,0
0,0,0,0,0,0,0,0,0,0,0,0,0,0,0,0,0,0,0,0,0,0,0
0,0,0,0,0,0,0,0,0,0,0,0,0,0,0,0,0,0,0,0,0,0,0
0,0,0,0,0,0,0,0,0,0,0,0,0,0,0,0,0,0,0,0,0,0,0
0,0,0,0,0,0,0,0,0,0,0,0,0,0,0,0,0,0,0,0,0,0,0
:endlayer
layer: 16
0,0,0,0,0,0,0,0,0,0,0,0,0,0,0,0,0,0,0,0,0,0,0
0,0,0,0,0,0,0,0,0,0,0,0,0,0,0,68,0,0,0,69,0,0,0
0,0,0,0,0,0,0,0,0,0,0,0,0,0,0,68,3,3,3,69,0,0,0
0,0,0,0,0,0,0,0,0,0,0,0,0,0,0,68,0,67,0,69,0,0,0
0,0,0,0,0,0,0,0,0,0,0,0,0,0,0,68,0,0,0,69,0,0,0
0,0,0,0,0,0,0,0,0,0,0,0,0,0,0,68,0,0,0,69,0,0,0
0,0,0,0,0,0,0,0,0,0,0,0,0,0,0,68,0,0,0,69,0,0,0
0,0,0,0,0,0,0,0,0,0,0,0,0,0,0,68,0,0,0,69,0,0,0
0,0,0,0,0,0,0,0,0,0,0,0,0,0,0,3,0,0,0,3,0,0,0
0,0,0,0,0,0,0,0,0,0,0,0,0,0,3,0,0,0,0,0,3,0,0
0,0,0,0,0,0,0,0,0,0,0,0,0,0,74,0,0,0,0,0,74,0,0
0,0,0,0,0,0,0,0,0,0,0,0,0,0,3,0,0,0,0,0,3,0,0
0,0,0,0,0,0,0,0,0,0,0,0,0,0,0,3,0,0,78,3,0,0,0
0,0,0,0,0,0,0,0,0,0,0,0,0,0,0,0,3,74,3,0,0,0,0
0,0,0,0,0,0,0,0,0,0,0,0,0,0,0,0,0,0,0,0,0,0,0
0,0,0,0,0,0,0,0,0,0,0,0,0,0,0,0,0,0,0,0,0,0,0
0,0,0,0,0,0,0,0,0,0,0,0,0,0,0,0,0,0,0,0,0,0,0
0,0,0,0,0,0,0,0,0,0,0,0,0,0,0,0,0,0,0,0,0,0,0
:endlayer
layer: 17
0,0,0,0,0,0,0,0,0,0,0,0,0,0,0,0,0,0,0,0,0,0,0
0,0,0,0,0,0,0,0,0,0,0,0,0,0,0,0,68,0,69,0,0,0,0
0,0,0,0,0,0,0,0,0,0,0,0,0,0,0,0,68,3,69,0,0,0,0
0,0,0,0,0,0,0,0,0,0,0,0,0,0,0,0,68,75,69,0,0,0,0
0,0,0,0,0,0,0,0,0,0,0,0,0,0,0,0,68,75,69,0,0,0,0
0,0,0,0,0,0,0,0,0,0,0,0,0,0,0,0,68,75,69,0,0,0,0
0,0,0,0,0,0,0,0,0,0,0,0,0,0,0,0,68,75,69,0,0,0,0
0,0,0,0,0,0,0,0,0,0,0,0,0,0,0,0,4,3,3,0,0,0,0
0,0,0,0,0,0,0,0,0,0,0,0,0,0,0,3,0,0,0,3,0,0,0
0,0,0,0,0,0,0,0,0,0,0,0,0,0,3,0,0,0,0,0,3,0,0
0,0,0,0,0,0,0,0,0,0,0,0,0,0,74,0,0,0,0,0,74,0,0
0,0,0,0,0,0,0,0,0,0,0,0,0,0,3,0,0,0,0,0,3,0,0
0,0,0,0,0,0,0,0,0,0,0,0,0,0,0,3,0,0,78,3,0,0,0
0,0,0,0,0,0,0,0,0,0,0,0,0,0,0,0,3,74,3,0,0,0,0
0,0,0,0,0,0,0,0,0,0,0,0,0,0,0,0,0,0,0,0,0,0,0
0,0,0,0,0,0,0,0,0,0,0,0,0,0,0,0,0,0,0,0,0,0,0
0,0,0,0,0,0,0,0,0,0,0,0,0,0,0,0,0,0,0,0,0,0,0
0,0,0,0,0,0,0,0,0,0,0,0,0,0,0,0,0,0,0,0,0,0,0
:endlayer
layer: 18
0,0,0,0,0,0,0,0,0,0,0,0,0,0,0,0,0,0,0,0,0,0,0
0,0,0,0,0,0,0,0,0,0,0,0,0,0,0,0,0,79,0,0,0,0,0
0,0,0,0,0,0,0,0,0,0,0,0,0,0,0,0,0,79,0,0,0,0,0
0,0,0,0,0,0,0,0,0,0,0,0,0,0,0,0,0,79,0,0,0,0,0
0,0,0,0,0,0,0,0,0,0,0,0,0,0,0,0,0,79,0,0,0,0,0
0,0,0,0,0,0,0,0,0,0,0,0,0,0,0,0,0,79,0,0,0,0,0
0,0,0,0,0,0,0,0,0,0,0,0,0,0,0,0,0,79,0,0,0,0,0
0,0,0,0,0,0,0,0,0,0,0,0,0,0,0,0,3,3,3,0,0,0,0
0,0,0,0,0,0,0,0,0,0,0,0,0,0,0,3,0,67,0,3,0,0,0
0,0,0,0,0,0,0,0,0,0,0,0,0,0,3,0,0,0,0,0,3,0,0
0,0,0,0,0,0,0,0,0,0,0,0,0,0,74,0,0,0,0,0,74,0,0
0,0,0,0,0,0,0,0,0,0,0,0,0,0,3,0,0,0,0,0,3,0,0
0,0,0,0,0,0,0,0,0,0,0,0,0,0,0,3,0,0,78,3,0,0,0
0,0,0,0,0,0,0,0,0,0,0,0,0,0,0,0,3,74,3,0,0,0,0
0,0,0,0,0,0,0,0,0,0,0,0,0,0,0,0,0,0,0,0,0,0,0
0,0,0,0,0,0,0,0,0,0,0,0,0,0,0,0,0,0,0,0,0,0,0
0,0,0,0,0,0,0,0,0,0,0,0,0,0,0,0,0,0,0,0,0,0,0
0,0,0,0,0,0,0,0,0,0,0,0,0,0,0,0,0,0,0,0,0,0,0
:endlayer
layer: 19
0,0,0,0,0,0,0,0,0,0,0,0,0,0,0,0,0,0,0,0,0,0,0
0,0,0,0,0,0,0,0,0,0,0,0,0,0,0,0,0,0,0,0,0,0,0
0,0,0,0,0,0,0,0,0,0,0,0,0,0,0,0,0,0,0,0,0,0,0
0,0,0,0,0,0,0,0,0,0,0,0,0,0,0,0,0,0,0,0,0,0,0
0,0,0,0,0,0,0,0,0,0,0,0,0,0,0,0,0,0,0,0,0,0,0
0,0,0,0,0,0,0,0,0,0,0,0,0,0,0,0,0,0,0,0,0,0,0
0,0,0,0,0,0,0,0,0,0,0,0,0,0,0,0,0,0,0,0,0,0,0
0,0,0,0,0,0,0,0,0,0,0,0,0,0,0,80,3,3,3,80,0,0,0
0,0,0,0,0,0,0,0,0,0,0,0,0,0,81,3,3,3,3,3,82,0,0
0,0,0,0,0,0,0,0,0,0,0,0,0,0,3,3,3,3,3,3,3,0,0
0,0,0,0,0,0,0,0,0,0,0,0,0,0,3,3,3,3,3,3,3,0,0
0,0,0,0,0,0,0,0,0,0,0,0,0,0,3,3,3,3,3,3,3,0,0
0,0,0,0,0,0,0,0,0,0,0,0,0,0,81,3,3,3,78,3,82,0,0
0,0,0,0,0,0,0,0,0,0,0,0,0,0,0,40,3,3,3,40,0,0,0
0,0,0,0,0,0,0,0,0,0,0,0,0,0,0,0,0,0,0,0,0,0,0
0,0,0,0,0,0,0,0,0,0,0,0,0,0,0,0,0,0,0,0,0,0,0
0,0,0,0,0,0,0,0,0,0,0,0,0,0,0,0,0,0,0,0,0,0,0
0,0,0,0,0,0,0,0,0,0,0,0,0,0,0,0,0,0,0,0,0,0,0
:endlayer
layer: 20
0,0,0,0,0,0,0,0,0,0,0,0,0,0,0,0,0,0,0,0,0,0,0
0,0,0,0,0,0,0,0,0,0,0,0,0,0,0,0,0,0,0,0,0,0,0
0,0,0,0,0,0,0,0,0,0,0,0,0,0,0,0,0,0,0,0,0,0,0
0,0,0,0,0,0,0,0,0,0,0,0,0,0,0,0,0,0,0,0,0,0,0
0,0,0,0,0,0,0,0,0,0,0,0,0,0,0,0,0,0,0,0,0,0,0
0,0,0,0,0,0,0,0,0,0,0,0,0,0,0,0,0,0,0,0,0,0,0
0,0,0,0,0,0,0,0,0,0,0,0,0,0,0,0,0,0,0,0,0,0,0
0,0,0,0,0,0,0,0,0,0,0,0,0,0,3,3,3,3,3,3,3,0,0
0,0,0,0,0,0,0,0,0,0,0,0,0,0,3,3,83,83,83,3,3,0,0
0,0,0,0,0,0,0,0,0,0,0,0,0,0,3,83,83,83,83,83,3,0,0
0,0,0,0,0,0,0,0,0,0,0,0,0,0,3,83,83,3,0,83,3,0,0
0,0,0,0,0,0,0,0,0,0,0,0,0,0,3,83,83,0,0,83,3,0,0
0,0,0,0,0,0,0,0,0,0,0,0,0,0,3,3,83,0,84,3,3,0,0
0,0,0,0,0,0,0,0,0,0,0,0,0,0,3,3,3,3,3,3,3,0,0
0,0,0,0,0,0,0,0,0,0,0,0,0,0,0,0,0,0,0,0,0,0,0
0,0,0,0,0,0,0,0,0,0,0,0,0,0,0,0,0,0,0,0,0,0,0
0,0,0,0,0,0,0,0,0,0,0,0,0,0,0,0,0,0,0,0,0,0,0
0,0,0,0,0,0,0,0,0,0,0,0,0,0,0,0,0,0,0,0,0,0,0
:endlayer
layer: 21
0,0,0,0,0,0,0,0,0,0,0,0,0,0,0,0,0,0,0,0,0,0,0
0,0,0,0,0,0,0,0,0,0,0,0,0,0,0,0,0,0,0,0,0,0,0
0,0,0,0,0,0,0,0,0,0,0,0,0,0,0,0,0,0,0,0,0,0,0
0,0,0,0,0,0,0,0,0,0,0,0,0,0,0,0,0,0,0,0,0,0,0
0,0,0,0,0,0,0,0,0,0,0,0,0,0,0,0,0,0,0,0,0,0,0
0,0,0,0,0,0,0,0,0,0,0,0,0,0,0,0,0,0,0,0,0,0,0
0,0,0,0,0,0,0,0,0,0,0,0,0,0,0,0,0,0,0,0,0,0,0
0,0,0,0,0,0,0,0,0,0,0,0,0,0,3,0,3,0,3,0,3,0,0
0,0,0,0,0,0,0,0,0,0,0,0,0,0,0,0,0,0,0,85,0,0,0
0,0,0,0,0,0,0,0,0,0,0,0,0,0,3,0,0,0,0,0,3,0,0
0,0,0,0,0,0,0,0,0,0,0,0,0,0,0,0,0,46,0,0,0,0,0
0,0,0,0,0,0,0,0,0,0,0,0,0,0,3,0,0,0,0,0,3,0,0
0,0,0,0,0,0,0,0,0,0,0,0,0,0,0,86,0,0,0,0,0,0,0
0,0,0,0,0,0,0,0,0,0,0,0,0,0,3,0,3,0,3,0,3,0,0
0,0,0,0,0,0,0,0,0,0,0,0,0,0,0,0,0,0,0,0,0,0,0
0,0,0,0,0,0,0,0,0,0,0,0,0,0,0,0,0,0,0,0,0,0,0
0,0,0,0,0,0,0,0,0,0,0,0,0,0,0,0,0,0,0,0,0,0,0
0,0,0,0,0,0,0,0,0,0,0,0,0,0,0,0,0,0,0,0,0,0,0
:endlayer
layer: 22
0,0,0,0,0,0,0,0,0,0,0,0,0,0,0,0,0,0,0,0,0,0,0
0,0,0,0,0,0,0,0,0,0,0,0,0,0,0,0,0,0,0,0,0,0,0
0,0,0,0,0,0,0,0,0,0,0,0,0,0,0,0,0,0,0,0,0,0,0
0,0,0,0,0,0,0,0,0,0,0,0,0,0,0,0,0,0,0,0,0,0,0
0,0,0,0,0,0,0,0,0,0,0,0,0,0,0,0,0,0,0,0,0,0,0
0,0,0,0,0,0,0,0,0,0,0,0,0,0,0,0,0,0,0,0,0,0,0
0,0,0,0,0,0,0,0,0,0,0,0,0,0,0,0,0,0,0,0,0,0,0
0,0,0,0,0,0,0,0,0,0,0,0,0,0,45,0,0,0,0,0,45,0,0
0,0,0,0,0,0,0,0,0,0,0,0,0,0,0,0,0,0,0,0,0,0,0
0,0,0,0,0,0,0,0,0,0,0,0,0,0,0,0,0,0,0,0,0,0,0
0,0,0,0,0,0,0,0,0,0,0,0,0,0,0,0,0,0,0,0,0,0,0
0,0,0,0,0,0,0,0,0,0,0,0,0,0,0,0,0,0,0,0,0,0,0
0,0,0,0,0,0,0,0,0,0,0,0,0,0,0,0,0,0,0,0,0,0,0
0,0,0,0,0,0,0,0,0,0,0,0,0,0,45,0,0,0,0,0,45,0,0
0,0,0,0,0,0,0,0,0,0,0,0,0,0,0,0,0,0,0,0,0,0,0
0,0,0,0,0,0,0,0,0,0,0,0,0,0,0,0,0,0,0,0,0,0,0
0,0,0,0,0,0,0,0,0,0,0,0,0,0,0,0,0,0,0,0,0,0,0
0,0,0,0,0,0,0,0,0,0,0,0,0,0,0,0,0,0,0,0,0,0,0
:endlayer

#### RULES ####
rule:
plugin=vanillaBlocks
number=1
data:
JSON:{blockState:{blockName:"minecraft:stone",properties:{variant:"stone"}}}
:enddata
:endrule

rule:
plugin=vanillaBlocks
number=2
data:
JSON:{blockState:{blockName:"minecraft:stonebrick",properties:{variant:"mossy_stonebrick"}}}
:enddata
:endrule

rule:
plugin=vanillaBlocks
number=3
data:
JSON:{blockState:{blockName:"minecraft:stonebrick",properties:{variant:"stonebrick"}}}
:enddata
:endrule

rule:
plugin=vanillaBlocks
number=4
data:
JSON:{blockState:{blockName:"minecraft:stonebrick",properties:{variant:"cracked_stonebrick"}}}
:enddata
:endrule

rule:
plugin=vanillaBlocks
number=5
data:
JSON:{blockState:{blockName:"minecraft:double_stone_slab",properties:{seamless:"false",variant:"stone_brick"}}}
:enddata
:endrule

rule:
plugin=inventory
number=6
data:
JSON:{blockState:{blockName:"minecraft:chest",properties:{facing:"south"}},lootLevel:0,teData:{Items:[],id:"minecraft:chest",Lock:""},inventoryData:{length:0,inventoryContents:[]},legacyFeatures:1b}
:enddata
:endrule

rule:
plugin=vanillaSkull
number=7
data:
JSON:{blockState:{blockName:"minecraft:skull",properties:{nodrop:"false",facing:"up"}},skullRotation:0,teData:{Rot:0b,id:"minecraft:skull",SkullType:0b}}
:enddata
:endrule

rule:
plugin=inventory
number=8
data:
JSON:{blockState:{blockName:"minecraft:chest",properties:{facing:"north"}},lootLevel:0,teData:{Items:[],id:"minecraft:chest",Lock:""},inventoryData:{length:0,inventoryContents:[]},legacyFeatures:1b}
:enddata
:endrule

rule:
plugin=inventory
number=9
data:
JSON:{blockState:{blockName:"minecraft:chest",properties:{facing:"south"}},lootLevel:0,teData:{ForgeData:{},Items:[{Slot:2b,id:"minecraft:bone",Count:2b,Damage:0s},{Slot:3b,id:"minecraft:pumpkin_seeds",Count:2b,Damage:0s},{Slot:7b,id:"minecraft:bone",Count:2b,Damage:0s},{Slot:8b,id:"minecraft:gunpowder",Count:2b,Damage:0s},{Slot:9b,id:"minecraft:string",Count:2b,Damage:0s},{Slot:10b,id:"minecraft:melon_seeds",Count:2b,Damage:0s},{Slot:11b,id:"minecraft:gunpowder",Count:1b,Damage:0s},{Slot:12b,id:"ancientwarfarenpc:coin",Count:8b,tag:{metal:"copper"},Damage:0s},{Slot:13b,id:"ebwizardry:scroll",Count:1b,Damage:7s},{Slot:14b,id:"minecraft:string",Count:2b,Damage:0s},{Slot:15b,id:"minecraft:bone",Count:1b,Damage:0s},{Slot:16b,id:"minecraft:gold_ingot",Count:1b,Damage:0s},{Slot:18b,id:"ebwizardry:scroll",Count:1b,Damage:32s},{Slot:19b,id:"minecraft:bone",Count:1b,Damage:0s},{Slot:21b,id:"minecraft:string",Count:1b,Damage:0s},{Slot:22b,id:"minecraft:diamond_sword",Count:1b,Damage:0s},{Slot:24b,id:"minecraft:pumpkin_seeds",Count:1b,Damage:0s},{Slot:25b,id:"ancientwarfarenpc:coin",Count:7b,tag:{metal:"copper"},Damage:0s},{Slot:26b,id:"minecraft:bone",Count:1b,Damage:0s}],id:"minecraft:chest",Lock:""},inventoryData:{length:19,inventoryContents:[{id:"minecraft:bone",Count:2b,slot:0,Damage:0s},{id:"minecraft:pumpkin_seeds",Count:2b,slot:1,Damage:0s},{id:"minecraft:bone",Count:2b,slot:2,Damage:0s},{id:"minecraft:gunpowder",Count:2b,slot:3,Damage:0s},{id:"minecraft:string",Count:2b,slot:4,Damage:0s},{id:"minecraft:melon_seeds",Count:2b,slot:5,Damage:0s},{id:"minecraft:gunpowder",Count:1b,slot:6,Damage:0s},{id:"ancientwarfarenpc:coin",Count:8b,tag:{metal:"copper"},slot:7,Damage:0s},{id:"ebwizardry:scroll",Count:1b,slot:8,Damage:7s},{id:"minecraft:string",Count:2b,slot:9,Damage:0s},{id:"minecraft:bone",Count:1b,slot:10,Damage:0s},{id:"minecraft:gold_ingot",Count:1b,slot:11,Damage:0s},{id:"ebwizardry:scroll",Count:1b,slot:12,Damage:32s},{id:"minecraft:bone",Count:1b,slot:13,Damage:0s},{id:"minecraft:string",Count:1b,slot:14,Damage:0s},{id:"minecraft:diamond_sword",Count:1b,slot:15,Damage:0s},{id:"minecraft:pumpkin_seeds",Count:1b,slot:16,Damage:0s},{id:"ancientwarfarenpc:coin",Count:7b,tag:{metal:"copper"},slot:17,Damage:0s},{id:"minecraft:bone",Count:1b,slot:18,Damage:0s}]},legacyFeatures:1b}
:enddata
:endrule

rule:
plugin=vanillaBlocks
number=10
data:
JSON:{blockState:{blockName:"minecraft:stone_slab",properties:{half:"top",variant:"stone_brick"}}}
:enddata
:endrule

rule:
plugin=blockTile
number=11
data:
JSON:{blockState:{blockName:"ancientwarfarestructure:advanced_spawner",properties:{transparent:"true"}},teData:{id:"ancientwarfarestructure:advanced_spawner_tile",spawnerSettings:{minDelay:50,spawnDelay:48,lightSensitive:0b,spawnGroups:[{settingsList:[{remainingSpawnCount:2,hostile:1b,forced:1b,customTag:{ArmorDropChances:[0.085f,0.085f,0.085f,0.085f],ArmorItems:[{},{},{},{}],HandDropChances:[0.11f,0.085f],HandItems:[{id:"silentgems:sword",Count:1b,tag:{SG_UUIDLeast:-5770218025200803092L,SGProperties:{ToolTier:1,MeleeDamage:3.2250001f,MagicDamage:4.3f,Enchantability:10,ChargeSpeed:1.075f,HarvestSpeed:10.212501f,MeleeSpeed:1.0212501f,Durability:963,HarvestLevel:2,Protection:19.35f},SGStatistics:{OriginalOwner:"Zombie Villager(?)"},PartListForName:{part0:{id:"silentgems:gem",Count:1b,Damage:30s},part1:{id:"silentgems:gem",Count:1b,Damage:35s}},SGConstruction:{PartRod:"silentgems:rodwood#NONE",Part0:"silentgems:black_diamond#NONE",Part1:"silentgems:cats_eye#NONE"},display:{Name:"Black Diamond-Cat's Eye Sword"},SG_UUIDMost:-6328512056341017124L},Damage:0s},{}]},maxToSpawn:2,entityId:"minecraft:zombie_villager",minToSpawn:2}],groupWeight:1}],playerRange:1,respondToRedstone:0b,inventory:{Size:9,Items:[]},spawnRange:0,transparent:1b,maxDelay:50,xpToDrop:0,mobRange:0,debugMode:0b,maxNearbyMonsters:0}}}
:enddata
:endrule

rule:
plugin=blockTile
number=12
data:
JSON:{blockState:{blockName:"ancientwarfarestructure:advanced_loot_chest",properties:{facing:"north"}},teData:{LootTable:"minecraft:chests/simple_dungeon",lootRolls:1b,lootSettings:{lootRolls:1,splashPotion:0b,hasLoot:1b,lootTableName:"minecraft:chests/simple_dungeon",spawnEntity:0b},id:"ancientwarfarestructure:advanced_loot_chest_tile",Lock:"",LootTableSeed:8153647151357742265L}}
:enddata
:endrule

rule:
plugin=vanillaSkull
number=13
data:
JSON:{blockState:{blockName:"minecraft:skull",properties:{nodrop:"false",facing:"up"}},skullRotation:4,teData:{Rot:4b,id:"minecraft:skull",SkullType:0b}}
:enddata
:endrule

rule:
plugin=vanillaSkull
number=14
data:
JSON:{blockState:{blockName:"minecraft:skull",properties:{nodrop:"false",facing:"up"}},skullRotation:0,teData:{Rot:0b,id:"minecraft:skull",SkullType:0b}}
:enddata
:endrule

rule:
plugin=vanillaSkull
number=15
data:
JSON:{blockState:{blockName:"minecraft:skull",properties:{nodrop:"false",facing:"up"}},skullRotation:0,teData:{Rot:0b,id:"minecraft:skull",SkullType:0b}}
:enddata
:endrule

rule:
plugin=vanillaSkull
number=16
data:
JSON:{blockState:{blockName:"minecraft:skull",properties:{nodrop:"false",facing:"up"}},skullRotation:8,teData:{Rot:8b,id:"minecraft:skull",SkullType:0b}}
:enddata
:endrule

rule:
plugin=vanillaSkull
number=17
data:
JSON:{blockState:{blockName:"minecraft:skull",properties:{nodrop:"false",facing:"up"}},skullRotation:12,teData:{Rot:12b,id:"minecraft:skull",SkullType:0b}}
:enddata
:endrule

rule:
plugin=vanillaSkull
number=18
data:
JSON:{blockState:{blockName:"minecraft:skull",properties:{nodrop:"false",facing:"up"}},skullRotation:8,teData:{Rot:8b,id:"minecraft:skull",SkullType:0b}}
:enddata
:endrule

rule:
plugin=vanillaBlocks
number=19
data:
JSON:{blockState:{blockName:"minecraft:trapdoor",properties:{half:"top",facing:"west",open:"false"}}}
:enddata
:endrule

rule:
plugin=vanillaBlocks
number=20
data:
JSON:{blockState:{blockName:"minecraft:dirt",properties:{variant:"dirt",snowy:"false"}}}
:enddata
:endrule

rule:
plugin=blockTile
number=21
data:
JSON:{blockState:{blockName:"ancientwarfarestructure:advanced_spawner",properties:{transparent:"true"}},teData:{id:"ancientwarfarestructure:advanced_spawner_tile",spawnerSettings:{minDelay:0,spawnDelay:0,lightSensitive:0b,spawnGroups:[{settingsList:[{remainingSpawnCount:10,hostile:1b,forced:1b,customTag:{ArmorDropChances:[0.085f,0.085f,0.085f,0.085f],ArmorItems:[{},{},{},{}],HandDropChances:[0.085f,0.085f],HandItems:[{},{}]},maxToSpawn:10,entityId:"minecraft:bat",minToSpawn:10}],groupWeight:1}],playerRange:1,respondToRedstone:0b,inventory:{Size:9,Items:[]},spawnRange:0,transparent:1b,maxDelay:0,xpToDrop:0,mobRange:0,debugMode:0b,maxNearbyMonsters:0}}}
:enddata
:endrule

rule:
plugin=doors
number=22
data:
JSON:{blockState:{blockName:"minecraft:iron_door",properties:{hinge:"left",half:"lower",powered:"false",facing:"north",open:"false"}}}
:enddata
:endrule

rule:
plugin=vanillaBlocks
number=23
data:
JSON:{blockState:{blockName:"minecraft:stone_stairs",properties:{half:"bottom",shape:"straight",facing:"south"}}}
:enddata
:endrule

rule:
plugin=vanillaSkull
number=24
data:
JSON:{blockState:{blockName:"minecraft:skull",properties:{nodrop:"false",facing:"up"}},skullRotation:0,teData:{Rot:0b,id:"minecraft:skull",SkullType:0b}}
:enddata
:endrule

rule:
plugin=vanillaSkull
number=25
data:
JSON:{blockState:{blockName:"minecraft:skull",properties:{nodrop:"false",facing:"up"}},skullRotation:0,teData:{Rot:0b,id:"minecraft:skull",SkullType:0b}}
:enddata
:endrule

rule:
plugin=vanillaSkull
number=26
data:
JSON:{blockState:{blockName:"minecraft:skull",properties:{nodrop:"false",facing:"up"}},skullRotation:4,teData:{Rot:4b,id:"minecraft:skull",SkullType:0b}}
:enddata
:endrule

rule:
plugin=vanillaSkull
number=27
data:
JSON:{blockState:{blockName:"minecraft:skull",properties:{nodrop:"false",facing:"up"}},skullRotation:8,teData:{Rot:8b,id:"minecraft:skull",SkullType:0b}}
:enddata
:endrule

rule:
plugin=doors
number=28
data:
JSON:{blockState:{blockName:"minecraft:iron_door",properties:{hinge:"left",half:"upper",powered:"false",facing:"north",open:"false"}}}
:enddata
:endrule

rule:
plugin=vanillaSkull
number=29
data:
JSON:{blockState:{blockName:"minecraft:skull",properties:{nodrop:"false",facing:"up"}},skullRotation:8,teData:{Rot:8b,id:"minecraft:skull",SkullType:0b}}
:enddata
:endrule

rule:
plugin=vanillaBlocks
number=30
data:
JSON:{blockState:{blockName:"minecraft:grass",properties:{snowy:"false"}}}
:enddata
:endrule

rule:
plugin=vanillaBlocks
number=31
data:
JSON:{blockState:{blockName:"minecraft:gravel"}}
:enddata
:endrule

rule:
plugin=vanillaBlocks
number=32
data:
JSON:{blockState:{blockName:"minecraft:redstone_torch",properties:{facing:"north"}}}
:enddata
:endrule

rule:
plugin=vanillaBlocks
number=33
data:
JSON:{blockState:{blockName:"minecraft:lever",properties:{powered:"false",facing:"south"}}}
:enddata
:endrule

rule:
plugin=vanillaBlocks
number=34
data:
JSON:{blockState:{blockName:"minecraft:tallgrass",properties:{type:"tall_grass"}}}
:enddata
:endrule

rule:
plugin=vanillaBlocks
number=35
data:
JSON:{blockState:{blockName:"minecraft:log",properties:{variant:"birch",axis:"y"}}}
:enddata
:endrule

rule:
plugin=vanillaBlocks
number=36
data:
JSON:{blockState:{blockName:"minecraft:cobblestone_wall",properties:{east:"false",south:"false",north:"false",variant:"mossy_cobblestone",west:"false",up:"false"}}}
:enddata
:endrule

rule:
plugin=vanillaBlocks
number=37
data:
JSON:{blockState:{blockName:"minecraft:cobblestone_wall",properties:{east:"false",south:"false",north:"false",variant:"cobblestone",west:"false",up:"false"}}}
:enddata
:endrule

rule:
plugin=vanillaBlocks
number=38
data:
JSON:{blockState:{blockName:"minecraft:fence_gate",properties:{in_wall:"false",powered:"false",facing:"south",open:"false"}}}
:enddata
:endrule

rule:
plugin=vanillaBlocks
number=39
data:
JSON:{blockState:{blockName:"minecraft:stone_slab",properties:{half:"bottom",variant:"stone"}}}
:enddata
:endrule

rule:
plugin=vanillaBlocks
number=40
data:
JSON:{blockState:{blockName:"minecraft:stone_brick_stairs",properties:{half:"top",shape:"straight",facing:"north"}}}
:enddata
:endrule

rule:
plugin=blockTile
number=41
data:
JSON:{blockState:{blockName:"ancientwarfarestructure:advanced_spawner",properties:{transparent:"true"}},teData:{id:"ancientwarfarestructure:advanced_spawner_tile",spawnerSettings:{minDelay:0,spawnDelay:0,lightSensitive:0b,spawnGroups:[{settingsList:[{remainingSpawnCount:1,hostile:1b,forced:1b,customTag:{ArmorDropChances:[1.0f,1.0f,1.0f,1.0f],ArmorItems:[{},{},{},{}],HandDropChances:[1.0f,1.0f],factionName:"witchbane",HandItems:[{id:"ancientwarfarenpc:iron_spear",Count:1b,Damage:0s},{id:"ancientwarfarenpc:iron_shield",Count:1b,Damage:0s}]},maxToSpawn:1,entityId:"ancientwarfarenpc:faction.soldier",minToSpawn:1}],groupWeight:1}],playerRange:10,respondToRedstone:0b,inventory:{Size:9,Items:[]},spawnRange:0,transparent:1b,maxDelay:0,xpToDrop:0,mobRange:0,debugMode:0b,maxNearbyMonsters:0}}}
:enddata
:endrule

rule:
plugin=vanillaBlocks
number=42
data:
JSON:{blockState:{blockName:"minecraft:log",properties:{variant:"oak",axis:"y"}}}
:enddata
:endrule

rule:
plugin=vanillaBlocks
number=43
data:
JSON:{blockState:{blockName:"minecraft:fence_gate",properties:{in_wall:"false",powered:"false",facing:"west",open:"false"}}}
:enddata
:endrule

rule:
plugin=vanillaBlocks
number=44
data:
JSON:{blockState:{blockName:"minecraft:stone_brick_stairs",properties:{half:"bottom",shape:"straight",facing:"north"}}}
:enddata
:endrule

rule:
plugin=vanillaBlocks
number=45
data:
JSON:{blockState:{blockName:"minecraft:torch",properties:{facing:"up"}}}
:enddata
:endrule

rule:
plugin=vanillaBlocks
number=46
data:
JSON:{blockState:{blockName:"ancientwarfarestructure:fire_pit",properties:{lit:"true",variant:"square"}}}
:enddata
:endrule

rule:
plugin=vanillaBlocks
number=47
data:
JSON:{blockState:{blockName:"minecraft:leaves",properties:{check_decay:"false",decayable:"true",variant:"birch"}}}
:enddata
:endrule

rule:
plugin=vanillaBlocks
number=48
data:
JSON:{blockState:{blockName:"minecraft:stone_brick_stairs",properties:{half:"bottom",shape:"straight",facing:"south"}}}
:enddata
:endrule

rule:
plugin=vanillaBlocks
number=49
data:
JSON:{blockState:{blockName:"minecraft:stone_brick_stairs",properties:{half:"bottom",shape:"straight",facing:"east"}}}
:enddata
:endrule

rule:
plugin=blockTile
number=50
data:
JSON:{blockState:{blockName:"ancientwarfarestructure:advanced_spawner",properties:{transparent:"true"}},teData:{id:"ancientwarfarestructure:advanced_spawner_tile",spawnerSettings:{minDelay:0,spawnDelay:0,lightSensitive:0b,spawnGroups:[{settingsList:[{remainingSpawnCount:1,hostile:1b,forced:1b,customTag:{ArmorDropChances:[1.0f,1.0f,1.0f,1.0f],ArmorItems:[{},{},{},{}],HandDropChances:[1.0f,1.0f],factionName:"witchbane",HandItems:[{id:"minecraft:iron_sword",Count:1b,Damage:0s},{}]},maxToSpawn:1,entityId:"ancientwarfarenpc:faction.soldier.elite",minToSpawn:1}],groupWeight:1}],playerRange:4,respondToRedstone:0b,inventory:{Size:9,Items:[]},spawnRange:0,transparent:1b,maxDelay:0,xpToDrop:0,mobRange:0,debugMode:0b,maxNearbyMonsters:0}}}
:enddata
:endrule

rule:
plugin=blockTile
number=51
data:
JSON:{blockState:{blockName:"ancientwarfarestructure:advanced_spawner",properties:{transparent:"true"}},teData:{id:"ancientwarfarestructure:advanced_spawner_tile",spawnerSettings:{minDelay:0,spawnDelay:0,lightSensitive:0b,spawnGroups:[{settingsList:[{remainingSpawnCount:1,hostile:1b,forced:1b,customTag:{ArmorDropChances:[1.0f,1.0f,1.0f,1.0f],ArmorItems:[{},{},{},{}],HandDropChances:[1.0f,1.0f],factionName:"witchbane",HandItems:[{id:"minecraft:iron_sword",Count:1b,Damage:0s},{}]},maxToSpawn:1,entityId:"ancientwarfarenpc:faction.soldier.elite",minToSpawn:1}],groupWeight:1}],playerRange:4,respondToRedstone:0b,inventory:{Size:9,Items:[]},spawnRange:0,transparent:1b,maxDelay:0,xpToDrop:0,mobRange:0,debugMode:0b,maxNearbyMonsters:0}}}
:enddata
:endrule

rule:
plugin=vanillaBlocks
number=52
data:
JSON:{blockState:{blockName:"minecraft:stone_brick_stairs",properties:{half:"bottom",shape:"straight",facing:"west"}}}
:enddata
:endrule

rule:
plugin=blockTile
number=53
data:
JSON:{blockState:{blockName:"ancientwarfarestructure:advanced_spawner",properties:{transparent:"true"}},teData:{id:"ancientwarfarestructure:advanced_spawner_tile",spawnerSettings:{minDelay:0,spawnDelay:0,lightSensitive:0b,spawnGroups:[{settingsList:[{remainingSpawnCount:1,hostile:1b,forced:1b,customTag:{ArmorDropChances:[1.0f,1.0f,1.0f,1.0f],ArmorItems:[{},{},{},{}],HandDropChances:[1.0f,1.0f],factionName:"empire",HandItems:[{id:"minecraft:book",Count:1b,Damage:0s},{}]},maxToSpawn:1,entityId:"ancientwarfarenpc:faction.priest",minToSpawn:1}],groupWeight:1}],playerRange:8,respondToRedstone:0b,inventory:{Size:9,Items:[]},spawnRange:0,transparent:1b,maxDelay:0,xpToDrop:0,mobRange:0,debugMode:0b,maxNearbyMonsters:0}}}
:enddata
:endrule

rule:
plugin=vanillaBlocks
number=54
data:
JSON:{blockState:{blockName:"minecraft:dark_oak_stairs",properties:{half:"bottom",shape:"straight",facing:"south"}}}
:enddata
:endrule

rule:
plugin=blockTile
number=55
data:
JSON:{blockState:{blockName:"ancientwarfarestructure:advanced_spawner",properties:{transparent:"true"}},teData:{id:"ancientwarfarestructure:advanced_spawner_tile",spawnerSettings:{minDelay:0,spawnDelay:0,lightSensitive:0b,spawnGroups:[{settingsList:[{remainingSpawnCount:1,hostile:1b,forced:1b,customTag:{ArmorDropChances:[1.0f,1.0f,1.0f,1.0f],ArmorItems:[{},{},{},{}],HandDropChances:[1.0f,1.0f],factionName:"empire",HandItems:[{},{}]},maxToSpawn:1,entityId:"ancientwarfarenpc:faction.civilian.male",minToSpawn:1}],groupWeight:1}],playerRange:16,respondToRedstone:0b,inventory:{Size:9,Items:[]},spawnRange:0,transparent:1b,maxDelay:0,xpToDrop:0,mobRange:0,debugMode:0b,maxNearbyMonsters:0}}}
:enddata
:endrule

rule:
plugin=blockTile
number=56
data:
JSON:{blockState:{blockName:"ancientwarfarestructure:advanced_spawner",properties:{transparent:"true"}},teData:{id:"ancientwarfarestructure:advanced_spawner_tile",spawnerSettings:{minDelay:0,spawnDelay:0,lightSensitive:0b,spawnGroups:[{settingsList:[{remainingSpawnCount:1,hostile:1b,forced:1b,customTag:{ArmorDropChances:[1.0f,1.0f,1.0f,1.0f],ArmorItems:[{},{},{},{}],HandDropChances:[1.0f,1.0f],factionName:"empire",HandItems:[{},{}]},maxToSpawn:1,entityId:"ancientwarfarenpc:faction.civilian.female",minToSpawn:1}],groupWeight:1}],playerRange:16,respondToRedstone:0b,inventory:{Size:9,Items:[]},spawnRange:0,transparent:1b,maxDelay:0,xpToDrop:0,mobRange:0,debugMode:0b,maxNearbyMonsters:0}}}
:enddata
:endrule

rule:
plugin=blockTile
number=57
data:
JSON:{blockState:{blockName:"ancientwarfarestructure:advanced_spawner",properties:{transparent:"true"}},teData:{id:"ancientwarfarestructure:advanced_spawner_tile",spawnerSettings:{minDelay:0,spawnDelay:0,lightSensitive:0b,spawnGroups:[{settingsList:[{remainingSpawnCount:1,hostile:1b,forced:1b,customTag:{ArmorDropChances:[1.0f,1.0f,1.0f,1.0f],ArmorItems:[{},{},{},{}],HandDropChances:[1.0f,1.0f],factionName:"empire",HandItems:[{},{}]},maxToSpawn:1,entityId:"ancientwarfarenpc:faction.civilian.female",minToSpawn:1}],groupWeight:1}],playerRange:16,respondToRedstone:0b,inventory:{Size:9,Items:[]},spawnRange:0,transparent:1b,maxDelay:0,xpToDrop:0,mobRange:0,debugMode:0b,maxNearbyMonsters:0}}}
:enddata
:endrule

rule:
plugin=blockTile
number=58
data:
JSON:{blockState:{blockName:"ancientwarfarestructure:advanced_spawner",properties:{transparent:"true"}},teData:{id:"ancientwarfarestructure:advanced_spawner_tile",spawnerSettings:{minDelay:0,spawnDelay:0,lightSensitive:0b,spawnGroups:[{settingsList:[{remainingSpawnCount:1,hostile:1b,forced:1b,customTag:{ArmorDropChances:[1.0f,1.0f,1.0f,1.0f],ArmorItems:[{},{},{},{}],HandDropChances:[1.0f,1.0f],factionName:"empire",HandItems:[{},{}]},maxToSpawn:1,entityId:"ancientwarfarenpc:faction.civilian.male",minToSpawn:1}],groupWeight:1}],playerRange:16,respondToRedstone:0b,inventory:{Size:9,Items:[]},spawnRange:0,transparent:1b,maxDelay:0,xpToDrop:0,mobRange:0,debugMode:0b,maxNearbyMonsters:0}}}
:enddata
:endrule

rule:
plugin=vanillaBlocks
number=59
data:
JSON:{blockState:{blockName:"minecraft:cauldron",properties:{level:"3"}}}
:enddata
:endrule

rule:
plugin=doors
number=60
data:
JSON:{blockState:{blockName:"minecraft:wooden_door",properties:{hinge:"left",half:"lower",powered:"false",facing:"north",open:"true"}}}
:enddata
:endrule

rule:
plugin=vanillaBlocks
number=61
data:
JSON:{blockState:{blockName:"minecraft:leaves",properties:{check_decay:"false",decayable:"true",variant:"oak"}}}
:enddata
:endrule

rule:
plugin=vanillaBlocks
number=62
data:
JSON:{blockState:{blockName:"minecraft:stained_glass_pane",properties:{east:"false",color:"magenta",south:"false",north:"false",west:"false"}}}
:enddata
:endrule

rule:
plugin=vanillaBlocks
number=63
data:
JSON:{blockState:{blockName:"minecraft:carpet",properties:{color:"white"}}}
:enddata
:endrule

rule:
plugin=vanillaBlocks
number=64
data:
JSON:{blockState:{blockName:"minecraft:stained_glass_pane",properties:{east:"false",color:"light_blue",south:"false",north:"false",west:"false"}}}
:enddata
:endrule

rule:
plugin=doors
number=65
data:
JSON:{blockState:{blockName:"minecraft:wooden_door",properties:{hinge:"left",half:"upper",powered:"false",facing:"north",open:"false"}}}
:enddata
:endrule

rule:
plugin=vanillaBlocks
number=66
data:
JSON:{blockState:{blockName:"minecraft:stained_glass_pane",properties:{east:"false",color:"orange",south:"false",north:"false",west:"false"}}}
:enddata
:endrule

rule:
plugin=vanillaBlocks
number=67
data:
JSON:{blockState:{blockName:"minecraft:torch",properties:{facing:"south"}}}
:enddata
:endrule

rule:
plugin=vanillaBlocks
number=68
data:
JSON:{blockState:{blockName:"minecraft:stone_stairs",properties:{half:"bottom",shape:"straight",facing:"east"}}}
:enddata
:endrule

rule:
plugin=vanillaBlocks
number=69
data:
JSON:{blockState:{blockName:"minecraft:stone_stairs",properties:{half:"bottom",shape:"straight",facing:"west"}}}
:enddata
:endrule

rule:
plugin=vanillaBlocks
number=70
data:
JSON:{blockState:{blockName:"minecraft:torch",properties:{facing:"east"}}}
:enddata
:endrule

rule:
plugin=vanillaBlocks
number=71
data:
JSON:{blockState:{blockName:"minecraft:torch",properties:{facing:"west"}}}
:enddata
:endrule

rule:
plugin=vanillaBlocks
number=72
data:
JSON:{blockState:{blockName:"minecraft:log",properties:{variant:"oak",axis:"x"}}}
:enddata
:endrule

rule:
plugin=vanillaBlocks
number=73
data:
JSON:{blockState:{blockName:"minecraft:stone_stairs",properties:{half:"bottom",shape:"straight",facing:"north"}}}
:enddata
:endrule

rule:
plugin=vanillaBlocks
number=74
data:
JSON:{blockState:{blockName:"minecraft:stained_glass_pane",properties:{east:"false",color:"white",south:"false",north:"false",west:"false"}}}
:enddata
:endrule

rule:
plugin=vanillaBlocks
number=75
data:
JSON:{blockState:{blockName:"minecraft:log",properties:{variant:"oak",axis:"z"}}}
:enddata
:endrule

rule:
plugin=vanillaBlocks
number=76
data:
JSON:{blockState:{blockName:"minecraft:fence",properties:{east:"false",south:"false",north:"false",west:"false"}}}
:enddata
:endrule

rule:
plugin=blockTile
number=77
data:
JSON:{blockState:{blockName:"ancientwarfarestructure:advanced_spawner",properties:{transparent:"true"}},teData:{id:"ancientwarfarestructure:advanced_spawner_tile",spawnerSettings:{minDelay:0,spawnDelay:0,lightSensitive:0b,spawnGroups:[{settingsList:[{remainingSpawnCount:1,hostile:1b,forced:1b,customTag:{ArmorDropChances:[1.0f,1.0f,1.0f,1.0f],ArmorItems:[{},{},{},{}],HandDropChances:[1.0f,1.0f],factionName:"empire",HandItems:[{id:"minecraft:book",Count:1b,Damage:0s},{}]},maxToSpawn:1,entityId:"ancientwarfarenpc:faction.priest",minToSpawn:1}],groupWeight:1}],playerRange:6,respondToRedstone:0b,inventory:{Size:9,Items:[]},spawnRange:0,transparent:1b,maxDelay:0,xpToDrop:0,mobRange:0,debugMode:0b,maxNearbyMonsters:0}}}
:enddata
:endrule

rule:
plugin=vanillaBlocks
number=78
data:
JSON:{blockState:{blockName:"minecraft:ladder",properties:{facing:"west"}}}
:enddata
:endrule

rule:
plugin=vanillaBlocks
number=79
data:
JSON:{blockState:{blockName:"minecraft:stone_slab",properties:{half:"bottom",variant:"cobblestone"}}}
:enddata
:endrule

rule:
plugin=vanillaBlocks
number=80
data:
JSON:{blockState:{blockName:"minecraft:stone_brick_stairs",properties:{half:"top",shape:"straight",facing:"south"}}}
:enddata
:endrule

rule:
plugin=vanillaBlocks
number=81
data:
JSON:{blockState:{blockName:"minecraft:stone_brick_stairs",properties:{half:"top",shape:"straight",facing:"east"}}}
:enddata
:endrule

rule:
plugin=vanillaBlocks
number=82
data:
JSON:{blockState:{blockName:"minecraft:stone_brick_stairs",properties:{half:"top",shape:"straight",facing:"west"}}}
:enddata
:endrule

rule:
plugin=vanillaBlocks
number=83
data:
JSON:{blockState:{blockName:"minecraft:stone_slab",properties:{half:"bottom",variant:"stone_brick"}}}
:enddata
:endrule

rule:
plugin=vanillaBlocks
number=84
data:
JSON:{blockState:{blockName:"minecraft:trapdoor",properties:{half:"bottom",facing:"north",open:"false"}}}
:enddata
:endrule

rule:
plugin=blockTile
number=85
data:
JSON:{blockState:{blockName:"ancientwarfarestructure:advanced_spawner",properties:{transparent:"true"}},teData:{id:"ancientwarfarestructure:advanced_spawner_tile",spawnerSettings:{minDelay:0,spawnDelay:0,lightSensitive:0b,spawnGroups:[{settingsList:[{remainingSpawnCount:1,hostile:1b,forced:1b,customTag:{ArmorDropChances:[1.0f,1.0f,1.0f,1.0f],ArmorItems:[{},{},{},{}],HandDropChances:[1.0f,1.0f],factionName:"witchbane",HandItems:[{id:"minecraft:bow",Count:1b,Damage:0s},{}]},maxToSpawn:1,entityId:"ancientwarfarenpc:faction.archer.elite",minToSpawn:1}],groupWeight:1}],playerRange:16,respondToRedstone:0b,inventory:{Size:9,Items:[]},spawnRange:0,transparent:1b,maxDelay:0,xpToDrop:0,mobRange:0,debugMode:0b,maxNearbyMonsters:0}}}
:enddata
:endrule

rule:
plugin=blockTile
number=86
data:
JSON:{blockState:{blockName:"ancientwarfarestructure:advanced_spawner",properties:{transparent:"true"}},teData:{id:"ancientwarfarestructure:advanced_spawner_tile",spawnerSettings:{minDelay:0,spawnDelay:0,lightSensitive:0b,spawnGroups:[{settingsList:[{remainingSpawnCount:1,hostile:1b,forced:1b,customTag:{ArmorDropChances:[1.0f,1.0f,1.0f,1.0f],ArmorItems:[{},{},{},{}],HandDropChances:[1.0f,1.0f],factionName:"witchbane",HandItems:[{id:"minecraft:bow",Count:1b,Damage:0s},{}]},maxToSpawn:1,entityId:"ancientwarfarenpc:faction.archer.elite",minToSpawn:1}],groupWeight:1}],playerRange:16,respondToRedstone:0b,inventory:{Size:9,Items:[]},spawnRange:0,transparent:1b,maxDelay:0,xpToDrop:0,mobRange:0,debugMode:0b,maxNearbyMonsters:0}}}
:enddata
:endrule

#### ENTITIES ####
