# Ancient Warfare Structure Template File
# Auto-generated structure template file. created on: 12/21/2018 at: 1:0:27
# Lines beginning with # denote comments

header:
version=2.8
name=EmpireMilitaryBaronsCastle
mods=
size=39,96,42
offset=19,5,41
:endheader

#### VALIDATION ####
validation:
type=ground
survival=false
worldGenEnabled=true
unique=false
preserveBlocks=false
selectionWeight=120
clusterValue=50
minDuplicateDistance=1000
dimensionWhiteList=false
dimensionList=
biomeWhiteList=true
biomeList=traverse:meadow,biomesoplenty:meadow,minecraft:forest,minecraft:birch_forest,minecraft:birch_forest_hills,minecraft:smaller_extreme_hills
leveling=12
fill=12
border=12
blockSwap=false
:endvalidation

#### LAYERS ####
layer: 0
1,1,1,1,1,1,1,1,1,1,1,1,1,1,1,1,1,1,1,1,1,1,1,1,1,1,1,1,1,1,1,1,1,1,1,1,1,1,1
1,2,2,2,2,2,2,2,2,2,2,2,2,2,2,2,2,2,2,2,2,2,2,2,2,2,2,2,2,2,2,2,2,2,2,2,2,2,1
1,2,2,2,2,2,2,2,2,2,2,2,2,2,2,2,2,2,2,2,2,2,2,2,2,2,2,2,2,2,2,2,2,2,2,2,2,2,1
1,2,2,2,2,2,2,2,2,2,2,2,2,2,2,2,2,2,2,2,2,2,2,2,2,2,2,2,2,2,2,2,2,2,2,2,2,2,1
1,2,2,2,3,3,3,3,3,3,3,3,3,3,3,3,3,3,3,3,3,3,3,3,3,3,3,3,3,3,3,3,3,3,3,2,2,2,1
1,2,2,2,3,3,3,3,3,3,3,3,3,3,3,3,3,3,3,3,3,3,3,3,3,3,3,3,3,3,3,3,3,3,3,2,2,2,1
1,2,2,2,3,3,3,3,3,3,3,3,3,3,3,3,3,3,3,3,3,3,3,3,3,3,3,3,3,3,3,3,3,3,3,2,2,2,1
1,2,2,2,3,3,3,3,3,3,3,3,3,3,3,3,3,3,3,3,3,3,3,3,3,3,3,3,3,3,3,3,3,3,3,2,2,2,1
1,2,2,2,3,3,3,3,3,3,3,3,3,3,3,3,3,3,3,3,3,3,3,3,3,3,3,3,3,3,3,3,3,3,3,2,2,2,1
1,2,2,2,3,3,3,3,3,3,3,3,3,3,3,3,3,3,3,3,3,3,3,3,3,3,3,3,3,3,3,3,3,3,3,2,2,2,1
1,2,2,2,3,3,3,3,3,3,3,3,3,3,3,3,3,3,3,3,3,3,3,3,3,3,3,3,3,3,3,3,3,3,3,2,2,2,1
1,2,2,2,3,3,3,3,3,3,3,3,3,3,3,3,3,3,3,3,3,3,3,3,3,3,3,3,3,3,3,3,3,3,3,2,2,2,1
1,2,2,2,3,3,3,3,3,3,3,3,3,3,3,3,3,3,3,3,3,3,3,3,3,3,3,3,3,3,3,3,3,3,3,2,2,2,1
1,2,2,2,3,3,3,3,3,3,3,3,3,3,3,3,3,3,3,3,3,3,3,3,3,3,3,3,3,3,3,3,3,3,3,2,2,2,1
1,2,2,2,3,3,3,3,3,3,3,3,3,3,3,3,3,3,3,3,3,3,3,3,3,3,3,3,3,3,3,3,3,3,3,2,2,2,1
1,2,2,2,3,3,3,3,3,3,3,3,3,3,3,3,3,3,3,3,3,3,3,3,3,3,3,3,3,3,3,3,3,3,3,2,2,2,1
1,2,2,2,3,3,3,3,3,3,3,3,3,3,3,3,3,3,3,3,3,3,3,3,3,3,3,3,3,3,3,3,3,3,3,2,2,2,1
1,2,2,2,3,3,3,3,3,3,3,3,3,3,3,3,3,3,3,3,3,3,3,3,3,3,3,3,3,3,3,3,3,3,3,2,2,2,1
1,2,2,2,3,3,3,3,3,3,3,3,3,3,3,3,3,3,3,3,3,3,3,3,3,3,3,3,3,3,3,3,3,3,3,2,2,2,1
1,2,2,2,3,3,3,3,3,3,3,3,3,3,3,3,3,3,3,3,3,3,3,3,3,3,3,3,3,3,3,3,3,3,3,2,2,2,1
1,2,2,2,3,3,3,3,3,3,3,3,3,3,3,3,3,3,3,3,3,3,3,3,3,3,3,3,3,3,3,3,3,3,3,2,2,2,1
1,2,2,2,3,3,3,3,3,3,3,3,3,3,3,3,3,3,3,3,3,3,3,3,3,3,3,3,3,3,3,3,3,3,3,2,2,2,1
1,2,2,2,3,3,3,3,3,3,3,3,3,3,3,3,3,3,3,3,3,3,3,3,3,3,3,3,3,3,3,3,3,3,3,2,2,2,1
1,2,2,2,3,3,3,3,3,3,3,3,3,3,3,3,3,3,3,3,3,3,3,3,3,3,3,3,3,3,3,3,3,3,3,2,2,2,1
1,2,2,2,3,3,3,3,3,3,3,3,3,3,3,3,3,3,3,3,3,3,3,3,3,3,3,3,3,3,3,3,3,3,3,2,2,2,1
1,2,2,2,3,3,3,3,3,3,3,3,3,3,3,3,3,3,3,3,3,3,3,3,3,3,3,3,3,3,3,3,3,3,3,2,2,2,1
1,2,2,2,3,3,3,3,3,3,3,3,3,3,3,3,3,3,3,3,3,3,3,3,3,3,3,3,3,3,3,3,3,3,3,2,2,2,1
1,2,2,2,3,3,3,3,3,3,3,3,3,3,3,3,3,3,3,3,3,3,3,3,3,3,3,3,3,3,3,3,3,3,3,2,2,2,1
1,2,2,2,3,3,3,3,3,3,3,3,3,3,3,3,3,3,3,3,3,3,3,3,3,3,3,3,3,3,3,3,3,3,3,2,2,2,1
1,2,2,2,3,3,3,3,3,3,3,3,3,3,3,3,3,3,3,3,3,3,3,3,3,3,3,3,3,3,3,3,3,3,3,2,2,2,1
1,2,2,2,3,3,3,3,3,3,3,3,3,3,3,3,3,3,3,3,3,3,3,3,3,3,3,3,3,3,3,3,3,3,3,2,2,2,1
1,2,2,2,3,3,3,3,3,3,3,3,3,3,3,3,3,3,3,3,3,3,3,3,3,3,3,3,3,3,3,3,3,3,3,2,2,2,1
1,2,2,2,3,3,3,3,3,3,3,3,3,3,3,3,3,3,3,3,3,3,3,3,3,3,3,3,3,3,3,3,3,3,3,2,2,2,1
1,2,2,2,3,3,3,3,3,3,3,3,3,3,3,3,3,3,3,3,3,3,3,3,3,3,3,3,3,3,3,3,3,3,3,2,2,2,1
1,2,2,2,3,3,3,3,3,3,3,3,3,3,3,3,3,3,3,3,3,3,3,3,3,3,3,3,3,3,3,3,3,3,3,2,2,2,1
1,2,2,2,2,2,2,2,2,2,2,2,2,2,2,2,2,2,2,2,2,2,2,2,2,2,2,2,2,2,2,2,2,2,2,2,2,2,1
1,2,2,2,2,2,2,2,2,2,2,2,2,2,2,2,2,2,2,2,2,2,2,2,2,2,2,2,2,2,2,2,2,2,2,2,2,2,1
1,2,2,2,2,2,2,2,2,2,2,2,2,2,2,2,2,2,2,2,2,2,2,2,2,2,2,2,2,2,2,2,2,2,2,2,2,2,1
1,1,1,1,1,1,1,1,1,1,1,1,1,1,1,1,1,1,1,1,1,1,1,1,1,1,1,1,1,1,1,1,1,1,1,1,1,1,1
1,1,1,1,1,1,1,1,1,1,1,1,1,1,1,1,1,1,1,1,1,1,1,1,1,1,1,1,1,1,1,1,1,1,1,1,1,1,1
1,1,1,1,1,1,1,1,1,1,1,1,1,1,1,1,1,1,1,1,1,1,1,1,1,1,1,1,1,1,1,1,1,1,1,1,1,1,1
1,1,1,1,1,1,1,1,1,1,1,1,1,1,1,1,1,1,1,1,1,1,1,1,1,1,1,1,1,1,1,1,1,1,1,1,1,1,1
:endlayer
layer: 1
1,1,1,1,1,1,1,1,1,1,1,1,1,1,1,1,1,1,1,1,1,1,1,1,1,1,1,1,1,1,1,1,1,1,1,1,1,1,1
1,2,2,2,2,2,2,2,2,2,2,2,2,2,2,2,2,2,2,2,2,2,2,2,2,2,2,2,2,2,2,2,2,2,2,2,2,2,1
1,2,2,2,2,2,2,2,2,2,2,2,2,2,2,2,2,2,2,2,2,2,2,2,2,2,2,2,2,2,2,2,2,2,2,2,2,2,1
1,2,2,2,2,2,2,2,2,2,2,2,2,2,2,2,2,2,2,2,2,2,2,2,2,2,2,2,2,2,2,2,2,2,2,2,2,2,1
1,2,2,2,4,4,4,4,4,4,4,4,4,4,4,4,4,4,4,4,4,4,4,4,4,4,4,4,4,4,4,4,4,4,4,2,2,2,1
1,2,2,2,4,3,3,3,3,3,3,3,3,3,3,3,3,3,3,3,3,3,3,3,3,3,3,3,3,3,3,3,3,3,4,2,2,2,1
1,2,2,2,4,3,0,0,0,0,0,0,0,0,0,0,0,0,0,0,0,0,0,0,0,0,0,0,0,0,0,0,0,3,4,2,2,2,1
1,2,2,2,4,3,0,3,3,3,3,3,0,0,0,3,0,3,5,3,6,3,7,3,8,3,9,3,10,3,11,3,0,3,4,2,2,2,1
1,2,2,2,4,3,0,3,0,0,12,3,0,0,0,3,13,3,3,3,3,3,3,3,3,3,3,3,3,3,3,3,0,3,4,2,2,2,1
1,2,2,2,4,3,0,3,0,14,0,3,0,0,0,3,3,3,3,3,3,3,3,3,3,3,3,3,3,3,3,15,0,3,4,2,2,2,1
1,2,2,2,4,3,0,3,0,0,0,3,0,0,0,16,0,0,0,0,0,0,17,3,3,3,3,3,3,3,3,3,0,3,4,2,2,2,1
1,2,2,2,4,3,0,3,18,0,0,16,0,0,0,3,3,3,3,3,3,3,3,3,3,3,3,3,3,3,3,19,0,3,4,2,2,2,1
1,2,2,2,4,3,0,3,0,0,0,3,0,0,0,3,0,3,20,3,0,3,0,3,0,3,0,3,0,3,21,3,0,3,4,2,2,2,1
1,2,2,2,4,3,0,3,22,23,0,3,0,0,0,0,0,0,0,0,0,0,0,0,0,0,0,0,0,0,0,0,0,3,4,2,2,2,1
1,2,2,2,4,3,0,3,3,3,3,3,24,25,26,3,3,3,3,3,3,3,3,3,3,3,3,3,3,3,3,3,0,3,4,2,2,2,1
1,2,2,2,4,3,0,0,27,0,28,0,0,0,0,24,3,3,3,3,3,3,3,3,3,3,3,3,3,3,3,3,0,3,4,2,2,2,1
1,2,2,2,4,3,0,0,0,0,16,0,0,0,0,24,3,3,3,3,3,3,3,3,3,3,3,3,3,3,3,3,0,3,4,2,2,2,1
1,2,2,2,4,3,0,3,3,3,3,3,24,29,26,3,3,3,3,3,3,3,3,3,3,3,3,3,3,3,3,3,0,3,4,2,2,2,1
1,2,2,2,4,3,0,3,0,0,0,3,0,0,0,0,0,0,0,0,0,0,0,0,0,0,0,0,0,0,0,0,0,3,4,2,2,2,1
1,2,2,2,4,3,0,3,0,0,0,16,0,0,0,3,16,3,16,3,16,3,16,3,16,3,16,3,16,3,16,3,0,3,4,2,2,2,1
1,2,2,2,4,3,0,3,30,0,0,3,0,0,0,3,0,3,0,3,0,3,0,3,0,3,31,3,0,3,0,3,0,3,4,2,2,2,1
1,2,2,2,4,3,0,3,3,3,3,3,0,0,0,3,3,3,3,3,3,3,3,3,3,3,3,3,3,3,3,3,0,3,4,2,2,2,1
1,2,2,2,4,3,0,3,0,0,0,3,0,0,0,0,0,0,0,0,0,0,0,0,0,0,0,0,0,0,0,0,0,3,4,2,2,2,1
1,2,2,2,4,3,0,3,0,0,0,3,0,0,0,3,16,3,16,3,16,3,16,3,16,3,16,3,16,3,16,3,0,3,4,2,2,2,1
1,2,2,2,4,3,0,3,0,0,0,16,0,0,0,3,0,3,0,3,0,3,32,3,0,3,0,3,0,3,0,3,0,3,4,2,2,2,1
1,2,2,2,4,3,0,3,0,0,0,3,0,0,0,3,3,3,3,3,3,3,3,3,3,3,3,3,3,3,3,3,0,3,4,2,2,2,1
1,2,2,2,4,3,0,3,33,0,0,3,0,0,0,0,0,0,0,0,0,0,0,0,0,0,0,0,0,0,0,0,0,3,4,2,2,2,1
1,2,2,2,4,3,0,3,3,3,3,3,0,0,0,3,34,3,16,3,16,3,34,3,16,3,34,3,34,3,16,3,0,3,4,2,2,2,1
1,2,2,2,4,3,0,3,0,0,0,3,0,0,0,3,0,3,0,3,0,3,35,3,0,3,0,3,0,3,0,3,0,3,4,2,2,2,1
1,2,2,2,4,3,0,3,0,0,0,16,0,0,0,3,3,3,3,3,3,3,3,3,3,3,3,3,3,3,3,3,0,3,4,2,2,2,1
1,2,2,2,4,3,0,3,0,0,0,3,0,0,0,0,36,0,0,0,0,0,0,0,0,0,0,0,0,0,0,0,0,3,4,2,2,2,1
1,2,2,2,4,3,0,3,3,3,3,3,0,0,0,3,34,3,34,3,34,3,34,3,34,3,16,3,34,3,16,3,0,3,4,2,2,2,1
1,2,2,2,4,3,37,0,0,0,0,0,0,0,0,3,38,3,39,3,0,3,0,3,0,3,0,3,0,3,0,3,40,3,4,2,2,2,1
1,2,2,2,4,3,3,3,3,3,3,3,3,3,3,3,3,3,3,3,3,3,3,3,3,3,3,3,3,3,3,3,3,3,4,2,2,2,1
1,2,2,2,4,4,4,4,4,4,4,4,4,4,4,4,4,4,4,4,4,4,4,4,4,4,4,4,4,4,4,4,4,4,4,2,2,2,1
1,2,2,2,2,2,2,2,2,2,2,2,2,2,2,2,2,2,2,2,2,2,2,2,2,2,2,2,2,2,2,2,2,2,2,2,2,2,1
1,2,2,2,2,2,2,2,2,2,2,2,2,2,2,2,2,2,2,2,2,2,2,2,2,2,2,2,2,2,2,2,2,2,2,2,2,2,1
1,2,2,2,2,2,2,2,2,2,2,2,2,2,2,2,2,2,2,2,2,2,2,2,2,2,2,2,2,2,2,2,2,2,2,2,2,2,1
1,1,1,1,1,1,1,1,1,1,1,1,1,1,1,1,1,1,1,1,1,1,1,1,1,1,1,1,1,1,1,1,1,1,1,1,1,1,1
1,1,1,1,1,1,1,1,1,1,1,1,1,1,1,1,1,1,1,1,1,1,1,1,1,1,1,1,1,1,1,1,1,1,1,1,1,1,1
1,1,1,1,1,1,1,1,1,1,1,1,1,1,1,1,1,1,1,1,1,1,1,1,1,1,1,1,1,1,1,1,1,1,1,1,1,1,1
1,1,1,1,1,1,1,1,1,1,1,1,1,1,1,1,1,1,1,1,1,1,1,1,1,1,1,1,1,1,1,1,1,1,1,1,1,1,1
:endlayer
layer: 2
1,1,1,1,1,1,1,1,1,1,1,1,1,1,1,1,1,1,1,1,1,1,1,1,1,1,1,1,1,1,1,1,1,1,1,1,1,1,1
1,2,2,2,2,2,2,2,2,2,2,2,2,2,2,2,2,2,2,2,2,2,2,2,2,2,2,2,2,2,2,2,2,2,2,2,2,2,1
1,2,2,2,2,2,2,2,2,2,2,2,2,2,2,2,2,2,2,2,2,2,2,2,2,2,2,2,2,2,2,2,2,2,2,2,2,2,1
1,2,2,2,2,2,2,2,2,2,2,2,2,2,2,2,2,2,2,2,2,2,2,2,2,2,2,2,2,2,2,2,2,2,2,2,2,2,1
1,2,2,2,4,4,4,4,4,4,4,4,4,4,4,4,4,4,4,4,4,4,4,4,4,4,4,4,4,4,4,4,4,4,4,2,2,2,1
1,2,2,2,4,3,3,3,3,3,3,3,3,3,3,3,3,3,3,3,3,3,3,3,3,3,3,3,3,3,3,3,3,3,4,2,2,2,1
1,2,2,2,4,3,0,0,0,0,0,0,0,0,0,0,0,0,0,0,0,0,0,0,0,0,0,0,0,0,0,0,0,3,4,2,2,2,1
1,2,2,2,4,3,0,3,3,3,3,3,0,0,0,3,0,3,0,3,0,3,0,3,0,3,0,3,0,3,0,3,0,3,4,2,2,2,1
1,2,2,2,4,3,0,3,0,0,0,3,0,0,0,3,0,3,3,3,3,3,3,3,3,3,3,3,3,3,3,3,0,3,4,2,2,2,1
1,2,2,2,4,3,0,3,0,0,0,3,0,0,0,3,3,3,3,3,3,3,3,3,3,3,3,3,3,3,3,0,0,3,4,2,2,2,1
1,2,2,2,4,3,0,3,0,0,0,3,0,0,0,41,0,0,0,0,0,0,0,3,3,3,3,3,3,3,3,3,0,3,4,2,2,2,1
1,2,2,2,4,3,0,3,0,0,0,41,0,0,0,3,3,3,3,3,3,3,3,3,3,3,3,3,3,3,3,0,0,3,4,2,2,2,1
1,2,2,2,4,3,0,3,0,0,0,3,0,0,0,3,0,3,0,3,0,3,0,3,0,3,0,3,0,3,0,3,0,3,4,2,2,2,1
1,2,2,2,4,3,0,3,0,0,0,3,0,0,0,0,0,0,0,0,0,0,0,0,0,0,0,0,0,0,0,0,42,3,4,2,2,2,1
1,2,2,2,4,3,0,3,3,3,3,3,24,41,26,3,3,3,3,3,3,3,3,3,3,3,3,3,3,3,3,3,0,3,4,2,2,2,1
1,2,2,2,4,3,0,0,0,0,43,0,0,0,0,0,24,3,3,3,3,3,3,3,3,3,3,3,3,3,3,3,0,3,4,2,2,2,1
1,2,2,2,4,3,0,0,0,0,44,0,0,0,0,0,24,3,3,3,3,3,3,3,3,3,3,3,3,3,3,3,0,3,4,2,2,2,1
1,2,2,2,4,3,0,3,3,3,3,3,24,45,26,3,3,3,3,3,3,3,3,3,3,3,3,3,3,3,3,3,0,3,4,2,2,2,1
1,2,2,2,4,3,0,3,0,0,0,3,0,0,0,0,0,0,0,0,0,0,0,0,0,0,0,0,0,0,0,0,42,3,4,2,2,2,1
1,2,2,2,4,3,0,3,0,0,0,41,0,0,0,3,41,3,41,3,41,3,41,3,41,3,41,3,41,3,41,3,0,3,4,2,2,2,1
1,2,2,2,4,3,0,3,0,0,0,3,0,0,0,3,0,3,0,3,0,3,0,3,0,3,0,3,0,3,0,3,0,3,4,2,2,2,1
1,2,2,2,4,3,0,3,3,3,3,3,0,0,0,3,3,3,3,3,3,3,3,3,3,3,3,3,3,3,3,3,0,3,4,2,2,2,1
1,2,2,2,4,3,0,3,0,0,0,3,0,0,0,0,0,0,0,0,0,0,0,0,0,0,0,0,0,0,0,0,42,3,4,2,2,2,1
1,2,2,2,4,3,0,3,0,0,0,3,0,0,0,3,41,3,41,3,41,3,41,3,41,3,41,3,41,3,41,3,0,3,4,2,2,2,1
1,2,2,2,4,3,0,3,0,0,0,41,0,0,0,3,0,3,0,3,0,3,0,3,0,3,0,3,0,3,0,3,0,3,4,2,2,2,1
1,2,2,2,4,3,0,3,0,0,0,3,0,0,0,3,3,3,3,3,3,3,3,3,3,3,3,3,3,3,3,3,0,3,4,2,2,2,1
1,2,2,2,4,3,0,3,0,0,0,3,0,0,0,0,0,0,0,0,0,0,0,0,0,0,0,0,0,0,0,0,42,3,4,2,2,2,1
1,2,2,2,4,3,0,3,3,3,3,3,0,0,0,3,46,3,41,3,41,3,46,3,41,3,46,3,46,3,41,3,0,3,4,2,2,2,1
1,2,2,2,4,3,0,3,0,0,0,3,0,0,0,3,0,3,0,3,0,3,0,3,0,3,0,3,0,3,0,3,0,3,4,2,2,2,1
1,2,2,2,4,3,0,3,0,0,0,41,0,0,0,3,3,3,3,3,3,3,3,3,3,3,3,3,3,3,3,3,0,3,4,2,2,2,1
1,2,2,2,4,3,0,3,0,0,0,3,0,0,0,47,0,47,0,47,0,47,0,47,0,47,0,47,0,47,0,47,42,3,4,2,2,2,1
1,2,2,2,4,3,0,3,3,3,3,3,0,0,0,3,46,3,46,3,46,3,46,3,46,3,41,3,46,3,41,3,0,3,4,2,2,2,1
1,2,2,2,4,3,0,0,0,0,0,0,0,0,0,3,0,3,0,3,0,3,0,3,0,3,0,3,0,3,0,3,0,3,4,2,2,2,1
1,2,2,2,4,3,3,3,3,3,3,3,3,3,3,3,3,3,3,3,3,3,3,3,3,3,3,3,3,3,3,3,3,3,4,2,2,2,1
1,2,2,2,4,4,4,4,4,4,4,4,4,4,4,4,4,4,4,4,4,4,4,4,4,4,4,4,4,4,4,4,4,4,4,2,2,2,1
1,2,2,2,2,2,2,2,2,2,2,2,2,2,2,2,2,2,2,2,2,2,2,2,2,2,2,2,2,2,2,2,2,2,2,2,2,2,1
1,2,2,2,2,2,2,2,2,2,2,2,2,2,2,2,2,2,2,2,2,2,2,2,2,2,2,2,2,2,2,2,2,2,2,2,2,2,1
1,2,2,2,2,2,2,2,2,2,2,2,2,2,2,2,2,2,2,2,2,2,2,2,2,2,2,2,2,2,2,2,2,2,2,2,2,2,1
1,1,1,1,1,1,1,1,1,1,1,1,1,1,1,1,1,1,1,1,1,1,1,1,1,1,1,1,1,1,1,1,1,1,1,1,1,1,1
1,1,1,1,1,1,1,1,1,1,1,1,1,1,1,1,1,1,1,1,1,1,1,1,1,1,1,1,1,1,1,1,1,1,1,1,1,1,1
1,1,1,1,1,1,1,1,1,1,1,1,1,1,1,1,1,1,1,1,1,1,1,1,1,1,1,1,1,1,1,1,1,1,1,1,1,1,1
1,1,1,1,1,1,1,1,1,1,1,1,1,1,1,1,1,1,1,1,1,1,1,1,1,1,1,1,1,1,1,1,1,1,1,1,1,1,1
:endlayer
layer: 3
1,1,1,1,1,1,1,1,1,1,1,1,1,1,1,1,1,1,1,1,1,1,1,1,1,1,1,1,1,1,1,1,1,1,1,1,1,1,1
1,2,2,2,2,2,2,2,2,2,2,2,2,2,2,2,2,2,2,2,2,2,2,2,2,2,2,2,2,2,2,2,2,2,2,2,2,2,1
1,2,2,2,2,2,2,2,2,2,2,2,2,2,2,2,2,2,2,2,2,2,2,2,2,2,2,2,2,2,2,2,2,2,2,2,2,2,1
1,2,2,2,2,2,2,2,2,2,2,2,2,2,2,2,2,2,2,2,2,2,2,2,2,2,2,2,2,2,2,2,2,2,2,2,2,2,1
1,2,2,2,3,3,3,3,3,3,3,3,3,3,3,3,3,3,3,3,3,3,3,3,3,3,3,3,3,3,3,3,3,3,3,2,2,2,1
1,2,2,2,3,3,3,3,3,3,3,3,3,3,3,3,3,3,3,3,3,3,3,3,3,3,3,3,3,3,3,3,3,3,3,2,2,2,1
1,2,2,2,3,3,48,0,0,0,0,0,0,49,0,0,0,0,0,0,0,0,0,0,0,0,0,0,0,0,0,0,42,3,3,2,2,2,1
1,2,2,2,3,3,0,3,3,3,3,3,48,0,42,3,3,3,3,3,3,3,3,3,3,3,3,3,3,3,3,3,0,3,3,2,2,2,1
1,2,2,2,3,3,0,3,0,0,0,3,0,0,0,3,3,3,3,3,3,3,3,3,3,3,3,3,3,3,3,3,0,3,3,2,2,2,1
1,2,2,2,3,3,0,3,0,0,0,3,0,0,0,3,3,3,3,3,3,3,3,3,3,3,3,3,3,3,3,3,0,3,3,2,2,2,1
1,2,2,2,3,3,0,3,0,0,0,3,0,0,50,3,3,3,3,3,3,3,3,3,3,3,3,3,3,3,3,3,0,3,3,2,2,2,1
1,2,2,2,3,3,0,3,0,0,0,3,51,0,0,3,3,3,3,3,3,3,3,3,3,3,3,3,3,3,3,3,0,3,3,2,2,2,1
1,2,2,2,3,3,0,3,0,0,0,3,0,0,0,3,3,3,3,3,3,3,3,3,3,3,3,3,3,3,3,3,0,3,3,2,2,2,1
1,2,2,2,3,3,0,3,0,0,0,3,0,0,0,3,3,3,3,3,3,3,3,3,3,3,3,3,3,3,3,3,0,3,3,2,2,2,1
1,2,2,2,3,3,42,3,3,3,3,3,24,52,26,3,3,3,3,3,3,3,3,3,3,3,3,3,3,3,3,3,0,3,3,2,2,2,1
1,2,2,2,3,3,0,49,0,0,53,0,0,0,0,0,0,24,3,3,3,3,3,3,3,3,3,3,3,3,3,3,0,3,3,2,2,2,1
1,2,2,2,3,3,0,47,0,0,53,0,0,0,0,0,0,24,3,3,3,3,3,3,3,3,3,3,3,3,3,3,0,3,3,2,2,2,1
1,2,2,2,3,3,42,3,3,3,3,3,24,52,26,3,3,3,3,3,3,3,3,3,3,3,3,3,3,3,3,3,0,3,3,2,2,2,1
1,2,2,2,3,3,0,3,3,3,3,3,0,0,0,3,54,3,54,3,54,3,54,3,54,3,54,3,54,3,54,3,0,3,3,2,2,2,1
1,2,2,2,3,3,0,3,3,3,3,3,51,0,0,3,3,3,3,3,3,3,3,3,3,3,3,3,3,3,3,3,0,3,3,2,2,2,1
1,2,2,2,3,3,0,3,3,3,3,3,0,0,42,3,3,3,3,3,3,3,3,3,3,3,3,3,3,3,3,3,0,3,3,2,2,2,1
1,2,2,2,3,3,0,3,3,3,3,3,0,0,0,3,3,3,3,3,3,3,3,3,3,3,3,3,3,3,3,3,0,3,3,2,2,2,1
1,2,2,2,3,3,0,3,3,3,3,3,48,0,0,3,54,3,54,3,54,3,54,3,54,3,54,3,54,3,54,3,0,3,3,2,2,2,1
1,2,2,2,3,3,0,3,3,3,3,3,0,0,0,3,3,3,3,3,3,3,3,3,3,3,3,3,3,3,3,3,0,3,3,2,2,2,1
1,2,2,2,3,3,0,3,3,3,3,3,51,0,42,3,3,3,3,3,3,3,3,3,3,3,3,3,3,3,3,3,0,3,3,2,2,2,1
1,2,2,2,3,3,0,3,3,3,3,3,0,0,0,3,3,3,3,3,3,3,3,3,3,3,3,3,3,3,3,3,0,3,3,2,2,2,1
1,2,2,2,3,3,0,3,3,3,3,3,0,0,0,3,55,3,54,3,54,3,55,3,54,3,55,3,55,3,54,3,0,3,3,2,2,2,1
1,2,2,2,3,3,0,3,3,3,3,3,48,0,0,3,3,3,3,3,3,3,3,3,3,3,3,3,3,3,3,3,0,3,3,2,2,2,1
1,2,2,2,3,3,0,3,3,3,3,3,0,0,42,3,3,3,3,3,3,3,3,3,3,3,3,3,3,3,3,3,0,3,3,2,2,2,1
1,2,2,2,3,3,0,3,3,3,3,3,51,0,0,3,3,3,3,3,3,3,3,3,3,3,3,3,3,3,3,3,0,3,3,2,2,2,1
1,2,2,2,3,3,0,3,3,3,3,3,0,0,0,3,55,3,55,3,55,3,55,3,55,3,54,3,55,3,54,3,0,3,3,2,2,2,1
1,2,2,2,3,3,0,3,3,3,3,3,48,0,42,3,3,3,3,3,3,3,3,3,3,3,3,3,3,3,3,3,0,3,3,2,2,2,1
1,2,2,2,0,3,47,0,0,0,0,49,0,0,0,3,3,3,3,3,3,3,3,3,3,3,3,3,3,3,3,3,42,3,3,2,2,2,1
1,2,2,2,3,3,3,3,3,3,3,3,3,3,3,3,3,3,3,3,3,3,3,3,3,3,3,3,3,3,3,3,3,3,3,2,2,2,1
1,2,2,2,3,3,3,3,3,3,3,3,3,3,3,3,3,3,3,3,3,3,3,3,3,3,3,3,3,3,3,3,3,3,3,2,2,2,1
1,2,2,2,2,2,2,2,2,2,2,2,2,2,2,2,2,2,2,2,2,2,2,2,2,2,2,2,2,2,2,2,2,2,2,2,2,2,1
1,2,2,2,2,2,2,2,2,2,2,2,2,2,2,2,2,2,2,2,2,2,2,2,2,2,2,2,2,2,2,2,2,2,2,2,2,2,1
1,2,2,2,2,2,2,2,2,2,2,2,2,2,2,2,2,2,2,2,2,2,2,2,2,2,2,2,2,2,2,2,2,2,2,2,2,2,1
1,1,1,1,1,1,1,1,1,1,1,1,1,1,1,1,1,1,1,1,1,1,1,1,1,1,1,1,1,1,1,1,1,1,1,1,1,1,1
1,1,1,1,1,1,1,1,1,1,1,1,1,1,1,1,1,1,1,1,1,1,1,1,1,1,1,1,1,1,1,1,1,1,1,1,1,1,1
1,1,1,1,1,1,1,1,1,1,1,1,1,1,1,1,1,1,1,1,1,1,1,1,1,1,1,1,1,1,1,1,1,1,1,1,1,1,1
1,1,1,1,1,1,1,1,1,1,1,1,1,1,1,1,1,1,1,1,1,1,1,1,1,1,1,1,1,1,1,1,1,1,1,1,1,1,1
:endlayer
layer: 4
56,56,56,56,56,56,56,56,56,56,56,56,56,56,56,56,56,56,56,56,56,56,56,56,56,56,56,56,56,56,56,56,56,56,56,56,56,56,56
56,56,56,56,56,2,2,2,2,2,2,2,2,2,2,2,2,2,2,2,2,2,2,2,2,2,2,2,2,2,2,2,2,2,56,56,56,56,56
56,56,56,56,2,2,2,2,2,2,2,2,2,2,2,2,2,2,2,2,2,2,2,2,2,2,2,2,2,2,2,2,2,2,2,56,56,56,56
56,56,56,2,2,2,2,2,2,2,2,2,2,2,2,2,2,2,2,2,2,2,2,2,2,2,2,2,2,2,2,2,2,2,2,2,56,56,56
56,56,2,2,3,3,3,3,3,3,3,3,3,3,3,3,3,3,3,3,3,3,3,3,3,3,3,3,3,3,3,3,3,3,3,2,2,56,56
56,2,2,2,3,3,3,3,3,3,3,3,3,3,3,3,3,3,3,3,3,3,3,3,3,3,3,3,3,3,3,3,3,3,3,2,2,2,56
56,2,2,2,3,3,3,3,3,3,3,3,3,3,3,3,3,3,3,3,3,3,3,3,3,3,3,3,3,3,3,3,3,3,3,2,2,2,56
56,2,2,2,3,3,3,3,3,3,3,3,3,3,3,3,3,3,3,3,3,3,3,3,3,3,3,3,3,3,3,3,3,3,3,2,2,2,56
56,2,2,2,3,3,3,3,3,3,3,3,3,3,3,3,3,3,3,3,3,3,3,3,3,3,3,3,3,3,3,3,3,3,3,2,2,2,56
56,2,2,2,3,3,3,3,3,3,3,3,3,3,3,3,3,3,3,3,3,3,3,3,3,3,3,3,3,3,3,3,3,3,3,2,2,2,56
56,2,2,2,3,3,3,3,3,3,3,3,3,3,3,3,3,3,3,3,3,3,3,3,3,3,3,3,3,3,3,3,3,3,3,2,2,2,56
56,2,2,2,3,3,3,3,3,3,3,3,3,3,3,3,3,3,3,3,3,3,3,3,3,3,3,3,3,3,3,3,3,3,3,2,2,2,56
56,2,2,2,3,3,3,3,3,3,3,3,3,3,3,3,3,3,3,3,3,3,3,3,3,3,3,3,3,3,3,3,3,3,3,2,2,2,56
56,2,2,2,3,3,3,3,3,3,3,3,3,3,3,3,3,3,3,3,3,3,3,3,3,3,3,3,3,3,3,3,3,3,3,2,2,2,56
56,2,2,2,3,3,3,3,3,3,3,3,3,3,3,3,3,3,3,3,3,3,3,3,3,3,3,3,3,3,3,3,3,3,3,2,2,2,56
56,2,2,2,3,3,3,3,3,3,3,3,3,3,3,0,0,0,24,3,3,3,3,3,3,3,3,3,3,3,3,3,3,3,3,2,2,2,56
56,2,2,2,3,3,3,3,3,3,3,3,3,3,3,0,0,0,24,3,3,3,3,3,3,3,3,3,3,3,3,3,3,3,3,2,2,2,56
56,2,2,2,3,3,3,3,3,3,3,3,3,3,3,3,3,3,3,3,3,3,3,3,3,3,3,3,3,3,3,3,3,3,3,2,2,2,56
56,2,2,2,3,3,3,3,3,3,3,3,3,3,3,3,3,3,3,3,3,3,3,3,3,3,3,3,3,3,3,3,3,3,3,2,2,2,56
56,2,2,2,3,3,3,3,3,3,3,3,3,3,3,3,3,3,3,3,3,3,3,3,3,3,3,3,3,3,3,3,3,3,3,2,2,2,56
56,2,2,2,3,3,3,3,3,3,3,3,3,3,3,3,3,3,3,3,3,3,3,3,3,3,3,3,3,3,3,3,3,3,3,2,2,2,56
56,2,2,2,3,3,3,3,3,3,3,3,3,3,3,3,3,3,3,3,3,3,3,3,3,3,3,3,3,3,3,3,3,3,3,2,2,2,56
56,2,2,2,3,3,3,3,3,3,3,3,3,3,3,3,3,3,3,3,3,3,3,3,3,3,3,3,3,3,3,3,3,3,3,2,2,2,56
56,2,2,2,3,3,3,3,3,3,3,3,3,3,3,3,3,3,3,3,3,3,3,3,3,3,3,3,3,3,3,3,3,3,3,2,2,2,56
56,2,2,2,3,3,3,3,3,3,3,3,3,3,3,3,3,3,3,3,3,3,3,3,3,3,3,3,3,3,3,3,3,3,3,2,2,2,56
56,2,2,2,3,3,3,3,3,3,3,3,3,3,3,3,3,3,3,3,3,3,3,3,3,3,3,3,3,3,3,3,3,3,3,2,2,2,56
56,2,2,2,3,3,3,3,3,3,3,3,3,3,3,3,3,3,3,3,3,3,3,3,3,3,3,3,3,3,3,3,3,3,3,2,2,2,56
56,2,2,2,3,3,3,3,3,3,3,3,3,3,3,3,3,3,3,3,3,3,3,3,3,3,3,3,3,3,3,3,3,3,3,2,2,2,56
56,2,2,2,3,3,3,3,3,3,3,3,3,3,3,3,3,3,3,3,3,3,3,3,3,3,3,3,3,3,3,3,3,3,3,2,2,2,56
56,2,2,2,3,3,3,3,3,3,3,3,3,3,3,3,3,3,3,3,3,3,3,3,3,3,3,3,3,3,3,3,3,3,3,2,2,2,56
56,2,2,2,3,3,3,3,3,3,3,3,3,3,3,3,3,3,3,3,3,3,3,3,3,3,3,3,3,3,3,3,3,3,3,2,2,2,56
56,2,2,2,3,3,3,3,3,3,3,3,3,3,3,3,3,3,3,3,3,3,3,3,3,3,3,3,3,3,3,3,3,3,3,2,2,2,56
56,2,2,2,0,3,3,3,3,3,3,3,3,3,3,3,3,3,3,3,3,3,3,3,3,3,3,3,3,3,3,3,3,3,3,2,2,2,56
56,2,2,2,3,3,3,3,3,3,3,3,3,3,3,3,3,3,3,3,3,3,3,3,3,3,3,3,3,3,3,3,3,3,3,2,2,2,56
56,56,2,2,3,3,3,3,3,3,3,3,3,3,3,3,3,3,3,3,3,3,3,3,3,3,3,3,3,3,3,3,3,3,3,2,2,56,56
56,56,56,2,2,2,2,2,2,2,2,2,2,2,2,2,2,2,2,2,3,2,2,2,2,2,2,2,2,2,2,2,2,2,2,2,56,56,56
56,56,56,56,2,2,2,2,2,2,2,2,2,2,2,2,2,3,3,3,3,2,2,2,2,2,2,2,2,2,2,2,2,2,2,56,56,56,56
56,56,56,56,56,2,2,2,2,2,2,2,2,2,2,2,2,2,3,3,3,2,2,2,2,2,2,2,2,2,2,2,2,2,56,56,56,56,56
56,56,56,56,56,56,56,56,56,56,56,56,56,56,56,56,56,3,57,57,57,3,56,56,56,56,56,56,56,56,56,56,56,56,56,56,56,56,56
56,56,56,56,56,56,56,56,56,56,56,56,56,56,56,56,56,56,57,57,57,56,56,56,56,56,56,56,56,56,56,56,56,56,56,56,56,56,56
56,56,56,56,56,56,56,56,56,56,56,56,56,56,56,56,58,56,57,57,57,56,58,56,56,56,56,56,56,56,56,56,56,56,56,56,56,56,56
56,56,56,56,56,56,56,56,56,56,56,56,56,56,56,56,56,56,57,57,57,56,56,56,56,56,56,56,56,56,56,56,56,56,56,56,56,56,56
:endlayer
layer: 5
0,0,0,0,0,0,0,0,0,0,0,0,0,0,0,0,0,0,0,0,0,0,0,0,0,0,0,0,0,0,0,0,0,0,0,0,0,0,0
0,0,0,0,0,0,0,0,0,0,0,0,0,0,0,0,0,0,0,0,0,0,0,0,0,0,0,0,0,0,0,0,0,0,0,0,0,0,0
0,0,59,0,0,0,0,0,0,0,0,0,0,0,0,0,0,0,0,0,0,0,0,0,0,0,0,0,0,0,0,0,0,0,0,0,60,0,0
0,0,0,0,0,0,0,3,3,3,3,3,3,3,3,3,3,3,3,3,3,3,3,3,3,3,3,3,3,3,3,3,0,0,0,0,0,0,0
0,0,0,0,0,0,3,3,3,4,4,4,4,4,4,4,3,3,3,3,3,3,3,4,4,4,4,4,4,4,3,3,3,0,0,0,0,0,0
0,0,0,0,0,3,3,3,4,4,4,4,61,4,4,4,3,3,3,3,3,3,3,4,4,4,62,4,4,4,4,3,3,3,0,0,0,0,0
0,0,0,0,3,3,3,4,4,4,3,3,3,3,3,3,3,3,3,3,3,3,3,3,3,3,3,3,3,4,4,4,3,3,3,0,0,0,0
0,0,0,3,3,3,4,4,4,3,3,3,3,3,3,3,3,3,3,3,3,3,3,3,3,3,3,3,3,3,4,4,4,3,3,3,0,0,0
0,0,0,3,3,4,4,4,3,3,3,3,3,3,3,3,3,3,3,3,3,3,3,3,3,3,3,3,3,3,3,4,4,4,3,3,0,0,0
0,0,0,3,4,4,4,3,3,3,3,3,3,3,3,3,3,3,3,3,3,3,3,3,3,3,3,3,3,3,3,3,4,4,4,3,0,0,0
0,0,0,3,4,4,3,3,3,3,3,3,3,3,3,3,3,3,3,3,3,3,3,3,3,3,3,3,3,3,3,3,3,4,4,3,0,0,0
0,0,0,3,4,4,3,3,3,3,3,3,3,3,3,3,3,3,3,3,3,3,3,3,3,3,3,3,3,3,3,3,3,4,4,3,0,0,0
0,0,0,3,63,4,3,3,3,3,3,3,3,3,3,3,3,3,3,3,3,3,3,3,3,3,3,3,3,3,3,3,3,64,4,3,0,0,0
0,0,0,3,4,4,3,3,3,3,3,3,3,3,3,3,3,3,3,3,3,3,3,3,3,3,3,3,3,3,3,3,3,4,4,3,0,0,0
0,0,0,3,4,4,3,3,3,3,3,3,3,3,3,3,3,3,3,3,3,3,3,3,3,3,3,3,3,3,3,3,3,4,4,3,0,0,0
0,0,0,3,4,4,3,3,3,3,3,3,3,3,3,3,0,0,0,24,3,3,3,3,3,3,3,3,3,3,3,3,3,4,4,3,0,0,0
0,0,0,3,3,3,3,3,3,3,3,3,3,3,3,3,0,0,0,24,3,3,3,3,3,3,3,3,3,3,3,3,3,3,3,3,0,0,0
0,0,0,3,3,3,3,3,3,3,3,3,3,3,3,3,3,3,3,3,3,3,3,3,3,3,3,3,3,3,3,3,3,3,3,3,0,0,0
0,0,0,3,3,3,3,3,3,3,3,3,3,3,3,3,3,3,3,3,3,3,3,3,3,3,3,3,3,3,3,3,3,3,3,3,0,0,0
0,0,0,3,3,3,3,3,3,3,3,3,3,3,3,3,3,3,3,3,3,3,3,3,3,3,3,3,3,3,3,3,3,3,3,3,0,0,0
0,0,0,3,3,3,3,3,3,3,3,3,3,3,3,3,3,3,3,3,3,3,3,3,3,3,3,3,3,3,3,3,3,3,3,3,0,0,0
0,0,0,3,3,3,3,3,3,3,3,3,3,3,3,3,3,3,3,3,3,3,3,3,3,3,3,3,3,3,3,3,3,3,3,3,0,0,0
0,0,0,3,3,3,3,3,3,3,3,3,3,3,3,3,3,3,3,3,3,3,3,3,3,3,3,3,3,3,3,3,3,3,3,3,0,0,0
0,0,0,3,4,4,3,3,3,3,3,3,3,3,3,3,3,3,3,3,3,3,3,3,3,3,3,3,3,3,3,3,3,4,4,3,0,0,0
0,0,0,3,4,4,3,3,3,3,3,3,3,3,3,3,3,3,3,3,3,3,3,3,3,3,3,3,3,3,3,3,3,4,4,3,0,0,0
0,0,0,3,4,65,3,3,3,3,3,3,3,3,3,3,3,3,3,3,3,3,3,3,3,3,3,3,3,3,3,3,3,4,4,3,0,0,0
0,0,0,3,4,4,3,3,3,3,3,3,3,3,3,3,3,3,3,3,3,3,3,3,3,3,3,3,3,3,3,3,3,66,4,3,0,0,0
0,0,0,3,4,4,3,3,3,3,3,3,3,3,3,3,3,3,3,3,3,3,3,3,3,3,3,3,3,3,3,3,3,4,4,3,0,0,0
0,0,0,3,4,4,3,3,3,3,3,3,3,3,3,3,3,3,3,3,3,3,3,3,3,3,3,3,3,3,3,3,3,4,4,3,0,0,0
0,0,0,3,4,4,4,3,3,3,3,3,3,3,3,3,3,3,3,3,3,3,3,3,3,3,3,3,3,3,3,3,4,4,4,3,0,0,0
0,0,0,3,3,4,4,4,3,3,3,3,3,3,3,3,3,67,67,67,67,67,3,3,3,3,3,3,3,3,3,4,4,4,3,3,0,0,0
0,0,0,3,3,3,4,4,4,3,3,3,3,3,3,3,3,0,0,0,0,0,3,3,3,3,3,3,3,3,4,4,4,3,3,3,0,0,0
0,0,0,0,3,3,3,4,4,4,3,3,3,3,3,3,3,0,0,0,0,0,3,3,3,3,3,3,3,4,4,4,3,3,3,0,0,0,0
0,0,0,0,0,3,3,3,4,4,4,4,4,4,4,4,3,68,69,70,71,72,3,4,4,4,4,73,4,4,4,3,3,3,0,0,0,0,0
0,0,0,0,0,0,3,3,3,4,4,74,4,4,4,4,3,0,0,0,0,0,3,4,4,4,4,4,4,4,3,3,3,0,0,0,0,0,0
0,0,0,0,0,0,0,3,3,3,3,3,3,3,3,3,3,0,0,0,0,0,3,3,3,3,3,3,3,3,3,3,0,0,0,0,0,0,0
0,0,0,0,0,0,0,0,0,0,0,0,0,0,0,3,54,0,0,0,0,0,0,3,0,0,0,0,0,0,0,0,0,0,0,0,0,0,0
0,0,0,0,0,0,0,0,0,0,0,0,0,0,0,0,3,75,76,77,78,79,3,0,0,0,0,0,0,0,0,0,0,0,0,0,0,0,0
0,0,0,0,0,0,0,0,0,0,0,0,0,0,0,0,80,80,0,0,0,80,80,0,0,0,0,0,0,0,0,0,0,0,0,0,0,0,0
0,0,0,0,0,0,0,0,0,0,0,0,0,0,0,0,0,0,0,0,0,0,0,0,0,0,0,0,0,0,0,0,0,0,0,0,0,0,0
0,81,0,0,0,0,0,0,0,0,0,0,0,0,0,0,58,0,0,0,0,0,58,0,0,0,0,0,0,0,0,0,0,0,0,0,0,82,0
0,0,0,0,0,0,0,0,0,0,0,0,0,0,0,0,0,0,0,0,0,0,0,0,0,0,0,0,0,0,0,0,0,0,0,0,0,0,0
:endlayer
layer: 6
0,0,0,0,0,0,0,0,0,0,0,0,0,0,0,0,0,0,0,0,0,0,0,0,0,0,0,0,0,0,0,0,0,0,0,0,0,0,0
0,0,0,0,0,0,0,0,0,0,0,0,0,0,0,0,0,0,0,0,0,0,0,0,0,0,0,0,0,0,0,0,0,0,0,0,0,0,0
0,0,0,0,0,0,0,0,0,0,0,0,0,0,0,0,0,0,0,0,0,0,0,0,0,0,0,0,0,0,0,0,0,0,0,0,0,0,0
0,0,0,0,0,0,0,0,3,3,3,3,3,3,3,3,3,3,3,3,3,3,3,3,3,3,3,3,3,3,3,0,0,0,0,0,0,0,0
0,0,0,0,0,0,0,3,3,4,4,4,4,4,4,4,3,3,3,3,3,3,3,4,4,4,4,4,4,4,3,3,0,0,0,0,0,0,0
0,0,0,0,0,0,3,3,4,4,4,4,4,4,4,4,3,3,3,3,3,3,3,4,4,4,4,4,4,4,4,3,3,0,0,0,0,0,0
0,0,0,0,0,3,3,4,4,4,3,3,3,3,3,3,3,3,3,3,3,3,3,3,3,3,3,3,3,4,4,4,3,3,0,0,0,0,0
0,0,0,0,3,3,4,4,4,3,3,3,3,3,3,3,3,3,3,3,3,3,3,3,3,3,3,3,3,3,4,4,4,3,3,0,0,0,0
0,0,0,3,3,4,4,4,3,3,3,3,3,3,3,3,3,3,3,3,3,3,3,3,3,3,3,3,3,3,3,4,4,4,3,3,0,0,0
0,0,0,3,4,4,4,3,3,3,3,3,3,3,3,3,3,3,3,3,3,3,3,3,3,3,3,3,3,3,3,3,4,4,4,3,0,0,0
0,0,0,3,4,4,3,3,3,3,3,3,3,3,3,3,3,3,3,3,3,3,3,3,3,3,3,3,3,3,3,3,3,4,4,3,0,0,0
0,0,0,3,4,4,3,3,3,3,3,3,3,3,3,3,3,3,3,3,3,3,3,3,3,3,3,3,3,3,3,3,3,4,4,3,0,0,0
0,0,0,3,4,4,3,3,3,3,3,3,3,3,3,3,3,3,3,3,3,3,3,3,3,3,3,3,3,3,3,3,3,4,4,3,0,0,0
0,0,0,3,4,4,3,3,3,3,3,3,3,3,3,3,3,3,3,3,3,3,3,3,3,3,3,3,3,3,3,3,3,4,4,3,0,0,0
0,0,0,3,4,4,3,3,3,3,3,3,3,3,3,3,3,3,3,3,3,3,3,3,3,3,3,3,3,3,3,3,3,4,4,3,0,0,0
0,0,0,3,4,4,3,3,3,3,3,3,3,3,3,3,3,0,0,0,24,3,3,3,3,3,3,3,3,3,3,3,3,4,4,3,0,0,0
0,0,0,3,3,3,3,3,3,3,3,3,3,3,3,3,3,0,0,0,24,3,3,3,3,3,3,3,3,3,3,3,3,3,3,3,0,0,0
0,0,0,3,3,3,3,3,3,3,3,3,3,3,3,3,3,3,3,3,3,3,3,3,3,3,3,3,3,3,3,3,3,3,3,3,0,0,0
0,0,0,3,3,3,3,3,3,3,3,3,3,3,3,3,3,3,3,3,3,3,3,3,3,3,3,3,3,3,3,3,3,3,3,3,0,0,0
0,0,0,3,3,3,3,3,3,3,3,3,3,3,3,3,3,3,3,3,3,3,3,3,3,3,3,3,3,3,3,3,3,3,3,3,0,0,0
0,0,0,3,3,3,3,3,3,3,3,3,3,3,3,3,3,3,3,3,3,3,3,3,3,3,3,3,3,3,3,3,3,3,3,3,0,0,0
0,0,0,3,3,3,3,3,3,3,3,3,3,3,3,3,3,3,3,3,3,3,3,3,3,3,3,3,3,3,3,3,3,3,3,3,0,0,0
0,0,0,3,3,3,3,3,3,3,3,3,3,3,3,3,3,3,3,3,3,3,3,3,3,3,3,3,3,3,3,3,3,3,3,3,0,0,0
0,0,0,3,4,4,3,3,3,3,3,3,3,3,3,3,3,3,3,3,3,3,3,3,3,3,3,3,3,3,3,3,3,4,4,3,0,0,0
0,0,0,3,4,4,3,3,3,3,3,3,3,3,3,3,3,3,3,3,3,3,3,3,3,3,3,3,3,3,3,3,3,4,4,3,0,0,0
0,0,0,3,4,4,3,3,3,3,3,3,3,3,3,3,3,3,3,3,3,3,3,3,3,3,3,3,3,3,3,3,3,4,4,3,0,0,0
0,0,0,3,4,4,3,3,3,3,3,3,3,3,3,3,3,3,3,3,3,3,3,3,3,3,3,3,3,3,3,3,3,4,4,3,0,0,0
0,0,0,3,4,4,3,3,3,3,3,3,3,3,3,3,3,3,3,3,3,3,3,3,3,3,3,3,3,3,3,3,3,4,4,3,0,0,0
0,0,0,3,4,4,3,3,3,3,3,3,3,3,3,3,3,3,3,3,3,3,3,3,3,3,3,3,3,3,3,3,3,4,4,3,0,0,0
0,0,0,3,4,4,4,3,3,3,3,3,3,3,3,3,3,3,67,67,67,3,3,3,3,3,3,3,3,3,3,3,4,4,4,3,0,0,0
0,0,0,3,3,4,4,4,3,3,3,3,3,3,3,3,3,0,0,0,0,0,3,3,3,3,3,3,3,3,3,4,4,4,3,3,0,0,0
0,0,0,0,3,3,4,4,4,3,3,3,3,3,3,3,3,0,0,0,0,0,3,3,3,3,3,3,3,3,4,4,4,3,3,0,0,0,0
0,0,0,0,0,3,3,4,4,4,3,3,3,3,3,3,3,0,0,0,0,0,3,3,3,3,3,3,3,4,4,4,3,3,0,0,0,0,0
0,0,0,0,0,0,3,3,4,4,4,4,4,4,4,4,3,0,0,0,0,0,3,4,4,4,4,4,4,4,4,3,3,0,0,0,0,0,0
0,0,0,0,0,0,0,3,3,4,4,4,4,4,4,4,3,0,0,0,0,0,3,4,4,4,4,4,4,4,3,3,0,0,0,0,0,0,0
0,0,0,0,0,0,0,0,3,3,3,3,3,3,3,3,3,0,0,0,0,0,3,3,3,3,3,3,3,3,3,0,0,0,0,0,0,0,0
0,0,0,0,0,0,0,0,0,0,0,0,0,0,0,3,0,0,0,0,0,0,0,3,0,0,0,0,0,0,0,0,0,0,0,0,0,0,0
0,0,0,0,0,0,0,0,0,0,0,0,0,0,0,0,3,83,84,85,86,87,3,0,0,0,0,0,0,0,0,0,0,0,0,0,0,0,0
0,0,0,0,0,0,0,0,0,0,0,0,0,0,0,0,80,80,0,0,0,80,80,0,0,0,0,0,0,0,0,0,0,0,0,0,0,0,0
0,0,0,0,0,0,0,0,0,0,0,0,0,0,0,0,0,0,0,0,0,0,0,0,0,0,0,0,0,0,0,0,0,0,0,0,0,0,0
0,0,0,0,0,0,0,0,0,0,0,0,0,0,0,0,88,0,0,0,0,0,88,0,0,0,0,0,0,0,0,0,0,0,0,0,0,0,0
0,0,0,0,0,0,0,0,0,0,0,0,0,0,0,0,0,0,0,0,0,0,0,0,0,0,0,0,0,0,0,0,0,0,0,0,0,0,0
:endlayer
layer: 7
0,0,0,0,0,0,0,0,0,0,0,0,0,0,0,0,0,0,0,0,0,0,0,0,0,0,0,0,0,0,0,0,0,0,0,0,0,0,0
0,0,0,0,0,0,0,0,0,0,0,0,0,0,0,0,0,0,0,0,0,0,0,0,0,0,0,0,0,0,0,0,0,0,0,0,0,0,0
0,0,0,0,0,0,0,0,0,0,0,0,0,0,0,0,0,0,0,0,0,0,0,0,0,0,0,0,0,0,0,0,0,0,0,0,0,0,0
0,0,0,0,0,0,0,0,89,0,0,0,0,0,0,0,3,3,3,3,3,3,3,0,0,0,0,0,0,0,89,0,0,0,0,0,0,0,0
0,0,0,0,0,0,0,0,0,0,0,0,90,0,0,0,3,91,0,91,0,91,3,0,90,0,0,0,0,0,0,0,0,0,0,0,0,0,0
0,0,0,0,0,0,0,0,0,0,0,0,0,0,90,0,3,92,93,92,0,92,3,0,0,0,90,0,0,0,90,0,0,0,0,0,0,0,0
0,0,0,0,0,0,0,90,90,0,3,3,3,3,3,3,3,0,0,0,94,0,3,3,3,3,3,3,3,0,90,0,0,0,0,0,0,0,0
0,0,0,0,0,0,0,0,0,3,3,3,3,3,3,3,3,95,0,0,0,95,3,3,3,3,3,3,3,3,0,0,0,0,0,0,0,0,0
0,0,0,89,0,0,0,0,3,3,3,3,3,3,3,3,3,96,0,0,0,96,3,3,3,3,3,3,3,3,3,0,0,0,0,89,0,0,0
0,0,0,0,0,90,0,3,3,3,3,3,3,3,3,3,3,3,3,0,3,3,3,3,3,3,3,3,3,3,3,3,90,0,0,0,0,0,0
0,0,0,0,0,0,3,3,3,3,3,97,3,88,3,98,3,0,0,0,0,0,3,99,0,0,100,101,3,3,3,3,3,0,90,0,0,0,0
0,0,0,0,0,90,3,3,3,3,0,0,102,0,0,0,0,0,0,0,0,0,0,0,0,0,103,0,91,3,3,3,3,0,0,0,0,0,0
0,0,0,0,0,0,3,3,3,3,0,104,0,0,0,0,3,3,3,3,3,0,3,0,0,0,0,0,92,3,3,3,3,90,0,0,0,0,0
0,0,0,0,90,0,3,3,3,3,0,0,0,105,0,106,3,3,3,3,3,0,3,0,0,0,0,0,0,3,3,3,3,0,0,0,0,0,0
0,0,0,0,0,0,3,3,3,3,0,0,0,0,107,0,3,3,3,3,3,0,3,95,0,95,108,95,0,3,3,3,3,0,0,0,0,0,0
0,0,0,0,0,0,3,3,3,3,0,0,0,109,110,111,3,0,0,0,0,0,3,96,0,96,0,96,0,3,3,3,3,0,0,0,0,0,0
0,0,0,3,3,3,3,3,3,3,0,3,3,3,3,3,3,0,0,0,0,0,112,3,3,3,3,3,3,3,3,3,3,3,3,3,0,0,0
0,0,0,3,113,113,113,113,113,3,0,0,0,0,0,0,0,3,3,3,26,0,0,0,3,3,3,0,0,3,114,115,0,100,101,3,0,0,0
0,0,0,3,113,0,0,0,0,3,0,0,3,3,3,0,0,3,3,3,26,0,0,0,3,3,3,0,0,3,0,0,0,116,0,3,0,0,0
0,0,0,3,113,0,117,0,0,0,0,0,3,3,3,0,0,118,0,0,0,0,0,0,0,0,0,0,0,0,0,0,0,100,101,3,0,0,0
0,0,0,3,113,0,0,0,0,3,0,0,3,3,3,0,0,0,0,0,0,0,0,0,3,3,3,0,0,3,0,0,0,119,0,3,0,0,0
0,0,0,3,113,113,113,113,113,3,0,0,3,3,3,0,0,3,0,0,0,3,0,0,3,3,3,0,0,3,114,115,0,100,101,3,0,0,0
0,0,0,3,3,3,3,3,3,3,3,3,3,3,3,3,0,0,0,0,0,0,0,3,3,3,3,3,3,3,3,3,3,3,3,3,0,0,0
0,0,0,0,0,0,3,3,3,3,120,121,0,0,122,123,3,0,0,0,0,0,3,120,121,0,0,122,123,3,3,3,3,0,0,0,0,0,0
0,0,0,0,0,0,3,3,3,3,0,0,124,0,0,0,3,3,0,0,0,3,3,0,0,0,0,0,0,3,3,3,3,0,0,0,0,0,0
0,0,0,0,0,90,3,3,3,3,120,121,0,0,122,123,3,3,0,0,0,3,3,120,121,125,126,122,123,3,3,3,3,0,0,0,0,0,0
0,0,0,0,0,0,3,3,3,3,0,0,0,127,0,0,3,3,0,0,0,3,3,0,0,0,0,0,0,3,3,3,3,0,90,0,0,0,0
0,0,0,0,0,0,3,3,3,3,120,121,0,0,0,0,3,0,0,0,0,0,3,0,0,0,0,122,123,3,3,3,3,0,0,0,0,0,0
0,0,0,0,90,0,3,3,3,3,3,0,0,0,0,0,0,0,0,0,0,0,0,0,0,0,0,0,3,3,3,3,3,0,90,0,0,0,0
0,0,0,0,0,0,0,3,3,3,3,3,3,3,3,3,3,3,0,0,0,3,3,3,3,3,3,3,3,3,3,3,0,90,0,0,0,0,0
0,0,0,89,0,0,0,0,3,3,3,3,3,3,3,3,3,128,0,0,0,129,3,3,3,3,3,3,3,3,3,0,0,0,0,89,0,0,0
0,0,0,0,0,0,0,90,0,3,3,3,3,3,3,3,3,0,0,0,0,0,3,3,3,3,3,3,3,3,0,90,0,0,0,0,0,0,0
0,0,0,0,0,0,0,0,0,0,3,3,3,3,3,3,3,0,0,0,0,0,3,3,3,3,3,3,3,0,0,0,0,0,0,0,0,0,0
0,0,0,0,0,0,0,0,0,0,90,0,0,90,0,0,3,0,0,0,0,0,3,0,0,0,0,0,0,0,0,0,0,0,0,0,0,0,0
0,0,0,0,0,0,0,0,0,0,0,0,0,0,0,0,3,0,0,0,0,0,3,0,0,0,90,0,90,0,0,0,0,0,0,0,0,0,0
0,0,0,0,0,0,0,0,89,0,0,0,0,0,0,0,3,0,0,0,0,0,3,0,0,0,0,0,0,0,89,0,0,0,0,0,0,0,0
0,0,0,0,0,0,0,0,0,0,0,0,0,0,0,3,0,0,0,0,0,0,0,3,0,0,0,0,0,0,0,0,0,0,0,0,0,0,0
0,0,0,0,0,0,0,0,0,0,0,0,0,0,0,0,3,130,131,132,133,134,3,0,0,0,0,0,0,0,0,0,0,0,0,0,0,0,0
0,0,0,0,0,0,0,0,0,0,0,0,0,0,0,0,80,80,0,0,0,80,80,0,0,0,0,0,0,0,0,0,0,0,0,0,0,0,0
0,0,0,0,0,0,0,0,0,0,0,0,0,0,0,0,0,0,0,0,0,0,0,0,0,0,0,0,0,0,0,0,0,0,0,0,0,0,0
0,0,0,0,0,0,0,0,0,0,0,0,0,0,0,0,0,0,0,0,0,0,0,0,0,0,0,0,0,0,0,0,0,0,0,0,0,0,0
0,0,0,0,0,0,0,0,0,0,0,0,0,0,0,0,0,0,0,0,0,0,0,0,0,0,0,0,0,0,0,0,0,0,0,0,0,0,0
:endlayer
layer: 8
0,0,0,0,0,0,0,0,0,0,0,0,0,0,0,0,0,0,0,0,0,0,0,0,0,0,0,0,0,0,0,0,0,0,0,0,0,0,0
0,0,0,0,0,0,0,0,0,0,0,0,0,0,0,0,0,0,0,0,0,0,0,0,0,0,0,0,0,0,0,0,0,0,0,0,0,0,0
0,0,0,0,0,0,0,0,0,0,0,0,0,0,0,0,0,0,0,47,0,0,0,0,0,0,0,0,0,0,0,0,0,0,0,0,0,0,0
0,0,0,0,0,0,0,0,0,0,0,0,0,0,0,0,3,3,3,3,3,3,3,0,0,0,0,0,0,0,0,0,0,0,0,0,0,0,0
0,0,0,0,0,0,0,0,0,0,0,0,0,0,0,0,3,0,0,0,0,0,3,0,0,0,0,0,0,0,0,0,0,0,0,0,0,0,0
0,0,0,0,0,0,0,0,0,0,0,0,0,0,0,0,3,0,0,0,0,0,3,0,0,0,0,0,0,0,0,0,0,0,0,0,0,0,0
0,0,0,0,0,0,0,0,0,0,3,3,3,3,3,3,3,0,0,0,0,0,3,3,3,3,3,3,3,0,0,0,0,0,0,0,0,0,0
0,0,0,0,0,0,0,0,0,3,3,3,3,3,3,3,3,0,0,0,0,0,3,3,3,3,3,3,3,3,0,0,0,0,0,0,0,0,0
0,0,0,0,0,0,0,0,3,3,3,3,3,3,3,3,3,0,0,0,0,0,3,3,3,3,3,3,3,3,3,0,0,0,0,0,0,0,0
0,0,0,0,0,0,0,3,3,3,3,3,3,3,3,3,3,3,3,0,3,3,3,3,3,3,3,3,3,3,3,3,0,0,0,0,0,0,0
0,0,0,0,0,0,3,3,3,3,3,135,3,0,3,136,3,49,0,0,0,49,3,0,0,0,0,0,3,3,3,3,3,0,0,0,0,0,0
0,0,0,0,0,0,3,3,3,3,0,0,0,0,0,0,0,0,0,0,0,0,0,0,0,0,0,0,0,3,3,3,3,0,0,0,0,0,0
0,0,0,0,0,0,3,3,3,3,0,0,0,0,0,0,3,3,3,3,3,0,3,0,0,0,0,0,0,3,3,3,3,0,0,0,0,0,0
0,0,0,0,0,0,3,3,3,3,0,0,0,0,0,0,3,3,3,3,3,0,3,0,0,0,0,0,0,3,3,3,3,0,0,0,0,0,0
0,0,0,0,0,0,3,3,3,3,0,0,0,0,0,0,3,3,3,3,3,0,3,0,0,0,0,0,0,3,3,3,3,0,0,0,0,0,0
0,0,0,0,0,0,3,3,3,3,0,0,0,0,0,0,3,0,0,0,0,0,3,0,0,0,0,0,0,3,3,3,3,0,0,0,0,0,0
0,0,0,3,3,3,3,3,3,3,0,3,3,3,3,3,3,0,0,0,0,0,0,3,3,3,3,3,3,3,3,3,3,3,3,3,0,0,0
0,0,0,3,113,113,113,113,113,3,0,0,0,0,0,0,0,3,3,26,0,0,0,0,3,3,3,0,0,3,0,0,0,0,0,3,0,0,0
0,0,0,3,113,0,0,0,42,3,0,0,3,3,3,0,0,3,3,26,0,0,0,0,3,3,3,0,0,3,0,0,0,0,0,3,0,0,0
0,0,42,3,113,0,0,0,0,0,0,0,3,3,3,0,0,0,0,0,0,0,0,0,0,0,0,0,0,0,0,0,0,0,0,3,48,0,0
0,0,0,3,113,0,0,0,42,3,0,0,3,3,3,0,0,0,0,0,0,0,0,0,3,3,3,0,0,3,0,0,0,0,0,3,0,0,0
0,0,0,3,113,113,113,113,113,3,47,0,3,3,3,0,0,3,0,0,0,3,0,0,3,3,3,47,0,3,0,0,0,0,0,3,0,0,0
0,0,0,3,3,3,3,3,3,3,3,3,3,3,3,3,0,0,0,0,0,0,0,3,3,3,3,3,3,3,3,3,3,3,3,3,0,0,0
0,0,0,0,0,0,3,3,3,3,0,0,0,0,0,0,3,0,0,0,0,0,3,0,0,0,0,0,0,3,3,3,3,0,0,0,0,0,0
0,0,0,0,0,0,3,3,3,3,0,0,0,0,0,0,3,3,0,0,0,3,3,0,0,0,0,0,0,3,3,3,3,0,0,0,0,0,0
0,0,0,0,0,0,3,3,3,3,0,0,0,0,0,0,3,3,0,0,0,3,3,0,0,0,0,0,0,3,3,3,3,0,0,0,0,0,0
0,0,0,0,0,0,3,3,3,3,0,0,0,0,0,0,3,3,0,0,0,3,3,0,0,0,0,0,0,3,3,3,3,0,0,0,0,0,0
0,0,0,0,0,0,3,3,3,3,0,0,0,0,0,0,3,0,0,0,0,0,3,0,0,0,0,0,0,3,3,3,3,0,0,0,0,0,0
0,0,0,0,0,0,3,3,3,3,3,0,0,0,0,0,0,0,0,0,0,0,0,0,0,0,0,0,3,3,3,3,3,0,0,0,0,0,0
0,0,0,0,0,0,0,3,3,3,3,3,3,3,3,3,3,3,0,0,0,3,3,3,3,3,3,3,3,3,3,3,0,0,0,0,0,0,0
0,0,0,0,0,0,0,0,3,3,3,3,3,3,3,3,3,0,0,0,0,0,3,3,3,3,3,3,3,3,3,0,0,0,0,0,0,0,0
0,0,0,0,0,0,0,0,0,3,3,3,3,3,3,3,3,0,0,0,0,0,3,3,3,3,3,3,3,3,0,0,0,0,0,0,0,0,0
0,0,0,0,0,0,0,0,0,0,3,3,3,3,3,3,3,0,0,0,0,0,3,3,3,3,3,3,3,0,0,0,0,0,0,0,0,0,0
0,0,0,0,0,0,0,0,0,0,0,0,0,0,0,0,3,0,0,0,0,0,3,0,0,0,0,0,0,0,0,0,0,0,0,0,0,0,0
0,0,0,0,0,0,0,0,0,0,0,0,0,0,0,0,3,0,0,0,0,0,3,0,0,0,0,0,0,0,0,0,0,0,0,0,0,0,0
0,0,0,0,0,0,0,0,0,0,0,0,0,0,0,0,3,48,0,0,0,42,3,0,0,0,0,0,0,0,0,0,0,0,0,0,0,0,0
0,0,0,0,0,0,0,0,0,0,0,0,0,0,42,3,0,0,0,0,0,0,0,3,48,0,0,0,0,0,0,0,0,0,0,0,0,0,0
0,0,0,0,0,0,0,0,0,0,0,0,0,0,0,0,3,137,138,139,140,141,3,0,0,0,0,0,0,0,0,0,0,0,0,0,0,0,0
0,0,0,0,0,0,0,0,0,0,0,0,0,0,0,0,80,80,80,80,80,80,80,0,0,0,0,0,0,0,0,0,0,0,0,0,0,0,0
0,0,0,0,0,0,0,0,0,0,0,0,0,0,0,0,0,0,0,0,0,0,0,0,0,0,0,0,0,0,0,0,0,0,0,0,0,0,0
0,0,0,0,0,0,0,0,0,0,0,0,0,0,0,0,0,0,0,0,0,0,0,0,0,0,0,0,0,0,0,0,0,0,0,0,0,0,0
0,0,0,0,0,0,0,0,0,0,0,0,0,0,0,0,0,0,0,0,0,0,0,0,0,0,0,0,0,0,0,0,0,0,0,0,0,0,0
:endlayer
layer: 9
0,0,0,0,0,0,0,0,0,0,0,0,0,0,0,0,0,0,0,0,0,0,0,0,0,0,0,0,0,0,0,0,0,0,0,0,0,0,0
0,0,0,0,0,0,0,0,0,0,0,0,0,0,0,0,0,0,0,0,0,0,0,0,0,0,0,0,0,0,0,0,0,0,0,0,0,0,0
0,0,0,0,0,0,0,0,0,0,0,0,0,0,0,0,0,0,0,0,0,0,0,0,0,0,0,0,0,0,0,0,0,0,0,0,0,0,0
0,0,0,0,0,0,0,0,0,0,0,0,0,0,0,0,3,3,3,3,3,3,3,0,0,0,0,0,0,0,0,0,0,0,0,0,0,0,0
0,0,0,0,0,0,0,0,0,0,0,0,0,0,0,0,3,0,0,49,0,0,3,0,0,0,0,0,0,0,0,0,0,0,0,0,0,0,0
0,0,0,0,0,0,0,0,0,0,0,0,0,0,0,0,3,0,0,0,0,0,3,0,0,0,0,0,0,0,0,0,0,0,0,0,0,0,0
0,0,0,0,0,0,0,0,0,0,3,3,3,3,3,3,3,48,0,0,0,42,3,3,3,3,3,3,3,0,0,0,0,0,0,0,0,0,0
0,0,0,0,0,0,0,0,0,3,3,3,3,3,3,3,3,0,0,0,0,0,3,3,3,3,3,3,3,3,0,0,0,0,0,0,0,0,0
0,0,0,0,0,0,0,0,3,3,3,3,3,3,3,3,3,0,0,47,0,0,3,3,3,3,3,3,3,3,3,0,0,0,0,0,0,0,0
0,0,0,0,0,0,0,3,3,3,3,3,3,3,3,3,3,3,3,3,3,3,3,3,3,3,3,3,3,3,3,3,0,0,0,0,0,0,0
0,0,0,0,0,0,3,3,3,3,3,142,3,143,3,144,3,0,0,0,0,0,3,49,0,0,0,42,3,3,3,3,3,0,0,0,0,0,0
0,0,0,0,0,0,3,3,3,3,49,0,49,0,49,0,3,0,0,0,0,0,3,0,0,0,0,0,0,3,3,3,3,0,0,0,0,0,0
0,0,0,0,0,0,3,3,3,3,0,0,0,0,0,0,3,3,3,3,3,3,3,0,0,0,0,0,0,3,3,3,3,0,0,0,0,0,0
0,0,0,0,0,0,3,3,3,3,0,0,0,0,0,0,3,3,3,3,3,3,3,0,0,0,0,0,0,3,3,3,3,0,0,0,0,0,0
0,0,0,0,0,0,3,3,3,3,0,0,0,0,0,0,3,3,3,3,3,3,3,0,0,0,0,0,0,3,3,3,3,0,0,0,0,0,0
0,0,0,0,0,0,3,3,3,3,48,0,0,0,0,47,3,0,0,49,0,0,3,48,0,0,0,0,47,3,3,3,3,0,0,0,0,0,0
0,0,0,3,3,3,3,3,3,3,3,3,3,3,3,3,3,0,0,0,0,0,0,3,3,3,3,3,3,3,3,3,3,3,3,3,0,0,0
0,0,0,3,113,113,113,113,113,3,0,0,3,3,3,0,0,3,26,0,0,0,0,0,3,3,3,0,0,3,0,0,49,0,0,3,0,0,0
0,0,0,3,113,0,0,0,0,3,0,0,3,3,3,0,0,3,26,0,0,0,0,0,3,3,3,0,0,3,0,0,0,0,0,3,0,0,0
0,0,0,3,113,0,0,0,0,3,0,0,3,3,3,48,0,0,0,0,0,0,0,42,3,3,3,0,0,3,48,0,0,0,42,3,0,0,0
0,0,0,3,113,0,0,0,0,3,0,0,3,3,3,0,0,47,0,0,0,47,0,0,3,3,3,0,0,3,0,0,0,0,0,3,0,0,0
0,0,0,3,113,113,113,113,113,3,0,0,3,3,3,0,0,3,0,0,0,3,0,0,3,3,3,0,0,3,0,0,47,0,0,3,0,0,0
0,0,0,3,3,3,3,3,3,3,3,3,3,3,3,3,0,0,0,0,0,0,0,3,3,3,3,3,3,3,3,3,3,3,3,3,0,0,0
0,0,0,0,0,0,3,3,3,3,49,0,0,0,0,42,3,48,0,0,0,42,3,49,0,0,0,0,42,3,3,3,3,0,0,0,0,0,0
0,0,0,0,0,0,3,3,3,3,0,0,0,0,0,0,3,3,0,0,0,3,3,0,0,0,0,0,0,3,3,3,3,0,0,0,0,0,0
0,0,0,0,0,0,3,3,3,3,0,0,0,0,0,0,3,3,0,0,0,3,3,0,0,0,0,0,0,3,3,3,3,0,0,0,0,0,0
0,0,0,0,0,0,3,3,3,3,0,0,0,0,0,0,3,3,0,0,0,3,3,0,0,0,0,0,0,3,3,3,3,0,0,0,0,0,0
0,0,0,0,0,0,3,3,3,3,0,0,0,0,0,0,3,0,0,0,0,0,3,0,0,0,0,0,47,3,3,3,3,0,0,0,0,0,0
0,0,0,0,0,0,3,3,3,3,3,48,0,0,0,47,3,48,0,0,0,42,3,48,0,0,0,0,3,3,3,3,3,0,0,0,0,0,0
0,0,0,0,0,0,0,3,3,3,3,3,3,3,3,3,3,3,0,0,0,3,3,3,3,3,3,3,3,3,3,3,0,0,0,0,0,0,0
0,0,0,0,0,0,0,0,3,3,3,3,3,3,3,3,3,0,0,0,0,0,3,3,3,3,3,3,3,3,3,0,0,0,0,0,0,0,0
0,0,0,0,0,0,0,0,0,3,3,3,3,3,3,3,3,0,0,0,0,0,3,3,3,3,3,3,3,3,0,0,0,0,0,0,0,0,0
0,0,0,0,0,0,0,0,0,0,3,3,3,3,3,3,3,48,0,0,0,42,3,3,3,3,3,3,3,0,0,0,0,0,0,0,0,0,0
0,0,0,0,0,0,0,0,0,0,0,0,0,0,0,0,3,0,0,0,0,0,3,0,0,0,0,0,0,0,0,0,0,0,0,0,0,0,0
0,0,0,0,0,0,0,0,0,0,0,0,0,0,0,0,3,0,0,0,0,0,3,0,0,0,0,0,0,0,0,0,0,0,0,0,0,0,0
0,0,0,0,0,0,0,0,0,0,0,0,0,0,0,0,3,0,0,0,0,0,3,0,0,0,0,0,0,0,0,0,0,0,0,0,0,0,0
0,0,0,0,0,0,0,0,0,0,0,0,0,0,0,3,3,0,0,0,0,0,3,3,0,0,0,0,0,0,0,0,0,0,0,0,0,0,0
0,0,0,0,0,0,0,0,0,0,0,0,0,0,0,0,3,3,3,3,3,3,3,0,0,0,0,0,0,0,0,0,0,0,0,0,0,0,0
0,0,0,0,0,0,0,0,0,0,0,0,0,0,0,0,0,80,0,0,0,80,0,0,0,0,0,0,0,0,0,0,0,0,0,0,0,0,0
0,0,0,0,0,0,0,0,0,0,0,0,0,0,0,0,0,0,0,0,0,0,0,0,0,0,0,0,0,0,0,0,0,0,0,0,0,0,0
0,0,0,0,0,0,0,0,0,0,0,0,0,0,0,0,0,0,0,0,0,0,0,0,0,0,0,0,0,0,0,0,0,0,0,0,0,0,0
0,0,0,0,0,0,0,0,0,0,0,0,0,0,0,0,0,0,0,0,0,0,0,0,0,0,0,0,0,0,0,0,0,0,0,0,0,0,0
:endlayer
layer: 10
0,0,0,0,0,0,0,0,0,0,0,0,0,0,0,0,0,0,0,0,0,0,0,0,0,0,0,0,0,0,0,0,0,0,0,0,0,0,0
0,0,0,0,0,0,0,0,0,0,0,0,0,0,0,0,0,0,0,0,0,0,0,0,0,0,0,0,0,0,0,0,0,0,0,0,0,0,0
0,0,0,0,0,0,0,0,0,0,0,0,0,0,0,0,0,0,0,0,0,0,0,0,0,0,0,0,0,0,0,0,0,0,0,0,0,0,0
0,0,0,0,0,0,0,0,0,0,0,0,0,0,0,0,3,3,3,3,3,3,3,0,0,0,0,0,0,0,0,0,0,0,0,0,0,0,0
0,0,0,0,0,0,0,0,0,0,0,0,0,0,0,0,3,3,3,3,3,3,3,0,0,0,0,0,0,0,0,0,0,0,0,0,0,0,0
0,0,0,0,0,0,0,0,0,0,3,3,3,3,3,3,3,3,3,3,3,3,3,3,3,3,3,3,3,0,0,0,0,0,0,0,0,0,0
0,0,0,0,0,0,0,0,0,3,3,3,3,3,3,3,3,3,3,3,3,3,3,3,3,3,3,3,3,3,0,0,0,0,0,0,0,0,0
0,0,0,0,0,0,0,0,3,3,3,3,3,3,3,3,3,3,3,3,3,3,3,3,3,3,3,3,3,3,3,0,0,0,0,0,0,0,0
0,0,0,0,0,0,0,3,3,3,3,3,3,3,3,3,3,3,3,3,3,3,3,3,3,3,3,3,3,3,3,3,0,0,0,0,0,0,0
0,0,0,0,0,0,3,3,3,3,3,3,3,3,3,3,3,3,3,3,3,3,3,3,3,3,3,3,3,3,3,3,3,0,0,0,0,0,0
0,0,0,0,0,3,3,3,3,3,3,145,3,3,3,146,3,3,3,3,3,3,3,0,0,0,0,0,3,3,3,3,3,3,0,0,0,0,0
0,0,0,0,0,3,3,3,3,3,0,0,0,0,0,0,3,3,3,3,3,3,3,0,0,0,0,0,0,3,3,3,3,3,0,0,0,0,0
0,0,0,0,0,3,3,3,3,3,0,0,0,0,0,0,3,3,3,3,3,3,3,0,0,0,0,0,0,3,3,3,3,3,0,0,0,0,0
0,0,0,0,0,3,3,3,3,3,0,0,0,0,0,0,3,3,3,3,3,3,3,0,0,0,0,0,0,3,3,3,3,3,0,0,0,0,0
0,0,0,0,0,3,3,3,3,3,0,0,0,0,0,0,3,3,3,3,3,3,3,0,0,0,0,0,0,3,3,3,3,3,0,0,0,0,0
0,0,0,0,0,3,3,3,3,3,0,0,0,0,0,0,3,3,0,0,0,0,3,0,0,0,0,0,0,3,3,3,3,3,0,0,0,0,0
0,0,0,3,3,3,3,3,3,3,3,3,3,3,3,3,3,3,0,0,0,0,0,3,3,3,3,3,3,3,3,3,3,3,3,3,0,0,0
0,0,0,3,3,3,3,3,3,3,3,3,3,3,3,3,3,26,0,0,0,0,0,0,3,3,3,3,3,3,3,3,3,3,3,3,0,0,0
0,0,0,3,3,3,3,3,3,3,3,3,3,3,3,3,3,26,0,0,0,0,0,0,3,3,3,3,3,3,3,3,3,3,3,3,0,0,0
0,0,0,3,3,3,3,3,3,3,3,3,3,3,3,0,0,0,0,0,0,0,0,0,3,3,3,3,3,3,3,3,3,3,3,3,0,0,0
0,0,0,3,3,3,3,3,3,3,3,3,3,3,3,0,0,0,0,0,0,0,0,0,3,3,3,3,3,3,3,3,3,3,3,3,0,0,0
0,0,0,3,3,3,3,3,3,3,3,3,3,3,3,0,0,3,0,0,0,3,0,0,3,3,3,3,3,3,3,3,3,3,3,3,0,0,0
0,0,0,3,3,3,3,3,3,3,3,3,3,3,3,3,0,0,0,0,0,0,0,3,3,3,3,3,3,3,3,3,3,3,3,3,0,0,0
0,0,0,0,0,3,3,3,3,3,0,0,0,0,0,0,3,0,0,0,0,0,3,0,0,0,0,0,0,3,3,3,3,3,0,0,0,0,0
0,0,0,0,0,3,3,3,3,3,0,0,0,0,0,0,3,3,3,3,3,3,3,0,0,0,0,0,0,3,3,3,3,3,0,0,0,0,0
0,0,0,0,0,3,3,3,3,3,0,0,0,0,0,0,3,3,3,3,3,3,3,0,0,0,0,0,0,3,3,3,3,3,0,0,0,0,0
0,0,0,0,0,3,3,3,3,3,0,0,0,0,0,0,3,3,3,3,3,3,3,0,0,0,0,0,0,3,3,3,3,3,0,0,0,0,0
0,0,0,0,0,3,3,3,3,3,0,0,0,0,0,0,3,3,3,3,3,3,3,0,0,0,0,0,0,3,3,3,3,3,0,0,0,0,0
0,0,0,0,0,3,3,3,3,3,3,0,0,0,0,0,3,3,3,3,3,3,3,0,0,0,0,0,3,3,3,3,3,3,0,0,0,0,0
0,0,0,0,0,0,3,3,3,3,3,3,3,3,3,3,3,3,3,3,3,3,3,3,3,3,3,3,3,3,3,3,3,0,0,0,0,0,0
0,0,0,0,0,0,0,3,3,3,3,3,3,3,3,3,3,3,3,3,3,3,3,3,3,3,3,3,3,3,3,3,0,0,0,0,0,0,0
0,0,0,0,0,0,0,0,3,3,3,3,3,3,3,3,3,3,3,3,3,3,3,3,3,3,3,3,3,3,3,0,0,0,0,0,0,0,0
0,0,0,0,0,0,0,0,0,3,3,3,3,3,3,3,3,3,3,3,3,3,3,3,3,3,3,3,3,3,0,0,0,0,0,0,0,0,0
0,0,0,0,0,0,0,0,0,0,3,3,3,3,3,3,3,3,3,3,3,3,3,3,3,3,3,3,3,0,0,0,0,0,0,0,0,0,0
0,0,0,0,0,0,0,0,0,0,0,0,0,0,0,0,3,3,3,3,3,3,3,0,0,0,0,0,0,0,0,0,0,0,0,0,0,0,0
0,0,0,0,0,0,0,0,0,0,0,0,0,0,0,0,3,3,3,3,3,3,3,0,0,0,0,0,0,0,0,0,0,0,0,0,0,0,0
0,0,0,0,0,0,0,0,0,0,0,0,0,0,0,24,3,3,3,3,3,3,3,26,0,0,0,0,0,0,0,0,0,0,0,0,0,0,0
0,0,0,0,0,0,0,0,0,0,0,0,0,0,0,0,3,3,3,3,3,3,3,0,0,0,0,0,0,0,0,0,0,0,0,0,0,0,0
0,0,0,0,0,0,0,0,0,0,0,0,0,0,0,0,0,89,0,147,0,89,0,0,0,0,0,0,0,0,0,0,0,0,0,0,0,0,0
0,0,0,0,0,0,0,0,0,0,0,0,0,0,0,0,0,0,0,0,0,0,0,0,0,0,0,0,0,0,0,0,0,0,0,0,0,0,0
0,0,0,0,0,0,0,0,0,0,0,0,0,0,0,0,0,0,0,0,0,0,0,0,0,0,0,0,0,0,0,0,0,0,0,0,0,0,0
0,0,0,0,0,0,0,0,0,0,0,0,0,0,0,0,0,0,0,0,0,0,0,0,0,0,0,0,0,0,0,0,0,0,0,0,0,0,0
:endlayer
layer: 11
0,0,0,0,0,0,0,0,0,0,0,0,0,0,0,0,0,0,0,0,0,0,0,0,0,0,0,0,0,0,0,0,0,0,0,0,0,0,0
0,0,0,0,0,0,0,0,0,0,0,0,0,0,0,0,0,0,0,0,0,0,0,0,0,0,0,0,0,0,0,0,0,0,0,0,0,0,0
0,0,0,0,0,0,0,0,0,0,0,0,0,0,0,0,0,0,0,0,0,0,0,0,0,0,0,0,0,0,0,0,0,0,0,0,0,0,0
0,0,0,0,0,0,0,0,0,0,0,0,0,0,0,0,3,3,3,3,3,3,3,0,0,0,0,0,0,0,0,0,0,0,0,0,0,0,0
0,0,0,0,0,0,0,0,0,0,0,0,0,0,0,0,3,0,0,0,0,0,3,0,0,0,0,0,0,0,0,0,0,0,0,0,0,0,0
0,0,0,0,0,0,0,0,0,0,3,3,3,3,3,3,3,0,0,0,0,0,3,3,3,3,3,3,3,0,0,0,0,0,0,0,0,0,0
0,0,0,0,0,0,0,0,0,3,148,148,148,148,148,148,3,0,0,149,0,0,3,148,148,148,148,148,148,3,0,0,0,0,0,0,0,0,0
0,0,0,0,0,0,0,0,3,148,0,0,0,0,0,0,0,0,0,0,0,0,0,0,0,0,0,0,0,148,3,0,0,0,0,0,0,0,0
0,0,0,0,0,0,0,3,148,0,0,0,0,0,0,0,3,0,0,0,0,0,3,0,0,0,0,0,0,0,148,3,0,0,0,0,0,0,0
0,0,0,0,0,0,3,148,0,0,0,3,3,3,3,3,3,0,0,150,0,0,3,3,3,3,3,3,0,0,0,148,3,0,0,0,0,0,0
0,0,0,0,0,3,148,0,0,0,3,3,3,3,3,3,3,0,0,0,0,0,3,3,3,3,3,3,3,0,0,0,148,3,0,0,0,0,0
0,0,0,0,0,3,148,0,0,3,3,3,3,3,3,3,26,0,0,0,0,0,24,3,3,3,3,3,3,3,0,0,148,3,0,0,0,0,0
0,0,0,0,0,3,148,0,0,3,3,3,3,3,3,3,3,0,3,3,3,3,3,3,3,3,3,3,3,3,0,0,148,3,0,0,0,0,0
0,0,0,0,0,3,148,0,0,3,3,3,3,3,3,3,3,0,3,3,3,3,3,3,3,3,3,3,3,3,0,0,148,3,0,0,0,0,0
0,0,0,0,0,3,148,0,0,3,3,3,3,3,3,3,3,151,3,3,3,3,3,3,3,3,3,3,3,3,0,0,148,3,0,0,0,0,0
0,0,0,0,0,3,148,0,0,3,3,3,3,3,3,3,3,3,3,3,3,3,3,3,3,3,3,3,3,3,0,0,148,3,0,0,0,0,0
0,0,0,3,3,3,3,0,3,3,3,67,3,3,3,3,3,3,3,3,3,3,3,3,3,3,3,67,3,3,3,0,3,3,3,3,0,0,0
0,0,0,3,0,0,0,0,0,0,0,0,3,3,3,3,26,0,0,0,3,3,3,3,26,0,0,0,0,0,0,0,0,0,0,3,0,0,0
0,0,0,3,0,0,0,0,0,0,0,0,3,3,3,3,26,0,0,0,3,3,3,3,3,3,3,0,0,0,0,0,152,0,0,3,0,0,0
0,0,0,3,0,0,153,0,0,154,0,0,3,3,3,3,3,3,3,3,3,3,3,3,3,3,3,0,0,155,0,0,0,0,0,3,0,0,0
0,0,0,3,0,0,0,0,0,0,0,0,3,3,3,3,3,3,3,3,3,3,3,3,3,3,3,0,0,0,0,0,0,0,0,3,0,0,0
0,0,0,3,0,0,0,0,0,0,0,0,0,0,24,3,3,3,3,3,3,3,3,3,3,3,3,0,0,0,0,0,0,0,0,3,0,0,0
0,0,0,3,3,3,3,0,3,3,3,151,3,3,3,3,3,3,3,3,3,3,3,3,3,3,3,151,3,3,3,0,3,3,3,3,0,0,0
0,0,0,0,0,3,148,0,0,3,3,3,3,3,3,3,3,3,3,3,3,3,3,3,3,3,3,3,3,3,0,0,148,3,0,0,0,0,0
0,0,0,0,0,3,148,0,0,3,3,3,3,3,3,3,3,67,3,3,3,3,3,3,3,3,3,3,3,3,0,0,148,3,0,0,0,0,0
0,0,0,0,0,3,148,0,0,3,3,3,3,3,3,3,3,0,3,3,3,3,3,3,3,3,3,3,3,3,0,0,148,3,0,0,0,0,0
0,0,0,0,0,3,148,0,0,3,3,3,3,3,3,3,3,0,3,3,3,3,3,3,3,3,3,3,3,3,0,0,148,3,0,0,0,0,0
0,0,0,0,0,3,148,0,0,3,3,3,3,3,3,3,26,0,0,0,0,0,24,3,3,3,3,3,3,3,0,0,148,3,0,0,0,0,0
0,0,0,0,0,3,148,0,0,0,3,3,3,3,3,3,3,0,0,0,0,0,3,3,3,3,3,3,3,0,0,0,148,3,0,0,0,0,0
0,0,0,0,0,0,3,148,0,0,0,3,3,3,3,3,3,0,0,156,0,0,3,3,3,3,3,3,0,0,0,148,3,0,0,0,0,0,0
0,0,0,0,0,0,0,3,148,0,0,0,0,0,0,0,3,0,0,0,0,0,3,0,0,0,0,0,0,0,148,3,0,0,0,0,0,0,0
0,0,0,0,0,0,0,0,3,148,0,0,0,0,0,0,0,0,0,0,0,0,0,0,0,0,0,0,0,148,3,0,0,0,0,0,0,0,0
0,0,0,0,0,0,0,0,0,3,148,148,148,148,148,148,3,0,0,0,0,0,3,148,148,148,148,148,148,3,0,0,0,0,0,0,0,0,0
0,0,0,0,0,0,0,0,0,0,3,3,3,3,3,3,3,0,0,157,0,0,3,3,3,3,3,3,3,0,0,0,0,0,0,0,0,0,0
0,0,0,0,0,0,0,0,0,0,0,0,0,0,0,0,3,0,0,0,0,0,3,0,0,0,0,0,0,0,0,0,0,0,0,0,0,0,0
0,0,0,0,0,0,0,0,0,0,0,0,0,0,0,0,3,3,3,0,3,3,3,0,0,0,0,0,0,0,0,0,0,0,0,0,0,0,0
0,0,0,0,0,0,0,0,0,0,0,0,0,0,0,0,3,148,0,0,0,148,3,0,0,0,0,0,0,0,0,0,0,0,0,0,0,0,0
0,0,0,0,0,0,0,0,0,0,0,0,0,0,0,0,3,3,3,3,3,3,3,0,0,0,0,0,0,0,0,0,0,0,0,0,0,0,0
0,0,0,0,0,0,0,0,0,0,0,0,0,0,0,0,0,0,0,0,0,0,0,0,0,0,0,0,0,0,0,0,0,0,0,0,0,0,0
0,0,0,0,0,0,0,0,0,0,0,0,0,0,0,0,0,0,0,0,0,0,0,0,0,0,0,0,0,0,0,0,0,0,0,0,0,0,0
0,0,0,0,0,0,0,0,0,0,0,0,0,0,0,0,0,0,0,0,0,0,0,0,0,0,0,0,0,0,0,0,0,0,0,0,0,0,0
0,0,0,0,0,0,0,0,0,0,0,0,0,0,0,0,0,0,0,0,0,0,0,0,0,0,0,0,0,0,0,0,0,0,0,0,0,0,0
:endlayer
layer: 12
0,0,0,0,0,0,0,0,0,0,0,0,0,0,0,0,0,0,0,0,0,0,0,0,0,0,0,0,0,0,0,0,0,0,0,0,0,0,0
0,0,0,0,0,0,0,0,0,0,0,0,0,0,0,0,0,0,0,0,0,0,0,0,0,0,0,0,0,0,0,0,0,0,0,0,0,0,0
0,0,0,0,0,0,0,0,0,0,0,0,0,0,0,0,0,0,0,0,0,0,0,0,0,0,0,0,0,0,0,0,0,0,0,0,0,0,0
0,0,0,0,0,0,0,0,0,0,0,0,0,0,0,0,3,3,3,0,3,3,3,0,0,0,0,0,0,0,0,0,0,0,0,0,0,0,0
0,0,0,0,0,0,0,0,0,0,0,0,0,0,0,0,3,0,0,0,0,0,3,0,0,0,0,0,0,0,0,0,0,0,0,0,0,0,0
0,0,0,0,0,0,0,0,0,0,89,0,0,0,0,0,3,0,0,0,0,0,3,0,0,0,0,0,89,0,0,0,0,0,0,0,0,0,0
0,0,0,0,0,0,0,0,0,0,0,0,158,0,0,0,3,0,0,0,0,0,3,0,0,159,0,0,0,0,0,0,0,0,0,0,0,0,0
0,0,0,0,0,0,0,0,0,0,0,0,0,0,0,0,0,0,0,0,0,0,0,0,0,0,0,0,0,0,0,0,0,0,0,0,0,0,0
0,0,0,0,0,0,0,0,160,0,0,0,0,0,0,0,3,0,0,0,0,0,3,0,0,0,0,0,0,0,161,0,0,0,0,0,0,0,0
0,0,0,0,0,0,0,0,0,0,0,3,3,3,3,3,3,0,0,0,0,0,3,3,3,3,3,3,0,0,0,0,0,0,0,0,0,0,0
0,0,0,0,0,89,0,0,0,0,3,3,3,3,3,3,3,0,0,0,0,0,3,3,3,3,3,3,3,0,0,0,0,89,0,0,0,0,0
0,0,0,0,0,0,0,0,0,3,3,3,3,3,3,26,0,0,0,0,0,0,0,24,3,3,3,3,3,3,0,0,0,0,0,0,0,0,0
0,0,0,0,0,0,162,0,0,3,3,3,3,3,3,3,3,0,3,3,3,3,3,3,3,3,3,3,3,3,0,0,163,0,0,0,0,0,0
0,0,0,0,0,0,0,0,0,3,3,3,3,3,3,3,3,0,3,3,3,3,3,3,3,3,3,3,3,3,0,0,0,0,0,0,0,0,0
0,0,0,0,0,0,0,0,0,3,3,3,3,3,3,3,3,0,3,67,3,3,3,3,3,3,3,3,3,3,0,0,0,0,0,0,0,0,0
0,0,0,0,0,0,0,0,0,3,3,67,3,3,3,3,0,0,0,0,0,0,0,3,3,3,3,67,3,3,0,0,0,0,0,0,0,0,0
0,0,0,3,3,3,3,0,3,3,3,0,3,3,3,0,0,0,0,0,0,0,0,0,3,3,3,0,3,3,3,0,3,3,3,3,0,0,0
0,0,0,3,0,0,0,0,0,0,0,0,3,3,3,0,0,0,0,0,0,0,0,0,0,0,0,0,0,0,0,0,0,0,0,3,0,0,0
0,0,0,3,0,0,0,0,0,0,0,0,3,3,3,0,0,0,0,0,0,0,0,0,3,3,3,0,0,0,0,0,0,0,0,3,0,0,0
0,0,0,0,0,0,0,0,0,0,0,0,3,3,26,0,0,24,3,3,164,3,0,0,24,3,3,0,0,0,0,0,0,0,0,0,0,0,0
0,0,0,3,0,0,0,0,0,0,0,0,3,3,3,0,0,24,3,3,165,3,0,0,3,3,3,0,0,0,0,0,0,0,0,3,0,0,0
0,0,0,3,0,0,0,0,0,0,0,0,0,0,0,0,0,0,0,0,0,0,0,0,3,3,3,0,0,0,0,0,0,0,0,3,0,0,0
0,0,0,3,3,3,3,0,3,3,3,0,3,3,3,0,0,0,0,0,0,0,0,0,3,3,3,0,3,3,3,0,3,3,3,3,0,0,0
0,0,0,0,0,0,0,0,0,3,3,151,3,3,3,3,0,0,0,0,0,0,0,3,3,3,3,151,3,3,0,0,0,0,0,0,0,0,0
0,0,0,0,0,0,0,0,0,3,3,3,3,3,3,3,3,0,3,151,3,3,3,3,3,3,3,3,3,3,0,0,0,0,0,0,0,0,0
0,0,0,0,0,0,0,0,0,3,3,3,3,3,3,3,3,0,3,3,3,3,3,3,3,3,3,3,3,3,0,0,166,0,0,0,0,0,0
0,0,0,0,0,0,167,0,0,3,3,3,3,3,3,3,3,0,3,3,3,3,3,3,3,3,3,3,3,3,0,0,0,0,0,0,0,0,0
0,0,0,0,0,0,0,0,0,3,3,3,3,3,3,26,0,0,0,0,0,0,0,24,3,3,3,3,3,3,0,0,0,0,0,0,0,0,0
0,0,0,0,0,89,0,0,0,0,3,3,3,3,3,3,3,0,0,0,0,0,3,3,3,3,3,3,3,0,0,0,0,89,0,0,0,0,0
0,0,0,0,0,0,0,0,0,0,0,3,3,3,3,3,3,0,0,0,0,0,3,3,3,3,3,3,0,0,0,0,0,0,0,0,0,0,0
0,0,0,0,0,0,0,0,168,0,0,0,0,0,0,0,3,0,0,0,0,0,3,0,0,0,0,0,0,0,169,0,0,0,0,0,0,0,0
0,0,0,0,0,0,0,0,0,0,0,0,0,0,0,0,0,0,0,0,0,0,0,0,0,0,0,0,0,0,0,0,0,0,0,0,0,0,0
0,0,0,0,0,0,0,0,0,0,0,0,0,170,0,0,3,0,0,0,0,0,3,0,0,0,171,0,0,0,0,0,0,0,0,0,0,0,0
0,0,0,0,0,0,0,0,0,0,89,0,0,0,0,0,3,0,0,0,0,0,3,0,0,0,0,0,89,0,0,0,0,0,0,0,0,0,0
0,0,0,0,0,0,0,0,0,0,0,0,0,0,0,0,3,0,0,0,0,0,3,0,0,0,0,0,0,0,0,0,0,0,0,0,0,0,0
0,0,0,0,0,0,0,0,0,0,0,0,0,0,0,0,3,3,3,0,3,3,3,0,0,0,0,0,0,0,0,0,0,0,0,0,0,0,0
0,0,0,0,0,0,0,0,0,0,0,0,0,0,0,0,0,172,0,0,0,173,0,0,0,0,0,0,0,0,0,0,0,0,0,0,0,0,0
0,0,0,0,0,0,0,0,0,0,0,0,0,0,0,0,3,0,0,0,0,0,3,0,0,0,0,0,0,0,0,0,0,0,0,0,0,0,0
0,0,0,0,0,0,0,0,0,0,0,0,0,0,0,0,0,0,0,0,0,0,0,0,0,0,0,0,0,0,0,0,0,0,0,0,0,0,0
0,0,0,0,0,0,0,0,0,0,0,0,0,0,0,0,0,0,0,0,0,0,0,0,0,0,0,0,0,0,0,0,0,0,0,0,0,0,0
0,0,0,0,0,0,0,0,0,0,0,0,0,0,0,0,0,0,0,0,0,0,0,0,0,0,0,0,0,0,0,0,0,0,0,0,0,0,0
0,0,0,0,0,0,0,0,0,0,0,0,0,0,0,0,0,0,0,0,0,0,0,0,0,0,0,0,0,0,0,0,0,0,0,0,0,0,0
:endlayer
layer: 13
0,0,0,0,0,0,0,0,0,0,0,0,0,0,0,0,0,0,0,0,0,0,0,0,0,0,0,0,0,0,0,0,0,0,0,0,0,0,0
0,0,0,0,0,0,0,0,0,0,0,0,0,0,0,0,0,0,0,0,0,0,0,0,0,0,0,0,0,0,0,0,0,0,0,0,0,0,0
0,0,0,0,0,0,0,0,0,0,0,0,0,0,0,0,0,0,0,0,0,0,0,0,0,0,0,0,0,0,0,0,0,0,0,0,0,0,0
0,0,0,0,0,0,0,0,0,0,0,0,0,0,0,0,3,3,3,3,3,3,3,0,0,0,0,0,0,0,0,0,0,0,0,0,0,0,0
0,0,0,0,0,0,0,0,0,0,0,0,0,0,0,0,3,0,0,49,0,0,3,0,0,0,0,0,0,0,0,0,0,0,0,0,0,0,0
0,0,0,0,0,0,0,0,0,0,0,0,0,0,0,0,3,0,0,0,0,0,3,0,0,0,0,0,0,0,0,0,0,0,0,0,0,0,0
0,0,0,0,0,0,0,0,0,0,0,0,0,0,0,0,3,0,0,0,0,0,3,0,0,0,0,0,0,0,0,0,0,0,0,0,0,0,0
0,0,0,0,0,0,0,0,0,0,0,0,0,0,0,42,3,48,0,0,0,42,3,48,0,0,0,0,0,0,0,0,0,0,0,0,0,0,0
0,0,0,0,0,0,0,0,0,0,0,0,0,0,0,0,3,0,0,0,0,0,3,0,0,0,0,0,0,0,0,0,0,0,0,0,0,0,0
0,0,0,0,0,0,0,0,0,0,47,3,3,3,3,3,3,0,0,0,0,0,3,3,3,3,3,3,47,0,0,0,0,0,0,0,0,0,0
0,0,0,0,0,0,0,0,0,42,3,3,3,3,3,3,3,0,0,0,0,0,3,3,3,3,3,3,3,48,0,0,0,0,0,0,0,0,0
0,0,0,0,0,0,0,0,0,3,3,3,3,3,26,0,0,0,0,47,0,0,0,0,24,3,3,3,3,3,0,0,0,0,0,0,0,0,0
0,0,0,0,0,0,0,0,0,3,3,3,3,3,3,3,3,3,3,3,3,3,3,3,3,3,3,3,3,3,0,0,0,0,0,0,0,0,0
0,0,0,0,0,0,0,0,0,3,3,3,3,3,3,3,3,49,3,67,3,3,3,3,3,3,3,3,3,3,0,0,0,0,0,0,0,0,0
0,0,0,0,0,0,0,0,0,3,3,67,3,3,3,3,3,0,3,0,3,3,3,3,3,3,3,67,3,3,0,0,0,0,0,0,0,0,0
0,0,0,0,0,0,0,0,0,3,3,0,3,3,3,3,0,0,0,0,0,0,0,3,3,3,3,0,3,3,0,47,0,0,0,0,0,0,0
0,0,0,3,3,3,3,3,3,3,3,0,3,3,3,0,0,0,0,0,0,0,0,0,3,3,3,0,3,3,3,3,3,3,3,3,0,0,0
0,0,0,3,0,0,0,49,0,0,0,0,3,3,3,0,0,0,0,0,0,0,0,0,0,42,3,0,0,0,0,49,0,0,0,3,0,0,0
0,0,0,3,0,0,0,0,0,0,0,0,3,3,3,0,0,0,0,0,0,0,0,0,3,3,3,0,0,0,0,0,0,0,0,3,0,0,0
0,0,0,3,48,0,0,0,0,0,0,42,3,26,0,0,0,0,24,3,0,3,0,0,0,24,3,48,0,0,0,0,0,0,42,3,0,0,0
0,0,0,3,0,0,0,0,0,0,0,0,3,3,3,0,0,0,24,3,0,3,0,0,3,3,3,0,0,0,0,0,0,0,0,3,0,0,0
0,0,0,3,0,0,0,47,0,0,0,0,3,48,0,0,0,0,0,0,0,0,0,0,3,3,3,0,0,0,0,47,0,0,0,3,0,0,0
0,0,0,3,3,3,3,3,3,3,3,0,3,3,3,0,0,0,0,0,0,0,0,0,3,3,3,0,3,3,3,3,3,3,3,3,0,0,0
0,0,0,0,0,0,0,49,0,3,3,0,3,3,3,3,0,0,0,0,0,0,0,3,3,3,3,0,3,3,0,49,0,0,0,0,0,0,0
0,0,0,0,0,0,0,0,0,3,3,151,3,3,3,3,3,0,3,0,3,3,3,3,3,3,3,151,3,3,0,0,0,0,0,0,0,0,0
0,0,0,0,0,0,0,0,0,3,3,3,3,3,3,3,3,47,3,151,3,3,3,3,3,3,3,3,3,3,0,0,0,0,0,0,0,0,0
0,0,0,0,0,0,0,0,0,3,3,3,3,3,3,3,3,3,3,3,3,3,3,3,3,3,3,3,3,3,0,0,0,0,0,0,0,0,0
0,0,0,0,0,0,0,0,0,3,3,3,3,3,26,0,0,0,0,49,0,0,0,0,24,3,3,3,3,3,0,0,0,0,0,0,0,0,0
0,0,0,0,0,0,0,0,0,42,3,3,3,3,3,3,3,0,0,0,0,0,3,3,3,3,3,3,3,48,0,0,0,0,0,0,0,0,0
0,0,0,0,0,0,0,0,0,0,49,3,3,3,3,3,3,0,0,0,0,0,3,3,3,3,3,3,49,0,0,0,0,0,0,0,0,0,0
0,0,0,0,0,0,0,0,0,0,0,0,0,0,0,0,3,0,0,0,0,0,3,0,0,0,0,0,0,0,0,0,0,0,0,0,0,0,0
0,0,0,0,0,0,0,0,0,0,0,0,0,0,0,42,3,48,0,0,0,0,3,48,0,0,0,0,0,0,0,0,0,0,0,0,0,0,0
0,0,0,0,0,0,0,0,0,0,0,0,0,0,0,0,3,0,0,0,0,42,3,0,0,0,0,0,0,0,0,0,0,0,0,0,0,0,0
0,0,0,0,0,0,0,0,0,0,0,0,0,0,0,0,3,0,0,0,0,0,3,0,0,0,0,0,0,0,0,0,0,0,0,0,0,0,0
0,0,0,0,0,0,0,0,0,0,0,0,0,0,0,0,3,0,0,47,0,0,3,0,0,0,0,0,0,0,0,0,0,0,0,0,0,0,0
0,0,0,0,0,0,0,0,0,0,0,0,0,0,0,0,3,3,3,3,3,3,3,0,0,0,0,0,0,0,0,0,0,0,0,0,0,0,0
0,0,0,0,0,0,0,0,0,0,0,0,0,0,0,0,0,0,49,0,49,0,0,0,0,0,0,0,0,0,0,0,0,0,0,0,0,0,0
0,0,0,0,0,0,0,0,0,0,0,0,0,0,0,0,3,0,0,0,0,0,3,0,0,0,0,0,0,0,0,0,0,0,0,0,0,0,0
0,0,0,0,0,0,0,0,0,0,0,0,0,0,0,0,0,0,0,0,0,0,0,0,0,0,0,0,0,0,0,0,0,0,0,0,0,0,0
0,0,0,0,0,0,0,0,0,0,0,0,0,0,0,0,0,0,0,0,0,0,0,0,0,0,0,0,0,0,0,0,0,0,0,0,0,0,0
0,0,0,0,0,0,0,0,0,0,0,0,0,0,0,0,0,0,0,0,0,0,0,0,0,0,0,0,0,0,0,0,0,0,0,0,0,0,0
0,0,0,0,0,0,0,0,0,0,0,0,0,0,0,0,0,0,0,0,0,0,0,0,0,0,0,0,0,0,0,0,0,0,0,0,0,0,0
:endlayer
layer: 14
0,0,0,0,0,0,0,0,0,0,0,0,0,0,0,0,0,0,0,0,0,0,0,0,0,0,0,0,0,0,0,0,0,0,0,0,0,0,0
0,0,0,0,0,0,0,0,0,0,0,0,0,0,0,0,0,0,0,0,0,0,0,0,0,0,0,0,0,0,0,0,0,0,0,0,0,0,0
0,0,0,0,0,0,0,0,0,0,0,0,0,0,0,0,0,0,0,0,0,0,0,0,0,0,0,0,0,0,0,0,0,0,0,0,0,0,0
0,0,0,0,0,0,0,0,0,0,0,0,0,0,0,0,3,3,3,3,3,3,3,0,0,0,0,0,0,0,0,0,0,0,0,0,0,0,0
0,0,0,0,0,0,0,0,0,0,0,0,0,0,0,0,3,3,3,3,3,3,3,0,0,0,0,0,0,0,0,0,0,0,0,0,0,0,0
0,0,0,0,0,0,0,0,0,0,0,0,0,0,0,0,3,3,3,3,3,3,3,0,0,0,0,0,0,0,0,0,0,0,0,0,0,0,0
0,0,0,0,0,0,0,0,0,0,0,0,0,0,0,0,3,3,3,3,3,3,3,0,0,0,0,0,0,0,0,0,0,0,0,0,0,0,0
0,0,0,0,0,0,0,0,0,0,0,0,0,0,0,0,3,3,3,3,3,3,3,0,0,0,0,0,0,0,0,0,0,0,0,0,0,0,0
0,0,0,0,0,0,0,0,0,0,0,3,3,3,3,3,3,3,3,3,3,3,3,3,3,3,3,3,0,0,0,0,0,0,0,0,0,0,0
0,0,0,0,0,0,0,0,0,0,3,3,148,148,148,148,3,3,3,3,3,3,3,148,148,148,148,3,3,0,0,0,0,0,0,0,0,0,0
0,0,0,0,0,0,0,0,0,3,3,3,0,0,0,0,3,3,3,3,3,3,3,0,0,0,0,3,3,3,0,0,0,0,0,0,0,0,0
0,0,0,0,0,0,0,0,3,3,3,148,0,0,0,0,42,3,3,3,3,3,48,0,0,0,0,148,3,3,3,0,0,0,0,0,0,0,0
0,0,0,0,0,0,0,0,3,148,0,0,174,0,0,0,3,3,3,67,3,3,3,0,0,0,175,0,0,148,3,0,0,0,0,0,0,0,0
0,0,0,0,0,0,0,0,3,148,0,0,0,0,0,0,3,3,3,0,3,3,3,0,0,0,0,0,0,148,3,0,0,0,0,0,0,0,0
0,0,0,0,0,0,0,0,3,148,0,0,0,0,0,0,3,3,3,0,3,3,3,0,0,0,0,0,0,148,3,0,0,0,0,0,0,0,0
0,0,0,0,0,0,0,0,3,148,0,0,0,0,0,0,3,0,49,0,49,0,3,0,0,0,0,0,0,148,3,0,0,0,0,0,0,0,0
0,0,0,3,3,3,3,3,3,3,3,47,3,3,3,3,0,0,0,0,0,0,0,3,3,3,3,47,3,3,3,3,3,3,3,3,0,0,0
0,0,0,3,3,3,3,3,3,3,3,3,3,3,3,0,0,0,0,0,0,0,0,0,3,3,3,3,3,3,3,3,3,3,3,3,0,0,0
0,0,0,3,3,3,3,3,3,3,3,3,3,3,3,48,0,0,0,0,0,0,0,42,3,3,3,3,3,3,3,3,3,3,3,3,0,0,0
0,0,0,3,3,3,3,3,3,3,3,3,26,0,0,0,0,0,0,24,3,3,0,0,0,0,24,3,3,3,3,3,3,3,3,3,0,0,0
0,0,0,3,3,3,3,3,3,3,3,3,3,3,3,48,0,0,0,24,3,3,0,42,3,3,3,3,3,3,3,3,3,3,3,3,0,0,0
0,0,0,3,3,3,3,3,3,3,3,0,3,3,58,0,0,0,0,0,0,0,0,0,3,3,3,0,3,3,3,3,3,3,3,3,0,0,0
0,0,0,3,3,3,3,3,3,3,3,0,3,3,3,3,0,0,0,0,0,0,0,3,3,3,3,0,3,3,3,3,3,3,3,3,0,0,0
0,0,0,0,0,0,0,0,3,148,0,0,0,0,0,0,3,0,47,0,47,0,3,0,0,0,0,0,0,148,3,0,0,0,0,0,0,0,0
0,0,0,0,0,0,0,0,3,148,0,0,0,0,0,0,3,3,3,0,3,3,3,0,0,0,0,0,0,148,3,0,0,0,0,0,0,0,0
0,0,0,0,0,0,0,0,3,148,0,0,0,0,0,0,3,3,3,0,3,3,3,0,0,0,0,0,0,148,3,0,0,0,0,0,0,0,0
0,0,0,0,0,0,0,0,3,148,0,0,176,0,0,0,3,3,3,151,3,3,3,0,0,0,177,0,0,148,3,0,0,0,0,0,0,0,0
0,0,0,0,0,0,0,0,3,3,3,148,0,0,0,0,0,0,3,3,3,48,0,0,0,0,0,148,3,3,3,0,0,0,0,0,0,0,0
0,0,0,0,0,0,0,0,0,3,3,3,0,0,0,0,3,3,3,3,3,3,3,0,0,0,0,3,3,3,0,0,0,0,0,0,0,0,0
0,0,0,0,0,0,0,0,0,0,3,3,148,148,148,148,3,3,3,3,3,3,3,148,148,148,148,3,3,0,0,0,0,0,0,0,0,0,0
0,0,0,0,0,0,0,0,0,0,0,3,3,3,3,3,3,3,3,3,3,3,3,3,3,3,3,3,0,0,0,0,0,0,0,0,0,0,0
0,0,0,0,0,0,0,0,0,0,0,0,0,0,0,178,3,3,3,3,3,3,3,179,0,0,0,0,0,0,0,0,0,0,0,0,0,0,0
0,0,0,0,0,0,0,0,0,0,0,0,0,0,0,178,3,3,3,3,3,3,3,179,0,0,0,0,0,0,0,0,0,0,0,0,0,0,0
0,0,0,0,0,0,0,0,0,0,0,0,0,0,0,178,3,3,3,3,3,3,3,179,0,0,0,0,0,0,0,0,0,0,0,0,0,0,0
0,0,0,0,0,0,0,0,0,0,0,0,0,0,0,178,3,3,3,3,3,3,3,179,0,0,0,0,0,0,0,0,0,0,0,0,0,0,0
0,0,0,0,0,0,0,0,0,0,0,0,0,0,0,178,3,3,3,3,3,3,3,179,0,0,0,0,0,0,0,0,0,0,0,0,0,0,0
0,0,0,0,0,0,0,0,0,0,0,0,0,0,0,178,180,0,0,0,0,0,180,179,0,0,0,0,0,0,0,0,0,0,0,0,0,0,0
0,0,0,0,0,0,0,0,0,0,0,0,0,0,0,178,180,180,180,180,180,180,180,179,0,0,0,0,0,0,0,0,0,0,0,0,0,0,0
0,0,0,0,0,0,0,0,0,0,0,0,0,0,0,181,181,181,181,181,181,181,181,179,0,0,0,0,0,0,0,0,0,0,0,0,0,0,0
0,0,0,0,0,0,0,0,0,0,0,0,0,0,0,0,0,0,0,0,0,0,0,0,0,0,0,0,0,0,0,0,0,0,0,0,0,0,0
0,0,0,0,0,0,0,0,0,0,0,0,0,0,0,0,0,0,0,0,0,0,0,0,0,0,0,0,0,0,0,0,0,0,0,0,0,0,0
0,0,0,0,0,0,0,0,0,0,0,0,0,0,0,0,0,0,0,0,0,0,0,0,0,0,0,0,0,0,0,0,0,0,0,0,0,0,0
:endlayer
layer: 15
0,0,0,0,0,0,0,0,0,0,0,0,0,0,0,0,0,0,0,0,0,0,0,0,0,0,0,0,0,0,0,0,0,0,0,0,0,0,0
0,0,0,0,0,0,0,0,0,0,0,0,0,0,0,0,0,0,0,0,0,0,0,0,0,0,0,0,0,0,0,0,0,0,0,0,0,0,0
0,0,0,0,0,0,0,0,0,0,0,0,0,0,0,0,47,0,0,0,0,0,47,0,0,0,0,0,0,0,0,0,0,0,0,0,0,0,0
0,0,0,0,0,0,0,0,0,0,0,0,0,0,0,42,3,3,3,3,3,3,3,48,0,0,0,0,0,0,0,0,0,0,0,0,0,0,0
0,0,0,0,0,0,0,0,0,0,0,0,0,0,0,0,3,182,0,0,0,182,3,0,0,0,0,0,0,0,0,0,0,0,0,0,0,0,0
0,0,0,0,0,0,0,0,0,0,0,0,0,0,0,0,3,183,0,0,0,183,3,0,0,0,0,0,0,0,0,0,0,0,0,0,0,0,0
0,0,0,0,0,0,0,0,0,0,0,0,0,0,0,0,3,0,0,184,0,0,3,0,0,0,0,0,0,0,0,0,0,0,0,0,0,0,0
0,0,0,0,0,0,0,0,0,0,0,0,0,0,0,0,3,0,0,0,0,0,3,0,0,0,0,0,0,0,0,0,0,0,0,0,0,0,0
0,0,0,0,0,0,0,0,0,0,0,89,0,0,0,0,3,0,0,0,0,0,3,0,0,0,0,89,0,0,0,0,0,0,0,0,0,0,0
0,0,0,0,0,0,0,0,0,0,0,0,0,0,0,0,3,0,0,0,0,185,3,0,0,0,0,0,0,0,0,0,0,0,0,0,0,0,0
0,0,0,0,0,0,0,0,0,0,0,0,0,0,0,0,3,186,0,0,0,187,3,0,0,0,0,0,0,0,0,0,0,0,0,0,0,0,0
0,0,0,0,0,0,0,0,89,0,0,0,0,0,0,42,3,3,0,0,0,3,3,48,0,0,0,0,0,0,89,0,0,0,0,0,0,0,0
0,0,0,0,0,0,0,0,0,0,0,0,0,0,0,0,3,3,3,0,3,3,3,0,0,0,0,0,0,0,0,0,0,0,0,0,0,0,0
0,0,0,0,0,0,0,0,0,0,0,0,0,0,0,0,3,3,3,0,3,3,3,0,0,0,0,0,0,0,0,0,0,0,0,0,0,0,0
0,0,0,0,0,0,0,0,0,0,0,0,0,0,0,0,3,3,3,0,3,3,3,0,0,0,0,0,0,0,0,0,0,0,0,0,0,0,0
0,0,0,47,0,0,0,0,0,0,0,47,0,0,0,47,3,0,0,0,0,0,3,48,0,0,0,47,0,0,0,0,0,0,0,47,0,0,0
0,0,42,3,3,3,3,3,3,3,3,3,3,3,3,3,0,0,0,0,0,0,0,3,3,3,3,3,3,3,3,3,3,3,3,3,48,0,0
0,0,0,3,182,0,0,0,0,122,123,3,3,3,3,0,0,0,0,0,0,0,0,0,3,3,3,3,120,121,0,0,0,122,123,3,0,0,0
0,0,0,3,183,0,0,0,0,0,0,0,3,3,58,0,0,0,0,0,0,0,0,0,3,3,3,0,0,0,0,0,0,0,0,3,0,0,0
0,0,0,3,0,0,0,188,0,0,0,0,0,0,0,0,0,0,0,0,24,3,0,0,0,0,0,0,0,0,0,0,189,0,0,3,0,0,0
0,0,0,3,185,0,0,0,0,0,0,0,3,3,58,0,0,0,0,0,24,3,0,0,3,3,3,0,0,0,0,0,0,0,0,3,0,0,0
0,0,0,3,187,0,0,0,0,122,123,3,3,3,58,0,0,0,0,0,0,0,0,0,3,3,3,3,190,0,0,0,0,122,123,3,0,0,0
0,0,42,3,3,3,3,3,3,3,3,49,3,3,3,3,0,0,0,0,0,0,0,3,3,3,3,49,3,3,3,3,3,3,3,3,48,0,0
0,0,0,49,0,0,0,0,0,0,0,0,0,0,0,42,3,0,0,0,0,0,3,49,0,0,0,0,0,0,0,0,0,0,0,49,0,0,0
0,0,0,0,0,0,0,0,0,0,0,0,0,0,0,0,3,3,3,0,3,3,3,0,0,0,0,0,0,0,0,0,0,0,0,0,0,0,0
0,0,0,0,0,0,0,0,0,0,0,0,0,0,0,0,3,3,3,0,3,3,3,0,0,0,0,0,0,0,0,0,0,0,0,0,0,0,0
0,0,0,0,0,0,0,0,0,0,0,0,0,0,0,0,3,3,3,0,3,3,3,0,0,0,0,0,0,0,0,0,0,0,0,0,0,0,0
0,0,0,0,0,0,0,0,89,0,0,0,0,0,0,0,42,3,0,0,0,3,0,0,0,0,0,0,0,0,89,0,0,0,0,0,0,0,0
0,0,0,0,0,0,0,0,0,0,0,0,0,0,0,0,3,191,0,0,0,0,3,0,0,0,0,0,0,0,0,0,0,0,0,0,0,0,0
0,0,0,0,0,0,0,0,0,0,0,0,0,0,0,0,3,0,0,0,0,0,3,0,0,0,0,0,0,0,0,0,0,0,0,0,0,0,0
0,0,0,0,0,0,0,0,0,0,0,89,0,0,0,0,3,0,0,0,0,0,3,0,0,0,0,89,0,0,0,0,0,0,0,0,0,0,0
0,0,0,0,0,0,0,0,0,0,0,0,0,0,0,0,3,0,0,0,0,0,3,0,0,0,0,0,0,0,0,0,0,0,0,0,0,0,0
0,0,0,0,0,0,0,0,0,0,0,0,0,0,0,0,3,0,0,0,0,0,3,0,0,0,0,0,0,0,0,0,0,0,0,0,0,0,0
0,0,0,0,0,0,0,0,0,0,0,0,0,0,0,0,3,0,0,192,0,0,3,0,0,0,0,0,0,0,0,0,0,0,0,0,0,0,0
0,0,0,0,0,0,0,0,0,0,0,0,0,0,0,0,3,120,121,0,122,123,3,0,0,0,0,0,0,0,0,0,0,0,0,0,0,0,0
0,0,0,0,0,0,0,0,0,0,0,0,0,0,0,42,3,3,3,3,3,3,3,48,0,0,0,0,0,0,0,0,0,0,0,0,0,0,0
0,0,0,0,0,0,0,0,0,0,0,0,0,0,0,0,178,0,0,0,0,0,179,0,0,0,0,0,0,0,0,0,0,0,0,0,0,0,0
0,0,0,0,0,0,0,0,0,0,0,0,0,0,0,0,178,181,181,181,181,181,179,0,0,0,0,0,0,0,0,0,0,0,0,0,0,0,0
0,0,0,0,0,0,0,0,0,0,0,0,0,0,0,0,0,0,0,0,0,0,0,0,0,0,0,0,0,0,0,0,0,0,0,0,0,0,0
0,0,0,0,0,0,0,0,0,0,0,0,0,0,0,0,0,0,0,0,0,0,0,0,0,0,0,0,0,0,0,0,0,0,0,0,0,0,0
0,0,0,0,0,0,0,0,0,0,0,0,0,0,0,0,0,0,0,0,0,0,0,0,0,0,0,0,0,0,0,0,0,0,0,0,0,0,0
0,0,0,0,0,0,0,0,0,0,0,0,0,0,0,0,0,0,0,0,0,0,0,0,0,0,0,0,0,0,0,0,0,0,0,0,0,0,0
:endlayer
layer: 16
0,0,0,0,0,0,0,0,0,0,0,0,0,0,0,0,0,0,0,0,0,0,0,0,0,0,0,0,0,0,0,0,0,0,0,0,0,0,0
0,0,0,0,0,0,0,0,0,0,0,0,0,0,0,0,0,0,0,0,0,0,0,0,0,0,0,0,0,0,0,0,0,0,0,0,0,0,0
0,0,0,0,0,0,0,0,0,0,0,0,0,0,0,0,0,0,0,0,0,0,0,0,0,0,0,0,0,0,0,0,0,0,0,0,0,0,0
0,0,0,0,0,0,0,0,0,0,0,0,0,0,0,0,3,3,3,0,3,3,3,0,0,0,0,0,0,0,0,0,0,0,0,0,0,0,0
0,0,0,0,0,0,0,0,0,0,0,0,0,0,0,0,3,0,0,0,0,0,3,0,0,0,0,0,0,0,0,0,0,0,0,0,0,0,0
0,0,0,0,0,0,0,0,0,0,0,0,0,0,0,0,3,0,0,0,0,0,3,0,0,0,0,0,0,0,0,0,0,0,0,0,0,0,0
0,0,0,0,0,0,0,0,0,0,0,0,0,0,0,0,0,0,0,0,0,0,0,0,0,0,0,0,0,0,0,0,0,0,0,0,0,0,0
0,0,0,0,0,0,0,0,0,0,0,0,0,0,0,0,3,0,0,0,0,0,3,0,0,0,0,0,0,0,0,0,0,0,0,0,0,0,0
0,0,0,0,0,0,0,0,0,0,0,0,0,0,0,0,3,0,0,0,0,0,3,0,0,0,0,0,0,0,0,0,0,0,0,0,0,0,0
0,0,0,0,0,0,0,0,0,0,0,0,0,0,0,0,3,0,0,0,0,0,3,0,0,0,0,0,0,0,0,0,0,0,0,0,0,0,0
0,0,0,0,0,0,0,0,0,0,0,0,0,0,0,0,3,0,0,0,0,0,3,0,0,0,0,0,0,0,0,0,0,0,0,0,0,0,0
0,0,0,0,0,0,0,0,0,0,0,0,0,0,0,0,3,3,0,0,0,3,3,0,0,0,0,0,0,0,0,0,0,0,0,0,0,0,0
0,0,0,0,0,0,0,0,0,0,0,0,0,0,0,0,3,3,3,0,3,3,3,0,0,0,0,0,0,0,0,0,0,0,0,0,0,0,0
0,0,0,0,0,0,0,0,0,0,0,0,0,0,0,0,3,3,3,0,3,3,3,0,0,0,0,0,0,0,0,0,0,0,0,0,0,0,0
0,0,0,0,0,0,0,0,0,0,0,0,0,0,0,0,3,3,3,0,3,3,3,0,0,0,0,0,0,0,0,0,0,0,0,0,0,0,0
0,0,0,0,0,0,0,0,0,0,0,0,0,0,0,0,3,0,0,0,0,0,3,0,0,0,0,0,0,0,0,0,0,0,0,0,0,0,0
0,0,0,3,3,3,0,3,3,3,3,3,3,3,3,3,0,0,0,0,0,0,0,3,3,3,3,3,3,3,3,3,0,3,3,3,0,0,0
0,0,0,3,0,0,0,0,0,0,0,3,3,3,3,0,0,0,0,0,0,0,0,0,3,3,3,3,0,0,0,0,0,0,0,3,0,0,0
0,0,0,3,0,0,0,0,0,0,0,0,3,3,3,0,0,0,0,0,0,0,0,0,3,3,3,0,0,0,0,0,0,0,0,3,0,0,0
0,0,0,0,0,0,0,0,0,0,0,0,0,0,0,0,0,0,0,0,0,24,3,3,3,0,0,0,0,0,0,0,0,0,0,0,0,0,0
0,0,0,3,0,0,0,0,0,0,0,0,3,3,3,0,0,0,0,0,0,24,3,3,3,3,3,0,0,0,0,0,0,0,0,3,0,0,0
0,0,0,3,0,0,0,0,0,0,0,3,3,3,3,0,0,0,0,0,0,0,0,0,3,3,3,3,0,0,0,0,0,0,0,3,0,0,0
0,0,0,3,3,3,0,3,3,3,3,3,3,3,3,3,0,0,0,0,0,0,0,3,3,3,3,3,3,3,3,3,0,3,3,3,0,0,0
0,0,0,0,0,0,0,0,0,0,0,49,0,0,0,0,3,0,0,0,0,0,3,0,0,0,0,49,0,0,0,0,0,0,0,0,0,0,0
0,0,0,0,0,0,0,0,0,0,0,0,0,0,0,0,3,3,3,0,3,3,3,0,0,0,0,0,0,0,0,0,0,0,0,0,0,0,0
0,0,0,0,0,0,0,0,0,0,0,0,0,0,0,0,3,3,3,0,3,3,3,0,0,0,0,0,0,0,0,0,0,0,0,0,0,0,0
0,0,0,0,0,0,0,0,0,0,0,0,0,0,0,0,3,3,3,0,3,3,3,0,0,0,0,0,0,0,0,0,0,0,0,0,0,0,0
0,0,0,0,0,0,0,0,0,0,0,0,0,0,0,42,3,3,0,0,0,3,3,48,0,0,0,0,0,0,0,0,0,0,0,0,0,0,0
0,0,0,0,0,0,0,0,0,0,0,0,0,0,0,0,3,0,0,0,0,0,3,0,0,0,0,0,0,0,0,0,0,0,0,0,0,0,0
0,0,0,0,0,0,0,0,0,0,0,0,0,0,0,0,3,0,0,0,0,0,3,0,0,0,0,0,0,0,0,0,0,0,0,0,0,0,0
0,0,0,0,0,0,0,0,0,0,0,0,0,0,0,0,3,0,0,0,0,0,3,0,0,0,0,0,0,0,0,0,0,0,0,0,0,0,0
0,0,0,0,0,0,0,0,0,0,0,0,0,0,0,0,3,0,0,0,0,0,3,0,0,0,0,0,0,0,0,0,0,0,0,0,0,0,0
0,0,0,0,0,0,0,0,0,0,0,0,0,0,0,0,0,0,0,0,0,0,0,0,0,0,0,0,0,0,0,0,0,0,0,0,0,0,0
0,0,0,0,0,0,0,0,0,0,0,0,0,0,0,0,3,0,0,0,0,0,3,0,0,0,0,0,0,0,0,0,0,0,0,0,0,0,0
0,0,0,0,0,0,0,0,0,0,0,0,0,0,0,0,3,0,0,0,0,0,3,0,0,0,0,0,0,0,0,0,0,0,0,0,0,0,0
0,0,0,0,0,0,0,0,0,0,0,0,0,0,0,0,3,3,3,3,3,3,3,0,0,0,0,0,0,0,0,0,0,0,0,0,0,0,0
0,0,0,0,0,0,0,0,0,0,0,0,0,0,0,0,0,181,181,181,181,181,0,0,0,0,0,0,0,0,0,0,0,0,0,0,0,0,0
0,0,0,0,0,0,0,0,0,0,0,0,0,0,0,0,0,0,0,0,0,0,0,0,0,0,0,0,0,0,0,0,0,0,0,0,0,0,0
0,0,0,0,0,0,0,0,0,0,0,0,0,0,0,0,0,0,0,0,0,0,0,0,0,0,0,0,0,0,0,0,0,0,0,0,0,0,0
0,0,0,0,0,0,0,0,0,0,0,0,0,0,0,0,0,0,0,0,0,0,0,0,0,0,0,0,0,0,0,0,0,0,0,0,0,0,0
0,0,0,0,0,0,0,0,0,0,0,0,0,0,0,0,0,0,0,0,0,0,0,0,0,0,0,0,0,0,0,0,0,0,0,0,0,0,0
0,0,0,0,0,0,0,0,0,0,0,0,0,0,0,0,0,0,0,0,0,0,0,0,0,0,0,0,0,0,0,0,0,0,0,0,0,0,0
:endlayer
layer: 17
0,0,0,0,0,0,0,0,0,0,0,0,0,0,0,0,0,0,0,0,0,0,0,0,0,0,0,0,0,0,0,0,0,0,0,0,0,0,0
0,0,0,0,0,0,0,0,0,0,0,0,0,0,0,0,0,0,0,0,0,0,0,0,0,0,0,0,0,0,0,0,0,0,0,0,0,0,0
0,0,0,0,0,0,0,0,0,0,0,0,0,0,0,0,0,0,0,0,0,0,0,0,0,0,0,0,0,0,0,0,0,0,0,0,0,0,0
0,0,0,0,0,0,0,0,0,0,0,0,0,0,0,0,3,3,3,3,3,3,3,0,0,0,0,0,0,0,0,0,0,0,0,0,0,0,0
0,0,0,0,0,0,0,0,0,0,0,0,0,0,0,0,3,0,0,49,0,0,3,0,0,0,0,0,0,0,0,0,0,0,0,0,0,0,0
0,0,0,0,0,0,0,0,0,0,0,0,0,0,0,0,3,0,0,0,0,0,3,0,0,0,0,0,0,0,0,0,0,0,0,0,0,0,0
0,0,0,0,0,0,0,0,0,0,0,0,0,0,0,0,3,48,0,0,0,42,3,0,0,0,0,0,0,0,0,0,0,0,0,0,0,0,0
0,0,0,0,0,0,0,0,0,0,0,0,0,0,0,0,3,0,0,0,0,0,3,0,0,0,0,0,0,0,0,0,0,0,0,0,0,0,0
0,0,0,0,0,0,0,0,0,0,0,0,0,0,0,0,3,0,0,0,0,0,3,0,0,0,0,0,0,0,0,0,0,0,0,0,0,0,0
0,0,0,0,0,0,0,0,0,0,0,0,0,0,0,0,3,0,0,0,0,0,3,0,0,0,0,0,0,0,0,0,0,0,0,0,0,0,0
0,0,0,0,0,0,0,0,0,0,0,0,0,0,0,0,3,0,0,0,0,0,3,0,0,0,0,0,0,0,0,0,0,0,0,0,0,0,0
0,0,0,0,0,0,0,0,0,0,0,0,0,0,0,0,3,3,0,47,0,3,3,0,0,0,0,0,0,0,0,0,0,0,0,0,0,0,0
0,0,0,0,0,0,0,0,0,0,0,0,0,0,0,0,3,3,3,3,3,3,3,0,0,0,0,0,0,0,0,0,0,0,0,0,0,0,0
0,0,0,0,0,0,0,0,0,0,0,0,0,0,0,0,3,3,3,3,3,3,3,0,0,0,0,0,0,0,0,0,0,0,0,0,0,0,0
0,0,0,0,0,0,0,0,0,0,0,0,0,0,0,0,3,3,3,3,3,3,3,0,0,0,0,0,0,0,0,0,0,0,0,0,0,0,0
0,0,0,0,0,0,0,0,0,0,0,0,0,0,0,0,3,0,0,49,0,0,3,0,0,0,0,0,0,0,0,0,0,0,0,0,0,0,0
0,0,0,3,3,3,3,3,3,3,3,3,3,3,3,3,0,0,0,0,0,0,0,3,3,3,3,3,3,3,3,3,3,3,3,3,0,0,0
0,0,0,3,0,0,49,0,0,0,0,3,3,3,3,0,0,0,0,0,0,0,0,0,3,3,3,3,0,0,0,0,49,0,0,3,0,0,0
0,0,0,3,0,0,0,0,0,0,0,0,3,3,3,0,0,0,0,0,0,0,0,0,3,3,3,0,0,0,0,0,0,0,0,3,0,0,0
0,0,0,3,48,0,0,0,0,0,0,42,3,3,3,48,0,0,0,0,0,0,24,3,3,3,3,48,0,0,0,0,0,0,42,3,0,0,0
0,0,0,3,0,0,0,0,0,0,0,0,3,3,3,0,0,0,0,0,0,0,24,3,3,3,3,0,0,0,0,0,0,0,0,3,0,0,0
0,0,0,3,0,0,47,0,0,0,0,3,3,3,3,0,0,0,0,0,0,0,0,0,3,3,3,3,0,0,0,0,47,0,0,3,0,0,0
0,0,0,3,3,3,3,3,3,3,3,3,3,3,3,3,0,0,0,0,0,0,0,3,3,3,3,3,3,3,3,3,3,3,3,3,0,0,0
0,0,0,0,0,0,0,0,0,0,0,0,0,0,0,0,3,0,0,47,0,0,3,0,0,0,0,0,0,0,0,0,0,0,0,0,0,0,0
0,0,0,0,0,0,0,0,0,0,0,0,0,0,0,0,3,3,3,3,3,3,3,0,0,0,0,0,0,0,0,0,0,0,0,0,0,0,0
0,0,0,0,0,0,0,0,0,0,0,0,0,0,0,0,3,3,3,3,3,3,3,0,0,0,0,0,0,0,0,0,0,0,0,0,0,0,0
0,0,0,0,0,0,0,0,0,0,0,0,0,0,0,0,3,3,3,3,3,3,3,0,0,0,0,0,0,0,0,0,0,0,0,0,0,0,0
0,0,0,0,0,0,0,0,0,0,0,0,0,0,0,0,3,3,0,49,0,3,3,0,0,0,0,0,0,0,0,0,0,0,0,0,0,0,0
0,0,0,0,0,0,0,0,0,0,0,0,0,0,0,0,3,0,0,0,0,0,3,0,0,0,0,0,0,0,0,0,0,0,0,0,0,0,0
0,0,0,0,0,0,0,0,0,0,0,0,0,0,0,0,3,0,0,0,0,0,3,0,0,0,0,0,0,0,0,0,0,0,0,0,0,0,0
0,0,0,0,0,0,0,0,0,0,0,0,0,0,0,0,3,0,0,0,0,0,3,0,0,0,0,0,0,0,0,0,0,0,0,0,0,0,0
0,0,0,0,0,0,0,0,0,0,0,0,0,0,0,0,3,0,0,0,0,0,3,0,0,0,0,0,0,0,0,0,0,0,0,0,0,0,0
0,0,0,0,0,0,0,0,0,0,0,0,0,0,0,0,3,48,0,0,0,42,3,0,0,0,0,0,0,0,0,0,0,0,0,0,0,0,0
0,0,0,0,0,0,0,0,0,0,0,0,0,0,0,0,3,0,0,0,0,0,3,0,0,0,0,0,0,0,0,0,0,0,0,0,0,0,0
0,0,0,0,0,0,0,0,0,0,0,0,0,0,0,0,3,0,0,47,0,0,3,0,0,0,0,0,0,0,0,0,0,0,0,0,0,0,0
0,0,0,0,0,0,0,0,0,0,0,0,0,0,0,0,3,3,3,3,3,3,3,0,0,0,0,0,0,0,0,0,0,0,0,0,0,0,0
0,0,0,0,0,0,0,0,0,0,0,0,0,0,0,0,0,0,0,0,0,0,0,0,0,0,0,0,0,0,0,0,0,0,0,0,0,0,0
0,0,0,0,0,0,0,0,0,0,0,0,0,0,0,0,0,0,0,0,0,0,0,0,0,0,0,0,0,0,0,0,0,0,0,0,0,0,0
0,0,0,0,0,0,0,0,0,0,0,0,0,0,0,0,0,0,0,0,0,0,0,0,0,0,0,0,0,0,0,0,0,0,0,0,0,0,0
0,0,0,0,0,0,0,0,0,0,0,0,0,0,0,0,0,0,0,0,0,0,0,0,0,0,0,0,0,0,0,0,0,0,0,0,0,0,0
0,0,0,0,0,0,0,0,0,0,0,0,0,0,0,0,0,0,0,0,0,0,0,0,0,0,0,0,0,0,0,0,0,0,0,0,0,0,0
0,0,0,0,0,0,0,0,0,0,0,0,0,0,0,0,0,0,0,0,0,0,0,0,0,0,0,0,0,0,0,0,0,0,0,0,0,0,0
:endlayer
layer: 18
0,0,0,0,0,0,0,0,0,0,0,0,0,0,0,0,0,0,0,0,0,0,0,0,0,0,0,0,0,0,0,0,0,0,0,0,0,0,0
0,0,0,0,0,0,0,0,0,0,0,0,0,0,0,0,0,0,0,0,0,0,0,0,0,0,0,0,0,0,0,0,0,0,0,0,0,0,0
0,0,0,0,0,0,0,0,0,0,0,0,0,0,0,3,3,3,3,3,3,3,3,3,0,0,0,0,0,0,0,0,0,0,0,0,0,0,0
0,0,0,0,0,0,0,0,0,0,0,0,0,0,0,3,3,3,3,3,3,3,3,3,0,0,0,0,0,0,0,0,0,0,0,0,0,0,0
0,0,0,0,0,0,0,0,0,0,0,0,0,0,0,3,3,3,3,3,3,3,3,3,0,0,0,0,0,0,0,0,0,0,0,0,0,0,0
0,0,0,0,0,0,0,0,0,0,0,0,0,0,0,3,3,3,3,3,3,3,3,3,0,0,0,0,0,0,0,0,0,0,0,0,0,0,0
0,0,0,0,0,0,0,0,0,0,0,0,0,0,0,3,3,3,3,3,3,3,3,3,0,0,0,0,0,0,0,0,0,0,0,0,0,0,0
0,0,0,0,0,0,0,0,0,0,0,0,0,0,0,3,3,3,3,3,3,3,3,3,0,0,0,0,0,0,0,0,0,0,0,0,0,0,0
0,0,0,0,0,0,0,0,0,0,0,0,0,0,0,3,3,3,3,3,3,3,3,3,0,0,0,0,0,0,0,0,0,0,0,0,0,0,0
0,0,0,0,0,0,0,0,0,0,0,0,0,0,0,3,3,3,3,3,3,3,3,3,0,0,0,0,0,0,0,0,0,0,0,0,0,0,0
0,0,0,0,0,0,0,0,0,0,0,0,0,0,0,3,3,3,3,3,3,3,3,3,0,0,0,0,0,0,0,0,0,0,0,0,0,0,0
0,0,0,0,0,0,0,0,0,0,0,0,0,0,0,3,3,3,3,3,3,3,3,3,0,0,0,0,0,0,0,0,0,0,0,0,0,0,0
0,0,0,0,0,0,0,0,0,0,0,0,0,0,0,3,3,3,3,3,3,3,3,3,0,0,0,0,0,0,0,0,0,0,0,0,0,0,0
0,0,0,0,0,0,0,0,0,0,0,0,0,0,0,3,3,3,3,3,3,3,3,3,0,0,0,0,0,0,0,0,0,0,0,0,0,0,0
0,0,0,0,0,0,0,0,0,0,0,0,0,0,0,3,3,3,3,3,3,3,3,3,0,0,0,0,0,0,0,0,0,0,0,0,0,0,0
0,0,3,3,3,3,3,3,3,3,3,3,3,3,3,3,3,3,3,3,3,3,3,3,3,3,3,3,3,3,3,3,3,3,3,3,3,0,0
0,0,3,3,3,3,3,3,3,3,3,3,3,3,3,3,3,3,3,3,3,3,3,3,3,3,3,3,3,3,3,3,3,3,3,3,3,0,0
0,0,3,3,3,3,3,3,3,3,3,3,3,3,3,3,3,3,3,3,3,3,3,3,3,3,3,3,3,3,3,3,3,3,3,3,3,0,0
0,0,3,3,3,3,3,3,3,3,3,3,3,3,3,3,3,3,3,3,3,3,3,3,3,3,3,3,3,3,3,3,3,3,3,3,3,0,0
0,0,3,3,3,3,3,3,3,3,3,3,3,3,3,3,3,3,3,0,0,0,0,24,3,3,3,3,3,3,3,3,3,3,3,3,3,0,0
0,0,3,3,3,3,3,3,3,3,3,3,3,3,3,3,3,3,3,0,0,0,0,24,3,3,3,3,3,3,3,3,3,3,3,3,3,0,0
0,0,3,3,3,3,3,3,3,3,3,3,3,3,3,3,3,3,3,3,3,3,3,3,3,3,3,3,3,3,3,3,3,3,3,3,3,0,0
0,0,3,3,3,3,3,3,3,3,3,3,3,3,3,3,3,3,3,3,3,3,3,3,3,3,3,3,3,3,3,3,3,3,3,3,3,0,0
0,0,3,3,3,3,3,3,3,3,3,3,3,3,3,3,3,3,3,3,3,3,3,3,3,3,3,3,3,3,3,3,3,3,3,3,3,0,0
0,0,0,0,0,0,0,0,0,0,0,0,0,0,0,3,3,3,3,3,3,3,3,3,0,0,0,0,0,0,0,0,0,0,0,0,0,0,0
0,0,0,0,0,0,0,0,0,0,0,0,0,0,0,3,3,3,3,3,3,3,3,3,0,0,0,0,0,0,0,0,0,0,0,0,0,0,0
0,0,0,0,0,0,0,0,0,0,0,0,0,0,0,3,3,3,3,3,3,3,3,3,0,0,0,0,0,0,0,0,0,0,0,0,0,0,0
0,0,0,0,0,0,0,0,0,0,0,0,0,0,0,3,3,3,3,3,3,3,3,3,0,0,0,0,0,0,0,0,0,0,0,0,0,0,0
0,0,0,0,0,0,0,0,0,0,0,0,0,0,0,3,3,3,3,3,3,3,3,3,0,0,0,0,0,0,0,0,0,0,0,0,0,0,0
0,0,0,0,0,0,0,0,0,0,0,0,0,0,0,3,3,3,3,3,3,3,3,3,0,0,0,0,0,0,0,0,0,0,0,0,0,0,0
0,0,0,0,0,0,0,0,0,0,0,0,0,0,0,3,3,3,3,3,3,3,3,3,0,0,0,0,0,0,0,0,0,0,0,0,0,0,0
0,0,0,0,0,0,0,0,0,0,0,0,0,0,0,3,3,3,3,3,3,3,3,3,0,0,0,0,0,0,0,0,0,0,0,0,0,0,0
0,0,0,0,0,0,0,0,0,0,0,0,0,0,0,3,3,3,3,3,3,3,3,3,0,0,0,0,0,0,0,0,0,0,0,0,0,0,0
0,0,0,0,0,0,0,0,0,0,0,0,0,0,0,3,3,3,3,3,3,3,3,3,0,0,0,0,0,0,0,0,0,0,0,0,0,0,0
0,0,0,0,0,0,0,0,0,0,0,0,0,0,0,3,3,3,3,3,3,3,3,3,0,0,0,0,0,0,0,0,0,0,0,0,0,0,0
0,0,0,0,0,0,0,0,0,0,0,0,0,0,0,3,3,3,3,3,3,3,3,3,0,0,0,0,0,0,0,0,0,0,0,0,0,0,0
0,0,0,0,0,0,0,0,0,0,0,0,0,0,0,3,3,3,3,3,3,3,3,3,0,0,0,0,0,0,0,0,0,0,0,0,0,0,0
0,0,0,0,0,0,0,0,0,0,0,0,0,0,0,0,0,0,0,0,0,0,0,0,0,0,0,0,0,0,0,0,0,0,0,0,0,0,0
0,0,0,0,0,0,0,0,0,0,0,0,0,0,0,0,0,0,0,0,0,0,0,0,0,0,0,0,0,0,0,0,0,0,0,0,0,0,0
0,0,0,0,0,0,0,0,0,0,0,0,0,0,0,0,0,0,0,0,0,0,0,0,0,0,0,0,0,0,0,0,0,0,0,0,0,0,0
0,0,0,0,0,0,0,0,0,0,0,0,0,0,0,0,0,0,0,0,0,0,0,0,0,0,0,0,0,0,0,0,0,0,0,0,0,0,0
0,0,0,0,0,0,0,0,0,0,0,0,0,0,0,0,0,0,0,0,0,0,0,0,0,0,0,0,0,0,0,0,0,0,0,0,0,0,0
:endlayer
layer: 19
0,0,0,0,0,0,0,0,0,0,0,0,0,0,0,0,0,0,0,0,0,0,0,0,0,0,0,0,0,0,0,0,0,0,0,0,0,0,0
0,0,0,0,0,0,0,0,0,0,0,0,0,0,0,0,0,0,0,0,0,0,0,0,0,0,0,0,0,0,0,0,0,0,0,0,0,0,0
0,0,0,0,0,0,0,0,0,0,0,0,0,0,0,3,3,3,3,3,3,3,3,3,0,0,0,0,0,0,0,0,0,0,0,0,0,0,0
0,0,0,0,0,0,0,0,0,0,0,0,0,0,0,3,0,0,0,0,0,0,0,3,0,0,0,0,0,0,0,0,0,0,0,0,0,0,0
0,0,0,0,0,0,0,0,0,0,0,0,0,0,0,3,0,0,0,0,0,0,0,3,0,0,0,0,0,0,0,0,0,0,0,0,0,0,0
0,0,0,0,0,0,0,0,0,0,0,0,0,0,0,3,0,0,0,193,0,0,0,3,0,0,0,0,0,0,0,0,0,0,0,0,0,0,0
0,0,0,0,0,0,0,0,0,0,0,0,0,0,0,3,0,0,3,194,0,0,0,3,0,0,0,0,0,0,0,0,0,0,0,0,0,0,0
0,0,0,0,0,0,0,0,0,0,0,0,0,0,0,3,0,0,0,0,0,0,0,3,0,0,0,0,0,0,0,0,0,0,0,0,0,0,0
0,0,0,0,0,0,0,0,0,0,0,0,0,0,0,3,0,0,0,195,0,0,0,3,0,0,0,0,0,0,0,0,0,0,0,0,0,0,0
0,0,0,0,0,0,0,0,0,0,0,0,0,0,0,3,0,0,0,0,0,0,0,3,0,0,0,0,0,0,0,0,0,0,0,0,0,0,0
0,0,0,0,0,0,0,0,0,0,0,0,0,0,0,3,0,0,0,0,0,0,0,3,0,0,0,0,0,0,0,0,0,0,0,0,0,0,0
0,0,0,0,0,0,0,0,0,0,0,0,0,0,0,3,0,0,3,88,3,0,0,3,0,0,0,0,0,0,0,0,0,0,0,0,0,0,0
0,0,0,0,0,0,0,0,0,0,0,0,0,0,0,3,0,3,3,3,3,3,0,3,0,0,0,0,0,0,0,0,0,0,0,0,0,0,0
0,0,0,0,0,0,0,0,0,0,0,0,0,0,0,3,0,3,3,3,3,3,0,3,0,0,0,0,0,0,0,0,0,0,0,0,0,0,0
0,0,0,0,0,0,0,0,0,0,0,0,0,0,0,3,0,3,3,3,3,3,0,3,0,0,0,0,0,0,0,0,0,0,0,0,0,0,0
0,0,3,3,3,3,3,3,3,3,3,3,3,3,3,3,0,3,0,0,0,3,0,3,3,3,3,3,3,3,3,3,3,3,3,3,3,0,0
0,0,3,0,0,0,0,0,0,0,0,0,0,0,0,0,0,0,0,0,0,0,0,0,0,0,0,0,0,0,0,0,0,0,0,0,3,0,0
0,0,3,0,0,0,0,0,0,0,0,0,3,3,3,3,0,0,0,0,0,0,0,3,3,0,0,0,0,0,0,0,0,0,0,0,3,0,0
0,0,3,0,0,0,0,0,0,0,0,3,3,3,3,0,0,0,0,3,3,3,3,3,3,0,0,0,0,0,0,0,0,0,0,0,3,0,0
0,0,3,0,196,3,194,0,197,0,0,88,3,3,3,0,0,24,3,3,0,0,0,0,198,0,0,0,0,0,0,3,194,199,0,0,3,0,0
0,0,3,0,0,0,0,0,0,0,0,3,3,3,3,0,0,24,3,3,0,0,0,200,0,0,0,201,0,0,0,0,0,0,0,0,3,0,0
0,0,3,0,0,0,0,0,0,0,0,0,3,3,3,3,0,0,0,3,3,3,3,3,3,0,0,0,0,0,0,0,0,0,0,0,3,0,0
0,0,3,0,0,0,0,0,0,0,0,0,0,0,0,0,0,0,0,0,0,0,0,0,0,0,0,0,0,0,0,0,0,0,0,0,3,0,0
0,0,3,3,3,3,3,3,3,3,3,3,3,3,3,3,0,3,0,0,0,3,0,3,3,3,3,3,3,3,3,3,3,3,3,3,3,0,0
0,0,0,0,0,0,0,0,0,0,0,0,0,0,0,3,0,3,3,3,3,3,0,3,0,0,0,0,0,0,0,0,0,0,0,0,0,0,0
0,0,0,0,0,0,0,0,0,0,0,0,0,0,0,3,0,3,3,3,3,3,0,3,0,0,0,0,0,0,0,0,0,0,0,0,0,0,0
0,0,0,0,0,0,0,0,0,0,0,0,0,0,0,3,0,3,3,3,3,3,0,3,0,0,0,0,0,0,0,0,0,0,0,0,0,0,0
0,0,0,0,0,0,0,0,0,0,0,0,0,0,0,3,0,0,3,88,3,0,0,3,0,0,0,0,0,0,0,0,0,0,0,0,0,0,0
0,0,0,0,0,0,0,0,0,0,0,0,0,0,0,3,0,0,0,0,0,0,0,3,0,0,0,0,0,0,0,0,0,0,0,0,0,0,0
0,0,0,0,0,0,0,0,0,0,0,0,0,0,0,3,0,0,0,202,0,0,0,3,0,0,0,0,0,0,0,0,0,0,0,0,0,0,0
0,0,0,0,0,0,0,0,0,0,0,0,0,0,0,3,0,0,0,0,0,0,0,3,0,0,0,0,0,0,0,0,0,0,0,0,0,0,0
0,0,0,0,0,0,0,0,0,0,0,0,0,0,0,3,0,0,0,0,0,0,0,3,0,0,0,0,0,0,0,0,0,0,0,0,0,0,0
0,0,0,0,0,0,0,0,0,0,0,0,0,0,0,3,0,0,3,194,203,0,0,3,0,0,0,0,0,0,0,0,0,0,0,0,0,0,0
0,0,0,0,0,0,0,0,0,0,0,0,0,0,0,3,0,0,0,0,0,0,0,3,0,0,0,0,0,0,0,0,0,0,0,0,0,0,0
0,0,0,0,0,0,0,0,0,0,0,0,0,0,0,3,0,0,0,0,0,0,0,3,0,0,0,0,0,0,0,0,0,0,0,0,0,0,0
0,0,0,0,0,0,0,0,0,0,0,0,0,0,0,3,0,0,0,0,0,0,0,3,0,0,0,0,0,0,0,0,0,0,0,0,0,0,0
0,0,0,0,0,0,0,0,0,0,0,0,0,0,0,3,3,3,3,3,3,3,3,3,0,0,0,0,0,0,0,0,0,0,0,0,0,0,0
0,0,0,0,0,0,0,0,0,0,0,0,0,0,0,0,0,0,0,0,0,0,0,0,0,0,0,0,0,0,0,0,0,0,0,0,0,0,0
0,0,0,0,0,0,0,0,0,0,0,0,0,0,0,0,0,0,0,0,0,0,0,0,0,0,0,0,0,0,0,0,0,0,0,0,0,0,0
0,0,0,0,0,0,0,0,0,0,0,0,0,0,0,0,0,0,0,0,0,0,0,0,0,0,0,0,0,0,0,0,0,0,0,0,0,0,0
0,0,0,0,0,0,0,0,0,0,0,0,0,0,0,0,0,0,0,0,0,0,0,0,0,0,0,0,0,0,0,0,0,0,0,0,0,0,0
0,0,0,0,0,0,0,0,0,0,0,0,0,0,0,0,0,0,0,0,0,0,0,0,0,0,0,0,0,0,0,0,0,0,0,0,0,0,0
:endlayer
layer: 20
0,0,0,0,0,0,0,0,0,0,0,0,0,0,0,0,0,0,0,0,0,0,0,0,0,0,0,0,0,0,0,0,0,0,0,0,0,0,0
0,0,0,0,0,0,0,0,0,0,0,0,0,0,0,0,0,0,0,0,0,0,0,0,0,0,0,0,0,0,0,0,0,0,0,0,0,0,0
0,0,0,0,0,0,0,0,0,0,0,0,0,0,0,3,0,3,204,3,0,3,0,3,0,0,0,0,0,0,0,0,0,0,0,0,0,0,0
0,0,0,0,0,0,0,0,0,0,0,0,0,0,0,0,0,0,0,0,0,0,0,0,0,0,0,0,0,0,0,0,0,0,0,0,0,0,0
0,0,0,0,0,0,0,0,0,0,0,0,0,0,0,3,0,0,0,0,0,0,0,3,0,0,0,0,0,0,0,0,0,0,0,0,0,0,0
0,0,0,0,0,0,0,0,0,0,0,0,0,0,0,0,0,0,0,0,0,0,0,0,0,0,0,0,0,0,0,0,0,0,0,0,0,0,0
0,0,0,0,0,0,0,0,0,0,0,0,0,0,0,3,0,0,3,194,0,0,0,3,0,0,0,0,0,0,0,0,0,0,0,0,0,0,0
0,0,0,0,0,0,0,0,0,0,0,0,0,0,0,0,0,0,0,0,0,0,0,0,0,0,0,0,0,0,0,0,0,0,0,0,0,0,0
0,0,0,0,0,0,0,0,0,0,0,0,0,0,0,3,0,0,0,0,0,0,0,3,0,0,0,0,0,0,0,0,0,0,0,0,0,0,0
0,0,0,0,0,0,0,0,0,0,0,0,0,0,0,0,0,0,0,0,0,0,0,0,0,0,0,0,0,0,0,0,0,0,0,0,0,0,0
0,0,0,0,0,0,0,0,0,0,0,0,0,0,0,3,0,0,0,0,0,0,0,3,0,0,0,0,0,0,0,0,0,0,0,0,0,0,0
0,0,0,0,0,0,0,0,0,0,0,0,0,0,0,0,0,0,3,0,3,0,0,0,0,0,0,0,0,0,0,0,0,0,0,0,0,0,0
0,0,0,0,0,0,0,0,0,0,0,0,0,0,0,3,0,3,3,3,3,3,0,3,0,0,0,0,0,0,0,0,0,0,0,0,0,0,0
0,0,0,0,0,0,0,0,0,0,0,0,0,0,0,0,0,3,3,3,3,3,0,0,0,0,0,0,0,0,0,0,0,0,0,0,0,0,0
0,0,0,0,0,0,0,0,0,0,0,0,0,0,0,3,0,3,3,3,3,3,0,3,0,0,0,0,0,0,0,0,0,0,0,0,0,0,0
0,0,3,0,3,0,3,0,3,0,3,0,3,0,3,3,0,3,0,0,0,3,0,3,3,0,3,0,3,0,3,0,3,0,3,0,3,0,0
0,0,0,0,0,0,0,0,0,0,0,0,0,0,0,0,0,0,0,0,0,0,0,0,0,0,0,0,0,0,0,0,0,0,0,0,0,0,0
0,0,3,0,0,0,0,0,0,0,0,0,3,3,3,3,0,0,0,0,0,0,0,3,3,0,0,0,0,0,0,0,0,0,0,0,3,0,0
0,0,0,0,0,0,0,0,0,0,0,3,3,3,3,0,0,0,0,3,3,3,3,3,3,48,0,0,0,0,0,0,0,0,0,0,205,0,0
0,0,3,0,0,3,194,0,0,0,0,0,3,3,3,0,0,0,24,3,0,0,0,0,0,0,0,0,0,0,0,3,194,0,0,0,3,0,0
0,0,206,0,0,0,0,0,0,0,0,3,3,3,3,0,0,0,24,3,0,0,0,0,0,0,0,0,0,0,0,0,0,0,0,0,0,0,0
0,0,3,0,0,0,0,0,0,0,0,0,3,3,3,3,0,0,0,3,3,3,3,3,3,48,0,0,0,0,0,0,0,0,0,0,3,0,0
0,0,0,0,0,0,0,0,0,0,0,0,0,0,0,0,0,0,0,0,0,0,0,0,0,0,0,0,0,0,0,0,0,0,0,0,0,0,0
0,0,3,0,3,0,3,0,3,0,3,0,3,0,3,3,0,3,0,0,0,3,0,3,3,0,3,0,3,0,3,0,3,0,3,0,3,0,0
0,0,0,0,0,0,0,0,0,0,0,0,0,0,0,3,0,3,3,3,3,3,0,3,0,0,0,0,0,0,0,0,0,0,0,0,0,0,0
0,0,0,0,0,0,0,0,0,0,0,0,0,0,0,0,0,3,3,3,3,3,0,0,0,0,0,0,0,0,0,0,0,0,0,0,0,0,0
0,0,0,0,0,0,0,0,0,0,0,0,0,0,0,3,0,3,3,3,3,3,0,3,0,0,0,0,0,0,0,0,0,0,0,0,0,0,0
0,0,0,0,0,0,0,0,0,0,0,0,0,0,0,0,0,0,3,0,3,0,0,0,0,0,0,0,0,0,0,0,0,0,0,0,0,0,0
0,0,0,0,0,0,0,0,0,0,0,0,0,0,0,3,0,0,0,0,0,0,0,3,0,0,0,0,0,0,0,0,0,0,0,0,0,0,0
0,0,0,0,0,0,0,0,0,0,0,0,0,0,0,0,0,0,0,0,0,0,0,0,0,0,0,0,0,0,0,0,0,0,0,0,0,0,0
0,0,0,0,0,0,0,0,0,0,0,0,0,0,0,3,0,0,0,0,0,0,0,3,0,0,0,0,0,0,0,0,0,0,0,0,0,0,0
0,0,0,0,0,0,0,0,0,0,0,0,0,0,0,0,0,0,0,0,0,0,0,0,0,0,0,0,0,0,0,0,0,0,0,0,0,0,0
0,0,0,0,0,0,0,0,0,0,0,0,0,0,0,3,0,0,3,194,0,0,0,3,0,0,0,0,0,0,0,0,0,0,0,0,0,0,0
0,0,0,0,0,0,0,0,0,0,0,0,0,0,0,0,0,0,0,0,0,0,0,0,0,0,0,0,0,0,0,0,0,0,0,0,0,0,0
0,0,0,0,0,0,0,0,0,0,0,0,0,0,0,3,0,0,0,0,0,0,0,3,0,0,0,0,0,0,0,0,0,0,0,0,0,0,0
0,0,0,0,0,0,0,0,0,0,0,0,0,0,0,0,0,0,0,0,0,0,0,0,0,0,0,0,0,0,0,0,0,0,0,0,0,0,0
0,0,0,0,0,0,0,0,0,0,0,0,0,0,0,3,0,3,0,3,207,3,0,3,0,0,0,0,0,0,0,0,0,0,0,0,0,0,0
0,0,0,0,0,0,0,0,0,0,0,0,0,0,0,0,0,0,0,0,0,0,0,0,0,0,0,0,0,0,0,0,0,0,0,0,0,0,0
0,0,0,0,0,0,0,0,0,0,0,0,0,0,0,0,0,0,0,0,0,0,0,0,0,0,0,0,0,0,0,0,0,0,0,0,0,0,0
0,0,0,0,0,0,0,0,0,0,0,0,0,0,0,0,0,0,0,0,0,0,0,0,0,0,0,0,0,0,0,0,0,0,0,0,0,0,0
0,0,0,0,0,0,0,0,0,0,0,0,0,0,0,0,0,0,0,0,0,0,0,0,0,0,0,0,0,0,0,0,0,0,0,0,0,0,0
0,0,0,0,0,0,0,0,0,0,0,0,0,0,0,0,0,0,0,0,0,0,0,0,0,0,0,0,0,0,0,0,0,0,0,0,0,0,0
:endlayer
layer: 21
0,0,0,0,0,0,0,0,0,0,0,0,0,0,0,0,0,0,0,0,0,0,0,0,0,0,0,0,0,0,0,0,0,0,0,0,0,0,0
0,0,0,0,0,0,0,0,0,0,0,0,0,0,0,47,0,0,0,0,0,0,0,47,0,0,0,0,0,0,0,0,0,0,0,0,0,0,0
0,0,0,0,0,0,0,0,0,0,0,0,0,0,42,3,0,3,0,3,0,3,0,3,48,0,0,0,0,0,0,0,0,0,0,0,0,0,0
0,0,0,0,0,0,0,0,0,0,0,0,0,0,0,0,0,0,0,0,0,0,0,0,0,0,0,0,0,0,0,0,0,0,0,0,0,0,0
0,0,0,0,0,0,0,0,0,0,0,0,0,0,0,3,0,0,0,0,0,0,0,3,0,0,0,0,0,0,0,0,0,0,0,0,0,0,0
0,0,0,0,0,0,0,0,0,0,0,0,0,0,0,0,0,0,0,0,0,0,0,0,0,0,0,0,0,0,0,0,0,0,0,0,0,0,0
0,0,0,0,0,0,0,0,0,0,0,0,0,0,0,3,0,0,3,194,0,0,0,3,0,0,0,0,0,0,0,0,0,0,0,0,0,0,0
0,0,0,0,0,0,0,0,0,0,0,0,0,0,0,0,0,0,0,0,0,0,0,0,0,0,0,0,0,0,0,0,0,0,0,0,0,0,0
0,0,0,0,0,0,0,0,0,0,0,0,0,0,0,3,0,0,0,0,0,0,0,3,0,0,0,0,0,0,0,0,0,0,0,0,0,0,0
0,0,0,0,0,0,0,0,0,0,0,0,0,0,0,0,0,0,0,0,0,0,0,0,0,0,0,0,0,0,0,0,0,0,0,0,0,0,0
0,0,0,0,0,0,0,0,0,0,0,0,0,0,42,3,0,0,0,0,0,0,0,3,48,0,0,0,0,0,0,0,0,0,0,0,0,0,0
0,0,0,0,0,0,0,0,0,0,0,0,0,0,0,49,0,0,3,3,3,0,0,49,0,0,0,0,0,0,0,0,0,0,0,0,0,0,0
0,0,0,0,0,0,0,0,0,0,0,0,0,0,0,3,0,3,3,3,3,3,0,3,0,0,0,0,0,0,0,0,0,0,0,0,0,0,0
0,0,0,0,0,0,0,0,0,0,0,0,0,0,0,0,0,3,3,3,3,3,0,0,0,0,0,0,0,0,0,0,0,0,0,0,0,0,0
0,0,47,0,0,0,0,0,0,0,47,0,0,0,0,3,0,3,3,3,3,3,0,3,0,0,0,0,47,0,0,0,0,0,0,0,47,0,0
0,42,3,0,3,0,3,0,3,0,3,48,3,0,3,3,0,3,0,49,0,3,0,3,3,0,3,42,3,0,3,0,3,0,3,0,3,48,0
0,0,0,0,0,0,0,0,0,0,0,0,0,0,0,0,0,0,0,0,0,0,0,0,0,0,0,0,0,0,0,0,0,0,0,0,0,0,0
0,0,3,0,0,0,0,0,0,0,0,0,3,3,3,3,0,0,0,0,0,0,42,3,3,0,0,0,0,0,0,0,0,0,0,0,3,0,0
0,0,0,0,0,47,0,0,0,0,0,3,3,3,58,0,0,0,0,3,3,3,3,3,3,0,0,0,0,0,0,0,0,0,0,0,0,0,0
0,0,3,0,0,3,194,0,0,0,0,3,3,3,58,48,0,0,0,24,0,0,0,0,3,0,0,0,0,0,42,3,194,0,0,0,3,0,0
0,0,0,0,0,49,0,0,0,0,0,3,3,3,58,0,0,0,0,24,0,0,0,0,3,0,0,0,0,0,0,0,0,0,0,0,0,0,0
0,0,3,0,0,0,0,0,0,0,0,0,3,3,58,3,0,0,0,3,3,3,3,3,3,0,0,0,0,0,0,0,0,0,0,0,3,0,0
0,0,0,0,0,0,0,0,0,0,0,0,0,0,0,0,0,0,0,0,0,0,0,0,0,0,0,0,0,0,0,0,0,0,0,0,0,0,0
0,42,3,0,3,0,3,0,3,0,3,48,3,0,3,3,0,3,0,47,0,3,0,3,3,0,3,0,3,0,3,0,3,0,3,0,3,48,0
0,0,49,0,0,0,0,0,0,0,49,0,0,0,0,3,0,3,3,3,3,3,0,3,0,0,0,0,49,0,0,0,0,0,0,0,49,0,0
0,0,0,0,0,0,0,0,0,0,0,0,0,0,0,0,0,3,3,3,3,3,0,0,0,0,0,0,0,0,0,0,0,0,0,0,0,0,0
0,0,0,0,0,0,0,0,0,0,0,0,0,0,0,3,0,3,3,3,3,3,0,3,0,0,0,0,0,0,0,0,0,0,0,0,0,0,0
0,0,0,0,0,0,0,0,0,0,0,0,0,0,0,47,0,0,3,3,3,0,0,0,0,0,0,0,0,0,0,0,0,0,0,0,0,0,0
0,0,0,0,0,0,0,0,0,0,0,0,0,0,42,3,0,0,0,0,0,0,0,3,48,0,0,0,0,0,0,0,0,0,0,0,0,0,0
0,0,0,0,0,0,0,0,0,0,0,0,0,0,0,0,0,0,0,0,0,0,0,0,0,0,0,0,0,0,0,0,0,0,0,0,0,0,0
0,0,0,0,0,0,0,0,0,0,0,0,0,0,0,3,0,0,0,0,0,0,0,3,0,0,0,0,0,0,0,0,0,0,0,0,0,0,0
0,0,0,0,0,0,0,0,0,0,0,0,0,0,0,0,0,0,47,0,0,0,0,0,0,0,0,0,0,0,0,0,0,0,0,0,0,0,0
0,0,0,0,0,0,0,0,0,0,0,0,0,0,0,3,0,0,3,194,0,0,0,3,0,0,0,0,0,0,0,0,0,0,0,0,0,0,0
0,0,0,0,0,0,0,0,0,0,0,0,0,0,0,0,0,0,0,0,0,0,0,0,0,0,0,0,0,0,0,0,0,0,0,0,0,0,0
0,0,0,0,0,0,0,0,0,0,0,0,0,0,0,3,0,0,0,0,0,0,0,3,0,0,0,0,0,0,0,0,0,0,0,0,0,0,0
0,0,0,0,0,0,0,0,0,0,0,0,0,0,0,0,0,0,0,0,0,0,0,0,0,0,0,0,0,0,0,0,0,0,0,0,0,0,0
0,0,0,0,0,0,0,0,0,0,0,0,0,0,42,3,0,3,0,3,0,3,0,3,48,0,0,0,0,0,0,0,0,0,0,0,0,0,0
0,0,0,0,0,0,0,0,0,0,0,0,0,0,0,49,0,0,0,0,0,0,0,49,0,0,0,0,0,0,0,0,0,0,0,0,0,0,0
0,0,0,0,0,0,0,0,0,0,0,0,0,0,0,0,0,0,0,0,0,0,0,0,0,0,0,0,0,0,0,0,0,0,0,0,0,0,0
0,0,0,0,0,0,0,0,0,0,0,0,0,0,0,0,0,0,0,0,0,0,0,0,0,0,0,0,0,0,0,0,0,0,0,0,0,0,0
0,0,0,0,0,0,0,0,0,0,0,0,0,0,0,0,0,0,0,0,0,0,0,0,0,0,0,0,0,0,0,0,0,0,0,0,0,0,0
0,0,0,0,0,0,0,0,0,0,0,0,0,0,0,0,0,0,0,0,0,0,0,0,0,0,0,0,0,0,0,0,0,0,0,0,0,0,0
:endlayer
layer: 22
0,0,0,0,0,0,0,0,0,0,0,0,0,0,0,0,0,0,0,0,0,0,0,0,0,0,0,0,0,0,0,0,0,0,0,0,0,0,0
0,0,0,0,0,0,0,0,0,0,0,0,0,0,208,209,209,209,209,209,209,209,209,209,208,0,0,0,0,0,0,0,0,0,0,0,0,0,0
0,0,0,0,0,0,0,0,0,0,0,0,0,0,178,3,3,3,3,3,3,3,3,3,179,0,0,0,0,0,0,0,0,0,0,0,0,0,0
0,0,0,0,0,0,0,0,0,0,0,0,0,0,178,3,0,0,0,49,0,0,0,3,179,0,0,0,0,0,0,0,0,0,0,0,0,0,0
0,0,0,0,0,0,0,0,0,0,0,0,0,0,178,3,0,0,0,0,0,0,0,3,179,0,0,0,0,0,0,0,0,0,0,0,0,0,0
0,0,0,0,0,0,0,0,0,0,0,0,0,0,178,3,0,0,0,0,0,0,0,3,179,0,0,0,0,0,0,0,0,0,0,0,0,0,0
0,0,0,0,0,0,0,0,0,0,0,0,0,0,178,3,48,0,3,194,0,0,42,3,179,0,0,0,0,0,0,0,0,0,0,0,0,0,0
0,0,0,0,0,0,0,0,0,0,0,0,0,0,178,3,0,0,0,0,0,0,0,3,179,0,0,0,0,0,0,0,0,0,0,0,0,0,0
0,0,0,0,0,0,0,0,0,0,0,0,0,0,178,3,0,0,0,0,0,0,0,3,179,0,0,0,0,0,0,0,0,0,0,0,0,0,0
0,0,0,0,0,0,0,0,0,0,0,0,0,0,178,3,0,0,0,47,0,0,0,3,179,0,0,0,0,0,0,0,0,0,0,0,0,0,0
0,0,0,0,0,0,0,0,0,0,0,0,0,0,3,3,3,3,3,3,3,3,3,3,3,0,0,0,0,0,0,0,0,0,0,0,0,0,0
0,0,0,0,0,0,0,0,0,0,0,0,0,0,3,3,3,3,3,3,3,3,3,3,3,0,0,0,0,0,0,0,0,0,0,0,0,0,0
0,0,0,0,0,0,0,0,0,0,0,0,0,0,3,3,3,3,3,3,3,3,3,3,3,0,0,0,0,0,0,0,0,0,0,0,0,0,0
0,0,0,0,0,0,0,0,0,0,0,0,0,3,3,3,3,3,3,3,3,3,3,3,3,3,0,0,0,0,0,0,0,0,0,0,0,0,0
0,208,209,209,209,209,209,209,209,209,3,3,3,3,3,3,3,3,3,3,3,3,3,3,3,3,3,3,3,209,209,209,209,209,209,209,209,208,0
0,178,3,3,3,3,3,3,3,3,3,3,3,3,3,3,3,3,3,3,3,3,3,3,3,3,3,3,3,3,3,3,3,3,3,3,3,179,0
0,178,3,0,0,0,49,0,0,0,3,3,3,3,3,3,3,3,3,3,3,3,3,3,3,3,3,3,3,0,0,0,49,0,0,0,3,179,0
0,178,3,0,0,0,0,0,0,0,3,3,3,3,3,3,3,3,3,3,3,3,3,3,3,3,3,3,3,0,0,0,0,0,0,0,3,179,0
0,178,3,0,0,0,0,0,0,0,3,3,3,3,58,3,3,3,3,3,3,3,3,3,3,3,3,3,3,0,0,0,0,0,0,0,3,179,0
0,178,3,48,0,3,194,0,0,42,3,3,3,3,58,3,3,0,0,0,24,3,3,3,3,3,3,3,3,48,0,3,194,0,0,42,3,179,0
0,178,3,0,0,0,0,0,0,0,3,3,3,3,58,3,3,0,0,0,24,3,3,3,3,3,3,3,3,0,0,0,0,0,0,0,3,179,0
0,178,3,0,0,0,0,0,0,0,3,3,3,3,58,3,3,3,3,3,3,3,3,3,3,3,3,3,3,0,0,0,0,0,0,0,3,179,0
0,178,3,0,0,0,47,0,0,0,3,3,3,3,3,3,3,3,3,3,3,3,3,3,3,3,3,3,3,0,0,0,47,0,0,0,3,179,0
0,178,3,3,3,3,3,3,3,3,3,3,3,3,3,3,3,3,3,3,3,3,3,3,3,3,3,3,3,3,3,3,3,3,3,3,3,179,0
0,208,181,181,181,181,181,181,181,181,3,3,3,3,3,3,3,3,3,3,3,3,3,3,3,3,3,3,3,181,181,181,181,181,181,181,181,208,0
0,0,0,0,0,0,0,0,0,0,0,0,0,3,3,3,3,3,3,3,3,3,3,3,3,3,0,0,0,0,0,0,0,0,0,0,0,0,0
0,0,0,0,0,0,0,0,0,0,0,0,0,0,3,3,3,3,3,3,3,3,3,3,3,0,0,0,0,0,0,0,0,0,0,0,0,0,0
0,0,0,0,0,0,0,0,0,0,0,0,0,0,3,3,3,3,3,3,3,3,3,3,3,0,0,0,0,0,0,0,0,0,0,0,0,0,0
0,0,0,0,0,0,0,0,0,0,0,0,0,0,3,3,3,3,3,3,3,3,3,3,3,0,0,0,0,0,0,0,0,0,0,0,0,0,0
0,0,0,0,0,0,0,0,0,0,0,0,0,0,178,3,0,0,0,49,0,0,0,3,179,0,0,0,0,0,0,0,0,0,0,0,0,0,0
0,0,0,0,0,0,0,0,0,0,0,0,0,0,178,3,0,0,0,0,0,0,0,3,179,0,0,0,0,0,0,0,0,0,0,0,0,0,0
0,0,0,0,0,0,0,0,0,0,0,0,0,0,178,3,0,0,0,0,0,0,0,3,179,0,0,0,0,0,0,0,0,0,0,0,0,0,0
0,0,0,0,0,0,0,0,0,0,0,0,0,0,178,3,48,0,3,194,0,0,42,3,179,0,0,0,0,0,0,0,0,0,0,0,0,0,0
0,0,0,0,0,0,0,0,0,0,0,0,0,0,178,3,0,0,0,0,0,0,0,3,179,0,0,0,0,0,0,0,0,0,0,0,0,0,0
0,0,0,0,0,0,0,0,0,0,0,0,0,0,178,3,0,0,0,0,0,0,0,3,179,0,0,0,0,0,0,0,0,0,0,0,0,0,0
0,0,0,0,0,0,0,0,0,0,0,0,0,0,178,3,0,0,0,47,0,0,0,3,179,0,0,0,0,0,0,0,0,0,0,0,0,0,0
0,0,0,0,0,0,0,0,0,0,0,0,0,0,178,3,3,3,3,3,3,3,3,3,179,0,0,0,0,0,0,0,0,0,0,0,0,0,0
0,0,0,0,0,0,0,0,0,0,0,0,0,0,208,181,181,181,181,181,181,181,181,181,208,0,0,0,0,0,0,0,0,0,0,0,0,0,0
0,0,0,0,0,0,0,0,0,0,0,0,0,0,0,0,0,0,0,0,0,0,0,0,0,0,0,0,0,0,0,0,0,0,0,0,0,0,0
0,0,0,0,0,0,0,0,0,0,0,0,0,0,0,0,0,0,0,0,0,0,0,0,0,0,0,0,0,0,0,0,0,0,0,0,0,0,0
0,0,0,0,0,0,0,0,0,0,0,0,0,0,0,0,0,0,0,0,0,0,0,0,0,0,0,0,0,0,0,0,0,0,0,0,0,0,0
0,0,0,0,0,0,0,0,0,0,0,0,0,0,0,0,0,0,0,0,0,0,0,0,0,0,0,0,0,0,0,0,0,0,0,0,0,0,0
:endlayer
layer: 23
0,0,0,0,0,0,0,0,0,0,0,0,0,0,0,0,0,0,0,0,0,0,0,0,0,0,0,0,0,0,0,0,0,0,0,0,0,0,0
0,0,0,0,0,0,0,0,0,0,0,0,0,0,0,0,0,0,0,0,0,0,0,0,0,0,0,0,0,0,0,0,0,0,0,0,0,0,0
0,0,0,0,0,0,0,0,0,0,0,0,0,0,0,208,209,209,209,209,209,209,209,208,0,0,0,0,0,0,0,0,0,0,0,0,0,0,0
0,0,0,0,0,0,0,0,0,0,0,0,0,0,0,178,0,0,0,0,0,0,0,179,0,0,0,0,0,0,0,0,0,0,0,0,0,0,0
0,0,0,0,0,0,0,0,0,0,0,0,0,0,0,178,0,0,0,0,0,0,0,179,0,0,0,0,0,0,0,0,0,0,0,0,0,0,0
0,0,0,0,0,0,0,0,0,0,0,0,0,0,0,178,0,0,0,0,0,0,0,179,0,0,0,0,0,0,0,0,0,0,0,0,0,0,0
0,0,0,0,0,0,0,0,0,0,0,0,0,0,0,178,0,0,3,194,0,0,0,179,0,0,0,0,0,0,0,0,0,0,0,0,0,0,0
0,0,0,0,0,0,0,0,0,0,0,0,0,0,0,178,0,0,0,0,0,0,0,179,0,0,0,0,0,0,0,0,0,0,0,0,0,0,0
0,0,0,0,0,0,0,0,0,0,0,0,0,0,0,178,0,0,0,0,0,0,0,179,0,0,0,0,0,0,0,0,0,0,0,0,0,0,0
0,0,0,0,0,0,0,0,0,0,0,0,0,0,0,178,0,0,0,0,0,0,0,179,0,0,0,0,0,0,0,0,0,0,0,0,0,0,0
0,0,0,0,0,0,0,0,0,0,0,0,0,0,3,3,3,3,3,3,3,3,3,3,3,0,0,0,0,0,0,0,0,0,0,0,0,0,0
0,0,0,0,0,0,0,0,0,0,0,0,0,0,3,148,148,148,148,148,148,148,148,148,3,0,0,0,0,0,0,0,0,0,0,0,0,0,0
0,0,0,0,0,0,0,0,0,0,0,0,3,3,3,148,148,3,3,3,3,3,148,148,3,3,3,0,0,0,0,0,0,0,0,0,0,0,0
0,0,0,0,0,0,0,0,0,0,0,0,3,148,148,148,148,3,3,3,3,3,148,148,148,148,3,0,0,0,0,0,0,0,0,0,0,0,0
0,0,0,0,0,0,0,0,0,0,3,3,3,148,148,148,148,3,3,3,3,3,148,148,148,148,3,3,3,0,0,0,0,0,0,0,0,0,0
0,0,208,209,209,209,209,209,209,209,3,148,148,148,148,148,3,3,3,3,26,0,3,148,148,148,148,148,3,209,209,209,209,209,209,209,208,0,0
0,0,178,0,0,0,0,0,0,0,3,148,148,148,148,3,3,3,3,3,26,0,0,3,148,148,148,148,3,0,0,0,0,0,0,0,179,0,0
0,0,178,0,0,0,0,0,0,0,3,148,3,3,3,0,0,0,0,0,0,0,0,0,3,3,3,148,3,0,0,0,0,0,0,0,179,0,0
0,0,178,0,0,0,0,0,0,0,3,148,3,3,58,0,0,0,0,0,0,0,0,0,3,3,3,148,3,0,0,0,0,0,0,0,179,0,0
0,0,178,0,0,3,194,0,0,0,3,148,3,0,0,0,0,0,0,0,0,210,0,0,0,0,3,148,3,0,0,3,194,0,0,0,179,0,0
0,0,178,0,0,0,0,0,0,0,3,148,3,3,58,0,0,0,0,0,0,211,0,0,3,3,3,148,3,0,0,0,0,0,0,0,179,0,0
0,0,178,0,0,0,0,0,0,0,3,148,3,3,58,0,0,0,0,0,0,0,0,0,3,3,3,148,3,0,0,0,0,0,0,0,179,0,0
0,0,178,0,0,0,0,0,0,0,3,148,148,148,148,3,0,0,0,0,0,0,0,3,148,148,148,148,3,0,0,0,0,0,0,0,179,0,0
0,0,208,181,181,181,181,181,181,181,3,148,148,148,148,148,3,0,0,0,0,0,3,148,148,148,148,148,3,181,181,181,181,181,181,181,208,0,0
0,0,0,0,0,0,0,0,0,0,3,3,3,148,148,148,148,3,3,0,3,3,148,148,148,148,3,3,3,0,0,0,0,0,0,0,0,0,0
0,0,0,0,0,0,0,0,0,0,0,0,3,148,148,148,148,3,3,212,3,3,148,148,148,148,3,0,0,0,0,0,0,0,0,0,0,0,0
0,0,0,0,0,0,0,0,0,0,0,0,3,3,3,148,148,3,3,0,3,3,148,148,3,3,3,0,0,0,0,0,0,0,0,0,0,0,0
0,0,0,0,0,0,0,0,0,0,0,0,0,0,3,148,148,148,148,148,148,148,148,148,3,0,0,0,0,0,0,0,0,0,0,0,0,0,0
0,0,0,0,0,0,0,0,0,0,0,0,0,0,3,3,3,3,3,3,3,3,3,3,3,0,0,0,0,0,0,0,0,0,0,0,0,0,0
0,0,0,0,0,0,0,0,0,0,0,0,0,0,0,178,0,0,0,0,0,0,0,179,0,0,0,0,0,0,0,0,0,0,0,0,0,0,0
0,0,0,0,0,0,0,0,0,0,0,0,0,0,0,178,0,0,0,0,0,0,0,179,0,0,0,0,0,0,0,0,0,0,0,0,0,0,0
0,0,0,0,0,0,0,0,0,0,0,0,0,0,0,178,0,0,0,0,0,0,0,179,0,0,0,0,0,0,0,0,0,0,0,0,0,0,0
0,0,0,0,0,0,0,0,0,0,0,0,0,0,0,178,0,0,3,194,0,0,0,179,0,0,0,0,0,0,0,0,0,0,0,0,0,0,0
0,0,0,0,0,0,0,0,0,0,0,0,0,0,0,178,0,0,0,0,0,0,0,179,0,0,0,0,0,0,0,0,0,0,0,0,0,0,0
0,0,0,0,0,0,0,0,0,0,0,0,0,0,0,178,0,0,0,0,0,0,0,179,0,0,0,0,0,0,0,0,0,0,0,0,0,0,0
0,0,0,0,0,0,0,0,0,0,0,0,0,0,0,178,0,0,0,0,0,0,0,179,0,0,0,0,0,0,0,0,0,0,0,0,0,0,0
0,0,0,0,0,0,0,0,0,0,0,0,0,0,0,208,181,181,181,181,181,181,181,208,0,0,0,0,0,0,0,0,0,0,0,0,0,0,0
0,0,0,0,0,0,0,0,0,0,0,0,0,0,0,0,0,0,0,0,0,0,0,0,0,0,0,0,0,0,0,0,0,0,0,0,0,0,0
0,0,0,0,0,0,0,0,0,0,0,0,0,0,0,0,0,0,0,0,0,0,0,0,0,0,0,0,0,0,0,0,0,0,0,0,0,0,0
0,0,0,0,0,0,0,0,0,0,0,0,0,0,0,0,0,0,0,0,0,0,0,0,0,0,0,0,0,0,0,0,0,0,0,0,0,0,0
0,0,0,0,0,0,0,0,0,0,0,0,0,0,0,0,0,0,0,0,0,0,0,0,0,0,0,0,0,0,0,0,0,0,0,0,0,0,0
0,0,0,0,0,0,0,0,0,0,0,0,0,0,0,0,0,0,0,0,0,0,0,0,0,0,0,0,0,0,0,0,0,0,0,0,0,0,0
:endlayer
layer: 24
0,0,0,0,0,0,0,0,0,0,0,0,0,0,0,0,0,0,0,0,0,0,0,0,0,0,0,0,0,0,0,0,0,0,0,0,0,0,0
0,0,0,0,0,0,0,0,0,0,0,0,0,0,0,0,0,0,0,0,0,0,0,0,0,0,0,0,0,0,0,0,0,0,0,0,0,0,0
0,0,0,0,0,0,0,0,0,0,0,0,0,0,0,0,0,0,0,0,0,0,0,0,0,0,0,0,0,0,0,0,0,0,0,0,0,0,0
0,0,0,0,0,0,0,0,0,0,0,0,0,0,0,0,208,209,209,209,209,209,208,0,0,0,0,0,0,0,0,0,0,0,0,0,0,0,0
0,0,0,0,0,0,0,0,0,0,0,0,0,0,0,0,178,0,0,0,0,0,179,0,0,0,0,0,0,0,0,0,0,0,0,0,0,0,0
0,0,0,0,0,0,0,0,0,0,0,0,0,0,0,0,178,0,0,0,0,0,179,0,0,0,0,0,0,0,0,0,0,0,0,0,0,0,0
0,0,0,0,0,0,0,0,0,0,0,0,0,0,0,0,178,0,3,194,0,0,179,0,0,0,0,0,0,0,0,0,0,0,0,0,0,0,0
0,0,0,0,0,0,0,0,0,0,0,0,0,0,0,0,178,0,0,0,0,0,179,0,0,0,0,0,0,0,0,0,0,0,0,0,0,0,0
0,0,0,0,0,0,0,0,0,0,0,0,0,0,0,0,178,0,0,0,0,0,179,0,0,0,0,0,0,0,0,0,0,0,0,0,0,0,0
0,0,0,0,0,0,0,0,0,0,0,0,0,0,0,0,208,181,181,181,181,181,208,0,0,0,0,0,0,0,0,0,0,0,0,0,0,0,0
0,0,0,0,0,0,0,0,0,0,0,0,0,0,89,0,0,0,0,0,0,0,0,0,89,0,0,0,0,0,0,0,0,0,0,0,0,0,0
0,0,0,0,0,0,0,0,0,0,0,0,0,0,0,0,0,0,0,0,0,0,0,0,0,0,0,0,0,0,0,0,0,0,0,0,0,0,0
0,0,0,0,0,0,0,0,0,0,0,0,0,0,0,0,0,3,3,3,3,3,0,0,0,0,0,0,0,0,0,0,0,0,0,0,0,0,0
0,0,0,0,0,0,0,0,0,0,0,0,0,213,0,0,0,3,3,3,3,3,0,0,0,214,0,0,0,0,0,0,0,0,0,0,0,0,0
0,0,0,0,0,0,0,0,0,0,89,0,0,0,0,0,0,3,3,3,3,3,0,0,0,0,0,0,89,0,0,0,0,0,0,0,0,0,0
0,0,0,0,0,0,0,0,0,0,0,0,0,0,0,0,3,3,3,26,0,0,3,0,0,0,0,0,0,0,0,0,0,0,0,0,0,0,0
0,0,0,208,209,209,209,209,209,208,0,0,0,0,0,3,3,3,3,26,0,0,0,3,0,0,0,0,0,208,209,209,209,209,209,208,0,0,0
0,0,0,178,0,0,0,0,0,215,0,0,3,3,3,0,0,0,0,0,0,0,0,0,3,3,3,0,0,178,0,0,0,0,0,179,0,0,0
0,0,0,178,0,0,0,0,0,215,0,0,3,3,58,0,0,0,0,0,0,0,0,0,3,3,3,0,0,178,0,0,0,0,0,179,0,0,0
0,0,0,178,0,3,194,0,0,215,0,0,216,0,0,0,0,0,0,0,0,0,0,0,0,0,216,0,0,178,0,3,194,0,0,179,0,0,0
0,0,0,178,0,0,0,0,0,215,0,0,3,3,58,0,0,0,0,0,0,0,0,0,3,3,3,0,0,178,0,0,0,0,0,179,0,0,0
0,0,0,178,0,0,0,0,0,179,0,0,3,3,58,0,0,0,0,0,0,0,0,0,3,3,3,0,0,178,0,0,0,0,0,179,0,0,0
0,0,0,208,181,181,181,181,181,208,0,0,0,0,0,3,0,0,0,0,0,0,0,3,0,0,0,0,0,208,181,181,181,181,181,208,0,0,0
0,0,0,0,0,0,0,0,0,0,0,0,0,0,0,0,3,0,0,0,0,0,3,0,0,0,0,0,0,0,0,0,0,0,0,0,0,0,0
0,0,0,0,0,0,0,0,0,0,89,0,0,0,0,0,0,3,3,0,3,3,0,0,0,0,0,0,89,0,0,0,0,0,0,0,0,0,0
0,0,0,0,0,0,0,0,0,0,0,0,0,217,0,0,0,3,3,218,3,3,0,0,0,219,0,0,0,0,0,0,0,0,0,0,0,0,0
0,0,0,0,0,0,0,0,0,0,0,0,0,0,0,0,0,3,3,0,3,3,0,0,0,0,0,0,0,0,0,0,0,0,0,0,0,0,0
0,0,0,0,0,0,0,0,0,0,0,0,0,0,0,0,0,0,0,0,0,0,0,0,0,0,0,0,0,0,0,0,0,0,0,0,0,0,0
0,0,0,0,0,0,0,0,0,0,0,0,0,0,89,0,0,0,0,0,0,0,0,0,89,0,0,0,0,0,0,0,0,0,0,0,0,0,0
0,0,0,0,0,0,0,0,0,0,0,0,0,0,0,0,208,209,209,209,209,209,208,0,0,0,0,0,0,0,0,0,0,0,0,0,0,0,0
0,0,0,0,0,0,0,0,0,0,0,0,0,0,0,0,178,0,0,0,0,0,179,0,0,0,0,0,0,0,0,0,0,0,0,0,0,0,0
0,0,0,0,0,0,0,0,0,0,0,0,0,0,0,0,178,0,0,0,0,0,179,0,0,0,0,0,0,0,0,0,0,0,0,0,0,0,0
0,0,0,0,0,0,0,0,0,0,0,0,0,0,0,0,178,0,3,194,0,0,179,0,0,0,0,0,0,0,0,0,0,0,0,0,0,0,0
0,0,0,0,0,0,0,0,0,0,0,0,0,0,0,0,178,0,0,0,0,0,179,0,0,0,0,0,0,0,0,0,0,0,0,0,0,0,0
0,0,0,0,0,0,0,0,0,0,0,0,0,0,0,0,178,0,0,0,0,0,179,0,0,0,0,0,0,0,0,0,0,0,0,0,0,0,0
0,0,0,0,0,0,0,0,0,0,0,0,0,0,0,0,208,181,181,181,181,181,208,0,0,0,0,0,0,0,0,0,0,0,0,0,0,0,0
0,0,0,0,0,0,0,0,0,0,0,0,0,0,0,0,0,0,0,0,0,0,0,0,0,0,0,0,0,0,0,0,0,0,0,0,0,0,0
0,0,0,0,0,0,0,0,0,0,0,0,0,0,0,0,0,0,0,0,0,0,0,0,0,0,0,0,0,0,0,0,0,0,0,0,0,0,0
0,0,0,0,0,0,0,0,0,0,0,0,0,0,0,0,0,0,0,0,0,0,0,0,0,0,0,0,0,0,0,0,0,0,0,0,0,0,0
0,0,0,0,0,0,0,0,0,0,0,0,0,0,0,0,0,0,0,0,0,0,0,0,0,0,0,0,0,0,0,0,0,0,0,0,0,0,0
0,0,0,0,0,0,0,0,0,0,0,0,0,0,0,0,0,0,0,0,0,0,0,0,0,0,0,0,0,0,0,0,0,0,0,0,0,0,0
0,0,0,0,0,0,0,0,0,0,0,0,0,0,0,0,0,0,0,0,0,0,0,0,0,0,0,0,0,0,0,0,0,0,0,0,0,0,0
:endlayer
layer: 25
0,0,0,0,0,0,0,0,0,0,0,0,0,0,0,0,0,0,0,0,0,0,0,0,0,0,0,0,0,0,0,0,0,0,0,0,0,0,0
0,0,0,0,0,0,0,0,0,0,0,0,0,0,0,0,0,0,0,0,0,0,0,0,0,0,0,0,0,0,0,0,0,0,0,0,0,0,0
0,0,0,0,0,0,0,0,0,0,0,0,0,0,0,0,0,0,0,0,0,0,0,0,0,0,0,0,0,0,0,0,0,0,0,0,0,0,0
0,0,0,0,0,0,0,0,0,0,0,0,0,0,0,0,0,0,0,0,0,0,0,0,0,0,0,0,0,0,0,0,0,0,0,0,0,0,0
0,0,0,0,0,0,0,0,0,0,0,0,0,0,0,0,0,208,209,209,209,208,0,0,0,0,0,0,0,0,0,0,0,0,0,0,0,0,0
0,0,0,0,0,0,0,0,0,0,0,0,0,0,0,0,0,178,0,0,0,179,0,0,0,0,0,0,0,0,0,0,0,0,0,0,0,0,0
0,0,0,0,0,0,0,0,0,0,0,0,0,0,0,0,0,178,3,194,0,179,0,0,0,0,0,0,0,0,0,0,0,0,0,0,0,0,0
0,0,0,0,0,0,0,0,0,0,0,0,0,0,0,0,0,178,0,0,0,179,0,0,0,0,0,0,0,0,0,0,0,0,0,0,0,0,0
0,0,0,0,0,0,0,0,0,0,0,0,0,0,0,0,0,208,181,181,181,208,0,0,0,0,0,0,0,0,0,0,0,0,0,0,0,0,0
0,0,0,0,0,0,0,0,0,0,0,0,0,0,0,0,0,0,0,0,0,0,0,0,0,0,0,0,0,0,0,0,0,0,0,0,0,0,0
0,0,0,0,0,0,0,0,0,0,0,0,0,0,0,0,0,0,0,0,0,0,0,0,0,0,0,0,0,0,0,0,0,0,0,0,0,0,0
0,0,0,0,0,0,0,0,0,0,0,0,0,0,0,0,0,0,0,0,0,0,0,0,0,0,0,0,0,0,0,0,0,0,0,0,0,0,0
0,0,0,0,0,0,0,0,0,0,0,0,0,0,0,0,0,3,3,3,3,3,0,0,0,0,0,0,0,0,0,0,0,0,0,0,0,0,0
0,0,0,0,0,0,0,0,0,0,0,0,0,0,0,0,0,3,3,3,3,3,0,0,0,0,0,0,0,0,0,0,0,0,0,0,0,0,0
0,0,0,0,0,0,0,0,0,0,0,0,0,0,0,0,42,3,3,3,3,3,48,0,0,0,0,0,0,0,0,0,0,0,0,0,0,0,0
0,0,0,0,0,0,0,0,0,0,0,0,0,0,0,0,3,3,26,0,0,0,3,0,0,0,0,0,0,0,0,0,0,0,0,0,0,0,0
0,0,0,0,0,0,0,0,0,0,0,0,0,0,47,3,3,3,26,0,0,0,0,3,47,0,0,0,0,0,0,0,0,0,0,0,0,0,0
0,0,0,0,208,209,209,209,208,0,0,0,3,3,3,48,0,0,0,0,0,0,0,49,3,3,3,0,0,0,208,209,209,209,208,0,0,0,0
0,0,0,0,178,0,0,0,215,0,0,0,3,3,3,0,0,0,0,0,0,0,0,0,3,3,3,0,0,0,178,0,0,0,179,0,0,0,0
0,0,0,0,178,3,194,0,215,0,0,0,216,0,0,0,0,0,0,0,0,0,0,0,0,0,216,0,0,0,178,3,194,0,179,0,0,0,0
0,0,0,0,178,0,0,0,179,0,0,0,3,3,3,0,0,0,0,0,0,0,0,0,3,3,3,0,0,0,178,0,0,0,179,0,0,0,0
0,0,0,0,208,181,181,181,208,0,0,0,3,3,3,0,0,0,0,0,0,0,0,0,3,3,3,0,0,0,208,181,181,181,208,0,0,0,0
0,0,0,0,0,0,0,0,0,0,0,0,0,0,49,3,48,0,0,0,0,0,47,3,49,0,0,0,0,0,0,0,0,0,0,0,0,0,0
0,0,0,0,0,0,0,0,0,0,0,0,0,0,0,0,3,0,0,0,0,0,3,0,0,0,0,0,0,0,0,0,0,0,0,0,0,0,0
0,0,0,0,0,0,0,0,0,0,0,0,0,0,0,0,42,3,3,47,3,3,48,0,0,0,0,0,0,0,0,0,0,0,0,0,0,0,0
0,0,0,0,0,0,0,0,0,0,0,0,0,0,0,0,0,3,3,3,3,3,0,0,0,0,0,0,0,0,0,0,0,0,0,0,0,0,0
0,0,0,0,0,0,0,0,0,0,0,0,0,0,0,0,0,3,3,49,3,3,0,0,0,0,0,0,0,0,0,0,0,0,0,0,0,0,0
0,0,0,0,0,0,0,0,0,0,0,0,0,0,0,0,0,0,0,0,0,0,0,0,0,0,0,0,0,0,0,0,0,0,0,0,0,0,0
0,0,0,0,0,0,0,0,0,0,0,0,0,0,0,0,0,0,0,0,0,0,0,0,0,0,0,0,0,0,0,0,0,0,0,0,0,0,0
0,0,0,0,0,0,0,0,0,0,0,0,0,0,0,0,0,0,0,0,0,0,0,0,0,0,0,0,0,0,0,0,0,0,0,0,0,0,0
0,0,0,0,0,0,0,0,0,0,0,0,0,0,0,0,0,208,209,209,209,208,0,0,0,0,0,0,0,0,0,0,0,0,0,0,0,0,0
0,0,0,0,0,0,0,0,0,0,0,0,0,0,0,0,0,178,0,0,0,179,0,0,0,0,0,0,0,0,0,0,0,0,0,0,0,0,0
0,0,0,0,0,0,0,0,0,0,0,0,0,0,0,0,0,178,3,194,0,179,0,0,0,0,0,0,0,0,0,0,0,0,0,0,0,0,0
0,0,0,0,0,0,0,0,0,0,0,0,0,0,0,0,0,178,0,0,0,179,0,0,0,0,0,0,0,0,0,0,0,0,0,0,0,0,0
0,0,0,0,0,0,0,0,0,0,0,0,0,0,0,0,0,208,181,181,181,208,0,0,0,0,0,0,0,0,0,0,0,0,0,0,0,0,0
0,0,0,0,0,0,0,0,0,0,0,0,0,0,0,0,0,0,0,0,0,0,0,0,0,0,0,0,0,0,0,0,0,0,0,0,0,0,0
0,0,0,0,0,0,0,0,0,0,0,0,0,0,0,0,0,0,0,0,0,0,0,0,0,0,0,0,0,0,0,0,0,0,0,0,0,0,0
0,0,0,0,0,0,0,0,0,0,0,0,0,0,0,0,0,0,0,0,0,0,0,0,0,0,0,0,0,0,0,0,0,0,0,0,0,0,0
0,0,0,0,0,0,0,0,0,0,0,0,0,0,0,0,0,0,0,0,0,0,0,0,0,0,0,0,0,0,0,0,0,0,0,0,0,0,0
0,0,0,0,0,0,0,0,0,0,0,0,0,0,0,0,0,0,0,0,0,0,0,0,0,0,0,0,0,0,0,0,0,0,0,0,0,0,0
0,0,0,0,0,0,0,0,0,0,0,0,0,0,0,0,0,0,0,0,0,0,0,0,0,0,0,0,0,0,0,0,0,0,0,0,0,0,0
0,0,0,0,0,0,0,0,0,0,0,0,0,0,0,0,0,0,0,0,0,0,0,0,0,0,0,0,0,0,0,0,0,0,0,0,0,0,0
:endlayer
layer: 26
0,0,0,0,0,0,0,0,0,0,0,0,0,0,0,0,0,0,0,0,0,0,0,0,0,0,0,0,0,0,0,0,0,0,0,0,0,0,0
0,0,0,0,0,0,0,0,0,0,0,0,0,0,0,0,0,0,0,0,0,0,0,0,0,0,0,0,0,0,0,0,0,0,0,0,0,0,0
0,0,0,0,0,0,0,0,0,0,0,0,0,0,0,0,0,0,0,0,0,0,0,0,0,0,0,0,0,0,0,0,0,0,0,0,0,0,0
0,0,0,0,0,0,0,0,0,0,0,0,0,0,0,0,0,0,0,0,0,0,0,0,0,0,0,0,0,0,0,0,0,0,0,0,0,0,0
0,0,0,0,0,0,0,0,0,0,0,0,0,0,0,0,0,0,0,0,0,0,0,0,0,0,0,0,0,0,0,0,0,0,0,0,0,0,0
0,0,0,0,0,0,0,0,0,0,0,0,0,0,0,0,0,0,209,209,209,0,0,0,0,0,0,0,0,0,0,0,0,0,0,0,0,0,0
0,0,0,0,0,0,0,0,0,0,0,0,0,0,0,0,0,0,178,0,179,0,0,0,0,0,0,0,0,0,0,0,0,0,0,0,0,0,0
0,0,0,0,0,0,0,0,0,0,0,0,0,0,0,0,0,0,178,180,179,0,0,0,0,0,0,0,0,0,0,0,0,0,0,0,0,0,0
0,0,0,0,0,0,0,0,0,0,0,0,0,0,0,0,0,0,0,0,0,0,0,0,0,0,0,0,0,0,0,0,0,0,0,0,0,0,0
0,0,0,0,0,0,0,0,0,0,0,0,0,0,0,0,0,0,0,0,0,0,0,0,0,0,0,0,0,0,0,0,0,0,0,0,0,0,0
0,0,0,0,0,0,0,0,0,0,0,0,0,0,0,0,0,0,0,0,0,0,0,0,0,0,0,0,0,0,0,0,0,0,0,0,0,0,0
0,0,0,0,0,0,0,0,0,0,0,0,0,0,0,0,0,0,0,0,0,0,0,0,0,0,0,0,0,0,0,0,0,0,0,0,0,0,0
0,0,0,0,0,0,0,0,0,0,0,0,0,0,0,0,0,3,3,3,3,3,0,0,0,0,0,0,0,0,0,0,0,0,0,0,0,0,0
0,0,0,0,0,0,0,0,0,0,0,0,0,0,0,0,0,3,3,3,3,3,0,0,0,0,0,0,0,0,0,0,0,0,0,0,0,0,0
0,0,0,0,0,0,0,0,0,0,0,0,0,0,0,0,3,3,3,3,3,3,0,0,0,0,0,0,0,0,0,0,0,0,0,0,0,0,0
0,0,0,0,0,0,0,0,0,0,0,0,0,0,0,3,3,26,0,0,0,0,3,3,0,0,0,0,0,0,0,0,0,0,0,0,0,0,0
0,0,0,0,0,0,0,0,0,0,0,0,0,0,3,3,3,26,0,0,0,0,3,3,3,0,0,0,0,0,0,0,0,0,0,0,0,0,0
0,0,0,0,0,0,0,0,0,0,0,0,3,3,3,3,3,3,3,3,3,3,3,3,3,3,3,0,0,0,0,0,0,0,0,0,0,0,0
0,0,0,0,0,208,209,209,0,0,0,0,3,3,3,3,3,3,3,3,3,3,3,3,3,3,3,0,0,0,0,208,209,208,0,0,0,0,0
0,0,0,0,0,178,0,179,0,0,0,0,3,3,3,3,3,3,3,3,3,3,3,3,3,3,3,0,0,0,0,178,0,179,0,0,0,0,0
0,0,0,0,0,178,180,179,0,0,0,0,3,3,3,3,3,3,3,3,3,3,3,3,3,3,3,0,0,0,0,178,180,179,0,0,0,0,0
0,0,0,0,0,0,0,0,0,0,0,0,3,3,3,3,3,3,3,3,3,3,3,3,3,3,3,0,0,0,0,0,0,0,0,0,0,0,0
0,0,0,0,0,0,0,0,0,0,0,0,0,0,3,3,3,3,3,3,3,3,3,3,3,0,0,0,0,0,0,0,0,0,0,0,0,0,0
0,0,0,0,0,0,0,0,0,0,0,0,0,0,0,3,3,3,3,3,3,3,3,3,0,0,0,0,0,0,0,0,0,0,0,0,0,0,0
0,0,0,0,0,0,0,0,0,0,0,0,0,0,0,0,3,3,3,3,3,3,3,0,0,0,0,0,0,0,0,0,0,0,0,0,0,0,0
0,0,0,0,0,0,0,0,0,0,0,0,0,0,0,0,0,3,3,3,3,3,0,0,0,0,0,0,0,0,0,0,0,0,0,0,0,0,0
0,0,0,0,0,0,0,0,0,0,0,0,0,0,0,0,0,3,3,3,3,3,0,0,0,0,0,0,0,0,0,0,0,0,0,0,0,0,0
0,0,0,0,0,0,0,0,0,0,0,0,0,0,0,0,0,0,0,49,0,0,0,0,0,0,0,0,0,0,0,0,0,0,0,0,0,0,0
0,0,0,0,0,0,0,0,0,0,0,0,0,0,0,0,0,0,0,0,0,0,0,0,0,0,0,0,0,0,0,0,0,0,0,0,0,0,0
0,0,0,0,0,0,0,0,0,0,0,0,0,0,0,0,0,0,0,0,0,0,0,0,0,0,0,0,0,0,0,0,0,0,0,0,0,0,0
0,0,0,0,0,0,0,0,0,0,0,0,0,0,0,0,0,0,0,0,0,0,0,0,0,0,0,0,0,0,0,0,0,0,0,0,0,0,0
0,0,0,0,0,0,0,0,0,0,0,0,0,0,0,0,0,0,178,209,208,0,0,0,0,0,0,0,0,0,0,0,0,0,0,0,0,0,0
0,0,0,0,0,0,0,0,0,0,0,0,0,0,0,0,0,0,178,0,179,0,0,0,0,0,0,0,0,0,0,0,0,0,0,0,0,0,0
0,0,0,0,0,0,0,0,0,0,0,0,0,0,0,0,0,0,178,180,179,0,0,0,0,0,0,0,0,0,0,0,0,0,0,0,0,0,0
0,0,0,0,0,0,0,0,0,0,0,0,0,0,0,0,0,0,0,0,0,0,0,0,0,0,0,0,0,0,0,0,0,0,0,0,0,0,0
0,0,0,0,0,0,0,0,0,0,0,0,0,0,0,0,0,0,0,0,0,0,0,0,0,0,0,0,0,0,0,0,0,0,0,0,0,0,0
0,0,0,0,0,0,0,0,0,0,0,0,0,0,0,0,0,0,0,0,0,0,0,0,0,0,0,0,0,0,0,0,0,0,0,0,0,0,0
0,0,0,0,0,0,0,0,0,0,0,0,0,0,0,0,0,0,0,0,0,0,0,0,0,0,0,0,0,0,0,0,0,0,0,0,0,0,0
0,0,0,0,0,0,0,0,0,0,0,0,0,0,0,0,0,0,0,0,0,0,0,0,0,0,0,0,0,0,0,0,0,0,0,0,0,0,0
0,0,0,0,0,0,0,0,0,0,0,0,0,0,0,0,0,0,0,0,0,0,0,0,0,0,0,0,0,0,0,0,0,0,0,0,0,0,0
0,0,0,0,0,0,0,0,0,0,0,0,0,0,0,0,0,0,0,0,0,0,0,0,0,0,0,0,0,0,0,0,0,0,0,0,0,0,0
0,0,0,0,0,0,0,0,0,0,0,0,0,0,0,0,0,0,0,0,0,0,0,0,0,0,0,0,0,0,0,0,0,0,0,0,0,0,0
:endlayer
layer: 27
0,0,0,0,0,0,0,0,0,0,0,0,0,0,0,0,0,0,0,0,0,0,0,0,0,0,0,0,0,0,0,0,0,0,0,0,0,0,0
0,0,0,0,0,0,0,0,0,0,0,0,0,0,0,0,0,0,0,0,0,0,0,0,0,0,0,0,0,0,0,0,0,0,0,0,0,0,0
0,0,0,0,0,0,0,0,0,0,0,0,0,0,0,0,0,0,0,0,0,0,0,0,0,0,0,0,0,0,0,0,0,0,0,0,0,0,0
0,0,0,0,0,0,0,0,0,0,0,0,0,0,0,0,0,0,0,0,0,0,0,0,0,0,0,0,0,0,0,0,0,0,0,0,0,0,0
0,0,0,0,0,0,0,0,0,0,0,0,0,0,0,0,0,0,0,0,0,0,0,0,0,0,0,0,0,0,0,0,0,0,0,0,0,0,0
0,0,0,0,0,0,0,0,0,0,0,0,0,0,0,0,0,0,0,0,0,0,0,0,0,0,0,0,0,0,0,0,0,0,0,0,0,0,0
0,0,0,0,0,0,0,0,0,0,0,0,0,0,0,0,0,0,0,220,0,0,0,0,0,0,0,0,0,0,0,0,0,0,0,0,0,0,0
0,0,0,0,0,0,0,0,0,0,0,0,0,0,0,0,0,0,42,180,48,0,0,0,0,0,0,0,0,0,0,0,0,0,0,0,0,0,0
0,0,0,0,0,0,0,0,0,0,0,0,0,0,0,0,0,0,0,49,0,0,0,0,0,0,0,0,0,0,0,0,0,0,0,0,0,0,0
0,0,0,0,0,0,0,0,0,0,0,0,0,0,0,0,0,0,0,0,0,0,0,0,0,0,0,0,0,0,0,0,0,0,0,0,0,0,0
0,0,0,0,0,0,0,0,0,0,0,0,0,0,0,0,0,0,0,0,0,0,0,0,0,0,0,0,0,0,0,0,0,0,0,0,0,0,0
0,0,0,0,0,0,0,0,0,0,0,0,0,0,0,0,0,151,151,151,151,151,0,0,0,0,0,0,0,0,0,0,0,0,0,0,0,0,0
0,0,0,0,0,0,0,0,0,0,0,0,0,0,0,0,0,3,3,3,3,3,0,0,0,0,0,0,0,0,0,0,0,0,0,0,0,0,0
0,0,0,0,0,0,0,0,0,0,0,0,0,0,0,0,3,0,0,221,3,3,3,0,0,0,0,0,0,0,0,0,0,0,0,0,0,0,0
0,0,0,0,0,0,0,0,0,0,0,0,0,0,0,3,0,0,0,0,3,3,3,3,0,0,0,0,0,0,0,0,0,0,0,0,0,0,0
0,0,0,0,0,0,0,0,0,0,0,0,0,0,3,0,0,0,0,0,0,3,26,0,3,0,0,0,0,0,0,0,0,0,0,0,0,0,0
0,0,0,0,0,0,0,0,0,0,0,0,0,3,0,0,0,0,0,0,0,3,26,0,0,3,0,0,0,0,0,0,0,0,0,0,0,0,0
0,0,0,0,0,0,0,0,0,0,0,24,3,0,0,0,0,3,3,3,3,3,3,16,3,222,3,26,0,0,0,0,0,0,0,0,0,0,0
0,0,0,0,0,0,0,0,0,0,0,24,3,0,0,0,0,0,3,88,3,0,0,0,0,0,3,26,0,0,0,0,0,0,0,0,0,0,0
0,0,0,0,0,0,220,0,0,0,0,24,3,0,0,0,0,0,67,223,67,0,0,0,0,224,3,26,0,0,0,0,220,0,0,0,0,0,0
0,0,0,0,0,42,180,48,0,0,0,24,3,0,0,0,0,0,225,225,225,0,0,0,0,224,3,26,0,0,0,42,180,48,0,0,0,0,0
0,0,0,0,0,0,49,0,0,0,0,24,3,0,0,0,0,226,225,225,225,224,0,0,0,0,3,26,0,0,0,0,49,0,0,0,0,0,0
0,0,0,0,0,0,0,0,0,0,0,0,0,3,0,0,0,226,225,225,225,224,0,0,227,3,0,0,0,0,0,0,0,0,0,0,0,0,0
0,0,0,0,0,0,0,0,0,0,0,0,0,0,3,0,0,0,225,225,225,0,0,228,3,0,0,0,0,0,0,0,0,0,0,0,0,0,0
0,0,0,0,0,0,0,0,0,0,0,0,0,0,0,3,0,0,225,225,225,229,230,3,0,0,0,0,0,0,0,0,0,0,0,0,0,0,0
0,0,0,0,0,0,0,0,0,0,0,0,0,0,0,0,3,0,231,0,231,0,3,0,0,0,0,0,0,0,0,0,0,0,0,0,0,0,0
0,0,0,0,0,0,0,0,0,0,0,0,0,0,0,0,0,3,3,3,3,3,0,0,0,0,0,0,0,0,0,0,0,0,0,0,0,0,0
0,0,0,0,0,0,0,0,0,0,0,0,0,0,0,0,0,67,67,67,67,67,0,0,0,0,0,0,0,0,0,0,0,0,0,0,0,0,0
0,0,0,0,0,0,0,0,0,0,0,0,0,0,0,0,0,0,0,0,0,0,0,0,0,0,0,0,0,0,0,0,0,0,0,0,0,0,0
0,0,0,0,0,0,0,0,0,0,0,0,0,0,0,0,0,0,0,0,0,0,0,0,0,0,0,0,0,0,0,0,0,0,0,0,0,0,0
0,0,0,0,0,0,0,0,0,0,0,0,0,0,0,0,0,0,0,0,0,0,0,0,0,0,0,0,0,0,0,0,0,0,0,0,0,0,0
0,0,0,0,0,0,0,0,0,0,0,0,0,0,0,0,0,0,0,0,0,0,0,0,0,0,0,0,0,0,0,0,0,0,0,0,0,0,0
0,0,0,0,0,0,0,0,0,0,0,0,0,0,0,0,0,0,0,220,0,0,0,0,0,0,0,0,0,0,0,0,0,0,0,0,0,0,0
0,0,0,0,0,0,0,0,0,0,0,0,0,0,0,0,0,0,42,180,48,0,0,0,0,0,0,0,0,0,0,0,0,0,0,0,0,0,0
0,0,0,0,0,0,0,0,0,0,0,0,0,0,0,0,0,0,0,49,0,0,0,0,0,0,0,0,0,0,0,0,0,0,0,0,0,0,0
0,0,0,0,0,0,0,0,0,0,0,0,0,0,0,0,0,0,0,0,0,0,0,0,0,0,0,0,0,0,0,0,0,0,0,0,0,0,0
0,0,0,0,0,0,0,0,0,0,0,0,0,0,0,0,0,0,0,0,0,0,0,0,0,0,0,0,0,0,0,0,0,0,0,0,0,0,0
0,0,0,0,0,0,0,0,0,0,0,0,0,0,0,0,0,0,0,0,0,0,0,0,0,0,0,0,0,0,0,0,0,0,0,0,0,0,0
0,0,0,0,0,0,0,0,0,0,0,0,0,0,0,0,0,0,0,0,0,0,0,0,0,0,0,0,0,0,0,0,0,0,0,0,0,0,0
0,0,0,0,0,0,0,0,0,0,0,0,0,0,0,0,0,0,0,0,0,0,0,0,0,0,0,0,0,0,0,0,0,0,0,0,0,0,0
0,0,0,0,0,0,0,0,0,0,0,0,0,0,0,0,0,0,0,0,0,0,0,0,0,0,0,0,0,0,0,0,0,0,0,0,0,0,0
0,0,0,0,0,0,0,0,0,0,0,0,0,0,0,0,0,0,0,0,0,0,0,0,0,0,0,0,0,0,0,0,0,0,0,0,0,0,0
:endlayer
layer: 28
0,0,0,0,0,0,0,0,0,0,0,0,0,0,0,0,0,0,0,0,0,0,0,0,0,0,0,0,0,0,0,0,0,0,0,0,0,0,0
0,0,0,0,0,0,0,0,0,0,0,0,0,0,0,0,0,0,0,0,0,0,0,0,0,0,0,0,0,0,0,0,0,0,0,0,0,0,0
0,0,0,0,0,0,0,0,0,0,0,0,0,0,0,0,0,0,0,0,0,0,0,0,0,0,0,0,0,0,0,0,0,0,0,0,0,0,0
0,0,0,0,0,0,0,0,0,0,0,0,0,0,0,0,0,0,0,0,0,0,0,0,0,0,0,0,0,0,0,0,0,0,0,0,0,0,0
0,0,0,0,0,0,0,0,0,0,0,0,0,0,0,0,0,0,0,0,0,0,0,0,0,0,0,0,0,0,0,0,0,0,0,0,0,0,0
0,0,0,0,0,0,0,0,0,0,0,0,0,0,0,0,0,0,0,0,0,0,0,0,0,0,0,0,0,0,0,0,0,0,0,0,0,0,0
0,0,0,0,0,0,0,0,0,0,0,0,0,0,0,0,0,0,0,0,0,0,0,0,0,0,0,0,0,0,0,0,0,0,0,0,0,0,0
0,0,0,0,0,0,0,0,0,0,0,0,0,0,0,0,0,0,0,89,0,0,0,0,0,0,0,0,0,0,0,0,0,0,0,0,0,0,0
0,0,0,0,0,0,0,0,0,0,0,0,0,0,0,0,0,0,0,0,0,0,0,0,0,0,0,0,0,0,0,0,0,0,0,0,0,0,0
0,0,0,0,0,0,0,0,0,0,0,0,0,0,0,0,0,0,0,0,0,0,0,0,0,0,0,0,0,0,0,0,0,0,0,0,0,0,0
0,0,0,0,0,0,0,0,0,0,0,0,0,0,0,0,0,0,0,0,0,0,0,0,0,0,0,0,0,0,0,0,0,0,0,0,0,0,0
0,0,0,0,0,0,0,0,0,0,0,0,0,0,0,0,0,0,0,0,0,0,0,0,0,0,0,0,0,0,0,0,0,0,0,0,0,0,0
0,0,0,0,0,0,0,0,0,0,0,0,0,0,0,0,0,3,216,3,3,3,0,0,0,0,0,0,0,0,0,0,0,0,0,0,0,0,0
0,0,0,0,0,0,0,0,0,0,0,0,0,0,0,0,180,0,0,0,3,3,180,0,0,0,0,0,0,0,0,0,0,0,0,0,0,0,0
0,0,0,0,0,0,0,0,0,0,0,0,0,0,0,180,0,0,0,0,3,3,3,180,0,0,0,0,0,0,0,0,0,0,0,0,0,0,0
0,0,0,0,0,0,0,0,0,0,0,0,0,0,180,0,0,0,0,0,3,26,0,0,180,0,0,0,0,0,0,0,0,0,0,0,0,0,0
0,0,0,0,0,0,0,0,0,0,0,0,0,180,0,0,0,0,0,0,3,26,0,0,0,180,0,0,0,0,0,0,0,0,0,0,0,0,0
0,0,0,0,0,0,0,0,0,0,0,0,3,0,0,0,0,3,3,3,3,3,3,41,3,0,3,0,0,0,0,0,0,0,0,0,0,0,0
0,0,0,0,0,0,0,0,0,0,0,0,3,0,0,0,0,49,3,0,3,49,0,0,0,0,3,0,0,0,0,0,0,0,0,0,0,0,0
0,0,0,0,0,0,0,0,0,0,0,0,216,0,0,0,0,0,0,0,0,0,0,0,0,0,216,0,0,0,0,0,0,0,0,0,0,0,0
0,0,0,0,0,0,89,0,0,0,0,0,3,0,0,0,0,0,0,0,0,0,0,0,0,0,3,0,0,0,0,0,89,0,0,0,0,0,0
0,0,0,0,0,0,0,0,0,0,0,0,3,0,0,0,0,0,0,0,0,0,0,0,0,0,3,0,0,0,0,0,0,0,0,0,0,0,0
0,0,0,0,0,0,0,0,0,0,0,0,0,180,0,0,0,0,0,232,0,0,0,0,0,180,0,0,0,0,0,0,0,0,0,0,0,0,0
0,0,0,0,0,0,0,0,0,0,0,0,0,0,180,0,0,0,0,0,0,0,0,0,180,0,0,0,0,0,0,0,0,0,0,0,0,0,0
0,0,0,0,0,0,0,0,0,0,0,0,0,0,0,180,0,0,233,0,0,0,0,180,0,0,0,0,0,0,0,0,0,0,0,0,0,0,0
0,0,0,0,0,0,0,0,0,0,0,0,0,0,0,0,180,0,0,0,0,0,180,0,0,0,0,0,0,0,0,0,0,0,0,0,0,0,0
0,0,0,0,0,0,0,0,0,0,0,0,0,0,0,0,0,3,3,216,3,3,0,0,0,0,0,0,0,0,0,0,0,0,0,0,0,0,0
0,0,0,0,0,0,0,0,0,0,0,0,0,0,0,0,0,0,0,0,0,0,0,0,0,0,0,0,0,0,0,0,0,0,0,0,0,0,0
0,0,0,0,0,0,0,0,0,0,0,0,0,0,0,0,0,0,0,0,0,0,0,0,0,0,0,0,0,0,0,0,0,0,0,0,0,0,0
0,0,0,0,0,0,0,0,0,0,0,0,0,0,0,0,0,0,0,0,0,0,0,0,0,0,0,0,0,0,0,0,0,0,0,0,0,0,0
0,0,0,0,0,0,0,0,0,0,0,0,0,0,0,0,0,0,0,0,0,0,0,0,0,0,0,0,0,0,0,0,0,0,0,0,0,0,0
0,0,0,0,0,0,0,0,0,0,0,0,0,0,0,0,0,0,0,0,0,0,0,0,0,0,0,0,0,0,0,0,0,0,0,0,0,0,0
0,0,0,0,0,0,0,0,0,0,0,0,0,0,0,0,0,0,0,0,0,0,0,0,0,0,0,0,0,0,0,0,0,0,0,0,0,0,0
0,0,0,0,0,0,0,0,0,0,0,0,0,0,0,0,0,0,0,89,0,0,0,0,0,0,0,0,0,0,0,0,0,0,0,0,0,0,0
0,0,0,0,0,0,0,0,0,0,0,0,0,0,0,0,0,0,0,0,0,0,0,0,0,0,0,0,0,0,0,0,0,0,0,0,0,0,0
0,0,0,0,0,0,0,0,0,0,0,0,0,0,0,0,0,0,0,0,0,0,0,0,0,0,0,0,0,0,0,0,0,0,0,0,0,0,0
0,0,0,0,0,0,0,0,0,0,0,0,0,0,0,0,0,0,0,0,0,0,0,0,0,0,0,0,0,0,0,0,0,0,0,0,0,0,0
0,0,0,0,0,0,0,0,0,0,0,0,0,0,0,0,0,0,0,0,0,0,0,0,0,0,0,0,0,0,0,0,0,0,0,0,0,0,0
0,0,0,0,0,0,0,0,0,0,0,0,0,0,0,0,0,0,0,0,0,0,0,0,0,0,0,0,0,0,0,0,0,0,0,0,0,0,0
0,0,0,0,0,0,0,0,0,0,0,0,0,0,0,0,0,0,0,0,0,0,0,0,0,0,0,0,0,0,0,0,0,0,0,0,0,0,0
0,0,0,0,0,0,0,0,0,0,0,0,0,0,0,0,0,0,0,0,0,0,0,0,0,0,0,0,0,0,0,0,0,0,0,0,0,0,0
0,0,0,0,0,0,0,0,0,0,0,0,0,0,0,0,0,0,0,0,0,0,0,0,0,0,0,0,0,0,0,0,0,0,0,0,0,0,0
:endlayer
layer: 29
0,0,0,0,0,0,0,0,0,0,0,0,0,0,0,0,0,0,0,0,0,0,0,0,0,0,0,0,0,0,0,0,0,0,0,0,0,0,0
0,0,0,0,0,0,0,0,0,0,0,0,0,0,0,0,0,0,0,0,0,0,0,0,0,0,0,0,0,0,0,0,0,0,0,0,0,0,0
0,0,0,0,0,0,0,0,0,0,0,0,0,0,0,0,0,0,0,0,0,0,0,0,0,0,0,0,0,0,0,0,0,0,0,0,0,0,0
0,0,0,0,0,0,0,0,0,0,0,0,0,0,0,0,0,0,0,0,0,0,0,0,0,0,0,0,0,0,0,0,0,0,0,0,0,0,0
0,0,0,0,0,0,0,0,0,0,0,0,0,0,0,0,0,0,0,0,0,0,0,0,0,0,0,0,0,0,0,0,0,0,0,0,0,0,0
0,0,0,0,0,0,0,0,0,0,0,0,0,0,0,0,0,0,0,0,0,0,0,0,0,0,0,0,0,0,0,0,0,0,0,0,0,0,0
0,0,0,0,0,0,0,0,0,0,0,0,0,0,0,0,0,0,0,0,0,0,0,0,0,0,0,0,0,0,0,0,0,0,0,0,0,0,0
0,0,0,0,0,0,0,0,0,0,0,0,0,0,0,0,0,0,0,0,0,0,0,0,0,0,0,0,0,0,0,0,0,0,0,0,0,0,0
0,0,0,0,0,0,0,0,0,0,0,0,0,0,0,0,0,0,0,0,0,0,0,0,0,0,0,0,0,0,0,0,0,0,0,0,0,0,0
0,0,0,0,0,0,0,0,0,0,0,0,0,0,0,0,0,0,0,0,0,0,0,0,0,0,0,0,0,0,0,0,0,0,0,0,0,0,0
