# Ancient Warfare Structure Template File
# Auto-generated structure template file. created on: 8/19/2019 at: 10:23:10
# Lines beginning with # denote comments

header:
version=2.9
name=EmpireFarmLarge
mods=
size=39,12,29
offset=20,4,28
:endheader

#### VALIDATION ####
validation:
type=ground
survival=false
worldGenEnabled=true
unique=false
preserveBlocks=false
selectionWeight=30
clusterValue=20
minDuplicateDistance=600
dimensionWhiteList=true
dimensionList=0
biomeWhiteList=true
biomeList=biomesoplenty:meadow,traverse:meadow,minecraft:plains
leveling=5
fill=5
border=5
blockSwap=false
:endvalidation

#### LAYERS ####
layer: 0
1,1,1,1,1,1,1,1,1,1,1,1,1,1,1,1,1,1,1,1,1,1,1,1,1,1,1,1,1,1,1,1,1,1,1,1,1,1,1
1,1,1,1,1,1,1,1,1,1,1,1,1,1,1,1,1,1,1,1,1,1,1,1,1,1,1,1,1,1,1,1,1,1,1,1,1,1,1
1,1,1,1,1,1,1,1,1,1,1,1,1,1,1,1,1,1,1,1,1,1,1,1,1,1,1,1,1,1,1,1,1,1,1,1,1,1,1
1,1,1,1,1,1,1,1,1,1,1,1,1,1,1,1,1,1,1,1,1,1,1,1,1,1,1,1,1,1,1,1,1,1,1,1,1,1,1
1,1,1,1,1,1,1,1,1,1,1,1,1,1,1,1,1,1,1,1,1,1,1,1,1,1,1,1,1,1,1,1,1,1,1,1,1,1,1
1,1,1,1,1,1,1,1,1,1,1,1,1,1,1,1,1,1,1,1,1,1,1,1,1,1,1,1,1,1,1,1,1,1,1,1,1,1,1
1,1,1,1,1,1,1,1,1,1,1,1,1,1,1,1,1,1,1,1,1,1,1,1,1,1,1,1,1,1,1,1,1,1,1,1,1,1,1
1,1,1,1,1,1,1,1,1,1,1,1,1,1,1,1,1,1,1,1,1,1,1,1,1,1,1,1,1,1,1,1,1,1,1,1,1,1,1
1,1,1,1,1,1,1,1,1,1,1,1,1,1,1,1,1,1,1,1,1,1,1,1,1,1,1,1,1,1,1,1,1,1,1,1,1,1,1
1,1,1,1,1,1,1,1,1,1,1,1,1,1,1,1,1,1,1,1,1,1,1,1,1,1,1,1,1,1,1,1,1,1,1,1,1,1,1
1,1,1,1,1,1,1,1,1,1,1,1,1,1,1,1,1,1,1,1,1,1,1,1,1,1,1,1,1,1,1,1,1,1,1,1,1,1,1
1,1,1,1,1,1,1,1,1,1,1,1,1,1,1,1,1,1,1,1,1,1,1,1,1,1,1,1,1,1,1,1,1,1,1,1,1,1,1
1,1,1,1,1,1,1,1,1,1,1,1,1,1,1,1,1,1,1,1,1,1,1,1,1,1,1,1,1,1,1,1,1,1,1,1,1,1,1
1,1,1,1,1,1,1,1,1,1,1,1,1,1,1,1,1,1,1,1,1,1,1,1,1,1,1,1,1,1,1,1,1,1,1,1,1,1,1
1,1,1,1,1,1,1,1,1,1,1,1,1,1,1,1,1,1,1,1,1,1,1,1,1,1,1,1,1,1,1,1,1,1,1,1,1,1,1
1,1,1,1,1,1,1,1,1,1,1,1,1,1,1,1,1,1,1,1,1,1,1,1,1,1,1,1,1,1,1,1,1,1,1,1,1,1,1
1,1,1,1,1,1,1,1,1,1,1,1,1,1,1,1,1,1,1,1,1,1,1,1,1,1,1,1,1,1,1,1,1,1,1,1,1,1,1
1,1,1,1,1,1,1,1,1,1,1,1,1,1,1,1,1,1,1,1,1,1,1,1,1,1,1,1,1,1,1,1,1,1,1,1,1,1,1
1,1,1,1,1,1,1,1,1,1,1,1,1,1,1,1,1,1,1,1,1,1,1,1,1,1,1,1,1,1,1,1,1,1,1,1,1,1,1
1,1,1,1,1,1,1,1,1,1,1,1,1,1,1,1,1,1,1,1,1,1,1,1,1,1,1,1,1,1,1,1,1,1,1,1,1,1,1
1,1,1,1,1,1,1,1,1,1,1,1,1,1,1,1,1,1,1,1,1,1,1,1,1,1,1,1,1,1,1,1,1,1,1,1,1,1,1
1,1,1,1,1,1,1,1,1,1,1,1,1,1,1,1,1,1,1,1,1,1,1,1,1,1,1,1,1,1,1,1,1,1,1,1,1,1,1
1,1,1,1,1,1,1,1,1,1,1,1,1,1,1,1,1,1,1,1,1,1,1,1,1,1,1,1,1,1,1,1,1,1,1,1,1,1,1
1,1,1,1,1,1,1,1,1,1,1,1,1,1,1,1,1,1,1,1,1,1,1,1,1,1,1,1,1,1,1,1,1,1,1,1,1,1,1
1,1,1,1,1,1,1,1,1,1,1,1,1,1,1,1,1,1,1,1,1,1,1,1,1,1,1,1,1,1,1,1,1,1,1,1,1,1,1
1,1,1,1,1,1,1,1,1,1,1,1,1,1,1,1,1,1,1,1,1,1,1,1,1,1,1,1,1,1,1,1,1,1,1,1,1,1,1
1,1,1,1,1,1,1,1,1,1,1,1,1,1,1,1,1,1,1,1,1,1,1,1,1,1,1,1,1,1,1,1,1,1,1,1,1,1,1
1,1,1,1,1,1,1,1,1,1,1,1,1,1,1,1,1,1,1,1,1,1,1,1,1,1,1,1,1,1,1,1,1,1,1,1,1,1,1
1,1,1,1,1,1,1,1,1,1,1,1,1,1,1,1,1,1,1,1,1,1,1,1,1,1,1,1,1,1,1,1,1,1,1,1,1,1,1
:endlayer
layer: 1
1,1,1,1,1,1,1,1,1,1,1,1,1,1,1,1,1,1,1,1,1,1,1,1,1,1,1,1,1,1,1,1,1,1,1,1,1,1,1
1,1,1,1,1,1,1,1,1,1,1,1,1,1,1,1,1,1,1,1,1,1,1,1,1,1,1,1,1,1,1,1,1,1,1,1,1,1,1
1,1,1,1,1,1,1,1,1,1,1,1,1,1,1,1,1,1,1,1,1,1,1,1,1,1,1,1,1,1,1,1,1,1,1,1,1,1,1
1,1,1,1,1,1,1,1,1,1,1,1,1,1,1,1,1,1,1,1,1,1,1,1,1,1,1,1,1,1,1,1,1,1,1,1,1,1,1
1,1,1,1,1,1,1,1,1,1,1,1,1,1,1,1,1,1,1,1,1,1,1,1,1,1,1,1,1,1,1,1,1,1,1,1,1,1,1
1,1,1,1,1,1,1,1,1,1,1,1,1,1,1,1,1,1,1,1,1,1,1,1,1,1,1,1,1,1,1,1,1,1,1,1,1,1,1
1,1,1,1,1,1,1,1,1,1,1,1,1,1,1,1,1,1,1,1,1,1,1,1,1,1,1,1,1,1,1,1,1,1,1,1,1,1,1
1,1,1,1,1,1,1,1,1,1,1,1,1,1,1,1,1,1,1,1,1,1,1,1,1,1,1,1,1,1,1,1,1,1,1,1,1,1,1
1,1,1,1,1,1,1,1,1,1,1,1,1,1,1,1,1,1,1,1,1,1,1,1,1,1,1,1,1,1,1,1,1,1,1,1,1,1,1
1,1,1,1,1,1,1,1,1,1,1,1,1,1,1,1,1,1,1,1,1,1,1,1,1,1,1,1,1,1,1,1,1,1,1,1,1,1,1
1,1,1,1,1,1,1,1,1,1,1,1,1,1,1,1,1,1,1,1,1,1,1,1,1,1,1,1,1,1,1,1,1,1,1,1,1,1,1
1,1,1,1,1,1,1,1,1,1,1,1,1,1,1,1,1,1,1,1,1,1,1,1,1,1,1,1,1,1,1,1,1,1,1,1,1,1,1
1,1,1,1,1,1,1,1,1,1,1,1,1,1,1,1,1,1,1,1,1,1,1,1,1,1,1,1,1,1,1,1,1,1,1,1,1,1,1
1,1,1,1,1,1,1,1,1,1,1,1,1,1,1,1,1,1,1,1,1,1,1,1,1,1,1,1,1,1,1,1,1,1,1,1,1,1,1
1,1,1,1,1,1,1,1,1,1,1,1,1,1,1,1,1,1,1,1,1,1,1,1,1,1,1,1,1,1,1,1,1,1,1,1,1,1,1
1,1,1,1,1,1,1,1,1,1,1,1,1,1,1,1,1,1,1,1,1,1,1,1,1,1,1,1,1,1,1,1,1,1,1,1,1,1,1
1,1,1,1,1,1,1,1,1,1,1,1,1,1,1,1,1,1,1,1,1,1,1,1,1,1,1,1,1,1,1,1,1,1,1,1,1,1,1
1,1,1,1,1,1,1,1,1,1,1,1,1,1,1,1,1,1,1,1,1,1,1,1,1,1,1,1,1,1,1,1,1,1,1,1,1,1,1
1,1,1,1,1,1,1,1,1,1,1,1,1,1,1,1,1,1,1,1,1,1,1,1,1,1,1,1,1,1,1,1,1,1,1,1,1,1,1
1,1,1,1,1,1,1,1,1,1,1,1,1,1,1,1,1,1,1,1,1,1,1,1,1,1,1,1,1,1,1,1,1,1,1,1,1,1,1
1,1,1,1,1,1,1,1,1,1,1,1,1,1,1,1,1,1,1,1,1,1,1,1,1,1,1,1,1,1,1,1,1,1,1,1,1,1,1
1,1,1,1,1,1,1,1,1,1,1,1,1,1,1,1,1,1,1,1,1,1,1,1,1,1,1,1,1,1,1,1,1,1,1,1,1,1,1
1,1,1,1,1,1,1,1,1,1,1,1,1,1,1,1,1,1,1,1,1,1,1,1,1,1,1,1,1,1,1,1,1,1,1,1,1,1,1
1,1,1,1,1,1,1,1,1,1,1,1,1,1,1,1,1,1,1,1,1,1,1,1,1,1,1,1,1,1,1,1,1,1,1,1,1,1,1
1,1,1,1,1,1,1,1,1,1,1,1,1,1,1,1,1,1,1,1,1,1,1,1,1,1,1,1,1,1,1,1,1,1,1,1,1,1,1
1,1,1,1,1,1,1,1,1,1,1,1,1,1,1,1,1,1,1,1,1,1,1,1,1,1,1,1,1,1,1,1,1,1,1,1,1,1,1
1,1,1,1,1,1,1,1,1,1,1,1,1,1,1,1,1,1,1,1,1,1,1,1,1,1,1,1,1,1,1,1,1,1,1,1,1,1,1
1,1,1,1,1,1,1,1,1,1,1,1,1,1,1,1,1,1,1,1,1,1,1,1,1,1,1,1,1,1,1,1,1,1,1,1,1,1,1
1,1,1,1,1,1,1,1,1,1,1,1,1,1,1,1,1,1,1,1,1,1,1,1,1,1,1,1,1,1,1,1,1,1,1,1,1,1,1
:endlayer
layer: 2
1,1,1,1,1,1,1,1,1,1,1,1,1,1,1,1,1,1,1,1,1,1,1,1,1,1,1,1,1,1,1,1,1,1,1,1,1,1,1
1,1,1,1,1,1,1,1,1,1,1,1,1,1,1,1,1,1,1,1,1,1,1,1,4,4,4,4,4,4,4,4,4,4,4,4,4,4,1
1,1,2,2,2,2,2,2,2,2,2,2,2,2,2,2,2,2,2,2,2,2,2,1,4,4,4,4,4,4,4,4,4,4,4,4,4,4,1
1,1,2,1,1,1,1,1,1,1,1,1,1,1,1,1,1,1,1,1,1,1,2,1,4,4,4,4,4,4,4,4,4,4,4,4,4,4,1
1,1,2,1,1,1,1,1,1,1,1,1,1,1,1,1,1,1,1,1,1,1,2,1,4,4,4,4,4,4,4,4,4,4,4,4,4,4,1
1,1,2,1,1,1,1,1,1,1,1,1,1,1,1,1,1,1,1,1,1,1,2,1,4,4,4,4,4,4,4,4,4,4,4,4,4,4,1
1,1,2,1,1,1,1,1,1,1,1,1,1,1,1,1,1,1,1,1,1,1,2,1,4,4,4,4,4,4,4,4,4,4,4,4,4,4,1
1,1,2,1,1,1,1,1,1,1,1,1,1,1,1,1,1,1,1,1,1,1,2,1,4,4,4,4,4,4,4,4,4,4,4,4,4,4,1
1,1,2,1,1,1,1,1,1,1,1,1,1,1,1,1,1,1,1,1,1,1,2,1,4,4,4,4,4,4,4,4,4,4,4,4,4,4,1
1,1,2,1,1,1,1,1,1,1,1,1,1,1,1,1,1,1,1,1,1,1,2,1,4,4,4,4,4,4,4,4,4,4,4,4,4,4,1
1,1,2,1,1,1,1,1,1,1,1,1,1,1,1,1,1,1,1,1,1,1,2,1,4,4,4,4,4,4,4,4,4,4,4,4,4,4,1
1,1,2,1,1,1,1,1,1,1,1,1,1,1,1,1,1,1,1,1,1,1,2,1,4,4,4,4,4,4,4,4,4,4,4,4,4,4,1
1,1,2,1,1,1,1,1,1,1,1,1,1,1,1,1,1,1,1,1,1,1,2,1,4,4,4,4,4,4,4,4,4,4,4,4,4,4,1
1,1,2,1,1,1,1,1,1,1,1,1,1,1,1,1,1,1,1,1,1,1,2,1,4,4,4,4,4,4,4,4,4,4,4,4,4,4,1
1,1,2,1,1,1,1,1,1,1,1,1,1,1,1,1,1,1,1,1,1,1,2,1,1,1,1,1,1,1,1,1,1,1,1,1,1,1,1
1,1,2,1,1,1,1,1,1,1,1,1,1,1,1,1,1,1,1,1,1,1,2,1,1,1,1,1,1,1,1,1,1,1,1,1,1,1,1
1,1,2,1,1,1,1,1,1,1,1,1,1,1,1,1,1,1,1,1,1,1,2,1,1,1,1,1,1,1,1,1,1,1,1,1,1,1,1
1,1,2,1,1,1,1,1,1,1,1,1,1,1,1,1,1,1,1,1,1,1,2,1,3,1,1,1,1,1,1,1,1,1,1,1,1,1,1
1,1,2,1,1,1,1,1,1,1,1,1,1,1,1,1,1,1,1,1,1,1,2,1,1,1,1,1,1,1,1,1,1,1,1,1,1,1,1
1,1,2,1,1,1,1,1,1,1,1,1,1,1,1,1,1,1,1,1,1,1,2,1,1,1,1,1,1,1,1,1,1,1,1,1,1,1,1
1,1,2,1,1,1,1,1,1,1,1,1,1,1,1,1,1,1,1,1,1,1,2,1,1,1,1,1,1,1,1,1,1,1,1,1,1,1,1
1,1,2,1,1,1,1,1,1,1,1,1,1,1,1,1,1,1,1,1,1,1,2,1,1,1,1,1,1,1,1,1,1,1,1,1,1,1,1
1,1,2,1,1,1,1,1,1,1,1,1,1,1,1,1,1,1,1,1,1,1,2,1,1,1,1,1,1,1,1,1,1,1,1,1,1,1,1
1,1,2,1,1,1,1,1,1,1,1,1,1,1,1,1,1,1,1,1,1,1,2,1,1,1,1,1,1,1,1,1,1,1,1,1,1,1,1
1,1,2,1,1,1,1,1,1,1,1,1,1,1,1,1,1,1,1,1,1,1,2,1,1,1,1,1,1,1,1,1,1,1,1,1,1,1,1
1,1,2,1,1,1,1,1,1,1,1,1,1,1,1,1,1,1,1,1,1,1,2,1,1,1,1,1,1,1,1,1,1,1,1,1,1,1,1
1,1,2,2,2,2,2,2,2,2,2,2,2,2,2,2,2,2,2,2,2,2,2,1,1,1,1,1,1,1,1,1,1,1,1,1,1,1,1
1,1,1,1,1,1,1,1,1,1,1,1,1,1,1,1,1,1,1,1,1,1,1,1,1,1,1,1,1,1,1,1,1,1,1,1,1,1,1
1,1,1,1,1,1,1,1,1,1,1,1,1,1,1,1,1,1,1,1,1,1,1,1,1,1,1,1,1,1,1,1,1,1,1,1,1,1,1
:endlayer
layer: 3
2,2,2,2,2,2,2,2,2,2,2,2,2,2,2,2,2,2,2,2,2,2,2,2,5,2,2,2,2,2,2,2,2,2,2,2,2,2,2
2,2,2,2,2,2,2,2,2,2,2,2,2,2,2,2,2,2,2,2,2,2,2,2,5,2,2,2,2,2,2,2,2,2,2,2,2,2,2
2,2,6,6,6,6,6,6,6,6,6,6,6,6,6,6,6,6,6,6,6,6,6,2,5,5,1,1,1,1,1,1,1,1,1,1,1,2,2
2,2,6,1,1,1,1,1,1,1,1,1,1,1,1,1,1,1,1,1,1,1,6,2,5,5,1,1,1,1,1,1,1,1,1,1,1,2,2
2,2,6,1,1,1,1,2,2,1,2,2,1,2,2,1,2,2,1,1,1,1,6,2,5,5,1,1,1,1,1,1,1,1,1,1,1,2,2
2,2,6,1,1,1,1,2,2,1,2,2,1,2,2,1,2,2,1,1,1,1,6,2,5,5,1,1,1,1,1,1,1,1,1,1,1,2,2
2,2,6,1,1,1,1,2,2,1,2,2,1,2,2,1,2,2,1,1,1,1,6,2,5,5,1,1,1,1,1,1,1,1,1,1,1,2,2
2,2,6,1,1,1,1,2,2,1,2,2,1,2,2,1,2,2,1,1,1,1,6,2,5,5,1,1,1,1,1,1,1,1,1,1,1,2,2
2,2,6,1,1,1,1,2,2,1,2,2,1,2,2,1,2,1,1,1,1,1,6,2,5,5,5,5,5,5,5,1,10,10,10,10,1,2,2
2,2,6,1,1,1,1,2,2,1,2,2,1,2,2,1,1,2,1,1,1,1,6,2,5,5,5,5,5,5,5,1,10,10,10,10,1,2,2
2,2,6,1,1,1,1,2,2,1,2,2,1,2,2,1,2,2,1,1,1,1,6,2,5,5,5,5,5,5,5,4,10,10,10,10,1,2,2
2,2,6,1,1,1,1,1,1,1,1,1,1,1,1,1,1,1,1,1,1,1,6,2,5,5,5,5,5,5,5,1,10,10,10,10,1,2,2
5,5,6,1,1,1,1,1,1,1,1,1,1,1,1,1,1,1,1,1,1,1,6,5,5,5,5,5,5,5,5,1,1,1,1,1,1,2,2
2,2,6,1,1,1,1,1,1,1,1,1,1,1,1,1,1,1,1,1,1,1,6,2,5,5,5,5,5,5,5,5,5,5,5,5,2,2,2
2,2,6,1,2,2,2,2,2,2,2,1,1,1,2,2,2,2,2,2,2,1,6,2,5,5,5,5,5,5,5,5,5,5,5,5,2,2,2
2,2,6,1,2,2,2,2,2,2,2,1,1,1,2,2,2,2,2,2,2,1,6,2,5,5,5,5,5,5,5,5,5,5,5,5,2,2,2
2,2,6,1,1,1,1,1,1,1,1,1,1,1,1,1,1,1,1,1,1,1,6,2,5,5,5,5,5,5,5,5,5,5,5,5,5,5,5
2,2,6,1,2,2,2,2,2,2,2,1,1,1,2,2,2,2,2,2,2,1,6,2,5,5,5,5,5,5,5,5,5,5,5,5,2,2,2
2,2,6,1,1,1,2,2,1,1,1,1,1,1,1,1,1,1,1,1,1,1,6,2,5,5,5,5,5,5,5,5,5,5,5,5,2,2,2
2,2,6,1,1,1,2,1,2,1,1,1,1,1,1,1,1,1,1,1,1,1,6,2,5,5,8,4,4,4,8,4,4,4,4,4,4,2,2
2,2,6,1,2,2,2,2,2,2,2,1,1,1,2,2,2,2,2,2,2,1,6,2,5,5,4,4,4,4,4,4,4,4,4,9,4,2,2
2,2,6,1,2,2,2,2,2,2,2,1,1,1,2,2,2,2,2,2,2,1,6,2,5,5,4,4,4,4,4,4,4,4,4,7,4,2,2
2,2,6,1,2,1,1,1,2,1,1,1,1,1,1,1,2,1,1,2,1,1,6,2,5,5,4,0,4,4,4,4,4,4,4,7,4,2,2
2,2,6,1,2,2,2,2,2,2,2,1,1,1,2,2,2,2,1,2,2,1,6,2,5,5,8,4,4,4,4,4,4,4,4,7,4,2,2
2,2,6,1,2,2,2,2,2,2,2,1,1,1,2,1,1,2,2,2,1,1,6,2,5,5,1,4,4,4,1,4,4,4,4,7,4,2,2
2,2,6,1,1,1,1,1,1,1,1,1,1,1,1,1,1,1,1,1,1,1,6,2,5,5,1,4,4,4,1,4,4,4,4,7,4,2,2
2,2,6,6,6,6,6,6,6,6,6,6,6,6,6,6,6,6,6,6,6,6,6,2,5,5,1,1,4,1,1,4,4,4,4,4,4,2,2
2,2,2,2,2,2,2,2,2,2,2,2,5,2,2,2,2,2,2,2,2,2,2,2,5,2,2,2,2,2,2,2,5,2,2,2,2,2,2
2,2,2,2,2,2,2,2,2,2,2,2,5,2,2,2,2,2,2,2,2,2,2,2,5,2,2,2,2,2,2,2,5,2,2,2,2,2,2
:endlayer
layer: 4
11,11,11,0,0,0,0,0,0,11,11,11,11,0,0,0,0,0,0,0,11,37,11,11,0,0,0,0,0,11,11,11,0,0,0,0,11,11,0
11,12,12,12,12,12,12,12,12,12,12,12,12,12,12,12,12,12,12,12,12,12,12,12,14,12,12,0,11,11,11,11,11,0,0,11,11,11,0
0,12,0,0,0,0,0,0,0,0,0,0,0,0,0,0,0,0,0,0,0,0,0,12,0,0,8,8,8,8,8,8,8,8,8,8,8,11,11
0,12,0,8,8,8,8,8,8,8,8,8,8,8,8,8,8,8,8,8,8,8,0,12,0,0,8,10,10,10,10,10,10,10,10,10,8,0,11
0,12,0,8,33,1,2,21,21,6,21,21,21,21,21,6,21,21,21,2,2,8,0,12,0,0,8,10,10,10,10,10,10,10,10,10,8,0,0
0,12,0,8,2,2,2,21,21,6,21,21,21,21,21,6,21,21,21,2,1,8,0,12,0,0,8,10,10,10,10,10,10,10,10,10,8,0,0
0,12,0,8,33,2,2,21,21,6,21,21,21,21,21,6,21,21,21,2,33,8,0,12,0,0,8,10,10,10,10,10,10,10,10,10,8,0,0
11,12,0,8,1,2,2,21,21,6,21,21,21,21,21,6,21,21,21,2,1,8,0,12,0,0,8,8,8,8,8,8,10,36,10,10,8,11,0
11,12,0,8,33,2,2,21,21,6,21,21,21,21,21,6,21,21,21,2,33,8,0,12,0,0,0,0,0,0,0,8,0,0,0,18,8,0,11
11,12,0,8,1,2,2,21,21,6,21,21,21,21,21,6,21,21,21,2,1,8,0,12,0,0,0,0,0,0,0,8,0,35,0,34,8,11,11
11,12,0,8,33,2,2,21,21,6,21,21,21,21,21,6,21,21,21,2,33,8,0,12,0,0,0,0,0,0,0,32,0,0,0,10,8,11,11
0,12,12,8,2,2,2,21,21,2,21,21,2,21,21,2,21,21,21,2,2,8,12,12,0,0,0,0,0,0,0,8,0,0,31,10,8,11,11
0,25,17,8,5,5,5,5,5,5,5,5,5,5,5,5,5,5,5,5,5,8,17,0,0,0,0,0,0,0,12,8,8,8,8,8,8,0,0
11,12,12,8,21,21,21,21,21,21,21,5,5,5,21,21,21,21,21,21,21,8,12,12,0,0,0,0,0,0,0,0,0,0,0,0,12,0,0
11,12,0,8,21,21,21,21,21,21,21,21,5,21,21,21,21,21,21,21,21,8,0,12,0,0,0,0,0,0,0,0,0,0,30,0,12,0,0
11,12,0,8,21,21,21,21,21,21,21,21,5,21,21,21,21,21,21,21,21,8,0,12,0,0,0,0,0,0,0,0,0,0,0,0,12,0,0
11,12,0,8,6,6,6,6,6,6,6,2,5,2,6,6,6,6,6,6,6,8,0,12,0,0,0,0,0,0,0,0,0,0,29,0,28,0,0
0,12,0,8,21,21,21,21,21,21,21,21,5,21,21,21,21,21,21,21,21,8,0,12,0,0,0,0,0,0,0,0,0,0,0,0,12,0,0
0,12,0,8,21,21,21,21,21,21,21,21,5,21,21,21,21,21,21,21,21,8,0,12,0,0,0,0,0,0,0,0,0,0,0,0,12,0,0
0,12,0,8,21,21,21,21,21,21,21,21,5,21,21,21,21,21,21,21,21,8,0,12,0,0,8,16,16,16,8,0,0,0,8,12,8,0,0
0,12,0,8,21,21,21,21,21,21,21,21,5,21,21,21,21,21,21,21,21,8,0,12,0,0,16,4,27,0,16,0,0,7,12,0,12,11,11
0,12,0,8,21,21,21,21,21,21,21,21,5,21,21,21,21,21,21,21,21,8,0,12,0,0,16,4,4,0,16,0,0,9,12,0,12,0,11
11,12,0,8,6,6,6,6,6,6,6,2,5,2,6,6,6,6,6,6,6,8,0,12,0,0,16,26,0,0,16,0,0,0,25,0,12,11,11
11,12,0,8,21,21,21,21,21,21,21,21,5,21,21,21,21,21,2,21,21,8,0,12,0,0,16,0,24,0,23,0,0,22,12,0,12,11,11
11,12,0,8,21,21,21,21,21,21,21,21,5,21,21,2,2,21,21,21,2,8,0,12,0,0,16,0,0,0,16,20,0,0,12,0,12,0,0
0,12,0,8,8,8,8,8,8,8,8,8,8,8,8,8,8,8,8,8,8,8,0,12,0,0,16,19,18,0,16,0,0,0,12,0,12,0,0
0,12,0,0,0,0,0,0,0,0,0,12,17,12,0,0,0,0,0,0,0,0,0,12,0,0,8,16,16,16,8,12,15,12,8,12,8,0,0
0,12,12,12,12,12,12,12,12,12,12,12,14,12,12,12,12,12,12,12,12,12,12,12,13,12,12,0,11,0,0,11,0,0,11,11,0,0,0
0,0,0,11,11,0,11,0,0,0,0,0,0,0,0,11,11,11,11,11,0,0,0,0,0,0,0,11,11,11,11,0,0,0,11,11,11,0,0
:endlayer
layer: 5
0,0,0,0,0,0,0,0,0,0,0,0,0,0,0,0,0,0,0,0,0,0,0,0,0,0,0,0,0,0,0,0,0,0,0,0,0,0,0
0,39,0,0,0,0,0,39,0,0,0,0,39,0,0,0,0,39,0,0,0,0,0,39,0,0,0,0,0,0,0,0,0,0,0,0,0,0,0
0,0,0,0,0,0,0,0,0,0,0,0,0,0,0,0,0,0,0,0,0,0,0,0,0,0,8,16,16,16,16,8,16,16,16,16,8,0,0
0,0,0,12,12,12,12,12,12,12,12,12,12,12,12,12,12,12,12,12,12,12,0,0,0,0,16,18,0,64,64,16,0,0,0,36,16,0,0
0,0,0,12,51,54,0,42,42,0,44,44,44,44,44,0,42,42,42,0,63,12,0,0,0,0,16,62,0,0,0,16,0,0,61,12,16,0,0
0,0,0,12,0,0,0,42,42,0,44,44,44,44,44,0,42,42,42,0,53,12,0,0,0,0,16,60,0,0,0,23,0,0,0,59,16,0,0
0,39,0,12,51,58,0,42,42,0,44,44,44,44,44,0,42,42,42,0,50,12,0,39,0,0,16,57,55,56,55,16,0,0,0,0,16,0,0
0,0,0,12,54,0,0,42,42,0,44,44,44,44,44,0,42,42,42,0,53,12,0,0,0,0,8,16,16,16,16,8,16,0,16,16,8,0,0
0,0,0,12,51,0,0,42,42,0,44,44,44,44,44,0,42,42,42,0,50,12,0,0,0,0,0,0,0,0,0,16,38,0,0,0,16,0,0
0,0,0,12,54,0,0,42,42,0,44,44,44,44,44,0,42,42,42,0,53,12,0,0,0,0,0,0,0,0,0,16,0,0,0,52,16,0,0
0,0,0,12,51,0,0,42,42,0,44,44,44,44,44,0,42,0,42,0,50,12,0,0,0,0,0,0,0,0,0,43,0,0,0,36,16,0,0
0,39,0,12,0,0,0,42,42,39,44,44,49,44,44,39,42,0,42,0,0,12,0,39,0,0,0,0,0,0,0,16,0,0,0,0,16,0,0
0,0,48,25,0,0,0,0,0,0,0,0,0,0,0,0,0,47,0,0,0,46,0,0,0,0,0,0,0,0,39,8,16,16,16,16,8,0,0
0,39,0,12,42,42,42,42,42,42,42,12,0,12,44,44,44,44,44,44,44,12,0,39,0,0,0,0,0,0,0,0,0,0,0,0,0,0,0
0,0,0,12,42,42,42,42,42,42,42,42,0,44,44,44,44,44,44,44,44,12,0,0,0,0,0,0,0,0,0,0,0,0,0,0,0,0,0
0,0,0,12,42,42,42,42,42,42,0,0,0,44,44,44,44,44,44,44,44,12,0,0,0,0,0,0,0,0,0,0,0,0,0,0,39,0,0
0,0,0,12,0,0,0,0,0,0,0,39,0,39,0,0,0,0,0,0,0,12,0,0,0,0,0,0,0,0,0,0,0,0,0,0,0,0,0
0,0,0,12,44,44,44,44,44,44,44,44,0,44,44,44,44,44,44,44,44,12,0,0,0,0,0,0,0,0,0,0,0,0,0,0,39,0,0
0,0,0,12,44,44,44,44,44,44,44,44,0,44,44,44,44,44,44,44,44,12,0,0,0,0,45,0,0,0,45,0,0,0,0,0,0,0,0
0,39,0,12,44,44,44,44,44,44,44,44,0,44,44,44,44,44,44,44,44,12,0,39,0,0,8,16,12,16,8,0,0,0,8,12,8,0,0
0,0,0,12,44,44,44,44,0,44,44,44,0,44,44,44,44,44,44,44,44,12,0,0,0,40,16,4,0,0,16,0,0,7,12,0,12,0,0
0,0,0,12,44,44,44,44,44,44,44,44,0,44,44,44,44,44,44,44,44,12,0,0,0,0,16,26,4,0,16,0,0,0,12,0,12,0,0
0,0,0,12,0,0,0,0,0,0,0,39,0,39,0,0,0,0,0,0,0,12,0,0,0,0,12,0,0,0,16,0,0,0,0,0,12,0,0
0,0,0,12,42,42,42,42,42,42,42,0,0,42,42,0,0,42,0,0,0,12,0,0,0,0,12,0,0,0,43,0,0,0,12,0,12,0,0
0,0,0,12,42,42,42,42,42,42,42,0,0,42,42,0,0,42,42,0,41,12,0,0,0,0,16,0,0,0,16,0,0,0,12,0,12,0,0
0,0,0,12,12,12,12,12,12,12,12,12,14,12,12,12,12,12,12,12,12,12,0,0,0,40,16,0,0,0,16,0,0,0,12,0,12,0,0
0,0,0,0,0,0,0,0,0,0,0,0,0,0,0,0,0,0,0,0,0,0,0,0,0,0,8,16,12,16,8,0,0,0,8,12,8,0,0
0,39,0,0,0,0,0,39,0,0,0,39,0,39,0,0,0,39,0,0,0,0,0,39,0,0,38,0,0,0,38,0,0,0,0,0,0,0,0
0,0,0,0,0,0,0,0,0,0,0,0,0,0,0,0,0,0,0,0,0,0,0,0,0,0,0,0,0,0,0,0,0,0,0,0,0,0,0
:endlayer
layer: 6
0,0,0,0,0,0,0,0,0,0,0,0,0,0,0,0,0,0,0,0,0,0,0,0,0,0,0,0,0,0,0,0,0,0,0,0,0,0,0
0,0,0,0,0,0,0,0,0,0,0,0,0,0,0,0,0,0,0,0,0,0,0,0,0,0,0,0,0,0,0,0,0,0,0,0,0,0,0
0,0,0,0,0,0,0,0,0,0,0,0,0,0,0,0,0,0,0,0,0,0,0,0,0,0,8,16,16,16,16,8,16,67,67,16,8,0,0
0,0,0,39,0,0,0,0,0,0,0,0,39,0,0,0,0,0,0,0,0,39,0,0,0,0,16,0,0,0,0,16,38,0,0,0,16,0,0
0,0,0,0,0,0,0,0,0,0,0,0,0,0,0,0,0,0,0,0,0,0,0,0,0,0,16,0,0,0,0,16,0,0,0,68,16,0,0
0,0,0,0,0,0,0,0,0,0,0,0,0,0,0,0,0,0,0,0,0,0,0,0,0,0,16,0,0,0,0,43,0,0,0,40,16,0,0
0,0,0,0,0,0,0,0,0,0,0,0,0,0,0,0,0,0,0,0,0,0,0,0,0,0,16,0,0,0,0,16,0,0,0,0,16,0,0
0,0,0,0,0,0,0,0,0,0,0,0,0,0,0,0,0,0,0,0,0,0,0,0,0,0,8,16,16,16,16,8,16,0,16,16,8,0,0
0,0,0,0,0,0,0,0,0,0,0,0,0,0,0,0,0,0,0,0,0,0,0,0,0,0,0,0,0,0,0,16,0,0,0,0,16,0,0
0,0,0,0,0,0,0,0,0,0,0,0,0,0,0,0,0,0,0,0,0,0,0,0,0,0,0,0,0,0,0,16,0,0,0,36,16,0,0
0,0,0,0,0,0,0,0,0,0,0,0,0,0,0,0,0,0,0,0,0,0,0,0,0,0,0,0,0,0,0,16,0,0,0,0,16,0,0
0,0,0,39,0,0,0,0,0,0,0,0,0,0,0,0,0,0,0,0,0,39,0,0,0,0,0,0,0,0,0,16,0,0,0,0,16,0,0
0,0,0,0,0,0,0,0,0,0,0,0,0,0,0,0,0,0,0,0,0,0,0,0,0,0,0,0,0,0,0,8,16,67,67,16,8,0,0
0,0,0,39,0,0,0,0,0,0,0,39,0,39,0,0,0,0,0,0,0,39,0,0,0,0,0,0,0,0,0,0,0,0,0,0,0,0,0
0,0,0,0,0,0,0,0,0,0,0,0,0,0,0,0,0,0,0,0,0,0,0,0,0,0,0,0,0,0,0,0,0,0,0,0,0,0,0
0,0,0,0,0,0,0,0,0,0,0,0,0,0,0,0,0,0,0,0,0,0,0,0,0,0,0,0,0,0,0,0,0,0,0,0,0,0,0
0,0,0,0,0,0,0,0,0,0,0,0,0,0,0,0,0,0,0,0,0,0,0,0,0,0,0,0,0,0,0,0,0,0,0,0,0,0,0
0,0,0,0,0,0,0,0,0,0,0,0,0,0,0,0,0,0,0,0,0,0,0,0,0,0,0,0,0,0,0,0,0,0,0,0,0,0,0
0,0,0,0,0,0,0,0,0,0,0,0,0,0,0,0,0,0,0,0,0,0,0,0,0,0,0,0,0,0,0,0,0,0,0,0,45,0,0
0,0,0,39,0,0,0,0,0,0,0,0,0,0,0,0,0,0,0,0,0,39,0,0,0,0,8,16,16,16,8,0,0,0,8,12,8,65,0
0,0,0,0,0,0,0,0,0,0,0,0,0,0,0,0,0,0,0,0,0,0,0,0,0,0,16,0,66,40,16,0,0,0,0,0,12,0,0
0,0,0,0,0,0,0,0,0,0,0,0,0,0,0,0,0,0,0,0,0,0,0,0,0,0,16,0,4,0,16,0,0,0,0,0,12,0,0
0,0,0,0,0,0,0,0,0,0,0,0,0,0,0,0,0,0,0,0,0,0,0,0,0,0,16,0,0,0,16,0,0,0,0,0,12,0,0
0,0,0,0,0,0,0,0,0,0,0,0,0,0,0,0,0,0,0,0,0,0,0,0,0,0,16,0,0,0,16,65,0,0,0,0,12,0,0
0,0,0,0,0,0,0,0,0,0,0,0,0,0,0,0,0,0,0,0,0,0,0,0,0,0,16,0,0,40,16,0,0,0,0,0,12,0,0
0,0,0,39,0,0,0,0,0,0,0,39,0,39,0,0,0,0,0,0,0,39,0,0,0,0,16,65,0,0,16,0,0,0,0,0,12,0,0
0,0,0,0,0,0,0,0,0,0,0,0,0,0,0,0,0,0,0,0,0,0,0,0,0,0,8,16,16,16,8,0,0,0,8,12,8,65,0
0,0,0,0,0,0,0,0,0,0,0,0,0,0,0,0,0,0,0,0,0,0,0,0,0,0,0,0,0,0,0,0,0,0,0,0,38,0,0
0,0,0,0,0,0,0,0,0,0,0,0,0,0,0,0,0,0,0,0,0,0,0,0,0,0,0,0,0,0,0,0,0,0,0,0,0,0,0
:endlayer
layer: 7
0,0,0,0,0,0,0,0,0,0,0,0,0,0,0,0,0,0,0,0,0,0,0,0,0,0,0,0,0,0,0,0,0,0,0,0,0,0,0
0,0,0,0,0,0,0,0,0,0,0,0,0,0,0,0,0,0,0,0,0,0,0,0,0,0,45,0,0,0,0,0,0,0,0,0,45,0,0
0,0,0,0,0,0,0,0,0,0,0,0,0,0,0,0,0,0,0,0,0,0,0,0,0,40,8,16,16,16,16,8,16,16,16,16,8,65,0
0,0,0,0,0,0,0,0,0,0,0,0,0,0,0,0,0,0,0,0,0,0,0,0,0,0,16,0,0,0,0,16,0,0,0,0,16,0,0
0,0,0,0,0,0,0,0,0,0,0,0,0,0,0,0,0,0,0,0,0,0,0,0,0,0,16,0,0,0,0,16,0,0,0,0,16,0,0
0,0,0,0,0,0,0,0,0,0,0,0,0,0,0,0,0,0,0,0,0,0,0,0,0,0,16,0,0,0,0,16,0,0,0,0,16,0,0
0,0,0,0,0,0,0,0,0,0,0,0,0,0,0,0,0,0,0,0,0,0,0,0,0,0,16,0,0,0,0,16,0,0,0,0,16,0,0
0,0,0,0,0,0,0,0,0,0,0,0,0,0,0,0,0,0,0,0,0,0,0,0,0,40,8,16,16,16,16,8,16,16,16,16,8,0,0
0,0,0,0,0,0,0,0,0,0,0,0,0,0,0,0,0,0,0,0,0,0,0,0,0,0,38,0,0,0,0,16,10,10,10,36,16,0,0
0,0,0,0,0,0,0,0,0,0,0,0,0,0,0,0,0,0,0,0,0,0,0,0,0,0,0,0,0,0,0,16,0,0,0,0,16,0,0
0,0,0,0,0,0,0,0,0,0,0,0,0,0,0,0,0,0,0,0,0,0,0,0,0,0,0,0,0,0,40,16,0,0,0,0,16,0,0
0,0,0,0,0,0,0,0,0,0,0,0,0,0,0,0,0,0,0,0,0,0,0,0,0,0,0,0,0,0,0,16,0,0,0,0,16,0,0
0,0,0,0,0,0,0,0,0,0,0,0,0,0,0,0,0,0,0,0,0,0,0,0,0,0,0,0,0,0,40,8,16,16,16,16,8,65,0
0,0,0,0,0,0,0,0,0,0,0,0,0,0,0,0,0,0,0,0,0,0,0,0,0,0,0,0,0,0,0,38,0,0,0,0,38,0,0
0,0,0,0,0,0,0,0,0,0,0,0,0,0,0,0,0,0,0,0,0,0,0,0,0,0,0,0,0,0,0,0,0,0,0,0,0,0,0
0,0,0,0,0,0,0,0,0,0,0,0,0,0,0,0,0,0,0,0,0,0,0,0,0,0,0,0,0,0,0,0,0,0,0,0,0,0,0
0,0,0,0,0,0,0,0,0,0,0,0,0,0,0,0,0,0,0,0,0,0,0,0,0,0,0,0,0,0,0,0,0,0,0,0,0,0,0
0,0,0,0,0,0,0,0,0,0,0,0,0,0,0,0,0,0,0,0,0,0,0,0,0,0,0,0,0,0,0,0,0,0,0,0,0,0,0
0,0,0,0,0,0,0,0,0,0,0,0,0,0,0,0,0,0,0,0,0,0,0,0,0,31,0,0,0,0,0,0,0,0,0,70,69,17,0
0,0,0,0,0,0,0,0,0,0,0,0,0,0,0,0,0,0,0,0,0,0,0,0,0,31,71,71,71,71,71,71,71,71,71,12,69,17,0
0,0,0,0,0,0,0,0,0,0,0,0,0,0,0,0,0,0,0,0,0,0,0,0,0,31,8,0,0,66,4,4,4,4,16,0,69,17,0
0,0,0,0,0,0,0,0,0,0,0,0,0,0,0,0,0,0,0,0,0,0,0,0,0,31,8,0,4,4,4,4,4,4,16,0,69,17,0
0,0,0,0,0,0,0,0,0,0,0,0,0,0,0,0,0,0,0,0,0,0,0,0,0,31,8,0,4,4,4,4,4,4,16,0,69,17,0
0,0,0,0,0,0,0,0,0,0,0,0,0,0,0,0,0,0,0,0,0,0,0,0,0,31,8,4,4,4,4,4,4,4,16,0,69,17,0
0,0,0,0,0,0,0,0,0,0,0,0,0,0,0,0,0,0,0,0,0,0,0,0,0,31,8,4,4,4,4,4,4,4,16,0,69,17,0
0,0,0,0,0,0,0,0,0,0,0,0,0,0,0,0,0,0,0,0,0,0,0,0,0,31,8,4,4,4,4,4,4,4,16,0,69,17,0
0,0,0,0,0,0,0,0,0,0,0,0,0,0,0,0,0,0,0,0,0,0,0,0,0,31,71,71,71,71,71,71,71,71,71,12,69,17,0
0,0,0,0,0,0,0,0,0,0,0,0,0,0,0,0,0,0,0,0,0,0,0,0,0,31,0,0,0,0,0,0,0,0,0,70,69,17,0
0,0,0,0,0,0,0,0,0,0,0,0,0,0,0,0,0,0,0,0,0,0,0,0,0,0,0,0,0,0,0,0,0,0,0,0,0,0,0
:endlayer
layer: 8
0,0,0,0,0,0,0,0,0,0,0,0,0,0,0,0,0,0,0,0,0,0,0,0,0,0,0,0,0,0,0,0,0,0,0,0,0,0,0
0,0,0,0,0,0,0,0,0,0,0,0,0,0,0,0,0,0,0,0,0,0,0,0,0,59,59,59,59,59,59,59,59,59,59,59,59,76,0
0,0,0,0,0,0,0,0,0,0,0,0,0,0,0,0,0,0,0,0,0,0,0,0,0,0,8,8,8,8,8,8,8,8,8,8,8,69,0
0,0,0,0,0,0,0,0,0,0,0,0,0,0,0,0,0,0,0,0,0,0,0,0,0,0,8,0,0,0,0,8,10,10,10,10,8,69,0
0,0,0,0,0,0,0,0,0,0,0,0,0,0,0,0,0,0,0,0,0,0,0,0,0,0,8,0,0,0,0,8,10,10,10,10,8,69,0
0,0,0,0,0,0,0,0,0,0,0,0,0,0,0,0,0,0,0,0,0,0,0,0,0,0,8,0,0,0,0,8,10,10,10,10,8,69,0
0,0,0,0,0,0,0,0,0,0,0,0,0,0,0,0,0,0,0,0,0,0,0,0,0,0,8,0,0,0,0,8,10,10,10,10,8,69,0
0,0,0,0,0,0,0,0,0,0,0,0,0,0,0,0,0,0,0,0,0,0,0,0,0,0,8,8,8,8,8,8,8,36,36,8,8,69,0
0,0,0,0,0,0,0,0,0,0,0,0,0,0,0,0,0,0,0,0,0,0,0,0,0,36,36,36,36,36,10,8,0,0,0,0,8,69,0
0,0,0,0,0,0,0,0,0,0,0,0,0,0,0,0,0,0,0,0,0,0,0,0,0,0,0,0,0,0,31,8,0,0,0,0,8,69,0
0,0,0,0,0,0,0,0,0,0,0,0,0,0,0,0,0,0,0,0,0,0,0,0,0,0,0,0,0,0,31,8,0,0,0,0,8,69,0
0,0,0,0,0,0,0,0,0,0,0,0,0,0,0,0,0,0,0,0,0,0,0,0,0,0,0,0,0,0,31,8,0,0,0,0,8,69,0
0,0,0,0,0,0,0,0,0,0,0,0,0,0,0,0,0,0,0,0,0,0,0,0,0,0,0,0,0,0,31,8,8,8,8,8,8,69,0
0,0,0,0,0,0,0,0,0,0,0,0,0,0,0,0,0,0,0,0,0,0,0,0,0,0,0,0,0,0,31,76,76,76,76,76,76,69,0
0,0,0,0,0,0,0,0,0,0,0,0,0,0,0,0,0,0,0,0,0,0,0,0,0,0,0,0,0,0,0,0,0,0,0,0,0,0,0
0,0,0,0,0,0,0,0,0,0,0,0,0,0,0,0,0,0,0,0,0,0,0,0,0,0,0,0,0,0,0,0,0,0,0,0,0,0,0
0,0,0,0,0,0,0,0,0,0,0,0,0,0,0,0,0,0,0,0,0,0,0,0,0,0,0,0,0,0,0,0,0,0,0,0,0,0,0
0,0,0,0,0,0,0,0,0,0,0,0,0,0,0,0,0,0,0,0,0,0,0,0,0,0,0,0,0,0,0,0,0,0,0,0,0,0,0
0,0,0,0,0,0,0,0,0,0,0,0,0,0,0,0,0,0,0,0,0,0,0,0,0,0,31,0,0,0,0,0,0,0,0,69,0,0,0
0,0,0,0,0,0,0,0,0,0,0,0,0,0,0,0,0,0,0,0,0,0,0,0,0,0,31,16,16,16,16,16,16,16,16,69,0,0,0
0,0,0,0,0,0,0,0,0,0,0,0,0,0,0,0,0,0,0,0,0,0,0,0,0,0,31,0,0,0,0,0,0,75,16,69,0,0,0
0,0,0,0,0,0,0,0,0,0,0,0,0,0,0,0,0,0,0,0,0,0,0,0,0,0,31,0,12,12,0,0,0,0,16,69,0,0,0
0,0,0,0,0,0,0,0,0,0,0,0,0,0,0,0,0,0,0,0,0,0,0,0,0,0,31,0,12,0,0,0,74,73,16,69,0,0,0
0,0,0,0,0,0,0,0,0,0,0,0,0,0,0,0,0,0,0,0,0,0,0,0,0,0,31,12,12,0,0,0,74,73,16,69,0,0,0
0,0,0,0,0,0,0,0,0,0,0,0,0,0,0,0,0,0,0,0,0,0,0,0,0,0,31,0,0,0,0,0,0,0,16,69,0,0,0
0,0,0,0,0,0,0,0,0,0,0,0,0,0,0,0,0,0,0,0,0,0,0,0,0,0,31,0,0,0,0,59,0,72,16,69,0,0,0
0,0,0,0,0,0,0,0,0,0,0,0,0,0,0,0,0,0,0,0,0,0,0,0,0,0,31,16,16,16,16,16,16,16,16,69,0,0,0
0,0,0,0,0,0,0,0,0,0,0,0,0,0,0,0,0,0,0,0,0,0,0,0,0,0,31,0,0,0,0,0,0,0,0,69,0,0,0
0,0,0,0,0,0,0,0,0,0,0,0,0,0,0,0,0,0,0,0,0,0,0,0,0,0,0,0,0,0,0,0,0,0,0,0,0,0,0
:endlayer
layer: 9
0,0,0,0,0,0,0,0,0,0,0,0,0,0,0,0,0,0,0,0,0,0,0,0,0,0,0,0,0,0,0,0,0,0,0,0,0,0,0
0,0,0,0,0,0,0,0,0,0,0,0,0,0,0,0,0,0,0,0,0,0,0,0,0,0,0,0,0,0,0,0,0,0,0,0,0,0,0
0,0,0,0,0,0,0,0,0,0,0,0,0,0,0,0,0,0,0,0,0,0,0,0,0,59,59,59,59,59,59,59,59,59,59,59,76,0,0
0,0,0,0,0,0,0,0,0,0,0,0,0,0,0,0,0,0,0,0,0,0,0,0,0,0,8,0,0,0,0,8,12,12,12,12,69,0,0
0,0,0,0,0,0,0,0,0,0,0,0,0,0,0,0,0,0,0,0,0,0,0,0,0,0,67,0,0,0,0,12,80,79,78,12,69,0,0
0,0,0,0,0,0,0,0,0,0,0,0,0,0,0,0,0,0,0,0,0,0,0,0,0,0,67,0,0,0,0,12,77,0,0,12,69,0,0
0,0,0,0,0,0,0,0,0,0,0,0,0,0,0,0,0,0,0,0,0,0,0,0,0,0,8,0,0,0,0,8,12,0,0,12,69,0,0
0,0,0,0,0,0,0,0,0,0,0,0,0,0,0,0,0,0,0,0,0,0,0,0,0,36,36,36,36,36,36,10,8,0,0,8,69,0,0
0,0,0,0,0,0,0,0,0,0,0,0,0,0,0,0,0,0,0,0,0,0,0,0,0,0,0,0,0,0,0,31,0,0,0,0,69,0,0
0,0,0,0,0,0,0,0,0,0,0,0,0,0,0,0,0,0,0,0,0,0,0,0,0,0,0,0,0,0,0,31,0,0,0,0,69,0,0
0,0,0,0,0,0,0,0,0,0,0,0,0,0,0,0,0,0,0,0,0,0,0,0,0,0,0,0,0,0,0,31,0,0,0,0,69,0,0
0,0,0,0,0,0,0,0,0,0,0,0,0,0,0,0,0,0,0,0,0,0,0,0,0,0,0,0,0,0,0,31,0,0,0,0,69,0,0
0,0,0,0,0,0,0,0,0,0,0,0,0,0,0,0,0,0,0,0,0,0,0,0,0,0,0,0,0,0,0,31,8,67,67,8,69,0,0
0,0,0,0,0,0,0,0,0,0,0,0,0,0,0,0,0,0,0,0,0,0,0,0,0,0,0,0,0,0,0,31,0,0,0,0,69,0,0
0,0,0,0,0,0,0,0,0,0,0,0,0,0,0,0,0,0,0,0,0,0,0,0,0,0,0,0,0,0,0,0,0,0,0,0,0,0,0
0,0,0,0,0,0,0,0,0,0,0,0,0,0,0,0,0,0,0,0,0,0,0,0,0,0,0,0,0,0,0,0,0,0,0,0,0,0,0
0,0,0,0,0,0,0,0,0,0,0,0,0,0,0,0,0,0,0,0,0,0,0,0,0,0,0,0,0,0,0,0,0,0,0,0,0,0,0
0,0,0,0,0,0,0,0,0,0,0,0,0,0,0,0,0,0,0,0,0,0,0,0,0,0,0,0,0,0,0,0,0,0,0,0,0,0,0
0,0,0,0,0,0,0,0,0,0,0,0,0,0,0,0,0,0,0,0,0,0,0,0,0,0,0,31,0,0,0,0,0,0,69,0,0,0,0
0,0,0,0,0,0,0,0,0,0,0,0,0,0,0,0,0,0,0,0,0,0,0,0,0,0,0,31,16,16,12,12,16,16,69,0,0,0,0
0,0,0,0,0,0,0,0,0,0,0,0,0,0,0,0,0,0,0,0,0,0,0,0,0,0,0,31,38,0,0,0,0,38,69,0,0,0,0
0,0,0,0,0,0,0,0,0,0,0,0,0,0,0,0,0,0,0,0,0,0,0,0,0,0,0,31,0,0,0,0,0,0,69,0,0,0,0
0,0,0,0,0,0,0,0,0,0,0,0,0,0,0,0,0,0,0,0,0,0,0,0,0,0,0,31,0,0,0,0,0,0,69,0,0,0,0
0,0,0,0,0,0,0,0,0,0,0,0,0,0,0,0,0,0,0,0,0,0,0,0,0,0,0,31,0,0,0,0,0,0,69,0,0,0,0
0,0,0,0,0,0,0,0,0,0,0,0,0,0,0,0,0,0,0,0,0,0,0,0,0,0,0,31,0,0,0,0,0,0,69,0,0,0,0
0,0,0,0,0,0,0,0,0,0,0,0,0,0,0,0,0,0,0,0,0,0,0,0,0,0,0,31,0,0,0,0,0,45,69,0,0,0,0
0,0,0,0,0,0,0,0,0,0,0,0,0,0,0,0,0,0,0,0,0,0,0,0,0,0,0,31,16,16,12,12,16,16,69,0,0,0,0
0,0,0,0,0,0,0,0,0,0,0,0,0,0,0,0,0,0,0,0,0,0,0,0,0,0,0,31,0,0,0,0,0,0,69,0,0,0,0
0,0,0,0,0,0,0,0,0,0,0,0,0,0,0,0,0,0,0,0,0,0,0,0,0,0,0,0,0,0,0,0,0,0,0,0,0,0,0
:endlayer
layer: 10
0,0,0,0,0,0,0,0,0,0,0,0,0,0,0,0,0,0,0,0,0,0,0,0,0,0,0,0,0,0,0,0,0,0,0,0,0,0,0
0,0,0,0,0,0,0,0,0,0,0,0,0,0,0,0,0,0,0,0,0,0,0,0,0,0,0,0,0,0,0,0,0,0,0,0,0,0,0
0,0,0,0,0,0,0,0,0,0,0,0,0,0,0,0,0,0,0,0,0,0,0,0,0,0,0,0,0,0,0,0,0,0,0,0,0,0,0
0,0,0,0,0,0,0,0,0,0,0,0,0,0,0,0,0,0,0,0,0,0,0,0,0,59,59,59,59,59,59,59,59,59,59,76,0,0,0
0,0,0,0,0,0,0,0,0,0,0,0,0,0,0,0,0,0,0,0,0,0,0,0,0,81,8,0,0,0,0,8,65,0,0,69,0,0,0
0,0,0,0,0,0,0,0,0,0,0,0,0,0,0,0,0,0,0,0,0,0,0,0,0,81,8,0,0,0,0,8,0,0,0,69,0,0,0
0,0,0,0,0,0,0,0,0,0,0,0,0,0,0,0,0,0,0,0,0,0,0,0,0,36,36,36,36,36,36,36,10,0,0,69,0,0,0
0,0,0,0,0,0,0,0,0,0,0,0,0,0,0,0,0,0,0,0,0,0,0,0,0,0,0,0,0,0,0,0,31,0,0,69,0,0,0
0,0,0,0,0,0,0,0,0,0,0,0,0,0,0,0,0,0,0,0,0,0,0,0,0,0,0,0,0,0,0,0,31,0,0,69,0,0,0
0,0,0,0,0,0,0,0,0,0,0,0,0,0,0,0,0,0,0,0,0,0,0,0,0,0,0,0,0,0,0,0,31,0,0,69,0,0,0
0,0,0,0,0,0,0,0,0,0,0,0,0,0,0,0,0,0,0,0,0,0,0,0,0,0,0,0,0,0,0,0,31,0,0,69,0,0,0
0,0,0,0,0,0,0,0,0,0,0,0,0,0,0,0,0,0,0,0,0,0,0,0,0,0,0,0,0,0,0,0,31,0,0,69,0,0,0
0,0,0,0,0,0,0,0,0,0,0,0,0,0,0,0,0,0,0,0,0,0,0,0,0,0,0,0,0,0,0,0,31,8,8,69,0,0,0
0,0,0,0,0,0,0,0,0,0,0,0,0,0,0,0,0,0,0,0,0,0,0,0,0,0,0,0,0,0,0,0,31,81,81,69,0,0,0
0,0,0,0,0,0,0,0,0,0,0,0,0,0,0,0,0,0,0,0,0,0,0,0,0,0,0,0,0,0,0,0,0,0,0,0,0,0,0
0,0,0,0,0,0,0,0,0,0,0,0,0,0,0,0,0,0,0,0,0,0,0,0,0,0,0,0,0,0,0,0,0,0,0,0,0,0,0
0,0,0,0,0,0,0,0,0,0,0,0,0,0,0,0,0,0,0,0,0,0,0,0,0,0,0,0,0,0,0,0,0,0,0,0,0,0,0
0,0,0,0,0,0,0,0,0,0,0,0,0,0,0,0,0,0,0,0,0,0,0,0,0,0,0,0,0,0,0,0,0,0,0,0,0,0,0
0,0,0,0,0,0,0,0,0,0,0,0,0,0,0,0,0,0,0,0,0,0,0,0,0,0,0,0,31,0,45,45,0,69,0,0,0,0,0
0,0,0,0,0,0,0,0,0,0,0,0,0,0,0,0,0,0,0,0,0,0,0,0,0,0,0,0,31,16,16,16,16,69,0,0,0,0,0
0,0,0,0,0,0,0,0,0,0,0,0,0,0,0,0,0,0,0,0,0,0,0,0,0,0,0,0,31,0,0,0,0,69,0,0,0,0,0
0,0,0,0,0,0,0,0,0,0,0,0,0,0,0,0,0,0,0,0,0,0,0,0,0,0,0,0,31,0,0,0,0,69,0,0,0,0,0
0,0,0,0,0,0,0,0,0,0,0,0,0,0,0,0,0,0,0,0,0,0,0,0,0,0,0,0,31,0,0,0,0,69,0,0,0,0,0
0,0,0,0,0,0,0,0,0,0,0,0,0,0,0,0,0,0,0,0,0,0,0,0,0,0,0,0,31,0,0,0,0,69,0,0,0,0,0
0,0,0,0,0,0,0,0,0,0,0,0,0,0,0,0,0,0,0,0,0,0,0,0,0,0,0,0,31,0,0,0,0,69,0,0,0,0,0
0,0,0,0,0,0,0,0,0,0,0,0,0,0,0,0,0,0,0,0,0,0,0,0,0,0,0,0,31,45,0,0,0,69,0,0,0,0,0
0,0,0,0,0,0,0,0,0,0,0,0,0,0,0,0,0,0,0,0,0,0,0,0,0,0,0,0,31,16,16,16,16,69,0,0,0,0,0
0,0,0,0,0,0,0,0,0,0,0,0,0,0,0,0,0,0,0,0,0,0,0,0,0,0,0,0,31,0,38,38,0,69,0,0,0,0,0
0,0,0,0,0,0,0,0,0,0,0,0,0,0,0,0,0,0,0,0,0,0,0,0,0,0,0,0,0,0,0,0,0,0,0,0,0,0,0
:endlayer
layer: 11
0,0,0,0,0,0,0,0,0,0,0,0,0,0,0,0,0,0,0,0,0,0,0,0,0,0,0,0,0,0,0,0,0,0,0,0,0,0,0
0,0,0,0,0,0,0,0,0,0,0,0,0,0,0,0,0,0,0,0,0,0,0,0,0,0,0,0,0,0,0,0,0,0,0,0,0,0,0
0,0,0,0,0,0,0,0,0,0,0,0,0,0,0,0,0,0,0,0,0,0,0,0,0,0,0,0,0,0,0,0,0,0,0,0,0,0,0
0,0,0,0,0,0,0,0,0,0,0,0,0,0,0,0,0,0,0,0,0,0,0,0,0,0,0,0,0,0,0,0,0,0,0,0,0,0,0
0,0,0,0,0,0,0,0,0,0,0,0,0,0,0,0,0,0,0,0,0,0,0,0,0,0,76,59,59,59,59,59,59,59,76,0,0,0,0
0,0,0,0,0,0,0,0,0,0,0,0,0,0,0,0,0,0,0,0,0,0,0,0,0,0,76,36,36,36,36,36,36,10,69,0,0,0,0
0,0,0,0,0,0,0,0,0,0,0,0,0,0,0,0,0,0,0,0,0,0,0,0,0,0,0,0,0,0,0,0,0,31,69,0,0,0,0
0,0,0,0,0,0,0,0,0,0,0,0,0,0,0,0,0,0,0,0,0,0,0,0,0,0,0,0,0,0,0,0,0,31,69,0,0,0,0
0,0,0,0,0,0,0,0,0,0,0,0,0,0,0,0,0,0,0,0,0,0,0,0,0,0,0,0,0,0,0,0,0,31,69,0,0,0,0
0,0,0,0,0,0,0,0,0,0,0,0,0,0,0,0,0,0,0,0,0,0,0,0,0,0,0,0,0,0,0,0,0,31,69,0,0,0,0
0,0,0,0,0,0,0,0,0,0,0,0,0,0,0,0,0,0,0,0,0,0,0,0,0,0,0,0,0,0,0,0,0,31,69,0,0,0,0
0,0,0,0,0,0,0,0,0,0,0,0,0,0,0,0,0,0,0,0,0,0,0,0,0,0,0,0,0,0,0,0,0,31,69,0,0,0,0
0,0,0,0,0,0,0,0,0,0,0,0,0,0,0,0,0,0,0,0,0,0,0,0,0,0,0,0,0,0,0,0,0,76,76,0,0,0,0
0,0,0,0,0,0,0,0,0,0,0,0,0,0,0,0,0,0,0,0,0,0,0,0,0,0,0,0,0,0,0,0,0,0,0,0,0,0,0
0,0,0,0,0,0,0,0,0,0,0,0,0,0,0,0,0,0,0,0,0,0,0,0,0,0,0,0,0,0,0,0,0,0,0,0,0,0,0
0,0,0,0,0,0,0,0,0,0,0,0,0,0,0,0,0,0,0,0,0,0,0,0,0,0,0,0,0,0,0,0,0,0,0,0,0,0,0
0,0,0,0,0,0,0,0,0,0,0,0,0,0,0,0,0,0,0,0,0,0,0,0,0,0,0,0,0,0,0,0,0,0,0,0,0,0,0
0,0,0,0,0,0,0,0,0,0,0,0,0,0,0,0,0,0,0,0,0,0,0,0,0,0,0,0,0,0,0,0,0,0,0,0,0,0,0
0,0,0,0,0,0,0,0,0,0,0,0,0,0,0,0,0,0,0,0,0,0,0,0,0,0,0,0,0,76,31,69,76,0,0,0,0,0,0
0,0,0,0,0,0,0,0,0,0,0,0,0,0,0,0,0,0,0,0,0,0,0,0,0,0,0,0,0,76,31,69,76,0,0,0,0,0,0
0,0,0,0,0,0,0,0,0,0,0,0,0,0,0,0,0,0,0,0,0,0,0,0,0,0,0,0,0,76,31,69,76,0,0,0,0,0,0
0,0,0,0,0,0,0,0,0,0,0,0,0,0,0,0,0,0,0,0,0,0,0,0,0,0,0,0,0,76,31,69,76,0,0,0,0,0,0
0,0,0,0,0,0,0,0,0,0,0,0,0,0,0,0,0,0,0,0,0,0,0,0,0,0,0,0,0,76,31,69,76,0,0,0,0,0,0
0,0,0,0,0,0,0,0,0,0,0,0,0,0,0,0,0,0,0,0,0,0,0,0,0,0,0,0,0,76,31,69,76,0,0,0,0,0,0
0,0,0,0,0,0,0,0,0,0,0,0,0,0,0,0,0,0,0,0,0,0,0,0,0,0,0,0,0,76,31,69,76,0,0,0,0,0,0
0,0,0,0,0,0,0,0,0,0,0,0,0,0,0,0,0,0,0,0,0,0,0,0,0,0,0,0,0,76,31,69,76,0,0,0,0,0,0
0,0,0,0,0,0,0,0,0,0,0,0,0,0,0,0,0,0,0,0,0,0,0,0,0,0,0,0,0,76,31,69,76,0,0,0,0,0,0
0,0,0,0,0,0,0,0,0,0,0,0,0,0,0,0,0,0,0,0,0,0,0,0,0,0,0,0,0,76,31,69,76,0,0,0,0,0,0
0,0,0,0,0,0,0,0,0,0,0,0,0,0,0,0,0,0,0,0,0,0,0,0,0,0,0,0,0,0,0,0,0,0,0,0,0,0,0
:endlayer

#### RULES ####
rule:
plugin=vanillaBlocks
number=1
data:
JSON:{blockState:{blockName:"minecraft:dirt",properties:{variant:"dirt",snowy:"false"}}}
:enddata
:endrule

rule:
plugin=vanillaBlocks
number=2
data:
JSON:{blockState:{blockName:"minecraft:grass",properties:{snowy:"false"}}}
:enddata
:endrule

rule:
plugin=vanillaBlocks
number=3
data:
JSON:{blockState:{blockName:"minecraft:stone",properties:{variant:"stone"}}}
:enddata
:endrule

rule:
plugin=vanillaBlocks
number=4
data:
JSON:{blockState:{blockName:"minecraft:cobblestone"}}
:enddata
:endrule

rule:
plugin=vanillaBlocks
number=5
data:
JSON:{blockState:{blockName:"minecraft:gravel"}}
:enddata
:endrule

rule:
plugin=fluid
number=6
data:
JSON:{blockState:{blockName:"minecraft:water",properties:{level:"0"}}}
:enddata
:endrule

rule:
plugin=vanillaBlocks
number=7
data:
JSON:{blockState:{blockName:"minecraft:hay_block",properties:{axis:"y"}}}
:enddata
:endrule

rule:
plugin=vanillaBlocks
number=8
data:
JSON:{blockState:{blockName:"minecraft:log",properties:{variant:"oak",axis:"y"}}}
:enddata
:endrule

rule:
plugin=vanillaBlocks
number=9
data:
JSON:{blockState:{blockName:"minecraft:hay_block",properties:{axis:"z"}}}
:enddata
:endrule

rule:
plugin=vanillaBlocks
number=10
data:
JSON:{blockState:{blockName:"minecraft:planks",properties:{variant:"oak"}}}
:enddata
:endrule

rule:
plugin=vanillaBlocks
number=11
data:
JSON:{blockState:{blockName:"minecraft:tallgrass",properties:{type:"tall_grass"}}}
:enddata
:endrule

rule:
plugin=vanillaBlocks
number=12
data:
JSON:{blockState:{blockName:"minecraft:fence",properties:{east:"false",south:"false",north:"false",west:"false"}}}
:enddata
:endrule

rule:
plugin=vanillaBlocks
number=13
data:
JSON:{blockState:{blockName:"minecraft:fence_gate",properties:{in_wall:"false",powered:"false",facing:"north",open:"true"}}}
:enddata
:endrule

rule:
plugin=vanillaBlocks
number=14
data:
JSON:{blockState:{blockName:"minecraft:fence_gate",properties:{in_wall:"false",powered:"false",facing:"north",open:"false"}}}
:enddata
:endrule

rule:
plugin=vanillaBlocks
number=15
data:
JSON:{blockState:{blockName:"minecraft:fence_gate",properties:{in_wall:"false",powered:"false",facing:"south",open:"false"}}}
:enddata
:endrule

rule:
plugin=vanillaBlocks
number=16
data:
JSON:{blockState:{blockName:"minecraft:stonebrick",properties:{variant:"stonebrick"}}}
:enddata
:endrule

rule:
plugin=vanillaBlocks
number=17
data:
JSON:{blockState:{blockName:"minecraft:wooden_slab",properties:{half:"bottom",variant:"oak"}}}
:enddata
:endrule

rule:
plugin=vanillaBlocks
number=18
data:
JSON:{blockState:{blockName:"minecraft:crafting_table"}}
:enddata
:endrule

rule:
plugin=inventory
number=19
data:
JSON:{blockState:{blockName:"minecraft:chest",properties:{facing:"north"}},lootLevel:0,teData:{ForgeData:{},Items:[{Slot:0b,id:"minecraft:feather",Count:1b,Damage:0s},{Slot:1b,id:"minecraft:feather",Count:1b,Damage:0s},{Slot:2b,id:"minecraft:feather",Count:1b,Damage:0s},{Slot:3b,id:"minecraft:egg",Count:2b,Damage:0s},{Slot:7b,id:"ancientwarfarenpc:coin",Count:1b,tag:{metal:"copper"},Damage:0s},{Slot:9b,id:"minecraft:feather",Count:1b,Damage:0s},{Slot:10b,id:"minecraft:feather",Count:1b,Damage:0s},{Slot:11b,id:"minecraft:feather",Count:1b,Damage:0s},{Slot:14b,id:"minecraft:wooden_axe",Count:1b,Damage:0s},{Slot:17b,id:"ancientwarfarenpc:coin",Count:1b,tag:{metal:"copper"},Damage:0s},{Slot:18b,id:"minecraft:feather",Count:1b,Damage:0s},{Slot:19b,id:"minecraft:feather",Count:1b,Damage:0s},{Slot:20b,id:"minecraft:feather",Count:1b,Damage:0s},{Slot:23b,id:"minecraft:stick",Count:1b,Damage:0s},{Slot:25b,id:"ancientwarfarenpc:coin",Count:1b,tag:{metal:"copper"},Damage:0s}],id:"minecraft:chest",Lock:""},inventoryData:{length:15,inventoryContents:[{id:"minecraft:feather",Count:1b,slot:0,Damage:0s},{id:"minecraft:feather",Count:1b,slot:1,Damage:0s},{id:"minecraft:feather",Count:1b,slot:2,Damage:0s},{id:"minecraft:egg",Count:2b,slot:3,Damage:0s},{id:"ancientwarfarenpc:coin",Count:1b,tag:{metal:"copper"},slot:4,Damage:0s},{id:"minecraft:feather",Count:1b,slot:5,Damage:0s},{id:"minecraft:feather",Count:1b,slot:6,Damage:0s},{id:"minecraft:feather",Count:1b,slot:7,Damage:0s},{id:"minecraft:wooden_axe",Count:1b,slot:8,Damage:0s},{id:"ancientwarfarenpc:coin",Count:1b,tag:{metal:"copper"},slot:9,Damage:0s},{id:"minecraft:feather",Count:1b,slot:10,Damage:0s},{id:"minecraft:feather",Count:1b,slot:11,Damage:0s},{id:"minecraft:feather",Count:1b,slot:12,Damage:0s},{id:"minecraft:stick",Count:1b,slot:13,Damage:0s},{id:"ancientwarfarenpc:coin",Count:1b,tag:{metal:"copper"},slot:14,Damage:0s}]},legacyFeatures:1b}
:enddata
:endrule

rule:
plugin=blockTile
number=20
data:
JSON:{blockState:{blockName:"ancientwarfarestructure:advanced_spawner",properties:{transparent:"true"}},teData:{id:"ancientwarfarestructure:advanced_spawner_tile",spawnerSettings:{minDelay:0,spawnDelay:0,lightSensitive:0b,spawnGroups:[{settingsList:[{remainingSpawnCount:1,hostile:1b,forced:1b,customTag:{ArmorDropChances:[1.0f,1.0f,1.0f,1.0f],ArmorItems:[{},{},{},{}],HandDropChances:[1.0f,1.0f],factionName:"empire",HandItems:[{id:"minecraft:bow",Count:1b,Damage:0s},{}]},maxToSpawn:1,entityId:"ancientwarfarenpc:faction.archer",minToSpawn:1}],groupWeight:1}],playerRange:8,respondToRedstone:0b,inventory:{Size:9,Items:[]},spawnRange:0,transparent:1b,maxDelay:0,xpToDrop:0,mobRange:0,debugMode:0b,maxNearbyMonsters:0}}}
:enddata
:endrule

rule:
plugin=vanillaBlocks
number=21
data:
JSON:{blockState:{blockName:"minecraft:farmland",properties:{moisture:"7"}}}
:enddata
:endrule

rule:
plugin=blockTile
number=22
data:
JSON:{blockState:{blockName:"ancientwarfarestructure:advanced_spawner",properties:{transparent:"true"}},teData:{id:"ancientwarfarestructure:advanced_spawner_tile",spawnerSettings:{minDelay:0,spawnDelay:0,lightSensitive:0b,spawnGroups:[{settingsList:[{remainingSpawnCount:1,hostile:1b,forced:1b,customTag:{ArmorDropChances:[1.0f,1.0f,1.0f,1.0f],ArmorItems:[{},{},{},{}],HandDropChances:[1.0f,1.0f],factionName:"empire",HandItems:[{id:"minecraft:bow",Count:1b,Damage:0s},{}]},maxToSpawn:1,entityId:"ancientwarfarenpc:faction.archer",minToSpawn:1}],groupWeight:1}],playerRange:8,respondToRedstone:0b,inventory:{Size:9,Items:[]},spawnRange:0,transparent:1b,maxDelay:0,xpToDrop:0,mobRange:0,debugMode:0b,maxNearbyMonsters:0}}}
:enddata
:endrule

rule:
plugin=doors
number=23
data:
JSON:{blockState:{blockName:"minecraft:wooden_door",properties:{hinge:"left",half:"lower",powered:"false",facing:"west",open:"false"}}}
:enddata
:endrule

rule:
plugin=blockTile
number=24
data:
JSON:{blockState:{blockName:"ancientwarfarestructure:advanced_spawner",properties:{transparent:"true"}},teData:{id:"ancientwarfarestructure:advanced_spawner_tile",spawnerSettings:{minDelay:0,spawnDelay:0,lightSensitive:0b,spawnGroups:[{settingsList:[{remainingSpawnCount:1,hostile:1b,forced:1b,customTag:{ArmorDropChances:[1.0f,1.0f,1.0f,1.0f],ArmorItems:[{},{},{},{}],HandDropChances:[1.0f,1.0f],factionName:"empire",HandItems:[{},{}]},maxToSpawn:1,entityId:"ancientwarfarenpc:faction.civilian.female",minToSpawn:1}],groupWeight:1}],playerRange:6,respondToRedstone:0b,inventory:{Size:9,Items:[]},spawnRange:0,transparent:1b,maxDelay:0,xpToDrop:0,mobRange:0,debugMode:0b,maxNearbyMonsters:0}}}
:enddata
:endrule

rule:
plugin=vanillaBlocks
number=25
data:
JSON:{blockState:{blockName:"minecraft:fence_gate",properties:{in_wall:"false",powered:"false",facing:"east",open:"false"}}}
:enddata
:endrule

rule:
plugin=vanillaBlocks
number=26
data:
JSON:{blockState:{blockName:"minecraft:stone_stairs",properties:{half:"bottom",shape:"straight",facing:"north"}}}
:enddata
:endrule

rule:
plugin=inventory
number=27
data:
JSON:{blockState:{blockName:"minecraft:chest",properties:{facing:"east"}},lootLevel:0,teData:{Items:[{Slot:0b,id:"minecraft:wheat_seeds",Count:1b,Damage:0s},{Slot:1b,id:"minecraft:wheat_seeds",Count:1b,Damage:0s},{Slot:2b,id:"minecraft:wheat_seeds",Count:1b,Damage:0s},{Slot:3b,id:"minecraft:wheat_seeds",Count:1b,Damage:0s},{Slot:4b,id:"minecraft:egg",Count:1b,Damage:0s},{Slot:5b,id:"minecraft:egg",Count:1b,Damage:0s},{Slot:6b,id:"minecraft:egg",Count:1b,Damage:0s},{Slot:7b,id:"minecraft:chicken",Count:1b,Damage:0s},{Slot:8b,id:"minecraft:chicken",Count:1b,Damage:0s},{Slot:9b,id:"minecraft:wheat_seeds",Count:1b,Damage:0s},{Slot:10b,id:"minecraft:wheat_seeds",Count:1b,Damage:0s},{Slot:11b,id:"minecraft:wheat_seeds",Count:1b,Damage:0s},{Slot:12b,id:"minecraft:wheat_seeds",Count:1b,Damage:0s},{Slot:13b,id:"minecraft:egg",Count:1b,Damage:0s},{Slot:14b,id:"minecraft:egg",Count:1b,Damage:0s},{Slot:15b,id:"minecraft:egg",Count:1b,Damage:0s},{Slot:16b,id:"minecraft:chicken",Count:1b,Damage:0s},{Slot:17b,id:"minecraft:chicken",Count:1b,Damage:0s},{Slot:18b,id:"minecraft:wheat_seeds",Count:1b,Damage:0s},{Slot:19b,id:"minecraft:wheat_seeds",Count:1b,Damage:0s},{Slot:20b,id:"minecraft:wheat_seeds",Count:1b,Damage:0s},{Slot:21b,id:"minecraft:wheat_seeds",Count:1b,Damage:0s},{Slot:22b,id:"minecraft:wheat_seeds",Count:1b,Damage:0s},{Slot:23b,id:"minecraft:egg",Count:1b,Damage:0s},{Slot:24b,id:"minecraft:egg",Count:1b,Damage:0s},{Slot:25b,id:"minecraft:chicken",Count:1b,Damage:0s},{Slot:26b,id:"minecraft:chicken",Count:1b,Damage:0s}],id:"minecraft:chest",Lock:""},inventoryData:{length:27,inventoryContents:[{id:"minecraft:wheat_seeds",Count:1b,slot:0,Damage:0s},{id:"minecraft:wheat_seeds",Count:1b,slot:1,Damage:0s},{id:"minecraft:wheat_seeds",Count:1b,slot:2,Damage:0s},{id:"minecraft:wheat_seeds",Count:1b,slot:3,Damage:0s},{id:"minecraft:egg",Count:1b,slot:4,Damage:0s},{id:"minecraft:egg",Count:1b,slot:5,Damage:0s},{id:"minecraft:egg",Count:1b,slot:6,Damage:0s},{id:"minecraft:chicken",Count:1b,slot:7,Damage:0s},{id:"minecraft:chicken",Count:1b,slot:8,Damage:0s},{id:"minecraft:wheat_seeds",Count:1b,slot:9,Damage:0s},{id:"minecraft:wheat_seeds",Count:1b,slot:10,Damage:0s},{id:"minecraft:wheat_seeds",Count:1b,slot:11,Damage:0s},{id:"minecraft:wheat_seeds",Count:1b,slot:12,Damage:0s},{id:"minecraft:egg",Count:1b,slot:13,Damage:0s},{id:"minecraft:egg",Count:1b,slot:14,Damage:0s},{id:"minecraft:egg",Count:1b,slot:15,Damage:0s},{id:"minecraft:chicken",Count:1b,slot:16,Damage:0s},{id:"minecraft:chicken",Count:1b,slot:17,Damage:0s},{id:"minecraft:wheat_seeds",Count:1b,slot:18,Damage:0s},{id:"minecraft:wheat_seeds",Count:1b,slot:19,Damage:0s},{id:"minecraft:wheat_seeds",Count:1b,slot:20,Damage:0s},{id:"minecraft:wheat_seeds",Count:1b,slot:21,Damage:0s},{id:"minecraft:wheat_seeds",Count:1b,slot:22,Damage:0s},{id:"minecraft:egg",Count:1b,slot:23,Damage:0s},{id:"minecraft:egg",Count:1b,slot:24,Damage:0s},{id:"minecraft:chicken",Count:1b,slot:25,Damage:0s},{id:"minecraft:chicken",Count:1b,slot:26,Damage:0s}]},legacyFeatures:1b}
:enddata
:endrule

rule:
plugin=vanillaBlocks
number=28
data:
JSON:{blockState:{blockName:"minecraft:fence_gate",properties:{in_wall:"false",powered:"false",facing:"west",open:"false"}}}
:enddata
:endrule

rule:
plugin=blockTile
number=29
data:
JSON:{blockState:{blockName:"ancientwarfarestructure:advanced_spawner",properties:{transparent:"true"}},teData:{id:"ancientwarfarestructure:advanced_spawner_tile",spawnerSettings:{minDelay:0,spawnDelay:0,lightSensitive:0b,spawnGroups:[{settingsList:[{remainingSpawnCount:1,hostile:1b,forced:1b,customTag:{ArmorDropChances:[1.0f,1.0f,1.0f,1.0f],ArmorItems:[{},{},{},{}],HandDropChances:[1.0f,1.0f],factionName:"empire",HandItems:[{id:"minecraft:bow",Count:1b,Damage:0s},{}]},maxToSpawn:1,entityId:"ancientwarfarenpc:faction.archer",minToSpawn:1}],groupWeight:1}],playerRange:16,respondToRedstone:0b,inventory:{Size:9,Items:[]},spawnRange:0,transparent:1b,maxDelay:0,xpToDrop:0,mobRange:0,debugMode:0b,maxNearbyMonsters:0}}}
:enddata
:endrule

rule:
plugin=blockTile
number=30
data:
JSON:{blockState:{blockName:"ancientwarfarestructure:advanced_spawner",properties:{transparent:"true"}},teData:{id:"ancientwarfarestructure:advanced_spawner_tile",spawnerSettings:{minDelay:0,spawnDelay:0,lightSensitive:0b,spawnGroups:[{settingsList:[{remainingSpawnCount:1,hostile:1b,forced:1b,customTag:{ArmorDropChances:[1.0f,1.0f,1.0f,1.0f],ArmorItems:[{},{},{},{}],HandDropChances:[1.0f,1.0f],factionName:"empire",HandItems:[{id:"minecraft:bow",Count:1b,Damage:0s},{}]},maxToSpawn:1,entityId:"ancientwarfarenpc:faction.archer",minToSpawn:1}],groupWeight:1}],playerRange:16,respondToRedstone:0b,inventory:{Size:9,Items:[]},spawnRange:0,transparent:1b,maxDelay:0,xpToDrop:0,mobRange:0,debugMode:0b,maxNearbyMonsters:0}}}
:enddata
:endrule

rule:
plugin=vanillaBlocks
number=31
data:
JSON:{blockState:{blockName:"minecraft:oak_stairs",properties:{half:"bottom",shape:"straight",facing:"east"}}}
:enddata
:endrule

rule:
plugin=doors
number=32
data:
JSON:{blockState:{blockName:"minecraft:wooden_door",properties:{hinge:"left",half:"lower",powered:"false",facing:"east",open:"true"}}}
:enddata
:endrule

rule:
plugin=vanillaBlocks
number=33
data:
JSON:{blockState:{blockName:"minecraft:farmland",properties:{moisture:"0"}}}
:enddata
:endrule

rule:
plugin=inventory
number=34
data:
JSON:{blockState:{blockName:"minecraft:furnace",properties:{facing:"west"}},lootLevel:0,teData:{CookTime:0,BurnTime:0,Items:[],id:"minecraft:furnace",CookTimeTotal:0,Lock:""},inventoryData:{length:0,inventoryContents:[]},legacyFeatures:0b}
:enddata
:endrule

rule:
plugin=blockTile
number=35
data:
JSON:{blockState:{blockName:"ancientwarfarestructure:advanced_spawner",properties:{transparent:"true"}},teData:{id:"ancientwarfarestructure:advanced_spawner_tile",spawnerSettings:{minDelay:0,spawnDelay:0,lightSensitive:0b,spawnGroups:[{settingsList:[{remainingSpawnCount:1,hostile:1b,forced:1b,customTag:{ArmorDropChances:[1.0f,1.0f,1.0f,1.0f],ArmorItems:[{},{},{},{}],HandDropChances:[1.0f,1.0f],factionName:"empire",HandItems:[{},{}]},maxToSpawn:1,entityId:"ancientwarfarenpc:faction.civilian.female",minToSpawn:1}],groupWeight:1}],playerRange:6,respondToRedstone:0b,inventory:{Size:9,Items:[]},spawnRange:0,transparent:1b,maxDelay:0,xpToDrop:0,mobRange:0,debugMode:0b,maxNearbyMonsters:0}}}
:enddata
:endrule

rule:
plugin=vanillaBlocks
number=36
data:
JSON:{blockState:{blockName:"minecraft:oak_stairs",properties:{half:"bottom",shape:"straight",facing:"north"}}}
:enddata
:endrule

rule:
plugin=vanillaBlocks
number=37
data:
JSON:{blockState:{blockName:"minecraft:red_flower",properties:{type:"oxeye_daisy"}}}
:enddata
:endrule

rule:
plugin=vanillaBlocks
number=38
data:
JSON:{blockState:{blockName:"minecraft:torch",properties:{facing:"south"}}}
:enddata
:endrule

rule:
plugin=vanillaBlocks
number=39
data:
JSON:{blockState:{blockName:"minecraft:torch",properties:{facing:"up"}}}
:enddata
:endrule

rule:
plugin=vanillaBlocks
number=40
data:
JSON:{blockState:{blockName:"minecraft:torch",properties:{facing:"west"}}}
:enddata
:endrule

rule:
plugin=blockTile
number=41
data:
JSON:{blockState:{blockName:"ancientwarfarestructure:advanced_spawner",properties:{transparent:"true"}},teData:{id:"ancientwarfarestructure:advanced_spawner_tile",spawnerSettings:{minDelay:0,spawnDelay:0,lightSensitive:0b,spawnGroups:[{settingsList:[{remainingSpawnCount:1,hostile:1b,forced:1b,customTag:{ArmorDropChances:[1.0f,1.0f,1.0f,1.0f],ArmorItems:[{},{},{},{}],HandDropChances:[1.0f,1.0f],factionName:"empire",HandItems:[{id:"minecraft:bow",Count:1b,Damage:0s},{}]},maxToSpawn:1,entityId:"ancientwarfarenpc:faction.archer",minToSpawn:1}],groupWeight:1}],playerRange:16,respondToRedstone:0b,inventory:{Size:9,Items:[]},spawnRange:0,transparent:1b,maxDelay:0,xpToDrop:0,mobRange:0,debugMode:0b,maxNearbyMonsters:0}}}
:enddata
:endrule

rule:
plugin=vanillaBlocks
number=42
data:
JSON:{blockState:{blockName:"minecraft:potatoes",properties:{age:"7"}}}
:enddata
:endrule

rule:
plugin=doors
number=43
data:
JSON:{blockState:{blockName:"minecraft:wooden_door",properties:{hinge:"left",half:"upper",powered:"false",facing:"south",open:"false"}}}
:enddata
:endrule

rule:
plugin=vanillaBlocks
number=44
data:
JSON:{blockState:{blockName:"minecraft:wheat",properties:{age:"7"}}}
:enddata
:endrule

rule:
plugin=vanillaBlocks
number=45
data:
JSON:{blockState:{blockName:"minecraft:torch",properties:{facing:"north"}}}
:enddata
:endrule

rule:
plugin=vanillaBlocks
number=46
data:
JSON:{blockState:{blockName:"minecraft:fence_gate",properties:{in_wall:"false",powered:"false",facing:"west",open:"true"}}}
:enddata
:endrule

rule:
plugin=blockTile
number=47
data:
JSON:{blockState:{blockName:"ancientwarfarestructure:advanced_spawner",properties:{transparent:"true"}},teData:{id:"ancientwarfarestructure:advanced_spawner_tile",spawnerSettings:{minDelay:0,spawnDelay:0,lightSensitive:0b,spawnGroups:[{settingsList:[{remainingSpawnCount:1,hostile:1b,forced:1b,customTag:{ArmorDropChances:[1.0f,1.0f,1.0f,1.0f],ArmorItems:[{},{},{},{}],HandDropChances:[1.0f,1.0f],factionName:"empire",HandItems:[{id:"minecraft:bow",Count:1b,Damage:0s},{}]},maxToSpawn:1,entityId:"ancientwarfarenpc:faction.archer",minToSpawn:1}],groupWeight:1}],playerRange:16,respondToRedstone:0b,inventory:{Size:9,Items:[]},spawnRange:0,transparent:1b,maxDelay:0,xpToDrop:0,mobRange:0,debugMode:0b,maxNearbyMonsters:0}}}
:enddata
:endrule

rule:
plugin=blockTile
number=48
data:
JSON:{blockState:{blockName:"ancientwarfarestructure:advanced_spawner",properties:{transparent:"true"}},teData:{id:"ancientwarfarestructure:advanced_spawner_tile",spawnerSettings:{minDelay:0,spawnDelay:0,lightSensitive:0b,spawnGroups:[{settingsList:[{remainingSpawnCount:1,hostile:1b,forced:1b,customTag:{ArmorDropChances:[1.0f,1.0f,1.0f,1.0f],ArmorItems:[{},{},{},{}],HandDropChances:[1.0f,1.0f],factionName:"empire",HandItems:[{id:"minecraft:bow",Count:1b,Damage:0s},{}]},maxToSpawn:1,entityId:"ancientwarfarenpc:faction.archer",minToSpawn:1}],groupWeight:1}],playerRange:16,respondToRedstone:0b,inventory:{Size:9,Items:[]},spawnRange:0,transparent:1b,maxDelay:0,xpToDrop:0,mobRange:0,debugMode:0b,maxNearbyMonsters:0}}}
:enddata
:endrule

rule:
plugin=inventory
number=49
data:
JSON:{blockState:{blockName:"minecraft:chest",properties:{facing:"south"}},lootLevel:0,teData:{ForgeData:{},Items:[{Slot:4b,id:"minecraft:iron_hoe",Count:1b,Damage:0s},{Slot:15b,id:"minecraft:melon_seeds",Count:21b,Damage:0s},{Slot:22b,id:"minecraft:stone_hoe",Count:1b,Damage:0s}],id:"minecraft:chest",Lock:""},inventoryData:{length:3,inventoryContents:[{id:"minecraft:iron_hoe",Count:1b,slot:0,Damage:0s},{id:"minecraft:melon_seeds",Count:21b,slot:1,Damage:0s},{id:"minecraft:stone_hoe",Count:1b,slot:2,Damage:0s}]},legacyFeatures:1b}
:enddata
:endrule

rule:
plugin=vanillaBlocks
number=50
data:
JSON:{blockState:{blockName:"minecraft:melon_stem",properties:{facing:"up",age:"7"}}}
:enddata
:endrule

rule:
plugin=vanillaBlocks
number=51
data:
JSON:{blockState:{blockName:"minecraft:pumpkin_stem",properties:{facing:"up",age:"7"}}}
:enddata
:endrule

rule:
plugin=inventory
number=52
data:
JSON:{blockState:{blockName:"minecraft:furnace",properties:{facing:"west"}},lootLevel:0,teData:{CookTime:0,BurnTime:0,Items:[],id:"minecraft:furnace",CookTimeTotal:0,Lock:""},inventoryData:{length:0,inventoryContents:[]},legacyFeatures:0b}
:enddata
:endrule

rule:
plugin=vanillaBlocks
number=53
data:
JSON:{blockState:{blockName:"minecraft:melon_block"}}
:enddata
:endrule

rule:
plugin=vanillaBlocks
number=54
data:
JSON:{blockState:{blockName:"minecraft:pumpkin",properties:{facing:"north"}}}
:enddata
:endrule

rule:
plugin=vanillaBlocks
number=55
data:
JSON:{blockState:{blockName:"minecraft:oak_stairs",properties:{half:"top",shape:"straight",facing:"south"}}}
:enddata
:endrule

rule:
plugin=inventory
number=56
data:
JSON:{blockState:{blockName:"minecraft:lit_furnace",properties:{facing:"north"}},lootLevel:0,teData:{CookTime:0,BurnTime:0,Items:[],id:"minecraft:furnace",CookTimeTotal:0,Lock:""},inventoryData:{length:0,inventoryContents:[]},legacyFeatures:0b}
:enddata
:endrule

rule:
plugin=vanillaBlocks
number=57
data:
JSON:{blockState:{blockName:"minecraft:cauldron",properties:{level:"3"}}}
:enddata
:endrule

rule:
plugin=blockTile
number=58
data:
JSON:{blockState:{blockName:"ancientwarfarestructure:advanced_spawner",properties:{transparent:"true"}},teData:{id:"ancientwarfarestructure:advanced_spawner_tile",spawnerSettings:{minDelay:0,spawnDelay:0,lightSensitive:0b,spawnGroups:[{settingsList:[{remainingSpawnCount:1,hostile:1b,forced:1b,customTag:{ArmorDropChances:[1.0f,1.0f,1.0f,1.0f],ArmorItems:[{},{},{},{}],HandDropChances:[1.0f,1.0f],factionName:"empire",HandItems:[{id:"minecraft:bow",Count:1b,Damage:0s},{}]},maxToSpawn:1,entityId:"ancientwarfarenpc:faction.archer",minToSpawn:1}],groupWeight:1}],playerRange:16,respondToRedstone:0b,inventory:{Size:9,Items:[]},spawnRange:0,transparent:1b,maxDelay:0,xpToDrop:0,mobRange:0,debugMode:0b,maxNearbyMonsters:0}}}
:enddata
:endrule

rule:
plugin=vanillaBlocks
number=59
data:
JSON:{blockState:{blockName:"minecraft:oak_stairs",properties:{half:"bottom",shape:"straight",facing:"south"}}}
:enddata
:endrule

rule:
plugin=inventory
number=60
data:
JSON:{blockState:{blockName:"minecraft:chest",properties:{facing:"east"}},lootLevel:0,teData:{Items:[],id:"minecraft:chest",Lock:""},inventoryData:{length:0,inventoryContents:[]},legacyFeatures:1b}
:enddata
:endrule

rule:
plugin=blockTile
number=61
data:
JSON:{blockState:{blockName:"ancientwarfarestructure:advanced_spawner",properties:{transparent:"true"}},teData:{id:"ancientwarfarestructure:advanced_spawner_tile",spawnerSettings:{minDelay:0,spawnDelay:0,lightSensitive:0b,spawnGroups:[{settingsList:[{remainingSpawnCount:1,hostile:1b,forced:1b,customTag:{ArmorDropChances:[1.0f,1.0f,1.0f,1.0f],ArmorItems:[{},{},{},{}],HandDropChances:[1.0f,1.0f],factionName:"empire",HandItems:[{id:"minecraft:bow",Count:1b,Damage:0s},{}]},maxToSpawn:1,entityId:"ancientwarfarenpc:faction.archer",minToSpawn:1}],groupWeight:1}],playerRange:6,respondToRedstone:0b,inventory:{Size:9,Items:[]},spawnRange:0,transparent:1b,maxDelay:0,xpToDrop:0,mobRange:0,debugMode:0b,maxNearbyMonsters:0}}}
:enddata
:endrule

rule:
plugin=inventory
number=62
data:
JSON:{blockState:{blockName:"minecraft:chest",properties:{facing:"east"}},lootLevel:0,teData:{Items:[],id:"minecraft:chest",Lock:""},inventoryData:{length:0,inventoryContents:[]},legacyFeatures:1b}
:enddata
:endrule

rule:
plugin=blockTile
number=63
data:
JSON:{blockState:{blockName:"ancientwarfarestructure:advanced_spawner",properties:{transparent:"true"}},teData:{id:"ancientwarfarestructure:advanced_spawner_tile",spawnerSettings:{minDelay:0,spawnDelay:0,lightSensitive:0b,spawnGroups:[{settingsList:[{remainingSpawnCount:1,hostile:1b,forced:1b,customTag:{ArmorDropChances:[1.0f,1.0f,1.0f,1.0f],ArmorItems:[{},{},{},{}],HandDropChances:[1.0f,1.0f],factionName:"empire",HandItems:[{id:"minecraft:bow",Count:1b,Damage:0s},{}]},maxToSpawn:1,entityId:"ancientwarfarenpc:faction.archer",minToSpawn:1}],groupWeight:1}],playerRange:16,respondToRedstone:0b,inventory:{Size:9,Items:[]},spawnRange:0,transparent:1b,maxDelay:0,xpToDrop:0,mobRange:0,debugMode:0b,maxNearbyMonsters:0}}}
:enddata
:endrule

rule:
plugin=vanillaBlocks
number=64
data:
JSON:{blockState:{blockName:"minecraft:oak_stairs",properties:{half:"top",shape:"straight",facing:"north"}}}
:enddata
:endrule

rule:
plugin=vanillaBlocks
number=65
data:
JSON:{blockState:{blockName:"minecraft:torch",properties:{facing:"east"}}}
:enddata
:endrule

rule:
plugin=vanillaBlocks
number=66
data:
JSON:{blockState:{blockName:"minecraft:stone_stairs",properties:{half:"bottom",shape:"straight",facing:"east"}}}
:enddata
:endrule

rule:
plugin=vanillaBlocks
number=67
data:
JSON:{blockState:{blockName:"minecraft:glass_pane",properties:{east:"false",south:"false",north:"false",west:"false"}}}
:enddata
:endrule

rule:
plugin=vanillaBlocks
number=68
data:
JSON:{blockState:{blockName:"minecraft:stone_pressure_plate",properties:{powered:"false"}}}
:enddata
:endrule

rule:
plugin=vanillaBlocks
number=69
data:
JSON:{blockState:{blockName:"minecraft:oak_stairs",properties:{half:"bottom",shape:"straight",facing:"west"}}}
:enddata
:endrule

rule:
plugin=vanillaBlocks
number=70
data:
JSON:{blockState:{blockName:"minecraft:wooden_slab",properties:{half:"top",variant:"oak"}}}
:enddata
:endrule

rule:
plugin=vanillaBlocks
number=71
data:
JSON:{blockState:{blockName:"minecraft:log",properties:{variant:"oak",axis:"x"}}}
:enddata
:endrule

rule:
plugin=inventory
number=72
data:
JSON:{blockState:{blockName:"minecraft:chest",properties:{facing:"west"}},lootLevel:0,teData:{ForgeData:{},Items:[],id:"minecraft:chest",Lock:""},inventoryData:{length:0,inventoryContents:[]},legacyFeatures:1b}
:enddata
:endrule

rule:
plugin=bed
number=73
data:
JSON:{blockState:{blockName:"minecraft:bed",properties:{part:"head",facing:"east",occupied:"false"}},bedColor:14}
:enddata
:endrule

rule:
plugin=bed
number=74
data:
JSON:{blockState:{blockName:"minecraft:bed",properties:{part:"foot",facing:"east",occupied:"false"}},bedColor:14}
:enddata
:endrule

rule:
plugin=inventory
number=75
data:
JSON:{blockState:{blockName:"minecraft:chest",properties:{facing:"west"}},lootLevel:0,teData:{ForgeData:{},Items:[{Slot:0b,id:"minecraft:feather",Count:1b,Damage:0s},{Slot:4b,id:"minecraft:flint",Count:1b,Damage:0s},{Slot:12b,id:"minecraft:flint",Count:1b,Damage:0s},{Slot:13b,id:"minecraft:flint",Count:2b,Damage:0s},{Slot:16b,id:"ancientwarfarenpc:coin",Count:1b,tag:{metal:"copper"},Damage:0s},{Slot:20b,id:"minecraft:flint",Count:1b,Damage:0s},{Slot:22b,id:"minecraft:flint",Count:1b,Damage:0s},{Slot:24b,id:"ancientwarfarenpc:coin",Count:1b,tag:{metal:"copper"},Damage:0s},{Slot:25b,id:"ancientwarfarenpc:coin",Count:1b,tag:{metal:"copper"},Damage:0s}],id:"minecraft:chest",Lock:""},inventoryData:{length:9,inventoryContents:[{id:"minecraft:feather",Count:1b,slot:0,Damage:0s},{id:"minecraft:flint",Count:1b,slot:1,Damage:0s},{id:"minecraft:flint",Count:1b,slot:2,Damage:0s},{id:"minecraft:flint",Count:2b,slot:3,Damage:0s},{id:"ancientwarfarenpc:coin",Count:1b,tag:{metal:"copper"},slot:4,Damage:0s},{id:"minecraft:flint",Count:1b,slot:5,Damage:0s},{id:"minecraft:flint",Count:1b,slot:6,Damage:0s},{id:"ancientwarfarenpc:coin",Count:1b,tag:{metal:"copper"},slot:7,Damage:0s},{id:"ancientwarfarenpc:coin",Count:1b,tag:{metal:"copper"},slot:8,Damage:0s}]},legacyFeatures:1b}
:enddata
:endrule

rule:
plugin=vanillaBlocks
number=76
data:
JSON:{blockState:{blockName:"minecraft:stone_slab",properties:{half:"bottom",variant:"wood_old"}}}
:enddata
:endrule

rule:
plugin=bed
number=77
data:
JSON:{blockState:{blockName:"minecraft:bed",properties:{part:"foot",facing:"north",occupied:"false"}},bedColor:14}
:enddata
:endrule

rule:
plugin=inventory
number=78
data:
JSON:{blockState:{blockName:"minecraft:chest",properties:{facing:"south"}},lootLevel:0,teData:{ForgeData:{},Items:[{Slot:8b,id:"ancientwarfarenpc:coin",Count:1b,tag:{metal:"copper"},Damage:0s},{Slot:14b,id:"ancientwarfarenpc:coin",Count:1b,tag:{metal:"silver"},Damage:0s},{Slot:15b,id:"ancientwarfarenpc:coin",Count:1b,tag:{metal:"copper"},Damage:0s},{Slot:16b,id:"ancientwarfarenpc:coin",Count:1b,tag:{metal:"copper"},Damage:0s},{Slot:25b,id:"ancientwarfarenpc:coin",Count:1b,tag:{metal:"copper"},Damage:0s}],id:"minecraft:chest",Lock:""},inventoryData:{length:5,inventoryContents:[{id:"ancientwarfarenpc:coin",Count:1b,tag:{metal:"copper"},slot:0,Damage:0s},{id:"ancientwarfarenpc:coin",Count:1b,tag:{metal:"silver"},slot:1,Damage:0s},{id:"ancientwarfarenpc:coin",Count:1b,tag:{metal:"copper"},slot:2,Damage:0s},{id:"ancientwarfarenpc:coin",Count:1b,tag:{metal:"copper"},slot:3,Damage:0s},{id:"ancientwarfarenpc:coin",Count:1b,tag:{metal:"copper"},slot:4,Damage:0s}]},legacyFeatures:1b}
:enddata
:endrule

rule:
plugin=blockTile
number=79
data:
JSON:{blockState:{blockName:"ancientwarfarestructure:advanced_spawner",properties:{transparent:"true"}},teData:{id:"ancientwarfarestructure:advanced_spawner_tile",spawnerSettings:{minDelay:0,spawnDelay:0,lightSensitive:0b,spawnGroups:[{settingsList:[{remainingSpawnCount:1,hostile:1b,forced:1b,customTag:{ArmorDropChances:[1.0f,1.0f,1.0f,1.0f],ArmorItems:[{},{},{},{}],HandDropChances:[1.0f,1.0f],factionName:"empire",HandItems:[{id:"minecraft:bow",Count:1b,Damage:0s},{}]},maxToSpawn:1,entityId:"ancientwarfarenpc:faction.archer",minToSpawn:1}],groupWeight:1}],playerRange:4,respondToRedstone:0b,inventory:{Size:9,Items:[]},spawnRange:0,transparent:1b,maxDelay:0,xpToDrop:0,mobRange:0,debugMode:0b,maxNearbyMonsters:0}}}
:enddata
:endrule

rule:
plugin=bed
number=80
data:
JSON:{blockState:{blockName:"minecraft:bed",properties:{part:"head",facing:"north",occupied:"false"}},bedColor:14}
:enddata
:endrule

rule:
plugin=vanillaBlocks
number=81
data:
JSON:{blockState:{blockName:"minecraft:stone_slab",properties:{half:"top",variant:"wood_old"}}}
:enddata
:endrule

#### ENTITIES ####
entity:
plugin=entity
number=0
data:
JSON:{yOffset:0.0f,xOffset:0.63106257f,rotation:164.0216f,mobID:"minecraft:chicken",zOffset:0.06821817f,position:9620995178520L,entityData:{IsChickenJockey:0b,HurtByTimestamp:0,ForgeData:{"MP|Init":1b,Checked:1b,WITCInitialWidth:0.3f,cnpcmarkdata:{marks:[]},WITCInitialHeight:0.7f},Attributes:[{Base:4.0d,Name:"generic.maxHealth"},{Base:0.0d,Name:"generic.knockbackResistance"},{Base:0.25d,Name:"generic.movementSpeed"},{Base:0.0d,Name:"generic.armor"},{Base:0.0d,Name:"generic.armorToughness"},{Base:1.0d,Name:"forge.swimSpeed"},{Base:16.0d,Name:"generic.followRange"}],Invulnerable:0b,FallFlying:0b,ForcedAge:0,PortalCooldown:0,AbsorptionAmount:0.0f,FallDistance:0.0f,InLove:0,DeathTime:0s,ForgeCaps:{"dsurround:emojidata":{as:1,es:0,et:0},"llibrary:extendedentitydatacapability":{"mm:living":{frozenYaw:0.0f,freezeProgress:0.0f,frozenPitch:0.0f,frozenYawHead:0.0f,frozenEntityID:-1,frozenLimbSwingAmount:0.0f,frozenRenderYawOffset:0.0f,frozenSwingProgress:0.0f}}},HandDropChances:[0.085f,0.0f],PersistenceRequired:0b,Age:0,Motion:[0.0d,-0.0784000015258789d,0.0d],Leashed:0b,Health:4.0f,LeftHanded:0b,Air:300s,OnGround:1b,Dimension:0,Rotation:[344.02158f,0.0f],UpdateBlocked:0b,HandItems:[{},{}],ArmorDropChances:[0.085f,0.085f,0.085f,0.085f],EggLayTime:4530,Pos:[872.3689374316043d,134.0d,29.931781815111915d],Fire:-1s,ArmorItems:[{},{},{},{}],CanPickUpLoot:0b,HurtTime:0s}}
:enddata
:endentity

entity:
plugin=entity
number=1
data:
JSON:{yOffset:0.0f,xOffset:0.03927529f,rotation:357.55972f,mobID:"minecraft:chicken",zOffset:0.4619699f,position:9895873085463L,entityData:{IsChickenJockey:0b,HurtByTimestamp:0,ForgeData:{"MP|Init":1b,Checked:1b,WITCInitialWidth:0.3f,cnpcmarkdata:{marks:[]},WITCInitialHeight:0.7f},Attributes:[{Base:4.0d,Name:"generic.maxHealth"},{Base:0.0d,Name:"generic.knockbackResistance"},{Base:0.25d,Name:"generic.movementSpeed"},{Base:0.0d,Name:"generic.armor"},{Base:0.0d,Name:"generic.armorToughness"},{Base:1.0d,Name:"forge.swimSpeed"},{Base:16.0d,Name:"generic.followRange"}],Invulnerable:0b,FallFlying:0b,ForcedAge:0,PortalCooldown:0,AbsorptionAmount:0.0f,FallDistance:0.0f,InLove:0,DeathTime:0s,ForgeCaps:{"dsurround:emojidata":{as:0,es:0,et:0},"llibrary:extendedentitydatacapability":{"mm:living":{frozenYaw:0.0f,freezeProgress:0.0f,frozenPitch:0.0f,frozenYawHead:0.0f,frozenEntityID:-1,frozenLimbSwingAmount:0.0f,frozenRenderYawOffset:0.0f,frozenSwingProgress:0.0f}}},HandDropChances:[0.085f,0.0f],PersistenceRequired:0b,Age:0,Motion:[0.0d,-0.0784000015258789d,0.0d],Leashed:0b,Health:4.0f,LeftHanded:0b,Air:300s,OnGround:1b,Dimension:0,Rotation:[177.55972f,0.0f],UpdateBlocked:0b,HandItems:[{},{}],ArmorDropChances:[0.085f,0.085f,0.085f,0.085f],EggLayTime:6140,Pos:[871.9607247238933d,134.0d,30.53803010794543d],Fire:-1s,ArmorItems:[{},{},{},{}],CanPickUpLoot:0b,HurtTime:0s}}
:enddata
:endentity

entity:
plugin=entity
number=2
data:
JSON:{yOffset:0.0f,xOffset:0.12518787f,rotation:352.11813f,mobID:"minecraft:chicken",zOffset:0.6221119f,position:9620995178519L,entityData:{IsChickenJockey:0b,HurtByTimestamp:0,ForgeData:{"MP|Init":1b,Checked:1b,WITCInitialWidth:0.3f,cnpcmarkdata:{marks:[]},WITCInitialHeight:0.7f},Attributes:[{Base:4.0d,Name:"generic.maxHealth"},{Base:0.0d,Name:"generic.knockbackResistance"},{Base:0.25d,Name:"generic.movementSpeed"},{Base:0.0d,Name:"generic.armor"},{Base:0.0d,Name:"generic.armorToughness"},{Base:1.0d,Name:"forge.swimSpeed"},{Base:16.0d,Name:"generic.followRange"}],Invulnerable:0b,FallFlying:0b,ForcedAge:0,PortalCooldown:0,AbsorptionAmount:0.0f,FallDistance:0.0f,InLove:0,DeathTime:0s,ForgeCaps:{"dsurround:emojidata":{as:0,es:0,et:0},"llibrary:extendedentitydatacapability":{"mm:living":{frozenYaw:0.0f,freezeProgress:0.0f,frozenPitch:0.0f,frozenYawHead:0.0f,frozenEntityID:-1,frozenLimbSwingAmount:0.0f,frozenRenderYawOffset:0.0f,frozenSwingProgress:0.0f}}},HandDropChances:[0.085f,0.0f],PersistenceRequired:0b,Age:0,Motion:[0.0d,-0.0784000015258789d,0.0d],Leashed:0b,Health:4.0f,LeftHanded:0b,Air:300s,OnGround:1b,Dimension:0,Rotation:[172.11813f,0.0f],UpdateBlocked:0b,HandItems:[{},{}],ArmorDropChances:[0.085f,0.085f,0.085f,0.085f],EggLayTime:4108,Pos:[872.8748121379615d,134.0d,30.37788806178476d],Fire:-1s,ArmorItems:[{},{},{},{}],CanPickUpLoot:0b,HurtTime:0s}}
:enddata
:endentity

entity:
plugin=entity
number=3
data:
JSON:{yOffset:0.0f,xOffset:0.49908805f,rotation:180.08887f,mobID:"minecraft:chicken",zOffset:0.85471594f,position:10170750992393L,entityData:{IsChickenJockey:0b,HurtByTimestamp:0,ForgeData:{"MP|Init":1b,Checked:1b,WITCInitialWidth:0.3f,cnpcmarkdata:{marks:[]},WITCInitialHeight:0.7f},Attributes:[{Base:4.0d,Name:"generic.maxHealth"},{Base:0.0d,Name:"generic.knockbackResistance"},{Base:0.25d,Name:"generic.movementSpeed"},{Base:0.0d,Name:"generic.armor"},{Base:0.0d,Name:"generic.armorToughness"},{Base:1.0d,Name:"forge.swimSpeed"},{Base:16.0d,Name:"generic.followRange"}],Invulnerable:0b,FallFlying:0b,ForcedAge:0,PortalCooldown:0,AbsorptionAmount:0.0f,FallDistance:0.0f,InLove:0,DeathTime:0s,ForgeCaps:{"dsurround:emojidata":{as:0,es:0,et:0},"llibrary:extendedentitydatacapability":{"mm:living":{frozenYaw:0.0f,freezeProgress:0.0f,frozenPitch:0.0f,frozenYawHead:0.0f,frozenEntityID:-1,frozenLimbSwingAmount:0.0f,frozenRenderYawOffset:0.0f,frozenSwingProgress:0.0f}}},HandDropChances:[0.085f,0.0f],PersistenceRequired:0b,Age:0,Motion:[0.0d,-0.0784000015258789d,0.0d],Leashed:0b,Health:4.0f,LeftHanded:0b,Air:300s,OnGround:1b,Dimension:0,Rotation:[0.08885956f,0.0f],UpdateBlocked:0b,HandItems:[{},{}],ArmorDropChances:[0.085f,0.085f,0.085f,0.085f],EggLayTime:5760,Pos:[870.5009119791969d,134.0d,44.14528407843272d],Fire:-1s,ArmorItems:[{},{},{},{}],CanPickUpLoot:0b,HurtTime:0s}}
:enddata
:endentity

entity:
plugin=entity
number=4
data:
JSON:{yOffset:0.0f,xOffset:0.38687164f,rotation:277.68066f,mobID:"minecraft:item",zOffset:0.5912409f,position:10445628899341L,entityData:{Motion:[-4.9E-324d,-0.0d,-4.9E-324d],Health:5s,Invulnerable:0b,Air:300s,OnGround:1b,Dimension:0,PortalCooldown:0,Rotation:[97.68066f,0.0f],UpdateBlocked:0b,FallDistance:0.0f,Item:{id:"minecraft:egg",Count:1b,Damage:0s},Pos:[869.6131283935945d,134.0d,40.40875910901348d],PickupDelay:0s,Fire:-1s,ForgeCaps:{"llibrary:extendedentitydatacapability":{}},Lifespan:6000,Age:5658s}}
:enddata
:endentity

entity:
plugin=entity
number=5
data:
JSON:{yOffset:0.0f,xOffset:0.755348f,rotation:71.33426f,mobID:"minecraft:item",zOffset:0.7613363f,position:9620995178515L,entityData:{Motion:[-4.9E-324d,-0.0d,4.9E-324d],Health:5s,Invulnerable:0b,Air:300s,OnGround:1b,Dimension:0,PortalCooldown:0,Rotation:[251.33426f,0.0f],UpdateBlocked:0b,FallDistance:0.0f,Item:{id:"minecraft:egg",Count:1b,Damage:0s},Pos:[872.2446519812404d,134.0d,34.2386636617422d],PickupDelay:0s,Fire:-1s,ForgeCaps:{"llibrary:extendedentitydatacapability":{}},Lifespan:6000,Age:4973s}}
:enddata
:endentity

entity:
plugin=entity
number=6
data:
JSON:{yOffset:0.0f,xOffset:0.81458986f,rotation:162.52887f,mobID:"minecraft:item",zOffset:0.1868574f,position:9620995178517L,entityData:{Motion:[-4.9E-324d,-0.0d,-4.9E-324d],Health:5s,Invulnerable:0b,Air:300s,OnGround:1b,Dimension:0,PortalCooldown:0,Rotation:[342.52887f,0.0f],UpdateBlocked:0b,FallDistance:0.0f,Item:{id:"minecraft:egg",Count:1b,Damage:0s},Pos:[872.1854101508584d,134.0d,32.813142577198434d],PickupDelay:0s,Fire:-1s,ForgeCaps:{"llibrary:extendedentitydatacapability":{}},Lifespan:6000,Age:1807s}}
:enddata
:endentity

entity:
plugin=entity
number=7
data:
JSON:{yOffset:0.0f,xOffset:0.27191854f,rotation:103.20984f,mobID:"minecraft:chicken",zOffset:0.8f,position:9621062287366L,entityData:{IsChickenJockey:0b,HurtByTimestamp:0,ForgeData:{"MP|Init":1b,Checked:1b,WITCInitialWidth:0.3f,cnpcmarkdata:{marks:[]},WITCInitialHeight:0.7f},Attributes:[{Base:4.0d,Name:"generic.maxHealth"},{Base:0.0d,Name:"generic.knockbackResistance"},{Base:0.25d,Name:"generic.movementSpeed"},{Base:0.0d,Name:"generic.armor"},{Base:0.0d,Name:"generic.armorToughness"},{Base:1.0d,Name:"forge.swimSpeed"},{Base:16.0d,Name:"generic.followRange"}],Invulnerable:0b,FallFlying:0b,ForcedAge:0,PortalCooldown:0,AbsorptionAmount:0.0f,FallDistance:0.0f,InLove:0,DeathTime:0s,ForgeCaps:{"dsurround:emojidata":{as:0,es:0,et:0},"llibrary:extendedentitydatacapability":{"mm:living":{frozenYaw:0.0f,freezeProgress:0.0f,frozenPitch:0.0f,frozenYawHead:0.0f,frozenEntityID:-1,frozenLimbSwingAmount:0.0f,frozenRenderYawOffset:0.0f,frozenSwingProgress:0.0f}}},HandDropChances:[0.085f,0.0f],PersistenceRequired:0b,Age:0,Motion:[0.0d,-0.0784000015258789d,0.0d],Leashed:0b,Health:3.0f,LeftHanded:0b,Air:300s,OnGround:1b,Dimension:0,Rotation:[283.20984f,0.0f],UpdateBlocked:0b,HandItems:[{},{}],ArmorDropChances:[0.085f,0.085f,0.085f,0.085f],EggLayTime:7369,Pos:[872.7280814440005d,135.0d,47.20000000298023d],Fire:-1s,ArmorItems:[{},{},{},{}],CanPickUpLoot:0b,HurtTime:0s}}
:enddata
:endentity

entity:
plugin=entity
number=8
data:
JSON:{yOffset:0.0f,xOffset:0.8178812f,rotation:24.72342f,mobID:"minecraft:item",zOffset:0.5075567f,position:9620995178516L,entityData:{Motion:[-1.7124448022446576E-62d,-0.0d,-8.457095704000051E-63d],Health:5s,Invulnerable:0b,Air:300s,OnGround:1b,Dimension:0,PortalCooldown:0,Rotation:[204.72342f,0.0f],UpdateBlocked:0b,FallDistance:0.0f,Item:{id:"minecraft:feather",Count:1b,Damage:0s},Pos:[872.1821187655634d,134.0d,33.492443307266385d],PickupDelay:0s,Fire:-1s,ForgeCaps:{"llibrary:extendedentitydatacapability":{}},Lifespan:6000,Age:269s}}
:enddata
:endentity

entity:
plugin=entity
number=9
data:
JSON:{yOffset:0.5680845f,xOffset:0.17500001f,rotation:269.94464f,mobID:"minecraft:chicken",zOffset:0.5012771f,position:3023858303002L,entityData:{IsChickenJockey:0b,HurtByTimestamp:0,ForgeData:{"MP|Init":1b,Checked:1b,WITCInitialWidth:0.3f,cnpcmarkdata:{marks:[]},WITCInitialHeight:0.7f},Attributes:[{Base:4.0d,Name:"generic.maxHealth"},{Base:0.0d,Name:"generic.knockbackResistance"},{Base:0.25d,Name:"generic.movementSpeed"},{Base:0.0d,Name:"generic.armor"},{Base:0.0d,Name:"generic.armorToughness"},{Base:1.0d,Name:"forge.swimSpeed"},{Base:16.0d,Name:"generic.followRange"}],Invulnerable:0b,FallFlying:0b,ForcedAge:0,PortalCooldown:0,AbsorptionAmount:0.0f,FallDistance:0.08501077f,InLove:0,DeathTime:0s,ForgeCaps:{"dsurround:emojidata":{as:0,es:0,et:0},"llibrary:extendedentitydatacapability":{"mm:living":{frozenYaw:0.0f,freezeProgress:0.0f,frozenPitch:0.0f,frozenYawHead:0.0f,frozenEntityID:-1,frozenLimbSwingAmount:0.0f,frozenRenderYawOffset:0.0f,frozenSwingProgress:0.0f}}},HandDropChances:[0.085f,0.0f],PersistenceRequired:0b,Age:0,Motion:[0.0d,-0.05280517040807792d,0.0d],Leashed:0b,Health:4.0f,LeftHanded:0b,Air:300s,OnGround:0b,Dimension:0,Rotation:[89.944626f,0.0f],UpdateBlocked:0b,HandItems:[{},{}],ArmorDropChances:[0.085f,0.085f,0.085f,0.085f],EggLayTime:6004,Pos:[896.8250000029802d,133.56808447359708d,27.498722948726886d],Fire:-1s,ArmorItems:[{},{},{},{}],CanPickUpLoot:0b,HurtTime:0s}}
:enddata
:endentity

entity:
plugin=entity
number=10
data:
JSON:{yOffset:0.0f,xOffset:0.25f,rotation:99.24771f,mobID:"minecraft:item",zOffset:0.125f,position:3023858303002L,entityData:{Motion:[0.0d,-0.0d,0.0d],Health:5s,Invulnerable:0b,Air:300s,OnGround:1b,Dimension:0,PortalCooldown:0,Rotation:[279.2477f,0.0f],UpdateBlocked:0b,FallDistance:0.0f,Item:{id:"minecraft:egg",Count:1b,Damage:0s},Pos:[896.75d,133.0d,27.875d],PickupDelay:0s,Fire:-1s,ForgeCaps:{"llibrary:extendedentitydatacapability":{}},Lifespan:6000,Age:3360s}}
:enddata
:endentity

