# Ancient Warfare Structure Template File
# Auto-generated structure template file. created on: 8/28/2018 at: 17:29:59
# Lines beginning with # denote comments

header:
version=2.3
name=wall_bandit_corner
size=16,6,16
offset=15,1,15
:endheader

#### VALIDATION ####
validation:
type=ground
survival=false
worldGenEnabled=false
unique=false
preserveBlocks=false
selectionWeight=0
clusterValue=0
minDuplicateDistance=0
dimensionWhiteList=false
dimensionList=
biomeWhiteList=false
biomeList=
leveling=0
fill=0
border=0
blockSwap=false
data:
:enddata
:endvalidation

#### LAYERS ####
layer: 0
2,2,2,2,2,2,2,2,2,2,2,2,2,2,2,1
2,2,2,2,2,2,2,2,2,2,2,2,2,2,2,1
2,2,2,2,2,2,2,2,2,2,2,2,2,2,2,1
2,2,2,2,2,2,2,2,2,2,2,2,2,2,2,1
2,2,2,2,2,2,2,2,2,2,2,2,2,2,2,1
2,2,2,2,2,2,2,2,2,2,2,2,2,2,2,1
2,2,2,2,2,2,2,2,2,2,2,2,2,2,2,1
2,2,2,2,2,2,2,2,2,2,2,2,2,2,2,1
2,2,2,2,2,2,2,2,2,2,2,2,2,2,2,1
2,2,2,2,2,2,2,2,2,2,2,2,2,2,2,1
2,2,2,2,2,2,2,2,2,2,2,2,2,2,2,1
2,2,2,2,2,2,2,2,2,2,2,2,2,2,2,1
2,2,2,2,2,2,2,2,2,2,2,2,2,2,2,1
2,2,2,2,2,2,2,2,2,2,2,2,2,2,2,1
2,2,2,2,2,2,2,2,2,2,2,2,2,2,2,1
1,1,1,1,1,1,1,1,1,1,1,1,1,1,1,1
:endlayer
layer: 1
0,0,0,0,0,0,0,0,0,0,0,0,0,0,5,3
0,0,0,0,0,0,0,0,0,0,0,0,0,0,0,3
0,0,0,0,0,0,0,0,0,0,0,0,0,8,0,3
0,0,0,0,0,0,0,0,0,0,0,0,0,7,0,3
0,0,0,0,0,0,0,0,0,0,0,0,0,0,5,3
0,0,0,0,0,0,0,0,0,0,0,0,0,0,0,3
0,0,0,0,0,0,0,0,0,0,0,0,0,0,0,3
0,0,0,0,0,0,0,0,0,0,0,0,0,0,0,3
0,0,0,0,0,0,0,0,0,0,0,0,0,0,5,3
0,0,0,0,0,0,0,0,0,0,0,0,0,0,0,3
0,0,0,0,0,0,0,0,0,0,0,0,0,0,0,3
0,0,0,0,0,0,0,0,0,0,0,0,0,0,0,3
0,0,0,0,0,0,0,0,0,0,0,0,0,0,5,3
0,0,4,6,0,0,0,0,0,0,0,0,0,0,0,3
0,0,0,5,0,0,0,5,0,0,0,5,0,0,0,3
3,3,3,3,3,3,3,3,3,3,3,3,3,3,3,3
:endlayer
layer: 2
0,0,0,0,0,0,0,0,0,0,0,0,0,9,4,3
0,0,0,0,0,0,0,0,0,0,0,0,0,10,4,3
0,0,0,0,0,0,0,0,0,0,0,0,0,7,4,3
0,0,0,0,0,0,0,0,0,0,0,0,0,0,4,3
0,0,0,0,0,0,0,0,0,0,0,0,0,0,4,3
0,0,0,0,0,0,0,0,0,0,0,0,0,0,4,3
0,0,0,0,0,0,0,0,0,0,0,0,0,0,4,3
0,0,0,0,0,0,0,0,0,0,0,0,0,0,4,3
0,0,0,0,0,0,0,0,0,0,0,0,0,0,4,3
0,0,0,0,0,0,0,0,0,0,0,0,0,0,4,3
0,0,0,0,0,0,0,0,0,0,0,0,0,0,4,3
0,0,0,0,0,0,0,0,0,0,0,0,0,0,4,3
0,0,0,0,0,0,0,0,0,0,0,0,0,0,4,3
9,10,6,0,0,0,0,0,0,0,0,0,0,0,4,3
8,8,8,8,8,8,8,8,8,8,8,8,8,8,8,3
3,3,3,3,3,3,3,3,3,3,3,3,3,3,3,3
:endlayer
layer: 3
0,0,0,0,0,0,0,0,0,0,0,0,0,0,11,3
0,0,0,0,0,0,0,0,0,0,0,0,0,0,11,3
0,0,0,0,0,0,0,0,0,0,0,0,0,0,11,3
0,0,0,0,0,0,0,0,0,0,0,0,0,0,11,3
0,0,0,0,0,0,0,0,0,0,0,0,0,0,11,3
0,0,0,0,0,0,0,0,0,0,0,0,0,0,11,3
0,0,0,0,0,0,0,0,0,0,0,0,0,0,11,3
0,0,0,0,0,0,0,0,0,0,0,0,0,0,11,3
0,0,0,0,0,0,0,0,0,0,0,0,0,0,11,3
0,0,0,0,0,0,0,0,0,0,0,0,0,0,11,3
0,0,0,0,0,0,0,0,0,0,0,0,0,0,11,3
0,0,0,0,0,0,0,0,0,0,0,0,0,0,11,3
0,0,0,0,0,0,0,0,0,0,0,0,0,0,11,3
0,0,0,0,0,0,0,0,0,0,0,0,0,0,11,3
11,11,11,11,11,11,11,11,11,11,11,11,11,11,11,3
3,3,3,3,3,3,3,3,3,3,3,3,3,3,3,3
:endlayer
layer: 4
0,0,0,0,0,0,0,0,0,0,0,0,0,0,0,3
0,0,0,0,0,0,0,0,0,0,0,0,0,0,0,0
0,0,0,0,0,0,0,0,0,0,0,0,0,0,0,3
0,0,0,0,0,0,0,0,0,0,0,0,0,0,0,0
0,0,0,0,0,0,0,0,0,0,0,0,0,0,0,3
0,0,0,0,0,0,0,0,0,0,0,0,0,0,0,0
0,0,0,0,0,0,0,0,0,0,0,0,0,0,0,3
0,0,0,0,0,0,0,0,0,0,0,0,0,0,0,0
0,0,0,0,0,0,0,0,0,0,0,0,0,0,0,3
0,0,0,0,0,0,0,0,0,0,0,0,0,0,0,0
0,0,0,0,0,0,0,0,0,0,0,0,0,0,0,3
0,0,0,0,0,0,0,0,0,0,0,0,0,0,0,0
0,0,0,0,0,0,0,0,0,0,0,0,0,0,0,3
0,0,0,0,0,0,0,0,0,0,0,0,0,0,0,0
0,0,0,0,0,0,0,0,0,0,0,0,0,0,0,3
0,3,0,3,0,3,0,3,0,3,0,3,0,3,0,3
:endlayer
layer: 5
0,0,0,0,0,0,0,0,0,0,0,0,0,0,0,5
0,0,0,0,0,0,0,0,0,0,0,0,0,0,0,0
0,0,0,0,0,0,0,0,0,0,0,0,0,0,0,0
0,0,0,0,0,0,0,0,0,0,0,0,0,0,0,0
0,0,0,0,0,0,0,0,0,0,0,0,0,0,0,5
0,0,0,0,0,0,0,0,0,0,0,0,0,0,0,0
0,0,0,0,0,0,0,0,0,0,0,0,0,0,0,0
0,0,0,0,0,0,0,0,0,0,0,0,0,0,0,0
0,0,0,0,0,0,0,0,0,0,0,0,0,0,0,5
0,0,0,0,0,0,0,0,0,0,0,0,0,0,0,0
0,0,0,0,0,0,0,0,0,0,0,0,0,0,0,0
0,0,0,0,0,0,0,0,0,0,0,0,0,0,0,0
0,0,0,0,0,0,0,0,0,0,0,0,0,0,0,5
0,0,0,0,0,0,0,0,0,0,0,0,0,0,0,0
0,0,0,0,0,0,0,0,0,0,0,0,0,0,0,0
0,0,0,5,0,0,0,5,0,0,0,5,0,0,0,5
:endlayer

#### RULES ####
rule:
plugin=vanillaBlocks
number=1
data:
JSON:{buildPass:0,blockName:"minecraft:dirt",meta:0}
:enddata
:endrule

rule:
plugin=vanillaBlocks
number=2
data:
JSON:{buildPass:0,blockName:"minecraft:grass",meta:0}
:enddata
:endrule

rule:
plugin=vanillaBlocks
number=3
data:
JSON:{buildPass:0,blockName:"minecraft:log",meta:0}
:enddata
:endrule

rule:
plugin=vanillaBlocks
number=4
data:
JSON:{buildPass:0,blockName:"minecraft:oak_stairs",meta:4}
:enddata
:endrule

rule:
plugin=vanillaBlocks
number=5
data:
JSON:{buildPass:2,blockName:"minecraft:torch",meta:5}
:enddata
:endrule

rule:
plugin=vanillaBlocks
number=6
data:
JSON:{buildPass:0,blockName:"minecraft:oak_stairs",meta:1}
:enddata
:endrule

rule:
plugin=vanillaBlocks
number=7
data:
JSON:{buildPass:0,blockName:"minecraft:oak_stairs",meta:3}
:enddata
:endrule

rule:
plugin=vanillaBlocks
number=8
data:
JSON:{buildPass:0,blockName:"minecraft:oak_stairs",meta:6}
:enddata
:endrule

rule:
plugin=vanillaBlocks
number=9
data:
JSON:{buildPass:0,blockName:"minecraft:wooden_slab",meta:8}
:enddata
:endrule

rule:
plugin=vanillaBlocks
number=10
data:
JSON:{buildPass:0,blockName:"minecraft:double_wooden_slab",meta:0}
:enddata
:endrule

rule:
plugin=vanillaBlocks
number=11
data:
JSON:{buildPass:0,blockName:"minecraft:wooden_slab",meta:0}
:enddata
:endrule

#### ENTITIES ####
