# Ancient Warfare Structure Template File
# Auto-generated structure template file. created on: 12/21/2014 at: 14:42:7
# Lines beginning with # denote comments

header:
version=2.1
name=wall_cobble_corner
size=17,12,17
offset=15,1,15
:endheader

#### VALIDATION ####
validation:
type=ground
survival=false
worldGenEnabled=false
unique=false
preserveBlocks=false
selectionWeight=0
clusterValue=0
minDuplicateDistance=0
dimensionWhiteList=false
dimensionList=
biomeWhiteList=false
biomeList=
leveling=0
fill=0
border=0
blockSwap=false
data:
:enddata
:endvalidation

#### LAYERS ####
layer: 0
1,1,1,1,1,1,1,1,1,1,1,1,2,2,2,1,1
1,1,1,1,1,1,1,1,1,1,1,1,2,2,2,1,1
1,1,1,1,1,1,1,1,1,1,1,1,2,2,2,1,1
1,1,1,1,1,1,1,1,1,1,1,1,2,2,2,1,1
1,1,1,1,1,1,1,1,1,1,1,3,2,2,2,1,1
1,1,1,1,1,1,1,1,1,1,1,1,2,2,2,1,1
1,1,1,1,1,1,1,1,1,1,1,1,2,2,2,1,1
1,1,1,1,1,1,1,1,1,1,1,1,2,2,2,1,1
1,1,1,1,1,1,1,1,1,1,1,1,2,2,2,1,1
1,1,1,1,1,1,1,1,1,2,2,2,2,2,2,1,1
1,1,1,1,1,1,1,1,1,2,2,2,2,2,2,3,1
1,1,1,1,3,1,1,1,1,2,2,2,2,2,2,3,1
2,2,2,2,2,2,2,2,2,2,2,2,2,2,2,3,1
2,2,2,2,2,2,2,2,2,2,2,2,2,2,2,3,1
2,2,2,2,2,2,2,2,2,2,2,2,2,2,2,3,1
1,1,1,1,1,1,1,1,1,1,3,3,3,3,3,1,1
1,1,1,1,1,1,1,1,1,1,1,1,1,1,1,1,1
:endlayer
layer: 1
0,4,0,0,0,4,0,0,0,4,0,0,2,0,2,0,0
0,0,0,0,0,0,0,0,0,0,0,0,2,0,2,0,0
4,0,0,0,0,0,0,0,0,0,0,0,2,0,2,0,0
0,0,0,0,0,0,0,4,0,0,0,0,2,0,2,0,0
0,0,0,0,0,0,0,0,0,0,0,2,2,4,2,0,0
0,0,0,4,0,0,0,0,0,0,0,5,2,0,2,0,0
4,0,0,0,0,0,0,0,0,0,0,0,2,0,2,0,0
0,0,0,0,0,0,0,0,0,0,0,0,2,0,2,0,0
0,0,0,0,0,0,0,4,0,0,0,0,2,0,2,0,0
0,0,0,0,0,0,0,0,0,0,2,0,2,4,2,0,0
4,0,0,0,0,0,0,0,0,2,0,0,0,0,0,2,0
0,0,0,0,2,6,0,0,0,0,0,4,0,0,0,2,0
2,2,2,2,2,2,2,2,2,2,0,0,0,0,0,2,0
0,0,0,0,4,0,0,0,0,4,0,0,0,4,0,2,0
2,2,2,2,2,2,2,2,2,2,0,0,0,0,0,2,0
0,0,0,0,0,0,0,0,0,0,2,2,2,2,2,0,0
0,0,0,0,0,0,0,0,0,0,0,0,0,0,0,0,0
:endlayer
layer: 2
0,0,0,0,0,0,0,0,0,0,0,0,2,0,2,0,0
0,0,0,0,0,0,0,0,0,0,0,0,2,0,2,0,0
0,0,0,0,0,0,0,0,0,0,0,0,2,0,2,0,0
0,0,0,0,0,0,0,0,0,0,0,2,2,0,2,0,0
0,0,0,0,0,0,0,0,0,0,0,5,2,0,2,0,0
0,0,0,0,0,0,0,0,0,0,0,0,2,0,2,0,0
0,0,0,0,0,0,0,0,0,0,0,0,2,0,2,0,0
0,0,0,0,0,0,0,0,0,0,0,0,2,0,2,0,0
0,0,0,0,0,0,0,0,0,0,0,0,2,0,2,0,0
0,0,0,0,0,0,0,0,0,0,2,0,2,0,2,0,0
0,0,0,0,0,0,0,0,0,2,0,0,0,0,0,2,0
0,0,0,2,6,0,0,0,0,0,0,0,0,0,0,2,0
2,2,2,2,2,2,2,2,2,2,0,0,0,0,0,2,0
0,0,0,0,0,0,0,0,0,0,0,0,0,0,0,2,0
2,2,2,2,2,2,2,2,2,2,0,0,0,0,0,2,0
0,0,0,0,0,0,0,0,0,0,2,2,2,2,2,0,0
0,0,0,0,0,0,0,0,0,0,0,0,0,0,0,0,0
:endlayer
layer: 3
0,0,0,0,0,0,0,0,0,0,0,0,2,0,2,0,0
0,0,0,0,0,0,0,0,0,0,0,0,2,0,2,0,0
0,0,0,0,0,0,0,0,0,0,0,2,2,0,2,0,0
0,0,0,0,0,0,0,0,0,0,0,5,2,0,2,0,0
0,0,0,0,0,0,0,0,0,0,0,0,2,0,2,0,0
0,0,0,0,0,0,0,0,0,0,0,0,2,0,2,0,0
0,0,0,0,0,0,0,0,0,0,0,0,2,0,2,0,0
0,0,0,0,0,0,0,0,0,0,0,0,2,0,2,0,0
0,0,0,0,0,0,0,0,0,0,0,0,2,0,2,0,0
0,0,0,0,0,0,0,0,0,0,2,2,2,0,2,0,0
0,0,0,0,0,0,0,0,0,2,0,0,0,0,0,2,0
0,0,2,6,0,0,0,0,0,2,0,0,0,0,0,2,0
2,2,2,2,2,2,2,2,2,2,0,0,0,0,0,2,0
0,0,0,0,0,0,0,0,0,0,0,0,0,0,0,2,0
2,2,2,2,2,2,2,2,2,2,0,0,0,0,0,2,0
0,0,0,0,0,0,0,0,0,0,2,2,2,2,2,0,0
0,0,0,0,0,0,0,0,0,0,0,0,0,0,0,0,0
:endlayer
layer: 4
0,0,0,0,0,0,0,0,0,0,0,2,2,0,2,0,0
0,0,0,0,0,0,0,0,0,0,0,2,2,0,2,0,0
0,0,0,0,0,0,0,0,0,0,0,5,2,0,2,7,0
0,0,0,0,0,0,0,0,0,0,0,0,2,0,2,0,0
0,0,0,0,0,0,0,0,0,0,0,0,2,0,2,0,0
0,0,0,0,0,0,0,0,0,0,0,0,2,0,2,7,0
0,0,0,0,0,0,0,0,0,0,0,0,2,0,2,0,0
0,0,0,0,0,0,0,0,0,0,0,0,2,0,2,0,0
0,0,0,0,0,0,0,0,0,0,0,0,2,0,2,0,0
0,0,0,0,0,0,0,0,0,0,2,2,2,0,2,0,0
0,0,0,0,0,0,0,0,0,2,0,0,0,0,0,2,0
2,2,6,0,0,0,0,0,0,2,0,0,0,0,0,2,0
2,2,2,2,2,2,2,2,2,2,0,0,0,0,0,2,0
0,0,0,0,0,0,0,0,0,0,0,0,0,0,0,2,0
2,2,2,2,2,2,2,2,2,2,0,0,0,0,0,2,0
0,0,8,0,0,8,0,0,0,0,2,2,2,2,2,0,0
0,0,0,0,0,0,0,0,0,0,0,0,0,0,0,0,0
:endlayer
layer: 5
0,0,0,0,0,0,0,0,0,0,0,9,2,2,2,2,0
0,0,0,0,0,0,0,0,0,0,0,9,2,2,2,2,0
0,0,0,0,0,0,0,0,0,0,0,0,2,2,2,2,0
0,0,0,0,0,0,0,0,0,0,0,0,2,2,2,2,0
0,0,0,0,0,0,0,0,0,0,0,0,2,2,2,2,0
0,0,0,0,0,0,0,0,0,0,0,0,2,2,2,2,0
0,0,0,0,0,0,0,0,0,0,0,0,2,2,2,2,0
0,0,0,0,0,0,0,0,0,0,0,0,2,2,2,2,0
0,0,0,0,0,0,0,0,0,0,0,0,2,2,2,2,0
0,0,0,0,0,0,0,0,0,0,2,2,2,2,2,2,0
0,0,0,0,0,0,0,0,0,2,2,2,2,2,2,2,0
9,9,0,0,0,0,0,0,0,2,2,2,2,2,2,2,0
2,2,2,2,2,2,2,2,2,2,2,2,2,2,2,2,0
2,2,2,2,2,2,2,2,2,2,2,2,2,2,2,2,0
2,2,2,2,2,2,2,2,2,2,2,2,2,2,2,2,0
2,2,2,2,2,2,2,2,2,2,2,2,2,2,2,0,0
0,0,0,0,0,0,0,0,0,0,0,0,0,0,0,0,0
:endlayer
layer: 6
0,0,0,0,0,0,0,0,0,0,0,0,0,0,0,0,0
0,0,0,0,0,0,0,0,0,0,0,0,0,0,0,2,0
0,0,0,0,0,0,0,0,0,0,0,0,0,4,0,0,0
0,0,0,0,0,0,0,0,0,0,0,0,0,0,0,2,0
0,0,0,0,0,0,0,0,0,0,0,0,0,0,0,0,0
0,0,0,0,0,0,0,0,0,0,0,0,0,4,0,2,0
0,0,0,0,0,0,0,0,0,0,0,0,0,0,0,0,0
0,0,0,0,0,0,0,0,0,0,0,0,0,0,0,2,0
0,0,0,0,0,0,0,0,0,0,0,0,0,0,0,0,0
0,0,0,0,0,0,0,0,0,0,2,2,2,0,2,2,0
0,0,0,0,0,0,0,0,0,2,2,2,6,4,0,2,0
0,0,0,0,0,0,0,0,0,2,2,0,0,0,0,2,0
0,0,0,0,0,0,0,0,0,2,2,0,0,0,0,2,0
0,0,4,0,0,4,0,0,0,0,4,0,0,4,0,2,0
0,0,0,0,0,0,0,0,0,2,2,0,0,0,0,2,0
2,0,2,0,2,0,2,0,2,0,2,2,2,2,2,0,0
0,0,0,0,0,0,0,0,0,0,0,0,0,0,0,0,0
:endlayer
layer: 7
0,0,0,0,0,0,0,0,0,0,0,0,0,0,0,0,0
0,0,0,0,0,0,0,0,0,0,0,0,0,0,0,0,0
0,0,0,0,0,0,0,0,0,0,0,0,0,0,0,0,0
0,0,0,0,0,0,0,0,0,0,0,0,0,0,0,0,0
0,0,0,0,0,0,0,0,0,0,0,0,0,0,0,0,0
0,0,0,0,0,0,0,0,0,0,0,0,0,0,0,0,0
0,0,0,0,0,0,0,0,0,0,0,0,0,0,0,0,0
0,0,0,0,0,0,0,0,0,0,0,0,0,0,0,0,0
0,0,0,0,0,0,0,0,0,0,0,0,0,0,0,0,0
0,0,0,0,0,0,0,0,0,0,2,2,2,0,2,0,0
0,0,0,0,0,0,0,0,0,2,2,6,0,0,0,2,0
0,0,0,0,0,0,0,0,0,2,2,0,0,0,0,2,0
0,0,0,0,0,0,0,0,0,2,2,0,0,0,0,2,0
0,0,0,0,0,0,0,0,0,0,0,0,0,0,0,2,0
0,0,0,0,0,0,0,0,0,2,2,0,0,0,0,2,0
0,0,0,0,0,0,0,0,0,0,2,2,2,2,2,0,0
0,0,0,0,0,0,0,0,0,0,0,0,0,0,0,0,0
:endlayer
layer: 8
0,0,0,0,0,0,0,0,0,0,0,0,0,0,0,0,0
0,0,0,0,0,0,0,0,0,0,0,0,0,0,0,0,0
0,0,0,0,0,0,0,0,0,0,0,0,0,0,0,0,0
0,0,0,0,0,0,0,0,0,0,0,0,0,0,0,0,0
0,0,0,0,0,0,0,0,0,0,0,0,0,0,0,0,0
0,0,0,0,0,0,0,0,0,0,0,0,0,0,0,0,0
0,0,0,0,0,0,0,0,0,0,0,0,0,0,0,0,0
0,0,0,0,0,0,0,0,0,0,0,0,0,0,0,0,0
0,0,0,0,0,0,0,0,0,0,0,0,0,0,0,0,0
0,0,0,0,0,0,0,0,0,0,2,2,2,2,2,0,0
0,0,0,0,0,0,0,0,0,2,0,0,0,0,0,2,0
0,0,0,0,0,0,0,0,0,2,10,0,0,0,0,2,0
0,0,0,0,0,0,0,0,0,2,2,0,0,0,0,2,0
0,0,0,0,0,0,0,0,0,2,2,0,0,0,0,2,0
0,0,0,0,0,0,0,0,0,2,2,0,0,0,0,2,0
0,0,0,0,0,0,0,0,0,0,2,2,2,2,2,0,0
0,0,0,0,0,0,0,0,0,0,0,0,0,0,0,0,0
:endlayer
layer: 9
0,0,0,0,0,0,0,0,0,0,0,0,0,0,0,0,0
0,0,0,0,0,0,0,0,0,0,0,0,0,0,0,0,0
0,0,0,0,0,0,0,0,0,0,0,0,0,0,0,0,0
0,0,0,0,0,0,0,0,0,0,0,0,0,0,0,0,0
0,0,0,0,0,0,0,0,0,0,0,0,0,0,0,0,0
0,0,0,0,0,0,0,0,0,0,0,0,0,0,0,0,0
0,0,0,0,0,0,0,0,0,0,0,0,0,0,0,0,0
0,0,0,0,0,0,0,0,0,0,0,0,0,0,0,0,0
0,0,0,0,0,0,0,0,0,0,0,0,0,0,0,0,0
0,0,0,0,0,0,0,0,0,0,2,2,2,2,2,0,0
0,0,0,0,0,0,0,0,0,2,0,0,0,0,0,2,0
0,0,0,0,0,0,0,0,0,2,0,0,0,0,0,2,0
0,0,0,0,0,0,0,0,0,2,10,0,0,0,0,2,0
0,0,0,0,0,0,0,0,0,2,2,0,0,0,0,2,0
0,0,0,0,0,0,0,0,0,2,2,0,0,0,0,2,0
0,0,0,0,0,0,0,0,0,0,2,2,2,2,2,0,0
0,0,0,0,0,0,0,0,0,0,0,0,0,0,0,0,0
:endlayer
layer: 10
0,0,0,0,0,0,0,0,0,0,0,0,0,0,0,0,0
0,0,0,0,0,0,0,0,0,0,0,0,0,0,0,0,0
0,0,0,0,0,0,0,0,0,0,0,0,0,0,0,0,0
0,0,0,0,0,0,0,0,0,0,0,0,0,0,0,0,0
0,0,0,0,0,0,0,0,0,0,0,0,0,0,0,0,0
0,0,0,0,0,0,0,0,0,0,0,0,0,0,0,0,0
0,0,0,0,0,0,0,0,0,0,0,0,0,0,0,0,0
0,0,0,0,0,0,0,0,0,0,0,0,0,0,0,0,0
0,0,0,0,0,0,0,0,0,0,2,2,2,2,2,0,0
0,0,0,0,0,0,0,0,0,2,2,2,2,2,2,2,0
0,0,0,0,0,0,0,0,2,2,0,2,2,2,2,2,2
0,0,0,0,0,0,0,0,2,2,0,2,2,2,2,2,2
0,0,0,0,0,0,0,0,2,2,0,2,2,2,2,2,2
0,0,0,0,0,0,0,0,2,2,10,2,2,2,2,2,2
0,0,0,0,0,0,0,0,2,2,2,2,2,2,2,2,2
0,0,0,0,0,0,0,0,0,2,2,2,2,2,2,2,0
0,0,0,0,0,0,0,0,0,0,2,2,2,2,2,0,0
:endlayer
layer: 11
0,0,0,0,0,0,0,0,0,0,0,0,0,0,0,0,0
0,0,0,0,0,0,0,0,0,0,0,0,0,0,0,0,0
0,0,0,0,0,0,0,0,0,0,0,0,0,0,0,0,0
0,0,0,0,0,0,0,0,0,0,0,0,0,0,0,0,0
0,0,0,0,0,0,0,0,0,0,0,0,0,0,0,0,0
0,0,0,0,0,0,0,0,0,0,0,0,0,0,0,0,0
0,0,0,0,0,0,0,0,0,0,0,0,0,0,0,0,0
0,0,0,0,0,0,0,0,0,0,0,0,0,0,0,0,0
0,0,0,0,0,0,0,0,0,0,2,9,2,9,2,0,0
0,0,0,0,0,0,0,0,0,9,0,0,0,0,0,9,0
0,0,0,0,0,0,0,0,2,0,0,0,0,0,0,0,2
0,0,0,0,0,0,0,0,9,0,0,4,0,4,0,0,9
0,0,0,0,0,0,0,0,2,0,0,0,0,0,0,0,2
0,0,0,0,0,0,0,0,9,0,0,4,0,4,0,0,9
0,0,0,0,0,0,0,0,2,0,0,0,0,0,0,0,2
0,0,0,0,0,0,0,0,0,9,0,0,0,0,0,9,0
0,0,0,0,0,0,0,0,0,0,2,9,2,9,2,0,0
:endlayer

#### RULES ####
rule:
plugin=vanillaBlocks
number=1
data:
JSON:{{"val":{"blockName":{"val":"minecraft:grass","id":"ss"},"meta":{"val":"0","id":"pi"},"buildPass":{"val":"0","id":"pi"}},"id":"ct"}}
:enddata
:endrule

rule:
plugin=vanillaBlocks
number=2
data:
JSON:{{"val":{"blockName":{"val":"minecraft:cobblestone","id":"ss"},"meta":{"val":"0","id":"pi"},"buildPass":{"val":"0","id":"pi"}},"id":"ct"}}
:enddata
:endrule

rule:
plugin=vanillaBlocks
number=3
data:
JSON:{{"val":{"blockName":{"val":"minecraft:dirt","id":"ss"},"meta":{"val":"0","id":"pi"},"buildPass":{"val":"0","id":"pi"}},"id":"ct"}}
:enddata
:endrule

rule:
plugin=vanillaBlocks
number=4
data:
JSON:{{"val":{"blockName":{"val":"minecraft:torch","id":"ss"},"meta":{"val":"5","id":"pi"},"buildPass":{"val":"2","id":"pi"}},"id":"ct"}}
:enddata
:endrule

rule:
plugin=vanillaBlocks
number=5
data:
JSON:{{"val":{"blockName":{"val":"minecraft:stone_stairs","id":"ss"},"meta":{"val":"3","id":"pi"},"buildPass":{"val":"0","id":"pi"}},"id":"ct"}}
:enddata
:endrule

rule:
plugin=vanillaBlocks
number=6
data:
JSON:{{"val":{"blockName":{"val":"minecraft:stone_stairs","id":"ss"},"meta":{"val":"1","id":"pi"},"buildPass":{"val":"0","id":"pi"}},"id":"ct"}}
:enddata
:endrule

rule:
plugin=vanillaBlocks
number=7
data:
JSON:{{"val":{"blockName":{"val":"minecraft:torch","id":"ss"},"meta":{"val":"1","id":"pi"},"buildPass":{"val":"2","id":"pi"}},"id":"ct"}}
:enddata
:endrule

rule:
plugin=vanillaBlocks
number=8
data:
JSON:{{"val":{"blockName":{"val":"minecraft:torch","id":"ss"},"meta":{"val":"3","id":"pi"},"buildPass":{"val":"2","id":"pi"}},"id":"ct"}}
:enddata
:endrule

rule:
plugin=vanillaBlocks
number=9
data:
JSON:{{"val":{"blockName":{"val":"minecraft:stone_slab","id":"ss"},"meta":{"val":"3","id":"pi"},"buildPass":{"val":"0","id":"pi"}},"id":"ct"}}
:enddata
:endrule

rule:
plugin=vanillaBlocks
number=10
data:
JSON:{{"val":{"blockName":{"val":"minecraft:stone_stairs","id":"ss"},"meta":{"val":"2","id":"pi"},"buildPass":{"val":"0","id":"pi"}},"id":"ct"}}
:enddata
:endrule

#### ENTITIES ####
