# Ancient Warfare Structure Template File
# Auto-generated structure template file. created on: 1/2/2019 at: 21:52:20
# Lines beginning with # denote comments

header:
version=2.8
name=NorskaIrminsulSpire
mods=
size=13,54,12
offset=5,7,11
:endheader

#### VALIDATION ####
validation:
type=ground
survival=false
worldGenEnabled=true
unique=false
preserveBlocks=false
selectionWeight=30
clusterValue=40
minDuplicateDistance=1000
dimensionWhiteList=true
dimensionList=0
biomeWhiteList=true
biomeList=minecraft:taiga_cold,minecraft:mutated_ice_flats,minecraft:mutated_taiga_cold,minecraft:ice_mountains,minecraft:ice_flats,minecraft:taiga_cold_hills,minecraft:cold_beach
leveling=25
fill=25
border=6
blockSwap=false
:endvalidation

#### LAYERS ####
layer: 0
3,3,3,3,3,3,0,1,1,1,1,1,1
3,3,3,3,1,1,1,0,1,1,1,1,1
1,1,1,1,1,1,1,1,0,1,1,1,1
1,1,1,1,1,1,1,1,1,1,1,1,1
2,1,1,1,1,1,1,1,1,1,1,1,1
1,1,1,1,1,1,1,1,1,1,1,1,0
1,1,1,1,1,1,1,1,1,1,1,1,1
1,1,1,1,1,1,1,1,1,1,1,1,1
1,1,1,1,1,1,1,1,1,1,1,1,1
1,1,1,1,1,1,1,1,1,1,1,1,1
1,1,1,1,1,1,1,1,1,1,1,1,1
1,1,1,1,1,1,1,1,1,1,1,1,1
:endlayer
layer: 1
3,3,3,3,3,1,1,1,1,1,1,1,1
3,3,3,1,1,1,1,1,1,1,1,1,1
1,1,1,1,1,1,1,1,1,1,1,1,1
1,1,1,1,1,1,1,1,1,1,1,1,1
1,1,1,1,1,1,1,1,1,1,1,1,1
1,1,1,1,1,1,1,1,1,1,1,0,0
1,1,1,0,1,1,1,1,1,1,1,0,0
1,1,0,1,1,1,1,1,1,1,1,1,1
1,1,1,1,1,1,1,1,1,1,1,1,1
1,1,1,1,1,1,1,1,1,1,1,1,1
1,1,1,1,1,1,0,0,1,1,1,1,1
1,1,1,1,1,1,1,1,1,1,1,1,1
:endlayer
layer: 2
1,3,3,1,1,1,1,1,1,1,1,1,1
1,1,2,2,1,1,1,1,1,1,1,1,1
4,1,2,2,1,1,1,1,1,1,1,1,1
1,1,1,1,1,1,1,1,1,1,1,1,1
1,1,1,1,1,1,1,1,1,1,1,1,1
1,1,1,1,1,1,1,1,1,1,1,1,1
1,1,1,0,1,1,1,1,1,1,1,0,1
1,1,0,2,1,1,1,1,1,1,1,1,1
1,1,1,1,1,1,1,1,1,1,1,1,1
1,1,1,1,1,1,1,1,1,1,1,1,1
1,1,1,1,1,1,1,1,1,1,1,1,1
1,1,1,1,1,1,0,0,1,1,1,1,1
:endlayer
layer: 3
3,3,3,3,3,3,1,1,1,3,3,3,3
3,3,3,3,3,1,5,0,7,1,3,3,3
3,3,3,3,3,1,0,6,0,1,3,3,3
3,3,3,3,3,1,0,0,0,1,3,3,3
3,3,3,3,3,1,1,1,1,1,3,3,3
3,3,3,3,3,3,3,3,3,3,3,3,3
3,3,3,3,3,3,3,3,3,3,3,3,3
3,3,3,3,3,3,3,3,3,3,3,3,3
3,3,3,3,3,3,3,3,3,3,3,3,3
3,3,3,3,3,3,3,3,3,3,3,3,3
3,3,3,3,3,3,3,3,3,3,3,3,3
3,3,3,3,3,3,3,3,3,3,3,3,3
:endlayer
layer: 4
3,3,3,3,3,3,1,1,1,3,3,3,3
3,3,3,3,3,1,0,0,0,1,3,3,3
3,3,3,3,3,1,0,0,0,1,3,3,3
3,3,3,3,3,1,0,0,0,1,3,3,3
3,3,3,3,3,1,0,0,0,1,3,3,3
3,3,3,3,3,3,1,1,1,3,3,3,3
3,3,3,3,3,3,3,3,3,3,3,3,3
3,3,3,3,3,3,3,3,3,3,3,3,3
3,3,3,3,3,3,3,3,3,3,3,3,3
3,3,3,3,3,3,3,3,3,3,3,3,3
3,3,3,3,3,3,3,3,3,3,3,3,3
3,3,3,3,3,3,3,3,3,3,3,3,3
:endlayer
layer: 5
3,3,3,3,3,3,1,1,1,3,3,3,3
3,3,3,3,3,1,0,0,0,1,3,3,3
3,3,3,3,3,1,0,0,0,1,3,3,3
3,3,3,3,3,1,0,0,0,1,3,3,3
3,3,3,3,3,1,0,0,0,1,3,3,3
3,3,3,3,3,1,0,0,0,1,3,3,3
3,3,3,3,3,3,1,1,1,3,3,3,3
3,3,3,3,3,3,3,3,3,3,3,3,3
3,3,3,3,3,3,3,3,3,3,3,3,3
3,3,3,3,3,3,3,3,3,3,3,3,3
3,3,3,3,3,3,3,3,3,3,3,3,3
3,3,3,3,3,3,3,3,3,3,3,3,3
:endlayer
layer: 6
8,8,8,8,8,8,3,3,3,3,8,8,8
8,8,8,3,3,3,1,1,1,1,3,8,8
8,8,3,3,3,1,0,0,0,1,3,3,8
8,8,3,3,3,1,0,0,0,1,3,3,8
8,8,3,3,3,1,0,0,0,1,3,8,8
8,8,3,3,3,1,0,0,0,1,8,8,8
8,8,8,8,3,1,0,0,0,1,8,8,8
8,8,8,8,3,3,1,1,1,3,8,8,8
8,8,8,8,8,8,3,3,3,8,8,8,8
8,8,8,8,8,8,3,3,3,8,8,8,8
8,8,8,8,8,8,8,8,8,8,8,8,8
8,8,8,8,8,8,8,8,8,8,8,8,8
:endlayer
layer: 7
9,9,9,9,9,9,8,3,8,8,9,9,9
9,9,9,8,3,3,3,3,3,3,3,9,9
10,10,8,3,3,3,1,1,1,3,3,8,9
9,9,3,3,8,8,1,1,1,3,8,8,9
9,9,3,3,1,1,0,0,0,1,8,9,9
9,9,8,8,1,1,0,0,0,1,9,9,9
9,9,9,10,1,1,0,0,0,1,9,9,9
9,9,9,9,1,8,1,0,1,1,9,9,9
9,10,10,9,9,9,1,1,1,9,9,9,9
9,9,10,9,9,9,1,1,1,9,9,9,9
10,9,9,9,9,9,9,9,9,9,9,9,9
9,9,9,9,9,9,9,9,9,9,9,9,9
:endlayer
layer: 8
0,0,0,0,0,0,9,8,9,9,0,0,0
0,0,0,9,8,8,3,3,3,8,8,0,0
0,0,9,8,8,8,1,1,1,3,8,9,0
0,0,8,3,9,9,1,1,1,1,9,9,0
0,0,8,3,1,1,1,1,1,0,9,0,0
0,0,9,9,1,1,1,1,1,0,0,0,0
0,0,0,0,1,1,1,0,1,1,0,0,0
0,0,11,0,1,9,1,0,1,0,0,0,0
0,0,0,0,0,0,1,0,1,0,0,0,0
0,0,0,0,0,0,0,0,0,0,0,0,0
0,0,0,0,0,0,0,0,0,0,0,0,0
0,0,0,0,0,0,0,0,0,0,0,0,0
:endlayer
layer: 9
0,0,0,0,0,0,0,10,0,0,0,0,0
0,0,0,0,9,9,3,8,8,9,9,0,0
0,0,0,9,9,9,1,0,0,8,9,0,0
0,0,9,8,0,1,1,1,1,1,0,0,0
0,0,9,8,1,1,1,1,1,1,0,0,0
0,0,0,0,1,1,1,1,1,1,0,0,0
0,0,0,0,1,1,1,1,1,1,0,0,0
0,0,0,0,1,1,1,0,1,0,0,0,0
0,0,0,0,0,0,1,0,1,0,0,0,0
0,0,0,0,0,0,0,0,0,0,0,0,0
0,0,0,0,0,0,0,0,0,0,0,0,0
0,0,0,0,0,0,0,0,0,0,0,0,0
:endlayer
layer: 10
0,0,0,0,0,0,0,0,0,0,0,0,0
0,0,0,0,0,0,8,9,10,0,0,0,0
0,0,0,0,0,0,1,1,8,9,0,0,0
0,0,0,9,0,1,1,1,1,1,0,0,0
0,0,0,9,1,1,1,1,1,1,0,0,0
0,0,0,0,1,1,1,1,1,1,1,0,0
0,0,0,0,1,1,1,1,1,1,1,0,0
0,0,0,0,1,1,1,1,1,0,0,0,0
0,0,0,0,0,0,1,1,1,0,0,0,0
0,0,0,0,0,0,0,0,0,0,0,0,0
0,0,0,0,0,0,0,0,0,0,0,0,0
0,0,0,0,0,0,0,0,0,0,0,0,0
:endlayer
layer: 11
0,0,0,0,0,0,0,0,0,0,0,0,0
0,0,0,0,0,0,9,0,0,0,0,0,0
0,0,0,0,0,0,1,8,9,0,0,0,0
0,0,0,0,0,1,1,1,1,1,0,0,0
0,0,0,0,1,1,1,1,1,1,1,0,0
0,0,0,0,1,1,1,1,1,1,1,0,0
0,0,0,0,8,1,1,1,1,1,8,0,0
0,0,0,0,0,1,1,1,1,1,0,0,0
0,0,0,0,0,0,1,1,8,0,0,0,0
0,0,0,0,0,0,0,0,0,0,0,0,0
0,0,0,0,0,0,0,0,0,0,0,0,0
0,0,0,0,0,0,0,0,0,0,0,0,0
:endlayer
layer: 12
0,0,0,0,0,0,0,0,0,0,0,0,0
0,0,0,0,0,0,0,0,0,0,0,0,0
0,0,0,0,0,0,8,9,0,0,0,0,0
0,0,0,0,0,1,1,1,1,1,0,0,0
0,0,0,0,8,1,1,1,1,1,8,0,0
0,0,0,0,8,1,1,1,1,1,1,0,0
0,0,0,0,9,1,1,1,1,1,9,0,0
0,0,0,0,0,1,1,1,1,1,0,0,0
0,0,0,0,0,0,8,8,9,0,0,0,0
0,0,0,0,0,0,0,0,0,0,0,0,0
0,0,0,0,0,0,0,0,0,0,0,0,0
0,0,0,0,0,0,0,0,0,0,0,0,0
:endlayer
layer: 13
0,0,0,0,0,0,0,0,0,0,0,0,0
0,0,0,0,0,0,0,0,0,0,0,0,0
0,0,0,0,0,0,9,0,0,0,0,0,0
0,0,0,0,0,1,1,1,1,1,0,0,0
0,0,0,0,9,1,1,1,1,1,9,0,0
0,0,0,0,9,1,1,1,1,1,8,0,0
0,0,0,0,0,1,1,1,1,1,0,0,0
0,0,0,0,0,1,1,1,1,1,0,0,0
0,0,0,0,0,0,9,9,0,0,0,0,0
0,0,0,0,0,0,0,0,0,0,0,0,0
0,0,0,0,0,0,0,0,0,0,0,0,0
0,0,0,0,0,0,0,0,0,0,0,0,0
:endlayer
layer: 14
0,0,0,0,0,0,0,0,0,0,0,0,0
0,0,0,0,0,0,0,0,0,0,0,0,0
0,0,0,0,0,0,0,0,0,0,0,0,0
0,0,0,0,0,1,1,1,1,1,0,0,0
0,0,0,0,1,1,1,1,1,1,0,0,0
0,0,0,0,1,1,1,1,1,1,9,0,0
0,0,0,0,1,1,1,1,1,1,1,0,0
0,0,0,0,0,1,1,1,1,1,0,0,0
0,0,0,0,0,0,0,1,0,0,0,0,0
0,0,0,0,0,0,0,0,0,0,0,0,0
0,0,0,0,0,0,0,0,0,0,0,0,0
0,0,0,0,0,0,0,0,0,0,0,0,0
:endlayer
layer: 15
0,0,0,0,0,0,0,0,0,0,0,0,0
0,0,0,0,0,0,0,0,0,0,0,0,0
0,0,0,0,0,0,0,0,0,0,0,0,0
0,0,0,0,0,1,1,1,1,1,0,0,0
0,0,0,0,1,1,1,1,1,1,1,0,0
0,0,0,0,1,1,1,1,1,1,1,0,0
0,0,0,0,1,1,1,1,1,1,8,0,0
0,0,0,0,0,1,1,1,1,1,0,0,0
0,0,0,0,0,0,0,1,1,0,0,0,0
0,0,0,0,0,0,0,0,0,0,0,0,0
0,0,0,0,0,0,0,0,0,0,0,0,0
0,0,0,0,0,0,0,0,0,0,0,0,0
:endlayer
layer: 16
0,0,0,0,0,0,0,0,0,0,0,0,0
0,0,0,0,0,0,0,0,0,0,0,0,0
0,0,0,0,0,0,0,0,0,0,0,0,0
0,0,0,0,1,1,1,1,1,8,0,0,0
0,0,0,0,1,1,1,1,1,1,8,0,0
0,0,0,0,1,1,1,1,1,1,1,0,0
0,0,0,0,1,1,1,1,1,1,9,0,0
0,0,0,0,1,1,1,1,1,1,0,0,0
0,0,0,0,0,0,1,1,8,0,0,0,0
0,0,0,0,0,0,0,0,0,0,0,0,0
0,0,0,0,0,0,0,0,0,0,0,0,0
0,0,0,0,0,0,0,0,0,0,0,0,0
:endlayer
layer: 17
0,0,0,0,0,0,0,0,0,0,0,0,0
0,0,0,0,0,0,0,0,0,0,0,0,0
0,0,0,0,0,1,0,0,0,0,0,0,0
0,0,0,0,1,1,1,1,1,9,0,0,0
0,0,0,0,1,1,1,1,1,1,9,0,0
0,0,0,0,1,1,1,1,1,1,8,0,0
0,0,0,0,1,1,1,1,1,1,0,0,0
0,0,0,0,1,1,1,1,1,8,0,0,0
0,0,0,0,0,1,1,1,9,0,0,0,0
0,0,0,0,0,0,0,0,0,0,0,0,0
0,0,0,0,0,0,0,0,0,0,0,0,0
0,0,0,0,0,0,0,0,0,0,0,0,0
:endlayer
layer: 18
0,0,0,0,0,0,0,0,0,0,0,0,0
0,0,0,0,0,0,0,0,0,0,0,0,0
0,0,0,0,0,8,0,0,0,0,0,0,0
0,0,0,0,1,1,1,1,1,0,0,0,0
0,0,0,0,1,1,1,1,1,1,0,0,0
0,0,0,1,1,1,1,1,1,1,9,0,0
0,0,0,0,1,1,1,1,1,1,0,0,0
0,0,0,0,1,1,1,1,1,9,0,0,0
0,0,0,0,0,1,1,1,0,0,0,0,0
0,0,0,0,0,0,0,0,0,0,0,0,0
0,0,0,0,0,0,0,0,0,0,0,0,0
0,0,0,0,0,0,0,0,0,0,0,0,0
:endlayer
layer: 19
0,0,0,0,0,0,0,0,0,0,0,0,0
0,0,0,0,0,0,0,0,0,0,0,0,0
0,0,0,0,0,9,0,0,0,0,0,0,0
0,0,0,0,1,1,1,1,1,0,0,0,0
0,0,0,0,1,1,1,1,1,1,0,0,0
0,0,0,1,1,1,1,1,1,1,0,0,0
0,0,0,1,1,1,1,1,1,1,0,0,0
0,0,0,0,1,1,1,1,1,0,0,0,0
0,0,0,0,1,1,1,1,1,0,0,0,0
0,0,0,0,0,0,0,0,0,0,0,0,0
0,0,0,0,0,0,0,0,0,0,0,0,0
0,0,0,0,0,0,0,0,0,0,0,0,0
:endlayer
layer: 20
0,0,0,0,0,0,0,0,0,0,0,0,0
0,0,0,0,0,0,0,0,0,0,0,0,0
0,0,0,0,0,0,8,8,0,0,0,0,0
0,0,0,0,1,1,1,1,1,0,0,0,0
0,0,0,0,1,1,1,1,1,8,0,0,0
0,0,0,8,1,1,1,1,1,1,0,0,0
0,0,0,1,1,1,1,1,1,1,0,0,0
0,0,0,1,1,1,1,1,1,0,0,0,0
0,0,0,0,1,1,1,1,1,0,0,0,0
0,0,0,0,0,1,1,0,0,0,0,0,0
0,0,0,0,0,0,0,0,0,0,0,0,0
0,0,0,0,0,0,0,0,0,0,0,0,0
:endlayer
layer: 21
0,0,0,0,0,0,0,0,0,0,0,0,0
0,0,0,0,0,0,0,0,0,0,0,0,0
0,0,0,0,0,0,9,9,0,0,0,0,0
0,0,0,0,8,1,1,1,8,0,0,0,0
0,0,0,0,1,1,1,1,1,9,0,0,0
0,0,0,9,1,1,1,1,1,1,0,0,0
0,0,0,1,1,1,1,1,1,1,0,0,0
0,0,0,1,1,1,1,1,1,1,0,0,0
0,0,0,0,1,1,1,1,1,0,0,0,0
0,0,0,0,0,8,1,1,0,0,0,0,0
0,0,0,0,0,0,0,0,0,0,0,0,0
0,0,0,0,0,0,0,0,0,0,0,0,0
:endlayer
layer: 22
0,0,0,0,0,0,0,0,0,0,0,0,0
0,0,0,0,0,0,0,0,0,0,0,0,0
0,0,0,0,0,0,0,0,0,0,0,0,0
0,0,0,0,9,8,1,1,9,0,0,0,0
0,0,0,0,1,1,1,1,1,0,0,0,0
0,0,0,0,1,1,1,1,1,1,0,0,0
0,0,0,8,1,1,1,1,1,1,0,0,0
0,0,0,1,1,1,1,1,1,1,0,0,0
0,0,0,0,1,1,1,1,1,1,0,0,0
0,0,0,0,0,9,8,1,1,0,0,0,0
0,0,0,0,0,0,0,0,0,0,0,0,0
0,0,0,0,0,0,0,0,0,0,0,0,0
:endlayer
layer: 23
0,0,0,0,0,0,0,0,0,0,0,0,0
0,0,0,0,0,0,0,0,0,0,0,0,0
0,0,0,0,0,0,0,0,0,0,0,0,0
0,0,0,0,0,9,8,8,0,0,0,0,0
0,0,0,0,8,1,1,1,1,0,0,0,0
0,0,0,0,1,1,1,1,1,1,0,0,0
0,0,0,9,1,1,1,1,1,1,1,0,0
0,0,0,8,1,1,1,1,1,1,1,0,0
0,0,0,0,1,1,1,1,1,1,1,0,0
0,0,0,0,0,0,9,1,1,1,0,0,0
0,0,0,0,0,0,0,0,1,0,0,0,0
0,0,0,0,0,0,0,0,0,0,0,0,0
:endlayer
layer: 24
0,0,0,0,0,0,0,0,0,0,0,0,0
0,0,0,0,0,0,0,0,0,0,0,0,0
0,0,0,0,0,0,0,0,0,0,0,0,0
0,0,0,0,0,0,9,9,0,0,0,0,0
0,0,0,0,9,8,1,1,1,0,0,0,0
0,0,0,0,8,1,1,1,1,1,0,0,0
0,0,0,0,1,1,1,1,1,1,1,0,0
0,0,0,9,1,1,1,1,1,1,1,0,0
0,0,0,0,8,1,1,1,1,1,1,0,0
0,0,0,0,0,0,1,1,1,1,0,0,0
0,0,0,0,0,0,0,1,8,0,0,0,0
0,0,0,0,0,0,0,0,0,0,0,0,0
:endlayer
layer: 25
0,0,0,0,0,0,0,0,0,0,0,0,0
0,0,0,0,0,0,0,0,0,0,0,0,0
0,0,0,0,0,0,0,0,0,0,0,0,0
0,0,0,0,0,0,0,0,0,0,0,0,0
0,0,0,0,0,9,1,1,1,1,1,0,0
0,0,0,0,9,1,1,1,1,1,1,0,0
0,0,0,0,1,1,1,1,1,1,1,0,0
0,0,0,0,8,1,1,1,1,1,1,0,0
0,0,0,0,9,1,1,1,1,1,1,0,0
0,0,0,0,0,0,1,1,1,1,0,0,0
0,0,0,0,0,0,1,8,9,0,0,0,0
0,0,0,0,0,0,0,0,0,0,0,0,0
:endlayer
layer: 26
0,0,0,0,0,0,0,0,0,0,0,0,0
0,0,0,0,0,0,0,0,0,0,0,0,0
0,0,0,0,0,0,0,0,0,0,0,0,0
0,0,0,0,0,0,0,1,1,1,0,0,0
0,0,0,0,0,0,1,1,1,1,1,0,0
0,0,0,0,0,1,1,1,1,1,1,1,0
0,0,0,0,8,1,1,1,1,1,1,0,0
0,0,0,0,9,1,1,1,1,1,1,0,0
0,0,0,0,0,8,1,1,1,1,1,0,0
0,0,0,0,0,0,8,1,1,1,0,0,0
0,0,0,0,0,0,8,9,0,0,0,0,0
0,0,0,0,0,0,0,0,0,0,0,0,0
:endlayer
layer: 27
0,0,0,0,0,0,0,0,0,0,0,0,0
0,0,0,0,0,0,0,0,0,0,0,0,0
0,0,0,0,0,0,0,0,1,0,0,0,0
0,0,0,0,0,0,0,1,1,1,1,0,0
0,0,0,0,0,0,1,1,1,1,1,1,0
0,0,0,0,0,1,1,1,1,1,1,1,0
0,0,0,0,9,1,1,1,1,1,1,0,0
0,0,0,0,0,1,1,1,1,1,1,0,0
0,0,0,0,0,9,1,1,1,1,1,0,0
0,0,0,0,0,0,9,1,1,1,0,0,0
0,0,0,0,0,0,9,0,0,0,0,0,0
0,0,0,0,0,0,0,0,0,0,0,0,0
:endlayer
layer: 28
0,0,0,0,0,0,0,0,0,0,0,0,0
0,0,0,0,0,0,0,0,0,0,0,0,0
0,0,0,0,0,0,0,1,1,1,0,0,0
0,0,0,0,0,0,1,1,1,1,1,0,0
0,0,0,0,0,1,1,1,1,1,1,1,0
0,0,0,0,1,1,1,1,1,1,1,1,0
0,0,0,0,0,1,1,1,1,1,1,1,0
0,0,0,0,0,1,1,1,1,1,1,0,0
0,0,0,0,0,1,1,1,1,1,1,0,0
0,0,0,0,0,0,1,1,1,1,0,0,0
0,0,0,0,0,0,0,0,1,1,0,0,0
0,0,0,0,0,0,0,0,0,0,0,0,0
:endlayer
layer: 29
0,0,0,0,0,0,0,0,0,0,0,0,0
0,0,0,0,0,0,0,0,0,1,0,0,0
0,0,0,0,0,0,1,1,1,1,1,0,0
0,0,0,0,0,1,1,1,1,1,1,1,0
0,0,0,0,1,1,1,1,1,1,1,1,0
0,0,0,0,1,1,1,1,1,1,1,1,0
0,0,0,1,1,1,1,1,1,1,1,1,0
0,0,0,0,1,1,1,1,1,1,1,1,0
0,0,0,0,0,1,1,1,1,1,1,1,0
0,0,0,0,0,1,1,1,1,1,1,0,0
0,0,0,0,0,0,1,1,1,8,0,0,0
0,0,0,0,0,0,0,0,0,0,0,0,0
:endlayer
layer: 30
0,0,0,0,0,0,0,0,0,0,0,0,0
0,0,0,0,0,0,0,0,1,1,1,0,0
0,0,0,0,0,0,1,1,1,1,1,1,0
0,0,0,0,1,1,1,1,1,1,1,1,1
0,0,0,0,1,1,1,1,1,1,1,1,1
0,0,0,0,1,1,1,1,1,1,1,1,0
0,0,0,1,1,1,1,1,1,1,1,1,1
0,0,0,1,1,1,1,1,1,1,1,1,1
0,0,0,0,1,1,1,1,1,1,1,1,0
0,0,0,0,0,1,1,1,1,1,1,0,0
0,0,0,0,0,0,1,8,8,9,0,0,0
0,0,0,0,0,0,0,0,0,0,0,0,0
:endlayer
layer: 31
0,0,0,0,0,0,0,0,0,0,0,0,0
0,0,0,0,0,0,0,0,1,1,8,0,0
0,0,0,0,0,1,1,1,1,1,1,1,0
0,0,0,0,1,1,1,1,1,1,1,1,8
0,0,0,0,1,1,1,1,1,1,1,1,1
0,0,0,1,1,1,1,1,1,1,1,1,0
0,0,0,1,1,1,1,1,1,1,1,1,1
0,0,0,1,1,1,1,1,1,1,1,1,8
0,0,0,0,1,1,1,1,1,1,1,1,0
0,0,0,0,1,1,1,1,1,1,8,0,0
0,0,0,0,0,8,8,9,9,0,0,0,0
0,0,0,0,0,0,0,0,0,0,0,0,0
:endlayer
layer: 32
0,0,0,0,0,0,0,0,0,0,0,0,0
0,0,0,0,0,0,0,1,1,1,9,0,0
0,0,0,0,0,8,1,1,1,1,1,1,0
0,0,0,0,1,1,1,1,1,1,1,1,9
0,0,0,0,1,1,1,1,1,1,1,1,1
0,0,0,1,1,1,1,1,1,1,1,1,1
0,0,0,1,1,1,1,1,1,1,1,1,1
0,0,0,1,1,1,1,1,1,1,1,1,9
0,0,0,0,1,1,1,1,1,1,1,1,0
0,0,0,0,1,1,1,8,8,8,9,0,0
0,0,0,0,0,9,9,0,0,0,0,0,0
0,0,0,0,0,0,0,0,0,0,0,0,0
:endlayer
layer: 33
0,0,0,0,0,0,0,0,0,0,0,0,0
0,0,0,0,0,0,0,8,8,8,0,0,0
0,0,0,0,0,9,8,1,1,1,1,8,0
0,0,0,0,1,8,1,1,1,1,1,1,0
0,0,0,0,1,1,1,1,1,1,1,1,1
0,0,0,1,1,1,1,1,1,1,1,1,1
0,0,0,1,1,1,1,1,1,1,1,1,8
0,0,0,8,1,1,1,1,1,1,1,1,0
0,0,0,0,1,1,1,1,1,1,1,1,0
0,0,0,0,8,1,8,9,9,9,0,0,0
0,0,0,0,0,0,0,0,0,0,0,0,0
0,0,0,0,0,0,0,0,0,0,0,0,0
:endlayer
layer: 34
0,0,0,0,0,0,0,0,0,0,0,0,0
0,0,0,0,0,0,0,9,9,9,0,0,0
0,0,0,0,1,0,9,1,1,1,1,9,0
0,0,0,0,1,0,1,1,1,1,1,1,0
0,0,0,1,1,1,1,1,1,1,1,1,8
0,0,0,1,1,1,1,1,1,1,1,1,1
0,0,0,1,1,1,1,1,1,1,1,1,9
0,0,0,9,1,1,1,1,1,1,1,1,0
0,0,0,1,1,1,1,1,1,3,1,1,0
0,0,0,0,9,8,9,0,0,0,8,0,0
0,0,0,0,0,0,0,0,0,0,0,0,0
0,0,0,0,0,0,0,0,0,0,0,0,0
:endlayer
layer: 35
0,0,0,0,0,0,0,0,0,0,0,0,0
0,0,0,0,0,1,1,1,1,1,1,0,0
0,0,0,0,8,1,1,1,1,1,1,1,0
0,0,0,0,1,1,1,1,1,1,1,1,0
0,0,0,1,1,1,1,1,1,1,1,1,9
0,0,0,1,1,1,1,1,1,1,1,1,8
0,0,1,1,1,1,1,1,1,1,1,1,0
0,0,0,1,1,1,1,1,1,1,1,8,0
0,0,0,8,1,8,8,8,8,8,1,8,0
0,0,0,0,0,9,0,0,0,0,9,0,0
0,0,0,0,0,0,0,0,0,0,0,0,0
0,0,0,0,0,0,0,0,0,0,0,0,0
:endlayer
layer: 36
0,0,0,0,0,0,0,0,0,1,0,0,0
0,0,0,0,0,8,8,1,1,1,1,0,0
0,0,0,0,9,1,1,1,1,1,1,1,0
0,0,0,0,1,1,1,1,1,1,1,1,1
0,0,0,1,1,1,1,1,1,1,1,1,0
0,0,0,1,1,1,1,1,1,1,1,1,9
0,0,8,8,1,1,1,1,1,1,1,1,0
0,0,0,8,1,1,8,8,1,1,1,9,0
0,0,0,9,8,9,9,9,9,9,8,9,0
0,0,0,0,0,0,0,0,0,0,0,0,0
0,0,0,0,0,0,0,0,0,0,0,0,0
0,0,0,0,0,0,0,0,0,0,0,0,0
:endlayer
layer: 37
0,0,0,0,0,0,0,1,1,8,0,0,0
0,0,0,0,0,9,9,1,1,1,8,0,0
0,0,0,0,0,1,1,1,1,1,1,8,0
0,0,0,1,1,1,1,1,1,1,1,1,8
0,0,1,1,1,1,1,1,1,1,1,1,1
0,0,0,3,1,1,1,1,1,1,1,1,0
0,0,9,9,3,1,1,1,1,1,1,1,0
0,0,0,9,3,1,9,9,1,1,1,1,0
0,0,0,0,9,0,0,0,0,0,9,0,0
0,0,0,0,0,0,0,0,0,0,0,0,0
0,0,0,0,0,0,0,0,0,0,0,0,0
0,0,0,0,0,0,0,0,0,0,0,0,0
:endlayer
layer: 38
0,0,0,0,0,0,8,8,8,9,0,0,0
0,0,0,0,0,1,1,1,1,8,9,0,0
0,0,0,0,1,1,1,1,1,1,8,9,0
0,0,0,1,1,1,1,1,1,1,1,8,9
0,0,1,1,1,1,1,1,1,1,1,1,8
0,0,1,1,1,1,1,1,1,1,1,1,1
0,0,1,1,1,1,1,1,1,1,1,1,1
0,0,1,1,1,1,1,1,3,3,3,8,8
0,0,0,0,1,0,0,0,0,0,0,8,0
0,0,0,0,0,0,0,0,0,0,0,0,0
0,0,0,0,0,0,0,0,0,0,0,0,0
0,0,0,0,0,0,0,0,0,0,0,0,0
:endlayer
layer: 39
0,0,0,0,0,1,9,9,9,0,0,0,0
0,0,0,0,1,1,1,1,1,9,0,0,0
0,0,0,0,1,1,1,1,1,9,9,0,0
0,0,1,1,1,1,1,1,1,1,8,9,0
0,0,1,1,1,1,1,1,1,1,1,8,9
0,0,8,1,1,1,1,1,1,1,3,1,1
0,0,8,1,1,1,1,1,1,1,1,8,8
0,0,8,1,1,1,1,1,1,1,8,10,9
0,0,0,1,1,1,8,8,8,8,3,9,0
0,0,0,0,1,0,0,0,0,0,0,0,0
0,0,0,0,0,0,0,0,0,0,0,0,0
0,0,0,0,0,0,0,0,0,0,0,0,0
:endlayer
layer: 40
0,0,0,0,0,8,0,0,0,0,0,0,0
0,0,0,0,1,1,8,8,8,0,0,0,0
0,0,0,0,1,1,1,1,1,0,0,0,0
0,0,1,1,1,1,1,1,1,8,9,0,0
0,0,8,1,1,1,1,1,1,8,8,9,0
0,0,9,1,1,1,1,1,1,1,1,1,8
0,0,9,8,1,1,1,1,8,8,8,9,9
0,0,9,8,1,1,1,1,8,8,9,0,0
0,0,0,8,1,1,9,9,9,9,12,0,0
0,0,0,0,1,0,0,0,0,0,0,0,0
0,0,0,0,0,0,0,0,0,0,0,0,0
0,0,0,0,0,0,0,0,0,0,0,0,0
:endlayer
layer: 41
0,0,0,0,0,9,0,0,0,0,0,0,0
0,0,0,0,8,8,9,9,9,0,0,0,0
0,0,0,8,8,8,8,8,8,0,0,0,0
0,0,8,1,1,1,1,1,1,9,0,0,0
0,0,9,8,1,1,1,1,1,9,9,0,0
0,0,0,8,1,1,8,8,1,1,8,8,9
0,0,0,9,8,1,13,8,0,14,14,14,0
0,0,0,9,8,1,8,13,14,14,14,14,14
0,0,0,9,8,8,0,0,14,14,12,14,14
0,0,0,0,1,0,0,0,14,14,14,14,14
0,0,0,0,0,0,0,0,0,14,14,14,0
0,0,0,0,0,0,0,0,0,0,0,0,0
:endlayer
layer: 42
0,0,0,0,0,0,0,0,0,0,0,0,0
0,0,0,0,9,9,0,0,0,0,0,0,0
0,0,0,9,9,10,9,9,9,0,0,0,0
0,0,9,3,8,8,8,13,1,0,0,0,0
0,0,0,9,8,8,15,1,1,0,0,0,0
0,0,0,9,8,8,9,9,1,13,9,9,0
0,0,0,0,9,8,9,9,0,0,9,9,0
0,0,0,0,9,8,9,9,0,0,14,9,9
0,0,0,0,9,9,0,0,9,14,12,14,0
0,0,0,0,1,0,0,0,9,9,14,0,0
0,0,0,0,0,0,0,0,0,9,9,9,0
0,0,0,0,0,0,0,0,0,0,0,0,0
:endlayer
layer: 43
0,0,0,0,0,0,0,0,0,0,0,0,0
0,0,0,0,0,0,0,0,0,0,0,0,0
0,0,0,0,0,0,0,0,0,0,0,0,0
0,0,0,0,9,9,9,9,3,0,0,0,0
0,0,0,0,9,16,0,3,1,0,0,0,0
0,0,0,0,9,16,0,0,1,1,0,0,0
0,0,0,0,0,9,0,0,0,14,14,14,0
0,0,0,0,0,10,0,0,14,14,14,14,14
0,0,0,0,0,0,0,0,14,14,12,14,14
0,0,0,0,3,0,0,0,14,14,14,14,14
0,0,0,0,0,0,0,0,0,14,14,14,0
0,0,0,0,0,0,0,0,0,0,0,0,0
:endlayer
layer: 44
0,0,0,0,0,0,0,0,0,0,0,0,0
0,0,0,0,0,0,0,0,0,0,0,0,0
0,0,0,0,0,0,0,0,0,0,0,0,0
0,0,0,0,0,0,0,13,8,0,0,0,0
0,0,0,0,0,0,0,8,8,0,0,0,0
0,0,0,0,0,0,0,0,8,8,0,0,0
0,0,0,0,0,0,0,0,0,0,0,0,0
0,0,0,0,0,0,0,0,0,0,14,0,0
0,0,0,0,0,0,0,0,9,14,12,14,0
0,0,0,0,12,0,0,0,9,0,14,0,9
0,0,0,0,0,0,0,0,0,9,9,9,0
0,0,0,0,0,0,0,0,0,0,0,0,0
:endlayer
layer: 45
0,0,0,0,0,0,0,0,0,0,0,0,0
0,0,0,0,0,0,0,0,0,0,0,0,0
0,0,0,0,0,0,0,0,0,0,0,0,0
0,0,0,0,0,0,0,8,9,0,0,0,0
0,0,0,0,0,0,0,9,16,0,0,0,0
0,0,0,0,0,0,0,0,9,9,0,0,0
0,0,0,0,0,0,0,0,0,14,14,14,0
0,0,0,0,0,0,0,0,14,14,14,14,14
0,0,0,0,14,0,0,0,14,14,12,14,14
0,0,0,14,12,14,0,0,14,14,14,14,14
0,0,0,0,14,0,0,0,0,14,14,14,0
0,0,0,0,0,0,0,0,0,0,0,0,0
:endlayer
layer: 46
0,0,0,0,0,0,0,0,0,0,0,0,0
0,0,0,0,0,0,0,0,0,0,0,0,0
0,0,0,0,0,0,0,0,0,0,0,0,0
0,0,0,0,0,0,0,17,0,0,0,0,0
0,0,0,0,0,0,0,0,0,0,0,0,0
0,0,0,0,0,0,0,0,0,0,0,0,0
0,0,0,0,0,0,0,0,0,9,9,9,0
0,0,0,14,14,14,0,0,0,0,14,9,9
0,0,14,14,14,14,14,0,9,14,12,14,9
0,0,14,14,12,14,14,0,9,9,14,9,9
0,0,14,14,14,14,14,0,0,9,9,9,0
0,0,0,14,14,14,0,0,0,0,0,0,0
:endlayer
layer: 47
0,0,0,0,0,0,0,0,0,0,0,0,0
0,0,0,0,0,0,0,0,0,0,0,0,0
0,0,0,0,0,0,0,0,0,0,0,0,0
0,0,0,0,0,0,0,18,0,0,0,0,0
0,0,0,0,0,0,0,0,0,0,0,0,0
0,0,0,0,0,0,0,0,0,0,0,0,0
0,0,0,0,0,0,0,0,0,0,0,0,0
0,0,0,9,9,9,0,0,0,0,9,0,0
0,0,9,0,14,0,9,0,0,0,12,9,0
0,0,9,14,12,14,9,0,0,0,9,0,0
0,0,9,0,14,0,9,0,0,0,0,0,0
0,0,0,9,9,9,0,0,0,0,0,0,0
:endlayer
layer: 48
0,0,0,0,0,0,0,0,0,0,0,0,0
0,0,0,0,0,0,0,0,0,0,0,0,0
0,0,0,0,0,0,0,0,0,0,0,0,0
0,0,0,0,0,0,0,19,0,0,0,0,0
0,0,0,0,0,0,0,0,0,0,0,0,0
0,0,0,0,0,0,0,0,0,0,0,0,0
0,0,0,0,0,0,0,0,0,0,0,0,0
0,0,0,0,14,14,0,0,0,0,14,0,0
0,0,14,14,14,14,14,0,0,14,14,14,0
0,0,14,14,12,14,14,0,0,0,14,0,0
0,0,14,14,14,14,14,0,0,0,0,0,0
0,0,0,14,14,14,0,0,0,0,0,0,0
:endlayer
layer: 49
0,0,0,0,0,0,0,0,0,0,0,0,0
0,0,0,0,0,0,0,0,0,0,0,0,0
0,0,0,0,0,0,0,0,0,0,0,0,0
0,0,0,0,0,0,0,20,0,0,0,0,0
0,0,0,0,0,0,0,0,0,0,0,0,0
0,0,0,0,0,0,0,0,0,0,0,0,0
0,0,0,0,0,0,0,0,0,0,0,0,0
0,0,0,0,9,9,0,0,0,0,9,0,0
0,0,9,10,14,9,9,0,0,9,9,9,0
0,0,9,14,12,14,9,0,0,0,9,0,0
0,0,9,9,14,10,9,0,0,0,0,0,0
0,0,0,9,9,9,0,0,0,0,0,0,0
:endlayer
layer: 50
0,0,0,0,0,0,0,0,0,0,0,0,0
0,0,0,0,0,0,0,0,0,0,0,0,0
0,0,0,0,0,0,0,0,0,0,0,0,0
0,0,0,0,0,0,0,21,0,0,0,0,0
0,0,0,0,0,0,0,0,0,0,0,0,0
0,0,0,0,0,0,0,0,0,0,0,0,0
0,0,0,0,0,0,0,0,0,0,0,0,0
0,0,0,0,0,0,0,0,0,0,0,0,0
0,0,0,0,9,0,0,0,0,0,0,0,0
0,0,0,9,12,9,0,0,0,0,0,0,0
0,0,0,0,9,0,0,0,0,0,0,0,0
0,0,0,0,0,0,0,0,0,0,0,0,0
:endlayer
layer: 51
0,0,0,0,0,0,0,0,0,0,0,0,0
0,0,0,0,0,0,0,0,0,0,0,0,0
0,0,0,0,0,0,0,0,0,0,0,0,0
0,0,0,0,0,0,0,22,0,0,0,0,0
0,0,0,0,0,0,0,0,0,0,0,0,0
0,0,0,0,0,0,0,0,0,0,0,0,0
0,0,0,0,0,0,0,0,0,0,0,0,0
0,0,0,0,0,0,0,0,0,0,0,0,0
0,0,0,0,14,0,0,0,0,0,0,0,0
0,0,0,14,14,14,0,0,0,0,0,0,0
0,0,0,0,14,0,0,0,0,0,0,0,0
0,0,0,0,0,0,0,0,0,0,0,0,0
:endlayer
layer: 52
0,0,0,0,0,0,0,0,0,0,0,0,0
0,0,0,0,0,0,0,0,0,0,0,0,0
0,0,0,0,0,0,0,0,0,0,0,0,0
0,0,0,0,0,0,0,23,0,0,0,0,0
0,0,0,0,0,0,0,0,0,0,0,0,0
0,0,0,0,0,0,0,0,0,0,0,0,0
0,0,0,0,0,0,0,0,0,0,0,0,0
0,0,0,0,0,0,0,0,0,0,0,0,0
0,0,0,0,9,0,0,0,0,0,0,0,0
0,0,0,9,14,9,0,0,0,0,0,0,0
0,0,0,0,9,0,0,0,0,0,0,0,0
0,0,0,0,0,0,0,0,0,0,0,0,0
:endlayer
layer: 53
0,0,0,0,0,0,0,0,0,0,0,0,0
0,0,0,0,0,0,0,0,0,0,0,0,0
0,0,0,0,0,0,0,26,0,0,0,0,0
0,0,0,0,0,0,0,25,0,0,0,0,0
0,0,0,0,0,0,0,24,0,0,0,0,0
0,0,0,0,0,0,0,0,0,0,0,0,0
0,0,0,0,0,0,0,0,0,0,0,0,0
0,0,0,0,0,0,0,0,0,0,0,0,0
0,0,0,0,0,0,0,0,0,0,0,0,0
0,0,0,0,9,0,0,0,0,0,0,0,0
0,0,0,0,0,0,0,0,0,0,0,0,0
0,0,0,0,0,0,0,0,0,0,0,0,0
:endlayer

#### RULES ####
rule:
plugin=vanillaBlocks
number=1
data:
JSON:{blockState:{blockName:"minecraft:stone",properties:{variant:"stone"}}}
:enddata
:endrule

rule:
plugin=vanillaBlocks
number=2
data:
JSON:{blockState:{blockName:"minecraft:iron_ore"}}
:enddata
:endrule

rule:
plugin=vanillaBlocks
number=3
data:
JSON:{blockState:{blockName:"minecraft:dirt",properties:{variant:"dirt",snowy:"false"}}}
:enddata
:endrule

rule:
plugin=vanillaBlocks
number=4
data:
JSON:{blockState:{blockName:"harvestcraft:pamdragonfruit",properties:{age:"2"}}}
:enddata
:endrule

rule:
plugin=inventory
number=5
data:
JSON:{blockState:{blockName:"minecraft:chest",properties:{facing:"south"}},lootLevel:0,teData:{ForgeData:{},Items:[],id:"minecraft:chest",Lock:""},inventoryData:{length:0,inventoryContents:[]},legacyFeatures:1b}
:enddata
:endrule

rule:
plugin=blockTile
number=6
data:
JSON:{blockState:{blockName:"ancientwarfarestructure:advanced_spawner",properties:{transparent:"true"}},teData:{id:"ancientwarfarestructure:advanced_spawner_tile",spawnerSettings:{minDelay:0,spawnDelay:0,lightSensitive:0b,spawnGroups:[{settingsList:[{remainingSpawnCount:1,hostile:1b,forced:1b,customTag:{},maxToSpawn:1,entityId:"grimoireofgaia:yeti",minToSpawn:1}],groupWeight:1}],playerRange:5,respondToRedstone:0b,inventory:{Size:9,Items:[]},spawnRange:0,transparent:1b,maxDelay:0,xpToDrop:0,mobRange:0,debugMode:0b,maxNearbyMonsters:0}}}
:enddata
:endrule

rule:
plugin=blockTile
number=7
data:
JSON:{blockState:{blockName:"ancientwarfarestructure:advanced_loot_chest",properties:{facing:"south"}},teData:{LootTable:"minecraft:chests/simple_dungeon",lootRolls:1b,id:"ancientwarfarestructure:advanced_loot_chest_tile",Lock:""}}
:enddata
:endrule

rule:
plugin=vanillaBlocks
number=8
data:
JSON:{blockState:{blockName:"minecraft:grass",properties:{snowy:"false"}}}
:enddata
:endrule

rule:
plugin=vanillaBlocks
number=9
data:
JSON:{blockState:{blockName:"minecraft:snow_layer",properties:{layers:"1"}}}
:enddata
:endrule

rule:
plugin=vanillaBlocks
number=10
data:
JSON:{blockState:{blockName:"minecraft:snow_layer",properties:{layers:"2"}}}
:enddata
:endrule

rule:
plugin=blockTile
number=11
data:
JSON:{blockState:{blockName:"ancientwarfarestructure:advanced_spawner",properties:{transparent:"true"}},teData:{id:"ancientwarfarestructure:advanced_spawner_tile",spawnerSettings:{minDelay:0,spawnDelay:0,lightSensitive:0b,spawnGroups:[{settingsList:[{remainingSpawnCount:1,hostile:1b,forced:1b,customTag:{},maxToSpawn:1,entityId:"grimoireofgaia:yeti",minToSpawn:1}],groupWeight:1}],playerRange:9,respondToRedstone:0b,inventory:{Size:9,Items:[]},spawnRange:0,transparent:1b,maxDelay:0,xpToDrop:0,mobRange:0,debugMode:0b,maxNearbyMonsters:0}}}
:enddata
:endrule

rule:
plugin=vanillaBlocks
number=12
data:
JSON:{blockState:{blockName:"minecraft:log",properties:{variant:"spruce",axis:"y"}}}
:enddata
:endrule

rule:
plugin=vanillaBlocks
number=13
data:
JSON:{blockState:{blockName:"minecraft:stonebrick",properties:{variant:"cracked_stonebrick"}}}
:enddata
:endrule

rule:
plugin=vanillaBlocks
number=14
data:
JSON:{blockState:{blockName:"minecraft:leaves",properties:{check_decay:"false",decayable:"true",variant:"spruce"}}}
:enddata
:endrule

rule:
plugin=vanillaBlocks
number=15
data:
JSON:{blockState:{blockName:"minecraft:stone_slab",properties:{half:"bottom",variant:"stone_brick"}}}
:enddata
:endrule

rule:
plugin=vanillaBlocks
number=16
data:
JSON:{blockState:{blockName:"minecraft:tallgrass",properties:{type:"tall_grass"}}}
:enddata
:endrule

rule:
plugin=totemPart
number=17
data:
JSON:{blockState:{blockName:"ancientwarfarestructure:totem_part",properties:{visible:"true",variant:"base",facing:"west"}},variant:5b,mainBlock:1b}
:enddata
:endrule

rule:
plugin=totemPart
number=18
data:
JSON:{blockState:{blockName:"ancientwarfarestructure:totem_part",properties:{visible:"true",variant:"base",facing:"west"}},variant:6b,mainBlock:1b}
:enddata
:endrule

rule:
plugin=totemPart
number=19
data:
JSON:{blockState:{blockName:"ancientwarfarestructure:totem_part",properties:{visible:"true",variant:"base",facing:"west"}},variant:6b,mainBlock:1b}
:enddata
:endrule

rule:
plugin=totemPart
number=20
data:
JSON:{blockState:{blockName:"ancientwarfarestructure:totem_part",properties:{visible:"true",variant:"base",facing:"west"}},variant:6b,mainBlock:1b}
:enddata
:endrule

rule:
plugin=totemPart
number=21
data:
JSON:{blockState:{blockName:"ancientwarfarestructure:totem_part",properties:{visible:"true",variant:"base",facing:"west"}},variant:6b,mainBlock:1b}
:enddata
:endrule

rule:
plugin=totemPart
number=22
data:
JSON:{blockState:{blockName:"ancientwarfarestructure:totem_part",properties:{visible:"true",variant:"base",facing:"west"}},variant:6b,mainBlock:1b}
:enddata
:endrule

rule:
plugin=totemPart
number=23
data:
JSON:{blockState:{blockName:"ancientwarfarestructure:totem_part",properties:{visible:"true",variant:"base",facing:"west"}},variant:6b,mainBlock:1b}
:enddata
:endrule

rule:
plugin=totemPart
number=24
data:
JSON:{blockState:{blockName:"ancientwarfarestructure:totem_part",properties:{visible:"true",variant:"base",facing:"west"}},variant:8b,mainBlock:1b}
:enddata
:endrule

rule:
plugin=totemPart
number=25
data:
JSON:{blockState:{blockName:"ancientwarfarestructure:totem_part",properties:{visible:"true",variant:"base",facing:"west"}},variant:7b,mainBlock:1b}
:enddata
:endrule

rule:
plugin=totemPart
number=26
data:
JSON:{blockState:{blockName:"ancientwarfarestructure:totem_part",properties:{visible:"true",variant:"base",facing:"east"}},variant:8b,mainBlock:1b}
:enddata
:endrule

#### ENTITIES ####
