# Ancient Warfare Structure Template File
# Auto-generated structure template file. created on: 11/28/2018 at: 7:36:38
# Lines beginning with # denote comments

header:
version=2.7
name=NorskaPeasantFarmTiny
mods=
size=9,43,16
offset=5,6,15
:endheader

#### VALIDATION ####
validation:
type=ground
survival=false
worldGenEnabled=true
unique=false
preserveBlocks=false
selectionWeight=50
clusterValue=20
minDuplicateDistance=1000
dimensionWhiteList=false
dimensionList=
biomeWhiteList=true
biomeList=minecraft:taiga_cold,biomesoplenty:cold_desert,traverse:snowy_coniferous_forest,minecraft:ice_mountains,biomesoplenty:alps,minecraft:ice_flats,minecraft:taiga_cold_hills,minecraft:cold_beach
leveling=3
fill=3
border=3
blockSwap=false
:endvalidation

#### LAYERS ####
layer: 0
1,1,1,1,1,1,1,1,1
1,1,1,1,1,1,1,1,1
1,1,1,1,1,1,1,1,1
1,1,1,1,1,1,1,1,1
1,1,1,1,1,1,1,1,1
1,1,1,1,1,1,1,1,1
1,1,1,1,1,1,1,1,1
1,1,1,1,1,1,1,1,1
1,1,1,1,1,1,1,1,1
1,1,1,1,1,1,1,1,1
1,1,1,1,1,1,1,1,1
1,1,1,1,1,1,1,1,1
1,1,1,1,1,1,1,1,1
1,1,1,1,1,1,1,1,1
1,1,1,1,1,1,1,1,1
1,1,1,1,1,1,1,1,1
:endlayer
layer: 1
1,1,1,1,1,1,1,1,1
1,1,1,1,1,1,1,1,1
1,1,1,1,1,1,1,1,1
1,1,1,1,1,1,1,1,1
1,1,1,1,1,1,1,1,1
1,1,1,1,1,1,1,1,1
1,1,1,1,1,1,1,1,1
1,1,1,1,1,1,1,1,1
1,1,1,1,1,1,1,1,1
1,1,1,1,1,1,1,1,1
1,1,1,1,1,1,1,1,1
1,1,1,1,1,1,1,1,1
1,1,1,1,1,1,1,1,1
1,1,1,1,1,1,1,1,1
1,1,1,1,1,1,1,1,1
1,1,1,1,1,1,1,1,1
:endlayer
layer: 2
1,1,1,1,1,1,1,1,1
1,1,1,1,1,1,1,1,1
1,1,1,1,1,1,1,1,1
1,1,1,1,1,1,1,1,1
1,1,1,1,1,1,1,1,1
1,1,1,1,1,1,1,1,1
1,1,1,1,1,1,1,1,1
1,1,1,1,1,1,1,1,1
1,1,1,1,1,1,1,1,1
1,1,1,1,1,1,1,1,1
1,1,1,1,1,1,1,1,1
1,1,1,1,1,1,1,1,1
1,1,1,1,1,1,1,1,1
1,1,1,1,1,1,1,1,1
1,1,1,1,1,1,1,1,1
1,1,1,1,1,1,1,1,1
:endlayer
layer: 3
1,1,1,1,1,1,1,1,1
1,1,1,1,1,1,1,1,1
1,1,1,1,1,1,1,1,1
1,1,1,1,1,1,1,1,1
1,1,1,1,1,1,1,1,1
1,1,1,1,1,1,1,1,1
1,1,1,1,1,1,1,1,1
1,1,1,1,1,1,1,1,1
1,1,1,1,1,1,1,1,1
1,1,1,1,1,1,1,1,1
1,1,1,1,1,1,1,1,1
1,1,1,1,1,1,1,1,1
1,1,1,1,1,1,1,1,1
1,1,1,1,1,1,1,1,1
1,1,1,1,1,1,1,1,1
1,1,1,1,1,1,1,1,1
:endlayer
layer: 4
1,1,1,1,1,1,1,1,1
1,1,1,1,1,1,1,1,1
1,1,1,1,1,1,1,1,1
1,1,1,1,1,1,1,1,1
1,1,1,1,1,1,1,1,1
1,1,1,1,1,1,1,1,1
1,1,1,1,1,1,1,1,1
1,1,1,1,1,1,1,1,1
1,1,1,1,1,1,1,1,1
1,1,1,1,1,1,1,1,1
1,1,1,1,1,1,1,1,1
1,1,1,1,1,1,1,1,1
1,1,1,1,1,1,1,1,1
1,1,1,1,1,1,1,1,1
1,1,1,1,1,1,1,1,1
1,1,1,1,1,1,1,1,1
:endlayer
layer: 5
2,2,2,2,2,2,2,2,2
2,2,2,2,2,2,2,2,2
2,2,2,2,2,2,2,2,2
2,2,2,2,2,2,2,2,2
2,2,2,2,2,2,2,2,2
2,2,2,2,2,2,2,2,2
2,2,1,2,2,1,2,2,2
2,2,1,2,2,1,2,2,2
2,2,1,1,1,1,1,2,2
2,2,1,3,3,3,1,2,2
2,2,1,3,3,3,1,2,2
2,2,3,3,3,3,1,2,2
2,2,1,3,3,3,1,2,2
2,2,1,1,1,1,1,2,2
2,2,2,2,2,2,2,2,2
2,2,2,2,2,2,2,2,2
:endlayer
layer: 6
5,5,5,5,5,5,5,5,5
5,5,4,5,5,5,5,5,5
5,5,14,14,14,14,14,5,5
5,5,14,0,14,0,14,5,5
5,5,14,0,14,0,14,5,4
5,5,14,14,14,14,14,17,5
16,5,15,0,14,0,14,5,5
5,5,15,0,14,0,14,5,5
4,5,6,6,6,6,6,5,4
5,4,6,13,12,11,6,4,5
5,5,6,0,0,10,6,5,5
5,0,9,0,0,0,6,5,5
0,0,6,0,8,7,6,5,5
5,0,6,6,6,6,6,4,5
5,5,4,5,5,5,5,5,4
0,5,5,5,5,0,5,4,0
:endlayer
layer: 7
0,0,0,0,0,0,0,0,0
0,0,0,0,0,0,0,0,0
0,0,14,0,0,0,14,0,0
0,0,0,0,0,0,0,0,0
0,0,0,0,0,0,0,0,0
0,0,0,0,0,0,22,0,0
0,0,0,0,0,0,0,0,0
0,0,0,0,0,0,0,0,0
0,0,6,18,14,18,6,0,0
0,0,14,0,0,0,18,0,0
0,0,21,0,0,0,18,0,0
0,0,20,0,0,0,18,0,0
0,19,18,0,0,0,18,0,0
0,0,6,18,18,18,6,0,0
0,0,0,0,0,0,0,0,0
0,0,0,0,0,0,0,0,0
:endlayer
layer: 8
0,0,0,0,0,0,0,0,0
0,0,0,0,0,0,0,0,0
0,24,6,18,18,18,6,23,0
0,24,0,0,0,0,0,23,0
0,24,0,0,0,0,0,23,0
0,24,0,0,0,0,0,23,0
0,24,27,0,0,0,0,23,0
0,24,26,0,25,0,0,23,0
0,24,6,18,18,18,6,23,0
0,24,18,0,0,0,18,23,0
0,24,18,0,0,0,18,23,0
0,24,18,0,0,0,18,23,0
0,24,18,0,25,0,18,23,0
0,24,6,18,18,18,6,23,0
0,0,0,0,0,0,0,0,0
0,0,0,0,0,0,0,0,0
:endlayer
layer: 9
0,0,0,0,0,0,0,0,0
0,0,0,0,25,0,0,0,0
0,0,24,18,18,18,23,0,0
0,0,24,18,18,18,23,0,0
0,0,24,18,18,18,23,0,0
0,0,24,18,18,18,23,0,0
0,0,24,18,18,18,23,0,0
0,0,24,18,18,18,23,0,0
0,0,24,18,18,18,23,0,0
0,0,24,18,18,18,23,0,0
0,0,24,18,18,18,23,0,0
0,0,24,18,18,18,23,0,0
0,0,24,18,18,18,23,0,0
0,0,24,18,18,18,23,0,0
0,0,0,0,28,0,0,0,0
0,0,0,0,0,0,0,0,0
:endlayer
layer: 10
0,0,0,0,0,0,0,0,0
0,0,0,0,0,0,0,0,0
0,0,0,24,18,23,0,0,0
0,0,0,24,18,23,0,0,0
0,0,0,24,18,23,0,0,0
0,0,0,24,18,23,0,0,0
0,0,0,24,18,23,0,0,0
0,0,0,24,18,23,0,0,0
0,0,0,24,18,23,0,0,0
0,0,0,24,18,23,0,0,0
0,0,0,24,18,23,0,0,0
0,0,0,24,18,23,0,0,0
0,0,0,24,18,23,0,0,0
0,0,0,24,18,23,0,0,0
0,0,0,0,0,0,0,0,0
0,0,0,0,0,0,0,0,0
:endlayer
layer: 11
0,0,0,0,0,0,0,0,0
0,0,0,0,32,0,0,0,0
0,0,0,0,31,0,0,0,0
0,0,0,0,5,0,0,0,0
0,0,0,0,5,0,0,0,0
0,0,0,0,5,0,0,0,0
0,0,0,0,5,0,0,0,0
0,0,0,0,5,0,0,0,0
0,0,0,0,5,0,0,0,0
0,0,0,0,5,0,0,0,0
0,0,0,0,5,0,0,0,0
0,0,0,0,5,0,0,0,0
0,0,0,0,5,0,0,0,0
0,0,0,0,30,0,0,0,0
0,0,0,0,29,0,0,0,0
0,0,0,0,0,0,0,0,0
:endlayer
layer: 12
0,0,0,0,0,0,0,0,0
0,0,0,0,0,0,0,0,0
0,0,0,0,0,0,0,0,0
0,0,0,0,0,0,0,0,0
0,0,0,0,0,0,0,0,0
0,0,0,0,0,0,0,0,0
0,0,0,0,0,0,0,0,0
0,0,0,0,0,0,0,0,0
0,0,0,0,0,0,0,0,0
0,0,0,0,0,0,0,0,0
0,0,0,0,0,0,0,0,0
0,0,0,0,0,0,0,0,0
0,0,0,0,0,0,0,0,0
0,0,0,0,0,0,0,0,0
0,0,0,0,0,0,0,0,0
0,0,0,0,0,0,0,0,0
:endlayer
layer: 13
0,0,0,0,0,0,0,0,0
0,0,0,0,0,0,0,0,0
0,0,0,0,0,0,0,0,0
0,0,0,0,0,0,0,0,0
0,0,0,0,0,0,0,0,0
0,0,0,0,0,0,0,0,0
0,0,0,0,0,0,0,0,0
0,0,0,0,0,0,0,0,0
0,0,0,0,0,0,0,0,0
0,0,0,0,0,0,0,0,0
0,0,0,0,0,0,0,0,0
0,0,0,0,0,0,0,0,0
0,0,0,0,0,0,0,0,0
0,0,0,0,0,0,0,0,0
0,0,0,0,0,0,0,0,0
0,0,0,0,0,0,0,0,0
:endlayer
layer: 14
0,0,0,0,0,0,0,0,0
0,0,0,0,0,0,0,0,0
0,0,0,0,0,0,0,0,0
0,0,0,0,0,0,0,0,0
0,0,0,0,0,0,0,0,0
0,0,0,0,0,0,0,0,0
0,0,0,0,0,0,0,0,0
0,0,0,0,0,0,0,0,0
0,0,0,0,0,0,0,0,0
0,0,0,0,0,0,0,0,0
0,0,0,0,0,0,0,0,0
0,0,0,0,0,0,0,0,0
0,0,0,0,0,0,0,0,0
0,0,0,0,0,0,0,0,0
0,0,0,0,0,0,0,0,0
0,0,0,0,0,0,0,0,0
:endlayer
layer: 15
0,0,0,0,0,0,0,0,0
0,0,0,0,0,0,0,0,0
0,0,0,0,0,0,0,0,0
0,0,0,0,0,0,0,0,0
0,0,0,0,0,0,0,0,0
0,0,0,0,0,0,0,0,0
0,0,0,0,0,0,0,0,0
0,0,0,0,0,0,0,0,0
0,0,0,0,0,0,0,0,0
0,0,0,0,0,0,0,0,0
0,0,0,0,0,0,0,0,0
0,0,0,0,0,0,0,0,0
0,0,0,0,0,0,0,0,0
0,0,0,0,0,0,0,0,0
0,0,0,0,0,0,0,0,0
0,0,0,0,0,0,0,0,0
:endlayer
layer: 16
0,0,0,0,0,0,0,0,0
0,0,0,0,0,0,0,0,0
0,0,0,0,0,0,0,0,0
0,0,0,0,0,0,0,0,0
0,0,0,0,0,0,0,0,0
0,0,0,0,0,0,0,0,0
0,0,0,0,0,0,0,0,0
0,0,0,0,0,0,0,0,0
0,0,0,0,0,0,0,0,0
0,0,0,0,0,0,0,0,0
0,0,0,0,0,0,0,0,0
0,0,0,0,0,0,0,0,0
0,0,0,0,0,0,0,0,0
0,0,0,0,0,0,0,0,0
0,0,0,0,0,0,0,0,0
0,0,0,0,0,0,0,0,0
:endlayer
layer: 17
0,0,0,0,0,0,0,0,0
0,0,0,0,0,0,0,0,0
0,0,0,0,0,0,0,0,0
0,0,0,0,0,0,0,0,0
0,0,0,0,0,0,0,0,0
0,0,0,0,0,0,0,0,0
0,0,0,0,0,0,0,0,0
0,0,0,0,0,0,0,0,0
0,0,0,0,0,0,0,0,0
0,0,0,0,0,0,0,0,0
0,0,0,0,0,0,0,0,0
0,0,0,0,0,0,0,0,0
0,0,0,0,0,0,0,0,0
0,0,0,0,0,0,0,0,0
0,0,0,0,0,0,0,0,0
0,0,0,0,0,0,0,0,0
:endlayer
layer: 18
0,0,0,0,0,0,0,0,0
0,0,0,0,0,0,0,0,0
0,0,0,0,0,0,0,0,0
0,0,0,0,0,0,0,0,0
0,0,0,0,0,0,0,0,0
0,0,0,0,0,0,0,0,0
0,0,0,0,0,0,0,0,0
0,0,0,0,0,0,0,0,0
0,0,0,0,0,0,0,0,0
0,0,0,0,0,0,0,0,0
0,0,0,0,0,0,0,0,0
0,0,0,0,0,0,0,0,0
0,0,0,0,0,0,0,0,0
0,0,0,0,0,0,0,0,0
0,0,0,0,0,0,0,0,0
0,0,0,0,0,0,0,0,0
:endlayer
layer: 19
0,0,0,0,0,0,0,0,0
0,0,0,0,0,0,0,0,0
0,0,0,0,0,0,0,0,0
0,0,0,0,0,0,0,0,0
0,0,0,0,0,0,0,0,0
0,0,0,0,0,0,0,0,0
0,0,0,0,0,0,0,0,0
0,0,0,0,0,0,0,0,0
0,0,0,0,0,0,0,0,0
0,0,0,0,0,0,0,0,0
0,0,0,0,0,0,0,0,0
0,0,0,0,0,0,0,0,0
0,0,0,0,0,0,0,0,0
0,0,0,0,0,0,0,0,0
0,0,0,0,0,0,0,0,0
0,0,0,0,0,0,0,0,0
:endlayer
layer: 20
0,0,0,0,0,0,0,0,0
0,0,0,0,0,0,0,0,0
0,0,0,0,0,0,0,0,0
0,0,0,0,0,0,0,0,0
0,0,0,0,0,0,0,0,0
0,0,0,0,0,0,0,0,0
0,0,0,0,0,0,0,0,0
0,0,0,0,0,0,0,0,0
0,0,0,0,0,0,0,0,0
0,0,0,0,0,0,0,0,0
0,0,0,0,0,0,0,0,0
0,0,0,0,0,0,0,0,0
0,0,0,0,0,0,0,0,0
0,0,0,0,0,0,0,0,0
0,0,0,0,0,0,0,0,0
0,0,0,0,0,0,0,0,0
:endlayer
layer: 21
0,0,0,0,0,0,0,0,0
0,0,0,0,0,0,0,0,0
0,0,0,0,0,0,0,0,0
0,0,0,0,0,0,0,0,0
0,0,0,0,0,0,0,0,0
0,0,0,0,0,0,0,0,0
0,0,0,0,0,0,0,0,0
0,0,0,0,0,0,0,0,0
0,0,0,0,0,0,0,0,0
0,0,0,0,0,0,0,0,0
0,0,0,0,0,0,0,0,0
0,0,0,0,0,0,0,0,0
0,0,0,0,0,0,0,0,0
0,0,0,0,0,0,0,0,0
0,0,0,0,0,0,0,0,0
0,0,0,0,0,0,0,0,0
:endlayer
layer: 22
0,0,0,0,0,0,0,0,0
0,0,0,0,0,0,0,0,0
0,0,0,0,0,0,0,0,0
0,0,0,0,0,0,0,0,0
0,0,0,0,0,0,0,0,0
0,0,0,0,0,0,0,0,0
0,0,0,0,0,0,0,0,0
0,0,0,0,0,0,0,0,0
0,0,0,0,0,0,0,0,0
0,0,0,0,0,0,0,0,0
0,0,0,0,0,0,0,0,0
0,0,0,0,0,0,0,0,0
0,0,0,0,0,0,0,0,0
0,0,0,0,0,0,0,0,0
0,0,0,0,0,0,0,0,0
0,0,0,0,0,0,0,0,0
:endlayer
layer: 23
0,0,0,0,0,0,0,0,0
0,0,0,0,0,0,0,0,0
0,0,0,0,0,0,0,0,0
0,0,0,0,0,0,0,0,0
0,0,0,0,0,0,0,0,0
0,0,0,0,0,0,0,0,0
0,0,0,0,0,0,0,0,0
0,0,0,0,0,0,0,0,0
0,0,0,0,0,0,0,0,0
0,0,0,0,0,0,0,0,0
0,0,0,0,0,0,0,0,0
0,0,0,0,0,0,0,0,0
0,0,0,0,0,0,0,0,0
0,0,0,0,0,0,0,0,0
0,0,0,0,0,0,0,0,0
0,0,0,0,0,0,0,0,0
:endlayer
layer: 24
0,0,0,0,0,0,0,0,0
0,0,0,0,0,0,0,0,0
0,0,0,0,0,0,0,0,0
0,0,0,0,0,0,0,0,0
0,0,0,0,0,0,0,0,0
0,0,0,0,0,0,0,0,0
0,0,0,0,0,0,0,0,0
0,0,0,0,0,0,0,0,0
0,0,0,0,0,0,0,0,0
0,0,0,0,0,0,0,0,0
0,0,0,0,0,0,0,0,0
0,0,0,0,0,0,0,0,0
0,0,0,0,0,0,0,0,0
0,0,0,0,0,0,0,0,0
0,0,0,0,0,0,0,0,0
0,0,0,0,0,0,0,0,0
:endlayer
layer: 25
0,0,0,0,0,0,0,0,0
0,0,0,0,0,0,0,0,0
0,0,0,0,0,0,0,0,0
0,0,0,0,0,0,0,0,0
0,0,0,0,0,0,0,0,0
0,0,0,0,0,0,0,0,0
0,0,0,0,0,0,0,0,0
0,0,0,0,0,0,0,0,0
0,0,0,0,0,0,0,0,0
0,0,0,0,0,0,0,0,0
0,0,0,0,0,0,0,0,0
0,0,0,0,0,0,0,0,0
0,0,0,0,0,0,0,0,0
0,0,0,0,0,0,0,0,0
0,0,0,0,0,0,0,0,0
0,0,0,0,0,0,0,0,0
:endlayer
layer: 26
0,0,0,0,0,0,0,0,0
0,0,0,0,0,0,0,0,0
0,0,0,0,0,0,0,0,0
0,0,0,0,0,0,0,0,0
0,0,0,0,0,0,0,0,0
0,0,0,0,0,0,0,0,0
0,0,0,0,0,0,0,0,0
0,0,0,0,0,0,0,0,0
0,0,0,0,0,0,0,0,0
0,0,0,0,0,0,0,0,0
0,0,0,0,0,0,0,0,0
0,0,0,0,0,0,0,0,0
0,0,0,0,0,0,0,0,0
0,0,0,0,0,0,0,0,0
0,0,0,0,0,0,0,0,0
0,0,0,0,0,0,0,0,0
:endlayer
layer: 27
0,0,0,0,0,0,0,0,0
0,0,0,0,0,0,0,0,0
0,0,0,0,0,0,0,0,0
0,0,0,0,0,0,0,0,0
0,0,0,0,0,0,0,0,0
0,0,0,0,0,0,0,0,0
0,0,0,0,0,0,0,0,0
0,0,0,0,0,0,0,0,0
0,0,0,0,0,0,0,0,0
0,0,0,0,0,0,0,0,0
0,0,0,0,0,0,0,0,0
0,0,0,0,0,0,0,0,0
0,0,0,0,0,0,0,0,0
0,0,0,0,0,0,0,0,0
0,0,0,0,0,0,0,0,0
0,0,0,0,0,0,0,0,0
:endlayer
layer: 28
0,0,0,0,0,0,0,0,0
0,0,0,0,0,0,0,0,0
0,0,0,0,0,0,0,0,0
0,0,0,0,0,0,0,0,0
0,0,0,0,0,0,0,0,0
0,0,0,0,0,0,0,0,0
0,0,0,0,0,0,0,0,0
0,0,0,0,0,0,0,0,0
0,0,0,0,0,0,0,0,0
0,0,0,0,0,0,0,0,0
0,0,0,0,0,0,0,0,0
0,0,0,0,0,0,0,0,0
0,0,0,0,0,0,0,0,0
0,0,0,0,0,0,0,0,0
0,0,0,0,0,0,0,0,0
0,0,0,0,0,0,0,0,0
:endlayer
layer: 29
0,0,0,0,0,0,0,0,0
0,0,0,0,0,0,0,0,0
0,0,0,0,0,0,0,0,0
0,0,0,0,0,0,0,0,0
0,0,0,0,0,0,0,0,0
0,0,0,0,0,0,0,0,0
0,0,0,0,0,0,0,0,0
0,0,0,0,0,0,0,0,0
0,0,0,0,0,0,0,0,0
0,0,0,0,0,0,0,0,0
0,0,0,0,0,0,0,0,0
0,0,0,0,0,0,0,0,0
0,0,0,0,0,0,0,0,0
0,0,0,0,0,0,0,0,0
0,0,0,0,0,0,0,0,0
0,0,0,0,0,0,0,0,0
:endlayer
layer: 30
0,0,0,0,0,0,0,0,0
0,0,0,0,0,0,0,0,0
0,0,0,0,0,0,0,0,0
0,0,0,0,0,0,0,0,0
0,0,0,0,0,0,0,0,0
0,0,0,0,0,0,0,0,0
0,0,0,0,0,0,0,0,0
0,0,0,0,0,0,0,0,0
0,0,0,0,0,0,0,0,0
0,0,0,0,0,0,0,0,0
0,0,0,0,0,0,0,0,0
0,0,0,0,0,0,0,0,0
0,0,0,0,0,0,0,0,0
0,0,0,0,0,0,0,0,0
0,0,0,0,0,0,0,0,0
0,0,0,0,0,0,0,0,0
:endlayer
layer: 31
0,0,0,0,0,0,0,0,0
0,0,0,0,0,0,0,0,0
0,0,0,0,0,0,0,0,0
0,0,0,0,0,0,0,0,0
0,0,0,0,0,0,0,0,0
0,0,0,0,0,0,0,0,0
0,0,0,0,0,0,0,0,0
0,0,0,0,0,0,0,0,0
0,0,0,0,0,0,0,0,0
0,0,0,0,0,0,0,0,0
0,0,0,0,0,0,0,0,0
0,0,0,0,0,0,0,0,0
0,0,0,0,0,0,0,0,0
0,0,0,0,0,0,0,0,0
0,0,0,0,0,0,0,0,0
0,0,0,0,0,0,0,0,0
:endlayer
layer: 32
0,0,0,0,0,0,0,0,0
0,0,0,0,0,0,0,0,0
0,0,0,0,0,0,0,0,0
0,0,0,0,0,0,0,0,0
0,0,0,0,0,0,0,0,0
0,0,0,0,0,0,0,0,0
0,0,0,0,0,0,0,0,0
0,0,0,0,0,0,0,0,0
0,0,0,0,0,0,0,0,0
0,0,0,0,0,0,0,0,0
0,0,0,0,0,0,0,0,0
0,0,0,0,0,0,0,0,0
0,0,0,0,0,0,0,0,0
0,0,0,0,0,0,0,0,0
0,0,0,0,0,0,0,0,0
0,0,0,0,0,0,0,0,0
:endlayer
layer: 33
0,0,0,0,0,0,0,0,0
0,0,0,0,0,0,0,0,0
0,0,0,0,0,0,0,0,0
0,0,0,0,0,0,0,0,0
0,0,0,0,0,0,0,0,0
0,0,0,0,0,0,0,0,0
0,0,0,0,0,0,0,0,0
0,0,0,0,0,0,0,0,0
0,0,0,0,0,0,0,0,0
0,0,0,0,0,0,0,0,0
0,0,0,0,0,0,0,0,0
0,0,0,0,0,0,0,0,0
0,0,0,0,0,0,0,0,0
0,0,0,0,0,0,0,0,0
0,0,0,0,0,0,0,0,0
0,0,0,0,0,0,0,0,0
:endlayer
layer: 34
0,0,0,0,0,0,0,0,0
0,0,0,0,0,0,0,0,0
0,0,0,0,0,0,0,0,0
0,0,0,0,0,0,0,0,0
0,0,0,0,0,0,0,0,0
0,0,0,0,0,0,0,0,0
0,0,0,0,0,0,0,0,0
0,0,0,0,0,0,0,0,0
0,0,0,0,0,0,0,0,0
0,0,0,0,0,0,0,0,0
0,0,0,0,0,0,0,0,0
0,0,0,0,0,0,0,0,0
0,0,0,0,0,0,0,0,0
0,0,0,0,0,0,0,0,0
0,0,0,0,0,0,0,0,0
0,0,0,0,0,0,0,0,0
:endlayer
layer: 35
0,0,0,0,0,0,0,0,0
0,0,0,0,0,0,0,0,0
0,0,0,0,0,0,0,0,0
0,0,0,0,0,0,0,0,0
0,0,0,0,0,0,0,0,0
0,0,0,0,0,0,0,0,0
0,0,0,0,0,0,0,0,0
0,0,0,0,0,0,0,0,0
0,0,0,0,0,0,0,0,0
0,0,0,0,0,0,0,0,0
0,0,0,0,0,0,0,0,0
0,0,0,0,0,0,0,0,0
0,0,0,0,0,0,0,0,0
0,0,0,0,0,0,0,0,0
0,0,0,0,0,0,0,0,0
0,0,0,0,0,0,0,0,0
:endlayer
layer: 36
0,0,0,0,0,0,0,0,0
0,0,0,0,0,0,0,0,0
0,0,0,0,0,0,0,0,0
0,0,0,0,0,0,0,0,0
0,0,0,0,0,0,0,0,0
0,0,0,0,0,0,0,0,0
0,0,0,0,0,0,0,0,0
0,0,0,0,0,0,0,0,0
0,0,0,0,0,0,0,0,0
0,0,0,0,0,0,0,0,0
0,0,0,0,0,0,0,0,0
0,0,0,0,0,0,0,0,0
0,0,0,0,0,0,0,0,0
0,0,0,0,0,0,0,0,0
0,0,0,0,0,0,0,0,0
0,0,0,0,0,0,0,0,0
:endlayer
layer: 37
0,0,0,0,0,0,0,0,0
0,0,0,0,0,0,0,0,0
0,0,0,0,0,0,0,0,0
0,0,0,0,0,0,0,0,0
0,0,0,0,0,0,0,0,0
0,0,0,0,0,0,0,0,0
0,0,0,0,0,0,0,0,0
0,0,0,0,0,0,0,0,0
0,0,0,0,0,0,0,0,0
0,0,0,0,0,0,0,0,0
0,0,0,0,0,0,0,0,0
0,0,0,0,0,0,0,0,0
0,0,0,0,0,0,0,0,0
0,0,0,0,0,0,0,0,0
0,0,0,0,0,0,0,0,0
0,0,0,0,0,0,0,0,0
:endlayer
layer: 38
0,0,0,0,0,0,0,0,0
0,0,0,0,0,0,0,0,0
0,0,0,0,0,0,0,0,0
0,0,0,0,0,0,0,0,0
0,0,0,0,0,0,0,0,0
0,0,0,0,0,0,0,0,0
0,0,0,0,0,0,0,0,0
0,0,0,0,0,0,0,0,0
0,0,0,0,0,0,0,0,0
0,0,0,0,0,0,0,0,0
0,0,0,0,0,0,0,0,0
0,0,0,0,0,0,0,0,0
0,0,0,0,0,0,0,0,0
0,0,0,0,0,0,0,0,0
0,0,0,0,0,0,0,0,0
0,0,0,0,0,0,0,0,0
:endlayer
layer: 39
0,0,0,0,0,0,0,0,0
0,0,0,0,0,0,0,0,0
0,0,0,0,0,0,0,0,0
0,0,0,0,0,0,0,0,0
0,0,0,0,0,0,0,0,0
0,0,0,0,0,0,0,0,0
0,0,0,0,0,0,0,0,0
0,0,0,0,0,0,0,0,0
0,0,0,0,0,0,0,0,0
0,0,0,0,0,0,0,0,0
0,0,0,0,0,0,0,0,0
0,0,0,0,0,0,0,0,0
0,0,0,0,0,0,0,0,0
0,0,0,0,0,0,0,0,0
0,0,0,0,0,0,0,0,0
0,0,0,0,0,0,0,0,0
:endlayer
layer: 40
0,0,0,0,0,0,0,0,0
0,0,0,0,0,0,0,0,0
0,0,0,0,0,0,0,0,0
0,0,0,0,0,0,0,0,0
0,0,0,0,0,0,0,0,0
0,0,0,0,0,0,0,0,0
0,0,0,0,0,0,0,0,0
0,0,0,0,0,0,0,0,0
0,0,0,0,0,0,0,0,0
0,0,0,0,0,0,0,0,0
0,0,0,0,0,0,0,0,0
0,0,0,0,0,0,0,0,0
0,0,0,0,0,0,0,0,0
0,0,0,0,0,0,0,0,0
0,0,0,0,0,0,0,0,0
0,0,0,0,0,0,0,0,0
:endlayer
layer: 41
0,0,0,0,0,0,0,0,0
0,0,0,0,0,0,0,0,0
0,0,0,0,0,0,0,0,0
0,0,0,0,0,0,0,0,0
0,0,0,0,0,0,0,0,0
0,0,0,0,0,0,0,0,0
0,0,0,0,0,0,0,0,0
0,0,0,0,0,0,0,0,0
0,0,0,0,0,0,0,0,0
0,0,0,0,0,0,0,0,0
0,0,0,0,0,0,0,0,0
0,0,0,0,0,0,0,0,0
0,0,0,0,0,0,0,0,0
0,0,0,0,0,0,0,0,0
0,0,0,0,0,0,0,0,0
0,0,0,0,0,0,0,0,0
:endlayer
layer: 42
0,0,0,0,0,0,0,0,0
0,0,0,0,0,0,0,0,0
0,0,0,0,0,0,0,0,0
0,0,0,0,0,0,0,0,0
0,0,0,0,0,0,0,0,0
0,0,0,0,0,0,0,0,0
0,0,0,0,0,0,0,0,0
0,0,0,0,0,0,0,0,0
0,0,0,0,0,0,0,0,0
0,0,0,0,0,0,0,0,0
0,0,0,0,0,0,0,0,0
0,0,0,0,0,0,0,0,0
0,0,0,0,0,0,0,0,0
0,0,0,0,0,0,0,0,0
0,0,0,0,0,0,0,0,0
0,0,0,0,0,0,0,0,0
:endlayer

#### RULES ####
rule:
plugin=vanillaBlocks
number=1
data:
JSON:{blockState:{blockName:"minecraft:dirt",properties:{variant:"dirt",snowy:"false"}},buildPass:0}
:enddata
:endrule

rule:
plugin=vanillaBlocks
number=2
data:
JSON:{blockState:{blockName:"minecraft:grass",properties:{snowy:"false"}},buildPass:0}
:enddata
:endrule

rule:
plugin=vanillaBlocks
number=3
data:
JSON:{blockState:{blockName:"minecraft:planks",properties:{variant:"birch"}},buildPass:0}
:enddata
:endrule

rule:
plugin=vanillaBlocks
number=4
data:
JSON:{blockState:{blockName:"minecraft:snow_layer",properties:{layers:"2"}},buildPass:2}
:enddata
:endrule

rule:
plugin=vanillaBlocks
number=5
data:
JSON:{blockState:{blockName:"minecraft:snow_layer",properties:{layers:"1"}},buildPass:2}
:enddata
:endrule

rule:
plugin=vanillaBlocks
number=6
data:
JSON:{blockState:{blockName:"minecraft:cobblestone"},buildPass:0}
:enddata
:endrule

rule:
plugin=vanillaBlocks
number=7
data:
JSON:{blockState:{blockName:"minecraft:crafting_table"},buildPass:0}
:enddata
:endrule

rule:
plugin=inventory
number=8
data:
JSON:{blockState:{blockName:"minecraft:furnace",properties:{facing:"north"}},buildPass:0,lootLevel:0,teData:{CookTime:0,BurnTime:0,Items:[],id:"minecraft:furnace",CookTimeTotal:0,Lock:""},inventoryData:{length:0,inventoryContents:[]},legacyFeatures:0b}
:enddata
:endrule

rule:
plugin=doors
number=9
data:
JSON:{blockState:{blockName:"minecraft:wooden_door",properties:{hinge:"left",half:"lower",powered:"false",facing:"east",open:"false"}},buildPass:2}
:enddata
:endrule

rule:
plugin=blockTile
number=10
data:
JSON:{blockState:{blockName:"ancientwarfarestructure:advanced_spawner",properties:{transparent:"true"}},buildPass:0,teData:{id:"ancientwarfarestructure:advanced_spawner_tile",spawnerSettings:{minDelay:0,spawnDelay:0,lightSensitive:0b,spawnGroups:[{settingsList:[{remainingSpawnCount:1,hostile:1b,forced:1b,customTag:{factionName:"norska"},maxToSpawn:1,entityId:"ancientwarfarenpc:faction.soldier",minToSpawn:1}],groupWeight:1}],playerRange:5,respondToRedstone:0b,inventory:{Size:9,Items:[]},spawnRange:0,transparent:1b,maxDelay:0,xpToDrop:0,mobRange:0,debugMode:0b,maxNearbyMonsters:0}}}
:enddata
:endrule

rule:
plugin=bed
number=11
data:
JSON:{blockState:{blockName:"minecraft:bed",properties:{part:"head",facing:"east",occupied:"false"}},buildPass:2,bedColor:14}
:enddata
:endrule

rule:
plugin=bed
number=12
data:
JSON:{blockState:{blockName:"minecraft:bed",properties:{part:"foot",facing:"east",occupied:"false"}},buildPass:2,bedColor:14}
:enddata
:endrule

rule:
plugin=inventory
number=13
data:
JSON:{blockState:{blockName:"minecraft:chest",properties:{facing:"south"}},buildPass:0,lootLevel:0,teData:{ForgeData:{},Items:[{Slot:0b,id:"minecraft:bread",Count:2b,Damage:0s},{Slot:1b,id:"minecraft:bread",Count:1b,Damage:0s},{Slot:7b,id:"minecraft:porkchop",Count:2b,Damage:0s},{Slot:8b,id:"minecraft:porkchop",Count:1b,Damage:0s},{Slot:9b,id:"minecraft:bread",Count:2b,Damage:0s},{Slot:10b,id:"minecraft:bread",Count:1b,Damage:0s},{Slot:16b,id:"minecraft:porkchop",Count:1b,Damage:0s},{Slot:17b,id:"minecraft:porkchop",Count:1b,Damage:0s},{Slot:18b,id:"minecraft:bread",Count:1b,Damage:0s},{Slot:19b,id:"minecraft:bread",Count:1b,Damage:0s},{Slot:21b,id:"ancientwarfarenpc:coin",Count:7b,tag:{metal:"copper"},Damage:0s},{Slot:25b,id:"minecraft:porkchop",Count:1b,Damage:0s}],id:"minecraft:chest",Lock:""},inventoryData:{length:12,inventoryContents:[{id:"minecraft:bread",Count:2b,slot:0,Damage:0s},{id:"minecraft:bread",Count:1b,slot:1,Damage:0s},{id:"minecraft:porkchop",Count:2b,slot:2,Damage:0s},{id:"minecraft:porkchop",Count:1b,slot:3,Damage:0s},{id:"minecraft:bread",Count:2b,slot:4,Damage:0s},{id:"minecraft:bread",Count:1b,slot:5,Damage:0s},{id:"minecraft:porkchop",Count:1b,slot:6,Damage:0s},{id:"minecraft:porkchop",Count:1b,slot:7,Damage:0s},{id:"minecraft:bread",Count:1b,slot:8,Damage:0s},{id:"minecraft:bread",Count:1b,slot:9,Damage:0s},{id:"ancientwarfarenpc:coin",Count:7b,tag:{metal:"copper"},slot:10,Damage:0s},{id:"minecraft:porkchop",Count:1b,slot:11,Damage:0s}]},legacyFeatures:1b}
:enddata
:endrule

rule:
plugin=vanillaBlocks
number=14
data:
JSON:{blockState:{blockName:"minecraft:fence",properties:{east:"false",south:"false",north:"false",west:"false"}},buildPass:0}
:enddata
:endrule

rule:
plugin=vanillaBlocks
number=15
data:
JSON:{blockState:{blockName:"minecraft:double_stone_slab",properties:{seamless:"false",variant:"stone"}},buildPass:0}
:enddata
:endrule

rule:
plugin=vanillaBlocks
number=16
data:
JSON:{blockState:{blockName:"minecraft:snow_layer",properties:{layers:"3"}},buildPass:2}
:enddata
:endrule

rule:
plugin=blockTile
number=17
data:
JSON:{blockState:{blockName:"ancientwarfarestructure:advanced_spawner",properties:{transparent:"true"}},buildPass:0,teData:{id:"ancientwarfarestructure:advanced_spawner_tile",spawnerSettings:{minDelay:0,spawnDelay:0,lightSensitive:0b,spawnGroups:[{settingsList:[{remainingSpawnCount:1,hostile:1b,forced:1b,customTag:{factionName:"norska"},maxToSpawn:1,entityId:"ancientwarfarenpc:faction.soldier",minToSpawn:1}],groupWeight:1}],playerRange:9,respondToRedstone:0b,inventory:{Size:9,Items:[]},spawnRange:0,transparent:1b,maxDelay:0,xpToDrop:0,mobRange:0,debugMode:0b,maxNearbyMonsters:0}}}
:enddata
:endrule

rule:
plugin=vanillaBlocks
number=18
data:
JSON:{blockState:{blockName:"minecraft:planks",properties:{variant:"spruce"}},buildPass:0}
:enddata
:endrule

rule:
plugin=vanillaBlocks
number=19
data:
JSON:{blockState:{blockName:"minecraft:torch",properties:{facing:"west"}},buildPass:2}
:enddata
:endrule

rule:
plugin=doors
number=20
data:
JSON:{blockState:{blockName:"minecraft:wooden_door",properties:{hinge:"left",half:"upper",powered:"false",facing:"south",open:"false"}},buildPass:2}
:enddata
:endrule

rule:
plugin=vanillaBlocks
number=21
data:
JSON:{blockState:{blockName:"minecraft:log",properties:{variant:"spruce",axis:"y"}},buildPass:0}
:enddata
:endrule

rule:
plugin=vanillaBlocks
number=22
data:
JSON:{blockState:{blockName:"minecraft:torch",properties:{facing:"up"}},buildPass:2}
:enddata
:endrule

rule:
plugin=vanillaBlocks
number=23
data:
JSON:{blockState:{blockName:"minecraft:dark_oak_stairs",properties:{half:"bottom",shape:"straight",facing:"west"}},buildPass:0}
:enddata
:endrule

rule:
plugin=vanillaBlocks
number=24
data:
JSON:{blockState:{blockName:"minecraft:dark_oak_stairs",properties:{half:"bottom",shape:"straight",facing:"east"}},buildPass:0}
:enddata
:endrule

rule:
plugin=vanillaBlocks
number=25
data:
JSON:{blockState:{blockName:"minecraft:torch",properties:{facing:"north"}},buildPass:2}
:enddata
:endrule

rule:
plugin=inventory
number=26
data:
JSON:{blockState:{blockName:"minecraft:chest",properties:{facing:"east"}},buildPass:0,lootLevel:0,teData:{Items:[],id:"minecraft:chest",Lock:""},inventoryData:{length:0,inventoryContents:[]},legacyFeatures:1b}
:enddata
:endrule

rule:
plugin=inventory
number=27
data:
JSON:{blockState:{blockName:"minecraft:chest",properties:{facing:"east"}},buildPass:0,lootLevel:0,teData:{Items:[],id:"minecraft:chest",Lock:""},inventoryData:{length:0,inventoryContents:[]},legacyFeatures:1b}
:enddata
:endrule

rule:
plugin=vanillaBlocks
number=28
data:
JSON:{blockState:{blockName:"minecraft:torch",properties:{facing:"south"}},buildPass:2}
:enddata
:endrule

rule:
plugin=vanillaBlocks
number=29
data:
JSON:{blockState:{blockName:"minecraft:dark_oak_stairs",properties:{half:"top",shape:"straight",facing:"north"}},buildPass:0}
:enddata
:endrule

rule:
plugin=vanillaBlocks
number=30
data:
JSON:{blockState:{blockName:"minecraft:dark_oak_stairs",properties:{half:"bottom",shape:"straight",facing:"south"}},buildPass:0}
:enddata
:endrule

rule:
plugin=vanillaBlocks
number=31
data:
JSON:{blockState:{blockName:"minecraft:dark_oak_stairs",properties:{half:"bottom",shape:"straight",facing:"north"}},buildPass:0}
:enddata
:endrule

rule:
plugin=vanillaBlocks
number=32
data:
JSON:{blockState:{blockName:"minecraft:dark_oak_stairs",properties:{half:"top",shape:"straight",facing:"south"}},buildPass:0}
:enddata
:endrule

#### ENTITIES ####
entity:
plugin=entity
number=0
data:
JSON:{yOffset:0.0f,xOffset:0.54494035f,rotation:174.2962f,mobID:"minecraft:sheep",zOffset:0.77924204f,position:1374792187910L,entityData:{HurtByTimestamp:0,ForgeData:{cnpcmarkdata:{marks:[]}},Attributes:[{Base:8.0d,Name:"generic.maxHealth"},{Base:0.0d,Name:"generic.knockbackResistance"},{Base:0.23000000417232513d,Name:"generic.movementSpeed"},{Base:0.0d,Name:"generic.armor"},{Base:0.0d,Name:"generic.armorToughness"},{Base:1.0d,Name:"forge.swimSpeed"},{Base:16.0d,Name:"generic.followRange"}],Invulnerable:0b,FallFlying:0b,ForcedAge:0,PortalCooldown:0,AbsorptionAmount:0.0f,FallDistance:0.0f,InLove:0,DeathTime:0s,ForgeCaps:{"dsurround:emojidata":{as:0,es:0,et:0},"llibrary:extendedentitydatacapability":{"mm:living":{frozenYaw:0.0f,freezeProgress:0.0f,frozenPitch:0.0f,frozenYawHead:0.0f,frozenEntityID:-1,frozenLimbSwingAmount:0.0f,frozenRenderYawOffset:0.0f,frozenSwingProgress:0.0f}},"twilightforest:cap_shield":{permshields:0,tempshields:0}},HandDropChances:[0.085f,0.085f],PersistenceRequired:0b,Age:0,Motion:[0.0d,-0.0784000015258789d,0.0d],Leashed:0b,Health:8.0f,Color:0b,LeftHanded:0b,Air:300s,OnGround:1b,Dimension:0,Rotation:[354.2962f,0.0f],UpdateBlocked:0b,HandItems:[{},{}],ArmorDropChances:[0.085f,0.085f,0.085f,0.085f],Pos:[456.45505965630565d,118.0d,1076.2207579394385d],Fire:-1s,ArmorItems:[{},{},{},{}],CanPickUpLoot:0b,Sheared:0b,HurtTime:0s}}
:enddata
:endentity

entity:
plugin=entity
number=1
data:
JSON:{yOffset:0.0f,xOffset:0.07499999f,rotation:219.17764f,mobID:"minecraft:pig",zOffset:0.925f,position:825036374020L,entityData:{HurtByTimestamp:0,ForgeData:{cnpcmarkdata:{marks:[]}},Attributes:[{Base:10.0d,Name:"generic.maxHealth"},{Base:0.0d,Name:"generic.knockbackResistance"},{Base:0.25d,Name:"generic.movementSpeed"},{Base:0.0d,Name:"generic.armor"},{Base:0.0d,Name:"generic.armorToughness"},{Base:1.0d,Name:"forge.swimSpeed"},{Base:16.0d,Name:"generic.followRange"}],Invulnerable:0b,FallFlying:0b,ForcedAge:0,PortalCooldown:0,AbsorptionAmount:0.0f,Saddle:0b,FallDistance:0.0f,InLove:0,DeathTime:0s,ForgeCaps:{"dsurround:emojidata":{as:0,es:0,et:0},"llibrary:extendedentitydatacapability":{"mm:living":{frozenYaw:0.0f,freezeProgress:0.0f,frozenPitch:0.0f,frozenYawHead:0.0f,frozenEntityID:-1,frozenLimbSwingAmount:0.0f,frozenRenderYawOffset:0.0f,frozenSwingProgress:0.0f}},"twilightforest:cap_shield":{permshields:0,tempshields:0}},HandDropChances:[0.085f,0.085f],PersistenceRequired:0b,Age:0,Motion:[0.0d,-0.0784000015258789d,0.0d],Leashed:0b,Health:10.0f,LeftHanded:0b,Air:300s,OnGround:1b,Dimension:0,Rotation:[39.177643f,0.0f],UpdateBlocked:0b,HandItems:[{},{}],ArmorDropChances:[0.085f,0.085f,0.085f,0.085f],Pos:[458.92500001192093d,118.0d,1078.074999988079d],Fire:-1s,ArmorItems:[{},{},{},{}],CanPickUpLoot:0b,HurtTime:0s}}
:enddata
:endentity

entity:
plugin=entity
number=2
data:
JSON:{yOffset:0.0f,xOffset:0.925f,rotation:35.036102f,mobID:"minecraft:pig",zOffset:0.9453114f,position:825036374019L,entityData:{HurtByTimestamp:0,ForgeData:{cnpcmarkdata:{marks:[]}},Attributes:[{Base:10.0d,Name:"generic.maxHealth"},{Base:0.0d,Name:"generic.knockbackResistance"},{Base:0.25d,Name:"generic.movementSpeed"},{Base:0.0d,Name:"generic.armor"},{Base:0.0d,Name:"generic.armorToughness"},{Base:1.0d,Name:"forge.swimSpeed"},{Base:16.0d,Name:"generic.followRange"}],Invulnerable:0b,FallFlying:0b,ForcedAge:0,PortalCooldown:0,AbsorptionAmount:0.0f,Saddle:0b,FallDistance:0.0f,InLove:0,DeathTime:0s,ForgeCaps:{"dsurround:emojidata":{as:0,es:0,et:0},"llibrary:extendedentitydatacapability":{"mm:living":{frozenYaw:0.0f,freezeProgress:0.0f,frozenPitch:0.0f,frozenYawHead:0.0f,frozenEntityID:-1,frozenLimbSwingAmount:0.0f,frozenRenderYawOffset:0.0f,frozenSwingProgress:0.0f}},"twilightforest:cap_shield":{permshields:0,tempshields:0}},HandDropChances:[0.085f,0.085f],PersistenceRequired:0b,Age:0,Motion:[0.0d,-0.0784000015258789d,0.0d],Leashed:0b,Health:10.0f,LeftHanded:0b,Air:300s,OnGround:1b,Dimension:0,Rotation:[215.0361f,0.0f],UpdateBlocked:0b,HandItems:[{},{}],ArmorDropChances:[0.085f,0.085f,0.085f,0.085f],Pos:[458.07499998807907d,118.0d,1079.054688554325d],Fire:-1s,ArmorItems:[{},{},{},{}],CanPickUpLoot:0b,HurtTime:0s}}
:enddata
:endentity

entity:
plugin=entity
number=3
data:
JSON:{yOffset:0.0f,xOffset:0.07499999f,rotation:184.52844f,mobID:"minecraft:cow",zOffset:0.925f,position:1374792187908L,entityData:{HurtByTimestamp:0,ForgeData:{cnpcmarkdata:{marks:[]}},Attributes:[{Base:10.0d,Name:"generic.maxHealth"},{Base:0.0d,Name:"generic.knockbackResistance"},{Base:0.20000000298023224d,Name:"generic.movementSpeed"},{Base:0.0d,Name:"generic.armor"},{Base:0.0d,Name:"generic.armorToughness"},{Base:1.0d,Name:"forge.swimSpeed"},{Base:16.0d,Name:"generic.followRange"}],Invulnerable:0b,FallFlying:0b,ForcedAge:0,PortalCooldown:0,AbsorptionAmount:0.0f,FallDistance:0.0f,InLove:0,DeathTime:0s,ForgeCaps:{"dsurround:emojidata":{as:1,es:0,et:0},"llibrary:extendedentitydatacapability":{"mm:living":{frozenYaw:0.0f,freezeProgress:0.0f,frozenPitch:0.0f,frozenYawHead:0.0f,frozenEntityID:-1,frozenLimbSwingAmount:0.0f,frozenRenderYawOffset:0.0f,frozenSwingProgress:0.0f}},"twilightforest:cap_shield":{permshields:0,tempshields:0}},HandDropChances:[0.085f,0.085f],PersistenceRequired:0b,Age:0,Motion:[0.0d,-0.0784000015258789d,0.0d],Leashed:0b,Health:10.0f,LeftHanded:0b,Air:300s,OnGround:1b,Dimension:0,Rotation:[4.52845f,0.0f],UpdateBlocked:0b,HandItems:[{},{}],ArmorDropChances:[0.085f,0.085f,0.085f,0.085f],Pos:[456.92500001192093d,118.0d,1078.074999988079d],Fire:-1s,ArmorItems:[{},{},{},{}],CanPickUpLoot:0b,HurtTime:0s}}
:enddata
:endentity

entity:
plugin=entity
number=4
data:
JSON:{yOffset:0.0f,xOffset:0.3600759f,rotation:358.10312f,mobID:"minecraft:cow",zOffset:0.82893026f,position:1374792187907L,entityData:{HurtByTimestamp:0,ForgeData:{cnpcmarkdata:{marks:[]}},Attributes:[{Base:10.0d,Name:"generic.maxHealth"},{Base:0.0d,Name:"generic.knockbackResistance"},{Base:0.20000000298023224d,Name:"generic.movementSpeed"},{Base:0.0d,Name:"generic.armor"},{Base:0.0d,Name:"generic.armorToughness"},{Base:1.0d,Name:"forge.swimSpeed"},{Base:16.0d,Name:"generic.followRange"}],Invulnerable:0b,FallFlying:0b,ForcedAge:0,PortalCooldown:0,AbsorptionAmount:0.0f,FallDistance:0.0f,InLove:0,DeathTime:0s,ForgeCaps:{"dsurround:emojidata":{as:0,es:0,et:0},"llibrary:extendedentitydatacapability":{"mm:living":{frozenYaw:0.0f,freezeProgress:0.0f,frozenPitch:0.0f,frozenYawHead:0.0f,frozenEntityID:-1,frozenLimbSwingAmount:0.0f,frozenRenderYawOffset:0.0f,frozenSwingProgress:0.0f}},"twilightforest:cap_shield":{permshields:0,tempshields:0}},HandDropChances:[0.085f,0.085f],PersistenceRequired:0b,Age:0,Motion:[0.0d,-0.0784000015258789d,0.0d],Leashed:0b,Health:10.0f,LeftHanded:0b,Air:300s,OnGround:1b,Dimension:0,Rotation:[178.10312f,0.0f],UpdateBlocked:0b,HandItems:[{},{}],ArmorDropChances:[0.085f,0.085f,0.085f,0.085f],Pos:[456.63992409183794d,118.0d,1079.171069726184d],Fire:-1s,ArmorItems:[{},{},{},{}],CanPickUpLoot:0b,HurtTime:0s}}
:enddata
:endentity

entity:
plugin=entity
number=5
data:
JSON:{yOffset:0.0f,xOffset:0.17500001f,rotation:39.4563f,mobID:"minecraft:chicken",zOffset:0.2690788f,position:1649670094852L,entityData:{IsChickenJockey:0b,HurtByTimestamp:0,ForgeData:{cnpcmarkdata:{marks:[]}},Attributes:[{Base:4.0d,Name:"generic.maxHealth"},{Base:0.0d,Name:"generic.knockbackResistance"},{Base:0.25d,Name:"generic.movementSpeed"},{Base:0.0d,Name:"generic.armor"},{Base:0.0d,Name:"generic.armorToughness"},{Base:1.0d,Name:"forge.swimSpeed"},{Base:16.0d,Name:"generic.followRange"}],Invulnerable:0b,FallFlying:0b,ForcedAge:0,PortalCooldown:0,AbsorptionAmount:0.0f,FallDistance:0.0f,InLove:0,DeathTime:0s,ForgeCaps:{"dsurround:emojidata":{as:0,es:0,et:0},"llibrary:extendedentitydatacapability":{"mm:living":{frozenYaw:0.0f,freezeProgress:0.0f,frozenPitch:0.0f,frozenYawHead:0.0f,frozenEntityID:-1,frozenLimbSwingAmount:0.0f,frozenRenderYawOffset:0.0f,frozenSwingProgress:0.0f}},"twilightforest:cap_shield":{permshields:0,tempshields:0}},HandDropChances:[0.085f,0.085f],PersistenceRequired:0b,Age:0,Motion:[0.0d,-0.0784000015258789d,0.0d],Leashed:0b,Health:4.0f,LeftHanded:0b,Air:300s,OnGround:1b,Dimension:0,Rotation:[219.4563f,0.0f],UpdateBlocked:0b,HandItems:[{},{}],ArmorDropChances:[0.085f,0.085f,0.085f,0.085f],EggLayTime:3057,Pos:[455.82500000298023d,118.0d,1078.7309212238647d],Fire:-1s,ArmorItems:[{},{},{},{}],CanPickUpLoot:0b,HurtTime:0s}}
:enddata
:endentity

entity:
plugin=entity
number=6
data:
JSON:{yOffset:0.0f,xOffset:0.25f,rotation:351.13812f,mobID:"minecraft:item",zOffset:0.28602952f,position:1649670094852L,entityData:{Motion:[0.0d,-0.0d,-4.9E-324d],Health:5s,Invulnerable:0b,Air:300s,OnGround:1b,Dimension:0,PortalCooldown:0,Rotation:[171.13814f,0.0f],UpdateBlocked:0b,FallDistance:0.0f,Item:{id:"minecraft:egg",Count:1b,Damage:0s},Pos:[455.75d,118.0d,1078.713970453185d],PickupDelay:0s,Fire:-1s,ForgeCaps:{"llibrary:extendedentitydatacapability":{}},Lifespan:6000,Age:4650s}}
:enddata
:endentity

