# Ancient Warfare Structure Template File
# Auto-generated structure template file. created on: 1/2/2019 at: 21:48:41
# Lines beginning with # denote comments

header:
version=2.8
name=NorskaTavernBaldursBladdered
mods=
size=15,20,18
offset=9,7,17
:endheader

#### VALIDATION ####
validation:
type=ground
survival=false
worldGenEnabled=true
unique=false
preserveBlocks=false
selectionWeight=50
clusterValue=40
minDuplicateDistance=1000
dimensionWhiteList=true
dimensionList=0
biomeWhiteList=true
biomeList=minecraft:taiga_cold,traverse:snowy_coniferous_forest,biomesoplenty:cold_desert,minecraft:ice_mountains,biomesoplenty:alps,minecraft:ice_flats,minecraft:taiga_cold_hills,minecraft:cold_beach
leveling=6
fill=6
border=6
blockSwap=false
:endvalidation

#### LAYERS ####
layer: 0
1,1,1,1,1,1,1,1,1,1,1,1,1,1,1
1,1,1,1,1,1,1,1,1,1,1,1,1,1,1
1,1,1,1,1,1,1,1,1,1,1,1,1,1,1
1,1,1,1,1,1,1,1,1,1,1,1,1,1,1
1,1,1,1,1,1,1,1,1,1,1,1,1,1,1
1,1,1,1,1,1,1,1,1,1,1,1,1,1,1
1,1,1,1,1,1,1,1,1,1,1,1,1,1,1
1,1,1,1,1,1,1,1,1,1,1,1,1,1,1
1,1,1,1,1,1,1,1,1,1,1,1,1,1,1
1,1,1,1,1,1,1,1,1,1,1,1,1,1,1
1,1,1,1,1,1,1,1,1,1,1,1,1,1,1
1,1,1,1,1,1,1,1,1,1,1,1,1,1,1
1,1,1,1,1,1,1,1,1,1,1,1,1,1,1
1,1,1,1,1,1,1,1,1,1,1,1,1,1,1
1,1,1,1,1,1,1,1,1,1,1,1,1,1,1
1,1,1,1,1,1,1,1,1,1,1,1,1,1,1
1,1,1,1,1,1,1,1,1,1,1,1,1,1,1
1,1,1,1,1,1,1,1,1,1,1,1,1,1,1
:endlayer
layer: 1
1,1,1,1,1,1,1,1,1,1,1,1,1,1,1
1,1,1,1,1,1,1,1,1,1,1,1,1,1,1
1,1,1,1,1,1,1,1,1,1,1,1,1,1,1
1,1,1,1,1,1,1,1,1,1,1,1,1,1,1
1,1,1,1,1,1,1,1,1,1,1,1,1,1,1
1,1,1,1,1,1,1,1,1,1,1,1,1,1,1
1,1,1,1,1,1,1,1,1,1,1,1,1,1,1
1,1,1,1,1,1,1,1,1,1,1,1,1,1,1
1,1,1,1,1,1,1,1,1,1,1,1,1,1,1
1,1,1,1,1,1,1,1,1,1,1,1,1,1,1
1,1,1,1,1,1,1,1,1,1,1,1,1,1,1
1,1,1,1,1,1,1,1,1,1,1,1,1,1,1
1,1,1,1,1,1,1,1,1,1,1,1,1,1,1
1,1,1,1,1,1,1,1,1,1,1,1,1,1,1
1,1,1,1,1,1,1,1,1,1,1,1,1,1,1
1,1,1,1,1,1,1,1,1,1,1,1,1,1,1
1,1,1,1,1,1,1,1,1,1,1,1,1,1,1
1,1,1,1,1,1,1,1,1,1,1,1,1,1,1
:endlayer
layer: 2
1,1,1,1,1,1,1,1,1,1,1,1,1,1,1
1,1,1,1,1,1,1,1,1,1,1,1,1,1,1
1,1,1,1,1,1,1,1,1,1,1,1,1,1,1
1,1,1,1,1,1,1,1,1,1,1,1,1,1,1
1,1,1,1,1,1,1,1,1,1,1,1,1,1,1
1,1,1,1,1,1,1,1,1,1,1,1,1,1,1
1,1,1,1,1,1,1,1,1,1,1,1,1,1,1
1,1,1,1,1,1,1,1,1,1,1,1,1,1,1
1,1,1,1,1,1,1,1,1,1,1,1,1,1,1
1,1,1,1,1,1,1,1,1,1,1,1,1,1,1
1,1,1,1,1,1,1,1,1,1,1,1,1,1,1
1,1,1,1,1,1,1,1,1,1,1,1,1,1,1
1,1,1,1,1,1,1,1,1,1,1,1,1,1,1
1,1,1,1,1,1,1,1,1,1,1,1,1,1,1
1,1,1,1,1,1,1,1,1,1,1,1,1,1,1
1,1,1,1,1,1,1,1,1,1,1,1,1,1,1
1,1,1,1,1,1,1,1,1,1,1,1,1,1,1
1,1,1,1,1,1,1,1,1,1,1,1,1,1,1
:endlayer
layer: 3
1,1,1,1,1,1,1,1,1,1,1,1,1,1,1
1,1,1,1,1,1,1,1,1,1,1,1,1,1,1
1,1,1,1,1,1,1,1,1,1,1,1,1,1,1
1,1,1,1,1,1,1,1,1,1,1,1,1,1,1
1,1,1,1,1,1,1,1,1,1,1,1,1,1,1
1,1,1,1,1,1,1,1,1,1,1,1,1,1,1
1,1,1,1,1,1,1,1,1,1,1,1,1,1,1
1,1,1,1,1,1,1,1,1,1,1,1,1,1,1
1,1,1,1,1,1,1,1,1,1,1,1,1,1,1
1,1,1,1,1,1,1,1,1,1,1,1,1,1,1
1,1,1,1,1,1,1,1,1,1,1,1,1,1,1
1,1,1,1,1,1,1,1,1,1,1,1,1,1,1
1,1,1,1,1,1,1,1,1,1,1,1,1,1,1
1,1,1,1,1,1,1,1,1,1,1,1,1,1,1
1,1,1,1,1,1,1,1,1,1,1,1,1,1,1
1,1,1,1,1,1,1,1,1,1,1,1,1,1,1
1,1,1,1,1,1,1,1,1,1,1,1,1,1,1
1,1,1,1,1,1,1,1,1,1,1,1,1,1,1
:endlayer
layer: 4
1,1,1,1,1,1,1,1,1,1,1,1,1,1,1
1,1,1,1,1,1,1,1,1,1,1,1,1,1,1
1,1,1,1,1,1,1,1,1,1,1,1,1,1,1
1,1,1,1,1,1,1,1,1,1,1,1,1,1,1
1,1,1,1,1,1,1,1,1,1,1,1,1,1,1
1,1,1,1,1,1,1,1,1,1,1,1,1,1,1
1,1,1,1,1,1,1,1,1,1,1,1,1,1,1
1,1,1,1,1,1,1,1,1,1,1,1,1,1,1
1,1,1,1,1,1,1,1,1,1,1,1,1,1,1
1,1,1,1,1,1,1,1,1,1,1,1,1,1,1
1,1,1,1,1,1,1,1,1,1,1,1,1,1,1
1,1,1,1,1,1,1,1,1,1,1,1,1,1,1
1,1,1,1,1,1,1,1,1,1,1,1,1,1,1
1,1,1,1,1,1,1,1,1,1,1,1,1,1,1
1,1,1,1,1,1,1,1,1,1,1,1,1,1,1
1,1,1,1,1,1,1,1,1,1,1,1,1,1,1
1,1,1,1,1,1,1,1,1,1,1,1,1,1,1
1,1,1,1,1,1,1,1,1,1,1,1,1,1,1
:endlayer
layer: 5
1,1,1,1,1,1,1,1,1,1,1,1,1,1,1
1,1,1,1,1,1,1,1,1,1,1,1,1,1,1
1,1,1,1,1,1,1,1,1,1,1,1,1,1,1
1,1,1,1,1,1,1,1,1,1,1,1,1,1,1
1,1,1,1,1,1,1,1,1,1,1,1,1,1,1
1,1,1,1,1,1,1,1,1,1,1,1,1,1,1
1,1,1,1,1,1,1,1,1,1,1,1,1,1,1
1,1,1,1,1,1,1,1,1,1,1,1,1,1,1
1,1,1,1,1,1,1,1,1,1,1,1,1,1,1
1,1,1,1,1,1,1,1,1,1,1,1,1,1,1
1,1,1,1,1,1,1,1,1,1,1,1,1,1,1
1,1,1,1,1,1,1,1,1,1,1,1,1,1,1
1,1,1,1,1,1,1,1,1,1,1,1,1,1,1
1,1,1,1,1,1,1,1,1,1,1,1,1,1,1
1,1,1,1,1,1,1,1,1,1,1,1,1,1,1
1,1,1,1,1,1,1,1,1,1,1,1,1,1,1
1,1,1,1,1,1,1,1,1,1,1,1,1,1,1
1,1,1,1,1,1,1,1,1,1,1,1,1,1,1
:endlayer
layer: 6
2,2,2,2,2,2,2,2,2,2,2,2,2,2,2
2,2,2,2,2,2,2,2,2,2,2,2,2,2,2
2,2,1,1,1,1,1,1,1,1,1,1,1,2,2
2,2,1,1,1,1,1,1,1,1,1,1,1,2,2
2,2,1,1,1,1,1,1,1,1,1,1,1,1,2
2,2,1,1,1,1,1,1,1,1,1,1,1,1,2
2,2,1,1,1,1,1,1,1,1,1,1,1,1,2
2,2,1,1,1,1,1,1,1,1,1,1,1,2,2
2,2,1,1,1,1,1,1,1,1,1,1,1,2,2
2,2,1,1,1,1,1,1,1,1,1,1,1,2,2
2,2,1,1,1,1,1,1,1,1,1,1,1,2,2
2,2,1,1,1,1,1,1,1,1,1,1,1,2,2
2,2,1,1,1,1,1,1,1,1,1,1,1,2,2
2,2,1,1,1,1,1,1,1,1,1,1,1,2,2
2,2,1,1,1,1,1,1,1,1,1,1,1,2,2
2,2,1,1,1,1,1,1,1,1,1,1,1,2,2
2,2,2,2,2,2,2,2,2,2,2,2,2,2,2
2,2,2,2,2,2,2,2,2,2,2,2,2,2,2
:endlayer
layer: 7
3,3,3,3,3,3,3,3,3,3,3,3,3,3,3
3,3,3,3,3,3,3,3,3,3,3,5,3,3,3
3,3,7,7,7,2,7,7,7,2,7,7,7,3,3
3,3,2,7,7,7,7,7,7,7,7,7,7,5,5
3,3,7,7,7,6,8,6,6,6,6,7,7,7,5
3,3,7,7,6,8,8,8,6,6,6,9,7,7,3
3,3,7,7,7,6,6,6,6,6,6,7,7,7,5
3,3,7,7,7,6,8,6,6,6,6,6,7,0,5
3,3,2,7,7,6,8,6,6,6,6,6,7,3,3
0,3,2,2,7,6,6,6,6,6,6,6,7,5,3
3,0,7,2,7,6,6,6,6,6,6,6,7,0,3
3,3,6,6,7,6,6,6,6,6,6,6,7,5,3
3,0,6,6,7,6,6,6,6,6,6,6,7,3,3
3,3,6,6,7,6,6,6,6,6,6,6,7,3,3
3,3,6,6,6,6,6,6,6,6,6,6,6,3,3
3,3,6,6,6,6,6,6,6,6,6,6,6,3,3
3,3,3,5,3,3,3,3,3,0,4,0,4,0,3
0,3,3,3,3,3,3,3,3,0,3,3,3,3,3
:endlayer
layer: 8
0,0,0,0,0,0,0,0,0,0,0,0,0,0,0
0,0,0,0,0,0,0,0,0,0,0,0,0,0,0
0,0,3,3,3,0,3,3,3,5,0,3,3,0,0
0,0,3,0,10,7,7,7,10,7,7,7,10,0,0
0,0,3,0,7,14,11,12,0,36,0,31,7,7,0
0,0,3,0,20,0,0,0,0,35,0,0,34,7,0
0,0,3,33,7,0,0,32,0,0,0,31,7,7,0
0,0,3,0,10,0,0,0,6,6,0,30,10,0,0
0,0,26,3,7,0,29,0,24,0,28,27,7,0,0
0,0,26,3,7,0,0,25,24,0,23,0,7,0,0
0,0,3,4,7,14,12,0,6,22,0,21,7,0,0
0,0,3,0,10,19,19,19,10,19,20,19,10,0,0
0,0,3,3,7,0,18,0,0,0,0,0,7,0,0
0,0,3,3,7,17,0,0,16,0,0,0,7,0,0
0,0,15,3,7,14,13,12,11,14,13,12,7,0,0
0,0,11,11,10,7,7,7,10,7,7,7,10,0,0
0,0,0,0,0,0,0,0,0,0,0,0,0,0,0
0,0,0,0,0,0,0,0,0,0,0,0,0,0,0
:endlayer
layer: 9
0,0,0,0,0,0,0,0,0,0,0,0,0,0,0
0,0,0,0,0,0,0,0,0,0,0,0,0,0,0
0,0,0,0,0,0,0,0,0,0,0,0,0,0,0
0,0,0,0,10,7,7,7,10,7,7,7,10,0,0
0,0,0,43,7,0,42,0,0,0,0,40,7,7,0
0,0,0,0,38,0,0,0,0,0,0,0,0,7,0
0,0,0,41,7,0,0,0,0,0,0,40,7,7,0
0,0,0,0,10,0,0,0,0,0,0,0,10,0,0
0,0,0,0,7,0,0,0,0,0,0,39,7,0,0
0,0,0,0,11,0,0,0,0,0,0,39,7,0,0
0,0,0,0,7,14,12,0,0,0,0,39,7,0,0
0,0,0,0,10,19,19,19,10,19,38,19,10,0,0
0,0,0,0,7,0,0,0,0,0,0,0,7,0,0
0,0,0,0,11,0,0,0,0,0,0,0,7,0,0
0,0,0,0,7,14,13,12,37,14,13,12,7,0,0
0,0,37,0,10,7,7,7,10,7,7,7,10,0,0
0,0,0,0,0,0,0,0,0,0,0,0,0,0,0
0,0,0,0,0,0,0,0,0,0,0,0,0,0,0
:endlayer
layer: 10
0,0,0,0,0,0,0,0,0,0,0,0,0,0,0
0,0,0,0,0,0,0,0,0,0,0,0,0,0,0
0,0,0,0,0,0,0,0,0,0,0,0,0,0,0
0,0,0,45,10,7,7,7,10,7,7,7,10,0,0
0,0,0,0,7,0,0,0,0,0,0,7,7,7,0
0,0,0,0,7,44,0,0,0,0,45,7,0,7,0
0,0,0,0,7,0,0,0,0,0,0,7,7,7,0
0,0,0,45,10,0,0,0,0,0,0,0,10,44,0
0,0,0,0,7,0,0,0,0,0,0,13,7,0,0
0,0,0,0,7,0,0,0,0,0,0,13,7,0,0
0,0,0,0,7,13,13,0,0,0,46,13,7,0,0
0,0,0,45,10,19,19,19,10,19,19,19,10,44,0
0,0,0,0,7,0,0,0,0,0,0,0,7,0,0
0,0,0,0,7,0,0,0,0,0,0,0,7,0,0
0,0,0,0,7,13,13,13,0,13,13,13,7,0,0
0,0,0,0,10,7,7,7,10,7,7,7,10,44,0
0,0,0,0,0,0,0,0,0,0,0,0,0,0,0
0,0,0,0,0,0,0,0,0,0,0,0,0,0,0
:endlayer
layer: 11
0,0,0,0,0,0,0,0,0,0,0,0,0,0,0
0,0,0,0,0,0,0,0,0,0,0,0,0,0,0
0,0,0,24,46,0,0,0,46,0,0,0,46,24,0
0,0,0,24,10,10,10,10,10,10,10,10,10,24,0
0,0,0,24,10,0,0,0,11,0,0,7,7,7,0
0,0,0,24,10,0,0,11,11,11,0,7,0,7,0
0,0,0,24,10,0,0,0,11,0,0,7,7,7,0
0,0,0,24,10,0,0,0,0,0,0,0,10,24,0
0,0,0,24,10,0,0,0,11,0,0,0,10,24,0
0,0,0,24,10,0,0,11,11,11,0,0,10,24,0
0,0,0,24,10,0,0,0,11,0,0,0,10,24,0
0,0,0,24,10,10,10,10,10,10,10,10,10,24,0
0,0,0,24,10,0,0,0,0,0,0,0,10,24,0
0,0,0,24,10,0,0,0,0,0,0,0,10,24,0
0,0,0,24,10,0,0,0,0,0,0,0,10,24,0
0,0,0,24,10,10,10,10,10,10,10,10,10,24,0
0,0,0,24,47,0,0,0,47,0,0,0,47,24,0
0,0,0,0,0,0,0,0,0,0,0,0,0,0,0
:endlayer
layer: 12
0,0,0,0,0,0,0,0,0,0,0,0,0,0,0
0,0,0,0,0,0,0,0,0,0,0,0,0,0,0
0,0,0,12,49,0,0,0,0,0,0,0,48,14,0
0,0,0,12,10,7,7,7,10,7,7,7,10,14,0
0,0,0,12,6,0,13,0,37,0,13,7,7,7,0
0,0,0,12,6,0,13,37,11,37,13,7,0,7,0
0,0,0,12,6,0,13,0,37,0,13,7,7,7,0
0,0,0,12,6,13,13,13,13,13,13,13,6,14,0
0,0,0,12,6,0,13,0,37,0,13,0,6,14,0
0,0,0,12,6,0,13,37,11,37,13,0,6,14,0
0,0,0,12,6,0,13,0,37,0,13,0,6,14,0
0,0,0,12,10,19,19,19,10,19,19,19,10,14,0
0,0,0,12,6,0,13,0,0,0,13,0,6,14,0
0,0,0,12,6,13,13,13,13,13,13,13,6,14,0
0,0,0,12,6,0,13,0,0,0,13,0,6,14,0
0,0,0,12,10,7,7,7,10,7,7,7,10,14,0
0,0,0,12,49,0,0,0,0,0,0,0,48,14,0
0,0,0,0,0,0,0,0,0,0,0,0,0,0,0
:endlayer
layer: 13
0,0,0,0,0,0,0,0,0,0,0,0,0,0,0
0,0,0,0,0,0,0,0,0,0,0,0,0,0,0
0,0,0,0,12,49,0,0,0,0,0,48,14,0,0
0,0,0,0,12,10,7,7,10,7,7,10,14,0,0
0,0,0,0,12,6,0,0,0,0,0,7,7,7,0
0,0,0,0,12,6,0,0,11,0,0,7,0,7,0
0,0,0,0,12,6,0,0,0,0,0,7,7,7,0
0,0,0,0,12,6,0,0,0,0,0,6,14,0,0
0,0,0,0,12,6,0,0,0,0,0,6,14,0,0
0,0,0,0,12,6,0,0,11,0,0,6,14,0,0
0,0,0,0,12,6,0,0,0,0,0,6,14,0,0
0,0,0,0,12,10,19,19,10,19,19,10,14,0,0
0,0,0,0,12,6,0,0,0,0,0,6,14,0,0
0,0,0,0,12,6,0,0,0,0,0,6,14,0,0
0,0,0,0,12,6,0,0,0,0,0,6,14,0,0
0,0,0,0,12,10,7,7,10,7,7,10,14,0,0
0,0,0,0,12,49,0,0,0,0,0,48,14,0,0
0,0,0,0,0,0,0,0,0,0,0,0,0,0,0
:endlayer
layer: 14
0,0,0,0,0,0,0,0,0,0,0,0,0,0,0
0,0,0,0,0,0,0,0,0,0,0,0,0,0,0
0,0,0,0,0,12,49,0,0,0,48,14,0,0,0
0,0,0,0,0,12,10,7,10,7,10,14,0,0,0
0,0,0,0,0,12,6,0,0,0,6,7,7,7,0
0,0,0,0,0,12,6,0,11,0,6,7,0,7,0
0,0,0,0,0,12,6,0,0,0,6,7,7,7,0
0,0,0,0,0,12,6,0,0,0,6,14,0,0,0
0,0,0,0,0,12,6,0,0,0,6,14,0,0,0
0,0,0,0,0,12,6,0,11,0,6,14,0,0,0
0,0,0,0,0,12,6,0,0,0,6,14,0,0,0
0,0,0,0,0,12,10,19,10,19,10,14,0,0,0
0,0,0,0,0,12,6,0,0,0,6,14,0,0,0
0,0,0,0,0,12,6,0,0,0,6,14,0,0,0
0,0,0,0,0,12,6,0,0,0,6,14,0,0,0
0,0,0,0,0,12,10,7,10,7,10,14,0,0,0
0,0,0,0,0,12,49,0,0,0,48,14,0,0,0
0,0,0,0,0,0,0,0,0,0,0,0,0,0,0
:endlayer
layer: 15
0,0,0,0,0,0,0,0,0,0,0,0,0,0,0
0,0,0,0,0,0,0,0,0,0,0,0,0,0,0
0,0,0,0,0,0,12,49,0,48,14,0,0,0,0
0,0,0,0,0,0,12,10,10,10,14,0,0,0,0
0,0,0,0,0,0,12,6,0,6,14,7,7,7,0
0,0,0,0,0,0,12,6,11,6,14,7,0,7,0
0,0,0,0,0,0,12,6,0,6,14,7,7,7,0
0,0,0,0,0,0,12,6,0,6,14,0,0,0,0
0,0,0,0,0,0,12,6,0,6,14,0,0,0,0
0,0,0,0,0,0,12,6,11,6,14,0,0,0,0
0,0,0,0,0,0,12,6,0,6,14,0,0,0,0
0,0,0,0,0,0,12,10,10,10,14,0,0,0,0
0,0,0,0,0,0,12,6,0,6,14,0,0,0,0
0,0,0,0,0,0,12,6,0,6,14,0,0,0,0
0,0,0,0,0,0,12,6,0,6,14,0,0,0,0
0,0,0,0,0,0,12,10,10,10,14,0,0,0,0
0,0,0,0,0,0,12,49,0,48,14,0,0,0,0
0,0,0,0,0,0,0,0,0,0,0,0,0,0,0
:endlayer
layer: 16
0,0,0,0,0,0,0,0,0,0,0,0,0,0,0
0,0,0,0,0,0,0,0,0,0,0,0,0,0,0
0,0,0,0,0,0,0,12,6,14,0,0,0,0,0
0,0,0,0,0,0,0,12,10,14,0,0,0,0,0
0,0,0,0,0,0,0,12,6,14,0,7,7,7,0
0,0,0,0,0,0,0,12,6,14,0,7,0,50,0
0,0,0,0,0,0,0,12,6,14,0,7,7,7,0
0,0,0,0,0,0,0,12,6,14,0,0,0,0,0
0,0,0,0,0,0,0,12,6,14,0,0,0,0,0
0,0,0,0,0,0,0,12,6,14,0,0,0,0,0
0,0,0,0,0,0,0,12,6,14,0,0,0,0,0
0,0,0,0,0,0,0,12,10,14,0,0,0,0,0
0,0,0,0,0,0,0,12,6,14,0,0,0,0,0
0,0,0,0,0,0,0,12,6,14,0,0,0,0,0
0,0,0,0,0,0,0,12,6,14,0,0,0,0,0
0,0,0,0,0,0,0,12,10,14,0,0,0,0,0
0,0,0,0,0,0,0,12,6,14,0,0,0,0,0
0,0,0,0,0,0,0,0,0,0,0,0,0,0,0
:endlayer
layer: 17
0,0,0,0,0,0,0,0,0,0,0,0,0,0,0
0,0,0,0,0,0,0,0,0,0,0,0,0,0,0
0,0,0,0,0,0,0,0,13,0,0,0,0,0,0
0,0,0,0,0,0,0,0,13,0,0,0,0,0,0
0,0,0,0,0,0,0,0,13,0,0,9,7,7,0
0,0,0,0,0,0,0,0,13,0,0,7,51,7,0
0,0,0,0,0,0,0,0,13,0,0,50,7,9,0
0,0,0,0,0,0,0,0,13,0,0,0,0,0,0
0,0,0,0,0,0,0,0,13,0,0,0,0,0,0
0,0,0,0,0,0,0,0,13,0,0,0,0,0,0
0,0,0,0,0,0,0,0,13,0,0,0,0,0,0
0,0,0,0,0,0,0,0,13,0,0,0,0,0,0
0,0,0,0,0,0,0,0,13,0,0,0,0,0,0
0,0,0,0,0,0,0,0,13,0,0,0,0,0,0
0,0,0,0,0,0,0,0,13,0,0,0,0,0,0
0,0,0,0,0,0,0,0,13,0,0,0,0,0,0
0,0,0,0,0,0,0,0,13,0,0,0,0,0,0
0,0,0,0,0,0,0,0,0,0,0,0,0,0,0
:endlayer
layer: 18
0,0,0,0,0,0,0,0,0,0,0,0,0,0,0
0,0,0,0,0,0,0,0,0,0,0,0,0,0,0
0,0,0,0,0,0,0,0,0,0,0,0,0,0,0
0,0,0,0,0,0,0,0,0,0,0,0,0,0,0
0,0,0,0,0,0,0,0,0,0,0,52,52,50,0
0,0,0,0,0,0,0,0,0,0,0,52,53,52,0
0,0,0,0,0,0,0,0,0,0,0,50,7,7,0
0,0,0,0,0,0,0,0,0,0,0,0,0,0,0
0,0,0,0,0,0,0,0,0,0,0,0,0,0,0
0,0,0,0,0,0,0,0,0,0,0,0,0,0,0
0,0,0,0,0,0,0,0,0,0,0,0,0,0,0
0,0,0,0,0,0,0,0,0,0,0,0,0,0,0
0,0,0,0,0,0,0,0,0,0,0,0,0,0,0
0,0,0,0,0,0,0,0,0,0,0,0,0,0,0
0,0,0,0,0,0,0,0,0,0,0,0,0,0,0
0,0,0,0,0,0,0,0,0,0,0,0,0,0,0
0,0,0,0,0,0,0,0,0,0,0,0,0,0,0
0,0,0,0,0,0,0,0,0,0,0,0,0,0,0
:endlayer
layer: 19
0,0,0,0,0,0,0,0,0,0,0,0,0,0,0
0,0,0,0,0,0,0,0,0,0,0,0,0,0,0
0,0,0,0,0,0,0,0,0,0,0,0,0,0,0
0,0,0,0,0,0,0,0,0,0,0,0,0,0,0
0,0,0,0,0,0,0,0,0,0,0,9,9,0,0
0,0,0,0,0,0,0,0,0,0,0,9,0,9,0
0,0,0,0,0,0,0,0,0,0,0,0,9,9,0
0,0,0,0,0,0,0,0,0,0,0,0,0,0,0
0,0,0,0,0,0,0,0,0,0,0,0,0,0,0
0,0,0,0,0,0,0,0,0,0,0,0,0,0,0
0,0,0,0,0,0,0,0,0,0,0,0,0,0,0
0,0,0,0,0,0,0,0,0,0,0,0,0,0,0
0,0,0,0,0,0,0,0,0,0,0,0,0,0,0
0,0,0,0,0,0,0,0,0,0,0,0,0,0,0
0,0,0,0,0,0,0,0,0,0,0,0,0,0,0
0,0,0,0,0,0,0,0,0,0,0,0,0,0,0
0,0,0,0,0,0,0,0,0,0,0,0,0,0,0
0,0,0,0,0,0,0,0,0,0,0,0,0,0,0
:endlayer

#### RULES ####
rule:
plugin=vanillaBlocks
number=1
data:
JSON:{blockState:{blockName:"minecraft:dirt",properties:{variant:"dirt",snowy:"false"}}}
:enddata
:endrule

rule:
plugin=vanillaBlocks
number=2
data:
JSON:{blockState:{blockName:"minecraft:grass",properties:{snowy:"false"}}}
:enddata
:endrule

rule:
plugin=vanillaBlocks
number=3
data:
JSON:{blockState:{blockName:"minecraft:snow_layer",properties:{layers:"1"}}}
:enddata
:endrule

rule:
plugin=vanillaBlocks
number=4
data:
JSON:{blockState:{blockName:"minecraft:snow_layer",properties:{layers:"3"}}}
:enddata
:endrule

rule:
plugin=vanillaBlocks
number=5
data:
JSON:{blockState:{blockName:"minecraft:snow_layer",properties:{layers:"2"}}}
:enddata
:endrule

rule:
plugin=vanillaBlocks
number=6
data:
JSON:{blockState:{blockName:"minecraft:planks",properties:{variant:"dark_oak"}}}
:enddata
:endrule

rule:
plugin=vanillaBlocks
number=7
data:
JSON:{blockState:{blockName:"minecraft:cobblestone"}}
:enddata
:endrule

rule:
plugin=vanillaBlocks
number=8
data:
JSON:{blockState:{blockName:"minecraft:wool",properties:{color:"brown"}}}
:enddata
:endrule

rule:
plugin=vanillaBlocks
number=9
data:
JSON:{blockState:{blockName:"minecraft:stone_slab",properties:{half:"bottom",variant:"cobblestone"}}}
:enddata
:endrule

rule:
plugin=vanillaBlocks
number=10
data:
JSON:{blockState:{blockName:"minecraft:log",properties:{variant:"spruce",axis:"y"}}}
:enddata
:endrule

rule:
plugin=vanillaBlocks
number=11
data:
JSON:{blockState:{blockName:"minecraft:fence",properties:{east:"false",south:"false",north:"false",west:"false"}}}
:enddata
:endrule

rule:
plugin=vanillaBlocks
number=12
data:
JSON:{blockState:{blockName:"minecraft:dark_oak_stairs",properties:{half:"bottom",shape:"straight",facing:"east"}}}
:enddata
:endrule

rule:
plugin=vanillaBlocks
number=13
data:
JSON:{blockState:{blockName:"minecraft:stone_slab",properties:{half:"bottom",variant:"wood_old"}}}
:enddata
:endrule

rule:
plugin=vanillaBlocks
number=14
data:
JSON:{blockState:{blockName:"minecraft:dark_oak_stairs",properties:{half:"bottom",shape:"straight",facing:"west"}}}
:enddata
:endrule

rule:
plugin=blockTile
number=15
data:
JSON:{blockState:{blockName:"ancientwarfarestructure:advanced_spawner",properties:{transparent:"true"}},teData:{id:"ancientwarfarestructure:advanced_spawner_tile",spawnerSettings:{minDelay:0,spawnDelay:0,lightSensitive:0b,spawnGroups:[{settingsList:[{remainingSpawnCount:1,hostile:1b,forced:1b,customTag:{factionName:"norska"},maxToSpawn:1,entityId:"ancientwarfarenpc:faction.archer.elite",minToSpawn:1}],groupWeight:1}],playerRange:32,respondToRedstone:0b,inventory:{Size:9,Items:[]},spawnRange:0,transparent:1b,maxDelay:0,xpToDrop:0,mobRange:0,debugMode:0b,maxNearbyMonsters:0}}}
:enddata
:endrule

rule:
plugin=blockTile
number=16
data:
JSON:{blockState:{blockName:"ancientwarfarestructure:advanced_spawner",properties:{transparent:"true"}},teData:{id:"ancientwarfarestructure:advanced_spawner_tile",spawnerSettings:{minDelay:0,spawnDelay:0,lightSensitive:0b,spawnGroups:[{settingsList:[{remainingSpawnCount:1,hostile:1b,forced:1b,customTag:{factionName:"norska"},maxToSpawn:1,entityId:"ancientwarfarenpc:faction.soldier",minToSpawn:1}],groupWeight:1}],playerRange:6,respondToRedstone:0b,inventory:{Size:9,Items:[]},spawnRange:0,transparent:1b,maxDelay:0,xpToDrop:0,mobRange:0,debugMode:0b,maxNearbyMonsters:0}}}
:enddata
:endrule

rule:
plugin=vanillaBlocks
number=17
data:
JSON:{blockState:{blockName:"minecraft:crafting_table"}}
:enddata
:endrule

rule:
plugin=vanillaBlocks
number=18
data:
JSON:{blockState:{blockName:"minecraft:cauldron",properties:{level:"0"}}}
:enddata
:endrule

rule:
plugin=vanillaBlocks
number=19
data:
JSON:{blockState:{blockName:"minecraft:planks",properties:{variant:"birch"}}}
:enddata
:endrule

rule:
plugin=doors
number=20
data:
JSON:{blockState:{blockName:"minecraft:wooden_door",properties:{hinge:"left",half:"lower",powered:"false",facing:"south",open:"false"}}}
:enddata
:endrule

rule:
plugin=inventory
number=21
data:
JSON:{blockState:{blockName:"minecraft:chest",properties:{facing:"west"}},lootLevel:0,teData:{ForgeData:{},Items:[],id:"minecraft:chest",Lock:""},inventoryData:{length:0,inventoryContents:[]},legacyFeatures:1b}
:enddata
:endrule

rule:
plugin=inventory
number=22
data:
JSON:{blockState:{blockName:"minecraft:chest",properties:{facing:"north"}},lootLevel:0,teData:{ForgeData:{},Items:[{Slot:1b,id:"minecraft:porkchop",Count:2b,Damage:0s},{Slot:8b,id:"minecraft:bread",Count:1b,Damage:0s},{Slot:9b,id:"minecraft:porkchop",Count:2b,Damage:0s},{Slot:10b,id:"minecraft:porkchop",Count:2b,Damage:0s},{Slot:17b,id:"minecraft:bread",Count:2b,Damage:0s},{Slot:19b,id:"minecraft:porkchop",Count:2b,Damage:0s},{Slot:26b,id:"minecraft:bread",Count:2b,Damage:0s}],id:"minecraft:chest",Lock:""},inventoryData:{length:7,inventoryContents:[{id:"minecraft:porkchop",Count:2b,slot:0,Damage:0s},{id:"minecraft:bread",Count:1b,slot:1,Damage:0s},{id:"minecraft:porkchop",Count:2b,slot:2,Damage:0s},{id:"minecraft:porkchop",Count:2b,slot:3,Damage:0s},{id:"minecraft:bread",Count:2b,slot:4,Damage:0s},{id:"minecraft:porkchop",Count:2b,slot:5,Damage:0s},{id:"minecraft:bread",Count:2b,slot:6,Damage:0s}]},legacyFeatures:1b}
:enddata
:endrule

rule:
plugin=blockTile
number=23
data:
JSON:{blockState:{blockName:"ancientwarfarestructure:advanced_spawner",properties:{transparent:"true"}},teData:{id:"ancientwarfarestructure:advanced_spawner_tile",spawnerSettings:{minDelay:0,spawnDelay:0,lightSensitive:0b,spawnGroups:[{settingsList:[{remainingSpawnCount:1,hostile:1b,forced:1b,customTag:{ArmorDropChances:[1.0f,1.0f,1.0f,1.0f],ArmorItems:[{},{},{},{}],HandDropChances:[1.0f,1.0f],factionName:"norska",HandItems:[{},{}]},maxToSpawn:1,entityId:"ancientwarfarenpc:faction.civilian.female",minToSpawn:1}],groupWeight:1}],playerRange:6,respondToRedstone:0b,inventory:{Size:9,Items:[]},spawnRange:0,transparent:1b,maxDelay:0,xpToDrop:0,mobRange:0,debugMode:0b,maxNearbyMonsters:0}}}
:enddata
:endrule

rule:
plugin=vanillaBlocks
number=24
data:
JSON:{blockState:{blockName:"minecraft:stone_slab",properties:{half:"top",variant:"wood_old"}}}
:enddata
:endrule

rule:
plugin=blockTile
number=25
data:
JSON:{blockState:{blockName:"ancientwarfarestructure:advanced_spawner",properties:{transparent:"true"}},teData:{id:"ancientwarfarestructure:advanced_spawner_tile",spawnerSettings:{minDelay:0,spawnDelay:0,lightSensitive:0b,spawnGroups:[{settingsList:[{remainingSpawnCount:1,hostile:1b,forced:1b,customTag:{ArmorDropChances:[1.0f,1.0f,1.0f,1.0f],ArmorItems:[{},{},{},{}],HandDropChances:[1.0f,1.0f],factionName:"norska",HandItems:[{id:"minecraft:iron_axe",Count:1b,Damage:0s},{id:"minecraft:iron_axe",Count:1b,Damage:0s}]},maxToSpawn:1,entityId:"ancientwarfarenpc:faction.soldier.elite",minToSpawn:1}],groupWeight:1}],playerRange:6,respondToRedstone:0b,inventory:{Size:9,Items:[]},spawnRange:0,transparent:1b,maxDelay:0,xpToDrop:0,mobRange:0,debugMode:0b,maxNearbyMonsters:0}}}
:enddata
:endrule

rule:
plugin=vanillaBlocks
number=26
data:
JSON:{blockState:{blockName:"minecraft:tallgrass",properties:{type:"tall_grass"}}}
:enddata
:endrule

rule:
plugin=inventory
number=27
data:
JSON:{blockState:{blockName:"minecraft:chest",properties:{facing:"west"}},lootLevel:0,teData:{ForgeData:{},Items:[{Slot:10b,id:"ancientwarfarenpc:coin",Count:2b,tag:{metal:"silver"},Damage:0s},{Slot:19b,id:"ancientwarfarenpc:coin",Count:2b,tag:{metal:"silver"},Damage:0s}],id:"minecraft:chest",Lock:""},inventoryData:{length:2,inventoryContents:[{id:"ancientwarfarenpc:coin",Count:2b,tag:{metal:"silver"},slot:0,Damage:0s},{id:"ancientwarfarenpc:coin",Count:2b,tag:{metal:"silver"},slot:1,Damage:0s}]},legacyFeatures:1b}
:enddata
:endrule

rule:
plugin=blockTile
number=28
data:
JSON:{blockState:{blockName:"ancientwarfarestructure:advanced_spawner",properties:{transparent:"true"}},teData:{id:"ancientwarfarestructure:advanced_spawner_tile",spawnerSettings:{minDelay:0,spawnDelay:0,lightSensitive:0b,spawnGroups:[{settingsList:[{remainingSpawnCount:1,hostile:1b,forced:1b,customTag:{ArmorDropChances:[1.0f,1.0f,1.0f,1.0f],ArmorItems:[{},{},{},{}],HandDropChances:[1.0f,1.0f],factionName:"norska",HandItems:[{},{}]},maxToSpawn:1,entityId:"ancientwarfarenpc:faction.civilian.female",minToSpawn:1}],groupWeight:1}],playerRange:6,respondToRedstone:0b,inventory:{Size:9,Items:[]},spawnRange:0,transparent:1b,maxDelay:0,xpToDrop:0,mobRange:0,debugMode:0b,maxNearbyMonsters:0}}}
:enddata
:endrule

rule:
plugin=blockTile
number=29
data:
JSON:{blockState:{blockName:"ancientwarfarestructure:advanced_spawner",properties:{transparent:"true"}},teData:{id:"ancientwarfarestructure:advanced_spawner_tile",spawnerSettings:{minDelay:0,spawnDelay:0,lightSensitive:0b,spawnGroups:[{settingsList:[{remainingSpawnCount:1,hostile:1b,forced:1b,customTag:{factionName:"norska"},maxToSpawn:1,entityId:"ancientwarfarenpc:faction.soldier",minToSpawn:1}],groupWeight:1}],playerRange:6,respondToRedstone:0b,inventory:{Size:9,Items:[]},spawnRange:0,transparent:1b,maxDelay:0,xpToDrop:0,mobRange:0,debugMode:0b,maxNearbyMonsters:0}}}
:enddata
:endrule

rule:
plugin=inventory
number=30
data:
JSON:{blockState:{blockName:"minecraft:chest",properties:{facing:"west"}},lootLevel:0,teData:{Items:[{Slot:1b,id:"ancientwarfarenpc:coin",Count:2b,tag:{metal:"silver"},Damage:0s},{Slot:10b,id:"ancientwarfarenpc:coin",Count:1b,tag:{metal:"silver"},Damage:0s},{Slot:20b,id:"ancientwarfarenpc:coin",Count:2b,tag:{metal:"silver"},Damage:0s}],id:"minecraft:chest",Lock:""},inventoryData:{length:3,inventoryContents:[{id:"ancientwarfarenpc:coin",Count:2b,tag:{metal:"silver"},slot:0,Damage:0s},{id:"ancientwarfarenpc:coin",Count:1b,tag:{metal:"silver"},slot:1,Damage:0s},{id:"ancientwarfarenpc:coin",Count:2b,tag:{metal:"silver"},slot:2,Damage:0s}]},legacyFeatures:1b}
:enddata
:endrule

rule:
plugin=vanillaBlocks
number=31
data:
JSON:{blockState:{blockName:"minecraft:stone_stairs",properties:{half:"bottom",shape:"straight",facing:"east"}}}
:enddata
:endrule

rule:
plugin=blockTile
number=32
data:
JSON:{blockState:{blockName:"ancientwarfarestructure:advanced_spawner",properties:{transparent:"true"}},teData:{id:"ancientwarfarestructure:advanced_spawner_tile",spawnerSettings:{minDelay:0,spawnDelay:0,lightSensitive:0b,spawnGroups:[{settingsList:[{remainingSpawnCount:1,hostile:1b,forced:1b,customTag:{ArmorDropChances:[1.0f,1.0f,1.0f,1.0f],ArmorItems:[{},{},{},{}],HandDropChances:[1.0f,1.0f],factionName:"norska",HandItems:[{id:"minecraft:iron_axe",Count:1b,Damage:0s},{id:"minecraft:iron_axe",Count:1b,Damage:0s}]},maxToSpawn:1,entityId:"ancientwarfarenpc:faction.soldier.elite",minToSpawn:1}],groupWeight:1}],playerRange:6,respondToRedstone:0b,inventory:{Size:9,Items:[]},spawnRange:0,transparent:1b,maxDelay:0,xpToDrop:0,mobRange:0,debugMode:0b,maxNearbyMonsters:0}}}
:enddata
:endrule

rule:
plugin=vanillaSign
number=33
data:
JSON:{signContents0:"Trollvile§r",blockState:{blockName:"minecraft:wall_sign",properties:{facing:"west"}},signContents2:"Freehouse§r",signContents1:"Ales§r",signContents3:"",rotation:0}
:enddata
:endrule

rule:
plugin=vanillaBlocks
number=34
data:
JSON:{blockState:{blockName:"ancientwarfarestructure:fire_pit",properties:{lit:"true",variant:"square"}}}
:enddata
:endrule

rule:
plugin=blockTile
number=35
data:
JSON:{blockState:{blockName:"ancientwarfarestructure:advanced_spawner",properties:{transparent:"true"}},teData:{id:"ancientwarfarestructure:advanced_spawner_tile",spawnerSettings:{minDelay:0,spawnDelay:0,lightSensitive:0b,spawnGroups:[{settingsList:[{remainingSpawnCount:1,hostile:1b,forced:1b,customTag:{ArmorDropChances:[1.0f,1.0f,1.0f,1.0f],ArmorItems:[{},{},{},{}],HandDropChances:[1.0f,1.0f],factionName:"norska",HandItems:[{id:"minecraft:bow",Count:1b,Damage:0s},{}]},maxToSpawn:1,entityId:"ancientwarfarenpc:faction.archer",minToSpawn:1}],groupWeight:1}],playerRange:6,respondToRedstone:0b,inventory:{Size:9,Items:[]},spawnRange:0,transparent:1b,maxDelay:0,xpToDrop:0,mobRange:0,debugMode:0b,maxNearbyMonsters:0}}}
:enddata
:endrule

rule:
plugin=blockTile
number=36
data:
JSON:{blockState:{blockName:"ancientwarfarestructure:advanced_spawner",properties:{transparent:"true"}},teData:{id:"ancientwarfarestructure:advanced_spawner_tile",spawnerSettings:{minDelay:0,spawnDelay:0,lightSensitive:0b,spawnGroups:[{settingsList:[{remainingSpawnCount:1,hostile:1b,forced:1b,customTag:{factionName:"norska"},maxToSpawn:1,entityId:"ancientwarfarenpc:faction.soldier",minToSpawn:1}],groupWeight:1}],playerRange:6,respondToRedstone:0b,inventory:{Size:9,Items:[]},spawnRange:0,transparent:1b,maxDelay:0,xpToDrop:0,mobRange:0,debugMode:0b,maxNearbyMonsters:0}}}
:enddata
:endrule

rule:
plugin=vanillaBlocks
number=37
data:
JSON:{blockState:{blockName:"minecraft:torch",properties:{facing:"up"}}}
:enddata
:endrule

rule:
plugin=doors
number=38
data:
JSON:{blockState:{blockName:"minecraft:wooden_door",properties:{hinge:"left",half:"upper",powered:"false",facing:"south",open:"false"}}}
:enddata
:endrule

rule:
plugin=vanillaBlocks
number=39
data:
JSON:{blockState:{blockName:"minecraft:fence_gate",properties:{in_wall:"false",powered:"false",facing:"east",open:"true"}}}
:enddata
:endrule

rule:
plugin=vanillaBlocks
number=40
data:
JSON:{blockState:{blockName:"minecraft:stone_stairs",properties:{half:"top",shape:"straight",facing:"east"}}}
:enddata
:endrule

rule:
plugin=vanillaSign
number=41
data:
JSON:{signContents0:"Baldurs§r",blockState:{blockName:"minecraft:wall_sign",properties:{facing:"west"}},signContents2:"",signContents1:"Bladdered§r",signContents3:"",rotation:0}
:enddata
:endrule

rule:
plugin=vanillaBlocks
number=42
data:
JSON:{blockState:{blockName:"minecraft:wooden_pressure_plate",properties:{powered:"false"}}}
:enddata
:endrule

rule:
plugin=vanillaSign
number=43
data:
JSON:{signContents0:"Norska§r",blockState:{blockName:"minecraft:wall_sign",properties:{facing:"west"}},signContents2:"",signContents1:"Tavern§r",signContents3:"",rotation:0}
:enddata
:endrule

rule:
plugin=vanillaBlocks
number=44
data:
JSON:{blockState:{blockName:"minecraft:torch",properties:{facing:"east"}}}
:enddata
:endrule

rule:
plugin=vanillaBlocks
number=45
data:
JSON:{blockState:{blockName:"minecraft:torch",properties:{facing:"west"}}}
:enddata
:endrule

rule:
plugin=vanillaBlocks
number=46
data:
JSON:{blockState:{blockName:"minecraft:torch",properties:{facing:"north"}}}
:enddata
:endrule

rule:
plugin=vanillaBlocks
number=47
data:
JSON:{blockState:{blockName:"minecraft:torch",properties:{facing:"south"}}}
:enddata
:endrule

rule:
plugin=vanillaBlocks
number=48
data:
JSON:{blockState:{blockName:"minecraft:dark_oak_stairs",properties:{half:"top",shape:"straight",facing:"east"}}}
:enddata
:endrule

rule:
plugin=vanillaBlocks
number=49
data:
JSON:{blockState:{blockName:"minecraft:dark_oak_stairs",properties:{half:"top",shape:"straight",facing:"west"}}}
:enddata
:endrule

rule:
plugin=vanillaBlocks
number=50
data:
JSON:{blockState:{blockName:"minecraft:stone_slab",properties:{half:"top",variant:"cobblestone"}}}
:enddata
:endrule

rule:
plugin=vanillaBlocks
number=51
data:
JSON:{blockState:{blockName:"minecraft:netherrack"}}
:enddata
:endrule

rule:
plugin=vanillaBlocks
number=52
data:
JSON:{blockState:{blockName:"minecraft:double_stone_slab",properties:{seamless:"false",variant:"cobblestone"}}}
:enddata
:endrule

rule:
plugin=vanillaBlocks
number=53
data:
JSON:{blockState:{blockName:"minecraft:fire",properties:{east:"false",south:"false",north:"false",west:"false",up:"false",age:"15"}}}
:enddata
:endrule

#### ENTITIES ####
