# Ancient Warfare Structure Template File
# Auto-generated structure template file. created on: 1/2/2019 at: 23:32:41
# Lines beginning with # denote comments

header:
version=2.8
name=NorskaTavernTheRagnorok
mods=
size=23,19,24
offset=11,10,23
:endheader

#### VALIDATION ####
validation:
type=ground
survival=false
worldGenEnabled=true
unique=false
preserveBlocks=false
selectionWeight=50
clusterValue=40
minDuplicateDistance=1000
dimensionWhiteList=true
dimensionList=0
biomeWhiteList=true
biomeList=minecraft:taiga_cold,traverse:snowy_coniferous_forest,biomesoplenty:cold_desert,minecraft:ice_mountains,biomesoplenty:alps,minecraft:ice_flats,minecraft:taiga_cold_hills,minecraft:cold_beach
leveling=6
fill=6
border=6
blockSwap=false
:endvalidation

#### LAYERS ####
layer: 0
1,1,1,1,1,1,1,1,1,1,1,1,1,1,1,1,1,1,1,1,1,1,1
1,1,1,1,1,1,1,1,1,1,1,1,1,1,1,1,1,1,1,1,1,1,1
1,1,1,1,1,1,1,1,1,1,1,1,1,1,1,1,1,1,1,1,1,1,1
1,1,1,1,1,1,1,1,1,1,1,1,1,1,1,1,1,1,1,1,1,1,1
1,1,1,1,1,1,1,1,1,1,1,1,1,1,1,1,1,1,1,1,1,1,1
1,1,1,1,1,1,1,1,1,1,1,1,1,1,1,1,1,1,1,1,1,1,1
1,1,1,1,1,1,1,1,1,1,1,1,1,1,1,1,1,1,1,1,1,1,1
1,1,1,1,1,1,1,1,1,1,1,1,1,1,1,1,1,1,1,1,1,1,1
1,1,1,1,1,1,1,1,1,1,1,1,1,1,1,1,1,1,1,1,1,1,1
1,1,1,1,1,1,1,1,1,1,1,1,1,1,1,1,1,1,1,1,1,1,1
1,1,1,1,1,1,1,1,1,1,1,1,1,1,1,1,1,1,1,1,1,1,1
1,1,1,1,1,1,1,1,1,1,1,1,1,1,1,1,1,1,1,1,1,1,1
1,1,1,1,1,1,1,1,1,1,1,1,1,1,1,1,1,1,1,1,1,1,1
1,1,1,1,1,1,1,1,1,1,1,1,1,1,1,1,1,1,1,1,1,1,1
1,1,1,1,1,1,1,1,1,1,1,1,1,1,1,1,1,1,1,1,1,1,1
1,1,1,1,1,1,1,1,1,1,1,1,1,1,1,1,1,1,1,1,1,1,1
1,1,1,1,1,1,1,1,1,1,1,1,1,1,1,1,1,1,1,1,1,1,1
1,1,1,1,1,1,1,1,1,1,1,1,1,1,1,1,1,1,1,1,1,1,1
1,1,1,1,1,1,1,1,1,1,1,1,1,1,1,1,1,1,1,1,1,1,1
1,1,1,1,1,1,1,1,1,1,1,1,1,1,1,1,1,1,1,1,1,1,1
1,1,1,1,1,1,1,1,1,1,1,1,1,1,1,1,1,1,1,1,1,1,1
1,1,1,1,1,1,1,1,1,1,1,1,1,1,1,1,1,1,1,1,1,1,1
1,1,1,1,1,1,1,1,1,1,1,1,1,1,1,1,1,1,1,1,1,1,1
1,1,1,1,1,1,1,1,1,1,1,1,1,1,1,1,1,1,1,1,1,1,1
:endlayer
layer: 1
1,1,1,1,1,1,1,1,1,1,1,1,1,1,1,1,1,1,1,1,1,1,1
1,1,1,1,1,1,1,1,1,1,1,1,1,1,1,1,1,1,1,1,1,1,1
1,1,1,1,1,1,1,1,1,1,1,1,1,1,1,1,1,1,1,1,1,1,1
1,1,1,1,1,1,1,1,1,1,1,1,1,1,1,1,1,1,1,1,1,1,1
1,1,1,1,1,1,1,1,1,1,1,1,1,1,1,1,1,1,1,1,1,1,1
1,1,1,1,1,1,1,1,1,1,1,1,1,1,1,1,1,1,1,1,1,1,1
1,1,1,1,1,1,1,1,1,1,1,1,1,1,1,1,1,1,1,1,1,1,1
1,1,1,1,1,1,1,1,1,1,1,1,1,1,1,1,1,1,1,1,1,1,1
1,1,1,1,1,1,1,1,1,1,1,1,1,1,1,1,1,1,1,1,1,1,1
1,1,1,1,1,1,1,1,1,1,1,1,1,1,1,1,1,1,1,1,1,1,1
1,1,1,1,1,1,1,1,1,1,1,1,1,1,1,1,1,1,1,1,1,1,1
1,1,1,1,1,1,1,1,1,1,1,1,1,1,1,1,1,1,1,1,1,1,1
1,1,1,1,1,1,1,1,1,1,1,1,1,1,1,1,1,1,1,1,1,1,1
1,1,1,1,1,1,1,1,1,1,1,1,1,1,1,1,1,1,1,1,1,1,1
1,1,1,1,1,1,1,1,1,1,1,1,1,1,1,1,1,1,1,1,1,1,1
1,1,1,1,1,1,1,1,1,1,1,1,1,1,1,1,1,1,1,1,1,1,1
1,1,1,1,1,1,1,1,1,1,1,1,1,1,1,1,1,1,1,1,1,1,1
1,1,1,1,1,1,1,1,1,1,1,1,1,1,1,1,1,1,1,1,1,1,1
1,1,1,1,1,1,1,1,1,1,1,1,1,1,1,1,1,1,1,1,1,1,1
1,1,1,1,1,1,1,1,1,1,1,1,1,1,1,1,1,1,1,1,1,1,1
1,1,1,1,1,1,1,1,1,1,1,1,1,1,1,1,1,1,1,1,1,1,1
1,1,1,1,1,1,1,1,1,1,1,1,1,1,1,1,1,1,1,1,1,1,1
1,1,1,1,1,1,1,1,1,1,1,1,1,1,1,1,1,1,1,1,1,1,1
1,1,1,1,1,1,1,1,1,1,1,1,1,1,1,1,1,1,1,1,1,1,1
:endlayer
layer: 2
1,1,1,1,1,1,1,1,1,1,1,1,1,1,1,1,1,1,1,1,1,1,1
1,1,1,1,1,1,1,1,1,1,1,1,1,1,1,1,1,1,1,1,1,1,1
1,1,1,1,1,1,1,1,1,1,1,1,1,1,1,1,1,1,1,1,1,1,1
1,1,1,1,1,1,1,1,1,1,1,1,1,1,1,1,1,1,1,1,1,1,1
1,1,1,1,1,1,1,1,1,1,1,1,1,1,1,1,1,1,1,1,1,1,1
1,1,1,1,1,1,1,1,1,1,1,1,1,1,1,1,1,1,1,1,1,1,1
1,1,1,1,1,1,1,1,1,1,1,1,1,1,1,1,1,1,1,1,1,1,1
1,1,1,1,1,1,1,1,1,1,1,1,1,1,1,1,1,1,1,1,1,1,1
1,1,1,1,1,1,1,1,1,1,1,1,1,1,1,1,1,1,1,1,1,1,1
1,1,1,1,1,1,1,1,1,1,1,1,1,1,1,1,1,1,1,1,1,1,1
1,1,1,1,1,1,1,1,1,1,1,1,1,1,1,1,1,1,1,1,1,1,1
1,1,1,1,1,1,1,1,1,1,1,1,1,1,1,1,1,1,1,1,1,1,1
1,1,1,1,1,1,1,1,1,1,1,1,1,1,1,1,1,1,1,1,1,1,1
1,1,1,1,1,1,1,1,1,1,1,1,1,1,1,1,1,1,1,1,1,1,1
1,1,1,1,1,1,1,1,1,1,1,1,1,1,1,1,1,1,1,1,1,1,1
1,1,1,1,1,1,1,1,1,1,1,1,1,1,1,1,1,1,1,1,1,1,1
1,1,1,1,1,1,1,1,1,1,1,1,1,1,1,1,1,1,1,1,1,1,1
1,1,1,1,1,1,1,1,1,1,1,1,1,1,1,1,1,1,1,1,1,1,1
1,1,1,1,1,1,1,1,1,1,1,1,1,1,1,1,1,1,1,1,1,1,1
1,1,1,1,1,1,1,1,1,1,1,1,1,1,1,1,1,1,1,1,1,1,1
1,1,1,1,1,1,1,1,1,1,1,1,1,1,1,1,1,1,1,1,1,1,1
1,1,1,1,1,1,1,1,1,1,1,1,1,1,1,1,1,1,1,1,1,1,1
1,1,1,1,1,1,1,1,1,1,1,1,1,1,1,1,1,1,1,1,1,1,1
1,1,1,1,1,1,1,1,1,1,1,1,1,1,1,1,1,1,1,1,1,1,1
:endlayer
layer: 3
1,1,1,1,1,1,1,1,1,1,1,1,1,1,1,1,1,1,1,1,1,1,1
1,1,1,1,1,1,1,1,1,1,1,1,1,1,1,1,1,1,1,1,1,1,1
1,1,1,1,1,1,1,1,1,1,1,1,1,1,1,1,1,1,1,1,1,1,1
1,1,1,1,1,1,1,1,1,1,1,1,1,1,1,1,1,1,1,1,1,1,1
1,1,1,1,1,1,1,1,1,1,1,1,1,1,1,1,1,1,1,1,1,1,1
1,1,1,1,1,1,1,1,1,1,1,1,1,1,1,1,1,1,1,1,1,1,1
1,1,1,1,1,1,1,1,1,1,1,1,1,1,1,1,1,1,1,1,1,1,1
1,1,1,1,1,1,1,1,1,1,1,1,1,1,1,1,1,1,1,1,1,1,1
1,1,1,1,1,1,1,1,1,1,1,1,1,1,1,1,1,1,1,1,1,1,1
1,1,1,1,1,1,1,1,1,1,1,1,1,1,1,1,1,1,1,1,1,1,1
1,1,1,1,1,1,1,1,1,1,1,1,1,1,1,1,1,1,1,1,1,1,1
1,1,1,1,1,1,1,1,1,1,1,1,1,1,1,1,1,1,1,1,1,1,1
1,1,1,1,1,1,1,1,1,1,1,1,1,1,1,1,1,1,1,1,1,1,1
1,1,1,1,1,1,1,1,1,1,1,1,1,1,1,1,1,1,1,1,1,1,1
1,1,1,1,1,1,1,1,1,1,1,1,1,1,1,1,1,1,1,1,1,1,1
1,1,1,1,1,1,1,1,1,1,1,1,1,1,1,1,1,1,1,1,1,1,1
1,1,1,1,1,1,1,1,1,1,1,1,1,1,1,1,1,1,1,1,1,1,1
1,1,1,1,1,1,1,1,1,1,1,1,1,1,1,1,1,1,1,1,1,1,1
1,1,1,1,1,1,1,1,1,1,1,1,1,1,1,1,1,1,1,1,1,1,1
1,1,1,1,1,1,1,1,1,1,1,1,1,1,1,1,1,1,1,1,1,1,1
1,1,1,1,1,1,1,1,1,1,1,1,1,1,1,1,1,1,1,1,1,1,1
1,1,1,1,1,1,1,1,1,1,1,1,1,1,1,1,1,1,1,1,1,1,1
1,1,1,1,1,1,1,1,1,1,1,1,1,1,1,1,1,1,1,1,1,1,1
1,1,1,1,1,1,1,1,1,1,1,1,1,1,1,1,1,1,1,1,1,1,1
:endlayer
layer: 4
1,1,1,1,1,1,1,1,1,1,1,1,1,1,1,1,1,1,1,1,1,1,1
1,1,1,1,1,1,1,1,1,1,1,1,1,1,1,1,1,1,1,1,1,1,1
1,1,1,1,1,1,1,1,1,1,1,1,1,1,1,1,1,1,1,1,1,1,1
1,1,1,1,1,1,1,1,1,1,1,1,1,1,1,1,1,1,1,1,1,1,1
1,1,1,1,1,1,1,1,1,1,1,1,1,1,1,1,1,1,1,1,1,1,1
1,1,1,1,1,1,1,1,1,1,1,1,1,1,1,1,1,1,1,1,1,1,1
1,1,1,1,1,1,1,1,1,1,1,1,1,1,1,1,1,1,1,1,1,1,1
1,1,1,1,1,1,1,1,1,1,1,1,1,1,1,1,1,1,1,1,1,1,1
1,1,1,1,1,1,1,1,1,1,1,1,1,1,1,1,1,1,1,1,1,1,1
1,1,1,1,1,1,1,1,1,1,1,1,1,1,1,1,1,1,1,1,1,1,1
1,1,1,1,1,1,1,1,1,1,1,1,1,1,1,1,1,1,1,1,1,1,1
1,1,1,1,1,1,1,1,1,1,1,1,1,1,1,1,1,1,1,1,1,1,1
1,1,1,1,1,1,1,1,1,1,1,1,1,1,1,1,1,1,1,1,1,1,1
1,1,1,1,1,1,1,1,1,1,1,1,1,1,1,1,1,1,1,1,1,1,1
1,1,1,1,1,1,1,1,1,1,1,1,1,1,1,1,1,1,1,1,1,1,1
1,1,1,1,1,1,1,1,1,1,1,1,1,1,1,1,1,1,1,1,1,1,1
1,1,1,1,1,1,1,1,1,1,1,1,1,1,1,1,1,1,1,1,1,1,1
1,1,1,1,1,1,1,1,1,1,1,1,1,1,1,1,1,1,1,1,1,1,1
1,1,1,1,1,1,1,1,1,1,1,1,1,1,1,1,1,1,1,1,1,1,1
1,1,1,1,1,1,1,1,1,1,1,1,1,1,1,1,1,1,1,1,1,1,1
1,1,1,1,1,1,1,1,1,1,1,1,1,1,1,1,1,1,1,1,1,1,1
1,1,1,1,1,1,1,1,1,1,1,1,1,1,1,1,1,1,1,1,1,1,1
1,1,1,1,1,1,1,1,1,1,1,1,1,1,1,1,1,1,1,1,1,1,1
1,1,1,1,1,1,1,1,1,1,1,1,1,1,1,1,1,1,1,1,1,1,1
:endlayer
layer: 5
1,1,1,1,1,1,1,1,1,1,1,1,1,1,1,1,1,1,1,1,1,1,1
1,1,1,1,1,1,1,1,1,1,1,1,1,1,1,1,1,1,1,1,1,1,1
1,1,1,1,1,1,1,1,1,1,1,1,1,1,1,1,1,1,1,1,1,1,1
1,1,1,1,1,1,1,1,1,1,1,1,1,1,1,1,1,1,1,1,1,1,1
1,1,1,1,1,1,1,1,1,1,1,1,1,1,1,1,1,1,1,1,1,1,1
1,1,1,1,1,1,1,1,1,1,1,1,1,1,1,1,1,1,1,1,1,1,1
1,1,1,1,1,1,1,1,1,1,1,1,1,1,1,1,1,1,1,1,1,1,1
1,1,1,1,1,1,1,1,1,1,1,1,1,1,1,1,1,1,1,1,1,1,1
1,1,1,1,1,1,1,1,1,1,1,1,1,1,1,1,1,1,1,1,1,1,1
1,1,1,1,1,1,1,1,1,1,1,1,1,1,1,1,1,1,1,1,1,1,1
1,1,1,1,1,1,1,1,1,1,1,1,1,1,1,1,1,1,1,1,1,1,1
1,1,1,1,1,1,1,1,1,1,1,1,1,1,1,1,1,1,1,1,1,1,1
1,1,1,1,1,1,1,1,1,1,1,1,1,1,1,1,1,1,1,1,1,1,1
1,1,1,1,1,1,1,1,1,1,1,1,1,1,1,1,1,1,1,1,1,1,1
1,1,1,1,1,1,1,1,1,1,1,1,1,1,1,1,1,1,1,1,1,1,1
1,1,1,1,1,1,1,1,1,1,1,1,1,1,1,1,1,1,1,1,1,1,1
1,1,1,1,1,1,1,1,1,1,1,1,1,1,1,1,1,1,1,1,1,1,1
1,1,1,1,1,1,1,1,1,1,1,1,1,1,1,1,1,1,1,1,1,1,1
1,1,1,1,1,1,1,1,1,1,1,1,1,1,1,1,1,1,1,1,1,1,1
1,1,1,1,1,1,1,1,1,1,1,1,1,1,1,1,1,1,1,1,1,1,1
1,1,1,1,1,1,1,1,1,1,1,1,1,1,1,1,1,1,1,1,1,1,1
1,1,1,1,1,1,1,1,1,1,1,1,1,1,1,1,1,1,1,1,1,1,1
1,1,1,1,1,1,1,1,1,1,1,1,1,1,1,1,1,1,1,1,1,1,1
1,1,1,1,1,1,1,1,1,1,1,1,1,1,1,1,1,1,1,1,1,1,1
:endlayer
layer: 6
1,1,1,1,1,1,1,1,1,1,1,1,1,1,1,1,1,1,1,1,1,1,1
1,1,1,1,1,1,1,1,1,1,1,1,1,1,1,1,1,1,1,1,1,1,1
1,1,1,1,1,1,1,1,1,1,1,1,1,1,1,1,1,1,1,1,1,1,1
1,1,1,1,1,1,1,1,1,1,1,1,1,1,1,1,1,1,1,1,1,1,1
1,1,1,1,1,1,1,1,1,1,1,1,1,1,1,1,1,1,1,1,1,1,1
1,1,1,1,1,1,1,1,1,1,1,1,1,1,1,1,1,1,1,1,1,1,1
1,1,1,1,1,1,1,1,1,1,1,1,1,1,1,1,1,1,1,1,1,1,1
1,1,1,1,1,1,1,1,1,1,1,1,1,1,1,1,1,1,1,1,1,1,1
1,1,1,1,1,1,1,1,1,1,1,1,1,1,1,1,1,1,1,1,1,1,1
1,1,1,1,1,1,1,1,1,1,1,1,1,1,1,1,1,1,1,1,1,1,1
1,1,1,1,1,1,1,1,1,1,1,1,1,1,1,1,1,1,1,1,1,1,1
1,1,1,1,1,1,1,1,1,1,1,1,1,1,1,1,1,1,1,1,1,1,1
1,1,1,1,1,1,1,1,1,1,1,1,1,1,1,1,1,1,1,1,1,1,1
1,1,1,1,1,1,1,1,1,1,1,1,1,1,1,1,1,1,1,1,1,1,1
1,1,1,1,1,1,1,1,1,1,1,1,1,1,1,1,1,1,1,1,1,1,1
1,1,1,1,1,1,1,1,1,1,1,1,1,1,1,1,1,1,1,1,1,1,1
1,1,1,1,1,1,1,1,1,1,1,1,1,1,1,1,1,1,1,1,1,1,1
1,1,1,1,1,1,1,1,1,1,1,1,1,1,1,1,1,1,1,1,1,1,1
1,1,1,1,1,1,1,1,1,1,1,1,1,1,1,1,1,1,1,1,1,1,1
1,1,1,1,1,1,1,1,1,1,1,1,1,1,1,1,1,1,1,1,1,1,1
1,1,1,1,1,1,1,1,1,1,1,1,1,1,1,1,1,1,1,1,1,1,1
1,1,1,1,1,1,1,1,1,1,1,1,1,1,1,1,1,1,1,1,1,1,1
1,1,1,1,1,1,1,1,1,1,1,1,1,1,1,1,1,1,1,1,1,1,1
1,1,1,1,1,1,1,1,1,1,1,1,1,1,1,1,1,1,1,1,1,1,1
:endlayer
layer: 7
1,1,1,1,1,1,1,1,1,1,1,1,1,1,1,1,1,1,1,1,1,1,1
1,1,1,1,1,1,1,1,1,1,1,1,1,1,1,1,1,1,1,1,1,1,1
1,1,1,1,1,1,1,1,1,1,1,1,1,1,1,1,1,1,1,1,1,1,1
1,1,1,1,1,1,1,1,1,1,1,1,1,1,1,1,1,1,1,1,1,1,1
1,1,1,1,1,1,1,1,1,1,1,1,1,1,1,1,1,1,1,1,1,1,1
1,1,1,1,1,1,1,1,1,1,1,1,1,1,1,1,1,1,1,1,1,1,1
1,1,1,1,1,1,1,1,1,1,1,1,1,1,1,1,1,1,1,1,1,1,1
1,1,1,1,1,1,1,1,1,1,1,1,1,1,1,1,1,1,1,1,1,1,1
1,1,1,1,1,1,1,1,1,1,1,1,1,1,1,1,1,1,1,1,1,1,1
1,1,1,1,1,1,1,1,1,1,1,1,1,1,1,1,1,1,1,1,1,1,1
1,1,1,1,1,1,1,1,1,1,1,1,1,1,1,1,1,1,1,1,1,1,1
1,1,1,1,1,1,1,1,1,1,1,1,1,1,1,1,1,1,1,1,1,1,1
1,1,1,1,1,1,1,1,1,1,1,1,1,1,1,1,1,1,1,1,1,1,1
1,1,1,1,1,1,1,1,1,1,1,1,1,1,1,1,1,1,1,1,1,1,1
1,1,1,1,1,1,1,1,1,1,1,1,1,1,1,1,1,1,1,1,1,1,1
1,1,1,1,1,1,1,1,1,1,1,1,1,1,1,1,1,1,1,1,1,1,1
1,1,1,1,1,1,1,1,1,1,1,1,1,1,1,1,1,1,1,1,1,1,1
1,1,1,1,1,1,1,1,1,1,1,1,1,1,1,1,1,1,1,1,1,1,1
1,1,1,1,1,1,1,1,1,1,1,1,1,1,1,1,1,1,1,1,1,1,1
1,1,1,1,1,1,1,1,1,1,1,1,1,1,1,1,1,1,1,1,1,1,1
1,1,1,1,1,1,1,1,1,1,1,1,1,1,1,1,1,1,1,1,1,1,1
1,1,1,1,1,1,1,1,1,1,1,1,1,1,1,1,1,1,1,1,1,1,1
1,1,1,1,1,1,1,1,1,1,1,1,1,1,1,1,1,1,1,1,1,1,1
1,1,1,1,1,1,1,1,1,1,1,1,1,1,1,1,1,1,1,1,1,1,1
:endlayer
layer: 8
1,1,1,1,1,1,1,1,1,1,1,1,1,1,1,1,1,1,1,1,1,1,1
1,1,1,1,1,1,1,1,1,1,1,1,1,1,1,1,1,1,1,1,1,1,1
1,1,1,1,1,1,1,1,1,1,1,1,1,1,1,1,1,1,1,1,1,1,1
1,1,1,1,1,1,1,1,1,1,1,1,1,1,1,1,1,1,1,1,1,1,1
1,1,1,1,1,1,1,1,1,1,1,1,1,1,1,1,1,1,1,1,1,1,1
1,1,1,1,1,1,1,1,1,1,1,1,1,1,1,1,1,1,1,1,1,1,1
1,1,1,1,1,1,1,1,1,1,1,1,1,1,1,1,1,1,1,1,1,1,1
1,1,1,1,1,1,1,1,1,1,1,1,1,1,1,1,1,1,1,1,1,1,1
1,1,1,1,1,1,1,1,1,1,1,1,1,1,1,1,1,1,1,1,1,1,1
1,1,1,1,1,1,1,1,1,1,1,1,1,1,1,1,1,1,1,1,1,1,1
1,1,1,1,1,1,1,1,1,1,1,1,1,1,1,1,1,1,1,1,1,1,1
1,1,1,1,1,1,1,1,1,1,1,1,1,1,1,1,1,1,1,1,1,1,1
1,1,1,1,1,1,1,1,1,1,1,1,1,1,1,1,1,1,1,1,1,1,1
1,1,1,1,1,1,1,1,1,1,1,1,1,1,1,1,1,1,1,1,1,1,1
1,1,1,1,1,1,1,1,1,1,1,1,1,1,1,1,1,1,1,1,1,1,1
1,1,1,1,1,1,1,1,1,1,1,1,1,1,1,1,1,1,1,1,1,1,1
1,1,1,1,1,1,1,1,1,1,1,1,1,1,1,1,1,1,1,1,1,1,1
1,1,1,1,1,1,1,1,1,1,1,1,1,1,1,1,1,1,1,1,1,1,1
1,1,1,1,1,1,1,1,1,1,1,1,1,1,1,1,1,1,1,1,1,1,1
1,1,1,1,1,1,1,1,1,1,1,1,1,1,1,1,1,1,1,1,1,1,1
1,1,1,1,1,1,1,1,1,1,1,1,1,1,1,1,1,1,1,1,1,1,1
1,1,1,1,1,1,1,1,1,1,1,1,1,1,1,1,1,1,1,1,1,1,1
1,1,1,1,1,1,1,1,1,1,1,1,1,1,1,1,1,1,1,1,1,1,1
1,1,1,1,1,1,1,1,1,1,1,1,1,1,1,1,1,1,1,1,1,1,1
:endlayer
layer: 9
2,2,2,2,2,2,2,2,2,2,2,2,2,2,2,2,2,2,2,2,2,2,2
2,2,2,2,2,2,2,2,2,2,2,2,2,2,2,2,2,2,2,2,2,2,2
2,2,1,2,2,2,2,2,2,2,2,2,2,2,2,2,2,2,2,2,1,2,2
2,2,2,2,2,2,2,2,2,2,2,2,2,2,2,2,2,2,2,2,2,2,2
2,2,2,2,2,2,2,2,1,1,1,3,3,1,1,1,2,2,2,2,2,2,2
2,2,2,2,2,2,2,2,1,4,5,4,4,5,4,1,2,2,2,2,2,2,2
2,2,2,2,2,2,2,2,1,4,4,4,4,4,4,1,2,2,2,2,2,2,2
2,2,2,2,2,2,2,2,1,4,4,4,4,4,4,1,2,2,2,2,2,2,2
2,2,2,2,2,2,2,2,1,4,4,4,4,4,4,1,2,2,2,2,2,2,2
2,2,2,1,1,1,1,1,1,4,4,4,4,4,4,1,1,1,1,1,1,2,2
2,2,2,1,4,4,4,4,4,4,4,4,4,4,4,4,4,4,4,4,1,2,2
2,2,2,1,4,4,4,4,4,4,4,4,4,4,4,4,4,4,4,4,1,2,2
2,2,2,3,4,4,4,4,4,4,4,4,4,4,4,4,4,4,4,4,3,2,2
2,2,2,3,4,4,4,4,4,4,4,4,4,4,4,4,4,4,4,4,3,2,2
2,2,2,1,4,4,4,4,4,4,4,4,4,4,4,4,4,4,4,4,1,2,2
2,2,2,1,4,4,4,4,4,4,4,4,4,4,4,4,4,4,4,4,1,2,2
2,2,2,1,1,1,1,1,1,4,4,4,4,4,4,1,1,1,1,1,1,2,2
2,2,2,2,2,2,2,2,1,4,4,4,4,4,4,1,2,2,2,2,2,2,2
2,2,2,2,2,2,2,2,1,4,4,4,4,4,4,1,2,2,2,2,2,2,2
2,2,2,2,2,2,2,2,1,4,4,4,4,4,4,1,2,2,2,2,2,2,2
2,2,2,2,2,2,2,2,1,4,4,4,4,4,4,1,2,2,2,2,2,2,2
2,2,1,2,2,2,2,2,1,1,1,3,3,1,1,1,2,2,2,2,1,2,2
2,2,2,2,2,2,2,2,2,2,2,2,2,2,2,2,2,2,2,2,2,2,2
2,2,2,2,2,2,2,2,2,2,2,2,2,2,2,2,2,2,2,2,2,2,2
:endlayer
layer: 10
6,6,0,6,6,6,6,6,6,6,6,6,6,6,6,6,6,6,6,6,0,6,6
6,0,0,0,6,6,6,6,6,6,6,6,6,6,6,6,6,6,6,0,0,0,6
0,0,5,0,0,6,6,6,6,6,6,6,6,6,6,6,6,6,0,0,5,0,0
6,0,0,0,6,6,9,6,6,0,6,6,6,6,0,6,6,7,6,0,0,0,6
6,6,0,6,6,6,6,6,10,10,10,10,10,10,10,10,6,6,6,6,0,6,6
6,6,6,6,6,6,6,6,10,0,45,47,46,45,0,10,6,6,6,6,6,6,6
6,6,6,6,6,6,6,6,10,44,0,43,0,0,42,10,6,6,6,6,6,6,6
6,6,6,6,6,6,6,6,10,41,0,40,40,0,39,10,6,6,6,6,6,6,6
6,6,6,6,6,6,6,6,10,38,0,0,37,0,0,10,6,6,6,6,6,6,6
6,6,6,10,10,10,10,10,10,36,36,36,36,36,35,10,10,10,10,10,10,6,6
6,6,8,10,0,0,34,0,0,0,33,32,0,31,0,0,0,30,0,0,10,8,6
6,6,6,10,0,0,0,0,0,0,0,0,0,0,0,0,0,0,0,0,10,6,6
6,6,6,25,0,0,21,8,20,29,0,28,27,0,26,21,8,20,0,0,24,6,6
6,6,6,25,0,0,21,8,20,0,21,8,8,20,0,21,8,20,0,0,24,6,6
6,6,6,10,0,0,0,23,0,0,21,8,8,20,0,0,0,0,0,0,10,6,6
6,6,8,10,0,0,22,0,0,0,21,8,8,20,0,0,19,0,0,0,10,8,6
6,6,6,10,10,10,10,10,10,0,0,0,18,0,0,10,10,10,10,10,10,6,6
6,6,6,6,6,6,6,6,10,17,0,16,0,15,0,10,6,6,6,6,6,14,6
6,6,6,6,6,6,6,6,10,13,13,0,0,13,13,10,6,6,6,6,6,6,6
6,6,0,6,6,6,6,6,10,8,8,0,0,8,8,10,6,6,6,6,0,6,6
6,0,0,0,6,6,6,6,10,12,12,0,0,12,12,10,6,6,6,0,0,0,6
0,0,5,0,0,6,6,6,10,10,10,11,11,10,10,10,6,6,0,0,5,0,0
6,0,0,0,6,6,9,6,6,8,6,0,0,6,8,6,6,7,6,0,0,0,6
6,6,0,6,6,6,6,6,6,6,6,0,0,6,6,6,6,6,6,6,0,6,6
:endlayer
layer: 11
0,0,0,0,0,0,0,0,0,0,0,0,0,0,0,0,0,0,0,0,0,0,0
0,0,0,0,0,0,0,0,0,0,0,0,0,0,0,0,0,0,0,0,0,0,0
0,0,45,0,0,0,0,0,0,0,0,0,0,0,0,0,0,0,0,0,45,0,0
0,0,0,0,0,0,0,4,0,0,0,0,0,0,0,0,4,0,0,0,0,0,0
0,0,0,0,0,0,0,0,36,36,36,8,8,36,36,36,0,0,0,0,0,0,0
0,0,0,0,0,0,0,0,36,0,54,0,0,54,0,36,0,0,0,0,0,0,0
0,0,0,0,0,0,0,0,36,0,0,0,0,0,0,36,0,0,0,0,0,0,0
0,0,0,0,0,0,0,0,36,0,0,0,0,0,0,36,0,0,0,0,0,0,0
0,0,0,0,0,0,0,0,36,0,0,0,0,0,0,36,0,0,0,0,0,0,0
0,0,0,36,36,36,36,36,36,51,51,51,51,51,0,36,36,36,36,36,36,0,0
0,0,8,36,0,0,0,0,0,0,0,0,0,0,0,0,0,0,0,0,36,8,0
0,0,0,36,53,0,0,0,0,0,0,0,0,0,0,0,0,0,0,52,36,0,0
0,0,0,49,0,0,0,51,0,0,0,0,0,0,0,0,51,0,0,0,48,0,0
0,0,0,48,0,0,0,51,0,0,0,51,51,0,0,0,51,0,0,0,49,0,0
0,0,0,36,53,0,0,0,0,0,0,51,51,0,0,0,0,0,0,52,36,0,0
0,0,8,36,0,0,0,0,0,0,0,51,51,0,0,0,0,0,0,0,36,8,0
0,0,0,36,36,36,36,36,36,0,0,0,0,0,0,36,36,36,36,36,36,0,0
0,0,0,0,0,0,0,0,36,0,0,0,0,0,0,36,0,0,0,0,0,0,0
0,0,0,0,0,0,0,0,36,0,0,0,0,0,0,36,0,0,0,0,0,0,0
0,0,0,0,0,0,0,0,36,51,51,0,0,51,51,36,0,0,0,0,0,0,0
0,0,0,0,0,0,0,0,36,0,50,0,0,50,0,36,0,0,0,0,0,0,0
0,0,45,0,0,0,0,0,36,36,36,49,48,36,36,36,0,0,0,0,45,0,0
0,0,0,0,0,0,0,4,0,8,0,0,0,0,8,0,4,0,0,0,0,0,0
0,0,0,0,0,0,0,0,0,0,0,0,0,0,0,0,0,0,0,0,0,0,0
:endlayer
layer: 12
0,0,0,0,0,0,0,0,0,0,0,0,0,0,0,0,0,0,0,0,0,0,0
0,0,0,0,0,0,0,0,0,0,0,0,0,0,0,0,0,0,0,0,0,0,0
0,0,0,0,0,0,0,0,0,0,0,0,0,0,0,0,0,0,0,0,0,0,0
0,0,0,0,0,0,0,9,0,0,0,0,0,0,0,0,7,0,0,0,0,0,0
0,0,0,0,0,0,0,9,36,36,36,36,36,36,36,36,7,0,0,0,0,0,0
0,0,0,0,0,0,0,9,36,0,0,0,0,0,0,36,7,0,0,0,0,0,0
0,0,0,0,0,0,0,9,36,0,0,0,0,0,0,36,7,0,0,0,0,0,0
0,0,0,0,0,0,0,9,36,0,0,0,0,0,0,36,7,0,0,0,0,0,0
0,0,63,63,63,63,63,9,36,0,0,0,0,0,0,36,63,63,63,63,63,63,0
0,0,8,36,36,36,36,36,36,8,8,8,8,8,8,36,36,36,36,36,36,8,0
0,55,8,36,0,0,0,0,54,0,0,0,0,0,0,54,0,0,0,0,36,8,55
0,0,8,36,0,0,0,0,0,0,0,0,0,0,0,0,0,0,0,0,36,8,0
0,0,62,36,0,0,0,0,0,0,0,0,0,0,0,0,0,0,0,0,36,61,0
0,0,60,36,0,0,0,0,0,0,0,0,0,0,0,0,0,0,0,0,36,59,0
0,0,8,36,0,0,0,0,0,0,0,0,0,0,0,0,0,0,0,0,36,8,0
0,55,8,36,0,0,0,0,50,0,0,0,0,0,0,50,0,0,0,0,36,8,55
0,0,8,36,36,36,36,36,36,53,0,0,0,0,52,36,36,36,36,36,36,8,0
0,0,58,58,58,58,58,9,36,0,0,0,0,0,0,36,7,58,58,58,58,58,0
0,0,0,0,0,0,0,9,36,0,0,0,0,0,0,36,7,0,0,0,0,0,0
0,0,0,0,0,0,0,9,36,0,0,0,0,0,0,36,7,0,0,0,0,0,0
0,0,0,0,0,0,0,9,36,0,0,0,0,0,0,36,7,0,0,0,0,0,0
0,0,0,0,0,0,0,9,36,36,36,36,36,36,36,36,7,0,0,0,0,0,0
0,0,0,0,0,0,0,9,8,8,8,57,56,8,8,8,7,0,0,0,0,0,0
0,0,0,0,0,0,0,0,0,55,0,0,0,0,55,0,0,0,0,0,0,0,0
:endlayer
layer: 13
0,0,0,0,0,0,0,0,0,0,0,0,0,0,0,0,0,0,0,0,0,0,0
0,0,0,0,0,0,0,0,0,0,0,0,0,0,0,0,0,0,0,0,0,0,0
0,0,0,0,0,0,0,0,0,0,0,0,0,0,0,0,0,0,0,0,0,0,0
0,0,0,0,0,0,0,0,4,0,0,0,0,0,0,4,0,0,0,0,0,0,0
0,0,0,0,0,0,0,0,4,4,4,4,4,4,4,4,0,0,0,0,0,0,0
0,0,0,0,0,0,0,0,4,0,0,0,0,0,0,4,0,0,0,0,0,0,0
0,0,0,0,0,0,0,0,4,0,0,0,0,0,0,4,0,0,0,0,0,0,0
0,0,0,0,0,0,0,0,4,0,0,0,0,0,0,4,0,0,0,0,0,0,0
0,0,0,0,0,0,0,0,4,0,0,0,0,0,0,4,0,0,0,0,0,0,0
0,0,4,4,4,4,4,4,4,8,8,8,8,8,8,4,4,4,4,4,4,4,0
0,64,65,4,0,0,0,0,0,0,0,0,0,0,0,0,0,0,0,0,4,65,64
0,0,65,4,0,0,0,0,0,0,0,0,0,0,0,0,0,0,0,0,4,65,0
0,0,65,4,0,0,0,0,0,0,0,0,0,0,0,0,0,0,0,0,4,65,0
0,0,65,4,0,0,0,0,0,0,0,0,0,0,0,0,0,0,0,0,4,65,0
0,0,65,4,0,0,0,0,0,0,0,0,0,0,0,0,0,0,0,0,4,65,0
0,64,65,4,0,0,0,0,0,0,0,0,0,0,0,0,0,0,0,0,4,65,64
0,0,4,4,4,4,4,4,4,0,0,0,0,0,0,4,4,4,4,4,4,4,0
0,0,0,0,0,0,0,0,4,0,0,0,0,0,0,4,0,0,0,0,0,0,0
0,0,0,0,0,0,0,0,4,0,0,0,0,0,0,4,0,0,0,0,0,0,0
0,0,0,0,0,0,0,0,4,0,0,0,0,0,0,4,0,0,0,0,0,0,0
0,0,0,0,0,0,0,0,4,0,0,0,0,0,0,4,0,0,0,0,0,0,0
0,0,0,0,0,0,0,0,4,4,4,4,4,4,4,4,0,0,0,0,0,0,0
0,0,0,0,0,0,0,0,4,65,65,65,65,65,65,4,0,0,0,0,0,0,0
0,0,0,0,0,0,0,0,0,64,0,0,0,0,64,0,0,0,0,0,0,0,0
:endlayer
layer: 14
0,0,0,0,0,0,0,0,0,0,0,0,0,0,0,0,0,0,0,0,0,0,0
0,0,0,0,0,0,0,0,0,0,0,0,0,0,0,0,0,0,0,0,0,0,0
0,0,0,0,0,0,0,0,0,0,0,0,0,0,0,0,0,0,0,0,0,0,0
0,0,0,0,0,0,0,0,9,67,0,0,0,0,66,7,0,0,0,0,0,0,0
0,0,0,0,0,0,0,0,9,36,36,36,36,36,36,7,0,0,0,0,0,0,0
0,0,0,0,0,0,0,0,9,67,0,0,0,0,66,7,0,0,0,0,0,0,0
0,0,0,0,0,0,0,0,9,67,0,0,0,0,66,7,0,0,0,0,0,0,0
0,0,0,0,0,0,0,0,9,67,0,0,0,0,66,7,0,0,0,0,0,0,0
0,0,0,0,0,0,0,0,9,67,0,0,0,0,66,7,0,0,0,0,0,0,0
0,0,63,63,63,63,63,63,9,67,0,0,0,0,66,63,63,63,63,63,63,63,0
0,0,69,36,69,69,69,69,69,67,0,0,0,0,66,69,69,69,69,69,36,69,0
0,0,0,36,0,0,0,0,0,0,0,0,0,0,0,0,0,0,0,0,36,0,0
0,0,0,36,0,0,0,0,0,0,0,0,0,0,0,0,0,0,0,0,36,0,0
0,0,0,36,0,0,0,0,0,0,0,0,0,0,0,0,0,0,0,0,36,0,0
0,0,0,36,0,0,0,0,0,0,0,0,0,0,0,0,0,0,0,0,36,0,0
0,0,68,36,68,68,68,68,68,68,0,0,0,0,68,68,68,68,68,68,36,68,0
0,0,58,58,58,58,58,58,58,67,0,0,0,0,66,58,58,58,58,58,58,58,0
0,0,0,0,0,0,0,0,9,67,0,0,0,0,66,7,0,0,0,0,0,0,0
0,0,0,0,0,0,0,0,9,67,0,0,0,0,66,7,0,0,0,0,0,0,0
0,0,0,0,0,0,0,0,9,67,0,0,0,0,66,7,0,0,0,0,0,0,0
0,0,0,0,0,0,0,0,9,67,0,0,0,0,66,7,0,0,0,0,0,0,0
0,0,0,0,0,0,0,0,9,36,36,36,36,36,36,7,0,0,0,0,0,0,0
0,0,0,0,0,0,0,0,9,67,0,0,0,0,66,7,0,0,0,0,0,0,0
0,0,0,0,0,0,0,0,0,0,0,0,0,0,0,0,0,0,0,0,0,0,0
:endlayer
layer: 15
0,0,0,0,0,0,0,0,0,0,0,0,0,0,0,0,0,0,0,0,0,0,0
0,0,0,0,0,0,0,0,0,0,0,0,0,0,0,0,0,0,0,0,0,0,0
0,0,0,0,0,0,0,0,0,0,0,0,0,0,0,0,0,0,0,0,0,0,0
0,0,0,0,0,0,0,0,0,9,67,0,0,66,7,0,0,0,0,0,0,0,0
0,0,0,0,0,0,0,0,0,9,36,36,36,36,7,0,0,0,0,0,0,0,0
0,0,0,0,0,0,0,0,0,9,67,0,0,66,7,0,0,0,0,0,0,0,0
0,0,0,0,0,0,0,0,0,9,67,0,0,66,7,0,0,0,0,0,0,0,0
0,0,0,0,0,0,0,0,0,9,67,0,0,66,7,0,0,0,0,0,0,0,0
0,0,0,0,0,0,0,0,0,9,67,0,0,66,7,0,0,0,0,0,0,0,0
0,0,0,0,0,0,0,0,0,9,67,0,0,66,7,0,0,0,0,0,0,0,0
0,0,63,63,63,63,63,63,63,63,67,0,0,66,63,63,63,63,63,63,63,63,0
0,0,69,36,69,69,69,69,69,69,69,0,0,69,69,69,69,69,69,69,36,69,0
0,0,0,36,0,0,0,0,0,0,0,0,0,0,0,0,0,0,0,0,36,0,0
0,0,0,36,0,0,0,0,0,0,0,0,0,0,0,0,0,0,0,0,36,0,0
0,0,68,36,68,68,68,68,68,68,67,0,0,66,68,68,68,68,68,68,36,68,0
0,0,58,58,58,58,58,58,58,58,67,0,0,66,7,58,58,58,58,58,58,58,0
0,0,0,0,0,0,0,0,0,9,67,0,0,66,7,0,0,0,0,0,0,0,0
0,0,0,0,0,0,0,0,0,9,67,0,0,66,7,0,0,0,0,0,0,0,0
0,0,0,0,0,0,0,0,0,9,67,0,0,66,7,0,0,0,0,0,0,0,0
0,0,0,0,0,0,0,0,0,9,67,0,0,66,7,0,0,0,0,0,0,0,0
0,0,0,0,0,0,0,0,0,9,67,0,0,66,7,0,0,0,0,0,0,0,0
0,0,0,0,0,0,0,0,0,9,36,36,36,36,7,0,0,0,0,0,0,0,0
0,0,0,0,0,0,0,0,0,9,67,0,0,66,7,0,0,0,0,0,0,0,0
0,0,0,0,0,0,0,0,0,0,0,0,0,0,0,0,0,0,0,0,0,0,0
:endlayer
layer: 16
0,0,0,0,0,0,0,0,0,0,0,0,0,0,0,0,0,0,0,0,0,0,0
0,0,0,0,0,0,0,0,0,0,0,0,0,0,0,0,0,0,0,0,0,0,0
0,0,0,0,0,0,0,0,0,0,0,0,0,0,0,0,0,0,0,0,0,0,0
0,0,0,0,0,0,0,0,0,0,9,67,66,7,0,0,0,0,0,0,0,0,0
0,0,0,0,0,0,0,0,0,0,9,36,36,7,0,0,0,0,0,0,0,0,0
0,0,0,0,0,0,0,0,0,0,9,67,66,7,0,0,0,0,0,0,0,0,0
0,0,0,0,0,0,0,0,0,0,9,67,66,7,0,0,0,0,0,0,0,0,0
0,0,0,0,0,0,0,0,0,0,9,67,66,7,0,0,0,0,0,0,0,0,0
0,0,0,0,0,0,0,0,0,0,9,67,66,7,0,0,0,0,0,0,0,0,0
0,0,0,0,0,0,0,0,0,0,9,67,66,7,0,0,0,0,0,0,0,0,0
0,0,0,0,0,0,0,0,0,0,9,67,66,7,0,0,0,0,0,0,0,0,0
0,0,63,63,63,63,63,63,63,63,63,67,66,7,63,63,63,63,63,63,63,63,0
0,0,69,36,69,69,69,69,69,69,69,4,4,69,69,69,69,69,69,69,36,69,0
0,0,68,36,68,68,68,68,68,68,68,4,4,68,68,68,68,68,68,68,36,68,0
0,0,58,58,58,58,58,58,58,58,9,67,66,7,58,58,58,58,58,58,58,58,0
0,0,0,0,0,0,0,0,0,0,9,67,66,7,0,0,0,0,0,0,0,0,0
0,0,0,0,0,0,0,0,0,0,9,67,66,7,0,0,0,0,0,0,0,0,0
0,0,0,0,0,0,0,0,0,0,9,67,66,7,0,0,0,0,0,0,0,0,0
0,0,0,0,0,0,0,0,0,0,9,67,66,7,0,0,0,0,0,0,0,0,0
0,0,0,0,0,0,0,0,0,0,9,67,66,7,0,0,0,0,0,0,0,0,0
0,0,0,0,0,0,0,0,0,0,9,67,66,7,0,0,0,0,0,0,0,0,0
0,0,0,0,0,0,0,0,0,0,9,36,36,7,0,0,0,0,0,0,0,0,0
0,0,0,0,0,0,0,0,0,0,9,67,66,7,0,0,0,0,0,0,0,0,0
0,0,0,0,0,0,0,0,0,0,0,0,0,0,0,0,0,0,0,0,0,0,0
:endlayer
layer: 17
0,0,0,0,0,0,0,0,0,0,0,0,0,0,0,0,0,0,0,0,0,0,0
0,0,0,0,0,0,0,0,0,0,0,0,0,0,0,0,0,0,0,0,0,0,0
0,0,0,0,0,0,0,0,0,0,0,63,63,0,0,0,0,0,0,0,0,0,0
0,0,0,0,0,0,0,0,0,0,0,4,4,0,0,0,0,0,0,0,0,0,0
0,0,0,0,0,0,0,0,0,0,0,9,7,0,0,0,0,0,0,0,0,0,0
0,0,0,0,0,0,0,0,0,0,0,9,7,0,0,0,0,0,0,0,0,0,0
0,0,0,0,0,0,0,0,0,0,0,9,7,0,0,0,0,0,0,0,0,0,0
0,0,0,0,0,0,0,0,0,0,0,9,7,0,0,0,0,0,0,0,0,0,0
0,0,0,0,0,0,0,0,0,0,0,9,7,0,0,0,0,0,0,0,0,0,0
0,0,0,0,0,0,0,0,0,0,0,9,7,0,0,0,0,0,0,0,0,0,0
0,0,0,0,0,0,0,0,0,0,0,9,7,0,0,0,0,0,0,0,0,0,0
0,0,0,0,0,0,0,0,0,0,0,9,7,0,0,0,0,0,0,0,0,0,0
0,9,63,4,63,63,63,63,63,63,63,4,4,63,63,63,63,63,63,63,63,4,7
0,9,58,4,58,58,58,58,58,58,58,4,4,58,58,58,58,58,58,58,58,4,7
0,0,0,0,0,0,0,0,0,0,0,9,7,0,0,0,0,0,0,0,0,0,0
0,0,0,0,0,0,0,0,0,0,0,9,7,0,0,0,0,0,0,0,0,0,0
0,0,0,0,0,0,0,0,0,0,0,9,7,0,0,0,0,0,0,0,0,0,0
0,0,0,0,0,0,0,0,0,0,0,9,7,0,0,0,0,0,0,0,0,0,0
0,0,0,0,0,0,0,0,0,0,0,9,7,0,0,0,0,0,0,0,0,0,0
0,0,0,0,0,0,0,0,0,0,0,9,7,0,0,0,0,0,0,0,0,0,0
0,0,0,0,0,0,0,0,0,0,0,9,7,0,0,0,0,0,0,0,0,0,0
0,0,0,0,0,0,0,0,0,0,0,9,7,0,0,0,0,0,0,0,0,0,0
0,0,0,0,0,0,0,0,0,0,0,4,4,0,0,0,0,0,0,0,0,0,0
0,0,0,0,0,0,0,0,0,0,0,58,58,0,0,0,0,0,0,0,0,0,0
:endlayer
layer: 18
0,0,0,0,0,0,0,0,0,0,0,0,0,0,0,0,0,0,0,0,0,0,0
0,0,0,0,0,0,0,0,0,0,0,0,0,0,0,0,0,0,0,0,0,0,0
0,0,0,0,0,0,0,0,0,0,0,0,0,0,0,0,0,0,0,0,0,0,0
0,0,0,0,0,0,0,0,0,0,0,64,64,0,0,0,0,0,0,0,0,0,0
0,0,0,0,0,0,0,0,0,0,0,0,0,0,0,0,0,0,0,0,0,0,0
0,0,0,0,0,0,0,0,0,0,0,0,0,0,0,0,0,0,0,0,0,0,0
0,0,0,0,0,0,0,0,0,0,0,0,0,0,0,0,0,0,0,0,0,0,0
0,0,0,0,0,0,0,0,0,0,0,0,0,0,0,0,0,0,0,0,0,0,0
0,0,0,0,0,0,0,0,0,0,0,0,0,0,0,0,0,0,0,0,0,0,0
0,0,0,0,0,0,0,0,0,0,0,0,0,0,0,0,0,0,0,0,0,0,0
0,0,0,0,0,0,0,0,0,0,0,0,0,0,0,0,0,0,0,0,0,0,0
0,0,0,0,0,0,0,0,0,0,0,0,0,0,0,0,0,0,0,0,0,0,0
0,0,0,64,0,0,0,0,0,0,0,64,64,0,0,0,0,0,0,0,0,64,0
0,0,0,64,0,0,0,0,0,0,0,64,64,0,0,0,0,0,0,0,0,64,0
0,0,0,0,0,0,0,0,0,0,0,0,0,0,0,0,0,0,0,0,0,0,0
0,0,0,0,0,0,0,0,0,0,0,0,0,0,0,0,0,0,0,0,0,0,0
0,0,0,0,0,0,0,0,0,0,0,0,0,0,0,0,0,0,0,0,0,0,0
0,0,0,0,0,0,0,0,0,0,0,0,0,0,0,0,0,0,0,0,0,0,0
0,0,0,0,0,0,0,0,0,0,0,0,0,0,0,0,0,0,0,0,0,0,0
0,0,0,0,0,0,0,0,0,0,0,0,0,0,0,0,0,0,0,0,0,0,0
0,0,0,0,0,0,0,0,0,0,0,0,0,0,0,0,0,0,0,0,0,0,0
0,0,0,0,0,0,0,0,0,0,0,0,0,0,0,0,0,0,0,0,0,0,0
0,0,0,0,0,0,0,0,0,0,0,64,64,0,0,0,0,0,0,0,0,0,0
0,0,0,0,0,0,0,0,0,0,0,0,0,0,0,0,0,0,0,0,0,0,0
:endlayer

#### RULES ####
rule:
plugin=vanillaBlocks
number=1
data:
JSON:{blockState:{blockName:"minecraft:dirt",properties:{variant:"dirt",snowy:"false"}}}
:enddata
:endrule

rule:
plugin=vanillaBlocks
number=2
data:
JSON:{blockState:{blockName:"minecraft:grass",properties:{snowy:"false"}}}
:enddata
:endrule

rule:
plugin=vanillaBlocks
number=3
data:
JSON:{blockState:{blockName:"minecraft:stone",properties:{variant:"stone"}}}
:enddata
:endrule

rule:
plugin=vanillaBlocks
number=4
data:
JSON:{blockState:{blockName:"minecraft:planks",properties:{variant:"spruce"}}}
:enddata
:endrule

rule:
plugin=vanillaBlocks
number=5
data:
JSON:{blockState:{blockName:"minecraft:cobblestone"}}
:enddata
:endrule

rule:
plugin=vanillaBlocks
number=6
data:
JSON:{blockState:{blockName:"minecraft:snow_layer",properties:{layers:"1"}}}
:enddata
:endrule

rule:
plugin=vanillaBlocks
number=7
data:
JSON:{blockState:{blockName:"minecraft:spruce_stairs",properties:{half:"bottom",shape:"straight",facing:"west"}}}
:enddata
:endrule

rule:
plugin=vanillaBlocks
number=8
data:
JSON:{blockState:{blockName:"minecraft:spruce_fence",properties:{east:"false",south:"false",north:"false",west:"false"}}}
:enddata
:endrule

rule:
plugin=vanillaBlocks
number=9
data:
JSON:{blockState:{blockName:"minecraft:spruce_stairs",properties:{half:"bottom",shape:"straight",facing:"east"}}}
:enddata
:endrule

rule:
plugin=vanillaBlocks
number=10
data:
JSON:{blockState:{blockName:"minecraft:stonebrick",properties:{variant:"stonebrick"}}}
:enddata
:endrule

rule:
plugin=doors
number=11
data:
JSON:{blockState:{blockName:"minecraft:spruce_door",properties:{hinge:"left",half:"lower",powered:"false",facing:"south",open:"false"}}}
:enddata
:endrule

rule:
plugin=vanillaBlocks
number=12
data:
JSON:{blockState:{blockName:"minecraft:oak_stairs",properties:{half:"bottom",shape:"straight",facing:"south"}}}
:enddata
:endrule

rule:
plugin=vanillaBlocks
number=13
data:
JSON:{blockState:{blockName:"minecraft:oak_stairs",properties:{half:"bottom",shape:"straight",facing:"north"}}}
:enddata
:endrule

rule:
plugin=vanillaBlocks
number=14
data:
JSON:{blockState:{blockName:"minecraft:snow_layer",properties:{layers:"2"}}}
:enddata
:endrule

rule:
plugin=blockTile
number=15
data:
JSON:{blockState:{blockName:"ancientwarfarestructure:advanced_spawner",properties:{transparent:"true"}},teData:{id:"ancientwarfarestructure:advanced_spawner_tile",spawnerSettings:{minDelay:0,spawnDelay:0,lightSensitive:0b,spawnGroups:[{settingsList:[{remainingSpawnCount:1,hostile:1b,forced:1b,customTag:{ArmorDropChances:[1.0f,1.0f,1.0f,1.0f],ArmorItems:[{},{},{},{}],HandDropChances:[1.0f,1.0f],factionName:"norska",HandItems:[{},{}]},maxToSpawn:1,entityId:"ancientwarfarenpc:faction.civilian.female",minToSpawn:1}],groupWeight:1}],playerRange:6,respondToRedstone:0b,inventory:{Size:9,Items:[]},spawnRange:0,transparent:1b,maxDelay:0,xpToDrop:0,mobRange:0,debugMode:0b,maxNearbyMonsters:0}}}
:enddata
:endrule

rule:
plugin=blockTile
number=16
data:
JSON:{blockState:{blockName:"ancientwarfarestructure:advanced_spawner",properties:{transparent:"true"}},teData:{id:"ancientwarfarestructure:advanced_spawner_tile",spawnerSettings:{minDelay:0,spawnDelay:0,lightSensitive:0b,spawnGroups:[{settingsList:[{remainingSpawnCount:1,hostile:1b,forced:1b,customTag:{ArmorDropChances:[1.0f,1.0f,1.0f,1.0f],ArmorItems:[{},{},{},{}],HandDropChances:[1.0f,1.0f],factionName:"norska",HandItems:[{id:"minecraft:bow",Count:1b,Damage:0s},{}]},maxToSpawn:1,entityId:"ancientwarfarenpc:faction.archer",minToSpawn:1}],groupWeight:1}],playerRange:6,respondToRedstone:0b,inventory:{Size:9,Items:[]},spawnRange:0,transparent:1b,maxDelay:0,xpToDrop:0,mobRange:0,debugMode:0b,maxNearbyMonsters:0}}}
:enddata
:endrule

rule:
plugin=blockTile
number=17
data:
JSON:{blockState:{blockName:"ancientwarfarestructure:advanced_spawner",properties:{transparent:"true"}},teData:{id:"ancientwarfarestructure:advanced_spawner_tile",spawnerSettings:{minDelay:0,spawnDelay:0,lightSensitive:0b,spawnGroups:[{settingsList:[{remainingSpawnCount:1,hostile:1b,forced:1b,customTag:{ArmorDropChances:[1.0f,1.0f,1.0f,1.0f],ArmorItems:[{},{},{},{}],HandDropChances:[1.0f,1.0f],factionName:"norska",HandItems:[{id:"minecraft:iron_sword",Count:1b,Damage:0s},{}]},maxToSpawn:1,entityId:"ancientwarfarenpc:faction.soldier",minToSpawn:1}],groupWeight:1}],playerRange:6,respondToRedstone:0b,inventory:{Size:9,Items:[]},spawnRange:0,transparent:1b,maxDelay:0,xpToDrop:0,mobRange:0,debugMode:0b,maxNearbyMonsters:0}}}
:enddata
:endrule

rule:
plugin=blockTile
number=18
data:
JSON:{blockState:{blockName:"ancientwarfarestructure:advanced_spawner",properties:{transparent:"true"}},teData:{id:"ancientwarfarestructure:advanced_spawner_tile",spawnerSettings:{minDelay:0,spawnDelay:0,lightSensitive:0b,spawnGroups:[{settingsList:[{remainingSpawnCount:1,hostile:1b,forced:1b,customTag:{ArmorDropChances:[1.0f,1.0f,1.0f,1.0f],ArmorItems:[{},{},{},{}],HandDropChances:[1.0f,1.0f],factionName:"norska",HandItems:[{id:"minecraft:iron_axe",Count:1b,Damage:0s},{id:"minecraft:iron_axe",Count:1b,Damage:0s}]},maxToSpawn:1,entityId:"ancientwarfarenpc:faction.soldier.elite",minToSpawn:1}],groupWeight:1}],playerRange:6,respondToRedstone:0b,inventory:{Size:9,Items:[]},spawnRange:0,transparent:1b,maxDelay:0,xpToDrop:0,mobRange:0,debugMode:0b,maxNearbyMonsters:0}}}
:enddata
:endrule

rule:
plugin=blockTile
number=19
data:
JSON:{blockState:{blockName:"ancientwarfarestructure:advanced_spawner",properties:{transparent:"true"}},teData:{id:"ancientwarfarestructure:advanced_spawner_tile",spawnerSettings:{minDelay:0,spawnDelay:0,lightSensitive:0b,spawnGroups:[{settingsList:[{remainingSpawnCount:1,hostile:1b,forced:1b,customTag:{ArmorDropChances:[1.0f,1.0f,1.0f,1.0f],ArmorItems:[{},{},{},{}],HandDropChances:[1.0f,1.0f],factionName:"norska",HandItems:[{id:"minecraft:iron_sword",Count:1b,Damage:0s},{}]},maxToSpawn:1,entityId:"ancientwarfarenpc:faction.soldier",minToSpawn:1}],groupWeight:1}],playerRange:6,respondToRedstone:0b,inventory:{Size:9,Items:[]},spawnRange:0,transparent:1b,maxDelay:0,xpToDrop:0,mobRange:0,debugMode:0b,maxNearbyMonsters:0}}}
:enddata
:endrule

rule:
plugin=vanillaBlocks
number=20
data:
JSON:{blockState:{blockName:"minecraft:oak_stairs",properties:{half:"bottom",shape:"straight",facing:"east"}}}
:enddata
:endrule

rule:
plugin=vanillaBlocks
number=21
data:
JSON:{blockState:{blockName:"minecraft:oak_stairs",properties:{half:"bottom",shape:"straight",facing:"west"}}}
:enddata
:endrule

rule:
plugin=blockTile
number=22
data:
JSON:{blockState:{blockName:"ancientwarfarestructure:advanced_spawner",properties:{transparent:"true"}},teData:{id:"ancientwarfarestructure:advanced_spawner_tile",spawnerSettings:{minDelay:0,spawnDelay:0,lightSensitive:0b,spawnGroups:[{settingsList:[{remainingSpawnCount:1,hostile:1b,forced:1b,customTag:{ArmorDropChances:[1.0f,1.0f,1.0f,1.0f],ArmorItems:[{},{},{},{}],HandDropChances:[1.0f,1.0f],factionName:"norska",HandItems:[{id:"minecraft:iron_sword",Count:1b,Damage:0s},{}]},maxToSpawn:1,entityId:"ancientwarfarenpc:faction.soldier",minToSpawn:1}],groupWeight:1}],playerRange:6,respondToRedstone:0b,inventory:{Size:9,Items:[]},spawnRange:0,transparent:1b,maxDelay:0,xpToDrop:0,mobRange:0,debugMode:0b,maxNearbyMonsters:0}}}
:enddata
:endrule

rule:
plugin=blockTile
number=23
data:
JSON:{blockState:{blockName:"ancientwarfarestructure:advanced_spawner",properties:{transparent:"true"}},teData:{id:"ancientwarfarestructure:advanced_spawner_tile",spawnerSettings:{minDelay:0,spawnDelay:0,lightSensitive:0b,spawnGroups:[{settingsList:[{remainingSpawnCount:1,hostile:1b,forced:1b,customTag:{ArmorDropChances:[1.0f,1.0f,1.0f,1.0f],ArmorItems:[{},{},{},{}],HandDropChances:[1.0f,1.0f],factionName:"norska",HandItems:[{},{}]},maxToSpawn:1,entityId:"ancientwarfarenpc:faction.civilian.female",minToSpawn:1}],groupWeight:1}],playerRange:6,respondToRedstone:0b,inventory:{Size:9,Items:[]},spawnRange:0,transparent:1b,maxDelay:0,xpToDrop:0,mobRange:0,debugMode:0b,maxNearbyMonsters:0}}}
:enddata
:endrule

rule:
plugin=doors
number=24
data:
JSON:{blockState:{blockName:"minecraft:spruce_door",properties:{hinge:"left",half:"lower",powered:"false",facing:"east",open:"false"}}}
:enddata
:endrule

rule:
plugin=doors
number=25
data:
JSON:{blockState:{blockName:"minecraft:spruce_door",properties:{hinge:"left",half:"lower",powered:"false",facing:"west",open:"false"}}}
:enddata
:endrule

rule:
plugin=blockTile
number=26
data:
JSON:{blockState:{blockName:"ancientwarfarestructure:advanced_spawner",properties:{transparent:"true"}},teData:{id:"ancientwarfarestructure:advanced_spawner_tile",spawnerSettings:{minDelay:0,spawnDelay:0,lightSensitive:0b,spawnGroups:[{settingsList:[{remainingSpawnCount:1,hostile:1b,forced:1b,customTag:{ArmorDropChances:[1.0f,1.0f,1.0f,1.0f],ArmorItems:[{},{},{},{}],HandDropChances:[1.0f,1.0f],factionName:"norska",HandItems:[{id:"minecraft:bow",Count:1b,Damage:0s},{}]},maxToSpawn:1,entityId:"ancientwarfarenpc:faction.archer",minToSpawn:1}],groupWeight:1}],playerRange:6,respondToRedstone:0b,inventory:{Size:9,Items:[]},spawnRange:0,transparent:1b,maxDelay:0,xpToDrop:0,mobRange:0,debugMode:0b,maxNearbyMonsters:0}}}
:enddata
:endrule

rule:
plugin=blockTile
number=27
data:
JSON:{blockState:{blockName:"ancientwarfarestructure:advanced_spawner",properties:{transparent:"true"}},teData:{id:"ancientwarfarestructure:advanced_spawner_tile",spawnerSettings:{minDelay:0,spawnDelay:0,lightSensitive:0b,spawnGroups:[{settingsList:[{remainingSpawnCount:1,hostile:1b,forced:1b,customTag:{ArmorDropChances:[1.0f,1.0f,1.0f,1.0f],ArmorItems:[{},{},{},{}],HandDropChances:[1.0f,1.0f],factionName:"norska",HandItems:[{id:"minecraft:diamond_axe",Count:1b,Damage:0s},{}]},maxToSpawn:1,entityId:"ancientwarfarenpc:faction.leader",minToSpawn:1}],groupWeight:1}],playerRange:6,respondToRedstone:0b,inventory:{Size:9,Items:[]},spawnRange:0,transparent:1b,maxDelay:0,xpToDrop:0,mobRange:0,debugMode:0b,maxNearbyMonsters:0}}}
:enddata
:endrule

rule:
plugin=blockTile
number=28
data:
JSON:{blockState:{blockName:"ancientwarfarestructure:advanced_spawner",properties:{transparent:"true"}},teData:{id:"ancientwarfarestructure:advanced_spawner_tile",spawnerSettings:{minDelay:0,spawnDelay:0,lightSensitive:0b,spawnGroups:[{settingsList:[{remainingSpawnCount:1,hostile:1b,forced:1b,customTag:{factionName:"norska"},maxToSpawn:1,entityId:"ancientwarfarenpc:faction.priest",minToSpawn:1}],groupWeight:1}],playerRange:8,respondToRedstone:0b,inventory:{Size:9,Items:[]},spawnRange:0,transparent:1b,maxDelay:0,xpToDrop:0,mobRange:0,debugMode:0b,maxNearbyMonsters:0}}}
:enddata
:endrule

rule:
plugin=blockTile
number=29
data:
JSON:{blockState:{blockName:"ancientwarfarestructure:advanced_spawner",properties:{transparent:"true"}},teData:{id:"ancientwarfarestructure:advanced_spawner_tile",spawnerSettings:{minDelay:0,spawnDelay:0,lightSensitive:0b,spawnGroups:[{settingsList:[{remainingSpawnCount:1,hostile:1b,forced:1b,customTag:{ArmorDropChances:[1.0f,1.0f,1.0f,1.0f],ArmorItems:[{},{},{},{}],HandDropChances:[1.0f,1.0f],factionName:"norska",HandItems:[{id:"minecraft:bow",Count:1b,Damage:0s},{}]},maxToSpawn:1,entityId:"ancientwarfarenpc:faction.archer",minToSpawn:1}],groupWeight:1}],playerRange:6,respondToRedstone:0b,inventory:{Size:9,Items:[]},spawnRange:0,transparent:1b,maxDelay:0,xpToDrop:0,mobRange:0,debugMode:0b,maxNearbyMonsters:0}}}
:enddata
:endrule

rule:
plugin=blockTile
number=30
data:
JSON:{blockState:{blockName:"ancientwarfarestructure:advanced_spawner",properties:{transparent:"true"}},teData:{id:"ancientwarfarestructure:advanced_spawner_tile",spawnerSettings:{minDelay:0,spawnDelay:0,lightSensitive:0b,spawnGroups:[{settingsList:[{remainingSpawnCount:1,hostile:1b,forced:1b,customTag:{ArmorDropChances:[1.0f,1.0f,1.0f,1.0f],ArmorItems:[{},{},{},{}],HandDropChances:[1.0f,1.0f],factionName:"norska",HandItems:[{id:"minecraft:iron_sword",Count:1b,Damage:0s},{}]},maxToSpawn:1,entityId:"ancientwarfarenpc:faction.soldier",minToSpawn:1}],groupWeight:1}],playerRange:6,respondToRedstone:0b,inventory:{Size:9,Items:[]},spawnRange:0,transparent:1b,maxDelay:0,xpToDrop:0,mobRange:0,debugMode:0b,maxNearbyMonsters:0}}}
:enddata
:endrule

rule:
plugin=blockTile
number=31
data:
JSON:{blockState:{blockName:"ancientwarfarestructure:advanced_spawner",properties:{transparent:"true"}},teData:{id:"ancientwarfarestructure:advanced_spawner_tile",spawnerSettings:{minDelay:0,spawnDelay:0,lightSensitive:0b,spawnGroups:[{settingsList:[{remainingSpawnCount:1,hostile:1b,forced:1b,customTag:{ArmorDropChances:[1.0f,1.0f,1.0f,1.0f],ArmorItems:[{},{},{},{}],HandDropChances:[1.0f,1.0f],factionName:"norska",HandItems:[{id:"minecraft:iron_axe",Count:1b,Damage:0s},{id:"minecraft:iron_axe",Count:1b,Damage:0s}]},maxToSpawn:1,entityId:"ancientwarfarenpc:faction.soldier.elite",minToSpawn:1}],groupWeight:1}],playerRange:6,respondToRedstone:0b,inventory:{Size:9,Items:[]},spawnRange:0,transparent:1b,maxDelay:0,xpToDrop:0,mobRange:0,debugMode:0b,maxNearbyMonsters:0}}}
:enddata
:endrule

rule:
plugin=blockTile
number=32
data:
JSON:{blockState:{blockName:"ancientwarfarestructure:advanced_spawner",properties:{transparent:"true"}},teData:{id:"ancientwarfarestructure:advanced_spawner_tile",spawnerSettings:{minDelay:0,spawnDelay:0,lightSensitive:0b,spawnGroups:[{settingsList:[{remainingSpawnCount:1,hostile:1b,forced:1b,customTag:{ArmorDropChances:[1.0f,1.0f,1.0f,1.0f],ArmorItems:[{},{},{},{}],HandDropChances:[1.0f,1.0f],factionName:"norska",HandItems:[{id:"minecraft:iron_sword",Count:1b,Damage:0s},{}]},maxToSpawn:1,entityId:"ancientwarfarenpc:faction.soldier",minToSpawn:1}],groupWeight:1}],playerRange:6,respondToRedstone:0b,inventory:{Size:9,Items:[]},spawnRange:0,transparent:1b,maxDelay:0,xpToDrop:0,mobRange:0,debugMode:0b,maxNearbyMonsters:0}}}
:enddata
:endrule

rule:
plugin=blockTile
number=33
data:
JSON:{blockState:{blockName:"ancientwarfarestructure:advanced_spawner",properties:{transparent:"true"}},teData:{id:"ancientwarfarestructure:advanced_spawner_tile",spawnerSettings:{minDelay:0,spawnDelay:0,lightSensitive:0b,spawnGroups:[{settingsList:[{remainingSpawnCount:1,hostile:1b,forced:1b,customTag:{ArmorDropChances:[1.0f,1.0f,1.0f,1.0f],ArmorItems:[{},{},{},{}],HandDropChances:[1.0f,1.0f],factionName:"norska",HandItems:[{id:"minecraft:iron_axe",Count:1b,Damage:0s},{id:"minecraft:iron_axe",Count:1b,Damage:0s}]},maxToSpawn:1,entityId:"ancientwarfarenpc:faction.soldier.elite",minToSpawn:1}],groupWeight:1}],playerRange:6,respondToRedstone:0b,inventory:{Size:9,Items:[]},spawnRange:0,transparent:1b,maxDelay:0,xpToDrop:0,mobRange:0,debugMode:0b,maxNearbyMonsters:0}}}
:enddata
:endrule

rule:
plugin=blockTile
number=34
data:
JSON:{blockState:{blockName:"ancientwarfarestructure:advanced_spawner",properties:{transparent:"true"}},teData:{id:"ancientwarfarestructure:advanced_spawner_tile",spawnerSettings:{minDelay:0,spawnDelay:0,lightSensitive:0b,spawnGroups:[{settingsList:[{remainingSpawnCount:1,hostile:1b,forced:1b,customTag:{ArmorDropChances:[1.0f,1.0f,1.0f,1.0f],ArmorItems:[{},{},{},{}],HandDropChances:[1.0f,1.0f],factionName:"norska",HandItems:[{id:"minecraft:iron_sword",Count:1b,Damage:0s},{}]},maxToSpawn:1,entityId:"ancientwarfarenpc:faction.soldier",minToSpawn:1}],groupWeight:1}],playerRange:6,respondToRedstone:0b,inventory:{Size:9,Items:[]},spawnRange:0,transparent:1b,maxDelay:0,xpToDrop:0,mobRange:0,debugMode:0b,maxNearbyMonsters:0}}}
:enddata
:endrule

rule:
plugin=vanillaBlocks
number=35
data:
JSON:{blockState:{blockName:"minecraft:trapdoor",properties:{half:"top",facing:"west",open:"false"}}}
:enddata
:endrule

rule:
plugin=vanillaBlocks
number=36
data:
JSON:{blockState:{blockName:"minecraft:planks",properties:{variant:"dark_oak"}}}
:enddata
:endrule

rule:
plugin=blockTile
number=37
data:
JSON:{blockState:{blockName:"ancientwarfarestructure:advanced_spawner",properties:{transparent:"true"}},teData:{id:"ancientwarfarestructure:advanced_spawner_tile",spawnerSettings:{minDelay:0,spawnDelay:0,lightSensitive:0b,spawnGroups:[{settingsList:[{remainingSpawnCount:1,hostile:1b,forced:1b,customTag:{ArmorDropChances:[1.0f,1.0f,1.0f,1.0f],ArmorItems:[{},{},{},{}],HandDropChances:[1.0f,1.0f],factionName:"norska",HandItems:[{},{}]},maxToSpawn:1,entityId:"ancientwarfarenpc:faction.civilian.female",minToSpawn:1}],groupWeight:1}],playerRange:8,respondToRedstone:0b,inventory:{Size:9,Items:[]},spawnRange:0,transparent:1b,maxDelay:0,xpToDrop:0,mobRange:0,debugMode:0b,maxNearbyMonsters:0}}}
:enddata
:endrule

rule:
plugin=blockTile
number=38
data:
JSON:{blockState:{blockName:"ancientwarfarestructure:advanced_spawner",properties:{transparent:"true"}},teData:{id:"ancientwarfarestructure:advanced_spawner_tile",spawnerSettings:{minDelay:0,spawnDelay:0,lightSensitive:0b,spawnGroups:[{settingsList:[{remainingSpawnCount:1,hostile:1b,forced:1b,customTag:{ArmorDropChances:[1.0f,1.0f,1.0f,1.0f],ArmorItems:[{},{},{},{}],HandDropChances:[1.0f,1.0f],factionName:"norska",HandItems:[{},{}]},maxToSpawn:1,entityId:"ancientwarfarenpc:faction.civilian.female",minToSpawn:1}],groupWeight:1}],playerRange:8,respondToRedstone:0b,inventory:{Size:9,Items:[]},spawnRange:0,transparent:1b,maxDelay:0,xpToDrop:0,mobRange:0,debugMode:0b,maxNearbyMonsters:0}}}
:enddata
:endrule

rule:
plugin=inventory
number=39
data:
JSON:{blockState:{blockName:"minecraft:chest",properties:{facing:"west"}},lootLevel:0,teData:{ForgeData:{},Items:[{Slot:6b,id:"minecraft:bread",Count:2b,Damage:0s},{Slot:7b,id:"minecraft:bread",Count:1b,Damage:0s},{Slot:11b,id:"minecraft:porkchop",Count:2b,Damage:0s},{Slot:12b,id:"minecraft:porkchop",Count:2b,Damage:0s},{Slot:13b,id:"minecraft:porkchop",Count:2b,Damage:0s},{Slot:15b,id:"minecraft:bread",Count:1b,Damage:0s},{Slot:16b,id:"minecraft:bread",Count:1b,Damage:0s},{Slot:19b,id:"minecraft:porkchop",Count:1b,Damage:0s},{Slot:22b,id:"minecraft:porkchop",Count:1b,Damage:0s},{Slot:24b,id:"minecraft:bread",Count:1b,Damage:0s},{Slot:26b,id:"minecraft:bread",Count:1b,Damage:0s}],id:"minecraft:chest",Lock:""},inventoryData:{length:11,inventoryContents:[{id:"minecraft:bread",Count:2b,slot:0,Damage:0s},{id:"minecraft:bread",Count:1b,slot:1,Damage:0s},{id:"minecraft:porkchop",Count:2b,slot:2,Damage:0s},{id:"minecraft:porkchop",Count:2b,slot:3,Damage:0s},{id:"minecraft:porkchop",Count:2b,slot:4,Damage:0s},{id:"minecraft:bread",Count:1b,slot:5,Damage:0s},{id:"minecraft:bread",Count:1b,slot:6,Damage:0s},{id:"minecraft:porkchop",Count:1b,slot:7,Damage:0s},{id:"minecraft:porkchop",Count:1b,slot:8,Damage:0s},{id:"minecraft:bread",Count:1b,slot:9,Damage:0s},{id:"minecraft:bread",Count:1b,slot:10,Damage:0s}]},legacyFeatures:1b}
:enddata
:endrule

rule:
plugin=vanillaBlocks
number=40
data:
JSON:{blockState:{blockName:"minecraft:crafting_table"}}
:enddata
:endrule

rule:
plugin=inventory
number=41
data:
JSON:{blockState:{blockName:"minecraft:chest",properties:{facing:"east"}},lootLevel:0,teData:{ForgeData:{},Items:[{Slot:12b,id:"ancientwarfarenpc:coin",Count:2b,tag:{metal:"copper"},Damage:0s},{Slot:13b,id:"ancientwarfarenpc:coin",Count:2b,tag:{metal:"copper"},Damage:0s},{Slot:14b,id:"ancientwarfarenpc:coin",Count:2b,tag:{metal:"copper"},Damage:0s},{Slot:15b,id:"ancientwarfarenpc:coin",Count:2b,tag:{metal:"copper"},Damage:0s},{Slot:21b,id:"ancientwarfarenpc:coin",Count:1b,tag:{metal:"copper"},Damage:0s},{Slot:22b,id:"ancientwarfarenpc:coin",Count:3b,tag:{metal:"copper"},Damage:0s},{Slot:23b,id:"ancientwarfarenpc:coin",Count:1b,tag:{metal:"copper"},Damage:0s},{Slot:24b,id:"ancientwarfarenpc:coin",Count:5b,tag:{metal:"copper"},Damage:0s}],id:"minecraft:chest",Lock:""},inventoryData:{length:8,inventoryContents:[{id:"ancientwarfarenpc:coin",Count:2b,tag:{metal:"copper"},slot:0,Damage:0s},{id:"ancientwarfarenpc:coin",Count:2b,tag:{metal:"copper"},slot:1,Damage:0s},{id:"ancientwarfarenpc:coin",Count:2b,tag:{metal:"copper"},slot:2,Damage:0s},{id:"ancientwarfarenpc:coin",Count:2b,tag:{metal:"copper"},slot:3,Damage:0s},{id:"ancientwarfarenpc:coin",Count:1b,tag:{metal:"copper"},slot:4,Damage:0s},{id:"ancientwarfarenpc:coin",Count:3b,tag:{metal:"copper"},slot:5,Damage:0s},{id:"ancientwarfarenpc:coin",Count:1b,tag:{metal:"copper"},slot:6,Damage:0s},{id:"ancientwarfarenpc:coin",Count:5b,tag:{metal:"copper"},slot:7,Damage:0s}]},legacyFeatures:1b}
:enddata
:endrule

rule:
plugin=inventory
number=42
data:
JSON:{blockState:{blockName:"minecraft:chest",properties:{facing:"west"}},lootLevel:0,teData:{Items:[{Slot:0b,id:"minecraft:porkchop",Count:1b,Damage:0s},{Slot:1b,id:"minecraft:porkchop",Count:1b,Damage:0s},{Slot:3b,id:"minecraft:porkchop",Count:1b,Damage:0s},{Slot:6b,id:"minecraft:bread",Count:1b,Damage:0s},{Slot:7b,id:"minecraft:bread",Count:1b,Damage:0s},{Slot:8b,id:"minecraft:bread",Count:1b,Damage:0s},{Slot:9b,id:"minecraft:porkchop",Count:1b,Damage:0s},{Slot:10b,id:"minecraft:porkchop",Count:1b,Damage:0s},{Slot:11b,id:"minecraft:porkchop",Count:3b,Damage:0s},{Slot:12b,id:"minecraft:porkchop",Count:1b,Damage:0s},{Slot:15b,id:"minecraft:bread",Count:2b,Damage:0s},{Slot:19b,id:"minecraft:porkchop",Count:2b,Damage:0s},{Slot:24b,id:"minecraft:bread",Count:1b,Damage:0s},{Slot:25b,id:"minecraft:bread",Count:3b,Damage:0s}],id:"minecraft:chest",Lock:""},inventoryData:{length:14,inventoryContents:[{id:"minecraft:porkchop",Count:1b,slot:0,Damage:0s},{id:"minecraft:porkchop",Count:1b,slot:1,Damage:0s},{id:"minecraft:porkchop",Count:1b,slot:2,Damage:0s},{id:"minecraft:bread",Count:1b,slot:3,Damage:0s},{id:"minecraft:bread",Count:1b,slot:4,Damage:0s},{id:"minecraft:bread",Count:1b,slot:5,Damage:0s},{id:"minecraft:porkchop",Count:1b,slot:6,Damage:0s},{id:"minecraft:porkchop",Count:1b,slot:7,Damage:0s},{id:"minecraft:porkchop",Count:3b,slot:8,Damage:0s},{id:"minecraft:porkchop",Count:1b,slot:9,Damage:0s},{id:"minecraft:bread",Count:2b,slot:10,Damage:0s},{id:"minecraft:porkchop",Count:2b,slot:11,Damage:0s},{id:"minecraft:bread",Count:1b,slot:12,Damage:0s},{id:"minecraft:bread",Count:3b,slot:13,Damage:0s}]},legacyFeatures:1b}
:enddata
:endrule

rule:
plugin=blockTile
number=43
data:
JSON:{blockState:{blockName:"ancientwarfarestructure:advanced_spawner",properties:{transparent:"true"}},teData:{id:"ancientwarfarestructure:advanced_spawner_tile",spawnerSettings:{minDelay:0,spawnDelay:0,lightSensitive:0b,spawnGroups:[{settingsList:[{remainingSpawnCount:1,hostile:1b,forced:1b,customTag:{ArmorDropChances:[1.0f,1.0f,1.0f,1.0f],ArmorItems:[{},{},{},{}],HandDropChances:[1.0f,1.0f],factionName:"norska",HandItems:[{},{}]},maxToSpawn:1,entityId:"ancientwarfarenpc:faction.civilian.female",minToSpawn:1}],groupWeight:1}],playerRange:8,respondToRedstone:0b,inventory:{Size:9,Items:[]},spawnRange:0,transparent:1b,maxDelay:0,xpToDrop:0,mobRange:0,debugMode:0b,maxNearbyMonsters:0}}}
:enddata
:endrule

rule:
plugin=inventory
number=44
data:
JSON:{blockState:{blockName:"minecraft:chest",properties:{facing:"east"}},lootLevel:0,teData:{Items:[{Slot:1b,id:"ancientwarfarenpc:coin",Count:2b,tag:{metal:"silver"},Damage:0s},{Slot:4b,id:"ancientwarfarenpc:coin",Count:2b,tag:{metal:"copper"},Damage:0s},{Slot:5b,id:"ancientwarfarenpc:coin",Count:2b,tag:{metal:"copper"},Damage:0s},{Slot:6b,id:"ancientwarfarenpc:coin",Count:2b,tag:{metal:"copper"},Damage:0s},{Slot:7b,id:"ancientwarfarenpc:coin",Count:3b,tag:{metal:"gold"},Damage:0s},{Slot:8b,id:"ancientwarfarenpc:coin",Count:2b,tag:{metal:"gold"},Damage:0s},{Slot:9b,id:"ancientwarfarenpc:coin",Count:4b,tag:{metal:"silver"},Damage:0s},{Slot:10b,id:"ancientwarfarenpc:coin",Count:3b,tag:{metal:"silver"},Damage:0s},{Slot:11b,id:"minecraft:gold_ingot",Count:1b,Damage:0s},{Slot:13b,id:"ancientwarfarenpc:coin",Count:1b,tag:{metal:"copper"},Damage:0s},{Slot:14b,id:"ancientwarfarenpc:coin",Count:4b,tag:{metal:"copper"},Damage:0s},{Slot:15b,id:"ancientwarfarenpc:coin",Count:2b,tag:{metal:"copper"},Damage:0s},{Slot:16b,id:"ancientwarfarenpc:coin",Count:6b,tag:{metal:"gold"},Damage:0s},{Slot:17b,id:"ancientwarfarenpc:coin",Count:3b,tag:{metal:"gold"},Damage:0s},{Slot:18b,id:"ancientwarfarenpc:coin",Count:1b,tag:{metal:"silver"},Damage:0s},{Slot:20b,id:"minecraft:gold_ingot",Count:1b,Damage:0s},{Slot:22b,id:"ancientwarfarenpc:coin",Count:1b,tag:{metal:"copper"},Damage:0s},{Slot:23b,id:"ancientwarfarenpc:coin",Count:2b,tag:{metal:"copper"},Damage:0s},{Slot:24b,id:"ancientwarfarenpc:coin",Count:1b,tag:{metal:"copper"},Damage:0s}],id:"minecraft:chest",Lock:""},inventoryData:{length:19,inventoryContents:[{id:"ancientwarfarenpc:coin",Count:2b,tag:{metal:"silver"},slot:0,Damage:0s},{id:"ancientwarfarenpc:coin",Count:2b,tag:{metal:"copper"},slot:1,Damage:0s},{id:"ancientwarfarenpc:coin",Count:2b,tag:{metal:"copper"},slot:2,Damage:0s},{id:"ancientwarfarenpc:coin",Count:2b,tag:{metal:"copper"},slot:3,Damage:0s},{id:"ancientwarfarenpc:coin",Count:3b,tag:{metal:"gold"},slot:4,Damage:0s},{id:"ancientwarfarenpc:coin",Count:2b,tag:{metal:"gold"},slot:5,Damage:0s},{id:"ancientwarfarenpc:coin",Count:4b,tag:{metal:"silver"},slot:6,Damage:0s},{id:"ancientwarfarenpc:coin",Count:3b,tag:{metal:"silver"},slot:7,Damage:0s},{id:"minecraft:gold_ingot",Count:1b,slot:8,Damage:0s},{id:"ancientwarfarenpc:coin",Count:1b,tag:{metal:"copper"},slot:9,Damage:0s},{id:"ancientwarfarenpc:coin",Count:4b,tag:{metal:"copper"},slot:10,Damage:0s},{id:"ancientwarfarenpc:coin",Count:2b,tag:{metal:"copper"},slot:11,Damage:0s},{id:"ancientwarfarenpc:coin",Count:6b,tag:{metal:"gold"},slot:12,Damage:0s},{id:"ancientwarfarenpc:coin",Count:3b,tag:{metal:"gold"},slot:13,Damage:0s},{id:"ancientwarfarenpc:coin",Count:1b,tag:{metal:"silver"},slot:14,Damage:0s},{id:"minecraft:gold_ingot",Count:1b,slot:15,Damage:0s},{id:"ancientwarfarenpc:coin",Count:1b,tag:{metal:"copper"},slot:16,Damage:0s},{id:"ancientwarfarenpc:coin",Count:2b,tag:{metal:"copper"},slot:17,Damage:0s},{id:"ancientwarfarenpc:coin",Count:1b,tag:{metal:"copper"},slot:18,Damage:0s}]},legacyFeatures:1b}
:enddata
:endrule

rule:
plugin=vanillaBlocks
number=45
data:
JSON:{blockState:{blockName:"ancientwarfarestructure:fire_pit",properties:{lit:"true",variant:"square"}}}
:enddata
:endrule

rule:
plugin=inventory
number=46
data:
JSON:{blockState:{blockName:"minecraft:furnace",properties:{facing:"south"}},lootLevel:0,teData:{CookTime:0,BurnTime:0,Items:[],id:"minecraft:furnace",CookTimeTotal:0,Lock:""},inventoryData:{length:0,inventoryContents:[]},legacyFeatures:0b}
:enddata
:endrule

rule:
plugin=inventory
number=47
data:
JSON:{blockState:{blockName:"minecraft:furnace",properties:{facing:"south"}},lootLevel:0,teData:{CookTime:0,BurnTime:0,Items:[],id:"minecraft:furnace",CookTimeTotal:0,Lock:""},inventoryData:{length:0,inventoryContents:[]},legacyFeatures:0b}
:enddata
:endrule

rule:
plugin=doors
number=48
data:
JSON:{blockState:{blockName:"minecraft:spruce_door",properties:{hinge:"left",half:"upper",powered:"false",facing:"south",open:"false"}}}
:enddata
:endrule

rule:
plugin=doors
number=49
data:
JSON:{blockState:{blockName:"minecraft:spruce_door",properties:{hinge:"right",half:"upper",powered:"false",facing:"south",open:"false"}}}
:enddata
:endrule

rule:
plugin=vanillaBlocks
number=50
data:
JSON:{blockState:{blockName:"minecraft:torch",properties:{facing:"north"}}}
:enddata
:endrule

rule:
plugin=vanillaBlocks
number=51
data:
JSON:{blockState:{blockName:"minecraft:carpet",properties:{color:"gray"}}}
:enddata
:endrule

rule:
plugin=vanillaBlocks
number=52
data:
JSON:{blockState:{blockName:"minecraft:torch",properties:{facing:"west"}}}
:enddata
:endrule

rule:
plugin=vanillaBlocks
number=53
data:
JSON:{blockState:{blockName:"minecraft:torch",properties:{facing:"east"}}}
:enddata
:endrule

rule:
plugin=vanillaBlocks
number=54
data:
JSON:{blockState:{blockName:"minecraft:torch",properties:{facing:"south"}}}
:enddata
:endrule

rule:
plugin=vanillaBlocks
number=55
data:
JSON:{blockState:{blockName:"minecraft:fence",properties:{east:"false",south:"false",north:"false",west:"false"}}}
:enddata
:endrule

rule:
plugin=vanillaSign
number=56
data:
JSON:{signContents0:"The§r",blockState:{blockName:"minecraft:wall_sign",properties:{facing:"south"}},signContents2:"",signContents1:"Ragnorok§r",signContents3:"",rotation:0}
:enddata
:endrule

rule:
plugin=vanillaSign
number=57
data:
JSON:{signContents0:"Norska§r",blockState:{blockName:"minecraft:wall_sign",properties:{facing:"south"}},signContents2:"",signContents1:"Tavern§r",signContents3:"",rotation:0}
:enddata
:endrule

rule:
plugin=vanillaBlocks
number=58
data:
JSON:{blockState:{blockName:"minecraft:spruce_stairs",properties:{half:"bottom",shape:"straight",facing:"north"}}}
:enddata
:endrule

rule:
plugin=vanillaSign
number=59
data:
JSON:{signContents0:"Norska§r",blockState:{blockName:"minecraft:wall_sign",properties:{facing:"east"}},signContents2:"",signContents1:"Tavern§r",signContents3:"",rotation:0}
:enddata
:endrule

rule:
plugin=vanillaSign
number=60
data:
JSON:{signContents0:"The§r",blockState:{blockName:"minecraft:wall_sign",properties:{facing:"west"}},signContents2:"",signContents1:"Ragonorok§r",signContents3:"",rotation:0}
:enddata
:endrule

rule:
plugin=vanillaSign
number=61
data:
JSON:{signContents0:"The§r",blockState:{blockName:"minecraft:wall_sign",properties:{facing:"east"}},signContents2:"",signContents1:"Ragnorok§r",signContents3:"",rotation:0}
:enddata
:endrule

rule:
plugin=vanillaSign
number=62
data:
JSON:{signContents0:"Norska§r",blockState:{blockName:"minecraft:wall_sign",properties:{facing:"west"}},signContents2:"",signContents1:"Tavern§r",signContents3:"",rotation:0}
:enddata
:endrule

rule:
plugin=vanillaBlocks
number=63
data:
JSON:{blockState:{blockName:"minecraft:spruce_stairs",properties:{half:"bottom",shape:"straight",facing:"south"}}}
:enddata
:endrule

rule:
plugin=vanillaBlocks
number=64
data:
JSON:{blockState:{blockName:"minecraft:torch",properties:{facing:"up"}}}
:enddata
:endrule

rule:
plugin=vanillaBlocks
number=65
data:
JSON:{blockState:{blockName:"minecraft:wooden_slab",properties:{half:"bottom",variant:"spruce"}}}
:enddata
:endrule

rule:
plugin=vanillaBlocks
number=66
data:
JSON:{blockState:{blockName:"minecraft:spruce_stairs",properties:{half:"top",shape:"straight",facing:"east"}}}
:enddata
:endrule

rule:
plugin=vanillaBlocks
number=67
data:
JSON:{blockState:{blockName:"minecraft:spruce_stairs",properties:{half:"top",shape:"straight",facing:"west"}}}
:enddata
:endrule

rule:
plugin=vanillaBlocks
number=68
data:
JSON:{blockState:{blockName:"minecraft:spruce_stairs",properties:{half:"top",shape:"straight",facing:"south"}}}
:enddata
:endrule

rule:
plugin=vanillaBlocks
number=69
data:
JSON:{blockState:{blockName:"minecraft:spruce_stairs",properties:{half:"top",shape:"straight",facing:"north"}}}
:enddata
:endrule

#### ENTITIES ####
