# Ancient Warfare Structure Template File
# Auto-generated structure template file. created on: 11/24/2014 at: 22:50:48
# Lines beginning with # denote comments

header:
version=2.1
name=TownBlocksGovernorsTower
size=21,68,23
offset=10,10,22
:endheader

#### VALIDATION ####
validation:
type=ground
survival=false
worldGenEnabled=false
unique=false
preserveBlocks=false
selectionWeight=0
clusterValue=0
minDuplicateDistance=0
dimensionWhiteList=false
dimensionList=
biomeWhiteList=false
biomeList=
leveling=0
fill=0
border=0
validTargetBlocks=
blockSwap=false
data:
:enddata
:endvalidation

#### LAYERS ####
layer: 0
1,1,1,1,1,1,1,1,1,1,1,1,1,1,1,1,1,1,1,1,1
1,1,1,1,1,1,1,1,1,1,1,1,1,1,1,1,1,1,1,1,1
1,1,2,2,2,2,2,2,2,2,2,2,2,2,2,2,2,2,2,1,1
1,1,2,2,2,2,2,2,2,2,2,2,2,2,2,2,2,2,2,1,1
1,1,2,2,2,2,2,2,2,2,2,2,2,2,2,2,2,2,2,1,1
1,1,2,2,2,2,2,2,2,2,2,2,2,2,2,2,2,2,2,1,1
1,1,2,2,2,2,2,2,2,2,2,2,2,2,2,2,2,2,2,1,1
1,1,2,2,2,2,2,2,2,2,2,2,2,2,2,2,2,2,2,1,1
1,1,2,2,2,2,2,2,2,2,2,2,2,2,2,2,2,2,2,1,1
1,1,2,2,2,2,2,2,2,2,2,2,2,2,2,2,2,2,2,1,1
1,1,2,2,2,2,2,2,2,2,2,2,2,2,2,2,2,2,2,1,1
1,1,2,2,2,2,2,2,2,2,2,2,2,2,2,2,2,2,2,1,1
1,1,2,2,2,2,2,2,2,2,2,2,2,2,2,2,2,2,2,1,1
1,1,2,2,2,2,2,2,2,2,2,2,2,2,2,2,2,2,2,1,1
1,1,2,2,2,2,2,2,2,2,2,2,2,2,2,2,2,2,2,1,1
1,1,2,2,2,2,2,2,2,2,2,2,2,2,2,2,2,2,2,1,1
1,1,2,2,2,2,2,2,2,2,2,2,2,2,2,2,2,2,2,1,1
1,1,2,2,2,2,2,2,2,2,2,2,2,2,2,2,2,2,2,1,1
1,1,2,2,2,2,2,2,2,2,2,2,2,2,2,2,2,2,2,1,1
1,1,1,1,1,1,1,1,1,1,1,1,1,1,1,1,1,1,1,1,1
1,1,1,1,1,1,1,1,1,1,1,1,1,1,1,1,1,1,1,1,1
1,1,1,1,1,1,1,1,1,1,1,1,1,1,1,1,1,1,1,1,1
1,1,1,1,1,1,1,1,1,1,1,1,1,1,1,1,1,1,1,1,1
:endlayer
layer: 1
1,1,1,1,1,1,1,1,1,1,1,1,1,1,1,1,1,1,1,1,1
1,1,1,1,1,1,1,1,1,1,1,1,1,1,1,1,1,1,1,1,1
1,1,2,2,2,2,2,2,2,2,2,2,2,2,2,2,2,2,2,1,1
1,1,2,0,0,0,2,0,0,0,0,0,0,0,0,2,0,0,2,1,1
1,1,2,0,0,0,6,0,0,0,0,0,0,0,0,2,0,0,2,1,1
1,1,2,2,2,2,2,0,0,0,0,0,0,0,0,2,0,0,2,1,1
1,1,2,0,0,0,0,0,2,2,2,2,2,0,0,2,3,2,2,1,1
1,1,2,0,0,0,0,2,0,0,2,0,0,2,0,0,0,0,2,1,1
1,1,2,0,0,0,2,2,0,0,2,0,0,0,2,0,0,0,2,1,1
1,1,2,0,0,0,2,2,2,3,2,0,0,0,2,0,0,0,2,1,1
1,1,2,0,0,0,2,2,0,0,4,0,0,0,2,0,0,0,2,1,1
1,1,2,0,0,0,2,2,0,0,2,2,2,2,2,0,0,0,2,1,1
1,1,2,0,0,0,2,2,2,0,0,0,0,0,2,0,0,0,2,1,1
1,1,2,0,0,0,0,2,2,2,5,0,0,2,0,0,0,0,2,1,1
1,1,2,0,0,0,0,0,2,2,2,3,2,0,0,0,0,0,2,1,1
1,1,2,2,7,2,2,0,0,0,0,0,0,0,2,2,2,2,2,1,1
1,1,2,0,0,0,2,0,0,0,0,0,0,0,4,0,0,0,2,1,1
1,1,2,0,0,0,2,0,0,0,0,0,0,0,2,0,0,0,2,1,1
1,1,2,2,2,2,2,2,2,2,2,2,2,2,2,2,2,2,2,1,1
1,1,1,1,1,1,1,1,1,1,1,1,1,1,1,1,1,1,1,1,1
1,1,1,1,1,1,1,1,1,1,1,1,1,1,1,1,1,1,1,1,1
1,1,1,1,1,1,1,1,1,1,1,1,1,1,1,1,1,1,1,1,1
1,1,1,1,1,1,1,1,1,1,1,1,1,1,1,1,1,1,1,1,1
:endlayer
layer: 2
1,1,1,1,1,1,1,1,1,1,1,1,1,1,1,1,1,1,1,1,1
1,1,1,1,1,1,1,1,1,1,1,1,1,1,1,1,1,1,1,1,1
1,1,2,2,2,2,2,2,2,2,2,2,2,2,2,2,2,2,2,1,1
1,1,2,0,0,0,2,18,0,0,0,0,0,0,0,9,0,0,2,1,1
1,1,2,0,0,0,19,0,0,0,0,0,0,0,0,9,0,0,2,1,1
1,1,2,9,9,9,2,0,0,0,0,0,0,0,0,9,0,0,2,1,1
1,1,2,0,0,0,0,0,2,2,2,2,2,0,0,2,10,2,2,1,1
1,1,2,0,0,0,0,2,0,0,9,0,0,2,0,0,0,8,2,1,1
1,1,2,0,0,0,2,2,0,0,9,0,0,0,2,0,0,0,2,1,1
1,1,2,0,0,0,2,2,2,16,2,0,0,0,2,0,0,0,2,1,1
1,1,2,0,0,0,2,2,8,0,15,0,0,0,2,0,0,0,2,1,1
1,1,2,0,0,0,2,17,0,12,2,9,9,9,2,0,0,0,2,1,1
1,1,2,0,0,0,2,17,17,0,0,0,0,0,2,0,0,0,2,1,1
1,1,2,0,0,0,0,2,17,5,0,0,13,2,0,0,0,0,2,1,1
1,1,2,13,0,0,0,0,2,2,2,14,2,0,0,0,0,0,2,1,1
1,1,2,2,20,2,9,0,0,0,0,0,0,0,2,9,9,9,2,1,1
1,1,2,0,0,0,9,0,0,0,0,0,0,0,11,0,0,0,2,1,1
1,1,2,0,0,0,9,0,0,0,0,0,0,12,2,0,0,0,2,1,1
1,1,2,2,2,2,2,2,2,2,2,2,2,2,2,2,2,2,2,1,1
1,1,1,1,1,1,1,1,1,1,1,1,1,1,1,1,1,1,1,1,1
1,1,1,1,1,1,1,1,1,1,1,1,1,1,1,1,1,1,1,1,1
1,1,1,1,1,1,1,1,1,1,1,1,1,1,1,1,1,1,1,1,1
1,1,1,1,1,1,1,1,1,1,1,1,1,1,1,1,1,1,1,1,1
:endlayer
layer: 3
1,1,1,1,1,1,1,1,1,1,1,1,1,1,1,1,1,1,1,1,1
1,1,1,1,1,1,1,1,1,1,1,1,1,1,1,1,1,1,1,1,1
1,1,2,2,2,2,2,2,2,2,2,2,2,2,2,2,2,2,2,1,1
1,1,2,0,0,0,2,0,0,0,0,0,0,0,0,9,0,0,2,1,1
1,1,2,0,0,0,2,0,0,0,0,0,0,0,0,9,0,0,2,1,1
1,1,2,9,9,9,2,0,0,0,0,0,0,0,0,9,0,0,2,1,1
1,1,2,0,0,0,0,0,2,2,2,2,2,0,0,2,2,2,2,1,1
1,1,2,0,0,0,0,2,0,0,9,0,0,2,0,0,0,0,2,1,1
1,1,2,0,0,0,2,2,0,0,9,0,0,0,2,0,0,0,2,1,1
1,1,2,0,0,0,2,2,2,2,2,0,0,0,2,0,0,0,2,1,1
1,1,2,0,0,0,2,2,0,0,2,0,0,0,2,0,0,0,2,1,1
1,1,2,0,0,0,2,22,0,0,2,9,9,9,2,0,0,0,2,1,1
1,1,2,0,0,0,2,0,0,0,0,0,0,21,2,0,0,0,2,1,1
1,1,2,0,0,0,0,2,0,0,0,0,0,2,0,0,0,0,2,1,1
1,1,2,0,0,0,0,0,2,2,2,2,2,0,0,0,0,0,2,1,1
1,1,2,2,2,2,9,0,0,0,0,0,0,0,2,9,9,9,2,1,1
1,1,2,0,0,0,9,0,0,0,0,0,0,0,2,0,0,0,2,1,1
1,1,2,0,0,0,9,0,0,0,0,0,0,0,2,0,0,0,2,1,1
1,1,2,2,2,2,2,2,2,2,2,2,2,2,2,2,2,2,2,1,1
1,1,1,1,1,1,1,1,1,1,1,1,1,1,1,1,1,1,1,1,1
1,1,1,1,1,1,1,1,1,1,1,1,1,1,1,1,1,1,1,1,1
1,1,1,1,1,1,1,1,1,1,1,1,1,1,1,1,1,1,1,1,1
1,1,1,1,1,1,1,1,1,1,1,1,1,1,1,1,1,1,1,1,1
:endlayer
layer: 4
1,1,1,1,1,1,1,1,1,1,1,1,1,1,1,1,1,1,1,1,1
1,1,1,1,1,1,1,1,1,1,1,1,1,1,1,1,1,1,1,1,1
1,1,2,2,2,2,2,2,2,2,2,2,2,2,2,2,2,2,2,1,1
1,1,2,0,0,0,2,0,0,0,0,0,0,0,0,9,0,0,2,1,1
1,1,2,0,0,0,2,0,0,0,0,0,0,0,0,9,0,0,2,1,1
1,1,2,9,9,9,2,0,0,0,0,0,0,0,0,9,0,0,2,1,1
1,1,2,0,0,0,0,0,2,2,2,2,2,0,0,2,2,2,2,1,1
1,1,2,0,0,0,0,2,2,2,2,2,2,2,0,0,0,0,2,1,1
1,1,2,0,0,0,2,2,2,2,2,2,2,2,2,0,0,0,2,1,1
1,1,2,0,0,0,2,2,2,2,2,2,2,2,2,0,0,0,2,1,1
1,1,2,0,0,0,2,22,0,0,2,2,2,2,2,0,0,0,2,1,1
1,1,2,0,0,0,2,0,0,0,2,2,2,2,2,0,0,0,2,1,1
1,1,2,0,0,0,2,0,0,0,0,0,2,2,2,0,0,0,2,1,1
1,1,2,0,0,0,0,2,0,0,0,0,2,2,0,0,0,0,2,1,1
1,1,2,0,0,0,0,0,2,2,2,2,2,0,0,0,0,0,2,1,1
1,1,2,2,2,2,9,0,0,0,0,0,0,0,2,9,9,9,2,1,1
1,1,2,0,0,0,9,0,0,0,0,0,0,0,2,0,0,0,2,1,1
1,1,2,0,0,0,9,0,0,0,0,0,0,0,2,0,0,0,2,1,1
1,1,2,2,2,2,2,2,2,2,2,2,2,2,2,2,2,2,2,1,1
1,1,1,1,1,1,1,1,1,1,1,1,1,1,1,1,1,1,1,1,1
1,1,1,1,1,1,1,1,1,1,1,1,1,1,1,1,1,1,1,1,1
1,1,1,1,1,1,1,1,1,1,1,1,1,1,1,1,1,1,1,1,1
1,1,1,1,1,1,1,1,1,1,1,1,1,1,1,1,1,1,1,1,1
:endlayer
layer: 5
1,1,1,1,1,1,1,1,1,1,1,1,1,1,1,1,1,1,1,1,1
1,1,1,1,1,1,1,1,1,1,1,1,1,1,1,1,1,1,1,1,1
1,1,2,2,2,2,2,2,2,2,2,2,2,2,2,2,2,2,2,1,1
1,1,2,2,2,2,2,2,0,0,0,0,0,2,2,2,2,2,2,1,1
1,1,2,2,2,2,2,2,0,0,0,0,0,2,2,2,2,2,2,1,1
1,1,2,2,2,2,2,2,0,0,0,0,0,2,2,2,2,2,2,1,1
1,1,2,2,2,2,2,2,2,2,2,2,2,2,2,2,2,2,2,1,1
1,1,2,2,2,2,2,2,17,17,2,2,2,2,2,2,2,2,2,1,1
1,1,2,0,0,0,2,17,17,17,2,2,2,2,2,0,0,0,2,1,1
1,1,2,0,0,0,2,22,2,2,2,2,2,2,2,0,0,0,2,1,1
1,1,2,0,0,0,2,0,0,0,2,2,2,2,2,0,0,0,2,1,1
1,1,2,0,0,0,2,0,0,0,2,2,2,2,2,0,0,0,2,1,1
1,1,2,0,0,0,2,0,0,0,2,2,2,2,2,0,0,0,2,1,1
1,1,2,2,2,2,2,2,0,23,2,2,2,2,2,2,2,2,2,1,1
1,1,2,2,2,2,2,2,2,2,2,2,2,2,2,2,2,2,2,1,1
1,1,2,2,2,2,2,2,0,0,0,0,0,2,2,2,2,2,2,1,1
1,1,2,2,2,2,2,2,0,0,0,0,0,2,2,2,2,2,2,1,1
1,1,2,2,2,2,2,2,0,0,0,0,0,2,2,2,2,2,2,1,1
1,1,2,2,2,2,2,2,2,2,2,2,2,2,2,2,2,2,2,1,1
1,1,1,1,1,1,1,1,1,1,1,1,1,1,1,1,1,1,1,1,1
1,1,1,1,1,1,1,1,1,1,1,1,1,1,1,1,1,1,1,1,1
1,1,1,1,1,1,1,1,1,1,1,1,1,1,1,1,1,1,1,1,1
1,1,1,1,1,1,1,1,1,1,1,1,1,1,1,1,1,1,1,1,1
:endlayer
layer: 6
1,1,1,1,1,1,1,1,1,1,1,1,1,1,1,1,1,1,1,1,1
1,1,1,1,1,1,1,1,1,1,1,1,1,1,1,1,1,1,1,1,1
1,1,2,2,2,2,2,2,2,2,2,2,2,2,2,2,2,2,2,1,1
1,1,2,0,0,0,0,0,0,0,0,0,0,0,0,0,0,0,2,1,1
1,1,2,0,0,0,0,0,0,0,0,0,0,0,0,0,0,0,2,1,1
1,1,2,0,0,0,0,0,0,0,0,0,0,0,0,0,0,0,2,1,1
1,1,2,0,0,0,0,0,2,2,2,2,2,0,0,0,0,0,2,1,1
1,1,2,0,0,0,0,2,0,24,17,2,2,2,0,0,0,0,2,1,1
1,1,2,0,0,0,2,0,0,0,0,0,2,0,2,0,0,0,2,1,1
1,1,2,0,0,0,2,0,0,0,0,0,0,0,2,0,0,0,2,1,1
1,1,2,0,0,0,2,0,0,0,0,0,2,2,2,0,0,0,2,1,1
1,1,2,0,0,0,2,0,0,0,0,0,0,0,2,0,0,0,2,1,1
1,1,2,0,0,0,2,0,0,0,0,0,0,0,2,0,0,0,2,1,1
1,1,2,0,0,0,0,2,0,0,0,0,0,2,0,0,0,0,2,1,1
1,1,2,0,0,0,0,0,2,2,2,2,2,0,0,0,0,0,2,1,1
1,1,2,0,0,0,0,0,0,0,0,0,0,0,0,0,0,0,2,1,1
1,1,2,0,0,0,0,0,0,0,0,0,0,0,0,0,0,0,2,1,1
1,1,2,0,0,0,0,0,0,0,0,0,0,0,0,0,0,0,2,1,1
1,1,2,2,2,2,2,2,2,2,2,2,2,2,2,2,2,2,2,1,1
1,1,1,1,1,1,1,1,1,1,1,1,1,1,1,1,1,1,1,1,1
1,1,1,1,1,1,1,1,1,1,1,1,1,1,1,1,1,1,1,1,1
1,1,1,1,1,1,1,1,1,1,1,1,1,1,1,1,1,1,1,1,1
1,1,1,1,1,1,1,1,1,1,1,1,1,1,1,1,1,1,1,1,1
:endlayer
layer: 7
1,1,1,1,1,1,1,1,1,1,1,1,1,1,1,1,1,1,1,1,1
1,1,1,1,1,1,1,1,1,1,1,1,1,1,1,1,1,1,1,1,1
1,1,2,2,2,2,2,2,2,2,2,2,2,2,2,2,2,2,2,1,1
1,1,2,0,0,0,0,0,0,0,0,0,0,0,0,0,0,0,2,1,1
1,1,2,0,0,0,0,0,0,0,0,0,0,0,0,0,0,0,2,1,1
1,1,2,0,0,0,0,0,0,0,0,0,0,0,0,0,0,0,2,1,1
1,1,2,0,0,0,0,0,2,2,2,2,2,0,0,0,0,0,2,1,1
1,1,2,0,0,0,0,2,0,0,24,2,2,2,0,0,0,0,2,1,1
1,1,2,0,0,0,2,0,0,0,0,0,2,0,2,0,0,0,2,1,1
1,1,2,0,0,0,2,0,0,0,0,0,0,0,2,0,0,0,2,1,1
1,1,2,0,0,0,2,0,0,0,0,0,2,2,2,0,0,0,2,1,1
1,1,2,0,0,0,2,0,0,0,0,0,0,0,2,0,0,0,2,1,1
1,1,2,0,0,0,2,0,0,0,0,0,0,0,2,0,0,0,2,1,1
1,1,2,0,0,0,0,2,0,0,0,0,0,2,0,0,0,0,2,1,1
1,1,2,0,0,0,0,0,2,2,2,2,2,0,0,0,0,0,2,1,1
1,1,2,0,0,0,0,0,0,0,0,0,0,0,0,0,0,0,2,1,1
1,1,2,0,0,0,0,0,0,0,0,0,0,0,0,0,0,0,2,1,1
1,1,2,0,0,0,0,0,0,0,0,0,0,0,0,0,0,0,2,1,1
1,1,2,2,2,2,2,2,2,2,2,2,2,2,2,2,2,2,2,1,1
1,1,1,1,1,1,1,1,1,1,1,1,1,1,1,1,1,1,1,1,1
1,1,1,1,1,1,1,1,1,1,1,1,1,1,1,1,1,1,1,1,1
1,1,1,1,1,1,1,1,1,1,1,1,1,1,1,1,1,1,1,1,1
1,1,1,1,1,1,1,1,1,1,1,1,1,1,1,1,1,1,1,1,1
:endlayer
layer: 8
1,1,1,1,1,1,1,1,1,1,1,1,1,1,1,1,1,1,1,1,1
1,1,1,1,1,1,1,1,1,1,1,1,1,1,1,1,1,1,1,1,1
1,1,2,2,2,2,2,2,2,2,2,2,2,2,2,2,2,2,2,1,1
1,1,2,0,0,0,0,0,0,0,0,0,0,0,0,0,0,0,2,1,1
1,1,2,0,0,0,0,0,0,0,0,0,0,0,0,0,0,0,2,1,1
1,1,2,0,0,0,0,0,0,0,0,0,0,0,0,0,0,0,2,1,1
1,1,2,0,0,0,0,0,2,2,2,2,2,0,0,0,0,0,2,1,1
1,1,2,0,0,0,0,2,0,0,0,24,17,2,0,0,0,0,2,1,1
1,1,2,0,0,0,2,0,0,0,0,0,17,17,2,0,0,0,2,1,1
1,1,2,0,0,0,2,0,0,0,0,0,17,17,2,0,0,0,2,1,1
1,1,2,0,0,0,2,0,0,0,0,0,2,2,2,0,0,0,2,1,1
1,1,2,0,0,0,2,0,0,0,0,0,0,0,2,0,0,0,2,1,1
1,1,2,0,0,0,2,0,0,0,0,0,0,0,2,0,0,0,2,1,1
1,1,2,0,0,0,0,2,0,0,0,0,0,2,0,0,0,0,2,1,1
1,1,2,0,0,0,0,0,2,2,2,2,2,0,0,0,0,0,2,1,1
1,1,2,0,0,0,0,0,0,0,0,0,0,0,0,0,0,0,2,1,1
1,1,2,0,0,0,0,0,0,0,0,0,0,0,0,0,0,0,2,1,1
1,1,2,0,0,0,0,0,0,0,0,0,0,0,0,0,0,0,2,1,1
1,1,2,2,2,2,2,2,2,2,2,2,2,2,2,2,2,2,2,1,1
1,1,1,1,1,1,1,1,1,1,1,1,1,1,1,1,1,1,1,1,1
1,1,1,1,1,1,1,1,1,1,1,1,1,1,1,1,1,1,1,1,1
1,1,1,1,1,1,1,1,1,1,1,1,1,1,1,1,1,1,1,1,1
1,1,1,1,1,1,1,1,1,1,1,1,1,1,1,1,1,1,1,1,1
:endlayer
layer: 9
1,1,1,1,1,1,1,1,1,1,1,1,1,1,1,1,1,1,1,1,1
1,1,1,1,1,1,1,1,1,1,1,1,1,1,1,1,1,1,1,1,1
1,1,2,2,2,2,2,2,2,2,2,2,2,2,2,2,2,2,2,1,1
1,1,2,0,0,0,0,0,0,0,0,0,0,0,0,0,0,0,2,1,1
1,1,2,0,0,0,0,0,0,0,0,0,0,0,0,0,0,0,2,1,1
1,1,2,0,0,0,0,0,0,0,0,0,0,0,0,0,0,0,2,1,1
1,1,2,0,0,0,0,0,2,2,2,2,2,0,0,0,0,0,2,1,1
1,1,2,0,0,0,0,2,0,0,0,0,0,2,0,0,0,0,2,1,1
1,1,2,0,0,0,2,0,0,0,0,0,0,0,2,0,0,0,2,1,1
1,1,2,0,0,0,2,0,0,0,0,0,0,25,2,0,0,0,2,1,1
1,1,2,0,0,0,2,0,0,0,0,0,2,2,2,0,0,0,2,1,1
1,1,2,0,0,0,2,0,0,0,0,0,0,0,2,0,0,0,2,1,1
1,1,2,0,0,0,2,0,0,0,0,0,0,0,2,0,0,0,2,1,1
1,1,2,0,0,0,0,2,0,0,0,0,0,2,0,0,0,0,2,1,1
1,1,2,0,0,0,0,0,2,2,2,2,2,0,0,0,0,0,2,1,1
1,1,2,0,0,0,0,0,0,0,0,0,0,0,0,0,0,0,2,1,1
1,1,2,0,0,0,0,0,0,0,0,0,0,0,0,0,0,0,2,1,1
1,1,2,0,0,0,0,0,0,0,0,0,0,0,0,0,0,0,2,1,1
1,1,2,2,2,2,2,2,2,2,2,2,2,2,2,2,2,2,2,1,1
1,1,1,1,1,1,1,1,1,1,1,1,1,1,1,1,1,1,1,1,1
1,1,1,1,1,1,1,1,1,1,1,1,1,1,1,1,1,1,1,1,1
1,1,1,1,1,1,1,1,1,1,1,1,1,1,1,1,1,1,1,1,1
1,1,1,1,1,1,1,1,1,1,1,1,1,1,1,1,1,1,1,1,1
:endlayer
layer: 10
26,26,26,26,26,26,26,26,26,26,26,26,26,26,26,26,26,26,26,26,26
26,26,26,26,26,26,26,26,26,26,26,26,26,26,26,26,26,26,26,26,26
26,26,26,2,2,2,2,2,2,2,2,2,2,2,2,2,2,2,26,26,26
26,26,2,0,0,0,0,0,0,0,0,0,0,0,0,0,0,0,2,26,26
26,26,2,0,0,0,0,0,0,0,0,0,0,0,0,0,0,0,2,26,26
26,26,2,0,0,0,0,0,0,0,0,0,0,0,0,0,0,0,2,26,26
26,26,2,0,0,0,0,0,2,2,2,2,2,0,0,0,0,0,2,26,26
26,26,2,0,0,0,0,2,0,0,0,0,0,2,0,0,0,0,2,26,26
26,26,2,0,0,0,2,0,0,0,0,0,0,0,2,0,0,0,2,26,26
26,26,2,0,0,0,2,0,0,0,0,0,0,0,2,0,0,0,2,26,26
26,26,2,0,0,0,2,0,0,0,0,0,2,25,2,0,0,0,2,26,26
26,26,2,0,0,0,2,0,0,0,0,0,0,0,2,0,0,0,2,26,26
26,26,2,0,0,0,2,0,0,0,0,0,0,0,2,0,0,0,2,26,26
26,26,2,0,0,0,0,2,0,0,0,0,0,2,0,0,0,0,2,26,26
26,26,2,0,0,0,0,0,2,2,2,2,2,0,0,0,0,0,2,26,26
26,26,2,0,0,0,0,0,0,0,0,0,0,0,0,0,0,0,2,26,26
26,26,2,0,0,0,0,0,0,0,0,0,0,0,0,0,0,0,2,26,26
26,26,2,0,0,0,0,0,0,0,0,0,0,0,0,0,0,0,2,26,26
26,26,26,2,2,2,2,2,2,2,2,2,2,2,2,2,2,2,26,26,26
26,26,26,26,26,26,26,26,2,2,2,2,2,26,26,26,26,26,26,26,26
26,26,26,26,26,26,26,26,26,26,26,26,26,26,26,26,26,26,26,26,26
26,26,26,26,26,26,26,26,26,26,26,26,26,26,26,26,26,26,26,26,26
26,26,26,26,26,26,26,26,26,26,26,26,26,26,26,26,26,26,26,26,26
:endlayer
layer: 11
0,0,0,0,0,0,0,0,0,0,0,0,0,0,0,0,0,0,0,0,0
0,0,0,0,0,0,0,0,0,0,0,0,0,0,0,0,0,0,0,0,0
0,0,0,2,2,2,2,2,2,2,2,2,2,2,2,2,2,2,0,0,0
0,0,2,2,2,2,2,2,2,2,2,2,2,2,2,2,2,2,2,0,0
0,0,2,2,2,2,2,2,2,2,2,2,2,2,2,2,2,2,2,0,0
0,0,2,2,2,2,2,2,2,2,2,2,2,2,2,2,2,2,2,0,0
0,0,2,2,2,2,2,2,2,2,2,2,2,2,2,2,2,2,2,0,0
0,0,2,2,2,2,2,2,2,2,2,2,2,2,2,2,2,2,2,0,0
0,0,2,2,2,2,2,2,2,2,2,2,2,0,2,2,2,2,2,0,0
0,0,2,2,2,2,2,2,2,2,2,2,2,0,2,2,2,2,2,0,0
0,0,2,2,2,2,2,2,2,2,2,2,2,0,2,2,2,2,2,0,0
0,0,2,2,2,2,2,2,2,2,2,2,2,25,2,2,2,2,2,0,0
0,0,2,2,2,2,2,2,2,2,2,2,2,2,2,2,2,2,2,0,0
0,0,2,2,2,2,2,2,2,2,2,2,2,2,2,2,2,2,2,0,0
0,0,2,2,2,2,2,2,2,2,2,2,2,2,2,2,2,2,2,0,0
0,0,2,2,2,2,2,2,2,2,2,2,2,2,2,2,2,2,2,0,0
0,0,2,2,2,2,2,2,2,2,2,2,2,2,2,2,2,2,2,0,0
0,0,2,2,2,2,2,2,2,2,2,2,2,2,2,2,2,2,2,0,0
0,0,0,2,2,2,2,2,2,2,2,2,2,2,2,2,2,2,0,0,0
0,0,0,0,0,0,0,0,2,27,27,27,2,0,0,0,0,0,0,0,0
0,0,0,0,0,0,0,0,0,0,0,0,0,0,0,0,0,0,0,0,0
0,0,0,0,0,0,0,0,0,0,0,0,0,0,0,0,0,0,0,0,0
0,0,0,0,0,0,0,0,0,0,0,0,0,0,0,0,0,0,0,0,0
:endlayer
layer: 12
0,0,0,0,0,0,0,0,0,0,0,0,0,0,0,0,0,0,0,0,0
0,0,0,0,0,0,0,0,0,0,0,0,0,0,0,0,0,0,0,0,0
0,0,0,2,2,2,2,2,2,2,2,2,2,2,2,2,2,2,0,0,0
0,0,2,0,0,0,0,0,0,0,0,0,0,0,0,0,0,0,2,0,0
0,0,2,0,0,0,0,0,0,0,0,0,0,0,0,0,0,0,2,0,0
0,0,2,0,0,0,0,0,0,0,0,0,0,0,0,0,0,0,2,0,0
0,0,2,0,0,0,0,0,2,2,2,2,2,0,0,0,0,0,2,0,0
0,0,2,0,0,0,0,2,2,0,0,0,2,2,0,0,0,0,2,0,0
0,0,2,0,0,0,2,2,2,29,0,0,2,0,2,0,0,0,2,0,0
0,0,2,0,0,0,2,2,0,0,0,0,2,0,2,0,0,0,2,0,0
0,0,2,0,0,2,2,30,0,0,0,0,2,0,2,0,0,0,2,0,0
0,0,2,0,0,2,2,0,0,0,0,0,2,0,2,0,0,0,2,0,0
0,0,2,0,0,0,2,31,0,0,0,0,28,0,2,0,0,0,2,0,0
0,0,2,0,0,0,0,2,0,0,0,0,2,2,0,0,0,0,2,0,0
0,0,2,0,0,0,0,0,2,0,0,0,2,0,0,0,0,0,2,0,0
0,0,2,0,0,0,0,0,0,0,0,0,0,0,0,0,0,0,2,0,0
0,0,2,0,0,0,0,0,0,0,0,0,0,0,0,0,0,0,2,0,0
0,0,2,0,0,0,0,0,0,0,0,0,0,0,0,0,0,0,2,0,0
0,0,0,2,2,2,2,2,2,0,0,0,2,2,2,2,2,2,0,0,0
0,0,0,0,0,0,0,0,2,0,0,0,2,0,0,0,0,0,0,0,0
0,0,0,0,0,0,0,0,0,0,0,0,0,0,0,0,0,0,0,0,0
0,0,0,0,0,0,0,0,0,0,0,0,0,0,0,0,0,0,0,0,0
0,0,0,0,0,0,0,0,0,0,0,0,0,0,0,0,0,0,0,0,0
:endlayer
layer: 13
0,0,0,0,0,0,0,0,0,0,0,0,0,0,0,0,0,0,0,0,0
0,0,0,0,0,0,0,0,0,0,0,0,0,0,0,0,0,0,0,0,0
0,0,0,2,2,32,2,32,2,32,2,32,2,32,2,32,2,2,0,0,0
0,0,2,0,0,0,0,0,0,0,0,0,0,0,0,0,0,0,2,0,0
0,0,2,0,0,0,0,0,0,0,0,0,0,0,0,0,0,0,2,0,0
0,0,32,0,0,0,0,0,0,0,0,0,0,0,0,0,0,0,32,0,0
0,0,2,0,0,0,0,0,2,2,2,2,2,0,0,0,0,0,2,0,0
0,0,32,0,0,0,0,2,0,0,0,0,2,2,0,0,0,0,32,0,0
0,0,2,0,0,0,2,2,29,0,0,0,9,0,2,0,0,0,2,0,0
0,0,32,0,0,0,2,2,0,0,0,0,9,0,2,0,0,0,32,0,0
0,0,2,0,0,2,2,0,0,0,0,0,9,0,2,0,0,0,2,0,0
0,0,32,0,0,2,2,0,0,0,0,0,2,0,2,0,0,0,32,0,0
0,0,2,0,0,0,2,0,0,0,0,0,33,0,2,0,0,0,2,0,0
0,0,32,0,0,0,0,2,0,0,0,0,2,2,0,0,0,0,32,0,0
0,0,2,0,0,0,0,0,2,0,0,0,2,0,0,0,0,0,2,0,0
0,0,32,0,0,0,0,0,0,0,0,0,0,0,0,0,0,0,32,0,0
0,0,2,0,0,0,0,0,0,0,0,0,0,0,0,0,0,0,2,0,0
0,0,2,0,0,0,0,0,0,0,0,0,0,0,0,0,0,0,2,0,0
0,0,0,2,2,32,2,32,2,0,0,0,2,32,2,32,2,2,0,0,0
0,0,0,0,0,0,0,0,2,0,0,0,2,0,0,0,0,0,0,0,0
0,0,0,0,0,0,0,0,0,0,0,0,0,0,0,0,0,0,0,0,0
0,0,0,0,0,0,0,0,0,0,0,0,0,0,0,0,0,0,0,0,0
0,0,0,0,0,0,0,0,0,0,0,0,0,0,0,0,0,0,0,0,0
:endlayer
layer: 14
0,0,0,0,0,0,0,0,0,0,0,0,0,0,0,0,0,0,0,0,0
0,0,0,0,0,0,0,0,0,0,0,0,0,0,0,0,0,0,0,0,0
0,0,0,2,2,32,2,32,2,32,2,32,2,32,2,32,2,2,0,0,0
0,0,2,0,0,0,0,0,0,0,0,0,0,0,0,0,0,0,2,0,0
0,0,2,0,0,0,0,0,0,0,0,0,0,0,0,0,0,0,2,0,0
0,0,32,0,0,0,0,0,0,0,0,0,0,0,0,0,0,0,32,0,0
0,0,2,0,0,0,0,0,2,2,2,2,2,0,0,0,0,0,2,0,0
0,0,32,0,0,0,0,2,0,0,35,0,2,2,0,0,0,0,32,0,0
0,0,2,0,0,0,2,0,0,0,0,0,2,0,2,0,0,0,2,0,0
0,0,32,0,0,0,2,37,0,0,0,0,2,21,2,0,0,0,32,0,0
0,0,2,0,0,2,2,2,36,0,0,0,2,0,2,0,0,0,2,0,0
0,0,32,0,0,2,2,2,0,0,0,0,2,0,2,0,0,0,32,0,0
0,0,2,0,0,0,2,2,36,0,0,0,34,0,2,0,0,0,2,0,0
0,0,32,0,0,0,0,2,0,0,0,0,2,2,0,0,0,0,32,0,0
0,0,2,0,0,0,0,0,2,0,0,0,2,0,0,0,0,0,2,0,0
0,0,32,0,0,0,0,0,0,0,0,0,0,0,0,0,0,0,32,0,0
0,0,2,0,0,0,0,0,0,0,0,0,0,0,0,0,0,0,2,0,0
0,0,2,0,0,0,0,0,0,0,0,0,0,0,0,0,0,0,2,0,0
0,0,0,2,2,32,2,32,2,0,0,0,2,32,2,32,2,2,0,0,0
0,0,0,0,0,0,0,0,2,0,0,0,2,0,0,0,0,0,0,0,0
0,0,0,0,0,0,0,0,35,0,0,0,35,0,0,0,0,0,0,0,0
0,0,0,0,0,0,0,0,0,0,0,0,0,0,0,0,0,0,0,0,0
0,0,0,0,0,0,0,0,0,0,0,0,0,0,0,0,0,0,0,0,0
:endlayer
layer: 15
0,0,0,0,0,0,0,0,0,0,0,0,0,0,0,0,0,0,0,0,0
0,0,0,0,0,23,0,23,0,23,0,23,0,23,0,23,0,0,0,0,0
0,0,0,2,2,2,2,2,2,2,2,2,2,2,2,2,2,2,0,0,0
0,0,2,35,0,0,0,0,0,0,0,0,0,0,0,0,0,35,2,0,0
0,0,2,0,0,0,0,0,0,0,0,0,0,0,0,0,0,0,2,0,0
0,21,2,0,0,0,0,0,0,0,23,0,0,0,0,0,0,0,2,36,0
0,0,2,0,0,0,0,0,2,2,2,2,2,0,0,0,0,0,2,0,0
0,21,2,0,0,0,0,2,0,0,0,0,2,2,0,0,0,0,2,36,0
0,0,2,0,0,0,2,0,0,0,0,0,2,0,2,0,0,0,2,0,0
0,21,2,0,0,0,2,0,0,0,0,0,2,0,2,0,0,0,2,36,0
0,0,2,0,21,2,2,37,0,0,0,0,2,0,2,36,0,0,2,0,0
0,21,2,0,0,2,2,2,0,0,0,0,2,0,2,0,0,0,2,36,0
0,0,2,0,0,0,2,2,0,0,0,0,2,0,2,0,0,0,2,0,0
0,21,2,0,0,0,0,2,0,0,0,0,2,2,0,0,0,0,2,36,0
0,0,2,0,0,0,0,0,2,2,2,2,2,0,0,0,0,0,2,0,0
0,21,2,0,0,0,0,0,35,0,0,0,35,0,0,0,0,0,2,36,0
0,0,2,0,0,0,0,0,0,0,0,0,0,0,0,0,0,0,2,0,0
0,0,2,23,0,0,0,0,0,0,0,0,0,0,0,0,0,23,2,0,0
0,0,0,2,2,2,2,2,2,2,2,2,2,2,2,2,2,2,0,0,0
0,0,0,0,0,35,0,35,27,27,27,27,27,35,0,35,0,0,0,0,0
0,0,0,0,0,0,0,0,0,0,0,0,0,0,0,0,0,0,0,0,0
0,0,0,0,0,0,0,0,0,0,0,0,0,0,0,0,0,0,0,0,0
0,0,0,0,0,0,0,0,0,0,0,0,0,0,0,0,0,0,0,0,0
:endlayer
layer: 16
0,0,0,0,0,0,0,0,0,0,0,0,0,0,0,0,0,0,0,0,0
0,0,0,40,40,40,40,40,40,40,40,40,40,40,40,40,40,40,0,0,0
0,0,40,2,2,2,2,2,2,2,2,2,2,2,2,2,2,2,38,0,0
0,41,2,2,2,2,2,2,2,2,2,2,2,2,2,2,2,2,2,38,0
0,41,2,2,2,2,2,2,2,2,2,2,2,2,2,2,2,2,2,38,0
0,41,2,2,2,2,2,2,2,2,2,2,2,2,2,2,2,2,2,38,0
0,41,2,2,2,2,2,2,2,2,2,2,2,2,2,2,2,2,2,38,0
0,41,2,2,2,2,2,2,2,2,2,2,2,2,2,2,2,2,2,38,0
0,41,2,2,2,2,2,0,0,2,2,2,2,2,2,2,2,2,2,38,0
0,41,2,2,2,2,2,0,2,2,2,2,2,2,2,2,2,2,2,38,0
0,41,2,2,2,2,2,0,2,2,2,2,2,2,2,2,2,2,2,38,0
0,41,2,2,2,2,2,37,2,2,2,2,2,2,2,2,2,2,2,38,0
0,41,2,2,2,2,2,2,2,2,2,2,2,2,2,2,2,2,2,38,0
0,41,2,2,2,2,2,2,2,2,2,2,2,2,2,2,2,2,2,38,0
0,41,2,2,2,2,2,2,2,2,2,2,2,2,2,2,2,2,2,38,0
0,41,2,2,2,2,2,2,2,2,2,2,2,2,2,2,2,2,2,38,0
0,41,2,2,2,2,2,2,2,2,2,2,2,2,2,2,2,2,2,38,0
0,41,2,2,2,2,2,2,2,2,2,2,2,2,2,2,2,2,2,39,0
0,0,41,2,2,2,2,2,2,2,2,2,2,2,2,2,2,2,38,0,0
0,0,0,39,39,39,39,39,39,39,39,39,39,39,39,39,39,39,0,0,0
0,0,0,0,0,0,0,0,0,0,0,0,0,0,0,0,0,0,0,0,0
0,0,0,0,0,0,0,0,0,0,0,0,0,0,0,0,0,0,0,0,0
0,0,0,0,0,0,0,0,0,0,0,0,0,0,0,0,0,0,0,0,0
:endlayer
layer: 17
0,0,0,0,0,0,0,0,0,0,0,0,0,0,0,0,0,0,0,0,0
0,0,0,2,2,2,2,2,2,2,2,2,2,2,2,2,2,2,0,0,0
0,0,2,0,0,0,0,0,0,0,0,0,0,0,0,0,0,0,2,0,0
0,2,0,0,0,0,0,0,0,0,0,0,0,0,0,0,0,0,0,2,0
0,2,0,0,0,0,0,0,0,0,0,0,0,0,0,0,0,0,0,2,0
0,2,0,0,0,0,0,0,2,2,2,2,2,0,0,0,0,0,0,2,0
0,2,0,0,0,0,0,2,2,2,2,2,2,2,0,0,0,0,0,2,0
0,2,0,0,0,0,2,2,0,43,0,0,0,2,2,0,0,0,0,2,0
0,2,0,0,0,2,2,0,0,43,0,0,0,17,2,2,0,0,0,2,0
0,2,0,0,0,2,2,0,43,43,0,0,0,17,2,2,0,0,0,2,0
0,2,0,0,0,2,2,0,43,0,0,0,0,22,2,2,0,0,0,2,0
0,2,0,0,0,2,2,0,0,0,0,0,0,0,42,0,0,0,0,2,0
0,2,0,0,0,2,2,0,0,0,0,0,0,0,2,2,0,0,0,2,0
0,2,0,0,0,0,2,2,0,0,0,0,0,2,2,0,0,0,0,2,0
0,2,0,0,0,0,0,2,2,2,2,2,2,2,0,0,0,0,0,2,0
0,2,0,0,0,0,0,0,2,2,2,2,2,0,0,0,0,0,0,2,0
0,2,0,0,0,0,0,0,0,0,0,0,0,0,0,0,0,0,0,2,0
0,2,0,0,0,0,0,0,0,0,0,0,0,0,0,0,0,0,0,2,0
0,0,2,0,0,0,0,0,0,0,0,0,0,0,0,0,0,0,2,0,0
0,0,0,2,2,2,2,2,2,2,2,2,2,2,2,2,2,2,0,0,0
0,0,0,0,0,0,0,0,0,0,0,0,0,0,0,0,0,0,0,0,0
0,0,0,0,0,0,0,0,0,0,0,0,0,0,0,0,0,0,0,0,0
0,0,0,0,0,0,0,0,0,0,0,0,0,0,0,0,0,0,0,0,0
:endlayer
layer: 18
0,0,0,0,0,0,0,0,0,0,0,0,0,0,0,0,0,0,0,0,0
0,0,0,46,29,0,46,29,0,46,44,29,0,46,29,0,46,29,0,0,0
0,0,45,0,0,0,0,0,0,0,0,0,0,0,0,0,0,0,45,0,0
0,37,0,0,0,0,0,0,0,0,0,0,0,0,0,0,0,0,0,37,0
0,27,0,0,0,0,0,0,0,0,0,0,0,0,0,0,0,0,0,27,0
0,0,0,0,0,0,0,0,2,2,2,2,2,0,0,0,0,0,0,0,0
0,37,0,0,0,0,0,2,2,2,2,2,2,2,0,0,0,0,0,37,0
0,27,0,0,0,0,2,2,0,0,0,0,0,2,2,0,0,0,0,27,0
0,0,0,0,0,2,2,0,0,0,0,0,0,17,2,2,0,0,0,0,0
0,37,0,0,0,2,2,0,0,0,0,0,0,22,2,2,0,0,0,37,0
0,44,0,0,0,2,2,0,0,0,0,0,0,0,2,2,0,0,0,44,0
0,27,0,0,0,2,2,0,0,0,0,0,0,0,47,0,0,0,0,27,0
0,0,0,0,0,2,2,0,0,0,0,0,0,0,2,2,0,0,0,0,0
0,37,0,0,0,0,2,2,0,0,0,0,0,2,2,0,0,0,0,37,0
0,27,0,0,0,0,0,2,2,2,2,2,2,2,0,0,0,0,0,27,0
0,0,0,0,0,0,0,0,2,2,2,2,2,0,0,0,0,0,0,0,0
0,37,0,0,0,0,0,0,0,0,0,0,0,0,0,0,0,0,0,37,0
0,27,0,0,0,0,0,0,0,0,0,0,0,0,0,0,0,0,0,27,0
0,0,45,0,0,0,0,0,0,0,0,0,0,0,0,0,0,0,45,0,0
0,0,0,46,29,0,46,29,0,46,44,29,0,46,29,0,46,29,0,0,0
0,0,0,0,0,0,0,0,0,0,0,0,0,0,0,0,0,0,0,0,0
0,0,0,0,0,0,0,0,0,0,0,0,0,0,0,0,0,0,0,0,0
0,0,0,0,0,0,0,0,0,0,0,0,0,0,0,0,0,0,0,0,0
:endlayer
layer: 19
0,0,0,0,0,0,0,0,0,0,0,0,0,0,0,0,0,0,0,0,0
0,0,0,0,0,0,0,0,0,0,0,0,0,0,0,0,0,0,0,0,0
0,0,0,0,0,0,0,0,0,0,0,0,0,0,0,0,0,0,0,0,0
0,0,0,0,0,0,0,0,0,0,0,0,0,0,0,0,0,0,0,0,0
0,0,0,0,0,0,0,0,0,0,0,0,0,0,0,0,0,0,0,0,0
0,0,0,0,0,0,0,0,2,0,45,0,2,0,0,0,0,0,0,0,0
0,0,0,0,0,0,0,2,2,2,2,2,2,2,0,0,0,0,0,0,0
0,0,0,0,0,0,2,2,0,0,0,0,0,2,2,0,0,0,0,0,0
0,0,0,0,0,2,2,0,0,0,0,0,0,22,2,2,0,0,0,0,0
0,0,0,0,0,0,2,0,0,0,0,0,0,0,2,2,0,0,0,0,0
0,0,0,0,0,45,2,0,0,0,0,0,0,0,2,2,36,0,0,0,0
0,0,0,0,0,0,2,0,0,0,0,0,0,0,2,2,0,0,0,0,0
0,0,0,0,0,2,2,0,0,0,0,0,0,0,2,2,0,0,0,0,0
0,0,0,0,0,0,2,2,0,0,0,0,0,2,2,0,0,0,0,0,0
0,0,0,0,0,0,0,2,2,2,2,2,2,2,0,0,0,0,0,0,0
0,0,0,0,0,0,0,0,2,0,45,0,2,0,0,0,0,0,0,0,0
0,0,0,0,0,0,0,0,0,0,0,0,0,0,0,0,0,0,0,0,0
0,0,0,0,0,0,0,0,0,0,0,0,0,0,0,0,0,0,0,0,0
0,0,0,0,0,0,0,0,0,0,0,0,0,0,0,0,0,0,0,0,0
0,0,0,0,0,0,0,0,0,0,0,0,0,0,0,0,0,0,0,0,0
0,0,0,0,0,0,0,0,0,0,0,0,0,0,0,0,0,0,0,0,0
0,0,0,0,0,0,0,0,0,0,0,0,0,0,0,0,0,0,0,0,0
0,0,0,0,0,0,0,0,0,0,0,0,0,0,0,0,0,0,0,0,0
:endlayer
layer: 20
0,0,0,0,0,0,0,0,0,0,0,0,0,0,0,0,0,0,0,0,0
0,0,0,0,0,0,0,0,0,0,0,0,0,0,0,0,0,0,0,0,0
0,0,0,0,0,0,0,0,0,0,0,0,0,0,0,0,0,0,0,0,0
0,0,0,0,0,0,0,0,0,0,0,0,0,0,0,0,0,0,0,0,0
0,0,0,0,0,0,0,0,0,0,0,0,0,0,0,0,0,0,0,0,0
0,0,0,0,0,0,0,0,17,17,17,17,17,0,0,0,0,0,0,0,0
0,0,0,0,0,0,0,17,17,17,17,17,17,17,0,0,0,0,0,0,0
0,0,0,0,0,0,17,17,0,0,35,0,0,22,17,0,0,0,0,0,0
0,0,0,0,0,17,17,0,0,0,0,0,0,0,17,17,0,0,0,0,0
0,0,0,0,0,17,17,0,0,0,0,0,0,0,17,17,0,0,0,0,0
0,0,0,0,0,17,17,36,0,0,0,0,0,0,17,17,0,0,0,0,0
0,0,0,0,0,17,17,0,0,0,0,0,0,21,17,17,0,0,0,0,0
0,0,0,0,0,17,17,0,0,0,0,0,0,0,17,17,0,0,0,0,0
0,0,0,0,0,0,17,17,0,0,23,0,0,17,17,0,0,0,0,0,0
0,0,0,0,0,0,0,17,17,17,17,17,17,17,0,0,0,0,0,0,0
0,0,0,0,0,0,0,0,17,17,17,17,17,0,0,0,0,0,0,0,0
0,0,0,0,0,0,0,0,0,0,0,0,0,0,0,0,0,0,0,0,0
0,0,0,0,0,0,0,0,0,0,0,0,0,0,0,0,0,0,0,0,0
0,0,0,0,0,0,0,0,0,0,0,0,0,0,0,0,0,0,0,0,0
0,0,0,0,0,0,0,0,0,0,0,0,0,0,0,0,0,0,0,0,0
0,0,0,0,0,0,0,0,0,0,0,0,0,0,0,0,0,0,0,0,0
0,0,0,0,0,0,0,0,0,0,0,0,0,0,0,0,0,0,0,0,0
0,0,0,0,0,0,0,0,0,0,0,0,0,0,0,0,0,0,0,0,0
:endlayer
layer: 21
0,0,0,0,0,0,0,0,0,0,0,0,0,0,0,0,0,0,0,0,0
0,0,0,0,0,0,0,0,0,0,0,0,0,0,0,0,0,0,0,0,0
0,0,0,0,0,0,0,0,0,0,0,0,0,0,0,0,0,0,0,0,0
0,0,0,0,0,0,0,0,0,0,17,0,0,0,0,0,0,0,0,0,0
0,0,0,0,0,0,0,0,17,17,17,17,17,0,0,0,0,0,0,0,0
0,0,0,0,0,0,17,17,17,17,17,17,17,17,17,0,0,0,0,0,0
0,0,0,0,0,17,17,17,17,17,17,17,17,22,17,17,0,0,0,0,0
0,0,0,0,0,17,17,17,17,17,17,17,17,0,17,17,0,0,0,0,0
0,0,0,0,17,17,17,17,17,17,17,17,17,0,17,17,17,0,0,0,0
0,0,0,0,17,17,17,17,17,17,17,17,17,0,17,17,17,0,0,0,0
0,0,0,17,17,17,17,17,17,17,17,17,17,0,17,17,17,17,0,0,0
0,0,0,0,17,17,17,17,17,17,17,17,17,17,17,17,17,0,0,0,0
0,0,0,0,17,17,17,17,17,17,17,17,17,17,17,17,17,0,0,0,0
0,0,0,0,0,17,17,17,17,17,17,17,17,17,17,17,0,0,0,0,0
0,0,0,0,0,17,17,17,17,17,17,17,17,17,17,17,0,0,0,0,0
0,0,0,0,0,0,17,17,17,17,17,17,17,17,17,0,0,0,0,0,0
0,0,0,0,0,0,0,0,17,17,17,17,17,0,0,0,0,0,0,0,0
0,0,0,0,0,0,0,0,0,0,17,0,0,0,0,0,0,0,0,0,0
0,0,0,0,0,0,0,0,0,0,0,0,0,0,0,0,0,0,0,0,0
0,0,0,0,0,0,0,0,0,0,0,0,0,0,0,0,0,0,0,0,0
0,0,0,0,0,0,0,0,0,0,0,0,0,0,0,0,0,0,0,0,0
0,0,0,0,0,0,0,0,0,0,0,0,0,0,0,0,0,0,0,0,0
0,0,0,0,0,0,0,0,0,0,0,0,0,0,0,0,0,0,0,0,0
:endlayer
layer: 22
0,0,0,0,0,0,0,0,0,0,0,0,0,0,0,0,0,0,0,0,0
0,0,0,0,0,0,0,0,0,0,0,0,0,0,0,0,0,0,0,0,0
0,0,0,0,0,0,0,0,0,0,0,0,0,0,0,0,0,0,0,0,0
0,0,0,0,0,0,0,0,2,2,2,2,2,0,0,0,0,0,0,0,0
0,0,0,0,0,0,2,2,0,0,0,0,0,2,2,0,0,0,0,0,0
0,0,0,0,0,2,0,17,17,17,17,5,0,0,43,2,0,0,0,0,0
0,0,0,0,2,0,0,0,0,0,0,0,0,0,43,0,2,0,0,0,0
0,0,0,0,2,0,0,0,0,0,0,0,43,0,43,0,2,0,0,0,0
0,0,0,2,0,0,0,0,0,0,0,0,43,0,43,0,0,2,0,0,0
0,0,0,2,0,0,0,0,0,0,0,0,43,0,43,0,0,2,0,0,0
0,0,0,2,0,0,0,0,0,0,0,0,43,0,43,0,0,2,0,0,0
0,0,0,2,0,0,0,0,0,0,0,0,17,17,17,0,0,2,0,0,0
0,0,0,2,0,0,17,0,0,0,0,0,0,0,0,0,0,2,0,0,0
0,0,0,0,2,0,0,0,0,0,0,17,0,0,0,0,2,0,0,0,0
0,0,0,0,2,0,0,0,0,0,0,0,0,0,0,0,2,0,0,0,0
0,0,0,0,0,2,0,0,0,0,0,0,0,0,0,2,0,0,0,0,0
0,0,0,0,0,0,2,2,0,0,0,0,0,2,2,0,0,0,0,0,0
0,0,0,0,0,0,0,0,2,2,2,2,2,0,0,0,0,0,0,0,0
0,0,0,0,0,0,0,0,0,0,0,0,0,0,0,0,0,0,0,0,0
0,0,0,0,0,0,0,0,0,0,0,0,0,0,0,0,0,0,0,0,0
0,0,0,0,0,0,0,0,0,0,0,0,0,0,0,0,0,0,0,0,0
0,0,0,0,0,0,0,0,0,0,0,0,0,0,0,0,0,0,0,0,0
0,0,0,0,0,0,0,0,0,0,0,0,0,0,0,0,0,0,0,0,0
:endlayer
layer: 23
0,0,0,0,0,0,0,0,0,0,0,0,0,0,0,0,0,0,0,0,0
0,0,0,0,0,0,0,0,0,0,0,0,0,0,0,0,0,0,0,0,0
0,0,0,0,0,0,0,0,0,23,0,23,0,0,0,0,0,0,0,0,0
0,0,0,0,0,0,0,0,2,17,48,17,2,0,0,0,0,0,0,0,0
0,0,0,0,0,0,2,2,0,0,0,0,0,2,2,0,0,0,0,0,0
0,0,0,0,0,2,0,17,17,17,5,0,0,0,0,2,0,0,0,0,0
0,0,0,0,2,0,0,0,0,0,0,0,0,0,0,0,2,0,0,0,0
0,0,0,0,2,0,0,0,0,0,0,0,43,0,43,0,2,0,0,0,0
0,0,0,2,0,0,0,0,0,0,0,0,43,0,43,0,0,2,0,0,0
0,0,21,17,0,0,0,0,0,0,0,0,43,0,43,0,0,17,36,0,0
0,0,0,48,0,0,0,0,0,0,0,0,43,0,43,0,0,48,0,0,0
0,0,21,17,0,0,0,0,0,0,0,0,17,17,17,0,0,17,36,0,0
0,0,0,2,0,0,17,0,0,0,0,0,0,0,0,0,0,2,0,0,0
0,0,0,0,2,0,0,0,0,0,0,17,0,0,0,0,2,0,0,0,0
0,0,0,0,2,0,0,0,0,0,0,0,0,0,0,0,2,0,0,0,0
0,0,0,0,0,2,0,0,0,0,0,0,0,0,0,2,0,0,0,0,0
0,0,0,0,0,0,2,2,0,0,0,0,0,2,2,0,0,0,0,0,0
0,0,0,0,0,0,0,0,2,17,48,17,2,0,0,0,0,0,0,0,0
0,0,0,0,0,0,0,0,0,35,0,35,0,0,0,0,0,0,0,0,0
0,0,0,0,0,0,0,0,0,0,0,0,0,0,0,0,0,0,0,0,0
0,0,0,0,0,0,0,0,0,0,0,0,0,0,0,0,0,0,0,0,0
0,0,0,0,0,0,0,0,0,0,0,0,0,0,0,0,0,0,0,0,0
0,0,0,0,0,0,0,0,0,0,0,0,0,0,0,0,0,0,0,0,0
:endlayer
layer: 24
0,0,0,0,0,0,0,0,0,0,0,0,0,0,0,0,0,0,0,0,0
0,0,0,0,0,0,0,0,0,0,0,0,0,0,0,0,0,0,0,0,0
0,0,0,0,0,0,0,0,0,0,0,0,0,0,0,0,0,0,0,0,0
0,0,0,0,0,0,0,0,2,17,48,17,2,0,0,0,0,0,0,0,0
0,0,0,0,0,0,2,2,0,0,0,0,0,2,2,0,0,0,0,0,0
0,0,0,0,0,32,0,17,17,5,0,0,0,0,0,32,0,0,0,0,0
0,0,0,0,2,0,0,0,0,0,0,0,0,0,0,0,2,0,0,0,0
0,0,0,0,2,0,0,0,0,0,0,0,43,0,43,0,2,0,0,0,0
0,0,0,2,0,0,0,0,0,0,0,0,43,0,43,0,0,2,0,0,0
0,0,0,17,0,0,0,0,0,0,0,0,43,0,43,0,0,17,0,0,0
0,0,0,48,0,0,0,0,0,0,0,0,43,0,43,0,0,48,0,0,0
0,0,0,17,0,0,0,0,0,0,0,0,17,17,17,0,0,17,0,0,0
0,0,0,2,0,0,17,0,0,0,0,0,0,0,0,0,0,2,0,0,0
0,0,0,0,2,0,0,0,0,0,0,17,0,0,0,0,2,0,0,0,0
0,0,0,0,2,0,0,0,0,0,0,0,0,0,0,0,2,0,0,0,0
0,0,0,0,0,32,0,0,0,0,0,0,0,0,0,32,0,0,0,0,0
0,0,0,0,0,0,2,2,0,0,0,0,0,2,2,0,0,0,0,0,0
0,0,0,0,0,0,0,0,2,17,48,17,2,0,0,0,0,0,0,0,0
0,0,0,0,0,0,0,0,0,0,0,0,0,0,0,0,0,0,0,0,0
0,0,0,0,0,0,0,0,0,0,0,0,0,0,0,0,0,0,0,0,0
0,0,0,0,0,0,0,0,0,0,0,0,0,0,0,0,0,0,0,0,0
0,0,0,0,0,0,0,0,0,0,0,0,0,0,0,0,0,0,0,0,0
0,0,0,0,0,0,0,0,0,0,0,0,0,0,0,0,0,0,0,0,0
:endlayer
layer: 25
0,0,0,0,0,0,0,0,0,0,0,0,0,0,0,0,0,0,0,0,0
0,0,0,0,0,0,0,0,0,0,0,0,0,0,0,0,0,0,0,0,0
0,0,0,0,0,0,0,0,0,0,0,0,0,0,0,0,0,0,0,0,0
0,0,0,0,0,0,0,0,2,17,48,17,2,0,0,0,0,0,0,0,0
0,0,0,0,0,0,2,2,0,0,0,0,21,2,2,0,0,0,0,0,0
0,0,0,0,0,32,0,17,5,0,0,0,0,35,0,32,0,0,0,0,0
0,0,0,0,2,0,0,0,0,0,0,0,0,0,0,0,2,0,0,0,0
0,0,0,0,2,36,0,0,0,0,0,0,17,43,17,21,2,0,0,0,0
0,0,0,2,35,0,0,0,0,0,0,0,17,0,17,0,35,2,0,0,0
0,0,0,17,0,0,0,0,0,0,0,0,17,0,17,0,0,17,0,0,0
0,0,0,48,0,0,0,0,0,0,0,0,17,0,17,0,0,48,0,0,0
0,0,0,17,0,0,0,0,0,0,0,0,17,17,17,0,0,17,0,0,0
0,0,0,2,23,0,17,0,0,0,0,0,0,0,0,0,23,2,0,0,0
0,0,0,0,2,36,0,0,0,0,0,17,0,0,0,21,2,0,0,0,0
0,0,0,0,2,0,0,0,0,0,0,0,0,0,0,0,2,0,0,0,0
0,0,0,0,0,32,0,23,0,0,0,0,0,23,0,32,0,0,0,0,0
0,0,0,0,0,0,2,2,36,0,0,0,21,2,2,0,0,0,0,0,0
0,0,0,0,0,0,0,0,2,17,48,17,2,0,0,0,0,0,0,0,0
0,0,0,0,0,0,0,0,0,0,0,0,0,0,0,0,0,0,0,0,0
0,0,0,0,0,0,0,0,0,0,0,0,0,0,0,0,0,0,0,0,0
0,0,0,0,0,0,0,0,0,0,0,0,0,0,0,0,0,0,0,0,0
0,0,0,0,0,0,0,0,0,0,0,0,0,0,0,0,0,0,0,0,0
0,0,0,0,0,0,0,0,0,0,0,0,0,0,0,0,0,0,0,0,0
:endlayer
layer: 26
0,0,0,0,0,0,0,0,0,0,0,0,0,0,0,0,0,0,0,0,0
0,0,0,0,0,0,0,0,0,0,0,0,0,0,0,0,0,0,0,0,0
0,0,0,0,0,0,0,0,0,0,25,0,0,0,0,0,0,0,0,0,0
0,0,0,0,0,0,0,0,2,2,2,2,2,0,0,0,0,0,0,0,0
0,0,0,0,0,0,2,2,0,0,0,0,17,2,2,0,0,0,0,0,0
0,0,0,0,0,2,17,5,0,0,0,0,17,17,17,2,0,0,0,0,0
0,0,0,0,2,17,17,17,0,0,0,0,17,17,17,17,2,0,0,0,0
0,0,0,0,2,17,17,17,0,0,0,0,17,17,17,17,2,0,0,0,0
0,0,0,2,17,17,17,17,0,0,0,0,17,17,17,17,17,2,0,0,0
0,0,0,2,17,17,17,17,0,0,0,0,17,17,17,17,17,2,0,0,0
0,0,24,2,17,17,17,17,0,0,0,0,17,17,17,17,17,2,5,0,0
0,0,0,2,17,17,17,17,0,0,0,0,17,17,17,17,17,2,0,0,0
0,0,0,2,17,17,17,17,0,0,0,0,17,17,17,17,17,2,0,0,0
0,0,0,0,2,17,17,17,17,17,17,17,17,17,17,17,2,0,0,0,0
0,0,0,0,2,17,17,17,17,17,17,17,17,17,17,17,2,0,0,0,0
0,0,0,0,0,2,17,17,17,17,17,17,17,17,17,2,0,0,0,0,0
0,0,0,0,0,0,2,2,17,17,17,17,17,2,2,0,0,0,0,0,0
0,0,0,0,0,0,0,0,2,2,2,2,2,0,0,0,0,0,0,0,0
0,0,0,0,0,0,0,0,0,0,22,0,0,0,0,0,0,0,0,0,0
0,0,0,0,0,0,0,0,0,0,0,0,0,0,0,0,0,0,0,0,0
0,0,0,0,0,0,0,0,0,0,0,0,0,0,0,0,0,0,0,0,0
0,0,0,0,0,0,0,0,0,0,0,0,0,0,0,0,0,0,0,0,0
0,0,0,0,0,0,0,0,0,0,0,0,0,0,0,0,0,0,0,0,0
:endlayer
layer: 27
0,0,0,0,0,0,0,0,0,0,0,0,0,0,0,0,0,0,0,0,0
0,0,0,0,0,0,0,0,0,0,0,0,0,0,0,0,0,0,0,0,0
0,0,0,0,0,0,0,0,17,17,17,17,17,0,0,0,0,0,0,0,0
0,0,0,0,0,0,17,17,17,17,17,17,17,17,17,0,0,0,0,0,0
0,0,0,0,17,17,17,17,0,0,0,0,43,17,17,17,17,0,0,0,0
0,0,0,0,17,17,0,0,0,0,0,0,43,0,0,17,17,0,0,0,0
0,0,0,17,17,0,0,43,0,0,0,0,43,0,0,0,17,17,0,0,0
0,0,0,17,17,0,0,43,0,0,0,0,43,0,0,0,17,17,0,0,0
0,0,17,17,0,0,0,43,0,0,0,0,43,0,0,0,0,17,17,0,0
0,0,17,17,0,0,0,43,0,0,0,0,43,0,0,0,0,17,17,0,0
0,0,17,17,0,0,0,43,0,0,0,0,43,0,0,0,0,17,17,0,0
0,0,17,17,0,0,0,43,0,0,0,0,43,0,0,0,0,17,17,0,0
0,0,17,17,0,0,0,43,0,0,0,0,43,0,0,0,0,17,17,0,0
0,0,0,17,17,0,0,24,17,17,17,17,43,0,0,0,17,17,0,0,0
0,0,0,17,17,0,0,0,0,0,0,0,0,0,0,0,17,17,0,0,0
0,0,0,0,17,17,0,0,0,0,0,0,0,0,0,17,17,0,0,0,0
0,0,0,0,17,17,17,17,0,0,0,0,0,17,17,17,17,0,0,0,0
0,0,0,0,0,0,17,17,17,17,17,17,17,17,17,0,0,0,0,0,0
0,0,0,0,0,0,0,0,17,17,17,17,17,0,0,0,0,0,0,0,0
0,0,0,0,0,0,0,0,0,0,0,0,0,0,0,0,0,0,0,0,0
0,0,0,0,0,0,0,0,0,0,0,0,0,0,0,0,0,0,0,0,0
0,0,0,0,0,0,0,0,0,0,0,0,0,0,0,0,0,0,0,0,0
0,0,0,0,0,0,0,0,0,0,0,0,0,0,0,0,0,0,0,0,0
:endlayer
layer: 28
0,0,0,0,0,0,0,0,0,0,0,0,0,0,0,0,0,0,0,0,0
0,0,0,0,0,0,0,0,0,0,0,0,0,0,0,0,0,0,0,0,0
0,0,0,0,0,0,0,0,0,0,0,0,0,0,0,0,0,0,0,0,0
0,0,0,0,0,0,0,0,17,17,17,17,17,0,0,0,0,0,0,0,0
0,0,0,0,0,0,17,17,0,0,0,0,0,17,17,0,0,0,0,0,0
0,0,0,0,0,17,0,0,0,0,0,0,0,0,0,17,0,0,0,0,0
0,0,0,0,17,0,0,45,0,0,0,0,0,0,0,0,17,0,0,0,0
0,0,0,0,17,0,0,0,0,0,0,0,0,0,0,0,17,0,0,0,0
0,0,0,17,0,0,0,0,0,0,0,0,0,0,0,0,0,17,0,0,0
0,0,0,17,0,0,0,0,0,0,0,0,0,0,0,0,0,17,0,0,0
0,0,0,17,0,0,0,0,0,0,0,0,0,0,0,0,0,17,0,0,0
0,0,0,17,0,0,0,0,0,0,0,0,0,0,0,0,0,17,0,0,0
0,0,0,17,0,0,0,0,0,0,0,0,0,0,0,0,0,17,0,0,0
0,0,0,0,17,0,0,0,24,17,17,17,0,0,0,0,17,0,0,0,0
0,0,0,0,17,0,0,0,0,0,0,0,0,0,0,0,17,0,0,0,0
0,0,0,0,0,17,0,0,0,0,0,0,0,0,0,17,0,0,0,0,0
0,0,0,0,0,0,17,17,0,0,0,0,0,17,17,0,0,0,0,0,0
0,0,0,0,0,0,0,0,17,17,17,17,17,0,0,0,0,0,0,0,0
0,0,0,0,0,0,0,0,0,0,0,0,0,0,0,0,0,0,0,0,0
0,0,0,0,0,0,0,0,0,0,0,0,0,0,0,0,0,0,0,0,0
0,0,0,0,0,0,0,0,0,0,0,0,0,0,0,0,0,0,0,0,0
0,0,0,0,0,0,0,0,0,0,0,0,0,0,0,0,0,0,0,0,0
0,0,0,0,0,0,0,0,0,0,0,0,0,0,0,0,0,0,0,0,0
:endlayer
layer: 29
0,0,0,0,0,0,0,0,0,0,0,0,0,0,0,0,0,0,0,0,0
0,0,0,0,0,0,0,0,0,0,0,0,0,0,0,0,0,0,0,0,0
0,0,0,0,0,0,0,0,0,0,0,0,0,0,0,0,0,0,0,0,0
0,0,0,0,0,0,0,0,0,0,0,0,0,0,0,0,0,0,0,0,0
0,0,0,0,0,0,0,0,17,17,17,17,17,0,0,0,0,0,0,0,0
0,0,0,0,0,0,17,17,0,0,0,0,0,17,17,0,0,0,0,0,0
0,0,0,0,0,17,0,0,0,0,0,0,0,0,0,17,0,0,0,0,0
0,0,0,0,0,17,0,0,0,0,0,0,0,0,0,17,0,0,0,0,0
0,0,0,0,17,0,0,0,0,0,0,0,0,0,0,0,17,0,0,0,0
0,0,0,0,17,0,0,0,0,0,0,0,0,0,0,0,17,0,0,0,0
0,0,0,0,17,0,0,0,0,0,0,0,0,0,0,0,17,0,0,0,0
0,0,0,0,17,36,0,0,0,0,0,0,0,0,0,21,17,0,0,0,0
0,0,0,0,17,0,0,0,0,0,0,0,0,0,0,0,17,0,0,0,0
0,0,0,0,0,17,0,0,0,24,17,17,0,0,0,17,0,0,0,0,0
0,0,0,0,0,17,0,0,0,0,0,0,0,0,0,17,0,0,0,0,0
0,0,0,0,0,0,17,17,0,0,23,0,0,17,17,0,0,0,0,0,0
0,0,0,0,0,0,0,0,17,17,17,17,17,0,0,0,0,0,0,0,0
0,0,0,0,0,0,0,0,0,0,0,0,0,0,0,0,0,0,0,0,0
0,0,0,0,0,0,0,0,0,0,0,0,0,0,0,0,0,0,0,0,0
0,0,0,0,0,0,0,0,0,0,0,0,0,0,0,0,0,0,0,0,0
0,0,0,0,0,0,0,0,0,0,0,0,0,0,0,0,0,0,0,0,0
0,0,0,0,0,0,0,0,0,0,0,0,0,0,0,0,0,0,0,0,0
0,0,0,0,0,0,0,0,0,0,0,0,0,0,0,0,0,0,0,0,0
:endlayer
layer: 30
0,0,0,0,0,0,0,0,0,0,0,0,0,0,0,0,0,0,0,0,0
0,0,0,0,0,0,0,0,0,0,0,0,0,0,0,0,0,0,0,0,0
0,0,0,0,0,0,0,0,0,0,0,0,0,0,0,0,0,0,0,0,0
0,0,0,0,0,0,0,0,0,0,0,0,0,0,0,0,0,0,0,0,0
0,0,0,0,0,0,0,0,0,0,0,0,0,0,0,0,0,0,0,0,0
0,0,0,0,0,0,0,0,17,17,17,17,17,0,0,0,0,0,0,0,0
0,0,0,0,0,0,17,17,2,2,2,2,2,17,17,0,0,0,0,0,0
0,0,0,0,0,0,17,2,0,0,0,0,0,2,17,0,0,0,0,0,0
0,0,0,0,0,17,2,0,0,0,0,0,0,0,2,17,0,0,0,0,0
0,0,0,0,0,17,2,0,0,0,0,0,0,0,2,17,0,0,0,0,0
0,0,0,0,0,17,2,0,0,0,0,0,0,0,2,17,0,0,0,0,0
0,0,0,0,0,17,2,0,0,0,0,0,0,0,2,17,0,0,0,0,0
0,0,0,0,0,17,2,0,0,0,0,0,0,0,2,17,0,0,0,0,0
0,0,0,0,0,0,17,0,0,0,24,17,0,2,17,0,0,0,0,0,0
0,0,0,0,0,0,17,17,2,2,2,2,2,17,17,0,0,0,0,0,0
0,0,0,0,0,0,0,0,17,17,17,17,17,0,0,0,0,0,0,0,0
0,0,0,0,0,0,0,0,0,0,0,0,0,0,0,0,0,0,0,0,0
0,0,0,0,0,0,0,0,0,0,0,0,0,0,0,0,0,0,0,0,0
0,0,0,0,0,0,0,0,0,0,0,0,0,0,0,0,0,0,0,0,0
0,0,0,0,0,0,0,0,0,0,0,0,0,0,0,0,0,0,0,0,0
0,0,0,0,0,0,0,0,0,0,0,0,0,0,0,0,0,0,0,0,0
0,0,0,0,0,0,0,0,0,0,0,0,0,0,0,0,0,0,0,0,0
0,0,0,0,0,0,0,0,0,0,0,0,0,0,0,0,0,0,0,0,0
:endlayer
layer: 31
0,0,0,0,0,0,0,0,0,0,0,0,0,0,0,0,0,0,0,0,0
0,0,0,0,0,0,0,0,0,0,0,0,0,0,0,0,0,0,0,0,0
0,0,0,0,0,0,0,0,0,0,0,0,0,0,0,0,0,0,0,0,0
0,0,0,0,0,0,0,0,0,0,0,0,0,0,0,0,0,0,0,0,0
0,0,0,0,0,0,0,0,0,0,0,0,0,0,0,0,0,0,0,0,0
0,0,0,0,0,0,0,0,0,0,17,0,0,0,0,0,0,0,0,0,0
0,0,0,0,0,0,0,0,2,2,2,2,2,0,0,0,0,0,0,0,0
0,0,0,0,0,0,0,2,0,0,0,0,0,2,0,0,0,0,0,0,0
0,0,0,0,0,0,2,0,0,0,0,0,0,0,2,0,0,0,0,0,0
0,0,0,0,0,0,2,0,0,0,0,0,0,0,2,0,0,0,0,0,0
0,0,0,0,0,17,2,0,0,0,0,0,0,0,2,17,0,0,0,0,0
0,0,0,0,0,0,2,0,0,0,0,0,0,0,2,0,0,0,0,0,0
0,0,0,0,0,0,2,0,0,0,0,0,0,0,2,0,0,0,0,0,0
0,0,0,0,0,0,0,2,0,0,0,24,0,2,0,0,0,0,0,0,0
0,0,0,0,0,0,0,0,2,2,2,2,2,0,0,0,0,0,0,0,0
0,0,0,0,0,0,0,0,0,0,17,0,0,0,0,0,0,0,0,0,0
0,0,0,0,0,0,0,0,0,0,0,0,0,0,0,0,0,0,0,0,0
0,0,0,0,0,0,0,0,0,0,0,0,0,0,0,0,0,0,0,0,0
0,0,0,0,0,0,0,0,0,0,0,0,0,0,0,0,0,0,0,0,0
0,0,0,0,0,0,0,0,0,0,0,0,0,0,0,0,0,0,0,0,0
0,0,0,0,0,0,0,0,0,0,0,0,0,0,0,0,0,0,0,0,0
0,0,0,0,0,0,0,0,0,0,0,0,0,0,0,0,0,0,0,0,0
0,0,0,0,0,0,0,0,0,0,0,0,0,0,0,0,0,0,0,0,0
:endlayer
layer: 32
0,0,0,0,0,0,0,0,0,0,0,0,0,0,0,0,0,0,0,0,0
0,0,0,0,0,0,0,0,0,0,0,0,0,0,0,0,0,0,0,0,0
0,0,0,0,0,0,0,0,0,0,0,0,0,0,0,0,0,0,0,0,0
0,0,0,0,0,0,0,0,0,0,0,0,0,0,0,0,0,0,0,0,0
0,0,0,0,0,0,0,0,0,0,0,0,0,0,0,0,0,0,0,0,0
0,0,0,0,0,0,0,0,0,0,45,0,0,0,0,0,0,0,0,0,0
0,0,0,0,0,0,0,0,2,2,2,2,2,0,0,0,0,0,0,0,0
0,0,0,0,0,0,0,2,17,17,17,17,17,2,0,0,0,0,0,0,0
0,0,0,0,0,0,2,17,17,17,17,17,17,17,2,0,0,0,0,0,0
0,0,0,0,0,0,2,17,17,17,17,17,17,17,2,0,0,0,0,0,0
0,0,0,0,0,45,2,17,17,17,17,17,17,17,2,45,0,0,0,0,0
0,0,0,0,0,0,2,17,17,17,17,17,17,17,2,0,0,0,0,0,0
0,0,0,0,0,0,2,17,17,17,17,17,17,17,2,0,0,0,0,0,0
0,0,0,0,0,0,0,2,17,0,0,0,24,2,0,0,0,0,0,0,0
0,0,0,0,0,0,0,0,2,2,2,2,2,0,0,0,0,0,0,0,0
0,0,0,0,0,0,0,0,0,0,45,0,0,0,0,0,0,0,0,0,0
0,0,0,0,0,0,0,0,0,0,0,0,0,0,0,0,0,0,0,0,0
0,0,0,0,0,0,0,0,0,0,0,0,0,0,0,0,0,0,0,0,0
0,0,0,0,0,0,0,0,0,0,0,0,0,0,0,0,0,0,0,0,0
0,0,0,0,0,0,0,0,0,0,0,0,0,0,0,0,0,0,0,0,0
0,0,0,0,0,0,0,0,0,0,0,0,0,0,0,0,0,0,0,0,0
0,0,0,0,0,0,0,0,0,0,0,0,0,0,0,0,0,0,0,0,0
0,0,0,0,0,0,0,0,0,0,0,0,0,0,0,0,0,0,0,0,0
:endlayer
layer: 33
0,0,0,0,0,0,0,0,0,0,0,0,0,0,0,0,0,0,0,0,0
0,0,0,0,0,0,0,0,0,0,0,0,0,0,0,0,0,0,0,0,0
0,0,0,0,0,0,0,0,0,0,0,0,0,0,0,0,0,0,0,0,0
0,0,0,0,0,0,0,0,0,0,0,0,0,0,0,0,0,0,0,0,0
0,0,0,0,0,0,0,0,0,0,0,0,0,0,0,0,0,0,0,0,0
0,0,0,0,0,0,0,0,0,0,0,0,0,0,0,0,0,0,0,0,0
0,0,0,0,0,0,0,0,2,2,2,2,2,0,0,0,0,0,0,0,0
0,0,0,0,0,0,0,2,17,17,17,50,49,2,0,0,0,0,0,0,0
0,0,0,0,0,0,2,17,17,0,0,0,0,0,2,0,0,0,0,0,0
0,0,0,0,0,0,2,22,0,0,0,0,0,0,2,0,0,0,0,0,0
0,0,0,0,0,0,2,0,0,0,0,0,0,0,2,0,0,0,0,0,0
0,0,0,0,0,0,2,0,0,0,0,0,0,0,2,0,0,0,0,0,0
0,0,0,0,0,0,2,0,0,0,0,0,0,0,2,0,0,0,0,0,0
0,0,0,0,0,0,0,2,17,0,0,0,0,2,0,0,0,0,0,0,0
0,0,0,0,0,0,0,0,2,2,2,2,2,0,0,0,0,0,0,0,0
0,0,0,0,0,0,0,0,0,0,0,0,0,0,0,0,0,0,0,0,0
0,0,0,0,0,0,0,0,0,0,0,0,0,0,0,0,0,0,0,0,0
0,0,0,0,0,0,0,0,0,0,0,0,0,0,0,0,0,0,0,0,0
0,0,0,0,0,0,0,0,0,0,0,0,0,0,0,0,0,0,0,0,0
0,0,0,0,0,0,0,0,0,0,0,0,0,0,0,0,0,0,0,0,0
0,0,0,0,0,0,0,0,0,0,0,0,0,0,0,0,0,0,0,0,0
0,0,0,0,0,0,0,0,0,0,0,0,0,0,0,0,0,0,0,0,0
0,0,0,0,0,0,0,0,0,0,0,0,0,0,0,0,0,0,0,0,0
:endlayer
layer: 34
0,0,0,0,0,0,0,0,0,0,0,0,0,0,0,0,0,0,0,0,0
0,0,0,0,0,0,0,0,0,0,0,0,0,0,0,0,0,0,0,0,0
0,0,0,0,0,0,0,0,0,0,0,0,0,0,0,0,0,0,0,0,0
0,0,0,0,0,0,0,0,0,0,0,0,0,0,0,0,0,0,0,0,0
0,0,0,0,0,0,0,0,0,0,0,0,0,0,0,0,0,0,0,0,0
0,0,0,0,0,0,0,0,0,0,0,0,0,0,0,0,0,0,0,0,0
0,0,0,0,0,0,0,0,2,2,2,2,2,0,0,0,0,0,0,0,0
0,0,0,0,0,0,0,2,0,24,17,0,0,2,0,0,0,0,0,0,0
0,0,0,0,0,0,2,0,0,0,0,0,0,0,2,0,0,0,0,0,0
0,0,0,0,0,0,2,0,0,0,0,0,0,0,2,0,0,0,0,0,0
0,0,0,0,0,0,2,0,0,0,0,0,0,0,2,0,0,0,0,0,0
0,0,0,0,0,0,2,0,0,0,0,0,0,0,2,0,0,0,0,0,0
0,0,0,0,0,0,2,0,0,0,0,0,0,0,2,0,0,0,0,0,0
0,0,0,0,0,0,0,2,0,0,0,0,0,2,0,0,0,0,0,0,0
0,0,0,0,0,0,0,0,2,2,2,2,2,0,0,0,0,0,0,0,0
0,0,0,0,0,0,0,0,0,0,0,0,0,0,0,0,0,0,0,0,0
0,0,0,0,0,0,0,0,0,0,0,0,0,0,0,0,0,0,0,0,0
0,0,0,0,0,0,0,0,0,0,0,0,0,0,0,0,0,0,0,0,0
0,0,0,0,0,0,0,0,0,0,0,0,0,0,0,0,0,0,0,0,0
0,0,0,0,0,0,0,0,0,0,0,0,0,0,0,0,0,0,0,0,0
0,0,0,0,0,0,0,0,0,0,0,0,0,0,0,0,0,0,0,0,0
0,0,0,0,0,0,0,0,0,0,0,0,0,0,0,0,0,0,0,0,0
0,0,0,0,0,0,0,0,0,0,0,0,0,0,0,0,0,0,0,0,0
:endlayer
layer: 35
0,0,0,0,0,0,0,0,0,0,0,0,0,0,0,0,0,0,0,0,0
0,0,0,0,0,0,0,0,0,0,0,0,0,0,0,0,0,0,0,0,0
0,0,0,0,0,0,0,0,0,0,0,0,0,0,0,0,0,0,0,0,0
0,0,0,0,0,0,0,0,0,0,0,0,0,0,0,0,0,0,0,0,0
0,0,0,0,0,0,0,0,0,0,0,0,0,0,0,0,0,0,0,0,0
0,0,0,0,0,0,0,0,0,0,0,0,0,0,0,0,0,0,0,0,0
0,0,0,0,0,0,0,0,2,2,2,2,2,0,0,0,0,0,0,0,0
0,0,0,0,0,0,0,2,0,0,24,17,17,2,0,0,0,0,0,0,0
0,0,0,0,0,0,2,0,0,0,0,0,0,0,2,0,0,0,0,0,0
0,0,0,0,0,0,2,0,0,0,0,0,0,0,2,0,0,0,0,0,0
0,0,0,0,0,0,2,36,0,0,0,0,0,21,2,0,0,0,0,0,0
0,0,0,0,0,0,2,0,0,0,0,0,0,0,2,0,0,0,0,0,0
0,0,0,0,0,0,2,0,0,0,0,0,0,0,2,0,0,0,0,0,0
0,0,0,0,0,0,0,2,0,0,0,0,0,2,0,0,0,0,0,0,0
0,0,0,0,0,0,0,0,2,2,2,2,2,0,0,0,0,0,0,0,0
0,0,0,0,0,0,0,0,0,0,0,0,0,0,0,0,0,0,0,0,0
0,0,0,0,0,0,0,0,0,0,0,0,0,0,0,0,0,0,0,0,0
0,0,0,0,0,0,0,0,0,0,0,0,0,0,0,0,0,0,0,0,0
0,0,0,0,0,0,0,0,0,0,0,0,0,0,0,0,0,0,0,0,0
0,0,0,0,0,0,0,0,0,0,0,0,0,0,0,0,0,0,0,0,0
0,0,0,0,0,0,0,0,0,0,0,0,0,0,0,0,0,0,0,0,0
0,0,0,0,0,0,0,0,0,0,0,0,0,0,0,0,0,0,0,0,0
0,0,0,0,0,0,0,0,0,0,0,0,0,0,0,0,0,0,0,0,0
:endlayer
layer: 36
0,0,0,0,0,0,0,0,0,0,0,0,0,0,0,0,0,0,0,0,0
0,0,0,0,0,0,0,0,0,0,0,0,0,0,0,0,0,0,0,0,0
0,0,0,0,0,0,0,0,0,0,0,0,0,0,0,0,0,0,0,0,0
0,0,0,0,0,0,0,0,0,0,0,0,0,0,0,0,0,0,0,0,0
0,0,0,0,0,0,0,0,0,0,0,0,0,0,0,0,0,0,0,0,0
0,0,0,0,0,0,0,0,0,0,0,0,0,0,0,0,0,0,0,0,0
0,0,0,0,0,0,0,0,2,2,2,2,2,0,0,0,0,0,0,0,0
0,0,0,0,0,0,0,2,0,0,0,24,17,2,0,0,0,0,0,0,0
0,0,0,0,0,0,2,0,0,0,0,0,17,17,2,0,0,0,0,0,0
0,0,0,0,0,0,2,0,0,0,0,0,17,17,2,0,0,0,0,0,0
0,0,0,0,0,0,2,0,0,0,0,0,0,0,2,0,0,0,0,0,0
0,0,0,0,0,0,2,0,0,0,0,0,0,0,2,0,0,0,0,0,0
0,0,0,0,0,0,2,0,0,0,0,0,0,0,2,0,0,0,0,0,0
0,0,0,0,0,0,0,2,0,0,23,0,0,2,0,0,0,0,0,0,0
0,0,0,0,0,0,0,0,2,2,2,2,2,0,0,0,0,0,0,0,0
0,0,0,0,0,0,0,0,0,0,0,0,0,0,0,0,0,0,0,0,0
0,0,0,0,0,0,0,0,0,0,0,0,0,0,0,0,0,0,0,0,0
0,0,0,0,0,0,0,0,0,0,0,0,0,0,0,0,0,0,0,0,0
0,0,0,0,0,0,0,0,0,0,0,0,0,0,0,0,0,0,0,0,0
0,0,0,0,0,0,0,0,0,0,0,0,0,0,0,0,0,0,0,0,0
0,0,0,0,0,0,0,0,0,0,0,0,0,0,0,0,0,0,0,0,0
0,0,0,0,0,0,0,0,0,0,0,0,0,0,0,0,0,0,0,0,0
0,0,0,0,0,0,0,0,0,0,0,0,0,0,0,0,0,0,0,0,0
:endlayer
layer: 37
0,0,0,0,0,0,0,0,0,0,0,0,0,0,0,0,0,0,0,0,0
0,0,0,0,0,0,0,0,0,0,0,0,0,0,0,0,0,0,0,0,0
0,0,0,0,0,0,0,0,0,0,0,0,0,0,0,0,0,0,0,0,0
0,0,0,0,0,0,0,0,0,0,0,0,0,0,0,0,0,0,0,0,0
0,0,0,0,0,0,0,0,0,0,0,0,0,0,0,0,0,0,0,0,0
0,0,0,0,0,0,0,0,0,0,0,0,0,0,0,0,0,0,0,0,0
0,0,0,0,0,0,0,0,2,2,2,2,2,0,0,0,0,0,0,0,0
0,0,0,0,0,0,0,2,0,0,0,0,0,2,0,0,0,0,0,0,0
0,0,0,0,0,0,2,0,0,0,0,0,0,0,2,0,0,0,0,0,0
0,0,0,0,0,0,2,0,0,0,0,0,17,25,2,0,0,0,0,0,0
0,0,0,0,0,0,2,0,0,0,0,0,17,17,2,0,0,0,0,0,0
0,0,0,0,0,0,2,17,17,17,17,17,17,17,2,0,0,0,0,0,0
0,0,0,0,0,0,2,17,17,17,17,17,17,17,2,0,0,0,0,0,0
0,0,0,0,0,0,0,2,17,17,17,17,17,2,0,0,0,0,0,0,0
0,0,0,0,0,0,0,0,2,2,2,2,2,0,0,0,0,0,0,0,0
0,0,0,0,0,0,0,0,0,0,0,0,0,0,0,0,0,0,0,0,0
0,0,0,0,0,0,0,0,0,0,0,0,0,0,0,0,0,0,0,0,0
0,0,0,0,0,0,0,0,0,0,0,0,0,0,0,0,0,0,0,0,0
0,0,0,0,0,0,0,0,0,0,0,0,0,0,0,0,0,0,0,0,0
0,0,0,0,0,0,0,0,0,0,0,0,0,0,0,0,0,0,0,0,0
0,0,0,0,0,0,0,0,0,0,0,0,0,0,0,0,0,0,0,0,0
0,0,0,0,0,0,0,0,0,0,0,0,0,0,0,0,0,0,0,0,0
0,0,0,0,0,0,0,0,0,0,0,0,0,0,0,0,0,0,0,0,0
:endlayer
layer: 38
0,0,0,0,0,0,0,0,0,0,0,0,0,0,0,0,0,0,0,0,0
0,0,0,0,0,0,0,0,0,0,0,0,0,0,0,0,0,0,0,0,0
0,0,0,0,0,0,0,0,0,0,0,0,0,0,0,0,0,0,0,0,0
0,0,0,0,0,0,0,0,0,0,0,0,0,0,0,0,0,0,0,0,0
0,0,0,0,0,0,0,0,0,0,0,0,0,0,0,0,0,0,0,0,0
0,0,0,0,0,0,0,0,0,0,0,0,0,0,0,0,0,0,0,0,0
0,0,0,0,0,0,0,0,2,2,2,2,2,0,0,0,0,0,0,0,0
0,0,0,0,0,0,0,2,0,0,0,0,0,2,0,0,0,0,0,0,0
0,0,0,0,0,0,2,0,0,0,0,0,0,0,2,0,0,0,0,0,0
0,0,0,0,0,0,2,0,0,0,0,0,43,0,2,0,0,0,0,0,0
0,0,0,0,0,0,2,0,0,0,0,0,43,0,2,0,0,0,0,0,0
0,0,0,0,0,0,2,43,43,43,43,43,43,0,2,0,0,0,0,0,0
0,0,0,0,0,0,2,0,0,0,0,0,0,0,2,0,0,0,0,0,0
0,0,0,0,0,0,0,2,51,2,17,5,0,2,0,0,0,0,0,0,0
0,0,0,0,0,0,0,0,2,2,2,2,2,0,0,0,0,0,0,0,0
0,0,0,0,0,0,0,0,0,0,0,0,0,0,0,0,0,0,0,0,0
0,0,0,0,0,0,0,0,0,0,0,0,0,0,0,0,0,0,0,0,0
0,0,0,0,0,0,0,0,0,0,0,0,0,0,0,0,0,0,0,0,0
0,0,0,0,0,0,0,0,0,0,0,0,0,0,0,0,0,0,0,0,0
0,0,0,0,0,0,0,0,0,0,0,0,0,0,0,0,0,0,0,0,0
0,0,0,0,0,0,0,0,0,0,0,0,0,0,0,0,0,0,0,0,0
0,0,0,0,0,0,0,0,0,0,0,0,0,0,0,0,0,0,0,0,0
0,0,0,0,0,0,0,0,0,0,0,0,0,0,0,0,0,0,0,0,0
:endlayer
layer: 39
0,0,0,0,0,0,0,0,0,0,0,0,0,0,0,0,0,0,0,0,0
0,0,0,0,0,0,0,0,0,0,0,0,0,0,0,0,0,0,0,0,0
0,0,0,0,0,0,0,0,0,0,0,0,0,0,0,0,0,0,0,0,0
0,0,0,0,0,0,0,0,0,0,0,0,0,0,0,0,0,0,0,0,0
0,0,0,0,0,0,0,0,0,0,0,0,0,0,0,0,0,0,0,0,0
0,0,0,0,0,0,0,0,0,0,0,0,0,0,0,0,0,0,0,0,0
0,0,0,0,0,0,0,0,2,2,2,2,2,0,0,0,0,0,0,0,0
0,0,0,0,0,0,0,2,0,0,0,0,0,2,0,0,0,0,0,0,0
0,0,0,0,0,0,2,0,0,0,0,0,0,0,2,0,0,0,0,0,0
0,0,0,0,0,0,2,36,0,0,0,0,45,0,2,0,0,0,0,0,0
0,0,0,0,0,0,2,0,0,0,0,0,0,0,2,0,0,0,0,0,0
0,0,0,0,0,0,2,0,0,0,0,0,0,0,2,0,0,0,0,0,0
0,0,0,0,0,0,2,0,0,0,0,0,0,0,2,0,0,0,0,0,0
0,0,0,0,0,0,0,2,0,17,5,0,0,2,0,0,0,0,0,0,0
0,0,0,0,0,0,0,0,2,2,2,2,2,0,0,0,0,0,0,0,0
0,0,0,0,0,0,0,0,0,0,0,0,0,0,0,0,0,0,0,0,0
0,0,0,0,0,0,0,0,0,0,0,0,0,0,0,0,0,0,0,0,0
0,0,0,0,0,0,0,0,0,0,0,0,0,0,0,0,0,0,0,0,0
0,0,0,0,0,0,0,0,0,0,0,0,0,0,0,0,0,0,0,0,0
0,0,0,0,0,0,0,0,0,0,0,0,0,0,0,0,0,0,0,0,0
0,0,0,0,0,0,0,0,0,0,0,0,0,0,0,0,0,0,0,0,0
0,0,0,0,0,0,0,0,0,0,0,0,0,0,0,0,0,0,0,0,0
0,0,0,0,0,0,0,0,0,0,0,0,0,0,0,0,0,0,0,0,0
:endlayer
layer: 40
0,0,0,0,0,0,0,0,0,0,0,0,0,0,0,0,0,0,0,0,0
0,0,0,0,0,0,0,0,0,0,0,0,0,0,0,0,0,0,0,0,0
0,0,0,0,0,0,0,0,0,0,0,0,0,0,0,0,0,0,0,0,0
0,0,0,0,0,0,0,0,0,0,0,0,0,0,0,0,0,0,0,0,0
0,0,0,0,0,0,0,0,0,0,0,0,0,0,0,0,0,0,0,0,0
0,0,0,0,0,0,0,0,17,17,17,17,17,0,0,0,0,0,0,0,0
0,0,0,0,0,0,0,17,17,17,17,17,17,17,0,0,0,0,0,0,0
0,0,0,0,0,0,17,17,0,0,0,0,0,17,17,0,0,0,0,0,0
0,0,0,0,0,17,17,0,0,0,0,0,0,0,17,17,0,0,0,0,0
0,0,0,0,0,17,17,0,0,0,0,0,0,0,17,17,0,0,0,0,0
0,0,0,0,0,17,17,0,0,0,0,0,0,0,17,17,0,0,0,0,0
0,0,0,0,0,17,17,0,0,0,0,0,0,0,17,17,0,0,0,0,0
0,0,0,0,0,17,17,0,0,0,0,0,0,0,17,17,0,0,0,0,0
0,0,0,0,0,0,17,17,17,5,0,0,0,17,17,0,0,0,0,0,0
0,0,0,0,0,0,0,17,17,17,17,17,17,17,0,0,0,0,0,0,0
0,0,0,0,0,0,0,0,17,17,17,17,17,0,0,0,0,0,0,0,0
0,0,0,0,0,0,0,0,0,0,0,0,0,0,0,0,0,0,0,0,0
0,0,0,0,0,0,0,0,0,0,0,0,0,0,0,0,0,0,0,0,0
0,0,0,0,0,0,0,0,0,0,0,0,0,0,0,0,0,0,0,0,0
0,0,0,0,0,0,0,0,0,0,0,0,0,0,0,0,0,0,0,0,0
0,0,0,0,0,0,0,0,0,0,0,0,0,0,0,0,0,0,0,0,0
0,0,0,0,0,0,0,0,0,0,0,0,0,0,0,0,0,0,0,0,0
0,0,0,0,0,0,0,0,0,0,0,0,0,0,0,0,0,0,0,0,0
:endlayer
layer: 41
0,0,0,0,0,0,0,0,0,0,0,0,0,0,0,0,0,0,0,0,0
0,0,0,0,0,0,0,0,0,0,0,0,0,0,0,0,0,0,0,0,0
0,0,0,0,0,0,0,0,0,0,0,0,0,0,0,0,0,0,0,0,0
0,0,0,0,0,0,0,0,0,0,17,0,0,0,0,0,0,0,0,0,0
0,0,0,0,0,0,0,0,17,17,17,17,17,0,0,0,0,0,0,0,0
0,0,0,0,0,0,17,17,17,17,17,17,17,17,17,0,0,0,0,0,0
0,0,0,0,0,17,17,17,17,17,17,17,17,17,17,17,0,0,0,0,0
0,0,0,0,0,17,17,17,17,17,17,17,17,17,17,17,0,0,0,0,0
0,0,0,0,17,17,17,17,17,17,17,17,17,17,17,17,17,0,0,0,0
0,0,0,0,17,17,17,17,17,17,17,17,17,17,17,17,17,0,0,0,0
0,0,0,17,17,17,17,17,17,17,17,17,17,17,17,17,17,17,0,0,0
0,0,0,0,17,17,17,17,17,17,17,17,17,17,17,17,17,0,0,0,0
0,0,0,0,17,17,17,17,17,17,17,17,17,17,17,17,17,0,0,0,0
0,0,0,0,0,17,17,5,0,0,0,0,17,17,17,17,0,0,0,0,0
0,0,0,0,0,17,17,17,17,17,17,17,17,17,17,17,0,0,0,0,0
0,0,0,0,0,0,17,17,17,17,17,17,17,17,17,0,0,0,0,0,0
0,0,0,0,0,0,0,0,17,17,17,17,17,0,0,0,0,0,0,0,0
0,0,0,0,0,0,0,0,0,0,17,0,0,0,0,0,0,0,0,0,0
0,0,0,0,0,0,0,0,0,0,0,0,0,0,0,0,0,0,0,0,0
0,0,0,0,0,0,0,0,0,0,0,0,0,0,0,0,0,0,0,0,0
0,0,0,0,0,0,0,0,0,0,0,0,0,0,0,0,0,0,0,0,0
0,0,0,0,0,0,0,0,0,0,0,0,0,0,0,0,0,0,0,0,0
0,0,0,0,0,0,0,0,0,0,0,0,0,0,0,0,0,0,0,0,0
:endlayer
layer: 42
0,0,0,0,0,0,0,0,0,0,0,0,0,0,0,0,0,0,0,0,0
0,0,0,0,0,0,0,0,0,0,0,0,0,0,0,0,0,0,0,0,0
0,0,0,0,0,0,0,0,0,0,0,0,0,0,0,0,0,0,0,0,0
0,0,0,0,0,0,0,0,2,2,2,2,2,0,0,0,0,0,0,0,0
0,0,0,0,0,0,2,2,0,0,0,0,0,2,2,0,0,0,0,0,0
0,0,0,0,0,2,0,0,0,0,0,0,0,0,0,2,0,0,0,0,0
0,0,0,0,2,0,0,0,0,0,0,0,0,0,0,0,2,0,0,0,0
0,0,0,0,2,0,0,0,0,0,0,0,0,0,0,0,2,0,0,0,0
0,0,0,2,0,0,0,0,0,0,0,0,0,0,0,0,0,2,0,0,0
0,0,0,2,0,0,0,0,0,0,0,0,0,0,0,0,0,2,0,0,0
0,0,0,2,0,0,0,0,0,0,0,0,0,0,0,0,0,2,0,0,0
0,0,0,2,0,0,0,0,0,0,0,0,0,0,0,0,0,2,0,0,0
0,0,0,2,0,0,0,0,43,43,43,43,43,0,0,0,0,2,0,0,0
0,0,0,0,2,0,0,0,0,0,0,0,43,0,0,0,2,0,0,0,0
0,0,0,0,2,0,0,0,43,43,43,43,43,0,0,0,2,0,0,0,0
0,0,0,0,0,2,0,0,0,0,0,0,0,0,0,2,0,0,0,0,0
0,0,0,0,0,0,2,2,0,0,0,0,0,2,2,0,0,0,0,0,0
0,0,0,0,0,0,0,0,2,2,2,2,2,0,0,0,0,0,0,0,0
0,0,0,0,0,0,0,0,0,0,0,0,0,0,0,0,0,0,0,0,0
0,0,0,0,0,0,0,0,0,0,0,0,0,0,0,0,0,0,0,0,0
0,0,0,0,0,0,0,0,0,0,0,0,0,0,0,0,0,0,0,0,0
0,0,0,0,0,0,0,0,0,0,0,0,0,0,0,0,0,0,0,0,0
0,0,0,0,0,0,0,0,0,0,0,0,0,0,0,0,0,0,0,0,0
:endlayer
layer: 43
0,0,0,0,0,0,0,0,0,0,0,0,0,0,0,0,0,0,0,0,0
0,0,0,0,0,0,0,0,0,0,0,0,0,0,0,0,0,0,0,0,0
0,0,0,0,0,0,0,0,0,23,0,23,0,0,0,0,0,0,0,0,0
0,0,0,0,0,0,0,0,2,17,48,17,2,0,0,0,0,0,0,0,0
0,0,0,0,0,0,2,2,0,0,0,0,0,2,2,0,0,0,0,0,0
0,0,0,0,0,2,0,0,0,0,0,0,0,0,0,2,0,0,0,0,0
0,0,0,0,2,0,0,0,0,0,0,0,0,0,0,0,2,0,0,0,0
0,0,0,0,2,0,0,0,0,0,0,0,0,0,0,0,2,0,0,0,0
0,0,0,2,0,0,0,0,0,0,0,0,0,0,0,0,0,2,0,0,0
0,0,21,17,0,0,0,0,0,0,0,0,0,0,0,0,0,17,36,0,0
0,0,0,48,0,0,0,0,0,0,0,0,0,0,0,0,0,48,0,0,0
0,0,21,17,0,0,0,0,0,0,0,0,0,0,0,0,0,17,36,0,0
0,0,0,2,0,0,0,0,0,0,0,0,0,0,0,0,0,2,0,0,0
0,0,0,0,2,0,0,0,0,0,0,0,0,0,0,0,2,0,0,0,0
0,0,0,0,2,0,0,0,0,0,0,0,0,0,0,0,2,0,0,0,0
0,0,0,0,0,2,0,0,0,0,0,0,0,0,0,2,0,0,0,0,0
0,0,0,0,0,0,2,2,0,0,0,0,0,2,2,0,0,0,0,0,0
0,0,0,0,0,0,0,0,2,17,48,17,2,0,0,0,0,0,0,0,0
0,0,0,0,0,0,0,0,0,35,0,35,0,0,0,0,0,0,0,0,0
0,0,0,0,0,0,0,0,0,0,0,0,0,0,0,0,0,0,0,0,0
0,0,0,0,0,0,0,0,0,0,0,0,0,0,0,0,0,0,0,0,0
0,0,0,0,0,0,0,0,0,0,0,0,0,0,0,0,0,0,0,0,0
0,0,0,0,0,0,0,0,0,0,0,0,0,0,0,0,0,0,0,0,0
:endlayer
layer: 44
0,0,0,0,0,0,0,0,0,0,0,0,0,0,0,0,0,0,0,0,0
0,0,0,0,0,0,0,0,0,0,0,0,0,0,0,0,0,0,0,0,0
0,0,0,0,0,0,0,0,0,0,0,0,0,0,0,0,0,0,0,0,0
0,0,0,0,0,0,0,0,2,17,48,17,2,0,0,0,0,0,0,0,0
0,0,0,0,0,0,2,2,0,0,0,0,0,2,2,0,0,0,0,0,0
0,0,0,0,0,32,0,0,0,0,0,0,0,0,0,32,0,0,0,0,0
0,0,0,0,2,0,0,0,0,0,0,0,0,0,0,0,2,0,0,0,0
0,0,0,0,2,0,0,0,0,0,0,0,0,0,0,0,2,0,0,0,0
0,0,0,2,0,0,0,0,0,0,0,0,0,0,0,0,0,2,0,0,0
0,0,0,17,0,0,0,0,0,0,0,0,0,0,0,0,0,17,0,0,0
0,0,0,48,0,0,0,0,0,0,0,0,0,0,0,0,0,48,0,0,0
0,0,0,17,0,0,0,0,0,0,0,0,0,0,0,0,0,17,0,0,0
0,0,0,2,0,0,0,0,0,0,0,0,0,0,0,0,0,2,0,0,0
0,0,0,0,2,0,0,0,0,0,0,0,0,0,0,0,2,0,0,0,0
0,0,0,0,2,0,0,0,0,0,0,0,0,0,0,0,2,0,0,0,0
0,0,0,0,0,32,0,0,0,0,0,0,0,0,0,32,0,0,0,0,0
0,0,0,0,0,0,2,2,0,0,0,0,0,2,2,0,0,0,0,0,0
0,0,0,0,0,0,0,0,2,17,48,17,2,0,0,0,0,0,0,0,0
0,0,0,0,0,0,0,0,0,0,0,0,0,0,0,0,0,0,0,0,0
0,0,0,0,0,0,0,0,0,0,0,0,0,0,0,0,0,0,0,0,0
0,0,0,0,0,0,0,0,0,0,0,0,0,0,0,0,0,0,0,0,0
0,0,0,0,0,0,0,0,0,0,0,0,0,0,0,0,0,0,0,0,0
0,0,0,0,0,0,0,0,0,0,0,0,0,0,0,0,0,0,0,0,0
:endlayer
layer: 45
0,0,0,0,0,0,0,0,0,0,0,0,0,0,0,0,0,0,0,0,0
0,0,0,0,0,0,0,0,0,0,0,0,0,0,0,0,0,0,0,0,0
0,0,0,0,0,0,0,0,0,0,0,0,0,0,0,0,0,0,0,0,0
0,0,0,0,0,0,0,0,2,17,48,17,2,0,0,0,0,0,0,0,0
0,0,0,0,0,0,2,2,0,0,0,0,0,2,2,0,0,0,0,0,0
0,0,0,0,0,32,0,0,0,0,0,0,0,0,0,32,0,0,0,0,0
0,0,0,0,2,0,0,0,0,0,0,0,0,0,0,0,2,0,0,0,0
0,0,0,0,2,0,0,0,0,0,0,0,0,0,0,0,2,0,0,0,0
0,0,0,2,0,0,0,0,0,0,0,0,0,0,0,0,0,2,0,0,0
0,0,0,17,0,0,0,0,0,0,0,0,0,0,0,0,0,17,0,0,0
0,0,0,48,0,0,0,0,0,0,0,0,0,0,0,0,0,48,0,0,0
0,0,0,17,0,0,0,0,0,0,0,0,0,0,0,0,0,17,0,0,0
0,0,0,2,0,0,0,0,0,0,0,0,0,0,0,0,0,2,0,0,0
0,0,0,0,2,0,0,0,0,0,0,0,0,0,0,0,2,0,0,0,0
0,0,0,0,2,0,0,0,0,0,0,0,0,0,0,0,2,0,0,0,0
0,0,0,0,0,32,0,0,0,0,0,0,0,0,0,32,0,0,0,0,0
0,0,0,0,0,0,2,2,0,0,0,0,0,2,2,0,0,0,0,0,0
0,0,0,0,0,0,0,0,2,17,48,17,2,0,0,0,0,0,0,0,0
0,0,0,0,0,0,0,0,0,0,0,0,0,0,0,0,0,0,0,0,0
0,0,0,0,0,0,0,0,0,0,0,0,0,0,0,0,0,0,0,0,0
0,0,0,0,0,0,0,0,0,0,0,0,0,0,0,0,0,0,0,0,0
0,0,0,0,0,0,0,0,0,0,0,0,0,0,0,0,0,0,0,0,0
0,0,0,0,0,0,0,0,0,0,0,0,0,0,0,0,0,0,0,0,0
:endlayer
layer: 46
0,0,0,0,0,0,0,0,0,0,0,0,0,0,0,0,0,0,0,0,0
0,0,0,0,0,0,0,0,0,0,0,0,0,0,0,0,0,0,0,0,0
0,0,0,0,0,0,0,0,0,0,25,0,0,0,0,0,0,0,0,0,0
0,0,0,0,0,0,0,0,2,2,2,2,2,0,0,0,0,0,0,0,0
0,0,0,0,0,0,2,2,0,0,35,0,0,2,2,0,0,0,0,0,0
0,0,0,0,0,2,0,0,0,0,0,0,0,0,0,2,0,0,0,0,0
0,0,0,0,2,0,0,0,0,0,0,0,0,0,0,0,2,0,0,0,0
0,0,0,0,2,0,0,0,0,0,0,0,0,0,0,0,2,0,0,0,0
0,0,0,2,0,0,0,0,0,0,0,0,0,0,0,0,0,2,0,0,0
0,0,0,2,0,0,0,0,0,0,0,0,0,0,0,0,0,2,0,0,0
0,0,24,2,36,0,0,0,0,0,0,0,0,0,0,0,21,2,5,0,0
0,0,0,2,0,0,0,0,0,0,0,0,0,0,0,0,0,2,0,0,0
0,0,0,2,0,0,0,0,0,0,0,0,0,0,0,0,0,2,0,0,0
0,0,0,0,2,0,0,0,0,0,0,0,0,0,0,0,2,0,0,0,0
0,0,0,0,2,0,0,0,0,0,0,0,0,0,0,0,2,0,0,0,0
0,0,0,0,0,2,0,0,0,0,0,0,0,0,0,2,0,0,0,0,0
0,0,0,0,0,0,2,2,0,0,23,0,0,2,2,0,0,0,0,0,0
0,0,0,0,0,0,0,0,2,2,2,2,2,0,0,0,0,0,0,0,0
0,0,0,0,0,0,0,0,0,0,22,0,0,0,0,0,0,0,0,0,0
0,0,0,0,0,0,0,0,0,0,0,0,0,0,0,0,0,0,0,0,0
0,0,0,0,0,0,0,0,0,0,0,0,0,0,0,0,0,0,0,0,0
0,0,0,0,0,0,0,0,0,0,0,0,0,0,0,0,0,0,0,0,0
0,0,0,0,0,0,0,0,0,0,0,0,0,0,0,0,0,0,0,0,0
:endlayer
layer: 47
0,0,0,0,0,0,0,0,0,0,0,0,0,0,0,0,0,0,0,0,0
0,0,0,0,0,0,0,0,0,0,0,0,0,0,0,0,0,0,0,0,0
0,0,0,0,0,0,0,0,17,17,17,17,17,0,0,0,0,0,0,0,0
0,0,0,0,0,0,17,17,17,17,17,17,17,17,17,0,0,0,0,0,0
0,0,0,0,17,17,17,17,0,0,0,0,0,17,17,17,17,0,0,0,0
0,0,0,0,17,17,0,0,0,0,0,0,0,0,0,17,17,0,0,0,0
0,0,0,17,17,0,0,0,0,0,0,0,0,0,0,0,17,17,0,0,0
0,0,0,17,17,0,0,0,0,0,0,0,0,0,0,0,17,17,0,0,0
0,0,17,17,0,0,0,0,0,0,0,0,0,0,0,0,0,17,17,0,0
0,0,17,17,0,0,0,0,0,0,0,0,0,0,0,0,0,17,17,0,0
0,0,17,17,0,0,0,0,0,0,0,0,0,0,0,0,0,17,17,0,0
0,0,17,17,0,0,0,0,0,0,0,0,0,0,0,0,0,17,17,0,0
0,0,17,17,0,0,0,0,0,0,0,0,0,0,0,0,0,17,17,0,0
0,0,0,17,17,0,0,0,0,0,0,0,0,0,0,0,17,17,0,0,0
0,0,0,17,17,0,0,0,0,0,0,0,0,0,0,0,17,17,0,0,0
0,0,0,0,17,17,0,0,0,0,0,0,0,0,0,17,17,0,0,0,0
0,0,0,0,17,17,17,17,0,0,0,0,0,17,17,17,17,0,0,0,0
0,0,0,0,0,0,17,17,17,17,17,17,17,17,17,0,0,0,0,0,0
0,0,0,0,0,0,0,0,17,17,17,17,17,0,0,0,0,0,0,0,0
0,0,0,0,0,0,0,0,0,0,0,0,0,0,0,0,0,0,0,0,0
0,0,0,0,0,0,0,0,0,0,0,0,0,0,0,0,0,0,0,0,0
0,0,0,0,0,0,0,0,0,0,0,0,0,0,0,0,0,0,0,0,0
0,0,0,0,0,0,0,0,0,0,0,0,0,0,0,0,0,0,0,0,0
:endlayer
layer: 48
0,0,0,0,0,0,0,0,0,0,0,0,0,0,0,0,0,0,0,0,0
0,0,0,0,0,0,0,0,0,0,0,0,0,0,0,0,0,0,0,0,0
0,0,0,0,0,0,0,0,0,0,0,0,0,0,0,0,0,0,0,0,0
0,0,0,0,0,0,0,0,17,17,17,17,17,0,0,0,0,0,0,0,0
0,0,0,0,0,0,17,17,0,0,0,0,0,17,17,0,0,0,0,0,0
0,0,0,0,0,17,0,0,0,0,0,0,0,0,0,17,0,0,0,0,0
0,0,0,0,17,0,0,0,0,0,0,0,0,0,0,0,17,0,0,0,0
0,0,0,0,17,0,0,0,0,0,0,0,0,0,0,0,17,0,0,0,0
0,0,0,17,0,0,0,0,0,0,43,0,0,0,0,0,0,17,0,0,0
0,0,0,17,0,0,0,0,0,0,43,0,0,0,0,0,0,17,0,0,0
0,0,0,17,0,0,0,0,43,43,43,43,43,0,0,0,0,17,0,0,0
0,0,0,17,0,0,0,0,0,0,43,0,0,0,0,0,0,17,0,0,0
0,0,0,17,0,0,0,0,0,0,43,0,0,0,0,0,0,17,0,0,0
0,0,0,0,17,0,0,0,0,0,0,0,0,0,0,0,17,0,0,0,0
0,0,0,0,17,0,0,0,0,0,0,0,0,0,0,0,17,0,0,0,0
0,0,0,0,0,17,0,0,0,0,0,0,0,0,0,17,0,0,0,0,0
0,0,0,0,0,0,17,17,0,0,0,0,0,17,17,0,0,0,0,0,0
0,0,0,0,0,0,0,0,17,17,17,17,17,0,0,0,0,0,0,0,0
0,0,0,0,0,0,0,0,0,0,0,0,0,0,0,0,0,0,0,0,0
0,0,0,0,0,0,0,0,0,0,0,0,0,0,0,0,0,0,0,0,0
0,0,0,0,0,0,0,0,0,0,0,0,0,0,0,0,0,0,0,0,0
0,0,0,0,0,0,0,0,0,0,0,0,0,0,0,0,0,0,0,0,0
0,0,0,0,0,0,0,0,0,0,0,0,0,0,0,0,0,0,0,0,0
:endlayer
layer: 49
0,0,0,0,0,0,0,0,0,0,0,0,0,0,0,0,0,0,0,0,0
0,0,0,0,0,0,0,0,0,0,0,0,0,0,0,0,0,0,0,0,0
0,0,0,0,0,0,0,0,0,0,0,0,0,0,0,0,0,0,0,0,0
0,0,0,0,0,0,0,0,0,0,0,0,0,0,0,0,0,0,0,0,0
0,0,0,0,0,0,0,0,17,17,17,17,17,0,0,0,0,0,0,0,0
0,0,0,0,0,0,17,17,0,0,0,0,0,17,17,0,0,0,0,0,0
0,0,0,0,0,17,0,0,0,0,0,0,0,0,0,17,0,0,0,0,0
0,0,0,0,0,17,0,0,0,0,0,0,0,0,0,17,0,0,0,0,0
0,0,0,0,17,0,0,0,0,0,45,0,0,0,0,0,17,0,0,0,0
0,0,0,0,17,0,0,0,0,0,0,0,0,0,0,0,17,0,0,0,0
0,0,0,0,17,0,0,0,45,0,43,0,45,0,0,0,17,0,0,0,0
0,0,0,0,17,0,0,0,0,0,0,0,0,0,0,0,17,0,0,0,0
0,0,0,0,17,0,0,0,0,0,45,0,0,0,0,0,17,0,0,0,0
0,0,0,0,0,17,0,0,0,0,0,0,0,0,0,17,0,0,0,0,0
0,0,0,0,0,17,0,0,0,0,0,0,0,0,0,17,0,0,0,0,0
0,0,0,0,0,0,17,17,0,0,0,0,0,17,17,0,0,0,0,0,0
0,0,0,0,0,0,0,0,17,17,17,17,17,0,0,0,0,0,0,0,0
0,0,0,0,0,0,0,0,0,0,0,0,0,0,0,0,0,0,0,0,0
0,0,0,0,0,0,0,0,0,0,0,0,0,0,0,0,0,0,0,0,0
0,0,0,0,0,0,0,0,0,0,0,0,0,0,0,0,0,0,0,0,0
0,0,0,0,0,0,0,0,0,0,0,0,0,0,0,0,0,0,0,0,0
0,0,0,0,0,0,0,0,0,0,0,0,0,0,0,0,0,0,0,0,0
0,0,0,0,0,0,0,0,0,0,0,0,0,0,0,0,0,0,0,0,0
:endlayer
layer: 50
0,0,0,0,0,0,0,0,0,0,0,0,0,0,0,0,0,0,0,0,0
0,0,0,0,0,0,0,0,0,0,0,0,0,0,0,0,0,0,0,0,0
0,0,0,0,0,0,0,0,0,0,0,0,0,0,0,0,0,0,0,0,0
0,0,0,0,0,0,0,0,0,0,0,0,0,0,0,0,0,0,0,0,0
0,0,0,0,0,0,0,0,0,0,0,0,0,0,0,0,0,0,0,0,0
0,0,0,0,0,0,0,0,17,17,17,17,17,0,0,0,0,0,0,0,0
0,0,0,0,0,0,17,17,0,0,0,0,0,17,17,0,0,0,0,0,0
0,0,0,0,0,0,17,0,0,0,0,0,0,0,17,0,0,0,0,0,0
0,0,0,0,0,17,0,0,0,0,0,0,0,0,0,17,0,0,0,0,0
0,0,0,0,0,17,0,0,0,0,0,0,0,0,0,17,0,0,0,0,0
0,0,0,0,0,17,0,0,0,0,43,0,0,0,0,17,0,0,0,0,0
0,0,0,0,0,17,0,0,0,0,0,0,0,0,0,17,0,0,0,0,0
0,0,0,0,0,17,0,0,0,0,0,0,0,0,0,17,0,0,0,0,0
0,0,0,0,0,0,17,0,0,0,0,0,0,0,17,0,0,0,0,0,0
0,0,0,0,0,0,17,17,0,0,0,0,0,17,17,0,0,0,0,0,0
0,0,0,0,0,0,0,0,17,17,17,17,17,0,0,0,0,0,0,0,0
0,0,0,0,0,0,0,0,0,0,0,0,0,0,0,0,0,0,0,0,0
0,0,0,0,0,0,0,0,0,0,0,0,0,0,0,0,0,0,0,0,0
0,0,0,0,0,0,0,0,0,0,0,0,0,0,0,0,0,0,0,0,0
0,0,0,0,0,0,0,0,0,0,0,0,0,0,0,0,0,0,0,0,0
0,0,0,0,0,0,0,0,0,0,0,0,0,0,0,0,0,0,0,0,0
0,0,0,0,0,0,0,0,0,0,0,0,0,0,0,0,0,0,0,0,0
0,0,0,0,0,0,0,0,0,0,0,0,0,0,0,0,0,0,0,0,0
:endlayer
layer: 51
0,0,0,0,0,0,0,0,0,0,0,0,0,0,0,0,0,0,0,0,0
0,0,0,0,0,0,0,0,0,0,0,0,0,0,0,0,0,0,0,0,0
0,0,0,0,0,0,0,0,0,0,0,0,0,0,0,0,0,0,0,0,0
0,0,0,0,0,0,0,0,0,0,0,0,0,0,0,0,0,0,0,0,0
0,0,0,0,0,0,0,0,0,0,0,0,0,0,0,0,0,0,0,0,0
0,0,0,0,0,0,0,0,0,0,17,0,0,0,0,0,0,0,0,0,0
0,0,0,0,0,0,0,0,17,17,17,17,17,0,0,0,0,0,0,0,0
0,0,0,0,0,0,0,17,0,0,0,0,0,17,0,0,0,0,0,0,0
0,0,0,0,0,0,17,0,0,0,0,0,0,0,17,0,0,0,0,0,0
0,0,0,0,0,0,17,0,0,0,0,0,0,0,17,0,0,0,0,0,0
0,0,0,0,0,17,17,0,0,0,43,0,0,0,17,17,0,0,0,0,0
0,0,0,0,0,0,17,0,0,0,0,0,0,0,17,0,0,0,0,0,0
0,0,0,0,0,0,17,0,0,0,0,0,0,0,17,0,0,0,0,0,0
0,0,0,0,0,0,0,17,0,0,0,0,0,17,0,0,0,0,0,0,0
0,0,0,0,0,0,0,0,17,17,17,17,17,0,0,0,0,0,0,0,0
0,0,0,0,0,0,0,0,0,0,17,0,0,0,0,0,0,0,0,0,0
0,0,0,0,0,0,0,0,0,0,0,0,0,0,0,0,0,0,0,0,0
0,0,0,0,0,0,0,0,0,0,0,0,0,0,0,0,0,0,0,0,0
0,0,0,0,0,0,0,0,0,0,0,0,0,0,0,0,0,0,0,0,0
0,0,0,0,0,0,0,0,0,0,0,0,0,0,0,0,0,0,0,0,0
0,0,0,0,0,0,0,0,0,0,0,0,0,0,0,0,0,0,0,0,0
0,0,0,0,0,0,0,0,0,0,0,0,0,0,0,0,0,0,0,0,0
0,0,0,0,0,0,0,0,0,0,0,0,0,0,0,0,0,0,0,0,0
:endlayer
layer: 52
0,0,0,0,0,0,0,0,0,0,0,0,0,0,0,0,0,0,0,0,0
0,0,0,0,0,0,0,0,0,0,0,0,0,0,0,0,0,0,0,0,0
0,0,0,0,0,0,0,0,0,0,0,0,0,0,0,0,0,0,0,0,0
0,0,0,0,0,0,0,0,0,0,0,0,0,0,0,0,0,0,0,0,0
0,0,0,0,0,0,0,0,0,0,0,0,0,0,0,0,0,0,0,0,0
0,0,0,0,0,0,0,0,0,0,45,0,0,0,0,0,0,0,0,0,0
0,0,0,0,0,0,0,0,0,0,17,0,0,0,0,0,0,0,0,0,0
0,0,0,0,0,0,0,0,17,17,17,17,17,0,0,0,0,0,0,0,0
0,0,0,0,0,0,0,17,0,0,0,0,0,17,0,0,0,0,0,0,0
0,0,0,0,0,0,0,17,0,0,0,0,0,17,0,0,0,0,0,0,0
0,0,0,0,0,45,17,17,0,0,43,0,0,17,17,45,0,0,0,0,0
0,0,0,0,0,0,0,17,0,0,0,0,0,17,0,0,0,0,0,0,0
0,0,0,0,0,0,0,17,0,0,0,0,0,17,0,0,0,0,0,0,0
0,0,0,0,0,0,0,0,17,17,17,17,17,0,0,0,0,0,0,0,0
0,0,0,0,0,0,0,0,0,0,17,0,0,0,0,0,0,0,0,0,0
0,0,0,0,0,0,0,0,0,0,45,0,0,0,0,0,0,0,0,0,0
0,0,0,0,0,0,0,0,0,0,0,0,0,0,0,0,0,0,0,0,0
0,0,0,0,0,0,0,0,0,0,0,0,0,0,0,0,0,0,0,0,0
0,0,0,0,0,0,0,0,0,0,0,0,0,0,0,0,0,0,0,0,0
0,0,0,0,0,0,0,0,0,0,0,0,0,0,0,0,0,0,0,0,0
0,0,0,0,0,0,0,0,0,0,0,0,0,0,0,0,0,0,0,0,0
0,0,0,0,0,0,0,0,0,0,0,0,0,0,0,0,0,0,0,0,0
0,0,0,0,0,0,0,0,0,0,0,0,0,0,0,0,0,0,0,0,0
:endlayer
layer: 53
0,0,0,0,0,0,0,0,0,0,0,0,0,0,0,0,0,0,0,0,0
0,0,0,0,0,0,0,0,0,0,0,0,0,0,0,0,0,0,0,0,0
0,0,0,0,0,0,0,0,0,0,0,0,0,0,0,0,0,0,0,0,0
0,0,0,0,0,0,0,0,0,0,0,0,0,0,0,0,0,0,0,0,0
0,0,0,0,0,0,0,0,0,0,0,0,0,0,0,0,0,0,0,0,0
0,0,0,0,0,0,0,0,0,0,0,0,0,0,0,0,0,0,0,0,0
0,0,0,0,0,0,0,0,0,0,0,0,0,0,0,0,0,0,0,0,0
0,0,0,0,0,0,0,0,17,17,17,17,17,0,0,0,0,0,0,0,0
0,0,0,0,0,0,0,17,0,0,0,0,0,17,0,0,0,0,0,0,0
0,0,0,0,0,0,0,17,0,0,0,0,0,17,0,0,0,0,0,0,0
0,0,0,0,0,0,0,17,0,0,43,0,0,17,0,0,0,0,0,0,0
0,0,0,0,0,0,0,17,0,0,0,0,0,17,0,0,0,0,0,0,0
0,0,0,0,0,0,0,17,0,0,0,0,0,17,0,0,0,0,0,0,0
0,0,0,0,0,0,0,0,17,17,17,17,17,0,0,0,0,0,0,0,0
0,0,0,0,0,0,0,0,0,0,0,0,0,0,0,0,0,0,0,0,0
0,0,0,0,0,0,0,0,0,0,0,0,0,0,0,0,0,0,0,0,0
0,0,0,0,0,0,0,0,0,0,0,0,0,0,0,0,0,0,0,0,0
0,0,0,0,0,0,0,0,0,0,0,0,0,0,0,0,0,0,0,0,0
0,0,0,0,0,0,0,0,0,0,0,0,0,0,0,0,0,0,0,0,0
0,0,0,0,0,0,0,0,0,0,0,0,0,0,0,0,0,0,0,0,0
0,0,0,0,0,0,0,0,0,0,0,0,0,0,0,0,0,0,0,0,0
0,0,0,0,0,0,0,0,0,0,0,0,0,0,0,0,0,0,0,0,0
0,0,0,0,0,0,0,0,0,0,0,0,0,0,0,0,0,0,0,0,0
:endlayer
layer: 54
0,0,0,0,0,0,0,0,0,0,0,0,0,0,0,0,0,0,0,0,0
0,0,0,0,0,0,0,0,0,0,0,0,0,0,0,0,0,0,0,0,0
0,0,0,0,0,0,0,0,0,0,0,0,0,0,0,0,0,0,0,0,0
0,0,0,0,0,0,0,0,0,0,0,0,0,0,0,0,0,0,0,0,0
0,0,0,0,0,0,0,0,0,0,0,0,0,0,0,0,0,0,0,0,0
0,0,0,0,0,0,0,0,0,0,0,0,0,0,0,0,0,0,0,0,0
0,0,0,0,0,0,0,0,0,0,0,0,0,0,0,0,0,0,0,0,0
0,0,0,0,0,0,0,0,0,0,17,0,0,0,0,0,0,0,0,0,0
0,0,0,0,0,0,0,0,17,17,17,17,17,0,0,0,0,0,0,0,0
0,0,0,0,0,0,0,0,17,0,35,0,17,0,0,0,0,0,0,0,0
0,0,0,0,0,0,0,17,17,36,43,21,17,17,0,0,0,0,0,0,0
0,0,0,0,0,0,0,0,17,0,23,0,17,0,0,0,0,0,0,0,0
0,0,0,0,0,0,0,0,17,17,17,17,17,0,0,0,0,0,0,0,0
0,0,0,0,0,0,0,0,0,0,17,0,0,0,0,0,0,0,0,0,0
0,0,0,0,0,0,0,0,0,0,0,0,0,0,0,0,0,0,0,0,0
0,0,0,0,0,0,0,0,0,0,0,0,0,0,0,0,0,0,0,0,0
0,0,0,0,0,0,0,0,0,0,0,0,0,0,0,0,0,0,0,0,0
0,0,0,0,0,0,0,0,0,0,0,0,0,0,0,0,0,0,0,0,0
0,0,0,0,0,0,0,0,0,0,0,0,0,0,0,0,0,0,0,0,0
0,0,0,0,0,0,0,0,0,0,0,0,0,0,0,0,0,0,0,0,0
0,0,0,0,0,0,0,0,0,0,0,0,0,0,0,0,0,0,0,0,0
0,0,0,0,0,0,0,0,0,0,0,0,0,0,0,0,0,0,0,0,0
0,0,0,0,0,0,0,0,0,0,0,0,0,0,0,0,0,0,0,0,0
:endlayer
layer: 55
0,0,0,0,0,0,0,0,0,0,0,0,0,0,0,0,0,0,0,0,0
0,0,0,0,0,0,0,0,0,0,0,0,0,0,0,0,0,0,0,0,0
0,0,0,0,0,0,0,0,0,0,0,0,0,0,0,0,0,0,0,0,0
0,0,0,0,0,0,0,0,0,0,0,0,0,0,0,0,0,0,0,0,0
0,0,0,0,0,0,0,0,0,0,0,0,0,0,0,0,0,0,0,0,0
0,0,0,0,0,0,0,0,0,0,0,0,0,0,0,0,0,0,0,0,0
0,0,0,0,0,0,0,0,0,0,0,0,0,0,0,0,0,0,0,0,0
0,0,0,0,0,0,0,0,0,0,0,0,0,0,0,0,0,0,0,0,0
0,0,0,0,0,0,0,0,0,17,17,17,0,0,0,0,0,0,0,0,0
0,0,0,0,0,0,0,0,17,0,0,0,17,0,0,0,0,0,0,0,0
0,0,0,0,0,0,0,0,17,0,43,0,17,0,0,0,0,0,0,0,0
0,0,0,0,0,0,0,0,17,0,0,0,17,0,0,0,0,0,0,0,0
0,0,0,0,0,0,0,0,0,17,17,17,0,0,0,0,0,0,0,0,0
0,0,0,0,0,0,0,0,0,0,0,0,0,0,0,0,0,0,0,0,0
0,0,0,0,0,0,0,0,0,0,0,0,0,0,0,0,0,0,0,0,0
0,0,0,0,0,0,0,0,0,0,0,0,0,0,0,0,0,0,0,0,0
0,0,0,0,0,0,0,0,0,0,0,0,0,0,0,0,0,0,0,0,0
0,0,0,0,0,0,0,0,0,0,0,0,0,0,0,0,0,0,0,0,0
0,0,0,0,0,0,0,0,0,0,0,0,0,0,0,0,0,0,0,0,0
0,0,0,0,0,0,0,0,0,0,0,0,0,0,0,0,0,0,0,0,0
0,0,0,0,0,0,0,0,0,0,0,0,0,0,0,0,0,0,0,0,0
0,0,0,0,0,0,0,0,0,0,0,0,0,0,0,0,0,0,0,0,0
0,0,0,0,0,0,0,0,0,0,0,0,0,0,0,0,0,0,0,0,0
:endlayer
layer: 56
0,0,0,0,0,0,0,0,0,0,0,0,0,0,0,0,0,0,0,0,0
0,0,0,0,0,0,0,0,0,0,0,0,0,0,0,0,0,0,0,0,0
0,0,0,0,0,0,0,0,0,0,0,0,0,0,0,0,0,0,0,0,0
0,0,0,0,0,0,0,0,0,0,0,0,0,0,0,0,0,0,0,0,0
0,0,0,0,0,0,0,0,0,0,0,0,0,0,0,0,0,0,0,0,0
0,0,0,0,0,0,0,0,0,0,0,0,0,0,0,0,0,0,0,0,0
0,0,0,0,0,0,0,0,0,0,0,0,0,0,0,0,0,0,0,0,0
0,0,0,0,0,0,0,0,0,0,0,0,0,0,0,0,0,0,0,0,0
0,0,0,0,0,0,0,0,0,0,0,0,0,0,0,0,0,0,0,0,0
0,0,0,0,0,0,0,0,0,17,17,17,0,0,0,0,0,0,0,0,0
0,0,0,0,0,0,0,0,0,17,17,17,0,0,0,0,0,0,0,0,0
0,0,0,0,0,0,0,0,0,17,17,17,0,0,0,0,0,0,0,0,0
0,0,0,0,0,0,0,0,0,0,0,0,0,0,0,0,0,0,0,0,0
0,0,0,0,0,0,0,0,0,0,0,0,0,0,0,0,0,0,0,0,0
0,0,0,0,0,0,0,0,0,0,0,0,0,0,0,0,0,0,0,0,0
0,0,0,0,0,0,0,0,0,0,0,0,0,0,0,0,0,0,0,0,0
0,0,0,0,0,0,0,0,0,0,0,0,0,0,0,0,0,0,0,0,0
0,0,0,0,0,0,0,0,0,0,0,0,0,0,0,0,0,0,0,0,0
0,0,0,0,0,0,0,0,0,0,0,0,0,0,0,0,0,0,0,0,0
0,0,0,0,0,0,0,0,0,0,0,0,0,0,0,0,0,0,0,0,0
0,0,0,0,0,0,0,0,0,0,0,0,0,0,0,0,0,0,0,0,0
0,0,0,0,0,0,0,0,0,0,0,0,0,0,0,0,0,0,0,0,0
0,0,0,0,0,0,0,0,0,0,0,0,0,0,0,0,0,0,0,0,0
:endlayer
layer: 57
0,0,0,0,0,0,0,0,0,0,0,0,0,0,0,0,0,0,0,0,0
0,0,0,0,0,0,0,0,0,0,0,0,0,0,0,0,0,0,0,0,0
0,0,0,0,0,0,0,0,0,0,0,0,0,0,0,0,0,0,0,0,0
0,0,0,0,0,0,0,0,0,0,0,0,0,0,0,0,0,0,0,0,0
0,0,0,0,0,0,0,0,0,0,0,0,0,0,0,0,0,0,0,0,0
0,0,0,0,0,0,0,0,0,0,0,0,0,0,0,0,0,0,0,0,0
0,0,0,0,0,0,0,0,0,0,0,0,0,0,0,0,0,0,0,0,0
0,0,0,0,0,0,0,0,0,0,0,0,0,0,0,0,0,0,0,0,0
0,0,0,0,0,0,0,0,0,0,0,0,0,0,0,0,0,0,0,0,0
0,0,0,0,0,0,0,0,0,0,0,0,0,0,0,0,0,0,0,0,0
0,0,0,0,0,0,0,0,0,0,17,0,0,0,0,0,0,0,0,0,0
0,0,0,0,0,0,0,0,0,0,0,0,0,0,0,0,0,0,0,0,0
0,0,0,0,0,0,0,0,0,0,0,0,0,0,0,0,0,0,0,0,0
0,0,0,0,0,0,0,0,0,0,0,0,0,0,0,0,0,0,0,0,0
0,0,0,0,0,0,0,0,0,0,0,0,0,0,0,0,0,0,0,0,0
0,0,0,0,0,0,0,0,0,0,0,0,0,0,0,0,0,0,0,0,0
0,0,0,0,0,0,0,0,0,0,0,0,0,0,0,0,0,0,0,0,0
0,0,0,0,0,0,0,0,0,0,0,0,0,0,0,0,0,0,0,0,0
0,0,0,0,0,0,0,0,0,0,0,0,0,0,0,0,0,0,0,0,0
0,0,0,0,0,0,0,0,0,0,0,0,0,0,0,0,0,0,0,0,0
0,0,0,0,0,0,0,0,0,0,0,0,0,0,0,0,0,0,0,0,0
0,0,0,0,0,0,0,0,0,0,0,0,0,0,0,0,0,0,0,0,0
0,0,0,0,0,0,0,0,0,0,0,0,0,0,0,0,0,0,0,0,0
:endlayer
layer: 58
0,0,0,0,0,0,0,0,0,0,0,0,0,0,0,0,0,0,0,0,0
0,0,0,0,0,0,0,0,0,0,0,0,0,0,0,0,0,0,0,0,0
0,0,0,0,0,0,0,0,0,0,0,0,0,0,0,0,0,0,0,0,0
0,0,0,0,0,0,0,0,0,0,0,0,0,0,0,0,0,0,0,0,0
0,0,0,0,0,0,0,0,0,0,0,0,0,0,0,0,0,0,0,0,0
0,0,0,0,0,0,0,0,0,0,0,0,0,0,0,0,0,0,0,0,0
0,0,0,0,0,0,0,0,0,0,0,0,0,0,0,0,0,0,0,0,0
0,0,0,0,0,0,0,0,0,0,0,0,0,0,0,0,0,0,0,0,0
0,0,0,0,0,0,0,0,0,0,0,0,0,0,0,0,0,0,0,0,0
0,0,0,0,0,0,0,0,0,0,0,0,0,0,0,0,0,0,0,0,0
0,0,0,0,0,0,0,0,0,0,17,0,0,0,0,0,0,0,0,0,0
0,0,0,0,0,0,0,0,0,0,0,0,0,0,0,0,0,0,0,0,0
0,0,0,0,0,0,0,0,0,0,0,0,0,0,0,0,0,0,0,0,0
0,0,0,0,0,0,0,0,0,0,0,0,0,0,0,0,0,0,0,0,0
0,0,0,0,0,0,0,0,0,0,0,0,0,0,0,0,0,0,0,0,0
0,0,0,0,0,0,0,0,0,0,0,0,0,0,0,0,0,0,0,0,0
0,0,0,0,0,0,0,0,0,0,0,0,0,0,0,0,0,0,0,0,0
0,0,0,0,0,0,0,0,0,0,0,0,0,0,0,0,0,0,0,0,0
0,0,0,0,0,0,0,0,0,0,0,0,0,0,0,0,0,0,0,0,0
0,0,0,0,0,0,0,0,0,0,0,0,0,0,0,0,0,0,0,0,0
0,0,0,0,0,0,0,0,0,0,0,0,0,0,0,0,0,0,0,0,0
0,0,0,0,0,0,0,0,0,0,0,0,0,0,0,0,0,0,0,0,0
0,0,0,0,0,0,0,0,0,0,0,0,0,0,0,0,0,0,0,0,0
:endlayer
layer: 59
0,0,0,0,0,0,0,0,0,0,0,0,0,0,0,0,0,0,0,0,0
0,0,0,0,0,0,0,0,0,0,0,0,0,0,0,0,0,0,0,0,0
0,0,0,0,0,0,0,0,0,0,0,0,0,0,0,0,0,0,0,0,0
0,0,0,0,0,0,0,0,0,0,0,0,0,0,0,0,0,0,0,0,0
0,0,0,0,0,0,0,0,0,0,0,0,0,0,0,0,0,0,0,0,0
0,0,0,0,0,0,0,0,0,0,0,0,0,0,0,0,0,0,0,0,0
0,0,0,0,0,0,0,0,0,0,0,0,0,0,0,0,0,0,0,0,0
0,0,0,0,0,0,0,0,0,0,0,0,0,0,0,0,0,0,0,0,0
0,0,0,0,0,0,0,0,0,0,0,0,0,0,0,0,0,0,0,0,0
0,0,0,0,0,0,0,0,0,0,0,0,0,0,0,0,0,0,0,0,0
0,0,0,0,0,0,0,0,0,0,43,0,0,0,0,0,0,0,0,0,0
0,0,0,0,0,0,0,0,0,0,0,0,0,0,0,0,0,0,0,0,0
0,0,0,0,0,0,0,0,0,0,0,0,0,0,0,0,0,0,0,0,0
0,0,0,0,0,0,0,0,0,0,0,0,0,0,0,0,0,0,0,0,0
0,0,0,0,0,0,0,0,0,0,0,0,0,0,0,0,0,0,0,0,0
0,0,0,0,0,0,0,0,0,0,0,0,0,0,0,0,0,0,0,0,0
0,0,0,0,0,0,0,0,0,0,0,0,0,0,0,0,0,0,0,0,0
0,0,0,0,0,0,0,0,0,0,0,0,0,0,0,0,0,0,0,0,0
0,0,0,0,0,0,0,0,0,0,0,0,0,0,0,0,0,0,0,0,0
0,0,0,0,0,0,0,0,0,0,0,0,0,0,0,0,0,0,0,0,0
0,0,0,0,0,0,0,0,0,0,0,0,0,0,0,0,0,0,0,0,0
0,0,0,0,0,0,0,0,0,0,0,0,0,0,0,0,0,0,0,0,0
0,0,0,0,0,0,0,0,0,0,0,0,0,0,0,0,0,0,0,0,0
:endlayer
layer: 60
0,0,0,0,0,0,0,0,0,0,0,0,0,0,0,0,0,0,0,0,0
0,0,0,0,0,0,0,0,0,0,0,0,0,0,0,0,0,0,0,0,0
0,0,0,0,0,0,0,0,0,0,0,0,0,0,0,0,0,0,0,0,0
0,0,0,0,0,0,0,0,0,0,0,0,0,0,0,0,0,0,0,0,0
0,0,0,0,0,0,0,0,0,0,0,0,0,0,0,0,0,0,0,0,0
0,0,0,0,0,0,0,0,0,0,0,0,0,0,0,0,0,0,0,0,0
0,0,0,0,0,0,0,0,0,0,0,0,0,0,0,0,0,0,0,0,0
0,0,0,0,0,0,0,0,0,0,0,0,0,0,0,0,0,0,0,0,0
0,0,0,0,0,0,0,0,0,0,0,0,0,0,0,0,0,0,0,0,0
0,0,0,0,0,0,0,0,0,0,0,0,0,0,0,0,0,0,0,0,0
0,0,0,0,0,0,0,0,0,0,43,0,0,0,0,0,0,0,0,0,0
0,0,0,0,0,0,0,0,0,0,0,0,0,0,0,0,0,0,0,0,0
0,0,0,0,0,0,0,0,0,0,0,0,0,0,0,0,0,0,0,0,0
0,0,0,0,0,0,0,0,0,0,0,0,0,0,0,0,0,0,0,0,0
0,0,0,0,0,0,0,0,0,0,0,0,0,0,0,0,0,0,0,0,0
0,0,0,0,0,0,0,0,0,0,0,0,0,0,0,0,0,0,0,0,0
0,0,0,0,0,0,0,0,0,0,0,0,0,0,0,0,0,0,0,0,0
0,0,0,0,0,0,0,0,0,0,0,0,0,0,0,0,0,0,0,0,0
0,0,0,0,0,0,0,0,0,0,0,0,0,0,0,0,0,0,0,0,0
0,0,0,0,0,0,0,0,0,0,0,0,0,0,0,0,0,0,0,0,0
0,0,0,0,0,0,0,0,0,0,0,0,0,0,0,0,0,0,0,0,0
0,0,0,0,0,0,0,0,0,0,0,0,0,0,0,0,0,0,0,0,0
0,0,0,0,0,0,0,0,0,0,0,0,0,0,0,0,0,0,0,0,0
:endlayer
layer: 61
0,0,0,0,0,0,0,0,0,0,0,0,0,0,0,0,0,0,0,0,0
0,0,0,0,0,0,0,0,0,0,0,0,0,0,0,0,0,0,0,0,0
0,0,0,0,0,0,0,0,0,0,0,0,0,0,0,0,0,0,0,0,0
0,0,0,0,0,0,0,0,0,0,0,0,0,0,0,0,0,0,0,0,0
0,0,0,0,0,0,0,0,0,0,0,0,0,0,0,0,0,0,0,0,0
0,0,0,0,0,0,0,0,0,0,0,0,0,0,0,0,0,0,0,0,0
0,0,0,0,0,0,0,0,0,0,0,0,0,0,0,0,0,0,0,0,0
0,0,0,0,0,0,0,0,0,0,0,0,0,0,0,0,0,0,0,0,0
0,0,0,0,0,0,0,0,0,0,0,0,0,0,0,0,0,0,0,0,0
0,0,0,0,0,0,0,0,0,0,0,0,0,0,0,0,0,0,0,0,0
0,0,0,0,0,0,0,0,0,0,45,0,0,0,0,0,0,0,0,0,0
0,0,0,0,0,0,0,0,0,0,0,0,0,0,0,0,0,0,0,0,0
0,0,0,0,0,0,0,0,0,0,0,0,0,0,0,0,0,0,0,0,0
0,0,0,0,0,0,0,0,0,0,0,0,0,0,0,0,0,0,0,0,0
0,0,0,0,0,0,0,0,0,0,0,0,0,0,0,0,0,0,0,0,0
0,0,0,0,0,0,0,0,0,0,0,0,0,0,0,0,0,0,0,0,0
0,0,0,0,0,0,0,0,0,0,0,0,0,0,0,0,0,0,0,0,0
0,0,0,0,0,0,0,0,0,0,0,0,0,0,0,0,0,0,0,0,0
0,0,0,0,0,0,0,0,0,0,0,0,0,0,0,0,0,0,0,0,0
0,0,0,0,0,0,0,0,0,0,0,0,0,0,0,0,0,0,0,0,0
0,0,0,0,0,0,0,0,0,0,0,0,0,0,0,0,0,0,0,0,0
0,0,0,0,0,0,0,0,0,0,0,0,0,0,0,0,0,0,0,0,0
0,0,0,0,0,0,0,0,0,0,0,0,0,0,0,0,0,0,0,0,0
:endlayer
layer: 62
0,0,0,0,0,0,0,0,0,0,0,0,0,0,0,0,0,0,0,0,0
0,0,0,0,0,0,0,0,0,0,0,0,0,0,0,0,0,0,0,0,0
0,0,0,0,0,0,0,0,0,0,0,0,0,0,0,0,0,0,0,0,0
0,0,0,0,0,0,0,0,0,0,0,0,0,0,0,0,0,0,0,0,0
0,0,0,0,0,0,0,0,0,0,0,0,0,0,0,0,0,0,0,0,0
0,0,0,0,0,0,0,0,0,0,0,0,0,0,0,0,0,0,0,0,0
0,0,0,0,0,0,0,0,0,0,0,0,0,0,0,0,0,0,0,0,0
0,0,0,0,0,0,0,0,0,0,0,0,0,0,0,0,0,0,0,0,0
0,0,0,0,0,0,0,0,0,0,0,0,0,0,0,0,0,0,0,0,0
0,0,0,0,0,0,0,0,0,0,0,0,0,0,0,0,0,0,0,0,0
0,0,0,0,0,0,0,0,0,0,0,0,0,0,0,0,0,0,0,0,0
0,0,0,0,0,0,0,0,0,0,0,0,0,0,0,0,0,0,0,0,0
0,0,0,0,0,0,0,0,0,0,0,0,0,0,0,0,0,0,0,0,0
0,0,0,0,0,0,0,0,0,0,0,0,0,0,0,0,0,0,0,0,0
0,0,0,0,0,0,0,0,0,0,0,0,0,0,0,0,0,0,0,0,0
0,0,0,0,0,0,0,0,0,0,0,0,0,0,0,0,0,0,0,0,0
0,0,0,0,0,0,0,0,0,0,0,0,0,0,0,0,0,0,0,0,0
0,0,0,0,0,0,0,0,0,0,0,0,0,0,0,0,0,0,0,0,0
0,0,0,0,0,0,0,0,0,0,0,0,0,0,0,0,0,0,0,0,0
0,0,0,0,0,0,0,0,0,0,0,0,0,0,0,0,0,0,0,0,0
0,0,0,0,0,0,0,0,0,0,0,0,0,0,0,0,0,0,0,0,0
0,0,0,0,0,0,0,0,0,0,0,0,0,0,0,0,0,0,0,0,0
0,0,0,0,0,0,0,0,0,0,0,0,0,0,0,0,0,0,0,0,0
:endlayer
layer: 63
0,0,0,0,0,0,0,0,0,0,0,0,0,0,0,0,0,0,0,0,0
0,0,0,0,0,0,0,0,0,0,0,0,0,0,0,0,0,0,0,0,0
0,0,0,0,0,0,0,0,0,0,0,0,0,0,0,0,0,0,0,0,0
0,0,0,0,0,0,0,0,0,0,0,0,0,0,0,0,0,0,0,0,0
0,0,0,0,0,0,0,0,0,0,0,0,0,0,0,0,0,0,0,0,0
0,0,0,0,0,0,0,0,0,0,0,0,0,0,0,0,0,0,0,0,0
0,0,0,0,0,0,0,0,0,0,0,0,0,0,0,0,0,0,0,0,0
0,0,0,0,0,0,0,0,0,0,0,0,0,0,0,0,0,0,0,0,0
0,0,0,0,0,0,0,0,0,0,0,0,0,0,0,0,0,0,0,0,0
0,0,0,0,0,0,0,0,0,0,0,0,0,0,0,0,0,0,0,0,0
0,0,0,0,0,0,0,0,0,0,0,0,0,0,0,0,0,0,0,0,0
0,0,0,0,0,0,0,0,0,0,0,0,0,0,0,0,0,0,0,0,0
0,0,0,0,0,0,0,0,0,0,0,0,0,0,0,0,0,0,0,0,0
0,0,0,0,0,0,0,0,0,0,0,0,0,0,0,0,0,0,0,0,0
0,0,0,0,0,0,0,0,0,0,0,0,0,0,0,0,0,0,0,0,0
0,0,0,0,0,0,0,0,0,0,0,0,0,0,0,0,0,0,0,0,0
0,0,0,0,0,0,0,0,0,0,0,0,0,0,0,0,0,0,0,0,0
0,0,0,0,0,0,0,0,0,0,0,0,0,0,0,0,0,0,0,0,0
0,0,0,0,0,0,0,0,0,0,0,0,0,0,0,0,0,0,0,0,0
0,0,0,0,0,0,0,0,0,0,0,0,0,0,0,0,0,0,0,0,0
0,0,0,0,0,0,0,0,0,0,0,0,0,0,0,0,0,0,0,0,0
0,0,0,0,0,0,0,0,0,0,0,0,0,0,0,0,0,0,0,0,0
0,0,0,0,0,0,0,0,0,0,0,0,0,0,0,0,0,0,0,0,0
:endlayer
layer: 64
0,0,0,0,0,0,0,0,0,0,0,0,0,0,0,0,0,0,0,0,0
0,0,0,0,0,0,0,0,0,0,0,0,0,0,0,0,0,0,0,0,0
0,0,0,0,0,0,0,0,0,0,0,0,0,0,0,0,0,0,0,0,0
0,0,0,0,0,0,0,0,0,0,0,0,0,0,0,0,0,0,0,0,0
0,0,0,0,0,0,0,0,0,0,0,0,0,0,0,0,0,0,0,0,0
0,0,0,0,0,0,0,0,0,0,0,0,0,0,0,0,0,0,0,0,0
0,0,0,0,0,0,0,0,0,0,0,0,0,0,0,0,0,0,0,0,0
0,0,0,0,0,0,0,0,0,0,0,0,0,0,0,0,0,0,0,0,0
0,0,0,0,0,0,0,0,0,0,0,0,0,0,0,0,0,0,0,0,0
0,0,0,0,0,0,0,0,0,0,0,0,0,0,0,0,0,0,0,0,0
0,0,0,0,0,0,0,0,0,0,0,0,0,0,0,0,0,0,0,0,0
0,0,0,0,0,0,0,0,0,0,0,0,0,0,0,0,0,0,0,0,0
0,0,0,0,0,0,0,0,0,0,0,0,0,0,0,0,0,0,0,0,0
0,0,0,0,0,0,0,0,0,0,0,0,0,0,0,0,0,0,0,0,0
0,0,0,0,0,0,0,0,0,0,0,0,0,0,0,0,0,0,0,0,0
0,0,0,0,0,0,0,0,0,0,0,0,0,0,0,0,0,0,0,0,0
0,0,0,0,0,0,0,0,0,0,0,0,0,0,0,0,0,0,0,0,0
0,0,0,0,0,0,0,0,0,0,0,0,0,0,0,0,0,0,0,0,0
0,0,0,0,0,0,0,0,0,0,0,0,0,0,0,0,0,0,0,0,0
0,0,0,0,0,0,0,0,0,0,0,0,0,0,0,0,0,0,0,0,0
0,0,0,0,0,0,0,0,0,0,0,0,0,0,0,0,0,0,0,0,0
0,0,0,0,0,0,0,0,0,0,0,0,0,0,0,0,0,0,0,0,0
0,0,0,0,0,0,0,0,0,0,0,0,0,0,0,0,0,0,0,0,0
:endlayer
layer: 65
0,0,0,0,0,0,0,0,0,0,0,0,0,0,0,0,0,0,0,0,0
0,0,0,0,0,0,0,0,0,0,0,0,0,0,0,0,0,0,0,0,0
0,0,0,0,0,0,0,0,0,0,0,0,0,0,0,0,0,0,0,0,0
0,0,0,0,0,0,0,0,0,0,0,0,0,0,0,0,0,0,0,0,0
0,0,0,0,0,0,0,0,0,0,0,0,0,0,0,0,0,0,0,0,0
0,0,0,0,0,0,0,0,0,0,0,0,0,0,0,0,0,0,0,0,0
0,0,0,0,0,0,0,0,0,0,0,0,0,0,0,0,0,0,0,0,0
0,0,0,0,0,0,0,0,0,0,0,0,0,0,0,0,0,0,0,0,0
0,0,0,0,0,0,0,0,0,0,0,0,0,0,0,0,0,0,0,0,0
0,0,0,0,0,0,0,0,0,0,0,0,0,0,0,0,0,0,0,0,0
0,0,0,0,0,0,0,0,0,0,0,0,0,0,0,0,0,0,0,0,0
0,0,0,0,0,0,0,0,0,0,0,0,0,0,0,0,0,0,0,0,0
0,0,0,0,0,0,0,0,0,0,0,0,0,0,0,0,0,0,0,0,0
0,0,0,0,0,0,0,0,0,0,0,0,0,0,0,0,0,0,0,0,0
0,0,0,0,0,0,0,0,0,0,0,0,0,0,0,0,0,0,0,0,0
0,0,0,0,0,0,0,0,0,0,0,0,0,0,0,0,0,0,0,0,0
0,0,0,0,0,0,0,0,0,0,0,0,0,0,0,0,0,0,0,0,0
0,0,0,0,0,0,0,0,0,0,0,0,0,0,0,0,0,0,0,0,0
0,0,0,0,0,0,0,0,0,0,0,0,0,0,0,0,0,0,0,0,0
0,0,0,0,0,0,0,0,0,0,0,0,0,0,0,0,0,0,0,0,0
0,0,0,0,0,0,0,0,0,0,0,0,0,0,0,0,0,0,0,0,0
0,0,0,0,0,0,0,0,0,0,0,0,0,0,0,0,0,0,0,0,0
0,0,0,0,0,0,0,0,0,0,0,0,0,0,0,0,0,0,0,0,0
:endlayer
layer: 66
0,0,0,0,0,0,0,0,0,0,0,0,0,0,0,0,0,0,0,0,0
0,0,0,0,0,0,0,0,0,0,0,0,0,0,0,0,0,0,0,0,0
0,0,0,0,0,0,0,0,0,0,0,0,0,0,0,0,0,0,0,0,0
0,0,0,0,0,0,0,0,0,0,0,0,0,0,0,0,0,0,0,0,0
0,0,0,0,0,0,0,0,0,0,0,0,0,0,0,0,0,0,0,0,0
0,0,0,0,0,0,0,0,0,0,0,0,0,0,0,0,0,0,0,0,0
0,0,0,0,0,0,0,0,0,0,0,0,0,0,0,0,0,0,0,0,0
0,0,0,0,0,0,0,0,0,0,0,0,0,0,0,0,0,0,0,0,0
0,0,0,0,0,0,0,0,0,0,0,0,0,0,0,0,0,0,0,0,0
0,0,0,0,0,0,0,0,0,0,0,0,0,0,0,0,0,0,0,0,0
0,0,0,0,0,0,0,0,0,0,0,0,0,0,0,0,0,0,0,0,0
0,0,0,0,0,0,0,0,0,0,0,0,0,0,0,0,0,0,0,0,0
0,0,0,0,0,0,0,0,0,0,0,0,0,0,0,0,0,0,0,0,0
0,0,0,0,0,0,0,0,0,0,0,0,0,0,0,0,0,0,0,0,0
0,0,0,0,0,0,0,0,0,0,0,0,0,0,0,0,0,0,0,0,0
0,0,0,0,0,0,0,0,0,0,0,0,0,0,0,0,0,0,0,0,0
0,0,0,0,0,0,0,0,0,0,0,0,0,0,0,0,0,0,0,0,0
0,0,0,0,0,0,0,0,0,0,0,0,0,0,0,0,0,0,0,0,0
0,0,0,0,0,0,0,0,0,0,0,0,0,0,0,0,0,0,0,0,0
0,0,0,0,0,0,0,0,0,0,0,0,0,0,0,0,0,0,0,0,0
0,0,0,0,0,0,0,0,0,0,0,0,0,0,0,0,0,0,0,0,0
0,0,0,0,0,0,0,0,0,0,0,0,0,0,0,0,0,0,0,0,0
0,0,0,0,0,0,0,0,0,0,0,0,0,0,0,0,0,0,0,0,0
:endlayer
layer: 67
0,0,0,0,0,0,0,0,0,0,0,0,0,0,0,0,0,0,0,0,0
0,0,0,0,0,0,0,0,0,0,0,0,0,0,0,0,0,0,0,0,0
0,0,0,0,0,0,0,0,0,0,0,0,0,0,0,0,0,0,0,0,0
0,0,0,0,0,0,0,0,0,0,0,0,0,0,0,0,0,0,0,0,0
0,0,0,0,0,0,0,0,0,0,0,0,0,0,0,0,0,0,0,0,0
0,0,0,0,0,0,0,0,0,0,0,0,0,0,0,0,0,0,0,0,0
0,0,0,0,0,0,0,0,0,0,0,0,0,0,0,0,0,0,0,0,0
0,0,0,0,0,0,0,0,0,0,0,0,0,0,0,0,0,0,0,0,0
0,0,0,0,0,0,0,0,0,0,0,0,0,0,0,0,0,0,0,0,0
0,0,0,0,0,0,0,0,0,0,0,0,0,0,0,0,0,0,0,0,0
0,0,0,0,0,0,0,0,0,0,0,0,0,0,0,0,0,0,0,0,0
0,0,0,0,0,0,0,0,0,0,0,0,0,0,0,0,0,0,0,0,0
0,0,0,0,0,0,0,0,0,0,0,0,0,0,0,0,0,0,0,0,0
0,0,0,0,0,0,0,0,0,0,0,0,0,0,0,0,0,0,0,0,0
0,0,0,0,0,0,0,0,0,0,0,0,0,0,0,0,0,0,0,0,0
0,0,0,0,0,0,0,0,0,0,0,0,0,0,0,0,0,0,0,0,0
0,0,0,0,0,0,0,0,0,0,0,0,0,0,0,0,0,0,0,0,0
0,0,0,0,0,0,0,0,0,0,0,0,0,0,0,0,0,0,0,0,0
0,0,0,0,0,0,0,0,0,0,0,0,0,0,0,0,0,0,0,0,0
0,0,0,0,0,0,0,0,0,0,0,0,0,0,0,0,0,0,0,0,0
0,0,0,0,0,0,0,0,0,0,0,0,0,0,0,0,0,0,0,0,0
0,0,0,0,0,0,0,0,0,0,0,0,0,0,0,0,0,0,0,0,0
0,0,0,0,0,0,0,0,0,0,0,0,0,0,0,0,0,0,0,0,0
:endlayer

#### RULES ####
rule:
plugin=vanillaBlocks
number=1
data:
JSON:{{"val":{"blockName":{"val":"minecraft:stone","id":"ss"},"meta":{"val":"0","id":"pi"},"buildPass":{"val":"0","id":"pi"}},"id":"ct"}}
:enddata
:endrule

rule:
plugin=vanillaBlocks
number=2
data:
JSON:{{"val":{"blockName":{"val":"minecraft:stonebrick","id":"ss"},"meta":{"val":"0","id":"pi"},"buildPass":{"val":"0","id":"pi"}},"id":"ct"}}
:enddata
:endrule

rule:
plugin=vanillaDoors
number=3
data:
JSON:{{"val":{"sideFlag":{"val":"8","id":"pb"},"blockName":{"val":"minecraft:iron_door","id":"ss"},"meta":{"val":"3","id":"pi"},"buildPass":{"val":"2","id":"pi"}},"id":"ct"}}
:enddata
:endrule

rule:
plugin=vanillaDoors
number=4
data:
JSON:{{"val":{"sideFlag":{"val":"9","id":"pb"},"blockName":{"val":"minecraft:iron_door","id":"ss"},"meta":{"val":"0","id":"pi"},"buildPass":{"val":"2","id":"pi"}},"id":"ct"}}
:enddata
:endrule

rule:
plugin=vanillaBlocks
number=5
data:
JSON:{{"val":{"blockName":{"val":"minecraft:oak_stairs","id":"ss"},"meta":{"val":"1","id":"pi"},"buildPass":{"val":"0","id":"pi"}},"id":"ct"}}
:enddata
:endrule

rule:
plugin=vanillaDoors
number=6
data:
JSON:{{"val":{"sideFlag":{"val":"8","id":"pb"},"blockName":{"val":"minecraft:iron_door","id":"ss"},"meta":{"val":"2","id":"pi"},"buildPass":{"val":"2","id":"pi"}},"id":"ct"}}
:enddata
:endrule

rule:
plugin=vanillaDoors
number=7
data:
JSON:{{"val":{"sideFlag":{"val":"9","id":"pb"},"blockName":{"val":"minecraft:iron_door","id":"ss"},"meta":{"val":"1","id":"pi"},"buildPass":{"val":"2","id":"pi"}},"id":"ct"}}
:enddata
:endrule

rule:
plugin=vanillaBlocks
number=8
data:
JSON:{{"val":{"blockName":{"val":"minecraft:lever","id":"ss"},"meta":{"val":"3","id":"pi"},"buildPass":{"val":"2","id":"pi"}},"id":"ct"}}
:enddata
:endrule

rule:
plugin=vanillaBlocks
number=9
data:
JSON:{{"val":{"blockName":{"val":"minecraft:iron_bars","id":"ss"},"meta":{"val":"0","id":"pi"},"buildPass":{"val":"0","id":"pi"}},"id":"ct"}}
:enddata
:endrule

rule:
plugin=vanillaDoors
number=10
data:
JSON:{{"val":{"sideFlag":{"val":"0","id":"pb"},"blockName":{"val":"minecraft:iron_door","id":"ss"},"meta":{"val":"8","id":"pi"},"buildPass":{"val":"2","id":"pi"}},"id":"ct"}}
:enddata
:endrule

rule:
plugin=vanillaDoors
number=11
data:
JSON:{{"val":{"sideFlag":{"val":"0","id":"pb"},"blockName":{"val":"minecraft:iron_door","id":"ss"},"meta":{"val":"9","id":"pi"},"buildPass":{"val":"2","id":"pi"}},"id":"ct"}}
:enddata
:endrule

rule:
plugin=vanillaBlocks
number=12
data:
JSON:{{"val":{"blockName":{"val":"minecraft:lever","id":"ss"},"meta":{"val":"2","id":"pi"},"buildPass":{"val":"2","id":"pi"}},"id":"ct"}}
:enddata
:endrule

rule:
plugin=vanillaBlocks
number=13
data:
JSON:{{"val":{"blockName":{"val":"minecraft:lever","id":"ss"},"meta":{"val":"4","id":"pi"},"buildPass":{"val":"2","id":"pi"}},"id":"ct"}}
:enddata
:endrule

rule:
plugin=vanillaDoors
number=14
data:
JSON:{{"val":{"sideFlag":{"val":"0","id":"pb"},"blockName":{"val":"minecraft:iron_door","id":"ss"},"meta":{"val":"8","id":"pi"},"buildPass":{"val":"2","id":"pi"}},"id":"ct"}}
:enddata
:endrule

rule:
plugin=vanillaDoors
number=15
data:
JSON:{{"val":{"sideFlag":{"val":"0","id":"pb"},"blockName":{"val":"minecraft:iron_door","id":"ss"},"meta":{"val":"9","id":"pi"},"buildPass":{"val":"2","id":"pi"}},"id":"ct"}}
:enddata
:endrule

rule:
plugin=vanillaDoors
number=16
data:
JSON:{{"val":{"sideFlag":{"val":"0","id":"pb"},"blockName":{"val":"minecraft:iron_door","id":"ss"},"meta":{"val":"8","id":"pi"},"buildPass":{"val":"2","id":"pi"}},"id":"ct"}}
:enddata
:endrule

rule:
plugin=vanillaBlocks
number=17
data:
JSON:{{"val":{"blockName":{"val":"minecraft:planks","id":"ss"},"meta":{"val":"0","id":"pi"},"buildPass":{"val":"0","id":"pi"}},"id":"ct"}}
:enddata
:endrule

rule:
plugin=vanillaBlocks
number=18
data:
JSON:{{"val":{"blockName":{"val":"minecraft:lever","id":"ss"},"meta":{"val":"1","id":"pi"},"buildPass":{"val":"2","id":"pi"}},"id":"ct"}}
:enddata
:endrule

rule:
plugin=vanillaDoors
number=19
data:
JSON:{{"val":{"sideFlag":{"val":"0","id":"pb"},"blockName":{"val":"minecraft:iron_door","id":"ss"},"meta":{"val":"8","id":"pi"},"buildPass":{"val":"2","id":"pi"}},"id":"ct"}}
:enddata
:endrule

rule:
plugin=vanillaDoors
number=20
data:
JSON:{{"val":{"sideFlag":{"val":"0","id":"pb"},"blockName":{"val":"minecraft:iron_door","id":"ss"},"meta":{"val":"9","id":"pi"},"buildPass":{"val":"2","id":"pi"}},"id":"ct"}}
:enddata
:endrule

rule:
plugin=vanillaBlocks
number=21
data:
JSON:{{"val":{"blockName":{"val":"minecraft:torch","id":"ss"},"meta":{"val":"2","id":"pi"},"buildPass":{"val":"2","id":"pi"}},"id":"ct"}}
:enddata
:endrule

rule:
plugin=vanillaBlocks
number=22
data:
JSON:{{"val":{"blockName":{"val":"minecraft:oak_stairs","id":"ss"},"meta":{"val":"3","id":"pi"},"buildPass":{"val":"0","id":"pi"}},"id":"ct"}}
:enddata
:endrule

rule:
plugin=vanillaBlocks
number=23
data:
JSON:{{"val":{"blockName":{"val":"minecraft:torch","id":"ss"},"meta":{"val":"4","id":"pi"},"buildPass":{"val":"2","id":"pi"}},"id":"ct"}}
:enddata
:endrule

rule:
plugin=vanillaBlocks
number=24
data:
JSON:{{"val":{"blockName":{"val":"minecraft:oak_stairs","id":"ss"},"meta":{"val":"0","id":"pi"},"buildPass":{"val":"0","id":"pi"}},"id":"ct"}}
:enddata
:endrule

rule:
plugin=vanillaBlocks
number=25
data:
JSON:{{"val":{"blockName":{"val":"minecraft:oak_stairs","id":"ss"},"meta":{"val":"2","id":"pi"},"buildPass":{"val":"0","id":"pi"}},"id":"ct"}}
:enddata
:endrule

rule:
plugin=vanillaBlocks
number=26
data:
JSON:{{"val":{"blockName":{"val":"minecraft:gravel","id":"ss"},"meta":{"val":"0","id":"pi"},"buildPass":{"val":"0","id":"pi"}},"id":"ct"}}
:enddata
:endrule

rule:
plugin=vanillaBlocks
number=27
data:
JSON:{{"val":{"blockName":{"val":"minecraft:stone_brick_stairs","id":"ss"},"meta":{"val":"3","id":"pi"},"buildPass":{"val":"0","id":"pi"}},"id":"ct"}}
:enddata
:endrule

rule:
plugin=vanillaDoors
number=28
data:
JSON:{{"val":{"sideFlag":{"val":"8","id":"pb"},"blockName":{"val":"minecraft:iron_door","id":"ss"},"meta":{"val":"0","id":"pi"},"buildPass":{"val":"2","id":"pi"}},"id":"ct"}}
:enddata
:endrule

rule:
plugin=vanillaBlocks
number=29
data:
JSON:{{"val":{"blockName":{"val":"minecraft:stone_brick_stairs","id":"ss"},"meta":{"val":"1","id":"pi"},"buildPass":{"val":"0","id":"pi"}},"id":"ct"}}
:enddata
:endrule

rule:
plugin=vanillaInventory
number=30
data:
JSON:{{"val":{"lootLevel":{"val":"0","id":"pi"},"inventoryData":{"val":{"length":{"val":"27","id":"pi"},"inventoryContents":{"val":[],"id":"ls"}},"id":"ct"},"teData":{"val":{"id":{"val":"Chest","id":"ss"},"z":{"val":"1043","id":"pi"},"y":{"val":"76","id":"pi"},"x":{"val":"1612","id":"pi"}},"id":"ct"},"blockName":{"val":"minecraft:chest","id":"ss"},"meta":{"val":"5","id":"pi"},"buildPass":{"val":"0","id":"pi"}},"id":"ct"}}
:enddata
:endrule

rule:
plugin=vanillaInventory
number=31
data:
JSON:{{"val":{"lootLevel":{"val":"0","id":"pi"},"inventoryData":{"val":{"length":{"val":"27","id":"pi"},"inventoryContents":{"val":[],"id":"ls"}},"id":"ct"},"teData":{"val":{"id":{"val":"Chest","id":"ss"},"z":{"val":"1043","id":"pi"},"y":{"val":"76","id":"pi"},"x":{"val":"1614","id":"pi"}},"id":"ct"},"blockName":{"val":"minecraft:chest","id":"ss"},"meta":{"val":"5","id":"pi"},"buildPass":{"val":"0","id":"pi"}},"id":"ct"}}
:enddata
:endrule

rule:
plugin=vanillaBlocks
number=32
data:
JSON:{{"val":{"blockName":{"val":"minecraft:glass","id":"ss"},"meta":{"val":"0","id":"pi"},"buildPass":{"val":"0","id":"pi"}},"id":"ct"}}
:enddata
:endrule

rule:
plugin=vanillaDoors
number=33
data:
JSON:{{"val":{"sideFlag":{"val":"0","id":"pb"},"blockName":{"val":"minecraft:iron_door","id":"ss"},"meta":{"val":"8","id":"pi"},"buildPass":{"val":"2","id":"pi"}},"id":"ct"}}
:enddata
:endrule

rule:
plugin=vanillaBlocks
number=34
data:
JSON:{{"val":{"blockName":{"val":"minecraft:lever","id":"ss"},"meta":{"val":"0","id":"pi"},"buildPass":{"val":"2","id":"pi"}},"id":"ct"}}
:enddata
:endrule

rule:
plugin=vanillaBlocks
number=35
data:
JSON:{{"val":{"blockName":{"val":"minecraft:torch","id":"ss"},"meta":{"val":"3","id":"pi"},"buildPass":{"val":"2","id":"pi"}},"id":"ct"}}
:enddata
:endrule

rule:
plugin=vanillaBlocks
number=36
data:
JSON:{{"val":{"blockName":{"val":"minecraft:torch","id":"ss"},"meta":{"val":"1","id":"pi"},"buildPass":{"val":"2","id":"pi"}},"id":"ct"}}
:enddata
:endrule

rule:
plugin=vanillaBlocks
number=37
data:
JSON:{{"val":{"blockName":{"val":"minecraft:stone_brick_stairs","id":"ss"},"meta":{"val":"2","id":"pi"},"buildPass":{"val":"0","id":"pi"}},"id":"ct"}}
:enddata
:endrule

rule:
plugin=vanillaBlocks
number=38
data:
JSON:{{"val":{"blockName":{"val":"minecraft:stone_brick_stairs","id":"ss"},"meta":{"val":"5","id":"pi"},"buildPass":{"val":"0","id":"pi"}},"id":"ct"}}
:enddata
:endrule

rule:
plugin=vanillaBlocks
number=39
data:
JSON:{{"val":{"blockName":{"val":"minecraft:stone_brick_stairs","id":"ss"},"meta":{"val":"7","id":"pi"},"buildPass":{"val":"0","id":"pi"}},"id":"ct"}}
:enddata
:endrule

rule:
plugin=vanillaBlocks
number=40
data:
JSON:{{"val":{"blockName":{"val":"minecraft:stone_brick_stairs","id":"ss"},"meta":{"val":"6","id":"pi"},"buildPass":{"val":"0","id":"pi"}},"id":"ct"}}
:enddata
:endrule

rule:
plugin=vanillaBlocks
number=41
data:
JSON:{{"val":{"blockName":{"val":"minecraft:stone_brick_stairs","id":"ss"},"meta":{"val":"4","id":"pi"},"buildPass":{"val":"0","id":"pi"}},"id":"ct"}}
:enddata
:endrule

rule:
plugin=vanillaDoors
number=42
data:
JSON:{{"val":{"sideFlag":{"val":"8","id":"pb"},"blockName":{"val":"minecraft:wooden_door","id":"ss"},"meta":{"val":"2","id":"pi"},"buildPass":{"val":"2","id":"pi"}},"id":"ct"}}
:enddata
:endrule

rule:
plugin=vanillaBlocks
number=43
data:
JSON:{{"val":{"blockName":{"val":"minecraft:fence","id":"ss"},"meta":{"val":"0","id":"pi"},"buildPass":{"val":"0","id":"pi"}},"id":"ct"}}
:enddata
:endrule

rule:
plugin=vanillaBlocks
number=44
data:
JSON:{{"val":{"blockName":{"val":"minecraft:stone_slab","id":"ss"},"meta":{"val":"5","id":"pi"},"buildPass":{"val":"0","id":"pi"}},"id":"ct"}}
:enddata
:endrule

rule:
plugin=vanillaBlocks
number=45
data:
JSON:{{"val":{"blockName":{"val":"minecraft:torch","id":"ss"},"meta":{"val":"5","id":"pi"},"buildPass":{"val":"2","id":"pi"}},"id":"ct"}}
:enddata
:endrule

rule:
plugin=vanillaBlocks
number=46
data:
JSON:{{"val":{"blockName":{"val":"minecraft:stone_brick_stairs","id":"ss"},"meta":{"val":"0","id":"pi"},"buildPass":{"val":"0","id":"pi"}},"id":"ct"}}
:enddata
:endrule

rule:
plugin=vanillaDoors
number=47
data:
JSON:{{"val":{"sideFlag":{"val":"0","id":"pb"},"blockName":{"val":"minecraft:wooden_door","id":"ss"},"meta":{"val":"8","id":"pi"},"buildPass":{"val":"2","id":"pi"}},"id":"ct"}}
:enddata
:endrule

rule:
plugin=vanillaBlocks
number=48
data:
JSON:{{"val":{"blockName":{"val":"minecraft:glass_pane","id":"ss"},"meta":{"val":"0","id":"pi"},"buildPass":{"val":"0","id":"pi"}},"id":"ct"}}
:enddata
:endrule

rule:
plugin=vanillaInventory
number=49
data:
JSON:{{"val":{"lootLevel":{"val":"0","id":"pi"},"inventoryData":{"val":{"length":{"val":"27","id":"pi"},"inventoryContents":{"val":[],"id":"ls"}},"id":"ct"},"teData":{"val":{"id":{"val":"Chest","id":"ss"},"z":{"val":"1038","id":"pi"},"y":{"val":"97","id":"pi"},"x":{"val":"1609","id":"pi"}},"id":"ct"},"blockName":{"val":"minecraft:chest","id":"ss"},"meta":{"val":"3","id":"pi"},"buildPass":{"val":"0","id":"pi"}},"id":"ct"}}
:enddata
:endrule

rule:
plugin=vanillaInventory
number=50
data:
JSON:{{"val":{"lootLevel":{"val":"0","id":"pi"},"inventoryData":{"val":{"length":{"val":"27","id":"pi"},"inventoryContents":{"val":[],"id":"ls"}},"id":"ct"},"teData":{"val":{"id":{"val":"Chest","id":"ss"},"z":{"val":"1039","id":"pi"},"y":{"val":"97","id":"pi"},"x":{"val":"1609","id":"pi"}},"id":"ct"},"blockName":{"val":"minecraft:chest","id":"ss"},"meta":{"val":"3","id":"pi"},"buildPass":{"val":"0","id":"pi"}},"id":"ct"}}
:enddata
:endrule

rule:
plugin=vanillaInventory
number=51
data:
JSON:{{"val":{"lootLevel":{"val":"0","id":"pi"},"inventoryData":{"val":{"length":{"val":"27","id":"pi"},"inventoryContents":{"val":[],"id":"ls"}},"id":"ct"},"teData":{"val":{"id":{"val":"Chest","id":"ss"},"z":{"val":"1042","id":"pi"},"y":{"val":"102","id":"pi"},"x":{"val":"1615","id":"pi"}},"id":"ct"},"blockName":{"val":"minecraft:chest","id":"ss"},"meta":{"val":"2","id":"pi"},"buildPass":{"val":"0","id":"pi"}},"id":"ct"}}
:enddata
:endrule

#### ENTITIES ####
