# Ancient Warfare Structure Template File
# Auto-generated structure template file. created on: 11/24/2014 at: 22:31:25
# Lines beginning with # denote comments

header:
version=2.1
name=TownBlocksLargeManufactory
size=28,23,25
offset=9,4,24
:endheader

#### VALIDATION ####
validation:
type=ground
survival=false
worldGenEnabled=false
unique=false
preserveBlocks=false
selectionWeight=0
clusterValue=0
minDuplicateDistance=0
dimensionWhiteList=false
dimensionList=
biomeWhiteList=false
biomeList=
leveling=0
fill=0
border=0
validTargetBlocks=
blockSwap=false
data:
:enddata
:endvalidation

#### LAYERS ####
layer: 0
1,1,1,1,1,1,1,1,1,1,1,1,1,1,1,1,1,1,1,1,1,1,1,1,1,1,1,1
1,1,1,1,1,1,1,1,1,1,1,1,1,1,1,1,1,1,1,1,1,1,1,1,1,1,1,1
1,1,1,1,1,1,1,1,1,1,1,1,1,1,1,1,1,1,1,1,1,1,1,1,1,1,1,1
1,1,4,4,4,5,5,4,4,4,4,4,4,4,4,3,3,3,3,3,3,3,3,3,3,3,3,1
1,1,4,4,4,4,5,4,4,4,4,4,4,4,4,3,3,3,3,3,3,3,3,3,3,3,3,1
1,1,4,4,4,4,5,5,4,4,4,4,4,4,4,4,3,3,3,3,3,3,3,3,3,3,3,1
1,1,4,4,5,5,5,5,4,4,4,4,4,4,4,4,3,3,3,3,3,3,3,3,3,3,3,1
1,1,4,5,5,5,5,5,4,4,4,4,4,4,4,4,3,3,3,3,3,3,3,3,3,3,3,1
1,1,5,5,5,5,5,4,4,4,4,4,4,4,4,4,4,3,3,3,3,3,3,3,3,3,3,1
1,1,4,5,4,4,4,4,4,4,4,4,4,4,4,4,4,4,3,3,4,4,3,3,3,3,3,1
1,1,4,4,4,4,4,4,4,4,4,4,4,4,4,4,4,4,4,3,4,4,3,3,3,3,3,1
1,1,4,4,4,4,4,4,4,4,4,4,4,4,4,4,4,4,4,4,4,4,4,4,4,4,4,1
1,1,4,4,4,4,4,4,4,4,4,4,4,4,4,4,4,4,4,4,4,4,4,4,4,4,4,1
1,1,4,4,4,4,4,4,4,4,4,4,4,4,4,4,4,4,4,4,4,4,4,4,4,4,4,1
1,1,4,4,4,4,4,4,4,4,4,4,4,4,4,4,4,4,4,4,4,4,4,4,4,3,3,1
1,1,4,4,4,4,4,4,4,4,4,4,4,4,4,4,4,4,4,4,4,3,3,3,3,3,3,1
1,1,4,4,4,4,4,4,4,4,4,4,4,4,4,4,3,3,0,4,4,3,3,3,3,3,3,1
1,1,4,4,4,4,4,4,4,4,4,4,4,4,4,3,3,3,3,4,4,3,3,3,3,3,3,1
1,1,4,4,4,4,4,4,4,4,4,4,4,4,4,3,3,3,3,0,4,3,3,3,3,3,3,1
1,1,4,4,4,4,4,4,4,4,4,4,4,4,4,4,3,3,3,0,0,3,3,3,3,3,3,1
1,1,4,4,4,4,4,4,4,4,4,4,4,4,4,4,4,0,0,0,4,3,3,3,3,3,2,1
1,1,4,4,4,4,4,4,4,4,4,4,4,4,4,4,4,4,4,4,4,3,3,3,3,2,2,1
1,1,4,4,4,4,4,4,4,4,4,4,4,4,4,4,4,4,4,4,4,3,3,3,3,2,2,1
1,1,4,4,4,4,5,4,4,4,4,4,4,4,4,4,4,4,4,4,4,3,3,3,3,3,2,1
1,1,1,1,1,1,1,1,1,1,1,1,1,1,1,1,1,1,1,1,1,1,1,1,1,1,1,1
:endlayer
layer: 1
1,1,1,1,1,1,1,1,1,1,1,1,1,1,1,1,1,1,1,1,1,1,1,1,1,1,1,1
1,1,1,1,1,1,1,1,1,1,1,1,1,1,1,1,1,1,1,1,1,1,1,1,1,1,1,1
1,1,1,1,1,1,1,1,1,1,1,1,1,1,1,1,1,1,1,1,1,1,1,1,1,1,1,1
1,1,4,4,4,4,4,4,4,4,4,4,4,4,4,4,3,3,3,3,3,3,3,3,3,3,3,1
1,1,4,4,4,4,4,4,4,4,4,4,4,4,4,4,3,3,3,3,3,3,3,3,3,3,3,1
1,1,4,4,4,4,4,4,4,4,4,4,4,4,4,4,3,3,3,3,3,3,3,3,3,3,3,1
1,1,4,4,4,4,4,4,4,4,4,4,4,4,4,4,4,3,3,3,4,4,3,3,3,3,3,1
1,1,4,4,4,4,4,4,4,4,4,4,4,4,4,4,4,3,3,4,4,4,3,3,3,3,3,1
1,1,4,4,4,4,4,4,4,4,4,4,4,4,4,4,4,4,4,4,4,4,4,3,3,3,3,1
1,1,4,4,4,4,4,4,4,4,4,4,4,4,4,4,4,4,4,4,4,4,4,3,3,3,3,1
1,1,4,4,4,4,4,4,4,4,4,4,4,4,4,4,4,4,4,4,4,4,4,3,3,3,3,1
1,1,4,4,4,4,4,4,4,4,4,4,4,4,4,4,4,4,4,4,4,4,4,3,3,3,3,1
1,1,4,4,4,4,4,4,4,4,4,4,4,4,4,4,4,4,4,4,4,4,4,4,4,4,3,1
1,1,4,4,4,4,4,4,4,4,4,4,4,4,4,4,4,4,4,4,4,4,4,4,4,4,3,1
1,1,4,4,4,4,4,4,4,4,4,4,4,4,4,4,4,4,4,4,4,4,4,4,3,4,4,1
1,1,4,4,4,4,4,4,4,4,4,4,4,4,4,4,4,4,4,4,4,3,3,3,3,4,4,1
1,1,4,4,4,4,4,4,4,4,4,4,4,4,4,4,3,3,4,4,4,4,3,3,4,4,4,1
1,1,4,4,4,4,4,4,4,4,4,4,4,4,4,3,3,3,3,4,4,4,4,3,4,4,4,1
1,1,4,4,4,4,4,4,4,4,4,4,4,4,4,3,3,3,3,4,4,4,4,3,4,4,4,1
1,1,4,4,4,4,4,4,4,4,4,4,4,4,4,4,3,3,3,4,4,4,4,3,3,4,4,1
1,1,4,4,4,4,4,4,4,4,4,4,4,4,4,4,4,4,4,4,4,4,3,3,3,4,4,1
1,1,4,4,4,4,4,4,4,4,4,4,4,4,4,4,4,4,4,4,4,4,3,3,3,3,3,1
1,1,4,4,4,4,4,4,4,4,4,4,4,4,4,4,4,4,4,4,4,4,3,3,3,3,3,1
1,1,4,4,4,4,4,4,4,4,4,4,4,4,4,4,4,4,4,4,4,4,4,3,3,3,3,1
1,1,1,1,1,1,1,1,1,1,1,1,1,1,1,1,1,1,1,1,1,1,1,1,1,1,1,1
:endlayer
layer: 2
1,1,1,1,1,1,1,1,1,1,1,1,1,1,1,1,1,1,1,1,1,1,1,1,1,1,1,1
1,1,1,1,1,1,1,1,1,1,1,1,1,1,1,1,1,1,1,1,1,1,1,1,1,1,1,1
1,1,1,1,1,1,1,1,1,1,1,1,1,1,1,1,1,1,1,1,1,1,1,1,1,1,1,1
1,1,4,4,4,4,1,1,1,1,1,4,4,4,4,4,4,3,3,3,3,3,3,3,3,3,3,1
1,1,4,4,4,4,1,1,1,1,1,4,4,4,4,4,4,3,3,3,3,3,3,3,3,3,3,1
1,1,4,4,4,4,1,1,1,1,1,4,4,4,4,4,4,3,3,3,3,3,3,3,3,3,3,1
1,1,4,4,4,4,1,1,1,1,1,4,4,4,4,4,4,4,3,3,4,4,3,3,3,3,3,1
1,1,4,4,4,4,1,1,1,1,1,4,4,4,4,4,4,4,4,6,4,4,4,3,3,3,3,1
1,1,4,4,4,4,1,1,1,1,1,4,4,4,4,4,4,4,4,4,4,4,4,3,3,3,3,1
1,1,4,4,4,4,1,1,1,1,1,4,4,4,4,4,4,4,4,4,4,4,4,3,3,3,3,1
1,1,4,4,4,4,1,1,1,1,1,4,4,4,4,4,4,4,4,4,4,4,4,3,3,3,3,1
1,1,4,4,4,4,1,1,1,1,1,4,4,4,4,4,4,4,4,4,4,4,4,3,3,3,3,1
1,1,4,4,4,4,1,1,1,1,1,4,4,4,4,4,4,4,4,4,4,4,4,3,3,4,4,1
1,1,4,4,4,4,1,1,1,1,1,4,4,4,4,4,4,4,4,4,4,4,4,4,4,4,4,1
1,1,4,4,4,4,1,1,1,1,1,4,4,4,4,4,4,4,4,4,4,4,4,4,4,4,4,1
1,1,4,4,4,4,1,1,1,1,1,4,4,4,4,4,4,4,4,4,4,4,4,4,4,4,4,1
1,1,4,4,4,4,1,1,1,1,1,4,4,4,4,4,3,3,4,4,4,4,4,4,4,4,4,1
1,1,4,4,4,4,1,1,1,1,1,4,4,4,4,3,3,3,3,4,4,4,4,4,4,4,4,1
1,1,4,4,4,4,1,1,1,1,1,4,4,4,4,3,3,3,3,4,4,4,4,4,4,4,4,1
1,1,4,4,4,4,1,1,1,1,1,4,4,4,4,4,3,3,3,4,4,4,4,4,4,4,4,1
1,1,4,4,4,4,1,1,1,1,1,4,4,4,4,4,4,4,4,4,4,4,4,4,4,4,4,1
1,1,4,4,4,4,1,1,1,1,1,4,4,4,4,4,4,4,4,4,4,4,4,4,4,4,4,1
1,1,4,4,4,4,4,4,4,4,4,4,4,4,4,4,4,4,4,4,4,4,4,4,4,3,3,1
1,1,4,4,4,4,4,4,4,4,4,4,4,4,4,4,4,4,4,4,4,4,4,4,4,3,3,1
1,1,1,1,1,1,1,1,1,1,1,1,1,1,1,1,1,1,1,1,1,1,1,1,1,1,1,1
:endlayer
layer: 3
1,1,1,1,1,1,1,1,1,1,1,1,1,1,1,1,1,1,1,1,1,1,1,1,1,1,1,1
1,1,1,1,1,1,1,1,1,1,1,1,1,1,1,1,1,1,1,1,1,1,1,1,1,1,1,1
1,1,1,1,1,1,1,1,1,1,1,1,1,1,1,1,1,1,1,1,1,1,1,1,1,1,1,1
1,1,4,4,4,4,1,1,1,1,1,4,4,4,4,4,4,3,3,3,3,3,3,3,3,3,3,1
1,1,4,4,4,4,1,1,1,1,1,4,4,4,4,4,4,4,4,3,3,3,3,3,3,3,3,1
1,1,4,4,4,4,1,1,1,1,1,4,4,4,4,4,4,4,4,3,3,3,3,3,3,3,3,1
1,1,4,4,4,4,1,1,1,1,1,4,4,4,4,4,4,4,4,4,4,3,3,6,3,4,3,1
1,1,4,4,4,4,1,1,1,1,1,4,4,4,4,4,4,4,4,4,4,4,3,6,4,4,4,1
1,1,4,4,4,4,1,1,1,1,1,4,4,4,4,4,4,4,4,4,4,4,4,4,4,4,4,1
1,1,4,4,4,4,1,1,1,1,1,4,4,4,4,4,4,4,4,4,4,4,4,4,4,4,4,1
1,1,4,4,4,4,1,1,1,1,1,4,4,4,4,4,4,4,4,4,4,4,4,4,4,4,4,1
1,1,4,4,4,4,1,1,1,1,1,4,4,4,4,4,4,4,4,4,4,4,4,4,4,4,4,1
1,1,1,1,4,4,1,1,1,1,1,4,4,4,4,4,4,4,4,4,4,4,4,4,4,4,4,1
1,1,1,1,4,4,1,1,1,1,1,4,4,4,4,4,4,4,4,4,4,4,4,4,4,4,4,1
1,1,1,1,4,4,1,1,1,1,1,4,4,4,4,4,4,4,4,4,4,4,4,4,4,4,4,1
1,1,1,1,4,4,1,1,1,1,1,4,4,4,4,4,4,4,4,4,4,4,4,4,4,4,4,1
1,1,1,1,4,4,1,1,1,1,1,4,4,4,4,4,3,3,4,4,4,4,4,4,4,4,4,1
1,1,1,1,4,4,1,1,1,1,1,4,4,4,4,3,3,3,3,4,4,4,4,4,4,4,4,1
1,1,1,1,4,4,1,1,1,1,1,4,4,4,4,3,3,3,3,4,4,4,4,4,4,4,4,1
1,1,1,1,4,4,1,1,1,1,1,4,4,4,4,4,3,3,3,4,4,4,4,4,4,4,4,1
1,1,1,1,4,4,1,1,1,1,1,4,4,4,4,4,4,4,4,4,4,4,4,4,4,4,4,1
1,1,1,1,4,4,1,1,1,1,1,4,4,4,4,4,4,4,4,4,4,4,4,4,4,4,4,1
1,1,1,1,4,4,1,1,1,1,1,4,4,4,4,4,4,4,4,4,4,4,4,4,4,4,4,1
1,1,1,1,4,4,1,1,1,1,1,4,4,4,4,4,4,4,4,4,4,4,4,4,4,4,4,1
1,1,1,1,1,1,1,1,1,1,1,1,1,1,1,1,1,1,1,1,1,1,1,1,1,1,1,1
:endlayer
layer: 4
2,2,2,2,2,2,2,2,2,2,2,2,2,2,2,2,2,2,2,2,2,2,2,2,2,2,2,2
2,2,2,2,2,2,2,2,2,2,2,2,2,2,2,2,2,2,2,2,2,2,2,2,2,2,2,2
2,2,2,1,1,1,1,1,1,1,1,1,1,1,1,1,1,1,1,1,1,1,1,1,1,2,2,2
2,2,2,1,7,7,1,1,1,1,1,7,7,7,7,7,7,7,7,7,7,7,7,7,4,2,2,2
2,2,2,1,7,7,1,1,1,1,1,7,7,7,7,7,7,7,7,7,7,7,7,7,4,2,2,2
2,2,2,4,7,7,1,1,1,1,1,7,7,7,7,7,7,7,7,7,7,7,7,7,4,2,2,2
2,2,2,1,7,7,1,1,1,1,1,7,7,7,7,7,7,7,7,7,7,7,7,7,4,2,2,2
2,2,2,1,7,7,1,1,1,1,1,7,7,7,7,7,7,7,7,7,7,7,7,7,4,2,2,2
2,2,2,1,7,7,1,1,1,1,1,7,7,7,7,7,7,7,7,7,7,7,7,7,4,2,2,2
2,2,2,4,7,7,1,1,1,1,1,7,7,7,7,7,7,7,7,7,7,7,7,7,4,2,2,2
2,2,2,1,7,7,1,1,1,1,1,7,7,7,7,7,7,7,7,7,7,7,7,7,4,2,2,2
2,2,2,1,7,7,1,1,1,1,1,7,7,7,7,7,7,7,7,7,7,7,7,7,4,2,2,2
2,2,2,1,7,7,1,1,1,1,1,4,7,7,7,4,7,7,4,7,7,4,7,7,4,2,2,2
2,2,2,1,7,7,1,1,1,1,1,7,7,7,7,7,7,7,7,7,7,7,7,7,4,2,2,2
2,2,2,1,7,7,1,1,1,1,1,7,7,7,7,7,7,7,7,7,7,7,7,7,4,2,2,2
2,2,2,1,7,7,1,1,1,1,1,7,7,7,7,7,7,7,7,7,7,7,7,7,4,2,2,2
2,2,2,1,7,7,1,1,1,1,1,7,7,7,7,7,3,3,7,7,7,7,7,7,4,2,2,2
2,2,2,1,7,7,1,1,1,1,1,7,7,7,7,3,3,3,3,1,1,1,1,1,4,2,2,2
2,2,2,1,7,7,1,1,1,1,1,7,7,7,7,3,3,3,3,1,1,1,1,1,4,2,2,2
2,2,2,1,7,7,1,1,1,1,1,7,7,7,7,7,3,3,3,1,1,1,1,1,1,2,2,2
2,2,2,1,7,7,1,1,1,1,1,7,7,7,7,7,7,7,7,1,1,1,1,1,4,2,2,2
2,2,2,1,7,7,1,1,1,1,1,4,4,4,4,4,4,4,4,4,4,4,4,4,4,2,2,2
2,2,2,2,2,2,2,2,2,2,2,2,2,2,2,2,2,2,2,2,2,2,2,2,2,2,2,2
2,2,2,2,2,2,2,2,2,2,2,2,2,2,2,2,2,2,2,2,2,2,2,2,2,2,2,2
2,2,2,2,2,2,2,2,2,2,2,2,2,2,2,2,2,2,2,2,2,2,2,2,2,2,2,2
:endlayer
layer: 5
0,0,0,0,0,0,0,0,0,0,0,0,0,0,0,0,0,0,0,0,0,0,0,0,0,0,0,0
0,0,0,0,0,0,0,0,0,0,0,0,0,0,0,0,0,0,0,0,0,0,0,0,0,0,0,0
0,0,0,0,10,10,8,8,8,8,8,8,8,8,8,8,8,8,8,8,8,8,8,8,8,0,0,0
0,0,0,0,10,10,8,0,0,0,8,10,10,10,10,10,10,10,10,10,10,10,10,10,8,0,0,0
0,0,0,0,10,10,8,0,0,0,0,10,10,10,10,10,10,10,10,10,10,10,10,10,8,0,0,0
0,0,0,8,10,10,8,0,0,0,0,10,10,10,10,10,10,10,10,10,10,10,10,10,8,0,0,0
0,0,0,0,10,10,8,8,0,0,8,10,10,10,10,10,10,10,10,10,10,10,10,10,8,0,0,0
0,0,0,0,10,10,8,8,0,13,0,10,10,10,10,10,10,10,10,10,10,10,10,10,8,0,0,0
0,0,0,0,10,10,8,12,0,0,0,10,10,10,10,10,10,10,10,10,10,10,10,10,8,0,0,0
0,0,0,8,10,10,8,0,0,0,8,10,10,10,10,10,10,10,10,10,10,10,10,10,8,0,0,0
0,0,0,0,10,10,8,0,0,0,0,10,10,10,10,10,10,10,10,10,10,10,10,10,8,0,0,0
0,0,0,0,10,10,8,0,0,0,0,10,10,10,10,10,10,10,10,10,10,10,10,10,8,0,0,0
0,0,0,0,10,10,8,0,0,0,8,8,10,10,10,8,10,10,8,10,10,8,10,10,8,0,0,0
0,0,0,8,10,10,8,0,0,0,0,10,10,10,10,10,10,10,10,10,10,10,10,10,8,0,0,0
0,0,0,0,10,10,8,0,0,0,0,10,10,10,10,10,10,10,10,10,10,10,10,10,8,0,0,0
0,0,0,0,10,10,8,0,0,0,8,10,10,10,10,10,10,10,10,10,10,10,10,10,8,0,0,0
0,0,0,0,10,10,8,0,0,0,0,10,10,10,10,10,10,10,10,10,10,10,10,10,8,0,0,0
0,0,0,8,10,10,8,0,0,0,0,10,10,10,10,10,10,10,10,8,8,9,8,8,8,0,0,0
0,0,0,0,10,10,8,0,0,0,8,10,10,10,10,10,10,10,10,8,0,0,0,0,8,0,0,0
0,0,0,0,10,10,8,0,0,0,0,10,10,10,10,10,10,10,10,8,0,0,0,0,11,0,0,0
0,0,0,0,10,10,8,0,0,0,8,10,10,10,10,10,10,10,10,8,0,0,0,0,8,0,0,0
0,0,0,8,10,10,8,8,9,8,8,8,8,8,8,8,8,8,8,8,8,8,8,8,8,0,0,0
0,0,0,0,0,0,0,0,0,0,0,0,0,0,0,0,0,0,0,0,0,0,0,0,0,0,0,0
0,0,0,0,0,0,0,0,0,0,0,0,0,0,0,0,0,0,0,0,0,0,0,0,0,0,0,0
0,0,0,0,0,0,0,0,0,0,0,0,0,0,0,0,0,0,0,0,0,0,0,0,0,0,0,0
:endlayer
layer: 6
0,0,0,0,0,0,0,0,0,0,0,0,0,0,0,0,0,0,0,0,0,0,0,0,0,0,0,0
0,0,0,0,0,0,0,0,0,0,0,0,0,0,0,0,0,0,0,0,0,0,0,0,0,0,0,0
0,0,0,0,0,0,8,8,16,8,8,8,8,8,8,8,8,8,8,8,8,8,8,8,8,0,0,0
0,0,0,0,0,0,8,0,0,0,8,18,0,0,0,0,0,0,0,0,0,0,0,0,8,0,0,0
0,0,0,0,0,0,8,0,0,0,0,0,0,0,0,0,0,0,0,0,0,0,0,0,8,0,0,0
0,0,0,8,0,0,8,0,0,0,0,0,0,0,0,0,0,0,0,0,0,0,0,0,8,0,0,0
0,0,0,0,0,0,8,8,0,0,8,0,0,0,0,0,0,0,0,0,0,0,0,0,8,0,0,0
0,0,0,0,0,0,16,12,0,0,0,0,0,0,0,0,0,0,0,0,0,0,0,0,8,0,0,0
0,0,0,0,0,0,8,0,0,0,0,0,0,0,0,0,0,0,0,0,0,0,0,0,8,0,0,0
0,0,0,8,0,0,8,0,0,0,8,0,0,0,0,0,0,0,0,0,0,0,0,0,8,0,0,0
0,0,0,0,0,0,8,0,0,0,0,0,0,0,0,0,0,0,0,0,0,0,0,0,8,0,0,0
0,0,0,0,0,0,16,0,0,0,0,0,0,0,0,0,0,0,0,0,0,0,0,0,8,0,0,0
0,0,0,0,0,0,8,0,0,0,8,8,0,0,0,8,0,0,8,0,0,8,0,0,8,0,0,0
0,0,0,8,0,0,8,0,0,0,0,0,0,0,0,0,0,0,0,0,0,0,0,0,8,0,0,0
0,0,0,0,0,0,8,0,0,0,0,0,0,0,0,0,0,0,0,0,0,0,0,0,8,0,0,0
0,0,0,0,0,0,16,0,0,0,8,0,0,0,0,0,0,0,0,0,0,0,0,0,8,0,0,0
0,0,0,0,0,0,8,0,0,0,0,0,0,0,0,0,0,0,0,0,0,0,0,0,8,0,0,0
0,0,0,8,0,0,8,0,0,0,0,0,0,0,0,0,0,0,0,8,8,17,8,8,8,0,0,0
0,0,0,0,0,0,8,0,0,0,8,0,0,0,0,0,0,0,0,8,0,0,0,0,8,0,0,0
0,0,0,0,0,0,16,0,0,0,0,0,0,0,0,0,0,0,0,8,0,0,0,0,15,0,0,0
0,0,0,0,0,0,8,0,0,0,8,0,0,0,0,0,0,0,0,8,0,0,0,0,8,0,0,0
0,0,0,8,0,0,8,8,14,8,8,8,8,8,8,8,8,8,8,8,8,8,8,8,8,0,0,0
0,0,0,0,0,0,0,0,0,0,0,0,0,0,0,0,0,0,0,0,0,0,0,0,0,0,0,0
0,0,0,0,0,0,0,0,0,0,0,0,0,0,0,0,0,0,0,0,0,0,0,0,0,0,0,0
0,0,0,0,0,0,0,0,0,0,0,0,0,0,0,0,0,0,0,0,0,0,0,0,0,0,0,0
:endlayer
layer: 7
0,0,0,0,0,0,0,0,0,0,0,0,0,0,0,0,0,0,0,0,0,0,0,0,0,0,0,0
0,0,0,0,0,0,0,0,0,0,0,0,0,0,0,0,0,0,0,0,0,0,0,0,0,0,0,0
0,0,0,0,0,0,8,8,16,8,8,8,16,8,16,8,16,8,16,8,16,8,16,8,8,0,0,0
0,0,0,0,0,0,8,8,0,20,8,0,0,0,0,0,0,0,0,0,0,0,0,18,8,0,0,0
0,0,0,0,0,0,8,8,0,0,18,0,0,0,0,0,0,0,0,0,0,0,0,0,16,0,0,0
0,0,20,8,19,0,8,8,0,0,0,0,0,0,0,0,0,0,0,0,0,0,0,0,8,0,0,0
0,0,0,0,0,0,8,12,0,0,8,0,0,0,0,0,0,0,0,0,0,0,0,0,16,0,0,0
0,0,0,0,0,0,16,0,0,0,18,0,0,0,0,0,0,0,0,0,0,0,0,0,8,0,0,0
0,0,0,0,0,0,8,0,0,0,0,0,0,0,0,0,0,0,0,0,0,0,0,0,16,0,0,0
0,0,20,8,19,0,8,0,0,0,8,0,0,0,0,0,0,0,0,0,0,0,0,0,8,0,0,0
0,0,0,0,0,0,8,0,0,0,0,0,0,0,0,0,0,0,0,0,0,0,0,0,16,0,0,0
0,0,0,0,0,0,16,0,0,0,21,0,0,0,0,0,0,0,0,0,0,0,0,0,8,0,0,0
0,0,0,0,0,0,8,0,0,0,8,8,19,0,20,8,19,20,8,19,20,8,19,0,16,0,0,0
0,0,20,8,19,0,8,0,0,0,18,0,0,0,0,0,0,0,0,0,0,0,0,0,8,0,0,0
0,0,0,0,0,0,8,0,0,0,0,0,0,0,0,0,0,0,0,0,0,0,0,0,16,0,0,0
0,0,0,0,0,0,16,0,0,0,8,0,0,0,0,0,0,0,0,0,0,0,0,0,8,0,0,0
0,0,0,0,0,0,8,0,0,0,0,0,0,0,0,0,0,0,0,0,0,21,0,0,16,0,0,0
0,0,20,8,19,0,8,0,0,0,21,0,0,0,0,0,0,0,0,8,8,8,8,8,8,0,0,0
0,0,0,0,0,0,8,0,0,0,8,0,0,0,0,0,0,0,0,8,0,0,0,0,8,0,0,0
0,0,0,0,0,0,16,0,0,0,0,0,0,0,0,0,0,0,0,8,0,0,0,20,8,19,0,0
0,0,0,0,0,0,8,0,21,0,8,0,0,0,0,0,0,0,0,8,0,21,0,0,8,0,0,0
0,0,20,8,19,0,8,8,8,8,8,8,16,8,16,8,16,8,16,8,16,8,16,8,8,0,0,0
0,0,0,18,0,0,0,0,18,0,0,0,0,0,0,0,0,0,0,0,0,0,0,0,0,0,0,0
0,0,0,0,0,0,0,0,0,0,0,0,0,0,0,0,0,0,0,0,0,0,0,0,0,0,0,0
0,0,0,0,0,0,0,0,0,0,0,0,0,0,0,0,0,0,0,0,0,0,0,0,0,0,0,0
:endlayer
layer: 8
0,0,0,0,0,0,0,0,0,0,0,0,0,0,0,0,0,0,0,0,0,0,0,0,0,0,0,0
0,0,0,0,0,0,21,0,0,0,0,0,0,0,0,0,0,0,0,0,0,0,0,0,21,0,0,0
0,0,0,0,0,20,8,8,16,8,8,8,16,8,16,8,16,8,16,8,16,8,16,8,8,19,0,0
0,0,0,0,0,0,8,8,0,0,8,0,0,0,0,0,0,0,0,0,0,0,0,0,8,0,0,0
0,0,0,0,0,0,8,8,0,0,8,0,0,0,0,0,0,0,0,0,0,0,0,0,16,0,0,0
0,0,0,8,0,0,8,12,0,0,8,0,0,0,0,0,0,0,0,0,0,0,0,0,8,19,0,0
0,0,0,0,0,0,8,0,0,0,8,0,0,0,0,0,0,0,0,0,0,0,0,0,16,0,0,0
0,0,0,0,0,0,16,0,0,0,8,0,0,0,0,0,0,0,0,0,0,0,0,0,8,19,0,0
0,0,0,0,0,0,8,0,0,0,8,0,0,0,0,0,0,0,0,0,0,0,0,0,16,0,0,0
0,0,0,8,0,0,8,0,0,0,8,0,0,0,0,0,0,0,0,0,0,0,0,0,8,19,0,0
0,0,0,0,0,0,8,0,0,0,8,0,0,0,0,0,0,0,0,0,0,0,0,0,16,0,0,0
0,0,0,0,0,0,16,0,0,0,8,0,0,0,0,0,0,0,0,0,0,0,0,0,8,19,0,0
0,0,0,0,0,0,8,0,0,0,8,8,0,0,0,8,0,0,8,0,0,8,0,0,16,0,0,0
0,0,0,8,0,0,8,0,0,0,8,0,0,0,0,0,0,0,0,0,0,0,0,0,8,19,0,0
0,0,0,0,0,0,8,19,0,0,8,0,0,0,0,0,0,0,0,0,0,0,0,0,16,0,0,0
0,0,0,0,0,0,16,0,0,0,8,0,0,0,0,0,0,0,0,0,0,0,0,0,8,19,0,0
0,0,0,0,0,0,8,0,0,0,8,0,0,0,0,0,0,0,0,21,0,0,0,21,16,0,0,0
0,0,0,8,0,0,8,0,0,0,8,0,0,0,0,0,0,0,20,8,8,8,8,8,8,19,0,0
0,0,0,0,0,0,8,0,0,20,8,0,0,0,0,0,0,0,0,8,0,0,0,0,8,0,0,0
0,0,0,0,0,0,16,0,0,0,8,0,0,0,0,0,0,0,0,8,0,0,0,0,8,0,0,0
0,0,0,0,0,0,8,0,0,0,8,0,0,0,0,0,0,0,0,8,0,0,0,0,8,0,0,0
0,0,0,8,0,20,8,8,8,8,8,8,16,8,16,8,16,8,16,8,16,8,16,8,8,19,0,0
0,0,0,0,0,0,18,0,0,0,0,18,0,18,0,18,0,18,0,18,0,18,0,0,18,0,0,0
0,0,0,0,0,0,0,0,0,0,0,0,0,0,0,0,0,0,0,0,0,0,0,0,0,0,0,0
0,0,0,0,0,0,0,0,0,0,0,0,0,0,0,0,0,0,0,0,0,0,0,0,0,0,0,0
:endlayer
layer: 9
0,0,0,0,0,0,0,0,0,0,0,0,0,0,0,0,0,0,0,0,0,0,0,0,0,0,0,0
0,0,0,0,0,0,0,0,0,0,0,0,0,0,0,0,0,0,0,0,0,0,0,0,0,0,0,0
0,0,0,0,0,0,8,8,8,8,8,8,16,8,16,8,16,8,16,8,16,8,16,8,8,0,0,0
0,0,0,0,0,0,8,8,8,8,8,0,0,18,0,0,0,18,0,0,0,18,0,0,8,0,0,0
0,0,24,25,25,25,8,12,8,8,8,0,0,0,0,0,0,0,0,0,0,0,0,0,16,0,0,0
0,0,24,8,8,8,8,0,8,8,8,0,0,0,0,0,0,0,0,0,0,0,0,0,8,0,0,0
0,0,24,8,8,8,8,0,8,8,8,0,0,0,0,0,0,0,0,0,0,0,0,0,16,0,0,0
0,0,24,8,8,8,8,0,8,8,8,0,0,0,0,0,0,0,0,0,0,0,0,20,8,0,0,0
0,0,24,8,8,8,8,8,8,8,8,0,0,0,0,0,0,0,0,0,0,0,0,0,16,0,0,0
0,0,24,8,8,8,8,8,8,8,8,0,0,0,0,0,0,0,0,0,0,0,0,20,8,0,0,0
0,0,24,8,8,8,8,8,8,8,8,0,0,0,0,0,0,0,0,0,0,0,0,0,16,0,0,0
0,0,24,8,8,8,8,8,8,8,8,0,0,0,0,0,0,0,0,0,0,0,0,0,8,0,0,0
0,0,24,8,8,8,8,8,8,8,8,8,0,0,0,8,0,0,8,0,0,8,0,0,16,0,0,0
0,0,24,8,8,8,8,8,8,8,8,0,0,0,0,0,0,0,0,0,0,0,0,0,8,0,0,0
0,0,24,8,8,8,8,8,8,8,8,0,0,0,0,0,0,0,0,0,0,0,0,0,16,0,0,0
0,0,24,8,8,8,8,8,8,8,8,0,0,0,0,0,0,0,0,0,0,0,0,0,8,0,0,0
0,0,24,8,8,8,8,8,8,8,8,0,0,0,0,0,0,0,0,0,0,0,0,0,16,0,0,0
0,0,24,8,8,8,8,8,8,8,8,0,0,0,0,0,0,0,0,8,8,8,8,8,8,0,0,0
0,0,24,8,8,8,8,8,8,8,8,0,0,0,0,0,0,0,0,8,0,0,0,0,8,0,0,0
0,0,24,8,8,8,8,8,8,8,8,0,0,0,0,0,0,0,0,8,0,0,0,0,8,0,0,0
0,0,24,8,8,8,8,8,8,8,8,0,0,0,0,0,0,0,0,8,0,0,0,0,8,0,0,0
0,0,24,8,8,8,8,8,8,8,8,8,16,8,16,8,16,8,16,8,16,8,16,8,8,0,0,0
0,0,24,23,23,23,23,23,23,23,22,0,0,0,0,0,0,0,0,0,0,0,0,0,0,0,0,0
0,0,0,0,0,0,0,0,0,0,0,0,0,0,0,0,0,0,0,0,0,0,0,0,0,0,0,0
0,0,0,0,0,0,0,0,0,0,0,0,0,0,0,0,0,0,0,0,0,0,0,0,0,0,0,0
:endlayer
layer: 10
0,0,0,0,0,0,0,0,0,0,0,0,0,0,0,0,0,0,0,0,0,0,0,0,0,0,0,0
0,0,0,0,0,0,0,0,0,0,0,0,0,0,0,0,0,0,0,0,0,0,0,0,0,0,0,0
0,0,0,0,0,0,8,8,8,8,8,8,8,8,8,8,8,8,8,8,8,8,8,8,8,0,0,0
0,0,0,0,0,0,8,0,0,0,8,19,0,0,0,0,0,0,0,0,0,0,0,0,8,0,0,0
0,0,0,0,0,0,8,0,0,0,8,0,0,0,0,0,0,0,0,0,0,0,0,0,8,0,0,0
0,0,0,8,8,8,8,0,0,0,8,0,0,0,0,0,0,0,0,0,0,0,0,0,8,0,0,0
0,0,0,8,0,0,0,0,0,0,8,19,0,0,0,0,0,0,0,0,0,0,0,0,8,0,0,0
0,0,0,8,0,0,0,0,0,0,8,0,0,0,0,0,0,0,0,0,0,0,0,0,8,0,0,0
0,0,0,8,0,0,0,0,0,0,27,0,0,0,0,0,0,0,0,0,0,0,0,0,8,0,0,0
0,0,0,8,0,0,0,0,0,0,27,0,0,0,0,0,0,0,0,0,0,0,0,0,8,0,0,0
0,0,0,8,0,0,0,0,0,0,27,0,0,0,0,0,0,0,0,0,0,0,0,0,8,0,0,0
0,0,0,8,0,0,0,0,0,0,27,0,0,0,0,21,0,0,21,0,0,21,0,0,8,0,0,0
0,0,0,8,8,8,8,8,26,8,8,8,19,0,20,8,19,20,8,19,20,8,19,20,8,0,0,0
0,0,0,8,0,0,0,0,0,0,8,0,0,0,0,18,0,0,18,0,0,18,0,0,8,0,0,0
0,0,0,8,0,0,0,0,0,0,8,19,0,0,0,0,0,0,0,0,0,0,0,0,8,0,0,0
0,0,0,8,0,0,0,0,0,0,8,0,0,0,0,0,0,0,0,0,0,0,0,0,8,0,0,0
0,0,0,8,0,0,0,0,0,0,8,0,0,0,0,0,0,0,0,0,0,0,0,0,8,0,0,0
0,0,0,8,0,0,0,0,0,0,8,19,0,0,0,0,0,0,0,8,8,8,8,8,8,0,0,0
0,0,0,8,0,0,0,0,0,0,8,0,0,0,0,0,0,0,0,8,0,0,0,0,8,0,0,0
0,0,0,8,0,0,0,0,0,0,8,0,0,0,0,0,0,0,0,8,0,0,0,0,8,0,0,0
0,0,0,8,0,0,0,0,0,0,8,19,0,0,21,0,0,21,0,8,0,21,0,0,8,0,0,0
0,0,0,8,8,8,8,8,8,8,8,8,8,8,8,8,8,8,8,8,8,8,8,8,8,0,0,0
0,0,0,0,0,0,0,0,0,0,0,0,0,0,0,0,0,0,0,0,0,0,0,0,0,0,0,0
0,0,0,0,0,0,0,0,0,0,0,0,0,0,0,0,0,0,0,0,0,0,0,0,0,0,0,0
0,0,0,0,0,0,0,0,0,0,0,0,0,0,0,0,0,0,0,0,0,0,0,0,0,0,0,0
:endlayer
layer: 11
0,0,0,0,0,0,0,0,0,0,0,0,0,0,0,0,0,0,0,0,0,0,0,0,0,0,0,0
0,0,0,0,0,0,0,0,0,0,0,0,0,0,0,0,0,0,0,0,0,0,0,0,0,0,0,0
0,0,0,0,0,0,8,8,16,8,8,25,25,25,25,25,25,25,25,25,25,25,25,25,25,25,0,0
0,0,0,0,0,0,8,0,0,0,8,0,0,0,0,0,0,0,0,0,0,0,0,0,8,0,0,0
0,0,0,0,0,0,8,0,0,0,8,0,0,0,0,0,0,0,0,0,0,0,0,0,16,0,0,0
0,0,0,8,8,8,8,0,0,0,8,0,0,0,0,0,0,0,0,0,0,0,0,0,8,0,0,0
0,0,0,8,0,0,0,0,0,0,8,28,23,23,23,23,23,23,23,23,23,23,23,23,23,23,0,0
0,0,0,16,0,0,0,0,0,0,8,25,25,25,25,25,25,25,25,25,25,25,25,25,25,25,0,0
0,0,0,8,0,0,0,0,0,0,0,0,0,0,0,0,0,0,0,0,0,0,0,0,8,0,0,0
0,0,0,16,0,0,0,0,0,0,0,0,0,0,0,0,0,0,0,0,0,0,0,0,8,0,0,0
0,0,0,8,0,0,0,0,0,0,0,0,0,0,0,0,0,0,0,0,0,0,0,0,8,0,0,0
0,0,0,16,0,0,0,0,0,0,0,0,0,0,0,0,0,0,0,0,0,0,0,0,8,0,0,0
0,0,0,8,8,8,8,8,29,8,8,8,8,8,8,8,8,8,8,8,8,8,8,8,8,0,0,0
0,0,0,16,0,0,0,0,0,0,8,0,0,0,0,0,0,0,0,0,0,0,0,20,8,0,0,0
0,0,0,8,0,0,0,0,0,0,8,0,0,0,0,0,0,0,0,0,0,0,0,0,8,0,0,0
0,0,0,16,0,0,0,0,0,0,8,0,0,0,0,0,0,0,0,0,0,0,0,20,8,0,0,0
0,0,0,8,0,0,0,0,0,0,8,0,0,0,0,0,0,0,0,0,0,0,0,0,8,0,0,0
0,0,0,16,0,0,0,0,0,0,8,23,23,23,23,23,23,23,23,23,23,23,23,23,23,23,0,0
0,0,0,8,0,0,0,0,0,0,8,25,25,25,25,25,25,25,25,25,25,25,25,25,25,25,0,0
0,0,0,16,0,0,0,0,0,0,8,0,0,0,0,0,0,0,0,28,0,0,0,20,8,19,0,0
0,0,0,8,0,0,0,0,0,0,8,0,0,0,0,0,0,0,0,28,0,0,0,0,8,19,0,0
0,0,0,8,8,16,8,8,16,8,8,23,23,23,23,23,23,23,23,23,23,23,23,23,23,23,0,0
0,0,0,0,0,0,0,0,0,0,0,0,0,0,0,0,0,0,0,0,0,0,0,0,0,0,0,0
0,0,0,0,0,0,0,0,0,0,0,0,0,0,0,0,0,0,0,0,0,0,0,0,0,0,0,0
0,0,0,0,0,0,0,0,0,0,0,0,0,0,0,0,0,0,0,0,0,0,0,0,0,0,0,0
:endlayer
layer: 12
0,0,0,0,0,0,0,0,0,0,0,0,0,0,0,0,0,0,0,0,0,0,0,0,0,0,0,0
0,0,0,0,0,0,0,0,0,0,0,0,0,0,0,0,0,0,0,0,0,0,0,0,0,0,0,0
0,0,0,0,0,0,8,8,16,8,8,0,0,0,0,0,0,0,0,0,0,0,0,0,0,0,0,0
0,0,0,0,0,0,8,0,0,20,8,25,25,25,25,25,25,25,25,25,25,25,25,25,25,25,0,0
0,0,0,0,0,0,8,0,0,0,8,28,32,32,32,28,32,32,32,32,32,32,32,28,8,30,0,0
0,0,0,8,8,8,8,19,0,0,8,23,23,23,23,23,23,23,23,23,23,23,23,23,23,23,0,0
0,0,0,8,18,0,0,0,0,0,8,0,0,0,0,0,0,0,0,0,0,0,0,0,0,0,0,0
0,0,0,16,0,0,0,0,0,0,8,19,0,0,0,0,0,0,0,0,0,0,0,0,0,0,0,0
0,0,0,8,0,0,0,0,0,0,31,25,25,25,25,25,25,25,25,25,25,25,25,25,25,25,0,0
0,0,0,16,0,0,0,0,0,0,0,0,0,0,0,0,0,0,0,0,0,0,0,0,8,0,0,0
0,0,0,8,0,0,0,0,0,0,0,0,0,0,0,0,0,0,0,0,0,0,0,0,16,0,0,0
0,0,0,16,0,0,0,0,21,0,0,0,0,0,0,0,0,0,0,0,0,0,0,0,8,0,0,0
0,0,0,8,8,8,8,8,8,8,8,8,8,8,8,8,8,8,8,8,8,8,8,8,8,0,0,0
0,0,0,16,0,18,0,0,18,0,8,0,0,0,0,0,0,0,0,0,0,0,0,0,8,0,0,0
0,0,0,8,0,0,0,0,0,0,8,0,0,0,0,0,0,0,0,0,0,0,0,0,16,0,0,0
0,0,0,16,0,0,0,0,0,20,8,0,0,0,0,0,0,0,0,0,0,0,0,0,8,0,0,0
0,0,0,8,19,0,0,0,0,0,8,23,23,23,23,23,23,23,24,30,23,23,23,23,23,23,0,0
0,0,0,16,0,0,0,0,0,0,8,0,0,0,0,0,0,0,24,28,22,0,0,0,0,0,0,0
0,0,0,8,0,0,0,0,0,0,8,19,0,0,0,0,0,0,24,28,22,0,0,0,0,0,0,0
0,0,0,16,0,0,0,0,0,0,8,25,25,25,25,25,25,25,25,30,25,25,25,25,25,25,0,0
0,0,0,8,19,0,0,0,0,20,8,23,23,23,23,23,23,23,23,23,23,23,23,23,23,23,0,0
0,0,0,8,8,16,8,8,16,8,8,19,0,0,0,0,0,0,0,0,0,0,0,0,0,0,0,0
0,0,0,0,0,0,0,0,0,0,0,0,0,0,0,0,0,0,0,0,0,0,0,0,0,0,0,0
0,0,0,0,0,0,0,0,0,0,0,0,0,0,0,0,0,0,0,0,0,0,0,0,0,0,0,0
0,0,0,0,0,0,0,0,0,0,0,0,0,0,0,0,0,0,0,0,0,0,0,0,0,0,0,0
:endlayer
layer: 13
0,0,0,0,0,0,0,0,0,0,0,0,0,0,0,0,0,0,0,0,0,0,0,0,0,0,0,0
0,0,0,0,0,24,36,36,36,36,22,0,0,0,0,0,0,0,0,0,0,0,0,0,0,0,0,0
0,0,0,0,0,24,28,28,28,28,28,0,0,0,0,0,0,0,0,0,0,0,0,0,0,0,0,0
0,0,0,0,0,24,28,0,0,0,28,0,0,0,0,0,0,0,0,0,0,0,0,0,0,0,0,0
0,0,34,34,34,24,28,0,0,0,28,35,0,0,0,35,0,0,0,0,0,0,0,0,35,0,0,0
0,0,34,28,34,24,28,0,0,0,28,0,0,0,0,0,0,0,0,0,0,0,0,0,0,0,0,0
0,0,34,34,34,24,28,0,0,0,28,0,0,0,0,0,0,0,0,0,0,0,0,0,0,0,0,0
0,0,34,34,34,24,28,0,0,0,28,0,0,0,0,0,0,0,0,0,0,0,0,0,0,0,0,0
0,0,34,34,34,24,28,0,0,0,28,0,0,0,0,0,0,0,0,0,0,0,0,0,0,0,0,0
0,0,34,34,34,24,28,0,0,0,28,25,25,25,25,25,25,25,25,25,25,25,25,25,25,25,0,0
0,0,34,28,34,24,28,0,0,0,0,0,0,0,0,0,0,0,0,0,0,0,0,0,8,0,0,0
0,0,34,34,34,24,28,0,0,0,28,22,0,0,0,0,0,0,0,0,0,0,0,0,8,0,0,0
0,0,34,34,34,24,28,8,8,8,28,28,28,28,28,28,28,28,28,28,28,28,28,28,8,0,0,0
0,0,34,34,34,24,28,0,0,0,28,22,0,0,0,0,0,0,0,0,0,0,0,0,8,0,0,0
0,0,34,28,34,24,28,0,0,0,28,22,0,0,0,0,0,0,0,0,0,0,0,0,8,0,0,0
0,0,34,34,34,24,28,0,0,0,28,23,23,23,23,23,23,23,23,23,23,23,23,23,23,23,0,0
0,0,34,34,34,24,28,0,0,0,28,22,0,0,0,0,0,0,0,0,0,0,0,0,0,0,0,0
0,0,34,34,34,24,28,0,0,0,28,22,0,0,0,0,0,0,0,35,0,0,0,0,0,0,0,0
0,0,34,28,34,24,28,0,0,0,28,22,0,0,0,0,0,0,0,35,0,0,0,0,0,0,0,0
0,0,34,34,34,24,28,0,0,0,28,22,0,0,0,0,0,0,0,0,0,0,0,0,0,0,0,0
0,0,34,34,34,24,28,0,0,0,28,22,0,0,0,0,0,0,0,0,0,0,0,0,0,0,0,0
0,0,34,34,34,24,28,28,28,28,28,22,0,0,0,0,0,0,0,0,0,0,0,0,0,0,0,0
0,0,34,34,34,33,23,23,23,23,23,22,0,0,0,0,0,0,0,0,0,0,0,0,0,0,0,0
0,0,0,0,0,0,0,0,0,0,0,0,0,0,0,0,0,0,0,0,0,0,0,0,0,0,0,0
0,0,0,0,0,0,0,0,0,0,0,0,0,0,0,0,0,0,0,0,0,0,0,0,0,0,0,0
:endlayer
layer: 14
0,0,0,0,0,0,0,0,0,0,0,0,0,0,0,0,0,0,0,0,0,0,0,0,0,0,0,0
0,0,0,0,0,0,0,0,0,0,0,0,0,0,0,0,0,0,0,0,0,0,0,0,0,0,0,0
0,0,0,0,0,0,33,25,25,25,33,0,0,0,0,0,0,0,0,0,0,0,0,0,0,0,0,0
0,0,0,0,0,0,24,28,28,28,22,0,0,0,0,0,0,0,0,0,0,0,0,0,0,0,0,0
0,0,0,0,0,0,24,28,0,28,22,0,0,0,0,0,0,0,0,0,0,0,0,0,0,0,0,0
0,0,0,35,0,0,24,28,0,28,22,0,0,0,0,0,0,0,0,0,0,0,0,0,0,0,0,0
0,0,0,0,0,0,24,28,0,28,22,0,0,0,0,0,0,0,0,0,0,0,0,0,0,0,0,0
0,0,0,0,0,0,24,28,0,28,22,0,0,0,0,0,0,0,0,0,0,0,0,0,0,0,0,0
0,0,0,0,0,0,24,28,0,28,22,0,0,0,0,0,0,0,0,0,0,0,0,0,0,0,0,0
0,0,0,0,0,0,24,28,0,28,22,0,0,0,0,0,0,0,0,0,0,0,0,0,0,0,0,0
0,0,0,35,0,0,24,28,0,28,28,25,25,25,25,25,25,25,25,25,25,25,25,25,25,25,0,0
0,0,0,0,0,0,24,28,0,28,22,0,0,0,0,0,0,0,0,0,0,0,0,0,8,19,0,0
0,0,0,0,0,0,24,28,8,28,28,28,28,28,28,28,28,28,28,28,28,28,28,28,8,0,0,0
0,0,0,0,0,0,24,28,0,28,22,0,0,0,0,0,0,0,0,0,0,0,0,0,8,19,0,0
0,0,0,35,0,0,24,28,0,28,28,23,23,23,23,23,23,23,23,23,23,23,23,23,23,23,0,0
0,0,0,0,0,0,24,28,0,28,22,0,0,0,0,0,0,0,0,0,0,0,0,0,0,0,0,0
0,0,0,0,0,0,24,28,0,28,22,0,0,0,0,0,0,0,0,0,0,0,0,0,0,0,0,0
0,0,0,0,0,0,24,28,0,28,22,0,0,0,0,0,0,0,0,0,0,0,0,0,0,0,0,0
0,0,0,35,0,0,24,28,0,28,22,0,0,0,0,0,0,0,0,0,0,0,0,0,0,0,0,0
0,0,0,0,0,0,24,28,0,28,22,0,0,0,0,0,0,0,0,0,0,0,0,0,0,0,0,0
0,0,0,0,0,0,24,28,28,28,22,0,0,0,0,0,0,0,0,0,0,0,0,0,0,0,0,0
0,0,0,0,0,0,33,23,23,23,33,0,0,0,0,0,0,0,0,0,0,0,0,0,0,0,0,0
0,0,0,0,0,0,0,0,0,0,0,0,0,0,0,0,0,0,0,0,0,0,0,0,0,0,0,0
0,0,0,0,0,0,0,0,0,0,0,0,0,0,0,0,0,0,0,0,0,0,0,0,0,0,0,0
0,0,0,0,0,0,0,0,0,0,0,0,0,0,0,0,0,0,0,0,0,0,0,0,0,0,0,0
:endlayer
layer: 15
0,0,0,0,0,0,0,0,0,0,0,0,0,0,0,0,0,0,0,0,0,0,0,0,0,0,0,0
0,0,0,0,0,0,0,0,0,0,0,0,0,0,0,0,0,0,0,0,0,0,0,0,0,0,0,0
0,0,0,0,0,0,0,0,0,0,0,0,0,0,0,0,0,0,0,0,0,0,0,0,0,0,0,0
0,0,0,0,0,0,0,33,25,33,0,0,0,0,0,0,0,0,0,0,0,0,0,0,0,0,0,0
0,0,0,0,0,0,0,24,28,22,0,0,0,0,0,0,0,0,0,0,0,0,0,0,0,0,0,0
0,0,0,0,0,0,0,24,28,22,0,0,0,0,0,0,0,0,0,0,0,0,0,0,0,0,0,0
0,0,0,0,0,0,0,24,28,22,0,0,0,0,0,0,0,0,0,0,0,0,0,0,0,0,0,0
0,0,0,0,0,0,0,24,28,22,0,0,0,0,0,0,0,0,0,0,0,0,0,0,0,0,0,0
0,0,0,0,0,0,0,24,28,22,0,0,0,0,0,0,0,0,0,0,0,0,0,0,0,0,0,0
0,0,0,0,0,0,0,24,28,22,0,0,0,0,0,0,0,0,0,0,0,0,0,0,0,0,0,0
0,0,0,0,0,0,0,24,28,22,35,0,0,0,0,0,0,0,0,0,0,0,0,0,0,0,0,0
0,0,0,0,0,0,0,24,28,22,25,25,25,25,25,25,25,25,25,25,25,25,25,25,25,25,0,0
0,0,0,0,0,0,0,24,28,28,28,28,28,28,28,28,28,28,28,28,28,28,28,28,28,30,0,0
0,0,0,0,0,0,0,24,28,22,23,23,23,23,23,23,23,23,23,23,23,23,23,23,23,23,0,0
0,0,0,0,0,0,0,24,28,22,35,0,0,0,0,0,0,0,0,0,0,0,0,0,0,0,0,0
0,0,0,0,0,0,0,24,28,22,0,0,0,0,0,0,0,0,0,0,0,0,0,0,0,0,0,0
0,0,0,0,0,0,0,24,28,22,0,0,0,0,0,0,0,0,0,0,0,0,0,0,0,0,0,0
0,0,0,0,0,0,0,24,28,22,0,0,0,0,0,0,0,0,0,0,0,0,0,0,0,0,0,0
0,0,0,0,0,0,0,24,28,22,0,0,0,0,0,0,0,0,0,0,0,0,0,0,0,0,0,0
0,0,0,0,0,0,0,24,28,22,0,0,0,0,0,0,0,0,0,0,0,0,0,0,0,0,0,0
0,0,0,0,0,0,0,33,23,33,0,0,0,0,0,0,0,0,0,0,0,0,0,0,0,0,0,0
0,0,0,0,0,0,0,0,0,0,0,0,0,0,0,0,0,0,0,0,0,0,0,0,0,0,0,0
0,0,0,0,0,0,0,0,0,0,0,0,0,0,0,0,0,0,0,0,0,0,0,0,0,0,0,0
0,0,0,0,0,0,0,0,0,0,0,0,0,0,0,0,0,0,0,0,0,0,0,0,0,0,0,0
0,0,0,0,0,0,0,0,0,0,0,0,0,0,0,0,0,0,0,0,0,0,0,0,0,0,0,0
:endlayer
layer: 16
0,0,0,0,0,0,0,0,0,0,0,0,0,0,0,0,0,0,0,0,0,0,0,0,0,0,0,0
0,0,0,0,0,0,0,0,0,0,0,0,0,0,0,0,0,0,0,0,0,0,0,0,0,0,0,0
0,0,0,0,0,0,0,0,0,0,0,0,0,0,0,0,0,0,0,0,0,0,0,0,0,0,0,0
0,0,0,0,0,0,0,0,0,0,0,0,0,0,0,0,0,0,0,0,0,0,0,0,0,0,0,0
0,0,0,0,0,0,0,0,33,0,0,0,0,0,0,0,0,0,0,0,0,0,0,0,0,0,0,0
0,0,0,0,0,0,0,0,33,0,0,0,0,0,0,0,0,0,0,0,0,0,0,0,0,0,0,0
0,0,0,0,0,0,0,0,33,0,0,0,0,0,0,0,0,0,0,0,0,0,0,0,0,0,0,0
0,0,0,0,0,0,0,0,33,0,0,0,0,0,0,0,0,0,0,0,0,0,0,0,0,0,0,0
0,0,0,0,0,0,0,0,33,0,0,0,0,0,0,0,0,0,0,0,0,0,0,0,0,0,0,0
0,0,0,0,0,0,0,0,33,0,0,0,0,0,0,0,0,0,0,0,0,0,0,0,0,0,0,0
0,0,0,0,0,0,0,0,33,0,0,0,0,0,0,0,0,0,0,0,0,0,0,0,0,0,0,0
0,0,0,0,0,0,0,0,33,0,0,0,0,0,0,0,0,0,0,0,0,0,0,0,0,0,0,0
0,0,0,0,0,0,0,0,33,35,0,0,0,35,0,0,0,0,35,0,0,0,0,0,35,0,0,0
0,0,0,0,0,0,0,0,33,0,0,0,0,0,0,0,0,0,0,0,0,0,0,0,0,0,0,0
0,0,0,0,0,0,0,0,33,0,0,0,0,0,0,0,0,0,0,0,0,0,0,0,0,0,0,0
0,0,0,0,0,0,0,0,33,0,0,0,0,0,0,0,0,0,0,0,0,0,0,0,0,0,0,0
0,0,0,0,0,0,0,0,33,0,0,0,0,0,0,0,0,0,0,0,0,0,0,0,0,0,0,0
0,0,0,0,0,0,0,0,33,0,0,0,0,0,0,0,0,0,0,0,0,0,0,0,0,0,0,0
0,0,0,0,0,0,0,0,33,0,0,0,0,0,0,0,0,0,0,0,0,0,0,0,0,0,0,0
0,0,0,0,0,0,0,0,33,0,0,0,0,0,0,0,0,0,0,0,0,0,0,0,0,0,0,0
0,0,0,0,0,0,0,0,0,0,0,0,0,0,0,0,0,0,0,0,0,0,0,0,0,0,0,0
0,0,0,0,0,0,0,0,0,0,0,0,0,0,0,0,0,0,0,0,0,0,0,0,0,0,0,0
0,0,0,0,0,0,0,0,0,0,0,0,0,0,0,0,0,0,0,0,0,0,0,0,0,0,0,0
0,0,0,0,0,0,0,0,0,0,0,0,0,0,0,0,0,0,0,0,0,0,0,0,0,0,0,0
0,0,0,0,0,0,0,0,0,0,0,0,0,0,0,0,0,0,0,0,0,0,0,0,0,0,0,0
:endlayer
layer: 17
0,0,0,0,0,0,0,0,0,0,0,0,0,0,0,0,0,0,0,0,0,0,0,0,0,0,0,0
0,0,0,0,0,0,0,0,0,0,0,0,0,0,0,0,0,0,0,0,0,0,0,0,0,0,0,0
0,0,0,0,0,0,0,0,0,0,0,0,0,0,0,0,0,0,0,0,0,0,0,0,0,0,0,0
0,0,0,0,0,0,0,0,0,0,0,0,0,0,0,0,0,0,0,0,0,0,0,0,0,0,0,0
0,0,0,0,0,0,0,0,0,0,0,0,0,0,0,0,0,0,0,0,0,0,0,0,0,0,0,0
0,0,0,0,0,0,0,0,0,0,0,0,0,0,0,0,0,0,0,0,0,0,0,0,0,0,0,0
0,0,0,0,0,0,0,0,0,0,0,0,0,0,0,0,0,0,0,0,0,0,0,0,0,0,0,0
0,0,0,0,0,0,0,0,0,0,0,0,0,0,0,0,0,0,0,0,0,0,0,0,0,0,0,0
0,0,0,0,0,0,0,0,0,0,0,0,0,0,0,0,0,0,0,0,0,0,0,0,0,0,0,0
0,0,0,0,0,0,0,0,0,0,0,0,0,0,0,0,0,0,0,0,0,0,0,0,0,0,0,0
0,0,0,0,0,0,0,0,0,0,0,0,0,0,0,0,0,0,0,0,0,0,0,0,0,0,0,0
0,0,0,0,0,0,0,0,0,0,0,0,0,0,0,0,0,0,0,0,0,0,0,0,0,0,0,0
0,0,0,0,0,0,0,0,0,0,0,0,0,0,0,0,0,0,0,0,0,0,0,0,0,0,0,0
0,0,0,0,0,0,0,0,0,0,0,0,0,0,0,0,0,0,0,0,0,0,0,0,0,0,0,0
0,0,0,0,0,0,0,0,0,0,0,0,0,0,0,0,0,0,0,0,0,0,0,0,0,0,0,0
0,0,0,0,0,0,0,0,0,0,0,0,0,0,0,0,0,0,0,0,0,0,0,0,0,0,0,0
0,0,0,0,0,0,0,0,0,0,0,0,0,0,0,0,0,0,0,0,0,0,0,0,0,0,0,0
0,0,0,0,0,0,0,0,0,0,0,0,0,0,0,0,0,0,0,0,0,0,0,0,0,0,0,0
0,0,0,0,0,0,0,0,0,0,0,0,0,0,0,0,0,0,0,0,0,0,0,0,0,0,0,0
0,0,0,0,0,0,0,0,0,0,0,0,0,0,0,0,0,0,0,0,0,0,0,0,0,0,0,0
0,0,0,0,0,0,0,0,0,0,0,0,0,0,0,0,0,0,0,0,0,0,0,0,0,0,0,0
0,0,0,0,0,0,0,0,0,0,0,0,0,0,0,0,0,0,0,0,0,0,0,0,0,0,0,0
0,0,0,0,0,0,0,0,0,0,0,0,0,0,0,0,0,0,0,0,0,0,0,0,0,0,0,0
0,0,0,0,0,0,0,0,0,0,0,0,0,0,0,0,0,0,0,0,0,0,0,0,0,0,0,0
0,0,0,0,0,0,0,0,0,0,0,0,0,0,0,0,0,0,0,0,0,0,0,0,0,0,0,0
:endlayer
layer: 18
0,0,0,0,0,0,0,0,0,0,0,0,0,0,0,0,0,0,0,0,0,0,0,0,0,0,0,0
0,0,0,0,0,0,0,0,0,0,0,0,0,0,0,0,0,0,0,0,0,0,0,0,0,0,0,0
0,0,0,0,0,0,0,0,0,0,0,0,0,0,0,0,0,0,0,0,0,0,0,0,0,0,0,0
0,0,0,0,0,0,0,0,0,0,0,0,0,0,0,0,0,0,0,0,0,0,0,0,0,0,0,0
0,0,0,0,0,0,0,0,0,0,0,0,0,0,0,0,0,0,0,0,0,0,0,0,0,0,0,0
0,0,0,0,0,0,0,0,0,0,0,0,0,0,0,0,0,0,0,0,0,0,0,0,0,0,0,0
0,0,0,0,0,0,0,0,0,0,0,0,0,0,0,0,0,0,0,0,0,0,0,0,0,0,0,0
0,0,0,0,0,0,0,0,0,0,0,0,0,0,0,0,0,0,0,0,0,0,0,0,0,0,0,0
0,0,0,0,0,0,0,0,0,0,0,0,0,0,0,0,0,0,0,0,0,0,0,0,0,0,0,0
0,0,0,0,0,0,0,0,0,0,0,0,0,0,0,0,0,0,0,0,0,0,0,0,0,0,0,0
0,0,0,0,0,0,0,0,0,0,0,0,0,0,0,0,0,0,0,0,0,0,0,0,0,0,0,0
0,0,0,0,0,0,0,0,0,0,0,0,0,0,0,0,0,0,0,0,0,0,0,0,0,0,0,0
0,0,0,0,0,0,0,0,0,0,0,0,0,0,0,0,0,0,0,0,0,0,0,0,0,0,0,0
0,0,0,0,0,0,0,0,0,0,0,0,0,0,0,0,0,0,0,0,0,0,0,0,0,0,0,0
0,0,0,0,0,0,0,0,0,0,0,0,0,0,0,0,0,0,0,0,0,0,0,0,0,0,0,0
0,0,0,0,0,0,0,0,0,0,0,0,0,0,0,0,0,0,0,0,0,0,0,0,0,0,0,0
0,0,0,0,0,0,0,0,0,0,0,0,0,0,0,0,0,0,0,0,0,0,0,0,0,0,0,0
0,0,0,0,0,0,0,0,0,0,0,0,0,0,0,0,0,0,0,0,0,0,0,0,0,0,0,0
0,0,0,0,0,0,0,0,0,0,0,0,0,0,0,0,0,0,0,0,0,0,0,0,0,0,0,0
0,0,0,0,0,0,0,0,0,0,0,0,0,0,0,0,0,0,0,0,0,0,0,0,0,0,0,0
0,0,0,0,0,0,0,0,0,0,0,0,0,0,0,0,0,0,0,0,0,0,0,0,0,0,0,0
0,0,0,0,0,0,0,0,0,0,0,0,0,0,0,0,0,0,0,0,0,0,0,0,0,0,0,0
0,0,0,0,0,0,0,0,0,0,0,0,0,0,0,0,0,0,0,0,0,0,0,0,0,0,0,0
0,0,0,0,0,0,0,0,0,0,0,0,0,0,0,0,0,0,0,0,0,0,0,0,0,0,0,0
0,0,0,0,0,0,0,0,0,0,0,0,0,0,0,0,0,0,0,0,0,0,0,0,0,0,0,0
:endlayer
layer: 19
0,0,0,0,0,0,0,0,0,0,0,0,0,0,0,0,0,0,0,0,0,0,0,0,0,0,0,0
0,0,0,0,0,0,0,0,0,0,0,0,0,0,0,0,0,0,0,0,0,0,0,0,0,0,0,0
0,0,0,0,0,0,0,0,0,0,0,0,0,0,0,0,0,0,0,0,0,0,0,0,0,0,0,0
0,0,0,0,0,0,0,0,0,0,0,0,0,0,0,0,0,0,0,0,0,0,0,0,0,0,0,0
0,0,0,0,0,0,0,0,0,0,0,0,0,0,0,0,0,0,0,0,0,0,0,0,0,0,0,0
0,0,0,0,0,0,0,0,0,0,0,0,0,0,0,0,0,0,0,0,0,0,0,0,0,0,0,0
0,0,0,0,0,0,0,0,0,0,0,0,0,0,0,0,0,0,0,0,0,0,0,0,0,0,0,0
0,0,0,0,0,0,0,0,0,0,0,0,0,0,0,0,0,0,0,0,0,0,0,0,0,0,0,0
0,0,0,0,0,0,0,0,0,0,0,0,0,0,0,0,0,0,0,0,0,0,0,0,0,0,0,0
0,0,0,0,0,0,0,0,0,0,0,0,0,0,0,0,0,0,0,0,0,0,0,0,0,0,0,0
0,0,0,0,0,0,0,0,0,0,0,0,0,0,0,0,0,0,0,0,0,0,0,0,0,0,0,0
0,0,0,0,0,0,0,0,0,0,0,0,0,0,0,0,0,0,0,0,0,0,0,0,0,0,0,0
0,0,0,0,0,0,0,0,0,0,0,0,0,0,0,0,0,0,0,0,0,0,0,0,0,0,0,0
0,0,0,0,0,0,0,0,0,0,0,0,0,0,0,0,0,0,0,0,0,0,0,0,0,0,0,0
0,0,0,0,0,0,0,0,0,0,0,0,0,0,0,0,0,0,0,0,0,0,0,0,0,0,0,0
0,0,0,0,0,0,0,0,0,0,0,0,0,0,0,0,0,0,0,0,0,0,0,0,0,0,0,0
0,0,0,0,0,0,0,0,0,0,0,0,0,0,0,0,0,0,0,0,0,0,0,0,0,0,0,0
0,0,0,0,0,0,0,0,0,0,0,0,0,0,0,0,0,0,0,0,0,0,0,0,0,0,0,0
0,0,0,0,0,0,0,0,0,0,0,0,0,0,0,0,0,0,0,0,0,0,0,0,0,0,0,0
0,0,0,0,0,0,0,0,0,0,0,0,0,0,0,0,0,0,0,0,0,0,0,0,0,0,0,0
0,0,0,0,0,0,0,0,0,0,0,0,0,0,0,0,0,0,0,0,0,0,0,0,0,0,0,0
0,0,0,0,0,0,0,0,0,0,0,0,0,0,0,0,0,0,0,0,0,0,0,0,0,0,0,0
0,0,0,0,0,0,0,0,0,0,0,0,0,0,0,0,0,0,0,0,0,0,0,0,0,0,0,0
0,0,0,0,0,0,0,0,0,0,0,0,0,0,0,0,0,0,0,0,0,0,0,0,0,0,0,0
0,0,0,0,0,0,0,0,0,0,0,0,0,0,0,0,0,0,0,0,0,0,0,0,0,0,0,0
:endlayer
layer: 20
0,0,0,0,0,0,0,0,0,0,0,0,0,0,0,0,0,0,0,0,0,0,0,0,0,0,0,0
0,0,0,0,0,0,0,0,0,0,0,0,0,0,0,0,0,0,0,0,0,0,0,0,0,0,0,0
0,0,0,0,0,0,0,0,0,0,0,0,0,0,0,0,0,0,0,0,0,0,0,0,0,0,0,0
0,0,0,0,0,0,0,0,0,0,0,0,0,0,0,0,0,0,0,0,0,0,0,0,0,0,0,0
0,0,0,0,0,0,0,0,0,0,0,0,0,0,0,0,0,0,0,0,0,0,0,0,0,0,0,0
0,0,0,0,0,0,0,0,0,0,0,0,0,0,0,0,0,0,0,0,0,0,0,0,0,0,0,0
0,0,0,0,0,0,0,0,0,0,0,0,0,0,0,0,0,0,0,0,0,0,0,0,0,0,0,0
0,0,0,0,0,0,0,0,0,0,0,0,0,0,0,0,0,0,0,0,0,0,0,0,0,0,0,0
0,0,0,0,0,0,0,0,0,0,0,0,0,0,0,0,0,0,0,0,0,0,0,0,0,0,0,0
0,0,0,0,0,0,0,0,0,0,0,0,0,0,0,0,0,0,0,0,0,0,0,0,0,0,0,0
0,0,0,0,0,0,0,0,0,0,0,0,0,0,0,0,0,0,0,0,0,0,0,0,0,0,0,0
0,0,0,0,0,0,0,0,0,0,0,0,0,0,0,0,0,0,0,0,0,0,0,0,0,0,0,0
0,0,0,0,0,0,0,0,0,0,0,0,0,0,0,0,0,0,0,0,0,0,0,0,0,0,0,0
0,0,0,0,0,0,0,0,0,0,0,0,0,0,0,0,0,0,0,0,0,0,0,0,0,0,0,0
0,0,0,0,0,0,0,0,0,0,0,0,0,0,0,0,0,0,0,0,0,0,0,0,0,0,0,0
0,0,0,0,0,0,0,0,0,0,0,0,0,0,0,0,0,0,0,0,0,0,0,0,0,0,0,0
0,0,0,0,0,0,0,0,0,0,0,0,0,0,0,0,0,0,0,0,0,0,0,0,0,0,0,0
0,0,0,0,0,0,0,0,0,0,0,0,0,0,0,0,0,0,0,0,0,0,0,0,0,0,0,0
0,0,0,0,0,0,0,0,0,0,0,0,0,0,0,0,0,0,0,0,0,0,0,0,0,0,0,0
0,0,0,0,0,0,0,0,0,0,0,0,0,0,0,0,0,0,0,0,0,0,0,0,0,0,0,0
0,0,0,0,0,0,0,0,0,0,0,0,0,0,0,0,0,0,0,0,0,0,0,0,0,0,0,0
0,0,0,0,0,0,0,0,0,0,0,0,0,0,0,0,0,0,0,0,0,0,0,0,0,0,0,0
0,0,0,0,0,0,0,0,0,0,0,0,0,0,0,0,0,0,0,0,0,0,0,0,0,0,0,0
0,0,0,0,0,0,0,0,0,0,0,0,0,0,0,0,0,0,0,0,0,0,0,0,0,0,0,0
0,0,0,0,0,0,0,0,0,0,0,0,0,0,0,0,0,0,0,0,0,0,0,0,0,0,0,0
:endlayer
layer: 21
0,0,0,0,0,0,0,0,0,0,0,0,0,0,0,0,0,0,0,0,0,0,0,0,0,0,0,0
0,0,0,0,0,0,0,0,0,0,0,0,0,0,0,0,0,0,0,0,0,0,0,0,0,0,0,0
0,0,0,0,0,0,0,0,0,0,0,0,0,0,0,0,0,0,0,0,0,0,0,0,0,0,0,0
0,0,0,0,0,0,0,0,0,0,0,0,0,0,0,0,0,0,0,0,0,0,0,0,0,0,0,0
0,0,0,0,0,0,0,0,0,0,0,0,0,0,0,0,0,0,0,0,0,0,0,0,0,0,0,0
0,0,0,0,0,0,0,0,0,0,0,0,0,0,0,0,0,0,0,0,0,0,0,0,0,0,0,0
0,0,0,0,0,0,0,0,0,0,0,0,0,0,0,0,0,0,0,0,0,0,0,0,0,0,0,0
0,0,0,0,0,0,0,0,0,0,0,0,0,0,0,0,0,0,0,0,0,0,0,0,0,0,0,0
0,0,0,0,0,0,0,0,0,0,0,0,0,0,0,0,0,0,0,0,0,0,0,0,0,0,0,0
0,0,0,0,0,0,0,0,0,0,0,0,0,0,0,0,0,0,0,0,0,0,0,0,0,0,0,0
0,0,0,0,0,0,0,0,0,0,0,0,0,0,0,0,0,0,0,0,0,0,0,0,0,0,0,0
0,0,0,0,0,0,0,0,0,0,0,0,0,0,0,0,0,0,0,0,0,0,0,0,0,0,0,0
0,0,0,0,0,0,0,0,0,0,0,0,0,0,0,0,0,0,0,0,0,0,0,0,0,0,0,0
0,0,0,0,0,0,0,0,0,0,0,0,0,0,0,0,0,0,0,0,0,0,0,0,0,0,0,0
0,0,0,0,0,0,0,0,0,0,0,0,0,0,0,0,0,0,0,0,0,0,0,0,0,0,0,0
0,0,0,0,0,0,0,0,0,0,0,0,0,0,0,0,0,0,0,0,0,0,0,0,0,0,0,0
0,0,0,0,0,0,0,0,0,0,0,0,0,0,0,0,0,0,0,0,0,0,0,0,0,0,0,0
0,0,0,0,0,0,0,0,0,0,0,0,0,0,0,0,0,0,0,0,0,0,0,0,0,0,0,0
0,0,0,0,0,0,0,0,0,0,0,0,0,0,0,0,0,0,0,0,0,0,0,0,0,0,0,0
0,0,0,0,0,0,0,0,0,0,0,0,0,0,0,0,0,0,0,0,0,0,0,0,0,0,0,0
0,0,0,0,0,0,0,0,0,0,0,0,0,0,0,0,0,0,0,0,0,0,0,0,0,0,0,0
0,0,0,0,0,0,0,0,0,0,0,0,0,0,0,0,0,0,0,0,0,0,0,0,0,0,0,0
0,0,0,0,0,0,0,0,0,0,0,0,0,0,0,0,0,0,0,0,0,0,0,0,0,0,0,0
0,0,0,0,0,0,0,0,0,0,0,0,0,0,0,0,0,0,0,0,0,0,0,0,0,0,0,0
0,0,0,0,0,0,0,0,0,0,0,0,0,0,0,0,0,0,0,0,0,0,0,0,0,0,0,0
:endlayer
layer: 22
0,0,0,0,0,0,0,0,0,0,0,0,0,0,0,0,0,0,0,0,0,0,0,0,0,0,0,0
0,0,0,0,0,0,0,0,0,0,0,0,0,0,0,0,0,0,0,0,0,0,0,0,0,0,0,0
0,0,0,0,0,0,0,0,0,0,0,0,0,0,0,0,0,0,0,0,0,0,0,0,0,0,0,0
0,0,0,0,0,0,0,0,0,0,0,0,0,0,0,0,0,0,0,0,0,0,0,0,0,0,0,0
0,0,0,0,0,0,0,0,0,0,0,0,0,0,0,0,0,0,0,0,0,0,0,0,0,0,0,0
0,0,0,0,0,0,0,0,0,0,0,0,0,0,0,0,0,0,0,0,0,0,0,0,0,0,0,0
0,0,0,0,0,0,0,0,0,0,0,0,0,0,0,0,0,0,0,0,0,0,0,0,0,0,0,0
0,0,0,0,0,0,0,0,0,0,0,0,0,0,0,0,0,0,0,0,0,0,0,0,0,0,0,0
0,0,0,0,0,0,0,0,0,0,0,0,0,0,0,0,0,0,0,0,0,0,0,0,0,0,0,0
0,0,0,0,0,0,0,0,0,0,0,0,0,0,0,0,0,0,0,0,0,0,0,0,0,0,0,0
0,0,0,0,0,0,0,0,0,0,0,0,0,0,0,0,0,0,0,0,0,0,0,0,0,0,0,0
0,0,0,0,0,0,0,0,0,0,0,0,0,0,0,0,0,0,0,0,0,0,0,0,0,0,0,0
0,0,0,0,0,0,0,0,0,0,0,0,0,0,0,0,0,0,0,0,0,0,0,0,0,0,0,0
0,0,0,0,0,0,0,0,0,0,0,0,0,0,0,0,0,0,0,0,0,0,0,0,0,0,0,0
0,0,0,0,0,0,0,0,0,0,0,0,0,0,0,0,0,0,0,0,0,0,0,0,0,0,0,0
0,0,0,0,0,0,0,0,0,0,0,0,0,0,0,0,0,0,0,0,0,0,0,0,0,0,0,0
0,0,0,0,0,0,0,0,0,0,0,0,0,0,0,0,0,0,0,0,0,0,0,0,0,0,0,0
0,0,0,0,0,0,0,0,0,0,0,0,0,0,0,0,0,0,0,0,0,0,0,0,0,0,0,0
0,0,0,0,0,0,0,0,0,0,0,0,0,0,0,0,0,0,0,0,0,0,0,0,0,0,0,0
0,0,0,0,0,0,0,0,0,0,0,0,0,0,0,0,0,0,0,0,0,0,0,0,0,0,0,0
0,0,0,0,0,0,0,0,0,0,0,0,0,0,0,0,0,0,0,0,0,0,0,0,0,0,0,0
0,0,0,0,0,0,0,0,0,0,0,0,0,0,0,0,0,0,0,0,0,0,0,0,0,0,0,0
0,0,0,0,0,0,0,0,0,0,0,0,0,0,0,0,0,0,0,0,0,0,0,0,0,0,0,0
0,0,0,0,0,0,0,0,0,0,0,0,0,0,0,0,0,0,0,0,0,0,0,0,0,0,0,0
0,0,0,0,0,0,0,0,0,0,0,0,0,0,0,0,0,0,0,0,0,0,0,0,0,0,0,0
:endlayer

#### RULES ####
rule:
plugin=vanillaBlocks
number=1
data:
JSON:{{"val":{"blockName":{"val":"minecraft:cobblestone","id":"ss"},"meta":{"val":"0","id":"pi"},"buildPass":{"val":"0","id":"pi"}},"id":"ct"}}
:enddata
:endrule

rule:
plugin=vanillaBlocks
number=2
data:
JSON:{{"val":{"blockName":{"val":"minecraft:gravel","id":"ss"},"meta":{"val":"0","id":"pi"},"buildPass":{"val":"0","id":"pi"}},"id":"ct"}}
:enddata
:endrule

rule:
plugin=vanillaBlocks
number=3
data:
JSON:{{"val":{"blockName":{"val":"minecraft:stone","id":"ss"},"meta":{"val":"0","id":"pi"},"buildPass":{"val":"0","id":"pi"}},"id":"ct"}}
:enddata
:endrule

rule:
plugin=vanillaBlocks
number=4
data:
JSON:{{"val":{"blockName":{"val":"minecraft:dirt","id":"ss"},"meta":{"val":"0","id":"pi"},"buildPass":{"val":"0","id":"pi"}},"id":"ct"}}
:enddata
:endrule

rule:
plugin=vanillaBlocks
number=5
data:
JSON:{{"val":{"blockName":{"val":"minecraft:sand","id":"ss"},"meta":{"val":"0","id":"pi"},"buildPass":{"val":"0","id":"pi"}},"id":"ct"}}
:enddata
:endrule

rule:
plugin=vanillaBlocks
number=6
data:
JSON:{{"val":{"blockName":{"val":"minecraft:coal_ore","id":"ss"},"meta":{"val":"0","id":"pi"},"buildPass":{"val":"0","id":"pi"}},"id":"ct"}}
:enddata
:endrule

rule:
plugin=vanillaBlocks
number=7
data:
JSON:{{"val":{"blockName":{"val":"minecraft:grass","id":"ss"},"meta":{"val":"0","id":"pi"},"buildPass":{"val":"0","id":"pi"}},"id":"ct"}}
:enddata
:endrule

rule:
plugin=vanillaBlocks
number=8
data:
JSON:{{"val":{"blockName":{"val":"minecraft:stonebrick","id":"ss"},"meta":{"val":"0","id":"pi"},"buildPass":{"val":"0","id":"pi"}},"id":"ct"}}
:enddata
:endrule

rule:
plugin=vanillaDoors
number=9
data:
JSON:{{"val":{"sideFlag":{"val":"8","id":"pb"},"blockName":{"val":"minecraft:wooden_door","id":"ss"},"meta":{"val":"3","id":"pi"},"buildPass":{"val":"2","id":"pi"}},"id":"ct"}}
:enddata
:endrule

rule:
plugin=vanillaBlocks
number=10
data:
JSON:{{"val":{"blockName":{"val":"minecraft:stone_slab","id":"ss"},"meta":{"val":"5","id":"pi"},"buildPass":{"val":"0","id":"pi"}},"id":"ct"}}
:enddata
:endrule

rule:
plugin=vanillaDoors
number=11
data:
JSON:{{"val":{"sideFlag":{"val":"8","id":"pb"},"blockName":{"val":"minecraft:wooden_door","id":"ss"},"meta":{"val":"2","id":"pi"},"buildPass":{"val":"2","id":"pi"}},"id":"ct"}}
:enddata
:endrule

rule:
plugin=vanillaBlocks
number=12
data:
JSON:{{"val":{"blockName":{"val":"minecraft:stone_brick_stairs","id":"ss"},"meta":{"val":"3","id":"pi"},"buildPass":{"val":"0","id":"pi"}},"id":"ct"}}
:enddata
:endrule

rule:
plugin=vanillaBlocks
number=13
data:
JSON:{{"val":{"blockName":{"val":"minecraft:cauldron","id":"ss"},"meta":{"val":"2","id":"pi"},"buildPass":{"val":"0","id":"pi"}},"id":"ct"}}
:enddata
:endrule

rule:
plugin=vanillaDoors
number=14
data:
JSON:{{"val":{"sideFlag":{"val":"0","id":"pb"},"blockName":{"val":"minecraft:wooden_door","id":"ss"},"meta":{"val":"8","id":"pi"},"buildPass":{"val":"2","id":"pi"}},"id":"ct"}}
:enddata
:endrule

rule:
plugin=vanillaDoors
number=15
data:
JSON:{{"val":{"sideFlag":{"val":"0","id":"pb"},"blockName":{"val":"minecraft:wooden_door","id":"ss"},"meta":{"val":"8","id":"pi"},"buildPass":{"val":"2","id":"pi"}},"id":"ct"}}
:enddata
:endrule

rule:
plugin=vanillaBlocks
number=16
data:
JSON:{{"val":{"blockName":{"val":"minecraft:glass_pane","id":"ss"},"meta":{"val":"0","id":"pi"},"buildPass":{"val":"0","id":"pi"}},"id":"ct"}}
:enddata
:endrule

rule:
plugin=vanillaDoors
number=17
data:
JSON:{{"val":{"sideFlag":{"val":"0","id":"pb"},"blockName":{"val":"minecraft:wooden_door","id":"ss"},"meta":{"val":"8","id":"pi"},"buildPass":{"val":"2","id":"pi"}},"id":"ct"}}
:enddata
:endrule

rule:
plugin=vanillaBlocks
number=18
data:
JSON:{{"val":{"blockName":{"val":"minecraft:torch","id":"ss"},"meta":{"val":"3","id":"pi"},"buildPass":{"val":"2","id":"pi"}},"id":"ct"}}
:enddata
:endrule

rule:
plugin=vanillaBlocks
number=19
data:
JSON:{{"val":{"blockName":{"val":"minecraft:torch","id":"ss"},"meta":{"val":"1","id":"pi"},"buildPass":{"val":"2","id":"pi"}},"id":"ct"}}
:enddata
:endrule

rule:
plugin=vanillaBlocks
number=20
data:
JSON:{{"val":{"blockName":{"val":"minecraft:torch","id":"ss"},"meta":{"val":"2","id":"pi"},"buildPass":{"val":"2","id":"pi"}},"id":"ct"}}
:enddata
:endrule

rule:
plugin=vanillaBlocks
number=21
data:
JSON:{{"val":{"blockName":{"val":"minecraft:torch","id":"ss"},"meta":{"val":"4","id":"pi"},"buildPass":{"val":"2","id":"pi"}},"id":"ct"}}
:enddata
:endrule

rule:
plugin=vanillaBlocks
number=22
data:
JSON:{{"val":{"blockName":{"val":"minecraft:oak_stairs","id":"ss"},"meta":{"val":"1","id":"pi"},"buildPass":{"val":"0","id":"pi"}},"id":"ct"}}
:enddata
:endrule

rule:
plugin=vanillaBlocks
number=23
data:
JSON:{{"val":{"blockName":{"val":"minecraft:oak_stairs","id":"ss"},"meta":{"val":"3","id":"pi"},"buildPass":{"val":"0","id":"pi"}},"id":"ct"}}
:enddata
:endrule

rule:
plugin=vanillaBlocks
number=24
data:
JSON:{{"val":{"blockName":{"val":"minecraft:oak_stairs","id":"ss"},"meta":{"val":"0","id":"pi"},"buildPass":{"val":"0","id":"pi"}},"id":"ct"}}
:enddata
:endrule

rule:
plugin=vanillaBlocks
number=25
data:
JSON:{{"val":{"blockName":{"val":"minecraft:oak_stairs","id":"ss"},"meta":{"val":"2","id":"pi"},"buildPass":{"val":"0","id":"pi"}},"id":"ct"}}
:enddata
:endrule

rule:
plugin=vanillaDoors
number=26
data:
JSON:{{"val":{"sideFlag":{"val":"8","id":"pb"},"blockName":{"val":"minecraft:wooden_door","id":"ss"},"meta":{"val":"1","id":"pi"},"buildPass":{"val":"2","id":"pi"}},"id":"ct"}}
:enddata
:endrule

rule:
plugin=vanillaBlocks
number=27
data:
JSON:{{"val":{"blockName":{"val":"minecraft:iron_bars","id":"ss"},"meta":{"val":"0","id":"pi"},"buildPass":{"val":"0","id":"pi"}},"id":"ct"}}
:enddata
:endrule

rule:
plugin=vanillaBlocks
number=28
data:
JSON:{{"val":{"blockName":{"val":"minecraft:planks","id":"ss"},"meta":{"val":"0","id":"pi"},"buildPass":{"val":"0","id":"pi"}},"id":"ct"}}
:enddata
:endrule

rule:
plugin=vanillaDoors
number=29
data:
JSON:{{"val":{"sideFlag":{"val":"0","id":"pb"},"blockName":{"val":"minecraft:wooden_door","id":"ss"},"meta":{"val":"8","id":"pi"},"buildPass":{"val":"2","id":"pi"}},"id":"ct"}}
:enddata
:endrule

rule:
plugin=vanillaBlocks
number=30
data:
JSON:{{"val":{"blockName":{"val":"minecraft:oak_stairs","id":"ss"},"meta":{"val":"5","id":"pi"},"buildPass":{"val":"0","id":"pi"}},"id":"ct"}}
:enddata
:endrule

rule:
plugin=vanillaBlocks
number=31
data:
JSON:{{"val":{"blockName":{"val":"minecraft:stone_brick_stairs","id":"ss"},"meta":{"val":"7","id":"pi"},"buildPass":{"val":"0","id":"pi"}},"id":"ct"}}
:enddata
:endrule

rule:
plugin=vanillaBlocks
number=32
data:
JSON:{{"val":{"blockName":{"val":"minecraft:wooden_slab","id":"ss"},"meta":{"val":"8","id":"pi"},"buildPass":{"val":"0","id":"pi"}},"id":"ct"}}
:enddata
:endrule

rule:
plugin=vanillaBlocks
number=33
data:
JSON:{{"val":{"blockName":{"val":"minecraft:stone_slab","id":"ss"},"meta":{"val":"2","id":"pi"},"buildPass":{"val":"0","id":"pi"}},"id":"ct"}}
:enddata
:endrule

rule:
plugin=vanillaBlocks
number=34
data:
JSON:{{"val":{"blockName":{"val":"minecraft:wooden_slab","id":"ss"},"meta":{"val":"0","id":"pi"},"buildPass":{"val":"0","id":"pi"}},"id":"ct"}}
:enddata
:endrule

rule:
plugin=vanillaBlocks
number=35
data:
JSON:{{"val":{"blockName":{"val":"minecraft:torch","id":"ss"},"meta":{"val":"5","id":"pi"},"buildPass":{"val":"2","id":"pi"}},"id":"ct"}}
:enddata
:endrule

rule:
plugin=vanillaBlocks
number=36
data:
JSON:{{"val":{"blockName":{"val":"minecraft:oak_stairs","id":"ss"},"meta":{"val":"6","id":"pi"},"buildPass":{"val":"0","id":"pi"}},"id":"ct"}}
:enddata
:endrule

#### ENTITIES ####
