# Ancient Warfare Structure Template File
# Auto-generated structure template file. created on: 11/24/2014 at: 22:45:38
# Lines beginning with # denote comments

header:
version=2.1
name=TownBlocksLarge3Housing
size=31,28,30
offset=16,2,29
:endheader

#### VALIDATION ####
validation:
type=ground
survival=false
worldGenEnabled=false
unique=false
preserveBlocks=false
selectionWeight=0
clusterValue=0
minDuplicateDistance=0
dimensionWhiteList=false
dimensionList=
biomeWhiteList=false
biomeList=
leveling=0
fill=0
border=0
validTargetBlocks=
blockSwap=false
data:
:enddata
:endvalidation

#### LAYERS ####
layer: 0
1,1,1,1,1,1,1,1,1,1,1,1,1,1,1,1,1,1,1,1,1,1,1,1,1,1,1,1,1,1,1
1,1,1,1,1,1,1,1,1,1,1,1,1,1,1,1,1,1,1,1,1,1,1,1,1,1,1,1,1,1,1
1,1,1,4,4,4,4,4,4,4,4,6,5,3,3,3,3,3,3,3,3,2,2,2,2,1,1,1,1,1,1
1,1,1,4,5,6,5,5,4,3,3,3,3,3,3,3,3,3,3,3,3,2,2,2,2,1,1,1,1,1,1
1,1,1,3,3,3,3,3,3,3,3,3,3,3,3,3,3,3,3,3,3,2,2,2,2,1,1,1,1,1,1
1,1,1,1,1,1,1,1,1,1,1,1,1,3,3,3,3,3,3,3,3,2,2,2,2,1,1,1,1,1,1
1,1,1,1,1,1,1,1,1,1,1,1,1,3,3,3,3,3,3,3,3,2,2,2,2,1,1,1,1,1,1
1,1,1,1,1,1,1,1,1,1,1,1,1,3,3,3,3,3,3,3,3,2,2,2,2,1,1,1,1,1,1
1,1,1,1,1,1,1,1,1,1,1,1,1,3,3,3,3,3,3,3,3,2,2,2,2,1,1,1,1,1,1
1,1,1,1,1,1,1,1,1,1,1,1,1,3,3,3,3,3,3,3,2,2,2,2,2,1,1,1,1,1,1
1,1,1,1,1,1,1,1,1,1,1,1,1,3,3,3,3,3,3,3,2,2,2,2,2,1,1,1,1,1,1
1,1,1,1,1,1,1,1,1,1,1,1,1,3,3,3,3,3,3,3,2,2,2,2,2,1,1,1,1,1,1
1,1,1,1,1,1,1,1,1,1,1,1,1,3,3,3,3,3,3,3,2,2,2,2,2,1,1,1,1,1,1
1,1,1,1,1,1,1,1,1,1,1,1,1,3,3,3,3,3,3,2,2,2,2,2,2,1,1,1,1,1,1
1,1,1,3,3,3,3,3,3,3,3,3,3,3,3,3,3,3,3,2,2,7,2,2,8,1,1,1,1,1,1
1,1,1,3,3,3,3,3,3,3,3,3,3,3,3,3,3,3,2,2,7,7,7,2,8,1,1,1,1,1,1
1,1,1,3,3,3,3,3,3,3,3,3,3,3,3,3,3,2,2,2,7,7,7,2,2,1,1,1,1,1,1
1,1,1,3,3,3,3,3,3,3,3,3,3,3,3,3,3,2,2,7,7,7,2,2,8,1,1,1,1,1,1
1,1,1,3,3,3,3,3,3,3,3,3,3,3,3,3,2,2,2,2,7,7,2,2,8,1,1,1,1,1,1
1,1,1,3,3,3,3,3,3,3,3,3,3,3,3,2,2,2,2,2,2,2,2,2,2,1,1,1,1,1,1
1,1,1,3,3,3,3,3,3,3,2,2,2,2,2,2,2,2,2,2,2,2,2,2,2,1,1,1,1,1,1
1,1,1,2,2,2,2,2,2,2,2,2,2,2,2,2,2,2,2,2,2,2,2,2,2,1,1,1,1,1,1
1,1,1,2,2,2,2,2,2,2,2,2,2,2,2,2,2,2,2,2,2,2,2,2,2,1,1,1,1,1,1
1,1,1,2,2,2,2,2,2,2,2,2,2,2,2,2,2,2,2,2,2,2,2,2,2,1,1,1,1,1,1
1,1,1,1,1,1,1,1,1,1,1,1,1,1,1,1,1,1,1,1,1,1,1,1,1,1,1,1,1,1,1
1,1,1,1,1,1,1,1,1,1,1,1,1,1,1,1,1,1,1,1,1,1,1,1,1,1,1,1,1,1,1
1,1,1,1,1,1,1,1,1,1,1,1,1,1,1,1,1,1,1,1,1,1,1,1,1,1,1,1,1,1,1
1,1,1,1,1,1,1,1,1,1,1,1,1,1,1,1,1,1,1,1,1,1,1,1,1,1,1,1,1,1,1
1,1,1,1,1,1,1,1,1,1,1,1,1,1,1,1,1,1,1,1,1,1,1,1,1,1,1,1,1,1,1
1,1,1,1,1,1,1,1,1,1,1,1,1,1,1,1,1,1,1,1,1,1,1,1,1,1,1,1,1,1,1
:endlayer
layer: 1
1,1,1,1,1,1,1,1,1,1,1,1,1,1,1,1,1,1,1,1,1,1,1,1,1,1,1,1,1,1,1
1,1,1,1,1,1,1,1,1,1,1,1,1,1,1,1,1,1,1,1,1,1,1,1,1,1,1,1,1,1,1
1,1,1,4,4,4,6,4,4,4,5,5,5,3,3,3,3,3,3,3,3,3,2,3,2,1,1,1,1,1,1
1,1,1,6,5,5,5,5,5,3,3,3,3,3,3,3,3,3,3,3,3,2,2,2,2,1,1,1,1,1,1
1,1,1,3,3,3,3,3,3,3,3,3,3,3,3,1,1,1,1,3,3,2,2,2,2,1,1,1,1,1,1
1,1,1,1,1,1,1,1,1,1,1,1,1,3,3,1,1,1,1,3,3,2,2,2,2,1,1,1,1,1,1
1,1,1,1,1,1,1,1,1,1,1,1,1,3,3,1,1,1,1,3,3,2,2,2,2,1,1,1,1,1,1
1,1,1,1,1,1,1,1,1,1,1,1,1,3,3,1,1,1,1,3,3,2,2,2,2,1,1,1,1,1,1
1,1,1,1,1,1,1,1,1,1,1,1,1,3,3,1,1,1,1,3,3,2,2,2,2,1,1,1,1,1,1
1,1,1,1,1,1,1,1,1,1,1,1,1,3,3,1,1,1,1,3,2,2,2,2,2,1,1,1,1,1,1
1,1,1,1,1,1,1,1,1,1,1,1,1,3,3,1,1,1,1,3,3,2,2,2,2,1,1,1,1,1,1
1,1,1,1,1,1,1,1,1,1,1,1,1,3,3,1,1,1,1,3,3,2,2,2,2,1,1,1,1,1,1
1,1,1,1,1,1,1,1,1,1,1,1,1,3,3,1,1,1,1,3,3,2,2,2,2,1,1,1,1,1,1
1,1,1,1,1,1,1,1,1,1,1,1,1,1,3,3,3,3,2,2,2,2,2,2,2,1,1,1,1,1,1
1,1,1,1,1,1,1,1,1,1,1,1,1,1,1,1,1,1,2,2,2,2,2,2,2,1,1,1,1,1,1
1,1,1,1,1,1,1,1,1,1,1,1,1,1,1,2,2,2,2,2,2,2,2,2,2,1,1,1,1,1,1
1,1,1,1,1,1,1,1,1,1,1,1,1,1,1,2,2,2,2,2,7,2,2,2,2,1,1,1,1,1,1
1,1,1,1,1,1,1,1,1,1,1,1,1,1,1,2,2,2,2,2,7,2,2,2,2,1,1,1,1,1,1
1,1,1,3,3,3,3,3,3,3,3,3,1,1,1,2,2,2,2,2,2,2,2,2,2,1,1,1,1,1,1
1,1,1,3,3,3,3,3,3,3,3,3,2,2,2,2,2,2,2,2,2,2,2,2,2,1,1,1,1,1,1
1,1,1,3,3,3,3,3,3,2,2,2,2,2,2,2,2,2,2,2,2,2,2,2,2,1,1,1,1,1,1
1,1,1,3,2,2,2,2,2,2,2,2,2,2,2,2,2,2,2,2,2,2,2,2,2,1,1,1,1,1,1
1,1,1,2,2,2,2,2,2,2,2,2,2,2,2,2,2,2,2,2,2,2,2,2,2,1,1,1,1,1,1
1,1,1,2,2,2,2,2,2,2,2,2,2,2,2,2,2,2,2,2,2,2,2,2,2,1,1,1,1,1,1
1,1,1,1,1,1,1,1,1,1,1,1,1,1,1,1,1,1,1,1,1,1,1,1,1,1,1,1,1,1,1
1,1,1,1,1,1,1,1,1,1,1,1,1,1,1,1,1,1,1,1,1,1,1,1,1,1,1,1,1,1,1
1,1,1,1,1,1,1,1,1,1,1,1,1,1,1,1,1,1,1,1,1,1,1,1,1,1,1,1,1,1,1
1,1,1,1,1,1,1,1,1,1,1,1,1,1,1,1,1,1,1,1,1,1,1,1,1,1,1,1,1,1,1
1,1,1,1,1,1,1,1,1,1,1,1,1,1,1,1,1,1,1,1,1,1,1,1,1,1,1,1,1,1,1
1,1,1,1,1,1,1,1,1,1,1,1,1,1,1,1,1,1,1,1,1,1,1,1,1,1,1,1,1,1,1
:endlayer
layer: 2
8,8,8,8,8,8,8,8,8,8,8,8,8,8,8,8,8,8,8,8,8,8,8,8,8,8,8,8,8,8,8
8,8,8,8,8,8,8,8,8,8,8,8,8,8,8,8,8,8,8,8,8,8,8,8,8,8,8,8,8,8,8
8,8,8,8,8,8,8,8,8,8,8,8,8,8,8,8,8,8,1,1,1,1,1,1,1,1,1,1,8,8,8
8,8,8,8,8,8,8,8,8,8,8,8,8,8,8,8,8,8,1,3,4,0,0,0,0,0,0,1,8,8,8
8,8,8,9,9,9,9,9,9,9,9,9,9,8,8,1,1,1,1,1,4,0,0,0,0,0,0,1,8,8,8
8,8,8,1,1,1,1,1,1,1,1,1,1,8,8,1,1,1,1,1,4,0,0,0,0,0,12,1,8,8,8
8,8,8,1,1,1,1,1,1,1,1,1,1,8,8,1,1,1,1,1,4,0,0,0,0,0,0,1,8,8,8
8,8,8,1,1,1,1,1,1,1,1,1,1,8,8,1,1,1,1,1,4,0,0,0,0,0,0,1,8,8,8
8,8,8,1,1,1,1,1,1,1,1,1,1,8,8,1,1,1,1,1,4,0,0,0,0,0,0,1,8,8,8
8,8,8,1,1,1,1,1,1,1,1,1,1,8,8,1,1,1,1,1,4,4,4,4,4,4,4,1,8,8,8
8,8,8,1,1,1,1,1,1,1,1,1,1,8,8,1,1,1,1,1,4,0,0,0,0,0,0,1,8,8,8
8,8,8,1,1,1,1,1,1,1,1,1,1,8,8,1,1,1,1,1,4,0,0,0,0,0,0,1,8,8,8
8,8,8,1,1,1,1,1,1,1,1,1,1,8,8,1,1,1,1,3,4,0,0,0,0,0,0,1,8,8,8
8,8,8,1,1,1,1,1,1,1,1,1,1,8,8,8,8,8,4,4,4,0,0,0,0,0,12,1,8,8,8
8,8,8,1,1,1,1,1,1,1,1,1,1,1,1,4,4,4,4,4,4,0,0,0,0,0,0,1,8,8,8
8,8,8,1,1,1,1,1,1,1,1,1,1,1,4,0,0,0,0,0,4,0,0,0,0,0,0,1,8,8,8
8,8,8,1,1,1,1,1,1,1,1,1,1,1,4,0,0,0,0,0,4,4,4,4,4,4,4,1,8,8,8
8,8,8,1,1,1,1,1,1,1,1,1,1,1,4,0,0,0,0,0,4,0,0,0,0,0,0,1,8,8,8
8,8,8,1,1,1,1,1,1,3,1,4,4,4,4,0,0,0,0,0,4,0,0,0,0,0,0,1,8,8,8
8,8,8,1,1,1,1,1,1,4,4,4,0,0,4,4,4,11,4,4,4,0,0,0,0,0,0,1,8,8,8
8,8,8,1,1,1,1,1,4,0,0,0,0,0,0,0,4,0,0,0,4,0,0,0,0,0,12,1,8,8,8
8,8,8,1,1,1,1,1,4,0,0,0,0,0,0,0,4,0,0,0,4,4,4,4,4,0,0,1,8,8,8
8,8,8,1,1,1,1,1,4,0,0,0,0,0,0,0,4,0,0,0,0,0,0,0,4,0,0,1,8,8,8
8,8,8,1,1,1,1,1,4,0,0,0,0,0,0,0,4,0,0,0,0,0,0,0,4,0,0,1,8,8,8
8,8,8,1,1,1,1,4,4,0,0,0,0,0,10,0,4,0,0,0,0,10,0,0,4,0,0,1,8,8,8
8,8,8,1,1,1,1,1,1,1,1,1,1,1,1,1,1,1,1,1,1,1,1,1,1,1,1,1,8,8,8
8,8,8,8,8,8,8,8,8,8,8,8,8,8,8,8,8,8,8,8,8,8,8,8,8,8,8,8,8,8,8
8,8,8,8,8,8,8,8,4,8,8,8,8,8,8,8,8,8,8,8,8,8,8,8,8,8,8,8,8,8,8
8,8,8,8,8,8,8,8,8,8,8,8,8,8,8,8,8,8,8,8,8,8,8,8,8,8,8,8,8,8,8
8,8,8,8,8,8,8,8,8,8,8,8,8,8,8,8,8,8,8,8,8,8,8,8,8,8,8,8,8,8,8
:endlayer
layer: 3
0,0,0,0,0,0,0,0,0,0,0,0,0,0,0,0,0,0,0,0,0,0,0,0,0,0,0,0,0,0,0
0,0,0,0,0,0,0,0,0,0,0,0,0,0,0,0,0,0,0,0,0,0,0,0,0,0,0,0,0,0,0
0,0,0,0,0,0,0,0,0,0,0,0,0,0,0,0,0,0,18,4,4,4,4,4,4,4,4,4,0,4,0
0,0,0,0,0,0,0,0,0,0,0,0,0,0,0,0,0,0,18,4,4,0,0,0,0,0,0,4,0,0,0
0,0,0,0,0,0,0,0,0,0,0,0,0,0,0,4,4,4,4,4,4,0,0,0,0,0,0,4,0,0,0
0,0,0,4,4,4,4,4,4,4,4,4,4,0,0,4,4,4,4,4,4,0,0,0,0,0,0,19,0,0,0
0,0,0,4,0,0,0,0,0,0,0,0,4,0,0,4,4,4,4,4,4,0,0,0,0,0,0,4,0,0,0
0,0,0,4,0,0,0,0,0,0,0,0,4,0,0,4,4,4,4,4,4,0,0,0,0,0,0,4,0,0,0
0,0,0,4,0,0,0,0,0,0,0,0,4,0,0,4,4,4,4,4,4,0,0,0,0,0,0,4,0,0,0
0,0,0,4,0,0,0,0,0,0,0,0,4,0,0,4,4,4,4,4,4,4,4,4,4,4,4,4,0,0,0
0,0,0,4,0,0,0,0,0,0,0,0,4,0,0,4,4,4,4,4,4,0,0,0,0,0,0,4,0,0,0
0,0,0,4,0,0,0,0,0,0,0,0,4,0,0,4,4,4,4,4,4,0,0,0,0,0,0,4,0,0,0
0,0,0,4,0,0,0,0,0,0,0,0,4,0,0,4,4,4,4,4,4,0,0,0,0,0,0,4,0,4,0
0,0,0,4,4,4,4,4,11,4,4,4,4,0,0,0,0,0,18,4,4,0,0,0,0,0,0,19,0,0,0
0,0,0,0,0,0,0,0,0,0,0,0,4,4,4,4,4,4,4,4,4,0,0,0,0,0,0,4,0,0,0
0,0,0,0,0,0,0,0,0,0,0,0,4,4,4,0,0,0,0,0,4,0,0,0,0,0,0,4,0,0,0
0,0,0,0,0,0,0,0,0,16,16,0,4,4,4,0,0,0,0,0,4,4,4,4,4,4,4,4,0,0,0
0,4,0,4,13,4,4,4,4,4,4,0,4,4,4,0,0,0,0,0,4,0,0,0,0,0,0,4,0,0,0
0,0,0,4,0,0,0,0,4,4,4,4,4,4,4,0,0,0,0,0,4,0,0,0,0,0,0,4,0,0,0
0,0,0,4,0,0,0,0,4,4,4,4,0,0,4,4,4,17,4,4,4,0,0,0,0,0,0,4,0,4,0
0,0,0,4,0,0,0,15,4,0,0,0,0,0,0,0,4,0,0,0,4,0,0,0,0,0,0,19,0,0,0
0,0,0,4,0,0,0,14,4,0,0,0,0,0,0,0,4,0,0,0,4,4,4,4,4,0,0,4,0,0,0
0,4,0,4,0,0,0,0,4,0,0,0,0,0,0,0,4,0,0,0,0,0,0,0,4,0,0,4,0,0,0
0,0,0,4,0,0,0,0,4,0,0,0,0,0,0,0,4,0,0,0,0,0,0,0,4,0,0,4,0,0,0
0,0,0,4,4,4,4,4,4,0,0,0,0,0,0,0,4,0,0,0,0,0,0,0,4,0,0,4,0,0,0
0,0,0,4,4,4,4,4,4,4,4,4,4,4,11,4,4,4,4,4,4,11,4,4,4,4,4,4,0,0,0
0,0,0,0,0,0,0,0,0,0,0,0,0,0,0,0,0,0,0,0,0,0,0,0,0,0,0,0,0,0,0
0,4,0,0,0,0,0,0,4,0,0,0,0,0,0,4,0,0,0,0,0,0,4,0,0,0,0,0,0,4,0
0,0,0,0,0,0,0,0,0,0,0,0,0,0,0,0,0,0,0,0,0,0,0,0,0,0,0,0,0,0,0
0,0,0,0,0,0,0,0,0,0,0,0,0,0,0,0,0,0,0,0,0,0,0,0,0,0,0,0,0,0,0
:endlayer
layer: 4
0,0,0,0,0,0,0,0,0,0,0,0,0,0,0,0,0,0,0,0,0,0,0,0,0,0,0,0,0,0,0
0,0,0,0,0,0,0,0,0,0,0,0,0,0,0,0,0,0,0,0,0,0,0,0,0,0,0,0,0,0,0
0,0,0,0,0,0,0,0,0,0,0,0,0,0,0,0,0,0,0,0,18,4,4,4,4,4,4,4,0,20,0
0,0,0,0,0,0,0,0,0,0,0,0,0,0,0,0,0,0,0,0,18,0,0,0,0,0,0,4,0,0,0
0,0,0,0,0,0,0,0,0,0,0,0,0,0,0,4,4,4,4,4,4,0,0,0,0,0,0,4,0,0,0
0,0,0,4,4,4,4,4,21,4,4,4,4,0,0,4,4,4,4,4,4,0,0,0,0,0,0,32,0,0,0
0,0,0,4,0,0,0,0,0,0,0,0,4,0,0,4,4,4,4,4,4,0,0,0,0,0,29,4,0,0,0
0,0,0,4,0,0,0,0,0,0,0,0,4,0,0,4,4,4,4,4,4,0,0,0,0,0,0,21,0,0,0
0,0,0,4,0,0,0,0,0,0,0,0,4,0,0,4,4,4,4,4,4,0,0,0,0,0,0,4,0,0,0
0,0,0,21,0,0,0,0,0,0,0,0,21,0,0,4,4,4,4,4,4,4,4,4,4,4,4,4,0,0,0
0,0,0,4,0,0,0,0,0,0,0,0,4,0,0,4,4,4,4,4,4,0,0,0,0,0,0,4,0,0,0
0,0,0,4,0,0,0,0,0,0,0,0,4,0,0,4,4,4,4,4,4,0,0,0,0,0,0,21,0,0,0
0,0,0,4,0,0,0,0,0,0,0,0,4,0,0,4,4,4,4,4,4,0,0,0,0,0,0,4,0,20,0
0,0,0,4,4,4,4,4,23,4,4,4,4,0,0,0,0,0,0,18,4,0,0,0,0,0,0,31,0,0,0
0,0,0,0,0,0,0,0,0,0,0,0,4,4,4,4,4,4,4,4,4,0,0,0,0,0,29,4,0,0,0
0,0,0,0,0,0,0,0,0,0,0,0,4,4,4,0,0,0,0,0,4,0,0,0,0,0,0,21,0,0,0
0,0,0,0,0,0,0,0,0,0,0,0,4,4,4,0,0,0,0,0,4,4,4,4,4,4,4,4,0,0,0
0,20,0,4,22,4,4,4,4,16,16,0,4,4,4,0,0,0,0,0,4,24,0,0,0,0,29,4,0,0,0
0,0,0,4,0,0,0,0,4,4,4,0,4,4,4,0,0,0,0,0,4,0,0,0,0,0,0,21,0,0,0
0,0,0,21,0,0,0,0,4,4,4,4,0,0,4,4,4,4,4,4,4,0,0,0,0,0,0,4,0,20,0
0,0,0,4,0,0,0,0,4,0,0,0,0,0,0,0,4,27,0,0,4,0,0,0,0,0,0,30,0,0,0
0,0,0,4,0,0,0,0,4,0,0,0,0,0,0,0,4,0,0,0,4,4,4,4,4,0,29,4,0,0,0
0,20,0,21,0,0,0,0,4,0,0,0,0,0,0,0,4,0,0,0,0,0,0,29,4,0,0,21,0,0,0
0,0,0,4,0,0,0,0,4,24,0,0,0,0,0,0,4,0,0,0,0,0,0,0,4,0,0,4,0,0,0
0,0,0,4,4,4,4,4,4,0,0,0,0,25,0,0,4,24,0,0,25,0,0,0,4,25,0,4,0,0,0
0,0,0,4,4,4,4,4,4,4,4,4,21,4,26,4,4,4,4,21,4,28,4,21,4,4,4,4,0,0,0
0,0,0,0,0,0,0,0,0,0,0,0,0,0,0,0,0,0,0,0,0,0,0,0,0,0,0,0,0,0,0
0,20,0,0,0,0,0,0,20,0,0,0,0,0,0,20,0,0,0,0,0,0,20,0,0,0,0,0,0,20,0
0,0,0,0,0,0,0,0,0,0,0,0,0,0,0,0,0,0,0,0,0,0,0,0,0,0,0,0,0,0,0
0,0,0,0,0,0,0,0,0,0,0,0,0,0,0,0,0,0,0,0,0,0,0,0,0,0,0,0,0,0,0
:endlayer
layer: 5
0,0,0,0,0,0,0,0,0,0,0,0,0,0,0,0,0,0,0,0,0,0,0,0,0,0,0,0,0,0,0
0,0,0,0,0,0,0,0,0,0,0,0,0,0,0,0,0,0,0,0,0,0,0,0,0,0,0,0,0,0,0
0,0,0,0,0,0,0,0,0,0,0,0,0,0,0,0,0,0,0,0,0,18,4,4,4,4,4,4,24,20,0
0,0,0,0,0,0,0,0,0,0,0,0,0,0,0,0,0,0,0,0,0,18,4,4,4,4,4,4,0,0,0
0,0,0,0,0,0,0,0,0,0,0,0,0,0,0,4,4,4,4,4,4,4,4,4,4,4,4,4,0,0,0
0,0,0,4,4,4,4,4,21,4,4,4,4,0,0,4,4,4,4,4,4,4,4,4,4,4,4,4,24,0,0
0,0,0,4,0,0,0,0,0,27,0,0,4,0,0,4,4,4,4,4,4,4,4,4,4,4,4,4,0,0,0
0,0,0,4,0,0,0,0,0,0,0,0,4,0,0,4,4,4,4,4,4,4,4,4,4,4,4,4,0,0,0
0,0,0,4,0,0,0,0,0,0,0,0,4,0,0,4,4,4,4,4,4,4,4,4,4,4,4,4,0,0,0
0,0,0,21,0,0,0,0,0,0,0,0,21,0,0,4,4,4,4,4,4,4,4,4,4,4,4,4,0,0,0
0,0,0,4,0,0,0,0,0,0,0,0,4,0,0,4,4,4,4,4,4,4,4,4,4,4,4,4,0,0,0
0,0,0,4,0,0,0,0,0,0,0,0,4,0,0,4,4,4,4,4,4,4,4,4,4,4,4,4,0,0,0
0,0,0,4,0,0,0,0,0,25,0,0,4,0,0,4,4,4,4,4,4,4,4,4,4,4,4,4,0,20,0
0,0,0,4,4,4,4,4,4,4,4,4,4,0,0,0,0,0,0,0,18,4,4,4,4,4,4,4,24,0,0
0,0,0,0,27,0,0,0,27,0,0,0,4,4,4,4,4,4,4,4,4,4,4,4,4,4,4,4,0,0,0
0,0,0,0,0,0,0,0,0,0,0,29,4,4,4,27,0,0,0,27,4,4,4,4,4,4,4,4,0,0,0
0,0,0,0,0,0,0,0,0,0,0,0,4,4,4,0,0,0,0,0,4,4,4,4,4,4,4,4,0,0,0
0,20,0,4,4,4,21,4,4,0,0,0,4,4,4,0,0,0,0,0,4,4,4,4,4,4,4,4,0,0,0
0,0,0,4,0,0,0,0,4,16,16,0,4,4,4,25,0,0,0,25,4,4,4,4,4,4,4,4,0,0,0
0,0,0,21,0,0,0,0,4,4,4,4,0,0,4,4,4,4,4,4,4,4,4,4,4,4,4,4,0,20,0
0,0,0,4,0,0,0,0,4,4,4,0,0,0,0,0,4,0,0,4,4,4,4,4,4,4,4,4,24,0,0
0,0,0,4,0,0,0,0,4,4,4,0,0,0,0,0,4,0,0,4,4,4,4,4,4,4,4,4,0,0,0
0,20,0,21,0,0,0,0,4,4,4,0,0,0,0,0,4,0,0,4,4,4,4,4,4,4,4,4,0,0,0
0,0,0,4,0,0,0,0,4,4,4,4,4,4,4,4,4,4,4,4,4,4,4,4,4,4,4,4,0,0,0
0,0,0,4,4,4,4,4,4,4,4,4,4,4,4,4,4,4,4,4,4,4,4,4,4,4,4,4,0,0,0
0,0,0,4,4,4,4,4,4,4,4,4,4,4,4,4,4,4,4,4,4,4,4,4,4,4,4,4,24,0,0
0,0,0,0,0,0,0,0,0,0,0,0,0,0,0,0,0,0,0,0,0,0,0,0,0,0,0,27,0,0,0
0,20,0,0,0,0,0,0,20,0,0,0,0,0,0,20,0,0,0,0,0,0,20,0,0,0,0,0,0,20,0
0,0,0,0,0,0,0,0,0,0,0,0,0,0,0,0,0,0,0,0,0,0,0,0,0,0,0,0,0,0,0
0,0,0,0,0,0,0,0,0,0,0,0,0,0,0,0,0,0,0,0,0,0,0,0,0,0,0,0,0,0,0
:endlayer
layer: 6
0,0,0,0,0,0,0,0,0,0,0,0,0,0,0,0,0,0,0,0,0,0,0,0,0,0,0,0,0,0,0
0,0,0,0,0,0,0,0,0,0,0,0,0,0,0,0,0,0,0,0,0,0,0,0,0,0,0,0,0,0,0
0,0,0,0,0,0,0,0,0,0,0,0,0,0,0,0,0,0,0,0,0,0,0,18,4,4,4,4,36,33,0
0,0,0,0,0,0,0,0,0,0,0,0,0,0,0,25,0,0,0,0,0,0,0,18,4,4,4,4,36,33,0
0,0,0,25,0,0,0,0,0,0,0,0,25,0,29,4,4,4,4,4,4,4,4,4,4,4,4,4,36,33,0
0,0,29,4,4,4,4,4,21,4,4,4,4,24,0,4,4,4,4,4,4,4,4,4,4,4,4,4,36,33,0
0,0,0,4,0,0,0,0,0,0,0,0,4,0,0,4,4,4,4,4,4,4,4,4,4,4,4,4,36,33,0
0,0,0,4,0,0,0,0,0,0,0,0,4,0,0,4,4,4,4,4,4,4,4,4,4,4,4,4,36,33,0
0,0,0,4,0,0,0,0,0,0,0,0,4,0,0,4,4,4,4,4,4,4,4,4,4,4,4,4,36,33,0
0,0,0,21,0,0,0,0,0,0,0,0,21,0,0,4,4,4,4,4,4,4,4,4,4,4,4,4,36,33,0
0,0,0,4,0,0,0,0,0,0,0,0,4,0,0,4,4,4,4,4,4,4,4,4,4,4,4,4,36,33,0
0,0,0,4,24,0,0,0,0,0,0,0,4,0,0,4,4,4,4,4,4,4,4,4,4,4,4,4,36,33,0
0,0,0,4,0,0,0,0,0,0,0,0,4,0,0,4,4,4,4,4,4,4,4,4,4,4,4,4,36,33,0
0,0,0,4,4,4,4,4,4,4,4,4,4,25,0,0,0,0,0,0,0,18,4,4,4,4,4,4,36,33,0
0,0,0,0,0,0,0,0,0,0,0,0,4,4,4,4,4,4,4,4,4,4,4,4,4,4,4,4,36,33,0
0,0,0,0,0,0,0,0,0,0,0,0,4,4,4,4,4,4,4,4,3,4,4,4,4,4,4,4,36,33,0
0,0,0,0,0,0,0,0,0,0,0,0,4,4,4,4,4,4,4,4,3,4,4,4,4,4,4,4,36,33,0
0,33,34,4,4,4,4,4,4,0,0,0,4,4,4,4,4,4,4,4,3,4,4,3,4,4,4,4,36,33,0
0,33,34,4,0,0,0,0,4,0,0,0,4,4,4,4,4,4,4,4,3,4,4,3,4,4,4,4,36,33,0
0,33,34,4,0,0,0,0,4,16,16,4,4,4,4,4,4,4,4,4,4,4,4,4,4,4,4,4,36,33,0
0,33,34,4,0,0,0,0,4,4,4,4,4,4,4,4,4,4,4,4,4,4,4,4,4,4,4,4,36,33,0
0,33,34,4,0,0,0,0,4,4,4,4,4,4,4,4,4,4,4,4,4,4,4,4,4,4,4,4,36,33,0
0,33,34,4,0,0,0,0,4,4,4,4,4,4,4,4,4,4,4,4,4,4,4,4,4,4,4,4,36,33,0
0,33,34,4,0,0,0,0,4,4,4,4,4,4,4,4,4,4,4,4,4,4,4,4,4,4,4,4,36,33,0
0,33,34,4,4,4,4,4,4,4,4,4,4,4,4,4,4,4,4,4,4,4,4,4,4,4,4,4,36,33,0
0,33,34,4,4,4,4,4,4,4,4,4,4,4,4,4,4,4,4,4,4,4,4,4,4,4,4,4,36,33,0
0,33,34,35,35,35,35,35,35,35,35,35,35,35,35,35,35,35,35,35,35,35,35,35,35,35,35,35,35,33,0
0,33,33,33,33,33,33,33,33,33,33,33,33,33,33,33,33,33,33,33,33,33,33,33,33,33,33,33,33,33,0
0,0,0,0,0,0,0,0,0,0,0,0,0,0,0,0,0,0,0,0,0,0,0,0,0,0,0,0,0,0,0
0,0,0,0,0,0,0,0,0,0,0,0,0,0,0,0,0,0,0,0,0,0,0,0,0,0,0,0,0,0,0
:endlayer
layer: 7
0,0,0,0,0,0,0,0,0,0,0,0,0,0,0,0,0,0,0,0,0,0,0,0,0,0,0,0,0,0,0
0,0,0,0,0,0,0,0,0,0,0,0,0,0,0,0,0,0,0,0,0,0,0,0,0,0,0,0,0,0,0
0,0,0,0,0,0,0,0,0,0,0,0,0,0,0,0,0,0,0,0,0,0,0,0,0,20,20,4,4,0,0
0,0,0,0,0,0,0,0,0,0,0,0,0,0,0,0,0,0,0,0,0,0,0,0,0,0,0,0,4,0,0
0,0,0,0,0,0,0,0,0,0,0,0,0,0,0,4,4,4,4,4,4,4,4,4,0,0,0,0,4,0,0
0,0,0,4,4,4,4,4,4,4,4,4,4,0,0,4,4,4,4,4,4,4,4,4,0,0,0,0,4,0,0
0,0,0,4,4,4,4,4,4,4,4,4,4,0,0,4,4,4,4,4,4,4,4,4,0,0,0,0,4,0,0
0,0,0,4,4,4,4,4,4,4,4,4,4,0,0,4,4,4,4,4,4,4,4,4,16,16,16,16,4,0,0
0,0,0,4,4,4,4,4,4,4,4,4,4,0,0,4,4,4,4,4,4,4,4,4,4,4,4,4,4,0,0
0,0,0,4,4,4,4,4,4,4,4,4,4,0,0,4,4,4,4,4,4,4,4,4,4,4,4,4,4,0,0
0,0,0,4,4,4,4,4,4,4,4,4,4,0,0,4,4,4,4,4,4,4,4,4,4,4,4,4,4,0,0
0,0,0,4,4,4,4,4,4,4,4,4,4,0,0,4,4,4,4,4,4,4,4,4,4,4,4,4,4,0,0
0,0,0,4,4,4,4,4,4,4,4,4,4,0,0,4,4,4,4,4,4,4,4,4,4,4,4,4,4,0,0
0,0,0,4,4,4,4,4,4,4,4,4,4,0,0,0,0,0,0,0,0,0,18,4,4,4,4,4,4,0,0
0,0,0,0,0,0,0,0,0,0,0,0,4,4,4,4,4,4,4,4,4,4,4,4,4,4,4,4,4,0,0
0,0,0,0,0,0,0,0,0,0,0,0,4,4,4,4,4,4,3,3,3,3,3,3,4,4,4,4,4,0,0
0,0,0,0,0,0,0,0,0,0,0,0,4,4,4,4,4,4,3,3,3,3,3,3,4,4,4,4,4,0,0
0,0,4,4,4,4,4,4,4,0,0,0,4,4,4,4,4,4,3,3,3,3,3,3,4,4,4,4,4,0,0
0,0,4,4,4,4,4,4,4,0,0,0,4,4,4,4,4,4,3,3,3,3,3,3,4,4,4,4,4,0,0
0,0,4,4,4,4,4,4,4,0,0,4,4,4,4,4,4,4,4,4,4,4,4,4,4,4,4,4,4,0,0
0,0,4,4,4,4,4,4,4,16,16,4,4,4,4,4,4,4,4,4,4,4,4,4,4,4,4,4,4,0,0
0,0,4,4,4,4,4,4,4,4,4,4,4,4,4,4,4,4,4,4,4,4,4,4,4,4,4,4,4,0,0
0,0,4,4,4,4,4,4,4,4,4,4,4,4,4,4,4,4,4,4,4,4,4,4,4,4,4,4,4,0,0
0,0,4,4,4,4,4,4,4,4,4,4,4,4,4,4,4,4,4,4,4,4,4,4,4,4,4,4,4,0,0
0,0,4,4,4,4,4,4,4,4,4,4,4,4,4,4,4,4,4,4,4,4,4,4,4,4,4,4,4,0,0
0,0,4,4,4,4,4,4,4,4,4,4,4,4,4,4,4,4,4,4,4,4,4,4,4,4,4,4,4,0,0
0,0,4,4,4,4,4,4,4,4,4,4,4,4,4,4,4,4,4,4,4,4,4,4,4,4,4,4,4,0,0
0,0,0,0,0,0,0,0,0,0,0,0,0,0,0,0,0,0,0,0,0,0,0,0,0,0,0,0,0,0,0
0,0,0,0,0,0,0,0,0,0,0,0,0,0,0,0,0,0,0,0,0,0,0,0,0,0,0,0,0,0,0
0,0,0,0,0,0,0,0,0,0,0,0,0,0,0,0,0,0,0,0,0,0,0,0,0,0,0,0,0,0,0
:endlayer
layer: 8
0,0,0,0,0,0,0,0,0,0,0,0,0,0,0,0,0,0,0,0,0,0,0,0,0,0,0,0,0,0,0
0,0,0,0,0,0,0,0,0,0,0,0,0,0,0,0,0,0,0,0,0,0,0,0,0,0,0,0,0,0,0
0,0,0,0,0,0,0,0,0,0,0,0,0,0,0,0,0,0,0,0,0,0,0,0,0,0,20,20,20,0,0
0,0,0,0,0,0,0,0,0,0,0,0,0,0,0,0,0,0,0,0,0,0,0,0,0,0,0,0,20,0,0
0,0,0,0,0,0,0,0,0,0,0,0,0,0,0,4,4,4,4,4,4,4,4,4,0,0,0,0,20,0,0
0,0,0,4,4,4,4,4,4,4,4,4,4,0,0,4,4,4,4,40,0,0,43,4,0,0,0,0,20,0,0
0,0,0,4,0,0,0,0,0,0,0,0,4,0,0,4,4,0,0,0,0,0,0,4,0,0,0,0,20,0,0
0,0,0,4,0,0,0,0,0,0,0,0,4,0,0,4,38,0,0,0,0,0,0,4,0,0,0,0,20,0,0
0,0,0,4,0,0,0,0,0,0,0,0,4,0,0,4,37,0,0,0,0,0,0,19,0,0,0,20,20,0,0
0,0,0,4,0,0,0,0,0,0,0,0,4,0,0,4,0,0,0,0,0,0,0,4,0,0,0,0,20,0,0
0,0,0,4,0,0,0,0,0,0,0,0,4,0,0,4,0,0,0,0,0,0,0,4,0,0,0,0,20,0,0
0,0,0,4,0,0,0,0,0,0,0,0,4,0,0,4,0,0,0,0,0,0,0,4,0,0,0,0,20,0,0
0,0,0,4,0,0,0,0,0,0,0,0,4,0,0,4,4,4,4,4,4,4,4,4,0,0,0,0,20,0,0
0,0,0,4,4,4,4,4,4,4,4,4,4,0,0,0,0,0,0,0,0,0,0,0,0,0,0,0,20,0,0
0,0,0,0,0,0,0,0,0,0,0,0,4,4,4,4,4,4,0,0,0,0,0,0,0,0,0,20,20,0,0
0,0,0,0,0,0,0,0,0,0,0,0,4,0,0,0,0,4,16,4,4,4,4,4,4,0,0,0,20,0,0
0,0,0,0,0,0,0,0,0,0,0,0,4,0,0,0,0,4,4,4,42,42,42,42,4,0,0,0,20,0,0
0,0,20,20,20,20,20,20,20,0,0,0,4,0,0,0,0,4,4,4,42,42,42,42,4,0,0,0,20,0,0
0,0,20,0,0,0,0,0,20,0,0,0,4,4,4,11,4,4,39,4,42,42,42,42,4,0,0,0,20,0,0
0,0,20,0,0,0,0,0,20,0,0,4,4,0,0,0,0,4,0,4,42,42,42,42,4,0,0,0,20,0,0
0,0,20,0,0,0,0,0,20,0,0,0,4,0,0,0,0,4,0,4,41,41,41,42,4,0,0,0,20,0,0
0,0,20,0,0,0,0,0,0,0,0,0,4,0,0,0,0,4,0,4,41,41,41,42,4,40,0,0,20,0,0
0,0,20,0,0,0,0,0,0,0,0,0,4,0,0,0,0,4,0,4,41,41,41,42,4,0,0,0,20,0,0
0,0,20,0,0,0,0,0,0,0,0,0,4,4,4,4,4,4,0,4,4,4,4,4,4,0,0,0,20,0,0
0,0,20,0,0,0,0,0,0,0,0,0,0,0,0,0,0,0,0,0,0,0,0,0,0,0,0,0,20,0,0
0,0,20,0,0,0,0,0,0,0,0,0,0,0,0,0,0,0,0,0,0,0,0,0,0,0,0,0,20,0,0
0,0,20,20,20,20,20,20,20,20,20,20,20,20,20,20,20,20,20,20,20,20,20,20,20,20,20,20,20,0,0
0,0,0,0,0,0,0,0,0,0,0,0,0,0,0,0,0,0,0,0,0,0,0,0,0,0,0,0,0,0,0
0,0,0,0,0,0,0,0,0,0,0,0,0,0,0,0,0,0,0,0,0,0,0,0,0,0,0,0,0,0,0
0,0,0,0,0,0,0,0,0,0,0,0,0,0,0,0,0,0,0,0,0,0,0,0,0,0,0,0,0,0,0
:endlayer
layer: 9
0,0,0,0,0,0,0,0,0,0,0,0,0,0,0,0,0,0,0,0,0,0,0,0,0,0,0,0,0,0,0
0,0,0,0,0,0,0,0,0,0,0,0,0,0,0,0,0,0,0,0,0,0,0,0,0,0,0,0,0,0,0
0,0,0,0,0,0,0,0,0,0,0,0,0,0,0,0,0,0,0,0,0,0,0,0,0,0,0,20,44,0,0
0,0,0,0,0,0,0,0,0,0,0,0,0,0,0,0,0,0,0,0,0,0,0,25,0,0,0,0,0,0,0
0,0,0,0,0,0,0,0,0,0,0,0,0,0,0,4,4,4,4,21,4,4,4,4,24,0,0,0,0,0,0
0,0,0,4,4,4,4,4,21,4,4,4,4,0,0,4,4,4,40,0,0,0,0,4,0,0,0,0,0,0,0
0,0,0,4,0,0,0,0,0,0,0,0,4,0,0,4,4,0,0,0,0,0,0,4,0,0,0,0,0,0,0
0,0,0,4,0,0,0,0,0,0,0,0,4,0,0,4,0,0,0,0,0,0,0,4,0,0,0,0,44,0,0
0,0,0,4,0,0,0,0,0,0,0,0,4,0,0,21,0,0,0,0,0,0,0,48,0,0,0,20,0,0,0
0,0,0,21,0,0,0,0,0,0,0,0,21,0,0,4,0,0,0,0,0,0,0,4,0,0,0,0,0,0,0
0,0,0,4,0,0,0,0,0,0,0,0,4,0,0,4,0,0,0,0,0,0,0,4,0,0,0,0,0,0,0
0,0,0,4,0,0,0,0,0,0,0,0,4,0,0,4,0,0,0,0,0,0,0,4,0,0,0,0,0,0,0
0,0,0,4,0,0,0,0,0,0,0,0,4,0,0,4,4,4,4,21,4,4,4,4,0,0,0,0,0,0,0
0,0,0,4,4,4,4,4,21,4,4,4,4,0,0,0,0,0,0,0,0,0,0,0,0,0,0,0,0,0,0
0,0,0,0,0,0,0,0,0,0,0,0,4,4,4,21,4,4,0,0,0,0,0,0,0,0,0,20,44,0,0
0,0,0,0,0,0,0,0,0,0,0,0,4,0,0,0,0,4,0,4,4,4,4,4,4,0,0,0,0,0,0
0,0,0,0,0,0,0,0,0,0,0,0,21,0,0,0,0,4,0,4,0,0,35,42,4,0,0,0,0,0,0
0,0,44,0,0,0,0,0,44,0,0,0,4,0,0,0,0,4,0,46,0,0,20,34,4,0,0,0,0,0,0
0,0,0,0,0,0,0,0,0,0,0,0,4,4,4,45,4,4,0,4,0,0,0,0,4,0,0,0,0,0,0
0,0,0,0,0,0,0,0,0,0,0,4,4,0,0,0,0,4,0,4,0,0,0,0,4,0,0,0,0,0,0
0,0,0,0,0,0,0,0,44,0,0,0,4,0,0,0,0,4,0,4,47,47,0,0,4,0,0,0,0,0,0
0,0,0,0,0,0,0,0,0,0,0,0,21,0,0,0,0,4,0,4,0,47,0,0,46,0,0,0,0,0,0
0,0,0,0,0,0,0,0,0,0,0,0,4,0,0,0,0,4,0,4,0,47,0,0,4,0,0,0,0,0,0
0,0,0,0,0,0,0,0,0,0,0,0,4,4,21,21,4,4,0,4,4,4,4,4,4,0,0,0,0,0,0
0,0,0,0,0,0,0,0,0,0,0,0,0,0,0,0,0,0,0,0,0,0,0,0,0,0,0,0,0,0,0
0,0,0,0,0,0,0,0,0,0,0,0,0,0,0,0,0,0,0,0,0,0,0,0,0,0,0,0,0,0,0
0,0,44,0,0,0,0,0,0,0,0,0,0,0,0,0,0,0,0,0,0,0,0,0,0,0,0,0,44,0,0
0,0,0,0,0,0,0,0,0,0,0,0,0,0,0,0,0,0,0,0,0,0,0,0,0,0,0,0,0,0,0
0,0,0,0,0,0,0,0,0,0,0,0,0,0,0,0,0,0,0,0,0,0,0,0,0,0,0,0,0,0,0
0,0,0,0,0,0,0,0,0,0,0,0,0,0,0,0,0,0,0,0,0,0,0,0,0,0,0,0,0,0,0
:endlayer
layer: 10
0,0,0,0,0,0,0,0,0,0,0,0,0,0,0,0,0,0,0,0,0,0,0,0,0,0,0,0,0,0,0
0,0,0,0,0,0,0,0,0,0,0,0,0,0,0,0,0,0,0,0,0,0,0,0,0,0,0,0,0,0,0
0,0,0,0,0,0,0,0,0,0,0,0,0,0,0,0,0,0,0,0,0,0,0,0,0,0,0,20,0,0,0
0,0,0,0,0,0,0,0,0,0,0,0,0,0,0,0,0,0,0,0,0,0,0,0,0,0,0,0,0,0,0
0,0,0,0,0,0,0,0,0,0,0,0,0,0,0,4,4,4,4,21,4,4,4,4,0,0,0,0,0,0,0
0,0,0,4,4,4,4,4,21,4,4,4,4,0,0,4,4,40,0,0,0,0,0,4,0,0,0,0,0,0,0
0,0,0,4,0,0,0,0,0,27,0,0,4,0,0,4,4,0,0,0,0,0,0,4,0,0,0,0,0,0,0
0,0,0,4,0,0,0,0,0,0,0,0,4,0,0,4,24,0,0,0,0,0,29,4,0,0,0,0,0,0,0
0,0,0,4,0,0,0,0,0,0,0,0,4,0,0,21,0,0,0,0,0,0,0,4,0,0,0,20,0,0,0
0,0,0,21,0,0,0,0,0,0,0,0,21,0,0,4,0,0,0,0,0,0,0,4,0,0,0,0,0,0,0
0,0,0,4,0,0,0,0,0,0,0,0,4,0,0,4,0,0,0,0,0,0,0,4,0,0,0,0,0,0,0
0,0,0,4,0,0,0,0,0,0,0,0,4,0,0,4,0,0,0,0,0,0,0,4,0,0,0,0,0,0,0
0,0,0,4,0,0,0,0,0,25,0,0,4,0,0,4,4,4,4,21,4,4,4,4,0,0,0,0,0,0,0
0,0,29,4,4,4,4,4,21,4,4,4,4,0,0,0,0,0,0,0,0,0,0,0,0,0,0,0,0,0,0
0,0,0,27,0,0,0,0,0,0,0,0,4,4,4,21,4,4,0,0,0,0,0,0,25,0,0,20,0,0,0
0,0,0,0,0,0,0,0,0,0,0,0,4,0,0,0,27,4,0,4,50,21,21,50,4,24,0,0,0,0,0
0,0,0,0,0,0,0,0,0,0,0,0,21,0,0,0,0,4,0,42,0,0,0,0,42,0,0,0,0,0,0
0,0,0,0,0,0,0,0,0,0,0,0,4,0,0,0,25,4,0,49,0,0,51,0,21,0,0,0,0,0,0
0,0,0,0,0,0,0,0,0,0,0,0,4,4,4,4,4,4,0,42,0,0,0,0,21,0,0,0,0,0,0
0,0,0,0,0,0,0,0,0,0,0,4,4,0,0,0,0,4,29,42,0,0,0,0,42,0,0,0,0,0,0
0,0,0,0,0,0,0,0,0,0,0,0,4,0,0,0,0,4,0,21,0,0,0,0,42,0,0,0,0,0,0
0,0,0,0,0,0,0,0,0,0,0,0,21,0,0,0,0,4,0,42,0,0,0,0,52,0,0,0,0,0,0
0,0,0,0,0,0,0,0,0,0,0,0,4,0,0,0,0,4,0,42,0,0,0,0,42,0,0,0,0,0,0
0,0,0,0,0,0,0,0,0,0,0,0,4,4,21,21,4,4,29,4,50,21,21,50,4,24,0,0,0,0,0
0,0,0,0,0,0,0,0,0,0,0,0,0,0,0,0,0,0,0,27,0,0,0,0,27,0,0,0,0,0,0
0,0,0,0,0,0,0,0,0,0,0,0,0,0,0,0,0,0,0,0,0,0,0,0,0,0,0,0,0,0,0
0,0,0,0,0,0,0,0,0,0,0,0,0,0,0,0,0,0,0,0,0,0,0,0,0,0,0,0,0,0,0
0,0,0,0,0,0,0,0,0,0,0,0,0,0,0,0,0,0,0,0,0,0,0,0,0,0,0,0,0,0,0
0,0,0,0,0,0,0,0,0,0,0,0,0,0,0,0,0,0,0,0,0,0,0,0,0,0,0,0,0,0,0
0,0,0,0,0,0,0,0,0,0,0,0,0,0,0,0,0,0,0,0,0,0,0,0,0,0,0,0,0,0,0
:endlayer
layer: 11
0,0,0,0,0,0,0,0,0,0,0,0,0,0,0,0,0,0,0,0,0,0,0,0,0,0,0,0,0,0,0
0,0,0,0,0,0,0,0,0,0,0,0,0,0,0,0,0,0,0,0,0,0,0,0,0,0,0,0,0,0,0
0,0,0,0,0,0,0,0,0,0,0,0,0,0,0,0,0,0,0,0,0,0,0,0,0,0,0,20,0,0,0
0,0,0,0,0,0,0,0,0,0,0,0,0,0,0,0,0,0,0,0,0,0,0,0,0,0,0,0,0,0,0
0,0,53,53,53,53,53,53,53,53,53,53,53,0,0,4,4,4,4,21,4,4,4,4,0,0,0,0,0,0,0
0,0,0,4,42,42,42,42,42,42,42,42,4,0,0,4,40,0,0,0,0,0,0,4,0,0,0,0,0,0,0
0,0,0,4,0,0,0,0,0,0,0,0,4,0,0,4,4,0,0,0,0,0,0,4,0,0,0,0,0,0,0
0,0,0,4,0,0,0,0,0,0,0,0,4,0,0,4,0,0,0,0,0,0,0,4,0,0,0,0,0,0,0
0,0,0,4,0,0,0,0,0,0,0,0,4,0,0,21,0,0,0,0,0,0,0,4,0,0,0,20,0,0,0
0,0,0,4,0,0,0,0,0,0,0,0,4,0,0,4,0,0,0,0,0,0,0,4,0,0,0,0,0,0,0
0,0,0,4,0,0,0,0,0,0,0,0,4,0,0,4,0,0,0,0,0,0,0,4,0,0,0,0,0,0,0
0,0,0,4,0,0,0,0,0,0,0,0,4,0,0,4,0,0,0,0,0,0,0,4,0,0,0,0,0,0,0
0,0,0,4,0,0,0,0,0,0,0,0,4,0,29,4,4,4,4,21,4,4,4,4,24,0,0,0,0,0,0
0,0,0,4,42,42,42,42,42,42,42,42,4,0,0,27,0,25,0,0,0,0,0,27,0,0,0,0,0,0,0
0,0,35,35,35,35,35,35,35,35,35,35,4,4,4,21,4,4,24,0,0,0,0,0,0,0,0,20,0,0,0
0,0,0,0,0,0,0,0,0,0,0,0,4,0,0,0,0,4,0,4,4,4,4,4,4,36,0,0,0,0,0
0,0,0,0,0,0,0,0,0,0,0,0,21,0,0,0,0,4,0,42,27,0,0,0,42,36,0,0,0,0,0
0,0,0,0,0,0,0,0,0,0,0,0,4,0,0,0,0,4,0,42,24,0,0,0,42,36,0,0,0,0,0
0,0,0,0,0,0,0,0,0,0,0,29,4,4,4,4,4,4,0,42,0,0,0,0,42,36,0,0,0,0,0
0,0,0,0,0,0,0,0,0,0,0,4,4,0,0,0,0,4,0,42,0,0,0,0,42,36,0,0,0,0,0
0,0,0,0,0,0,0,0,0,0,0,0,4,0,0,0,0,4,0,42,0,0,0,0,42,36,0,0,0,0,0
0,0,0,0,0,0,0,0,0,0,0,0,4,0,0,0,0,4,0,42,0,0,0,29,42,36,0,0,0,0,0
0,0,0,0,0,0,0,0,0,0,0,0,4,0,0,0,0,4,0,42,24,0,0,0,42,36,0,0,0,0,0
0,0,0,0,0,0,0,0,0,0,0,29,4,4,4,4,4,4,0,4,4,4,4,4,4,36,0,0,0,0,0
0,0,0,0,0,0,0,0,0,0,0,0,27,0,0,0,0,0,0,0,0,0,0,0,0,36,0,0,0,0,0
0,0,0,0,0,0,0,0,0,0,0,0,0,0,0,0,0,0,0,0,0,0,0,0,0,0,0,0,0,0,0
0,0,0,0,0,0,0,0,0,0,0,0,0,0,0,0,0,0,0,0,0,0,0,0,0,0,0,0,0,0,0
0,0,0,0,0,0,0,0,0,0,0,0,0,0,0,0,0,0,0,0,0,0,0,0,0,0,0,0,0,0,0
0,0,0,0,0,0,0,0,0,0,0,0,0,0,0,0,0,0,0,0,0,0,0,0,0,0,0,0,0,0,0
0,0,0,0,0,0,0,0,0,0,0,0,0,0,0,0,0,0,0,0,0,0,0,0,0,0,0,0,0,0,0
:endlayer
layer: 12
0,0,0,0,0,0,0,0,0,0,0,0,0,0,0,0,0,0,0,0,0,0,0,0,0,0,0,0,0,0,0
0,0,0,0,0,0,0,0,0,0,0,0,0,0,0,0,0,0,0,0,0,0,0,0,0,0,0,0,0,0,0
0,0,0,0,0,0,0,0,0,0,0,0,0,42,42,42,42,42,42,42,42,42,42,42,42,42,42,42,0,0,0
0,0,0,0,0,0,0,0,0,0,0,0,0,42,42,42,42,42,42,42,42,42,42,42,42,42,42,42,0,0,0
0,0,0,0,0,0,0,0,0,0,0,0,0,42,42,4,4,4,4,4,4,4,4,4,42,42,42,42,0,0,0
0,0,53,53,53,53,53,53,53,53,53,53,53,42,42,4,0,0,0,4,4,4,4,4,42,42,42,42,0,0,0
0,0,0,4,42,42,42,42,42,42,42,42,4,42,42,4,16,4,4,4,4,4,4,4,42,42,42,42,0,0,0
0,0,0,4,0,0,0,0,0,0,0,0,4,42,42,4,4,4,4,4,4,4,4,4,42,42,42,42,0,0,0
0,0,0,4,0,0,0,0,0,0,0,0,4,42,42,4,4,4,4,4,4,4,4,4,42,42,42,42,0,0,0
0,0,0,4,0,0,0,0,0,0,0,0,4,42,42,4,4,4,4,4,4,4,4,4,42,42,42,42,0,0,0
0,0,0,4,0,0,0,0,0,0,0,0,4,42,42,4,4,4,4,4,4,4,4,4,42,42,42,42,0,0,0
0,0,0,4,0,0,0,0,0,0,0,0,4,42,42,4,4,4,4,4,4,4,4,4,42,42,42,42,0,0,0
0,0,0,4,42,42,42,42,42,42,42,42,4,42,42,4,4,4,4,4,4,4,4,4,42,42,42,42,0,0,0
0,0,35,35,35,35,35,35,35,35,35,35,35,42,42,42,42,42,42,42,42,42,42,42,42,42,42,42,0,0,0
0,0,0,0,0,0,0,0,0,0,0,0,4,4,4,4,4,4,42,42,42,42,42,42,42,42,42,42,0,0,0
0,0,0,0,0,0,0,0,0,0,0,0,4,0,0,0,0,4,56,42,42,42,42,42,36,0,0,0,0,0,0
0,0,0,0,0,0,0,0,0,0,0,0,4,0,0,0,0,4,56,42,42,0,0,42,36,0,0,0,0,0,0
0,0,0,0,0,0,0,0,0,0,0,0,4,0,0,0,0,4,56,42,42,0,0,42,36,0,0,0,0,0,0
0,0,0,0,0,0,0,0,0,0,0,0,4,4,4,4,4,4,56,42,42,0,0,42,36,0,0,0,0,0,0
0,0,0,0,0,0,0,0,0,0,0,4,4,0,0,0,0,4,56,42,42,0,0,42,36,0,0,0,0,0,0
0,0,0,0,0,0,0,0,0,0,0,55,4,0,0,0,0,4,56,42,42,0,0,42,36,0,0,0,0,0,0
0,0,0,0,0,0,0,0,0,0,0,55,4,0,0,0,0,4,56,42,42,0,0,42,36,0,0,0,0,0,0
0,0,0,0,0,0,0,0,0,0,0,55,4,0,0,0,0,4,56,42,42,0,0,42,36,0,0,0,0,0,0
0,0,0,0,0,0,0,0,0,0,0,55,4,4,4,4,4,4,56,42,42,42,42,42,36,0,0,0,0,0,0
0,0,0,0,0,0,0,0,0,0,0,54,54,54,54,54,54,54,56,0,0,0,0,0,36,0,0,0,0,0,0
0,0,0,0,0,0,0,0,0,0,0,0,0,0,0,0,0,0,0,0,0,0,0,0,0,0,0,0,0,0,0
0,0,0,0,0,0,0,0,0,0,0,0,0,0,0,0,0,0,0,0,0,0,0,0,0,0,0,0,0,0,0
0,0,0,0,0,0,0,0,0,0,0,0,0,0,0,0,0,0,0,0,0,0,0,0,0,0,0,0,0,0,0
0,0,0,0,0,0,0,0,0,0,0,0,0,0,0,0,0,0,0,0,0,0,0,0,0,0,0,0,0,0,0
0,0,0,0,0,0,0,0,0,0,0,0,0,0,0,0,0,0,0,0,0,0,0,0,0,0,0,0,0,0,0
:endlayer
layer: 13
0,0,0,0,0,0,0,0,0,0,0,0,0,0,0,0,0,0,0,0,0,0,0,0,0,0,0,0,0,0,0
0,0,0,0,0,0,0,0,0,0,0,0,0,0,0,0,0,0,0,0,0,0,0,0,0,0,0,0,0,0,0
0,0,0,0,0,0,0,0,0,0,0,0,0,20,20,20,20,20,20,20,20,20,20,20,20,20,20,20,0,0,0
0,0,0,0,0,0,0,0,0,0,0,0,0,20,0,0,0,0,0,0,0,0,0,0,0,0,0,20,0,0,0
0,0,0,0,0,0,0,0,0,0,0,0,0,20,0,4,4,4,4,4,4,4,4,4,0,0,0,20,0,0,0
0,0,0,0,0,0,0,0,0,0,0,0,0,20,0,4,0,0,0,60,0,0,0,4,0,0,0,20,0,0,0
0,0,53,53,53,53,53,53,53,53,53,53,53,20,0,4,0,0,0,0,0,0,0,19,0,0,0,20,0,0,0
0,0,0,4,42,42,42,42,42,42,42,42,4,0,0,4,0,0,0,0,0,0,0,4,0,0,0,20,0,0,0
0,0,0,4,0,0,0,0,0,0,0,0,4,0,0,4,0,0,0,0,0,0,0,4,0,0,0,20,0,0,0
0,0,0,4,0,0,0,0,0,0,0,0,4,0,0,4,0,0,0,0,0,0,0,4,0,0,0,20,0,0,0
0,0,0,4,0,0,0,0,0,0,0,0,4,0,0,57,0,0,0,0,0,0,0,4,0,0,0,20,0,0,0
0,0,0,4,42,42,42,42,42,42,42,42,4,0,0,4,0,58,59,0,0,0,0,4,0,0,0,20,0,0,0
0,0,35,35,35,35,35,35,35,35,35,35,35,0,0,4,4,4,4,4,4,4,4,4,0,0,0,20,0,0,0
0,0,0,0,0,0,0,0,0,0,0,0,0,0,0,0,0,0,0,0,0,0,0,0,0,0,0,20,0,0,0
0,0,0,0,0,0,0,0,0,0,0,0,4,42,42,42,42,4,0,20,20,20,20,20,20,20,20,20,0,0,0
0,0,0,0,0,0,0,0,0,0,0,0,4,0,0,0,0,4,0,0,34,42,42,36,0,0,0,0,0,0,0
0,0,0,0,0,0,0,0,0,0,0,0,4,0,0,0,0,4,0,0,34,42,42,36,0,0,0,0,0,0,0
0,0,0,0,0,0,0,0,0,0,0,0,4,0,0,0,0,4,0,0,34,42,42,36,0,0,0,0,0,0,0
0,0,0,0,0,0,0,0,0,0,0,0,4,42,42,42,42,4,24,0,34,42,42,36,0,0,0,0,0,0,0
0,0,0,0,0,0,0,0,0,0,0,34,35,35,35,35,35,35,0,0,34,42,42,36,0,0,0,0,0,0,0
0,0,0,0,0,0,0,0,0,0,0,0,33,33,33,33,33,33,0,0,34,42,42,36,0,0,0,0,0,0,0
0,0,0,0,0,0,0,0,0,0,0,0,33,33,33,33,33,33,0,0,34,42,42,36,0,0,0,0,0,0,0
0,0,0,0,0,0,0,0,0,0,0,0,33,33,33,33,33,33,0,0,34,42,42,36,0,0,0,0,0,0,0
0,0,0,0,0,0,0,0,0,0,0,0,33,33,42,33,33,33,0,0,34,42,42,36,0,0,0,0,0,0,0
0,0,0,0,0,0,0,0,0,0,0,0,0,0,0,0,0,0,0,0,34,0,0,36,0,0,0,0,0,0,0
0,0,0,0,0,0,0,0,0,0,0,0,0,0,0,0,0,0,0,0,0,0,0,0,0,0,0,0,0,0,0
0,0,0,0,0,0,0,0,0,0,0,0,0,0,0,0,0,0,0,0,0,0,0,0,0,0,0,0,0,0,0
0,0,0,0,0,0,0,0,0,0,0,0,0,0,0,0,0,0,0,0,0,0,0,0,0,0,0,0,0,0,0
0,0,0,0,0,0,0,0,0,0,0,0,0,0,0,0,0,0,0,0,0,0,0,0,0,0,0,0,0,0,0
0,0,0,0,0,0,0,0,0,0,0,0,0,0,0,0,0,0,0,0,0,0,0,0,0,0,0,0,0,0,0
:endlayer
layer: 14
0,0,0,0,0,0,0,0,0,0,0,0,0,0,0,0,0,0,0,0,0,0,0,0,0,0,0,0,0,0,0
0,0,0,0,0,0,0,0,0,0,0,0,0,0,0,0,0,0,0,0,0,0,0,0,0,0,0,0,0,0,0
0,0,0,0,0,0,0,0,0,0,0,0,0,44,0,0,0,0,0,0,0,0,0,0,0,0,0,44,0,0,0
0,0,0,0,0,0,0,0,0,0,0,0,0,0,0,0,0,0,0,0,0,0,0,0,0,0,0,0,0,0,0
0,0,0,0,0,0,0,0,0,0,0,0,0,0,0,4,4,4,4,21,4,4,4,4,0,0,0,0,0,0,0
0,0,0,0,0,0,0,0,0,0,0,0,0,0,0,4,0,0,0,0,0,0,0,4,0,0,0,0,0,0,0
0,0,0,0,0,0,0,0,0,0,0,0,0,0,0,4,0,0,0,0,0,0,0,62,0,0,0,0,0,0,0
0,0,53,53,53,53,53,53,53,53,53,53,53,0,0,4,0,0,0,0,0,0,0,4,0,0,0,44,0,0,0
0,0,0,4,42,42,42,42,42,42,42,42,4,0,0,21,0,0,0,0,0,0,0,21,0,0,0,0,0,0,0
0,0,0,4,0,0,0,0,0,0,0,0,4,0,0,4,0,0,0,0,0,0,0,4,0,0,0,0,0,0,0
0,0,0,4,42,42,42,42,42,42,42,42,4,0,0,61,0,0,0,0,0,0,0,4,0,0,0,0,0,0,0
0,0,35,35,35,35,35,35,35,35,35,35,35,0,0,4,0,0,0,0,0,0,0,4,0,0,0,0,0,0,0
0,0,0,0,0,0,0,0,0,0,0,0,0,0,0,4,4,4,4,21,4,4,4,4,0,0,0,0,0,0,0
0,0,0,0,0,0,0,0,0,0,0,0,0,0,0,0,0,0,0,0,0,0,0,0,0,0,0,0,0,0,0
0,0,0,0,0,0,0,0,0,0,0,53,53,53,53,53,53,53,0,44,0,0,0,0,0,0,0,44,0,0,0
0,0,0,0,0,0,0,0,0,0,0,0,4,42,42,42,42,4,0,0,0,34,36,0,0,0,0,0,0,0,0
0,0,0,0,0,0,0,0,0,0,0,0,4,0,0,0,0,4,0,0,0,34,36,0,0,0,0,0,0,0,0
0,0,0,0,0,0,0,0,0,0,0,0,4,42,42,42,42,4,0,0,0,34,36,0,0,0,0,0,0,0,0
0,0,0,0,0,0,0,0,0,0,0,35,35,35,35,35,35,35,0,0,0,34,36,0,0,0,0,0,0,0,0
0,0,0,0,0,0,0,0,0,0,0,0,0,0,0,0,0,0,0,0,0,34,36,0,0,0,0,0,0,0,0
0,0,0,0,0,0,0,0,0,0,0,0,0,0,0,0,0,0,0,0,0,34,36,0,0,0,0,0,0,0,0
0,0,0,0,0,0,0,0,0,0,0,0,0,0,0,0,0,0,0,0,0,34,36,0,0,0,0,0,0,0,0
0,0,0,0,0,0,0,0,0,0,0,0,0,0,0,0,0,0,0,0,0,34,36,0,0,0,0,0,0,0,0
0,0,0,0,0,0,0,0,0,0,0,0,0,0,44,0,0,0,0,0,0,34,36,0,0,0,0,0,0,0,0
0,0,0,0,0,0,0,0,0,0,0,0,0,0,0,0,0,0,0,0,0,34,36,0,0,0,0,0,0,0,0
0,0,0,0,0,0,0,0,0,0,0,0,0,0,0,0,0,0,0,0,0,0,0,0,0,0,0,0,0,0,0
0,0,0,0,0,0,0,0,0,0,0,0,0,0,0,0,0,0,0,0,0,0,0,0,0,0,0,0,0,0,0
0,0,0,0,0,0,0,0,0,0,0,0,0,0,0,0,0,0,0,0,0,0,0,0,0,0,0,0,0,0,0
0,0,0,0,0,0,0,0,0,0,0,0,0,0,0,0,0,0,0,0,0,0,0,0,0,0,0,0,0,0,0
0,0,0,0,0,0,0,0,0,0,0,0,0,0,0,0,0,0,0,0,0,0,0,0,0,0,0,0,0,0,0
:endlayer
layer: 15
0,0,0,0,0,0,0,0,0,0,0,0,0,0,0,0,0,0,0,0,0,0,0,0,0,0,0,0,0,0,0
0,0,0,0,0,0,0,0,0,0,0,0,0,0,0,0,0,0,0,0,0,0,0,0,0,0,0,0,0,0,0
0,0,0,0,0,0,0,0,0,0,0,0,0,0,0,0,0,0,0,0,0,0,0,0,0,0,0,0,0,0,0
0,0,0,0,0,0,0,0,0,0,0,0,0,0,0,25,0,0,0,0,0,0,0,25,0,0,0,0,0,0,0
0,0,0,0,0,0,0,0,0,0,0,0,0,0,29,4,4,4,4,21,4,4,4,4,24,0,0,0,0,0,0
0,0,0,0,0,0,0,0,0,0,0,0,0,0,0,4,0,0,0,0,0,0,0,4,0,0,0,0,0,0,0
0,0,0,0,0,0,0,0,0,0,0,0,0,0,0,4,0,0,0,0,0,0,0,4,0,0,0,0,0,0,0
0,0,0,0,0,0,0,0,0,0,0,0,0,0,0,4,24,0,0,0,0,0,29,4,0,0,0,0,0,0,0
0,0,53,53,53,53,53,53,53,53,53,53,53,0,0,21,0,0,0,0,0,0,0,21,0,0,0,0,0,0,0
0,0,55,42,42,42,42,42,42,42,42,42,42,0,0,4,0,0,0,0,0,0,0,4,0,0,0,0,0,0,0
0,0,35,35,35,35,35,35,35,35,35,35,35,0,0,4,0,0,0,0,0,0,0,4,0,0,0,0,0,0,0
0,0,0,0,0,0,0,0,0,0,0,0,0,0,0,4,0,0,0,0,0,0,0,4,0,0,0,0,0,0,0
0,0,0,0,0,0,0,0,0,0,0,0,0,0,29,4,4,4,4,21,4,4,4,4,24,0,0,0,0,0,0
0,0,0,0,0,0,0,0,0,0,0,0,0,0,0,27,0,0,0,0,0,0,0,27,0,0,0,0,0,0,0
0,0,0,0,0,0,0,0,0,0,0,0,0,0,0,0,0,0,0,0,0,0,0,0,0,0,0,0,0,0,0
0,0,0,0,0,0,0,0,0,0,0,53,53,53,53,53,53,53,0,0,0,0,0,0,0,0,0,0,0,0,0
0,0,0,0,0,0,0,0,0,0,0,55,42,42,42,42,42,42,0,0,0,0,0,0,0,0,0,0,0,0,0
0,0,0,0,0,0,0,0,0,0,0,35,35,35,35,35,35,35,0,0,0,0,0,0,0,0,0,0,0,0,0
0,0,0,0,0,0,0,0,0,0,0,0,0,0,0,0,0,0,0,0,0,0,0,0,0,0,0,0,0,0,0
0,0,0,0,0,0,0,0,0,0,0,0,0,0,0,0,0,0,0,0,0,0,0,0,0,0,0,0,0,0,0
0,0,0,0,0,0,0,0,0,0,0,0,0,0,0,0,0,0,0,0,0,0,0,0,0,0,0,0,0,0,0
0,0,0,0,0,0,0,0,0,0,0,0,0,0,0,0,0,0,0,0,0,0,0,0,0,0,0,0,0,0,0
0,0,0,0,0,0,0,0,0,0,0,0,0,0,0,0,0,0,0,0,0,0,0,0,0,0,0,0,0,0,0
0,0,0,0,0,0,0,0,0,0,0,0,0,0,0,0,0,0,0,0,0,0,0,0,0,0,0,0,0,0,0
0,0,0,0,0,0,0,0,0,0,0,0,0,0,0,0,0,0,0,0,0,0,0,0,0,0,0,0,0,0,0
0,0,0,0,0,0,0,0,0,0,0,0,0,0,0,0,0,0,0,0,0,0,0,0,0,0,0,0,0,0,0
0,0,0,0,0,0,0,0,0,0,0,0,0,0,0,0,0,0,0,0,0,0,0,0,0,0,0,0,0,0,0
0,0,0,0,0,0,0,0,0,0,0,0,0,0,0,0,0,0,0,0,0,0,0,0,0,0,0,0,0,0,0
0,0,0,0,0,0,0,0,0,0,0,0,0,0,0,0,0,0,0,0,0,0,0,0,0,0,0,0,0,0,0
0,0,0,0,0,0,0,0,0,0,0,0,0,0,0,0,0,0,0,0,0,0,0,0,0,0,0,0,0,0,0
:endlayer
layer: 16
0,0,0,0,0,0,0,0,0,0,0,0,0,0,0,0,0,0,0,0,0,0,0,0,0,0,0,0,0,0,0
0,0,0,0,0,0,0,0,0,0,0,0,0,0,0,0,0,0,0,0,0,0,0,0,0,0,0,0,0,0,0
0,0,0,0,0,0,0,0,0,0,0,0,0,0,0,0,0,0,0,0,0,0,0,0,0,0,0,0,0,0,0
0,0,0,0,0,0,0,0,0,0,0,0,0,0,34,0,0,0,0,0,0,0,0,0,36,0,0,0,0,0,0
0,0,0,0,0,0,0,0,0,0,0,0,0,0,34,4,4,4,4,4,4,4,4,4,36,0,0,0,0,0,0
0,0,0,0,0,0,0,0,0,0,0,0,0,0,34,42,0,0,0,0,0,0,0,42,36,0,0,0,0,0,0
0,0,0,0,0,0,0,0,0,0,0,0,0,0,34,42,0,0,0,0,0,0,0,42,36,0,0,0,0,0,0
0,0,0,0,0,0,0,0,0,0,0,0,0,0,34,42,0,0,0,0,0,0,0,42,36,0,0,0,0,0,0
0,0,0,0,0,0,0,0,0,0,0,0,0,0,34,42,0,0,0,0,0,0,0,42,36,0,0,0,0,0,0
0,0,0,44,0,0,0,0,0,0,0,0,44,0,34,42,0,0,0,0,0,0,0,42,36,0,0,0,0,0,0
0,0,0,0,0,0,0,0,0,0,0,0,0,0,34,42,0,0,0,0,0,0,0,42,36,0,0,0,0,0,0
0,0,0,0,0,0,0,0,0,0,0,0,0,0,34,42,0,0,0,0,0,0,0,42,36,0,0,0,0,0,0
0,0,0,0,0,0,0,0,0,0,0,0,0,0,34,4,4,4,4,4,4,4,4,4,36,0,0,0,0,0,0
0,0,0,0,0,0,0,0,0,0,0,0,0,0,34,0,0,0,0,0,0,0,0,0,36,0,0,0,0,0,0
0,0,0,0,0,0,0,0,0,0,0,0,0,0,0,0,0,0,0,0,0,0,0,0,0,0,0,0,0,0,0
0,0,0,0,0,0,0,0,0,0,0,0,0,0,0,0,0,0,0,0,0,0,0,0,0,0,0,0,0,0,0
0,0,0,0,0,0,0,0,0,0,0,0,44,0,0,0,0,44,0,0,0,0,0,0,0,0,0,0,0,0,0
0,0,0,0,0,0,0,0,0,0,0,0,0,0,0,0,0,0,0,0,0,0,0,0,0,0,0,0,0,0,0
0,0,0,0,0,0,0,0,0,0,0,0,0,0,0,0,0,0,0,0,0,0,0,0,0,0,0,0,0,0,0
0,0,0,0,0,0,0,0,0,0,0,0,0,0,0,0,0,0,0,0,0,0,0,0,0,0,0,0,0,0,0
0,0,0,0,0,0,0,0,0,0,0,0,0,0,0,0,0,0,0,0,0,0,0,0,0,0,0,0,0,0,0
0,0,0,0,0,0,0,0,0,0,0,0,0,0,0,0,0,0,0,0,0,0,0,0,0,0,0,0,0,0,0
0,0,0,0,0,0,0,0,0,0,0,0,0,0,0,0,0,0,0,0,0,0,0,0,0,0,0,0,0,0,0
0,0,0,0,0,0,0,0,0,0,0,0,0,0,0,0,0,0,0,0,0,0,0,0,0,0,0,0,0,0,0
0,0,0,0,0,0,0,0,0,0,0,0,0,0,0,0,0,0,0,0,0,0,0,0,0,0,0,0,0,0,0
0,0,0,0,0,0,0,0,0,0,0,0,0,0,0,0,0,0,0,0,0,0,0,0,0,0,0,0,0,0,0
0,0,0,0,0,0,0,0,0,0,0,0,0,0,0,0,0,0,0,0,0,0,0,0,0,0,0,0,0,0,0
0,0,0,0,0,0,0,0,0,0,0,0,0,0,0,0,0,0,0,0,0,0,0,0,0,0,0,0,0,0,0
0,0,0,0,0,0,0,0,0,0,0,0,0,0,0,0,0,0,0,0,0,0,0,0,0,0,0,0,0,0,0
0,0,0,0,0,0,0,0,0,0,0,0,0,0,0,0,0,0,0,0,0,0,0,0,0,0,0,0,0,0,0
:endlayer
layer: 17
0,0,0,0,0,0,0,0,0,0,0,0,0,0,0,0,0,0,0,0,0,0,0,0,0,0,0,0,0,0,0
0,0,0,0,0,0,0,0,0,0,0,0,0,0,0,0,0,0,0,0,0,0,0,0,0,0,0,0,0,0,0
0,0,0,0,0,0,0,0,0,0,0,0,0,0,0,0,0,0,0,0,0,0,0,0,0,0,0,0,0,0,0
0,0,0,0,0,0,0,0,0,0,0,0,0,0,0,34,0,0,0,0,0,0,0,36,0,0,0,0,0,0,0
0,0,0,0,0,0,0,0,0,0,0,0,0,0,0,34,4,4,4,4,4,4,4,36,0,0,0,0,0,0,0
0,0,0,0,0,0,0,0,0,0,0,0,0,0,0,34,42,0,0,0,0,0,42,36,0,0,0,0,0,0,0
0,0,0,0,0,0,0,0,0,0,0,0,0,0,0,34,42,0,0,0,0,0,42,36,0,0,0,0,0,0,0
0,0,0,0,0,0,0,0,0,0,0,0,0,0,0,34,42,0,0,0,0,0,42,36,0,0,0,0,0,0,0
0,0,0,0,0,0,0,0,0,0,0,0,0,0,0,34,42,0,0,0,0,0,42,36,0,0,0,0,0,0,0
0,0,0,0,0,0,0,0,0,0,0,0,0,0,0,34,42,0,0,0,0,0,42,36,0,0,0,0,0,0,0
0,0,0,0,0,0,0,0,0,0,0,0,0,0,0,34,42,0,0,0,0,0,42,36,0,0,0,0,0,0,0
0,0,0,0,0,0,0,0,0,0,0,0,0,0,0,34,42,0,0,0,0,0,42,36,0,0,0,0,0,0,0
0,0,0,0,0,0,0,0,0,0,0,0,0,0,0,34,4,4,4,4,4,4,4,36,0,0,0,0,0,0,0
0,0,0,0,0,0,0,0,0,0,0,0,0,0,0,34,0,0,0,0,0,0,0,36,0,0,0,0,0,0,0
0,0,0,0,0,0,0,0,0,0,0,0,0,0,0,0,0,0,0,0,0,0,0,0,0,0,0,0,0,0,0
0,0,0,0,0,0,0,0,0,0,0,0,0,0,0,0,0,0,0,0,0,0,0,0,0,0,0,0,0,0,0
0,0,0,0,0,0,0,0,0,0,0,0,0,0,0,0,0,0,0,0,0,0,0,0,0,0,0,0,0,0,0
0,0,0,0,0,0,0,0,0,0,0,0,0,0,0,0,0,0,0,0,0,0,0,0,0,0,0,0,0,0,0
0,0,0,0,0,0,0,0,0,0,0,0,0,0,0,0,0,0,0,0,0,0,0,0,0,0,0,0,0,0,0
0,0,0,0,0,0,0,0,0,0,0,0,0,0,0,0,0,0,0,0,0,0,0,0,0,0,0,0,0,0,0
0,0,0,0,0,0,0,0,0,0,0,0,0,0,0,0,0,0,0,0,0,0,0,0,0,0,0,0,0,0,0
0,0,0,0,0,0,0,0,0,0,0,0,0,0,0,0,0,0,0,0,0,0,0,0,0,0,0,0,0,0,0
0,0,0,0,0,0,0,0,0,0,0,0,0,0,0,0,0,0,0,0,0,0,0,0,0,0,0,0,0,0,0
0,0,0,0,0,0,0,0,0,0,0,0,0,0,0,0,0,0,0,0,0,0,0,0,0,0,0,0,0,0,0
0,0,0,0,0,0,0,0,0,0,0,0,0,0,0,0,0,0,0,0,0,0,0,0,0,0,0,0,0,0,0
0,0,0,0,0,0,0,0,0,0,0,0,0,0,0,0,0,0,0,0,0,0,0,0,0,0,0,0,0,0,0
0,0,0,0,0,0,0,0,0,0,0,0,0,0,0,0,0,0,0,0,0,0,0,0,0,0,0,0,0,0,0
0,0,0,0,0,0,0,0,0,0,0,0,0,0,0,0,0,0,0,0,0,0,0,0,0,0,0,0,0,0,0
0,0,0,0,0,0,0,0,0,0,0,0,0,0,0,0,0,0,0,0,0,0,0,0,0,0,0,0,0,0,0
0,0,0,0,0,0,0,0,0,0,0,0,0,0,0,0,0,0,0,0,0,0,0,0,0,0,0,0,0,0,0
:endlayer
layer: 18
0,0,0,0,0,0,0,0,0,0,0,0,0,0,0,0,0,0,0,0,0,0,0,0,0,0,0,0,0,0,0
0,0,0,0,0,0,0,0,0,0,0,0,0,0,0,0,0,0,0,0,0,0,0,0,0,0,0,0,0,0,0
0,0,0,0,0,0,0,0,0,0,0,0,0,0,0,0,0,0,0,0,0,0,0,0,0,0,0,0,0,0,0
0,0,0,0,0,0,0,0,0,0,0,0,0,0,0,0,34,0,0,0,0,0,36,0,0,0,0,0,0,0,0
0,0,0,0,0,0,0,0,0,0,0,0,0,0,0,0,34,4,4,4,4,4,36,0,0,0,0,0,0,0,0
0,0,0,0,0,0,0,0,0,0,0,0,0,0,0,0,34,42,0,0,0,42,36,0,0,0,0,0,0,0,0
0,0,0,0,0,0,0,0,0,0,0,0,0,0,0,0,34,42,0,0,0,42,36,0,0,0,0,0,0,0,0
0,0,0,0,0,0,0,0,0,0,0,0,0,0,0,0,34,42,0,0,0,42,36,0,0,0,0,0,0,0,0
0,0,0,0,0,0,0,0,0,0,0,0,0,0,0,0,34,42,0,0,0,42,36,0,0,0,0,0,0,0,0
0,0,0,0,0,0,0,0,0,0,0,0,0,0,0,0,34,42,0,0,0,42,36,0,0,0,0,0,0,0,0
0,0,0,0,0,0,0,0,0,0,0,0,0,0,0,0,34,42,0,0,0,42,36,0,0,0,0,0,0,0,0
0,0,0,0,0,0,0,0,0,0,0,0,0,0,0,0,34,42,0,0,0,42,36,0,0,0,0,0,0,0,0
0,0,0,0,0,0,0,0,0,0,0,0,0,0,0,0,34,4,4,4,4,4,36,0,0,0,0,0,0,0,0
0,0,0,0,0,0,0,0,0,0,0,0,0,0,0,0,34,0,0,0,0,0,36,0,0,0,0,0,0,0,0
0,0,0,0,0,0,0,0,0,0,0,0,0,0,0,0,0,0,0,0,0,0,0,0,0,0,0,0,0,0,0
0,0,0,0,0,0,0,0,0,0,0,0,0,0,0,0,0,0,0,0,0,0,0,0,0,0,0,0,0,0,0
0,0,0,0,0,0,0,0,0,0,0,0,0,0,0,0,0,0,0,0,0,0,0,0,0,0,0,0,0,0,0
0,0,0,0,0,0,0,0,0,0,0,0,0,0,0,0,0,0,0,0,0,0,0,0,0,0,0,0,0,0,0
0,0,0,0,0,0,0,0,0,0,0,0,0,0,0,0,0,0,0,0,0,0,0,0,0,0,0,0,0,0,0
0,0,0,0,0,0,0,0,0,0,0,0,0,0,0,0,0,0,0,0,0,0,0,0,0,0,0,0,0,0,0
0,0,0,0,0,0,0,0,0,0,0,0,0,0,0,0,0,0,0,0,0,0,0,0,0,0,0,0,0,0,0
0,0,0,0,0,0,0,0,0,0,0,0,0,0,0,0,0,0,0,0,0,0,0,0,0,0,0,0,0,0,0
0,0,0,0,0,0,0,0,0,0,0,0,0,0,0,0,0,0,0,0,0,0,0,0,0,0,0,0,0,0,0
0,0,0,0,0,0,0,0,0,0,0,0,0,0,0,0,0,0,0,0,0,0,0,0,0,0,0,0,0,0,0
0,0,0,0,0,0,0,0,0,0,0,0,0,0,0,0,0,0,0,0,0,0,0,0,0,0,0,0,0,0,0
0,0,0,0,0,0,0,0,0,0,0,0,0,0,0,0,0,0,0,0,0,0,0,0,0,0,0,0,0,0,0
0,0,0,0,0,0,0,0,0,0,0,0,0,0,0,0,0,0,0,0,0,0,0,0,0,0,0,0,0,0,0
0,0,0,0,0,0,0,0,0,0,0,0,0,0,0,0,0,0,0,0,0,0,0,0,0,0,0,0,0,0,0
0,0,0,0,0,0,0,0,0,0,0,0,0,0,0,0,0,0,0,0,0,0,0,0,0,0,0,0,0,0,0
0,0,0,0,0,0,0,0,0,0,0,0,0,0,0,0,0,0,0,0,0,0,0,0,0,0,0,0,0,0,0
:endlayer
layer: 19
0,0,0,0,0,0,0,0,0,0,0,0,0,0,0,0,0,0,0,0,0,0,0,0,0,0,0,0,0,0,0
0,0,0,0,0,0,0,0,0,0,0,0,0,0,0,0,0,0,0,0,0,0,0,0,0,0,0,0,0,0,0
0,0,0,0,0,0,0,0,0,0,0,0,0,0,0,0,0,0,0,0,0,0,0,0,0,0,0,0,0,0,0
0,0,0,0,0,0,0,0,0,0,0,0,0,0,0,0,0,34,0,0,0,36,0,0,0,0,0,0,0,0,0
0,0,0,0,0,0,0,0,0,0,0,0,0,0,0,0,0,34,4,4,4,36,0,0,0,0,0,0,0,0,0
0,0,0,0,0,0,0,0,0,0,0,0,0,0,0,0,0,34,42,0,42,36,0,0,0,0,0,0,0,0,0
0,0,0,0,0,0,0,0,0,0,0,0,0,0,0,0,0,34,42,0,42,36,0,0,0,0,0,0,0,0,0
0,0,0,0,0,0,0,0,0,0,0,0,0,0,0,0,0,34,42,0,42,36,0,0,0,0,0,0,0,0,0
0,0,0,0,0,0,0,0,0,0,0,0,0,0,0,0,0,34,42,0,42,36,0,0,0,0,0,0,0,0,0
0,0,0,0,0,0,0,0,0,0,0,0,0,0,0,0,0,34,42,0,42,36,0,0,0,0,0,0,0,0,0
0,0,0,0,0,0,0,0,0,0,0,0,0,0,0,0,0,34,42,0,42,36,0,0,0,0,0,0,0,0,0
0,0,0,0,0,0,0,0,0,0,0,0,0,0,0,0,0,34,42,0,42,36,0,0,0,0,0,0,0,0,0
0,0,0,0,0,0,0,0,0,0,0,0,0,0,0,0,0,34,4,4,4,36,0,0,0,0,0,0,0,0,0
0,0,0,0,0,0,0,0,0,0,0,0,0,0,0,0,0,34,0,0,0,36,0,0,0,0,0,0,0,0,0
0,0,0,0,0,0,0,0,0,0,0,0,0,0,0,0,0,0,0,0,0,0,0,0,0,0,0,0,0,0,0
0,0,0,0,0,0,0,0,0,0,0,0,0,0,0,0,0,0,0,0,0,0,0,0,0,0,0,0,0,0,0
0,0,0,0,0,0,0,0,0,0,0,0,0,0,0,0,0,0,0,0,0,0,0,0,0,0,0,0,0,0,0
0,0,0,0,0,0,0,0,0,0,0,0,0,0,0,0,0,0,0,0,0,0,0,0,0,0,0,0,0,0,0
0,0,0,0,0,0,0,0,0,0,0,0,0,0,0,0,0,0,0,0,0,0,0,0,0,0,0,0,0,0,0
0,0,0,0,0,0,0,0,0,0,0,0,0,0,0,0,0,0,0,0,0,0,0,0,0,0,0,0,0,0,0
0,0,0,0,0,0,0,0,0,0,0,0,0,0,0,0,0,0,0,0,0,0,0,0,0,0,0,0,0,0,0
0,0,0,0,0,0,0,0,0,0,0,0,0,0,0,0,0,0,0,0,0,0,0,0,0,0,0,0,0,0,0
0,0,0,0,0,0,0,0,0,0,0,0,0,0,0,0,0,0,0,0,0,0,0,0,0,0,0,0,0,0,0
0,0,0,0,0,0,0,0,0,0,0,0,0,0,0,0,0,0,0,0,0,0,0,0,0,0,0,0,0,0,0
0,0,0,0,0,0,0,0,0,0,0,0,0,0,0,0,0,0,0,0,0,0,0,0,0,0,0,0,0,0,0
0,0,0,0,0,0,0,0,0,0,0,0,0,0,0,0,0,0,0,0,0,0,0,0,0,0,0,0,0,0,0
0,0,0,0,0,0,0,0,0,0,0,0,0,0,0,0,0,0,0,0,0,0,0,0,0,0,0,0,0,0,0
0,0,0,0,0,0,0,0,0,0,0,0,0,0,0,0,0,0,0,0,0,0,0,0,0,0,0,0,0,0,0
0,0,0,0,0,0,0,0,0,0,0,0,0,0,0,0,0,0,0,0,0,0,0,0,0,0,0,0,0,0,0
0,0,0,0,0,0,0,0,0,0,0,0,0,0,0,0,0,0,0,0,0,0,0,0,0,0,0,0,0,0,0
:endlayer
layer: 20
0,0,0,0,0,0,0,0,0,0,0,0,0,0,0,0,0,0,0,0,0,0,0,0,0,0,0,0,0,0,0
0,0,0,0,0,0,0,0,0,0,0,0,0,0,0,0,0,0,0,0,0,0,0,0,0,0,0,0,0,0,0
0,0,0,0,0,0,0,0,0,0,0,0,0,0,0,0,0,0,0,0,0,0,0,0,0,0,0,0,0,0,0
0,0,0,0,0,0,0,0,0,0,0,0,0,0,0,0,0,0,34,63,36,0,0,0,0,0,0,0,0,0,0
0,0,0,0,0,0,0,0,0,0,0,0,0,0,0,0,0,0,34,42,36,0,0,0,0,0,0,0,0,0,0
0,0,0,0,0,0,0,0,0,0,0,0,0,0,0,0,0,0,34,42,36,0,0,0,0,0,0,0,0,0,0
0,0,0,0,0,0,0,0,0,0,0,0,0,0,0,0,0,0,34,42,36,0,0,0,0,0,0,0,0,0,0
0,0,0,0,0,0,0,0,0,0,0,0,0,0,0,0,0,0,34,42,36,0,0,0,0,0,0,0,0,0,0
0,0,0,0,0,0,0,0,0,0,0,0,0,0,0,0,0,0,34,42,36,0,0,0,0,0,0,0,0,0,0
0,0,0,0,0,0,0,0,0,0,0,0,0,0,0,0,0,0,34,42,36,0,0,0,0,0,0,0,0,0,0
0,0,0,0,0,0,0,0,0,0,0,0,0,0,0,0,0,0,34,42,36,0,0,0,0,0,0,0,0,0,0
0,0,0,0,0,0,0,0,0,0,0,0,0,0,0,0,0,0,34,42,36,0,0,0,0,0,0,0,0,0,0
0,0,0,0,0,0,0,0,0,0,0,0,0,0,0,0,0,0,34,42,36,0,0,0,0,0,0,0,0,0,0
0,0,0,0,0,0,0,0,0,0,0,0,0,0,0,0,0,0,34,54,36,0,0,0,0,0,0,0,0,0,0
0,0,0,0,0,0,0,0,0,0,0,0,0,0,0,0,0,0,0,0,0,0,0,0,0,0,0,0,0,0,0
0,0,0,0,0,0,0,0,0,0,0,0,0,0,0,0,0,0,0,0,0,0,0,0,0,0,0,0,0,0,0
0,0,0,0,0,0,0,0,0,0,0,0,0,0,0,0,0,0,0,0,0,0,0,0,0,0,0,0,0,0,0
0,0,0,0,0,0,0,0,0,0,0,0,0,0,0,0,0,0,0,0,0,0,0,0,0,0,0,0,0,0,0
0,0,0,0,0,0,0,0,0,0,0,0,0,0,0,0,0,0,0,0,0,0,0,0,0,0,0,0,0,0,0
0,0,0,0,0,0,0,0,0,0,0,0,0,0,0,0,0,0,0,0,0,0,0,0,0,0,0,0,0,0,0
0,0,0,0,0,0,0,0,0,0,0,0,0,0,0,0,0,0,0,0,0,0,0,0,0,0,0,0,0,0,0
0,0,0,0,0,0,0,0,0,0,0,0,0,0,0,0,0,0,0,0,0,0,0,0,0,0,0,0,0,0,0
0,0,0,0,0,0,0,0,0,0,0,0,0,0,0,0,0,0,0,0,0,0,0,0,0,0,0,0,0,0,0
0,0,0,0,0,0,0,0,0,0,0,0,0,0,0,0,0,0,0,0,0,0,0,0,0,0,0,0,0,0,0
0,0,0,0,0,0,0,0,0,0,0,0,0,0,0,0,0,0,0,0,0,0,0,0,0,0,0,0,0,0,0
0,0,0,0,0,0,0,0,0,0,0,0,0,0,0,0,0,0,0,0,0,0,0,0,0,0,0,0,0,0,0
0,0,0,0,0,0,0,0,0,0,0,0,0,0,0,0,0,0,0,0,0,0,0,0,0,0,0,0,0,0,0
0,0,0,0,0,0,0,0,0,0,0,0,0,0,0,0,0,0,0,0,0,0,0,0,0,0,0,0,0,0,0
0,0,0,0,0,0,0,0,0,0,0,0,0,0,0,0,0,0,0,0,0,0,0,0,0,0,0,0,0,0,0
0,0,0,0,0,0,0,0,0,0,0,0,0,0,0,0,0,0,0,0,0,0,0,0,0,0,0,0,0,0,0
:endlayer
layer: 21
0,0,0,0,0,0,0,0,0,0,0,0,0,0,0,0,0,0,0,0,0,0,0,0,0,0,0,0,0,0,0
0,0,0,0,0,0,0,0,0,0,0,0,0,0,0,0,0,0,0,0,0,0,0,0,0,0,0,0,0,0,0
0,0,0,0,0,0,0,0,0,0,0,0,0,0,0,0,0,0,0,0,0,0,0,0,0,0,0,0,0,0,0
0,0,0,0,0,0,0,0,0,0,0,0,0,0,0,0,0,0,0,0,0,0,0,0,0,0,0,0,0,0,0
0,0,0,0,0,0,0,0,0,0,0,0,0,0,0,0,0,0,0,44,0,0,0,0,0,0,0,0,0,0,0
0,0,0,0,0,0,0,0,0,0,0,0,0,0,0,0,0,0,0,0,0,0,0,0,0,0,0,0,0,0,0
0,0,0,0,0,0,0,0,0,0,0,0,0,0,0,0,0,0,0,0,0,0,0,0,0,0,0,0,0,0,0
0,0,0,0,0,0,0,0,0,0,0,0,0,0,0,0,0,0,0,0,0,0,0,0,0,0,0,0,0,0,0
0,0,0,0,0,0,0,0,0,0,0,0,0,0,0,0,0,0,0,0,0,0,0,0,0,0,0,0,0,0,0
0,0,0,0,0,0,0,0,0,0,0,0,0,0,0,0,0,0,0,0,0,0,0,0,0,0,0,0,0,0,0
0,0,0,0,0,0,0,0,0,0,0,0,0,0,0,0,0,0,0,0,0,0,0,0,0,0,0,0,0,0,0
0,0,0,0,0,0,0,0,0,0,0,0,0,0,0,0,0,0,0,0,0,0,0,0,0,0,0,0,0,0,0
0,0,0,0,0,0,0,0,0,0,0,0,0,0,0,0,0,0,0,44,0,0,0,0,0,0,0,0,0,0,0
0,0,0,0,0,0,0,0,0,0,0,0,0,0,0,0,0,0,0,0,0,0,0,0,0,0,0,0,0,0,0
0,0,0,0,0,0,0,0,0,0,0,0,0,0,0,0,0,0,0,0,0,0,0,0,0,0,0,0,0,0,0
0,0,0,0,0,0,0,0,0,0,0,0,0,0,0,0,0,0,0,0,0,0,0,0,0,0,0,0,0,0,0
0,0,0,0,0,0,0,0,0,0,0,0,0,0,0,0,0,0,0,0,0,0,0,0,0,0,0,0,0,0,0
0,0,0,0,0,0,0,0,0,0,0,0,0,0,0,0,0,0,0,0,0,0,0,0,0,0,0,0,0,0,0
0,0,0,0,0,0,0,0,0,0,0,0,0,0,0,0,0,0,0,0,0,0,0,0,0,0,0,0,0,0,0
0,0,0,0,0,0,0,0,0,0,0,0,0,0,0,0,0,0,0,0,0,0,0,0,0,0,0,0,0,0,0
0,0,0,0,0,0,0,0,0,0,0,0,0,0,0,0,0,0,0,0,0,0,0,0,0,0,0,0,0,0,0
0,0,0,0,0,0,0,0,0,0,0,0,0,0,0,0,0,0,0,0,0,0,0,0,0,0,0,0,0,0,0
0,0,0,0,0,0,0,0,0,0,0,0,0,0,0,0,0,0,0,0,0,0,0,0,0,0,0,0,0,0,0
0,0,0,0,0,0,0,0,0,0,0,0,0,0,0,0,0,0,0,0,0,0,0,0,0,0,0,0,0,0,0
0,0,0,0,0,0,0,0,0,0,0,0,0,0,0,0,0,0,0,0,0,0,0,0,0,0,0,0,0,0,0
0,0,0,0,0,0,0,0,0,0,0,0,0,0,0,0,0,0,0,0,0,0,0,0,0,0,0,0,0,0,0
0,0,0,0,0,0,0,0,0,0,0,0,0,0,0,0,0,0,0,0,0,0,0,0,0,0,0,0,0,0,0
0,0,0,0,0,0,0,0,0,0,0,0,0,0,0,0,0,0,0,0,0,0,0,0,0,0,0,0,0,0,0
0,0,0,0,0,0,0,0,0,0,0,0,0,0,0,0,0,0,0,0,0,0,0,0,0,0,0,0,0,0,0
0,0,0,0,0,0,0,0,0,0,0,0,0,0,0,0,0,0,0,0,0,0,0,0,0,0,0,0,0,0,0
:endlayer
layer: 22
0,0,0,0,0,0,0,0,0,0,0,0,0,0,0,0,0,0,0,0,0,0,0,0,0,0,0,0,0,0,0
0,0,0,0,0,0,0,0,0,0,0,0,0,0,0,0,0,0,0,0,0,0,0,0,0,0,0,0,0,0,0
0,0,0,0,0,0,0,0,0,0,0,0,0,0,0,0,0,0,0,0,0,0,0,0,0,0,0,0,0,0,0
0,0,0,0,0,0,0,0,0,0,0,0,0,0,0,0,0,0,0,0,0,0,0,0,0,0,0,0,0,0,0
0,0,0,0,0,0,0,0,0,0,0,0,0,0,0,0,0,0,0,0,0,0,0,0,0,0,0,0,0,0,0
0,0,0,0,0,0,0,0,0,0,0,0,0,0,0,0,0,0,0,0,0,0,0,0,0,0,0,0,0,0,0
0,0,0,0,0,0,0,0,0,0,0,0,0,0,0,0,0,0,0,0,0,0,0,0,0,0,0,0,0,0,0
0,0,0,0,0,0,0,0,0,0,0,0,0,0,0,0,0,0,0,0,0,0,0,0,0,0,0,0,0,0,0
0,0,0,0,0,0,0,0,0,0,0,0,0,0,0,0,0,0,0,0,0,0,0,0,0,0,0,0,0,0,0
0,0,0,0,0,0,0,0,0,0,0,0,0,0,0,0,0,0,0,0,0,0,0,0,0,0,0,0,0,0,0
0,0,0,0,0,0,0,0,0,0,0,0,0,0,0,0,0,0,0,0,0,0,0,0,0,0,0,0,0,0,0
0,0,0,0,0,0,0,0,0,0,0,0,0,0,0,0,0,0,0,0,0,0,0,0,0,0,0,0,0,0,0
0,0,0,0,0,0,0,0,0,0,0,0,0,0,0,0,0,0,0,0,0,0,0,0,0,0,0,0,0,0,0
0,0,0,0,0,0,0,0,0,0,0,0,0,0,0,0,0,0,0,0,0,0,0,0,0,0,0,0,0,0,0
0,0,0,0,0,0,0,0,0,0,0,0,0,0,0,0,0,0,0,0,0,0,0,0,0,0,0,0,0,0,0
0,0,0,0,0,0,0,0,0,0,0,0,0,0,0,0,0,0,0,0,0,0,0,0,0,0,0,0,0,0,0
0,0,0,0,0,0,0,0,0,0,0,0,0,0,0,0,0,0,0,0,0,0,0,0,0,0,0,0,0,0,0
0,0,0,0,0,0,0,0,0,0,0,0,0,0,0,0,0,0,0,0,0,0,0,0,0,0,0,0,0,0,0
0,0,0,0,0,0,0,0,0,0,0,0,0,0,0,0,0,0,0,0,0,0,0,0,0,0,0,0,0,0,0
0,0,0,0,0,0,0,0,0,0,0,0,0,0,0,0,0,0,0,0,0,0,0,0,0,0,0,0,0,0,0
0,0,0,0,0,0,0,0,0,0,0,0,0,0,0,0,0,0,0,0,0,0,0,0,0,0,0,0,0,0,0
0,0,0,0,0,0,0,0,0,0,0,0,0,0,0,0,0,0,0,0,0,0,0,0,0,0,0,0,0,0,0
0,0,0,0,0,0,0,0,0,0,0,0,0,0,0,0,0,0,0,0,0,0,0,0,0,0,0,0,0,0,0
0,0,0,0,0,0,0,0,0,0,0,0,0,0,0,0,0,0,0,0,0,0,0,0,0,0,0,0,0,0,0
0,0,0,0,0,0,0,0,0,0,0,0,0,0,0,0,0,0,0,0,0,0,0,0,0,0,0,0,0,0,0
0,0,0,0,0,0,0,0,0,0,0,0,0,0,0,0,0,0,0,0,0,0,0,0,0,0,0,0,0,0,0
0,0,0,0,0,0,0,0,0,0,0,0,0,0,0,0,0,0,0,0,0,0,0,0,0,0,0,0,0,0,0
0,0,0,0,0,0,0,0,0,0,0,0,0,0,0,0,0,0,0,0,0,0,0,0,0,0,0,0,0,0,0
0,0,0,0,0,0,0,0,0,0,0,0,0,0,0,0,0,0,0,0,0,0,0,0,0,0,0,0,0,0,0
0,0,0,0,0,0,0,0,0,0,0,0,0,0,0,0,0,0,0,0,0,0,0,0,0,0,0,0,0,0,0
:endlayer
layer: 23
0,0,0,0,0,0,0,0,0,0,0,0,0,0,0,0,0,0,0,0,0,0,0,0,0,0,0,0,0,0,0
0,0,0,0,0,0,0,0,0,0,0,0,0,0,0,0,0,0,0,0,0,0,0,0,0,0,0,0,0,0,0
0,0,0,0,0,0,0,0,0,0,0,0,0,0,0,0,0,0,0,0,0,0,0,0,0,0,0,0,0,0,0
0,0,0,0,0,0,0,0,0,0,0,0,0,0,0,0,0,0,0,0,0,0,0,0,0,0,0,0,0,0,0
0,0,0,0,0,0,0,0,0,0,0,0,0,0,0,0,0,0,0,0,0,0,0,0,0,0,0,0,0,0,0
0,0,0,0,0,0,0,0,0,0,0,0,0,0,0,0,0,0,0,0,0,0,0,0,0,0,0,0,0,0,0
0,0,0,0,0,0,0,0,0,0,0,0,0,0,0,0,0,0,0,0,0,0,0,0,0,0,0,0,0,0,0
0,0,0,0,0,0,0,0,0,0,0,0,0,0,0,0,0,0,0,0,0,0,0,0,0,0,0,0,0,0,0
0,0,0,0,0,0,0,0,0,0,0,0,0,0,0,0,0,0,0,0,0,0,0,0,0,0,0,0,0,0,0
0,0,0,0,0,0,0,0,0,0,0,0,0,0,0,0,0,0,0,0,0,0,0,0,0,0,0,0,0,0,0
0,0,0,0,0,0,0,0,0,0,0,0,0,0,0,0,0,0,0,0,0,0,0,0,0,0,0,0,0,0,0
0,0,0,0,0,0,0,0,0,0,0,0,0,0,0,0,0,0,0,0,0,0,0,0,0,0,0,0,0,0,0
0,0,0,0,0,0,0,0,0,0,0,0,0,0,0,0,0,0,0,0,0,0,0,0,0,0,0,0,0,0,0
0,0,0,0,0,0,0,0,0,0,0,0,0,0,0,0,0,0,0,0,0,0,0,0,0,0,0,0,0,0,0
0,0,0,0,0,0,0,0,0,0,0,0,0,0,0,0,0,0,0,0,0,0,0,0,0,0,0,0,0,0,0
0,0,0,0,0,0,0,0,0,0,0,0,0,0,0,0,0,0,0,0,0,0,0,0,0,0,0,0,0,0,0
0,0,0,0,0,0,0,0,0,0,0,0,0,0,0,0,0,0,0,0,0,0,0,0,0,0,0,0,0,0,0
0,0,0,0,0,0,0,0,0,0,0,0,0,0,0,0,0,0,0,0,0,0,0,0,0,0,0,0,0,0,0
0,0,0,0,0,0,0,0,0,0,0,0,0,0,0,0,0,0,0,0,0,0,0,0,0,0,0,0,0,0,0
0,0,0,0,0,0,0,0,0,0,0,0,0,0,0,0,0,0,0,0,0,0,0,0,0,0,0,0,0,0,0
0,0,0,0,0,0,0,0,0,0,0,0,0,0,0,0,0,0,0,0,0,0,0,0,0,0,0,0,0,0,0
0,0,0,0,0,0,0,0,0,0,0,0,0,0,0,0,0,0,0,0,0,0,0,0,0,0,0,0,0,0,0
0,0,0,0,0,0,0,0,0,0,0,0,0,0,0,0,0,0,0,0,0,0,0,0,0,0,0,0,0,0,0
0,0,0,0,0,0,0,0,0,0,0,0,0,0,0,0,0,0,0,0,0,0,0,0,0,0,0,0,0,0,0
0,0,0,0,0,0,0,0,0,0,0,0,0,0,0,0,0,0,0,0,0,0,0,0,0,0,0,0,0,0,0
0,0,0,0,0,0,0,0,0,0,0,0,0,0,0,0,0,0,0,0,0,0,0,0,0,0,0,0,0,0,0
0,0,0,0,0,0,0,0,0,0,0,0,0,0,0,0,0,0,0,0,0,0,0,0,0,0,0,0,0,0,0
0,0,0,0,0,0,0,0,0,0,0,0,0,0,0,0,0,0,0,0,0,0,0,0,0,0,0,0,0,0,0
0,0,0,0,0,0,0,0,0,0,0,0,0,0,0,0,0,0,0,0,0,0,0,0,0,0,0,0,0,0,0
0,0,0,0,0,0,0,0,0,0,0,0,0,0,0,0,0,0,0,0,0,0,0,0,0,0,0,0,0,0,0
:endlayer
layer: 24
0,0,0,0,0,0,0,0,0,0,0,0,0,0,0,0,0,0,0,0,0,0,0,0,0,0,0,0,0,0,0
0,0,0,0,0,0,0,0,0,0,0,0,0,0,0,0,0,0,0,0,0,0,0,0,0,0,0,0,0,0,0
0,0,0,0,0,0,0,0,0,0,0,0,0,0,0,0,0,0,0,0,0,0,0,0,0,0,0,0,0,0,0
0,0,0,0,0,0,0,0,0,0,0,0,0,0,0,0,0,0,0,0,0,0,0,0,0,0,0,0,0,0,0
0,0,0,0,0,0,0,0,0,0,0,0,0,0,0,0,0,0,0,0,0,0,0,0,0,0,0,0,0,0,0
0,0,0,0,0,0,0,0,0,0,0,0,0,0,0,0,0,0,0,0,0,0,0,0,0,0,0,0,0,0,0
0,0,0,0,0,0,0,0,0,0,0,0,0,0,0,0,0,0,0,0,0,0,0,0,0,0,0,0,0,0,0
0,0,0,0,0,0,0,0,0,0,0,0,0,0,0,0,0,0,0,0,0,0,0,0,0,0,0,0,0,0,0
0,0,0,0,0,0,0,0,0,0,0,0,0,0,0,0,0,0,0,0,0,0,0,0,0,0,0,0,0,0,0
0,0,0,0,0,0,0,0,0,0,0,0,0,0,0,0,0,0,0,0,0,0,0,0,0,0,0,0,0,0,0
0,0,0,0,0,0,0,0,0,0,0,0,0,0,0,0,0,0,0,0,0,0,0,0,0,0,0,0,0,0,0
0,0,0,0,0,0,0,0,0,0,0,0,0,0,0,0,0,0,0,0,0,0,0,0,0,0,0,0,0,0,0
0,0,0,0,0,0,0,0,0,0,0,0,0,0,0,0,0,0,0,0,0,0,0,0,0,0,0,0,0,0,0
0,0,0,0,0,0,0,0,0,0,0,0,0,0,0,0,0,0,0,0,0,0,0,0,0,0,0,0,0,0,0
0,0,0,0,0,0,0,0,0,0,0,0,0,0,0,0,0,0,0,0,0,0,0,0,0,0,0,0,0,0,0
0,0,0,0,0,0,0,0,0,0,0,0,0,0,0,0,0,0,0,0,0,0,0,0,0,0,0,0,0,0,0
0,0,0,0,0,0,0,0,0,0,0,0,0,0,0,0,0,0,0,0,0,0,0,0,0,0,0,0,0,0,0
0,0,0,0,0,0,0,0,0,0,0,0,0,0,0,0,0,0,0,0,0,0,0,0,0,0,0,0,0,0,0
0,0,0,0,0,0,0,0,0,0,0,0,0,0,0,0,0,0,0,0,0,0,0,0,0,0,0,0,0,0,0
0,0,0,0,0,0,0,0,0,0,0,0,0,0,0,0,0,0,0,0,0,0,0,0,0,0,0,0,0,0,0
0,0,0,0,0,0,0,0,0,0,0,0,0,0,0,0,0,0,0,0,0,0,0,0,0,0,0,0,0,0,0
0,0,0,0,0,0,0,0,0,0,0,0,0,0,0,0,0,0,0,0,0,0,0,0,0,0,0,0,0,0,0
0,0,0,0,0,0,0,0,0,0,0,0,0,0,0,0,0,0,0,0,0,0,0,0,0,0,0,0,0,0,0
0,0,0,0,0,0,0,0,0,0,0,0,0,0,0,0,0,0,0,0,0,0,0,0,0,0,0,0,0,0,0
0,0,0,0,0,0,0,0,0,0,0,0,0,0,0,0,0,0,0,0,0,0,0,0,0,0,0,0,0,0,0
0,0,0,0,0,0,0,0,0,0,0,0,0,0,0,0,0,0,0,0,0,0,0,0,0,0,0,0,0,0,0
0,0,0,0,0,0,0,0,0,0,0,0,0,0,0,0,0,0,0,0,0,0,0,0,0,0,0,0,0,0,0
0,0,0,0,0,0,0,0,0,0,0,0,0,0,0,0,0,0,0,0,0,0,0,0,0,0,0,0,0,0,0
0,0,0,0,0,0,0,0,0,0,0,0,0,0,0,0,0,0,0,0,0,0,0,0,0,0,0,0,0,0,0
0,0,0,0,0,0,0,0,0,0,0,0,0,0,0,0,0,0,0,0,0,0,0,0,0,0,0,0,0,0,0
:endlayer
layer: 25
0,0,0,0,0,0,0,0,0,0,0,0,0,0,0,0,0,0,0,0,0,0,0,0,0,0,0,0,0,0,0
0,0,0,0,0,0,0,0,0,0,0,0,0,0,0,0,0,0,0,0,0,0,0,0,0,0,0,0,0,0,0
0,0,0,0,0,0,0,0,0,0,0,0,0,0,0,0,0,0,0,0,0,0,0,0,0,0,0,0,0,0,0
0,0,0,0,0,0,0,0,0,0,0,0,0,0,0,0,0,0,0,0,0,0,0,0,0,0,0,0,0,0,0
0,0,0,0,0,0,0,0,0,0,0,0,0,0,0,0,0,0,0,0,0,0,0,0,0,0,0,0,0,0,0
0,0,0,0,0,0,0,0,0,0,0,0,0,0,0,0,0,0,0,0,0,0,0,0,0,0,0,0,0,0,0
0,0,0,0,0,0,0,0,0,0,0,0,0,0,0,0,0,0,0,0,0,0,0,0,0,0,0,0,0,0,0
0,0,0,0,0,0,0,0,0,0,0,0,0,0,0,0,0,0,0,0,0,0,0,0,0,0,0,0,0,0,0
0,0,0,0,0,0,0,0,0,0,0,0,0,0,0,0,0,0,0,0,0,0,0,0,0,0,0,0,0,0,0
0,0,0,0,0,0,0,0,0,0,0,0,0,0,0,0,0,0,0,0,0,0,0,0,0,0,0,0,0,0,0
0,0,0,0,0,0,0,0,0,0,0,0,0,0,0,0,0,0,0,0,0,0,0,0,0,0,0,0,0,0,0
0,0,0,0,0,0,0,0,0,0,0,0,0,0,0,0,0,0,0,0,0,0,0,0,0,0,0,0,0,0,0
0,0,0,0,0,0,0,0,0,0,0,0,0,0,0,0,0,0,0,0,0,0,0,0,0,0,0,0,0,0,0
0,0,0,0,0,0,0,0,0,0,0,0,0,0,0,0,0,0,0,0,0,0,0,0,0,0,0,0,0,0,0
0,0,0,0,0,0,0,0,0,0,0,0,0,0,0,0,0,0,0,0,0,0,0,0,0,0,0,0,0,0,0
0,0,0,0,0,0,0,0,0,0,0,0,0,0,0,0,0,0,0,0,0,0,0,0,0,0,0,0,0,0,0
0,0,0,0,0,0,0,0,0,0,0,0,0,0,0,0,0,0,0,0,0,0,0,0,0,0,0,0,0,0,0
0,0,0,0,0,0,0,0,0,0,0,0,0,0,0,0,0,0,0,0,0,0,0,0,0,0,0,0,0,0,0
0,0,0,0,0,0,0,0,0,0,0,0,0,0,0,0,0,0,0,0,0,0,0,0,0,0,0,0,0,0,0
0,0,0,0,0,0,0,0,0,0,0,0,0,0,0,0,0,0,0,0,0,0,0,0,0,0,0,0,0,0,0
0,0,0,0,0,0,0,0,0,0,0,0,0,0,0,0,0,0,0,0,0,0,0,0,0,0,0,0,0,0,0
0,0,0,0,0,0,0,0,0,0,0,0,0,0,0,0,0,0,0,0,0,0,0,0,0,0,0,0,0,0,0
0,0,0,0,0,0,0,0,0,0,0,0,0,0,0,0,0,0,0,0,0,0,0,0,0,0,0,0,0,0,0
0,0,0,0,0,0,0,0,0,0,0,0,0,0,0,0,0,0,0,0,0,0,0,0,0,0,0,0,0,0,0
0,0,0,0,0,0,0,0,0,0,0,0,0,0,0,0,0,0,0,0,0,0,0,0,0,0,0,0,0,0,0
0,0,0,0,0,0,0,0,0,0,0,0,0,0,0,0,0,0,0,0,0,0,0,0,0,0,0,0,0,0,0
0,0,0,0,0,0,0,0,0,0,0,0,0,0,0,0,0,0,0,0,0,0,0,0,0,0,0,0,0,0,0
0,0,0,0,0,0,0,0,0,0,0,0,0,0,0,0,0,0,0,0,0,0,0,0,0,0,0,0,0,0,0
0,0,0,0,0,0,0,0,0,0,0,0,0,0,0,0,0,0,0,0,0,0,0,0,0,0,0,0,0,0,0
0,0,0,0,0,0,0,0,0,0,0,0,0,0,0,0,0,0,0,0,0,0,0,0,0,0,0,0,0,0,0
:endlayer
layer: 26
0,0,0,0,0,0,0,0,0,0,0,0,0,0,0,0,0,0,0,0,0,0,0,0,0,0,0,0,0,0,0
0,0,0,0,0,0,0,0,0,0,0,0,0,0,0,0,0,0,0,0,0,0,0,0,0,0,0,0,0,0,0
0,0,0,0,0,0,0,0,0,0,0,0,0,0,0,0,0,0,0,0,0,0,0,0,0,0,0,0,0,0,0
0,0,0,0,0,0,0,0,0,0,0,0,0,0,0,0,0,0,0,0,0,0,0,0,0,0,0,0,0,0,0
0,0,0,0,0,0,0,0,0,0,0,0,0,0,0,0,0,0,0,0,0,0,0,0,0,0,0,0,0,0,0
0,0,0,0,0,0,0,0,0,0,0,0,0,0,0,0,0,0,0,0,0,0,0,0,0,0,0,0,0,0,0
0,0,0,0,0,0,0,0,0,0,0,0,0,0,0,0,0,0,0,0,0,0,0,0,0,0,0,0,0,0,0
0,0,0,0,0,0,0,0,0,0,0,0,0,0,0,0,0,0,0,0,0,0,0,0,0,0,0,0,0,0,0
0,0,0,0,0,0,0,0,0,0,0,0,0,0,0,0,0,0,0,0,0,0,0,0,0,0,0,0,0,0,0
0,0,0,0,0,0,0,0,0,0,0,0,0,0,0,0,0,0,0,0,0,0,0,0,0,0,0,0,0,0,0
0,0,0,0,0,0,0,0,0,0,0,0,0,0,0,0,0,0,0,0,0,0,0,0,0,0,0,0,0,0,0
0,0,0,0,0,0,0,0,0,0,0,0,0,0,0,0,0,0,0,0,0,0,0,0,0,0,0,0,0,0,0
0,0,0,0,0,0,0,0,0,0,0,0,0,0,0,0,0,0,0,0,0,0,0,0,0,0,0,0,0,0,0
0,0,0,0,0,0,0,0,0,0,0,0,0,0,0,0,0,0,0,0,0,0,0,0,0,0,0,0,0,0,0
0,0,0,0,0,0,0,0,0,0,0,0,0,0,0,0,0,0,0,0,0,0,0,0,0,0,0,0,0,0,0
0,0,0,0,0,0,0,0,0,0,0,0,0,0,0,0,0,0,0,0,0,0,0,0,0,0,0,0,0,0,0
0,0,0,0,0,0,0,0,0,0,0,0,0,0,0,0,0,0,0,0,0,0,0,0,0,0,0,0,0,0,0
0,0,0,0,0,0,0,0,0,0,0,0,0,0,0,0,0,0,0,0,0,0,0,0,0,0,0,0,0,0,0
0,0,0,0,0,0,0,0,0,0,0,0,0,0,0,0,0,0,0,0,0,0,0,0,0,0,0,0,0,0,0
0,0,0,0,0,0,0,0,0,0,0,0,0,0,0,0,0,0,0,0,0,0,0,0,0,0,0,0,0,0,0
0,0,0,0,0,0,0,0,0,0,0,0,0,0,0,0,0,0,0,0,0,0,0,0,0,0,0,0,0,0,0
0,0,0,0,0,0,0,0,0,0,0,0,0,0,0,0,0,0,0,0,0,0,0,0,0,0,0,0,0,0,0
0,0,0,0,0,0,0,0,0,0,0,0,0,0,0,0,0,0,0,0,0,0,0,0,0,0,0,0,0,0,0
0,0,0,0,0,0,0,0,0,0,0,0,0,0,0,0,0,0,0,0,0,0,0,0,0,0,0,0,0,0,0
0,0,0,0,0,0,0,0,0,0,0,0,0,0,0,0,0,0,0,0,0,0,0,0,0,0,0,0,0,0,0
0,0,0,0,0,0,0,0,0,0,0,0,0,0,0,0,0,0,0,0,0,0,0,0,0,0,0,0,0,0,0
0,0,0,0,0,0,0,0,0,0,0,0,0,0,0,0,0,0,0,0,0,0,0,0,0,0,0,0,0,0,0
0,0,0,0,0,0,0,0,0,0,0,0,0,0,0,0,0,0,0,0,0,0,0,0,0,0,0,0,0,0,0
0,0,0,0,0,0,0,0,0,0,0,0,0,0,0,0,0,0,0,0,0,0,0,0,0,0,0,0,0,0,0
0,0,0,0,0,0,0,0,0,0,0,0,0,0,0,0,0,0,0,0,0,0,0,0,0,0,0,0,0,0,0
:endlayer
layer: 27
0,0,0,0,0,0,0,0,0,0,0,0,0,0,0,0,0,0,0,0,0,0,0,0,0,0,0,0,0,0,0
0,0,0,0,0,0,0,0,0,0,0,0,0,0,0,0,0,0,0,0,0,0,0,0,0,0,0,0,0,0,0
0,0,0,0,0,0,0,0,0,0,0,0,0,0,0,0,0,0,0,0,0,0,0,0,0,0,0,0,0,0,0
0,0,0,0,0,0,0,0,0,0,0,0,0,0,0,0,0,0,0,0,0,0,0,0,0,0,0,0,0,0,0
0,0,0,0,0,0,0,0,0,0,0,0,0,0,0,0,0,0,0,0,0,0,0,0,0,0,0,0,0,0,0
0,0,0,0,0,0,0,0,0,0,0,0,0,0,0,0,0,0,0,0,0,0,0,0,0,0,0,0,0,0,0
0,0,0,0,0,0,0,0,0,0,0,0,0,0,0,0,0,0,0,0,0,0,0,0,0,0,0,0,0,0,0
0,0,0,0,0,0,0,0,0,0,0,0,0,0,0,0,0,0,0,0,0,0,0,0,0,0,0,0,0,0,0
0,0,0,0,0,0,0,0,0,0,0,0,0,0,0,0,0,0,0,0,0,0,0,0,0,0,0,0,0,0,0
0,0,0,0,0,0,0,0,0,0,0,0,0,0,0,0,0,0,0,0,0,0,0,0,0,0,0,0,0,0,0
0,0,0,0,0,0,0,0,0,0,0,0,0,0,0,0,0,0,0,0,0,0,0,0,0,0,0,0,0,0,0
0,0,0,0,0,0,0,0,0,0,0,0,0,0,0,0,0,0,0,0,0,0,0,0,0,0,0,0,0,0,0
0,0,0,0,0,0,0,0,0,0,0,0,0,0,0,0,0,0,0,0,0,0,0,0,0,0,0,0,0,0,0
0,0,0,0,0,0,0,0,0,0,0,0,0,0,0,0,0,0,0,0,0,0,0,0,0,0,0,0,0,0,0
0,0,0,0,0,0,0,0,0,0,0,0,0,0,0,0,0,0,0,0,0,0,0,0,0,0,0,0,0,0,0
0,0,0,0,0,0,0,0,0,0,0,0,0,0,0,0,0,0,0,0,0,0,0,0,0,0,0,0,0,0,0
0,0,0,0,0,0,0,0,0,0,0,0,0,0,0,0,0,0,0,0,0,0,0,0,0,0,0,0,0,0,0
0,0,0,0,0,0,0,0,0,0,0,0,0,0,0,0,0,0,0,0,0,0,0,0,0,0,0,0,0,0,0
0,0,0,0,0,0,0,0,0,0,0,0,0,0,0,0,0,0,0,0,0,0,0,0,0,0,0,0,0,0,0
0,0,0,0,0,0,0,0,0,0,0,0,0,0,0,0,0,0,0,0,0,0,0,0,0,0,0,0,0,0,0
0,0,0,0,0,0,0,0,0,0,0,0,0,0,0,0,0,0,0,0,0,0,0,0,0,0,0,0,0,0,0
0,0,0,0,0,0,0,0,0,0,0,0,0,0,0,0,0,0,0,0,0,0,0,0,0,0,0,0,0,0,0
0,0,0,0,0,0,0,0,0,0,0,0,0,0,0,0,0,0,0,0,0,0,0,0,0,0,0,0,0,0,0
0,0,0,0,0,0,0,0,0,0,0,0,0,0,0,0,0,0,0,0,0,0,0,0,0,0,0,0,0,0,0
0,0,0,0,0,0,0,0,0,0,0,0,0,0,0,0,0,0,0,0,0,0,0,0,0,0,0,0,0,0,0
0,0,0,0,0,0,0,0,0,0,0,0,0,0,0,0,0,0,0,0,0,0,0,0,0,0,0,0,0,0,0
0,0,0,0,0,0,0,0,0,0,0,0,0,0,0,0,0,0,0,0,0,0,0,0,0,0,0,0,0,0,0
0,0,0,0,0,0,0,0,0,0,0,0,0,0,0,0,0,0,0,0,0,0,0,0,0,0,0,0,0,0,0
0,0,0,0,0,0,0,0,0,0,0,0,0,0,0,0,0,0,0,0,0,0,0,0,0,0,0,0,0,0,0
0,0,0,0,0,0,0,0,0,0,0,0,0,0,0,0,0,0,0,0,0,0,0,0,0,0,0,0,0,0,0
:endlayer

#### RULES ####
rule:
plugin=vanillaBlocks
number=1
data:
JSON:{{"val":{"blockName":{"val":"minecraft:cobblestone","id":"ss"},"meta":{"val":"0","id":"pi"},"buildPass":{"val":"0","id":"pi"}},"id":"ct"}}
:enddata
:endrule

rule:
plugin=vanillaBlocks
number=2
data:
JSON:{{"val":{"blockName":{"val":"minecraft:stone","id":"ss"},"meta":{"val":"0","id":"pi"},"buildPass":{"val":"0","id":"pi"}},"id":"ct"}}
:enddata
:endrule

rule:
plugin=vanillaBlocks
number=3
data:
JSON:{{"val":{"blockName":{"val":"minecraft:dirt","id":"ss"},"meta":{"val":"0","id":"pi"},"buildPass":{"val":"0","id":"pi"}},"id":"ct"}}
:enddata
:endrule

rule:
plugin=vanillaBlocks
number=4
data:
JSON:{{"val":{"blockName":{"val":"minecraft:stonebrick","id":"ss"},"meta":{"val":"0","id":"pi"},"buildPass":{"val":"0","id":"pi"}},"id":"ct"}}
:enddata
:endrule

rule:
plugin=vanillaBlocks
number=5
data:
JSON:{{"val":{"blockName":{"val":"minecraft:stonebrick","id":"ss"},"meta":{"val":"1","id":"pi"},"buildPass":{"val":"0","id":"pi"}},"id":"ct"}}
:enddata
:endrule

rule:
plugin=vanillaBlocks
number=6
data:
JSON:{{"val":{"blockName":{"val":"minecraft:stonebrick","id":"ss"},"meta":{"val":"2","id":"pi"},"buildPass":{"val":"0","id":"pi"}},"id":"ct"}}
:enddata
:endrule

rule:
plugin=vanillaBlocks
number=7
data:
JSON:{{"val":{"blockName":{"val":"minecraft:coal_ore","id":"ss"},"meta":{"val":"0","id":"pi"},"buildPass":{"val":"0","id":"pi"}},"id":"ct"}}
:enddata
:endrule

rule:
plugin=vanillaBlocks
number=8
data:
JSON:{{"val":{"blockName":{"val":"minecraft:gravel","id":"ss"},"meta":{"val":"0","id":"pi"},"buildPass":{"val":"0","id":"pi"}},"id":"ct"}}
:enddata
:endrule

rule:
plugin=vanillaBlocks
number=9
data:
JSON:{{"val":{"blockName":{"val":"minecraft:grass","id":"ss"},"meta":{"val":"0","id":"pi"},"buildPass":{"val":"0","id":"pi"}},"id":"ct"}}
:enddata
:endrule

rule:
plugin=vanillaBlocks
number=10
data:
JSON:{{"val":{"blockName":{"val":"minecraft:stone_stairs","id":"ss"},"meta":{"val":"2","id":"pi"},"buildPass":{"val":"0","id":"pi"}},"id":"ct"}}
:enddata
:endrule

rule:
plugin=vanillaDoors
number=11
data:
JSON:{{"val":{"sideFlag":{"val":"8","id":"pb"},"blockName":{"val":"minecraft:wooden_door","id":"ss"},"meta":{"val":"3","id":"pi"},"buildPass":{"val":"2","id":"pi"}},"id":"ct"}}
:enddata
:endrule

rule:
plugin=vanillaBlocks
number=12
data:
JSON:{{"val":{"blockName":{"val":"minecraft:stone_stairs","id":"ss"},"meta":{"val":"0","id":"pi"},"buildPass":{"val":"0","id":"pi"}},"id":"ct"}}
:enddata
:endrule

rule:
plugin=vanillaDoors
number=13
data:
JSON:{{"val":{"sideFlag":{"val":"8","id":"pb"},"blockName":{"val":"minecraft:wooden_door","id":"ss"},"meta":{"val":"1","id":"pi"},"buildPass":{"val":"2","id":"pi"}},"id":"ct"}}
:enddata
:endrule

rule:
plugin=vanillaInventory
number=14
data:
JSON:{{"val":{"lootLevel":{"val":"0","id":"pi"},"inventoryData":{"val":{"length":{"val":"27","id":"pi"},"inventoryContents":{"val":[],"id":"ls"}},"id":"ct"},"teData":{"val":{"id":{"val":"Chest","id":"ss"},"z":{"val":"731","id":"pi"},"y":{"val":"87","id":"pi"},"x":{"val":"1112","id":"pi"}},"id":"ct"},"blockName":{"val":"minecraft:chest","id":"ss"},"meta":{"val":"4","id":"pi"},"buildPass":{"val":"0","id":"pi"}},"id":"ct"}}
:enddata
:endrule

rule:
plugin=vanillaInventory
number=15
data:
JSON:{{"val":{"lootLevel":{"val":"0","id":"pi"},"inventoryData":{"val":{"length":{"val":"27","id":"pi"},"inventoryContents":{"val":[],"id":"ls"}},"id":"ct"},"teData":{"val":{"id":{"val":"Chest","id":"ss"},"z":{"val":"731","id":"pi"},"y":{"val":"87","id":"pi"},"x":{"val":"1113","id":"pi"}},"id":"ct"},"blockName":{"val":"minecraft:chest","id":"ss"},"meta":{"val":"4","id":"pi"},"buildPass":{"val":"0","id":"pi"}},"id":"ct"}}
:enddata
:endrule

rule:
plugin=vanillaBlocks
number=16
data:
JSON:{{"val":{"blockName":{"val":"minecraft:stone_brick_stairs","id":"ss"},"meta":{"val":"2","id":"pi"},"buildPass":{"val":"0","id":"pi"}},"id":"ct"}}
:enddata
:endrule

rule:
plugin=vanillaDoors
number=17
data:
JSON:{{"val":{"sideFlag":{"val":"0","id":"pb"},"blockName":{"val":"minecraft:wooden_door","id":"ss"},"meta":{"val":"8","id":"pi"},"buildPass":{"val":"2","id":"pi"}},"id":"ct"}}
:enddata
:endrule

rule:
plugin=vanillaBlocks
number=18
data:
JSON:{{"val":{"blockName":{"val":"minecraft:stone_brick_stairs","id":"ss"},"meta":{"val":"0","id":"pi"},"buildPass":{"val":"0","id":"pi"}},"id":"ct"}}
:enddata
:endrule

rule:
plugin=vanillaDoors
number=19
data:
JSON:{{"val":{"sideFlag":{"val":"8","id":"pb"},"blockName":{"val":"minecraft:wooden_door","id":"ss"},"meta":{"val":"2","id":"pi"},"buildPass":{"val":"2","id":"pi"}},"id":"ct"}}
:enddata
:endrule

rule:
plugin=vanillaBlocks
number=20
data:
JSON:{{"val":{"blockName":{"val":"minecraft:fence","id":"ss"},"meta":{"val":"0","id":"pi"},"buildPass":{"val":"0","id":"pi"}},"id":"ct"}}
:enddata
:endrule

rule:
plugin=vanillaBlocks
number=21
data:
JSON:{{"val":{"blockName":{"val":"minecraft:glass_pane","id":"ss"},"meta":{"val":"0","id":"pi"},"buildPass":{"val":"0","id":"pi"}},"id":"ct"}}
:enddata
:endrule

rule:
plugin=vanillaDoors
number=22
data:
JSON:{{"val":{"sideFlag":{"val":"0","id":"pb"},"blockName":{"val":"minecraft:wooden_door","id":"ss"},"meta":{"val":"8","id":"pi"},"buildPass":{"val":"2","id":"pi"}},"id":"ct"}}
:enddata
:endrule

rule:
plugin=vanillaDoors
number=23
data:
JSON:{{"val":{"sideFlag":{"val":"0","id":"pb"},"blockName":{"val":"minecraft:wooden_door","id":"ss"},"meta":{"val":"8","id":"pi"},"buildPass":{"val":"2","id":"pi"}},"id":"ct"}}
:enddata
:endrule

rule:
plugin=vanillaBlocks
number=24
data:
JSON:{{"val":{"blockName":{"val":"minecraft:torch","id":"ss"},"meta":{"val":"1","id":"pi"},"buildPass":{"val":"2","id":"pi"}},"id":"ct"}}
:enddata
:endrule

rule:
plugin=vanillaBlocks
number=25
data:
JSON:{{"val":{"blockName":{"val":"minecraft:torch","id":"ss"},"meta":{"val":"4","id":"pi"},"buildPass":{"val":"2","id":"pi"}},"id":"ct"}}
:enddata
:endrule

rule:
plugin=vanillaDoors
number=26
data:
JSON:{{"val":{"sideFlag":{"val":"0","id":"pb"},"blockName":{"val":"minecraft:wooden_door","id":"ss"},"meta":{"val":"8","id":"pi"},"buildPass":{"val":"2","id":"pi"}},"id":"ct"}}
:enddata
:endrule

rule:
plugin=vanillaBlocks
number=27
data:
JSON:{{"val":{"blockName":{"val":"minecraft:torch","id":"ss"},"meta":{"val":"3","id":"pi"},"buildPass":{"val":"2","id":"pi"}},"id":"ct"}}
:enddata
:endrule

rule:
plugin=vanillaDoors
number=28
data:
JSON:{{"val":{"sideFlag":{"val":"0","id":"pb"},"blockName":{"val":"minecraft:wooden_door","id":"ss"},"meta":{"val":"8","id":"pi"},"buildPass":{"val":"2","id":"pi"}},"id":"ct"}}
:enddata
:endrule

rule:
plugin=vanillaBlocks
number=29
data:
JSON:{{"val":{"blockName":{"val":"minecraft:torch","id":"ss"},"meta":{"val":"2","id":"pi"},"buildPass":{"val":"2","id":"pi"}},"id":"ct"}}
:enddata
:endrule

rule:
plugin=vanillaDoors
number=30
data:
JSON:{{"val":{"sideFlag":{"val":"0","id":"pb"},"blockName":{"val":"minecraft:wooden_door","id":"ss"},"meta":{"val":"8","id":"pi"},"buildPass":{"val":"2","id":"pi"}},"id":"ct"}}
:enddata
:endrule

rule:
plugin=vanillaDoors
number=31
data:
JSON:{{"val":{"sideFlag":{"val":"0","id":"pb"},"blockName":{"val":"minecraft:wooden_door","id":"ss"},"meta":{"val":"8","id":"pi"},"buildPass":{"val":"2","id":"pi"}},"id":"ct"}}
:enddata
:endrule

rule:
plugin=vanillaDoors
number=32
data:
JSON:{{"val":{"sideFlag":{"val":"0","id":"pb"},"blockName":{"val":"minecraft:wooden_door","id":"ss"},"meta":{"val":"8","id":"pi"},"buildPass":{"val":"2","id":"pi"}},"id":"ct"}}
:enddata
:endrule

rule:
plugin=vanillaBlocks
number=33
data:
JSON:{{"val":{"blockName":{"val":"minecraft:wooden_slab","id":"ss"},"meta":{"val":"0","id":"pi"},"buildPass":{"val":"0","id":"pi"}},"id":"ct"}}
:enddata
:endrule

rule:
plugin=vanillaBlocks
number=34
data:
JSON:{{"val":{"blockName":{"val":"minecraft:oak_stairs","id":"ss"},"meta":{"val":"0","id":"pi"},"buildPass":{"val":"0","id":"pi"}},"id":"ct"}}
:enddata
:endrule

rule:
plugin=vanillaBlocks
number=35
data:
JSON:{{"val":{"blockName":{"val":"minecraft:oak_stairs","id":"ss"},"meta":{"val":"3","id":"pi"},"buildPass":{"val":"0","id":"pi"}},"id":"ct"}}
:enddata
:endrule

rule:
plugin=vanillaBlocks
number=36
data:
JSON:{{"val":{"blockName":{"val":"minecraft:oak_stairs","id":"ss"},"meta":{"val":"1","id":"pi"},"buildPass":{"val":"0","id":"pi"}},"id":"ct"}}
:enddata
:endrule

rule:
plugin=vanillaInventory
number=37
data:
JSON:{{"val":{"lootLevel":{"val":"0","id":"pi"},"inventoryData":{"val":{"length":{"val":"27","id":"pi"},"inventoryContents":{"val":[],"id":"ls"}},"id":"ct"},"teData":{"val":{"id":{"val":"Chest","id":"ss"},"z":{"val":"740","id":"pi"},"y":{"val":"92","id":"pi"},"x":{"val":"1125","id":"pi"}},"id":"ct"},"blockName":{"val":"minecraft:chest","id":"ss"},"meta":{"val":"5","id":"pi"},"buildPass":{"val":"0","id":"pi"}},"id":"ct"}}
:enddata
:endrule

rule:
plugin=vanillaInventory
number=38
data:
JSON:{{"val":{"lootLevel":{"val":"0","id":"pi"},"inventoryData":{"val":{"length":{"val":"27","id":"pi"},"inventoryContents":{"val":[],"id":"ls"}},"id":"ct"},"teData":{"val":{"id":{"val":"Chest","id":"ss"},"z":{"val":"740","id":"pi"},"y":{"val":"92","id":"pi"},"x":{"val":"1126","id":"pi"}},"id":"ct"},"blockName":{"val":"minecraft:chest","id":"ss"},"meta":{"val":"5","id":"pi"},"buildPass":{"val":"0","id":"pi"}},"id":"ct"}}
:enddata
:endrule

rule:
plugin=vanillaBlocks
number=39
data:
JSON:{{"val":{"blockName":{"val":"minecraft:stone_brick_stairs","id":"ss"},"meta":{"val":"3","id":"pi"},"buildPass":{"val":"0","id":"pi"}},"id":"ct"}}
:enddata
:endrule

rule:
plugin=vanillaBlocks
number=40
data:
JSON:{{"val":{"blockName":{"val":"minecraft:stone_brick_stairs","id":"ss"},"meta":{"val":"1","id":"pi"},"buildPass":{"val":"0","id":"pi"}},"id":"ct"}}
:enddata
:endrule

rule:
plugin=vanillaBlocks
number=41
data:
JSON:{{"val":{"blockName":{"val":"minecraft:double_stone_slab","id":"ss"},"meta":{"val":"0","id":"pi"},"buildPass":{"val":"0","id":"pi"}},"id":"ct"}}
:enddata
:endrule

rule:
plugin=vanillaBlocks
number=42
data:
JSON:{{"val":{"blockName":{"val":"minecraft:planks","id":"ss"},"meta":{"val":"0","id":"pi"},"buildPass":{"val":"0","id":"pi"}},"id":"ct"}}
:enddata
:endrule

rule:
plugin=vanillaInventory
number=43
data:
JSON:{{"val":{"lootLevel":{"val":"0","id":"pi"},"inventoryData":{"val":{"length":{"val":"27","id":"pi"},"inventoryContents":{"val":[],"id":"ls"}},"id":"ct"},"teData":{"val":{"id":{"val":"Chest","id":"ss"},"z":{"val":"746","id":"pi"},"y":{"val":"92","id":"pi"},"x":{"val":"1128","id":"pi"}},"id":"ct"},"blockName":{"val":"minecraft:chest","id":"ss"},"meta":{"val":"3","id":"pi"},"buildPass":{"val":"0","id":"pi"}},"id":"ct"}}
:enddata
:endrule

rule:
plugin=vanillaBlocks
number=44
data:
JSON:{{"val":{"blockName":{"val":"minecraft:torch","id":"ss"},"meta":{"val":"5","id":"pi"},"buildPass":{"val":"2","id":"pi"}},"id":"ct"}}
:enddata
:endrule

rule:
plugin=vanillaDoors
number=45
data:
JSON:{{"val":{"sideFlag":{"val":"0","id":"pb"},"blockName":{"val":"minecraft:wooden_door","id":"ss"},"meta":{"val":"8","id":"pi"},"buildPass":{"val":"2","id":"pi"}},"id":"ct"}}
:enddata
:endrule

rule:
plugin=vanillaDoors
number=46
data:
JSON:{{"val":{"sideFlag":{"val":"8","id":"pb"},"blockName":{"val":"minecraft:wooden_door","id":"ss"},"meta":{"val":"5","id":"pi"},"buildPass":{"val":"2","id":"pi"}},"id":"ct"}}
:enddata
:endrule

rule:
plugin=vanillaBlocks
number=47
data:
JSON:{{"val":{"blockName":{"val":"minecraft:planks","id":"ss"},"meta":{"val":"3","id":"pi"},"buildPass":{"val":"0","id":"pi"}},"id":"ct"}}
:enddata
:endrule

rule:
plugin=vanillaDoors
number=48
data:
JSON:{{"val":{"sideFlag":{"val":"0","id":"pb"},"blockName":{"val":"minecraft:wooden_door","id":"ss"},"meta":{"val":"8","id":"pi"},"buildPass":{"val":"2","id":"pi"}},"id":"ct"}}
:enddata
:endrule

rule:
plugin=vanillaDoors
number=49
data:
JSON:{{"val":{"sideFlag":{"val":"0","id":"pb"},"blockName":{"val":"minecraft:wooden_door","id":"ss"},"meta":{"val":"8","id":"pi"},"buildPass":{"val":"2","id":"pi"}},"id":"ct"}}
:enddata
:endrule

rule:
plugin=vanillaBlocks
number=50
data:
JSON:{{"val":{"blockName":{"val":"minecraft:log","id":"ss"},"meta":{"val":"0","id":"pi"},"buildPass":{"val":"0","id":"pi"}},"id":"ct"}}
:enddata
:endrule

rule:
plugin=vanillaBlocks
number=51
data:
JSON:{{"val":{"blockName":{"val":"minecraft:wooden_pressure_plate","id":"ss"},"meta":{"val":"0","id":"pi"},"buildPass":{"val":"2","id":"pi"}},"id":"ct"}}
:enddata
:endrule

rule:
plugin=vanillaDoors
number=52
data:
JSON:{{"val":{"sideFlag":{"val":"0","id":"pb"},"blockName":{"val":"minecraft:wooden_door","id":"ss"},"meta":{"val":"8","id":"pi"},"buildPass":{"val":"2","id":"pi"}},"id":"ct"}}
:enddata
:endrule

rule:
plugin=vanillaBlocks
number=53
data:
JSON:{{"val":{"blockName":{"val":"minecraft:oak_stairs","id":"ss"},"meta":{"val":"2","id":"pi"},"buildPass":{"val":"0","id":"pi"}},"id":"ct"}}
:enddata
:endrule

rule:
plugin=vanillaBlocks
number=54
data:
JSON:{{"val":{"blockName":{"val":"minecraft:oak_stairs","id":"ss"},"meta":{"val":"7","id":"pi"},"buildPass":{"val":"0","id":"pi"}},"id":"ct"}}
:enddata
:endrule

rule:
plugin=vanillaBlocks
number=55
data:
JSON:{{"val":{"blockName":{"val":"minecraft:oak_stairs","id":"ss"},"meta":{"val":"4","id":"pi"},"buildPass":{"val":"0","id":"pi"}},"id":"ct"}}
:enddata
:endrule

rule:
plugin=vanillaBlocks
number=56
data:
JSON:{{"val":{"blockName":{"val":"minecraft:oak_stairs","id":"ss"},"meta":{"val":"5","id":"pi"},"buildPass":{"val":"0","id":"pi"}},"id":"ct"}}
:enddata
:endrule

rule:
plugin=vanillaDoors
number=57
data:
JSON:{{"val":{"sideFlag":{"val":"8","id":"pb"},"blockName":{"val":"minecraft:wooden_door","id":"ss"},"meta":{"val":"0","id":"pi"},"buildPass":{"val":"2","id":"pi"}},"id":"ct"}}
:enddata
:endrule

rule:
plugin=vanillaInventory
number=58
data:
JSON:{{"val":{"lootLevel":{"val":"0","id":"pi"},"inventoryData":{"val":{"length":{"val":"27","id":"pi"},"inventoryContents":{"val":[],"id":"ls"}},"id":"ct"},"teData":{"val":{"id":{"val":"Chest","id":"ss"},"z":{"val":"741","id":"pi"},"y":{"val":"97","id":"pi"},"x":{"val":"1122","id":"pi"}},"id":"ct"},"blockName":{"val":"minecraft:chest","id":"ss"},"meta":{"val":"2","id":"pi"},"buildPass":{"val":"0","id":"pi"}},"id":"ct"}}
:enddata
:endrule

rule:
plugin=vanillaInventory
number=59
data:
JSON:{{"val":{"lootLevel":{"val":"0","id":"pi"},"inventoryData":{"val":{"length":{"val":"27","id":"pi"},"inventoryContents":{"val":[],"id":"ls"}},"id":"ct"},"teData":{"val":{"id":{"val":"Chest","id":"ss"},"z":{"val":"742","id":"pi"},"y":{"val":"97","id":"pi"},"x":{"val":"1122","id":"pi"}},"id":"ct"},"blockName":{"val":"minecraft:chest","id":"ss"},"meta":{"val":"2","id":"pi"},"buildPass":{"val":"0","id":"pi"}},"id":"ct"}}
:enddata
:endrule

rule:
plugin=vanillaInventory
number=60
data:
JSON:{{"val":{"lootLevel":{"val":"0","id":"pi"},"inventoryData":{"val":{"length":{"val":"27","id":"pi"},"inventoryContents":{"val":[],"id":"ls"}},"id":"ct"},"teData":{"val":{"id":{"val":"Chest","id":"ss"},"z":{"val":"743","id":"pi"},"y":{"val":"97","id":"pi"},"x":{"val":"1128","id":"pi"}},"id":"ct"},"blockName":{"val":"minecraft:chest","id":"ss"},"meta":{"val":"3","id":"pi"},"buildPass":{"val":"0","id":"pi"}},"id":"ct"}}
:enddata
:endrule

rule:
plugin=vanillaDoors
number=61
data:
JSON:{{"val":{"sideFlag":{"val":"0","id":"pb"},"blockName":{"val":"minecraft:wooden_door","id":"ss"},"meta":{"val":"8","id":"pi"},"buildPass":{"val":"2","id":"pi"}},"id":"ct"}}
:enddata
:endrule

rule:
plugin=vanillaDoors
number=62
data:
JSON:{{"val":{"sideFlag":{"val":"0","id":"pb"},"blockName":{"val":"minecraft:wooden_door","id":"ss"},"meta":{"val":"8","id":"pi"},"buildPass":{"val":"2","id":"pi"}},"id":"ct"}}
:enddata
:endrule

rule:
plugin=vanillaBlocks
number=63
data:
JSON:{{"val":{"blockName":{"val":"minecraft:oak_stairs","id":"ss"},"meta":{"val":"6","id":"pi"},"buildPass":{"val":"0","id":"pi"}},"id":"ct"}}
:enddata
:endrule

#### ENTITIES ####
