# Ancient Warfare Structure Template File
# Auto-generated structure template file. created on: 11/24/2014 at: 21:45:39
# Lines beginning with # denote comments

header:
version=2.1
name=TownBlocks1HousesB
size=15,18,11
offset=9,3,10
:endheader

#### VALIDATION ####
validation:
type=ground
survival=false
worldGenEnabled=false
unique=false
preserveBlocks=false
selectionWeight=0
clusterValue=0
minDuplicateDistance=0
dimensionWhiteList=false
dimensionList=
biomeWhiteList=false
biomeList=
leveling=0
fill=0
border=0
validTargetBlocks=
blockSwap=false
data:
:enddata
:endvalidation

#### LAYERS ####
layer: 0
1,1,1,1,1,1,1,1,1,1,1,1,1,1,1
1,1,1,1,1,1,1,1,1,1,1,1,1,1,1
1,1,1,1,1,1,1,1,1,1,1,1,1,1,1
2,1,1,1,1,1,1,1,1,1,1,1,1,1,1
1,1,1,1,1,1,1,1,1,1,1,1,1,1,1
1,1,1,1,1,1,1,1,1,1,1,1,1,1,1
1,1,1,1,1,1,1,1,1,1,1,1,1,1,1
1,1,1,1,1,1,1,1,1,1,1,1,1,1,1
1,1,1,1,1,1,1,1,1,1,1,1,1,1,1
1,1,1,1,1,1,1,1,1,1,1,1,1,1,1
1,1,1,1,1,1,1,1,1,1,1,1,1,1,1
:endlayer
layer: 1
1,1,1,1,1,1,1,1,1,1,1,1,1,1,1
1,1,1,1,1,1,1,1,1,1,1,1,1,1,1
1,1,1,1,1,1,1,1,3,3,3,3,3,3,1
2,1,1,1,1,1,1,1,3,3,3,3,3,3,1
1,1,1,1,1,1,1,1,3,3,3,3,3,3,1
1,1,1,1,1,1,1,1,3,3,3,3,3,3,1
1,1,1,1,1,1,1,1,3,3,3,3,3,3,1
1,1,1,1,1,1,1,1,3,3,3,3,3,3,1
1,1,1,1,1,1,1,1,3,3,3,3,3,3,1
1,1,1,1,1,1,1,1,1,1,1,1,1,1,1
1,1,1,1,1,1,1,1,1,1,1,1,1,1,1
:endlayer
layer: 2
3,3,3,3,3,3,3,3,3,3,3,3,3,3,3
3,3,3,3,3,3,3,3,3,3,3,3,3,3,3
3,1,1,1,1,1,1,1,3,3,3,3,3,3,1
3,1,1,1,1,1,1,1,3,3,3,3,3,3,1
3,1,1,1,1,1,1,1,3,3,3,3,3,3,1
3,1,1,1,1,1,1,1,3,3,3,3,3,3,1
3,1,1,1,1,1,1,1,3,3,3,3,3,3,1
3,1,1,1,1,1,1,1,3,3,3,3,3,3,1
3,1,1,1,1,1,1,1,3,3,3,3,3,3,1
3,3,3,3,3,3,3,3,3,3,3,3,3,1,1
3,3,3,3,3,3,3,3,3,3,3,3,3,3,3
:endlayer
layer: 3
4,4,4,4,4,4,4,4,4,4,4,4,4,4,4
4,4,3,3,3,3,3,3,4,4,4,4,4,4,4
4,4,1,1,1,1,1,1,3,3,3,3,3,3,4
4,4,1,1,1,1,1,1,3,3,3,3,3,3,4
4,4,1,1,1,1,1,1,3,3,3,3,3,3,4
4,4,3,3,3,3,3,3,3,3,3,3,3,3,4
4,4,3,3,3,3,3,3,3,3,3,3,3,3,4
4,4,3,3,3,3,3,3,3,3,3,3,3,3,4
4,4,3,3,3,3,3,3,3,3,3,3,3,3,4
4,4,3,3,3,3,3,3,4,4,4,4,4,4,4
4,4,4,4,4,4,4,4,4,4,4,4,4,4,4
:endlayer
layer: 4
0,0,0,0,0,0,0,0,0,0,0,0,0,0,0
0,0,6,6,6,6,6,6,0,0,0,0,0,0,0
0,5,6,6,6,6,6,6,6,6,9,6,6,6,0
0,5,6,6,6,6,6,7,0,0,0,0,0,6,0
0,0,6,6,6,6,6,7,0,0,0,0,0,6,0
0,0,6,6,6,6,6,7,0,0,0,0,0,6,0
0,0,6,6,6,6,6,7,0,0,0,0,0,6,0
0,0,6,6,6,6,6,7,0,0,0,0,0,6,0
0,0,6,6,6,6,6,6,6,6,8,6,6,6,0
0,0,6,6,6,6,6,6,0,0,0,0,0,0,0
0,0,0,0,0,0,0,0,0,0,0,0,0,0,0
:endlayer
layer: 5
0,0,0,0,0,0,0,0,0,0,0,0,0,0,0
0,0,6,6,6,6,6,6,0,0,0,0,0,0,0
0,0,11,0,0,0,0,6,6,6,17,6,6,6,0
0,0,10,0,0,0,0,0,0,0,0,0,0,6,0
0,0,6,0,0,0,0,0,0,0,0,0,0,6,0
0,0,6,0,0,0,0,0,0,0,0,0,0,18,0
0,0,6,0,0,0,0,0,0,0,0,0,0,6,0
0,0,6,0,0,14,0,0,0,0,0,0,0,6,0
0,0,6,12,0,13,15,6,6,6,16,6,6,6,0
0,0,6,6,6,6,6,6,0,0,0,0,0,0,0
0,0,0,0,0,0,0,0,0,0,0,0,0,0,0
:endlayer
layer: 6
0,0,23,0,0,0,0,23,0,0,0,0,0,0,0
0,19,6,15,18,18,15,6,25,0,23,0,0,0,0
0,0,22,0,0,0,0,15,6,6,6,6,6,6,0
0,0,21,0,0,0,0,0,0,20,0,0,0,6,0
0,0,15,0,0,0,0,0,0,0,0,0,0,6,0
0,0,18,0,0,0,0,0,0,0,0,0,0,18,0
0,0,18,0,0,0,0,0,0,0,0,0,0,6,0
0,0,18,0,0,24,0,0,0,23,0,0,0,6,0
0,0,15,0,0,0,0,15,6,6,6,6,6,6,0
0,19,6,15,18,18,15,6,25,0,20,0,0,0,0
0,0,20,0,0,0,0,20,0,0,0,0,0,0,0
:endlayer
layer: 7
0,0,0,0,0,0,0,0,0,0,0,0,0,0,0
0,0,6,15,18,18,15,6,0,0,0,0,0,23,0
0,19,15,0,0,0,26,15,6,6,6,6,6,6,25
0,19,15,0,0,0,0,0,0,0,0,0,0,6,0
0,0,15,25,0,0,0,0,0,0,0,0,0,6,0
0,0,18,0,0,0,0,0,0,0,0,0,0,18,0
0,0,18,0,0,0,0,0,0,0,0,0,0,6,0
0,0,18,0,0,0,0,0,0,0,0,0,0,6,0
0,0,15,0,0,0,26,15,6,6,6,6,6,6,25
0,0,6,15,18,18,15,6,0,0,0,0,0,20,0
0,0,0,0,0,0,0,0,0,0,0,0,0,0,0
:endlayer
layer: 8
0,0,0,0,0,0,0,0,0,0,0,0,0,0,0
0,0,6,15,15,15,15,6,0,0,0,0,0,0,0
0,0,15,15,20,0,15,15,6,6,6,6,6,6,0
0,0,15,15,0,0,15,15,0,0,0,0,0,6,0
0,0,15,15,0,0,15,15,0,0,0,0,0,6,0
0,0,15,15,0,0,15,15,0,0,0,0,0,6,0
0,0,15,15,0,0,15,15,0,0,0,0,0,6,0
0,0,15,15,0,0,15,15,0,0,0,0,0,6,0
0,0,15,15,23,0,15,15,6,6,6,6,6,6,0
0,0,6,15,15,15,15,6,0,0,0,0,0,0,0
0,0,0,0,0,0,0,0,0,0,0,0,0,0,0
:endlayer
layer: 9
0,27,0,0,0,0,0,0,28,0,0,0,0,0,0
0,27,6,6,6,6,6,6,28,0,0,0,0,0,0
0,27,6,6,6,6,6,6,6,6,6,6,6,6,0
0,27,6,6,6,6,6,6,0,0,0,0,0,6,0
0,27,6,6,6,6,6,6,0,0,0,0,0,6,0
0,27,6,6,6,6,6,6,0,0,0,0,0,6,0
0,27,6,6,6,6,6,6,0,0,0,0,0,6,0
0,27,6,6,6,6,6,6,0,0,0,0,0,6,0
0,27,6,6,6,6,6,6,6,6,6,6,6,6,0
0,27,6,6,6,6,6,6,28,0,0,0,0,0,0
0,27,0,0,0,0,0,0,28,0,0,0,0,0,0
:endlayer
layer: 10
0,0,27,0,0,0,0,28,0,0,0,0,0,0,0
0,0,27,6,6,6,6,28,0,0,0,0,0,0,28
0,0,27,6,6,6,6,15,6,6,6,6,6,6,28
0,0,27,6,6,6,6,15,0,0,0,0,0,15,28
0,0,27,6,6,6,6,15,0,0,0,0,0,15,28
0,0,27,6,6,6,6,15,0,0,0,0,0,15,28
0,0,27,6,6,6,6,15,0,0,0,0,0,15,28
0,0,27,6,6,6,6,15,0,0,0,0,0,15,28
0,0,27,6,6,6,6,15,6,6,6,6,6,6,28
0,0,27,6,6,6,6,28,0,0,0,0,0,0,28
0,0,27,0,0,0,0,28,0,0,0,0,0,0,0
:endlayer
layer: 11
0,0,0,27,23,23,28,0,0,0,0,0,0,0,0
0,0,0,27,6,6,28,0,27,0,0,0,0,28,0
0,0,0,27,6,6,28,29,27,6,6,6,6,28,0
0,0,0,27,6,6,28,0,27,15,0,0,15,28,0
0,0,0,27,6,6,28,0,27,15,0,0,15,28,0
0,0,0,27,6,6,28,0,27,15,0,0,15,28,0
0,0,0,27,6,6,28,0,27,15,0,0,15,28,0
0,0,0,27,6,6,28,0,27,15,0,0,15,28,0
0,0,0,27,6,6,28,29,27,6,6,6,6,28,0
0,0,0,27,6,6,28,0,27,0,0,0,0,28,0
0,0,0,27,0,0,28,0,0,0,0,0,0,0,0
:endlayer
layer: 12
0,0,0,0,27,28,0,0,0,0,0,0,0,0,0
0,0,0,0,27,28,0,0,0,27,23,23,28,0,0
0,0,0,0,27,28,0,0,0,27,6,6,28,0,0
0,0,0,0,27,28,0,0,0,27,15,15,28,0,0
0,0,0,0,27,28,0,0,0,27,15,15,28,0,0
0,0,0,0,27,28,0,0,0,27,15,15,28,0,0
0,0,0,0,27,28,0,0,0,27,15,15,28,0,0
0,0,0,0,27,28,0,0,0,27,15,15,28,0,0
0,0,0,0,27,28,0,0,0,27,6,6,28,0,0
0,0,0,0,27,28,0,0,0,27,0,0,28,0,0
0,0,0,0,27,28,0,0,0,0,0,0,0,0,0
:endlayer
layer: 13
0,0,0,0,0,0,0,0,0,0,0,0,0,0,0
0,0,0,0,0,0,0,0,0,0,27,28,0,0,0
0,0,0,0,0,0,0,0,0,0,27,28,0,0,0
0,0,0,0,0,0,0,0,0,0,27,28,0,0,0
0,0,0,0,0,0,0,0,0,0,27,28,0,0,0
0,0,0,0,0,0,0,0,0,0,27,28,0,0,0
0,0,0,0,0,0,0,0,0,0,27,28,0,0,0
0,0,0,0,0,0,0,0,0,0,27,28,0,0,0
0,0,0,0,0,0,0,0,0,0,27,28,0,0,0
0,0,0,0,0,0,0,0,0,0,27,28,0,0,0
0,0,0,0,0,0,0,0,0,0,0,0,0,0,0
:endlayer
layer: 14
0,0,0,0,0,0,0,0,0,0,0,0,0,0,0
0,0,0,0,0,0,0,0,0,0,0,0,0,0,0
0,0,0,0,0,0,0,0,0,0,0,0,0,0,0
0,0,0,0,0,0,0,0,0,0,0,0,0,0,0
0,0,0,0,0,0,0,0,0,0,0,0,0,0,0
0,0,0,0,0,0,0,0,0,0,0,0,0,0,0
0,0,0,0,0,0,0,0,0,0,0,0,0,0,0
0,0,0,0,0,0,0,0,0,0,0,0,0,0,0
0,0,0,0,0,0,0,0,0,0,0,0,0,0,0
0,0,0,0,0,0,0,0,0,0,0,0,0,0,0
0,0,0,0,0,0,0,0,0,0,0,0,0,0,0
:endlayer
layer: 15
0,0,0,0,0,0,0,0,0,0,0,0,0,0,0
0,0,0,0,0,0,0,0,0,0,0,0,0,0,0
0,0,0,0,0,0,0,0,0,0,0,0,0,0,0
0,0,0,0,0,0,0,0,0,0,0,0,0,0,0
0,0,0,0,0,0,0,0,0,0,0,0,0,0,0
0,0,0,0,0,0,0,0,0,0,0,0,0,0,0
0,0,0,0,0,0,0,0,0,0,0,0,0,0,0
0,0,0,0,0,0,0,0,0,0,0,0,0,0,0
0,0,0,0,0,0,0,0,0,0,0,0,0,0,0
0,0,0,0,0,0,0,0,0,0,0,0,0,0,0
0,0,0,0,0,0,0,0,0,0,0,0,0,0,0
:endlayer
layer: 16
0,0,0,0,0,0,0,0,0,0,0,0,0,0,0
0,0,0,0,0,0,0,0,0,0,0,0,0,0,0
0,0,0,0,0,0,0,0,0,0,0,0,0,0,0
0,0,0,0,0,0,0,0,0,0,0,0,0,0,0
0,0,0,0,0,0,0,0,0,0,0,0,0,0,0
0,0,0,0,0,0,0,0,0,0,0,0,0,0,0
0,0,0,0,0,0,0,0,0,0,0,0,0,0,0
0,0,0,0,0,0,0,0,0,0,0,0,0,0,0
0,0,0,0,0,0,0,0,0,0,0,0,0,0,0
0,0,0,0,0,0,0,0,0,0,0,0,0,0,0
0,0,0,0,0,0,0,0,0,0,0,0,0,0,0
:endlayer
layer: 17
0,0,0,0,0,0,0,0,0,0,0,0,0,0,0
0,0,0,0,0,0,0,0,0,0,0,0,0,0,0
0,0,0,0,0,0,0,0,0,0,0,0,0,0,0
0,0,0,0,0,0,0,0,0,0,0,0,0,0,0
0,0,0,0,0,0,0,0,0,0,0,0,0,0,0
0,0,0,0,0,0,0,0,0,0,0,0,0,0,0
0,0,0,0,0,0,0,0,0,0,0,0,0,0,0
0,0,0,0,0,0,0,0,0,0,0,0,0,0,0
0,0,0,0,0,0,0,0,0,0,0,0,0,0,0
0,0,0,0,0,0,0,0,0,0,0,0,0,0,0
0,0,0,0,0,0,0,0,0,0,0,0,0,0,0
:endlayer

#### RULES ####
rule:
plugin=vanillaBlocks
number=1
data:
JSON:{{"val":{"blockName":{"val":"minecraft:dirt","id":"ss"},"meta":{"val":"0","id":"pi"},"buildPass":{"val":"0","id":"pi"}},"id":"ct"}}
:enddata
:endrule

rule:
plugin=vanillaBlocks
number=2
data:
JSON:{{"val":{"blockName":{"val":"minecraft:stone","id":"ss"},"meta":{"val":"0","id":"pi"},"buildPass":{"val":"0","id":"pi"}},"id":"ct"}}
:enddata
:endrule

rule:
plugin=vanillaBlocks
number=3
data:
JSON:{{"val":{"blockName":{"val":"minecraft:cobblestone","id":"ss"},"meta":{"val":"0","id":"pi"},"buildPass":{"val":"0","id":"pi"}},"id":"ct"}}
:enddata
:endrule

rule:
plugin=vanillaBlocks
number=4
data:
JSON:{{"val":{"blockName":{"val":"minecraft:gravel","id":"ss"},"meta":{"val":"0","id":"pi"},"buildPass":{"val":"0","id":"pi"}},"id":"ct"}}
:enddata
:endrule

rule:
plugin=vanillaBlocks
number=5
data:
JSON:{{"val":{"blockName":{"val":"minecraft:stone_brick_stairs","id":"ss"},"meta":{"val":"0","id":"pi"},"buildPass":{"val":"0","id":"pi"}},"id":"ct"}}
:enddata
:endrule

rule:
plugin=vanillaBlocks
number=6
data:
JSON:{{"val":{"blockName":{"val":"minecraft:stonebrick","id":"ss"},"meta":{"val":"0","id":"pi"},"buildPass":{"val":"0","id":"pi"}},"id":"ct"}}
:enddata
:endrule

rule:
plugin=vanillaBlocks
number=7
data:
JSON:{{"val":{"blockName":{"val":"minecraft:stone_brick_stairs","id":"ss"},"meta":{"val":"1","id":"pi"},"buildPass":{"val":"0","id":"pi"}},"id":"ct"}}
:enddata
:endrule

rule:
plugin=vanillaDoors
number=8
data:
JSON:{{"val":{"sideFlag":{"val":"8","id":"pb"},"blockName":{"val":"minecraft:wooden_door","id":"ss"},"meta":{"val":"3","id":"pi"},"buildPass":{"val":"2","id":"pi"}},"id":"ct"}}
:enddata
:endrule

rule:
plugin=vanillaDoors
number=9
data:
JSON:{{"val":{"sideFlag":{"val":"8","id":"pb"},"blockName":{"val":"minecraft:wooden_door","id":"ss"},"meta":{"val":"1","id":"pi"},"buildPass":{"val":"2","id":"pi"}},"id":"ct"}}
:enddata
:endrule

rule:
plugin=vanillaDoors
number=10
data:
JSON:{{"val":{"sideFlag":{"val":"9","id":"pb"},"blockName":{"val":"minecraft:wooden_door","id":"ss"},"meta":{"val":"0","id":"pi"},"buildPass":{"val":"2","id":"pi"}},"id":"ct"}}
:enddata
:endrule

rule:
plugin=vanillaDoors
number=11
data:
JSON:{{"val":{"sideFlag":{"val":"8","id":"pb"},"blockName":{"val":"minecraft:wooden_door","id":"ss"},"meta":{"val":"0","id":"pi"},"buildPass":{"val":"2","id":"pi"}},"id":"ct"}}
:enddata
:endrule

rule:
plugin=vanillaBlocks
number=12
data:
JSON:{{"val":{"blockName":{"val":"minecraft:crafting_table","id":"ss"},"meta":{"val":"0","id":"pi"},"buildPass":{"val":"0","id":"pi"}},"id":"ct"}}
:enddata
:endrule

rule:
plugin=vanillaBlocks
number=13
data:
JSON:{{"val":{"blockName":{"val":"minecraft:oak_stairs","id":"ss"},"meta":{"val":"2","id":"pi"},"buildPass":{"val":"0","id":"pi"}},"id":"ct"}}
:enddata
:endrule

rule:
plugin=vanillaBlocks
number=14
data:
JSON:{{"val":{"blockName":{"val":"minecraft:fence","id":"ss"},"meta":{"val":"0","id":"pi"},"buildPass":{"val":"0","id":"pi"}},"id":"ct"}}
:enddata
:endrule

rule:
plugin=vanillaBlocks
number=15
data:
JSON:{{"val":{"blockName":{"val":"minecraft:planks","id":"ss"},"meta":{"val":"0","id":"pi"},"buildPass":{"val":"0","id":"pi"}},"id":"ct"}}
:enddata
:endrule

rule:
plugin=vanillaDoors
number=16
data:
JSON:{{"val":{"sideFlag":{"val":"0","id":"pb"},"blockName":{"val":"minecraft:wooden_door","id":"ss"},"meta":{"val":"8","id":"pi"},"buildPass":{"val":"2","id":"pi"}},"id":"ct"}}
:enddata
:endrule

rule:
plugin=vanillaDoors
number=17
data:
JSON:{{"val":{"sideFlag":{"val":"0","id":"pb"},"blockName":{"val":"minecraft:wooden_door","id":"ss"},"meta":{"val":"8","id":"pi"},"buildPass":{"val":"2","id":"pi"}},"id":"ct"}}
:enddata
:endrule

rule:
plugin=vanillaBlocks
number=18
data:
JSON:{{"val":{"blockName":{"val":"minecraft:glass_pane","id":"ss"},"meta":{"val":"0","id":"pi"},"buildPass":{"val":"0","id":"pi"}},"id":"ct"}}
:enddata
:endrule

rule:
plugin=vanillaBlocks
number=19
data:
JSON:{{"val":{"blockName":{"val":"minecraft:torch","id":"ss"},"meta":{"val":"2","id":"pi"},"buildPass":{"val":"2","id":"pi"}},"id":"ct"}}
:enddata
:endrule

rule:
plugin=vanillaBlocks
number=20
data:
JSON:{{"val":{"blockName":{"val":"minecraft:torch","id":"ss"},"meta":{"val":"3","id":"pi"},"buildPass":{"val":"2","id":"pi"}},"id":"ct"}}
:enddata
:endrule

rule:
plugin=vanillaDoors
number=21
data:
JSON:{{"val":{"sideFlag":{"val":"0","id":"pb"},"blockName":{"val":"minecraft:wooden_door","id":"ss"},"meta":{"val":"9","id":"pi"},"buildPass":{"val":"2","id":"pi"}},"id":"ct"}}
:enddata
:endrule

rule:
plugin=vanillaDoors
number=22
data:
JSON:{{"val":{"sideFlag":{"val":"0","id":"pb"},"blockName":{"val":"minecraft:wooden_door","id":"ss"},"meta":{"val":"8","id":"pi"},"buildPass":{"val":"2","id":"pi"}},"id":"ct"}}
:enddata
:endrule

rule:
plugin=vanillaBlocks
number=23
data:
JSON:{{"val":{"blockName":{"val":"minecraft:torch","id":"ss"},"meta":{"val":"4","id":"pi"},"buildPass":{"val":"2","id":"pi"}},"id":"ct"}}
:enddata
:endrule

rule:
plugin=vanillaBlocks
number=24
data:
JSON:{{"val":{"blockName":{"val":"minecraft:wooden_pressure_plate","id":"ss"},"meta":{"val":"0","id":"pi"},"buildPass":{"val":"2","id":"pi"}},"id":"ct"}}
:enddata
:endrule

rule:
plugin=vanillaBlocks
number=25
data:
JSON:{{"val":{"blockName":{"val":"minecraft:torch","id":"ss"},"meta":{"val":"1","id":"pi"},"buildPass":{"val":"2","id":"pi"}},"id":"ct"}}
:enddata
:endrule

rule:
plugin=vanillaBlocks
number=26
data:
JSON:{{"val":{"blockName":{"val":"minecraft:bookshelf","id":"ss"},"meta":{"val":"0","id":"pi"},"buildPass":{"val":"0","id":"pi"}},"id":"ct"}}
:enddata
:endrule

rule:
plugin=vanillaBlocks
number=27
data:
JSON:{{"val":{"blockName":{"val":"minecraft:oak_stairs","id":"ss"},"meta":{"val":"0","id":"pi"},"buildPass":{"val":"0","id":"pi"}},"id":"ct"}}
:enddata
:endrule

rule:
plugin=vanillaBlocks
number=28
data:
JSON:{{"val":{"blockName":{"val":"minecraft:oak_stairs","id":"ss"},"meta":{"val":"1","id":"pi"},"buildPass":{"val":"0","id":"pi"}},"id":"ct"}}
:enddata
:endrule

rule:
plugin=vanillaBlocks
number=29
data:
JSON:{{"val":{"blockName":{"val":"minecraft:torch","id":"ss"},"meta":{"val":"5","id":"pi"},"buildPass":{"val":"2","id":"pi"}},"id":"ct"}}
:enddata
:endrule

#### ENTITIES ####
