# Ancient Warfare Structure Template File
# Auto-generated structure template file. created on: 11/25/2014 at: 20:11:41
# Lines beginning with # denote comments

header:
version=2.1
name=TownBlocksTownHall
size=23,33,21
offset=11,3,20
:endheader

#### VALIDATION ####
validation:
type=ground
survival=false
worldGenEnabled=false
unique=false
preserveBlocks=false
selectionWeight=0
clusterValue=0
minDuplicateDistance=0
dimensionWhiteList=false
dimensionList=
biomeWhiteList=false
biomeList=
leveling=0
fill=0
border=0
validTargetBlocks=
blockSwap=false
data:
:enddata
:endvalidation

#### LAYERS ####
layer: 0
1,1,1,1,1,1,1,1,1,1,1,1,1,1,1,1,1,1,1,1,1,1,1
1,1,1,1,1,1,1,1,1,1,1,1,1,1,1,1,1,1,1,1,1,1,1
1,1,1,1,1,1,1,1,1,1,1,1,1,1,1,1,1,1,1,1,1,1,1
1,1,1,1,1,1,1,1,1,1,1,1,1,1,1,1,1,1,1,1,1,1,1
1,1,1,1,1,1,1,1,1,1,1,1,1,1,1,1,1,1,1,1,1,1,1
1,1,1,1,1,1,1,1,1,1,1,1,1,1,1,1,1,1,1,1,1,1,1
1,1,1,1,1,1,1,1,1,1,1,1,1,1,1,1,1,1,1,1,1,1,1
1,1,1,1,1,1,1,1,1,1,1,1,1,1,1,1,1,1,1,1,1,1,1
1,1,1,1,1,1,1,1,1,1,1,1,1,1,1,1,1,1,1,1,1,1,1
1,1,1,1,1,1,1,1,1,1,1,1,1,1,1,1,1,1,1,1,1,1,1
1,1,1,1,1,1,1,1,1,1,1,1,1,1,1,1,1,1,1,1,1,1,1
1,1,1,1,1,1,1,1,1,1,1,1,1,1,1,1,1,1,1,1,1,1,1
1,1,1,1,1,1,1,1,1,1,1,1,1,1,1,1,1,1,1,1,1,1,1
1,1,1,1,1,1,1,1,1,1,1,1,1,1,1,1,1,1,1,1,1,1,1
1,1,1,1,1,1,1,1,1,1,1,1,1,1,1,1,1,1,1,1,1,1,1
1,1,1,1,1,1,1,1,1,1,1,1,1,1,1,1,1,1,1,1,1,1,1
1,1,1,1,1,1,1,1,1,1,1,1,1,1,1,1,1,1,1,1,1,1,1
1,1,1,1,1,1,1,1,1,1,1,1,1,1,1,1,1,1,1,1,1,1,1
1,1,1,1,1,1,1,1,1,1,1,1,1,1,1,1,1,1,1,1,1,1,1
1,1,1,1,1,1,1,1,1,1,1,1,1,1,1,1,1,1,1,1,1,1,1
1,1,1,1,1,1,1,1,1,1,1,1,1,1,1,1,1,1,1,1,1,1,1
:endlayer
layer: 1
1,1,1,1,1,1,1,1,1,1,1,1,1,1,1,1,1,1,1,1,1,1,1
1,1,1,1,1,1,1,1,1,1,1,1,1,1,1,1,1,1,1,1,1,1,1
1,1,1,1,1,1,1,1,1,1,1,1,1,1,1,1,1,1,1,1,1,1,1
1,1,1,1,1,1,1,1,1,1,1,1,1,1,1,1,1,1,1,1,1,1,1
1,1,1,1,1,1,1,1,1,1,1,1,1,1,1,1,1,1,1,1,1,1,1
1,1,1,1,1,1,1,1,1,1,1,1,1,1,1,1,1,1,1,1,1,1,1
1,1,1,1,1,1,1,1,1,1,1,1,1,1,1,1,1,1,1,1,1,1,1
1,1,1,1,1,1,1,1,1,1,1,1,1,1,1,1,1,1,1,1,1,1,1
1,1,1,1,1,1,1,1,1,1,1,1,1,1,1,1,1,1,1,1,1,1,1
1,1,1,1,1,1,1,1,1,1,1,1,1,1,1,1,1,1,1,1,1,1,1
1,1,1,1,1,1,1,1,1,1,1,1,1,1,1,1,1,1,1,1,1,1,1
1,1,1,1,1,1,1,1,1,1,1,1,1,1,1,1,1,1,1,1,1,1,1
1,1,1,1,1,1,1,1,1,1,1,1,1,1,1,1,1,1,1,1,1,1,1
1,1,1,1,1,1,1,1,1,1,1,1,1,1,1,1,1,1,1,1,1,1,1
1,1,1,1,1,1,1,1,1,1,1,1,1,1,1,1,1,1,1,1,1,1,1
1,1,1,1,1,1,1,1,1,1,1,1,1,1,1,1,1,1,1,1,1,1,1
1,1,1,1,1,1,1,1,1,1,1,1,1,1,1,1,1,1,1,1,1,1,1
1,1,1,1,1,1,1,1,1,1,1,1,1,1,1,1,1,1,1,1,1,1,1
1,1,1,1,1,1,1,1,1,1,1,1,1,1,1,1,1,1,1,1,1,1,1
1,1,1,1,1,1,1,1,1,1,1,1,1,1,1,1,1,1,1,1,1,1,1
1,1,1,1,1,1,1,1,1,1,1,1,1,1,1,1,1,1,1,1,1,1,1
:endlayer
layer: 2
1,1,1,1,1,1,1,1,1,1,1,1,1,1,1,1,1,1,1,1,1,1,1
1,1,1,1,1,1,1,1,1,1,1,1,1,1,1,1,1,1,1,1,1,1,1
1,1,1,1,1,1,1,1,1,1,1,1,1,1,1,1,1,1,1,1,1,1,1
1,1,1,1,1,1,1,1,1,1,1,1,1,1,1,1,1,1,1,1,1,1,1
1,1,1,1,1,1,1,1,1,1,1,1,1,1,1,1,1,1,1,1,1,1,1
1,1,1,1,1,1,1,1,1,1,1,1,1,1,1,1,1,1,1,1,1,1,1
1,1,1,1,1,1,1,1,1,1,1,1,1,1,1,1,1,1,1,1,1,1,1
1,1,1,1,1,1,1,1,1,1,1,1,1,1,1,1,1,1,1,1,1,1,1
1,1,1,1,1,1,1,1,1,1,1,1,1,1,1,1,1,1,1,1,1,1,1
1,1,1,1,1,1,1,1,1,1,1,1,1,1,1,1,1,1,1,1,1,1,1
1,1,1,1,1,1,1,1,1,1,1,1,1,1,1,1,1,1,1,1,1,1,1
1,1,1,1,1,1,1,1,1,1,1,1,1,1,1,1,1,1,1,1,1,1,1
1,1,1,1,1,1,1,1,1,1,1,1,1,1,1,1,1,1,1,1,1,1,1
1,1,1,1,1,1,1,1,1,1,1,1,1,1,1,1,1,1,1,1,1,1,1
1,1,1,1,1,1,1,1,1,1,1,1,1,1,1,1,1,1,1,1,1,1,1
1,1,1,1,1,1,1,1,1,1,1,1,1,1,1,1,1,1,1,1,1,1,1
1,1,1,1,1,1,1,1,1,1,1,1,1,1,1,1,1,1,1,1,1,1,1
1,1,1,1,1,1,1,1,1,1,1,1,1,1,1,1,1,1,1,1,1,1,1
1,1,1,1,1,1,1,1,1,1,1,1,1,1,1,1,1,1,1,1,1,1,1
1,1,1,1,1,1,1,1,1,1,1,1,1,1,1,1,1,1,1,1,1,1,1
1,1,1,1,1,1,1,1,1,1,1,1,1,1,1,1,1,1,1,1,1,1,1
:endlayer
layer: 3
2,2,2,2,2,2,2,2,2,2,2,2,2,2,2,2,2,2,2,2,2,2,2
2,2,2,2,2,2,2,2,2,1,1,1,1,1,2,2,2,2,2,2,2,2,2
2,2,1,1,1,1,1,1,1,1,1,1,1,1,1,1,1,1,1,1,1,2,2
2,2,1,1,1,1,1,1,1,1,1,1,1,1,1,1,1,1,1,1,1,2,2
2,2,1,1,1,1,1,1,1,1,1,1,1,1,1,1,1,1,1,1,1,2,2
2,2,1,1,1,1,1,1,1,1,1,1,1,1,1,1,1,1,1,1,1,2,2
2,2,1,1,1,1,1,1,1,1,1,1,1,1,1,1,1,1,1,1,1,2,2
2,2,1,1,1,1,1,1,1,1,1,1,1,1,1,1,1,1,1,1,1,2,2
2,2,1,1,1,1,1,1,1,1,1,1,1,1,1,1,1,1,1,1,1,2,2
2,2,1,1,1,1,1,1,1,1,1,1,1,1,1,1,1,1,1,1,1,2,2
2,2,1,1,1,1,1,1,1,1,1,1,1,1,1,1,1,1,1,1,1,2,2
2,2,1,1,1,1,1,1,1,1,1,1,1,1,1,1,1,1,1,1,1,2,2
2,2,1,1,1,1,1,1,1,1,1,1,1,1,1,1,1,1,1,1,1,2,2
2,2,1,1,1,1,1,1,1,1,1,1,1,1,1,1,1,1,1,1,1,2,2
2,2,1,1,1,1,1,1,1,1,1,1,1,1,1,1,1,1,1,1,1,2,2
2,2,1,1,1,1,1,1,1,1,1,1,1,1,1,1,1,1,1,1,1,2,2
2,2,1,1,1,1,1,1,1,1,1,1,1,1,1,1,1,1,1,1,1,2,2
2,2,2,2,2,2,2,2,2,2,2,2,2,2,2,2,2,2,2,2,2,2,2
2,2,2,2,2,2,2,2,2,2,2,2,2,2,2,2,2,2,2,2,2,2,2
2,2,2,2,2,2,2,2,2,2,2,2,2,2,2,2,2,2,2,2,2,2,2
2,2,2,2,2,2,2,2,2,2,2,2,2,2,2,2,2,2,2,2,2,2,2
:endlayer
layer: 4
0,0,0,0,0,0,0,0,0,0,0,0,0,0,0,0,0,0,0,0,0,0,0
0,0,0,0,0,0,0,0,0,3,3,3,3,3,0,0,0,0,0,0,0,0,0
0,0,4,4,4,4,4,4,4,3,3,3,3,3,4,4,4,4,4,4,4,0,0
0,0,4,5,5,5,5,5,5,3,3,3,3,3,5,5,5,5,5,5,4,0,0
0,0,4,5,6,6,6,6,3,3,7,7,7,3,3,6,6,6,6,5,4,0,0
0,0,4,5,6,6,6,6,3,3,3,3,3,3,3,6,6,6,6,5,4,0,0
0,0,4,5,6,6,6,6,3,3,3,3,3,3,3,6,6,6,6,5,4,0,0
0,0,4,5,6,6,6,6,8,8,8,8,8,8,8,6,6,6,6,5,4,0,0
0,0,4,5,6,6,6,6,8,8,8,8,8,8,8,6,6,6,6,5,4,0,0
0,0,4,5,6,6,6,6,6,8,8,8,8,8,6,6,6,6,6,5,4,0,0
0,0,4,5,6,6,6,6,6,8,8,8,8,8,6,6,6,6,6,5,4,0,0
0,0,4,5,6,6,6,6,6,6,8,8,8,6,6,6,6,6,6,5,4,0,0
0,0,4,5,6,6,6,6,6,6,8,8,8,6,6,6,6,6,6,5,4,0,0
0,0,4,5,6,6,6,6,6,6,8,8,8,6,6,6,6,6,6,5,4,0,0
0,0,4,5,6,6,6,6,6,6,8,8,8,6,6,6,6,6,6,5,4,0,0
0,0,4,5,5,5,5,5,5,5,5,6,5,5,5,5,5,5,5,5,4,0,0
0,0,4,4,4,4,4,4,4,4,6,6,6,4,4,4,4,4,4,4,4,0,0
0,0,0,0,0,0,0,0,0,4,4,4,4,4,0,0,0,0,0,0,0,0,0
0,0,0,0,0,0,0,0,0,0,0,0,0,0,0,0,0,0,0,0,0,0,0
0,0,0,0,0,0,0,0,0,0,0,0,0,0,0,0,0,0,0,0,0,0,0
0,0,0,0,0,0,0,0,0,0,0,0,0,0,0,0,0,0,0,0,0,0,0
:endlayer
layer: 5
0,0,0,0,0,0,0,0,0,0,0,0,0,0,0,0,0,0,0,0,0,0,0
0,0,0,0,0,0,0,0,0,3,3,3,3,3,0,0,0,0,0,0,0,0,0
0,0,0,0,0,0,0,0,0,3,3,3,3,3,0,0,0,0,0,0,0,0,0
0,0,0,5,3,3,3,5,3,3,3,3,3,3,3,5,3,3,3,5,0,0,0
0,0,0,3,0,0,0,0,0,3,9,9,9,3,0,0,0,0,0,3,0,0,0
0,0,0,3,0,0,0,0,0,10,11,11,11,10,0,0,0,0,0,3,0,0,0
0,0,0,3,12,12,0,0,0,0,0,0,0,0,0,0,0,12,12,3,0,0,0
0,0,0,3,12,12,0,0,0,0,0,0,0,0,0,0,0,12,12,3,0,0,0
0,0,0,3,13,13,0,0,0,0,0,0,0,0,0,0,0,13,13,3,0,0,0
0,0,0,5,0,0,0,0,0,0,0,0,0,0,0,0,0,0,0,5,0,0,0
0,0,0,3,0,0,0,0,0,0,0,0,0,0,0,0,0,0,0,3,0,0,0
0,0,0,3,0,0,0,0,0,0,0,0,0,0,0,0,0,0,0,3,0,0,0
0,0,0,3,0,0,0,0,0,0,0,0,0,0,0,0,0,0,0,3,0,0,0
0,0,0,3,0,0,0,0,0,0,0,0,0,0,0,0,0,0,0,3,0,0,0
0,0,0,3,0,0,0,0,0,0,0,0,0,0,0,0,0,0,0,3,0,0,0
0,0,0,5,3,3,3,5,3,3,5,14,5,3,3,5,3,3,3,5,0,0,0
0,0,0,0,0,0,0,0,0,0,0,0,0,0,0,0,0,0,0,0,0,0,0
0,0,0,0,0,0,0,0,0,0,0,0,0,0,0,0,0,0,0,0,0,0,0
0,0,0,0,0,0,0,0,0,0,0,0,0,0,0,0,0,0,0,0,0,0,0
0,0,0,0,0,0,0,0,0,0,0,0,0,0,0,0,0,0,0,0,0,0,0
0,0,0,0,0,0,0,0,0,0,0,0,0,0,0,0,0,0,0,0,0,0,0
:endlayer
layer: 6
0,0,0,0,0,0,0,0,0,0,0,0,0,0,0,0,0,0,0,0,0,0,0
0,0,0,0,0,0,0,0,0,3,3,3,3,3,0,0,0,0,0,0,0,0,0
0,0,0,0,0,0,0,0,0,3,3,3,3,3,0,0,0,0,0,0,0,0,0
0,0,0,5,3,15,3,5,3,3,3,3,3,3,3,5,3,15,3,5,0,0,0
0,0,0,3,0,0,0,0,0,3,0,0,0,3,0,0,0,0,0,3,0,0,0
0,0,0,15,0,0,0,0,0,0,0,0,0,0,0,0,0,0,0,15,0,0,0
0,0,0,3,12,12,0,0,0,0,0,0,0,0,0,0,0,12,12,3,0,0,0
0,0,0,15,13,13,0,0,0,0,0,0,0,0,0,0,0,13,13,15,0,0,0
0,0,0,3,0,0,0,0,0,0,0,0,0,0,0,0,0,0,0,3,0,0,0
0,0,0,5,0,0,0,0,0,0,0,0,0,0,0,0,0,0,0,5,0,0,0
0,0,0,3,0,0,0,0,0,0,0,0,0,0,0,0,0,0,0,3,0,0,0
0,0,0,15,0,0,0,0,0,0,0,0,0,0,0,0,0,0,0,15,0,0,0
0,0,0,3,0,0,0,0,0,0,0,0,0,0,0,0,0,0,0,3,0,0,0
0,0,0,15,0,0,0,0,0,0,0,0,0,0,0,0,0,0,0,15,0,0,0
0,0,0,3,0,0,0,0,0,0,0,0,0,0,0,0,0,0,0,3,0,0,0
0,0,0,5,3,15,3,5,3,3,5,16,5,3,3,5,3,15,3,5,0,0,0
0,0,0,0,0,0,0,0,0,0,0,0,0,0,0,0,0,0,0,0,0,0,0
0,0,0,0,0,0,0,0,0,0,0,0,0,0,0,0,0,0,0,0,0,0,0
0,0,0,0,0,0,0,0,0,0,0,0,0,0,0,0,0,0,0,0,0,0,0
0,0,0,0,0,0,0,0,0,0,0,0,0,0,0,0,0,0,0,0,0,0,0
0,0,0,0,0,0,0,0,0,0,0,0,0,0,0,0,0,0,0,0,0,0,0
:endlayer
layer: 7
0,0,0,0,0,0,0,0,0,0,0,0,0,0,0,0,0,0,0,0,0,0,0
0,0,0,0,0,0,0,0,0,3,3,3,3,3,0,0,0,0,0,0,0,0,0
0,0,0,17,0,0,0,17,0,3,3,3,3,3,0,17,0,0,0,17,0,0,0
0,0,18,5,3,3,3,5,3,3,3,0,3,3,3,5,3,3,3,5,19,0,0
0,0,0,3,20,20,0,21,0,3,0,0,0,3,0,21,0,20,20,3,0,0,0
0,0,0,3,20,20,0,0,0,0,0,0,0,0,0,0,0,20,20,3,0,0,0
0,0,0,3,13,13,0,0,0,0,0,0,0,0,0,0,0,13,13,3,0,0,0
0,0,0,3,0,0,0,0,0,0,0,0,0,0,0,0,0,0,0,3,0,0,0
0,0,0,3,0,0,0,0,0,0,0,0,0,0,0,0,0,0,0,3,0,0,0
0,0,18,5,19,0,0,0,0,0,0,0,0,0,0,0,0,0,18,5,19,0,0
0,0,0,3,0,0,0,0,0,0,0,0,0,0,0,0,0,0,0,3,0,0,0
0,0,0,3,0,0,0,0,0,0,0,0,0,0,0,0,0,0,0,3,0,0,0
0,0,0,3,0,0,0,0,0,0,0,0,0,0,0,0,0,0,0,3,0,0,0
0,0,0,3,0,0,0,0,0,0,0,0,0,0,0,0,0,0,0,3,0,0,0
0,0,0,3,0,0,0,17,0,0,0,0,0,0,0,17,0,0,0,3,0,0,0
0,0,18,5,3,3,3,5,3,3,5,5,5,3,3,5,3,3,3,5,19,0,0
0,0,0,21,0,0,0,22,0,0,21,22,21,0,0,22,0,0,0,21,0,0,0
0,0,0,0,0,0,0,0,0,0,0,0,0,0,0,0,0,0,0,0,0,0,0
0,0,0,0,0,0,0,0,0,0,0,0,0,0,0,0,0,0,0,0,0,0,0
0,0,0,0,0,0,0,0,0,0,0,0,0,0,0,0,0,0,0,0,0,0,0
0,0,0,0,0,0,0,0,0,0,0,0,0,0,0,0,0,0,0,0,0,0,0
:endlayer
layer: 8
0,0,0,0,0,0,0,0,0,0,0,0,0,0,0,0,0,0,0,0,0,0,0
0,0,0,0,0,0,0,0,0,3,3,3,3,3,0,0,0,0,0,0,0,0,0
0,0,5,5,5,5,5,5,5,3,3,3,3,3,5,5,5,5,5,5,5,0,0
0,0,5,6,6,6,6,6,3,3,3,0,3,3,3,6,6,6,6,6,5,0,0
0,0,5,6,6,6,6,6,0,3,0,0,0,3,0,6,6,6,6,6,5,0,0
0,0,5,6,13,13,6,6,0,0,0,0,0,0,0,6,6,13,13,6,5,0,0
0,0,5,6,0,0,6,6,0,0,0,0,0,0,0,6,6,0,0,6,5,0,0
0,0,5,6,0,0,6,6,0,0,0,0,0,0,0,6,6,0,0,6,5,0,0
0,0,5,6,0,0,6,6,6,6,6,6,6,6,6,6,6,0,0,6,5,0,0
0,0,5,6,6,6,6,6,6,6,6,6,6,6,6,6,6,6,6,6,5,0,0
0,0,5,6,6,6,6,6,6,6,6,6,6,6,6,6,6,6,6,6,5,0,0
0,0,5,6,6,6,6,6,6,6,6,6,6,6,6,6,6,6,6,6,5,0,0
0,0,5,6,6,6,6,6,6,6,6,6,6,6,6,6,6,6,6,6,5,0,0
0,0,5,6,6,6,6,6,6,6,6,6,6,6,6,6,6,6,6,6,5,0,0
0,0,5,6,6,6,6,6,6,6,6,6,6,6,6,6,6,6,6,6,5,0,0
0,0,5,6,6,6,6,6,6,6,6,6,6,6,6,6,6,6,6,6,5,0,0
0,0,5,5,5,5,5,5,5,5,5,5,5,5,5,5,5,5,5,5,5,0,0
0,0,0,0,0,0,0,6,0,0,0,6,0,0,0,6,0,0,0,0,0,0,0
0,0,0,0,0,0,0,0,0,0,0,0,0,0,0,0,0,0,0,0,0,0,0
0,0,0,0,0,0,0,0,0,0,0,0,0,0,0,0,0,0,0,0,0,0,0
0,0,0,0,0,0,0,0,0,0,0,0,0,0,0,0,0,0,0,0,0,0,0
:endlayer
layer: 9
0,0,0,0,0,0,0,0,0,0,0,0,0,0,0,0,0,0,0,0,0,0,0
0,0,0,0,0,0,0,0,0,3,3,3,3,3,0,0,0,0,0,0,0,0,0
0,0,5,3,3,3,5,3,3,3,3,3,3,3,3,3,5,3,3,3,5,0,0
0,0,3,0,0,0,0,23,24,3,3,0,3,3,25,23,0,0,0,0,3,0,0
0,0,3,0,0,0,0,23,0,3,3,3,3,3,0,23,0,0,0,0,3,0,0
0,0,3,0,0,0,0,23,0,0,0,0,0,0,0,23,0,0,0,0,3,0,0
0,0,3,0,0,0,0,23,0,0,0,0,0,0,0,23,0,0,0,0,3,0,0
0,0,5,0,0,0,0,23,0,0,0,0,0,0,0,23,0,0,0,0,5,0,0
0,0,3,0,0,0,0,23,23,23,23,23,23,23,23,23,0,0,0,0,3,0,0
0,0,3,0,0,0,0,0,0,0,0,0,0,0,0,0,0,0,0,0,3,0,0
0,0,3,0,0,0,0,0,0,0,0,0,0,0,0,0,0,0,0,0,3,0,0
0,0,5,0,0,0,0,0,0,0,0,0,0,0,0,0,0,0,0,0,5,0,0
0,0,3,0,0,0,0,0,0,0,0,0,0,0,0,0,0,0,0,0,3,0,0
0,0,3,0,0,0,0,0,0,0,0,0,0,0,0,0,0,0,0,0,3,0,0
0,0,3,0,0,4,4,4,4,4,4,4,4,4,4,4,4,4,0,0,3,0,0
0,0,3,0,0,4,6,6,6,6,6,6,6,6,6,6,6,4,0,0,3,0,0
0,0,5,3,3,3,5,6,6,6,6,6,6,6,6,6,5,3,3,3,5,0,0
0,0,0,0,0,0,5,5,5,5,5,5,5,5,5,5,5,0,0,0,0,0,0
0,0,0,0,0,0,0,0,0,0,0,0,0,0,0,0,0,0,0,0,0,0,0
0,0,0,0,0,0,0,0,0,0,0,0,0,0,0,0,0,0,0,0,0,0,0
0,0,0,0,0,0,0,0,0,0,0,0,0,0,0,0,0,0,0,0,0,0,0
:endlayer
layer: 10
0,0,0,0,0,0,0,0,0,0,0,0,0,0,0,0,0,0,0,0,0,0,0
0,0,0,0,0,0,0,0,0,25,3,3,3,24,0,0,0,0,0,0,0,0,0
0,0,5,3,26,3,5,3,3,24,3,3,3,25,3,3,5,3,15,3,5,0,0
0,0,3,0,0,0,0,0,0,3,3,0,3,3,0,0,0,0,0,0,3,0,0
0,0,26,0,0,0,0,0,0,24,3,3,3,25,0,0,0,0,0,0,15,0,0
0,0,26,0,0,0,0,0,0,0,0,0,0,0,0,0,0,0,0,0,15,0,0
0,0,3,0,0,0,0,0,0,0,0,0,0,0,0,0,0,0,0,0,3,0,0
0,0,5,0,0,0,0,0,0,0,0,0,0,0,0,0,0,0,0,0,5,0,0
0,0,3,0,0,0,0,0,0,0,0,0,0,0,0,0,0,0,0,0,3,0,0
0,0,26,0,0,0,0,0,0,0,0,0,0,0,0,0,0,0,0,0,15,0,0
0,0,3,0,0,0,0,0,0,0,0,0,0,0,0,0,0,0,0,0,3,0,0
0,0,5,0,0,0,0,0,0,0,0,0,0,0,0,0,0,0,0,0,5,0,0
0,0,3,0,0,0,0,0,0,0,0,0,0,0,0,0,0,0,0,0,3,0,0
0,0,26,0,0,0,0,0,0,0,0,0,0,0,0,0,0,0,0,0,15,0,0
0,0,26,0,0,0,0,0,0,0,0,0,0,0,0,0,0,0,0,0,15,0,0
0,0,3,0,0,0,0,0,27,28,0,0,0,0,0,0,0,0,0,0,3,0,0
0,0,5,3,26,3,5,0,27,28,0,0,0,0,0,0,5,3,15,3,5,0,0
0,0,0,0,0,0,5,3,3,3,3,5,3,3,3,3,5,0,0,0,0,0,0
0,0,0,0,0,0,0,0,0,0,0,0,0,0,0,0,0,0,0,0,0,0,0
0,0,0,0,0,0,0,0,0,0,0,0,0,0,0,0,0,0,0,0,0,0,0
0,0,0,0,0,0,0,0,0,0,0,0,0,0,0,0,0,0,0,0,0,0,0
:endlayer
layer: 11
0,0,0,0,0,0,0,0,0,0,0,0,0,0,0,0,0,0,0,0,0,0,0
27,6,0,0,29,0,0,0,0,0,3,3,3,0,0,0,0,0,29,0,0,6,30
27,6,5,3,3,3,5,3,3,3,3,3,3,3,3,3,5,3,3,3,5,6,30
27,6,3,0,0,0,21,0,0,0,3,0,3,0,0,0,21,0,0,0,3,6,30
27,6,3,0,0,0,0,0,0,0,3,3,3,0,0,0,0,0,0,0,3,6,30
27,6,3,0,0,0,0,0,0,0,0,0,0,0,0,0,0,0,0,0,3,6,30
27,6,3,0,0,0,0,0,0,0,0,0,0,0,0,0,0,0,0,0,3,6,30
27,6,5,0,0,0,0,0,0,0,0,0,0,0,0,0,0,0,0,0,5,6,30
27,6,3,0,0,0,0,0,0,0,0,0,0,0,0,0,0,0,0,0,3,6,30
27,6,3,0,0,0,0,0,0,0,0,0,0,0,0,0,0,0,0,0,3,6,30
27,6,3,0,0,0,0,0,0,0,0,0,0,0,0,0,0,0,0,0,3,6,30
27,6,5,19,0,0,0,0,0,0,0,0,0,0,0,0,0,0,0,18,5,6,30
27,6,3,0,0,0,0,0,0,0,0,0,0,0,0,0,0,0,0,0,3,6,30
27,6,3,0,0,0,0,0,0,0,0,0,0,0,0,0,0,0,0,0,3,6,30
27,6,3,0,0,0,0,0,0,0,0,0,0,0,0,0,0,0,0,0,3,6,30
27,6,3,0,0,0,17,0,0,27,28,0,0,0,0,0,17,0,0,0,3,6,30
27,6,5,3,3,3,5,0,0,27,28,0,0,0,0,0,5,3,3,3,5,6,30
27,6,0,0,31,0,5,3,26,3,3,5,3,3,26,3,5,0,31,0,0,6,30
0,0,0,0,0,0,0,0,0,0,0,0,0,0,0,0,0,0,0,0,0,0,0
0,0,0,0,0,0,0,0,0,0,0,0,0,0,0,0,0,0,0,0,0,0,0
0,0,0,0,0,0,0,0,0,0,0,0,0,0,0,0,0,0,0,0,0,0,0
:endlayer
layer: 12
0,0,0,0,0,0,0,0,0,0,0,0,0,0,0,0,0,0,0,0,0,0,0
0,27,6,0,0,0,0,0,0,0,3,3,3,0,0,0,0,0,0,0,6,30,0
0,27,6,6,6,6,6,6,6,6,3,3,3,6,6,6,6,6,6,6,6,30,0
0,27,6,0,0,0,0,0,0,0,3,0,3,0,0,0,0,0,0,0,6,30,0
0,27,6,0,0,0,0,0,0,0,3,3,3,0,0,0,0,0,0,0,6,30,0
0,27,6,0,0,0,0,0,0,0,0,0,0,0,0,0,0,0,0,0,6,30,0
0,27,6,0,0,0,0,0,0,0,0,0,0,0,0,0,0,0,0,0,6,30,0
0,27,6,0,0,0,0,0,0,0,0,0,0,0,0,0,0,0,0,0,6,30,0
0,27,6,0,0,0,0,0,0,0,0,0,0,0,0,0,0,0,0,0,6,30,0
0,27,6,0,0,0,0,0,0,0,0,0,0,0,0,0,0,0,0,0,6,30,0
0,27,6,0,0,0,0,0,0,0,0,0,0,0,0,0,0,0,0,0,6,30,0
0,27,6,0,0,0,0,0,0,0,0,0,0,0,0,0,0,0,0,0,6,30,0
0,27,6,0,0,0,0,0,0,0,0,0,0,0,0,0,0,0,0,0,6,30,0
0,27,6,0,0,0,0,0,0,0,0,0,0,0,0,0,0,0,0,0,6,30,0
0,27,6,0,0,0,0,0,0,0,0,0,0,0,0,0,0,0,0,0,6,30,0
0,27,6,0,0,0,0,0,0,0,27,28,0,0,0,0,0,0,0,0,6,30,0
0,27,6,6,6,6,6,0,0,0,27,28,0,0,0,0,6,6,6,6,6,30,0
0,27,6,0,27,6,5,3,3,3,3,5,3,3,3,3,5,6,30,0,6,30,0
0,0,0,0,27,6,0,0,29,0,0,0,0,0,29,0,0,6,30,0,0,0,0
0,0,0,0,0,0,0,0,0,0,0,0,0,0,0,0,0,0,0,0,0,0,0
0,0,0,0,0,0,0,0,0,0,0,0,0,0,0,0,0,0,0,0,0,0,0
:endlayer
layer: 13
0,0,0,0,0,0,0,0,0,0,0,0,0,0,0,0,0,0,0,0,0,0,0
0,0,27,6,0,0,0,0,0,0,3,3,3,0,0,0,0,0,0,6,30,0,0
0,0,27,6,3,3,3,3,3,3,3,3,3,3,3,3,3,3,3,6,30,0,0
0,0,27,0,0,0,0,0,0,0,3,0,3,0,0,0,0,0,0,0,30,0,0
0,0,27,0,0,0,0,0,0,0,3,3,3,0,0,0,0,0,0,0,30,0,0
0,0,27,0,0,0,0,0,0,0,0,0,0,0,0,0,0,0,0,0,30,0,0
0,0,27,0,0,0,0,0,0,0,0,0,0,0,0,0,0,0,0,0,30,0,0
0,0,27,0,0,0,0,0,0,0,0,0,0,0,0,0,0,0,0,0,30,0,0
0,0,27,0,0,0,0,0,0,0,0,0,0,0,0,0,0,0,0,0,30,0,0
0,0,27,0,0,0,0,0,0,0,0,0,0,0,0,0,0,0,0,0,30,0,0
0,0,27,0,0,0,0,0,0,0,0,0,0,0,0,0,0,0,0,0,30,0,0
0,0,27,0,0,0,0,0,0,0,0,0,0,0,0,0,0,0,0,0,30,0,0
0,0,27,0,0,0,0,0,0,0,0,0,0,0,0,0,0,0,0,0,30,0,0
0,0,27,0,0,0,0,0,0,0,0,0,0,0,0,0,0,0,0,0,30,0,0
0,0,27,0,0,0,0,0,0,0,0,0,0,0,0,0,0,0,0,0,30,0,0
0,0,27,0,0,0,0,0,0,0,0,27,28,0,0,0,0,0,0,0,30,0,0
0,0,27,3,3,3,6,0,0,0,0,27,28,0,0,0,6,3,3,3,30,0,0
0,0,27,6,0,27,6,6,6,6,6,6,6,6,6,6,6,30,0,6,30,0,0
0,0,0,0,0,27,6,32,32,32,32,32,32,32,32,32,6,30,0,0,0,0,0
0,0,0,0,0,0,0,0,0,0,0,0,0,0,0,0,0,0,0,0,0,0,0
0,0,0,0,0,0,0,0,0,0,0,0,0,0,0,0,0,0,0,0,0,0,0
:endlayer
layer: 14
0,0,0,0,0,0,0,0,0,0,0,0,0,0,0,0,0,0,0,0,0,0,0
0,0,0,27,6,0,0,0,0,0,3,3,3,0,0,0,0,0,6,30,0,0,0
0,0,0,27,6,3,3,3,3,3,3,3,3,3,3,3,3,3,6,30,0,0,0
0,0,0,27,6,6,6,6,6,6,3,0,3,6,6,6,6,6,6,30,0,0,0
0,0,0,27,6,6,6,6,6,6,3,3,3,6,6,6,6,6,6,30,0,0,0
0,0,0,27,6,6,6,6,6,6,6,6,6,6,6,6,6,6,6,30,0,0,0
0,0,0,5,5,6,6,6,6,6,6,6,6,6,6,6,6,6,5,5,0,0,0
0,0,0,5,6,6,6,6,6,6,6,6,6,6,6,6,6,6,6,5,0,0,0
0,0,0,5,6,6,6,6,6,6,6,6,6,6,6,6,6,6,6,5,0,0,0
0,0,0,5,6,6,6,6,6,6,6,6,6,6,6,6,6,6,6,5,0,0,0
0,0,0,5,6,6,6,6,6,6,6,6,6,6,6,6,6,6,6,5,0,0,0
0,0,0,5,6,6,6,6,6,6,6,6,6,6,6,6,6,6,6,5,0,0,0
0,0,0,5,5,6,6,6,6,6,6,6,6,6,6,6,6,6,5,5,0,0,0
0,0,0,27,6,6,6,6,6,6,6,6,6,6,6,6,6,6,6,30,0,0,0
0,0,0,27,6,6,6,6,6,6,6,6,6,6,6,6,6,6,6,30,0,0,0
0,0,0,27,6,6,6,6,6,0,0,0,27,6,6,6,6,6,6,30,0,0,0
0,0,0,27,3,3,3,6,6,0,0,0,27,6,6,6,3,3,3,30,0,0,0
0,0,0,27,6,0,27,6,3,3,6,6,6,3,3,6,30,0,6,30,0,0,0
0,0,0,0,0,0,27,6,0,0,0,0,0,0,0,6,30,0,0,0,0,0,0
0,0,0,0,0,0,0,0,0,0,0,0,0,0,0,0,0,0,0,0,0,0,0
0,0,0,0,0,0,0,0,0,0,0,0,0,0,0,0,0,0,0,0,0,0,0
:endlayer
layer: 15
0,0,0,0,0,0,0,0,0,0,0,0,0,0,0,0,0,0,0,0,0,0,0
0,0,0,0,27,6,0,0,0,0,3,3,3,0,0,0,0,6,30,0,0,0,0
0,0,0,0,27,6,3,3,3,3,3,3,3,3,3,3,3,6,30,0,0,0,0
0,0,0,0,27,0,0,0,5,0,3,0,3,0,5,0,0,0,30,0,0,0,0
0,0,0,0,27,0,0,0,5,0,3,3,3,0,5,0,0,0,30,0,0,0,0
0,0,0,0,27,0,0,0,5,0,0,0,0,0,5,0,0,0,30,0,0,0,0
0,0,0,5,3,0,0,0,5,0,0,0,0,0,5,0,0,0,3,5,0,0,0
0,0,0,3,0,0,0,0,5,0,0,0,0,0,5,0,0,0,0,3,0,0,0
0,0,0,3,0,0,0,0,5,0,0,0,0,0,5,0,0,0,0,3,0,0,0
0,0,0,3,0,0,0,0,5,0,0,0,0,0,5,0,0,0,0,3,0,0,0
0,0,0,3,0,0,0,0,33,0,0,0,0,0,34,0,0,0,0,3,0,0,0
0,0,0,3,0,0,0,0,35,0,0,0,0,0,36,0,0,0,0,3,0,0,0
0,0,0,5,3,0,0,0,5,0,0,0,0,0,5,0,0,0,3,5,0,0,0
0,0,0,0,27,0,0,0,5,0,0,0,0,0,5,0,0,0,30,0,0,0,0
0,0,0,0,27,0,0,0,5,0,0,0,0,0,5,0,0,0,30,0,0,0,0
0,0,0,0,27,0,0,0,5,0,0,0,0,0,5,0,0,0,30,0,0,0,0
0,0,0,0,27,3,3,3,5,0,0,0,0,0,5,3,3,3,30,0,0,0,0
0,0,0,0,27,6,0,27,6,3,3,6,3,3,6,30,0,6,30,0,0,0,0
0,0,0,0,0,0,0,27,6,0,0,0,0,0,6,30,0,0,0,0,0,0,0
0,0,0,0,0,0,0,0,0,0,0,0,0,0,0,0,0,0,0,0,0,0,0
0,0,0,0,0,0,0,0,0,0,0,0,0,0,0,0,0,0,0,0,0,0,0
:endlayer
layer: 16
0,0,0,0,0,0,0,0,0,0,0,0,0,0,0,0,0,0,0,0,0,0,0
0,0,0,0,0,27,6,0,0,0,3,3,3,0,0,0,6,30,0,0,0,0,0
0,0,0,0,0,27,6,3,3,3,3,3,3,3,3,3,6,30,0,0,0,0,0
0,0,0,0,0,27,0,0,5,0,3,0,3,0,5,0,0,30,0,0,0,0,0
0,0,0,0,0,27,0,0,6,0,3,3,3,0,6,0,0,30,0,0,0,0,0
0,0,0,0,0,27,0,0,6,0,0,0,0,0,6,0,0,30,0,0,0,0,0
0,0,0,5,3,3,0,0,6,0,0,0,0,0,6,0,0,3,3,5,0,0,0
0,0,0,3,0,0,0,0,6,0,0,0,0,0,6,0,0,0,0,3,0,0,0
0,0,0,15,0,0,0,0,6,0,0,0,0,0,6,0,0,0,0,15,0,0,0
0,0,0,3,0,0,0,0,5,0,0,0,0,0,5,0,0,0,0,3,0,0,0
0,0,0,15,0,0,0,0,37,0,0,0,0,0,38,0,0,0,0,15,0,0,0
0,0,0,3,0,0,0,0,39,0,0,0,0,0,40,0,0,0,0,3,0,0,0
0,0,0,5,3,3,0,0,5,0,0,0,0,0,5,0,0,3,3,5,0,0,0
0,0,0,0,0,27,0,0,6,0,0,0,0,0,6,0,0,30,0,0,0,0,0
0,0,0,0,0,27,0,0,6,0,0,0,0,0,6,0,0,30,0,0,0,0,0
0,0,0,0,0,27,0,0,5,0,0,0,0,0,5,0,0,30,0,0,0,0,0
0,0,0,0,0,27,3,3,3,0,0,0,0,0,3,3,3,30,0,0,0,0,0
0,0,0,0,0,27,6,0,27,6,3,6,3,6,30,0,6,30,0,0,0,0,0
0,0,0,0,0,0,0,0,27,6,0,0,0,6,30,0,0,0,0,0,0,0,0
0,0,0,0,0,0,0,0,0,0,0,0,0,0,0,0,0,0,0,0,0,0,0
0,0,0,0,0,0,0,0,0,0,0,0,0,0,0,0,0,0,0,0,0,0,0
:endlayer
layer: 17
0,0,0,0,0,0,0,0,0,0,0,0,0,0,0,0,0,0,0,0,0,0,0
0,0,0,0,0,0,27,6,0,0,3,3,3,0,0,6,30,0,0,0,0,0,0
0,0,0,0,0,0,27,6,3,3,3,3,3,3,3,6,30,0,0,0,0,0,0
0,0,0,0,0,0,27,21,5,0,3,0,3,0,5,21,30,0,0,0,0,0,0
0,0,41,41,41,41,6,0,6,0,3,3,3,0,6,0,6,41,41,41,41,0,0
0,0,6,6,0,0,27,0,6,0,0,0,0,0,6,0,30,0,0,6,6,0,0
0,0,0,5,3,3,3,0,6,0,0,0,0,0,6,0,3,3,3,5,0,0,0
0,0,0,3,0,0,0,0,6,0,0,0,0,0,6,0,0,0,0,3,0,0,0
0,0,42,3,0,0,0,0,6,0,0,0,0,0,6,0,0,0,0,3,43,0,0
0,0,0,3,0,0,0,0,5,0,0,0,0,0,5,0,0,0,0,3,0,0,0
0,0,42,3,0,0,0,0,6,0,0,0,0,0,6,0,0,0,0,3,43,0,0
0,0,0,3,0,0,0,0,6,0,0,0,0,0,6,0,0,0,0,3,0,0,0
0,0,0,5,3,3,3,0,5,0,0,0,0,0,5,0,3,3,3,5,0,0,0
0,0,6,6,0,0,27,0,6,0,0,0,0,0,6,0,30,0,0,6,6,0,0
0,0,13,13,13,13,6,0,6,0,0,0,0,0,6,0,6,13,13,13,13,0,0
0,0,0,0,0,0,27,17,5,0,0,0,0,0,5,17,30,0,0,0,0,0,0
0,0,0,0,0,0,27,3,3,3,0,0,0,3,3,3,30,0,0,0,0,0,0
0,0,0,0,0,0,27,6,0,27,6,6,6,30,0,6,30,0,0,0,0,0,0
0,0,0,0,0,0,0,0,0,27,6,0,6,30,0,0,0,0,0,0,0,0,0
0,0,0,0,0,0,0,0,0,0,0,0,0,0,0,0,0,0,0,0,0,0,0
0,0,0,0,0,0,0,0,0,0,0,0,0,0,0,0,0,0,0,0,0,0,0
:endlayer
layer: 18
0,0,0,0,0,0,0,0,0,0,0,0,0,0,0,0,0,0,0,0,0,0,0
0,0,0,0,0,0,0,27,6,0,3,3,3,0,6,30,0,0,0,0,0,0,0
0,0,0,0,0,0,0,27,6,3,3,3,3,3,6,30,0,0,0,0,0,0,0
0,0,0,0,0,0,0,27,5,0,3,0,3,0,5,30,0,0,0,0,0,0,0
0,0,0,0,0,0,0,27,6,0,3,3,3,0,6,30,0,0,0,0,0,0,0
0,0,41,41,41,41,41,6,6,0,0,21,0,0,6,6,41,41,41,41,41,0,0
0,0,6,6,0,0,0,27,6,0,0,0,0,0,6,30,0,0,0,6,6,0,0
0,0,32,6,0,0,0,27,6,0,0,0,0,0,6,30,0,0,0,6,32,0,0
0,0,32,6,0,0,0,27,6,0,0,0,0,0,6,30,0,0,0,6,32,0,0
0,0,32,6,0,0,0,27,5,19,0,0,0,18,5,30,0,0,0,6,32,0,0
0,0,32,6,0,0,0,27,5,0,0,0,0,0,5,30,0,0,0,6,32,0,0
0,0,32,6,0,0,0,27,5,0,0,0,0,0,5,30,0,0,0,6,32,0,0
0,0,6,6,0,0,0,27,5,19,0,0,0,18,5,30,0,0,0,6,6,0,0
0,0,13,13,13,13,13,6,6,0,0,0,0,0,6,6,13,13,13,13,13,0,0
0,0,0,0,0,0,0,27,6,0,0,0,0,0,6,30,0,0,0,0,0,0,0
0,0,0,0,0,0,0,27,5,0,0,0,0,0,5,30,0,0,0,0,0,0,0
0,0,0,0,0,0,0,27,3,3,3,17,3,3,3,30,0,0,0,0,0,0,0
0,0,0,0,0,0,0,27,6,0,27,6,30,0,6,30,0,0,0,0,0,0,0
0,0,0,0,0,0,0,0,0,0,27,6,30,0,0,0,0,0,0,0,0,0,0
0,0,0,0,0,0,0,0,0,0,0,0,0,0,0,0,0,0,0,0,0,0,0
0,0,0,0,0,0,0,0,0,0,0,0,0,0,0,0,0,0,0,0,0,0,0
:endlayer
layer: 19
0,0,0,0,0,0,0,0,0,0,0,0,0,0,0,0,0,0,0,0,0,0,0
0,0,0,0,0,0,0,0,27,6,3,3,3,6,30,0,0,0,0,0,0,0,0
0,0,0,0,0,0,0,0,27,6,3,3,3,6,30,0,0,0,0,0,0,0,0
0,0,0,0,0,0,0,0,27,21,3,0,3,21,30,0,0,0,0,0,0,0,0
0,0,0,0,0,0,0,0,27,0,3,3,3,0,30,0,0,0,0,0,0,0,0
0,0,0,0,0,0,0,0,27,0,0,0,0,0,30,0,0,0,0,0,0,0,0
0,0,41,41,41,41,41,41,6,0,0,0,0,0,6,41,41,41,41,41,41,0,0
0,0,6,6,0,0,0,0,27,0,0,0,0,0,30,0,0,0,0,6,6,0,0
0,0,0,3,0,0,0,0,27,0,0,0,0,0,30,0,0,0,0,3,0,0,0
0,0,0,3,0,0,0,0,27,0,0,0,0,0,30,0,0,0,0,3,0,0,0
0,0,0,3,0,0,0,0,27,0,0,0,0,0,30,0,0,0,0,3,0,0,0
0,0,6,6,0,0,0,0,27,0,0,0,0,0,30,0,0,0,0,6,6,0,0
0,0,13,13,13,13,13,13,6,0,0,0,0,0,6,13,13,13,13,13,13,0,0
0,0,0,0,0,0,0,0,27,0,0,0,0,0,30,0,0,0,0,0,0,0,0
0,0,0,0,0,0,0,0,27,0,0,0,0,0,30,0,0,0,0,0,0,0,0
0,0,0,0,0,0,0,0,27,0,0,0,0,0,30,0,0,0,0,0,0,0,0
0,0,0,0,0,0,0,0,27,3,3,3,3,3,30,0,0,0,0,0,0,0,0
0,0,0,0,0,0,0,0,27,6,0,0,0,6,30,0,0,0,0,0,0,0,0
0,0,0,0,0,0,0,0,0,0,0,0,0,0,0,0,0,0,0,0,0,0,0
0,0,0,0,0,0,0,0,0,0,0,0,0,0,0,0,0,0,0,0,0,0,0
0,0,0,0,0,0,0,0,0,0,0,0,0,0,0,0,0,0,0,0,0,0,0
:endlayer
layer: 20
0,0,0,0,0,0,0,0,0,0,0,0,0,0,0,0,0,0,0,0,0,0,0
0,0,0,0,0,0,0,0,0,27,3,3,3,30,0,0,0,0,0,0,0,0,0
0,0,0,0,0,0,0,0,0,27,3,3,3,30,0,0,0,0,0,0,0,0,0
0,0,0,0,0,0,0,0,0,27,3,0,3,30,0,0,0,0,0,0,0,0,0
0,0,0,0,0,0,0,0,0,27,3,3,3,30,0,0,0,0,0,0,0,0,0
0,0,0,0,0,0,0,0,0,27,0,0,0,30,0,0,0,0,0,0,0,0,0
0,0,0,0,0,0,0,0,0,27,0,0,0,30,0,0,0,0,0,0,0,0,0
0,0,41,41,41,41,41,41,41,6,0,0,0,6,41,41,41,41,41,41,41,0,0
0,0,6,6,0,0,0,0,0,27,0,0,0,30,0,0,0,0,0,6,6,0,0
0,0,0,3,19,0,0,0,0,27,0,0,0,30,0,0,0,0,18,3,0,0,0
0,0,6,6,0,0,0,0,0,27,0,0,0,30,0,0,0,0,0,6,6,0,0
0,0,13,13,13,13,13,13,13,6,0,0,0,6,13,13,13,13,13,13,13,0,0
0,0,0,0,0,0,0,0,0,27,0,0,0,30,0,0,0,0,0,0,0,0,0
0,0,0,0,0,0,0,0,0,27,0,0,0,30,0,0,0,0,0,0,0,0,0
0,0,0,0,0,0,0,0,0,27,0,0,0,30,0,0,0,0,0,0,0,0,0
0,0,0,0,0,0,0,0,0,27,0,0,0,30,0,0,0,0,0,0,0,0,0
0,0,0,0,0,0,0,0,0,27,3,3,3,30,0,0,0,0,0,0,0,0,0
0,0,0,0,0,0,0,0,0,27,6,6,6,30,0,0,0,0,0,0,0,0,0
0,0,0,0,0,0,0,0,0,0,0,0,0,0,0,0,0,0,0,0,0,0,0
0,0,0,0,0,0,0,0,0,0,0,0,0,0,0,0,0,0,0,0,0,0,0
0,0,0,0,0,0,0,0,0,0,0,0,0,0,0,0,0,0,0,0,0,0,0
:endlayer
layer: 21
0,0,0,0,0,0,0,0,0,0,0,0,0,0,0,0,0,0,0,0,0,0,0
0,0,0,0,0,0,0,0,0,0,24,3,25,0,0,0,0,0,0,0,0,0,0
0,0,0,0,0,0,0,0,0,0,3,3,3,0,0,0,0,0,0,0,0,0,0
0,0,0,0,0,0,0,0,0,0,3,0,3,0,0,0,0,0,0,0,0,0,0
0,0,0,0,0,0,0,0,0,0,3,3,3,0,0,0,0,0,0,0,0,0,0
0,0,0,0,0,0,0,0,0,0,27,6,30,0,0,0,0,0,0,0,0,0,0
0,0,0,0,0,0,0,0,0,0,27,6,30,0,0,0,0,0,0,0,0,0,0
0,0,0,0,0,0,0,0,0,0,27,6,30,0,0,0,0,0,0,0,0,0,0
0,0,41,41,41,41,41,41,41,41,6,6,6,41,41,41,41,41,41,41,41,0,0
0,0,6,6,6,6,6,6,6,6,6,6,6,6,6,6,6,6,6,6,6,0,0
0,0,13,13,13,13,13,13,13,13,6,6,6,13,13,13,13,13,13,13,13,0,0
0,0,0,0,0,0,0,0,0,0,27,6,30,0,0,0,0,0,0,0,0,0,0
0,0,0,0,0,0,0,0,0,0,27,6,30,0,0,0,0,0,0,0,0,0,0
0,0,0,0,0,0,0,0,0,0,27,6,30,0,0,0,0,0,0,0,0,0,0
0,0,0,0,0,0,0,0,0,0,27,6,30,0,0,0,0,0,0,0,0,0,0
0,0,0,0,0,0,0,0,0,0,27,6,30,0,0,0,0,0,0,0,0,0,0
0,0,0,0,0,0,0,0,0,0,27,6,30,0,0,0,0,0,0,0,0,0,0
0,0,0,0,0,0,0,0,0,0,27,6,30,0,0,0,0,0,0,0,0,0,0
0,0,0,0,0,0,0,0,0,0,0,0,0,0,0,0,0,0,0,0,0,0,0
0,0,0,0,0,0,0,0,0,0,0,0,0,0,0,0,0,0,0,0,0,0,0
0,0,0,0,0,0,0,0,0,0,0,0,0,0,0,0,0,0,0,0,0,0,0
:endlayer
layer: 22
0,0,0,0,0,0,0,0,0,0,0,0,0,0,0,0,0,0,0,0,0,0,0
0,0,0,0,0,0,0,0,0,0,0,3,0,0,0,0,0,0,0,0,0,0,0
0,0,0,0,0,0,0,0,0,0,3,3,3,0,0,0,0,0,0,0,0,0,0
0,0,0,0,0,0,0,0,0,0,3,0,3,0,0,0,0,0,0,0,0,0,0
0,0,0,0,0,0,0,0,0,0,3,3,3,0,0,0,0,0,0,0,0,0,0
0,0,0,0,0,0,0,0,0,0,0,21,0,0,0,0,0,0,0,0,0,0,0
0,0,0,0,0,0,0,0,0,0,0,0,0,0,0,0,0,0,0,0,0,0,0
0,0,0,0,0,0,0,0,0,0,0,0,0,0,0,0,0,0,0,0,0,0,0
0,0,0,0,0,0,0,0,0,0,0,0,0,0,0,0,0,0,0,0,0,0,0
0,0,0,0,0,0,0,0,0,0,0,0,0,0,0,0,0,0,0,0,0,0,0
0,0,0,0,0,0,0,0,0,0,0,0,0,0,0,0,0,0,0,0,0,0,0
0,0,0,0,0,0,0,0,0,0,0,0,0,0,0,0,0,0,0,0,0,0,0
0,0,0,0,0,0,0,0,0,0,0,0,0,0,0,0,0,0,0,0,0,0,0
0,0,0,0,0,0,0,0,0,0,0,0,0,0,0,0,0,0,0,0,0,0,0
0,0,0,0,0,0,0,0,0,0,0,0,0,0,0,0,0,0,0,0,0,0,0
0,0,0,0,0,0,0,0,0,0,0,0,0,0,0,0,0,0,0,0,0,0,0
0,0,0,0,0,0,0,0,0,0,0,0,0,0,0,0,0,0,0,0,0,0,0
0,0,0,0,0,0,0,0,0,0,0,0,0,0,0,0,0,0,0,0,0,0,0
0,0,0,0,0,0,0,0,0,0,0,0,0,0,0,0,0,0,0,0,0,0,0
0,0,0,0,0,0,0,0,0,0,0,0,0,0,0,0,0,0,0,0,0,0,0
0,0,0,0,0,0,0,0,0,0,0,0,0,0,0,0,0,0,0,0,0,0,0
:endlayer
layer: 23
0,0,0,0,0,0,0,0,0,0,0,0,0,0,0,0,0,0,0,0,0,0,0
0,0,0,0,0,0,0,0,0,0,0,0,0,0,0,0,0,0,0,0,0,0,0
0,0,0,0,0,0,0,0,0,0,11,44,11,0,0,0,0,0,0,0,0,0,0
0,0,0,0,0,0,0,0,0,0,24,3,25,0,0,0,0,0,0,0,0,0,0
0,0,0,0,0,0,0,0,0,0,11,10,11,0,0,0,0,0,0,0,0,0,0
0,0,0,0,0,0,0,0,0,0,0,0,0,0,0,0,0,0,0,0,0,0,0
0,0,0,0,0,0,0,0,0,0,0,0,0,0,0,0,0,0,0,0,0,0,0
0,0,0,0,0,0,0,0,0,0,0,0,0,0,0,0,0,0,0,0,0,0,0
0,0,0,0,0,0,0,0,0,0,0,0,0,0,0,0,0,0,0,0,0,0,0
0,0,0,0,0,0,0,0,0,0,0,0,0,0,0,0,0,0,0,0,0,0,0
0,0,0,0,0,0,0,0,0,0,0,0,0,0,0,0,0,0,0,0,0,0,0
0,0,0,0,0,0,0,0,0,0,0,0,0,0,0,0,0,0,0,0,0,0,0
0,0,0,0,0,0,0,0,0,0,0,0,0,0,0,0,0,0,0,0,0,0,0
0,0,0,0,0,0,0,0,0,0,0,0,0,0,0,0,0,0,0,0,0,0,0
0,0,0,0,0,0,0,0,0,0,0,0,0,0,0,0,0,0,0,0,0,0,0
0,0,0,0,0,0,0,0,0,0,0,0,0,0,0,0,0,0,0,0,0,0,0
0,0,0,0,0,0,0,0,0,0,0,0,0,0,0,0,0,0,0,0,0,0,0
0,0,0,0,0,0,0,0,0,0,0,0,0,0,0,0,0,0,0,0,0,0,0
0,0,0,0,0,0,0,0,0,0,0,0,0,0,0,0,0,0,0,0,0,0,0
0,0,0,0,0,0,0,0,0,0,0,0,0,0,0,0,0,0,0,0,0,0,0
0,0,0,0,0,0,0,0,0,0,0,0,0,0,0,0,0,0,0,0,0,0,0
:endlayer
layer: 24
0,0,0,0,0,0,0,0,0,0,0,0,0,0,0,0,0,0,0,0,0,0,0
0,0,0,0,0,0,0,0,0,0,0,0,0,0,0,0,0,0,0,0,0,0,0
0,0,0,0,0,0,0,0,0,0,0,0,0,0,0,0,0,0,0,0,0,0,0
0,0,0,0,0,0,0,0,0,0,0,3,0,0,0,0,0,0,0,0,0,0,0
0,0,0,0,0,0,0,0,0,0,0,0,0,0,0,0,0,0,0,0,0,0,0
0,0,0,0,0,0,0,0,0,0,0,0,0,0,0,0,0,0,0,0,0,0,0
0,0,0,0,0,0,0,0,0,0,0,0,0,0,0,0,0,0,0,0,0,0,0
0,0,0,0,0,0,0,0,0,0,0,0,0,0,0,0,0,0,0,0,0,0,0
0,0,0,0,0,0,0,0,0,0,0,0,0,0,0,0,0,0,0,0,0,0,0
0,0,0,0,0,0,0,0,0,0,0,0,0,0,0,0,0,0,0,0,0,0,0
0,0,0,0,0,0,0,0,0,0,0,0,0,0,0,0,0,0,0,0,0,0,0
0,0,0,0,0,0,0,0,0,0,0,0,0,0,0,0,0,0,0,0,0,0,0
0,0,0,0,0,0,0,0,0,0,0,0,0,0,0,0,0,0,0,0,0,0,0
0,0,0,0,0,0,0,0,0,0,0,0,0,0,0,0,0,0,0,0,0,0,0
0,0,0,0,0,0,0,0,0,0,0,0,0,0,0,0,0,0,0,0,0,0,0
0,0,0,0,0,0,0,0,0,0,0,0,0,0,0,0,0,0,0,0,0,0,0
0,0,0,0,0,0,0,0,0,0,0,0,0,0,0,0,0,0,0,0,0,0,0
0,0,0,0,0,0,0,0,0,0,0,0,0,0,0,0,0,0,0,0,0,0,0
0,0,0,0,0,0,0,0,0,0,0,0,0,0,0,0,0,0,0,0,0,0,0
0,0,0,0,0,0,0,0,0,0,0,0,0,0,0,0,0,0,0,0,0,0,0
0,0,0,0,0,0,0,0,0,0,0,0,0,0,0,0,0,0,0,0,0,0,0
:endlayer
layer: 25
0,0,0,0,0,0,0,0,0,0,0,0,0,0,0,0,0,0,0,0,0,0,0
0,0,0,0,0,0,0,0,0,0,0,0,0,0,0,0,0,0,0,0,0,0,0
0,0,0,0,0,0,0,0,0,0,0,0,0,0,0,0,0,0,0,0,0,0,0
0,0,0,0,0,0,0,0,0,0,0,3,0,0,0,0,0,0,0,0,0,0,0
0,0,0,0,0,0,0,0,0,0,0,0,0,0,0,0,0,0,0,0,0,0,0
0,0,0,0,0,0,0,0,0,0,0,0,0,0,0,0,0,0,0,0,0,0,0
0,0,0,0,0,0,0,0,0,0,0,0,0,0,0,0,0,0,0,0,0,0,0
0,0,0,0,0,0,0,0,0,0,0,0,0,0,0,0,0,0,0,0,0,0,0
0,0,0,0,0,0,0,0,0,0,0,0,0,0,0,0,0,0,0,0,0,0,0
0,0,0,0,0,0,0,0,0,0,0,0,0,0,0,0,0,0,0,0,0,0,0
0,0,0,0,0,0,0,0,0,0,0,0,0,0,0,0,0,0,0,0,0,0,0
0,0,0,0,0,0,0,0,0,0,0,0,0,0,0,0,0,0,0,0,0,0,0
0,0,0,0,0,0,0,0,0,0,0,0,0,0,0,0,0,0,0,0,0,0,0
0,0,0,0,0,0,0,0,0,0,0,0,0,0,0,0,0,0,0,0,0,0,0
0,0,0,0,0,0,0,0,0,0,0,0,0,0,0,0,0,0,0,0,0,0,0
0,0,0,0,0,0,0,0,0,0,0,0,0,0,0,0,0,0,0,0,0,0,0
0,0,0,0,0,0,0,0,0,0,0,0,0,0,0,0,0,0,0,0,0,0,0
0,0,0,0,0,0,0,0,0,0,0,0,0,0,0,0,0,0,0,0,0,0,0
0,0,0,0,0,0,0,0,0,0,0,0,0,0,0,0,0,0,0,0,0,0,0
0,0,0,0,0,0,0,0,0,0,0,0,0,0,0,0,0,0,0,0,0,0,0
0,0,0,0,0,0,0,0,0,0,0,0,0,0,0,0,0,0,0,0,0,0,0
:endlayer
layer: 26
0,0,0,0,0,0,0,0,0,0,0,0,0,0,0,0,0,0,0,0,0,0,0
0,0,0,0,0,0,0,0,0,0,0,0,0,0,0,0,0,0,0,0,0,0,0
0,0,0,0,0,0,0,0,0,0,0,0,0,0,0,0,0,0,0,0,0,0,0
0,0,0,0,0,0,0,0,0,0,0,3,0,0,0,0,0,0,0,0,0,0,0
0,0,0,0,0,0,0,0,0,0,0,0,0,0,0,0,0,0,0,0,0,0,0
0,0,0,0,0,0,0,0,0,0,0,0,0,0,0,0,0,0,0,0,0,0,0
0,0,0,0,0,0,0,0,0,0,0,0,0,0,0,0,0,0,0,0,0,0,0
0,0,0,0,0,0,0,0,0,0,0,0,0,0,0,0,0,0,0,0,0,0,0
0,0,0,0,0,0,0,0,0,0,0,0,0,0,0,0,0,0,0,0,0,0,0
0,0,0,0,0,0,0,0,0,0,0,0,0,0,0,0,0,0,0,0,0,0,0
0,0,0,0,0,0,0,0,0,0,0,0,0,0,0,0,0,0,0,0,0,0,0
0,0,0,0,0,0,0,0,0,0,0,0,0,0,0,0,0,0,0,0,0,0,0
0,0,0,0,0,0,0,0,0,0,0,0,0,0,0,0,0,0,0,0,0,0,0
0,0,0,0,0,0,0,0,0,0,0,0,0,0,0,0,0,0,0,0,0,0,0
0,0,0,0,0,0,0,0,0,0,0,0,0,0,0,0,0,0,0,0,0,0,0
0,0,0,0,0,0,0,0,0,0,0,0,0,0,0,0,0,0,0,0,0,0,0
0,0,0,0,0,0,0,0,0,0,0,0,0,0,0,0,0,0,0,0,0,0,0
0,0,0,0,0,0,0,0,0,0,0,0,0,0,0,0,0,0,0,0,0,0,0
0,0,0,0,0,0,0,0,0,0,0,0,0,0,0,0,0,0,0,0,0,0,0
0,0,0,0,0,0,0,0,0,0,0,0,0,0,0,0,0,0,0,0,0,0,0
0,0,0,0,0,0,0,0,0,0,0,0,0,0,0,0,0,0,0,0,0,0,0
:endlayer
layer: 27
0,0,0,0,0,0,0,0,0,0,0,0,0,0,0,0,0,0,0,0,0,0,0
0,0,0,0,0,0,0,0,0,0,0,0,0,0,0,0,0,0,0,0,0,0,0
0,0,0,0,0,0,0,0,0,0,0,0,0,0,0,0,0,0,0,0,0,0,0
0,0,0,0,0,0,0,0,0,0,0,3,0,0,0,0,0,0,0,0,0,0,0
0,0,0,0,0,0,0,0,0,0,0,0,0,0,0,0,0,0,0,0,0,0,0
0,0,0,0,0,0,0,0,0,0,0,0,0,0,0,0,0,0,0,0,0,0,0
0,0,0,0,0,0,0,0,0,0,0,0,0,0,0,0,0,0,0,0,0,0,0
0,0,0,0,0,0,0,0,0,0,0,0,0,0,0,0,0,0,0,0,0,0,0
0,0,0,0,0,0,0,0,0,0,0,0,0,0,0,0,0,0,0,0,0,0,0
0,0,0,0,0,0,0,0,0,0,0,0,0,0,0,0,0,0,0,0,0,0,0
0,0,0,0,0,0,0,0,0,0,0,0,0,0,0,0,0,0,0,0,0,0,0
0,0,0,0,0,0,0,0,0,0,0,0,0,0,0,0,0,0,0,0,0,0,0
0,0,0,0,0,0,0,0,0,0,0,0,0,0,0,0,0,0,0,0,0,0,0
0,0,0,0,0,0,0,0,0,0,0,0,0,0,0,0,0,0,0,0,0,0,0
0,0,0,0,0,0,0,0,0,0,0,0,0,0,0,0,0,0,0,0,0,0,0
0,0,0,0,0,0,0,0,0,0,0,0,0,0,0,0,0,0,0,0,0,0,0
0,0,0,0,0,0,0,0,0,0,0,0,0,0,0,0,0,0,0,0,0,0,0
0,0,0,0,0,0,0,0,0,0,0,0,0,0,0,0,0,0,0,0,0,0,0
0,0,0,0,0,0,0,0,0,0,0,0,0,0,0,0,0,0,0,0,0,0,0
0,0,0,0,0,0,0,0,0,0,0,0,0,0,0,0,0,0,0,0,0,0,0
0,0,0,0,0,0,0,0,0,0,0,0,0,0,0,0,0,0,0,0,0,0,0
:endlayer
layer: 28
0,0,0,0,0,0,0,0,0,0,0,0,0,0,0,0,0,0,0,0,0,0,0
0,0,0,0,0,0,0,0,0,0,0,0,0,0,0,0,0,0,0,0,0,0,0
0,0,0,0,0,0,0,0,0,0,0,0,0,0,0,0,0,0,0,0,0,0,0
0,0,0,0,0,0,0,0,0,0,0,0,0,0,0,0,0,0,0,0,0,0,0
0,0,0,0,0,0,0,0,0,0,0,0,0,0,0,0,0,0,0,0,0,0,0
0,0,0,0,0,0,0,0,0,0,0,0,0,0,0,0,0,0,0,0,0,0,0
0,0,0,0,0,0,0,0,0,0,0,0,0,0,0,0,0,0,0,0,0,0,0
0,0,0,0,0,0,0,0,0,0,0,0,0,0,0,0,0,0,0,0,0,0,0
0,0,0,0,0,0,0,0,0,0,0,0,0,0,0,0,0,0,0,0,0,0,0
0,0,0,0,0,0,0,0,0,0,0,0,0,0,0,0,0,0,0,0,0,0,0
0,0,0,0,0,0,0,0,0,0,0,0,0,0,0,0,0,0,0,0,0,0,0
0,0,0,0,0,0,0,0,0,0,0,0,0,0,0,0,0,0,0,0,0,0,0
0,0,0,0,0,0,0,0,0,0,0,0,0,0,0,0,0,0,0,0,0,0,0
0,0,0,0,0,0,0,0,0,0,0,0,0,0,0,0,0,0,0,0,0,0,0
0,0,0,0,0,0,0,0,0,0,0,0,0,0,0,0,0,0,0,0,0,0,0
0,0,0,0,0,0,0,0,0,0,0,0,0,0,0,0,0,0,0,0,0,0,0
0,0,0,0,0,0,0,0,0,0,0,0,0,0,0,0,0,0,0,0,0,0,0
0,0,0,0,0,0,0,0,0,0,0,0,0,0,0,0,0,0,0,0,0,0,0
0,0,0,0,0,0,0,0,0,0,0,0,0,0,0,0,0,0,0,0,0,0,0
0,0,0,0,0,0,0,0,0,0,0,0,0,0,0,0,0,0,0,0,0,0,0
0,0,0,0,0,0,0,0,0,0,0,0,0,0,0,0,0,0,0,0,0,0,0
:endlayer
layer: 29
0,0,0,0,0,0,0,0,0,0,0,0,0,0,0,0,0,0,0,0,0,0,0
0,0,0,0,0,0,0,0,0,0,0,0,0,0,0,0,0,0,0,0,0,0,0
0,0,0,0,0,0,0,0,0,0,0,0,0,0,0,0,0,0,0,0,0,0,0
0,0,0,0,0,0,0,0,0,0,0,0,0,0,0,0,0,0,0,0,0,0,0
0,0,0,0,0,0,0,0,0,0,0,0,0,0,0,0,0,0,0,0,0,0,0
0,0,0,0,0,0,0,0,0,0,0,0,0,0,0,0,0,0,0,0,0,0,0
0,0,0,0,0,0,0,0,0,0,0,0,0,0,0,0,0,0,0,0,0,0,0
0,0,0,0,0,0,0,0,0,0,0,0,0,0,0,0,0,0,0,0,0,0,0
0,0,0,0,0,0,0,0,0,0,0,0,0,0,0,0,0,0,0,0,0,0,0
0,0,0,0,0,0,0,0,0,0,0,0,0,0,0,0,0,0,0,0,0,0,0
0,0,0,0,0,0,0,0,0,0,0,0,0,0,0,0,0,0,0,0,0,0,0
0,0,0,0,0,0,0,0,0,0,0,0,0,0,0,0,0,0,0,0,0,0,0
0,0,0,0,0,0,0,0,0,0,0,0,0,0,0,0,0,0,0,0,0,0,0
0,0,0,0,0,0,0,0,0,0,0,0,0,0,0,0,0,0,0,0,0,0,0
0,0,0,0,0,0,0,0,0,0,0,0,0,0,0,0,0,0,0,0,0,0,0
0,0,0,0,0,0,0,0,0,0,0,0,0,0,0,0,0,0,0,0,0,0,0
0,0,0,0,0,0,0,0,0,0,0,0,0,0,0,0,0,0,0,0,0,0,0
0,0,0,0,0,0,0,0,0,0,0,0,0,0,0,0,0,0,0,0,0,0,0
0,0,0,0,0,0,0,0,0,0,0,0,0,0,0,0,0,0,0,0,0,0,0
0,0,0,0,0,0,0,0,0,0,0,0,0,0,0,0,0,0,0,0,0,0,0
0,0,0,0,0,0,0,0,0,0,0,0,0,0,0,0,0,0,0,0,0,0,0
:endlayer
layer: 30
0,0,0,0,0,0,0,0,0,0,0,0,0,0,0,0,0,0,0,0,0,0,0
0,0,0,0,0,0,0,0,0,0,0,0,0,0,0,0,0,0,0,0,0,0,0
0,0,0,0,0,0,0,0,0,0,0,0,0,0,0,0,0,0,0,0,0,0,0
0,0,0,0,0,0,0,0,0,0,0,0,0,0,0,0,0,0,0,0,0,0,0
0,0,0,0,0,0,0,0,0,0,0,0,0,0,0,0,0,0,0,0,0,0,0
0,0,0,0,0,0,0,0,0,0,0,0,0,0,0,0,0,0,0,0,0,0,0
0,0,0,0,0,0,0,0,0,0,0,0,0,0,0,0,0,0,0,0,0,0,0
0,0,0,0,0,0,0,0,0,0,0,0,0,0,0,0,0,0,0,0,0,0,0
0,0,0,0,0,0,0,0,0,0,0,0,0,0,0,0,0,0,0,0,0,0,0
0,0,0,0,0,0,0,0,0,0,0,0,0,0,0,0,0,0,0,0,0,0,0
0,0,0,0,0,0,0,0,0,0,0,0,0,0,0,0,0,0,0,0,0,0,0
0,0,0,0,0,0,0,0,0,0,0,0,0,0,0,0,0,0,0,0,0,0,0
0,0,0,0,0,0,0,0,0,0,0,0,0,0,0,0,0,0,0,0,0,0,0
0,0,0,0,0,0,0,0,0,0,0,0,0,0,0,0,0,0,0,0,0,0,0
0,0,0,0,0,0,0,0,0,0,0,0,0,0,0,0,0,0,0,0,0,0,0
0,0,0,0,0,0,0,0,0,0,0,0,0,0,0,0,0,0,0,0,0,0,0
0,0,0,0,0,0,0,0,0,0,0,0,0,0,0,0,0,0,0,0,0,0,0
0,0,0,0,0,0,0,0,0,0,0,0,0,0,0,0,0,0,0,0,0,0,0
0,0,0,0,0,0,0,0,0,0,0,0,0,0,0,0,0,0,0,0,0,0,0
0,0,0,0,0,0,0,0,0,0,0,0,0,0,0,0,0,0,0,0,0,0,0
0,0,0,0,0,0,0,0,0,0,0,0,0,0,0,0,0,0,0,0,0,0,0
:endlayer
layer: 31
0,0,0,0,0,0,0,0,0,0,0,0,0,0,0,0,0,0,0,0,0,0,0
0,0,0,0,0,0,0,0,0,0,0,0,0,0,0,0,0,0,0,0,0,0,0
0,0,0,0,0,0,0,0,0,0,0,0,0,0,0,0,0,0,0,0,0,0,0
0,0,0,0,0,0,0,0,0,0,0,0,0,0,0,0,0,0,0,0,0,0,0
0,0,0,0,0,0,0,0,0,0,0,0,0,0,0,0,0,0,0,0,0,0,0
0,0,0,0,0,0,0,0,0,0,0,0,0,0,0,0,0,0,0,0,0,0,0
0,0,0,0,0,0,0,0,0,0,0,0,0,0,0,0,0,0,0,0,0,0,0
0,0,0,0,0,0,0,0,0,0,0,0,0,0,0,0,0,0,0,0,0,0,0
0,0,0,0,0,0,0,0,0,0,0,0,0,0,0,0,0,0,0,0,0,0,0
0,0,0,0,0,0,0,0,0,0,0,0,0,0,0,0,0,0,0,0,0,0,0
0,0,0,0,0,0,0,0,0,0,0,0,0,0,0,0,0,0,0,0,0,0,0
0,0,0,0,0,0,0,0,0,0,0,0,0,0,0,0,0,0,0,0,0,0,0
0,0,0,0,0,0,0,0,0,0,0,0,0,0,0,0,0,0,0,0,0,0,0
0,0,0,0,0,0,0,0,0,0,0,0,0,0,0,0,0,0,0,0,0,0,0
0,0,0,0,0,0,0,0,0,0,0,0,0,0,0,0,0,0,0,0,0,0,0
0,0,0,0,0,0,0,0,0,0,0,0,0,0,0,0,0,0,0,0,0,0,0
0,0,0,0,0,0,0,0,0,0,0,0,0,0,0,0,0,0,0,0,0,0,0
0,0,0,0,0,0,0,0,0,0,0,0,0,0,0,0,0,0,0,0,0,0,0
0,0,0,0,0,0,0,0,0,0,0,0,0,0,0,0,0,0,0,0,0,0,0
0,0,0,0,0,0,0,0,0,0,0,0,0,0,0,0,0,0,0,0,0,0,0
0,0,0,0,0,0,0,0,0,0,0,0,0,0,0,0,0,0,0,0,0,0,0
:endlayer
layer: 32
0,0,0,0,0,0,0,0,0,0,0,0,0,0,0,0,0,0,0,0,0,0,0
0,0,0,0,0,0,0,0,0,0,0,0,0,0,0,0,0,0,0,0,0,0,0
0,0,0,0,0,0,0,0,0,0,0,0,0,0,0,0,0,0,0,0,0,0,0
0,0,0,0,0,0,0,0,0,0,0,0,0,0,0,0,0,0,0,0,0,0,0
0,0,0,0,0,0,0,0,0,0,0,0,0,0,0,0,0,0,0,0,0,0,0
0,0,0,0,0,0,0,0,0,0,0,0,0,0,0,0,0,0,0,0,0,0,0
0,0,0,0,0,0,0,0,0,0,0,0,0,0,0,0,0,0,0,0,0,0,0
0,0,0,0,0,0,0,0,0,0,0,0,0,0,0,0,0,0,0,0,0,0,0
0,0,0,0,0,0,0,0,0,0,0,0,0,0,0,0,0,0,0,0,0,0,0
0,0,0,0,0,0,0,0,0,0,0,0,0,0,0,0,0,0,0,0,0,0,0
0,0,0,0,0,0,0,0,0,0,0,0,0,0,0,0,0,0,0,0,0,0,0
0,0,0,0,0,0,0,0,0,0,0,0,0,0,0,0,0,0,0,0,0,0,0
0,0,0,0,0,0,0,0,0,0,0,0,0,0,0,0,0,0,0,0,0,0,0
0,0,0,0,0,0,0,0,0,0,0,0,0,0,0,0,0,0,0,0,0,0,0
0,0,0,0,0,0,0,0,0,0,0,0,0,0,0,0,0,0,0,0,0,0,0
0,0,0,0,0,0,0,0,0,0,0,0,0,0,0,0,0,0,0,0,0,0,0
0,0,0,0,0,0,0,0,0,0,0,0,0,0,0,0,0,0,0,0,0,0,0
0,0,0,0,0,0,0,0,0,0,0,0,0,0,0,0,0,0,0,0,0,0,0
0,0,0,0,0,0,0,0,0,0,0,0,0,0,0,0,0,0,0,0,0,0,0
0,0,0,0,0,0,0,0,0,0,0,0,0,0,0,0,0,0,0,0,0,0,0
0,0,0,0,0,0,0,0,0,0,0,0,0,0,0,0,0,0,0,0,0,0,0
:endlayer

#### RULES ####
rule:
plugin=vanillaBlocks
number=1
data:
JSON:{{"val":{"blockName":{"val":"minecraft:cobblestone","id":"ss"},"meta":{"val":"0","id":"pi"},"buildPass":{"val":"0","id":"pi"}},"id":"ct"}}
:enddata
:endrule

rule:
plugin=vanillaBlocks
number=2
data:
JSON:{{"val":{"blockName":{"val":"minecraft:gravel","id":"ss"},"meta":{"val":"0","id":"pi"},"buildPass":{"val":"0","id":"pi"}},"id":"ct"}}
:enddata
:endrule

rule:
plugin=vanillaBlocks
number=3
data:
JSON:{{"val":{"blockName":{"val":"minecraft:stonebrick","id":"ss"},"meta":{"val":"0","id":"pi"},"buildPass":{"val":"0","id":"pi"}},"id":"ct"}}
:enddata
:endrule

rule:
plugin=vanillaBlocks
number=4
data:
JSON:{{"val":{"blockName":{"val":"minecraft:stone_slab","id":"ss"},"meta":{"val":"2","id":"pi"},"buildPass":{"val":"0","id":"pi"}},"id":"ct"}}
:enddata
:endrule

rule:
plugin=vanillaBlocks
number=5
data:
JSON:{{"val":{"blockName":{"val":"minecraft:log","id":"ss"},"meta":{"val":"0","id":"pi"},"buildPass":{"val":"0","id":"pi"}},"id":"ct"}}
:enddata
:endrule

rule:
plugin=vanillaBlocks
number=6
data:
JSON:{{"val":{"blockName":{"val":"minecraft:planks","id":"ss"},"meta":{"val":"0","id":"pi"},"buildPass":{"val":"0","id":"pi"}},"id":"ct"}}
:enddata
:endrule

rule:
plugin=vanillaBlocks
number=7
data:
JSON:{{"val":{"blockName":{"val":"minecraft:netherrack","id":"ss"},"meta":{"val":"0","id":"pi"},"buildPass":{"val":"0","id":"pi"}},"id":"ct"}}
:enddata
:endrule

rule:
plugin=vanillaBlocks
number=8
data:
JSON:{{"val":{"blockName":{"val":"minecraft:wool","id":"ss"},"meta":{"val":"14","id":"pi"},"buildPass":{"val":"0","id":"pi"}},"id":"ct"}}
:enddata
:endrule

rule:
plugin=vanillaBlocks
number=9
data:
JSON:{{"val":{"blockName":{"val":"minecraft:fire","id":"ss"},"meta":{"val":"15","id":"pi"},"buildPass":{"val":"0","id":"pi"}},"id":"ct"}}
:enddata
:endrule

rule:
plugin=vanillaBlocks
number=10
data:
JSON:{{"val":{"blockName":{"val":"minecraft:stone_brick_stairs","id":"ss"},"meta":{"val":"2","id":"pi"},"buildPass":{"val":"0","id":"pi"}},"id":"ct"}}
:enddata
:endrule

rule:
plugin=vanillaBlocks
number=11
data:
JSON:{{"val":{"blockName":{"val":"minecraft:stone_slab","id":"ss"},"meta":{"val":"5","id":"pi"},"buildPass":{"val":"0","id":"pi"}},"id":"ct"}}
:enddata
:endrule

rule:
plugin=vanillaBlocks
number=12
data:
JSON:{{"val":{"blockName":{"val":"minecraft:double_wooden_slab","id":"ss"},"meta":{"val":"0","id":"pi"},"buildPass":{"val":"0","id":"pi"}},"id":"ct"}}
:enddata
:endrule

rule:
plugin=vanillaBlocks
number=13
data:
JSON:{{"val":{"blockName":{"val":"minecraft:oak_stairs","id":"ss"},"meta":{"val":"3","id":"pi"},"buildPass":{"val":"0","id":"pi"}},"id":"ct"}}
:enddata
:endrule

rule:
plugin=vanillaDoors
number=14
data:
JSON:{{"val":{"sideFlag":{"val":"11","id":"pb"},"blockName":{"val":"minecraft:wooden_door","id":"ss"},"meta":{"val":"3","id":"pi"},"buildPass":{"val":"2","id":"pi"}},"id":"ct"}}
:enddata
:endrule

rule:
plugin=vanillaBlocks
number=15
data:
JSON:{{"val":{"blockName":{"val":"minecraft:glass","id":"ss"},"meta":{"val":"0","id":"pi"},"buildPass":{"val":"0","id":"pi"}},"id":"ct"}}
:enddata
:endrule

rule:
plugin=vanillaDoors
number=16
data:
JSON:{{"val":{"sideFlag":{"val":"0","id":"pb"},"blockName":{"val":"minecraft:wooden_door","id":"ss"},"meta":{"val":"11","id":"pi"},"buildPass":{"val":"2","id":"pi"}},"id":"ct"}}
:enddata
:endrule

rule:
plugin=vanillaBlocks
number=17
data:
JSON:{{"val":{"blockName":{"val":"minecraft:torch","id":"ss"},"meta":{"val":"4","id":"pi"},"buildPass":{"val":"2","id":"pi"}},"id":"ct"}}
:enddata
:endrule

rule:
plugin=vanillaBlocks
number=18
data:
JSON:{{"val":{"blockName":{"val":"minecraft:torch","id":"ss"},"meta":{"val":"2","id":"pi"},"buildPass":{"val":"2","id":"pi"}},"id":"ct"}}
:enddata
:endrule

rule:
plugin=vanillaBlocks
number=19
data:
JSON:{{"val":{"blockName":{"val":"minecraft:torch","id":"ss"},"meta":{"val":"1","id":"pi"},"buildPass":{"val":"2","id":"pi"}},"id":"ct"}}
:enddata
:endrule

rule:
plugin=vanillaBlocks
number=20
data:
JSON:{{"val":{"blockName":{"val":"minecraft:wooden_slab","id":"ss"},"meta":{"val":"8","id":"pi"},"buildPass":{"val":"0","id":"pi"}},"id":"ct"}}
:enddata
:endrule

rule:
plugin=vanillaBlocks
number=21
data:
JSON:{{"val":{"blockName":{"val":"minecraft:torch","id":"ss"},"meta":{"val":"3","id":"pi"},"buildPass":{"val":"2","id":"pi"}},"id":"ct"}}
:enddata
:endrule

rule:
plugin=vanillaBlocks
number=22
data:
JSON:{{"val":{"blockName":{"val":"minecraft:oak_stairs","id":"ss"},"meta":{"val":"7","id":"pi"},"buildPass":{"val":"0","id":"pi"}},"id":"ct"}}
:enddata
:endrule

rule:
plugin=vanillaBlocks
number=23
data:
JSON:{{"val":{"blockName":{"val":"minecraft:fence","id":"ss"},"meta":{"val":"0","id":"pi"},"buildPass":{"val":"0","id":"pi"}},"id":"ct"}}
:enddata
:endrule

rule:
plugin=vanillaBlocks
number=24
data:
JSON:{{"val":{"blockName":{"val":"minecraft:stone_brick_stairs","id":"ss"},"meta":{"val":"1","id":"pi"},"buildPass":{"val":"0","id":"pi"}},"id":"ct"}}
:enddata
:endrule

rule:
plugin=vanillaBlocks
number=25
data:
JSON:{{"val":{"blockName":{"val":"minecraft:stone_brick_stairs","id":"ss"},"meta":{"val":"0","id":"pi"},"buildPass":{"val":"0","id":"pi"}},"id":"ct"}}
:enddata
:endrule

rule:
plugin=vanillaBlocks
number=26
data:
JSON:{{"val":{"blockName":{"val":"minecraft:glass_pane","id":"ss"},"meta":{"val":"0","id":"pi"},"buildPass":{"val":"0","id":"pi"}},"id":"ct"}}
:enddata
:endrule

rule:
plugin=vanillaBlocks
number=27
data:
JSON:{{"val":{"blockName":{"val":"minecraft:oak_stairs","id":"ss"},"meta":{"val":"0","id":"pi"},"buildPass":{"val":"0","id":"pi"}},"id":"ct"}}
:enddata
:endrule

rule:
plugin=vanillaBlocks
number=28
data:
JSON:{{"val":{"blockName":{"val":"minecraft:oak_stairs","id":"ss"},"meta":{"val":"5","id":"pi"},"buildPass":{"val":"0","id":"pi"}},"id":"ct"}}
:enddata
:endrule

rule:
plugin=vanillaBlocks
number=29
data:
JSON:{{"val":{"blockName":{"val":"minecraft:trapdoor","id":"ss"},"meta":{"val":"1","id":"pi"},"buildPass":{"val":"2","id":"pi"}},"id":"ct"}}
:enddata
:endrule

rule:
plugin=vanillaBlocks
number=30
data:
JSON:{{"val":{"blockName":{"val":"minecraft:oak_stairs","id":"ss"},"meta":{"val":"1","id":"pi"},"buildPass":{"val":"0","id":"pi"}},"id":"ct"}}
:enddata
:endrule

rule:
plugin=vanillaBlocks
number=31
data:
JSON:{{"val":{"blockName":{"val":"minecraft:trapdoor","id":"ss"},"meta":{"val":"0","id":"pi"},"buildPass":{"val":"2","id":"pi"}},"id":"ct"}}
:enddata
:endrule

rule:
plugin=vanillaBlocks
number=32
data:
JSON:{{"val":{"blockName":{"val":"minecraft:wooden_slab","id":"ss"},"meta":{"val":"0","id":"pi"},"buildPass":{"val":"0","id":"pi"}},"id":"ct"}}
:enddata
:endrule

rule:
plugin=vanillaDoors
number=33
data:
JSON:{{"val":{"sideFlag":{"val":"9","id":"pb"},"blockName":{"val":"minecraft:wooden_door","id":"ss"},"meta":{"val":"2","id":"pi"},"buildPass":{"val":"2","id":"pi"}},"id":"ct"}}
:enddata
:endrule

rule:
plugin=vanillaDoors
number=34
data:
JSON:{{"val":{"sideFlag":{"val":"8","id":"pb"},"blockName":{"val":"minecraft:wooden_door","id":"ss"},"meta":{"val":"0","id":"pi"},"buildPass":{"val":"2","id":"pi"}},"id":"ct"}}
:enddata
:endrule

rule:
plugin=vanillaDoors
number=35
data:
JSON:{{"val":{"sideFlag":{"val":"10","id":"pb"},"blockName":{"val":"minecraft:wooden_door","id":"ss"},"meta":{"val":"2","id":"pi"},"buildPass":{"val":"2","id":"pi"}},"id":"ct"}}
:enddata
:endrule

rule:
plugin=vanillaDoors
number=36
data:
JSON:{{"val":{"sideFlag":{"val":"9","id":"pb"},"blockName":{"val":"minecraft:wooden_door","id":"ss"},"meta":{"val":"0","id":"pi"},"buildPass":{"val":"2","id":"pi"}},"id":"ct"}}
:enddata
:endrule

rule:
plugin=vanillaDoors
number=37
data:
JSON:{{"val":{"sideFlag":{"val":"0","id":"pb"},"blockName":{"val":"minecraft:wooden_door","id":"ss"},"meta":{"val":"9","id":"pi"},"buildPass":{"val":"2","id":"pi"}},"id":"ct"}}
:enddata
:endrule

rule:
plugin=vanillaDoors
number=38
data:
JSON:{{"val":{"sideFlag":{"val":"0","id":"pb"},"blockName":{"val":"minecraft:wooden_door","id":"ss"},"meta":{"val":"8","id":"pi"},"buildPass":{"val":"2","id":"pi"}},"id":"ct"}}
:enddata
:endrule

rule:
plugin=vanillaDoors
number=39
data:
JSON:{{"val":{"sideFlag":{"val":"0","id":"pb"},"blockName":{"val":"minecraft:wooden_door","id":"ss"},"meta":{"val":"10","id":"pi"},"buildPass":{"val":"2","id":"pi"}},"id":"ct"}}
:enddata
:endrule

rule:
plugin=vanillaDoors
number=40
data:
JSON:{{"val":{"sideFlag":{"val":"0","id":"pb"},"blockName":{"val":"minecraft:wooden_door","id":"ss"},"meta":{"val":"9","id":"pi"},"buildPass":{"val":"2","id":"pi"}},"id":"ct"}}
:enddata
:endrule

rule:
plugin=vanillaBlocks
number=41
data:
JSON:{{"val":{"blockName":{"val":"minecraft:oak_stairs","id":"ss"},"meta":{"val":"2","id":"pi"},"buildPass":{"val":"0","id":"pi"}},"id":"ct"}}
:enddata
:endrule

rule:
plugin=vanillaBlocks
number=42
data:
JSON:{{"val":{"blockName":{"val":"minecraft:trapdoor","id":"ss"},"meta":{"val":"2","id":"pi"},"buildPass":{"val":"2","id":"pi"}},"id":"ct"}}
:enddata
:endrule

rule:
plugin=vanillaBlocks
number=43
data:
JSON:{{"val":{"blockName":{"val":"minecraft:trapdoor","id":"ss"},"meta":{"val":"3","id":"pi"},"buildPass":{"val":"2","id":"pi"}},"id":"ct"}}
:enddata
:endrule

rule:
plugin=vanillaBlocks
number=44
data:
JSON:{{"val":{"blockName":{"val":"minecraft:stone_brick_stairs","id":"ss"},"meta":{"val":"3","id":"pi"},"buildPass":{"val":"0","id":"pi"}},"id":"ct"}}
:enddata
:endrule

#### ENTITIES ####
