# Ancient Warfare Structure Template File
# Auto-generated structure template file. created on: 11/24/2014 at: 21:42:30
# Lines beginning with # denote comments

header:
version=2.1
name=TownBlocksGovernorsPalace
size=29,46,29
offset=14,4,28
:endheader

#### VALIDATION ####
validation:
type=ground
survival=false
worldGenEnabled=false
unique=false
preserveBlocks=false
selectionWeight=0
clusterValue=0
minDuplicateDistance=0
dimensionWhiteList=false
dimensionList=
biomeWhiteList=false
biomeList=
leveling=0
fill=0
border=0
validTargetBlocks=
blockSwap=false
data:
:enddata
:endvalidation

#### LAYERS ####
layer: 0
1,1,1,1,1,1,1,1,1,1,1,1,1,1,1,1,1,1,1,1,1,1,1,1,1,1,1,1,1
1,1,1,1,1,1,1,1,1,1,1,1,1,1,1,1,1,1,1,1,1,1,1,1,1,1,1,1,1
1,1,1,1,1,1,1,1,1,1,1,1,1,1,1,1,1,1,1,1,1,1,1,1,1,1,1,1,1
1,1,1,1,1,1,1,1,1,1,1,1,1,1,1,1,1,1,1,1,1,1,1,1,1,1,1,1,1
1,1,1,1,1,1,1,1,1,1,1,1,1,1,1,1,1,1,1,1,1,1,1,1,1,1,1,1,1
1,1,1,1,1,1,1,1,1,1,1,1,1,1,1,1,1,1,1,1,1,1,1,1,1,1,1,1,1
1,1,1,1,1,1,1,1,1,1,1,1,1,1,1,1,1,1,1,1,1,1,1,1,1,1,1,1,1
1,1,1,1,1,1,1,1,1,1,1,1,1,1,1,1,1,1,1,1,1,1,1,1,1,1,1,1,1
1,1,1,1,1,1,1,1,1,1,1,1,1,1,1,1,1,1,1,1,1,1,1,1,1,1,1,1,1
1,1,1,1,1,1,1,1,1,1,1,1,1,1,1,1,1,1,1,1,1,1,1,1,1,1,1,1,1
1,1,1,1,1,1,1,1,1,2,2,2,2,2,2,2,2,2,2,2,2,2,1,1,1,1,1,1,1
1,1,1,1,1,1,1,1,1,2,2,2,2,3,2,2,2,2,2,2,2,2,1,1,1,1,1,1,1
1,1,1,1,1,1,1,1,1,2,2,2,2,3,5,5,5,3,2,2,2,2,1,1,1,1,1,1,1
1,1,1,1,1,1,1,1,1,2,2,2,2,3,5,5,5,3,3,2,2,2,1,1,1,1,1,1,1
1,1,1,1,1,1,1,1,1,2,2,3,3,0,0,0,0,7,3,3,2,2,1,1,1,1,1,1,1
1,1,1,1,1,1,1,1,1,2,2,3,0,0,0,0,0,0,0,3,3,2,1,1,1,1,1,1,1
1,1,1,1,1,1,1,1,1,2,3,0,0,0,0,0,0,0,0,0,3,2,1,1,1,1,1,1,1
1,1,1,1,1,1,1,1,1,2,3,0,0,0,0,0,0,0,0,0,3,2,1,1,1,1,1,1,1
1,1,1,1,1,1,1,1,1,2,3,0,0,0,0,0,0,0,0,0,3,2,1,1,1,1,1,1,1
1,1,1,1,1,1,1,1,1,2,2,3,0,0,0,0,0,0,0,3,2,2,1,1,1,1,1,1,1
1,1,1,1,1,1,1,1,1,2,2,2,3,0,0,0,0,0,3,2,2,2,1,1,1,1,1,1,1
1,1,1,1,1,1,1,1,1,2,2,2,2,3,4,0,6,3,2,2,2,2,1,1,1,1,1,1,1
1,1,1,1,1,1,1,1,1,2,2,2,2,2,3,3,3,2,2,2,2,2,1,1,1,1,1,1,1
1,1,1,1,1,1,1,1,1,2,2,2,2,2,2,2,2,2,2,2,2,2,1,1,1,1,1,1,1
1,1,1,1,1,1,1,1,1,1,1,1,1,1,1,1,1,1,1,1,1,1,1,1,1,1,1,1,1
1,1,1,1,1,1,1,1,1,1,1,1,1,1,1,1,1,1,1,1,1,1,1,1,1,1,1,1,1
1,1,1,1,1,1,1,1,1,1,1,1,1,1,1,1,1,1,1,1,1,1,1,1,1,1,1,1,1
1,1,1,1,1,1,1,1,1,1,1,1,1,1,1,1,1,1,1,1,1,1,1,1,1,1,1,1,1
1,1,1,1,1,1,1,1,1,1,1,1,1,1,1,1,1,1,1,1,1,1,1,1,1,1,1,1,1
:endlayer
layer: 1
2,2,2,2,2,2,2,2,2,2,2,2,2,2,2,2,2,2,2,2,2,2,2,2,2,2,2,2,2
2,2,2,2,2,2,2,2,2,2,2,2,2,2,2,2,2,2,2,2,2,2,2,2,2,2,2,2,2
2,2,2,2,2,2,2,2,2,2,2,2,2,2,2,2,2,2,2,2,2,2,2,2,2,2,2,2,2
2,2,2,2,2,2,2,2,2,2,2,2,2,2,2,2,2,2,2,2,2,2,2,2,2,2,2,2,2
2,2,2,2,2,2,2,2,2,2,2,2,2,2,2,2,2,2,2,2,2,2,2,2,2,2,2,2,2
2,2,2,2,2,2,2,2,2,2,2,2,2,2,2,2,2,2,2,2,2,2,2,2,2,2,2,2,2
2,2,2,2,2,2,2,2,2,2,2,2,2,2,2,2,2,2,2,2,2,2,2,2,2,2,2,2,2
2,2,2,2,2,2,2,2,2,2,2,2,2,2,2,2,2,2,2,2,2,2,2,2,2,2,2,2,2
2,2,2,2,2,2,2,2,2,2,2,2,2,2,2,2,2,2,2,2,2,2,2,2,2,2,2,2,2
2,2,2,2,2,2,2,2,2,2,2,2,2,2,2,2,2,2,2,2,2,2,2,2,2,2,2,2,2
2,2,2,2,2,2,2,2,2,2,2,2,2,3,2,2,2,3,2,2,2,2,2,2,2,2,2,2,2
2,2,2,2,2,2,2,2,2,2,2,2,2,3,5,5,5,3,2,2,2,2,2,2,2,2,2,2,2
2,2,2,2,2,2,2,2,2,2,2,2,2,3,5,5,5,3,2,2,2,2,2,2,2,2,2,2,2
2,2,2,2,2,2,2,2,2,2,2,2,2,3,0,0,0,3,2,2,2,2,2,2,2,2,2,2,2
2,2,2,2,2,2,2,2,2,2,2,3,3,0,0,0,0,0,3,3,2,2,2,2,2,2,2,2,2
2,2,2,2,2,2,2,2,2,2,2,3,0,0,0,0,0,0,0,3,3,2,2,2,2,2,2,2,2
2,2,2,2,2,2,2,2,2,2,3,0,0,0,0,0,0,0,0,0,3,2,2,2,2,2,2,2,2
2,2,2,2,2,2,2,2,2,2,3,0,0,0,0,0,0,0,0,0,3,2,2,2,2,2,2,2,2
2,2,2,2,2,2,2,2,2,2,3,0,0,0,0,0,0,0,0,0,3,2,2,2,2,2,2,2,2
2,2,2,2,2,2,2,2,2,2,2,3,0,0,0,0,0,0,0,3,2,2,2,2,2,2,2,2,2
2,2,2,2,2,2,2,2,2,2,2,2,3,0,0,0,0,0,3,2,2,2,2,2,2,2,2,2,2
2,2,2,2,2,2,2,2,2,2,2,2,2,3,0,0,0,3,2,2,2,2,2,2,2,2,2,2,2
2,2,2,2,2,2,2,2,2,2,2,2,2,2,3,3,3,2,2,2,2,2,2,2,2,2,2,2,2
2,2,2,2,2,2,2,2,2,2,2,2,2,2,2,2,2,2,2,2,2,2,2,2,2,2,2,2,2
2,2,2,2,2,2,2,2,2,2,2,2,2,2,2,2,2,2,2,2,2,2,2,2,2,2,2,2,2
2,2,2,2,2,2,2,2,2,2,2,2,2,2,2,2,2,2,2,2,2,2,2,2,2,2,2,2,2
2,2,2,2,2,2,2,2,2,2,2,2,2,2,2,2,2,2,2,2,2,2,2,2,2,2,2,2,2
2,2,2,2,2,2,2,2,2,2,2,2,2,2,2,2,2,2,2,2,2,2,2,2,2,2,2,2,2
2,2,2,2,2,2,2,2,2,2,2,2,2,2,2,2,2,2,2,2,2,2,2,2,2,2,2,2,2
:endlayer
layer: 2
8,8,8,8,8,8,8,8,8,8,8,8,8,8,8,8,8,8,8,8,8,8,8,8,8,8,8,8,8
8,8,8,8,8,8,8,8,8,8,8,8,8,8,8,8,8,8,8,8,8,8,8,8,8,8,8,8,8
8,8,2,2,2,2,2,2,2,2,2,2,2,2,2,2,2,2,2,2,2,2,2,2,2,2,2,8,8
8,8,2,2,2,2,2,2,2,2,2,2,2,2,2,2,2,2,2,2,2,2,2,2,2,2,2,8,8
8,8,2,2,2,2,2,2,2,2,2,2,2,2,2,2,2,2,2,2,2,2,2,2,2,2,2,8,8
8,8,2,2,2,2,2,2,2,2,2,2,2,2,2,2,2,2,2,2,2,2,2,2,2,2,2,8,8
8,8,2,2,2,2,2,2,2,2,2,2,2,2,2,2,2,2,2,2,2,2,2,2,2,2,2,8,8
8,8,2,2,2,2,2,2,2,2,2,2,2,2,2,2,2,2,2,2,2,2,2,2,2,2,2,8,8
8,8,2,2,2,2,2,2,2,2,2,2,2,2,2,2,2,2,2,2,2,2,2,2,2,2,2,8,8
8,8,2,2,2,2,2,2,2,2,2,2,2,3,2,2,2,3,2,2,2,2,2,2,2,2,2,8,8
8,8,2,2,2,2,2,2,2,2,2,2,2,3,5,5,5,3,2,2,2,2,2,2,2,2,2,8,8
8,8,2,2,2,2,2,2,2,2,2,2,2,3,5,5,5,3,2,2,2,2,2,2,2,2,2,8,8
8,8,2,2,2,2,2,2,2,2,2,2,2,3,0,0,0,3,2,2,2,2,2,2,2,2,2,8,8
8,8,2,2,2,2,2,2,2,2,2,2,2,3,0,0,0,3,2,2,2,2,2,2,2,2,2,8,8
8,8,2,2,2,2,2,2,2,2,2,3,3,9,0,0,0,11,3,3,2,2,2,2,2,2,2,8,8
8,8,2,2,2,2,2,2,2,2,2,3,0,0,0,0,0,0,0,3,3,2,2,2,2,2,2,8,8
8,8,2,2,2,2,2,2,2,2,3,0,0,0,0,0,0,0,0,0,3,2,2,2,2,2,2,8,8
8,8,2,2,2,2,2,2,2,2,3,9,0,0,0,0,0,0,0,11,3,2,2,2,2,2,2,8,8
8,8,2,2,2,2,2,2,2,2,3,0,0,0,0,0,0,0,0,0,3,2,2,2,2,2,2,8,8
8,8,2,2,2,2,2,2,2,2,2,3,0,0,0,0,0,0,0,3,2,2,2,2,2,2,2,8,8
8,8,2,2,2,2,2,2,2,2,2,2,3,0,0,0,0,0,3,2,2,2,2,2,2,2,2,8,8
8,8,2,2,2,2,2,2,2,2,2,2,2,3,0,10,0,3,2,2,2,2,2,2,2,2,2,8,8
8,8,2,2,2,2,2,2,2,2,2,2,2,2,3,3,3,2,2,2,2,2,2,2,2,2,2,8,8
8,8,2,2,2,2,2,2,2,2,2,2,2,2,2,2,2,2,2,2,2,2,2,2,2,2,2,8,8
8,8,2,2,2,2,2,2,2,2,2,2,2,2,2,2,2,2,2,2,2,2,2,2,2,2,2,8,8
8,8,2,2,2,2,2,2,2,2,2,2,2,2,2,2,2,2,2,2,2,2,2,2,2,2,2,8,8
8,8,2,2,2,2,2,8,8,8,8,8,8,8,8,8,8,8,8,8,8,8,2,2,2,2,2,8,8
8,8,8,8,8,8,8,8,8,8,8,8,8,8,8,8,8,8,8,8,8,8,8,8,8,8,8,8,8
8,8,8,8,8,8,8,8,8,8,8,8,8,8,8,8,8,8,8,8,8,8,8,8,8,8,8,8,8
:endlayer
layer: 3
8,8,8,8,8,8,8,8,8,8,8,8,8,8,8,8,8,8,8,8,8,8,8,8,8,8,8,8,8
8,8,8,8,8,8,8,8,8,8,8,8,8,8,8,8,8,8,8,8,8,8,8,8,8,8,8,8,8
8,8,2,2,2,2,2,8,8,8,8,8,8,8,8,8,8,8,8,8,8,8,2,2,2,2,2,8,8
8,8,2,2,2,2,2,2,2,2,2,2,2,2,2,2,2,2,2,2,2,2,2,2,2,2,2,8,8
8,8,2,2,2,2,2,2,2,2,2,2,2,2,2,2,2,2,2,2,2,2,2,2,2,2,2,8,8
8,8,2,2,2,2,2,2,2,2,2,2,2,2,2,2,2,2,2,2,2,2,2,2,2,2,2,8,8
8,8,2,2,2,2,2,2,2,2,2,2,2,2,2,2,2,2,2,2,2,2,2,2,2,2,2,8,8
8,8,8,2,2,2,2,2,2,2,2,2,2,2,2,2,2,2,2,2,2,2,2,2,2,2,8,8,8
8,8,8,2,2,2,2,2,2,2,2,2,2,3,2,2,2,3,2,2,2,2,2,2,2,2,8,8,8
8,8,8,2,2,2,2,2,2,2,2,2,2,3,5,5,5,3,2,2,2,2,2,2,2,2,8,8,8
8,8,8,2,2,2,2,2,2,2,2,2,2,3,5,5,5,3,2,2,2,2,2,2,2,2,8,8,8
8,8,8,2,2,2,2,2,2,2,2,2,2,3,0,0,0,3,2,2,2,2,2,2,2,2,8,8,8
8,8,8,2,2,2,2,2,2,2,2,2,2,3,0,0,0,3,2,2,2,2,2,2,2,2,8,8,8
8,8,8,2,2,2,2,2,2,2,2,2,2,3,0,0,0,3,2,2,2,2,2,2,2,2,8,8,8
8,8,8,2,2,2,2,2,2,2,2,3,3,3,12,12,12,3,3,3,2,2,2,2,2,2,8,8,8
8,8,8,2,2,2,2,2,2,2,2,3,3,3,3,3,3,3,3,3,3,2,2,2,2,2,8,8,8
8,8,8,2,2,2,2,2,2,2,3,3,3,3,3,3,3,3,3,3,3,2,2,2,2,2,8,8,8
8,8,8,2,2,2,2,2,2,2,3,3,3,3,3,3,3,3,3,3,3,2,2,2,2,2,8,8,8
8,8,8,2,2,2,2,2,2,2,3,3,3,3,3,3,3,3,3,3,3,2,2,2,2,2,8,8,8
8,8,8,2,2,2,2,2,2,2,2,3,3,3,3,3,3,3,3,3,2,2,2,2,2,2,8,8,8
8,8,8,2,2,2,2,2,2,2,2,2,3,3,3,3,3,3,3,2,2,2,2,2,2,2,8,8,8
8,8,8,2,2,2,2,2,2,2,2,2,2,3,3,3,3,3,2,2,2,2,2,2,2,2,8,8,8
8,8,2,2,2,2,2,2,2,2,2,2,2,2,3,3,3,2,2,2,2,2,2,2,2,2,2,8,8
8,8,2,2,2,2,2,2,2,2,2,2,2,2,2,2,2,2,2,2,2,2,2,2,2,2,2,8,8
8,8,2,2,2,2,2,2,2,2,2,2,2,2,2,2,2,2,2,2,2,2,2,2,2,2,2,8,8
8,8,2,2,2,2,2,2,2,2,2,2,2,2,2,2,2,2,2,2,2,2,2,2,2,2,2,8,8
8,8,2,2,2,2,2,8,8,8,8,8,8,8,8,8,8,8,8,8,8,8,2,2,2,2,2,8,8
8,8,8,8,8,8,8,8,8,8,8,8,8,8,8,8,8,8,8,8,8,8,8,8,8,8,8,8,8
8,8,8,8,8,8,8,8,8,8,8,8,8,8,8,8,8,8,8,8,8,8,8,8,8,8,8,8,8
:endlayer
layer: 4
8,8,8,8,8,8,8,8,8,8,8,8,8,8,8,8,8,8,8,8,8,8,8,8,8,8,8,8,8
8,8,8,8,8,8,8,8,8,8,8,8,8,8,8,8,8,8,8,8,8,8,8,8,8,8,8,8,8
8,8,3,3,3,3,3,8,8,8,8,8,8,8,8,8,8,8,8,8,8,8,3,3,3,3,3,8,8
8,8,3,3,3,3,3,8,8,8,8,8,8,8,8,8,8,8,8,8,8,8,3,3,3,3,3,8,8
8,8,3,3,3,3,3,3,3,3,3,3,3,3,3,3,3,3,3,3,3,3,3,3,3,3,3,8,8
8,8,3,3,3,3,3,3,3,3,3,3,3,3,3,3,3,3,3,3,3,3,3,3,3,3,3,8,8
8,8,3,3,3,3,3,3,3,3,3,3,3,3,3,3,3,3,3,3,3,3,3,3,3,3,3,8,8
8,8,8,8,3,3,3,3,3,3,3,3,3,3,3,3,3,3,3,3,3,3,3,3,3,8,8,8,8
8,8,8,8,3,3,3,3,3,3,3,3,3,3,3,3,3,3,3,3,3,3,3,3,3,8,8,8,8
8,8,8,8,3,3,3,3,3,3,3,3,3,3,5,5,5,3,3,3,3,3,3,3,3,8,8,8,8
8,8,8,8,3,3,3,3,3,3,3,3,3,3,0,0,0,3,3,3,3,3,3,3,3,8,8,8,8
8,8,8,8,3,3,3,3,3,3,3,3,3,3,0,0,0,3,3,3,3,3,3,3,3,8,8,8,8
8,8,8,8,3,3,3,3,3,3,3,3,3,3,0,0,0,3,3,3,3,3,3,3,3,8,8,8,8
8,8,8,8,3,3,3,3,3,3,3,3,3,3,3,3,3,3,3,3,3,3,3,3,3,8,8,8,8
8,8,8,8,3,3,3,3,3,3,3,3,3,3,3,3,3,3,3,3,3,3,3,3,3,8,8,8,8
8,8,8,8,3,3,3,3,3,3,3,3,3,3,3,3,3,3,3,3,3,3,3,3,3,8,8,8,8
8,8,8,8,3,3,3,3,3,3,3,3,3,3,3,3,3,3,3,3,3,3,3,3,3,8,8,8,8
8,8,8,8,3,3,3,3,3,3,3,3,3,3,3,3,3,3,3,3,3,3,3,3,3,8,8,8,8
8,8,8,8,3,3,3,3,3,3,3,3,3,3,3,3,3,3,3,3,3,3,3,3,3,8,8,8,8
8,8,8,8,3,3,3,3,3,3,3,3,3,3,3,3,3,3,3,3,3,3,3,3,3,8,8,8,8
8,8,8,8,3,3,3,3,3,3,3,3,3,3,3,3,3,3,3,3,3,3,3,3,3,8,8,8,8
8,8,8,8,3,3,3,3,3,3,3,3,3,3,3,3,3,3,3,3,3,3,3,3,3,8,8,8,8
8,8,3,3,3,3,3,3,3,3,3,3,3,3,3,3,3,3,3,3,3,3,3,3,3,3,3,8,8
8,8,3,3,3,3,3,3,3,3,3,3,3,3,3,3,3,3,3,3,3,3,3,3,3,3,3,8,8
8,8,3,3,3,3,3,3,3,3,3,3,3,3,3,3,3,3,3,3,3,3,3,3,3,3,3,8,8
8,8,3,3,3,3,3,8,8,8,8,8,2,2,2,2,2,8,8,8,8,8,3,3,3,3,3,8,8
8,8,3,3,3,3,3,8,8,8,8,8,8,8,8,8,8,8,8,8,8,8,3,3,3,3,3,8,8
8,8,8,8,8,8,8,8,8,8,8,8,8,8,8,8,8,8,8,8,8,8,8,8,8,8,8,8,8
8,8,8,8,8,8,8,8,8,8,8,8,8,8,8,8,8,8,8,8,8,8,8,8,8,8,8,8,8
:endlayer
layer: 5
0,0,0,0,0,0,0,0,0,0,0,0,0,0,0,0,0,0,0,0,0,0,0,0,0,0,0,0,0
0,0,0,0,0,0,0,0,0,0,0,0,0,0,0,0,0,0,0,0,0,0,0,0,0,0,0,0,0
0,0,3,3,3,3,3,0,0,0,0,0,0,0,0,0,0,0,0,0,0,0,3,3,3,3,3,0,0
0,0,3,3,3,3,3,0,0,0,0,0,0,0,0,0,0,0,0,0,0,0,3,3,3,3,3,0,0
0,0,3,0,3,5,3,3,3,3,3,3,3,3,3,3,3,3,3,3,3,3,3,5,3,0,3,0,0
0,0,3,0,0,0,3,3,3,3,3,3,13,0,0,0,0,0,3,0,26,27,3,0,0,0,3,0,0
0,0,3,3,3,17,3,19,22,0,0,0,0,0,0,0,0,0,25,0,0,0,3,17,3,3,3,0,0
0,0,0,0,3,0,0,0,0,0,0,0,0,0,0,0,0,0,3,0,0,0,0,0,3,0,0,0,0
0,0,0,0,3,0,0,3,0,0,3,0,0,3,3,24,3,3,3,0,0,0,0,0,3,0,0,0,0
0,0,0,0,3,0,0,0,0,0,0,0,0,3,0,0,0,3,3,0,0,0,0,0,3,0,0,0,0
0,0,0,0,3,16,16,16,16,0,0,0,0,3,0,0,0,3,3,0,0,0,0,34,3,0,0,0,0
0,0,0,0,3,0,0,0,21,0,0,0,0,3,0,0,0,3,3,0,0,0,0,33,3,0,0,0,0
0,0,0,0,3,16,16,16,16,0,0,0,0,3,0,0,0,3,3,0,0,0,0,32,3,0,0,0,0
0,0,0,0,3,0,0,0,21,0,0,0,0,3,3,3,3,3,3,0,0,0,0,31,3,0,0,0,0
0,0,0,0,3,16,16,16,16,0,0,0,0,0,0,0,0,0,3,0,0,0,0,31,3,0,0,0,0
0,0,0,0,3,0,0,0,21,0,0,0,0,0,0,0,0,0,25,0,0,0,0,31,3,0,0,0,0
0,0,0,0,3,16,16,16,16,0,0,0,0,0,0,0,0,0,3,0,0,0,0,30,3,0,0,0,0
0,0,0,0,3,15,0,0,0,0,0,0,0,0,0,0,0,0,3,0,0,0,0,29,3,0,0,0,0
0,0,0,0,3,14,0,0,0,0,0,0,0,0,0,0,0,0,3,0,0,0,0,28,3,0,0,0,0
0,0,0,0,3,3,3,3,20,3,3,23,0,0,0,0,0,0,3,3,20,3,3,3,3,0,0,0,0
0,0,0,0,3,0,0,0,0,0,3,3,0,0,0,0,0,3,3,0,0,0,0,0,3,0,0,0,0
0,0,0,0,3,0,0,0,0,0,3,0,0,0,0,0,0,7,3,0,0,0,0,0,3,0,0,0,0
0,0,3,3,3,3,3,0,0,0,3,0,0,0,0,0,0,0,3,0,0,0,3,3,3,3,3,0,0
0,0,3,3,13,0,18,0,0,0,3,23,0,0,0,0,0,0,3,0,0,0,25,0,35,3,3,0,0
0,0,3,3,3,0,3,3,3,3,3,3,0,0,0,0,0,3,3,3,3,3,3,0,3,3,3,0,0
0,0,3,3,0,0,3,0,0,0,0,0,0,0,0,0,0,7,0,0,0,0,3,0,0,3,3,0,0
0,0,3,3,3,3,3,0,0,0,0,0,0,0,0,0,0,0,0,0,0,0,3,3,3,3,3,0,0
0,0,0,0,0,0,0,0,0,0,0,0,0,0,0,0,0,0,0,0,0,0,0,0,0,0,0,0,0
0,0,0,0,0,0,0,0,0,0,0,0,0,0,0,0,0,0,0,0,0,0,0,0,0,0,0,0,0
:endlayer
layer: 6
0,0,0,0,0,0,0,0,0,0,0,0,0,0,0,0,0,0,0,0,0,0,0,0,0,0,0,0,0
0,0,0,0,0,0,0,0,0,0,0,0,0,0,0,0,0,0,0,0,0,0,0,0,0,0,0,0,0
0,0,3,3,3,3,3,0,0,0,0,0,0,0,0,0,0,0,0,0,0,0,3,3,3,3,3,0,0
0,0,3,3,13,0,3,0,0,0,0,0,0,0,0,0,0,0,0,0,0,0,3,0,35,3,3,0,0
0,0,3,37,3,0,3,3,3,3,3,3,3,3,3,3,3,3,3,3,3,3,3,0,3,37,3,0,0
0,0,3,0,10,0,3,3,3,3,3,13,0,0,0,0,0,0,3,0,0,0,3,0,0,0,3,0,0
0,0,3,3,3,40,3,0,0,0,0,0,0,0,0,0,0,0,45,0,0,0,3,48,3,3,3,0,0
0,0,0,0,3,0,0,0,0,0,0,0,0,0,0,0,0,0,3,0,0,0,0,0,3,0,0,0,0
0,0,0,0,3,0,0,3,0,0,3,0,0,3,3,43,3,3,3,0,0,0,0,0,3,0,0,0,0
0,0,0,0,3,0,0,0,0,0,0,0,0,3,0,0,0,3,3,0,0,0,0,0,3,0,0,0,0
0,0,0,0,3,16,16,16,16,0,0,0,0,3,0,0,0,3,3,0,0,0,0,0,3,0,0,0,0
0,0,0,0,3,0,0,0,0,0,0,0,0,3,0,0,0,3,3,0,0,0,0,0,3,0,0,0,0
0,0,0,0,3,16,16,16,16,0,0,0,0,3,0,0,0,3,3,0,0,0,0,0,3,0,0,0,0
0,0,0,0,3,0,0,0,0,0,0,0,0,3,3,3,3,3,3,0,0,0,0,0,3,0,0,0,0
0,0,0,0,3,16,16,16,16,0,0,0,0,0,0,0,0,0,3,0,0,0,0,0,3,0,0,0,0
0,0,0,0,3,0,0,0,0,0,0,0,0,0,0,0,0,0,44,0,0,0,0,0,3,0,0,0,0
0,0,0,0,3,16,16,16,16,0,0,0,0,0,0,0,0,0,3,0,0,0,0,0,3,0,0,0,0
0,0,0,0,3,0,0,0,0,0,0,0,0,0,0,0,0,0,3,0,0,0,0,0,3,0,0,0,0
0,0,0,0,3,0,0,0,0,0,0,0,0,0,0,0,0,0,3,0,0,0,0,0,3,0,0,0,0
0,0,0,0,3,3,3,3,42,3,3,0,0,0,0,0,0,0,3,3,46,3,3,3,3,0,0,0,0
0,0,0,0,3,0,0,0,0,0,3,3,0,0,0,0,0,3,3,0,0,0,0,0,3,0,0,0,0
0,0,0,0,3,0,0,0,0,0,3,0,0,0,0,0,0,0,3,0,0,0,0,0,3,0,0,0,0
0,0,3,3,3,3,3,0,0,0,3,0,0,0,0,0,0,0,3,0,0,0,3,3,3,3,3,0,0
0,0,3,0,39,0,41,0,0,0,3,0,0,0,0,0,0,0,3,0,0,0,47,0,0,0,3,0,0
0,0,3,36,3,0,3,3,3,3,3,3,0,0,0,0,0,3,3,3,3,3,3,0,3,36,3,0,0
0,0,3,3,38,0,3,0,0,0,0,0,0,0,0,0,0,0,0,0,0,0,3,0,0,3,3,0,0
0,0,3,3,3,3,3,0,0,0,0,0,0,0,0,0,0,0,0,0,0,0,3,3,3,3,3,0,0
0,0,0,0,0,0,0,0,0,0,0,0,0,0,0,0,0,0,0,0,0,0,0,0,0,0,0,0,0
0,0,0,0,0,0,0,0,0,0,0,0,0,0,0,0,0,0,0,0,0,0,0,0,0,0,0,0,0
:endlayer
layer: 7
0,0,0,0,0,0,0,0,0,0,0,0,0,0,0,0,0,0,0,0,0,0,0,0,0,0,0,0,0
0,0,0,0,0,0,0,0,0,0,0,0,0,0,0,0,0,0,0,0,0,0,0,0,0,0,0,0,0
0,0,3,3,3,3,3,0,0,0,0,0,0,0,0,0,0,0,0,0,0,0,3,3,3,3,3,0,0
0,0,3,0,0,0,3,0,0,0,0,0,0,0,0,0,0,0,0,0,0,0,3,0,0,0,3,0,0
0,0,3,36,3,11,3,3,3,3,3,3,3,3,3,3,3,3,3,3,3,3,3,9,3,36,3,0,0
0,0,3,3,38,0,3,3,3,3,13,0,0,0,0,0,0,0,3,0,0,0,3,0,50,3,3,0,0
0,0,3,3,3,3,3,0,0,39,0,0,0,0,0,0,0,0,3,0,0,0,3,3,3,3,3,0,0
0,0,0,0,3,0,0,0,0,0,0,0,0,0,0,0,0,0,3,0,0,0,0,0,3,0,0,0,0
0,0,0,0,3,0,0,3,0,0,3,0,0,3,3,49,3,3,3,0,0,0,0,0,3,0,0,0,0
0,0,0,0,3,0,0,0,0,0,0,0,0,3,0,0,0,3,3,0,0,0,0,11,3,0,0,0,0
0,0,0,0,3,0,16,0,16,0,0,0,0,3,0,0,0,3,3,0,0,0,0,0,3,0,0,0,0
0,0,0,0,3,0,0,0,0,0,0,0,0,3,0,0,0,3,3,0,0,0,0,0,3,0,0,0,0
0,0,0,0,3,0,16,0,16,0,0,0,0,3,0,0,0,3,3,0,0,0,0,0,3,0,0,0,0
0,0,0,0,3,0,0,0,0,0,0,0,0,3,3,3,3,3,3,0,0,0,0,11,3,0,0,0,0
0,0,0,0,3,0,16,0,16,0,0,0,0,0,0,0,0,0,3,0,0,0,0,0,3,0,0,0,0
0,0,0,0,3,0,0,0,0,0,0,0,0,0,0,0,0,0,3,0,0,0,0,0,3,0,0,0,0
0,0,0,0,3,0,16,0,16,0,0,0,0,0,0,0,0,0,3,0,0,0,0,0,3,0,0,0,0
0,0,0,0,3,0,0,0,0,0,0,0,0,0,0,0,0,0,3,0,0,0,0,11,3,0,0,0,0
0,0,0,0,3,0,0,0,0,0,0,0,0,0,0,0,0,0,3,9,0,0,0,0,3,0,0,0,0
0,0,0,0,3,3,3,3,3,3,3,0,0,0,0,0,0,0,3,3,3,3,3,3,3,0,0,0,0
0,0,0,0,3,0,0,0,0,0,3,3,0,0,0,0,0,3,3,0,0,0,0,0,3,0,0,0,0
0,0,0,0,3,0,0,0,0,0,3,0,0,0,0,0,0,0,3,0,0,0,0,0,3,0,0,0,0
0,0,3,3,3,3,3,0,0,0,3,0,0,0,0,0,0,0,3,0,0,0,3,3,3,3,3,0,0
0,0,3,0,0,0,3,0,0,0,3,0,0,0,0,0,0,0,3,10,0,0,3,0,39,0,3,0,0
0,0,3,0,3,0,3,3,3,3,3,3,0,0,0,0,0,3,3,3,3,3,3,12,3,0,3,0,0
0,0,3,0,35,3,3,0,0,0,0,0,0,0,0,0,0,0,0,0,0,0,3,3,13,0,3,0,0
0,0,3,3,3,3,3,0,0,0,0,0,0,0,0,0,0,0,0,0,0,0,3,3,3,3,3,0,0
0,0,0,0,0,0,0,0,0,0,0,0,0,0,0,0,0,0,0,0,0,0,0,0,0,0,0,0,0
0,0,0,0,0,0,0,0,0,0,0,0,0,0,0,0,0,0,0,0,0,0,0,0,0,0,0,0,0
:endlayer
layer: 8
0,0,0,0,0,0,0,0,0,0,0,0,0,0,0,0,0,0,0,0,0,0,0,0,0,0,0,0,0
0,0,0,0,0,0,0,0,0,0,0,0,0,0,0,0,0,0,0,0,0,0,0,0,0,0,0,0,0
0,0,3,3,3,3,3,0,0,0,0,0,0,0,0,0,0,0,0,0,0,0,3,3,3,3,3,0,0
0,0,3,0,0,0,3,0,0,0,0,0,0,0,0,0,0,0,0,0,0,0,3,0,0,0,3,0,0
0,0,3,0,3,12,3,3,3,3,3,3,3,3,3,3,3,3,3,3,3,3,3,12,3,0,3,0,0
0,0,3,0,35,3,3,3,3,13,0,0,0,0,39,0,0,0,3,9,0,11,3,3,13,0,3,0,0
0,0,3,3,3,3,3,3,0,0,0,0,0,0,0,0,0,11,3,0,0,0,3,3,3,3,3,0,0
0,0,0,0,3,9,0,3,9,0,0,0,0,10,0,10,0,0,3,0,0,0,0,0,3,0,0,0,0
0,0,0,0,3,0,0,3,3,3,3,3,3,3,3,3,3,3,3,0,0,0,0,0,3,0,0,0,0
0,0,0,0,3,0,0,39,0,0,39,0,0,3,0,0,0,3,3,0,0,0,0,0,3,0,0,0,0
0,0,0,0,3,0,16,0,16,0,0,0,0,3,0,0,0,3,3,9,0,0,0,0,3,0,0,0,0
0,0,0,0,3,9,0,0,0,0,0,0,0,3,0,0,0,3,3,0,0,0,0,0,3,0,0,0,0
0,0,0,0,3,0,16,0,16,0,0,0,0,3,0,0,0,3,3,0,0,0,0,0,3,0,0,0,0
0,0,0,0,3,9,0,0,0,0,0,0,11,3,3,3,3,3,3,0,0,0,0,0,3,0,0,0,0
0,0,0,0,3,0,16,0,16,0,0,0,0,39,0,0,0,0,3,0,0,0,0,0,3,0,0,0,0
0,0,0,0,3,9,0,0,0,0,0,0,0,0,0,0,0,11,3,0,0,0,0,0,3,0,0,0,0
0,0,0,0,3,0,16,0,16,0,0,0,0,0,0,0,0,0,3,0,0,0,0,0,3,0,0,0,0
0,0,0,0,3,0,0,0,0,0,0,0,0,0,0,0,0,0,3,0,0,0,0,0,3,0,0,0,0
0,0,0,0,3,9,0,0,0,0,10,0,0,0,0,0,0,0,3,0,0,0,0,0,3,0,0,0,0
0,0,0,0,3,3,3,3,3,3,3,9,0,0,0,0,0,11,3,3,3,3,3,3,3,0,0,0,0
0,0,0,0,3,0,0,0,0,0,3,3,0,0,0,0,0,3,3,0,0,0,0,0,3,0,0,0,0
0,0,0,0,3,0,0,0,0,0,3,0,0,0,0,0,0,0,3,0,0,0,0,0,3,0,0,0,0
0,0,3,3,3,3,3,0,0,0,3,9,0,0,0,0,0,11,3,0,0,0,3,3,3,3,3,0,0
0,0,3,0,50,3,3,0,0,0,3,0,0,0,0,0,0,0,3,0,0,0,3,3,38,0,3,0,0
0,0,3,9,3,5,3,3,3,3,3,3,0,0,0,0,0,3,3,3,3,3,3,5,3,0,3,0,0
0,0,3,0,0,0,3,0,0,0,39,0,0,0,0,0,0,0,39,0,0,0,3,0,0,0,3,0,0
0,0,3,3,3,3,3,0,0,0,0,0,0,0,0,0,0,0,0,0,0,0,3,3,3,3,3,0,0
0,0,0,0,0,0,0,0,0,0,0,0,0,0,0,0,0,0,0,0,0,0,0,0,0,0,0,0,0
0,0,0,0,0,0,0,0,0,0,0,0,0,0,0,0,0,0,0,0,0,0,0,0,0,0,0,0,0
:endlayer
layer: 9
0,0,0,0,0,0,0,0,0,0,0,0,0,0,0,0,0,0,0,0,0,0,0,0,0,0,0,0,0
0,0,0,0,0,0,0,0,0,0,0,0,0,0,0,0,0,0,0,0,0,0,0,0,0,0,0,0,0
0,0,3,3,3,3,3,0,0,0,0,0,0,0,0,0,0,0,0,0,0,0,3,3,3,3,3,0,0
0,0,3,0,50,3,3,0,0,0,0,0,0,0,0,0,0,0,0,0,0,0,3,3,38,0,3,0,0
0,0,3,0,3,5,3,3,3,3,3,3,3,3,3,3,3,3,3,3,3,3,3,5,3,11,3,0,0
0,0,3,9,0,0,35,3,13,0,0,0,0,3,3,3,3,3,3,3,3,3,13,0,0,0,3,0,0
0,0,3,3,3,3,3,3,3,3,3,3,3,3,3,3,3,3,3,3,3,3,3,3,3,3,3,0,0
0,0,0,0,3,3,3,3,3,3,3,3,3,3,3,3,3,3,3,3,3,3,3,3,3,0,0,0,0
0,0,0,0,3,3,3,3,3,3,3,3,3,3,3,3,3,3,3,3,3,3,3,3,3,0,0,0,0
0,0,0,0,3,3,3,3,3,3,3,3,3,3,3,3,3,3,3,3,3,3,3,3,3,0,0,0,0
0,0,0,0,3,3,3,3,3,3,3,3,3,3,3,3,3,3,3,3,3,3,3,3,3,0,0,0,0
0,0,0,0,3,3,3,3,3,3,3,3,3,3,3,3,3,3,3,3,3,3,3,3,3,0,0,0,0
0,0,0,0,3,3,3,3,3,3,3,3,3,3,3,3,3,3,3,3,3,3,3,3,3,0,0,0,0
0,0,0,0,3,3,3,3,3,3,3,3,3,3,3,3,3,3,3,3,3,3,3,3,3,0,0,0,0
0,0,0,0,3,3,3,3,3,3,3,3,3,3,3,3,3,3,3,3,3,3,3,3,3,0,0,0,0
0,0,0,0,3,3,3,3,3,3,3,3,3,3,3,3,3,3,3,3,3,3,3,3,3,0,0,0,0
0,0,0,0,3,3,3,3,3,3,3,3,3,3,3,3,3,3,3,3,3,3,3,3,3,0,0,0,0
0,0,0,0,3,3,3,3,3,3,3,3,3,3,3,3,3,3,3,3,3,3,3,3,3,0,0,0,0
0,0,0,0,3,3,3,3,3,3,3,3,3,3,3,3,3,3,3,3,3,3,3,3,3,0,0,0,0
0,0,0,0,3,3,3,3,3,3,3,3,3,3,3,3,3,3,3,3,3,3,3,3,3,0,0,0,0
0,0,0,0,3,3,3,3,3,3,3,3,3,3,3,3,3,3,3,3,3,3,3,3,3,0,0,0,0
0,0,0,0,3,3,3,3,3,3,3,3,3,3,3,3,3,3,3,3,3,3,3,3,3,0,0,0,0
0,0,3,3,3,5,3,3,3,3,3,3,3,3,3,3,3,3,3,3,3,3,3,5,3,3,3,0,0
0,0,3,3,13,0,3,3,3,3,3,3,3,3,3,3,3,3,3,3,3,3,3,0,35,3,3,0,0
0,0,3,37,3,0,3,3,3,3,3,3,37,37,37,37,37,3,3,3,3,3,3,0,3,37,3,0,0
0,0,3,0,0,0,3,0,0,0,0,0,0,0,0,0,0,0,0,0,0,0,3,0,10,0,3,0,0
0,0,3,3,3,3,3,0,0,0,0,0,0,0,0,0,0,0,0,0,0,0,3,3,3,3,3,0,0
0,0,0,0,0,0,0,0,0,0,0,0,0,0,0,0,0,0,0,0,0,0,0,0,0,0,0,0,0
0,0,0,0,0,0,0,0,0,0,0,0,0,0,0,0,0,0,0,0,0,0,0,0,0,0,0,0,0
:endlayer
layer: 10
0,0,0,0,0,0,0,0,0,0,0,0,0,0,0,0,0,0,0,0,0,0,0,0,0,0,0,0,0
0,0,0,0,0,0,0,0,0,0,0,0,0,0,0,0,0,0,0,0,0,0,0,0,0,0,0,0,0
0,0,3,3,3,3,3,0,0,0,0,0,0,0,0,0,0,0,0,0,0,0,3,3,3,3,3,0,0
0,0,3,3,13,0,3,0,0,0,0,0,0,0,0,0,0,0,0,0,0,0,3,0,35,3,3,0,0
0,0,3,37,3,0,3,3,3,3,3,3,3,3,3,3,3,3,3,3,3,3,3,0,3,37,3,0,0
0,0,3,0,0,0,0,0,0,0,0,0,0,0,0,0,0,0,0,0,0,0,0,0,0,0,3,0,0
0,0,3,3,3,3,3,0,0,0,0,0,0,0,0,0,0,0,0,0,0,0,3,3,3,3,3,0,0
0,0,0,0,3,0,3,36,0,0,0,0,0,0,0,0,0,0,0,0,0,0,0,0,3,0,0,0,0
0,0,0,0,3,0,3,3,0,0,0,0,0,0,0,0,0,0,0,0,0,0,0,0,3,0,0,0,0
0,0,0,0,3,0,3,3,0,0,0,0,0,0,0,0,0,0,0,0,0,0,0,0,3,0,0,0,0
0,0,0,0,3,0,3,3,0,52,0,0,0,0,0,0,0,0,0,52,0,0,0,0,3,0,0,0,0
0,0,0,0,3,51,3,3,0,0,0,0,0,0,0,0,0,0,0,0,0,0,0,0,3,0,0,0,0
0,0,0,0,3,0,0,0,0,0,0,0,0,0,0,0,0,0,0,0,0,0,0,0,3,0,0,0,0
0,0,0,0,3,0,0,0,0,0,0,0,0,0,0,0,0,0,0,0,0,0,0,0,3,0,0,0,0
0,0,0,0,3,0,0,0,0,0,0,0,0,0,52,0,0,0,0,0,0,0,0,0,3,0,0,0,0
0,0,0,0,3,0,0,0,0,0,0,0,0,0,0,0,0,0,0,0,0,0,0,0,3,0,0,0,0
0,0,0,0,3,0,0,0,0,0,0,0,0,0,0,0,0,0,0,0,0,0,0,0,3,0,0,0,0
0,0,0,0,3,0,0,0,0,0,0,0,0,0,0,0,0,0,0,0,0,0,0,0,3,0,0,0,0
0,0,0,0,3,0,0,0,0,52,0,0,0,0,0,0,0,0,0,0,0,0,0,0,3,0,0,0,0
0,0,0,0,3,0,0,0,0,0,0,0,0,0,0,0,0,0,52,0,0,0,0,0,3,0,0,0,0
0,0,0,0,3,0,0,0,0,0,0,0,0,0,0,0,0,0,0,0,0,0,0,0,3,0,0,0,0
0,0,0,0,3,0,0,0,0,0,0,0,0,0,0,0,0,0,0,0,0,0,0,0,3,0,0,0,0
0,0,3,3,3,0,3,0,0,0,0,0,0,0,0,0,0,0,0,0,0,0,3,0,3,3,3,0,0
0,0,3,0,0,0,3,0,0,0,0,0,0,0,0,0,0,0,0,0,0,0,3,0,0,0,3,0,0
0,0,3,36,3,11,3,3,3,3,3,3,3,3,3,3,3,3,3,3,3,3,3,0,3,36,3,0,0
0,0,3,3,38,0,3,0,0,0,0,0,0,39,0,39,0,0,0,0,0,0,3,0,50,3,3,0,0
0,0,3,3,3,3,3,0,0,0,0,0,0,0,0,0,0,0,0,0,0,0,3,3,3,3,3,0,0
0,0,0,0,0,0,0,0,0,0,0,0,0,0,0,0,0,0,0,0,0,0,0,0,0,0,0,0,0
0,0,0,0,0,0,0,0,0,0,0,0,0,0,0,0,0,0,0,0,0,0,0,0,0,0,0,0,0
:endlayer
layer: 11
0,0,0,0,0,0,0,0,0,0,0,0,0,0,0,0,0,0,0,0,0,0,0,0,0,0,0,0,0
0,0,0,0,0,0,0,0,0,0,0,0,0,0,0,0,0,0,0,0,0,0,0,0,0,0,0,0,0
0,0,3,3,3,3,3,0,0,0,0,0,0,0,0,0,0,0,0,0,0,0,3,3,3,3,3,0,0
0,0,3,0,0,0,3,0,0,0,0,0,0,0,0,0,0,0,0,0,0,0,3,0,0,0,3,0,0
0,0,3,36,3,11,3,3,3,3,3,3,3,3,3,3,3,3,3,3,3,3,3,0,3,36,3,0,0
0,0,3,3,38,0,0,0,0,0,0,0,0,0,0,0,0,0,0,0,0,0,0,0,50,3,3,0,0
0,0,3,3,3,3,3,0,0,0,0,0,0,0,0,0,0,0,0,0,0,0,3,3,3,3,3,0,0
0,0,0,0,3,0,3,0,0,0,0,0,0,0,0,0,0,0,0,0,0,0,0,0,3,0,0,0,0
0,0,0,0,3,0,3,36,0,0,0,0,0,0,0,0,0,0,0,0,0,0,0,0,3,0,0,0,0
0,0,0,0,3,0,3,3,0,0,0,0,0,0,0,0,0,0,0,0,0,0,0,0,3,0,0,0,0
0,0,0,0,3,0,3,3,0,0,0,0,0,0,0,0,0,0,0,0,0,0,0,0,3,0,0,0,0
0,0,0,0,3,53,3,3,0,0,0,0,0,0,0,0,0,0,0,0,0,0,0,0,3,0,0,0,0
0,0,0,0,3,0,0,0,0,0,0,0,0,0,0,0,0,0,0,0,0,0,0,0,3,0,0,0,0
0,0,0,0,3,0,0,0,0,0,0,0,0,0,0,0,0,0,0,0,0,0,0,0,3,0,0,0,0
0,0,0,0,3,0,0,0,0,0,0,0,0,0,0,0,0,0,0,0,0,0,0,0,3,0,0,0,0
0,0,0,0,3,0,0,0,0,0,0,0,0,0,0,0,0,0,0,0,0,0,0,0,3,0,0,0,0
0,0,0,0,3,0,0,0,0,0,0,0,0,0,0,0,0,0,0,0,0,0,0,0,3,0,0,0,0
0,0,0,0,3,0,0,0,0,0,0,0,0,0,0,0,0,0,0,0,0,0,0,0,3,0,0,0,0
0,0,0,0,3,0,0,0,0,0,0,0,0,0,0,0,0,0,0,0,0,0,0,0,3,0,0,0,0
0,0,0,0,3,0,0,0,0,0,0,0,0,0,0,0,0,0,0,0,0,0,0,0,3,0,0,0,0
0,0,0,0,3,0,0,0,0,0,0,0,0,0,0,0,0,0,0,0,0,0,0,0,3,0,0,0,0
0,0,0,0,3,0,0,0,0,0,0,0,0,0,0,0,0,0,0,0,0,0,0,0,3,0,0,0,0
0,0,3,3,3,0,3,0,0,0,0,0,0,0,0,0,0,0,0,0,0,0,3,0,3,3,3,0,0
0,0,3,0,0,0,3,0,0,0,0,0,0,0,0,0,0,0,0,0,0,0,3,0,0,0,3,0,0
0,0,3,0,3,12,3,3,3,3,3,3,3,3,3,3,3,3,3,3,3,3,3,12,3,11,3,0,0
0,0,3,0,35,3,3,0,0,0,0,0,0,0,0,0,0,0,0,0,0,0,3,3,13,0,3,0,0
0,0,3,3,3,3,3,0,0,0,0,0,0,0,0,0,0,0,0,0,0,0,3,3,3,3,3,0,0
0,0,0,0,0,0,0,0,0,0,0,0,0,0,0,0,0,0,0,0,0,0,0,0,0,0,0,0,0
0,0,0,0,0,0,0,0,0,0,0,0,0,0,0,0,0,0,0,0,0,0,0,0,0,0,0,0,0
:endlayer
layer: 12
0,0,0,0,0,0,0,0,0,0,0,0,0,0,0,0,0,0,0,0,0,0,0,0,0,0,0,0,0
0,0,0,0,0,0,0,0,0,0,0,0,0,0,0,0,0,0,0,0,0,0,0,0,0,0,0,0,0
0,0,3,3,3,3,3,0,0,0,0,0,0,0,0,0,0,0,0,0,0,0,3,3,3,3,3,0,0
0,0,3,0,0,0,3,0,0,0,0,0,0,0,0,0,0,0,0,0,0,0,3,0,39,0,3,0,0
0,0,3,0,3,12,3,3,3,3,3,3,3,3,3,3,3,3,3,3,3,3,3,12,3,0,3,0,0
0,0,3,0,35,3,38,0,0,0,0,0,0,0,39,0,0,0,39,0,0,0,50,3,13,0,3,0,0
0,0,3,3,3,3,3,0,0,0,0,0,0,0,0,0,0,0,0,0,0,0,3,3,3,3,3,0,0
0,0,0,0,3,0,3,0,0,0,0,0,0,0,0,0,0,0,0,0,0,0,0,0,3,0,0,0,0
0,0,0,0,3,0,3,0,0,0,0,0,0,0,0,0,0,0,0,0,0,0,0,0,3,0,0,0,0
0,0,0,0,3,0,3,36,0,0,0,0,0,0,0,0,0,0,0,0,0,0,0,11,3,0,0,0,0
0,0,0,0,3,9,3,3,0,0,0,0,0,0,0,0,0,0,0,0,0,0,0,0,3,0,0,0,0
0,0,0,0,3,49,3,3,0,0,0,0,0,0,0,0,0,0,0,0,0,0,0,0,3,0,0,0,0
0,0,0,0,3,0,0,0,0,0,0,0,0,0,0,0,0,0,0,0,0,0,0,0,3,0,0,0,0
0,0,0,0,3,0,0,0,0,0,0,0,0,0,0,0,0,0,0,0,0,0,0,11,3,0,0,0,0
0,0,0,0,3,0,0,0,0,0,0,0,0,0,0,0,0,0,0,0,0,0,0,0,3,0,0,0,0
0,0,0,0,3,9,0,0,0,0,0,0,0,0,0,0,0,0,0,0,0,0,0,0,3,0,0,0,0
0,0,0,0,3,0,0,0,0,0,0,0,0,0,0,0,0,0,0,0,0,0,0,0,3,0,0,0,0
0,0,0,0,3,0,0,0,0,0,0,0,0,0,0,0,0,0,0,0,0,0,0,0,3,0,0,0,0
0,0,0,0,3,0,0,0,0,0,0,0,0,0,0,0,0,0,0,0,0,0,0,11,3,0,0,0,0
0,0,0,0,3,9,0,0,0,0,0,0,0,0,0,0,0,0,0,0,0,0,0,0,3,0,0,0,0
0,0,0,0,3,0,0,0,0,0,0,0,0,0,0,0,0,0,0,0,0,0,0,0,3,0,0,0,0
0,0,0,0,3,0,0,0,0,0,0,0,0,0,0,0,0,0,0,0,0,0,0,0,3,0,0,0,0
0,0,3,3,3,12,3,0,0,0,0,0,0,0,0,0,0,0,0,0,0,0,3,12,3,3,3,0,0
0,0,3,0,50,3,3,0,0,10,0,0,0,0,10,0,0,0,0,10,0,0,3,3,38,0,3,0,0
0,0,3,9,3,5,3,3,3,3,3,3,3,3,3,3,3,3,3,3,3,3,3,5,3,0,3,0,0
0,0,3,0,0,0,3,37,37,37,37,37,37,37,37,37,37,37,37,37,37,37,3,0,0,0,3,0,0
0,0,3,3,3,3,3,0,0,0,0,0,0,0,0,0,0,0,0,0,0,0,3,3,3,3,3,0,0
0,0,0,0,0,0,0,0,0,0,0,0,0,0,0,0,0,0,0,0,0,0,0,0,0,0,0,0,0
0,0,0,0,0,0,0,0,0,0,0,0,0,0,0,0,0,0,0,0,0,0,0,0,0,0,0,0,0
:endlayer
layer: 13
0,0,0,0,0,0,0,0,0,0,0,0,0,0,0,0,0,0,0,0,0,0,0,0,0,0,0,0,0
0,0,0,0,0,0,0,0,0,0,0,0,0,0,0,0,0,0,0,0,0,0,0,0,0,0,0,0,0
0,0,3,3,3,3,3,0,0,0,0,0,0,0,0,0,0,0,0,0,0,0,3,3,3,3,3,0,0
0,0,3,0,50,3,3,3,3,3,3,3,3,3,3,3,3,3,3,3,3,3,3,3,38,0,3,0,0
0,0,3,9,3,5,3,3,3,3,3,3,3,3,3,3,3,3,3,3,3,3,3,5,3,0,3,0,0
0,0,3,0,0,0,35,3,3,3,3,3,3,3,3,3,3,3,3,3,3,3,13,0,0,0,3,0,0
0,0,3,3,3,3,3,37,3,3,3,3,3,3,3,3,3,3,3,3,3,3,3,3,3,3,3,0,0
0,0,0,3,3,3,3,0,3,3,3,3,3,3,3,3,3,3,3,3,3,3,3,3,3,3,0,0,0
0,0,0,3,3,3,3,0,3,3,3,3,3,3,3,3,3,3,3,3,3,3,3,3,3,3,0,0,0
0,0,0,3,3,3,3,0,3,3,3,3,3,3,3,3,3,3,3,3,3,3,3,3,3,3,0,0,0
0,0,0,3,3,3,3,36,3,3,3,3,3,3,3,3,3,3,3,3,3,3,3,3,3,3,0,0,0
0,0,0,3,3,3,3,3,3,3,3,3,3,3,3,3,3,3,3,3,3,3,3,3,3,3,0,0,0
0,0,0,3,3,3,3,3,3,3,3,3,3,3,3,3,3,3,3,3,3,3,3,3,3,3,0,0,0
0,0,0,3,3,3,3,3,3,3,3,3,3,3,3,3,3,3,3,3,3,3,3,3,3,3,0,0,0
0,0,0,3,3,3,3,3,3,3,3,3,3,3,3,3,3,3,3,3,3,3,3,3,3,3,0,0,0
0,0,0,3,3,3,3,3,3,3,3,3,3,3,3,3,3,3,3,3,3,3,3,3,3,3,0,0,0
0,0,0,3,3,3,3,3,3,3,3,3,3,3,3,3,3,3,3,3,3,3,3,3,3,3,0,0,0
0,0,0,3,3,3,3,3,3,3,3,3,3,3,3,3,3,3,3,3,3,3,3,3,3,3,0,0,0
0,0,0,3,3,3,3,3,3,3,3,3,3,3,3,3,3,3,3,3,3,3,3,3,3,3,0,0,0
0,0,0,3,3,3,3,3,3,3,3,3,3,3,3,3,3,3,3,3,3,3,3,3,3,3,0,0,0
0,0,0,3,3,3,3,3,3,3,3,3,3,3,3,3,3,3,3,3,3,3,3,3,3,3,0,0,0
0,0,0,3,3,3,3,3,3,3,3,3,3,3,3,3,3,3,3,3,3,3,3,3,3,3,0,0,0
0,0,3,3,3,3,3,3,3,3,3,3,3,3,3,3,3,3,3,3,3,3,3,3,3,3,3,0,0
0,0,3,3,13,0,3,3,3,3,3,3,3,3,3,3,3,3,3,3,3,3,3,0,35,3,3,0,0
0,0,3,37,3,0,3,3,3,3,3,3,3,3,3,3,3,3,3,3,3,3,3,0,3,37,3,0,0
0,0,3,0,0,0,3,3,3,3,3,3,3,3,3,3,3,3,3,3,3,3,3,0,0,0,3,0,0
0,0,3,3,3,3,3,0,0,0,0,0,0,0,0,0,0,0,0,0,0,0,3,3,3,3,3,0,0
0,0,0,0,0,0,0,0,0,0,0,0,0,0,0,0,0,0,0,0,0,0,0,0,0,0,0,0,0
0,0,0,0,0,0,0,0,0,0,0,0,0,0,0,0,0,0,0,0,0,0,0,0,0,0,0,0,0
:endlayer
layer: 14
0,0,0,0,0,0,0,0,0,0,0,0,0,0,0,0,0,0,0,0,0,0,0,0,0,0,0,0,0
0,0,0,0,0,0,0,0,0,0,0,0,0,0,0,0,0,0,0,0,0,0,0,0,0,0,0,0,0
0,0,3,3,3,3,3,0,0,0,0,0,0,0,0,0,0,0,0,0,0,0,3,3,3,3,3,0,0
0,0,3,3,13,0,3,3,3,3,3,3,3,3,3,3,3,3,3,3,3,3,3,0,35,3,3,0,0
0,0,3,37,3,0,3,54,54,54,54,54,54,54,54,54,54,54,54,54,54,54,3,0,3,37,3,0,0
0,0,3,0,0,0,0,54,54,54,54,54,54,54,54,54,54,54,54,54,54,54,0,0,10,0,3,0,0
0,0,3,3,3,3,3,3,54,54,54,54,54,54,54,54,54,54,54,54,54,3,3,3,3,3,3,0,0
0,0,0,3,54,54,3,0,3,3,3,3,0,3,3,3,3,3,3,3,3,3,3,54,54,3,0,0,0
0,0,0,3,54,54,3,0,3,3,0,0,0,0,0,0,0,0,0,0,0,3,3,54,54,3,0,0,0
0,0,0,3,54,54,3,0,3,3,0,0,0,0,0,0,0,0,0,0,0,3,3,54,54,3,0,0,0
0,0,0,3,54,54,0,0,0,3,0,0,0,0,0,0,0,0,0,0,0,3,5,54,54,3,0,0,0
0,0,0,3,54,54,0,0,0,0,0,0,0,0,0,0,0,0,0,0,0,0,0,54,54,3,0,0,0
0,0,0,3,54,54,0,3,3,3,0,0,0,0,0,0,0,0,0,0,0,3,0,54,54,3,0,0,0
0,0,0,3,54,54,0,0,3,3,3,3,3,3,3,3,3,3,3,3,3,0,0,54,54,3,0,0,0
0,0,0,3,54,54,0,0,3,2,2,2,2,2,2,2,2,2,2,2,3,0,0,54,54,3,0,0,0
0,0,0,3,54,54,0,0,3,2,2,2,2,2,2,2,2,2,2,2,3,0,0,54,54,3,0,0,0
0,0,0,3,54,54,0,0,3,2,2,2,2,2,2,2,2,2,2,2,3,0,0,54,54,3,0,0,0
0,0,0,3,54,54,0,0,3,2,2,2,2,2,2,2,2,2,2,2,3,0,0,54,54,3,0,0,0
0,0,0,3,54,54,0,0,3,2,2,2,2,2,2,2,2,2,2,2,3,0,0,54,54,3,0,0,0
0,0,0,3,54,54,0,0,3,2,2,2,2,2,2,2,2,2,2,2,3,0,0,54,54,3,0,0,0
0,0,0,3,54,54,0,0,3,2,2,2,2,2,2,2,2,2,2,2,3,0,0,54,54,3,0,0,0
0,0,0,3,54,54,0,0,3,3,3,3,3,3,3,3,3,3,3,3,3,0,0,54,54,3,0,0,0
0,0,3,3,3,3,0,3,54,54,54,54,35,3,3,3,13,54,54,54,54,3,3,3,3,3,3,0,0
0,0,3,0,0,0,0,54,54,54,54,54,35,3,3,3,13,54,54,54,54,54,3,39,0,0,3,0,0
0,0,3,36,3,11,3,54,54,54,54,54,35,54,3,54,13,54,54,54,54,54,3,0,3,36,3,0,0
0,0,3,3,38,0,3,3,3,3,3,3,3,3,3,3,3,3,3,3,3,3,3,0,50,3,3,0,0
0,0,3,3,3,3,3,0,0,0,0,0,0,0,0,0,0,0,0,0,0,0,3,3,3,3,3,0,0
0,0,0,0,0,0,0,0,0,0,0,0,0,0,0,0,0,0,0,0,0,0,0,0,0,0,0,0,0
0,0,0,0,0,0,0,0,0,0,0,0,0,0,0,0,0,0,0,0,0,0,0,0,0,0,0,0,0
:endlayer
layer: 15
0,0,0,0,0,0,0,0,0,0,0,0,0,0,0,0,0,0,0,0,0,0,0,0,0,0,0,0,0
0,0,0,0,0,0,0,0,0,0,0,0,0,0,0,0,0,0,0,0,0,0,0,0,0,0,0,0,0
0,0,3,3,3,3,3,0,0,0,0,0,0,0,0,0,0,0,0,0,0,0,3,3,3,3,3,0,0
0,0,3,0,0,0,3,0,3,0,3,0,3,0,3,0,3,0,3,0,3,0,3,0,0,0,3,0,0
0,0,3,36,3,11,3,0,0,0,0,0,0,0,0,0,0,0,0,0,0,0,3,0,3,36,3,0,0
0,0,3,3,38,0,0,0,0,0,0,0,0,0,0,0,0,0,0,0,0,0,0,0,50,3,3,0,0
0,0,3,3,3,3,3,3,0,0,0,0,0,0,0,0,0,0,0,0,0,3,3,3,3,3,3,0,0
0,0,0,0,0,0,3,0,3,3,3,3,0,3,3,3,3,3,3,3,3,3,3,0,0,0,0,0,0
0,0,0,3,0,0,3,0,3,3,0,0,0,0,0,0,0,0,0,0,0,3,3,0,0,3,0,0,0
0,0,0,0,0,0,5,0,5,3,0,0,0,0,0,0,0,0,0,0,0,3,5,0,0,0,0,0,0
0,0,0,3,0,0,0,0,0,3,0,0,0,0,0,0,0,0,0,0,0,3,0,0,0,3,0,0,0
0,0,0,0,0,0,0,0,0,0,0,0,0,0,0,0,0,0,0,0,0,0,0,0,0,0,0,0,0
0,0,0,3,0,0,0,3,3,3,0,0,0,0,0,0,0,0,0,0,0,3,0,0,0,3,0,0,0
0,0,0,0,0,0,0,0,3,3,3,3,3,3,3,3,3,3,3,3,3,0,0,0,0,0,0,0,0
0,0,0,3,0,0,0,0,3,0,0,57,58,32,3,59,60,3,13,0,3,0,0,0,0,3,0,0,0
0,0,0,0,0,0,0,0,3,0,0,0,0,0,0,0,0,0,0,0,3,0,0,0,0,0,0,0,0
0,0,0,3,0,0,0,0,3,0,0,0,0,0,0,0,0,0,0,0,3,0,0,0,0,3,0,0,0
0,0,0,0,0,0,0,0,3,0,0,0,0,0,0,0,0,0,0,0,3,0,0,0,0,0,0,0,0
0,0,0,3,0,0,0,0,3,0,0,0,0,0,0,0,0,0,0,0,3,0,0,0,0,3,0,0,0
0,0,0,0,0,0,0,0,3,56,0,0,0,0,0,0,0,0,0,0,3,0,0,0,0,0,0,0,0
0,0,0,3,0,0,0,0,3,55,0,0,0,36,36,36,0,0,61,62,3,0,0,0,0,3,0,0,0
0,0,0,0,0,0,0,0,3,3,3,3,3,3,3,3,3,3,3,3,3,0,0,0,0,0,0,0,0
0,0,3,3,3,3,0,3,0,0,0,0,0,35,3,13,0,0,0,0,0,3,3,3,3,3,3,0,0
0,0,3,0,0,0,0,0,0,0,0,0,0,35,3,13,0,0,0,0,0,0,3,0,0,0,3,0,0
0,0,3,0,3,12,3,0,0,0,0,0,0,35,3,13,0,0,0,0,0,0,3,12,3,0,3,0,0
0,0,3,0,35,3,3,0,3,0,3,0,3,3,3,3,3,0,3,0,3,0,3,3,13,0,3,0,0
0,0,3,3,3,3,3,0,0,0,0,0,0,0,0,0,0,0,0,0,0,0,3,3,3,3,3,0,0
0,0,0,0,0,0,0,0,0,0,0,0,0,0,0,0,0,0,0,0,0,0,0,0,0,0,0,0,0
0,0,0,0,0,0,0,0,0,0,0,0,0,0,0,0,0,0,0,0,0,0,0,0,0,0,0,0,0
:endlayer
layer: 16
0,0,0,0,0,0,0,0,0,0,0,0,0,0,0,0,0,0,0,0,0,0,0,0,0,0,0,0,0
0,0,0,0,0,0,0,0,0,0,0,0,0,0,0,0,0,0,0,0,0,0,0,0,0,0,0,0,0
0,0,3,3,3,3,3,0,0,0,0,0,0,0,0,0,0,0,0,0,0,0,3,3,3,3,3,0,0
0,0,3,0,0,0,3,0,16,0,0,0,0,0,16,0,0,0,0,0,16,0,3,0,0,0,3,0,0
0,0,3,0,3,12,3,0,0,0,0,0,0,0,0,0,0,0,0,0,0,0,3,12,3,0,3,0,0
0,0,3,0,35,3,0,0,0,0,0,0,0,0,0,0,0,0,0,0,0,0,0,3,13,0,3,0,0
0,0,3,3,3,3,3,3,0,0,0,0,0,0,0,0,0,0,0,0,0,3,3,3,3,3,3,0,0
0,0,0,0,0,0,3,3,3,3,3,3,0,3,3,3,3,3,3,3,3,3,3,0,0,0,0,0,0
0,0,0,16,0,0,5,3,5,3,0,0,0,0,0,0,0,0,0,0,0,3,5,0,0,16,0,0,0
0,0,0,0,0,0,0,0,0,3,0,0,0,0,0,0,0,0,0,0,0,3,0,0,0,0,0,0,0
0,0,0,0,0,0,0,0,0,3,0,0,0,0,0,0,0,0,0,0,0,3,0,0,0,0,0,0,0
0,0,0,0,0,0,0,0,0,0,0,0,0,0,0,0,0,0,0,0,0,0,0,0,0,0,0,0,0
0,0,0,0,0,0,0,3,3,3,0,0,0,0,0,0,0,0,0,0,0,3,0,0,0,0,0,0,0
0,0,0,0,0,0,0,0,3,3,3,3,3,3,3,3,3,3,3,3,3,0,0,0,0,0,0,0,0
0,0,0,16,0,0,0,0,3,0,0,0,0,0,3,63,50,13,0,0,3,0,0,0,0,16,0,0,0
0,0,0,0,0,0,0,0,3,0,0,0,0,0,0,0,0,0,0,0,3,0,0,0,0,0,0,0,0
0,0,0,0,0,0,0,0,3,0,0,0,0,0,0,0,0,0,0,0,3,0,0,0,0,0,0,0,0
0,0,0,0,0,0,0,0,3,0,0,0,0,0,0,0,0,0,0,0,3,0,0,0,0,0,0,0,0
0,0,0,0,0,0,0,0,3,0,0,0,0,0,0,0,0,0,0,0,3,0,0,0,0,0,0,0,0
0,0,0,0,0,0,0,0,3,0,0,0,0,0,0,0,0,0,0,0,3,0,0,0,0,0,0,0,0
0,0,0,16,0,0,0,0,3,0,0,0,0,0,0,0,0,0,0,0,3,0,0,0,0,16,0,0,0
0,0,0,0,0,0,0,0,3,3,3,3,3,3,51,3,3,3,3,3,3,0,0,0,0,0,0,0,0
0,0,3,3,3,3,0,3,0,0,0,0,0,0,0,0,0,0,0,0,0,3,3,3,3,3,3,0,0
0,0,3,0,50,3,0,0,0,0,0,0,0,0,0,0,0,0,0,0,0,0,3,3,38,0,3,0,0
0,0,3,0,3,5,3,0,0,0,0,0,0,0,0,0,0,0,0,0,0,0,3,5,3,0,3,0,0
0,0,3,0,0,0,3,0,16,0,0,0,0,3,3,3,0,0,0,0,16,0,3,0,0,0,3,0,0
0,0,3,3,3,3,3,0,0,0,0,0,0,0,0,0,0,0,0,0,0,0,3,3,3,3,3,0,0
0,0,0,0,0,0,0,0,0,0,0,0,0,0,0,0,0,0,0,0,0,0,0,0,0,0,0,0,0
0,0,0,0,0,0,0,0,0,0,0,0,0,0,0,0,0,0,0,0,0,0,0,0,0,0,0,0,0
:endlayer
layer: 17
0,0,0,0,0,0,0,0,0,0,0,0,0,0,0,0,0,0,0,0,0,0,0,0,0,0,0,0,0
0,3,3,3,3,3,3,3,0,0,0,0,0,0,0,0,0,0,0,0,0,3,3,3,3,3,3,3,0
0,3,3,3,3,3,3,3,0,0,0,0,0,0,0,0,0,0,0,0,0,3,3,3,3,3,3,3,0
0,3,3,0,3,3,3,3,16,0,0,0,0,0,16,0,0,0,0,0,16,3,3,3,3,0,3,3,0
0,3,3,0,3,5,3,3,0,0,0,0,0,0,0,0,0,0,0,0,0,3,3,5,3,0,3,3,0
0,3,3,0,0,0,3,3,0,0,0,0,0,0,0,0,0,0,0,0,0,3,3,0,0,0,3,3,0
0,3,3,3,3,3,3,3,9,0,0,0,0,0,0,0,0,0,0,0,11,3,3,3,3,3,3,3,0
0,3,3,3,3,3,3,3,3,3,3,3,3,3,3,3,3,3,3,3,3,3,5,3,3,3,3,3,0
0,0,0,16,0,0,0,3,3,3,39,0,0,0,0,0,39,0,0,0,39,3,0,0,0,16,0,0,0
0,0,0,0,0,0,0,3,0,3,0,0,0,0,0,0,0,0,0,0,0,3,0,0,0,0,0,0,0
0,0,0,0,0,0,0,3,0,3,0,0,0,0,0,0,0,0,0,0,0,3,0,0,0,0,0,0,0
0,0,0,0,0,0,0,3,0,3,9,0,0,0,0,0,0,0,0,0,11,3,0,0,0,0,0,0,0
0,0,0,0,0,0,0,3,3,3,0,0,0,0,0,10,0,0,0,0,0,3,0,0,0,0,0,0,0
0,0,0,0,0,0,0,0,3,3,3,3,3,3,3,3,3,3,3,3,3,0,0,0,0,0,0,0,0
0,0,0,16,0,0,0,0,3,0,0,0,0,0,3,50,13,0,0,0,3,0,0,0,0,16,0,0,0
0,0,0,0,0,0,0,0,3,0,0,0,0,0,0,0,0,0,0,0,3,0,0,0,0,0,0,0,0
0,0,0,0,0,0,0,0,3,0,0,0,0,0,0,0,0,0,0,0,3,0,0,0,0,0,0,0,0
0,0,0,0,0,0,0,0,3,0,0,0,0,0,0,0,0,0,0,0,3,0,0,0,0,0,0,0,0
0,0,0,0,0,0,0,0,3,0,0,0,0,0,0,0,0,0,0,0,3,0,0,0,0,0,0,0,0
0,0,0,0,0,0,0,0,3,0,0,0,0,0,0,0,0,0,0,0,3,0,0,0,0,0,0,0,0
0,0,0,16,0,0,0,0,3,0,0,0,0,0,0,0,0,0,0,0,3,0,0,0,0,16,0,0,0
0,3,3,3,3,3,3,3,3,3,3,3,3,3,64,3,3,3,3,3,3,3,3,3,3,3,3,3,0
0,3,3,3,3,3,3,3,0,0,0,0,0,0,0,0,0,0,0,0,0,3,3,3,3,3,3,3,0
0,3,3,3,13,0,0,3,0,0,0,0,0,0,0,0,0,0,0,0,0,3,3,0,35,3,3,3,0
0,3,3,3,3,0,3,3,0,0,0,0,0,0,0,0,0,0,0,0,0,3,3,0,3,3,3,3,0
0,3,3,0,0,0,3,3,16,0,0,0,0,16,0,16,0,0,0,0,16,3,3,0,0,0,3,3,0
0,3,3,3,3,3,3,3,0,0,0,0,0,0,0,0,0,0,0,0,0,3,3,3,3,3,3,3,0
0,3,3,3,3,3,3,3,0,0,0,0,0,0,0,0,0,0,0,0,0,3,3,3,3,3,3,3,0
0,0,0,0,0,0,0,0,0,0,0,0,0,0,0,0,0,0,0,0,0,0,0,0,0,0,0,0,0
:endlayer
layer: 18
0,0,0,0,0,0,0,0,0,0,0,0,0,0,0,0,0,0,0,0,0,0,0,0,0,0,0,0,0
0,3,3,3,3,3,3,3,0,0,0,0,0,0,0,0,0,0,0,0,0,3,3,3,3,3,3,3,0
0,3,54,54,54,54,54,3,0,0,0,0,0,0,0,0,0,0,0,0,0,3,54,54,54,54,54,3,0
0,3,54,54,54,54,54,3,69,69,69,69,69,69,69,69,69,69,69,69,69,3,54,54,54,54,54,3,0
0,3,54,0,3,0,54,3,31,31,31,31,31,31,31,31,31,31,31,31,31,3,54,0,3,0,54,3,0
0,3,54,0,0,0,54,3,0,0,0,0,0,0,0,0,0,0,0,0,0,3,54,0,0,0,54,3,0
0,3,54,54,54,54,54,3,0,0,0,0,0,0,0,0,0,0,0,0,0,3,54,54,54,54,54,3,0
0,3,3,3,3,3,3,3,3,3,3,3,3,3,3,3,3,3,3,3,3,3,0,3,3,3,3,3,0
0,0,0,65,65,66,0,3,3,3,3,3,3,3,3,3,3,3,3,3,3,3,0,65,65,65,0,0,0
0,0,0,65,65,66,0,3,3,3,3,3,3,3,3,3,3,3,3,3,3,3,0,65,65,65,0,0,0
0,0,0,65,65,66,0,3,3,3,3,3,3,3,3,3,3,3,3,3,3,3,0,65,65,65,0,0,0
0,0,0,65,65,66,0,3,3,3,3,3,3,3,3,3,3,3,3,3,3,3,67,70,65,65,0,0,0
0,0,0,65,65,66,0,3,3,3,3,3,3,3,3,3,3,3,3,3,3,3,0,70,65,65,0,0,0
0,0,0,65,65,66,67,11,3,3,3,3,3,3,3,3,3,3,3,3,3,0,0,70,65,65,0,0,0
0,0,0,65,65,66,0,0,3,39,0,0,0,0,3,13,0,0,0,39,3,9,0,70,65,65,0,0,0
0,0,0,65,65,66,0,0,3,0,0,0,0,0,39,0,0,0,0,0,3,0,0,70,65,65,0,0,0
0,0,0,65,65,66,0,0,3,0,0,0,0,0,0,0,0,0,0,0,3,0,0,70,65,65,0,0,0
0,0,0,65,65,66,0,0,3,0,0,0,0,0,0,0,0,0,0,0,3,0,0,70,65,65,0,0,0
0,0,0,65,65,66,0,11,3,0,0,0,0,0,0,0,0,0,0,0,3,9,0,70,65,65,0,0,0
0,0,0,65,65,66,0,0,3,0,0,0,0,0,0,0,0,0,0,0,3,0,0,70,65,65,0,0,0
0,0,0,65,65,66,0,0,3,10,0,0,0,10,0,10,0,0,0,10,3,0,0,70,65,65,0,0,0
0,3,3,3,3,3,3,3,3,3,3,3,3,3,49,3,3,3,3,3,3,3,3,3,3,3,3,3,0
0,3,54,54,54,54,0,3,39,0,0,0,0,39,0,39,0,0,0,0,39,3,0,54,54,54,54,3,0
0,3,54,54,0,0,0,3,0,0,0,0,0,0,0,0,0,0,0,0,0,3,0,0,0,54,54,3,0
0,3,54,54,3,0,54,3,68,68,68,68,68,68,68,68,68,68,68,68,68,3,54,0,3,54,54,3,0
0,3,54,54,0,0,54,3,65,65,65,65,65,65,65,65,65,65,65,65,65,3,54,0,0,54,54,3,0
0,3,54,54,54,54,54,3,0,0,0,0,0,0,0,0,0,0,0,0,0,3,54,54,54,54,54,3,0
0,3,3,3,3,3,3,3,0,0,0,0,0,0,0,0,0,0,0,0,0,3,3,3,3,3,3,3,0
0,0,0,0,0,0,0,0,0,0,0,0,0,0,0,0,0,0,0,0,0,0,0,0,0,0,0,0,0
:endlayer
layer: 19
0,0,0,0,0,0,0,0,0,0,0,0,0,0,0,0,0,0,0,0,0,0,0,0,0,0,0,0,0
0,3,0,3,0,3,0,3,0,0,0,0,0,0,0,0,0,0,0,0,0,3,0,3,0,3,0,3,0
0,0,0,0,0,0,0,0,0,0,0,0,0,0,0,0,0,0,0,0,0,0,0,0,0,0,0,0,0
0,3,0,0,0,0,0,3,0,0,0,0,0,0,0,0,0,0,0,0,0,3,0,0,0,0,0,3,0
0,0,0,0,52,0,0,0,0,0,0,0,0,0,0,0,0,0,0,0,0,0,0,0,52,0,0,0,0
0,3,0,0,0,0,0,3,69,69,69,69,69,69,69,69,69,69,69,69,69,3,0,0,0,0,0,3,0
0,0,0,0,0,0,0,3,31,31,31,31,31,31,31,31,31,31,31,31,31,3,0,0,0,0,0,0,0
0,3,0,3,0,3,0,3,3,3,3,3,3,3,3,3,3,3,3,3,3,3,0,3,0,3,0,3,0
0,0,0,0,0,0,66,3,54,54,54,54,54,54,54,54,54,54,54,54,54,3,0,0,0,0,0,0,0
0,0,0,0,0,0,66,3,54,0,0,0,0,0,0,0,0,0,0,0,54,3,0,0,0,0,0,0,0
0,0,0,0,0,0,66,3,54,0,0,0,0,0,0,0,0,0,0,0,54,3,0,0,0,0,0,0,0
0,0,0,0,0,0,66,3,54,0,0,0,0,0,36,0,0,0,0,0,54,3,70,0,0,0,0,0,0
0,0,0,0,0,0,66,3,3,3,3,3,3,3,3,3,3,3,3,3,3,3,70,0,0,0,0,0,0
0,0,0,0,0,0,66,0,3,3,3,3,3,3,3,3,3,3,3,3,3,0,70,0,0,0,0,0,0
0,0,0,0,0,0,66,0,3,3,3,3,3,3,13,0,0,0,50,3,3,0,70,0,0,0,0,0,0
0,0,0,0,0,0,66,0,3,3,3,3,3,3,3,3,3,3,3,3,3,0,70,0,0,0,0,0,0
0,0,0,0,0,0,66,0,3,3,3,3,3,3,3,3,3,3,3,3,3,0,70,0,0,0,0,0,0
0,0,0,0,0,0,66,0,3,3,3,3,3,3,3,3,3,3,3,3,3,0,70,0,0,0,0,0,0
0,0,0,0,0,0,66,0,3,3,3,3,3,3,3,3,3,3,3,3,3,0,70,0,0,0,0,0,0
0,0,0,0,0,0,66,0,3,3,3,3,3,3,3,3,3,3,3,3,3,0,70,0,0,0,0,0,0
0,0,0,0,0,0,66,0,3,3,3,3,3,3,3,3,3,3,3,3,3,0,70,0,0,0,0,0,0
0,3,0,3,0,3,3,3,3,3,3,3,3,3,3,3,3,3,3,3,3,3,3,3,0,3,0,3,0
0,0,0,0,0,0,0,3,0,0,0,0,0,0,0,0,0,0,0,0,0,3,0,0,0,0,0,0,0
0,3,0,0,0,0,0,3,68,68,68,68,68,68,68,68,68,68,68,68,68,3,0,0,0,0,0,3,0
0,0,0,0,52,0,0,0,0,0,0,0,0,0,0,0,0,0,0,0,0,0,0,0,52,0,0,0,0
0,3,0,0,0,0,0,3,0,0,0,0,0,0,0,0,0,0,0,0,0,3,0,0,0,0,0,3,0
0,0,0,0,0,0,0,0,0,0,0,0,0,0,0,0,0,0,0,0,0,0,0,0,0,0,0,0,0
0,3,0,3,0,3,0,3,0,0,0,0,0,0,0,0,0,0,0,0,0,3,0,3,0,3,0,3,0
0,0,0,0,0,0,0,0,0,0,0,0,0,0,0,0,0,0,0,0,0,0,0,0,0,0,0,0,0
:endlayer
layer: 20
0,0,0,0,0,0,0,0,0,0,0,0,0,0,0,0,0,0,0,0,0,0,0,0,0,0,0,0,0
0,3,0,3,0,3,0,3,0,0,0,0,0,0,0,0,0,0,0,0,0,3,0,3,0,3,0,3,0
0,0,0,0,0,0,0,0,0,0,0,0,0,0,0,0,0,0,0,0,0,0,0,0,0,0,0,0,0
0,3,0,0,0,0,0,3,0,0,0,0,0,0,0,0,0,0,0,0,0,3,0,0,0,0,0,3,0
0,0,0,0,0,0,0,0,0,0,0,0,0,0,0,0,0,0,0,0,0,0,0,0,0,0,0,0,0
0,3,0,0,0,0,0,3,0,0,0,0,0,0,0,0,0,0,0,0,0,3,0,0,0,0,0,3,0
0,0,0,0,0,0,0,0,0,0,0,0,0,0,0,0,0,0,0,0,0,0,0,0,0,0,0,0,0
0,3,0,3,0,3,0,3,3,0,3,0,3,0,3,0,3,0,3,0,3,3,0,3,0,3,0,3,0
0,0,0,0,0,0,0,3,0,0,0,0,0,0,0,0,0,0,0,0,0,3,0,0,0,0,0,0,0
0,0,0,0,0,0,0,0,0,0,0,0,0,0,0,0,0,0,0,0,0,0,0,0,0,0,0,0,0
0,0,0,0,0,0,0,3,0,0,0,0,0,0,0,0,0,0,0,0,0,3,0,0,0,0,0,0,0
0,0,0,0,0,0,0,0,0,0,0,0,0,0,0,0,0,0,0,0,0,0,0,0,0,0,0,0,0
0,0,0,0,0,0,0,3,3,3,3,3,3,3,20,3,3,3,3,3,3,3,0,0,0,0,0,0,0
0,0,0,0,0,0,0,3,0,0,0,0,0,0,0,79,81,0,0,85,3,3,0,0,0,0,0,0,0
0,0,0,0,0,0,0,3,0,0,75,0,77,0,0,0,0,0,84,0,3,3,0,0,0,0,0,0,0
0,0,0,0,0,0,0,3,0,73,0,73,0,0,0,16,16,16,83,0,5,3,0,0,0,0,0,0,0
0,0,0,0,0,0,0,3,0,0,0,0,0,0,0,0,0,0,0,0,0,3,0,0,0,0,0,0,0
0,0,0,0,0,0,0,3,0,0,0,0,0,0,0,0,0,0,0,0,0,3,0,0,0,0,0,0,0
0,0,0,0,0,0,0,3,0,0,0,0,0,0,0,0,0,0,0,0,0,3,0,0,0,0,0,0,0
0,0,0,0,0,0,0,3,0,72,0,72,0,72,0,72,0,72,0,0,0,3,0,0,0,0,0,0,0
0,0,0,0,0,0,0,3,0,71,74,71,76,71,78,71,80,71,82,0,0,3,0,0,0,0,0,0,0
0,3,0,3,0,3,3,3,0,0,0,0,0,0,0,0,0,0,0,0,0,3,3,3,0,3,0,3,0
0,0,0,0,0,0,0,3,3,3,3,3,3,3,3,3,3,3,3,3,3,3,0,0,0,0,0,0,0
0,3,0,0,0,0,0,3,0,0,0,0,0,0,0,0,0,0,0,0,0,3,0,0,0,0,0,3,0
0,0,0,0,0,0,0,0,0,0,0,0,0,0,0,0,0,0,0,0,0,0,0,0,0,0,0,0,0
0,3,0,0,0,0,0,3,0,0,0,0,0,0,0,0,0,0,0,0,0,3,0,0,0,0,0,3,0
0,0,0,0,0,0,0,0,0,0,0,0,0,0,0,0,0,0,0,0,0,0,0,0,0,0,0,0,0
0,3,0,3,0,3,0,3,0,0,0,0,0,0,0,0,0,0,0,0,0,3,0,3,0,3,0,3,0
0,0,0,0,0,0,0,0,0,0,0,0,0,0,0,0,0,0,0,0,0,0,0,0,0,0,0,0,0
:endlayer
layer: 21
0,0,0,0,0,0,0,0,0,0,0,0,0,0,0,0,0,0,0,0,0,0,0,0,0,0,0,0,0
0,3,0,3,0,3,0,3,0,0,0,0,0,0,0,0,0,0,0,0,0,3,0,3,0,3,0,3,0
0,0,0,0,0,0,0,0,0,0,0,0,0,0,0,0,0,0,0,0,0,0,0,0,0,0,0,0,0
0,3,0,0,0,0,0,3,0,0,0,0,0,0,0,0,0,0,0,0,0,3,0,0,0,0,0,3,0
0,0,0,0,0,0,0,0,0,0,0,0,0,0,0,0,0,0,0,0,0,0,0,0,0,0,0,0,0
0,3,0,0,0,0,0,3,0,0,0,0,0,0,0,0,0,0,0,0,0,3,0,0,0,0,0,3,0
0,0,0,0,0,0,0,0,0,0,0,0,0,0,0,0,0,0,0,0,0,0,0,0,0,0,0,0,0
0,3,0,3,0,3,0,3,0,0,0,0,52,0,0,0,52,0,0,0,0,3,0,3,0,3,0,3,0
0,0,0,0,0,0,0,0,0,0,0,0,0,0,0,0,0,0,0,0,0,0,0,0,0,0,0,0,0
0,0,0,0,0,0,0,0,0,0,0,0,0,0,0,0,0,0,0,0,0,0,0,0,0,0,0,0,0
0,0,0,0,0,0,0,52,0,0,0,0,0,0,0,0,0,0,0,0,0,52,0,0,0,0,0,0,0
0,0,0,0,0,0,0,0,0,0,0,0,0,0,0,0,0,0,0,0,0,0,0,0,0,0,0,0,0
0,0,0,0,0,0,0,3,86,3,86,3,86,3,87,3,3,3,3,3,3,3,0,0,0,0,0,0,0
0,0,0,0,0,0,0,86,0,0,0,0,0,0,0,0,0,0,0,50,3,3,0,0,0,0,0,0,0
0,0,0,0,0,0,0,3,0,0,0,0,0,0,0,0,0,0,0,0,5,3,0,0,0,0,0,0,0
0,0,0,0,0,0,0,86,0,0,0,0,0,0,0,52,0,52,0,0,0,86,0,0,0,0,0,0,0
0,0,0,0,0,0,0,3,0,0,0,0,0,0,0,0,0,0,0,0,0,3,0,0,0,0,0,0,0
0,0,0,0,0,0,0,86,0,0,0,0,0,0,0,0,0,0,0,0,0,86,0,0,0,0,0,0,0
0,0,0,0,0,0,0,3,0,0,0,0,0,0,0,0,0,0,0,0,0,3,0,0,0,0,0,0,0
0,0,0,0,0,0,0,86,0,0,0,0,0,0,0,0,0,0,0,0,0,86,0,0,0,0,0,0,0
0,0,0,0,0,0,0,3,0,0,0,0,0,0,0,0,0,0,0,0,0,3,0,0,0,0,0,0,0
0,3,0,3,0,3,3,3,0,0,0,0,0,0,0,0,0,0,0,0,0,3,3,3,0,3,0,3,0
0,0,0,0,0,0,0,3,86,3,86,3,86,3,86,3,86,3,86,3,86,3,0,0,0,0,0,0,0
0,3,0,0,0,0,0,3,0,0,0,0,0,0,0,0,0,0,0,0,0,3,0,0,0,0,0,3,0
0,0,0,0,0,0,0,0,0,0,0,0,0,0,0,0,0,0,0,0,0,0,0,0,0,0,0,0,0
0,3,0,0,0,0,0,3,0,0,0,0,0,0,0,0,0,0,0,0,0,3,0,0,0,0,0,3,0
0,0,0,0,0,0,0,0,0,0,0,0,0,0,0,0,0,0,0,0,0,0,0,0,0,0,0,0,0
0,3,0,3,0,3,0,3,0,0,0,0,0,0,0,0,0,0,0,0,0,3,0,3,0,3,0,3,0
0,0,0,0,0,0,0,0,0,0,0,0,0,0,0,0,0,0,0,0,0,0,0,0,0,0,0,0,0
:endlayer
layer: 22
69,69,69,69,69,69,69,69,69,0,0,0,0,0,0,0,0,0,0,0,66,69,69,69,69,69,69,69,70
66,3,3,3,3,3,3,3,70,0,0,0,0,0,0,0,0,0,0,0,66,3,3,3,3,3,3,3,70
66,3,0,0,0,0,0,3,70,0,0,0,0,0,0,0,0,0,0,0,66,3,0,0,0,0,0,3,70
66,3,0,0,0,0,0,3,70,0,0,0,0,0,0,0,0,0,0,0,66,3,0,0,0,0,0,3,70
66,3,0,0,0,0,0,3,70,0,0,0,0,0,0,0,0,0,0,0,66,3,0,0,0,0,0,3,70
66,3,0,0,0,0,0,3,70,0,0,0,0,0,0,0,0,0,0,0,66,3,0,0,0,0,0,3,70
66,3,0,0,0,0,0,3,70,0,0,0,0,0,0,0,0,0,0,0,66,3,0,0,0,0,0,3,70
66,3,3,3,3,3,3,3,70,0,0,0,0,0,0,0,0,0,0,0,66,3,3,3,3,3,3,3,70
68,68,68,68,68,68,68,68,70,0,0,0,0,0,0,0,0,0,0,0,68,68,68,68,68,68,68,68,70
0,0,0,0,0,0,0,0,0,0,0,0,0,0,0,0,0,0,0,0,0,0,0,0,0,0,0,0,0
0,0,0,0,0,0,0,0,0,0,0,0,0,0,0,0,0,0,0,0,0,0,0,0,0,0,0,0,0
0,0,0,0,0,0,0,0,0,0,0,0,0,0,10,0,0,0,0,0,0,0,0,0,0,0,0,0,0
0,0,0,0,0,0,0,3,86,3,86,3,86,3,3,3,3,3,3,3,3,3,0,0,0,0,0,0,0
0,0,0,0,0,0,0,86,0,0,0,0,0,0,0,0,0,39,50,13,0,3,0,0,0,0,0,0,0
0,0,0,0,0,0,0,3,0,0,0,0,0,0,0,0,0,0,0,0,0,3,0,0,0,0,0,0,0
0,0,0,0,0,0,0,86,0,0,0,0,0,0,0,0,0,0,0,0,0,86,0,0,0,0,0,0,0
0,0,0,0,0,0,0,3,0,0,0,0,0,0,0,0,0,0,0,0,0,3,0,0,0,0,0,0,0
0,0,0,0,0,0,0,86,0,0,0,0,0,0,0,0,0,0,0,0,0,86,0,0,0,0,0,0,0
0,0,0,0,0,0,0,3,0,0,0,0,0,0,0,0,0,0,0,0,0,3,0,0,0,0,0,0,0
0,0,0,0,0,0,0,86,0,0,0,0,0,0,0,0,0,0,0,0,0,86,0,0,0,0,0,0,0
66,69,69,69,69,69,69,3,0,0,0,0,0,0,0,0,0,0,0,0,0,3,69,69,69,69,69,69,69
66,3,3,3,3,3,3,3,0,0,0,0,0,0,0,0,0,0,0,0,0,3,3,3,3,3,3,3,70
66,3,0,0,0,0,0,3,86,3,86,3,86,3,86,3,86,3,86,3,86,3,0,0,0,0,0,3,70
66,3,0,0,0,0,0,3,70,0,0,0,0,0,0,0,0,0,0,0,66,3,0,0,0,0,0,3,70
66,3,0,0,0,0,0,3,70,0,0,0,0,0,0,0,0,0,0,0,66,3,0,0,0,0,0,3,70
66,3,0,0,0,0,0,3,70,0,0,0,0,0,0,0,0,0,0,0,66,3,0,0,0,0,0,3,70
66,3,0,0,0,0,0,3,70,0,0,0,0,0,0,0,0,0,0,0,66,3,0,0,0,0,0,3,70
66,3,3,3,3,3,3,3,70,0,0,0,0,0,0,0,0,0,0,0,66,3,3,3,3,3,3,3,70
68,68,68,68,68,68,68,68,70,0,0,0,0,0,0,0,0,0,0,0,68,68,68,68,68,68,68,68,68
:endlayer
layer: 23
0,0,0,0,0,0,0,0,0,0,0,0,0,0,0,0,0,0,0,0,0,0,0,0,0,0,0,0,0
0,69,69,69,69,69,69,69,0,0,0,0,0,0,0,0,0,0,0,0,0,66,69,69,69,69,69,70,0
0,66,88,0,0,0,88,70,0,0,0,0,0,0,0,0,0,0,0,0,0,66,88,0,0,0,88,70,0
0,66,0,0,0,0,0,70,0,0,0,0,0,0,0,0,0,0,0,0,0,66,0,0,0,0,0,70,0
0,66,0,0,0,0,0,70,0,0,0,0,0,0,0,0,0,0,0,0,0,66,0,0,0,0,0,70,0
0,66,0,0,0,0,0,70,0,0,0,0,0,0,0,0,0,0,0,0,0,66,0,0,0,0,0,70,0
0,66,88,0,0,0,88,70,0,0,0,0,0,0,0,0,0,0,0,0,0,66,88,0,0,0,88,70,0
0,68,68,68,68,68,68,70,0,0,0,0,0,0,0,0,0,0,0,0,0,68,68,68,68,68,68,68,0
0,0,0,0,0,0,0,0,0,0,0,0,0,0,0,0,0,0,0,0,0,0,0,0,0,0,0,0,0
0,0,0,0,0,0,0,0,0,0,0,0,0,0,0,0,0,0,0,0,0,0,0,0,0,0,0,0,0
0,0,0,0,0,0,0,0,0,0,0,0,0,0,0,0,0,0,0,0,0,0,0,0,0,0,0,0,0
0,0,0,0,0,0,0,0,0,0,0,0,0,0,0,0,0,0,0,0,0,0,0,0,0,0,0,0,0
0,0,0,0,0,0,0,3,86,3,86,3,86,3,3,3,3,3,3,3,3,3,0,0,0,0,0,0,0
0,0,0,0,0,0,0,86,0,0,0,0,0,0,0,0,0,50,13,0,0,3,0,0,0,0,0,0,0
0,0,0,0,0,0,0,3,0,0,0,0,0,0,0,0,0,0,0,0,0,3,0,0,0,0,0,0,0
0,0,0,0,0,0,0,86,0,0,0,0,0,0,0,0,0,0,0,0,0,86,0,0,0,0,0,0,0
0,0,0,0,0,0,0,3,0,0,0,0,0,0,0,0,0,0,0,0,0,3,0,0,0,0,0,0,0
0,0,0,0,0,0,0,86,0,0,0,0,0,0,0,0,0,0,0,0,0,86,0,0,0,0,0,0,0
0,0,0,0,0,0,0,3,0,0,0,0,0,0,0,0,0,0,0,0,0,3,0,0,0,0,0,0,0
0,0,0,0,0,0,0,86,0,0,0,0,0,0,0,0,0,0,0,0,0,86,0,0,0,0,0,0,0
0,0,0,0,0,0,0,3,0,0,0,0,0,0,0,0,0,0,0,0,0,3,0,0,0,0,0,0,0
0,69,69,69,69,69,69,3,0,0,0,0,0,0,0,0,0,0,0,0,0,3,69,69,69,69,69,70,0
0,66,3,0,0,0,3,3,86,3,86,3,86,3,86,3,86,3,86,3,86,3,3,0,0,0,3,70,0
0,66,0,0,0,0,0,70,0,0,0,0,0,0,0,0,0,0,0,0,0,66,0,0,0,0,0,70,0
0,66,0,0,0,0,0,70,0,0,0,0,0,0,0,0,0,0,0,0,0,66,0,0,0,0,0,70,0
0,66,0,0,0,0,0,70,0,0,0,0,0,0,0,0,0,0,0,0,0,66,0,0,0,0,0,70,0
0,66,3,0,0,0,3,70,0,0,0,0,0,0,0,0,0,0,0,0,0,66,3,0,0,0,3,70,0
0,68,68,68,68,68,68,70,0,0,0,0,0,0,0,0,0,0,0,0,0,66,68,68,68,68,68,68,0
0,0,0,0,0,0,0,0,0,0,0,0,0,0,0,0,0,0,0,0,0,0,0,0,0,0,0,0,0
:endlayer
layer: 24
0,0,0,0,0,0,0,0,0,0,0,0,0,0,0,0,0,0,0,0,0,0,0,0,0,0,0,0,0
0,0,0,0,0,0,0,0,0,0,0,0,0,0,0,0,0,0,0,0,0,0,0,0,0,0,0,0,0
0,0,69,69,69,69,69,0,0,0,0,0,0,0,0,0,0,0,0,0,0,0,69,69,69,69,69,0,0
0,0,66,88,88,88,70,0,0,0,0,0,0,0,0,0,0,0,0,0,0,0,66,88,88,88,70,0,0
0,0,66,88,88,88,70,0,0,0,0,0,0,0,0,0,0,0,0,0,0,0,66,88,88,88,70,0,0
0,0,66,88,88,88,70,0,0,0,0,0,0,0,0,0,0,0,0,0,0,0,66,88,88,88,70,0,0
0,0,66,68,68,68,68,0,0,0,0,0,0,0,0,0,0,0,0,0,0,0,66,68,68,68,68,0,0
0,0,0,0,0,0,0,0,0,0,0,0,0,0,0,0,0,0,0,0,0,0,0,0,0,0,0,0,0
0,0,0,0,0,0,0,0,0,0,0,0,0,0,0,0,0,0,0,0,0,0,0,0,0,0,0,0,0
0,0,0,0,0,0,0,0,0,0,0,0,0,0,0,0,0,0,0,0,0,0,0,0,0,0,0,0,0
0,0,0,0,0,0,0,0,0,0,0,0,0,0,0,0,0,0,0,0,0,0,0,0,0,0,0,0,0
0,0,0,0,0,0,0,10,0,0,0,0,0,0,0,0,0,0,0,0,0,10,0,0,0,0,0,0,0
0,0,0,0,0,0,11,3,3,3,3,3,3,3,3,3,3,3,3,3,3,3,9,0,0,0,0,0,0
0,0,0,0,0,0,0,3,39,0,0,39,0,0,39,0,50,13,0,0,11,3,0,0,0,0,0,0,0
0,0,0,0,0,0,0,3,0,0,0,0,0,0,0,0,0,0,0,0,0,3,0,0,0,0,0,0,0
0,0,0,0,0,0,0,3,0,0,0,0,0,0,0,0,0,0,0,0,0,3,0,0,0,0,0,0,0
0,0,0,0,0,0,0,3,0,0,0,0,0,0,0,0,0,0,0,0,0,3,0,0,0,0,0,0,0
0,0,0,0,0,0,0,3,0,0,0,0,0,0,0,0,0,0,0,0,11,3,0,0,0,0,0,0,0
0,0,0,0,0,0,0,3,9,0,0,0,0,0,0,0,0,0,0,0,0,3,0,0,0,0,0,0,0
0,0,0,0,0,0,0,3,0,0,0,0,0,0,0,0,0,0,0,0,0,3,0,0,0,0,0,0,0
0,0,0,0,0,0,0,3,0,0,0,0,0,0,0,0,0,0,0,0,0,3,0,0,0,0,0,0,0
0,0,0,0,0,0,0,3,10,0,0,10,0,0,10,0,0,10,0,0,10,3,0,0,0,0,0,0,0
0,0,69,69,69,69,69,3,3,3,3,3,3,3,3,3,3,3,3,3,3,3,69,69,69,69,70,0,0
0,0,66,88,88,88,70,39,0,0,0,0,0,0,0,0,0,0,0,0,0,39,66,88,88,88,70,0,0
0,0,66,88,88,88,70,0,0,0,0,0,0,0,0,0,0,0,0,0,0,0,66,88,88,88,70,0,0
0,0,66,88,88,88,70,0,0,0,0,0,0,0,0,0,0,0,0,0,0,0,66,88,88,88,70,0,0
0,0,66,68,68,68,68,0,0,0,0,0,0,0,0,0,0,0,0,0,0,0,68,68,68,68,70,0,0
0,0,0,0,0,0,0,0,0,0,0,0,0,0,0,0,0,0,0,0,0,0,0,0,0,0,0,0,0
0,0,0,0,0,0,0,0,0,0,0,0,0,0,0,0,0,0,0,0,0,0,0,0,0,0,0,0,0
:endlayer
layer: 25
0,0,0,0,0,0,0,0,0,0,0,0,0,0,0,0,0,0,0,0,0,0,0,0,0,0,0,0,0
0,0,0,0,0,0,0,0,0,0,0,0,0,0,0,0,0,0,0,0,0,0,0,0,0,0,0,0,0
0,0,0,0,0,0,0,0,0,0,0,0,0,0,0,0,0,0,0,0,0,0,0,0,0,0,0,0,0
0,0,0,66,69,70,0,0,0,0,0,0,0,0,0,0,0,0,0,0,0,0,0,69,69,70,0,0,0
0,0,0,66,88,70,0,0,0,0,0,0,0,0,0,0,0,0,0,0,0,0,0,66,88,70,0,0,0
0,0,0,68,68,68,0,0,0,0,0,0,0,0,0,0,0,0,0,0,0,0,0,66,68,70,0,0,0
0,0,0,0,0,0,0,0,0,0,0,0,0,0,0,0,0,0,0,0,0,0,0,0,0,0,0,0,0
0,0,0,0,0,0,0,0,0,0,0,0,0,0,0,0,0,0,0,0,0,0,0,0,0,0,0,0,0
0,0,0,0,0,0,0,0,0,0,0,0,0,0,0,0,0,0,0,0,0,0,0,0,0,0,0,0,0
0,0,0,0,0,0,0,0,0,0,0,0,0,0,0,0,0,0,0,0,0,0,0,0,0,0,0,0,0
0,0,0,0,0,0,0,0,0,0,0,0,0,0,0,0,0,0,0,0,0,0,0,0,0,0,0,0,0
0,0,0,0,0,0,50,12,12,12,12,12,12,12,12,12,12,12,12,12,12,12,12,0,0,0,0,0,0
0,0,0,0,0,0,50,3,3,3,3,3,3,3,3,3,3,3,3,3,3,3,38,0,0,0,0,0,0
0,0,0,0,0,0,50,3,3,3,3,3,3,3,3,3,13,0,0,0,50,3,38,0,0,0,0,0,0
0,0,0,0,0,0,50,3,3,3,3,3,3,3,3,3,3,3,3,3,3,3,38,0,0,0,0,0,0
0,0,0,0,0,0,50,3,3,3,3,3,3,3,3,3,3,3,3,3,3,3,38,0,0,0,0,0,0
0,0,0,0,0,0,50,3,3,3,3,3,3,3,3,3,3,3,3,3,3,3,38,0,0,0,0,0,0
0,0,0,0,0,0,50,3,3,3,3,3,3,3,3,3,3,3,3,3,3,3,38,0,0,0,0,0,0
0,0,0,0,0,0,50,3,3,3,3,3,3,3,3,3,3,3,3,3,3,3,38,0,0,0,0,0,0
0,0,0,0,0,0,50,3,3,3,3,3,3,3,3,3,3,3,3,3,3,3,38,0,0,0,0,0,0
0,0,0,0,0,0,50,3,3,3,3,3,3,3,3,3,3,3,3,3,3,3,38,0,0,0,0,0,0
0,0,0,0,0,0,50,3,3,3,3,3,3,3,3,3,3,3,3,3,3,3,38,0,0,0,0,0,0
0,0,0,0,0,0,50,3,3,3,3,3,3,3,3,3,3,3,3,3,3,3,38,0,0,0,0,0,0
0,0,0,66,69,69,50,37,37,37,37,37,37,37,37,37,37,37,37,37,37,37,38,66,69,70,0,0,0
0,0,0,66,88,70,0,0,0,0,0,0,0,0,0,0,0,0,0,0,0,0,0,66,88,70,0,0,0
0,0,0,66,68,68,0,0,0,0,0,0,0,0,0,0,0,0,0,0,0,0,0,66,68,68,0,0,0
0,0,0,0,0,0,0,0,0,0,0,0,0,0,0,0,0,0,0,0,0,0,0,0,0,0,0,0,0
0,0,0,0,0,0,0,0,0,0,0,0,0,0,0,0,0,0,0,0,0,0,0,0,0,0,0,0,0
0,0,0,0,0,0,0,0,0,0,0,0,0,0,0,0,0,0,0,0,0,0,0,0,0,0,0,0,0
:endlayer
layer: 26
0,0,0,0,0,0,0,0,0,0,0,0,0,0,0,0,0,0,0,0,0,0,0,0,0,0,0,0,0
0,0,0,0,0,0,0,0,0,0,0,0,0,0,0,0,0,0,0,0,0,0,0,0,0,0,0,0,0
0,0,0,0,0,0,0,0,0,0,0,0,0,0,0,0,0,0,0,0,0,0,0,0,0,0,0,0,0
0,0,0,0,0,0,0,0,0,0,0,0,0,0,0,0,0,0,0,0,0,0,0,0,0,0,0,0,0
0,0,0,0,52,0,0,0,0,0,0,0,0,0,0,0,0,0,0,0,0,0,0,0,52,0,0,0,0
0,0,0,0,0,0,0,0,0,0,0,0,0,0,0,0,0,0,0,0,0,0,0,0,0,0,0,0,0
0,0,0,0,0,0,0,0,0,0,0,0,0,0,0,0,0,0,0,0,0,0,0,0,0,0,0,0,0
0,0,0,0,0,0,0,0,0,0,0,0,0,0,0,0,0,0,0,0,0,0,0,0,0,0,0,0,0
0,0,0,0,0,0,0,0,0,0,0,0,0,0,0,0,0,0,0,0,0,0,0,0,0,0,0,0,0
0,0,0,0,0,0,0,0,0,0,0,0,0,0,0,0,0,0,0,0,0,0,0,0,0,0,0,0,0
0,0,0,0,0,0,0,0,0,0,0,0,0,0,0,0,0,0,0,0,0,0,0,0,0,0,0,0,0
0,0,0,0,0,0,3,3,3,3,3,3,3,3,3,3,3,3,3,3,3,3,3,0,0,0,0,0,0
0,0,0,0,0,0,3,0,0,0,0,0,0,0,3,0,16,0,0,0,16,95,3,0,0,0,0,0,0
0,0,0,0,0,0,3,0,0,0,0,0,0,0,25,0,0,0,0,0,16,0,3,0,0,0,0,0,0
0,0,0,0,0,0,3,0,0,0,0,0,0,0,3,0,16,16,16,16,16,0,3,0,0,0,0,0,0
0,0,0,0,0,0,3,0,0,0,0,0,0,36,3,0,0,0,0,0,0,0,3,0,0,0,0,0,0
0,0,0,0,0,0,3,0,0,0,0,0,0,3,3,0,0,0,0,0,0,0,3,0,0,0,0,0,0
0,0,0,0,0,0,3,0,0,0,0,0,90,3,3,0,0,0,0,0,0,0,3,0,0,0,0,0,0
0,0,0,0,0,0,3,0,0,0,0,0,89,3,3,0,0,0,0,0,0,0,3,0,0,0,0,0,0
0,0,0,0,0,0,3,0,0,0,0,0,0,25,0,0,0,0,0,0,0,0,3,0,0,0,0,0,0
0,0,0,0,0,0,3,0,0,0,0,0,0,3,3,0,0,0,0,0,0,0,3,0,0,0,0,0,0
0,0,0,0,0,0,3,0,0,0,0,0,0,92,3,94,0,0,0,0,0,0,3,0,0,0,0,0,0
0,0,0,0,0,0,3,0,0,0,0,0,0,91,3,93,0,0,0,0,0,0,3,0,0,0,0,0,0
0,0,0,0,0,0,3,3,3,3,3,3,3,3,3,3,3,3,3,3,3,3,3,0,0,0,0,0,0
0,0,0,0,52,0,0,0,0,0,0,0,0,0,0,0,0,0,0,0,0,0,0,0,52,0,0,0,0
0,0,0,0,0,0,0,0,0,0,0,0,0,0,0,0,0,0,0,0,0,0,0,0,0,0,0,0,0
0,0,0,0,0,0,0,0,0,0,0,0,0,0,0,0,0,0,0,0,0,0,0,0,0,0,0,0,0
0,0,0,0,0,0,0,0,0,0,0,0,0,0,0,0,0,0,0,0,0,0,0,0,0,0,0,0,0
0,0,0,0,0,0,0,0,0,0,0,0,0,0,0,0,0,0,0,0,0,0,0,0,0,0,0,0,0
:endlayer
layer: 27
0,0,0,0,0,0,0,0,0,0,0,0,0,0,0,0,0,0,0,0,0,0,0,0,0,0,0,0,0
0,0,0,0,0,0,0,0,0,0,0,0,0,0,0,0,0,0,0,0,0,0,0,0,0,0,0,0,0
0,0,0,0,0,0,0,0,0,0,0,0,0,0,0,0,0,0,0,0,0,0,0,0,0,0,0,0,0
0,0,0,0,0,0,0,0,0,0,0,0,0,0,0,0,0,0,0,0,0,0,0,0,0,0,0,0,0
0,0,0,0,0,0,0,0,0,0,0,0,0,0,0,0,0,0,0,0,0,0,0,0,0,0,0,0,0
0,0,0,0,0,0,0,0,0,0,0,0,0,0,0,0,0,0,0,0,0,0,0,0,0,0,0,0,0
0,0,0,0,0,0,0,0,0,0,0,0,0,0,0,0,0,0,0,0,0,0,0,0,0,0,0,0,0
0,0,0,0,0,0,0,0,0,0,0,0,0,0,0,0,0,0,0,0,0,0,0,0,0,0,0,0,0
0,0,0,0,0,0,0,0,0,0,0,0,0,0,0,0,0,0,0,0,0,0,0,0,0,0,0,0,0
0,0,0,0,0,0,0,0,0,0,0,0,0,0,0,0,0,0,0,0,0,0,0,0,0,0,0,0,0
0,0,0,0,0,0,0,0,0,0,0,0,0,0,0,0,0,0,0,0,0,0,0,0,0,0,0,0,0
0,0,0,0,0,0,3,86,3,86,3,86,3,86,3,86,3,86,3,86,3,86,3,0,0,0,0,0,0
0,0,0,0,0,0,86,0,0,0,0,0,0,0,3,0,0,0,0,0,0,0,86,0,0,0,0,0,0
0,0,0,0,0,0,3,0,0,0,0,0,0,0,97,0,0,0,0,0,0,0,3,0,0,0,0,0,0
0,0,0,0,0,0,86,0,0,0,0,0,0,0,3,0,0,0,0,0,0,0,86,0,0,0,0,0,0
0,0,0,0,0,0,3,0,0,0,0,0,0,0,3,0,0,0,0,0,0,0,3,0,0,0,0,0,0
0,0,0,0,0,0,86,0,0,0,0,0,0,36,3,0,0,0,0,0,0,0,86,0,0,0,0,0,0
0,0,0,0,0,0,3,0,0,0,0,0,0,3,3,0,0,0,0,0,0,0,3,0,0,0,0,0,0
0,0,0,0,0,0,86,0,0,0,0,0,0,3,3,0,0,0,0,0,0,0,86,0,0,0,0,0,0
0,0,0,0,0,0,3,0,0,0,0,0,0,96,0,0,0,0,0,0,0,0,3,0,0,0,0,0,0
0,0,0,0,0,0,86,0,0,0,0,0,0,3,3,0,0,0,0,0,0,0,86,0,0,0,0,0,0
0,0,0,0,0,0,3,0,0,0,0,0,0,0,3,0,0,0,0,0,0,0,3,0,0,0,0,0,0
0,0,0,0,0,0,86,0,0,0,0,0,0,0,3,0,0,0,0,0,0,0,86,0,0,0,0,0,0
0,0,0,0,0,0,3,86,3,86,3,86,3,86,3,86,3,86,3,86,3,86,3,0,0,0,0,0,0
0,0,0,0,0,0,0,0,0,0,0,0,0,0,0,0,0,0,0,0,0,0,0,0,0,0,0,0,0
0,0,0,0,0,0,0,0,0,0,0,0,0,0,0,0,0,0,0,0,0,0,0,0,0,0,0,0,0
0,0,0,0,0,0,0,0,0,0,0,0,0,0,0,0,0,0,0,0,0,0,0,0,0,0,0,0,0
0,0,0,0,0,0,0,0,0,0,0,0,0,0,0,0,0,0,0,0,0,0,0,0,0,0,0,0,0
0,0,0,0,0,0,0,0,0,0,0,0,0,0,0,0,0,0,0,0,0,0,0,0,0,0,0,0,0
:endlayer
layer: 28
0,0,0,0,0,0,0,0,0,0,0,0,0,0,0,0,0,0,0,0,0,0,0,0,0,0,0,0,0
0,0,0,0,0,0,0,0,0,0,0,0,0,0,0,0,0,0,0,0,0,0,0,0,0,0,0,0,0
0,0,0,0,0,0,0,0,0,0,0,0,0,0,0,0,0,0,0,0,0,0,0,0,0,0,0,0,0
0,0,0,0,0,0,0,0,0,0,0,0,0,0,0,0,0,0,0,0,0,0,0,0,0,0,0,0,0
0,0,0,0,0,0,0,0,0,0,0,0,0,0,0,0,0,0,0,0,0,0,0,0,0,0,0,0,0
0,0,0,0,0,0,0,0,0,0,0,0,0,0,0,0,0,0,0,0,0,0,0,0,0,0,0,0,0
0,0,0,0,0,0,0,0,0,0,0,0,0,0,0,0,0,0,0,0,0,0,0,0,0,0,0,0,0
0,0,0,0,0,0,0,0,0,0,0,0,0,0,0,0,0,0,0,0,0,0,0,0,0,0,0,0,0
0,0,0,0,0,0,0,0,0,0,0,0,0,0,0,0,0,0,0,0,0,0,0,0,0,0,0,0,0
0,0,0,0,0,0,0,0,0,0,0,0,0,0,0,0,0,0,0,0,0,0,0,0,0,0,0,0,0
0,0,0,0,0,0,0,0,0,0,0,0,0,0,0,0,0,0,0,0,0,0,0,0,0,0,0,0,0
0,0,0,0,0,0,3,86,3,86,3,86,3,86,3,86,3,86,3,86,3,86,3,0,0,0,0,0,0
0,0,0,0,0,0,86,0,0,0,0,0,0,0,3,0,0,0,0,0,0,0,86,0,0,0,0,0,0
0,0,0,0,0,0,3,0,0,0,0,0,0,0,3,9,0,0,0,0,0,0,3,0,0,0,0,0,0
0,0,0,0,0,0,86,0,0,0,0,0,0,0,3,0,0,0,0,0,0,0,86,0,0,0,0,0,0
0,0,0,0,0,0,3,0,0,0,0,0,0,0,3,0,0,0,0,0,0,0,3,0,0,0,0,0,0
0,0,0,0,0,0,86,0,0,0,0,0,0,0,3,0,0,0,0,0,0,0,86,0,0,0,0,0,0
0,0,0,0,0,0,3,0,0,0,0,0,0,36,3,0,0,0,0,0,0,0,3,0,0,0,0,0,0
0,0,0,0,0,0,86,0,0,0,0,0,0,3,3,0,0,0,0,0,0,0,86,0,0,0,0,0,0
0,0,0,0,0,0,3,0,0,0,0,0,11,3,3,9,0,0,0,0,0,0,3,0,0,0,0,0,0
0,0,0,0,0,0,86,0,0,0,0,0,0,3,3,0,0,0,0,0,0,0,86,0,0,0,0,0,0
0,0,0,0,0,0,3,0,0,0,0,0,0,0,3,0,0,0,0,0,0,0,3,0,0,0,0,0,0
0,0,0,0,0,0,86,0,0,0,0,0,0,0,3,0,0,0,0,0,0,0,86,0,0,0,0,0,0
0,0,0,0,0,0,3,86,3,86,3,86,3,86,3,86,3,86,3,86,3,86,3,0,0,0,0,0,0
0,0,0,0,0,0,0,0,0,0,0,0,0,0,0,0,0,0,0,0,0,0,0,0,0,0,0,0,0
0,0,0,0,0,0,0,0,0,0,0,0,0,0,0,0,0,0,0,0,0,0,0,0,0,0,0,0,0
0,0,0,0,0,0,0,0,0,0,0,0,0,0,0,0,0,0,0,0,0,0,0,0,0,0,0,0,0
0,0,0,0,0,0,0,0,0,0,0,0,0,0,0,0,0,0,0,0,0,0,0,0,0,0,0,0,0
0,0,0,0,0,0,0,0,0,0,0,0,0,0,0,0,0,0,0,0,0,0,0,0,0,0,0,0,0
:endlayer
layer: 29
0,0,0,0,0,0,0,0,0,0,0,0,0,0,0,0,0,0,0,0,0,0,0,0,0,0,0,0,0
0,0,0,0,0,0,0,0,0,0,0,0,0,0,0,0,0,0,0,0,0,0,0,0,0,0,0,0,0
0,0,0,0,0,0,0,0,0,0,0,0,0,0,0,0,0,0,0,0,0,0,0,0,0,0,0,0,0
0,0,0,0,0,0,0,0,0,0,0,0,0,0,0,0,0,0,0,0,0,0,0,0,0,0,0,0,0
0,0,0,0,0,0,0,0,0,0,0,0,0,0,0,0,0,0,0,0,0,0,0,0,0,0,0,0,0
0,0,0,0,0,0,0,0,0,0,0,0,0,0,0,0,0,0,0,0,0,0,0,0,0,0,0,0,0
0,0,0,0,0,0,0,0,0,0,0,0,0,0,0,0,0,0,0,0,0,0,0,0,0,0,0,0,0
0,0,0,0,0,0,0,0,0,0,0,0,0,0,0,0,0,0,0,0,0,0,0,0,0,0,0,0,0
0,0,0,0,0,0,0,0,0,0,0,0,0,0,0,0,0,0,0,0,0,0,0,0,0,0,0,0,0
0,0,0,0,0,0,0,0,0,0,0,0,0,0,0,0,0,0,0,0,0,0,0,0,0,0,0,0,0
0,0,0,0,0,0,0,0,0,0,0,0,0,0,0,0,0,0,0,0,0,0,0,0,0,0,0,0,0
0,0,0,0,0,0,3,3,3,3,3,3,3,3,3,3,3,3,3,3,3,3,3,0,0,0,0,0,0
0,0,0,0,0,0,3,9,0,0,0,0,0,11,3,39,0,0,0,0,0,39,3,0,0,0,0,0,0
0,0,0,0,0,0,3,0,0,0,0,0,0,0,3,0,0,0,0,0,0,0,3,0,0,0,0,0,0
0,0,0,0,0,0,3,0,0,0,0,0,0,0,3,0,0,0,0,0,0,0,3,0,0,0,0,0,0
0,0,0,0,0,0,3,0,0,0,0,0,0,0,3,0,0,0,0,0,0,0,3,0,0,0,0,0,0
0,0,0,0,0,0,3,0,0,0,0,0,0,0,3,0,0,0,0,0,0,0,3,0,0,0,0,0,0
0,0,0,0,0,0,3,0,0,0,0,0,0,0,3,0,0,0,0,0,0,0,3,0,0,0,0,0,0
0,0,0,0,0,0,3,0,0,0,0,0,0,36,3,0,0,0,0,0,0,0,3,0,0,0,0,0,0
0,0,0,0,0,0,3,0,0,0,0,0,0,3,3,0,0,0,0,0,0,0,3,0,0,0,0,0,0
0,0,0,0,0,0,3,0,0,0,0,0,0,3,3,0,0,0,0,0,0,0,3,0,0,0,0,0,0
0,0,0,0,0,0,3,0,0,0,0,0,0,0,3,0,0,0,0,0,0,0,3,0,0,0,0,0,0
0,0,0,0,0,0,3,10,0,0,0,0,0,10,3,10,0,0,0,0,0,10,3,0,0,0,0,0,0
0,0,0,0,0,0,3,3,3,3,3,3,3,3,3,3,3,3,3,3,3,3,3,0,0,0,0,0,0
0,0,0,0,0,0,0,0,0,0,0,0,0,0,0,0,0,0,0,0,0,0,0,0,0,0,0,0,0
0,0,0,0,0,0,0,0,0,0,0,0,0,0,0,0,0,0,0,0,0,0,0,0,0,0,0,0,0
0,0,0,0,0,0,0,0,0,0,0,0,0,0,0,0,0,0,0,0,0,0,0,0,0,0,0,0,0
0,0,0,0,0,0,0,0,0,0,0,0,0,0,0,0,0,0,0,0,0,0,0,0,0,0,0,0,0
0,0,0,0,0,0,0,0,0,0,0,0,0,0,0,0,0,0,0,0,0,0,0,0,0,0,0,0,0
:endlayer
layer: 30
0,0,0,0,0,0,0,0,0,0,0,0,0,0,0,0,0,0,0,0,0,0,0,0,0,0,0,0,0
0,0,0,0,0,0,0,0,0,0,0,0,0,0,0,0,0,0,0,0,0,0,0,0,0,0,0,0,0
0,0,0,0,0,0,0,0,0,0,0,0,0,0,0,0,0,0,0,0,0,0,0,0,0,0,0,0,0
0,0,0,0,0,0,0,0,0,0,0,0,0,0,0,0,0,0,0,0,0,0,0,0,0,0,0,0,0
0,0,0,0,0,0,0,0,0,0,0,0,0,0,0,0,0,0,0,0,0,0,0,0,0,0,0,0,0
0,0,0,0,0,0,0,0,0,0,0,0,0,0,0,0,0,0,0,0,0,0,0,0,0,0,0,0,0
0,0,0,0,0,0,0,0,0,0,0,0,0,0,0,0,0,0,0,0,0,0,0,0,0,0,0,0,0
0,0,0,0,0,0,0,0,0,0,0,0,0,0,0,0,0,0,0,0,0,0,0,0,0,0,0,0,0
0,0,0,0,0,0,0,0,0,0,0,0,0,0,0,0,0,0,0,0,0,0,0,0,0,0,0,0,0
0,0,0,0,0,0,0,0,0,0,0,0,0,0,0,0,0,0,0,0,0,0,0,0,0,0,0,0,0
0,0,0,0,0,66,69,69,69,69,69,69,69,69,69,69,69,69,69,69,69,69,69,70,0,0,0,0,0
0,0,0,0,0,66,3,3,3,3,3,3,3,3,3,3,3,3,3,3,3,3,3,70,0,0,0,0,0
0,0,0,0,0,66,3,0,0,0,0,0,0,0,3,0,0,0,0,0,0,0,3,70,0,0,0,0,0
0,0,0,0,0,66,3,0,0,0,0,0,0,0,3,0,0,0,0,0,0,0,3,70,0,0,0,0,0
0,0,0,0,0,66,3,0,0,0,0,0,0,0,3,0,0,0,0,0,0,0,3,70,0,0,0,0,0
0,0,0,0,0,66,3,0,0,0,0,0,0,0,3,0,0,0,0,0,0,0,3,70,0,0,0,0,0
0,0,0,0,0,66,3,0,0,0,0,0,0,0,3,0,0,0,0,0,0,0,3,70,0,0,0,0,0
0,0,0,0,0,66,3,0,0,0,0,0,0,0,3,0,0,0,0,0,0,0,3,70,0,0,0,0,0
0,0,0,0,0,66,3,0,0,0,0,0,0,0,3,0,0,0,0,0,0,0,3,70,0,0,0,0,0
0,0,0,0,0,66,3,0,0,0,0,0,0,36,3,0,0,0,0,0,0,0,3,70,0,0,0,0,0
0,0,0,0,0,66,3,0,0,0,0,0,0,3,3,0,0,0,0,0,0,0,3,70,0,0,0,0,0
0,0,0,0,0,66,3,0,0,0,0,0,0,0,3,0,0,0,0,0,0,0,3,70,0,0,0,0,0
0,0,0,0,0,66,3,0,0,0,0,0,0,0,3,0,0,0,0,0,0,0,3,70,0,0,0,0,0
0,0,0,0,0,66,3,3,3,3,3,3,3,3,3,3,3,3,3,3,3,3,3,70,0,0,0,0,0
0,0,0,0,0,66,68,68,68,68,68,68,68,68,68,68,68,68,68,68,68,68,68,68,0,0,0,0,0
0,0,0,0,0,0,0,0,0,0,0,0,0,0,0,0,0,0,0,0,0,0,0,0,0,0,0,0,0
0,0,0,0,0,0,0,0,0,0,0,0,0,0,0,0,0,0,0,0,0,0,0,0,0,0,0,0,0
0,0,0,0,0,0,0,0,0,0,0,0,0,0,0,0,0,0,0,0,0,0,0,0,0,0,0,0,0
0,0,0,0,0,0,0,0,0,0,0,0,0,0,0,0,0,0,0,0,0,0,0,0,0,0,0,0,0
:endlayer
layer: 31
0,0,0,0,0,0,0,0,0,0,0,0,0,0,0,0,0,0,0,0,0,0,0,0,0,0,0,0,0
0,0,0,0,0,0,0,0,0,0,0,0,0,0,0,0,0,0,0,0,0,0,0,0,0,0,0,0,0
0,0,0,0,0,0,0,0,0,0,0,0,0,0,0,0,0,0,0,0,0,0,0,0,0,0,0,0,0
0,0,0,0,0,0,0,0,0,0,0,0,0,0,0,0,0,0,0,0,0,0,0,0,0,0,0,0,0
0,0,0,0,0,0,0,0,0,0,0,0,0,0,0,0,0,0,0,0,0,0,0,0,0,0,0,0,0
0,0,0,0,0,0,0,0,0,0,0,0,0,0,0,0,0,0,0,0,0,0,0,0,0,0,0,0,0
0,0,0,0,0,0,0,0,0,0,0,0,0,0,0,0,0,0,0,0,0,0,0,0,0,0,0,0,0
0,0,0,0,0,0,0,0,0,0,0,0,0,0,0,0,0,0,0,0,0,0,0,0,0,0,0,0,0
0,0,0,0,0,0,0,0,0,0,0,0,0,0,0,0,0,0,0,0,0,0,0,0,0,0,0,0,0
0,0,0,0,0,0,0,0,0,0,0,0,0,0,0,0,0,0,0,0,0,0,0,0,0,0,0,0,0
0,0,0,0,0,0,0,0,0,0,0,0,0,0,0,0,0,0,0,0,0,0,0,0,0,0,0,0,0
0,0,0,0,0,0,69,69,69,69,69,69,69,69,69,69,69,69,69,69,69,69,70,0,0,0,0,0,0
0,0,0,0,0,0,66,88,88,88,88,88,88,88,88,88,88,88,88,88,88,88,70,0,0,0,0,0,0
0,0,0,0,0,0,66,88,88,88,88,88,88,88,88,88,88,88,88,88,88,88,70,0,0,0,0,0,0
0,0,0,0,0,0,66,88,88,88,88,88,88,88,88,88,88,88,88,88,88,88,70,0,0,0,0,0,0
0,0,0,0,0,0,66,88,88,88,88,88,88,88,88,88,88,88,88,88,88,88,70,0,0,0,0,0,0
0,0,0,0,0,0,66,88,88,88,88,88,88,0,88,88,88,88,88,88,88,88,70,0,0,0,0,0,0
0,0,0,0,0,0,66,88,88,88,88,88,88,0,88,88,88,88,88,88,88,88,70,0,0,0,0,0,0
0,0,0,0,0,0,66,88,88,88,88,88,88,0,88,88,88,88,88,88,88,88,70,0,0,0,0,0,0
0,0,0,0,0,0,66,88,88,88,88,88,88,0,88,88,88,88,88,88,88,88,70,0,0,0,0,0,0
0,0,0,0,0,0,66,88,88,88,88,88,88,69,88,88,88,88,88,88,88,88,70,0,0,0,0,0,0
0,0,0,0,0,0,66,88,88,88,88,88,88,88,88,88,88,88,88,88,88,88,70,0,0,0,0,0,0
0,0,0,0,0,0,66,88,88,88,88,88,88,88,88,88,88,88,88,88,88,88,70,0,0,0,0,0,0
0,0,0,0,0,0,68,68,68,68,68,68,68,68,68,68,68,68,68,68,68,68,68,0,0,0,0,0,0
0,0,0,0,0,0,0,0,0,0,0,0,0,0,0,0,0,0,0,0,0,0,0,0,0,0,0,0,0
0,0,0,0,0,0,0,0,0,0,0,0,0,0,0,0,0,0,0,0,0,0,0,0,0,0,0,0,0
0,0,0,0,0,0,0,0,0,0,0,0,0,0,0,0,0,0,0,0,0,0,0,0,0,0,0,0,0
0,0,0,0,0,0,0,0,0,0,0,0,0,0,0,0,0,0,0,0,0,0,0,0,0,0,0,0,0
0,0,0,0,0,0,0,0,0,0,0,0,0,0,0,0,0,0,0,0,0,0,0,0,0,0,0,0,0
:endlayer
layer: 32
0,0,0,0,0,0,0,0,0,0,0,0,0,0,0,0,0,0,0,0,0,0,0,0,0,0,0,0,0
0,0,0,0,0,0,0,0,0,0,0,0,0,0,0,0,0,0,0,0,0,0,0,0,0,0,0,0,0
0,0,0,0,0,0,0,0,0,0,0,0,0,0,0,0,0,0,0,0,0,0,0,0,0,0,0,0,0
0,0,0,0,0,0,0,0,0,0,0,0,0,0,0,0,0,0,0,0,0,0,0,0,0,0,0,0,0
0,0,0,0,0,0,0,0,0,0,0,0,0,0,0,0,0,0,0,0,0,0,0,0,0,0,0,0,0
0,0,0,0,0,0,0,0,0,0,0,0,0,0,0,0,0,0,0,0,0,0,0,0,0,0,0,0,0
0,0,0,0,0,0,0,0,0,0,0,0,0,0,0,0,0,0,0,0,0,0,0,0,0,0,0,0,0
0,0,0,0,0,0,0,0,0,0,0,0,0,0,0,0,0,0,0,0,0,0,0,0,0,0,0,0,0
0,0,0,0,0,0,0,0,0,0,0,0,0,0,0,0,0,0,0,0,0,0,0,0,0,0,0,0,0
0,0,0,0,0,0,0,0,0,0,0,0,0,0,0,0,0,0,0,0,0,0,0,0,0,0,0,0,0
0,0,0,0,0,0,0,0,0,0,0,0,0,0,0,0,0,0,0,0,0,0,0,0,0,0,0,0,0
0,0,0,0,0,0,0,0,0,0,0,0,0,0,0,0,0,0,0,0,0,0,0,0,0,0,0,0,0
0,0,0,0,0,0,0,69,69,69,69,69,69,69,69,69,69,69,69,69,69,70,0,0,0,0,0,0,0
0,0,0,0,0,0,0,66,88,0,0,0,0,0,0,0,0,0,0,0,88,70,0,0,0,0,0,0,0
0,0,0,0,0,0,0,66,0,88,0,0,0,0,0,0,0,0,0,88,0,70,0,0,0,0,0,0,0
0,0,0,0,0,0,0,66,0,0,0,0,16,16,16,0,0,0,0,0,0,70,0,0,0,0,0,0,0
0,0,0,0,0,0,0,66,0,0,0,0,16,0,16,0,0,0,0,0,0,70,0,0,0,0,0,0,0
0,0,0,0,0,0,0,66,0,0,0,0,16,0,16,0,0,0,0,0,0,70,0,0,0,0,0,0,0
0,0,0,0,0,0,0,66,0,0,0,0,16,0,16,0,0,0,0,0,0,70,0,0,0,0,0,0,0
0,0,0,0,0,0,0,66,0,0,0,0,16,0,16,0,0,0,0,0,0,70,0,0,0,0,0,0,0
0,0,0,0,0,0,0,66,0,88,0,0,0,0,0,0,0,0,0,88,0,70,0,0,0,0,0,0,0
0,0,0,0,0,0,0,66,88,0,0,0,0,0,0,0,0,0,0,0,88,70,0,0,0,0,0,0,0
0,0,0,0,0,0,0,68,68,68,68,68,68,68,68,68,68,68,68,68,68,68,0,0,0,0,0,0,0
0,0,0,0,0,0,0,0,0,0,0,0,0,0,0,0,0,0,0,0,0,0,0,0,0,0,0,0,0
0,0,0,0,0,0,0,0,0,0,0,0,0,0,0,0,0,0,0,0,0,0,0,0,0,0,0,0,0
0,0,0,0,0,0,0,0,0,0,0,0,0,0,0,0,0,0,0,0,0,0,0,0,0,0,0,0,0
0,0,0,0,0,0,0,0,0,0,0,0,0,0,0,0,0,0,0,0,0,0,0,0,0,0,0,0,0
0,0,0,0,0,0,0,0,0,0,0,0,0,0,0,0,0,0,0,0,0,0,0,0,0,0,0,0,0
0,0,0,0,0,0,0,0,0,0,0,0,0,0,0,0,0,0,0,0,0,0,0,0,0,0,0,0,0
:endlayer
layer: 33
0,0,0,0,0,0,0,0,0,0,0,0,0,0,0,0,0,0,0,0,0,0,0,0,0,0,0,0,0
0,0,0,0,0,0,0,0,0,0,0,0,0,0,0,0,0,0,0,0,0,0,0,0,0,0,0,0,0
0,0,0,0,0,0,0,0,0,0,0,0,0,0,0,0,0,0,0,0,0,0,0,0,0,0,0,0,0
0,0,0,0,0,0,0,0,0,0,0,0,0,0,0,0,0,0,0,0,0,0,0,0,0,0,0,0,0
0,0,0,0,0,0,0,0,0,0,0,0,0,0,0,0,0,0,0,0,0,0,0,0,0,0,0,0,0
0,0,0,0,0,0,0,0,0,0,0,0,0,0,0,0,0,0,0,0,0,0,0,0,0,0,0,0,0
0,0,0,0,0,0,0,0,0,0,0,0,0,0,0,0,0,0,0,0,0,0,0,0,0,0,0,0,0
0,0,0,0,0,0,0,0,0,0,0,0,0,0,0,0,0,0,0,0,0,0,0,0,0,0,0,0,0
0,0,0,0,0,0,0,0,0,0,0,0,0,0,0,0,0,0,0,0,0,0,0,0,0,0,0,0,0
0,0,0,0,0,0,0,0,0,0,0,0,0,0,0,0,0,0,0,0,0,0,0,0,0,0,0,0,0
0,0,0,0,0,0,0,0,0,0,0,0,0,0,0,0,0,0,0,0,0,0,0,0,0,0,0,0,0
0,0,0,0,0,0,0,0,0,0,0,0,0,0,0,0,0,0,0,0,0,0,0,0,0,0,0,0,0
0,0,0,0,0,0,0,0,0,0,0,0,0,0,0,0,0,0,0,0,0,0,0,0,0,0,0,0,0
0,0,0,0,0,0,0,0,66,69,69,69,69,69,69,69,69,69,69,69,70,0,0,0,0,0,0,0,0
0,0,0,0,0,0,0,0,66,88,9,0,0,0,0,0,0,0,11,88,70,0,0,0,0,0,0,0,0
0,0,0,0,0,0,0,0,66,39,0,0,0,0,0,0,0,0,0,39,70,0,0,0,0,0,0,0,0
0,0,0,0,0,0,0,0,66,0,0,0,0,0,0,0,0,0,0,0,70,0,0,0,0,0,0,0,0
0,0,0,0,0,0,0,0,66,0,0,0,0,0,0,0,0,0,0,0,70,0,0,0,0,0,0,0,0
0,0,0,0,0,0,0,0,66,0,0,0,0,0,0,0,0,0,0,0,70,0,0,0,0,0,0,0,0
0,0,0,0,0,0,0,0,66,10,0,0,0,0,0,0,0,0,0,10,70,0,0,0,0,0,0,0,0
0,0,0,0,0,0,0,0,66,88,9,0,0,0,0,0,0,0,11,88,70,0,0,0,0,0,0,0,0
0,0,0,0,0,0,0,0,68,68,68,68,68,68,68,68,68,68,68,68,70,0,0,0,0,0,0,0,0
0,0,0,0,0,0,0,0,0,0,0,0,0,0,0,0,0,0,0,0,0,0,0,0,0,0,0,0,0
0,0,0,0,0,0,0,0,0,0,0,0,0,0,0,0,0,0,0,0,0,0,0,0,0,0,0,0,0
0,0,0,0,0,0,0,0,0,0,0,0,0,0,0,0,0,0,0,0,0,0,0,0,0,0,0,0,0
0,0,0,0,0,0,0,0,0,0,0,0,0,0,0,0,0,0,0,0,0,0,0,0,0,0,0,0,0
0,0,0,0,0,0,0,0,0,0,0,0,0,0,0,0,0,0,0,0,0,0,0,0,0,0,0,0,0
0,0,0,0,0,0,0,0,0,0,0,0,0,0,0,0,0,0,0,0,0,0,0,0,0,0,0,0,0
0,0,0,0,0,0,0,0,0,0,0,0,0,0,0,0,0,0,0,0,0,0,0,0,0,0,0,0,0
:endlayer
layer: 34
0,0,0,0,0,0,0,0,0,0,0,0,0,0,0,0,0,0,0,0,0,0,0,0,0,0,0,0,0
0,0,0,0,0,0,0,0,0,0,0,0,0,0,0,0,0,0,0,0,0,0,0,0,0,0,0,0,0
0,0,0,0,0,0,0,0,0,0,0,0,0,0,0,0,0,0,0,0,0,0,0,0,0,0,0,0,0
0,0,0,0,0,0,0,0,0,0,0,0,0,0,0,0,0,0,0,0,0,0,0,0,0,0,0,0,0
0,0,0,0,0,0,0,0,0,0,0,0,0,0,0,0,0,0,0,0,0,0,0,0,0,0,0,0,0
0,0,0,0,0,0,0,0,0,0,0,0,0,0,0,0,0,0,0,0,0,0,0,0,0,0,0,0,0
0,0,0,0,0,0,0,0,0,0,0,0,0,0,0,0,0,0,0,0,0,0,0,0,0,0,0,0,0
0,0,0,0,0,0,0,0,0,0,0,0,0,0,0,0,0,0,0,0,0,0,0,0,0,0,0,0,0
0,0,0,0,0,0,0,0,0,0,0,0,0,0,0,0,0,0,0,0,0,0,0,0,0,0,0,0,0
0,0,0,0,0,0,0,0,0,0,0,0,0,0,0,0,0,0,0,0,0,0,0,0,0,0,0,0,0
0,0,0,0,0,0,0,0,0,0,0,0,0,0,0,0,0,0,0,0,0,0,0,0,0,0,0,0,0
0,0,0,0,0,0,0,0,0,0,0,0,0,0,0,0,0,0,0,0,0,0,0,0,0,0,0,0,0
0,0,0,0,0,0,0,0,0,0,0,0,0,0,0,0,0,0,0,0,0,0,0,0,0,0,0,0,0
0,0,0,0,0,0,0,0,0,0,0,0,0,0,0,0,0,0,0,0,0,0,0,0,0,0,0,0,0
0,0,0,0,0,0,0,0,0,66,69,69,69,69,69,69,69,69,69,70,0,0,0,0,0,0,0,0,0
0,0,0,0,0,0,0,0,0,66,88,0,0,0,0,0,0,0,88,70,0,0,0,0,0,0,0,0,0
0,0,0,0,0,0,0,0,0,66,0,0,0,0,0,0,0,0,0,70,0,0,0,0,0,0,0,0,0
0,0,0,0,0,0,0,0,0,66,0,0,0,0,0,0,0,0,0,70,0,0,0,0,0,0,0,0,0
0,0,0,0,0,0,0,0,0,66,0,0,0,0,0,0,0,0,0,70,0,0,0,0,0,0,0,0,0
0,0,0,0,0,0,0,0,0,66,88,0,0,0,0,0,0,0,88,70,0,0,0,0,0,0,0,0,0
0,0,0,0,0,0,0,0,0,68,68,68,68,68,68,68,68,68,68,70,0,0,0,0,0,0,0,0,0
0,0,0,0,0,0,0,0,0,0,0,0,0,0,0,0,0,0,0,0,0,0,0,0,0,0,0,0,0
0,0,0,0,0,0,0,0,0,0,0,0,0,0,0,0,0,0,0,0,0,0,0,0,0,0,0,0,0
0,0,0,0,0,0,0,0,0,0,0,0,0,0,0,0,0,0,0,0,0,0,0,0,0,0,0,0,0
0,0,0,0,0,0,0,0,0,0,0,0,0,0,0,0,0,0,0,0,0,0,0,0,0,0,0,0,0
0,0,0,0,0,0,0,0,0,0,0,0,0,0,0,0,0,0,0,0,0,0,0,0,0,0,0,0,0
0,0,0,0,0,0,0,0,0,0,0,0,0,0,0,0,0,0,0,0,0,0,0,0,0,0,0,0,0
0,0,0,0,0,0,0,0,0,0,0,0,0,0,0,0,0,0,0,0,0,0,0,0,0,0,0,0,0
0,0,0,0,0,0,0,0,0,0,0,0,0,0,0,0,0,0,0,0,0,0,0,0,0,0,0,0,0
:endlayer
layer: 35
0,0,0,0,0,0,0,0,0,0,0,0,0,0,0,0,0,0,0,0,0,0,0,0,0,0,0,0,0
0,0,0,0,0,0,0,0,0,0,0,0,0,0,0,0,0,0,0,0,0,0,0,0,0,0,0,0,0
0,0,0,0,0,0,0,0,0,0,0,0,0,0,0,0,0,0,0,0,0,0,0,0,0,0,0,0,0
0,0,0,0,0,0,0,0,0,0,0,0,0,0,0,0,0,0,0,0,0,0,0,0,0,0,0,0,0
0,0,0,0,0,0,0,0,0,0,0,0,0,0,0,0,0,0,0,0,0,0,0,0,0,0,0,0,0
0,0,0,0,0,0,0,0,0,0,0,0,0,0,0,0,0,0,0,0,0,0,0,0,0,0,0,0,0
0,0,0,0,0,0,0,0,0,0,0,0,0,0,0,0,0,0,0,0,0,0,0,0,0,0,0,0,0
0,0,0,0,0,0,0,0,0,0,0,0,0,0,0,0,0,0,0,0,0,0,0,0,0,0,0,0,0
0,0,0,0,0,0,0,0,0,0,0,0,0,0,0,0,0,0,0,0,0,0,0,0,0,0,0,0,0
0,0,0,0,0,0,0,0,0,0,0,0,0,0,0,0,0,0,0,0,0,0,0,0,0,0,0,0,0
0,0,0,0,0,0,0,0,0,0,0,0,0,0,0,0,0,0,0,0,0,0,0,0,0,0,0,0,0
0,0,0,0,0,0,0,0,0,0,0,0,0,0,0,0,0,0,0,0,0,0,0,0,0,0,0,0,0
0,0,0,0,0,0,0,0,0,0,0,0,0,0,0,0,0,0,0,0,0,0,0,0,0,0,0,0,0
0,0,0,0,0,0,0,0,0,0,0,0,0,0,0,0,0,0,0,0,0,0,0,0,0,0,0,0,0
0,0,0,0,0,0,0,0,0,0,0,0,0,0,0,0,0,0,0,0,0,0,0,0,0,0,0,0,0
0,0,0,0,0,0,0,0,0,0,66,69,69,69,69,69,69,69,70,0,0,0,0,0,0,0,0,0,0
0,0,0,0,0,0,0,0,0,0,66,88,88,88,88,88,88,88,70,0,0,0,0,0,0,0,0,0,0
0,0,0,0,0,0,0,0,0,0,66,88,0,0,0,0,0,88,70,0,0,0,0,0,0,0,0,0,0
0,0,0,0,0,0,0,0,0,0,66,88,88,88,88,88,88,88,70,0,0,0,0,0,0,0,0,0,0
0,0,0,0,0,0,0,0,0,0,66,68,68,68,68,68,68,68,70,0,0,0,0,0,0,0,0,0,0
0,0,0,0,0,0,0,0,0,0,0,0,0,0,0,0,0,0,0,0,0,0,0,0,0,0,0,0,0
0,0,0,0,0,0,0,0,0,0,0,0,0,0,0,0,0,0,0,0,0,0,0,0,0,0,0,0,0
0,0,0,0,0,0,0,0,0,0,0,0,0,0,0,0,0,0,0,0,0,0,0,0,0,0,0,0,0
0,0,0,0,0,0,0,0,0,0,0,0,0,0,0,0,0,0,0,0,0,0,0,0,0,0,0,0,0
0,0,0,0,0,0,0,0,0,0,0,0,0,0,0,0,0,0,0,0,0,0,0,0,0,0,0,0,0
0,0,0,0,0,0,0,0,0,0,0,0,0,0,0,0,0,0,0,0,0,0,0,0,0,0,0,0,0
0,0,0,0,0,0,0,0,0,0,0,0,0,0,0,0,0,0,0,0,0,0,0,0,0,0,0,0,0
0,0,0,0,0,0,0,0,0,0,0,0,0,0,0,0,0,0,0,0,0,0,0,0,0,0,0,0,0
0,0,0,0,0,0,0,0,0,0,0,0,0,0,0,0,0,0,0,0,0,0,0,0,0,0,0,0,0
:endlayer
layer: 36
0,0,0,0,0,0,0,0,0,0,0,0,0,0,0,0,0,0,0,0,0,0,0,0,0,0,0,0,0
0,0,0,0,0,0,0,0,0,0,0,0,0,0,0,0,0,0,0,0,0,0,0,0,0,0,0,0,0
0,0,0,0,0,0,0,0,0,0,0,0,0,0,0,0,0,0,0,0,0,0,0,0,0,0,0,0,0
0,0,0,0,0,0,0,0,0,0,0,0,0,0,0,0,0,0,0,0,0,0,0,0,0,0,0,0,0
0,0,0,0,0,0,0,0,0,0,0,0,0,0,0,0,0,0,0,0,0,0,0,0,0,0,0,0,0
0,0,0,0,0,0,0,0,0,0,0,0,0,0,0,0,0,0,0,0,0,0,0,0,0,0,0,0,0
0,0,0,0,0,0,0,0,0,0,0,0,0,0,0,0,0,0,0,0,0,0,0,0,0,0,0,0,0
0,0,0,0,0,0,0,0,0,0,0,0,0,0,0,0,0,0,0,0,0,0,0,0,0,0,0,0,0
0,0,0,0,0,0,0,0,0,0,0,0,0,0,0,0,0,0,0,0,0,0,0,0,0,0,0,0,0
0,0,0,0,0,0,0,0,0,0,0,0,0,0,0,0,0,0,0,0,0,0,0,0,0,0,0,0,0
0,0,0,0,0,0,0,0,0,0,0,0,0,0,0,0,0,0,0,0,0,0,0,0,0,0,0,0,0
0,0,0,0,0,0,0,0,0,0,0,0,0,0,0,0,0,0,0,0,0,0,0,0,0,0,0,0,0
0,0,0,0,0,0,0,0,0,0,0,0,0,0,0,0,0,0,0,0,0,0,0,0,0,0,0,0,0
0,0,0,0,0,0,0,0,0,0,0,0,0,0,0,0,0,0,0,0,0,0,0,0,0,0,0,0,0
0,0,0,0,0,0,0,0,0,0,0,0,0,0,0,0,0,0,0,0,0,0,0,0,0,0,0,0,0
0,0,0,0,0,0,0,0,0,0,0,0,0,0,0,0,0,0,0,0,0,0,0,0,0,0,0,0,0
0,0,0,0,0,0,0,0,0,0,0,69,69,69,69,69,69,70,0,0,0,0,0,0,0,0,0,0,0
0,0,0,0,0,0,0,0,0,0,0,66,88,88,88,88,88,70,0,0,0,0,0,0,0,0,0,0,0
0,0,0,0,0,0,0,0,0,0,0,66,68,68,68,68,68,70,0,0,0,0,0,0,0,0,0,0,0
0,0,0,0,0,0,0,0,0,0,0,0,0,0,0,0,0,0,0,0,0,0,0,0,0,0,0,0,0
0,0,0,0,0,0,0,0,0,0,0,0,0,0,0,0,0,0,0,0,0,0,0,0,0,0,0,0,0
0,0,0,0,0,0,0,0,0,0,0,0,0,0,0,0,0,0,0,0,0,0,0,0,0,0,0,0,0
0,0,0,0,0,0,0,0,0,0,0,0,0,0,0,0,0,0,0,0,0,0,0,0,0,0,0,0,0
0,0,0,0,0,0,0,0,0,0,0,0,0,0,0,0,0,0,0,0,0,0,0,0,0,0,0,0,0
0,0,0,0,0,0,0,0,0,0,0,0,0,0,0,0,0,0,0,0,0,0,0,0,0,0,0,0,0
0,0,0,0,0,0,0,0,0,0,0,0,0,0,0,0,0,0,0,0,0,0,0,0,0,0,0,0,0
0,0,0,0,0,0,0,0,0,0,0,0,0,0,0,0,0,0,0,0,0,0,0,0,0,0,0,0,0
0,0,0,0,0,0,0,0,0,0,0,0,0,0,0,0,0,0,0,0,0,0,0,0,0,0,0,0,0
0,0,0,0,0,0,0,0,0,0,0,0,0,0,0,0,0,0,0,0,0,0,0,0,0,0,0,0,0
:endlayer
layer: 37
0,0,0,0,0,0,0,0,0,0,0,0,0,0,0,0,0,0,0,0,0,0,0,0,0,0,0,0,0
0,0,0,0,0,0,0,0,0,0,0,0,0,0,0,0,0,0,0,0,0,0,0,0,0,0,0,0,0
0,0,0,0,0,0,0,0,0,0,0,0,0,0,0,0,0,0,0,0,0,0,0,0,0,0,0,0,0
0,0,0,0,0,0,0,0,0,0,0,0,0,0,0,0,0,0,0,0,0,0,0,0,0,0,0,0,0
0,0,0,0,0,0,0,0,0,0,0,0,0,0,0,0,0,0,0,0,0,0,0,0,0,0,0,0,0
0,0,0,0,0,0,0,0,0,0,0,0,0,0,0,0,0,0,0,0,0,0,0,0,0,0,0,0,0
0,0,0,0,0,0,0,0,0,0,0,0,0,0,0,0,0,0,0,0,0,0,0,0,0,0,0,0,0
0,0,0,0,0,0,0,0,0,0,0,0,0,0,0,0,0,0,0,0,0,0,0,0,0,0,0,0,0
0,0,0,0,0,0,0,0,0,0,0,0,0,0,0,0,0,0,0,0,0,0,0,0,0,0,0,0,0
0,0,0,0,0,0,0,0,0,0,0,0,0,0,0,0,0,0,0,0,0,0,0,0,0,0,0,0,0
0,0,0,0,0,0,0,0,0,0,0,0,0,0,0,0,0,0,0,0,0,0,0,0,0,0,0,0,0
0,0,0,0,0,0,0,0,0,0,0,0,0,0,0,0,0,0,0,0,0,0,0,0,0,0,0,0,0
0,0,0,0,0,0,0,0,0,0,0,0,0,0,0,0,0,0,0,0,0,0,0,0,0,0,0,0,0
0,0,0,0,0,0,0,0,0,0,0,0,0,0,0,0,0,0,0,0,0,0,0,0,0,0,0,0,0
0,0,0,0,0,0,0,0,0,0,0,0,0,0,0,0,0,0,0,0,0,0,0,0,0,0,0,0,0
0,0,0,0,0,0,0,0,0,0,0,0,0,0,0,0,0,0,0,0,0,0,0,0,0,0,0,0,0
0,0,0,0,0,0,0,0,0,0,0,0,0,0,0,0,0,0,0,0,0,0,0,0,0,0,0,0,0
0,0,0,0,0,0,0,0,0,0,0,0,65,65,88,65,65,0,0,0,0,0,0,0,0,0,0,0,0
0,0,0,0,0,0,0,0,0,0,0,0,0,0,0,0,0,0,0,0,0,0,0,0,0,0,0,0,0
0,0,0,0,0,0,0,0,0,0,0,0,0,0,0,0,0,0,0,0,0,0,0,0,0,0,0,0,0
0,0,0,0,0,0,0,0,0,0,0,0,0,0,0,0,0,0,0,0,0,0,0,0,0,0,0,0,0
0,0,0,0,0,0,0,0,0,0,0,0,0,0,0,0,0,0,0,0,0,0,0,0,0,0,0,0,0
0,0,0,0,0,0,0,0,0,0,0,0,0,0,0,0,0,0,0,0,0,0,0,0,0,0,0,0,0
0,0,0,0,0,0,0,0,0,0,0,0,0,0,0,0,0,0,0,0,0,0,0,0,0,0,0,0,0
0,0,0,0,0,0,0,0,0,0,0,0,0,0,0,0,0,0,0,0,0,0,0,0,0,0,0,0,0
0,0,0,0,0,0,0,0,0,0,0,0,0,0,0,0,0,0,0,0,0,0,0,0,0,0,0,0,0
0,0,0,0,0,0,0,0,0,0,0,0,0,0,0,0,0,0,0,0,0,0,0,0,0,0,0,0,0
0,0,0,0,0,0,0,0,0,0,0,0,0,0,0,0,0,0,0,0,0,0,0,0,0,0,0,0,0
0,0,0,0,0,0,0,0,0,0,0,0,0,0,0,0,0,0,0,0,0,0,0,0,0,0,0,0,0
:endlayer
layer: 38
0,0,0,0,0,0,0,0,0,0,0,0,0,0,0,0,0,0,0,0,0,0,0,0,0,0,0,0,0
0,0,0,0,0,0,0,0,0,0,0,0,0,0,0,0,0,0,0,0,0,0,0,0,0,0,0,0,0
0,0,0,0,0,0,0,0,0,0,0,0,0,0,0,0,0,0,0,0,0,0,0,0,0,0,0,0,0
0,0,0,0,0,0,0,0,0,0,0,0,0,0,0,0,0,0,0,0,0,0,0,0,0,0,0,0,0
0,0,0,0,0,0,0,0,0,0,0,0,0,0,0,0,0,0,0,0,0,0,0,0,0,0,0,0,0
0,0,0,0,0,0,0,0,0,0,0,0,0,0,0,0,0,0,0,0,0,0,0,0,0,0,0,0,0
0,0,0,0,0,0,0,0,0,0,0,0,0,0,0,0,0,0,0,0,0,0,0,0,0,0,0,0,0
0,0,0,0,0,0,0,0,0,0,0,0,0,0,0,0,0,0,0,0,0,0,0,0,0,0,0,0,0
0,0,0,0,0,0,0,0,0,0,0,0,0,0,0,0,0,0,0,0,0,0,0,0,0,0,0,0,0
0,0,0,0,0,0,0,0,0,0,0,0,0,0,0,0,0,0,0,0,0,0,0,0,0,0,0,0,0
0,0,0,0,0,0,0,0,0,0,0,0,0,0,0,0,0,0,0,0,0,0,0,0,0,0,0,0,0
0,0,0,0,0,0,0,0,0,0,0,0,0,0,0,0,0,0,0,0,0,0,0,0,0,0,0,0,0
0,0,0,0,0,0,0,0,0,0,0,0,0,0,0,0,0,0,0,0,0,0,0,0,0,0,0,0,0
0,0,0,0,0,0,0,0,0,0,0,0,0,0,0,0,0,0,0,0,0,0,0,0,0,0,0,0,0
0,0,0,0,0,0,0,0,0,0,0,0,0,0,0,0,0,0,0,0,0,0,0,0,0,0,0,0,0
0,0,0,0,0,0,0,0,0,0,0,0,0,0,0,0,0,0,0,0,0,0,0,0,0,0,0,0,0
0,0,0,0,0,0,0,0,0,0,0,0,0,0,0,0,0,0,0,0,0,0,0,0,0,0,0,0,0
0,0,0,0,0,0,0,0,0,0,0,0,0,0,52,0,0,0,0,0,0,0,0,0,0,0,0,0,0
0,0,0,0,0,0,0,0,0,0,0,0,0,0,0,0,0,0,0,0,0,0,0,0,0,0,0,0,0
0,0,0,0,0,0,0,0,0,0,0,0,0,0,0,0,0,0,0,0,0,0,0,0,0,0,0,0,0
0,0,0,0,0,0,0,0,0,0,0,0,0,0,0,0,0,0,0,0,0,0,0,0,0,0,0,0,0
0,0,0,0,0,0,0,0,0,0,0,0,0,0,0,0,0,0,0,0,0,0,0,0,0,0,0,0,0
0,0,0,0,0,0,0,0,0,0,0,0,0,0,0,0,0,0,0,0,0,0,0,0,0,0,0,0,0
0,0,0,0,0,0,0,0,0,0,0,0,0,0,0,0,0,0,0,0,0,0,0,0,0,0,0,0,0
0,0,0,0,0,0,0,0,0,0,0,0,0,0,0,0,0,0,0,0,0,0,0,0,0,0,0,0,0
0,0,0,0,0,0,0,0,0,0,0,0,0,0,0,0,0,0,0,0,0,0,0,0,0,0,0,0,0
0,0,0,0,0,0,0,0,0,0,0,0,0,0,0,0,0,0,0,0,0,0,0,0,0,0,0,0,0
0,0,0,0,0,0,0,0,0,0,0,0,0,0,0,0,0,0,0,0,0,0,0,0,0,0,0,0,0
0,0,0,0,0,0,0,0,0,0,0,0,0,0,0,0,0,0,0,0,0,0,0,0,0,0,0,0,0
:endlayer
layer: 39
0,0,0,0,0,0,0,0,0,0,0,0,0,0,0,0,0,0,0,0,0,0,0,0,0,0,0,0,0
0,0,0,0,0,0,0,0,0,0,0,0,0,0,0,0,0,0,0,0,0,0,0,0,0,0,0,0,0
0,0,0,0,0,0,0,0,0,0,0,0,0,0,0,0,0,0,0,0,0,0,0,0,0,0,0,0,0
0,0,0,0,0,0,0,0,0,0,0,0,0,0,0,0,0,0,0,0,0,0,0,0,0,0,0,0,0
0,0,0,0,0,0,0,0,0,0,0,0,0,0,0,0,0,0,0,0,0,0,0,0,0,0,0,0,0
0,0,0,0,0,0,0,0,0,0,0,0,0,0,0,0,0,0,0,0,0,0,0,0,0,0,0,0,0
0,0,0,0,0,0,0,0,0,0,0,0,0,0,0,0,0,0,0,0,0,0,0,0,0,0,0,0,0
0,0,0,0,0,0,0,0,0,0,0,0,0,0,0,0,0,0,0,0,0,0,0,0,0,0,0,0,0
0,0,0,0,0,0,0,0,0,0,0,0,0,0,0,0,0,0,0,0,0,0,0,0,0,0,0,0,0
0,0,0,0,0,0,0,0,0,0,0,0,0,0,0,0,0,0,0,0,0,0,0,0,0,0,0,0,0
0,0,0,0,0,0,0,0,0,0,0,0,0,0,0,0,0,0,0,0,0,0,0,0,0,0,0,0,0
0,0,0,0,0,0,0,0,0,0,0,0,0,0,0,0,0,0,0,0,0,0,0,0,0,0,0,0,0
0,0,0,0,0,0,0,0,0,0,0,0,0,0,0,0,0,0,0,0,0,0,0,0,0,0,0,0,0
0,0,0,0,0,0,0,0,0,0,0,0,0,0,0,0,0,0,0,0,0,0,0,0,0,0,0,0,0
0,0,0,0,0,0,0,0,0,0,0,0,0,0,0,0,0,0,0,0,0,0,0,0,0,0,0,0,0
0,0,0,0,0,0,0,0,0,0,0,0,0,0,0,0,0,0,0,0,0,0,0,0,0,0,0,0,0
0,0,0,0,0,0,0,0,0,0,0,0,0,0,0,0,0,0,0,0,0,0,0,0,0,0,0,0,0
0,0,0,0,0,0,0,0,0,0,0,0,0,0,0,0,0,0,0,0,0,0,0,0,0,0,0,0,0
0,0,0,0,0,0,0,0,0,0,0,0,0,0,0,0,0,0,0,0,0,0,0,0,0,0,0,0,0
0,0,0,0,0,0,0,0,0,0,0,0,0,0,0,0,0,0,0,0,0,0,0,0,0,0,0,0,0
0,0,0,0,0,0,0,0,0,0,0,0,0,0,0,0,0,0,0,0,0,0,0,0,0,0,0,0,0
0,0,0,0,0,0,0,0,0,0,0,0,0,0,0,0,0,0,0,0,0,0,0,0,0,0,0,0,0
0,0,0,0,0,0,0,0,0,0,0,0,0,0,0,0,0,0,0,0,0,0,0,0,0,0,0,0,0
0,0,0,0,0,0,0,0,0,0,0,0,0,0,0,0,0,0,0,0,0,0,0,0,0,0,0,0,0
0,0,0,0,0,0,0,0,0,0,0,0,0,0,0,0,0,0,0,0,0,0,0,0,0,0,0,0,0
0,0,0,0,0,0,0,0,0,0,0,0,0,0,0,0,0,0,0,0,0,0,0,0,0,0,0,0,0
0,0,0,0,0,0,0,0,0,0,0,0,0,0,0,0,0,0,0,0,0,0,0,0,0,0,0,0,0
0,0,0,0,0,0,0,0,0,0,0,0,0,0,0,0,0,0,0,0,0,0,0,0,0,0,0,0,0
0,0,0,0,0,0,0,0,0,0,0,0,0,0,0,0,0,0,0,0,0,0,0,0,0,0,0,0,0
:endlayer
layer: 40
0,0,0,0,0,0,0,0,0,0,0,0,0,0,0,0,0,0,0,0,0,0,0,0,0,0,0,0,0
0,0,0,0,0,0,0,0,0,0,0,0,0,0,0,0,0,0,0,0,0,0,0,0,0,0,0,0,0
0,0,0,0,0,0,0,0,0,0,0,0,0,0,0,0,0,0,0,0,0,0,0,0,0,0,0,0,0
0,0,0,0,0,0,0,0,0,0,0,0,0,0,0,0,0,0,0,0,0,0,0,0,0,0,0,0,0
0,0,0,0,0,0,0,0,0,0,0,0,0,0,0,0,0,0,0,0,0,0,0,0,0,0,0,0,0
0,0,0,0,0,0,0,0,0,0,0,0,0,0,0,0,0,0,0,0,0,0,0,0,0,0,0,0,0
0,0,0,0,0,0,0,0,0,0,0,0,0,0,0,0,0,0,0,0,0,0,0,0,0,0,0,0,0
0,0,0,0,0,0,0,0,0,0,0,0,0,0,0,0,0,0,0,0,0,0,0,0,0,0,0,0,0
0,0,0,0,0,0,0,0,0,0,0,0,0,0,0,0,0,0,0,0,0,0,0,0,0,0,0,0,0
0,0,0,0,0,0,0,0,0,0,0,0,0,0,0,0,0,0,0,0,0,0,0,0,0,0,0,0,0
0,0,0,0,0,0,0,0,0,0,0,0,0,0,0,0,0,0,0,0,0,0,0,0,0,0,0,0,0
0,0,0,0,0,0,0,0,0,0,0,0,0,0,0,0,0,0,0,0,0,0,0,0,0,0,0,0,0
0,0,0,0,0,0,0,0,0,0,0,0,0,0,0,0,0,0,0,0,0,0,0,0,0,0,0,0,0
0,0,0,0,0,0,0,0,0,0,0,0,0,0,0,0,0,0,0,0,0,0,0,0,0,0,0,0,0
0,0,0,0,0,0,0,0,0,0,0,0,0,0,0,0,0,0,0,0,0,0,0,0,0,0,0,0,0
0,0,0,0,0,0,0,0,0,0,0,0,0,0,0,0,0,0,0,0,0,0,0,0,0,0,0,0,0
0,0,0,0,0,0,0,0,0,0,0,0,0,0,0,0,0,0,0,0,0,0,0,0,0,0,0,0,0
0,0,0,0,0,0,0,0,0,0,0,0,0,0,0,0,0,0,0,0,0,0,0,0,0,0,0,0,0
0,0,0,0,0,0,0,0,0,0,0,0,0,0,0,0,0,0,0,0,0,0,0,0,0,0,0,0,0
0,0,0,0,0,0,0,0,0,0,0,0,0,0,0,0,0,0,0,0,0,0,0,0,0,0,0,0,0
0,0,0,0,0,0,0,0,0,0,0,0,0,0,0,0,0,0,0,0,0,0,0,0,0,0,0,0,0
0,0,0,0,0,0,0,0,0,0,0,0,0,0,0,0,0,0,0,0,0,0,0,0,0,0,0,0,0
0,0,0,0,0,0,0,0,0,0,0,0,0,0,0,0,0,0,0,0,0,0,0,0,0,0,0,0,0
0,0,0,0,0,0,0,0,0,0,0,0,0,0,0,0,0,0,0,0,0,0,0,0,0,0,0,0,0
0,0,0,0,0,0,0,0,0,0,0,0,0,0,0,0,0,0,0,0,0,0,0,0,0,0,0,0,0
0,0,0,0,0,0,0,0,0,0,0,0,0,0,0,0,0,0,0,0,0,0,0,0,0,0,0,0,0
0,0,0,0,0,0,0,0,0,0,0,0,0,0,0,0,0,0,0,0,0,0,0,0,0,0,0,0,0
0,0,0,0,0,0,0,0,0,0,0,0,0,0,0,0,0,0,0,0,0,0,0,0,0,0,0,0,0
0,0,0,0,0,0,0,0,0,0,0,0,0,0,0,0,0,0,0,0,0,0,0,0,0,0,0,0,0
:endlayer
layer: 41
0,0,0,0,0,0,0,0,0,0,0,0,0,0,0,0,0,0,0,0,0,0,0,0,0,0,0,0,0
0,0,0,0,0,0,0,0,0,0,0,0,0,0,0,0,0,0,0,0,0,0,0,0,0,0,0,0,0
0,0,0,0,0,0,0,0,0,0,0,0,0,0,0,0,0,0,0,0,0,0,0,0,0,0,0,0,0
0,0,0,0,0,0,0,0,0,0,0,0,0,0,0,0,0,0,0,0,0,0,0,0,0,0,0,0,0
0,0,0,0,0,0,0,0,0,0,0,0,0,0,0,0,0,0,0,0,0,0,0,0,0,0,0,0,0
0,0,0,0,0,0,0,0,0,0,0,0,0,0,0,0,0,0,0,0,0,0,0,0,0,0,0,0,0
0,0,0,0,0,0,0,0,0,0,0,0,0,0,0,0,0,0,0,0,0,0,0,0,0,0,0,0,0
0,0,0,0,0,0,0,0,0,0,0,0,0,0,0,0,0,0,0,0,0,0,0,0,0,0,0,0,0
0,0,0,0,0,0,0,0,0,0,0,0,0,0,0,0,0,0,0,0,0,0,0,0,0,0,0,0,0
0,0,0,0,0,0,0,0,0,0,0,0,0,0,0,0,0,0,0,0,0,0,0,0,0,0,0,0,0
0,0,0,0,0,0,0,0,0,0,0,0,0,0,0,0,0,0,0,0,0,0,0,0,0,0,0,0,0
0,0,0,0,0,0,0,0,0,0,0,0,0,0,0,0,0,0,0,0,0,0,0,0,0,0,0,0,0
0,0,0,0,0,0,0,0,0,0,0,0,0,0,0,0,0,0,0,0,0,0,0,0,0,0,0,0,0
0,0,0,0,0,0,0,0,0,0,0,0,0,0,0,0,0,0,0,0,0,0,0,0,0,0,0,0,0
0,0,0,0,0,0,0,0,0,0,0,0,0,0,0,0,0,0,0,0,0,0,0,0,0,0,0,0,0
0,0,0,0,0,0,0,0,0,0,0,0,0,0,0,0,0,0,0,0,0,0,0,0,0,0,0,0,0
0,0,0,0,0,0,0,0,0,0,0,0,0,0,0,0,0,0,0,0,0,0,0,0,0,0,0,0,0
0,0,0,0,0,0,0,0,0,0,0,0,0,0,0,0,0,0,0,0,0,0,0,0,0,0,0,0,0
0,0,0,0,0,0,0,0,0,0,0,0,0,0,0,0,0,0,0,0,0,0,0,0,0,0,0,0,0
0,0,0,0,0,0,0,0,0,0,0,0,0,0,0,0,0,0,0,0,0,0,0,0,0,0,0,0,0
0,0,0,0,0,0,0,0,0,0,0,0,0,0,0,0,0,0,0,0,0,0,0,0,0,0,0,0,0
0,0,0,0,0,0,0,0,0,0,0,0,0,0,0,0,0,0,0,0,0,0,0,0,0,0,0,0,0
0,0,0,0,0,0,0,0,0,0,0,0,0,0,0,0,0,0,0,0,0,0,0,0,0,0,0,0,0
0,0,0,0,0,0,0,0,0,0,0,0,0,0,0,0,0,0,0,0,0,0,0,0,0,0,0,0,0
0,0,0,0,0,0,0,0,0,0,0,0,0,0,0,0,0,0,0,0,0,0,0,0,0,0,0,0,0
0,0,0,0,0,0,0,0,0,0,0,0,0,0,0,0,0,0,0,0,0,0,0,0,0,0,0,0,0
0,0,0,0,0,0,0,0,0,0,0,0,0,0,0,0,0,0,0,0,0,0,0,0,0,0,0,0,0
0,0,0,0,0,0,0,0,0,0,0,0,0,0,0,0,0,0,0,0,0,0,0,0,0,0,0,0,0
0,0,0,0,0,0,0,0,0,0,0,0,0,0,0,0,0,0,0,0,0,0,0,0,0,0,0,0,0
:endlayer
layer: 42
0,0,0,0,0,0,0,0,0,0,0,0,0,0,0,0,0,0,0,0,0,0,0,0,0,0,0,0,0
0,0,0,0,0,0,0,0,0,0,0,0,0,0,0,0,0,0,0,0,0,0,0,0,0,0,0,0,0
0,0,0,0,0,0,0,0,0,0,0,0,0,0,0,0,0,0,0,0,0,0,0,0,0,0,0,0,0
0,0,0,0,0,0,0,0,0,0,0,0,0,0,0,0,0,0,0,0,0,0,0,0,0,0,0,0,0
0,0,0,0,0,0,0,0,0,0,0,0,0,0,0,0,0,0,0,0,0,0,0,0,0,0,0,0,0
0,0,0,0,0,0,0,0,0,0,0,0,0,0,0,0,0,0,0,0,0,0,0,0,0,0,0,0,0
0,0,0,0,0,0,0,0,0,0,0,0,0,0,0,0,0,0,0,0,0,0,0,0,0,0,0,0,0
0,0,0,0,0,0,0,0,0,0,0,0,0,0,0,0,0,0,0,0,0,0,0,0,0,0,0,0,0
0,0,0,0,0,0,0,0,0,0,0,0,0,0,0,0,0,0,0,0,0,0,0,0,0,0,0,0,0
0,0,0,0,0,0,0,0,0,0,0,0,0,0,0,0,0,0,0,0,0,0,0,0,0,0,0,0,0
0,0,0,0,0,0,0,0,0,0,0,0,0,0,0,0,0,0,0,0,0,0,0,0,0,0,0,0,0
0,0,0,0,0,0,0,0,0,0,0,0,0,0,0,0,0,0,0,0,0,0,0,0,0,0,0,0,0
0,0,0,0,0,0,0,0,0,0,0,0,0,0,0,0,0,0,0,0,0,0,0,0,0,0,0,0,0
0,0,0,0,0,0,0,0,0,0,0,0,0,0,0,0,0,0,0,0,0,0,0,0,0,0,0,0,0
0,0,0,0,0,0,0,0,0,0,0,0,0,0,0,0,0,0,0,0,0,0,0,0,0,0,0,0,0
0,0,0,0,0,0,0,0,0,0,0,0,0,0,0,0,0,0,0,0,0,0,0,0,0,0,0,0,0
0,0,0,0,0,0,0,0,0,0,0,0,0,0,0,0,0,0,0,0,0,0,0,0,0,0,0,0,0
0,0,0,0,0,0,0,0,0,0,0,0,0,0,0,0,0,0,0,0,0,0,0,0,0,0,0,0,0
0,0,0,0,0,0,0,0,0,0,0,0,0,0,0,0,0,0,0,0,0,0,0,0,0,0,0,0,0
0,0,0,0,0,0,0,0,0,0,0,0,0,0,0,0,0,0,0,0,0,0,0,0,0,0,0,0,0
0,0,0,0,0,0,0,0,0,0,0,0,0,0,0,0,0,0,0,0,0,0,0,0,0,0,0,0,0
0,0,0,0,0,0,0,0,0,0,0,0,0,0,0,0,0,0,0,0,0,0,0,0,0,0,0,0,0
0,0,0,0,0,0,0,0,0,0,0,0,0,0,0,0,0,0,0,0,0,0,0,0,0,0,0,0,0
0,0,0,0,0,0,0,0,0,0,0,0,0,0,0,0,0,0,0,0,0,0,0,0,0,0,0,0,0
0,0,0,0,0,0,0,0,0,0,0,0,0,0,0,0,0,0,0,0,0,0,0,0,0,0,0,0,0
0,0,0,0,0,0,0,0,0,0,0,0,0,0,0,0,0,0,0,0,0,0,0,0,0,0,0,0,0
0,0,0,0,0,0,0,0,0,0,0,0,0,0,0,0,0,0,0,0,0,0,0,0,0,0,0,0,0
0,0,0,0,0,0,0,0,0,0,0,0,0,0,0,0,0,0,0,0,0,0,0,0,0,0,0,0,0
0,0,0,0,0,0,0,0,0,0,0,0,0,0,0,0,0,0,0,0,0,0,0,0,0,0,0,0,0
:endlayer
layer: 43
0,0,0,0,0,0,0,0,0,0,0,0,0,0,0,0,0,0,0,0,0,0,0,0,0,0,0,0,0
0,0,0,0,0,0,0,0,0,0,0,0,0,0,0,0,0,0,0,0,0,0,0,0,0,0,0,0,0
0,0,0,0,0,0,0,0,0,0,0,0,0,0,0,0,0,0,0,0,0,0,0,0,0,0,0,0,0
0,0,0,0,0,0,0,0,0,0,0,0,0,0,0,0,0,0,0,0,0,0,0,0,0,0,0,0,0
0,0,0,0,0,0,0,0,0,0,0,0,0,0,0,0,0,0,0,0,0,0,0,0,0,0,0,0,0
0,0,0,0,0,0,0,0,0,0,0,0,0,0,0,0,0,0,0,0,0,0,0,0,0,0,0,0,0
0,0,0,0,0,0,0,0,0,0,0,0,0,0,0,0,0,0,0,0,0,0,0,0,0,0,0,0,0
0,0,0,0,0,0,0,0,0,0,0,0,0,0,0,0,0,0,0,0,0,0,0,0,0,0,0,0,0
0,0,0,0,0,0,0,0,0,0,0,0,0,0,0,0,0,0,0,0,0,0,0,0,0,0,0,0,0
0,0,0,0,0,0,0,0,0,0,0,0,0,0,0,0,0,0,0,0,0,0,0,0,0,0,0,0,0
0,0,0,0,0,0,0,0,0,0,0,0,0,0,0,0,0,0,0,0,0,0,0,0,0,0,0,0,0
0,0,0,0,0,0,0,0,0,0,0,0,0,0,0,0,0,0,0,0,0,0,0,0,0,0,0,0,0
0,0,0,0,0,0,0,0,0,0,0,0,0,0,0,0,0,0,0,0,0,0,0,0,0,0,0,0,0
0,0,0,0,0,0,0,0,0,0,0,0,0,0,0,0,0,0,0,0,0,0,0,0,0,0,0,0,0
0,0,0,0,0,0,0,0,0,0,0,0,0,0,0,0,0,0,0,0,0,0,0,0,0,0,0,0,0
0,0,0,0,0,0,0,0,0,0,0,0,0,0,0,0,0,0,0,0,0,0,0,0,0,0,0,0,0
0,0,0,0,0,0,0,0,0,0,0,0,0,0,0,0,0,0,0,0,0,0,0,0,0,0,0,0,0
0,0,0,0,0,0,0,0,0,0,0,0,0,0,0,0,0,0,0,0,0,0,0,0,0,0,0,0,0
0,0,0,0,0,0,0,0,0,0,0,0,0,0,0,0,0,0,0,0,0,0,0,0,0,0,0,0,0
0,0,0,0,0,0,0,0,0,0,0,0,0,0,0,0,0,0,0,0,0,0,0,0,0,0,0,0,0
0,0,0,0,0,0,0,0,0,0,0,0,0,0,0,0,0,0,0,0,0,0,0,0,0,0,0,0,0
0,0,0,0,0,0,0,0,0,0,0,0,0,0,0,0,0,0,0,0,0,0,0,0,0,0,0,0,0
0,0,0,0,0,0,0,0,0,0,0,0,0,0,0,0,0,0,0,0,0,0,0,0,0,0,0,0,0
0,0,0,0,0,0,0,0,0,0,0,0,0,0,0,0,0,0,0,0,0,0,0,0,0,0,0,0,0
0,0,0,0,0,0,0,0,0,0,0,0,0,0,0,0,0,0,0,0,0,0,0,0,0,0,0,0,0
0,0,0,0,0,0,0,0,0,0,0,0,0,0,0,0,0,0,0,0,0,0,0,0,0,0,0,0,0
0,0,0,0,0,0,0,0,0,0,0,0,0,0,0,0,0,0,0,0,0,0,0,0,0,0,0,0,0
0,0,0,0,0,0,0,0,0,0,0,0,0,0,0,0,0,0,0,0,0,0,0,0,0,0,0,0,0
0,0,0,0,0,0,0,0,0,0,0,0,0,0,0,0,0,0,0,0,0,0,0,0,0,0,0,0,0
:endlayer
layer: 44
0,0,0,0,0,0,0,0,0,0,0,0,0,0,0,0,0,0,0,0,0,0,0,0,0,0,0,0,0
0,0,0,0,0,0,0,0,0,0,0,0,0,0,0,0,0,0,0,0,0,0,0,0,0,0,0,0,0
0,0,0,0,0,0,0,0,0,0,0,0,0,0,0,0,0,0,0,0,0,0,0,0,0,0,0,0,0
0,0,0,0,0,0,0,0,0,0,0,0,0,0,0,0,0,0,0,0,0,0,0,0,0,0,0,0,0
0,0,0,0,0,0,0,0,0,0,0,0,0,0,0,0,0,0,0,0,0,0,0,0,0,0,0,0,0
0,0,0,0,0,0,0,0,0,0,0,0,0,0,0,0,0,0,0,0,0,0,0,0,0,0,0,0,0
0,0,0,0,0,0,0,0,0,0,0,0,0,0,0,0,0,0,0,0,0,0,0,0,0,0,0,0,0
0,0,0,0,0,0,0,0,0,0,0,0,0,0,0,0,0,0,0,0,0,0,0,0,0,0,0,0,0
0,0,0,0,0,0,0,0,0,0,0,0,0,0,0,0,0,0,0,0,0,0,0,0,0,0,0,0,0
0,0,0,0,0,0,0,0,0,0,0,0,0,0,0,0,0,0,0,0,0,0,0,0,0,0,0,0,0
0,0,0,0,0,0,0,0,0,0,0,0,0,0,0,0,0,0,0,0,0,0,0,0,0,0,0,0,0
0,0,0,0,0,0,0,0,0,0,0,0,0,0,0,0,0,0,0,0,0,0,0,0,0,0,0,0,0
0,0,0,0,0,0,0,0,0,0,0,0,0,0,0,0,0,0,0,0,0,0,0,0,0,0,0,0,0
0,0,0,0,0,0,0,0,0,0,0,0,0,0,0,0,0,0,0,0,0,0,0,0,0,0,0,0,0
0,0,0,0,0,0,0,0,0,0,0,0,0,0,0,0,0,0,0,0,0,0,0,0,0,0,0,0,0
0,0,0,0,0,0,0,0,0,0,0,0,0,0,0,0,0,0,0,0,0,0,0,0,0,0,0,0,0
0,0,0,0,0,0,0,0,0,0,0,0,0,0,0,0,0,0,0,0,0,0,0,0,0,0,0,0,0
0,0,0,0,0,0,0,0,0,0,0,0,0,0,0,0,0,0,0,0,0,0,0,0,0,0,0,0,0
0,0,0,0,0,0,0,0,0,0,0,0,0,0,0,0,0,0,0,0,0,0,0,0,0,0,0,0,0
0,0,0,0,0,0,0,0,0,0,0,0,0,0,0,0,0,0,0,0,0,0,0,0,0,0,0,0,0
0,0,0,0,0,0,0,0,0,0,0,0,0,0,0,0,0,0,0,0,0,0,0,0,0,0,0,0,0
0,0,0,0,0,0,0,0,0,0,0,0,0,0,0,0,0,0,0,0,0,0,0,0,0,0,0,0,0
0,0,0,0,0,0,0,0,0,0,0,0,0,0,0,0,0,0,0,0,0,0,0,0,0,0,0,0,0
0,0,0,0,0,0,0,0,0,0,0,0,0,0,0,0,0,0,0,0,0,0,0,0,0,0,0,0,0
0,0,0,0,0,0,0,0,0,0,0,0,0,0,0,0,0,0,0,0,0,0,0,0,0,0,0,0,0
0,0,0,0,0,0,0,0,0,0,0,0,0,0,0,0,0,0,0,0,0,0,0,0,0,0,0,0,0
0,0,0,0,0,0,0,0,0,0,0,0,0,0,0,0,0,0,0,0,0,0,0,0,0,0,0,0,0
0,0,0,0,0,0,0,0,0,0,0,0,0,0,0,0,0,0,0,0,0,0,0,0,0,0,0,0,0
0,0,0,0,0,0,0,0,0,0,0,0,0,0,0,0,0,0,0,0,0,0,0,0,0,0,0,0,0
:endlayer
layer: 45
0,0,0,0,0,0,0,0,0,0,0,0,0,0,0,0,0,0,0,0,0,0,0,0,0,0,0,0,0
0,0,0,0,0,0,0,0,0,0,0,0,0,0,0,0,0,0,0,0,0,0,0,0,0,0,0,0,0
0,0,0,0,0,0,0,0,0,0,0,0,0,0,0,0,0,0,0,0,0,0,0,0,0,0,0,0,0
0,0,0,0,0,0,0,0,0,0,0,0,0,0,0,0,0,0,0,0,0,0,0,0,0,0,0,0,0
0,0,0,0,0,0,0,0,0,0,0,0,0,0,0,0,0,0,0,0,0,0,0,0,0,0,0,0,0
0,0,0,0,0,0,0,0,0,0,0,0,0,0,0,0,0,0,0,0,0,0,0,0,0,0,0,0,0
0,0,0,0,0,0,0,0,0,0,0,0,0,0,0,0,0,0,0,0,0,0,0,0,0,0,0,0,0
0,0,0,0,0,0,0,0,0,0,0,0,0,0,0,0,0,0,0,0,0,0,0,0,0,0,0,0,0
0,0,0,0,0,0,0,0,0,0,0,0,0,0,0,0,0,0,0,0,0,0,0,0,0,0,0,0,0
0,0,0,0,0,0,0,0,0,0,0,0,0,0,0,0,0,0,0,0,0,0,0,0,0,0,0,0,0
0,0,0,0,0,0,0,0,0,0,0,0,0,0,0,0,0,0,0,0,0,0,0,0,0,0,0,0,0
0,0,0,0,0,0,0,0,0,0,0,0,0,0,0,0,0,0,0,0,0,0,0,0,0,0,0,0,0
0,0,0,0,0,0,0,0,0,0,0,0,0,0,0,0,0,0,0,0,0,0,0,0,0,0,0,0,0
0,0,0,0,0,0,0,0,0,0,0,0,0,0,0,0,0,0,0,0,0,0,0,0,0,0,0,0,0
0,0,0,0,0,0,0,0,0,0,0,0,0,0,0,0,0,0,0,0,0,0,0,0,0,0,0,0,0
0,0,0,0,0,0,0,0,0,0,0,0,0,0,0,0,0,0,0,0,0,0,0,0,0,0,0,0,0
0,0,0,0,0,0,0,0,0,0,0,0,0,0,0,0,0,0,0,0,0,0,0,0,0,0,0,0,0
0,0,0,0,0,0,0,0,0,0,0,0,0,0,0,0,0,0,0,0,0,0,0,0,0,0,0,0,0
0,0,0,0,0,0,0,0,0,0,0,0,0,0,0,0,0,0,0,0,0,0,0,0,0,0,0,0,0
0,0,0,0,0,0,0,0,0,0,0,0,0,0,0,0,0,0,0,0,0,0,0,0,0,0,0,0,0
0,0,0,0,0,0,0,0,0,0,0,0,0,0,0,0,0,0,0,0,0,0,0,0,0,0,0,0,0
0,0,0,0,0,0,0,0,0,0,0,0,0,0,0,0,0,0,0,0,0,0,0,0,0,0,0,0,0
0,0,0,0,0,0,0,0,0,0,0,0,0,0,0,0,0,0,0,0,0,0,0,0,0,0,0,0,0
0,0,0,0,0,0,0,0,0,0,0,0,0,0,0,0,0,0,0,0,0,0,0,0,0,0,0,0,0
0,0,0,0,0,0,0,0,0,0,0,0,0,0,0,0,0,0,0,0,0,0,0,0,0,0,0,0,0
0,0,0,0,0,0,0,0,0,0,0,0,0,0,0,0,0,0,0,0,0,0,0,0,0,0,0,0,0
0,0,0,0,0,0,0,0,0,0,0,0,0,0,0,0,0,0,0,0,0,0,0,0,0,0,0,0,0
0,0,0,0,0,0,0,0,0,0,0,0,0,0,0,0,0,0,0,0,0,0,0,0,0,0,0,0,0
0,0,0,0,0,0,0,0,0,0,0,0,0,0,0,0,0,0,0,0,0,0,0,0,0,0,0,0,0
:endlayer

#### RULES ####
rule:
plugin=vanillaBlocks
number=1
data:
JSON:{{"val":{"blockName":{"val":"minecraft:stone","id":"ss"},"meta":{"val":"0","id":"pi"},"buildPass":{"val":"0","id":"pi"}},"id":"ct"}}
:enddata
:endrule

rule:
plugin=vanillaBlocks
number=2
data:
JSON:{{"val":{"blockName":{"val":"minecraft:cobblestone","id":"ss"},"meta":{"val":"0","id":"pi"},"buildPass":{"val":"0","id":"pi"}},"id":"ct"}}
:enddata
:endrule

rule:
plugin=vanillaBlocks
number=3
data:
JSON:{{"val":{"blockName":{"val":"minecraft:stonebrick","id":"ss"},"meta":{"val":"0","id":"pi"},"buildPass":{"val":"0","id":"pi"}},"id":"ct"}}
:enddata
:endrule

rule:
plugin=vanillaInventory
number=4
data:
JSON:{{"val":{"lootLevel":{"val":"0","id":"pi"},"inventoryData":{"val":{"length":{"val":"27","id":"pi"},"inventoryContents":{"val":[{"val":{"item":{"val":"minecraft:bread","id":"ss"},"damage":{"val":"0","id":"pi"},"quantity":{"val":"1","id":"pi"},"slot":{"val":"5","id":"pi"}},"id":"ct"},{"val":{"item":{"val":"minecraft:record_cat","id":"ss"},"damage":{"val":"0","id":"pi"},"quantity":{"val":"1","id":"pi"},"slot":{"val":"9","id":"pi"}},"id":"ct"},{"val":{"item":{"val":"minecraft:redstone","id":"ss"},"damage":{"val":"0","id":"pi"},"quantity":{"val":"2","id":"pi"},"slot":{"val":"23","id":"pi"}},"id":"ct"}],"id":"ls"}},"id":"ct"},"teData":{"val":{"id":{"val":"Chest","id":"ss"},"z":{"val":"1009","id":"pi"},"y":{"val":"77","id":"pi"},"x":{"val":"1189","id":"pi"}},"id":"ct"},"blockName":{"val":"minecraft:chest","id":"ss"},"meta":{"val":"2","id":"pi"},"buildPass":{"val":"0","id":"pi"}},"id":"ct"}}
:enddata
:endrule

rule:
plugin=vanillaBlocks
number=5
data:
JSON:{{"val":{"blockName":{"val":"minecraft:stone_brick_stairs","id":"ss"},"meta":{"val":"3","id":"pi"},"buildPass":{"val":"0","id":"pi"}},"id":"ct"}}
:enddata
:endrule

rule:
plugin=vanillaInventory
number=6
data:
JSON:{{"val":{"lootLevel":{"val":"0","id":"pi"},"inventoryData":{"val":{"length":{"val":"27","id":"pi"},"inventoryContents":{"val":[{"val":{"item":{"val":"minecraft:gunpowder","id":"ss"},"damage":{"val":"0","id":"pi"},"quantity":{"val":"2","id":"pi"},"slot":{"val":"7","id":"pi"}},"id":"ct"},{"val":{"item":{"val":"minecraft:gunpowder","id":"ss"},"damage":{"val":"0","id":"pi"},"quantity":{"val":"2","id":"pi"},"slot":{"val":"18","id":"pi"}},"id":"ct"}],"id":"ls"}},"id":"ct"},"teData":{"val":{"id":{"val":"Chest","id":"ss"},"z":{"val":"1011","id":"pi"},"y":{"val":"77","id":"pi"},"x":{"val":"1189","id":"pi"}},"id":"ct"},"blockName":{"val":"minecraft:chest","id":"ss"},"meta":{"val":"2","id":"pi"},"buildPass":{"val":"0","id":"pi"}},"id":"ct"}}
:enddata
:endrule

rule:
plugin=vanillaBlocks
number=7
data:
JSON:{{"val":{"blockName":{"val":"minecraft:stone_button","id":"ss"},"meta":{"val":"3","id":"pi"},"buildPass":{"val":"2","id":"pi"}},"id":"ct"}}
:enddata
:endrule

rule:
plugin=vanillaBlocks
number=8
data:
JSON:{{"val":{"blockName":{"val":"minecraft:gravel","id":"ss"},"meta":{"val":"0","id":"pi"},"buildPass":{"val":"0","id":"pi"}},"id":"ct"}}
:enddata
:endrule

rule:
plugin=vanillaBlocks
number=9
data:
JSON:{{"val":{"blockName":{"val":"minecraft:torch","id":"ss"},"meta":{"val":"1","id":"pi"},"buildPass":{"val":"2","id":"pi"}},"id":"ct"}}
:enddata
:endrule

rule:
plugin=vanillaBlocks
number=10
data:
JSON:{{"val":{"blockName":{"val":"minecraft:torch","id":"ss"},"meta":{"val":"4","id":"pi"},"buildPass":{"val":"2","id":"pi"}},"id":"ct"}}
:enddata
:endrule

rule:
plugin=vanillaBlocks
number=11
data:
JSON:{{"val":{"blockName":{"val":"minecraft:torch","id":"ss"},"meta":{"val":"2","id":"pi"},"buildPass":{"val":"2","id":"pi"}},"id":"ct"}}
:enddata
:endrule

rule:
plugin=vanillaBlocks
number=12
data:
JSON:{{"val":{"blockName":{"val":"minecraft:stone_brick_stairs","id":"ss"},"meta":{"val":"6","id":"pi"},"buildPass":{"val":"0","id":"pi"}},"id":"ct"}}
:enddata
:endrule

rule:
plugin=vanillaBlocks
number=13
data:
JSON:{{"val":{"blockName":{"val":"minecraft:stone_brick_stairs","id":"ss"},"meta":{"val":"1","id":"pi"},"buildPass":{"val":"0","id":"pi"}},"id":"ct"}}
:enddata
:endrule

rule:
plugin=vanillaInventory
number=14
data:
JSON:{{"val":{"lootLevel":{"val":"0","id":"pi"},"inventoryData":{"val":{"length":{"val":"27","id":"pi"},"inventoryContents":{"val":[{"val":{"item":{"val":"minecraft:gunpowder","id":"ss"},"damage":{"val":"0","id":"pi"},"quantity":{"val":"4","id":"pi"},"slot":{"val":"8","id":"pi"}},"id":"ct"},{"val":{"item":{"val":"minecraft:name_tag","id":"ss"},"damage":{"val":"0","id":"pi"},"quantity":{"val":"1","id":"pi"},"slot":{"val":"19","id":"pi"}},"id":"ct"},{"val":{"item":{"val":"minecraft:gunpowder","id":"ss"},"damage":{"val":"0","id":"pi"},"quantity":{"val":"1","id":"pi"},"slot":{"val":"25","id":"pi"}},"id":"ct"}],"id":"ls"}},"id":"ct"},"teData":{"val":{"id":{"val":"Chest","id":"ss"},"z":{"val":"1000","id":"pi"},"y":{"val":"82","id":"pi"},"x":{"val":"1192","id":"pi"}},"id":"ct"},"blockName":{"val":"minecraft:chest","id":"ss"},"meta":{"val":"5","id":"pi"},"buildPass":{"val":"0","id":"pi"}},"id":"ct"}}
:enddata
:endrule

rule:
plugin=vanillaInventory
number=15
data:
JSON:{{"val":{"lootLevel":{"val":"0","id":"pi"},"inventoryData":{"val":{"length":{"val":"27","id":"pi"},"inventoryContents":{"val":[{"val":{"item":{"val":"minecraft:bucket","id":"ss"},"damage":{"val":"0","id":"pi"},"quantity":{"val":"1","id":"pi"},"slot":{"val":"16","id":"pi"}},"id":"ct"}],"id":"ls"}},"id":"ct"},"teData":{"val":{"id":{"val":"Chest","id":"ss"},"z":{"val":"1000","id":"pi"},"y":{"val":"82","id":"pi"},"x":{"val":"1193","id":"pi"}},"id":"ct"},"blockName":{"val":"minecraft:chest","id":"ss"},"meta":{"val":"5","id":"pi"},"buildPass":{"val":"0","id":"pi"}},"id":"ct"}}
:enddata
:endrule

rule:
plugin=vanillaBlocks
number=16
data:
JSON:{{"val":{"blockName":{"val":"minecraft:fence","id":"ss"},"meta":{"val":"0","id":"pi"},"buildPass":{"val":"0","id":"pi"}},"id":"ct"}}
:enddata
:endrule

rule:
plugin=vanillaDoors
number=17
data:
JSON:{{"val":{"sideFlag":{"val":"8","id":"pb"},"blockName":{"val":"minecraft:wooden_door","id":"ss"},"meta":{"val":"3","id":"pi"},"buildPass":{"val":"2","id":"pi"}},"id":"ct"}}
:enddata
:endrule

rule:
plugin=vanillaDoors
number=18
data:
JSON:{{"val":{"sideFlag":{"val":"8","id":"pb"},"blockName":{"val":"minecraft:wooden_door","id":"ss"},"meta":{"val":"6","id":"pi"},"buildPass":{"val":"2","id":"pi"}},"id":"ct"}}
:enddata
:endrule

rule:
plugin=vanillaInventory
number=19
data:
JSON:{{"val":{"lootLevel":{"val":"0","id":"pi"},"inventoryData":{"val":{"length":{"val":"27","id":"pi"},"inventoryContents":{"val":[{"val":{"item":{"val":"minecraft:gunpowder","id":"ss"},"damage":{"val":"0","id":"pi"},"quantity":{"val":"2","id":"pi"},"slot":{"val":"4","id":"pi"}},"id":"ct"},{"val":{"item":{"val":"minecraft:iron_horse_armor","id":"ss"},"damage":{"val":"0","id":"pi"},"quantity":{"val":"1","id":"pi"},"slot":{"val":"23","id":"pi"}},"id":"ct"}],"id":"ls"}},"id":"ct"},"teData":{"val":{"id":{"val":"Chest","id":"ss"},"z":{"val":"1002","id":"pi"},"y":{"val":"82","id":"pi"},"x":{"val":"1204","id":"pi"}},"id":"ct"},"blockName":{"val":"minecraft:chest","id":"ss"},"meta":{"val":"3","id":"pi"},"buildPass":{"val":"0","id":"pi"}},"id":"ct"}}
:enddata
:endrule

rule:
plugin=vanillaDoors
number=20
data:
JSON:{{"val":{"sideFlag":{"val":"8","id":"pb"},"blockName":{"val":"minecraft:wooden_door","id":"ss"},"meta":{"val":"1","id":"pi"},"buildPass":{"val":"2","id":"pi"}},"id":"ct"}}
:enddata
:endrule

rule:
plugin=vanillaBlocks
number=21
data:
JSON:{{"val":{"blockName":{"val":"minecraft:fence_gate","id":"ss"},"meta":{"val":"1","id":"pi"},"buildPass":{"val":"0","id":"pi"}},"id":"ct"}}
:enddata
:endrule

rule:
plugin=vanillaInventory
number=22
data:
JSON:{{"val":{"lootLevel":{"val":"0","id":"pi"},"inventoryData":{"val":{"length":{"val":"27","id":"pi"},"inventoryContents":{"val":[{"val":{"item":{"val":"minecraft:saddle","id":"ss"},"damage":{"val":"0","id":"pi"},"quantity":{"val":"1","id":"pi"},"slot":{"val":"18","id":"pi"}},"id":"ct"}],"id":"ls"}},"id":"ct"},"teData":{"val":{"id":{"val":"Chest","id":"ss"},"z":{"val":"1003","id":"pi"},"y":{"val":"82","id":"pi"},"x":{"val":"1204","id":"pi"}},"id":"ct"},"blockName":{"val":"minecraft:chest","id":"ss"},"meta":{"val":"3","id":"pi"},"buildPass":{"val":"0","id":"pi"}},"id":"ct"}}
:enddata
:endrule

rule:
plugin=vanillaBlocks
number=23
data:
JSON:{{"val":{"blockName":{"val":"minecraft:lever","id":"ss"},"meta":{"val":"12","id":"pi"},"buildPass":{"val":"2","id":"pi"}},"id":"ct"}}
:enddata
:endrule

rule:
plugin=vanillaDoors
number=24
data:
JSON:{{"val":{"sideFlag":{"val":"8","id":"pb"},"blockName":{"val":"minecraft:iron_door","id":"ss"},"meta":{"val":"1","id":"pi"},"buildPass":{"val":"2","id":"pi"}},"id":"ct"}}
:enddata
:endrule

rule:
plugin=vanillaDoors
number=25
data:
JSON:{{"val":{"sideFlag":{"val":"8","id":"pb"},"blockName":{"val":"minecraft:wooden_door","id":"ss"},"meta":{"val":"0","id":"pi"},"buildPass":{"val":"2","id":"pi"}},"id":"ct"}}
:enddata
:endrule

rule:
plugin=vanillaInventory
number=26
data:
JSON:{{"val":{"lootLevel":{"val":"0","id":"pi"},"inventoryData":{"val":{"length":{"val":"27","id":"pi"},"inventoryContents":{"val":[{"val":{"item":{"val":"minecraft:golden_apple","id":"ss"},"damage":{"val":"0","id":"pi"},"quantity":{"val":"1","id":"pi"},"slot":{"val":"25","id":"pi"}},"id":"ct"}],"id":"ls"}},"id":"ct"},"teData":{"val":{"id":{"val":"Chest","id":"ss"},"z":{"val":"1015","id":"pi"},"y":{"val":"82","id":"pi"},"x":{"val":"1205","id":"pi"}},"id":"ct"},"blockName":{"val":"minecraft:chest","id":"ss"},"meta":{"val":"3","id":"pi"},"buildPass":{"val":"0","id":"pi"}},"id":"ct"}}
:enddata
:endrule

rule:
plugin=vanillaInventory
number=27
data:
JSON:{{"val":{"lootLevel":{"val":"0","id":"pi"},"inventoryData":{"val":{"length":{"val":"27","id":"pi"},"inventoryContents":{"val":[{"val":{"item":{"val":"minecraft:bread","id":"ss"},"damage":{"val":"0","id":"pi"},"quantity":{"val":"1","id":"pi"},"slot":{"val":"21","id":"pi"}},"id":"ct"}],"id":"ls"}},"id":"ct"},"teData":{"val":{"id":{"val":"Chest","id":"ss"},"z":{"val":"1016","id":"pi"},"y":{"val":"82","id":"pi"},"x":{"val":"1205","id":"pi"}},"id":"ct"},"blockName":{"val":"minecraft:chest","id":"ss"},"meta":{"val":"3","id":"pi"},"buildPass":{"val":"0","id":"pi"}},"id":"ct"}}
:enddata
:endrule

rule:
plugin=awAutomationLogic
number=28
data:
JSON:{{"val":{"teData":{"val":{"id":{"val":"Furnace","id":"ss"},"Items":{"val":[],"id":"ls"},"BurnTime":{"val":"0","id":"ps"},"z":{"val":"1018","id":"pi"},"y":{"val":"82","id":"pi"},"CookTime":{"val":"0","id":"ps"},"x":{"val":"1192","id":"pi"}},"id":"ct"},"blockName":{"val":"minecraft:furnace","id":"ss"},"meta":{"val":"3","id":"pi"},"buildPass":{"val":"0","id":"pi"}},"id":"ct"}}
:enddata
:endrule

rule:
plugin=awAutomationLogic
number=29
data:
JSON:{{"val":{"teData":{"val":{"id":{"val":"Furnace","id":"ss"},"Items":{"val":[],"id":"ls"},"BurnTime":{"val":"0","id":"ps"},"z":{"val":"1018","id":"pi"},"y":{"val":"82","id":"pi"},"CookTime":{"val":"0","id":"ps"},"x":{"val":"1193","id":"pi"}},"id":"ct"},"blockName":{"val":"minecraft:furnace","id":"ss"},"meta":{"val":"3","id":"pi"},"buildPass":{"val":"0","id":"pi"}},"id":"ct"}}
:enddata
:endrule

rule:
plugin=awAutomationLogic
number=30
data:
JSON:{{"val":{"teData":{"val":{"id":{"val":"Furnace","id":"ss"},"Items":{"val":[],"id":"ls"},"BurnTime":{"val":"0","id":"ps"},"z":{"val":"1018","id":"pi"},"y":{"val":"82","id":"pi"},"CookTime":{"val":"0","id":"ps"},"x":{"val":"1194","id":"pi"}},"id":"ct"},"blockName":{"val":"minecraft:furnace","id":"ss"},"meta":{"val":"5","id":"pi"},"buildPass":{"val":"0","id":"pi"}},"id":"ct"}}
:enddata
:endrule

rule:
plugin=vanillaBlocks
number=31
data:
JSON:{{"val":{"blockName":{"val":"minecraft:wooden_slab","id":"ss"},"meta":{"val":"8","id":"pi"},"buildPass":{"val":"0","id":"pi"}},"id":"ct"}}
:enddata
:endrule

rule:
plugin=vanillaBlocks
number=32
data:
JSON:{{"val":{"blockName":{"val":"minecraft:crafting_table","id":"ss"},"meta":{"val":"0","id":"pi"},"buildPass":{"val":"0","id":"pi"}},"id":"ct"}}
:enddata
:endrule

rule:
plugin=vanillaInventory
number=33
data:
JSON:{{"val":{"lootLevel":{"val":"0","id":"pi"},"inventoryData":{"val":{"length":{"val":"27","id":"pi"},"inventoryContents":{"val":[{"val":{"item":{"val":"minecraft:record_cat","id":"ss"},"damage":{"val":"0","id":"pi"},"quantity":{"val":"1","id":"pi"},"slot":{"val":"13","id":"pi"}},"id":"ct"},{"val":{"item":{"val":"minecraft:saddle","id":"ss"},"damage":{"val":"0","id":"pi"},"quantity":{"val":"1","id":"pi"},"slot":{"val":"22","id":"pi"}},"id":"ct"},{"val":{"item":{"val":"minecraft:bread","id":"ss"},"damage":{"val":"0","id":"pi"},"quantity":{"val":"1","id":"pi"},"slot":{"val":"25","id":"pi"}},"id":"ct"}],"id":"ls"}},"id":"ct"},"teData":{"val":{"id":{"val":"Chest","id":"ss"},"z":{"val":"1018","id":"pi"},"y":{"val":"82","id":"pi"},"x":{"val":"1199","id":"pi"}},"id":"ct"},"blockName":{"val":"minecraft:chest","id":"ss"},"meta":{"val":"4","id":"pi"},"buildPass":{"val":"0","id":"pi"}},"id":"ct"}}
:enddata
:endrule

rule:
plugin=vanillaInventory
number=34
data:
JSON:{{"val":{"lootLevel":{"val":"0","id":"pi"},"inventoryData":{"val":{"length":{"val":"27","id":"pi"},"inventoryContents":{"val":[{"val":{"item":{"val":"minecraft:iron_ingot","id":"ss"},"damage":{"val":"0","id":"pi"},"quantity":{"val":"4","id":"pi"},"slot":{"val":"24","id":"pi"}},"id":"ct"}],"id":"ls"}},"id":"ct"},"teData":{"val":{"id":{"val":"Chest","id":"ss"},"z":{"val":"1018","id":"pi"},"y":{"val":"82","id":"pi"},"x":{"val":"1200","id":"pi"}},"id":"ct"},"blockName":{"val":"minecraft:chest","id":"ss"},"meta":{"val":"4","id":"pi"},"buildPass":{"val":"0","id":"pi"}},"id":"ct"}}
:enddata
:endrule

rule:
plugin=vanillaBlocks
number=35
data:
JSON:{{"val":{"blockName":{"val":"minecraft:stone_brick_stairs","id":"ss"},"meta":{"val":"0","id":"pi"},"buildPass":{"val":"0","id":"pi"}},"id":"ct"}}
:enddata
:endrule

rule:
plugin=vanillaBlocks
number=36
data:
JSON:{{"val":{"blockName":{"val":"minecraft:stone_brick_stairs","id":"ss"},"meta":{"val":"2","id":"pi"},"buildPass":{"val":"0","id":"pi"}},"id":"ct"}}
:enddata
:endrule

rule:
plugin=vanillaBlocks
number=37
data:
JSON:{{"val":{"blockName":{"val":"minecraft:stone_brick_stairs","id":"ss"},"meta":{"val":"7","id":"pi"},"buildPass":{"val":"0","id":"pi"}},"id":"ct"}}
:enddata
:endrule

rule:
plugin=vanillaBlocks
number=38
data:
JSON:{{"val":{"blockName":{"val":"minecraft:stone_brick_stairs","id":"ss"},"meta":{"val":"5","id":"pi"},"buildPass":{"val":"0","id":"pi"}},"id":"ct"}}
:enddata
:endrule

rule:
plugin=vanillaBlocks
number=39
data:
JSON:{{"val":{"blockName":{"val":"minecraft:torch","id":"ss"},"meta":{"val":"3","id":"pi"},"buildPass":{"val":"2","id":"pi"}},"id":"ct"}}
:enddata
:endrule

rule:
plugin=vanillaDoors
number=40
data:
JSON:{{"val":{"sideFlag":{"val":"0","id":"pb"},"blockName":{"val":"minecraft:wooden_door","id":"ss"},"meta":{"val":"8","id":"pi"},"buildPass":{"val":"2","id":"pi"}},"id":"ct"}}
:enddata
:endrule

rule:
plugin=vanillaDoors
number=41
data:
JSON:{{"val":{"sideFlag":{"val":"0","id":"pb"},"blockName":{"val":"minecraft:wooden_door","id":"ss"},"meta":{"val":"8","id":"pi"},"buildPass":{"val":"2","id":"pi"}},"id":"ct"}}
:enddata
:endrule

rule:
plugin=vanillaDoors
number=42
data:
JSON:{{"val":{"sideFlag":{"val":"0","id":"pb"},"blockName":{"val":"minecraft:wooden_door","id":"ss"},"meta":{"val":"8","id":"pi"},"buildPass":{"val":"2","id":"pi"}},"id":"ct"}}
:enddata
:endrule

rule:
plugin=vanillaDoors
number=43
data:
JSON:{{"val":{"sideFlag":{"val":"0","id":"pb"},"blockName":{"val":"minecraft:iron_door","id":"ss"},"meta":{"val":"8","id":"pi"},"buildPass":{"val":"2","id":"pi"}},"id":"ct"}}
:enddata
:endrule

rule:
plugin=vanillaDoors
number=44
data:
JSON:{{"val":{"sideFlag":{"val":"0","id":"pb"},"blockName":{"val":"minecraft:wooden_door","id":"ss"},"meta":{"val":"8","id":"pi"},"buildPass":{"val":"2","id":"pi"}},"id":"ct"}}
:enddata
:endrule

rule:
plugin=vanillaDoors
number=45
data:
JSON:{{"val":{"sideFlag":{"val":"0","id":"pb"},"blockName":{"val":"minecraft:wooden_door","id":"ss"},"meta":{"val":"8","id":"pi"},"buildPass":{"val":"2","id":"pi"}},"id":"ct"}}
:enddata
:endrule

rule:
plugin=vanillaDoors
number=46
data:
JSON:{{"val":{"sideFlag":{"val":"0","id":"pb"},"blockName":{"val":"minecraft:wooden_door","id":"ss"},"meta":{"val":"8","id":"pi"},"buildPass":{"val":"2","id":"pi"}},"id":"ct"}}
:enddata
:endrule

rule:
plugin=vanillaDoors
number=47
data:
JSON:{{"val":{"sideFlag":{"val":"0","id":"pb"},"blockName":{"val":"minecraft:wooden_door","id":"ss"},"meta":{"val":"8","id":"pi"},"buildPass":{"val":"2","id":"pi"}},"id":"ct"}}
:enddata
:endrule

rule:
plugin=vanillaDoors
number=48
data:
JSON:{{"val":{"sideFlag":{"val":"0","id":"pb"},"blockName":{"val":"minecraft:wooden_door","id":"ss"},"meta":{"val":"8","id":"pi"},"buildPass":{"val":"2","id":"pi"}},"id":"ct"}}
:enddata
:endrule

rule:
plugin=vanillaBlocks
number=49
data:
JSON:{{"val":{"blockName":{"val":"minecraft:lever","id":"ss"},"meta":{"val":"7","id":"pi"},"buildPass":{"val":"2","id":"pi"}},"id":"ct"}}
:enddata
:endrule

rule:
plugin=vanillaBlocks
number=50
data:
JSON:{{"val":{"blockName":{"val":"minecraft:stone_brick_stairs","id":"ss"},"meta":{"val":"4","id":"pi"},"buildPass":{"val":"0","id":"pi"}},"id":"ct"}}
:enddata
:endrule

rule:
plugin=vanillaDoors
number=51
data:
