# Ancient Warfare Structure Template File
# Auto-generated structure template file. created on: 11/24/2014 at: 22:43:8
# Lines beginning with # denote comments

header:
version=2.1
name=TownBlocksManufactory2
size=25,28,24
offset=10,5,23
:endheader

#### VALIDATION ####
validation:
type=ground
survival=false
worldGenEnabled=false
unique=false
preserveBlocks=false
selectionWeight=0
clusterValue=0
minDuplicateDistance=0
dimensionWhiteList=false
dimensionList=
biomeWhiteList=false
biomeList=
leveling=0
fill=0
border=0
validTargetBlocks=
blockSwap=false
data:
:enddata
:endvalidation

#### LAYERS ####
layer: 0
1,1,1,1,1,1,1,1,1,1,1,1,1,1,1,1,1,1,1,1,1,1,1,1,1
1,1,1,1,1,1,1,1,1,1,1,1,1,1,1,1,1,1,1,1,1,1,1,1,1
1,1,2,3,3,3,3,3,3,3,3,3,3,3,3,3,3,3,3,3,3,3,1,1,1
1,1,2,3,3,3,3,3,3,3,3,3,3,3,3,3,3,3,3,3,3,3,1,1,1
1,1,2,2,3,3,3,3,3,3,3,3,3,3,3,3,3,3,3,3,3,3,1,1,1
1,1,2,3,3,3,3,3,3,3,3,3,3,3,3,3,3,3,3,3,3,3,1,1,1
1,1,3,3,3,3,3,3,3,3,3,3,3,3,3,3,3,3,3,2,2,2,1,1,1
1,1,3,3,3,3,3,3,3,3,3,3,3,3,3,3,3,2,2,2,2,2,1,1,1
1,1,3,3,3,3,3,3,3,3,3,3,3,3,3,3,3,2,2,2,2,2,1,1,1
1,1,3,3,3,3,3,3,3,3,3,3,3,3,3,3,3,2,2,2,2,2,1,1,1
1,1,3,3,3,3,3,3,3,3,3,3,3,3,3,3,3,2,2,2,2,2,1,1,1
1,1,3,3,3,3,3,3,3,3,3,3,3,3,3,3,3,3,2,2,2,2,1,1,1
1,1,3,3,3,3,3,3,3,3,3,3,3,3,3,3,3,3,3,2,2,2,1,1,1
1,1,3,3,3,3,3,3,3,3,3,3,3,3,3,3,2,2,2,2,2,2,1,1,1
1,1,3,3,3,3,3,3,3,3,3,3,3,3,3,3,2,2,2,2,2,2,1,1,1
1,1,3,3,2,2,2,2,3,3,3,3,3,3,3,3,2,2,2,2,2,2,1,1,1
1,1,2,2,2,2,2,2,2,3,3,3,3,3,3,3,2,2,2,2,2,2,1,1,1
1,1,2,2,2,2,2,2,2,3,3,3,3,3,3,3,2,2,2,2,2,2,1,1,1
1,1,1,2,2,2,2,2,2,3,3,3,3,3,3,2,2,2,2,2,2,2,1,1,1
1,1,1,2,2,2,2,2,2,3,3,3,3,3,3,2,2,2,2,2,2,2,1,1,1
1,1,1,2,2,2,2,2,2,3,3,1,3,3,3,2,2,2,2,2,2,2,1,1,1
1,1,1,1,1,1,1,1,1,1,1,1,1,1,1,1,1,1,1,1,1,1,1,1,1
1,1,1,1,1,1,1,1,1,1,1,1,1,1,1,1,1,1,1,1,1,1,1,1,1
1,1,1,1,1,1,1,1,1,1,1,1,1,1,1,1,1,1,1,1,1,1,1,1,1
:endlayer
layer: 1
1,1,1,1,1,1,1,1,1,1,1,1,1,1,1,1,1,1,1,1,1,1,1,1,1
1,1,1,1,1,1,1,1,1,1,1,1,1,1,1,1,1,1,1,1,1,1,1,1,1
1,1,3,3,3,3,3,3,3,3,3,3,3,3,3,3,3,3,3,3,3,3,1,1,1
1,1,2,3,3,3,3,3,3,3,3,3,3,3,3,3,3,3,3,3,3,3,1,1,1
1,1,2,3,3,3,3,3,3,3,3,3,3,3,3,3,3,3,3,3,3,3,1,1,1
1,1,3,3,3,3,3,3,3,3,3,3,3,3,3,3,3,3,3,3,3,3,1,1,1
1,1,3,3,3,3,3,3,3,3,3,3,3,3,3,3,3,3,3,3,3,3,1,1,1
1,1,3,3,3,3,3,3,3,3,3,3,3,3,3,3,3,3,3,2,3,3,1,1,1
1,1,3,3,3,3,3,3,3,3,3,3,3,3,3,3,3,2,2,2,2,3,1,1,1
1,1,3,3,3,3,3,3,3,3,3,3,3,3,3,3,3,2,2,2,2,2,1,1,1
1,1,3,3,3,3,3,3,3,3,3,3,3,3,3,3,3,2,2,2,2,2,1,1,1
1,1,3,3,3,3,3,3,3,3,3,3,3,3,3,3,3,2,2,2,2,2,1,1,1
1,1,3,3,3,3,3,3,3,3,3,3,3,3,3,3,3,2,2,2,2,2,1,1,1
1,1,3,3,3,3,3,3,3,3,3,3,3,3,3,3,3,2,2,2,2,2,1,1,1
1,1,3,3,3,3,3,3,3,3,3,3,3,3,3,3,3,2,2,2,2,2,1,1,1
1,1,3,3,2,2,2,2,3,3,3,3,3,3,3,3,2,2,2,2,2,2,1,1,1
1,1,2,2,2,2,2,2,2,3,3,3,3,3,3,3,2,2,2,2,2,2,1,1,1
1,1,2,2,2,2,2,2,2,3,3,3,3,3,3,3,2,2,2,2,2,2,1,1,1
1,1,2,2,2,2,2,2,2,3,3,3,3,3,3,3,2,2,2,2,2,2,1,1,1
1,1,2,2,2,2,2,2,2,3,3,3,3,3,3,3,4,2,2,2,2,2,1,1,1
1,1,2,2,2,2,2,2,2,3,3,3,3,3,3,4,4,2,2,2,2,2,1,1,1
1,1,1,1,1,1,1,1,1,1,1,1,1,1,1,1,1,1,1,1,1,1,1,1,1
1,1,1,1,1,1,1,1,1,1,1,1,1,1,1,1,1,1,1,1,1,1,1,1,1
1,1,1,1,1,1,1,1,1,1,1,1,1,1,1,1,1,1,1,1,1,1,1,1,1
:endlayer
layer: 2
1,1,1,1,1,1,1,1,1,1,1,1,1,1,1,1,1,1,1,1,1,1,1,1,1
1,1,1,1,1,1,1,1,1,1,1,1,1,1,1,1,1,1,1,1,1,1,1,1,1
1,1,3,3,3,3,3,3,3,3,3,3,3,3,3,3,3,3,3,3,3,3,1,1,1
1,1,3,3,3,3,3,3,3,3,3,3,3,3,3,3,3,3,3,3,3,3,1,1,1
1,1,3,3,3,3,3,3,3,3,3,3,3,3,3,3,3,3,3,3,3,3,1,1,1
1,1,3,3,3,3,3,3,3,3,3,3,3,3,3,3,3,3,3,3,3,3,1,1,1
1,1,3,3,3,3,3,3,3,3,3,3,3,3,3,3,3,3,3,3,3,3,1,1,1
1,1,3,3,3,3,3,3,3,3,3,3,3,3,3,3,3,3,3,2,3,3,1,1,1
1,1,3,3,3,3,3,3,3,3,3,3,3,3,3,3,3,3,3,2,3,3,1,1,1
1,1,3,3,3,3,3,3,3,3,3,3,3,3,3,3,3,3,3,2,2,2,1,1,1
1,1,3,3,3,3,3,3,3,3,3,3,3,3,3,3,3,3,2,2,2,2,1,1,1
1,1,3,3,3,3,3,3,3,3,3,3,3,3,3,3,3,3,3,2,2,2,1,1,1
1,1,3,3,3,3,3,3,3,3,3,3,3,3,3,3,3,3,3,2,2,2,1,1,1
1,1,3,3,3,3,3,3,3,3,3,3,3,3,3,3,3,3,2,2,2,2,1,1,1
1,1,3,3,3,3,3,3,3,3,3,3,3,3,3,3,3,3,2,2,2,2,1,1,1
1,1,3,2,2,2,2,2,3,3,3,3,3,3,3,3,3,2,2,2,2,2,1,1,1
1,1,2,2,2,2,2,2,2,3,3,3,3,3,3,3,3,2,2,2,2,2,1,1,1
1,1,2,2,2,2,2,2,2,3,3,3,3,3,3,3,3,2,2,2,2,2,1,1,1
1,1,2,2,2,2,2,2,2,3,3,3,3,3,3,3,2,2,2,2,2,2,1,1,1
1,1,2,2,2,2,2,2,2,3,3,3,3,3,3,3,4,2,2,2,2,2,1,1,1
1,1,2,2,2,2,2,2,2,3,3,3,3,3,3,3,4,4,2,2,2,2,1,1,1
1,1,1,1,1,1,1,1,1,1,1,1,1,1,1,1,1,1,1,1,1,1,1,1,1
1,1,1,1,1,1,1,1,1,1,1,1,1,1,1,1,1,1,1,1,1,1,1,1,1
1,1,1,1,1,1,1,1,1,1,1,1,1,1,1,1,1,1,1,1,1,1,1,1,1
:endlayer
layer: 3
1,1,1,1,1,1,1,1,1,1,1,1,1,1,1,1,1,1,1,1,1,1,1,1,1
1,1,1,1,1,1,1,1,1,1,1,1,1,1,1,1,1,1,1,1,1,1,1,1,1
1,1,1,1,1,1,1,1,3,3,3,3,3,3,3,3,3,3,3,3,3,3,1,1,1
1,1,1,1,1,1,1,1,3,3,3,3,3,3,3,3,3,3,3,3,3,3,1,1,1
1,1,1,1,1,1,1,1,3,3,3,3,3,3,3,3,3,3,3,3,3,3,1,1,1
1,1,1,1,1,1,1,1,3,3,3,3,3,3,3,3,3,3,3,3,3,3,1,1,1
1,1,1,1,1,1,1,1,3,3,3,3,3,3,3,3,3,3,3,3,3,3,1,1,1
1,1,1,1,1,1,1,1,3,3,3,3,3,3,3,3,3,3,3,3,3,3,1,1,1
1,1,1,1,1,1,1,1,3,3,3,3,3,3,3,3,3,3,3,2,3,3,1,1,1
1,1,1,1,1,1,1,1,3,3,3,3,3,3,3,3,3,3,3,3,3,3,1,1,1
1,1,1,3,3,3,3,3,3,3,3,3,3,3,3,3,3,3,3,3,3,3,1,1,1
1,1,1,3,3,3,3,3,3,3,3,3,3,3,3,3,3,3,3,3,3,3,1,1,1
1,1,1,3,3,3,3,3,3,3,3,3,3,3,3,3,3,3,3,3,3,3,1,1,1
1,1,1,3,3,3,3,3,3,3,3,3,3,3,3,3,3,3,3,3,3,3,1,1,1
1,1,1,3,3,3,3,3,3,3,3,3,3,3,3,3,3,3,3,2,2,2,1,1,1
1,1,1,3,3,3,3,2,3,3,3,3,3,3,3,3,3,3,2,2,2,2,1,1,1
1,1,1,2,2,2,2,2,3,3,3,3,3,3,3,3,3,3,2,2,2,2,1,1,1
1,1,1,2,2,2,2,2,3,3,3,3,3,3,3,3,3,2,2,2,2,2,1,1,1
1,1,1,2,2,2,2,2,3,3,3,3,3,3,3,3,3,2,2,2,2,2,1,1,1
1,1,1,2,2,2,2,2,3,3,3,3,3,3,3,3,3,2,2,2,2,2,1,1,1
1,1,1,2,2,2,2,2,3,3,3,3,3,3,3,3,4,4,2,2,2,2,1,1,1
1,1,1,1,1,1,1,1,1,1,1,1,1,1,1,1,1,1,1,1,1,1,1,1,1
1,1,1,1,1,1,1,1,1,1,1,1,1,1,1,1,1,1,1,1,1,1,1,1,1
1,1,1,1,1,1,1,1,1,1,1,1,1,1,1,1,1,1,1,1,1,1,1,1,1
:endlayer
layer: 4
1,1,1,1,1,1,1,1,1,1,1,1,1,1,1,1,1,1,1,1,1,1,1,1,1
1,1,1,1,1,1,1,1,1,1,1,1,1,1,1,1,1,1,1,1,1,1,1,1,1
1,1,1,1,1,1,1,1,3,3,3,3,3,3,3,3,3,3,3,3,3,3,1,1,1
1,1,1,1,1,1,1,1,3,3,3,3,3,3,3,3,3,3,3,3,3,3,1,1,1
1,1,1,1,1,1,1,1,3,3,3,3,3,3,3,3,3,3,3,3,3,3,1,1,1
1,1,1,1,1,1,1,1,3,3,3,3,3,3,3,3,3,3,3,3,3,3,1,1,1
1,1,1,1,1,1,1,1,3,3,3,3,3,3,3,3,3,3,3,3,3,3,1,1,1
1,1,1,1,1,1,1,1,3,3,3,3,3,3,3,3,3,3,3,3,3,3,1,1,1
1,1,1,1,1,1,1,1,1,1,1,1,1,1,1,1,1,1,1,2,1,1,1,1,1
1,1,1,1,1,1,1,1,1,1,1,1,1,1,1,1,1,1,1,1,1,1,1,1,1
1,1,1,1,1,1,1,1,1,1,1,1,1,1,1,1,1,1,1,1,1,1,1,1,1
1,1,1,1,1,1,1,1,1,1,1,1,1,1,1,1,1,1,1,1,1,1,1,1,1
1,1,1,1,1,1,1,1,1,1,1,1,1,1,1,1,1,1,1,1,1,1,1,1,1
1,1,1,1,1,1,1,1,3,3,3,3,3,3,3,3,3,3,3,3,3,3,1,1,1
1,1,1,3,3,3,3,3,3,3,3,3,3,3,3,3,3,3,3,3,3,3,1,1,1
1,1,1,3,3,3,3,3,3,3,3,3,3,3,3,3,3,3,3,3,3,3,1,1,1
1,1,1,2,2,2,2,2,3,3,3,3,3,3,3,3,3,3,3,2,2,2,1,1,1
1,1,1,2,2,2,2,2,3,3,3,3,3,3,3,3,3,3,2,2,2,2,1,1,1
1,1,1,3,2,2,2,2,3,3,3,3,3,3,3,3,3,3,2,2,2,2,1,1,1
1,1,1,3,3,3,2,2,3,3,3,3,3,3,3,3,3,2,2,2,2,2,1,1,1
1,1,1,1,1,1,1,1,1,1,1,1,1,1,1,1,1,2,2,2,2,2,1,1,1
1,1,1,1,1,1,1,1,1,1,1,1,1,1,1,1,1,1,1,1,1,1,1,1,1
1,1,1,1,1,1,1,1,1,1,1,1,1,1,1,1,1,1,1,1,1,1,1,1,1
1,1,1,1,1,1,1,1,1,1,1,1,1,1,1,1,1,1,1,1,1,1,1,1,1
:endlayer
layer: 5
4,4,4,4,4,4,4,4,4,4,4,4,4,4,4,4,4,4,4,4,4,4,4,4,4
4,1,1,1,1,1,1,1,4,4,4,4,4,4,4,4,4,4,4,4,4,4,4,4,4
4,1,1,1,1,1,1,1,5,3,3,3,3,3,3,3,3,3,3,3,3,3,1,4,4
4,1,1,1,1,1,1,1,5,3,3,3,3,3,3,3,3,3,3,3,3,3,1,4,4
4,1,1,1,1,1,1,1,5,3,3,3,3,3,3,3,3,3,3,3,3,3,1,4,4
4,1,1,1,1,1,1,1,5,3,3,3,3,3,3,3,3,3,3,3,3,3,1,4,4
4,1,1,1,1,1,1,1,5,3,3,3,3,3,3,3,3,3,3,3,3,3,1,4,4
4,1,1,1,1,1,1,1,5,5,5,3,5,5,5,3,5,5,5,5,3,5,1,4,4
4,1,1,1,1,1,1,1,4,4,4,4,4,4,4,4,4,4,4,4,4,4,4,4,4
4,1,1,1,1,1,1,1,4,4,4,4,4,4,4,4,4,4,4,4,4,4,4,4,4
4,1,1,1,1,1,1,4,4,4,4,4,4,4,4,4,4,4,4,4,4,4,4,4,4
4,1,1,1,1,1,1,4,4,4,4,1,1,1,1,1,1,1,4,4,4,4,1,4,4
4,1,1,1,1,1,1,1,1,1,1,1,1,1,1,1,1,1,4,4,4,4,1,4,4
4,1,1,1,1,1,1,1,3,3,3,3,3,3,3,3,3,1,4,4,4,4,1,4,4
4,1,1,1,1,1,1,1,3,3,3,3,3,3,3,3,3,3,3,3,1,3,1,4,4
4,1,1,1,1,1,1,1,3,3,3,3,3,3,3,3,3,3,6,6,6,6,1,4,4
4,1,1,1,1,1,1,1,3,3,3,3,3,3,3,3,3,3,6,6,6,6,1,4,4
4,1,1,1,1,1,1,1,3,3,3,3,3,3,3,3,3,3,6,6,6,6,1,4,4
4,1,1,1,1,1,1,1,1,3,3,3,3,3,3,3,3,3,6,6,6,6,1,4,4
4,1,1,1,1,1,1,1,1,1,1,1,1,1,1,1,3,3,6,6,6,6,1,4,4
4,1,1,1,1,1,1,1,1,1,1,1,1,1,1,1,1,3,2,2,2,2,1,4,4
4,1,1,1,1,1,1,1,1,1,1,1,1,1,1,1,1,1,1,1,1,1,1,4,4
4,4,4,4,4,4,4,4,4,4,4,4,4,4,4,4,4,4,4,4,4,4,4,4,4
4,4,4,4,4,4,4,4,4,4,4,4,4,4,4,4,4,4,4,4,4,4,4,4,4
:endlayer
layer: 6
0,0,0,0,0,0,0,0,0,0,0,0,0,0,0,0,0,0,0,0,0,0,0,0,0
0,7,7,7,7,7,7,7,0,0,0,0,0,0,0,0,0,0,0,0,0,0,0,0,0
0,7,7,0,0,0,0,7,0,7,7,7,7,7,7,7,7,7,7,7,7,7,7,0,0
0,7,7,0,0,0,0,7,0,7,3,3,7,7,7,7,7,7,7,3,3,7,7,0,0
0,7,7,0,0,0,0,7,0,7,3,3,7,7,7,7,7,7,7,3,3,7,7,0,0
0,7,7,0,0,0,0,7,0,7,3,3,7,7,7,7,7,7,7,3,3,7,7,0,0
0,7,7,0,0,0,0,7,0,7,7,7,7,7,7,7,7,7,7,7,7,7,7,0,0
0,7,7,0,0,0,0,7,0,0,0,10,0,0,0,10,0,0,0,0,10,0,13,0,0
0,7,7,0,0,0,0,7,0,0,0,0,0,0,0,0,0,0,0,0,0,0,13,0,0
0,7,7,7,7,8,7,7,0,0,0,0,0,0,0,0,0,0,0,0,0,0,0,0,0
0,7,7,0,0,0,0,0,0,0,0,0,0,0,0,0,0,0,0,0,0,0,13,0,0
0,7,0,0,0,0,0,0,0,0,0,9,9,9,9,9,9,7,0,0,0,0,13,0,0
0,7,0,0,0,0,0,7,7,7,7,7,7,7,7,7,7,12,0,0,0,0,13,0,0
0,7,0,0,0,0,0,7,7,7,7,7,7,7,7,7,7,12,0,0,0,0,13,0,0
0,7,7,0,0,0,0,7,7,7,7,7,7,7,7,7,7,7,7,7,8,7,7,0,0
0,7,0,0,0,0,0,7,7,7,7,7,7,7,7,7,7,7,0,0,0,0,7,0,0
0,7,0,0,0,0,0,7,7,7,7,7,7,7,7,7,7,7,0,0,0,0,7,0,0
0,7,0,0,0,0,0,7,7,7,7,7,7,7,7,7,7,7,0,0,0,0,7,0,0
0,7,7,0,0,0,0,7,7,7,7,7,7,7,7,7,7,7,0,0,0,0,7,0,0
0,7,0,0,0,0,0,0,0,0,0,0,0,0,0,0,7,7,0,0,0,0,7,0,0
0,7,7,0,0,0,7,0,0,0,0,0,0,0,7,0,7,7,7,7,7,7,7,0,0
0,0,0,0,0,0,0,0,0,0,0,0,0,0,0,0,11,7,7,7,7,7,7,0,0
0,0,0,0,0,0,0,0,0,0,0,0,0,0,0,0,0,0,0,0,0,0,0,0,0
0,0,0,0,0,0,0,0,0,0,0,0,0,0,0,0,0,0,0,0,0,0,0,0,0
:endlayer
layer: 7
0,0,0,0,0,0,0,0,0,0,0,0,0,0,0,0,0,0,0,0,0,0,0,0,0
0,7,7,7,7,14,7,7,0,0,0,0,0,0,0,0,0,0,0,0,0,0,0,0,0
0,0,7,0,0,0,0,7,0,18,6,6,18,7,6,6,6,7,18,6,6,18,0,0,0
0,7,7,0,0,0,0,7,0,6,20,13,6,6,20,0,0,6,6,20,13,6,0,0,0
0,0,7,0,0,0,0,7,0,6,19,0,6,6,19,0,0,6,6,19,0,6,0,0,0
0,0,14,0,0,0,0,14,0,6,0,0,6,6,0,0,0,6,6,0,0,6,0,0,0
0,0,7,0,0,0,0,7,0,18,6,22,18,7,6,8,6,7,18,6,31,18,0,0,0
0,7,7,0,0,0,0,7,0,0,0,0,0,0,0,0,0,0,0,0,0,0,0,0,0
0,0,7,0,0,0,0,7,0,0,0,0,0,0,0,0,0,0,0,0,0,0,0,0,0
0,7,7,7,7,15,7,7,0,0,0,0,0,0,0,0,0,0,0,0,0,0,0,0,0
0,0,7,0,0,0,0,0,0,0,0,0,0,0,0,0,0,0,0,0,0,0,0,0,0
0,0,0,0,0,0,0,0,0,0,0,0,0,0,0,0,0,13,0,0,0,0,13,0,0
0,0,0,0,0,0,0,7,6,6,7,7,7,0,0,0,7,0,0,0,0,0,0,0,0
0,0,0,0,0,0,0,6,0,0,0,0,25,0,0,27,0,0,0,0,0,0,0,0,0
0,0,7,0,0,0,0,6,0,0,0,7,7,0,0,0,29,7,14,7,30,7,7,0,0
0,0,0,0,0,0,0,6,0,0,0,0,7,7,0,0,0,7,0,0,0,0,7,0,0
0,0,0,0,0,0,0,6,16,13,0,0,24,7,9,7,9,7,0,0,0,0,7,0,0
0,0,0,0,0,0,0,6,6,17,0,21,23,7,26,7,28,7,0,0,0,0,7,0,0
0,0,7,0,0,0,0,7,6,6,6,6,6,7,7,7,7,7,0,0,0,0,7,0,0
0,0,0,0,0,0,0,0,0,0,0,0,0,0,0,0,7,7,0,0,0,0,7,0,0
0,0,13,0,0,0,13,0,0,0,0,0,0,0,13,0,7,7,7,7,7,7,7,0,0
0,0,0,0,0,0,0,0,0,0,0,0,0,0,0,0,0,11,7,7,7,7,7,0,0
0,0,0,0,0,0,0,0,0,0,0,0,0,0,0,0,0,0,0,0,0,0,0,0,0
0,0,0,0,0,0,0,0,0,0,0,0,0,0,0,0,0,0,0,0,0,0,0,0,0
:endlayer
layer: 8
0,0,0,0,0,0,0,0,0,0,0,0,0,0,0,0,0,0,0,0,0,0,0,0,0
0,11,7,7,7,14,7,7,0,0,0,0,0,0,0,0,0,0,0,0,0,0,0,0,0
0,0,7,0,0,0,33,7,0,18,6,6,18,7,6,14,6,7,18,6,6,18,0,0,0
0,11,7,0,0,0,0,7,0,6,0,35,6,6,0,0,0,6,6,0,35,6,0,0,0
0,0,7,0,0,0,0,7,0,14,0,0,14,14,0,0,0,14,14,0,0,14,0,0,0
0,0,14,0,0,0,0,14,0,6,0,0,6,6,0,0,0,6,6,0,0,6,0,0,0
0,0,7,0,0,0,0,7,0,18,6,36,18,7,6,40,6,7,18,6,41,18,0,0,0
0,11,7,0,0,0,0,7,0,0,0,0,0,0,0,0,0,0,0,0,0,0,0,0,0
0,0,7,0,0,0,34,7,0,0,0,0,0,0,0,0,0,0,0,0,0,0,0,0,0
0,11,7,7,7,7,7,7,0,0,0,0,0,0,0,0,0,0,0,0,0,0,0,0,0
0,0,7,32,0,33,0,0,0,0,0,0,0,0,0,0,0,0,0,0,0,0,0,0,0
0,0,0,0,0,0,0,0,0,0,0,0,0,0,0,0,0,13,0,0,0,0,13,0,0
0,0,0,0,0,0,0,7,6,6,7,7,7,0,0,0,7,0,0,0,0,0,0,0,0
0,0,0,0,0,0,0,6,0,0,0,0,37,0,0,0,0,0,0,0,34,0,0,0,0
0,0,7,32,0,0,0,14,0,0,0,7,7,0,0,0,0,7,7,7,7,7,7,0,0
0,0,0,0,0,0,0,6,0,0,0,0,7,38,0,0,0,7,7,7,7,7,7,0,0
0,0,0,0,0,0,0,14,0,35,0,0,0,7,0,39,0,7,33,0,0,0,7,0,0
0,0,0,0,0,0,0,6,0,0,0,0,0,7,0,39,0,7,0,0,0,0,7,0,0
0,0,7,0,0,0,0,7,6,14,6,14,6,7,7,7,7,7,0,0,0,0,7,0,0
0,0,0,0,0,0,0,0,0,0,0,0,0,33,0,0,7,7,0,0,0,0,7,0,0
0,0,13,0,0,0,13,0,0,0,0,0,0,0,13,0,7,7,7,7,7,7,7,0,0
0,0,0,0,0,0,0,0,0,0,0,0,0,0,0,0,0,0,11,7,7,7,7,0,0
0,0,0,0,0,0,0,0,0,0,0,0,0,0,0,0,0,0,0,0,0,0,0,0,0
0,0,0,0,0,0,0,0,0,0,0,0,0,0,0,0,0,0,0,0,0,0,0,0,0
:endlayer
layer: 9
0,0,0,0,0,0,0,0,0,0,0,0,0,0,0,0,0,0,0,0,0,0,0,0,0
0,42,7,7,7,14,7,7,32,34,0,0,34,0,0,0,0,0,34,0,0,34,0,0,0
0,0,7,0,0,0,0,7,0,18,6,6,18,7,6,6,6,7,18,6,6,18,0,0,0
0,0,7,0,0,0,0,7,0,6,33,0,6,6,0,33,0,6,6,0,0,6,0,0,0
0,0,7,0,0,0,0,7,0,6,0,0,6,6,0,0,0,6,6,0,0,6,0,0,0
0,0,14,0,0,0,0,14,0,6,0,34,6,6,0,34,0,6,6,0,34,6,0,0,0
0,0,7,0,0,0,0,7,0,18,6,6,18,7,6,6,6,7,18,6,6,18,0,0,0
0,0,7,0,0,0,0,7,0,33,0,0,33,0,0,0,0,0,33,0,0,33,0,0,0
0,0,7,0,0,0,0,7,0,0,0,0,0,0,0,0,0,0,0,0,0,0,0,0,0
0,0,7,7,7,7,7,7,32,0,0,0,0,0,0,0,0,0,0,0,0,0,0,0,0
0,42,7,0,0,0,0,44,0,0,0,0,0,0,0,0,0,0,0,0,0,0,0,0,0
0,0,33,0,0,0,0,43,34,0,43,0,0,0,0,0,43,13,0,0,0,0,13,0,0
0,0,0,0,0,0,0,7,6,6,7,7,7,0,0,0,7,0,0,0,0,0,0,0,0
0,0,34,0,0,0,0,6,0,33,0,42,7,32,0,0,0,0,0,0,0,0,34,0,0
0,42,7,0,0,0,0,6,0,0,0,7,7,0,0,0,0,7,7,7,7,7,7,32,0
0,0,33,0,0,0,42,6,0,0,0,0,7,45,0,34,0,7,7,7,7,7,7,0,0
0,0,0,0,0,0,0,6,0,0,0,0,0,7,0,7,0,7,0,0,0,0,7,0,0
0,0,0,0,0,0,0,6,0,0,0,0,42,7,0,7,0,7,0,0,0,0,7,0,0
0,42,7,32,0,0,42,7,6,6,6,6,6,7,7,7,7,7,0,0,0,0,7,0,0
0,0,33,0,0,0,0,33,0,0,0,0,0,0,0,0,7,7,7,0,0,0,7,0,0
0,0,13,0,0,0,13,0,0,0,0,0,0,0,13,0,7,7,7,7,7,7,7,0,0
0,0,0,0,0,0,0,0,0,0,0,0,0,0,0,0,0,0,0,11,7,7,7,32,0
0,0,0,0,0,0,0,0,0,0,0,0,0,0,0,0,0,0,0,0,0,0,33,0,0
0,0,0,0,0,0,0,0,0,0,0,0,0,0,0,0,0,0,0,0,0,0,0,0,0
:endlayer
layer: 10
0,0,0,0,0,0,0,0,0,0,0,0,0,0,0,0,0,0,0,0,0,0,0,0,0
0,0,7,7,7,7,7,7,17,17,17,17,17,17,17,17,17,17,17,17,17,17,17,0,0
0,0,7,7,7,7,7,7,0,18,18,18,0,18,18,18,18,18,0,18,18,18,0,0,0
0,0,7,7,7,7,7,7,0,18,0,0,18,18,6,6,6,18,18,0,33,18,0,0,0
0,0,7,7,7,7,7,7,0,18,0,0,18,18,6,6,6,18,18,0,0,18,0,0,0
0,0,7,7,7,7,7,7,0,18,0,0,18,18,6,6,6,18,18,0,0,18,0,0,0
0,0,7,7,7,7,7,7,0,18,18,18,0,18,18,18,18,18,0,18,18,18,0,0,0
0,0,7,7,7,7,7,7,46,46,46,46,46,46,46,46,46,46,46,46,46,46,46,0,0
0,0,7,7,7,7,7,7,0,0,0,0,0,0,0,0,0,0,0,0,0,0,0,0,0
0,0,7,7,7,7,7,7,0,0,0,0,0,0,0,0,0,0,0,0,0,0,0,0,0
0,0,7,7,7,7,7,7,0,0,0,0,0,0,0,0,0,0,0,0,0,0,0,0,0
0,0,7,7,7,7,7,7,7,7,7,7,7,7,7,7,7,6,6,6,6,6,6,0,0
0,0,7,7,7,7,7,7,7,7,7,7,7,7,7,7,7,6,6,6,6,6,6,0,0
0,0,7,7,7,7,7,7,7,7,7,7,7,7,7,7,7,6,6,6,6,6,6,0,0
0,0,7,7,7,7,7,7,7,7,7,7,7,7,7,7,7,7,7,7,7,7,7,0,0
0,0,7,7,7,7,7,7,7,7,7,7,7,7,7,7,7,7,7,7,7,7,7,0,0
0,0,7,7,7,7,7,7,7,7,7,7,7,7,7,7,7,7,7,7,7,7,7,0,0
0,0,7,7,7,7,7,7,7,7,7,7,7,7,7,7,7,7,7,7,7,7,7,0,0
0,0,7,7,7,7,7,7,7,7,7,7,7,7,7,7,7,7,7,7,7,7,7,0,0
0,0,6,6,6,6,6,6,6,6,6,6,6,6,6,6,6,6,6,7,7,7,7,0,0
0,0,6,6,6,6,6,6,6,6,6,6,6,6,6,6,6,6,6,7,7,7,7,0,0
0,0,0,0,0,0,0,0,0,0,0,0,0,0,0,0,0,0,0,0,11,7,7,0,0
0,0,0,0,0,0,0,0,0,0,0,0,0,0,0,0,0,0,0,0,0,0,0,0,0
0,0,0,0,0,0,0,0,0,0,0,0,0,0,0,0,0,0,0,0,0,0,0,0,0
:endlayer
layer: 11
0,0,0,0,0,0,0,0,0,0,0,0,0,0,0,0,0,0,0,0,0,0,0,0,0
0,0,7,7,7,7,7,7,0,0,0,0,0,0,0,0,0,0,0,0,0,0,0,0,0
0,0,7,47,20,20,49,7,17,17,17,17,17,17,17,17,17,17,17,17,17,17,17,0,0
0,0,7,0,19,19,0,7,6,6,6,6,6,6,6,6,6,6,6,6,6,6,51,0,0
0,0,7,0,0,0,0,7,6,6,6,6,6,6,6,6,6,6,6,6,6,6,51,0,0
0,0,7,0,0,0,0,7,6,6,6,6,6,6,6,6,6,6,6,6,6,6,51,0,0
0,0,7,0,0,0,0,7,46,46,46,46,46,46,46,46,46,46,46,46,46,46,46,0,0
0,0,7,0,0,0,0,7,0,0,0,0,0,0,0,0,0,0,0,0,0,0,0,0,0
0,0,7,0,0,0,0,7,0,0,0,0,0,0,0,0,0,0,0,0,0,0,0,0,0
0,0,7,7,7,8,7,7,0,0,0,0,0,0,0,0,0,0,0,0,0,0,0,0,0
0,0,7,0,0,0,0,7,0,0,0,0,0,0,0,0,0,0,0,0,0,0,0,0,0
0,0,7,0,0,0,0,7,7,7,7,7,7,7,7,7,7,13,13,13,13,13,13,0,0
0,0,7,0,0,0,0,25,0,0,0,0,0,0,0,0,7,0,0,0,0,0,13,0,0
0,0,7,7,7,7,22,7,0,0,0,0,0,0,0,0,25,0,0,0,0,0,13,0,0
0,0,7,20,0,48,0,7,0,0,0,0,0,0,0,0,7,7,7,7,7,7,7,0,0
0,0,7,19,0,0,0,7,0,0,0,0,0,0,0,0,0,7,0,0,0,0,7,0,0
0,0,7,0,0,0,0,7,0,0,0,0,0,0,0,0,0,50,0,0,0,0,7,0,0
0,0,7,0,0,0,0,7,0,0,0,0,0,0,0,0,0,7,0,0,0,0,7,0,0
0,0,7,7,22,7,7,7,7,7,7,7,7,7,7,7,7,7,7,7,22,7,7,0,0
0,0,13,0,0,0,0,0,0,0,0,0,0,0,0,0,0,0,0,0,0,0,13,0,0
0,0,13,13,13,13,13,13,13,13,13,13,13,13,13,13,13,13,13,0,0,0,13,0,0
0,0,0,0,0,0,0,0,0,0,0,0,0,0,0,0,0,0,0,0,0,0,13,0,0
0,0,0,0,0,0,0,0,0,0,0,0,0,0,0,0,0,0,0,0,0,0,0,0,0
0,0,0,0,0,0,0,0,0,0,0,0,0,0,0,0,0,0,0,0,0,0,0,0,0
:endlayer
layer: 12
0,0,0,0,0,0,0,0,0,0,0,0,0,0,0,0,0,0,0,0,0,0,0,0,0
0,0,7,7,7,14,7,7,0,0,0,0,0,0,0,0,0,0,0,0,0,0,0,0,0
0,0,7,0,0,0,0,7,0,0,0,0,0,0,0,0,0,0,0,0,0,0,0,0,0
0,0,7,0,0,0,0,7,0,0,0,0,0,0,0,0,0,0,0,0,0,0,0,0,0
0,0,7,0,0,0,0,7,0,0,0,52,0,0,0,0,0,0,0,0,52,0,0,0,0
0,0,14,0,0,0,0,14,0,0,0,0,0,0,0,0,0,0,0,0,0,0,0,0,0
0,0,7,0,0,0,0,7,0,0,0,0,0,0,0,0,0,0,0,0,0,0,0,0,0
0,0,7,0,0,0,0,7,0,0,0,0,0,0,0,0,0,0,0,0,0,0,0,0,0
0,0,7,0,0,0,0,7,0,0,0,0,0,0,0,0,0,0,0,0,0,0,0,0,0
0,0,7,7,7,54,7,7,0,0,0,0,0,0,0,0,0,0,0,0,0,0,0,0,0
0,0,7,0,0,0,0,7,0,0,0,0,0,0,0,0,0,0,0,0,0,0,0,0,0
0,0,14,0,0,0,0,7,7,7,14,7,14,7,14,7,7,0,0,0,0,0,52,0,0
0,0,7,0,0,0,0,56,0,0,0,0,0,0,0,0,7,0,0,0,0,0,0,0,0
0,0,7,7,7,7,55,7,0,0,0,0,0,0,0,0,57,0,0,0,0,0,0,0,0
0,0,7,0,0,0,0,7,0,0,0,0,0,0,0,0,7,7,7,14,14,7,7,0,0
0,0,7,0,0,0,0,7,0,0,0,0,0,0,0,0,0,7,0,0,0,0,7,0,0
0,0,14,0,0,0,0,7,0,0,0,0,0,0,0,0,0,58,0,0,0,0,14,0,0
0,0,7,0,0,0,0,7,0,0,0,0,0,0,0,0,0,7,0,0,0,0,7,0,0
0,0,7,7,53,7,7,7,7,14,7,14,7,14,7,14,7,7,7,7,59,7,7,0,0
0,0,52,0,0,0,0,0,0,0,0,0,0,0,0,0,0,0,0,0,0,0,13,0,0
0,0,13,0,0,52,0,13,0,0,52,0,13,0,0,52,0,0,13,0,0,0,13,0,0
0,0,0,0,0,0,0,0,0,0,0,0,0,0,0,0,0,0,0,0,0,0,52,0,0
0,0,0,0,0,0,0,0,0,0,0,0,0,0,0,0,0,0,0,0,0,0,0,0,0
0,0,0,0,0,0,0,0,0,0,0,0,0,0,0,0,0,0,0,0,0,0,0,0,0
:endlayer
layer: 13
0,0,0,0,0,0,0,0,0,0,0,0,0,0,0,0,0,0,0,0,0,0,0,0,0
0,42,7,7,7,14,7,7,32,0,0,0,0,0,0,0,0,0,0,0,0,0,0,0,0
0,0,7,33,0,0,33,7,0,0,0,0,0,0,0,0,0,0,0,0,0,0,0,0,0
0,0,7,0,0,0,0,7,0,0,0,0,0,0,0,0,0,0,0,0,0,0,0,0,0
0,0,7,0,0,0,0,7,0,0,0,0,0,0,0,0,0,0,0,0,0,0,0,0,0
0,0,14,0,0,0,0,14,0,0,0,0,0,0,0,0,0,0,0,0,0,0,0,0,0
0,0,7,0,0,0,0,7,0,0,0,0,0,0,0,0,0,0,0,0,0,0,0,0,0
0,0,7,0,0,0,0,7,0,0,0,0,0,0,0,0,0,0,0,0,0,0,0,0,0
0,0,7,34,0,0,34,7,0,0,0,0,0,0,0,0,0,0,0,0,0,0,0,0,0
0,42,7,7,7,7,7,7,32,0,0,0,0,0,0,0,0,0,0,0,0,0,0,0,0
0,0,7,0,0,33,0,7,0,0,0,0,0,0,0,0,0,0,0,0,0,0,0,0,0
0,0,14,0,0,0,0,7,7,7,14,7,14,7,14,7,7,0,0,0,0,0,0,0,0
0,0,7,0,0,0,42,7,0,33,0,33,0,33,0,0,7,0,0,0,0,0,0,0,0
0,0,7,7,7,7,7,7,0,0,0,0,0,0,0,0,7,34,0,0,0,0,34,0,0
0,0,7,0,0,33,0,7,32,0,0,0,0,0,0,0,7,7,7,14,14,7,7,0,0
0,0,7,0,0,0,0,7,0,0,0,0,0,0,0,0,0,7,0,0,0,0,7,0,0
0,0,14,0,0,0,0,7,0,0,0,0,0,0,0,0,42,7,0,0,0,0,14,0,0
0,0,7,0,0,34,0,7,32,0,34,0,34,0,34,0,0,7,0,0,0,0,7,0,0
0,0,7,7,7,7,7,7,7,14,7,14,7,14,7,14,7,7,7,7,7,7,7,0,0
0,0,0,0,0,0,0,0,0,0,0,0,0,0,0,0,0,33,0,0,33,0,33,0,0
0,0,13,0,0,0,0,13,0,0,0,0,13,0,0,0,0,0,13,0,0,0,13,0,0
0,0,0,0,0,0,0,0,0,0,0,0,0,0,0,0,0,0,0,0,0,0,0,0,0
0,0,0,0,0,0,0,0,0,0,0,0,0,0,0,0,0,0,0,0,0,0,0,0,0
0,0,0,0,0,0,0,0,0,0,0,0,0,0,0,0,0,0,0,0,0,0,0,0,0
:endlayer
layer: 14
0,60,0,0,0,0,0,0,16,0,0,0,0,0,0,0,0,0,0,0,0,0,0,0,0
0,60,7,7,7,7,7,7,16,0,0,0,0,0,0,0,0,0,0,0,0,0,0,0,0
0,60,6,0,0,0,0,6,16,0,0,0,0,0,0,0,0,0,0,0,0,0,0,0,0
0,60,6,0,0,0,0,6,16,0,0,0,0,0,0,0,0,0,0,0,0,0,0,0,0
0,60,6,0,0,0,0,6,16,0,0,0,0,0,0,0,0,0,0,0,0,0,0,0,0
0,60,6,0,0,0,0,6,16,0,0,0,0,0,0,0,0,0,0,0,0,0,0,0,0
0,60,6,0,0,0,0,6,16,0,0,0,0,0,0,0,0,0,0,0,0,0,0,0,0
0,60,6,0,0,0,0,6,16,0,0,0,0,0,0,0,0,0,0,0,0,0,0,0,0
0,60,6,0,0,0,0,6,16,0,0,0,0,0,0,0,0,0,0,0,0,0,0,0,0
0,60,7,7,7,7,7,7,16,0,0,0,0,0,0,0,0,0,0,0,0,0,0,0,0
0,60,7,0,0,0,0,7,62,62,62,62,62,62,62,62,62,51,0,0,0,0,0,0,0
0,60,7,32,0,0,0,7,7,7,7,7,7,7,7,7,7,0,0,0,0,0,0,0,0
0,60,7,0,0,0,0,7,0,0,0,0,0,0,0,0,7,0,0,0,0,0,0,0,0
0,60,7,7,7,7,7,7,0,0,0,0,0,0,0,42,7,0,0,0,0,0,0,0,0
0,60,7,0,0,0,0,7,0,0,0,0,0,0,0,0,7,7,7,7,7,7,7,0,0
0,60,7,0,0,0,0,7,0,0,0,0,0,0,0,0,7,7,0,0,0,0,7,0,0
0,60,7,32,0,0,0,7,0,0,0,0,0,0,0,0,7,7,32,0,0,42,7,0,0
0,60,7,0,0,0,0,7,0,0,0,0,0,0,0,42,7,7,0,0,0,0,7,0,0
0,60,7,7,7,7,7,7,7,7,7,7,7,7,7,7,7,7,7,7,7,7,7,0,0
0,46,46,46,46,46,46,46,46,46,46,46,46,46,46,46,46,46,46,46,46,46,46,46,0
0,0,61,61,61,61,61,61,61,61,61,61,61,61,61,61,61,61,61,61,61,61,61,0,0
0,0,0,0,0,0,0,0,0,0,0,0,0,0,0,0,0,0,0,0,0,0,0,0,0
0,0,0,0,0,0,0,0,0,0,0,0,0,0,0,0,0,0,0,0,0,0,0,0,0
0,0,0,0,0,0,0,0,0,0,0,0,0,0,0,0,0,0,0,0,0,0,0,0,0
:endlayer
layer: 15
0,0,60,0,0,0,0,16,0,0,0,0,0,0,0,0,0,0,0,0,0,0,0,0,0
0,0,60,7,7,7,7,16,0,0,0,0,0,0,0,0,0,0,0,0,0,0,0,0,0
0,0,60,6,0,0,6,16,0,0,0,0,0,0,0,0,0,0,0,0,0,0,0,0,0
0,0,60,6,0,0,6,16,0,0,0,0,0,0,0,0,0,0,0,0,0,0,0,0,0
0,0,60,6,0,0,6,16,0,0,0,0,0,0,0,0,0,0,0,0,0,0,0,0,0
0,0,60,6,0,0,6,16,0,0,0,0,0,0,0,0,0,0,0,0,0,0,0,0,0
0,0,60,6,0,0,6,16,0,0,0,0,0,0,0,0,0,0,0,0,0,0,0,0,0
0,0,60,6,0,0,6,16,0,0,0,0,0,0,0,0,0,0,0,0,0,0,0,0,0
0,0,60,6,0,0,6,16,0,0,0,0,0,0,0,0,0,0,0,0,0,0,0,0,0
0,0,60,7,7,7,7,16,0,0,0,0,0,0,0,0,0,0,0,0,0,0,0,0,0
0,0,61,61,61,61,61,7,0,0,0,0,0,0,0,0,0,0,0,0,0,0,0,0,0
0,0,61,61,61,61,61,7,17,17,17,17,17,17,17,17,17,17,0,0,0,0,0,0,0
0,0,61,61,61,61,61,7,0,0,0,0,0,0,0,0,7,0,0,0,0,0,0,0,0
0,17,17,17,17,17,17,7,0,0,0,0,0,0,0,0,7,0,0,0,0,0,0,0,0
0,0,7,0,0,0,0,7,0,0,0,0,0,0,0,0,7,17,17,17,17,17,17,17,0
0,0,7,0,0,0,42,7,0,0,0,0,0,0,0,0,7,7,0,0,0,0,7,0,0
0,0,7,0,0,0,0,7,0,0,0,0,0,0,0,0,7,7,0,0,0,0,7,0,0
0,0,7,0,0,0,0,7,0,0,0,0,0,0,0,0,7,7,0,0,0,0,7,0,0
0,46,46,46,46,46,46,46,46,46,46,46,46,46,46,46,46,46,46,46,46,46,46,46,0
0,0,0,0,0,0,0,0,0,0,0,0,0,0,0,0,0,0,0,0,0,0,0,0,0
0,0,0,0,0,0,0,0,0,0,0,0,0,0,0,0,0,0,0,0,0,0,0,0,0
0,0,0,0,0,0,0,0,0,0,0,0,0,0,0,0,0,0,0,0,0,0,0,0,0
0,0,0,0,0,0,0,0,0,0,0,0,0,0,0,0,0,0,0,0,0,0,0,0,0
0,0,0,0,0,0,0,0,0,0,0,0,0,0,0,0,0,0,0,0,0,0,0,0,0
:endlayer
layer: 16
0,0,0,60,0,0,16,0,0,0,0,0,0,0,0,0,0,0,0,0,0,0,0,0,0
0,0,0,60,7,7,16,0,0,0,0,0,0,0,0,0,0,0,0,0,0,0,0,0,0
0,0,0,60,6,6,16,0,0,0,0,0,0,0,0,0,0,0,0,0,0,0,0,0,0
0,0,0,60,6,6,16,0,0,0,0,0,0,0,0,0,0,0,0,0,0,0,0,0,0
0,0,0,60,6,6,16,0,0,0,0,0,0,0,0,0,0,0,0,0,0,0,0,0,0
0,0,0,60,6,6,16,0,0,0,0,0,0,0,0,0,0,0,0,0,0,0,0,0,0
0,0,0,60,6,6,16,0,0,0,0,0,0,0,0,0,0,0,0,0,0,0,0,0,0
0,0,0,60,6,6,16,0,0,0,0,0,0,0,0,0,0,0,0,0,0,0,0,0,0
0,0,0,60,6,6,16,0,0,0,0,0,0,0,0,0,0,0,0,0,0,0,0,0,0
0,0,0,60,7,7,16,0,0,0,0,0,0,0,0,0,0,0,0,0,0,0,0,0,0
0,0,0,0,33,33,0,52,0,0,0,0,0,0,0,0,0,0,0,0,0,0,0,0,0
0,0,0,0,0,0,0,7,0,0,0,0,0,0,0,0,0,0,0,0,0,0,0,0,0
0,0,0,0,0,0,0,17,17,17,17,17,17,17,17,17,17,17,0,0,0,0,0,0,0
0,0,0,0,0,0,0,7,0,0,0,0,0,0,0,0,7,0,0,0,0,0,0,0,0
0,17,17,17,17,17,17,7,0,0,0,0,0,0,0,0,7,0,0,0,0,0,0,0,0
0,0,7,0,0,0,0,7,0,0,0,0,0,0,0,0,7,17,17,17,17,17,17,17,0
0,0,7,0,0,0,0,7,0,0,0,0,0,0,0,0,7,7,6,6,6,6,7,51,0
0,46,46,46,46,46,46,46,46,46,46,46,46,46,46,46,46,46,46,46,46,46,46,46,0
0,0,0,0,0,0,0,0,0,0,0,0,0,0,0,0,0,0,0,0,0,0,0,0,0
0,0,0,0,0,0,0,0,0,0,0,0,0,0,0,0,0,0,0,0,0,0,0,0,0
0,0,0,0,0,0,0,0,0,0,0,0,0,0,0,0,0,0,0,0,0,0,0,0,0
0,0,0,0,0,0,0,0,0,0,0,0,0,0,0,0,0,0,0,0,0,0,0,0,0
0,0,0,0,0,0,0,0,0,0,0,0,0,0,0,0,0,0,0,0,0,0,0,0,0
0,0,0,0,0,0,0,0,0,0,0,0,0,0,0,0,0,0,0,0,0,0,0,0,0
:endlayer
layer: 17
0,0,0,0,60,16,0,0,0,0,0,0,0,0,0,0,0,0,0,0,0,0,0,0,0
0,0,0,0,60,16,0,0,0,0,0,0,0,0,0,0,0,0,0,0,0,0,0,0,0
0,0,0,0,60,16,0,0,0,0,0,0,0,0,0,0,0,0,0,0,0,0,0,0,0
0,0,0,0,60,16,0,0,0,0,0,0,0,0,0,0,0,0,0,0,0,0,0,0,0
0,0,0,0,60,16,0,0,0,0,0,0,0,0,0,0,0,0,0,0,0,0,0,0,0
0,0,0,0,60,16,0,0,0,0,0,0,0,0,0,0,0,0,0,0,0,0,0,0,0
0,0,0,0,60,16,0,0,0,0,0,0,0,0,0,0,0,0,0,0,0,0,0,0,0
0,0,0,0,60,16,0,0,0,0,0,0,0,0,0,0,0,0,0,0,0,0,0,0,0
0,0,0,0,60,16,0,0,0,0,0,0,0,0,0,0,0,0,0,0,0,0,0,0,0
0,0,0,0,60,16,0,0,0,0,0,0,0,0,0,0,0,0,0,0,0,0,0,0,0
0,0,0,0,0,0,0,0,0,0,0,0,0,0,0,0,0,0,0,0,0,0,0,0,0
0,0,0,0,0,0,0,7,0,0,0,0,0,0,0,0,0,0,0,0,0,0,0,0,0
0,0,0,0,0,0,0,0,0,0,0,0,0,0,0,0,0,0,0,0,0,0,0,0,0
0,0,0,0,0,0,0,17,17,17,17,17,17,17,17,17,17,17,0,0,0,0,0,0,0
0,0,0,0,0,0,42,7,0,0,0,0,0,0,0,0,7,0,0,0,0,0,0,0,0
0,17,17,17,17,17,17,7,0,0,0,0,0,0,0,0,7,0,0,0,0,0,0,0,0
0,46,46,46,46,46,46,46,46,46,46,46,46,46,46,46,46,7,0,0,0,0,7,0,0
0,0,0,0,0,0,0,0,0,0,0,0,0,0,0,0,0,0,0,0,0,0,0,0,0
0,0,0,0,0,0,0,0,0,0,0,0,0,0,0,0,0,0,0,0,0,0,0,0,0
0,0,0,0,0,0,0,0,0,0,0,0,0,0,0,0,0,0,0,0,0,0,0,0,0
0,0,0,0,0,0,0,0,0,0,0,0,0,0,0,0,0,0,0,0,0,0,0,0,0
0,0,0,0,0,0,0,0,0,0,0,0,0,0,0,0,0,0,0,0,0,0,0,0,0
0,0,0,0,0,0,0,0,0,0,0,0,0,0,0,0,0,0,0,0,0,0,0,0,0
0,0,0,0,0,0,0,0,0,0,0,0,0,0,0,0,0,0,0,0,0,0,0,0,0
:endlayer
layer: 18
0,0,0,0,0,0,0,0,0,0,0,0,0,0,0,0,0,0,0,0,0,0,0,0,0
0,0,0,0,0,0,0,0,0,0,0,0,0,0,0,0,0,0,0,0,0,0,0,0,0
0,0,0,0,0,0,0,0,0,0,0,0,0,0,0,0,0,0,0,0,0,0,0,0,0
0,0,0,0,0,0,0,0,0,0,0,0,0,0,0,0,0,0,0,0,0,0,0,0,0
0,0,0,0,0,0,0,0,0,0,0,0,0,0,0,0,0,0,0,0,0,0,0,0,0
0,0,0,0,0,0,0,0,0,0,0,0,0,0,0,0,0,0,0,0,0,0,0,0,0
0,0,0,0,0,0,0,0,0,0,0,0,0,0,0,0,0,0,0,0,0,0,0,0,0
0,0,0,0,0,0,0,0,0,0,0,0,0,0,0,0,0,0,0,0,0,0,0,0,0
0,0,0,0,0,0,0,0,0,0,0,0,0,0,0,0,0,0,0,0,0,0,0,0,0
0,0,0,0,0,0,0,0,0,0,0,0,0,0,0,0,0,0,0,0,0,0,0,0,0
0,0,0,0,0,0,0,0,0,0,0,0,0,0,0,0,0,0,0,0,0,0,0,0,0
0,0,0,0,0,0,0,7,0,0,0,0,0,0,0,0,0,0,0,0,0,0,0,0,0
0,0,0,0,0,0,0,0,0,0,0,0,0,0,0,0,0,0,0,0,0,0,0,0,0
0,0,0,0,0,0,0,0,0,0,0,0,0,0,0,0,0,0,0,0,0,0,0,0,0
0,0,0,0,0,0,0,17,17,17,17,17,17,17,17,17,17,17,0,0,0,0,0,0,0
0,0,0,0,0,0,0,46,46,46,46,46,46,46,46,46,46,46,0,0,0,0,0,0,0
0,0,0,0,0,0,0,0,0,0,0,0,0,0,0,0,0,7,0,0,0,0,7,0,0
0,0,0,0,0,0,0,0,0,0,0,0,0,0,0,0,0,0,0,0,0,0,0,0,0
0,0,0,0,0,0,0,0,0,0,0,0,0,0,0,0,0,0,0,0,0,0,0,0,0
0,0,0,0,0,0,0,0,0,0,0,0,0,0,0,0,0,0,0,0,0,0,0,0,0
0,0,0,0,0,0,0,0,0,0,0,0,0,0,0,0,0,0,0,0,0,0,0,0,0
0,0,0,0,0,0,0,0,0,0,0,0,0,0,0,0,0,0,0,0,0,0,0,0,0
0,0,0,0,0,0,0,0,0,0,0,0,0,0,0,0,0,0,0,0,0,0,0,0,0
0,0,0,0,0,0,0,0,0,0,0,0,0,0,0,0,0,0,0,0,0,0,0,0,0
:endlayer
layer: 19
0,0,0,0,0,0,0,0,0,0,0,0,0,0,0,0,0,0,0,0,0,0,0,0,0
0,0,0,0,0,0,0,0,0,0,0,0,0,0,0,0,0,0,0,0,0,0,0,0,0
0,0,0,0,0,0,0,0,0,0,0,0,0,0,0,0,0,0,0,0,0,0,0,0,0
0,0,0,0,0,0,0,0,0,0,0,0,0,0,0,0,0,0,0,0,0,0,0,0,0
0,0,0,0,0,0,0,0,0,0,0,0,0,0,0,0,0,0,0,0,0,0,0,0,0
0,0,0,0,0,0,0,0,0,0,0,0,0,0,0,0,0,0,0,0,0,0,0,0,0
0,0,0,0,0,0,0,0,0,0,0,0,0,0,0,0,0,0,0,0,0,0,0,0,0
0,0,0,0,0,0,0,0,0,0,0,0,0,0,0,0,0,0,0,0,0,0,0,0,0
0,0,0,0,0,0,0,0,0,0,0,0,0,0,0,0,0,0,0,0,0,0,0,0,0
0,0,0,0,0,0,0,0,0,0,0,0,0,0,0,0,0,0,0,0,0,0,0,0,0
0,0,0,0,0,0,0,0,0,0,0,0,0,0,0,0,0,0,0,0,0,0,0,0,0
0,0,0,0,0,0,0,7,0,0,0,0,0,0,0,0,0,0,0,0,0,0,0,0,0
0,0,0,0,0,0,0,0,0,0,0,0,0,0,0,0,0,0,0,0,0,0,0,0,0
0,0,0,0,0,0,0,0,0,0,0,0,0,0,0,0,0,0,0,0,0,0,0,0,0
0,0,0,0,0,0,0,0,0,0,0,0,0,0,0,0,0,0,0,0,0,0,0,0,0
0,0,0,0,0,0,0,0,0,0,0,0,0,0,0,0,0,0,0,0,0,0,0,0,0
0,0,0,0,0,0,0,0,0,0,0,0,0,0,0,0,0,7,0,0,0,0,7,0,0
0,0,0,0,0,0,0,0,0,0,0,0,0,0,0,0,0,0,0,0,0,0,0,0,0
0,0,0,0,0,0,0,0,0,0,0,0,0,0,0,0,0,0,0,0,0,0,0,0,0
0,0,0,0,0,0,0,0,0,0,0,0,0,0,0,0,0,0,0,0,0,0,0,0,0
0,0,0,0,0,0,0,0,0,0,0,0,0,0,0,0,0,0,0,0,0,0,0,0,0
0,0,0,0,0,0,0,0,0,0,0,0,0,0,0,0,0,0,0,0,0,0,0,0,0
0,0,0,0,0,0,0,0,0,0,0,0,0,0,0,0,0,0,0,0,0,0,0,0,0
0,0,0,0,0,0,0,0,0,0,0,0,0,0,0,0,0,0,0,0,0,0,0,0,0
:endlayer
layer: 20
0,0,0,0,0,0,0,0,0,0,0,0,0,0,0,0,0,0,0,0,0,0,0,0,0
0,0,0,0,0,0,0,0,0,0,0,0,0,0,0,0,0,0,0,0,0,0,0,0,0
0,0,0,0,0,0,0,0,0,0,0,0,0,0,0,0,0,0,0,0,0,0,0,0,0
0,0,0,0,0,0,0,0,0,0,0,0,0,0,0,0,0,0,0,0,0,0,0,0,0
0,0,0,0,0,0,0,0,0,0,0,0,0,0,0,0,0,0,0,0,0,0,0,0,0
0,0,0,0,0,0,0,0,0,0,0,0,0,0,0,0,0,0,0,0,0,0,0,0,0
0,0,0,0,0,0,0,0,0,0,0,0,0,0,0,0,0,0,0,0,0,0,0,0,0
0,0,0,0,0,0,0,0,0,0,0,0,0,0,0,0,0,0,0,0,0,0,0,0,0
0,0,0,0,0,0,0,0,0,0,0,0,0,0,0,0,0,0,0,0,0,0,0,0,0
0,0,0,0,0,0,0,0,0,0,0,0,0,0,0,0,0,0,0,0,0,0,0,0,0
0,0,0,0,0,0,0,0,0,0,0,0,0,0,0,0,0,0,0,0,0,0,0,0,0
0,0,0,0,0,0,0,7,0,0,0,0,0,0,0,0,0,0,0,0,0,0,0,0,0
0,0,0,0,0,0,0,0,0,0,0,0,0,0,0,0,0,0,0,0,0,0,0,0,0
0,0,0,0,0,0,0,0,0,0,0,0,0,0,0,0,0,0,0,0,0,0,0,0,0
0,0,0,0,0,0,0,0,0,0,0,0,0,0,0,0,0,0,0,0,0,0,0,0,0
0,0,0,0,0,0,0,0,0,0,0,0,0,0,0,0,0,0,0,0,0,0,0,0,0
0,0,0,0,0,0,0,0,0,0,0,0,0,0,0,0,0,63,0,0,0,0,63,0,0
0,0,0,0,0,0,0,0,0,0,0,0,0,0,0,0,0,0,0,0,0,0,0,0,0
0,0,0,0,0,0,0,0,0,0,0,0,0,0,0,0,0,0,0,0,0,0,0,0,0
0,0,0,0,0,0,0,0,0,0,0,0,0,0,0,0,0,0,0,0,0,0,0,0,0
0,0,0,0,0,0,0,0,0,0,0,0,0,0,0,0,0,0,0,0,0,0,0,0,0
0,0,0,0,0,0,0,0,0,0,0,0,0,0,0,0,0,0,0,0,0,0,0,0,0
0,0,0,0,0,0,0,0,0,0,0,0,0,0,0,0,0,0,0,0,0,0,0,0,0
0,0,0,0,0,0,0,0,0,0,0,0,0,0,0,0,0,0,0,0,0,0,0,0,0
:endlayer
layer: 21
0,0,0,0,0,0,0,0,0,0,0,0,0,0,0,0,0,0,0,0,0,0,0,0,0
0,0,0,0,0,0,0,0,0,0,0,0,0,0,0,0,0,0,0,0,0,0,0,0,0
0,0,0,0,0,0,0,0,0,0,0,0,0,0,0,0,0,0,0,0,0,0,0,0,0
0,0,0,0,0,0,0,0,0,0,0,0,0,0,0,0,0,0,0,0,0,0,0,0,0
0,0,0,0,0,0,0,0,0,0,0,0,0,0,0,0,0,0,0,0,0,0,0,0,0
0,0,0,0,0,0,0,0,0,0,0,0,0,0,0,0,0,0,0,0,0,0,0,0,0
0,0,0,0,0,0,0,0,0,0,0,0,0,0,0,0,0,0,0,0,0,0,0,0,0
0,0,0,0,0,0,0,0,0,0,0,0,0,0,0,0,0,0,0,0,0,0,0,0,0
0,0,0,0,0,0,0,0,0,0,0,0,0,0,0,0,0,0,0,0,0,0,0,0,0
0,0,0,0,0,0,0,0,0,0,0,0,0,0,0,0,0,0,0,0,0,0,0,0,0
0,0,0,0,0,0,0,0,0,0,0,0,0,0,0,0,0,0,0,0,0,0,0,0,0
0,0,0,0,0,0,0,7,0,0,0,0,0,0,0,0,0,0,0,0,0,0,0,0,0
0,0,0,0,0,0,0,0,0,0,0,0,0,0,0,0,0,0,0,0,0,0,0,0,0
0,0,0,0,0,0,0,0,0,0,0,0,0,0,0,0,0,0,0,0,0,0,0,0,0
0,0,0,0,0,0,0,0,0,0,0,0,0,0,0,0,0,0,0,0,0,0,0,0,0
0,0,0,0,0,0,0,0,0,0,0,0,0,0,0,0,0,0,0,0,0,0,0,0,0
0,0,0,0,0,0,0,0,0,0,0,0,0,0,0,0,0,0,0,0,0,0,0,0,0
0,0,0,0,0,0,0,0,0,0,0,0,0,0,0,0,0,0,0,0,0,0,0,0,0
0,0,0,0,0,0,0,0,0,0,0,0,0,0,0,0,0,0,0,0,0,0,0,0,0
0,0,0,0,0,0,0,0,0,0,0,0,0,0,0,0,0,0,0,0,0,0,0,0,0
0,0,0,0,0,0,0,0,0,0,0,0,0,0,0,0,0,0,0,0,0,0,0,0,0
0,0,0,0,0,0,0,0,0,0,0,0,0,0,0,0,0,0,0,0,0,0,0,0,0
0,0,0,0,0,0,0,0,0,0,0,0,0,0,0,0,0,0,0,0,0,0,0,0,0
0,0,0,0,0,0,0,0,0,0,0,0,0,0,0,0,0,0,0,0,0,0,0,0,0
:endlayer
layer: 22
0,0,0,0,0,0,0,0,0,0,0,0,0,0,0,0,0,0,0,0,0,0,0,0,0
0,0,0,0,0,0,0,0,0,0,0,0,0,0,0,0,0,0,0,0,0,0,0,0,0
0,0,0,0,0,0,0,0,0,0,0,0,0,0,0,0,0,0,0,0,0,0,0,0,0
0,0,0,0,0,0,0,0,0,0,0,0,0,0,0,0,0,0,0,0,0,0,0,0,0
0,0,0,0,0,0,0,0,0,0,0,0,0,0,0,0,0,0,0,0,0,0,0,0,0
0,0,0,0,0,0,0,0,0,0,0,0,0,0,0,0,0,0,0,0,0,0,0,0,0
0,0,0,0,0,0,0,0,0,0,0,0,0,0,0,0,0,0,0,0,0,0,0,0,0
0,0,0,0,0,0,0,0,0,0,0,0,0,0,0,0,0,0,0,0,0,0,0,0,0
0,0,0,0,0,0,0,0,0,0,0,0,0,0,0,0,0,0,0,0,0,0,0,0,0
0,0,0,0,0,0,0,0,0,0,0,0,0,0,0,0,0,0,0,0,0,0,0,0,0
0,0,0,0,0,0,0,0,0,0,0,0,0,0,0,0,0,0,0,0,0,0,0,0,0
0,0,0,0,0,0,0,63,0,0,0,0,0,0,0,0,0,0,0,0,0,0,0,0,0
0,0,0,0,0,0,0,0,0,0,0,0,0,0,0,0,0,0,0,0,0,0,0,0,0
0,0,0,0,0,0,0,0,0,0,0,0,0,0,0,0,0,0,0,0,0,0,0,0,0
0,0,0,0,0,0,0,0,0,0,0,0,0,0,0,0,0,0,0,0,0,0,0,0,0
0,0,0,0,0,0,0,0,0,0,0,0,0,0,0,0,0,0,0,0,0,0,0,0,0
0,0,0,0,0,0,0,0,0,0,0,0,0,0,0,0,0,0,0,0,0,0,0,0,0
0,0,0,0,0,0,0,0,0,0,0,0,0,0,0,0,0,0,0,0,0,0,0,0,0
0,0,0,0,0,0,0,0,0,0,0,0,0,0,0,0,0,0,0,0,0,0,0,0,0
0,0,0,0,0,0,0,0,0,0,0,0,0,0,0,0,0,0,0,0,0,0,0,0,0
0,0,0,0,0,0,0,0,0,0,0,0,0,0,0,0,0,0,0,0,0,0,0,0,0
0,0,0,0,0,0,0,0,0,0,0,0,0,0,0,0,0,0,0,0,0,0,0,0,0
0,0,0,0,0,0,0,0,0,0,0,0,0,0,0,0,0,0,0,0,0,0,0,0,0
0,0,0,0,0,0,0,0,0,0,0,0,0,0,0,0,0,0,0,0,0,0,0,0,0
:endlayer
layer: 23
0,0,0,0,0,0,0,0,0,0,0,0,0,0,0,0,0,0,0,0,0,0,0,0,0
0,0,0,0,0,0,0,0,0,0,0,0,0,0,0,0,0,0,0,0,0,0,0,0,0
0,0,0,0,0,0,0,0,0,0,0,0,0,0,0,0,0,0,0,0,0,0,0,0,0
0,0,0,0,0,0,0,0,0,0,0,0,0,0,0,0,0,0,0,0,0,0,0,0,0
0,0,0,0,0,0,0,0,0,0,0,0,0,0,0,0,0,0,0,0,0,0,0,0,0
0,0,0,0,0,0,0,0,0,0,0,0,0,0,0,0,0,0,0,0,0,0,0,0,0
0,0,0,0,0,0,0,0,0,0,0,0,0,0,0,0,0,0,0,0,0,0,0,0,0
0,0,0,0,0,0,0,0,0,0,0,0,0,0,0,0,0,0,0,0,0,0,0,0,0
0,0,0,0,0,0,0,0,0,0,0,0,0,0,0,0,0,0,0,0,0,0,0,0,0
0,0,0,0,0,0,0,0,0,0,0,0,0,0,0,0,0,0,0,0,0,0,0,0,0
0,0,0,0,0,0,0,0,0,0,0,0,0,0,0,0,0,0,0,0,0,0,0,0,0
0,0,0,0,0,0,0,0,0,0,0,0,0,0,0,0,0,0,0,0,0,0,0,0,0
0,0,0,0,0,0,0,0,0,0,0,0,0,0,0,0,0,0,0,0,0,0,0,0,0
0,0,0,0,0,0,0,0,0,0,0,0,0,0,0,0,0,0,0,0,0,0,0,0,0
0,0,0,0,0,0,0,0,0,0,0,0,0,0,0,0,0,0,0,0,0,0,0,0,0
0,0,0,0,0,0,0,0,0,0,0,0,0,0,0,0,0,0,0,0,0,0,0,0,0
0,0,0,0,0,0,0,0,0,0,0,0,0,0,0,0,0,0,0,0,0,0,0,0,0
0,0,0,0,0,0,0,0,0,0,0,0,0,0,0,0,0,0,0,0,0,0,0,0,0
0,0,0,0,0,0,0,0,0,0,0,0,0,0,0,0,0,0,0,0,0,0,0,0,0
0,0,0,0,0,0,0,0,0,0,0,0,0,0,0,0,0,0,0,0,0,0,0,0,0
0,0,0,0,0,0,0,0,0,0,0,0,0,0,0,0,0,0,0,0,0,0,0,0,0
0,0,0,0,0,0,0,0,0,0,0,0,0,0,0,0,0,0,0,0,0,0,0,0,0
0,0,0,0,0,0,0,0,0,0,0,0,0,0,0,0,0,0,0,0,0,0,0,0,0
0,0,0,0,0,0,0,0,0,0,0,0,0,0,0,0,0,0,0,0,0,0,0,0,0
:endlayer
layer: 24
0,0,0,0,0,0,0,0,0,0,0,0,0,0,0,0,0,0,0,0,0,0,0,0,0
0,0,0,0,0,0,0,0,0,0,0,0,0,0,0,0,0,0,0,0,0,0,0,0,0
0,0,0,0,0,0,0,0,0,0,0,0,0,0,0,0,0,0,0,0,0,0,0,0,0
0,0,0,0,0,0,0,0,0,0,0,0,0,0,0,0,0,0,0,0,0,0,0,0,0
0,0,0,0,0,0,0,0,0,0,0,0,0,0,0,0,0,0,0,0,0,0,0,0,0
0,0,0,0,0,0,0,0,0,0,0,0,0,0,0,0,0,0,0,0,0,0,0,0,0
0,0,0,0,0,0,0,0,0,0,0,0,0,0,0,0,0,0,0,0,0,0,0,0,0
0,0,0,0,0,0,0,0,0,0,0,0,0,0,0,0,0,0,0,0,0,0,0,0,0
0,0,0,0,0,0,0,0,0,0,0,0,0,0,0,0,0,0,0,0,0,0,0,0,0
0,0,0,0,0,0,0,0,0,0,0,0,0,0,0,0,0,0,0,0,0,0,0,0,0
0,0,0,0,0,0,0,0,0,0,0,0,0,0,0,0,0,0,0,0,0,0,0,0,0
0,0,0,0,0,0,0,0,0,0,0,0,0,0,0,0,0,0,0,0,0,0,0,0,0
0,0,0,0,0,0,0,0,0,0,0,0,0,0,0,0,0,0,0,0,0,0,0,0,0
0,0,0,0,0,0,0,0,0,0,0,0,0,0,0,0,0,0,0,0,0,0,0,0,0
0,0,0,0,0,0,0,0,0,0,0,0,0,0,0,0,0,0,0,0,0,0,0,0,0
0,0,0,0,0,0,0,0,0,0,0,0,0,0,0,0,0,0,0,0,0,0,0,0,0
0,0,0,0,0,0,0,0,0,0,0,0,0,0,0,0,0,0,0,0,0,0,0,0,0
0,0,0,0,0,0,0,0,0,0,0,0,0,0,0,0,0,0,0,0,0,0,0,0,0
0,0,0,0,0,0,0,0,0,0,0,0,0,0,0,0,0,0,0,0,0,0,0,0,0
0,0,0,0,0,0,0,0,0,0,0,0,0,0,0,0,0,0,0,0,0,0,0,0,0
0,0,0,0,0,0,0,0,0,0,0,0,0,0,0,0,0,0,0,0,0,0,0,0,0
0,0,0,0,0,0,0,0,0,0,0,0,0,0,0,0,0,0,0,0,0,0,0,0,0
0,0,0,0,0,0,0,0,0,0,0,0,0,0,0,0,0,0,0,0,0,0,0,0,0
0,0,0,0,0,0,0,0,0,0,0,0,0,0,0,0,0,0,0,0,0,0,0,0,0
:endlayer
layer: 25
0,0,0,0,0,0,0,0,0,0,0,0,0,0,0,0,0,0,0,0,0,0,0,0,0
0,0,0,0,0,0,0,0,0,0,0,0,0,0,0,0,0,0,0,0,0,0,0,0,0
0,0,0,0,0,0,0,0,0,0,0,0,0,0,0,0,0,0,0,0,0,0,0,0,0
0,0,0,0,0,0,0,0,0,0,0,0,0,0,0,0,0,0,0,0,0,0,0,0,0
0,0,0,0,0,0,0,0,0,0,0,0,0,0,0,0,0,0,0,0,0,0,0,0,0
0,0,0,0,0,0,0,0,0,0,0,0,0,0,0,0,0,0,0,0,0,0,0,0,0
0,0,0,0,0,0,0,0,0,0,0,0,0,0,0,0,0,0,0,0,0,0,0,0,0
0,0,0,0,0,0,0,0,0,0,0,0,0,0,0,0,0,0,0,0,0,0,0,0,0
0,0,0,0,0,0,0,0,0,0,0,0,0,0,0,0,0,0,0,0,0,0,0,0,0
0,0,0,0,0,0,0,0,0,0,0,0,0,0,0,0,0,0,0,0,0,0,0,0,0
0,0,0,0,0,0,0,0,0,0,0,0,0,0,0,0,0,0,0,0,0,0,0,0,0
0,0,0,0,0,0,0,0,0,0,0,0,0,0,0,0,0,0,0,0,0,0,0,0,0
0,0,0,0,0,0,0,0,0,0,0,0,0,0,0,0,0,0,0,0,0,0,0,0,0
0,0,0,0,0,0,0,0,0,0,0,0,0,0,0,0,0,0,0,0,0,0,0,0,0
0,0,0,0,0,0,0,0,0,0,0,0,0,0,0,0,0,0,0,0,0,0,0,0,0
0,0,0,0,0,0,0,0,0,0,0,0,0,0,0,0,0,0,0,0,0,0,0,0,0
0,0,0,0,0,0,0,0,0,0,0,0,0,0,0,0,0,0,0,0,0,0,0,0,0
0,0,0,0,0,0,0,0,0,0,0,0,0,0,0,0,0,0,0,0,0,0,0,0,0
0,0,0,0,0,0,0,0,0,0,0,0,0,0,0,0,0,0,0,0,0,0,0,0,0
0,0,0,0,0,0,0,0,0,0,0,0,0,0,0,0,0,0,0,0,0,0,0,0,0
0,0,0,0,0,0,0,0,0,0,0,0,0,0,0,0,0,0,0,0,0,0,0,0,0
0,0,0,0,0,0,0,0,0,0,0,0,0,0,0,0,0,0,0,0,0,0,0,0,0
0,0,0,0,0,0,0,0,0,0,0,0,0,0,0,0,0,0,0,0,0,0,0,0,0
0,0,0,0,0,0,0,0,0,0,0,0,0,0,0,0,0,0,0,0,0,0,0,0,0
:endlayer
layer: 26
0,0,0,0,0,0,0,0,0,0,0,0,0,0,0,0,0,0,0,0,0,0,0,0,0
0,0,0,0,0,0,0,0,0,0,0,0,0,0,0,0,0,0,0,0,0,0,0,0,0
0,0,0,0,0,0,0,0,0,0,0,0,0,0,0,0,0,0,0,0,0,0,0,0,0
0,0,0,0,0,0,0,0,0,0,0,0,0,0,0,0,0,0,0,0,0,0,0,0,0
0,0,0,0,0,0,0,0,0,0,0,0,0,0,0,0,0,0,0,0,0,0,0,0,0
0,0,0,0,0,0,0,0,0,0,0,0,0,0,0,0,0,0,0,0,0,0,0,0,0
0,0,0,0,0,0,0,0,0,0,0,0,0,0,0,0,0,0,0,0,0,0,0,0,0
0,0,0,0,0,0,0,0,0,0,0,0,0,0,0,0,0,0,0,0,0,0,0,0,0
0,0,0,0,0,0,0,0,0,0,0,0,0,0,0,0,0,0,0,0,0,0,0,0,0
0,0,0,0,0,0,0,0,0,0,0,0,0,0,0,0,0,0,0,0,0,0,0,0,0
0,0,0,0,0,0,0,0,0,0,0,0,0,0,0,0,0,0,0,0,0,0,0,0,0
0,0,0,0,0,0,0,0,0,0,0,0,0,0,0,0,0,0,0,0,0,0,0,0,0
0,0,0,0,0,0,0,0,0,0,0,0,0,0,0,0,0,0,0,0,0,0,0,0,0
0,0,0,0,0,0,0,0,0,0,0,0,0,0,0,0,0,0,0,0,0,0,0,0,0
0,0,0,0,0,0,0,0,0,0,0,0,0,0,0,0,0,0,0,0,0,0,0,0,0
0,0,0,0,0,0,0,0,0,0,0,0,0,0,0,0,0,0,0,0,0,0,0,0,0
0,0,0,0,0,0,0,0,0,0,0,0,0,0,0,0,0,0,0,0,0,0,0,0,0
0,0,0,0,0,0,0,0,0,0,0,0,0,0,0,0,0,0,0,0,0,0,0,0,0
0,0,0,0,0,0,0,0,0,0,0,0,0,0,0,0,0,0,0,0,0,0,0,0,0
0,0,0,0,0,0,0,0,0,0,0,0,0,0,0,0,0,0,0,0,0,0,0,0,0
0,0,0,0,0,0,0,0,0,0,0,0,0,0,0,0,0,0,0,0,0,0,0,0,0
0,0,0,0,0,0,0,0,0,0,0,0,0,0,0,0,0,0,0,0,0,0,0,0,0
0,0,0,0,0,0,0,0,0,0,0,0,0,0,0,0,0,0,0,0,0,0,0,0,0
0,0,0,0,0,0,0,0,0,0,0,0,0,0,0,0,0,0,0,0,0,0,0,0,0
:endlayer
layer: 27
0,0,0,0,0,0,0,0,0,0,0,0,0,0,0,0,0,0,0,0,0,0,0,0,0
0,0,0,0,0,0,0,0,0,0,0,0,0,0,0,0,0,0,0,0,0,0,0,0,0
0,0,0,0,0,0,0,0,0,0,0,0,0,0,0,0,0,0,0,0,0,0,0,0,0
0,0,0,0,0,0,0,0,0,0,0,0,0,0,0,0,0,0,0,0,0,0,0,0,0
0,0,0,0,0,0,0,0,0,0,0,0,0,0,0,0,0,0,0,0,0,0,0,0,0
0,0,0,0,0,0,0,0,0,0,0,0,0,0,0,0,0,0,0,0,0,0,0,0,0
0,0,0,0,0,0,0,0,0,0,0,0,0,0,0,0,0,0,0,0,0,0,0,0,0
0,0,0,0,0,0,0,0,0,0,0,0,0,0,0,0,0,0,0,0,0,0,0,0,0
0,0,0,0,0,0,0,0,0,0,0,0,0,0,0,0,0,0,0,0,0,0,0,0,0
0,0,0,0,0,0,0,0,0,0,0,0,0,0,0,0,0,0,0,0,0,0,0,0,0
0,0,0,0,0,0,0,0,0,0,0,0,0,0,0,0,0,0,0,0,0,0,0,0,0
0,0,0,0,0,0,0,0,0,0,0,0,0,0,0,0,0,0,0,0,0,0,0,0,0
0,0,0,0,0,0,0,0,0,0,0,0,0,0,0,0,0,0,0,0,0,0,0,0,0
0,0,0,0,0,0,0,0,0,0,0,0,0,0,0,0,0,0,0,0,0,0,0,0,0
0,0,0,0,0,0,0,0,0,0,0,0,0,0,0,0,0,0,0,0,0,0,0,0,0
0,0,0,0,0,0,0,0,0,0,0,0,0,0,0,0,0,0,0,0,0,0,0,0,0
0,0,0,0,0,0,0,0,0,0,0,0,0,0,0,0,0,0,0,0,0,0,0,0,0
0,0,0,0,0,0,0,0,0,0,0,0,0,0,0,0,0,0,0,0,0,0,0,0,0
0,0,0,0,0,0,0,0,0,0,0,0,0,0,0,0,0,0,0,0,0,0,0,0,0
0,0,0,0,0,0,0,0,0,0,0,0,0,0,0,0,0,0,0,0,0,0,0,0,0
0,0,0,0,0,0,0,0,0,0,0,0,0,0,0,0,0,0,0,0,0,0,0,0,0
0,0,0,0,0,0,0,0,0,0,0,0,0,0,0,0,0,0,0,0,0,0,0,0,0
0,0,0,0,0,0,0,0,0,0,0,0,0,0,0,0,0,0,0,0,0,0,0,0,0
0,0,0,0,0,0,0,0,0,0,0,0,0,0,0,0,0,0,0,0,0,0,0,0,0
:endlayer

#### RULES ####
rule:
plugin=vanillaBlocks
number=1
data:
JSON:{{"val":{"blockName":{"val":"minecraft:cobblestone","id":"ss"},"meta":{"val":"0","id":"pi"},"buildPass":{"val":"0","id":"pi"}},"id":"ct"}}
:enddata
:endrule

rule:
plugin=vanillaBlocks
number=2
data:
JSON:{{"val":{"blockName":{"val":"minecraft:stone","id":"ss"},"meta":{"val":"0","id":"pi"},"buildPass":{"val":"0","id":"pi"}},"id":"ct"}}
:enddata
:endrule

rule:
plugin=vanillaBlocks
number=3
data:
JSON:{{"val":{"blockName":{"val":"minecraft:dirt","id":"ss"},"meta":{"val":"0","id":"pi"},"buildPass":{"val":"0","id":"pi"}},"id":"ct"}}
:enddata
:endrule

rule:
plugin=vanillaBlocks
number=4
data:
JSON:{{"val":{"blockName":{"val":"minecraft:gravel","id":"ss"},"meta":{"val":"0","id":"pi"},"buildPass":{"val":"0","id":"pi"}},"id":"ct"}}
:enddata
:endrule

rule:
plugin=vanillaBlocks
number=5
data:
JSON:{{"val":{"blockName":{"val":"minecraft:grass","id":"ss"},"meta":{"val":"0","id":"pi"},"buildPass":{"val":"0","id":"pi"}},"id":"ct"}}
:enddata
:endrule

rule:
plugin=vanillaBlocks
number=6
data:
JSON:{{"val":{"blockName":{"val":"minecraft:planks","id":"ss"},"meta":{"val":"0","id":"pi"},"buildPass":{"val":"0","id":"pi"}},"id":"ct"}}
:enddata
:endrule

rule:
plugin=vanillaBlocks
number=7
data:
JSON:{{"val":{"blockName":{"val":"minecraft:stonebrick","id":"ss"},"meta":{"val":"0","id":"pi"},"buildPass":{"val":"0","id":"pi"}},"id":"ct"}}
:enddata
:endrule

rule:
plugin=vanillaDoors
number=8
data:
JSON:{{"val":{"sideFlag":{"val":"8","id":"pb"},"blockName":{"val":"minecraft:wooden_door","id":"ss"},"meta":{"val":"1","id":"pi"},"buildPass":{"val":"2","id":"pi"}},"id":"ct"}}
:enddata
:endrule

rule:
plugin=vanillaBlocks
number=9
data:
JSON:{{"val":{"blockName":{"val":"minecraft:stone_brick_stairs","id":"ss"},"meta":{"val":"2","id":"pi"},"buildPass":{"val":"0","id":"pi"}},"id":"ct"}}
:enddata
:endrule

rule:
plugin=vanillaBlocks
number=10
data:
JSON:{{"val":{"blockName":{"val":"minecraft:stone_brick_stairs","id":"ss"},"meta":{"val":"3","id":"pi"},"buildPass":{"val":"0","id":"pi"}},"id":"ct"}}
:enddata
:endrule

rule:
plugin=vanillaBlocks
number=11
data:
JSON:{{"val":{"blockName":{"val":"minecraft:stone_brick_stairs","id":"ss"},"meta":{"val":"0","id":"pi"},"buildPass":{"val":"0","id":"pi"}},"id":"ct"}}
:enddata
:endrule

rule:
plugin=vanillaBlocks
number=12
data:
JSON:{{"val":{"blockName":{"val":"minecraft:stone_brick_stairs","id":"ss"},"meta":{"val":"1","id":"pi"},"buildPass":{"val":"0","id":"pi"}},"id":"ct"}}
:enddata
:endrule

rule:
plugin=vanillaBlocks
number=13
data:
JSON:{{"val":{"blockName":{"val":"minecraft:fence","id":"ss"},"meta":{"val":"0","id":"pi"},"buildPass":{"val":"0","id":"pi"}},"id":"ct"}}
:enddata
:endrule

rule:
plugin=vanillaBlocks
number=14
data:
JSON:{{"val":{"blockName":{"val":"minecraft:glass_pane","id":"ss"},"meta":{"val":"0","id":"pi"},"buildPass":{"val":"0","id":"pi"}},"id":"ct"}}
:enddata
:endrule

rule:
plugin=vanillaDoors
number=15
data:
JSON:{{"val":{"sideFlag":{"val":"0","id":"pb"},"blockName":{"val":"minecraft:wooden_door","id":"ss"},"meta":{"val":"8","id":"pi"},"buildPass":{"val":"2","id":"pi"}},"id":"ct"}}
:enddata
:endrule

rule:
plugin=vanillaBlocks
number=16
data:
JSON:{{"val":{"blockName":{"val":"minecraft:oak_stairs","id":"ss"},"meta":{"val":"1","id":"pi"},"buildPass":{"val":"0","id":"pi"}},"id":"ct"}}
:enddata
:endrule

rule:
plugin=vanillaBlocks
number=17
data:
JSON:{{"val":{"blockName":{"val":"minecraft:oak_stairs","id":"ss"},"meta":{"val":"2","id":"pi"},"buildPass":{"val":"0","id":"pi"}},"id":"ct"}}
:enddata
:endrule

rule:
plugin=vanillaBlocks
number=18
data:
JSON:{{"val":{"blockName":{"val":"minecraft:log","id":"ss"},"meta":{"val":"0","id":"pi"},"buildPass":{"val":"0","id":"pi"}},"id":"ct"}}
:enddata
:endrule

rule:
plugin=vanillaBlocks
number=19
data:
JSON:{{"val":{"blockName":{"val":"minecraft:bed","id":"ss"},"meta":{"val":"2","id":"pi"},"buildPass":{"val":"2","id":"pi"}},"id":"ct"}}
:enddata
:endrule

rule:
plugin=vanillaBlocks
number=20
data:
JSON:{{"val":{"blockName":{"val":"minecraft:bed","id":"ss"},"meta":{"val":"10","id":"pi"},"buildPass":{"val":"2","id":"pi"}},"id":"ct"}}
:enddata
:endrule

rule:
plugin=vanillaBlocks
number=21
data:
JSON:{{"val":{"blockName":{"val":"minecraft:bed","id":"ss"},"meta":{"val":"3","id":"pi"},"buildPass":{"val":"2","id":"pi"}},"id":"ct"}}
:enddata
:endrule

rule:
plugin=vanillaDoors
number=22
data:
JSON:{{"val":{"sideFlag":{"val":"8","id":"pb"},"blockName":{"val":"minecraft:wooden_door","id":"ss"},"meta":{"val":"3","id":"pi"},"buildPass":{"val":"2","id":"pi"}},"id":"ct"}}
:enddata
:endrule

rule:
plugin=vanillaBlocks
number=23
data:
JSON:{{"val":{"blockName":{"val":"minecraft:bed","id":"ss"},"meta":{"val":"11","id":"pi"},"buildPass":{"val":"2","id":"pi"}},"id":"ct"}}
:enddata
:endrule

rule:
plugin=vanillaInventory
number=24
data:
JSON:{{"val":{"lootLevel":{"val":"0","id":"pi"},"inventoryData":{"val":{"length":{"val":"27","id":"pi"},"inventoryContents":{"val":[],"id":"ls"}},"id":"ct"},"teData":{"val":{"id":{"val":"Chest","id":"ss"},"z":{"val":"783","id":"pi"},"y":{"val":"86","id":"pi"},"x":{"val":"1117","id":"pi"}},"id":"ct"},"blockName":{"val":"minecraft:chest","id":"ss"},"meta":{"val":"4","id":"pi"},"buildPass":{"val":"0","id":"pi"}},"id":"ct"}}
:enddata
:endrule

rule:
plugin=vanillaDoors
number=25
data:
JSON:{{"val":{"sideFlag":{"val":"8","id":"pb"},"blockName":{"val":"minecraft:wooden_door","id":"ss"},"meta":{"val":"2","id":"pi"},"buildPass":{"val":"2","id":"pi"}},"id":"ct"}}
:enddata
:endrule

rule:
plugin=vanillaBlocks
number=26
data:
JSON:{{"val":{"blockName":{"val":"minecraft:lava","id":"ss"},"meta":{"val":"0","id":"pi"},"buildPass":{"val":"0","id":"pi"}},"id":"ct"}}
:enddata
:endrule

rule:
plugin=vanillaBlocks
number=27
data:
JSON:{{"val":{"blockName":{"val":"minecraft:anvil","id":"ss"},"meta":{"val":"2","id":"pi"},"buildPass":{"val":"0","id":"pi"}},"id":"ct"}}
:enddata
:endrule

rule:
plugin=vanillaBlocks
number=28
data:
JSON:{{"val":{"blockName":{"val":"minecraft:water","id":"ss"},"meta":{"val":"0","id":"pi"},"buildPass":{"val":"0","id":"pi"}},"id":"ct"}}
:enddata
:endrule

rule:
plugin=vanillaInventory
number=29
data:
JSON:{{"val":{"lootLevel":{"val":"0","id":"pi"},"inventoryData":{"val":{"length":{"val":"27","id":"pi"},"inventoryContents":{"val":[],"id":"ls"}},"id":"ct"},"teData":{"val":{"id":{"val":"Chest","id":"ss"},"z":{"val":"787","id":"pi"},"y":{"val":"86","id":"pi"},"x":{"val":"1119","id":"pi"}},"id":"ct"},"blockName":{"val":"minecraft:chest","id":"ss"},"meta":{"val":"4","id":"pi"},"buildPass":{"val":"0","id":"pi"}},"id":"ct"}}
:enddata
:endrule

rule:
plugin=vanillaDoors
number=30
data:
JSON:{{"val":{"sideFlag":{"val":"0","id":"pb"},"blockName":{"val":"minecraft:wooden_door","id":"ss"},"meta":{"val":"8","id":"pi"},"buildPass":{"val":"2","id":"pi"}},"id":"ct"}}
:enddata
:endrule

rule:
plugin=vanillaDoors
number=31
data:
JSON:{{"val":{"sideFlag":{"val":"14","id":"pb"},"blockName":{"val":"minecraft:wooden_door","id":"ss"},"meta":{"val":"3","id":"pi"},"buildPass":{"val":"2","id":"pi"}},"id":"ct"}}
:enddata
:endrule

rule:
plugin=vanillaBlocks
number=32
data:
JSON:{{"val":{"blockName":{"val":"minecraft:torch","id":"ss"},"meta":{"val":"1","id":"pi"},"buildPass":{"val":"2","id":"pi"}},"id":"ct"}}
:enddata
:endrule

rule:
plugin=vanillaBlocks
number=33
data:
JSON:{{"val":{"blockName":{"val":"minecraft:torch","id":"ss"},"meta":{"val":"3","id":"pi"},"buildPass":{"val":"2","id":"pi"}},"id":"ct"}}
:enddata
:endrule

rule:
plugin=vanillaBlocks
number=34
data:
JSON:{{"val":{"blockName":{"val":"minecraft:torch","id":"ss"},"meta":{"val":"4","id":"pi"},"buildPass":{"val":"2","id":"pi"}},"id":"ct"}}
:enddata
:endrule

rule:
plugin=vanillaBlocks
number=35
data:
JSON:{{"val":{"blockName":{"val":"minecraft:wooden_pressure_plate","id":"ss"},"meta":{"val":"0","id":"pi"},"buildPass":{"val":"2","id":"pi"}},"id":"ct"}}
:enddata
:endrule

rule:
plugin=vanillaDoors
number=36
data:
JSON:{{"val":{"sideFlag":{"val":"0","id":"pb"},"blockName":{"val":"minecraft:wooden_door","id":"ss"},"meta":{"val":"8","id":"pi"},"buildPass":{"val":"2","id":"pi"}},"id":"ct"}}
:enddata
:endrule

rule:
plugin=vanillaDoors
number=37
data:
JSON:{{"val":{"sideFlag":{"val":"0","id":"pb"},"blockName":{"val":"minecraft:wooden_door","id":"ss"},"meta":{"val":"8","id":"pi"},"buildPass":{"val":"2","id":"pi"}},"id":"ct"}}
:enddata
:endrule

rule:
plugin=awAutomationLogic
number=38
data:
JSON:{{"val":{"teData":{"val":{"id":{"val":"Furnace","id":"ss"},"Items":{"val":[],"id":"ls"},"BurnTime":{"val":"0","id":"ps"},"z":{"val":"784","id":"pi"},"y":{"val":"87","id":"pi"},"CookTime":{"val":"0","id":"ps"},"x":{"val":"1118","id":"pi"}},"id":"ct"},"blockName":{"val":"minecraft:furnace","id":"ss"},"meta":{"val":"2","id":"pi"},"buildPass":{"val":"0","id":"pi"}},"id":"ct"}}
:enddata
:endrule

rule:
plugin=vanillaBlocks
number=39
data:
JSON:{{"val":{"blockName":{"val":"minecraft:iron_bars","id":"ss"},"meta":{"val":"0","id":"pi"},"buildPass":{"val":"0","id":"pi"}},"id":"ct"}}
:enddata
:endrule

rule:
plugin=vanillaDoors
number=40
data:
JSON:{{"val":{"sideFlag":{"val":"0","id":"pb"},"blockName":{"val":"minecraft:wooden_door","id":"ss"},"meta":{"val":"8","id":"pi"},"buildPass":{"val":"2","id":"pi"}},"id":"ct"}}
:enddata
:endrule

rule:
plugin=vanillaDoors
number=41
data:
JSON:{{"val":{"sideFlag":{"val":"0","id":"pb"},"blockName":{"val":"minecraft:wooden_door","id":"ss"},"meta":{"val":"14","id":"pi"},"buildPass":{"val":"2","id":"pi"}},"id":"ct"}}
:enddata
:endrule

rule:
plugin=vanillaBlocks
number=42
data:
JSON:{{"val":{"blockName":{"val":"minecraft:torch","id":"ss"},"meta":{"val":"2","id":"pi"},"buildPass":{"val":"2","id":"pi"}},"id":"ct"}}
:enddata
:endrule

rule:
plugin=vanillaBlocks
number=43
data:
JSON:{{"val":{"blockName":{"val":"minecraft:stone_brick_stairs","id":"ss"},"meta":{"val":"6","id":"pi"},"buildPass":{"val":"0","id":"pi"}},"id":"ct"}}
:enddata
:endrule

rule:
plugin=vanillaBlocks
number=44
data:
JSON:{{"val":{"blockName":{"val":"minecraft:stone_brick_stairs","id":"ss"},"meta":{"val":"7","id":"pi"},"buildPass":{"val":"0","id":"pi"}},"id":"ct"}}
:enddata
:endrule

rule:
plugin=awAutomationLogic
number=45
data:
JSON:{{"val":{"teData":{"val":{"id":{"val":"Furnace","id":"ss"},"Items":{"val":[],"id":"ls"},"BurnTime":{"val":"0","id":"ps"},"z":{"val":"784","id":"pi"},"y":{"val":"88","id":"pi"},"CookTime":{"val":"0","id":"ps"},"x":{"val":"1118","id":"pi"}},"id":"ct"},"blockName":{"val":"minecraft:furnace","id":"ss"},"meta":{"val":"2","id":"pi"},"buildPass":{"val":"0","id":"pi"}},"id":"ct"}}
:enddata
:endrule

rule:
plugin=vanillaBlocks
number=46
data:
JSON:{{"val":{"blockName":{"val":"minecraft:oak_stairs","id":"ss"},"meta":{"val":"3","id":"pi"},"buildPass":{"val":"0","id":"pi"}},"id":"ct"}}
:enddata
:endrule

rule:
plugin=vanillaInventory
number=47
data:
JSON:{{"val":{"lootLevel":{"val":"0","id":"pi"},"inventoryData":{"val":{"length":{"val":"27","id":"pi"},"inventoryContents":{"val":[],"id":"ls"}},"id":"ct"},"teData":{"val":{"id":{"val":"Chest","id":"ss"},"z":{"val":"774","id":"pi"},"y":{"val":"90","id":"pi"},"x":{"val":"1131","id":"pi"}},"id":"ct"},"blockName":{"val":"minecraft:chest","id":"ss"},"meta":{"val":"3","id":"pi"},"buildPass":{"val":"0","id":"pi"}},"id":"ct"}}
:enddata
:endrule

rule:
plugin=vanillaInventory
number=48
data:
JSON:{{"val":{"lootLevel":{"val":"0","id":"pi"},"inventoryData":{"val":{"length":{"val":"27","id":"pi"},"inventoryContents":{"val":[],"id":"ls"}},"id":"ct"},"teData":{"val":{"id":{"val":"Chest","id":"ss"},"z":{"val":"776","id":"pi"},"y":{"val":"90","id":"pi"},"x":{"val":"1119","id":"pi"}},"id":"ct"},"blockName":{"val":"minecraft:chest","id":"ss"},"meta":{"val":"3","id":"pi"},"buildPass":{"val":"0","id":"pi"}},"id":"ct"}}
:enddata
:endrule

rule:
plugin=vanillaInventory
number=49
data:
JSON:{{"val":{"lootLevel":{"val":"0","id":"pi"},"inventoryData":{"val":{"length":{"val":"27","id":"pi"},"inventoryContents":{"val":[],"id":"ls"}},"id":"ct"},"teData":{"val":{"id":{"val":"Chest","id":"ss"},"z":{"val":"777","id":"pi"},"y":{"val":"90","id":"pi"},"x":{"val":"1131","id":"pi"}},"id":"ct"},"blockName":{"val":"minecraft:chest","id":"ss"},"meta":{"val":"3","id":"pi"},"buildPass":{"val":"0","id":"pi"}},"id":"ct"}}
:enddata
:endrule

rule:
plugin=vanillaDoors
number=50
data:
JSON:{{"val":{"sideFlag":{"val":"8","id":"pb"},"blockName":{"val":"minecraft:wooden_door","id":"ss"},"meta":{"val":"0","id":"pi"},"buildPass":{"val":"2","id":"pi"}},"id":"ct"}}
:enddata
:endrule

rule:
plugin=vanillaBlocks
number=51
data:
JSON:{{"val":{"blockName":{"val":"minecraft:oak_stairs","id":"ss"},"meta":{"val":"5","id":"pi"},"buildPass":{"val":"0","id":"pi"}},"id":"ct"}}
:enddata
:endrule

rule:
plugin=vanillaBlocks
number=52
data:
JSON:{{"val":{"blockName":{"val":"minecraft:torch","id":"ss"},"meta":{"val":"5","id":"pi"},"buildPass":{"val":"2","id":"pi"}},"id":"ct"}}
:enddata
:endrule

rule:
plugin=vanillaDoors
number=53
data:
JSON:{{"val":{"sideFlag":{"val":"0","id":"pb"},"blockName":{"val":"minecraft:wooden_door","id":"ss"},"meta":{"val":"8","id":"pi"},"buildPass":{"val":"2","id":"pi"}},"id":"ct"}}
:enddata
:endrule

rule:
plugin=vanillaDoors
number=54
data:
JSON:{{"val":{"sideFlag":{"val":"0","id":"pb"},"blockName":{"val":"minecraft:wooden_door","id":"ss"},"meta":{"val":"8","id":"pi"},"buildPass":{"val":"2","id":"pi"}},"id":"ct"}}
:enddata
:endrule

rule:
plugin=vanillaDoors
number=55
data:
JSON:{{"val":{"sideFlag":{"val":"0","id":"pb"},"blockName":{"val":"minecraft:wooden_door","id":"ss"},"meta":{"val":"8","id":"pi"},"buildPass":{"val":"2","id":"pi"}},"id":"ct"}}
:enddata
:endrule

rule:
plugin=vanillaDoors
number=56
data:
JSON:{{"val":{"sideFlag":{"val":"0","id":"pb"},"blockName":{"val":"minecraft:wooden_door","id":"ss"},"meta":{"val":"8","id":"pi"},"buildPass":{"val":"2","id":"pi"}},"id":"ct"}}
:enddata
:endrule

rule:
plugin=vanillaDoors
number=57
data:
JSON:{{"val":{"sideFlag":{"val":"0","id":"pb"},"blockName":{"val":"minecraft:wooden_door","id":"ss"},"meta":{"val":"8","id":"pi"},"buildPass":{"val":"2","id":"pi"}},"id":"ct"}}
:enddata
:endrule

rule:
plugin=vanillaDoors
number=58
data:
JSON:{{"val":{"sideFlag":{"val":"0","id":"pb"},"blockName":{"val":"minecraft:wooden_door","id":"ss"},"meta":{"val":"8","id":"pi"},"buildPass":{"val":"2","id":"pi"}},"id":"ct"}}
:enddata
:endrule

rule:
plugin=vanillaDoors
number=59
data:
JSON:{{"val":{"sideFlag":{"val":"0","id":"pb"},"blockName":{"val":"minecraft:wooden_door","id":"ss"},"meta":{"val":"8","id":"pi"},"buildPass":{"val":"2","id":"pi"}},"id":"ct"}}
:enddata
:endrule

rule:
plugin=vanillaBlocks
number=60
data:
JSON:{{"val":{"blockName":{"val":"minecraft:oak_stairs","id":"ss"},"meta":{"val":"0","id":"pi"},"buildPass":{"val":"0","id":"pi"}},"id":"ct"}}
:enddata
:endrule

rule:
plugin=vanillaBlocks
number=61
data:
JSON:{{"val":{"blockName":{"val":"minecraft:wooden_slab","id":"ss"},"meta":{"val":"0","id":"pi"},"buildPass":{"val":"0","id":"pi"}},"id":"ct"}}
:enddata
:endrule

rule:
plugin=vanillaBlocks
number=62
data:
JSON:{{"val":{"blockName":{"val":"minecraft:oak_stairs","id":"ss"},"meta":{"val":"6","id":"pi"},"buildPass":{"val":"0","id":"pi"}},"id":"ct"}}
:enddata
:endrule

rule:
plugin=vanillaBlocks
number=63
data:
JSON:{{"val":{"blockName":{"val":"minecraft:cobblestone_wall","id":"ss"},"meta":{"val":"0","id":"pi"},"buildPass":{"val":"0","id":"pi"}},"id":"ct"}}
:enddata
:endrule

#### ENTITIES ####
