# Ancient Warfare Structure Template File
# Auto-generated structure template file. created on: 11/25/2014 at: 20:18:36
# Lines beginning with # denote comments

header:
version=2.1
name=TownBlocksSingleHouse6
size=15,22,11
offset=3,3,8
:endheader

#### VALIDATION ####
validation:
type=ground
survival=false
worldGenEnabled=false
unique=false
preserveBlocks=false
selectionWeight=0
clusterValue=0
minDuplicateDistance=0
dimensionWhiteList=false
dimensionList=
biomeWhiteList=false
biomeList=
leveling=0
fill=0
border=0
validTargetBlocks=
blockSwap=false
data:
:enddata
:endvalidation

#### LAYERS ####
layer: 0
1,1,1,1,1,1,1,1,1,1,1,1,1,1,1
1,1,1,1,1,1,1,1,1,1,1,1,1,1,1
1,1,1,1,1,1,1,1,1,1,1,1,1,1,1
1,1,1,1,1,1,1,1,1,1,1,1,1,1,1
1,1,1,1,1,1,1,1,1,1,1,1,1,1,1
1,1,1,1,1,1,1,1,1,1,1,1,1,1,1
1,1,1,1,1,1,1,1,1,1,1,1,1,1,1
1,1,1,1,1,1,1,1,1,1,1,1,1,1,1
1,1,1,1,1,1,1,1,1,1,1,1,1,1,1
1,1,1,1,1,1,1,1,1,1,1,1,1,1,1
1,1,1,1,1,1,1,1,1,1,1,1,1,1,1
:endlayer
layer: 1
1,1,1,1,1,1,1,1,1,1,1,1,1,1,1
1,1,1,1,1,1,1,1,1,1,1,1,1,1,1
1,1,1,1,1,1,1,1,1,1,1,1,1,1,1
1,1,1,1,1,1,1,1,1,1,1,1,1,1,1
1,1,1,1,1,1,1,1,1,1,1,1,1,1,1
1,1,1,1,1,1,1,1,1,1,1,1,1,1,1
1,1,1,1,1,1,1,1,1,1,1,1,1,1,1
1,1,1,1,1,1,1,1,1,1,1,1,1,1,1
1,1,1,1,1,1,1,1,1,1,1,1,1,1,1
1,1,1,1,1,1,1,1,1,1,1,1,1,1,1
1,1,1,1,1,1,1,1,1,1,1,1,1,1,1
:endlayer
layer: 2
2,2,2,2,2,2,2,2,2,2,2,2,2,2,2
2,2,2,2,2,2,2,2,2,2,2,2,2,2,2
2,2,3,3,3,3,3,3,3,3,3,3,3,2,2
2,2,3,3,3,3,3,3,3,3,3,3,3,2,2
2,2,3,3,3,3,3,3,3,3,3,3,3,2,2
2,2,3,3,3,3,3,3,3,3,3,3,3,2,2
2,2,3,3,3,3,3,3,3,3,3,3,3,2,2
2,2,3,3,3,3,3,3,3,3,3,3,3,2,2
2,2,2,3,2,3,2,2,2,2,2,2,2,2,2
4,4,4,4,4,4,4,4,4,4,4,4,4,4,4
4,4,4,4,4,4,4,4,4,4,4,4,4,4,4
:endlayer
layer: 3
0,0,0,0,0,0,0,0,0,0,0,0,0,0,0
0,0,0,0,0,0,0,0,0,0,0,0,0,0,0
0,0,5,5,5,5,5,5,5,5,5,5,5,0,0
0,0,5,6,6,6,6,6,6,6,6,6,5,0,0
0,0,5,6,6,6,6,6,6,6,6,6,5,0,0
0,0,5,6,6,6,6,6,6,6,6,6,5,0,0
0,0,5,6,6,6,6,6,6,6,6,6,5,0,0
0,0,5,5,6,5,5,5,5,5,5,5,5,0,0
0,0,0,5,7,5,0,0,0,0,0,0,0,0,0
0,0,0,0,0,0,0,0,0,0,0,0,0,0,0
0,0,0,0,0,0,0,0,0,0,0,0,0,0,0
:endlayer
layer: 4
0,0,0,0,0,0,0,0,0,0,0,0,0,0,0
0,0,0,0,0,0,0,0,0,0,0,0,0,0,0
0,0,5,8,8,8,8,5,8,8,8,8,5,0,0
0,0,8,6,9,0,0,8,0,0,0,0,8,0,0
0,0,8,10,0,0,0,8,0,0,0,0,8,0,0
0,0,8,10,0,0,0,8,0,0,0,0,8,0,0
0,0,8,10,0,0,0,0,0,0,0,0,8,0,0
0,0,5,8,11,8,8,5,8,8,8,8,5,0,0
0,0,0,12,0,12,0,0,0,0,0,0,0,0,0
0,0,0,0,0,0,0,0,0,0,0,0,0,0,0
0,0,0,0,0,0,0,0,0,0,0,0,0,0,0
:endlayer
layer: 5
0,0,0,0,0,0,0,0,0,0,0,0,0,0,0
0,0,0,0,0,0,0,0,0,0,0,0,0,0,0
0,0,5,8,8,8,8,5,8,8,8,8,5,0,0
0,0,8,0,0,0,0,8,0,0,0,0,8,0,0
0,0,8,13,0,0,0,8,0,0,0,0,8,0,0
0,0,8,10,0,0,0,8,0,0,0,0,8,0,0
0,0,8,10,0,0,0,0,0,0,0,0,8,0,0
0,0,5,8,14,8,8,5,8,8,8,8,5,0,0
0,0,0,0,0,0,0,0,0,0,0,0,0,0,0
0,0,0,0,0,0,0,0,0,0,0,0,0,0,0
0,0,0,0,0,0,0,0,0,0,0,0,0,0,0
:endlayer
layer: 6
0,0,0,0,0,0,0,0,0,0,0,0,0,0,0
0,0,15,0,0,0,0,0,0,0,0,0,15,0,0
0,16,5,8,8,8,8,5,8,8,8,8,5,17,0
0,0,8,0,0,0,0,8,0,0,0,0,8,0,0
0,0,8,0,0,0,0,8,0,0,0,0,8,0,0
0,0,8,13,0,0,0,8,0,0,0,0,8,0,0
0,0,8,10,0,0,0,8,0,0,0,0,8,0,0
0,16,5,8,8,8,8,5,8,8,8,8,5,17,0
0,0,18,0,18,0,0,0,0,0,0,0,18,0,0
0,0,0,0,0,0,0,0,0,0,0,0,0,0,0
0,0,0,0,0,0,0,0,0,0,0,0,0,0,0
:endlayer
layer: 7
0,0,0,0,0,0,0,0,0,0,0,0,0,0,0
0,12,5,12,12,12,12,5,12,12,12,12,5,12,0
0,5,5,5,5,5,5,5,5,5,5,5,5,5,0
0,12,5,17,0,0,16,5,17,0,0,16,5,12,0
0,12,5,0,0,0,0,5,0,0,0,0,5,12,0
0,12,5,0,0,0,0,5,0,0,0,0,5,12,0
0,12,5,13,0,0,16,5,17,0,0,16,5,12,0
0,5,5,5,5,5,5,5,5,5,5,5,5,5,0
0,12,5,12,12,12,12,5,12,12,12,12,5,12,0
0,0,0,0,0,0,0,0,0,0,0,0,0,0,0
0,0,0,0,0,0,0,0,0,0,0,0,0,0,0
:endlayer
layer: 8
0,0,0,0,0,0,0,0,0,0,0,0,0,0,0
0,12,5,5,5,5,5,5,5,5,5,5,5,12,0
0,5,6,6,6,6,6,6,6,6,6,6,6,5,0
0,5,6,6,6,6,6,6,6,6,6,6,6,5,0
0,5,6,0,6,6,6,6,6,6,6,6,6,5,0
0,5,6,0,6,6,6,6,6,6,6,6,6,5,0
0,5,19,0,6,6,6,6,6,6,6,6,6,5,0
0,5,19,20,21,6,6,6,6,6,6,6,6,5,0
0,12,5,5,5,5,5,5,5,5,5,5,5,12,0
0,0,0,0,0,0,0,0,0,0,0,0,0,0,0
0,0,0,0,0,0,0,0,0,0,0,0,0,0,0
:endlayer
layer: 9
0,0,0,0,0,0,0,0,0,0,0,0,0,0,0
0,12,5,6,22,22,6,5,6,22,22,6,5,12,0
0,5,0,0,0,0,0,6,0,0,0,23,23,5,0
0,6,12,12,12,0,0,6,0,0,0,24,24,6,0
0,22,12,0,12,0,0,6,0,0,0,0,0,22,0
0,22,12,0,12,0,0,6,0,0,0,0,0,22,0
0,6,7,0,12,0,0,5,0,0,0,0,0,6,0
0,5,0,0,0,0,0,25,0,0,0,0,0,5,0
0,12,5,6,22,22,6,5,6,22,22,6,5,12,0
0,0,0,0,0,0,0,0,0,0,0,0,0,0,0
0,0,0,0,0,0,0,0,0,0,0,0,0,0,0
:endlayer
layer: 10
0,0,0,0,0,0,0,0,0,0,0,0,0,0,0
0,12,5,6,22,22,6,5,6,22,22,6,5,12,0
0,5,0,0,0,0,0,6,0,0,0,0,0,5,0
0,6,0,0,0,0,0,6,0,0,0,0,0,6,0
0,22,0,0,0,0,0,6,0,0,0,0,0,22,0
0,22,7,0,0,0,0,6,0,0,0,0,0,22,0
0,6,0,0,0,0,0,5,0,0,0,0,0,6,0
0,5,0,0,0,0,0,26,0,0,0,0,0,5,0
0,12,5,6,22,22,6,5,6,22,22,6,5,12,0
0,0,0,0,0,0,0,0,0,0,0,0,0,0,0
0,0,0,0,0,0,0,0,0,0,0,0,0,0,0
:endlayer
layer: 11
0,0,0,0,0,0,0,0,0,0,0,0,0,0,0
0,12,5,6,22,22,6,5,6,22,22,6,5,12,0
0,5,18,0,0,0,0,6,0,0,0,0,18,5,0
0,6,0,0,0,0,0,6,0,0,0,0,0,6,0
0,22,7,0,0,0,0,6,0,0,0,0,0,22,0
0,22,0,0,0,0,0,6,0,0,0,0,0,22,0
0,6,0,0,0,0,16,5,17,0,0,0,0,6,0
0,5,15,0,0,0,0,5,0,0,0,0,15,5,0
0,12,5,6,22,22,6,5,6,22,22,6,5,12,0
0,0,0,0,0,0,0,0,0,0,0,0,0,0,0
0,0,0,0,0,0,0,0,0,0,0,0,0,0,0
:endlayer
layer: 12
13,13,13,13,13,13,13,13,13,13,13,13,13,13,13
27,5,5,5,5,5,5,5,5,5,5,5,5,5,27
27,5,6,6,6,6,6,6,6,6,6,6,6,5,27
28,5,20,6,6,6,6,6,6,6,6,6,6,5,28
21,5,0,6,6,6,6,6,6,6,6,6,6,5,9
21,5,0,6,6,6,6,6,6,6,6,6,6,5,9
28,5,0,6,6,6,6,6,6,6,6,6,6,5,28
27,5,6,6,6,6,6,6,6,6,6,6,6,5,27
27,5,5,5,5,5,5,5,5,5,5,5,5,5,27
7,7,7,7,7,7,7,7,7,7,7,7,7,7,7
0,0,0,0,0,0,0,0,0,0,0,0,0,0,0
:endlayer
layer: 13
0,0,0,0,0,0,0,0,0,0,0,0,0,0,0
13,13,13,13,13,13,13,13,13,13,13,13,13,13,13
0,5,12,12,12,12,12,5,12,12,12,12,12,5,0
12,6,0,0,0,0,0,12,0,0,0,0,0,6,12
0,22,0,12,0,0,0,0,0,0,0,0,0,22,0
0,22,0,12,0,0,0,0,0,0,0,0,0,22,0
12,6,0,12,0,0,0,12,0,0,0,0,0,6,12
0,5,12,12,12,12,12,5,12,12,12,12,12,5,0
7,7,7,7,7,7,7,7,7,7,7,7,7,7,7
0,0,0,0,0,0,0,0,0,0,0,0,0,0,0
0,0,0,0,0,0,0,0,0,0,0,0,0,0,0
:endlayer
layer: 14
0,0,0,0,0,0,0,0,0,0,0,0,0,0,0
0,0,0,0,0,0,0,0,0,0,0,0,0,0,0
13,13,13,13,13,13,13,13,13,13,13,13,13,13,13
12,5,17,0,0,0,16,5,17,0,0,0,16,5,12
0,22,0,0,0,0,0,0,0,0,0,0,0,22,0
0,22,0,0,0,0,0,0,0,0,0,0,0,22,0
12,5,17,0,0,0,16,5,17,0,0,0,16,5,12
7,7,7,7,7,7,7,7,7,7,7,7,7,7,7
0,0,0,0,0,0,0,0,0,0,0,0,0,0,0
0,0,0,0,0,0,0,0,0,0,0,0,0,0,0
0,0,0,0,0,0,0,0,0,0,0,0,0,0,0
:endlayer
layer: 15
0,0,0,0,0,0,0,0,0,0,0,0,0,0,0
0,0,0,0,0,0,0,0,0,0,0,0,0,0,0
0,0,0,0,0,0,0,0,0,0,0,0,0,0,0
13,13,13,13,13,13,13,13,13,13,13,13,13,13,13
0,5,0,0,0,0,0,5,0,0,0,0,0,5,0
0,5,0,0,0,0,0,5,0,0,0,0,0,5,0
7,7,7,7,7,7,7,7,7,7,7,7,7,7,7
0,0,0,0,0,0,0,0,0,0,0,0,0,0,0
0,0,0,0,0,0,0,0,0,0,0,0,0,0,0
0,0,0,0,0,0,0,0,0,0,0,0,0,0,0
0,0,0,0,0,0,0,0,0,0,0,0,0,0,0
:endlayer
layer: 16
0,0,0,0,0,0,0,0,0,0,0,0,0,0,0
0,0,0,0,0,0,0,0,0,0,0,0,0,0,0
0,0,0,0,0,0,0,0,0,0,0,0,0,0,0
0,0,0,0,0,0,0,0,0,0,0,0,0,0,0
27,13,13,13,13,13,13,13,13,13,13,13,13,13,27
27,7,7,7,7,7,7,7,7,7,7,7,7,7,27
0,0,0,0,0,0,0,0,0,0,0,0,0,0,0
0,0,0,0,0,0,0,0,0,0,0,0,0,0,0
0,0,0,0,0,0,0,0,0,0,0,0,0,0,0
0,0,0,0,0,0,0,0,0,0,0,0,0,0,0
0,0,0,0,0,0,0,0,0,0,0,0,0,0,0
:endlayer
layer: 17
0,0,0,0,0,0,0,0,0,0,0,0,0,0,0
0,0,0,0,0,0,0,0,0,0,0,0,0,0,0
0,0,0,0,0,0,0,0,0,0,0,0,0,0,0
0,0,0,0,0,0,0,0,0,0,0,0,0,0,0
0,0,0,0,0,0,0,0,0,0,0,0,0,0,0
0,0,0,0,0,0,0,0,0,0,0,0,0,0,0
0,0,0,0,0,0,0,0,0,0,0,0,0,0,0
0,0,0,0,0,0,0,0,0,0,0,0,0,0,0
0,0,0,0,0,0,0,0,0,0,0,0,0,0,0
0,0,0,0,0,0,0,0,0,0,0,0,0,0,0
0,0,0,0,0,0,0,0,0,0,0,0,0,0,0
:endlayer
layer: 18
0,0,0,0,0,0,0,0,0,0,0,0,0,0,0
0,0,0,0,0,0,0,0,0,0,0,0,0,0,0
0,0,0,0,0,0,0,0,0,0,0,0,0,0,0
0,0,0,0,0,0,0,0,0,0,0,0,0,0,0
0,0,0,0,0,0,0,0,0,0,0,0,0,0,0
0,0,0,0,0,0,0,0,0,0,0,0,0,0,0
0,0,0,0,0,0,0,0,0,0,0,0,0,0,0
0,0,0,0,0,0,0,0,0,0,0,0,0,0,0
0,0,0,0,0,0,0,0,0,0,0,0,0,0,0
0,0,0,0,0,0,0,0,0,0,0,0,0,0,0
0,0,0,0,0,0,0,0,0,0,0,0,0,0,0
:endlayer
layer: 19
0,0,0,0,0,0,0,0,0,0,0,0,0,0,0
0,0,0,0,0,0,0,0,0,0,0,0,0,0,0
0,0,0,0,0,0,0,0,0,0,0,0,0,0,0
0,0,0,0,0,0,0,0,0,0,0,0,0,0,0
0,0,0,0,0,0,0,0,0,0,0,0,0,0,0
0,0,0,0,0,0,0,0,0,0,0,0,0,0,0
0,0,0,0,0,0,0,0,0,0,0,0,0,0,0
0,0,0,0,0,0,0,0,0,0,0,0,0,0,0
0,0,0,0,0,0,0,0,0,0,0,0,0,0,0
0,0,0,0,0,0,0,0,0,0,0,0,0,0,0
0,0,0,0,0,0,0,0,0,0,0,0,0,0,0
:endlayer
layer: 20
0,0,0,0,0,0,0,0,0,0,0,0,0,0,0
0,0,0,0,0,0,0,0,0,0,0,0,0,0,0
0,0,0,0,0,0,0,0,0,0,0,0,0,0,0
0,0,0,0,0,0,0,0,0,0,0,0,0,0,0
0,0,0,0,0,0,0,0,0,0,0,0,0,0,0
0,0,0,0,0,0,0,0,0,0,0,0,0,0,0
0,0,0,0,0,0,0,0,0,0,0,0,0,0,0
0,0,0,0,0,0,0,0,0,0,0,0,0,0,0
0,0,0,0,0,0,0,0,0,0,0,0,0,0,0
0,0,0,0,0,0,0,0,0,0,0,0,0,0,0
0,0,0,0,0,0,0,0,0,0,0,0,0,0,0
:endlayer
layer: 21
0,0,0,0,0,0,0,0,0,0,0,0,0,0,0
0,0,0,0,0,0,0,0,0,0,0,0,0,0,0
0,0,0,0,0,0,0,0,0,0,0,0,0,0,0
0,0,0,0,0,0,0,0,0,0,0,0,0,0,0
0,0,0,0,0,0,0,0,0,0,0,0,0,0,0
0,0,0,0,0,0,0,0,0,0,0,0,0,0,0
0,0,0,0,0,0,0,0,0,0,0,0,0,0,0
0,0,0,0,0,0,0,0,0,0,0,0,0,0,0
0,0,0,0,0,0,0,0,0,0,0,0,0,0,0
0,0,0,0,0,0,0,0,0,0,0,0,0,0,0
0,0,0,0,0,0,0,0,0,0,0,0,0,0,0
:endlayer

#### RULES ####
rule:
plugin=vanillaBlocks
number=1
data:
JSON:{{"val":{"blockName":{"val":"minecraft:cobblestone","id":"ss"},"meta":{"val":"0","id":"pi"},"buildPass":{"val":"0","id":"pi"}},"id":"ct"}}
:enddata
:endrule

rule:
plugin=vanillaBlocks
number=2
data:
JSON:{{"val":{"blockName":{"val":"minecraft:grass","id":"ss"},"meta":{"val":"0","id":"pi"},"buildPass":{"val":"0","id":"pi"}},"id":"ct"}}
:enddata
:endrule

rule:
plugin=vanillaBlocks
number=3
data:
JSON:{{"val":{"blockName":{"val":"minecraft:dirt","id":"ss"},"meta":{"val":"0","id":"pi"},"buildPass":{"val":"0","id":"pi"}},"id":"ct"}}
:enddata
:endrule

rule:
plugin=vanillaBlocks
number=4
data:
JSON:{{"val":{"blockName":{"val":"minecraft:gravel","id":"ss"},"meta":{"val":"0","id":"pi"},"buildPass":{"val":"0","id":"pi"}},"id":"ct"}}
:enddata
:endrule

rule:
plugin=vanillaBlocks
number=5
data:
JSON:{{"val":{"blockName":{"val":"minecraft:log","id":"ss"},"meta":{"val":"0","id":"pi"},"buildPass":{"val":"0","id":"pi"}},"id":"ct"}}
:enddata
:endrule

rule:
plugin=vanillaBlocks
number=6
data:
JSON:{{"val":{"blockName":{"val":"minecraft:planks","id":"ss"},"meta":{"val":"0","id":"pi"},"buildPass":{"val":"0","id":"pi"}},"id":"ct"}}
:enddata
:endrule

rule:
plugin=vanillaBlocks
number=7
data:
JSON:{{"val":{"blockName":{"val":"minecraft:oak_stairs","id":"ss"},"meta":{"val":"3","id":"pi"},"buildPass":{"val":"0","id":"pi"}},"id":"ct"}}
:enddata
:endrule

rule:
plugin=vanillaBlocks
number=8
data:
JSON:{{"val":{"blockName":{"val":"minecraft:stonebrick","id":"ss"},"meta":{"val":"0","id":"pi"},"buildPass":{"val":"0","id":"pi"}},"id":"ct"}}
:enddata
:endrule

rule:
plugin=vanillaBlocks
number=9
data:
JSON:{{"val":{"blockName":{"val":"minecraft:oak_stairs","id":"ss"},"meta":{"val":"1","id":"pi"},"buildPass":{"val":"0","id":"pi"}},"id":"ct"}}
:enddata
:endrule

rule:
plugin=vanillaBlocks
number=10
data:
JSON:{{"val":{"blockName":{"val":"minecraft:bookshelf","id":"ss"},"meta":{"val":"0","id":"pi"},"buildPass":{"val":"0","id":"pi"}},"id":"ct"}}
:enddata
:endrule

rule:
plugin=vanillaDoors
number=11
data:
JSON:{{"val":{"sideFlag":{"val":"8","id":"pb"},"blockName":{"val":"minecraft:wooden_door","id":"ss"},"meta":{"val":"3","id":"pi"},"buildPass":{"val":"2","id":"pi"}},"id":"ct"}}
:enddata
:endrule

rule:
plugin=vanillaBlocks
number=12
data:
JSON:{{"val":{"blockName":{"val":"minecraft:fence","id":"ss"},"meta":{"val":"0","id":"pi"},"buildPass":{"val":"0","id":"pi"}},"id":"ct"}}
:enddata
:endrule

rule:
plugin=vanillaBlocks
number=13
data:
JSON:{{"val":{"blockName":{"val":"minecraft:oak_stairs","id":"ss"},"meta":{"val":"2","id":"pi"},"buildPass":{"val":"0","id":"pi"}},"id":"ct"}}
:enddata
:endrule

rule:
plugin=vanillaDoors
number=14
data:
JSON:{{"val":{"sideFlag":{"val":"0","id":"pb"},"blockName":{"val":"minecraft:wooden_door","id":"ss"},"meta":{"val":"8","id":"pi"},"buildPass":{"val":"2","id":"pi"}},"id":"ct"}}
:enddata
:endrule

rule:
plugin=vanillaBlocks
number=15
data:
JSON:{{"val":{"blockName":{"val":"minecraft:torch","id":"ss"},"meta":{"val":"4","id":"pi"},"buildPass":{"val":"2","id":"pi"}},"id":"ct"}}
:enddata
:endrule

rule:
plugin=vanillaBlocks
number=16
data:
JSON:{{"val":{"blockName":{"val":"minecraft:torch","id":"ss"},"meta":{"val":"2","id":"pi"},"buildPass":{"val":"2","id":"pi"}},"id":"ct"}}
:enddata
:endrule

rule:
plugin=vanillaBlocks
number=17
data:
JSON:{{"val":{"blockName":{"val":"minecraft:torch","id":"ss"},"meta":{"val":"1","id":"pi"},"buildPass":{"val":"2","id":"pi"}},"id":"ct"}}
:enddata
:endrule

rule:
plugin=vanillaBlocks
number=18
data:
JSON:{{"val":{"blockName":{"val":"minecraft:torch","id":"ss"},"meta":{"val":"3","id":"pi"},"buildPass":{"val":"2","id":"pi"}},"id":"ct"}}
:enddata
:endrule

rule:
plugin=vanillaBlocks
number=19
data:
JSON:{{"val":{"blockName":{"val":"minecraft:double_stone_slab","id":"ss"},"meta":{"val":"2","id":"pi"},"buildPass":{"val":"0","id":"pi"}},"id":"ct"}}
:enddata
:endrule

rule:
plugin=vanillaBlocks
number=20
data:
JSON:{{"val":{"blockName":{"val":"minecraft:stone_slab","id":"ss"},"meta":{"val":"2","id":"pi"},"buildPass":{"val":"0","id":"pi"}},"id":"ct"}}
:enddata
:endrule

rule:
plugin=vanillaBlocks
number=21
data:
JSON:{{"val":{"blockName":{"val":"minecraft:oak_stairs","id":"ss"},"meta":{"val":"0","id":"pi"},"buildPass":{"val":"0","id":"pi"}},"id":"ct"}}
:enddata
:endrule

rule:
plugin=vanillaBlocks
number=22
data:
JSON:{{"val":{"blockName":{"val":"minecraft:glass_pane","id":"ss"},"meta":{"val":"0","id":"pi"},"buildPass":{"val":"0","id":"pi"}},"id":"ct"}}
:enddata
:endrule

rule:
plugin=vanillaBlocks
number=23
data:
JSON:{{"val":{"blockName":{"val":"minecraft:bed","id":"ss"},"meta":{"val":"10","id":"pi"},"buildPass":{"val":"2","id":"pi"}},"id":"ct"}}
:enddata
:endrule

rule:
plugin=vanillaBlocks
number=24
data:
JSON:{{"val":{"blockName":{"val":"minecraft:bed","id":"ss"},"meta":{"val":"2","id":"pi"},"buildPass":{"val":"2","id":"pi"}},"id":"ct"}}
:enddata
:endrule

rule:
plugin=vanillaDoors
number=25
data:
JSON:{{"val":{"sideFlag":{"val":"8","id":"pb"},"blockName":{"val":"minecraft:wooden_door","id":"ss"},"meta":{"val":"4","id":"pi"},"buildPass":{"val":"2","id":"pi"}},"id":"ct"}}
:enddata
:endrule

rule:
plugin=vanillaDoors
number=26
data:
JSON:{{"val":{"sideFlag":{"val":"0","id":"pb"},"blockName":{"val":"minecraft:wooden_door","id":"ss"},"meta":{"val":"8","id":"pi"},"buildPass":{"val":"2","id":"pi"}},"id":"ct"}}
:enddata
:endrule

rule:
plugin=vanillaBlocks
number=27
data:
JSON:{{"val":{"blockName":{"val":"minecraft:wooden_slab","id":"ss"},"meta":{"val":"0","id":"pi"},"buildPass":{"val":"0","id":"pi"}},"id":"ct"}}
:enddata
:endrule

rule:
plugin=vanillaBlocks
number=28
data:
JSON:{{"val":{"blockName":{"val":"minecraft:double_wooden_slab","id":"ss"},"meta":{"val":"0","id":"pi"},"buildPass":{"val":"0","id":"pi"}},"id":"ct"}}
:enddata
:endrule

#### ENTITIES ####
