# Ancient Warfare Structure Template File
# Auto-generated structure template file. created on: 11/24/2014 at: 21:37:33
# Lines beginning with # denote comments

header:
version=2.1
name=TownBlocks2Houses
size=25,22,16
offset=13,1,15
:endheader

#### VALIDATION ####
validation:
type=ground
survival=false
worldGenEnabled=false
unique=false
preserveBlocks=false
selectionWeight=0
clusterValue=0
minDuplicateDistance=0
dimensionWhiteList=false
dimensionList=
biomeWhiteList=false
biomeList=
leveling=0
fill=0
border=0
validTargetBlocks=
blockSwap=false
data:
:enddata
:endvalidation

#### LAYERS ####
layer: 0
1,1,1,1,1,1,1,1,1,1,1,1,1,1,1,1,1,1,1,1,1,1,1,1,1
1,1,1,1,1,1,1,1,1,1,1,1,1,1,1,1,1,1,1,1,1,1,1,1,1
1,1,1,1,1,1,1,1,1,1,1,1,1,1,1,1,1,1,1,1,1,1,1,1,1
1,1,1,1,1,1,1,1,3,3,3,3,3,3,2,2,2,2,2,2,2,1,1,1,1
1,1,1,1,1,1,1,1,3,3,3,3,3,3,3,2,2,2,2,2,2,1,1,1,1
1,1,1,1,1,1,1,1,3,2,3,1,1,3,3,3,3,2,2,2,2,1,1,1,1
1,1,1,1,1,3,3,3,2,2,2,1,1,3,3,3,3,3,3,2,2,1,1,1,1
1,1,1,1,1,3,1,1,1,2,2,1,1,3,3,3,3,3,2,2,2,1,1,1,1
1,1,1,1,1,2,1,1,1,2,2,1,1,3,3,3,3,3,2,1,1,2,1,1,1
1,1,1,1,1,2,1,1,1,1,1,1,1,3,3,3,2,2,2,2,2,2,1,1,1
1,1,1,1,1,2,1,1,1,1,1,1,1,3,3,2,2,2,2,2,3,2,1,1,1
1,1,1,1,1,1,1,1,1,1,1,1,1,2,2,2,2,2,2,2,2,2,1,1,1
1,1,1,1,1,1,1,1,1,1,1,1,1,1,1,1,1,2,2,2,2,2,1,1,1
1,1,1,1,1,1,1,1,2,2,2,2,1,1,1,1,1,2,2,2,2,2,1,1,1
1,1,1,1,1,1,1,1,2,2,2,2,1,1,1,1,1,2,1,1,1,1,1,1,1
1,1,1,1,1,1,1,1,2,2,2,2,1,1,1,1,1,2,1,1,1,1,1,1,1
:endlayer
layer: 1
4,4,4,4,4,4,4,4,4,4,4,4,4,4,4,4,4,4,4,4,4,4,4,4,4
4,4,4,4,4,4,4,4,4,4,4,4,4,4,4,4,4,4,4,4,4,4,4,4,4
4,4,5,5,5,5,5,5,5,1,1,1,1,1,1,1,1,1,1,1,1,1,1,4,4
4,4,5,0,0,0,0,0,5,3,3,3,3,3,2,2,2,1,1,1,1,1,1,4,4
4,4,5,0,0,0,0,0,5,2,5,5,5,3,1,1,1,1,1,1,1,1,1,4,4
4,4,5,6,0,0,0,0,5,2,5,0,0,5,1,1,1,1,1,1,1,8,8,4,4
4,4,5,0,0,5,5,5,5,2,5,0,0,5,1,1,1,1,1,1,1,8,8,4,4
4,4,5,0,0,5,0,0,0,5,5,0,0,5,1,1,1,1,1,1,1,8,8,4,4
4,4,5,0,0,5,0,0,0,5,5,0,0,5,1,1,1,2,1,1,1,8,8,4,4
4,4,5,0,0,5,0,0,0,0,0,0,0,5,1,1,2,2,8,8,8,8,8,4,4
4,4,5,0,0,5,0,0,0,0,0,0,0,5,2,2,2,1,8,8,8,8,8,4,4
4,4,5,0,0,0,0,0,0,0,0,0,0,5,1,1,1,1,8,8,8,8,8,4,4
4,4,5,0,0,0,7,0,0,0,0,0,0,5,1,1,1,1,8,8,8,2,8,4,4
4,4,5,5,5,5,5,5,5,5,5,5,5,5,4,4,4,4,8,8,8,8,8,4,4
4,4,4,4,4,4,4,4,4,4,4,4,4,4,4,4,4,4,4,4,4,4,4,4,4
4,4,4,4,4,4,4,4,4,4,4,4,4,4,4,4,4,4,4,4,4,4,4,4,4
:endlayer
layer: 2
0,0,0,0,0,0,0,0,0,0,0,0,0,0,0,0,0,0,0,0,0,0,0,0,0
0,0,0,0,0,0,0,0,0,0,0,0,0,0,0,0,0,0,0,0,0,0,0,0,0
0,0,5,5,5,5,5,5,5,5,5,5,5,5,5,5,5,5,5,5,5,5,15,0,0
0,0,5,0,0,0,0,0,5,2,2,2,2,2,5,5,5,5,5,5,5,5,15,0,0
0,0,5,0,0,0,0,0,5,2,5,5,5,5,0,0,0,0,0,5,5,5,15,0,0
0,0,9,0,0,0,0,0,5,2,5,0,0,5,0,0,0,0,0,5,5,0,0,0,0
0,0,5,0,0,5,5,5,5,5,5,0,0,5,0,0,0,0,0,5,5,13,0,0,0
0,0,5,0,0,5,0,0,0,5,5,0,0,5,0,0,0,0,0,5,5,0,0,0,0
0,0,5,0,0,5,0,0,0,5,5,0,0,5,0,0,0,5,5,5,5,0,0,0,0
0,0,5,0,0,5,0,0,0,0,0,0,0,5,12,5,5,5,13,0,0,0,0,0,0
0,0,5,0,0,5,0,0,0,0,0,0,0,5,5,5,5,5,0,0,0,0,0,0,0
0,0,5,0,0,0,0,0,0,0,0,0,0,5,5,5,5,5,0,0,0,0,0,0,0
0,0,5,0,0,0,0,0,0,0,0,0,0,5,11,11,11,5,0,0,0,14,0,0,0
0,0,5,5,5,5,10,5,5,5,5,5,5,5,0,0,0,0,0,0,0,0,0,0,0
0,0,0,0,0,0,0,0,0,0,0,0,0,0,0,0,0,0,0,0,0,0,0,0,0
0,0,0,0,0,0,0,0,0,0,0,0,0,0,0,0,0,0,0,0,0,0,0,0,0
:endlayer
layer: 3
0,0,0,0,0,0,0,0,0,0,0,0,0,0,0,0,0,0,0,0,0,0,0,0,0
0,0,0,0,0,0,0,0,0,0,0,0,0,0,0,0,0,0,0,0,0,0,0,0,0
0,0,5,5,16,5,16,5,5,5,5,5,5,5,5,5,5,5,5,5,5,15,0,0,0
0,0,5,0,0,0,0,0,5,5,2,2,2,5,5,5,5,5,5,5,5,15,0,0,0
0,0,5,0,0,0,0,0,5,5,5,5,5,5,0,0,0,0,0,5,5,0,0,0,0
0,0,17,0,0,0,0,0,5,5,5,0,0,5,0,0,0,0,0,5,5,0,0,0,0
0,0,5,0,0,5,5,5,5,5,5,0,0,5,0,0,0,0,0,5,5,0,0,0,0
0,0,5,0,0,5,0,0,0,5,5,0,0,5,0,0,0,0,0,5,5,0,0,0,0
0,0,5,0,0,5,0,0,0,5,5,0,0,5,0,0,0,5,5,5,5,0,0,0,0
0,0,5,0,0,5,0,0,0,0,0,0,0,5,0,5,5,5,0,0,0,0,0,0,0
0,0,16,0,0,5,0,0,0,0,0,0,0,5,19,5,5,5,0,0,0,0,0,0,0
0,0,5,0,0,0,0,0,0,0,0,0,0,5,0,11,11,5,0,0,0,0,0,0,0
0,0,5,0,0,0,0,0,0,0,0,0,0,5,0,0,0,0,0,0,0,14,0,0,0
0,0,5,5,5,5,18,5,5,16,5,5,5,5,0,0,0,0,0,0,0,0,0,0,0
0,0,0,0,0,0,0,0,0,0,0,0,0,0,0,0,0,0,0,0,0,0,0,0,0
0,0,0,0,0,0,0,0,0,0,0,0,0,0,0,0,0,0,0,0,0,0,0,0,0
:endlayer
layer: 4
0,0,0,0,0,0,0,0,0,0,0,0,0,0,0,0,0,0,0,0,0,0,0,0,0
0,0,0,0,0,0,0,0,0,0,0,0,0,0,0,0,0,0,0,0,0,0,0,0,0
0,0,5,5,5,5,5,5,5,5,5,5,5,5,5,5,5,5,5,5,15,0,0,0,0
0,0,5,0,0,0,0,0,5,5,5,5,5,5,5,5,5,5,5,5,15,0,0,0,0
0,0,5,0,0,0,0,0,5,5,5,5,5,5,0,0,0,21,0,5,5,0,0,0,0
0,20,5,0,0,0,0,0,5,5,5,0,21,5,0,0,0,0,0,5,5,0,0,0,0
0,0,5,0,0,5,5,5,5,5,5,0,0,5,0,0,0,0,0,5,5,0,0,0,0
0,0,5,0,0,5,5,5,5,5,5,0,0,5,0,0,0,0,0,5,5,0,0,0,0
0,0,5,0,0,5,5,5,5,5,5,0,0,5,0,0,20,5,5,5,5,0,0,0,0
0,0,5,0,0,5,0,0,0,0,0,0,0,5,0,5,5,5,0,0,0,0,0,0,0
0,0,5,0,0,5,0,0,0,0,0,0,0,5,23,11,11,5,0,0,0,0,0,0,0
0,0,5,0,0,0,0,0,0,0,0,0,0,5,0,0,0,0,0,0,0,0,0,0,0
0,0,5,13,0,0,0,0,0,0,0,0,22,5,0,0,0,0,0,0,0,14,0,0,0
0,0,5,5,5,5,5,5,5,5,5,5,5,5,13,0,0,0,0,0,0,0,0,0,0
0,0,21,0,0,0,21,0,0,0,0,0,0,21,0,0,0,0,0,0,0,0,0,0,0
0,0,0,0,0,0,0,0,0,0,0,0,0,0,0,0,0,0,0,0,0,0,0,0,0
:endlayer
layer: 5
0,0,0,0,0,0,0,0,0,0,0,0,0,0,0,0,0,0,0,0,0,0,0,0,0
0,0,0,0,0,0,0,0,0,0,0,0,0,0,0,0,0,0,0,0,0,0,0,0,0
0,0,5,5,5,5,5,5,5,5,5,5,5,5,5,5,5,5,5,15,0,0,0,0,0
0,0,5,5,5,5,5,5,5,5,5,5,5,5,5,5,5,5,5,15,0,0,0,0,0
0,0,5,5,5,5,5,5,5,5,5,5,5,5,5,5,5,5,5,5,5,0,0,0,0
0,0,5,5,5,5,5,5,5,5,5,24,24,5,5,5,5,5,5,5,5,0,0,0,0
0,0,5,5,5,5,5,5,5,5,5,24,24,5,5,5,5,5,5,5,5,0,0,0,0
0,0,5,5,5,5,5,5,5,5,5,24,24,5,5,5,5,5,5,5,5,0,0,0,0
0,0,5,5,5,5,5,5,5,5,5,24,24,5,5,5,5,5,5,5,5,13,0,0,0
0,0,5,5,5,5,5,5,5,5,5,24,24,24,5,11,11,5,0,0,21,0,0,0,0
0,0,5,5,5,5,5,5,5,5,5,24,24,24,11,0,0,0,0,0,0,0,0,0,0
0,0,5,5,5,5,5,5,5,5,5,24,24,24,0,0,0,0,0,0,0,25,0,0,0
0,0,5,24,24,24,24,24,24,24,24,24,24,24,0,0,0,0,0,0,25,14,25,0,0
0,0,5,24,24,24,24,24,24,24,24,24,24,24,0,0,0,0,0,0,0,25,0,0,0
0,0,0,0,0,0,0,0,0,0,0,0,0,0,0,0,0,0,0,0,0,0,0,0,0
0,0,0,0,0,0,0,0,0,0,0,0,0,0,0,0,0,0,0,0,0,0,0,0,0
:endlayer
layer: 6
0,0,0,0,0,0,0,0,0,0,0,0,0,0,0,0,0,0,0,0,0,0,0,0,0
0,0,0,0,0,0,0,0,0,0,0,0,0,0,0,0,0,0,0,0,0,0,0,0,0
0,0,26,26,26,26,26,26,26,26,26,26,26,26,26,26,26,26,26,0,0,0,0,0,0
0,0,26,0,0,0,0,0,0,0,0,0,0,0,0,0,0,0,0,0,0,0,0,0,0
0,0,26,0,0,0,0,0,0,0,0,0,0,5,5,10,5,5,5,5,5,0,0,0,0
0,0,26,0,5,5,5,10,5,5,5,0,0,5,0,0,28,5,0,0,5,0,0,0,0
0,0,26,0,5,0,0,0,0,0,5,0,0,5,0,0,0,0,0,0,5,0,0,0,0
0,0,26,0,5,0,0,0,0,0,5,0,0,5,0,0,0,0,0,0,5,0,0,0,0
0,0,26,0,27,0,0,0,0,5,5,0,0,5,5,29,30,5,5,5,5,0,0,0,0
0,0,26,0,5,0,0,0,0,5,5,0,0,26,0,0,0,31,0,0,0,0,0,0,0
0,0,26,0,5,0,0,0,28,5,5,0,0,26,0,0,0,0,0,0,0,0,0,0,0
0,0,26,0,5,5,5,5,5,5,5,0,0,26,0,0,0,0,0,0,0,25,0,0,0
0,0,26,0,0,0,0,0,0,0,0,0,0,26,0,0,0,0,0,0,25,14,25,0,0
0,0,26,26,26,26,26,26,26,26,26,26,26,26,0,0,0,0,0,0,0,25,0,0,0
0,0,0,0,0,0,0,0,0,0,0,0,0,0,0,0,0,0,0,0,0,0,0,0,0
0,0,0,0,0,0,0,0,0,0,0,0,0,0,0,0,0,0,0,0,0,0,0,0,0
:endlayer
layer: 7
0,0,0,0,0,0,0,0,0,0,0,0,0,0,0,0,0,0,0,0,0,0,0,0,0
0,0,0,0,0,0,0,0,0,0,0,0,0,0,0,0,0,0,0,0,0,0,0,0,0
0,0,26,0,0,0,0,0,0,0,26,0,0,0,0,0,0,0,26,0,0,0,0,0,0
0,0,0,0,0,0,0,0,0,0,0,0,0,0,0,0,0,0,0,0,0,0,0,0,0
0,0,0,0,0,0,0,0,0,0,0,0,0,5,5,35,5,5,5,5,5,0,0,0,0
0,0,0,0,5,5,5,33,5,5,5,0,0,5,0,0,0,28,0,0,5,0,0,0,0
0,0,0,0,5,0,0,0,0,0,5,0,0,16,0,0,0,0,0,0,16,0,0,0,0
0,0,0,0,5,0,0,0,0,0,5,0,0,5,0,0,0,0,0,0,5,0,0,0,0
0,0,0,0,32,0,0,0,0,5,5,0,0,5,5,34,36,5,5,5,5,0,0,0,0
0,0,0,0,5,0,0,0,0,11,5,0,0,0,0,0,0,0,0,0,0,0,0,0,0
0,0,0,0,5,0,0,0,0,0,5,0,0,0,0,0,0,0,0,0,0,37,0,0,0
0,0,0,0,5,5,5,16,5,5,5,0,0,0,0,0,0,0,0,0,37,25,0,0,0
0,0,0,0,0,0,0,0,0,0,0,0,0,0,0,0,0,0,0,0,25,14,25,0,0
0,0,26,0,0,0,0,31,0,0,0,0,0,26,0,0,0,0,0,0,37,25,37,0,0
0,0,0,0,0,0,0,0,0,0,0,0,0,0,0,0,0,0,0,0,0,0,0,0,0
0,0,0,0,0,0,0,0,0,0,0,0,0,0,0,0,0,0,0,0,0,0,0,0,0
:endlayer
layer: 8
0,0,0,0,0,0,0,0,0,0,0,0,0,0,0,0,0,0,0,0,0,0,0,0,0
0,0,0,0,0,0,0,0,0,0,0,0,0,0,0,0,0,0,0,0,0,0,0,0,0
0,0,26,0,0,0,0,0,0,0,26,0,0,0,0,0,0,0,26,0,0,0,0,0,0
0,0,0,0,0,0,0,0,0,0,0,0,0,0,0,0,0,0,0,0,0,0,0,0,0
0,0,0,0,0,0,0,0,0,0,0,0,0,5,5,5,5,5,5,5,5,0,0,0,0
0,0,0,0,5,5,5,5,5,5,5,0,0,5,0,21,0,0,28,5,5,0,0,0,0
0,0,0,0,5,0,21,0,0,5,5,0,0,16,0,0,0,0,0,0,16,0,0,0,0
0,0,0,0,5,0,0,0,0,5,5,0,0,5,0,22,0,0,0,20,5,0,0,0,0
0,0,0,0,5,0,0,0,0,11,5,0,0,5,5,5,5,5,5,5,5,0,0,0,0
0,0,0,0,5,0,0,0,0,0,5,0,0,0,0,21,21,0,0,0,0,0,0,0,0
0,0,0,0,5,0,22,0,0,0,5,0,0,0,0,0,0,0,0,0,0,37,0,0,0
0,0,0,0,5,5,5,16,5,5,5,0,0,0,0,0,0,0,0,0,37,37,37,0,0
0,0,0,0,0,0,0,0,0,0,0,0,0,0,0,0,0,0,0,0,37,14,37,0,0
0,0,26,0,0,0,0,0,0,0,0,0,0,26,0,0,0,0,0,0,37,37,37,0,0
0,0,0,0,0,0,0,0,0,0,0,0,0,0,0,0,0,0,0,0,0,0,0,0,0
0,0,0,0,0,0,0,0,0,0,0,0,0,0,0,0,0,0,0,0,0,0,0,0,0
:endlayer
layer: 9
0,0,0,0,0,0,0,0,0,0,0,0,0,0,0,0,0,0,0,0,0,0,0,0,0
0,0,0,0,0,0,0,0,0,0,0,0,0,0,0,0,0,0,0,0,0,0,0,0,0
0,0,26,0,0,0,0,0,0,0,26,0,0,0,0,0,0,0,26,0,0,0,0,0,0
0,0,0,0,0,0,0,0,0,0,0,0,0,22,0,38,0,0,0,0,22,0,0,0,0
0,0,0,0,22,0,0,38,0,0,22,0,20,5,5,5,5,5,5,5,5,13,0,0,0
0,0,0,20,5,5,5,5,5,5,5,13,0,5,0,0,0,0,0,28,5,0,0,0,0
0,0,0,0,5,0,0,0,0,5,5,0,0,16,0,0,0,0,0,0,16,0,0,0,0
0,0,0,0,5,0,0,0,0,11,5,0,0,5,0,0,0,0,0,0,5,0,0,0,0
0,0,0,0,5,0,0,0,0,0,5,0,20,5,5,5,5,5,5,5,5,13,0,0,0
0,0,0,0,5,0,0,0,0,0,5,0,0,21,0,0,0,0,0,0,21,0,0,0,0
0,0,0,0,5,0,0,0,0,0,5,0,0,0,0,0,0,0,0,0,0,37,0,0,0
0,0,0,20,5,5,5,16,5,5,5,13,0,0,0,0,0,0,0,0,37,37,37,0,0
0,0,0,0,21,0,0,0,0,0,21,0,0,0,0,0,0,0,0,37,37,14,37,37,0
0,0,26,0,0,0,0,0,0,0,0,0,0,26,0,0,0,0,0,0,37,37,37,0,0
0,0,0,0,0,0,0,0,0,0,0,0,0,0,0,0,0,0,0,0,0,37,0,0,0
0,0,0,0,0,0,0,0,0,0,0,0,0,0,0,0,0,0,0,0,0,0,0,0,0
:endlayer
layer: 10
0,0,0,0,0,0,0,0,0,0,0,0,0,0,0,0,0,0,0,0,0,0,0,0,0
0,0,0,0,0,0,0,0,0,0,0,0,0,0,0,0,0,0,0,0,0,0,0,0,0
0,0,39,39,39,39,39,39,39,39,24,24,24,24,24,24,24,24,24,24,24,24,24,0,0
0,0,24,24,24,24,24,24,24,24,24,24,24,24,24,24,24,24,24,24,24,24,24,0,0
0,0,24,24,24,24,24,24,24,24,24,24,24,5,5,5,5,5,5,5,5,24,24,0,0
0,0,24,24,5,5,5,5,5,5,5,24,24,5,5,5,5,0,0,0,5,24,24,0,0
0,0,24,24,5,5,5,5,5,11,5,24,24,5,5,5,5,5,5,12,5,24,24,0,0
0,0,24,24,5,5,5,5,5,0,5,24,24,5,5,5,5,5,5,5,5,24,24,0,0
0,0,24,24,5,5,5,5,5,0,5,24,24,5,5,5,5,5,5,5,5,24,24,0,0
0,0,24,24,5,5,5,5,5,0,5,24,24,24,24,24,24,24,24,24,24,24,24,0,0
0,0,24,24,5,5,5,5,5,5,5,24,24,24,24,24,24,24,24,24,24,24,24,0,0
0,0,24,24,5,5,5,5,5,5,5,24,24,40,0,0,0,0,0,0,37,37,37,37,0
0,0,24,24,24,24,24,24,24,24,24,24,24,40,0,0,0,0,0,37,37,14,37,37,0
0,0,24,24,24,24,24,24,24,24,24,24,24,40,0,0,0,0,0,0,37,37,37,0,0
0,0,0,0,0,0,0,0,0,0,0,0,0,0,0,0,0,0,0,0,0,37,37,0,0
0,0,0,0,0,0,0,0,0,0,0,0,0,0,0,0,0,0,0,0,0,0,0,0,0
:endlayer
layer: 11
0,0,0,0,0,0,0,0,0,0,0,0,0,0,0,0,0,0,0,0,0,0,0,0,0
0,0,0,0,0,0,0,0,0,0,0,0,0,0,0,0,0,0,0,0,0,0,0,0,0
0,0,0,0,0,0,0,0,0,0,26,26,26,26,26,26,26,26,26,26,26,26,26,0,0
0,0,26,26,26,26,26,26,26,26,26,0,0,0,0,0,0,0,0,0,0,0,26,0,0
0,0,26,0,0,0,0,0,0,0,0,0,0,5,5,5,5,5,5,5,5,0,26,0,0
0,0,26,0,5,5,5,5,5,5,5,0,0,5,0,0,0,0,0,0,5,0,26,0,0
0,0,26,0,5,0,0,0,0,0,5,0,0,27,0,0,0,0,0,0,5,0,26,0,0
0,0,26,0,5,0,0,0,0,0,5,0,0,5,0,0,0,0,0,0,5,0,26,0,0
0,0,26,0,27,0,0,0,0,0,5,0,0,5,5,5,5,5,5,5,5,0,26,0,0
0,0,26,0,5,0,0,0,0,0,5,0,0,0,0,0,0,0,0,0,0,0,26,0,0
0,0,26,0,5,0,0,0,0,0,5,0,26,26,26,26,26,26,26,26,26,26,26,0,0
0,0,26,0,5,5,5,5,5,5,5,0,26,0,0,0,0,0,0,0,37,37,37,0,0
0,0,26,0,0,0,0,0,0,0,0,0,26,0,0,0,0,0,0,37,37,14,37,37,0
0,0,26,26,26,26,26,26,26,26,26,26,26,0,0,0,0,0,0,0,37,37,37,37,0
0,0,0,0,0,0,0,0,0,0,0,0,0,0,0,0,0,0,0,0,0,41,0,0,0
0,0,0,0,0,0,0,0,0,0,0,0,0,0,0,0,0,0,0,0,0,0,0,0,0
:endlayer
layer: 12
0,0,0,0,0,0,0,0,0,0,0,0,0,0,0,0,0,0,0,0,0,0,0,0,0
0,0,0,0,0,0,0,0,0,0,0,0,0,0,0,0,0,0,0,0,0,0,0,0,0
0,0,0,0,0,0,0,0,0,0,31,0,0,0,0,0,0,0,0,0,0,0,31,0,0
0,0,31,0,0,0,0,0,0,0,0,0,0,0,0,0,0,0,0,0,0,0,0,0,0
0,0,0,0,0,0,0,0,0,0,0,0,0,5,5,5,16,5,5,5,5,0,0,0,0
0,0,0,0,5,5,5,16,5,5,5,0,0,5,0,0,0,0,0,0,5,0,0,0,0
0,0,26,0,5,0,0,0,0,0,5,0,0,43,0,0,0,0,0,0,16,0,31,0,0
0,0,0,0,5,0,0,0,0,0,5,0,0,5,0,0,0,0,0,0,5,0,0,0,0
0,0,0,0,42,0,0,0,0,0,16,0,0,5,5,5,16,5,5,5,5,0,0,0,0
0,0,0,0,5,0,0,0,0,0,5,0,0,0,0,0,0,0,0,0,0,0,0,0,0
0,0,26,0,5,0,0,0,0,0,5,0,31,0,0,0,0,31,0,0,0,0,31,0,0
0,0,0,0,5,5,5,16,5,5,5,0,0,0,0,0,0,0,0,0,0,37,37,0,0
0,0,0,0,0,0,0,0,0,0,0,0,0,0,0,0,0,0,0,37,37,14,37,37,0
0,0,31,0,0,0,0,0,0,0,0,0,31,0,0,0,0,0,0,0,37,37,37,0,0
0,0,0,0,0,0,0,0,0,0,0,0,0,0,0,0,0,0,0,0,0,41,0,0,0
0,0,0,0,0,0,0,0,0,0,0,0,0,0,0,0,0,0,0,0,0,0,0,0,0
:endlayer
layer: 13
0,0,0,0,0,0,0,0,0,0,0,0,0,0,0,0,0,0,0,0,0,0,0,0,0
0,0,0,0,0,0,0,0,0,0,0,0,0,0,0,0,0,0,0,0,0,0,0,0,0
0,0,0,0,0,0,0,0,0,0,0,0,0,0,0,0,0,0,0,0,0,0,0,0,0
0,0,0,0,0,0,0,0,0,0,0,0,0,22,0,0,0,0,0,0,22,0,0,0,0
0,0,0,0,22,0,0,0,0,0,22,0,20,5,5,5,16,5,5,5,5,13,0,0,0
0,0,44,20,5,5,5,16,5,5,5,13,0,5,0,21,0,0,0,0,5,0,0,0,0
0,0,44,0,5,0,21,0,0,0,5,0,0,5,0,0,0,0,0,0,16,0,0,0,0
0,0,44,0,5,0,0,0,0,0,5,0,0,5,0,22,0,0,0,0,5,0,0,0,0
0,0,44,0,5,0,0,0,0,0,16,0,20,5,5,5,16,5,5,5,5,13,0,0,0
0,0,44,0,5,0,0,0,0,0,5,0,0,21,0,0,0,0,0,0,21,0,0,0,0
0,0,44,0,5,0,22,0,0,0,5,0,0,0,0,0,0,0,0,0,0,0,0,0,0
0,0,44,20,5,5,5,16,5,5,5,13,0,0,0,0,0,0,0,0,0,37,37,0,0
0,0,0,0,21,0,0,0,0,0,21,0,0,0,0,0,0,0,0,0,37,14,37,0,0
0,0,0,0,0,0,0,0,0,0,0,0,0,0,0,0,0,0,0,0,0,37,37,0,0
0,0,0,0,0,0,0,0,0,0,0,0,0,0,0,0,0,0,0,0,0,0,0,0,0
0,0,0,0,0,0,0,0,0,0,0,0,0,0,0,0,0,0,0,0,0,0,0,0,0
:endlayer
layer: 14
0,0,0,0,0,0,0,0,0,0,0,0,0,0,0,0,0,0,0,0,0,0,0,0,0
0,0,0,0,0,0,0,0,0,0,0,0,0,0,0,0,0,0,0,0,0,0,0,0,0
0,0,0,0,0,0,0,0,0,0,0,0,0,0,0,0,0,0,0,0,0,0,0,0,0
0,0,0,0,0,0,0,0,0,0,0,0,39,39,39,39,39,39,39,39,39,39,0,0,0
0,0,0,45,39,39,39,39,39,39,39,39,0,5,24,24,24,24,24,24,5,0,0,0,0
0,0,0,44,5,24,24,24,24,24,5,0,0,5,0,0,0,0,0,0,5,0,0,0,0
0,0,0,44,5,0,0,0,0,0,5,0,0,5,0,0,0,0,0,0,5,0,0,0,0
0,0,0,44,5,0,0,0,0,0,5,0,0,5,0,0,0,0,0,0,5,0,0,0,0
0,0,0,44,5,0,0,0,0,0,5,0,0,5,24,24,24,24,24,24,5,0,0,0,0
0,0,0,44,5,0,0,0,0,0,5,0,46,46,46,46,46,46,46,46,46,46,0,0,0
0,0,0,44,5,0,0,0,0,0,5,0,0,0,0,0,0,0,0,0,0,0,0,0,0
0,0,0,44,5,24,24,24,24,24,5,0,0,0,0,0,0,0,0,0,0,0,0,0,0
0,0,0,45,46,46,46,46,46,46,46,46,0,0,0,0,0,0,0,0,0,37,0,0,0
0,0,0,0,0,0,0,0,0,0,0,0,0,0,0,0,0,0,0,0,0,0,0,0,0
0,0,0,0,0,0,0,0,0,0,0,0,0,0,0,0,0,0,0,0,0,0,0,0,0
0,0,0,0,0,0,0,0,0,0,0,0,0,0,0,0,0,0,0,0,0,0,0,0,0
:endlayer
layer: 15
0,0,0,0,0,0,0,0,0,0,0,0,0,0,0,0,0,0,0,0,0,0,0,0,0
0,0,0,0,0,0,0,0,0,0,0,0,0,0,0,0,0,0,0,0,0,0,0,0,0
0,0,0,0,0,0,0,0,0,0,0,0,0,0,0,0,0,0,0,0,0,0,0,0,0
0,0,0,0,0,0,0,0,0,0,0,0,0,0,0,0,0,0,0,0,0,0,0,0,0
0,0,0,0,0,0,0,0,0,0,0,0,39,39,39,39,39,39,39,39,39,39,0,0,0
0,0,0,0,39,39,39,39,39,39,39,39,0,5,24,24,24,24,24,24,5,0,0,0,0
0,0,0,0,5,24,24,24,24,24,5,0,0,5,0,0,0,0,0,0,5,0,0,0,0
0,0,0,0,5,0,0,0,0,0,5,0,0,5,24,24,24,24,24,24,5,0,0,0,0
0,0,0,0,5,0,0,0,0,0,5,0,46,46,46,46,46,46,46,46,46,46,0,0,0
0,0,0,0,5,0,0,0,0,0,5,0,0,0,0,0,0,0,0,0,0,0,0,0,0
0,0,0,0,5,24,24,24,24,24,5,0,0,0,0,0,0,0,0,0,0,0,0,0,0
0,0,0,0,46,46,46,46,46,46,46,46,0,0,0,0,0,0,0,0,0,0,0,0,0
0,0,0,0,0,0,0,0,0,0,0,0,0,0,0,0,0,0,0,0,0,0,0,0,0
0,0,0,0,0,0,0,0,0,0,0,0,0,0,0,0,0,0,0,0,0,0,0,0,0
0,0,0,0,0,0,0,0,0,0,0,0,0,0,0,0,0,0,0,0,0,0,0,0,0
0,0,0,0,0,0,0,0,0,0,0,0,0,0,0,0,0,0,0,0,0,0,0,0,0
:endlayer
layer: 16
0,0,0,0,0,0,0,0,0,0,0,0,0,0,0,0,0,0,0,0,0,0,0,0,0
0,0,0,0,0,0,0,0,0,0,0,0,0,0,0,0,0,0,0,0,0,0,0,0,0
0,0,0,0,0,0,0,0,0,0,0,0,0,0,0,0,0,0,0,0,0,0,0,0,0
0,0,0,0,0,0,0,0,0,0,0,0,0,0,0,0,0,0,0,0,0,0,0,0,0
0,0,0,0,0,0,0,0,0,0,0,0,0,0,0,0,0,0,0,0,0,0,0,0,0
0,0,0,0,0,0,0,0,0,0,0,0,39,39,39,39,39,39,39,39,39,39,0,0,0
0,0,0,0,39,39,39,39,39,39,39,39,47,24,24,24,24,24,24,24,24,48,0,0,0
0,0,0,0,5,24,24,24,24,24,5,0,46,46,46,46,46,46,46,46,46,46,0,0,0
0,0,0,20,5,0,0,0,0,0,5,13,0,0,0,0,0,0,0,0,0,0,0,0,0
0,0,0,0,5,24,24,24,24,24,5,0,0,0,0,0,0,0,0,0,0,0,0,0,0
0,0,0,0,46,46,46,46,46,46,46,46,0,0,0,0,0,0,0,0,0,0,0,0,0
0,0,0,0,0,0,0,0,0,0,0,0,0,0,0,0,0,0,0,0,0,0,0,0,0
0,0,0,0,0,0,0,0,0,0,0,0,0,0,0,0,0,0,0,0,0,0,0,0,0
0,0,0,0,0,0,0,0,0,0,0,0,0,0,0,0,0,0,0,0,0,0,0,0,0
0,0,0,0,0,0,0,0,0,0,0,0,0,0,0,0,0,0,0,0,0,0,0,0,0
0,0,0,0,0,0,0,0,0,0,0,0,0,0,0,0,0,0,0,0,0,0,0,0,0
:endlayer
layer: 17
0,0,0,0,0,0,0,0,0,0,0,0,0,0,0,0,0,0,0,0,0,0,0,0,0
0,0,0,0,0,0,0,0,0,0,0,0,0,0,0,0,0,0,0,0,0,0,0,0,0
0,0,0,0,0,0,0,0,0,0,0,0,0,0,0,0,0,0,0,0,0,0,0,0,0
0,0,0,0,0,0,0,0,0,0,0,0,0,0,0,0,0,0,0,0,0,0,0,0,0
0,0,0,0,0,0,0,0,0,0,0,0,0,0,0,0,0,0,0,0,0,0,0,0,0
0,0,0,0,0,0,0,0,0,0,0,0,0,0,0,0,0,0,0,0,0,0,0,0,0
0,0,0,0,0,0,0,0,0,0,0,0,0,31,0,0,0,0,0,0,31,0,0,0,0
0,0,0,0,39,39,39,39,39,39,39,39,0,0,0,0,0,0,0,0,0,0,0,0,0
0,0,0,0,24,24,24,24,24,24,24,48,0,0,0,0,0,0,0,0,0,0,0,0,0
0,0,0,0,46,46,46,46,46,46,46,46,0,0,0,0,0,0,0,0,0,0,0,0,0
0,0,0,0,0,0,0,0,0,0,0,0,0,0,0,0,0,0,0,0,0,0,0,0,0
0,0,0,0,0,0,0,0,0,0,0,0,0,0,0,0,0,0,0,0,0,0,0,0,0
0,0,0,0,0,0,0,0,0,0,0,0,0,0,0,0,0,0,0,0,0,0,0,0,0
0,0,0,0,0,0,0,0,0,0,0,0,0,0,0,0,0,0,0,0,0,0,0,0,0
0,0,0,0,0,0,0,0,0,0,0,0,0,0,0,0,0,0,0,0,0,0,0,0,0
0,0,0,0,0,0,0,0,0,0,0,0,0,0,0,0,0,0,0,0,0,0,0,0,0
:endlayer
layer: 18
0,0,0,0,0,0,0,0,0,0,0,0,0,0,0,0,0,0,0,0,0,0,0,0,0
0,0,0,0,0,0,0,0,0,0,0,0,0,0,0,0,0,0,0,0,0,0,0,0,0
0,0,0,0,0,0,0,0,0,0,0,0,0,0,0,0,0,0,0,0,0,0,0,0,0
0,0,0,0,0,0,0,0,0,0,0,0,0,0,0,0,0,0,0,0,0,0,0,0,0
0,0,0,0,0,0,0,0,0,0,0,0,0,0,0,0,0,0,0,0,0,0,0,0,0
0,0,0,0,0,0,0,0,0,0,0,0,0,0,0,0,0,0,0,0,0,0,0,0,0
0,0,0,0,0,0,0,0,0,0,0,0,0,0,0,0,0,0,0,0,0,0,0,0,0
0,0,0,0,0,0,0,0,0,0,0,0,0,0,0,0,0,0,0,0,0,0,0,0,0
0,0,0,0,31,0,0,0,0,0,31,0,0,0,0,0,0,0,0,0,0,0,0,0,0
0,0,0,0,0,0,0,0,0,0,0,0,0,0,0,0,0,0,0,0,0,0,0,0,0
0,0,0,0,0,0,0,0,0,0,0,0,0,0,0,0,0,0,0,0,0,0,0,0,0
0,0,0,0,0,0,0,0,0,0,0,0,0,0,0,0,0,0,0,0,0,0,0,0,0
0,0,0,0,0,0,0,0,0,0,0,0,0,0,0,0,0,0,0,0,0,0,0,0,0
0,0,0,0,0,0,0,0,0,0,0,0,0,0,0,0,0,0,0,0,0,0,0,0,0
0,0,0,0,0,0,0,0,0,0,0,0,0,0,0,0,0,0,0,0,0,0,0,0,0
0,0,0,0,0,0,0,0,0,0,0,0,0,0,0,0,0,0,0,0,0,0,0,0,0
:endlayer
layer: 19
0,0,0,0,0,0,0,0,0,0,0,0,0,0,0,0,0,0,0,0,0,0,0,0,0
0,0,0,0,0,0,0,0,0,0,0,0,0,0,0,0,0,0,0,0,0,0,0,0,0
0,0,0,0,0,0,0,0,0,0,0,0,0,0,0,0,0,0,0,0,0,0,0,0,0
0,0,0,0,0,0,0,0,0,0,0,0,0,0,0,0,0,0,0,0,0,0,0,0,0
0,0,0,0,0,0,0,0,0,0,0,0,0,0,0,0,0,0,0,0,0,0,0,0,0
0,0,0,0,0,0,0,0,0,0,0,0,0,0,0,0,0,0,0,0,0,0,0,0,0
0,0,0,0,0,0,0,0,0,0,0,0,0,0,0,0,0,0,0,0,0,0,0,0,0
0,0,0,0,0,0,0,0,0,0,0,0,0,0,0,0,0,0,0,0,0,0,0,0,0
0,0,0,0,0,0,0,0,0,0,0,0,0,0,0,0,0,0,0,0,0,0,0,0,0
0,0,0,0,0,0,0,0,0,0,0,0,0,0,0,0,0,0,0,0,0,0,0,0,0
0,0,0,0,0,0,0,0,0,0,0,0,0,0,0,0,0,0,0,0,0,0,0,0,0
0,0,0,0,0,0,0,0,0,0,0,0,0,0,0,0,0,0,0,0,0,0,0,0,0
0,0,0,0,0,0,0,0,0,0,0,0,0,0,0,0,0,0,0,0,0,0,0,0,0
0,0,0,0,0,0,0,0,0,0,0,0,0,0,0,0,0,0,0,0,0,0,0,0,0
0,0,0,0,0,0,0,0,0,0,0,0,0,0,0,0,0,0,0,0,0,0,0,0,0
0,0,0,0,0,0,0,0,0,0,0,0,0,0,0,0,0,0,0,0,0,0,0,0,0
:endlayer
layer: 20
0,0,0,0,0,0,0,0,0,0,0,0,0,0,0,0,0,0,0,0,0,0,0,0,0
0,0,0,0,0,0,0,0,0,0,0,0,0,0,0,0,0,0,0,0,0,0,0,0,0
0,0,0,0,0,0,0,0,0,0,0,0,0,0,0,0,0,0,0,0,0,0,0,0,0
0,0,0,0,0,0,0,0,0,0,0,0,0,0,0,0,0,0,0,0,0,0,0,0,0
0,0,0,0,0,0,0,0,0,0,0,0,0,0,0,0,0,0,0,0,0,0,0,0,0
0,0,0,0,0,0,0,0,0,0,0,0,0,0,0,0,0,0,0,0,0,0,0,0,0
0,0,0,0,0,0,0,0,0,0,0,0,0,0,0,0,0,0,0,0,0,0,0,0,0
0,0,0,0,0,0,0,0,0,0,0,0,0,0,0,0,0,0,0,0,0,0,0,0,0
0,0,0,0,0,0,0,0,0,0,0,0,0,0,0,0,0,0,0,0,0,0,0,0,0
0,0,0,0,0,0,0,0,0,0,0,0,0,0,0,0,0,0,0,0,0,0,0,0,0
0,0,0,0,0,0,0,0,0,0,0,0,0,0,0,0,0,0,0,0,0,0,0,0,0
0,0,0,0,0,0,0,0,0,0,0,0,0,0,0,0,0,0,0,0,0,0,0,0,0
0,0,0,0,0,0,0,0,0,0,0,0,0,0,0,0,0,0,0,0,0,0,0,0,0
0,0,0,0,0,0,0,0,0,0,0,0,0,0,0,0,0,0,0,0,0,0,0,0,0
0,0,0,0,0,0,0,0,0,0,0,0,0,0,0,0,0,0,0,0,0,0,0,0,0
0,0,0,0,0,0,0,0,0,0,0,0,0,0,0,0,0,0,0,0,0,0,0,0,0
:endlayer
layer: 21
0,0,0,0,0,0,0,0,0,0,0,0,0,0,0,0,0,0,0,0,0,0,0,0,0
0,0,0,0,0,0,0,0,0,0,0,0,0,0,0,0,0,0,0,0,0,0,0,0,0
0,0,0,0,0,0,0,0,0,0,0,0,0,0,0,0,0,0,0,0,0,0,0,0,0
0,0,0,0,0,0,0,0,0,0,0,0,0,0,0,0,0,0,0,0,0,0,0,0,0
0,0,0,0,0,0,0,0,0,0,0,0,0,0,0,0,0,0,0,0,0,0,0,0,0
0,0,0,0,0,0,0,0,0,0,0,0,0,0,0,0,0,0,0,0,0,0,0,0,0
0,0,0,0,0,0,0,0,0,0,0,0,0,0,0,0,0,0,0,0,0,0,0,0,0
0,0,0,0,0,0,0,0,0,0,0,0,0,0,0,0,0,0,0,0,0,0,0,0,0
0,0,0,0,0,0,0,0,0,0,0,0,0,0,0,0,0,0,0,0,0,0,0,0,0
0,0,0,0,0,0,0,0,0,0,0,0,0,0,0,0,0,0,0,0,0,0,0,0,0
0,0,0,0,0,0,0,0,0,0,0,0,0,0,0,0,0,0,0,0,0,0,0,0,0
0,0,0,0,0,0,0,0,0,0,0,0,0,0,0,0,0,0,0,0,0,0,0,0,0
0,0,0,0,0,0,0,0,0,0,0,0,0,0,0,0,0,0,0,0,0,0,0,0,0
0,0,0,0,0,0,0,0,0,0,0,0,0,0,0,0,0,0,0,0,0,0,0,0,0
0,0,0,0,0,0,0,0,0,0,0,0,0,0,0,0,0,0,0,0,0,0,0,0,0
0,0,0,0,0,0,0,0,0,0,0,0,0,0,0,0,0,0,0,0,0,0,0,0,0
:endlayer

#### RULES ####
rule:
plugin=vanillaBlocks
number=1
data:
JSON:{{"val":{"blockName":{"val":"minecraft:cobblestone","id":"ss"},"meta":{"val":"0","id":"pi"},"buildPass":{"val":"0","id":"pi"}},"id":"ct"}}
:enddata
:endrule

rule:
plugin=vanillaBlocks
number=2
data:
JSON:{{"val":{"blockName":{"val":"minecraft:dirt","id":"ss"},"meta":{"val":"0","id":"pi"},"buildPass":{"val":"0","id":"pi"}},"id":"ct"}}
:enddata
:endrule

rule:
plugin=vanillaBlocks
number=3
data:
JSON:{{"val":{"blockName":{"val":"minecraft:stone","id":"ss"},"meta":{"val":"0","id":"pi"},"buildPass":{"val":"0","id":"pi"}},"id":"ct"}}
:enddata
:endrule

rule:
plugin=vanillaBlocks
number=4
data:
JSON:{{"val":{"blockName":{"val":"minecraft:gravel","id":"ss"},"meta":{"val":"0","id":"pi"},"buildPass":{"val":"0","id":"pi"}},"id":"ct"}}
:enddata
:endrule

rule:
plugin=vanillaBlocks
number=5
data:
JSON:{{"val":{"blockName":{"val":"minecraft:stonebrick","id":"ss"},"meta":{"val":"0","id":"pi"},"buildPass":{"val":"0","id":"pi"}},"id":"ct"}}
:enddata
:endrule

rule:
plugin=vanillaBlocks
number=6
data:
JSON:{{"val":{"blockName":{"val":"minecraft:stone_stairs","id":"ss"},"meta":{"val":"1","id":"pi"},"buildPass":{"val":"0","id":"pi"}},"id":"ct"}}
:enddata
:endrule

rule:
plugin=vanillaBlocks
number=7
data:
JSON:{{"val":{"blockName":{"val":"minecraft:stone_stairs","id":"ss"},"meta":{"val":"2","id":"pi"},"buildPass":{"val":"0","id":"pi"}},"id":"ct"}}
:enddata
:endrule

rule:
plugin=vanillaBlocks
number=8
data:
JSON:{{"val":{"blockName":{"val":"minecraft:grass","id":"ss"},"meta":{"val":"0","id":"pi"},"buildPass":{"val":"0","id":"pi"}},"id":"ct"}}
:enddata
:endrule

rule:
plugin=vanillaDoors
number=9
data:
JSON:{{"val":{"sideFlag":{"val":"8","id":"pb"},"blockName":{"val":"minecraft:wooden_door","id":"ss"},"meta":{"val":"2","id":"pi"},"buildPass":{"val":"2","id":"pi"}},"id":"ct"}}
:enddata
:endrule

rule:
plugin=vanillaDoors
number=10
data:
JSON:{{"val":{"sideFlag":{"val":"8","id":"pb"},"blockName":{"val":"minecraft:wooden_door","id":"ss"},"meta":{"val":"1","id":"pi"},"buildPass":{"val":"2","id":"pi"}},"id":"ct"}}
:enddata
:endrule

rule:
plugin=vanillaBlocks
number=11
data:
JSON:{{"val":{"blockName":{"val":"minecraft:stone_brick_stairs","id":"ss"},"meta":{"val":"3","id":"pi"},"buildPass":{"val":"0","id":"pi"}},"id":"ct"}}
:enddata
:endrule

rule:
plugin=vanillaBlocks
number=12
data:
JSON:{{"val":{"blockName":{"val":"minecraft:stone_brick_stairs","id":"ss"},"meta":{"val":"2","id":"pi"},"buildPass":{"val":"0","id":"pi"}},"id":"ct"}}
:enddata
:endrule

rule:
plugin=vanillaBlocks
number=13
data:
JSON:{{"val":{"blockName":{"val":"minecraft:torch","id":"ss"},"meta":{"val":"1","id":"pi"},"buildPass":{"val":"2","id":"pi"}},"id":"ct"}}
:enddata
:endrule

rule:
plugin=vanillaBlocks
number=14
data:
JSON:{{"val":{"blockName":{"val":"minecraft:log","id":"ss"},"meta":{"val":"2","id":"pi"},"buildPass":{"val":"0","id":"pi"}},"id":"ct"}}
:enddata
:endrule

rule:
plugin=vanillaBlocks
number=15
data:
JSON:{{"val":{"blockName":{"val":"minecraft:stone_brick_stairs","id":"ss"},"meta":{"val":"1","id":"pi"},"buildPass":{"val":"0","id":"pi"}},"id":"ct"}}
:enddata
:endrule

rule:
plugin=vanillaBlocks
number=16
data:
JSON:{{"val":{"blockName":{"val":"minecraft:glass_pane","id":"ss"},"meta":{"val":"0","id":"pi"},"buildPass":{"val":"0","id":"pi"}},"id":"ct"}}
:enddata
:endrule

rule:
plugin=vanillaDoors
number=17
data:
JSON:{{"val":{"sideFlag":{"val":"0","id":"pb"},"blockName":{"val":"minecraft:wooden_door","id":"ss"},"meta":{"val":"8","id":"pi"},"buildPass":{"val":"2","id":"pi"}},"id":"ct"}}
:enddata
:endrule

rule:
plugin=vanillaDoors
number=18
data:
JSON:{{"val":{"sideFlag":{"val":"0","id":"pb"},"blockName":{"val":"minecraft:wooden_door","id":"ss"},"meta":{"val":"8","id":"pi"},"buildPass":{"val":"2","id":"pi"}},"id":"ct"}}
:enddata
:endrule

rule:
plugin=vanillaDoors
number=19
data:
JSON:{{"val":{"sideFlag":{"val":"9","id":"pb"},"blockName":{"val":"minecraft:wooden_door","id":"ss"},"meta":{"val":"1","id":"pi"},"buildPass":{"val":"2","id":"pi"}},"id":"ct"}}
:enddata
:endrule

rule:
plugin=vanillaBlocks
number=20
data:
JSON:{{"val":{"blockName":{"val":"minecraft:torch","id":"ss"},"meta":{"val":"2","id":"pi"},"buildPass":{"val":"2","id":"pi"}},"id":"ct"}}
:enddata
:endrule

rule:
plugin=vanillaBlocks
number=21
data:
JSON:{{"val":{"blockName":{"val":"minecraft:torch","id":"ss"},"meta":{"val":"3","id":"pi"},"buildPass":{"val":"2","id":"pi"}},"id":"ct"}}
:enddata
:endrule

rule:
plugin=vanillaBlocks
number=22
data:
JSON:{{"val":{"blockName":{"val":"minecraft:torch","id":"ss"},"meta":{"val":"4","id":"pi"},"buildPass":{"val":"2","id":"pi"}},"id":"ct"}}
:enddata
:endrule

rule:
plugin=vanillaDoors
number=23
data:
JSON:{{"val":{"sideFlag":{"val":"0","id":"pb"},"blockName":{"val":"minecraft:wooden_door","id":"ss"},"meta":{"val":"9","id":"pi"},"buildPass":{"val":"2","id":"pi"}},"id":"ct"}}
:enddata
:endrule

rule:
plugin=vanillaBlocks
number=24
data:
JSON:{{"val":{"blockName":{"val":"minecraft:planks","id":"ss"},"meta":{"val":"0","id":"pi"},"buildPass":{"val":"0","id":"pi"}},"id":"ct"}}
:enddata
:endrule

rule:
plugin=vanillaBlocks
number=25
data:
JSON:{{"val":{"blockName":{"val":"minecraft:leaves","id":"ss"},"meta":{"val":"2","id":"pi"},"buildPass":{"val":"0","id":"pi"}},"id":"ct"}}
:enddata
:endrule

rule:
plugin=vanillaBlocks
number=26
data:
JSON:{{"val":{"blockName":{"val":"minecraft:fence","id":"ss"},"meta":{"val":"0","id":"pi"},"buildPass":{"val":"0","id":"pi"}},"id":"ct"}}
:enddata
:endrule

rule:
plugin=vanillaDoors
number=27
data:
JSON:{{"val":{"sideFlag":{"val":"8","id":"pb"},"blockName":{"val":"minecraft:wooden_door","id":"ss"},"meta":{"val":"0","id":"pi"},"buildPass":{"val":"2","id":"pi"}},"id":"ct"}}
:enddata
:endrule

rule:
plugin=vanillaBlocks
number=28
data:
JSON:{{"val":{"blockName":{"val":"minecraft:stone_brick_stairs","id":"ss"},"meta":{"val":"0","id":"pi"},"buildPass":{"val":"0","id":"pi"}},"id":"ct"}}
:enddata
:endrule

rule:
plugin=vanillaDoors
number=29
data:
JSON:{{"val":{"sideFlag":{"val":"8","id":"pb"},"blockName":{"val":"minecraft:wooden_door","id":"ss"},"meta":{"val":"3","id":"pi"},"buildPass":{"val":"2","id":"pi"}},"id":"ct"}}
:enddata
:endrule

rule:
plugin=vanillaDoors
number=30
data:
JSON:{{"val":{"sideFlag":{"val":"9","id":"pb"},"blockName":{"val":"minecraft:wooden_door","id":"ss"},"meta":{"val":"3","id":"pi"},"buildPass":{"val":"2","id":"pi"}},"id":"ct"}}
:enddata
:endrule

rule:
plugin=vanillaBlocks
number=31
data:
JSON:{{"val":{"blockName":{"val":"minecraft:torch","id":"ss"},"meta":{"val":"5","id":"pi"},"buildPass":{"val":"2","id":"pi"}},"id":"ct"}}
:enddata
:endrule

rule:
plugin=vanillaDoors
number=32
data:
JSON:{{"val":{"sideFlag":{"val":"0","id":"pb"},"blockName":{"val":"minecraft:wooden_door","id":"ss"},"meta":{"val":"8","id":"pi"},"buildPass":{"val":"2","id":"pi"}},"id":"ct"}}
:enddata
:endrule

rule:
plugin=vanillaDoors
number=33
data:
JSON:{{"val":{"sideFlag":{"val":"0","id":"pb"},"blockName":{"val":"minecraft:wooden_door","id":"ss"},"meta":{"val":"8","id":"pi"},"buildPass":{"val":"2","id":"pi"}},"id":"ct"}}
:enddata
:endrule

rule:
plugin=vanillaDoors
number=34
data:
JSON:{{"val":{"sideFlag":{"val":"0","id":"pb"},"blockName":{"val":"minecraft:wooden_door","id":"ss"},"meta":{"val":"8","id":"pi"},"buildPass":{"val":"2","id":"pi"}},"id":"ct"}}
:enddata
:endrule

rule:
plugin=vanillaDoors
number=35
data:
JSON:{{"val":{"sideFlag":{"val":"0","id":"pb"},"blockName":{"val":"minecraft:wooden_door","id":"ss"},"meta":{"val":"8","id":"pi"},"buildPass":{"val":"2","id":"pi"}},"id":"ct"}}
:enddata
:endrule

rule:
plugin=vanillaDoors
number=36
data:
JSON:{{"val":{"sideFlag":{"val":"0","id":"pb"},"blockName":{"val":"minecraft:wooden_door","id":"ss"},"meta":{"val":"9","id":"pi"},"buildPass":{"val":"2","id":"pi"}},"id":"ct"}}
:enddata
:endrule

rule:
plugin=vanillaBlocks
number=37
data:
JSON:{{"val":{"blockName":{"val":"minecraft:leaves","id":"ss"},"meta":{"val":"6","id":"pi"},"buildPass":{"val":"0","id":"pi"}},"id":"ct"}}
:enddata
:endrule

rule:
plugin=vanillaBlocks
number=38
data:
JSON:{{"val":{"blockName":{"val":"minecraft:oak_stairs","id":"ss"},"meta":{"val":"6","id":"pi"},"buildPass":{"val":"0","id":"pi"}},"id":"ct"}}
:enddata
:endrule

rule:
plugin=vanillaBlocks
number=39
data:
JSON:{{"val":{"blockName":{"val":"minecraft:oak_stairs","id":"ss"},"meta":{"val":"2","id":"pi"},"buildPass":{"val":"0","id":"pi"}},"id":"ct"}}
:enddata
:endrule

rule:
plugin=vanillaBlocks
number=40
data:
JSON:{{"val":{"blockName":{"val":"minecraft:oak_stairs","id":"ss"},"meta":{"val":"1","id":"pi"},"buildPass":{"val":"0","id":"pi"}},"id":"ct"}}
:enddata
:endrule

rule:
plugin=vanillaBlocks
number=41
data:
JSON:{{"val":{"blockName":{"val":"minecraft:leaves","id":"ss"},"meta":{"val":"14","id":"pi"},"buildPass":{"val":"0","id":"pi"}},"id":"ct"}}
:enddata
:endrule

rule:
plugin=vanillaDoors
number=42
data:
JSON:{{"val":{"sideFlag":{"val":"0","id":"pb"},"blockName":{"val":"minecraft:wooden_door","id":"ss"},"meta":{"val":"8","id":"pi"},"buildPass":{"val":"2","id":"pi"}},"id":"ct"}}
:enddata
:endrule

rule:
plugin=vanillaDoors
number=43
data:
JSON:{{"val":{"sideFlag":{"val":"0","id":"pb"},"blockName":{"val":"minecraft:wooden_door","id":"ss"},"meta":{"val":"8","id":"pi"},"buildPass":{"val":"2","id":"pi"}},"id":"ct"}}
:enddata
:endrule

rule:
plugin=vanillaBlocks
number=44
data:
JSON:{{"val":{"blockName":{"val":"minecraft:oak_stairs","id":"ss"},"meta":{"val":"0","id":"pi"},"buildPass":{"val":"0","id":"pi"}},"id":"ct"}}
:enddata
:endrule

rule:
plugin=vanillaBlocks
number=45
data:
JSON:{{"val":{"blockName":{"val":"minecraft:wooden_slab","id":"ss"},"meta":{"val":"0","id":"pi"},"buildPass":{"val":"0","id":"pi"}},"id":"ct"}}
:enddata
:endrule

rule:
plugin=vanillaBlocks
number=46
data:
JSON:{{"val":{"blockName":{"val":"minecraft:oak_stairs","id":"ss"},"meta":{"val":"3","id":"pi"},"buildPass":{"val":"0","id":"pi"}},"id":"ct"}}
:enddata
:endrule

rule:
plugin=vanillaBlocks
number=47
data:
JSON:{{"val":{"blockName":{"val":"minecraft:oak_stairs","id":"ss"},"meta":{"val":"4","id":"pi"},"buildPass":{"val":"0","id":"pi"}},"id":"ct"}}
:enddata
:endrule

rule:
plugin=vanillaBlocks
number=48
data:
JSON:{{"val":{"blockName":{"val":"minecraft:oak_stairs","id":"ss"},"meta":{"val":"5","id":"pi"},"buildPass":{"val":"0","id":"pi"}},"id":"ct"}}
:enddata
:endrule

#### ENTITIES ####
