# Ancient Warfare Structure Template File
# Auto-generated structure template file. created on: 12/9/2014 at: 9:49:37
# Lines beginning with # denote comments

header:
version=2.1
name=wall_t_2
size=16,28,16
offset=15,4,15
:endheader

#### VALIDATION ####
validation:
type=ground
survival=false
worldGenEnabled=false
unique=false
preserveBlocks=false
selectionWeight=0
clusterValue=0
minDuplicateDistance=0
dimensionWhiteList=false
dimensionList=
biomeWhiteList=false
biomeList=
leveling=0
fill=0
border=0
validTargetBlocks=
blockSwap=false
data:
:enddata
:endvalidation

#### LAYERS ####
layer: 0
1,1,1,1,1,1,1,1,1,1,1,1,1,1,1,1
1,1,1,1,1,1,1,1,1,1,1,1,1,1,1,1
1,1,1,1,1,1,1,1,1,1,1,1,1,1,1,1
1,1,1,1,1,1,1,1,1,1,1,1,1,1,1,1
1,1,1,1,1,1,1,1,1,1,1,1,1,1,1,1
1,1,1,1,1,1,1,1,1,1,1,1,1,1,1,1
1,1,1,1,1,1,1,1,1,1,1,1,1,1,1,1
1,1,1,1,1,1,1,1,1,1,1,1,1,1,1,1
1,1,1,1,1,1,1,1,1,1,1,1,1,1,1,1
1,1,1,1,1,1,1,1,1,1,1,1,1,1,1,1
1,1,1,1,1,1,1,1,1,1,1,1,1,1,1,1
1,1,1,1,1,1,1,1,1,1,1,1,1,1,1,1
1,1,1,1,1,1,1,1,1,1,1,1,1,1,1,1
1,1,1,1,1,1,1,1,1,1,1,1,1,1,1,1
1,1,1,1,1,1,1,1,1,1,1,1,1,1,1,1
1,1,1,1,1,1,1,1,1,1,1,1,1,1,1,1
:endlayer
layer: 1
1,1,1,1,1,1,1,1,1,1,1,1,1,1,1,1
1,1,1,1,1,1,1,1,1,1,1,1,1,1,1,1
1,1,1,1,1,1,1,1,1,1,1,1,1,1,1,1
1,1,1,1,1,1,1,1,1,1,1,1,1,1,1,1
1,1,1,1,1,1,1,1,1,1,1,1,1,1,1,1
1,1,1,1,1,1,1,1,1,1,1,1,1,1,1,1
1,1,1,1,1,1,1,1,1,1,1,1,1,1,1,1
1,1,1,1,1,1,1,1,1,1,1,1,1,1,1,1
1,1,1,1,1,1,1,1,1,1,1,1,1,1,1,1
1,1,1,1,1,1,1,1,1,1,1,1,1,1,1,1
1,1,1,1,1,1,1,1,1,1,1,1,1,1,1,1
1,1,1,1,1,1,1,1,1,1,1,1,1,1,1,1
1,1,1,1,1,1,1,1,1,1,1,1,1,1,1,1
1,1,1,1,1,1,1,1,1,1,1,1,1,1,1,1
1,1,1,1,1,1,1,1,1,1,1,1,1,1,1,1
1,1,1,1,1,1,1,1,1,1,1,1,1,1,1,1
:endlayer
layer: 2
1,1,1,1,1,1,1,1,1,1,1,1,1,1,1,1
1,1,1,1,1,1,1,1,1,1,1,1,1,1,1,1
1,1,1,1,1,1,1,1,1,1,1,1,1,1,1,1
1,1,1,1,1,1,1,1,1,1,1,1,1,1,1,1
1,1,1,1,1,1,2,2,2,2,5,5,1,1,1,1
1,1,1,1,1,1,2,2,2,2,2,2,1,1,1,1
1,1,1,1,1,1,2,4,2,2,4,2,2,1,1,1
2,2,2,2,2,2,2,2,4,3,2,2,4,1,2,2
2,3,3,2,3,2,2,2,2,2,2,2,2,2,3,2
2,2,2,2,2,2,2,2,3,2,2,2,2,2,2,2
2,4,4,2,2,2,2,2,2,2,2,2,2,2,4,2
2,2,2,2,2,2,4,4,2,2,2,4,3,2,2,2
2,2,2,2,3,4,2,2,3,2,2,2,2,1,2,2
1,1,1,1,2,2,3,2,2,2,2,4,3,1,1,1
1,1,1,1,2,2,4,2,2,2,2,2,5,1,1,1
1,1,1,1,1,1,2,2,2,2,1,1,1,1,1,1
:endlayer
layer: 3
6,6,6,6,6,6,6,6,6,6,6,6,6,6,6,6
6,6,6,6,6,6,6,6,6,6,6,6,6,6,6,6
6,6,6,6,6,6,6,6,6,6,6,6,6,6,6,6
6,6,6,6,6,1,1,1,1,1,1,6,6,6,6,6
6,6,6,1,1,1,4,4,2,4,1,1,1,6,6,6
6,6,1,1,2,2,2,2,2,2,2,3,1,1,6,6
1,1,1,2,2,2,3,3,2,2,2,2,2,1,1,1
2,2,2,2,2,2,2,2,2,2,2,2,2,6,2,2
2,2,2,2,2,3,2,2,2,2,2,2,2,2,2,2
2,2,2,4,2,2,2,4,2,2,2,2,2,2,2,2
2,2,2,2,2,3,2,2,2,2,2,2,2,2,2,2
4,2,2,2,3,2,2,2,2,2,2,4,2,2,2,4
3,2,2,2,2,4,2,2,2,2,2,2,2,6,2,3
1,1,1,1,2,2,4,2,2,2,2,2,2,5,1,1
1,1,1,1,2,2,2,2,4,3,2,2,1,1,1,1
7,7,7,7,7,7,2,2,2,2,7,7,7,7,7,7
:endlayer
layer: 4
0,0,0,0,0,0,0,0,0,0,0,0,0,0,0,0
0,0,0,0,0,0,0,0,0,0,0,0,0,0,0,0
0,0,0,0,0,0,0,0,0,0,0,0,0,0,0,0
0,0,0,0,0,0,0,0,0,0,0,0,0,0,0,0
0,0,0,0,0,0,2,2,15,2,0,0,0,0,0,0
0,0,0,0,2,2,0,0,0,0,2,2,0,0,0,0
0,0,0,2,0,0,0,0,0,0,0,10,2,0,0,0
2,2,2,2,0,0,0,18,16,13,0,0,2,2,2,2
2,2,2,0,0,0,0,18,16,13,0,0,2,2,2,2
0,0,22,0,0,0,0,18,16,13,0,0,9,0,0,0
2,2,2,11,11,0,0,18,16,13,0,0,2,2,2,2
2,2,2,21,0,0,0,0,17,0,0,11,2,2,2,2
2,2,2,2,11,0,0,0,0,0,0,12,2,2,2,2
0,0,2,2,11,20,11,0,11,0,11,11,2,2,0,0
0,0,0,0,2,2,11,19,11,14,2,2,0,0,0,0
8,8,8,0,8,0,2,2,2,2,0,0,0,0,8,8
:endlayer
layer: 5
0,0,0,0,0,0,0,0,0,0,0,0,0,0,0,0
0,0,0,0,0,0,0,0,0,0,0,0,0,0,0,0
0,0,0,0,0,0,0,0,0,0,0,0,0,0,0,0
0,0,0,0,0,0,0,0,0,0,0,0,0,0,0,0
0,0,0,0,0,0,2,3,25,2,0,0,0,0,0,0
0,0,0,0,2,2,0,0,0,0,2,2,0,0,0,0
0,0,0,2,0,0,0,0,0,0,0,0,2,0,0,0
2,2,2,2,0,0,0,0,26,0,0,0,2,2,2,2
2,3,3,0,0,0,0,0,26,0,0,0,2,23,3,2
0,0,27,0,0,0,0,0,26,0,0,0,24,0,0,0
2,2,2,0,0,0,0,0,26,0,0,0,2,2,2,2
2,2,2,0,0,0,0,0,0,0,0,0,2,2,2,2
4,2,2,2,0,0,0,0,0,0,0,0,2,2,2,4
0,0,2,2,0,0,0,0,0,0,0,0,3,2,0,0
0,0,0,0,2,2,0,0,0,0,2,2,0,0,0,0
0,0,0,0,0,0,3,2,2,2,0,0,0,0,0,0
:endlayer
layer: 6
0,0,0,0,0,0,0,0,0,0,0,0,0,0,0,0
0,0,0,0,0,0,0,0,0,0,0,0,0,0,0,0
0,0,0,0,0,0,0,0,0,0,0,0,0,0,0,0
0,0,0,0,0,0,0,0,29,0,0,0,0,0,0,0
0,0,0,0,0,0,2,2,2,2,0,0,0,0,0,0
0,0,0,0,2,2,0,0,0,0,2,2,0,0,0,0
0,0,0,2,0,0,0,0,0,0,0,0,4,0,0,0
2,2,2,2,0,0,0,0,0,0,0,0,2,2,2,2
2,2,2,0,0,0,0,0,0,0,0,0,2,2,2,2
2,4,4,30,0,0,0,0,0,0,0,28,2,2,4,2
2,2,2,0,0,0,0,0,0,0,0,0,2,2,2,2
2,2,2,31,0,0,0,0,0,0,0,0,2,2,2,2
2,2,2,2,0,0,0,0,0,0,0,0,2,2,2,2
0,0,2,2,0,0,0,0,0,0,0,0,2,2,0,0
0,0,0,0,2,2,0,0,0,0,2,3,0,0,0,0
0,0,0,0,0,0,2,2,2,2,0,0,0,0,0,0
:endlayer
layer: 7
0,0,0,0,0,0,0,0,0,0,0,0,0,0,0,0
0,0,0,0,0,0,0,0,0,0,0,0,0,0,0,0
0,0,0,0,0,0,0,0,0,0,0,0,0,0,0,0
0,0,0,0,0,0,0,0,0,0,0,0,0,0,0,0
0,0,0,0,0,0,2,2,2,2,0,0,0,0,0,0
0,0,0,0,2,2,0,0,0,23,2,2,0,0,0,0
0,0,0,2,31,0,0,0,0,0,0,0,3,0,0,0
2,2,2,2,0,0,0,0,0,0,0,0,2,2,2,2
2,2,2,0,0,0,0,0,0,0,0,32,2,2,2,2
2,2,2,0,0,0,0,0,0,0,0,0,2,2,2,2
2,2,2,0,0,0,0,0,0,0,0,0,2,2,2,2
2,2,2,0,0,0,0,0,0,0,0,0,2,2,2,2
2,2,2,3,0,0,0,0,0,0,0,0,2,2,2,2
0,0,2,2,0,0,0,0,0,0,0,29,2,2,0,0
0,0,0,0,4,4,29,0,0,0,2,2,0,0,0,0
0,0,0,0,0,0,2,2,2,2,0,0,0,0,0,0
:endlayer
layer: 8
0,0,0,0,0,0,0,0,0,0,0,0,0,0,0,0
0,0,0,0,0,0,0,0,0,0,0,0,0,0,0,0
0,0,0,0,0,0,0,0,0,0,0,0,0,0,0,0
0,0,0,0,0,0,0,0,0,0,0,0,0,0,0,0
0,0,0,0,0,0,2,2,2,2,0,0,0,0,0,0
0,0,0,0,2,2,2,2,2,2,2,2,0,0,0,0
0,0,0,2,2,2,4,2,2,3,2,2,2,0,0,0
2,2,2,2,2,2,2,2,2,4,2,2,2,2,2,2
2,2,2,2,2,2,2,3,2,2,2,2,2,2,2,2
2,2,2,2,2,2,2,2,3,2,2,2,2,2,2,2
2,2,2,4,2,2,3,2,2,2,2,2,2,2,2,2
2,2,2,4,4,2,2,2,2,2,2,2,2,2,2,2
3,2,2,2,2,2,2,2,2,3,2,2,2,2,2,3
0,0,2,3,2,2,2,2,2,2,2,2,2,2,0,0
0,0,23,32,2,2,2,2,2,2,2,2,31,23,0,0
0,0,0,0,0,32,2,3,2,3,31,0,0,0,0,0
:endlayer
layer: 9
0,0,0,0,0,0,0,0,0,0,0,0,0,0,0,0
0,0,0,0,0,0,0,0,0,0,0,0,0,0,0,0
0,0,0,0,0,0,0,0,0,0,0,0,0,0,0,0
0,0,0,0,0,0,0,0,0,0,0,0,0,0,0,0
0,0,0,0,0,0,2,2,2,2,0,0,0,0,0,0
0,0,0,0,2,2,0,33,0,0,2,2,0,0,0,0
0,0,0,2,0,0,0,0,0,0,0,0,2,0,0,0
2,2,2,2,0,0,0,0,0,0,0,0,2,2,2,2
2,2,2,0,0,0,0,0,0,0,0,0,2,2,2,2
2,2,2,0,0,0,0,0,0,0,0,0,2,2,2,2
2,2,2,0,0,0,0,0,0,0,0,0,2,2,2,2
2,2,2,0,0,0,0,0,0,0,0,0,2,2,2,2
2,2,2,2,0,0,0,0,0,0,0,0,2,2,2,2
0,0,2,2,0,0,0,0,0,0,0,0,2,2,0,0
0,0,0,0,2,2,0,0,0,0,4,2,0,0,0,0
0,0,0,0,0,0,3,2,3,2,0,0,0,0,0,0
:endlayer
layer: 10
0,0,0,0,0,0,0,0,0,0,0,0,0,0,0,0
0,0,0,0,0,0,0,0,0,0,0,0,0,0,0,0
0,0,0,0,0,0,0,0,0,0,0,0,0,0,0,0
0,0,0,0,0,0,0,0,0,0,0,0,0,0,0,0
0,0,0,0,0,0,2,2,2,2,0,0,0,0,0,0
0,0,0,0,2,2,0,33,0,0,2,2,0,0,0,0
0,0,0,2,0,0,0,0,0,0,0,0,4,0,0,0
2,2,2,2,0,0,0,0,0,0,0,0,2,2,2,2
2,2,2,0,0,0,0,0,0,0,0,0,2,2,2,2
2,2,2,0,0,0,0,0,0,0,0,0,2,2,2,2
2,3,3,0,0,0,0,0,0,0,0,0,2,2,3,2
2,2,2,0,0,0,0,0,0,0,0,0,2,2,2,2
2,2,2,2,0,0,0,0,0,0,0,0,2,2,2,2
0,0,34,2,0,0,0,0,0,0,0,0,2,34,0,0
0,0,0,0,2,2,0,0,0,0,2,2,0,0,0,0
0,0,0,0,0,0,2,3,2,2,0,0,0,0,0,0
:endlayer
layer: 11
0,0,0,0,0,0,0,0,0,0,0,0,0,0,0,0
0,0,0,0,0,0,0,0,0,0,0,0,0,0,0,0
0,0,0,0,0,0,0,0,0,0,0,0,0,0,0,0
0,0,0,0,0,0,0,0,0,0,0,0,0,0,0,0
0,0,0,0,0,0,2,2,2,2,0,0,0,0,0,0
0,0,0,0,2,2,0,0,0,0,4,2,0,0,0,0
0,0,0,2,0,0,0,0,0,0,0,0,2,0,0,0
2,2,2,2,0,0,0,0,0,0,0,0,2,2,2,2
2,2,2,0,0,0,0,0,0,0,0,0,2,2,2,2
2,3,3,0,0,0,0,0,0,0,0,0,2,2,3,2
2,2,2,0,0,0,0,0,0,0,0,0,2,2,2,2
2,2,2,31,0,0,0,0,0,0,0,0,2,2,2,2
2,2,2,2,0,0,0,0,0,0,0,0,2,2,2,2
35,35,35,2,0,0,0,0,0,0,0,0,2,35,35,35
0,0,0,0,2,2,0,0,0,0,2,2,0,0,0,0
0,0,0,0,0,0,2,2,2,3,0,0,0,0,0,0
:endlayer
layer: 12
0,0,0,0,0,0,0,0,0,0,0,0,0,0,0,0
0,0,0,0,0,0,0,0,0,0,0,0,0,0,0,0
0,0,0,0,0,0,0,0,0,0,0,0,0,0,0,0
0,0,0,0,0,0,0,0,0,0,0,0,0,0,0,0
0,0,0,0,0,0,3,3,2,2,0,0,0,0,0,0
0,0,0,0,2,2,2,2,2,2,2,2,0,0,0,0
0,0,0,2,2,2,2,2,2,2,2,2,2,0,0,0
2,2,2,2,2,2,2,2,2,2,2,2,2,2,2,2
0,2,2,2,2,2,2,2,2,4,2,2,2,2,2,0
0,2,2,2,2,2,2,2,2,3,2,2,2,2,2,0
0,0,37,2,2,2,3,2,2,2,2,2,2,2,36,0
0,2,2,2,2,2,2,2,2,4,2,4,2,2,2,0
0,0,2,3,2,2,2,2,2,2,2,2,2,2,0,0
2,2,2,2,2,2,2,2,2,2,2,2,2,2,2,2
0,0,0,0,2,2,2,2,2,2,2,2,0,0,0,0
0,0,0,0,0,0,2,3,3,2,0,0,0,0,0,0
:endlayer
layer: 13
0,0,0,0,0,0,0,0,0,0,0,0,0,0,0,0
0,0,0,0,0,0,0,0,0,0,0,0,0,0,0,0
0,0,0,0,0,0,0,0,0,0,0,0,0,0,0,0
0,0,0,0,0,0,0,0,0,0,0,0,0,0,0,0
0,0,0,0,0,0,2,2,2,2,0,0,0,0,0,0
0,0,0,0,2,2,0,0,0,0,2,2,0,0,0,0
0,0,0,2,0,0,0,0,0,0,0,0,2,0,0,0
0,36,2,2,2,2,0,0,0,0,0,0,2,2,36,0
0,2,2,2,2,2,0,0,0,0,0,0,2,2,2,0
0,2,2,0,34,34,0,0,0,0,0,0,2,2,2,0
0,0,0,0,0,0,0,0,0,0,0,0,0,0,0,0
0,2,2,0,0,0,0,0,0,0,0,0,2,2,2,0
0,0,2,2,0,0,0,0,0,0,0,0,2,2,0,0
0,36,36,2,0,0,0,0,0,0,0,0,2,36,0,36
0,0,0,0,2,2,0,0,0,0,4,2,0,0,0,0
0,0,0,0,0,0,2,2,2,4,0,0,0,0,0,0
:endlayer
layer: 14
0,0,0,0,0,0,0,0,0,0,0,0,0,0,0,0
0,0,0,0,0,0,0,0,0,0,0,0,0,0,0,0
0,0,0,0,0,0,0,0,0,0,0,0,0,0,0,0
0,0,0,0,0,0,0,0,0,0,0,0,0,0,0,0
0,0,0,0,0,0,2,2,0,2,0,0,0,0,0,0
0,0,0,0,2,2,0,0,0,0,3,2,0,0,0,0
0,0,0,2,0,0,0,0,0,0,0,0,3,0,0,0
0,0,2,2,2,2,0,0,0,0,0,0,2,2,0,0
0,2,2,0,34,34,0,0,0,0,0,0,2,2,2,0
0,2,2,0,0,0,0,0,0,0,0,0,2,2,2,0
0,0,0,0,0,0,0,0,0,0,0,0,0,0,0,0
0,2,2,0,0,0,0,0,0,0,0,0,2,2,2,0
0,0,2,2,0,0,0,0,0,0,0,0,2,2,0,0
0,0,0,2,0,0,0,0,0,0,0,0,3,0,0,0
0,0,0,0,2,2,0,0,0,0,2,2,0,0,0,0
0,0,0,0,0,0,2,2,0,2,0,0,0,0,0,0
:endlayer
layer: 15
0,0,0,0,0,0,0,0,0,0,0,0,0,0,0,0
0,0,0,0,0,0,0,0,0,0,0,0,0,0,0,0
0,0,0,0,0,0,0,0,0,0,0,0,0,0,0,0
0,0,0,0,0,0,0,0,0,0,0,0,0,0,0,0
0,0,0,0,0,0,2,3,0,2,0,0,0,0,0,0
0,0,0,0,2,2,31,0,0,0,2,2,0,0,0,0
0,0,0,2,2,2,0,0,0,0,0,0,2,0,0,0
0,0,2,2,34,34,0,0,0,0,0,0,2,2,0,0
0,3,3,0,0,0,0,0,0,0,0,0,2,2,3,0
0,2,2,0,0,0,0,0,0,0,0,0,2,2,2,0
32,2,2,0,0,0,0,0,0,0,0,32,2,2,2,31
0,2,2,31,0,0,0,0,0,0,0,0,2,2,2,0
0,0,2,2,0,0,0,0,0,0,0,0,2,2,0,0
0,0,0,2,0,0,0,0,0,0,29,0,2,0,0,0
0,0,0,0,2,2,0,0,0,0,2,2,0,0,0,0
0,0,0,0,0,0,2,2,0,2,0,0,0,0,0,0
:endlayer
layer: 16
0,0,0,0,0,0,0,0,0,0,0,0,0,0,0,0
0,0,0,0,0,0,0,0,0,0,0,0,0,0,0,0
0,0,0,0,0,0,0,0,0,0,0,0,0,0,0,0
0,0,0,0,0,0,0,0,0,0,0,0,0,0,0,0
0,0,0,0,0,0,2,2,2,2,0,0,0,0,0,0
0,0,0,0,2,2,2,2,2,2,2,2,0,0,0,0
38,38,38,2,34,34,2,2,2,2,3,2,2,38,38,38
0,0,2,2,0,0,2,2,2,2,2,2,2,2,38,0
0,2,2,2,0,0,2,2,2,2,2,4,2,2,2,0
0,2,2,2,0,0,2,2,2,3,2,3,2,2,2,0
0,2,2,3,2,2,2,2,2,2,2,2,2,2,2,0
0,2,2,2,2,2,2,2,2,2,2,2,2,2,2,0
0,0,2,2,2,2,2,2,4,2,2,2,2,2,29,0
39,39,39,4,2,4,4,2,2,2,2,3,4,11,39,39
0,0,0,0,2,2,2,3,2,2,2,2,0,0,0,0
0,0,0,0,0,0,2,2,2,2,0,0,0,0,0,0
:endlayer
layer: 17
0,0,0,0,0,0,0,0,0,0,0,0,0,0,0,0
0,0,0,0,0,0,0,0,0,0,0,0,0,0,0,0
0,0,0,0,0,0,0,0,0,0,0,0,0,0,0,0
0,0,0,0,0,0,0,0,0,0,0,0,0,0,0,0
0,0,0,0,0,0,2,2,2,2,0,0,0,0,0,0
0,0,0,0,2,2,2,0,0,0,2,2,0,0,0,0
0,0,0,2,0,0,0,0,0,0,0,0,2,0,0,0
17,17,2,2,0,0,0,0,0,0,0,0,2,2,0,17
40,2,2,0,0,0,2,0,0,0,0,0,2,2,2,40
40,2,2,0,0,0,2,0,0,0,0,0,2,2,2,40
40,2,2,0,0,0,34,0,0,0,0,0,2,2,2,40
40,2,2,0,0,0,0,0,0,0,0,0,2,2,2,40
39,39,2,2,0,0,0,0,0,0,0,0,2,2,39,39
0,0,0,2,0,0,0,0,0,0,0,0,2,0,0,0
0,0,0,0,2,2,0,0,0,0,2,2,0,0,0,0
0,0,0,0,0,0,2,2,3,2,0,0,0,0,0,0
:endlayer
layer: 18
0,0,0,0,0,0,0,0,0,0,0,0,0,0,0,0
0,0,0,0,0,0,0,0,0,0,0,0,0,0,0,0
0,0,0,0,0,0,0,0,0,0,0,0,0,0,0,0
0,0,0,0,0,0,0,0,0,0,0,0,0,0,0,0
0,0,0,0,0,0,2,2,2,2,0,0,0,0,0,0
0,0,0,0,2,2,2,0,0,0,2,2,0,0,0,0
0,0,0,2,0,0,0,0,0,0,0,0,2,0,0,0
0,0,2,2,0,0,0,0,0,0,0,0,2,2,0,0
17,2,2,0,0,0,2,0,0,0,0,0,2,2,2,17
40,2,2,0,0,0,34,0,0,0,0,0,2,2,2,40
40,2,2,0,0,0,0,0,0,0,0,0,2,2,2,40
39,2,2,0,0,0,0,0,0,0,0,0,2,2,2,39
0,0,2,2,0,0,0,0,0,0,0,0,2,2,0,0
0,0,0,2,0,0,0,0,0,0,0,0,2,0,0,0
0,0,0,0,2,2,0,0,0,0,2,2,0,0,0,0
0,0,0,0,0,0,4,2,0,2,0,0,0,0,0,0
:endlayer
layer: 19
0,0,0,0,0,0,0,0,0,0,0,0,0,0,0,0
0,0,0,0,0,0,0,0,0,0,0,0,0,0,0,0
0,0,0,0,0,0,0,0,0,0,0,0,0,0,0,0
0,0,0,0,0,0,0,0,0,0,0,0,0,0,0,0
0,0,0,0,0,0,2,4,2,2,0,0,0,0,0,0
0,0,0,0,2,2,2,0,0,32,2,2,0,0,0,0
0,0,0,2,0,0,0,0,0,0,23,0,3,0,0,0
0,0,2,2,31,0,0,0,0,0,0,0,2,2,0,0
0,2,2,0,0,0,34,0,0,0,0,0,2,2,2,0
32,2,2,0,0,0,0,0,0,0,0,0,2,2,2,0
0,2,2,0,0,0,0,0,0,0,0,0,2,2,2,0
0,2,2,31,0,0,0,0,0,0,0,0,2,2,2,0
0,0,2,2,0,0,0,0,0,0,0,0,2,2,0,0
0,0,0,2,0,0,0,0,0,0,29,0,2,0,0,0
0,0,0,0,2,2,0,0,0,0,2,2,0,0,0,0
0,0,0,0,0,0,2,2,0,2,0,0,0,0,0,0
:endlayer
layer: 20
0,0,0,0,0,0,0,0,0,0,0,0,0,0,0,0
0,0,0,0,0,0,0,0,0,0,0,0,0,0,0,0
0,0,0,0,0,0,0,0,0,0,0,0,0,0,0,0
0,0,0,0,0,0,0,0,0,0,0,0,0,0,0,0
0,0,0,0,0,0,2,2,2,4,0,0,0,0,0,0
0,0,0,0,2,2,2,2,2,2,2,2,0,0,0,0
0,0,0,2,2,4,2,2,2,2,3,2,4,0,0,0
0,0,2,2,2,2,34,2,2,2,2,2,2,2,0,0
0,2,2,2,2,2,0,2,2,2,2,2,2,2,2,0
0,3,3,2,2,2,0,2,2,2,2,2,2,2,3,0
0,2,2,2,2,2,0,2,2,2,2,2,2,2,2,0
0,2,2,2,2,2,2,2,2,2,2,2,2,2,2,0
0,0,2,2,2,2,3,2,2,2,3,2,2,2,0,0
0,0,0,2,2,2,2,2,2,3,2,2,2,0,0,0
0,0,0,0,4,2,2,2,2,2,2,2,0,0,0,0
0,0,0,0,0,0,2,2,2,2,0,0,0,0,0,0
:endlayer
layer: 21
0,0,0,0,0,0,0,0,0,0,0,0,0,0,0,0
0,0,0,0,0,0,0,0,0,0,0,0,0,0,0,0
0,0,0,0,0,0,0,0,0,0,0,0,0,0,0,0
0,0,0,0,0,0,0,0,0,0,0,0,0,0,0,0
0,0,0,0,0,0,2,2,2,2,0,0,0,0,0,0
0,0,0,0,2,2,0,0,0,0,2,2,0,0,0,0
0,0,0,2,0,0,0,0,0,0,0,0,2,0,0,0
0,0,2,2,0,0,0,0,0,0,0,0,2,2,0,0
0,2,2,0,0,0,0,2,0,0,0,0,2,2,2,0
0,2,2,0,0,0,0,2,0,0,0,0,2,2,2,0
0,2,2,0,0,0,0,34,0,0,0,0,2,2,2,0
0,2,2,0,0,0,0,0,0,0,0,0,2,2,2,0
0,0,2,2,0,0,0,0,0,0,0,0,2,2,0,0
0,0,0,2,0,0,0,0,0,0,0,0,2,0,0,0
0,0,0,0,4,2,0,0,0,0,2,2,0,0,0,0
0,0,0,0,0,0,2,2,2,3,0,0,0,0,0,0
:endlayer
layer: 22
0,0,0,0,0,0,0,0,0,0,0,0,0,0,0,0
0,0,0,0,0,0,0,0,0,0,0,0,0,0,0,0
0,0,0,0,0,0,0,0,0,0,0,0,0,0,0,0
0,0,0,0,0,0,0,0,0,0,0,0,0,0,0,0
0,0,0,0,0,0,2,2,0,2,0,0,0,0,0,0
0,0,0,0,2,2,0,0,0,0,2,2,0,0,0,0
0,0,0,2,0,0,0,0,0,0,0,0,2,0,0,0
0,0,2,2,0,0,0,0,0,0,0,0,2,2,0,0
0,2,2,0,0,0,0,2,0,0,0,0,2,2,2,0
0,2,2,0,0,0,0,34,0,0,0,0,2,2,2,0
0,0,0,0,0,0,0,0,0,0,0,0,2,2,0,0
0,2,2,0,0,0,0,0,0,0,0,0,2,2,2,0
0,0,2,2,0,0,0,0,0,0,0,0,2,2,0,0
0,0,0,2,0,0,0,0,0,0,0,0,2,0,0,0
0,0,0,0,2,2,0,0,0,0,2,2,0,0,0,0
0,0,0,0,0,0,2,2,0,2,0,0,0,0,0,0
:endlayer
layer: 23
0,0,0,0,0,0,0,0,0,0,0,0,0,0,0,0
0,0,0,0,0,0,0,0,0,0,0,0,0,0,0,0
0,0,0,0,0,0,0,0,0,0,0,0,0,0,0,0
0,0,0,0,0,0,0,0,0,0,0,0,0,0,0,0
0,0,0,0,0,0,2,2,0,2,0,0,0,0,0,0
0,0,0,0,2,2,0,23,0,0,2,2,0,0,0,0
0,0,0,2,0,0,0,0,0,0,23,0,2,0,0,0
0,0,2,2,0,0,0,0,0,0,0,0,2,2,0,0
0,2,2,0,0,0,0,34,0,0,0,0,2,2,2,0
0,2,2,0,0,0,0,0,0,0,0,0,2,2,2,0
0,0,0,0,0,0,0,0,0,0,0,0,2,2,0,0
0,3,3,31,0,0,0,0,0,0,0,0,2,2,3,0
0,0,2,4,0,0,0,0,0,0,0,0,2,2,0,0
0,0,0,2,0,29,0,0,0,0,29,0,2,0,0,0
0,0,0,0,2,4,0,0,0,0,2,4,0,0,0,0
0,0,0,0,0,0,2,2,0,4,0,0,0,0,0,0
:endlayer
layer: 24
0,0,0,0,0,0,0,0,0,0,0,0,0,0,0,0
0,0,0,0,0,0,0,0,0,0,0,0,0,0,0,0
0,0,0,0,0,0,0,0,0,0,0,0,0,0,0,0
0,0,0,0,0,0,0,0,0,0,0,0,0,0,0,0
0,0,0,0,0,0,2,2,2,2,0,0,0,0,0,0
0,0,0,0,4,2,2,2,2,2,2,2,0,0,0,0
0,0,0,2,4,2,2,2,2,2,2,2,2,0,0,0
0,0,2,2,2,2,2,34,2,2,2,2,2,2,0,0
0,2,2,2,2,2,4,0,2,2,2,3,2,2,2,0
0,2,2,2,2,2,3,0,2,2,2,2,2,2,2,0
0,2,2,2,2,2,3,0,2,2,2,2,2,2,2,0
0,4,4,2,2,2,2,2,2,2,2,2,2,2,4,0
0,0,2,2,2,2,2,2,2,2,2,2,2,2,0,0
0,0,0,2,3,4,2,2,2,2,2,2,2,0,0,0
0,0,0,0,2,2,2,2,2,4,2,2,0,0,0,0
0,0,0,0,0,0,2,2,2,2,0,0,0,0,0,0
:endlayer
layer: 25
0,0,0,0,0,0,0,0,0,0,0,0,0,0,0,0
0,0,0,0,0,0,0,0,0,0,0,0,0,0,0,0
0,0,0,0,0,0,0,0,0,0,0,0,0,0,0,0
0,0,0,0,0,0,0,0,0,0,0,0,0,0,0,0
0,0,0,0,0,0,2,2,2,2,0,0,0,0,0,0
0,0,0,0,2,2,0,0,0,0,2,2,0,0,0,0
0,0,0,2,0,0,0,0,0,0,0,0,2,0,0,0
0,0,2,2,0,0,0,0,0,0,0,0,2,2,0,0
0,2,0,0,0,0,0,0,0,0,0,0,0,0,2,0
0,2,0,0,0,0,0,0,0,0,0,0,0,0,2,0
0,4,0,0,0,0,0,0,0,0,0,0,0,0,4,0
0,2,2,0,0,0,0,0,0,0,0,0,0,0,2,0
0,0,2,0,0,0,0,0,0,0,0,0,0,2,0,0
0,0,0,2,0,0,0,0,0,0,0,0,2,0,0,0
0,0,0,0,2,2,0,0,0,0,2,2,0,0,0,0
0,0,0,0,0,0,2,2,2,2,0,0,0,0,0,0
:endlayer
layer: 26
0,0,0,0,0,0,0,0,0,0,0,0,0,0,0,0
0,0,0,0,0,0,0,0,0,0,0,0,0,0,0,0
0,0,0,0,0,0,0,0,0,0,0,0,0,0,0,0
0,0,0,0,0,0,0,0,0,0,0,0,0,0,0,0
0,0,0,0,0,0,0,2,0,2,0,0,0,0,0,0
0,0,0,0,0,2,0,0,0,0,0,2,0,0,0,0
0,0,0,2,0,0,0,0,0,0,0,0,0,0,0,0
0,0,0,0,0,0,0,0,0,0,0,0,0,2,0,0
0,2,0,0,0,0,0,0,0,0,0,0,0,0,0,0
0,0,0,0,0,0,0,0,0,0,0,0,0,0,2,0
0,2,0,0,0,0,0,0,0,0,0,0,0,0,0,0
0,0,0,0,0,0,0,0,0,0,0,0,0,0,2,0
0,0,2,0,0,0,0,0,0,0,0,0,0,0,0,0
0,0,0,0,0,0,0,0,0,0,0,0,2,0,0,0
0,0,0,0,2,0,0,0,0,0,2,0,0,0,0,0
0,0,0,0,0,0,2,0,2,0,0,0,0,0,0,0
:endlayer
layer: 27
0,0,0,0,0,0,0,0,0,0,0,0,0,0,0,0
0,0,0,0,0,0,0,0,0,0,0,0,0,0,0,0
0,0,0,0,0,0,0,0,0,0,0,0,0,0,0,0
0,0,0,0,0,0,0,0,0,0,0,0,0,0,0,0
0,0,0,0,0,0,0,0,0,0,0,0,0,0,0,0
0,0,0,0,0,41,0,0,0,0,0,41,0,0,0,0
0,0,0,0,0,0,0,0,0,0,0,0,0,0,0,0
0,0,0,0,0,0,0,0,0,0,0,0,0,0,0,0
0,0,0,0,0,0,0,0,0,0,0,0,0,0,0,0
0,0,0,0,0,0,0,0,0,0,0,0,0,0,0,0
0,41,0,0,0,0,0,0,0,0,0,0,0,0,0,0
0,0,0,0,0,0,0,0,0,0,0,0,0,0,41,0
0,0,0,0,0,0,0,0,0,0,0,0,0,0,0,0
0,0,0,0,0,0,0,0,0,0,0,0,0,0,0,0
0,0,0,0,41,0,0,0,0,0,41,0,0,0,0,0
0,0,0,0,0,0,0,0,0,0,0,0,0,0,0,0
:endlayer

#### RULES ####
rule:
plugin=vanillaBlocks
number=1
data:
JSON:{{"val":{"blockName":{"val":"minecraft:cobblestone","id":"ss"},"meta":{"val":"0","id":"pi"},"buildPass":{"val":"0","id":"pi"}},"id":"ct"}}
:enddata
:endrule

rule:
plugin=vanillaBlocks
number=2
data:
JSON:{{"val":{"blockName":{"val":"minecraft:stonebrick","id":"ss"},"meta":{"val":"0","id":"pi"},"buildPass":{"val":"0","id":"pi"}},"id":"ct"}}
:enddata
:endrule

rule:
plugin=vanillaBlocks
number=3
data:
JSON:{{"val":{"blockName":{"val":"minecraft:stonebrick","id":"ss"},"meta":{"val":"2","id":"pi"},"buildPass":{"val":"0","id":"pi"}},"id":"ct"}}
:enddata
:endrule

rule:
plugin=vanillaBlocks
number=4
data:
JSON:{{"val":{"blockName":{"val":"minecraft:stonebrick","id":"ss"},"meta":{"val":"1","id":"pi"},"buildPass":{"val":"0","id":"pi"}},"id":"ct"}}
:enddata
:endrule

rule:
plugin=vanillaBlocks
number=5
data:
JSON:{{"val":{"blockName":{"val":"minecraft:dirt","id":"ss"},"meta":{"val":"0","id":"pi"},"buildPass":{"val":"0","id":"pi"}},"id":"ct"}}
:enddata
:endrule

rule:
plugin=vanillaBlocks
number=6
data:
JSON:{{"val":{"blockName":{"val":"minecraft:gravel","id":"ss"},"meta":{"val":"0","id":"pi"},"buildPass":{"val":"0","id":"pi"}},"id":"ct"}}
:enddata
:endrule

rule:
plugin=vanillaBlocks
number=7
data:
JSON:{{"val":{"blockName":{"val":"minecraft:grass","id":"ss"},"meta":{"val":"0","id":"pi"},"buildPass":{"val":"0","id":"pi"}},"id":"ct"}}
:enddata
:endrule

rule:
plugin=vanillaBlocks
number=8
data:
JSON:{{"val":{"blockName":{"val":"minecraft:tallgrass","id":"ss"},"meta":{"val":"1","id":"pi"},"buildPass":{"val":"2","id":"pi"}},"id":"ct"}}
:enddata
:endrule

rule:
plugin=vanillaDoors
number=9
data:
JSON:{{"val":{"sideFlag":{"val":"8","id":"pb"},"blockName":{"val":"minecraft:iron_door","id":"ss"},"meta":{"val":"0","id":"pi"},"buildPass":{"val":"2","id":"pi"}},"id":"ct"}}
:enddata
:endrule

rule:
plugin=awAutomationLogic
number=10
data:
JSON:{{"val":{"teData":{"val":{"id":{"val":"Furnace","id":"ss"},"Items":{"val":[],"id":"ls"},"BurnTime":{"val":"0","id":"ps"},"z":{"val":"-1205","id":"pi"},"y":{"val":"20","id":"pi"},"CookTime":{"val":"0","id":"ps"},"x":{"val":"-260","id":"pi"}},"id":"ct"},"blockName":{"val":"minecraft:furnace","id":"ss"},"meta":{"val":"4","id":"pi"},"buildPass":{"val":"0","id":"pi"}},"id":"ct"}}
:enddata
:endrule

rule:
plugin=vanillaBlocks
number=11
data:
JSON:{{"val":{"blockName":{"val":"minecraft:wooden_slab","id":"ss"},"meta":{"val":"0","id":"pi"},"buildPass":{"val":"0","id":"pi"}},"id":"ct"}}
:enddata
:endrule

rule:
plugin=vanillaInventory
number=12
data:
JSON:{{"val":{"lootLevel":{"val":"0","id":"pi"},"inventoryData":{"val":{"length":{"val":"27","id":"pi"},"inventoryContents":{"val":[],"id":"ls"}},"id":"ct"},"teData":{"val":{"id":{"val":"Chest","id":"ss"},"z":{"val":"-1205","id":"pi"},"y":{"val":"20","id":"pi"},"x":{"val":"-254","id":"pi"}},"id":"ct"},"blockName":{"val":"minecraft:chest","id":"ss"},"meta":{"val":"2","id":"pi"},"buildPass":{"val":"0","id":"pi"}},"id":"ct"}}
:enddata
:endrule

rule:
plugin=vanillaBlocks
number=13
data:
JSON:{{"val":{"blockName":{"val":"minecraft:oak_stairs","id":"ss"},"meta":{"val":"0","id":"pi"},"buildPass":{"val":"0","id":"pi"}},"id":"ct"}}
:enddata
:endrule

rule:
plugin=vanillaInventory
number=14
data:
JSON:{{"val":{"lootLevel":{"val":"0","id":"pi"},"inventoryData":{"val":{"length":{"val":"27","id":"pi"},"inventoryContents":{"val":[],"id":"ls"}},"id":"ct"},"teData":{"val":{"id":{"val":"Chest","id":"ss"},"z":{"val":"-1203","id":"pi"},"y":{"val":"20","id":"pi"},"x":{"val":"-252","id":"pi"}},"id":"ct"},"blockName":{"val":"minecraft:chest","id":"ss"},"meta":{"val":"2","id":"pi"},"buildPass":{"val":"0","id":"pi"}},"id":"ct"}}
:enddata
:endrule

rule:
plugin=vanillaDoors
number=15
data:
JSON:{{"val":{"sideFlag":{"val":"8","id":"pb"},"blockName":{"val":"minecraft:wooden_door","id":"ss"},"meta":{"val":"1","id":"pi"},"buildPass":{"val":"2","id":"pi"}},"id":"ct"}}
:enddata
:endrule

rule:
plugin=vanillaBlocks
number=16
data:
JSON:{{"val":{"blockName":{"val":"minecraft:fence","id":"ss"},"meta":{"val":"0","id":"pi"},"buildPass":{"val":"0","id":"pi"}},"id":"ct"}}
:enddata
:endrule

rule:
plugin=vanillaBlocks
number=17
data:
JSON:{{"val":{"blockName":{"val":"minecraft:oak_stairs","id":"ss"},"meta":{"val":"2","id":"pi"},"buildPass":{"val":"0","id":"pi"}},"id":"ct"}}
:enddata
:endrule

rule:
plugin=vanillaBlocks
number=18
data:
JSON:{{"val":{"blockName":{"val":"minecraft:oak_stairs","id":"ss"},"meta":{"val":"1","id":"pi"},"buildPass":{"val":"0","id":"pi"}},"id":"ct"}}
:enddata
:endrule

rule:
plugin=vanillaInventory
number=19
data:
JSON:{{"val":{"lootLevel":{"val":"0","id":"pi"},"inventoryData":{"val":{"length":{"val":"27","id":"pi"},"inventoryContents":{"val":[],"id":"ls"}},"id":"ct"},"teData":{"val":{"id":{"val":"Chest","id":"ss"},"z":{"val":"-1201","id":"pi"},"y":{"val":"20","id":"pi"},"x":{"val":"-252","id":"pi"}},"id":"ct"},"blockName":{"val":"minecraft:chest","id":"ss"},"meta":{"val":"2","id":"pi"},"buildPass":{"val":"0","id":"pi"}},"id":"ct"}}
:enddata
:endrule

rule:
plugin=vanillaInventory
number=20
data:
JSON:{{"val":{"lootLevel":{"val":"0","id":"pi"},"inventoryData":{"val":{"length":{"val":"27","id":"pi"},"inventoryContents":{"val":[],"id":"ls"}},"id":"ct"},"teData":{"val":{"id":{"val":"Chest","id":"ss"},"z":{"val":"-1199","id":"pi"},"y":{"val":"20","id":"pi"},"x":{"val":"-253","id":"pi"}},"id":"ct"},"blockName":{"val":"minecraft:chest","id":"ss"},"meta":{"val":"2","id":"pi"},"buildPass":{"val":"0","id":"pi"}},"id":"ct"}}
:enddata
:endrule

rule:
plugin=vanillaInventory
number=21
data:
JSON:{{"val":{"lootLevel":{"val":"0","id":"pi"},"inventoryData":{"val":{"length":{"val":"27","id":"pi"},"inventoryContents":{"val":[],"id":"ls"}},"id":"ct"},"teData":{"val":{"id":{"val":"Chest","id":"ss"},"z":{"val":"-1197","id":"pi"},"y":{"val":"20","id":"pi"},"x":{"val":"-255","id":"pi"}},"id":"ct"},"blockName":{"val":"minecraft:chest","id":"ss"},"meta":{"val":"5","id":"pi"},"buildPass":{"val":"0","id":"pi"}},"id":"ct"}}
:enddata
:endrule

rule:
plugin=vanillaDoors
number=22
data:
JSON:{{"val":{"sideFlag":{"val":"8","id":"pb"},"blockName":{"val":"minecraft:iron_door","id":"ss"},"meta":{"val":"2","id":"pi"},"buildPass":{"val":"2","id":"pi"}},"id":"ct"}}
:enddata
:endrule

rule:
plugin=vanillaBlocks
number=23
data:
JSON:{{"val":{"blockName":{"val":"minecraft:torch","id":"ss"},"meta":{"val":"3","id":"pi"},"buildPass":{"val":"2","id":"pi"}},"id":"ct"}}
:enddata
:endrule

rule:
plugin=vanillaDoors
number=24
data:
JSON:{{"val":{"sideFlag":{"val":"0","id":"pb"},"blockName":{"val":"minecraft:iron_door","id":"ss"},"meta":{"val":"8","id":"pi"},"buildPass":{"val":"2","id":"pi"}},"id":"ct"}}
:enddata
:endrule

rule:
plugin=vanillaDoors
number=25
data:
JSON:{{"val":{"sideFlag":{"val":"0","id":"pb"},"blockName":{"val":"minecraft:wooden_door","id":"ss"},"meta":{"val":"8","id":"pi"},"buildPass":{"val":"2","id":"pi"}},"id":"ct"}}
:enddata
:endrule

rule:
plugin=vanillaBlocks
number=26
data:
JSON:{{"val":{"blockName":{"val":"minecraft:carpet","id":"ss"},"meta":{"val":"12","id":"pi"},"buildPass":{"val":"2","id":"pi"}},"id":"ct"}}
:enddata
:endrule

rule:
plugin=vanillaDoors
number=27
data:
JSON:{{"val":{"sideFlag":{"val":"0","id":"pb"},"blockName":{"val":"minecraft:iron_door","id":"ss"},"meta":{"val":"8","id":"pi"},"buildPass":{"val":"2","id":"pi"}},"id":"ct"}}
:enddata
:endrule

rule:
plugin=vanillaBlocks
number=28
data:
JSON:{{"val":{"blockName":{"val":"minecraft:lever","id":"ss"},"meta":{"val":"2","id":"pi"},"buildPass":{"val":"2","id":"pi"}},"id":"ct"}}
:enddata
:endrule

rule:
plugin=vanillaBlocks
number=29
data:
JSON:{{"val":{"blockName":{"val":"minecraft:torch","id":"ss"},"meta":{"val":"4","id":"pi"},"buildPass":{"val":"2","id":"pi"}},"id":"ct"}}
:enddata
:endrule

rule:
plugin=vanillaBlocks
number=30
data:
JSON:{{"val":{"blockName":{"val":"minecraft:lever","id":"ss"},"meta":{"val":"1","id":"pi"},"buildPass":{"val":"2","id":"pi"}},"id":"ct"}}
:enddata
:endrule

rule:
plugin=vanillaBlocks
number=31
data:
JSON:{{"val":{"blockName":{"val":"minecraft:torch","id":"ss"},"meta":{"val":"1","id":"pi"},"buildPass":{"val":"2","id":"pi"}},"id":"ct"}}
:enddata
:endrule

rule:
plugin=vanillaBlocks
number=32
data:
JSON:{{"val":{"blockName":{"val":"minecraft:torch","id":"ss"},"meta":{"val":"2","id":"pi"},"buildPass":{"val":"2","id":"pi"}},"id":"ct"}}
:enddata
:endrule

rule:
plugin=vanillaBlocks
number=33
data:
JSON:{{"val":{"blockName":{"val":"minecraft:ladder","id":"ss"},"meta":{"val":"3","id":"pi"},"buildPass":{"val":"2","id":"pi"}},"id":"ct"}}
:enddata
:endrule

rule:
plugin=vanillaBlocks
number=34
data:
JSON:{{"val":{"blockName":{"val":"minecraft:stone_brick_stairs","id":"ss"},"meta":{"val":"3","id":"pi"},"buildPass":{"val":"0","id":"pi"}},"id":"ct"}}
:enddata
:endrule

rule:
plugin=vanillaBlocks
number=35
data:
JSON:{{"val":{"blockName":{"val":"minecraft:stone_brick_stairs","id":"ss"},"meta":{"val":"7","id":"pi"},"buildPass":{"val":"0","id":"pi"}},"id":"ct"}}
:enddata
:endrule

rule:
plugin=vanillaBlocks
number=36
data:
JSON:{{"val":{"blockName":{"val":"minecraft:stone_slab","id":"ss"},"meta":{"val":"5","id":"pi"},"buildPass":{"val":"0","id":"pi"}},"id":"ct"}}
:enddata
:endrule

rule:
plugin=vanillaBlocks
number=37
data:
JSON:{{"val":{"blockName":{"val":"minecraft:stone_brick_stairs","id":"ss"},"meta":{"val":"0","id":"pi"},"buildPass":{"val":"0","id":"pi"}},"id":"ct"}}
:enddata
:endrule

rule:
plugin=vanillaBlocks
number=38
data:
JSON:{{"val":{"blockName":{"val":"minecraft:wooden_slab","id":"ss"},"meta":{"val":"8","id":"pi"},"buildPass":{"val":"0","id":"pi"}},"id":"ct"}}
:enddata
:endrule

rule:
plugin=vanillaBlocks
number=39
data:
JSON:{{"val":{"blockName":{"val":"minecraft:oak_stairs","id":"ss"},"meta":{"val":"3","id":"pi"},"buildPass":{"val":"0","id":"pi"}},"id":"ct"}}
:enddata
:endrule

rule:
plugin=vanillaBlocks
number=40
data:
JSON:{{"val":{"blockName":{"val":"minecraft:planks","id":"ss"},"meta":{"val":"0","id":"pi"},"buildPass":{"val":"0","id":"pi"}},"id":"ct"}}
:enddata
:endrule

rule:
plugin=vanillaBlocks
number=41
data:
JSON:{{"val":{"blockName":{"val":"minecraft:torch","id":"ss"},"meta":{"val":"5","id":"pi"},"buildPass":{"val":"2","id":"pi"}},"id":"ct"}}
:enddata
:endrule

#### ENTITIES ####
