# Ancient Warfare Structure Template File
# Auto-generated structure template file. created on: 12/25/2018 at: 22:43:41
# Lines beginning with # denote comments

header:
version=2.8
name=RuinGenericSmall8
mods=
size=10,14,16
offset=4,9,15
:endheader

#### VALIDATION ####
validation:
type=ground
survival=false
worldGenEnabled=true
unique=false
preserveBlocks=false
selectionWeight=30
clusterValue=10
minDuplicateDistance=900
dimensionWhiteList=true
dimensionList=0
biomeWhiteList=true
biomeList=biomesoplenty:shrubland,minecraft:mutated_roofed_forest,biomesoplenty:dead_forest,biomesoplenty:wasteland,minecraft:extreme_hills,biomesoplenty:ominous_woods,biomesoplenty:steppe
leveling=6
fill=6
border=6
blockSwap=true
:endvalidation

#### LAYERS ####
layer: 0
1,1,1,1,1,1,1,1,1,1
1,1,1,1,1,1,1,1,1,1
1,1,1,1,1,1,1,1,1,1
1,1,1,1,1,1,1,1,1,1
1,1,1,1,1,1,1,1,1,1
1,1,1,1,1,1,1,1,1,1
1,1,1,1,1,1,1,1,1,1
1,1,1,1,1,1,1,1,1,1
1,1,1,1,1,1,1,1,1,1
1,1,1,1,1,1,1,1,1,1
1,1,1,1,1,1,1,1,1,1
1,1,1,1,1,1,1,1,1,1
1,1,1,1,1,1,1,1,1,1
1,1,1,1,1,1,1,1,1,1
1,1,1,1,1,1,1,1,1,1
1,1,1,1,1,1,1,1,1,1
:endlayer
layer: 1
1,1,1,1,1,1,1,1,1,1
1,1,1,1,1,1,1,1,1,1
1,1,1,1,1,1,1,1,1,1
1,1,1,1,1,1,1,1,1,1
1,1,1,1,1,1,1,1,1,1
1,1,1,1,1,1,1,1,1,1
1,1,1,1,1,1,1,1,1,1
1,1,1,1,1,1,1,1,1,1
1,1,1,1,1,1,1,1,1,1
1,1,1,1,1,1,1,1,1,1
1,1,1,1,1,1,1,1,1,1
1,1,1,1,1,1,1,1,1,1
1,1,1,1,1,1,1,1,1,1
1,1,1,1,1,1,1,1,1,1
1,1,1,1,1,1,1,1,1,1
1,1,1,1,1,1,1,1,1,1
:endlayer
layer: 2
1,1,1,1,1,1,1,1,1,1
1,1,1,1,1,1,1,1,1,1
1,1,1,1,1,1,1,1,1,1
1,1,1,1,1,1,1,1,1,1
1,1,1,1,1,1,1,1,1,1
1,1,1,1,1,1,1,1,1,1
1,1,1,1,1,1,1,1,1,1
1,1,1,1,1,1,1,1,1,1
1,1,1,1,1,1,1,1,1,1
1,1,1,1,1,1,1,1,1,1
1,1,1,1,1,1,1,1,1,1
1,1,1,1,1,1,1,1,1,1
1,1,1,1,1,1,1,1,1,1
1,1,1,1,1,1,1,1,1,1
1,1,1,1,1,1,1,1,1,1
1,1,1,1,1,1,1,1,1,1
:endlayer
layer: 3
1,1,1,1,1,1,1,1,1,1
1,1,1,1,1,1,1,1,1,1
1,1,1,1,1,1,1,1,1,1
1,1,1,1,1,1,1,1,1,1
1,1,1,1,1,1,1,1,1,1
1,1,1,1,1,1,1,1,1,1
1,1,1,1,1,1,1,1,1,1
1,1,1,1,1,1,1,1,1,1
1,1,1,1,1,1,1,1,1,1
1,1,1,1,1,1,1,1,1,1
1,1,1,1,1,1,1,1,1,1
1,1,1,1,1,1,1,1,1,1
1,1,1,1,1,1,1,1,1,1
1,1,1,1,1,1,1,1,1,1
1,1,1,1,1,1,1,1,1,1
1,1,1,1,1,1,1,1,1,1
:endlayer
layer: 4
1,1,1,1,1,1,1,1,1,1
1,1,1,1,1,1,1,1,1,1
1,1,1,1,1,1,1,1,1,1
1,1,1,1,1,1,1,1,1,1
1,1,1,1,1,1,1,1,1,1
1,1,1,1,1,1,1,1,1,1
1,1,1,1,1,1,1,1,1,1
1,1,1,1,1,1,1,1,1,1
1,1,1,1,1,1,1,1,1,1
1,1,1,1,1,1,1,1,1,1
1,1,1,1,1,1,1,1,1,1
1,1,1,1,1,1,1,1,1,1
1,1,1,1,1,1,1,1,1,1
1,1,1,1,1,1,1,1,1,1
1,1,1,1,1,1,1,1,1,1
1,1,1,1,1,1,1,1,1,1
:endlayer
layer: 5
1,1,1,1,1,1,1,1,1,1
1,1,1,1,1,1,1,1,1,1
1,1,1,1,1,1,1,1,1,1
1,1,1,1,1,1,1,1,1,1
1,1,1,1,1,1,1,1,1,1
1,1,1,1,1,1,1,1,1,1
1,1,1,1,1,1,1,1,1,1
1,1,1,1,1,1,1,1,1,1
1,1,1,1,1,1,1,1,1,1
1,1,1,1,1,1,1,1,1,1
1,1,1,1,1,1,1,1,1,1
1,1,1,1,1,1,1,1,1,1
1,1,1,1,1,1,1,1,1,1
1,1,1,1,1,1,1,1,1,1
1,1,1,1,1,1,1,1,1,1
1,1,1,1,1,1,1,1,1,1
:endlayer
layer: 6
1,1,1,1,1,1,1,1,1,1
1,1,1,1,1,1,1,1,1,1
1,1,1,1,1,1,1,1,1,1
1,1,1,1,1,1,1,1,1,1
1,1,1,1,1,1,1,1,1,1
1,1,1,1,1,1,1,1,1,1
1,1,1,1,1,1,1,1,1,1
1,1,1,1,1,1,1,1,1,1
1,1,1,1,1,1,1,1,1,1
1,1,1,1,1,1,1,1,1,1
1,1,1,1,1,1,1,1,1,1
1,1,1,1,1,1,1,1,1,1
1,1,1,1,1,1,1,1,1,1
1,1,1,1,1,1,1,1,1,1
1,1,1,1,1,1,1,1,1,1
1,1,1,1,1,1,1,1,1,1
:endlayer
layer: 7
1,1,1,1,1,1,1,1,1,1
1,1,1,1,1,1,1,1,1,1
1,1,1,1,1,1,1,1,1,1
1,1,1,1,1,1,1,1,1,1
1,1,1,1,1,1,1,1,1,1
1,1,1,1,1,1,1,1,1,1
1,1,1,1,1,1,1,1,1,1
1,1,1,1,1,1,1,1,1,1
1,1,1,1,1,1,1,1,1,1
1,1,1,1,1,1,1,1,1,1
1,1,1,1,1,1,1,1,1,1
1,1,1,1,1,1,1,1,1,1
1,1,1,1,1,1,1,1,1,1
1,1,1,1,1,1,1,1,1,1
1,1,1,1,1,1,1,1,1,1
1,1,1,1,1,1,1,1,1,1
:endlayer
layer: 8
2,2,2,2,2,2,2,2,2,2
2,2,2,2,2,2,2,2,2,2
2,2,2,2,2,2,2,2,2,2
2,2,2,2,2,2,2,2,2,2
2,2,2,2,2,2,2,2,2,2
2,2,2,2,2,1,2,2,2,2
2,2,1,2,2,2,1,2,2,2
2,2,2,2,1,2,2,2,2,2
2,2,2,1,1,1,2,2,2,2
2,2,1,2,1,2,2,1,2,2
2,2,1,2,2,2,1,2,2,2
2,2,1,2,2,2,1,2,2,2
2,2,2,2,2,2,2,2,2,2
2,2,2,2,2,2,2,2,2,2
2,2,2,2,2,2,2,2,2,2
2,2,2,2,2,2,2,2,2,2
:endlayer
layer: 9
0,0,5,0,0,0,3,0,3,0
5,0,3,0,3,3,3,3,3,0
3,3,0,5,0,0,3,3,3,3
3,0,3,3,3,0,7,3,3,7
0,3,3,3,3,18,0,0,0,0
0,0,18,3,3,10,3,3,3,0
3,15,10,13,16,13,10,9,0,0
3,3,3,16,14,13,16,0,3,0
7,3,16,14,16,14,13,3,3,3
3,15,14,16,14,17,3,10,3,3
3,15,10,16,13,16,10,9,3,3
0,15,14,13,12,11,10,9,3,3
3,3,8,0,0,0,8,3,3,7
3,7,0,3,0,3,3,3,3,0
3,3,0,0,0,0,3,3,3,0
6,3,3,0,0,5,4,3,3,0
:endlayer
layer: 10
0,0,0,0,0,0,0,0,0,0
0,0,0,0,0,0,0,0,0,0
0,0,0,0,0,0,0,0,0,0
0,0,0,0,0,0,0,0,0,0
0,0,0,0,0,0,0,0,0,0
0,0,0,0,0,11,0,0,0,0
0,0,0,0,18,13,0,0,0,0
0,0,0,15,10,9,0,0,0,0
0,0,0,0,8,13,0,0,0,0
0,0,11,15,14,9,0,0,0,0
0,0,11,0,13,0,18,0,0,0
0,0,0,0,0,15,10,9,0,0
0,0,0,0,0,0,8,0,0,0
0,0,0,0,0,0,0,0,0,0
0,0,0,0,0,0,0,0,0,0
0,0,0,0,0,0,0,0,0,0
:endlayer
layer: 11
0,0,0,0,0,0,0,0,0,0
0,0,0,0,0,0,0,0,0,0
0,0,0,0,0,0,0,0,0,0
0,0,0,0,0,0,0,0,0,0
0,0,0,0,0,0,0,0,0,0
0,0,0,0,0,0,0,0,0,0
0,0,0,0,18,0,0,0,0,0
0,0,0,15,20,9,0,0,0,0
0,0,0,0,21,0,0,0,0,0
0,0,0,15,20,9,0,0,0,0
0,0,0,0,8,0,0,0,0,0
0,0,0,0,0,0,19,0,0,0
0,0,0,0,0,0,0,0,0,0
0,0,0,0,0,0,0,0,0,0
0,0,0,0,0,0,0,0,0,0
0,0,0,0,0,0,0,0,0,0
:endlayer
layer: 12
0,0,0,0,0,0,0,0,0,0
0,0,0,0,0,0,0,0,0,0
0,0,0,0,0,0,0,0,0,0
0,0,0,0,0,0,0,0,0,0
0,0,0,0,0,0,0,0,0,0
0,0,0,0,0,0,0,0,0,0
0,0,0,0,18,0,0,0,0,0
0,0,0,15,14,9,0,0,0,0
0,0,0,0,21,0,0,0,0,0
0,0,0,15,14,9,0,0,0,0
0,0,0,0,8,0,0,0,0,0
0,0,0,0,0,0,0,0,0,0
0,0,0,0,0,0,0,0,0,0
0,0,0,0,0,0,0,0,0,0
0,0,0,0,0,0,0,0,0,0
0,0,0,0,0,0,0,0,0,0
:endlayer
layer: 13
0,0,0,0,0,0,0,0,0,0
0,0,0,0,0,0,0,0,0,0
0,0,0,0,0,0,0,0,0,0
0,0,0,0,0,0,0,0,0,0
0,0,0,0,0,0,0,0,0,0
0,0,0,0,0,0,0,0,0,0
0,0,0,0,0,0,0,0,0,0
0,0,0,0,21,0,0,0,0,0
0,0,0,0,20,0,0,0,0,0
0,0,0,0,21,0,0,0,0,0
0,0,0,0,0,0,0,0,0,0
0,0,0,0,0,0,0,0,0,0
0,0,0,0,0,0,0,0,0,0
0,0,0,0,0,0,0,0,0,0
0,0,0,0,0,0,0,0,0,0
0,0,0,0,0,0,0,0,0,0
:endlayer

#### RULES ####
rule:
plugin=vanillaBlocks
number=1
data:
JSON:{blockState:{blockName:"minecraft:dirt",properties:{variant:"dirt",snowy:"false"}}}
:enddata
:endrule

rule:
plugin=vanillaBlocks
number=2
data:
JSON:{blockState:{blockName:"minecraft:grass",properties:{snowy:"false"}}}
:enddata
:endrule

rule:
plugin=vanillaBlocks
number=3
data:
JSON:{blockState:{blockName:"minecraft:tallgrass",properties:{type:"tall_grass"}}}
:enddata
:endrule

rule:
plugin=vanillaBlocks
number=4
data:
JSON:{blockState:{blockName:"minecraft:red_flower",properties:{type:"white_tulip"}}}
:enddata
:endrule

rule:
plugin=vanillaBlocks
number=5
data:
JSON:{blockState:{blockName:"minecraft:yellow_flower",properties:{type:"dandelion"}}}
:enddata
:endrule

rule:
plugin=vanillaBlocks
number=6
data:
JSON:{blockState:{blockName:"minecraft:red_flower",properties:{type:"poppy"}}}
:enddata
:endrule

rule:
plugin=vanillaBlocks
number=7
data:
JSON:{blockState:{blockName:"minecraft:red_flower",properties:{type:"houstonia"}}}
:enddata
:endrule

rule:
plugin=vine
number=8
data:
JSON:{blockState:{blockName:"minecraft:vine",properties:{east:"false",south:"false",north:"true",west:"false",up:"false"}}}
:enddata
:endrule

rule:
plugin=vine
number=9
data:
JSON:{blockState:{blockName:"minecraft:vine",properties:{east:"false",south:"false",north:"false",west:"true",up:"false"}}}
:enddata
:endrule

rule:
plugin=vanillaBlocks
number=10
data:
JSON:{blockState:{blockName:"minecraft:stonebrick",properties:{variant:"cracked_stonebrick"}}}
:enddata
:endrule

rule:
plugin=vanillaBlocks
number=11
data:
JSON:{blockState:{blockName:"minecraft:wooden_slab",properties:{half:"bottom",variant:"spruce"}}}
:enddata
:endrule

rule:
plugin=vanillaBlocks
number=12
data:
JSON:{blockState:{blockName:"minecraft:tallgrass",properties:{type:"fern"}}}
:enddata
:endrule

rule:
plugin=vanillaBlocks
number=13
data:
JSON:{blockState:{blockName:"minecraft:leaves",properties:{check_decay:"false",decayable:"false",variant:"oak"}}}
:enddata
:endrule

rule:
plugin=vanillaBlocks
number=14
data:
JSON:{blockState:{blockName:"minecraft:stonebrick",properties:{variant:"mossy_stonebrick"}}}
:enddata
:endrule

rule:
plugin=vine
number=15
data:
JSON:{blockState:{blockName:"minecraft:vine",properties:{east:"true",south:"false",north:"false",west:"false",up:"false"}}}
:enddata
:endrule

rule:
plugin=vanillaBlocks
number=16
data:
JSON:{blockState:{blockName:"minecraft:stone_slab",properties:{half:"bottom",variant:"cobblestone"}}}
:enddata
:endrule

rule:
plugin=vanillaSkull
number=17
data:
JSON:{blockState:{blockName:"minecraft:skull",properties:{nodrop:"false",facing:"up"}},skullRotation:6,teData:{Rot:14b,id:"minecraft:skull",SkullType:0b}}
:enddata
:endrule

rule:
plugin=vine
number=18
data:
JSON:{blockState:{blockName:"minecraft:vine",properties:{east:"false",south:"true",north:"false",west:"false",up:"false"}}}
:enddata
:endrule

rule:
plugin=vanillaFlowerPot
number=19
data:
JSON:{blockState:{blockName:"minecraft:flower_pot",properties:{contents:"empty",legacy_data:"0"}},itemMeta:0}
:enddata
:endrule

rule:
plugin=vanillaBlocks
number=20
data:
JSON:{blockState:{blockName:"minecraft:stonebrick",properties:{variant:"chiseled_stonebrick"}}}
:enddata
:endrule

rule:
plugin=vanillaBlocks
number=21
data:
JSON:{blockState:{blockName:"minecraft:cobblestone_wall",properties:{east:"false",south:"false",north:"false",variant:"cobblestone",west:"false",up:"false"}}}
:enddata
:endrule

#### ENTITIES ####
