# Ancient Warfare Structure Template File
# Auto-generated structure template file. created on: 12/25/2018 at: 22:43:59
# Lines beginning with # denote comments

header:
version=2.8
name=RuinGenericSmall4
mods=
size=15,16,13
offset=8,3,12
:endheader

#### VALIDATION ####
validation:
type=ground
survival=false
worldGenEnabled=true
unique=false
preserveBlocks=false
selectionWeight=30
clusterValue=10
minDuplicateDistance=900
dimensionWhiteList=true
dimensionList=0
biomeWhiteList=true
biomeList=biomesoplenty:shrubland,minecraft:mutated_roofed_forest,biomesoplenty:dead_forest,biomesoplenty:wasteland,minecraft:extreme_hills,biomesoplenty:ominous_woods,biomesoplenty:steppe
leveling=6
fill=6
border=6
blockSwap=true
:endvalidation

#### LAYERS ####
layer: 0
1,1,1,1,1,1,1,1,1,1,1,1,1,1,1
1,1,1,1,1,1,1,1,1,1,1,1,1,1,1
1,1,1,1,1,1,1,1,1,1,1,1,1,1,1
1,1,1,1,1,1,1,1,1,1,1,1,1,1,1
1,1,1,1,1,1,1,1,1,1,1,1,1,1,1
1,1,1,1,1,1,1,1,1,1,1,1,1,1,1
1,1,1,1,1,1,1,1,1,1,1,1,1,1,1
1,1,1,1,1,1,1,1,1,1,1,1,1,1,1
1,1,1,1,1,1,1,1,1,1,1,1,1,1,1
1,1,1,1,1,1,1,1,1,1,1,1,1,1,1
1,1,1,1,1,1,1,1,1,1,1,1,1,1,1
1,1,1,1,1,1,1,1,1,1,1,1,1,1,1
1,1,1,1,1,1,1,1,1,1,1,1,1,1,1
:endlayer
layer: 1
1,1,1,1,1,1,1,1,1,1,1,1,1,1,1
1,1,1,1,1,1,1,1,1,1,1,1,1,1,1
1,1,1,1,1,1,1,1,1,1,1,1,1,1,1
1,1,1,1,1,1,1,1,1,1,1,1,1,1,1
1,1,1,1,1,1,1,1,1,1,1,1,1,1,1
1,1,1,1,1,1,1,1,1,1,1,1,1,1,1
1,1,1,1,1,1,1,1,1,1,1,1,1,1,1
1,1,1,1,1,1,1,1,1,1,1,1,1,1,1
1,1,1,1,1,1,1,1,1,1,1,1,1,1,1
1,1,1,1,1,1,1,1,1,1,1,1,1,1,1
1,1,1,1,1,1,1,1,1,1,1,1,1,1,1
1,1,1,1,1,1,1,1,1,1,1,1,1,1,1
1,1,1,1,1,1,1,1,1,1,1,1,1,1,1
:endlayer
layer: 2
2,2,2,2,2,2,2,2,2,2,2,2,2,2,2
2,2,2,2,2,2,2,2,2,2,2,2,2,2,2
2,2,2,2,2,2,2,2,2,2,2,2,2,2,2
2,2,2,2,2,1,1,1,1,2,2,2,2,2,2
2,2,2,2,1,1,1,1,1,1,2,2,2,2,2
2,2,2,1,1,1,1,1,1,1,1,2,2,2,2
2,2,2,1,1,1,1,1,1,1,1,2,2,2,2
2,2,2,1,1,1,1,1,1,1,1,2,2,2,2
2,2,2,1,1,1,1,1,1,1,1,2,2,2,2
2,2,2,2,1,1,1,1,1,1,2,2,2,2,2
2,2,2,2,2,1,1,1,1,2,2,2,2,2,2
2,2,2,2,2,2,2,2,2,2,2,2,2,2,2
2,2,2,2,2,2,2,2,2,2,2,2,2,2,2
:endlayer
layer: 3
0,0,0,0,0,12,7,0,0,0,0,0,0,0,0
0,0,0,12,16,7,0,0,0,7,0,0,12,7,0
0,0,0,7,0,21,0,0,21,7,0,0,7,7,6
0,0,7,7,0,9,19,19,14,7,7,0,0,0,0
0,7,7,7,11,11,9,11,11,13,7,6,0,0,0
0,20,18,9,13,15,11,11,14,14,15,17,12,6,0
16,16,7,19,14,11,13,14,9,13,10,7,7,6,0
0,0,7,10,15,14,11,15,9,15,19,7,3,7,0
0,0,18,13,9,15,9,9,9,14,14,17,0,0,0
0,16,7,7,15,11,14,9,13,9,7,6,12,0,0
0,0,7,7,3,11,10,10,9,7,7,8,7,6,0
0,0,0,0,0,4,3,5,4,0,0,0,0,0,0
0,0,0,0,0,0,0,0,0,3,0,0,0,0,0
:endlayer
layer: 4
0,0,0,0,0,0,0,0,0,0,0,0,0,0,0
0,0,0,0,0,0,0,0,0,0,0,0,0,0,0
0,0,0,0,0,22,0,0,22,7,0,0,0,0,0
0,0,0,0,7,13,0,0,13,7,6,0,0,0,0
0,0,16,7,15,0,6,3,3,13,0,0,0,0,0
0,12,0,11,0,6,0,0,7,7,9,22,12,6,0
16,0,0,3,7,12,16,7,7,0,0,0,7,6,0
0,0,0,0,16,0,7,0,0,0,0,0,3,0,0
0,0,22,15,0,16,7,7,0,0,9,7,0,0,0
0,0,0,7,14,8,7,0,0,13,7,6,0,0,0
0,0,0,3,3,15,7,16,13,6,0,6,0,0,0
0,0,0,0,0,22,3,3,22,0,6,0,0,0,0
0,0,0,0,0,0,0,0,0,3,0,0,0,0,0
:endlayer
layer: 5
0,0,0,0,0,0,0,0,0,0,0,0,0,0,0
0,0,0,0,0,0,0,0,0,0,0,0,0,0,0
0,0,0,0,0,22,0,0,24,0,0,0,0,0,0
0,0,0,0,0,9,0,0,11,12,0,0,0,0,0
0,0,0,0,15,0,6,3,3,13,0,0,0,0,0
0,12,22,9,0,6,0,0,0,16,14,22,12,6,0
16,0,0,3,0,12,16,0,0,0,0,0,7,6,0
0,0,0,0,23,0,0,0,0,0,0,0,3,0,0
0,0,0,9,0,16,7,0,0,0,14,0,0,0,0
0,0,0,0,11,6,0,0,0,11,7,6,0,0,0
0,0,0,3,3,13,0,16,15,6,0,6,0,0,0
0,0,0,0,0,22,0,3,22,0,6,0,0,0,0
0,0,0,0,0,0,0,0,0,3,0,0,0,0,0
:endlayer
layer: 6
0,0,0,0,0,0,0,0,0,0,0,0,0,0,0
0,0,0,0,0,0,0,0,0,0,0,0,0,0,0
0,0,0,0,0,0,0,0,24,0,0,0,0,0,0
0,0,0,0,0,15,26,25,13,12,0,0,0,0,0
0,0,0,7,14,0,6,3,3,15,0,0,0,0,0
0,12,24,11,0,6,0,0,0,16,15,24,12,6,0
16,7,0,28,0,12,16,0,0,0,28,0,7,6,0
0,0,0,27,23,7,0,0,0,0,27,0,3,0,0
0,0,24,15,7,7,0,0,0,0,15,24,0,0,0
0,0,0,7,9,0,0,0,0,13,0,0,0,0,0
0,0,0,3,3,15,26,25,15,6,0,6,0,0,0
0,0,0,0,0,24,0,3,24,0,6,0,0,0,0
0,0,0,0,0,0,0,0,0,3,0,0,0,0,0
:endlayer
layer: 7
0,0,0,0,0,0,0,0,0,0,0,0,0,0,0
0,0,0,0,0,0,0,0,0,0,0,0,0,0,0
0,0,0,0,0,27,30,29,27,0,0,0,0,0,0
0,0,0,0,30,13,9,9,13,29,0,0,0,0,0
0,0,0,30,14,13,6,3,15,14,30,0,0,0,0
0,12,25,13,14,6,0,11,11,13,11,26,12,6,0
16,7,30,14,15,13,16,15,9,11,11,29,7,6,0
0,0,30,14,3,0,7,7,9,15,13,30,3,0,0
0,0,25,11,9,15,7,0,11,13,14,26,0,0,0
0,0,7,29,15,9,15,0,15,13,30,0,0,0,0
0,0,0,0,30,9,15,13,9,29,0,6,0,0,0
0,0,0,0,0,28,29,3,10,0,6,0,0,0,0
0,0,0,0,0,0,0,0,0,3,0,0,0,0,0
:endlayer
layer: 8
0,0,0,0,0,0,0,0,0,0,0,0,0,0,0
0,0,0,0,0,0,0,0,0,0,0,0,0,0,0
0,0,0,0,0,22,24,0,22,0,0,0,0,0,0
0,0,0,0,22,15,6,16,9,22,0,0,0,0,0
0,0,0,22,15,3,0,0,12,15,0,0,0,0,0
0,12,22,15,32,0,0,6,7,3,14,22,7,6,0
0,7,22,0,0,0,0,6,0,0,0,22,7,6,0
0,0,24,0,0,0,0,0,6,7,7,24,3,0,0
0,0,22,9,31,0,7,0,6,7,13,22,0,0,0
0,0,7,24,9,12,0,0,12,13,24,0,0,0,0
0,0,0,0,22,11,0,0,13,0,0,6,0,0,0
0,0,0,0,0,22,3,0,3,0,6,0,0,0,0
0,0,0,0,0,0,0,0,0,3,0,0,0,0,0
:endlayer
layer: 9
0,0,0,0,0,0,0,0,0,0,0,0,0,0,0
0,0,0,0,0,0,0,0,0,0,0,0,0,0,0
0,0,0,0,0,12,12,0,0,0,0,0,0,0,0
0,0,0,0,24,14,6,0,0,22,0,0,0,0,0
0,0,0,7,14,3,0,0,12,14,24,0,0,0,0
0,12,0,9,3,0,0,6,0,23,11,7,0,0,0
0,7,7,0,0,0,0,6,0,0,0,6,0,0,0
0,0,16,0,0,0,7,0,6,12,7,6,0,0,0
0,0,7,9,31,0,0,0,6,33,11,6,0,0,0
0,0,0,3,13,12,0,0,12,14,0,0,0,0,0
0,0,0,0,22,9,0,0,15,24,0,6,0,0,0
0,0,0,0,0,3,3,0,3,0,6,0,0,0,0
0,0,0,0,0,0,0,0,0,3,0,0,0,0,0
:endlayer
layer: 10
0,0,0,0,0,0,0,0,0,0,0,0,0,0,0
0,0,0,0,0,0,0,0,0,0,0,0,0,0,0
0,0,0,0,0,12,12,0,0,0,0,0,0,0,0
0,0,0,0,22,9,30,0,0,0,0,0,0,0,0
0,0,0,22,14,3,0,0,12,0,22,0,0,0,0
0,0,0,7,3,0,0,6,0,16,11,7,0,0,0
0,0,7,29,0,0,0,6,0,0,0,6,0,0,0
0,0,16,27,0,0,7,0,6,12,29,6,0,0,0
0,0,16,14,31,0,0,0,6,33,14,6,0,0,0
0,0,0,3,11,12,0,0,12,13,24,0,0,0,0
0,0,0,0,3,14,26,25,13,0,0,6,0,0,0
0,0,0,0,0,3,3,0,3,0,6,0,0,0,0
0,0,0,0,0,0,0,0,0,3,0,0,0,0,0
:endlayer
layer: 11
0,0,0,0,0,0,0,0,0,0,0,0,0,0,0
0,0,0,0,0,0,0,0,0,0,0,0,0,0,0
0,0,0,0,0,12,12,0,0,0,0,0,0,0,0
0,0,0,0,22,11,34,0,0,0,0,0,0,0,0
0,0,0,16,9,6,0,0,12,0,0,0,0,0,0
0,0,0,0,3,0,0,6,0,0,7,0,0,0,0
0,0,7,7,0,0,7,6,0,0,0,6,0,0,0
0,0,16,34,0,0,7,0,6,12,34,6,0,0,0
0,0,16,9,6,0,0,0,6,16,11,6,0,0,0
0,0,0,24,9,12,0,0,12,14,22,0,0,0,0
0,0,0,0,24,11,34,34,13,22,0,6,0,0,0
0,0,0,0,0,3,3,0,3,7,6,0,0,0,0
0,0,0,0,0,0,0,0,0,3,0,0,0,0,0
:endlayer
layer: 12
0,0,0,0,0,0,0,0,0,0,0,0,0,0,0
0,0,0,0,0,0,0,0,0,0,0,0,0,0,0
0,0,0,0,0,12,0,0,0,0,0,0,0,0,0
0,0,0,0,16,9,0,0,0,0,0,0,0,0,0
0,0,0,0,0,0,0,0,12,0,0,0,0,0,0
0,0,0,0,7,7,13,6,15,0,0,0,0,0,0
0,0,16,7,7,14,11,6,13,0,13,6,0,0,0
0,0,29,0,11,15,7,15,6,33,0,29,0,0,0
0,0,25,13,14,14,14,13,6,11,11,26,0,0,0
0,0,0,25,15,14,15,13,13,13,26,0,0,0,0
0,0,0,0,28,14,15,11,9,28,0,6,0,0,0
0,0,0,0,0,28,29,30,28,7,6,0,0,0,0
0,0,0,0,0,0,0,0,0,3,0,0,0,0,0
:endlayer
layer: 13
0,0,0,0,0,0,0,0,0,0,0,0,0,0,0
0,0,0,0,0,0,0,0,0,0,0,0,0,0,0
0,0,0,0,0,0,0,0,0,0,0,0,0,0,0
0,0,0,0,0,0,0,0,0,0,0,0,0,0,0
0,0,0,0,0,0,0,0,0,0,0,0,0,0,0
0,0,0,0,0,7,0,0,0,0,0,0,0,0,0
0,0,16,14,0,7,12,0,0,0,0,22,0,0,0
0,0,16,9,10,7,7,6,0,16,9,22,0,0,0
0,0,24,11,19,7,5,6,0,10,7,0,0,0,0
0,0,0,22,14,10,5,19,19,11,24,0,0,0,0
0,0,0,0,22,13,9,15,15,22,7,6,0,0,0
0,0,0,0,0,24,24,22,22,7,6,0,0,0,0
0,0,0,0,0,0,0,0,0,3,0,0,0,0,0
:endlayer
layer: 14
0,0,0,0,0,0,0,0,0,0,0,0,0,0,0
0,0,0,0,0,0,0,0,0,0,0,0,0,0,0
0,0,0,0,0,0,0,0,0,0,0,0,0,0,0
0,0,0,0,0,0,0,0,0,0,0,0,0,0,0
0,0,0,0,0,0,0,0,0,0,0,0,0,0,0
0,0,0,0,0,0,0,0,0,0,0,0,0,0,0
0,0,0,0,0,0,0,0,0,0,0,0,0,0,0
0,0,10,7,6,0,0,0,0,0,0,10,0,0,0
0,0,10,7,7,0,0,0,0,0,7,10,0,0,0
0,0,0,19,3,0,0,12,0,7,10,5,0,0,0
0,0,0,0,0,0,5,7,0,19,5,6,0,0,0
0,0,0,0,0,19,10,19,19,5,6,0,0,0,0
0,0,0,0,0,0,0,0,0,0,0,0,0,0,0
:endlayer
layer: 15
0,0,0,0,0,0,0,0,0,0,0,0,0,0,0
0,0,0,0,0,0,0,0,0,0,0,0,0,0,0
0,0,0,0,0,0,0,0,0,0,0,0,0,0,0
0,0,0,0,0,0,0,0,0,0,0,0,0,0,0
0,0,0,0,0,0,0,0,0,0,0,0,0,0,0
0,0,0,0,0,0,0,0,0,0,0,0,0,0,0
0,0,0,0,0,0,0,0,0,0,0,0,0,0,0
0,0,7,6,0,0,0,0,0,0,0,0,0,0,0
0,0,7,6,0,0,0,0,0,0,0,0,0,0,0
0,0,0,0,0,0,0,0,0,0,7,0,0,0,0
0,0,0,0,0,0,0,0,0,0,0,0,0,0,0
0,0,0,0,0,0,0,0,0,0,0,0,0,0,0
0,0,0,0,0,0,0,0,0,0,0,0,0,0,0
:endlayer

#### RULES ####
rule:
plugin=vanillaBlocks
number=1
data:
JSON:{blockState:{blockName:"minecraft:dirt",properties:{variant:"dirt",snowy:"false"}}}
:enddata
:endrule

rule:
plugin=vanillaBlocks
number=2
data:
JSON:{blockState:{blockName:"minecraft:grass",properties:{snowy:"false"}}}
:enddata
:endrule

rule:
plugin=vine
number=3
data:
JSON:{blockState:{blockName:"minecraft:vine",properties:{east:"false",south:"false",north:"true",west:"false",up:"false"}}}
:enddata
:endrule

rule:
plugin=vanillaBlocks
number=4
data:
JSON:{blockState:{blockName:"minecraft:stone_brick_stairs",properties:{half:"bottom",shape:"straight",facing:"north"}}}
:enddata
:endrule

rule:
plugin=vanillaBlocks
number=5
data:
JSON:{blockState:{blockName:"minecraft:leaves",properties:{check_decay:"true",decayable:"false",variant:"jungle"}}}
:enddata
:endrule

rule:
plugin=vine
number=6
data:
JSON:{blockState:{blockName:"minecraft:vine",properties:{east:"false",south:"false",north:"false",west:"true",up:"false"}}}
:enddata
:endrule

rule:
plugin=vanillaBlocks
number=7
data:
JSON:{blockState:{blockName:"minecraft:leaves",properties:{check_decay:"false",decayable:"false",variant:"jungle"}}}
:enddata
:endrule

rule:
plugin=vine
number=8
data:
JSON:{blockState:{blockName:"minecraft:vine",properties:{east:"true",south:"false",north:"false",west:"true",up:"false"}}}
:enddata
:endrule

rule:
plugin=vanillaBlocks
number=9
data:
JSON:{blockState:{blockName:"minecraft:stonebrick",properties:{variant:"cracked_stonebrick"}}}
:enddata
:endrule

rule:
plugin=vanillaBlocks
number=10
data:
JSON:{blockState:{blockName:"minecraft:stone_slab",properties:{half:"bottom",variant:"stone_brick"}}}
:enddata
:endrule

rule:
plugin=vanillaBlocks
number=11
data:
JSON:{blockState:{blockName:"minecraft:mossy_cobblestone"}}
:enddata
:endrule

rule:
plugin=vine
number=12
data:
JSON:{blockState:{blockName:"minecraft:vine",properties:{east:"false",south:"true",north:"false",west:"false",up:"false"}}}
:enddata
:endrule

rule:
plugin=vanillaBlocks
number=13
data:
JSON:{blockState:{blockName:"minecraft:stonebrick",properties:{variant:"mossy_stonebrick"}}}
:enddata
:endrule

rule:
plugin=vanillaBlocks
number=14
data:
JSON:{blockState:{blockName:"minecraft:cobblestone"}}
:enddata
:endrule

rule:
plugin=vanillaBlocks
number=15
data:
JSON:{blockState:{blockName:"minecraft:stonebrick",properties:{variant:"stonebrick"}}}
:enddata
:endrule

rule:
plugin=vine
number=16
data:
JSON:{blockState:{blockName:"minecraft:vine",properties:{east:"true",south:"false",north:"false",west:"false",up:"false"}}}
:enddata
:endrule

rule:
plugin=vanillaBlocks
number=17
data:
JSON:{blockState:{blockName:"minecraft:stone_brick_stairs",properties:{half:"bottom",shape:"straight",facing:"west"}}}
:enddata
:endrule

rule:
plugin=vanillaBlocks
number=18
data:
JSON:{blockState:{blockName:"minecraft:stone_brick_stairs",properties:{half:"bottom",shape:"straight",facing:"east"}}}
:enddata
:endrule

rule:
plugin=vanillaBlocks
number=19
data:
JSON:{blockState:{blockName:"minecraft:stone_slab",properties:{half:"bottom",variant:"cobblestone"}}}
:enddata
:endrule

rule:
plugin=vine
number=20
data:
JSON:{blockState:{blockName:"minecraft:vine",properties:{east:"false",south:"true",north:"true",west:"false",up:"false"}}}
:enddata
:endrule

rule:
plugin=vanillaBlocks
number=21
data:
JSON:{blockState:{blockName:"minecraft:stone_brick_stairs",properties:{half:"bottom",shape:"straight",facing:"south"}}}
:enddata
:endrule

rule:
plugin=vanillaBlocks
number=22
data:
JSON:{blockState:{blockName:"minecraft:cobblestone_wall",properties:{east:"false",south:"false",north:"false",variant:"cobblestone",west:"false",up:"false"}}}
:enddata
:endrule

rule:
plugin=vine
number=23
data:
JSON:{blockState:{blockName:"minecraft:vine",properties:{east:"true",south:"false",north:"true",west:"false",up:"false"}}}
:enddata
:endrule

rule:
plugin=vanillaBlocks
number=24
data:
JSON:{blockState:{blockName:"minecraft:cobblestone_wall",properties:{east:"false",south:"false",north:"false",variant:"mossy_cobblestone",west:"false",up:"false"}}}
:enddata
:endrule

rule:
plugin=vanillaBlocks
number=25
data:
JSON:{blockState:{blockName:"minecraft:stone_brick_stairs",properties:{half:"top",shape:"straight",facing:"east"}}}
:enddata
:endrule

rule:
plugin=vanillaBlocks
number=26
data:
JSON:{blockState:{blockName:"minecraft:stone_brick_stairs",properties:{half:"top",shape:"straight",facing:"west"}}}
:enddata
:endrule

rule:
plugin=vanillaBlocks
number=27
data:
JSON:{blockState:{blockName:"minecraft:stone_brick_stairs",properties:{half:"top",shape:"straight",facing:"south"}}}
:enddata
:endrule

rule:
plugin=vanillaBlocks
number=28
data:
JSON:{blockState:{blockName:"minecraft:stone_brick_stairs",properties:{half:"top",shape:"straight",facing:"north"}}}
:enddata
:endrule

rule:
plugin=vanillaBlocks
number=29
data:
JSON:{blockState:{blockName:"minecraft:stone_slab",properties:{half:"top",variant:"cobblestone"}}}
:enddata
:endrule

rule:
plugin=vanillaBlocks
number=30
data:
JSON:{blockState:{blockName:"minecraft:stone_slab",properties:{half:"top",variant:"stone_brick"}}}
:enddata
:endrule

rule:
plugin=vine
number=31
data:
JSON:{blockState:{blockName:"minecraft:vine",properties:{east:"false",south:"true",north:"false",west:"true",up:"false"}}}
:enddata
:endrule

rule:
plugin=vine
number=32
data:
JSON:{blockState:{blockName:"minecraft:vine",properties:{east:"false",south:"false",north:"true",west:"true",up:"false"}}}
:enddata
:endrule

rule:
plugin=vine
number=33
data:
JSON:{blockState:{blockName:"minecraft:vine",properties:{east:"true",south:"true",north:"false",west:"false",up:"false"}}}
:enddata
:endrule

rule:
plugin=vanillaBlocks
number=34
data:
JSON:{blockState:{blockName:"minecraft:stone",properties:{variant:"smooth_andesite"}}}
:enddata
:endrule

#### ENTITIES ####
