# Ancient Warfare Structure Template File
# Auto-generated structure template file. created on: 12/25/2018 at: 22:43:46
# Lines beginning with # denote comments

header:
version=2.8
name=RuinGenericSmall14
mods=
size=20,20,20
offset=11,9,19
:endheader

#### VALIDATION ####
validation:
type=ground
survival=false
worldGenEnabled=true
unique=false
preserveBlocks=false
selectionWeight=30
clusterValue=10
minDuplicateDistance=900
dimensionWhiteList=true
dimensionList=0
biomeWhiteList=true
biomeList=biomesoplenty:shrubland,minecraft:mutated_roofed_forest,biomesoplenty:dead_forest,biomesoplenty:wasteland,minecraft:extreme_hills,biomesoplenty:ominous_woods,biomesoplenty:steppe
leveling=6
fill=6
border=6
blockSwap=true
:endvalidation

#### LAYERS ####
layer: 0
1,1,1,1,1,1,1,1,1,1,1,1,1,1,1,1,1,1,1,1
1,2,2,2,2,2,2,2,2,2,2,2,2,2,2,2,2,2,2,1
1,2,2,2,2,2,2,2,2,2,2,2,2,4,4,2,2,2,2,1
1,2,2,2,2,2,2,2,2,2,2,2,2,3,3,2,2,2,2,1
1,2,2,2,2,2,2,2,2,2,2,2,2,2,2,2,2,2,2,1
1,2,2,2,2,2,2,2,2,2,2,2,2,2,2,2,2,2,2,1
1,2,2,2,2,2,2,2,2,2,2,2,2,2,2,2,2,2,2,1
1,2,2,2,2,2,2,2,2,2,2,2,2,2,2,2,2,2,2,1
1,2,2,2,2,2,2,2,2,2,2,2,2,2,2,2,2,2,2,1
1,2,2,2,2,2,2,2,2,2,2,2,2,2,2,2,2,2,2,1
1,2,2,2,2,2,2,2,2,2,2,2,2,2,2,2,2,2,2,1
1,2,2,0,2,2,2,2,2,2,2,2,2,2,2,2,2,2,2,1
1,2,2,2,2,2,2,2,2,2,2,2,2,2,2,2,2,2,2,1
1,2,2,2,2,2,2,2,2,2,2,2,2,2,2,2,2,2,2,1
1,2,2,2,2,2,2,2,2,2,2,2,2,2,2,2,2,2,2,1
1,2,2,2,2,2,2,2,2,2,2,2,2,2,2,2,2,2,2,1
1,2,2,2,2,2,2,2,2,2,2,2,2,2,2,2,2,2,2,1
1,2,2,2,2,2,2,2,2,2,2,2,2,2,2,2,0,2,2,1
1,2,2,2,2,2,2,2,2,2,2,2,2,2,2,2,2,2,2,1
1,1,1,1,1,1,1,1,1,1,1,1,1,1,1,1,1,1,1,1
:endlayer
layer: 1
1,1,1,1,1,1,1,1,1,1,1,1,1,1,1,1,1,1,1,1
1,2,2,2,2,2,2,2,2,2,2,2,2,2,2,2,2,2,2,1
1,2,2,2,2,2,2,2,2,2,2,2,2,18,18,2,2,2,2,1
1,2,2,0,0,0,0,3,0,0,3,8,8,8,8,8,11,2,2,1
1,2,2,0,0,0,0,0,0,0,3,0,0,0,0,0,11,2,2,1
1,2,2,0,0,0,0,3,0,0,0,0,0,0,0,0,17,2,2,1
1,2,2,0,0,0,0,3,0,0,3,0,0,0,0,0,0,2,2,1
1,2,2,3,0,3,3,3,3,11,11,3,3,3,0,3,3,2,2,1
1,2,14,0,0,0,3,3,11,3,3,0,0,0,0,0,0,2,2,1
1,2,14,0,0,0,16,3,3,11,3,12,12,3,0,3,0,2,2,1
1,2,14,0,0,0,15,11,3,3,3,3,3,3,0,3,12,2,2,1
1,2,14,0,0,0,3,11,3,13,0,0,0,0,0,3,12,2,2,1
1,2,2,3,3,0,3,3,11,11,11,3,3,3,0,3,3,2,2,1
1,2,2,0,0,0,0,3,0,0,3,10,0,0,0,0,9,2,2,1
1,2,2,0,0,0,0,0,0,0,3,0,0,8,8,8,0,2,2,1
1,2,2,0,0,0,0,3,0,0,0,0,0,8,3,8,0,2,2,1
1,2,2,0,0,0,0,3,0,0,3,0,0,8,8,8,0,2,2,1
1,2,2,7,0,0,0,3,6,0,3,5,0,0,0,0,0,2,2,1
1,2,2,2,2,2,2,2,2,2,2,2,2,2,2,2,2,2,2,1
1,1,1,1,1,1,1,1,1,1,1,1,1,1,1,1,1,1,1,1
:endlayer
layer: 2
1,1,1,1,1,1,1,1,1,1,1,1,1,1,1,1,1,1,1,1
1,2,2,2,2,2,2,2,2,2,2,2,2,2,2,2,2,2,2,1
1,2,2,2,2,2,2,2,2,2,2,2,2,22,22,2,2,2,2,1
1,2,2,0,0,0,0,3,0,0,3,0,0,0,0,0,11,2,2,1
1,2,2,0,0,0,0,0,0,0,3,0,0,0,0,0,17,2,2,1
1,2,2,0,0,0,0,3,0,0,0,0,0,0,0,0,0,2,2,1
1,2,2,0,0,0,0,3,0,0,3,0,0,0,0,0,0,2,2,1
1,2,2,3,0,3,3,3,3,11,11,3,3,3,0,3,3,2,2,1
1,2,14,0,0,0,21,3,11,3,11,0,0,0,0,0,0,2,2,1
1,2,14,0,0,0,0,3,11,3,3,0,0,3,0,3,0,2,2,1
1,2,14,0,0,0,20,11,17,3,11,3,3,3,0,3,0,2,2,1
1,2,14,0,0,0,19,3,0,0,0,0,0,0,0,3,0,2,2,1
1,2,2,3,3,0,3,11,3,3,3,3,3,3,0,3,3,2,2,1
1,2,2,0,0,0,0,3,0,0,3,0,0,0,0,0,0,2,2,1
1,2,2,0,0,0,0,0,0,0,3,0,0,0,0,0,0,2,2,1
1,2,2,0,0,0,0,3,0,0,0,0,0,0,0,0,0,2,2,1
1,2,2,0,0,0,0,3,0,0,3,0,0,0,0,0,0,2,2,1
1,2,2,0,0,0,0,3,0,0,3,0,0,0,0,0,0,2,2,1
1,2,2,2,2,2,2,2,2,2,2,2,2,2,2,2,2,2,2,1
1,1,1,1,1,1,1,1,1,1,1,1,1,1,1,1,1,1,1,1
:endlayer
layer: 3
1,1,1,1,1,1,1,1,1,1,1,1,1,1,1,1,1,1,1,1
1,2,2,2,2,2,2,2,2,2,2,2,2,2,2,2,2,2,2,1
1,2,2,2,2,2,2,2,2,2,2,2,2,2,2,2,2,2,2,1
1,2,2,15,15,15,15,3,0,0,3,3,3,3,3,3,17,2,2,1
1,2,2,15,0,0,15,3,0,0,3,3,3,3,3,3,0,2,2,1
1,2,2,15,0,0,15,3,0,0,3,3,3,3,3,3,0,2,2,1
1,2,2,15,15,15,15,3,0,0,3,3,3,3,3,3,0,2,2,1
1,2,2,3,3,3,3,3,3,3,11,3,3,3,3,3,3,2,2,1
1,2,3,25,26,26,15,3,3,11,3,0,0,3,0,3,0,2,2,1
1,2,2,25,0,0,15,3,17,11,3,0,0,3,0,3,0,2,2,1
1,2,3,25,0,0,15,11,0,3,3,3,3,3,0,3,0,2,2,1
1,2,2,25,24,24,15,11,0,0,0,0,0,0,0,3,0,2,2,1
1,2,2,3,3,3,3,3,3,3,3,3,3,3,3,3,3,2,2,1
1,2,2,0,0,0,0,3,15,15,3,0,0,0,0,0,0,2,2,1
1,2,2,0,0,0,0,3,0,15,3,0,0,0,0,0,23,2,2,1
1,2,2,0,0,0,0,3,15,15,3,0,0,0,0,0,0,2,2,1
1,2,2,0,0,0,0,3,15,15,3,0,0,0,0,0,23,2,2,1
1,2,2,0,0,0,0,3,24,24,3,0,23,0,23,0,0,2,2,1
1,2,2,2,2,2,2,2,2,2,2,2,2,2,2,2,2,2,2,1
1,1,1,1,1,1,1,1,1,1,1,1,1,1,1,1,1,1,1,1
:endlayer
layer: 4
1,1,1,1,1,1,1,1,1,1,1,1,1,1,1,1,1,1,1,1
1,2,2,2,2,2,2,2,2,2,2,2,2,2,2,2,2,2,2,1
1,2,2,2,2,2,2,2,2,2,2,2,2,2,2,2,2,2,2,1
1,2,2,0,0,41,40,3,0,0,3,0,0,0,0,0,0,2,2,1
1,2,2,39,0,0,0,3,0,0,3,38,0,0,0,0,0,2,2,1
1,2,2,0,0,0,37,3,0,0,3,12,0,12,0,12,0,2,2,1
1,2,2,0,36,0,0,3,0,0,3,12,0,12,0,12,0,2,2,1
1,2,3,3,3,3,3,3,3,3,11,3,3,3,3,3,3,2,2,1
1,3,0,0,0,0,35,3,0,34,11,0,0,3,0,3,0,2,2,1
1,2,3,0,0,0,33,11,0,3,3,0,0,3,0,3,0,2,2,1
1,3,0,0,0,0,32,11,0,3,3,3,3,3,0,3,0,2,2,1
1,2,3,0,0,0,31,3,0,0,0,0,0,0,0,3,0,2,2,1
1,2,2,3,3,3,3,3,3,3,3,3,3,3,3,3,3,2,2,1
1,2,2,8,8,8,8,3,0,0,3,0,0,0,0,0,0,2,2,1
1,2,2,8,0,0,8,3,0,0,3,0,0,0,0,0,30,2,2,1
1,2,2,8,0,0,8,3,0,0,3,0,0,0,0,0,0,2,2,1
1,2,2,8,0,0,8,3,0,0,3,0,0,0,0,0,29,2,2,1
1,2,2,8,8,8,8,3,0,0,3,0,28,0,27,0,0,2,2,1
1,2,2,2,2,2,2,2,2,2,2,2,2,2,2,2,2,2,2,1
1,1,1,1,1,1,1,1,1,1,1,1,1,1,1,1,1,1,1,1
:endlayer
layer: 5
1,1,1,1,1,1,1,1,1,1,1,1,1,1,1,1,1,1,1,1
1,2,2,2,2,2,2,2,2,2,2,2,2,2,2,2,2,2,2,1
1,2,2,2,2,2,2,2,2,2,2,2,2,2,2,2,2,2,2,1
1,2,2,0,0,0,0,3,0,0,3,0,0,0,0,0,0,2,2,1
1,2,2,0,0,0,0,3,0,0,3,0,0,0,0,0,0,2,2,1
1,2,2,0,0,0,0,3,0,0,3,0,0,0,0,0,0,2,2,1
1,2,2,0,0,0,0,3,0,0,3,0,0,0,0,0,0,2,2,1
1,2,3,3,3,3,3,3,3,11,3,3,3,3,3,3,3,2,2,1
1,3,0,0,0,0,0,3,0,0,34,0,0,3,0,3,0,2,2,1
1,2,3,0,0,0,0,3,0,3,3,0,0,3,0,3,0,2,2,1
1,3,0,0,0,0,0,11,0,3,3,3,3,3,0,3,0,2,2,1
1,2,3,0,0,0,0,11,0,0,11,0,0,0,0,3,0,2,2,1
1,2,2,3,3,3,3,3,11,3,11,3,3,3,3,3,3,2,2,1
1,2,2,0,0,0,0,3,0,0,3,0,0,0,0,0,0,2,2,1
1,2,2,0,0,0,0,3,0,0,3,0,0,0,0,0,0,2,2,1
1,2,2,0,0,0,0,3,0,0,3,0,0,0,0,0,0,2,2,1
1,2,2,0,0,0,0,3,0,0,3,0,0,0,0,0,0,2,2,1
1,2,2,0,0,0,0,3,0,0,3,0,0,0,0,0,0,2,2,1
1,2,2,2,2,2,2,2,2,2,2,2,2,2,2,2,2,2,2,1
1,1,1,1,1,1,1,1,1,1,1,1,1,1,1,1,1,1,1,1
:endlayer
layer: 6
1,1,1,1,1,1,1,1,1,1,1,1,1,1,1,1,1,1,1,1
1,2,2,2,2,2,2,2,2,2,2,2,2,2,2,2,2,2,2,1
1,2,2,2,2,2,2,2,2,2,2,2,2,2,2,2,2,2,2,1
1,2,2,2,2,2,2,2,2,2,2,2,2,2,2,2,2,2,2,1
1,2,2,2,2,2,2,2,2,2,2,2,2,2,2,2,2,2,2,1
1,2,2,2,2,2,2,2,2,2,2,2,2,2,2,2,2,2,2,1
1,2,2,2,2,2,2,2,2,2,2,2,2,2,2,2,2,2,2,1
1,2,2,2,2,2,2,11,11,3,3,3,3,2,2,2,2,2,2,1
1,2,2,2,2,2,2,11,0,0,0,34,2,2,2,2,2,2,2,1
1,2,2,2,2,2,2,11,0,3,3,11,2,2,2,2,2,2,2,1
1,2,2,2,2,2,2,2,11,2,2,2,2,2,2,2,2,2,2,1
1,2,2,2,2,2,2,2,2,2,2,2,2,2,2,2,2,2,2,1
1,2,2,2,2,2,2,2,2,2,2,2,2,2,2,2,2,2,2,1
1,2,2,2,2,2,2,2,2,2,2,2,2,2,2,2,2,2,2,1
1,2,2,2,2,2,2,2,2,2,2,2,2,2,2,2,2,2,2,1
1,2,2,2,2,2,2,2,2,2,2,2,2,2,2,2,2,2,2,1
1,2,2,2,2,2,2,2,2,2,2,2,2,2,2,2,2,2,2,1
1,2,2,2,2,2,2,2,2,2,2,2,2,2,2,2,2,2,2,1
1,2,2,2,2,2,2,2,2,2,2,2,2,2,2,2,2,2,2,1
1,1,1,1,1,1,1,1,1,1,1,1,1,1,1,1,1,1,1,1
:endlayer
layer: 7
1,1,1,1,1,1,1,1,1,1,1,1,1,1,1,1,1,1,1,1
1,1,45,45,45,45,45,45,1,1,1,1,1,1,1,1,1,1,1,1
1,45,42,45,45,45,1,1,1,43,46,1,1,1,1,1,1,43,1,1
1,45,45,45,45,1,1,1,1,1,1,1,1,1,1,1,1,1,1,1
1,45,45,1,1,1,1,1,1,1,1,1,1,1,1,1,1,1,1,1
1,45,1,1,1,1,1,1,1,1,1,1,1,1,1,1,1,1,1,1
1,1,1,1,1,1,1,1,1,1,1,1,1,1,1,1,1,1,1,1
1,1,1,1,1,1,1,1,1,1,1,1,3,1,1,1,1,1,1,1
1,1,1,1,1,1,1,1,11,0,0,0,34,1,1,1,1,1,1,1
1,1,42,1,1,1,1,1,11,43,43,1,1,1,1,1,1,43,1,1
1,1,42,1,1,1,1,1,11,43,43,1,1,1,1,1,1,43,1,1
1,1,1,1,1,1,1,1,1,1,1,1,1,1,1,1,1,1,1,1
1,1,1,1,1,1,1,1,1,1,1,1,1,1,1,1,1,1,1,1
1,1,1,1,1,1,1,1,1,1,1,1,1,1,1,1,1,1,1,1
1,1,1,1,1,1,1,1,1,1,1,1,1,1,1,1,1,1,1,1
1,1,1,1,1,1,1,1,1,1,1,1,1,1,1,1,1,1,1,1
1,1,1,1,1,1,1,1,1,1,1,1,1,1,1,1,1,1,1,1
1,1,44,1,1,1,1,1,1,44,43,1,1,1,1,1,1,42,1,1
1,1,1,1,1,1,1,1,1,1,1,1,1,1,1,1,1,1,1,1
1,1,1,1,1,1,1,1,1,1,1,1,1,1,1,1,1,1,1,1
:endlayer
layer: 8
45,45,45,45,45,45,45,45,45,45,45,45,45,45,45,45,45,45,45,45
45,45,0,0,0,0,0,0,45,45,45,45,45,45,45,45,1,1,45,45
45,0,46,0,0,0,45,45,45,43,43,45,45,1,45,1,1,42,1,45
45,0,0,0,0,45,45,45,45,45,45,45,45,45,45,45,1,1,1,45
45,0,0,45,45,45,45,45,45,45,45,45,45,45,45,45,1,1,1,45
45,0,45,45,45,45,45,45,45,45,1,45,45,45,45,45,1,1,45,45
45,45,45,45,45,45,45,45,45,45,45,45,45,45,45,1,1,1,1,45
45,45,45,45,45,45,45,45,1,1,1,1,1,1,1,1,1,1,1,45
45,45,45,45,45,45,45,45,45,11,0,0,0,34,45,1,1,1,1,45
45,45,42,45,45,45,45,45,45,43,43,1,1,1,1,1,1,43,1,45
45,45,44,45,45,45,45,45,1,43,43,1,1,1,1,1,1,44,1,45
45,45,45,45,45,45,1,1,1,1,1,1,1,1,1,1,1,1,1,45
45,45,45,45,45,1,1,1,1,1,1,1,1,1,1,1,1,1,1,45
45,45,45,45,1,1,1,1,1,1,1,1,1,1,1,1,1,1,1,45
45,45,45,45,1,1,1,1,1,1,1,1,1,1,1,1,1,1,45,45
45,45,1,1,1,1,1,1,1,1,1,1,1,1,1,1,1,1,1,45
45,1,1,1,1,1,1,1,1,1,1,1,1,1,1,1,1,1,1,45
45,1,42,1,1,1,1,1,1,43,43,1,1,1,1,1,1,44,45,45
45,45,1,1,1,1,1,1,1,1,1,1,1,1,1,1,1,1,45,45
45,45,45,45,45,45,45,45,45,45,45,45,45,45,45,45,45,45,45,45
:endlayer
layer: 9
0,0,0,0,0,0,0,0,0,0,0,0,0,0,0,0,0,0,0,0
0,0,0,0,0,0,0,0,0,0,0,0,0,0,0,0,45,45,0,0
0,0,43,0,0,0,0,0,0,44,43,0,0,48,0,45,45,42,45,0
0,0,0,0,0,0,47,47,47,47,0,0,47,0,47,47,45,45,45,0
0,0,0,0,0,0,47,47,0,47,0,47,47,47,0,47,45,45,45,0
0,0,0,0,47,0,0,47,0,0,11,0,47,47,0,0,45,45,0,0
0,0,0,47,0,47,47,47,47,0,0,47,47,47,47,11,45,45,45,0
0,47,0,47,0,0,0,47,48,45,45,45,45,45,45,45,45,45,45,0
0,0,0,0,0,47,47,0,0,45,45,0,0,0,47,45,45,45,45,0
0,0,44,0,0,0,0,0,0,43,45,45,45,1,45,45,45,44,45,0
0,0,42,0,0,0,0,0,45,43,43,45,45,45,45,45,45,42,45,0
0,0,0,0,0,0,45,45,45,45,45,45,45,45,45,45,45,45,45,0
0,0,0,0,0,45,45,45,45,45,45,45,45,45,45,45,45,45,45,0
0,0,0,0,45,45,45,45,45,1,45,45,45,45,45,45,45,45,45,0
0,47,47,0,45,45,45,45,45,45,45,45,45,1,45,45,45,45,0,0
0,0,45,45,45,45,45,45,45,45,45,45,45,45,45,45,45,45,45,0
0,45,45,45,45,45,45,45,45,45,45,45,45,45,45,45,45,45,45,0
0,45,44,45,45,45,45,45,45,44,43,45,45,45,45,45,45,42,0,0
0,0,43,44,44,46,44,44,43,44,44,44,44,46,43,44,44,43,0,0
0,0,0,0,0,0,0,0,0,0,0,0,0,0,0,0,0,0,0,0
:endlayer
layer: 10
0,0,0,0,0,0,0,0,0,0,0,0,0,0,0,0,0,0,0,0
0,0,0,0,0,0,0,0,0,0,0,49,49,49,49,49,0,0,0,0
0,0,43,0,0,0,0,0,0,44,42,49,49,48,49,49,0,11,0,0
0,0,0,0,0,0,0,0,0,0,0,49,49,49,49,49,0,0,0,0
0,0,0,0,0,0,0,0,0,0,0,49,49,49,49,49,0,0,0,0
0,0,0,0,0,0,0,0,0,0,11,0,0,0,0,0,0,47,0,0
0,0,0,0,0,0,0,0,0,0,0,0,0,0,0,11,0,47,0,0
0,0,0,0,0,0,0,0,48,0,47,47,47,47,0,47,0,0,0,0
0,0,0,0,0,0,0,0,0,0,0,0,0,0,0,47,0,0,0,0
0,0,42,0,0,0,0,0,0,43,47,0,47,48,47,47,47,42,0,0
0,0,44,0,0,0,0,0,47,43,43,0,0,0,47,47,47,42,0,0
0,0,0,0,0,0,0,47,0,47,0,47,0,47,47,0,0,0,0,0
0,0,0,0,0,0,47,0,0,0,47,0,47,47,47,47,47,47,0,0
0,0,0,0,47,47,47,0,0,11,0,0,0,0,47,47,0,0,0,0
0,0,0,0,0,0,0,47,0,0,0,47,0,11,47,0,0,47,0,0
0,0,0,0,0,0,0,0,0,0,0,0,47,0,0,0,47,47,0,0
0,0,0,0,0,0,0,0,0,0,0,0,0,0,0,0,0,0,0,0
0,0,42,0,0,0,0,47,0,44,43,0,0,0,0,0,0,43,0,0
0,0,44,44,46,0,0,0,0,46,46,0,0,0,0,44,43,44,0,0
0,0,0,0,0,0,0,0,0,0,0,0,0,0,0,0,0,0,0,0
:endlayer
layer: 11
0,0,0,0,0,0,0,0,0,0,0,0,0,0,0,0,0,0,0,0
0,0,0,0,0,0,0,0,0,0,0,49,49,49,49,49,0,0,0,0
0,0,46,0,0,0,0,0,0,42,44,49,49,48,49,49,0,0,0,0
0,0,0,0,0,0,0,0,0,0,0,49,49,49,49,49,0,0,0,0
0,0,0,0,0,0,0,0,0,0,0,49,49,49,49,0,0,0,0,0
0,0,0,0,0,0,0,0,0,0,0,0,0,0,0,0,0,0,0,0
0,0,0,0,0,0,0,0,0,0,0,0,0,0,0,11,0,0,0,0
0,0,0,0,0,0,0,0,48,0,0,0,0,0,0,0,0,0,0,0
0,0,0,0,0,0,0,0,0,0,0,0,0,0,0,0,0,0,0,0
0,0,42,0,0,0,0,0,0,44,0,0,0,48,0,0,0,44,0,0
0,0,42,0,0,0,0,0,0,43,43,0,0,0,0,0,0,43,0,0
0,0,0,0,0,0,0,0,0,0,0,0,0,0,0,0,0,0,0,0
0,0,0,0,0,0,0,0,0,0,0,0,0,0,0,0,0,0,0,0
0,0,0,0,0,0,0,0,0,0,0,0,0,0,0,0,0,0,0,0
0,0,0,0,0,0,0,0,0,0,0,0,0,0,0,0,0,0,0,0
0,0,0,0,0,0,0,0,0,0,0,0,0,0,0,0,0,0,0,0
0,0,0,0,0,0,0,0,0,0,0,0,0,0,0,0,0,0,0,0
0,0,44,0,0,0,0,0,0,42,43,0,0,0,0,0,0,43,0,0
0,0,44,44,0,0,0,0,0,43,46,0,0,0,0,0,44,46,0,0
0,0,0,0,0,0,0,0,0,0,0,0,0,0,0,0,0,0,0,0
:endlayer
layer: 12
0,0,0,0,0,0,0,0,0,0,0,0,0,0,0,0,0,0,0,0
0,0,0,0,0,0,0,0,0,0,0,0,49,49,0,0,0,0,0,0
0,0,50,0,0,0,0,0,0,42,43,0,49,48,49,0,0,0,0,0
0,0,0,0,0,0,0,0,0,0,0,0,0,49,49,0,0,0,0,0
0,0,0,0,0,0,0,0,0,0,0,0,0,0,0,0,0,0,0,0
0,0,0,0,0,0,49,49,49,49,49,0,0,0,0,0,0,0,0,0
0,0,0,0,0,0,49,49,49,49,49,0,0,0,0,0,0,0,0,0
0,0,0,0,0,0,49,49,48,49,49,0,49,49,49,49,0,0,0,0
0,0,0,0,0,0,49,49,49,49,49,49,49,49,49,49,0,0,0,0
0,0,43,0,0,0,49,49,49,42,0,49,49,48,49,49,0,44,0,0
0,0,43,0,0,0,0,0,0,42,42,49,49,49,49,49,0,43,0,0
0,0,0,0,0,0,0,0,0,0,0,0,49,49,49,49,0,0,0,0
0,0,0,0,0,0,0,0,0,0,0,0,0,0,0,0,0,0,0,0
0,0,0,0,0,0,0,0,0,0,0,0,0,0,0,0,0,0,0,0
0,0,0,0,0,0,0,0,0,0,0,0,0,0,0,0,0,0,0,0
0,0,0,0,0,0,0,0,0,0,0,0,0,0,0,0,0,0,0,0
0,0,0,0,0,0,0,0,0,0,0,0,0,0,0,0,0,0,0,0
0,0,43,0,0,0,0,0,0,42,43,0,0,0,0,0,0,43,0,0
0,0,43,0,0,0,0,0,0,0,0,0,0,0,0,0,0,43,0,0
0,0,0,0,0,0,0,0,0,0,0,0,0,0,0,0,0,0,0,0
:endlayer
layer: 13
0,0,0,0,0,0,0,0,0,0,0,0,0,0,0,0,0,0,0,0
0,0,0,0,0,0,0,0,0,0,0,0,0,49,0,0,0,0,0,0
0,0,43,0,0,0,0,0,0,42,44,0,49,49,49,0,0,0,0,0
0,0,0,0,0,0,0,0,0,0,0,0,0,49,0,0,0,0,0,0
0,0,0,0,0,0,0,0,0,0,0,0,0,0,0,0,0,0,0,0
0,0,0,0,0,0,0,49,49,49,49,0,0,0,0,0,0,0,0,0
0,0,0,0,0,0,49,49,49,49,49,0,0,0,0,0,0,0,0,0
0,0,0,0,0,0,49,49,48,49,49,49,49,49,49,49,0,0,0,0
0,0,0,0,0,0,49,49,49,49,49,49,49,49,49,49,0,0,0,0
0,0,43,0,0,0,49,49,49,42,0,49,49,48,49,49,0,44,0,0
0,0,42,0,0,0,0,0,0,42,42,49,49,49,49,49,0,43,0,0
0,0,0,0,0,0,0,0,0,0,0,49,49,49,49,49,0,0,0,0
0,0,0,0,0,0,0,0,0,0,0,0,0,0,0,0,0,0,0,0
0,0,0,0,0,0,0,0,0,0,0,0,0,0,0,0,0,0,0,0
0,0,0,0,0,0,0,0,0,0,0,0,0,0,0,0,0,0,0,0
0,0,0,0,0,0,0,0,0,0,0,0,0,0,0,0,0,0,0,0
0,0,0,0,0,0,0,0,0,0,0,0,0,0,0,0,0,0,0,0
0,0,44,0,0,0,0,0,0,42,43,0,0,0,0,0,0,43,0,0
0,0,0,0,0,0,0,0,0,0,0,0,0,0,0,0,0,0,0,0
0,0,0,0,0,0,0,0,0,0,0,0,0,0,0,0,0,0,0,0
:endlayer
layer: 14
0,0,0,0,0,0,0,0,0,0,0,0,0,0,0,0,0,0,0,0
0,0,0,0,0,0,0,0,0,0,0,0,0,0,0,0,0,0,0,0
0,0,43,0,0,0,0,0,0,42,42,0,0,0,0,0,0,0,0,0
0,0,0,0,0,0,0,0,0,0,0,0,0,0,0,0,0,0,0,0
0,0,0,0,0,0,0,0,0,0,0,0,0,0,0,0,0,0,0,0
0,0,0,0,0,0,0,0,0,0,0,0,0,0,0,0,0,0,0,0
0,0,0,0,0,0,0,0,49,49,0,0,0,0,0,0,0,0,0,0
0,0,0,0,0,0,0,49,48,49,0,0,0,0,0,0,0,0,0,0
0,0,0,0,0,0,0,0,49,49,0,0,0,49,49,0,0,0,0,0
0,0,43,0,0,0,0,0,0,44,0,0,49,48,49,0,0,46,0,0
0,0,43,0,0,0,0,0,0,44,43,0,0,49,0,0,0,44,0,0
0,0,0,0,0,0,0,0,0,0,0,0,0,0,0,0,0,0,0,0
0,0,0,0,0,0,0,0,0,0,0,0,0,0,0,0,0,0,0,0
0,0,0,0,0,0,0,0,0,0,0,0,0,0,0,0,0,0,0,0
0,0,0,0,0,0,0,0,0,0,0,0,0,0,0,0,0,0,0,0
0,0,0,0,0,0,0,0,0,0,0,0,0,0,0,0,0,0,0,0
0,0,0,0,0,0,0,0,0,0,0,0,0,0,0,0,0,0,0,0
0,0,42,0,0,0,0,0,0,43,43,0,0,0,0,0,0,43,0,0
0,0,0,0,0,0,0,0,0,0,0,0,0,0,0,0,0,0,0,0
0,0,0,0,0,0,0,0,0,0,0,0,0,0,0,0,0,0,0,0
:endlayer
layer: 15
0,0,0,0,0,0,0,0,0,0,0,0,0,0,0,0,0,0,0,0
0,0,0,0,0,0,0,0,0,0,0,0,0,0,0,0,0,0,0,0
0,0,42,0,0,0,0,0,0,44,0,0,0,0,0,0,0,0,0,0
0,0,0,0,0,0,0,0,0,0,0,0,0,0,0,0,0,0,0,0
0,0,0,0,0,0,0,0,0,0,0,0,0,0,0,0,0,0,0,0
0,0,0,0,0,0,0,0,0,0,0,0,0,0,0,0,0,0,0,0
0,0,0,0,0,0,0,0,49,0,0,0,0,0,0,0,0,0,0,0
0,0,0,0,0,0,0,49,49,49,0,0,0,0,0,0,0,0,0,0
0,0,0,0,0,0,0,0,49,0,0,0,0,49,0,0,0,0,0,0
0,0,42,0,0,0,0,0,0,43,0,0,49,49,49,0,0,0,0,0
0,0,43,0,0,0,0,0,0,43,43,0,0,49,0,0,0,44,0,0
0,0,0,0,0,0,0,0,0,0,0,0,0,0,0,0,0,0,0,0
0,0,0,0,0,0,0,0,0,0,0,0,0,0,0,0,0,0,0,0
0,0,0,0,0,0,0,0,0,0,0,0,0,0,0,0,0,0,0,0
0,0,0,0,0,0,0,0,0,0,0,0,0,0,0,0,0,0,0,0
0,0,0,0,0,0,0,0,0,0,0,0,0,0,0,0,0,0,0,0
0,0,0,0,0,0,0,0,0,0,0,0,0,0,0,0,0,0,0,0
0,0,42,0,0,0,0,0,0,43,43,0,0,0,0,0,0,43,0,0
0,0,0,0,0,0,0,0,0,0,0,0,0,0,0,0,0,0,0,0
0,0,0,0,0,0,0,0,0,0,0,0,0,0,0,0,0,0,0,0
:endlayer
layer: 16
0,0,0,0,0,0,0,0,0,0,0,0,0,0,0,0,0,0,0,0
0,0,0,0,0,0,0,0,0,0,0,0,0,0,0,0,0,0,0,0
0,0,44,0,0,0,0,0,0,44,0,0,0,0,0,0,0,0,0,0
0,0,0,0,0,0,0,0,0,0,0,0,0,0,0,0,0,0,0,0
0,0,0,0,0,0,0,0,0,0,0,0,0,0,0,0,0,0,0,0
0,0,0,0,0,0,0,0,0,0,0,0,0,0,0,0,0,0,0,0
0,0,0,0,0,0,0,0,0,0,0,0,0,0,0,0,0,0,0,0
0,0,0,0,0,0,0,0,0,0,0,0,0,0,0,0,0,0,0,0
0,0,0,0,0,0,0,0,0,0,0,0,0,0,0,0,0,0,0,0
0,0,42,0,0,0,0,0,0,43,0,0,0,0,0,0,0,0,0,0
0,0,42,0,0,0,0,0,0,43,43,0,0,0,0,0,0,43,0,0
0,0,0,0,0,0,0,0,0,0,0,0,0,0,0,0,0,0,0,0
0,0,0,0,0,0,0,0,0,0,0,0,0,0,0,0,0,0,0,0
0,0,0,0,0,0,0,0,0,0,0,0,0,0,0,0,0,0,0,0
0,0,0,0,0,0,0,0,0,0,0,0,0,0,0,0,0,0,0,0
0,0,0,0,0,0,0,0,0,0,0,0,0,0,0,0,0,0,0,0
0,0,0,0,0,0,0,0,0,0,0,0,0,0,0,0,0,0,0,0
0,0,43,0,0,0,0,0,0,42,42,0,0,0,0,0,0,43,0,0
0,0,0,0,0,0,0,0,0,0,0,0,0,0,0,0,0,0,0,0
0,0,0,0,0,0,0,0,0,0,0,0,0,0,0,0,0,0,0,0
:endlayer
layer: 17
0,0,0,0,0,0,0,0,0,0,0,0,0,0,0,0,0,0,0,0
0,0,0,0,0,0,0,0,0,0,0,0,0,0,0,0,0,0,0,0
0,0,46,52,0,0,0,0,51,44,0,0,0,0,0,0,0,0,0,0
0,0,54,0,0,0,0,0,0,54,0,0,0,0,0,0,0,0,0,0
0,0,0,0,0,0,0,0,0,0,0,0,0,0,0,0,0,0,0,0
0,0,0,0,0,0,0,0,0,0,0,0,0,0,0,0,0,0,0,0
0,0,0,0,0,0,0,0,0,0,0,0,0,0,0,0,0,0,0,0
0,0,0,0,0,0,0,0,0,0,0,0,0,0,0,0,0,0,0,0
0,0,53,0,0,0,0,0,0,53,0,0,0,0,0,0,0,0,0,0
0,0,42,52,0,0,0,0,51,43,0,0,0,0,0,0,0,0,0,0
0,0,44,52,0,0,0,0,51,43,43,52,0,0,0,0,51,43,0,0
0,0,54,0,0,0,0,0,0,54,54,0,0,0,0,0,0,54,0,0
0,0,0,0,0,0,0,0,0,0,0,0,0,0,0,0,0,0,0,0
0,0,0,0,0,0,0,0,0,0,0,0,0,0,0,0,0,0,0,0
0,0,0,0,0,0,0,0,0,0,0,0,0,0,0,0,0,0,0,0
0,0,0,0,0,0,0,0,0,0,0,0,0,0,0,0,0,0,0,0
0,0,53,0,0,0,0,0,0,53,53,0,0,0,0,0,0,53,0,0
0,0,43,52,0,0,0,0,51,46,43,52,0,0,0,0,51,42,0,0
0,0,0,0,0,0,0,0,0,0,0,0,0,0,0,0,0,0,0,0
0,0,0,0,0,0,0,0,0,0,0,0,0,0,0,0,0,0,0,0
:endlayer
layer: 18
0,0,0,0,0,0,0,0,0,0,0,0,0,0,0,0,0,0,0,0
0,0,0,0,0,0,0,0,0,0,0,0,0,0,0,0,0,0,0,0
0,0,43,43,52,0,0,51,43,42,0,0,0,0,0,0,0,0,0,0
0,0,44,0,0,0,0,0,0,46,0,0,0,0,0,0,0,0,0,0
0,0,54,0,0,0,0,0,0,54,0,0,0,0,0,0,0,0,0,0
0,0,0,0,0,0,0,0,0,0,0,0,0,0,0,0,0,0,0,0
0,0,0,0,0,0,0,0,0,0,0,0,0,0,0,0,0,0,0,0
0,0,53,0,0,0,0,0,0,53,0,0,0,0,0,0,0,0,0,0
0,0,43,0,0,0,0,0,0,42,0,0,0,0,0,0,0,0,0,0
0,0,42,44,52,0,0,51,43,44,0,0,0,0,0,0,0,0,0,0
0,0,44,42,52,0,0,51,42,42,46,43,52,0,0,51,44,42,0,0
0,0,42,0,0,0,0,0,0,44,42,0,0,0,0,0,0,43,0,0
0,0,54,0,0,0,0,0,0,54,54,0,0,0,0,0,0,54,0,0
0,0,0,0,0,0,0,0,0,0,0,0,0,0,0,0,0,0,0,0
0,0,0,0,0,0,0,0,0,0,0,0,0,0,0,0,0,0,0,0
0,0,53,0,0,0,0,0,0,53,53,0,0,0,0,0,0,53,0,0
0,0,43,0,0,0,0,0,0,43,43,0,0,0,0,0,0,44,0,0
0,0,43,43,52,0,0,51,43,43,46,43,52,0,0,51,44,42,0,0
0,0,0,0,0,0,0,0,0,0,0,0,0,0,0,0,0,0,0,0
0,0,0,0,0,0,0,0,0,0,0,0,0,0,0,0,0,0,0,0
:endlayer
layer: 19
0,0,0,0,0,0,0,0,0,0,0,0,0,0,0,0,0,0,0,0
0,0,0,0,0,0,0,0,0,0,0,0,0,0,0,0,0,0,0,0
0,0,8,0,0,0,0,0,0,50,0,0,0,0,0,0,0,0,0,0
0,0,55,0,0,0,0,0,0,0,0,0,0,0,0,0,0,0,0,0
0,0,8,0,0,0,0,0,0,55,0,0,0,0,0,0,0,0,0,0
0,0,0,0,0,0,0,0,0,8,0,0,0,0,0,0,0,0,0,0
0,0,0,0,0,0,0,0,0,8,0,0,0,0,0,0,0,0,0,0
0,0,0,0,0,0,0,0,0,0,0,0,0,0,0,0,0,0,0,0
0,0,0,0,0,0,0,0,0,0,0,0,0,0,0,0,0,0,0,0
0,0,42,8,0,0,0,8,8,8,0,0,0,0,0,0,0,0,0,0
0,0,8,8,0,55,55,8,8,8,43,8,55,0,8,8,0,55,0,0
0,0,55,0,0,0,0,0,0,0,8,0,0,0,0,0,0,0,0,0
0,0,0,0,0,0,0,0,0,8,0,0,0,0,0,0,0,8,0,0
0,0,0,0,0,0,0,0,0,0,8,0,0,0,0,0,0,0,0,0
0,0,8,0,0,0,0,0,0,0,0,0,0,0,0,0,0,0,0,0
0,0,0,0,0,0,0,0,0,0,0,0,0,0,0,0,0,8,0,0
0,0,0,0,0,0,0,0,0,8,8,0,0,0,0,0,0,0,0,0
0,0,8,8,0,0,0,0,0,55,8,8,8,8,0,8,55,55,0,0
0,0,0,0,0,0,0,0,0,0,0,0,0,0,0,0,0,0,0,0
0,0,0,0,0,0,0,0,0,0,0,0,0,0,0,0,0,0,0,0
:endlayer

#### RULES ####
rule:
plugin=vanillaBlocks
number=1
data:
JSON:{blockState:{blockName:"minecraft:dirt",properties:{variant:"dirt",snowy:"false"}}}
:enddata
:endrule

rule:
plugin=vanillaBlocks
number=2
data:
JSON:{blockState:{blockName:"minecraft:stone",properties:{variant:"stone"}}}
:enddata
:endrule

rule:
plugin=vanillaBlocks
number=3
data:
JSON:{blockState:{blockName:"minecraft:cobblestone"}}
:enddata
:endrule

rule:
plugin=vanillaBlocks
number=4
data:
JSON:{blockState:{blockName:"minecraft:netherrack"}}
:enddata
:endrule

rule:
plugin=vanillaSkull
number=5
data:
JSON:{blockState:{blockName:"minecraft:skull",properties:{nodrop:"false",facing:"up"}},skullRotation:8,teData:{Rot:0b,id:"minecraft:skull",SkullType:0b}}
:enddata
:endrule

rule:
plugin=inventory
number=6
data:
JSON:{blockState:{blockName:"minecraft:chest",properties:{facing:"north"}},lootLevel:0,teData:{Items:[],id:"minecraft:chest",Lock:""},inventoryData:{length:0,inventoryContents:[]},legacyFeatures:1b}
:enddata
:endrule

rule:
plugin=inventory
number=7
data:
JSON:{blockState:{blockName:"minecraft:chest",properties:{facing:"north"}},lootLevel:0,teData:{Items:[],id:"minecraft:chest",Lock:""},inventoryData:{length:0,inventoryContents:[]},legacyFeatures:1b}
:enddata
:endrule

rule:
plugin=vanillaBlocks
number=8
data:
JSON:{blockState:{blockName:"minecraft:stone_slab",properties:{half:"bottom",variant:"cobblestone"}}}
:enddata
:endrule

rule:
plugin=vanillaSkull
number=9
data:
JSON:{blockState:{blockName:"minecraft:skull",properties:{nodrop:"false",facing:"up"}},skullRotation:8,teData:{Rot:0b,id:"minecraft:skull",SkullType:0b}}
:enddata
:endrule

rule:
plugin=vanillaSkull
number=10
data:
JSON:{blockState:{blockName:"minecraft:skull",properties:{nodrop:"false",facing:"up"}},skullRotation:8,teData:{Rot:0b,id:"minecraft:skull",SkullType:0b}}
:enddata
:endrule

rule:
plugin=vanillaBlocks
number=11
data:
JSON:{blockState:{blockName:"minecraft:mossy_cobblestone"}}
:enddata
:endrule

rule:
plugin=vanillaBlocks
number=12
data:
JSON:{blockState:{blockName:"minecraft:wooden_slab",properties:{half:"bottom",variant:"oak"}}}
:enddata
:endrule

rule:
plugin=vanillaBlocks
number=13
data:
JSON:{blockState:{blockName:"minecraft:stone_stairs",properties:{half:"bottom",shape:"straight",facing:"west"}}}
:enddata
:endrule

rule:
plugin=vanillaBlocks
number=14
data:
JSON:{blockState:{blockName:"minecraft:bookshelf"}}
:enddata
:endrule

rule:
plugin=vanillaBlocks
number=15
data:
JSON:{blockState:{blockName:"minecraft:stone_slab",properties:{half:"top",variant:"cobblestone"}}}
:enddata
:endrule

rule:
plugin=vanillaBlocks
number=16
data:
JSON:{blockState:{blockName:"minecraft:cauldron",properties:{level:"3"}}}
:enddata
:endrule

rule:
plugin=vanillaBlocks
number=17
data:
JSON:{blockState:{blockName:"minecraft:stone_stairs",properties:{half:"bottom",shape:"straight",facing:"north"}}}
:enddata
:endrule

rule:
plugin=vanillaBlocks
number=18
data:
JSON:{blockState:{blockName:"minecraft:fire",properties:{east:"false",south:"false",north:"false",west:"false",up:"false",age:"15"}}}
:enddata
:endrule

rule:
plugin=vanillaSkull
number=19
data:
JSON:{blockState:{blockName:"minecraft:skull",properties:{nodrop:"false",facing:"up"}},skullRotation:8,teData:{Rot:0b,id:"minecraft:skull",SkullType:0b}}
:enddata
:endrule

rule:
plugin=inventory
number=20
data:
JSON:{blockState:{blockName:"minecraft:chest",properties:{facing:"west"}},lootLevel:0,teData:{Items:[],id:"minecraft:chest",Lock:""},inventoryData:{length:0,inventoryContents:[]},legacyFeatures:1b}
:enddata
:endrule

rule:
plugin=inventory
number=21
data:
JSON:{blockState:{blockName:"minecraft:brewing_stand",properties:{has_bottle_0:"false",has_bottle_1:"false",has_bottle_2:"false"}},lootLevel:0,teData:{Fuel:0b,Items:[],id:"minecraft:brewing_stand",BrewTime:0s,Lock:""},inventoryData:{length:0,inventoryContents:[]},legacyFeatures:0b}
:enddata
:endrule

rule:
plugin=vanillaBlocks
number=22
data:
JSON:{blockState:{blockName:"minecraft:iron_bars",properties:{east:"false",south:"false",north:"false",west:"false"}}}
:enddata
:endrule

rule:
plugin=vanillaBlocks
number=23
data:
JSON:{blockState:{blockName:"minecraft:fence",properties:{east:"false",south:"false",north:"false",west:"false"}}}
:enddata
:endrule

rule:
plugin=vanillaBlocks
number=24
data:
JSON:{blockState:{blockName:"minecraft:stone_stairs",properties:{half:"top",shape:"straight",facing:"south"}}}
:enddata
:endrule

rule:
plugin=vanillaBlocks
number=25
data:
JSON:{blockState:{blockName:"minecraft:stone_stairs",properties:{half:"top",shape:"straight",facing:"west"}}}
:enddata
:endrule

rule:
plugin=vanillaBlocks
number=26
data:
JSON:{blockState:{blockName:"minecraft:stone_stairs",properties:{half:"top",shape:"straight",facing:"north"}}}
:enddata
:endrule

rule:
plugin=vanillaSkull
number=27
data:
JSON:{blockState:{blockName:"minecraft:skull",properties:{nodrop:"false",facing:"up"}},skullRotation:8,teData:{Rot:0b,id:"minecraft:skull",SkullType:0b}}
:enddata
:endrule

rule:
plugin=vanillaSkull
number=28
data:
JSON:{blockState:{blockName:"minecraft:skull",properties:{nodrop:"false",facing:"up"}},skullRotation:8,teData:{Rot:0b,id:"minecraft:skull",SkullType:0b}}
:enddata
:endrule

rule:
plugin=vanillaSkull
number=29
data:
JSON:{blockState:{blockName:"minecraft:skull",properties:{nodrop:"false",facing:"up"}},skullRotation:8,teData:{Rot:0b,id:"minecraft:skull",SkullType:0b}}
:enddata
:endrule

rule:
plugin=vanillaSkull
number=30
data:
JSON:{blockState:{blockName:"minecraft:skull",properties:{nodrop:"false",facing:"up"}},skullRotation:8,teData:{Rot:0b,id:"minecraft:skull",SkullType:0b}}
:enddata
:endrule

rule:
plugin=vanillaSkull
number=31
data:
JSON:{blockState:{blockName:"minecraft:skull",properties:{nodrop:"false",facing:"up"}},skullRotation:8,teData:{Rot:0b,id:"minecraft:skull",SkullType:0b}}
:enddata
:endrule

rule:
plugin=vanillaSkull
number=32
data:
JSON:{blockState:{blockName:"minecraft:skull",properties:{nodrop:"false",facing:"up"}},skullRotation:8,teData:{Rot:0b,id:"minecraft:skull",SkullType:0b}}
:enddata
:endrule

rule:
plugin=vanillaSkull
number=33
data:
JSON:{blockState:{blockName:"minecraft:skull",properties:{nodrop:"false",facing:"up"}},skullRotation:8,teData:{Rot:0b,id:"minecraft:skull",SkullType:0b}}
:enddata
:endrule

rule:
plugin=vanillaBlocks
number=34
data:
JSON:{blockState:{blockName:"minecraft:stone_stairs",properties:{half:"bottom",shape:"straight",facing:"east"}}}
:enddata
:endrule

rule:
plugin=vanillaSkull
number=35
data:
JSON:{blockState:{blockName:"minecraft:skull",properties:{nodrop:"false",facing:"up"}},skullRotation:8,teData:{Rot:0b,id:"minecraft:skull",SkullType:0b}}
:enddata
:endrule

rule:
plugin=vanillaSkull
number=36
data:
JSON:{blockState:{blockName:"minecraft:skull",properties:{nodrop:"false",facing:"up"}},skullRotation:8,teData:{Rot:0b,id:"minecraft:skull",SkullType:0b}}
:enddata
:endrule

rule:
plugin=vanillaSkull
number=37
data:
JSON:{blockState:{blockName:"minecraft:skull",properties:{nodrop:"false",facing:"up"}},skullRotation:8,teData:{Rot:0b,id:"minecraft:skull",SkullType:0b}}
:enddata
:endrule

rule:
plugin=inventory
number=38
data:
JSON:{blockState:{blockName:"minecraft:chest",properties:{facing:"east"}},lootLevel:0,teData:{Items:[],id:"minecraft:chest",Lock:""},inventoryData:{length:0,inventoryContents:[]},legacyFeatures:1b}
:enddata
:endrule

rule:
plugin=vanillaSkull
number=39
data:
JSON:{blockState:{blockName:"minecraft:skull",properties:{nodrop:"false",facing:"up"}},skullRotation:8,teData:{Rot:0b,id:"minecraft:skull",SkullType:0b}}
:enddata
:endrule

rule:
plugin=vanillaSkull
number=40
data:
JSON:{blockState:{blockName:"minecraft:skull",properties:{nodrop:"false",facing:"up"}},skullRotation:8,teData:{Rot:0b,id:"minecraft:skull",SkullType:0b}}
:enddata
:endrule

rule:
plugin=vanillaSkull
number=41
data:
JSON:{blockState:{blockName:"minecraft:skull",properties:{nodrop:"false",facing:"up"}},skullRotation:8,teData:{Rot:0b,id:"minecraft:skull",SkullType:0b}}
:enddata
:endrule

rule:
plugin=vanillaBlocks
number=42
data:
JSON:{blockState:{blockName:"minecraft:monster_egg",properties:{variant:"stone_brick"}}}
:enddata
:endrule

rule:
plugin=vanillaBlocks
number=43
data:
JSON:{blockState:{blockName:"minecraft:stonebrick",properties:{variant:"mossy_stonebrick"}}}
:enddata
:endrule

rule:
plugin=vanillaBlocks
number=44
data:
JSON:{blockState:{blockName:"minecraft:stonebrick",properties:{variant:"stonebrick"}}}
:enddata
:endrule

rule:
plugin=vanillaBlocks
number=45
data:
JSON:{blockState:{blockName:"minecraft:grass",properties:{snowy:"false"}}}
:enddata
:endrule

rule:
plugin=vanillaBlocks
number=46
data:
JSON:{blockState:{blockName:"minecraft:stonebrick",properties:{variant:"cracked_stonebrick"}}}
:enddata
:endrule

rule:
plugin=vanillaBlocks
number=47
data:
JSON:{blockState:{blockName:"minecraft:tallgrass",properties:{type:"tall_grass"}}}
:enddata
:endrule

rule:
plugin=vanillaBlocks
number=48
data:
JSON:{blockState:{blockName:"minecraft:log",properties:{variant:"oak",axis:"y"}}}
:enddata
:endrule

rule:
plugin=vanillaBlocks
number=49
data:
JSON:{blockState:{blockName:"minecraft:leaves",properties:{check_decay:"false",decayable:"true",variant:"oak"}}}
:enddata
:endrule

rule:
plugin=vanillaBlocks
number=50
data:
JSON:{blockState:{blockName:"minecraft:stonebrick",properties:{variant:"chiseled_stonebrick"}}}
:enddata
:endrule

rule:
plugin=vanillaBlocks
number=51
data:
JSON:{blockState:{blockName:"minecraft:stone_brick_stairs",properties:{half:"top",shape:"straight",facing:"east"}}}
:enddata
:endrule

rule:
plugin=vanillaBlocks
number=52
data:
JSON:{blockState:{blockName:"minecraft:stone_brick_stairs",properties:{half:"top",shape:"straight",facing:"west"}}}
:enddata
:endrule

rule:
plugin=vanillaBlocks
number=53
data:
JSON:{blockState:{blockName:"minecraft:stone_brick_stairs",properties:{half:"top",shape:"straight",facing:"south"}}}
:enddata
:endrule

rule:
plugin=vanillaBlocks
number=54
data:
JSON:{blockState:{blockName:"minecraft:stone_brick_stairs",properties:{half:"top",shape:"straight",facing:"north"}}}
:enddata
:endrule

rule:
plugin=vanillaBlocks
number=55
data:
JSON:{blockState:{blockName:"minecraft:stone_slab",properties:{half:"bottom",variant:"stone_brick"}}}
:enddata
:endrule

#### ENTITIES ####
