# Ancient Warfare Structure Template File
# Auto-generated structure template file. created on: 1/4/2019 at: 21:31:9
# Lines beginning with # denote comments

header:
version=2.8
name=BarbarianSwordGodTempleHuge
mods=
size=57,124,42
offset=28,15,41
:endheader

#### VALIDATION ####
validation:
type=ground
survival=false
worldGenEnabled=true
unique=false
preserveBlocks=false
selectionWeight=100
clusterValue=50
minDuplicateDistance=1000
dimensionWhiteList=true
dimensionList=0
biomeWhiteList=true
biomeList=traverse:rocky_plains,minecraft:taiga
leveling=20
fill=20
border=20
blockSwap=false
:endvalidation

#### LAYERS ####
layer: 0
1,1,1,1,1,1,1,1,1,1,1,1,1,1,1,1,1,1,1,1,1,1,1,1,1,1,1,1,1,1,1,1,1,1,1,1,1,1,1,1,1,1,1,1,1,1,1,1,1,1,1,1,1,1,1,1,1
1,1,1,1,1,1,1,1,1,1,1,1,1,1,1,1,1,1,1,1,1,1,1,1,1,1,1,1,1,1,1,1,1,1,1,1,1,1,1,1,1,1,1,1,1,1,1,1,1,1,1,1,1,1,1,1,1
1,1,1,1,1,1,1,1,1,1,1,1,1,1,1,1,1,1,1,1,1,1,1,1,1,1,1,1,1,1,1,1,1,1,1,1,1,1,1,1,1,1,1,1,1,1,1,1,1,1,1,1,1,1,1,1,1
1,1,1,1,1,1,1,1,1,1,1,1,1,1,1,1,1,1,1,1,1,1,1,1,1,1,1,1,1,1,1,1,1,1,1,1,1,1,1,1,1,1,1,1,1,1,1,1,1,1,1,1,1,1,1,1,1
1,1,1,1,1,1,1,1,1,1,1,1,1,1,1,1,1,1,1,1,1,1,1,1,1,1,1,1,1,1,1,1,1,1,1,1,1,1,1,1,1,1,1,1,1,1,1,1,1,1,1,1,1,1,1,1,1
1,1,1,1,1,1,1,1,1,1,1,1,1,1,1,1,1,1,1,1,1,1,1,1,1,1,1,1,1,1,1,1,1,1,1,1,1,1,1,1,1,1,1,1,1,1,1,1,1,1,1,1,1,1,1,1,1
1,1,1,1,1,1,1,1,1,1,1,1,1,1,1,1,1,1,1,1,1,1,1,1,1,1,1,1,1,1,1,1,1,1,1,1,1,1,1,1,1,1,1,1,1,1,1,1,1,1,1,1,1,1,1,1,1
1,1,1,1,1,1,1,1,1,1,1,1,1,1,1,1,1,1,1,1,1,1,1,1,1,1,1,1,1,1,1,1,1,1,1,1,1,1,1,1,1,1,1,1,1,1,1,1,1,1,1,1,1,1,1,1,1
1,1,1,1,1,1,1,1,1,1,1,1,1,1,1,1,1,1,1,1,1,1,1,1,1,1,1,1,1,1,1,1,1,1,1,1,1,1,1,1,1,1,1,1,1,1,1,1,1,1,1,1,1,1,1,1,1
1,1,1,1,1,1,1,1,1,1,1,1,1,1,1,1,1,1,1,1,1,1,1,1,1,1,1,1,1,1,1,1,1,1,1,1,1,1,1,1,1,1,1,1,1,1,1,1,1,1,1,1,1,1,1,1,1
1,1,1,1,1,1,1,1,1,1,1,1,1,1,1,1,1,1,1,1,1,1,1,1,1,1,1,1,1,1,1,1,1,1,1,1,1,1,1,1,1,1,1,1,1,1,1,1,1,1,1,1,1,1,1,1,1
1,1,1,1,1,1,1,1,1,1,1,1,1,1,1,1,1,1,1,1,1,1,1,1,1,1,1,1,1,1,1,1,1,1,1,1,1,1,1,1,1,1,1,1,1,1,1,1,1,1,1,1,1,1,1,1,1
1,1,1,1,1,1,1,1,1,1,1,1,1,1,1,1,1,1,1,1,1,1,1,1,1,1,1,1,1,1,1,1,1,1,1,1,1,1,1,1,1,1,1,1,1,1,1,1,1,1,1,1,1,1,1,1,1
1,1,1,1,1,1,1,1,1,1,1,1,1,1,1,1,1,1,1,1,1,1,1,1,1,1,1,1,1,1,1,1,1,1,1,1,1,1,1,1,1,1,1,1,1,1,1,1,1,1,1,1,1,1,1,1,1
1,1,1,1,1,1,1,1,1,1,1,1,1,1,1,1,1,1,1,1,1,1,1,1,1,1,1,1,1,1,1,1,1,1,1,1,1,1,1,1,1,1,1,1,1,1,1,1,1,1,1,1,1,1,1,1,1
1,1,1,1,1,1,1,1,1,1,1,1,1,1,1,1,1,1,1,1,1,1,1,1,1,1,1,1,1,1,1,1,1,1,1,1,1,1,1,1,1,1,1,1,1,1,1,1,1,1,1,1,1,1,1,1,1
1,1,1,1,1,1,1,1,1,1,1,1,1,1,1,1,1,1,1,1,1,1,1,1,1,1,1,1,1,1,1,1,1,1,1,1,1,1,1,1,1,1,1,1,1,1,1,1,1,1,1,1,1,1,1,1,1
1,1,1,1,1,1,1,1,1,1,1,1,1,1,1,1,1,1,1,1,1,1,1,1,1,1,1,1,1,1,1,1,1,1,1,1,1,1,1,1,1,1,1,1,1,1,1,1,1,1,1,1,1,1,1,1,1
1,1,1,1,1,1,1,1,1,1,1,1,1,1,1,1,1,1,1,1,1,1,1,1,1,1,1,1,1,1,1,1,1,1,1,1,1,1,1,1,1,1,1,1,1,1,1,1,1,1,1,1,1,1,1,1,1
1,1,1,1,1,1,1,1,1,1,1,1,1,1,1,1,1,1,1,1,1,1,1,1,1,1,1,1,1,1,1,1,1,1,1,1,1,1,1,1,1,1,1,1,1,1,1,1,1,1,1,1,1,1,1,1,1
1,1,1,1,1,1,1,1,1,1,1,1,1,1,1,1,1,1,1,1,1,1,1,1,1,1,1,1,1,1,1,1,1,1,1,1,1,1,1,1,1,1,1,1,1,1,1,1,1,1,1,1,1,1,1,1,1
1,1,1,1,1,1,1,1,1,1,1,1,1,1,1,1,1,1,1,1,1,1,1,1,1,1,1,1,1,1,1,1,1,1,1,1,1,1,1,1,1,1,1,1,1,1,1,1,1,1,1,1,1,1,1,1,1
1,1,1,1,1,1,1,1,1,1,1,1,1,1,1,1,1,1,1,1,1,1,1,1,1,1,1,1,1,1,1,1,1,1,1,1,1,1,1,1,1,1,1,1,1,1,1,1,1,1,1,1,1,1,1,1,1
1,1,1,1,1,1,1,1,1,1,1,1,2,3,2,1,1,1,1,1,1,1,1,1,1,1,1,1,1,1,1,1,1,1,1,1,1,1,1,1,1,1,1,1,1,1,1,1,1,1,1,1,1,1,1,1,1
1,1,1,1,1,1,1,1,1,1,1,1,2,4,2,1,1,1,1,1,1,1,1,1,1,1,1,1,1,1,1,1,1,1,1,1,1,1,1,1,1,1,1,1,1,1,1,1,1,1,1,1,1,1,1,1,1
1,1,1,1,1,1,1,1,1,1,1,1,2,5,2,1,1,1,1,1,1,1,1,1,1,1,1,1,1,1,1,1,1,1,1,1,1,1,1,1,1,1,1,1,1,1,1,1,1,1,1,1,1,1,1,1,1
1,1,1,1,1,1,1,1,1,1,1,1,1,2,2,1,1,1,1,1,1,1,1,1,1,1,1,1,1,1,1,1,1,1,1,1,1,1,1,1,1,1,1,1,1,1,1,1,1,1,1,1,1,1,1,1,1
1,1,1,1,1,1,1,1,1,1,1,1,1,1,1,1,1,1,1,1,1,1,1,1,1,1,1,1,1,1,1,1,1,1,1,1,1,1,1,1,1,1,1,1,1,1,1,1,1,1,1,1,1,1,1,1,1
1,1,1,1,1,1,1,1,1,1,1,1,1,1,1,1,1,1,1,1,1,1,1,1,1,1,1,1,1,1,1,1,1,1,1,1,1,1,1,1,1,1,1,1,1,1,1,1,1,1,1,1,1,1,1,1,1
1,1,1,1,1,1,1,1,1,1,1,1,1,1,1,1,1,1,1,1,1,1,1,1,1,1,1,1,1,1,1,1,1,1,1,1,1,1,1,1,1,1,1,1,1,1,1,1,1,1,1,1,1,1,1,1,1
1,1,1,1,1,1,1,1,1,1,1,1,1,1,1,1,1,1,1,1,1,1,1,1,1,1,1,1,1,1,1,1,1,1,1,1,1,1,1,1,1,1,1,1,1,1,1,1,1,1,1,1,1,1,1,1,1
1,1,1,1,1,1,1,1,1,1,1,1,1,1,1,1,1,1,1,1,1,1,1,1,1,1,1,1,1,1,1,1,1,1,1,1,1,1,1,1,1,1,1,1,1,1,1,1,1,1,1,1,1,1,1,1,1
1,1,1,1,1,1,1,1,1,1,1,1,1,1,1,1,1,1,1,1,1,1,1,1,1,1,1,1,1,1,1,1,1,1,1,1,1,1,1,1,1,1,1,1,1,1,1,1,1,1,1,1,1,1,1,1,1
1,1,1,1,1,1,1,1,1,1,1,1,1,1,1,1,1,1,1,1,1,1,1,1,1,1,1,1,1,1,1,1,1,1,1,1,1,1,1,1,1,1,1,1,1,1,1,1,1,1,1,1,1,1,1,1,1
1,1,1,1,1,1,1,1,1,1,1,1,1,1,1,1,1,1,1,1,1,1,1,1,1,1,1,1,1,1,1,1,1,1,1,1,1,1,1,1,1,1,1,1,1,1,1,1,1,1,1,1,1,1,1,1,1
1,1,1,1,1,1,1,1,1,1,1,1,1,1,1,1,1,1,1,1,1,1,1,1,1,1,1,1,1,1,1,1,1,1,1,1,1,1,1,1,1,1,1,1,1,1,1,1,1,1,1,1,1,1,1,1,1
1,1,1,1,1,1,1,1,1,1,1,1,1,1,1,1,1,1,1,1,1,1,1,1,1,1,1,1,1,1,1,1,1,1,1,1,1,1,1,1,1,1,1,1,1,1,1,1,1,1,1,1,1,1,1,1,1
1,1,1,1,1,1,1,1,1,1,1,1,1,1,1,1,1,1,1,1,1,1,1,1,1,1,1,1,1,1,1,1,1,1,1,1,1,1,1,1,1,1,1,1,1,1,1,1,1,1,1,1,1,1,1,1,1
1,1,1,1,1,1,1,1,1,1,1,1,1,1,1,1,1,1,1,1,1,1,1,1,1,1,1,1,1,1,1,1,1,1,1,1,1,1,1,1,1,1,1,1,1,1,1,1,1,1,1,1,1,1,1,1,1
1,1,1,1,1,1,1,1,1,1,1,1,1,1,1,1,1,1,1,1,1,1,1,1,1,1,1,1,1,1,1,1,1,1,1,1,1,1,1,1,1,1,1,1,1,1,1,1,1,1,1,1,1,1,1,1,1
1,1,1,1,1,1,1,1,1,1,1,1,1,1,1,1,1,1,1,1,1,1,1,1,1,1,1,1,1,1,1,1,1,1,1,1,1,1,1,1,1,1,1,1,1,1,1,1,1,1,1,1,1,1,1,1,1
1,1,1,1,1,1,1,1,1,1,1,1,1,1,1,1,1,1,1,1,1,1,1,1,1,1,1,1,1,1,1,1,1,1,1,1,1,1,1,1,1,1,1,1,1,1,1,1,1,1,1,1,1,1,1,1,1
:endlayer
layer: 1
1,1,1,1,1,1,1,1,1,1,1,1,1,1,1,1,1,1,1,1,1,1,1,1,1,1,1,1,1,1,1,1,1,1,1,1,1,1,1,1,1,1,1,1,1,1,1,1,1,1,1,1,1,1,1,1,1
1,1,1,1,1,1,1,1,1,1,1,1,1,1,1,1,1,1,1,1,1,1,1,1,1,1,1,1,1,1,1,1,1,1,1,1,1,1,1,1,1,1,1,1,1,1,1,1,1,1,1,1,1,1,1,1,1
1,1,1,1,1,1,1,1,1,1,1,1,1,1,1,1,1,1,1,1,1,1,1,1,1,1,1,1,1,1,1,1,1,1,1,1,1,1,1,1,1,1,1,1,1,1,1,1,1,1,1,1,1,1,1,1,1
1,1,1,1,1,1,1,1,1,1,1,1,1,1,1,1,1,1,1,1,1,1,1,1,1,1,1,1,1,1,1,1,1,1,1,1,1,1,1,1,1,1,1,1,1,1,1,1,1,1,1,1,1,1,1,1,1
1,1,1,1,1,1,1,1,1,1,1,1,1,1,1,1,1,1,1,1,1,1,1,1,1,1,1,1,1,1,1,1,1,1,1,1,1,1,1,1,1,1,1,1,1,1,1,1,1,1,1,1,1,1,1,1,1
1,1,1,1,1,1,1,1,1,1,1,1,1,1,1,1,1,1,1,1,1,1,1,1,1,1,1,1,1,1,1,1,1,1,1,1,1,1,1,1,1,1,1,1,1,1,1,1,1,1,1,1,1,1,1,1,1
1,1,1,1,1,1,1,1,1,1,1,1,1,1,1,1,1,1,1,1,1,1,1,1,1,1,1,1,1,1,1,1,1,1,1,1,1,1,1,1,1,1,1,1,1,1,1,1,1,1,1,1,1,1,1,1,1
1,1,1,1,1,1,1,1,1,1,1,1,1,1,1,1,1,1,1,1,1,1,1,1,1,1,1,1,1,1,1,1,1,1,1,1,1,1,1,1,1,1,1,1,1,1,1,1,1,1,1,1,1,1,1,1,1
1,1,1,1,1,1,1,1,1,1,1,1,1,1,1,1,1,1,1,1,1,1,1,1,1,1,1,1,1,1,1,1,1,1,1,1,1,1,1,1,1,1,1,1,1,1,1,1,1,1,1,1,1,1,1,1,1
1,1,1,1,1,1,1,1,1,1,1,1,1,1,1,1,1,1,1,1,1,1,1,1,1,1,1,1,1,1,1,1,1,1,1,1,1,1,1,1,1,1,1,1,1,1,1,1,1,1,1,1,1,1,1,1,1
1,1,1,1,1,1,1,1,1,1,1,1,1,1,1,1,1,1,1,1,1,1,1,1,1,1,1,1,1,1,1,1,1,1,1,1,1,1,1,1,1,1,1,1,1,1,1,1,1,1,1,1,1,1,1,1,1
1,1,1,1,1,1,1,1,1,1,1,1,1,1,1,1,1,1,1,1,1,1,1,1,1,1,1,1,1,1,1,1,1,1,1,1,1,1,1,1,1,1,1,1,1,1,1,1,1,1,1,1,1,1,1,1,1
1,1,1,1,1,1,1,1,1,1,1,1,1,1,1,1,1,1,1,1,1,1,1,1,1,1,1,1,1,1,1,1,1,1,1,1,1,1,1,1,1,1,1,1,1,1,1,1,1,1,1,1,1,1,1,1,1
1,1,1,1,1,1,1,1,1,1,1,1,1,1,1,1,1,1,1,1,1,1,1,1,1,1,1,1,1,1,1,1,1,1,1,1,1,1,1,1,1,1,1,1,1,1,1,1,1,1,1,1,1,1,1,1,1
1,1,1,1,1,1,1,1,1,1,1,1,1,1,1,1,1,1,1,1,1,1,1,1,1,1,1,1,1,1,1,1,1,1,1,1,1,1,1,1,1,1,1,1,1,1,1,1,1,1,1,1,1,1,1,1,1
1,1,1,1,1,1,1,1,1,1,1,1,1,1,1,1,1,1,1,1,1,1,1,1,1,1,1,1,1,1,1,1,1,1,1,1,1,1,1,1,1,1,1,1,1,1,1,1,1,1,1,1,1,1,1,1,1
1,1,1,1,1,1,1,1,1,1,1,1,1,1,1,1,1,1,1,1,1,1,1,1,1,1,1,1,1,1,1,1,1,1,1,1,1,1,1,1,1,1,1,1,1,1,1,1,1,1,1,1,1,1,1,1,1
1,1,1,1,1,1,1,1,1,1,1,1,1,1,1,1,1,1,1,1,1,1,1,1,1,1,1,1,1,1,1,1,1,1,1,1,1,1,1,1,1,1,1,1,1,1,1,1,1,1,1,1,1,1,1,1,1
1,1,1,1,1,1,1,1,1,1,1,1,1,1,1,1,1,1,1,1,1,1,1,1,1,1,1,1,1,1,1,1,1,1,1,1,1,1,1,1,1,1,1,1,1,1,1,1,1,1,1,1,1,1,1,1,1
1,1,1,1,1,1,1,1,1,1,1,1,1,1,1,1,1,1,1,1,1,1,1,1,1,1,1,1,1,1,1,1,1,1,1,1,1,1,1,1,1,1,1,1,1,1,1,1,1,1,1,1,1,1,1,1,1
1,1,1,1,1,1,1,1,1,1,1,1,1,1,1,1,1,1,1,1,1,1,1,1,1,1,1,1,1,1,1,1,1,1,1,1,1,1,1,1,1,1,1,1,1,1,1,1,1,1,1,1,1,1,1,1,1
1,1,1,1,1,1,1,1,1,1,1,1,1,1,1,1,1,1,1,1,1,1,1,1,1,1,1,1,1,1,1,1,1,1,1,1,1,1,1,1,1,1,1,1,1,1,1,1,1,1,1,1,1,1,1,1,1
1,1,1,1,1,1,1,1,1,1,1,1,1,1,1,1,1,1,1,1,1,1,1,1,1,1,1,1,1,1,1,1,1,1,1,1,1,1,1,1,1,1,1,1,1,1,1,1,1,1,1,1,1,1,1,1,1
1,1,1,1,1,1,1,1,1,1,1,1,2,2,2,1,1,1,1,1,1,1,1,1,1,1,1,1,1,1,1,1,1,1,1,1,1,1,1,1,1,1,1,1,1,1,1,1,1,1,1,1,1,1,1,1,1
1,1,1,1,1,1,1,1,1,1,1,1,2,2,2,1,1,1,1,1,1,1,1,1,1,1,1,1,1,1,1,1,1,1,1,1,1,1,1,1,1,1,1,1,1,1,1,1,1,1,1,1,1,1,1,1,1
1,1,1,1,1,1,1,1,1,1,1,2,2,2,2,1,1,1,1,1,1,1,1,1,1,1,1,1,1,1,1,1,1,1,1,1,1,1,1,1,1,1,1,1,1,1,1,1,1,1,1,1,1,1,1,1,1
1,1,1,1,1,1,1,1,1,1,1,1,1,2,2,1,1,1,1,1,1,1,1,1,1,1,1,1,1,1,1,1,1,1,1,1,1,1,1,1,1,1,1,1,1,1,1,1,1,1,1,1,1,1,1,1,1
1,1,1,1,1,1,1,1,1,1,1,1,1,1,1,1,1,1,1,1,1,1,1,1,1,1,1,1,1,1,1,1,1,1,1,1,1,1,1,1,1,1,1,1,1,1,1,1,1,1,1,1,1,1,1,1,1
1,1,1,1,1,1,1,1,1,1,1,1,1,1,1,1,1,1,1,1,1,1,1,1,1,1,1,1,1,1,1,1,1,1,1,1,1,1,1,1,1,1,1,1,1,1,1,1,1,1,1,1,1,1,1,1,1
1,1,1,1,1,1,1,1,1,1,1,1,1,1,1,1,1,1,1,1,1,1,1,1,1,1,1,1,1,1,1,1,1,1,1,1,1,1,1,1,1,1,1,1,1,1,1,1,1,1,1,1,1,1,1,1,1
1,1,1,1,1,1,1,1,1,1,1,1,1,1,1,1,1,1,1,1,1,1,1,1,1,1,1,1,1,1,1,1,1,1,1,1,1,1,1,1,1,1,1,1,1,1,1,1,1,1,1,1,1,1,1,1,1
1,1,1,1,1,1,1,1,1,1,1,1,1,1,1,1,1,1,1,1,1,1,1,1,1,1,1,1,1,1,1,1,1,1,1,1,1,1,1,1,1,1,1,1,1,1,1,1,1,1,1,1,1,1,1,1,1
1,1,1,1,1,1,1,1,1,1,1,1,1,1,1,1,1,1,1,1,1,1,1,1,1,1,1,1,1,1,1,1,1,1,1,1,1,1,1,1,1,1,1,1,1,1,1,1,1,1,1,1,1,1,1,1,1
1,1,1,1,1,1,1,1,1,1,1,1,1,1,1,1,1,1,1,1,1,1,1,1,1,1,1,1,1,1,1,1,1,1,1,1,1,1,1,1,1,1,1,1,1,1,1,1,1,1,1,1,1,1,1,1,1
1,1,1,1,1,1,1,1,1,1,1,1,1,1,1,1,1,1,1,1,1,1,1,1,1,1,1,1,1,1,1,1,1,1,6,1,1,1,1,1,1,1,1,1,1,1,1,1,1,1,1,1,1,1,1,1,1
1,1,1,1,1,1,1,1,1,1,1,1,1,1,1,1,1,1,1,1,1,1,1,1,1,1,1,1,1,1,1,1,1,7,0,8,1,1,1,1,1,1,1,1,1,1,1,1,1,1,1,1,1,1,1,1,1
1,1,1,1,1,1,1,1,1,1,1,1,1,1,1,1,1,1,1,1,1,1,1,1,1,1,1,1,1,1,1,1,1,1,9,1,1,1,1,1,1,1,1,1,1,1,1,1,1,1,1,1,1,1,1,1,1
1,1,1,1,1,1,1,1,1,1,1,1,1,1,1,1,1,1,1,1,1,1,1,1,1,1,1,1,1,1,1,1,1,1,1,1,1,1,1,1,1,1,1,1,1,1,1,1,1,1,1,1,1,1,1,1,1
1,1,1,1,1,1,1,1,1,1,1,1,1,1,1,1,1,1,1,1,1,1,1,1,1,1,1,1,1,1,1,1,1,1,1,1,1,1,1,1,1,1,1,1,1,1,1,1,1,1,1,1,1,1,1,1,1
1,1,1,1,1,1,1,1,1,1,1,1,1,1,1,1,1,1,1,1,1,1,1,1,1,1,1,1,1,1,1,1,1,1,1,1,1,1,1,1,1,1,1,1,1,1,1,1,1,1,1,1,1,1,1,1,1
1,1,1,1,1,1,1,1,1,1,1,1,1,1,1,1,1,1,1,1,1,1,1,1,1,1,1,1,1,1,1,1,1,1,1,1,1,1,1,1,1,1,1,1,1,1,1,1,1,1,1,1,1,1,1,1,1
1,1,1,1,1,1,1,1,1,1,1,1,1,1,1,1,1,1,1,1,1,1,1,1,1,1,1,1,1,1,1,1,1,1,1,1,1,1,1,1,1,1,1,1,1,1,1,1,1,1,1,1,1,1,1,1,1
:endlayer
layer: 2
1,1,1,1,1,1,1,1,1,1,1,1,1,1,1,1,1,1,1,1,1,1,1,1,1,1,1,1,1,1,1,1,1,1,1,1,1,1,1,1,1,1,1,1,1,1,1,1,1,1,1,1,1,1,1,1,1
1,1,1,1,1,1,1,1,1,1,1,1,1,1,1,1,1,1,1,1,1,1,1,1,1,1,1,1,1,1,1,1,1,1,1,1,1,1,1,1,1,1,1,1,1,1,1,1,1,1,1,1,1,1,1,1,1
1,1,1,1,1,1,1,1,1,1,1,1,1,1,1,1,1,1,1,1,1,1,1,1,1,1,1,1,1,1,1,1,1,1,1,1,1,1,1,1,1,1,1,1,1,1,1,1,1,1,1,1,1,1,1,1,1
1,1,1,1,1,1,1,1,1,1,1,1,1,1,1,1,1,1,1,1,1,1,1,1,1,1,1,1,1,1,1,1,1,1,1,1,1,1,1,1,1,1,1,1,1,1,1,1,1,1,1,1,1,1,1,1,1
1,1,1,1,1,1,1,1,1,1,1,1,1,1,1,1,1,1,1,1,1,1,1,1,1,1,1,1,1,1,1,1,1,1,1,1,1,1,1,1,1,1,1,1,1,1,1,1,1,1,1,1,1,1,1,1,1
1,1,1,1,1,1,1,1,1,1,1,1,1,1,1,1,1,1,1,1,1,1,1,1,1,1,1,1,1,1,1,1,1,1,1,1,1,1,1,1,1,1,1,1,1,1,1,1,1,1,1,1,1,1,1,1,1
1,1,1,1,1,1,1,1,1,1,1,1,1,1,1,1,1,1,1,1,1,1,1,1,1,1,1,1,1,1,1,1,1,1,1,1,1,1,1,1,1,1,1,1,1,1,1,1,1,1,1,1,1,1,1,1,1
1,1,1,1,1,1,1,1,1,1,1,1,1,1,1,1,1,1,1,1,1,1,1,1,1,1,1,1,1,1,1,1,1,1,1,1,1,1,1,1,1,1,1,1,1,1,1,1,1,1,1,1,1,1,1,1,1
1,1,1,1,1,1,1,1,1,1,1,1,1,1,1,1,1,1,1,1,1,1,1,1,1,1,1,1,1,1,1,1,1,1,1,1,1,1,1,1,1,1,1,1,1,1,1,1,1,1,1,1,1,1,1,1,1
1,1,1,1,1,1,1,1,1,1,1,1,1,1,1,1,1,1,1,1,1,1,1,1,1,1,1,1,1,1,1,1,1,1,1,1,1,1,1,1,1,1,1,1,1,1,1,1,1,1,1,1,1,1,1,1,1
1,1,1,1,1,1,1,1,1,1,1,1,1,1,1,1,1,1,1,1,1,1,1,1,1,1,1,1,1,1,1,1,1,1,1,1,1,1,1,1,1,1,1,1,1,1,1,1,1,1,1,1,1,1,1,1,1
1,1,1,1,1,1,1,1,1,1,1,1,1,1,1,1,1,1,1,1,1,1,1,1,1,1,1,1,1,1,1,1,1,1,1,1,1,1,1,1,1,1,1,1,1,1,1,1,1,1,1,1,1,1,1,1,1
1,1,1,1,1,1,1,1,1,1,1,1,1,1,1,1,1,1,1,1,1,1,1,1,1,1,1,1,1,1,1,1,1,1,1,1,1,1,1,1,1,1,1,1,1,1,1,1,1,1,1,1,1,1,1,1,1
1,1,1,1,1,1,1,1,1,1,1,1,1,1,1,1,1,1,1,1,1,1,1,1,1,1,1,1,1,1,1,1,1,1,1,1,1,1,1,1,1,1,1,1,1,1,1,1,1,1,1,1,1,1,1,1,1
1,1,1,1,1,1,1,1,1,1,1,1,1,1,1,1,1,1,1,1,1,1,1,1,1,1,1,1,1,1,1,1,1,1,1,1,1,1,1,1,1,1,1,1,1,1,1,1,1,1,1,1,1,1,1,1,1
1,1,1,1,1,1,1,1,1,1,1,1,1,1,1,1,1,1,1,1,1,1,1,1,1,1,1,1,1,1,1,1,1,1,1,1,1,1,1,1,1,1,1,1,1,1,1,1,1,1,1,1,1,1,1,1,1
1,1,1,1,1,1,1,1,1,1,1,1,1,1,1,1,1,1,1,1,1,1,1,1,1,1,1,1,1,1,1,1,1,1,1,1,1,1,1,1,1,1,1,1,1,1,1,1,1,1,1,1,1,1,1,1,1
1,1,1,1,1,1,1,1,1,1,1,1,1,1,1,1,1,1,1,1,1,1,1,1,1,1,1,1,1,1,1,1,1,1,1,1,1,1,1,1,1,1,1,1,1,1,1,1,1,1,1,1,1,1,1,1,1
1,1,1,1,1,1,1,1,1,1,1,1,1,1,1,1,1,1,1,1,1,1,1,1,1,1,1,1,1,1,1,1,1,1,1,1,1,1,1,1,1,1,1,1,1,1,1,1,1,1,1,1,1,1,1,1,1
1,1,1,1,1,1,1,1,1,1,1,1,1,1,1,1,1,1,1,1,1,1,1,1,1,1,1,1,1,1,1,1,1,1,1,1,1,1,1,1,1,1,1,1,1,1,1,1,1,1,1,1,1,1,1,1,1
1,1,1,1,1,1,1,1,1,1,1,1,1,1,1,1,1,1,1,1,1,1,1,1,1,1,1,1,1,1,1,1,1,1,1,1,1,1,1,1,1,1,1,1,1,1,1,1,1,1,1,1,1,1,1,1,1
1,1,1,1,1,1,1,1,1,1,1,1,1,1,1,1,1,1,1,1,1,1,1,1,1,1,1,1,1,1,1,1,1,1,1,1,1,1,1,1,1,1,1,1,1,1,1,1,1,1,1,1,1,1,1,1,1
1,1,1,1,1,1,1,1,1,1,1,1,1,1,1,1,1,1,1,1,1,1,1,1,1,1,1,1,1,1,1,1,1,1,1,1,1,1,1,1,1,1,1,1,1,1,1,1,1,1,1,1,1,1,1,1,1
1,1,1,1,1,1,1,1,1,1,1,1,10,10,10,1,1,1,1,1,1,1,1,1,1,1,1,1,1,1,1,1,1,1,1,1,1,1,1,1,1,1,1,1,1,1,1,1,1,1,1,1,1,1,1,1,1
1,1,1,1,1,1,1,1,1,1,1,1,10,10,10,1,1,1,1,1,1,1,1,1,1,1,1,1,1,1,1,1,1,1,1,1,1,1,1,1,1,1,1,1,1,1,1,1,1,1,1,1,1,1,1,1,1
1,1,1,1,1,1,1,1,1,1,1,10,10,10,2,1,1,1,1,1,1,1,1,1,1,1,1,1,1,1,1,1,1,1,1,1,1,1,1,1,1,1,1,1,1,1,1,1,1,1,1,1,1,1,1,1,1
1,1,1,1,1,1,1,1,1,1,1,1,1,2,2,1,1,1,1,1,1,1,1,1,1,1,1,1,1,1,1,1,1,1,1,1,1,1,1,1,1,1,1,1,1,1,1,1,1,1,1,1,1,1,1,1,1
1,1,1,1,1,1,1,1,1,1,1,1,1,1,1,1,1,1,1,1,1,1,1,1,1,1,1,1,1,1,1,1,1,1,1,1,1,1,1,1,1,1,1,1,1,1,1,1,1,1,1,1,1,1,1,1,1
1,1,1,1,1,1,1,1,1,1,1,1,1,1,1,1,1,1,1,1,1,1,1,1,1,1,1,1,1,1,1,1,1,1,1,1,1,1,1,1,1,1,1,1,1,1,1,1,1,1,1,1,1,1,1,1,1
1,1,1,1,1,1,1,1,1,1,1,1,1,1,1,1,1,1,1,1,1,1,1,1,1,1,1,1,1,1,1,1,1,1,1,1,1,1,1,1,1,1,1,1,1,1,1,1,1,1,1,1,1,1,1,1,1
1,1,1,1,1,1,1,1,1,1,1,1,1,1,1,1,1,1,1,1,1,1,1,1,1,1,1,1,1,1,1,1,1,1,1,1,1,1,1,1,1,1,1,1,1,1,1,1,1,1,1,1,1,1,1,1,1
1,1,1,1,1,1,1,1,1,1,1,1,1,1,1,1,1,1,1,1,1,1,1,1,1,1,1,1,1,1,1,1,1,1,1,1,1,1,1,1,1,1,1,1,1,1,1,1,1,1,1,1,1,1,1,1,1
1,1,1,1,1,1,1,1,1,1,1,1,1,1,1,1,1,1,1,1,1,1,1,1,1,1,1,1,1,1,1,1,1,1,1,1,1,1,1,1,1,1,1,1,1,1,1,1,1,1,1,1,1,1,1,1,1
1,1,1,1,1,1,1,1,1,1,1,1,1,1,1,1,1,1,1,1,1,1,1,1,1,1,1,1,1,1,1,1,1,1,1,1,1,1,1,1,1,1,1,1,1,1,1,1,1,1,1,1,1,1,1,1,1
1,1,1,1,1,1,1,1,1,1,1,1,1,1,1,1,1,1,1,1,1,1,1,1,1,1,1,1,1,1,1,1,1,1,0,1,1,1,1,1,1,1,1,1,1,1,1,1,1,1,1,1,1,1,1,1,1
1,1,1,1,1,1,1,1,1,1,1,1,1,1,1,1,1,1,1,1,1,1,1,1,1,1,1,1,1,1,1,1,1,0,0,0,1,1,1,1,1,1,1,1,1,1,1,1,1,1,1,1,1,1,1,1,1
1,1,1,1,1,1,1,1,1,1,1,1,1,1,1,1,1,1,1,1,1,1,1,1,1,1,1,1,1,1,1,1,1,1,0,1,1,1,1,1,1,1,1,1,1,1,1,1,1,1,1,1,1,1,1,1,1
1,1,1,1,1,1,1,1,1,1,1,1,1,1,1,1,1,1,1,1,1,1,1,1,1,1,1,1,1,1,1,1,1,1,1,1,1,1,1,1,1,1,1,1,1,1,1,1,1,1,1,1,1,1,1,1,1
1,1,1,1,1,1,1,1,1,1,1,1,1,1,1,1,1,1,1,1,1,1,1,1,1,1,1,1,1,1,1,1,1,1,1,1,1,1,1,1,1,1,1,1,1,1,1,1,1,1,1,1,1,1,1,1,1
1,1,1,1,1,1,1,1,1,1,1,1,1,1,1,1,1,1,1,1,1,1,1,1,1,1,1,1,1,1,1,1,1,1,1,1,1,1,1,1,1,1,1,1,1,1,1,1,1,1,1,1,1,1,1,1,1
1,1,1,1,1,1,1,1,1,1,1,1,1,1,1,1,1,1,1,1,1,1,1,1,1,1,1,1,1,1,1,1,1,1,1,1,1,1,1,1,1,1,1,1,1,1,1,1,1,1,1,1,1,1,1,1,1
1,1,1,1,1,1,1,1,1,1,1,1,1,1,1,1,1,1,1,1,1,1,1,1,1,1,1,1,1,1,1,1,1,1,1,1,1,1,1,1,1,1,1,1,1,1,1,1,1,1,1,1,1,1,1,1,1
:endlayer
layer: 3
1,1,1,1,1,1,1,1,1,1,1,1,1,1,1,1,1,1,1,1,1,1,1,1,1,1,1,1,1,1,1,1,1,1,1,1,1,1,1,1,1,1,1,1,1,1,1,1,1,1,1,1,1,1,1,1,1
1,1,1,1,1,1,1,1,1,1,1,1,1,1,1,1,1,1,1,1,1,1,1,1,1,1,1,1,1,1,1,1,1,1,1,1,1,1,1,1,1,1,1,1,1,1,1,1,1,1,1,1,1,1,1,1,1
1,1,1,1,1,1,1,1,1,1,1,1,1,1,1,1,1,1,1,1,1,1,1,1,1,1,1,1,1,1,1,1,1,1,1,1,1,1,1,1,1,1,1,1,1,1,1,1,1,1,1,1,1,1,1,1,1
1,1,1,1,1,1,1,1,1,1,1,1,1,1,1,1,1,1,1,1,1,1,1,1,1,1,1,1,1,1,1,1,1,1,1,1,1,1,1,1,1,1,1,1,1,1,1,1,1,1,1,1,1,1,1,1,1
1,1,1,1,1,1,1,1,1,1,1,1,1,1,1,1,1,1,1,1,1,1,1,1,1,1,1,1,1,1,1,1,1,1,1,1,1,1,1,1,1,1,1,1,1,1,1,1,1,1,1,1,1,1,1,1,1
1,1,1,1,1,1,1,1,1,1,1,1,1,1,1,1,1,1,1,1,1,1,1,1,1,1,1,1,1,1,1,1,1,1,1,1,1,1,1,1,1,1,1,1,1,1,1,1,1,1,1,1,1,1,1,1,1
1,1,1,1,1,1,1,1,1,1,1,1,1,1,1,1,1,1,1,1,1,1,1,1,1,1,1,1,1,1,1,1,1,1,1,1,1,1,1,1,1,1,1,1,1,1,1,1,1,1,1,1,1,1,1,1,1
1,1,1,1,1,1,1,1,1,1,1,1,1,1,1,1,1,1,1,1,1,1,1,1,1,1,1,1,1,1,1,1,1,1,1,1,1,1,1,1,1,1,1,1,1,1,1,1,1,1,1,1,1,1,1,1,1
1,1,1,1,1,1,1,1,1,1,1,1,1,1,1,1,1,1,1,1,1,1,1,1,1,1,1,1,1,1,1,1,1,1,1,1,1,1,1,1,1,1,1,1,1,1,1,1,1,1,1,1,1,1,1,1,1
1,1,1,1,1,1,1,1,1,1,1,1,1,1,1,1,1,1,1,1,1,1,1,1,1,1,1,1,1,1,1,1,1,1,1,1,1,1,1,1,1,1,1,1,1,1,1,1,1,1,1,1,1,1,1,1,1
1,1,1,1,1,1,1,1,1,1,1,1,1,1,1,1,1,1,1,1,1,1,1,1,1,1,1,1,1,1,1,1,1,1,1,1,1,1,1,1,1,1,1,1,1,1,1,1,1,1,1,1,1,1,1,1,1
1,1,1,1,1,1,1,1,1,1,1,1,1,1,1,1,1,1,1,1,1,1,1,1,1,1,1,1,1,1,1,1,1,1,1,1,1,1,1,1,1,1,1,1,1,1,1,1,1,1,1,1,1,1,1,1,1
1,1,1,1,1,1,1,1,1,1,1,1,1,1,1,1,1,1,1,1,1,1,1,1,1,1,1,1,1,1,1,1,1,1,1,1,1,1,1,1,1,1,1,1,1,1,1,1,1,1,1,1,1,1,1,1,1
1,1,1,1,1,1,1,1,1,1,1,1,1,1,1,1,1,1,1,1,1,1,1,1,1,1,1,1,1,1,1,1,1,1,1,1,1,1,1,1,1,1,1,1,1,1,1,1,1,1,1,1,1,1,1,1,1
1,1,1,1,1,1,1,1,1,1,1,1,1,1,1,1,1,1,1,1,1,1,1,1,1,1,1,1,1,1,1,1,1,1,1,1,1,1,1,1,1,1,1,1,1,1,1,1,1,1,1,1,1,1,1,1,1
1,1,1,1,1,1,1,1,1,1,1,1,1,1,1,1,1,1,1,1,1,1,1,1,1,1,1,1,1,1,1,1,1,1,1,1,1,1,1,1,1,1,1,1,1,1,1,1,1,1,1,1,1,1,1,1,1
1,1,1,1,1,1,1,1,1,1,1,1,1,1,1,1,1,1,1,1,1,1,1,1,1,1,1,1,1,1,1,1,1,1,1,1,1,1,1,1,1,1,1,1,1,1,1,1,1,1,1,1,1,1,1,1,1
1,1,1,1,1,1,1,1,1,1,1,1,1,1,1,1,1,1,1,1,1,1,1,1,1,1,1,1,1,1,1,1,1,1,1,1,1,1,1,1,1,1,1,1,1,1,1,1,1,1,1,1,1,1,1,1,1
1,1,1,1,1,1,1,1,1,1,1,1,1,1,1,1,1,1,1,1,1,1,1,1,1,1,1,1,1,1,1,1,1,1,1,1,1,1,1,1,1,1,1,1,1,1,1,1,1,1,1,1,1,1,1,1,1
1,1,1,1,1,1,1,1,1,1,1,1,1,1,1,1,1,1,1,1,1,1,1,1,1,1,1,1,1,1,1,1,1,1,1,1,1,1,1,1,1,1,1,1,1,1,1,1,1,1,1,1,1,1,1,1,1
1,1,1,1,1,1,1,1,1,1,1,1,1,1,1,1,1,1,1,1,1,1,1,1,1,1,1,1,1,1,1,1,1,1,1,1,1,1,1,1,1,1,1,1,1,1,1,1,1,1,1,1,1,1,1,1,1
1,1,1,1,1,1,1,1,1,1,1,1,1,1,1,1,1,1,1,1,1,1,1,1,1,1,1,1,1,1,1,1,1,1,1,1,1,1,1,1,1,1,1,1,1,1,1,1,1,1,1,1,1,1,1,1,1
1,1,1,1,1,1,1,1,1,1,1,1,10,10,10,1,1,1,1,1,1,1,1,1,1,1,1,1,1,1,1,1,1,1,1,1,1,1,1,1,1,1,1,1,1,1,1,1,1,1,1,1,1,1,1,1,1
1,1,1,1,1,1,1,1,1,1,1,1,10,10,10,1,1,1,1,1,1,1,1,1,1,1,1,1,1,1,1,1,1,1,1,1,1,1,1,1,1,1,1,1,1,1,1,1,1,1,1,1,1,1,1,1,1
1,1,1,1,1,1,1,1,1,1,1,1,10,10,10,1,1,1,1,1,1,1,1,1,1,1,1,1,1,1,1,1,1,1,1,1,1,1,1,1,1,1,1,1,1,1,1,1,1,1,1,1,1,1,1,1,1
1,1,1,1,1,1,1,1,1,1,1,10,10,10,10,1,1,1,1,1,1,1,1,1,1,1,1,1,1,1,1,1,1,1,1,1,1,1,1,1,1,1,1,1,1,1,1,1,1,1,1,1,1,1,1,1,1
1,1,1,1,1,1,1,1,1,1,1,1,1,10,10,1,1,1,1,1,1,1,1,1,1,1,1,1,1,1,1,1,1,1,1,1,1,1,1,1,1,1,1,1,1,1,1,1,1,1,1,1,1,1,1,1,1
1,1,1,1,1,1,1,1,1,1,1,1,1,1,1,1,1,1,1,1,1,1,1,1,1,1,1,1,1,1,1,1,1,1,1,1,1,1,1,1,1,1,1,1,1,1,1,1,1,1,1,1,1,1,1,1,1
1,1,1,1,1,1,1,1,1,1,1,1,1,1,1,1,1,1,1,1,1,1,1,1,1,1,1,1,1,1,1,1,1,1,1,1,1,1,1,1,1,1,1,1,1,1,1,1,1,1,1,1,1,1,1,1,1
1,1,1,1,1,1,1,1,1,1,1,1,1,1,1,1,1,1,1,1,1,1,1,1,1,1,1,1,1,1,1,1,1,1,1,1,1,1,1,1,1,1,1,1,1,1,1,1,1,1,1,1,1,1,1,1,1
1,1,1,1,1,1,1,1,1,1,1,1,1,1,1,1,1,1,1,1,1,1,1,1,1,1,1,1,1,1,1,1,1,1,1,1,1,1,1,1,1,1,1,1,1,1,1,1,1,1,1,1,1,1,1,1,1
1,1,1,1,1,1,1,1,1,1,1,1,1,1,1,1,1,1,1,1,1,1,1,1,1,1,1,1,1,1,1,1,1,1,1,1,1,1,1,1,1,1,1,1,1,1,1,1,1,1,1,1,1,1,1,1,1
1,1,1,1,1,1,1,1,1,1,1,1,1,1,1,1,1,1,1,1,1,1,1,1,1,1,1,1,1,1,1,1,1,1,1,1,1,1,1,1,1,1,1,1,1,1,1,1,1,1,1,1,1,1,1,1,1
1,1,1,1,1,1,1,1,1,1,1,1,1,1,1,1,1,1,1,1,1,1,1,1,1,1,1,1,1,1,1,1,1,1,1,1,1,1,1,1,1,1,1,1,1,1,1,1,1,1,1,1,1,1,1,1,1
1,1,1,1,1,1,1,1,1,1,1,1,1,1,1,1,1,1,1,1,1,1,1,1,1,1,1,1,1,1,1,1,1,1,0,1,1,1,1,1,1,1,1,1,1,1,1,1,1,1,1,1,1,1,1,1,1
1,1,1,1,1,1,1,1,1,1,1,1,1,1,1,1,1,1,1,1,1,1,1,1,1,1,1,1,1,1,1,1,1,0,0,0,1,1,1,1,1,1,1,1,1,1,1,1,1,1,1,1,1,1,1,1,1
1,1,1,1,1,1,1,1,1,1,1,1,1,1,1,1,1,1,1,1,1,1,1,1,1,1,1,1,1,1,1,1,1,1,0,1,1,1,1,1,1,1,1,1,1,1,1,1,1,1,1,1,1,1,1,1,1
1,1,1,1,1,1,1,1,1,1,1,1,1,1,1,1,1,1,1,1,1,1,1,1,1,1,1,1,1,1,1,1,1,1,1,1,1,1,1,1,1,1,1,1,1,1,1,1,1,1,1,1,1,1,1,1,1
1,1,1,1,1,1,1,1,1,1,1,1,1,1,1,1,1,1,1,1,1,1,1,1,1,1,1,1,1,1,1,1,1,1,1,1,1,1,1,1,1,1,1,1,1,1,1,1,1,1,1,1,1,1,1,1,1
1,1,1,1,1,1,1,1,1,1,1,1,1,1,1,1,1,1,1,1,1,1,1,1,1,1,1,1,1,1,1,1,1,1,1,1,1,1,1,1,1,1,1,1,1,1,1,1,1,1,1,1,1,1,1,1,1
1,1,1,1,1,1,1,1,1,1,1,1,1,1,1,1,1,1,1,1,1,1,1,1,1,1,1,1,1,1,1,1,1,1,1,1,1,1,1,1,1,1,1,1,1,1,1,1,1,1,1,1,1,1,1,1,1
1,1,1,1,1,1,1,1,1,1,1,1,1,1,1,1,1,1,1,1,1,1,1,1,1,1,1,1,1,1,1,1,1,1,1,1,1,1,1,1,1,1,1,1,1,1,1,1,1,1,1,1,1,1,1,1,1
:endlayer
layer: 4
1,1,1,1,1,1,11,11,11,11,11,11,11,11,11,11,11,11,11,11,11,11,11,11,11,11,11,11,11,11,11,11,11,11,11,11,11,11,11,11,11,11,11,11,11,11,11,11,11,11,11,1,1,1,1,1,1
1,1,1,1,1,1,11,11,11,11,11,11,11,11,11,11,11,11,11,11,11,11,11,11,11,11,11,11,11,11,11,11,11,11,11,11,11,11,11,11,11,11,11,11,11,11,11,11,11,11,11,1,1,1,1,1,1
1,1,1,1,1,1,11,11,11,11,11,11,11,11,11,11,11,11,11,11,11,11,11,11,11,11,11,11,11,11,11,11,11,11,11,11,11,11,11,11,11,11,11,11,11,11,11,11,11,11,11,1,1,1,1,1,1
1,1,1,1,1,1,11,11,11,11,11,11,11,11,11,11,11,11,11,11,11,11,11,11,11,11,11,11,11,11,11,11,11,11,11,11,11,11,11,11,11,11,11,11,11,11,11,11,11,11,11,1,1,1,1,1,1
1,1,1,1,1,1,11,11,11,11,11,11,11,11,11,11,11,11,11,11,11,11,11,11,11,11,11,11,11,11,11,11,11,11,11,11,11,11,11,11,11,11,11,11,11,11,11,11,11,11,11,1,1,1,1,1,1
1,1,1,1,1,1,11,11,11,11,11,11,11,11,11,11,11,11,11,11,11,11,11,11,11,11,11,11,11,11,11,11,11,11,11,11,11,11,11,11,11,11,11,11,11,11,11,11,11,11,11,1,1,1,1,1,1
1,1,1,1,1,1,11,11,11,11,11,11,11,11,11,11,11,11,11,11,11,11,11,11,11,11,11,11,11,11,11,11,11,11,11,11,11,11,11,11,11,11,11,11,11,11,11,11,11,11,11,1,1,1,1,1,1
1,1,1,1,1,1,11,11,11,11,11,11,11,11,11,11,11,11,11,11,11,11,11,11,11,11,11,11,11,11,11,11,11,11,11,11,11,11,11,11,11,11,11,11,11,11,11,11,11,11,11,1,1,1,1,1,1
1,1,1,1,1,1,11,11,11,11,11,11,11,11,11,11,11,11,11,11,11,11,11,11,11,11,11,11,11,11,11,11,11,11,11,11,11,11,11,11,11,11,11,11,11,11,11,11,11,11,11,1,1,1,1,1,1
1,1,1,1,1,1,11,11,11,11,11,11,11,11,11,11,11,11,11,11,11,11,11,11,11,11,11,11,11,11,11,11,11,11,11,11,11,11,11,11,11,11,11,11,11,11,11,11,11,11,11,1,1,1,1,1,1
1,1,1,1,1,1,11,11,11,11,11,11,11,11,11,11,11,11,11,11,11,11,11,11,11,11,11,11,11,11,11,11,11,11,11,11,11,11,11,11,11,11,11,11,11,11,11,11,11,11,11,1,1,1,1,1,1
1,1,1,1,1,1,11,11,11,11,11,11,11,11,11,11,11,11,11,11,11,11,11,11,11,11,11,11,11,11,11,11,11,11,11,11,11,11,11,11,11,11,11,11,11,11,11,11,11,11,11,1,1,1,1,1,1
1,1,1,1,1,1,11,11,11,11,11,11,11,11,11,11,11,11,11,11,11,11,11,11,11,11,11,11,11,11,11,11,11,11,11,11,11,11,11,11,11,11,11,11,11,11,11,11,11,11,11,1,1,1,1,1,1
1,1,1,1,1,1,11,11,11,11,11,11,11,11,11,11,11,11,11,11,11,11,11,11,11,11,11,11,11,11,11,11,11,11,11,11,11,11,11,11,11,11,11,11,11,11,11,11,11,11,11,1,1,1,1,1,1
1,1,1,1,1,1,11,11,11,11,11,11,11,11,11,11,11,11,11,11,11,11,11,11,11,11,11,11,11,11,11,11,11,11,11,11,11,11,11,11,11,11,11,11,11,11,11,11,11,11,11,1,1,1,1,1,1
1,1,1,1,1,1,11,11,11,11,11,11,11,11,11,11,11,11,11,11,11,11,11,11,11,11,11,11,11,11,11,11,11,11,11,11,11,11,11,11,11,11,11,11,11,11,11,11,11,11,11,1,1,1,1,1,1
1,1,1,1,1,1,11,11,11,11,11,11,11,11,11,11,11,11,11,11,11,11,11,11,11,11,11,11,11,11,11,11,11,11,11,11,11,11,11,11,11,11,11,11,11,11,11,11,11,11,11,1,1,1,1,1,1
1,1,1,1,1,1,11,11,11,11,11,11,11,11,11,11,11,11,11,11,11,11,11,11,11,11,11,11,11,11,11,11,11,11,11,11,11,11,11,11,11,11,11,11,11,11,11,11,11,11,11,1,1,1,1,1,1
1,1,1,1,1,1,11,11,11,11,11,11,11,11,11,11,11,11,11,11,11,11,11,11,11,11,11,11,11,11,11,11,11,11,11,11,11,11,11,11,11,11,11,11,11,11,11,11,11,11,11,1,1,1,1,1,1
1,1,1,1,1,1,11,11,11,11,11,11,11,11,11,11,11,11,11,11,11,11,11,11,11,11,11,11,11,11,11,11,11,11,11,11,11,11,11,11,11,11,11,11,11,11,11,11,11,11,11,1,1,1,1,1,1
1,1,1,1,1,1,11,11,11,11,11,11,11,11,11,11,11,11,11,11,11,11,11,11,11,11,11,11,11,11,11,11,11,11,11,11,11,11,12,11,11,11,11,11,11,11,11,11,11,11,11,1,1,1,1,1,1
1,1,1,1,1,1,11,11,11,11,11,10,10,10,10,10,11,11,11,11,11,11,11,11,11,11,11,11,11,11,11,11,11,11,11,11,11,11,11,11,11,11,11,11,11,11,11,11,11,11,11,1,1,1,1,1,1
1,1,1,1,1,1,11,11,11,11,10,10,10,10,10,10,10,11,11,11,11,11,11,11,11,11,11,11,11,11,11,11,11,11,11,11,11,11,11,11,11,11,11,11,11,11,11,11,11,11,11,1,1,1,1,1,1
1,1,1,1,1,1,11,11,11,11,10,10,10,10,10,10,10,11,11,11,11,11,11,11,11,11,13,11,11,11,11,11,11,11,11,11,11,11,11,11,11,11,11,11,11,11,11,11,11,11,11,1,1,1,1,1,1
1,1,1,1,1,1,11,11,11,11,10,10,10,10,10,10,10,11,11,11,11,11,11,11,11,11,11,11,11,11,11,11,11,11,11,11,11,11,11,11,11,11,11,11,11,11,11,11,11,11,11,1,1,1,1,1,1
1,1,1,1,1,1,11,11,11,11,10,10,10,10,10,10,10,11,11,11,11,11,11,11,11,11,11,11,11,11,11,11,11,11,11,11,11,11,11,11,11,11,11,11,11,11,11,11,11,11,11,1,1,1,1,1,1
1,1,1,1,1,1,11,11,11,11,10,10,10,10,10,10,10,11,11,11,11,11,11,11,11,11,11,11,11,11,11,11,11,11,11,11,11,11,11,11,11,11,11,11,11,11,11,11,11,11,11,1,1,1,1,1,1
1,1,1,1,1,1,11,11,11,11,11,10,10,10,10,10,11,11,11,11,11,11,11,11,11,11,11,11,11,11,11,11,11,11,11,11,11,11,11,11,11,11,11,11,11,11,11,11,11,11,11,1,1,1,1,1,1
1,1,1,1,1,1,11,11,11,11,14,14,14,14,14,14,14,11,11,11,11,11,11,11,11,11,11,11,11,11,11,11,11,11,11,11,11,11,11,11,11,11,11,11,11,11,11,11,11,11,11,1,1,1,1,1,1
1,1,1,1,1,1,11,11,11,11,14,14,14,14,14,14,14,11,11,11,11,11,11,11,11,11,11,11,11,11,11,11,11,11,11,11,11,11,11,11,11,11,11,11,11,11,11,11,11,11,11,1,1,1,1,1,1
1,1,1,1,1,1,11,11,11,11,14,14,14,14,14,14,14,11,11,11,11,11,11,11,11,11,11,11,11,11,11,11,11,11,11,11,11,11,11,11,11,11,11,11,11,11,11,11,11,11,11,1,1,1,1,1,1
1,1,1,1,1,1,11,11,11,11,14,14,14,14,14,14,14,11,11,11,11,11,11,11,11,11,11,11,11,11,11,11,11,11,11,11,11,11,11,11,11,11,11,11,11,11,11,11,11,11,11,1,1,1,1,1,1
1,1,1,1,1,1,11,11,11,11,14,14,14,14,14,14,14,11,11,11,11,11,11,11,11,11,11,11,11,11,11,11,11,11,11,11,11,11,11,11,11,11,11,11,11,11,11,11,11,11,11,11,11,1,1,1,1
1,1,1,1,1,1,11,11,11,11,11,14,14,14,14,14,11,11,11,11,11,11,11,11,11,11,11,11,11,11,11,11,11,11,11,11,11,11,11,11,11,11,11,11,11,11,11,11,11,11,11,11,11,1,1,1,1
1,1,1,1,1,1,11,11,11,11,11,11,11,11,11,11,11,11,11,11,11,11,11,11,11,11,11,11,11,11,11,11,11,11,11,11,11,11,11,11,11,11,11,11,11,11,11,11,11,11,11,11,11,1,1,1,1
1,1,1,1,1,1,11,11,11,11,11,11,11,11,11,11,11,11,11,11,11,11,11,11,11,11,11,11,11,11,11,11,11,11,0,11,11,11,11,11,11,11,11,11,11,11,11,11,11,11,11,1,1,1,1,1,1
1,1,1,1,1,1,11,11,11,11,11,11,11,11,11,11,11,11,11,11,11,11,11,11,11,11,11,11,11,11,11,11,11,11,11,11,11,11,11,11,11,11,11,11,11,11,11,11,11,11,11,1,1,1,1,1,1
1,1,1,1,1,1,11,11,11,11,11,11,11,11,11,11,11,11,11,11,11,11,11,11,11,11,11,11,11,11,11,11,11,11,11,11,11,11,11,11,11,11,11,11,11,11,11,11,11,11,11,1,1,1,1,1,1
1,1,1,1,1,1,11,11,11,11,11,11,11,11,11,11,11,11,11,11,11,11,11,11,11,11,11,11,11,11,11,11,11,11,11,11,11,11,11,11,11,11,11,11,11,11,11,11,11,11,11,1,1,1,1,1,1
1,1,1,1,1,1,11,11,11,11,11,11,11,11,11,11,11,11,11,11,11,11,11,11,11,11,11,11,11,11,11,11,11,11,11,11,11,11,11,11,11,11,11,11,11,11,11,11,11,11,11,1,1,1,1,1,1
1,1,1,1,1,1,1,1,1,1,1,1,1,1,1,1,1,1,1,1,1,1,1,1,1,1,1,1,1,1,1,1,1,1,1,1,1,1,1,1,1,1,1,1,1,1,1,1,1,1,1,1,1,1,1,1,1
1,1,1,1,1,1,1,1,1,1,1,1,1,1,1,1,1,1,1,1,1,1,1,1,1,1,1,1,1,1,1,1,1,1,1,1,1,1,1,1,1,1,1,1,1,1,1,1,1,1,1,1,1,1,1,1,1
:endlayer
layer: 5
1,1,1,1,1,1,11,11,11,11,11,11,11,0,11,11,11,11,11,11,11,11,11,11,11,11,11,11,11,11,11,11,11,11,11,11,11,11,11,11,11,11,11,11,11,11,11,11,11,11,11,1,1,1,1,1,1
1,1,1,1,1,1,11,11,11,15,0,16,0,0,17,11,11,11,18,19,0,20,0,21,11,11,14,22,0,0,16,16,23,16,0,0,23,24,0,25,16,0,0,0,26,11,11,11,11,11,11,1,1,1,1,1,1
1,1,1,1,1,1,11,11,11,0,0,16,0,0,0,27,11,11,0,0,0,0,16,16,11,11,11,0,28,0,0,16,16,0,0,0,0,0,0,0,0,0,29,0,0,11,11,11,11,11,11,1,1,1,1,1,1
1,1,1,1,1,1,11,11,11,0,0,30,0,0,0,31,11,11,0,0,0,0,0,16,31,14,11,32,0,0,16,16,33,0,0,0,33,34,0,25,16,0,35,0,36,11,11,11,11,11,11,1,1,1,1,1,1
1,1,1,1,1,1,11,11,11,0,0,0,0,0,0,0,25,0,0,0,37,0,0,0,14,11,11,31,31,31,11,11,11,0,0,0,31,31,31,11,11,14,31,31,31,11,11,11,11,11,11,1,1,1,1,1,1
1,1,1,1,1,1,11,11,11,0,0,0,0,0,0,0,0,0,0,0,0,0,16,0,31,11,11,31,31,31,11,11,11,0,0,0,31,0,31,31,14,11,31,0,31,11,11,11,11,11,11,1,1,1,1,1,1
1,1,1,1,1,1,11,11,11,38,38,38,0,0,0,0,25,0,0,0,0,0,0,0,39,11,31,31,31,31,11,14,11,0,0,0,31,31,31,11,11,31,31,31,31,11,11,11,11,11,11,1,1,1,1,1,1
1,1,1,1,1,1,11,11,11,31,31,31,0,0,0,11,11,11,31,31,31,31,31,31,31,31,40,0,0,0,12,0,41,16,0,0,12,0,16,0,16,0,42,43,44,11,11,11,11,11,11,1,1,1,1,1,1
1,1,1,1,1,1,11,11,11,31,45,31,0,16,0,31,11,11,31,0,0,0,0,31,14,0,11,0,0,0,0,0,0,0,0,0,0,0,0,0,0,16,0,46,47,11,11,11,11,11,11,1,1,1,1,1,1
1,1,1,1,1,1,11,11,11,31,31,31,0,0,16,14,31,11,31,31,31,31,31,31,14,11,11,16,0,0,12,0,41,0,16,0,48,0,0,0,0,0,0,0,49,11,11,11,11,11,11,1,1,1,1,1,1
1,1,1,1,1,1,11,11,11,50,0,25,0,0,0,31,31,31,0,0,51,0,0,0,52,11,11,0,0,0,11,11,11,31,31,31,11,11,14,31,31,31,11,11,11,11,11,11,11,11,11,1,1,1,1,1,1
1,1,1,1,1,1,11,11,11,0,0,25,0,0,0,31,53,31,0,0,0,16,0,0,11,31,31,0,0,0,0,31,11,31,31,31,14,11,54,31,55,31,11,11,14,11,11,11,11,11,11,1,1,1,1,1,1
1,1,1,1,1,1,11,11,11,56,0,25,0,0,0,31,31,31,0,0,0,0,16,0,11,11,14,0,0,0,0,31,14,31,31,31,14,11,0,31,31,31,11,11,11,11,11,11,11,11,11,1,1,1,1,1,1
1,1,1,1,1,1,11,11,11,11,11,14,0,0,0,0,12,0,0,0,0,0,0,57,31,31,31,0,0,0,11,58,59,0,0,0,0,0,0,0,0,0,0,0,0,11,11,11,11,11,11,1,1,1,1,1,1
1,1,1,1,1,1,11,11,11,14,31,11,0,0,0,0,0,16,0,0,0,16,0,0,31,31,31,0,0,0,11,11,31,0,0,0,0,0,0,0,0,0,0,0,0,11,11,11,11,11,11,1,1,1,1,1,1
1,1,1,1,1,1,11,11,11,31,11,11,0,0,0,0,12,0,0,0,0,0,0,0,60,31,31,0,0,0,11,11,11,0,0,0,0,0,0,0,0,0,0,0,0,11,11,11,11,11,11,1,1,1,1,1,1
1,1,1,1,1,1,0,0,0,61,0,0,0,0,0,11,11,31,31,11,11,11,0,0,60,11,14,0,0,0,14,11,11,0,0,0,31,11,11,11,0,11,0,0,16,0,0,11,11,11,11,1,1,1,1,1,1
1,1,1,1,1,1,0,0,0,62,0,0,0,0,0,14,11,11,11,11,11,11,0,0,60,11,11,0,0,0,31,11,14,16,0,0,11,11,31,11,63,11,0,0,64,0,0,11,11,11,11,1,1,1,1,1,1
1,1,1,1,1,1,0,0,0,65,0,0,0,0,0,14,11,11,11,14,11,11,11,11,31,11,31,0,0,16,14,14,11,0,0,0,11,11,11,11,66,14,0,16,0,0,0,11,11,11,11,1,1,1,1,1,1
1,1,1,1,1,1,0,0,0,67,0,0,0,0,0,0,0,0,0,0,0,11,31,11,0,0,23,0,0,0,31,31,31,0,0,0,0,0,0,11,11,14,11,11,14,11,11,11,11,11,11,1,1,1,1,1,1
1,1,1,1,1,1,11,11,11,31,31,31,16,0,0,0,0,0,0,0,16,11,11,11,68,0,0,0,0,0,31,31,31,0,0,0,0,0,0,11,11,11,11,11,11,11,11,11,11,11,11,1,1,1,1,1,1
1,1,1,1,1,1,11,11,11,31,31,0,0,0,0,0,0,16,0,0,0,11,11,11,0,0,33,16,0,16,31,31,31,0,0,0,16,0,0,11,11,31,31,11,11,11,11,11,11,11,11,1,1,1,1,1,1
1,1,1,1,1,1,11,11,11,16,0,0,0,0,0,0,0,0,0,0,16,11,31,11,11,31,11,0,0,0,69,31,11,0,0,16,16,0,0,0,12,0,70,0,71,11,11,11,11,11,11,1,1,1,1,1,1
1,1,1,1,1,1,11,11,11,0,0,0,0,0,0,0,0,0,0,0,0,11,11,11,14,11,0,0,0,0,72,11,11,0,0,16,0,16,0,0,33,0,0,73,0,11,11,11,11,11,11,1,1,1,1,1,1
1,1,1,1,1,1,11,11,11,0,0,0,0,2,0,0,0,0,0,0,0,11,11,11,11,11,11,0,16,0,11,11,11,0,0,0,0,0,0,0,12,0,74,0,75,11,11,11,11,11,11,1,1,1,1,1,1
1,1,1,1,1,1,11,11,11,16,0,0,0,0,0,0,0,11,0,0,16,11,11,11,0,0,0,0,0,0,31,31,31,11,11,11,0,0,0,11,11,11,31,31,31,11,11,11,11,11,11,1,1,1,1,1,1
1,1,1,1,1,1,11,11,11,16,0,0,0,0,0,0,0,11,76,0,60,11,11,14,0,0,0,0,0,0,31,77,31,14,14,11,76,41,60,11,11,14,31,31,31,11,11,11,11,11,11,1,1,1,1,1,1
1,1,1,1,1,1,11,11,11,48,0,0,0,0,0,0,11,11,16,0,0,11,11,11,0,0,0,0,0,0,31,31,31,11,31,11,0,0,0,11,11,11,31,31,31,11,11,11,11,11,11,1,1,1,1,1,1
1,1,1,1,1,1,11,11,11,41,0,0,0,0,0,0,0,0,0,0,0,0,0,16,0,16,0,0,0,0,16,0,0,0,0,16,16,0,16,0,0,0,0,0,0,11,11,11,11,11,11,1,1,1,1,1,1
1,1,1,1,1,1,11,11,11,41,0,0,0,0,0,0,0,0,0,0,0,0,0,0,0,0,0,16,0,0,0,16,0,0,0,0,0,0,16,0,16,0,0,16,0,11,11,11,11,11,11,1,1,1,1,1,1
1,1,1,1,1,1,11,11,11,41,0,0,0,0,0,0,0,16,16,0,0,0,16,0,16,0,0,16,0,0,16,0,0,0,0,0,0,0,0,16,0,0,0,0,0,11,11,11,11,11,11,1,1,1,1,1,1
1,1,1,1,1,1,11,11,11,41,0,0,0,0,0,0,0,0,11,11,11,0,16,0,11,14,11,31,31,31,11,11,11,11,11,11,0,0,0,31,31,31,0,0,16,11,11,11,11,11,11,11,11,1,1,1,1
1,1,1,1,1,1,11,11,11,41,0,0,0,0,0,0,0,0,14,11,14,76,0,60,11,11,11,31,0,31,11,11,11,11,11,11,0,0,0,31,31,31,0,0,0,23,0,25,0,0,23,0,78,11,1,1,1
1,1,1,1,1,1,11,11,11,12,12,12,12,12,12,25,25,25,11,14,11,0,0,0,14,11,11,31,31,31,31,11,11,31,11,14,0,16,0,31,31,31,0,0,0,0,0,0,0,0,0,0,0,11,1,1,1
1,1,1,1,1,1,11,11,11,48,25,25,11,11,11,0,25,0,31,31,31,0,0,0,31,31,31,0,0,0,0,0,16,0,79,25,0,0,0,14,11,11,0,0,0,33,0,25,0,0,33,0,80,11,1,1,1
1,1,1,1,1,1,11,11,11,0,0,0,11,11,0,0,81,0,31,31,31,0,82,0,31,31,31,83,0,84,0,0,0,0,0,25,0,85,0,11,31,11,0,0,0,11,11,11,11,11,11,11,11,1,1,1,1
1,1,1,1,1,1,11,11,11,0,86,87,31,11,14,88,0,89,31,31,31,90,91,92,31,31,31,0,0,0,0,0,16,0,0,0,0,0,0,14,31,31,12,93,12,11,11,11,11,11,11,1,1,1,1,1,1
1,1,1,1,1,1,11,11,11,11,11,11,11,11,11,11,11,11,11,11,11,11,11,11,11,11,11,11,11,11,11,11,11,11,11,11,11,11,11,11,11,11,11,11,11,11,11,11,11,11,11,1,1,1,1,1,1
1,1,1,1,1,1,11,11,11,11,11,11,11,11,11,11,11,11,11,11,11,11,11,11,11,11,11,11,11,11,11,11,11,11,11,11,11,11,11,11,11,11,11,11,11,11,11,11,11,11,11,1,1,1,1,1,1
1,1,1,1,1,1,11,11,11,11,11,11,11,11,11,11,11,11,11,11,11,11,11,11,11,11,11,11,11,11,11,11,11,11,11,11,11,11,11,11,11,11,11,11,11,11,11,11,11,11,11,1,1,1,1,1,1
1,1,1,1,1,1,1,1,1,1,1,1,1,1,1,1,1,1,1,1,1,1,1,1,1,1,1,1,1,1,1,1,1,1,1,1,1,1,1,1,1,1,1,1,1,1,1,1,1,1,1,1,1,1,1,1,1
1,1,1,1,1,1,1,1,1,1,1,1,1,1,1,1,1,1,1,1,1,1,1,1,1,1,1,1,1,1,1,1,1,1,1,1,1,1,1,1,1,1,1,1,1,1,1,1,1,1,1,1,1,1,1,1,1
:endlayer
layer: 6
1,1,1,1,1,1,11,11,11,11,11,11,11,0,11,11,11,11,11,11,11,11,11,11,11,11,11,11,11,11,11,11,11,11,11,11,11,11,11,11,11,11,11,11,11,11,11,11,11,11,11,1,1,1,1,1,1
1,1,1,1,1,1,11,11,11,0,0,0,0,0,0,11,11,11,38,38,38,38,38,38,31,11,14,0,0,0,16,16,94,0,0,0,94,0,0,25,0,0,0,0,0,11,11,11,11,11,11,1,1,1,1,1,1
1,1,1,1,1,1,11,11,11,0,0,0,0,0,0,31,11,11,0,0,0,0,0,0,11,11,14,0,0,0,0,16,16,0,0,0,0,0,0,0,0,0,0,0,0,11,11,11,11,11,11,1,1,1,1,1,1
1,1,1,1,1,1,11,95,25,0,0,0,0,0,0,11,11,11,0,0,0,0,0,0,96,11,11,0,0,0,0,16,97,0,0,0,97,0,0,25,16,0,0,0,0,11,11,11,11,11,11,1,1,1,1,1,1
1,1,1,1,1,1,11,98,25,0,0,0,0,0,0,0,25,0,0,0,0,0,0,0,11,11,11,31,31,31,11,11,11,0,0,0,31,31,31,11,11,11,31,31,31,11,11,11,11,11,11,1,1,1,1,1,1
1,1,1,1,1,1,11,11,11,0,0,0,0,0,0,0,0,0,0,0,0,0,0,0,11,11,0,31,99,31,31,31,11,0,0,0,31,0,31,11,11,11,31,0,31,11,11,11,11,11,11,1,1,1,1,1,1
1,1,1,1,1,1,11,11,11,100,101,102,0,0,0,0,25,0,0,0,0,0,0,0,12,14,14,31,31,31,11,11,11,0,0,0,31,31,31,11,11,14,31,31,31,11,11,11,11,11,11,1,1,1,1,1,1
1,1,1,1,1,1,11,11,11,31,31,31,0,0,0,11,31,11,31,31,31,31,31,31,11,11,0,0,0,0,0,0,0,0,0,0,38,0,0,0,0,0,0,0,0,11,11,11,11,11,11,1,1,1,1,1,1
1,1,1,1,1,1,11,11,11,31,103,31,0,0,0,31,11,31,31,0,0,0,0,31,0,11,11,0,0,0,0,0,0,0,0,0,0,0,0,0,0,0,0,0,0,11,11,11,11,11,11,1,1,1,1,1,1
1,1,1,1,1,1,11,11,11,31,31,31,0,0,0,14,11,11,31,31,31,31,31,31,11,11,11,0,0,0,0,0,0,0,0,0,12,0,0,0,0,0,0,0,0,11,11,11,11,11,11,1,1,1,1,1,1
1,1,1,1,1,1,11,11,11,0,0,0,0,0,0,31,31,31,0,0,0,0,0,0,0,11,11,0,0,0,11,11,11,31,31,31,11,11,11,31,31,31,11,11,11,11,11,11,11,11,11,1,1,1,1,1,1
1,1,1,1,1,1,11,11,11,0,0,25,0,0,0,31,104,31,0,0,0,0,0,0,11,11,11,0,0,0,0,11,31,31,105,31,11,11,0,31,106,31,11,14,11,11,11,11,11,11,11,1,1,1,1,1,1
1,1,1,1,1,1,11,11,11,0,0,25,0,0,0,31,31,31,0,0,0,0,0,0,11,11,11,0,0,0,0,14,11,31,31,31,11,31,0,31,31,31,11,11,11,11,11,11,11,11,11,1,1,1,1,1,1
1,1,1,1,1,1,11,11,11,11,11,11,0,0,0,0,12,0,0,0,0,0,0,0,31,31,31,0,0,0,11,0,0,0,0,0,0,0,0,0,0,0,0,0,0,11,11,11,11,11,11,1,1,1,1,1,1
1,1,1,1,1,1,11,11,11,11,31,11,0,0,0,0,0,0,0,0,0,0,0,0,31,11,31,0,0,0,14,11,11,0,0,0,0,0,0,0,0,0,0,0,0,11,11,11,11,11,11,1,1,1,1,1,1
1,1,1,1,1,1,11,11,11,14,31,11,0,0,0,0,12,0,0,0,0,0,0,0,0,60,31,0,0,0,11,11,11,0,0,0,0,0,0,0,0,0,0,0,0,11,11,11,11,11,11,1,1,1,1,1,1
1,1,1,1,1,1,0,0,0,0,0,0,0,0,0,11,11,11,31,11,31,14,0,0,0,60,11,0,0,0,11,11,11,0,0,0,31,11,11,11,0,11,0,0,16,0,0,11,11,11,11,1,1,1,1,1,1
1,1,1,1,1,1,0,0,0,0,0,0,0,0,0,11,11,31,11,31,31,14,0,0,0,60,11,0,0,0,11,31,31,0,0,0,31,11,11,31,0,14,0,0,16,0,0,11,11,11,11,1,1,1,1,1,1
1,1,1,1,1,1,0,0,0,0,0,0,0,0,0,31,14,31,11,31,31,11,11,11,11,11,11,0,0,0,11,11,11,0,0,0,31,11,11,11,0,11,0,0,16,0,0,11,11,11,11,1,1,1,1,1,1
1,1,1,1,1,1,0,0,0,0,0,0,0,0,0,0,0,0,0,0,0,31,11,11,0,0,94,0,0,0,31,31,31,0,0,0,0,0,0,31,31,11,11,11,11,11,11,11,11,11,11,1,1,1,1,1,1
1,1,1,1,1,1,11,11,11,31,107,31,0,0,0,0,0,0,0,0,0,31,11,11,0,0,0,0,0,0,31,108,31,0,0,0,0,0,0,11,14,14,11,11,11,11,11,11,11,11,11,1,1,1,1,1,1
1,1,1,1,1,1,11,11,11,31,31,0,0,0,0,0,0,0,0,0,0,11,11,11,0,0,97,0,0,0,31,31,31,0,0,0,0,0,0,14,31,11,11,14,11,11,11,11,11,11,11,1,1,1,1,1,1
1,1,1,1,1,1,11,11,11,0,0,0,0,0,0,0,0,0,0,0,0,11,31,11,11,11,14,0,0,0,0,11,11,0,0,0,0,0,0,0,23,0,0,0,0,11,11,11,11,11,11,1,1,1,1,1,1
1,1,1,1,1,1,11,11,11,0,0,0,0,0,0,0,0,0,0,0,0,11,11,11,11,0,11,0,0,0,0,11,11,0,0,0,0,0,0,0,23,0,0,0,0,11,11,11,11,11,11,1,1,1,1,1,1
1,1,1,1,1,1,11,11,11,0,0,0,0,2,0,0,0,0,0,0,0,11,11,11,11,11,11,0,0,0,14,11,11,0,0,0,0,0,0,0,38,0,0,0,0,11,11,11,11,11,11,1,1,1,1,1,1
1,1,1,1,1,1,11,11,11,0,0,0,0,0,0,0,0,11,0,0,0,14,11,11,0,0,0,0,0,0,31,31,31,11,11,14,0,0,0,11,11,11,31,31,31,11,11,11,11,11,11,1,1,1,1,1,1
1,1,1,1,1,1,11,11,11,0,0,0,0,0,0,0,0,11,109,0,110,11,14,11,0,0,0,0,0,0,31,111,31,31,31,11,109,38,110,11,14,11,31,112,31,11,11,11,11,11,11,1,1,1,1,1,1
1,1,1,1,1,1,11,11,11,48,0,0,0,0,0,0,11,11,0,0,0,11,14,31,0,0,0,0,0,0,31,31,31,14,11,11,0,0,0,11,113,11,31,31,31,11,11,11,11,11,11,1,1,1,1,1,1
1,1,1,1,1,1,11,11,11,41,0,0,0,0,0,0,0,0,0,0,0,0,0,0,0,0,0,0,0,0,0,0,0,0,0,0,0,0,0,0,0,0,0,0,0,11,11,11,11,11,11,1,1,1,1,1,1
1,1,1,1,1,1,11,11,11,41,0,0,0,0,0,0,0,0,0,0,0,0,0,0,0,0,0,0,0,0,0,0,0,0,0,0,0,0,0,0,0,0,0,0,0,11,11,11,11,11,11,1,1,1,1,1,1
1,1,1,1,1,1,11,11,11,41,0,0,0,0,0,0,0,0,0,0,0,0,0,0,0,0,0,0,0,0,0,0,0,0,0,0,0,0,0,0,0,0,0,0,0,11,11,11,11,11,11,1,1,1,1,1,1
1,1,1,1,1,1,11,11,11,41,0,0,0,0,0,0,0,0,11,11,11,0,0,0,11,11,31,31,31,31,11,11,31,11,14,11,0,0,0,31,31,31,0,0,0,11,11,11,11,11,11,11,11,1,1,1,1
1,1,1,1,1,1,11,11,11,41,0,0,0,0,0,0,0,0,11,11,11,109,0,110,11,11,11,31,0,31,11,11,11,11,11,11,0,0,0,31,114,31,0,0,0,0,0,25,0,0,0,0,0,11,1,1,1
1,1,1,1,1,1,11,11,11,12,0,0,12,0,12,0,0,0,11,11,11,0,0,0,31,14,11,31,31,31,11,11,11,11,31,31,0,0,0,31,31,31,0,0,0,0,0,0,0,0,0,0,0,11,1,1,1
1,1,1,1,1,1,11,11,11,48,25,25,11,11,11,0,25,0,31,31,31,0,0,0,31,31,31,0,0,0,0,0,0,0,0,25,0,0,0,11,11,11,0,0,0,0,0,25,0,0,0,0,0,11,1,1,1
1,1,1,1,1,1,11,11,11,0,0,0,11,11,11,0,0,0,31,115,31,0,0,0,31,116,31,0,0,0,0,0,0,0,0,25,0,0,0,117,14,31,0,0,0,11,11,11,11,11,11,11,11,1,1,1,1
1,1,1,1,1,1,11,11,11,0,0,0,31,11,14,0,0,0,31,31,31,0,0,0,31,31,31,0,0,0,0,0,0,0,0,0,0,0,0,11,31,11,12,12,12,11,11,11,11,11,11,1,1,1,1,1,1
1,1,1,1,1,1,11,11,11,11,11,11,11,11,11,11,11,11,11,11,11,11,11,11,11,11,11,11,11,11,11,11,11,11,11,11,11,11,11,11,11,11,11,11,11,11,11,11,11,11,11,1,1,1,1,1,1
1,1,1,1,1,1,11,11,11,11,11,11,11,11,11,11,11,11,11,11,11,11,11,11,11,11,11,11,11,11,11,11,11,11,11,11,11,11,11,11,11,11,11,11,11,11,11,11,11,11,11,1,1,1,1,1,1
1,1,1,1,1,1,11,11,11,11,11,11,11,11,11,11,11,11,11,11,11,11,11,11,11,11,11,11,11,11,11,11,11,11,11,11,11,11,11,11,11,11,11,11,11,11,11,11,11,11,11,1,1,1,1,1,1
1,1,1,1,1,1,1,1,1,1,1,1,1,1,1,1,1,1,1,1,1,1,1,1,1,1,1,1,1,1,1,1,1,1,1,1,1,1,1,1,1,1,1,1,1,1,1,1,1,1,1,1,1,1,1,1,1
1,1,1,1,1,1,1,1,1,1,1,1,1,1,1,1,1,1,1,1,1,1,1,1,1,1,1,1,1,1,1,1,1,1,1,1,1,1,1,1,1,1,1,1,1,1,1,1,1,1,1,1,1,1,1,1,1
:endlayer
layer: 7
1,1,1,1,1,1,11,11,11,11,11,11,11,0,11,11,11,11,11,11,11,11,11,11,11,11,11,11,11,11,11,11,11,11,11,11,11,11,11,11,11,11,11,11,11,11,11,11,11,11,11,1,1,1,1,1,1
1,1,1,1,1,1,11,11,11,0,0,0,0,0,0,11,11,11,118,0,119,0,120,0,11,11,11,0,0,0,0,0,23,0,0,0,23,0,0,25,0,0,0,0,0,11,11,11,11,11,11,1,1,1,1,1,1
1,1,1,1,1,1,11,11,11,0,0,0,0,0,0,11,11,11,0,0,0,0,0,0,11,11,11,0,0,0,0,16,16,0,0,0,16,0,0,25,0,0,0,0,0,11,11,11,11,11,11,1,1,1,1,1,1
1,1,1,1,1,1,11,0,0,0,0,0,0,0,0,11,31,11,0,0,0,0,0,0,31,11,11,0,0,0,0,16,33,0,0,0,33,0,0,25,0,0,0,0,0,11,11,11,11,11,11,1,1,1,1,1,1
1,1,1,1,1,1,11,0,0,0,0,0,0,0,0,0,25,0,0,0,0,0,0,0,31,0,11,31,31,31,11,14,14,0,0,0,31,31,31,11,11,11,31,31,31,11,11,11,11,11,11,1,1,1,1,1,1
1,1,1,1,1,1,11,11,11,0,0,0,0,0,0,0,0,0,0,0,0,0,0,0,14,0,11,31,0,31,31,31,16,0,0,0,31,0,31,11,11,11,31,0,31,11,11,11,11,11,11,1,1,1,1,1,1
1,1,1,1,1,1,11,11,11,0,0,0,0,0,0,0,25,0,0,0,0,0,0,0,11,11,11,31,31,31,11,11,11,0,0,0,31,31,31,11,11,11,31,31,31,11,11,11,11,11,11,1,1,1,1,1,1
1,1,1,1,1,1,11,11,11,31,31,31,0,0,0,11,11,11,31,31,31,31,31,31,11,31,11,0,0,0,0,0,0,0,0,0,12,0,0,0,0,0,0,0,0,11,11,11,11,11,11,1,1,1,1,1,1
1,1,1,1,1,1,11,11,11,31,0,31,0,0,0,11,11,11,31,0,31,31,0,31,31,11,11,0,0,0,12,0,0,0,0,0,12,0,0,0,0,0,0,0,0,11,11,11,11,11,11,1,1,1,1,1,1
1,1,1,1,1,1,11,11,11,31,31,31,0,0,0,11,11,14,31,31,31,31,31,31,11,11,11,0,0,0,12,0,0,0,0,0,38,0,0,0,0,0,0,0,0,11,11,11,11,11,11,1,1,1,1,1,1
1,1,1,1,1,1,11,11,11,0,0,25,0,0,0,31,31,31,0,0,0,0,0,0,11,11,11,0,0,0,11,11,11,31,31,31,14,11,11,31,31,31,11,11,11,11,11,11,11,11,11,1,1,1,1,1,1
1,1,1,1,1,1,11,11,11,0,0,25,0,0,0,31,0,31,0,0,0,0,0,0,11,14,11,0,0,0,0,14,11,31,0,31,11,11,11,31,0,31,11,11,11,11,11,11,11,11,11,1,1,1,1,1,1
1,1,1,1,1,1,11,11,11,0,0,25,0,0,0,31,31,31,0,0,0,0,0,0,11,11,11,0,0,0,0,31,11,31,31,31,0,11,11,31,31,31,0,11,14,11,11,11,11,11,11,1,1,1,1,1,1
1,1,1,1,1,1,11,11,11,11,11,11,0,0,0,0,12,0,0,0,0,0,0,0,31,31,31,0,0,0,31,11,11,0,0,0,0,0,0,0,0,0,0,0,0,11,11,11,11,11,11,1,1,1,1,1,1
1,1,1,1,1,1,11,11,11,11,11,11,0,0,0,0,0,0,0,0,0,0,0,0,31,11,31,0,0,0,11,0,11,0,0,0,0,0,0,0,0,0,0,0,0,11,11,11,11,11,11,1,1,1,1,1,1
1,1,1,1,1,1,11,11,11,11,31,0,0,0,0,0,12,0,0,0,0,0,0,0,0,0,60,0,0,0,11,11,11,0,0,0,0,0,0,0,0,0,0,0,0,11,11,11,11,11,11,1,1,1,1,1,1
1,1,1,1,1,1,0,0,0,0,0,0,0,0,0,11,11,11,11,11,11,11,0,0,0,0,60,0,0,0,11,31,31,0,0,0,31,11,11,11,11,14,0,0,16,16,0,11,11,11,11,1,1,1,1,1,1
1,1,1,1,1,1,0,0,0,0,0,0,0,0,0,14,14,14,11,11,11,11,0,0,0,0,60,0,0,0,31,11,11,0,0,0,11,11,11,11,11,11,0,0,0,0,0,11,11,11,11,1,1,1,1,1,1
1,1,1,1,1,1,0,0,0,0,0,0,0,0,0,11,31,11,11,11,11,11,97,11,11,11,14,0,0,0,11,11,11,0,0,0,31,11,14,31,14,11,0,121,16,0,0,11,11,11,11,1,1,1,1,1,1
1,1,1,1,1,1,0,0,0,0,0,0,0,0,0,0,0,0,0,0,0,11,11,11,0,0,23,0,0,0,31,31,31,0,0,0,0,0,0,14,11,0,11,11,11,11,11,11,11,11,11,1,1,1,1,1,1
1,1,1,1,1,1,11,11,11,31,12,31,0,0,0,0,0,0,0,0,0,11,11,14,0,0,0,0,0,0,31,0,31,0,0,0,0,0,0,11,11,11,11,14,0,11,11,11,11,11,11,1,1,1,1,1,1
1,1,1,1,1,1,11,11,11,31,31,0,0,0,0,0,0,0,0,0,0,11,11,11,0,0,33,0,0,0,31,31,31,0,0,0,0,0,0,11,11,11,11,14,11,11,11,11,11,11,11,1,1,1,1,1,1
1,1,1,1,1,1,11,11,11,0,0,0,0,0,0,0,0,0,0,0,0,14,11,11,31,11,14,0,0,0,11,31,11,0,0,0,0,0,0,0,41,0,0,0,0,11,11,11,11,11,11,1,1,1,1,1,1
1,1,1,1,1,1,11,11,11,0,0,0,0,0,0,0,0,0,0,0,0,0,11,31,11,11,11,0,0,0,11,31,11,0,0,0,0,0,0,0,41,0,0,0,0,11,11,11,11,11,11,1,1,1,1,1,1
1,1,1,1,1,1,11,11,11,0,0,0,0,2,0,0,0,0,0,0,0,11,11,11,11,31,14,0,0,0,11,14,11,0,0,0,0,0,0,0,38,0,0,0,0,11,11,11,11,11,11,1,1,1,1,1,1
1,1,1,1,1,1,11,11,11,0,0,0,0,0,0,0,0,11,0,0,0,11,11,31,0,0,0,0,0,0,31,31,31,11,11,11,0,0,0,31,11,14,31,31,31,11,11,11,11,11,11,1,1,1,1,1,1
1,1,1,1,1,1,11,11,11,0,0,0,0,0,0,0,0,11,76,0,60,14,31,11,0,0,0,0,0,0,31,0,31,11,11,11,76,0,60,31,11,11,31,0,31,11,11,11,11,11,11,1,1,1,1,1,1
1,1,1,1,1,1,11,11,11,48,0,0,0,0,0,0,11,11,0,0,0,31,11,14,0,0,0,0,0,0,31,31,31,11,31,11,0,0,0,11,12,11,31,31,31,11,11,11,11,11,11,1,1,1,1,1,1
1,1,1,1,1,1,11,11,11,41,0,0,0,0,0,0,0,0,0,0,0,0,0,0,0,0,0,0,0,0,0,0,0,0,0,0,0,0,0,0,0,0,0,0,0,11,11,11,11,11,11,1,1,1,1,1,1
1,1,1,1,1,1,11,11,11,41,0,0,0,0,0,0,0,0,0,0,0,0,0,0,0,0,0,0,0,0,0,0,0,0,0,0,0,0,0,0,0,0,0,0,0,11,11,11,11,11,11,1,1,1,1,1,1
1,1,1,1,1,1,11,11,11,41,0,0,0,0,0,0,0,0,0,0,0,0,0,0,0,0,0,0,0,0,0,0,0,0,0,0,0,0,0,0,0,0,0,0,0,11,11,11,11,11,11,1,1,1,1,1,1
1,1,1,1,1,1,11,11,11,41,0,0,0,0,0,0,0,0,11,14,11,0,0,0,11,11,11,31,31,31,11,11,11,11,11,11,0,0,0,31,31,31,0,0,0,11,11,11,11,11,11,11,11,1,1,1,1
1,1,1,1,1,1,11,11,11,41,0,0,0,0,0,0,0,0,31,11,11,76,0,60,11,31,14,31,0,31,11,11,11,11,11,31,0,0,0,31,0,31,0,0,0,94,0,25,0,0,94,0,0,11,1,1,1
1,1,1,1,1,1,11,11,11,12,0,0,12,0,12,0,0,0,11,11,11,0,0,0,11,11,11,31,31,31,11,14,11,11,11,11,0,0,0,31,31,31,0,0,0,0,0,25,0,0,0,0,0,11,1,1,1
1,1,1,1,1,1,11,11,11,48,38,38,11,11,11,25,25,25,31,31,31,0,0,0,31,31,31,0,0,0,0,0,0,0,0,25,0,0,0,11,11,11,0,0,0,97,0,25,0,0,97,0,0,11,1,1,1
1,1,1,1,1,1,11,11,11,0,0,0,11,11,14,0,0,0,31,0,31,0,0,0,31,0,31,0,0,0,0,0,0,0,0,25,0,0,0,12,11,11,0,0,0,11,11,11,11,11,11,11,11,1,1,1,1
1,1,1,1,1,1,11,11,11,0,0,0,31,11,11,0,0,0,31,31,31,0,0,0,31,31,31,0,0,0,0,0,0,0,0,0,0,0,0,11,11,11,12,12,12,11,11,11,11,11,11,1,1,1,1,1,1
1,1,1,1,1,1,11,11,11,11,11,11,11,11,11,11,11,11,11,11,11,11,11,11,11,11,11,11,11,11,11,11,11,11,11,11,11,11,11,11,11,11,11,11,11,11,11,11,11,11,11,1,1,1,1,1,1
1,1,1,1,1,1,11,11,11,11,11,11,11,11,11,11,11,11,11,11,11,11,11,11,11,11,11,11,11,11,11,11,11,11,11,11,11,11,11,11,11,11,11,11,11,11,11,11,11,11,11,1,1,1,1,1,1
1,1,1,1,1,1,11,11,11,11,11,11,11,11,11,11,11,11,11,11,11,11,11,11,11,11,11,11,11,11,11,11,11,11,11,11,11,11,11,11,11,11,11,11,11,11,11,11,11,11,11,1,1,1,1,1,1
1,1,1,1,1,1,1,1,1,1,1,1,1,1,1,1,1,1,1,1,1,1,1,1,1,1,1,1,1,1,1,1,1,1,1,1,1,1,1,1,1,1,1,1,1,1,1,1,1,1,1,1,1,1,1,1,1
1,1,1,1,1,1,1,1,1,1,1,1,1,1,1,1,1,1,1,1,1,1,1,1,1,1,1,1,1,1,1,1,1,1,1,1,1,1,1,1,1,1,1,1,1,1,1,1,1,1,1,1,1,1,1,1,1
:endlayer
layer: 8
1,1,1,1,1,1,11,11,11,11,11,11,11,11,11,11,11,11,11,11,11,11,11,11,11,11,11,11,11,11,11,11,11,11,11,11,11,11,11,11,11,11,11,11,11,11,11,11,11,11,11,1,1,1,1,1,1
1,1,1,1,1,1,11,11,11,16,0,0,0,0,0,11,31,14,0,0,16,0,0,0,0,11,11,0,0,0,0,16,94,16,0,0,94,0,0,25,16,0,0,0,0,11,11,11,11,11,11,1,1,1,1,1,1
1,1,1,1,1,1,11,11,11,0,0,0,0,0,0,11,11,31,0,0,16,16,0,0,14,11,11,0,0,0,0,16,16,0,0,0,16,0,0,25,0,0,0,0,0,11,11,11,11,11,11,1,1,1,1,1,1
1,1,1,1,1,1,11,11,11,0,0,0,16,0,0,14,11,11,0,16,0,0,0,0,0,11,11,0,0,0,16,16,97,0,0,0,97,16,16,25,0,0,0,0,0,11,11,11,11,11,11,1,1,1,1,1,1
1,1,1,1,1,1,11,11,11,0,0,0,0,0,0,16,25,0,0,0,0,0,0,0,11,11,11,31,31,31,11,11,11,0,0,0,31,31,31,31,11,11,31,31,31,11,11,11,11,11,11,1,1,1,1,1,1
1,1,1,1,1,1,11,11,11,0,16,0,0,0,0,0,25,0,0,0,0,0,0,0,11,11,11,31,0,31,0,11,11,0,0,0,31,0,31,11,11,11,31,0,31,11,11,11,11,11,11,1,1,1,1,1,1
1,1,1,1,1,1,11,11,11,0,0,0,0,0,0,16,25,0,0,0,0,0,0,0,14,11,11,31,31,31,12,11,11,0,0,0,31,31,31,11,11,11,31,31,31,11,11,11,11,11,11,1,1,1,1,1,1
1,1,1,1,1,1,11,11,11,31,31,31,0,0,0,31,11,11,31,31,31,31,31,31,11,31,11,0,0,0,12,0,0,0,0,16,16,0,0,0,0,0,0,0,0,11,11,11,11,11,11,1,1,1,1,1,1
1,1,1,1,1,1,11,11,11,31,0,31,0,0,0,0,31,14,31,0,31,31,0,31,11,11,31,0,0,0,12,0,0,0,0,0,12,0,16,16,0,0,0,0,0,11,11,11,11,11,11,1,1,1,1,1,1
1,1,1,1,1,1,11,11,11,31,31,31,0,0,0,11,11,31,31,31,31,31,31,31,11,11,11,0,0,0,0,0,0,0,0,0,0,0,0,0,0,0,0,0,0,11,11,11,11,11,11,1,1,1,1,1,1
1,1,1,1,1,1,11,11,11,0,0,25,0,0,16,31,31,31,0,0,0,0,0,16,11,11,11,0,0,16,11,11,11,31,31,31,14,11,0,31,31,31,11,11,14,11,11,11,11,11,11,1,1,1,1,1,1
1,1,1,1,1,1,11,11,11,0,0,25,0,0,16,31,0,31,0,0,0,0,0,0,11,11,11,0,0,0,0,14,31,31,0,31,11,0,11,31,0,31,11,11,11,11,11,11,11,11,11,1,1,1,1,1,1
1,1,1,1,1,1,11,11,11,0,0,25,0,0,0,31,31,31,0,0,0,0,0,0,11,11,14,0,0,0,0,11,31,31,31,31,11,11,11,31,31,31,11,31,11,11,11,11,11,11,11,1,1,1,1,1,1
1,1,1,1,1,1,11,11,11,11,11,11,0,0,0,0,12,0,0,0,0,0,0,0,31,31,31,0,0,0,11,11,11,0,0,0,0,0,0,0,0,0,0,16,0,11,11,11,11,11,11,1,1,1,1,1,1
1,1,1,1,1,1,11,11,11,11,11,31,0,0,0,0,12,0,0,0,16,0,0,16,31,11,31,16,0,16,31,11,11,0,0,0,0,0,16,0,16,16,0,0,0,11,11,11,11,11,11,1,1,1,1,1,1
1,1,1,1,1,1,11,11,11,31,0,11,0,0,0,16,12,0,0,0,0,0,0,0,0,0,0,60,11,11,11,11,31,0,0,0,0,16,0,16,0,0,16,0,0,11,11,11,11,11,11,1,1,1,1,1,1
1,1,1,1,1,1,11,11,11,0,0,0,0,0,0,11,11,11,11,14,11,31,0,0,0,0,0,60,11,11,11,11,11,0,16,0,11,11,11,11,11,11,0,0,0,16,0,11,11,11,11,1,1,1,1,1,1
1,1,1,1,1,1,11,11,11,0,0,0,0,0,0,11,11,11,11,11,11,11,0,0,0,0,0,60,11,11,11,11,11,0,0,0,14,11,11,11,31,14,0,0,16,0,0,11,11,11,11,1,1,1,1,1,1
1,1,1,1,1,1,11,11,11,0,0,0,0,0,16,0,11,11,11,11,11,31,11,11,31,11,11,11,11,11,11,14,11,0,0,0,11,11,11,11,11,11,0,0,16,0,0,11,11,11,11,1,1,1,1,1,1
1,1,1,1,1,1,11,11,11,31,31,31,16,0,0,0,0,0,0,0,0,31,11,11,0,0,94,0,0,0,31,31,31,0,0,0,0,16,0,11,11,11,14,14,31,11,11,11,11,11,11,1,1,1,1,1,1
1,1,1,1,1,1,11,11,11,31,0,31,0,0,0,0,16,0,0,0,0,11,11,11,0,0,0,0,0,0,31,0,31,0,0,0,16,0,0,11,11,11,31,11,11,11,11,11,11,11,11,1,1,1,1,1,1
1,1,1,1,1,1,11,11,11,31,31,0,0,0,0,0,0,0,0,0,16,11,11,31,0,0,97,0,0,16,31,31,31,0,16,0,0,0,0,14,11,11,31,0,11,11,11,11,11,11,11,1,1,1,1,1,1
1,1,1,1,1,1,11,11,11,0,0,0,0,0,0,0,0,0,0,0,0,11,11,11,11,11,11,0,0,0,0,11,11,0,0,0,0,0,0,0,12,0,0,0,0,11,11,11,11,11,11,1,1,1,1,1,1
1,1,1,1,1,1,11,11,11,0,0,0,0,0,0,0,0,0,0,0,0,11,31,11,11,11,11,0,0,0,11,11,0,0,0,0,0,0,0,0,16,0,0,0,0,11,11,11,11,11,11,1,1,1,1,1,1
1,1,1,1,1,1,11,11,11,16,0,0,0,2,0,0,0,0,0,0,0,11,11,14,14,11,14,0,0,0,11,31,11,0,0,0,0,0,0,0,12,0,0,0,0,11,11,11,11,11,11,1,1,1,1,1,1
1,1,1,1,1,1,11,11,11,0,0,0,0,0,0,0,0,11,16,0,16,11,14,11,16,0,0,0,0,0,31,31,31,14,14,11,0,0,0,11,11,11,31,31,31,11,11,11,11,11,11,1,1,1,1,1,1
1,1,1,1,1,1,11,11,11,0,0,0,0,0,0,0,0,11,109,0,110,0,11,11,0,0,0,0,0,0,31,0,31,11,11,14,109,38,110,11,11,11,31,0,31,11,11,11,11,11,11,1,1,1,1,1,1
1,1,1,1,1,1,11,11,11,48,38,0,0,0,0,0,31,11,48,38,48,11,11,11,0,0,0,0,0,0,31,31,31,31,11,11,0,0,0,11,11,11,31,31,31,11,11,11,11,11,11,1,1,1,1,1,1
1,1,1,1,1,1,11,11,11,38,0,0,0,0,0,0,0,0,16,0,0,0,0,0,0,0,0,0,0,0,0,0,0,0,0,0,16,0,0,0,0,0,0,16,0,11,11,11,11,11,11,1,1,1,1,1,1
1,1,1,1,1,1,11,11,11,38,0,0,0,0,0,0,0,0,0,0,0,0,0,0,0,0,0,0,0,0,0,0,0,0,0,0,0,0,0,0,0,0,0,0,0,11,11,11,11,11,11,1,1,1,1,1,1
1,1,1,1,1,1,11,11,11,38,0,0,0,0,0,0,0,0,16,16,0,0,16,0,0,0,0,0,0,0,0,0,0,0,0,0,0,0,0,0,0,0,0,0,0,11,11,11,11,11,11,1,1,1,1,1,1
1,1,1,1,1,1,11,11,11,38,0,0,0,0,0,0,0,0,11,31,11,0,0,0,11,11,11,31,31,31,31,14,11,11,11,11,16,0,0,31,31,31,0,0,0,11,11,11,11,11,11,1,1,1,1,1,1
1,1,1,1,1,1,11,11,11,38,0,0,0,0,0,0,0,0,14,11,11,109,0,110,14,11,11,31,0,31,14,11,31,11,11,11,0,0,0,31,0,31,16,0,0,11,11,11,11,11,11,11,11,1,1,1,1
1,1,1,1,1,1,11,11,11,12,0,0,12,0,12,0,0,0,11,11,11,0,0,0,14,11,11,31,31,31,11,11,31,11,11,31,0,0,0,31,31,31,0,0,0,11,11,11,11,11,11,11,11,1,1,1,1
1,1,1,1,1,1,11,11,11,48,38,38,11,11,11,25,25,25,31,31,31,0,0,0,31,31,31,0,0,0,0,16,0,0,0,25,0,0,0,11,11,11,0,0,0,11,11,11,11,11,11,11,11,1,1,1,1
1,1,1,1,1,1,11,11,11,38,0,38,11,11,11,0,0,0,31,0,31,0,0,0,31,0,31,0,0,0,16,0,0,0,0,25,0,0,0,11,11,11,0,0,0,11,11,11,11,11,11,1,1,1,1,1,1
1,1,1,1,1,1,11,11,11,38,38,38,31,31,11,0,0,0,31,31,31,0,0,0,31,31,31,0,0,0,0,0,0,0,0,25,0,0,0,11,11,11,12,12,12,11,11,11,11,11,11,1,1,1,1,1,1
1,1,1,1,1,1,11,11,11,11,11,11,11,11,11,11,11,11,11,11,11,11,11,11,11,11,11,11,11,11,11,11,11,11,11,11,11,11,11,11,11,11,11,11,11,11,11,11,11,11,11,1,1,1,1,1,1
1,1,1,1,1,1,11,11,11,11,11,11,11,11,11,11,11,11,11,11,11,11,11,11,11,11,11,11,11,11,11,11,11,11,11,11,11,11,11,11,11,11,11,11,11,11,11,11,11,11,11,1,1,1,1,1,1
1,1,1,1,1,1,11,11,11,11,11,11,11,11,11,11,11,11,11,11,11,11,11,11,11,11,11,11,11,11,11,11,11,11,11,11,11,11,11,11,11,11,11,11,11,11,11,11,11,11,11,1,1,1,1,1,1
1,1,1,1,1,1,1,1,1,1,1,1,1,1,1,1,1,1,1,1,1,1,1,1,1,1,1,1,1,1,1,1,1,1,1,1,1,1,1,1,1,1,1,1,1,1,1,1,1,1,1,1,1,1,1,1,1
1,1,1,1,1,1,1,1,1,1,1,1,1,1,1,1,1,1,1,1,1,1,1,1,1,1,1,1,1,1,1,1,1,1,1,1,1,1,1,1,1,1,1,1,1,1,1,1,1,1,1,1,1,1,1,1,1
:endlayer
layer: 9
1,1,1,1,1,1,11,11,11,11,11,11,11,11,11,11,11,11,11,11,11,11,11,11,11,11,11,11,11,11,11,11,11,11,11,11,11,11,11,11,11,11,11,11,11,11,11,11,11,11,11,1,1,1,1,1,1
1,1,1,1,1,1,11,11,11,11,11,11,11,11,11,11,11,11,11,11,11,11,11,11,11,11,11,11,11,11,11,11,11,11,11,11,11,11,11,11,11,11,11,11,11,11,11,11,11,11,11,1,1,1,1,1,1
1,1,1,1,1,1,11,11,11,11,11,11,11,11,11,11,11,11,11,11,11,11,11,11,11,11,11,11,11,11,11,11,11,11,11,11,11,11,11,11,11,11,11,11,11,11,11,11,11,11,11,1,1,1,1,1,1
1,1,1,1,1,1,11,11,11,11,11,11,11,11,11,11,11,11,11,11,11,11,11,11,11,11,11,11,11,11,11,11,11,11,11,11,11,11,11,11,11,11,11,11,11,11,11,11,11,11,11,1,1,1,1,1,1
1,1,1,1,1,1,11,11,11,11,11,11,11,11,11,11,11,11,11,11,11,11,11,11,11,11,11,11,11,11,11,11,11,11,11,11,11,11,11,11,11,11,11,11,11,11,11,11,11,11,11,1,1,1,1,1,1
1,1,1,1,1,1,11,11,11,11,11,11,11,11,11,11,11,11,11,11,11,11,11,11,11,11,11,11,11,11,11,11,11,11,11,11,11,11,11,11,11,11,11,11,11,11,11,11,11,11,11,1,1,1,1,1,1
1,1,1,1,1,1,11,11,11,11,11,11,11,11,11,11,11,11,11,11,11,11,11,11,11,11,11,11,11,11,11,11,11,11,11,11,11,11,11,11,11,11,11,11,11,11,11,11,11,11,11,1,1,1,1,1,1
1,1,1,1,1,1,11,11,11,11,11,11,11,11,11,11,11,11,11,11,11,11,11,11,11,11,11,11,11,11,11,11,11,11,11,11,11,11,11,11,11,11,11,11,11,11,11,11,11,11,11,1,1,1,1,1,1
1,1,1,1,1,1,11,11,11,11,11,11,11,11,11,11,11,11,11,11,11,11,11,11,11,11,11,11,11,11,11,11,11,11,11,11,11,11,11,11,11,11,11,11,11,11,11,11,11,11,11,1,1,1,1,1,1
1,1,1,1,1,1,11,11,11,11,11,11,11,11,11,11,11,11,11,11,11,11,11,11,11,11,11,11,11,11,11,11,11,11,11,11,11,11,11,11,11,11,11,11,11,11,11,11,11,11,11,1,1,1,1,1,1
1,1,1,1,1,1,11,11,11,11,11,11,11,11,11,11,11,11,11,11,11,11,11,11,11,11,11,11,11,11,11,11,11,11,11,11,11,11,11,11,11,11,11,11,11,11,11,11,11,11,11,1,1,1,1,1,1
1,1,1,1,1,1,11,11,11,11,11,11,11,11,11,11,11,11,11,11,11,11,11,11,11,11,11,0,0,0,0,11,11,11,11,11,11,11,11,11,11,11,11,11,11,11,11,11,11,11,11,1,1,1,1,1,1
1,1,1,1,1,1,11,11,11,11,11,11,11,11,11,11,11,11,11,11,11,11,11,11,11,11,11,0,0,0,0,11,11,11,11,11,11,11,11,11,11,11,11,11,11,11,11,11,11,11,11,1,1,1,1,1,1
1,1,1,1,1,1,11,11,11,11,11,11,11,11,11,11,11,11,11,11,11,11,11,11,11,11,11,11,11,11,11,11,11,11,11,11,11,11,11,11,11,11,11,11,11,11,11,11,11,11,11,1,1,1,1,1,1
1,1,1,1,1,1,11,11,11,11,11,11,11,11,11,11,11,11,11,11,11,11,11,11,11,11,11,11,11,11,11,11,11,11,11,11,11,11,11,11,11,11,11,11,11,11,11,11,11,11,11,1,1,1,1,1,1
1,1,1,1,1,1,11,11,11,11,11,11,11,11,11,11,11,11,11,11,11,11,11,0,0,0,0,16,60,11,11,11,11,11,11,11,11,11,11,11,11,11,11,11,11,11,11,11,11,11,11,1,1,1,1,1,1
1,1,1,1,1,1,11,11,11,11,11,11,11,11,11,11,11,11,11,11,11,11,0,0,0,0,0,0,60,11,11,11,11,11,11,11,11,11,11,11,11,11,11,11,11,11,11,11,11,11,11,1,1,1,1,1,1
1,1,1,1,1,1,11,11,11,11,11,11,11,11,11,11,11,11,11,11,11,11,0,0,0,0,16,0,60,11,11,11,11,11,11,11,11,11,11,11,11,11,11,11,11,11,11,11,11,11,11,1,1,1,1,1,1
1,1,1,1,1,1,11,11,11,11,11,11,11,11,11,11,11,11,11,11,11,11,11,11,11,11,11,11,11,11,11,11,11,11,11,11,11,11,11,11,11,11,11,11,11,11,11,11,11,11,11,1,1,1,1,1,1
1,1,1,1,1,1,11,11,11,11,11,11,11,11,11,11,11,11,11,11,11,11,11,11,11,11,11,11,11,11,11,11,11,11,11,11,11,11,11,11,11,11,11,11,11,11,11,11,11,11,11,1,1,1,1,1,1
1,1,1,1,1,1,11,11,11,11,11,11,11,11,11,11,11,11,11,11,11,11,11,11,11,11,11,11,11,11,11,11,11,11,11,11,11,11,11,11,11,11,11,11,11,11,11,11,11,11,11,1,1,1,1,1,1
1,1,1,1,1,1,11,11,11,11,11,0,0,0,0,0,11,11,11,11,11,11,11,11,11,11,11,11,11,11,11,11,11,11,11,11,11,11,11,11,11,11,11,11,11,11,11,11,11,11,11,1,1,1,1,1,1
1,1,1,1,1,1,11,11,11,11,0,0,0,0,0,0,0,11,11,11,11,11,11,11,11,11,11,11,11,11,11,11,11,11,11,11,11,11,11,11,11,11,11,11,11,11,11,11,11,11,11,1,1,1,1,1,1
1,1,1,1,1,1,11,11,11,11,0,0,0,0,0,0,0,11,11,11,11,11,11,11,11,11,11,11,11,11,11,11,11,11,11,11,11,11,11,11,11,11,11,11,11,11,11,11,11,11,11,1,1,1,1,1,1
1,1,1,1,1,1,11,11,11,11,0,0,0,2,0,0,0,11,11,11,11,11,11,11,11,11,11,11,11,11,11,11,11,11,11,11,11,11,11,11,11,11,11,11,11,11,11,11,11,11,11,1,1,1,1,1,1
1,1,1,1,1,1,11,11,11,11,0,0,0,0,0,0,0,11,11,11,11,11,11,11,11,11,11,11,11,11,11,11,11,11,11,11,11,11,11,11,11,11,11,11,11,11,11,11,11,11,11,1,1,1,1,1,1
1,1,1,1,1,1,11,11,11,11,0,0,0,0,0,0,0,11,11,11,11,11,11,11,11,11,11,11,11,11,11,11,11,11,11,11,11,11,11,11,11,11,11,11,11,11,11,11,11,11,11,1,1,1,1,1,1
1,1,1,1,1,1,11,11,11,11,11,0,0,0,0,0,11,11,11,11,11,11,11,11,11,11,11,11,11,11,11,11,11,11,11,11,11,11,11,11,11,11,11,11,11,11,11,11,11,11,11,1,1,1,1,1,1
1,1,1,1,1,1,11,11,11,11,14,14,14,14,14,14,14,11,11,11,11,11,11,11,11,11,11,11,11,11,11,11,11,11,11,11,11,11,11,11,11,11,11,11,11,11,11,11,11,11,11,1,1,1,1,1,1
1,1,1,1,1,1,11,11,11,11,14,14,14,14,14,14,14,11,11,11,11,11,11,11,11,11,11,11,11,11,11,11,11,11,11,11,11,11,11,11,11,11,11,11,11,11,11,11,11,11,11,1,1,1,1,1,1
1,1,1,1,1,1,11,11,11,11,14,14,14,14,14,14,14,11,11,11,11,11,11,11,11,11,11,11,11,11,11,11,11,11,11,11,11,11,11,11,11,11,11,11,11,11,11,11,11,11,11,1,1,1,1,1,1
1,1,1,1,1,1,11,11,11,11,14,14,14,14,14,14,14,11,11,11,11,11,11,11,11,11,11,11,11,11,11,11,11,11,11,11,11,11,11,11,11,11,11,11,11,11,11,11,11,11,11,1,1,1,1,1,1
1,1,1,1,1,1,11,11,11,11,14,14,14,14,14,14,14,11,11,11,11,11,11,11,11,11,11,11,11,11,11,11,11,11,11,11,11,11,11,11,11,11,11,11,11,11,11,11,11,11,11,1,1,1,1,1,1
1,1,1,1,1,1,11,11,11,11,11,14,14,14,14,14,11,11,11,11,11,11,11,11,11,11,11,11,11,11,11,11,11,11,11,11,11,11,11,11,11,11,11,11,11,11,11,11,11,11,11,1,1,1,1,1,1
1,1,1,1,1,1,11,11,11,11,11,11,11,11,11,11,11,11,11,11,11,11,11,11,11,11,11,11,11,11,11,11,11,11,11,11,11,11,11,11,11,11,11,11,11,11,11,11,11,11,11,1,1,1,1,1,1
1,1,1,1,1,1,11,11,11,11,11,11,11,11,11,11,11,11,11,11,11,11,11,11,11,11,11,11,11,11,11,11,11,11,11,11,11,11,11,11,11,11,11,11,11,11,11,11,11,11,11,1,1,1,1,1,1
1,1,1,1,1,1,11,11,11,11,11,11,11,11,11,11,11,11,11,11,11,11,11,11,11,11,11,11,11,11,11,11,11,11,11,11,11,11,11,11,11,11,11,11,11,11,11,11,11,11,11,1,1,1,1,1,1
1,1,1,1,1,1,11,11,11,11,11,11,11,11,11,11,11,11,11,11,11,11,11,11,11,11,11,11,11,11,11,11,11,11,11,11,11,11,11,11,11,11,11,11,11,11,11,11,11,11,11,1,1,1,1,1,1
1,1,1,1,1,1,11,11,11,11,11,11,11,11,11,11,11,11,11,11,11,11,11,11,11,11,11,11,11,11,11,11,11,11,11,11,11,11,11,11,11,11,11,11,11,11,11,11,11,11,11,1,1,1,1,1,1
1,1,1,1,1,1,11,11,11,11,11,11,11,11,11,11,11,11,11,11,11,11,11,11,11,11,11,11,11,11,11,11,11,11,11,11,11,11,11,11,11,11,11,11,11,11,11,11,11,11,11,1,1,1,1,1,1
1,1,1,1,1,1,1,1,1,1,1,1,1,1,1,1,1,1,1,1,1,1,1,1,1,1,1,1,1,1,1,1,1,1,1,1,1,1,1,1,1,1,1,1,1,1,1,1,1,1,1,1,1,1,1,1,1
1,1,1,1,1,1,1,1,1,1,1,1,1,1,1,1,1,1,1,1,1,1,1,1,1,1,1,1,1,1,1,1,1,1,1,1,1,1,1,1,1,1,1,1,1,1,1,1,1,1,1,1,1,1,1,1,1
:endlayer
layer: 10
1,1,1,1,1,1,1,1,1,1,1,1,1,1,1,1,1,1,1,1,1,1,1,1,1,1,1,1,1,1,1,1,1,1,1,1,1,1,1,1,1,1,1,1,1,1,1,1,1,1,1,1,1,1,1,1,1
1,1,1,1,1,1,1,1,1,1,1,1,1,1,1,1,1,1,1,1,1,1,1,1,1,1,1,1,1,1,1,1,1,1,1,1,1,1,1,1,1,1,1,1,1,1,1,1,1,1,1,1,1,1,1,1,1
1,1,1,1,1,1,1,1,1,1,1,1,1,1,1,1,1,1,1,1,1,1,1,1,1,1,1,1,1,1,1,1,1,1,1,1,1,1,1,1,1,1,1,1,1,1,1,1,1,1,1,1,1,1,1,1,1
1,1,1,1,1,1,1,1,1,1,1,1,1,1,1,1,1,1,1,1,1,1,1,1,1,1,1,1,1,1,1,1,1,1,1,1,1,1,1,1,1,1,1,1,1,1,1,1,1,1,1,1,1,1,1,1,1
1,1,1,1,1,1,1,1,1,1,1,1,1,1,1,1,1,1,1,1,1,1,1,1,1,1,1,1,1,1,1,1,1,1,1,1,1,1,1,1,1,1,1,1,1,1,1,1,1,1,1,1,1,1,1,1,1
1,1,1,1,1,1,1,1,1,1,1,1,1,1,1,1,1,1,1,1,1,1,1,1,1,1,1,1,1,1,1,1,1,1,1,1,1,1,1,1,1,1,1,1,1,1,1,1,1,1,1,1,1,1,1,1,1
1,1,1,1,1,1,1,1,1,1,1,1,1,1,1,1,1,1,1,1,1,1,1,1,1,1,1,1,1,1,1,1,1,1,1,1,1,1,1,1,1,1,1,1,1,1,1,1,1,1,1,1,1,1,1,1,1
1,1,1,1,1,1,1,1,1,1,1,1,1,1,1,1,1,1,1,1,1,1,1,1,1,1,1,1,1,1,1,1,1,1,1,1,1,1,1,1,1,1,1,1,1,1,1,1,1,1,1,1,1,1,1,1,1
1,1,1,1,1,1,1,1,1,1,1,1,1,1,1,1,1,1,1,1,1,1,1,1,1,1,1,1,1,1,1,1,1,1,1,1,1,1,1,1,1,1,1,1,1,1,1,1,1,1,1,1,1,1,1,1,1
1,1,1,1,1,1,1,1,1,1,1,1,1,1,1,1,1,1,1,1,1,1,1,1,1,1,1,1,1,1,1,1,1,1,1,1,1,1,1,1,1,1,1,1,1,1,1,1,1,1,1,1,1,1,1,1,1
1,1,1,1,1,1,1,1,1,1,1,1,1,1,1,1,1,1,1,1,1,1,1,1,1,1,1,1,1,1,1,1,1,1,1,1,1,1,1,1,1,1,1,1,1,1,1,1,1,1,1,1,1,1,1,1,1
1,1,1,1,1,1,1,1,1,1,1,1,1,1,1,1,1,1,1,1,1,1,1,1,1,1,1,0,0,0,0,1,1,1,1,1,1,1,1,1,1,1,1,1,1,1,1,1,1,1,1,1,1,1,1,1,1
1,1,1,1,1,1,1,1,1,1,1,1,1,1,1,1,1,1,1,1,1,1,1,1,1,1,1,0,0,0,0,1,1,1,1,1,1,1,1,1,1,1,1,1,1,1,1,1,1,1,1,1,1,1,1,1,1
1,1,1,1,1,1,1,1,1,1,1,1,1,1,1,1,1,1,1,1,1,1,1,1,1,1,1,1,1,0,0,1,1,1,1,1,1,1,1,1,1,1,1,1,1,1,1,1,1,1,1,1,1,1,1,1,1
1,1,1,1,1,1,1,1,1,1,1,1,1,1,1,1,1,1,1,1,1,1,1,1,1,1,1,1,1,23,23,23,1,1,1,1,1,1,1,1,1,1,1,1,1,1,1,1,1,1,1,1,1,1,1,1,1
1,1,1,1,1,1,1,1,1,1,1,1,1,1,1,1,1,1,1,1,1,1,1,1,0,0,0,16,16,0,0,0,1,1,1,1,1,1,1,1,1,1,1,1,1,1,1,1,1,1,1,1,1,1,1,1,1
1,1,1,1,1,1,1,1,1,1,1,1,1,1,1,1,1,1,1,1,1,1,1,1,0,0,0,0,16,0,0,0,1,1,1,1,1,1,1,1,1,1,1,1,1,1,1,1,1,1,1,1,1,1,1,1,1
1,1,1,1,1,1,1,1,1,1,1,1,1,1,1,1,1,1,1,1,1,1,33,1,0,16,0,0,16,0,0,0,1,1,1,1,1,1,1,1,1,1,1,1,1,1,1,1,1,1,1,1,1,1,1,1,1
1,1,1,1,1,1,1,1,1,1,1,1,1,1,1,1,1,1,1,1,1,1,1,1,1,1,1,1,1,1,1,1,1,1,1,1,1,1,1,1,1,1,1,1,1,1,1,1,1,1,1,1,1,1,1,1,1
1,1,1,1,1,1,1,1,1,1,1,1,1,1,1,1,1,1,1,1,1,1,1,1,1,1,1,1,1,1,1,1,1,1,1,1,1,1,1,1,1,1,1,1,1,1,1,1,1,1,1,1,1,1,1,1,1
1,1,1,1,1,1,1,1,1,1,1,1,1,1,1,1,1,1,1,1,1,1,1,1,1,1,1,1,1,1,1,1,1,1,1,1,1,1,1,1,1,1,1,1,1,1,1,1,1,1,1,1,1,1,1,1,1
1,1,1,1,1,1,1,1,1,1,1,1,1,1,1,1,1,1,1,1,1,1,1,1,1,1,1,1,1,1,1,1,1,1,1,1,1,1,1,1,1,1,1,1,1,1,1,1,1,1,1,1,1,1,1,1,1
1,1,1,1,1,1,1,1,1,1,1,1,1,1,1,1,1,1,1,1,1,1,1,1,1,1,1,1,1,1,1,1,1,1,1,1,1,1,1,1,1,1,1,1,1,1,1,1,1,1,1,1,1,1,1,1,1
1,1,1,1,1,1,1,1,1,1,1,1,1,1,1,1,1,1,1,1,1,1,1,1,1,1,1,1,1,1,1,1,1,1,1,1,1,1,1,1,1,1,1,1,1,1,1,1,1,1,1,1,1,1,1,1,1
1,1,1,1,1,1,1,1,1,1,1,1,1,2,1,1,1,1,1,1,1,1,1,1,1,1,1,1,1,1,1,1,1,1,1,1,1,1,1,1,1,1,1,1,1,1,1,1,1,1,1,1,1,1,1,1,1
1,1,1,1,1,1,1,1,1,1,1,1,1,1,1,1,1,1,1,1,1,1,1,1,1,1,1,1,1,1,1,1,1,1,1,1,1,1,1,1,1,1,1,1,1,1,1,1,1,1,1,1,1,1,1,1,1
1,1,1,1,1,1,1,1,1,1,1,1,1,1,1,1,1,1,1,1,1,1,1,1,1,1,1,1,1,1,1,1,1,1,1,1,1,1,1,1,1,1,1,1,1,1,1,1,1,1,1,1,1,1,1,1,1
1,1,1,1,1,1,1,1,1,1,1,1,1,1,1,1,1,1,1,1,1,1,1,1,1,1,1,1,1,1,1,1,1,1,1,1,1,1,1,1,1,1,1,1,1,1,1,1,1,1,1,1,1,1,1,1,1
1,1,1,1,1,1,1,1,1,1,1,1,1,1,1,1,1,1,1,1,1,1,1,1,1,1,1,1,1,1,1,1,1,1,1,1,1,1,1,1,1,1,1,1,1,1,1,1,1,1,1,1,1,1,1,1,1
1,1,1,1,1,1,1,1,1,1,1,1,1,1,1,1,1,1,1,1,1,1,1,1,1,1,1,1,1,1,1,1,1,1,1,1,1,1,1,1,1,1,1,1,1,1,1,1,1,1,1,1,1,1,1,1,1
1,1,1,1,1,1,1,1,1,1,1,1,1,1,1,1,1,1,1,1,1,1,1,1,1,1,1,1,1,1,1,1,1,1,1,1,1,1,1,1,1,1,1,1,1,1,1,1,1,1,1,1,1,1,1,1,1
1,1,1,1,1,1,1,1,1,1,1,1,1,1,1,1,1,1,1,1,1,1,1,1,1,1,1,1,1,1,1,1,1,1,1,1,1,1,1,1,1,1,1,1,1,1,1,1,1,1,1,1,1,1,1,1,1
1,1,1,1,1,1,1,1,1,1,1,1,1,1,1,1,1,1,1,1,1,1,1,1,1,1,1,1,1,1,1,1,1,1,1,1,1,1,1,1,1,1,1,1,1,1,1,1,1,1,1,1,1,1,1,1,1
1,1,1,1,1,1,1,1,1,1,1,1,1,1,1,1,1,1,1,1,1,1,1,1,1,1,1,1,1,1,1,1,1,1,1,1,1,1,1,1,1,1,1,1,1,1,1,1,1,1,1,1,1,1,1,1,1
1,1,1,1,1,1,1,1,1,1,1,1,1,1,1,1,1,1,1,1,1,1,1,1,1,1,1,1,1,1,1,1,1,1,1,1,1,1,1,1,1,1,1,1,1,1,1,1,1,1,1,1,1,1,1,1,1
1,1,1,1,1,1,1,1,1,1,1,1,1,1,1,1,1,1,1,1,1,1,1,1,1,1,1,1,1,1,1,1,1,1,1,1,1,1,1,1,1,1,1,1,1,1,1,1,1,1,1,1,1,1,1,1,1
1,1,1,1,1,1,1,1,1,1,1,1,1,1,1,1,1,1,1,1,1,1,1,1,1,1,1,1,1,1,1,1,1,1,1,1,1,1,1,1,1,1,1,1,1,1,1,1,1,1,1,1,1,1,1,1,1
1,1,1,1,1,1,1,1,1,1,1,1,1,1,1,1,1,1,1,1,1,1,1,1,1,1,1,1,1,1,1,1,1,1,1,1,1,1,1,1,1,1,1,1,1,1,1,1,1,1,1,1,1,1,1,1,1
1,1,1,1,1,1,1,1,1,1,1,1,1,1,1,1,1,1,1,1,1,1,1,1,1,1,1,1,1,1,1,1,1,1,1,1,1,1,1,1,1,1,1,1,1,1,1,1,1,1,1,1,1,1,1,1,1
1,1,1,1,1,1,1,1,1,1,1,1,1,1,1,1,1,1,1,1,1,1,1,1,1,1,1,1,1,1,1,1,1,1,1,1,1,1,1,1,1,1,1,1,1,1,1,1,1,1,1,1,1,1,1,1,1
1,1,1,1,1,1,1,1,1,1,1,1,1,1,1,1,1,1,1,1,1,1,1,1,1,1,1,1,1,1,1,1,1,1,1,1,1,1,1,1,1,1,1,1,1,1,1,1,1,1,1,1,1,1,1,1,1
1,1,1,1,1,1,1,1,1,1,1,1,1,1,1,1,1,1,1,1,1,1,1,1,1,1,1,1,1,1,1,1,1,1,1,1,1,1,1,1,1,1,1,1,1,1,1,1,1,1,1,1,1,1,1,1,1
:endlayer
layer: 11
1,1,1,1,1,1,1,1,1,1,1,1,1,1,1,1,1,1,1,1,1,1,1,1,1,1,1,1,1,1,1,1,1,1,1,1,1,1,1,1,1,1,1,1,1,1,1,1,1,1,1,1,1,1,1,1,1
1,1,1,1,1,1,1,1,1,1,1,1,1,1,1,1,1,1,1,1,1,1,1,1,1,1,1,1,1,1,1,1,1,1,1,1,1,1,1,1,1,1,1,1,1,1,1,1,1,1,1,1,1,1,1,1,1
1,1,1,1,1,1,1,1,1,1,1,1,1,1,1,1,1,1,1,1,1,1,1,1,1,1,1,1,1,1,1,1,1,1,1,1,1,1,1,1,1,1,1,1,1,1,1,1,1,1,1,1,1,1,1,1,1
1,1,1,1,1,1,1,1,1,1,1,1,1,1,1,1,1,1,1,1,1,1,1,1,1,1,1,1,1,1,1,1,1,1,1,1,1,1,1,1,1,1,1,1,1,1,1,1,1,1,1,1,1,1,1,1,1
1,1,1,1,1,1,1,1,1,1,1,1,1,1,1,1,1,1,1,1,1,1,1,1,1,1,1,1,1,1,1,1,1,1,1,1,1,1,1,1,1,1,1,1,1,1,1,1,1,1,1,1,1,1,1,1,1
1,1,1,1,1,1,1,1,1,1,1,1,1,1,1,1,1,1,1,1,1,1,1,1,1,1,1,1,1,1,1,1,1,1,1,1,1,1,1,1,1,1,1,1,1,1,1,1,1,1,1,1,1,1,1,1,1
1,1,1,1,1,1,1,1,1,1,1,1,1,1,1,1,1,1,1,1,1,1,1,1,1,1,1,1,1,1,1,1,1,1,1,1,1,1,1,1,1,1,1,1,1,1,1,1,1,1,1,1,1,1,1,1,1
1,1,1,1,1,1,1,1,1,1,1,1,1,1,1,1,1,1,1,1,1,1,1,1,1,1,1,1,1,1,1,1,1,1,1,1,1,1,1,1,1,1,1,1,1,1,1,1,1,1,1,1,1,1,1,1,1
1,1,1,1,1,1,1,1,1,1,1,1,1,1,1,1,1,1,1,1,1,1,1,1,1,1,1,1,1,1,1,1,1,1,1,1,1,1,1,1,1,1,1,1,1,1,1,1,1,1,1,1,1,1,1,1,1
1,1,1,1,1,1,1,1,1,1,1,1,1,1,1,1,1,1,1,1,1,1,1,1,1,1,1,1,1,1,1,1,1,1,1,1,1,1,1,1,1,1,1,1,1,1,1,1,1,1,1,1,1,1,1,1,1
1,1,1,1,1,1,1,1,1,1,1,1,1,1,1,1,1,1,1,1,1,1,1,1,1,1,1,1,1,11,11,11,1,1,1,1,1,1,1,1,1,1,1,1,1,1,1,1,1,1,1,1,1,1,1,1,1
1,1,1,1,1,1,1,1,1,1,1,1,1,1,1,1,1,1,1,1,1,1,1,1,1,1,1,11,11,11,11,11,1,1,1,1,1,1,1,1,1,1,1,1,1,1,1,1,1,1,1,1,1,1,1,1,1
1,1,1,1,1,1,1,1,1,1,1,1,1,1,1,1,1,1,1,1,1,1,1,1,1,1,1,11,11,11,11,11,1,1,1,1,1,1,1,1,1,1,1,1,1,1,1,1,1,1,1,1,1,1,1,1,1
1,1,1,1,1,1,1,1,1,1,1,1,1,1,1,1,1,1,1,1,1,1,1,1,1,1,1,1,1,23,23,23,1,1,1,1,1,1,1,1,1,1,1,1,1,1,1,1,1,1,1,1,1,1,1,1,1
1,1,1,1,1,1,1,1,1,1,1,1,1,1,1,1,1,1,1,1,1,1,1,1,1,1,1,1,1,0,0,0,1,1,1,1,1,1,1,1,1,1,1,1,1,1,1,1,1,1,1,1,1,1,1,1,1
1,1,1,1,1,1,1,1,1,1,1,1,1,1,1,1,1,1,1,1,1,1,1,1,1,16,0,16,16,0,0,0,1,1,1,1,1,1,1,1,1,1,1,1,1,1,1,1,1,1,1,1,1,1,1,1,1
1,1,1,1,1,1,1,1,1,1,1,1,1,1,1,1,1,1,1,1,1,1,1,1,1,16,0,16,16,0,0,0,1,1,1,1,1,1,1,1,1,1,1,1,1,1,1,1,1,1,1,1,1,1,1,1,1
1,1,1,1,1,1,1,1,1,1,1,1,1,1,1,1,1,1,1,1,1,1,1,1,1,16,0,0,0,0,0,0,1,1,1,1,1,1,1,1,1,1,1,1,1,1,1,1,1,1,1,1,1,1,1,1,1
1,1,1,1,1,1,1,1,1,1,1,1,1,1,1,1,1,1,1,1,1,1,1,1,1,1,1,1,1,1,1,1,1,1,1,1,1,1,1,1,1,1,1,1,1,1,1,1,1,1,1,1,1,1,1,1,1
1,1,1,1,1,1,1,1,1,1,1,1,1,1,1,1,1,1,1,1,1,1,1,1,1,1,1,1,1,1,1,1,1,1,1,1,1,1,1,1,1,1,1,1,1,1,1,1,1,1,1,1,1,1,1,1,1
1,1,1,1,1,1,1,1,1,1,1,1,1,1,1,1,1,1,1,1,1,1,1,1,1,1,1,1,1,1,1,1,1,1,1,1,1,1,1,1,1,1,1,1,1,1,1,1,1,1,1,1,1,1,1,1,1
1,1,1,1,1,1,1,1,1,1,1,1,1,1,1,1,1,1,1,1,1,1,1,1,1,1,1,1,1,1,1,1,1,1,1,1,1,1,1,1,1,1,1,1,1,1,1,1,1,1,1,1,1,1,1,1,1
1,1,1,1,1,1,1,1,1,1,1,1,1,1,1,1,1,1,1,1,1,1,1,1,1,1,1,1,1,1,1,1,1,1,1,1,1,1,1,1,1,1,1,1,1,1,1,1,1,1,1,1,1,1,1,1,1
1,1,1,1,1,1,1,1,1,1,1,1,1,1,1,1,1,1,1,1,1,1,1,1,1,1,1,1,1,1,1,1,1,1,1,1,1,1,1,1,1,1,1,1,1,1,1,1,1,1,1,1,1,1,1,1,1
1,1,1,1,1,1,1,1,1,1,1,1,1,10,1,1,1,1,1,1,1,1,1,1,1,1,1,1,1,1,1,1,1,1,1,1,1,1,1,1,1,1,1,1,1,1,1,1,1,1,1,1,1,1,1,1,1
1,1,1,1,1,1,1,1,1,1,1,1,1,1,1,1,1,1,1,1,1,1,1,1,1,1,1,1,1,1,1,1,1,1,1,1,1,1,1,1,1,1,1,1,1,1,1,1,1,1,1,1,1,1,1,1,1
1,1,1,1,1,1,1,1,1,1,1,1,1,1,1,1,1,1,1,1,1,1,1,1,1,1,1,1,1,1,1,1,1,1,1,1,1,1,1,1,1,1,1,1,1,1,1,1,1,1,1,1,1,1,1,1,1
1,1,1,1,1,1,1,1,1,1,1,1,1,1,1,1,1,1,1,1,1,1,1,1,1,1,1,1,1,1,1,1,1,1,1,1,1,1,1,1,1,1,1,1,1,1,1,1,1,1,1,1,1,1,1,1,1
1,1,1,1,1,1,1,1,1,1,1,1,1,1,1,1,1,1,1,1,1,1,1,1,1,1,1,1,1,1,1,1,1,1,1,1,1,1,1,1,1,1,1,1,1,1,1,1,1,1,1,1,1,1,1,1,1
1,1,1,1,1,1,1,1,1,1,1,1,1,1,1,1,1,1,1,1,1,1,1,1,1,1,1,1,1,1,1,1,1,1,1,1,1,1,1,1,1,1,1,1,1,1,1,1,1,1,1,1,1,1,1,1,1
1,1,1,1,1,1,1,1,1,1,1,1,1,1,1,1,1,1,1,1,1,1,1,1,1,1,1,1,1,1,1,1,1,1,1,1,1,1,1,1,1,1,1,1,1,1,1,1,1,1,1,1,1,1,1,1,1
1,1,1,1,1,1,1,1,1,1,1,1,1,1,1,1,1,1,1,1,1,1,1,1,1,1,1,1,1,1,1,1,1,1,1,1,1,1,1,1,1,1,1,1,1,1,1,1,1,1,1,1,1,1,1,1,1
1,1,1,1,1,1,1,1,1,1,1,1,1,1,1,1,1,1,1,1,1,1,1,1,1,1,1,1,1,1,1,1,1,1,1,1,1,1,1,1,1,1,1,1,1,1,1,1,1,1,1,1,1,1,1,1,1
1,1,1,1,1,1,1,1,1,1,1,1,1,1,1,1,1,1,1,1,1,1,1,1,1,1,1,1,1,1,1,1,1,1,1,1,1,1,1,1,1,1,1,1,1,1,1,1,1,1,1,1,1,1,1,1,1
1,1,1,1,1,1,1,1,1,1,1,1,1,1,1,1,1,1,1,1,1,1,1,1,1,1,1,1,1,1,1,1,1,1,1,1,1,1,1,1,1,1,1,1,1,1,1,1,1,1,1,1,1,1,1,1,1
1,1,1,1,1,1,1,1,1,1,1,1,1,1,1,1,1,1,1,1,1,1,1,1,1,1,1,1,1,1,1,1,1,1,1,1,1,1,1,1,1,1,1,1,1,1,1,1,1,1,1,1,1,1,1,1,1
1,1,1,1,1,1,1,1,1,1,1,1,1,1,1,1,1,1,1,1,1,1,1,1,1,1,1,1,1,1,1,1,1,1,1,1,1,1,1,1,1,1,1,1,1,1,1,1,1,1,1,1,1,1,1,1,1
1,1,1,1,1,1,1,1,1,1,1,1,1,1,1,1,1,1,1,1,1,1,1,1,1,1,1,1,1,1,1,1,1,1,1,1,1,1,1,1,1,1,1,1,1,1,1,1,1,1,1,1,1,1,1,1,1
1,1,1,1,1,1,1,1,1,1,1,1,1,1,1,1,1,1,1,1,1,1,1,1,1,1,1,1,1,1,1,1,1,1,1,1,1,1,1,1,1,1,1,1,1,1,1,1,1,1,1,1,1,1,1,1,1
1,1,1,1,1,1,1,1,1,1,1,1,1,1,1,1,1,1,1,1,1,1,1,1,1,1,1,1,1,1,1,1,1,1,1,1,1,1,1,1,1,1,1,1,1,1,1,1,1,1,1,1,1,1,1,1,1
1,1,1,1,1,1,1,1,1,1,1,1,1,1,1,1,1,1,1,1,1,1,1,1,1,1,1,1,1,1,1,1,1,1,1,1,1,1,1,1,1,1,1,1,1,1,1,1,1,1,1,1,1,1,1,1,1
1,1,1,1,1,1,1,1,1,1,1,1,1,1,1,1,1,1,1,1,1,1,1,1,1,1,1,1,1,1,1,1,1,1,1,1,1,1,1,1,1,1,1,1,1,1,1,1,1,1,1,1,1,1,1,1,1
:endlayer
layer: 12
1,1,1,1,1,1,1,1,1,1,1,1,1,1,1,1,1,1,1,1,1,1,1,1,1,1,1,1,1,1,1,1,1,1,1,1,1,1,1,1,1,1,1,1,1,1,1,1,1,1,1,1,1,1,1,1,1
1,1,1,1,1,1,1,1,1,1,1,1,1,1,1,1,1,1,1,1,1,1,1,1,1,1,1,1,1,1,1,1,1,1,1,1,1,1,1,1,1,1,1,1,1,1,1,1,1,1,1,1,1,1,1,1,1
1,1,1,1,1,1,1,1,1,1,1,1,1,1,1,1,1,1,1,1,1,1,1,1,1,1,1,1,1,1,1,1,1,1,1,1,1,1,1,1,1,1,1,1,1,1,1,1,1,1,1,1,1,1,1,1,1
1,1,1,1,1,1,1,1,1,1,1,1,1,1,1,1,1,1,1,1,1,1,1,1,1,1,1,1,1,1,1,1,1,1,1,1,1,1,1,1,1,1,1,1,1,1,1,1,1,1,1,1,1,1,1,1,1
1,1,1,1,1,1,1,1,1,1,1,1,1,1,1,1,1,1,1,1,1,1,1,1,1,1,1,1,1,1,1,1,1,1,1,1,1,1,1,1,1,1,1,1,1,1,1,1,1,1,1,1,1,1,1,1,1
1,1,1,1,1,1,1,1,1,1,1,1,1,1,1,1,1,1,1,1,1,1,1,1,1,1,1,1,1,1,1,1,1,1,1,1,1,1,1,1,1,1,1,1,1,1,1,1,1,1,1,1,1,1,1,1,1
1,1,1,1,1,1,1,1,1,1,1,1,1,1,1,1,1,1,1,1,1,1,1,1,1,1,1,1,1,1,1,1,1,1,1,1,1,1,1,1,1,1,1,1,1,1,1,1,1,1,1,1,1,1,1,1,1
1,1,1,1,1,1,1,1,1,1,1,1,1,1,1,1,1,1,1,1,1,1,1,1,1,1,1,1,1,1,1,1,1,1,1,1,1,1,1,1,1,1,1,1,1,1,1,1,1,1,1,1,1,1,1,1,1
1,1,1,1,1,1,1,1,1,1,1,1,1,1,1,1,1,1,1,1,1,1,1,1,1,1,1,1,1,1,1,1,1,1,1,1,1,1,1,1,1,1,1,1,1,1,1,1,1,1,1,1,1,1,1,1,1
1,1,1,1,1,1,1,1,1,1,1,1,1,1,1,1,1,1,1,1,1,1,1,1,1,1,1,1,1,1,1,1,1,1,1,1,1,1,1,1,1,1,1,1,1,1,1,1,1,1,1,1,1,1,1,1,1
1,1,1,1,1,1,1,1,1,1,1,1,1,1,1,1,1,1,1,1,1,1,1,1,1,1,1,1,76,0,0,0,1,1,1,1,1,1,1,1,1,1,1,1,1,1,1,1,1,1,1,1,1,1,1,1,1
1,1,1,1,1,1,1,1,1,1,1,1,1,1,1,1,1,1,1,1,1,1,1,1,1,1,1,0,76,0,0,0,1,1,1,1,1,1,1,1,1,1,1,1,1,1,1,1,1,1,1,1,1,1,1,1,1
1,1,1,1,1,1,1,1,1,1,1,1,1,1,1,1,1,1,1,1,1,1,1,1,122,122,122,122,122,0,0,0,1,1,1,1,1,1,1,1,1,1,1,1,1,1,1,1,1,1,1,1,1,1,1,1,1
1,1,1,1,1,1,1,1,1,1,1,1,1,1,1,1,1,1,1,1,1,1,1,1,1,1,1,1,1,0,0,0,1,1,1,1,1,1,1,1,1,1,1,1,1,1,1,1,1,1,1,1,1,1,1,1,1
1,1,1,1,1,1,1,1,1,1,1,1,1,1,1,1,1,1,1,1,1,1,1,1,1,1,1,1,1,0,0,0,1,1,1,1,1,1,1,1,1,1,1,1,1,1,1,1,1,1,1,1,1,1,1,1,1
1,1,1,1,1,1,1,1,1,1,1,1,1,1,1,1,1,1,1,1,1,1,1,1,1,1,16,16,0,0,0,0,1,1,1,1,1,1,1,1,1,1,1,1,1,1,1,1,1,1,1,1,1,1,1,1,1
1,1,1,1,1,1,1,1,1,1,1,1,1,1,1,1,1,1,1,1,1,1,1,1,1,1,16,0,0,0,0,0,1,1,1,1,1,1,1,1,1,1,1,1,1,1,1,1,1,1,1,1,1,1,1,1,1
1,1,1,1,1,1,1,1,1,1,1,1,1,1,1,1,1,1,1,1,1,1,1,1,1,1,16,16,0,0,0,0,1,1,1,1,1,1,1,1,1,1,1,1,1,1,1,1,1,1,1,1,1,1,1,1,1
1,1,1,1,1,1,1,1,1,1,1,1,1,1,1,1,1,1,1,1,1,1,1,1,1,1,1,1,1,1,1,1,1,1,1,1,1,1,1,1,1,1,1,1,1,1,1,1,1,1,1,1,1,1,1,1,1
1,1,1,1,1,1,1,1,1,1,1,1,1,1,1,1,1,1,1,1,1,1,1,1,1,1,1,1,1,1,1,1,1,1,1,1,1,1,1,1,1,1,1,1,1,1,1,1,1,1,1,1,1,1,1,1,1
1,1,1,1,1,1,1,1,1,1,1,1,1,1,1,1,1,1,1,1,1,1,1,1,1,1,1,1,1,1,1,1,1,1,1,1,1,1,1,1,1,1,1,1,1,1,1,1,1,1,1,1,1,1,1,1,1
1,1,1,1,1,1,1,1,1,1,1,1,1,1,1,1,1,1,1,1,1,1,1,1,1,1,1,1,1,1,1,1,1,1,1,1,1,1,1,1,1,1,1,1,1,1,1,1,1,1,1,1,1,1,1,1,1
1,1,1,1,1,1,1,1,1,1,1,1,1,1,1,1,1,1,1,1,1,1,1,1,1,1,1,1,1,1,1,1,1,1,1,1,1,1,1,1,1,1,1,1,1,1,1,1,1,1,1,1,1,1,1,1,1
1,1,1,1,1,1,1,1,1,1,1,1,1,1,1,1,1,1,1,1,1,1,1,1,1,1,1,1,1,1,1,1,1,1,1,1,1,1,1,1,1,1,1,1,1,1,1,1,1,1,1,1,1,1,1,1,1
1,1,1,1,1,1,1,1,1,1,1,1,1,1,1,1,1,1,1,1,1,1,1,1,1,1,1,1,1,1,1,1,1,1,1,1,1,1,1,1,1,1,1,1,1,1,1,1,1,1,1,1,1,1,1,1,1
1,1,1,1,1,1,1,1,1,1,1,1,1,1,1,1,1,1,1,1,1,1,1,1,1,1,1,1,1,1,1,1,1,1,1,1,1,1,1,1,1,1,1,1,1,1,1,1,1,1,1,1,1,1,1,1,1
1,1,1,1,1,1,1,1,1,1,1,1,1,1,1,1,1,1,1,1,1,1,1,1,1,1,1,1,1,1,1,1,1,1,1,1,1,1,1,1,1,1,1,1,1,1,1,1,1,1,1,1,1,1,1,1,1
1,1,1,1,1,1,1,1,1,1,1,1,1,1,1,1,1,1,1,1,1,1,1,1,1,1,1,1,1,1,1,1,1,1,1,1,1,1,1,1,1,1,1,1,1,1,1,1,1,1,1,1,1,1,1,1,1
1,1,1,1,1,1,1,1,1,1,1,1,1,1,1,1,1,1,1,1,1,1,1,1,1,1,1,1,1,1,1,1,1,1,1,1,1,1,1,1,1,1,1,1,1,1,1,1,1,1,1,1,1,1,1,1,1
1,1,1,1,1,1,1,1,1,1,1,1,1,1,1,1,1,1,1,1,1,1,1,1,1,1,1,1,1,1,1,1,1,1,1,1,1,1,1,1,1,1,1,1,1,1,1,1,1,1,1,1,1,1,1,1,1
1,1,1,1,1,1,1,1,1,1,1,1,1,1,1,1,1,1,1,1,1,1,1,1,1,1,1,1,1,1,1,1,1,1,1,1,1,1,1,1,1,1,1,1,1,1,1,1,1,1,1,1,1,1,1,1,1
1,1,1,1,1,1,1,1,1,1,1,1,1,1,1,1,1,1,1,1,1,1,1,1,1,1,1,1,1,1,1,1,1,1,1,1,1,1,1,1,1,1,1,1,1,1,1,1,1,1,1,1,1,1,1,1,1
1,1,1,1,1,1,1,1,1,1,1,1,1,1,1,1,1,1,1,1,1,1,1,1,1,1,1,1,1,1,1,1,1,1,1,1,1,1,1,1,1,1,1,1,1,1,1,1,1,1,1,1,1,1,1,1,1
1,1,1,1,1,1,1,1,1,1,1,1,1,1,1,1,1,1,1,1,1,1,1,1,1,1,1,1,1,1,1,1,1,1,1,1,1,1,1,1,1,1,1,1,1,1,1,1,1,1,1,1,1,1,1,1,1
1,1,1,1,1,1,1,1,1,1,1,1,1,1,1,1,1,1,1,1,1,1,1,1,1,1,1,1,1,1,1,1,1,1,1,1,1,1,1,1,1,1,1,1,1,1,1,1,1,1,1,1,1,1,1,1,1
1,1,1,1,1,1,1,1,1,1,1,1,1,1,1,1,1,1,1,1,1,1,1,1,1,1,1,1,1,1,1,1,1,1,1,1,1,1,1,1,1,1,1,1,1,1,1,1,1,1,1,1,1,1,1,1,1
1,1,1,1,1,1,1,1,1,1,1,1,1,1,1,1,1,1,1,1,1,1,1,1,1,1,1,1,1,1,1,1,1,1,1,1,1,1,1,1,1,1,1,1,1,1,1,1,1,1,1,1,1,1,1,1,1
1,1,1,1,1,1,1,1,1,1,1,1,1,1,1,1,1,1,1,1,1,1,1,1,1,1,1,1,1,1,1,1,1,1,1,1,1,1,1,1,1,1,1,1,1,1,1,1,1,1,1,1,1,1,1,1,1
1,1,1,1,1,1,1,1,1,1,1,1,1,1,1,1,1,1,1,1,1,1,1,1,1,1,1,1,1,1,1,1,1,1,1,1,1,1,1,1,1,1,1,1,1,1,1,1,1,1,1,1,1,1,1,1,1
1,1,1,1,1,1,1,1,1,1,1,1,1,1,1,1,1,1,1,1,1,1,1,1,1,1,1,1,1,1,1,1,1,1,1,1,1,1,1,1,1,1,1,1,1,1,1,1,1,1,1,1,1,1,1,1,1
1,1,1,1,1,1,1,1,1,1,1,1,1,1,1,1,1,1,1,1,1,1,1,1,1,1,1,1,1,1,1,1,1,1,1,1,1,1,1,1,1,1,1,1,1,1,1,1,1,1,1,1,1,1,1,1,1
1,1,1,1,1,1,1,1,1,1,1,1,1,1,1,1,1,1,1,1,1,1,1,1,1,1,1,1,1,1,1,1,1,1,1,1,1,1,1,1,1,1,1,1,1,1,1,1,1,1,1,1,1,1,1,1,1
:endlayer
layer: 13
1,1,1,1,1,1,1,1,1,1,1,1,1,1,1,1,1,1,1,1,1,1,1,1,1,1,1,1,1,1,1,1,1,1,1,1,1,1,1,1,1,1,1,1,1,1,1,1,1,1,1,1,1,1,1,1,1
1,1,1,1,1,1,1,1,1,1,1,1,1,1,1,1,1,1,1,1,1,1,1,1,1,1,1,1,1,1,1,1,1,1,1,1,1,1,1,1,1,1,1,1,1,1,1,1,1,1,1,1,1,1,1,1,1
1,1,1,1,1,1,1,1,1,1,1,1,1,1,1,1,1,1,1,1,1,1,1,1,1,1,1,1,1,1,1,1,1,1,1,1,1,1,1,1,1,1,1,1,1,1,1,1,1,1,1,1,1,1,1,1,1
1,1,1,1,1,1,1,1,1,1,1,1,1,1,1,1,1,1,1,1,1,1,1,1,1,1,1,1,1,1,1,1,1,1,1,1,1,1,1,1,1,1,1,1,1,1,1,1,1,1,1,1,1,1,1,1,1
1,1,1,1,1,1,1,1,1,1,1,1,1,1,1,1,1,1,1,1,1,1,1,1,1,1,1,1,1,1,1,1,1,1,1,1,1,1,1,1,1,1,1,1,1,1,1,1,1,1,1,1,1,1,1,1,1
1,1,1,1,1,1,1,1,1,1,1,1,1,1,1,1,1,1,1,1,1,1,1,1,1,1,1,1,1,1,1,1,1,1,1,1,1,1,1,1,1,1,1,1,1,1,1,1,1,1,1,1,1,1,1,1,1
1,1,1,1,1,1,1,1,1,1,1,1,1,1,1,1,1,1,1,1,1,1,1,1,1,1,1,1,1,1,1,1,1,1,1,1,1,1,1,1,1,1,1,1,1,1,1,1,1,1,1,1,1,1,1,1,1
1,1,1,1,1,1,1,1,1,1,1,1,1,1,1,1,1,1,1,1,1,1,1,1,1,1,1,1,1,1,1,1,1,1,1,1,1,1,1,1,1,1,1,1,1,1,1,1,1,1,1,1,1,1,1,1,1
1,1,1,1,1,1,1,1,1,1,1,1,1,1,1,1,1,1,1,1,1,1,1,1,1,1,1,1,1,1,1,1,1,1,1,1,1,1,1,1,1,1,1,1,1,1,1,1,1,1,1,1,1,1,1,1,1
1,1,1,1,1,1,1,1,1,1,1,1,1,1,1,1,1,1,1,1,1,1,1,1,1,1,1,1,1,1,1,1,1,1,1,1,1,1,1,1,1,1,1,1,1,1,1,1,1,1,1,1,1,1,1,1,1
1,1,1,1,1,1,1,1,1,1,1,1,1,1,1,1,1,1,1,1,1,1,1,1,1,1,1,76,0,0,0,0,1,1,1,1,1,1,1,1,1,1,1,1,1,1,1,1,1,1,1,1,1,1,1,1,1
1,1,1,1,1,1,1,1,1,1,1,1,1,1,1,1,1,1,1,1,1,1,1,1,1,1,1,76,0,0,0,0,1,1,1,1,1,1,1,1,1,1,1,1,1,1,1,1,1,1,1,1,1,1,1,1,1
1,1,1,1,1,1,1,1,1,1,1,1,1,1,1,1,1,1,1,1,1,1,1,1,122,122,122,122,122,0,0,0,1,1,1,1,1,1,1,1,1,1,1,1,1,1,1,1,1,1,1,1,1,1,1,1,1
1,1,1,1,1,1,1,1,1,1,1,1,1,1,1,1,1,1,1,1,1,1,1,1,1,1,1,1,1,0,0,0,1,1,1,1,1,1,1,1,1,1,1,1,1,1,1,1,1,1,1,1,1,1,1,1,1
1,1,1,1,1,1,1,1,1,1,1,1,1,1,1,1,1,1,1,1,1,1,1,1,1,1,1,1,1,0,0,0,1,1,1,1,1,1,1,1,1,1,1,1,1,1,1,1,1,1,1,1,1,1,1,1,1
1,1,1,1,1,1,1,1,1,1,1,1,1,1,1,1,1,1,1,1,1,1,1,1,1,1,1,16,0,0,0,0,1,1,1,1,1,1,1,1,1,1,1,1,1,1,1,1,1,1,1,1,1,1,1,1,1
1,1,1,1,1,1,1,1,1,1,1,1,1,1,1,1,1,1,1,1,1,1,1,1,1,1,1,16,16,0,0,0,1,1,1,1,1,1,1,1,1,1,1,1,1,1,1,1,1,1,1,1,1,1,1,1,1
1,1,1,1,1,1,1,1,1,1,1,1,1,1,1,1,1,1,1,1,1,1,1,1,1,1,1,16,0,0,0,0,1,1,1,1,1,1,1,1,1,1,1,1,1,1,1,1,1,1,1,1,1,1,1,1,1
1,1,1,1,1,1,1,1,1,1,1,1,1,1,1,1,1,1,1,1,1,1,1,1,1,1,1,1,1,1,1,1,1,1,1,1,1,1,1,1,1,1,1,1,1,1,1,1,1,1,1,1,1,1,1,1,1
1,1,1,1,1,1,1,1,1,1,1,1,1,1,1,1,1,1,1,1,1,1,1,1,1,1,1,1,1,1,1,1,1,1,1,1,1,1,1,1,1,1,1,1,1,1,1,1,1,1,1,1,1,1,1,1,1
1,1,1,1,1,1,1,1,1,1,1,1,1,1,1,1,1,1,1,1,1,1,1,1,1,1,1,1,1,1,1,1,1,1,1,1,1,1,1,1,1,1,1,1,1,1,1,1,1,1,1,1,1,1,1,1,1
1,1,1,1,1,1,1,1,1,1,1,1,1,1,1,1,1,1,1,1,1,1,1,1,1,1,1,1,1,1,1,1,1,1,1,1,1,1,1,1,1,1,1,1,1,1,1,1,1,1,1,1,1,1,1,1,1
1,1,1,1,1,1,1,1,1,1,1,1,1,1,1,1,1,1,1,1,1,1,1,1,1,1,1,1,1,1,1,1,1,1,1,1,1,1,1,1,1,1,1,1,1,1,1,1,1,1,1,1,1,1,1,1,1
1,1,1,1,1,1,1,1,1,1,1,1,1,1,1,1,1,1,1,1,1,1,1,1,1,1,1,1,1,1,1,1,1,1,1,1,1,1,1,1,1,1,1,1,1,1,1,1,1,1,1,1,1,1,1,1,1
1,1,1,1,1,1,1,1,1,1,1,1,1,1,1,1,1,1,1,1,1,1,1,1,1,1,1,1,1,1,1,1,1,1,1,1,1,1,1,1,1,1,1,1,1,1,1,1,1,1,1,1,1,1,1,1,1
1,1,1,1,1,1,1,1,1,1,1,1,1,1,1,1,1,1,1,1,1,1,1,1,1,1,1,1,1,1,1,1,1,1,1,1,1,1,1,1,1,1,1,1,1,1,1,1,1,1,1,1,1,1,1,1,1
1,1,1,1,1,1,1,1,1,1,1,1,1,1,1,1,1,1,1,1,1,1,1,1,1,1,1,1,1,1,1,1,1,1,1,1,1,1,1,1,1,1,1,1,1,1,1,1,1,1,1,1,1,1,1,1,1
1,1,1,1,1,1,1,1,1,1,1,1,1,1,1,1,1,1,1,1,1,1,1,1,1,1,1,1,1,1,1,1,1,1,1,1,1,1,1,1,1,1,1,1,1,1,1,1,1,1,1,1,1,1,1,1,1
1,1,1,1,1,1,1,1,1,1,1,1,1,1,1,1,1,1,1,1,1,1,1,1,1,1,1,1,1,1,1,1,1,1,1,1,1,1,1,1,1,1,1,1,1,1,1,1,1,1,1,1,1,1,1,1,1
1,1,1,1,1,1,1,1,1,1,1,1,1,1,1,1,1,1,1,1,1,1,1,1,1,1,1,1,1,1,1,1,1,1,1,1,1,1,1,1,1,1,1,1,1,1,1,1,1,1,1,1,1,1,1,1,1
1,1,1,1,1,1,1,1,1,1,1,1,1,1,1,1,1,1,1,1,1,1,1,1,1,1,1,1,1,1,1,1,1,1,1,1,1,1,1,1,1,1,1,1,1,1,1,1,1,1,1,1,1,1,1,1,1
1,1,1,1,1,1,1,1,1,1,1,1,1,1,1,1,1,1,1,1,1,1,1,1,1,1,1,1,1,1,1,1,1,1,1,1,1,1,1,1,1,1,1,1,1,1,1,1,1,1,1,1,1,1,1,1,1
1,1,1,1,1,1,1,1,1,1,1,1,1,1,1,1,1,1,1,1,1,1,1,1,1,1,1,1,1,1,1,1,1,1,1,1,1,1,1,1,1,1,1,1,1,1,1,1,1,1,1,1,1,1,1,1,1
1,1,1,1,1,1,1,1,1,1,1,1,1,1,1,1,1,1,1,1,1,1,1,1,1,1,1,1,1,1,1,1,1,1,1,1,1,1,1,1,1,1,1,1,1,1,1,1,1,1,1,1,1,1,1,1,1
1,1,1,1,1,1,1,1,1,1,1,1,1,1,1,1,1,1,1,1,1,1,1,1,1,1,1,1,1,1,1,1,1,1,1,1,1,1,1,1,1,1,1,1,1,1,1,1,1,1,1,1,1,1,1,1,1
1,1,1,1,1,1,1,1,1,1,1,1,1,1,1,1,1,1,1,1,1,1,1,1,1,1,1,1,1,1,1,1,1,1,1,1,1,1,1,1,1,1,1,1,1,1,1,1,1,1,1,1,1,1,1,1,1
1,1,1,1,1,1,1,1,1,1,1,1,1,1,1,1,1,1,1,1,1,1,1,1,1,1,1,1,1,1,1,1,1,1,1,1,1,1,1,1,1,1,1,1,1,1,1,1,1,1,1,1,1,1,1,1,1
1,1,1,1,1,1,1,1,1,1,1,1,1,1,1,1,1,1,1,1,1,1,1,1,1,1,1,1,1,1,1,1,1,1,1,1,1,1,1,1,1,1,1,1,1,1,1,1,1,1,1,1,1,1,1,1,1
1,1,1,1,1,1,1,1,1,1,1,1,1,1,1,1,1,1,1,1,1,1,1,1,1,1,1,1,1,1,1,1,1,1,1,1,1,1,1,1,1,1,1,1,1,1,1,1,1,1,1,1,1,1,1,1,1
1,1,1,1,1,1,1,1,1,1,1,1,1,1,1,1,1,1,1,1,1,1,1,1,1,1,1,1,1,1,1,1,1,1,1,1,1,1,1,1,1,1,1,1,1,1,1,1,1,1,1,1,1,1,1,1,1
1,1,1,1,1,1,1,1,1,1,1,1,1,1,1,1,1,1,1,1,1,1,1,1,1,1,1,1,1,1,1,1,1,1,1,1,1,1,1,1,1,1,1,1,1,1,1,1,1,1,1,1,1,1,1,1,1
1,1,1,1,1,1,1,1,1,1,1,1,1,1,1,1,1,1,1,1,1,1,1,1,1,1,1,1,1,1,1,1,1,1,1,1,1,1,1,1,1,1,1,1,1,1,1,1,1,1,1,1,1,1,1,1,1
:endlayer
layer: 14
1,1,1,1,1,1,1,1,1,1,1,1,1,1,1,1,1,1,1,1,1,1,1,1,1,1,1,1,1,1,1,1,1,1,1,1,1,1,1,1,1,1,1,1,1,1,1,1,1,1,1,1,1,1,1,1,1
1,1,1,1,1,1,1,1,1,1,1,1,1,1,1,1,1,1,1,1,1,1,1,1,1,1,1,1,1,1,1,1,1,1,1,1,1,1,1,1,1,1,1,1,1,1,1,1,1,1,1,1,1,1,1,1,1
1,1,1,1,1,1,1,1,1,1,1,1,1,1,1,1,1,1,1,1,1,1,1,1,1,1,1,1,1,1,1,1,1,1,1,1,1,1,1,1,1,1,1,1,1,1,1,1,1,1,1,1,1,1,1,1,1
1,1,1,1,1,1,1,1,1,1,1,1,1,1,1,1,1,1,1,1,1,1,1,1,1,1,1,1,1,1,1,1,1,1,1,1,1,1,1,1,1,1,1,1,1,1,1,1,1,1,1,1,1,1,1,1,1
1,1,1,1,1,1,1,1,1,1,1,1,1,1,1,1,1,1,1,1,1,1,1,1,1,1,1,1,1,1,1,1,1,1,1,1,1,1,1,1,1,1,1,1,1,1,1,1,1,1,1,1,1,1,1,1,1
1,1,1,1,1,1,1,1,1,1,1,1,1,1,1,1,1,1,1,1,1,1,1,1,1,1,1,1,1,1,1,1,1,1,1,1,1,1,1,1,1,1,1,1,1,1,1,1,1,1,1,1,1,1,1,1,1
1,1,1,1,1,1,1,1,1,1,1,1,1,1,1,1,1,1,1,1,1,1,1,1,1,1,1,1,1,1,1,1,1,1,1,1,1,1,1,1,1,1,1,1,1,1,1,1,1,1,1,1,1,1,1,1,1
1,1,1,1,1,1,1,1,1,1,1,1,1,1,1,1,1,1,1,1,1,1,1,1,1,1,1,1,1,1,1,1,1,1,1,1,1,1,1,1,1,1,1,1,1,1,1,1,1,1,1,1,1,1,1,1,1
1,1,1,1,1,1,1,1,1,1,1,1,1,1,1,1,1,1,1,1,1,1,1,1,1,1,1,1,1,1,1,1,1,1,1,1,1,1,1,1,1,1,1,1,1,1,1,1,1,1,1,1,1,1,1,1,1
1,1,1,1,1,1,1,1,1,1,1,1,1,1,1,1,1,1,1,1,1,1,1,1,1,1,1,1,1,1,1,1,1,1,1,1,1,1,1,1,1,1,1,1,1,1,1,1,1,1,1,1,1,1,1,1,1
1,1,1,1,1,1,1,1,1,1,1,1,1,1,1,1,1,1,1,1,1,1,1,1,1,1,76,0,0,0,0,0,1,1,1,1,1,1,1,1,1,1,1,1,1,1,1,1,1,1,1,1,1,1,1,1,1
1,1,1,1,1,1,1,1,1,1,1,1,1,1,1,1,1,1,1,1,1,1,1,1,1,1,76,0,0,0,0,0,1,1,1,1,1,1,1,1,1,1,1,1,1,1,1,1,1,1,1,1,1,1,1,1,1
1,1,1,1,1,1,1,1,1,1,1,1,1,1,1,1,1,1,1,1,1,1,1,1,122,122,122,122,122,0,0,0,1,1,1,1,1,1,1,1,1,1,1,1,1,1,1,1,1,1,1,1,1,1,1,1,1
1,1,1,1,1,1,1,1,1,1,1,1,1,1,1,1,1,1,1,1,1,1,1,1,1,1,1,1,1,0,0,0,1,1,1,1,1,1,1,1,1,1,1,1,1,1,1,1,1,1,1,1,1,1,1,1,1
1,1,1,1,1,1,1,1,1,1,1,1,1,1,1,1,1,1,1,1,1,1,1,1,1,1,1,1,1,0,0,0,1,1,1,1,1,1,1,1,1,1,1,1,1,1,1,1,1,1,1,1,1,1,1,1,1
1,1,1,1,1,1,1,1,1,1,1,1,1,1,1,1,1,1,1,1,1,1,1,1,1,1,1,1,1,0,0,0,1,1,1,1,1,1,1,1,1,1,1,1,1,1,1,1,1,1,1,1,1,1,1,1,1
1,1,1,1,1,1,1,1,1,1,1,1,1,1,1,1,1,1,1,1,1,1,1,1,1,1,1,1,1,0,0,0,1,1,1,1,1,1,1,1,1,1,1,1,1,1,1,1,1,1,1,1,1,1,1,1,1
1,1,1,1,1,1,1,1,1,1,1,1,1,1,1,1,1,1,1,1,1,1,1,1,1,1,1,1,1,0,0,0,1,1,1,1,1,1,1,1,1,1,1,1,1,1,1,1,1,1,1,1,1,1,1,1,1
1,1,1,1,1,1,1,1,1,1,1,1,1,1,1,1,1,1,1,1,1,1,1,1,1,1,1,1,1,1,1,1,1,1,1,1,1,1,1,1,1,1,1,1,1,1,1,1,1,1,1,1,1,1,1,1,1
1,1,1,1,1,1,1,1,1,1,1,1,1,1,1,1,1,1,1,1,1,1,1,1,1,1,1,1,1,1,1,1,1,1,1,1,1,1,1,1,1,1,1,1,1,1,1,1,1,1,1,1,1,1,1,1,1
1,1,1,1,1,1,1,1,1,1,1,1,1,1,1,1,1,1,1,1,1,1,1,1,1,1,1,1,1,1,1,1,1,1,1,1,1,1,1,1,1,1,1,1,1,1,1,1,1,1,1,1,1,1,1,1,1
1,1,1,1,1,1,1,1,1,1,1,1,1,1,1,1,1,1,1,1,1,1,1,1,1,1,1,1,1,1,1,1,1,1,1,1,1,1,1,1,1,1,1,1,1,1,1,1,1,1,1,1,1,1,1,1,1
1,1,1,1,1,1,1,1,1,1,1,1,1,1,1,1,1,1,1,1,1,1,1,1,1,1,1,1,1,1,1,1,1,1,1,1,1,1,1,1,1,1,1,1,1,1,1,1,1,1,1,1,1,1,1,1,1
1,1,1,1,1,1,1,1,1,1,1,1,1,1,1,1,1,1,1,1,1,1,1,1,1,1,1,1,1,1,1,1,1,1,1,1,1,1,1,1,1,1,1,1,1,1,1,1,1,1,1,1,1,1,1,1,1
1,1,1,1,1,1,1,1,1,1,1,1,1,1,1,1,1,1,1,1,1,1,1,1,1,1,1,1,1,1,1,1,1,1,1,1,1,1,1,1,1,1,1,1,1,1,1,1,1,1,1,1,1,1,1,1,1
1,1,1,1,1,1,1,1,1,1,1,1,1,1,1,1,1,1,1,1,1,1,1,1,1,1,1,1,1,1,1,1,1,1,1,1,1,1,1,1,1,1,1,1,1,1,1,1,1,1,1,1,1,1,1,1,1
1,1,1,1,1,1,1,1,1,1,1,1,1,1,1,1,1,1,1,1,1,1,1,1,1,1,1,1,1,1,1,1,1,1,1,1,1,1,1,1,1,1,1,1,1,1,1,1,1,1,1,1,1,1,1,1,1
1,1,1,1,1,1,1,1,1,1,1,1,1,1,1,1,1,1,1,1,1,1,1,1,1,1,1,1,1,1,1,1,1,1,1,1,1,1,1,1,1,1,1,1,1,1,1,1,1,1,1,1,1,1,1,1,1
1,1,1,1,1,1,1,1,1,1,1,1,1,1,1,1,1,1,1,1,1,1,1,1,1,1,1,1,1,1,1,1,1,1,1,1,1,1,1,1,1,1,1,1,1,1,1,1,1,1,1,1,1,1,1,1,1
1,1,1,1,1,1,1,1,1,1,1,1,1,1,1,1,1,1,1,1,1,1,1,1,1,1,1,1,1,1,1,1,1,1,1,1,1,1,1,1,1,1,1,1,1,1,1,1,1,1,1,1,1,1,1,1,1
1,1,1,1,1,1,1,1,1,1,1,1,1,1,1,1,1,1,1,1,1,1,1,1,1,1,1,1,1,1,1,1,1,1,1,1,1,1,1,1,1,1,1,1,1,1,1,1,1,1,1,1,1,1,1,1,1
1,1,1,1,1,1,1,1,1,1,1,1,1,1,1,1,1,1,1,1,1,1,1,1,1,1,1,1,1,1,1,1,1,1,1,1,1,1,1,1,1,1,1,1,1,1,1,1,1,1,1,1,1,1,1,1,1
1,1,1,1,1,1,1,1,1,1,1,1,1,1,1,1,1,1,1,1,1,1,1,1,1,1,1,1,1,1,1,1,1,1,1,1,1,1,1,1,1,1,1,1,1,1,1,1,1,1,1,1,1,1,1,1,1
1,1,1,1,1,1,1,1,1,1,1,1,1,1,1,1,1,1,1,1,1,1,1,1,1,1,1,1,1,1,1,1,1,1,1,1,1,1,1,1,1,1,1,1,1,1,1,1,1,1,1,1,1,1,1,1,1
1,1,1,1,1,1,1,1,1,1,1,1,1,1,1,1,1,1,1,1,1,1,1,1,1,1,1,1,1,1,1,1,1,1,1,1,1,1,1,1,1,1,1,1,1,1,1,1,1,1,1,1,1,1,1,1,1
1,1,1,1,1,1,1,1,1,1,1,1,1,1,1,1,1,1,1,1,1,1,1,1,1,1,1,1,1,1,1,1,1,1,1,1,1,1,1,1,1,1,1,1,1,1,1,1,1,1,1,1,1,1,1,1,1
1,1,1,1,1,1,1,1,1,1,1,1,1,1,1,1,1,1,1,1,1,1,1,1,1,1,1,1,1,1,1,1,1,1,1,1,1,1,1,1,1,1,1,1,1,1,1,1,1,1,1,1,1,1,1,1,1
1,1,1,1,1,1,1,1,1,1,1,1,1,1,1,1,1,1,1,1,1,1,1,1,1,1,1,1,1,1,1,1,1,1,1,1,1,1,1,1,1,1,1,1,1,1,1,1,1,1,1,1,1,1,1,1,1
1,1,1,1,1,1,1,1,1,1,1,1,1,1,1,1,1,1,1,1,1,1,1,1,1,1,1,1,1,1,1,1,1,1,1,1,1,1,1,1,1,1,1,1,1,1,1,1,1,1,1,1,1,1,1,1,1
1,1,1,1,1,1,1,1,1,1,1,1,1,1,1,1,1,1,1,1,1,1,1,1,1,1,1,1,1,1,1,1,1,1,1,1,1,1,1,1,1,1,1,1,1,1,1,1,1,1,1,1,1,1,1,1,1
1,1,1,1,1,1,1,1,1,1,1,1,1,1,1,1,1,1,1,1,1,1,1,1,1,1,1,1,1,1,1,1,1,1,1,1,1,1,1,1,1,1,1,1,1,1,1,1,1,1,1,1,1,1,1,1,1
1,1,1,1,1,1,1,1,1,1,1,1,1,1,1,1,1,1,1,1,1,1,1,1,1,1,1,1,1,1,1,1,1,1,1,1,1,1,1,1,1,1,1,1,1,1,1,1,1,1,1,1,1,1,1,1,1
:endlayer
layer: 15
0,0,0,0,0,0,0,0,0,0,0,0,0,0,0,0,0,0,0,0,0,0,0,0,0,0,0,0,0,0,0,0,0,0,0,0,0,0,0,0,0,0,0,0,0,0,0,0,0,0,0,0,0,0,0,0,0
0,0,0,0,0,0,0,0,0,0,0,0,0,0,0,0,0,0,0,0,0,0,0,0,0,0,0,0,0,0,0,0,0,0,0,0,0,0,0,0,0,0,0,0,0,0,0,0,0,0,0,0,0,0,0,0,0
0,123,123,123,123,123,123,123,123,123,123,123,122,122,122,123,123,122,123,123,123,123,123,123,122,123,123,122,123,123,123,122,123,122,123,122,123,122,122,122,123,122,123,122,122,123,123,122,122,122,123,122,123,123,123,123,0
0,123,123,123,123,123,123,122,123,123,122,123,123,122,123,122,123,123,122,123,123,123,123,123,123,123,122,122,123,123,123,123,123,123,123,123,123,123,123,123,123,122,123,123,122,123,123,122,123,122,123,123,123,123,123,123,0
0,123,122,123,122,123,123,123,123,122,122,123,123,122,123,123,123,123,123,123,123,123,123,123,123,122,123,123,123,123,122,123,123,123,123,123,123,122,123,123,123,123,123,122,123,123,122,123,123,123,123,123,123,123,123,122,0
0,122,123,123,123,122,123,123,122,123,122,122,123,123,123,123,122,123,123,123,122,123,123,123,123,123,123,122,123,123,123,122,123,122,123,123,122,122,123,122,123,122,123,122,123,123,122,122,123,122,122,123,122,123,123,123,0
0,123,122,123,123,123,123,123,123,123,123,123,123,122,122,123,123,122,123,122,123,122,123,123,123,123,123,123,123,123,123,123,123,122,123,123,123,122,122,123,123,123,123,122,122,122,123,123,122,123,123,123,123,123,123,123,0
0,123,123,123,122,123,123,123,123,123,122,122,122,123,123,123,123,122,123,123,123,122,122,122,123,123,122,123,123,123,122,122,123,122,123,122,123,123,123,123,123,123,122,123,123,123,122,122,123,123,122,123,123,123,122,122,0
0,123,123,123,123,123,123,123,122,122,123,123,122,122,123,123,123,123,122,123,123,123,123,123,123,122,123,123,123,123,122,123,123,123,123,123,123,123,123,122,123,123,123,122,123,123,123,122,123,123,122,122,123,123,123,123,0
0,122,123,123,122,122,123,122,123,122,122,123,123,122,122,123,123,122,123,123,122,123,123,122,123,122,123,122,122,123,123,123,122,123,123,123,123,122,123,122,123,123,123,123,123,122,123,123,123,123,123,123,123,123,122,122,0
0,123,123,122,123,122,123,122,123,122,123,122,123,123,123,122,123,123,123,123,123,123,122,122,123,76,0,0,0,0,0,0,122,123,123,122,123,123,123,123,123,122,123,123,122,123,123,123,122,123,123,123,123,122,122,123,0
0,123,123,122,123,123,122,123,123,123,123,123,122,123,123,122,123,123,123,122,123,123,123,122,123,76,0,0,0,0,0,0,11,11,122,123,122,123,123,122,123,123,123,122,123,123,123,122,122,122,123,123,122,123,122,122,0
0,123,122,123,123,123,123,122,123,123,123,123,122,123,123,122,122,123,123,123,123,123,122,123,122,122,122,122,122,122,122,122,122,11,123,123,122,123,123,123,122,123,122,122,123,123,122,122,123,123,123,123,123,122,122,123,0
0,123,123,122,123,122,123,123,123,123,122,123,123,123,123,123,122,123,123,122,122,122,123,122,123,122,122,123,123,122,123,123,123,123,123,122,123,123,123,122,123,122,123,123,123,123,123,123,123,123,123,123,122,123,122,122,0
0,123,122,123,123,122,123,123,122,122,123,123,122,123,122,123,122,123,123,123,123,123,123,122,123,123,123,123,123,122,123,123,123,123,122,123,123,123,123,123,122,123,123,122,122,123,123,123,123,123,122,123,122,123,122,123,0
0,123,123,122,123,123,122,123,123,122,123,123,123,123,123,123,122,123,123,122,123,123,123,123,123,123,123,122,123,122,123,123,123,123,123,123,123,122,123,123,123,122,122,123,123,123,123,123,123,123,122,123,122,122,123,123,0
0,123,122,123,122,123,122,123,123,123,122,122,123,123,123,123,123,123,122,122,123,123,123,123,123,123,123,122,123,122,123,123,123,122,123,123,123,122,123,123,123,122,123,123,123,123,122,123,122,123,123,123,123,123,122,123,0
0,123,123,122,123,123,123,123,123,123,123,123,123,123,123,123,123,123,123,123,123,123,122,123,122,123,123,123,123,123,123,123,123,123,123,123,122,123,123,123,123,123,122,123,122,122,123,123,123,123,123,123,123,122,122,123,0
0,122,122,123,122,122,122,123,122,122,123,123,122,123,123,122,122,123,122,123,123,122,123,123,123,122,123,123,122,122,123,123,123,123,123,122,123,123,123,123,123,123,122,122,122,123,123,123,123,123,122,122,123,123,123,122,0
0,123,123,122,122,123,123,123,122,122,122,123,122,122,123,123,122,123,123,123,122,123,122,123,123,123,122,123,123,122,123,123,123,123,122,123,122,122,123,123,122,123,123,123,122,123,123,122,123,123,122,123,123,122,123,122,0
0,123,123,123,123,123,123,122,123,123,123,123,123,122,123,123,123,123,123,123,123,123,123,123,122,123,122,123,123,123,123,123,123,123,122,122,123,123,123,122,123,123,123,123,123,123,123,123,123,122,123,123,123,123,122,123,0
0,123,123,122,123,122,123,123,122,122,123,123,123,122,122,123,123,123,123,123,123,122,123,122,123,123,122,123,123,123,123,123,122,123,122,123,123,122,123,123,122,123,123,123,122,122,122,122,122,123,122,122,123,123,122,122,0
0,123,123,123,123,123,123,123,123,122,122,122,123,123,122,123,123,123,122,123,123,123,122,123,122,122,123,122,123,123,123,122,123,123,123,123,123,123,123,123,123,123,123,123,123,123,123,122,123,122,123,123,122,123,123,122,0
0,123,122,122,123,122,123,123,123,122,122,122,123,123,122,123,122,123,122,123,123,123,123,122,123,123,123,123,122,123,123,122,123,123,122,123,123,123,122,122,122,123,122,122,122,123,123,123,122,123,122,123,123,122,123,123,0
0,123,123,122,122,122,122,123,123,123,123,123,122,123,122,123,122,122,123,123,123,122,122,122,123,122,123,122,122,122,122,123,122,122,123,123,122,123,123,123,123,123,123,122,123,122,122,122,123,123,122,123,122,122,122,122,0
0,122,122,123,123,122,122,123,123,123,123,123,122,123,123,123,123,123,122,122,123,122,122,123,123,123,123,122,123,123,123,122,123,123,122,123,122,123,123,122,123,123,123,122,123,122,123,123,123,123,123,123,122,123,123,123,0
0,123,122,123,122,123,123,123,123,122,123,123,123,122,123,123,122,123,123,123,122,123,123,122,123,123,123,123,123,123,123,122,123,123,122,123,123,123,123,123,123,123,123,122,123,123,123,122,122,123,123,122,123,122,123,123,0
0,123,123,123,123,122,123,123,123,123,122,123,122,122,123,123,123,123,123,123,122,123,123,123,123,123,122,123,123,122,122,123,123,123,123,122,122,123,123,123,123,123,123,123,123,123,123,122,123,123,123,123,123,123,122,123,0
0,123,122,123,123,123,122,123,123,122,123,123,123,123,123,123,123,123,123,122,122,122,123,123,123,123,123,123,122,122,123,123,123,123,123,123,123,122,123,123,123,123,123,123,123,122,122,122,123,123,123,122,123,123,123,123,0
0,123,123,122,123,123,122,123,123,123,123,123,123,123,122,122,123,123,123,123,123,123,123,123,123,123,122,123,123,123,123,123,123,122,122,122,123,123,123,123,122,123,123,122,123,123,123,123,123,122,123,123,123,122,123,123,0
0,123,123,123,123,122,123,123,123,123,123,123,122,123,123,122,122,123,123,122,123,123,123,123,122,123,123,123,123,123,122,123,122,123,122,123,123,122,122,123,123,122,122,123,123,123,123,122,123,123,122,123,123,123,123,123,0
0,122,123,122,123,123,123,123,123,123,122,122,122,123,122,122,123,122,123,123,122,123,123,122,123,123,122,123,122,123,123,122,122,122,123,123,122,123,123,123,122,122,123,122,123,123,123,122,123,122,123,123,123,123,123,123,0
0,122,122,123,122,122,123,123,123,123,123,123,123,123,123,122,123,123,123,122,122,123,123,123,122,123,123,123,123,123,123,123,122,123,123,123,122,123,123,123,123,122,123,123,123,123,123,122,122,123,122,122,123,123,123,123,0
0,123,122,123,122,122,122,123,123,123,123,123,122,123,122,123,123,123,123,122,123,123,122,122,123,122,123,123,123,123,123,123,123,123,123,123,122,123,122,122,122,123,122,123,122,122,123,123,123,123,122,123,123,123,123,122,0
0,123,122,123,122,122,123,123,123,123,123,122,123,123,123,122,123,122,123,122,123,123,123,123,123,123,123,123,123,122,123,123,122,122,123,123,122,123,123,123,122,123,123,123,123,122,122,123,123,122,123,123,123,123,123,123,0
0,122,123,123,123,123,123,123,123,123,122,123,123,123,123,122,122,122,123,123,123,123,123,123,122,122,122,122,123,123,122,123,122,123,123,123,122,122,123,123,123,123,122,122,123,123,123,122,123,122,123,123,123,122,123,123,0
0,122,122,122,123,123,122,123,122,123,123,123,123,123,123,122,122,123,123,123,123,123,122,123,122,123,123,122,123,123,123,123,123,123,123,123,122,122,122,123,123,122,123,123,123,123,123,123,123,123,122,123,123,122,123,122,0
0,123,123,123,123,122,123,123,123,122,123,122,123,122,122,122,123,122,122,123,123,123,123,122,123,123,123,123,122,122,123,123,122,123,123,123,123,123,123,123,123,123,123,123,122,122,122,122,123,122,123,123,123,122,122,123,0
0,123,122,123,123,123,123,123,123,122,123,123,123,123,123,123,123,122,122,123,122,122,122,123,122,123,123,122,123,123,123,123,123,122,123,123,123,123,123,123,123,123,123,123,123,123,123,122,123,123,123,123,123,123,122,123,0
0,123,122,123,123,123,123,122,123,123,123,123,123,122,123,123,123,123,123,122,123,123,122,123,123,122,123,123,123,122,123,123,123,123,123,123,123,122,123,122,123,122,123,122,123,123,122,123,122,123,122,123,123,123,122,123,0
0,123,123,123,122,123,123,122,123,123,123,123,123,123,123,123,123,123,123,122,123,122,123,122,122,123,122,123,122,123,122,122,123,123,123,123,123,123,123,123,123,122,122,122,122,123,123,123,123,123,123,123,123,123,123,123,0
0,0,0,0,0,0,0,0,0,0,0,0,0,0,0,0,0,0,0,0,0,0,0,0,0,0,0,0,0,0,0,0,0,0,0,0,0,0,0,0,0,0,0,0,0,0,0,0,0,0,0,0,0,0,0,0,0
:endlayer
layer: 16
0,0,0,0,0,0,0,0,0,0,0,0,0,0,0,0,0,0,0,0,0,0,0,0,0,0,0,0,0,0,0,0,0,0,0,0,0,0,0,0,0,0,0,0,0,0,0,0,0,0,0,0,0,0,0,0,0
0,0,0,0,0,0,0,0,0,0,0,0,0,0,0,0,0,0,0,0,0,0,0,0,0,0,0,0,0,0,0,0,0,0,0,0,0,0,0,0,0,0,0,0,0,0,0,0,0,0,0,0,0,0,0,0,0
0,0,122,122,123,123,123,122,122,123,123,122,123,123,123,123,123,123,122,122,123,122,123,122,123,123,123,123,123,123,123,123,123,122,123,123,123,123,123,123,123,123,123,123,123,123,122,122,122,123,122,123,122,122,123,0,0
0,0,122,123,123,123,123,122,123,122,123,123,123,122,123,122,123,122,123,122,122,123,123,123,123,122,123,123,123,123,123,123,123,123,122,122,123,123,122,123,123,123,122,123,122,122,123,123,123,123,123,122,123,123,123,0,0
0,0,122,123,123,122,123,123,122,123,123,123,122,122,122,123,123,123,123,123,123,123,122,123,123,122,123,122,123,123,123,122,122,122,123,123,123,123,122,123,122,123,123,123,123,123,123,123,122,123,123,122,122,123,123,0,0
0,0,122,123,123,123,122,122,123,122,123,123,123,123,122,122,123,122,123,123,123,123,123,123,123,122,123,122,122,123,122,122,123,123,122,123,123,123,123,123,122,122,123,122,122,123,123,123,122,123,123,122,123,122,122,0,0
0,0,123,122,122,123,123,123,123,122,123,123,122,123,122,123,122,123,123,123,122,122,123,123,123,122,122,122,122,123,122,123,123,123,123,123,123,122,123,123,123,123,122,123,123,122,122,123,123,123,122,123,123,122,123,0,0
0,0,123,123,123,123,123,122,123,122,123,122,123,122,123,123,122,123,123,123,122,122,123,123,123,122,123,123,123,122,122,123,123,122,123,123,122,123,122,123,122,122,123,122,122,123,123,123,123,122,122,123,123,123,123,0,0
0,0,123,123,123,123,123,123,123,122,123,123,123,123,123,122,123,123,123,123,123,123,123,123,123,123,122,123,123,123,123,122,122,123,122,122,123,123,123,122,123,123,123,123,123,123,123,123,122,123,123,123,122,123,123,0,0
0,0,123,123,122,122,122,122,122,122,123,123,123,123,122,123,123,123,123,123,122,122,123,122,122,122,123,123,123,123,122,122,123,123,122,123,123,123,122,122,123,123,123,122,123,122,122,123,123,123,122,122,122,122,123,0,0
0,0,123,123,123,123,123,122,123,123,123,122,123,123,122,123,123,123,123,123,122,123,123,123,76,0,0,0,0,0,0,0,123,123,123,122,123,123,123,123,122,123,123,123,123,122,123,123,123,123,123,123,123,123,122,0,0
0,0,122,123,123,123,122,123,123,123,123,123,122,123,123,122,123,123,123,122,123,123,122,122,76,0,0,0,0,0,0,0,11,11,123,123,123,123,122,123,122,123,123,123,123,123,123,123,123,122,122,123,123,122,122,0,0
0,0,122,123,123,123,122,123,122,123,123,123,123,123,123,124,122,125,122,126,127,123,123,123,122,122,122,122,122,122,122,122,122,11,122,122,123,122,122,122,123,123,122,123,123,123,123,122,123,123,123,123,123,123,123,0,0
0,0,123,123,123,123,122,123,123,123,123,123,123,122,123,0,128,0,0,0,0,123,123,123,122,122,123,123,122,123,123,123,122,123,123,123,123,122,123,123,123,123,123,122,123,122,123,123,123,123,123,122,123,122,123,0,0
0,0,123,123,123,123,123,123,123,122,122,123,123,122,122,129,130,0,0,0,0,60,123,123,123,123,123,123,123,123,123,122,123,122,122,122,123,123,123,122,123,123,123,123,123,123,123,123,122,122,123,122,123,122,123,0,0
0,0,123,123,122,122,123,123,123,123,123,122,122,123,122,0,131,0,0,0,0,122,122,123,123,123,123,123,123,123,122,123,123,123,123,123,123,122,123,123,123,123,123,123,123,123,123,123,123,122,123,122,122,123,122,0,0
0,0,122,123,123,122,122,123,123,122,122,122,123,122,123,129,130,132,0,0,0,123,123,123,122,122,123,123,122,122,122,123,123,122,122,123,123,123,123,122,123,122,123,123,122,123,123,123,123,122,123,123,122,123,123,0,0
0,0,122,123,122,123,123,123,122,122,123,122,123,123,122,0,133,0,134,135,134,123,122,123,122,122,123,123,122,123,123,123,122,122,123,123,123,123,123,123,123,123,122,123,123,122,123,123,122,123,123,122,122,123,123,0,0
0,0,123,122,123,123,123,123,123,122,123,122,123,123,123,129,130,0,136,0,136,123,123,123,123,122,123,123,123,123,123,123,123,123,123,123,123,122,123,122,123,123,122,123,122,123,123,123,123,123,123,122,123,122,123,0,0
0,0,122,123,123,123,123,122,123,123,122,122,122,122,122,122,122,123,122,123,123,123,123,123,123,123,122,123,123,123,123,123,123,123,123,123,123,123,122,122,123,123,123,123,123,123,122,123,123,123,122,122,123,123,123,0,0
0,0,122,123,122,123,122,123,122,122,123,123,122,122,123,123,122,123,122,123,123,123,123,122,122,122,123,123,123,122,123,123,123,122,123,122,123,123,123,122,122,123,122,123,122,123,123,123,123,123,123,122,123,123,123,0,0
0,0,123,123,122,123,122,123,123,123,123,122,122,123,123,122,123,123,123,122,123,123,122,123,122,122,122,123,123,123,123,123,122,122,123,123,123,122,122,123,123,122,123,123,123,122,123,122,122,122,123,123,123,122,123,0,0
0,0,123,123,122,123,123,122,123,123,122,123,123,123,123,123,122,123,123,123,123,122,123,123,123,123,123,123,122,123,123,122,123,122,123,123,123,122,123,123,123,123,122,123,123,123,122,122,122,122,122,122,123,123,123,0,0
0,0,123,123,123,123,123,122,122,123,123,123,123,122,122,122,123,123,123,123,123,122,123,123,123,123,123,123,123,123,123,123,123,123,122,123,123,122,122,123,123,123,122,122,122,122,122,123,123,123,122,123,122,123,123,0,0
0,0,123,123,123,123,123,122,122,123,123,123,123,123,123,123,123,123,122,122,123,123,123,123,123,123,123,123,123,123,123,123,123,123,123,123,123,123,123,123,123,123,122,122,122,123,122,123,123,123,123,123,123,123,122,0,0
0,0,123,123,123,123,122,122,123,122,123,122,123,123,123,122,123,123,123,122,123,123,122,123,123,123,122,122,123,122,123,123,123,123,123,123,123,123,123,122,122,122,123,123,122,123,123,122,122,123,123,123,123,123,123,0,0
0,0,122,122,123,123,122,122,122,123,122,123,123,123,123,122,123,123,123,122,122,123,123,123,123,123,123,123,123,122,123,122,123,123,123,123,122,123,123,123,123,123,122,122,123,123,123,123,123,123,122,123,123,122,123,0,0
0,0,123,122,122,123,123,123,123,122,123,123,123,123,123,123,122,123,123,122,123,123,123,123,122,123,123,123,122,123,123,122,123,122,123,122,123,123,123,123,123,123,123,122,123,123,123,122,123,123,123,122,122,123,122,0,0
0,0,122,123,122,123,122,123,123,122,122,123,122,122,123,122,122,122,123,123,122,123,122,123,123,122,123,123,123,123,123,123,123,122,123,123,122,123,123,123,123,123,123,123,123,122,123,122,123,123,123,123,122,123,122,0,0
0,0,123,122,123,123,122,123,123,122,123,123,123,122,123,123,123,123,123,123,123,123,122,122,123,123,123,122,122,123,123,123,123,123,123,122,123,123,122,123,123,123,123,123,123,123,123,123,123,122,123,123,123,123,123,0,0
0,0,123,122,123,123,123,122,122,122,123,122,123,122,122,123,123,122,123,123,123,123,123,123,122,122,123,123,123,122,123,123,123,122,123,122,123,122,123,122,123,123,123,123,123,123,123,123,122,123,122,123,123,122,123,0,0
0,0,123,123,123,122,122,122,123,123,123,123,122,123,123,123,123,123,123,123,123,123,123,123,123,123,123,122,122,122,123,122,123,123,123,123,123,123,123,123,122,122,122,122,123,122,123,123,123,123,123,123,123,123,122,0,0
0,0,123,123,123,123,123,123,123,122,122,123,122,123,123,123,123,122,123,123,123,123,123,122,123,123,123,122,123,122,123,123,123,123,123,123,123,123,122,122,123,122,123,122,123,123,123,123,122,123,123,122,123,122,122,0,0
0,0,123,123,123,122,123,123,122,123,123,123,123,123,122,122,123,122,123,122,123,122,122,123,123,123,123,123,123,123,123,123,123,123,123,123,123,123,123,122,123,123,123,123,123,123,122,122,122,123,123,123,123,122,122,0,0
0,0,123,122,122,122,122,123,123,122,123,123,122,122,123,122,123,122,123,123,123,122,123,122,123,122,123,122,123,123,123,122,122,123,122,123,123,122,123,122,122,123,123,123,123,122,123,122,122,123,123,122,122,123,122,0,0
0,0,123,122,123,123,122,123,123,123,122,122,123,123,123,123,123,123,123,123,123,123,123,123,122,123,122,123,122,123,122,123,123,123,123,122,122,123,123,123,123,123,122,122,122,123,123,122,123,122,123,122,123,123,123,0,0
0,0,123,123,123,122,123,122,123,122,123,122,123,123,122,123,123,123,122,123,123,123,123,123,122,123,123,123,122,122,123,122,122,123,123,122,122,123,123,122,123,123,123,123,122,123,123,123,123,122,123,123,122,122,122,0,0
0,0,122,123,123,122,123,123,123,122,123,123,122,123,123,123,122,122,123,123,123,123,122,123,123,123,123,123,123,123,123,123,123,122,123,123,123,123,123,123,123,122,123,123,123,123,123,123,123,123,123,123,123,123,122,0,0
0,0,122,123,123,123,123,123,123,123,123,123,122,123,123,123,123,122,123,123,123,123,123,123,123,123,123,122,123,123,123,123,123,122,123,123,123,123,123,122,122,123,123,123,122,123,122,123,122,123,123,123,123,123,123,0,0
0,0,123,123,123,123,123,122,123,122,123,123,123,123,123,123,122,122,122,122,123,122,123,123,123,123,123,123,123,123,123,123,122,123,123,122,123,123,123,122,123,123,122,123,122,122,123,123,122,123,122,122,123,122,122,0,0
0,0,0,0,0,0,0,0,0,0,0,0,0,0,0,0,0,0,0,0,0,0,0,0,0,0,0,0,0,0,0,0,0,0,0,0,0,0,0,0,0,0,0,0,0,0,0,0,0,0,0,0,0,0,0,0,0
0,0,0,0,0,0,0,0,0,0,0,0,0,0,0,0,0,0,0,0,0,0,0,0,0,0,0,0,0,0,0,0,0,0,0,0,0,0,0,0,0,0,0,0,0,0,0,0,0,0,0,0,0,0,0,0,0
:endlayer
layer: 17
0,0,0,0,0,0,0,0,0,0,0,0,0,0,0,0,0,0,0,0,0,0,0,0,0,0,0,0,0,0,0,0,0,0,0,0,0,0,0,0,0,0,0,0,0,0,0,0,0,0,0,0,0,0,0,0,0
0,0,0,0,0,0,0,0,0,0,0,0,0,0,0,0,0,0,0,0,0,0,0,0,0,0,0,0,0,0,0,0,0,0,0,0,0,0,0,0,0,0,0,0,0,0,0,0,0,0,0,0,0,0,0,0,0
0,0,0,0,0,0,0,0,0,0,0,0,0,0,0,0,0,0,0,0,0,0,0,0,0,0,0,0,0,0,0,0,0,0,0,0,0,0,0,0,0,0,0,0,0,0,0,0,0,0,0,0,0,0,0,0,0
0,0,0,0,0,0,0,0,0,0,0,0,0,0,0,0,0,0,0,0,0,0,0,0,0,0,0,0,0,0,0,0,0,0,0,0,0,0,0,0,0,0,0,0,0,0,0,0,0,0,0,0,0,0,0,0,0
0,0,0,0,0,0,0,0,0,0,0,0,0,0,0,0,0,0,0,0,0,0,0,0,0,0,0,0,0,0,0,0,0,0,0,0,0,0,0,0,0,0,0,0,0,0,0,0,0,0,0,0,0,0,0,0,0
0,0,0,0,0,0,0,0,0,0,0,0,0,0,0,0,0,0,0,0,0,0,0,0,0,0,0,0,0,0,0,0,0,0,0,0,0,0,0,0,0,0,0,0,0,0,0,0,0,0,0,0,0,0,0,0,0
0,0,0,0,0,0,0,0,123,122,123,123,122,123,122,123,122,123,123,123,123,123,123,123,123,123,123,123,123,122,123,122,123,0,123,123,122,123,122,122,123,123,122,122,123,123,122,123,122,0,0,0,0,0,0,0,0
0,0,0,0,0,0,0,123,123,123,123,122,122,123,122,122,123,122,122,123,122,123,123,123,123,123,123,123,123,123,123,123,123,0,123,123,123,123,123,123,123,123,123,123,123,122,123,122,123,123,0,0,0,0,0,0,0
0,0,0,0,0,0,122,122,123,123,123,122,123,123,122,123,123,123,122,123,122,123,122,122,122,122,122,122,123,123,122,122,122,0,122,123,123,122,123,122,123,123,123,123,123,123,123,123,123,122,123,0,0,0,0,0,0
0,0,0,0,0,123,123,122,123,122,122,123,122,123,122,122,123,123,123,122,123,123,122,123,123,123,122,123,122,123,123,123,123,0,123,123,122,123,122,122,123,122,122,123,123,122,122,122,122,122,123,122,0,0,0,0,0
