# Ancient Warfare Structure Template File
# Auto-generated structure template file. created on: 1/4/2019 at: 21:10:47
# Lines beginning with # denote comments

header:
version=2.8
name=BarbarianBroch2
mods=
size=23,28,27
offset=13,7,26
:endheader

#### VALIDATION ####
validation:
type=ground
survival=false
worldGenEnabled=true
unique=false
preserveBlocks=false
selectionWeight=40
clusterValue=50
minDuplicateDistance=600
dimensionWhiteList=true
dimensionList=0
biomeWhiteList=true
biomeList=traverse:rocky_plains,minecraft:taiga,minecraft:redwood_taiga,minecraft:extreme_hills,minecraft:mutated_taiga,biomesoplenty:steppe,traverse:rocky_plateau
leveling=10
fill=10
border=10
blockSwap=false
:endvalidation

#### LAYERS ####
layer: 0
1,1,1,1,1,1,1,1,1,1,1,1,1,1,1,1,1,1,1,1,1,1,1
1,1,1,1,1,1,1,1,1,1,1,1,1,1,1,1,1,1,1,1,1,1,1
1,1,1,1,1,1,1,1,1,1,1,1,1,1,1,1,1,1,1,1,1,1,1
1,1,1,1,1,1,1,1,1,1,1,1,1,1,1,1,1,1,1,1,1,1,1
1,1,1,1,1,1,1,1,1,1,1,1,1,1,1,1,1,1,1,1,1,1,1
1,1,1,1,1,1,1,1,1,1,1,1,1,1,1,1,1,1,1,1,1,1,1
1,1,1,1,1,1,1,1,1,1,1,1,1,1,1,1,1,1,1,1,1,1,1
1,1,1,1,1,1,1,1,1,1,1,1,1,1,1,1,1,1,1,1,1,1,1
1,1,1,1,1,1,1,1,1,1,1,1,1,1,1,1,1,1,1,1,1,1,1
1,1,1,1,1,1,1,1,1,1,1,1,1,1,1,1,1,1,1,1,1,1,1
1,1,1,1,1,1,1,1,1,1,1,1,1,1,1,1,1,1,1,1,1,1,1
1,1,1,1,1,1,1,1,1,1,1,1,1,1,1,1,1,1,1,1,1,1,1
1,1,1,1,1,1,1,1,1,1,1,1,1,1,1,1,1,1,1,1,1,1,1
1,1,1,1,1,1,1,1,1,1,1,1,1,1,1,1,1,1,1,1,1,1,1
1,1,1,1,1,1,1,1,1,1,1,1,1,1,1,1,1,1,1,1,1,1,1
1,1,1,1,1,1,1,1,1,1,1,1,1,1,1,1,1,1,1,1,1,1,1
1,1,1,1,1,1,1,1,1,1,1,1,1,1,1,1,1,1,1,1,1,1,1
1,1,1,1,1,1,1,1,1,1,1,1,1,1,1,1,1,1,1,1,1,1,1
1,1,1,1,1,1,1,1,1,1,1,1,1,1,1,1,1,1,1,1,1,1,1
1,1,1,1,1,1,1,1,1,1,1,1,1,1,1,1,1,1,1,1,1,1,1
1,1,1,1,1,1,1,1,1,1,1,1,1,1,1,1,1,1,1,1,1,1,1
1,1,1,1,1,1,1,1,1,1,1,1,1,1,1,1,1,1,1,1,1,1,1
1,1,1,1,1,1,1,1,1,1,1,1,1,1,1,1,1,1,1,1,1,1,1
1,1,1,1,1,1,1,1,1,1,1,1,1,1,1,1,1,1,1,1,1,1,1
1,1,1,1,1,1,1,1,1,1,1,1,1,1,1,1,1,1,1,1,1,1,1
1,1,1,1,1,1,1,1,1,1,1,1,1,1,1,1,1,1,1,1,1,1,1
1,1,1,1,1,1,1,1,1,1,1,1,1,1,1,1,1,1,1,1,1,1,1
:endlayer
layer: 1
1,1,1,1,1,1,1,1,1,1,1,1,1,1,1,1,1,1,1,1,1,1,1
1,1,1,1,1,1,1,1,1,1,1,1,1,1,1,1,1,1,1,1,1,1,1
1,1,1,1,1,1,1,1,1,1,1,1,1,1,1,1,1,1,1,1,1,1,1
1,1,1,1,1,1,1,1,1,1,1,1,1,1,1,1,1,1,1,1,1,1,1
1,1,1,1,1,1,1,1,1,1,1,1,1,1,1,1,1,1,1,1,1,1,1
1,1,1,1,1,1,1,1,1,1,1,1,1,1,1,1,1,1,1,1,1,1,1
1,1,1,1,1,1,1,1,1,1,1,1,1,1,1,1,1,1,1,1,1,1,1
1,1,1,1,1,1,1,1,1,1,1,1,1,1,1,1,1,1,1,1,1,1,1
1,1,1,1,1,1,1,1,1,1,1,1,1,1,1,1,1,1,1,1,1,1,1
1,1,1,1,1,1,1,1,1,1,1,1,1,1,1,1,1,1,1,1,1,1,1
1,1,1,1,1,1,1,1,1,1,1,1,1,1,1,1,1,1,1,1,1,1,1
1,1,1,1,1,1,1,1,1,1,1,1,1,1,1,1,1,1,1,1,1,1,1
1,1,1,1,1,1,1,1,1,1,1,1,1,1,1,1,1,1,1,1,1,1,1
1,1,1,1,1,1,1,1,1,1,1,1,1,1,1,1,1,1,1,1,1,1,1
1,1,1,1,1,1,1,1,1,1,1,1,1,1,1,1,1,1,1,1,1,1,1
1,1,1,1,1,1,1,1,1,1,1,1,1,1,1,1,1,1,1,1,1,1,1
1,1,1,1,1,1,1,1,1,1,1,1,1,1,1,1,1,1,1,1,1,1,1
1,1,1,1,1,1,1,1,1,1,1,1,1,1,1,1,1,1,1,1,1,1,1
1,1,1,1,1,1,1,1,1,1,1,1,1,1,1,1,1,1,1,1,1,1,1
1,1,1,1,1,1,1,1,1,1,1,1,1,1,1,1,1,1,1,1,1,1,1
1,1,1,1,1,1,1,1,1,1,1,1,1,1,1,1,1,1,1,1,1,1,1
1,1,1,1,1,1,1,1,1,1,1,1,1,1,1,1,1,1,1,1,1,1,1
1,1,1,1,1,1,1,1,1,1,1,1,1,1,1,1,1,1,1,1,1,1,1
1,1,1,1,1,1,1,1,1,1,1,1,1,1,1,1,1,1,1,1,1,1,1
1,1,1,1,1,1,1,1,1,1,1,1,1,1,1,1,1,1,1,1,1,1,1
1,1,1,1,1,1,1,1,1,1,1,1,1,1,1,1,1,1,1,1,1,1,1
1,1,1,1,1,1,1,1,1,1,1,1,1,1,1,1,1,1,1,1,1,1,1
:endlayer
layer: 2
1,1,1,1,1,1,1,1,1,1,1,1,1,1,1,1,1,1,1,1,1,1,1
1,1,1,1,1,1,1,1,1,1,1,1,1,1,1,1,1,1,1,1,1,1,1
1,1,1,1,1,1,1,1,1,1,1,1,1,1,1,1,1,1,1,1,1,1,1
1,1,1,1,1,1,1,1,1,1,1,1,1,1,1,1,1,1,1,1,1,1,1
1,1,1,1,1,1,1,1,1,1,1,1,1,1,1,1,1,1,1,1,1,1,1
1,1,1,1,1,1,1,1,1,1,1,1,1,1,1,1,1,1,1,1,1,1,1
1,1,1,1,1,1,1,1,1,1,1,1,1,1,1,1,1,1,1,1,1,1,1
1,1,1,1,1,1,1,1,1,1,1,1,1,1,1,1,1,1,1,1,1,1,1
1,1,1,1,1,1,1,1,1,1,1,1,1,1,1,1,1,1,1,1,1,1,1
1,1,1,1,1,1,1,1,1,1,1,1,1,1,1,1,1,1,1,1,1,1,1
1,1,1,1,1,1,1,1,1,1,1,1,1,1,1,1,1,1,1,1,1,1,1
1,1,1,1,1,1,1,1,1,1,1,1,1,1,1,1,1,1,1,1,1,1,1
1,1,1,1,1,1,1,1,1,1,1,1,1,1,1,1,1,1,1,1,1,1,1
1,1,1,1,1,1,1,1,1,1,1,1,1,1,1,1,1,1,1,1,1,1,1
1,1,1,1,1,1,1,1,1,1,1,1,1,1,1,1,1,1,1,1,1,1,1
1,1,1,1,1,1,1,1,1,1,1,1,1,1,1,1,1,1,1,1,1,1,1
1,1,1,1,1,1,1,1,1,1,1,1,1,1,1,1,1,1,1,1,1,1,1
1,1,1,1,1,1,1,1,1,1,1,1,1,1,1,1,1,1,1,1,1,1,1
1,1,1,1,1,1,1,1,1,1,1,1,1,1,1,1,1,1,1,1,1,1,1
1,1,1,1,1,1,1,1,1,1,1,1,1,1,1,1,1,1,1,1,1,1,1
1,1,1,1,1,1,1,1,1,1,1,1,1,1,1,1,1,1,1,1,1,1,1
1,1,1,1,1,1,1,1,1,1,1,1,1,1,1,1,1,1,1,1,1,1,1
1,1,1,1,1,1,1,1,1,1,1,1,1,1,1,1,1,1,1,1,1,1,1
1,1,1,1,1,1,1,1,1,1,1,1,1,1,1,1,1,1,1,1,1,1,1
1,1,1,1,1,1,1,1,1,1,1,1,1,1,1,1,1,1,1,1,1,1,1
1,1,1,1,1,1,1,1,1,1,1,1,1,1,1,1,1,1,1,1,1,1,1
1,1,1,1,1,1,1,1,1,1,1,1,1,1,1,1,1,1,1,1,1,1,1
:endlayer
layer: 3
1,1,1,1,1,1,1,1,1,1,1,1,1,1,1,1,1,1,1,1,1,1,1
1,1,1,1,1,1,1,1,1,1,1,1,1,1,1,1,1,1,1,1,1,1,1
1,1,1,1,1,1,1,1,1,1,1,1,1,1,1,1,1,1,1,1,1,1,1
1,1,1,1,1,1,1,1,1,1,1,1,1,1,1,1,1,1,1,1,1,1,1
1,1,1,1,1,1,1,1,1,1,1,1,1,1,1,1,1,1,1,1,1,1,1
1,1,1,1,1,1,1,1,1,1,1,1,1,1,1,1,1,1,1,1,1,1,1
1,1,1,1,1,1,1,1,1,1,1,1,1,1,1,1,1,1,1,1,1,1,1
1,1,1,1,1,1,1,1,1,1,1,1,1,1,1,1,1,1,1,1,1,1,1
1,1,1,1,1,1,1,1,1,1,1,1,1,1,1,1,1,1,1,1,1,1,1
1,1,1,1,1,1,1,1,1,1,1,1,1,1,1,1,1,1,1,1,1,1,1
1,1,1,1,1,1,1,1,1,1,1,1,1,1,1,1,1,1,1,1,1,1,1
1,1,1,1,1,1,1,1,1,1,1,1,1,1,1,1,1,1,1,1,1,1,1
1,1,1,1,1,1,1,1,1,1,1,1,1,1,1,1,1,1,1,1,1,1,1
1,1,1,1,1,1,1,1,1,1,1,1,1,1,1,1,1,1,1,1,1,1,1
1,1,1,1,1,1,1,1,1,1,1,1,1,1,1,1,1,1,1,1,1,1,1
1,1,1,1,1,1,1,1,1,1,1,1,1,1,1,1,1,1,1,1,1,1,1
1,1,1,1,1,1,1,1,1,1,1,1,1,1,1,1,1,1,1,1,1,1,1
1,1,1,1,1,1,1,1,1,1,1,1,1,1,1,1,1,1,1,1,1,1,1
1,1,1,1,1,1,1,1,1,1,1,1,1,1,1,1,1,1,1,1,1,1,1
1,1,1,1,1,1,1,1,1,1,1,1,1,1,1,1,1,1,1,1,1,1,1
1,1,1,1,1,1,1,1,1,1,1,1,1,1,1,1,1,1,1,1,1,1,1
1,1,1,1,1,1,1,1,1,1,1,1,1,1,1,1,1,1,1,1,1,1,1
1,1,1,1,1,1,1,1,1,1,1,1,1,1,1,1,1,1,1,1,1,1,1
1,1,1,1,1,1,1,1,1,1,1,1,1,1,1,1,1,1,1,1,1,1,1
1,1,1,1,1,1,1,1,1,1,1,1,1,1,1,1,1,1,1,1,1,1,1
1,1,1,1,1,1,1,1,1,1,1,1,1,1,1,1,1,1,1,1,1,1,1
1,1,1,1,1,1,1,1,1,1,1,1,1,1,1,1,1,1,1,1,1,1,1
:endlayer
layer: 4
1,1,1,1,1,1,1,1,1,1,1,1,1,1,1,1,1,1,1,1,1,1,1
1,1,1,1,1,1,1,1,1,1,1,1,1,1,1,1,1,1,1,1,1,1,1
1,1,1,1,1,1,1,1,1,1,1,1,1,1,1,1,1,1,1,1,1,1,1
1,1,1,1,1,1,1,1,1,1,1,1,1,1,1,1,1,1,1,1,1,1,1
1,1,1,1,1,1,1,1,1,1,1,1,1,1,1,1,1,1,1,1,1,1,1
1,1,1,1,1,1,1,1,1,1,1,1,1,1,1,1,1,1,1,1,1,1,1
1,1,1,1,1,1,1,1,1,1,1,1,1,1,1,1,1,1,1,1,1,1,1
1,1,1,1,1,1,1,1,1,1,1,1,1,1,1,1,1,1,1,1,1,1,1
1,1,1,1,1,1,1,1,1,1,1,1,1,1,1,1,1,1,1,1,1,1,1
1,1,1,1,1,1,1,1,1,1,1,1,1,1,1,1,1,1,1,1,1,1,1
1,1,1,1,1,1,1,1,1,1,1,1,1,1,1,1,1,1,1,1,1,1,1
1,1,1,1,1,1,1,1,1,1,1,1,1,1,1,1,1,1,1,1,1,1,1
1,1,1,1,1,1,1,1,1,1,1,1,1,1,1,1,1,1,1,1,1,1,1
1,1,1,1,1,1,1,1,1,1,1,1,1,1,1,1,1,1,1,1,1,1,1
1,1,1,1,1,1,1,1,1,1,1,1,1,1,1,1,1,1,1,1,1,1,1
1,1,1,1,1,1,1,1,1,1,1,1,1,1,1,1,1,1,1,1,1,1,1
1,1,1,1,1,1,1,1,1,1,1,1,1,1,1,1,1,1,1,1,1,1,1
1,1,1,1,1,1,1,1,1,1,1,1,1,1,1,1,1,1,1,1,1,1,1
1,1,1,1,1,1,1,1,1,1,1,1,1,1,1,1,1,1,1,1,1,1,1
1,1,1,1,1,1,1,1,1,1,1,1,1,1,1,1,1,1,1,1,1,1,1
1,1,1,1,1,1,1,1,1,1,1,1,1,1,1,1,1,1,1,1,1,1,1
1,1,1,1,1,1,1,1,1,1,1,1,1,1,1,1,1,1,1,1,1,1,1
1,1,1,1,1,1,1,1,1,1,1,1,1,1,1,1,1,1,1,1,1,1,1
1,1,1,1,1,1,1,1,1,1,1,1,1,1,1,1,1,1,1,1,1,1,1
1,1,1,1,1,1,1,1,1,1,1,1,1,1,1,1,1,1,1,1,1,1,1
1,1,1,1,1,1,1,1,1,1,1,1,1,1,1,1,1,1,1,1,1,1,1
1,1,1,1,1,1,1,1,1,1,1,1,1,1,1,1,1,1,1,1,1,1,1
:endlayer
layer: 5
1,1,1,1,1,1,1,1,1,1,1,1,1,1,1,1,1,1,1,1,1,1,1
1,1,1,1,1,1,1,1,1,1,1,1,1,1,1,1,1,1,1,1,1,1,1
1,1,1,1,1,1,1,1,1,1,1,1,1,1,1,1,1,1,1,1,1,1,1
1,1,1,1,1,1,1,1,1,1,1,1,1,1,1,1,1,1,1,1,1,1,1
1,1,1,1,1,1,1,1,1,1,1,1,1,1,1,1,1,1,1,1,1,1,1
1,1,1,1,1,1,1,1,1,1,1,1,1,1,1,1,1,1,1,1,1,1,1
1,1,1,1,1,1,1,1,1,1,1,1,1,1,1,1,1,1,1,1,1,1,1
1,1,1,1,1,1,1,1,1,1,1,1,1,1,1,1,1,1,1,1,1,1,1
1,1,1,1,1,1,1,1,1,1,1,1,1,1,1,1,1,1,1,1,1,1,1
1,1,1,1,1,1,1,1,1,1,1,1,1,1,1,1,1,1,1,1,1,1,1
1,1,1,1,1,1,1,1,1,1,1,1,1,1,1,1,1,1,1,1,1,1,1
1,1,1,1,1,1,1,1,1,1,1,1,1,1,1,1,1,1,1,1,1,1,1
1,1,1,1,1,1,1,1,1,1,1,1,1,1,1,1,1,1,1,1,1,1,1
1,1,1,1,1,1,1,1,1,1,1,1,1,1,1,1,1,1,1,1,1,1,1
1,1,1,1,1,1,1,1,1,1,1,1,1,1,1,1,1,1,1,1,1,1,1
1,1,1,1,1,1,1,1,1,1,1,1,1,1,1,1,1,1,1,1,1,1,1
1,1,1,1,1,1,1,1,1,1,1,1,1,1,1,1,1,1,1,1,1,1,1
1,1,1,1,1,1,1,1,1,1,1,1,1,1,1,1,1,1,1,1,1,1,1
1,1,1,1,1,1,1,1,1,1,1,1,1,1,1,1,1,1,1,1,1,1,1
1,1,1,1,1,1,1,1,1,1,1,1,1,1,1,1,1,1,1,1,1,1,1
1,1,1,1,1,1,1,1,1,1,1,1,1,1,1,1,1,1,1,1,1,1,1
1,1,1,1,1,1,1,1,1,1,1,1,1,1,1,1,1,1,1,1,1,1,1
1,1,1,1,1,1,1,1,1,1,1,1,1,1,1,1,1,1,1,1,1,1,1
1,1,1,1,1,1,1,1,1,1,1,1,1,1,1,1,1,1,1,1,1,1,1
1,1,1,1,1,1,1,1,1,1,1,1,1,1,1,1,1,1,1,1,1,1,1
1,1,1,1,1,1,1,1,1,1,1,1,1,1,1,1,1,1,1,1,1,1,1
1,1,1,1,1,1,1,1,1,1,1,1,1,1,1,1,1,1,1,1,1,1,1
:endlayer
layer: 6
2,2,2,2,2,2,2,2,2,2,2,2,2,2,2,2,2,2,2,2,2,2,2
2,2,2,2,2,2,2,2,2,2,2,2,2,2,2,2,2,2,2,2,2,2,2
2,2,2,1,2,2,2,2,2,2,2,2,2,2,2,2,2,2,2,2,2,2,2
2,2,2,2,2,2,2,2,2,2,2,2,2,2,2,2,2,2,2,1,2,2,2
2,2,2,2,2,2,2,2,1,2,3,3,3,3,3,2,2,2,2,2,2,2,2
2,2,2,2,2,2,1,2,3,3,3,3,3,3,3,1,1,2,2,2,2,2,2
2,2,2,2,2,1,3,3,3,3,3,3,3,3,3,3,3,1,2,2,2,2,2
2,2,2,2,1,3,3,3,3,3,3,3,3,3,3,3,3,3,1,2,2,2,2
2,2,2,2,3,3,3,3,3,3,3,3,3,3,3,3,3,3,3,1,2,2,2
2,2,2,3,3,3,3,3,3,3,3,3,3,3,3,3,3,3,3,3,1,2,2
2,2,1,3,3,3,3,3,3,3,3,3,3,3,3,3,3,3,3,3,1,2,2
2,2,3,3,3,3,3,3,3,3,3,3,3,3,3,3,3,3,3,3,3,1,2
2,2,3,3,3,3,3,3,3,3,3,3,3,3,3,3,3,3,3,3,3,1,2
2,2,3,3,3,3,3,3,3,3,3,3,3,3,3,3,3,3,3,3,3,1,2
2,2,3,3,3,3,3,3,3,3,3,3,3,3,3,3,3,3,3,3,3,1,2
2,1,3,3,3,3,3,3,3,3,3,3,3,3,3,3,3,3,3,3,3,2,2
2,2,3,3,3,3,3,3,3,3,3,3,3,3,3,3,3,3,3,3,3,2,2
2,2,3,3,3,3,3,3,3,3,3,3,3,3,3,3,3,3,3,3,3,2,2
2,2,1,3,3,3,3,3,3,3,3,3,3,3,3,3,3,3,3,3,2,2,2
2,2,2,3,3,3,3,3,3,3,3,3,3,3,3,3,3,3,3,3,1,2,2
2,2,2,1,3,3,3,3,3,3,3,3,3,3,3,3,3,4,4,1,2,2,2
2,2,2,2,2,5,5,5,5,5,5,5,5,5,3,3,3,4,2,2,2,2,2
2,2,2,2,2,2,3,3,3,3,3,3,3,3,3,3,3,2,2,2,2,2,2
2,1,2,2,2,2,1,1,3,3,3,3,3,3,3,1,2,2,2,2,2,2,2
2,2,2,2,2,2,2,2,2,1,2,2,2,2,2,2,2,2,2,2,1,2,2
2,2,2,2,2,2,2,2,2,2,2,2,2,2,2,2,2,2,2,2,2,2,2
2,2,2,2,2,2,2,2,2,2,2,2,2,2,2,2,2,2,2,2,2,2,2
:endlayer
layer: 7
0,0,0,0,0,0,6,0,0,6,6,0,0,6,0,6,6,6,0,0,0,6,6
0,0,6,0,6,6,6,6,6,6,0,0,6,0,0,6,6,6,12,0,6,6,6
0,6,6,10,0,0,6,6,6,6,0,0,0,0,0,6,6,6,0,0,6,6,6
0,6,6,6,6,6,6,6,6,6,0,0,0,0,6,6,6,0,0,10,0,6,6
6,6,6,0,0,6,0,0,4,11,0,0,0,4,4,0,0,6,6,0,6,0,0
6,6,0,6,6,0,4,11,13,13,13,13,13,13,13,4,4,0,0,0,0,0,0
6,0,6,0,0,4,13,13,13,13,13,13,13,13,13,13,13,4,0,0,0,0,0
0,0,0,0,4,13,13,13,13,13,13,13,13,13,13,13,13,13,4,0,0,0,0
0,0,6,11,13,13,13,13,13,13,13,13,13,13,13,13,13,13,13,4,0,0,0
0,0,11,13,13,13,13,13,13,13,13,13,13,13,13,13,13,13,13,13,4,0,0
6,6,4,13,13,13,13,13,13,13,13,13,13,13,13,13,13,13,13,13,4,0,0
6,11,5,13,13,13,13,13,13,13,13,13,13,13,13,13,13,13,13,13,13,4,0
6,11,5,17,13,13,13,13,13,13,13,13,13,13,13,13,13,13,13,13,13,4,0
0,11,18,13,13,13,13,13,13,13,13,13,13,13,13,13,13,13,13,13,13,4,6
0,11,18,13,13,13,13,13,13,13,13,13,13,13,13,13,13,13,13,13,13,4,6
0,4,18,13,13,13,13,13,13,13,13,13,13,13,13,13,13,13,13,13,13,11,6
0,11,5,17,13,13,13,13,13,13,13,13,13,13,13,13,13,13,13,13,13,11,6
0,11,5,13,13,13,13,13,13,13,13,13,13,13,13,13,13,13,13,13,13,11,0
0,0,4,13,13,13,13,13,13,13,13,13,13,13,13,13,13,13,13,13,11,0,0
0,6,11,13,13,13,13,13,5,16,5,15,5,13,13,13,13,13,13,13,4,0,0
0,6,6,4,13,13,13,14,5,5,5,5,5,5,5,13,13,4,4,4,6,0,6
6,6,6,6,11,5,5,5,5,5,5,5,5,5,5,13,13,4,11,0,6,6,6
0,0,6,0,0,11,5,13,13,13,13,13,13,13,13,13,13,11,0,6,0,6,6
6,10,0,6,6,6,4,4,5,5,5,5,5,5,5,4,11,6,6,6,6,0,6
0,0,6,12,6,6,0,0,11,4,11,11,11,11,11,6,6,6,6,7,10,0,0
0,0,9,6,6,6,0,6,0,0,8,6,6,0,0,0,0,6,6,6,6,0,0
0,0,0,6,6,6,0,0,0,0,6,6,6,0,0,0,6,6,7,0,6,0,0
:endlayer
layer: 8
0,0,0,0,0,0,0,0,0,0,0,0,0,0,0,0,0,0,0,0,0,0,0
0,0,0,0,0,0,0,0,0,0,0,0,0,0,0,0,0,0,43,43,43,0,0
0,0,0,10,0,0,0,0,0,0,0,0,0,0,0,0,0,43,43,43,43,43,0
0,0,0,0,0,0,0,0,0,0,0,0,0,0,0,0,0,43,43,10,43,43,0
0,0,0,0,0,0,0,0,4,4,0,0,0,4,11,0,0,43,43,43,43,43,0
0,0,0,0,0,0,4,11,45,0,0,0,0,0,44,4,11,0,43,43,43,0,0
0,0,0,0,0,11,0,0,0,0,0,0,0,0,0,0,0,4,0,0,0,0,0
0,0,0,0,11,0,0,0,0,0,0,0,0,0,0,0,0,0,4,0,0,0,0
0,0,0,11,0,0,0,0,0,0,0,0,0,0,0,0,0,0,0,4,0,0,0
0,0,4,0,0,0,0,0,0,0,0,0,0,0,0,0,0,0,0,0,11,0,0
0,0,4,0,0,0,0,0,0,0,0,0,0,0,0,0,0,0,0,0,4,0,0
0,4,42,0,0,0,0,41,0,0,0,0,0,0,0,0,0,0,0,0,0,4,0
0,4,5,0,0,0,0,0,0,0,0,0,0,0,40,0,39,0,0,0,0,4,0
0,4,0,0,0,0,0,38,0,0,0,0,0,0,0,0,0,0,0,0,0,4,0
0,11,0,0,0,0,0,0,0,0,0,0,0,0,0,0,0,0,0,0,0,11,0
0,4,0,0,0,0,0,0,0,0,0,0,0,0,0,0,0,0,0,0,0,4,0
0,11,5,0,0,0,0,37,0,0,0,36,0,0,0,0,0,0,0,0,0,11,0
0,11,35,0,0,34,0,0,0,0,33,0,0,0,0,0,0,32,0,0,0,4,0
0,0,11,0,0,0,0,31,0,0,0,0,0,30,0,0,0,0,0,0,4,0,0
0,0,11,0,0,0,0,0,5,0,29,0,5,0,0,0,0,0,0,0,4,0,0
0,0,0,4,0,0,0,0,14,5,5,5,5,5,5,0,0,4,4,11,0,0,0
0,0,0,0,4,5,5,5,5,5,5,5,5,5,5,0,0,4,11,0,0,0,0
0,0,0,0,0,11,28,27,0,0,0,26,0,0,0,25,24,11,0,0,0,0,0
0,10,0,0,0,0,4,4,23,22,0,21,0,20,19,11,4,0,0,0,0,0,0
0,0,0,0,0,0,0,0,11,4,4,4,4,11,4,0,0,0,0,0,10,0,0
0,0,0,0,0,0,0,0,0,0,0,0,0,0,0,0,0,0,0,0,0,0,0
0,0,0,0,0,0,0,0,0,0,0,0,0,0,0,0,0,0,0,0,0,0,0
:endlayer
layer: 9
0,0,0,0,0,0,0,0,0,0,0,0,0,0,0,0,0,0,0,0,0,0,0
0,0,0,43,0,0,0,0,0,0,0,0,0,0,0,0,0,0,0,0,0,0,0
0,0,43,10,43,0,0,0,0,0,0,0,0,0,0,0,0,0,0,43,0,0,0
0,0,0,43,0,0,0,0,0,46,0,0,0,46,0,0,0,0,43,10,43,0,0
0,0,0,0,0,0,0,0,11,4,0,0,0,4,11,0,0,0,0,43,0,0,0
0,0,0,0,0,0,4,4,0,51,0,0,0,51,0,11,11,0,0,0,0,0,0
0,0,0,0,0,4,0,0,0,0,0,0,0,0,0,0,0,11,0,0,0,0,0
0,0,0,0,11,48,0,0,0,0,0,0,0,0,0,0,0,47,4,0,0,0,0
0,0,0,11,0,0,0,0,0,0,0,0,0,0,0,0,0,0,0,4,0,0,0
0,0,4,48,0,0,0,0,0,0,0,0,0,0,0,0,0,0,0,47,4,0,0
0,0,4,0,0,0,0,0,0,0,0,0,0,0,0,0,0,0,0,0,11,0,0
0,11,50,0,0,0,0,0,0,0,0,0,0,0,0,0,0,0,0,0,0,11,0
0,11,5,0,0,0,0,0,0,0,0,0,0,0,0,0,0,0,0,0,47,11,0
0,4,0,0,0,0,0,0,0,0,0,0,0,0,0,0,0,0,0,0,0,11,0
0,4,0,0,0,0,0,0,0,0,0,0,0,0,0,0,0,0,0,0,0,4,0
0,11,0,0,0,0,0,0,0,0,0,0,0,0,0,0,0,0,0,0,0,4,0
0,11,5,0,0,0,0,0,0,0,0,0,0,0,0,0,0,0,0,0,47,11,0
0,11,49,0,0,0,0,0,0,0,0,0,0,0,0,0,0,0,0,0,0,11,0
0,0,4,0,0,0,0,0,0,0,0,0,0,0,0,0,0,0,0,0,4,0,0
0,0,11,48,0,0,0,0,5,0,46,0,5,0,46,0,0,46,0,47,4,0,0
0,0,0,11,46,0,0,0,0,14,5,5,5,5,5,0,0,4,4,11,0,0,0
43,43,43,0,4,5,5,5,5,5,5,5,5,5,5,0,0,4,11,0,0,0,0
43,43,43,43,0,11,0,0,0,0,0,0,0,0,0,0,0,4,0,0,0,0,0
43,10,43,43,0,0,4,11,0,46,0,0,0,46,0,4,4,0,0,0,43,0,0
43,43,43,43,0,0,0,0,11,11,11,11,11,4,4,0,0,0,0,43,10,43,0
43,43,43,0,0,0,0,0,0,0,0,0,0,0,0,0,0,0,0,0,43,0,0
0,0,0,0,0,0,0,0,0,0,0,0,0,0,0,0,0,0,0,0,0,0,0
:endlayer
layer: 10
0,0,43,43,43,0,0,0,0,0,0,0,0,0,0,0,0,0,0,0,0,0,0
0,43,43,43,43,43,0,0,0,0,0,0,0,0,0,0,0,0,43,43,43,0,0
0,43,43,10,43,43,0,0,0,0,0,0,0,0,0,0,0,43,43,43,43,43,0
0,43,43,43,43,43,0,0,0,0,0,0,0,0,0,0,0,43,43,10,43,43,0
0,0,43,43,43,0,0,0,4,11,55,0,54,4,11,0,0,43,43,43,43,43,0
0,0,0,0,0,0,11,11,0,0,0,0,0,0,0,11,11,0,43,43,43,0,0
0,0,0,0,0,11,0,0,0,0,0,0,0,0,0,0,0,11,0,0,0,0,0
0,0,0,0,11,0,0,0,0,0,0,0,0,0,0,0,0,0,4,0,0,0,0
0,0,0,4,0,0,0,0,0,0,0,0,0,0,0,0,0,0,0,4,0,0,0
0,0,11,0,0,0,0,0,0,0,0,0,0,0,0,0,0,0,0,0,11,0,0
0,0,4,0,0,0,0,0,0,0,0,0,0,0,0,0,0,0,0,0,11,0,0
0,4,53,0,0,0,0,0,0,0,0,0,0,0,0,0,0,0,0,0,0,4,0
0,4,5,48,0,0,0,0,0,0,0,0,0,0,0,0,0,0,0,0,0,4,0
0,11,0,0,0,0,0,0,0,0,0,0,0,0,0,0,0,0,0,0,0,4,0
0,11,0,0,0,0,0,0,0,0,0,0,0,0,0,0,0,0,0,0,0,11,0
0,11,0,0,0,0,0,0,0,0,0,0,0,0,0,0,0,0,0,0,0,11,0
0,4,5,48,0,0,0,0,0,0,0,0,0,0,0,0,0,0,0,0,0,11,0
0,11,52,0,0,0,0,0,0,0,0,0,0,0,0,0,0,0,0,0,0,11,0
0,0,11,0,0,0,0,0,0,0,0,0,0,0,0,0,0,0,0,0,4,0,0
0,0,11,0,0,0,0,0,5,0,0,0,5,0,0,0,0,0,0,0,4,0,0
0,0,0,4,0,0,0,0,0,0,14,5,5,5,5,5,5,5,4,11,0,0,0
0,0,0,0,11,5,5,5,5,5,5,5,5,5,5,0,0,4,11,0,0,0,0
0,43,0,0,0,11,0,0,0,0,0,0,0,0,0,0,0,11,0,43,43,43,0
43,10,43,0,0,0,4,4,0,0,0,0,0,0,0,11,4,0,43,43,43,43,43
0,43,0,0,0,0,0,0,11,4,11,4,4,4,4,0,0,0,43,43,10,43,43
0,0,0,0,0,0,0,0,0,0,0,0,0,0,0,0,0,0,43,43,43,43,43
0,0,0,0,0,0,0,0,0,0,0,0,0,0,0,0,0,0,0,43,43,43,0
:endlayer
layer: 11
0,0,0,0,0,0,0,0,0,0,0,0,0,0,0,0,0,0,0,0,0,0,0
0,0,0,43,0,0,0,0,0,0,0,0,0,0,0,0,0,0,0,0,0,0,0
0,0,43,10,43,0,0,0,0,0,0,0,0,0,0,0,0,0,0,43,0,0,0
0,0,0,43,0,0,0,0,0,0,0,0,0,0,0,0,0,0,43,10,43,0,0
0,0,0,0,0,0,0,0,4,4,4,4,11,4,4,0,0,0,0,43,0,0,0
0,0,0,0,0,0,11,11,0,0,0,51,0,0,0,11,11,0,0,0,0,0,0
0,0,0,0,0,4,0,0,0,0,0,0,0,0,0,0,0,11,0,0,0,0,0
0,0,0,0,11,0,0,0,0,0,0,0,0,0,0,0,0,0,4,0,0,0,0
0,0,0,4,0,0,0,0,0,0,0,0,0,0,0,0,0,0,0,11,0,0,0
0,0,11,0,0,0,0,0,0,0,0,0,0,0,0,0,0,0,0,0,4,0,0
0,0,4,0,0,0,0,0,0,0,0,0,0,0,0,0,0,0,0,0,4,0,0
0,11,57,0,0,0,0,0,0,0,0,0,0,0,0,0,0,0,0,0,0,11,0
0,11,5,55,0,0,0,0,0,0,0,0,0,0,0,0,0,0,0,0,0,4,0
0,11,5,55,0,0,0,0,0,0,0,0,0,0,0,0,0,0,0,0,0,4,0
0,11,0,55,0,0,0,0,0,0,0,0,0,0,0,0,0,0,0,0,0,4,0
0,4,5,55,0,0,0,0,0,0,0,0,0,0,0,0,0,0,0,0,0,11,0
0,4,5,55,0,0,0,0,0,0,0,0,0,0,0,0,0,0,0,0,0,11,0
0,4,56,0,0,0,0,0,0,0,0,0,0,0,0,0,0,0,0,0,0,11,0
0,0,11,0,0,0,0,0,46,0,0,0,46,0,0,0,0,0,0,0,4,0,0
0,0,4,0,0,0,0,0,5,0,0,0,5,0,0,0,0,0,0,0,11,0,0
0,0,0,4,0,0,0,0,0,0,0,14,5,5,5,5,5,5,4,11,0,0,0
43,43,43,0,4,5,5,5,5,5,5,5,5,5,5,0,0,4,11,0,0,0,0
43,43,43,43,0,4,0,0,0,0,0,0,0,0,0,0,0,11,0,0,0,0,0
43,10,43,43,0,0,4,11,0,0,0,0,0,0,0,4,11,0,0,0,43,0,0
43,43,43,43,0,0,0,0,4,11,11,4,11,11,11,0,0,0,0,43,10,43,0
43,43,43,0,0,0,0,0,0,0,0,0,0,0,0,0,0,0,0,0,43,0,0
0,0,0,0,0,0,0,0,0,0,0,0,0,0,0,0,0,0,0,0,0,0,0
:endlayer
layer: 12
0,0,0,0,0,0,0,0,0,0,0,0,0,0,0,0,0,0,0,0,0,0,0
0,0,0,0,0,0,0,0,0,0,0,0,0,0,0,0,0,0,43,43,43,0,0
0,0,0,43,0,0,0,0,0,0,0,0,0,0,0,0,0,43,43,43,43,43,0
0,0,0,0,0,0,0,0,0,0,0,0,0,0,0,0,0,43,43,10,43,43,0
0,0,0,0,0,0,0,0,0,0,0,61,0,0,0,0,0,43,43,43,43,43,0
0,0,0,0,0,0,0,0,4,11,11,11,4,4,11,0,0,0,43,43,43,0,0
0,0,0,0,0,0,11,4,0,0,0,0,0,0,0,11,4,0,0,0,0,0,0
0,0,0,0,0,11,0,0,0,0,0,0,0,0,0,0,0,11,0,0,0,0,0
0,0,0,0,4,0,0,0,0,0,0,0,0,0,0,0,0,0,4,0,0,0,0
0,0,0,11,0,0,0,0,0,0,0,0,0,0,0,0,0,0,0,4,0,0,0
0,0,0,4,0,0,0,0,0,0,0,0,0,0,0,0,0,0,0,4,0,0,0
0,0,11,5,0,0,0,0,0,0,0,0,0,0,0,0,0,0,0,0,11,0,0
0,0,4,0,0,0,0,0,0,0,0,0,0,0,0,0,0,0,0,0,4,0,0
0,60,11,0,0,0,0,0,0,0,0,0,0,0,0,0,0,0,0,0,4,0,0
0,0,0,5,0,0,0,0,0,0,0,0,0,0,0,0,0,0,0,0,4,59,0
0,0,11,0,0,0,0,0,0,0,0,0,0,0,0,0,0,0,0,0,4,0,0
0,0,11,0,0,0,0,0,0,0,0,0,0,0,0,0,0,0,0,0,11,0,0
0,0,4,5,0,0,0,0,0,0,0,0,0,0,0,0,0,0,0,0,11,0,0
0,0,0,11,0,0,0,0,0,0,0,0,0,0,0,0,0,0,0,4,0,0,0
0,0,0,11,0,0,0,0,5,0,0,0,5,0,0,0,0,0,0,11,0,0,0
0,0,0,0,4,0,0,0,0,0,0,0,14,5,5,5,5,5,4,0,0,0,0
0,0,0,0,0,4,5,5,5,5,5,5,5,5,5,5,5,4,0,0,0,0,0
0,43,0,0,0,0,11,11,0,0,0,0,0,0,0,11,5,0,0,43,43,43,0
43,10,43,0,0,0,0,0,11,11,4,4,4,4,11,0,0,0,43,43,43,43,43
0,43,0,0,0,0,0,0,0,0,0,58,0,0,0,0,0,0,43,43,10,43,43
0,0,0,0,0,0,0,0,0,0,0,0,0,0,0,0,0,0,43,43,43,43,43
0,0,0,0,0,0,0,0,0,0,0,0,0,0,0,0,0,0,0,43,43,43,0
:endlayer
layer: 13
0,0,0,0,0,0,0,0,0,0,0,0,0,0,0,0,0,0,0,0,0,0,0
0,0,0,43,0,0,0,0,0,0,0,0,0,0,0,0,0,0,0,0,0,0,0
0,0,43,43,43,0,0,0,0,0,0,0,0,0,0,0,0,0,0,43,0,0,0
0,0,0,43,0,0,0,0,0,0,0,0,0,0,0,0,0,0,43,10,43,0,0
0,0,0,0,0,0,0,0,0,0,0,0,0,0,0,0,0,0,0,43,0,0,0
0,0,0,0,0,0,0,0,4,11,11,11,4,11,4,0,0,0,0,0,0,0,0
0,0,0,0,0,0,4,4,13,11,13,11,13,13,13,4,4,0,0,0,0,0,0
0,0,0,0,0,4,13,11,13,11,13,13,13,13,13,11,13,11,0,0,0,0,0
0,0,0,0,11,13,13,11,13,13,13,13,13,13,13,11,13,13,4,0,0,0,0
0,0,0,11,11,11,13,13,13,13,13,13,13,13,13,13,13,13,13,4,0,0,0
0,0,0,11,13,13,13,13,13,13,13,13,13,13,13,13,13,11,11,4,0,0,0
0,0,4,11,11,13,13,13,13,13,13,13,13,13,13,13,13,13,13,13,4,0,0
0,0,11,13,13,13,13,13,13,13,13,13,13,13,13,13,13,13,11,11,11,0,0
0,0,4,13,13,13,13,13,13,13,13,13,13,13,13,13,13,13,13,13,11,0,0
0,0,0,13,13,13,13,13,13,13,13,13,13,13,13,13,13,13,13,13,4,0,0
0,0,4,13,13,13,13,13,13,13,13,13,13,13,13,13,13,13,11,11,11,0,0
0,0,4,11,11,13,13,13,13,13,13,13,13,13,13,13,13,13,13,13,11,0,0
0,0,11,13,13,13,13,13,13,13,13,13,13,13,13,13,13,13,11,11,4,0,0
0,0,0,4,13,13,13,13,13,13,13,13,13,13,13,13,13,13,13,4,0,0,0
0,0,0,4,11,11,13,13,13,13,13,13,13,13,13,13,13,13,13,11,0,0,0
0,0,0,0,4,13,13,13,0,0,0,0,0,0,5,13,13,13,11,0,0,0,0
0,0,0,0,0,4,13,13,13,13,13,13,13,13,13,13,13,4,0,0,0,0,0
0,0,0,0,0,0,4,4,13,13,13,13,13,13,13,4,11,0,0,0,0,0,0
0,10,0,0,0,0,0,0,11,4,11,11,11,4,11,0,0,0,0,0,43,0,0
0,0,0,0,0,0,0,0,0,0,0,0,0,0,0,0,0,0,0,43,10,43,0
0,0,0,0,0,0,0,0,0,0,0,0,0,0,0,0,0,0,0,0,43,0,0
0,0,0,0,0,0,0,0,0,0,0,0,0,0,0,0,0,0,0,0,0,0,0
:endlayer
layer: 14
0,0,0,0,0,0,0,0,0,0,0,0,0,0,0,0,0,0,0,0,0,0,0
0,0,0,0,0,0,0,0,0,0,0,0,0,0,0,0,0,0,0,0,0,0,0
0,0,0,43,0,0,0,0,0,0,0,0,0,0,0,0,0,0,0,0,0,0,0
0,0,0,0,0,0,0,0,0,0,0,0,0,0,0,0,0,0,0,43,0,0,0
0,0,0,0,0,0,0,0,0,0,0,0,0,0,0,0,0,0,0,0,0,0,0
0,0,0,0,0,0,0,0,4,11,11,11,4,11,11,0,0,0,0,0,0,0,0
0,0,0,0,0,0,11,4,0,72,51,73,51,0,0,11,4,0,0,0,0,0,0
0,0,0,0,0,11,48,72,0,71,0,0,0,0,0,72,47,4,0,0,0,0,0
0,0,0,0,4,51,0,71,0,0,0,0,0,0,0,71,0,51,11,0,0,0,0
0,0,0,4,67,66,0,0,0,0,0,0,0,0,0,0,0,0,0,4,0,0,0
0,0,0,11,0,0,0,70,0,0,0,0,0,0,0,0,69,63,62,11,0,0,0
0,0,11,67,66,0,0,0,0,0,68,0,0,0,0,0,0,0,0,0,11,0,0
0,0,11,0,0,0,0,0,0,0,0,0,0,0,0,0,0,0,63,62,11,0,0
0,0,11,48,0,0,0,0,0,0,0,0,0,0,0,0,0,0,0,0,4,0,0
0,0,11,0,0,0,0,0,0,0,0,0,0,0,0,0,0,0,0,47,4,0,0
0,0,11,48,0,0,0,0,0,0,0,0,0,0,0,0,0,0,63,62,11,0,0
0,0,4,67,66,0,0,0,0,0,0,0,0,0,0,0,0,0,0,0,4,0,0
0,0,4,0,0,0,0,65,0,0,0,0,0,0,0,0,0,64,63,62,11,0,0
0,0,0,11,48,0,0,0,0,0,0,0,0,0,0,0,0,0,47,4,0,0,0
0,0,0,4,0,0,0,0,0,0,0,0,0,0,46,0,0,0,0,4,0,0,0
0,0,0,0,11,0,0,0,0,0,0,0,0,0,5,0,0,0,4,0,0,0,0
0,0,0,0,0,4,0,0,0,0,0,0,0,0,0,0,0,11,0,0,0,0,0
0,43,0,0,0,0,4,11,46,0,0,46,0,0,46,11,4,0,0,0,0,0,0
43,43,43,0,0,0,0,0,4,11,4,4,4,4,11,0,0,0,0,0,0,0,0
0,43,0,0,0,0,0,0,0,0,0,0,0,0,0,0,0,0,0,0,10,0,0
0,0,0,0,0,0,0,0,0,0,0,0,0,0,0,0,0,0,0,0,0,0,0
0,0,0,0,0,0,0,0,0,0,0,0,0,0,0,0,0,0,0,0,0,0,0
:endlayer
layer: 15
0,0,0,0,0,0,0,0,0,0,0,0,0,0,0,0,0,0,0,0,0,0,0
0,0,0,0,0,0,0,0,0,0,0,0,0,0,0,0,0,0,0,0,0,0,0
0,0,0,0,0,0,0,0,0,0,0,0,0,0,0,0,0,0,0,43,0,0,0
0,0,0,0,0,0,0,0,0,0,0,0,0,0,0,0,0,0,43,43,43,0,0
0,0,0,0,0,0,0,0,0,0,0,0,0,0,0,0,0,0,0,43,0,0,0
0,0,0,0,0,0,0,0,11,4,4,11,11,4,4,0,0,0,0,0,0,0,0
0,0,0,0,0,0,11,11,0,0,0,0,0,0,0,4,11,0,0,0,0,0,0
0,0,0,0,0,11,0,0,0,0,0,0,0,0,0,0,0,11,0,0,0,0,0
0,0,0,0,11,0,0,0,0,0,0,0,0,0,0,0,0,0,11,0,0,0,0
0,0,0,4,0,0,0,0,0,0,0,0,0,0,0,0,0,0,0,4,0,0,0
0,0,0,11,0,0,0,0,0,0,0,0,0,0,0,0,0,0,0,11,0,0,0
0,0,4,0,0,0,0,0,0,0,0,0,0,0,0,0,0,0,0,0,4,0,0
0,0,4,0,0,0,0,0,0,0,0,0,0,0,0,0,0,0,0,0,4,0,0
0,0,11,0,0,0,0,0,0,0,0,0,0,0,0,0,0,0,0,0,4,0,0
0,0,4,0,0,0,0,0,0,0,0,0,0,0,0,0,0,0,0,0,11,0,0
0,0,4,0,0,0,0,0,0,0,0,0,0,0,0,0,0,0,0,0,11,0,0
0,0,11,0,0,0,0,0,0,0,0,0,0,0,0,0,0,0,0,0,4,0,0
0,0,4,0,0,0,0,0,0,0,0,0,0,0,0,0,0,0,0,0,11,0,0
0,0,0,4,0,0,0,0,0,0,0,0,0,0,0,0,0,0,0,4,0,0,0
0,0,0,4,0,0,0,0,0,0,0,0,0,0,0,0,0,0,0,11,0,0,0
0,0,0,0,4,0,0,0,0,0,0,0,0,0,5,0,0,0,4,0,0,0,0
0,0,0,0,0,11,0,0,0,0,0,0,0,0,0,0,0,11,0,0,0,0,0
0,0,0,0,0,0,11,4,0,0,0,0,0,0,0,11,11,0,0,0,0,0,0
0,43,0,0,0,0,0,0,11,11,11,11,11,4,11,0,0,0,0,0,43,0,0
0,0,0,0,0,0,0,0,0,0,0,0,0,0,0,0,0,0,0,43,43,43,0
0,0,0,0,0,0,0,0,0,0,0,0,0,0,0,0,0,0,0,0,43,0,0
0,0,0,0,0,0,0,0,0,0,0,0,0,0,0,0,0,0,0,0,0,0,0
:endlayer
layer: 16
0,0,0,0,0,0,0,0,0,0,0,0,0,0,0,0,0,0,0,0,0,0,0
0,0,0,0,0,0,0,0,0,0,0,0,0,0,0,0,0,0,0,0,0,0,0
0,0,0,0,0,0,0,0,0,0,0,0,0,0,0,0,0,0,0,0,0,0,0
0,0,0,0,0,0,0,0,0,0,0,0,0,0,0,0,0,0,0,43,0,0,0
0,0,0,0,0,0,0,0,0,0,0,0,0,0,0,0,0,0,0,0,0,0,0
0,0,0,0,0,0,0,0,0,0,0,0,0,0,0,0,0,0,0,0,0,0,0
0,0,0,0,0,0,0,0,11,11,4,11,4,11,11,0,0,0,0,0,0,0,0
0,0,0,0,0,0,4,4,4,4,4,4,11,11,4,4,4,0,0,0,0,0,0
0,0,0,0,0,4,11,4,4,11,11,4,11,4,11,4,4,4,0,0,0,0,0
0,0,0,0,11,11,4,4,4,11,11,11,11,11,4,4,4,11,4,0,0,0,0
0,0,0,0,4,11,11,11,11,11,4,11,11,4,4,4,11,11,4,0,0,0,0
0,0,0,4,4,4,11,4,4,4,11,11,11,11,4,4,11,4,11,11,0,0,0
0,0,0,11,4,4,11,4,11,11,4,4,4,11,4,11,11,11,11,11,0,0,0
0,0,0,11,11,11,11,4,4,11,4,4,4,4,11,11,11,4,4,4,0,0,0
0,0,0,11,4,4,4,11,11,4,11,11,4,4,11,11,11,4,11,4,0,0,0
0,0,0,4,11,11,11,4,4,4,4,4,11,4,11,11,11,4,11,11,0,0,0
0,0,0,4,11,4,11,4,11,11,11,4,4,4,4,4,4,4,4,11,0,0,0
0,0,0,11,11,11,4,11,4,11,4,4,4,11,11,11,11,11,4,11,0,0,0
0,0,0,0,4,11,11,4,4,4,11,11,11,11,11,4,11,4,4,0,0,0,0
0,0,0,0,4,4,4,4,4,4,11,4,11,4,11,4,11,4,11,0,0,0,0
0,0,0,0,0,4,11,11,4,11,4,11,4,11,11,11,4,11,0,0,0,0,0
0,0,0,0,0,0,4,4,11,4,4,11,11,4,4,4,4,0,0,0,0,0,0
0,0,0,0,0,0,0,0,11,4,11,4,11,11,4,0,0,0,0,0,0,0,0
0,0,0,0,0,0,0,0,0,0,0,0,0,0,0,0,0,0,0,0,0,0,0
0,0,0,0,0,0,0,0,0,0,0,0,0,0,0,0,0,0,0,0,43,0,0
0,0,0,0,0,0,0,0,0,0,0,0,0,0,0,0,0,0,0,0,0,0,0
0,0,0,0,0,0,0,0,0,0,0,0,0,0,0,0,0,0,0,0,0,0,0
:endlayer
layer: 17
0,0,0,0,0,0,0,0,0,0,0,0,0,0,0,0,0,0,0,0,0,0,0
0,0,0,0,0,0,0,0,0,0,0,0,0,0,0,0,0,0,0,0,0,0,0
0,0,0,0,0,0,0,0,0,0,0,0,0,0,0,0,0,0,0,0,0,0,0
0,0,0,0,0,0,0,0,0,0,0,0,0,0,0,0,0,0,0,0,0,0,0
0,0,0,0,0,0,0,0,0,0,0,0,0,0,0,0,0,0,0,0,0,0,0
0,0,0,0,0,0,0,0,0,0,0,0,0,0,0,0,0,0,0,0,0,0,0
0,0,0,0,0,0,0,0,0,0,0,0,0,0,0,0,0,0,0,0,0,0,0
0,0,0,0,0,0,0,0,0,11,11,11,11,11,0,0,0,0,0,0,0,0,0
0,0,0,0,0,0,0,11,11,11,11,4,4,11,11,4,0,0,0,0,0,0,0
0,0,0,0,0,0,11,11,4,2,2,2,2,2,11,11,4,0,0,0,0,0,0
0,0,0,0,0,11,11,2,2,2,2,2,2,2,2,2,4,11,0,0,0,0,0
0,0,0,0,0,11,4,2,1,2,2,2,2,2,2,2,4,4,0,0,0,0,0
0,0,0,0,4,4,2,2,2,2,2,2,2,2,1,1,2,4,11,0,0,0,0
0,0,0,0,4,4,2,2,2,2,1,1,1,2,1,1,1,4,11,0,0,0,0
0,0,0,0,11,4,2,2,2,2,1,1,1,1,1,1,1,4,4,0,0,0,0
0,0,0,0,11,11,2,2,1,1,1,1,1,1,2,1,1,4,11,0,0,0,0
0,0,0,0,11,11,1,1,1,1,1,1,1,2,2,2,1,11,11,0,0,0,0
0,0,0,0,0,4,4,1,1,1,1,2,2,2,2,2,4,11,0,0,0,0,0
0,0,0,0,0,4,4,1,1,1,2,2,2,2,2,2,11,4,0,0,0,0,0
0,0,0,0,0,0,11,11,11,1,2,2,2,2,4,11,11,0,0,0,0,0,0
0,0,0,0,0,0,0,11,11,4,4,11,11,11,11,11,0,0,0,0,0,0,0
0,0,0,0,0,0,0,0,0,4,11,4,4,4,0,0,0,0,0,0,0,0,0
0,0,0,0,0,0,0,0,0,0,0,0,0,0,0,0,0,0,0,0,0,0,0
0,0,0,0,0,0,0,0,0,0,0,0,0,0,0,0,0,0,0,0,0,0,0
0,0,0,0,0,0,0,0,0,0,0,0,0,0,0,0,0,0,0,0,0,0,0
0,0,0,0,0,0,0,0,0,0,0,0,0,0,0,0,0,0,0,0,0,0,0
0,0,0,0,0,0,0,0,0,0,0,0,0,0,0,0,0,0,0,0,0,0,0
:endlayer
layer: 18
0,0,0,0,0,0,0,0,0,0,0,0,0,0,0,0,0,0,0,0,0,0,0
0,0,0,0,0,0,0,0,0,0,0,0,0,0,0,0,0,0,0,0,0,0,0
0,0,0,0,0,0,0,0,0,0,0,0,0,0,0,0,0,0,0,0,0,0,0
0,0,0,0,0,0,0,0,0,0,0,0,0,0,0,0,0,0,0,0,0,0,0
0,0,0,0,0,0,0,0,0,0,0,0,0,0,0,0,0,0,0,0,0,0,0
0,0,0,0,0,0,0,0,0,0,0,0,0,0,0,0,0,0,0,0,0,0,0
0,0,0,0,0,0,0,0,0,0,0,0,0,0,0,0,0,0,0,0,0,0,0
0,0,0,0,0,0,0,0,0,0,0,0,0,0,0,0,0,0,0,0,0,0,0
0,0,0,0,0,0,0,0,0,4,11,11,11,11,0,0,0,0,0,0,0,0,0
0,0,0,0,0,0,0,4,11,0,0,0,0,0,4,4,0,0,0,0,0,0,0
0,0,0,0,0,0,11,0,0,0,0,0,0,0,0,0,4,0,0,0,0,0,0
0,0,0,0,0,0,4,0,10,0,0,0,0,0,0,0,4,0,0,0,0,0,0
0,0,0,0,0,11,0,0,0,0,0,0,0,0,2,2,0,4,0,0,0,0,0
0,0,0,0,0,4,0,0,0,0,4,11,11,0,2,2,2,11,0,0,0,0,0
0,0,0,0,0,11,0,0,0,0,11,4,11,4,2,1,2,11,0,0,0,0,0
0,0,0,0,0,11,0,0,2,2,11,11,4,4,0,2,2,4,0,0,0,0,0
0,0,0,0,0,11,2,2,2,2,2,4,11,0,0,0,2,11,0,0,0,0,0
0,0,0,0,0,0,11,2,1,2,2,0,0,0,0,0,11,0,0,0,0,0,0
0,0,0,0,0,0,11,2,2,2,0,0,0,0,0,0,11,0,0,0,0,0,0
0,0,0,0,0,0,0,11,11,2,0,0,0,0,4,11,0,0,0,0,0,0,0
0,0,0,0,0,0,0,0,0,11,11,4,11,4,0,0,0,0,0,0,0,0,0
0,0,0,0,0,0,0,0,0,0,0,0,0,0,0,0,0,0,0,0,0,0,0
0,0,0,0,0,0,0,0,0,0,0,0,0,0,0,0,0,0,0,0,0,0,0
0,0,0,0,0,0,0,0,0,0,0,0,0,0,0,0,0,0,0,0,0,0,0
0,0,0,0,0,0,0,0,0,0,0,0,0,0,0,0,0,0,0,0,0,0,0
0,0,0,0,0,0,0,0,0,0,0,0,0,0,0,0,0,0,0,0,0,0,0
0,0,0,0,0,0,0,0,0,0,0,0,0,0,0,0,0,0,0,0,0,0,0
:endlayer
layer: 19
0,0,0,0,0,0,0,0,0,0,0,0,0,0,0,0,0,0,0,0,0,0,0
0,0,0,0,0,0,0,0,0,0,0,0,0,0,0,0,0,0,0,0,0,0,0
0,0,0,0,0,0,0,0,0,0,0,0,0,0,0,0,0,0,0,0,0,0,0
0,0,0,0,0,0,0,0,0,0,0,0,0,0,0,0,0,0,0,0,0,0,0
0,0,0,0,0,0,0,0,0,0,0,0,0,0,0,0,0,0,0,0,0,0,0
0,0,0,0,0,0,0,0,0,0,0,0,0,0,0,0,0,0,0,0,0,0,0
0,0,0,0,0,0,0,0,0,0,0,0,0,0,0,0,0,0,0,0,0,0,0
0,0,0,0,0,0,0,0,0,0,0,0,0,0,0,0,0,0,0,0,0,0,0
0,0,0,0,0,0,0,0,0,0,4,77,4,0,0,0,0,0,0,0,0,0,0
0,0,0,0,0,0,0,0,4,0,0,0,0,0,11,0,0,0,0,0,0,0,0
0,0,0,0,0,0,11,0,0,0,0,0,0,0,0,0,11,0,0,0,0,0,0
0,0,0,0,0,0,0,0,10,0,0,0,0,0,0,0,0,0,0,0,0,0,0
0,0,0,0,0,11,0,0,0,0,0,0,0,0,0,0,0,11,0,0,0,0,0
0,0,0,0,0,76,0,0,0,0,0,0,0,0,0,0,0,75,0,0,0,0,0
0,0,0,0,0,4,0,0,0,0,0,11,11,0,0,10,0,11,0,0,0,0,0
0,0,0,0,0,0,0,0,0,0,0,11,4,0,0,0,0,0,0,0,0,0,0
0,0,0,0,0,11,0,0,0,0,0,0,0,0,0,0,0,11,0,0,0,0,0
0,0,0,0,0,0,11,0,10,0,0,0,0,0,0,0,0,0,0,0,0,0,0
0,0,0,0,0,0,0,0,0,0,0,0,0,0,0,0,11,0,0,0,0,0,0
0,0,0,0,0,0,0,0,4,0,0,0,0,0,11,0,0,0,0,0,0,0,0
0,0,0,0,0,0,0,0,0,0,11,0,11,74,0,0,0,0,0,0,0,0,0
0,0,0,0,0,0,0,0,0,0,0,0,0,0,0,0,0,0,0,0,0,0,0
0,0,0,0,0,0,0,0,0,0,0,0,0,0,0,0,0,0,0,0,0,0,0
0,0,0,0,0,0,0,0,0,0,0,0,0,0,0,0,0,0,0,0,0,0,0
0,0,0,0,0,0,0,0,0,0,0,0,0,0,0,0,0,0,0,0,0,0,0
0,0,0,0,0,0,0,0,0,0,0,0,0,0,0,0,0,0,0,0,0,0,0
0,0,0,0,0,0,0,0,0,0,0,0,0,0,0,0,0,0,0,0,0,0,0
:endlayer
layer: 20
0,0,0,0,0,0,0,0,0,0,0,0,0,0,0,0,0,0,0,0,0,0,0
0,0,0,0,0,0,0,0,0,0,0,0,0,0,0,0,0,0,0,0,0,0,0
0,0,0,0,0,0,0,0,0,0,0,0,0,0,0,0,0,0,0,0,0,0,0
0,0,0,0,0,0,0,0,0,0,0,0,0,0,0,0,0,0,0,0,0,0,0
0,0,0,0,0,0,0,0,0,0,0,0,0,0,0,0,0,0,0,0,0,0,0
0,0,0,0,0,0,0,0,0,0,0,0,0,0,0,0,0,0,0,0,0,0,0
0,0,0,0,0,0,0,0,0,0,0,0,0,0,0,0,0,0,0,0,0,0,0
0,0,0,0,0,0,0,0,0,0,0,0,0,0,0,0,0,0,0,0,0,0,0
0,0,0,0,0,0,0,0,0,0,0,0,0,0,0,0,0,0,0,0,0,0,0
0,0,0,0,0,0,0,0,0,0,0,0,0,0,0,0,0,0,0,0,0,0,0
0,0,0,0,0,0,0,0,43,0,0,0,0,0,0,0,0,0,0,0,0,0,0
0,0,0,0,0,0,0,43,10,43,0,0,0,0,0,0,0,0,0,0,0,0,0
0,0,0,0,0,0,0,0,43,0,0,0,0,0,0,0,0,0,0,0,0,0,0
0,0,0,0,0,0,0,0,0,0,0,0,0,0,0,0,0,0,0,0,0,0,0
0,0,0,0,0,0,43,43,43,43,43,0,0,0,0,10,0,0,0,0,0,0,0
0,0,0,0,0,43,43,43,43,43,43,43,0,0,0,0,0,0,0,0,0,0,0
0,0,0,0,0,43,43,43,43,43,43,43,0,0,0,0,0,0,0,0,0,0,0
0,0,0,0,0,43,43,43,10,43,43,43,0,0,0,0,0,0,0,0,0,0,0
0,0,0,0,0,43,43,43,43,43,43,43,0,0,0,0,0,0,0,0,0,0,0
0,0,0,0,0,43,43,43,43,43,43,43,0,0,0,0,0,0,0,0,0,0,0
0,0,0,0,0,0,43,43,43,43,43,0,0,0,0,0,0,0,0,0,0,0,0
0,0,0,0,0,0,0,0,0,0,0,0,0,0,0,0,0,0,0,0,0,0,0
0,0,0,0,0,0,0,0,0,0,0,0,0,0,0,0,0,0,0,0,0,0,0
0,0,0,0,0,0,0,0,0,0,0,0,0,0,0,0,0,0,0,0,0,0,0
0,0,0,0,0,0,0,0,0,0,0,0,0,0,0,0,0,0,0,0,0,0,0
0,0,0,0,0,0,0,0,0,0,0,0,0,0,0,0,0,0,0,0,0,0,0
0,0,0,0,0,0,0,0,0,0,0,0,0,0,0,0,0,0,0,0,0,0,0
:endlayer
layer: 21
0,0,0,0,0,0,0,0,0,0,0,0,0,0,0,0,0,0,0,0,0,0,0
0,0,0,0,0,0,0,0,0,0,0,0,0,0,0,0,0,0,0,0,0,0,0
0,0,0,0,0,0,0,0,0,0,0,0,0,0,0,0,0,0,0,0,0,0,0
0,0,0,0,0,0,0,0,0,0,0,0,0,0,0,0,0,0,0,0,0,0,0
0,0,0,0,0,0,0,0,0,0,0,0,0,0,0,0,0,0,0,0,0,0,0
0,0,0,0,0,0,0,0,0,0,0,0,0,0,0,0,0,0,0,0,0,0,0
0,0,0,0,0,0,0,0,0,0,0,0,0,0,0,0,0,0,0,0,0,0,0
0,0,0,0,0,0,0,0,0,0,0,0,0,0,0,0,0,0,0,0,0,0,0
0,0,0,0,0,0,0,0,0,0,0,0,0,0,0,0,0,0,0,0,0,0,0
0,0,0,0,0,0,0,43,43,43,0,0,0,0,0,0,0,0,0,0,0,0,0
0,0,0,0,0,0,43,43,43,43,43,0,0,0,0,0,0,0,0,0,0,0,0
0,0,0,0,0,0,43,43,10,43,43,0,0,0,0,0,0,0,0,0,0,0,0
0,0,0,0,0,0,43,43,43,43,43,0,0,0,43,43,43,0,0,0,0,0,0
0,0,0,0,0,0,0,43,43,43,0,0,0,43,43,43,43,43,0,0,0,0,0
0,0,0,0,0,0,0,0,0,0,0,0,0,43,43,10,43,43,0,0,0,0,0
0,0,0,0,0,0,0,43,43,43,0,0,0,43,43,43,43,43,0,0,0,0,0
0,0,0,0,0,0,43,43,43,43,43,0,0,0,43,43,43,0,0,0,0,0,0
0,0,0,0,0,0,43,43,10,43,43,0,0,0,0,0,0,0,0,0,0,0,0
0,0,0,0,0,0,43,43,43,43,43,0,0,0,0,0,0,0,0,0,0,0,0
0,0,0,0,0,0,0,43,43,43,0,0,0,0,0,0,0,0,0,0,0,0,0
0,0,0,0,0,0,0,0,0,0,0,0,0,0,0,0,0,0,0,0,0,0,0
0,0,0,0,0,0,0,0,0,0,0,0,0,0,0,0,0,0,0,0,0,0,0
0,0,0,0,0,0,0,0,0,0,0,0,0,0,0,0,0,0,0,0,0,0,0
0,0,0,0,0,0,0,0,0,0,0,0,0,0,0,0,0,0,0,0,0,0,0
0,0,0,0,0,0,0,0,0,0,0,0,0,0,0,0,0,0,0,0,0,0,0
0,0,0,0,0,0,0,0,0,0,0,0,0,0,0,0,0,0,0,0,0,0,0
0,0,0,0,0,0,0,0,0,0,0,0,0,0,0,0,0,0,0,0,0,0,0
:endlayer
layer: 22
0,0,0,0,0,0,0,0,0,0,0,0,0,0,0,0,0,0,0,0,0,0,0
0,0,0,0,0,0,0,0,0,0,0,0,0,0,0,0,0,0,0,0,0,0,0
0,0,0,0,0,0,0,0,0,0,0,0,0,0,0,0,0,0,0,0,0,0,0
0,0,0,0,0,0,0,0,0,0,0,0,0,0,0,0,0,0,0,0,0,0,0
0,0,0,0,0,0,0,0,0,0,0,0,0,0,0,0,0,0,0,0,0,0,0
0,0,0,0,0,0,0,0,0,0,0,0,0,0,0,0,0,0,0,0,0,0,0
0,0,0,0,0,0,0,0,0,0,0,0,0,0,0,0,0,0,0,0,0,0,0
0,0,0,0,0,0,0,0,0,0,0,0,0,0,0,0,0,0,0,0,0,0,0
0,0,0,0,0,0,0,0,0,0,0,0,0,0,0,0,0,0,0,0,0,0,0
0,0,0,0,0,0,0,0,0,0,0,0,0,0,0,0,0,0,0,0,0,0,0
0,0,0,0,0,0,0,0,43,0,0,0,0,0,0,0,0,0,0,0,0,0,0
0,0,0,0,0,0,0,43,10,43,0,0,0,0,0,0,0,0,0,0,0,0,0
0,0,0,0,0,0,0,0,43,0,0,0,0,0,0,0,0,0,0,0,0,0,0
0,0,0,0,0,0,0,0,0,0,0,0,0,0,0,43,0,0,0,0,0,0,0
0,0,0,0,0,0,0,0,0,0,0,0,0,0,43,10,43,0,0,0,0,0,0
0,0,0,0,0,0,0,0,0,0,0,0,0,0,0,43,0,0,0,0,0,0,0
0,0,0,0,0,0,0,0,43,0,0,0,0,0,0,0,0,0,0,0,0,0,0
0,0,0,0,0,0,0,43,10,43,0,0,0,0,0,0,0,0,0,0,0,0,0
0,0,0,0,0,0,0,0,43,0,0,0,0,0,0,0,0,0,0,0,0,0,0
0,0,0,0,0,0,0,0,0,0,0,0,0,0,0,0,0,0,0,0,0,0,0
0,0,0,0,0,0,0,0,0,0,0,0,0,0,0,0,0,0,0,0,0,0,0
0,0,0,0,0,0,0,0,0,0,0,0,0,0,0,0,0,0,0,0,0,0,0
0,0,0,0,0,0,0,0,0,0,0,0,0,0,0,0,0,0,0,0,0,0,0
0,0,0,0,0,0,0,0,0,0,0,0,0,0,0,0,0,0,0,0,0,0,0
0,0,0,0,0,0,0,0,0,0,0,0,0,0,0,0,0,0,0,0,0,0,0
0,0,0,0,0,0,0,0,0,0,0,0,0,0,0,0,0,0,0,0,0,0,0
0,0,0,0,0,0,0,0,0,0,0,0,0,0,0,0,0,0,0,0,0,0,0
:endlayer
layer: 23
0,0,0,0,0,0,0,0,0,0,0,0,0,0,0,0,0,0,0,0,0,0,0
0,0,0,0,0,0,0,0,0,0,0,0,0,0,0,0,0,0,0,0,0,0,0
0,0,0,0,0,0,0,0,0,0,0,0,0,0,0,0,0,0,0,0,0,0,0
0,0,0,0,0,0,0,0,0,0,0,0,0,0,0,0,0,0,0,0,0,0,0
0,0,0,0,0,0,0,0,0,0,0,0,0,0,0,0,0,0,0,0,0,0,0
0,0,0,0,0,0,0,0,0,0,0,0,0,0,0,0,0,0,0,0,0,0,0
0,0,0,0,0,0,0,0,0,0,0,0,0,0,0,0,0,0,0,0,0,0,0
0,0,0,0,0,0,0,0,0,0,0,0,0,0,0,0,0,0,0,0,0,0,0
0,0,0,0,0,0,0,0,0,0,0,0,0,0,0,0,0,0,0,0,0,0,0
0,0,0,0,0,0,0,43,43,43,0,0,0,0,0,0,0,0,0,0,0,0,0
0,0,0,0,0,0,43,43,43,43,43,0,0,0,0,0,0,0,0,0,0,0,0
0,0,0,0,0,0,43,43,10,43,43,0,0,0,0,0,0,0,0,0,0,0,0
0,0,0,0,0,0,43,43,43,43,43,0,0,0,43,43,43,0,0,0,0,0,0
0,0,0,0,0,0,0,43,43,43,0,0,0,43,43,43,43,43,0,0,0,0,0
0,0,0,0,0,0,0,0,0,0,0,0,0,43,43,10,43,43,0,0,0,0,0
0,0,0,0,0,0,0,43,43,43,0,0,0,43,43,43,43,43,0,0,0,0,0
0,0,0,0,0,0,43,43,43,43,43,0,0,0,43,43,43,0,0,0,0,0,0
0,0,0,0,0,0,43,43,10,43,43,0,0,0,0,0,0,0,0,0,0,0,0
0,0,0,0,0,0,43,43,43,43,43,0,0,0,0,0,0,0,0,0,0,0,0
0,0,0,0,0,0,0,43,43,43,0,0,0,0,0,0,0,0,0,0,0,0,0
0,0,0,0,0,0,0,0,0,0,0,0,0,0,0,0,0,0,0,0,0,0,0
0,0,0,0,0,0,0,0,0,0,0,0,0,0,0,0,0,0,0,0,0,0,0
0,0,0,0,0,0,0,0,0,0,0,0,0,0,0,0,0,0,0,0,0,0,0
0,0,0,0,0,0,0,0,0,0,0,0,0,0,0,0,0,0,0,0,0,0,0
0,0,0,0,0,0,0,0,0,0,0,0,0,0,0,0,0,0,0,0,0,0,0
0,0,0,0,0,0,0,0,0,0,0,0,0,0,0,0,0,0,0,0,0,0,0
0,0,0,0,0,0,0,0,0,0,0,0,0,0,0,0,0,0,0,0,0,0,0
:endlayer
layer: 24
0,0,0,0,0,0,0,0,0,0,0,0,0,0,0,0,0,0,0,0,0,0,0
0,0,0,0,0,0,0,0,0,0,0,0,0,0,0,0,0,0,0,0,0,0,0
0,0,0,0,0,0,0,0,0,0,0,0,0,0,0,0,0,0,0,0,0,0,0
0,0,0,0,0,0,0,0,0,0,0,0,0,0,0,0,0,0,0,0,0,0,0
0,0,0,0,0,0,0,0,0,0,0,0,0,0,0,0,0,0,0,0,0,0,0
0,0,0,0,0,0,0,0,0,0,0,0,0,0,0,0,0,0,0,0,0,0,0
0,0,0,0,0,0,0,0,0,0,0,0,0,0,0,0,0,0,0,0,0,0,0
0,0,0,0,0,0,0,0,0,0,0,0,0,0,0,0,0,0,0,0,0,0,0
0,0,0,0,0,0,0,0,0,0,0,0,0,0,0,0,0,0,0,0,0,0,0
0,0,0,0,0,0,0,0,0,0,0,0,0,0,0,0,0,0,0,0,0,0,0
0,0,0,0,0,0,0,0,43,0,0,0,0,0,0,0,0,0,0,0,0,0,0
0,0,0,0,0,0,0,43,10,43,0,0,0,0,0,0,0,0,0,0,0,0,0
0,0,0,0,0,0,0,0,43,0,0,0,0,0,0,0,0,0,0,0,0,0,0
0,0,0,0,0,0,0,0,0,0,0,0,0,0,0,43,0,0,0,0,0,0,0
0,0,0,0,0,0,0,0,0,0,0,0,0,0,43,10,43,0,0,0,0,0,0
0,0,0,0,0,0,0,0,0,0,0,0,0,0,0,43,0,0,0,0,0,0,0
0,0,0,0,0,0,0,0,43,0,0,0,0,0,0,0,0,0,0,0,0,0,0
0,0,0,0,0,0,0,43,43,43,0,0,0,0,0,0,0,0,0,0,0,0,0
0,0,0,0,0,0,0,0,43,0,0,0,0,0,0,0,0,0,0,0,0,0,0
0,0,0,0,0,0,0,0,0,0,0,0,0,0,0,0,0,0,0,0,0,0,0
0,0,0,0,0,0,0,0,0,0,0,0,0,0,0,0,0,0,0,0,0,0,0
0,0,0,0,0,0,0,0,0,0,0,0,0,0,0,0,0,0,0,0,0,0,0
0,0,0,0,0,0,0,0,0,0,0,0,0,0,0,0,0,0,0,0,0,0,0
0,0,0,0,0,0,0,0,0,0,0,0,0,0,0,0,0,0,0,0,0,0,0
0,0,0,0,0,0,0,0,0,0,0,0,0,0,0,0,0,0,0,0,0,0,0
0,0,0,0,0,0,0,0,0,0,0,0,0,0,0,0,0,0,0,0,0,0,0
0,0,0,0,0,0,0,0,0,0,0,0,0,0,0,0,0,0,0,0,0,0,0
:endlayer
layer: 25
0,0,0,0,0,0,0,0,0,0,0,0,0,0,0,0,0,0,0,0,0,0,0
0,0,0,0,0,0,0,0,0,0,0,0,0,0,0,0,0,0,0,0,0,0,0
0,0,0,0,0,0,0,0,0,0,0,0,0,0,0,0,0,0,0,0,0,0,0
0,0,0,0,0,0,0,0,0,0,0,0,0,0,0,0,0,0,0,0,0,0,0
0,0,0,0,0,0,0,0,0,0,0,0,0,0,0,0,0,0,0,0,0,0,0
0,0,0,0,0,0,0,0,0,0,0,0,0,0,0,0,0,0,0,0,0,0,0
0,0,0,0,0,0,0,0,0,0,0,0,0,0,0,0,0,0,0,0,0,0,0
0,0,0,0,0,0,0,0,0,0,0,0,0,0,0,0,0,0,0,0,0,0,0
0,0,0,0,0,0,0,0,0,0,0,0,0,0,0,0,0,0,0,0,0,0,0
0,0,0,0,0,0,0,0,0,0,0,0,0,0,0,0,0,0,0,0,0,0,0
0,0,0,0,0,0,0,0,0,0,0,0,0,0,0,0,0,0,0,0,0,0,0
0,0,0,0,0,0,0,0,43,0,0,0,0,0,0,0,0,0,0,0,0,0,0
0,0,0,0,0,0,0,0,0,0,0,0,0,0,0,0,0,0,0,0,0,0,0
0,0,0,0,0,0,0,0,0,0,0,0,0,0,0,0,0,0,0,0,0,0,0
0,0,0,0,0,0,0,0,0,0,0,0,0,0,0,43,0,0,0,0,0,0,0
0,0,0,0,0,0,0,0,0,0,0,0,0,0,0,0,0,0,0,0,0,0,0
0,0,0,0,0,0,0,0,0,0,0,0,0,0,0,0,0,0,0,0,0,0,0
0,0,0,0,0,0,0,0,43,0,0,0,0,0,0,0,0,0,0,0,0,0,0
0,0,0,0,0,0,0,0,0,0,0,0,0,0,0,0,0,0,0,0,0,0,0
0,0,0,0,0,0,0,0,0,0,0,0,0,0,0,0,0,0,0,0,0,0,0
0,0,0,0,0,0,0,0,0,0,0,0,0,0,0,0,0,0,0,0,0,0,0
0,0,0,0,0,0,0,0,0,0,0,0,0,0,0,0,0,0,0,0,0,0,0
0,0,0,0,0,0,0,0,0,0,0,0,0,0,0,0,0,0,0,0,0,0,0
0,0,0,0,0,0,0,0,0,0,0,0,0,0,0,0,0,0,0,0,0,0,0
0,0,0,0,0,0,0,0,0,0,0,0,0,0,0,0,0,0,0,0,0,0,0
0,0,0,0,0,0,0,0,0,0,0,0,0,0,0,0,0,0,0,0,0,0,0
0,0,0,0,0,0,0,0,0,0,0,0,0,0,0,0,0,0,0,0,0,0,0
:endlayer
layer: 26
0,0,0,0,0,0,0,0,0,0,0,0,0,0,0,0,0,0,0,0,0,0,0
0,0,0,0,0,0,0,0,0,0,0,0,0,0,0,0,0,0,0,0,0,0,0
0,0,0,0,0,0,0,0,0,0,0,0,0,0,0,0,0,0,0,0,0,0,0
0,0,0,0,0,0,0,0,0,0,0,0,0,0,0,0,0,0,0,0,0,0,0
0,0,0,0,0,0,0,0,0,0,0,0,0,0,0,0,0,0,0,0,0,0,0
0,0,0,0,0,0,0,0,0,0,0,0,0,0,0,0,0,0,0,0,0,0,0
0,0,0,0,0,0,0,0,0,0,0,0,0,0,0,0,0,0,0,0,0,0,0
0,0,0,0,0,0,0,0,0,0,0,0,0,0,0,0,0,0,0,0,0,0,0
0,0,0,0,0,0,0,0,0,0,0,0,0,0,0,0,0,0,0,0,0,0,0
0,0,0,0,0,0,0,0,0,0,0,0,0,0,0,0,0,0,0,0,0,0,0
0,0,0,0,0,0,0,0,43,0,0,0,0,0,0,0,0,0,0,0,0,0,0
0,0,0,0,0,0,0,43,43,43,0,0,0,0,0,0,0,0,0,0,0,0,0
0,0,0,0,0,0,0,0,43,0,0,0,0,0,0,0,0,0,0,0,0,0,0
0,0,0,0,0,0,0,0,0,0,0,0,0,0,0,43,0,0,0,0,0,0,0
0,0,0,0,0,0,0,0,0,0,0,0,0,0,43,43,43,0,0,0,0,0,0
0,0,0,0,0,0,0,0,0,0,0,0,0,0,0,43,0,0,0,0,0,0,0
0,0,0,0,0,0,0,0,43,0,0,0,0,0,0,0,0,0,0,0,0,0,0
0,0,0,0,0,0,0,43,43,43,0,0,0,0,0,0,0,0,0,0,0,0,0
0,0,0,0,0,0,0,0,43,0,0,0,0,0,0,0,0,0,0,0,0,0,0
0,0,0,0,0,0,0,0,0,0,0,0,0,0,0,0,0,0,0,0,0,0,0
0,0,0,0,0,0,0,0,0,0,0,0,0,0,0,0,0,0,0,0,0,0,0
0,0,0,0,0,0,0,0,0,0,0,0,0,0,0,0,0,0,0,0,0,0,0
0,0,0,0,0,0,0,0,0,0,0,0,0,0,0,0,0,0,0,0,0,0,0
0,0,0,0,0,0,0,0,0,0,0,0,0,0,0,0,0,0,0,0,0,0,0
0,0,0,0,0,0,0,0,0,0,0,0,0,0,0,0,0,0,0,0,0,0,0
0,0,0,0,0,0,0,0,0,0,0,0,0,0,0,0,0,0,0,0,0,0,0
0,0,0,0,0,0,0,0,0,0,0,0,0,0,0,0,0,0,0,0,0,0,0
:endlayer
layer: 27
0,0,0,0,0,0,0,0,0,0,0,0,0,0,0,0,0,0,0,0,0,0,0
0,0,0,0,0,0,0,0,0,0,0,0,0,0,0,0,0,0,0,0,0,0,0
0,0,0,0,0,0,0,0,0,0,0,0,0,0,0,0,0,0,0,0,0,0,0
0,0,0,0,0,0,0,0,0,0,0,0,0,0,0,0,0,0,0,0,0,0,0
0,0,0,0,0,0,0,0,0,0,0,0,0,0,0,0,0,0,0,0,0,0,0
0,0,0,0,0,0,0,0,0,0,0,0,0,0,0,0,0,0,0,0,0,0,0
0,0,0,0,0,0,0,0,0,0,0,0,0,0,0,0,0,0,0,0,0,0,0
0,0,0,0,0,0,0,0,0,0,0,0,0,0,0,0,0,0,0,0,0,0,0
0,0,0,0,0,0,0,0,0,0,0,0,0,0,0,0,0,0,0,0,0,0,0
0,0,0,0,0,0,0,0,0,0,0,0,0,0,0,0,0,0,0,0,0,0,0
0,0,0,0,0,0,0,0,0,0,0,0,0,0,0,0,0,0,0,0,0,0,0
0,0,0,0,0,0,0,0,0,0,0,0,0,0,0,0,0,0,0,0,0,0,0
0,0,0,0,0,0,0,0,0,0,0,0,0,0,0,0,0,0,0,0,0,0,0
0,0,0,0,0,0,0,0,0,0,0,0,0,0,0,0,0,0,0,0,0,0,0
0,0,0,0,0,0,0,0,0,0,0,0,0,0,0,43,0,0,0,0,0,0,0
0,0,0,0,0,0,0,0,0,0,0,0,0,0,0,0,0,0,0,0,0,0,0
0,0,0,0,0,0,0,0,0,0,0,0,0,0,0,0,0,0,0,0,0,0,0
0,0,0,0,0,0,0,0,0,0,0,0,0,0,0,0,0,0,0,0,0,0,0
0,0,0,0,0,0,0,0,0,0,0,0,0,0,0,0,0,0,0,0,0,0,0
0,0,0,0,0,0,0,0,0,0,0,0,0,0,0,0,0,0,0,0,0,0,0
0,0,0,0,0,0,0,0,0,0,0,0,0,0,0,0,0,0,0,0,0,0,0
0,0,0,0,0,0,0,0,0,0,0,0,0,0,0,0,0,0,0,0,0,0,0
0,0,0,0,0,0,0,0,0,0,0,0,0,0,0,0,0,0,0,0,0,0,0
0,0,0,0,0,0,0,0,0,0,0,0,0,0,0,0,0,0,0,0,0,0,0
0,0,0,0,0,0,0,0,0,0,0,0,0,0,0,0,0,0,0,0,0,0,0
0,0,0,0,0,0,0,0,0,0,0,0,0,0,0,0,0,0,0,0,0,0,0
0,0,0,0,0,0,0,0,0,0,0,0,0,0,0,0,0,0,0,0,0,0,0
:endlayer

#### RULES ####
rule:
plugin=vanillaBlocks
number=1
data:
JSON:{blockState:{blockName:"minecraft:dirt",properties:{variant:"dirt",snowy:"false"}}}
:enddata
:endrule

rule:
plugin=vanillaBlocks
number=2
data:
JSON:{blockState:{blockName:"minecraft:grass",properties:{snowy:"false"}}}
:enddata
:endrule

rule:
plugin=vanillaBlocks
number=3
data:
JSON:{blockState:{blockName:"minecraft:stone",properties:{variant:"stone"}}}
:enddata
:endrule

rule:
plugin=vanillaBlocks
number=4
data:
JSON:{blockState:{blockName:"minecraft:stonebrick",properties:{variant:"cracked_stonebrick"}}}
:enddata
:endrule

rule:
plugin=vanillaBlocks
number=5
data:
JSON:{blockState:{blockName:"minecraft:stonebrick",properties:{variant:"stonebrick"}}}
:enddata
:endrule

rule:
plugin=vanillaBlocks
number=6
data:
JSON:{blockState:{blockName:"minecraft:tallgrass",properties:{type:"tall_grass"}}}
:enddata
:endrule

rule:
plugin=vanillaBlocks
number=7
data:
JSON:{blockState:{blockName:"minecraft:yellow_flower",properties:{type:"dandelion"}}}
:enddata
:endrule

rule:
plugin=vanillaBlocks
number=8
data:
JSON:{blockState:{blockName:"minecraft:red_flower",properties:{type:"pink_tulip"}}}
:enddata
:endrule

rule:
plugin=vanillaBlocks
number=9
data:
JSON:{blockState:{blockName:"minecraft:red_flower",properties:{type:"oxeye_daisy"}}}
:enddata
:endrule

rule:
plugin=vanillaBlocks
number=10
data:
JSON:{blockState:{blockName:"minecraft:log",properties:{variant:"spruce",axis:"y"}}}
:enddata
:endrule

rule:
plugin=vanillaBlocks
number=11
data:
JSON:{blockState:{blockName:"minecraft:double_stone_slab",properties:{seamless:"false",variant:"stone_brick"}}}
:enddata
:endrule

rule:
plugin=vanillaBlocks
number=12
data:
JSON:{blockState:{blockName:"minecraft:red_flower",properties:{type:"houstonia"}}}
:enddata
:endrule

rule:
plugin=vanillaBlocks
number=13
data:
JSON:{blockState:{blockName:"minecraft:stone_slab",properties:{half:"bottom",variant:"stone_brick"}}}
:enddata
:endrule

rule:
plugin=vanillaBlocks
number=14
data:
JSON:{blockState:{blockName:"minecraft:stone_brick_stairs",properties:{half:"bottom",shape:"straight",facing:"east"}}}
:enddata
:endrule

rule:
plugin=inventory
number=15
data:
JSON:{blockState:{blockName:"minecraft:chest",properties:{facing:"north"}},lootLevel:0,teData:{ForgeData:{},Items:[{Slot:2b,id:"minecraft:beef",Count:1b,Damage:0s},{Slot:3b,id:"minecraft:beef",Count:2b,Damage:0s},{Slot:5b,id:"minecraft:beef",Count:1b,Damage:0s},{Slot:6b,id:"minecraft:beef",Count:2b,Damage:0s},{Slot:7b,id:"minecraft:beef",Count:1b,Damage:0s},{Slot:8b,id:"minecraft:beef",Count:1b,Damage:0s},{Slot:10b,id:"minecraft:beef",Count:1b,Damage:0s},{Slot:11b,id:"minecraft:beef",Count:3b,Damage:0s},{Slot:12b,id:"minecraft:beef",Count:3b,Damage:0s},{Slot:13b,id:"minecraft:beef",Count:3b,Damage:0s},{Slot:14b,id:"minecraft:beef",Count:2b,Damage:0s},{Slot:15b,id:"minecraft:beef",Count:1b,Damage:0s},{Slot:16b,id:"minecraft:beef",Count:1b,Damage:0s},{Slot:17b,id:"minecraft:beef",Count:1b,Damage:0s},{Slot:20b,id:"minecraft:beef",Count:1b,Damage:0s},{Slot:25b,id:"minecraft:beef",Count:2b,Damage:0s}],id:"minecraft:chest",Lock:""},inventoryData:{length:16,inventoryContents:[{id:"minecraft:beef",Count:1b,slot:0,Damage:0s},{id:"minecraft:beef",Count:2b,slot:1,Damage:0s},{id:"minecraft:beef",Count:1b,slot:2,Damage:0s},{id:"minecraft:beef",Count:2b,slot:3,Damage:0s},{id:"minecraft:beef",Count:1b,slot:4,Damage:0s},{id:"minecraft:beef",Count:1b,slot:5,Damage:0s},{id:"minecraft:beef",Count:1b,slot:6,Damage:0s},{id:"minecraft:beef",Count:3b,slot:7,Damage:0s},{id:"minecraft:beef",Count:3b,slot:8,Damage:0s},{id:"minecraft:beef",Count:3b,slot:9,Damage:0s},{id:"minecraft:beef",Count:2b,slot:10,Damage:0s},{id:"minecraft:beef",Count:1b,slot:11,Damage:0s},{id:"minecraft:beef",Count:1b,slot:12,Damage:0s},{id:"minecraft:beef",Count:1b,slot:13,Damage:0s},{id:"minecraft:beef",Count:1b,slot:14,Damage:0s},{id:"minecraft:beef",Count:2b,slot:15,Damage:0s}]},legacyFeatures:1b}
:enddata
:endrule

rule:
plugin=blockTile
number=16
data:
JSON:{blockState:{blockName:"ancientwarfarestructure:advanced_loot_chest",properties:{facing:"north"}},teData:{LootTable:"minecraft:chests/village_blacksmith",lootRolls:1b,id:"ancientwarfarestructure:advanced_loot_chest_tile",Lock:"",LootTableSeed:-7616273058652940761L}}
:enddata
:endrule

rule:
plugin=vanillaBlocks
number=17
data:
JSON:{blockState:{blockName:"minecraft:stone_brick_stairs",properties:{half:"bottom",shape:"straight",facing:"west"}}}
:enddata
:endrule

rule:
plugin=vanillaBlocks
number=18
data:
JSON:{blockState:{blockName:"ancientwarfarestructure:fire_pit",properties:{lit:"true",variant:"log"}}}
:enddata
:endrule

rule:
plugin=inventory
number=19
data:
JSON:{blockState:{blockName:"minecraft:chest",properties:{facing:"north"}},lootLevel:0,teData:{Items:[{Slot:2b,id:"ancientwarfarenpc:coin",Count:1b,tag:{metal:"copper"},Damage:0s},{Slot:3b,id:"ancientwarfarenpc:coin",Count:1b,tag:{metal:"copper"},Damage:0s},{Slot:4b,id:"ancientwarfarenpc:coin",Count:2b,tag:{metal:"copper"},Damage:0s},{Slot:7b,id:"ancientwarfarenpc:coin",Count:1b,tag:{metal:"copper"},Damage:0s},{Slot:10b,id:"ancientwarfarenpc:coin",Count:2b,tag:{metal:"copper"},Damage:0s},{Slot:11b,id:"ancientwarfarenpc:coin",Count:4b,tag:{metal:"copper"},Damage:0s},{Slot:13b,id:"ancientwarfarenpc:coin",Count:1b,tag:{metal:"copper"},Damage:0s},{Slot:14b,id:"ancientwarfarenpc:coin",Count:1b,tag:{metal:"copper"},Damage:0s},{Slot:15b,id:"ancientwarfarenpc:coin",Count:2b,tag:{metal:"copper"},Damage:0s},{Slot:16b,id:"ancientwarfarenpc:coin",Count:2b,tag:{metal:"copper"},Damage:0s},{Slot:17b,id:"ancientwarfarenpc:coin",Count:1b,tag:{metal:"copper"},Damage:0s},{Slot:20b,id:"ancientwarfarenpc:coin",Count:1b,tag:{metal:"copper"},Damage:0s},{Slot:21b,id:"ancientwarfarenpc:coin",Count:1b,tag:{metal:"copper"},Damage:0s},{Slot:22b,id:"ancientwarfarenpc:coin",Count:1b,tag:{metal:"copper"},Damage:0s},{Slot:23b,id:"ancientwarfarenpc:coin",Count:1b,tag:{metal:"copper"},Damage:0s},{Slot:24b,id:"ancientwarfarenpc:coin",Count:1b,tag:{metal:"copper"},Damage:0s},{Slot:25b,id:"ancientwarfarenpc:coin",Count:1b,tag:{metal:"copper"},Damage:0s},{Slot:26b,id:"ancientwarfarenpc:coin",Count:1b,tag:{metal:"copper"},Damage:0s}],id:"minecraft:chest",Lock:""},inventoryData:{length:18,inventoryContents:[{id:"ancientwarfarenpc:coin",Count:1b,tag:{metal:"copper"},slot:0,Damage:0s},{id:"ancientwarfarenpc:coin",Count:1b,tag:{metal:"copper"},slot:1,Damage:0s},{id:"ancientwarfarenpc:coin",Count:2b,tag:{metal:"copper"},slot:2,Damage:0s},{id:"ancientwarfarenpc:coin",Count:1b,tag:{metal:"copper"},slot:3,Damage:0s},{id:"ancientwarfarenpc:coin",Count:2b,tag:{metal:"copper"},slot:4,Damage:0s},{id:"ancientwarfarenpc:coin",Count:4b,tag:{metal:"copper"},slot:5,Damage:0s},{id:"ancientwarfarenpc:coin",Count:1b,tag:{metal:"copper"},slot:6,Damage:0s},{id:"ancientwarfarenpc:coin",Count:1b,tag:{metal:"copper"},slot:7,Damage:0s},{id:"ancientwarfarenpc:coin",Count:2b,tag:{metal:"copper"},slot:8,Damage:0s},{id:"ancientwarfarenpc:coin",Count:2b,tag:{metal:"copper"},slot:9,Damage:0s},{id:"ancientwarfarenpc:coin",Count:1b,tag:{metal:"copper"},slot:10,Damage:0s},{id:"ancientwarfarenpc:coin",Count:1b,tag:{metal:"copper"},slot:11,Damage:0s},{id:"ancientwarfarenpc:coin",Count:1b,tag:{metal:"copper"},slot:12,Damage:0s},{id:"ancientwarfarenpc:coin",Count:1b,tag:{metal:"copper"},slot:13,Damage:0s},{id:"ancientwarfarenpc:coin",Count:1b,tag:{metal:"copper"},slot:14,Damage:0s},{id:"ancientwarfarenpc:coin",Count:1b,tag:{metal:"copper"},slot:15,Damage:0s},{id:"ancientwarfarenpc:coin",Count:1b,tag:{metal:"copper"},slot:16,Damage:0s},{id:"ancientwarfarenpc:coin",Count:1b,tag:{metal:"copper"},slot:17,Damage:0s}]},legacyFeatures:1b}
:enddata
:endrule

rule:
plugin=inventory
number=20
data:
JSON:{blockState:{blockName:"minecraft:chest",properties:{facing:"north"}},lootLevel:0,teData:{ForgeData:{},Items:[{Slot:1b,id:"ancientwarfarenpc:coin",Count:1b,tag:{metal:"copper"},Damage:0s},{Slot:2b,id:"ancientwarfarenpc:coin",Count:2b,tag:{metal:"copper"},Damage:0s},{Slot:3b,id:"ancientwarfarenpc:coin",Count:1b,tag:{metal:"copper"},Damage:0s},{Slot:4b,id:"ancientwarfarenpc:coin",Count:2b,tag:{metal:"copper"},Damage:0s},{Slot:5b,id:"ancientwarfarenpc:coin",Count:1b,tag:{metal:"copper"},Damage:0s},{Slot:6b,id:"ancientwarfarenpc:coin",Count:1b,tag:{metal:"copper"},Damage:0s},{Slot:7b,id:"ancientwarfarenpc:coin",Count:1b,tag:{metal:"copper"},Damage:0s},{Slot:8b,id:"ancientwarfarenpc:coin",Count:1b,tag:{metal:"copper"},Damage:0s},{Slot:10b,id:"ancientwarfarenpc:coin",Count:2b,tag:{metal:"copper"},Damage:0s},{Slot:11b,id:"ancientwarfarenpc:coin",Count:3b,tag:{metal:"copper"},Damage:0s},{Slot:12b,id:"ancientwarfarenpc:coin",Count:2b,tag:{metal:"copper"},Damage:0s},{Slot:13b,id:"ancientwarfarenpc:coin",Count:2b,tag:{metal:"copper"},Damage:0s},{Slot:14b,id:"ancientwarfarenpc:coin",Count:3b,tag:{metal:"copper"},Damage:0s},{Slot:15b,id:"ancientwarfarenpc:coin",Count:2b,tag:{metal:"copper"},Damage:0s},{Slot:16b,id:"ancientwarfarenpc:coin",Count:1b,tag:{metal:"copper"},Damage:0s},{Slot:21b,id:"ancientwarfarenpc:coin",Count:1b,tag:{metal:"copper"},Damage:0s},{Slot:22b,id:"ancientwarfarenpc:coin",Count:1b,tag:{metal:"copper"},Damage:0s},{Slot:23b,id:"ancientwarfarenpc:coin",Count:1b,tag:{metal:"copper"},Damage:0s},{Slot:24b,id:"ancientwarfarenpc:coin",Count:1b,tag:{metal:"copper"},Damage:0s}],id:"minecraft:chest",Lock:""},inventoryData:{length:19,inventoryContents:[{id:"ancientwarfarenpc:coin",Count:1b,tag:{metal:"copper"},slot:0,Damage:0s},{id:"ancientwarfarenpc:coin",Count:2b,tag:{metal:"copper"},slot:1,Damage:0s},{id:"ancientwarfarenpc:coin",Count:1b,tag:{metal:"copper"},slot:2,Damage:0s},{id:"ancientwarfarenpc:coin",Count:2b,tag:{metal:"copper"},slot:3,Damage:0s},{id:"ancientwarfarenpc:coin",Count:1b,tag:{metal:"copper"},slot:4,Damage:0s},{id:"ancientwarfarenpc:coin",Count:1b,tag:{metal:"copper"},slot:5,Damage:0s},{id:"ancientwarfarenpc:coin",Count:1b,tag:{metal:"copper"},slot:6,Damage:0s},{id:"ancientwarfarenpc:coin",Count:1b,tag:{metal:"copper"},slot:7,Damage:0s},{id:"ancientwarfarenpc:coin",Count:2b,tag:{metal:"copper"},slot:8,Damage:0s},{id:"ancientwarfarenpc:coin",Count:3b,tag:{metal:"copper"},slot:9,Damage:0s},{id:"ancientwarfarenpc:coin",Count:2b,tag:{metal:"copper"},slot:10,Damage:0s},{id:"ancientwarfarenpc:coin",Count:2b,tag:{metal:"copper"},slot:11,Damage:0s},{id:"ancientwarfarenpc:coin",Count:3b,tag:{metal:"copper"},slot:12,Damage:0s},{id:"ancientwarfarenpc:coin",Count:2b,tag:{metal:"copper"},slot:13,Damage:0s},{id:"ancientwarfarenpc:coin",Count:1b,tag:{metal:"copper"},slot:14,Damage:0s},{id:"ancientwarfarenpc:coin",Count:1b,tag:{metal:"copper"},slot:15,Damage:0s},{id:"ancientwarfarenpc:coin",Count:1b,tag:{metal:"copper"},slot:16,Damage:0s},{id:"ancientwarfarenpc:coin",Count:1b,tag:{metal:"copper"},slot:17,Damage:0s},{id:"ancientwarfarenpc:coin",Count:1b,tag:{metal:"copper"},slot:18,Damage:0s}]},legacyFeatures:1b}
:enddata
:endrule

rule:
plugin=inventory
number=21
data:
JSON:{blockState:{blockName:"minecraft:chest",properties:{facing:"north"}},lootLevel:0,teData:{ForgeData:{},Items:[{Slot:2b,id:"ancientwarfarenpc:coin",Count:2b,tag:{metal:"silver"},Damage:0s},{Slot:4b,id:"ancientwarfarenpc:coin",Count:2b,tag:{metal:"silver"},Damage:0s},{Slot:5b,id:"ancientwarfarenpc:coin",Count:2b,tag:{metal:"silver"},Damage:0s},{Slot:6b,id:"ancientwarfarenpc:coin",Count:2b,tag:{metal:"silver"},Damage:0s},{Slot:7b,id:"ancientwarfarenpc:coin",Count:1b,tag:{metal:"silver"},Damage:0s},{Slot:10b,id:"ancientwarfarenpc:coin",Count:1b,tag:{metal:"silver"},Damage:0s},{Slot:11b,id:"ancientwarfarenpc:coin",Count:2b,tag:{metal:"silver"},Damage:0s},{Slot:13b,id:"ancientwarfarenpc:coin",Count:1b,tag:{metal:"silver"},Damage:0s},{Slot:15b,id:"ancientwarfarenpc:coin",Count:3b,tag:{metal:"silver"},Damage:0s},{Slot:16b,id:"ancientwarfarenpc:coin",Count:2b,tag:{metal:"silver"},Damage:0s},{Slot:17b,id:"ancientwarfarenpc:coin",Count:3b,tag:{metal:"silver"},Damage:0s},{Slot:19b,id:"ancientwarfarenpc:coin",Count:1b,tag:{metal:"silver"},Damage:0s},{Slot:21b,id:"ancientwarfarenpc:coin",Count:1b,tag:{metal:"silver"},Damage:0s},{Slot:22b,id:"ancientwarfarenpc:coin",Count:1b,tag:{metal:"silver"},Damage:0s},{Slot:23b,id:"ancientwarfarenpc:coin",Count:2b,tag:{metal:"silver"},Damage:0s},{Slot:26b,id:"ancientwarfarenpc:coin",Count:1b,tag:{metal:"silver"},Damage:0s}],id:"minecraft:chest",Lock:""},inventoryData:{length:16,inventoryContents:[{id:"ancientwarfarenpc:coin",Count:2b,tag:{metal:"silver"},slot:0,Damage:0s},{id:"ancientwarfarenpc:coin",Count:2b,tag:{metal:"silver"},slot:1,Damage:0s},{id:"ancientwarfarenpc:coin",Count:2b,tag:{metal:"silver"},slot:2,Damage:0s},{id:"ancientwarfarenpc:coin",Count:2b,tag:{metal:"silver"},slot:3,Damage:0s},{id:"ancientwarfarenpc:coin",Count:1b,tag:{metal:"silver"},slot:4,Damage:0s},{id:"ancientwarfarenpc:coin",Count:1b,tag:{metal:"silver"},slot:5,Damage:0s},{id:"ancientwarfarenpc:coin",Count:2b,tag:{metal:"silver"},slot:6,Damage:0s},{id:"ancientwarfarenpc:coin",Count:1b,tag:{metal:"silver"},slot:7,Damage:0s},{id:"ancientwarfarenpc:coin",Count:3b,tag:{metal:"silver"},slot:8,Damage:0s},{id:"ancientwarfarenpc:coin",Count:2b,tag:{metal:"silver"},slot:9,Damage:0s},{id:"ancientwarfarenpc:coin",Count:3b,tag:{metal:"silver"},slot:10,Damage:0s},{id:"ancientwarfarenpc:coin",Count:1b,tag:{metal:"silver"},slot:11,Damage:0s},{id:"ancientwarfarenpc:coin",Count:1b,tag:{metal:"silver"},slot:12,Damage:0s},{id:"ancientwarfarenpc:coin",Count:1b,tag:{metal:"silver"},slot:13,Damage:0s},{id:"ancientwarfarenpc:coin",Count:2b,tag:{metal:"silver"},slot:14,Damage:0s},{id:"ancientwarfarenpc:coin",Count:1b,tag:{metal:"silver"},slot:15,Damage:0s}]},legacyFeatures:1b}
:enddata
:endrule

rule:
plugin=inventory
number=22
data:
JSON:{blockState:{blockName:"minecraft:chest",properties:{facing:"north"}},lootLevel:0,teData:{ForgeData:{},Items:[{Slot:10b,id:"minecraft:iron_chestplate",Count:1b,Damage:0s},{Slot:14b,id:"ancientwarfarenpc:coin",Count:2b,tag:{metal:"gold"},Damage:0s},{Slot:16b,id:"ancientwarfarenpc:coin",Count:1b,tag:{metal:"gold"},Damage:0s},{Slot:22b,id:"ancientwarfarenpc:coin",Count:1b,tag:{metal:"gold"},Damage:0s}],id:"minecraft:chest",Lock:""},inventoryData:{length:4,inventoryContents:[{id:"minecraft:iron_chestplate",Count:1b,slot:0,Damage:0s},{id:"ancientwarfarenpc:coin",Count:2b,tag:{metal:"gold"},slot:1,Damage:0s},{id:"ancientwarfarenpc:coin",Count:1b,tag:{metal:"gold"},slot:2,Damage:0s},{id:"ancientwarfarenpc:coin",Count:1b,tag:{metal:"gold"},slot:3,Damage:0s}]},legacyFeatures:1b}
:enddata
:endrule

rule:
plugin=inventory
number=23
data:
JSON:{blockState:{blockName:"minecraft:chest",properties:{facing:"north"}},lootLevel:0,teData:{Items:[{Slot:0b,id:"minecraft:gold_ingot",Count:5b,Damage:0s},{Slot:4b,id:"ancientwarfarenpc:coin",Count:1b,tag:{metal:"gold"},Damage:0s},{Slot:6b,id:"minecraft:golden_horse_armor",Count:1b,Damage:0s},{Slot:11b,id:"minecraft:iron_sword",Count:1b,Damage:0s},{Slot:13b,id:"ancientwarfarenpc:coin",Count:1b,tag:{metal:"gold"},Damage:0s},{Slot:16b,id:"ancientwarfarenpc:coin",Count:1b,tag:{metal:"gold"},Damage:0s}],id:"minecraft:chest",Lock:""},inventoryData:{length:6,inventoryContents:[{id:"minecraft:gold_ingot",Count:5b,slot:0,Damage:0s},{id:"ancientwarfarenpc:coin",Count:1b,tag:{metal:"gold"},slot:1,Damage:0s},{id:"minecraft:golden_horse_armor",Count:1b,slot:2,Damage:0s},{id:"minecraft:iron_sword",Count:1b,slot:3,Damage:0s},{id:"ancientwarfarenpc:coin",Count:1b,tag:{metal:"gold"},slot:4,Damage:0s},{id:"ancientwarfarenpc:coin",Count:1b,tag:{metal:"gold"},slot:5,Damage:0s}]},legacyFeatures:1b}
:enddata
:endrule

rule:
plugin=blockTile
number=24
data:
JSON:{blockState:{blockName:"ancientwarfarestructure:advanced_spawner",properties:{transparent:"true"}},teData:{id:"ancientwarfarestructure:advanced_spawner_tile",spawnerSettings:{minDelay:0,spawnDelay:0,lightSensitive:0b,spawnGroups:[{settingsList:[{remainingSpawnCount:1,hostile:1b,forced:1b,customTag:{ArmorDropChances:[1.0f,1.0f,1.0f,1.0f],ArmorItems:[{},{},{},{}],HandDropChances:[1.0f,1.0f],factionName:"barbarian",HandItems:[{id:"minecraft:stone_axe",Count:1b,Damage:0s},{}]},maxToSpawn:1,entityId:"ancientwarfarenpc:faction.soldier",minToSpawn:1}],groupWeight:1}],playerRange:6,respondToRedstone:0b,inventory:{Size:9,Items:[]},spawnRange:0,transparent:1b,maxDelay:0,xpToDrop:0,mobRange:0,debugMode:0b,maxNearbyMonsters:0}}}
:enddata
:endrule

rule:
plugin=blockTile
number=25
data:
JSON:{blockState:{blockName:"ancientwarfarestructure:advanced_spawner",properties:{transparent:"true"}},teData:{id:"ancientwarfarestructure:advanced_spawner_tile",spawnerSettings:{minDelay:0,spawnDelay:0,lightSensitive:0b,spawnGroups:[{settingsList:[{remainingSpawnCount:1,hostile:1b,forced:1b,customTag:{ArmorDropChances:[1.0f,1.0f,1.0f,1.0f],ArmorItems:[{},{},{},{}],HandDropChances:[1.0f,1.0f],factionName:"barbarian",HandItems:[{id:"minecraft:stone_axe",Count:1b,Damage:0s},{}]},maxToSpawn:1,entityId:"ancientwarfarenpc:faction.soldier",minToSpawn:1}],groupWeight:1}],playerRange:6,respondToRedstone:0b,inventory:{Size:9,Items:[]},spawnRange:0,transparent:1b,maxDelay:0,xpToDrop:0,mobRange:0,debugMode:0b,maxNearbyMonsters:0}}}
:enddata
:endrule

rule:
plugin=blockTile
number=26
data:
JSON:{blockState:{blockName:"ancientwarfarestructure:advanced_spawner",properties:{transparent:"true"}},teData:{id:"ancientwarfarestructure:advanced_spawner_tile",spawnerSettings:{minDelay:0,spawnDelay:0,lightSensitive:0b,spawnGroups:[{settingsList:[{remainingSpawnCount:1,hostile:1b,forced:1b,customTag:{ArmorDropChances:[1.0f,1.0f,1.0f,1.0f],ArmorItems:[{},{},{},{}],HandDropChances:[1.0f,1.0f],factionName:"barbarian",HandItems:[{id:"minecraft:stone_axe",Count:1b,Damage:0s},{}]},maxToSpawn:1,entityId:"ancientwarfarenpc:faction.soldier",minToSpawn:1}],groupWeight:1}],playerRange:5,respondToRedstone:0b,inventory:{Size:9,Items:[]},spawnRange:0,transparent:1b,maxDelay:0,xpToDrop:0,mobRange:0,debugMode:0b,maxNearbyMonsters:0}}}
:enddata
:endrule

rule:
plugin=blockTile
number=27
data:
JSON:{blockState:{blockName:"ancientwarfarestructure:advanced_spawner",properties:{transparent:"true"}},teData:{id:"ancientwarfarestructure:advanced_spawner_tile",spawnerSettings:{minDelay:0,spawnDelay:0,lightSensitive:0b,spawnGroups:[{settingsList:[{remainingSpawnCount:1,hostile:1b,forced:1b,customTag:{ArmorDropChances:[1.0f,1.0f,1.0f,1.0f],ArmorItems:[{},{},{},{}],HandDropChances:[1.0f,1.0f],factionName:"barbarian",HandItems:[{id:"minecraft:stone_axe",Count:1b,Damage:0s},{}]},maxToSpawn:1,entityId:"ancientwarfarenpc:faction.soldier",minToSpawn:1}],groupWeight:1}],playerRange:3,respondToRedstone:0b,inventory:{Size:9,Items:[]},spawnRange:0,transparent:1b,maxDelay:0,xpToDrop:0,mobRange:0,debugMode:0b,maxNearbyMonsters:0}}}
:enddata
:endrule

rule:
plugin=blockTile
number=28
data:
JSON:{blockState:{blockName:"ancientwarfarestructure:advanced_loot_chest",properties:{facing:"east"}},teData:{LootTable:"minecraft:chests/village_blacksmith",lootRolls:1b,id:"ancientwarfarestructure:advanced_loot_chest_tile",Lock:"",LootTableSeed:-1287826319913005241L}}
:enddata
:endrule

rule:
plugin=vanillaBlocks
number=29
data:
JSON:{blockState:{blockName:"minecraft:crafting_table"}}
:enddata
:endrule

rule:
plugin=blockTile
number=30
data:
JSON:{blockState:{blockName:"ancientwarfarestructure:advanced_spawner",properties:{transparent:"true"}},teData:{id:"ancientwarfarestructure:advanced_spawner_tile",spawnerSettings:{minDelay:0,spawnDelay:0,lightSensitive:0b,spawnGroups:[{settingsList:[{remainingSpawnCount:1,hostile:1b,forced:1b,customTag:{ArmorDropChances:[1.0f,1.0f,1.0f,1.0f],ArmorItems:[{},{},{},{}],HandDropChances:[1.0f,1.0f],factionName:"barbarian",HandItems:[{id:"minecraft:bow",Count:1b,Damage:0s},{}]},maxToSpawn:1,entityId:"ancientwarfarenpc:faction.archer",minToSpawn:1}],groupWeight:1}],playerRange:16,respondToRedstone:0b,inventory:{Size:9,Items:[]},spawnRange:0,transparent:1b,maxDelay:0,xpToDrop:0,mobRange:0,debugMode:0b,maxNearbyMonsters:0}}}
:enddata
:endrule

rule:
plugin=blockTile
number=31
data:
JSON:{blockState:{blockName:"ancientwarfarestructure:advanced_spawner",properties:{transparent:"true"}},teData:{id:"ancientwarfarestructure:advanced_spawner_tile",spawnerSettings:{minDelay:0,spawnDelay:0,lightSensitive:0b,spawnGroups:[{settingsList:[{remainingSpawnCount:1,hostile:1b,forced:1b,customTag:{ArmorDropChances:[1.0f,1.0f,1.0f,1.0f],ArmorItems:[{},{},{},{}],HandDropChances:[1.0f,1.0f],factionName:"barbarian",HandItems:[{id:"minecraft:bow",Count:1b,Damage:0s},{}]},maxToSpawn:1,entityId:"ancientwarfarenpc:faction.archer",minToSpawn:1}],groupWeight:1}],playerRange:16,respondToRedstone:0b,inventory:{Size:9,Items:[]},spawnRange:0,transparent:1b,maxDelay:0,xpToDrop:0,mobRange:0,debugMode:0b,maxNearbyMonsters:0}}}
:enddata
:endrule

rule:
plugin=blockTile
number=32
data:
JSON:{blockState:{blockName:"ancientwarfarestructure:advanced_spawner",properties:{transparent:"true"}},teData:{id:"ancientwarfarestructure:advanced_spawner_tile",spawnerSettings:{minDelay:0,spawnDelay:0,lightSensitive:0b,spawnGroups:[{settingsList:[{remainingSpawnCount:1,hostile:1b,forced:1b,customTag:{ArmorDropChances:[1.0f,1.0f,1.0f,1.0f],ArmorItems:[{},{},{},{}],HandDropChances:[1.0f,1.0f],factionName:"barbarian",HandItems:[{id:"minecraft:stone_axe",Count:1b,Damage:0s},{}]},maxToSpawn:1,entityId:"ancientwarfarenpc:faction.soldier",minToSpawn:1}],groupWeight:1}],playerRange:16,respondToRedstone:0b,inventory:{Size:9,Items:[]},spawnRange:0,transparent:1b,maxDelay:0,xpToDrop:0,mobRange:0,debugMode:0b,maxNearbyMonsters:0}}}
:enddata
:endrule

rule:
plugin=blockTile
number=33
data:
JSON:{blockState:{blockName:"ancientwarfarestructure:advanced_spawner",properties:{transparent:"true"}},teData:{id:"ancientwarfarestructure:advanced_spawner_tile",spawnerSettings:{minDelay:0,spawnDelay:0,lightSensitive:0b,spawnGroups:[{settingsList:[{remainingSpawnCount:1,hostile:1b,forced:1b,customTag:{ArmorDropChances:[1.0f,1.0f,1.0f,1.0f],ArmorItems:[{},{},{},{}],HandDropChances:[1.0f,1.0f],factionName:"barbarian",HandItems:[{id:"minecraft:iron_axe",Count:1b,Damage:0s},{id:"ancientwarfarenpc:wooden_shield",Count:1b,Damage:0s}]},maxToSpawn:1,entityId:"ancientwarfarenpc:faction.leader",minToSpawn:1}],groupWeight:1}],playerRange:8,respondToRedstone:0b,inventory:{Size:9,Items:[]},spawnRange:0,transparent:1b,maxDelay:0,xpToDrop:0,mobRange:0,debugMode:0b,maxNearbyMonsters:0}}}
:enddata
:endrule

rule:
plugin=blockTile
number=34
data:
JSON:{blockState:{blockName:"ancientwarfarestructure:advanced_spawner",properties:{transparent:"true"}},teData:{id:"ancientwarfarestructure:advanced_spawner_tile",spawnerSettings:{minDelay:0,spawnDelay:0,lightSensitive:0b,spawnGroups:[{settingsList:[{remainingSpawnCount:1,hostile:1b,forced:1b,customTag:{ArmorDropChances:[1.0f,1.0f,1.0f,1.0f],ArmorItems:[{},{},{},{}],HandDropChances:[1.0f,1.0f],factionName:"barbarian",HandItems:[{id:"minecraft:stone_axe",Count:1b,Damage:0s},{}]},maxToSpawn:1,entityId:"ancientwarfarenpc:faction.soldier",minToSpawn:1}],groupWeight:1}],playerRange:16,respondToRedstone:0b,inventory:{Size:9,Items:[]},spawnRange:0,transparent:1b,maxDelay:0,xpToDrop:0,mobRange:0,debugMode:0b,maxNearbyMonsters:0}}}
:enddata
:endrule

rule:
plugin=inventory
number=35
data:
JSON:{blockState:{blockName:"minecraft:furnace",properties:{facing:"east"}},lootLevel:0,teData:{CookTime:0,BurnTime:0,Items:[],id:"minecraft:furnace",CookTimeTotal:0,Lock:""},inventoryData:{length:0,inventoryContents:[]},legacyFeatures:0b}
:enddata
:endrule

rule:
plugin=blockTile
number=36
data:
JSON:{blockState:{blockName:"ancientwarfarestructure:advanced_spawner",properties:{transparent:"true"}},teData:{id:"ancientwarfarestructure:advanced_spawner_tile",spawnerSettings:{minDelay:0,spawnDelay:0,lightSensitive:0b,spawnGroups:[{settingsList:[{remainingSpawnCount:1,hostile:1b,forced:1b,customTag:{ArmorDropChances:[1.0f,1.0f,1.0f,1.0f],ArmorItems:[{},{},{},{}],HandDropChances:[1.0f,1.0f],factionName:"barbarian",HandItems:[{id:"minecraft:stone_axe",Count:1b,Damage:0s},{}]},maxToSpawn:1,entityId:"ancientwarfarenpc:faction.soldier",minToSpawn:1}],groupWeight:1}],playerRange:8,respondToRedstone:0b,inventory:{Size:9,Items:[]},spawnRange:0,transparent:1b,maxDelay:0,xpToDrop:0,mobRange:0,debugMode:0b,maxNearbyMonsters:0}}}
:enddata
:endrule

rule:
plugin=blockTile
number=37
data:
JSON:{blockState:{blockName:"ancientwarfarestructure:advanced_spawner",properties:{transparent:"true"}},teData:{id:"ancientwarfarestructure:advanced_spawner_tile",spawnerSettings:{minDelay:0,spawnDelay:0,lightSensitive:0b,spawnGroups:[{settingsList:[{remainingSpawnCount:1,hostile:1b,forced:1b,customTag:{ArmorDropChances:[1.0f,1.0f,1.0f,1.0f],ArmorItems:[{},{},{},{}],HandDropChances:[1.0f,1.0f],factionName:"barbarian",HandItems:[{id:"minecraft:stone_axe",Count:1b,Damage:0s},{}]},maxToSpawn:1,entityId:"ancientwarfarenpc:faction.soldier",minToSpawn:1}],groupWeight:1}],playerRange:8,respondToRedstone:0b,inventory:{Size:9,Items:[]},spawnRange:0,transparent:1b,maxDelay:0,xpToDrop:0,mobRange:0,debugMode:0b,maxNearbyMonsters:0}}}
:enddata
:endrule

rule:
plugin=blockTile
number=38
data:
JSON:{blockState:{blockName:"ancientwarfarestructure:advanced_spawner",properties:{transparent:"true"}},teData:{id:"ancientwarfarestructure:advanced_spawner_tile",spawnerSettings:{minDelay:0,spawnDelay:0,lightSensitive:0b,spawnGroups:[{settingsList:[{remainingSpawnCount:1,hostile:1b,forced:1b,customTag:{ArmorDropChances:[1.0f,1.0f,1.0f,1.0f],ArmorItems:[{},{},{},{}],HandDropChances:[1.0f,1.0f],factionName:"barbarian",HandItems:[{id:"minecraft:stone_axe",Count:1b,Damage:0s},{}]},maxToSpawn:1,entityId:"ancientwarfarenpc:faction.soldier",minToSpawn:1}],groupWeight:1}],playerRange:16,respondToRedstone:0b,inventory:{Size:9,Items:[]},spawnRange:0,transparent:1b,maxDelay:0,xpToDrop:0,mobRange:0,debugMode:0b,maxNearbyMonsters:0}}}
:enddata
:endrule

rule:
plugin=blockTile
number=39
data:
JSON:{blockState:{blockName:"ancientwarfarestructure:advanced_spawner",properties:{transparent:"true"}},teData:{id:"ancientwarfarestructure:advanced_spawner_tile",spawnerSettings:{minDelay:0,spawnDelay:0,lightSensitive:0b,spawnGroups:[{settingsList:[{remainingSpawnCount:1,hostile:1b,forced:1b,customTag:{ArmorDropChances:[1.0f,1.0f,1.0f,1.0f],ArmorItems:[{},{},{},{}],HandDropChances:[1.0f,1.0f],factionName:"barbarian",HandItems:[{id:"minecraft:bow",Count:1b,Damage:0s},{}]},maxToSpawn:1,entityId:"ancientwarfarenpc:faction.archer",minToSpawn:1}],groupWeight:1}],playerRange:16,respondToRedstone:0b,inventory:{Size:9,Items:[]},spawnRange:0,transparent:1b,maxDelay:0,xpToDrop:0,mobRange:0,debugMode:0b,maxNearbyMonsters:0}}}
:enddata
:endrule

rule:
plugin=blockTile
number=40
data:
JSON:{blockState:{blockName:"ancientwarfarestructure:advanced_spawner",properties:{transparent:"true"}},teData:{id:"ancientwarfarestructure:advanced_spawner_tile",spawnerSettings:{minDelay:0,spawnDelay:0,lightSensitive:0b,spawnGroups:[{settingsList:[{remainingSpawnCount:1,hostile:1b,forced:1b,customTag:{ArmorDropChances:[1.0f,1.0f,1.0f,1.0f],ArmorItems:[{},{},{},{}],HandDropChances:[1.0f,1.0f],factionName:"barbarian",HandItems:[{id:"minecraft:stone_axe",Count:1b,Damage:0s},{}]},maxToSpawn:1,entityId:"ancientwarfarenpc:faction.soldier",minToSpawn:1}],groupWeight:1}],playerRange:16,respondToRedstone:0b,inventory:{Size:9,Items:[]},spawnRange:0,transparent:1b,maxDelay:0,xpToDrop:0,mobRange:0,debugMode:0b,maxNearbyMonsters:0}}}
:enddata
:endrule

rule:
plugin=blockTile
number=41
data:
JSON:{blockState:{blockName:"ancientwarfarestructure:advanced_spawner",properties:{transparent:"true"}},teData:{id:"ancientwarfarestructure:advanced_spawner_tile",spawnerSettings:{minDelay:0,spawnDelay:0,lightSensitive:0b,spawnGroups:[{settingsList:[{remainingSpawnCount:1,hostile:1b,forced:1b,customTag:{ArmorDropChances:[1.0f,1.0f,1.0f,1.0f],ArmorItems:[{},{},{},{}],HandDropChances:[1.0f,1.0f],factionName:"barbarian",HandItems:[{id:"minecraft:bow",Count:1b,Damage:0s},{}]},maxToSpawn:1,entityId:"ancientwarfarenpc:faction.archer",minToSpawn:1}],groupWeight:1}],playerRange:16,respondToRedstone:0b,inventory:{Size:9,Items:[]},spawnRange:0,transparent:1b,maxDelay:0,xpToDrop:0,mobRange:0,debugMode:0b,maxNearbyMonsters:0}}}
:enddata
:endrule

rule:
plugin=inventory
number=42
data:
JSON:{blockState:{blockName:"minecraft:furnace",properties:{facing:"east"}},lootLevel:0,teData:{CookTime:0,BurnTime:0,Items:[],id:"minecraft:furnace",CookTimeTotal:0,Lock:""},inventoryData:{length:0,inventoryContents:[]},legacyFeatures:0b}
:enddata
:endrule

rule:
plugin=vanillaBlocks
number=43
data:
JSON:{blockState:{blockName:"minecraft:leaves",properties:{check_decay:"false",decayable:"true",variant:"spruce"}}}
:enddata
:endrule

rule:
plugin=blockTile
number=44
data:
JSON:{blockState:{blockName:"ancientwarfarestructure:advanced_spawner",properties:{transparent:"true"}},teData:{id:"ancientwarfarestructure:advanced_spawner_tile",spawnerSettings:{minDelay:0,spawnDelay:0,lightSensitive:0b,spawnGroups:[{settingsList:[{remainingSpawnCount:1,hostile:1b,forced:1b,customTag:{ArmorDropChances:[1.0f,1.0f,1.0f,1.0f],ArmorItems:[{},{},{},{}],HandDropChances:[1.0f,1.0f],factionName:"barbarian",HandItems:[{id:"minecraft:stone_axe",Count:1b,Damage:0s},{}]},maxToSpawn:1,entityId:"ancientwarfarenpc:faction.soldier",minToSpawn:1}],groupWeight:1}],playerRange:3,respondToRedstone:0b,inventory:{Size:9,Items:[]},spawnRange:0,transparent:1b,maxDelay:0,xpToDrop:0,mobRange:0,debugMode:0b,maxNearbyMonsters:0}}}
:enddata
:endrule

rule:
plugin=blockTile
number=45
data:
JSON:{blockState:{blockName:"ancientwarfarestructure:advanced_spawner",properties:{transparent:"true"}},teData:{id:"ancientwarfarestructure:advanced_spawner_tile",spawnerSettings:{minDelay:0,spawnDelay:0,lightSensitive:0b,spawnGroups:[{settingsList:[{remainingSpawnCount:1,hostile:1b,forced:1b,customTag:{ArmorDropChances:[1.0f,1.0f,1.0f,1.0f],ArmorItems:[{},{},{},{}],HandDropChances:[1.0f,1.0f],factionName:"barbarian",HandItems:[{id:"minecraft:stone_axe",Count:1b,Damage:0s},{}]},maxToSpawn:1,entityId:"ancientwarfarenpc:faction.soldier",minToSpawn:1}],groupWeight:1}],playerRange:3,respondToRedstone:0b,inventory:{Size:9,Items:[]},spawnRange:0,transparent:1b,maxDelay:0,xpToDrop:0,mobRange:0,debugMode:0b,maxNearbyMonsters:0}}}
:enddata
:endrule

rule:
plugin=vanillaBlocks
number=46
data:
JSON:{blockState:{blockName:"minecraft:torch",properties:{facing:"north"}}}
:enddata
:endrule

rule:
plugin=vanillaBlocks
number=47
data:
JSON:{blockState:{blockName:"minecraft:torch",properties:{facing:"west"}}}
:enddata
:endrule

rule:
plugin=vanillaBlocks
number=48
data:
JSON:{blockState:{blockName:"minecraft:torch",properties:{facing:"east"}}}
:enddata
:endrule

rule:
plugin=inventory
number=49
data:
JSON:{blockState:{blockName:"minecraft:furnace",properties:{facing:"east"}},lootLevel:0,teData:{CookTime:0,BurnTime:0,Items:[],id:"minecraft:furnace",CookTimeTotal:0,Lock:""},inventoryData:{length:0,inventoryContents:[]},legacyFeatures:0b}
:enddata
:endrule

rule:
plugin=inventory
number=50
data:
JSON:{blockState:{blockName:"minecraft:furnace",properties:{facing:"east"}},lootLevel:0,teData:{CookTime:0,BurnTime:0,Items:[],id:"minecraft:furnace",CookTimeTotal:0,Lock:""},inventoryData:{length:0,inventoryContents:[]},legacyFeatures:0b}
:enddata
:endrule

rule:
plugin=vanillaBlocks
number=51
data:
JSON:{blockState:{blockName:"minecraft:torch",properties:{facing:"south"}}}
:enddata
:endrule

rule:
plugin=inventory
number=52
data:
JSON:{blockState:{blockName:"minecraft:furnace",properties:{facing:"east"}},lootLevel:0,teData:{CookTime:0,BurnTime:0,Items:[],id:"minecraft:furnace",CookTimeTotal:0,Lock:""},inventoryData:{length:0,inventoryContents:[]},legacyFeatures:0b}
:enddata
:endrule

rule:
plugin=inventory
number=53
data:
JSON:{blockState:{blockName:"minecraft:furnace",properties:{facing:"east"}},lootLevel:0,teData:{CookTime:0,BurnTime:0,Items:[],id:"minecraft:furnace",CookTimeTotal:0,Lock:""},inventoryData:{length:0,inventoryContents:[]},legacyFeatures:0b}
:enddata
:endrule

rule:
plugin=vanillaBlocks
number=54
data:
JSON:{blockState:{blockName:"minecraft:stone_brick_stairs",properties:{half:"top",shape:"straight",facing:"east"}}}
:enddata
:endrule

rule:
plugin=vanillaBlocks
number=55
data:
JSON:{blockState:{blockName:"minecraft:stone_brick_stairs",properties:{half:"top",shape:"straight",facing:"west"}}}
:enddata
:endrule

rule:
plugin=inventory
number=56
data:
JSON:{blockState:{blockName:"minecraft:furnace",properties:{facing:"east"}},lootLevel:0,teData:{CookTime:0,BurnTime:0,Items:[],id:"minecraft:furnace",CookTimeTotal:0,Lock:""},inventoryData:{length:0,inventoryContents:[]},legacyFeatures:0b}
:enddata
:endrule

rule:
plugin=inventory
number=57
data:
JSON:{blockState:{blockName:"minecraft:furnace",properties:{facing:"east"}},lootLevel:0,teData:{CookTime:0,BurnTime:0,Items:[],id:"minecraft:furnace",CookTimeTotal:0,Lock:""},inventoryData:{length:0,inventoryContents:[]},legacyFeatures:0b}
:enddata
:endrule

rule:
plugin=blockTile
number=58
data:
JSON:{blockState:{blockName:"ancientwarfarestructure:advanced_spawner",properties:{transparent:"true"}},teData:{id:"ancientwarfarestructure:advanced_spawner_tile",spawnerSettings:{minDelay:0,spawnDelay:0,lightSensitive:0b,spawnGroups:[{settingsList:[{remainingSpawnCount:1,hostile:1b,forced:1b,customTag:{ArmorDropChances:[1.0f,1.0f,1.0f,1.0f],ArmorItems:[{},{},{},{}],HandDropChances:[1.0f,1.0f],factionName:"barbarian",HandItems:[{id:"minecraft:bow",Count:1b,Damage:0s},{}]},maxToSpawn:1,entityId:"ancientwarfarenpc:faction.archer",minToSpawn:1}],groupWeight:1}],playerRange:16,respondToRedstone:0b,inventory:{Size:9,Items:[]},spawnRange:0,transparent:1b,maxDelay:0,xpToDrop:0,mobRange:0,debugMode:0b,maxNearbyMonsters:0}}}
:enddata
:endrule

rule:
plugin=blockTile
number=59
data:
JSON:{blockState:{blockName:"ancientwarfarestructure:advanced_spawner",properties:{transparent:"true"}},teData:{id:"ancientwarfarestructure:advanced_spawner_tile",spawnerSettings:{minDelay:0,spawnDelay:0,lightSensitive:0b,spawnGroups:[{settingsList:[{remainingSpawnCount:1,hostile:1b,forced:1b,customTag:{ArmorDropChances:[1.0f,1.0f,1.0f,1.0f],ArmorItems:[{},{},{},{}],HandDropChances:[1.0f,1.0f],factionName:"barbarian",HandItems:[{id:"minecraft:bow",Count:1b,Damage:0s},{}]},maxToSpawn:1,entityId:"ancientwarfarenpc:faction.archer",minToSpawn:1}],groupWeight:1}],playerRange:16,respondToRedstone:0b,inventory:{Size:9,Items:[]},spawnRange:0,transparent:1b,maxDelay:0,xpToDrop:0,mobRange:0,debugMode:0b,maxNearbyMonsters:0}}}
:enddata
:endrule

rule:
plugin=blockTile
number=60
data:
JSON:{blockState:{blockName:"ancientwarfarestructure:advanced_spawner",properties:{transparent:"true"}},teData:{id:"ancientwarfarestructure:advanced_spawner_tile",spawnerSettings:{minDelay:0,spawnDelay:0,lightSensitive:0b,spawnGroups:[{settingsList:[{remainingSpawnCount:1,hostile:1b,forced:1b,customTag:{ArmorDropChances:[1.0f,1.0f,1.0f,1.0f],ArmorItems:[{},{},{},{}],HandDropChances:[1.0f,1.0f],factionName:"barbarian",HandItems:[{id:"minecraft:bow",Count:1b,Damage:0s},{}]},maxToSpawn:1,entityId:"ancientwarfarenpc:faction.archer",minToSpawn:1}],groupWeight:1}],playerRange:16,respondToRedstone:0b,inventory:{Size:9,Items:[]},spawnRange:0,transparent:1b,maxDelay:0,xpToDrop:0,mobRange:0,debugMode:0b,maxNearbyMonsters:0}}}
:enddata
:endrule

rule:
plugin=blockTile
number=61
data:
JSON:{blockState:{blockName:"ancientwarfarestructure:advanced_spawner",properties:{transparent:"true"}},teData:{id:"ancientwarfarestructure:advanced_spawner_tile",spawnerSettings:{minDelay:0,spawnDelay:0,lightSensitive:0b,spawnGroups:[{settingsList:[{remainingSpawnCount:1,hostile:1b,forced:1b,customTag:{ArmorDropChances:[1.0f,1.0f,1.0f,1.0f],ArmorItems:[{},{},{},{}],HandDropChances:[1.0f,1.0f],factionName:"barbarian",HandItems:[{id:"minecraft:bow",Count:1b,Damage:0s},{}]},maxToSpawn:1,entityId:"ancientwarfarenpc:faction.archer",minToSpawn:1}],groupWeight:1}],playerRange:16,respondToRedstone:0b,inventory:{Size:9,Items:[]},spawnRange:0,transparent:1b,maxDelay:0,xpToDrop:0,mobRange:0,debugMode:0b,maxNearbyMonsters:0}}}
:enddata
:endrule

rule:
plugin=bed
number=62
data:
JSON:{blockState:{blockName:"minecraft:bed",properties:{part:"head",facing:"east",occupied:"false"}},bedColor:12}
:enddata
:endrule

rule:
plugin=bed
number=63
data:
JSON:{blockState:{blockName:"minecraft:bed",properties:{part:"foot",facing:"east",occupied:"false"}},bedColor:12}
:enddata
:endrule

rule:
plugin=blockTile
number=64
data:
JSON:{blockState:{blockName:"ancientwarfarestructure:advanced_spawner",properties:{transparent:"true"}},teData:{id:"ancientwarfarestructure:advanced_spawner_tile",spawnerSettings:{minDelay:0,spawnDelay:0,lightSensitive:0b,spawnGroups:[{settingsList:[{remainingSpawnCount:1,hostile:1b,forced:1b,customTag:{ArmorDropChances:[1.0f,1.0f,1.0f,1.0f],ArmorItems:[{},{},{},{}],HandDropChances:[1.0f,1.0f],factionName:"barbarian",HandItems:[{id:"minecraft:stone_axe",Count:1b,Damage:0s},{}]},maxToSpawn:1,entityId:"ancientwarfarenpc:faction.soldier",minToSpawn:1}],groupWeight:1}],playerRange:6,respondToRedstone:0b,inventory:{Size:9,Items:[]},spawnRange:0,transparent:1b,maxDelay:0,xpToDrop:0,mobRange:0,debugMode:0b,maxNearbyMonsters:0}}}
:enddata
:endrule

rule:
plugin=blockTile
number=65
data:
JSON:{blockState:{blockName:"ancientwarfarestructure:advanced_spawner",properties:{transparent:"true"}},teData:{id:"ancientwarfarestructure:advanced_spawner_tile",spawnerSettings:{minDelay:0,spawnDelay:0,lightSensitive:0b,spawnGroups:[{settingsList:[{remainingSpawnCount:1,hostile:1b,forced:1b,customTag:{ArmorDropChances:[1.0f,1.0f,1.0f,1.0f],ArmorItems:[{},{},{},{}],HandDropChances:[1.0f,1.0f],factionName:"barbarian",HandItems:[{id:"minecraft:stone_axe",Count:1b,Damage:0s},{}]},maxToSpawn:1,entityId:"ancientwarfarenpc:faction.soldier",minToSpawn:1}],groupWeight:1}],playerRange:6,respondToRedstone:0b,inventory:{Size:9,Items:[]},spawnRange:0,transparent:1b,maxDelay:0,xpToDrop:0,mobRange:0,debugMode:0b,maxNearbyMonsters:0}}}
:enddata
:endrule

rule:
plugin=bed
number=66
data:
JSON:{blockState:{blockName:"minecraft:bed",properties:{part:"foot",facing:"west",occupied:"false"}},bedColor:12}
:enddata
:endrule

rule:
plugin=bed
number=67
data:
JSON:{blockState:{blockName:"minecraft:bed",properties:{part:"head",facing:"west",occupied:"false"}},bedColor:12}
:enddata
:endrule

rule:
plugin=blockTile
number=68
data:
JSON:{blockState:{blockName:"ancientwarfarestructure:advanced_spawner",properties:{transparent:"true"}},teData:{id:"ancientwarfarestructure:advanced_spawner_tile",spawnerSettings:{minDelay:0,spawnDelay:0,lightSensitive:0b,spawnGroups:[{settingsList:[{remainingSpawnCount:1,hostile:1b,forced:1b,customTag:{ArmorDropChances:[1.0f,1.0f,1.0f,1.0f],ArmorItems:[{},{},{},{}],HandDropChances:[1.0f,1.0f],factionName:"barbarian",HandItems:[{id:"minecraft:iron_axe",Count:1b,Damage:0s},{id:"ancientwarfarenpc:wooden_shield",Count:1b,Damage:0s}]},maxToSpawn:1,entityId:"ancientwarfarenpc:faction.leader",minToSpawn:1}],groupWeight:1}],playerRange:5,respondToRedstone:0b,inventory:{Size:9,Items:[]},spawnRange:0,transparent:1b,maxDelay:0,xpToDrop:0,mobRange:0,debugMode:0b,maxNearbyMonsters:0}}}
:enddata
:endrule

rule:
plugin=blockTile
number=69
data:
JSON:{blockState:{blockName:"ancientwarfarestructure:advanced_spawner",properties:{transparent:"true"}},teData:{id:"ancientwarfarestructure:advanced_spawner_tile",spawnerSettings:{minDelay:0,spawnDelay:0,lightSensitive:0b,spawnGroups:[{settingsList:[{remainingSpawnCount:1,hostile:1b,forced:1b,customTag:{ArmorDropChances:[1.0f,1.0f,1.0f,1.0f],ArmorItems:[{},{},{},{}],HandDropChances:[1.0f,1.0f],factionName:"barbarian",HandItems:[{id:"minecraft:stone_axe",Count:1b,Damage:0s},{}]},maxToSpawn:1,entityId:"ancientwarfarenpc:faction.soldier",minToSpawn:1}],groupWeight:1}],playerRange:6,respondToRedstone:0b,inventory:{Size:9,Items:[]},spawnRange:0,transparent:1b,maxDelay:0,xpToDrop:0,mobRange:0,debugMode:0b,maxNearbyMonsters:0}}}
:enddata
:endrule

rule:
plugin=blockTile
number=70
data:
JSON:{blockState:{blockName:"ancientwarfarestructure:advanced_spawner",properties:{transparent:"true"}},teData:{id:"ancientwarfarestructure:advanced_spawner_tile",spawnerSettings:{minDelay:0,spawnDelay:0,lightSensitive:0b,spawnGroups:[{settingsList:[{remainingSpawnCount:1,hostile:1b,forced:1b,customTag:{ArmorDropChances:[1.0f,1.0f,1.0f,1.0f],ArmorItems:[{},{},{},{}],HandDropChances:[1.0f,1.0f],factionName:"barbarian",HandItems:[{id:"minecraft:stone_axe",Count:1b,Damage:0s},{}]},maxToSpawn:1,entityId:"ancientwarfarenpc:faction.soldier",minToSpawn:1}],groupWeight:1}],playerRange:6,respondToRedstone:0b,inventory:{Size:9,Items:[]},spawnRange:0,transparent:1b,maxDelay:0,xpToDrop:0,mobRange:0,debugMode:0b,maxNearbyMonsters:0}}}
:enddata
:endrule

rule:
plugin=bed
number=71
data:
JSON:{blockState:{blockName:"minecraft:bed",properties:{part:"foot",facing:"north",occupied:"false"}},bedColor:12}
:enddata
:endrule

rule:
plugin=bed
number=72
data:
JSON:{blockState:{blockName:"minecraft:bed",properties:{part:"head",facing:"north",occupied:"false"}},bedColor:12}
:enddata
:endrule

rule:
plugin=blockTile
number=73
data:
JSON:{blockState:{blockName:"ancientwarfarestructure:advanced_loot_chest",properties:{facing:"south"}},teData:{LootTable:"minecraft:chests/village_blacksmith",lootRolls:1b,id:"ancientwarfarestructure:advanced_loot_chest_tile",Lock:"",LootTableSeed:-5718322933814706872L}}
:enddata
:endrule

rule:
plugin=blockTile
number=74
data:
JSON:{blockState:{blockName:"ancientwarfarestructure:advanced_spawner",properties:{transparent:"true"}},teData:{id:"ancientwarfarestructure:advanced_spawner_tile",spawnerSettings:{minDelay:0,spawnDelay:0,lightSensitive:0b,spawnGroups:[{settingsList:[{remainingSpawnCount:1,hostile:1b,forced:1b,customTag:{ArmorDropChances:[1.0f,1.0f,1.0f,1.0f],ArmorItems:[{},{},{},{}],HandDropChances:[1.0f,1.0f],factionName:"barbarian",HandItems:[{id:"minecraft:bow",Count:1b,Damage:0s},{}]},maxToSpawn:1,entityId:"ancientwarfarenpc:faction.archer",minToSpawn:1}],groupWeight:1}],playerRange:16,respondToRedstone:0b,inventory:{Size:9,Items:[]},spawnRange:0,transparent:1b,maxDelay:0,xpToDrop:0,mobRange:0,debugMode:0b,maxNearbyMonsters:0}}}
:enddata
:endrule

rule:
plugin=blockTile
number=75
data:
JSON:{blockState:{blockName:"ancientwarfarestructure:advanced_spawner",properties:{transparent:"true"}},teData:{id:"ancientwarfarestructure:advanced_spawner_tile",spawnerSettings:{minDelay:0,spawnDelay:0,lightSensitive:0b,spawnGroups:[{settingsList:[{remainingSpawnCount:1,hostile:1b,forced:1b,customTag:{ArmorDropChances:[1.0f,1.0f,1.0f,1.0f],ArmorItems:[{},{},{},{}],HandDropChances:[1.0f,1.0f],factionName:"barbarian",HandItems:[{id:"minecraft:bow",Count:1b,Damage:0s},{}]},maxToSpawn:1,entityId:"ancientwarfarenpc:faction.archer",minToSpawn:1}],groupWeight:1}],playerRange:16,respondToRedstone:0b,inventory:{Size:9,Items:[]},spawnRange:0,transparent:1b,maxDelay:0,xpToDrop:0,mobRange:0,debugMode:0b,maxNearbyMonsters:0}}}
:enddata
:endrule

rule:
plugin=blockTile
number=76
data:
JSON:{blockState:{blockName:"ancientwarfarestructure:advanced_spawner",properties:{transparent:"true"}},teData:{id:"ancientwarfarestructure:advanced_spawner_tile",spawnerSettings:{minDelay:0,spawnDelay:0,lightSensitive:0b,spawnGroups:[{settingsList:[{remainingSpawnCount:1,hostile:1b,forced:1b,customTag:{ArmorDropChances:[1.0f,1.0f,1.0f,1.0f],ArmorItems:[{},{},{},{}],HandDropChances:[1.0f,1.0f],factionName:"barbarian",HandItems:[{id:"minecraft:bow",Count:1b,Damage:0s},{}]},maxToSpawn:1,entityId:"ancientwarfarenpc:faction.archer",minToSpawn:1}],groupWeight:1}],playerRange:16,respondToRedstone:0b,inventory:{Size:9,Items:[]},spawnRange:0,transparent:1b,maxDelay:0,xpToDrop:0,mobRange:0,debugMode:0b,maxNearbyMonsters:0}}}
:enddata
:endrule

rule:
plugin=blockTile
number=77
data:
JSON:{blockState:{blockName:"ancientwarfarestructure:advanced_spawner",properties:{transparent:"true"}},teData:{id:"ancientwarfarestructure:advanced_spawner_tile",spawnerSettings:{minDelay:0,spawnDelay:0,lightSensitive:0b,spawnGroups:[{settingsList:[{remainingSpawnCount:1,hostile:1b,forced:1b,customTag:{ArmorDropChances:[1.0f,1.0f,1.0f,1.0f],ArmorItems:[{},{},{},{}],HandDropChances:[1.0f,1.0f],factionName:"barbarian",HandItems:[{id:"minecraft:bow",Count:1b,Damage:0s},{}]},maxToSpawn:1,entityId:"ancientwarfarenpc:faction.archer",minToSpawn:1}],groupWeight:1}],playerRange:16,respondToRedstone:0b,inventory:{Size:9,Items:[]},spawnRange:0,transparent:1b,maxDelay:0,xpToDrop:0,mobRange:0,debugMode:0b,maxNearbyMonsters:0}}}
:enddata
:endrule

#### ENTITIES ####
