# Ancient Warfare Structure Template File
# Auto-generated structure template file. created on: 11/24/2018 at: 18:33:29
# Lines beginning with # denote comments

header:
version=2.7
name=PMMOBSSwampRuin4
mods=primitivemobs
size=8,41,9
offset=5,4,7
:endheader

#### VALIDATION ####
validation:
type=ground
survival=false
worldGenEnabled=true
unique=false
preserveBlocks=true
selectionWeight=30
clusterValue=50
minDuplicateDistance=1000
dimensionWhiteList=false
dimensionList=
biomeWhiteList=true
biomeList=minecraft:swampland,biomesoplenty:dead_swamp,biomesoplenty:bayou,biomesoplenty:marsh
leveling=0
fill=0
border=0
blockSwap=false
data:
:enddata
:endvalidation

#### LAYERS ####
layer: 0
0,0,0,0,0,0,0,0
0,0,0,0,3,3,0,0
0,0,0,3,3,3,0,0
0,4,0,3,3,3,3,0
2,3,3,3,3,3,3,0
0,0,3,3,3,3,3,0
0,0,0,3,3,3,0,0
0,0,0,0,3,0,0,0
1,0,0,0,0,0,0,0
:endlayer
layer: 1
0,0,0,0,0,0,0,0
0,0,0,0,3,3,0,0
0,0,0,3,3,3,0,0
0,4,0,3,3,3,3,0
2,3,3,3,3,3,3,0
0,5,3,3,3,3,3,0
0,0,0,3,3,3,0,0
0,0,0,2,3,0,0,0
0,0,0,0,0,0,0,0
:endlayer
layer: 2
0,0,0,0,0,0,0,0
0,0,0,0,3,3,0,0
0,0,0,3,3,3,0,0
0,4,0,3,3,3,3,0
2,3,3,3,3,3,3,0
0,5,3,3,3,3,3,0
0,0,0,3,3,3,0,0
0,0,0,2,3,0,0,0
0,0,0,0,0,0,0,0
:endlayer
layer: 3
0,0,0,0,0,0,0,0
0,0,0,0,3,3,0,0
0,0,0,3,3,3,0,0
0,4,0,3,3,3,3,0
2,3,3,3,3,3,3,0
0,5,3,3,3,3,3,0
0,0,0,3,3,3,0,0
0,0,0,2,3,1,0,0
0,0,0,0,6,0,0,0
:endlayer
layer: 4
0,0,0,7,0,0,0,0
0,0,7,7,10,7,0,0
0,7,7,10,10,3,7,0
7,7,9,3,10,9,9,0
2,8,3,8,8,3,1,9
7,7,1,9,10,8,1,0
0,7,7,3,10,8,7,7
0,0,7,2,8,0,7,0
0,0,0,0,0,0,0,0
:endlayer
layer: 5
0,0,0,0,7,0,0,0
0,0,4,12,9,13,0,0
0,2,7,9,10,8,7,0
0,7,3,3,8,10,9,0
2,1,8,1,10,9,10,10
2,7,3,10,10,10,9,0
0,11,7,8,10,3,7,14
0,0,2,2,1,0,14,0
0,0,0,0,0,0,0,0
:endlayer
layer: 6
0,0,0,0,7,0,0,0
0,0,4,12,3,13,0,0
0,2,7,9,3,8,7,0
0,2,10,1,8,3,10,0
2,9,3,8,3,10,3,8
2,7,3,3,10,3,8,0
0,5,11,9,10,8,7,14
0,0,2,7,3,0,14,0
0,0,0,0,0,0,0,0
:endlayer
layer: 7
0,0,0,0,15,0,0,0
0,0,4,4,8,13,0,0
0,2,7,10,9,9,13,0
0,2,1,1,1,10,10,7
2,1,1,3,1,8,10,1
2,7,1,10,8,9,10,0
0,5,11,3,1,8,5,14
0,0,0,7,8,7,14,0
0,0,0,0,0,0,0,0
:endlayer
layer: 8
0,0,0,0,7,0,0,0
0,0,4,4,18,4,0,0
0,2,15,10,10,8,4,0
0,2,1,9,1,10,8,7
0,16,8,8,8,10,3,19
2,7,9,9,3,1,9,0
0,5,11,8,10,10,5,14
0,0,0,7,17,7,14,0
0,0,0,0,0,0,0,0
:endlayer
layer: 9
0,0,0,0,0,0,0,0
0,0,4,4,7,4,0,0
0,2,15,8,10,15,4,0
0,0,9,10,10,9,8,7
0,0,3,10,8,3,3,0
2,7,1,9,10,1,10,0
0,5,5,8,9,9,5,14
0,0,0,7,5,7,5,0
0,0,0,0,0,0,0,0
:endlayer
layer: 10
0,0,0,0,0,0,0,0
0,0,0,4,0,0,0,0
0,0,0,7,10,1,4,0
0,0,9,1,1,1,10,20
0,0,8,10,1,8,8,15
2,7,1,9,10,10,1,0
0,0,5,7,8,10,7,14
0,0,0,0,5,5,5,0
0,0,0,0,0,0,0,0
:endlayer
layer: 11
0,0,0,0,0,0,0,0
0,0,0,4,0,0,0,0
0,0,0,7,19,8,4,0
0,0,1,7,8,3,1,20
0,7,3,10,9,9,15,0
0,0,3,1,10,1,8,15
0,0,5,5,7,9,15,14
0,0,0,0,5,5,5,0
0,0,0,0,0,0,0,0
:endlayer
layer: 12
0,0,0,0,0,0,0,0
0,0,0,0,0,0,0,0
0,0,0,0,0,0,4,0
0,0,21,0,7,7,9,20
0,0,10,7,8,9,0,0
0,0,0,7,8,8,19,0
0,0,0,5,0,9,15,20
0,0,0,0,0,5,5,0
0,0,0,0,0,0,0,0
:endlayer
layer: 13
0,0,0,0,0,0,0,0
0,0,0,0,0,0,0,0
0,0,0,0,0,0,4,0
0,0,0,0,0,2,15,20
0,0,0,22,15,9,23,0
0,0,0,0,15,9,0,0
0,0,0,0,0,15,0,0
0,0,0,0,0,5,0,0
0,0,0,0,0,0,0,0
:endlayer
layer: 14
0,0,0,0,0,0,0,0
0,0,0,0,0,0,0,0
0,0,0,0,0,0,0,0
0,0,0,0,0,0,0,0
0,0,0,0,0,16,0,0
0,0,0,0,0,15,0,0
0,0,0,0,0,0,0,0
0,0,0,0,0,0,0,0
0,0,0,0,0,0,0,0
:endlayer
layer: 15
0,0,0,0,0,0,0,0
0,0,0,0,0,0,0,0
0,0,0,0,0,0,0,0
0,0,0,0,0,0,0,0
0,0,0,0,0,0,0,0
0,0,0,0,0,0,0,0
0,0,0,0,0,0,0,0
0,0,0,0,0,0,0,0
0,0,0,0,0,0,0,0
:endlayer
layer: 16
0,0,0,0,0,0,0,0
0,0,0,0,0,0,0,0
0,0,0,0,0,0,0,0
0,0,0,0,0,0,0,0
0,0,0,0,0,0,0,0
0,0,0,0,0,0,0,0
0,0,0,0,0,0,0,0
0,0,0,0,0,0,0,0
0,0,0,0,0,0,0,0
:endlayer
layer: 17
0,0,0,0,0,0,0,0
0,0,0,0,0,0,0,0
0,0,0,0,0,0,0,0
0,0,0,0,0,0,0,0
0,0,0,0,0,0,0,0
0,0,0,0,0,0,0,0
0,0,0,0,0,0,0,0
0,0,0,0,0,0,0,0
0,0,0,0,0,0,0,0
:endlayer
layer: 18
0,0,0,0,0,0,0,0
0,0,0,0,0,0,0,0
0,0,0,0,0,0,0,0
0,0,0,0,0,0,0,0
0,0,0,0,0,0,0,0
0,0,0,0,0,0,0,0
0,0,0,0,0,0,0,0
0,0,0,0,0,0,0,0
0,0,0,0,0,0,0,0
:endlayer
layer: 19
0,0,0,0,0,0,0,0
0,0,0,0,0,0,0,0
0,0,0,0,0,0,0,0
0,0,0,0,0,0,0,0
0,0,0,0,0,0,0,0
0,0,0,0,0,0,0,0
0,0,0,0,0,0,0,0
0,0,0,0,0,0,0,0
0,0,0,0,0,0,0,0
:endlayer
layer: 20
0,0,0,0,0,0,0,0
0,0,0,0,0,0,0,0
0,0,0,0,0,0,0,0
0,0,0,0,0,0,0,0
0,0,0,0,0,0,0,0
0,0,0,0,0,0,0,0
0,0,0,0,0,0,0,0
0,0,0,0,0,0,0,0
0,0,0,0,0,0,0,0
:endlayer
layer: 21
0,0,0,0,0,0,0,0
0,0,0,0,0,0,0,0
0,0,0,0,0,0,0,0
0,0,0,0,0,0,0,0
0,0,0,0,0,0,0,0
0,0,0,0,0,0,0,0
0,0,0,0,0,0,0,0
0,0,0,0,0,0,0,0
0,0,0,0,0,0,0,0
:endlayer
layer: 22
0,0,0,0,0,0,0,0
0,0,0,0,0,0,0,0
0,0,0,0,0,0,0,0
0,0,0,0,0,0,0,0
0,0,0,0,0,0,0,0
0,0,0,0,0,0,0,0
0,0,0,0,0,0,0,0
0,0,0,0,0,0,0,0
0,0,0,0,0,0,0,0
:endlayer
layer: 23
0,0,0,0,0,0,0,0
0,0,0,0,0,0,0,0
0,0,0,0,0,0,0,0
0,0,0,0,0,0,0,0
0,0,0,0,0,0,0,0
0,0,0,0,0,0,0,0
0,0,0,0,0,0,0,0
0,0,0,0,0,0,0,0
0,0,0,0,0,0,0,0
:endlayer
layer: 24
0,0,0,0,0,0,0,0
0,0,0,0,0,0,0,0
0,0,0,0,0,0,0,0
0,0,0,0,0,0,0,0
0,0,0,0,0,0,0,0
0,0,0,0,0,0,0,0
0,0,0,0,0,0,0,0
0,0,0,0,0,0,0,0
0,0,0,0,0,0,0,0
:endlayer
layer: 25
0,0,0,0,0,0,0,0
0,0,0,0,0,0,0,0
0,0,0,0,0,0,0,0
0,0,0,0,0,0,0,0
0,0,0,0,0,0,0,0
0,0,0,0,0,0,0,0
0,0,0,0,0,0,0,0
0,0,0,0,0,0,0,0
0,0,0,0,0,0,0,0
:endlayer
layer: 26
0,0,0,0,0,0,0,0
0,0,0,0,0,0,0,0
0,0,0,0,0,0,0,0
0,0,0,0,0,0,0,0
0,0,0,0,0,0,0,0
0,0,0,0,0,0,0,0
0,0,0,0,0,0,0,0
0,0,0,0,0,0,0,0
0,0,0,0,0,0,0,0
:endlayer
layer: 27
0,0,0,0,0,0,0,0
0,0,0,0,0,0,0,0
0,0,0,0,0,0,0,0
0,0,0,0,0,0,0,0
0,0,0,0,0,0,0,0
0,0,0,0,0,0,0,0
0,0,0,0,0,0,0,0
0,0,0,0,0,0,0,0
0,0,0,0,0,0,0,0
:endlayer
layer: 28
0,0,0,0,0,0,0,0
0,0,0,0,0,0,0,0
0,0,0,0,0,0,0,0
0,0,0,0,0,0,0,0
0,0,0,0,0,0,0,0
0,0,0,0,0,0,0,0
0,0,0,0,0,0,0,0
0,0,0,0,0,0,0,0
0,0,0,0,0,0,0,0
:endlayer
layer: 29
0,0,0,0,0,0,0,0
0,0,0,0,0,0,0,0
0,0,0,0,0,0,0,0
0,0,0,0,0,0,0,0
0,0,0,0,0,0,0,0
0,0,0,0,0,0,0,0
0,0,0,0,0,0,0,0
0,0,0,0,0,0,0,0
0,0,0,0,0,0,0,0
:endlayer
layer: 30
0,0,0,0,0,0,0,0
0,0,0,0,0,0,0,0
0,0,0,0,0,0,0,0
0,0,0,0,0,0,0,0
0,0,0,0,0,0,0,0
0,0,0,0,0,0,0,0
0,0,0,0,0,0,0,0
0,0,0,0,0,0,0,0
0,0,0,0,0,0,0,0
:endlayer
layer: 31
0,0,0,0,0,0,0,0
0,0,0,0,0,0,0,0
0,0,0,0,0,0,0,0
0,0,0,0,0,0,0,0
0,0,0,0,0,0,0,0
0,0,0,0,0,0,0,0
0,0,0,0,0,0,0,0
0,0,0,0,0,0,0,0
0,0,0,0,0,0,0,0
:endlayer
layer: 32
0,0,0,0,0,0,0,0
0,0,0,0,0,0,0,0
0,0,0,0,0,0,0,0
0,0,0,0,0,0,0,0
0,0,0,0,0,0,0,0
0,0,0,0,0,0,0,0
0,0,0,0,0,0,0,0
0,0,0,0,0,0,0,0
0,0,0,0,0,0,0,0
:endlayer
layer: 33
0,0,0,0,0,0,0,0
0,0,0,0,0,0,0,0
0,0,0,0,0,0,0,0
0,0,0,0,0,0,0,0
0,0,0,0,0,0,0,0
0,0,0,0,0,0,0,0
0,0,0,0,0,0,0,0
0,0,0,0,0,0,0,0
0,0,0,0,0,0,0,0
:endlayer
layer: 34
0,0,0,0,0,0,0,0
0,0,0,0,0,0,0,0
0,0,0,0,0,0,0,0
0,0,0,0,0,0,0,0
0,0,0,0,0,0,0,0
0,0,0,0,0,0,0,0
0,0,0,0,0,0,0,0
0,0,0,0,0,0,0,0
0,0,0,0,0,0,0,0
:endlayer
layer: 35
0,0,0,0,0,0,0,0
0,0,0,0,0,0,0,0
0,0,0,0,0,0,0,0
0,0,0,0,0,0,0,0
0,0,0,0,0,0,0,0
0,0,0,0,0,0,0,0
0,0,0,0,0,0,0,0
0,0,0,0,0,0,0,0
0,0,0,0,0,0,0,0
:endlayer
layer: 36
0,0,0,0,0,0,0,0
0,0,0,0,0,0,0,0
0,0,0,0,0,0,0,0
0,0,0,0,0,0,0,0
0,0,0,0,0,0,0,0
0,0,0,0,0,0,0,0
0,0,0,0,0,0,0,0
0,0,0,0,0,0,0,0
0,0,0,0,0,0,0,0
:endlayer
layer: 37
0,0,0,0,0,0,0,0
0,0,0,0,0,0,0,0
0,0,0,0,0,0,0,0
0,0,0,0,0,0,0,0
0,0,0,0,0,0,0,0
0,0,0,0,0,0,0,0
0,0,0,0,0,0,0,0
0,0,0,0,0,0,0,0
0,0,0,0,0,0,0,0
:endlayer
layer: 38
0,0,0,0,0,0,0,0
0,0,0,0,0,0,0,0
0,0,0,0,0,0,0,0
0,0,0,0,0,0,0,0
0,0,0,0,0,0,0,0
0,0,0,0,0,0,0,0
0,0,0,0,0,0,0,0
0,0,0,0,0,0,0,0
0,0,0,0,0,0,0,0
:endlayer
layer: 39
0,0,0,0,0,0,0,0
0,0,0,0,0,0,0,0
0,0,0,0,0,0,0,0
0,0,0,0,0,0,0,0
0,0,0,0,0,0,0,0
0,0,0,0,0,0,0,0
0,0,0,0,0,0,0,0
0,0,0,0,0,0,0,0
0,0,0,0,0,0,0,0
:endlayer
layer: 40
0,0,0,0,0,0,0,0
0,0,0,0,0,0,0,0
0,0,0,0,0,0,0,0
0,0,0,0,0,0,0,0
0,0,0,0,0,0,0,0
0,0,0,0,0,0,0,0
0,0,0,0,0,0,0,0
0,0,0,0,0,0,0,0
0,0,0,0,0,0,0,0
:endlayer

#### RULES ####
rule:
plugin=vanillaBlocks
number=1
data:
JSON:{blockState:{blockName:"minecraft:cobblestone",properties:{}},buildPass:0}
:enddata
:endrule

rule:
plugin=vanillaBlocks
number=2
data:
JSON:{blockState:{blockName:"minecraft:vine",properties:{east:"false",south:"true",north:"false",west:"false",up:"false"}},buildPass:0}
:enddata
:endrule

rule:
plugin=vanillaBlocks
number=3
data:
JSON:{blockState:{blockName:"minecraft:stonebrick",properties:{variant:"stonebrick"}},buildPass:0}
:enddata
:endrule

rule:
plugin=vanillaBlocks
number=4
data:
JSON:{blockState:{blockName:"minecraft:vine",properties:{east:"false",south:"false",north:"false",west:"true",up:"false"}},buildPass:0}
:enddata
:endrule

rule:
plugin=vanillaBlocks
number=5
data:
JSON:{blockState:{blockName:"minecraft:vine",properties:{east:"true",south:"false",north:"false",west:"false",up:"false"}},buildPass:0}
:enddata
:endrule

rule:
plugin=blockTile
number=6
data:
JSON:{blockState:{blockName:"ancientwarfarestructure:structure_scanner_block",properties:{facing:"down"}},buildPass:0,teData:{boundsActive:1b,scannerInventory:{Size:1,Items:[{Slot:0,id:"ancientwarfarestructure:structure_scanner",Count:1b,tag:{include:1b,structureName:"PMMOBSSwampRuin4",structData:{buildKey:{face:5b,key:-70362033289908L},pos1:-70637112523449L,pos2:-68435404913330L}},Damage:0s}]},facing:4b,id:"ancientwarfarestructure:structure_scanner_block_tile"}}
:enddata
:endrule

rule:
plugin=vanillaBlocks
number=7
data:
JSON:{blockState:{blockName:"minecraft:leaves",properties:{check_decay:"false",decayable:"false",variant:"jungle"}},buildPass:0}
:enddata
:endrule

rule:
plugin=vanillaBlocks
number=8
data:
JSON:{blockState:{blockName:"minecraft:stonebrick",properties:{variant:"cracked_stonebrick"}},buildPass:0}
:enddata
:endrule

rule:
plugin=vanillaBlocks
number=9
data:
JSON:{blockState:{blockName:"minecraft:mossy_cobblestone",properties:{}},buildPass:0}
:enddata
:endrule

rule:
plugin=vanillaBlocks
number=10
data:
JSON:{blockState:{blockName:"minecraft:stonebrick",properties:{variant:"mossy_stonebrick"}},buildPass:0}
:enddata
:endrule

rule:
plugin=vanillaBlocks
number=11
data:
JSON:{blockState:{blockName:"minecraft:vine",properties:{east:"true",south:"true",north:"false",west:"false",up:"false"}},buildPass:0}
:enddata
:endrule

rule:
plugin=vanillaBlocks
number=12
data:
JSON:{blockState:{blockName:"minecraft:vine",properties:{east:"false",south:"true",north:"false",west:"true",up:"false"}},buildPass:0}
:enddata
:endrule

rule:
plugin=vanillaBlocks
number=13
data:
JSON:{blockState:{blockName:"minecraft:vine",properties:{east:"false",south:"false",north:"true",west:"true",up:"false"}},buildPass:0}
:enddata
:endrule

rule:
plugin=vanillaBlocks
number=14
data:
JSON:{blockState:{blockName:"minecraft:vine",properties:{east:"true",south:"false",north:"true",west:"false",up:"false"}},buildPass:0}
:enddata
:endrule

rule:
plugin=vanillaBlocks
number=15
data:
JSON:{blockState:{blockName:"minecraft:leaves",properties:{check_decay:"true",decayable:"false",variant:"jungle"}},buildPass:0}
:enddata
:endrule

rule:
plugin=vanillaBlocks
number=16
data:
JSON:{blockState:{blockName:"minecraft:stone_slab",properties:{half:"bottom",variant:"cobblestone"}},buildPass:0}
:enddata
:endrule

rule:
plugin=vanillaBlocks
number=17
data:
JSON:{blockState:{blockName:"minecraft:stone_brick_stairs",properties:{half:"bottom",shape:"straight",facing:"north"}},buildPass:0}
:enddata
:endrule

rule:
plugin=vanillaBlocks
number=18
data:
JSON:{blockState:{blockName:"minecraft:stone_stairs",properties:{half:"bottom",shape:"straight",facing:"south"}},buildPass:0}
:enddata
:endrule

rule:
plugin=vanillaBlocks
number=19
data:
JSON:{blockState:{blockName:"minecraft:stone_slab",properties:{half:"bottom",variant:"stone_brick"}},buildPass:0}
:enddata
:endrule

rule:
plugin=vanillaBlocks
number=20
data:
JSON:{blockState:{blockName:"minecraft:vine",properties:{east:"false",south:"false",north:"true",west:"false",up:"false"}},buildPass:0}
:enddata
:endrule

rule:
plugin=vanillaBlocks
number=21
data:
JSON:{blockState:{blockName:"minecraft:stone_brick_stairs",properties:{half:"bottom",shape:"straight",facing:"south"}},buildPass:0}
:enddata
:endrule

rule:
plugin=vanillaSkull
number=22
data:
JSON:{blockState:{blockName:"minecraft:skull",properties:{nodrop:"false",facing:"up"}},buildPass:0,skullRotation:10,teData:{Owner:{Id:"a865c038-0012-4337-ba85-1316083a2be3",Properties:{textures:[{Value:"eyJ0ZXh0dXJlcyI6eyJTS0lOIjp7InVybCI6Imh0dHA6Ly90ZXh0dXJlcy5taW5lY3JhZnQubmV0L3RleHR1cmUvNzk3OTMyNmNkZGMzNTU2NWFkYTg2Zjk3Yzg3OWVmNzViYzYyZmY5MjBiMTY4YTI0OWVlMDU2NjI0MThhMSJ9fX0="}]}},Rot:14b,id:"minecraft:skull",SkullType:3b}}
:enddata
:endrule

rule:
plugin=vanillaBlocks
number=23
data:
JSON:{blockState:{blockName:"minecraft:stone_brick_stairs",properties:{half:"top",shape:"straight",facing:"west"}},buildPass:0}
:enddata
:endrule

#### ENTITIES ####
