# Ancient Warfare Structure Template File
# Auto-generated structure template file. created on: 11/20/2018 at: 6:28:41
# Lines beginning with # denote comments

header:
version=2.7
name=OrcRuinedCastleOakWoodsGeneric
mods=
size=46,75,41
offset=25,15,40
:endheader

#### VALIDATION ####
validation:
type=ground
survival=false
worldGenEnabled=true
unique=false
preserveBlocks=false
selectionWeight=100
clusterValue=60
minDuplicateDistance=1000
dimensionWhiteList=false
dimensionList=
biomeWhiteList=true
biomeList=minecraft:swampland,biomesoplenty:woodland,biomesoplenty:dead_swamp,biomesoplenty:dead_forest,traverse:woodlands,minecraft:forest,traverse:rocky_plains,traverse:badlands,minecraft:ice_flats,biomesoplenty:steppe,traverse:rocky_plateau
leveling=7
fill=4
border=7
blockSwap=true
data:
:enddata
:endvalidation

#### LAYERS ####
layer: 0
1,1,1,1,1,1,1,1,1,1,1,1,1,1,1,1,1,1,1,1,1,1,1,1,1,1,1,1,1,1,1,1,1,1,1,1,1,1,1,1,1,1,1,1,1,1
1,1,1,1,1,1,1,1,1,1,1,1,1,1,1,1,1,1,1,1,1,1,1,1,1,1,1,1,1,1,1,1,1,1,1,1,1,1,1,1,1,1,1,1,1,1
1,1,1,1,1,1,1,1,1,1,1,1,1,1,1,1,1,1,1,1,1,1,1,1,1,1,1,1,1,1,1,1,1,1,1,1,1,1,1,1,1,1,1,1,1,1
1,1,1,1,1,1,1,1,1,1,1,1,1,1,1,1,1,1,1,1,1,1,1,1,1,1,1,1,1,1,1,1,1,1,1,1,1,1,1,1,1,1,1,1,1,1
1,1,1,1,1,1,1,1,1,5,5,1,1,1,1,1,1,1,1,1,1,1,1,1,1,1,1,1,1,1,1,1,1,1,1,1,1,1,1,1,1,1,1,1,1,1
1,1,1,1,1,1,1,1,1,1,1,1,1,1,1,1,1,1,1,1,1,1,1,1,1,1,1,1,1,1,1,1,1,1,1,1,1,1,1,1,1,1,1,1,1,1
1,1,1,1,1,1,1,1,1,1,1,1,1,1,1,1,1,1,1,1,1,1,1,1,1,1,1,1,1,1,1,1,1,1,1,1,1,1,1,1,1,1,1,1,1,1
1,1,1,1,1,1,1,1,1,1,1,1,1,1,1,1,1,1,1,1,1,1,1,1,1,1,1,1,1,1,1,1,1,1,1,1,1,1,1,1,1,1,1,1,1,1
1,1,1,1,1,1,1,1,1,1,1,1,1,1,1,1,1,1,1,1,1,1,1,1,1,1,1,1,1,1,1,1,1,1,1,1,1,1,1,1,1,1,1,1,1,1
1,1,1,1,1,1,1,1,1,1,1,1,1,1,1,1,1,1,1,1,1,1,1,1,1,1,1,1,1,1,1,1,1,1,1,1,1,1,1,1,1,1,1,1,1,1
1,1,1,1,1,1,1,1,1,1,1,1,1,1,1,1,1,1,1,1,1,1,1,1,1,1,1,1,1,1,1,1,1,1,1,1,1,1,1,1,1,1,1,1,1,1
1,1,1,1,1,1,1,1,1,1,1,1,1,1,1,1,1,1,1,1,1,1,1,1,1,1,1,1,1,1,1,1,1,1,1,1,1,1,1,1,1,1,1,1,1,1
1,1,1,1,1,1,1,1,1,1,1,1,1,1,1,1,1,1,1,1,1,1,1,1,1,1,1,1,1,1,1,1,1,1,1,1,1,1,1,1,1,1,1,1,1,1
1,1,1,1,1,1,1,1,1,1,1,1,1,1,1,1,1,1,1,1,1,1,1,1,1,1,1,1,1,1,1,1,1,1,1,1,1,1,1,1,1,1,1,1,1,1
1,1,1,1,1,1,1,1,1,1,1,1,1,1,1,1,1,1,1,1,1,1,1,1,1,1,1,1,1,1,1,1,1,1,1,1,1,1,1,1,1,1,1,1,1,1
1,1,1,1,1,1,1,1,1,1,1,1,1,1,1,1,1,1,1,1,1,1,1,1,1,1,1,1,1,1,1,1,1,1,1,1,1,1,1,1,1,1,1,1,1,1
1,1,1,1,1,1,1,1,1,1,1,1,1,1,1,1,1,1,1,1,1,1,1,1,1,1,1,1,1,1,1,1,1,1,1,1,1,1,1,1,1,1,1,1,1,1
1,1,1,1,1,1,1,1,1,1,1,1,1,1,1,1,1,1,1,1,1,1,1,1,1,1,1,1,1,1,1,1,1,1,1,1,1,1,1,1,1,1,1,1,1,1
1,1,1,1,1,1,1,1,1,1,1,1,1,1,1,1,1,1,1,1,1,1,1,1,1,1,1,1,1,1,1,1,1,1,1,1,1,1,1,1,1,1,1,1,1,1
1,1,1,1,1,1,1,1,1,1,1,1,1,1,1,1,1,1,1,1,1,1,1,1,1,1,1,1,1,1,1,1,1,1,1,1,1,1,1,1,1,1,1,1,1,1
1,1,1,1,1,1,1,1,1,1,1,1,1,1,1,1,1,1,1,1,1,1,1,1,1,1,1,1,1,1,1,1,1,1,1,1,1,1,1,1,1,1,1,1,1,1
1,1,1,1,1,1,1,1,1,1,1,1,1,1,1,1,1,1,1,1,1,1,1,1,1,1,1,1,1,1,1,1,1,1,1,1,1,1,1,1,1,1,1,1,1,1
1,1,1,1,1,1,1,1,1,1,1,1,1,1,1,1,1,1,1,1,1,1,1,1,1,1,1,1,1,1,1,1,1,1,1,1,1,1,1,1,1,1,1,1,1,1
1,1,1,1,1,1,1,1,1,1,1,1,1,1,1,1,1,1,1,1,1,1,1,1,1,1,1,1,1,1,1,1,1,1,1,1,1,1,1,1,1,1,1,1,1,1
1,1,1,1,1,1,1,1,1,1,1,1,1,1,1,1,1,1,1,1,1,1,1,1,1,1,1,1,1,1,1,1,1,1,1,1,1,1,1,1,1,1,1,1,1,1
1,1,1,1,1,1,1,1,1,1,1,1,1,1,1,1,1,1,1,1,1,1,1,1,1,1,1,1,1,1,1,1,1,1,1,1,1,1,1,1,1,1,1,1,1,1
1,1,1,1,1,1,1,1,1,1,1,1,1,1,1,1,1,1,1,1,1,1,1,1,1,1,1,1,1,1,1,1,1,1,1,1,1,1,1,1,1,1,1,1,1,1
1,1,1,1,1,1,1,1,1,1,1,1,1,1,1,1,1,1,1,1,1,1,1,1,1,1,1,1,1,1,1,1,1,1,1,1,1,1,1,1,1,1,1,1,1,1
1,1,1,1,1,1,1,1,1,1,1,1,1,1,1,1,1,1,1,1,1,1,1,1,1,1,1,1,1,2,1,1,1,1,1,1,1,1,1,1,1,1,1,1,1,1
1,1,1,1,1,1,1,1,1,1,1,1,1,1,1,1,1,1,1,1,1,1,1,1,1,1,1,1,1,2,1,1,1,1,1,1,1,1,1,1,1,1,1,1,1,1
1,1,1,1,1,1,1,1,1,1,1,1,1,1,1,1,1,1,1,1,1,1,1,1,1,1,1,1,1,2,1,1,1,1,1,1,1,1,1,1,1,1,1,1,1,1
1,1,1,1,1,1,1,1,1,1,1,1,1,1,1,1,1,1,1,1,1,1,1,1,1,1,1,1,1,1,1,1,1,1,1,1,1,1,1,1,1,1,1,1,1,1
1,1,1,1,1,1,1,1,1,1,1,1,1,1,1,1,1,1,1,1,1,1,1,1,1,1,1,1,1,1,1,1,1,1,1,1,1,1,1,1,1,1,1,1,1,1
1,1,1,1,1,1,1,1,1,1,1,1,1,1,1,1,1,1,1,1,1,1,1,1,1,1,1,1,1,1,1,1,1,1,1,1,1,1,1,1,1,1,1,1,1,1
1,1,1,1,1,1,1,1,1,1,1,1,1,1,1,1,1,1,1,1,1,1,1,1,1,1,1,1,1,1,1,1,1,1,1,1,1,1,1,1,1,1,1,1,1,1
1,1,1,1,1,1,1,1,1,1,1,1,1,1,1,1,1,1,1,1,1,1,1,1,1,1,1,1,1,3,1,1,1,1,1,1,1,1,1,1,1,1,1,1,1,1
1,1,1,1,1,1,1,1,1,1,1,1,1,1,1,1,1,1,1,1,1,1,1,1,1,1,1,1,1,4,1,1,1,1,1,1,1,1,1,1,1,1,1,1,1,1
1,1,1,1,1,1,1,1,1,1,1,1,1,1,1,1,1,1,1,1,1,1,1,1,1,1,1,1,1,1,1,1,1,1,1,1,1,1,1,1,1,1,1,1,1,1
1,1,1,1,1,1,1,1,1,1,1,1,1,1,1,1,1,1,1,1,1,1,1,1,1,1,1,1,1,1,1,1,1,1,1,1,1,1,1,1,1,1,1,1,1,1
1,1,1,1,1,1,1,1,1,1,1,1,1,1,1,1,1,1,1,1,1,1,1,1,1,1,1,1,1,1,1,1,1,1,1,1,1,1,1,1,1,1,1,1,1,1
1,1,1,1,1,1,1,1,1,1,1,1,1,1,1,1,1,1,1,1,1,1,1,1,1,1,1,1,1,1,1,1,1,1,1,1,1,1,1,1,1,1,1,1,1,1
:endlayer
layer: 1
0,0,0,0,0,0,0,0,0,0,0,0,0,0,0,0,0,0,0,0,0,0,0,0,0,0,0,0,0,0,0,0,0,0,0,0,0,0,0,0,0,0,0,0,0,0
0,6,6,6,6,6,6,6,6,6,6,6,6,6,6,6,6,6,6,6,6,6,6,0,0,0,6,6,6,6,6,6,6,6,6,6,6,6,6,6,6,6,6,6,6,0
0,6,6,6,6,6,6,6,6,6,6,6,6,6,6,6,6,6,6,6,6,6,6,0,0,0,6,6,6,6,6,6,6,6,6,6,6,6,6,6,6,6,6,6,6,0
0,6,6,1,1,1,1,1,1,1,1,1,1,1,1,1,1,1,1,1,1,1,1,52,1,28,1,1,1,1,1,1,1,1,1,1,1,1,1,1,1,1,1,1,6,0
0,6,6,1,89,0,0,0,1,79,79,7,0,56,0,56,0,56,0,56,56,1,54,0,1,0,45,1,0,0,0,0,0,23,1,7,7,7,7,7,7,7,7,1,6,0
0,6,6,1,0,0,0,0,37,80,80,37,0,56,0,56,0,56,0,0,0,1,0,0,1,0,0,1,0,0,0,0,0,23,1,7,8,8,8,8,8,8,7,1,6,0
0,6,6,1,0,0,0,0,0,86,0,0,0,0,0,0,0,0,0,0,0,1,0,0,1,0,0,1,0,0,0,0,0,23,1,7,8,8,8,8,8,8,7,1,6,0
0,6,6,1,0,0,0,0,0,0,0,0,0,72,0,0,0,0,0,0,41,55,41,0,0,0,41,44,41,0,32,0,0,23,1,7,8,8,9,1,8,8,7,1,6,0
0,6,6,1,0,0,0,0,1,0,81,1,75,0,1,0,0,1,0,0,0,1,0,0,0,0,0,1,0,0,0,0,0,23,1,7,8,8,8,1,8,8,7,1,6,0
0,6,6,1,0,0,0,0,0,0,0,0,0,0,0,0,0,0,0,56,56,1,0,0,0,0,0,1,0,0,0,0,0,23,1,7,8,8,8,8,8,8,7,1,6,0
0,6,6,1,0,0,0,0,0,0,0,0,0,0,0,0,0,0,0,0,0,1,0,0,0,0,0,1,0,0,0,0,0,23,1,7,8,8,10,8,8,8,7,1,6,0
0,6,6,1,0,0,0,0,0,56,0,56,0,56,0,56,0,56,0,56,0,1,0,0,0,0,0,1,0,0,0,0,0,23,1,7,7,7,7,7,7,7,7,1,6,0
0,6,6,1,0,41,0,0,0,56,0,56,0,56,0,56,0,56,0,56,0,1,0,0,0,0,0,1,1,1,1,1,1,1,1,1,1,1,1,1,1,1,1,1,6,0
0,6,6,1,7,52,7,7,7,7,7,7,7,7,7,7,7,7,7,7,7,1,0,0,0,0,0,1,42,38,33,0,26,24,1,0,1,0,0,1,1,1,1,1,6,0
0,6,6,1,0,41,0,0,87,0,82,0,76,0,70,0,66,0,63,0,57,7,0,0,0,0,0,7,43,0,0,0,27,0,1,0,20,0,0,1,1,1,1,1,6,0
0,6,6,1,0,0,0,0,0,0,0,0,0,0,0,0,0,0,0,0,0,1,0,0,0,0,0,1,0,0,0,0,0,0,1,0,1,0,0,1,1,1,1,1,6,0
0,6,6,1,0,88,0,0,0,0,0,0,0,0,0,0,0,0,0,0,0,1,0,0,0,0,0,1,0,0,0,0,0,0,1,0,1,19,11,1,1,1,1,1,6,0
0,6,6,1,0,0,0,0,0,0,0,0,0,0,0,0,0,0,0,0,0,1,0,0,50,0,0,1,1,1,34,1,1,1,1,0,1,1,1,1,1,1,1,1,6,0
0,6,6,1,0,0,0,41,0,0,0,0,0,0,41,0,0,0,0,41,41,21,41,0,0,0,41,20,41,0,0,0,0,0,0,0,20,0,0,1,1,1,1,1,6,0
0,6,6,1,7,7,7,60,7,1,7,7,1,7,34,7,7,7,7,60,7,1,0,0,0,0,0,1,1,1,1,1,28,1,1,0,1,0,12,1,1,1,1,1,6,0
0,6,6,1,90,0,0,41,0,0,83,7,77,0,41,0,67,7,64,41,58,1,0,0,0,0,0,1,0,0,0,0,0,0,1,0,1,1,1,1,1,1,1,1,6,0
0,6,6,1,56,56,0,0,0,56,56,7,0,0,0,0,0,7,0,0,0,1,0,0,0,0,0,1,0,0,0,0,0,0,1,0,20,0,0,1,1,1,1,1,6,0
0,6,6,1,91,0,0,0,0,0,84,7,0,0,0,0,0,7,0,0,0,1,0,35,35,35,0,1,0,0,0,0,0,0,1,0,1,0,13,1,1,1,1,1,6,0
0,6,6,1,56,56,0,0,0,56,56,7,0,0,0,0,0,7,0,0,0,1,0,1,1,1,0,1,0,0,0,0,0,0,1,0,1,1,1,1,1,1,1,1,6,0
0,6,6,1,92,0,0,0,0,0,85,7,0,0,0,69,0,7,0,0,0,1,0,1,1,1,0,1,0,39,0,0,0,0,1,0,20,0,0,1,1,1,1,1,6,0
0,6,6,1,1,1,1,1,1,1,1,1,1,1,1,1,1,1,1,1,1,1,0,1,1,1,0,1,0,0,0,31,0,0,1,0,1,0,14,1,1,1,1,1,6,0
0,6,6,1,53,0,0,0,0,0,35,53,53,61,61,61,61,61,61,61,0,1,0,0,0,0,0,1,7,7,7,7,7,7,7,0,1,1,1,1,1,1,1,1,6,0
0,6,6,1,53,0,0,0,0,0,35,0,53,53,0,0,0,0,0,0,0,1,0,0,0,0,0,1,35,35,35,7,0,0,21,0,1,0,15,1,1,1,1,1,6,0
0,6,6,1,0,0,0,0,0,0,35,0,0,61,61,61,61,61,61,61,0,1,0,1,0,1,0,1,23,40,36,7,0,0,1,0,20,0,0,1,1,1,1,1,6,0
0,6,6,1,0,0,0,0,0,0,35,0,0,0,0,0,0,0,0,0,41,55,41,0,0,0,0,1,23,40,36,7,1,1,1,0,1,0,16,1,1,1,1,1,6,0
0,6,6,1,53,0,0,0,0,53,1,0,0,61,61,61,61,61,61,61,0,1,0,0,0,0,0,1,23,40,36,7,0,0,21,0,1,1,1,1,1,1,1,1,6,0
0,6,6,1,53,0,0,0,0,0,0,0,0,0,0,0,0,0,0,0,0,1,0,0,0,0,0,1,37,37,37,7,29,0,1,0,20,0,0,1,1,1,1,1,6,0
0,6,6,1,0,0,0,0,0,0,0,0,78,73,53,53,0,0,0,0,0,1,0,0,0,0,0,1,0,0,0,7,1,1,7,0,1,0,0,1,1,1,1,1,6,0
0,6,6,1,0,0,0,0,53,53,1,0,61,61,61,61,61,61,61,61,0,1,0,0,0,0,41,20,41,0,0,0,0,0,0,0,1,0,17,1,1,1,1,1,6,0
0,6,6,1,0,0,0,0,53,53,35,0,61,0,0,0,0,0,0,0,0,1,0,0,0,0,0,1,0,0,0,7,1,1,1,0,1,1,1,1,1,1,1,1,6,0
0,6,6,1,0,0,0,0,0,0,35,0,0,74,71,0,68,0,65,0,0,1,0,0,0,0,0,1,23,35,36,7,30,25,1,0,20,0,0,1,1,1,1,1,6,0
0,6,6,1,53,0,0,0,0,0,35,0,61,0,0,0,0,0,0,0,0,1,0,0,51,48,46,1,23,8,36,7,0,0,1,0,1,0,0,1,1,1,1,1,6,0
0,6,6,1,0,0,0,0,0,53,35,0,61,61,61,61,61,61,61,62,59,1,53,53,1,49,47,1,23,37,36,7,0,0,22,0,1,0,18,1,1,1,1,1,6,0
0,6,6,1,1,1,1,1,1,1,1,1,1,1,1,1,1,1,1,1,1,1,1,1,1,1,1,1,1,1,1,1,1,1,1,1,1,1,1,1,1,1,1,1,6,0
0,6,6,6,6,6,6,6,6,6,6,6,6,6,6,6,6,6,6,6,6,6,6,6,6,6,6,6,6,6,6,6,6,6,6,6,6,6,6,6,6,6,6,6,6,0
0,0,0,0,0,0,0,0,0,0,0,0,0,0,0,0,0,0,0,0,0,0,0,0,0,0,0,0,0,0,0,0,0,0,0,0,0,0,0,0,0,0,0,0,0,0
:endlayer
layer: 2
0,0,0,0,0,0,0,0,0,0,0,0,0,0,0,0,0,0,0,0,0,0,0,0,0,0,0,0,0,0,0,0,0,0,0,0,0,0,0,0,0,0,0,0,0,0
0,6,6,6,6,6,6,6,6,6,6,6,6,6,6,6,6,6,6,6,6,6,6,0,0,0,6,6,6,6,6,6,6,6,6,6,6,6,6,6,6,6,6,6,6,0
0,6,6,6,6,6,6,6,6,6,6,6,6,6,6,6,6,6,6,6,6,6,6,0,0,0,6,6,6,6,6,6,6,6,6,6,6,6,6,6,6,6,6,6,6,0
0,6,6,1,1,1,1,1,1,1,1,1,1,1,1,1,1,1,1,1,1,1,1,96,1,94,1,1,1,1,1,1,1,1,1,1,1,1,1,1,1,1,1,1,6,0
0,6,6,1,0,0,0,0,1,0,0,1,0,0,0,0,0,0,0,0,0,1,0,0,1,0,0,1,0,0,0,0,0,0,23,7,7,7,7,7,7,7,7,1,6,0
0,6,6,1,0,0,0,0,0,80,80,0,0,0,0,0,0,0,0,0,0,1,0,0,1,0,0,1,0,0,0,0,0,0,23,7,8,8,8,8,8,8,7,1,6,0
0,6,6,1,0,0,0,0,0,0,0,0,0,0,0,0,0,0,0,0,0,1,0,0,1,0,0,1,0,0,0,0,0,0,23,7,8,8,8,8,8,8,1,1,6,0
0,6,6,1,0,0,0,0,0,0,0,0,0,0,0,0,0,0,0,0,0,97,0,0,0,0,0,95,0,0,0,0,0,0,23,7,1,8,8,1,8,8,7,1,6,0
0,6,6,1,0,0,0,0,1,0,0,1,0,0,1,0,0,1,0,0,0,1,0,0,0,0,0,1,0,0,0,0,0,0,23,7,1,8,8,1,8,8,1,1,6,0
0,6,6,1,0,0,0,0,0,0,0,0,0,0,0,0,0,0,0,0,0,1,0,0,0,0,0,1,0,0,0,0,0,0,23,7,8,8,8,8,8,93,7,1,6,0
0,6,6,1,0,0,0,0,0,0,0,0,0,0,0,0,0,0,0,0,0,1,0,0,0,0,0,1,0,0,0,0,0,0,23,7,8,8,8,8,8,8,1,1,6,0
0,6,6,1,0,0,0,0,0,0,0,0,0,0,0,0,0,0,0,0,0,1,0,0,0,0,0,1,0,0,0,0,0,0,23,7,7,1,1,7,1,7,1,1,6,0
0,6,6,1,0,0,0,0,0,0,0,0,0,0,0,0,0,0,0,0,0,1,0,0,0,0,0,1,1,1,1,1,1,1,1,1,1,1,1,1,1,1,1,1,6,0
0,6,6,1,7,96,7,7,7,7,7,7,7,7,7,7,7,7,7,7,7,1,0,0,0,0,0,1,0,0,0,0,0,0,7,0,7,0,0,1,1,1,1,1,6,0
0,6,6,1,0,0,0,0,0,0,0,0,0,0,0,0,0,0,0,0,0,7,0,0,0,0,0,7,0,0,0,0,0,0,1,0,94,0,0,1,1,1,1,1,6,0
0,6,6,1,0,0,0,0,0,0,0,0,0,0,0,0,0,0,0,0,0,1,0,0,0,0,0,1,0,0,0,0,0,0,7,0,7,0,0,1,1,1,1,1,6,0
0,6,6,1,0,0,0,0,0,0,0,0,0,0,0,0,0,0,0,0,0,1,0,0,0,0,0,1,0,0,0,0,0,0,7,0,1,0,0,1,1,1,1,1,6,0
0,6,6,1,0,0,0,0,0,0,0,0,0,0,0,0,0,0,0,0,0,1,0,0,0,0,0,1,7,7,94,7,7,7,7,0,7,1,7,1,1,1,1,1,6,0
0,6,6,1,0,0,0,0,0,0,0,0,0,0,0,0,0,0,0,0,0,94,0,0,0,0,0,94,0,0,0,0,0,0,0,0,94,0,0,1,1,1,1,1,6,0
0,6,6,1,1,1,1,98,1,1,1,1,1,1,99,1,1,1,1,98,1,1,0,0,0,0,0,1,7,7,7,7,94,7,7,0,1,0,0,1,1,1,1,1,6,0
0,6,6,1,0,0,0,0,0,0,0,1,0,0,0,0,0,1,0,0,0,1,0,0,0,0,0,1,0,0,0,0,0,0,7,0,7,1,7,1,1,1,1,1,6,0
0,6,6,1,0,0,0,0,0,0,0,1,0,0,0,0,0,1,0,0,0,1,0,0,0,0,0,1,0,0,0,0,0,0,7,0,94,0,0,1,1,1,1,1,6,0
0,6,6,1,0,0,0,0,0,0,0,1,0,0,0,0,0,1,0,0,0,1,0,0,0,0,0,1,0,0,0,0,0,0,7,0,1,0,0,1,1,1,1,1,6,0
0,6,6,1,0,0,0,0,0,0,0,1,0,0,0,0,0,1,0,0,0,1,0,35,35,35,0,1,0,0,0,0,0,0,7,0,7,1,7,1,1,1,1,1,6,0
0,6,6,1,0,0,0,0,0,0,0,1,0,0,0,0,0,1,0,0,0,1,0,1,1,1,0,1,0,0,0,0,0,0,7,0,94,0,0,1,1,1,1,1,6,0
0,6,6,1,1,1,1,1,1,1,1,1,1,1,1,1,1,1,1,1,1,1,0,1,1,1,0,1,0,0,0,0,0,0,1,0,1,0,0,1,1,1,1,1,6,0
0,6,6,1,53,0,0,53,0,53,35,53,53,61,61,61,61,61,61,61,0,1,0,0,0,0,0,1,7,1,1,7,1,1,7,0,7,7,7,1,1,1,1,1,6,0
0,6,6,1,53,0,0,0,0,53,35,0,53,53,0,0,0,0,0,0,0,1,0,0,0,0,0,1,0,0,0,7,0,0,94,0,1,0,0,1,1,1,1,1,6,0
0,6,6,1,0,0,0,0,0,53,35,0,0,61,61,61,61,61,61,61,0,1,0,1,0,1,0,1,0,0,0,7,0,0,7,0,94,0,0,1,1,1,1,1,6,0
0,6,6,1,0,0,0,0,0,53,35,0,0,0,0,0,0,0,0,0,0,97,0,0,0,0,0,1,0,0,0,7,7,7,7,0,1,0,0,1,1,1,1,1,6,0
0,6,6,1,0,0,0,0,0,53,1,0,0,61,61,61,61,61,61,61,0,1,0,0,0,0,0,1,0,0,0,7,0,0,94,0,1,1,1,1,1,1,1,1,6,0
0,6,6,1,53,0,0,0,0,0,0,0,0,0,0,0,0,0,0,0,0,1,0,0,0,0,0,1,0,0,0,7,0,0,7,0,94,0,0,1,1,1,1,1,6,0
0,6,6,1,0,0,0,0,0,0,0,0,0,0,78,73,0,0,0,0,0,1,0,0,0,0,0,1,0,0,0,7,1,1,7,0,1,0,0,1,1,1,1,1,6,0
0,6,6,1,0,0,0,0,53,53,7,0,61,61,61,61,61,61,61,61,0,7,0,0,0,0,0,94,0,0,0,0,0,0,0,0,1,0,0,1,1,1,1,1,6,0
0,6,6,1,0,0,0,0,0,0,35,0,61,0,0,0,0,0,0,0,0,1,0,0,0,0,0,1,0,0,0,7,1,1,7,0,7,1,1,1,1,1,1,1,6,0
0,6,6,1,0,0,0,0,0,0,35,0,0,0,0,0,0,0,0,0,0,1,0,0,0,0,0,1,0,0,0,1,0,0,7,0,94,0,0,1,1,1,1,1,6,0
0,6,6,1,53,0,0,0,0,0,35,0,61,0,0,0,0,0,0,0,0,1,0,0,0,0,0,1,0,0,0,1,0,0,7,0,7,0,0,1,1,1,1,1,6,0
0,6,6,1,53,0,0,0,0,53,35,0,61,61,61,61,61,61,61,0,0,1,0,53,1,0,0,1,0,0,0,7,0,0,94,0,7,0,0,1,1,1,1,1,6,0
0,6,6,1,1,1,1,1,1,1,1,1,1,1,1,1,1,1,1,1,1,1,53,1,1,1,1,1,1,1,1,1,1,1,1,1,1,1,1,1,1,1,1,1,6,0
0,6,6,6,6,6,6,6,6,6,6,6,6,6,6,6,6,6,6,6,6,6,6,6,6,6,6,6,6,6,6,6,6,6,6,6,6,6,6,6,6,6,6,6,6,0
0,0,0,0,0,0,0,0,0,0,0,0,0,0,0,0,0,0,0,0,0,0,0,0,0,0,0,0,0,0,0,0,0,0,0,0,0,0,0,0,0,0,0,0,0,0
:endlayer
layer: 3
0,0,0,0,0,0,0,0,0,0,0,0,0,0,0,0,0,0,0,0,0,0,0,0,0,0,0,0,0,0,0,0,0,0,0,0,0,0,0,0,0,0,0,0,0,0
0,6,6,6,6,6,6,6,6,6,6,6,6,6,6,6,6,6,6,6,6,6,6,0,0,0,6,6,6,6,6,6,6,6,6,6,6,6,6,6,6,6,6,6,6,0
0,6,6,6,6,6,6,6,6,6,6,6,6,6,6,6,6,6,6,6,6,6,6,0,0,0,6,6,6,6,6,6,6,6,6,6,6,6,6,6,6,6,6,6,6,0
0,6,6,1,1,1,1,1,1,1,1,1,1,1,1,1,1,1,1,1,1,1,1,110,1,110,1,1,1,1,1,1,1,1,1,1,1,1,1,1,1,1,1,1,6,0
0,6,6,1,0,0,0,0,1,0,0,7,0,0,0,0,0,0,0,0,0,1,1,1,1,1,1,1,0,0,0,0,0,0,0,0,0,0,0,0,0,0,0,1,6,0
0,6,6,1,0,0,0,0,0,0,0,0,0,0,0,0,0,0,0,0,0,1,1,7,111,7,1,1,0,0,0,0,0,0,0,0,0,0,0,0,0,0,0,1,6,0
0,6,6,1,0,0,0,0,0,0,0,0,0,0,0,0,0,0,0,0,0,1,1,1,1,1,1,1,0,0,0,0,0,0,0,0,0,0,0,0,0,0,0,1,6,0
0,6,6,1,0,0,0,0,0,0,0,0,0,0,0,0,0,0,0,0,0,1,106,0,0,0,105,1,0,0,0,0,0,0,0,0,0,0,0,1,0,0,0,1,6,0
0,6,6,1,0,0,0,0,1,0,0,1,0,0,1,0,0,1,0,0,0,1,0,0,0,0,0,1,0,0,0,0,0,0,0,0,0,0,0,1,0,0,0,1,6,0
0,6,6,1,0,0,0,0,0,0,0,0,0,0,0,0,0,0,0,0,0,1,0,0,0,0,0,1,0,0,0,0,0,0,0,0,0,0,0,0,0,0,0,1,6,0
0,6,6,1,0,0,0,0,0,0,0,0,0,0,0,0,0,0,0,0,0,1,0,0,0,0,0,1,0,0,0,0,0,0,0,0,0,0,0,0,0,0,0,1,6,0
0,6,6,1,0,0,0,0,0,0,0,0,0,0,0,0,0,0,0,0,0,1,0,0,0,0,0,1,0,0,0,0,0,0,0,0,0,0,0,0,0,41,0,1,6,0
0,6,6,1,0,0,0,0,0,0,0,0,0,0,0,0,0,0,0,0,0,1,0,0,0,0,0,1,1,1,1,1,1,1,1,1,1,1,1,1,1,102,1,1,6,0
0,6,6,1,7,7,7,7,7,7,7,7,7,7,7,7,7,7,7,7,7,1,0,0,0,0,0,1,0,0,0,0,0,0,1,0,1,0,0,1,0,41,0,1,6,0
0,6,6,1,0,109,0,0,0,0,0,0,0,0,0,0,0,0,0,0,0,1,0,0,0,0,0,1,0,0,0,0,0,0,1,105,1,0,0,1,0,0,0,1,6,0
0,6,6,1,0,0,0,0,0,0,0,0,0,0,0,0,0,0,0,0,0,1,0,0,0,0,0,1,0,0,0,0,0,0,7,0,1,0,0,1,0,0,0,1,6,0
0,6,6,1,0,0,0,0,0,0,0,0,0,0,0,0,0,0,0,0,0,1,0,0,0,0,0,1,0,0,0,0,0,0,7,0,1,0,0,1,0,0,0,1,6,0
0,6,6,1,0,0,0,0,0,0,0,0,0,0,0,0,0,0,0,0,0,1,0,0,0,0,0,1,7,7,7,7,7,7,7,0,1,1,1,1,0,0,0,1,6,0
0,6,6,1,0,0,0,108,0,0,0,0,0,53,108,0,0,0,0,108,105,1,106,0,0,0,105,1,0,0,109,0,108,0,0,105,1,0,0,1,0,0,0,1,6,0
0,6,6,1,1,1,1,7,1,1,1,7,1,1,1,1,1,1,1,1,1,1,0,0,0,0,0,1,7,7,7,7,7,7,7,0,1,0,0,1,0,0,0,1,6,0
0,6,6,1,0,0,0,0,0,0,0,1,0,0,0,0,0,1,0,0,0,1,0,0,0,0,0,1,0,0,0,0,0,0,7,0,1,1,1,1,0,0,0,1,6,0
0,6,6,1,0,0,0,0,0,0,0,1,0,0,0,0,0,1,0,0,0,1,0,0,0,0,0,1,0,0,0,0,0,0,7,105,1,0,0,1,0,41,0,1,6,0
0,6,6,1,0,0,0,0,0,0,0,1,0,0,0,0,0,1,0,0,0,1,0,0,0,0,0,1,0,0,0,0,0,0,7,0,1,0,0,1,1,60,1,1,6,0
0,6,6,1,0,0,0,0,0,0,0,1,0,0,0,0,0,1,0,0,0,1,0,0,0,0,0,1,0,0,0,0,0,0,7,0,1,1,1,1,0,41,0,1,6,0
0,6,6,1,0,0,0,0,0,0,0,1,0,0,0,0,0,1,0,0,0,1,7,35,35,35,7,1,0,0,0,0,0,0,7,105,1,0,0,1,0,0,0,1,6,0
0,6,6,1,1,1,1,1,1,1,1,1,1,1,1,1,1,1,1,1,1,1,7,1,1,1,7,1,0,0,0,0,0,0,1,0,1,0,0,1,0,41,0,1,6,0
0,6,6,1,53,0,0,53,0,0,35,53,53,61,61,61,61,61,61,61,112,1,7,0,0,0,7,1,7,1,1,7,1,1,7,0,7,7,7,1,7,28,7,1,6,0
0,6,6,1,0,0,0,0,0,0,35,0,0,53,0,0,0,0,0,0,0,1,7,0,0,0,7,1,0,0,0,7,0,0,1,106,1,0,0,1,7,41,7,1,6,0
0,6,6,1,0,0,0,0,0,0,35,0,0,61,61,61,61,61,61,61,0,1,7,1,7,1,7,1,0,0,0,7,0,0,1,105,1,0,0,7,103,0,0,1,6,0
0,6,6,1,0,0,0,0,0,53,35,0,0,0,0,0,0,0,0,0,105,1,106,0,0,0,0,1,0,0,0,7,7,7,1,0,1,0,0,1,7,0,0,1,6,0
0,6,6,1,0,0,0,0,0,53,1,0,0,61,61,61,61,61,61,61,0,1,0,0,0,0,0,1,0,0,0,7,0,0,7,106,1,1,1,1,1,0,0,1,6,0
0,6,6,1,53,0,0,0,0,0,1,114,0,0,0,0,0,0,0,0,0,1,0,0,0,0,0,1,0,0,0,7,0,0,7,105,1,0,0,1,1,0,0,1,6,0
0,6,6,1,0,0,0,0,0,0,1,114,0,0,0,0,78,73,0,0,0,1,0,0,0,0,0,1,0,0,0,7,1,1,7,0,1,0,0,1,1,0,0,1,6,0
0,6,6,1,0,0,0,0,0,53,35,0,61,61,61,61,61,61,61,61,0,1,0,0,0,0,105,1,0,0,0,0,0,0,0,0,1,0,0,1,1,0,0,1,6,0
0,6,6,1,0,0,0,0,0,53,35,0,61,0,0,0,0,0,0,0,0,1,0,0,0,0,0,1,0,0,0,7,1,1,7,0,7,1,1,1,37,0,0,1,6,0
0,6,6,1,0,0,0,0,0,0,35,0,0,0,0,0,0,0,0,0,113,1,0,0,0,0,0,1,0,0,0,1,0,0,7,105,7,0,0,1,0,0,0,1,6,0
0,6,6,1,0,0,0,0,0,0,35,0,61,0,0,0,0,0,0,0,0,1,0,0,0,0,0,1,0,0,0,1,0,0,7,0,7,0,0,1,7,28,7,1,6,0
0,6,6,1,53,0,0,0,0,53,35,115,61,61,61,61,61,61,61,61,61,1,53,0,1,0,0,1,0,0,0,7,0,0,7,107,7,0,0,1,104,101,101,100,6,0
0,6,6,1,1,1,1,1,1,1,1,1,1,1,1,1,1,1,1,1,1,1,1,1,1,1,1,1,1,1,1,1,1,1,1,1,1,1,1,1,1,1,1,1,6,0
0,6,6,6,6,6,6,6,6,6,6,6,6,6,6,6,6,6,6,6,6,6,6,6,6,6,6,6,6,6,6,6,6,6,6,6,6,6,6,6,6,6,6,6,6,0
0,0,0,0,0,0,0,0,0,0,0,0,0,0,0,0,0,0,0,0,0,0,0,0,0,0,0,0,0,0,0,0,0,0,0,0,0,0,0,0,0,0,0,0,0,0
:endlayer
layer: 4
6,6,6,6,6,6,6,6,6,6,6,6,6,6,6,6,6,6,6,6,6,6,6,6,6,6,6,6,6,6,6,6,6,6,6,6,6,6,6,6,6,6,6,6,6,6
6,6,6,6,6,6,6,6,6,6,6,6,6,6,6,6,6,6,6,6,6,6,6,6,6,6,6,6,6,6,6,6,6,6,6,6,6,6,6,6,6,6,6,6,6,6
6,6,6,6,6,6,6,6,6,6,6,6,6,6,6,6,6,6,6,6,6,6,6,6,6,6,6,6,6,6,6,6,6,6,6,6,6,6,6,6,6,6,6,6,6,6
6,6,6,1,1,1,1,1,1,1,1,1,1,1,1,1,1,1,1,1,1,1,1,1,1,1,1,1,1,1,1,1,1,1,1,1,1,1,1,1,1,1,1,1,6,6
6,6,6,1,0,0,0,0,7,0,0,1,0,0,0,0,0,0,0,0,0,1,0,0,1,0,0,1,0,0,0,0,0,0,0,0,0,0,0,0,0,0,0,1,6,6
6,6,6,1,0,0,0,0,0,0,0,0,0,0,0,0,0,0,0,0,0,80,0,0,0,0,0,80,0,0,0,0,0,0,0,0,0,0,0,0,0,0,0,1,6,6
6,6,6,1,0,0,0,0,0,0,0,0,0,0,0,0,0,0,0,0,0,80,121,1,1,1,118,80,0,0,0,0,0,0,0,0,0,0,0,0,0,0,0,1,6,6
6,6,6,1,0,0,0,0,0,0,0,0,0,0,0,0,0,0,0,0,0,80,0,0,0,0,0,1,0,0,0,0,0,0,0,0,0,0,0,1,0,0,0,1,6,6
6,6,6,1,0,0,0,0,1,0,0,1,0,0,1,0,0,1,0,0,0,80,0,0,0,0,0,80,0,0,0,0,0,0,0,0,0,0,0,1,0,0,0,1,6,6
6,6,6,1,0,0,0,0,0,0,0,0,0,0,0,0,0,0,0,0,0,80,0,0,0,0,0,80,0,0,0,0,0,0,0,0,0,0,0,0,0,0,0,1,6,6
6,6,6,1,0,0,0,0,0,0,0,0,0,0,0,0,0,0,0,0,0,80,0,0,0,0,0,80,0,0,0,0,0,0,0,0,0,0,0,0,0,0,0,1,6,6
6,6,6,1,0,0,0,0,0,0,0,0,0,0,0,0,0,0,0,0,0,80,0,0,0,0,0,7,0,0,0,0,0,0,0,0,0,0,0,0,0,0,0,1,6,6
6,6,6,1,0,0,0,0,0,0,0,0,0,0,0,0,0,0,0,0,0,7,0,0,0,0,0,1,1,1,1,1,1,1,1,1,1,1,1,1,1,116,1,1,6,6
6,6,6,1,7,7,7,7,7,7,7,7,7,7,7,7,7,7,7,7,7,7,0,0,0,0,0,1,0,0,0,0,0,0,1,7,1,1,1,1,0,0,0,1,6,6
6,6,6,1,0,0,0,0,0,0,0,0,0,0,0,0,0,0,0,0,0,80,0,0,0,0,0,1,0,0,0,0,0,0,1,1,1,1,1,1,0,0,0,1,6,6
6,6,6,1,0,0,0,0,0,0,0,0,0,0,0,0,0,0,0,0,0,80,0,0,0,0,0,1,0,0,0,0,0,0,1,1,1,1,1,1,0,0,0,1,6,6
6,6,6,1,0,0,0,0,0,0,0,0,0,0,0,0,0,0,0,0,0,80,0,0,0,0,0,1,0,0,0,0,0,0,7,1,1,1,1,1,0,0,0,1,6,6
6,6,6,1,0,0,0,0,0,0,0,0,0,0,0,0,0,0,0,0,0,80,0,0,0,0,0,1,80,80,80,80,80,80,7,1,1,1,1,1,0,0,0,1,6,6
6,6,6,1,0,0,0,0,0,0,0,0,0,53,0,0,0,0,0,0,0,1,0,0,0,0,0,1,0,0,0,0,0,0,7,1,1,1,1,1,0,0,0,1,6,6
6,6,6,1,7,7,7,1,1,7,7,7,1,7,1,7,1,1,7,7,7,7,0,0,0,0,0,1,80,80,80,80,80,80,7,1,1,1,1,1,0,0,0,1,6,6
6,6,6,1,0,0,0,0,0,0,0,1,0,0,0,0,0,1,0,0,0,80,0,0,0,0,0,1,0,0,0,0,0,0,1,1,1,1,1,1,0,0,0,1,6,6
6,6,6,1,0,0,0,0,0,0,0,1,0,0,0,0,0,1,0,0,0,80,0,0,0,0,0,1,0,0,0,0,0,0,1,1,1,1,1,1,0,0,0,1,6,6
6,6,6,1,0,0,0,0,0,0,0,1,0,0,0,0,0,1,0,0,0,80,0,0,0,0,0,1,0,0,0,0,0,0,1,1,1,1,1,1,1,98,1,1,6,6
6,6,6,1,0,0,0,0,0,0,0,1,0,0,0,0,0,1,0,0,0,80,0,0,0,0,0,1,0,0,0,0,0,0,1,1,1,1,1,1,0,0,0,1,6,6
6,6,6,1,0,0,0,0,0,0,0,1,0,0,0,0,0,1,0,0,0,80,122,0,0,0,119,1,0,0,0,0,0,0,1,1,1,1,1,1,0,0,0,1,6,6
6,6,6,1,1,1,1,1,1,1,1,1,1,1,1,1,1,1,1,1,1,1,0,35,35,35,0,1,0,0,0,0,0,0,1,1,1,1,1,1,0,0,0,1,6,6
6,6,6,1,53,0,0,124,0,53,35,53,0,61,61,61,61,61,61,61,0,80,0,1,1,1,0,7,7,1,1,7,1,1,7,7,7,7,7,1,7,94,7,1,6,6
6,6,6,1,0,0,0,0,0,0,35,0,0,53,0,0,0,0,0,0,0,80,0,1,1,1,0,80,0,0,0,7,0,0,7,0,7,0,0,1,7,0,7,1,6,6
6,6,6,1,126,0,0,0,0,0,35,0,0,61,61,61,61,61,61,61,0,80,80,1,120,1,80,80,0,0,0,7,0,0,7,0,7,0,0,1,0,0,0,1,6,6
6,6,6,1,0,0,0,0,53,53,35,0,0,0,0,0,0,0,0,0,0,80,0,0,0,0,0,80,0,0,0,7,7,7,7,0,7,0,0,1,7,0,0,1,6,6
6,6,6,1,0,0,0,0,0,0,35,0,0,61,61,61,61,61,61,61,0,80,0,0,0,0,0,80,0,0,0,7,0,0,7,0,7,7,7,1,1,0,0,1,6,6
6,6,6,1,53,0,0,0,0,53,35,0,0,0,0,0,0,0,0,0,0,80,0,0,0,0,0,80,0,0,0,7,0,0,7,0,7,0,0,1,1,0,0,1,6,6
6,6,6,1,0,0,0,0,0,53,35,0,0,0,0,0,0,0,78,73,0,80,0,0,0,0,0,80,0,0,0,7,1,1,7,0,1,0,0,1,1,0,0,1,6,6
6,6,6,1,0,0,0,0,0,0,35,0,61,61,61,61,61,61,61,61,61,1,0,0,0,0,0,1,0,0,0,1,0,0,7,0,1,0,0,1,37,0,0,1,6,6
6,6,6,1,0,0,0,0,0,0,35,0,61,0,0,0,0,0,0,0,0,80,0,0,0,0,0,80,0,0,0,7,1,1,7,0,7,1,7,1,0,0,0,1,6,6
6,6,6,1,0,0,0,0,0,0,35,0,0,0,0,0,0,0,0,0,0,80,0,0,0,0,0,80,0,0,0,1,0,0,7,0,1,0,0,1,0,0,0,1,6,6
6,6,6,1,0,0,0,0,0,0,35,0,61,0,0,0,0,0,0,0,0,80,0,0,0,0,0,80,0,0,0,1,0,0,7,0,1,0,0,1,7,94,7,1,6,6
6,6,6,1,0,0,125,0,123,0,35,0,61,61,61,61,61,61,61,61,61,1,0,0,1,0,0,1,0,0,0,7,0,0,7,0,7,0,0,117,0,0,0,0,6,6
6,6,6,1,1,1,1,1,1,1,1,1,1,1,1,1,1,1,1,1,1,1,1,1,1,1,1,1,1,1,1,1,1,1,1,1,1,1,1,1,1,1,1,1,6,6
6,6,6,6,6,6,6,6,6,6,6,6,6,6,6,6,6,6,6,6,6,6,6,6,6,6,6,6,6,6,6,6,6,6,6,6,6,6,6,6,6,6,6,6,6,6
6,6,6,6,6,6,6,6,6,6,6,6,6,6,6,6,6,6,6,6,6,6,6,6,6,6,6,6,6,6,6,6,6,6,6,6,6,6,6,6,6,6,6,6,6,6
:endlayer
layer: 5
6,6,6,6,6,6,6,6,6,6,6,6,6,6,6,6,6,6,6,6,6,6,6,6,6,6,6,6,6,6,6,6,6,6,6,6,6,6,6,6,6,6,6,6,6,6
6,6,6,6,6,6,6,6,6,6,6,6,6,6,6,6,6,6,6,6,6,6,6,6,6,6,6,6,6,6,6,6,6,6,6,6,6,6,6,6,6,6,6,6,6,6
6,6,6,6,6,6,6,6,6,6,6,6,6,6,6,6,6,6,6,6,6,6,6,6,6,6,6,6,6,6,6,6,6,6,6,6,6,6,6,6,6,6,6,6,6,6
6,6,6,1,1,1,1,1,1,1,1,1,1,1,1,1,1,1,1,1,1,1,1,1,1,1,1,1,1,1,1,1,1,1,1,1,1,1,1,1,1,1,1,1,6,6
6,6,6,1,0,0,0,0,7,0,0,1,0,0,0,0,0,0,0,0,0,1,0,0,1,0,0,1,0,0,0,0,0,0,0,0,0,0,0,0,0,0,0,1,6,6
6,6,6,1,0,0,0,0,132,132,132,132,0,0,0,0,0,0,0,0,0,1,0,0,0,0,0,1,0,0,0,0,0,0,0,0,0,0,0,0,0,0,0,1,6,6
6,6,6,1,0,0,0,0,0,0,0,0,0,0,0,0,0,0,0,0,0,1,0,0,1,0,0,1,0,0,0,0,0,0,0,0,0,0,0,0,0,0,0,1,6,6
6,6,6,1,0,0,0,0,0,0,0,0,0,0,0,0,0,0,0,0,0,1,0,0,0,0,0,1,0,0,0,0,0,0,0,0,0,0,0,127,0,0,0,1,6,6
6,6,6,1,0,0,0,0,1,0,0,1,0,0,1,0,0,1,0,0,0,1,0,0,0,0,0,1,0,0,0,0,0,0,0,0,0,0,0,128,0,0,0,1,6,6
6,6,6,1,0,0,0,0,0,0,0,0,0,0,0,0,0,0,0,0,0,1,0,0,0,0,0,1,0,0,0,0,0,0,0,0,0,0,0,0,0,0,0,1,6,6
6,6,6,1,0,0,0,0,0,0,0,0,0,0,0,0,0,0,0,0,0,1,0,0,0,0,0,1,0,0,0,0,0,0,0,0,0,0,0,0,0,0,0,1,6,6
6,6,6,1,0,0,0,0,0,0,0,0,0,0,0,0,0,0,0,0,0,1,0,0,0,0,0,1,0,0,0,0,0,0,0,0,0,0,0,0,0,0,0,1,6,6
6,6,6,1,0,0,0,0,0,0,0,0,0,0,0,0,0,0,0,0,0,1,0,0,0,0,0,1,1,1,1,1,1,1,1,1,1,7,1,1,1,1,1,1,6,6
6,6,6,1,7,7,7,7,7,7,7,7,7,7,7,7,7,7,7,7,7,1,0,0,0,0,0,80,0,0,0,0,0,0,80,0,0,0,129,1,0,0,0,1,6,6
6,6,6,1,53,0,0,0,0,0,0,53,0,0,0,0,0,0,0,0,0,1,0,0,0,0,0,80,0,0,0,0,0,0,80,0,0,0,0,80,0,0,0,1,6,6
6,6,6,1,0,0,0,0,0,0,0,0,0,0,0,0,0,0,0,0,0,1,0,0,0,0,0,80,0,0,0,0,0,0,80,0,0,0,0,1,0,0,0,1,6,6
6,6,6,1,0,0,0,0,0,0,0,0,0,0,0,0,0,0,0,0,0,1,0,0,0,0,0,80,0,0,0,0,0,0,80,0,0,0,0,80,0,0,0,1,6,6
6,6,6,1,0,0,0,0,0,0,0,0,0,0,0,0,0,0,0,0,0,1,0,0,0,0,0,80,80,80,80,80,80,80,1,0,0,0,0,1,0,0,0,1,6,6
6,6,6,1,0,0,0,0,0,0,0,0,0,53,53,0,0,0,0,0,0,1,0,0,0,0,0,1,0,0,0,0,0,0,36,0,0,0,0,80,0,0,0,1,6,6
6,6,6,1,1,1,1,1,1,1,1,1,1,1,1,1,1,1,1,1,1,1,0,0,0,0,0,80,80,80,80,80,80,80,1,0,0,0,0,1,0,0,0,1,6,6
6,6,6,1,1,1,1,1,1,1,1,1,1,1,1,1,1,1,1,1,1,1,0,0,0,0,0,80,0,0,0,0,0,0,80,0,0,0,0,80,0,0,0,1,6,6
6,6,6,1,1,1,1,1,1,1,1,1,1,1,1,1,1,1,1,1,1,1,0,0,0,0,0,80,0,0,0,0,0,0,80,0,0,0,0,1,0,0,0,1,6,6
6,6,6,1,1,1,1,1,1,1,1,1,1,1,1,1,1,1,1,1,1,1,0,0,0,0,0,80,0,0,0,0,0,0,80,0,0,0,0,1,1,1,1,1,6,6
6,6,6,1,1,1,1,1,1,1,1,1,1,1,1,1,1,1,1,1,1,1,0,0,0,0,0,80,0,0,0,0,0,0,80,0,0,0,0,1,0,0,0,1,6,6
6,6,6,1,1,1,1,1,1,1,1,1,1,1,1,1,1,1,1,1,1,1,0,0,0,0,0,80,0,0,0,0,0,0,80,0,0,0,0,1,0,0,0,1,6,6
6,6,6,1,1,1,1,1,1,1,1,1,1,1,1,1,1,1,1,1,1,1,0,0,0,0,0,80,0,0,0,0,0,0,1,0,1,35,7,1,0,0,0,1,6,6
6,6,6,1,0,0,0,0,0,0,35,53,0,61,61,61,61,61,61,61,0,1,0,35,35,35,0,1,7,80,7,7,7,1,7,80,1,7,1,1,7,108,7,1,6,6
6,6,6,1,0,0,0,0,0,0,35,0,0,53,0,0,0,0,0,0,0,1,0,1,1,1,0,1,0,0,0,7,7,7,7,0,1,1,1,1,7,7,7,1,6,6
6,6,6,1,0,0,0,0,0,0,35,0,0,61,61,61,61,61,61,61,0,1,80,1,0,1,80,1,0,0,0,7,7,7,7,130,1,1,1,1,7,109,0,1,6,6
6,6,6,1,0,0,0,0,0,0,35,0,0,0,0,0,0,0,0,0,0,1,0,0,0,0,0,1,0,0,0,7,7,7,7,130,1,1,1,1,7,0,0,1,6,6
6,6,6,1,0,0,0,0,0,0,35,0,0,61,61,61,61,61,61,61,73,1,0,0,0,0,0,1,0,0,0,7,7,7,7,130,1,1,1,1,1,0,0,1,6,6
6,6,6,1,0,0,0,0,0,0,35,0,0,0,0,0,0,0,0,0,131,1,0,0,0,0,0,1,0,0,0,7,7,7,7,1,1,1,1,1,1,0,0,1,6,6
6,6,6,1,0,0,0,0,0,0,35,0,0,0,0,0,0,0,0,0,78,1,0,0,0,0,0,1,0,0,0,7,1,1,7,130,1,1,1,1,37,0,0,1,6,6
6,6,6,1,133,0,0,0,0,0,35,0,61,61,61,61,61,61,61,61,131,1,0,0,0,0,0,1,0,0,0,1,0,0,7,130,1,1,1,1,0,0,0,1,6,6
6,6,6,1,0,0,0,0,0,0,35,0,61,0,0,0,0,0,0,61,131,1,0,0,0,0,0,1,0,0,0,7,7,7,7,130,1,1,1,1,0,0,0,1,6,6
6,6,6,1,0,0,0,0,0,0,35,0,61,0,0,0,0,0,0,61,131,1,0,0,0,0,0,1,0,0,0,1,7,7,7,130,1,1,1,1,0,108,0,1,6,6
6,6,6,1,0,0,0,0,0,0,35,0,61,0,0,0,0,0,0,61,131,1,0,0,53,0,0,1,0,0,0,1,7,7,7,130,1,1,1,1,7,1,1,1,6,6
6,6,6,1,0,0,0,0,0,0,35,0,61,61,61,61,61,61,61,61,131,1,53,0,1,0,0,1,0,0,0,7,7,7,7,1,1,1,1,1,0,0,0,1,6,6
6,6,6,1,1,1,1,1,1,1,1,1,1,1,1,1,1,1,1,1,1,1,1,1,1,1,1,1,1,1,1,1,1,1,1,1,1,1,1,1,1,1,1,1,6,6
6,6,6,6,6,6,6,6,6,6,6,6,6,6,6,6,6,6,6,6,6,6,6,6,6,6,6,6,6,6,6,6,6,6,6,6,6,6,6,6,6,6,6,6,6,6
6,6,6,6,6,6,6,6,6,6,6,6,6,6,6,6,6,6,6,6,6,6,6,6,6,6,6,6,6,6,6,6,6,6,6,6,6,6,6,6,6,6,6,6,6,6
:endlayer
layer: 6
6,6,6,6,6,6,6,6,6,6,6,6,6,6,6,6,6,6,6,6,6,6,6,6,6,6,6,6,6,6,6,6,6,6,6,6,6,6,6,6,6,6,6,6,6,6
6,6,6,6,6,6,6,6,6,6,6,6,6,6,6,6,6,6,6,6,6,6,6,6,6,6,6,6,6,6,6,6,6,6,6,6,6,6,6,6,6,6,6,6,6,6
6,6,6,6,6,6,6,6,6,6,6,6,6,6,6,6,6,6,6,6,6,6,6,6,6,6,6,6,6,6,6,6,6,6,6,6,6,6,6,6,6,6,6,6,6,6
6,6,6,1,1,1,1,1,1,1,1,1,1,1,1,1,1,1,1,1,1,1,1,1,1,1,1,1,1,1,1,1,1,1,1,1,1,1,1,1,1,1,1,1,6,6
6,6,6,1,0,0,0,0,7,1,1,7,0,0,7,0,0,7,0,0,0,1,0,0,1,0,0,1,0,0,0,0,0,0,0,0,0,0,0,0,0,0,0,1,6,6
6,6,6,1,0,0,0,0,7,1,1,7,0,0,7,0,0,7,0,0,0,1,0,0,0,0,0,1,0,0,0,0,0,0,0,0,0,0,0,0,0,0,0,1,6,6
6,6,6,1,0,0,0,0,7,0,0,7,0,0,7,0,0,7,0,0,0,1,0,0,1,0,0,1,0,0,0,0,0,0,0,0,0,0,0,0,0,0,0,1,6,6
6,6,6,1,0,0,0,0,7,0,0,7,0,0,7,0,0,7,0,0,0,1,0,0,0,0,0,1,0,0,0,0,0,0,0,0,0,0,0,0,0,0,0,1,6,6
6,6,6,1,7,7,7,7,7,7,7,7,7,7,7,7,7,7,7,7,7,1,0,0,0,0,0,1,0,0,0,0,0,0,0,0,0,0,0,0,0,0,0,1,6,6
6,6,6,1,0,0,0,0,7,0,0,7,0,0,7,0,0,7,0,0,0,1,0,0,0,0,0,1,0,0,0,0,0,0,0,0,0,0,0,0,0,0,0,1,6,6
6,6,6,1,0,0,0,0,7,0,0,7,0,0,7,0,0,7,0,0,0,1,0,0,0,0,0,1,0,0,0,0,0,0,0,0,0,0,0,0,0,0,0,1,6,6
6,6,6,1,0,0,0,0,7,0,0,7,0,0,7,0,0,7,0,0,0,1,0,0,0,0,0,1,0,0,0,0,0,0,0,0,0,0,0,0,0,0,0,1,6,6
6,6,6,1,0,0,0,0,7,0,0,7,0,0,7,0,0,7,0,0,0,1,0,0,0,0,0,1,1,1,1,1,1,1,1,80,1,80,1,1,1,1,1,1,6,6
6,6,6,1,7,7,7,7,7,7,7,7,7,7,7,7,7,7,7,7,7,1,0,0,0,0,0,1,0,0,0,0,0,0,0,0,0,0,0,1,0,0,0,1,6,6
6,6,6,1,1,80,80,80,7,80,80,7,80,80,7,80,80,7,80,80,7,1,0,0,0,0,0,1,0,0,0,0,0,0,0,0,0,0,0,80,0,0,0,1,6,6
6,6,6,1,7,80,80,80,7,80,80,7,80,80,7,80,80,7,80,80,7,1,0,0,0,0,0,1,0,0,0,0,0,0,0,0,0,0,0,1,0,0,0,1,6,6
6,6,6,1,7,80,80,80,7,80,80,7,80,80,7,80,80,7,80,80,7,1,0,0,0,0,0,1,0,0,0,0,0,0,0,0,0,0,0,80,0,0,0,1,6,6
6,6,6,1,7,80,80,80,7,80,80,7,80,80,7,80,80,7,80,80,7,1,1,1,1,1,1,1,1,1,1,1,1,1,1,0,0,0,0,1,0,0,0,1,6,6
6,6,6,7,7,7,7,7,37,7,7,7,7,7,37,7,7,37,7,7,1,1,1,1,7,1,1,1,1,1,1,1,1,36,0,0,0,0,0,80,0,0,0,1,6,6
6,6,6,1,1,159,0,0,0,156,155,143,152,152,0,149,149,0,0,0,37,1,1,1,1,1,1,1,1,1,1,1,1,1,1,0,0,0,0,1,0,0,0,1,6,6
6,6,6,1,161,160,0,0,0,0,155,0,0,152,0,149,0,0,0,0,0,1,0,0,0,0,0,1,0,0,0,0,0,0,0,0,0,0,0,80,0,0,0,1,6,6
6,6,6,1,162,0,0,0,0,0,0,0,0,0,0,0,0,0,0,0,0,1,0,0,0,0,0,1,0,0,0,0,0,0,0,0,0,0,0,1,0,0,0,1,6,6
6,6,6,1,163,0,0,0,0,0,0,0,0,0,0,0,0,0,0,0,0,1,0,0,0,0,0,1,0,0,0,0,0,0,0,0,0,0,0,1,7,7,7,1,6,6
6,6,6,1,143,0,0,150,0,0,0,150,0,0,0,150,0,0,0,0,0,1,0,0,0,0,0,1,0,0,0,0,0,0,0,0,0,0,0,1,7,7,7,1,6,6
6,6,6,1,7,159,0,158,0,157,0,154,0,153,0,151,0,148,1,0,0,1,0,0,0,0,0,1,0,0,0,0,0,0,0,0,0,0,0,1,7,0,7,1,6,6
6,6,6,1,1,1,1,1,1,1,1,1,1,1,1,1,1,1,1,1,1,1,0,0,0,0,0,1,0,0,0,0,0,0,1,0,1,0,7,1,7,7,7,1,6,6
6,6,6,1,0,0,0,0,0,0,35,53,0,61,61,61,61,61,61,61,78,1,0,0,0,0,0,1,7,1,1,7,7,7,1,7,1,28,1,1,7,37,7,1,6,6
6,6,6,1,0,0,0,0,0,0,35,0,0,78,78,78,78,78,78,78,78,1,0,35,35,35,0,1,0,0,0,7,142,140,139,138,135,0,135,1,0,0,134,1,6,6
6,6,6,1,0,0,0,0,0,0,35,0,0,78,78,78,78,78,78,78,78,1,80,1,0,1,80,1,0,0,0,7,0,0,0,0,0,0,0,1,0,0,0,1,6,6
6,6,6,1,0,0,0,0,0,0,35,0,0,78,78,78,78,78,78,78,78,1,0,0,0,0,0,1,0,0,0,7,143,0,0,0,0,0,0,1,0,0,0,1,6,6
6,6,6,1,0,0,0,0,0,0,35,0,0,78,78,78,78,78,78,78,78,1,0,0,0,0,0,1,0,0,0,7,144,0,0,0,0,0,0,1,0,0,0,1,6,6
6,6,6,1,0,0,0,0,0,0,35,0,0,78,78,78,78,78,78,78,0,1,0,0,0,0,0,1,0,0,0,7,145,0,0,0,0,0,0,22,0,0,0,1,6,6
6,6,6,1,0,0,0,0,0,0,35,0,0,78,78,78,78,0,0,0,0,1,0,0,0,0,0,1,0,0,0,7,1,1,7,0,0,0,0,1,0,0,0,1,6,6
6,6,6,1,0,0,0,0,0,0,35,0,78,78,78,78,78,78,78,78,0,1,0,0,0,0,0,1,0,0,0,1,0,0,80,0,0,0,0,1,0,0,0,1,6,6
6,6,6,1,0,0,53,53,0,0,35,0,78,78,78,78,78,78,78,78,78,1,0,0,0,0,0,1,0,0,0,7,7,7,7,0,0,0,0,1,0,0,0,1,6,6
6,6,6,1,0,0,0,53,0,0,35,0,78,78,78,78,78,78,78,78,78,1,0,0,0,0,0,1,0,0,0,1,146,141,0,0,0,0,0,1,0,0,0,1,6,6
6,6,6,1,0,0,0,53,53,0,35,0,78,78,78,78,78,78,78,78,78,1,0,0,53,0,0,1,0,0,0,1,147,0,0,0,136,0,136,1,1,1,1,1,6,6
6,6,6,1,0,0,0,0,53,53,35,0,61,61,61,61,61,61,61,61,78,1,0,0,1,0,0,1,0,0,0,1,146,141,0,0,137,0,137,1,0,0,0,1,6,6
6,6,6,1,1,1,1,1,1,1,1,1,1,1,1,1,1,1,1,1,1,1,1,1,1,1,1,1,1,1,1,1,1,1,1,1,1,1,1,1,1,1,1,1,6,6
6,6,6,6,6,6,6,6,6,6,6,6,6,6,6,6,6,6,6,6,6,6,6,6,6,6,6,6,6,6,6,6,6,6,6,6,6,6,6,6,6,6,6,6,6,6
6,6,6,6,6,6,6,6,6,6,6,6,6,6,6,6,6,6,6,6,6,6,6,6,6,6,6,6,6,6,6,6,6,6,6,6,6,6,6,6,6,6,6,6,6,6
:endlayer
layer: 7
6,6,6,6,6,6,6,6,6,6,6,6,6,6,6,6,6,6,6,6,6,6,6,6,6,6,6,6,6,6,6,6,6,6,6,6,6,6,6,6,6,6,6,6,6,6
6,6,6,6,6,6,6,6,6,6,6,6,6,6,6,6,6,6,6,6,6,6,6,6,6,6,6,6,6,6,6,6,6,6,6,6,6,6,6,6,6,6,6,6,6,6
6,6,6,6,6,6,6,6,6,6,6,6,6,6,6,6,6,6,6,6,6,6,6,6,6,6,6,6,6,6,6,6,6,6,6,6,6,6,6,6,6,6,6,6,6,6
6,6,6,1,1,1,1,1,1,1,1,1,1,1,1,1,1,1,1,1,1,1,1,1,1,1,1,1,1,1,1,1,1,1,1,1,1,1,1,1,1,1,1,1,6,6
6,6,6,1,0,0,0,0,0,1,1,0,0,0,176,0,0,0,0,0,0,1,0,0,1,0,0,1,0,0,0,0,0,0,0,0,0,0,0,0,0,0,0,1,6,6
6,6,6,1,0,0,0,0,0,0,0,0,0,0,0,0,0,0,0,0,0,1,0,0,1,0,0,1,0,0,0,0,0,0,0,0,0,0,0,0,0,0,0,1,6,6
6,6,6,1,0,0,0,0,0,0,0,0,0,0,0,0,0,0,0,0,0,1,0,0,1,0,0,1,0,0,0,0,0,0,0,0,0,0,0,0,0,0,0,1,6,6
6,6,6,1,0,0,0,0,0,0,0,0,0,0,0,0,0,0,0,0,0,1,0,0,0,0,0,1,0,0,0,0,0,0,0,0,0,0,0,0,0,0,0,1,6,6
6,6,6,0,181,0,0,0,0,0,0,0,0,0,0,0,0,0,0,0,111,1,0,0,0,0,0,1,0,0,0,0,0,0,0,0,0,0,0,0,0,0,0,1,6,6
6,6,6,1,0,0,0,0,0,0,0,0,0,0,0,0,0,0,0,0,0,1,0,0,0,0,0,1,0,0,0,0,0,0,0,0,0,0,0,0,0,0,0,1,6,6
6,6,6,1,0,0,0,0,0,0,0,179,0,0,0,0,0,174,0,0,0,1,0,0,0,0,0,1,0,0,0,0,0,0,0,0,0,0,0,0,0,0,0,1,6,6
6,6,6,1,0,0,0,0,0,0,0,0,0,0,0,0,0,0,0,0,0,1,0,0,0,0,0,1,0,0,0,0,0,0,0,0,0,0,0,0,0,0,0,1,6,6
6,6,6,1,0,0,0,0,0,0,0,0,0,0,0,0,0,0,0,0,0,1,0,0,0,0,0,1,1,1,1,1,1,1,1,80,1,80,1,1,1,1,1,1,6,6
6,6,6,1,7,7,7,7,0,7,7,0,7,7,0,7,7,0,7,7,0,1,0,0,0,0,0,1,0,0,0,0,0,0,0,0,0,0,0,1,0,0,0,1,6,6
6,6,6,1,0,0,0,0,0,0,0,0,0,0,0,0,0,0,0,0,0,1,0,0,0,0,0,1,0,0,0,0,0,0,0,0,0,0,0,1,0,0,0,1,6,6
6,6,6,1,0,0,0,0,0,0,0,0,0,0,0,0,0,0,0,0,0,1,0,0,0,0,0,1,0,0,0,0,0,0,0,0,0,0,0,1,0,0,0,1,6,6
6,6,6,1,0,0,0,0,0,0,0,0,0,0,0,0,0,0,0,0,0,1,0,0,0,0,0,1,0,0,0,0,0,0,0,0,0,0,0,1,0,0,0,1,6,6
6,6,6,1,0,0,0,0,0,0,0,0,0,0,0,0,0,0,0,0,0,1,80,80,171,80,80,1,80,80,80,80,80,80,1,0,0,0,0,1,0,0,0,1,6,6
6,6,6,7,7,7,7,7,0,7,7,7,7,7,0,7,7,0,7,7,0,0,0,0,0,0,0,0,0,0,0,0,0,0,0,0,0,0,0,1,0,0,0,1,6,6
6,6,6,1,7,0,0,0,0,156,180,0,152,177,0,149,149,0,0,0,0,1,80,80,172,80,80,1,80,80,80,80,80,80,1,0,0,0,0,1,0,0,0,1,6,6
6,6,6,1,0,0,0,0,0,0,0,0,0,0,0,0,0,0,0,0,0,1,0,0,0,0,0,1,0,0,0,0,0,0,0,0,0,0,0,1,0,0,0,1,6,6
6,6,6,1,0,0,0,0,0,0,0,0,0,0,0,0,0,0,0,0,0,1,0,0,0,0,0,1,0,0,0,0,0,0,0,0,0,0,0,1,0,0,0,1,6,6
6,6,6,1,0,0,0,0,0,0,0,0,0,0,0,0,0,0,0,0,0,1,0,0,0,0,0,1,0,0,0,0,0,0,0,0,0,0,0,1,7,7,7,1,6,6
6,6,6,1,0,0,0,0,0,0,0,0,0,0,0,0,0,0,0,0,0,1,0,0,0,0,0,1,0,0,0,0,0,0,0,0,0,0,0,1,0,111,0,1,6,6
6,6,6,1,1,0,0,0,0,0,0,0,0,0,0,0,0,0,1,78,78,1,0,0,0,0,0,1,0,0,0,0,0,0,0,0,0,0,0,1,0,0,0,1,6,6
6,6,6,1,1,1,1,1,1,1,1,1,1,1,1,1,1,1,1,1,1,1,0,0,0,0,0,1,0,0,0,0,0,0,1,0,1,0,7,1,0,0,0,1,6,6
6,6,6,1,53,0,0,0,0,0,35,53,0,61,61,61,61,61,61,61,0,1,0,0,0,0,0,1,7,1,7,7,7,7,1,80,1,165,1,1,7,0,7,1,6,6
6,6,6,1,0,0,0,0,0,0,35,0,0,0,0,0,175,0,0,0,0,1,0,0,0,0,0,1,0,0,0,7,169,167,166,0,135,0,135,1,0,0,0,1,6,6
6,6,6,1,0,0,0,0,0,0,35,0,0,0,0,0,0,0,0,0,0,1,80,35,35,35,80,1,0,0,0,7,0,0,0,0,0,0,0,1,0,0,0,1,6,6
6,6,6,1,0,0,0,0,0,0,35,0,0,0,0,0,0,0,0,0,113,1,0,1,1,1,0,1,0,0,0,7,170,0,0,0,0,0,0,80,0,0,0,1,6,6
6,6,6,1,53,53,0,0,0,0,35,0,0,0,0,0,0,0,0,0,0,1,0,1,1,1,0,1,0,0,0,7,0,0,0,0,0,0,0,1,0,0,0,1,6,6
6,6,6,1,0,0,0,0,0,0,35,0,0,0,0,0,0,0,0,0,0,1,0,0,0,0,0,1,0,0,0,7,0,168,0,0,0,0,0,164,0,0,0,1,6,6
6,6,6,1,0,0,0,0,0,0,35,0,0,0,0,0,0,0,0,0,0,1,0,0,0,0,0,1,0,0,0,7,1,1,7,0,0,0,0,1,0,0,0,1,6,6
6,6,6,1,0,0,0,0,0,0,35,0,178,0,0,0,0,0,173,0,0,1,0,0,0,0,0,1,0,0,0,1,0,0,80,0,0,0,0,80,0,0,0,1,6,6
6,6,6,1,0,0,0,53,0,0,35,0,0,0,0,0,0,0,0,0,0,1,0,0,0,0,0,1,0,0,0,7,7,7,7,0,0,0,0,1,0,0,0,1,6,6
6,6,6,1,0,0,0,0,0,0,35,0,0,0,0,0,0,0,0,0,113,1,0,0,0,0,0,1,0,0,0,1,0,0,0,0,0,0,0,1,0,0,0,1,6,6
6,6,6,1,0,0,0,0,53,53,35,0,0,0,0,0,0,0,0,0,0,1,0,0,53,0,0,1,0,0,0,1,170,0,0,0,0,0,0,1,1,1,1,1,6,6
6,6,6,1,0,0,0,0,0,53,35,0,61,61,61,61,61,61,61,61,0,1,0,0,1,53,0,1,0,0,0,1,0,0,0,0,0,0,0,1,0,0,0,1,6,6
6,6,6,1,1,1,1,1,1,1,1,1,1,1,1,1,1,1,1,1,1,1,1,1,1,1,1,1,1,1,1,1,1,1,1,1,1,1,1,1,1,1,1,1,6,6
6,6,6,6,6,6,6,6,6,6,6,6,6,6,6,6,6,6,6,6,6,6,6,6,6,6,6,6,6,6,6,6,6,6,6,6,6,6,6,6,6,6,6,6,6,6
6,6,6,6,6,6,6,6,6,6,6,6,6,6,6,6,6,6,6,6,6,6,6,6,6,6,6,6,6,6,6,6,6,6,6,6,6,6,6,6,6,6,6,6,6,6
:endlayer
layer: 8
6,6,6,6,6,6,6,6,6,6,6,6,6,6,6,6,6,6,6,6,6,6,6,6,6,6,6,6,6,6,6,6,6,6,6,6,6,6,6,6,6,6,6,6,6,6
6,6,6,6,6,6,6,6,6,6,6,6,6,6,6,6,6,6,6,6,6,6,6,6,6,6,6,6,6,6,6,6,6,6,6,6,6,6,6,6,6,6,6,6,6,6
6,6,6,6,6,6,6,6,6,6,6,6,6,6,6,6,6,6,6,6,6,6,6,6,6,6,6,6,6,6,6,6,6,6,6,6,6,6,6,6,6,6,6,6,6,6
6,6,6,1,1,1,1,1,1,1,1,1,1,1,1,1,1,1,1,1,1,1,1,1,1,1,1,1,1,1,1,1,1,1,1,1,1,1,1,1,1,1,1,1,6,6
6,6,6,1,0,0,0,0,0,1,1,0,0,0,0,0,0,0,0,0,0,1,0,0,1,0,0,1,0,0,0,0,0,0,0,0,0,0,0,0,0,0,0,1,6,6
6,6,6,1,0,0,0,0,0,0,0,0,0,0,0,0,0,0,0,0,0,1,0,0,1,0,0,1,0,0,0,0,0,0,0,0,0,0,0,0,0,0,0,1,6,6
6,6,6,1,0,0,0,0,0,0,0,0,0,0,0,0,0,0,0,0,0,1,0,0,1,0,0,1,0,0,0,0,0,0,0,0,0,0,0,0,0,0,0,1,6,6
6,6,6,1,0,0,0,0,0,0,0,0,0,0,0,0,0,0,0,0,0,1,0,0,0,0,0,1,0,0,0,0,0,0,0,0,0,0,0,0,0,0,0,1,6,6
6,6,6,1,0,0,0,0,0,0,0,0,0,0,0,0,0,0,0,0,0,1,0,0,0,0,0,1,0,0,0,0,0,0,0,0,0,0,0,0,0,0,0,1,6,6
6,6,6,1,0,0,0,0,0,0,0,0,0,0,0,0,0,0,0,0,0,1,0,0,0,0,0,1,0,0,0,0,0,0,0,0,0,0,0,0,0,0,0,1,6,6
6,6,6,1,0,0,0,0,0,0,0,0,0,0,0,0,0,0,0,0,0,1,0,0,0,0,0,1,0,0,0,0,0,0,0,0,0,0,0,0,0,0,0,1,6,6
6,6,6,1,0,0,0,0,0,0,0,0,0,0,0,0,0,0,0,0,0,1,0,0,0,0,0,1,0,0,0,0,0,0,0,0,0,0,0,0,0,0,0,1,6,6
6,6,6,1,0,0,0,0,0,0,0,0,0,0,0,0,0,0,0,0,0,1,0,0,0,0,0,1,1,1,1,1,1,1,1,1,1,1,1,1,1,1,1,1,6,6
6,6,6,1,7,7,7,7,0,7,7,0,7,7,0,7,7,0,7,7,0,1,0,0,0,0,0,1,0,0,0,0,0,0,0,0,0,0,0,1,0,0,0,1,6,6
6,6,6,1,0,0,0,0,0,0,0,0,0,0,0,0,0,0,0,0,0,1,0,0,0,0,0,1,0,0,0,0,0,0,0,0,0,0,0,1,0,0,0,1,6,6
6,6,6,1,0,0,0,0,0,0,0,0,0,0,0,0,0,0,0,0,0,1,0,0,0,0,0,1,0,0,0,0,0,0,0,0,0,0,0,1,0,0,0,1,6,6
6,6,6,1,0,0,0,0,0,0,0,0,0,0,0,0,0,0,0,0,0,1,0,0,0,0,0,1,0,0,0,0,0,0,0,0,0,0,0,1,0,0,0,1,6,6
6,6,6,1,0,0,0,0,0,0,0,0,0,0,0,0,0,0,0,0,0,1,0,0,0,0,0,1,0,0,0,0,0,0,1,0,0,0,0,1,0,0,0,1,6,6
6,6,6,7,7,7,7,7,0,7,7,7,7,7,0,7,7,0,7,7,0,0,0,0,0,0,0,0,0,0,0,0,0,0,0,0,0,0,0,1,0,0,0,1,6,6
6,6,6,1,1,0,0,0,0,0,180,0,0,152,0,0,149,0,0,0,0,1,0,0,0,0,0,1,0,0,0,0,0,0,1,0,0,0,0,1,0,0,0,1,6,6
6,6,6,1,0,0,0,0,0,0,0,0,0,0,0,0,0,0,0,0,0,1,0,0,0,0,0,1,0,0,0,0,0,0,0,0,0,0,0,1,0,0,0,1,6,6
6,6,6,1,0,0,0,0,0,0,0,0,0,0,0,0,0,0,0,0,0,1,0,0,0,0,0,1,0,0,0,0,0,0,0,0,0,0,0,1,0,0,0,1,6,6
6,6,6,1,0,0,0,0,0,0,0,0,0,0,0,0,0,0,0,0,0,1,0,0,0,0,0,1,0,0,0,0,0,0,0,0,0,0,0,1,7,7,7,1,6,6
6,6,6,1,0,0,0,0,0,0,0,0,0,0,0,0,0,0,0,0,0,1,0,0,0,0,0,1,0,0,0,0,0,0,0,0,0,0,0,1,0,0,0,1,6,6
6,6,6,1,7,0,0,0,0,0,0,0,0,0,0,0,0,0,1,0,0,1,0,0,0,0,0,1,0,0,0,0,0,0,0,0,0,0,0,1,0,0,0,1,6,6
6,6,6,1,1,1,1,1,1,1,1,1,1,1,1,1,1,1,1,1,1,1,0,0,0,0,0,1,0,0,0,0,0,0,1,0,1,108,7,1,0,0,0,1,6,6
6,6,6,1,53,53,0,0,0,53,35,53,0,61,61,61,61,61,61,61,0,1,0,0,0,0,0,1,7,7,7,7,7,1,1,1,1,1,1,1,7,0,7,1,6,6
6,6,6,1,0,0,0,0,0,0,35,0,0,0,0,0,0,0,0,0,0,1,0,0,0,0,0,1,0,0,0,7,186,185,184,0,135,109,135,1,0,0,0,1,6,6
6,6,6,1,0,0,0,0,0,0,35,0,0,0,0,0,0,0,0,0,0,1,80,0,0,0,80,1,0,0,0,7,0,0,0,0,0,0,0,1,0,0,0,1,6,6
6,6,6,1,53,0,0,0,0,53,35,0,0,0,0,0,0,0,0,0,0,1,0,35,35,35,0,1,0,0,0,7,0,0,0,0,0,0,0,1,0,0,0,1,6,6
6,6,6,1,53,53,0,0,0,53,35,0,0,0,0,0,0,0,0,0,0,1,0,1,1,1,0,1,0,0,0,7,0,0,0,0,0,0,0,1,0,0,0,1,6,6
6,6,6,1,53,0,0,0,0,53,35,0,0,0,0,0,0,0,0,0,0,1,0,1,1,1,0,1,0,0,0,7,0,0,0,0,0,0,183,1,107,0,0,1,6,6
6,6,6,1,0,0,0,0,0,0,35,0,0,0,0,0,0,0,0,0,0,1,0,0,1,0,0,1,0,0,0,7,1,1,7,0,0,0,0,1,0,0,0,1,6,6
6,6,6,1,0,0,0,0,0,53,35,0,0,0,0,0,0,0,0,0,0,1,0,0,1,0,0,1,0,0,0,1,0,0,7,0,0,0,0,1,0,0,0,1,6,6
6,6,6,1,0,0,0,53,0,0,35,0,0,0,0,0,0,0,0,0,0,1,0,0,1,0,0,1,0,0,0,7,7,7,7,0,0,0,0,1,0,0,0,1,6,6
6,6,6,1,0,0,53,53,53,53,35,0,0,0,0,0,0,0,0,0,0,1,0,0,1,0,0,1,0,0,0,1,0,0,0,0,0,0,0,1,0,0,0,1,6,6
6,6,6,1,0,0,0,0,0,0,35,0,0,0,0,0,0,0,0,0,0,1,0,0,1,0,0,1,0,0,0,1,0,0,0,0,0,0,0,1,1,1,1,1,6,6
6,6,6,1,53,0,0,0,53,53,35,0,61,61,61,61,61,61,61,61,0,1,0,53,1,53,53,1,0,0,0,1,0,0,0,0,0,0,0,1,0,0,0,1,6,6
6,6,6,1,1,1,1,1,1,1,1,1,1,1,1,1,1,1,1,1,1,1,1,1,1,1,1,1,1,1,1,1,1,1,1,1,1,1,1,1,1,1,1,1,6,6
6,6,6,6,6,6,6,6,6,6,6,6,6,6,6,6,6,6,6,6,6,6,6,6,6,6,6,6,6,6,6,6,6,6,6,6,6,6,6,6,6,6,6,6,6,6
6,6,6,6,6,6,6,6,6,6,6,6,6,6,6,6,6,6,6,6,6,6,6,6,6,6,6,6,6,6,6,6,6,6,6,6,6,6,6,6,6,6,6,6,6,6
:endlayer
layer: 9
6,6,6,6,6,6,6,6,6,6,6,6,6,6,6,6,6,6,6,6,6,6,6,6,6,6,6,6,6,6,6,6,6,6,6,6,6,6,6,6,6,6,6,6,6,6
6,6,6,6,6,6,6,6,6,6,6,6,6,6,6,6,6,6,6,6,6,6,6,6,6,6,6,6,6,6,6,6,6,6,6,6,6,6,6,6,6,6,6,6,6,6
6,6,6,6,6,6,6,6,6,6,6,6,6,6,6,6,6,6,6,6,6,6,6,6,6,6,6,6,6,6,6,6,6,6,6,6,6,6,6,6,6,6,6,6,6,6
6,6,6,1,1,1,1,1,1,1,1,1,1,1,1,1,1,1,1,1,1,1,1,1,1,1,1,1,1,1,1,1,1,1,1,1,1,1,1,1,1,1,1,1,6,6
6,6,6,1,1,1,1,1,1,1,1,1,1,1,1,1,1,1,1,1,1,1,1,1,1,1,1,1,1,1,1,1,1,1,1,1,1,1,1,1,1,1,1,1,6,6
6,6,6,1,1,1,1,1,1,1,1,1,1,1,1,1,1,1,1,1,1,1,1,1,1,1,1,1,1,1,1,1,1,1,1,1,1,1,1,1,1,1,1,1,6,6
6,6,6,1,1,1,1,1,1,1,1,1,1,1,1,1,1,1,1,1,1,1,1,1,1,1,1,1,1,1,1,1,1,1,1,1,1,1,1,1,1,1,1,1,6,6
6,6,6,1,1,1,1,1,1,1,1,1,1,1,1,1,1,1,1,1,1,1,1,1,1,1,1,1,1,1,1,1,1,1,1,1,1,1,1,1,1,1,1,1,6,6
6,6,6,1,1,1,1,1,1,1,1,1,1,1,1,1,1,1,1,1,1,1,1,1,1,1,1,1,1,1,1,1,1,1,1,1,1,1,1,1,1,1,1,1,6,6
6,6,6,1,1,1,1,1,1,1,1,1,1,1,1,1,1,1,1,1,1,1,1,1,1,1,1,1,1,1,1,1,1,1,1,1,1,1,1,1,1,1,1,1,6,6
6,6,6,1,1,1,1,1,1,1,1,1,1,1,1,1,1,1,1,1,1,1,1,1,1,1,1,1,1,1,1,1,1,1,1,1,1,1,1,1,1,1,1,1,6,6
6,6,6,1,1,1,1,1,1,1,1,1,1,1,1,1,1,1,1,1,1,1,1,1,1,1,1,1,1,1,1,1,1,1,1,1,1,1,1,1,1,1,1,1,6,6
6,6,6,1,1,1,1,1,1,1,1,1,1,1,1,1,1,1,1,1,1,1,1,1,1,1,1,1,1,1,1,1,1,1,1,1,1,1,1,1,1,1,1,1,6,6
6,6,6,1,1,1,1,1,1,1,1,1,1,1,1,1,1,1,1,1,1,1,1,1,1,1,1,1,1,1,1,1,1,1,1,1,1,1,1,1,1,1,1,1,6,6
6,6,6,1,1,1,1,1,1,1,1,1,1,1,1,1,1,1,1,1,1,1,1,1,1,1,1,1,1,1,1,1,1,1,1,1,1,1,1,1,1,1,1,1,6,6
6,6,6,1,1,1,1,1,1,1,1,1,1,1,1,1,1,1,1,1,1,1,1,1,1,1,1,1,1,1,1,1,1,1,1,1,1,1,1,1,1,1,1,1,6,6
6,6,6,1,1,1,1,1,1,1,1,1,1,1,1,1,1,1,1,1,1,1,1,1,1,1,1,1,1,1,1,1,1,1,1,1,1,1,1,1,1,1,1,1,6,6
6,6,6,1,1,1,1,1,1,1,1,1,1,1,1,1,1,1,1,1,1,1,1,1,1,1,1,1,1,1,1,1,1,1,1,1,1,1,1,1,1,1,1,1,6,6
6,6,6,1,1,1,1,1,1,1,1,1,1,1,1,1,1,1,1,1,1,1,1,1,1,1,1,1,1,1,1,1,1,1,1,1,1,1,1,1,1,1,1,1,6,6
6,6,6,1,1,1,1,1,1,1,1,1,1,1,1,1,1,1,1,1,1,1,1,1,1,1,1,1,1,1,1,1,1,1,1,1,1,1,1,1,1,1,1,1,6,6
6,6,6,1,1,1,1,1,1,1,1,1,1,1,1,1,1,1,1,1,1,1,1,1,1,1,1,1,1,1,1,1,1,1,1,1,1,1,1,1,1,1,1,1,6,6
6,6,6,1,1,1,1,1,1,1,1,1,1,1,1,1,1,1,1,1,1,1,1,1,1,1,1,1,1,1,1,1,1,1,1,1,1,1,1,1,1,1,1,1,6,6
6,6,6,1,1,1,1,1,1,1,1,1,1,1,1,1,1,1,1,1,1,1,1,1,1,1,1,1,1,1,1,1,1,1,1,1,1,1,1,1,1,1,1,1,6,6
6,6,6,1,1,1,1,1,1,1,1,1,1,1,1,1,1,1,1,1,1,1,1,1,1,1,1,1,1,1,1,1,1,1,1,1,1,1,1,1,1,1,1,1,6,6
6,6,6,1,1,1,1,1,1,1,1,1,1,1,1,1,1,1,1,1,1,1,1,1,1,1,1,1,1,1,1,1,1,1,1,1,1,1,1,1,1,1,1,1,6,6
6,6,6,1,1,1,1,1,1,1,1,1,1,1,1,1,1,1,1,1,1,1,1,1,1,1,1,1,1,1,1,1,1,1,1,1,1,1,1,1,1,1,1,1,6,6
6,6,6,1,1,1,1,1,1,1,1,1,1,1,1,1,1,1,1,1,1,1,1,0,0,0,1,1,1,1,1,1,1,1,1,1,1,1,1,1,1,1,1,1,6,6
6,6,6,1,1,1,1,1,1,1,1,1,1,1,1,1,1,1,1,1,1,1,1,0,0,0,1,1,1,1,1,1,1,1,1,1,1,1,1,1,1,1,1,1,6,6
6,6,6,1,1,1,1,1,1,1,1,1,1,1,1,1,1,1,1,1,1,1,1,0,0,0,1,1,1,1,1,1,1,1,1,1,1,1,1,1,1,1,1,1,6,6
6,6,6,1,1,1,1,1,1,1,1,1,1,1,1,1,1,1,1,1,1,1,1,0,0,0,1,1,1,1,1,1,1,1,1,1,1,1,1,1,1,1,1,1,6,6
6,6,6,1,1,1,1,1,1,1,1,1,1,1,1,1,1,1,1,1,1,1,1,35,35,35,1,1,1,1,1,1,1,1,1,1,1,1,1,1,1,1,1,1,6,6
6,6,6,1,1,1,1,53,1,1,1,1,1,1,1,1,1,1,1,1,1,1,1,1,1,1,1,1,1,1,1,1,1,1,1,1,1,1,1,1,1,1,1,1,6,6
6,6,6,1,1,1,1,1,1,1,1,1,1,1,1,1,1,1,1,1,1,1,1,1,1,1,1,1,1,1,1,1,1,1,1,1,1,1,1,1,1,1,1,1,6,6
6,6,6,1,1,1,1,1,1,1,1,1,1,1,1,1,1,1,1,1,1,1,1,1,1,1,1,1,1,1,1,1,1,1,1,1,1,1,1,1,1,1,1,1,6,6
6,6,6,1,1,1,1,1,1,1,1,1,1,1,1,1,1,1,1,1,1,1,1,1,1,1,1,1,1,1,1,1,1,1,1,1,1,1,1,1,1,1,1,1,6,6
6,6,6,1,1,1,1,1,1,1,1,1,1,1,1,1,1,1,1,1,1,1,1,1,1,1,1,1,1,1,1,1,1,1,1,1,1,1,1,1,1,1,1,1,6,6
6,6,6,1,1,1,1,1,1,1,1,1,1,1,1,1,1,1,1,1,1,1,1,1,1,1,1,1,1,1,1,1,1,1,1,1,1,1,1,1,1,1,1,1,6,6
6,6,6,1,1,1,1,1,1,1,1,1,1,1,1,1,1,1,1,1,1,1,1,1,1,1,1,1,1,1,1,1,1,1,1,1,1,1,1,1,1,1,1,1,6,6
6,6,6,1,1,1,1,1,1,1,1,1,1,1,1,1,1,1,1,1,1,1,1,1,1,1,1,1,1,1,1,1,1,1,1,1,1,1,1,1,1,1,1,1,6,6
6,6,6,6,6,6,6,6,6,6,6,6,6,6,6,6,6,6,6,6,6,6,6,6,6,6,6,6,6,6,6,6,6,6,6,6,6,6,6,6,6,6,6,6,6,6
6,6,6,6,6,6,6,6,6,6,6,6,6,6,6,6,6,6,6,6,6,6,6,6,6,6,6,6,6,6,6,6,6,6,6,6,6,6,6,6,6,6,6,6,6,6
:endlayer
layer: 10
6,6,6,6,6,6,6,6,6,6,6,6,6,6,6,6,6,6,6,6,6,6,6,6,6,6,6,6,6,6,6,6,6,6,6,6,6,6,6,6,6,6,6,6,6,6
6,6,6,6,6,6,6,6,6,6,6,6,6,6,6,6,6,6,6,6,6,6,6,6,6,6,6,6,6,6,6,6,6,6,6,6,6,6,6,6,6,6,6,6,6,6
6,6,6,6,6,6,6,6,6,6,6,6,6,6,6,6,6,6,6,6,6,6,6,6,6,6,6,6,6,6,6,6,6,6,6,6,6,6,6,6,6,6,6,6,6,6
6,6,6,1,1,1,1,1,1,1,1,1,1,1,1,1,1,1,1,1,1,1,1,1,1,1,1,1,1,1,1,1,1,1,1,1,1,1,1,1,1,1,1,1,6,6
6,6,6,1,1,1,1,1,1,1,1,1,1,1,1,1,1,1,1,1,1,1,1,1,1,1,1,1,1,1,1,1,1,1,1,1,1,1,1,1,1,1,1,1,6,6
6,6,6,1,1,1,1,1,1,1,1,1,1,1,1,1,1,1,1,1,1,1,1,1,1,1,1,1,1,1,1,1,1,1,1,1,1,1,1,1,1,1,1,1,6,6
6,6,6,1,1,1,1,1,1,1,1,1,1,1,1,1,1,1,1,1,1,1,1,1,1,1,1,1,1,1,1,1,1,1,1,1,1,1,1,1,1,1,1,1,6,6
6,6,6,1,1,1,1,1,1,1,1,1,1,1,1,1,1,1,1,1,1,1,1,1,1,1,1,1,1,1,1,1,1,1,1,1,1,1,1,1,1,1,1,1,6,6
6,6,6,1,1,1,1,1,1,1,1,1,1,1,1,1,1,1,1,1,1,1,1,1,1,1,1,1,1,1,1,1,1,1,1,1,1,1,1,1,1,1,1,1,6,6
6,6,6,1,1,1,1,1,1,1,1,1,1,1,1,1,1,1,1,1,1,1,1,1,1,1,1,1,1,1,1,1,1,1,1,1,1,1,1,1,1,1,1,1,6,6
6,6,6,1,1,1,1,1,1,1,1,1,1,1,1,1,1,1,1,1,1,1,1,1,1,1,1,1,1,1,1,1,1,1,1,1,1,1,1,1,1,1,1,1,6,6
6,6,6,1,1,1,1,1,1,1,1,1,1,1,1,1,1,1,1,1,1,1,1,1,1,1,1,1,1,1,1,1,1,1,1,1,1,1,1,1,1,1,1,1,6,6
6,6,6,1,1,1,1,1,1,1,1,1,1,1,1,1,1,1,1,1,1,1,1,1,1,1,1,1,1,1,1,1,1,1,1,1,1,1,1,1,1,1,1,1,6,6
6,6,6,1,1,1,1,1,1,1,1,1,1,1,1,1,1,1,1,1,1,1,1,1,1,1,1,1,1,1,1,1,1,1,1,1,1,1,1,1,1,1,1,1,6,6
6,6,6,1,1,1,1,1,1,1,1,1,1,1,1,1,1,1,1,1,1,1,1,1,1,1,1,1,1,1,1,1,1,1,1,1,1,1,1,1,1,1,1,1,6,6
6,6,6,1,1,1,1,1,1,1,1,1,1,1,1,1,1,1,1,1,1,1,1,1,1,1,1,1,1,1,1,1,1,1,1,1,1,1,1,1,1,1,1,1,6,6
6,6,6,1,1,1,1,1,1,1,1,1,1,1,1,1,1,1,1,1,1,1,1,1,1,1,1,1,1,1,1,1,1,1,1,1,1,1,1,1,1,1,1,1,6,6
6,6,6,1,1,1,1,1,1,1,1,1,1,1,1,1,1,1,1,1,1,1,1,1,1,1,1,1,1,1,1,1,1,1,1,1,1,1,1,1,1,1,1,1,6,6
6,6,6,1,1,1,1,1,1,1,1,1,1,1,1,1,1,1,1,1,1,1,1,1,1,1,1,1,1,1,1,1,1,1,1,1,1,1,1,1,1,1,1,1,6,6
6,6,6,1,1,1,1,1,1,1,1,1,1,1,1,1,1,1,1,1,1,1,1,1,1,1,1,1,1,1,1,1,1,1,1,1,1,1,1,1,1,1,1,1,6,6
6,6,6,1,1,1,1,1,1,1,1,1,1,1,1,1,1,1,1,1,1,1,1,1,1,1,1,1,1,1,1,1,1,1,1,1,1,1,1,1,1,1,1,1,6,6
6,6,6,1,1,1,1,1,1,1,1,1,1,1,1,1,1,1,1,1,1,1,1,1,1,1,1,1,1,1,1,1,1,1,1,1,1,1,1,1,1,1,1,1,6,6
6,6,6,1,1,1,1,1,1,1,1,1,1,1,1,1,1,1,1,1,1,1,1,1,1,1,1,1,1,1,1,1,1,1,1,1,1,1,1,1,1,1,1,1,6,6
6,6,6,1,1,1,1,1,1,1,1,1,1,1,1,1,1,1,1,1,1,1,1,1,1,1,1,1,1,1,1,1,1,1,1,1,1,1,1,1,1,1,1,1,6,6
6,6,6,1,1,1,1,1,1,1,1,1,1,1,1,1,1,1,1,1,1,1,1,1,1,1,1,1,1,1,1,1,1,1,1,1,1,1,1,1,1,1,1,1,6,6
6,6,6,1,1,1,1,1,1,1,1,1,1,1,1,1,1,1,1,1,1,1,1,1,1,1,1,1,1,1,1,1,1,1,1,1,1,1,1,1,1,1,1,1,6,6
6,6,6,1,1,1,1,1,1,1,1,1,1,1,1,1,1,1,1,1,1,1,1,1,1,1,1,1,1,1,1,1,1,1,1,1,1,1,1,1,1,1,1,1,6,6
6,6,6,1,1,1,1,1,1,1,1,1,1,1,1,1,1,1,1,1,1,1,1,0,0,0,1,1,1,1,1,1,1,1,1,1,1,1,1,1,1,1,1,1,6,6
6,6,6,1,1,1,1,1,1,1,1,1,1,1,1,1,1,1,1,1,1,1,1,0,0,0,1,1,1,1,1,1,1,1,1,1,1,1,1,1,1,1,1,1,6,6
6,6,6,1,1,1,1,1,1,1,1,1,1,1,1,1,1,1,1,1,1,1,1,0,0,0,1,1,1,1,1,1,1,1,1,1,1,1,1,1,1,1,1,1,6,6
6,6,6,1,1,1,1,1,1,1,1,1,1,1,1,1,1,1,1,1,1,1,1,0,0,0,1,1,1,1,1,1,1,1,1,1,1,1,1,1,1,1,1,1,6,6
6,6,6,1,1,1,1,1,1,1,1,1,1,1,1,1,1,1,1,1,1,1,1,35,35,35,1,1,1,1,1,1,1,1,1,1,1,1,1,1,1,1,1,1,6,6
6,6,6,1,1,1,1,1,1,1,1,1,1,1,1,1,1,1,1,1,1,1,1,1,1,1,1,1,1,1,1,1,1,1,1,1,1,1,1,1,1,1,1,1,6,6
6,6,6,1,1,1,1,1,1,1,1,1,1,1,1,1,1,1,1,1,1,1,1,1,1,1,1,1,1,1,1,1,1,1,1,1,1,1,1,1,1,1,1,1,6,6
6,6,6,1,1,1,1,1,1,1,1,1,1,1,1,1,1,1,1,1,1,1,1,1,1,1,1,1,1,1,1,1,1,1,1,1,1,1,1,1,1,1,1,1,6,6
6,6,6,1,1,1,1,1,1,1,1,1,1,1,1,1,1,1,1,1,1,1,1,1,1,1,1,1,1,1,1,1,1,1,1,1,1,1,1,1,1,1,1,1,6,6
6,6,6,1,1,1,1,1,1,1,1,1,1,1,1,1,1,1,1,1,1,1,1,1,1,1,1,1,1,1,1,1,1,1,1,1,1,1,1,1,1,1,1,1,6,6
6,6,6,1,1,1,1,1,1,1,1,1,1,1,1,1,1,1,1,1,1,1,1,1,1,1,1,1,1,1,1,1,1,1,1,1,1,1,1,1,1,1,1,1,6,6
6,6,6,1,1,1,1,1,1,1,1,1,1,1,1,1,1,1,1,1,1,1,1,1,1,1,1,1,1,1,1,1,1,1,1,1,1,1,1,1,1,1,1,1,6,6
6,6,6,6,6,6,6,6,6,6,6,6,6,6,6,6,6,6,6,6,6,6,6,6,6,6,6,6,6,6,6,6,6,6,6,6,6,6,6,6,6,6,6,6,6,6
6,6,6,6,6,6,6,6,6,6,6,6,6,6,6,6,6,6,6,6,6,6,6,6,6,6,6,6,6,6,6,6,6,6,6,6,6,6,6,6,6,6,6,6,6,6
:endlayer
layer: 11
6,6,6,6,6,6,6,6,6,6,6,6,6,6,6,6,6,6,6,6,6,6,6,6,6,6,6,6,6,6,6,6,6,6,6,6,6,6,6,6,6,6,6,6,6,6
6,6,6,6,6,6,6,6,6,6,6,6,6,6,6,6,6,6,6,6,6,6,6,6,6,6,6,6,6,6,6,6,6,6,6,6,6,6,6,6,6,6,6,6,6,6
6,6,6,6,6,6,6,6,6,6,6,6,6,6,6,6,6,6,6,6,6,6,6,6,6,6,6,6,6,6,6,6,6,6,6,6,6,6,6,6,6,6,6,6,6,6
6,6,6,6,6,6,6,6,6,6,6,6,6,6,6,6,6,6,6,6,6,6,6,6,6,6,6,6,6,6,6,6,6,6,6,6,6,6,6,6,6,6,6,6,6,6
6,6,6,6,6,6,6,6,6,6,6,6,6,6,6,6,6,6,6,6,6,6,6,6,6,6,6,6,6,6,6,6,6,6,6,6,6,6,6,6,6,6,6,6,6,6
6,6,6,6,6,6,6,6,6,6,6,6,6,6,6,6,6,6,6,6,6,6,6,6,6,6,6,6,6,6,6,6,6,6,6,6,6,6,6,6,6,6,6,6,6,6
6,6,6,6,6,6,6,6,6,6,6,6,6,6,6,6,6,6,6,6,6,6,6,6,6,6,6,6,6,6,6,6,6,6,6,6,6,6,6,6,6,6,6,6,6,6
6,6,6,6,6,6,6,6,6,6,6,6,6,6,6,6,6,6,6,6,6,6,6,6,6,6,6,6,6,6,6,6,6,6,6,6,6,6,6,6,6,6,6,6,6,6
6,6,6,6,6,6,6,6,6,6,6,6,6,6,6,6,6,6,6,6,6,6,6,6,6,6,6,6,6,6,6,6,6,6,6,6,6,6,6,6,6,6,6,6,6,6
6,6,6,6,6,6,6,6,6,6,6,6,6,6,6,6,6,6,6,6,6,6,6,6,6,6,6,6,6,6,6,6,6,6,6,6,6,6,6,6,6,6,6,6,6,6
6,6,6,6,6,6,6,6,6,6,6,6,6,6,6,6,6,6,6,6,6,6,6,6,6,6,6,6,6,6,6,6,6,6,6,6,6,6,6,6,6,6,6,6,6,6
6,6,6,6,6,6,6,6,6,6,6,6,6,6,6,6,6,6,6,6,6,6,6,6,6,6,6,6,6,6,6,6,6,6,6,6,6,6,6,6,6,6,6,6,6,6
6,6,6,6,6,6,6,6,6,6,6,6,6,6,6,6,6,6,6,6,6,6,6,6,6,6,6,6,6,6,6,6,6,6,6,6,6,6,6,6,6,6,6,6,6,6
6,6,6,6,6,6,6,6,6,6,6,6,6,6,6,6,6,6,6,6,6,6,6,6,6,6,6,6,6,6,6,6,6,6,6,6,6,6,6,6,6,6,6,6,6,6
6,6,6,6,6,6,6,6,6,6,6,6,6,6,6,6,6,6,6,6,6,6,6,6,6,6,6,6,6,6,6,6,6,6,6,6,6,6,6,6,6,6,6,6,6,6
6,6,6,6,6,6,6,6,6,6,6,6,6,6,6,6,6,6,6,6,6,6,6,6,6,6,6,6,6,6,6,6,6,6,6,6,6,6,6,6,6,6,6,6,6,6
6,6,6,6,6,6,6,6,6,6,6,6,6,6,6,6,6,6,6,6,6,6,6,6,6,6,6,6,6,6,6,6,6,6,6,6,6,6,6,6,6,6,6,6,6,6
6,6,6,6,6,6,6,6,6,6,6,6,6,6,6,6,6,6,6,6,6,6,6,6,6,6,6,6,6,6,6,6,6,6,6,6,6,6,6,6,6,6,6,6,6,6
6,6,6,6,6,6,6,6,6,6,6,6,6,6,6,6,6,6,6,6,6,6,6,6,6,6,6,6,6,6,6,6,6,6,6,6,6,6,6,6,6,6,6,6,6,6
6,6,6,6,6,6,6,6,6,6,6,6,6,6,6,6,6,6,6,6,6,6,6,6,6,6,6,6,6,6,6,6,6,6,6,6,6,6,6,6,6,6,6,6,6,6
6,6,6,6,6,6,6,6,6,6,6,6,6,6,6,6,6,6,6,6,6,6,6,6,6,6,6,6,6,6,6,6,6,6,6,6,6,6,6,6,6,6,6,6,6,6
6,6,6,6,6,6,6,6,6,6,6,6,6,6,6,6,6,6,6,6,6,6,6,6,6,6,6,6,6,6,6,6,6,6,6,6,6,6,6,6,6,6,6,6,6,6
6,6,6,6,6,6,6,6,6,6,6,6,6,6,6,6,6,6,6,6,6,6,6,6,6,6,6,6,6,6,6,6,6,6,6,6,6,6,6,6,6,6,6,6,6,6
6,6,6,6,6,6,6,6,6,6,6,6,6,6,6,6,6,6,6,6,6,6,6,6,6,6,6,6,6,6,6,6,6,6,6,6,6,6,6,6,6,6,6,6,6,6
6,6,6,6,6,6,6,6,6,6,6,6,6,6,6,6,6,6,6,6,6,6,6,6,6,6,6,6,6,6,6,6,6,6,6,6,6,6,6,6,6,6,6,6,6,6
6,6,6,6,6,6,6,6,6,6,6,6,6,6,6,6,6,6,6,6,6,6,6,6,6,6,6,6,6,6,6,6,6,6,6,6,6,6,6,6,6,6,6,6,6,6
6,6,6,6,6,6,6,6,6,6,6,6,6,6,6,6,6,6,6,6,6,6,6,1,1,1,6,6,6,6,6,6,6,6,6,6,6,6,6,6,6,6,6,6,6,6
6,6,6,6,6,6,6,6,6,6,6,6,6,6,6,6,6,6,6,6,6,6,1,0,0,0,1,6,6,6,6,6,6,6,6,6,6,6,6,6,6,6,6,6,6,6
6,6,6,6,6,6,6,6,6,6,6,6,6,6,6,6,6,6,6,6,6,6,1,0,0,0,1,6,6,6,6,6,6,6,6,6,6,6,6,6,6,6,6,6,6,6
6,6,6,6,6,6,6,6,6,6,6,6,6,6,6,6,6,6,6,6,6,6,1,0,0,0,1,6,6,6,6,6,6,6,6,6,6,6,6,6,6,6,6,6,6,6
6,6,6,6,6,6,6,6,6,6,6,6,6,6,6,6,6,6,6,6,6,6,1,0,0,0,1,6,6,6,6,6,6,6,6,6,6,6,6,6,6,6,6,6,6,6
6,6,6,6,6,6,6,6,6,6,6,6,6,6,6,6,6,6,6,6,6,6,1,0,0,0,1,6,6,6,6,6,6,6,6,6,6,6,6,6,6,6,6,6,6,6
6,6,6,6,6,6,6,6,6,6,6,6,6,6,6,6,6,6,6,6,6,6,1,35,35,35,6,6,6,6,6,6,6,6,6,6,6,6,6,6,6,6,6,6,6,6
6,6,6,6,6,6,6,6,6,6,6,6,6,6,6,6,6,6,6,6,6,6,6,6,6,6,6,6,6,6,6,6,6,6,6,6,6,6,6,6,6,6,6,6,6,6
6,6,6,6,6,6,6,6,6,6,6,6,6,6,6,6,6,6,6,6,6,6,6,6,6,6,6,6,6,6,6,6,6,6,6,6,6,6,6,6,6,6,6,6,6,6
6,6,6,6,6,6,6,6,6,6,6,6,6,6,6,6,6,6,6,6,6,6,6,6,6,6,6,6,6,6,6,6,6,6,6,6,6,6,6,6,6,6,6,6,6,6
6,6,6,6,6,6,6,6,6,6,6,6,6,6,6,6,6,6,6,6,6,6,6,6,6,6,6,6,6,6,6,6,6,6,6,6,6,6,6,6,6,6,6,6,6,6
6,6,6,6,6,6,6,6,6,6,6,6,6,6,6,6,6,6,6,6,6,6,6,6,6,6,6,6,6,6,6,6,6,6,6,6,6,6,6,6,6,6,6,6,6,6
6,6,6,6,6,6,6,6,6,6,6,6,6,6,6,6,6,6,6,6,6,6,6,6,6,6,6,6,6,6,6,6,6,6,6,6,6,6,6,6,6,6,6,6,6,6
6,6,6,6,6,6,6,6,6,6,6,6,6,6,6,6,6,6,6,6,6,6,6,6,6,6,6,6,6,6,6,6,6,6,6,6,6,6,6,6,6,6,6,6,6,6
6,6,6,6,6,6,6,6,6,6,6,6,6,6,6,6,6,6,6,6,6,6,6,6,6,6,6,6,6,6,6,6,6,6,6,6,6,6,6,6,6,6,6,6,6,6
:endlayer
layer: 12
187,187,187,187,187,187,187,187,187,187,187,187,187,187,187,187,187,187,187,187,187,187,187,187,187,187,187,187,187,187,187,187,187,187,187,187,187,187,187,187,187,187,187,187,187,187
187,187,187,187,187,187,187,187,187,187,187,187,187,187,187,187,187,187,187,187,187,187,187,187,187,187,187,187,187,187,187,187,187,187,187,187,187,187,187,187,187,187,187,187,187,187
187,187,187,187,8,187,187,187,187,187,187,187,187,187,187,187,187,187,187,187,187,187,187,187,187,187,187,187,187,187,187,187,187,187,187,187,187,187,8,8,8,187,187,187,187,187
187,187,187,8,8,8,8,8,187,187,187,187,8,8,8,187,187,187,187,187,187,187,187,187,187,187,187,187,187,187,187,187,187,187,187,187,187,8,187,8,8,187,187,187,187,187
187,187,187,8,8,8,8,8,187,187,187,8,8,187,8,187,187,187,187,187,187,8,187,187,187,187,187,187,187,187,187,8,8,187,187,187,187,8,8,8,8,8,187,187,187,187
187,187,187,187,8,8,8,8,187,187,187,8,8,8,8,8,187,187,187,187,8,187,8,187,187,187,187,187,187,187,8,8,8,8,187,187,187,8,8,8,8,187,187,187,187,187
187,187,187,187,8,8,8,8,187,187,187,187,8,8,8,187,187,187,187,187,187,8,8,187,187,187,187,187,187,4,8,8,8,187,187,187,187,187,187,187,8,187,187,187,187,187
187,187,187,187,187,187,187,187,187,187,187,187,187,187,187,187,187,187,187,8,8,8,8,8,187,187,187,187,187,187,8,8,8,8,187,187,187,187,187,187,187,187,187,187,187,187
187,187,187,187,187,187,187,187,187,187,187,187,187,187,187,187,187,187,187,187,8,8,8,187,187,187,187,187,187,187,8,8,187,187,187,187,187,187,187,187,187,187,187,187,187,187
187,187,187,187,187,187,187,187,187,187,187,187,187,187,187,187,187,187,187,187,187,187,187,187,187,187,187,187,187,187,187,187,187,187,187,187,187,187,187,187,187,8,8,8,187,187
187,187,187,187,187,187,187,187,187,187,187,187,187,187,187,187,187,187,187,187,187,187,187,187,187,187,187,187,187,187,187,187,187,187,187,187,187,187,187,187,187,8,8,187,8,187
187,187,187,187,187,187,187,187,187,187,187,187,187,192,191,187,187,187,187,187,187,187,187,187,187,187,187,187,187,187,187,187,187,187,187,187,187,187,187,187,187,8,8,8,187,187
187,187,187,187,187,187,187,187,187,187,187,187,187,188,187,187,187,187,187,187,187,187,187,187,187,187,187,187,187,187,187,187,187,187,187,187,187,187,187,187,187,187,187,187,187,187
187,187,187,187,187,187,187,187,187,187,187,187,187,187,187,187,187,187,187,187,187,187,187,187,187,187,187,187,187,187,187,187,187,187,187,187,187,187,187,187,187,187,187,187,187,187
187,187,187,187,187,187,187,187,187,187,187,187,187,187,187,187,187,187,187,187,187,187,187,187,187,187,187,187,187,187,187,187,187,187,187,187,187,187,187,187,187,187,187,187,187,187
187,187,187,187,187,187,187,187,187,187,187,187,187,187,187,187,187,187,187,187,187,187,187,187,187,187,187,187,187,187,187,187,187,187,187,187,187,187,187,189,187,187,187,187,187,187
187,187,187,187,187,187,187,187,187,187,187,187,187,187,187,187,187,187,187,187,187,187,187,187,187,187,187,187,187,187,187,187,187,187,187,187,187,187,187,187,8,8,187,187,187,187
187,187,187,187,4,187,187,187,187,187,187,187,187,187,187,187,187,187,187,187,187,187,187,187,187,187,187,187,187,187,187,187,187,187,187,187,187,187,187,8,8,8,8,187,187,187
187,187,187,8,8,4,187,187,187,187,187,187,187,187,187,187,187,187,187,187,187,187,187,187,187,187,187,187,187,187,187,187,187,187,187,187,187,187,187,187,187,187,187,187,187,187
187,187,187,8,8,4,187,187,187,187,187,187,187,187,187,187,187,187,187,187,187,187,187,187,187,187,187,187,187,187,187,187,187,187,187,187,187,187,187,187,187,187,187,187,187,187
187,187,187,8,8,193,187,193,4,4,187,187,187,187,187,187,187,187,187,187,187,187,187,187,187,187,187,187,187,187,187,187,187,187,187,187,187,187,187,187,187,187,187,187,187,187
187,187,187,8,8,187,187,187,187,187,187,187,187,187,187,187,187,187,187,187,187,187,187,187,187,187,187,187,187,187,187,187,187,187,187,187,187,187,187,187,187,187,187,187,187,187
187,187,187,187,187,187,187,187,187,187,187,187,187,187,187,187,187,187,187,187,187,187,187,187,187,187,187,187,187,187,187,187,187,187,187,187,187,187,187,187,187,187,187,187,187,187
187,187,187,187,187,187,187,187,187,187,187,187,187,187,187,187,187,187,187,187,187,187,187,187,187,187,187,187,187,187,187,187,187,187,187,187,187,187,187,187,8,187,187,187,187,187
187,187,187,187,187,187,187,187,187,187,187,187,187,187,187,187,187,187,187,187,187,187,187,187,187,187,187,187,187,187,187,187,187,187,187,187,187,187,187,8,8,8,8,187,187,187
187,187,187,187,187,187,187,187,187,187,187,187,187,187,187,187,187,187,187,187,187,187,187,187,187,187,187,187,187,187,187,187,187,187,187,187,187,187,8,8,8,8,8,187,187,187
187,187,187,187,187,187,187,187,187,187,187,187,8,8,8,187,187,187,187,187,187,187,187,187,187,187,187,187,187,187,187,187,187,187,187,187,187,187,187,8,8,8,8,187,187,187
187,187,187,187,187,187,187,187,187,187,187,187,8,187,8,8,187,187,187,187,187,187,187,187,187,187,187,187,187,187,187,187,187,187,187,187,187,187,187,187,187,188,187,187,187,187
187,187,187,187,187,187,187,8,8,8,187,187,8,8,8,187,187,187,187,187,187,187,187,1,1,1,187,187,187,187,187,187,187,187,187,187,187,187,187,187,187,187,187,187,187,187
187,187,187,187,187,8,8,8,8,187,187,187,187,8,8,187,187,187,187,187,187,187,1,0,0,0,1,187,187,187,187,187,187,187,187,187,187,187,187,187,187,187,187,187,187,187
187,187,187,187,187,8,8,8,8,4,187,187,187,187,187,187,187,187,187,187,187,187,1,0,0,0,1,187,187,187,187,187,187,187,187,187,187,187,187,187,187,8,8,8,187,187
187,187,187,187,187,187,187,8,187,187,187,187,187,187,187,187,187,187,187,187,187,187,1,0,0,0,1,187,187,187,187,8,8,187,187,187,187,187,187,187,8,8,8,8,8,187
187,187,187,187,187,187,187,187,187,187,187,187,187,187,187,187,187,187,187,7,187,187,1,0,0,0,1,187,187,8,8,8,8,187,187,187,187,187,187,187,8,8,8,8,8,187
187,187,187,187,187,187,187,187,187,187,187,187,187,187,187,187,187,0,187,7,7,1,1,35,35,35,1,187,8,8,8,8,187,187,187,187,187,187,187,187,187,8,8,8,187,187
187,187,187,187,187,187,187,187,187,187,187,187,187,187,187,187,187,0,0,7,7,1,1,1,1,1,187,187,187,8,8,8,8,187,187,187,187,4,187,187,187,187,187,187,187,187
187,187,187,187,187,187,187,187,187,187,187,187,187,187,187,187,187,0,7,7,7,1,1,187,1,1,187,187,187,8,8,8,187,187,187,187,187,4,4,4,4,187,187,187,187,187
187,187,187,187,187,187,187,187,187,187,187,187,187,187,187,187,187,190,7,7,7,1,187,187,187,187,187,187,187,187,187,187,187,187,187,187,187,8,8,8,187,187,187,187,187,187
187,187,187,187,187,187,187,187,187,187,187,187,187,187,187,187,187,187,187,8,187,187,187,187,187,187,187,187,187,187,187,187,187,187,187,187,187,187,187,8,8,187,187,187,187,187
187,187,187,187,187,187,187,187,187,187,187,187,187,187,187,187,187,187,187,187,187,187,187,187,187,187,187,187,187,187,187,187,187,187,187,187,187,187,187,187,187,187,187,187,187,187
187,187,187,187,187,187,187,187,187,187,187,187,187,187,187,187,187,187,187,187,187,187,187,187,187,187,187,187,187,187,187,187,187,187,187,187,187,187,187,187,187,187,187,187,187,187
187,187,187,187,187,187,187,187,187,187,187,187,187,187,187,187,187,187,187,187,187,187,187,187,187,187,187,187,187,187,187,187,187,187,187,187,187,187,187,187,187,187,187,187,187,187
:endlayer
layer: 13
187,187,187,187,187,187,187,187,187,187,187,187,187,187,187,187,187,187,187,187,187,187,187,187,187,187,187,187,187,187,187,187,187,187,187,187,187,187,187,187,187,187,187,187,187,187
187,187,187,187,187,8,8,187,187,187,187,187,8,8,8,187,187,187,187,187,187,187,187,187,187,187,187,187,187,187,187,187,187,187,187,187,187,187,8,8,187,187,187,187,187,187
187,187,187,8,8,8,8,8,187,187,187,8,8,8,8,8,187,187,187,187,187,187,187,187,187,187,187,187,187,187,187,187,187,187,187,187,187,8,8,8,8,8,187,187,187,187
187,187,187,8,8,8,8,8,8,187,187,8,8,8,8,8,8,187,187,187,187,8,8,187,187,187,187,187,187,187,187,8,187,187,187,187,187,8,8,8,8,8,187,187,187,187
187,187,8,8,8,8,8,8,8,187,187,8,8,8,8,8,8,187,187,187,8,8,8,8,187,187,187,187,187,8,8,8,8,8,187,187,187,8,8,8,8,8,187,187,187,187
187,187,187,8,8,8,8,8,8,187,187,8,8,8,8,8,8,187,187,8,8,8,8,8,187,187,187,187,187,8,8,8,8,8,8,187,187,8,8,8,8,1,187,187,187,187
187,187,187,8,8,8,8,8,8,187,187,8,8,8,8,8,187,187,8,8,8,8,8,8,8,187,187,187,4,8,8,8,8,8,8,187,187,1,8,8,8,1,187,187,187,187
187,187,187,187,187,8,187,187,187,187,187,187,8,187,187,187,187,187,187,8,8,8,8,8,187,187,187,187,187,8,8,8,8,8,8,187,187,187,1,187,1,187,8,187,187,187
187,187,187,187,187,187,187,187,187,187,187,187,187,187,187,187,187,187,187,8,8,8,8,8,8,187,187,187,187,8,8,8,8,8,187,187,187,187,187,187,8,8,8,8,8,187
187,187,187,187,187,187,187,187,187,187,187,187,187,8,187,187,187,187,187,187,187,187,187,187,187,187,187,187,187,187,187,187,187,187,187,187,187,187,187,187,8,8,8,8,8,187
187,187,187,187,187,187,187,187,187,187,187,187,8,8,8,187,187,187,187,187,187,187,187,187,187,187,187,187,187,187,187,187,187,187,187,187,187,187,187,187,8,8,8,8,8,187
187,187,187,187,187,187,187,187,187,187,187,187,8,8,8,187,187,187,187,187,187,187,187,187,187,187,187,187,187,187,187,187,187,187,187,187,187,187,187,187,8,8,8,8,8,187
187,187,187,187,187,187,187,187,187,187,187,187,8,197,187,187,187,187,187,187,187,187,187,187,187,187,187,187,187,187,187,187,187,187,187,187,187,187,187,8,8,8,8,8,8,187
187,187,187,187,187,187,187,187,187,187,187,187,187,187,187,187,187,187,187,187,187,187,187,187,187,187,187,187,187,187,187,187,187,187,187,187,187,187,187,187,187,187,8,8,187,187
187,187,187,187,187,187,187,187,187,187,187,187,187,187,187,187,187,187,187,187,187,187,187,187,187,187,187,187,187,187,187,194,187,187,187,187,187,187,8,8,8,8,187,187,187,187
187,187,187,187,187,187,187,187,187,187,187,187,187,187,187,187,187,187,187,187,187,187,187,187,187,187,187,187,187,187,187,187,187,187,187,187,187,187,8,8,8,8,8,187,187,187
187,187,187,187,187,187,187,187,187,187,187,187,187,187,187,187,187,187,187,187,187,187,8,187,187,187,187,187,187,187,187,187,187,187,187,187,187,187,8,8,8,8,8,187,187,187
187,187,8,8,4,8,8,187,187,187,187,187,187,187,187,187,187,187,187,187,187,187,196,187,187,187,187,187,187,187,187,187,187,187,187,187,187,187,8,8,8,8,8,8,187,187
187,8,8,8,8,4,8,187,187,187,187,187,187,187,187,187,187,187,187,187,187,187,187,187,187,187,187,187,187,187,187,187,187,187,187,187,187,187,8,8,8,8,8,187,187,187
187,187,8,8,8,4,8,8,8,8,8,187,187,187,187,187,187,187,187,187,187,187,187,187,187,187,187,187,187,8,187,187,187,187,187,187,187,187,187,8,8,8,187,187,187,187
187,187,8,8,8,193,8,193,8,8,8,187,187,187,187,187,187,187,187,187,187,187,187,187,187,187,187,187,187,187,187,187,187,187,187,187,187,187,187,187,187,187,187,187,187,187
187,187,8,8,8,8,8,8,187,8,187,187,187,187,187,187,187,187,187,187,187,187,187,187,187,187,187,187,187,187,187,187,187,187,187,187,187,187,187,187,187,187,187,187,187,187
187,187,187,8,8,8,187,187,187,187,187,187,187,187,187,187,187,187,187,187,187,187,187,187,187,187,187,187,187,187,187,187,187,187,187,187,187,187,187,187,187,187,187,187,187,187
187,187,187,187,187,187,187,187,187,187,187,187,187,190,190,187,187,187,187,187,187,187,187,187,187,187,187,187,187,187,187,187,187,187,187,187,187,187,8,8,8,8,8,187,187,187
187,187,187,187,187,187,187,187,187,187,187,187,8,8,8,8,187,187,187,187,187,187,187,187,187,187,187,187,187,187,187,187,187,187,187,187,187,187,8,8,8,8,8,187,187,187
187,187,187,187,187,187,187,187,187,187,187,190,8,8,8,8,187,187,187,187,187,187,187,187,187,187,187,187,187,187,187,187,187,187,187,187,187,187,8,8,8,8,8,187,187,187
187,187,187,187,190,187,190,190,190,187,8,8,8,8,8,8,187,187,187,187,187,187,187,187,187,187,187,187,187,187,187,187,187,187,187,187,187,187,8,8,8,8,8,187,187,187
187,187,187,187,187,8,8,8,8,8,8,8,8,8,8,8,187,187,187,187,187,187,187,187,187,187,187,187,187,187,187,187,187,187,187,187,187,187,8,8,8,8,8,187,187,187
187,187,187,187,190,8,8,8,8,8,190,8,8,8,8,8,187,187,187,187,187,187,187,1,1,1,187,187,187,187,187,187,187,187,187,187,187,187,187,8,8,8,187,8,187,187
187,187,187,187,8,8,8,8,8,8,8,8,8,8,8,187,187,187,187,7,7,7,1,0,0,0,1,187,187,187,187,187,187,187,187,187,187,187,187,187,8,8,8,8,8,187
187,187,187,187,8,8,8,8,8,8,187,187,187,187,187,187,187,187,187,7,7,7,1,0,0,0,1,7,187,187,187,187,187,187,187,187,187,187,187,187,8,8,8,8,8,187
187,187,187,187,190,8,8,8,8,8,187,187,187,187,187,187,187,187,187,7,7,7,1,0,0,0,1,7,7,8,8,8,8,187,187,187,187,187,187,8,8,8,8,8,8,187
187,187,187,187,190,190,190,8,190,187,187,187,187,187,187,187,187,1,7,7,7,1,1,0,0,0,1,1,7,8,8,8,8,8,187,187,187,187,187,187,8,8,8,8,8,187
187,187,187,187,187,187,187,190,187,187,187,187,187,187,187,187,1,0,0,7,7,1,1,195,0,195,1,1,8,8,8,8,8,187,187,187,8,8,8,8,8,8,8,8,8,187
187,187,187,187,187,187,187,187,187,187,187,187,187,187,187,187,1,0,0,7,7,1,1,35,35,35,1,1,8,8,8,8,8,8,187,187,8,8,8,8,8,8,8,8,187,187
187,187,187,187,187,187,187,187,187,187,187,187,187,187,187,187,187,0,7,7,7,1,1,1,1,1,1,1,8,8,8,8,8,187,187,187,8,8,8,8,8,8,187,187,187,187
187,187,187,187,187,187,187,187,187,187,187,187,187,187,187,187,187,0,7,7,7,1,1,1,1,1,1,187,8,8,8,8,187,187,187,187,8,8,8,8,8,187,187,187,187,187
187,187,187,187,187,187,187,187,187,187,187,187,187,187,187,187,187,187,8,8,8,187,187,187,187,187,187,187,187,187,187,187,187,187,187,187,8,8,8,8,8,187,187,187,187,187
187,187,187,187,187,187,187,187,187,187,187,187,187,187,187,187,187,187,187,187,187,187,187,187,187,187,187,187,187,187,187,187,187,187,187,187,187,187,8,8,187,187,187,187,187,187
187,187,187,187,187,187,187,187,187,187,187,187,187,187,187,187,187,187,187,187,187,187,187,187,187,187,187,187,187,187,187,187,187,187,187,187,187,187,187,187,187,187,187,187,187,187
187,187,187,187,187,187,187,187,187,187,187,187,187,187,187,187,187,187,187,187,187,187,187,187,187,187,187,187,187,187,187,187,187,187,187,187,187,187,187,187,187,187,187,187,187,187
:endlayer
layer: 14
190,190,190,190,190,190,190,190,190,190,190,190,190,190,190,190,190,190,190,190,190,190,190,190,190,190,190,190,190,190,190,190,190,190,190,190,190,190,190,190,190,190,190,190,190,190
190,190,190,8,8,8,8,8,8,190,190,8,8,8,8,8,8,190,190,190,190,190,190,190,190,190,190,190,190,190,190,190,190,190,190,190,190,190,8,8,8,8,190,190,190,190
190,190,8,8,8,8,8,8,8,187,8,8,8,8,8,8,8,190,190,190,187,190,8,190,190,190,190,190,190,190,190,190,190,190,190,190,8,8,8,8,8,8,8,187,190,190
190,190,8,8,8,8,8,8,8,190,8,8,8,8,8,8,8,190,8,8,8,8,8,190,190,190,190,190,8,8,8,8,8,8,187,190,8,8,8,8,8,8,8,190,190,190
190,190,8,8,8,8,8,8,8,8,8,8,8,8,8,8,8,8,8,8,8,8,8,8,8,190,190,190,8,8,8,8,8,8,8,190,8,8,8,8,8,8,8,8,190,190
190,190,8,8,8,8,8,8,8,187,8,8,8,8,8,8,8,187,8,8,8,8,8,8,8,190,190,190,8,8,8,8,8,8,8,187,8,8,8,8,8,1,8,190,190,190
190,190,8,8,8,8,8,198,198,198,198,198,8,8,8,187,187,187,8,8,8,8,8,8,8,8,190,190,8,8,8,8,8,8,8,187,187,187,8,8,8,1,190,190,187,190
190,190,8,190,190,187,198,198,198,198,198,198,187,187,187,187,187,187,8,8,8,8,8,8,8,187,187,187,8,8,8,8,8,8,8,187,187,187,187,187,187,8,8,8,8,190
190,190,190,190,190,187,198,198,198,198,198,198,8,187,187,187,198,198,187,1,1,8,8,1,1,1,1,1,1,1,1,8,1,1,1,187,198,198,187,187,8,8,8,8,8,190
190,190,190,190,190,187,198,198,198,8,8,8,8,187,187,198,198,198,198,1,1,1,1,1,1,1,1,1,1,1,1,1,1,1,1,198,198,198,198,198,198,8,8,8,8,190
190,190,190,190,190,187,198,198,8,8,8,8,8,8,187,198,198,198,187,1,1,1,1,1,1,1,1,1,1,1,1,1,1,1,1,187,198,198,198,198,198,8,8,8,8,190
190,190,190,190,190,187,198,198,8,8,8,8,8,8,187,187,198,187,187,1,1,1,1,1,1,1,187,187,1,1,1,1,1,1,1,187,187,198,187,187,8,8,8,8,8,190
190,190,187,190,190,187,198,198,8,8,8,8,8,198,8,1,1,1,1,8,8,8,8,1,3,1,187,187,1,1,1,1,1,1,1,1,1,1,1,8,8,8,8,8,8,190
190,190,190,190,190,198,198,198,8,8,8,8,8,8,8,1,1,1,1,8,8,8,8,8,8,1,187,187,1,1,1,1,1,1,1,1,1,1,1,8,8,8,8,8,8,190
190,190,190,190,190,187,198,198,198,8,8,8,8,8,8,1,1,1,1,8,8,8,8,8,8,1,187,187,1,1,1,8,1,1,1,1,1,1,1,8,8,8,8,8,187,190
190,190,190,190,8,8,198,198,198,204,204,198,198,198,187,1,1,1,1,8,8,8,8,8,8,1,187,187,1,1,1,1,1,1,1,1,1,1,1,8,8,8,8,8,190,190
190,190,8,8,8,8,8,8,8,204,204,198,198,198,187,1,1,1,1,8,8,8,8,8,1,1,187,187,1,1,1,1,1,1,1,1,1,1,8,8,8,8,8,8,190,190
190,8,8,8,8,8,8,8,8,8,8,8,198,198,187,1,1,1,1,8,8,8,1,8,1,1,8,8,8,8,8,8,8,8,1,1,1,1,8,8,8,8,8,8,190,190
190,8,8,8,8,8,8,8,8,8,8,8,198,198,187,1,1,1,1,1,1,1,1,1,1,1,8,8,8,8,8,8,8,8,1,1,1,1,1,8,8,8,8,8,190,190
190,8,8,8,8,8,8,8,8,8,8,8,187,187,187,1,1,1,1,1,1,1,1,1,1,1,1,8,8,8,8,8,8,8,1,1,1,1,1,8,8,8,8,8,190,190
190,8,8,8,8,3,8,3,8,8,8,187,190,190,187,1,1,1,1,1,1,1,1,1,1,1,1,8,8,8,8,8,8,8,1,1,1,1,1,187,8,190,187,190,190,190
190,8,8,8,8,8,8,8,190,190,190,190,190,190,187,1,1,1,1,1,1,1,1,1,1,1,8,8,8,8,8,8,8,1,1,1,1,1,1,187,190,190,190,190,190,190
190,190,8,8,8,8,8,190,190,190,190,190,190,190,187,1,1,1,1,1,1,1,1,1,1,1,187,8,1,8,1,8,1,1,1,1,1,1,1,8,8,8,8,190,190,190
190,190,190,8,8,190,8,190,187,187,187,187,190,202,0,1,1,1,1,1,1,1,1,1,1,1,187,187,1,1,1,1,1,1,1,1,1,1,1,8,8,8,8,8,190,190
190,190,190,187,190,190,190,190,187,187,187,187,0,0,0,1,1,1,1,1,1,1,1,1,1,1,187,187,1,1,1,1,1,1,1,1,1,1,1,8,8,8,8,8,187,190
190,190,190,190,190,190,190,190,187,187,187,0,0,0,0,1,1,1,1,1,1,1,1,1,1,1,187,187,1,1,1,1,1,1,1,1,1,1,8,8,8,8,8,8,8,190
190,190,190,190,0,190,0,205,0,187,0,0,0,0,0,0,1,1,1,1,1,1,1,1,1,1,187,187,1,1,1,1,1,1,1,1,1,1,8,8,8,8,8,8,190,190
190,190,190,190,190,0,0,0,0,187,0,0,203,203,0,1,1,1,1,1,1,1,1,1,1,1,187,187,1,1,1,1,1,1,1,1,1,1,1,8,8,8,8,8,190,190
190,190,190,190,0,0,0,205,0,0,0,0,0,0,0,0,198,187,187,1,1,1,1,1,1,1,7,7,1,1,1,1,1,1,1,187,187,198,187,8,8,8,8,8,8,190
190,190,190,190,0,0,0,0,195,0,187,187,0,198,0,198,198,198,7,37,37,37,37,1,1,1,1,1,1,1,1,1,1,1,1,187,198,198,198,198,198,8,8,8,8,190
190,190,190,190,0,0,0,205,0,0,187,187,187,198,198,198,198,198,7,0,0,0,0,0,0,0,0,23,1,1,1,1,1,1,1,198,198,198,198,198,198,8,8,8,8,190
190,190,190,190,0,0,0,0,0,187,187,187,187,187,187,187,198,198,7,0,0,0,0,0,0,0,0,23,1,8,8,1,1,1,1,187,198,198,187,187,8,8,8,8,8,190
190,190,190,190,0,0,0,205,0,187,187,187,187,187,187,187,187,1,7,0,0,0,0,0,0,0,0,1,7,8,8,8,8,8,187,187,187,187,187,187,8,8,8,8,8,190
190,190,190,190,190,187,190,205,187,187,187,187,187,187,187,187,1,0,0,201,195,195,195,195,0,195,195,1,8,8,8,8,8,8,190,187,8,8,8,8,8,8,8,8,8,190
190,190,190,190,190,190,190,190,187,187,187,187,187,187,187,187,1,0,0,201,0,0,0,0,0,0,0,1,8,8,8,8,8,8,190,8,8,8,8,8,8,8,8,8,8,190
190,190,190,190,190,190,190,190,187,187,187,187,187,187,187,187,187,7,7,0,0,0,0,200,0,0,199,1,8,8,8,8,8,8,190,8,8,8,8,8,8,8,8,8,190,190
190,190,190,187,190,190,190,190,187,187,187,187,187,187,187,187,187,0,7,7,7,1,1,1,1,1,1,187,8,8,8,8,8,8,190,8,8,8,8,8,8,8,8,187,190,190
190,190,190,190,190,190,190,190,187,187,187,187,187,187,187,187,187,187,8,8,8,8,8,190,8,190,190,190,190,187,8,8,190,190,187,8,8,8,8,8,8,8,190,190,190,190
190,190,190,190,190,190,190,190,187,187,187,187,187,187,187,187,187,187,190,190,8,190,190,190,190,190,190,190,190,190,190,190,190,190,190,8,8,8,8,8,8,190,190,190,190,190
190,190,190,190,190,190,190,190,190,190,190,190,190,190,190,190,190,190,190,190,190,190,190,190,190,190,190,190,190,190,190,190,190,190,190,190,190,8,8,190,190,190,190,190,190,190
190,190,190,190,190,190,190,190,190,190,190,190,190,190,190,190,190,190,190,190,190,190,190,190,190,190,190,190,190,190,190,190,190,190,190,190,190,190,190,190,190,190,190,190,190,190
:endlayer
layer: 15
0,0,0,0,0,0,0,0,202,202,202,202,0,0,202,0,202,202,202,202,202,0,202,0,0,0,202,0,202,0,0,0,0,0,0,0,0,0,0,0,0,202,202,202,202,0
0,0,0,0,0,0,0,0,0,0,202,0,0,0,0,0,0,202,202,202,202,202,202,0,0,0,0,202,202,202,0,0,0,0,202,202,0,0,0,0,0,0,202,202,202,0
0,0,0,0,0,0,0,0,0,177,0,0,0,0,0,0,0,202,202,0,177,202,0,202,0,0,0,202,202,202,0,0,0,0,0,202,0,0,0,0,0,0,0,177,0,0
0,202,0,0,0,0,0,0,0,0,0,0,0,0,0,0,0,202,0,0,0,0,0,0,0,0,202,202,0,0,0,0,0,0,177,202,0,0,0,0,0,0,0,202,202,202
0,202,0,0,0,0,0,0,0,0,0,0,0,0,0,203,203,203,0,0,0,0,0,0,0,202,0,202,0,0,0,0,0,0,0,202,0,203,203,203,203,0,0,0,202,202
202,202,0,0,205,0,0,205,0,1,1,0,0,0,0,0,198,198,0,201,0,0,0,0,0,0,0,0,0,0,0,0,0,0,0,198,198,0,203,205,0,198,0,202,202,202
202,202,0,0,205,1,192,195,195,195,195,0,198,198,198,198,198,198,0,201,0,0,0,203,203,0,203,0,203,203,203,203,203,203,197,198,198,198,198,198,198,198,0,0,177,202
0,215,0,0,205,1,0,0,0,0,0,0,198,198,198,198,198,198,198,0,0,0,0,0,198,198,198,198,198,0,0,0,0,205,0,198,198,198,198,198,198,198,0,0,0,202
0,0,0,0,205,1,201,0,0,0,0,0,198,198,198,198,0,0,1,192,0,192,195,195,209,0,0,0,0,0,0,0,0,0,0,1,0,0,198,206,206,0,201,0,0,0
0,0,0,0,202,1,0,0,0,0,0,205,0,198,198,212,0,0,1,201,0,0,0,205,0,0,0,0,0,0,0,0,0,0,0,1,0,0,0,0,0,0,201,0,0,0
0,0,0,0,0,1,201,0,0,0,0,0,0,198,198,212,0,0,1,201,203,0,0,205,0,0,0,0,0,0,0,0,0,0,0,1,0,0,0,0,0,0,201,0,0,0
0,0,202,202,205,1,214,0,0,0,0,0,0,198,198,1,0,1,198,201,0,0,0,0,0,198,198,198,198,0,0,198,0,0,198,198,1,0,1,198,198,0,201,0,0,0
0,202,177,202,0,1,0,0,0,0,0,0,195,209,198,0,0,0,198,0,0,0,0,0,195,0,198,198,195,195,195,195,0,0,0,198,0,0,0,198,195,195,0,0,0,0
0,202,202,202,205,6,0,0,0,0,0,0,0,0,0,0,0,0,198,0,0,0,0,0,0,195,198,198,0,0,0,0,0,0,0,198,0,0,0,198,201,0,0,0,0,0
0,202,202,202,202,1,0,0,0,0,0,0,0,0,0,0,0,0,198,0,0,0,0,0,0,0,198,198,0,0,0,0,0,0,205,198,0,0,0,198,201,0,0,0,177,0
0,202,202,202,0,1,0,0,0,204,204,0,0,0,198,0,0,0,0,201,0,0,0,0,0,0,198,198,201,0,0,0,0,0,0,198,0,0,0,192,201,0,0,0,0,0
0,0,0,0,0,0,0,0,0,204,204,0,0,0,198,0,0,0,0,201,0,0,0,0,0,205,198,198,201,0,0,0,0,0,205,0,0,0,0,0,201,0,0,0,0,0
0,0,0,0,205,0,0,0,0,0,0,0,0,0,198,0,0,0,0,201,0,0,0,0,0,205,198,198,0,0,0,0,0,0,205,0,0,0,0,0,201,0,0,0,0,0
0,0,0,0,205,0,0,0,0,0,0,0,0,0,198,0,0,0,198,0,0,0,0,0,0,205,0,0,0,0,0,0,0,0,205,198,0,0,0,0,0,0,0,0,202,202
0,0,0,0,205,0,0,0,0,0,0,0,1,1,198,0,0,0,198,201,0,0,0,0,0,0,0,0,0,0,0,0,0,0,205,198,0,0,0,198,0,0,0,0,202,202
0,0,0,0,0,195,195,195,1,1,1,1,202,202,198,0,0,0,198,201,0,0,0,0,0,205,0,0,0,0,0,0,0,0,205,198,0,0,0,198,0,0,177,202,0,202
0,0,0,0,0,0,0,0,202,202,202,202,0,202,198,0,0,0,198,0,0,0,0,195,195,205,198,0,0,0,0,0,0,0,0,198,0,0,0,198,0,0,0,0,202,0
0,0,0,0,0,0,0,202,203,0,202,202,202,205,198,0,0,0,0,0,0,0,0,0,0,205,198,198,201,0,0,0,0,0,0,0,0,0,0,198,0,0,0,0,202,0
0,0,0,0,0,0,0,205,198,198,198,198,202,205,198,0,0,0,0,201,0,0,0,0,0,205,198,198,201,0,0,0,0,0,0,0,0,0,0,198,0,0,0,0,0,0
0,0,0,177,0,0,0,205,198,198,198,198,0,0,0,0,0,0,198,0,0,0,0,0,0,205,198,198,201,0,0,0,0,0,205,198,0,0,0,0,0,0,0,0,177,202
0,0,202,0,202,0,0,205,198,198,198,0,0,0,0,0,0,0,198,201,0,0,0,0,0,205,198,198,201,0,0,0,0,0,205,198,0,0,0,0,0,0,0,0,0,0
0,0,202,202,0,0,0,205,198,198,198,0,0,0,0,0,0,0,198,0,0,0,0,0,203,197,198,198,0,0,0,0,0,0,205,198,0,0,0,0,0,0,0,0,202,202
0,202,213,0,0,0,0,0,198,198,198,0,203,203,0,0,0,0,198,0,0,0,0,205,0,0,198,198,0,0,0,0,0,0,197,198,0,0,0,0,203,203,0,0,0,202
0,202,202,202,0,0,0,205,0,198,198,111,0,0,0,1,0,1,198,0,0,0,0,7,7,7,7,198,198,0,0,198,0,0,198,198,1,0,1,0,0,0,201,0,0,0
0,202,202,202,0,0,0,0,195,198,198,198,198,0,0,0,0,0,1,0,0,0,0,0,0,0,0,0,0,0,0,0,0,0,0,1,0,0,0,0,0,0,201,0,0,0
0,202,202,0,0,0,0,205,0,198,198,198,0,195,195,0,0,0,7,0,0,0,0,0,0,0,0,0,0,0,0,0,0,0,0,0,0,0,0,0,0,0,201,0,0,0
0,202,0,0,0,0,0,0,0,198,198,198,198,0,0,195,0,0,1,0,0,0,0,0,0,0,0,0,0,0,0,0,0,0,0,1,0,0,198,207,207,0,201,0,0,0
202,0,202,202,0,0,0,205,198,198,198,198,0,0,0,0,198,198,198,0,0,0,0,0,0,0,0,198,7,0,0,0,0,198,198,198,198,198,198,198,0,0,201,0,0,0
0,0,202,202,202,177,0,205,198,198,198,198,0,201,0,0,198,198,0,201,195,195,195,195,0,195,195,7,192,195,0,0,0,195,209,198,198,198,198,0,0,0,201,0,0,0
202,202,202,202,202,202,0,205,198,198,198,198,195,0,0,205,198,198,0,201,0,0,0,0,0,0,0,7,0,0,0,0,0,0,205,198,0,201,0,0,0,0,0,0,0,0
202,202,202,202,202,0,0,0,198,198,198,198,198,198,198,198,198,7,7,0,0,0,0,0,0,0,0,7,0,0,0,0,0,0,0,0,208,195,195,195,195,0,0,0,0,0
0,0,202,177,0,0,0,205,198,198,198,198,198,198,198,198,198,7,7,7,7,7,7,1,1,1,1,7,0,0,0,0,0,0,0,0,0,0,0,0,0,0,0,177,0,0
0,0,0,0,0,0,202,0,198,198,198,198,198,198,198,198,198,211,210,0,0,0,0,0,0,0,0,0,202,177,0,0,0,0,177,0,0,0,0,0,0,0,0,0,0,0
0,0,0,202,202,0,202,0,198,198,198,198,198,198,198,198,198,211,210,0,0,202,202,202,0,0,0,0,202,202,0,202,0,0,0,0,0,0,0,0,0,202,202,0,202,0
0,202,202,0,202,0,0,0,195,195,195,0,202,202,213,202,0,0,0,0,202,202,202,202,0,0,0,0,202,202,202,0,0,0,0,0,0,0,0,202,0,202,0,202,0,0
0,0,0,0,202,202,202,0,0,0,0,202,0,202,202,202,0,0,0,0,202,202,202,0,202,0,0,202,0,202,202,202,0,0,0,0,0,0,0,0,202,202,202,0,202,0
:endlayer
layer: 16
0,0,0,0,0,0,0,0,0,0,0,0,0,0,0,0,0,0,0,0,0,0,0,0,0,0,0,0,0,0,0,0,0,0,0,0,0,0,0,0,0,0,0,0,0,0
0,0,0,0,0,0,0,0,0,0,0,0,0,0,0,0,0,0,0,0,0,0,0,0,0,0,0,0,0,0,0,0,0,0,0,0,0,0,0,0,0,0,0,0,0,0
0,0,0,0,0,0,0,0,0,177,0,0,0,0,0,0,0,0,0,0,177,0,0,0,0,0,0,0,0,0,0,0,0,0,0,0,0,0,0,0,0,0,0,177,0,0
0,0,0,0,0,0,0,0,0,0,0,0,0,0,0,0,0,0,0,0,0,0,0,0,0,0,0,0,0,0,0,0,0,0,177,0,0,0,0,0,0,0,0,0,0,0
0,0,0,0,0,0,0,0,0,0,0,0,0,0,0,203,203,203,0,0,0,0,0,0,0,0,0,0,0,0,0,0,0,0,0,0,0,203,203,203,203,0,216,216,216,216
0,0,0,0,205,0,0,205,1,1,1,0,0,0,0,0,1,1,0,201,0,0,0,0,0,0,0,0,0,0,0,0,0,0,0,198,0,0,0,205,0,0,216,216,216,216
0,0,0,0,205,1,192,195,195,195,195,0,1,198,198,198,198,198,0,201,0,0,0,203,203,0,203,0,203,203,203,203,203,203,197,1,198,198,212,0,209,1,216,216,177,216
0,0,0,0,205,1,0,0,0,0,0,0,1,198,198,198,198,198,1,0,0,0,0,0,1,1,1,1,1,0,0,0,0,205,1,1,198,198,212,0,0,1,216,216,216,216
0,0,0,0,205,1,201,0,0,0,0,0,1,206,206,198,0,0,1,192,0,192,195,195,209,0,0,0,0,0,0,0,0,0,0,1,0,0,198,0,0,0,201,216,216,216
0,0,0,0,205,1,0,0,0,0,0,205,1,0,0,0,0,0,1,201,0,0,0,205,0,0,0,0,0,0,0,0,0,0,0,1,0,0,0,0,0,0,201,0,0,0
0,0,0,0,0,1,201,0,0,0,0,0,0,0,0,0,0,0,1,201,203,0,0,205,0,0,0,0,0,0,0,0,0,0,0,1,0,0,0,0,0,0,201,0,0,0
0,0,0,0,205,1,214,0,0,0,0,0,0,1,1,1,0,1,0,201,0,0,0,0,0,198,198,198,198,0,0,198,0,0,198,198,1,0,1,1,1,0,201,0,0,0
0,0,177,0,0,1,0,0,0,0,0,0,195,209,1,0,0,0,0,0,0,0,0,0,195,0,198,198,195,195,195,195,0,0,0,198,0,0,0,1,195,195,216,216,216,216
0,0,0,0,205,217,0,0,0,0,0,0,0,0,0,0,0,0,0,0,0,0,0,0,0,195,198,198,0,0,0,0,0,0,0,198,0,0,0,1,201,0,216,216,216,216
0,0,0,0,218,1,0,0,0,0,0,0,0,0,1,0,0,0,0,0,0,0,0,0,0,0,198,198,0,0,0,0,0,0,205,198,0,0,0,1,201,0,216,216,177,216
0,0,0,0,0,0,0,0,0,204,204,0,0,0,1,0,0,0,0,201,0,0,0,0,0,0,198,198,201,0,0,0,0,0,0,198,0,0,0,192,201,0,216,216,216,216
0,0,0,0,0,0,0,0,0,204,204,0,0,0,1,0,0,0,0,201,0,0,0,0,0,205,198,198,201,0,0,0,0,0,205,0,0,0,0,0,201,0,216,216,216,216
0,0,0,0,205,0,0,0,0,0,0,0,0,0,1,0,0,0,0,201,0,0,0,0,0,205,198,111,0,0,0,0,0,0,205,0,0,0,0,0,201,0,0,0,0,0
0,0,0,0,205,0,0,0,0,0,0,0,0,0,1,0,0,0,198,0,0,0,0,0,0,205,0,0,0,0,0,0,0,0,205,198,0,0,0,0,0,0,0,0,0,0
0,0,0,0,205,0,0,0,0,0,0,0,1,1,1,0,0,0,198,201,0,0,0,0,0,0,0,0,0,0,0,0,0,0,205,198,0,0,0,0,0,0,0,0,0,0
0,0,0,0,0,195,195,195,1,1,1,1,0,205,1,0,0,0,198,201,0,0,0,0,0,205,0,0,0,0,0,0,0,0,205,198,0,0,0,1,0,0,177,0,0,0
0,0,0,0,0,0,0,0,205,0,0,0,0,205,1,0,0,0,198,0,0,0,0,195,195,205,198,0,0,0,0,0,0,0,0,198,0,0,0,1,0,0,0,0,0,0
0,0,0,0,0,0,0,0,203,0,0,0,0,205,1,0,0,0,0,0,0,0,0,0,0,205,198,198,201,0,0,0,0,0,0,0,0,0,0,1,0,0,0,216,216,216
0,0,0,0,0,0,0,205,198,198,198,198,0,205,1,0,0,0,0,201,0,0,0,0,0,205,198,198,201,0,0,0,0,0,0,0,0,0,0,1,0,0,216,216,216,216
0,0,0,177,0,0,0,205,198,198,198,198,0,0,0,0,0,0,198,0,0,0,0,0,0,205,198,198,201,0,0,0,0,0,205,198,0,0,0,0,0,0,216,216,177,216
0,0,0,0,0,0,0,205,198,198,198,0,0,0,0,0,0,0,198,201,0,0,0,0,0,205,198,198,201,0,0,0,0,0,205,198,0,0,0,0,0,0,216,216,216,216
0,0,0,0,0,0,0,205,198,198,198,0,0,0,0,0,0,0,198,0,0,0,0,0,203,197,198,198,0,0,0,0,0,0,205,198,0,0,0,0,0,0,216,216,216,216
0,0,0,0,0,0,0,0,0,198,198,0,203,203,0,0,0,0,198,0,0,0,0,205,0,0,198,198,0,0,0,0,0,0,203,198,0,0,0,0,203,203,0,0,0,0
0,0,0,0,0,0,0,205,0,198,198,0,0,0,0,1,0,1,198,0,0,0,0,7,0,7,7,198,198,0,0,198,0,0,198,198,1,0,1,1,0,0,201,0,0,0
0,0,0,0,0,0,0,0,195,198,198,198,1,0,0,0,0,0,1,0,0,0,0,0,0,0,0,0,0,0,0,0,0,0,0,1,0,0,0,0,0,0,201,0,0,0
0,0,0,0,0,0,0,205,0,198,198,198,0,192,195,0,0,0,0,0,0,0,0,0,0,0,0,0,0,0,0,0,0,0,0,0,0,0,0,0,0,0,201,0,0,0
0,0,0,0,0,0,0,0,0,198,198,198,0,0,0,195,0,0,1,0,0,0,0,0,0,0,0,0,0,0,0,0,0,0,0,1,0,0,198,0,0,0,201,0,0,0
0,0,0,0,0,0,0,205,198,198,198,198,0,0,0,0,198,198,1,0,0,0,0,0,0,0,0,1,7,0,0,0,0,0,1,1,198,198,212,0,0,0,201,0,0,0
0,0,0,0,0,177,0,205,198,198,198,198,0,201,0,0,198,198,0,201,195,195,195,195,0,195,195,7,192,195,0,0,0,195,209,1,198,198,212,0,0,0,201,0,0,0
0,216,216,216,216,0,0,205,198,198,198,198,195,0,0,205,1,1,0,201,0,0,0,0,0,0,0,7,0,0,0,0,0,0,205,198,0,201,0,0,0,0,216,216,216,216
0,216,216,216,216,216,0,0,198,198,198,198,198,198,198,7,7,7,7,0,0,0,0,0,0,0,0,7,0,0,0,0,216,216,216,216,216,195,195,195,195,216,216,216,216,216
0,216,216,177,216,216,0,205,198,198,198,198,198,198,198,7,7,7,7,7,7,7,7,7,7,7,7,7,0,0,0,0,216,216,216,216,216,0,0,0,0,216,216,177,216,216
0,216,216,216,216,216,0,0,198,198,198,198,198,0,198,211,210,0,0,0,0,0,0,0,0,0,0,0,0,177,0,0,216,216,177,216,216,0,0,0,0,216,216,216,216,216
0,216,216,216,216,216,0,0,198,198,198,198,198,198,198,211,210,0,0,0,0,0,0,0,0,0,0,0,0,0,0,0,216,216,216,216,216,0,0,0,0,216,216,216,216,216
0,0,0,0,0,0,0,0,195,195,195,0,0,0,0,0,0,0,0,0,0,0,0,0,0,0,0,0,0,0,0,0,216,216,216,216,216,0,0,0,0,0,0,0,0,0
0,0,0,0,0,0,0,0,0,0,0,0,0,0,0,0,0,0,0,0,0,0,0,0,0,0,0,0,0,0,0,0,0,0,0,0,0,0,0,0,0,0,0,0,0,0
:endlayer
layer: 17
0,0,0,0,0,0,0,0,216,216,216,216,0,0,0,0,0,0,0,216,216,216,216,0,0,0,0,0,0,0,0,0,0,0,0,0,0,0,0,0,0,0,0,0,0,0
0,0,0,0,0,0,0,216,216,216,216,216,0,0,0,0,0,0,216,216,216,216,216,0,0,0,0,0,0,0,0,0,0,0,0,0,0,0,0,0,0,0,0,0,0,0
0,0,0,0,0,0,0,216,216,177,216,216,0,0,0,0,0,0,216,216,177,216,216,0,0,0,0,0,0,0,0,0,0,0,0,0,0,0,0,0,0,0,0,177,0,0
0,0,0,0,0,0,0,216,216,216,216,216,0,0,0,0,0,0,216,216,216,216,216,0,0,0,0,0,0,0,0,0,0,0,177,0,0,0,0,0,0,0,0,0,0,0
0,0,0,0,0,0,0,0,216,216,216,0,0,0,0,203,203,203,216,216,216,216,216,0,0,0,0,0,0,0,0,0,0,0,208,0,0,203,203,203,203,0,216,216,216,216
0,0,0,0,205,0,0,205,1,1,0,0,0,0,0,0,1,1,198,201,0,0,0,0,0,0,0,0,0,0,0,0,0,0,208,198,1,0,0,205,1,0,216,216,216,216
0,0,0,0,205,1,192,195,195,195,195,0,1,0,0,219,198,198,0,201,0,0,0,203,203,0,203,0,203,203,203,203,203,203,197,1,0,0,0,0,209,1,216,216,177,216
0,0,0,0,205,1,0,0,0,0,0,0,1,0,0,219,198,198,1,0,0,0,0,0,1,1,1,1,1,1,0,0,0,205,1,1,0,0,205,0,0,1,216,216,216,216
0,0,0,0,205,1,201,0,0,0,0,0,1,0,0,198,198,198,1,192,0,192,195,195,209,0,0,0,0,0,0,0,0,0,0,1,207,207,198,0,0,0,201,216,216,216
0,0,0,0,205,1,0,0,0,0,0,205,0,0,0,0,0,0,1,201,0,0,0,205,0,0,0,0,0,0,0,0,0,0,0,1,0,0,0,0,0,0,201,0,0,0
0,0,0,0,0,1,201,0,0,0,0,0,0,0,0,0,0,0,1,201,203,0,0,205,0,0,0,0,0,0,0,0,0,0,0,1,0,0,0,0,0,0,201,0,0,0
0,0,0,0,205,1,214,0,0,0,0,0,0,1,1,1,1,1,198,201,0,0,0,0,198,198,198,198,198,198,198,198,198,198,198,198,1,1,1,1,1,0,201,0,0,0
0,0,177,0,0,1,0,0,0,0,0,0,195,209,1,0,0,0,0,0,0,0,0,0,195,0,198,198,195,195,195,195,0,0,0,198,0,0,0,1,195,195,216,216,216,216
0,0,0,0,205,1,0,0,0,0,0,0,0,0,0,0,0,0,0,0,0,0,0,0,0,195,198,198,0,0,0,0,0,0,0,198,0,0,0,1,201,0,216,216,216,216
0,0,0,0,205,1,0,0,0,0,0,0,0,0,1,0,0,0,0,0,0,0,0,0,0,0,198,198,0,0,0,0,0,0,205,198,0,0,0,1,201,0,216,216,177,216
0,0,0,0,0,1,0,0,0,204,204,0,0,0,1,0,0,0,0,201,0,0,0,0,0,0,198,198,201,0,0,0,0,0,0,198,0,0,0,192,201,0,216,216,216,216
0,0,0,0,0,0,0,0,0,204,204,0,1,1,1,0,0,0,0,201,0,0,0,0,0,205,198,198,201,0,0,0,0,0,205,198,0,0,0,0,201,0,0,216,216,216
0,0,0,0,205,1,0,0,0,0,0,0,1,1,1,0,0,0,198,201,0,0,0,0,0,205,198,0,0,0,0,0,0,0,205,198,0,0,0,0,201,0,0,0,0,0
0,0,0,0,205,0,0,0,0,0,0,0,1,1,1,0,0,0,198,0,0,0,0,0,0,205,198,0,0,0,0,0,0,0,205,198,0,0,0,0,216,216,216,216,0,0
0,0,0,0,205,0,1,0,0,0,0,1,1,1,1,0,0,0,198,0,0,0,0,0,0,0,198,0,0,0,0,0,0,0,205,198,0,0,0,1,216,216,216,216,216,0
0,0,0,0,0,195,195,195,1,1,1,1,0,205,1,0,0,0,198,201,208,0,0,0,0,205,198,0,0,0,0,0,0,0,205,198,0,0,0,1,216,216,177,216,216,0
0,0,0,0,0,0,0,0,205,0,0,0,0,205,1,0,0,0,198,0,0,0,0,195,195,205,198,0,0,0,0,0,0,0,0,198,0,0,0,1,216,216,216,216,216,0
0,0,216,216,216,0,0,0,203,0,0,0,0,205,1,0,0,0,198,0,0,0,0,0,0,205,198,198,201,0,0,0,0,0,0,198,0,0,0,1,216,216,216,216,216,216
0,216,216,216,216,216,0,205,198,198,198,198,0,205,1,0,0,0,198,201,0,0,0,0,0,205,198,198,201,0,0,0,0,0,0,198,0,0,0,1,0,0,216,216,216,216
0,216,216,177,216,216,0,205,198,198,198,198,0,0,1,0,0,0,198,0,0,0,0,0,0,205,198,198,201,0,0,0,0,0,205,198,0,0,0,0,0,0,216,216,177,216
0,216,216,216,216,216,0,205,198,198,198,0,0,0,0,0,0,0,198,201,0,0,0,0,0,205,198,198,201,0,0,0,0,0,205,198,0,0,0,0,0,0,216,216,216,216
0,0,216,216,216,0,0,205,198,198,198,0,0,0,0,0,0,0,198,0,0,0,0,0,203,197,198,198,0,0,0,0,0,0,205,198,0,0,0,0,0,0,216,216,216,216
0,0,0,0,0,0,0,0,0,198,198,0,203,203,0,0,0,0,198,0,0,0,0,205,0,0,198,198,0,0,0,0,0,0,203,198,0,0,0,0,214,203,0,0,0,0
0,0,0,0,0,0,0,205,0,198,198,198,0,0,1,1,1,1,198,0,0,0,0,7,7,7,7,198,198,198,198,198,198,198,198,198,1,1,1,1,1,0,201,0,0,0
0,0,0,0,0,0,0,0,195,198,198,198,1,0,0,0,0,0,1,0,0,0,0,0,0,0,0,0,0,0,0,0,0,0,0,1,0,0,0,0,0,0,201,0,0,0
0,0,0,0,0,0,0,205,0,198,198,198,0,192,195,0,0,0,1,0,0,0,0,0,0,0,0,0,0,0,0,0,0,0,0,1,0,0,0,0,0,0,201,0,0,0
0,0,0,0,0,0,0,0,0,198,198,198,0,0,0,195,206,206,1,0,0,0,0,0,0,0,0,0,0,0,0,0,0,0,0,1,206,206,198,0,0,0,201,0,0,0
0,0,0,0,0,0,0,0,0,198,198,198,0,0,0,0,0,205,1,0,0,0,0,0,0,0,0,0,7,0,0,0,0,1,1,1,0,0,0,0,0,0,201,0,0,0
0,0,0,0,0,177,0,205,198,198,198,198,0,201,0,0,203,205,0,201,195,195,195,195,0,195,195,7,192,195,0,0,0,195,209,1,0,0,0,0,0,0,201,0,0,0
0,0,216,216,216,0,0,205,0,198,0,0,195,0,0,205,0,1,0,201,0,0,0,0,0,0,0,7,0,0,0,0,0,0,205,198,0,201,0,0,0,216,216,216,216,0
0,216,216,216,216,216,0,0,195,0,195,0,0,0,0,0,0,7,7,0,0,0,0,0,0,0,0,7,0,0,0,0,0,216,216,216,216,195,195,195,195,216,216,216,216,216
0,216,216,177,216,216,0,205,198,0,0,0,0,0,0,7,7,7,7,7,7,7,0,7,7,7,0,7,0,0,0,0,216,216,216,216,216,0,0,0,0,216,216,177,216,216
0,216,216,216,216,216,0,0,0,0,0,0,0,0,0,0,0,0,0,0,0,0,0,0,0,0,0,0,0,177,0,0,216,216,177,216,216,0,0,0,0,216,216,216,216,216
0,0,216,216,216,216,0,0,198,198,0,0,0,211,210,0,0,0,0,0,0,0,0,0,0,0,0,0,0,0,0,0,216,216,216,216,216,0,0,0,0,0,216,216,216,216
0,0,0,0,0,0,0,0,195,195,0,0,0,0,0,0,0,0,0,0,0,0,0,0,0,0,0,0,0,0,0,0,0,216,216,216,0,0,0,0,0,0,0,0,0,0
0,0,0,0,0,0,0,0,0,0,0,0,0,0,0,0,0,0,0,0,0,0,0,0,0,0,0,0,0,0,0,0,0,0,0,0,0,0,0,0,0,0,0,0,0,0
:endlayer
layer: 18
0,0,0,0,0,0,0,216,216,216,216,0,0,0,0,0,0,0,216,216,216,216,216,0,0,0,0,0,0,0,0,0,0,0,0,0,0,0,0,0,0,216,216,216,216,216
0,0,0,0,0,0,0,216,216,216,216,216,0,0,0,0,0,0,216,216,216,216,216,0,0,0,0,0,0,0,0,0,216,216,216,216,0,0,0,0,0,216,216,216,216,216
0,0,0,0,0,0,0,216,216,177,216,216,0,0,0,0,0,0,216,216,177,216,216,0,0,0,0,0,0,0,0,0,216,216,216,216,216,0,0,0,0,216,216,177,216,216
0,0,0,0,0,0,0,216,216,216,216,216,0,0,0,0,0,0,216,216,216,216,216,0,0,0,0,0,0,0,0,0,216,216,177,216,216,0,0,0,0,216,216,216,216,216
0,0,0,0,0,0,0,0,216,216,216,0,0,0,0,203,203,203,216,216,216,216,216,0,0,0,0,0,0,0,0,0,216,216,216,216,216,203,203,203,203,0,216,216,216,0
0,0,0,0,205,0,0,205,1,1,1,1,0,0,0,1,1,1,198,201,0,0,0,0,0,0,0,0,0,0,0,0,216,216,216,198,1,0,1,1,0,0,201,216,216,216
0,0,0,0,205,1,192,195,195,195,195,0,1,0,0,0,0,0,1,201,0,0,0,203,203,0,203,0,203,203,203,203,203,203,197,1,0,0,0,0,205,1,201,216,177,216
0,0,0,0,205,1,0,0,0,0,0,0,1,0,0,0,0,205,1,0,0,0,0,0,1,1,1,1,1,1,0,0,0,1,1,1,0,0,205,0,0,1,201,216,216,216
0,0,0,0,205,1,201,0,0,0,0,0,1,0,0,198,207,207,198,192,0,192,195,195,209,198,198,198,198,111,198,198,198,198,198,1,0,0,198,0,0,0,201,0,0,0
0,0,0,0,205,1,0,0,0,0,0,205,0,0,0,198,198,198,198,201,0,0,0,205,0,198,198,198,198,198,198,198,198,198,198,198,207,207,198,198,198,0,201,0,0,0
0,0,0,0,0,1,201,0,0,0,0,0,0,0,0,198,198,198,198,201,203,0,0,205,198,198,198,198,198,198,198,198,198,198,198,198,198,198,198,198,198,0,201,0,0,0
0,0,0,0,205,1,214,0,0,0,0,0,198,1,1,198,198,198,198,201,0,0,0,198,198,198,198,198,198,198,198,198,198,198,198,198,198,198,198,1,1,0,201,0,0,0
0,0,177,0,0,1,0,0,0,0,0,0,195,209,1,198,198,198,0,0,0,0,0,0,195,220,198,198,220,220,220,220,220,220,220,198,198,198,198,1,195,195,0,0,0,0
0,0,0,0,205,1,0,0,0,0,0,0,0,0,1,198,198,198,198,0,0,0,0,0,0,195,220,220,0,0,220,0,220,220,220,198,198,198,198,1,201,0,0,216,216,0
0,0,0,0,205,1,0,0,0,0,0,0,0,0,1,198,198,198,0,0,0,0,0,0,0,0,220,0,0,0,0,0,0,0,220,198,198,198,198,0,201,0,0,216,177,216
0,0,0,0,0,1,1,1,0,1,1,1,1,1,1,198,198,198,198,201,0,0,0,0,0,0,220,0,0,0,0,0,0,0,220,198,198,198,198,201,201,0,0,0,216,0
0,0,0,0,0,1,0,0,0,204,204,1,0,0,1,198,198,198,198,201,0,0,0,0,0,220,220,0,0,0,0,0,0,0,220,198,198,198,198,0,201,0,0,0,0,0
0,0,0,0,205,1,0,0,0,0,0,0,0,0,1,198,198,198,198,201,0,0,0,0,220,220,198,0,0,0,0,0,0,0,220,198,198,198,198,0,201,0,0,0,0,0
0,0,0,0,205,1,1,0,0,0,0,1,0,1,1,198,198,198,198,220,0,0,220,220,220,220,220,0,0,0,0,0,0,0,205,198,198,198,198,0,216,216,216,216,216,0
0,0,0,0,205,0,1,1,0,0,0,1,1,1,1,198,198,198,198,0,0,0,220,220,220,220,220,0,0,0,0,0,0,0,205,198,198,198,198,1,216,216,216,216,216,0
0,0,0,0,0,195,195,195,1,1,1,1,0,205,1,198,198,198,198,220,220,220,220,220,0,220,220,0,0,0,0,0,0,0,220,198,198,198,198,1,216,216,177,216,216,0
0,0,0,0,0,0,0,0,205,0,0,0,0,205,1,0,0,0,0,220,220,220,220,195,195,220,220,0,0,0,0,0,0,0,220,198,198,198,198,1,216,216,216,216,216,0
0,216,216,216,216,216,0,0,203,0,0,0,0,205,0,0,0,0,0,220,220,220,220,0,0,205,0,0,0,0,0,0,0,0,220,198,198,198,198,1,216,216,216,216,216,0
0,216,216,216,216,216,0,205,198,198,198,198,0,0,0,0,0,0,0,220,220,220,220,0,0,205,0,0,0,0,0,0,220,220,220,198,198,198,198,1,0,0,0,0,216,216
0,216,216,177,216,216,0,205,198,198,198,198,0,0,0,0,0,0,0,0,220,220,220,0,0,205,0,0,0,0,220,220,220,220,220,198,198,198,198,0,0,0,0,216,177,216
0,216,216,216,216,216,0,205,198,198,198,198,0,0,0,0,0,0,0,0,0,0,0,0,0,205,0,0,0,0,220,220,220,220,220,198,198,198,198,0,0,0,0,0,216,216
0,216,216,216,216,216,0,205,198,198,198,0,0,0,0,0,0,0,0,0,0,0,0,0,203,203,0,0,0,220,220,220,220,220,220,198,198,198,198,1,0,0,0,0,0,0
0,0,0,0,0,0,0,0,198,211,211,211,203,203,0,198,198,198,198,0,0,0,0,205,220,220,198,198,220,220,220,220,220,220,220,198,198,198,198,0,214,203,0,0,0,0
0,0,0,0,0,0,0,205,198,210,210,210,198,1,1,198,198,198,198,0,0,0,0,7,0,198,198,198,198,198,198,198,198,198,198,198,198,198,198,1,1,0,201,0,0,0
0,0,0,0,0,0,0,0,195,0,0,0,1,198,198,198,198,198,198,0,0,0,0,0,198,198,198,198,198,198,198,198,198,198,198,198,198,198,198,198,198,0,201,0,0,0
0,0,0,0,0,0,0,205,0,0,0,1,1,192,195,198,206,206,1,0,0,0,0,198,198,198,198,198,198,198,198,198,198,198,198,198,206,206,198,198,198,0,201,0,0,0
0,0,0,0,0,0,0,0,1,0,221,1,0,0,0,195,0,0,1,198,198,198,198,198,198,198,198,198,198,198,198,198,198,111,198,198,0,0,198,198,0,0,201,0,0,0
0,0,0,0,0,0,0,0,1,0,0,1,0,0,0,0,0,205,1,0,1,1,0,1,0,0,1,0,1,1,0,0,0,1,1,1,0,0,0,0,0,0,201,0,0,0
0,0,0,0,0,177,0,205,1,0,0,1,0,201,0,0,203,205,0,201,195,195,195,195,0,195,195,7,192,195,0,0,0,195,209,1,0,0,0,0,0,0,201,0,0,0
0,0,0,0,0,0,0,205,0,0,0,0,195,0,0,205,0,1,198,201,0,0,0,0,0,0,0,0,0,0,0,0,0,0,205,198,1,201,0,0,0,0,201,0,0,0
0,0,216,216,0,0,0,0,195,0,195,0,0,0,0,0,0,7,195,0,0,0,0,0,0,0,0,0,0,0,0,0,0,0,0,195,195,195,195,195,195,195,0,216,216,0
0,0,216,177,216,0,0,0,0,0,0,0,0,0,0,0,7,7,7,7,7,7,0,7,7,0,0,7,0,0,0,0,0,0,216,216,0,0,0,0,0,0,216,177,216,0
0,0,0,216,216,0,0,0,0,0,0,0,0,0,0,0,0,0,0,0,0,0,0,0,0,0,0,0,0,177,0,0,0,216,177,216,0,0,0,0,0,0,0,216,216,0
0,0,0,0,0,0,0,0,0,0,0,0,0,0,0,0,0,0,0,0,0,0,0,0,0,0,0,0,0,0,0,0,0,216,216,0,0,0,0,0,0,0,0,0,0,0
0,0,0,0,0,0,0,0,0,0,0,0,0,0,0,0,0,0,0,0,0,0,0,0,0,0,0,0,0,0,0,0,0,0,0,0,0,0,0,0,0,0,0,0,0,0
0,0,0,0,0,0,0,0,0,0,0,0,0,0,0,0,0,0,0,0,0,0,0,0,0,0,0,0,0,0,0,0,0,0,0,0,0,0,0,0,0,0,0,0,0,0
:endlayer
layer: 19
0,0,0,0,0,0,0,0,0,0,0,0,0,0,0,0,0,0,0,0,0,0,0,0,0,0,0,0,0,0,0,0,0,0,0,0,0,0,0,0,0,0,216,216,216,216
0,0,0,0,0,0,0,0,0,216,0,0,0,0,0,0,0,0,0,216,216,216,0,0,0,0,0,0,0,0,0,0,0,216,216,216,0,0,0,0,0,216,216,216,216,216
0,0,0,0,0,0,0,0,216,177,216,0,0,0,0,0,0,0,0,216,177,216,0,0,0,0,0,0,0,0,0,0,216,216,216,216,216,0,0,0,0,216,216,177,216,216
0,0,0,0,0,0,0,0,216,216,0,0,0,0,0,0,0,0,0,216,216,0,0,0,0,0,0,0,0,0,0,0,216,216,177,216,216,0,0,0,0,216,216,216,216,216
0,0,0,0,0,0,0,0,0,0,0,0,0,0,0,203,203,203,203,0,0,0,0,0,0,0,0,0,0,0,0,0,216,216,216,216,216,203,203,203,203,216,216,216,216,0
0,0,0,0,205,1,1,1,1,1,1,1,198,1,1,1,1,1,198,201,0,0,0,0,0,0,0,0,0,0,0,0,216,216,216,198,1,1,1,1,1,198,201,0,216,0
0,0,0,0,205,1,192,195,195,195,195,0,1,0,0,0,0,0,1,201,0,0,0,203,203,0,203,0,203,203,203,203,203,203,197,1,0,0,0,198,198,1,201,216,216,216
0,216,0,0,205,1,0,0,0,0,0,0,1,0,0,0,0,205,1,0,0,0,0,0,1,1,1,1,1,1,1,1,1,1,1,1,0,0,205,198,198,1,201,0,216,0
216,216,216,0,205,1,201,0,0,0,0,0,1,198,198,198,0,205,198,192,0,192,195,195,209,0,198,198,198,0,0,0,0,0,198,1,0,0,198,206,206,1,201,0,0,0
0,216,0,0,205,1,0,0,0,0,0,205,1,198,198,212,0,0,195,0,0,0,0,205,0,0,0,0,0,0,0,0,0,0,0,198,0,0,205,0,0,1,201,0,0,0
0,0,0,0,0,1,201,0,0,0,0,0,1,198,198,212,0,0,0,0,203,0,0,205,0,0,0,0,0,0,0,0,0,0,0,0,0,0,0,0,0,1,201,0,0,0
0,0,0,0,205,1,214,0,0,0,0,0,198,1,1,1,0,1,0,0,0,0,0,205,0,198,198,198,198,0,0,0,0,0,198,198,1,0,1,1,1,198,201,0,0,0
0,0,177,0,0,1,0,0,0,0,0,0,195,205,1,198,0,198,198,0,0,0,0,0,0,0,198,198,0,0,0,0,0,0,0,198,0,0,0,1,195,195,0,0,0,0
0,0,0,0,205,1,0,0,0,0,0,0,0,0,1,212,0,0,0,0,0,0,0,0,0,0,0,0,0,0,0,0,0,0,0,0,0,0,0,1,201,0,0,0,216,0
0,0,0,0,205,1,0,0,0,0,0,0,0,0,1,212,0,0,0,0,0,0,0,0,0,0,0,0,0,0,0,0,0,0,0,0,0,0,0,1,201,0,0,216,216,216
0,0,0,0,0,1,1,1,1,1,1,1,1,1,1,212,0,0,0,201,0,0,0,0,0,0,0,0,0,0,0,0,0,0,0,0,0,0,0,1,201,0,0,0,216,0
0,0,0,0,0,1,0,0,0,204,204,0,0,0,1,198,0,0,198,201,0,0,0,0,0,0,0,0,0,0,0,0,0,0,0,0,0,0,0,1,201,0,0,0,0,0
0,0,0,0,205,1,0,0,0,0,0,0,0,0,1,198,0,0,198,201,0,0,0,0,0,0,198,0,0,0,0,0,0,0,205,0,0,0,0,1,201,0,0,0,0,0
0,0,0,0,205,1,0,0,0,0,0,0,0,0,1,0,0,0,0,0,0,0,0,0,0,0,0,0,0,0,0,0,0,0,205,198,0,0,198,1,201,0,0,0,0,0
0,0,0,0,205,1,1,1,1,0,0,1,1,1,1,201,0,0,0,0,0,0,0,0,0,0,0,0,0,0,0,0,0,0,205,198,0,0,198,1,201,0,216,0,0,0
0,0,0,0,0,195,195,195,1,0,0,1,0,205,1,201,0,0,0,0,0,0,0,0,0,205,0,0,0,0,0,0,0,0,205,198,0,0,198,1,201,216,177,216,0,0
0,0,0,0,0,0,0,0,205,1,1,0,0,0,195,0,0,0,0,0,220,220,220,195,195,0,0,0,0,0,0,0,0,0,205,198,0,0,198,1,0,0,216,216,0,0
0,0,0,0,0,0,0,0,203,0,0,0,0,205,0,0,0,0,0,0,220,223,220,0,0,205,0,0,0,0,0,0,0,0,0,0,0,0,0,1,0,0,0,0,0,0
0,0,216,216,0,0,0,205,198,198,198,198,0,0,0,0,0,0,0,0,220,220,220,0,0,205,0,0,0,0,0,0,0,0,0,0,0,0,0,1,0,0,0,0,216,0
0,0,216,177,216,0,0,205,198,198,198,198,0,0,0,0,0,0,0,0,0,0,0,0,0,205,0,0,0,0,0,201,0,0,0,0,0,0,0,1,0,0,0,216,216,216
0,0,216,216,0,0,0,205,198,211,211,211,0,0,0,0,0,0,0,0,0,0,0,0,0,205,0,0,0,0,0,0,0,0,0,0,0,0,0,1,0,0,0,0,216,0
0,0,0,0,0,0,0,205,198,210,210,210,0,0,1,0,0,0,0,0,0,0,0,0,0,0,0,0,0,0,0,0,0,0,0,0,0,0,0,1,0,0,0,0,0,0
0,0,0,0,0,0,0,0,198,0,0,0,203,203,1,198,0,198,0,0,0,0,0,0,0,0,0,0,0,0,0,0,0,0,0,198,0,0,0,1,214,203,0,0,0,0
0,0,0,0,0,0,0,205,198,0,0,205,198,1,1,1,0,1,198,0,0,0,0,0,0,198,198,198,198,0,0,0,0,0,198,198,1,0,1,1,1,0,201,0,0,0
0,0,0,0,0,0,0,0,210,0,0,0,1,0,0,0,0,0,0,0,0,0,0,0,0,0,0,0,0,0,0,0,0,0,0,0,0,0,0,0,0,1,201,0,0,0
0,0,0,0,0,0,0,205,1,0,0,1,1,201,0,0,0,0,0,0,0,0,0,0,0,0,0,0,0,0,0,0,0,0,0,0,0,0,0,0,0,1,201,0,0,0
0,0,216,0,0,0,0,0,1,0,221,1,1,0,0,0,0,0,198,0,0,0,0,0,0,198,198,198,198,0,0,0,0,0,198,198,0,0,198,207,207,1,201,0,0,0
0,216,216,216,0,0,0,0,1,0,0,1,0,0,0,0,0,205,1,1,1,1,1,1,1,1,1,1,1,1,1,1,1,1,1,1,0,0,198,0,0,0,201,0,0,0
0,0,216,0,0,177,0,205,1,0,0,1,0,201,0,0,203,205,1,201,195,195,195,195,0,195,195,195,195,195,0,0,0,195,209,1,0,0,198,0,0,0,201,0,0,0
0,0,0,0,0,152,0,205,0,0,0,0,195,0,0,205,1,1,198,201,0,0,0,0,0,0,0,0,0,0,0,0,0,0,205,198,1,1,1,0,0,0,201,0,0,0
0,0,0,216,0,0,152,0,195,0,195,0,0,0,0,0,0,195,195,0,0,0,0,0,0,0,0,0,0,0,152,0,0,0,0,195,195,195,195,195,195,195,0,216,0,0
0,0,216,216,216,0,0,0,0,0,0,0,0,0,0,0,0,0,0,0,0,7,0,7,0,0,216,0,0,152,0,0,0,0,216,0,0,0,0,0,0,0,216,216,216,0
0,0,0,216,0,0,0,0,0,0,0,0,0,0,0,0,0,0,0,0,0,0,0,0,0,216,216,216,0,177,0,0,0,216,216,216,0,0,0,0,0,0,0,216,0,0
0,0,0,0,0,0,0,0,0,0,0,0,0,0,0,0,0,0,0,0,0,0,0,0,0,0,216,0,0,0,222,222,0,0,216,0,0,0,0,0,0,0,0,0,0,0
0,0,0,0,0,0,0,0,0,0,0,0,0,0,0,0,0,0,0,0,0,0,0,0,0,0,0,0,0,0,0,0,0,0,0,0,0,0,0,0,0,0,0,0,0,0
0,0,0,0,0,0,0,0,0,0,0,0,0,0,0,0,0,0,0,0,0,0,0,0,0,0,0,0,0,0,0,0,0,0,0,0,0,0,0,0,0,0,0,0,0,0
:endlayer
layer: 20
0,0,0,0,0,0,0,0,0,0,0,0,0,0,0,0,0,0,0,0,0,0,0,0,0,0,0,0,0,0,0,0,0,0,0,0,0,0,0,0,0,0,0,0,0,0
0,0,0,0,0,0,0,0,0,216,0,0,0,0,0,0,0,0,0,0,216,0,0,0,0,0,0,0,0,0,0,0,0,0,0,0,0,0,0,0,0,0,216,216,216,0
0,0,0,0,0,0,0,0,216,216,216,0,0,0,0,0,0,0,0,216,216,216,0,0,0,0,0,0,0,0,0,0,0,216,216,0,0,0,0,0,0,0,216,177,216,0
0,0,0,0,0,0,0,0,0,216,0,0,0,0,0,0,0,0,0,0,216,0,0,0,0,0,0,0,0,0,0,0,0,216,177,216,0,0,0,0,0,0,216,216,216,0
0,0,0,0,0,0,0,0,0,0,0,0,0,0,0,203,203,203,203,0,0,0,0,0,0,0,0,0,0,0,0,0,0,216,216,216,203,203,203,203,203,203,0,0,0,0
0,0,0,0,205,1,0,1,1,1,1,1,198,1,1,1,1,1,198,201,0,0,0,0,0,0,0,0,0,0,0,0,0,0,205,0,0,0,0,0,1,198,201,0,0,0
216,216,216,0,205,1,192,195,195,195,195,220,198,198,198,0,0,0,1,201,0,0,0,203,203,0,203,0,203,203,203,203,203,203,197,0,0,0,0,0,0,1,201,0,0,0
216,216,216,216,205,195,0,0,0,0,0,220,198,198,198,0,0,205,1,0,0,0,0,0,1,201,1,1,1,1,1,1,1,1,1,201,0,0,205,0,0,1,201,0,0,0
216,216,216,216,205,0,0,0,0,0,0,220,198,198,198,198,0,205,198,192,0,192,195,195,209,0,198,198,198,0,0,0,0,0,198,0,0,0,0,0,0,1,201,0,0,0
216,216,216,216,205,0,0,0,0,0,0,205,198,198,212,201,0,0,195,0,0,0,0,205,0,0,0,0,0,0,0,0,0,0,0,0,0,0,205,0,0,1,201,0,0,0
216,216,216,0,0,0,0,0,0,0,220,220,198,198,212,203,0,0,0,0,203,0,0,205,0,0,0,0,0,0,0,0,0,0,0,0,0,0,0,0,0,1,201,0,0,0
216,0,0,0,0,0,203,0,0,0,0,220,198,198,1,1,0,1,198,0,0,0,0,205,0,198,198,198,198,0,0,0,0,0,198,198,1,0,1,1,1,198,201,0,0,0
216,0,177,0,0,1,220,220,220,0,220,220,195,220,1,198,0,198,198,0,0,0,0,0,0,0,198,198,0,0,0,0,0,0,0,198,0,0,0,1,195,195,0,0,0,0
216,0,152,0,205,1,220,220,220,220,0,0,220,220,212,0,0,0,0,0,0,0,0,0,0,0,0,0,0,0,0,0,0,0,0,0,0,0,0,1,201,0,0,0,0,0
0,216,152,216,205,1,220,220,220,220,220,220,220,220,212,0,0,0,0,0,0,0,0,0,0,0,0,0,0,0,0,0,0,0,0,0,0,0,0,1,201,0,0,0,0,0
0,216,216,216,0,1,220,220,220,220,220,220,220,220,212,0,0,0,0,201,0,0,0,0,0,0,0,0,0,0,0,0,0,0,0,0,0,0,0,1,201,0,0,0,0,0
0,0,216,0,0,1,220,220,220,220,220,220,220,220,1,198,0,0,198,201,0,0,0,0,0,0,0,0,0,0,0,0,0,0,0,0,0,0,0,1,201,0,0,0,0,0
0,0,0,0,205,1,220,220,220,220,220,220,220,220,1,198,0,0,198,201,0,0,0,0,0,0,198,0,0,0,0,0,0,0,205,0,0,0,0,1,201,0,0,0,0,0
0,0,0,0,205,1,1,220,220,220,220,220,220,1,1,0,0,0,0,0,0,0,0,0,0,0,0,0,0,0,0,0,0,0,205,198,0,0,198,1,201,0,0,0,0,0
0,0,0,0,205,1,1,1,198,198,198,198,1,1,1,201,0,0,0,0,0,0,0,0,0,0,0,0,0,0,0,0,0,0,205,198,0,0,198,1,201,0,216,0,0,0
0,0,0,0,0,195,195,195,198,198,198,198,0,205,1,201,0,0,0,0,0,0,0,0,0,205,0,0,0,0,0,0,0,0,205,198,0,0,198,1,201,216,216,216,0,0
0,0,0,0,0,0,0,0,220,220,220,220,0,0,195,0,0,0,0,0,220,0,220,195,195,0,0,0,0,0,0,0,0,0,205,198,0,0,198,1,0,0,216,0,0,0
0,0,0,0,0,0,0,0,220,220,220,220,0,205,0,0,0,0,0,0,0,0,0,0,0,205,0,0,0,0,0,0,0,0,0,0,0,0,0,1,0,0,0,0,0,0
0,0,0,216,0,0,0,205,198,211,211,211,0,0,0,0,0,0,0,0,220,0,220,0,0,205,0,0,0,0,0,0,0,0,0,0,0,0,0,1,0,0,0,0,0,0
0,0,216,216,216,0,0,205,198,210,210,210,0,0,0,0,0,0,0,0,0,0,0,0,0,205,0,0,0,0,0,201,0,0,0,0,0,0,0,1,0,0,0,0,0,0
0,0,0,216,0,0,0,205,198,0,0,0,0,0,0,0,0,0,0,0,0,0,0,0,0,205,0,0,0,0,0,0,0,0,0,0,0,0,0,1,0,0,0,0,0,0
0,0,0,0,0,0,0,205,198,0,0,0,0,0,0,0,0,0,0,0,0,0,0,0,0,0,0,0,0,0,0,0,0,0,0,0,0,0,0,1,0,0,0,0,0,0
0,0,0,0,0,0,0,0,210,0,0,0,203,203,1,0,0,0,0,0,0,0,0,0,0,0,0,0,0,0,0,0,0,0,0,198,0,0,0,1,214,203,0,0,0,0
0,0,0,0,0,0,0,0,210,0,0,205,198,1,1,1,0,1,198,0,0,0,0,0,0,0,198,198,198,0,0,0,0,0,198,198,1,0,1,1,1,198,201,0,0,0
0,0,0,0,0,0,0,0,0,0,0,0,1,0,0,0,0,0,0,0,0,0,0,0,0,0,0,0,0,0,0,0,0,0,0,0,0,0,0,0,0,1,201,0,0,0
0,216,216,216,0,0,0,205,1,0,0,1,1,201,0,0,0,0,0,0,0,0,0,0,0,0,0,0,0,0,0,0,0,0,0,0,0,0,0,0,0,1,201,0,0,0
216,216,216,216,216,0,0,0,1,0,221,1,1,0,0,0,0,0,0,0,0,0,0,0,0,198,198,198,198,0,0,0,0,0,198,198,0,0,198,0,0,1,201,0,0,0
216,216,216,222,216,0,0,0,1,0,0,1,1,0,0,0,0,0,0,1,0,1,1,1,1,1,1,1,1,1,1,1,1,1,1,1,198,198,212,0,0,0,201,0,0,0
216,216,216,216,222,177,0,205,1,0,0,1,1,201,0,0,0,0,0,201,195,195,195,195,0,195,195,195,195,195,216,0,0,195,209,1,198,198,212,0,0,0,201,0,0,0
0,216,216,216,0,0,222,205,1,0,0,0,195,0,0,0,0,0,198,201,0,0,0,0,0,0,0,0,0,216,152,216,0,0,205,198,1,1,1,1,0,0,201,0,0,0
0,0,0,0,0,0,216,0,195,0,195,0,0,0,0,0,0,195,195,0,0,0,0,0,0,216,216,216,0,0,216,0,0,0,0,195,195,195,195,195,195,195,0,0,0,0
0,0,0,0,0,216,152,216,0,0,0,0,0,0,0,0,0,0,0,0,0,7,0,0,216,216,216,216,216,0,0,0,0,0,0,0,0,0,0,0,0,0,0,0,0,0
0,0,0,0,0,0,216,0,0,0,0,0,0,0,0,0,0,0,0,0,0,0,0,0,216,216,216,216,216,177,0,0,0,0,0,0,0,0,0,0,0,0,0,0,0,0
0,0,0,0,0,0,0,0,0,0,0,0,0,0,0,0,0,0,0,0,0,0,0,0,216,216,216,222,222,0,0,0,216,0,0,0,0,0,0,0,0,0,0,0,0,0
0,0,0,0,0,0,0,0,0,0,0,0,0,0,0,0,0,0,0,0,0,0,0,0,0,216,216,216,0,0,0,216,222,216,0,0,0,0,0,0,0,0,0,0,0,0
0,0,0,0,0,0,0,0,0,0,0,0,0,0,0,0,0,0,0,0,0,0,0,0,0,0,0,0,0,0,0,0,216,0,0,0,0,0,0,0,0,0,0,0,0,0
:endlayer
layer: 21
0,0,0,0,0,0,0,0,0,0,0,0,0,0,0,0,0,0,0,0,0,0,0,0,0,0,0,0,0,0,0,0,0,0,0,0,0,0,0,0,0,0,0,0,0,0
0,0,0,0,0,0,0,0,0,0,0,0,0,0,0,0,0,0,0,0,0,0,0,0,0,0,0,0,0,0,0,0,0,0,0,0,0,0,0,0,0,0,0,216,0,0
0,0,0,0,0,0,0,0,0,0,0,0,0,0,0,0,0,0,0,0,0,0,0,0,0,0,0,0,0,0,0,0,0,0,216,0,0,0,0,0,0,0,216,216,216,0
0,0,0,0,0,0,0,0,0,0,0,0,0,0,0,0,0,0,0,0,0,0,0,0,0,0,0,0,0,0,0,0,0,216,216,216,0,0,0,0,0,0,0,216,0,0
0,0,0,0,0,0,0,0,0,0,0,0,0,0,0,203,203,203,203,0,0,0,0,0,0,0,0,0,0,0,0,0,0,0,216,203,203,203,203,203,203,203,0,0,0,0
0,0,0,0,205,1,0,0,0,0,0,1,198,1,1,1,1,1,198,201,0,0,0,0,0,0,0,0,0,0,0,0,0,0,205,0,0,0,0,1,1,198,201,0,0,0
216,216,216,0,0,195,192,195,195,195,195,195,219,198,198,198,0,0,1,201,0,0,0,203,203,0,203,0,203,203,203,203,203,203,197,0,0,0,0,0,0,1,201,0,0,0
216,216,216,216,205,195,0,0,0,0,0,0,219,198,198,198,0,205,1,0,0,0,0,0,1,1,1,1,1,1,1,0,1,1,1,201,0,0,205,0,0,1,201,0,0,0
216,216,216,216,205,0,0,0,0,0,0,209,198,198,198,198,0,205,198,192,0,192,195,195,209,198,198,198,198,0,0,0,0,0,198,0,0,0,0,0,0,1,201,0,0,0
216,216,216,216,205,0,0,0,0,0,0,205,0,0,0,201,0,0,195,0,0,0,0,205,0,0,0,0,0,0,0,0,0,0,0,198,198,198,205,0,0,1,201,0,0,0
216,216,216,0,0,0,0,0,0,0,0,205,203,0,0,203,0,0,0,0,203,0,0,205,0,0,0,0,0,0,0,0,0,0,0,198,198,198,0,0,0,1,201,0,0,0
216,0,0,0,0,0,0,0,0,0,0,205,198,1,1,1,1,1,198,0,0,0,0,205,0,198,198,198,198,0,0,0,0,0,198,198,1,1,1,1,1,198,201,0,0,0
216,216,177,216,0,1,0,0,0,0,0,0,195,0,1,198,198,198,198,0,0,0,0,0,0,0,198,198,0,0,0,0,0,0,0,198,0,0,0,1,195,195,0,0,0,0
216,216,216,216,205,1,0,0,0,0,0,0,0,0,0,0,0,0,0,0,0,0,0,0,0,0,0,0,0,0,0,0,0,0,0,0,0,0,0,1,201,0,0,0,0,0
216,216,216,216,205,1,0,0,0,0,0,0,0,0,0,0,0,0,0,0,0,0,0,0,0,0,0,0,0,0,0,0,0,0,0,0,0,0,0,1,201,0,0,0,0,0
216,216,216,216,216,1,0,0,0,0,0,0,0,0,0,0,0,0,0,214,0,0,0,0,0,0,0,0,0,0,0,0,0,0,0,0,0,0,0,0,201,0,0,0,0,0
216,216,216,216,216,1,0,0,0,101,101,0,0,0,1,198,0,0,198,201,0,0,0,0,0,0,0,0,0,0,0,0,0,0,0,0,0,0,0,1,201,0,0,0,0,0
0,216,216,216,205,1,1,1,1,0,0,1,1,1,1,198,0,0,198,201,0,0,0,0,0,0,198,0,0,0,0,0,0,0,205,0,0,0,0,1,201,0,0,0,0,0
0,0,0,0,205,1,224,228,227,198,198,226,225,224,1,0,0,0,0,0,0,0,0,0,0,0,0,0,0,0,0,0,0,0,205,198,0,0,198,1,201,0,0,0,0,0
0,0,0,0,205,1,1,1,1,0,0,1,1,1,1,201,0,0,0,0,0,0,0,0,0,0,0,0,0,0,0,0,0,0,205,198,0,0,198,1,201,0,0,0,0,0
0,0,0,0,0,195,195,195,195,41,41,195,0,205,1,201,0,0,0,0,0,0,0,0,0,205,0,0,0,0,0,0,0,0,205,198,0,0,198,1,201,0,0,0,0,0
0,0,0,0,0,0,0,0,0,0,0,0,0,0,195,0,0,0,0,0,220,0,220,195,195,0,0,0,0,0,0,0,0,0,205,198,0,0,198,1,0,0,0,0,0,0
0,0,0,0,0,0,0,0,0,0,0,0,0,205,0,0,0,0,0,0,0,0,0,0,0,205,0,0,0,0,0,0,0,0,0,0,0,0,0,1,0,0,0,0,0,0
0,0,0,0,0,0,0,205,198,0,0,0,0,0,0,0,0,0,0,0,220,0,220,0,0,205,0,0,0,0,0,0,0,0,0,0,0,0,0,1,0,0,0,0,0,0
0,0,0,0,0,0,0,205,198,0,0,0,0,0,0,0,0,0,0,0,0,0,0,0,0,205,0,0,0,0,0,201,0,0,0,0,0,0,0,0,0,0,0,0,0,0
0,0,0,0,0,0,0,0,210,0,0,0,0,0,0,0,0,0,0,0,0,0,0,0,0,205,0,0,0,0,0,0,0,0,0,0,0,0,0,1,0,0,0,0,0,0
0,0,0,0,0,0,0,0,210,0,0,0,0,0,1,0,0,0,0,0,0,0,0,0,0,0,0,0,0,0,0,0,0,0,0,0,0,0,0,1,0,0,0,0,0,0
0,0,0,0,0,0,0,0,0,0,0,0,203,203,1,198,198,198,0,0,0,0,0,0,0,0,0,198,0,0,0,0,0,0,0,198,0,0,0,1,214,203,0,0,0,0
0,0,0,0,0,0,0,0,0,0,0,205,198,1,1,1,1,1,198,0,0,0,0,0,0,198,198,198,198,0,0,0,0,0,198,198,1,1,1,1,1,198,201,0,0,0
0,0,0,0,0,0,0,0,0,0,0,0,1,0,0,198,198,198,0,0,0,0,0,0,0,0,0,0,0,0,0,0,0,0,0,198,198,198,198,0,0,1,201,0,0,0
0,216,216,216,0,0,0,205,1,1,1,1,1,201,0,198,198,198,0,0,0,0,0,0,0,0,0,0,0,0,0,0,0,0,0,198,198,198,198,0,0,1,201,0,0,0
216,216,216,216,216,0,0,0,1,0,221,1,1,0,0,0,0,0,0,0,0,0,0,0,0,198,198,198,198,0,0,0,0,0,198,1,206,206,198,0,0,1,201,0,0,0
216,216,222,216,216,0,0,0,1,0,0,1,1,0,0,0,0,0,0,1,1,1,0,1,1,1,1,1,1,1,1,216,1,1,1,1,0,0,0,0,0,0,201,0,0,0
216,216,216,216,216,177,0,205,1,0,0,1,1,201,0,0,0,0,0,201,195,195,195,195,0,195,195,195,216,195,195,216,216,195,209,1,0,0,0,0,0,0,201,0,0,0
0,216,216,216,0,216,216,205,1,0,0,0,198,0,0,0,0,0,0,201,0,0,0,0,0,0,0,0,216,216,216,216,216,0,205,198,1,1,1,1,0,0,201,0,0,0
0,0,0,0,216,216,216,222,195,0,195,0,0,0,0,0,0,195,195,0,0,0,0,0,0,216,216,216,216,216,216,216,216,0,0,195,195,195,195,195,195,195,0,0,0,0
0,0,0,0,216,216,216,216,216,0,0,0,0,0,0,0,0,0,0,0,0,0,0,0,216,216,216,216,216,216,216,216,0,0,0,0,0,0,0,0,0,0,0,0,0,0
