# Ancient Warfare Structure Template File
# Auto-generated structure template file. created on: 8/19/2019 at: 10:23:14
# Lines beginning with # denote comments

header:
version=2.9
name=OrcRuinCircleMediumGeneric
mods=
size=29,19,29
offset=14,8,28
:endheader

#### VALIDATION ####
validation:
type=ground
survival=false
worldGenEnabled=true
unique=false
preserveBlocks=false
selectionWeight=30
clusterValue=30
minDuplicateDistance=1000
dimensionWhiteList=true
dimensionList=0
biomeWhiteList=true
biomeList=biomesoplenty:shrubland,biomesoplenty:woodland,biomesoplenty:dead_swamp,biomesoplenty:dead_forest,traverse:woodlands,minecraft:forest,minecraft:extreme_hills,minecraft:redwood_taiga,traverse:badlands,biomesoplenty:moor,traverse:rocky_plateau
leveling=4
fill=4
border=4
blockSwap=true
:endvalidation

#### LAYERS ####
layer: 0
1,1,1,1,1,1,1,1,1,1,1,1,1,1,1,1,1,1,1,1,1,1,1,1,1,1,1,1,1
1,2,2,2,2,2,2,2,2,2,2,2,2,2,2,2,2,2,2,2,2,2,2,2,2,2,2,2,1
1,2,2,2,2,2,2,2,2,2,2,2,2,2,2,2,2,2,2,2,2,2,2,2,2,2,2,2,1
1,2,2,2,2,2,2,2,2,2,2,2,2,2,2,2,2,2,2,2,2,2,2,2,2,2,2,2,1
1,2,2,2,2,2,2,2,2,2,2,2,2,2,2,3,2,2,2,2,2,2,2,2,2,2,2,2,1
1,2,2,2,2,2,2,2,2,2,2,2,2,2,2,2,2,2,2,2,2,2,2,2,2,2,2,2,1
1,2,2,2,2,2,2,2,2,2,2,2,2,2,2,2,2,2,2,2,2,2,2,2,2,2,2,2,1
1,2,2,2,2,2,2,2,2,2,2,2,2,2,2,2,2,2,2,2,2,2,2,2,2,2,2,2,1
1,2,2,2,2,2,2,2,2,2,2,2,2,2,2,2,2,2,2,2,2,2,2,2,2,2,2,2,1
1,2,2,2,2,2,2,2,2,2,2,2,2,2,2,2,2,2,2,2,2,2,2,2,2,2,2,2,1
1,2,2,2,2,2,2,2,2,2,2,2,2,2,2,2,2,2,2,2,2,2,2,2,2,2,2,2,1
1,2,2,2,2,2,2,2,2,2,2,2,2,2,2,2,2,2,2,2,2,2,2,2,2,2,2,2,1
1,2,2,2,2,2,2,2,2,2,2,2,2,2,2,2,2,2,2,2,2,2,2,2,2,2,2,2,1
1,2,2,2,2,2,2,2,2,2,2,2,2,2,2,2,2,2,2,2,2,2,2,2,2,2,2,2,1
1,2,2,2,2,2,2,2,2,2,2,2,2,2,2,2,2,2,2,2,2,2,2,2,2,2,2,2,1
1,2,2,2,2,2,2,2,2,2,2,2,2,2,2,2,2,2,2,2,2,2,2,2,2,2,2,2,1
1,2,2,2,2,2,2,2,2,2,2,2,2,2,2,2,2,2,2,2,2,2,2,2,2,2,2,2,1
1,2,2,2,2,2,2,2,2,2,2,2,2,2,2,2,2,2,2,2,2,2,2,2,2,2,2,2,1
1,2,2,2,2,2,2,2,2,2,2,2,2,2,2,2,2,2,2,2,2,2,2,2,2,2,2,2,1
1,2,2,2,2,2,3,3,3,2,2,2,2,2,2,2,2,2,2,2,2,2,2,2,2,2,2,2,1
1,2,2,2,2,2,3,4,3,2,2,2,2,2,2,2,2,2,2,2,2,2,2,2,2,2,2,2,1
1,2,2,2,2,2,3,3,3,2,2,2,2,2,2,2,2,2,2,2,2,2,2,2,2,2,2,2,1
1,2,2,2,2,2,2,2,2,2,2,2,2,2,2,2,2,2,2,2,2,2,2,2,2,2,2,2,1
1,2,2,2,2,2,2,2,2,2,2,2,2,2,2,2,2,2,2,2,2,2,2,2,2,2,2,2,1
1,2,2,2,2,2,2,2,2,2,2,2,2,2,2,2,2,2,2,2,2,2,2,2,2,2,2,2,1
1,2,2,2,2,2,2,2,2,2,2,2,2,2,2,2,2,2,2,2,2,2,2,2,2,2,2,2,1
1,2,2,2,2,2,2,2,2,2,2,2,2,2,2,2,2,2,2,2,2,2,2,2,2,2,2,2,1
1,2,2,2,2,2,2,2,2,2,2,2,2,2,2,2,2,2,2,2,2,2,2,2,2,2,2,2,1
1,1,1,1,1,1,1,1,1,1,1,1,1,1,1,1,1,1,1,1,1,1,1,1,1,1,1,1,1
:endlayer
layer: 1
1,1,1,1,1,1,1,1,1,1,1,1,1,1,1,1,1,1,1,1,1,1,1,1,1,1,1,1,1
1,2,2,2,2,2,2,2,2,2,2,2,2,2,2,2,2,2,2,2,2,2,2,2,2,2,2,2,1
1,2,2,2,2,2,2,2,2,2,2,2,2,2,2,2,2,2,2,2,2,2,2,2,2,2,2,2,1
1,2,2,23,23,23,23,23,3,16,14,5,0,0,0,0,0,0,0,0,0,0,0,0,0,0,0,2,1
1,2,2,23,0,0,26,23,3,17,0,5,0,0,0,0,3,0,0,9,3,3,3,3,3,3,0,2,1
1,2,0,23,0,28,0,23,3,0,0,3,0,0,0,0,3,3,3,3,3,7,0,0,0,3,0,2,1
1,2,2,23,0,0,0,23,3,18,0,5,0,0,0,0,0,0,0,0,0,0,0,0,0,3,0,2,1
1,2,2,3,3,12,3,3,3,18,0,5,3,3,0,3,3,3,3,3,3,3,3,3,3,3,0,2,1
1,2,32,0,0,0,0,0,19,3,0,5,11,0,0,10,3,0,0,0,0,0,0,0,0,3,0,2,1
1,2,2,0,0,0,3,0,0,12,0,3,0,0,0,0,3,0,3,3,3,3,3,0,3,3,0,0,0
1,2,2,3,29,0,3,3,3,3,3,5,0,0,0,0,3,0,3,0,0,0,3,0,0,0,0,5,1
1,2,33,0,0,0,0,0,0,0,0,5,0,0,0,0,3,0,3,0,3,0,3,3,3,3,3,2,1
1,2,2,0,0,20,0,0,0,0,0,5,0,0,0,0,3,0,3,0,3,0,0,0,0,0,0,5,1
1,2,2,30,21,0,0,0,0,0,0,5,0,0,0,3,3,0,3,0,3,3,3,3,3,0,3,2,1
1,2,2,5,6,0,0,0,0,0,0,12,0,0,0,3,0,0,0,0,3,0,0,0,0,0,0,5,1
1,2,2,31,21,0,0,0,0,0,0,3,3,3,3,3,3,3,3,0,0,0,3,3,3,3,3,2,1
0,0,0,0,0,20,0,0,0,0,0,3,0,0,0,0,0,0,3,0,3,0,0,0,0,0,0,5,1
1,2,34,0,0,0,0,24,0,0,15,3,0,3,3,3,3,0,3,0,3,3,3,3,3,3,0,5,1
1,2,2,3,0,0,0,0,0,0,0,3,0,3,0,0,0,0,0,0,3,0,0,0,0,0,0,5,1
1,2,2,0,0,0,20,21,20,0,0,3,0,3,0,3,0,3,3,3,3,3,3,5,0,3,5,2,1
1,2,35,0,0,0,21,25,21,0,0,3,0,3,0,3,0,3,3,3,3,3,6,0,0,0,0,5,1
1,2,2,0,0,0,20,21,20,0,0,3,0,3,0,3,0,3,3,3,3,3,3,3,3,0,3,2,1
1,2,2,0,0,0,27,0,22,0,0,3,0,0,0,3,0,0,3,0,0,0,3,0,0,0,0,3,1
1,2,36,0,0,0,0,0,0,0,0,3,3,3,0,3,3,0,3,0,3,8,3,0,3,3,0,3,1
1,2,2,18,0,18,0,18,0,18,0,12,12,3,0,0,3,0,3,0,3,3,3,3,3,0,0,3,1
1,2,2,18,0,18,0,18,0,18,0,5,13,3,0,0,3,0,0,0,0,0,0,0,0,0,0,3,1
1,2,2,2,2,2,2,2,2,2,2,2,2,2,5,5,2,5,5,5,5,5,3,3,5,3,5,2,1
1,2,2,2,2,2,2,2,2,2,2,2,2,2,2,2,2,2,2,2,2,2,2,2,2,2,2,2,1
1,1,1,1,1,1,1,1,1,1,1,1,1,1,1,1,1,1,1,1,1,1,1,1,1,1,1,1,1
:endlayer
layer: 2
1,1,1,1,1,1,1,1,1,1,1,1,1,1,1,1,1,1,1,1,1,1,1,1,1,1,1,1,1
1,2,2,2,2,2,2,2,2,2,2,2,2,2,2,2,2,2,2,2,2,2,2,2,2,2,2,2,1
1,2,2,2,2,2,2,2,2,2,2,2,2,2,2,2,2,2,2,2,2,2,2,2,2,2,2,2,1
1,2,2,23,23,23,23,23,3,37,0,3,0,0,0,0,0,0,0,0,0,0,0,0,0,0,0,2,1
1,2,2,23,0,0,0,23,3,0,0,3,0,0,0,0,5,0,0,0,3,5,5,3,5,5,0,2,1
1,2,0,23,0,0,0,23,3,0,0,3,0,0,0,0,5,5,5,3,5,0,0,0,0,3,0,2,1
1,2,2,23,38,0,38,23,3,0,0,3,0,0,0,0,0,0,0,0,0,0,0,0,0,5,0,2,1
1,2,2,3,3,0,3,3,3,0,0,5,3,3,0,3,5,3,5,3,5,5,5,5,3,5,0,2,1
1,2,0,0,0,0,0,0,0,3,0,3,0,0,0,0,5,0,0,0,0,0,0,0,0,3,0,2,1
1,2,2,0,0,0,3,0,0,0,0,5,0,0,0,0,3,0,5,3,3,5,3,0,3,5,0,0,0
1,2,2,3,0,0,3,3,3,3,3,3,0,0,0,0,5,0,3,0,0,0,3,0,0,0,0,5,1
1,2,0,0,0,0,0,0,0,0,0,5,0,0,0,0,3,0,5,0,5,0,5,3,5,5,3,2,1
1,2,2,0,0,39,0,0,0,0,0,3,0,0,0,0,5,0,3,0,3,0,0,0,0,0,0,5,1
1,2,2,0,0,0,0,0,0,0,0,3,0,0,0,3,3,0,5,0,5,5,3,5,3,0,3,2,1
1,2,2,41,0,0,0,0,0,0,0,0,0,0,0,3,0,0,0,0,3,0,0,0,0,0,0,5,1
1,2,2,0,0,0,0,0,0,0,0,3,5,3,5,3,5,3,3,0,0,0,5,3,5,3,3,2,1
0,0,0,0,0,40,0,0,0,0,0,3,0,0,0,0,0,0,5,0,3,0,0,0,0,0,0,5,1
1,2,0,0,0,0,0,0,0,0,0,5,0,5,3,5,3,0,3,0,3,5,5,3,5,3,0,5,1
1,2,2,3,0,0,0,0,0,0,0,3,0,3,0,0,0,0,0,0,3,0,0,0,0,0,0,5,1
1,2,2,0,0,0,20,0,20,0,0,3,0,5,0,3,0,3,3,3,3,3,3,3,0,3,5,2,1
1,2,0,0,0,0,0,14,0,0,0,5,0,3,0,5,0,3,3,3,3,6,0,0,0,0,0,5,1
1,2,2,0,0,0,20,0,20,0,0,3,0,3,0,3,0,3,3,3,3,3,3,3,5,0,3,2,1
1,2,2,0,0,0,0,0,0,0,0,5,0,0,0,5,0,0,5,0,0,0,3,0,0,0,0,3,1
1,2,0,0,0,0,0,0,0,0,0,5,3,5,0,5,3,0,3,0,5,0,3,0,3,3,0,3,1
1,2,2,0,0,0,0,0,0,0,0,0,0,3,0,0,5,0,5,0,3,5,5,5,3,0,0,3,1
1,2,2,0,0,0,0,0,0,0,0,5,0,3,0,0,3,0,0,0,0,0,0,0,0,0,0,3,1
1,2,2,2,2,2,2,2,2,2,2,2,2,2,5,5,2,5,5,3,3,5,3,5,3,5,3,2,1
1,2,2,2,2,2,2,2,2,2,2,2,2,2,2,2,2,2,2,2,2,2,2,2,2,2,2,2,1
1,1,1,1,1,1,1,1,1,1,1,1,1,1,1,1,1,1,1,1,1,1,1,1,1,1,1,1,1
:endlayer
layer: 3
1,1,1,1,1,1,1,1,1,1,1,1,1,1,1,1,1,1,1,1,1,1,1,1,1,1,1,1,1
1,2,2,2,2,2,2,2,2,2,2,2,2,2,2,2,2,2,2,2,2,2,2,2,2,2,2,2,1
1,2,2,2,2,2,2,2,2,2,2,2,2,2,2,2,2,2,2,2,2,2,2,2,2,2,2,2,1
1,2,2,3,3,3,3,3,3,0,45,3,0,0,0,0,0,0,0,0,0,0,0,0,0,0,0,2,1
1,2,2,3,48,48,48,3,3,0,0,5,0,0,0,0,3,0,0,0,3,3,3,3,3,3,0,2,1
1,2,2,3,48,0,48,3,3,0,0,3,0,0,0,0,3,3,3,3,3,0,0,0,0,3,0,2,1
1,2,2,3,48,48,48,3,3,0,0,5,0,0,0,0,0,0,0,0,0,0,0,0,0,3,0,2,1
1,2,2,3,3,3,3,3,3,0,0,5,3,3,0,3,3,3,3,3,3,3,3,3,3,3,0,2,1
1,2,2,0,0,0,3,0,0,3,0,3,0,0,0,0,3,0,0,0,0,0,0,0,0,3,0,2,1
1,2,2,0,0,0,3,0,0,0,0,3,0,0,0,0,3,0,3,3,3,3,3,0,3,3,0,3,1
1,2,2,3,49,49,3,49,3,3,46,5,0,0,0,0,3,0,3,0,0,0,3,0,0,0,0,5,1
1,2,2,0,0,0,0,0,0,0,47,5,0,0,0,0,3,0,3,0,3,0,3,3,3,3,3,2,1
1,2,2,0,0,0,0,0,0,0,47,5,0,0,0,0,3,0,3,0,3,0,0,0,0,0,0,5,1
1,2,2,0,0,0,0,0,0,0,47,3,0,0,0,3,3,0,3,0,3,3,3,3,3,0,3,2,1
1,2,2,50,0,0,0,0,0,0,47,44,0,0,0,3,0,0,0,0,3,0,0,0,0,0,0,5,1
1,2,2,0,0,0,0,0,0,0,47,3,3,3,3,3,3,3,3,0,0,0,3,3,3,3,3,2,1
1,2,2,0,0,0,0,0,0,0,47,3,0,0,0,0,0,0,3,0,3,0,0,0,0,0,0,5,1
1,2,2,0,0,0,0,0,0,0,47,3,0,3,3,3,3,0,3,0,3,3,3,3,3,3,0,5,1
1,2,2,3,0,0,0,0,0,0,47,3,0,3,0,0,0,0,0,0,3,0,0,0,0,0,0,5,1
1,2,2,44,0,0,20,20,20,0,47,3,0,3,0,3,0,3,3,3,3,3,3,5,5,5,3,2,1
1,2,2,44,0,0,20,0,20,0,47,3,0,3,0,3,43,3,3,3,6,0,0,0,0,0,0,5,1
1,2,2,44,0,0,20,20,20,0,47,3,0,3,0,3,0,3,3,3,3,3,3,5,5,5,5,2,1
1,2,2,44,0,0,0,0,0,0,47,3,0,0,0,3,0,0,3,0,42,0,3,0,0,0,0,3,1
1,2,2,44,0,0,0,0,0,0,47,3,3,3,0,3,3,0,3,0,3,0,3,0,3,3,0,3,1
1,2,2,44,0,0,0,0,0,0,48,0,0,3,0,0,3,0,3,0,3,3,3,3,3,0,0,3,1
1,2,2,46,46,46,46,46,46,46,46,5,0,3,0,0,3,0,0,0,0,0,0,0,0,0,0,3,1
1,2,2,2,2,2,2,2,2,2,2,2,2,2,5,5,3,5,5,5,3,3,3,3,3,5,3,2,1
1,2,2,2,2,2,2,2,2,2,2,2,2,2,2,2,2,2,2,2,2,2,2,2,2,2,2,2,1
1,1,1,1,1,1,1,1,1,1,1,1,1,1,1,1,1,1,1,1,1,1,1,1,1,1,1,1,1
:endlayer
layer: 4
1,1,1,1,1,1,1,1,1,1,1,1,1,1,1,1,1,1,1,1,1,1,1,1,1,1,1,1,1
1,2,2,2,2,2,2,2,2,2,2,2,2,2,2,2,2,2,2,2,2,2,2,2,2,2,2,2,1
1,2,2,2,2,2,2,2,2,2,2,2,2,2,2,2,2,2,2,2,2,2,2,2,2,2,2,2,1
1,2,2,3,3,3,3,3,3,0,0,3,0,0,0,0,0,42,0,0,0,0,0,0,0,0,43,2,1
1,2,2,3,0,0,0,3,3,0,0,5,0,0,0,0,3,0,0,0,5,5,3,5,3,5,0,2,1
1,2,2,3,0,0,0,3,3,0,0,5,0,0,0,0,5,3,5,5,3,0,0,0,0,5,0,2,1
1,2,2,3,0,0,0,3,3,0,0,5,0,0,0,0,0,0,0,0,0,0,0,0,0,3,0,2,1
1,2,2,3,3,3,3,3,3,0,0,5,3,3,0,3,5,3,5,3,5,5,3,3,3,3,0,2,1
1,2,2,3,21,21,2,2,2,2,0,5,0,0,0,0,3,0,0,0,0,0,0,0,0,5,0,2,1
1,2,3,3,3,3,2,2,2,2,2,5,0,0,0,0,5,0,5,3,5,3,3,0,3,5,0,5,1
1,2,2,0,0,0,0,0,0,0,0,5,0,0,0,0,3,0,3,0,0,0,5,0,0,0,0,3,1
1,2,2,0,0,0,0,0,0,0,0,3,0,0,0,0,5,0,3,0,5,0,3,5,3,5,3,3,1
1,2,2,0,0,0,0,0,0,0,0,3,0,0,0,0,5,0,5,0,3,0,0,0,0,0,0,3,1
1,2,2,50,0,0,0,0,0,0,0,3,0,0,0,5,3,0,3,0,5,3,3,5,3,0,3,2,1
1,2,2,41,0,0,0,0,0,0,0,21,0,0,0,3,0,0,0,0,5,0,0,0,0,0,0,3,1
1,2,2,50,0,0,0,0,0,0,0,3,5,3,5,3,3,3,5,0,0,0,5,3,3,5,3,2,1
1,2,2,0,0,0,0,0,0,0,0,5,0,0,0,0,0,0,3,0,5,0,0,0,0,0,0,3,1
1,2,2,0,0,0,0,0,0,0,0,5,0,5,5,3,5,0,5,0,3,5,5,3,5,3,0,5,1
1,54,0,0,0,0,0,0,0,0,0,3,0,3,0,0,0,0,0,0,3,0,0,0,0,0,0,3,1
1,2,2,0,0,0,20,20,20,0,0,5,0,5,0,3,0,3,3,3,3,3,3,3,5,3,3,2,1
1,55,0,0,0,0,20,0,20,0,0,3,0,3,0,3,0,3,3,6,0,0,0,0,0,0,0,5,1
1,2,2,0,0,0,20,20,20,0,0,5,0,5,0,3,0,3,3,3,3,3,3,5,3,5,3,2,1
1,56,0,0,0,0,0,0,0,0,0,5,0,0,0,5,0,0,3,0,0,0,3,0,0,0,0,2,1
1,2,2,0,0,0,0,0,0,0,0,3,5,3,0,5,3,0,3,0,5,0,5,0,5,3,0,2,1
1,57,0,0,0,0,0,0,0,0,0,21,0,3,0,0,5,0,5,0,3,3,3,5,3,0,0,2,1
1,2,2,0,0,0,0,0,0,0,0,5,0,5,0,0,3,0,0,0,0,0,0,0,0,0,0,2,1
1,2,2,2,0,2,0,2,0,2,0,2,2,2,2,2,2,2,2,2,2,2,2,2,2,2,2,2,1
1,2,2,2,0,2,53,2,52,2,51,2,2,2,2,2,2,2,2,2,2,2,2,2,2,2,2,2,1
1,1,1,1,0,1,1,1,1,1,1,1,1,1,1,1,1,1,1,1,1,1,1,1,1,1,1,1,1
:endlayer
layer: 5
1,1,1,1,1,1,1,1,1,1,1,1,1,1,1,1,1,1,1,1,1,1,1,1,1,1,1,1,1
1,2,2,2,2,2,2,2,2,2,2,2,2,2,2,2,2,2,2,2,2,2,2,2,2,2,2,2,1
1,2,2,2,2,2,2,2,2,2,2,2,2,2,2,2,2,2,2,2,2,2,2,2,2,2,2,2,1
1,2,2,3,3,3,3,3,3,0,0,5,0,0,0,0,0,0,0,0,0,0,0,0,0,0,0,2,1
1,2,2,3,0,0,0,3,3,0,0,58,0,0,0,0,5,0,0,0,3,58,5,58,58,5,0,2,1
1,2,2,3,0,0,0,3,3,0,0,58,0,0,0,0,3,58,5,58,5,0,0,0,0,58,0,2,1
1,2,2,3,0,0,0,3,3,0,0,58,0,0,0,0,0,0,0,0,0,0,0,0,0,58,0,2,1
1,2,2,3,3,3,3,3,3,0,0,58,3,3,0,3,5,58,58,58,58,58,3,58,58,3,0,2,1
1,2,2,0,0,0,0,0,0,2,2,5,0,0,0,0,58,0,0,0,0,0,0,0,0,5,0,2,1
1,2,0,0,0,0,0,0,0,0,0,58,0,0,0,0,58,0,5,58,58,58,5,0,5,3,0,3,1
1,2,2,0,0,0,0,0,0,0,0,58,0,0,0,0,58,0,58,0,0,0,58,0,0,0,0,5,1
1,2,2,0,0,0,0,0,0,0,0,58,0,0,0,0,58,0,58,0,5,0,3,58,58,58,58,3,1
1,2,2,0,0,0,0,0,0,0,0,58,0,0,0,0,58,0,58,0,58,0,0,0,0,0,0,3,1
1,2,2,0,0,0,0,0,0,0,0,5,0,0,0,5,3,0,5,0,5,58,58,58,3,0,3,2,1
1,2,2,50,0,0,0,0,0,0,0,0,0,0,0,58,0,0,0,0,5,0,0,0,42,0,0,3,1
1,2,2,0,0,0,0,0,0,0,0,5,58,58,58,3,58,58,5,0,0,0,3,58,58,58,3,2,1
1,2,2,0,0,0,0,0,0,0,0,58,0,0,0,0,0,0,58,0,5,0,0,0,0,0,0,3,1
1,2,2,0,0,0,0,0,0,0,0,58,0,5,58,58,5,0,5,0,5,58,58,58,58,0,0,3,1
1,0,0,0,0,0,0,0,0,0,0,58,0,58,0,0,0,0,0,0,58,0,0,0,0,0,0,5,1
1,2,2,0,0,0,0,0,0,0,0,58,0,58,0,3,0,3,3,3,3,3,3,5,5,5,5,2,1
1,0,0,0,0,0,20,20,20,0,0,5,0,58,0,58,0,3,6,0,0,0,0,0,0,0,3,2,1
1,2,2,0,0,0,0,0,0,0,0,58,0,3,0,58,0,3,3,3,3,3,3,5,5,5,5,2,1
1,0,0,0,0,0,0,0,0,0,0,58,0,0,0,58,0,0,58,0,0,0,58,0,0,0,0,2,1
1,2,2,0,0,0,0,0,0,0,0,5,58,5,0,3,3,0,58,0,5,0,58,0,5,5,0,2,1
1,0,0,0,0,0,0,0,0,0,0,0,0,58,0,0,58,0,3,0,5,58,5,58,5,0,0,2,1
1,2,2,0,0,0,0,0,0,0,0,5,0,58,0,0,58,0,0,0,0,0,0,0,0,0,43,2,1
1,2,2,2,0,2,0,2,0,2,0,2,2,2,2,2,2,2,2,2,2,2,2,2,2,2,2,2,1
1,2,2,2,0,2,0,2,0,2,0,2,2,2,2,2,2,2,2,2,2,2,2,2,2,2,2,2,1
1,1,1,1,0,1,1,1,1,1,1,1,1,1,1,1,1,1,1,1,1,1,1,1,1,1,1,1,1
:endlayer
layer: 6
1,1,1,1,1,1,1,1,1,1,1,1,1,1,1,1,1,1,1,1,1,1,1,1,1,1,1,1,1
1,2,2,2,2,2,2,2,2,2,2,2,2,2,2,2,2,2,2,2,2,2,2,2,2,2,2,2,1
1,2,2,2,2,2,2,2,2,2,2,2,2,2,2,2,2,2,2,2,2,2,2,2,2,2,2,2,1
1,2,2,2,2,2,2,2,2,2,2,2,2,2,2,2,2,2,2,2,2,2,2,2,2,2,2,2,1
1,2,2,2,2,2,2,2,2,2,2,2,2,2,2,2,2,2,2,2,2,2,2,2,2,2,2,2,1
1,2,2,2,2,2,2,2,2,2,2,2,2,2,2,2,2,2,2,2,2,2,2,2,2,2,2,2,1
1,2,2,2,2,2,2,2,2,2,2,2,2,2,2,2,2,2,2,2,2,2,2,2,2,2,2,2,1
1,2,2,2,2,2,2,2,2,2,2,2,2,2,2,2,2,2,2,2,2,2,2,2,2,2,2,2,1
1,2,2,2,2,2,2,2,2,2,2,2,2,2,2,2,2,2,2,2,2,2,2,2,2,2,2,2,1
1,2,2,2,2,2,2,2,2,2,2,2,2,2,2,2,2,2,2,2,2,2,2,2,2,2,2,2,1
1,2,2,2,2,2,2,2,2,2,2,2,2,2,2,2,2,2,2,2,2,2,2,2,2,2,2,2,1
1,2,2,2,2,2,2,2,2,2,2,2,2,2,2,2,2,2,2,2,2,2,2,2,2,2,2,2,1
1,2,2,2,2,2,2,2,2,2,2,2,2,2,2,2,2,2,2,2,2,2,2,2,2,2,2,2,1
1,2,2,2,2,2,2,2,2,2,2,2,2,2,2,2,2,2,2,2,2,2,2,2,2,2,2,2,1
1,2,2,2,2,2,2,2,2,2,2,2,2,2,2,2,2,2,2,2,2,2,2,2,2,2,2,2,1
1,2,2,2,2,2,2,2,2,2,2,2,2,2,2,2,2,2,2,2,2,2,2,2,2,2,2,2,1
1,2,2,2,2,2,2,2,2,2,2,2,2,2,2,2,2,2,2,2,2,2,2,2,2,2,2,2,1
1,2,2,2,2,2,2,2,2,2,2,2,2,2,2,2,2,2,2,2,2,2,2,2,2,2,2,2,1
1,2,2,2,2,2,2,2,2,2,2,2,2,2,2,2,2,2,2,2,2,2,2,2,2,2,2,2,1
1,2,2,2,2,2,2,2,2,2,2,2,2,2,2,2,2,2,3,3,3,2,2,2,2,2,2,2,1
1,2,2,2,2,2,2,2,2,2,2,2,2,2,2,2,2,6,0,0,0,2,2,2,2,2,2,2,1
1,2,2,2,2,2,2,2,2,2,2,2,2,2,2,2,3,3,3,2,2,2,2,2,2,2,2,2,1
1,2,2,2,2,2,2,2,2,2,2,2,2,2,2,2,2,2,2,2,2,2,2,2,2,2,2,2,1
1,2,2,2,2,2,2,2,2,2,2,2,2,2,2,2,2,2,2,2,2,2,2,2,2,2,2,2,1
1,2,2,2,2,2,2,2,2,2,2,2,2,2,2,2,2,2,2,2,2,2,2,2,2,2,2,2,1
1,2,2,2,2,2,2,2,2,2,2,2,2,2,2,2,2,2,2,2,2,2,2,2,2,2,2,2,1
1,2,2,2,2,2,2,2,2,2,2,2,2,2,2,2,2,2,2,2,2,2,2,2,2,2,2,2,1
1,2,2,2,2,2,2,2,2,2,2,2,2,2,2,2,2,2,2,2,2,2,2,2,2,2,2,2,1
1,1,1,1,1,1,1,1,1,1,1,1,1,1,1,1,1,1,1,1,1,1,1,1,1,1,1,1,1
:endlayer
layer: 7
59,59,59,59,59,59,59,59,59,59,59,59,59,59,59,59,59,59,59,59,59,59,59,59,59,59,59,59,59
59,59,59,59,59,59,59,59,59,1,1,1,60,60,60,60,60,1,1,1,59,59,59,59,59,59,59,59,59
59,59,59,59,59,59,59,1,1,60,60,60,60,60,60,60,60,60,60,60,1,1,59,59,59,59,59,59,59
59,59,59,59,59,59,1,60,60,60,60,60,60,60,60,60,60,60,60,60,60,60,1,59,59,59,59,59,59
59,59,59,59,59,1,60,60,60,60,60,60,60,60,60,60,60,60,60,60,60,60,60,1,59,59,59,59,59
59,59,59,59,1,60,60,60,60,60,60,60,1,60,60,60,1,60,60,60,60,60,60,60,1,59,59,59,59
59,59,59,1,60,60,60,60,60,60,1,1,59,59,59,59,59,1,1,60,60,60,60,60,60,1,59,59,59
59,59,1,60,60,60,60,60,60,1,59,59,59,59,59,59,59,59,59,1,60,60,60,60,60,60,1,59,59
59,59,1,60,60,59,59,59,59,59,59,59,59,59,59,59,59,59,59,59,60,60,60,60,60,60,1,59,59
59,1,60,60,60,60,59,1,59,59,59,2,2,2,2,2,2,2,59,59,59,1,60,60,60,60,60,1,59
59,1,60,60,60,60,1,59,59,59,2,2,59,59,59,59,59,2,2,59,59,59,1,60,60,60,60,1,59
59,1,60,60,60,60,1,59,59,2,2,59,59,2,2,2,59,59,2,2,59,59,1,60,60,60,60,1,59
59,60,60,60,60,1,59,59,59,2,59,59,2,2,2,2,2,59,59,2,59,59,59,1,60,60,60,60,59
59,60,60,60,60,60,59,59,59,2,59,2,2,59,59,59,2,2,59,2,59,59,59,1,60,60,60,60,59
59,60,60,60,60,60,59,59,59,2,59,2,2,59,59,59,2,2,59,2,59,59,1,1,60,60,60,60,59
59,60,60,60,60,60,59,59,59,2,59,2,2,59,59,59,2,2,59,2,59,59,1,1,60,60,60,60,59
59,60,60,60,60,1,59,59,59,2,59,59,2,2,2,2,2,59,59,2,59,1,1,1,60,60,60,60,59
59,1,60,60,60,60,1,59,59,2,2,59,59,2,2,2,59,59,2,2,59,1,1,60,60,60,60,1,59
59,1,60,60,60,60,1,59,59,59,2,2,59,59,59,59,59,2,2,1,59,1,1,60,60,60,60,1,59
59,1,60,60,60,60,60,1,59,59,59,2,2,2,2,2,2,2,2,2,2,1,60,60,60,60,60,1,59
59,59,1,60,60,60,60,60,60,59,59,59,59,3,3,3,6,0,0,0,0,1,60,60,60,60,1,59,59
59,59,1,60,60,60,60,60,60,1,59,59,59,3,3,3,3,3,3,1,1,60,60,60,60,60,1,59,59
59,59,59,1,60,60,60,60,60,60,1,1,59,3,3,3,59,1,1,60,60,60,60,60,60,1,59,59,59
59,59,59,59,1,60,60,60,60,60,60,60,1,60,60,60,1,60,60,60,60,60,60,60,59,59,59,59,59
59,59,59,59,59,1,60,60,60,60,60,60,60,60,60,60,60,60,60,60,60,60,60,59,59,59,59,59,59
59,59,59,59,59,59,1,60,60,60,0,60,60,60,60,60,60,60,60,60,60,60,1,59,59,59,59,59,59
59,59,59,59,59,59,59,1,1,60,60,60,60,60,60,60,60,60,60,60,1,1,59,59,59,59,59,59,59
59,59,59,59,59,59,59,59,59,1,1,1,60,60,60,60,60,1,1,1,59,59,59,59,59,59,59,59,59
59,59,59,59,59,59,59,59,59,59,59,59,59,59,59,59,59,59,59,59,59,59,59,59,59,59,59,59,59
:endlayer
layer: 8
0,0,0,0,0,0,0,0,0,0,67,67,0,0,0,0,0,67,67,0,0,0,0,0,0,0,0,0,0
0,86,63,0,63,63,63,67,0,64,64,64,61,0,0,0,73,64,64,64,0,67,63,63,0,63,0,62,0
0,63,63,63,63,63,73,64,64,0,0,0,0,0,0,0,0,0,0,0,64,64,0,0,63,63,63,0,0
0,63,63,63,63,0,64,0,0,0,0,0,0,0,0,0,0,0,0,0,0,0,64,63,63,63,63,0,0
0,63,63,0,0,64,0,0,0,0,0,0,0,0,0,67,0,0,0,0,0,0,0,64,0,63,63,63,0
0,63,0,63,64,0,0,0,0,0,0,0,71,0,0,0,71,0,0,0,0,0,0,0,64,69,0,0,0
0,63,0,64,0,0,0,0,0,0,71,71,65,65,65,63,63,71,72,0,0,0,0,0,0,64,67,0,0
0,73,64,0,0,0,0,67,0,71,63,0,0,0,63,0,63,63,0,71,0,0,0,0,0,0,64,0,0
0,63,64,0,0,0,0,0,61,63,0,0,63,0,0,0,63,63,63,65,65,0,0,0,0,0,64,63,0
0,64,0,0,0,0,0,71,0,0,63,0,64,0,0,0,64,0,0,63,73,71,0,64,0,0,0,64,0
0,64,0,0,0,0,71,61,0,63,0,0,0,63,0,63,0,0,0,0,63,65,71,0,70,0,0,64,61
73,64,61,0,0,0,64,0,63,0,0,0,0,0,0,0,0,63,0,0,63,0,72,0,0,0,0,64,61
0,65,0,0,0,71,63,0,0,64,0,81,64,0,0,0,64,75,63,64,0,63,73,71,61,0,0,65,0
0,0,0,0,0,0,0,63,63,0,0,0,0,0,63,63,0,0,0,0,0,0,73,71,0,0,0,0,0
0,0,0,0,0,0,0,0,0,0,0,0,0,80,79,78,0,0,0,0,0,63,74,71,0,0,0,0,0
0,0,0,0,0,0,63,0,63,0,63,0,0,0,0,63,0,0,0,0,63,0,64,72,0,0,0,0,0
0,0,0,0,73,72,61,63,0,64,63,82,64,0,0,0,64,76,0,64,63,72,64,71,0,0,0,0,0
0,64,0,0,0,84,72,0,0,0,0,63,0,0,0,0,0,0,0,0,63,72,71,0,0,0,0,64,61
0,64,0,0,0,73,64,0,0,0,0,0,63,63,63,0,0,0,0,74,63,64,64,61,0,0,0,64,61
0,64,0,0,0,0,0,71,63,63,63,0,64,0,0,0,64,70,72,72,72,71,0,0,0,0,0,64,0
0,0,64,0,0,0,0,0,0,63,0,63,0,0,0,0,0,0,0,72,72,71,72,67,0,0,64,61,0
0,0,64,0,0,0,0,0,0,71,63,0,0,0,0,0,70,0,67,72,71,72,72,71,61,0,64,61,0
0,0,85,64,0,0,0,0,74,65,64,71,63,67,67,67,63,77,71,61,71,72,72,71,71,64,68,0,0
0,63,63,65,64,0,0,0,0,0,0,0,72,0,0,0,71,0,0,0,0,71,71,64,63,63,63,0,0
0,0,0,0,73,64,0,0,0,0,0,0,0,65,65,65,0,0,0,0,0,65,71,65,63,0,63,0,0
0,63,63,63,0,65,64,0,0,0,0,0,0,0,0,0,0,0,0,0,0,0,64,61,63,0,63,0,0
0,0,63,0,0,63,83,64,64,0,0,0,0,0,0,0,0,0,0,0,64,64,0,0,63,0,63,0,0
0,87,0,0,63,63,0,63,63,64,64,64,61,0,0,0,73,64,64,64,63,63,0,0,0,0,63,66,0
0,0,0,0,0,0,0,0,0,0,0,65,0,0,0,0,0,0,65,0,0,0,0,0,0,0,0,0,0
:endlayer
layer: 9
0,0,0,0,0,0,0,0,0,0,67,67,0,0,0,0,0,67,67,0,0,0,0,0,0,0,0,0,0
0,0,0,0,0,0,0,67,0,71,71,71,61,0,0,0,73,71,71,71,0,67,0,0,0,0,0,0,0
0,0,0,0,0,0,73,71,71,0,0,0,0,0,0,0,0,0,0,0,71,71,0,0,0,0,0,0,0
0,0,0,0,0,0,71,0,0,0,0,0,0,0,0,0,0,0,0,0,0,0,71,67,0,0,0,0,0
0,0,0,0,0,71,0,0,0,0,0,0,0,0,0,67,0,0,0,0,0,0,0,71,0,0,0,0,0
0,0,0,73,71,0,0,0,0,0,0,0,72,0,0,0,72,0,0,0,0,0,0,0,71,61,0,0,0
0,0,0,71,0,0,0,0,0,0,0,72,65,65,65,65,0,0,77,0,0,0,0,0,0,71,67,0,0
0,73,71,0,0,0,0,67,0,72,0,0,0,0,0,0,0,0,0,72,0,0,0,0,0,0,71,0,0
0,0,71,0,0,0,0,0,61,65,0,0,0,0,0,0,0,0,0,65,65,0,0,0,0,0,71,0,0
0,71,0,0,0,0,0,72,0,0,0,0,64,0,0,0,64,0,0,0,73,64,0,0,0,0,0,71,0
0,71,0,0,0,0,77,61,0,0,0,0,0,0,0,0,0,0,0,0,0,65,0,0,0,0,0,71,61
73,71,61,0,0,0,64,0,0,0,0,0,0,0,0,0,0,0,0,0,0,0,71,0,0,0,0,71,61
0,65,0,0,0,72,0,0,0,64,0,0,64,0,0,0,64,0,0,64,0,0,73,72,61,0,0,65,0
0,0,0,0,0,0,0,0,0,0,0,0,0,0,0,0,0,0,0,0,0,0,73,64,0,0,0,0,0
0,0,0,0,0,0,0,0,0,0,0,0,0,0,0,0,0,0,0,0,0,0,0,71,0,0,0,0,0
0,0,0,0,0,0,0,0,0,0,0,0,0,0,0,0,0,0,0,0,0,0,74,72,0,0,0,0,0
0,0,0,0,73,64,61,0,0,64,0,0,64,0,0,0,64,0,0,64,0,71,64,71,0,0,0,0,0
0,71,0,0,0,65,0,0,0,0,0,0,0,0,0,0,0,0,0,0,0,71,71,0,0,0,0,71,61
0,71,0,0,0,73,77,0,0,0,0,0,0,0,0,0,0,0,0,0,0,72,77,61,0,0,0,71,61
0,71,0,0,0,0,0,72,0,0,0,0,64,0,0,0,64,0,0,0,0,71,0,0,0,0,0,71,0
0,0,71,0,0,0,0,0,0,67,0,0,0,0,0,0,0,0,0,0,85,64,71,67,0,0,71,61,0
0,0,71,0,0,0,0,0,0,72,68,0,0,0,0,0,0,0,67,71,71,71,71,71,61,0,71,61,0
0,0,73,71,0,0,0,0,0,65,77,64,0,67,67,67,67,72,72,61,64,71,71,71,77,71,68,0,0
0,0,0,65,71,0,0,0,0,0,0,0,72,0,0,0,72,0,0,0,0,71,71,71,0,0,0,0,0
0,0,0,0,73,71,0,0,0,0,0,0,0,65,65,65,0,0,0,0,0,65,72,65,0,0,0,0,0
0,0,0,0,0,65,71,0,0,0,0,0,0,0,0,0,0,0,0,0,0,0,71,61,0,0,0,0,0
0,0,0,0,0,0,83,71,71,0,0,0,0,0,0,0,0,0,0,0,71,71,0,0,0,0,0,0,0
0,0,0,0,0,0,0,0,0,71,71,71,61,0,0,0,73,71,71,71,88,0,0,0,0,0,0,0,0
0,0,0,0,0,0,0,0,0,0,0,65,0,0,0,0,0,0,65,0,0,0,0,0,0,0,0,0,0
:endlayer
layer: 10
0,0,0,0,0,0,0,0,0,0,67,67,0,0,0,0,0,67,67,0,0,0,0,0,0,0,0,0,0
0,0,0,0,0,0,0,67,0,71,71,71,61,0,0,0,73,71,71,0,0,67,0,0,0,0,0,0,0
0,0,0,0,0,0,73,64,0,0,0,0,0,0,0,0,0,0,0,0,73,64,0,0,0,0,0,0,0
0,0,0,0,0,0,0,0,0,0,0,0,0,0,0,0,0,0,0,0,0,0,64,67,0,0,0,0,0
0,0,0,0,0,0,0,0,0,0,0,0,0,0,0,67,0,0,0,0,0,0,0,64,0,0,0,0,0
0,0,0,73,64,0,0,0,0,0,0,0,64,90,0,91,72,0,0,0,0,0,0,0,0,0,0,0,0
0,0,0,0,0,0,0,0,0,0,0,0,65,65,65,65,0,0,0,0,0,0,0,0,0,0,67,0,0
0,73,64,0,0,0,0,67,91,77,0,0,0,0,0,0,0,0,0,72,90,0,0,0,0,0,64,0,0
0,0,65,0,0,0,0,89,61,65,0,0,0,0,0,0,0,0,0,65,65,89,0,0,0,0,0,0,0
0,0,0,0,0,0,0,64,0,0,0,0,64,0,0,0,64,0,0,0,73,77,0,0,0,0,0,67,0
0,71,0,0,0,0,71,61,0,0,0,0,0,0,0,0,0,0,0,0,0,65,0,0,0,0,0,64,61
73,71,61,0,0,0,72,0,0,0,0,0,0,0,0,0,0,0,0,0,0,0,0,0,0,0,0,71,61
0,65,0,0,0,72,0,0,0,64,0,0,64,0,0,0,64,0,0,64,0,0,73,71,61,0,0,65,0
0,0,0,0,0,92,0,0,0,0,0,0,0,0,0,0,0,0,0,0,0,0,73,71,0,0,0,0,0
0,0,0,0,0,0,0,0,0,0,0,0,0,0,0,0,0,0,0,0,0,0,0,77,0,0,0,0,0
0,0,0,0,0,89,0,0,0,0,0,0,0,0,0,0,0,0,0,0,0,0,0,71,0,0,0,0,0
0,0,0,0,73,64,61,0,0,64,0,0,64,0,0,0,64,0,0,64,0,0,0,72,0,0,0,0,0
0,71,0,0,0,65,0,0,0,0,0,0,0,0,0,0,0,0,0,0,0,74,71,0,0,0,0,71,61
0,65,0,0,0,0,0,0,0,0,0,0,0,0,0,0,0,0,0,0,0,77,71,61,0,0,0,71,61
0,0,0,0,0,0,0,64,0,0,0,0,64,0,0,0,64,0,0,0,0,71,0,0,0,0,0,0,0
0,0,71,0,0,0,0,0,0,67,0,0,0,0,0,0,0,0,0,0,85,64,64,67,0,0,0,0,0
0,0,65,0,0,0,0,0,0,64,61,0,0,0,0,0,0,0,67,71,77,64,64,72,61,0,64,61,0
0,0,73,71,0,0,0,0,0,65,70,0,0,67,67,67,67,64,77,61,64,64,64,71,70,64,68,0,0
0,0,0,65,0,0,0,0,0,0,0,0,64,90,0,91,71,0,0,0,0,71,71,70,0,0,0,0,0
0,0,0,0,73,71,0,0,0,0,0,0,0,65,65,65,0,0,0,0,0,65,70,0,0,0,0,0,0
0,0,0,0,0,65,0,0,0,0,0,0,0,0,0,0,0,0,0,0,0,0,64,61,0,0,0,0,0
0,0,0,0,0,0,73,64,0,0,0,0,0,0,0,0,0,0,0,0,71,61,0,0,0,0,0,0,0
0,0,0,0,0,0,0,0,0,0,71,71,61,0,0,0,73,71,71,71,61,0,0,0,0,0,0,0,0
0,0,0,0,0,0,0,0,0,0,0,65,0,0,0,0,0,0,65,0,0,0,0,0,0,0,0,0,0
:endlayer
layer: 11
0,0,0,0,0,0,0,0,0,0,0,67,0,0,0,0,0,67,0,0,0,0,0,0,0,0,0,0,0
0,0,0,0,0,0,0,0,0,64,0,71,61,0,0,0,73,71,61,0,0,0,0,0,0,0,0,0,0
0,0,0,0,0,0,0,0,0,0,0,0,0,0,0,0,0,0,0,0,0,0,0,0,0,0,0,0,0
0,0,0,0,0,0,0,0,0,0,0,0,0,0,0,0,0,0,0,0,0,0,0,0,0,0,0,0,0
0,0,0,0,0,0,0,0,0,0,0,0,0,0,0,67,0,0,0,0,0,0,0,0,0,0,0,0,0
0,0,0,0,0,0,0,0,0,0,0,0,77,77,71,71,71,0,0,0,0,0,0,0,0,0,0,0,0
0,0,0,0,0,0,0,0,0,0,0,0,65,65,65,65,0,0,0,0,0,0,0,0,0,0,67,0,0
0,0,0,0,0,0,0,67,72,72,0,0,0,0,0,0,0,0,0,71,71,0,0,0,0,0,64,0,0
0,0,0,0,0,0,0,71,61,65,0,0,0,0,0,0,0,0,0,65,65,71,0,0,0,0,0,0,0
0,0,0,0,0,0,0,72,0,0,0,0,0,0,0,0,0,0,0,0,73,72,0,0,0,0,0,0,0
0,0,0,0,0,0,72,61,0,0,0,0,0,0,0,0,0,0,0,0,0,65,0,0,0,0,0,67,0
73,71,61,0,0,0,65,0,0,0,0,0,0,0,0,0,0,0,0,0,0,0,0,0,0,0,0,71,61
0,65,0,0,0,0,0,0,0,0,0,0,0,0,0,0,0,0,0,0,0,0,0,0,0,0,0,65,0
0,0,0,0,0,64,0,0,0,0,0,0,0,0,0,0,0,0,0,0,0,0,73,71,0,0,0,0,0
0,0,0,0,0,71,0,0,0,0,0,0,0,0,0,0,0,0,0,0,0,0,0,64,0,0,0,0,0
0,0,0,0,0,77,0,0,0,0,0,0,0,0,0,0,0,0,0,0,0,0,0,71,0,0,0,0,0
0,0,0,0,73,72,61,0,0,0,0,0,0,0,0,0,0,0,0,0,0,0,0,0,0,0,0,0,0
0,71,0,0,0,65,0,0,0,0,0,0,0,0,0,0,0,0,0,0,0,0,71,0,0,0,0,71,61
0,65,0,0,0,0,0,0,0,0,0,0,0,0,0,0,0,0,0,0,0,93,71,61,0,0,0,0,0
0,0,0,0,0,0,0,0,0,0,0,0,0,0,0,0,0,0,0,0,0,71,0,0,0,0,0,0,0
0,0,0,0,0,0,0,0,0,67,0,0,0,0,0,0,0,0,0,0,73,71,0,0,0,0,0,0,0
0,0,0,0,0,0,0,0,0,64,61,0,0,0,0,0,0,0,67,0,93,72,70,0,0,0,64,61,0
0,0,0,0,0,0,0,0,0,65,0,0,0,67,67,67,67,0,71,61,72,70,70,0,0,0,65,0,0
0,0,0,0,0,0,0,0,0,0,0,0,72,77,71,71,64,0,0,0,0,0,0,0,0,0,0,0,0
0,0,0,0,73,71,0,0,0,0,0,0,0,65,65,65,0,0,0,0,0,0,0,0,0,0,0,0,0
0,0,0,0,0,65,0,0,0,0,0,0,0,0,0,0,0,0,0,0,0,0,0,0,0,0,0,0,0
0,0,0,0,0,0,73,64,0,0,0,0,0,0,0,0,0,0,0,0,0,0,0,0,0,0,0,0,0
0,0,0,0,0,0,0,0,0,0,0,71,61,0,0,0,73,71,71,0,0,0,0,0,0,0,0,0,0
0,0,0,0,0,0,0,0,0,0,0,65,0,0,0,0,0,0,65,0,0,0,0,0,0,0,0,0,0
:endlayer
layer: 12
0,0,0,0,0,0,0,0,0,0,0,67,0,0,0,0,0,67,0,0,0,0,0,0,0,0,0,0,0
0,0,0,0,0,0,0,0,0,0,0,71,61,0,0,0,73,71,61,0,0,0,0,0,0,0,0,0,0
0,0,0,0,0,0,0,0,0,0,0,0,0,0,0,0,0,0,0,0,0,0,0,0,0,0,0,0,0
0,0,0,0,0,0,0,0,0,0,0,0,0,0,0,0,0,0,0,0,0,0,0,0,0,0,0,0,0
0,0,0,0,0,0,0,0,0,0,0,0,0,0,0,67,0,0,0,0,0,0,0,0,0,0,0,0,0
0,0,0,0,0,0,0,0,0,0,0,0,64,64,73,64,0,0,0,0,0,0,0,0,0,0,0,0,0
0,0,0,0,0,0,0,0,0,0,0,0,65,65,0,65,0,0,0,0,0,0,0,0,0,0,0,0,0
0,0,0,0,0,0,0,67,0,64,0,0,0,0,0,0,0,0,0,64,0,0,0,0,0,0,0,0,0
0,0,0,0,0,0,0,71,61,65,0,0,0,0,0,0,0,0,0,65,0,0,0,0,0,0,0,0,0
0,0,0,0,0,0,0,71,0,0,0,0,0,0,0,0,0,0,0,0,73,64,0,0,0,0,0,0,0
0,0,0,0,0,0,71,61,0,0,0,0,0,0,0,0,0,0,0,0,0,65,0,0,0,0,0,0,0
0,0,0,0,0,0,65,0,0,0,0,0,0,0,0,0,0,0,0,0,0,0,0,0,0,0,0,0,0
0,0,0,0,0,0,0,0,0,0,0,0,0,0,0,0,0,0,0,0,0,0,0,0,0,0,0,0,0
0,0,0,0,0,71,0,0,0,0,0,0,0,0,0,0,0,0,0,0,0,0,73,71,0,0,0,0,0
0,0,0,0,0,71,0,0,0,0,0,0,0,0,0,0,0,0,0,0,0,0,0,94,0,0,0,0,0
0,0,0,0,0,67,0,0,0,0,0,0,0,0,0,0,0,0,0,0,0,0,0,64,0,0,0,0,0
0,0,0,0,73,64,61,0,0,0,0,0,0,0,0,0,0,0,0,0,0,0,0,0,0,0,0,0,0
0,0,0,0,0,65,0,0,0,0,0,0,0,0,0,0,0,0,0,0,0,0,67,0,0,0,0,0,0
0,0,0,0,0,0,0,0,0,0,0,0,0,0,0,0,0,0,0,0,0,73,71,61,0,0,0,0,0
0,0,0,0,0,0,0,0,0,0,0,0,0,0,0,0,0,0,0,0,0,0,0,0,0,0,0,0,0
0,0,0,0,0,0,0,0,0,67,0,0,0,0,0,0,0,0,0,0,0,67,0,0,0,0,0,0,0
0,0,0,0,0,0,0,0,0,64,61,0,0,0,0,0,0,0,67,0,73,71,61,0,0,0,0,0,0
0,0,0,0,0,0,0,0,0,65,0,0,0,67,67,67,0,0,71,61,0,65,0,0,0,0,0,0,0
0,0,0,0,0,0,0,0,0,0,0,0,71,71,95,71,0,0,0,0,0,0,0,0,0,0,0,0,0
0,0,0,0,0,0,0,0,0,0,0,0,0,65,65,65,0,0,0,0,0,0,0,0,0,0,0,0,0
0,0,0,0,0,0,0,0,0,0,0,0,0,0,0,0,0,0,0,0,0,0,0,0,0,0,0,0,0
0,0,0,0,0,0,0,0,0,0,0,0,0,0,0,0,0,0,0,0,0,0,0,0,0,0,0,0,0
0,0,0,0,0,0,0,0,0,0,0,71,61,0,0,0,73,71,0,0,0,0,0,0,0,0,0,0,0
0,0,0,0,0,0,0,0,0,0,0,65,0,0,0,0,0,0,0,0,0,0,0,0,0,0,0,0,0
:endlayer
layer: 13
0,0,0,0,0,0,0,0,0,0,0,0,0,0,0,0,0,0,0,0,0,0,0,0,0,0,0,0,0
0,0,0,0,0,0,0,0,0,0,0,0,0,0,0,0,0,0,0,0,0,0,0,0,0,0,0,0,0
0,0,0,0,0,0,0,0,0,0,0,0,0,0,0,0,0,0,0,0,0,0,0,0,0,0,0,0,0
0,0,0,0,0,0,0,0,0,0,0,0,0,0,0,0,0,0,0,0,0,0,0,0,0,0,0,0,0
0,0,0,0,0,0,0,0,0,0,0,0,0,0,0,67,0,0,0,0,0,0,0,0,0,0,0,0,0
0,0,0,0,0,0,0,0,0,0,0,0,64,96,73,64,0,0,0,0,0,0,0,0,0,0,0,0,0
0,0,0,0,0,0,0,0,0,0,0,0,65,65,0,65,0,0,0,0,0,0,0,0,0,0,0,0,0
0,0,0,0,0,0,0,67,0,64,0,0,0,0,0,0,0,0,0,64,0,0,0,0,0,0,0,0,0
0,0,0,0,0,0,0,71,61,65,0,0,0,0,0,0,0,0,0,65,0,0,0,0,0,0,0,0,0
0,0,0,0,0,0,0,65,0,0,0,0,0,0,0,0,0,0,0,0,73,64,0,0,0,0,0,0,0
0,0,0,0,0,0,71,61,0,0,0,0,0,0,0,0,0,0,0,0,0,65,0,0,0,0,0,0,0
0,0,0,0,0,0,65,0,0,0,0,0,0,0,0,0,0,0,0,0,0,0,0,0,0,0,0,0,0
0,0,0,0,0,0,0,0,0,0,0,0,0,0,0,0,0,0,0,0,0,0,0,0,0,0,0,0,0
0,0,0,0,0,71,0,0,0,0,0,0,0,0,0,0,0,0,0,0,0,0,73,71,0,0,0,0,0
0,0,0,0,0,97,0,0,0,0,0,0,0,0,0,0,0,0,0,0,0,0,0,0,0,0,0,0,0
0,0,0,0,0,67,0,0,0,0,0,0,0,0,0,0,0,0,0,0,0,0,0,64,0,0,0,0,0
0,0,0,0,73,64,61,0,0,0,0,0,0,0,0,0,0,0,0,0,0,0,0,0,0,0,0,0,0
0,0,0,0,0,65,0,0,0,0,0,0,0,0,0,0,0,0,0,0,0,0,67,0,0,0,0,0,0
0,0,0,0,0,0,0,0,0,0,0,0,0,0,0,0,0,0,0,0,0,73,71,61,0,0,0,0,0
0,0,0,0,0,0,0,0,0,0,0,0,0,0,0,0,0,0,0,0,0,0,0,0,0,0,0,0,0
0,0,0,0,0,0,0,0,0,67,0,0,0,0,0,0,0,0,0,0,0,67,0,0,0,0,0,0,0
0,0,0,0,0,0,0,0,0,71,61,0,0,0,0,0,0,0,67,0,73,71,61,0,0,0,0,0,0
0,0,0,0,0,0,0,0,0,65,0,0,0,67,0,0,0,0,71,61,0,65,0,0,0,0,0,0,0
0,0,0,0,0,0,0,0,0,0,0,0,0,71,61,0,0,0,0,0,0,0,0,0,0,0,0,0,0
0,0,0,0,0,0,0,0,0,0,0,0,0,65,0,0,0,0,0,0,0,0,0,0,0,0,0,0,0
0,0,0,0,0,0,0,0,0,0,0,0,0,0,0,0,0,0,0,0,0,0,0,0,0,0,0,0,0
0,0,0,0,0,0,0,0,0,0,0,0,0,0,0,0,0,0,0,0,0,0,0,0,0,0,0,0,0
0,0,0,0,0,0,0,0,0,0,0,0,0,0,0,0,0,0,0,0,0,0,0,0,0,0,0,0,0
0,0,0,0,0,0,0,0,0,0,0,0,0,0,0,0,0,0,0,0,0,0,0,0,0,0,0,0,0
:endlayer
layer: 14
0,0,0,0,0,0,0,0,0,0,0,0,0,0,0,0,0,0,0,0,0,0,0,0,0,0,0,0,0
0,0,0,0,0,0,0,0,0,0,0,0,0,0,0,0,0,0,0,0,0,0,0,0,0,0,0,0,0
0,0,0,0,0,0,0,0,0,0,0,0,0,0,0,0,0,0,0,0,0,0,0,0,0,0,0,0,0
0,0,0,0,0,0,0,0,0,0,0,0,0,0,0,0,0,0,0,0,0,0,0,0,0,0,0,0,0
0,0,0,0,0,0,0,0,0,0,0,0,0,0,0,67,0,0,0,0,0,0,0,0,0,0,0,0,0
0,0,0,0,0,0,0,0,0,0,0,0,64,0,73,64,0,0,0,0,0,0,0,0,0,0,0,0,0
0,0,0,0,0,0,0,0,0,0,0,0,65,0,0,65,0,0,0,0,0,0,0,0,0,0,0,0,0
0,0,0,0,0,0,0,67,0,64,0,0,0,0,0,0,0,0,0,0,0,0,0,0,0,0,0,0,0
0,0,0,0,0,0,0,71,61,65,0,0,0,0,0,0,0,0,0,0,0,0,0,0,0,0,0,0,0
0,0,0,0,0,0,0,65,0,0,0,0,0,0,0,0,0,0,0,0,0,0,0,0,0,0,0,0,0
0,0,0,0,0,0,71,61,0,0,0,0,0,0,0,0,0,0,0,0,0,0,0,0,0,0,0,0,0
0,0,0,0,0,0,65,0,0,0,0,0,0,0,0,0,0,0,0,0,0,0,0,0,0,0,0,0,0
0,0,0,0,0,0,0,0,0,0,0,0,0,0,0,0,0,0,0,0,0,0,0,0,0,0,0,0,0
0,0,0,0,0,71,0,0,0,0,0,0,0,0,0,0,0,0,0,0,0,0,0,0,0,0,0,0,0
0,0,0,0,0,0,0,0,0,0,0,0,0,0,0,0,0,0,0,0,0,0,0,0,0,0,0,0,0
0,0,0,0,0,67,0,0,0,0,0,0,0,0,0,0,0,0,0,0,0,0,0,0,0,0,0,0,0
0,0,0,0,73,64,61,0,0,0,0,0,0,0,0,0,0,0,0,0,0,0,0,0,0,0,0,0,0
0,0,0,0,0,65,0,0,0,0,0,0,0,0,0,0,0,0,0,0,0,0,0,0,0,0,0,0,0
0,0,0,0,0,0,0,0,0,0,0,0,0,0,0,0,0,0,0,0,0,0,0,0,0,0,0,0,0
0,0,0,0,0,0,0,0,0,0,0,0,0,0,0,0,0,0,0,0,0,0,0,0,0,0,0,0,0
0,0,0,0,0,0,0,0,0,67,0,0,0,0,0,0,0,0,0,0,0,67,0,0,0,0,0,0,0
0,0,0,0,0,0,0,0,0,71,61,0,0,0,0,0,0,0,67,0,73,71,61,0,0,0,0,0,0
0,0,0,0,0,0,0,0,0,65,0,0,0,0,0,0,0,0,71,61,0,65,0,0,0,0,0,0,0
0,0,0,0,0,0,0,0,0,0,0,0,0,0,0,0,0,0,0,0,0,0,0,0,0,0,0,0,0
0,0,0,0,0,0,0,0,0,0,0,0,0,0,0,0,0,0,0,0,0,0,0,0,0,0,0,0,0
0,0,0,0,0,0,0,0,0,0,0,0,0,0,0,0,0,0,0,0,0,0,0,0,0,0,0,0,0
0,0,0,0,0,0,0,0,0,0,0,0,0,0,0,0,0,0,0,0,0,0,0,0,0,0,0,0,0
0,0,0,0,0,0,0,0,0,0,0,0,0,0,0,0,0,0,0,0,0,0,0,0,0,0,0,0,0
0,0,0,0,0,0,0,0,0,0,0,0,0,0,0,0,0,0,0,0,0,0,0,0,0,0,0,0,0
:endlayer
layer: 15
0,0,0,0,0,0,0,0,0,0,0,0,0,0,0,0,0,0,0,0,0,0,0,0,0,0,0,0,0
0,0,0,0,0,0,0,0,0,0,0,0,0,0,0,0,0,0,0,0,0,0,0,0,0,0,0,0,0
0,0,0,0,0,0,0,0,0,0,0,0,0,0,0,0,0,0,0,0,0,0,0,0,0,0,0,0,0
0,0,0,0,0,0,0,0,0,0,0,0,0,0,0,0,0,0,0,0,0,0,0,0,0,0,0,0,0
0,0,0,0,0,0,0,0,0,0,0,0,0,0,0,67,0,0,0,0,0,0,0,0,0,0,0,0,0
0,0,0,0,0,0,0,0,0,0,0,0,0,0,73,64,0,0,0,0,0,0,0,0,0,0,0,0,0
0,0,0,0,0,0,0,0,0,0,0,0,0,0,0,65,0,0,0,0,0,0,0,0,0,0,0,0,0
0,0,0,0,0,0,0,67,0,0,0,0,0,0,0,0,0,0,0,0,0,0,0,0,0,0,0,0,0
0,0,0,0,0,0,0,64,61,0,0,0,0,0,0,0,0,0,0,0,0,0,0,0,0,0,0,0,0
0,0,0,0,0,0,0,65,0,0,0,0,0,0,0,0,0,0,0,0,0,0,0,0,0,0,0,0,0
0,0,0,0,0,0,0,0,0,0,0,0,0,0,0,0,0,0,0,0,0,0,0,0,0,0,0,0,0
0,0,0,0,0,0,0,0,0,0,0,0,0,0,0,0,0,0,0,0,0,0,0,0,0,0,0,0,0
0,0,0,0,0,0,0,0,0,0,0,0,0,0,0,0,0,0,0,0,0,0,0,0,0,0,0,0,0
0,0,0,0,0,71,0,0,0,0,0,0,0,0,0,0,0,0,0,0,0,0,0,0,0,0,0,0,0
0,0,0,0,0,0,0,0,0,0,0,0,0,0,0,0,0,0,0,0,0,0,0,0,0,0,0,0,0
0,0,0,0,0,67,0,0,0,0,0,0,0,0,0,0,0,0,0,0,0,0,0,0,0,0,0,0,0
0,0,0,0,73,64,61,0,0,0,0,0,0,0,0,0,0,0,0,0,0,0,0,0,0,0,0,0,0
0,0,0,0,0,65,0,0,0,0,0,0,0,0,0,0,0,0,0,0,0,0,0,0,0,0,0,0,0
0,0,0,0,0,0,0,0,0,0,0,0,0,0,0,0,0,0,0,0,0,0,0,0,0,0,0,0,0
0,0,0,0,0,0,0,0,0,0,0,0,0,0,0,0,0,0,0,0,0,0,0,0,0,0,0,0,0
0,0,0,0,0,0,0,0,0,67,0,0,0,0,0,0,0,0,0,0,0,67,0,0,0,0,0,0,0
0,0,0,0,0,0,0,0,0,71,61,0,0,0,0,0,0,0,67,0,73,71,61,0,0,0,0,0,0
0,0,0,0,0,0,0,0,0,65,0,0,0,0,0,0,0,0,71,61,0,65,0,0,0,0,0,0,0
0,0,0,0,0,0,0,0,0,0,0,0,0,0,0,0,0,0,0,0,0,0,0,0,0,0,0,0,0
0,0,0,0,0,0,0,0,0,0,0,0,0,0,0,0,0,0,0,0,0,0,0,0,0,0,0,0,0
0,0,0,0,0,0,0,0,0,0,0,0,0,0,0,0,0,0,0,0,0,0,0,0,0,0,0,0,0
0,0,0,0,0,0,0,0,0,0,0,0,0,0,0,0,0,0,0,0,0,0,0,0,0,0,0,0,0
0,0,0,0,0,0,0,0,0,0,0,0,0,0,0,0,0,0,0,0,0,0,0,0,0,0,0,0,0
0,0,0,0,0,0,0,0,0,0,0,0,0,0,0,0,0,0,0,0,0,0,0,0,0,0,0,0,0
:endlayer
layer: 16
0,0,0,0,0,0,0,0,0,0,0,0,0,0,0,0,0,0,0,0,0,0,0,0,0,0,0,0,0
0,0,0,0,0,0,0,0,0,0,0,0,0,0,0,0,0,0,0,0,0,0,0,0,0,0,0,0,0
0,0,0,0,0,0,0,0,0,0,0,0,0,0,0,0,0,0,0,0,0,0,0,0,0,0,0,0,0
0,0,0,0,0,0,0,0,0,0,0,0,0,0,0,0,0,0,0,0,0,0,0,0,0,0,0,0,0
0,0,0,0,0,0,0,0,0,0,0,0,0,0,0,0,0,0,0,0,0,0,0,0,0,0,0,0,0
0,0,0,0,0,0,0,0,0,0,0,0,0,0,0,0,0,0,0,0,0,0,0,0,0,0,0,0,0
0,0,0,0,0,0,0,0,0,0,0,0,0,0,0,0,0,0,0,0,0,0,0,0,0,0,0,0,0
0,0,0,0,0,0,0,67,0,0,0,0,0,0,0,0,0,0,0,0,0,0,0,0,0,0,0,0,0
0,0,0,0,0,0,0,64,61,0,0,0,0,0,0,0,0,0,0,0,0,0,0,0,0,0,0,0,0
0,0,0,0,0,0,0,65,0,0,0,0,0,0,0,0,0,0,0,0,0,0,0,0,0,0,0,0,0
0,0,0,0,0,0,0,0,0,0,0,0,0,0,0,0,0,0,0,0,0,0,0,0,0,0,0,0,0
0,0,0,0,0,0,0,0,0,0,0,0,0,0,0,0,0,0,0,0,0,0,0,0,0,0,0,0,0
0,0,0,0,0,0,0,0,0,0,0,0,0,0,0,0,0,0,0,0,0,0,0,0,0,0,0,0,0
0,0,0,0,0,71,0,0,0,0,0,0,0,0,0,0,0,0,0,0,0,0,0,0,0,0,0,0,0
0,0,0,0,0,0,0,0,0,0,0,0,0,0,0,0,0,0,0,0,0,0,0,0,0,0,0,0,0
0,0,0,0,0,0,0,0,0,0,0,0,0,0,0,0,0,0,0,0,0,0,0,0,0,0,0,0,0
0,0,0,0,0,0,0,0,0,0,0,0,0,0,0,0,0,0,0,0,0,0,0,0,0,0,0,0,0
0,0,0,0,0,0,0,0,0,0,0,0,0,0,0,0,0,0,0,0,0,0,0,0,0,0,0,0,0
0,0,0,0,0,0,0,0,0,0,0,0,0,0,0,0,0,0,0,0,0,0,0,0,0,0,0,0,0
0,0,0,0,0,0,0,0,0,0,0,0,0,0,0,0,0,0,0,0,0,0,0,0,0,0,0,0,0
0,0,0,0,0,0,0,0,0,0,0,0,0,0,0,0,0,0,0,0,0,67,0,0,0,0,0,0,0
0,0,0,0,0,0,0,0,0,0,0,0,0,0,0,0,0,0,67,0,73,71,61,0,0,0,0,0,0
0,0,0,0,0,0,0,0,0,0,0,0,0,0,0,0,0,0,71,61,0,65,0,0,0,0,0,0,0
0,0,0,0,0,0,0,0,0,0,0,0,0,0,0,0,0,0,0,0,0,0,0,0,0,0,0,0,0
0,0,0,0,0,0,0,0,0,0,0,0,0,0,0,0,0,0,0,0,0,0,0,0,0,0,0,0,0
0,0,0,0,0,0,0,0,0,0,0,0,0,0,0,0,0,0,0,0,0,0,0,0,0,0,0,0,0
0,0,0,0,0,0,0,0,0,0,0,0,0,0,0,0,0,0,0,0,0,0,0,0,0,0,0,0,0
0,0,0,0,0,0,0,0,0,0,0,0,0,0,0,0,0,0,0,0,0,0,0,0,0,0,0,0,0
0,0,0,0,0,0,0,0,0,0,0,0,0,0,0,0,0,0,0,0,0,0,0,0,0,0,0,0,0
:endlayer
layer: 17
0,0,0,0,0,0,0,0,0,0,0,0,0,0,0,0,0,0,0,0,0,0,0,0,0,0,0,0,0
0,0,0,0,0,0,0,0,0,0,0,0,0,0,0,0,0,0,0,0,0,0,0,0,0,0,0,0,0
0,0,0,0,0,0,0,0,0,0,0,0,0,0,0,0,0,0,0,0,0,0,0,0,0,0,0,0,0
0,0,0,0,0,0,0,0,0,0,0,0,0,0,0,0,0,0,0,0,0,0,0,0,0,0,0,0,0
0,0,0,0,0,0,0,0,0,0,0,0,0,0,0,0,0,0,0,0,0,0,0,0,0,0,0,0,0
0,0,0,0,0,0,0,0,0,0,0,0,0,0,0,0,0,0,0,0,0,0,0,0,0,0,0,0,0
0,0,0,0,0,0,0,0,0,0,0,0,0,0,0,0,0,0,0,0,0,0,0,0,0,0,0,0,0
0,0,0,0,0,0,0,67,0,0,0,0,0,0,0,0,0,0,0,0,0,0,0,0,0,0,0,0,0
0,0,0,0,0,0,0,64,61,0,0,0,0,0,0,0,0,0,0,0,0,0,0,0,0,0,0,0,0
0,0,0,0,0,0,0,65,0,0,0,0,0,0,0,0,0,0,0,0,0,0,0,0,0,0,0,0,0
0,0,0,0,0,0,0,0,0,0,0,0,0,0,0,0,0,0,0,0,0,0,0,0,0,0,0,0,0
0,0,0,0,0,0,0,0,0,0,0,0,0,0,0,0,0,0,0,0,0,0,0,0,0,0,0,0,0
0,0,0,0,0,0,0,0,0,0,0,0,0,0,0,0,0,0,0,0,0,0,0,0,0,0,0,0,0
0,0,0,0,0,0,0,0,0,0,0,0,0,0,0,0,0,0,0,0,0,0,0,0,0,0,0,0,0
0,0,0,0,0,0,0,0,0,0,0,0,0,0,0,0,0,0,0,0,0,0,0,0,0,0,0,0,0
0,0,0,0,0,0,0,0,0,0,0,0,0,0,0,0,0,0,0,0,0,0,0,0,0,0,0,0,0
0,0,0,0,0,0,0,0,0,0,0,0,0,0,0,0,0,0,0,0,0,0,0,0,0,0,0,0,0
0,0,0,0,0,0,0,0,0,0,0,0,0,0,0,0,0,0,0,0,0,0,0,0,0,0,0,0,0
0,0,0,0,0,0,0,0,0,0,0,0,0,0,0,0,0,0,0,0,0,0,0,0,0,0,0,0,0
0,0,0,0,0,0,0,0,0,0,0,0,0,0,0,0,0,0,0,0,0,0,0,0,0,0,0,0,0
0,0,0,0,0,0,0,0,0,0,0,0,0,0,0,0,0,0,0,0,0,0,0,0,0,0,0,0,0
0,0,0,0,0,0,0,0,0,0,0,0,0,0,0,0,0,0,0,0,0,0,0,0,0,0,0,0,0
0,0,0,0,0,0,0,0,0,0,0,0,0,0,0,0,0,0,0,0,0,0,0,0,0,0,0,0,0
0,0,0,0,0,0,0,0,0,0,0,0,0,0,0,0,0,0,0,0,0,0,0,0,0,0,0,0,0
0,0,0,0,0,0,0,0,0,0,0,0,0,0,0,0,0,0,0,0,0,0,0,0,0,0,0,0,0
0,0,0,0,0,0,0,0,0,0,0,0,0,0,0,0,0,0,0,0,0,0,0,0,0,0,0,0,0
0,0,0,0,0,0,0,0,0,0,0,0,0,0,0,0,0,0,0,0,0,0,0,0,0,0,0,0,0
0,0,0,0,0,0,0,0,0,0,0,0,0,0,0,0,0,0,0,0,0,0,0,0,0,0,0,0,0
0,0,0,0,0,0,0,0,0,0,0,0,0,0,0,0,0,0,0,0,0,0,0,0,0,0,0,0,0
:endlayer
layer: 18
0,0,0,0,0,0,0,0,0,0,0,0,0,0,0,0,0,0,0,0,0,0,0,0,0,0,0,0,0
0,0,0,0,0,0,0,0,0,0,0,0,0,0,0,0,0,0,0,0,0,0,0,0,0,0,0,0,0
0,0,0,0,0,0,0,0,0,0,0,0,0,0,0,0,0,0,0,0,0,0,0,0,0,0,0,0,0
0,0,0,0,0,0,0,0,0,0,0,0,0,0,0,0,0,0,0,0,0,0,0,0,0,0,0,0,0
0,0,0,0,0,0,0,0,0,0,0,0,0,0,0,0,0,0,0,0,0,0,0,0,0,0,0,0,0
0,0,0,0,0,0,0,0,0,0,0,0,0,0,0,0,0,0,0,0,0,0,0,0,0,0,0,0,0
0,0,0,0,0,0,0,0,0,0,0,0,0,0,0,0,0,0,0,0,0,0,0,0,0,0,0,0,0
0,0,0,0,0,0,0,67,0,0,0,0,0,0,0,0,0,0,0,0,0,0,0,0,0,0,0,0,0
0,0,0,0,0,0,0,64,61,0,0,0,0,0,0,0,0,0,0,0,0,0,0,0,0,0,0,0,0
0,0,0,0,0,0,0,65,0,0,0,0,0,0,0,0,0,0,0,0,0,0,0,0,0,0,0,0,0
0,0,0,0,0,0,0,0,0,0,0,0,0,0,0,0,0,0,0,0,0,0,0,0,0,0,0,0,0
0,0,0,0,0,0,0,0,0,0,0,0,0,0,0,0,0,0,0,0,0,0,0,0,0,0,0,0,0
0,0,0,0,0,0,0,0,0,0,0,0,0,0,0,0,0,0,0,0,0,0,0,0,0,0,0,0,0
0,0,0,0,0,0,0,0,0,0,0,0,0,0,0,0,0,0,0,0,0,0,0,0,0,0,0,0,0
0,0,0,0,0,0,0,0,0,0,0,0,0,0,0,0,0,0,0,0,0,0,0,0,0,0,0,0,0
0,0,0,0,0,0,0,0,0,0,0,0,0,0,0,0,0,0,0,0,0,0,0,0,0,0,0,0,0
0,0,0,0,0,0,0,0,0,0,0,0,0,0,0,0,0,0,0,0,0,0,0,0,0,0,0,0,0
0,0,0,0,0,0,0,0,0,0,0,0,0,0,0,0,0,0,0,0,0,0,0,0,0,0,0,0,0
0,0,0,0,0,0,0,0,0,0,0,0,0,0,0,0,0,0,0,0,0,0,0,0,0,0,0,0,0
0,0,0,0,0,0,0,0,0,0,0,0,0,0,0,0,0,0,0,0,0,0,0,0,0,0,0,0,0
0,0,0,0,0,0,0,0,0,0,0,0,0,0,0,0,0,0,0,0,0,0,0,0,0,0,0,0,0
0,0,0,0,0,0,0,0,0,0,0,0,0,0,0,0,0,0,0,0,0,0,0,0,0,0,0,0,0
0,0,0,0,0,0,0,0,0,0,0,0,0,0,0,0,0,0,0,0,0,0,0,0,0,0,0,0,0
0,0,0,0,0,0,0,0,0,0,0,0,0,0,0,0,0,0,0,0,0,0,0,0,0,0,0,0,0
0,0,0,0,0,0,0,0,0,0,0,0,0,0,0,0,0,0,0,0,0,0,0,0,0,0,0,0,0
0,0,0,0,0,0,0,0,0,0,0,0,0,0,0,0,0,0,0,0,0,0,0,0,0,0,0,0,0
0,0,0,0,0,0,0,0,0,0,0,0,0,0,0,0,0,0,0,0,0,0,0,0,0,0,0,0,0
0,0,0,0,0,0,0,0,0,0,0,0,0,0,0,0,0,0,0,0,0,0,0,0,0,0,0,0,0
0,0,0,0,0,0,0,0,0,0,0,0,0,0,0,0,0,0,0,0,0,0,0,0,0,0,0,0,0
:endlayer

#### RULES ####
rule:
plugin=vanillaBlocks
number=1
data:
JSON:{blockState:{blockName:"minecraft:dirt",properties:{variant:"dirt",snowy:"false"}}}
:enddata
:endrule

rule:
plugin=vanillaBlocks
number=2
data:
JSON:{blockState:{blockName:"minecraft:stone",properties:{variant:"stone"}}}
:enddata
:endrule

rule:
plugin=vanillaBlocks
number=3
data:
JSON:{blockState:{blockName:"minecraft:cobblestone"}}
:enddata
:endrule

rule:
plugin=vanillaBlocks
number=4
data:
JSON:{blockState:{blockName:"minecraft:netherrack"}}
:enddata
:endrule

rule:
plugin=vanillaBlocks
number=5
data:
JSON:{blockState:{blockName:"minecraft:mossy_cobblestone"}}
:enddata
:endrule

rule:
plugin=vanillaBlocks
number=6
data:
JSON:{blockState:{blockName:"minecraft:stone_stairs",properties:{half:"bottom",shape:"straight",facing:"west"}}}
:enddata
:endrule

rule:
plugin=blockTile
number=7
data:
JSON:{blockState:{blockName:"ancientwarfarestructure:advanced_spawner",properties:{transparent:"true"}},teData:{id:"ancientwarfarestructure:advanced_spawner_tile",spawnerSettings:{minDelay:0,spawnDelay:0,lightSensitive:0b,spawnGroups:[{settingsList:[{remainingSpawnCount:1,hostile:1b,forced:1b,customTag:{factionName:"orc"},maxToSpawn:1,entityId:"ancientwarfarenpc:faction.soldier",minToSpawn:1}],groupWeight:1}],playerRange:2,respondToRedstone:0b,inventory:{Size:9,Items:[]},spawnRange:0,transparent:1b,maxDelay:0,xpToDrop:0,mobRange:0,debugMode:0b,maxNearbyMonsters:0}}}
:enddata
:endrule

rule:
plugin=blockTile
number=8
data:
JSON:{blockState:{blockName:"ancientwarfarestructure:advanced_spawner",properties:{transparent:"true"}},teData:{id:"ancientwarfarestructure:advanced_spawner_tile",spawnerSettings:{minDelay:0,spawnDelay:0,lightSensitive:0b,spawnGroups:[{settingsList:[{remainingSpawnCount:1,hostile:1b,forced:1b,customTag:{factionName:"orc"},maxToSpawn:1,entityId:"ancientwarfarenpc:faction.soldier",minToSpawn:1}],groupWeight:1}],playerRange:2,respondToRedstone:0b,inventory:{Size:9,Items:[]},spawnRange:0,transparent:1b,maxDelay:0,xpToDrop:0,mobRange:0,debugMode:0b,maxNearbyMonsters:0}}}
:enddata
:endrule

rule:
plugin=blockTile
number=9
data:
JSON:{blockState:{blockName:"ancientwarfarestructure:advanced_spawner",properties:{transparent:"true"}},teData:{id:"ancientwarfarestructure:advanced_spawner_tile",spawnerSettings:{minDelay:0,spawnDelay:0,lightSensitive:0b,spawnGroups:[{settingsList:[{remainingSpawnCount:1,hostile:1b,forced:1b,customTag:{factionName:"orc"},maxToSpawn:1,entityId:"ancientwarfarenpc:faction.soldier",minToSpawn:1}],groupWeight:1}],playerRange:2,respondToRedstone:0b,inventory:{Size:9,Items:[]},spawnRange:0,transparent:1b,maxDelay:0,xpToDrop:0,mobRange:0,debugMode:0b,maxNearbyMonsters:0}}}
:enddata
:endrule

rule:
plugin=blockTile
number=10
data:
JSON:{blockState:{blockName:"ancientwarfarestructure:advanced_spawner",properties:{transparent:"true"}},teData:{id:"ancientwarfarestructure:advanced_spawner_tile",spawnerSettings:{minDelay:0,spawnDelay:0,lightSensitive:0b,spawnGroups:[{settingsList:[{remainingSpawnCount:1,hostile:1b,forced:1b,customTag:{factionName:"orc"},maxToSpawn:1,entityId:"ancientwarfarenpc:faction.soldier",minToSpawn:1}],groupWeight:1}],playerRange:3,respondToRedstone:0b,inventory:{Size:9,Items:[]},spawnRange:0,transparent:1b,maxDelay:0,xpToDrop:0,mobRange:0,debugMode:0b,maxNearbyMonsters:0}}}
:enddata
:endrule

rule:
plugin=blockTile
number=11
data:
JSON:{blockState:{blockName:"ancientwarfarestructure:advanced_spawner",properties:{transparent:"true"}},teData:{id:"ancientwarfarestructure:advanced_spawner_tile",spawnerSettings:{minDelay:0,spawnDelay:0,lightSensitive:0b,spawnGroups:[{settingsList:[{remainingSpawnCount:1,hostile:1b,forced:1b,customTag:{factionName:"orc"},maxToSpawn:1,entityId:"ancientwarfarenpc:faction.soldier",minToSpawn:1}],groupWeight:1}],playerRange:3,respondToRedstone:0b,inventory:{Size:9,Items:[]},spawnRange:0,transparent:1b,maxDelay:0,xpToDrop:0,mobRange:0,debugMode:0b,maxNearbyMonsters:0}}}
:enddata
:endrule

rule:
plugin=vanillaBlocks
number=12
data:
JSON:{blockState:{blockName:"minecraft:stone_pressure_plate",properties:{powered:"false"}}}
:enddata
:endrule

rule:
plugin=inventory
number=13
data:
JSON:{blockState:{blockName:"minecraft:chest",properties:{facing:"north"}},lootLevel:0,teData:{ForgeData:{},Items:[{Slot:0b,id:"minecraft:redstone",Count:1b,Damage:0s},{Slot:1b,id:"minecraft:redstone",Count:1b,Damage:0s},{Slot:2b,id:"minecraft:redstone",Count:1b,Damage:0s},{Slot:3b,id:"minecraft:redstone",Count:1b,Damage:0s},{Slot:4b,id:"minecraft:redstone",Count:2b,Damage:0s},{Slot:5b,id:"minecraft:redstone",Count:2b,Damage:0s},{Slot:6b,id:"minecraft:redstone",Count:1b,Damage:0s},{Slot:7b,id:"minecraft:redstone",Count:1b,Damage:0s},{Slot:8b,id:"minecraft:redstone",Count:1b,Damage:0s},{Slot:9b,id:"minecraft:redstone",Count:1b,Damage:0s},{Slot:10b,id:"minecraft:redstone",Count:4b,Damage:0s},{Slot:11b,id:"minecraft:redstone",Count:2b,Damage:0s},{Slot:13b,id:"minecraft:redstone",Count:32b,Damage:0s},{Slot:14b,id:"minecraft:redstone",Count:1b,Damage:0s},{Slot:15b,id:"minecraft:redstone",Count:1b,Damage:0s},{Slot:16b,id:"minecraft:redstone",Count:1b,Damage:0s},{Slot:17b,id:"minecraft:redstone",Count:1b,Damage:0s},{Slot:18b,id:"minecraft:redstone",Count:1b,Damage:0s},{Slot:19b,id:"minecraft:redstone",Count:1b,Damage:0s},{Slot:20b,id:"minecraft:redstone",Count:1b,Damage:0s},{Slot:21b,id:"minecraft:redstone",Count:2b,Damage:0s},{Slot:22b,id:"minecraft:redstone",Count:2b,Damage:0s},{Slot:23b,id:"minecraft:redstone",Count:2b,Damage:0s},{Slot:25b,id:"minecraft:redstone",Count:1b,Damage:0s}],id:"minecraft:chest",Lock:""},inventoryData:{length:24,inventoryContents:[{id:"minecraft:redstone",Count:1b,slot:0,Damage:0s},{id:"minecraft:redstone",Count:1b,slot:1,Damage:0s},{id:"minecraft:redstone",Count:1b,slot:2,Damage:0s},{id:"minecraft:redstone",Count:1b,slot:3,Damage:0s},{id:"minecraft:redstone",Count:2b,slot:4,Damage:0s},{id:"minecraft:redstone",Count:2b,slot:5,Damage:0s},{id:"minecraft:redstone",Count:1b,slot:6,Damage:0s},{id:"minecraft:redstone",Count:1b,slot:7,Damage:0s},{id:"minecraft:redstone",Count:1b,slot:8,Damage:0s},{id:"minecraft:redstone",Count:1b,slot:9,Damage:0s},{id:"minecraft:redstone",Count:4b,slot:10,Damage:0s},{id:"minecraft:redstone",Count:2b,slot:11,Damage:0s},{id:"minecraft:redstone",Count:32b,slot:12,Damage:0s},{id:"minecraft:redstone",Count:1b,slot:13,Damage:0s},{id:"minecraft:redstone",Count:1b,slot:14,Damage:0s},{id:"minecraft:redstone",Count:1b,slot:15,Damage:0s},{id:"minecraft:redstone",Count:1b,slot:16,Damage:0s},{id:"minecraft:redstone",Count:1b,slot:17,Damage:0s},{id:"minecraft:redstone",Count:1b,slot:18,Damage:0s},{id:"minecraft:redstone",Count:1b,slot:19,Damage:0s},{id:"minecraft:redstone",Count:2b,slot:20,Damage:0s},{id:"minecraft:redstone",Count:2b,slot:21,Damage:0s},{id:"minecraft:redstone",Count:2b,slot:22,Damage:0s},{id:"minecraft:redstone",Count:1b,slot:23,Damage:0s}]},legacyFeatures:1b}
:enddata
:endrule

rule:
plugin=vanillaBlocks
number=14
data:
JSON:{blockState:{blockName:"minecraft:cauldron",properties:{level:"3"}}}
:enddata
:endrule

rule:
plugin=blockTile
number=15
data:
JSON:{blockState:{blockName:"ancientwarfarestructure:advanced_spawner",properties:{transparent:"true"}},teData:{id:"ancientwarfarestructure:advanced_spawner_tile",spawnerSettings:{minDelay:0,spawnDelay:0,lightSensitive:0b,spawnGroups:[{settingsList:[{remainingSpawnCount:1,hostile:1b,forced:1b,customTag:{factionName:"orc"},maxToSpawn:1,entityId:"ancientwarfarenpc:faction.soldier",minToSpawn:1}],groupWeight:1}],playerRange:6,respondToRedstone:0b,inventory:{Size:9,Items:[]},spawnRange:0,transparent:1b,maxDelay:0,xpToDrop:0,mobRange:0,debugMode:0b,maxNearbyMonsters:0}}}
:enddata
:endrule

rule:
plugin=vanillaBlocks
number=16
data:
JSON:{blockState:{blockName:"minecraft:planks",properties:{variant:"dark_oak"}}}
:enddata
:endrule

rule:
plugin=inventory
number=17
data:
JSON:{blockState:{blockName:"minecraft:chest",properties:{facing:"east"}},lootLevel:0,teData:{ForgeData:{},Items:[{Slot:3b,id:"minecraft:blaze_powder",Count:4b,Damage:0s},{Slot:6b,id:"minecraft:nether_wart",Count:4b,Damage:0s},{Slot:7b,id:"minecraft:nether_wart",Count:4b,Damage:0s},{Slot:10b,id:"minecraft:blaze_rod",Count:3b,Damage:0s},{Slot:13b,id:"minecraft:magma_cream",Count:4b,Damage:0s},{Slot:15b,id:"minecraft:nether_wart",Count:3b,Damage:0s},{Slot:17b,id:"minecraft:ghast_tear",Count:1b,Damage:0s},{Slot:18b,id:"minecraft:fermented_spider_eye",Count:10b,Damage:0s},{Slot:25b,id:"minecraft:speckled_melon",Count:6b,Damage:0s}],id:"minecraft:chest",Lock:""},inventoryData:{length:9,inventoryContents:[{id:"minecraft:blaze_powder",Count:4b,slot:0,Damage:0s},{id:"minecraft:nether_wart",Count:4b,slot:1,Damage:0s},{id:"minecraft:nether_wart",Count:4b,slot:2,Damage:0s},{id:"minecraft:blaze_rod",Count:3b,slot:3,Damage:0s},{id:"minecraft:magma_cream",Count:4b,slot:4,Damage:0s},{id:"minecraft:nether_wart",Count:3b,slot:5,Damage:0s},{id:"minecraft:ghast_tear",Count:1b,slot:6,Damage:0s},{id:"minecraft:fermented_spider_eye",Count:10b,slot:7,Damage:0s},{id:"minecraft:speckled_melon",Count:6b,slot:8,Damage:0s}]},legacyFeatures:1b}
:enddata
:endrule

rule:
plugin=vanillaBlocks
number=18
data:
JSON:{blockState:{blockName:"minecraft:wooden_slab",properties:{half:"bottom",variant:"oak"}}}
:enddata
:endrule

rule:
plugin=blockTile
number=19
data:
JSON:{blockState:{blockName:"ancientwarfarestructure:advanced_spawner",properties:{transparent:"true"}},teData:{id:"ancientwarfarestructure:advanced_spawner_tile",spawnerSettings:{minDelay:0,spawnDelay:0,lightSensitive:0b,spawnGroups:[{settingsList:[{remainingSpawnCount:1,hostile:1b,forced:1b,customTag:{factionName:"orc"},maxToSpawn:1,entityId:"ancientwarfarenpc:faction.soldier",minToSpawn:1}],groupWeight:1}],playerRange:3,respondToRedstone:0b,inventory:{Size:9,Items:[]},spawnRange:0,transparent:1b,maxDelay:0,xpToDrop:0,mobRange:0,debugMode:0b,maxNearbyMonsters:0}}}
:enddata
:endrule

rule:
plugin=vanillaBlocks
number=20
data:
JSON:{blockState:{blockName:"minecraft:nether_brick_fence",properties:{east:"false",south:"false",north:"false",west:"false"}}}
:enddata
:endrule

rule:
plugin=vanillaBlocks
number=21
data:
JSON:{blockState:{blockName:"minecraft:stone_slab",properties:{half:"bottom",variant:"cobblestone"}}}
:enddata
:endrule

rule:
plugin=blockTile
number=22
data:
JSON:{blockState:{blockName:"ancientwarfarestructure:advanced_spawner",properties:{transparent:"true"}},teData:{id:"ancientwarfarestructure:advanced_spawner_tile",spawnerSettings:{minDelay:0,spawnDelay:0,lightSensitive:0b,spawnGroups:[{settingsList:[{remainingSpawnCount:1,hostile:1b,forced:1b,customTag:{factionName:"orc"},maxToSpawn:1,entityId:"ancientwarfarenpc:faction.priest",minToSpawn:1}],groupWeight:1}],playerRange:6,respondToRedstone:0b,inventory:{Size:9,Items:[]},spawnRange:0,transparent:1b,maxDelay:0,xpToDrop:0,mobRange:0,debugMode:0b,maxNearbyMonsters:0}}}
:enddata
:endrule

rule:
plugin=vanillaBlocks
number=23
data:
JSON:{blockState:{blockName:"minecraft:bookshelf"}}
:enddata
:endrule

rule:
plugin=blockTile
number=24
data:
JSON:{blockState:{blockName:"ancientwarfarestructure:advanced_spawner",properties:{transparent:"true"}},teData:{id:"ancientwarfarestructure:advanced_spawner_tile",spawnerSettings:{minDelay:0,spawnDelay:0,lightSensitive:0b,spawnGroups:[{settingsList:[{remainingSpawnCount:1,hostile:1b,forced:1b,customTag:{factionName:"orc"},maxToSpawn:1,entityId:"ancientwarfarenpc:faction.leader.elite",minToSpawn:1}],groupWeight:1}],playerRange:6,respondToRedstone:0b,inventory:{Size:9,Items:[]},spawnRange:0,transparent:1b,maxDelay:0,xpToDrop:0,mobRange:0,debugMode:0b,maxNearbyMonsters:0}}}
:enddata
:endrule

rule:
plugin=vanillaBlocks
number=25
data:
JSON:{blockState:{blockName:"minecraft:fire",properties:{east:"false",south:"false",north:"false",west:"false",up:"false",age:"15"}}}
:enddata
:endrule

rule:
plugin=blockTile
number=26
data:
JSON:{blockState:{blockName:"ancientwarfarestructure:advanced_spawner",properties:{transparent:"true"}},teData:{id:"ancientwarfarestructure:advanced_spawner_tile",spawnerSettings:{minDelay:0,spawnDelay:0,lightSensitive:0b,spawnGroups:[{settingsList:[{remainingSpawnCount:1,hostile:1b,forced:1b,customTag:{factionName:"orc"},maxToSpawn:1,entityId:"ancientwarfarenpc:faction.priest",minToSpawn:1}],groupWeight:1}],playerRange:6,respondToRedstone:0b,inventory:{Size:9,Items:[]},spawnRange:0,transparent:1b,maxDelay:0,xpToDrop:0,mobRange:0,debugMode:0b,maxNearbyMonsters:0}}}
:enddata
:endrule

rule:
plugin=blockTile
number=27
data:
JSON:{blockState:{blockName:"ancientwarfarestructure:advanced_spawner",properties:{transparent:"true"}},teData:{id:"ancientwarfarestructure:advanced_spawner_tile",spawnerSettings:{minDelay:0,spawnDelay:0,lightSensitive:0b,spawnGroups:[{settingsList:[{remainingSpawnCount:1,hostile:1b,forced:1b,customTag:{factionName:"orc"},maxToSpawn:1,entityId:"ancientwarfarenpc:faction.priest",minToSpawn:1}],groupWeight:1}],playerRange:6,respondToRedstone:0b,inventory:{Size:9,Items:[]},spawnRange:0,transparent:1b,maxDelay:0,xpToDrop:0,mobRange:0,debugMode:0b,maxNearbyMonsters:0}}}
:enddata
:endrule

rule:
plugin=blockTile
number=28
data:
JSON:{blockState:{blockName:"minecraft:enchanting_table"},teData:{id:"minecraft:enchanting_table"}}
:enddata
:endrule

rule:
plugin=blockTile
number=29
data:
JSON:{blockState:{blockName:"ancientwarfarestructure:advanced_spawner",properties:{transparent:"true"}},teData:{id:"ancientwarfarestructure:advanced_spawner_tile",spawnerSettings:{minDelay:0,spawnDelay:0,lightSensitive:0b,spawnGroups:[{settingsList:[{remainingSpawnCount:1,hostile:1b,forced:1b,customTag:{factionName:"orc"},maxToSpawn:1,entityId:"ancientwarfarenpc:faction.soldier",minToSpawn:1}],groupWeight:1}],playerRange:5,respondToRedstone:0b,inventory:{Size:9,Items:[]},spawnRange:0,transparent:1b,maxDelay:0,xpToDrop:0,mobRange:0,debugMode:0b,maxNearbyMonsters:0}}}
:enddata
:endrule

rule:
plugin=vanillaBlocks
number=30
data:
JSON:{blockState:{blockName:"minecraft:stone_stairs",properties:{half:"bottom",shape:"straight",facing:"south"}}}
:enddata
:endrule

rule:
plugin=vanillaBlocks
number=31
data:
JSON:{blockState:{blockName:"minecraft:stone_stairs",properties:{half:"bottom",shape:"straight",facing:"north"}}}
:enddata
:endrule

rule:
plugin=inventory
number=32
data:
JSON:{blockState:{blockName:"minecraft:chest",properties:{facing:"east"}},lootLevel:0,teData:{ForgeData:{},Items:[{Slot:0b,id:"minecraft:nether_wart",Count:7b,Damage:0s},{Slot:1b,id:"minecraft:nether_wart",Count:11b,Damage:0s},{Slot:3b,id:"minecraft:blaze_powder",Count:1b,Damage:0s},{Slot:7b,id:"minecraft:fermented_spider_eye",Count:5b,Damage:0s},{Slot:8b,id:"minecraft:fermented_spider_eye",Count:9b,Damage:0s},{Slot:11b,id:"minecraft:blaze_powder",Count:2b,Damage:0s},{Slot:12b,id:"minecraft:blaze_powder",Count:2b,Damage:0s},{Slot:17b,id:"minecraft:magma_cream",Count:4b,Damage:0s},{Slot:18b,id:"minecraft:speckled_melon",Count:6b,Damage:0s},{Slot:21b,id:"minecraft:ghast_tear",Count:1b,Damage:0s},{Slot:23b,id:"ancientwarfarenpc:coin",Count:10b,tag:{metal:"gold"},Damage:0s},{Slot:24b,id:"ancientwarfarenpc:coin",Count:16b,tag:{metal:"silver"},Damage:0s},{Slot:25b,id:"ancientwarfarenpc:coin",Count:32b,tag:{metal:"copper"},Damage:0s}],id:"minecraft:chest",Lock:""},inventoryData:{length:13,inventoryContents:[{id:"minecraft:nether_wart",Count:7b,slot:0,Damage:0s},{id:"minecraft:nether_wart",Count:11b,slot:1,Damage:0s},{id:"minecraft:blaze_powder",Count:1b,slot:2,Damage:0s},{id:"minecraft:fermented_spider_eye",Count:5b,slot:3,Damage:0s},{id:"minecraft:fermented_spider_eye",Count:9b,slot:4,Damage:0s},{id:"minecraft:blaze_powder",Count:2b,slot:5,Damage:0s},{id:"minecraft:blaze_powder",Count:2b,slot:6,Damage:0s},{id:"minecraft:magma_cream",Count:4b,slot:7,Damage:0s},{id:"minecraft:speckled_melon",Count:6b,slot:8,Damage:0s},{id:"minecraft:ghast_tear",Count:1b,slot:9,Damage:0s},{id:"ancientwarfarenpc:coin",Count:10b,tag:{metal:"gold"},slot:10,Damage:0s},{id:"ancientwarfarenpc:coin",Count:16b,tag:{metal:"silver"},slot:11,Damage:0s},{id:"ancientwarfarenpc:coin",Count:32b,tag:{metal:"copper"},slot:12,Damage:0s}]},legacyFeatures:1b}
:enddata
:endrule

rule:
plugin=inventory
number=33
data:
JSON:{blockState:{blockName:"minecraft:chest",properties:{facing:"east"}},lootLevel:0,teData:{ForgeData:{},Items:[{Slot:0b,id:"minecraft:poisonous_potato",Count:3b,Damage:0s},{Slot:1b,id:"minecraft:brown_mushroom",Count:7b,Damage:0s},{Slot:2b,id:"minecraft:red_mushroom",Count:5b,Damage:0s},{Slot:3b,id:"minecraft:rotten_flesh",Count:3b,Damage:0s},{Slot:4b,id:"minecraft:rotten_flesh",Count:2b,Damage:0s},{Slot:5b,id:"minecraft:bone",Count:5b,Damage:0s},{Slot:6b,id:"minecraft:gunpowder",Count:3b,Damage:0s},{Slot:7b,id:"minecraft:bone",Count:8b,Damage:0s},{Slot:8b,id:"ancientwarfarenpc:coin",Count:25b,tag:{metal:"copper"},Damage:0s},{Slot:9b,id:"minecraft:poisonous_potato",Count:6b,Damage:0s},{Slot:10b,id:"minecraft:poisonous_potato",Count:4b,Damage:0s},{Slot:11b,id:"minecraft:gold_nugget",Count:4b,Damage:0s},{Slot:12b,id:"minecraft:rotten_flesh",Count:5b,Damage:0s},{Slot:13b,id:"minecraft:rotten_flesh",Count:3b,Damage:0s},{Slot:14b,id:"minecraft:red_mushroom",Count:5b,Damage:0s},{Slot:15b,id:"minecraft:bone",Count:1b,Damage:0s},{Slot:16b,id:"minecraft:spider_eye",Count:4b,Damage:0s},{Slot:17b,id:"minecraft:coal",Count:5b,Damage:0s},{Slot:18b,id:"minecraft:poisonous_potato",Count:2b,Damage:0s},{Slot:19b,id:"minecraft:poisonous_potato",Count:3b,Damage:0s},{Slot:20b,id:"minecraft:rotten_flesh",Count:2b,Damage:0s},{Slot:21b,id:"minecraft:rotten_flesh",Count:4b,Damage:0s},{Slot:22b,id:"minecraft:rotten_flesh",Count:2b,Damage:0s},{Slot:23b,id:"minecraft:feather",Count:4b,Damage:0s},{Slot:24b,id:"minecraft:dye",Count:4b,Damage:4s},{Slot:25b,id:"minecraft:bone",Count:1b,Damage:0s},{Slot:26b,id:"minecraft:flint",Count:5b,Damage:0s}],id:"minecraft:chest",Lock:""},inventoryData:{length:27,inventoryContents:[{id:"minecraft:poisonous_potato",Count:3b,slot:0,Damage:0s},{id:"minecraft:brown_mushroom",Count:7b,slot:1,Damage:0s},{id:"minecraft:red_mushroom",Count:5b,slot:2,Damage:0s},{id:"minecraft:rotten_flesh",Count:3b,slot:3,Damage:0s},{id:"minecraft:rotten_flesh",Count:2b,slot:4,Damage:0s},{id:"minecraft:bone",Count:5b,slot:5,Damage:0s},{id:"minecraft:gunpowder",Count:3b,slot:6,Damage:0s},{id:"minecraft:bone",Count:8b,slot:7,Damage:0s},{id:"ancientwarfarenpc:coin",Count:25b,tag:{metal:"copper"},slot:8,Damage:0s},{id:"minecraft:poisonous_potato",Count:6b,slot:9,Damage:0s},{id:"minecraft:poisonous_potato",Count:4b,slot:10,Damage:0s},{id:"minecraft:gold_nugget",Count:4b,slot:11,Damage:0s},{id:"minecraft:rotten_flesh",Count:5b,slot:12,Damage:0s},{id:"minecraft:rotten_flesh",Count:3b,slot:13,Damage:0s},{id:"minecraft:red_mushroom",Count:5b,slot:14,Damage:0s},{id:"minecraft:bone",Count:1b,slot:15,Damage:0s},{id:"minecraft:spider_eye",Count:4b,slot:16,Damage:0s},{id:"minecraft:coal",Count:5b,slot:17,Damage:0s},{id:"minecraft:poisonous_potato",Count:2b,slot:18,Damage:0s},{id:"minecraft:poisonous_potato",Count:3b,slot:19,Damage:0s},{id:"minecraft:rotten_flesh",Count:2b,slot:20,Damage:0s},{id:"minecraft:rotten_flesh",Count:4b,slot:21,Damage:0s},{id:"minecraft:rotten_flesh",Count:2b,slot:22,Damage:0s},{id:"minecraft:feather",Count:4b,slot:23,Damage:0s},{id:"minecraft:dye",Count:4b,slot:24,Damage:4s},{id:"minecraft:bone",Count:1b,slot:25,Damage:0s},{id:"minecraft:flint",Count:5b,slot:26,Damage:0s}]},legacyFeatures:1b}
:enddata
:endrule

rule:
plugin=inventory
number=34
data:
JSON:{blockState:{blockName:"minecraft:chest",properties:{facing:"east"}},lootLevel:0,teData:{Items:[],id:"minecraft:chest",Lock:""},inventoryData:{length:0,inventoryContents:[]},legacyFeatures:1b}
:enddata
:endrule

rule:
plugin=inventory
number=35
data:
JSON:{blockState:{blockName:"minecraft:chest",properties:{facing:"east"}},lootLevel:0,teData:{ForgeData:{},Items:[{Slot:0b,id:"minecraft:gold_nugget",Count:6b,Damage:0s},{Slot:3b,id:"minecraft:spider_eye",Count:6b,Damage:0s},{Slot:5b,id:"minecraft:poisonous_potato",Count:3b,Damage:0s},{Slot:6b,id:"minecraft:red_mushroom",Count:4b,Damage:0s},{Slot:7b,id:"minecraft:rotten_flesh",Count:2b,Damage:0s},{Slot:8b,id:"minecraft:rotten_flesh",Count:2b,Damage:0s},{Slot:10b,id:"minecraft:flint",Count:6b,Damage:0s},{Slot:11b,id:"minecraft:slime_ball",Count:5b,Damage:0s},{Slot:12b,id:"minecraft:coal",Count:7b,Damage:0s},{Slot:13b,id:"minecraft:feather",Count:6b,Damage:0s},{Slot:14b,id:"minecraft:poisonous_potato",Count:2b,Damage:0s},{Slot:15b,id:"minecraft:poisonous_potato",Count:2b,Damage:0s},{Slot:16b,id:"minecraft:rotten_flesh",Count:2b,Damage:0s},{Slot:17b,id:"minecraft:brown_mushroom",Count:5b,Damage:0s},{Slot:18b,id:"minecraft:stick",Count:5b,Damage:0s},{Slot:20b,id:"minecraft:slime_ball",Count:2b,Damage:0s},{Slot:22b,id:"minecraft:rotten_flesh",Count:1b,Damage:0s},{Slot:23b,id:"minecraft:rotten_flesh",Count:4b,Damage:0s},{Slot:24b,id:"minecraft:poisonous_potato",Count:2b,Damage:0s},{Slot:25b,id:"minecraft:dye",Count:6b,Damage:4s},{Slot:26b,id:"minecraft:gunpowder",Count:5b,Damage:0s}],id:"minecraft:chest",Lock:""},inventoryData:{length:21,inventoryContents:[{id:"minecraft:gold_nugget",Count:6b,slot:0,Damage:0s},{id:"minecraft:spider_eye",Count:6b,slot:1,Damage:0s},{id:"minecraft:poisonous_potato",Count:3b,slot:2,Damage:0s},{id:"minecraft:red_mushroom",Count:4b,slot:3,Damage:0s},{id:"minecraft:rotten_flesh",Count:2b,slot:4,Damage:0s},{id:"minecraft:rotten_flesh",Count:2b,slot:5,Damage:0s},{id:"minecraft:flint",Count:6b,slot:6,Damage:0s},{id:"minecraft:slime_ball",Count:5b,slot:7,Damage:0s},{id:"minecraft:coal",Count:7b,slot:8,Damage:0s},{id:"minecraft:feather",Count:6b,slot:9,Damage:0s},{id:"minecraft:poisonous_potato",Count:2b,slot:10,Damage:0s},{id:"minecraft:poisonous_potato",Count:2b,slot:11,Damage:0s},{id:"minecraft:rotten_flesh",Count:2b,slot:12,Damage:0s},{id:"minecraft:brown_mushroom",Count:5b,slot:13,Damage:0s},{id:"minecraft:stick",Count:5b,slot:14,Damage:0s},{id:"minecraft:slime_ball",Count:2b,slot:15,Damage:0s},{id:"minecraft:rotten_flesh",Count:1b,slot:16,Damage:0s},{id:"minecraft:rotten_flesh",Count:4b,slot:17,Damage:0s},{id:"minecraft:poisonous_potato",Count:2b,slot:18,Damage:0s},{id:"minecraft:dye",Count:6b,slot:19,Damage:4s},{id:"minecraft:gunpowder",Count:5b,slot:20,Damage:0s}]},legacyFeatures:1b}
:enddata
:endrule

rule:
plugin=inventory
number=36
data:
JSON:{blockState:{blockName:"minecraft:chest",properties:{facing:"east"}},lootLevel:0,teData:{ForgeData:{},Items:[{Slot:1b,id:"minecraft:gold_nugget",Count:5b,Damage:0s},{Slot:3b,id:"minecraft:flint",Count:5b,Damage:0s},{Slot:4b,id:"minecraft:gunpowder",Count:6b,Damage:0s},{Slot:5b,id:"minecraft:feather",Count:5b,Damage:0s},{Slot:7b,id:"minecraft:poisonous_potato",Count:2b,Damage:0s},{Slot:8b,id:"minecraft:dye",Count:5b,Damage:4s},{Slot:9b,id:"minecraft:coal",Count:6b,Damage:0s},{Slot:12b,id:"minecraft:rotten_flesh",Count:3b,Damage:0s},{Slot:13b,id:"minecraft:rotten_flesh",Count:5b,Damage:0s},{Slot:14b,id:"minecraft:rotten_flesh",Count:3b,Damage:0s},{Slot:15b,id:"minecraft:spider_eye",Count:4b,Damage:0s},{Slot:16b,id:"minecraft:poisonous_potato",Count:1b,Damage:0s},{Slot:17b,id:"minecraft:poisonous_potato",Count:6b,Damage:0s},{Slot:18b,id:"minecraft:stick",Count:7b,Damage:0s},{Slot:19b,id:"minecraft:slime_ball",Count:5b,Damage:0s},{Slot:21b,id:"minecraft:rotten_flesh",Count:2b,Damage:0s},{Slot:22b,id:"minecraft:rotten_flesh",Count:3b,Damage:0s},{Slot:23b,id:"minecraft:rotten_flesh",Count:5b,Damage:0s},{Slot:24b,id:"minecraft:red_mushroom",Count:5b,Damage:0s},{Slot:25b,id:"minecraft:poisonous_potato",Count:1b,Damage:0s},{Slot:26b,id:"minecraft:brown_mushroom",Count:5b,Damage:0s}],id:"minecraft:chest",Lock:""},inventoryData:{length:21,inventoryContents:[{id:"minecraft:gold_nugget",Count:5b,slot:0,Damage:0s},{id:"minecraft:flint",Count:5b,slot:1,Damage:0s},{id:"minecraft:gunpowder",Count:6b,slot:2,Damage:0s},{id:"minecraft:feather",Count:5b,slot:3,Damage:0s},{id:"minecraft:poisonous_potato",Count:2b,slot:4,Damage:0s},{id:"minecraft:dye",Count:5b,slot:5,Damage:4s},{id:"minecraft:coal",Count:6b,slot:6,Damage:0s},{id:"minecraft:rotten_flesh",Count:3b,slot:7,Damage:0s},{id:"minecraft:rotten_flesh",Count:5b,slot:8,Damage:0s},{id:"minecraft:rotten_flesh",Count:3b,slot:9,Damage:0s},{id:"minecraft:spider_eye",Count:4b,slot:10,Damage:0s},{id:"minecraft:poisonous_potato",Count:1b,slot:11,Damage:0s},{id:"minecraft:poisonous_potato",Count:6b,slot:12,Damage:0s},{id:"minecraft:stick",Count:7b,slot:13,Damage:0s},{id:"minecraft:slime_ball",Count:5b,slot:14,Damage:0s},{id:"minecraft:rotten_flesh",Count:2b,slot:15,Damage:0s},{id:"minecraft:rotten_flesh",Count:3b,slot:16,Damage:0s},{id:"minecraft:rotten_flesh",Count:5b,slot:17,Damage:0s},{id:"minecraft:red_mushroom",Count:5b,slot:18,Damage:0s},{id:"minecraft:poisonous_potato",Count:1b,slot:19,Damage:0s},{id:"minecraft:brown_mushroom",Count:5b,slot:20,Damage:0s}]},legacyFeatures:1b}
:enddata
:endrule

rule:
plugin=inventory
number=37
data:
JSON:{blockState:{blockName:"minecraft:brewing_stand",properties:{has_bottle_0:"false",has_bottle_1:"false",has_bottle_2:"false"}},lootLevel:0,teData:{Fuel:0b,Items:[],id:"minecraft:brewing_stand",BrewTime:0s,Lock:""},inventoryData:{length:0,inventoryContents:[]},legacyFeatures:0b}
:enddata
:endrule

rule:
plugin=vanillaBlocks
number=38
data:
JSON:{blockState:{blockName:"minecraft:redstone_torch",properties:{facing:"north"}}}
:enddata
:endrule

rule:
plugin=vanillaSkull
number=39
data:
JSON:{blockState:{blockName:"minecraft:skull",properties:{nodrop:"false",facing:"up"}},skullRotation:8,teData:{Rot:4b,id:"minecraft:skull",SkullType:0b}}
:enddata
:endrule

rule:
plugin=vanillaSkull
number=40
data:
JSON:{blockState:{blockName:"minecraft:skull",properties:{nodrop:"false",facing:"up"}},skullRotation:8,teData:{Rot:4b,id:"minecraft:skull",SkullType:0b}}
:enddata
:endrule

rule:
plugin=vanillaBlocks
number=41
data:
JSON:{blockState:{blockName:"minecraft:lit_pumpkin",properties:{facing:"south"}}}
:enddata
:endrule

rule:
plugin=vanillaBlocks
number=42
data:
JSON:{blockState:{blockName:"minecraft:torch",properties:{facing:"south"}}}
:enddata
:endrule

rule:
plugin=vanillaBlocks
number=43
data:
JSON:{blockState:{blockName:"minecraft:torch",properties:{facing:"west"}}}
:enddata
:endrule

rule:
plugin=vanillaBlocks
number=44
data:
JSON:{blockState:{blockName:"minecraft:stone_stairs",properties:{half:"top",shape:"straight",facing:"west"}}}
:enddata
:endrule

rule:
plugin=vanillaBlocks
number=45
data:
JSON:{blockState:{blockName:"minecraft:redstone_torch",properties:{facing:"south"}}}
:enddata
:endrule

rule:
plugin=vanillaBlocks
number=46
data:
JSON:{blockState:{blockName:"minecraft:stone_stairs",properties:{half:"top",shape:"straight",facing:"south"}}}
:enddata
:endrule

rule:
plugin=vanillaBlocks
number=47
data:
JSON:{blockState:{blockName:"minecraft:stone_stairs",properties:{half:"top",shape:"straight",facing:"east"}}}
:enddata
:endrule

rule:
plugin=vanillaBlocks
number=48
data:
JSON:{blockState:{blockName:"minecraft:stone_slab",properties:{half:"top",variant:"cobblestone"}}}
:enddata
:endrule

rule:
plugin=vanillaBlocks
number=49
data:
JSON:{blockState:{blockName:"minecraft:stone_stairs",properties:{half:"top",shape:"straight",facing:"north"}}}
:enddata
:endrule

rule:
plugin=vanillaBlocks
number=50
data:
JSON:{blockState:{blockName:"minecraft:obsidian"}}
:enddata
:endrule

rule:
plugin=blockTile
number=51
data:
JSON:{blockState:{blockName:"ancientwarfarestructure:advanced_spawner",properties:{transparent:"true"}},teData:{id:"ancientwarfarestructure:advanced_spawner_tile",spawnerSettings:{minDelay:0,spawnDelay:0,lightSensitive:0b,spawnGroups:[{settingsList:[{remainingSpawnCount:1,hostile:1b,forced:1b,customTag:{factionName:"orc"},maxToSpawn:1,entityId:"ancientwarfarenpc:faction.soldier",minToSpawn:1}],groupWeight:1}],playerRange:6,respondToRedstone:0b,inventory:{Size:9,Items:[]},spawnRange:0,transparent:1b,maxDelay:0,xpToDrop:0,mobRange:0,debugMode:0b,maxNearbyMonsters:0}}}
:enddata
:endrule

rule:
plugin=blockTile
number=52
data:
JSON:{blockState:{blockName:"ancientwarfarestructure:advanced_spawner",properties:{transparent:"true"}},teData:{id:"ancientwarfarestructure:advanced_spawner_tile",spawnerSettings:{minDelay:0,spawnDelay:0,lightSensitive:0b,spawnGroups:[{settingsList:[{remainingSpawnCount:1,hostile:1b,forced:1b,customTag:{factionName:"orc"},maxToSpawn:1,entityId:"ancientwarfarenpc:faction.soldier",minToSpawn:1}],groupWeight:1}],playerRange:6,respondToRedstone:0b,inventory:{Size:9,Items:[]},spawnRange:0,transparent:1b,maxDelay:0,xpToDrop:0,mobRange:0,debugMode:0b,maxNearbyMonsters:0}}}
:enddata
:endrule

rule:
plugin=blockTile
number=53
data:
JSON:{blockState:{blockName:"ancientwarfarestructure:advanced_spawner",properties:{transparent:"true"}},teData:{id:"ancientwarfarestructure:advanced_spawner_tile",spawnerSettings:{minDelay:0,spawnDelay:0,lightSensitive:0b,spawnGroups:[{settingsList:[{remainingSpawnCount:1,hostile:1b,forced:1b,customTag:{factionName:"orc"},maxToSpawn:1,entityId:"ancientwarfarenpc:faction.soldier",minToSpawn:1}],groupWeight:1}],playerRange:6,respondToRedstone:0b,inventory:{Size:9,Items:[]},spawnRange:0,transparent:1b,maxDelay:0,xpToDrop:0,mobRange:0,debugMode:0b,maxNearbyMonsters:0}}}
:enddata
:endrule

rule:
plugin=blockTile
number=54
data:
JSON:{blockState:{blockName:"ancientwarfarestructure:advanced_spawner",properties:{transparent:"true"}},teData:{id:"ancientwarfarestructure:advanced_spawner_tile",spawnerSettings:{minDelay:0,spawnDelay:0,lightSensitive:0b,spawnGroups:[{settingsList:[{remainingSpawnCount:1,hostile:1b,forced:1b,customTag:{factionName:"orc"},maxToSpawn:1,entityId:"ancientwarfarenpc:faction.soldier",minToSpawn:1}],groupWeight:1}],playerRange:6,respondToRedstone:0b,inventory:{Size:9,Items:[]},spawnRange:0,transparent:1b,maxDelay:0,xpToDrop:0,mobRange:0,debugMode:0b,maxNearbyMonsters:0}}}
:enddata
:endrule

rule:
plugin=blockTile
number=55
data:
JSON:{blockState:{blockName:"ancientwarfarestructure:advanced_spawner",properties:{transparent:"true"}},teData:{id:"ancientwarfarestructure:advanced_spawner_tile",spawnerSettings:{minDelay:0,spawnDelay:0,lightSensitive:0b,spawnGroups:[{settingsList:[{remainingSpawnCount:1,hostile:1b,forced:1b,customTag:{factionName:"orc"},maxToSpawn:1,entityId:"ancientwarfarenpc:faction.soldier",minToSpawn:1}],groupWeight:1}],playerRange:6,respondToRedstone:0b,inventory:{Size:9,Items:[]},spawnRange:0,transparent:1b,maxDelay:0,xpToDrop:0,mobRange:0,debugMode:0b,maxNearbyMonsters:0}}}
:enddata
:endrule

rule:
plugin=blockTile
number=56
data:
JSON:{blockState:{blockName:"ancientwarfarestructure:advanced_spawner",properties:{transparent:"true"}},teData:{id:"ancientwarfarestructure:advanced_spawner_tile",spawnerSettings:{minDelay:0,spawnDelay:0,lightSensitive:0b,spawnGroups:[{settingsList:[{remainingSpawnCount:1,hostile:1b,forced:1b,customTag:{factionName:"orc"},maxToSpawn:1,entityId:"ancientwarfarenpc:faction.soldier",minToSpawn:1}],groupWeight:1}],playerRange:6,respondToRedstone:0b,inventory:{Size:9,Items:[]},spawnRange:0,transparent:1b,maxDelay:0,xpToDrop:0,mobRange:0,debugMode:0b,maxNearbyMonsters:0}}}
:enddata
:endrule

rule:
plugin=blockTile
number=57
data:
JSON:{blockState:{blockName:"ancientwarfarestructure:advanced_spawner",properties:{transparent:"true"}},teData:{id:"ancientwarfarestructure:advanced_spawner_tile",spawnerSettings:{minDelay:0,spawnDelay:0,lightSensitive:0b,spawnGroups:[{settingsList:[{remainingSpawnCount:1,hostile:1b,forced:1b,customTag:{factionName:"orc"},maxToSpawn:1,entityId:"ancientwarfarenpc:faction.soldier",minToSpawn:1}],groupWeight:1}],playerRange:6,respondToRedstone:0b,inventory:{Size:9,Items:[]},spawnRange:0,transparent:1b,maxDelay:0,xpToDrop:0,mobRange:0,debugMode:0b,maxNearbyMonsters:0}}}
:enddata
:endrule

rule:
plugin=vanillaBlocks
number=58
data:
JSON:{blockState:{blockName:"minecraft:iron_bars",properties:{east:"false",south:"false",north:"false",west:"false"}}}
:enddata
:endrule

rule:
plugin=vanillaBlocks
number=59
data:
JSON:{blockState:{blockName:"minecraft:grass",properties:{snowy:"false"}}}
:enddata
:endrule

rule:
plugin=vanillaBlocks
number=60
data:
JSON:{blockState:{blockName:"minecraft:gravel"}}
:enddata
:endrule

rule:
plugin=vine
number=61
data:
JSON:{blockState:{blockName:"minecraft:vine",properties:{east:"false",south:"false",north:"false",west:"true",up:"false"}}}
:enddata
:endrule

rule:
plugin=blockTile
number=62
data:
JSON:{blockState:{blockName:"ancientwarfarestructure:advanced_spawner",properties:{transparent:"true"}},teData:{id:"ancientwarfarestructure:advanced_spawner_tile",spawnerSettings:{minDelay:0,spawnDelay:0,lightSensitive:0b,spawnGroups:[{settingsList:[{remainingSpawnCount:1,hostile:1b,forced:1b,customTag:{factionName:"orc"},maxToSpawn:1,entityId:"ancientwarfarenpc:faction.mounted_archer",minToSpawn:1}],groupWeight:1}],playerRange:16,respondToRedstone:0b,inventory:{Size:9,Items:[]},spawnRange:0,transparent:1b,maxDelay:0,xpToDrop:0,mobRange:0,debugMode:0b,maxNearbyMonsters:0}}}
:enddata
:endrule

rule:
plugin=vanillaBlocks
number=63
data:
JSON:{blockState:{blockName:"minecraft:tallgrass",properties:{type:"tall_grass"}}}
:enddata
:endrule

rule:
plugin=vanillaBlocks
number=64
data:
JSON:{blockState:{blockName:"minecraft:stonebrick",properties:{variant:"cracked_stonebrick"}}}
:enddata
:endrule

rule:
plugin=vine
number=65
data:
JSON:{blockState:{blockName:"minecraft:vine",properties:{east:"false",south:"false",north:"true",west:"false",up:"false"}}}
:enddata
:endrule

rule:
plugin=blockTile
number=66
data:
JSON:{blockState:{blockName:"ancientwarfarestructure:advanced_spawner",properties:{transparent:"true"}},teData:{id:"ancientwarfarestructure:advanced_spawner_tile",spawnerSettings:{minDelay:0,spawnDelay:0,lightSensitive:0b,spawnGroups:[{settingsList:[{remainingSpawnCount:1,hostile:1b,forced:1b,customTag:{factionName:"orc"},maxToSpawn:1,entityId:"ancientwarfarenpc:faction.mounted_archer",minToSpawn:1}],groupWeight:1}],playerRange:16,respondToRedstone:0b,inventory:{Size:9,Items:[]},spawnRange:0,transparent:1b,maxDelay:0,xpToDrop:0,mobRange:0,debugMode:0b,maxNearbyMonsters:0}}}
:enddata
:endrule

rule:
plugin=vine
number=67
data:
JSON:{blockState:{blockName:"minecraft:vine",properties:{east:"false",south:"true",north:"false",west:"false",up:"false"}}}
:enddata
:endrule

rule:
plugin=vine
number=68
data:
JSON:{blockState:{blockName:"minecraft:vine",properties:{east:"false",south:"false",north:"true",west:"true",up:"false"}}}
:enddata
:endrule

rule:
plugin=vine
number=69
data:
JSON:{blockState:{blockName:"minecraft:vine",properties:{east:"false",south:"true",north:"false",west:"true",up:"false"}}}
:enddata
:endrule

rule:
plugin=vanillaBlocks
number=70
data:
JSON:{blockState:{blockName:"minecraft:stone_slab",properties:{half:"bottom",variant:"stone_brick"}}}
:enddata
:endrule

rule:
plugin=vanillaBlocks
number=71
data:
JSON:{blockState:{blockName:"minecraft:stonebrick",properties:{variant:"stonebrick"}}}
:enddata
:endrule

rule:
plugin=vanillaBlocks
number=72
data:
JSON:{blockState:{blockName:"minecraft:stonebrick",properties:{variant:"mossy_stonebrick"}}}
:enddata
:endrule

rule:
plugin=vine
number=73
data:
JSON:{blockState:{blockName:"minecraft:vine",properties:{east:"true",south:"false",north:"false",west:"false",up:"false"}}}
:enddata
:endrule

rule:
plugin=vanillaBlocks
number=74
data:
JSON:{blockState:{blockName:"minecraft:stone_brick_stairs",properties:{half:"bottom",shape:"straight",facing:"south"}}}
:enddata
:endrule

rule:
plugin=blockTile
number=75
data:
JSON:{blockState:{blockName:"ancientwarfarestructure:advanced_spawner",properties:{transparent:"true"}},teData:{id:"ancientwarfarestructure:advanced_spawner_tile",spawnerSettings:{minDelay:0,spawnDelay:0,lightSensitive:0b,spawnGroups:[{settingsList:[{remainingSpawnCount:1,hostile:1b,forced:1b,customTag:{factionName:"orc"},maxToSpawn:1,entityId:"ancientwarfarenpc:faction.archer",minToSpawn:1}],groupWeight:1}],playerRange:16,respondToRedstone:0b,inventory:{Size:9,Items:[]},spawnRange:0,transparent:1b,maxDelay:0,xpToDrop:0,mobRange:0,debugMode:0b,maxNearbyMonsters:0}}}
:enddata
:endrule

rule:
plugin=blockTile
number=76
data:
JSON:{blockState:{blockName:"ancientwarfarestructure:advanced_spawner",properties:{transparent:"true"}},teData:{id:"ancientwarfarestructure:advanced_spawner_tile",spawnerSettings:{minDelay:0,spawnDelay:0,lightSensitive:0b,spawnGroups:[{settingsList:[{remainingSpawnCount:1,hostile:1b,forced:1b,customTag:{factionName:"orc"},maxToSpawn:1,entityId:"ancientwarfarenpc:faction.archer",minToSpawn:1}],groupWeight:1}],playerRange:16,respondToRedstone:0b,inventory:{Size:9,Items:[]},spawnRange:0,transparent:1b,maxDelay:0,xpToDrop:0,mobRange:0,debugMode:0b,maxNearbyMonsters:0}}}
:enddata
:endrule

rule:
plugin=vanillaBlocks
number=77
data:
JSON:{blockState:{blockName:"minecraft:stonebrick",properties:{variant:"chiseled_stonebrick"}}}
:enddata
:endrule

rule:
plugin=blockTile
number=78
data:
JSON:{blockState:{blockName:"ancientwarfarestructure:advanced_spawner",properties:{transparent:"true"}},teData:{id:"ancientwarfarestructure:advanced_spawner_tile",spawnerSettings:{minDelay:0,spawnDelay:0,lightSensitive:0b,spawnGroups:[{settingsList:[{remainingSpawnCount:1,hostile:1b,forced:1b,customTag:{factionName:"orc"},maxToSpawn:1,entityId:"ancientwarfarenpc:faction.soldier",minToSpawn:1}],groupWeight:1}],playerRange:16,respondToRedstone:0b,inventory:{Size:9,Items:[]},spawnRange:0,transparent:1b,maxDelay:0,xpToDrop:0,mobRange:0,debugMode:0b,maxNearbyMonsters:0}}}
:enddata
:endrule

rule:
plugin=blockTile
number=79
data:
JSON:{blockState:{blockName:"ancientwarfarestructure:advanced_spawner",properties:{transparent:"true"}},teData:{id:"ancientwarfarestructure:advanced_spawner_tile",spawnerSettings:{minDelay:0,spawnDelay:0,lightSensitive:0b,spawnGroups:[{settingsList:[{remainingSpawnCount:1,hostile:1b,forced:1b,customTag:{factionName:"orc"},maxToSpawn:1,entityId:"ancientwarfarenpc:faction.soldier",minToSpawn:1}],groupWeight:1}],playerRange:16,respondToRedstone:0b,inventory:{Size:9,Items:[]},spawnRange:0,transparent:1b,maxDelay:0,xpToDrop:0,mobRange:0,debugMode:0b,maxNearbyMonsters:0}}}
:enddata
:endrule

rule:
plugin=blockTile
number=80
data:
JSON:{blockState:{blockName:"ancientwarfarestructure:advanced_spawner",properties:{transparent:"true"}},teData:{id:"ancientwarfarestructure:advanced_spawner_tile",spawnerSettings:{minDelay:0,spawnDelay:0,lightSensitive:0b,spawnGroups:[{settingsList:[{remainingSpawnCount:1,hostile:1b,forced:1b,customTag:{factionName:"orc"},maxToSpawn:1,entityId:"ancientwarfarenpc:faction.soldier",minToSpawn:1}],groupWeight:1}],playerRange:16,respondToRedstone:0b,inventory:{Size:9,Items:[]},spawnRange:0,transparent:1b,maxDelay:0,xpToDrop:0,mobRange:0,debugMode:0b,maxNearbyMonsters:0}}}
:enddata
:endrule

rule:
plugin=blockTile
number=81
data:
JSON:{blockState:{blockName:"ancientwarfarestructure:advanced_spawner",properties:{transparent:"true"}},teData:{id:"ancientwarfarestructure:advanced_spawner_tile",spawnerSettings:{minDelay:0,spawnDelay:0,lightSensitive:0b,spawnGroups:[{settingsList:[{remainingSpawnCount:1,hostile:1b,forced:1b,customTag:{factionName:"orc"},maxToSpawn:1,entityId:"ancientwarfarenpc:faction.archer",minToSpawn:1}],groupWeight:1}],playerRange:16,respondToRedstone:0b,inventory:{Size:9,Items:[]},spawnRange:0,transparent:1b,maxDelay:0,xpToDrop:0,mobRange:0,debugMode:0b,maxNearbyMonsters:0}}}
:enddata
:endrule

rule:
plugin=blockTile
number=82
data:
JSON:{blockState:{blockName:"ancientwarfarestructure:advanced_spawner",properties:{transparent:"true"}},teData:{id:"ancientwarfarestructure:advanced_spawner_tile",spawnerSettings:{minDelay:0,spawnDelay:0,lightSensitive:0b,spawnGroups:[{settingsList:[{remainingSpawnCount:1,hostile:1b,forced:1b,customTag:{factionName:"orc"},maxToSpawn:1,entityId:"ancientwarfarenpc:faction.archer",minToSpawn:1}],groupWeight:1}],playerRange:16,respondToRedstone:0b,inventory:{Size:9,Items:[]},spawnRange:0,transparent:1b,maxDelay:0,xpToDrop:0,mobRange:0,debugMode:0b,maxNearbyMonsters:0}}}
:enddata
:endrule

rule:
plugin=vine
number=83
data:
JSON:{blockState:{blockName:"minecraft:vine",properties:{east:"true",south:"false",north:"true",west:"false",up:"false"}}}
:enddata
:endrule

rule:
plugin=vine
number=84
data:
JSON:{blockState:{blockName:"minecraft:vine",properties:{east:"true",south:"true",north:"true",west:"false",up:"false"}}}
:enddata
:endrule

rule:
plugin=vine
number=85
data:
JSON:{blockState:{blockName:"minecraft:vine",properties:{east:"true",south:"true",north:"false",west:"false",up:"false"}}}
:enddata
:endrule

rule:
plugin=blockTile
number=86
data:
JSON:{blockState:{blockName:"ancientwarfarestructure:advanced_spawner",properties:{transparent:"true"}},teData:{id:"ancientwarfarestructure:advanced_spawner_tile",spawnerSettings:{minDelay:0,spawnDelay:0,lightSensitive:0b,spawnGroups:[{settingsList:[{remainingSpawnCount:1,hostile:1b,forced:1b,customTag:{factionName:"orc"},maxToSpawn:1,entityId:"ancientwarfarenpc:faction.mounted_archer",minToSpawn:1}],groupWeight:1}],playerRange:16,respondToRedstone:0b,inventory:{Size:9,Items:[]},spawnRange:0,transparent:1b,maxDelay:0,xpToDrop:0,mobRange:0,debugMode:0b,maxNearbyMonsters:0}}}
:enddata
:endrule

rule:
plugin=blockTile
number=87
data:
JSON:{blockState:{blockName:"ancientwarfarestructure:advanced_spawner",properties:{transparent:"true"}},teData:{id:"ancientwarfarestructure:advanced_spawner_tile",spawnerSettings:{minDelay:0,spawnDelay:0,lightSensitive:0b,spawnGroups:[{settingsList:[{remainingSpawnCount:1,hostile:1b,forced:1b,customTag:{factionName:"orc"},maxToSpawn:1,entityId:"ancientwarfarenpc:faction.mounted_archer",minToSpawn:1}],groupWeight:1}],playerRange:16,respondToRedstone:0b,inventory:{Size:9,Items:[]},spawnRange:0,transparent:1b,maxDelay:0,xpToDrop:0,mobRange:0,debugMode:0b,maxNearbyMonsters:0}}}
:enddata
:endrule

rule:
plugin=vine
number=88
data:
JSON:{blockState:{blockName:"minecraft:vine",properties:{east:"true",south:"false",north:"true",west:"true",up:"false"}}}
:enddata
:endrule

rule:
plugin=vanillaBlocks
number=89
data:
JSON:{blockState:{blockName:"minecraft:stone_brick_stairs",properties:{half:"top",shape:"straight",facing:"south"}}}
:enddata
:endrule

rule:
plugin=vanillaBlocks
number=90
data:
JSON:{blockState:{blockName:"minecraft:stone_brick_stairs",properties:{half:"top",shape:"straight",facing:"west"}}}
:enddata
:endrule

rule:
plugin=vanillaBlocks
number=91
data:
JSON:{blockState:{blockName:"minecraft:stone_brick_stairs",properties:{half:"top",shape:"straight",facing:"east"}}}
:enddata
:endrule

rule:
plugin=vanillaBlocks
number=92
data:
JSON:{blockState:{blockName:"minecraft:stone_brick_stairs",properties:{half:"top",shape:"straight",facing:"north"}}}
:enddata
:endrule

rule:
plugin=vine
number=93
data:
JSON:{blockState:{blockName:"minecraft:vine",properties:{east:"true",south:"true",north:"false",west:"true",up:"false"}}}
:enddata
:endrule

rule:
plugin=blockTile
number=94
data:
JSON:{blockState:{blockName:"ancientwarfarestructure:advanced_spawner",properties:{transparent:"true"}},teData:{id:"ancientwarfarestructure:advanced_spawner_tile",spawnerSettings:{minDelay:0,spawnDelay:0,lightSensitive:0b,spawnGroups:[{settingsList:[{remainingSpawnCount:1,hostile:1b,forced:1b,customTag:{factionName:"orc"},maxToSpawn:1,entityId:"ancientwarfarenpc:faction.archer.elite",minToSpawn:1}],groupWeight:1}],playerRange:32,respondToRedstone:0b,inventory:{Size:9,Items:[]},spawnRange:0,transparent:1b,maxDelay:0,xpToDrop:0,mobRange:0,debugMode:0b,maxNearbyMonsters:0}}}
:enddata
:endrule

rule:
plugin=blockTile
number=95
data:
JSON:{blockState:{blockName:"ancientwarfarestructure:advanced_spawner",properties:{transparent:"true"}},teData:{id:"ancientwarfarestructure:advanced_spawner_tile",spawnerSettings:{minDelay:0,spawnDelay:0,lightSensitive:0b,spawnGroups:[{settingsList:[{remainingSpawnCount:1,hostile:1b,forced:1b,customTag:{factionName:"orc"},maxToSpawn:1,entityId:"ancientwarfarenpc:faction.archer.elite",minToSpawn:1}],groupWeight:1}],playerRange:32,respondToRedstone:0b,inventory:{Size:9,Items:[]},spawnRange:0,transparent:1b,maxDelay:0,xpToDrop:0,mobRange:0,debugMode:0b,maxNearbyMonsters:0}}}
:enddata
:endrule

rule:
plugin=blockTile
number=96
data:
JSON:{blockState:{blockName:"ancientwarfarestructure:advanced_spawner",properties:{transparent:"true"}},teData:{id:"ancientwarfarestructure:advanced_spawner_tile",spawnerSettings:{minDelay:0,spawnDelay:0,lightSensitive:0b,spawnGroups:[{settingsList:[{remainingSpawnCount:1,hostile:1b,forced:1b,customTag:{factionName:"orc"},maxToSpawn:1,entityId:"ancientwarfarenpc:faction.archer.elite",minToSpawn:1}],groupWeight:1}],playerRange:32,respondToRedstone:0b,inventory:{Size:9,Items:[]},spawnRange:0,transparent:1b,maxDelay:0,xpToDrop:0,mobRange:0,debugMode:0b,maxNearbyMonsters:0}}}
:enddata
:endrule

rule:
plugin=blockTile
number=97
data:
JSON:{blockState:{blockName:"ancientwarfarestructure:advanced_spawner",properties:{transparent:"true"}},teData:{id:"ancientwarfarestructure:advanced_spawner_tile",spawnerSettings:{minDelay:0,spawnDelay:0,lightSensitive:0b,spawnGroups:[{settingsList:[{remainingSpawnCount:1,hostile:1b,forced:1b,customTag:{factionName:"orc"},maxToSpawn:1,entityId:"ancientwarfarenpc:faction.archer.elite",minToSpawn:1}],groupWeight:1}],playerRange:32,respondToRedstone:0b,inventory:{Size:9,Items:[]},spawnRange:0,transparent:1b,maxDelay:0,xpToDrop:0,mobRange:0,debugMode:0b,maxNearbyMonsters:0}}}
:enddata
:endrule

#### ENTITIES ####
entity:
plugin=entity
number=0
data:
JSON:{yOffset:0.0f,xOffset:0.5f,rotation:5.171234f,mobID:"primitivemobs:traveling_merchant",zOffset:0.5f,position:7147362451483L,entityData:{HurtByTimestamp:0,ForgeData:{},Attributes:[{Base:20.0d,Name:"generic.maxHealth"},{Base:0.0d,Name:"generic.knockbackResistance"},{Base:0.5d,Name:"generic.movementSpeed"},{Base:0.0d,Name:"generic.armor"},{Base:0.0d,Name:"generic.armorToughness"},{Base:1.0d,Name:"forge.swimSpeed"},{Base:16.0d,Modifiers:[{UUIDMost:-504373860962382171L,UUIDLeast:-5401520398208587000L,Amount:-0.04711967870271189d,Operation:1,Name:"Random spawn bonus"}],Name:"generic.followRange"}],Riches:0,Invulnerable:0b,FallFlying:0b,ForcedAge:0,canDespawn:1b,PortalCooldown:0,AbsorptionAmount:0.0f,FallDistance:0.0f,DeathTime:0s,ForgeCaps:{"dsurround:emojidata":{as:0,es:0,et:0},"llibrary:extendedentitydatacapability":{"mm:living":{frozenYaw:0.0f,freezeProgress:0.0f,frozenPitch:0.0f,frozenYawHead:0.0f,frozenEntityID:-1,frozenLimbSwingAmount:0.0f,frozenRenderYawOffset:0.0f,frozenSwingProgress:0.0f}}},HandDropChances:[0.085f,0.085f],PersistenceRequired:0b,Age:0,Motion:[0.0d,-0.0784000015258789d,0.0d],Leashed:0b,Health:20.0f,LeftHanded:0b,Air:300s,OnGround:1b,Dimension:0,Offers:{Recipes:[{maxUses:7,buy:{id:"minecraft:cooked_rabbit",Count:5b,Damage:0s},sell:{id:"minecraft:emerald",Count:1b,Damage:0s},uses:0,rewardExp:1b},{maxUses:7,buy:{id:"minecraft:emerald",Count:1b,Damage:0s},sell:{id:"minecraft:paper",Count:34b,Damage:0s},uses:0,rewardExp:1b},{maxUses:7,buy:{id:"minecraft:emerald",Count:1b,Damage:0s},sell:{id:"minecraft:melon_seeds",Count:10b,Damage:0s},uses:0,rewardExp:1b}]},Rotation:[275.17123f,0.0f],UpdateBlocked:0b,HandItems:[{},{}],ProfessionName:"primitivemobs:merchant",ArmorDropChances:[0.085f,0.085f,0.085f,0.085f],Profession:7,Pos:[569.5d,106.0d,865.5d],Fire:-1s,ArmorItems:[{},{},{},{}],CanPickUpLoot:1b,HurtTime:0s,CareerLevel:1,Career:1,Inventory:[],Willing:0b}}
:enddata
:endentity

