# Ancient Warfare Structure Template File
# Auto-generated structure template file. created on: 8/19/2019 at: 10:23:14
# Lines beginning with # denote comments

header:
version=2.9
name=OrcRuinedCastleOakWoodsGeneric
mods=
size=46,50,41
offset=25,15,40
:endheader

#### VALIDATION ####
validation:
type=ground
survival=false
worldGenEnabled=true
unique=false
preserveBlocks=false
selectionWeight=100
clusterValue=60
minDuplicateDistance=1000
dimensionWhiteList=true
dimensionList=0
biomeWhiteList=true
biomeList=minecraft:swampland,biomesoplenty:woodland,biomesoplenty:dead_swamp,biomesoplenty:dead_forest,traverse:woodlands,minecraft:forest,traverse:rocky_plains,traverse:badlands,minecraft:ice_flats,biomesoplenty:steppe,traverse:rocky_plateau
leveling=7
fill=4
border=7
blockSwap=true
:endvalidation

#### LAYERS ####
layer: 0
1,1,1,1,1,1,1,1,1,1,1,1,1,1,1,1,1,1,1,1,1,1,1,1,1,1,1,1,1,1,1,1,1,1,1,1,1,1,1,1,1,1,1,1,1,1
1,1,1,1,1,1,1,1,1,1,1,1,1,1,1,1,1,1,1,1,1,1,1,1,1,1,1,1,1,1,1,1,1,1,1,1,1,1,1,1,1,1,1,1,1,1
1,1,1,1,1,1,1,1,1,1,1,1,1,1,1,1,1,1,1,1,1,1,1,1,1,1,1,1,1,1,1,1,1,1,1,1,1,1,1,1,1,1,1,1,1,1
1,1,1,1,1,1,1,1,1,1,1,1,1,1,1,1,1,1,1,1,1,1,1,1,1,1,1,1,1,1,1,1,1,1,1,1,1,1,1,1,1,1,1,1,1,1
1,1,1,1,1,1,1,1,1,5,5,1,1,1,1,1,1,1,1,1,1,1,1,1,1,1,1,1,1,1,1,1,1,1,1,1,1,1,1,1,1,1,1,1,1,1
1,1,1,1,1,1,1,1,1,1,1,1,1,1,1,1,1,1,1,1,1,1,1,1,1,1,1,1,1,1,1,1,1,1,1,1,1,1,1,1,1,1,1,1,1,1
1,1,1,1,1,1,1,1,1,1,1,1,1,1,1,1,1,1,1,1,1,1,1,1,1,1,1,1,1,1,1,1,1,1,1,1,1,1,1,1,1,1,1,1,1,1
1,1,1,1,1,1,1,1,1,1,1,1,1,1,1,1,1,1,1,1,1,1,1,1,1,1,1,1,1,1,1,1,1,1,1,1,1,1,1,1,1,1,1,1,1,1
1,1,1,1,1,1,1,1,1,1,1,1,1,1,1,1,1,1,1,1,1,1,1,1,1,1,1,1,1,1,1,1,1,1,1,1,1,1,1,1,1,1,1,1,1,1
1,1,1,1,1,1,1,1,1,1,1,1,1,1,1,1,1,1,1,1,1,1,1,1,1,1,1,1,1,1,1,1,1,1,1,1,1,1,1,1,1,1,1,1,1,1
1,1,1,1,1,1,1,1,1,1,1,1,1,1,1,1,1,1,1,1,1,1,1,1,1,1,1,1,1,1,1,1,1,1,1,1,1,1,1,1,1,1,1,1,1,1
1,1,1,1,1,1,1,1,1,1,1,1,1,1,1,1,1,1,1,1,1,1,1,1,1,1,1,1,1,1,1,1,1,1,1,1,1,1,1,1,1,1,1,1,1,1
1,1,1,1,1,1,1,1,1,1,1,1,1,1,1,1,1,1,1,1,1,1,1,1,1,1,1,1,1,1,1,1,1,1,1,1,1,1,1,1,1,1,1,1,1,1
1,1,1,1,1,1,1,1,1,1,1,1,1,1,1,1,1,1,1,1,1,1,1,1,1,1,1,1,1,1,1,1,1,1,1,1,1,1,1,1,1,1,1,1,1,1
1,1,1,1,1,1,1,1,1,1,1,1,1,1,1,1,1,1,1,1,1,1,1,1,1,1,1,1,1,1,1,1,1,1,1,1,1,1,1,1,1,1,1,1,1,1
1,1,1,1,1,1,1,1,1,1,1,1,1,1,1,1,1,1,1,1,1,1,1,1,1,1,1,1,1,1,1,1,1,1,1,1,1,1,1,1,1,1,1,1,1,1
1,1,1,1,1,1,1,1,1,1,1,1,1,1,1,1,1,1,1,1,1,1,1,1,1,1,1,1,1,1,1,1,1,1,1,1,1,1,1,1,1,1,1,1,1,1
1,1,1,1,1,1,1,1,1,1,1,1,1,1,1,1,1,1,1,1,1,1,1,1,1,1,1,1,1,1,1,1,1,1,1,1,1,1,1,1,1,1,1,1,1,1
1,1,1,1,1,1,1,1,1,1,1,1,1,1,1,1,1,1,1,1,1,1,1,1,1,1,1,1,1,1,1,1,1,1,1,1,1,1,1,1,1,1,1,1,1,1
1,1,1,1,1,1,1,1,1,1,1,1,1,1,1,1,1,1,1,1,1,1,1,1,1,1,1,1,1,1,1,1,1,1,1,1,1,1,1,1,1,1,1,1,1,1
1,1,1,1,1,1,1,1,1,1,1,1,1,1,1,1,1,1,1,1,1,1,1,1,1,1,1,1,1,1,1,1,1,1,1,1,1,1,1,1,1,1,1,1,1,1
1,1,1,1,1,1,1,1,1,1,1,1,1,1,1,1,1,1,1,1,1,1,1,1,1,1,1,1,1,1,1,1,1,1,1,1,1,1,1,1,1,1,1,1,1,1
1,1,1,1,1,1,1,1,1,1,1,1,1,1,1,1,1,1,1,1,1,1,1,1,1,1,1,1,1,1,1,1,1,1,1,1,1,1,1,1,1,1,1,1,1,1
1,1,1,1,1,1,1,1,1,1,1,1,1,1,1,1,1,1,1,1,1,1,1,1,1,1,1,1,1,1,1,1,1,1,1,1,1,1,1,1,1,1,1,1,1,1
1,1,1,1,1,1,1,1,1,1,1,1,1,1,1,1,1,1,1,1,1,1,1,1,1,1,1,1,1,1,1,1,1,1,1,1,1,1,1,1,1,1,1,1,1,1
1,1,1,1,1,1,1,1,1,1,1,1,1,1,1,1,1,1,1,1,1,1,1,1,1,1,1,1,1,1,1,1,1,1,1,1,1,1,1,1,1,1,1,1,1,1
1,1,1,1,1,1,1,1,1,1,1,1,1,1,1,1,1,1,1,1,1,1,1,1,1,1,1,1,1,1,1,1,1,1,1,1,1,1,1,1,1,1,1,1,1,1
1,1,1,1,1,1,1,1,1,1,1,1,1,1,1,1,1,1,1,1,1,1,1,1,1,1,1,1,1,1,1,1,1,1,1,1,1,1,1,1,1,1,1,1,1,1
1,1,1,1,1,1,1,1,1,1,1,1,1,1,1,1,1,1,1,1,1,1,1,1,1,1,1,1,1,2,1,1,1,1,1,1,1,1,1,1,1,1,1,1,1,1
1,1,1,1,1,1,1,1,1,1,1,1,1,1,1,1,1,1,1,1,1,1,1,1,1,1,1,1,1,2,1,1,1,1,1,1,1,1,1,1,1,1,1,1,1,1
1,1,1,1,1,1,1,1,1,1,1,1,1,1,1,1,1,1,1,1,1,1,1,1,1,1,1,1,1,2,1,1,1,1,1,1,1,1,1,1,1,1,1,1,1,1
1,1,1,1,1,1,1,1,1,1,1,1,1,1,1,1,1,1,1,1,1,1,1,1,1,1,1,1,1,1,1,1,1,1,1,1,1,1,1,1,1,1,1,1,1,1
1,1,1,1,1,1,1,1,1,1,1,1,1,1,1,1,1,1,1,1,1,1,1,1,1,1,1,1,1,1,1,1,1,1,1,1,1,1,1,1,1,1,1,1,1,1
1,1,1,1,1,1,1,1,1,1,1,1,1,1,1,1,1,1,1,1,1,1,1,1,1,1,1,1,1,1,1,1,1,1,1,1,1,1,1,1,1,1,1,1,1,1
1,1,1,1,1,1,1,1,1,1,1,1,1,1,1,1,1,1,1,1,1,1,1,1,1,1,1,1,1,1,1,1,1,1,1,1,1,1,1,1,1,1,1,1,1,1
1,1,1,1,1,1,1,1,1,1,1,1,1,1,1,1,1,1,1,1,1,1,1,1,1,1,1,1,1,3,1,1,1,1,1,1,1,1,1,1,1,1,1,1,1,1
1,1,1,1,1,1,1,1,1,1,1,1,1,1,1,1,1,1,1,1,1,1,1,1,1,1,1,1,1,4,1,1,1,1,1,1,1,1,1,1,1,1,1,1,1,1
1,1,1,1,1,1,1,1,1,1,1,1,1,1,1,1,1,1,1,1,1,1,1,1,1,1,1,1,1,1,1,1,1,1,1,1,1,1,1,1,1,1,1,1,1,1
1,1,1,1,1,1,1,1,1,1,1,1,1,1,1,1,1,1,1,1,1,1,1,1,1,1,1,1,1,1,1,1,1,1,1,1,1,1,1,1,1,1,1,1,1,1
1,1,1,1,1,1,1,1,1,1,1,1,1,1,1,1,1,1,1,1,1,1,1,1,1,1,1,1,1,1,1,1,1,1,1,1,1,1,1,1,1,1,1,1,1,1
1,1,1,1,1,1,1,1,1,1,1,1,1,1,1,1,1,1,1,1,1,1,1,1,1,1,1,1,1,1,1,1,1,1,1,1,1,1,1,1,1,1,1,1,1,1
:endlayer
layer: 1
0,0,0,0,0,0,0,0,0,0,0,0,0,0,0,0,0,0,0,0,0,0,0,0,0,0,0,0,0,0,0,0,0,0,0,0,0,0,0,0,0,0,0,0,0,0
0,6,6,6,6,6,6,6,6,6,6,6,6,6,6,6,6,6,6,6,6,6,6,0,0,0,6,6,6,6,6,6,6,6,6,6,6,6,6,6,6,6,6,6,6,0
0,6,6,6,6,6,6,6,6,6,6,6,6,6,6,6,6,6,6,6,6,6,6,0,0,0,6,6,6,6,6,6,6,6,6,6,6,6,6,6,6,6,6,6,6,0
0,6,6,1,1,1,1,1,1,1,1,1,1,1,1,1,1,1,1,1,1,1,1,28,1,28,1,1,1,1,1,1,1,1,1,1,1,1,1,1,1,1,1,1,6,0
0,6,6,1,84,0,0,0,1,75,75,7,0,53,0,53,0,53,0,53,53,1,52,0,1,0,44,1,0,0,0,0,0,23,1,7,7,7,7,7,7,7,7,1,6,0
0,6,6,1,0,0,0,0,37,76,76,37,0,53,0,53,0,53,0,0,0,1,0,0,1,0,0,1,0,0,0,0,0,23,1,7,8,8,8,8,8,8,7,1,6,0
0,6,6,1,0,0,0,0,0,82,0,0,0,0,0,0,0,0,0,0,0,1,0,0,1,0,0,1,0,0,0,0,0,23,1,7,8,8,8,8,8,8,7,1,6,0
0,6,6,1,0,0,0,0,0,0,0,0,0,68,0,0,0,0,0,0,41,20,41,0,0,0,41,21,41,0,32,0,0,23,1,7,8,8,9,1,8,8,7,1,6,0
0,6,6,1,0,0,0,0,1,0,77,1,71,0,1,0,0,1,0,0,0,1,0,0,0,0,0,1,0,0,0,0,0,23,1,7,8,8,8,1,8,8,7,1,6,0
0,6,6,1,0,0,0,0,0,0,0,0,0,0,0,0,0,0,0,53,53,1,0,0,0,0,0,1,0,0,0,0,0,23,1,7,8,8,8,8,8,8,7,1,6,0
0,6,6,1,0,0,0,0,0,0,0,0,0,0,0,0,0,0,0,0,0,1,0,0,0,0,0,1,0,0,0,0,0,23,1,7,8,8,10,8,8,8,7,1,6,0
0,6,6,1,0,0,0,0,0,53,0,53,0,53,0,53,0,53,0,53,0,1,0,0,0,0,0,1,0,0,0,0,0,23,1,7,7,7,7,7,7,7,7,1,6,0
0,6,6,1,0,41,0,0,0,53,0,53,0,53,0,53,0,53,0,53,0,1,0,0,0,0,0,1,1,1,1,1,1,1,1,1,1,1,1,1,1,1,1,1,6,0
0,6,6,1,7,28,7,7,7,7,7,7,7,7,7,7,7,7,7,7,7,1,0,0,0,0,0,1,42,38,33,0,26,24,1,0,1,0,0,1,1,1,1,1,6,0
0,6,6,1,0,41,0,0,83,0,78,0,72,0,66,0,62,0,59,0,54,7,0,0,0,0,0,7,43,0,0,0,27,0,1,0,20,0,0,1,1,1,1,1,6,0
0,6,6,1,0,0,0,0,0,0,0,0,0,0,0,0,0,0,0,0,0,1,0,0,0,0,0,1,0,0,0,0,0,0,1,0,1,0,0,1,1,1,1,1,6,0
0,6,6,1,0,0,0,0,0,0,0,0,0,0,0,0,0,0,0,0,0,1,0,0,0,0,0,1,0,0,0,0,0,0,1,0,1,19,11,1,1,1,1,1,6,0
0,6,6,1,0,0,0,0,0,0,0,0,0,0,0,0,0,0,0,0,0,1,0,0,49,0,0,1,1,1,34,1,1,1,1,0,1,1,1,1,1,1,1,1,6,0
0,6,6,1,0,0,0,41,0,0,0,0,0,0,41,0,0,0,0,41,41,21,41,0,0,0,41,20,41,0,0,0,0,0,0,0,20,0,0,1,1,1,1,1,6,0
0,6,6,1,7,7,7,34,7,1,7,7,1,7,34,7,7,7,7,34,7,1,0,0,0,0,0,1,1,1,1,1,28,1,1,0,1,0,12,1,1,1,1,1,6,0
0,6,6,1,85,0,0,41,0,0,79,7,73,0,41,0,63,7,60,41,55,1,0,0,0,0,0,1,0,0,0,0,0,0,1,0,1,1,1,1,1,1,1,1,6,0
0,6,6,1,53,53,0,0,0,53,53,7,0,0,0,0,0,7,0,0,0,1,0,0,0,0,0,1,0,0,0,0,0,0,1,0,20,0,0,1,1,1,1,1,6,0
0,6,6,1,86,0,0,0,0,0,80,7,0,0,0,0,0,7,0,0,0,1,0,35,35,35,0,1,0,0,0,0,0,0,1,0,1,0,13,1,1,1,1,1,6,0
0,6,6,1,53,53,0,0,0,53,53,7,0,0,0,0,0,7,0,0,0,1,0,1,1,1,0,1,0,0,0,0,0,0,1,0,1,1,1,1,1,1,1,1,6,0
0,6,6,1,87,0,0,0,0,0,81,7,0,0,0,65,0,7,0,0,0,1,0,1,1,1,0,1,0,39,0,0,0,0,1,0,20,0,0,1,1,1,1,1,6,0
0,6,6,1,1,1,1,1,1,1,1,1,1,1,1,1,1,1,1,1,1,1,0,1,1,1,0,1,0,0,0,31,0,0,1,0,1,0,14,1,1,1,1,1,6,0
0,6,6,1,51,0,0,0,0,0,35,51,51,57,57,57,57,57,57,57,0,1,0,0,0,0,0,1,7,7,7,7,7,7,7,0,1,1,1,1,1,1,1,1,6,0
0,6,6,1,51,0,0,0,0,0,35,0,51,51,0,0,0,0,0,0,0,1,0,0,0,0,0,1,35,35,35,7,0,0,21,0,1,0,15,1,1,1,1,1,6,0
0,6,6,1,0,0,0,0,0,0,35,0,0,57,57,57,57,57,57,57,0,1,0,1,0,1,0,1,23,40,36,7,0,0,1,0,20,0,0,1,1,1,1,1,6,0
0,6,6,1,0,0,0,0,0,0,35,0,0,0,0,0,0,0,0,0,41,20,41,0,0,0,0,1,23,40,36,7,1,1,1,0,1,0,16,1,1,1,1,1,6,0
0,6,6,1,51,0,0,0,0,51,1,0,0,57,57,57,57,57,57,57,0,1,0,0,0,0,0,1,23,40,36,7,0,0,21,0,1,1,1,1,1,1,1,1,6,0
0,6,6,1,51,0,0,0,0,0,0,0,0,0,0,0,0,0,0,0,0,1,0,0,0,0,0,1,37,37,37,7,29,0,1,0,20,0,0,1,1,1,1,1,6,0
0,6,6,1,0,0,0,0,0,0,0,0,74,69,51,51,0,0,0,0,0,1,0,0,0,0,0,1,0,0,0,7,1,1,7,0,1,0,0,1,1,1,1,1,6,0
0,6,6,1,0,0,0,0,51,51,1,0,57,57,57,57,57,57,57,57,0,1,0,0,0,0,41,20,41,0,0,0,0,0,0,0,1,0,17,1,1,1,1,1,6,0
0,6,6,1,0,0,0,0,51,51,35,0,57,0,0,0,0,0,0,0,0,1,0,0,0,0,0,1,0,0,0,7,1,1,1,0,1,1,1,1,1,1,1,1,6,0
0,6,6,1,0,0,0,0,0,0,35,0,0,70,67,0,64,0,61,0,0,1,0,0,0,0,0,1,23,35,36,7,30,25,1,0,20,0,0,1,1,1,1,1,6,0
0,6,6,1,51,0,0,0,0,0,35,0,57,0,0,0,0,0,0,0,0,1,0,0,50,47,45,1,23,8,36,7,0,0,1,0,1,0,0,1,1,1,1,1,6,0
0,6,6,1,0,0,0,0,0,51,35,0,57,57,57,57,57,57,57,58,56,1,51,51,1,48,46,1,23,37,36,7,0,0,22,0,1,0,18,1,1,1,1,1,6,0
0,6,6,1,1,1,1,1,1,1,1,1,1,1,1,1,1,1,1,1,1,1,1,1,1,1,1,1,1,1,1,1,1,1,1,1,1,1,1,1,1,1,1,1,6,0
0,6,6,6,6,6,6,6,6,6,6,6,6,6,6,6,6,6,6,6,6,6,6,6,6,6,6,6,6,6,6,6,6,6,6,6,6,6,6,6,6,6,6,6,6,0
0,0,0,0,0,0,0,0,0,0,0,0,0,0,0,0,0,0,0,0,0,0,0,0,0,0,0,0,0,0,0,0,0,0,0,0,0,0,0,0,0,0,0,0,0,0
:endlayer
layer: 2
0,0,0,0,0,0,0,0,0,0,0,0,0,0,0,0,0,0,0,0,0,0,0,0,0,0,0,0,0,0,0,0,0,0,0,0,0,0,0,0,0,0,0,0,0,0
0,6,6,6,6,6,6,6,6,6,6,6,6,6,6,6,6,6,6,6,6,6,6,0,0,0,6,6,6,6,6,6,6,6,6,6,6,6,6,6,6,6,6,6,6,0
0,6,6,6,6,6,6,6,6,6,6,6,6,6,6,6,6,6,6,6,6,6,6,0,0,0,6,6,6,6,6,6,6,6,6,6,6,6,6,6,6,6,6,6,6,0
0,6,6,1,1,1,1,1,1,1,1,1,1,1,1,1,1,1,1,1,1,1,1,90,1,89,1,1,1,1,1,1,1,1,1,1,1,1,1,1,1,1,1,1,6,0
0,6,6,1,0,0,0,0,1,0,0,1,0,0,0,0,0,0,0,0,0,1,0,0,1,0,0,1,0,0,0,0,0,0,23,7,7,7,7,7,7,7,7,1,6,0
0,6,6,1,0,0,0,0,0,76,76,0,0,0,0,0,0,0,0,0,0,1,0,0,1,0,0,1,0,0,0,0,0,0,23,7,8,8,8,8,8,8,7,1,6,0
0,6,6,1,0,0,0,0,0,0,0,0,0,0,0,0,0,0,0,0,0,1,0,0,1,0,0,1,0,0,0,0,0,0,23,7,8,8,8,8,8,8,1,1,6,0
0,6,6,1,0,0,0,0,0,0,0,0,0,0,0,0,0,0,0,0,0,90,0,0,0,0,0,90,0,0,0,0,0,0,23,7,1,8,8,1,8,8,7,1,6,0
0,6,6,1,0,0,0,0,1,0,0,1,0,0,1,0,0,1,0,0,0,1,0,0,0,0,0,1,0,0,0,0,0,0,23,7,1,8,8,1,8,8,1,1,6,0
0,6,6,1,0,0,0,0,0,0,0,0,0,0,0,0,0,0,0,0,0,1,0,0,0,0,0,1,0,0,0,0,0,0,23,7,8,8,8,8,8,88,7,1,6,0
0,6,6,1,0,0,0,0,0,0,0,0,0,0,0,0,0,0,0,0,0,1,0,0,0,0,0,1,0,0,0,0,0,0,23,7,8,8,8,8,8,8,1,1,6,0
0,6,6,1,0,0,0,0,0,0,0,0,0,0,0,0,0,0,0,0,0,1,0,0,0,0,0,1,0,0,0,0,0,0,23,7,7,1,1,7,1,7,1,1,6,0
0,6,6,1,0,0,0,0,0,0,0,0,0,0,0,0,0,0,0,0,0,1,0,0,0,0,0,1,1,1,1,1,1,1,1,1,1,1,1,1,1,1,1,1,6,0
0,6,6,1,7,90,7,7,7,7,7,7,7,7,7,7,7,7,7,7,7,1,0,0,0,0,0,1,0,0,0,0,0,0,7,0,7,0,0,1,1,1,1,1,6,0
0,6,6,1,0,0,0,0,0,0,0,0,0,0,0,0,0,0,0,0,0,7,0,0,0,0,0,7,0,0,0,0,0,0,1,0,89,0,0,1,1,1,1,1,6,0
0,6,6,1,0,0,0,0,0,0,0,0,0,0,0,0,0,0,0,0,0,1,0,0,0,0,0,1,0,0,0,0,0,0,7,0,7,0,0,1,1,1,1,1,6,0
0,6,6,1,0,0,0,0,0,0,0,0,0,0,0,0,0,0,0,0,0,1,0,0,0,0,0,1,0,0,0,0,0,0,7,0,1,0,0,1,1,1,1,1,6,0
0,6,6,1,0,0,0,0,0,0,0,0,0,0,0,0,0,0,0,0,0,1,0,0,0,0,0,1,7,7,89,7,7,7,7,0,7,1,7,1,1,1,1,1,6,0
0,6,6,1,0,0,0,0,0,0,0,0,0,0,0,0,0,0,0,0,0,89,0,0,0,0,0,89,0,0,0,0,0,0,0,0,89,0,0,1,1,1,1,1,6,0
0,6,6,1,1,1,1,90,1,1,1,1,1,1,89,1,1,1,1,90,1,1,0,0,0,0,0,1,7,7,7,7,89,7,7,0,1,0,0,1,1,1,1,1,6,0
0,6,6,1,0,0,0,0,0,0,0,1,0,0,0,0,0,1,0,0,0,1,0,0,0,0,0,1,0,0,0,0,0,0,7,0,7,1,7,1,1,1,1,1,6,0
0,6,6,1,0,0,0,0,0,0,0,1,0,0,0,0,0,1,0,0,0,1,0,0,0,0,0,1,0,0,0,0,0,0,7,0,89,0,0,1,1,1,1,1,6,0
0,6,6,1,0,0,0,0,0,0,0,1,0,0,0,0,0,1,0,0,0,1,0,0,0,0,0,1,0,0,0,0,0,0,7,0,1,0,0,1,1,1,1,1,6,0
0,6,6,1,0,0,0,0,0,0,0,1,0,0,0,0,0,1,0,0,0,1,0,35,35,35,0,1,0,0,0,0,0,0,7,0,7,1,7,1,1,1,1,1,6,0
0,6,6,1,0,0,0,0,0,0,0,1,0,0,0,0,0,1,0,0,0,1,0,1,1,1,0,1,0,0,0,0,0,0,7,0,89,0,0,1,1,1,1,1,6,0
0,6,6,1,1,1,1,1,1,1,1,1,1,1,1,1,1,1,1,1,1,1,0,1,1,1,0,1,0,0,0,0,0,0,1,0,1,0,0,1,1,1,1,1,6,0
0,6,6,1,51,0,0,51,0,51,35,51,51,57,57,57,57,57,57,57,0,1,0,0,0,0,0,1,7,1,1,7,1,1,7,0,7,7,7,1,1,1,1,1,6,0
0,6,6,1,51,0,0,0,0,51,35,0,51,51,0,0,0,0,0,0,0,1,0,0,0,0,0,1,0,0,0,7,0,0,89,0,1,0,0,1,1,1,1,1,6,0
0,6,6,1,0,0,0,0,0,51,35,0,0,57,57,57,57,57,57,57,0,1,0,1,0,1,0,1,0,0,0,7,0,0,7,0,89,0,0,1,1,1,1,1,6,0
0,6,6,1,0,0,0,0,0,51,35,0,0,0,0,0,0,0,0,0,0,90,0,0,0,0,0,1,0,0,0,7,7,7,7,0,1,0,0,1,1,1,1,1,6,0
0,6,6,1,0,0,0,0,0,51,1,0,0,57,57,57,57,57,57,57,0,1,0,0,0,0,0,1,0,0,0,7,0,0,89,0,1,1,1,1,1,1,1,1,6,0
0,6,6,1,51,0,0,0,0,0,0,0,0,0,0,0,0,0,0,0,0,1,0,0,0,0,0,1,0,0,0,7,0,0,7,0,89,0,0,1,1,1,1,1,6,0
0,6,6,1,0,0,0,0,0,0,0,0,0,0,74,69,0,0,0,0,0,1,0,0,0,0,0,1,0,0,0,7,1,1,7,0,1,0,0,1,1,1,1,1,6,0
0,6,6,1,0,0,0,0,51,51,7,0,57,57,57,57,57,57,57,57,0,7,0,0,0,0,0,89,0,0,0,0,0,0,0,0,1,0,0,1,1,1,1,1,6,0
0,6,6,1,0,0,0,0,0,0,35,0,57,0,0,0,0,0,0,0,0,1,0,0,0,0,0,1,0,0,0,7,1,1,7,0,7,1,1,1,1,1,1,1,6,0
0,6,6,1,0,0,0,0,0,0,35,0,0,0,0,0,0,0,0,0,0,1,0,0,0,0,0,1,0,0,0,1,0,0,7,0,89,0,0,1,1,1,1,1,6,0
0,6,6,1,51,0,0,0,0,0,35,0,57,0,0,0,0,0,0,0,0,1,0,0,0,0,0,1,0,0,0,1,0,0,7,0,7,0,0,1,1,1,1,1,6,0
0,6,6,1,51,0,0,0,0,51,35,0,57,57,57,57,57,57,57,0,0,1,0,51,1,0,0,1,0,0,0,7,0,0,89,0,7,0,0,1,1,1,1,1,6,0
0,6,6,1,1,1,1,1,1,1,1,1,1,1,1,1,1,1,1,1,1,1,51,1,1,1,1,1,1,1,1,1,1,1,1,1,1,1,1,1,1,1,1,1,6,0
0,6,6,6,6,6,6,6,6,6,6,6,6,6,6,6,6,6,6,6,6,6,6,6,6,6,6,6,6,6,6,6,6,6,6,6,6,6,6,6,6,6,6,6,6,0
0,0,0,0,0,0,0,0,0,0,0,0,0,0,0,0,0,0,0,0,0,0,0,0,0,0,0,0,0,0,0,0,0,0,0,0,0,0,0,0,0,0,0,0,0,0
:endlayer
layer: 3
0,0,0,0,0,0,0,0,0,0,0,0,0,0,0,0,0,0,0,0,0,0,0,0,0,0,0,0,0,0,0,0,0,0,0,0,0,0,0,0,0,0,0,0,0,0
0,6,6,6,6,6,6,6,6,6,6,6,6,6,6,6,6,6,6,6,6,6,6,0,0,0,6,6,6,6,6,6,6,6,6,6,6,6,6,6,6,6,6,6,6,0
0,6,6,6,6,6,6,6,6,6,6,6,6,6,6,6,6,6,6,6,6,6,6,0,0,0,6,6,6,6,6,6,6,6,6,6,6,6,6,6,6,6,6,6,6,0
0,6,6,1,1,1,1,1,1,1,1,1,1,1,1,1,1,1,1,1,1,1,1,100,1,100,1,1,1,1,1,1,1,1,1,1,1,1,1,1,1,1,1,1,6,0
0,6,6,1,0,0,0,0,1,0,0,7,0,0,0,0,0,0,0,0,0,1,1,1,1,1,1,1,0,0,0,0,0,0,0,0,0,0,0,0,0,0,0,1,6,0
0,6,6,1,0,0,0,0,0,0,0,0,0,0,0,0,0,0,0,0,0,1,1,7,101,7,1,1,0,0,0,0,0,0,0,0,0,0,0,0,0,0,0,1,6,0
0,6,6,1,0,0,0,0,0,0,0,0,0,0,0,0,0,0,0,0,0,1,1,1,1,1,1,1,0,0,0,0,0,0,0,0,0,0,0,0,0,0,0,1,6,0
0,6,6,1,0,0,0,0,0,0,0,0,0,0,0,0,0,0,0,0,0,1,96,0,0,0,95,1,0,0,0,0,0,0,0,0,0,0,0,1,0,0,0,1,6,0
0,6,6,1,0,0,0,0,1,0,0,1,0,0,1,0,0,1,0,0,0,1,0,0,0,0,0,1,0,0,0,0,0,0,0,0,0,0,0,1,0,0,0,1,6,0
0,6,6,1,0,0,0,0,0,0,0,0,0,0,0,0,0,0,0,0,0,1,0,0,0,0,0,1,0,0,0,0,0,0,0,0,0,0,0,0,0,0,0,1,6,0
0,6,6,1,0,0,0,0,0,0,0,0,0,0,0,0,0,0,0,0,0,1,0,0,0,0,0,1,0,0,0,0,0,0,0,0,0,0,0,0,0,0,0,1,6,0
0,6,6,1,0,0,0,0,0,0,0,0,0,0,0,0,0,0,0,0,0,1,0,0,0,0,0,1,0,0,0,0,0,0,0,0,0,0,0,0,0,41,0,1,6,0
0,6,6,1,0,0,0,0,0,0,0,0,0,0,0,0,0,0,0,0,0,1,0,0,0,0,0,1,1,1,1,1,1,1,1,1,1,1,1,1,1,34,1,1,6,0
0,6,6,1,7,7,7,7,7,7,7,7,7,7,7,7,7,7,7,7,7,1,0,0,0,0,0,1,0,0,0,0,0,0,1,0,1,0,0,1,0,41,0,1,6,0
0,6,6,1,0,99,0,0,0,0,0,0,0,0,0,0,0,0,0,0,0,1,0,0,0,0,0,1,0,0,0,0,0,0,1,95,1,0,0,1,0,0,0,1,6,0
0,6,6,1,0,0,0,0,0,0,0,0,0,0,0,0,0,0,0,0,0,1,0,0,0,0,0,1,0,0,0,0,0,0,7,0,1,0,0,1,0,0,0,1,6,0
0,6,6,1,0,0,0,0,0,0,0,0,0,0,0,0,0,0,0,0,0,1,0,0,0,0,0,1,0,0,0,0,0,0,7,0,1,0,0,1,0,0,0,1,6,0
0,6,6,1,0,0,0,0,0,0,0,0,0,0,0,0,0,0,0,0,0,1,0,0,0,0,0,1,7,7,7,7,7,7,7,0,1,1,1,1,0,0,0,1,6,0
0,6,6,1,0,0,0,98,0,0,0,0,0,51,98,0,0,0,0,98,95,1,96,0,0,0,95,1,0,0,99,0,98,0,0,95,1,0,0,1,0,0,0,1,6,0
0,6,6,1,1,1,1,7,1,1,1,7,1,1,1,1,1,1,1,1,1,1,0,0,0,0,0,1,7,7,7,7,7,7,7,0,1,0,0,1,0,0,0,1,6,0
0,6,6,1,0,0,0,0,0,0,0,1,0,0,0,0,0,1,0,0,0,1,0,0,0,0,0,1,0,0,0,0,0,0,7,0,1,1,1,1,0,0,0,1,6,0
0,6,6,1,0,0,0,0,0,0,0,1,0,0,0,0,0,1,0,0,0,1,0,0,0,0,0,1,0,0,0,0,0,0,7,95,1,0,0,1,0,41,0,1,6,0
0,6,6,1,0,0,0,0,0,0,0,1,0,0,0,0,0,1,0,0,0,1,0,0,0,0,0,1,0,0,0,0,0,0,7,0,1,0,0,1,1,34,1,1,6,0
0,6,6,1,0,0,0,0,0,0,0,1,0,0,0,0,0,1,0,0,0,1,0,0,0,0,0,1,0,0,0,0,0,0,7,0,1,1,1,1,0,41,0,1,6,0
0,6,6,1,0,0,0,0,0,0,0,1,0,0,0,0,0,1,0,0,0,1,7,35,35,35,7,1,0,0,0,0,0,0,7,95,1,0,0,1,0,0,0,1,6,0
0,6,6,1,1,1,1,1,1,1,1,1,1,1,1,1,1,1,1,1,1,1,7,1,1,1,7,1,0,0,0,0,0,0,1,0,1,0,0,1,0,41,0,1,6,0
0,6,6,1,51,0,0,51,0,0,35,51,51,57,57,57,57,57,57,57,102,1,7,0,0,0,7,1,7,1,1,7,1,1,7,0,7,7,7,1,7,28,7,1,6,0
0,6,6,1,0,0,0,0,0,0,35,0,0,51,0,0,0,0,0,0,0,1,7,0,0,0,7,1,0,0,0,7,0,0,1,96,1,0,0,1,7,41,7,1,6,0
0,6,6,1,0,0,0,0,0,0,35,0,0,57,57,57,57,57,57,57,0,1,7,1,7,1,7,1,0,0,0,7,0,0,1,95,1,0,0,7,93,0,0,1,6,0
0,6,6,1,0,0,0,0,0,51,35,0,0,0,0,0,0,0,0,0,95,1,96,0,0,0,0,1,0,0,0,7,7,7,1,0,1,0,0,1,7,0,0,1,6,0
0,6,6,1,0,0,0,0,0,51,1,0,0,57,57,57,57,57,57,57,0,1,0,0,0,0,0,1,0,0,0,7,0,0,7,96,1,1,1,1,1,0,0,1,6,0
0,6,6,1,51,0,0,0,0,0,1,104,0,0,0,0,0,0,0,0,0,1,0,0,0,0,0,1,0,0,0,7,0,0,7,95,1,0,0,1,1,0,0,1,6,0
0,6,6,1,0,0,0,0,0,0,1,104,0,0,0,0,74,69,0,0,0,1,0,0,0,0,0,1,0,0,0,7,1,1,7,0,1,0,0,1,1,0,0,1,6,0
0,6,6,1,0,0,0,0,0,51,35,0,57,57,57,57,57,57,57,57,0,1,0,0,0,0,95,1,0,0,0,0,0,0,0,0,1,0,0,1,1,0,0,1,6,0
0,6,6,1,0,0,0,0,0,51,35,0,57,0,0,0,0,0,0,0,0,1,0,0,0,0,0,1,0,0,0,7,1,1,7,0,7,1,1,1,37,0,0,1,6,0
0,6,6,1,0,0,0,0,0,0,35,0,0,0,0,0,0,0,0,0,103,1,0,0,0,0,0,1,0,0,0,1,0,0,7,95,7,0,0,1,0,0,0,1,6,0
0,6,6,1,0,0,0,0,0,0,35,0,57,0,0,0,0,0,0,0,0,1,0,0,0,0,0,1,0,0,0,1,0,0,7,0,7,0,0,1,7,28,7,1,6,0
0,6,6,1,51,0,0,0,0,51,35,105,57,57,57,57,57,57,57,57,57,1,51,0,1,0,0,1,0,0,0,7,0,0,7,97,7,0,0,1,94,92,92,91,6,0
0,6,6,1,1,1,1,1,1,1,1,1,1,1,1,1,1,1,1,1,1,1,1,1,1,1,1,1,1,1,1,1,1,1,1,1,1,1,1,1,1,1,1,1,6,0
0,6,6,6,6,6,6,6,6,6,6,6,6,6,6,6,6,6,6,6,6,6,6,6,6,6,6,6,6,6,6,6,6,6,6,6,6,6,6,6,6,6,6,6,6,0
0,0,0,0,0,0,0,0,0,0,0,0,0,0,0,0,0,0,0,0,0,0,0,0,0,0,0,0,0,0,0,0,0,0,0,0,0,0,0,0,0,0,0,0,0,0
:endlayer
layer: 4
6,6,6,6,6,6,6,6,6,6,6,6,6,6,6,6,6,6,6,6,6,6,6,6,6,6,6,6,6,6,6,6,6,6,6,6,6,6,6,6,6,6,6,6,6,6
6,6,6,6,6,6,6,6,6,6,6,6,6,6,6,6,6,6,6,6,6,6,6,6,6,6,6,6,6,6,6,6,6,6,6,6,6,6,6,6,6,6,6,6,6,6
6,6,6,6,6,6,6,6,6,6,6,6,6,6,6,6,6,6,6,6,6,6,6,6,6,6,6,6,6,6,6,6,6,6,6,6,6,6,6,6,6,6,6,6,6,6
6,6,6,1,1,1,1,1,1,1,1,1,1,1,1,1,1,1,1,1,1,1,1,1,1,1,1,1,1,1,1,1,1,1,1,1,1,1,1,1,1,1,1,1,6,6
6,6,6,1,0,0,0,0,7,0,0,1,0,0,0,0,0,0,0,0,0,1,0,0,1,0,0,1,0,0,0,0,0,0,0,0,0,0,0,0,0,0,0,1,6,6
6,6,6,1,0,0,0,0,0,0,0,0,0,0,0,0,0,0,0,0,0,76,0,0,0,0,0,76,0,0,0,0,0,0,0,0,0,0,0,0,0,0,0,1,6,6
6,6,6,1,0,0,0,0,0,0,0,0,0,0,0,0,0,0,0,0,0,76,110,1,1,1,107,76,0,0,0,0,0,0,0,0,0,0,0,0,0,0,0,1,6,6
6,6,6,1,0,0,0,0,0,0,0,0,0,0,0,0,0,0,0,0,0,76,0,0,0,0,0,1,0,0,0,0,0,0,0,0,0,0,0,1,0,0,0,1,6,6
6,6,6,1,0,0,0,0,1,0,0,1,0,0,1,0,0,1,0,0,0,76,0,0,0,0,0,76,0,0,0,0,0,0,0,0,0,0,0,1,0,0,0,1,6,6
6,6,6,1,0,0,0,0,0,0,0,0,0,0,0,0,0,0,0,0,0,76,0,0,0,0,0,76,0,0,0,0,0,0,0,0,0,0,0,0,0,0,0,1,6,6
6,6,6,1,0,0,0,0,0,0,0,0,0,0,0,0,0,0,0,0,0,76,0,0,0,0,0,76,0,0,0,0,0,0,0,0,0,0,0,0,0,0,0,1,6,6
6,6,6,1,0,0,0,0,0,0,0,0,0,0,0,0,0,0,0,0,0,76,0,0,0,0,0,7,0,0,0,0,0,0,0,0,0,0,0,0,0,0,0,1,6,6
6,6,6,1,0,0,0,0,0,0,0,0,0,0,0,0,0,0,0,0,0,7,0,0,0,0,0,1,1,1,1,1,1,1,1,1,1,1,1,1,1,90,1,1,6,6
6,6,6,1,7,7,7,7,7,7,7,7,7,7,7,7,7,7,7,7,7,7,0,0,0,0,0,1,0,0,0,0,0,0,1,7,1,1,1,1,0,0,0,1,6,6
6,6,6,1,0,0,0,0,0,0,0,0,0,0,0,0,0,0,0,0,0,76,0,0,0,0,0,1,0,0,0,0,0,0,1,1,1,1,1,1,0,0,0,1,6,6
6,6,6,1,0,0,0,0,0,0,0,0,0,0,0,0,0,0,0,0,0,76,0,0,0,0,0,1,0,0,0,0,0,0,1,1,1,1,1,1,0,0,0,1,6,6
6,6,6,1,0,0,0,0,0,0,0,0,0,0,0,0,0,0,0,0,0,76,0,0,0,0,0,1,0,0,0,0,0,0,7,1,1,1,1,1,0,0,0,1,6,6
6,6,6,1,0,0,0,0,0,0,0,0,0,0,0,0,0,0,0,0,0,76,0,0,0,0,0,1,76,76,76,76,76,76,7,1,1,1,1,1,0,0,0,1,6,6
6,6,6,1,0,0,0,0,0,0,0,0,0,51,0,0,0,0,0,0,0,1,0,0,0,0,0,1,0,0,0,0,0,0,7,1,1,1,1,1,0,0,0,1,6,6
6,6,6,1,7,7,7,1,1,7,7,7,1,7,1,7,1,1,7,7,7,7,0,0,0,0,0,1,76,76,76,76,76,76,7,1,1,1,1,1,0,0,0,1,6,6
6,6,6,1,0,0,0,0,0,0,0,1,0,0,0,0,0,1,0,0,0,76,0,0,0,0,0,1,0,0,0,0,0,0,1,1,1,1,1,1,0,0,0,1,6,6
6,6,6,1,0,0,0,0,0,0,0,1,0,0,0,0,0,1,0,0,0,76,0,0,0,0,0,1,0,0,0,0,0,0,1,1,1,1,1,1,0,0,0,1,6,6
6,6,6,1,0,0,0,0,0,0,0,1,0,0,0,0,0,1,0,0,0,76,0,0,0,0,0,1,0,0,0,0,0,0,1,1,1,1,1,1,1,90,1,1,6,6
6,6,6,1,0,0,0,0,0,0,0,1,0,0,0,0,0,1,0,0,0,76,0,0,0,0,0,1,0,0,0,0,0,0,1,1,1,1,1,1,0,0,0,1,6,6
6,6,6,1,0,0,0,0,0,0,0,1,0,0,0,0,0,1,0,0,0,76,111,0,0,0,108,1,0,0,0,0,0,0,1,1,1,1,1,1,0,0,0,1,6,6
6,6,6,1,1,1,1,1,1,1,1,1,1,1,1,1,1,1,1,1,1,1,0,35,35,35,0,1,0,0,0,0,0,0,1,1,1,1,1,1,0,0,0,1,6,6
6,6,6,1,51,0,0,113,0,51,35,51,0,57,57,57,57,57,57,57,0,76,0,1,1,1,0,7,7,1,1,7,1,1,7,7,7,7,7,1,7,89,7,1,6,6
6,6,6,1,0,0,0,0,0,0,35,0,0,51,0,0,0,0,0,0,0,76,0,1,1,1,0,76,0,0,0,7,0,0,7,0,7,0,0,1,7,0,7,1,6,6
6,6,6,1,115,0,0,0,0,0,35,0,0,57,57,57,57,57,57,57,0,76,76,1,109,1,76,76,0,0,0,7,0,0,7,0,7,0,0,1,0,0,0,1,6,6
6,6,6,1,0,0,0,0,51,51,35,0,0,0,0,0,0,0,0,0,0,76,0,0,0,0,0,76,0,0,0,7,7,7,7,0,7,0,0,1,7,0,0,1,6,6
6,6,6,1,0,0,0,0,0,0,35,0,0,57,57,57,57,57,57,57,0,76,0,0,0,0,0,76,0,0,0,7,0,0,7,0,7,7,7,1,1,0,0,1,6,6
6,6,6,1,51,0,0,0,0,51,35,0,0,0,0,0,0,0,0,0,0,76,0,0,0,0,0,76,0,0,0,7,0,0,7,0,7,0,0,1,1,0,0,1,6,6
6,6,6,1,0,0,0,0,0,51,35,0,0,0,0,0,0,0,74,69,0,76,0,0,0,0,0,76,0,0,0,7,1,1,7,0,1,0,0,1,1,0,0,1,6,6
6,6,6,1,0,0,0,0,0,0,35,0,57,57,57,57,57,57,57,57,57,1,0,0,0,0,0,1,0,0,0,1,0,0,7,0,1,0,0,1,37,0,0,1,6,6
6,6,6,1,0,0,0,0,0,0,35,0,57,0,0,0,0,0,0,0,0,76,0,0,0,0,0,76,0,0,0,7,1,1,7,0,7,1,7,1,0,0,0,1,6,6
6,6,6,1,0,0,0,0,0,0,35,0,0,0,0,0,0,0,0,0,0,76,0,0,0,0,0,76,0,0,0,1,0,0,7,0,1,0,0,1,0,0,0,1,6,6
6,6,6,1,0,0,0,0,0,0,35,0,57,0,0,0,0,0,0,0,0,76,0,0,0,0,0,76,0,0,0,1,0,0,7,0,1,0,0,1,7,89,7,1,6,6
6,6,6,1,0,0,114,0,112,0,35,0,57,57,57,57,57,57,57,57,57,1,0,0,1,0,0,1,0,0,0,7,0,0,7,0,7,0,0,106,0,0,0,0,6,6
6,6,6,1,1,1,1,1,1,1,1,1,1,1,1,1,1,1,1,1,1,1,1,1,1,1,1,1,1,1,1,1,1,1,1,1,1,1,1,1,1,1,1,1,6,6
6,6,6,6,6,6,6,6,6,6,6,6,6,6,6,6,6,6,6,6,6,6,6,6,6,6,6,6,6,6,6,6,6,6,6,6,6,6,6,6,6,6,6,6,6,6
6,6,6,6,6,6,6,6,6,6,6,6,6,6,6,6,6,6,6,6,6,6,6,6,6,6,6,6,6,6,6,6,6,6,6,6,6,6,6,6,6,6,6,6,6,6
:endlayer
layer: 5
6,6,6,6,6,6,6,6,6,6,6,6,6,6,6,6,6,6,6,6,6,6,6,6,6,6,6,6,6,6,6,6,6,6,6,6,6,6,6,6,6,6,6,6,6,6
6,6,6,6,6,6,6,6,6,6,6,6,6,6,6,6,6,6,6,6,6,6,6,6,6,6,6,6,6,6,6,6,6,6,6,6,6,6,6,6,6,6,6,6,6,6
6,6,6,6,6,6,6,6,6,6,6,6,6,6,6,6,6,6,6,6,6,6,6,6,6,6,6,6,6,6,6,6,6,6,6,6,6,6,6,6,6,6,6,6,6,6
6,6,6,1,1,1,1,1,1,1,1,1,1,1,1,1,1,1,1,1,1,1,1,1,1,1,1,1,1,1,1,1,1,1,1,1,1,1,1,1,1,1,1,1,6,6
6,6,6,1,0,0,0,0,7,0,0,1,0,0,0,0,0,0,0,0,0,1,0,0,1,0,0,1,0,0,0,0,0,0,0,0,0,0,0,0,0,0,0,1,6,6
6,6,6,1,0,0,0,0,121,121,121,121,0,0,0,0,0,0,0,0,0,1,0,0,0,0,0,1,0,0,0,0,0,0,0,0,0,0,0,0,0,0,0,1,6,6
6,6,6,1,0,0,0,0,0,0,0,0,0,0,0,0,0,0,0,0,0,1,0,0,1,0,0,1,0,0,0,0,0,0,0,0,0,0,0,0,0,0,0,1,6,6
6,6,6,1,0,0,0,0,0,0,0,0,0,0,0,0,0,0,0,0,0,1,0,0,0,0,0,1,0,0,0,0,0,0,0,0,0,0,0,116,0,0,0,1,6,6
6,6,6,1,0,0,0,0,1,0,0,1,0,0,1,0,0,1,0,0,0,1,0,0,0,0,0,1,0,0,0,0,0,0,0,0,0,0,0,117,0,0,0,1,6,6
6,6,6,1,0,0,0,0,0,0,0,0,0,0,0,0,0,0,0,0,0,1,0,0,0,0,0,1,0,0,0,0,0,0,0,0,0,0,0,0,0,0,0,1,6,6
6,6,6,1,0,0,0,0,0,0,0,0,0,0,0,0,0,0,0,0,0,1,0,0,0,0,0,1,0,0,0,0,0,0,0,0,0,0,0,0,0,0,0,1,6,6
6,6,6,1,0,0,0,0,0,0,0,0,0,0,0,0,0,0,0,0,0,1,0,0,0,0,0,1,0,0,0,0,0,0,0,0,0,0,0,0,0,0,0,1,6,6
6,6,6,1,0,0,0,0,0,0,0,0,0,0,0,0,0,0,0,0,0,1,0,0,0,0,0,1,1,1,1,1,1,1,1,1,1,7,1,1,1,1,1,1,6,6
6,6,6,1,7,7,7,7,7,7,7,7,7,7,7,7,7,7,7,7,7,1,0,0,0,0,0,76,0,0,0,0,0,0,76,0,0,0,118,1,0,0,0,1,6,6
6,6,6,1,51,0,0,0,0,0,0,51,0,0,0,0,0,0,0,0,0,1,0,0,0,0,0,76,0,0,0,0,0,0,76,0,0,0,0,76,0,0,0,1,6,6
6,6,6,1,0,0,0,0,0,0,0,0,0,0,0,0,0,0,0,0,0,1,0,0,0,0,0,76,0,0,0,0,0,0,76,0,0,0,0,1,0,0,0,1,6,6
6,6,6,1,0,0,0,0,0,0,0,0,0,0,0,0,0,0,0,0,0,1,0,0,0,0,0,76,0,0,0,0,0,0,76,0,0,0,0,76,0,0,0,1,6,6
6,6,6,1,0,0,0,0,0,0,0,0,0,0,0,0,0,0,0,0,0,1,0,0,0,0,0,76,76,76,76,76,76,76,1,0,0,0,0,1,0,0,0,1,6,6
6,6,6,1,0,0,0,0,0,0,0,0,0,51,51,0,0,0,0,0,0,1,0,0,0,0,0,1,0,0,0,0,0,0,36,0,0,0,0,76,0,0,0,1,6,6
6,6,6,1,1,1,1,1,1,1,1,1,1,1,1,1,1,1,1,1,1,1,0,0,0,0,0,76,76,76,76,76,76,76,1,0,0,0,0,1,0,0,0,1,6,6
6,6,6,1,1,1,1,1,1,1,1,1,1,1,1,1,1,1,1,1,1,1,0,0,0,0,0,76,0,0,0,0,0,0,76,0,0,0,0,76,0,0,0,1,6,6
6,6,6,1,1,1,1,1,1,1,1,1,1,1,1,1,1,1,1,1,1,1,0,0,0,0,0,76,0,0,0,0,0,0,76,0,0,0,0,1,0,0,0,1,6,6
6,6,6,1,1,1,1,1,1,1,1,1,1,1,1,1,1,1,1,1,1,1,0,0,0,0,0,76,0,0,0,0,0,0,76,0,0,0,0,1,1,1,1,1,6,6
6,6,6,1,1,1,1,1,1,1,1,1,1,1,1,1,1,1,1,1,1,1,0,0,0,0,0,76,0,0,0,0,0,0,76,0,0,0,0,1,0,0,0,1,6,6
6,6,6,1,1,1,1,1,1,1,1,1,1,1,1,1,1,1,1,1,1,1,0,0,0,0,0,76,0,0,0,0,0,0,76,0,0,0,0,1,0,0,0,1,6,6
6,6,6,1,1,1,1,1,1,1,1,1,1,1,1,1,1,1,1,1,1,1,0,0,0,0,0,76,0,0,0,0,0,0,1,0,1,35,7,1,0,0,0,1,6,6
6,6,6,1,0,0,0,0,0,0,35,51,0,57,57,57,57,57,57,57,0,1,0,35,35,35,0,1,7,76,7,7,7,1,7,76,1,7,1,1,7,98,7,1,6,6
6,6,6,1,0,0,0,0,0,0,35,0,0,51,0,0,0,0,0,0,0,1,0,1,1,1,0,1,0,0,0,7,7,7,7,0,1,1,1,1,7,7,7,1,6,6
6,6,6,1,0,0,0,0,0,0,35,0,0,57,57,57,57,57,57,57,0,1,76,1,0,1,76,1,0,0,0,7,7,7,7,119,1,1,1,1,7,99,0,1,6,6
6,6,6,1,0,0,0,0,0,0,35,0,0,0,0,0,0,0,0,0,0,1,0,0,0,0,0,1,0,0,0,7,7,7,7,119,1,1,1,1,7,0,0,1,6,6
6,6,6,1,0,0,0,0,0,0,35,0,0,57,57,57,57,57,57,57,69,1,0,0,0,0,0,1,0,0,0,7,7,7,7,119,1,1,1,1,1,0,0,1,6,6
6,6,6,1,0,0,0,0,0,0,35,0,0,0,0,0,0,0,0,0,120,1,0,0,0,0,0,1,0,0,0,7,7,7,7,1,1,1,1,1,1,0,0,1,6,6
6,6,6,1,0,0,0,0,0,0,35,0,0,0,0,0,0,0,0,0,74,1,0,0,0,0,0,1,0,0,0,7,1,1,7,119,1,1,1,1,37,0,0,1,6,6
6,6,6,1,122,0,0,0,0,0,35,0,57,57,57,57,57,57,57,57,120,1,0,0,0,0,0,1,0,0,0,1,0,0,7,119,1,1,1,1,0,0,0,1,6,6
6,6,6,1,0,0,0,0,0,0,35,0,57,0,0,0,0,0,0,57,120,1,0,0,0,0,0,1,0,0,0,7,7,7,7,119,1,1,1,1,0,0,0,1,6,6
6,6,6,1,0,0,0,0,0,0,35,0,57,0,0,0,0,0,0,57,120,1,0,0,0,0,0,1,0,0,0,1,7,7,7,119,1,1,1,1,0,98,0,1,6,6
6,6,6,1,0,0,0,0,0,0,35,0,57,0,0,0,0,0,0,57,120,1,0,0,51,0,0,1,0,0,0,1,7,7,7,119,1,1,1,1,7,1,1,1,6,6
6,6,6,1,0,0,0,0,0,0,35,0,57,57,57,57,57,57,57,57,120,1,51,0,1,0,0,1,0,0,0,7,7,7,7,1,1,1,1,1,0,0,0,1,6,6
6,6,6,1,1,1,1,1,1,1,1,1,1,1,1,1,1,1,1,1,1,1,1,1,1,1,1,1,1,1,1,1,1,1,1,1,1,1,1,1,1,1,1,1,6,6
6,6,6,6,6,6,6,6,6,6,6,6,6,6,6,6,6,6,6,6,6,6,6,6,6,6,6,6,6,6,6,6,6,6,6,6,6,6,6,6,6,6,6,6,6,6
6,6,6,6,6,6,6,6,6,6,6,6,6,6,6,6,6,6,6,6,6,6,6,6,6,6,6,6,6,6,6,6,6,6,6,6,6,6,6,6,6,6,6,6,6,6
:endlayer
layer: 6
6,6,6,6,6,6,6,6,6,6,6,6,6,6,6,6,6,6,6,6,6,6,6,6,6,6,6,6,6,6,6,6,6,6,6,6,6,6,6,6,6,6,6,6,6,6
6,6,6,6,6,6,6,6,6,6,6,6,6,6,6,6,6,6,6,6,6,6,6,6,6,6,6,6,6,6,6,6,6,6,6,6,6,6,6,6,6,6,6,6,6,6
6,6,6,6,6,6,6,6,6,6,6,6,6,6,6,6,6,6,6,6,6,6,6,6,6,6,6,6,6,6,6,6,6,6,6,6,6,6,6,6,6,6,6,6,6,6
6,6,6,1,1,1,1,1,1,1,1,1,1,1,1,1,1,1,1,1,1,1,1,1,1,1,1,1,1,1,1,1,1,1,1,1,1,1,1,1,1,1,1,1,6,6
6,6,6,1,0,0,0,0,7,1,1,7,0,0,7,0,0,7,0,0,0,1,0,0,1,0,0,1,0,0,0,0,0,0,0,0,0,0,0,0,0,0,0,1,6,6
6,6,6,1,0,0,0,0,7,1,1,7,0,0,7,0,0,7,0,0,0,1,0,0,0,0,0,1,0,0,0,0,0,0,0,0,0,0,0,0,0,0,0,1,6,6
6,6,6,1,0,0,0,0,7,0,0,7,0,0,7,0,0,7,0,0,0,1,0,0,1,0,0,1,0,0,0,0,0,0,0,0,0,0,0,0,0,0,0,1,6,6
6,6,6,1,0,0,0,0,7,0,0,7,0,0,7,0,0,7,0,0,0,1,0,0,0,0,0,1,0,0,0,0,0,0,0,0,0,0,0,0,0,0,0,1,6,6
6,6,6,1,7,7,7,7,7,7,7,7,7,7,7,7,7,7,7,7,7,1,0,0,0,0,0,1,0,0,0,0,0,0,0,0,0,0,0,0,0,0,0,1,6,6
6,6,6,1,0,0,0,0,7,0,0,7,0,0,7,0,0,7,0,0,0,1,0,0,0,0,0,1,0,0,0,0,0,0,0,0,0,0,0,0,0,0,0,1,6,6
6,6,6,1,0,0,0,0,7,0,0,7,0,0,7,0,0,7,0,0,0,1,0,0,0,0,0,1,0,0,0,0,0,0,0,0,0,0,0,0,0,0,0,1,6,6
6,6,6,1,0,0,0,0,7,0,0,7,0,0,7,0,0,7,0,0,0,1,0,0,0,0,0,1,0,0,0,0,0,0,0,0,0,0,0,0,0,0,0,1,6,6
6,6,6,1,0,0,0,0,7,0,0,7,0,0,7,0,0,7,0,0,0,1,0,0,0,0,0,1,1,1,1,1,1,1,1,76,1,76,1,1,1,1,1,1,6,6
6,6,6,1,7,7,7,7,7,7,7,7,7,7,7,7,7,7,7,7,7,1,0,0,0,0,0,1,0,0,0,0,0,0,0,0,0,0,0,1,0,0,0,1,6,6
6,6,6,1,1,76,76,76,7,76,76,7,76,76,7,76,76,7,76,76,7,1,0,0,0,0,0,1,0,0,0,0,0,0,0,0,0,0,0,76,0,0,0,1,6,6
6,6,6,1,7,76,76,76,7,76,76,7,76,76,7,76,76,7,76,76,7,1,0,0,0,0,0,1,0,0,0,0,0,0,0,0,0,0,0,1,0,0,0,1,6,6
6,6,6,1,7,76,76,76,7,76,76,7,76,76,7,76,76,7,76,76,7,1,0,0,0,0,0,1,0,0,0,0,0,0,0,0,0,0,0,76,0,0,0,1,6,6
6,6,6,1,7,76,76,76,7,76,76,7,76,76,7,76,76,7,76,76,7,1,1,1,1,1,1,1,1,1,1,1,1,1,1,0,0,0,0,1,0,0,0,1,6,6
6,6,6,7,7,7,7,7,37,7,7,7,7,7,37,7,7,37,7,7,1,1,1,1,7,1,1,1,1,1,1,1,1,36,0,0,0,0,0,76,0,0,0,1,6,6
6,6,6,1,1,148,0,0,0,145,144,132,141,141,0,138,138,0,0,0,37,1,1,1,1,1,1,1,1,1,1,1,1,1,1,0,0,0,0,1,0,0,0,1,6,6
6,6,6,1,150,149,0,0,0,0,144,0,0,141,0,138,0,0,0,0,0,1,0,0,0,0,0,1,0,0,0,0,0,0,0,0,0,0,0,76,0,0,0,1,6,6
6,6,6,1,151,0,0,0,0,0,0,0,0,0,0,0,0,0,0,0,0,1,0,0,0,0,0,1,0,0,0,0,0,0,0,0,0,0,0,1,0,0,0,1,6,6
6,6,6,1,152,0,0,0,0,0,0,0,0,0,0,0,0,0,0,0,0,1,0,0,0,0,0,1,0,0,0,0,0,0,0,0,0,0,0,1,7,7,7,1,6,6
6,6,6,1,132,0,0,139,0,0,0,139,0,0,0,139,0,0,0,0,0,1,0,0,0,0,0,1,0,0,0,0,0,0,0,0,0,0,0,1,7,7,7,1,6,6
6,6,6,1,7,148,0,147,0,146,0,143,0,142,0,140,0,137,1,0,0,1,0,0,0,0,0,1,0,0,0,0,0,0,0,0,0,0,0,1,7,0,7,1,6,6
6,6,6,1,1,1,1,1,1,1,1,1,1,1,1,1,1,1,1,1,1,1,0,0,0,0,0,1,0,0,0,0,0,0,1,0,1,0,7,1,7,7,7,1,6,6
6,6,6,1,0,0,0,0,0,0,35,51,0,57,57,57,57,57,57,57,74,1,0,0,0,0,0,1,7,1,1,7,7,7,1,7,1,28,1,1,7,37,7,1,6,6
6,6,6,1,0,0,0,0,0,0,35,0,0,74,74,74,74,74,74,74,74,1,0,35,35,35,0,1,0,0,0,7,131,129,128,127,124,0,124,1,0,0,123,1,6,6
6,6,6,1,0,0,0,0,0,0,35,0,0,74,74,74,74,74,74,74,74,1,76,1,0,1,76,1,0,0,0,7,0,0,0,0,0,0,0,1,0,0,0,1,6,6
6,6,6,1,0,0,0,0,0,0,35,0,0,74,74,74,74,74,74,74,74,1,0,0,0,0,0,1,0,0,0,7,132,0,0,0,0,0,0,1,0,0,0,1,6,6
6,6,6,1,0,0,0,0,0,0,35,0,0,74,74,74,74,74,74,74,74,1,0,0,0,0,0,1,0,0,0,7,133,0,0,0,0,0,0,1,0,0,0,1,6,6
6,6,6,1,0,0,0,0,0,0,35,0,0,74,74,74,74,74,74,74,0,1,0,0,0,0,0,1,0,0,0,7,134,0,0,0,0,0,0,22,0,0,0,1,6,6
6,6,6,1,0,0,0,0,0,0,35,0,0,74,74,74,74,0,0,0,0,1,0,0,0,0,0,1,0,0,0,7,1,1,7,0,0,0,0,1,0,0,0,1,6,6
6,6,6,1,0,0,0,0,0,0,35,0,74,74,74,74,74,74,74,74,0,1,0,0,0,0,0,1,0,0,0,1,0,0,76,0,0,0,0,1,0,0,0,1,6,6
6,6,6,1,0,0,51,51,0,0,35,0,74,74,74,74,74,74,74,74,74,1,0,0,0,0,0,1,0,0,0,7,7,7,7,0,0,0,0,1,0,0,0,1,6,6
6,6,6,1,0,0,0,51,0,0,35,0,74,74,74,74,74,74,74,74,74,1,0,0,0,0,0,1,0,0,0,1,135,130,0,0,0,0,0,1,0,0,0,1,6,6
6,6,6,1,0,0,0,51,51,0,35,0,74,74,74,74,74,74,74,74,74,1,0,0,51,0,0,1,0,0,0,1,136,0,0,0,125,0,125,1,1,1,1,1,6,6
6,6,6,1,0,0,0,0,51,51,35,0,57,57,57,57,57,57,57,57,74,1,0,0,1,0,0,1,0,0,0,1,135,130,0,0,126,0,126,1,0,0,0,1,6,6
6,6,6,1,1,1,1,1,1,1,1,1,1,1,1,1,1,1,1,1,1,1,1,1,1,1,1,1,1,1,1,1,1,1,1,1,1,1,1,1,1,1,1,1,6,6
6,6,6,6,6,6,6,6,6,6,6,6,6,6,6,6,6,6,6,6,6,6,6,6,6,6,6,6,6,6,6,6,6,6,6,6,6,6,6,6,6,6,6,6,6,6
6,6,6,6,6,6,6,6,6,6,6,6,6,6,6,6,6,6,6,6,6,6,6,6,6,6,6,6,6,6,6,6,6,6,6,6,6,6,6,6,6,6,6,6,6,6
:endlayer
layer: 7
6,6,6,6,6,6,6,6,6,6,6,6,6,6,6,6,6,6,6,6,6,6,6,6,6,6,6,6,6,6,6,6,6,6,6,6,6,6,6,6,6,6,6,6,6,6
6,6,6,6,6,6,6,6,6,6,6,6,6,6,6,6,6,6,6,6,6,6,6,6,6,6,6,6,6,6,6,6,6,6,6,6,6,6,6,6,6,6,6,6,6,6
6,6,6,6,6,6,6,6,6,6,6,6,6,6,6,6,6,6,6,6,6,6,6,6,6,6,6,6,6,6,6,6,6,6,6,6,6,6,6,6,6,6,6,6,6,6
6,6,6,1,1,1,1,1,1,1,1,1,1,1,1,1,1,1,1,1,1,1,1,1,1,1,1,1,1,1,1,1,1,1,1,1,1,1,1,1,1,1,1,1,6,6
6,6,6,1,0,0,0,0,0,1,1,0,0,0,164,0,0,0,0,0,0,1,0,0,1,0,0,1,0,0,0,0,0,0,0,0,0,0,0,0,0,0,0,1,6,6
6,6,6,1,0,0,0,0,0,0,0,0,0,0,0,0,0,0,0,0,0,1,0,0,1,0,0,1,0,0,0,0,0,0,0,0,0,0,0,0,0,0,0,1,6,6
6,6,6,1,0,0,0,0,0,0,0,0,0,0,0,0,0,0,0,0,0,1,0,0,1,0,0,1,0,0,0,0,0,0,0,0,0,0,0,0,0,0,0,1,6,6
6,6,6,1,0,0,0,0,0,0,0,0,0,0,0,0,0,0,0,0,0,1,0,0,0,0,0,1,0,0,0,0,0,0,0,0,0,0,0,0,0,0,0,1,6,6
6,6,6,0,169,0,0,0,0,0,0,0,0,0,0,0,0,0,0,0,101,1,0,0,0,0,0,1,0,0,0,0,0,0,0,0,0,0,0,0,0,0,0,1,6,6
6,6,6,1,0,0,0,0,0,0,0,0,0,0,0,0,0,0,0,0,0,1,0,0,0,0,0,1,0,0,0,0,0,0,0,0,0,0,0,0,0,0,0,1,6,6
6,6,6,1,0,0,0,0,0,0,0,167,0,0,0,0,0,162,0,0,0,1,0,0,0,0,0,1,0,0,0,0,0,0,0,0,0,0,0,0,0,0,0,1,6,6
6,6,6,1,0,0,0,0,0,0,0,0,0,0,0,0,0,0,0,0,0,1,0,0,0,0,0,1,0,0,0,0,0,0,0,0,0,0,0,0,0,0,0,1,6,6
6,6,6,1,0,0,0,0,0,0,0,0,0,0,0,0,0,0,0,0,0,1,0,0,0,0,0,1,1,1,1,1,1,1,1,76,1,76,1,1,1,1,1,1,6,6
6,6,6,1,7,7,7,7,0,7,7,0,7,7,0,7,7,0,7,7,0,1,0,0,0,0,0,1,0,0,0,0,0,0,0,0,0,0,0,1,0,0,0,1,6,6
6,6,6,1,0,0,0,0,0,0,0,0,0,0,0,0,0,0,0,0,0,1,0,0,0,0,0,1,0,0,0,0,0,0,0,0,0,0,0,1,0,0,0,1,6,6
6,6,6,1,0,0,0,0,0,0,0,0,0,0,0,0,0,0,0,0,0,1,0,0,0,0,0,1,0,0,0,0,0,0,0,0,0,0,0,1,0,0,0,1,6,6
6,6,6,1,0,0,0,0,0,0,0,0,0,0,0,0,0,0,0,0,0,1,0,0,0,0,0,1,0,0,0,0,0,0,0,0,0,0,0,1,0,0,0,1,6,6
6,6,6,1,0,0,0,0,0,0,0,0,0,0,0,0,0,0,0,0,0,1,76,76,159,76,76,1,76,76,76,76,76,76,1,0,0,0,0,1,0,0,0,1,6,6
6,6,6,7,7,7,7,7,0,7,7,7,7,7,0,7,7,0,7,7,0,0,0,0,0,0,0,0,0,0,0,0,0,0,0,0,0,0,0,1,0,0,0,1,6,6
6,6,6,1,7,0,0,0,0,145,168,0,141,165,0,138,138,0,0,0,0,1,76,76,160,76,76,1,76,76,76,76,76,76,1,0,0,0,0,1,0,0,0,1,6,6
6,6,6,1,0,0,0,0,0,0,0,0,0,0,0,0,0,0,0,0,0,1,0,0,0,0,0,1,0,0,0,0,0,0,0,0,0,0,0,1,0,0,0,1,6,6
6,6,6,1,0,0,0,0,0,0,0,0,0,0,0,0,0,0,0,0,0,1,0,0,0,0,0,1,0,0,0,0,0,0,0,0,0,0,0,1,0,0,0,1,6,6
6,6,6,1,0,0,0,0,0,0,0,0,0,0,0,0,0,0,0,0,0,1,0,0,0,0,0,1,0,0,0,0,0,0,0,0,0,0,0,1,7,7,7,1,6,6
6,6,6,1,0,0,0,0,0,0,0,0,0,0,0,0,0,0,0,0,0,1,0,0,0,0,0,1,0,0,0,0,0,0,0,0,0,0,0,1,0,101,0,1,6,6
6,6,6,1,1,0,0,0,0,0,0,0,0,0,0,0,0,0,1,74,74,1,0,0,0,0,0,1,0,0,0,0,0,0,0,0,0,0,0,1,0,0,0,1,6,6
6,6,6,1,1,1,1,1,1,1,1,1,1,1,1,1,1,1,1,1,1,1,0,0,0,0,0,1,0,0,0,0,0,0,1,0,1,0,7,1,0,0,0,1,6,6
6,6,6,1,51,0,0,0,0,0,35,51,0,57,57,57,57,57,57,57,0,1,0,0,0,0,0,1,7,1,7,7,7,7,1,76,1,89,1,1,7,0,7,1,6,6
6,6,6,1,0,0,0,0,0,0,35,0,0,0,0,0,163,0,0,0,0,1,0,0,0,0,0,1,0,0,0,7,157,155,154,0,124,0,124,1,0,0,0,1,6,6
6,6,6,1,0,0,0,0,0,0,35,0,0,0,0,0,0,0,0,0,0,1,76,35,35,35,76,1,0,0,0,7,0,0,0,0,0,0,0,1,0,0,0,1,6,6
6,6,6,1,0,0,0,0,0,0,35,0,0,0,0,0,0,0,0,0,103,1,0,1,1,1,0,1,0,0,0,7,158,0,0,0,0,0,0,76,0,0,0,1,6,6
6,6,6,1,51,51,0,0,0,0,35,0,0,0,0,0,0,0,0,0,0,1,0,1,1,1,0,1,0,0,0,7,0,0,0,0,0,0,0,1,0,0,0,1,6,6
6,6,6,1,0,0,0,0,0,0,35,0,0,0,0,0,0,0,0,0,0,1,0,0,0,0,0,1,0,0,0,7,0,156,0,0,0,0,0,153,0,0,0,1,6,6
6,6,6,1,0,0,0,0,0,0,35,0,0,0,0,0,0,0,0,0,0,1,0,0,0,0,0,1,0,0,0,7,1,1,7,0,0,0,0,1,0,0,0,1,6,6
6,6,6,1,0,0,0,0,0,0,35,0,166,0,0,0,0,0,161,0,0,1,0,0,0,0,0,1,0,0,0,1,0,0,76,0,0,0,0,76,0,0,0,1,6,6
6,6,6,1,0,0,0,51,0,0,35,0,0,0,0,0,0,0,0,0,0,1,0,0,0,0,0,1,0,0,0,7,7,7,7,0,0,0,0,1,0,0,0,1,6,6
6,6,6,1,0,0,0,0,0,0,35,0,0,0,0,0,0,0,0,0,103,1,0,0,0,0,0,1,0,0,0,1,0,0,0,0,0,0,0,1,0,0,0,1,6,6
6,6,6,1,0,0,0,0,51,51,35,0,0,0,0,0,0,0,0,0,0,1,0,0,51,0,0,1,0,0,0,1,158,0,0,0,0,0,0,1,1,1,1,1,6,6
6,6,6,1,0,0,0,0,0,51,35,0,57,57,57,57,57,57,57,57,0,1,0,0,1,51,0,1,0,0,0,1,0,0,0,0,0,0,0,1,0,0,0,1,6,6
6,6,6,1,1,1,1,1,1,1,1,1,1,1,1,1,1,1,1,1,1,1,1,1,1,1,1,1,1,1,1,1,1,1,1,1,1,1,1,1,1,1,1,1,6,6
6,6,6,6,6,6,6,6,6,6,6,6,6,6,6,6,6,6,6,6,6,6,6,6,6,6,6,6,6,6,6,6,6,6,6,6,6,6,6,6,6,6,6,6,6,6
6,6,6,6,6,6,6,6,6,6,6,6,6,6,6,6,6,6,6,6,6,6,6,6,6,6,6,6,6,6,6,6,6,6,6,6,6,6,6,6,6,6,6,6,6,6
:endlayer
layer: 8
6,6,6,6,6,6,6,6,6,6,6,6,6,6,6,6,6,6,6,6,6,6,6,6,6,6,6,6,6,6,6,6,6,6,6,6,6,6,6,6,6,6,6,6,6,6
6,6,6,6,6,6,6,6,6,6,6,6,6,6,6,6,6,6,6,6,6,6,6,6,6,6,6,6,6,6,6,6,6,6,6,6,6,6,6,6,6,6,6,6,6,6
6,6,6,6,6,6,6,6,6,6,6,6,6,6,6,6,6,6,6,6,6,6,6,6,6,6,6,6,6,6,6,6,6,6,6,6,6,6,6,6,6,6,6,6,6,6
6,6,6,1,1,1,1,1,1,1,1,1,1,1,1,1,1,1,1,1,1,1,1,1,1,1,1,1,1,1,1,1,1,1,1,1,1,1,1,1,1,1,1,1,6,6
6,6,6,1,0,0,0,0,0,1,1,0,0,0,0,0,0,0,0,0,0,1,0,0,1,0,0,1,0,0,0,0,0,0,0,0,0,0,0,0,0,0,0,1,6,6
6,6,6,1,0,0,0,0,0,0,0,0,0,0,0,0,0,0,0,0,0,1,0,0,1,0,0,1,0,0,0,0,0,0,0,0,0,0,0,0,0,0,0,1,6,6
6,6,6,1,0,0,0,0,0,0,0,0,0,0,0,0,0,0,0,0,0,1,0,0,1,0,0,1,0,0,0,0,0,0,0,0,0,0,0,0,0,0,0,1,6,6
6,6,6,1,0,0,0,0,0,0,0,0,0,0,0,0,0,0,0,0,0,1,0,0,0,0,0,1,0,0,0,0,0,0,0,0,0,0,0,0,0,0,0,1,6,6
6,6,6,1,0,0,0,0,0,0,0,0,0,0,0,0,0,0,0,0,0,1,0,0,0,0,0,1,0,0,0,0,0,0,0,0,0,0,0,0,0,0,0,1,6,6
6,6,6,1,0,0,0,0,0,0,0,0,0,0,0,0,0,0,0,0,0,1,0,0,0,0,0,1,0,0,0,0,0,0,0,0,0,0,0,0,0,0,0,1,6,6
6,6,6,1,0,0,0,0,0,0,0,0,0,0,0,0,0,0,0,0,0,1,0,0,0,0,0,1,0,0,0,0,0,0,0,0,0,0,0,0,0,0,0,1,6,6
6,6,6,1,0,0,0,0,0,0,0,0,0,0,0,0,0,0,0,0,0,1,0,0,0,0,0,1,0,0,0,0,0,0,0,0,0,0,0,0,0,0,0,1,6,6
6,6,6,1,0,0,0,0,0,0,0,0,0,0,0,0,0,0,0,0,0,1,0,0,0,0,0,1,1,1,1,1,1,1,1,1,1,1,1,1,1,1,1,1,6,6
6,6,6,1,7,7,7,7,0,7,7,0,7,7,0,7,7,0,7,7,0,1,0,0,0,0,0,1,0,0,0,0,0,0,0,0,0,0,0,1,0,0,0,1,6,6
6,6,6,1,0,0,0,0,0,0,0,0,0,0,0,0,0,0,0,0,0,1,0,0,0,0,0,1,0,0,0,0,0,0,0,0,0,0,0,1,0,0,0,1,6,6
6,6,6,1,0,0,0,0,0,0,0,0,0,0,0,0,0,0,0,0,0,1,0,0,0,0,0,1,0,0,0,0,0,0,0,0,0,0,0,1,0,0,0,1,6,6
6,6,6,1,0,0,0,0,0,0,0,0,0,0,0,0,0,0,0,0,0,1,0,0,0,0,0,1,0,0,0,0,0,0,0,0,0,0,0,1,0,0,0,1,6,6
6,6,6,1,0,0,0,0,0,0,0,0,0,0,0,0,0,0,0,0,0,1,0,0,0,0,0,1,0,0,0,0,0,0,1,0,0,0,0,1,0,0,0,1,6,6
6,6,6,7,7,7,7,7,0,7,7,7,7,7,0,7,7,0,7,7,0,0,0,0,0,0,0,0,0,0,0,0,0,0,0,0,0,0,0,1,0,0,0,1,6,6
6,6,6,1,1,0,0,0,0,0,168,0,0,141,0,0,138,0,0,0,0,1,0,0,0,0,0,1,0,0,0,0,0,0,1,0,0,0,0,1,0,0,0,1,6,6
6,6,6,1,0,0,0,0,0,0,0,0,0,0,0,0,0,0,0,0,0,1,0,0,0,0,0,1,0,0,0,0,0,0,0,0,0,0,0,1,0,0,0,1,6,6
6,6,6,1,0,0,0,0,0,0,0,0,0,0,0,0,0,0,0,0,0,1,0,0,0,0,0,1,0,0,0,0,0,0,0,0,0,0,0,1,0,0,0,1,6,6
6,6,6,1,0,0,0,0,0,0,0,0,0,0,0,0,0,0,0,0,0,1,0,0,0,0,0,1,0,0,0,0,0,0,0,0,0,0,0,1,7,7,7,1,6,6
6,6,6,1,0,0,0,0,0,0,0,0,0,0,0,0,0,0,0,0,0,1,0,0,0,0,0,1,0,0,0,0,0,0,0,0,0,0,0,1,0,170,0,1,6,6
6,6,6,1,7,0,0,0,0,0,0,0,0,0,0,0,0,0,1,0,0,1,0,0,0,0,0,1,0,0,0,0,0,0,0,0,0,0,0,1,0,0,0,1,6,6
6,6,6,1,1,1,1,1,1,1,1,1,1,1,1,1,1,1,1,1,1,1,0,0,0,0,0,1,0,0,0,0,0,0,1,0,1,98,7,1,0,0,0,1,6,6
6,6,6,1,51,51,0,0,0,51,35,51,0,57,57,57,57,57,57,57,0,1,0,0,0,0,0,1,7,7,7,7,7,1,1,1,1,1,1,1,7,0,7,1,6,6
6,6,6,1,0,0,0,0,0,0,35,0,0,0,0,0,0,0,0,0,0,1,0,0,0,0,0,1,0,0,0,7,174,173,172,0,124,99,124,1,0,0,0,1,6,6
6,6,6,1,0,0,0,0,0,0,35,0,0,0,0,0,0,0,0,0,0,1,76,0,0,0,76,1,0,0,0,7,0,0,0,0,0,0,0,1,0,0,0,1,6,6
6,6,6,1,51,0,0,0,0,51,35,0,0,0,0,0,0,0,0,0,0,1,0,35,35,35,0,1,0,0,0,7,0,0,0,0,0,0,0,1,0,0,0,1,6,6
6,6,6,1,51,51,0,0,0,51,35,0,0,0,0,0,0,0,0,0,0,1,0,1,1,1,0,1,0,0,0,7,0,0,0,0,0,0,0,1,0,0,0,1,6,6
6,6,6,1,51,0,0,0,0,51,35,0,0,0,0,0,0,0,0,0,0,1,0,1,1,1,0,1,0,0,0,7,0,0,0,0,0,0,171,1,97,0,0,1,6,6
6,6,6,1,0,0,0,0,0,0,35,0,0,0,0,0,0,0,0,0,0,1,0,0,1,0,0,1,0,0,0,7,1,1,7,0,0,0,0,1,0,0,0,1,6,6
6,6,6,1,0,0,0,0,0,51,35,0,0,0,0,0,0,0,0,0,0,1,0,0,1,0,0,1,0,0,0,1,0,0,7,0,0,0,0,1,0,0,0,1,6,6
6,6,6,1,0,0,0,51,0,0,35,0,0,0,0,0,0,0,0,0,0,1,0,0,1,0,0,1,0,0,0,7,7,7,7,0,0,0,0,1,0,0,0,1,6,6
6,6,6,1,0,0,51,51,51,51,35,0,0,0,0,0,0,0,0,0,0,1,0,0,1,0,0,1,0,0,0,1,0,0,0,0,0,0,0,1,0,0,0,1,6,6
6,6,6,1,0,0,0,0,0,0,35,0,0,0,0,0,0,0,0,0,0,1,0,0,1,0,0,1,0,0,0,1,0,0,0,0,0,0,0,1,1,1,1,1,6,6
6,6,6,1,51,0,0,0,51,51,35,0,57,57,57,57,57,57,57,57,0,1,0,51,1,51,51,1,0,0,0,1,0,0,0,0,0,0,0,1,0,0,0,1,6,6
6,6,6,1,1,1,1,1,1,1,1,1,1,1,1,1,1,1,1,1,1,1,1,1,1,1,1,1,1,1,1,1,1,1,1,1,1,1,1,1,1,1,1,1,6,6
6,6,6,6,6,6,6,6,6,6,6,6,6,6,6,6,6,6,6,6,6,6,6,6,6,6,6,6,6,6,6,6,6,6,6,6,6,6,6,6,6,6,6,6,6,6
6,6,6,6,6,6,6,6,6,6,6,6,6,6,6,6,6,6,6,6,6,6,6,6,6,6,6,6,6,6,6,6,6,6,6,6,6,6,6,6,6,6,6,6,6,6
:endlayer
layer: 9
6,6,6,6,6,6,6,6,6,6,6,6,6,6,6,6,6,6,6,6,6,6,6,6,6,6,6,6,6,6,6,6,6,6,6,6,6,6,6,6,6,6,6,6,6,6
6,6,6,6,6,6,6,6,6,6,6,6,6,6,6,6,6,6,6,6,6,6,6,6,6,6,6,6,6,6,6,6,6,6,6,6,6,6,6,6,6,6,6,6,6,6
6,6,6,6,6,6,6,6,6,6,6,6,6,6,6,6,6,6,6,6,6,6,6,6,6,6,6,6,6,6,6,6,6,6,6,6,6,6,6,6,6,6,6,6,6,6
6,6,6,1,1,1,1,1,1,1,1,1,1,1,1,1,1,1,1,1,1,1,1,1,1,1,1,1,1,1,1,1,1,1,1,1,1,1,1,1,1,1,1,1,6,6
6,6,6,1,1,1,1,1,1,1,1,1,1,1,1,1,1,1,1,1,1,1,1,1,1,1,1,1,1,1,1,1,1,1,1,1,1,1,1,1,1,1,1,1,6,6
6,6,6,1,1,1,1,1,1,1,1,1,1,1,1,1,1,1,1,1,1,1,1,1,1,1,1,1,1,1,1,1,1,1,1,1,1,1,1,1,1,1,1,1,6,6
6,6,6,1,1,1,1,1,1,1,1,1,1,1,1,1,1,1,1,1,1,1,1,1,1,1,1,1,1,1,1,1,1,1,1,1,1,1,1,1,1,1,1,1,6,6
6,6,6,1,1,1,1,1,1,1,1,1,1,1,1,1,1,1,1,1,1,1,1,1,1,1,1,1,1,1,1,1,1,1,1,1,1,1,1,1,1,1,1,1,6,6
6,6,6,1,1,1,1,1,1,1,1,1,1,1,1,1,1,1,1,1,1,1,1,1,1,1,1,1,1,1,1,1,1,1,1,1,1,1,1,1,1,1,1,1,6,6
6,6,6,1,1,1,1,1,1,1,1,1,1,1,1,1,1,1,1,1,1,1,1,1,1,1,1,1,1,1,1,1,1,1,1,1,1,1,1,1,1,1,1,1,6,6
6,6,6,1,1,1,1,1,1,1,1,1,1,1,1,1,1,1,1,1,1,1,1,1,1,1,1,1,1,1,1,1,1,1,1,1,1,1,1,1,1,1,1,1,6,6
6,6,6,1,1,1,1,1,1,1,1,1,1,1,1,1,1,1,1,1,1,1,1,1,1,1,1,1,1,1,1,1,1,1,1,1,1,1,1,1,1,1,1,1,6,6
6,6,6,1,1,1,1,1,1,1,1,1,1,1,1,1,1,1,1,1,1,1,1,1,1,1,1,1,1,1,1,1,1,1,1,1,1,1,1,1,1,1,1,1,6,6
6,6,6,1,1,1,1,1,1,1,1,1,1,1,1,1,1,1,1,1,1,1,1,1,1,1,1,1,1,1,1,1,1,1,1,1,1,1,1,1,1,1,1,1,6,6
6,6,6,1,1,1,1,1,1,1,1,1,1,1,1,1,1,1,1,1,1,1,1,1,1,1,1,1,1,1,1,1,1,1,1,1,1,1,1,1,1,1,1,1,6,6
6,6,6,1,1,1,1,1,1,1,1,1,1,1,1,1,1,1,1,1,1,1,1,1,1,1,1,1,1,1,1,1,1,1,1,1,1,1,1,1,1,1,1,1,6,6
6,6,6,1,1,1,1,1,1,1,1,1,1,1,1,1,1,1,1,1,1,1,1,1,1,1,1,1,1,1,1,1,1,1,1,1,1,1,1,1,1,1,1,1,6,6
6,6,6,1,1,1,1,1,1,1,1,1,1,1,1,1,1,1,1,1,1,1,1,1,1,1,1,1,1,1,1,1,1,1,1,1,1,1,1,1,1,1,1,1,6,6
6,6,6,1,1,1,1,1,1,1,1,1,1,1,1,1,1,1,1,1,1,1,1,1,1,1,1,1,1,1,1,1,1,1,1,1,1,1,1,1,1,1,1,1,6,6
6,6,6,1,1,1,1,1,1,1,1,1,1,1,1,1,1,1,1,1,1,1,1,1,1,1,1,1,1,1,1,1,1,1,1,1,1,1,1,1,1,1,1,1,6,6
6,6,6,1,1,1,1,1,1,1,1,1,1,1,1,1,1,1,1,1,1,1,1,1,1,1,1,1,1,1,1,1,1,1,1,1,1,1,1,1,1,1,1,1,6,6
6,6,6,1,1,1,1,1,1,1,1,1,1,1,1,1,1,1,1,1,1,1,1,1,1,1,1,1,1,1,1,1,1,1,1,1,1,1,1,1,1,1,1,1,6,6
6,6,6,1,1,1,1,1,1,1,1,1,1,1,1,1,1,1,1,1,1,1,1,1,1,1,1,1,1,1,1,1,1,1,1,1,1,1,1,1,1,1,1,1,6,6
6,6,6,1,1,1,1,1,1,1,1,1,1,1,1,1,1,1,1,1,1,1,1,1,1,1,1,1,1,1,1,1,1,1,1,1,1,1,1,1,1,1,1,1,6,6
6,6,6,1,1,1,1,1,1,1,1,1,1,1,1,1,1,1,1,1,1,1,1,1,1,1,1,1,1,1,1,1,1,1,1,1,1,1,1,1,1,1,1,1,6,6
6,6,6,1,1,1,1,1,1,1,1,1,1,1,1,1,1,1,1,1,1,1,1,1,1,1,1,1,1,1,1,1,1,1,1,1,1,1,1,1,1,1,1,1,6,6
6,6,6,1,1,1,1,1,1,1,1,1,1,1,1,1,1,1,1,1,1,1,1,0,0,0,1,1,1,1,1,1,1,1,1,1,1,1,1,1,1,1,1,1,6,6
6,6,6,1,1,1,1,1,1,1,1,1,1,1,1,1,1,1,1,1,1,1,1,0,0,0,1,1,1,1,1,1,1,1,1,1,1,1,1,1,1,1,1,1,6,6
6,6,6,1,1,1,1,1,1,1,1,1,1,1,1,1,1,1,1,1,1,1,1,0,0,0,1,1,1,1,1,1,1,1,1,1,1,1,1,1,1,1,1,1,6,6
6,6,6,1,1,1,1,1,1,1,1,1,1,1,1,1,1,1,1,1,1,1,1,0,0,0,1,1,1,1,1,1,1,1,1,1,1,1,1,1,1,1,1,1,6,6
6,6,6,1,1,1,1,1,1,1,1,1,1,1,1,1,1,1,1,1,1,1,1,35,35,35,1,1,1,1,1,1,1,1,1,1,1,1,1,1,1,1,1,1,6,6
6,6,6,1,1,1,1,51,1,1,1,1,1,1,1,1,1,1,1,1,1,1,1,1,1,1,1,1,1,1,1,1,1,1,1,1,1,1,1,1,1,1,1,1,6,6
6,6,6,1,1,1,1,1,1,1,1,1,1,1,1,1,1,1,1,1,1,1,1,1,1,1,1,1,1,1,1,1,1,1,1,1,1,1,1,1,1,1,1,1,6,6
6,6,6,1,1,1,1,1,1,1,1,1,1,1,1,1,1,1,1,1,1,1,1,1,1,1,1,1,1,1,1,1,1,1,1,1,1,1,1,1,1,1,1,1,6,6
6,6,6,1,1,1,1,1,1,1,1,1,1,1,1,1,1,1,1,1,1,1,1,1,1,1,1,1,1,1,1,1,1,1,1,1,1,1,1,1,1,1,1,1,6,6
6,6,6,1,1,1,1,1,1,1,1,1,1,1,1,1,1,1,1,1,1,1,1,1,1,1,1,1,1,1,1,1,1,1,1,1,1,1,1,1,1,1,1,1,6,6
6,6,6,1,1,1,1,1,1,1,1,1,1,1,1,1,1,1,1,1,1,1,1,1,1,1,1,1,1,1,1,1,1,1,1,1,1,1,1,1,1,1,1,1,6,6
6,6,6,1,1,1,1,1,1,1,1,1,1,1,1,1,1,1,1,1,1,1,1,1,1,1,1,1,1,1,1,1,1,1,1,1,1,1,1,1,1,1,1,1,6,6
6,6,6,1,1,1,1,1,1,1,1,1,1,1,1,1,1,1,1,1,1,1,1,1,1,1,1,1,1,1,1,1,1,1,1,1,1,1,1,1,1,1,1,1,6,6
6,6,6,6,6,6,6,6,6,6,6,6,6,6,6,6,6,6,6,6,6,6,6,6,6,6,6,6,6,6,6,6,6,6,6,6,6,6,6,6,6,6,6,6,6,6
6,6,6,6,6,6,6,6,6,6,6,6,6,6,6,6,6,6,6,6,6,6,6,6,6,6,6,6,6,6,6,6,6,6,6,6,6,6,6,6,6,6,6,6,6,6
:endlayer
layer: 10
6,6,6,6,6,6,6,6,6,6,6,6,6,6,6,6,6,6,6,6,6,6,6,6,6,6,6,6,6,6,6,6,6,6,6,6,6,6,6,6,6,6,6,6,6,6
6,6,6,6,6,6,6,6,6,6,6,6,6,6,6,6,6,6,6,6,6,6,6,6,6,6,6,6,6,6,6,6,6,6,6,6,6,6,6,6,6,6,6,6,6,6
6,6,6,6,6,6,6,6,6,6,6,6,6,6,6,6,6,6,6,6,6,6,6,6,6,6,6,6,6,6,6,6,6,6,6,6,6,6,6,6,6,6,6,6,6,6
6,6,6,1,1,1,1,1,1,1,1,1,1,1,1,1,1,1,1,1,1,1,1,1,1,1,1,1,1,1,1,1,1,1,1,1,1,1,1,1,1,1,1,1,6,6
6,6,6,1,1,1,1,1,1,1,1,1,1,1,1,1,1,1,1,1,1,1,1,1,1,1,1,1,1,1,1,1,1,1,1,1,1,1,1,1,1,1,1,1,6,6
6,6,6,1,1,1,1,1,1,1,1,1,1,1,1,1,1,1,1,1,1,1,1,1,1,1,1,1,1,1,1,1,1,1,1,1,1,1,1,1,1,1,1,1,6,6
6,6,6,1,1,1,1,1,1,1,1,1,1,1,1,1,1,1,1,1,1,1,1,1,1,1,1,1,1,1,1,1,1,1,1,1,1,1,1,1,1,1,1,1,6,6
6,6,6,1,1,1,1,1,1,1,1,1,1,1,1,1,1,1,1,1,1,1,1,1,1,1,1,1,1,1,1,1,1,1,1,1,1,1,1,1,1,1,1,1,6,6
6,6,6,1,1,1,1,1,1,1,1,1,1,1,1,1,1,1,1,1,1,1,1,1,1,1,1,1,1,1,1,1,1,1,1,1,1,1,1,1,1,1,1,1,6,6
6,6,6,1,1,1,1,1,1,1,1,1,1,1,1,1,1,1,1,1,1,1,1,1,1,1,1,1,1,1,1,1,1,1,1,1,1,1,1,1,1,1,1,1,6,6
6,6,6,1,1,1,1,1,1,1,1,1,1,1,1,1,1,1,1,1,1,1,1,1,1,1,1,1,1,1,1,1,1,1,1,1,1,1,1,1,1,1,1,1,6,6
6,6,6,1,1,1,1,1,1,1,1,1,1,1,1,1,1,1,1,1,1,1,1,1,1,1,1,1,1,1,1,1,1,1,1,1,1,1,1,1,1,1,1,1,6,6
6,6,6,1,1,1,1,1,1,1,1,1,1,1,1,1,1,1,1,1,1,1,1,1,1,1,1,1,1,1,1,1,1,1,1,1,1,1,1,1,1,1,1,1,6,6
6,6,6,1,1,1,1,1,1,1,1,1,1,1,1,1,1,1,1,1,1,1,1,1,1,1,1,1,1,1,1,1,1,1,1,1,1,1,1,1,1,1,1,1,6,6
6,6,6,1,1,1,1,1,1,1,1,1,1,1,1,1,1,1,1,1,1,1,1,1,1,1,1,1,1,1,1,1,1,1,1,1,1,1,1,1,1,1,1,1,6,6
6,6,6,1,1,1,1,1,1,1,1,1,1,1,1,1,1,1,1,1,1,1,1,1,1,1,1,1,1,1,1,1,1,1,1,1,1,1,1,1,1,1,1,1,6,6
6,6,6,1,1,1,1,1,1,1,1,1,1,1,1,1,1,1,1,1,1,1,1,1,1,1,1,1,1,1,1,1,1,1,1,1,1,1,1,1,1,1,1,1,6,6
6,6,6,1,1,1,1,1,1,1,1,1,1,1,1,1,1,1,1,1,1,1,1,1,1,1,1,1,1,1,1,1,1,1,1,1,1,1,1,1,1,1,1,1,6,6
6,6,6,1,1,1,1,1,1,1,1,1,1,1,1,1,1,1,1,1,1,1,1,1,1,1,1,1,1,1,1,1,1,1,1,1,1,1,1,1,1,1,1,1,6,6
6,6,6,1,1,1,1,1,1,1,1,1,1,1,1,1,1,1,1,1,1,1,1,1,1,1,1,1,1,1,1,1,1,1,1,1,1,1,1,1,1,1,1,1,6,6
6,6,6,1,1,1,1,1,1,1,1,1,1,1,1,1,1,1,1,1,1,1,1,1,1,1,1,1,1,1,1,1,1,1,1,1,1,1,1,1,1,1,1,1,6,6
6,6,6,1,1,1,1,1,1,1,1,1,1,1,1,1,1,1,1,1,1,1,1,1,1,1,1,1,1,1,1,1,1,1,1,1,1,1,1,1,1,1,1,1,6,6
6,6,6,1,1,1,1,1,1,1,1,1,1,1,1,1,1,1,1,1,1,1,1,1,1,1,1,1,1,1,1,1,1,1,1,1,1,1,1,1,1,1,1,1,6,6
6,6,6,1,1,1,1,1,1,1,1,1,1,1,1,1,1,1,1,1,1,1,1,1,1,1,1,1,1,1,1,1,1,1,1,1,1,1,1,1,1,1,1,1,6,6
6,6,6,1,1,1,1,1,1,1,1,1,1,1,1,1,1,1,1,1,1,1,1,1,1,1,1,1,1,1,1,1,1,1,1,1,1,1,1,1,1,1,1,1,6,6
6,6,6,1,1,1,1,1,1,1,1,1,1,1,1,1,1,1,1,1,1,1,1,1,1,1,1,1,1,1,1,1,1,1,1,1,1,1,1,1,1,1,1,1,6,6
6,6,6,1,1,1,1,1,1,1,1,1,1,1,1,1,1,1,1,1,1,1,1,1,1,1,1,1,1,1,1,1,1,1,1,1,1,1,1,1,1,1,1,1,6,6
6,6,6,1,1,1,1,1,1,1,1,1,1,1,1,1,1,1,1,1,1,1,1,0,0,0,1,1,1,1,1,1,1,1,1,1,1,1,1,1,1,1,1,1,6,6
6,6,6,1,1,1,1,1,1,1,1,1,1,1,1,1,1,1,1,1,1,1,1,0,0,0,1,1,1,1,1,1,1,1,1,1,1,1,1,1,1,1,1,1,6,6
6,6,6,1,1,1,1,1,1,1,1,1,1,1,1,1,1,1,1,1,1,1,1,0,0,0,1,1,1,1,1,1,1,1,1,1,1,1,1,1,1,1,1,1,6,6
6,6,6,1,1,1,1,1,1,1,1,1,1,1,1,1,1,1,1,1,1,1,1,0,0,0,1,1,1,1,1,1,1,1,1,1,1,1,1,1,1,1,1,1,6,6
6,6,6,1,1,1,1,1,1,1,1,1,1,1,1,1,1,1,1,1,1,1,1,35,35,35,1,1,1,1,1,1,1,1,1,1,1,1,1,1,1,1,1,1,6,6
6,6,6,1,1,1,1,1,1,1,1,1,1,1,1,1,1,1,1,1,1,1,1,1,1,1,1,1,1,1,1,1,1,1,1,1,1,1,1,1,1,1,1,1,6,6
6,6,6,1,1,1,1,1,1,1,1,1,1,1,1,1,1,1,1,1,1,1,1,1,1,1,1,1,1,1,1,1,1,1,1,1,1,1,1,1,1,1,1,1,6,6
6,6,6,1,1,1,1,1,1,1,1,1,1,1,1,1,1,1,1,1,1,1,1,1,1,1,1,1,1,1,1,1,1,1,1,1,1,1,1,1,1,1,1,1,6,6
6,6,6,1,1,1,1,1,1,1,1,1,1,1,1,1,1,1,1,1,1,1,1,1,1,1,1,1,1,1,1,1,1,1,1,1,1,1,1,1,1,1,1,1,6,6
6,6,6,1,1,1,1,1,1,1,1,1,1,1,1,1,1,1,1,1,1,1,1,1,1,1,1,1,1,1,1,1,1,1,1,1,1,1,1,1,1,1,1,1,6,6
6,6,6,1,1,1,1,1,1,1,1,1,1,1,1,1,1,1,1,1,1,1,1,1,1,1,1,1,1,1,1,1,1,1,1,1,1,1,1,1,1,1,1,1,6,6
6,6,6,1,1,1,1,1,1,1,1,1,1,1,1,1,1,1,1,1,1,1,1,1,1,1,1,1,1,1,1,1,1,1,1,1,1,1,1,1,1,1,1,1,6,6
6,6,6,6,6,6,6,6,6,6,6,6,6,6,6,6,6,6,6,6,6,6,6,6,6,6,6,6,6,6,6,6,6,6,6,6,6,6,6,6,6,6,6,6,6,6
6,6,6,6,6,6,6,6,6,6,6,6,6,6,6,6,6,6,6,6,6,6,6,6,6,6,6,6,6,6,6,6,6,6,6,6,6,6,6,6,6,6,6,6,6,6
:endlayer
layer: 11
6,6,6,6,6,6,6,6,6,6,6,6,6,6,6,6,6,6,6,6,6,6,6,6,6,6,6,6,6,6,6,6,6,6,6,6,6,6,6,6,6,6,6,6,6,6
6,6,6,6,6,6,6,6,6,6,6,6,6,6,6,6,6,6,6,6,6,6,6,6,6,6,6,6,6,6,6,6,6,6,6,6,6,6,6,6,6,6,6,6,6,6
6,6,6,6,6,6,6,6,6,6,6,6,6,6,6,6,6,6,6,6,6,6,6,6,6,6,6,6,6,6,6,6,6,6,6,6,6,6,6,6,6,6,6,6,6,6
6,6,6,6,6,6,6,6,6,6,6,6,6,6,6,6,6,6,6,6,6,6,6,6,6,6,6,6,6,6,6,6,6,6,6,6,6,6,6,6,6,6,6,6,6,6
6,6,6,6,6,6,6,6,6,6,6,6,6,6,6,6,6,6,6,6,6,6,6,6,6,6,6,6,6,6,6,6,6,6,6,6,6,6,6,6,6,6,6,6,6,6
6,6,6,6,6,6,6,6,6,6,6,6,6,6,6,6,6,6,6,6,6,6,6,6,6,6,6,6,6,6,6,6,6,6,6,6,6,6,6,6,6,6,6,6,6,6
6,6,6,6,6,6,6,6,6,6,6,6,6,6,6,6,6,6,6,6,6,6,6,6,6,6,6,6,6,6,6,6,6,6,6,6,6,6,6,6,6,6,6,6,6,6
6,6,6,6,6,6,6,6,6,6,6,6,6,6,6,6,6,6,6,6,6,6,6,6,6,6,6,6,6,6,6,6,6,6,6,6,6,6,6,6,6,6,6,6,6,6
6,6,6,6,6,6,6,6,6,6,6,6,6,6,6,6,6,6,6,6,6,6,6,6,6,6,6,6,6,6,6,6,6,6,6,6,6,6,6,6,6,6,6,6,6,6
6,6,6,6,6,6,6,6,6,6,6,6,6,6,6,6,6,6,6,6,6,6,6,6,6,6,6,6,6,6,6,6,6,6,6,6,6,6,6,6,6,6,6,6,6,6
6,6,6,6,6,6,6,6,6,6,6,6,6,6,6,6,6,6,6,6,6,6,6,6,6,6,6,6,6,6,6,6,6,6,6,6,6,6,6,6,6,6,6,6,6,6
6,6,6,6,6,6,6,6,6,6,6,6,6,6,6,6,6,6,6,6,6,6,6,6,6,6,6,6,6,6,6,6,6,6,6,6,6,6,6,6,6,6,6,6,6,6
6,6,6,6,6,6,6,6,6,6,6,6,6,6,6,6,6,6,6,6,6,6,6,6,6,6,6,6,6,6,6,6,6,6,6,6,6,6,6,6,6,6,6,6,6,6
6,6,6,6,6,6,6,6,6,6,6,6,6,6,6,6,6,6,6,6,6,6,6,6,6,6,6,6,6,6,6,6,6,6,6,6,6,6,6,6,6,6,6,6,6,6
6,6,6,6,6,6,6,6,6,6,6,6,6,6,6,6,6,6,6,6,6,6,6,6,6,6,6,6,6,6,6,6,6,6,6,6,6,6,6,6,6,6,6,6,6,6
6,6,6,6,6,6,6,6,6,6,6,6,6,6,6,6,6,6,6,6,6,6,6,6,6,6,6,6,6,6,6,6,6,6,6,6,6,6,6,6,6,6,6,6,6,6
6,6,6,6,6,6,6,6,6,6,6,6,6,6,6,6,6,6,6,6,6,6,6,6,6,6,6,6,6,6,6,6,6,6,6,6,6,6,6,6,6,6,6,6,6,6
6,6,6,6,6,6,6,6,6,6,6,6,6,6,6,6,6,6,6,6,6,6,6,6,6,6,6,6,6,6,6,6,6,6,6,6,6,6,6,6,6,6,6,6,6,6
6,6,6,6,6,6,6,6,6,6,6,6,6,6,6,6,6,6,6,6,6,6,6,6,6,6,6,6,6,6,6,6,6,6,6,6,6,6,6,6,6,6,6,6,6,6
6,6,6,6,6,6,6,6,6,6,6,6,6,6,6,6,6,6,6,6,6,6,6,6,6,6,6,6,6,6,6,6,6,6,6,6,6,6,6,6,6,6,6,6,6,6
6,6,6,6,6,6,6,6,6,6,6,6,6,6,6,6,6,6,6,6,6,6,6,6,6,6,6,6,6,6,6,6,6,6,6,6,6,6,6,6,6,6,6,6,6,6
6,6,6,6,6,6,6,6,6,6,6,6,6,6,6,6,6,6,6,6,6,6,6,6,6,6,6,6,6,6,6,6,6,6,6,6,6,6,6,6,6,6,6,6,6,6
6,6,6,6,6,6,6,6,6,6,6,6,6,6,6,6,6,6,6,6,6,6,6,6,6,6,6,6,6,6,6,6,6,6,6,6,6,6,6,6,6,6,6,6,6,6
6,6,6,6,6,6,6,6,6,6,6,6,6,6,6,6,6,6,6,6,6,6,6,6,6,6,6,6,6,6,6,6,6,6,6,6,6,6,6,6,6,6,6,6,6,6
6,6,6,6,6,6,6,6,6,6,6,6,6,6,6,6,6,6,6,6,6,6,6,6,6,6,6,6,6,6,6,6,6,6,6,6,6,6,6,6,6,6,6,6,6,6
6,6,6,6,6,6,6,6,6,6,6,6,6,6,6,6,6,6,6,6,6,6,6,6,6,6,6,6,6,6,6,6,6,6,6,6,6,6,6,6,6,6,6,6,6,6
6,6,6,6,6,6,6,6,6,6,6,6,6,6,6,6,6,6,6,6,6,6,6,1,1,1,6,6,6,6,6,6,6,6,6,6,6,6,6,6,6,6,6,6,6,6
6,6,6,6,6,6,6,6,6,6,6,6,6,6,6,6,6,6,6,6,6,6,1,0,0,0,1,6,6,6,6,6,6,6,6,6,6,6,6,6,6,6,6,6,6,6
6,6,6,6,6,6,6,6,6,6,6,6,6,6,6,6,6,6,6,6,6,6,1,0,0,0,1,6,6,6,6,6,6,6,6,6,6,6,6,6,6,6,6,6,6,6
6,6,6,6,6,6,6,6,6,6,6,6,6,6,6,6,6,6,6,6,6,6,1,0,0,0,1,6,6,6,6,6,6,6,6,6,6,6,6,6,6,6,6,6,6,6
6,6,6,6,6,6,6,6,6,6,6,6,6,6,6,6,6,6,6,6,6,6,1,0,0,0,1,6,6,6,6,6,6,6,6,6,6,6,6,6,6,6,6,6,6,6
6,6,6,6,6,6,6,6,6,6,6,6,6,6,6,6,6,6,6,6,6,6,1,0,0,0,1,6,6,6,6,6,6,6,6,6,6,6,6,6,6,6,6,6,6,6
6,6,6,6,6,6,6,6,6,6,6,6,6,6,6,6,6,6,6,6,6,6,1,35,35,35,6,6,6,6,6,6,6,6,6,6,6,6,6,6,6,6,6,6,6,6
6,6,6,6,6,6,6,6,6,6,6,6,6,6,6,6,6,6,6,6,6,6,6,6,6,6,6,6,6,6,6,6,6,6,6,6,6,6,6,6,6,6,6,6,6,6
6,6,6,6,6,6,6,6,6,6,6,6,6,6,6,6,6,6,6,6,6,6,6,6,6,6,6,6,6,6,6,6,6,6,6,6,6,6,6,6,6,6,6,6,6,6
6,6,6,6,6,6,6,6,6,6,6,6,6,6,6,6,6,6,6,6,6,6,6,6,6,6,6,6,6,6,6,6,6,6,6,6,6,6,6,6,6,6,6,6,6,6
6,6,6,6,6,6,6,6,6,6,6,6,6,6,6,6,6,6,6,6,6,6,6,6,6,6,6,6,6,6,6,6,6,6,6,6,6,6,6,6,6,6,6,6,6,6
6,6,6,6,6,6,6,6,6,6,6,6,6,6,6,6,6,6,6,6,6,6,6,6,6,6,6,6,6,6,6,6,6,6,6,6,6,6,6,6,6,6,6,6,6,6
6,6,6,6,6,6,6,6,6,6,6,6,6,6,6,6,6,6,6,6,6,6,6,6,6,6,6,6,6,6,6,6,6,6,6,6,6,6,6,6,6,6,6,6,6,6
6,6,6,6,6,6,6,6,6,6,6,6,6,6,6,6,6,6,6,6,6,6,6,6,6,6,6,6,6,6,6,6,6,6,6,6,6,6,6,6,6,6,6,6,6,6
6,6,6,6,6,6,6,6,6,6,6,6,6,6,6,6,6,6,6,6,6,6,6,6,6,6,6,6,6,6,6,6,6,6,6,6,6,6,6,6,6,6,6,6,6,6
:endlayer
layer: 12
175,175,175,175,175,175,175,175,175,175,175,175,175,175,175,175,175,175,175,175,175,175,175,175,175,175,175,175,175,175,175,175,175,175,175,175,175,175,175,175,175,175,175,175,175,175
175,175,175,175,175,175,175,175,175,175,175,175,175,175,175,175,175,175,175,175,175,175,175,175,175,175,175,175,175,175,175,175,175,175,175,175,175,175,175,175,175,175,175,175,175,175
175,175,175,175,8,175,175,175,175,175,175,175,175,175,175,175,175,175,175,175,175,175,175,175,175,175,175,175,175,175,175,175,175,175,175,175,175,175,8,8,8,175,175,175,175,175
175,175,175,8,8,8,8,8,175,175,175,175,8,8,8,175,175,175,175,175,175,175,175,175,175,175,175,175,175,175,175,175,175,175,175,175,175,8,175,8,8,175,175,175,175,175
175,175,175,8,8,8,8,8,175,175,175,8,8,175,8,175,175,175,175,175,175,8,175,175,175,175,175,175,175,175,175,8,8,175,175,175,175,8,8,8,8,8,175,175,175,175
175,175,175,175,8,8,8,8,175,175,175,8,8,8,8,8,175,175,175,175,8,175,8,175,175,175,175,175,175,175,8,8,8,8,175,175,175,8,8,8,8,175,175,175,175,175
175,175,175,175,8,8,8,8,175,175,175,175,8,8,8,175,175,175,175,175,175,8,8,175,175,175,175,175,175,4,8,8,8,175,175,175,175,175,175,175,8,175,175,175,175,175
175,175,175,175,175,175,175,175,175,175,175,175,175,175,175,175,175,175,175,8,8,8,8,8,175,175,175,175,175,175,8,8,8,8,175,175,175,175,175,175,175,175,175,175,175,175
175,175,175,175,175,175,175,175,175,175,175,175,175,175,175,175,175,175,175,175,8,8,8,175,175,175,175,175,175,175,8,8,175,175,175,175,175,175,175,175,175,175,175,175,175,175
175,175,175,175,175,175,175,175,175,175,175,175,175,175,175,175,175,175,175,175,175,175,175,175,175,175,175,175,175,175,175,175,175,175,175,175,175,175,175,175,175,8,8,8,175,175
175,175,175,175,175,175,175,175,175,175,175,175,175,175,175,175,175,175,175,175,175,175,175,175,175,175,175,175,175,175,175,175,175,175,175,175,175,175,175,175,175,8,8,175,8,175
175,175,175,175,175,175,175,175,175,175,175,175,175,180,179,175,175,175,175,175,175,175,175,175,175,175,175,175,175,175,175,175,175,175,175,175,175,175,175,175,175,8,8,8,175,175
175,175,175,175,175,175,175,175,175,175,175,175,175,176,175,175,175,175,175,175,175,175,175,175,175,175,175,175,175,175,175,175,175,175,175,175,175,175,175,175,175,175,175,175,175,175
175,175,175,175,175,175,175,175,175,175,175,175,175,175,175,175,175,175,175,175,175,175,175,175,175,175,175,175,175,175,175,175,175,175,175,175,175,175,175,175,175,175,175,175,175,175
175,175,175,175,175,175,175,175,175,175,175,175,175,175,175,175,175,175,175,175,175,175,175,175,175,175,175,175,175,175,175,175,175,175,175,175,175,175,175,175,175,175,175,175,175,175
175,175,175,175,175,175,175,175,175,175,175,175,175,175,175,175,175,175,175,175,175,175,175,175,175,175,175,175,175,175,175,175,175,175,175,175,175,175,175,177,175,175,175,175,175,175
175,175,175,175,175,175,175,175,175,175,175,175,175,175,175,175,175,175,175,175,175,175,175,175,175,175,175,175,175,175,175,175,175,175,175,175,175,175,175,175,8,8,175,175,175,175
175,175,175,175,4,175,175,175,175,175,175,175,175,175,175,175,175,175,175,175,175,175,175,175,175,175,175,175,175,175,175,175,175,175,175,175,175,175,175,8,8,8,8,175,175,175
175,175,175,8,8,4,175,175,175,175,175,175,175,175,175,175,175,175,175,175,175,175,175,175,175,175,175,175,175,175,175,175,175,175,175,175,175,175,175,175,175,175,175,175,175,175
175,175,175,8,8,4,175,175,175,175,175,175,175,175,175,175,175,175,175,175,175,175,175,175,175,175,175,175,175,175,175,175,175,175,175,175,175,175,175,175,175,175,175,175,175,175
175,175,175,8,8,181,175,181,4,4,175,175,175,175,175,175,175,175,175,175,175,175,175,175,175,175,175,175,175,175,175,175,175,175,175,175,175,175,175,175,175,175,175,175,175,175
175,175,175,8,8,175,175,175,175,175,175,175,175,175,175,175,175,175,175,175,175,175,175,175,175,175,175,175,175,175,175,175,175,175,175,175,175,175,175,175,175,175,175,175,175,175
175,175,175,175,175,175,175,175,175,175,175,175,175,175,175,175,175,175,175,175,175,175,175,175,175,175,175,175,175,175,175,175,175,175,175,175,175,175,175,175,175,175,175,175,175,175
175,175,175,175,175,175,175,175,175,175,175,175,175,175,175,175,175,175,175,175,175,175,175,175,175,175,175,175,175,175,175,175,175,175,175,175,175,175,175,175,8,175,175,175,175,175
175,175,175,175,175,175,175,175,175,175,175,175,175,175,175,175,175,175,175,175,175,175,175,175,175,175,175,175,175,175,175,175,175,175,175,175,175,175,175,8,8,8,8,175,175,175
175,175,175,175,175,175,175,175,175,175,175,175,175,175,175,175,175,175,175,175,175,175,175,175,175,175,175,175,175,175,175,175,175,175,175,175,175,175,8,8,8,8,8,175,175,175
175,175,175,175,175,175,175,175,175,175,175,175,8,8,8,175,175,175,175,175,175,175,175,175,175,175,175,175,175,175,175,175,175,175,175,175,175,175,175,8,8,8,8,175,175,175
175,175,175,175,175,175,175,175,175,175,175,175,8,175,8,8,175,175,175,175,175,175,175,175,175,175,175,175,175,175,175,175,175,175,175,175,175,175,175,175,175,176,175,175,175,175
175,175,175,175,175,175,175,8,8,8,175,175,8,8,8,175,175,175,175,175,175,175,175,1,1,1,175,175,175,175,175,175,175,175,175,175,175,175,175,175,175,175,175,175,175,175
175,175,175,175,175,8,8,8,8,175,175,175,175,8,8,175,175,175,175,175,175,175,1,0,0,0,1,175,175,175,175,175,175,175,175,175,175,175,175,175,175,175,175,175,175,175
175,175,175,175,175,8,8,8,8,4,175,175,175,175,175,175,175,175,175,175,175,175,1,0,0,0,1,175,175,175,175,175,175,175,175,175,175,175,175,175,175,8,8,8,175,175
175,175,175,175,175,175,175,8,175,175,175,175,175,175,175,175,175,175,175,175,175,175,1,0,0,0,1,175,175,175,175,8,8,175,175,175,175,175,175,175,8,8,8,8,8,175
175,175,175,175,175,175,175,175,175,175,175,175,175,175,175,175,175,175,175,7,175,175,1,0,0,0,1,175,175,8,8,8,8,175,175,175,175,175,175,175,8,8,8,8,8,175
175,175,175,175,175,175,175,175,175,175,175,175,175,175,175,175,175,0,175,7,7,1,1,35,35,35,1,175,8,8,8,8,175,175,175,175,175,175,175,175,175,8,8,8,175,175
175,175,175,175,175,175,175,175,175,175,175,175,175,175,175,175,175,0,0,7,7,1,1,1,1,1,175,175,175,8,8,8,8,175,175,175,175,4,175,175,175,175,175,175,175,175
175,175,175,175,175,175,175,175,175,175,175,175,175,175,175,175,175,0,7,7,7,1,1,175,1,1,175,175,175,8,8,8,175,175,175,175,175,4,4,4,4,175,175,175,175,175
175,175,175,175,175,175,175,175,175,175,175,175,175,175,175,175,175,178,7,7,7,1,175,175,175,175,175,175,175,175,175,175,175,175,175,175,175,8,8,8,175,175,175,175,175,175
175,175,175,175,175,175,175,175,175,175,175,175,175,175,175,175,175,175,175,8,175,175,175,175,175,175,175,175,175,175,175,175,175,175,175,175,175,175,175,8,8,175,175,175,175,175
175,175,175,175,175,175,175,175,175,175,175,175,175,175,175,175,175,175,175,175,175,175,175,175,175,175,175,175,175,175,175,175,175,175,175,175,175,175,175,175,175,175,175,175,175,175
175,175,175,175,175,175,175,175,175,175,175,175,175,175,175,175,175,175,175,175,175,175,175,175,175,175,175,175,175,175,175,175,175,175,175,175,175,175,175,175,175,175,175,175,175,175
175,175,175,175,175,175,175,175,175,175,175,175,175,175,175,175,175,175,175,175,175,175,175,175,175,175,175,175,175,175,175,175,175,175,175,175,175,175,175,175,175,175,175,175,175,175
:endlayer
layer: 13
175,175,175,175,175,175,175,175,175,175,175,175,175,175,175,175,175,175,175,175,175,175,175,175,175,175,175,175,175,175,175,175,175,175,175,175,175,175,175,175,175,175,175,175,175,175
175,175,175,175,175,8,8,175,175,175,175,175,8,8,8,175,175,175,175,175,175,175,175,175,175,175,175,175,175,175,175,175,175,175,175,175,175,175,8,8,175,175,175,175,175,175
175,175,175,8,8,8,8,8,175,175,175,8,8,8,8,8,175,175,175,175,175,175,175,175,175,175,175,175,175,175,175,175,175,175,175,175,175,8,8,8,8,8,175,175,175,175
175,175,175,8,8,8,8,8,8,175,175,8,8,8,8,8,8,175,175,175,175,8,8,175,175,175,175,175,175,175,175,8,175,175,175,175,175,8,8,8,8,8,175,175,175,175
175,175,8,8,8,8,8,8,8,175,175,8,8,8,8,8,8,175,175,175,8,8,8,8,175,175,175,175,175,8,8,8,8,8,175,175,175,8,8,8,8,8,175,175,175,175
175,175,175,8,8,8,8,8,8,175,175,8,8,8,8,8,8,175,175,8,8,8,8,8,175,175,175,175,175,8,8,8,8,8,8,175,175,8,8,8,8,1,175,175,175,175
175,175,175,8,8,8,8,8,8,175,175,8,8,8,8,8,175,175,8,8,8,8,8,8,8,175,175,175,4,8,8,8,8,8,8,175,175,1,8,8,8,1,175,175,175,175
175,175,175,175,175,8,175,175,175,175,175,175,8,175,175,175,175,175,175,8,8,8,8,8,175,175,175,175,175,8,8,8,8,8,8,175,175,175,1,175,1,175,8,175,175,175
175,175,175,175,175,175,175,175,175,175,175,175,175,175,175,175,175,175,175,8,8,8,8,8,8,175,175,175,175,8,8,8,8,8,175,175,175,175,175,175,8,8,8,8,8,175
175,175,175,175,175,175,175,175,175,175,175,175,175,8,175,175,175,175,175,175,175,175,175,175,175,175,175,175,175,175,175,175,175,175,175,175,175,175,175,175,8,8,8,8,8,175
175,175,175,175,175,175,175,175,175,175,175,175,8,8,8,175,175,175,175,175,175,175,175,175,175,175,175,175,175,175,175,175,175,175,175,175,175,175,175,175,8,8,8,8,8,175
175,175,175,175,175,175,175,175,175,175,175,175,8,8,8,175,175,175,175,175,175,175,175,175,175,175,175,175,175,175,175,175,175,175,175,175,175,175,175,175,8,8,8,8,8,175
175,175,175,175,175,175,175,175,175,175,175,175,8,185,175,175,175,175,175,175,175,175,175,175,175,175,175,175,175,175,175,175,175,175,175,175,175,175,175,8,8,8,8,8,8,175
175,175,175,175,175,175,175,175,175,175,175,175,175,175,175,175,175,175,175,175,175,175,175,175,175,175,175,175,175,175,175,175,175,175,175,175,175,175,175,175,175,175,8,8,175,175
175,175,175,175,175,175,175,175,175,175,175,175,175,175,175,175,175,175,175,175,175,175,175,175,175,175,175,175,175,175,175,182,175,175,175,175,175,175,8,8,8,8,175,175,175,175
175,175,175,175,175,175,175,175,175,175,175,175,175,175,175,175,175,175,175,175,175,175,175,175,175,175,175,175,175,175,175,175,175,175,175,175,175,175,8,8,8,8,8,175,175,175
175,175,175,175,175,175,175,175,175,175,175,175,175,175,175,175,175,175,175,175,175,175,8,175,175,175,175,175,175,175,175,175,175,175,175,175,175,175,8,8,8,8,8,175,175,175
175,175,8,8,4,8,8,175,175,175,175,175,175,175,175,175,175,175,175,175,175,175,184,175,175,175,175,175,175,175,175,175,175,175,175,175,175,175,8,8,8,8,8,8,175,175
175,8,8,8,8,4,8,175,175,175,175,175,175,175,175,175,175,175,175,175,175,175,175,175,175,175,175,175,175,175,175,175,175,175,175,175,175,175,8,8,8,8,8,175,175,175
175,175,8,8,8,4,8,8,8,8,8,175,175,175,175,175,175,175,175,175,175,175,175,175,175,175,175,175,175,8,175,175,175,175,175,175,175,175,175,8,8,8,175,175,175,175
175,175,8,8,8,181,8,181,8,8,8,175,175,175,175,175,175,175,175,175,175,175,175,175,175,175,175,175,175,175,175,175,175,175,175,175,175,175,175,175,175,175,175,175,175,175
175,175,8,8,8,8,8,8,175,8,175,175,175,175,175,175,175,175,175,175,175,175,175,175,175,175,175,175,175,175,175,175,175,175,175,175,175,175,175,175,175,175,175,175,175,175
175,175,175,8,8,8,175,175,175,175,175,175,175,175,175,175,175,175,175,175,175,175,175,175,175,175,175,175,175,175,175,175,175,175,175,175,175,175,175,175,175,175,175,175,175,175
175,175,175,175,175,175,175,175,175,175,175,175,175,178,178,175,175,175,175,175,175,175,175,175,175,175,175,175,175,175,175,175,175,175,175,175,175,175,8,8,8,8,8,175,175,175
175,175,175,175,175,175,175,175,175,175,175,175,8,8,8,8,175,175,175,175,175,175,175,175,175,175,175,175,175,175,175,175,175,175,175,175,175,175,8,8,8,8,8,175,175,175
175,175,175,175,175,175,175,175,175,175,175,178,8,8,8,8,175,175,175,175,175,175,175,175,175,175,175,175,175,175,175,175,175,175,175,175,175,175,8,8,8,8,8,175,175,175
175,175,175,175,178,175,178,178,178,175,8,8,8,8,8,8,175,175,175,175,175,175,175,175,175,175,175,175,175,175,175,175,175,175,175,175,175,175,8,8,8,8,8,175,175,175
175,175,175,175,175,8,8,8,8,8,8,8,8,8,8,8,175,175,175,175,175,175,175,175,175,175,175,175,175,175,175,175,175,175,175,175,175,175,8,8,8,8,8,175,175,175
175,175,175,175,178,8,8,8,8,8,178,8,8,8,8,8,175,175,175,175,175,175,175,1,1,1,175,175,175,175,175,175,175,175,175,175,175,175,175,8,8,8,175,8,175,175
175,175,175,175,8,8,8,8,8,8,8,8,8,8,8,175,175,175,175,7,7,7,1,0,0,0,1,175,175,175,175,175,175,175,175,175,175,175,175,175,8,8,8,8,8,175
175,175,175,175,8,8,8,8,8,8,175,175,175,175,175,175,175,175,175,7,7,7,1,0,0,0,1,7,175,175,175,175,175,175,175,175,175,175,175,175,8,8,8,8,8,175
175,175,175,175,178,8,8,8,8,8,175,175,175,175,175,175,175,175,175,7,7,7,1,0,0,0,1,7,7,8,8,8,8,175,175,175,175,175,175,8,8,8,8,8,8,175
175,175,175,175,178,178,178,8,178,175,175,175,175,175,175,175,175,1,7,7,7,1,1,0,0,0,1,1,7,8,8,8,8,8,175,175,175,175,175,175,8,8,8,8,8,175
175,175,175,175,175,175,175,178,175,175,175,175,175,175,175,175,1,0,0,7,7,1,1,183,0,183,1,1,8,8,8,8,8,175,175,175,8,8,8,8,8,8,8,8,8,175
175,175,175,175,175,175,175,175,175,175,175,175,175,175,175,175,1,0,0,7,7,1,1,35,35,35,1,1,8,8,8,8,8,8,175,175,8,8,8,8,8,8,8,8,175,175
175,175,175,175,175,175,175,175,175,175,175,175,175,175,175,175,175,0,7,7,7,1,1,1,1,1,1,1,8,8,8,8,8,175,175,175,8,8,8,8,8,8,175,175,175,175
175,175,175,175,175,175,175,175,175,175,175,175,175,175,175,175,175,0,7,7,7,1,1,1,1,1,1,175,8,8,8,8,175,175,175,175,8,8,8,8,8,175,175,175,175,175
175,175,175,175,175,175,175,175,175,175,175,175,175,175,175,175,175,175,8,8,8,175,175,175,175,175,175,175,175,175,175,175,175,175,175,175,8,8,8,8,8,175,175,175,175,175
175,175,175,175,175,175,175,175,175,175,175,175,175,175,175,175,175,175,175,175,175,175,175,175,175,175,175,175,175,175,175,175,175,175,175,175,175,175,8,8,175,175,175,175,175,175
175,175,175,175,175,175,175,175,175,175,175,175,175,175,175,175,175,175,175,175,175,175,175,175,175,175,175,175,175,175,175,175,175,175,175,175,175,175,175,175,175,175,175,175,175,175
175,175,175,175,175,175,175,175,175,175,175,175,175,175,175,175,175,175,175,175,175,175,175,175,175,175,175,175,175,175,175,175,175,175,175,175,175,175,175,175,175,175,175,175,175,175
:endlayer
layer: 14
178,178,178,178,178,178,178,178,178,178,178,178,178,178,178,178,178,178,178,178,178,178,178,178,178,178,178,178,178,178,178,178,178,178,178,178,178,178,178,178,178,178,178,178,178,178
178,178,178,8,8,8,8,8,8,178,178,8,8,8,8,8,8,178,178,178,178,178,178,178,178,178,178,178,178,178,178,178,178,178,178,178,178,178,8,8,8,8,178,178,178,178
178,178,8,8,8,8,8,8,8,175,8,8,8,8,8,8,8,178,178,178,175,178,8,178,178,178,178,178,178,178,178,178,178,178,178,178,8,8,8,8,8,8,8,175,178,178
178,178,8,8,8,8,8,8,8,178,8,8,8,8,8,8,8,178,8,8,8,8,8,178,178,178,178,178,8,8,8,8,8,8,175,178,8,8,8,8,8,8,8,178,178,178
178,178,8,8,8,8,8,8,8,8,8,8,8,8,8,8,8,8,8,8,8,8,8,8,8,178,178,178,8,8,8,8,8,8,8,178,8,8,8,8,8,8,8,8,178,178
178,178,8,8,8,8,8,8,8,175,8,8,8,8,8,8,8,175,8,8,8,8,8,8,8,178,178,178,8,8,8,8,8,8,8,175,8,8,8,8,8,1,8,178,178,178
178,178,8,8,8,8,8,186,186,186,186,186,8,8,8,175,175,175,8,8,8,8,8,8,8,8,178,178,8,8,8,8,8,8,8,175,175,175,8,8,8,1,178,178,175,178
178,178,8,178,178,175,186,186,186,186,186,186,175,175,175,175,175,175,8,8,8,8,8,8,8,175,175,175,8,8,8,8,8,8,8,175,175,175,175,175,175,8,8,8,8,178
178,178,178,178,178,175,186,186,186,186,186,186,8,175,175,175,186,186,175,1,1,8,8,1,1,1,1,1,1,1,1,8,1,1,1,175,186,186,175,175,8,8,8,8,8,178
178,178,178,178,178,175,186,186,186,8,8,8,8,175,175,186,186,186,186,1,1,1,1,1,1,1,1,1,1,1,1,1,1,1,1,186,186,186,186,186,186,8,8,8,8,178
178,178,178,178,178,175,186,186,8,8,8,8,8,8,175,186,186,186,175,1,1,1,1,1,1,1,1,1,1,1,1,1,1,1,1,175,186,186,186,186,186,8,8,8,8,178
178,178,178,178,178,175,186,186,8,8,8,8,8,8,175,175,186,175,175,1,1,1,1,1,1,1,175,175,1,1,1,1,1,1,1,175,175,186,175,175,8,8,8,8,8,178
178,178,175,178,178,175,186,186,8,8,8,8,8,186,8,1,1,1,1,8,8,8,8,1,3,1,175,175,1,1,1,1,1,1,1,1,1,1,1,8,8,8,8,8,8,178
178,178,178,178,178,186,186,186,8,8,8,8,8,8,8,1,1,1,1,8,8,8,8,8,8,1,175,175,1,1,1,1,1,1,1,1,1,1,1,8,8,8,8,8,8,178
178,178,178,178,178,175,186,186,186,8,8,8,8,8,8,1,1,1,1,8,8,8,8,8,8,1,175,175,1,1,1,8,1,1,1,1,1,1,1,8,8,8,8,8,175,178
178,178,178,178,8,8,186,186,186,192,192,186,186,186,175,1,1,1,1,8,8,8,8,8,8,1,175,175,1,1,1,1,1,1,1,1,1,1,1,8,8,8,8,8,178,178
178,178,8,8,8,8,8,8,8,192,192,186,186,186,175,1,1,1,1,8,8,8,8,8,1,1,175,175,1,1,1,1,1,1,1,1,1,1,8,8,8,8,8,8,178,178
178,8,8,8,8,8,8,8,8,8,8,8,186,186,175,1,1,1,1,8,8,8,1,8,1,1,8,8,8,8,8,8,8,8,1,1,1,1,8,8,8,8,8,8,178,178
178,8,8,8,8,8,8,8,8,8,8,8,186,186,175,1,1,1,1,1,1,1,1,1,1,1,8,8,8,8,8,8,8,8,1,1,1,1,1,8,8,8,8,8,178,178
178,8,8,8,8,8,8,8,8,8,8,8,175,175,175,1,1,1,1,1,1,1,1,1,1,1,1,8,8,8,8,8,8,8,1,1,1,1,1,8,8,8,8,8,178,178
178,8,8,8,8,3,8,3,8,8,8,175,178,178,175,1,1,1,1,1,1,1,1,1,1,1,1,8,8,8,8,8,8,8,1,1,1,1,1,175,8,178,175,178,178,178
178,8,8,8,8,8,8,8,178,178,178,178,178,178,175,1,1,1,1,1,1,1,1,1,1,1,8,8,8,8,8,8,8,1,1,1,1,1,1,175,178,178,178,178,178,178
178,178,8,8,8,8,8,178,178,178,178,178,178,178,175,1,1,1,1,1,1,1,1,1,1,1,175,8,1,8,1,8,1,1,1,1,1,1,1,8,8,8,8,178,178,178
178,178,178,8,8,178,8,178,175,175,175,175,178,190,0,1,1,1,1,1,1,1,1,1,1,1,175,175,1,1,1,1,1,1,1,1,1,1,1,8,8,8,8,8,178,178
178,178,178,175,178,178,178,178,175,175,175,175,0,0,0,1,1,1,1,1,1,1,1,1,1,1,175,175,1,1,1,1,1,1,1,1,1,1,1,8,8,8,8,8,175,178
178,178,178,178,178,178,178,178,175,175,175,0,0,0,0,1,1,1,1,1,1,1,1,1,1,1,175,175,1,1,1,1,1,1,1,1,1,1,8,8,8,8,8,8,8,178
178,178,178,178,0,178,0,193,0,175,0,0,0,0,0,0,1,1,1,1,1,1,1,1,1,1,175,175,1,1,1,1,1,1,1,1,1,1,8,8,8,8,8,8,178,178
178,178,178,178,178,0,0,0,0,175,0,0,191,191,0,1,1,1,1,1,1,1,1,1,1,1,175,175,1,1,1,1,1,1,1,1,1,1,1,8,8,8,8,8,178,178
178,178,178,178,0,0,0,193,0,0,0,0,0,0,0,0,186,175,175,1,1,1,1,1,1,1,7,7,1,1,1,1,1,1,1,175,175,186,175,8,8,8,8,8,8,178
178,178,178,178,0,0,0,0,183,0,175,175,0,186,0,186,186,186,7,37,37,37,37,1,1,1,1,1,1,1,1,1,1,1,1,175,186,186,186,186,186,8,8,8,8,178
178,178,178,178,0,0,0,193,0,0,175,175,175,186,186,186,186,186,7,0,0,0,0,0,0,0,0,23,1,1,1,1,1,1,1,186,186,186,186,186,186,8,8,8,8,178
178,178,178,178,0,0,0,0,0,175,175,175,175,175,175,175,186,186,7,0,0,0,0,0,0,0,0,23,1,8,8,1,1,1,1,175,186,186,175,175,8,8,8,8,8,178
178,178,178,178,0,0,0,193,0,175,175,175,175,175,175,175,175,1,7,0,0,0,0,0,0,0,0,1,7,8,8,8,8,8,175,175,175,175,175,175,8,8,8,8,8,178
178,178,178,178,178,175,178,193,175,175,175,175,175,175,175,175,1,0,0,189,183,183,183,183,0,183,183,1,8,8,8,8,8,8,178,175,8,8,8,8,8,8,8,8,8,178
178,178,178,178,178,178,178,178,175,175,175,175,175,175,175,175,1,0,0,189,0,0,0,0,0,0,0,1,8,8,8,8,8,8,178,8,8,8,8,8,8,8,8,8,8,178
178,178,178,178,178,178,178,178,175,175,175,175,175,175,175,175,175,7,7,0,0,0,0,188,0,0,187,1,8,8,8,8,8,8,178,8,8,8,8,8,8,8,8,8,178,178
178,178,178,175,178,178,178,178,175,175,175,175,175,175,175,175,175,0,7,7,7,1,1,1,1,1,1,175,8,8,8,8,8,8,178,8,8,8,8,8,8,8,8,175,178,178
178,178,178,178,178,178,178,178,175,175,175,175,175,175,175,175,175,175,8,8,8,8,8,178,8,178,178,178,178,175,8,8,178,178,175,8,8,8,8,8,8,8,178,178,178,178
178,178,178,178,178,178,178,178,175,175,175,175,175,175,175,175,175,175,178,178,8,178,178,178,178,178,178,178,178,178,178,178,178,178,178,8,8,8,8,8,8,178,178,178,178,178
178,178,178,178,178,178,178,178,178,178,178,178,178,178,178,178,178,178,178,178,178,178,178,178,178,178,178,178,178,178,178,178,178,178,178,178,178,8,8,178,178,178,178,178,178,178
178,178,178,178,178,178,178,178,178,178,178,178,178,178,178,178,178,178,178,178,178,178,178,178,178,178,178,178,178,178,178,178,178,178,178,178,178,178,178,178,178,178,178,178,178,178
:endlayer
layer: 15
0,0,0,0,0,0,0,0,190,190,190,190,0,0,190,0,190,190,190,190,190,0,190,0,0,0,190,0,190,0,0,0,0,0,0,0,0,0,0,0,0,190,190,190,190,0
0,0,0,0,0,0,0,0,0,0,190,0,0,0,0,0,0,190,190,190,190,190,190,0,0,0,0,190,190,190,0,0,0,0,190,190,0,0,0,0,0,0,190,190,190,0
0,0,0,0,0,0,0,0,0,165,0,0,0,0,0,0,0,190,190,0,165,190,0,190,0,0,0,190,190,190,0,0,0,0,0,190,0,0,0,0,0,0,0,165,0,0
0,190,0,0,0,0,0,0,0,0,0,0,0,0,0,0,0,190,0,0,0,0,0,0,0,0,190,190,0,0,0,0,0,0,165,190,0,0,0,0,0,0,0,190,190,190
0,190,0,0,0,191,0,0,0,0,0,0,0,0,0,191,191,191,0,0,0,0,0,0,0,190,0,190,0,0,0,0,0,0,0,190,0,191,191,191,191,0,0,0,190,190
190,190,0,0,193,0,0,193,0,1,1,0,0,0,0,0,186,186,0,189,0,0,0,0,0,0,0,0,0,0,0,0,0,0,0,186,186,0,191,193,0,186,0,190,190,190
190,190,0,0,193,1,180,183,183,183,183,0,186,186,186,186,186,186,0,189,0,0,0,191,191,0,191,0,191,191,191,191,191,191,185,186,186,186,186,186,186,186,0,0,165,190
0,203,0,0,193,1,0,0,0,0,0,0,186,186,186,186,186,186,186,0,0,0,0,0,186,186,186,186,186,0,0,0,0,193,0,186,186,186,186,186,186,186,0,0,0,190
0,0,0,0,193,1,189,0,0,0,0,0,186,186,186,186,0,0,1,180,0,180,183,183,198,0,0,0,0,0,0,0,0,0,0,1,0,0,186,194,194,0,189,0,0,0
0,0,0,0,190,1,0,0,0,0,0,193,0,186,186,201,0,0,1,189,0,0,0,193,0,0,0,0,0,0,0,0,0,0,0,1,0,0,0,0,0,0,189,0,0,0
0,0,0,0,0,1,189,0,0,0,0,0,0,186,186,201,0,0,1,189,191,0,0,193,0,0,0,0,0,0,0,0,0,0,0,1,0,0,0,0,0,0,189,0,0,0
0,0,190,190,193,1,195,0,0,0,0,0,0,186,186,1,0,1,186,189,0,0,0,0,0,186,186,186,186,0,0,186,0,0,186,186,1,0,1,186,186,0,189,0,0,0
0,190,165,190,0,1,0,0,0,0,0,0,183,198,186,0,0,0,186,0,0,0,0,0,183,0,186,186,183,183,183,183,0,0,0,186,0,0,0,186,183,183,0,0,0,0
0,190,190,190,193,6,0,0,0,0,0,0,0,0,0,0,0,0,186,0,0,0,0,0,0,183,186,186,0,0,0,0,0,0,0,186,0,0,0,186,189,0,0,0,0,0
0,190,190,190,190,1,0,0,0,0,0,0,0,0,0,0,0,0,186,0,0,0,0,0,0,0,186,186,0,0,0,0,0,0,193,186,0,0,0,186,189,0,0,0,165,0
0,190,190,190,0,1,0,0,0,192,192,0,0,0,186,0,0,0,0,195,0,0,0,0,0,0,186,186,189,0,0,0,0,0,0,186,0,0,0,180,189,0,0,0,0,0
0,0,0,0,0,0,0,0,0,192,192,0,0,0,186,0,0,0,0,189,0,0,0,0,0,193,186,186,189,0,0,0,0,0,193,0,0,0,0,0,189,0,0,0,0,0
0,0,0,0,193,0,0,0,0,0,0,0,0,0,186,0,0,0,0,189,0,0,0,0,0,193,186,186,0,0,0,0,0,0,193,0,0,0,0,0,189,0,0,0,0,0
0,0,0,0,193,0,0,0,0,0,0,0,0,0,186,0,0,0,186,0,0,0,0,0,0,193,0,0,0,0,0,0,0,0,193,186,0,0,0,0,0,0,0,0,190,190
0,0,0,0,193,0,0,0,0,0,0,0,1,1,186,0,0,0,186,180,0,0,0,0,0,0,0,0,0,0,0,0,0,0,193,186,0,0,0,186,0,0,0,0,190,190
0,0,0,0,0,183,183,183,1,1,1,1,190,190,186,0,0,0,186,189,0,0,0,0,0,193,0,0,0,0,0,0,0,0,193,186,0,0,0,186,0,0,165,190,0,190
0,0,0,0,0,0,0,0,190,190,190,190,0,190,186,0,0,0,186,0,0,0,0,183,183,193,186,0,0,0,0,0,0,0,0,186,0,0,0,186,0,0,0,0,190,0
0,0,0,0,0,0,0,190,191,0,190,190,190,193,186,0,0,0,0,0,0,0,0,0,0,193,186,186,189,0,0,0,0,0,0,0,0,0,0,186,0,0,0,0,190,0
0,0,0,0,0,0,0,193,186,186,186,186,190,193,186,0,0,0,0,189,0,0,0,0,0,193,186,186,189,0,0,0,0,0,0,0,0,0,0,186,0,0,0,0,0,0
0,0,0,165,0,0,0,193,186,186,186,186,0,0,0,0,0,0,186,0,0,0,0,0,0,193,186,186,189,0,0,0,0,0,193,186,0,0,0,0,0,0,0,0,165,190
0,0,190,0,190,0,0,193,186,186,186,0,0,0,0,0,0,0,186,189,0,0,0,0,0,193,186,186,189,0,0,0,0,0,193,186,0,0,0,0,0,0,0,0,0,0
0,0,190,190,0,0,0,193,186,186,186,0,0,0,0,0,0,0,186,0,0,0,0,0,191,185,186,186,0,0,0,0,0,0,193,186,0,0,0,0,0,0,0,0,190,190
0,190,202,0,0,0,0,0,186,186,186,0,191,191,0,0,0,0,186,0,0,0,0,193,0,0,186,186,0,0,0,0,0,0,185,186,0,0,0,0,195,191,0,0,0,190
0,190,190,190,0,0,0,193,0,186,186,101,0,0,0,1,0,1,186,0,0,0,0,7,7,7,7,186,186,0,0,186,0,0,186,186,1,0,1,0,0,0,189,0,0,0
0,190,190,190,0,0,0,0,183,186,186,186,186,0,0,0,0,0,1,0,0,0,0,0,0,0,0,0,0,0,0,0,0,0,0,1,0,0,0,0,0,0,189,0,0,0
0,190,190,0,0,0,0,193,0,186,186,186,0,180,183,0,0,0,7,0,0,0,0,0,0,0,0,0,0,0,0,0,0,0,0,0,0,0,0,0,0,0,189,0,0,0
0,190,0,0,0,0,0,0,0,186,186,186,186,0,0,183,0,0,1,0,0,0,0,0,0,0,0,0,0,0,0,0,0,0,0,1,0,0,186,196,196,0,189,0,0,0
190,0,190,190,0,0,0,193,186,186,186,186,0,0,0,0,186,186,186,0,0,0,0,0,0,0,0,186,7,0,0,0,0,186,186,186,186,186,186,186,0,0,189,0,0,0
0,0,190,190,190,165,0,193,186,186,186,186,0,189,0,0,186,186,0,189,183,183,183,183,0,183,183,7,180,183,0,0,0,183,198,186,186,186,186,0,0,0,189,0,0,0
190,190,190,190,190,190,0,193,186,186,186,186,183,0,0,193,186,186,0,189,0,0,0,0,0,0,0,7,0,0,0,0,0,0,193,186,0,189,0,0,0,0,0,0,0,0
190,190,190,190,190,0,0,0,186,186,186,186,186,186,186,186,186,7,7,0,0,0,0,0,0,0,0,7,0,0,0,0,0,0,0,0,197,183,183,183,183,0,0,0,0,0
0,0,190,165,0,0,0,193,186,186,186,186,186,186,186,186,186,7,7,7,7,7,7,1,1,1,1,7,0,0,0,0,0,0,0,0,0,0,0,0,0,0,0,165,0,0
0,0,0,0,0,0,190,0,186,186,186,186,186,186,186,186,186,200,199,0,0,0,0,0,0,0,0,0,190,165,0,0,0,0,165,0,0,0,0,0,0,0,0,0,0,0
0,0,0,190,190,0,190,0,186,186,186,186,186,186,186,186,186,200,199,0,0,190,190,190,0,0,0,0,190,190,0,190,0,0,0,0,0,0,0,0,0,190,190,0,190,0
0,190,190,0,190,0,0,0,183,183,183,0,190,190,202,190,0,0,0,0,190,190,190,190,0,0,0,0,190,190,190,0,0,0,0,0,0,0,0,190,0,190,0,190,0,0
0,0,0,0,190,190,190,0,0,0,0,190,0,190,190,190,0,0,0,0,190,190,190,0,190,0,0,190,0,190,190,190,0,0,0,0,0,0,0,0,190,190,190,0,190,0
:endlayer
layer: 16
0,0,0,0,0,0,0,0,0,0,0,0,0,0,0,0,0,0,0,0,0,0,0,0,0,0,0,0,0,0,0,0,0,0,0,0,0,0,0,0,0,0,0,0,0,0
0,0,0,0,0,0,0,0,0,0,0,0,0,0,0,0,0,0,0,0,0,0,0,0,0,0,0,0,0,0,0,0,0,0,0,0,0,0,0,0,0,0,0,0,0,0
0,0,0,0,0,0,0,0,0,165,0,0,0,0,0,0,0,0,0,0,165,0,0,0,0,0,0,0,0,0,0,0,0,0,0,0,0,0,0,0,0,0,0,165,0,0
0,0,0,0,0,0,0,0,0,0,0,0,0,0,0,0,0,0,0,0,0,0,0,0,0,0,0,0,0,0,0,0,0,0,165,0,0,0,0,0,0,0,0,0,0,0
0,0,0,0,0,191,0,0,0,0,0,0,0,0,0,191,191,191,0,0,0,0,0,0,0,0,0,0,0,0,0,0,0,0,0,0,0,191,191,191,191,0,204,204,204,204
0,0,0,0,193,0,0,193,1,1,1,0,0,0,0,0,1,1,0,189,0,0,0,0,0,0,0,0,0,0,0,0,0,0,0,186,0,0,0,193,0,0,204,204,204,204
0,0,0,0,193,1,180,183,183,183,183,0,1,186,186,186,186,186,0,189,0,0,0,191,191,0,191,0,191,191,191,191,191,191,185,1,186,186,201,0,198,1,204,204,165,204
0,0,0,0,193,1,0,0,0,0,0,0,1,186,186,186,186,186,1,0,0,0,0,0,1,1,1,1,1,0,0,0,0,193,1,1,186,186,201,0,0,1,204,204,204,204
0,0,0,0,193,1,189,0,0,0,0,0,1,194,194,186,0,0,1,180,0,180,183,183,198,0,0,0,0,0,0,0,0,0,0,1,0,0,186,0,0,0,189,204,204,204
0,0,0,0,193,1,0,0,0,0,0,193,1,0,0,0,0,0,1,189,0,0,0,193,0,0,0,0,0,0,0,0,0,0,0,1,0,0,0,0,0,0,189,0,0,0
0,0,0,0,0,1,189,0,0,0,0,0,0,0,0,0,0,0,1,189,191,0,0,193,0,0,0,0,0,0,0,0,0,0,0,1,0,0,0,0,0,0,189,0,0,0
0,0,0,0,193,1,195,0,0,0,0,0,0,1,1,1,0,1,0,189,0,0,0,0,0,186,186,186,186,0,0,186,0,0,186,186,1,0,1,1,1,0,189,0,0,0
0,0,165,0,0,1,0,0,0,0,0,0,183,198,1,0,0,0,0,0,0,0,0,0,183,0,186,186,183,183,183,183,0,0,0,186,0,0,0,1,183,183,204,204,204,204
0,0,0,0,193,205,0,0,0,0,0,0,0,0,0,0,0,0,0,0,0,0,0,0,0,183,186,186,0,0,0,0,0,0,0,186,0,0,0,1,189,0,204,204,204,204
0,0,0,0,206,1,0,0,0,0,0,0,0,0,1,0,0,0,0,0,0,0,0,0,0,0,186,186,0,0,0,0,0,0,193,186,0,0,0,1,189,0,204,204,165,204
0,0,0,0,0,0,0,0,0,192,192,0,0,0,1,0,0,0,0,195,0,0,0,0,0,0,186,186,189,0,0,0,0,0,0,186,0,0,0,180,189,0,204,204,204,204
0,0,0,0,0,0,0,0,0,192,192,0,0,0,1,0,0,0,0,189,0,0,0,0,0,193,186,186,189,0,0,0,0,0,193,0,0,0,0,0,189,0,204,204,204,204
0,0,0,0,193,0,0,0,0,0,0,0,0,0,1,0,0,0,0,189,0,0,0,0,0,193,186,101,0,0,0,0,0,0,193,0,0,0,0,0,189,0,0,0,0,0
0,0,0,0,193,0,0,0,0,0,0,0,0,0,1,0,0,0,186,0,0,0,0,0,0,193,0,0,0,0,0,0,0,0,193,186,0,0,0,0,0,0,0,0,0,0
0,0,0,0,193,0,0,0,0,0,0,0,1,1,1,0,0,0,186,180,0,0,0,0,0,0,0,0,0,0,0,0,0,0,193,186,0,0,0,0,0,0,0,0,0,0
0,0,0,0,0,183,183,183,1,1,1,1,0,193,1,0,0,0,186,189,0,0,0,0,0,193,0,0,0,0,0,0,0,0,193,186,0,0,0,1,0,0,165,0,0,0
0,0,0,0,0,0,0,0,193,0,0,0,0,193,1,0,0,0,186,0,0,0,0,183,183,193,186,0,0,0,0,0,0,0,0,186,0,0,0,1,0,0,0,0,0,0
0,0,0,0,0,0,0,0,191,0,0,0,0,193,1,0,0,0,0,0,0,0,0,0,0,193,186,186,189,0,0,0,0,0,0,0,0,0,0,1,0,0,0,204,204,204
0,0,0,0,0,0,0,193,186,186,186,186,0,193,1,0,0,0,0,189,0,0,0,0,0,193,186,186,189,0,0,0,0,0,0,0,0,0,0,1,0,0,204,204,204,204
0,0,0,165,0,0,0,193,186,186,186,186,0,0,0,0,0,0,186,0,0,0,0,0,0,193,186,186,189,0,0,0,0,0,193,186,0,0,0,0,0,0,204,204,165,204
0,0,0,0,0,0,0,193,186,186,186,0,0,0,0,0,0,0,186,189,0,0,0,0,0,193,186,186,189,0,0,0,0,0,193,186,0,0,0,0,0,0,204,204,204,204
0,0,0,0,0,0,0,193,186,186,186,0,0,0,0,0,0,0,186,0,0,0,0,0,191,185,186,186,0,0,0,0,0,0,193,186,0,0,0,0,0,0,204,204,204,204
0,0,0,0,0,0,0,0,0,186,186,0,191,191,0,0,0,0,186,0,0,0,0,193,0,0,186,186,0,0,0,0,0,0,191,186,0,0,0,0,195,191,0,0,0,0
0,0,0,0,0,0,0,193,0,186,186,0,0,0,0,1,0,1,186,0,0,0,0,7,0,7,7,186,186,0,0,186,0,0,186,186,1,0,1,1,0,0,189,0,0,0
0,0,0,0,0,0,0,0,183,186,186,186,1,0,0,0,0,0,1,0,0,0,0,0,0,0,0,0,0,0,0,0,0,0,0,1,0,0,0,0,0,0,189,0,0,0
0,0,0,0,0,0,0,193,0,186,186,186,0,180,183,0,0,0,0,0,0,0,0,0,0,0,0,0,0,0,0,0,0,0,0,0,0,0,0,0,0,0,189,0,0,0
0,0,0,0,0,0,0,0,0,186,186,186,0,0,0,183,0,0,1,0,0,0,0,0,0,0,0,0,0,0,0,0,0,0,0,1,0,0,186,0,0,0,189,0,0,0
0,0,0,0,0,0,0,193,186,186,186,186,0,0,0,0,186,186,1,0,0,0,0,0,0,0,0,1,7,0,0,0,0,0,1,1,186,186,201,0,0,0,189,0,0,0
0,0,0,0,0,165,0,193,186,186,186,186,0,189,0,0,186,186,0,189,183,183,183,183,0,183,183,7,180,183,0,0,0,183,198,1,186,186,201,0,0,0,189,0,0,0
0,204,204,204,204,0,0,193,186,186,186,186,183,0,0,193,1,1,0,189,0,0,0,0,0,0,0,7,0,0,0,0,0,0,193,186,0,189,0,0,0,0,204,204,204,204
0,204,204,204,204,204,0,0,186,186,186,186,186,186,186,7,7,7,7,0,0,0,0,0,0,0,0,7,0,0,0,0,204,204,204,204,204,183,183,183,183,204,204,204,204,204
0,204,204,165,204,204,0,193,186,186,186,186,186,186,186,7,7,7,7,7,7,7,7,7,7,7,7,7,0,0,0,0,204,204,204,204,204,0,0,0,0,204,204,165,204,204
0,204,204,204,204,204,0,0,186,186,186,186,186,0,186,200,199,0,0,0,0,0,0,0,0,0,0,0,0,165,0,0,204,204,165,204,204,0,0,0,0,204,204,204,204,204
0,204,204,204,204,204,0,0,186,186,186,186,186,186,186,200,199,0,0,0,0,0,0,0,0,0,0,0,0,0,0,0,204,204,204,204,204,0,0,0,0,204,204,204,204,204
0,0,0,0,0,0,0,0,183,183,183,0,0,0,0,0,0,0,0,0,0,0,0,0,0,0,0,0,0,0,0,0,204,204,204,204,204,0,0,0,0,0,0,0,0,0
0,0,0,0,0,0,0,0,0,0,0,0,0,0,0,0,0,0,0,0,0,0,0,0,0,0,0,0,0,0,0,0,0,0,0,0,0,0,0,0,0,0,0,0,0,0
:endlayer
layer: 17
0,0,0,0,0,0,0,0,204,204,204,204,0,0,0,0,0,0,0,204,204,204,204,0,0,0,0,0,0,0,0,0,0,0,0,0,0,0,0,0,0,0,0,0,0,0
0,0,0,0,0,0,0,204,204,204,204,204,0,0,0,0,0,0,204,204,204,204,204,0,0,0,0,0,0,0,0,0,0,0,0,0,0,0,0,0,0,0,0,0,0,0
0,0,0,0,0,0,0,204,204,165,204,204,0,0,0,0,0,0,204,204,165,204,204,0,0,0,0,0,0,0,0,0,0,0,0,0,0,0,0,0,0,0,0,165,0,0
0,0,0,0,0,0,0,204,204,204,204,204,0,0,0,0,0,0,204,204,204,204,204,0,0,0,0,0,0,0,0,0,0,0,165,0,0,0,0,0,0,0,0,0,0,0
0,0,0,0,0,191,0,0,204,204,204,0,0,0,0,191,191,191,204,204,204,204,204,0,0,0,0,0,0,0,0,0,0,0,197,0,0,191,191,191,191,0,204,204,204,204
0,0,0,0,193,0,0,193,1,1,0,0,0,0,0,0,1,1,186,189,0,0,0,0,0,0,0,0,0,0,0,0,0,0,197,186,1,0,0,193,1,0,204,204,204,204
0,0,0,0,193,1,180,183,183,183,183,0,1,0,0,207,186,186,0,189,0,0,0,191,191,0,191,0,191,191,191,191,191,191,185,1,0,0,0,0,198,1,204,204,165,204
0,0,0,0,193,1,0,0,0,0,0,0,1,0,0,207,186,186,1,0,0,0,0,0,1,1,1,1,1,1,0,0,0,193,1,1,0,0,193,0,0,1,204,204,204,204
0,0,0,0,193,1,189,0,0,0,0,0,1,0,0,186,186,186,1,180,0,180,183,183,198,0,0,0,0,0,0,0,0,0,0,1,196,196,186,0,0,0,189,204,204,204
0,0,0,0,193,1,0,0,0,0,0,193,0,0,0,0,0,0,1,189,0,0,0,193,0,0,0,0,0,0,0,0,0,0,0,1,0,0,0,0,0,0,189,0,0,0
0,0,0,0,0,1,189,0,0,0,0,0,0,0,0,0,0,0,1,189,191,0,0,193,0,0,0,0,0,0,0,0,0,0,0,1,0,0,0,0,0,0,189,0,0,0
0,0,0,0,193,1,195,0,0,0,0,0,0,1,1,1,1,1,186,189,0,0,0,0,186,186,186,186,186,186,186,186,186,186,186,186,1,1,1,1,1,0,189,0,0,0
0,0,165,0,0,1,0,0,0,0,0,0,183,198,1,0,0,0,0,0,0,0,0,0,183,0,186,186,183,183,183,183,0,0,0,186,0,0,0,1,183,183,204,204,204,204
0,0,0,0,193,1,0,0,0,0,0,0,0,0,0,0,0,0,0,0,0,0,0,0,0,183,186,186,0,0,0,0,0,0,0,186,0,0,0,1,189,0,204,204,204,204
0,0,0,0,193,1,0,0,0,0,0,0,0,0,1,0,0,0,0,0,0,0,0,0,0,0,186,186,0,0,0,0,0,0,193,186,0,0,0,1,189,0,204,204,165,204
0,0,0,0,0,1,0,0,0,192,192,0,0,0,1,0,0,0,0,195,0,0,0,0,0,0,186,186,189,0,0,0,0,0,0,186,0,0,0,180,189,0,204,204,204,204
0,0,0,0,0,0,0,0,0,192,192,0,1,1,1,0,0,0,0,189,0,0,0,0,0,193,186,186,189,0,0,0,0,0,193,186,0,0,0,0,189,0,0,204,204,204
0,0,0,0,193,1,0,0,0,0,0,0,1,1,1,0,0,0,186,189,0,0,0,0,0,193,186,0,0,0,0,0,0,0,193,186,0,0,0,0,189,0,0,0,0,0
0,0,0,0,193,0,0,0,0,0,0,0,1,1,1,0,0,0,186,0,0,0,0,0,0,193,186,0,0,0,0,0,0,0,193,186,0,0,0,0,204,204,204,204,0,0
0,0,0,0,193,0,1,0,0,0,0,1,1,1,1,0,0,0,186,180,0,0,0,0,0,0,186,0,0,0,0,0,0,0,193,186,0,0,0,1,204,204,204,204,204,0
0,0,0,0,0,183,183,183,1,1,1,1,0,193,1,0,0,0,186,189,197,0,0,0,0,193,186,0,0,0,0,0,0,0,193,186,0,0,0,1,204,204,165,204,204,0
0,0,0,0,0,0,0,0,193,0,0,0,0,193,1,0,0,0,186,0,0,0,0,183,183,193,186,0,0,0,0,0,0,0,0,186,0,0,0,1,204,204,204,204,204,0
0,0,204,204,204,0,0,0,191,0,0,0,0,193,1,0,0,0,186,0,0,0,0,0,0,193,186,186,189,0,0,0,0,0,0,186,0,0,0,1,204,204,204,204,204,204
0,204,204,204,204,204,0,193,186,186,186,186,0,193,1,0,0,0,186,189,0,0,0,0,0,193,186,186,189,0,0,0,0,0,0,186,0,0,0,1,0,0,204,204,204,204
0,204,204,165,204,204,0,193,186,186,186,186,0,0,1,0,0,0,186,0,0,0,0,0,0,193,186,186,189,0,0,0,0,0,193,186,0,0,0,0,0,0,204,204,165,204
0,204,204,204,204,204,0,193,186,186,186,0,0,0,0,0,0,0,186,189,0,0,0,0,0,193,186,186,189,0,0,0,0,0,193,186,0,0,0,0,0,0,204,204,204,204
0,0,204,204,204,0,0,193,186,186,186,0,0,0,0,0,0,0,186,0,0,0,0,0,191,185,186,186,0,0,0,0,0,0,193,186,0,0,0,0,0,0,204,204,204,204
0,0,0,0,0,0,0,0,0,186,186,0,191,191,0,0,0,0,186,0,0,0,0,193,0,0,186,186,0,0,0,0,0,0,191,186,0,0,0,0,195,191,0,0,0,0
0,0,0,0,0,0,0,193,0,186,186,186,0,0,1,1,1,1,186,0,0,0,0,7,7,7,7,186,186,186,186,186,186,186,186,186,1,1,1,1,1,0,189,0,0,0
0,0,0,0,0,0,0,0,183,186,186,186,1,0,0,0,0,0,1,0,0,0,0,0,0,0,0,0,0,0,0,0,0,0,0,1,0,0,0,0,0,0,189,0,0,0
0,0,0,0,0,0,0,193,0,186,186,186,0,180,183,0,0,0,1,0,0,0,0,0,0,0,0,0,0,0,0,0,0,0,0,1,0,0,0,0,0,0,189,0,0,0
0,0,0,0,0,0,0,0,0,186,186,186,0,0,0,183,194,194,1,0,0,0,0,0,0,0,0,0,0,0,0,0,0,0,0,1,194,194,186,0,0,0,189,0,0,0
0,0,0,0,0,0,0,0,0,186,186,186,0,0,0,0,0,193,1,0,0,0,0,0,0,0,0,0,7,0,0,0,0,1,1,1,0,0,0,0,0,0,189,0,0,0
0,0,0,0,0,165,0,193,186,186,186,186,0,189,0,0,191,193,0,189,183,183,183,183,0,183,183,7,180,183,0,0,0,183,198,1,0,0,0,0,0,0,189,0,0,0
0,0,204,204,204,0,0,193,0,186,0,0,183,0,0,193,0,1,0,189,0,0,0,0,0,0,0,7,0,0,0,0,0,0,193,186,0,189,0,0,0,204,204,204,204,0
0,204,204,204,204,204,0,0,183,0,183,0,0,0,0,0,0,7,7,0,0,0,0,0,0,0,0,7,0,0,0,0,0,204,204,204,204,183,183,183,183,204,204,204,204,204
0,204,204,165,204,204,0,193,186,0,0,0,0,0,0,7,7,7,7,7,7,7,0,7,7,7,0,7,0,0,0,0,204,204,204,204,204,0,0,0,0,204,204,165,204,204
0,204,204,204,204,204,0,0,0,0,0,0,0,0,0,0,0,0,0,0,0,0,0,0,0,0,0,0,0,165,0,0,204,204,165,204,204,0,0,0,0,204,204,204,204,204
0,0,204,204,204,204,0,0,186,186,0,0,0,200,199,0,0,0,0,0,0,0,0,0,0,0,0,0,0,0,0,0,204,204,204,204,204,0,0,0,0,0,204,204,204,204
0,0,0,0,0,0,0,0,183,183,0,0,0,0,0,0,0,0,0,0,0,0,0,0,0,0,0,0,0,0,0,0,0,204,204,204,0,0,0,0,0,0,0,0,0,0
0,0,0,0,0,0,0,0,0,0,0,0,0,0,0,0,0,0,0,0,0,0,0,0,0,0,0,0,0,0,0,0,0,0,0,0,0,0,0,0,0,0,0,0,0,0
:endlayer
layer: 18
0,0,0,0,0,0,0,204,204,204,204,0,0,0,0,0,0,0,204,204,204,204,204,0,0,0,0,0,0,0,0,0,0,0,0,0,0,0,0,0,0,204,204,204,204,204
0,0,0,0,0,0,0,204,204,204,204,204,0,0,0,0,0,0,204,204,204,204,204,0,0,0,0,0,0,0,0,0,204,204,204,204,0,0,0,0,0,204,204,204,204,204
0,0,0,0,0,0,0,204,204,165,204,204,0,0,0,0,0,0,204,204,165,204,204,0,0,0,0,0,0,0,0,0,204,204,204,204,204,0,0,0,0,204,204,165,204,204
0,0,0,0,0,0,0,204,204,204,204,204,0,0,0,0,0,0,204,204,204,204,204,0,0,0,0,0,0,0,0,0,204,204,165,204,204,0,0,0,0,204,204,204,204,204
0,0,0,0,0,191,0,0,204,204,204,0,0,0,0,191,191,191,204,204,204,204,204,0,0,0,0,0,0,0,0,0,204,204,204,204,204,191,191,191,191,0,204,204,204,0
0,0,0,0,193,0,0,193,1,1,1,1,0,0,0,1,1,1,186,189,0,0,0,0,0,0,0,0,0,0,0,0,204,204,204,186,1,0,1,1,0,0,189,204,204,204
0,0,0,0,193,1,180,183,183,183,183,0,1,0,0,0,0,0,1,189,0,0,0,191,191,0,191,0,191,191,191,191,191,191,185,1,0,0,0,0,193,1,189,204,165,204
0,0,0,0,193,1,0,0,0,0,0,0,1,0,0,0,0,193,1,0,0,0,0,0,1,1,1,1,1,1,0,0,0,1,1,1,0,0,193,0,0,1,189,204,204,204
0,0,0,0,193,1,189,0,0,0,0,0,1,0,0,186,196,196,186,180,0,180,183,183,198,186,186,186,186,101,186,186,186,186,186,1,0,0,186,0,0,0,189,0,0,0
0,0,0,0,193,1,0,0,0,0,0,193,0,0,0,186,186,186,186,189,0,0,0,193,0,186,186,186,186,186,186,186,186,186,186,186,196,196,186,186,186,0,189,0,0,0
0,0,0,0,0,1,189,0,0,0,0,0,0,0,0,186,186,186,186,189,191,0,0,193,186,186,186,186,186,186,186,186,186,186,186,186,186,186,186,186,186,0,189,0,0,0
0,0,0,0,193,1,195,0,0,0,0,0,186,1,1,186,186,186,186,189,0,0,0,186,186,186,186,186,186,186,186,186,186,186,186,186,186,186,186,1,1,0,189,0,0,0
0,0,165,0,0,1,0,0,0,0,0,0,183,198,1,186,186,186,0,0,0,0,0,0,183,208,186,186,208,208,208,208,208,208,208,186,186,186,186,1,183,183,0,0,0,0
0,0,0,0,193,1,0,0,0,0,0,0,0,0,1,186,186,186,186,0,0,0,0,0,0,183,208,208,0,0,208,0,208,208,208,186,186,186,186,1,189,0,0,204,204,0
0,0,0,0,193,1,0,0,0,0,0,0,0,0,1,186,186,186,0,0,0,0,0,0,0,0,208,0,0,0,0,0,0,0,208,186,186,186,186,0,189,0,0,204,165,204
0,0,0,0,0,1,1,1,0,1,1,1,1,1,1,186,186,186,186,195,0,0,0,0,0,0,208,0,0,0,0,0,0,0,208,186,186,186,186,189,189,0,0,0,204,0
0,0,0,0,0,1,0,0,0,192,192,1,0,0,1,186,186,186,186,189,0,0,0,0,0,208,208,0,0,0,0,0,0,0,208,186,186,186,186,0,189,0,0,0,0,0
0,0,0,0,193,1,0,0,0,0,0,0,0,0,1,186,186,186,186,189,0,0,0,0,208,208,186,0,0,0,0,0,0,0,208,186,186,186,186,0,189,0,0,0,0,0
0,0,0,0,193,1,1,0,0,0,0,1,0,1,1,186,186,186,186,208,0,0,208,208,208,208,208,0,0,0,0,0,0,0,193,186,186,186,186,0,204,204,204,204,204,0
0,0,0,0,193,0,1,1,0,0,0,1,1,1,1,186,186,186,186,180,0,0,208,208,208,208,208,0,0,0,0,0,0,0,193,186,186,186,186,1,204,204,204,204,204,0
0,0,0,0,0,183,183,183,1,1,1,1,0,193,1,186,186,186,186,208,208,208,208,208,0,208,208,0,0,0,0,0,0,0,208,186,186,186,186,1,204,204,165,204,204,0
0,0,0,0,0,0,0,0,193,0,0,0,0,193,1,0,0,0,0,208,208,208,208,183,183,208,208,0,0,0,0,0,0,0,208,186,186,186,186,1,204,204,204,204,204,0
0,204,204,204,204,204,0,0,191,0,0,0,0,193,0,0,0,0,0,208,208,208,208,0,0,193,0,0,0,0,0,0,0,0,208,186,186,186,186,1,204,204,204,204,204,0
0,204,204,204,204,204,0,193,186,186,186,186,0,0,0,0,0,0,0,208,208,208,208,0,0,193,0,0,0,0,0,0,208,208,208,186,186,186,186,1,0,0,0,0,204,204
0,204,204,165,204,204,0,193,186,186,186,186,0,0,0,0,0,0,0,0,208,208,208,0,0,193,0,0,0,0,208,208,208,208,208,186,186,186,186,0,0,0,0,204,165,204
0,204,204,204,204,204,0,193,186,186,186,186,0,0,0,0,0,0,0,0,0,0,0,0,0,193,0,0,0,0,208,208,208,208,208,186,186,186,186,0,0,0,0,0,204,204
0,204,204,204,204,204,0,193,186,186,186,0,0,0,0,0,0,0,0,0,0,0,0,0,191,191,0,0,0,208,208,208,208,208,208,186,186,186,186,1,0,0,0,0,0,0
0,0,0,0,0,0,0,0,186,200,200,200,191,191,0,186,186,186,186,0,0,0,0,193,208,208,186,186,208,208,208,208,208,208,208,186,186,186,186,0,195,191,0,0,0,0
0,0,0,0,0,0,0,193,186,199,199,199,186,1,1,186,186,186,186,0,0,0,0,7,0,186,186,186,186,186,186,186,186,186,186,186,186,186,186,1,1,0,189,0,0,0
0,0,0,0,0,0,0,0,183,0,0,0,1,186,186,186,186,186,186,0,0,0,0,0,186,186,186,186,186,186,186,186,186,186,186,186,186,186,186,186,186,0,189,0,0,0
0,0,0,0,0,0,0,193,0,0,0,1,1,180,183,186,194,194,1,0,0,0,0,186,186,186,186,186,186,186,186,186,186,186,186,186,194,194,186,186,186,0,189,0,0,0
0,0,0,0,0,0,0,0,1,0,209,1,0,0,0,183,0,0,1,186,186,186,186,186,186,186,186,186,186,186,186,186,186,101,186,186,0,0,186,186,0,0,189,0,0,0
0,0,0,0,0,0,0,0,1,0,0,1,0,0,0,0,0,193,1,0,1,1,0,1,0,0,1,0,1,1,0,0,0,1,1,1,0,0,0,0,0,0,189,0,0,0
0,0,0,0,0,165,0,193,1,0,0,1,0,189,0,0,191,193,0,189,183,183,183,183,0,183,183,7,180,183,0,0,0,183,198,1,0,0,0,0,0,0,189,0,0,0
0,0,0,0,0,0,0,193,0,0,0,0,183,0,0,193,0,1,186,189,0,0,0,0,0,0,0,0,0,0,0,0,0,0,193,186,1,189,0,0,0,0,189,0,0,0
0,0,204,204,0,0,0,0,183,0,183,0,0,0,0,0,0,7,183,0,0,0,0,0,0,0,0,0,0,0,0,0,0,0,0,183,183,183,183,183,183,183,0,204,204,0
0,0,204,165,204,0,0,0,0,0,0,0,0,0,0,0,7,7,7,7,7,7,0,7,7,0,0,7,0,0,0,0,0,0,204,204,0,0,0,0,0,0,204,165,204,0
0,0,0,204,204,0,0,0,0,0,0,0,0,0,0,0,0,0,0,0,0,0,0,0,0,0,0,0,0,165,0,0,0,204,165,204,0,0,0,0,0,0,0,204,204,0
0,0,0,0,0,0,0,0,0,0,0,0,0,0,0,0,0,0,0,0,0,0,0,0,0,0,0,0,0,0,0,0,0,204,204,0,0,0,0,0,0,0,0,0,0,0
0,0,0,0,0,0,0,0,0,0,0,0,0,0,0,0,0,0,0,0,0,0,0,0,0,0,0,0,0,0,0,0,0,0,0,0,0,0,0,0,0,0,0,0,0,0
0,0,0,0,0,0,0,0,0,0,0,0,0,0,0,0,0,0,0,0,0,0,0,0,0,0,0,0,0,0,0,0,0,0,0,0,0,0,0,0,0,0,0,0,0,0
:endlayer
layer: 19
0,0,0,0,0,0,0,0,0,0,0,0,0,0,0,0,0,0,0,0,0,0,0,0,0,0,0,0,0,0,0,0,0,0,0,0,0,0,0,0,0,0,204,204,204,204
0,0,0,0,0,0,0,0,0,204,0,0,0,0,0,0,0,0,0,204,204,204,0,0,0,0,0,0,0,0,0,0,0,204,204,204,0,0,0,0,0,204,204,204,204,204
0,0,0,0,0,0,0,0,204,165,204,0,0,0,0,0,0,0,0,204,165,204,0,0,0,0,0,0,0,0,0,0,204,204,204,204,204,0,0,0,0,204,204,165,204,204
0,0,0,0,0,0,0,0,204,204,0,0,0,0,0,0,0,0,0,204,204,0,0,0,0,0,0,0,0,0,0,0,204,204,165,204,204,0,0,0,0,204,204,204,204,204
0,0,0,0,0,191,0,0,0,0,0,0,0,0,0,191,191,191,191,0,0,0,0,0,0,0,0,0,0,0,0,0,204,204,204,204,204,191,191,191,191,204,204,204,204,0
0,0,0,0,193,1,1,1,1,1,1,1,186,1,1,1,1,1,186,189,0,0,0,0,0,0,0,0,0,0,0,0,204,204,204,186,1,1,1,1,1,186,189,0,204,0
0,0,0,0,193,1,180,183,183,183,183,0,1,0,0,0,0,0,1,189,0,0,0,191,191,0,191,0,191,191,191,191,191,191,185,1,0,0,0,186,186,1,189,204,204,204
0,204,0,0,193,1,0,0,0,0,0,0,1,0,0,0,0,193,1,0,0,0,0,0,1,1,1,1,1,1,1,1,1,1,1,1,0,0,193,186,186,1,189,0,204,0
204,204,204,0,193,1,189,0,0,0,0,0,1,186,186,186,0,193,186,180,0,180,183,183,198,0,186,186,186,0,0,0,0,0,186,1,0,0,186,194,194,1,189,0,0,0
0,204,0,0,193,1,0,0,0,0,0,193,1,186,186,201,0,0,183,0,0,0,0,193,0,0,0,0,0,0,0,0,0,0,0,186,0,0,193,0,0,1,189,0,0,0
0,0,0,0,0,1,189,0,0,0,0,0,1,186,186,201,0,0,0,0,191,0,0,193,0,0,0,0,0,0,0,0,0,0,0,0,0,0,0,0,0,1,189,0,0,0
0,0,0,0,193,1,195,0,0,0,0,0,186,1,1,1,0,1,0,0,0,0,0,193,0,186,186,186,186,0,0,0,0,0,186,186,1,0,1,1,1,186,189,0,0,0
0,0,165,0,0,1,0,0,0,0,0,0,183,193,1,186,0,186,186,0,0,0,0,0,0,0,186,186,0,0,0,0,0,0,0,186,0,0,0,1,183,183,0,0,0,0
0,0,0,0,193,1,0,0,0,0,0,0,0,0,1,201,0,0,0,0,0,0,0,0,0,0,0,0,0,0,0,0,0,0,0,0,0,0,0,1,189,0,0,0,204,0
0,0,0,0,193,1,0,0,0,0,0,0,0,0,1,201,0,0,0,0,0,0,0,0,0,0,0,0,0,0,0,0,0,0,0,0,0,0,0,1,189,0,0,204,204,204
0,0,0,0,0,1,1,1,1,1,1,1,1,1,1,201,0,0,0,195,0,0,0,0,0,0,0,0,0,0,0,0,0,0,0,0,0,0,0,1,189,0,0,0,204,0
0,0,0,0,0,1,0,0,0,192,192,0,0,0,1,186,0,0,186,189,0,0,0,0,0,0,0,0,0,0,0,0,0,0,0,0,0,0,0,1,189,0,0,0,0,0
0,0,0,0,193,1,0,0,0,0,0,0,0,0,1,186,0,0,186,189,0,0,0,0,0,0,186,0,0,0,0,0,0,0,193,0,0,0,0,1,189,0,0,0,0,0
0,0,0,0,193,1,0,0,0,0,0,0,0,0,1,0,0,0,0,0,0,0,0,0,0,0,0,0,0,0,0,0,0,0,193,186,0,0,186,1,189,0,0,0,0,0
0,0,0,0,193,1,1,1,1,0,0,1,1,1,1,180,0,0,0,0,0,0,0,0,0,0,0,0,0,0,0,0,0,0,193,186,0,0,186,1,189,0,204,0,0,0
0,0,0,0,0,183,183,183,1,0,0,1,0,193,1,189,0,0,0,0,0,0,0,0,0,193,0,0,0,0,0,0,0,0,193,186,0,0,186,1,189,204,165,204,0,0
0,0,0,0,0,0,0,0,193,1,1,0,0,0,183,0,0,0,0,0,208,208,208,183,183,0,0,0,0,0,0,0,0,0,193,186,0,0,186,1,0,0,204,204,0,0
0,0,0,0,0,0,0,0,191,0,0,0,0,193,0,0,0,0,0,0,208,211,208,0,0,193,0,0,0,0,0,0,0,0,0,0,0,0,0,1,0,0,0,0,0,0
0,0,204,204,0,0,0,193,186,186,186,186,0,0,0,0,0,0,0,0,208,208,208,0,0,193,0,0,0,0,0,0,0,0,0,0,0,0,0,1,0,0,0,0,204,0
0,0,204,165,204,0,0,193,186,186,186,186,0,0,0,0,0,0,0,0,0,0,0,0,0,193,0,0,0,0,0,189,0,0,0,0,0,0,0,1,0,0,0,204,204,204
0,0,204,204,0,0,0,193,186,200,200,200,0,0,0,0,0,0,0,0,0,0,0,0,0,193,0,0,0,0,0,0,0,0,0,0,0,0,0,1,0,0,0,0,204,0
0,0,0,0,0,0,0,193,186,199,199,199,0,0,1,0,0,0,0,0,0,0,0,0,0,0,0,0,0,0,0,0,0,0,0,0,0,0,0,1,0,0,0,0,0,0
0,0,0,0,0,0,0,0,186,0,0,0,191,191,1,186,0,186,0,0,0,0,0,0,0,0,0,0,0,0,0,0,0,0,0,186,0,0,0,1,195,191,0,0,0,0
0,0,0,0,0,0,0,193,186,0,0,193,186,1,1,1,0,1,186,0,0,0,0,0,0,186,186,186,186,0,0,0,0,0,186,186,1,0,1,1,1,0,189,0,0,0
0,0,0,0,0,0,0,0,199,0,0,0,1,0,0,0,0,0,0,0,0,0,0,0,0,0,0,0,0,0,0,0,0,0,0,0,0,0,0,0,0,1,189,0,0,0
0,0,0,0,0,0,0,193,1,0,0,1,1,189,0,0,0,0,0,0,0,0,0,0,0,0,0,0,0,0,0,0,0,0,0,0,0,0,0,0,0,1,189,0,0,0
0,0,204,0,0,0,0,0,1,0,209,1,1,0,0,0,0,0,186,0,0,0,0,0,0,186,186,186,186,0,0,0,0,0,186,186,0,0,186,196,196,1,189,0,0,0
0,204,204,204,0,0,0,0,1,0,0,1,0,0,0,0,0,193,1,1,1,1,1,1,1,1,1,1,1,1,1,1,1,1,1,1,0,0,186,0,0,0,189,0,0,0
0,0,204,0,0,165,0,193,1,0,0,1,0,189,0,0,191,193,1,189,183,183,183,183,0,183,183,183,183,183,0,0,0,183,198,1,0,0,186,0,0,0,189,0,0,0
0,0,0,0,0,141,0,193,0,0,0,0,183,0,0,193,1,1,186,189,0,0,0,0,0,0,0,0,0,0,0,0,0,0,193,186,1,1,1,0,0,0,189,0,0,0
0,0,0,204,0,0,141,0,183,0,183,0,0,0,0,0,0,183,183,0,0,0,0,0,0,0,0,0,0,0,141,0,0,0,0,183,183,183,183,183,183,183,0,204,0,0
0,0,204,204,204,0,0,0,0,0,0,0,0,0,0,0,0,0,0,0,0,7,0,7,0,0,204,0,0,141,0,0,0,0,204,0,0,0,0,0,0,0,204,204,204,0
0,0,0,204,0,0,0,0,0,0,0,0,0,0,0,0,0,0,0,0,0,0,0,0,0,204,204,204,0,165,0,0,0,204,204,204,0,0,0,0,0,0,0,204,0,0
0,0,0,0,0,0,0,0,0,0,0,0,0,0,0,0,0,0,0,0,0,0,0,0,0,0,204,0,0,0,210,210,0,0,204,0,0,0,0,0,0,0,0,0,0,0
0,0,0,0,0,0,0,0,0,0,0,0,0,0,0,0,0,0,0,0,0,0,0,0,0,0,0,0,0,0,0,0,0,0,0,0,0,0,0,0,0,0,0,0,0,0
0,0,0,0,0,0,0,0,0,0,0,0,0,0,0,0,0,0,0,0,0,0,0,0,0,0,0,0,0,0,0,0,0,0,0,0,0,0,0,0,0,0,0,0,0,0
:endlayer
layer: 20
0,0,0,0,0,0,0,0,0,0,0,0,0,0,0,0,0,0,0,0,0,0,0,0,0,0,0,0,0,0,0,0,0,0,0,0,0,0,0,0,0,0,0,0,0,0
0,0,0,0,0,0,0,0,0,204,0,0,0,0,0,0,0,0,0,0,204,0,0,0,0,0,0,0,0,0,0,0,0,0,0,0,0,0,0,0,0,0,204,204,204,0
0,0,0,0,0,0,0,0,204,204,204,0,0,0,0,0,0,0,0,204,204,204,0,0,0,0,0,0,0,0,0,0,0,204,204,0,0,0,0,0,0,0,204,165,204,0
0,0,0,0,0,0,0,0,0,204,0,0,0,0,0,0,0,0,0,0,204,0,0,0,0,0,0,0,0,0,0,0,0,204,165,204,0,0,0,0,0,0,204,204,204,0
0,0,0,0,0,191,0,0,0,0,0,0,0,0,0,191,191,191,191,0,0,0,0,0,0,0,0,0,0,0,0,0,0,204,204,204,191,191,191,191,191,191,0,0,0,0
0,0,0,0,193,1,0,1,1,1,1,1,186,1,1,1,1,1,186,189,0,0,0,0,0,0,0,0,0,0,0,0,0,0,193,0,0,0,0,0,1,186,189,0,0,0
204,204,204,0,193,1,180,183,183,183,183,208,186,186,186,0,0,0,1,189,0,0,0,191,191,0,191,0,191,191,191,191,191,191,185,0,0,0,0,0,0,1,189,0,0,0
204,204,204,204,193,183,0,0,0,0,0,208,186,186,186,0,0,193,1,0,0,0,0,0,1,189,1,1,1,1,1,1,1,1,1,189,0,0,193,0,0,1,189,0,0,0
204,204,204,204,193,0,0,0,0,0,0,208,186,186,186,186,0,193,186,180,0,180,183,183,198,0,186,186,186,0,0,0,0,0,186,0,0,0,0,0,0,1,189,0,0,0
204,204,204,204,193,0,0,0,0,0,0,193,186,186,201,189,0,0,183,0,0,0,0,193,0,0,0,0,0,0,0,0,0,0,0,0,0,0,193,0,0,1,189,0,0,0
204,204,204,0,0,0,0,0,0,0,208,208,186,186,201,191,0,0,0,0,191,0,0,193,0,0,0,0,0,0,0,0,0,0,0,0,0,0,0,0,0,1,189,0,0,0
204,0,0,0,0,0,191,0,0,0,0,208,186,186,1,1,0,1,186,0,0,0,0,193,0,186,186,186,186,0,0,0,0,0,186,186,1,0,1,1,1,186,189,0,0,0
204,0,165,0,0,1,208,208,208,0,208,208,183,208,1,186,0,186,186,0,0,0,0,0,0,0,186,186,0,0,0,0,0,0,0,186,0,0,0,1,183,183,0,0,0,0
204,0,141,0,193,1,208,208,208,208,0,0,208,208,201,0,0,0,0,0,0,0,0,0,0,0,0,0,0,0,0,0,0,0,0,0,0,0,0,1,189,0,0,0,0,0
0,204,141,204,193,1,208,208,208,208,208,208,208,208,201,0,0,0,0,0,0,0,0,0,0,0,0,0,0,0,0,0,0,0,0,0,0,0,0,1,189,0,0,0,0,0
0,204,204,204,0,1,208,208,208,208,208,208,208,208,201,0,0,0,0,195,0,0,0,0,0,0,0,0,0,0,0,0,0,0,0,0,0,0,0,1,189,0,0,0,0,0
0,0,204,0,0,1,208,208,208,208,208,208,208,208,1,186,0,0,186,189,0,0,0,0,0,0,0,0,0,0,0,0,0,0,0,0,0,0,0,1,189,0,0,0,0,0
0,0,0,0,193,1,208,208,208,208,208,208,208,208,1,186,0,0,186,189,0,0,0,0,0,0,186,0,0,0,0,0,0,0,193,0,0,0,0,1,189,0,0,0,0,0
0,0,0,0,193,1,1,208,208,208,208,208,208,1,1,0,0,0,0,0,0,0,0,0,0,0,0,0,0,0,0,0,0,0,193,186,0,0,186,1,189,0,0,0,0,0
0,0,0,0,193,1,1,1,186,186,186,186,1,1,1,180,0,0,0,0,0,0,0,0,0,0,0,0,0,0,0,0,0,0,193,186,0,0,186,1,189,0,204,0,0,0
0,0,0,0,0,183,183,183,186,186,186,186,0,193,1,189,0,0,0,0,0,0,0,0,0,193,0,0,0,0,0,0,0,0,193,186,0,0,186,1,189,204,204,204,0,0
0,0,0,0,0,0,0,0,208,208,208,208,0,0,183,0,0,0,0,0,208,0,208,183,183,0,0,0,0,0,0,0,0,0,193,186,0,0,186,1,0,0,204,0,0,0
0,0,0,0,0,0,0,0,208,208,208,208,0,193,0,0,0,0,0,0,0,0,0,0,0,193,0,0,0,0,0,0,0,0,0,0,0,0,0,1,0,0,0,0,0,0
0,0,0,204,0,0,0,193,186,200,200,200,0,0,0,0,0,0,0,0,208,0,208,0,0,193,0,0,0,0,0,0,0,0,0,0,0,0,0,1,0,0,0,0,0,0
0,0,204,204,204,0,0,193,186,199,199,199,0,0,0,0,0,0,0,0,0,0,0,0,0,193,0,0,0,0,0,189,0,0,0,0,0,0,0,1,0,0,0,0,0,0
0,0,0,204,0,0,0,193,186,0,0,0,0,0,0,0,0,0,0,0,0,0,0,0,0,193,0,0,0,0,0,0,0,0,0,0,0,0,0,1,0,0,0,0,0,0
0,0,0,0,0,0,0,193,186,0,0,0,0,0,0,0,0,0,0,0,0,0,0,0,0,0,0,0,0,0,0,0,0,0,0,0,0,0,0,1,0,0,0,0,0,0
0,0,0,0,0,0,0,0,199,0,0,0,191,191,1,0,0,0,0,0,0,0,0,0,0,0,0,0,0,0,0,0,0,0,0,186,0,0,0,1,195,191,0,0,0,0
0,0,0,0,0,0,0,0,199,0,0,193,186,1,1,1,0,1,186,0,0,0,0,0,0,0,186,186,186,0,0,0,0,0,186,186,1,0,1,1,1,186,189,0,0,0
0,0,0,0,0,0,0,0,0,0,0,0,1,0,0,0,0,0,0,0,0,0,0,0,0,0,0,0,0,0,0,0,0,0,0,0,0,0,0,0,0,1,189,0,0,0
0,204,204,204,0,0,0,193,1,0,0,1,1,189,0,0,0,0,0,0,0,0,0,0,0,0,0,0,0,0,0,0,0,0,0,0,0,0,0,0,0,1,189,0,0,0
204,204,204,204,204,0,0,0,1,0,209,1,1,0,0,0,0,0,0,0,0,0,0,0,0,186,186,186,186,0,0,0,0,0,186,186,0,0,186,0,0,1,189,0,0,0
204,204,204,210,204,0,0,0,1,0,0,1,1,0,0,0,0,0,0,1,0,1,1,1,1,1,1,1,1,1,1,1,1,1,1,1,186,186,201,0,0,0,189,0,0,0
204,204,204,204,210,165,0,193,1,0,0,1,1,189,0,0,0,0,0,189,183,183,183,183,0,183,183,183,183,183,204,0,0,183,198,1,186,186,201,0,0,0,189,0,0,0
0,204,204,204,0,0,210,193,1,0,0,0,183,0,0,0,0,0,186,189,0,0,0,0,0,0,0,0,0,204,141,204,0,0,193,186,1,1,1,1,0,0,189,0,0,0
0,0,0,0,0,0,204,0,183,0,183,0,0,0,0,0,0,183,183,0,0,0,0,0,0,204,204,204,0,0,204,0,0,0,0,183,183,183,183,183,183,183,0,0,0,0
0,0,0,0,0,204,141,204,0,0,0,0,0,0,0,0,0,0,0,0,0,7,0,0,204,204,204,204,204,0,0,0,0,0,0,0,0,0,0,0,0,0,0,0,0,0
0,0,0,0,0,0,204,0,0,0,0,0,0,0,0,0,0,0,0,0,0,0,0,0,204,204,204,204,204,165,0,0,0,0,0,0,0,0,0,0,0,0,0,0,0,0
0,0,0,0,0,0,0,0,0,0,0,0,0,0,0,0,0,0,0,0,0,0,0,0,204,204,204,210,210,0,0,0,204,0,0,0,0,0,0,0,0,0,0,0,0,0
0,0,0,0,0,0,0,0,0,0,0,0,0,0,0,0,0,0,0,0,0,0,0,0,0,204,204,204,0,0,0,204,210,204,0,0,0,0,0,0,0,0,0,0,0,0
0,0,0,0,0,0,0,0,0,0,0,0,0,0,0,0,0,0,0,0,0,0,0,0,0,0,0,0,0,0,0,0,204,0,0,0,0,0,0,0,0,0,0,0,0,0
:endlayer
layer: 21
0,0,0,0,0,0,0,0,0,0,0,0,0,0,0,0,0,0,0,0,0,0,0,0,0,0,0,0,0,0,0,0,0,0,0,0,0,0,0,0,0,0,0,0,0,0
0,0,0,0,0,0,0,0,0,0,0,0,0,0,0,0,0,0,0,0,0,0,0,0,0,0,0,0,0,0,0,0,0,0,0,0,0,0,0,0,0,0,0,204,0,0
0,0,0,0,0,0,0,0,0,0,0,0,0,0,0,0,0,0,0,0,0,0,0,0,0,0,0,0,0,0,0,0,0,0,204,0,0,0,0,0,0,0,204,204,204,0
0,0,0,0,0,0,0,0,0,0,0,0,0,0,0,0,0,0,0,0,0,0,0,0,0,0,0,0,0,0,0,0,0,204,204,204,0,0,0,0,0,0,0,204,0,0
0,0,0,0,0,191,0,0,0,0,0,0,0,0,0,191,191,191,191,0,0,0,0,0,0,0,0,0,0,0,0,0,0,0,204,191,191,191,191,191,191,191,0,0,0,0
0,0,0,0,193,1,0,0,0,0,0,1,186,1,1,1,1,1,186,189,0,0,0,0,0,0,0,0,0,0,0,0,0,0,193,0,0,0,0,1,1,186,189,0,0,0
204,204,204,0,193,183,180,183,183,183,183,183,207,186,186,186,0,0,1,189,0,0,0,191,191,0,191,0,191,191,191,191,191,191,185,0,0,0,0,0,0,1,189,0,0,0
204,204,204,204,193,183,0,0,0,0,0,0,207,186,186,186,0,193,1,0,0,0,0,0,1,1,1,1,1,1,1,0,1,1,1,189,0,0,193,0,0,1,189,0,0,0
204,204,204,204,193,0,0,0,0,0,0,198,186,186,186,186,0,193,186,180,0,180,183,183,198,186,186,186,186,0,0,0,0,0,186,0,0,0,0,0,0,1,189,0,0,0
204,204,204,204,193,0,0,0,0,0,0,193,0,0,0,189,0,0,183,0,0,0,0,193,0,0,0,0,0,0,0,0,0,0,0,186,186,186,193,0,0,1,189,0,0,0
204,204,204,0,0,0,0,0,0,0,0,193,191,0,0,191,0,0,0,0,191,0,0,193,0,0,0,0,0,0,0,0,0,0,0,186,186,186,0,0,0,1,189,0,0,0
204,0,0,0,0,0,0,0,0,0,0,193,186,1,1,1,1,1,186,0,0,0,0,193,0,186,186,186,186,0,0,0,0,0,186,186,1,1,1,1,1,186,189,0,0,0
204,204,165,204,0,1,0,0,0,0,0,0,183,0,1,186,186,186,186,0,0,0,0,0,0,0,186,186,0,0,0,0,0,0,0,186,0,0,0,1,183,183,0,0,0,0
204,204,204,204,193,1,0,0,0,0,0,0,0,0,0,0,0,0,0,0,0,0,0,0,0,0,0,0,0,0,0,0,0,0,0,0,0,0,0,1,189,0,0,0,0,0
204,204,204,204,193,1,0,0,0,0,0,0,0,0,0,0,0,0,0,0,0,0,0,0,0,0,0,0,0,0,0,0,0,0,0,0,0,0,0,1,189,0,0,0,0,0
204,204,204,204,204,1,0,0,0,0,0,0,0,0,0,0,0,0,0,195,0,0,0,0,0,0,0,0,0,0,0,0,0,0,0,0,0,0,0,0,189,0,0,0,0,0
204,204,204,204,204,1,0,0,0,92,92,0,0,0,1,186,0,0,186,189,0,0,0,0,0,0,0,0,0,0,0,0,0,0,0,0,0,0,0,1,189,0,0,0,0,0
0,204,204,204,193,1,1,1,1,0,0,1,1,1,1,186,0,0,186,189,0,0,0,0,0,0,186,0,0,0,0,0,0,0,193,0,0,0,0,1,189,0,0,0,0,0
0,0,0,0,193,1,212,216,215,186,186,214,213,212,1,0,0,0,0,0,0,0,0,0,0,0,0,0,0,0,0,0,0,0,193,186,0,0,186,1,189,0,0,0,0,0
0,0,0,0,193,1,1,1,1,0,0,1,1,1,1,180,0,0,0,0,0,0,0,0,0,0,0,0,0,0,0,0,0,0,193,186,0,0,186,1,189,0,0,0,0,0
0,0,0,0,0,183,183,183,183,41,41,183,0,193,1,189,0,0,0,0,0,0,0,0,0,193,0,0,0,0,0,0,0,0,193,186,0,0,186,1,189,0,0,0,0,0
0,0,0,0,0,0,0,0,0,0,0,0,0,0,183,0,0,0,0,0,208,0,208,183,183,0,0,0,0,0,0,0,0,0,193,186,0,0,186,1,0,0,0,0,0,0
0,0,0,0,0,0,0,0,0,0,0,0,0,193,0,0,0,0,0,0,0,0,0,0,0,193,0,0,0,0,0,0,0,0,0,0,0,0,0,1,0,0,0,0,0,0
0,0,0,0,0,0,0,193,186,0,0,0,0,0,0,0,0,0,0,0,208,0,208,0,0,193,0,0,0,0,0,0,0,0,0,0,0,0,0,1,0,0,0,0,0,0
0,0,0,0,0,0,0,193,186,0,0,0,0,0,0,0,0,0,0,0,0,0,0,0,0,193,0,0,0,0,0,189,0,0,0,0,0,0,0,0,0,0,0,0,0,0
0,0,0,0,0,0,0,0,199,0,0,0,0,0,0,0,0,0,0,0,0,0,0,0,0,193,0,0,0,0,0,0,0,0,0,0,0,0,0,1,0,0,0,0,0,0
0,0,0,0,0,0,0,0,199,0,0,0,0,0,1,0,0,0,0,0,0,0,0,0,0,0,0,0,0,0,0,0,0,0,0,0,0,0,0,1,0,0,0,0,0,0
0,0,0,0,0,0,0,0,0,0,0,0,191,191,1,186,186,186,0,0,0,0,0,0,0,0,0,186,0,0,0,0,0,0,0,186,0,0,0,1,195,191,0,0,0,0
0,0,0,0,0,0,0,0,0,0,0,193,186,1,1,1,1,1,186,0,0,0,0,0,0,186,186,186,186,0,0,0,0,0,186,186,1,1,1,1,1,186,189,0,0,0
0,0,0,0,0,0,0,0,0,0,0,0,1,0,0,186,186,186,0,0,0,0,0,0,0,0,0,0,0,0,0,0,0,0,0,186,186,186,186,0,0,1,189,0,0,0
0,204,204,204,0,0,0,193,1,1,1,1,1,189,0,186,186,186,0,0,0,0,0,0,0,0,0,0,0,0,0,0,0,0,0,186,186,186,186,0,0,1,189,0,0,0
204,204,204,204,204,0,0,0,1,0,209,1,1,0,0,0,0,0,0,0,0,0,0,0,0,186,186,186,186,0,0,0,0,0,186,1,194,194,186,0,0,1,189,0,0,0
204,204,210,204,204,0,0,0,1,0,0,1,1,0,0,0,0,0,0,1,1,1,0,1,1,1,1,1,1,1,1,204,1,1,1,1,0,0,0,0,0,0,189,0,0,0
204,204,204,204,204,165,0,193,1,0,0,1,1,189,0,0,0,0,0,189,183,183,183,183,0,183,183,183,204,183,183,204,204,183,198,1,0,0,0,0,0,0,189,0,0,0
0,204,204,204,0,204,204,193,1,0,0,0,186,0,0,0,0,0,0,189,0,0,0,0,0,0,0,0,204,204,204,204,204,0,193,186,1,1,1,1,0,0,189,0,0,0
0,0,0,0,204,204,204,210,183,0,183,0,0,0,0,0,0,183,183,0,0,0,0,0,0,204,204,204,204,204,204,204,204,0,0,183,183,183,183,183,183,183,0,0,0,0
0,0,0,0,204,204,204,204,204,0,0,0,0,0,0,0,0,0,0,0,0,0,0,0,204,204,204,204,204,204,204,204,0,0,0,0,0,0,0,0,0,0,0,0,0,0
0,0,0,0,204,204,204,204,204,0,0,0,0,0,0,0,0,0,0,0,0,0,0,0,204,204,204,210,210,165,0,204,204,204,0,0,0,0,0,0,0,0,0,0,0,0
