# Ancient Warfare Structure Template File
# Auto-generated structure template file. created on: 8/19/2019 at: 10:23:14
# Lines beginning with # denote comments

header:
version=2.9
name=OrcRuinAndWarrenLargeGeneric
mods=
size=52,39,51
offset=24,14,50
:endheader

#### VALIDATION ####
validation:
type=ground
survival=false
worldGenEnabled=true
unique=false
preserveBlocks=false
selectionWeight=60
clusterValue=50
minDuplicateDistance=1000
dimensionWhiteList=true
dimensionList=0
biomeWhiteList=true
biomeList=biomesoplenty:shrubland,biomesoplenty:woodland,biomesoplenty:dead_swamp,biomesoplenty:dead_forest,traverse:woodlands,minecraft:forest,minecraft:extreme_hills,minecraft:redwood_taiga,traverse:badlands,biomesoplenty:moor,traverse:rocky_plateau
leveling=5
fill=5
border=5
blockSwap=true
:endvalidation

#### LAYERS ####
layer: 0
0,1,1,1,1,1,1,1,1,1,3,2,2,1,1,1,1,1,1,2,2,2,0,0,0,0,0,0,1,1,1,1,1,1,1,1,1,1,1,1,1,1,1,1,1,1,1,1,1,1,1,1
0,1,1,1,1,1,1,2,2,2,1,2,2,3,1,1,1,1,1,1,2,2,2,1,1,1,1,1,1,1,1,1,1,1,1,1,1,1,1,1,1,1,1,1,1,1,1,1,1,1,1,1
0,0,1,1,1,1,1,2,2,2,2,3,2,2,1,1,1,1,1,1,2,2,2,2,1,1,1,1,1,1,1,1,1,1,1,1,1,1,1,1,1,1,1,1,1,1,1,1,1,1,1,1
0,0,1,1,1,1,1,2,2,2,2,1,2,2,1,1,1,1,1,1,1,2,2,2,1,1,1,1,1,1,1,1,1,1,1,1,1,1,1,1,1,1,1,1,1,1,1,1,1,1,1,1
0,0,1,1,1,1,1,1,2,2,2,2,2,2,1,1,1,1,1,1,1,1,1,1,1,1,1,1,1,1,1,1,1,1,1,2,2,2,1,1,1,1,1,1,1,1,1,1,1,1,1,1
1,0,1,1,1,1,1,3,2,2,2,2,1,1,1,1,1,1,1,1,1,1,1,1,1,1,1,1,1,1,1,1,1,1,1,2,2,2,2,1,1,1,1,1,1,1,1,1,1,1,1,1
1,1,1,1,1,1,1,3,2,2,2,2,1,1,1,1,1,1,1,1,1,1,1,1,2,1,1,1,1,1,1,1,1,1,1,2,2,2,2,1,1,1,1,1,1,1,1,1,1,1,1,2
1,1,1,1,1,1,2,2,2,2,2,2,1,1,1,1,1,1,1,1,1,1,1,1,1,1,1,1,1,1,1,1,1,1,1,1,2,2,2,2,1,1,1,1,1,1,1,1,1,1,2,2
1,1,1,1,1,2,2,2,2,2,2,2,1,1,1,1,1,1,1,1,1,1,1,1,1,1,1,1,1,1,1,1,1,1,1,1,2,2,2,2,1,1,1,1,1,1,1,1,1,1,2,2
1,1,1,1,2,2,2,2,2,2,2,1,1,1,1,1,1,1,1,1,1,1,1,1,1,1,1,1,1,1,1,1,1,1,1,1,2,2,2,2,1,1,1,1,1,1,1,1,1,1,2,2
1,1,1,1,2,2,2,2,2,2,1,1,1,1,1,1,1,1,1,1,1,1,1,1,1,1,1,1,1,1,1,1,1,1,1,1,1,2,2,2,1,1,1,1,1,1,1,1,1,1,2,2
1,1,1,2,2,2,2,2,1,1,1,1,1,1,1,1,1,1,1,1,1,1,1,1,1,1,1,1,1,1,1,1,1,1,1,1,1,1,1,1,1,1,1,1,1,1,1,1,1,1,2,2
1,1,1,1,2,2,1,1,1,1,1,1,4,4,1,1,1,1,1,1,1,1,1,1,1,1,1,1,1,1,1,1,1,1,1,1,1,1,1,1,1,1,1,1,3,3,3,1,1,1,2,2
1,1,1,1,1,1,1,1,1,1,1,1,4,4,1,1,1,1,1,1,1,1,1,1,1,1,1,1,1,2,2,2,1,1,1,1,1,1,1,1,1,1,1,1,3,3,3,1,1,1,2,2
1,1,1,1,1,1,1,1,1,1,1,1,1,1,1,1,1,1,1,1,1,1,1,1,1,1,1,1,2,2,2,2,1,1,1,1,1,1,1,1,1,1,1,1,1,3,3,3,1,1,1,1
1,1,1,1,1,1,1,1,1,1,1,1,1,1,1,1,1,1,1,1,1,1,1,1,1,1,1,1,2,2,2,1,1,1,1,1,1,1,1,1,1,1,1,1,1,3,3,1,1,1,1,1
1,1,1,1,1,1,1,1,1,1,1,1,1,1,1,1,1,1,1,1,1,1,1,1,1,1,1,1,1,1,1,1,1,1,1,1,1,1,1,1,1,1,1,1,1,1,1,1,1,1,1,1
1,1,1,1,1,1,1,1,1,1,1,1,1,1,1,1,1,1,1,1,1,1,1,1,1,1,1,1,1,1,1,1,1,1,1,1,1,1,1,1,1,1,1,1,1,1,1,1,1,1,1,1
1,1,1,1,1,1,1,1,1,1,1,1,1,1,1,1,1,1,1,1,1,1,1,1,1,1,1,1,1,1,1,1,1,1,1,1,1,1,1,1,1,1,1,1,1,1,1,1,1,1,1,1
1,1,1,1,0,0,0,1,1,1,1,1,1,1,1,1,1,1,1,1,1,1,1,1,1,1,1,1,1,1,1,1,1,1,1,1,1,1,1,1,1,1,1,1,1,1,1,1,1,1,1,1
1,1,1,0,0,0,0,1,1,1,1,1,1,1,1,1,1,1,1,1,1,1,1,1,1,1,1,1,1,1,1,1,1,1,1,1,1,1,1,1,1,1,1,1,1,1,1,1,1,1,1,1
1,1,1,3,3,1,3,3,1,1,1,1,1,1,1,1,1,1,1,1,1,1,1,1,1,1,1,1,1,1,1,1,1,1,1,1,1,1,1,1,1,1,0,0,0,0,0,1,1,1,1,1
1,1,1,3,3,1,1,3,3,1,1,1,1,1,1,1,1,1,1,1,1,1,1,1,1,1,1,1,1,1,1,1,1,1,1,1,1,1,1,1,1,0,0,0,0,0,0,0,0,1,1,1
1,1,1,0,1,1,1,3,3,1,1,1,1,1,1,1,1,1,1,1,1,1,1,1,1,1,1,1,1,1,1,1,1,1,1,1,1,1,1,1,1,1,0,0,0,0,0,0,0,0,1,1
1,1,0,0,0,1,1,1,1,1,1,1,1,1,1,1,1,1,1,1,1,1,1,1,1,1,1,1,1,1,1,1,1,1,1,1,1,1,1,1,1,1,1,1,0,0,0,0,0,0,1,1
0,0,0,0,0,1,1,1,1,1,1,1,1,1,1,1,1,1,1,1,1,1,1,1,1,1,1,1,1,1,1,1,1,1,1,1,1,1,1,1,1,1,1,1,1,1,0,0,0,1,1,1
0,0,0,0,0,1,1,1,1,1,1,1,1,1,1,1,1,1,1,1,1,1,1,1,1,1,1,1,1,1,1,1,1,1,1,1,1,1,1,1,1,1,1,1,1,1,1,1,1,1,1,2
0,0,0,1,1,1,1,1,1,1,1,1,1,1,1,1,1,1,1,1,1,1,1,1,1,1,1,1,1,1,1,1,1,1,1,1,1,1,1,1,1,1,1,0,0,0,1,1,1,1,2,2
0,0,1,1,1,1,1,1,1,1,1,1,1,1,1,1,1,1,1,1,1,1,1,1,1,1,1,1,1,1,1,1,1,1,1,1,1,1,1,1,1,1,1,0,0,0,0,1,2,2,2,2
1,1,1,1,1,1,1,1,1,1,1,1,1,1,1,1,1,1,1,1,1,3,3,1,1,1,1,1,1,1,1,1,1,1,1,1,1,1,1,1,1,1,1,1,0,0,0,0,2,1,1,1
1,1,1,1,1,1,1,1,1,1,1,1,1,1,1,1,1,1,1,1,1,3,3,3,1,1,1,1,1,1,1,1,1,1,1,1,1,1,1,1,1,1,1,1,1,1,1,1,1,1,1,1
1,1,1,1,1,1,1,1,1,1,1,2,2,2,2,1,1,1,1,1,1,1,3,3,3,1,1,1,1,1,1,1,1,1,1,1,1,1,1,1,1,1,1,1,1,1,1,1,1,1,1,1
1,1,1,1,1,1,1,1,1,1,1,1,2,2,2,2,1,1,1,1,1,1,1,3,3,1,1,1,1,1,1,1,1,1,1,1,1,1,1,1,1,1,1,1,1,1,1,1,1,1,1,1
1,1,1,1,1,1,1,1,1,1,1,2,2,2,2,2,1,1,1,1,1,1,1,1,1,1,1,1,1,1,1,1,0,0,1,1,1,1,1,1,1,2,2,2,2,2,2,2,1,1,1,1
1,1,1,1,1,1,1,1,1,1,1,2,2,2,2,2,2,1,1,1,1,1,1,1,1,1,1,1,1,1,1,1,0,0,0,1,1,1,1,1,2,2,2,2,2,2,2,2,2,2,1,1
1,1,1,1,1,1,1,1,1,1,1,1,2,2,2,2,2,1,1,1,1,1,1,1,1,1,1,1,1,1,1,1,0,0,0,1,1,1,1,1,2,2,2,2,2,2,2,2,2,2,1,1
1,1,1,1,1,1,1,1,1,1,0,0,0,0,2,2,2,1,1,1,1,1,1,1,1,1,1,1,1,1,1,1,0,0,0,1,1,1,1,1,1,1,2,2,2,2,2,2,2,1,1,1
1,1,1,1,1,1,1,1,0,0,0,0,0,0,0,0,2,0,1,1,1,1,1,1,1,1,1,1,1,1,1,1,0,0,0,1,1,1,1,1,1,1,1,1,1,1,1,1,2,1,1,1
1,1,1,1,1,1,1,1,0,0,0,0,0,0,0,0,0,0,1,1,1,1,1,1,1,1,1,1,1,1,1,1,0,0,0,1,1,1,1,1,1,1,1,1,1,1,1,1,1,1,1,1
1,1,3,3,1,1,1,1,1,0,0,0,0,0,0,0,1,1,1,1,1,1,1,1,1,1,1,1,1,1,1,1,0,0,0,1,1,1,1,1,1,1,1,1,1,1,1,1,1,1,1,1
1,3,3,1,1,1,1,1,1,1,1,1,1,1,1,1,1,1,1,1,1,1,1,1,1,1,1,1,1,1,1,1,0,0,1,1,1,1,1,1,1,1,1,1,1,1,1,1,1,2,2,1
1,3,3,1,1,1,1,1,1,1,1,1,1,1,1,1,1,1,1,1,1,1,1,1,1,1,1,1,1,1,1,1,1,1,1,1,1,1,1,1,1,1,1,1,1,1,1,1,2,2,2,1
1,1,1,1,1,1,1,1,1,1,1,1,1,1,1,1,1,1,1,1,1,1,1,1,1,1,1,1,1,1,1,1,1,1,1,1,1,1,1,1,1,1,1,1,1,1,2,2,2,2,2,1
1,1,1,1,1,1,1,1,1,1,1,1,1,1,1,1,1,1,1,1,1,1,1,1,1,1,1,1,1,1,1,1,1,1,1,1,1,1,1,1,1,1,1,1,1,2,2,2,2,2,1,1
1,1,1,1,1,1,1,1,1,1,1,1,1,1,1,1,1,1,1,1,1,1,1,1,1,1,1,1,1,1,1,1,1,1,1,1,1,1,1,1,1,1,1,1,1,2,2,2,2,1,1,1
1,1,1,1,1,1,1,1,1,1,1,1,1,1,1,1,1,1,1,1,1,1,1,1,1,1,1,1,1,1,1,1,1,1,1,1,1,1,1,1,1,1,1,1,1,2,2,1,1,1,1,1
1,1,1,1,1,1,1,1,1,1,1,1,1,1,1,1,1,1,1,1,1,1,1,1,1,1,2,2,2,2,2,2,2,1,1,1,1,1,1,1,1,1,1,1,1,1,1,1,1,1,1,1
1,1,1,1,1,1,1,1,1,1,1,1,1,1,1,1,1,1,1,1,1,1,1,1,1,2,2,2,2,2,2,2,2,1,1,1,1,1,1,1,1,1,1,1,1,1,1,1,1,1,1,1
1,1,1,1,1,1,1,1,1,1,1,1,1,1,1,1,1,1,1,1,1,1,1,1,2,2,2,2,2,2,2,2,1,1,1,1,1,1,1,1,1,1,1,1,1,1,1,1,1,1,1,1
1,1,1,1,1,1,1,1,1,1,1,1,2,2,1,1,1,1,1,1,1,1,1,1,2,2,2,2,2,1,1,1,1,1,1,1,1,1,1,1,1,1,1,1,1,1,1,1,1,1,1,1
1,1,1,1,1,1,1,1,1,1,1,1,2,2,1,1,1,1,1,1,1,1,1,1,1,1,1,1,1,1,1,1,1,1,1,1,1,1,1,1,1,1,1,1,1,1,1,1,1,1,1,1
:endlayer
layer: 1
0,5,1,1,1,1,1,1,2,2,2,2,2,2,1,1,1,1,1,1,1,1,1,0,0,0,0,1,1,1,1,1,1,1,1,1,1,1,1,1,1,1,1,1,1,1,1,1,1,1,1,1
0,5,1,1,1,1,1,2,2,2,2,2,2,2,3,3,1,1,1,1,1,1,1,1,1,1,1,1,1,1,1,1,1,1,1,1,1,1,1,1,1,1,1,1,1,1,1,1,1,1,1,1
0,0,5,1,1,1,1,2,2,2,2,2,2,2,2,1,1,1,1,1,1,1,1,1,1,1,1,1,1,1,1,1,1,1,1,1,1,1,1,1,1,1,1,1,1,1,1,1,1,1,1,1
0,0,5,1,1,1,2,2,2,2,1,2,2,2,2,1,1,1,1,1,1,1,1,1,1,1,1,1,1,1,1,1,1,1,1,1,1,1,1,1,1,1,1,1,1,1,1,1,1,1,1,1
0,0,5,1,1,1,2,2,2,1,1,2,2,2,2,1,1,1,1,1,1,1,1,1,2,2,2,1,1,1,1,1,1,1,1,2,2,2,1,1,1,1,1,1,1,1,1,1,1,1,1,1
5,0,5,1,1,1,1,3,3,1,1,1,2,2,2,1,1,1,1,1,1,1,1,2,2,2,2,1,1,1,1,1,1,1,1,2,2,2,2,1,1,1,1,1,1,1,1,1,1,1,1,1
5,5,1,1,1,1,1,3,2,2,2,1,2,2,2,1,1,1,1,1,1,2,2,2,2,2,2,1,1,1,1,1,1,1,1,2,2,2,2,1,1,1,1,1,1,1,1,1,1,1,1,1
1,1,1,1,1,1,1,2,2,2,2,2,1,2,1,1,1,1,1,1,1,2,2,2,2,2,1,1,1,1,1,1,1,1,1,1,2,2,2,2,1,1,1,1,1,1,1,1,1,1,1,1
1,1,1,1,1,2,2,2,2,2,2,1,1,1,1,1,1,1,1,1,1,2,2,1,1,1,1,1,1,1,1,1,1,1,1,1,2,2,2,2,2,1,1,1,1,1,1,1,1,1,1,2
1,1,1,1,1,2,2,2,2,2,1,1,1,1,1,1,1,1,1,1,1,1,1,1,1,1,1,1,1,1,1,1,1,1,1,1,2,2,2,2,2,1,1,1,1,1,1,1,1,1,1,2
1,1,1,1,2,2,2,2,2,2,1,1,1,1,1,1,1,1,1,1,1,1,1,1,1,1,1,1,1,1,1,1,1,1,1,1,1,2,2,2,2,1,1,1,1,1,1,1,1,1,1,2
1,1,1,2,2,2,2,2,1,1,1,1,1,1,1,1,1,1,1,1,1,1,1,1,1,1,1,1,1,1,1,1,1,1,1,1,1,1,1,2,2,1,1,1,1,1,1,1,1,1,1,1
1,1,1,1,2,2,1,1,1,1,1,1,4,4,1,1,1,1,1,1,1,1,1,1,1,1,1,1,1,1,1,1,1,1,1,1,1,1,1,2,1,1,1,1,3,3,1,1,1,1,1,1
1,1,1,1,1,1,1,1,1,1,1,1,4,4,1,1,1,1,1,1,1,1,1,1,1,3,1,1,1,1,1,1,1,1,1,1,1,1,2,2,2,1,1,1,1,3,3,1,1,1,1,1
1,1,1,1,1,1,1,1,1,1,1,1,1,1,1,1,1,5,5,5,5,1,1,3,3,1,1,1,1,1,1,1,1,1,1,1,1,1,2,2,2,2,1,1,1,3,3,1,1,1,1,1
1,1,1,1,1,1,1,1,1,1,1,1,1,1,1,1,1,5,5,5,5,5,1,1,1,1,1,1,1,1,1,1,1,1,1,1,1,1,2,2,2,2,1,1,1,1,1,1,1,1,1,1
1,1,1,1,1,1,1,1,1,1,1,1,1,1,1,1,1,1,5,5,5,5,5,1,1,1,1,1,1,1,1,1,1,1,1,1,1,1,1,2,2,2,1,1,1,1,1,1,1,1,1,1
1,1,1,1,1,1,1,1,1,1,1,1,1,1,1,1,1,1,1,5,5,5,5,1,1,1,1,1,1,1,1,1,1,1,1,1,1,1,1,1,2,2,1,1,1,1,1,1,1,1,1,1
1,1,1,1,1,1,1,1,1,1,1,1,1,1,1,1,1,1,1,1,1,1,1,1,1,1,1,1,1,1,1,1,1,1,1,1,1,1,1,1,1,1,1,1,1,1,1,1,1,1,1,1
1,5,1,1,1,1,1,1,1,1,1,1,1,1,1,1,1,1,1,1,1,1,1,1,1,1,1,1,1,1,1,1,1,1,1,1,1,1,1,1,1,1,1,1,1,1,1,1,1,1,1,1
1,5,5,1,1,1,1,1,1,1,1,1,1,1,1,1,1,1,1,1,5,1,1,1,1,1,1,1,1,1,1,1,1,1,1,1,1,1,1,1,1,5,5,5,1,1,1,1,1,1,1,1
1,1,3,3,3,1,3,3,1,1,1,1,1,1,1,1,1,5,5,5,1,1,1,1,1,1,1,1,1,1,1,1,1,1,1,1,1,1,1,1,5,5,0,0,0,0,0,1,1,1,1,1
1,1,5,3,3,1,3,3,3,1,1,1,1,1,1,1,5,5,5,5,1,1,1,1,1,1,1,1,1,1,1,1,1,1,1,1,1,1,1,1,5,0,0,0,0,0,0,0,0,1,1,1
1,1,1,1,1,1,1,3,3,3,1,1,1,1,1,1,5,5,5,5,1,1,1,1,1,1,1,1,1,1,1,1,1,1,1,1,1,1,1,1,1,5,0,0,0,0,0,0,0,0,1,1
1,1,1,0,1,1,1,3,3,3,1,1,1,1,1,5,5,5,5,1,1,1,1,1,1,1,1,1,1,1,1,1,1,1,1,1,1,1,1,1,1,1,1,5,0,0,0,0,0,0,1,1
1,1,1,0,1,1,1,1,1,1,1,1,1,1,1,5,5,1,1,1,1,1,1,1,1,1,1,1,1,1,1,1,1,1,1,1,1,1,1,1,1,1,1,1,1,5,0,0,0,1,1,1
0,0,0,1,1,1,1,1,1,1,1,1,1,1,1,1,1,1,1,1,1,1,1,1,1,1,1,1,1,1,1,1,1,1,1,1,1,1,1,1,1,1,1,1,1,1,1,1,1,1,1,1
0,0,1,1,1,1,1,1,1,1,1,1,1,1,1,1,1,1,1,1,1,1,1,1,1,1,1,1,1,1,1,1,1,1,1,1,1,1,1,1,1,1,1,1,1,1,1,1,1,1,1,1
1,1,1,1,1,1,1,1,1,1,1,1,1,1,1,1,1,1,1,1,1,1,1,1,1,1,1,1,1,1,1,1,1,1,1,1,1,1,1,1,1,1,1,1,1,1,1,1,1,1,1,1
1,1,1,1,1,1,1,1,1,1,1,1,1,1,1,1,1,1,1,1,1,3,3,1,1,1,1,1,1,1,1,1,1,1,1,1,1,1,1,1,1,1,1,1,1,1,1,1,1,1,1,1
1,1,1,1,1,1,1,1,1,1,1,1,1,1,1,1,1,1,1,1,1,3,3,3,1,1,1,1,1,1,1,1,1,1,1,1,1,1,1,1,1,1,1,1,1,1,1,1,1,1,1,1
1,1,1,1,1,1,1,1,1,1,1,1,1,1,1,1,1,1,1,1,1,1,3,3,3,1,1,1,1,1,1,1,1,1,1,1,1,1,1,1,1,1,1,1,1,1,1,1,1,1,1,1
1,1,1,1,1,1,1,1,1,1,1,1,2,2,2,1,1,1,1,1,1,1,1,3,3,1,1,1,1,1,1,1,1,1,1,1,1,1,1,1,1,1,1,1,1,1,1,1,1,1,1,1
1,1,1,1,1,1,1,1,1,1,1,1,2,2,2,2,1,1,1,1,1,1,1,1,1,1,1,1,1,1,1,0,0,0,0,1,1,1,1,1,1,1,1,2,2,2,2,2,1,1,1,1
1,1,1,1,1,1,1,1,1,1,1,1,2,2,2,2,1,1,1,1,1,1,1,1,1,1,1,1,1,1,1,0,0,0,0,1,1,1,1,1,1,2,2,2,2,2,2,2,2,1,1,1
1,1,1,1,1,1,1,1,1,1,1,1,1,2,2,2,1,1,1,1,1,1,1,1,1,1,1,1,1,1,1,1,0,0,0,1,1,1,1,1,1,1,2,2,2,2,2,2,2,2,1,1
1,1,1,1,1,1,1,1,1,1,1,1,0,0,2,2,2,1,1,1,1,1,1,1,1,1,1,1,1,1,1,4,0,0,0,1,1,1,1,1,1,1,1,2,2,2,2,2,1,1,1,1
1,1,1,1,1,1,1,1,1,1,0,0,0,0,0,0,2,1,1,1,1,1,1,1,1,1,1,1,1,1,1,1,0,0,0,1,1,1,1,1,1,1,1,1,1,1,1,1,1,1,1,1
1,1,1,1,1,1,1,1,1,1,0,0,0,0,0,0,1,1,1,1,1,1,1,1,1,1,1,1,1,1,1,1,0,0,1,1,1,1,1,1,1,1,1,1,1,1,1,1,1,1,1,1
1,1,3,3,1,1,1,1,1,1,1,1,0,0,0,1,1,1,1,1,1,1,1,1,1,1,1,1,1,1,1,1,1,1,1,1,1,1,1,1,1,1,1,1,1,1,1,1,1,1,1,1
1,3,3,1,1,1,1,1,1,1,1,1,1,1,1,1,1,1,1,1,1,1,1,1,1,1,1,1,1,1,1,1,1,1,1,1,1,1,1,1,1,1,1,1,1,1,1,1,1,1,1,1
3,3,3,1,1,1,1,1,1,1,1,1,1,1,1,1,1,1,1,1,1,1,1,1,1,1,1,1,1,1,1,1,1,1,1,1,1,1,1,1,1,1,1,1,1,1,1,1,1,1,1,1
3,3,1,1,1,1,1,1,1,1,1,1,1,1,1,1,1,1,1,1,1,1,1,1,1,1,1,1,1,1,1,1,1,1,1,1,1,1,1,1,1,1,1,1,1,1,1,1,1,1,1,1
1,1,1,1,1,1,1,1,1,1,1,1,1,1,1,1,1,1,1,1,1,1,1,1,1,1,1,1,1,1,1,1,1,1,1,1,1,1,1,1,1,1,1,1,1,1,1,1,1,1,1,1
1,1,1,1,1,1,1,1,1,1,1,1,1,1,1,1,1,1,1,1,1,1,1,1,1,1,2,2,2,1,1,1,1,1,1,1,1,1,1,1,1,1,1,1,1,1,1,1,1,1,1,1
1,1,1,1,1,1,1,1,1,1,1,1,1,1,1,1,1,1,1,1,1,1,1,1,1,1,1,2,2,2,1,1,1,1,1,1,1,1,1,1,1,1,1,1,1,1,1,1,1,1,1,1
1,1,1,1,1,1,1,1,1,1,1,1,1,1,1,1,1,1,1,1,1,1,1,1,1,1,1,2,2,2,2,2,2,1,1,1,1,1,1,1,1,1,1,1,1,1,1,1,1,1,1,1
1,1,1,1,1,1,1,1,1,1,1,1,1,1,1,1,1,1,1,1,1,1,1,1,1,1,2,2,2,2,2,2,2,1,1,1,1,1,1,1,1,1,1,1,1,1,1,1,1,1,1,1
1,1,1,1,1,1,1,1,1,1,1,1,1,1,1,1,1,1,1,1,1,1,1,1,1,1,2,2,2,2,2,2,1,1,1,1,1,1,1,1,1,1,1,1,1,1,1,1,1,1,1,1
1,1,1,1,1,1,1,1,1,1,1,1,1,1,1,1,1,1,1,1,1,1,1,1,1,1,1,2,1,1,2,2,1,1,1,1,1,1,1,1,1,1,1,1,1,1,1,1,1,1,1,1
1,1,1,1,1,1,1,1,1,1,1,1,1,1,1,1,1,1,1,1,1,1,1,1,1,1,1,1,1,1,1,2,2,1,1,1,1,1,1,1,1,1,1,1,1,1,1,1,1,1,1,1
:endlayer
layer: 2
0,5,1,1,1,1,1,1,2,2,2,2,2,2,1,1,1,1,1,1,1,1,1,1,1,1,1,1,1,1,1,1,1,1,1,1,1,1,1,1,1,1,1,1,1,1,1,1,1,1,1,1
0,5,1,1,1,1,1,2,2,2,2,2,2,2,3,3,1,1,1,1,1,1,1,1,1,1,1,1,1,1,1,1,1,1,1,1,1,1,1,1,1,1,1,1,1,1,1,1,1,1,1,1
0,0,5,1,1,1,2,2,2,2,2,2,2,2,2,1,1,1,1,1,1,1,1,1,1,1,1,1,1,1,1,1,1,1,1,1,1,1,1,1,1,1,1,1,1,1,1,1,1,1,1,1
0,0,5,1,1,1,2,2,2,2,2,2,2,2,2,1,1,1,1,1,1,1,1,1,1,3,3,3,1,1,1,1,1,1,1,1,1,1,1,1,1,1,1,1,1,1,1,1,1,1,1,1
0,0,5,1,1,1,2,2,2,2,1,2,2,2,2,1,1,1,1,1,1,1,1,2,3,3,3,3,1,1,1,1,1,1,1,1,2,1,1,1,1,1,1,1,1,1,1,1,1,1,1,1
5,0,5,1,1,1,1,1,1,1,1,2,2,2,2,2,1,1,1,1,1,1,2,2,2,2,2,1,1,1,1,1,1,1,1,2,2,2,1,1,1,1,1,1,1,1,1,1,1,1,1,1
5,5,1,1,1,1,1,1,1,1,1,1,2,2,2,1,1,1,1,1,2,2,2,2,2,2,2,1,1,1,1,1,1,1,1,2,2,2,2,1,1,1,1,1,1,1,1,1,1,1,1,1
1,1,1,1,1,1,1,1,1,1,1,1,2,2,2,1,1,1,1,1,2,2,2,2,2,2,1,1,1,1,1,1,1,1,1,1,2,2,2,2,1,1,1,1,1,1,1,1,1,1,1,1
1,1,1,1,1,1,1,2,2,1,1,1,1,2,2,1,1,1,1,2,2,2,2,2,2,1,1,1,1,1,1,1,1,1,1,1,2,2,2,2,2,1,1,1,1,1,1,1,1,1,1,1
1,1,1,1,1,2,2,2,2,1,1,1,1,1,1,1,1,1,1,1,1,2,2,1,1,1,1,1,1,1,1,1,1,1,1,1,2,2,2,2,2,1,1,1,1,1,1,1,1,1,1,1
1,1,1,1,1,2,2,2,1,1,1,1,1,1,1,1,1,1,1,1,1,1,1,1,1,1,1,1,1,1,1,1,1,1,1,1,1,2,2,2,2,1,1,1,1,1,1,1,1,1,1,1
1,1,1,1,1,2,1,1,1,1,1,1,1,1,1,1,1,1,1,1,1,1,1,1,1,1,1,1,1,1,1,1,1,1,1,1,1,2,2,2,2,1,1,1,1,1,1,1,1,1,1,1
1,1,1,1,1,1,1,1,1,1,1,1,1,1,1,1,1,1,1,1,1,1,1,1,1,1,3,1,1,1,1,1,1,1,1,1,4,1,2,2,2,1,1,1,1,1,1,1,1,1,1,1
1,1,1,1,1,1,1,1,1,1,1,1,1,1,1,1,5,5,5,1,1,1,1,1,3,3,3,1,1,1,1,1,1,1,1,1,1,1,2,2,2,2,1,1,1,1,1,1,1,1,1,1
1,1,1,1,1,1,1,1,1,1,1,1,1,1,1,5,5,5,5,5,5,5,1,3,3,3,1,1,1,1,1,1,1,1,1,1,1,2,2,2,2,2,1,1,1,1,1,1,1,1,1,1
1,1,1,1,1,1,1,1,1,1,1,1,1,1,1,1,5,5,5,5,5,5,5,3,3,1,1,1,1,1,1,1,1,1,1,1,1,1,2,2,2,2,1,1,1,1,1,1,1,1,1,1
1,5,1,1,1,1,1,1,1,1,1,1,1,1,1,1,5,5,5,5,5,5,5,5,1,1,1,1,1,1,1,1,1,1,1,1,1,1,2,2,2,2,2,1,1,1,1,1,1,1,1,1
5,5,5,1,1,1,1,1,1,1,1,1,1,1,1,1,1,1,5,5,5,5,5,5,1,1,1,1,1,1,1,1,1,1,1,1,1,1,1,2,2,2,2,1,1,1,1,1,1,1,1,1
5,5,5,1,1,1,1,1,1,1,1,1,1,1,1,1,1,1,1,1,5,5,5,5,1,1,1,1,1,1,1,1,1,1,1,1,1,1,1,1,2,2,1,1,1,1,1,1,1,1,1,1
5,5,5,5,1,1,1,1,1,1,1,1,1,1,1,1,1,1,1,5,5,5,1,1,1,1,1,1,1,1,1,1,1,1,1,1,1,1,1,1,1,1,1,1,1,1,1,1,1,1,1,1
5,5,5,5,1,1,1,1,1,1,1,1,1,1,1,1,1,1,5,5,5,5,1,1,1,1,1,1,1,1,1,1,1,1,1,1,1,1,1,1,1,5,5,5,1,1,1,1,1,1,1,1
1,5,5,5,3,1,1,1,1,1,1,1,1,1,1,1,5,5,5,5,5,5,1,1,1,1,1,5,1,1,1,1,1,1,1,1,1,1,1,1,5,5,0,0,0,0,0,1,1,1,1,1
3,5,5,5,3,1,1,3,3,1,1,1,1,1,1,1,5,5,5,5,5,1,1,1,1,1,5,5,5,1,1,1,1,1,1,1,1,1,1,1,5,0,0,0,0,0,0,0,1,1,1,1
1,5,5,5,1,1,1,3,3,3,1,1,1,1,1,5,5,5,5,5,1,1,1,1,1,1,5,5,5,1,1,1,1,1,1,1,1,1,1,1,1,1,0,0,0,0,0,0,0,1,1,1
1,1,1,1,1,1,1,1,3,3,1,1,1,1,5,5,5,5,5,5,1,1,1,1,1,5,5,5,1,1,1,1,1,1,1,1,1,1,1,1,1,1,1,1,0,0,0,0,0,1,1,1
1,1,1,1,1,1,1,1,1,1,1,1,1,1,5,5,5,5,1,1,1,1,1,1,1,5,5,5,1,1,1,1,1,1,1,1,1,1,1,1,1,1,1,1,1,1,1,1,1,1,1,1
1,1,1,2,1,1,2,1,1,1,1,1,1,1,5,5,5,1,1,1,1,1,1,1,1,5,5,5,1,1,1,1,1,1,1,1,1,1,1,1,1,1,1,1,1,1,1,1,1,1,1,1
1,1,2,2,1,1,1,1,1,1,1,1,1,1,1,1,1,1,1,1,1,1,1,1,1,1,1,1,1,1,1,1,1,1,1,1,1,1,1,1,1,1,1,1,1,1,1,1,1,1,1,1
1,1,1,1,1,1,1,1,1,1,1,1,1,1,1,1,1,1,1,1,1,1,1,1,1,1,1,1,1,1,1,1,1,1,1,1,1,1,1,1,1,1,1,1,1,1,1,1,1,1,1,1
1,1,1,1,1,1,1,1,1,1,1,1,1,1,1,1,1,1,1,1,1,1,1,1,1,1,1,1,1,1,1,1,1,1,1,1,1,1,1,1,1,1,1,1,1,1,1,1,1,1,1,1
1,1,1,1,1,1,1,1,1,1,1,1,1,1,1,1,1,1,1,1,1,1,1,1,1,1,1,1,1,1,1,1,1,1,1,1,1,1,1,1,1,1,1,1,1,1,1,1,1,1,1,1
1,1,1,1,1,1,1,1,1,1,1,1,1,1,1,1,1,1,1,1,1,1,1,1,1,1,1,1,1,1,1,1,1,1,1,1,1,1,1,1,1,1,1,1,1,1,1,1,1,1,1,1
1,1,1,1,1,1,1,1,1,1,1,1,1,1,1,1,1,1,1,1,1,1,1,1,1,1,1,1,1,1,1,1,1,1,1,1,1,1,1,1,1,1,1,1,1,1,1,1,1,1,1,1
1,1,1,1,1,1,1,1,1,1,1,1,1,1,1,1,5,1,1,1,1,1,1,1,1,3,3,1,1,1,1,0,0,0,0,1,1,1,1,1,1,1,1,1,1,1,1,1,1,1,1,1
1,1,1,1,1,1,1,1,1,1,1,1,1,1,1,1,1,1,1,1,1,1,1,1,1,3,3,3,1,1,1,1,0,0,0,1,1,1,1,1,1,1,1,1,2,2,2,2,1,1,1,1
1,1,1,1,1,1,1,1,1,1,1,1,1,1,1,1,1,1,1,1,1,1,1,1,1,1,3,3,3,1,1,1,0,0,1,1,1,1,1,1,1,1,1,1,2,2,2,2,1,1,1,1
1,1,1,1,1,1,1,1,1,1,1,1,1,1,1,1,1,1,1,1,1,1,1,1,1,1,1,1,3,1,4,4,1,0,1,1,1,1,1,1,1,1,1,1,1,1,1,1,1,1,1,1
1,1,1,1,1,1,1,1,1,1,1,1,1,1,1,1,1,1,1,1,1,1,1,1,1,1,1,1,1,1,4,4,1,1,1,1,1,1,1,1,1,1,1,1,1,1,1,1,1,1,1,1
1,1,1,1,1,1,1,1,1,1,1,1,1,1,1,1,1,1,1,1,1,1,1,1,1,1,1,1,1,1,1,1,1,1,1,1,1,1,1,1,1,1,1,1,1,1,1,1,1,1,1,1
1,1,1,1,1,1,1,1,1,1,1,1,1,1,1,1,1,1,1,1,1,1,1,1,1,1,1,1,1,1,1,1,1,1,1,1,1,1,1,1,1,1,1,1,1,1,1,1,1,1,1,1
1,3,3,1,1,1,1,1,1,1,1,1,1,1,1,1,1,1,1,1,1,1,1,1,1,1,1,1,1,1,1,1,1,1,1,1,1,1,1,1,1,1,1,1,1,1,1,1,1,1,1,1
1,3,3,1,1,1,1,1,1,1,1,1,1,1,1,1,1,1,1,1,1,1,1,1,1,1,1,1,1,1,1,1,1,1,1,1,1,1,1,1,1,1,1,1,1,1,1,1,1,1,1,1
3,3,1,1,1,1,1,1,1,1,1,1,1,1,1,1,1,1,1,1,1,1,1,1,1,1,1,1,1,1,1,1,1,1,1,1,1,1,1,1,1,1,1,1,1,1,1,1,1,1,1,1
1,1,1,1,1,1,1,1,1,1,1,1,1,1,1,1,1,1,1,1,1,1,1,1,1,1,2,2,1,1,1,1,1,1,1,4,4,1,1,1,1,1,1,1,1,1,1,1,1,1,1,1
1,1,1,1,1,1,1,1,1,1,1,1,1,1,1,3,1,1,1,1,1,1,1,1,1,1,2,2,2,2,1,1,1,1,1,4,4,1,1,1,1,1,1,1,1,1,1,1,1,1,1,1
1,1,1,1,1,1,1,1,1,1,1,1,1,1,1,1,3,1,1,1,1,1,1,1,1,1,2,2,2,2,2,1,1,1,1,1,1,1,1,1,1,1,1,1,1,1,1,1,1,1,1,1
1,1,1,1,1,1,1,1,1,1,1,1,1,1,1,3,3,1,1,1,1,1,1,1,1,1,2,2,2,2,2,1,1,1,1,1,1,1,1,1,1,1,1,1,1,1,1,1,1,1,1,1
1,1,1,1,1,1,1,1,1,1,1,1,1,1,1,1,3,1,1,1,1,1,1,1,1,1,1,2,2,2,2,1,1,1,1,1,1,1,1,1,1,1,1,1,1,1,1,1,1,1,1,1
1,1,1,1,1,1,1,1,1,1,1,1,1,1,1,1,1,1,1,1,1,1,1,1,1,1,1,2,2,2,2,2,1,1,1,1,1,1,1,1,1,1,1,1,1,1,1,1,1,1,1,1
1,1,1,1,1,1,1,1,1,1,1,1,1,1,1,1,1,1,1,1,1,1,1,1,1,1,1,1,1,2,2,2,2,1,1,1,1,1,1,1,1,1,1,1,1,1,1,1,1,1,1,1
1,1,1,1,1,1,1,1,1,1,1,1,1,1,1,1,1,1,1,1,1,1,1,1,1,1,1,1,1,2,2,2,2,2,1,1,1,1,1,1,1,1,1,1,1,1,1,1,1,1,1,1
:endlayer
layer: 3
0,1,1,1,1,1,1,1,2,2,2,2,2,1,1,1,1,1,1,1,1,1,1,1,1,1,1,1,1,1,1,1,1,1,1,1,1,1,1,1,1,1,1,1,1,1,1,1,1,1,1,1
0,1,1,1,1,1,1,2,2,2,2,2,2,2,1,1,1,1,1,1,1,1,1,1,1,1,1,1,1,1,1,1,1,1,1,1,1,1,1,1,1,1,1,1,1,1,1,1,1,1,1,1
0,0,1,1,1,1,1,2,2,2,2,2,2,2,2,1,1,1,1,1,1,1,1,1,1,1,1,1,1,1,1,1,1,1,1,1,1,1,1,1,1,1,1,1,1,1,1,1,1,1,1,1
0,0,1,1,1,1,1,2,2,2,2,2,2,2,2,1,1,1,1,1,1,1,1,1,1,3,3,3,3,1,1,1,1,1,1,1,1,1,1,1,1,1,1,1,1,1,1,1,1,1,1,1
0,0,1,1,1,1,1,1,2,1,1,2,2,2,2,1,1,1,1,1,1,1,1,2,3,3,3,3,3,1,1,1,1,1,1,1,1,1,1,1,1,1,1,1,1,1,1,1,1,1,1,1
1,0,1,1,1,1,1,1,1,1,1,1,2,2,2,1,1,1,1,1,1,2,2,2,2,2,2,1,1,1,1,1,1,1,1,1,1,1,1,1,1,1,1,1,1,1,1,1,1,1,1,1
1,1,1,1,1,1,1,1,1,1,1,1,2,2,2,1,1,1,1,1,2,2,2,2,2,2,1,1,1,1,1,1,1,1,1,1,1,1,1,1,1,1,1,1,1,1,1,1,1,1,1,1
1,1,1,1,1,1,1,1,1,1,1,1,2,2,2,1,1,1,1,2,2,2,2,2,2,2,1,1,1,1,1,1,1,1,1,1,1,1,2,1,1,1,1,1,1,1,1,1,1,1,1,1
1,1,1,1,1,1,1,1,1,1,1,1,1,2,2,1,1,1,2,2,2,2,2,2,1,1,1,1,1,1,1,1,1,1,1,1,1,2,2,2,1,1,1,1,1,1,1,1,1,1,1,1
1,1,1,1,1,1,1,1,1,1,1,1,1,1,1,1,1,1,2,2,2,2,2,1,1,1,1,1,1,1,1,1,1,1,1,1,1,2,2,2,1,1,1,1,1,1,1,1,1,1,1,1
1,1,1,1,1,1,1,1,1,1,1,1,1,1,1,1,1,3,3,3,3,3,1,1,1,1,1,1,1,1,1,1,1,1,1,1,1,1,2,1,1,1,1,1,1,1,1,1,1,1,1,1
1,1,1,1,1,1,1,1,1,1,1,1,1,1,1,1,3,3,3,3,3,1,1,1,1,1,4,1,1,1,1,1,1,1,1,1,1,2,2,2,1,1,1,1,1,1,1,1,1,1,1,1
1,1,1,1,1,1,1,1,1,1,1,1,1,1,1,1,1,1,1,1,1,1,1,1,1,1,3,1,1,1,1,1,1,1,1,4,4,1,2,2,2,1,1,1,1,1,1,1,1,1,1,1
1,1,1,1,1,1,1,1,1,1,1,1,1,1,1,1,5,5,5,1,1,1,1,1,1,3,3,1,1,1,1,1,1,1,1,4,4,1,2,2,2,2,1,1,1,1,1,1,1,1,1,1
1,1,1,1,1,1,1,1,1,1,1,1,1,1,1,5,5,5,5,5,5,5,1,1,3,3,1,1,1,1,1,1,1,1,1,1,1,2,2,2,2,2,1,1,1,1,1,1,1,1,1,1
5,5,1,1,1,1,1,1,1,1,1,1,1,1,1,1,5,5,5,5,5,5,5,1,1,1,1,1,1,1,1,1,1,1,1,1,1,1,2,2,2,2,1,1,1,1,1,1,1,1,1,1
5,5,5,1,1,1,1,1,1,1,1,1,1,1,1,1,5,5,5,5,5,5,5,5,1,1,1,1,1,1,1,1,1,1,1,1,1,1,2,2,2,2,2,1,1,1,1,1,1,1,1,1
5,5,5,1,1,1,1,1,1,1,1,1,1,1,1,1,1,1,5,5,5,5,5,5,1,1,1,1,1,1,1,1,1,1,1,1,1,1,1,2,2,2,2,1,1,1,1,1,1,1,1,1
5,5,5,5,1,1,1,1,1,1,1,1,1,1,1,1,1,1,1,1,5,5,5,5,1,1,1,1,1,1,1,1,1,1,1,1,1,1,1,1,2,2,1,1,1,1,1,1,1,1,1,1
5,5,5,5,1,1,1,1,1,1,1,1,1,1,1,1,1,1,1,5,5,5,1,1,1,1,1,1,5,1,1,1,1,1,1,1,1,1,1,1,1,1,1,1,1,1,1,1,1,1,1,1
5,5,5,5,1,1,1,1,1,1,1,1,1,1,1,1,1,1,5,5,5,5,1,1,1,1,1,5,5,1,1,1,1,1,1,1,1,1,1,1,1,1,1,1,1,1,1,1,1,1,1,1
5,5,5,5,1,2,2,1,1,1,1,1,1,1,1,1,5,5,5,5,5,5,1,1,1,1,5,5,5,1,1,1,1,1,1,1,1,1,1,1,1,1,0,0,1,1,1,1,1,1,1,1
3,5,5,5,2,2,2,1,1,1,1,1,1,1,1,1,5,5,5,5,5,1,1,1,1,5,5,5,5,1,1,1,1,1,1,1,1,1,1,1,1,1,0,0,0,0,1,1,1,1,1,1
1,5,5,2,2,2,2,1,1,1,1,1,1,1,1,5,5,5,5,5,1,1,1,1,1,5,5,5,5,1,1,1,1,1,1,1,1,1,1,1,1,1,1,1,0,0,0,1,1,1,1,1
1,1,1,2,2,2,2,1,1,1,1,1,1,1,5,5,5,5,5,5,1,1,1,1,1,5,5,5,5,1,1,1,1,1,1,1,1,1,1,1,1,1,1,1,1,1,1,1,1,1,1,1
1,1,2,2,2,2,2,2,2,1,1,1,1,1,5,5,5,5,1,1,1,1,1,1,5,5,5,5,5,1,1,1,1,1,1,1,1,1,1,1,1,1,1,1,1,1,1,1,1,1,1,1
1,2,2,2,2,2,2,2,1,1,1,1,1,1,5,5,5,1,1,1,1,1,1,1,5,5,5,5,1,1,1,1,1,1,1,1,1,1,1,1,1,1,1,1,1,1,1,1,1,1,1,1
2,2,2,2,2,2,2,1,1,1,1,1,1,1,1,1,1,1,1,1,1,1,1,1,1,5,5,5,1,1,1,1,1,1,1,1,1,1,1,1,1,1,1,1,1,1,1,1,1,1,1,1
2,2,2,2,2,1,1,1,1,1,1,1,1,1,1,1,1,1,1,1,1,1,1,1,1,1,1,1,1,1,1,1,1,1,1,1,1,1,1,1,1,1,1,1,1,1,1,1,1,1,1,1
1,1,1,1,1,1,1,1,1,1,1,5,5,1,1,1,1,1,1,1,1,1,1,1,1,1,1,1,1,1,1,1,1,1,1,1,1,1,1,1,1,1,1,1,1,1,1,1,1,1,1,1
1,1,1,1,1,1,1,1,1,5,5,5,5,1,1,1,1,1,1,1,1,1,1,1,1,1,1,1,1,1,1,1,1,1,1,1,1,1,1,1,1,1,1,1,1,1,1,1,1,1,1,1
1,1,1,1,1,1,1,1,1,5,5,5,1,1,1,1,5,1,1,5,1,1,1,1,1,1,1,1,1,1,1,1,1,1,1,1,1,1,1,1,1,1,1,1,1,1,1,1,1,1,1,1
1,1,1,1,1,1,1,1,5,5,5,5,1,1,1,5,5,5,5,5,5,1,1,1,1,1,1,1,1,1,1,1,1,1,1,1,1,1,1,1,1,1,1,1,1,1,1,1,1,1,1,1
1,1,1,1,1,1,1,1,5,5,1,1,1,5,5,5,5,5,5,5,5,1,1,1,1,3,3,1,1,1,1,1,0,0,1,1,1,1,1,1,1,1,1,1,1,1,1,1,1,1,1,1
1,1,1,1,1,1,1,5,5,1,1,1,1,1,5,5,5,5,1,1,1,1,1,1,1,3,3,3,1,1,1,1,1,1,1,1,1,1,1,1,1,1,1,1,1,1,1,1,1,1,1,1
1,1,1,1,1,1,1,1,1,1,1,1,1,1,1,1,1,1,1,1,1,1,1,1,1,1,3,3,3,1,1,1,1,1,1,1,1,1,1,1,1,1,1,1,1,1,1,1,1,1,1,1
1,1,1,1,1,1,1,1,1,1,1,1,1,1,1,1,1,1,1,1,1,1,1,1,1,1,1,1,3,1,1,1,1,1,1,1,1,1,1,1,1,1,1,1,1,1,1,1,1,1,1,1
1,1,1,1,1,1,1,1,1,1,1,1,1,1,1,1,1,1,1,1,1,1,1,1,1,1,1,1,1,1,4,1,1,1,1,1,1,1,1,1,1,1,1,1,1,1,1,1,1,1,1,1
1,1,1,1,1,1,1,1,1,1,1,1,1,1,1,1,1,1,1,1,1,1,1,1,1,1,1,1,1,1,1,1,1,1,1,1,1,1,1,1,1,1,1,1,1,1,1,1,1,1,1,1
1,1,1,1,1,1,1,1,1,1,1,1,1,1,1,1,1,1,1,1,1,1,1,1,1,1,1,1,1,1,1,1,1,1,1,1,1,1,1,1,1,1,1,1,1,1,1,1,1,1,1,1
1,1,1,1,1,1,1,1,1,1,1,1,1,1,1,1,1,1,1,1,1,1,1,1,1,1,1,1,1,1,1,1,1,1,1,1,1,1,1,1,1,1,1,1,1,1,1,1,1,1,1,1
1,1,1,1,1,1,1,1,1,1,1,1,1,1,1,1,1,1,1,1,1,1,1,1,1,1,1,1,1,1,1,1,1,1,1,1,1,1,1,1,1,1,1,1,1,1,1,1,1,1,1,1
1,1,1,1,1,1,1,1,1,1,1,1,1,1,1,3,1,1,1,1,1,1,1,1,1,1,1,1,1,1,1,1,1,1,1,1,1,1,1,1,1,1,1,1,1,1,1,1,1,2,2,1
4,4,1,1,1,1,1,1,1,1,1,1,1,1,1,3,3,1,1,1,1,1,1,1,1,1,2,2,1,1,1,1,1,1,1,1,1,1,1,1,1,1,1,1,1,1,1,1,2,2,2,1
4,4,1,1,1,1,1,1,1,1,1,1,1,1,1,3,3,1,1,1,1,1,1,1,1,1,2,2,2,2,1,1,1,1,1,1,1,1,1,1,1,1,1,1,1,1,1,1,1,2,2,2
1,1,1,1,1,1,1,1,1,1,1,1,1,1,1,3,3,1,1,1,1,1,1,1,1,1,2,2,2,2,2,1,1,1,1,1,1,1,1,1,1,1,1,1,5,1,1,1,1,2,2,2
1,1,1,1,1,1,1,1,1,1,1,1,1,1,1,3,3,1,1,1,1,1,1,1,1,1,2,2,2,2,2,1,1,1,1,1,1,1,1,1,1,1,1,1,5,5,5,1,1,1,2,2
1,1,1,1,1,1,1,1,1,1,1,1,1,1,1,1,3,1,1,1,1,1,1,1,1,1,1,2,2,2,2,1,1,1,1,1,1,1,1,1,1,1,1,1,1,5,5,1,1,1,1,2
1,1,1,1,1,1,1,1,1,1,1,1,1,1,1,1,1,1,1,1,1,1,1,1,1,1,1,2,2,2,2,2,1,1,1,1,1,1,1,1,1,1,1,1,1,1,5,5,1,1,1,1
1,1,1,1,1,1,1,1,1,1,1,1,1,1,1,1,1,1,1,1,1,1,1,1,1,1,1,1,1,2,2,2,2,1,1,1,1,1,1,1,1,1,1,1,1,1,1,1,1,1,1,1
1,1,1,1,1,1,1,1,1,1,1,1,1,1,1,1,1,1,1,1,1,1,1,1,1,1,1,1,1,2,2,2,2,2,1,1,1,1,1,1,1,1,1,1,1,1,1,1,1,1,1,1
:endlayer
layer: 4
1,1,1,1,1,1,1,1,2,2,2,2,1,1,1,1,1,1,1,1,1,1,1,1,1,1,1,1,1,1,1,1,1,1,1,1,1,1,1,1,1,1,1,1,1,1,1,1,1,1,1,1
1,1,1,1,1,1,1,1,2,2,2,2,1,1,1,1,1,1,1,1,1,1,1,1,1,1,1,1,1,1,1,1,1,1,1,1,1,1,1,1,1,1,1,1,1,1,1,1,1,1,1,1
1,1,1,1,1,1,1,1,2,2,2,1,1,1,1,1,1,1,1,1,1,1,1,1,1,1,1,1,1,1,1,1,1,1,1,1,1,1,1,1,1,1,1,1,1,1,1,1,1,1,1,1
1,1,1,1,1,1,1,1,1,1,1,1,2,2,1,1,1,1,1,1,1,1,1,1,1,1,3,3,3,1,1,1,1,1,1,1,1,1,1,1,1,1,1,1,1,1,1,1,1,1,1,1
1,1,1,1,1,1,1,1,1,1,1,1,2,2,1,1,1,1,1,1,1,1,1,1,1,1,3,3,3,1,1,1,1,1,1,1,1,1,1,1,1,1,1,1,1,1,1,1,1,1,1,1
1,1,1,1,1,1,1,1,1,1,1,1,2,2,2,1,1,1,1,1,1,1,1,2,2,1,1,1,1,1,1,1,1,1,1,1,1,1,1,1,1,1,1,1,1,1,1,1,1,1,1,1
1,1,1,1,1,1,1,1,1,1,1,1,1,2,1,1,1,1,1,1,2,2,2,2,2,2,1,1,1,1,1,1,1,1,1,1,1,1,1,1,1,1,1,1,1,1,1,1,1,1,1,1
1,1,1,1,1,1,1,1,1,1,1,1,1,1,1,1,1,1,1,2,2,2,2,2,1,1,1,1,1,1,1,1,1,1,1,1,1,1,1,1,1,1,1,1,1,1,1,1,1,1,1,1
1,1,1,1,1,1,1,1,1,1,1,1,1,1,1,1,1,1,2,2,2,2,2,2,1,1,1,1,1,1,1,1,1,1,1,1,1,1,1,1,1,1,1,1,1,1,1,1,1,1,1,1
1,1,1,1,1,1,1,1,1,1,1,1,1,1,1,1,1,1,2,2,2,1,1,1,1,1,1,1,1,1,1,1,1,1,1,1,1,1,1,1,1,1,1,1,1,1,1,1,1,1,1,1
1,1,1,1,1,1,1,1,1,1,1,1,1,1,1,1,1,3,3,3,3,3,1,1,1,1,1,1,1,1,1,1,1,1,1,1,1,1,1,1,1,1,1,1,1,1,1,1,1,1,1,1
1,1,1,1,1,1,1,1,1,1,1,1,1,1,1,1,3,3,3,3,3,1,1,1,1,4,1,1,1,1,1,1,1,1,1,1,1,1,1,1,1,1,1,1,1,1,1,1,1,1,1,1
1,1,1,1,1,1,1,1,1,1,1,1,1,1,1,1,1,1,1,1,1,1,1,1,1,4,1,1,1,1,1,1,1,1,1,1,1,1,1,2,1,1,1,1,1,1,1,1,1,1,1,1
1,1,1,1,1,1,1,1,1,1,1,1,1,1,1,1,1,1,1,1,1,1,1,1,1,1,1,1,1,1,1,1,1,1,1,4,1,1,2,2,2,1,1,1,1,1,1,1,1,1,1,1
1,1,1,1,1,1,1,1,1,1,1,1,1,1,1,1,1,5,5,5,5,1,1,1,1,1,1,1,1,1,1,1,1,1,1,1,1,1,2,2,2,2,1,1,1,1,1,1,1,1,1,1
5,5,1,1,1,1,1,1,1,1,1,1,1,1,1,1,1,5,5,5,5,5,1,1,1,1,1,1,1,1,1,1,1,1,1,1,1,1,2,2,2,2,1,1,1,1,1,1,1,1,1,1
5,5,5,1,1,1,1,1,1,1,1,1,1,1,1,1,1,1,5,5,5,5,5,1,1,1,1,1,1,1,1,1,1,1,1,1,1,1,1,2,2,2,1,1,1,1,1,1,1,1,1,1
5,5,5,1,1,1,1,1,1,1,1,1,1,1,1,1,1,1,1,5,5,5,5,3,1,1,1,1,1,1,1,1,1,1,1,1,1,1,1,1,2,2,1,1,1,1,1,1,1,1,1,1
5,5,5,5,1,1,1,1,1,1,1,1,1,1,1,1,1,1,1,1,1,3,3,3,1,1,1,1,1,1,1,1,1,1,1,1,1,1,1,1,1,1,1,1,1,1,1,1,1,1,1,1
5,5,5,5,1,1,2,1,1,1,1,1,1,1,1,1,1,1,1,1,1,1,1,1,1,1,1,1,5,1,1,1,1,1,1,1,1,1,1,1,1,1,1,1,1,1,1,1,1,1,1,1
5,5,5,5,1,2,2,2,1,1,1,1,1,1,1,1,1,1,1,1,5,1,1,1,1,1,1,5,5,1,1,1,1,1,1,1,1,1,1,1,1,1,1,1,1,1,1,1,1,1,1,1
1,5,5,5,2,2,2,2,1,1,1,1,1,1,1,1,1,5,5,5,1,1,1,1,1,1,5,5,5,1,1,1,1,1,1,1,1,1,1,1,1,1,1,1,1,1,1,1,1,1,1,1
1,1,5,2,2,2,2,2,1,1,1,1,1,1,1,1,5,5,5,5,1,1,1,1,1,5,5,5,5,1,1,1,1,1,1,1,1,1,1,1,1,1,1,1,1,1,1,1,1,1,1,1
1,1,5,2,2,2,2,1,1,1,1,1,1,1,1,1,5,5,5,5,1,1,1,1,1,5,5,5,5,1,1,1,1,1,1,1,1,1,1,1,1,1,1,1,1,1,1,1,1,1,1,1
1,1,2,2,2,2,2,1,1,1,1,1,1,1,1,5,5,5,5,1,1,1,1,1,1,5,5,5,5,1,1,1,1,1,1,1,1,1,1,1,1,1,1,1,1,1,1,1,1,1,3,3
1,1,2,2,2,2,2,2,2,1,1,1,1,1,1,5,5,1,4,1,1,1,1,1,5,5,5,5,5,1,1,1,1,1,1,1,1,1,1,1,1,1,1,1,1,1,1,1,1,1,3,3
2,2,2,2,2,2,2,2,1,1,1,1,1,1,1,1,1,1,1,1,1,1,1,1,5,5,5,5,1,1,1,1,1,1,1,1,1,1,1,1,1,1,1,1,1,1,1,1,1,1,1,1
2,2,2,2,2,2,2,2,1,1,1,1,1,1,1,1,1,1,1,1,1,1,1,1,1,5,5,5,1,1,3,3,3,3,1,1,1,1,1,1,1,1,1,1,1,1,1,1,1,1,1,1
2,2,2,2,2,1,1,1,1,1,1,5,5,1,1,1,1,1,1,1,1,1,1,1,1,1,1,1,1,1,3,3,3,3,1,1,1,1,1,1,1,1,1,1,1,1,1,1,1,1,1,1
2,2,2,2,1,1,1,1,1,5,5,5,5,1,1,1,1,1,1,1,1,1,1,1,1,1,1,1,1,1,1,1,1,1,1,1,1,1,1,1,1,1,1,1,1,1,2,1,1,1,1,1
1,1,1,1,1,1,1,1,1,5,5,5,5,1,1,1,1,1,1,1,1,1,1,1,1,1,1,1,1,1,1,1,1,1,1,1,1,1,1,1,1,2,2,2,2,2,2,2,1,1,1,1
1,1,1,1,1,1,1,1,5,5,5,5,5,1,1,5,5,5,5,5,5,1,1,1,1,1,1,1,1,1,1,1,1,1,1,1,1,1,1,1,1,2,2,2,2,2,2,2,1,1,1,1
1,1,1,1,1,1,1,1,5,5,5,5,1,1,5,5,5,5,5,5,5,5,1,1,1,1,1,1,1,1,1,1,1,1,1,1,1,1,1,1,1,2,2,2,2,1,2,1,1,1,1,1
1,1,1,1,1,1,1,5,5,5,5,1,1,5,5,5,5,5,5,5,5,1,1,1,1,1,1,1,1,1,1,1,1,1,1,1,1,1,1,1,1,1,1,1,1,1,1,1,1,1,1,1
4,4,1,1,1,1,5,5,5,5,1,1,1,1,5,5,5,5,5,5,5,1,1,1,1,1,1,1,1,1,1,1,1,1,1,1,1,1,1,1,1,1,1,1,1,1,1,1,1,1,1,1
1,1,1,1,1,1,5,5,5,1,1,1,1,1,1,1,5,1,1,1,1,1,1,1,1,1,1,1,1,1,1,1,1,1,1,1,1,1,1,1,1,1,1,1,1,1,1,1,1,1,1,1
1,1,1,1,1,1,1,1,1,1,1,1,1,1,1,1,1,1,1,1,1,1,1,1,1,1,1,1,1,1,1,1,1,1,1,1,1,1,1,1,1,1,1,1,1,1,1,1,1,1,1,1
1,1,1,1,1,1,1,1,1,1,1,1,1,1,1,1,1,1,1,1,1,1,1,1,1,1,1,1,1,1,1,1,1,1,1,1,1,1,1,1,1,1,1,1,1,1,1,1,1,1,1,1
1,1,1,1,1,1,1,1,1,1,1,1,1,1,1,1,1,1,1,1,1,1,1,1,1,1,1,1,1,1,1,1,1,1,1,1,1,1,1,1,1,1,1,1,1,1,1,1,1,1,1,1
1,1,1,1,1,1,1,1,1,1,1,1,1,1,1,1,1,1,1,1,1,1,1,1,1,1,1,1,1,1,1,1,1,1,1,1,1,1,1,1,1,1,1,1,1,1,1,1,2,1,1,1
1,1,1,1,1,1,1,1,1,1,1,1,1,1,1,1,1,1,1,1,1,1,1,1,1,1,1,1,5,5,5,5,1,1,1,1,1,1,1,1,1,1,1,1,1,1,1,2,2,2,1,1
1,1,1,1,1,1,1,1,1,1,1,1,1,1,1,1,1,1,1,1,1,1,1,1,1,1,1,1,5,5,5,5,5,5,1,1,1,1,1,1,1,1,1,1,1,1,1,2,2,2,1,1
1,1,1,1,1,1,1,1,1,1,1,1,1,1,1,3,1,1,1,1,1,1,1,1,1,1,1,1,5,5,5,5,5,5,5,1,1,1,1,1,1,1,1,1,1,1,1,1,2,2,2,2
1,1,1,1,1,1,1,1,1,1,1,1,1,1,1,3,1,1,1,1,1,1,1,1,1,1,1,1,1,1,5,5,5,5,5,1,1,1,1,1,1,1,1,1,1,1,1,1,2,2,2,2
1,1,1,1,1,1,1,1,1,1,1,1,1,1,1,3,3,5,5,5,1,1,1,1,1,1,2,2,2,1,1,1,1,1,1,1,1,1,1,1,1,1,1,5,5,5,1,1,2,2,2,2
1,1,1,1,1,1,1,1,1,1,1,1,1,1,1,1,1,5,5,5,1,1,1,4,4,1,1,2,2,2,1,1,1,1,1,1,1,1,1,1,1,1,1,5,5,5,5,1,1,2,2,2
1,1,1,1,1,1,1,1,1,1,1,1,1,1,1,1,1,1,1,1,1,1,1,4,4,1,1,2,2,2,2,1,1,1,1,1,1,1,1,1,1,1,1,5,5,5,5,5,1,2,2,2
1,1,1,1,1,1,1,1,1,1,1,1,1,1,1,1,1,1,1,1,1,1,1,1,1,1,1,2,2,2,2,1,1,1,1,1,1,1,1,1,1,1,1,1,5,5,5,5,5,1,2,2
1,1,1,1,1,1,1,1,1,1,1,1,1,1,1,1,1,1,1,1,1,1,1,1,1,1,1,1,2,2,2,1,1,1,1,1,1,1,1,1,1,1,1,1,1,5,5,5,5,5,1,2
1,1,1,1,1,1,1,1,1,1,1,1,1,1,1,1,1,1,1,1,1,1,1,1,1,1,1,1,1,1,2,2,1,1,1,1,1,1,1,1,1,1,1,1,1,1,5,5,5,5,1,1
1,1,1,1,1,1,1,1,1,1,1,1,1,1,1,1,1,1,1,1,1,1,1,1,1,1,1,1,1,1,1,1,1,1,1,1,1,1,1,1,1,1,1,1,1,1,1,5,5,5,1,1
:endlayer
layer: 5
1,1,1,1,1,1,1,1,1,1,1,1,1,1,1,1,1,1,1,1,1,1,1,1,1,1,1,1,1,1,1,1,1,1,1,1,1,1,1,1,1,1,1,1,1,1,1,1,1,1,1,1
1,1,1,1,1,1,1,1,1,1,1,1,1,1,1,1,1,1,1,1,1,1,1,1,1,1,1,1,1,1,1,1,1,1,1,1,1,1,1,1,1,1,1,1,1,1,1,1,1,1,1,1
1,1,1,1,1,1,1,1,1,1,1,1,1,1,1,1,1,1,1,1,1,1,1,1,1,1,1,1,1,1,1,1,1,1,1,1,1,1,1,1,1,1,1,1,1,1,1,1,1,1,1,1
1,1,1,1,1,1,1,1,1,1,1,1,1,1,1,1,1,1,1,1,1,1,1,1,1,1,1,1,1,1,1,1,1,1,1,1,1,1,1,1,1,1,1,1,1,1,1,1,1,1,1,1
1,1,1,1,1,1,1,1,1,1,1,1,1,1,1,1,1,1,1,1,1,1,1,1,1,1,1,1,1,1,1,1,1,1,1,1,1,1,1,1,1,1,1,1,1,1,1,1,1,1,1,1
1,1,1,1,1,1,1,1,1,1,1,1,1,1,1,1,1,1,1,1,1,1,1,1,1,1,1,1,1,1,1,1,1,1,1,1,1,1,1,1,1,1,1,1,1,1,1,1,1,1,1,1
1,1,1,1,1,1,1,1,1,1,1,1,1,1,1,1,1,1,1,1,1,1,1,1,1,1,1,1,1,1,1,1,1,1,1,1,1,1,1,1,1,1,1,1,1,1,1,1,0,0,1,1
1,1,1,1,1,2,2,1,1,1,1,1,1,1,1,1,1,1,1,1,1,1,1,1,1,1,1,1,1,1,1,1,1,1,1,1,1,1,1,1,1,1,1,1,1,1,1,1,0,0,0,1
1,1,1,1,2,2,2,1,1,1,1,1,1,1,1,1,1,1,1,1,1,1,1,1,1,1,1,1,1,1,1,1,1,1,1,1,1,1,1,1,1,1,1,1,1,1,1,1,0,0,1,1
1,1,1,1,2,2,2,1,1,1,1,1,1,1,1,1,1,1,1,1,1,1,1,1,1,1,1,1,1,1,1,1,1,1,1,1,1,1,1,1,1,1,1,1,1,1,1,1,0,1,1,1
1,1,1,1,2,2,2,1,1,1,1,1,1,1,1,1,1,1,1,3,3,1,1,1,1,1,1,1,1,1,1,1,1,1,1,1,1,1,1,1,1,1,1,1,1,1,1,1,1,1,1,1
1,1,1,1,2,2,2,1,1,1,1,1,1,1,1,1,1,1,3,3,3,1,1,1,1,4,1,1,1,1,1,1,1,1,1,1,1,1,1,1,1,1,1,1,1,1,1,1,1,1,1,1
1,1,1,2,2,2,1,1,1,1,1,1,1,1,1,1,1,1,1,1,1,1,1,1,1,1,1,1,1,1,1,1,1,1,1,1,1,1,1,1,1,1,1,1,1,1,1,1,1,1,1,1
1,1,1,2,2,2,1,1,1,1,1,1,1,1,1,1,1,1,1,1,1,1,1,1,1,1,1,1,1,1,1,1,1,1,1,1,1,1,1,1,1,1,1,1,1,1,1,1,1,1,1,1
1,1,1,1,1,1,1,1,1,1,1,1,1,1,1,1,1,1,1,1,1,1,1,1,1,1,1,1,1,1,1,1,1,1,1,1,1,1,1,1,1,1,1,1,1,1,1,1,1,1,1,1
1,1,1,1,1,1,1,1,1,1,1,1,1,1,1,1,1,1,1,1,3,3,1,1,1,1,1,1,1,1,1,1,1,1,1,1,1,1,1,1,1,1,1,1,1,1,1,1,1,1,1,1
1,4,4,1,1,1,1,1,1,1,1,1,1,1,1,1,1,1,1,1,3,3,3,1,1,1,1,1,1,1,1,1,1,1,1,1,1,1,1,1,1,1,1,1,1,1,1,1,1,1,1,1
5,5,1,1,1,1,1,1,1,1,1,1,1,1,1,1,1,1,1,1,1,3,3,1,1,1,1,1,1,1,1,1,1,1,1,1,1,1,1,1,1,1,1,1,1,1,1,1,1,1,1,1
5,5,1,1,1,1,1,1,1,1,1,1,1,1,1,1,1,1,1,1,1,1,1,1,1,1,1,1,1,1,1,1,1,1,1,1,1,1,1,1,1,1,1,1,1,1,1,1,1,1,1,1
1,5,5,1,1,1,2,1,1,1,1,1,1,1,1,1,1,1,1,1,1,1,1,1,1,1,1,1,1,1,1,1,1,1,1,1,1,1,1,1,1,1,1,1,1,1,1,1,1,1,1,1
1,1,5,1,1,2,2,2,1,1,1,1,1,1,1,1,1,1,1,1,1,1,1,1,1,1,1,1,1,1,1,1,1,1,1,1,1,1,1,1,1,1,1,1,1,1,1,1,1,1,1,1
1,1,1,1,2,2,2,2,1,1,1,1,1,1,1,1,1,1,1,1,1,1,1,1,1,1,1,5,1,1,1,1,1,1,1,1,1,1,1,1,1,1,1,1,1,1,1,1,1,1,1,1
1,1,1,2,2,2,2,2,1,1,1,1,1,1,1,1,1,1,1,1,1,1,1,1,1,1,5,5,5,1,1,1,1,1,1,1,1,1,1,1,1,1,1,1,1,1,1,1,1,1,1,1
1,1,1,2,2,2,2,1,1,1,1,1,1,1,1,1,1,1,1,1,1,1,1,1,1,1,5,5,5,1,1,1,1,1,1,1,1,1,1,1,1,1,1,1,1,1,1,1,1,1,1,1
1,1,2,2,2,2,2,1,1,1,1,1,1,1,1,1,1,1,1,1,1,1,1,1,1,5,5,5,1,1,1,1,1,1,1,1,1,1,1,1,1,1,1,1,1,1,1,1,1,1,3,3
1,1,2,2,2,2,2,1,1,1,1,1,1,1,1,1,1,1,4,4,1,1,1,1,1,5,5,5,1,1,1,1,1,1,1,1,1,1,1,1,1,1,1,1,1,1,2,2,1,1,3,3
2,2,2,2,2,2,2,2,1,1,1,1,1,1,1,1,1,1,1,4,1,1,1,1,1,5,5,5,1,1,1,1,1,1,1,1,1,1,1,1,1,1,1,1,1,1,2,2,2,5,5,1
2,2,2,2,2,2,1,1,1,1,1,1,1,1,1,1,1,1,1,1,1,1,1,1,1,1,1,1,1,1,3,3,3,3,3,1,1,1,1,1,1,1,1,1,1,1,2,2,2,2,1,1
2,2,2,2,2,1,1,1,1,1,1,5,5,1,1,1,1,1,1,1,1,1,1,1,1,1,1,1,1,1,3,3,3,3,3,1,1,1,1,1,1,1,1,1,1,1,2,2,2,2,1,1
2,2,1,1,1,1,1,1,1,5,5,5,5,1,1,1,1,1,1,1,1,1,1,1,1,1,1,1,1,1,1,1,1,1,1,1,1,1,1,1,1,1,1,2,2,2,2,2,2,2,2,1
1,1,1,1,1,1,1,1,1,5,5,5,5,1,1,1,1,1,1,5,1,1,1,1,1,1,1,1,1,1,1,1,1,1,1,1,1,1,1,1,1,2,2,2,2,2,2,2,2,2,1,1
1,1,1,1,1,1,1,1,5,5,5,5,5,1,1,1,5,5,5,5,5,5,5,1,1,1,1,1,1,1,1,1,1,1,1,1,1,1,1,1,1,2,2,2,2,2,2,2,2,2,1,1
1,1,1,1,1,1,1,1,5,5,5,5,1,1,1,5,5,5,5,5,5,5,5,1,1,1,1,1,1,1,1,1,1,1,1,1,1,1,1,1,1,2,2,2,2,2,2,2,2,1,1,1
4,4,1,1,1,1,1,5,5,5,5,1,1,1,5,5,5,5,5,5,5,5,1,1,1,1,1,1,1,1,1,1,1,1,1,1,1,1,1,1,1,1,1,1,1,1,1,1,1,1,1,1
1,1,1,1,1,1,5,5,5,5,1,1,1,1,1,5,5,5,5,5,5,1,1,1,1,1,1,1,1,1,1,1,1,1,1,1,1,1,1,1,1,1,1,1,1,1,1,1,1,1,1,1
1,1,1,1,1,1,5,5,5,1,1,1,1,1,1,1,1,1,1,1,1,1,1,1,1,1,1,1,1,1,1,1,1,1,1,1,1,1,1,1,1,1,1,1,1,1,1,1,1,1,1,1
1,1,1,1,1,1,1,1,1,1,6,6,1,1,1,1,1,1,1,1,1,1,1,1,1,1,1,1,1,1,1,1,1,1,1,1,1,1,1,1,1,1,1,1,1,1,1,1,1,1,1,1
1,1,1,1,1,1,1,1,1,1,6,6,1,1,1,1,1,1,1,1,1,1,1,1,1,1,1,1,1,1,1,1,1,1,1,1,1,1,1,1,1,1,1,1,1,1,1,1,1,1,1,1
0,0,1,1,1,1,1,1,1,1,1,1,1,1,1,1,1,1,1,1,1,1,1,1,1,1,1,1,1,1,1,1,1,1,1,1,1,1,1,1,1,1,1,1,1,1,1,1,1,1,1,1
0,0,1,1,1,1,1,1,1,1,1,1,1,1,1,1,1,1,1,1,1,1,1,1,1,1,1,1,1,5,1,1,1,1,1,1,1,1,1,3,1,1,1,1,1,1,1,1,2,1,1,1
0,0,1,1,1,1,1,1,1,1,1,1,1,1,1,1,1,1,1,1,1,1,1,1,1,1,1,5,5,5,5,5,5,1,1,1,1,1,3,1,1,1,1,1,1,1,1,2,2,2,3,3
1,1,1,1,1,1,1,1,1,1,1,1,1,1,1,1,1,1,1,1,1,1,1,1,1,1,1,5,5,5,5,5,5,5,5,1,1,1,1,1,1,1,1,1,1,1,1,2,2,2,1,1
1,1,1,1,1,1,1,1,1,1,1,1,1,1,1,1,1,1,1,1,1,1,1,1,1,1,1,1,5,5,5,5,5,5,5,5,1,1,1,1,1,1,1,1,1,1,1,1,2,2,2,2
1,1,1,1,1,1,1,1,1,1,1,1,1,1,5,5,5,5,5,5,5,1,1,1,1,1,1,1,1,5,5,5,5,5,5,5,1,1,1,1,1,1,1,1,1,1,1,1,2,2,2,2
1,1,1,1,1,1,1,1,1,1,1,1,1,1,5,5,5,5,5,5,5,5,1,1,1,1,1,1,1,1,1,1,5,5,5,1,1,1,1,1,1,1,1,5,5,5,1,1,2,2,2,2
1,1,1,1,1,1,1,1,1,1,1,1,1,4,5,5,5,5,5,5,5,5,5,4,4,1,1,1,1,1,1,1,1,1,1,1,1,1,1,1,1,1,1,5,5,5,5,1,1,2,2,2
1,1,1,1,1,1,1,1,1,1,1,1,1,1,1,1,1,5,5,5,5,5,1,4,4,1,1,1,1,1,1,1,1,1,1,1,1,1,1,1,1,1,1,5,5,5,5,5,5,2,2,2
1,1,1,1,1,1,1,1,1,1,1,1,1,1,1,1,1,1,1,1,1,1,1,1,1,1,1,1,1,1,1,1,1,1,1,1,1,1,1,1,1,1,1,1,5,5,5,5,5,5,2,2
1,1,1,1,1,1,1,1,1,1,1,1,1,1,1,1,1,1,1,1,1,1,1,1,1,1,1,1,1,4,4,1,1,1,1,1,1,1,1,1,1,1,1,1,5,5,5,5,5,5,1,2
1,1,1,1,1,1,1,1,1,1,1,1,1,1,1,1,1,1,1,1,1,1,1,1,1,1,1,1,1,4,4,1,1,1,1,1,1,1,1,1,1,1,1,1,1,1,5,5,5,5,5,1
1,1,1,1,1,1,1,1,1,1,1,1,1,1,1,1,1,1,1,1,1,1,1,1,1,1,1,1,1,1,1,1,1,1,1,1,1,1,1,1,1,1,1,1,1,1,1,5,5,5,5,1
:endlayer
layer: 6
1,1,1,1,1,1,1,1,1,1,1,1,1,1,1,1,1,1,1,1,1,1,1,1,1,1,1,1,1,1,1,1,1,1,1,1,1,1,1,1,1,1,1,1,1,1,1,1,1,1,1,1
1,1,1,1,1,1,1,1,1,1,1,1,1,1,1,1,1,1,1,1,1,1,1,1,1,1,1,1,1,1,1,1,1,1,1,1,1,1,1,1,1,1,1,1,1,1,1,1,1,1,1,1
1,1,1,1,1,1,1,1,1,1,1,1,1,1,1,1,1,1,1,1,1,1,1,1,1,1,1,1,1,1,1,1,1,1,1,1,1,1,1,1,1,1,1,1,1,1,1,1,1,1,1,1
1,1,1,1,1,1,1,1,1,1,1,1,1,1,1,1,1,1,1,1,1,1,1,1,1,1,1,1,1,1,1,1,1,1,1,1,1,1,1,1,1,1,1,1,1,1,1,1,1,1,1,1
1,1,1,1,1,1,1,1,1,1,1,1,1,1,1,1,1,1,1,1,1,1,1,1,1,1,1,1,1,1,1,1,1,1,1,1,1,1,1,1,1,1,1,1,1,1,1,1,1,1,1,1
1,1,1,1,1,7,7,7,7,7,7,7,7,7,7,7,7,7,7,7,7,7,7,7,7,7,7,7,7,7,7,7,7,7,7,7,7,7,7,7,7,7,7,7,7,7,7,1,1,1,1,0
1,1,1,1,1,7,7,7,7,7,7,7,7,7,7,7,7,7,7,7,7,7,7,7,7,7,7,7,7,7,7,7,7,7,7,7,7,7,7,7,7,7,7,7,7,7,7,1,0,0,0,0
1,1,1,1,2,7,7,7,7,7,7,7,7,7,7,7,7,7,7,7,7,7,7,7,7,7,7,7,7,7,7,7,7,7,7,7,7,7,7,7,7,7,7,7,7,7,7,1,0,0,0,0
1,1,1,1,2,7,7,7,7,7,7,7,7,7,7,7,7,7,7,7,7,7,7,7,7,7,7,7,7,7,7,7,7,7,7,7,7,7,7,7,7,7,7,7,7,7,7,1,0,0,0,0
1,1,1,2,2,7,7,7,7,7,7,7,7,7,7,7,7,7,7,7,7,7,7,7,7,7,7,7,7,7,7,7,7,7,7,7,7,7,7,7,7,7,7,7,7,7,7,1,0,0,1,1
1,1,1,1,2,7,7,7,7,7,7,7,7,7,7,7,7,7,7,7,7,7,7,7,7,7,7,7,7,7,7,7,7,7,7,7,7,7,7,7,7,7,7,7,7,7,7,1,1,1,1,1
1,1,1,1,2,7,7,7,7,7,7,7,7,7,7,7,7,7,7,7,7,7,7,7,7,7,7,7,7,7,7,7,7,7,7,7,7,7,7,7,7,7,7,7,7,7,7,1,1,1,1,1
1,1,5,2,2,7,7,7,7,7,7,7,7,7,7,7,7,7,7,7,7,7,7,7,7,7,7,7,7,7,7,7,7,7,7,7,7,7,7,7,7,7,7,7,7,7,7,1,1,1,1,1
5,5,5,2,2,7,7,7,7,7,7,7,7,7,7,7,7,7,7,7,7,7,7,7,7,7,7,7,7,7,7,7,7,7,7,7,7,7,7,7,7,7,7,7,7,7,7,1,1,1,1,1
5,5,5,1,1,7,7,7,7,7,7,7,7,7,7,7,7,7,7,7,7,7,7,7,7,7,7,7,7,7,7,7,7,7,7,7,7,7,7,7,7,7,7,7,7,7,7,1,1,1,1,1
5,5,1,1,1,7,7,7,7,7,7,7,7,7,7,7,7,7,7,7,7,7,7,7,7,7,7,7,7,7,7,7,7,7,7,7,7,7,7,7,7,7,7,7,7,7,7,1,1,1,1,1
5,4,4,1,1,7,7,7,7,7,7,7,7,7,7,7,7,7,7,7,7,7,7,7,7,7,7,7,7,7,7,7,7,7,7,7,7,7,7,7,7,7,7,7,7,7,7,1,1,1,1,1
1,4,4,1,1,7,7,7,7,7,7,7,7,7,7,7,7,7,7,7,7,7,7,7,7,7,7,7,7,7,7,7,7,7,7,7,7,7,7,7,7,7,7,7,7,7,7,1,1,1,1,1
1,1,1,1,1,7,7,7,7,7,7,7,7,7,7,7,7,7,7,7,7,7,7,7,7,7,7,7,7,7,7,7,7,7,7,7,7,7,7,7,7,7,7,7,7,7,7,1,1,1,1,1
1,1,1,1,1,7,7,7,7,7,7,7,7,7,7,7,7,7,7,7,7,7,7,7,7,7,7,7,7,7,7,7,7,7,7,7,7,7,7,7,7,7,7,7,7,7,7,1,1,1,1,1
1,1,4,1,1,7,7,7,7,7,7,7,7,7,7,7,7,7,7,7,7,7,7,7,7,7,7,7,7,7,7,7,7,7,7,7,7,7,7,7,7,7,7,7,7,7,7,1,1,1,1,1
1,1,1,1,1,7,7,7,7,7,7,7,7,7,7,7,7,7,7,7,7,7,7,7,7,7,7,7,7,7,7,7,7,7,7,7,7,7,7,7,7,7,7,7,7,7,7,1,1,1,1,1
1,1,1,1,2,7,7,7,7,7,7,7,7,7,7,7,7,7,7,7,7,7,7,7,7,7,7,7,7,7,7,7,7,7,7,7,7,7,7,7,7,7,7,7,7,7,7,1,1,1,1,1
1,1,1,2,2,7,7,7,7,7,7,7,7,7,7,7,7,7,7,7,7,7,7,7,7,7,7,7,7,7,7,7,7,7,7,7,7,7,7,7,7,7,7,7,7,7,7,1,1,1,1,1
1,1,1,2,2,7,7,7,7,7,7,7,7,7,7,7,7,7,7,7,7,7,7,7,7,7,7,7,7,7,7,7,7,7,7,7,7,7,7,7,7,7,7,7,7,7,7,2,5,5,5,3
1,1,1,2,2,7,7,7,7,7,7,7,7,7,7,7,7,7,7,7,7,7,7,7,7,7,7,7,7,7,7,7,7,7,7,7,7,7,7,7,7,7,7,7,7,7,7,2,2,5,5,5
1,1,2,2,2,7,7,7,7,7,7,7,7,7,7,7,7,7,7,7,7,7,7,7,7,7,7,7,7,7,7,7,7,7,7,7,7,7,7,7,7,7,7,7,7,7,7,2,2,2,5,5
1,2,2,2,2,7,7,7,7,7,7,7,7,7,7,7,7,7,7,7,7,7,7,7,7,7,7,7,7,7,7,7,7,7,7,7,7,7,7,7,7,7,7,7,7,7,7,2,2,2,5,5
1,2,1,2,1,7,7,7,7,7,7,7,7,7,7,7,7,7,7,7,7,7,7,7,7,7,7,7,7,7,7,7,7,7,7,7,7,7,7,7,7,7,7,7,7,7,7,2,2,2,2,1
1,1,1,1,1,7,7,7,7,7,7,7,7,7,7,7,7,7,7,7,7,7,7,7,7,7,7,7,7,7,7,7,7,7,7,7,7,7,7,7,7,7,7,7,7,7,7,2,2,2,2,1
1,1,1,1,1,7,7,7,7,7,7,7,7,7,7,7,7,7,7,7,7,7,7,7,7,7,7,7,7,7,7,7,7,7,7,7,7,7,7,7,7,7,7,7,7,7,7,2,2,2,2,1
1,1,1,1,1,7,7,7,7,7,7,7,7,7,7,7,7,7,7,7,7,7,7,7,7,7,7,7,7,7,7,7,7,7,7,7,7,7,7,7,7,7,7,7,7,7,7,2,2,2,2,1
1,1,1,1,1,7,7,7,7,7,7,7,7,7,7,7,7,7,7,7,7,7,7,7,7,7,7,7,7,7,7,7,7,7,7,7,7,7,7,7,7,7,7,7,7,7,7,2,2,2,2,1
1,1,1,1,1,7,7,7,7,7,7,7,7,7,7,7,7,7,7,7,7,7,7,7,7,7,7,7,7,7,7,7,7,7,7,7,7,7,7,7,7,7,7,7,7,7,7,1,1,1,1,1
1,1,1,1,1,7,7,7,7,7,7,7,7,7,7,7,7,7,7,7,7,7,7,7,7,7,7,7,7,7,7,7,7,7,7,7,7,7,7,7,7,7,7,7,7,7,7,1,1,1,1,1
1,1,1,0,0,7,7,7,7,7,7,7,7,7,7,7,7,7,7,7,7,7,7,7,7,7,7,7,7,7,7,7,7,7,7,7,7,7,7,7,7,7,7,7,7,7,7,1,1,1,1,1
1,1,0,0,0,7,7,7,7,7,8,8,7,7,7,7,7,7,7,7,7,7,7,7,7,7,7,7,7,7,7,7,7,7,7,7,7,7,7,7,7,7,7,7,7,7,7,1,1,1,1,1
0,0,0,0,0,7,7,7,7,7,8,8,7,7,7,7,7,7,7,7,7,7,7,7,7,7,7,7,7,7,7,7,7,7,7,7,7,7,7,7,7,7,7,7,7,7,7,1,1,1,1,1
0,0,0,0,0,7,7,7,7,7,7,7,7,7,7,7,7,7,7,7,7,7,7,7,7,7,7,7,7,7,7,7,7,7,7,7,7,7,7,7,7,7,7,7,7,7,7,1,1,1,1,1
0,0,0,0,1,7,7,7,7,7,7,7,7,7,7,7,7,7,7,7,7,7,7,7,7,7,7,7,7,7,7,7,7,7,7,7,7,7,7,7,7,7,7,7,7,7,7,1,1,1,1,1
0,0,1,1,1,7,7,7,7,7,7,7,7,7,7,7,7,7,7,7,7,7,7,7,7,7,7,7,7,7,7,7,7,7,7,7,7,7,7,7,7,7,7,7,7,7,7,1,1,1,3,3
0,1,1,1,1,7,7,7,7,7,7,7,7,7,7,7,7,7,7,7,7,7,7,7,7,7,7,7,7,7,7,7,7,7,7,7,7,7,7,7,7,7,7,7,7,7,7,1,1,1,1,1
1,1,1,1,1,7,7,7,7,7,7,7,7,7,7,7,7,7,7,7,7,7,7,7,7,7,7,7,7,7,7,7,7,7,7,7,7,7,7,7,7,7,7,7,7,7,7,1,1,2,2,1
1,1,1,1,1,7,7,7,7,7,7,7,7,7,7,7,7,7,7,7,7,7,7,7,7,7,7,7,7,7,7,7,7,7,7,7,7,7,7,7,7,7,7,7,7,7,7,1,2,2,2,1
1,1,1,1,1,7,7,7,7,7,7,7,7,7,7,7,7,7,7,7,7,7,7,7,7,7,7,7,7,7,7,7,7,7,7,7,7,7,7,7,7,7,7,7,7,7,7,1,1,2,2,2
1,1,1,1,1,7,7,7,7,7,7,7,7,7,7,7,7,7,7,7,7,7,7,7,7,7,7,7,7,7,7,7,7,7,7,7,7,7,7,7,7,7,7,7,7,7,7,1,1,2,2,2
1,1,1,1,1,7,7,7,7,7,7,7,7,7,7,7,7,7,7,7,7,7,7,7,7,7,7,7,7,7,7,7,7,7,7,7,7,7,7,7,7,7,7,7,7,7,7,5,1,1,2,2
1,1,1,1,1,1,1,1,1,1,1,1,1,1,1,1,1,1,1,1,1,1,1,1,1,1,1,1,1,1,1,1,1,1,1,1,1,1,1,1,1,1,1,1,5,5,5,5,5,5,1,2
1,1,1,1,1,1,1,1,1,1,1,1,1,1,1,1,1,1,1,1,1,1,1,1,1,1,1,1,1,4,1,1,1,1,1,1,1,1,3,3,1,1,1,1,1,5,5,5,5,5,1,1
1,1,1,1,1,1,1,1,1,1,1,1,1,1,1,1,1,1,1,1,1,1,1,1,1,1,1,1,1,1,1,1,1,1,1,1,1,1,3,3,3,1,1,1,1,1,5,5,5,5,5,1
1,1,1,1,1,1,1,1,1,1,1,1,1,1,1,1,1,1,1,1,1,1,1,1,1,1,1,1,1,1,1,1,1,1,1,1,1,1,1,1,3,1,1,1,1,1,1,5,5,5,5,1
:endlayer
layer: 7
1,1,1,1,1,1,1,1,1,1,1,1,1,1,1,1,1,1,1,1,1,1,1,1,1,1,1,1,1,1,1,1,1,1,1,1,1,1,1,1,1,1,1,1,1,1,1,1,1,1,1,1
1,1,1,1,1,1,1,1,1,1,1,1,1,1,1,1,1,1,1,1,1,1,1,1,1,1,1,1,1,1,1,1,1,1,1,1,1,1,1,1,1,1,1,1,1,1,1,1,1,1,1,1
1,1,1,1,1,1,1,1,1,1,1,1,1,1,1,1,1,1,1,1,1,1,1,1,1,1,1,1,1,1,1,1,1,1,1,1,1,1,1,1,4,1,1,1,1,1,1,1,1,1,1,1
1,1,1,1,1,1,1,1,1,1,1,1,1,1,1,1,1,1,1,1,1,1,1,1,1,1,1,1,1,1,1,1,1,1,1,1,1,1,1,1,1,1,1,1,1,1,1,1,1,1,1,0
1,1,1,1,1,1,2,2,1,1,1,1,1,1,1,1,1,1,1,1,1,1,1,1,1,1,1,1,1,1,1,1,1,1,1,1,1,1,1,1,1,1,1,1,1,1,1,1,1,1,1,0
1,1,1,1,1,7,7,7,7,7,7,7,7,7,7,7,7,7,7,7,7,7,7,7,7,7,7,7,7,7,7,7,7,7,7,7,7,7,7,7,7,7,7,7,7,7,7,1,1,1,1,0
1,1,1,1,1,7,7,7,7,7,7,7,7,7,7,7,7,7,7,7,7,7,7,0,0,0,7,7,7,7,7,7,7,7,7,7,7,7,7,7,7,7,7,7,7,7,7,1,0,0,0,0
1,1,1,1,2,7,7,7,7,7,7,7,7,7,7,7,7,7,7,7,7,7,7,0,0,0,7,7,7,7,7,7,7,7,7,7,7,7,7,7,7,7,7,7,7,7,7,1,0,0,0,0
1,1,1,1,2,7,7,7,0,0,72,10,10,10,0,0,56,7,11,7,0,0,0,0,44,0,11,7,7,0,0,0,10,10,10,0,0,0,0,12,0,17,0,0,7,7,7,1,0,0,0,0
1,1,1,1,2,7,7,7,0,0,0,10,69,10,63,59,0,7,7,7,0,0,0,0,0,0,7,7,7,0,38,0,10,10,10,0,0,0,0,12,0,0,0,9,7,7,7,1,1,1,1,1
1,1,1,1,2,7,7,7,0,78,73,10,10,10,0,0,0,7,7,7,0,0,47,0,0,0,7,7,10,40,0,33,10,10,10,0,0,0,24,12,0,18,0,0,7,7,7,1,1,1,1,1
1,1,5,5,2,7,7,7,80,0,0,11,7,10,0,0,0,10,10,10,0,49,0,7,7,11,11,7,10,0,39,0,7,11,7,0,0,0,10,10,10,7,7,10,7,7,7,1,1,1,1,1
5,2,5,5,1,7,7,7,0,0,0,7,11,7,0,0,0,10,53,10,0,0,0,7,7,11,7,7,7,0,0,0,7,7,7,0,0,0,10,10,10,7,10,10,7,7,7,1,1,1,1,1
5,2,2,5,1,7,7,7,0,0,0,7,10,7,0,0,0,10,10,10,12,12,12,7,7,7,7,7,7,12,12,12,7,7,7,0,0,0,10,10,10,11,7,11,7,7,7,1,1,1,1,1
2,5,5,5,1,7,7,7,0,0,0,10,10,10,0,0,0,11,7,7,0,0,0,7,10,7,0,0,0,0,0,0,0,0,0,0,0,0,0,0,0,0,0,0,7,7,7,1,1,1,1,1
2,5,5,1,1,7,7,7,0,0,0,10,70,10,0,0,0,7,7,7,0,0,48,7,7,7,0,0,0,0,0,0,0,0,0,0,0,0,0,0,0,0,0,0,7,7,7,1,1,1,1,1
5,5,1,1,1,7,7,7,0,0,0,10,10,10,0,0,0,7,11,11,0,0,0,10,7,7,0,0,0,0,0,0,0,0,0,0,0,0,0,0,0,0,0,0,7,7,7,1,1,1,1,1
5,5,4,1,1,7,7,7,0,0,0,0,0,0,0,0,0,10,10,10,0,0,0,0,0,0,0,0,0,0,0,0,7,7,7,0,0,0,7,7,11,19,0,0,7,7,7,1,1,1,1,1
1,1,1,1,1,7,7,7,0,0,0,0,0,0,0,0,57,10,10,10,0,0,0,0,0,0,0,0,0,0,0,0,7,11,10,0,0,0,7,7,7,12,12,12,7,7,7,1,1,1,1,1
1,1,1,1,1,7,7,7,0,0,0,0,0,0,0,0,0,10,10,10,0,0,0,0,0,0,0,0,0,0,0,0,7,11,7,0,0,0,7,7,10,0,0,0,7,7,7,1,1,1,1,1
1,1,4,4,1,7,7,7,0,0,0,7,7,7,0,0,58,7,7,11,0,50,7,7,11,7,10,10,10,7,7,7,10,10,10,0,0,0,7,7,7,0,0,0,7,7,7,1,1,1,1,1
1,1,4,4,1,7,7,7,0,0,0,7,7,11,0,0,0,7,10,10,7,7,7,7,7,11,10,10,10,10,7,7,10,27,10,0,0,0,7,7,7,0,0,0,7,7,7,1,1,1,1,1
1,1,1,1,1,7,7,7,0,0,0,7,7,7,0,0,0,7,7,7,7,7,7,11,10,11,10,10,10,0,0,7,10,0,10,0,0,0,7,7,10,0,0,0,7,7,7,1,1,1,1,1
1,1,1,1,1,7,7,7,0,0,74,10,10,10,0,0,0,0,0,0,0,0,0,0,0,0,0,0,0,0,0,0,0,0,0,0,0,0,10,10,10,0,0,0,7,7,7,1,1,1,1,1
1,1,1,1,1,7,7,7,0,79,0,10,10,10,0,0,0,0,0,0,0,0,0,0,0,0,0,0,0,0,0,0,0,0,0,0,0,0,10,21,10,0,0,0,7,7,7,2,5,5,5,5
1,1,1,1,1,7,7,7,0,0,0,10,10,10,0,0,0,0,0,0,0,0,0,0,0,0,0,0,0,0,0,0,31,0,0,0,0,0,10,10,10,0,0,0,7,7,7,2,2,5,5,5
1,1,1,1,1,7,7,7,11,7,7,7,7,10,7,7,7,7,10,11,10,10,10,11,45,10,0,0,0,0,0,0,0,28,0,0,0,0,7,7,7,10,10,10,7,7,7,2,2,2,5,5
1,1,1,1,1,7,7,7,7,7,11,7,7,7,10,0,7,7,10,7,10,10,10,7,0,7,0,0,0,29,0,0,0,29,0,0,0,0,11,7,7,10,10,10,7,7,7,2,2,2,5,5
1,1,1,1,1,7,7,7,7,7,10,11,10,7,10,11,11,54,7,7,51,10,10,7,7,10,0,0,41,0,34,34,32,0,0,0,0,0,7,7,11,10,13,10,7,7,7,2,2,2,2,1
1,1,1,1,1,7,7,7,81,64,75,64,71,64,10,10,10,0,0,0,0,0,0,10,7,7,0,0,0,0,20,35,32,30,0,0,0,0,0,0,0,0,0,0,7,7,7,2,2,2,2,1
1,1,1,1,1,7,7,7,0,64,0,64,0,64,10,60,10,0,0,0,0,0,0,10,7,7,0,0,0,0,36,36,32,0,0,25,0,0,0,0,0,0,0,0,7,7,7,2,2,2,2,1
1,1,1,1,1,7,7,7,0,0,76,0,0,0,10,10,10,0,0,0,0,0,0,7,7,7,0,0,0,29,0,0,0,29,0,0,0,0,0,0,0,0,0,0,7,7,7,2,2,2,2,1
1,1,1,1,1,7,7,7,64,0,0,0,0,64,10,10,10,0,0,0,0,0,0,7,7,7,0,42,0,0,0,0,0,0,0,0,0,0,7,11,7,10,10,10,7,7,7,2,1,2,2,1
1,1,1,0,0,7,7,7,64,0,77,0,0,64,10,61,10,0,0,0,0,0,0,7,7,11,0,0,0,0,0,0,0,0,0,0,0,0,7,7,11,10,14,10,7,7,7,1,1,4,4,1
1,1,1,0,0,7,7,7,0,0,0,0,0,65,10,10,10,0,0,0,0,0,0,10,7,7,0,0,0,0,0,0,0,0,0,0,0,0,7,11,7,0,0,10,7,7,7,1,1,1,1,1
1,1,1,0,0,7,7,7,0,67,67,67,67,0,0,0,0,0,0,0,0,0,0,10,7,7,0,0,0,0,0,0,7,7,7,0,0,0,0,0,0,0,0,0,7,7,7,1,1,1,1,1
1,1,0,0,0,7,7,7,0,67,0,0,67,0,0,0,0,0,0,0,0,0,0,7,7,7,0,0,0,0,0,0,7,7,7,0,0,0,0,0,0,0,15,0,7,7,7,1,1,1,1,1
1,0,0,0,0,7,7,7,0,67,0,0,67,66,0,0,0,0,0,0,0,0,0,7,11,11,0,0,0,0,0,0,7,7,7,26,0,0,0,0,0,0,0,0,7,7,7,1,1,1,1,1
0,0,0,0,0,7,7,7,0,67,67,67,67,0,0,0,0,0,0,0,0,0,0,0,0,0,0,0,0,0,0,0,10,10,7,7,11,7,10,10,10,7,16,11,7,7,7,1,1,1,1,1
0,0,0,0,1,7,7,7,0,0,0,0,0,0,0,0,0,0,0,0,0,0,0,0,0,0,0,0,0,0,0,0,7,11,7,7,7,7,10,22,10,7,7,7,7,7,7,1,1,1,1,1
0,0,1,1,4,7,7,7,0,0,0,0,0,0,0,0,0,0,0,0,0,0,0,0,0,0,0,0,0,0,0,0,7,7,7,10,11,7,10,10,10,7,7,10,7,7,7,1,1,1,1,1
1,1,1,1,1,7,7,7,67,67,0,0,0,67,10,10,10,0,0,0,11,7,7,0,0,0,10,10,10,0,0,0,0,0,0,0,0,0,0,23,7,7,7,7,7,7,7,1,1,1,1,1
1,1,1,1,1,7,7,7,82,0,0,0,0,0,10,62,10,0,0,0,7,10,7,0,46,0,10,10,10,0,0,37,0,0,0,0,0,0,0,0,0,20,7,7,7,7,7,1,1,1,1,1
1,1,1,1,1,7,7,7,83,0,0,0,0,68,10,10,10,55,0,52,7,11,10,0,0,43,10,10,10,0,0,0,0,0,0,0,0,0,0,0,0,20,7,7,7,7,7,1,1,1,1,1
2,1,1,1,1,7,7,7,7,7,7,7,7,7,7,7,7,7,7,7,7,7,7,7,7,7,7,7,7,7,7,7,7,7,7,7,7,7,7,7,7,7,7,7,7,7,7,1,1,1,1,1
1,1,1,1,1,7,7,7,7,7,7,7,7,7,7,7,7,7,7,7,7,7,7,7,7,7,7,7,7,7,7,7,7,7,7,7,7,7,7,7,7,7,7,7,7,7,7,1,1,1,1,1
1,1,1,1,1,7,7,7,7,7,7,7,7,7,7,7,7,7,7,7,7,7,7,7,7,7,7,7,7,7,7,7,7,7,7,7,7,7,7,7,7,7,7,7,7,7,7,1,1,1,1,1
1,1,1,1,1,1,1,1,1,1,1,1,1,1,1,1,1,1,1,1,1,1,1,1,1,1,1,1,1,1,1,1,1,1,1,1,1,3,3,1,1,1,1,1,1,1,5,5,1,1,1,1
1,1,1,1,1,1,1,1,1,1,1,1,1,1,1,1,1,1,1,1,1,1,1,1,1,1,1,1,1,1,1,1,1,1,1,1,1,3,3,3,1,1,1,1,1,1,5,5,5,1,1,1
1,1,1,1,1,1,1,1,1,1,1,1,1,1,1,1,1,1,1,1,1,1,1,1,1,1,1,1,1,1,1,1,1,1,1,1,1,3,3,3,3,1,1,1,1,1,1,5,5,5,1,1
1,1,1,1,1,1,1,1,1,1,1,1,1,1,1,1,1,1,1,1,1,1,1,1,1,1,1,1,1,1,1,1,1,1,1,1,1,1,1,3,3,1,1,1,1,1,1,1,1,5,1,1
:endlayer
layer: 8
2,2,2,2,2,1,1,1,1,1,1,1,1,1,1,1,1,1,1,1,1,1,1,1,1,1,1,1,1,1,1,1,1,1,1,1,1,1,1,1,1,1,1,1,1,1,1,1,1,1,1,1
1,1,1,1,1,1,1,1,1,1,1,1,1,1,1,1,1,1,1,1,1,1,1,1,1,1,1,1,1,1,1,1,1,1,1,1,1,1,1,1,1,1,1,1,1,1,1,1,1,1,1,1
1,1,1,1,1,1,1,1,1,1,1,1,1,1,1,1,1,1,1,1,1,1,1,1,1,1,1,1,1,1,1,1,1,1,1,1,1,1,1,4,4,1,1,1,1,1,1,1,1,1,1,0
1,1,1,1,1,1,1,1,1,1,1,1,1,1,1,1,1,1,1,1,1,1,1,1,1,1,1,1,1,1,1,1,1,1,1,1,1,1,1,4,4,1,1,1,1,1,1,1,1,1,1,0
1,1,1,1,1,1,1,2,1,1,1,1,1,1,1,1,1,1,1,1,1,1,1,1,1,1,1,1,1,1,1,1,1,1,1,1,1,1,1,1,1,1,1,1,1,1,1,1,1,1,1,0
1,1,1,1,1,7,7,7,7,7,7,7,7,7,7,7,7,7,7,7,7,7,7,7,7,7,7,7,7,7,7,7,7,7,7,7,7,7,7,7,7,7,7,7,7,7,7,1,1,1,1,0
1,1,1,1,1,7,7,7,7,7,7,7,7,7,7,7,7,7,7,7,7,7,7,0,0,0,7,7,7,7,7,7,7,7,7,7,7,7,7,7,7,7,7,7,7,7,7,1,1,1,0,0
1,1,1,1,1,7,7,7,7,7,7,7,7,7,7,7,7,7,7,7,7,7,7,0,0,0,7,7,7,7,7,7,7,7,7,7,7,7,7,7,7,7,7,7,7,7,7,1,1,1,0,0
1,1,1,1,1,7,7,7,0,0,0,10,10,10,0,0,0,7,7,7,0,0,0,0,0,0,7,7,7,0,0,0,10,10,10,0,0,0,0,0,0,0,0,0,7,7,7,1,1,1,1,0
1,1,1,1,2,7,7,7,0,0,0,10,102,10,0,0,0,7,11,7,0,0,0,0,0,0,7,7,11,0,0,0,10,89,10,0,0,0,0,0,0,0,0,0,7,7,7,1,1,1,1,1
1,1,1,1,2,7,7,7,0,0,0,10,10,10,0,0,0,7,7,7,0,0,0,0,0,0,7,7,7,0,0,0,10,10,10,0,0,0,0,0,0,0,0,0,7,7,7,1,1,1,1,1
1,2,2,2,1,7,7,7,0,0,0,7,7,11,0,0,0,10,10,10,0,0,0,7,11,7,7,11,7,0,0,0,7,7,7,0,0,0,10,10,10,7,10,7,7,7,7,1,1,1,1,1
2,2,2,2,1,7,7,7,0,0,0,7,7,7,0,0,0,10,97,10,0,0,0,0,7,0,10,11,10,0,0,0,7,11,88,0,0,0,10,85,10,7,11,10,7,7,7,1,1,1,1,1
2,2,2,2,1,7,7,7,0,0,0,7,7,7,0,0,0,10,10,10,0,0,0,7,10,7,10,7,11,0,0,0,7,7,7,0,0,0,10,10,10,7,0,7,7,7,7,1,1,1,1,1
2,2,2,5,1,7,7,7,0,0,0,10,10,10,0,0,0,7,10,0,0,0,0,7,7,7,0,0,0,0,0,0,0,0,0,0,0,0,0,0,0,0,0,0,7,7,7,1,1,1,1,1
2,2,5,5,1,7,7,7,0,0,0,10,103,10,0,0,0,7,7,10,0,0,0,7,7,7,0,0,0,0,0,0,0,0,0,0,0,0,0,0,0,0,0,0,7,7,7,1,1,1,1,1
2,5,5,1,1,7,7,7,0,0,0,10,10,10,0,0,0,7,7,7,0,0,0,10,10,10,0,0,0,0,0,0,0,0,0,0,0,0,0,0,0,0,0,0,7,7,7,1,1,1,1,1
5,5,1,1,1,7,7,7,0,0,0,0,0,0,0,0,0,10,10,10,0,0,0,0,0,0,0,0,0,0,0,0,11,7,7,0,0,0,7,7,10,0,0,0,7,7,7,1,1,1,1,1
5,1,1,1,1,7,7,7,0,0,0,0,0,0,0,0,0,10,98,10,0,0,0,0,0,0,0,0,0,0,0,0,7,10,7,0,0,0,11,7,10,0,0,0,7,7,7,1,1,1,1,1
1,1,1,1,1,7,7,7,0,0,0,0,0,0,0,0,0,10,10,10,0,0,0,0,0,0,0,0,0,0,0,0,7,10,11,0,0,0,7,7,7,0,0,0,7,7,7,1,1,1,1,1
1,1,1,1,1,7,7,7,0,0,0,7,7,7,0,0,0,7,10,7,0,0,7,7,10,7,10,10,10,7,7,7,10,10,10,0,0,0,10,7,7,0,0,0,7,7,7,1,1,1,1,1
1,1,1,4,1,7,7,7,0,0,0,7,10,7,0,0,0,7,7,11,7,7,7,7,10,7,10,94,10,7,7,7,10,0,10,0,0,0,7,7,7,0,0,0,7,7,7,1,1,1,1,1
1,1,1,1,1,7,7,7,0,0,0,7,10,7,0,0,0,7,7,7,7,11,7,7,7,7,10,10,10,0,0,11,10,0,10,0,0,0,7,7,7,0,0,0,7,7,7,1,1,1,1,1
1,1,1,1,1,7,7,7,0,0,0,10,10,10,0,0,0,0,0,0,0,0,0,0,0,0,0,0,0,0,0,0,0,0,0,0,0,0,10,10,10,0,0,0,7,7,7,5,5,1,1,1
1,1,1,1,1,7,7,7,0,0,0,10,104,10,0,0,0,0,0,0,0,0,0,0,0,0,0,0,0,0,0,0,0,0,0,0,0,0,10,86,10,0,0,0,7,7,7,5,5,5,5,1
1,1,1,1,1,7,7,7,0,0,0,10,10,10,0,0,0,0,0,0,0,0,0,0,0,0,0,0,0,0,0,0,0,0,0,0,0,0,10,10,10,0,0,0,7,7,7,2,5,5,5,5
1,1,1,1,1,7,7,7,11,11,7,7,0,11,7,7,7,7,7,7,10,10,10,7,0,7,0,0,0,0,0,0,0,0,0,0,0,0,10,7,7,10,10,10,7,7,7,2,2,5,5,5
1,1,1,1,1,7,7,7,7,7,7,7,7,11,7,7,7,7,7,7,10,96,10,7,7,7,0,0,0,92,0,0,0,90,0,0,0,0,7,7,11,10,84,10,7,7,7,2,2,2,5,5
1,1,1,1,1,7,7,7,10,7,0,7,7,10,7,0,7,0,7,7,0,10,10,0,7,7,0,0,0,0,0,0,0,0,0,0,0,0,7,7,10,10,0,10,7,7,7,2,2,2,1,1
1,1,1,1,1,7,7,7,0,0,0,0,0,0,10,10,10,0,0,0,0,0,0,7,7,7,0,0,0,0,0,35,0,0,0,0,0,0,0,0,0,0,0,0,7,7,7,2,2,2,2,1
1,1,1,1,1,7,7,7,0,0,0,0,0,0,10,99,10,0,0,0,0,0,0,7,7,7,0,0,0,0,0,0,0,0,0,0,0,0,0,0,0,0,0,0,7,7,7,1,2,2,1,1
1,1,1,1,1,7,7,7,0,0,0,0,0,0,10,10,10,0,0,0,0,0,0,11,11,7,0,0,0,93,0,0,0,91,0,0,0,0,0,0,0,0,0,0,7,7,7,1,1,2,1,1
1,1,1,1,1,7,7,7,0,0,0,0,0,0,10,10,10,0,0,0,0,0,0,10,10,10,0,0,0,0,0,0,0,0,0,0,0,0,7,7,7,10,10,10,7,7,7,1,1,4,4,1
1,1,1,0,0,7,7,7,0,0,0,0,0,0,10,100,10,0,0,0,0,0,0,7,10,10,0,0,0,0,0,0,0,0,0,0,0,0,7,7,7,10,0,10,7,7,7,1,1,4,4,1
1,1,1,0,0,7,7,7,0,0,0,0,0,0,10,10,10,0,0,0,0,0,0,10,7,7,0,0,0,0,0,0,0,0,0,0,0,0,7,7,7,0,0,10,7,7,7,1,1,1,1,1
1,1,1,0,0,7,7,7,0,0,67,67,0,0,0,0,0,0,0,0,0,0,0,7,10,10,0,0,0,0,0,0,7,7,7,0,0,0,0,0,0,0,0,0,7,7,7,1,1,1,1,1
1,1,1,0,0,7,7,7,0,67,105,105,67,0,0,0,0,0,0,0,0,0,0,7,7,11,0,0,0,0,0,0,11,7,7,0,0,0,0,0,0,0,0,0,7,7,7,1,1,1,1,1
1,1,0,0,0,7,7,7,0,67,0,0,67,0,0,0,0,0,0,0,0,0,0,7,7,10,0,0,0,0,0,0,7,11,7,0,0,0,0,0,0,0,0,0,7,7,7,1,1,1,1,1
1,0,0,0,0,7,7,7,0,0,0,0,0,0,0,0,0,0,0,0,0,0,0,0,0,0,0,0,0,0,0,0,7,0,7,7,7,10,10,10,10,7,0,11,7,7,7,1,1,1,1,1
0,1,0,1,1,7,7,7,0,0,0,0,0,0,0,0,0,0,0,0,0,0,0,0,0,0,0,0,0,0,0,0,7,7,11,7,7,10,10,87,10,7,7,7,7,7,7,1,1,1,1,1
1,1,1,1,1,7,7,7,0,0,0,0,0,0,0,0,0,0,0,0,0,0,0,0,0,0,0,0,0,0,0,0,7,7,7,7,7,7,10,10,10,7,7,10,7,7,7,1,1,1,1,1
1,1,1,1,4,7,7,7,67,67,0,0,0,67,10,10,10,0,0,0,7,7,7,0,0,0,10,10,10,0,0,0,0,0,0,0,0,0,0,0,7,7,7,7,7,7,7,1,1,1,1,1
1,1,1,1,1,7,7,7,0,0,0,0,0,0,10,101,10,0,0,0,7,10,10,0,0,0,10,95,10,0,0,0,0,0,0,0,0,0,0,0,0,0,20,7,7,7,7,1,1,1,1,1
2,2,1,1,1,7,7,7,0,0,0,0,0,0,10,10,10,0,0,0,7,7,11,0,0,0,10,10,10,0,0,0,0,0,0,0,0,0,0,0,0,0,20,7,7,7,7,1,1,1,1,1
2,2,1,1,1,7,7,7,7,7,7,7,7,7,7,7,7,7,7,7,7,7,7,7,7,7,7,7,7,7,7,7,7,7,7,7,7,7,7,7,7,7,7,7,7,7,7,1,1,1,1,1
2,1,1,1,3,7,7,7,7,7,7,7,7,7,7,7,7,7,7,7,7,7,7,7,7,7,7,7,7,7,7,7,7,7,7,7,7,7,7,7,7,7,7,7,7,7,7,1,1,1,1,1
2,2,2,1,3,7,7,7,7,7,7,7,7,7,7,7,7,7,7,7,7,7,7,7,7,7,7,7,7,7,7,7,7,7,7,7,7,7,7,7,7,7,7,7,7,7,7,4,4,1,1,1
1,2,2,2,2,3,1,1,1,1,1,1,1,1,1,1,1,1,1,1,1,1,1,1,1,1,1,1,1,1,1,1,1,1,1,1,1,3,1,1,1,1,1,1,1,1,1,1,4,1,1,1
2,2,1,2,2,2,1,1,1,1,1,1,1,1,1,1,1,1,1,1,1,1,1,1,1,1,1,1,1,1,1,1,1,1,1,1,1,3,3,3,1,1,1,1,1,1,1,1,1,1,1,1
1,1,1,1,1,1,1,1,1,1,1,1,1,1,1,1,1,1,1,1,1,1,1,1,1,1,1,1,1,1,1,1,1,1,1,1,1,1,3,3,1,1,1,1,1,1,1,1,1,1,1,1
1,1,1,1,1,1,1,1,1,1,1,1,1,1,1,1,1,1,1,1,1,1,1,1,1,1,1,1,1,1,1,1,1,1,1,1,1,2,2,2,1,1,1,1,1,1,1,1,1,1,1,1
:endlayer
layer: 9
2,2,2,2,2,2,2,2,2,2,2,2,2,2,1,1,1,1,1,1,1,1,1,1,1,1,1,1,1,1,1,1,1,1,1,1,1,1,1,1,1,1,1,1,1,1,1,1,1,1,1,1
1,1,1,1,1,1,1,1,1,1,1,1,1,1,1,1,1,1,1,1,1,1,1,1,1,1,1,1,1,1,1,1,1,1,1,1,1,1,1,1,1,1,1,1,1,1,1,1,1,1,1,0
1,1,1,1,1,1,2,1,1,2,1,1,1,1,1,1,1,1,1,1,1,1,1,1,1,1,1,1,1,1,1,1,1,1,1,1,1,1,1,1,1,1,1,1,1,1,1,1,1,1,1,0
1,1,1,1,1,1,1,1,1,1,1,1,1,1,1,1,1,1,1,1,1,1,1,1,1,1,1,1,1,1,1,1,1,1,1,1,1,1,1,4,1,1,1,1,1,1,1,1,1,1,1,0
1,1,1,1,1,1,1,1,1,1,1,1,1,1,1,1,1,1,1,1,1,1,1,1,1,1,1,1,1,1,1,1,1,1,1,1,1,1,1,1,1,1,1,1,1,1,1,1,1,1,1,0
1,1,1,1,1,7,7,7,7,7,7,7,7,7,7,7,7,7,7,7,7,7,7,7,7,7,7,7,7,7,7,7,7,7,7,7,7,7,7,7,7,7,7,7,7,7,7,1,1,1,1,0
1,1,1,1,1,7,7,7,7,7,7,7,7,7,7,7,7,7,7,7,7,7,7,0,0,0,7,7,7,7,7,7,7,7,7,7,7,7,7,7,7,7,7,7,7,7,7,1,1,1,1,1
1,1,1,1,1,7,7,7,7,7,7,7,7,7,7,7,7,7,7,7,7,7,7,0,0,0,7,7,7,7,7,7,7,7,7,7,7,7,7,7,7,7,7,7,7,7,7,1,1,1,1,1
1,1,1,1,1,7,7,7,0,0,0,10,10,10,0,0,0,7,7,11,0,0,0,0,0,0,7,0,7,0,0,0,10,10,10,0,0,0,0,0,0,0,0,0,7,7,7,1,1,1,1,1
1,1,1,1,1,7,7,7,0,0,0,10,0,10,0,0,0,7,7,7,0,0,0,0,0,0,7,11,11,0,0,0,10,0,10,0,0,0,0,0,0,0,0,0,7,7,7,1,1,1,1,1
1,1,1,2,2,7,7,7,0,0,0,10,10,10,0,0,0,7,7,0,0,0,0,0,0,0,7,7,7,0,0,0,10,10,10,0,0,0,0,0,0,0,0,0,7,7,7,1,1,1,1,1
2,2,2,2,2,7,7,7,0,0,0,7,7,7,0,0,0,10,10,10,0,0,0,11,7,7,0,7,7,0,0,0,11,7,7,0,0,0,10,10,10,7,7,7,7,7,7,1,1,1,1,1
2,2,2,2,2,7,7,7,0,0,0,7,7,7,0,0,0,10,0,10,0,0,0,7,7,11,7,7,7,0,0,0,7,7,0,0,0,0,10,0,10,7,7,7,7,7,7,1,1,1,1,1
2,2,2,2,1,7,7,7,0,0,0,7,7,7,0,0,0,10,10,10,0,0,0,7,7,10,11,7,7,0,0,0,10,10,7,0,0,0,10,10,10,7,10,7,7,7,7,1,1,1,1,1
2,2,2,2,1,7,7,7,0,0,0,10,10,10,0,0,0,7,7,7,0,0,0,7,7,11,0,0,0,0,0,0,0,0,0,0,0,0,0,0,0,0,0,0,7,7,7,1,1,1,1,1
2,2,2,1,1,7,7,7,0,0,0,10,0,10,0,0,0,7,7,7,0,0,0,7,7,7,0,0,0,0,0,0,0,0,0,0,0,0,0,0,0,0,0,0,7,7,7,1,1,1,1,1
2,5,1,1,1,7,7,7,0,0,0,10,10,10,0,0,0,11,7,0,0,0,0,10,7,10,0,0,0,0,0,0,0,0,0,0,0,0,0,0,0,0,0,0,7,7,7,1,1,1,1,1
5,5,1,1,1,7,7,7,0,0,0,0,0,0,0,0,0,10,10,10,0,0,0,0,0,0,0,0,0,0,0,0,7,7,7,0,0,0,7,10,7,0,0,0,7,7,7,1,1,1,1,1
5,1,1,1,1,7,7,7,0,0,0,0,0,0,0,0,0,10,0,10,0,0,0,0,0,0,0,0,0,0,0,0,7,7,10,0,0,0,7,7,7,0,0,0,7,7,7,1,1,1,1,1
1,1,1,1,1,7,7,7,0,0,0,0,0,0,0,0,0,10,10,10,0,0,0,0,0,0,0,0,0,0,0,0,7,7,7,0,0,0,7,7,7,0,0,0,7,7,7,1,1,1,1,1
1,1,1,1,1,7,7,7,0,0,0,11,0,7,0,0,0,7,7,7,0,0,7,10,7,7,10,10,10,7,7,7,10,10,10,0,0,0,7,7,7,0,0,0,7,7,7,1,1,1,1,1
1,1,1,1,1,7,7,7,0,0,0,11,10,7,0,0,0,7,11,10,7,0,7,10,7,7,10,0,10,10,10,11,10,0,10,0,0,0,7,7,11,0,0,0,7,7,7,1,1,1,1,1
1,1,1,1,1,7,7,7,0,0,0,7,10,7,0,0,0,7,10,7,10,7,7,7,10,7,10,10,10,7,7,7,10,10,10,0,0,0,7,7,7,0,0,0,7,7,7,1,1,1,1,1
1,1,1,1,1,7,7,7,0,0,0,10,10,10,0,0,0,0,0,0,0,0,0,0,0,0,0,0,0,0,0,0,0,0,0,0,0,0,10,10,10,0,0,0,7,7,7,1,1,1,1,1
1,1,1,1,1,7,7,7,0,0,0,10,0,10,0,0,0,0,0,0,0,0,0,0,0,0,0,0,0,0,0,0,0,0,0,0,0,0,10,0,10,0,0,0,7,7,7,5,5,5,1,1
1,1,1,1,1,7,7,7,0,0,0,10,10,10,0,0,0,0,0,0,0,0,0,0,0,0,0,0,0,0,0,0,0,0,0,0,0,0,10,10,10,0,0,0,7,7,7,5,5,5,5,1
1,1,1,1,1,7,7,7,7,7,7,7,7,7,7,7,7,7,7,7,10,10,10,7,10,11,0,0,0,0,0,0,0,0,0,0,0,0,7,11,7,10,10,10,7,7,7,5,5,5,5,5
1,1,1,1,1,7,7,7,7,7,7,0,0,7,10,7,7,7,11,7,10,0,10,10,7,7,0,0,0,0,0,0,0,0,0,0,0,0,7,10,7,10,0,10,7,7,7,5,5,5,5,1
1,1,1,1,1,7,7,7,7,7,10,10,11,7,7,10,7,7,7,7,10,10,10,7,11,7,0,0,0,0,0,0,0,0,0,0,0,0,7,7,7,10,10,10,7,7,7,1,1,1,1,1
1,1,1,1,1,7,7,7,0,0,0,0,0,0,10,10,10,0,0,0,0,0,0,11,7,7,0,0,0,0,35,35,35,0,0,0,0,0,0,0,0,0,0,0,7,7,7,1,1,1,1,1
1,1,1,1,1,7,7,7,0,0,0,0,0,0,10,0,10,0,0,0,0,0,0,7,11,0,0,0,0,0,67,0,67,0,0,0,0,0,0,0,0,0,0,0,7,7,7,1,1,1,1,1
1,1,1,1,1,7,7,7,0,0,0,0,0,0,10,10,10,0,0,0,0,0,0,7,7,7,0,0,0,0,0,0,0,0,0,0,0,0,0,0,0,0,0,0,7,7,7,1,1,1,1,1
1,1,1,1,1,7,7,7,0,0,0,0,0,0,10,10,10,0,0,0,0,0,0,7,7,7,0,0,0,0,0,0,0,0,0,0,0,0,7,7,7,10,10,10,7,7,7,1,1,1,1,1
1,1,1,0,0,7,7,7,0,0,0,0,0,0,10,0,10,0,0,0,0,0,0,7,7,7,0,0,0,0,0,0,0,0,0,0,0,0,11,7,7,10,0,10,7,7,7,1,1,1,1,1
1,1,1,1,0,7,7,7,0,0,0,0,0,0,10,10,10,0,0,0,0,0,0,7,7,7,0,0,0,0,0,0,0,0,0,0,0,0,7,10,7,10,10,10,7,7,7,1,1,1,1,1
1,1,1,1,1,7,7,7,0,67,67,67,67,0,0,0,0,0,0,0,0,0,0,7,11,7,0,0,0,0,0,0,7,7,7,0,0,0,0,0,0,0,0,0,7,7,7,1,1,1,1,1
1,1,1,1,1,7,7,7,0,67,0,0,67,0,0,0,0,0,0,0,0,0,0,7,11,10,0,0,0,0,0,0,11,11,7,0,0,0,0,0,0,0,0,0,7,7,7,1,1,1,1,1
1,1,1,1,1,7,7,7,0,67,67,67,67,0,0,0,0,0,0,0,0,0,0,7,11,7,0,0,0,0,0,0,7,7,7,0,0,0,0,0,0,0,0,0,7,7,7,1,1,1,1,1
1,1,1,1,1,7,7,7,0,0,0,0,0,0,0,0,0,0,0,0,0,0,0,0,0,0,0,0,0,0,0,0,7,7,11,7,7,7,10,10,10,7,11,7,7,7,7,1,1,1,1,1
1,1,1,1,1,7,7,7,0,0,0,0,0,0,0,0,0,0,0,0,0,0,0,0,0,0,0,0,0,0,0,0,11,7,7,7,7,7,10,0,10,7,7,7,7,7,7,1,1,1,1,1
1,1,1,1,1,7,7,7,0,0,0,0,0,0,0,0,0,0,0,0,0,0,0,0,0,0,0,0,0,0,0,0,7,10,10,7,7,7,10,10,10,7,7,10,7,7,7,1,1,1,1,1
1,1,1,1,1,7,7,7,67,67,0,0,0,67,10,10,10,0,0,0,7,7,0,0,0,0,10,10,10,0,0,0,0,0,0,0,0,0,0,0,7,7,7,7,7,7,7,1,1,1,1,1
1,1,1,1,1,7,7,7,0,0,0,0,0,0,10,0,10,0,0,0,7,7,10,0,0,0,10,0,10,0,0,0,0,0,0,0,0,0,0,0,0,0,0,20,7,7,7,1,1,1,1,1
2,2,1,1,2,7,7,7,0,0,0,0,0,0,10,10,10,0,0,0,7,7,7,0,0,0,10,10,10,0,0,0,0,0,0,0,0,0,0,0,0,0,0,20,7,7,7,1,1,1,1,1
2,2,2,2,2,7,7,7,7,7,7,7,7,7,7,7,7,7,7,7,7,7,7,7,7,7,7,7,7,7,7,7,7,7,7,7,7,7,7,7,7,7,7,7,7,7,7,1,1,1,1,1
2,2,2,2,2,7,7,7,7,7,7,7,7,7,7,7,7,7,7,7,7,7,7,7,7,7,7,7,7,7,7,7,7,7,7,7,7,7,7,7,7,7,7,7,7,7,7,1,1,1,1,1
2,2,2,2,2,7,7,7,7,7,7,7,7,7,7,7,7,7,7,7,7,7,7,7,7,7,7,7,7,7,7,7,7,7,7,7,7,7,7,7,7,7,7,7,7,7,7,4,4,1,1,1
2,2,2,2,2,2,2,2,1,2,1,2,1,1,1,1,1,1,1,1,1,1,1,1,1,1,1,1,1,1,1,1,1,1,1,1,1,1,1,1,1,1,1,1,1,1,1,1,4,1,1,1
2,2,2,2,2,2,2,2,2,2,1,1,1,1,1,1,1,1,1,1,1,1,1,1,1,1,1,1,1,1,1,1,1,1,1,1,1,1,1,1,1,1,1,1,1,1,1,1,1,1,1,1
2,2,2,2,1,1,1,1,1,1,1,1,1,1,1,1,1,1,1,1,1,1,1,1,1,1,1,1,1,1,1,1,1,1,1,1,1,1,1,1,1,1,1,1,1,1,1,1,1,1,1,1
2,2,2,2,1,1,1,1,1,1,1,1,1,1,1,1,1,1,1,1,1,1,1,1,1,1,1,1,1,1,1,1,1,1,1,1,2,2,2,2,2,1,1,1,1,1,1,1,1,1,1,1
:endlayer
layer: 10
2,2,2,2,2,2,2,2,2,2,2,2,2,2,2,2,2,2,2,2,1,1,1,1,1,1,1,1,1,1,1,1,1,1,1,1,1,1,1,1,1,1,1,1,1,1,1,1,1,1,1,1
2,2,2,2,2,2,2,2,2,2,2,2,1,1,1,1,1,1,1,1,1,1,1,1,1,1,1,1,1,1,1,1,1,1,1,1,1,1,1,1,1,1,1,1,1,1,1,1,1,1,1,0
2,2,2,2,2,2,2,2,2,2,1,1,1,1,1,1,2,1,1,1,1,1,1,1,1,1,1,1,1,1,1,1,1,1,1,1,1,1,1,1,1,1,1,1,1,1,1,1,1,1,1,0
2,2,2,2,2,2,2,1,1,1,1,1,1,1,1,1,1,1,1,1,1,1,1,1,1,1,1,1,1,1,1,1,1,1,1,1,1,1,1,1,1,1,1,1,1,1,1,1,1,1,1,0
2,2,2,2,2,2,1,1,2,1,1,1,1,1,1,1,2,1,1,1,1,1,1,1,1,1,1,1,1,2,1,1,2,1,1,1,1,1,1,1,1,1,1,1,1,1,1,1,1,1,1,1
2,2,2,2,2,7,7,7,7,7,7,7,7,7,7,7,7,7,7,7,7,7,7,7,7,7,7,7,7,7,7,7,7,7,7,7,7,7,7,7,7,7,7,7,7,7,7,1,1,1,1,1
2,2,2,2,1,7,7,7,7,7,7,7,7,7,7,7,7,7,7,7,7,7,7,0,0,0,7,7,7,7,7,7,7,7,7,7,7,7,7,7,7,7,7,7,7,7,7,1,1,1,1,1
1,1,1,1,1,7,7,7,7,7,7,7,7,7,7,7,7,7,7,7,7,7,7,0,0,0,7,7,7,7,7,7,7,7,7,7,7,7,7,7,7,7,7,7,7,7,7,1,1,1,1,1
1,1,1,1,1,7,7,7,0,0,0,10,10,10,0,0,0,11,7,7,0,0,0,0,0,0,10,7,7,0,0,0,10,10,10,0,0,0,0,0,0,0,0,0,7,7,7,1,1,1,1,1
1,1,1,1,1,7,7,7,0,0,0,10,0,10,0,0,0,7,7,10,106,0,0,0,0,0,11,7,0,0,0,0,10,0,10,106,0,0,0,0,0,0,0,0,7,7,7,1,1,1,1,1
1,1,1,2,2,7,7,7,0,0,0,10,10,10,0,0,0,7,7,7,0,0,106,0,0,0,11,10,10,0,0,0,10,10,10,0,0,0,0,106,0,0,0,0,7,7,7,1,1,1,1,1
1,2,2,2,2,7,7,7,0,0,0,7,7,7,0,0,0,10,10,10,0,106,0,7,11,7,7,7,7,0,0,0,7,7,7,0,0,0,10,10,10,7,7,7,7,7,7,1,1,1,1,1
2,2,2,2,2,7,7,7,106,0,0,7,7,7,0,0,0,10,0,10,0,106,0,7,10,7,7,7,7,0,106,0,7,7,0,0,0,0,10,0,10,7,7,7,7,7,7,1,1,1,1,1
2,2,2,2,1,7,7,7,0,0,0,10,7,7,0,106,0,10,10,10,0,0,106,7,7,7,7,7,11,0,0,0,7,7,7,0,0,0,10,10,10,7,7,7,7,7,7,1,1,1,1,1
2,2,2,2,1,7,7,7,0,0,0,10,10,10,0,106,0,0,7,7,0,106,0,7,7,7,0,0,0,0,0,0,0,0,0,0,0,0,0,0,0,0,0,0,7,7,7,1,1,1,1,1
2,2,1,1,1,7,7,7,0,0,106,10,0,10,0,0,0,7,0,7,0,0,106,7,7,7,106,0,0,0,0,0,0,0,0,0,0,0,0,0,0,0,0,0,7,7,7,1,1,1,1,1
2,5,1,1,1,7,7,7,0,106,0,10,10,10,106,0,0,11,7,7,0,0,0,7,11,7,0,106,0,0,0,0,0,0,0,106,0,0,106,0,0,0,0,0,7,7,7,1,1,1,1,1
5,1,1,1,1,7,7,7,0,0,0,0,0,0,106,0,0,10,10,10,0,0,0,0,0,0,0,0,0,0,0,0,7,11,7,0,0,0,7,7,10,0,0,0,7,7,7,1,1,1,1,1
1,1,1,1,1,7,7,7,0,0,0,0,0,0,0,0,0,10,0,10,0,0,0,106,0,0,0,0,106,0,0,0,11,7,7,0,0,0,7,7,7,0,0,0,7,7,7,1,1,1,1,1
1,1,1,1,1,7,7,7,0,0,0,0,0,0,0,0,0,10,10,10,0,0,0,0,0,0,0,0,0,0,0,0,11,7,10,0,0,0,7,7,7,0,0,0,7,7,7,1,1,1,1,1
1,1,1,1,1,7,7,7,0,0,0,7,7,7,0,0,0,7,10,10,7,7,10,7,7,7,10,10,10,7,0,7,10,10,10,0,0,0,7,10,10,0,0,0,7,7,7,1,1,1,1,1
1,1,1,1,1,7,7,7,0,0,0,7,7,7,0,0,0,7,11,7,7,7,7,7,7,11,10,0,10,7,7,10,10,0,10,0,0,0,11,7,7,106,0,0,7,7,7,1,1,1,1,1
1,1,1,1,1,7,7,7,0,0,106,7,0,0,0,0,0,7,7,7,7,10,7,7,7,7,10,10,10,0,7,7,10,10,10,0,0,0,10,11,7,0,106,0,7,7,7,1,1,1,1,1
1,1,1,1,1,7,7,7,0,0,0,10,10,10,0,0,0,106,0,0,0,106,0,0,0,0,0,0,106,0,0,0,0,0,0,0,0,0,10,10,10,0,0,0,7,7,7,1,1,1,1,1
1,1,1,1,1,7,7,7,0,0,0,10,0,10,0,0,0,0,0,0,0,0,0,106,0,0,0,0,0,0,0,0,0,0,0,0,0,0,10,0,10,0,0,0,7,7,7,1,1,1,1,1
1,1,1,1,1,7,7,7,0,0,0,10,10,10,0,0,0,0,0,0,0,106,106,0,0,0,0,0,0,0,0,0,0,0,0,0,0,0,10,10,10,0,0,0,7,7,7,5,5,1,1,1
1,1,1,1,1,7,7,7,7,7,7,7,7,7,7,10,7,7,7,11,10,10,10,10,7,7,0,0,0,0,0,0,0,0,0,0,0,0,7,7,7,10,10,10,7,7,7,1,1,1,1,1
1,1,1,1,1,7,7,7,7,7,7,7,7,7,10,7,7,7,7,7,10,0,10,7,7,7,0,0,0,0,0,0,0,0,0,0,0,0,7,7,7,10,0,10,7,7,7,1,1,1,1,1
1,1,1,1,1,7,7,7,0,11,0,7,7,11,7,7,7,7,7,7,10,10,10,0,7,10,0,0,0,0,0,0,0,0,0,0,0,0,7,11,11,10,10,10,7,7,7,1,1,1,1,1
1,1,1,1,1,7,7,7,0,0,0,0,0,0,10,10,10,106,0,0,0,106,0,7,0,7,0,0,0,0,0,107,0,0,0,0,0,0,0,0,0,0,0,0,7,7,7,1,1,1,1,1
1,1,1,1,1,7,7,7,0,0,0,0,0,0,10,0,10,0,0,0,0,0,106,7,7,7,0,0,0,0,67,0,67,0,0,0,0,106,0,0,0,0,0,0,7,7,7,1,1,1,1,1
1,1,1,1,1,7,7,7,0,106,0,0,0,0,10,10,10,0,0,0,0,0,0,10,7,10,0,0,0,0,0,0,0,0,0,0,0,0,0,0,0,0,0,0,7,7,7,1,1,1,1,1
1,1,1,1,1,7,7,7,106,106,0,0,0,0,10,10,10,0,0,0,0,106,0,7,7,7,0,0,106,0,0,0,106,0,0,0,0,0,7,7,7,10,10,10,7,7,7,1,1,1,1,1
1,1,1,1,1,7,7,7,0,0,0,0,0,0,10,0,10,0,0,0,0,0,0,11,7,7,0,0,0,0,0,0,0,0,0,0,0,106,10,7,7,10,0,10,7,7,7,1,1,1,1,1
1,1,1,1,1,7,7,7,0,0,0,0,0,0,10,10,10,0,0,0,0,0,0,7,7,7,0,0,0,0,0,0,106,0,0,106,0,106,7,11,7,10,10,10,7,7,7,1,1,1,1,1
1,1,1,1,1,7,7,7,0,0,0,0,0,0,0,0,0,0,0,0,0,0,0,7,7,7,0,0,0,0,0,0,7,7,7,0,0,0,0,0,0,0,0,0,7,7,7,1,1,1,1,1
1,1,1,1,1,7,7,7,0,67,0,0,67,0,0,0,0,0,0,0,0,0,0,7,7,7,0,106,0,106,0,0,7,7,10,0,0,0,0,106,0,0,0,0,7,7,7,1,1,1,1,1
1,1,1,1,1,7,7,7,0,67,0,0,67,0,0,0,0,0,0,0,0,0,106,7,7,0,0,0,0,0,0,0,11,7,7,0,0,0,0,0,0,0,0,0,7,7,7,1,1,1,1,1
1,1,1,1,1,7,7,7,0,0,0,0,0,0,0,0,0,106,106,0,0,0,0,0,0,106,0,0,0,106,0,0,0,7,7,7,11,11,10,10,10,7,7,7,7,7,7,1,1,1,1,1
1,1,1,1,1,7,7,7,0,0,0,0,0,0,0,0,0,0,0,0,0,0,0,0,0,0,0,0,0,106,0,0,7,7,7,7,7,7,10,0,0,0,0,0,0,7,7,1,1,1,1,1
1,1,1,1,1,7,7,7,0,0,106,0,0,0,0,0,0,0,0,0,0,0,0,0,0,0,106,0,0,0,0,0,7,7,7,7,10,7,10,10,7,7,32,0,0,7,7,1,1,1,1,1
2,2,2,2,2,7,7,7,67,67,0,0,0,67,10,10,10,0,0,0,7,10,7,0,0,0,10,10,10,0,0,106,0,0,0,0,0,0,0,0,7,7,32,0,0,7,7,1,1,1,1,1
2,2,2,2,2,7,7,7,0,0,0,0,106,0,10,0,10,0,0,0,7,7,0,0,0,0,10,0,10,0,0,0,106,0,0,0,0,0,0,0,0,0,0,0,0,7,7,1,1,1,1,1
2,2,2,2,2,7,7,7,106,0,0,0,0,0,10,10,10,0,0,0,7,7,10,0,0,0,10,10,10,0,0,106,0,0,0,0,0,0,0,0,0,0,0,0,0,7,7,1,1,1,1,1
2,2,2,2,2,7,7,7,7,7,7,7,7,7,7,7,7,7,7,7,7,7,7,7,7,7,7,7,7,7,7,7,7,7,7,7,7,7,7,7,7,7,7,7,7,7,7,1,1,1,1,1
2,2,2,2,2,7,7,7,7,7,7,7,7,7,7,7,7,7,7,7,7,7,7,7,7,7,7,7,7,7,7,7,7,7,7,7,7,7,7,7,7,7,7,7,7,7,7,1,1,1,1,1
2,2,2,2,2,7,7,7,7,7,7,7,7,7,7,7,7,7,7,7,7,7,7,7,7,7,7,7,7,7,7,7,7,7,7,7,7,7,7,7,7,7,7,7,7,7,7,1,1,1,1,1
2,2,2,2,2,2,2,2,2,2,2,2,2,1,2,1,1,1,1,1,1,1,1,1,1,1,1,1,1,1,1,1,1,1,1,1,1,1,1,1,1,1,1,1,1,1,1,1,1,1,1,1
2,2,2,2,2,2,2,2,2,2,2,2,2,1,1,1,1,1,1,1,1,1,1,1,1,1,1,1,1,1,1,1,1,1,1,1,1,1,1,1,1,1,1,1,1,1,1,1,1,1,1,1
2,2,2,2,1,1,1,1,2,1,1,1,1,1,1,1,1,1,1,1,1,1,1,1,1,1,1,1,1,1,1,1,1,1,1,1,1,1,1,1,1,1,1,1,1,1,1,1,1,1,1,1
2,2,2,2,2,1,2,2,1,1,1,1,1,1,1,1,1,1,1,1,2,2,1,1,1,1,1,1,1,1,1,1,1,1,1,1,1,2,2,1,1,1,1,1,1,1,1,1,1,1,1,1
:endlayer
layer: 11
2,2,2,2,2,2,2,2,2,2,2,2,2,2,2,2,2,2,2,2,2,2,2,2,2,2,2,2,2,2,2,2,2,2,1,1,1,1,1,1,1,1,1,1,1,1,1,1,1,1,1,1
2,2,2,2,2,2,2,2,2,2,2,2,2,2,2,2,2,2,2,2,2,1,1,1,1,1,1,1,2,1,1,1,1,1,1,1,1,1,1,1,1,1,1,1,1,1,1,1,1,1,1,0
2,2,2,2,2,2,2,2,2,2,2,2,2,2,2,2,2,2,2,2,2,2,1,1,1,1,1,1,1,1,1,1,1,1,1,1,1,1,1,1,1,1,1,1,1,1,1,1,1,1,1,1
2,2,2,2,2,2,2,2,2,2,2,2,2,2,2,2,2,2,2,2,2,2,2,2,2,1,1,1,1,2,1,1,1,1,1,1,1,1,1,1,1,1,1,1,1,1,1,1,1,1,1,1
2,2,2,2,2,2,2,2,2,2,2,2,2,2,2,1,2,2,2,2,2,2,2,2,2,2,2,2,2,2,2,2,2,2,2,2,1,1,1,1,1,1,1,1,1,1,1,1,1,1,1,1
2,2,2,2,2,7,7,7,7,7,7,7,7,7,7,7,7,7,7,7,7,7,7,7,7,7,7,7,7,7,7,7,7,7,7,7,7,7,7,7,7,7,7,7,7,7,7,1,1,1,1,1
2,2,2,2,2,7,7,7,7,7,7,7,7,7,7,7,7,7,7,7,7,7,7,7,7,7,7,7,7,7,7,7,7,7,7,7,7,7,7,7,7,7,7,7,7,7,7,1,1,1,1,1
2,2,2,2,2,7,7,7,7,7,7,7,7,7,7,7,7,7,7,7,7,7,7,7,7,7,7,7,7,7,7,7,7,7,7,7,7,7,7,7,7,7,7,7,7,7,7,1,1,1,1,1
2,2,2,2,2,7,7,7,7,7,7,7,7,7,7,7,7,7,7,7,7,7,7,7,7,7,7,7,7,7,7,7,7,7,7,7,7,7,7,7,7,7,7,7,7,7,7,1,1,1,1,1
2,2,2,2,2,7,7,7,7,7,7,7,7,7,7,7,7,7,7,7,7,7,7,7,7,7,7,7,7,7,7,7,7,7,7,7,7,7,7,7,7,7,7,7,7,7,7,1,1,1,1,1
2,2,2,2,2,7,7,7,7,7,7,7,7,7,7,7,7,7,7,7,7,7,7,7,7,7,7,7,7,7,7,7,7,7,7,7,7,7,7,7,7,7,7,7,7,7,7,1,1,1,1,1
2,2,2,2,2,7,7,7,7,7,7,7,7,7,7,7,7,7,7,7,7,7,7,7,7,7,7,7,7,7,7,7,7,7,7,7,7,7,7,7,7,7,7,7,7,7,7,1,1,1,1,1
2,2,2,2,2,7,7,7,7,7,7,7,7,7,7,7,7,7,7,7,7,7,7,7,7,7,7,7,7,7,7,7,7,7,7,7,7,7,7,7,7,7,7,7,7,7,7,2,1,1,1,1
2,2,2,2,1,7,7,7,7,7,7,7,7,7,7,7,7,7,7,7,7,7,7,7,7,7,7,7,7,7,7,7,7,7,7,7,7,7,7,7,7,7,7,7,7,7,7,2,1,1,1,1
2,2,1,1,1,7,7,7,7,7,7,7,7,7,7,7,7,7,7,7,7,7,7,7,7,7,7,7,7,7,7,7,7,7,7,7,7,7,7,7,7,7,7,7,7,7,7,2,1,1,1,1
2,1,1,1,1,7,7,7,7,7,7,7,7,7,7,7,7,7,7,7,7,7,7,7,7,7,7,7,7,7,7,7,7,7,7,7,7,7,7,7,7,7,7,7,7,7,7,1,1,1,1,1
1,1,1,1,1,7,7,7,7,7,7,7,7,7,7,7,7,7,7,7,7,7,7,7,7,7,7,7,7,7,7,7,7,7,7,7,7,7,7,7,7,7,7,7,7,7,7,1,1,1,1,1
1,1,1,1,1,7,7,7,7,7,7,7,7,7,7,7,7,7,7,7,7,7,7,7,7,7,7,7,7,7,7,7,7,7,7,7,7,7,7,7,7,7,7,7,7,7,7,1,1,1,1,1
1,1,1,1,1,7,7,7,7,7,7,7,7,7,7,7,7,7,7,7,7,7,7,7,7,7,7,7,7,7,7,7,7,7,7,7,7,7,7,7,7,7,7,7,7,7,7,1,1,1,1,1
2,1,1,1,1,7,7,7,7,7,7,7,7,7,7,7,7,7,7,7,7,7,7,7,7,7,7,7,7,7,7,7,7,7,7,7,7,7,7,7,7,7,7,7,7,7,7,1,1,1,2,2
1,2,2,1,1,7,7,7,7,7,7,7,7,7,7,7,7,7,7,7,7,7,7,7,7,7,7,7,7,7,7,7,7,7,7,7,7,7,7,7,7,7,7,7,7,7,7,1,2,2,2,2
1,1,2,2,1,7,7,7,7,7,7,7,7,7,7,7,7,7,7,7,7,7,7,7,7,7,7,7,7,7,7,7,7,7,7,7,7,7,7,7,7,7,7,7,7,7,7,1,2,2,2,2
1,1,2,1,2,7,7,7,7,7,7,7,7,7,7,7,7,7,7,7,7,7,7,7,7,7,7,7,7,7,7,7,7,7,7,7,7,7,7,7,7,7,7,7,7,7,7,1,1,2,2,2
1,2,2,2,2,7,7,7,7,7,7,7,7,7,7,7,7,7,7,7,7,7,7,7,7,7,7,7,7,7,7,7,7,7,7,7,7,7,7,7,7,7,7,7,7,7,7,1,1,2,2,2
2,2,1,2,1,7,7,7,7,7,7,7,7,7,7,7,7,7,7,7,7,7,7,7,7,7,7,7,7,7,7,7,7,7,7,7,7,7,7,7,7,7,7,7,7,7,7,1,1,2,2,2
1,2,2,2,1,7,7,7,7,7,7,7,7,7,7,7,7,7,7,7,7,7,7,7,7,7,7,7,7,7,7,7,7,7,7,7,7,7,7,7,7,7,7,7,7,7,7,1,2,2,2,2
1,2,2,2,1,7,7,7,7,7,7,7,7,7,7,7,7,7,7,7,7,7,7,7,7,7,7,7,7,7,7,7,7,7,7,7,7,7,7,7,7,7,7,7,7,7,7,1,2,2,2,2
1,2,1,2,1,7,7,7,7,7,7,7,7,7,7,7,7,7,7,7,7,7,7,7,7,7,7,7,7,7,7,7,7,7,7,7,7,7,7,7,7,7,7,7,7,7,7,1,2,2,2,2
1,2,1,2,1,7,7,7,7,7,7,7,7,7,7,7,7,7,7,7,7,7,7,7,7,7,7,7,7,7,7,7,7,7,7,7,7,7,7,7,7,7,7,7,7,7,7,1,2,2,2,2
1,1,1,1,1,7,7,7,7,7,7,7,7,7,7,7,7,7,7,7,7,7,7,7,7,7,7,7,7,7,7,7,7,7,7,7,7,7,7,7,7,7,7,7,7,7,7,1,2,2,2,2
2,2,1,2,1,7,7,7,7,7,7,7,7,7,7,7,7,7,7,7,7,7,7,7,7,7,7,7,7,7,7,7,7,7,7,7,7,7,7,7,7,7,7,7,7,7,7,1,2,2,2,2
2,1,2,1,1,7,7,7,7,7,7,7,7,7,7,7,7,7,7,7,7,7,7,7,7,7,7,7,7,7,7,7,7,7,7,7,7,7,7,7,7,7,7,7,7,7,7,1,2,2,2,2
2,1,2,2,1,7,7,7,7,7,7,7,7,7,7,7,7,7,7,7,7,7,7,7,7,7,7,7,7,7,7,7,7,7,7,7,7,7,7,7,7,7,7,7,7,7,7,1,2,2,2,2
2,1,1,1,1,7,7,7,7,7,7,7,7,7,7,7,7,7,7,7,7,7,7,7,7,7,7,7,7,7,7,7,7,7,7,7,7,7,7,7,7,7,7,7,7,7,7,1,1,1,1,1
1,1,1,2,1,7,7,7,7,7,7,7,7,7,7,7,7,7,7,7,7,7,7,7,7,7,7,7,7,7,7,7,7,7,7,7,7,7,7,7,7,7,7,7,7,7,7,1,1,1,1,1
2,2,2,2,1,7,7,7,7,7,7,7,7,7,7,7,7,7,7,7,7,7,7,7,7,7,7,7,7,7,7,7,7,7,7,7,7,7,7,7,7,7,7,7,7,7,7,1,1,1,1,1
2,2,1,1,1,7,7,7,7,7,7,7,7,7,7,7,7,7,7,7,7,7,7,7,7,7,7,7,7,7,7,7,7,7,7,7,7,7,7,7,7,7,7,7,7,7,7,1,1,1,1,1
2,1,2,2,2,7,7,7,7,7,7,7,7,7,7,7,7,7,7,7,7,7,7,7,7,7,7,7,7,7,7,7,7,7,7,7,7,7,7,7,7,7,7,7,7,7,7,1,1,1,1,1
2,2,1,2,2,7,7,7,7,7,7,7,7,7,7,7,7,7,7,7,7,7,7,7,7,7,7,7,7,7,7,7,7,7,7,7,7,7,7,7,7,7,7,7,7,7,7,1,2,1,1,1
2,2,2,2,1,7,7,7,7,7,7,7,7,7,7,7,7,7,7,7,7,7,7,7,7,7,7,7,7,7,7,7,7,7,7,7,7,7,7,0,0,0,0,0,0,7,7,1,1,1,1,1
2,2,2,2,2,7,7,7,7,7,7,7,7,7,7,7,7,7,7,7,7,7,7,7,7,7,7,7,7,7,7,7,7,7,7,7,7,7,7,7,7,32,0,0,0,7,7,1,2,1,1,1
2,2,2,2,2,7,7,7,7,7,7,7,7,7,7,7,7,7,7,7,7,7,7,7,7,7,7,7,7,7,7,7,7,7,7,7,7,7,7,7,7,32,0,0,0,7,7,1,1,1,1,1
2,2,2,2,2,7,7,7,7,7,7,7,7,7,7,7,7,7,7,7,7,7,7,7,7,7,7,7,7,7,7,7,7,7,7,7,7,7,7,7,0,0,0,0,0,7,7,1,1,1,1,1
2,2,2,2,2,7,7,7,7,7,7,7,7,7,7,7,7,7,7,7,7,7,7,7,7,7,7,7,7,7,7,7,7,7,7,7,7,7,7,7,0,0,0,0,0,7,7,1,1,1,1,1
2,2,2,2,2,7,7,7,7,7,7,7,7,7,7,7,7,7,7,7,7,7,7,7,7,7,7,7,7,7,7,7,7,7,7,7,7,7,7,7,7,7,7,7,7,7,7,1,1,1,1,1
2,2,2,2,2,7,7,7,7,7,7,7,7,7,7,7,7,7,7,7,7,7,7,7,7,7,7,7,7,7,7,7,7,7,7,7,7,7,7,7,7,7,7,7,7,7,7,1,1,1,1,1
2,2,2,2,2,7,7,7,7,7,7,7,7,7,7,7,7,7,7,7,7,7,7,7,7,7,7,7,7,7,7,7,7,7,7,7,7,7,7,7,7,7,7,7,7,7,7,1,1,1,1,1
2,2,2,2,2,2,2,2,2,2,2,2,2,2,2,2,2,2,2,2,2,2,1,1,1,1,1,1,1,1,1,1,1,1,1,1,1,1,1,1,1,1,1,1,1,1,1,1,1,1,1,1
2,2,2,2,2,2,2,2,2,2,2,2,2,2,2,2,2,2,2,2,2,2,2,2,1,1,1,1,1,1,1,1,1,1,1,1,1,1,1,1,1,1,1,1,1,1,1,1,1,1,1,1
2,2,2,2,2,2,2,2,2,2,2,2,2,2,1,1,2,2,2,2,2,2,2,2,2,2,2,1,1,1,1,1,1,1,1,1,1,1,1,1,1,1,1,1,1,1,1,1,1,1,1,1
2,2,2,2,2,2,2,2,2,2,2,2,2,2,1,1,2,2,2,2,2,2,2,2,2,2,2,2,1,1,1,1,1,1,1,1,1,1,1,1,1,1,1,1,1,1,1,1,1,1,1,1
:endlayer
layer: 12
2,2,2,2,2,2,2,2,2,2,2,2,2,2,2,2,2,2,2,2,2,2,2,2,2,2,2,2,2,2,2,2,2,2,2,2,2,2,2,2,2,2,2,2,1,1,1,1,1,1,1,1
2,2,2,2,2,2,2,2,2,2,2,2,2,2,2,2,2,2,2,2,2,2,2,2,2,2,2,2,2,2,2,2,2,2,2,2,2,2,2,2,2,2,2,2,1,1,1,1,1,1,1,1
2,2,2,2,2,2,2,2,2,2,2,2,2,2,2,2,2,2,2,2,2,2,2,2,2,2,2,2,2,2,2,2,2,2,2,2,2,2,2,2,2,2,2,2,1,1,1,1,1,1,1,1
2,2,2,2,2,2,2,2,2,2,2,2,2,2,2,2,2,2,2,2,2,2,2,2,2,2,2,2,2,2,2,2,2,2,2,2,2,2,2,2,2,2,2,2,1,1,1,1,1,1,1,1
2,2,2,2,2,2,2,2,2,2,2,2,2,2,2,2,2,2,2,2,2,2,2,2,2,2,2,2,2,2,2,2,2,2,2,2,2,2,2,2,2,2,2,2,1,1,1,1,1,1,1,1
2,2,2,2,2,2,2,2,2,2,2,2,2,2,2,2,2,2,2,2,2,2,2,2,2,2,2,2,2,2,2,2,2,2,2,2,2,2,2,2,2,2,2,2,1,1,1,1,1,1,1,1
2,2,2,2,2,2,2,2,2,2,2,2,2,2,2,2,2,2,2,2,2,2,2,2,2,2,2,2,2,2,2,2,2,2,2,2,2,2,2,2,2,2,2,2,1,1,1,1,1,1,1,1
2,2,2,2,2,2,2,2,2,2,2,2,2,2,2,2,2,2,2,2,2,2,2,2,2,2,2,2,2,2,2,2,2,2,2,2,2,2,2,2,2,2,2,2,1,1,1,1,1,1,1,1
2,2,2,2,2,2,2,2,2,2,2,2,2,2,2,2,2,2,2,2,2,2,2,2,2,2,2,2,2,2,2,2,2,2,2,2,2,2,2,2,2,2,2,1,1,1,1,1,1,1,1,1
2,2,2,2,2,2,2,2,2,2,2,2,2,2,2,2,2,2,2,2,2,2,2,2,2,2,2,2,2,2,2,2,7,10,10,2,7,7,2,2,2,2,2,2,1,1,1,1,1,1,1,1
2,2,2,2,2,2,2,2,2,2,2,2,2,2,2,2,2,2,2,2,2,2,2,2,2,2,2,2,2,2,2,2,0,0,0,0,0,0,7,2,2,2,2,2,2,2,2,1,1,1,1,2
2,2,2,2,2,2,2,2,2,2,2,2,2,2,2,2,2,2,2,2,2,2,2,2,2,2,2,2,2,2,2,2,0,0,0,0,0,0,2,2,2,2,2,2,2,2,2,2,1,1,1,2
2,2,2,2,2,2,2,2,2,2,2,2,2,2,2,2,2,2,2,2,2,2,2,2,2,2,2,2,2,2,2,2,2,108,0,0,0,2,2,2,2,2,2,2,2,2,2,2,2,1,1,1
2,2,2,2,2,2,2,2,2,2,2,2,2,2,2,2,2,2,2,2,2,2,2,2,2,2,2,2,2,2,2,2,2,108,0,0,0,2,2,2,2,2,2,2,2,2,2,2,2,1,1,1
2,2,2,2,2,2,2,2,2,2,2,2,2,2,2,2,2,2,2,2,2,2,2,2,2,2,2,2,2,2,2,2,2,2,108,108,108,108,2,2,2,2,2,2,2,2,2,2,2,1,1,1
2,2,2,2,2,2,2,2,2,2,2,2,2,2,2,2,2,2,2,2,2,2,2,2,2,2,2,2,2,2,2,2,2,2,2,2,2,2,2,2,2,2,2,2,2,2,2,2,1,1,1,1
2,2,2,2,2,2,2,2,2,2,2,2,2,2,2,2,2,2,2,2,2,2,2,2,2,2,2,2,2,2,2,2,2,2,2,2,2,2,2,2,2,2,2,2,2,2,2,2,1,1,1,2
2,2,2,2,2,2,2,2,2,2,2,2,2,2,2,2,2,2,2,2,2,2,2,2,2,2,2,2,2,2,2,2,2,2,2,2,2,2,2,2,2,2,2,2,2,2,1,1,2,1,2,2
2,2,2,109,2,2,2,2,2,2,2,2,2,2,2,2,2,2,2,2,2,2,2,2,2,2,2,2,2,2,2,2,2,2,2,2,2,2,2,2,2,2,2,2,2,2,1,1,2,2,2,2
2,2,2,109,2,2,2,2,2,2,2,2,2,2,2,2,2,2,2,2,2,2,2,2,2,2,2,2,2,2,2,2,2,2,2,2,2,2,2,2,2,2,2,2,2,2,1,2,2,2,2,2
2,2,2,10,7,2,2,2,2,2,2,2,2,2,2,2,1,2,2,2,2,2,2,2,2,2,2,2,2,2,2,2,2,2,2,2,2,2,2,2,2,2,2,2,2,2,1,1,2,2,2,2
2,2,2,10,7,7,2,2,2,2,2,2,2,2,2,2,2,2,2,2,2,2,2,2,2,2,2,2,2,2,2,2,2,2,2,2,2,2,2,2,2,2,2,2,2,2,1,1,2,2,2,2
2,2,2,109,2,2,2,2,2,2,2,2,2,2,2,2,2,2,2,2,2,2,2,2,2,2,2,2,2,2,2,2,2,2,2,2,2,2,2,2,2,2,2,2,2,2,1,1,2,2,2,2
108,2,2,2,2,2,2,2,2,2,2,2,2,2,2,2,2,2,2,2,2,2,2,2,2,2,2,2,2,2,2,2,2,2,2,2,2,2,2,2,2,2,2,2,2,2,1,1,2,2,2,2
2,2,2,2,2,2,2,2,2,2,2,2,2,2,2,2,2,2,2,2,2,2,2,2,2,2,2,2,2,2,2,2,2,2,1,2,2,2,2,2,2,2,2,2,2,2,2,1,2,2,2,2
2,2,2,2,2,2,2,2,2,2,2,2,2,2,2,2,2,2,2,2,2,2,2,2,2,2,2,2,2,2,2,2,2,2,1,1,2,2,2,2,2,2,2,2,2,2,2,1,2,2,2,2
2,2,2,2,2,2,2,2,2,2,2,2,2,2,2,2,2,2,2,2,2,2,2,2,2,2,2,2,2,2,2,2,2,1,1,1,2,2,2,2,2,2,2,2,2,2,2,2,2,2,2,2
2,2,2,2,2,2,2,2,2,2,2,2,2,2,2,2,2,2,2,2,2,2,2,2,2,2,2,2,2,2,2,2,2,2,2,2,2,2,2,2,2,2,2,2,2,2,2,2,2,2,2,2
2,2,2,2,2,2,2,2,2,2,2,2,2,2,2,2,2,2,2,2,2,2,2,2,2,2,2,2,2,2,108,2,2,2,2,2,2,2,2,2,2,2,2,2,2,2,2,2,2,2,2,2
2,2,2,2,2,2,2,2,2,2,2,2,2,2,2,2,2,2,2,2,2,2,2,2,2,2,2,2,2,2,2,2,2,2,2,2,2,2,2,2,2,2,2,2,2,2,2,2,2,2,2,2
2,2,2,2,2,2,2,2,2,2,2,2,2,2,2,2,2,2,2,2,2,2,2,2,2,2,2,2,2,2,2,2,2,2,2,2,2,2,2,2,2,2,2,2,2,2,2,2,2,2,2,2
2,2,2,2,2,2,2,2,2,2,2,2,2,2,2,2,2,2,2,2,2,2,2,2,2,2,2,2,2,2,2,2,2,2,2,2,2,2,2,2,2,2,2,2,2,2,2,2,2,2,2,2
2,2,2,2,2,2,2,2,2,2,2,2,2,2,2,2,2,2,2,2,2,2,2,2,2,2,2,2,2,2,2,2,2,2,2,2,2,2,2,2,2,2,2,2,2,2,2,2,2,2,2,2
2,2,2,2,2,2,2,2,2,2,2,2,2,2,2,2,2,2,2,2,2,2,2,2,2,2,2,2,2,2,2,2,2,2,2,2,2,2,2,2,2,2,2,2,2,2,2,2,2,2,2,2
2,2,2,2,2,2,2,2,2,2,2,2,2,2,2,2,2,2,2,2,2,2,2,2,2,2,2,2,2,2,2,2,2,2,2,2,2,2,2,2,2,2,2,2,2,2,2,2,2,2,2,2
2,2,2,2,2,2,2,2,2,2,2,2,2,2,2,2,2,2,2,2,2,2,2,2,2,2,2,2,2,2,2,2,2,2,2,2,2,2,2,2,2,2,2,2,2,2,2,2,2,2,2,1
2,2,2,2,2,2,2,2,2,2,2,2,2,2,2,2,2,2,2,2,2,2,2,2,2,2,2,2,2,2,2,2,2,2,2,2,2,2,2,2,2,2,2,2,2,2,2,2,2,2,2,1
2,2,2,2,2,2,2,2,2,2,2,2,2,2,2,2,2,2,2,2,2,2,2,2,2,2,2,2,2,2,2,2,2,2,2,2,2,2,2,2,2,2,2,2,2,2,2,2,2,2,2,1
2,2,2,2,2,2,2,2,2,2,2,2,2,2,2,2,2,2,2,2,2,2,2,2,2,2,2,2,2,2,2,2,2,2,2,2,2,2,2,2,7,7,7,7,7,2,2,2,2,2,1,1
2,2,2,2,2,2,2,2,2,2,2,2,2,2,2,2,2,2,2,2,2,2,2,2,2,2,2,2,2,2,2,1,1,2,1,1,1,2,2,7,0,0,0,0,0,7,2,2,2,2,1,1
2,2,2,2,2,2,2,2,2,2,2,2,2,2,2,2,2,2,2,2,2,2,2,2,2,2,2,2,2,1,1,1,2,1,2,1,1,1,1,7,32,0,0,0,0,7,2,2,2,2,1,1
2,2,2,2,2,2,2,2,2,2,2,2,2,2,2,2,2,2,2,2,2,2,2,2,2,2,2,2,2,2,1,1,2,1,1,1,1,1,1,7,32,0,0,0,0,7,2,2,2,2,1,1
2,2,2,2,2,2,2,2,2,2,2,2,2,2,2,2,2,2,2,2,2,2,2,2,2,2,2,2,2,2,1,1,1,1,1,1,1,1,1,7,0,0,0,0,0,7,2,2,2,1,1,1
2,2,2,2,2,2,2,2,2,2,2,2,2,2,2,2,2,2,2,2,2,2,2,2,2,2,2,2,2,2,1,1,1,1,1,1,1,1,1,1,0,0,0,0,0,7,2,2,2,1,1,1
2,2,2,2,2,2,2,2,2,2,2,2,2,2,2,2,2,2,2,2,2,2,2,2,2,2,2,2,2,2,1,1,2,1,1,1,1,1,1,1,1,1,1,1,1,1,1,2,1,1,1,1
2,2,2,2,2,2,2,2,2,2,2,2,2,2,2,2,2,2,2,2,2,2,2,2,2,2,2,2,2,2,2,1,1,1,1,1,1,1,1,1,1,1,1,1,1,1,1,1,2,1,1,1
2,2,2,2,2,2,2,2,2,2,2,2,2,2,2,2,2,2,2,2,2,2,2,2,2,2,2,2,2,2,2,2,2,2,2,1,1,1,1,1,1,1,1,1,1,1,1,1,1,1,1,1
2,2,2,2,2,2,2,2,2,2,2,2,2,2,2,2,2,2,2,2,2,2,2,2,2,2,2,2,2,2,2,2,2,2,2,2,1,1,1,1,1,1,1,1,1,1,1,1,1,1,1,1
2,2,2,2,2,2,2,2,2,2,2,2,2,2,2,2,2,2,2,2,2,2,2,2,2,2,2,2,2,2,2,2,2,2,2,2,1,1,1,1,1,1,1,1,1,1,1,1,1,1,1,1
2,2,2,2,2,2,2,2,2,2,2,2,2,2,2,2,2,2,2,2,2,2,2,2,2,2,2,2,2,2,2,2,2,2,2,2,2,2,1,1,1,1,1,1,1,1,1,1,1,1,1,1
2,2,2,2,2,2,2,2,2,2,2,2,2,2,2,2,2,2,2,2,2,2,2,2,2,2,2,2,2,2,2,2,2,2,2,2,2,2,2,1,1,1,1,1,1,1,1,1,1,1,1,1
:endlayer
layer: 13
108,108,108,108,108,108,108,108,108,108,108,108,108,108,108,108,108,108,108,108,108,108,108,108,108,108,108,108,108,108,108,108,108,108,108,108,108,108,108,108,108,108,108,108,108,108,108,108,108,108,108,108
108,108,108,108,108,108,108,108,108,108,108,108,108,108,108,108,108,108,108,108,108,108,108,108,108,108,108,108,108,108,108,108,108,108,108,108,108,108,108,108,108,108,108,108,108,108,108,108,108,108,108,108
108,108,108,108,108,108,108,108,108,108,108,108,108,108,108,108,108,108,108,108,108,108,108,108,2,2,2,108,2,108,108,2,2,108,108,108,108,108,108,108,108,108,108,108,108,2,2,2,2,2,2,108
108,108,108,108,108,108,108,108,108,108,108,108,108,108,108,108,108,108,108,108,108,108,108,108,108,2,2,2,2,2,2,2,2,108,108,108,108,108,108,108,108,108,108,108,108,2,2,2,2,2,2,108
108,108,108,108,108,108,108,108,108,108,108,108,108,108,108,2,1,1,1,1,108,108,108,108,108,108,108,108,108,108,108,108,108,108,108,108,108,108,108,108,108,108,108,108,108,2,2,2,2,2,2,108
108,108,108,108,108,108,108,108,108,108,108,108,108,108,108,2,1,108,108,108,1,1,108,108,108,108,108,108,108,108,108,108,108,108,108,108,108,108,108,108,108,108,108,108,108,2,2,2,2,2,2,108
108,108,108,108,108,108,108,108,108,108,108,108,108,108,2,108,108,1,1,1,1,108,108,108,108,108,108,108,108,108,108,108,108,108,108,108,108,108,108,108,108,108,108,108,108,2,2,2,2,2,2,108
108,108,108,108,108,108,108,108,108,108,108,108,108,108,2,108,108,108,1,1,108,108,1,1,108,108,108,108,108,108,108,108,1,108,108,108,108,108,108,108,108,108,108,108,2,2,2,2,2,2,2,108
108,108,108,108,108,108,108,108,108,108,2,108,108,2,108,108,108,2,1,1,2,108,1,108,2,108,108,108,7,7,10,2,108,108,108,108,108,2,2,2,2,2,2,2,2,2,2,2,2,2,2,108
108,108,108,108,108,108,108,108,108,2,2,2,2,108,108,108,1,108,2,2,1,1,108,108,108,108,1,108,108,108,108,1,10,2,7,7,2,10,2,2,2,2,2,2,2,108,108,108,108,108,108,108
108,108,108,108,108,108,108,108,108,108,2,2,108,108,1,1,1,108,2,108,1,108,108,108,108,108,1,1,108,108,108,1,0,0,0,0,0,0,7,2,2,2,2,2,108,108,108,108,108,108,108,108
108,108,108,108,108,108,108,108,108,108,2,2,1,108,1,108,108,108,2,2,108,108,10,108,1,1,1,1,1,1,1,108,0,0,0,0,0,0,7,2,2,2,2,2,2,108,108,108,108,108,108,108
108,108,108,108,108,2,2,2,2,2,2,2,108,1,1,1,108,2,108,108,108,1,7,108,1,108,1,108,1,108,1,108,108,0,0,0,0,108,2,2,2,2,2,2,2,2,108,108,108,108,108,108
108,108,108,108,108,2,2,2,2,2,2,2,2,108,1,1,1,1,108,108,1,1,7,108,1,108,1,1,108,1,108,108,108,0,0,0,0,108,2,2,2,2,2,2,2,2,2,108,108,108,108,108
108,108,108,108,2,2,108,108,2,2,2,2,2,108,1,1,108,1,108,1,1,1,2,108,108,1,1,108,108,108,108,1,1,108,0,0,0,0,2,2,2,2,2,2,2,2,2,2,2,108,108,108
108,108,108,108,2,2,109,109,108,2,2,2,7,10,1,1,108,2,2,2,2,2,2,2,2,2,2,2,2,1,2,2,1,108,108,10,10,7,2,2,2,2,2,2,2,2,2,2,2,108,108,108
108,108,108,108,2,2,109,108,108,2,2,2,2,2,108,1,108,108,108,108,108,108,2,2,2,1,108,1,1,1,108,108,108,108,108,108,108,2,2,2,2,2,2,2,2,2,2,2,2,108,108,108
108,108,108,2,2,2,108,2,2,2,2,2,2,2,108,108,1,108,108,108,108,108,2,108,1,2,108,108,108,108,108,1,1,108,108,108,1,1,2,2,2,2,2,2,2,2,2,2,2,108,108,108
108,108,2,2,2,2,2,2,2,2,2,2,2,2,108,108,108,1,1,1,108,108,2,1,108,108,1,108,1,108,1,1,108,1,1,1,1,108,2,2,2,2,2,2,2,2,2,2,2,108,108,108
108,108,2,2,2,2,2,2,2,2,2,2,2,2,2,108,108,1,1,1,108,108,108,108,108,108,108,1,1,108,1,1,1,1,1,108,2,108,2,2,2,2,2,2,2,2,2,2,2,108,108,108
108,108,2,2,2,2,2,2,2,2,2,2,2,2,2,1,0,1,1,1,108,108,108,108,1,1,108,108,1,108,1,1,1,1,1,1,1,108,2,2,2,2,2,2,2,2,2,2,2,108,108,108
108,108,2,2,2,2,2,2,2,2,2,2,2,2,2,1,1,108,108,1,1,108,1,1,108,1,1,108,108,1,1,1,1,1,108,108,2,2,2,2,2,2,2,2,2,2,2,108,108,108,108,108
108,108,2,2,2,2,2,2,2,2,2,2,2,2,2,108,108,108,108,1,1,1,2,108,108,1,1,108,108,1,1,108,108,108,108,108,108,2,108,2,2,2,2,2,2,2,108,108,108,108,108,108
0,108,2,2,2,2,2,2,2,2,2,2,2,2,2,108,108,108,108,108,108,1,2,1,108,108,108,108,1,1,1,108,108,1,1,1,108,108,108,2,2,2,2,2,2,108,108,108,108,108,108,108
108,108,108,108,2,2,2,2,2,2,2,2,2,2,2,2,2,108,2,2,2,2,2,2,2,2,2,2,108,2,2,2,108,108,109,1,1,1,108,108,2,2,2,2,2,108,108,108,108,108,108,108
108,108,108,108,2,2,2,2,2,2,2,2,2,2,2,2,2,2,2,2,108,1,2,1,1,108,108,108,108,108,108,108,1,1,109,109,1,1,108,108,108,2,2,2,2,2,2,2,2,2,2,108
108,108,108,108,2,2,2,2,2,2,2,2,2,2,2,2,2,2,2,2,2,2,2,108,1,108,1,1,1,108,108,1,1,109,109,109,1,1,108,2,108,108,2,2,2,2,2,2,2,2,2,108
108,108,108,108,2,2,2,2,2,2,2,2,2,2,2,2,2,2,2,2,2,2,2,2,1,1,1,1,1,1,108,108,1,1,1,1,1,108,2,108,108,108,108,2,2,2,2,2,2,2,2,108
108,108,108,2,2,2,2,2,2,2,2,2,2,2,1,2,2,2,2,2,2,2,2,2,2,1,1,1,108,108,0,108,108,1,1,108,108,108,2,108,108,108,108,2,108,2,2,2,2,2,2,108
108,108,108,2,2,2,2,2,2,2,2,2,2,2,2,2,2,2,2,2,2,2,2,2,2,2,108,108,108,2,2,108,1,108,108,108,2,2,2,2,108,108,2,108,2,2,2,2,2,2,2,108
108,108,108,2,2,2,2,2,2,2,2,2,2,2,2,2,2,2,2,2,2,2,2,2,2,2,2,108,2,108,108,2,108,1,1,2,108,108,2,108,108,108,2,2,2,2,2,2,2,2,2,108
108,108,108,2,2,2,2,2,2,2,2,2,2,2,2,2,2,2,2,2,2,2,2,2,2,2,2,2,108,108,108,108,1,108,1,1,1,108,108,108,108,108,108,108,2,2,2,2,2,2,2,108
108,108,108,2,2,2,2,2,2,2,2,108,2,108,2,2,2,2,2,2,2,2,2,2,2,2,2,2,2,108,1,1,1,108,108,1,1,1,108,2,2,2,2,2,2,2,2,2,2,2,2,108
108,108,108,2,2,2,2,2,2,2,2,108,2,2,2,2,2,2,2,2,2,2,2,2,2,2,2,2,2,2,2,2,2,2,2,2,2,2,2,2,2,2,2,2,2,2,2,2,2,2,2,108
108,108,108,2,2,2,2,2,2,2,2,2,2,2,2,2,2,2,2,2,2,2,2,2,2,2,2,2,2,2,2,2,2,2,2,2,2,2,2,2,2,2,2,2,2,2,2,2,2,2,2,108
108,108,108,2,2,2,2,2,2,2,2,2,2,2,2,2,2,2,2,2,2,2,2,2,2,2,2,2,2,2,2,2,2,2,2,2,2,2,2,2,2,2,2,2,2,2,2,2,2,2,2,108
108,108,108,2,2,2,2,2,2,2,2,2,2,2,2,2,2,2,2,2,2,2,2,2,2,2,2,2,2,2,2,2,2,2,2,2,2,7,7,7,7,7,7,7,7,7,7,2,2,2,2,108
108,108,108,2,2,2,2,2,2,2,2,2,2,2,2,2,2,2,2,2,2,2,2,2,2,2,2,2,2,2,2,2,2,2,2,2,2,7,110,7,110,110,111,110,11,11,7,2,2,2,2,108
108,108,108,2,2,2,2,2,2,2,2,2,2,2,2,2,2,2,2,2,2,2,2,2,2,2,2,2,2,2,2,2,2,2,108,108,108,7,110,110,11,11,11,11,11,11,7,108,108,108,108,108
108,108,108,2,2,2,2,2,2,2,2,2,2,2,2,2,2,2,2,2,2,2,2,2,2,2,2,2,2,2,2,2,2,2,2,108,108,7,7,11,0,0,0,0,0,11,7,108,108,108,108,108
108,108,108,2,2,2,2,2,2,2,2,2,2,2,2,2,2,2,2,2,2,2,2,2,2,2,2,2,2,2,2,2,2,2,2,108,108,7,11,32,0,0,0,0,0,11,7,108,108,108,108,108
108,108,108,108,108,108,108,108,108,108,2,108,2,2,2,2,2,2,2,2,2,2,2,2,2,2,2,2,2,2,2,2,2,2,2,108,108,7,7,32,0,0,0,0,0,11,7,108,108,108,108,108
108,108,108,108,108,108,108,108,108,108,108,108,108,108,108,2,2,2,2,2,2,2,2,2,2,2,108,2,2,2,2,2,2,2,2,108,108,7,110,110,0,0,0,0,0,11,7,108,108,108,108,108
108,108,108,108,108,108,108,108,108,108,108,108,108,108,108,108,108,2,2,2,2,2,2,2,2,2,2,2,2,2,2,2,2,2,2,108,108,7,7,110,10,11,11,11,11,110,7,108,108,108,108,108
108,108,108,108,108,108,108,108,108,108,108,108,108,108,108,108,108,108,2,2,2,2,2,2,2,2,2,2,2,2,2,2,2,2,2,108,108,7,7,7,11,11,11,11,11,11,7,108,108,108,108,108
108,108,108,108,108,108,108,108,108,108,108,108,108,108,108,108,108,108,2,2,2,2,2,2,2,2,2,2,2,2,2,2,2,2,2,108,108,7,7,7,7,7,7,7,7,7,7,108,108,108,108,108
108,108,108,108,108,108,108,108,108,108,108,108,108,108,108,108,108,108,108,2,2,2,2,2,2,2,2,2,2,2,2,2,2,2,108,108,108,108,108,108,108,108,108,108,108,108,108,108,108,108,108,108
108,108,108,108,108,108,108,108,108,108,108,108,108,108,108,108,108,108,108,108,108,108,2,2,2,2,2,2,2,2,2,2,2,2,108,108,108,108,108,108,108,108,108,108,108,108,108,108,108,108,108,108
108,108,108,108,108,108,108,108,108,108,108,108,108,108,108,108,108,108,108,108,108,108,108,108,2,2,2,2,2,2,2,2,2,2,108,108,108,108,108,108,108,108,108,108,108,108,108,108,108,108,108,108
108,108,108,108,108,108,108,108,108,108,108,108,108,108,108,108,108,108,108,108,108,108,108,108,108,108,108,108,108,108,108,108,108,108,108,108,108,108,108,108,108,108,108,108,108,108,108,108,108,108,108,108
108,108,108,108,108,108,108,108,108,108,108,108,108,108,108,108,108,108,108,108,108,108,108,108,108,108,108,108,108,108,108,108,108,108,108,108,108,108,108,108,108,108,108,108,108,108,108,108,108,108,108,108
:endlayer
layer: 14
0,0,0,112,112,0,0,112,0,0,0,0,0,0,0,0,0,112,112,112,0,0,0,0,0,0,0,0,0,0,0,0,0,0,0,0,0,0,0,0,112,112,112,0,0,0,0,112,0,114,0,0
0,0,112,0,112,112,112,112,0,0,0,0,0,0,0,112,0,112,112,0,0,0,0,0,0,0,0,0,0,0,0,0,0,0,0,0,0,0,0,112,112,112,0,0,112,112,112,112,112,0,0,0
0,130,0,112,126,112,112,0,112,0,112,0,0,0,0,112,112,112,112,112,0,0,0,0,108,7,108,0,108,0,0,108,108,0,112,0,0,0,0,0,112,112,0,0,0,108,108,108,108,108,108,0
112,0,0,112,112,0,0,112,0,0,112,0,0,112,0,0,112,112,0,112,0,0,0,0,0,108,108,108,108,108,108,108,108,0,0,0,0,0,112,0,112,0,0,112,0,108,108,108,108,108,108,0
112,112,0,127,0,0,0,0,0,112,112,0,0,0,0,108,0,0,0,0,0,0,0,0,112,0,112,0,112,0,0,112,0,0,0,0,112,0,0,0,112,0,0,0,0,108,108,108,108,108,108,0
112,112,0,0,0,0,0,0,0,112,0,112,0,0,0,10,0,0,0,0,10,0,0,0,0,0,0,0,112,112,112,0,112,112,0,0,0,0,0,0,0,112,0,112,0,108,108,108,108,108,108,0
112,112,112,0,0,0,112,112,112,112,0,0,0,0,10,0,0,0,0,0,10,0,0,0,0,0,0,0,112,0,112,112,112,112,0,0,0,0,0,0,0,0,0,0,0,108,108,108,108,108,108,0
0,112,0,0,0,0,112,112,0,112,0,112,0,0,7,0,0,0,0,0,0,0,0,0,0,0,0,0,112,0,0,0,0,0,0,0,0,0,0,0,0,0,112,0,108,108,108,108,108,108,108,0
112,0,0,0,0,0,0,0,0,112,11,0,0,10,0,0,0,7,0,0,7,0,0,0,7,0,0,0,0,0,0,7,0,0,0,0,0,108,2,108,108,108,108,108,108,108,108,108,108,108,108,0
0,0,0,0,0,0,0,0,0,10,7,7,7,0,0,0,0,0,7,7,0,0,0,0,0,0,0,0,0,0,0,0,7,10,7,7,7,7,7,2,108,2,108,108,108,0,0,0,112,0,0,0
0,0,0,0,0,0,112,0,112,0,7,108,0,0,0,0,0,0,10,0,0,0,0,0,0,0,0,0,0,0,0,0,0,0,0,0,0,0,7,108,108,108,2,108,0,0,0,0,0,0,0,0
0,0,0,0,0,0,0,0,0,0,7,108,0,0,0,0,0,0,10,10,0,0,0,0,0,0,0,0,0,0,0,0,0,0,0,0,0,0,7,108,108,2,108,108,108,0,112,112,112,0,0,0
0,0,0,0,0,108,108,108,108,7,1,108,0,0,0,0,0,10,0,0,0,0,0,0,0,0,0,0,0,0,0,0,0,0,0,0,0,0,7,108,108,108,2,108,108,108,0,112,112,112,0,112
0,0,0,0,0,108,108,108,108,108,108,108,108,0,0,0,0,0,0,0,0,0,0,0,0,0,0,0,0,0,0,0,0,0,0,0,0,0,7,108,108,108,108,108,108,108,108,112,112,112,112,0
0,0,112,0,108,108,0,0,108,108,108,108,108,0,0,0,0,0,0,0,0,0,7,0,0,0,0,0,0,0,0,0,0,0,0,0,0,0,7,108,108,108,108,108,108,108,108,108,108,112,112,0
0,0,0,0,108,108,0,0,0,108,1,108,0,0,0,0,0,7,7,7,7,10,7,7,7,7,7,7,10,118,11,7,0,0,0,0,0,0,108,7,108,108,108,108,108,108,108,108,108,0,112,0
0,112,0,0,108,108,0,0,0,7,1,108,1,108,0,0,0,0,0,0,0,0,7,10,10,0,0,0,0,0,0,0,0,0,0,0,0,108,108,108,108,1,1,108,108,108,108,108,108,0,0,0
0,112,112,108,108,108,0,108,108,108,2,1,1,108,0,0,0,0,0,0,0,0,7,0,0,10,0,0,0,0,0,0,0,0,0,0,0,0,108,108,1,1,108,108,108,108,108,108,108,0,0,0
112,112,108,108,108,2,2,2,2,108,2,2,108,108,0,0,0,0,0,0,0,0,7,0,0,0,0,0,0,0,0,0,0,0,0,0,0,0,108,108,1,1,108,108,108,108,108,108,108,0,112,0
112,112,108,108,2,2,2,2,2,2,108,108,2,108,108,0,0,0,0,0,0,0,124,0,0,0,122,120,0,0,0,0,0,0,0,0,10,0,108,7,1,1,1,108,108,108,108,108,108,0,0,0
112,0,108,2,2,2,2,2,2,108,108,108,108,108,108,0,0,0,0,0,0,0,0,0,0,0,123,121,0,0,0,0,0,0,0,0,0,0,7,108,108,1,1,108,108,108,108,108,108,0,0,112
0,112,108,2,2,2,2,2,2,108,108,108,1,1,108,0,0,0,0,0,0,0,125,0,0,0,0,0,0,0,0,0,0,0,0,0,10,10,7,108,108,1,1,1,108,108,108,112,112,112,112,0
0,0,108,108,2,2,2,2,2,108,108,108,1,108,108,0,0,0,0,0,0,0,7,0,0,0,0,0,0,0,0,0,0,0,0,0,0,10,0,7,108,108,1,108,108,108,112,0,0,112,112,112
0,0,108,108,108,108,2,2,2,2,108,1,1,1,108,0,0,0,0,0,0,0,7,0,0,0,0,0,0,0,0,0,0,0,0,0,0,0,0,108,108,108,108,1,108,112,112,0,0,112,112,112
0,0,0,0,108,108,108,108,108,108,2,7,7,7,7,108,108,0,7,10,10,7,7,7,10,10,7,7,119,7,7,7,0,0,0,0,0,0,0,0,108,108,1,1,108,112,112,0,0,112,112,0
0,0,0,0,108,108,108,108,108,108,2,108,108,108,108,108,108,108,108,1,0,0,7,0,0,0,0,0,0,0,0,0,0,0,0,0,0,0,0,0,0,108,108,108,108,108,108,2,108,108,7,0
0,0,0,0,108,108,1,108,108,7,108,108,1,1,1,1,1,1,1,1,108,108,7,0,0,0,0,0,0,0,0,0,0,0,0,0,0,0,0,7,0,0,108,108,108,108,108,108,108,108,7,0
0,112,0,0,108,108,108,1,108,108,108,1,1,1,1,1,1,1,1,1,1,1,108,108,0,0,0,0,0,0,0,0,0,0,0,0,0,0,11,0,0,0,0,108,108,108,108,108,108,108,7,0
112,0,112,108,108,108,108,1,1,1,1,1,1,1,0,1,1,1,1,1,1,1,108,108,108,0,0,0,0,0,0,0,0,0,0,0,0,0,7,0,0,0,0,10,0,108,108,108,108,108,7,112
0,112,112,108,108,108,108,108,108,1,1,108,1,1,1,1,1,108,1,1,108,108,2,2,108,108,0,0,0,7,7,0,0,0,0,0,10,7,7,7,0,0,10,0,108,108,108,108,108,108,7,112
112,112,112,108,108,108,108,108,108,2,108,108,108,1,1,108,108,108,108,1,108,2,108,108,2,108,108,0,7,0,0,7,0,0,0,7,0,0,10,0,0,0,10,10,108,108,108,108,108,108,7,112
112,112,112,7,108,108,108,108,108,108,7,10,10,7,108,108,108,10,11,11,2,108,108,108,108,108,108,108,0,0,0,0,0,0,0,0,0,0,0,0,0,0,0,0,108,108,108,108,108,108,7,0
0,0,0,10,7,108,108,108,108,108,7,0,108,0,1,1,108,108,108,108,2,108,108,108,108,108,108,108,108,0,0,0,0,0,0,0,0,0,0,108,108,108,108,108,108,108,108,108,108,108,7,0
112,0,112,108,108,108,1,1,108,2,108,0,108,108,108,1,1,1,1,108,108,2,108,108,108,108,108,108,108,108,108,108,108,108,108,108,108,108,108,108,108,108,108,108,108,108,108,108,108,108,10,0
112,112,0,7,108,108,1,108,108,108,108,108,1,1,1,1,1,1,1,108,108,108,108,108,108,108,108,108,108,108,108,108,108,108,108,108,108,108,108,108,108,108,108,108,108,108,108,11,11,7,7,0
112,112,112,10,108,1,1,1,108,108,1,1,1,1,1,108,1,1,1,108,108,108,108,108,108,108,108,108,108,108,108,108,108,108,108,11,11,11,7,7,108,108,108,108,108,108,108,7,108,108,108,0
112,112,0,11,108,1,1,108,108,108,108,1,1,1,1,108,108,108,1,108,108,108,108,108,108,108,108,108,108,108,108,108,108,108,108,108,108,0,0,0,0,0,0,0,0,0,0,7,108,108,108,0
112,112,112,11,108,108,108,108,108,2,108,1,108,1,108,108,108,2,108,108,108,2,108,108,108,108,108,7,108,108,108,108,108,108,1,1,108,0,7,110,11,11,11,11,11,110,0,7,108,108,108,112
0,0,112,108,108,108,108,108,108,108,7,108,1,108,1,108,2,108,108,108,2,108,108,108,108,108,108,7,108,108,108,108,108,108,0,0,0,0,110,110,11,0,0,11,11,11,0,0,112,0,0,112
0,112,0,108,108,108,108,108,108,108,7,108,1,108,1,108,108,2,108,108,108,108,108,108,108,108,108,7,108,108,108,108,108,108,108,0,0,0,7,11,0,117,0,0,11,110,0,0,0,112,112,0
0,0,0,108,108,108,108,108,108,7,7,7,7,108,108,108,108,108,2,2,2,2,108,108,108,108,11,11,108,108,108,108,108,108,108,0,0,0,0,0,0,0,0,0,0,7,0,0,0,112,0,0
0,112,112,0,0,0,0,112,0,0,7,0,108,10,108,108,108,2,108,108,2,108,108,108,1,108,108,108,108,108,108,108,108,108,108,0,0,0,0,0,0,0,0,0,0,10,0,112,112,112,112,0
0,112,0,0,0,112,112,0,112,0,0,0,0,0,0,108,108,108,108,108,108,108,108,1,1,108,0,108,108,108,108,108,108,108,108,0,0,0,11,7,0,0,0,0,11,11,0,0,112,112,0,0
0,112,112,0,0,112,112,112,112,112,0,112,0,0,0,0,0,108,108,108,108,108,108,1,1,108,108,108,108,108,108,108,108,108,108,0,0,0,110,11,11,0,0,11,11,11,0,0,112,112,112,0
112,112,112,0,0,0,112,112,0,0,112,112,0,0,0,0,0,0,108,108,108,108,1,1,108,108,108,7,108,108,108,108,108,108,108,0,0,0,7,11,11,10,11,7,110,11,0,0,0,112,0,112
112,112,112,0,0,0,112,112,0,112,0,112,0,0,0,0,0,112,108,108,108,108,1,108,7,7,108,10,108,108,108,108,108,108,108,0,0,0,0,0,0,0,0,0,0,0,0,0,0,112,113,0
0,112,129,0,0,112,0,112,112,112,112,0,0,112,0,0,0,0,0,108,108,108,1,108,108,108,108,7,108,108,108,108,108,108,0,0,0,0,0,0,0,0,0,112,0,112,112,112,0,112,112,0
0,0,0,0,0,0,112,0,0,0,112,112,112,0,0,0,0,0,0,0,0,112,108,108,108,108,108,10,108,108,108,108,108,108,0,112,0,0,112,112,112,112,0,112,112,112,0,0,112,115,0,0
0,0,0,128,0,0,0,112,0,112,112,112,0,0,0,0,0,0,0,0,0,0,112,0,108,108,108,10,11,11,11,7,7,108,112,0,0,112,112,112,0,0,0,0,0,0,116,112,0,112,112,0
0,0,0,0,0,0,0,0,112,112,112,112,0,0,0,0,0,0,0,0,0,112,0,112,0,0,112,0,0,0,0,0,0,0,112,112,0,0,112,112,112,0,0,0,0,112,0,112,112,0,0,0
131,0,0,0,0,0,0,0,0,112,112,112,0,0,0,0,0,0,0,0,0,0,112,112,0,0,0,0,0,0,112,0,112,112,0,0,0,0,0,0,0,0,0,0,0,0,0,0,112,0,0,0
:endlayer
layer: 15
0,0,0,0,0,0,0,0,0,0,0,0,0,0,0,0,0,0,0,0,0,0,0,0,0,0,0,0,0,0,0,0,0,0,0,0,0,0,0,0,0,0,0,0,0,0,0,0,0,0,0,0
0,0,0,0,0,0,0,0,0,0,0,0,0,0,0,0,0,0,0,0,0,0,0,0,0,0,0,0,0,0,0,0,0,0,0,0,0,0,0,0,0,0,0,0,0,0,0,0,0,0,0,0
0,0,0,0,0,0,0,0,0,0,0,0,0,0,0,0,0,0,0,0,0,0,0,0,0,0,0,0,0,0,0,0,0,0,0,0,0,0,0,0,0,0,0,0,0,0,0,133,0,112,0,0
0,0,0,0,0,0,0,0,0,0,0,0,0,0,0,0,0,0,0,0,0,0,0,0,0,112,112,0,0,0,0,0,0,0,0,0,0,0,0,0,0,0,0,0,0,0,0,112,112,0,112,0
0,0,0,0,0,0,0,0,0,0,0,0,0,0,0,0,0,0,0,0,0,0,0,0,0,0,0,0,0,0,0,0,0,0,0,0,0,0,0,0,0,0,0,0,0,0,0,112,112,132,112,0
0,0,0,0,0,0,0,0,0,0,0,0,0,0,0,0,0,0,0,0,0,0,0,0,0,0,0,0,0,0,0,0,0,0,0,0,0,0,0,0,0,0,0,0,0,0,0,0,112,112,0,0
0,0,0,0,0,0,0,0,0,0,0,0,0,0,10,0,0,0,0,0,0,0,0,0,0,0,0,0,0,0,0,0,0,0,0,0,0,0,0,0,0,0,0,0,0,0,0,0,112,112,0,0
0,0,0,0,0,0,0,0,0,0,0,0,0,0,7,0,0,0,0,0,0,0,0,0,0,0,0,0,0,0,0,0,0,0,0,0,0,0,0,0,0,0,0,0,0,0,0,112,0,112,112,0
0,0,0,0,0,0,0,0,0,0,11,0,0,10,0,0,0,7,0,0,10,0,0,0,7,0,0,0,0,0,0,7,0,0,0,0,0,0,7,0,0,0,0,0,0,0,0,0,112,0,0,0
0,0,0,0,0,0,0,0,0,10,7,10,7,0,0,0,0,0,7,7,0,0,0,0,0,7,0,0,0,0,0,0,7,10,0,0,10,7,7,7,0,10,0,0,0,0,0,0,0,0,0,0
0,0,0,0,0,0,0,0,0,0,7,0,0,0,0,0,0,0,10,0,0,0,0,0,0,0,0,0,0,0,0,0,0,0,0,0,0,0,10,0,0,0,10,0,0,0,0,0,0,0,0,0
0,0,0,0,0,0,0,0,0,0,7,0,0,0,0,0,0,0,10,0,0,0,0,0,0,0,0,0,0,0,0,0,0,0,0,0,0,0,7,0,0,10,0,0,0,0,0,0,0,0,0,0
0,0,0,0,0,0,0,0,0,7,0,0,0,0,0,0,0,0,0,0,0,0,0,0,0,0,0,0,0,0,0,0,0,0,0,0,0,0,10,0,0,0,10,0,0,0,0,0,0,0,0,0
0,0,0,0,0,112,0,0,0,0,0,0,0,0,0,0,0,0,0,0,0,0,7,0,0,0,0,0,0,0,0,0,0,0,0,0,0,0,7,0,0,112,0,0,0,0,0,0,0,0,0,0
0,0,0,0,112,112,0,0,0,0,0,0,0,0,0,0,0,0,0,0,0,0,7,0,0,0,0,0,0,0,0,0,0,0,0,0,0,0,7,0,0,0,0,0,0,0,0,112,0,0,0,0
0,0,0,0,112,0,0,0,0,0,0,0,0,0,0,0,0,0,7,10,7,7,7,7,7,7,7,10,0,0,7,7,0,0,0,0,0,0,0,7,0,0,0,0,0,112,112,0,112,0,0,0
0,0,0,0,112,0,0,0,0,7,0,0,0,0,0,0,0,0,0,0,0,0,7,10,0,0,0,0,0,0,0,0,0,0,0,0,0,0,0,0,0,0,0,0,0,112,112,112,112,0,0,0
0,0,0,0,112,0,0,0,0,0,7,0,0,0,0,0,0,0,0,0,0,0,10,0,0,0,0,0,0,0,0,0,0,0,0,0,0,0,0,0,0,0,112,0,0,0,112,112,0,0,0,0
0,0,0,0,0,108,108,108,108,0,7,10,0,0,0,0,0,0,0,0,0,0,7,0,0,0,0,0,0,0,0,0,0,0,0,0,0,0,0,0,0,0,112,0,0,0,112,112,0,0,0,0
0,0,0,0,108,108,108,108,108,7,0,0,10,0,138,0,0,0,0,0,0,0,0,0,0,0,0,0,0,0,0,0,0,0,0,0,134,0,0,7,0,0,0,0,0,112,0,112,112,0,0,0
0,0,0,108,108,108,108,108,108,0,0,0,0,0,0,0,0,0,0,0,0,0,0,0,0,0,0,0,0,0,0,0,0,0,0,0,0,0,7,0,0,0,0,0,0,0,112,0,0,0,0,0
0,0,0,108,108,108,108,108,108,0,0,0,0,0,0,0,0,0,0,0,0,0,0,0,0,0,0,0,0,0,0,0,0,0,0,0,0,10,7,0,0,0,0,0,0,0,0,0,0,0,0,0
0,0,0,0,108,108,108,108,108,0,0,0,0,0,0,0,0,0,0,0,0,0,10,0,0,0,0,0,0,0,0,0,0,0,0,0,0,10,0,7,0,0,0,112,0,0,0,0,0,0,0,0
0,0,0,0,0,0,108,108,108,10,0,0,0,0,0,0,0,0,0,0,0,0,7,0,0,0,0,0,0,0,0,0,0,0,0,0,0,0,0,0,0,0,0,0,0,0,0,0,0,0,0,0
0,0,0,0,0,0,0,0,0,0,11,11,7,7,0,0,0,0,7,10,0,7,7,7,7,10,7,7,0,7,10,7,0,0,0,0,0,0,0,0,0,0,0,0,0,0,0,0,0,0,0,0
0,0,0,0,0,0,0,0,0,0,7,0,0,0,0,0,0,0,0,0,0,0,7,0,0,0,0,0,0,0,0,0,0,0,0,0,0,0,0,0,0,0,0,0,0,0,0,108,0,0,0,0
0,0,0,0,0,0,0,0,0,7,0,0,0,0,0,0,0,0,0,0,0,0,11,0,0,0,0,0,0,0,0,0,0,0,0,0,0,0,0,10,0,0,0,0,0,0,0,0,0,0,10,0
0,0,0,0,0,0,112,0,0,0,0,0,0,0,0,0,0,0,0,0,0,0,0,0,0,0,0,0,0,0,0,0,0,0,0,0,0,0,11,0,0,0,0,0,0,0,0,0,0,0,7,0
0,0,0,112,112,0,0,0,0,0,0,0,0,0,0,0,0,0,0,0,0,0,0,0,0,0,0,0,0,0,0,0,0,0,0,0,0,0,7,0,0,0,0,10,0,0,0,0,0,0,10,0
0,0,0,0,0,112,112,0,0,0,0,0,0,0,0,0,0,0,0,0,0,0,10,7,0,0,0,0,0,10,7,0,0,0,0,0,0,7,7,7,0,0,10,0,0,0,0,0,0,0,0,0
0,0,0,0,112,112,112,112,0,7,112,0,0,0,0,0,0,0,0,0,0,7,0,0,11,0,0,0,7,0,0,7,0,0,0,7,0,0,10,0,0,0,0,0,0,0,0,0,0,0,0,0
0,0,0,0,112,0,0,0,0,0,7,0,0,0,0,0,0,0,0,11,7,0,0,0,0,0,0,0,0,0,0,0,0,0,0,0,0,0,0,0,0,0,0,0,0,0,0,0,0,0,0,0
0,0,0,0,0,0,0,0,0,0,10,0,0,0,0,0,0,0,0,0,7,0,0,0,0,0,0,0,0,0,0,0,0,0,0,0,0,0,0,0,0,0,0,0,0,0,0,0,0,0,0,0
0,0,0,0,0,0,0,0,0,7,0,0,0,0,0,0,0,0,0,0,0,7,0,0,0,0,0,0,0,0,0,0,0,0,0,0,0,0,0,0,0,0,0,0,0,0,0,0,0,0,10,0
0,0,0,0,0,0,0,0,0,0,0,0,0,0,139,0,0,0,0,0,0,0,0,0,0,0,0,0,0,0,0,0,0,0,0,0,0,0,0,0,0,0,0,0,0,0,0,0,0,0,0,0
0,0,0,0,0,0,0,0,0,0,0,0,0,0,0,137,0,0,0,0,0,0,0,0,0,0,0,0,0,135,0,0,0,0,0,0,0,0,0,7,0,0,0,0,0,0,0,0,0,0,0,0
0,0,0,0,0,0,0,0,0,0,0,0,0,0,0,0,0,0,0,0,0,0,0,0,0,0,0,0,136,0,0,0,0,0,0,0,0,0,0,0,0,0,0,0,0,0,0,0,112,0,112,0
0,0,0,0,112,0,0,0,0,7,0,0,0,0,0,0,0,10,0,0,0,10,0,0,0,0,0,7,0,0,0,0,0,0,0,0,0,0,110,7,11,0,0,11,11,7,0,0,112,112,112,0
0,0,0,0,112,112,0,0,0,0,10,0,0,0,0,0,10,0,0,0,10,0,0,0,0,0,0,7,0,0,0,0,0,0,0,0,0,0,7,110,11,0,0,11,11,11,0,0,0,0,0,0
0,0,0,112,112,112,112,0,0,0,7,0,0,0,0,0,0,10,0,0,0,0,0,0,0,0,0,0,0,0,0,0,0,112,0,0,0,0,110,11,0,0,64,117,11,110,0,0,0,0,0,0
0,0,0,112,112,0,0,0,0,7,7,7,10,0,112,0,0,0,7,7,7,7,0,0,0,0,0,0,0,0,0,112,112,0,112,0,0,0,0,0,0,0,0,0,0,0,0,0,0,0,0,0
0,0,0,0,0,0,0,0,0,0,10,0,0,7,0,0,0,7,0,0,11,0,0,0,0,0,0,0,0,0,0,112,112,112,112,0,0,0,0,0,0,0,0,0,0,0,0,0,0,0,0,0
0,0,0,0,0,0,0,0,0,0,0,0,0,0,0,0,0,112,0,0,0,0,0,0,0,0,0,0,0,0,0,0,112,112,0,0,0,0,11,110,0,0,0,0,10,11,0,0,0,0,0,0
0,0,0,0,0,0,0,0,0,0,0,0,0,0,0,0,0,112,112,0,0,0,0,0,0,0,0,0,0,0,0,0,112,112,0,0,0,0,110,7,11,0,0,7,7,7,0,0,0,0,0,0
0,0,0,0,0,0,0,0,0,0,0,0,0,0,0,0,0,0,112,112,0,0,0,0,0,0,0,0,0,0,0,112,0,112,112,0,0,0,7,11,11,0,0,7,7,110,0,0,0,0,0,0
0,0,0,0,0,0,0,0,0,0,0,0,0,0,0,0,0,0,0,112,0,0,0,0,0,0,0,0,0,0,0,0,112,0,0,0,0,0,0,0,0,0,0,0,0,0,0,0,0,0,0,0
0,0,0,0,0,0,0,0,0,0,0,0,0,0,0,0,0,0,0,112,112,0,0,0,0,0,0,0,0,0,0,0,0,0,0,0,0,0,0,0,0,0,0,0,0,0,0,0,0,0,0,0
0,0,0,0,0,0,0,0,0,0,0,0,0,0,0,0,0,0,0,0,0,0,0,112,112,0,0,7,0,0,0,0,0,0,0,0,0,0,0,0,0,0,0,0,0,0,0,0,0,0,0,0
0,0,0,0,0,0,0,0,0,0,0,0,0,0,0,0,0,0,0,0,0,0,0,0,112,112,112,7,11,11,0,0,11,0,0,0,0,0,0,0,0,0,0,0,0,0,0,0,0,0,0,0
0,0,0,0,0,0,0,0,0,0,0,0,0,0,0,0,0,0,0,0,0,0,0,0,0,0,0,0,0,0,0,0,0,0,0,0,0,0,0,0,0,0,0,0,0,0,0,0,0,0,0,0
0,0,0,0,0,0,0,0,0,0,0,0,0,0,0,0,0,0,0,0,0,0,0,0,0,0,0,0,0,0,0,0,0,0,0,0,0,0,0,0,0,0,0,0,0,0,0,0,0,0,0,0
:endlayer
layer: 16
0,0,0,0,0,0,0,0,0,0,0,0,0,0,0,0,0,0,0,0,0,0,0,0,0,0,0,0,0,0,0,0,0,0,0,0,0,0,0,0,0,0,0,0,0,0,0,0,0,0,0,0
0,0,0,0,0,0,0,0,0,0,0,0,0,0,0,0,0,0,0,0,0,0,0,0,0,0,0,0,0,0,0,0,0,0,0,0,0,0,0,0,0,0,0,0,0,0,0,0,0,0,0,0
0,0,0,0,0,0,0,0,0,0,0,0,0,0,0,0,0,0,0,0,0,0,0,0,0,0,0,0,0,0,0,0,0,0,0,0,0,0,0,0,0,0,0,0,0,0,0,0,0,0,0,0
0,0,0,0,0,0,0,0,0,0,0,0,0,0,0,0,0,0,0,0,0,0,0,0,0,0,0,0,0,0,0,0,0,0,0,0,0,0,0,0,0,0,0,0,0,0,0,0,0,0,0,0
0,0,0,0,0,0,0,0,0,0,0,0,0,0,0,0,0,0,0,0,0,0,0,0,0,0,0,0,0,0,0,0,0,0,0,0,0,0,0,0,0,0,0,0,0,0,0,0,0,0,0,0
0,0,0,0,0,0,0,0,0,0,0,0,0,0,0,0,0,0,0,0,0,0,0,0,0,0,0,0,0,0,0,0,0,0,0,0,0,0,0,0,0,0,0,0,0,0,0,0,0,0,0,0
0,0,0,0,0,0,0,0,0,0,0,0,0,0,0,0,0,0,0,0,0,0,0,0,0,0,0,0,0,0,0,0,0,0,0,0,0,0,0,0,0,0,0,0,0,0,0,0,0,0,0,0
0,0,0,0,0,0,0,0,0,0,0,0,0,0,7,0,0,0,0,0,0,0,0,0,0,0,0,0,0,0,0,0,0,0,0,0,0,0,0,0,0,0,0,0,0,0,0,0,0,0,0,0
0,0,0,0,0,0,0,0,0,0,7,0,0,10,0,0,0,7,0,0,10,0,0,0,7,0,0,10,0,0,0,7,0,0,0,0,0,0,7,0,0,0,0,0,0,0,0,0,0,0,0,0
0,0,0,0,0,0,0,0,0,7,7,10,7,0,0,0,0,0,7,10,0,0,0,0,0,10,0,0,0,0,0,0,11,7,0,0,7,10,7,7,0,0,0,0,0,0,0,0,0,0,0,0
0,0,0,0,0,0,0,0,0,0,7,0,0,0,0,0,0,0,10,0,0,0,0,0,0,0,0,0,0,0,0,0,0,0,0,0,0,0,10,0,0,0,10,0,0,0,0,0,0,0,0,0
0,0,0,0,0,0,0,0,0,0,7,0,0,0,0,0,0,0,0,0,0,0,0,0,0,0,0,0,0,0,0,0,0,0,0,0,0,0,11,0,0,10,0,0,0,0,0,0,0,0,0,0
0,0,0,0,0,0,0,0,0,10,0,0,0,0,0,0,0,0,0,0,0,0,10,0,0,0,0,0,0,0,0,0,0,0,0,0,0,0,0,0,0,0,0,0,0,0,0,0,0,0,0,0
0,0,0,0,0,0,0,0,0,0,0,0,0,0,0,0,0,0,0,0,0,0,7,0,0,0,0,0,0,0,0,0,0,0,0,0,0,0,7,0,0,0,0,0,0,0,0,0,0,0,0,0
0,0,0,0,0,0,0,0,0,0,0,0,0,0,0,0,0,0,0,0,0,0,7,0,0,0,0,0,0,0,0,0,0,0,0,0,0,0,7,0,0,0,0,0,0,0,0,0,0,0,0,0
0,0,0,0,0,0,0,0,0,0,0,0,0,0,0,0,0,0,7,10,7,7,7,7,11,11,7,7,7,0,0,0,0,0,0,0,0,0,0,7,0,0,0,0,0,0,0,0,0,0,0,0
0,0,0,0,0,0,0,0,0,7,0,0,0,0,0,0,0,0,0,0,0,0,7,0,0,0,0,0,0,0,0,0,0,0,0,0,0,0,0,0,0,0,0,0,0,0,0,0,0,0,0,0
0,0,0,0,0,0,0,0,0,0,7,0,0,0,0,0,0,0,0,0,0,0,7,0,0,0,0,0,0,0,0,0,0,0,0,0,0,0,0,0,0,0,0,0,0,0,0,0,0,0,0,0
0,0,0,0,0,0,0,0,0,0,7,0,0,0,0,0,0,0,0,0,0,0,7,0,0,0,0,0,0,0,0,0,0,0,0,0,0,0,0,0,0,0,0,0,0,0,0,0,0,0,0,0
0,0,0,0,0,0,0,0,0,7,0,0,0,0,0,0,0,0,0,0,0,0,0,0,0,0,0,0,0,0,0,0,0,0,0,0,0,0,0,7,0,0,0,0,0,0,0,0,0,0,0,0
0,0,0,112,0,0,112,112,0,0,0,0,0,0,0,0,0,0,0,0,0,0,0,0,0,0,0,0,0,0,0,0,0,0,0,0,0,0,7,0,0,0,0,0,0,0,0,0,0,0,0,0
0,0,0,0,112,112,112,112,0,0,0,0,0,0,0,0,0,0,0,0,0,0,0,0,0,0,0,0,0,0,0,0,0,0,0,0,0,0,7,0,0,0,0,0,0,0,0,0,0,0,0,0
0,0,0,0,112,112,112,0,112,0,0,0,0,0,0,0,0,0,0,0,0,0,10,0,0,0,0,0,0,0,0,0,0,0,0,0,0,0,0,7,0,0,0,0,0,0,0,0,0,0,0,0
0,0,0,0,0,0,112,112,0,10,0,0,0,0,0,0,0,0,0,0,0,0,7,0,0,0,0,0,0,0,0,0,0,0,0,0,0,0,0,0,0,0,0,0,0,0,0,0,0,0,0,0
0,0,0,0,0,0,0,0,0,0,7,7,10,7,0,0,0,0,10,0,0,7,7,7,7,10,7,7,0,10,7,0,0,0,0,0,0,0,0,0,0,0,0,0,0,0,0,0,0,0,0,0
0,0,0,0,0,0,0,0,0,0,7,0,0,0,0,0,0,0,0,0,0,0,7,0,0,0,0,0,0,0,0,0,0,0,0,0,0,0,0,0,0,0,0,0,0,0,0,0,0,0,0,0
0,0,0,0,0,0,0,0,0,7,0,0,0,0,0,0,0,0,0,0,0,0,10,0,0,0,0,0,0,0,0,0,0,0,0,0,0,0,0,10,0,0,0,0,0,0,0,0,0,0,10,0
0,0,0,0,0,0,0,0,0,0,0,0,0,0,0,0,0,0,0,0,0,0,0,0,0,0,0,0,0,0,0,0,0,0,0,0,0,0,7,0,0,0,0,0,0,0,0,0,0,0,0,0
0,0,0,0,0,0,0,0,0,0,0,0,0,0,0,0,0,0,0,0,0,0,0,0,0,0,0,0,0,0,0,0,0,0,0,0,0,0,11,0,0,0,0,0,0,0,0,0,0,0,0,0
0,0,0,0,0,0,0,0,0,0,0,0,0,0,0,0,0,0,0,0,0,0,10,7,0,0,0,0,0,10,7,0,0,0,0,0,7,7,7,7,0,0,10,0,0,0,0,0,0,0,0,0
0,0,0,0,0,0,0,0,0,7,0,0,0,0,0,0,0,0,0,0,0,10,0,0,11,0,0,0,7,0,0,7,0,0,0,7,0,0,7,0,0,0,0,0,0,0,0,0,0,0,0,0
0,0,0,0,0,0,0,0,0,0,7,0,0,0,0,0,0,0,0,7,7,0,0,0,0,0,0,0,0,0,0,0,0,0,0,0,0,0,0,0,0,0,0,0,0,0,0,0,0,0,0,0
0,0,0,0,0,0,0,0,0,0,7,0,0,0,0,0,0,0,0,0,7,0,0,0,0,0,0,0,0,0,0,0,0,0,0,0,0,0,0,0,0,0,0,0,0,0,0,0,0,0,0,0
0,0,0,0,0,0,0,0,0,10,0,0,0,0,0,0,0,0,0,0,0,7,0,0,0,0,0,0,0,0,0,0,0,0,0,0,0,0,0,0,0,0,0,0,0,0,0,0,0,0,7,0
0,0,0,0,0,0,0,0,0,0,0,0,0,0,0,0,0,0,0,0,0,0,0,0,0,0,0,0,0,0,0,0,0,0,0,0,0,0,0,0,0,0,0,0,0,0,0,0,0,0,0,0
0,0,0,0,0,0,0,0,0,0,0,0,0,0,0,0,0,0,0,0,0,0,0,0,0,0,0,0,0,0,0,0,0,0,0,0,0,0,0,7,0,0,0,0,0,0,0,0,0,0,0,0
0,0,0,0,0,0,0,0,0,0,0,0,0,0,0,0,0,0,0,0,0,0,0,0,0,0,0,0,0,0,0,0,0,0,0,0,0,0,0,0,0,0,0,0,0,0,0,0,0,0,0,0
0,0,0,0,0,0,0,0,0,7,0,0,0,0,0,0,0,0,0,0,0,10,0,0,0,0,0,0,0,0,0,0,0,0,0,0,0,0,110,110,0,0,0,7,11,110,0,0,0,0,0,0
0,0,0,0,0,0,0,0,0,0,7,0,0,0,0,0,0,0,0,0,0,0,0,0,0,0,0,0,0,0,0,0,0,0,0,0,0,0,10,10,11,0,0,11,11,110,0,0,0,0,0,0
0,0,0,0,0,0,0,0,0,0,7,0,0,0,0,0,0,10,0,0,0,0,0,0,0,0,0,0,0,0,0,0,0,0,0,0,0,0,11,110,0,0,0,0,11,7,0,0,0,0,0,0
0,0,0,0,0,0,0,0,0,7,7,7,7,0,0,0,0,0,7,10,7,0,0,0,0,0,0,0,0,0,0,0,0,0,0,0,0,0,0,0,0,0,0,64,0,0,0,0,0,0,0,0
0,0,0,0,0,0,0,0,0,0,10,0,0,7,0,0,0,7,0,0,7,0,0,0,0,0,0,0,0,0,0,0,0,0,0,0,0,0,0,0,0,0,0,117,0,0,0,0,0,0,0,0
0,0,0,0,0,0,0,0,0,0,0,0,0,0,0,0,0,0,0,0,0,0,0,0,0,0,0,0,0,0,0,0,0,0,0,0,0,0,10,7,0,0,0,0,10,110,0,0,0,0,0,0
0,0,0,0,0,0,0,0,0,0,0,0,0,0,0,0,0,0,0,0,0,0,0,0,0,0,0,0,0,0,0,0,0,0,0,0,0,0,110,7,110,0,0,110,110,110,0,0,0,0,0,0
0,0,0,0,0,0,0,0,0,0,0,0,0,0,0,0,0,0,0,0,0,0,0,0,0,0,0,0,0,0,0,0,0,0,0,0,0,0,110,110,11,0,0,110,7,110,0,0,0,0,0,0
0,0,0,0,0,0,0,0,0,0,0,0,0,0,0,0,0,0,0,0,0,0,0,0,0,0,0,0,0,0,0,0,0,0,0,0,0,0,0,0,0,0,0,0,0,0,0,0,0,0,0,0
0,0,0,0,0,0,0,0,0,0,0,0,0,0,0,0,0,0,0,0,0,0,0,0,0,0,0,0,0,0,0,0,0,0,0,0,0,0,0,0,0,0,0,0,0,0,0,0,0,0,0,0
0,0,0,0,0,0,0,0,0,0,0,0,0,0,0,0,0,0,0,0,0,0,0,0,0,0,0,0,0,0,0,0,0,0,0,0,0,0,0,0,0,0,0,0,0,0,0,0,0,0,0,0
0,0,0,0,0,0,0,0,0,0,0,0,0,0,0,0,0,0,0,0,0,0,0,0,0,0,0,7,11,0,0,0,7,0,0,0,0,0,0,0,0,0,0,0,0,0,0,0,0,0,0,0
0,0,0,0,0,0,0,0,0,0,0,0,0,0,0,0,0,0,0,0,0,0,0,0,0,0,0,0,0,0,0,0,0,0,0,0,0,0,0,0,0,0,0,0,0,0,0,0,0,0,0,0
0,0,0,0,0,0,0,0,0,0,0,0,0,0,0,0,0,0,0,0,0,0,0,0,0,0,0,0,0,0,0,0,0,0,0,0,0,0,0,0,0,0,0,0,0,0,0,0,0,0,0,0
:endlayer
layer: 17
0,0,0,0,0,0,0,0,0,0,0,0,0,0,0,0,0,0,0,0,0,0,0,0,0,0,0,0,0,0,0,0,0,0,0,0,0,0,0,0,0,0,0,0,0,0,0,0,0,0,0,0
0,0,0,0,0,0,0,0,0,0,0,0,0,0,0,0,0,0,0,0,0,0,0,0,0,0,0,0,0,0,0,0,0,0,0,0,0,0,0,0,0,0,0,0,0,0,0,0,0,0,0,0
0,0,0,0,0,0,0,0,0,0,0,0,0,0,0,0,0,0,0,0,0,0,0,0,0,0,0,0,0,0,0,0,0,0,0,0,0,0,0,0,0,0,0,0,0,0,0,0,0,0,0,0
0,0,0,0,0,0,0,0,0,0,0,0,0,0,0,0,0,0,0,0,0,0,0,0,0,0,0,0,0,0,0,0,0,0,0,0,0,0,0,0,0,0,0,0,0,0,0,0,0,0,0,0
0,0,0,0,0,0,0,0,0,0,0,0,0,0,0,0,0,0,0,0,0,0,0,0,0,0,0,0,0,0,0,0,0,0,0,0,0,0,0,0,0,0,0,0,0,0,0,0,0,0,0,0
0,0,0,0,0,0,0,0,0,0,0,0,0,0,0,0,0,0,0,0,0,0,0,0,0,0,0,0,0,0,0,0,0,0,0,0,0,0,0,0,0,0,0,0,0,0,0,0,0,0,0,0
0,0,0,0,0,0,0,0,0,0,0,0,0,0,0,0,0,0,0,0,0,0,0,0,0,0,0,0,0,0,0,0,0,0,0,0,0,0,0,0,0,0,0,0,0,0,0,0,0,0,0,0
0,0,0,0,0,0,0,0,0,0,0,0,0,0,0,0,0,0,0,0,0,0,0,0,0,0,0,0,0,0,0,0,0,0,0,0,0,0,0,0,0,0,0,0,0,0,0,0,0,0,0,0
0,0,0,0,0,0,0,0,0,0,7,0,0,7,0,0,0,10,0,0,7,0,0,0,7,0,0,7,0,0,0,7,0,0,0,0,0,0,7,0,0,0,0,0,0,0,0,0,0,0,0,0
0,0,0,0,0,0,0,0,0,7,7,7,7,0,0,0,0,0,7,7,0,0,0,0,0,10,7,0,0,0,0,0,11,7,0,0,7,7,7,7,0,0,0,0,0,0,0,0,0,0,0,0
0,0,0,0,0,0,0,0,0,0,7,0,0,0,0,0,0,0,0,0,0,0,0,0,0,0,0,0,0,0,0,0,0,0,0,0,0,0,7,0,0,0,10,0,0,0,0,0,0,0,0,0
0,0,0,0,0,0,0,0,0,0,10,0,0,0,0,0,0,0,0,0,0,0,0,0,0,0,0,0,0,0,0,0,0,0,0,0,0,0,7,0,0,0,0,0,0,0,0,0,0,0,0,0
0,0,0,0,0,0,0,0,0,10,0,0,0,0,0,0,0,0,0,0,0,0,10,0,0,0,0,0,0,0,0,0,0,0,0,0,0,0,0,0,0,0,0,0,0,0,0,0,0,0,0,0
0,0,0,0,0,0,0,0,0,0,0,0,0,0,0,0,0,0,0,0,0,0,7,0,0,0,0,0,0,0,0,0,0,0,0,0,0,0,7,0,0,0,0,0,0,0,0,0,0,0,0,0
0,0,0,0,0,0,0,0,0,0,0,0,0,0,0,0,0,0,0,0,0,0,7,0,0,0,0,0,0,0,0,0,0,0,0,0,0,0,7,0,0,0,0,0,0,0,0,0,0,0,0,0
0,0,0,0,0,0,0,0,0,0,0,0,0,0,0,0,0,0,0,7,7,7,7,7,7,10,7,0,0,0,0,0,0,0,0,0,0,0,0,7,0,0,0,0,0,0,0,0,0,0,0,0
0,0,0,0,0,0,0,0,0,7,0,0,0,0,0,0,0,0,0,0,0,0,7,0,0,0,0,0,0,0,0,0,0,0,0,0,0,0,0,0,0,0,0,0,0,0,0,0,0,0,0,0
0,0,0,0,0,0,0,0,0,0,10,0,0,0,0,0,0,0,0,0,0,0,7,0,0,0,0,0,0,0,0,0,0,0,0,0,0,0,0,0,0,0,0,0,0,0,0,0,0,0,0,0
0,0,0,0,0,0,0,0,0,0,7,0,0,0,0,0,0,0,0,0,0,0,10,0,0,0,0,0,0,0,0,0,0,0,0,0,0,0,0,0,0,0,0,0,0,0,0,0,0,0,0,0
0,0,0,0,0,0,0,0,0,7,0,0,0,0,0,0,0,0,0,0,0,0,0,0,0,0,0,0,0,0,0,0,0,0,0,0,0,0,0,7,0,0,0,0,0,0,0,0,0,0,0,0
0,0,0,0,0,0,0,0,0,0,0,0,0,0,0,0,0,0,0,0,0,0,0,0,0,0,0,0,0,0,0,0,0,0,0,0,0,0,0,0,0,0,0,0,0,0,0,0,0,0,0,0
0,0,0,0,0,0,0,0,0,0,0,0,0,0,0,0,0,0,0,0,0,0,0,0,0,0,0,0,0,0,0,0,0,0,0,0,0,0,0,0,0,0,0,0,0,0,0,0,0,0,0,0
