# Ancient Warfare Structure Template File
# Auto-generated structure template file. created on: 8/19/2019 at: 10:23:14
# Lines beginning with # denote comments

header:
version=2.9
name=OrcVillageTowerRoofedForest
mods=
size=31,25,39
offset=18,6,38
:endheader

#### VALIDATION ####
validation:
type=ground
survival=false
worldGenEnabled=true
unique=false
preserveBlocks=false
selectionWeight=60
clusterValue=100
minDuplicateDistance=900
dimensionWhiteList=true
dimensionList=0
biomeWhiteList=true
biomeList=minecraft:roofed_forest
leveling=4
fill=3
border=3
blockSwap=false
:endvalidation

#### LAYERS ####
layer: 0
1,1,1,1,1,1,1,1,1,1,1,1,1,1,1,1,1,1,1,1,1,1,1,1,1,1,1,1,1,1,1
1,1,1,1,1,1,1,1,1,1,1,1,1,1,1,1,1,1,1,1,1,1,1,1,1,1,1,1,1,1,1
1,1,1,1,1,1,1,1,1,1,1,1,1,1,1,1,1,1,1,1,1,1,1,1,1,1,1,1,1,1,1
1,1,1,1,1,1,1,1,1,1,1,1,1,1,1,1,1,1,1,1,1,1,1,1,1,1,1,1,1,1,1
1,1,1,1,1,1,1,1,1,1,1,1,1,1,1,1,1,1,1,1,1,1,1,1,1,1,1,1,1,1,1
1,1,1,1,1,1,1,1,1,1,1,1,1,1,1,1,1,1,1,1,1,1,1,1,1,1,1,1,1,1,1
1,1,1,1,1,1,1,1,1,1,1,1,1,1,1,1,1,1,1,1,1,1,1,1,1,1,1,1,1,1,1
1,1,1,1,1,1,1,1,1,1,1,1,1,1,1,1,1,1,1,1,1,1,1,1,1,1,1,1,1,1,1
1,1,1,1,1,1,1,1,1,1,1,1,1,1,1,1,1,1,1,1,1,1,1,1,1,1,1,1,1,1,1
1,1,1,1,1,1,1,1,1,1,1,1,1,1,1,1,1,1,1,1,1,1,1,1,1,1,1,1,1,1,1
1,1,1,1,1,1,1,1,1,1,1,1,1,1,1,1,1,1,1,1,1,1,1,1,1,1,1,1,1,1,1
1,1,1,1,1,1,1,1,1,1,1,1,1,1,1,1,1,1,1,1,1,1,1,1,1,1,1,1,1,1,1
1,1,1,1,1,1,1,1,1,1,1,1,1,1,1,1,1,1,1,1,1,1,1,1,1,1,1,1,1,1,1
1,1,1,1,1,1,1,1,1,1,1,1,1,1,1,1,1,1,1,1,1,1,1,1,1,1,1,1,1,1,1
1,1,1,1,1,1,1,1,1,1,1,1,1,1,1,1,1,1,1,1,1,1,1,1,1,1,1,1,1,1,1
1,1,1,1,1,1,1,1,1,1,1,1,1,1,1,1,1,1,1,1,1,1,1,1,1,1,1,1,1,1,1
1,1,1,1,1,1,1,1,1,1,1,1,1,1,1,1,1,1,1,1,1,1,1,1,1,1,1,1,1,1,1
1,1,1,1,1,1,1,1,1,1,1,1,1,1,1,1,1,1,1,1,1,1,1,1,1,1,1,1,1,1,1
1,1,1,1,1,1,1,1,1,1,1,1,1,1,1,1,1,1,1,1,1,1,1,1,1,1,1,1,1,1,1
1,1,1,1,1,1,1,1,1,1,1,1,1,1,1,1,1,1,1,1,1,1,1,1,1,1,1,1,1,1,1
1,1,1,1,1,1,1,1,1,1,1,1,1,1,1,1,1,1,1,1,1,1,1,1,1,1,1,1,1,1,1
1,1,1,1,1,1,1,1,1,1,1,1,1,1,1,1,1,1,1,1,1,1,1,1,1,1,1,1,1,1,1
1,1,1,1,1,1,1,1,1,1,1,1,1,1,1,1,1,1,1,1,1,1,1,1,1,1,1,1,1,1,1
1,1,1,1,1,1,1,1,1,1,1,1,1,1,1,1,1,1,1,1,1,1,1,1,1,1,1,1,1,1,1
1,1,1,1,1,1,1,1,1,1,1,1,1,1,1,1,1,1,1,1,1,1,1,1,1,1,1,1,1,1,1
1,1,1,1,1,1,1,1,1,1,1,1,1,1,1,1,1,1,1,1,1,1,1,1,1,1,1,1,1,1,1
1,1,1,1,1,1,1,1,1,1,1,1,1,1,1,1,1,1,1,1,1,1,1,1,1,1,1,1,1,1,1
1,1,1,1,1,1,1,1,1,1,1,1,1,1,1,1,1,1,1,1,1,1,1,1,1,1,1,1,1,1,1
1,1,1,1,1,1,1,1,1,1,1,1,1,1,1,1,1,1,1,1,1,1,1,1,1,1,1,1,1,1,1
1,1,1,1,1,1,1,1,1,1,1,1,1,1,1,1,1,1,1,0,1,1,1,1,1,1,1,1,1,1,1
1,1,1,1,1,1,1,1,1,1,1,1,1,1,1,1,1,1,1,0,1,1,1,1,1,1,1,1,1,1,1
1,1,1,1,1,1,1,1,1,1,1,1,1,1,1,1,1,1,1,0,1,1,1,1,1,1,1,1,1,1,1
1,1,1,1,1,1,1,1,1,1,1,1,1,1,1,1,1,1,1,0,1,1,1,1,1,1,1,1,1,1,1
1,1,1,1,1,1,1,1,1,1,1,1,1,1,1,1,1,1,1,0,1,1,1,1,1,1,1,1,1,1,1
1,1,1,1,1,1,1,1,1,1,1,1,1,1,1,1,1,1,1,0,1,1,1,1,1,1,1,1,1,1,1
1,1,1,1,1,1,1,1,1,1,1,1,1,1,1,1,1,1,1,0,1,1,1,1,1,1,1,1,1,1,1
1,1,1,1,1,1,1,1,1,1,1,1,1,1,1,1,1,1,1,0,1,1,1,1,1,1,1,1,1,1,1
1,1,1,1,1,1,1,1,1,1,1,1,1,1,1,1,1,1,1,1,1,1,1,1,1,1,1,1,1,1,1
1,1,1,1,1,1,1,1,1,1,1,1,1,1,1,1,1,1,1,1,1,1,1,1,1,1,1,1,1,1,1
:endlayer
layer: 1
1,1,1,1,1,1,1,1,1,1,1,1,1,1,1,1,1,1,1,1,1,1,1,1,1,1,1,1,1,1,1
1,1,1,1,1,1,1,1,1,1,1,1,1,1,1,1,1,1,1,1,1,1,1,1,1,1,1,1,1,1,1
1,1,1,1,1,1,1,1,1,1,1,1,1,1,1,1,1,1,1,1,1,1,1,1,1,1,1,1,1,1,1
1,1,1,1,1,1,1,1,1,1,1,1,1,1,1,1,1,1,1,1,1,1,1,1,1,1,1,1,1,1,1
1,1,1,1,1,1,1,1,1,1,1,1,1,1,1,1,1,1,1,1,1,1,1,1,1,1,1,1,1,1,1
1,1,1,1,1,1,1,1,1,1,1,1,1,1,1,1,1,1,1,1,1,1,1,1,1,1,1,1,1,1,1
1,1,1,1,1,1,1,1,1,1,1,1,1,1,1,1,1,1,1,1,1,1,1,1,1,1,1,1,1,1,1
1,1,1,1,1,1,1,1,1,1,1,1,1,1,1,1,1,1,1,1,1,1,1,1,1,1,1,1,1,1,1
1,1,1,1,1,1,1,1,1,1,1,1,1,1,1,1,1,1,1,1,1,1,1,1,1,1,1,1,1,1,1
1,1,1,1,1,1,1,1,1,1,1,1,1,1,1,1,1,1,1,1,1,1,1,1,1,1,1,1,1,1,1
1,1,1,1,1,1,1,1,1,1,1,1,1,1,1,1,1,1,1,1,1,1,1,1,1,1,1,1,1,1,1
1,1,1,1,1,1,1,1,1,1,1,1,1,1,1,1,1,1,1,1,1,1,1,1,1,1,1,1,1,1,1
1,1,1,1,1,1,1,1,1,1,1,1,1,1,1,1,1,1,1,1,1,1,1,1,1,1,1,1,1,1,1
1,1,1,1,1,1,1,1,1,1,1,1,1,1,1,1,1,1,1,1,1,1,1,1,1,1,1,1,1,1,1
1,1,1,1,1,1,1,1,1,1,1,1,1,1,1,1,1,1,1,1,1,1,1,1,1,1,1,1,1,1,1
1,1,1,1,1,1,1,1,1,1,1,1,1,1,1,1,1,1,1,1,1,1,1,1,1,1,1,1,1,1,1
1,1,1,1,1,1,1,1,1,1,1,1,1,1,1,1,1,1,1,1,1,1,1,1,1,1,1,1,1,1,1
1,1,1,1,1,1,1,1,1,1,1,1,1,1,1,1,1,1,1,1,1,1,1,1,1,1,1,1,1,1,1
1,1,1,1,1,1,1,1,1,1,1,1,1,1,1,1,1,1,1,1,1,1,1,1,1,1,1,1,1,1,1
1,1,1,1,1,1,1,1,1,1,1,1,1,1,1,1,1,1,1,1,1,1,1,1,1,1,1,1,1,1,1
1,1,1,1,1,1,1,1,1,1,1,1,1,1,1,1,1,1,1,1,1,1,1,1,1,1,1,1,1,1,1
1,1,1,1,1,1,1,1,1,1,1,1,1,1,1,1,1,1,1,1,1,1,1,1,1,1,1,1,1,1,1
1,1,1,1,1,1,1,1,1,1,1,1,1,1,1,1,1,1,1,1,1,1,1,1,1,1,1,1,1,1,1
1,1,1,1,1,1,1,1,1,1,1,1,1,1,1,1,1,1,1,1,1,1,1,1,1,1,1,1,1,1,1
1,1,1,1,1,1,1,1,1,1,1,1,1,1,1,1,1,1,1,1,1,1,1,1,1,1,1,1,1,1,1
1,1,1,1,1,1,1,1,1,1,1,1,1,1,1,1,1,1,1,1,1,1,1,1,1,1,1,1,1,1,1
1,1,1,1,1,1,1,1,1,1,1,1,1,1,1,1,1,1,1,1,1,1,1,1,1,1,1,1,1,1,1
1,1,1,1,1,1,1,1,1,1,1,1,1,1,1,1,1,1,1,1,1,1,1,1,1,1,1,1,1,1,1
1,1,1,1,1,1,1,1,1,1,1,1,1,1,1,1,1,1,1,1,1,1,1,1,1,1,1,1,1,1,1
1,1,1,1,1,1,1,1,1,1,1,1,1,1,1,1,1,1,1,0,1,1,1,1,1,1,1,1,1,1,1
1,1,1,1,1,1,1,1,1,1,1,1,1,1,1,1,1,1,1,0,1,1,1,1,1,1,1,1,1,1,1
1,1,1,1,1,1,1,1,1,1,1,1,1,1,1,1,1,1,1,0,1,1,1,1,1,1,1,1,1,1,1
1,1,1,1,1,1,1,1,1,1,1,1,1,1,1,1,1,1,1,0,1,1,1,1,1,1,1,1,1,1,1
1,1,1,1,1,1,1,1,1,1,1,1,1,1,1,1,1,1,1,0,1,1,1,1,1,1,1,1,1,1,1
1,1,1,1,1,1,1,1,1,1,1,1,1,1,1,1,1,1,1,0,1,1,1,1,1,1,1,1,1,1,1
1,1,1,1,1,1,1,1,1,1,1,1,1,1,1,1,1,1,1,0,1,1,1,1,1,1,1,1,1,1,1
1,1,1,1,1,1,1,1,1,1,1,1,1,1,1,1,1,1,1,0,1,1,1,1,1,1,1,1,1,1,1
1,1,1,1,1,1,1,1,1,1,1,1,1,1,1,1,1,1,1,1,1,1,1,1,1,1,1,1,1,1,1
1,1,1,1,1,1,1,1,1,1,1,1,1,1,1,1,1,1,1,1,1,1,1,1,1,1,1,1,1,1,1
:endlayer
layer: 2
1,1,1,1,1,1,1,1,1,1,1,1,1,1,1,1,1,1,1,1,1,1,1,1,1,1,1,1,1,1,1
1,1,1,1,1,1,1,1,1,1,1,1,1,1,1,1,1,1,1,1,1,1,1,1,1,1,1,1,1,1,1
1,1,1,1,1,1,1,1,1,1,1,1,1,1,1,1,1,1,1,1,1,1,1,1,1,1,1,1,1,1,1
1,1,1,1,1,1,1,1,1,1,1,1,1,1,1,1,1,1,1,1,1,1,1,1,1,1,1,1,1,1,1
1,1,1,1,1,1,1,1,1,1,1,1,1,1,1,1,1,1,1,1,1,1,1,1,1,1,1,1,1,1,1
1,1,1,1,1,1,1,1,1,1,1,1,1,1,1,1,1,1,1,1,1,1,1,1,1,1,1,1,1,1,1
1,1,1,1,1,1,1,1,1,1,1,1,1,1,1,1,1,1,1,1,1,1,1,1,1,1,1,1,1,1,1
1,1,1,1,1,1,1,1,1,1,1,1,1,1,1,1,1,1,1,1,1,1,1,1,1,1,1,1,1,1,1
1,1,1,1,1,1,1,1,1,1,1,1,1,1,1,1,1,1,1,1,1,1,1,1,1,1,1,1,1,1,1
1,1,1,1,1,1,1,1,1,1,1,1,1,1,1,1,1,1,1,1,1,1,1,1,1,1,1,1,1,1,1
1,1,1,1,1,1,1,1,1,1,1,1,1,1,1,1,1,1,1,1,1,1,1,1,1,1,1,1,1,1,1
1,1,1,1,1,1,1,1,1,1,1,1,1,1,1,1,1,1,1,1,1,1,1,1,1,1,1,1,1,1,1
1,1,1,1,1,1,2,2,1,1,1,1,1,1,1,1,1,1,1,1,1,1,1,2,2,1,1,1,1,1,1
1,1,1,1,1,1,1,1,1,1,1,1,1,1,1,1,1,1,1,1,1,1,1,1,1,1,1,1,1,1,1
1,1,1,1,1,1,1,1,1,1,1,1,1,1,1,1,1,1,1,1,1,1,1,1,1,1,1,1,1,1,1
1,1,1,1,1,1,1,1,1,1,1,1,1,1,1,1,1,1,1,1,1,1,1,1,1,1,1,1,1,1,1
1,1,1,1,1,1,2,2,1,1,1,1,1,1,1,1,1,1,1,1,1,1,1,2,2,1,1,1,1,1,1
1,1,1,1,1,1,1,1,1,1,1,1,1,1,1,1,1,1,1,1,1,1,1,1,1,1,1,1,1,1,1
1,1,1,1,1,1,1,1,1,1,1,1,1,1,1,1,1,1,1,1,1,1,1,1,1,1,1,1,1,1,1
1,1,1,1,1,1,1,1,1,1,1,1,1,1,1,1,1,1,1,1,1,1,1,1,1,1,1,1,1,1,1
1,1,1,1,1,1,1,1,1,1,1,1,1,1,1,1,1,1,1,1,1,1,1,1,1,1,1,1,1,1,1
1,1,1,2,2,1,1,1,1,1,1,1,1,1,1,1,1,1,1,1,1,1,1,1,1,1,2,2,1,1,1
1,1,1,1,1,1,1,1,1,1,1,1,1,1,1,1,1,1,1,1,1,1,1,1,1,1,1,1,1,1,1
1,1,1,1,1,1,1,1,1,1,1,1,1,1,1,1,1,1,1,1,1,1,1,1,1,1,1,1,1,1,1
1,1,1,1,1,1,1,1,1,1,1,1,1,1,1,1,1,1,1,1,1,1,1,1,1,1,1,1,1,1,1
1,1,1,2,2,1,1,1,1,1,1,1,1,1,1,1,1,1,1,1,1,1,1,1,1,1,2,2,1,1,1
1,1,1,1,1,1,1,1,1,1,1,1,1,1,1,1,1,1,1,1,1,1,1,1,1,1,1,1,1,1,1
1,1,1,1,1,1,1,1,1,1,1,1,1,1,1,1,1,1,1,1,1,1,1,1,1,1,1,1,1,1,1
1,1,1,1,1,1,1,1,1,1,1,1,1,1,1,1,1,1,1,1,1,1,1,1,1,1,1,1,1,1,1
1,1,1,1,1,1,1,1,1,1,1,1,1,1,1,1,1,1,1,1,1,1,1,1,1,1,1,1,1,1,1
1,1,1,1,1,1,1,1,1,1,1,1,1,1,1,1,1,1,1,1,1,1,1,1,1,1,1,1,1,1,1
1,1,1,1,1,1,1,1,1,1,1,1,1,1,1,1,1,1,1,1,1,1,1,1,1,1,1,1,1,1,1
1,1,1,1,1,1,1,1,1,1,1,1,1,1,3,4,3,1,1,1,1,1,1,1,1,1,1,1,1,1,1
1,1,1,1,1,1,1,1,1,1,1,1,1,1,4,4,3,1,1,1,1,1,1,1,1,1,1,1,1,1,1
1,1,1,1,1,1,1,1,1,1,1,1,1,1,4,4,4,3,1,1,1,1,1,1,1,1,1,1,1,1,1
1,1,1,1,1,1,1,1,1,1,1,1,1,1,1,1,1,1,1,1,1,1,1,1,1,1,1,1,1,1,1
1,1,1,1,1,1,1,1,1,1,1,1,1,1,1,1,1,1,1,1,1,1,1,1,1,1,1,1,1,1,1
1,1,1,1,1,1,1,1,1,1,1,1,1,1,1,1,1,1,1,1,1,1,1,1,1,1,1,1,1,1,1
1,1,1,1,1,1,1,1,1,1,1,1,1,1,1,1,1,1,1,1,1,1,1,1,1,1,1,1,1,1,1
:endlayer
layer: 3
1,1,1,1,1,1,1,1,1,1,1,1,1,1,1,1,1,1,1,1,1,1,1,1,1,1,1,1,1,1,1
1,1,1,1,1,1,1,1,1,1,1,1,1,1,1,1,1,1,1,1,1,1,1,1,1,1,1,1,1,1,1
1,1,1,1,1,1,1,1,1,1,1,1,1,1,1,1,1,1,1,1,1,1,1,1,1,1,1,1,1,1,1
1,1,1,1,1,1,1,1,1,1,1,1,1,1,1,1,1,1,1,1,1,1,1,1,1,1,1,1,1,1,1
1,1,1,1,1,1,1,1,1,1,1,1,1,1,1,1,1,1,1,1,1,1,1,1,1,1,1,1,1,1,1
1,1,1,1,1,1,1,1,1,1,1,1,1,1,1,1,1,1,1,1,1,1,1,1,1,1,1,1,1,1,1
1,1,1,1,1,1,1,1,1,1,1,1,1,1,1,1,1,1,1,1,1,1,1,1,1,1,1,1,1,1,1
1,1,1,1,1,1,1,1,1,1,1,1,1,1,1,1,1,1,1,1,1,1,1,1,1,1,1,1,1,1,1
1,1,1,1,1,1,1,1,1,1,1,1,1,1,1,1,1,1,1,1,1,1,1,1,1,1,1,1,1,1,1
1,1,1,1,1,1,1,1,1,1,1,1,1,1,1,1,1,1,1,1,1,1,1,1,1,1,1,1,1,1,1
1,1,1,1,1,1,1,1,1,1,1,1,1,1,1,1,1,1,1,1,1,1,1,1,1,1,1,1,1,1,1
1,1,1,1,1,1,1,1,1,1,1,1,1,1,1,1,1,1,1,1,1,1,1,1,1,1,1,1,1,1,1
1,1,1,1,1,1,6,6,1,1,1,1,1,1,1,1,1,1,1,1,1,1,1,6,6,1,1,1,1,1,1
1,1,1,1,1,5,5,5,5,5,1,1,1,1,1,1,1,1,1,1,1,5,5,5,5,5,1,1,1,1,1
1,1,1,1,1,5,5,5,5,5,5,1,1,1,1,1,1,1,1,1,5,5,5,5,5,5,1,1,1,1,1
1,1,1,1,1,5,5,5,5,5,1,1,1,1,1,1,1,1,1,1,1,5,5,5,5,5,1,1,1,1,1
1,1,1,1,1,1,6,6,1,1,1,1,1,1,1,1,1,1,1,1,1,1,1,6,6,1,1,1,1,1,1
1,1,1,1,1,1,1,1,1,1,1,1,1,1,1,1,1,1,1,1,1,1,1,1,1,1,1,1,1,1,1
1,1,1,1,1,1,1,1,1,1,1,1,1,1,1,1,1,1,1,1,1,1,1,1,1,1,1,1,1,1,1
1,1,1,1,1,1,1,1,1,1,1,1,1,1,1,1,1,1,1,1,1,1,1,1,1,1,1,1,1,1,1
1,1,1,1,1,1,1,1,1,1,1,1,1,1,1,1,1,1,1,1,1,1,1,1,1,1,1,1,1,1,1
1,1,1,6,6,1,1,1,1,1,1,1,1,1,1,1,1,1,1,1,1,1,1,1,1,1,6,6,1,1,1
1,1,5,5,5,5,5,1,1,1,1,1,1,1,1,1,1,1,1,1,1,1,1,1,5,5,5,5,5,1,1
1,1,5,5,5,5,5,5,1,1,1,1,1,1,1,1,1,1,1,1,1,1,1,5,5,5,5,5,5,1,1
1,1,5,5,5,5,5,1,1,1,1,1,1,1,1,1,1,1,1,1,1,1,1,1,5,5,5,5,5,1,1
1,1,1,6,6,1,1,1,1,1,1,1,1,1,1,1,1,1,1,1,1,1,1,1,1,1,6,6,1,1,1
1,1,1,1,1,1,1,1,1,1,1,1,1,1,1,1,1,1,1,1,1,1,1,1,1,1,1,1,1,1,1
1,1,1,1,1,1,1,1,1,1,1,1,1,1,1,1,1,1,1,1,1,1,1,1,1,1,1,1,1,1,1
1,1,1,1,1,1,1,1,1,1,1,1,1,1,1,1,1,1,1,1,1,1,1,1,1,1,1,1,1,1,1
1,1,1,1,1,1,1,1,1,1,1,1,1,1,1,1,1,1,1,1,1,1,1,1,1,1,1,1,1,1,1
1,1,1,1,1,1,1,1,1,1,1,1,1,1,1,1,1,1,1,1,1,1,1,1,1,1,1,1,1,1,1
1,1,1,1,1,1,1,1,1,1,1,1,1,1,1,1,1,1,1,1,1,1,1,1,1,1,1,1,1,1,1
1,1,1,1,1,1,1,1,1,1,1,1,1,1,8,0,0,4,1,1,1,1,1,1,1,1,1,1,1,1,1
1,1,1,1,1,1,1,1,1,1,1,1,1,1,0,0,0,3,1,1,1,1,1,1,1,1,1,1,1,1,1
1,1,1,1,1,1,1,1,1,1,1,1,1,1,0,0,7,4,1,1,1,1,1,1,1,1,1,1,1,1,1
1,1,1,1,1,1,1,1,1,1,1,1,1,1,1,1,1,1,1,1,1,1,1,1,1,1,1,1,1,1,1
1,1,1,1,1,1,1,1,1,1,1,1,1,1,1,1,1,1,1,1,1,1,1,1,1,1,1,1,1,1,1
1,1,1,1,1,1,1,1,1,1,1,1,1,1,1,1,1,1,1,1,1,1,1,1,1,1,1,1,1,1,1
1,1,1,1,1,1,1,1,1,1,1,1,1,1,1,1,1,1,1,1,1,1,1,1,1,1,1,1,1,1,1
:endlayer
layer: 4
1,1,1,1,1,1,1,1,1,1,1,1,1,1,1,1,1,1,1,1,1,1,1,1,1,1,1,1,1,1,1
1,1,1,1,1,1,1,1,1,1,1,1,1,1,1,1,1,1,1,1,1,1,1,1,1,1,1,1,1,1,1
1,1,1,1,1,1,1,1,1,1,1,1,1,1,1,1,1,1,1,1,1,1,1,1,1,1,1,1,1,1,1
1,1,1,1,1,1,1,1,1,1,1,1,1,1,1,1,1,1,1,1,1,1,1,1,1,1,1,1,1,1,1
1,1,1,1,1,1,1,1,1,1,1,1,1,1,1,1,1,1,1,1,1,1,1,1,1,1,1,1,1,1,1
1,1,1,1,1,1,1,1,1,1,1,1,1,2,1,1,1,1,1,1,1,1,1,1,1,1,1,1,1,1,1
1,1,1,1,1,1,1,1,1,1,1,1,1,2,1,1,1,1,1,1,1,1,1,1,1,1,1,1,1,1,1
1,1,1,1,1,1,1,1,1,1,1,1,1,1,1,1,1,1,1,1,1,1,1,1,1,1,1,1,1,1,1
1,1,1,1,1,1,1,1,1,1,1,1,1,1,1,1,1,1,1,1,1,1,1,1,1,1,1,1,1,1,1
1,1,1,1,1,1,1,1,1,1,1,1,1,1,1,1,1,1,1,1,1,1,1,1,1,1,1,1,1,1,1
1,1,1,1,1,1,1,1,1,1,1,1,1,1,1,1,1,1,1,1,1,1,1,1,1,1,1,1,1,1,1
1,1,1,1,1,1,9,9,1,1,1,1,1,1,1,1,1,1,1,1,1,1,1,9,9,1,1,1,1,1,1
1,1,1,1,1,9,0,0,9,9,9,1,1,1,1,1,1,1,1,1,9,9,9,0,0,9,1,1,1,1,1
1,1,1,1,9,26,0,25,0,0,9,1,1,1,1,1,1,1,1,1,9,0,19,0,0,15,9,1,1,1,1
1,1,1,1,9,11,0,13,23,0,0,5,2,1,1,1,1,1,2,5,0,0,20,13,0,11,9,1,1,1,1
1,1,1,1,9,27,0,0,24,0,9,1,1,1,1,1,1,1,1,1,9,0,0,18,0,16,9,1,1,1,1
1,1,1,1,1,9,0,0,9,9,9,1,1,1,1,1,1,1,1,1,9,9,9,0,0,9,1,1,1,1,1
1,1,1,1,1,1,9,9,1,1,1,1,1,1,1,1,1,1,1,1,1,1,1,9,9,1,1,1,1,1,1
1,1,1,1,1,1,1,1,1,1,1,1,1,1,1,1,1,1,1,1,1,1,1,1,1,1,1,1,1,1,1
1,1,1,1,1,1,1,1,1,1,1,1,1,1,1,1,1,1,1,1,1,1,1,1,1,1,1,1,1,1,1
1,1,1,9,9,1,1,1,1,1,1,1,1,1,1,1,1,1,1,1,1,1,1,1,1,1,9,9,1,1,1
1,1,9,0,0,9,9,9,1,1,1,1,1,1,1,1,1,1,1,1,1,1,1,9,9,9,0,0,9,1,1
1,9,31,0,29,0,0,9,1,1,1,1,1,1,1,1,1,1,1,1,1,1,1,9,0,0,0,0,10,9,1
1,9,11,0,13,28,0,0,5,2,1,1,1,1,1,1,1,1,1,1,1,1,5,0,0,17,13,0,11,9,1
1,9,32,0,30,0,0,9,1,1,1,1,1,1,1,1,1,1,1,1,1,1,1,9,0,0,14,0,12,9,1
1,1,9,0,0,9,9,9,1,1,1,1,1,1,1,1,1,1,1,1,1,1,1,9,9,9,0,0,9,1,1
1,1,1,9,9,1,1,1,1,1,1,1,1,1,1,1,1,1,1,1,1,1,1,1,1,1,9,9,1,1,1
1,1,1,1,1,1,1,1,1,1,1,1,1,1,1,1,1,1,1,1,1,1,1,1,1,1,1,1,1,1,1
1,1,1,1,1,1,1,1,1,1,1,1,1,1,1,1,1,1,1,1,1,1,1,1,1,1,1,1,1,1,1
1,1,1,1,1,1,1,1,1,1,1,1,1,1,1,1,1,1,1,1,1,1,1,1,1,1,1,1,1,1,1
1,1,1,1,1,1,1,1,1,1,1,1,1,1,1,1,1,1,1,1,1,1,1,1,1,1,1,1,1,1,1
1,1,1,1,1,1,1,1,1,1,1,1,1,1,1,1,1,1,1,1,1,1,1,1,1,1,1,1,1,1,1
1,1,1,1,1,1,1,1,1,1,1,1,1,1,0,0,0,3,1,1,1,1,1,1,1,1,1,1,1,1,1
1,1,1,1,1,1,1,1,1,1,1,1,1,1,0,0,0,21,3,1,1,1,1,1,1,1,1,1,1,1,1
1,1,1,1,1,1,1,1,1,1,1,1,1,1,0,0,0,22,1,1,1,1,1,1,1,1,1,1,1,1,1
1,1,1,1,1,1,1,1,1,1,1,1,1,1,1,1,1,1,1,1,1,1,1,1,1,1,1,1,1,1,1
1,1,1,1,1,1,1,1,1,1,1,1,1,1,1,1,1,1,1,1,1,1,1,1,1,1,1,1,1,1,1
1,1,1,1,1,1,1,1,1,1,1,1,1,1,1,1,1,1,1,1,1,1,1,1,1,1,1,1,1,1,1
1,1,1,1,1,1,1,1,1,1,1,1,1,1,1,1,1,1,1,1,1,1,1,1,1,1,1,1,1,1,1
:endlayer
layer: 5
2,2,2,2,2,2,2,2,2,2,2,2,2,2,2,2,2,2,2,2,2,2,2,2,2,2,2,2,2,2,2
2,2,2,2,2,2,2,2,2,2,2,2,2,1,1,1,1,1,1,2,2,2,2,2,2,2,2,2,2,2,2
2,2,2,2,2,2,2,2,2,2,2,1,1,1,1,1,1,1,34,1,2,2,2,2,2,2,2,2,2,2,2
2,2,2,2,2,2,1,1,2,2,2,1,1,1,5,5,5,1,1,1,2,2,2,2,2,2,2,2,2,2,2
2,2,2,2,2,2,1,1,2,2,1,1,1,1,5,5,5,1,1,1,1,2,2,2,2,1,1,2,2,2,2
2,2,2,2,2,2,2,2,2,2,1,1,1,6,5,5,5,5,1,1,1,1,2,2,2,1,1,2,2,2,2
2,2,2,2,2,2,2,2,2,2,1,1,1,6,5,5,5,5,1,1,1,1,2,2,2,2,2,2,2,2,2
2,2,2,2,1,1,2,2,2,2,1,1,1,5,5,5,5,5,1,1,1,2,2,2,2,2,2,2,2,2,2
2,2,2,2,1,1,2,2,2,1,1,1,1,1,1,5,1,1,1,1,2,2,2,2,2,2,2,2,2,2,2
2,2,2,2,2,2,2,2,2,1,1,2,1,1,1,5,1,1,1,2,1,1,2,2,2,2,2,2,2,2,2
2,2,2,2,2,2,2,2,2,2,2,2,1,1,1,5,1,1,1,2,1,1,2,2,2,2,2,2,2,2,2
2,2,2,2,2,2,9,9,2,2,2,2,2,2,2,3,2,2,2,2,2,2,2,9,9,2,2,2,2,2,2
2,2,2,2,2,9,0,0,9,9,9,2,2,2,2,4,2,2,2,2,9,9,9,0,0,9,2,2,2,2,2
2,2,2,2,9,0,0,0,0,0,9,2,2,33,33,33,3,4,2,2,9,0,0,0,0,0,9,1,1,2,2
2,2,2,2,9,0,0,13,0,0,0,0,0,3,33,33,33,3,0,0,0,0,0,13,0,0,9,1,1,2,2
2,2,2,2,9,0,0,0,0,0,9,2,2,2,33,33,4,2,2,2,9,0,0,0,0,0,9,2,2,2,2
2,2,2,2,2,9,0,0,9,9,9,2,2,2,4,3,33,2,2,2,9,9,9,0,0,9,2,2,2,2,2
2,2,2,1,1,2,9,9,2,2,2,2,4,3,3,4,3,3,33,2,2,2,2,9,9,2,2,2,2,2,2
2,2,2,1,1,2,2,2,2,2,2,2,3,4,2,2,2,3,4,2,2,2,2,2,2,2,2,1,1,2,2
2,2,2,2,2,2,2,2,2,2,2,2,4,2,1,36,1,2,33,33,2,1,1,2,2,2,2,1,1,2,2
2,2,2,9,9,2,2,2,2,2,2,2,3,2,1,1,1,2,33,2,2,1,1,2,2,2,9,9,2,2,2
2,2,9,0,0,9,9,9,2,2,2,2,4,2,1,1,1,2,3,2,2,2,2,9,9,9,0,0,9,2,2
2,9,0,0,0,0,0,9,2,2,2,2,3,3,2,2,2,4,3,2,2,33,2,9,0,0,0,0,0,9,2
2,9,0,0,13,0,0,0,0,0,4,33,33,33,33,3,3,33,33,33,33,2,0,0,0,0,13,0,0,9,2
2,9,0,0,0,0,0,9,2,2,3,2,33,2,33,3,1,3,33,3,4,2,2,9,0,0,0,0,0,9,2
2,2,9,0,0,9,9,9,2,2,33,3,33,33,33,3,3,1,3,33,4,2,2,9,9,9,0,0,9,2,2
2,2,2,9,9,2,2,2,2,2,2,4,33,2,1,3,35,1,2,4,33,2,2,2,2,2,9,9,2,2,2
2,2,2,2,2,2,2,2,1,1,2,3,33,33,33,1,1,1,3,2,33,2,2,2,2,2,2,2,2,2,2
2,2,2,2,2,2,2,2,1,1,2,2,2,2,2,33,4,33,3,33,4,2,2,2,2,2,2,2,2,2,2
2,2,2,2,2,2,2,2,2,2,2,2,2,2,2,33,2,2,2,2,2,2,2,2,2,2,2,1,1,2,2
2,2,2,1,1,2,2,2,2,2,2,2,2,2,1,3,1,2,2,2,2,2,2,2,2,2,2,1,1,2,2
2,2,2,1,1,2,2,2,2,2,2,2,2,4,3,3,3,4,2,2,2,2,2,2,2,2,2,2,2,2,2
2,2,2,2,2,2,2,2,2,2,2,2,1,3,3,3,4,21,3,2,2,2,2,2,2,2,2,2,2,2,2
2,2,2,2,2,2,2,2,2,2,2,2,1,3,3,4,1,0,3,2,2,2,2,2,2,2,2,2,2,2,2
2,2,2,2,2,2,2,2,2,2,2,2,1,4,3,0,0,0,1,2,2,2,2,2,2,2,2,2,2,2,2
2,2,2,2,2,2,1,1,2,2,2,2,2,1,2,1,1,1,2,2,2,2,2,2,2,2,1,1,2,2,2
2,2,2,2,2,2,1,1,2,2,2,2,2,2,1,1,1,2,2,2,2,2,2,2,2,2,1,1,2,2,2
2,2,2,2,2,2,2,2,2,2,2,2,2,2,2,2,2,2,2,2,2,2,2,2,2,2,2,2,2,2,2
2,2,2,2,2,2,2,2,2,2,2,2,2,2,2,2,2,2,2,2,2,2,2,2,2,2,2,2,2,2,2
:endlayer
layer: 6
0,0,0,0,0,0,37,37,37,0,0,0,0,0,0,0,0,0,0,0,0,0,0,37,37,37,37,0,37,0,0
0,0,0,37,37,37,37,37,37,0,0,0,0,2,2,2,2,2,2,0,0,0,0,0,0,0,37,37,0,0,0
0,0,0,0,0,37,37,0,0,0,0,34,34,2,3,3,3,2,34,34,0,0,0,0,0,37,37,37,0,0,0
0,37,0,0,37,37,34,34,37,0,0,34,1,3,44,0,44,3,34,34,0,0,0,0,0,0,0,0,0,0,0
0,0,0,0,0,37,34,34,0,37,2,2,3,4,0,0,0,3,3,2,2,37,0,0,37,34,34,0,0,0,0
0,0,0,0,37,0,37,37,0,0,2,2,3,0,48,13,45,41,3,2,2,2,37,37,37,34,34,0,0,0,0
0,0,0,37,0,0,37,0,0,0,2,2,3,0,0,0,0,11,3,2,2,2,0,37,0,37,37,37,0,0,0
0,37,37,37,34,34,0,0,0,37,2,2,3,50,0,0,0,42,3,2,2,0,37,37,37,37,0,37,0,0,0
0,0,37,0,34,34,37,0,0,34,34,2,2,3,3,0,3,3,2,2,0,0,0,37,0,0,37,37,0,0,0
0,37,37,37,0,0,0,0,0,34,34,0,2,2,2,0,2,2,2,0,34,34,0,0,0,0,0,0,0,0,0
37,37,0,37,0,0,0,0,0,0,0,0,2,2,2,0,2,2,2,0,34,34,0,0,0,0,37,37,37,37,0
0,37,37,0,37,13,13,13,13,37,37,37,0,0,0,0,0,0,0,0,37,37,13,13,13,13,37,0,0,37,0
0,0,0,0,13,13,0,0,13,13,13,37,0,0,0,0,0,0,0,37,13,13,13,0,0,13,13,0,37,37,37
0,0,0,0,13,0,0,0,0,0,9,13,0,0,0,0,0,0,0,13,9,0,0,0,0,0,13,34,34,37,37
37,37,0,0,13,0,0,13,0,0,0,0,0,0,0,0,0,0,0,0,0,0,0,13,0,0,13,34,34,37,37
37,37,37,37,13,0,0,0,0,0,9,13,0,0,0,0,0,0,0,13,9,0,0,0,0,0,13,0,0,37,37
0,37,37,37,13,13,0,0,13,13,13,37,0,0,0,0,0,0,0,37,13,13,13,0,0,13,13,0,0,0,0
37,0,37,34,34,13,13,13,13,0,37,0,0,0,0,0,0,0,0,37,37,37,13,13,13,13,37,0,0,0,0
0,37,37,34,34,0,0,0,0,0,0,0,0,43,39,39,39,43,0,0,0,0,0,0,0,0,0,34,34,0,0
0,37,0,0,0,0,0,0,0,0,0,0,0,39,3,3,3,39,0,0,0,34,34,0,0,0,0,34,34,0,0
0,37,13,13,13,13,0,37,37,0,0,0,0,39,3,3,4,39,0,0,0,34,34,37,37,13,13,13,13,37,0
0,13,13,0,0,13,13,13,37,0,0,0,0,39,3,3,3,39,0,0,0,0,37,13,13,13,0,0,13,13,0
0,13,0,0,0,0,0,9,13,0,0,0,0,43,39,39,39,43,0,0,0,0,13,9,0,0,0,0,0,13,0
0,13,0,0,13,0,0,0,0,0,0,0,0,0,0,0,0,0,0,0,0,0,0,0,0,0,13,0,0,13,0
0,13,0,0,0,0,0,9,13,0,0,0,0,0,0,0,39,0,0,0,0,0,13,9,0,0,0,0,0,13,0
0,13,13,0,0,13,13,13,37,0,0,0,0,0,0,4,3,4,0,0,0,0,0,13,13,13,0,0,13,13,0
0,37,13,13,13,13,37,37,0,0,0,0,0,0,39,3,46,3,39,0,0,0,37,37,37,13,13,13,13,37,0
0,0,0,0,0,0,37,0,34,34,0,0,0,0,0,3,3,4,0,0,0,0,0,0,0,0,0,0,0,0,0
0,0,0,0,37,37,37,0,34,34,0,0,0,0,0,0,0,0,0,0,0,0,0,0,13,13,13,13,0,37,0
37,0,0,0,37,37,37,0,0,0,0,13,0,0,0,0,0,0,13,0,0,37,37,0,13,0,0,34,34,37,0
0,37,37,34,34,37,37,37,0,0,0,0,0,0,34,0,34,0,0,0,37,37,37,0,13,37,37,34,34,37,0
0,0,0,34,34,0,37,37,0,0,0,0,0,34,0,0,0,34,40,37,37,0,13,38,13,0,37,37,13,37,37
0,0,37,37,37,37,0,37,0,0,0,0,34,51,0,0,0,0,34,0,37,37,13,37,0,0,37,37,13,13,0
0,37,37,0,0,0,0,37,37,0,0,0,34,0,0,34,6,0,34,0,37,0,13,0,37,37,37,37,0,13,37
37,37,37,37,0,0,37,37,37,37,37,37,34,0,0,3,47,0,34,0,0,37,13,0,37,0,0,37,0,13,0
37,37,37,37,0,37,34,34,37,37,37,0,0,34,49,3,3,34,0,0,0,37,13,0,0,0,34,34,13,13,0
37,0,0,0,0,0,34,34,37,37,37,0,0,0,34,34,34,0,0,0,37,37,13,0,0,13,34,34,37,0,37
0,37,0,37,37,37,37,37,37,0,0,13,0,37,37,37,37,37,0,13,0,37,13,13,13,13,37,37,37,37,0
0,0,0,0,0,0,0,0,0,0,0,0,0,37,37,37,37,0,0,0,37,0,0,37,0,0,0,0,37,37,0
:endlayer
layer: 7
0,0,0,0,0,0,0,0,0,0,0,0,0,0,0,0,0,0,0,0,0,0,0,0,0,0,0,0,0,0,0
0,0,0,0,0,0,0,0,0,0,0,0,0,0,0,0,0,0,0,0,0,0,0,0,0,0,0,0,0,0,0
0,0,0,0,0,0,0,0,0,0,0,34,34,37,3,3,3,37,34,34,0,0,0,0,0,0,0,0,0,0,0
0,0,0,0,0,0,34,34,0,0,0,34,34,3,0,0,0,4,34,34,0,0,0,0,0,0,0,0,0,0,0
0,0,0,0,0,0,34,34,0,0,37,0,3,4,0,0,0,3,3,37,37,0,0,0,0,34,34,0,0,0,0
0,0,0,0,0,0,0,0,0,0,0,37,3,0,0,13,0,0,3,37,37,37,0,0,0,34,34,0,0,0,0
0,0,0,0,0,0,0,0,0,0,37,37,3,0,0,0,0,0,4,37,37,37,0,0,0,0,0,0,0,0,0
0,0,0,0,34,34,0,0,0,0,37,37,3,0,0,0,0,0,3,0,0,0,0,0,0,0,0,0,0,0,0
0,0,0,0,34,34,0,0,0,34,34,37,66,3,3,0,4,3,61,0,0,0,0,0,0,0,0,0,0,0,0
0,0,0,0,0,0,0,0,0,34,34,0,37,37,37,0,0,37,37,0,34,34,0,0,0,0,0,0,0,0,0
0,0,0,0,0,0,0,0,0,0,0,0,0,0,0,0,0,0,0,0,34,34,0,0,0,0,0,0,0,0,0
0,0,0,0,0,52,9,9,52,0,0,0,0,0,0,0,0,0,0,0,0,0,52,9,9,52,0,0,0,0,0
0,0,0,0,9,9,74,0,9,9,9,0,0,0,0,0,0,0,0,0,9,9,9,0,54,9,9,0,0,0,0
0,0,0,0,9,0,0,0,0,0,9,67,0,0,0,0,0,0,0,58,9,0,0,0,0,0,9,34,34,0,0
0,0,0,0,9,0,0,13,0,0,71,0,0,0,0,0,0,0,0,0,55,0,0,13,0,0,9,34,34,0,0
0,0,0,0,9,0,0,0,0,0,9,68,0,0,0,0,0,0,0,59,9,0,0,0,0,0,9,0,0,0,0
0,0,0,0,9,9,74,0,9,9,9,0,0,0,0,0,0,0,0,0,9,9,9,0,54,9,9,0,0,0,0
0,0,0,34,34,53,9,9,53,0,0,0,0,0,0,0,0,0,0,0,0,0,53,9,9,53,0,0,0,0,0
0,0,0,34,34,0,0,0,0,0,0,0,0,63,0,0,0,63,0,0,0,0,0,0,0,0,0,34,34,0,0
0,0,0,0,0,0,0,0,0,0,0,0,0,0,43,0,43,0,0,0,0,34,34,0,0,0,0,34,34,0,0
0,0,52,9,9,52,0,0,0,0,0,0,0,0,0,4,0,0,0,0,0,34,34,0,0,52,9,9,52,0,0
0,9,9,74,0,9,9,9,0,0,0,0,0,0,43,0,43,0,0,0,0,0,0,9,9,9,0,54,9,9,0
0,9,0,0,0,0,0,9,72,0,0,0,0,63,0,0,0,63,0,0,0,0,56,9,0,0,0,0,0,9,0
0,9,0,0,13,0,0,71,0,0,0,0,0,0,0,0,0,0,0,0,0,0,0,55,0,0,13,0,0,9,0
0,9,0,0,0,0,0,9,73,0,0,0,0,0,0,0,0,0,0,0,0,0,57,9,0,0,0,0,0,9,0
0,9,9,74,0,9,9,9,0,0,0,0,0,0,0,0,43,0,0,0,0,0,0,9,9,9,0,54,9,9,0
0,0,53,9,9,53,0,0,0,0,0,0,0,0,0,43,0,43,0,0,0,0,0,0,0,53,9,9,53,0,0
0,0,0,0,0,0,0,0,34,34,0,0,0,0,0,0,43,0,0,0,0,0,0,0,0,0,0,0,0,0,0
0,0,0,0,0,0,0,0,34,34,0,0,0,0,0,0,0,0,0,0,0,0,0,0,13,13,13,13,0,34,0
0,0,0,0,0,0,0,0,0,0,0,69,0,0,0,0,0,0,62,0,0,0,0,0,13,0,0,34,34,34,0
0,0,0,34,34,0,0,0,0,0,0,0,0,0,34,0,34,0,0,0,0,0,0,0,13,0,0,34,34,0,0
0,0,0,34,34,0,0,0,0,0,0,0,0,34,0,0,0,34,0,0,0,0,13,0,13,0,0,0,13,0,0
0,0,0,0,0,0,0,0,0,0,0,0,34,0,0,0,0,0,34,0,0,0,13,0,0,0,0,0,13,13,0
0,0,0,0,0,0,0,0,0,0,0,0,34,0,0,34,0,0,34,0,0,0,13,0,0,0,0,0,0,13,0
0,0,0,0,0,0,0,0,0,0,0,0,34,0,64,6,0,0,34,0,0,0,13,0,0,0,0,0,0,13,0
0,0,0,0,0,0,34,34,0,0,0,0,0,34,65,0,0,34,0,0,0,0,13,0,0,0,34,34,13,13,0
0,0,0,0,0,0,34,34,0,0,0,0,0,0,34,34,34,0,0,0,0,0,13,0,0,13,34,34,0,0,0
0,0,0,0,0,0,0,0,0,0,0,70,0,0,0,0,0,0,0,60,0,0,13,13,13,13,0,0,0,0,0
0,0,0,0,0,0,0,0,0,0,0,0,0,0,0,0,0,0,0,0,0,0,0,0,0,0,0,0,0,0,0
:endlayer
layer: 8
0,0,0,0,0,0,0,0,0,0,0,0,0,0,0,0,0,0,0,0,0,0,0,0,0,0,0,0,0,0,0
0,0,0,0,0,0,0,0,0,0,0,0,0,0,0,0,0,0,0,0,0,0,0,0,0,0,0,0,0,0,0
0,0,0,0,0,0,0,0,0,0,0,34,34,76,3,13,4,76,34,34,0,0,0,0,0,0,0,0,0,0,0
0,0,0,0,0,0,34,34,0,0,0,34,34,4,78,0,78,3,34,34,0,0,0,0,0,0,0,0,0,0,0
0,0,0,0,0,0,34,34,0,0,0,0,3,86,0,0,0,77,3,0,0,0,0,0,0,34,34,0,0,0,0
0,0,0,0,0,0,0,0,0,0,0,0,13,0,0,13,0,0,13,0,0,0,0,0,0,34,34,0,0,0,0
0,0,0,0,0,0,0,0,0,0,0,0,13,0,0,0,0,0,13,0,0,0,0,0,0,0,0,0,0,0,0
0,0,0,0,34,34,0,0,0,0,0,0,4,0,0,0,0,0,3,0,0,0,0,0,0,0,0,0,0,0,0
0,0,0,0,34,34,0,0,0,34,34,0,76,4,3,81,3,4,76,0,0,0,0,0,0,0,0,0,0,0,0
0,0,0,0,0,0,0,0,0,34,34,0,0,0,78,82,78,0,0,0,34,34,0,0,0,0,0,0,0,0,0
0,0,0,0,0,0,0,0,0,0,0,0,0,0,0,0,0,0,0,0,34,34,0,0,0,0,0,0,0,0,0
0,0,0,0,0,13,6,6,13,0,0,0,0,0,0,0,0,0,0,0,0,0,13,6,6,13,0,0,0,0,0
0,0,0,0,13,6,6,6,6,6,13,0,0,0,0,0,0,0,0,0,13,6,6,6,6,6,13,0,0,0,0
0,0,0,0,6,6,75,75,6,6,6,0,0,0,0,0,0,0,0,0,6,6,6,75,75,6,6,34,34,0,0
0,0,0,0,6,75,75,9,75,6,13,0,0,0,0,0,0,0,0,0,13,6,75,9,75,75,6,34,34,0,0
0,0,0,0,6,6,75,75,6,6,6,0,0,0,0,0,0,0,0,0,6,6,6,75,75,6,6,0,0,0,0
0,0,0,0,13,6,6,6,6,6,13,0,0,0,0,0,0,0,0,0,13,6,6,6,6,6,13,0,0,0,0
0,0,0,34,34,13,6,6,13,0,0,0,0,0,0,0,0,0,0,0,0,0,13,6,6,13,0,0,0,0,0
0,0,0,34,34,0,0,0,0,0,0,0,0,0,0,0,0,0,0,0,0,0,0,0,0,0,0,34,34,0,0
0,0,0,0,0,0,0,0,0,0,0,0,0,0,84,0,79,0,0,0,0,34,34,0,0,0,0,34,34,0,0
0,0,13,6,6,13,0,0,0,0,0,0,0,0,0,83,0,0,0,0,0,34,34,34,0,13,6,6,13,0,0
0,13,6,6,6,6,6,13,0,0,0,0,0,0,85,0,80,0,0,0,0,0,0,13,6,6,6,6,6,13,0
0,6,6,75,75,6,6,6,0,0,0,0,0,0,0,0,0,0,0,0,0,0,0,6,6,6,75,75,6,6,0
0,6,75,75,9,75,6,13,0,0,0,0,0,0,0,0,0,0,0,0,0,0,0,13,6,75,9,75,75,6,0
0,6,6,75,75,6,6,6,0,0,0,0,0,0,0,0,0,0,0,0,0,0,0,6,6,6,75,75,6,6,0
0,13,6,6,6,6,6,13,0,0,0,0,0,0,0,0,43,0,0,0,0,0,0,13,6,6,6,6,6,13,0
0,0,13,6,6,13,0,0,0,0,0,0,0,0,0,43,44,43,0,0,0,0,0,0,0,13,6,6,13,0,0
0,0,0,0,0,0,0,0,34,34,0,0,0,0,0,0,43,0,0,0,0,0,0,0,0,0,0,0,0,0,0
0,0,0,0,0,0,0,0,34,34,0,0,0,0,0,0,0,0,0,0,0,0,0,0,0,0,0,0,0,34,0
0,0,0,0,0,0,0,0,0,0,0,0,0,0,0,0,0,0,0,0,0,0,0,0,0,0,0,34,34,34,0
0,0,0,34,34,0,0,0,0,0,0,0,0,0,34,34,34,0,0,0,0,0,0,0,0,0,0,34,34,0,0
0,0,0,34,34,0,0,0,0,0,0,0,0,34,0,0,0,34,0,0,0,0,63,0,63,0,0,0,0,34,0
0,0,0,0,0,0,0,0,0,0,0,0,34,0,47,0,0,0,34,0,0,0,0,0,0,0,0,0,63,0,0
0,0,0,0,0,0,0,0,0,0,0,0,34,0,6,34,0,0,34,0,0,0,0,0,0,0,0,0,0,0,0
0,0,0,0,0,0,0,0,0,0,0,0,34,0,0,0,0,0,34,0,0,0,0,0,0,0,0,0,0,0,0
0,0,0,0,0,0,34,34,0,0,0,0,0,34,0,0,0,34,0,0,0,0,0,0,0,0,34,34,0,63,0
0,0,0,0,0,0,34,34,0,0,0,0,0,0,34,34,34,0,0,0,0,0,0,0,0,0,34,34,0,0,0
0,0,0,0,0,0,0,0,0,0,0,0,0,0,0,0,0,0,0,0,0,0,63,0,0,0,0,0,0,0,0
0,0,0,0,0,0,0,0,0,0,0,0,0,0,0,0,0,0,0,0,0,0,0,0,0,0,0,0,0,0,0
:endlayer
layer: 9
0,0,0,0,0,0,0,0,0,0,0,0,0,0,0,0,0,0,0,0,0,0,0,0,0,0,0,0,0,0,0
0,0,0,0,0,0,0,0,0,0,0,0,0,0,0,0,0,0,0,0,0,0,0,0,0,0,0,0,0,0,0
0,0,0,0,0,34,0,0,0,0,0,34,34,0,6,52,6,0,34,34,0,0,0,0,0,0,0,0,0,0,0
0,0,0,0,0,0,34,34,0,0,0,34,34,4,76,76,76,3,34,34,0,0,0,0,0,0,0,0,0,0,0
0,0,0,0,0,0,34,34,0,0,0,0,6,76,0,0,0,76,6,0,0,0,0,0,0,34,34,0,0,0,0
0,0,0,0,0,0,0,0,34,0,0,0,55,76,0,13,0,76,71,0,0,0,0,0,0,34,34,0,0,0,0
0,0,0,0,0,0,0,0,0,0,0,0,55,76,0,0,0,76,71,0,0,0,0,0,0,0,0,0,0,0,0
0,0,0,0,34,34,0,0,0,0,0,0,3,76,76,76,76,76,4,0,0,0,0,0,0,0,0,0,0,0,0
0,0,0,0,34,34,0,0,0,34,34,0,0,6,6,105,6,6,0,0,0,0,0,0,0,0,0,0,0,0,0
0,0,0,0,0,0,0,0,0,34,34,0,0,0,0,0,0,0,0,0,34,34,0,0,0,0,0,0,0,0,0
0,0,0,0,0,0,0,0,0,0,0,0,0,0,0,0,0,0,0,0,34,34,0,0,0,0,0,0,0,0,0
0,0,0,0,0,115,0,0,110,0,0,0,0,0,0,0,0,0,0,0,0,0,101,0,0,94,0,0,0,0,0
0,0,0,0,119,0,0,0,0,0,108,0,0,0,0,0,0,0,0,0,103,0,0,0,0,0,92,0,0,0,0
0,0,0,0,0,0,0,0,0,0,0,0,0,0,0,0,0,0,0,0,0,0,0,98,0,0,0,34,34,0,0
0,0,0,0,0,0,114,9,0,0,13,0,0,0,0,0,0,0,0,0,13,0,0,9,0,0,0,34,34,0,0
0,0,0,0,0,0,0,0,0,0,0,0,0,0,0,0,0,0,0,0,0,0,0,0,0,0,0,0,0,0,0
0,0,0,0,120,0,0,0,0,0,109,0,0,0,0,0,0,0,0,0,104,0,0,0,0,0,93,0,0,0,0
0,0,0,34,34,116,0,0,111,0,0,0,0,0,0,0,0,0,0,0,0,0,102,0,0,95,0,0,0,0,0
0,0,0,34,34,0,0,0,0,0,0,0,0,0,0,0,0,0,0,0,0,0,34,0,0,0,0,34,34,0,0
0,0,0,0,0,0,0,0,0,0,0,0,0,0,0,0,0,0,0,0,0,34,34,0,0,0,0,34,34,0,0
0,0,122,0,0,117,0,0,0,0,0,0,0,0,0,106,0,0,0,0,0,34,34,34,0,96,0,0,89,0,0
0,124,0,0,0,0,0,112,0,0,0,0,0,0,0,0,0,0,0,0,0,0,0,99,0,0,0,0,0,87,0
0,0,0,0,0,0,0,0,0,0,0,0,0,0,0,0,0,0,0,0,0,0,0,0,0,0,0,0,0,0,0
0,0,0,121,9,0,0,13,0,0,0,0,0,0,0,0,0,0,0,0,0,0,0,13,0,0,9,0,90,0,0
0,0,0,0,0,0,0,0,0,0,0,0,0,0,0,0,0,0,0,0,0,0,0,0,0,0,0,0,0,0,0
0,125,0,0,0,0,0,113,0,0,0,0,0,0,0,43,43,43,0,0,0,0,0,100,0,0,0,0,0,88,0
0,0,123,0,0,118,0,0,0,0,0,0,0,0,0,43,0,43,0,0,0,0,0,0,0,97,0,0,91,0,0
0,0,0,0,0,0,0,0,34,34,0,0,0,0,0,43,43,43,0,0,0,0,0,0,0,0,0,0,0,0,0
0,0,0,0,0,0,0,0,34,34,0,0,0,0,0,0,0,0,0,0,0,0,0,0,0,0,0,34,34,34,0
0,0,0,0,0,0,0,0,0,0,0,0,0,0,0,107,0,0,0,0,0,0,0,0,0,0,0,34,34,34,0
0,0,0,34,34,0,0,0,0,0,0,0,0,0,34,9,34,0,0,0,0,0,0,0,0,0,0,0,0,0,0
0,0,0,34,34,0,0,0,0,0,0,0,54,9,0,0,0,34,74,0,0,0,0,0,0,0,0,0,0,34,0
0,0,0,0,0,34,0,0,0,0,0,0,34,0,0,6,47,0,34,0,0,0,0,0,0,0,0,0,0,0,0
0,0,0,0,0,0,0,0,0,0,0,0,9,0,0,34,0,0,34,0,0,0,0,0,0,0,0,0,0,0,0
0,0,0,0,0,0,0,0,0,0,0,0,34,0,0,0,0,0,34,74,0,0,0,0,0,0,0,0,0,0,0
0,0,0,0,0,0,34,34,0,0,0,0,0,9,0,0,0,9,0,0,0,0,0,0,0,0,34,34,0,0,0
0,0,0,0,0,0,34,34,0,0,0,0,0,54,34,9,34,0,0,0,0,0,0,0,0,0,34,34,0,0,0
0,0,0,0,0,0,0,0,0,0,0,0,0,0,0,0,0,0,0,0,0,0,0,0,0,0,0,0,0,0,0
0,0,0,0,0,0,0,0,0,0,0,0,0,0,0,0,0,0,0,0,0,0,0,0,0,0,0,0,0,0,0
:endlayer
layer: 10
0,0,0,0,0,0,0,0,0,0,0,0,0,0,0,0,0,0,0,0,0,0,0,0,0,0,0,0,0,0,0
0,0,0,0,0,0,0,0,0,0,0,0,0,0,0,0,0,0,0,0,0,0,0,0,0,0,0,0,0,0,0
0,0,0,0,0,34,0,0,0,0,0,34,34,0,0,0,0,0,34,34,0,0,0,0,0,0,0,0,0,0,0
0,0,0,0,0,0,34,34,0,0,0,34,34,13,0,129,0,13,34,34,0,0,0,0,0,0,0,34,0,0,0
0,0,0,0,0,0,34,34,0,0,0,0,0,0,6,130,6,0,0,0,0,0,0,0,34,34,34,0,0,0,0
0,0,0,0,0,0,0,34,34,0,0,0,0,0,133,3,65,0,0,0,0,0,0,0,0,34,34,34,0,0,0
0,0,0,0,0,34,0,0,0,0,0,0,0,0,6,64,6,0,0,0,0,0,0,0,0,0,0,0,0,0,0
0,0,0,0,34,34,0,0,0,0,0,0,13,0,0,0,0,0,13,0,0,0,0,0,0,0,0,0,0,0,0
0,0,0,34,34,34,0,0,0,34,34,0,0,0,0,131,0,0,0,0,0,0,0,0,0,0,0,0,0,0,0
0,0,0,0,0,0,0,0,0,34,34,0,0,0,0,0,0,0,0,0,34,34,0,0,0,0,0,0,0,0,0
0,0,0,0,0,0,0,0,0,0,0,0,0,0,0,0,0,0,0,0,34,34,0,0,0,0,0,0,0,0,0
0,0,0,0,0,0,0,0,0,0,0,0,0,0,0,0,0,0,0,0,0,0,0,0,0,0,0,0,0,0,0
0,0,0,0,0,0,0,0,0,0,0,0,0,0,0,0,0,0,0,0,0,0,0,0,0,0,0,0,0,0,0
0,0,0,0,0,0,0,0,0,0,0,0,0,0,0,0,0,0,0,0,0,0,0,0,0,0,0,34,34,0,0
0,0,0,0,0,0,0,13,0,0,134,0,0,0,0,0,0,0,0,0,128,0,0,13,0,0,0,34,34,0,0
0,0,0,0,0,0,0,0,0,0,0,0,0,0,0,0,0,0,0,0,0,0,0,0,0,0,0,0,0,0,0
0,0,0,0,0,0,0,0,0,0,0,0,0,0,0,0,0,0,0,0,0,0,0,0,0,0,0,0,0,0,0
0,0,0,34,34,0,0,0,0,0,0,0,0,0,0,0,0,0,0,0,0,0,0,0,0,0,0,0,0,0,0
0,0,0,34,34,0,0,0,0,0,0,0,0,0,0,0,0,0,0,0,0,34,34,0,0,0,0,34,34,0,0
0,0,0,0,0,0,0,0,0,0,0,0,0,0,0,0,0,0,0,0,0,34,34,0,0,0,0,34,34,0,0
0,0,0,0,0,0,0,0,0,0,0,0,0,0,0,132,0,0,0,0,0,34,34,34,0,0,0,0,0,0,0
0,0,0,0,0,0,0,0,0,0,0,0,0,0,0,0,0,0,0,0,0,0,0,34,0,0,0,0,0,0,0
0,0,0,0,0,0,0,0,0,0,0,0,0,0,0,0,0,0,0,0,0,0,0,0,0,0,0,0,0,0,0
0,0,0,0,13,0,0,135,0,0,0,0,0,0,0,0,0,0,0,0,0,0,0,127,0,0,13,0,0,0,0
0,0,0,0,0,0,0,0,0,0,0,0,0,0,0,0,0,0,0,0,0,0,0,0,0,0,0,0,0,0,0
0,0,0,0,0,0,0,0,0,0,0,0,0,0,0,43,43,43,0,0,0,0,0,0,0,0,0,0,126,126,126
0,0,0,0,0,0,0,0,0,0,0,0,0,0,0,43,0,43,0,0,0,0,0,0,0,126,126,126,126,126,126
0,0,0,0,0,0,0,0,34,34,0,0,0,0,0,43,43,43,0,0,0,0,0,0,0,126,126,126,126,126,126
0,0,0,0,0,0,0,0,34,34,0,0,0,0,13,0,13,0,0,0,0,0,0,0,0,126,126,34,34,34,126
0,0,0,34,0,0,0,0,0,0,0,0,0,0,13,0,13,0,0,0,0,0,0,0,0,126,126,34,34,34,126
0,0,0,34,34,0,0,0,0,0,0,0,0,0,9,9,9,0,0,0,0,0,0,0,0,126,126,126,126,126,126
0,0,0,34,34,34,0,0,0,0,0,0,0,9,0,0,0,34,0,0,0,0,0,0,0,126,126,126,126,34,126
0,0,0,0,0,34,0,0,0,0,0,13,9,0,0,0,0,0,34,13,0,0,0,0,0,0,0,0,126,126,126
0,0,0,0,0,0,0,0,0,0,0,0,9,0,0,34,6,0,9,0,0,0,0,0,0,0,0,0,0,0,0
0,0,0,0,0,34,0,34,0,0,0,13,9,0,0,0,47,0,9,13,0,0,0,0,0,0,0,0,0,0,0
0,0,0,0,0,0,34,34,0,0,0,0,0,9,0,0,0,9,0,0,0,0,0,0,0,0,34,34,0,0,0
0,0,0,0,0,34,34,34,34,0,0,0,0,0,9,9,9,0,0,0,0,0,0,0,0,0,34,34,0,0,0
0,0,0,0,0,0,0,0,0,0,0,0,0,0,13,0,13,0,0,0,0,0,0,0,0,0,0,0,0,0,0
0,0,0,0,0,0,0,0,0,0,0,0,0,0,13,0,13,0,0,0,0,0,0,0,0,0,0,0,0,0,0
:endlayer
layer: 11
0,0,0,0,0,0,0,0,0,0,0,0,0,0,0,0,0,0,0,0,0,0,0,0,0,0,0,0,0,0,0
0,0,0,0,126,126,126,0,0,0,0,0,0,0,0,0,0,0,0,0,0,0,0,0,0,0,0,0,0,0,0
0,0,0,126,126,34,126,126,126,126,0,34,34,138,0,0,0,0,34,34,0,0,0,0,0,0,126,126,126,0,0
0,0,0,126,126,126,34,34,126,126,0,34,34,143,0,0,0,141,34,34,0,0,0,126,126,126,126,34,126,126,0
0,0,0,126,126,126,34,34,126,126,0,0,0,0,0,0,0,0,0,0,0,0,126,126,34,126,126,126,126,126,0
0,0,0,0,126,126,126,34,34,126,126,0,0,0,0,13,0,0,0,0,0,0,126,126,126,34,34,34,126,126,0
0,0,0,0,126,34,126,126,126,126,126,0,0,0,0,0,0,0,0,0,0,0,126,126,126,34,34,126,126,126,0
0,0,0,0,34,34,126,126,126,126,126,0,144,0,0,0,0,0,140,0,0,0,0,126,126,126,126,126,126,126,0
0,0,0,34,34,34,126,126,126,34,34,0,0,0,0,0,0,0,0,0,0,0,0,126,126,126,126,126,126,0,0
0,0,0,0,0,34,0,0,0,34,34,0,0,0,0,0,0,0,0,0,34,34,0,0,0,0,0,0,0,0,0
0,0,0,0,0,0,0,0,0,0,0,0,0,0,0,0,0,0,0,0,34,34,0,0,0,0,0,0,0,0,0
0,0,0,0,0,0,0,0,0,0,0,0,0,0,0,0,0,0,0,0,0,0,0,0,0,0,0,0,0,0,0
0,0,0,0,0,0,0,0,0,0,0,0,0,0,0,0,0,0,0,0,0,0,0,0,0,0,0,0,0,0,0
0,0,0,0,0,0,0,0,0,0,0,0,0,0,0,0,0,0,0,0,0,0,0,0,0,0,0,34,34,0,0
0,0,0,0,0,0,0,145,0,0,0,0,0,0,0,0,0,0,0,0,0,0,0,139,0,0,0,34,34,0,0
0,0,0,0,0,0,0,0,0,0,0,0,0,0,0,0,0,0,0,0,0,0,0,0,0,0,0,0,0,0,0
0,0,0,0,0,0,0,0,0,0,0,0,0,0,0,0,0,0,0,126,126,126,126,0,0,0,0,0,0,0,0
0,0,0,34,34,0,0,0,0,0,0,0,0,0,0,0,0,0,126,126,126,126,126,126,0,0,0,0,0,0,0
0,0,0,34,34,0,0,0,0,0,0,0,0,0,0,0,0,0,126,126,126,34,34,126,0,0,0,34,34,0,0
0,0,0,0,0,0,0,0,0,0,0,0,0,0,0,0,0,0,126,126,34,34,126,126,126,0,0,34,34,0,0
0,0,0,0,0,0,0,0,0,0,0,0,0,0,0,0,0,0,126,126,34,34,126,34,126,0,0,0,0,0,0
0,0,0,0,0,0,0,0,0,0,0,0,0,0,0,0,0,0,126,126,126,126,126,34,126,0,0,0,0,0,0
0,0,0,0,0,0,0,0,0,0,0,0,0,0,0,0,0,0,126,126,126,126,126,126,126,0,0,0,0,0,0
0,0,0,0,146,0,0,0,0,0,0,0,0,0,0,0,0,0,0,0,0,126,126,126,0,0,137,0,136,0,0
0,0,0,0,0,0,0,0,0,0,0,0,0,0,0,0,0,0,0,0,0,0,0,0,138,138,138,136,136,0,0
0,0,0,0,0,0,0,0,0,0,0,0,0,0,0,0,43,0,0,0,0,0,0,0,138,126,126,126,126,126,0
0,0,0,0,0,0,0,0,0,0,0,0,0,0,0,0,43,142,0,0,0,0,0,0,126,126,126,126,126,126,126
0,0,0,0,0,0,0,0,34,34,0,0,0,0,0,0,43,0,0,0,0,0,0,138,126,126,126,126,126,126,126
0,0,0,0,0,0,0,0,34,34,0,0,0,0,13,0,13,0,0,0,0,0,0,138,126,126,126,34,34,126,126
0,0,0,34,34,0,0,0,0,0,0,0,0,0,0,0,0,0,0,0,0,0,0,138,126,126,126,34,34,126,126
0,0,0,34,34,0,0,0,0,0,0,0,9,47,9,9,9,9,0,0,0,0,0,138,126,126,126,126,126,126,126
0,0,0,34,34,34,0,0,0,0,0,0,47,9,47,47,47,9,9,0,0,0,0,138,136,126,126,126,126,126,126
0,0,0,0,34,34,0,0,0,0,0,0,9,47,0,0,0,47,9,0,0,0,0,0,136,0,126,126,126,126,0
0,0,0,0,0,0,0,0,0,0,0,0,9,47,0,34,0,47,9,0,0,0,0,0,0,0,0,0,0,0,0
0,0,0,0,0,34,0,34,0,0,0,0,9,47,47,6,0,47,9,0,0,0,0,0,0,0,0,0,0,0,0
0,0,0,0,0,0,34,34,34,0,0,0,47,9,47,47,47,9,47,0,0,0,0,0,0,0,34,34,0,0,0
0,0,0,0,0,34,34,34,34,0,0,0,0,47,9,9,9,47,0,0,0,0,0,0,0,0,34,34,0,0,0
0,0,0,0,0,0,0,34,0,0,0,0,0,0,0,0,0,0,0,0,0,0,0,0,0,0,0,0,0,0,0
0,0,0,0,0,0,0,0,0,0,0,0,0,0,13,0,13,0,0,0,0,0,0,0,0,0,0,0,0,0,0
:endlayer
layer: 12
0,0,0,0,0,0,0,0,0,0,0,0,0,0,0,0,0,0,0,0,0,0,0,0,0,0,0,0,0,0,0
0,0,0,0,126,126,126,126,126,0,138,138,138,138,138,0,138,138,138,138,138,0,0,0,0,0,0,0,0,0,0
0,0,0,126,126,126,126,126,126,126,138,34,34,138,138,138,138,138,34,34,138,138,0,126,126,126,126,126,0,0,0
0,0,0,126,126,126,126,126,126,126,126,34,34,138,138,138,0,0,34,34,138,138,126,126,126,126,126,126,126,126,0
0,0,0,126,126,126,34,34,126,126,126,138,138,138,138,0,0,0,0,138,138,138,126,126,126,126,126,126,126,126,0
0,0,126,126,126,126,34,34,126,126,126,136,136,138,0,13,0,0,0,138,138,138,126,126,126,34,34,126,126,126,0
0,0,126,126,126,34,126,126,126,126,126,136,136,138,0,0,0,0,0,136,136,136,126,126,126,34,34,126,126,126,0
0,126,126,126,34,34,126,126,126,126,0,136,136,138,0,0,0,0,0,136,136,136,126,126,126,126,126,126,126,126,0
0,126,126,34,34,34,126,126,126,34,34,138,138,138,0,0,0,0,0,138,138,138,138,126,126,126,126,126,0,0,0
0,126,126,126,126,34,126,126,138,34,34,0,0,0,0,0,0,0,0,0,34,34,138,126,126,126,126,126,138,0,0
0,0,126,126,126,126,126,126,138,138,0,0,0,0,0,0,0,0,0,0,34,34,138,138,0,0,0,0,0,0,0
0,0,0,0,126,126,126,0,138,138,0,0,0,0,0,0,0,0,0,0,0,0,0,0,0,0,0,0,0,0,0
0,0,0,0,0,0,0,0,0,0,0,0,0,0,0,0,0,0,0,0,0,0,0,0,0,0,0,0,0,0,0
0,0,0,0,0,0,0,0,0,0,0,0,0,0,0,0,0,0,0,0,0,0,0,0,138,138,0,34,34,0,0
0,0,0,0,0,0,0,0,0,0,0,0,0,0,0,0,0,0,0,0,0,0,0,0,136,136,0,34,34,0,0
0,0,0,0,0,0,0,0,0,0,0,0,0,0,0,0,0,0,0,0,0,0,0,0,0,138,138,0,0,0,0
0,0,0,0,0,0,0,0,0,0,0,0,0,0,0,0,0,0,126,126,126,126,126,0,0,138,138,0,0,0,0
0,0,0,34,34,0,0,0,0,0,0,0,0,0,0,0,0,126,126,126,126,126,126,126,126,138,138,0,0,0,0
0,0,0,34,34,0,0,0,0,0,0,0,0,0,0,0,0,126,126,126,126,126,126,126,126,138,138,34,34,0,0
0,0,0,0,0,0,0,0,0,0,0,0,0,0,0,0,0,126,126,126,34,34,126,126,126,0,138,34,34,0,0
0,0,0,0,0,0,0,0,0,0,0,0,0,0,0,0,0,126,126,126,34,34,126,126,126,0,138,138,0,0,0
0,0,0,0,0,0,0,0,0,0,0,0,0,0,0,0,0,126,126,126,126,126,126,126,126,0,138,138,0,0,0
0,0,0,0,0,0,0,0,0,0,0,0,0,0,0,0,0,0,126,126,126,126,126,126,0,0,138,138,138,0,0
0,0,0,0,0,0,0,0,0,0,0,0,0,0,0,0,0,0,126,126,126,126,126,0,0,0,138,138,138,0,0
0,0,0,0,0,0,0,0,0,0,0,0,0,0,0,0,0,0,0,0,0,0,0,0,0,138,138,138,0,0,0
0,0,0,0,0,0,0,0,0,0,0,0,0,0,0,0,0,0,0,0,0,0,0,0,0,0,138,138,0,0,0
0,0,0,0,0,0,0,0,0,138,138,0,0,0,0,0,0,0,0,0,0,0,0,0,0,0,138,126,126,0,0
0,0,126,126,126,126,0,0,34,34,0,0,0,0,0,0,0,0,0,0,0,0,0,0,0,0,126,126,126,126,0
0,126,126,126,126,126,126,0,34,34,138,138,0,0,149,0,147,0,0,0,0,0,0,0,0,126,126,126,126,126,126
0,126,126,34,34,126,126,0,0,0,0,0,0,0,52,6,52,0,0,0,0,0,0,0,0,126,126,126,126,126,126
0,126,126,34,34,126,126,126,138,0,0,0,9,13,0,0,0,13,0,0,0,0,0,0,0,0,126,126,126,126,0
0,126,126,34,34,34,126,126,0,0,0,0,13,0,0,0,0,0,9,0,0,0,0,0,0,0,0,126,126,0,0
0,126,126,126,34,34,126,126,0,0,0,55,0,0,47,0,0,0,0,9,0,0,0,0,0,0,0,0,0,0,0
0,126,126,126,126,126,126,126,0,0,0,6,0,0,6,34,0,0,0,6,0,0,0,0,0,0,0,0,0,0,0
0,0,0,126,126,34,34,34,0,0,0,55,0,0,0,0,0,0,0,71,0,0,0,0,0,0,0,0,0,0,0
0,0,0,0,0,0,34,34,34,0,0,0,13,0,0,0,0,0,13,0,0,0,0,0,0,0,34,34,0,0,0
0,0,0,0,0,34,34,34,34,0,0,0,6,13,0,0,0,13,6,0,0,0,0,0,0,0,34,34,0,0,0
0,0,0,0,0,0,34,34,0,0,0,0,0,0,53,6,53,0,0,0,0,0,0,0,0,0,34,34,0,0,0
0,0,0,0,0,0,0,0,0,0,0,0,0,0,150,0,148,0,0,0,0,0,0,0,0,0,0,0,0,0,0
:endlayer
layer: 13
0,0,0,0,0,0,0,0,0,0,0,0,0,0,0,0,0,0,0,0,0,0,0,0,0,0,0,0,0,0,0
0,0,0,0,0,0,0,0,0,0,0,0,0,0,0,0,0,0,0,0,0,0,0,0,0,0,0,0,0,0,0
0,0,0,153,0,0,126,126,0,0,138,34,34,138,0,0,0,138,34,34,138,0,0,0,0,0,0,0,0,0,0
0,0,0,0,0,126,126,126,126,138,138,34,34,138,0,138,138,138,34,34,138,138,0,0,0,126,126,0,0,151,0
0,0,126,126,126,126,126,126,126,126,138,138,138,0,0,138,138,138,138,138,138,138,0,0,126,126,126,126,0,0,0
0,126,126,126,126,126,126,126,126,126,138,138,138,0,0,152,0,138,138,0,0,0,0,126,126,126,126,126,126,0,0
0,126,126,126,126,126,126,126,126,0,136,138,138,0,0,0,0,138,138,138,0,0,0,126,126,126,126,126,126,0,0
0,126,126,126,34,34,126,126,0,0,136,136,136,0,0,0,0,138,138,138,136,0,0,0,126,126,126,126,0,0,0
0,126,126,126,34,34,126,0,0,34,34,136,136,0,0,0,0,0,138,0,136,136,0,0,0,126,126,0,0,0,0
0,126,126,126,126,126,126,126,138,34,34,138,138,138,0,0,0,0,138,138,34,34,138,138,0,138,138,0,0,0,0
0,0,126,126,126,126,126,0,0,138,138,138,138,0,0,0,0,0,138,138,34,34,138,138,138,138,138,138,138,0,0
0,0,126,126,126,126,126,0,0,138,138,138,0,0,0,0,0,0,138,138,138,138,138,138,138,138,138,138,138,138,0
0,0,0,0,0,0,0,0,0,138,138,0,0,0,0,0,0,0,0,0,138,138,138,136,136,136,138,138,138,138,0
0,0,0,0,0,0,0,0,0,0,0,0,0,0,0,0,0,0,0,0,0,0,0,0,0,136,138,34,34,138,138
0,0,0,0,0,0,0,0,0,0,0,0,0,0,0,0,0,0,0,0,0,0,0,0,0,136,138,34,34,138,0
0,0,0,138,138,138,0,0,0,0,0,0,0,0,0,0,0,0,0,0,0,0,0,0,0,0,138,138,138,138,0
0,0,138,138,138,138,0,0,0,0,0,0,0,0,0,0,0,0,0,0,0,0,0,0,0,0,138,138,138,0,0
0,0,138,34,34,138,138,0,0,0,0,0,0,0,0,0,0,0,0,0,126,126,0,0,0,0,138,138,138,138,138
0,0,138,34,34,138,138,0,0,0,0,0,0,0,0,0,0,0,0,126,126,126,126,0,0,0,0,34,34,138,138
0,138,138,138,138,138,0,0,0,0,0,0,0,0,0,0,0,0,126,126,1,34,126,126,0,0,0,34,34,138,138
0,0,138,138,138,0,0,0,0,0,0,0,0,0,0,0,0,0,126,126,1,34,126,126,0,0,0,138,138,138,0
0,0,0,138,0,0,0,0,0,0,0,0,0,0,0,0,0,0,0,126,126,126,126,0,0,0,0,138,138,0,0
0,0,0,0,0,0,0,0,0,0,0,0,0,0,0,0,0,0,0,0,126,126,0,0,0,0,0,138,0,0,0
0,0,0,0,0,0,0,0,0,0,0,0,0,0,0,0,0,0,0,0,0,0,0,0,0,0,138,0,0,0,0
0,0,0,0,0,0,0,0,138,138,138,0,0,0,0,0,0,0,0,0,0,0,0,0,0,0,0,0,0,0,0
0,0,0,0,0,0,0,138,138,138,138,138,0,0,0,0,0,0,0,0,0,0,0,0,0,0,0,0,0,0,0
0,0,0,0,0,0,138,138,138,138,138,138,0,0,0,0,0,0,0,0,0,0,0,0,0,0,0,138,0,0,0
0,126,126,126,126,126,138,138,34,34,138,138,0,0,0,0,0,0,0,0,0,0,0,0,0,0,0,138,138,0,0
126,126,126,126,126,126,126,126,34,34,138,138,0,0,0,0,0,0,0,0,0,0,0,0,0,0,0,126,126,0,0
126,126,126,126,126,126,126,126,138,138,138,0,0,0,13,0,13,0,0,0,0,0,0,0,0,0,0,126,126,0,0
126,126,126,34,34,126,126,126,0,0,0,0,0,13,0,0,0,13,0,0,0,0,0,0,0,0,0,0,0,0,0
126,126,126,34,34,126,126,126,0,0,0,0,13,0,0,0,0,0,13,0,0,0,0,0,0,0,0,0,0,0,0
126,126,126,126,126,126,126,126,126,0,0,13,0,0,0,6,47,0,0,13,0,0,0,0,0,0,0,0,0,0,0
0,126,126,126,126,126,126,126,126,126,0,0,0,0,0,34,0,0,0,0,0,0,0,0,0,0,0,0,0,0,0
0,126,126,126,126,34,34,34,126,126,126,13,0,0,0,0,0,0,0,13,0,0,0,0,0,0,0,0,0,0,0
0,0,0,126,126,126,34,34,34,126,126,0,13,0,0,0,0,0,13,0,0,0,0,0,0,0,34,34,0,0,0
0,0,0,126,126,34,34,34,34,126,126,0,0,13,0,0,0,13,0,0,0,0,0,0,0,0,34,34,0,0,0
0,0,0,126,126,126,34,34,126,126,126,0,0,0,13,0,13,0,0,0,0,0,0,0,0,34,34,34,0,0,0
0,0,0,0,126,126,126,126,126,126,0,0,0,0,0,0,0,0,0,0,0,0,0,0,0,0,0,0,0,0,0
:endlayer
layer: 14
0,0,0,0,0,0,0,0,0,0,0,0,0,0,0,0,0,0,0,0,0,0,0,0,0,0,0,0,0,0,0
0,0,0,0,0,0,0,0,0,0,0,0,0,0,0,0,0,0,0,0,0,0,0,0,0,0,0,0,0,0,0
0,0,0,0,0,0,0,0,0,0,0,34,34,0,0,0,0,0,34,34,0,0,0,0,0,0,0,0,0,0,0
0,0,0,0,0,0,0,0,0,0,0,34,34,0,0,0,0,0,34,34,0,0,0,0,0,0,0,0,0,0,0
0,0,0,0,0,0,126,126,0,0,0,0,0,0,0,0,0,34,34,138,0,0,0,0,0,0,0,0,0,0,0
0,0,0,0,126,126,126,126,0,0,0,0,0,0,0,0,0,0,0,0,0,0,0,0,0,126,126,0,0,0,0
0,0,0,126,126,126,126,0,0,0,0,0,0,0,0,0,0,0,0,0,0,0,0,0,0,126,126,0,0,0,0
0,0,126,126,126,126,126,126,0,0,136,0,0,0,0,0,0,0,0,0,0,0,0,0,0,0,0,0,0,0,0
0,0,126,126,126,126,126,126,0,34,34,138,0,0,0,0,0,0,0,0,0,0,0,0,0,0,0,0,0,0,0
0,0,0,126,126,126,126,0,0,34,34,138,0,0,0,0,0,0,0,0,34,34,0,0,0,0,0,0,0,0,0
0,0,0,0,126,126,0,0,0,0,138,0,0,0,0,0,0,0,0,0,34,34,0,0,0,0,0,0,0,0,0
0,0,0,0,0,0,0,0,0,0,0,0,0,0,0,0,0,0,0,0,0,138,0,0,0,0,0,138,0,0,0
0,0,0,0,0,0,0,0,0,0,0,0,0,0,0,0,0,0,0,0,0,0,0,0,0,0,138,0,138,0,0
0,0,0,0,0,0,0,0,0,0,0,0,0,0,0,0,0,0,0,0,0,0,0,0,0,0,0,34,34,0,0
0,0,0,0,0,0,0,0,0,0,0,0,0,0,0,0,0,0,0,0,0,0,0,0,0,0,0,34,34,138,0
0,0,0,0,0,0,0,0,0,0,0,0,0,0,0,0,0,0,0,0,0,0,0,0,0,0,0,138,0,0,0
0,0,0,0,0,0,0,0,0,0,0,0,0,0,0,0,0,0,0,0,0,0,0,0,0,0,0,0,0,0,0
0,0,0,34,34,34,0,0,0,0,0,0,0,0,0,0,0,0,0,0,0,0,0,0,0,0,0,0,0,0,0
0,0,0,34,34,0,0,0,0,0,0,0,0,0,0,0,0,0,0,0,0,0,0,0,0,0,0,34,34,138,0
0,0,0,34,0,0,0,0,0,0,0,0,0,0,0,0,0,0,0,0,34,34,0,0,0,0,0,34,34,0,0
0,0,0,0,0,0,0,0,0,0,0,0,0,0,0,0,0,0,0,0,34,34,0,0,0,0,0,0,138,0,0
0,0,0,0,0,0,0,0,0,0,0,0,0,0,0,0,0,0,0,0,0,0,0,0,0,0,0,0,0,0,0
0,0,0,0,0,0,0,0,0,0,0,0,0,0,0,0,0,0,0,0,0,0,0,0,0,0,0,0,0,0,0
0,0,0,0,0,0,0,0,0,0,0,0,0,0,0,0,0,0,0,0,0,0,0,0,0,0,0,0,0,0,0
0,0,0,0,0,0,0,0,0,0,0,0,0,0,0,0,0,0,0,0,0,0,0,0,0,0,0,0,0,0,0
0,0,0,0,0,0,0,0,0,138,138,0,0,0,0,0,0,0,0,0,0,0,0,0,0,0,0,0,0,0,0
0,0,0,0,0,0,0,0,138,138,138,0,0,0,0,0,0,0,0,0,0,0,0,0,0,0,0,0,0,0,0
0,0,0,0,0,0,0,0,34,34,138,0,0,0,0,0,0,0,0,0,0,0,0,0,0,0,0,0,0,0,0
0,0,0,126,126,0,0,138,34,34,138,0,0,0,0,0,0,0,0,0,0,0,0,0,0,0,0,0,0,0,0
0,0,126,126,126,126,0,0,0,0,0,0,0,0,34,155,34,0,0,0,0,0,0,0,0,0,0,0,0,0,0
0,126,126,126,126,126,126,0,0,0,0,0,0,34,6,6,6,34,0,0,0,0,0,0,0,0,0,0,0,0,0
0,126,126,126,126,126,126,0,0,0,0,0,34,6,6,6,6,6,34,0,0,0,0,0,0,0,0,0,0,0,0
0,0,126,126,126,126,126,126,126,0,0,34,6,6,0,0,0,6,6,34,0,0,0,0,0,0,0,0,0,0,0
0,0,0,126,126,126,126,126,126,126,126,154,6,6,0,34,6,6,6,154,0,0,0,0,0,0,0,0,0,0,0
0,156,0,126,126,126,126,126,126,126,126,34,6,6,0,6,6,6,6,34,0,0,0,0,0,34,0,0,0,0,0
0,0,0,126,126,126,34,34,126,126,126,0,34,6,6,6,6,6,34,0,0,0,0,0,0,0,34,34,34,0,0
0,0,0,126,126,126,34,34,126,126,126,0,0,34,6,6,6,34,0,0,0,0,0,0,0,0,34,34,0,0,0
0,0,0,126,126,126,126,126,126,126,126,0,0,0,34,155,34,0,0,0,0,0,0,0,0,34,34,34,34,0,0
0,0,0,0,126,126,126,126,126,0,0,0,0,0,0,0,0,0,0,0,0,0,0,0,0,0,0,0,0,0,0
:endlayer
layer: 15
0,0,0,0,0,0,0,0,0,0,0,0,0,0,0,0,0,0,0,0,0,0,0,0,0,0,0,0,0,0,0
0,0,0,0,0,0,0,0,0,0,0,0,0,0,0,0,0,0,0,0,0,0,0,0,0,0,0,0,0,0,0
0,0,0,0,0,0,0,0,0,0,0,34,34,0,0,0,0,34,34,34,0,0,0,0,0,0,0,0,0,0,0
0,0,0,0,0,0,0,0,0,0,0,34,34,0,0,0,0,0,34,34,34,0,0,0,0,0,0,0,0,0,0
0,0,0,0,0,0,0,0,0,0,0,0,0,0,0,0,0,34,34,0,0,0,0,0,0,0,0,0,0,0,0
0,0,0,0,0,0,0,0,0,0,0,0,0,0,0,0,0,0,0,0,0,0,0,0,0,0,0,0,0,0,0
0,0,0,0,0,0,0,0,0,0,0,136,136,136,136,0,0,0,0,0,0,0,0,0,0,0,0,0,0,0,0
0,0,0,0,0,0,0,0,0,0,0,166,136,136,136,0,0,0,0,0,0,0,0,0,0,0,0,0,0,0,0
0,0,0,0,0,0,0,0,0,34,34,162,162,162,138,138,138,0,0,0,0,0,0,0,0,0,0,0,0,0,0
0,0,0,0,0,0,0,0,0,34,34,138,138,138,138,138,0,0,0,0,34,34,0,0,0,0,0,0,0,0,0
0,0,0,0,0,0,0,0,0,0,0,0,0,0,0,0,0,0,0,0,34,34,0,0,0,0,0,0,0,0,0
0,0,0,0,0,0,0,0,0,0,0,0,0,0,0,0,0,0,0,0,138,0,0,0,0,0,0,0,0,0,0
0,0,0,0,0,0,0,0,0,0,0,0,0,0,0,0,0,0,0,0,0,0,0,0,0,0,0,34,0,0,0
0,0,0,0,0,0,0,0,0,0,0,0,0,0,0,0,0,0,0,0,0,0,0,0,0,0,0,34,34,0,0
0,0,0,0,0,0,0,0,0,0,0,0,0,0,0,0,0,0,0,0,0,0,0,0,0,0,0,34,34,0,0
0,0,0,0,0,0,0,0,0,0,0,0,0,0,0,0,0,0,0,0,0,0,0,0,0,0,34,0,0,0,0
0,0,0,0,0,0,0,0,0,0,0,0,0,0,0,0,0,0,0,0,0,0,0,0,0,0,0,0,0,0,0
0,0,0,34,34,34,0,0,0,0,0,0,0,0,0,0,0,0,0,0,0,0,0,0,0,0,0,0,34,0,0
0,0,0,34,34,0,0,0,0,0,0,0,0,0,0,0,0,0,0,0,0,0,0,0,0,0,0,34,34,0,0
0,0,34,34,34,0,0,0,0,0,0,0,0,0,0,0,0,0,0,0,34,34,0,0,0,0,0,34,34,0,0
0,0,0,0,0,0,0,0,0,0,0,0,0,0,0,0,0,0,0,0,34,34,34,0,0,0,0,0,0,0,0
0,0,0,0,0,0,0,0,0,0,0,0,0,0,0,0,0,0,0,34,0,0,0,0,0,0,0,0,0,0,0
0,0,0,0,0,0,0,0,0,0,0,0,0,0,0,0,0,0,0,0,0,0,0,0,0,0,0,0,0,0,0
0,0,0,0,0,0,0,0,0,0,0,0,0,0,0,0,0,0,0,0,0,0,0,0,0,0,0,0,0,0,0
0,0,0,0,0,0,0,0,0,0,0,0,0,0,0,0,0,0,0,0,0,0,0,0,0,0,0,0,0,0,0
0,0,0,0,0,0,0,0,0,0,0,0,0,0,0,0,0,0,0,0,0,0,0,0,0,0,0,0,0,0,0
0,0,0,0,0,0,0,0,0,0,0,0,0,0,0,0,0,0,0,0,0,0,0,0,0,0,0,0,0,0,0
0,0,0,0,0,0,0,0,34,34,0,0,0,0,0,0,0,0,0,0,0,0,0,0,0,0,0,0,0,0,0
0,0,0,0,0,0,0,0,34,34,0,0,0,0,0,0,0,0,0,0,0,0,0,0,0,0,0,0,0,0,0
0,0,0,0,0,0,0,0,0,0,0,0,0,0,13,0,13,0,0,0,0,0,0,0,0,0,0,0,0,0,0
0,0,0,0,0,0,0,0,0,0,0,0,0,163,0,0,0,157,0,0,0,0,0,0,0,0,0,0,0,0,0
0,0,0,0,0,0,0,0,0,0,0,0,0,0,0,0,0,0,0,0,0,0,0,0,0,0,0,0,0,0,0
0,0,0,0,0,0,0,0,0,0,0,13,0,0,0,0,0,0,0,13,0,0,0,126,126,126,0,0,0,0,0
0,0,0,0,0,0,126,126,0,0,0,0,0,164,0,34,160,158,0,0,0,0,126,126,126,126,126,126,126,0,0
0,0,0,0,0,126,126,126,126,0,0,13,0,0,0,0,0,0,0,13,0,0,126,126,126,34,126,126,126,126,0
0,0,0,0,126,126,126,126,126,126,0,0,0,0,0,161,0,0,0,0,0,0,126,126,126,126,34,34,34,126,0
0,0,0,0,126,126,126,126,126,126,0,0,0,165,0,0,0,159,0,0,0,0,126,126,126,126,34,34,126,126,0
0,0,0,0,0,126,126,126,126,0,0,0,0,0,13,0,13,0,0,0,0,0,126,126,126,34,34,34,34,126,0
0,0,0,0,0,0,126,126,0,0,0,0,0,0,0,0,0,0,0,0,0,0,126,126,126,126,126,126,126,126,0
:endlayer
layer: 16
0,0,0,0,0,0,0,0,0,0,0,0,0,0,0,0,0,0,0,0,0,0,0,0,0,0,0,0,0,0,0
0,0,0,0,0,0,0,0,0,0,0,0,0,0,0,0,0,0,0,0,0,0,0,0,0,0,0,0,0,0,0
0,0,0,0,0,0,0,0,0,0,0,34,34,0,0,0,0,34,34,34,0,0,0,0,0,0,0,0,0,0,0
0,0,0,0,0,0,0,0,0,0,0,34,34,34,0,0,0,0,34,34,34,0,0,0,0,0,0,0,0,0,0
0,0,0,0,0,0,0,0,0,0,0,0,0,0,0,0,0,34,34,0,0,0,0,0,0,0,0,0,0,0,0
0,0,0,0,0,0,0,0,0,0,0,0,0,0,0,0,0,0,0,0,0,0,0,0,0,0,0,0,0,0,0
0,0,0,0,0,0,0,0,0,0,0,0,0,0,0,0,0,0,0,0,0,0,0,0,0,0,0,0,0,0,0
0,0,0,0,0,0,0,0,0,0,0,0,138,0,0,0,138,0,0,0,0,0,0,0,0,0,0,0,0,0,0
0,0,0,0,0,0,0,0,0,34,34,162,138,138,0,138,138,0,0,0,34,0,0,0,0,0,0,0,0,0,0
0,0,0,0,0,0,0,0,0,34,34,138,138,138,138,138,162,162,162,162,34,34,0,0,0,0,0,0,0,0,0
0,0,0,0,0,0,0,0,0,0,0,0,0,0,0,0,138,138,138,34,34,34,0,0,0,0,0,0,0,0,0
0,0,0,0,0,0,0,0,0,0,0,0,0,0,0,0,0,0,0,0,138,0,0,0,0,0,0,0,0,0,0
0,0,0,0,0,0,0,0,0,0,0,0,0,0,0,0,0,0,0,0,0,0,0,0,0,0,0,34,0,0,0
0,0,0,0,0,0,0,0,0,0,0,0,0,0,0,0,0,0,0,0,0,0,0,0,0,0,0,34,34,0,0
0,0,0,0,0,0,0,0,0,0,0,0,0,0,0,0,0,0,0,0,0,0,0,0,0,0,0,34,34,0,0
0,0,0,0,0,0,0,0,0,0,0,0,0,0,0,0,0,0,0,0,0,0,0,0,0,0,34,0,0,0,0
0,0,0,0,34,0,0,0,0,0,0,0,0,0,0,0,0,0,0,0,0,0,0,0,0,0,0,0,0,0,0
0,0,0,34,34,34,0,0,0,0,0,0,0,0,0,0,0,0,0,0,0,0,0,0,0,0,34,0,34,0,0
0,0,0,34,34,0,0,0,0,0,0,0,0,0,0,0,0,0,0,0,0,0,34,0,0,0,0,34,34,34,0
0,0,34,34,34,34,0,0,0,0,0,0,0,0,0,0,0,0,0,0,34,34,0,0,0,0,0,34,34,0,0
0,0,0,0,0,0,0,0,0,0,0,0,0,0,0,0,0,0,0,0,34,34,34,0,0,0,0,0,0,0,0
0,0,0,0,0,0,0,0,0,0,0,0,0,0,0,0,0,0,0,34,0,0,0,0,0,0,0,0,0,0,0
0,0,0,0,0,0,0,0,0,0,0,0,0,0,0,0,0,0,0,0,0,0,0,0,0,0,0,0,0,0,0
0,0,0,0,0,0,0,0,0,0,0,0,0,0,0,0,0,0,0,0,0,0,0,0,0,0,0,0,0,0,0
0,0,0,0,0,0,0,0,0,0,0,0,0,0,0,0,0,0,0,0,0,0,0,0,0,0,0,0,0,0,0
0,0,0,0,0,0,0,0,0,0,0,0,0,0,0,0,0,0,0,0,0,0,0,0,0,0,0,0,0,0,0
0,0,0,0,0,0,0,0,0,0,0,0,0,0,0,0,0,0,0,0,0,0,0,0,0,0,0,0,0,0,0
0,0,0,0,0,0,0,0,34,34,0,0,0,0,0,0,0,0,0,0,0,0,0,0,0,0,0,0,0,0,0
0,0,0,0,0,0,0,0,34,34,0,0,0,0,0,0,0,0,0,0,0,0,0,0,0,0,0,0,0,0,0
0,0,0,0,0,0,0,0,0,0,0,0,0,0,172,0,170,0,0,0,0,0,0,0,0,0,0,0,0,0,0
0,0,0,0,0,0,0,0,0,0,0,0,0,0,0,0,0,0,0,0,0,0,0,0,0,0,0,0,0,0,0
0,0,0,0,0,0,0,0,0,0,0,0,0,0,0,0,0,0,0,0,0,0,0,0,0,0,0,0,0,0,0
0,0,0,0,0,0,0,0,0,0,0,174,0,0,0,0,0,0,0,168,0,0,0,126,126,126,126,126,0,0,0
0,0,0,0,0,0,0,0,0,0,0,0,0,0,0,63,0,0,0,0,0,0,126,126,126,126,126,126,126,126,0
0,0,0,0,0,0,0,0,0,0,0,175,0,0,0,0,0,0,0,169,0,0,126,126,126,126,126,126,126,126,0
0,0,0,0,0,0,0,0,0,0,0,0,0,0,0,0,0,0,0,0,0,0,126,126,126,34,34,126,126,126,0
0,0,0,0,0,0,0,0,0,0,0,0,0,0,0,0,0,0,0,0,0,0,126,126,126,34,34,126,126,126,0
0,0,0,0,0,0,0,0,0,0,0,0,0,0,173,0,171,0,0,0,0,0,126,126,126,126,126,126,126,126,0
0,0,0,0,0,0,0,0,0,0,0,0,0,0,0,0,0,0,0,0,0,0,0,126,126,126,126,126,126,167,0
:endlayer
layer: 17
0,0,0,0,0,0,0,0,0,0,0,0,0,0,0,0,126,126,126,126,126,126,0,0,0,0,0,0,0,0,0
0,0,0,0,0,0,0,0,0,0,0,0,0,0,0,126,126,126,126,126,126,126,0,0,0,0,0,0,0,0,0
0,0,0,0,0,0,0,0,0,0,0,34,34,0,0,126,126,34,34,34,126,126,126,0,0,0,0,0,0,0,0
0,0,0,0,0,0,0,0,0,0,34,34,34,34,0,126,126,126,34,34,34,126,126,0,0,0,0,0,0,0,0
0,0,0,0,0,0,0,0,0,0,0,0,0,34,0,126,126,34,34,126,126,126,126,0,0,0,0,0,0,0,0
0,0,0,0,0,0,0,0,0,0,0,0,0,0,0,126,126,126,126,126,126,126,0,0,0,0,0,0,0,0,0
0,0,0,0,0,0,0,0,0,0,0,0,0,0,0,0,126,126,126,126,0,0,0,0,0,0,0,0,0,0,0
0,0,0,0,0,0,0,0,0,0,0,0,0,0,0,0,0,138,0,0,0,0,0,0,0,0,0,0,0,0,0
0,0,0,0,0,0,0,0,0,34,34,0,0,0,0,0,138,138,0,0,34,34,0,0,0,0,0,0,0,0,0
0,0,0,0,0,0,0,0,0,34,34,34,0,0,138,138,138,138,138,138,34,34,0,0,0,0,0,0,0,0,0
0,0,0,0,0,0,0,0,0,0,0,0,0,0,0,0,0,0,0,34,34,34,0,0,0,0,0,0,0,0,0
0,0,0,0,0,0,0,0,0,0,0,0,0,0,0,0,0,0,0,0,138,0,0,0,0,0,0,0,0,0,0
0,0,0,0,0,0,0,0,0,0,0,0,0,0,0,0,0,0,0,0,0,0,0,0,0,0,0,34,0,0,0
0,0,0,0,0,0,0,0,0,0,0,0,0,0,0,0,0,0,0,0,0,0,0,0,0,0,0,34,34,0,0
0,0,0,126,126,126,0,0,0,0,0,0,0,0,0,0,0,0,0,0,0,0,0,0,0,0,34,34,34,0,0
0,126,126,126,126,126,126,0,0,0,0,0,0,0,0,0,0,0,0,0,0,0,0,0,0,0,34,34,0,34,0
0,126,126,126,34,126,126,126,0,0,0,0,0,0,0,0,0,0,0,0,0,0,0,0,0,0,0,0,0,0,0
0,126,126,34,34,34,126,126,0,0,0,0,0,0,0,0,0,0,0,0,0,0,0,0,0,0,34,0,34,0,0
126,126,126,34,34,126,126,126,0,0,0,0,0,0,0,0,0,0,0,34,0,0,34,0,0,0,0,34,34,34,0
126,126,34,34,34,34,126,126,0,0,0,0,0,0,0,0,0,0,0,0,34,34,0,0,0,0,0,34,34,34,0
126,126,126,126,126,126,126,126,0,0,0,0,0,0,0,0,0,0,0,0,34,34,34,0,0,0,0,0,0,0,0
0,126,126,126,126,126,126,0,0,0,0,0,0,0,0,0,0,0,0,34,0,34,0,0,0,0,0,0,0,0,0
0,0,0,0,0,0,0,0,0,0,0,0,0,0,0,0,0,0,0,0,0,0,0,0,0,0,0,0,0,0,0
0,0,0,0,0,0,0,0,0,0,0,0,0,0,0,0,0,0,0,0,0,0,0,0,0,0,0,0,0,0,0
0,0,0,0,0,0,0,0,0,0,0,0,0,0,0,0,0,0,0,0,0,0,0,0,0,0,0,0,0,0,0
0,0,0,0,0,0,0,0,0,0,0,0,0,0,0,0,0,0,0,0,0,0,0,0,0,0,0,0,0,0,0
0,0,0,0,0,0,0,0,0,0,0,0,0,0,0,0,0,0,0,0,0,0,0,0,0,0,0,0,0,0,0
0,0,0,0,0,0,0,0,34,34,0,0,0,0,0,0,0,0,0,0,0,0,0,0,0,0,0,0,0,0,0
0,0,0,0,0,0,0,0,34,34,0,0,0,0,0,0,0,0,0,0,0,0,0,0,0,0,0,0,0,0,0
0,0,0,0,0,0,0,0,0,0,0,0,0,0,0,0,0,0,0,0,0,0,0,0,0,0,0,0,0,0,0
0,0,0,0,0,0,0,0,0,0,0,0,0,0,0,0,0,0,0,0,0,0,0,0,0,0,0,0,0,0,0
0,0,0,0,0,0,0,0,0,0,0,0,0,0,0,0,0,0,0,0,0,0,0,0,0,0,0,0,0,0,0
0,0,0,0,0,0,0,0,0,0,0,0,0,0,0,0,0,0,0,0,0,0,0,0,0,0,0,0,0,0,0
0,0,0,0,0,0,0,0,0,0,0,0,0,0,0,0,0,0,0,0,0,0,0,0,0,126,126,0,0,0,0
0,0,0,0,0,0,0,0,0,0,0,0,0,0,0,0,0,0,0,0,0,0,0,0,126,126,126,126,0,0,0
0,0,0,0,0,0,0,0,0,0,0,0,0,0,0,0,0,0,0,0,0,0,0,126,126,126,126,126,126,0,0
0,0,0,0,0,0,0,0,0,0,0,0,0,0,0,0,0,0,0,0,0,0,0,126,126,126,126,126,126,0,0
0,0,0,0,0,0,0,0,0,0,0,0,0,0,0,0,0,0,0,0,0,0,0,0,126,126,126,126,0,0,0
0,0,0,0,0,0,0,0,0,0,0,0,0,0,0,0,0,0,0,0,0,0,0,0,0,126,126,0,0,0,0
:endlayer
layer: 18
0,0,0,0,0,0,0,0,0,0,0,0,0,0,0,126,126,126,126,126,126,126,126,0,0,0,0,0,0,0,0
0,0,0,0,0,0,0,0,0,0,0,0,0,0,0,126,126,126,126,126,126,126,126,0,0,0,0,0,0,0,0
0,0,0,0,0,0,0,0,0,0,0,34,34,0,0,126,126,126,34,34,126,126,126,0,0,0,0,0,0,0,0
0,0,0,0,0,0,0,0,0,0,34,34,34,34,0,126,126,126,34,34,126,126,126,0,0,0,0,0,0,0,0
0,0,0,0,0,0,0,0,0,0,0,0,34,34,0,126,126,126,126,126,126,126,126,0,0,0,0,0,0,0,0
0,0,0,0,0,0,0,0,0,0,0,0,0,0,0,0,126,126,126,126,126,0,0,0,0,0,0,0,0,0,0
0,0,0,0,0,0,0,0,0,0,0,0,0,0,0,0,126,126,126,126,126,0,0,0,0,0,0,0,0,0,0
0,0,0,0,0,0,0,0,0,0,0,0,0,0,0,0,0,0,0,0,0,0,0,0,0,0,0,0,0,0,0
0,0,0,0,0,0,0,0,0,34,34,0,0,0,0,0,0,0,0,0,34,34,0,0,0,0,0,0,0,0,0
0,0,0,0,0,0,0,0,0,34,34,34,0,0,0,0,0,0,0,34,34,34,0,0,0,0,0,0,0,0,0
0,0,0,0,0,0,0,0,0,0,0,0,0,0,0,0,0,0,0,34,34,34,0,0,0,0,0,126,126,126,0
0,0,0,0,0,0,0,0,0,0,0,0,0,0,0,0,0,0,0,0,0,0,0,0,0,0,126,126,126,126,126
0,0,0,0,0,0,0,0,0,0,0,0,0,0,0,0,0,0,0,0,0,0,0,0,0,0,126,34,126,126,126
0,0,0,0,0,0,0,0,0,0,0,0,0,0,0,0,0,0,0,0,0,0,0,0,0,126,126,126,34,34,126
0,126,126,126,126,126,0,0,0,0,0,0,0,0,0,0,0,0,0,0,0,0,0,0,0,126,34,126,34,34,126
126,126,126,126,126,126,126,126,0,0,0,0,0,0,0,0,0,0,0,0,0,0,0,0,138,126,34,34,126,34,126
126,126,126,126,126,126,126,126,0,0,0,0,0,0,0,0,0,0,126,126,126,126,126,126,126,126,126,126,126,126,126
126,126,126,34,34,126,126,126,0,0,0,0,0,0,138,0,138,126,126,126,126,126,126,126,126,126,34,126,34,126,126
126,126,126,34,34,126,126,126,0,0,0,138,138,0,138,0,138,126,126,34,126,126,34,126,126,126,126,34,34,34,126
126,126,126,126,126,126,126,126,0,0,0,138,138,138,138,138,138,126,126,126,34,34,126,126,126,126,126,34,34,34,126
0,126,126,126,126,126,126,0,0,0,0,138,162,162,162,162,162,162,162,162,34,34,34,126,126,126,126,126,126,126,126
0,126,126,126,126,126,0,0,0,0,0,138,138,138,138,138,138,126,126,34,126,34,126,126,126,126,126,126,126,126,126
0,0,0,0,0,0,0,0,0,0,0,0,0,0,0,0,0,126,126,126,126,126,126,126,0,0,0,0,0,0,0
0,0,0,0,0,0,0,0,0,0,0,0,0,0,0,0,0,0,126,126,126,126,126,0,0,0,0,0,0,0,0
0,0,0,0,0,0,0,0,0,0,0,0,0,0,0,0,0,0,0,0,0,0,0,0,0,0,0,0,0,0,0
0,0,0,0,0,0,0,0,0,0,0,0,0,0,0,0,0,0,0,0,0,0,0,0,0,0,0,0,0,0,0
0,0,0,0,0,0,0,0,0,0,0,0,0,0,0,0,0,0,0,0,0,0,0,0,0,0,0,0,0,0,0
0,0,0,0,0,0,0,0,34,34,0,0,0,0,0,0,0,0,0,0,0,0,0,0,0,0,0,0,0,0,0
0,0,0,0,0,0,0,0,34,34,0,0,0,0,0,0,0,0,0,0,0,0,0,0,0,0,0,0,0,0,0
0,0,0,0,0,0,0,0,0,0,0,0,0,0,0,0,0,0,0,0,0,0,0,0,0,0,0,0,0,0,0
0,0,0,0,0,0,0,0,0,0,0,0,0,0,0,0,0,0,0,0,0,0,0,0,0,0,0,0,0,0,0
0,0,0,0,0,0,0,0,0,0,0,0,0,0,0,0,0,0,0,0,0,0,0,0,0,0,0,0,0,0,0
0,0,0,0,0,0,0,0,0,0,0,0,0,0,0,0,0,0,0,0,0,0,0,0,0,0,0,0,0,0,0
0,0,0,0,0,0,0,0,0,0,0,0,0,0,0,0,0,0,0,0,0,0,0,0,0,0,0,0,0,0,0
0,0,0,0,0,0,0,0,0,0,0,0,0,0,0,0,0,0,0,0,0,0,0,0,0,0,0,0,0,0,0
0,0,0,0,0,0,0,0,0,0,0,0,0,0,0,0,0,0,0,0,0,0,0,0,0,126,126,0,0,0,0
0,0,0,0,0,0,0,0,0,0,0,0,0,0,0,0,0,0,0,0,0,0,0,0,0,126,126,0,0,0,0
0,0,0,0,0,0,0,0,0,0,0,0,0,0,0,0,0,0,0,0,0,0,0,0,0,0,0,0,0,0,0
0,0,0,0,0,0,0,0,0,0,0,0,0,0,0,0,0,0,0,0,0,0,0,0,0,0,0,0,0,0,0
:endlayer
layer: 19
0,0,0,0,0,0,0,0,0,126,126,126,126,126,126,0,0,0,126,126,0,0,0,0,0,0,0,0,0,0,0
0,0,0,0,0,0,0,0,126,126,126,126,126,126,126,126,0,126,126,126,126,0,0,0,0,0,0,0,0,0,0
0,0,0,0,0,0,0,0,126,126,126,34,34,126,126,126,126,126,126,126,126,126,0,0,0,0,0,0,0,0,0
0,0,0,0,0,0,0,0,126,126,34,34,34,34,126,126,126,126,126,126,126,126,0,0,0,0,0,0,0,0,0
0,0,0,0,0,0,0,0,0,126,126,126,34,34,126,126,0,126,126,126,126,0,0,0,0,0,0,0,0,0,0
0,0,0,0,0,0,0,0,0,0,0,126,126,126,126,0,0,0,126,126,0,0,0,0,0,0,0,0,0,0,0
0,0,0,0,0,0,0,0,0,0,0,0,0,0,0,0,0,0,0,126,126,126,126,0,0,0,0,0,0,0,0
0,0,0,0,0,0,0,0,0,0,0,0,0,0,138,0,0,0,126,126,126,126,126,126,0,0,0,0,0,0,0
0,0,0,0,0,0,0,0,0,34,34,138,138,138,138,138,0,126,126,126,34,34,126,126,0,0,0,0,0,0,0
0,0,0,0,0,0,0,0,34,34,34,34,162,162,162,138,138,126,126,34,34,34,126,126,0,0,0,0,0,0,0
0,0,0,0,0,0,0,0,0,0,0,0,0,0,138,138,162,162,162,34,34,34,126,126,0,0,126,126,126,126,126
0,0,0,0,0,0,0,0,0,0,0,0,0,0,0,138,138,126,126,126,126,126,126,126,0,126,126,126,126,126,126
0,0,0,0,0,0,0,0,0,0,0,0,0,0,0,0,0,0,126,126,126,126,126,126,138,126,126,126,126,126,126
0,0,0,0,0,0,0,0,0,0,0,0,0,0,0,0,0,0,0,0,0,138,138,138,138,126,126,126,34,34,126
0,0,0,0,0,0,0,0,0,0,0,0,0,0,0,0,0,0,0,0,0,0,138,138,138,126,126,126,34,34,126
0,0,0,126,126,0,0,0,0,0,0,0,0,0,0,0,0,0,0,0,0,0,0,0,138,126,126,126,126,126,126
0,0,126,126,126,126,0,0,0,0,0,0,0,0,0,0,0,0,126,126,126,126,126,0,126,126,126,126,126,126,126
0,126,126,126,126,126,126,0,0,0,0,0,0,0,0,0,0,126,126,126,126,126,126,126,126,126,126,126,126,126,126
0,126,126,126,126,126,126,0,0,0,0,0,0,0,0,0,0,126,126,126,126,126,126,126,126,126,126,34,34,126,126
0,0,126,126,126,126,0,0,0,0,0,0,0,138,138,138,138,126,126,126,34,34,126,126,126,126,126,34,34,126,126
0,0,0,126,126,0,0,0,0,0,0,0,138,138,138,138,138,126,126,126,34,34,126,126,126,126,126,126,126,126,126
0,0,0,0,0,0,0,0,0,0,0,0,0,0,0,0,0,126,126,126,126,126,126,126,126,126,126,126,126,126,0
0,0,0,0,0,0,0,0,0,0,0,0,0,0,0,0,0,0,126,126,126,126,126,0,0,126,126,126,126,126,0
0,0,0,0,0,0,0,0,0,0,0,0,0,0,0,0,0,0,126,126,126,126,126,0,0,0,0,0,0,0,0
0,0,0,0,0,0,0,0,0,0,0,0,0,0,0,0,0,0,0,0,0,0,0,0,0,0,0,0,0,0,0
0,0,0,0,0,0,0,0,0,0,0,0,0,0,0,0,0,0,0,0,0,0,0,0,0,0,0,0,0,0,0
0,0,0,0,0,0,0,0,0,0,0,0,0,0,0,0,0,0,0,0,0,0,0,0,0,0,0,0,0,0,0
0,0,0,0,0,0,0,0,34,34,0,0,0,0,0,0,0,0,0,0,0,0,0,0,0,0,0,0,0,0,0
0,0,0,0,0,0,0,0,34,34,0,0,0,0,0,0,0,0,0,0,0,0,0,0,0,0,0,0,0,0,0
0,0,0,0,0,0,0,0,0,0,34,0,0,0,0,0,0,0,0,0,0,0,0,0,0,0,0,0,0,0,0
0,0,0,0,0,0,0,0,0,0,0,0,0,0,0,0,0,0,0,0,0,0,0,0,0,0,0,0,0,0,0
0,0,0,0,0,0,0,0,0,0,0,0,0,0,0,0,0,0,0,0,0,0,0,0,0,0,0,0,0,0,0
0,0,0,0,0,0,0,0,0,0,0,0,0,0,0,0,0,0,0,0,0,0,0,0,0,0,0,0,0,0,0
0,0,0,0,0,0,0,0,0,0,0,0,0,0,0,0,0,0,0,0,0,0,0,0,0,0,0,0,0,0,0
0,0,0,0,0,0,0,0,0,0,0,0,0,0,0,0,0,0,0,0,0,0,0,0,0,0,0,0,0,0,0
0,0,0,0,0,0,0,0,0,0,0,0,0,0,0,0,0,0,0,0,0,0,0,0,0,0,0,0,0,0,0
0,0,0,0,0,0,0,0,0,0,0,0,0,0,0,0,0,0,0,0,0,0,0,0,0,0,0,0,0,0,0
0,0,0,0,0,0,0,0,0,0,0,0,0,0,0,0,0,0,0,0,0,0,0,0,0,0,0,0,0,0,0
0,0,0,0,0,0,0,0,0,0,0,0,0,0,0,0,0,0,0,0,0,0,0,0,0,0,0,0,0,0,0
:endlayer
layer: 20
0,0,0,0,0,0,0,0,126,126,126,126,126,126,126,126,0,0,0,0,0,0,0,0,0,0,0,0,0,0,0
0,0,0,0,0,0,0,0,126,126,126,34,34,126,126,126,0,0,0,0,0,0,0,0,0,0,0,0,0,0,0
0,0,0,0,0,0,0,0,126,126,126,34,34,126,126,126,0,0,0,0,0,0,0,0,0,0,0,0,0,0,0
0,0,0,0,0,0,0,0,126,126,126,126,126,126,126,126,0,0,0,0,0,0,0,0,0,0,0,0,0,0,0
0,0,0,0,0,0,0,0,0,126,126,126,126,126,126,0,0,0,0,0,0,0,0,0,0,0,0,0,0,0,0
0,0,0,0,0,0,0,0,0,126,126,126,126,126,0,0,0,0,0,0,0,0,0,0,0,0,0,0,0,0,0
0,0,0,0,0,0,0,0,0,0,0,0,0,0,0,0,0,0,126,126,126,126,126,0,0,0,0,0,0,0,0
0,0,0,0,0,0,0,126,126,126,126,126,126,0,0,0,0,126,126,126,126,126,126,126,126,0,0,0,0,0,0
0,0,0,0,0,0,0,126,126,34,34,126,126,0,0,0,0,126,126,126,126,126,126,126,126,0,0,0,0,0,0
0,0,0,0,0,0,126,126,34,34,34,34,126,126,138,138,0,126,126,126,34,34,126,126,126,0,0,0,0,0,0
0,0,0,0,0,0,126,126,126,126,126,126,126,126,138,0,138,126,126,126,34,34,126,126,126,0,0,0,0,0,0
0,0,0,0,0,0,126,126,126,126,126,126,126,126,0,0,138,126,126,126,126,126,126,126,126,138,0,0,126,126,0
0,0,0,0,0,0,0,126,126,126,126,126,126,0,0,0,0,0,126,126,126,126,126,138,138,138,0,126,126,126,126
0,0,0,0,0,0,0,0,0,0,0,0,0,0,0,0,0,0,126,126,126,126,126,138,138,138,126,126,126,126,126
0,0,0,0,0,0,0,0,0,0,0,0,0,0,0,0,0,0,0,0,0,0,0,0,0,0,126,126,126,126,126
0,0,0,0,0,0,0,0,0,0,0,0,0,0,0,0,0,0,0,0,0,0,0,0,0,0,0,126,126,126,126
0,0,0,0,0,0,0,0,0,0,0,0,0,0,0,0,0,0,0,0,0,0,0,0,0,0,0,126,126,126,0
0,0,0,126,126,0,0,0,0,0,0,0,0,0,0,0,0,0,0,0,126,126,0,0,0,0,126,126,126,126,0
0,0,0,126,126,0,0,0,0,0,0,0,0,0,0,0,0,0,0,126,126,126,126,0,0,126,126,126,126,126,126
0,0,0,0,0,0,0,0,0,0,0,0,0,0,0,0,0,0,126,126,126,126,126,126,0,126,126,126,126,126,126
0,0,0,0,0,0,0,0,0,0,0,0,0,0,0,0,0,0,126,126,126,126,126,126,0,0,126,126,126,126,0
0,0,0,0,0,0,0,0,0,0,0,0,0,0,0,0,0,0,0,126,126,126,126,0,0,0,0,126,126,0,0
0,0,0,0,0,0,0,0,0,0,0,0,0,0,0,0,0,0,0,0,126,126,0,0,0,0,0,0,0,0,0
0,0,0,0,0,0,0,0,0,0,0,0,0,0,0,0,0,0,0,0,0,0,0,0,0,0,0,0,0,0,0
0,0,0,0,0,0,0,0,0,0,0,0,0,0,0,0,0,0,0,0,0,0,0,0,0,0,0,0,0,0,0
0,0,0,0,0,0,0,0,0,0,0,0,0,0,0,0,0,0,0,0,0,0,0,0,0,0,0,0,0,0,0
0,0,0,0,0,0,0,0,0,0,34,0,0,0,0,0,0,0,0,0,0,0,0,0,0,0,0,0,0,0,0
0,0,0,0,0,0,0,0,34,34,0,0,0,0,0,0,0,0,0,0,0,0,0,0,0,0,0,0,0,0,0
0,0,0,0,0,0,0,0,34,34,0,0,0,0,0,0,0,0,0,0,0,0,0,0,0,0,0,0,0,0,0
0,0,0,0,0,0,0,34,0,34,34,0,0,0,0,0,0,0,0,0,0,0,0,0,0,0,0,0,0,0,0
0,0,0,0,0,0,0,0,0,0,0,0,0,0,0,0,0,0,0,0,0,0,0,0,0,0,0,0,0,0,0
0,0,0,0,0,0,0,0,0,0,0,0,0,0,0,0,0,0,0,0,0,0,0,0,0,0,0,0,0,0,0
0,0,0,0,0,0,0,0,0,0,0,0,0,0,0,0,0,0,0,0,0,0,0,0,0,0,0,0,0,0,0
0,0,0,0,0,0,0,0,0,0,0,0,0,0,0,0,0,0,0,0,0,0,0,0,0,0,0,0,0,0,0
0,0,0,0,0,0,0,0,0,0,0,0,0,0,0,0,0,0,0,0,0,0,0,0,0,0,0,0,0,0,0
0,0,0,0,0,0,0,0,0,0,0,0,0,0,0,0,0,0,0,0,0,0,0,0,0,0,0,0,0,0,0
0,0,0,0,0,0,0,0,0,0,0,0,0,0,0,0,0,0,0,0,0,0,0,0,0,0,0,0,0,0,0
0,0,0,0,0,0,0,0,0,0,0,0,0,0,0,0,0,0,0,0,0,0,0,0,0,0,0,0,0,0,0
0,0,0,0,0,0,0,0,0,0,0,0,0,0,0,0,0,0,0,0,0,0,0,0,0,0,0,0,0,0,0
:endlayer
layer: 21
0,0,0,0,0,0,0,0,0,0,126,126,126,126,0,0,0,0,0,0,0,0,0,0,0,0,0,0,0,0,0
0,0,0,0,0,0,0,0,0,126,126,126,126,126,126,0,0,0,0,0,0,0,0,0,0,0,0,0,0,0,0
0,0,0,0,0,0,0,0,0,126,126,126,126,126,126,0,0,0,0,0,0,0,0,0,0,0,0,0,0,0,0
0,0,0,0,0,0,0,0,0,0,126,126,126,126,0,0,0,0,0,0,0,0,0,0,0,0,0,0,0,0,0
0,0,0,0,0,0,0,0,0,0,0,126,126,0,0,0,0,0,0,0,0,0,0,0,0,0,0,0,0,0,0
0,0,0,0,0,0,0,0,0,0,0,0,0,0,0,0,0,0,0,0,0,0,0,0,0,0,0,0,0,0,0
0,0,0,0,0,0,0,126,126,126,126,126,0,0,0,0,0,0,0,0,0,0,0,0,0,0,0,0,0,0,0
0,0,0,0,0,0,126,126,126,126,126,126,126,126,0,0,0,0,0,0,126,126,0,0,0,0,0,0,0,0,0
0,0,0,0,0,0,126,126,126,126,126,126,126,126,0,0,0,0,0,126,126,126,126,0,0,0,0,0,0,0,0
0,0,0,0,0,0,126,126,126,34,34,126,126,126,0,0,0,0,126,126,126,126,126,126,0,0,0,0,0,0,0
0,0,0,0,0,0,126,126,126,34,34,126,126,126,0,0,0,0,126,126,126,126,126,126,0,0,0,0,0,0,0
0,0,0,0,0,0,126,126,126,126,126,126,126,126,0,0,0,0,0,126,126,126,126,0,0,0,0,0,0,0,0
0,0,0,0,0,0,0,126,126,126,126,126,0,0,0,0,0,0,0,0,126,126,0,0,138,0,0,0,0,0,0
0,0,0,0,0,0,0,126,126,126,126,126,0,0,0,0,0,0,0,0,0,0,0,0,138,0,0,0,126,126,0
0,0,0,0,0,0,0,0,0,0,0,0,0,0,0,0,0,0,0,0,0,0,0,0,0,0,0,0,126,126,0
0,0,0,0,0,0,0,0,0,0,0,0,0,0,0,0,0,0,0,0,0,0,0,0,0,0,0,0,0,0,0
0,0,0,0,0,0,0,0,0,0,0,0,0,0,0,0,0,0,0,0,0,0,0,0,0,0,0,0,0,0,0
0,0,0,0,0,0,0,0,0,0,0,0,0,0,0,0,0,0,0,0,0,0,0,0,0,0,0,0,0,0,0
0,0,0,0,0,0,0,0,0,0,0,0,0,0,0,0,0,0,0,0,0,0,0,0,0,0,0,0,0,0,0
0,0,0,0,0,0,0,0,0,0,0,0,0,0,0,0,0,0,0,0,0,0,0,0,0,0,0,0,0,0,0
0,0,0,0,0,0,0,0,0,138,138,0,0,0,0,0,0,0,0,0,0,0,0,0,0,0,0,0,0,0,0
0,0,0,0,0,0,0,0,0,138,138,138,0,0,0,0,0,0,0,0,0,0,0,0,0,0,0,0,0,0,0
0,0,0,0,0,0,0,0,0,138,166,138,0,0,0,0,0,0,0,0,0,0,0,0,0,0,0,0,0,0,0
0,0,0,0,0,0,0,0,0,0,166,0,0,0,0,0,0,0,0,0,0,0,0,0,0,0,0,0,0,0,0
0,0,0,0,0,0,0,0,0,0,166,0,0,0,0,0,0,0,0,0,0,0,0,0,0,0,0,0,0,0,0
0,0,0,0,0,0,0,0,0,0,166,0,0,0,138,0,0,0,0,0,0,0,0,0,0,0,0,0,0,0,0
0,0,0,0,0,0,0,0,34,34,34,162,162,162,138,0,0,0,0,0,0,0,0,0,0,0,0,0,0,0,0
0,0,0,0,138,138,138,0,34,34,0,0,0,0,0,0,0,0,0,0,0,0,0,0,0,0,0,0,0,0,0
0,0,0,0,0,138,138,34,0,0,0,0,0,0,0,0,0,0,0,0,0,0,0,0,0,0,0,0,0,0,0
0,0,0,0,0,138,138,34,138,34,34,138,0,0,0,0,0,0,0,0,0,0,0,0,0,0,0,0,0,0,0
0,0,0,0,0,0,138,138,0,138,138,138,0,0,0,0,0,0,0,0,0,0,0,0,0,0,0,0,0,0,0
0,0,0,0,0,138,138,0,138,138,0,138,0,0,0,0,0,0,0,0,0,0,0,0,0,0,0,0,0,0,0
0,0,0,0,0,0,0,0,138,138,0,0,0,0,0,0,0,0,0,0,0,0,0,0,0,0,0,0,0,0,0
0,0,0,0,0,0,0,0,0,0,0,0,0,0,0,0,0,0,0,0,0,0,0,0,0,0,0,0,0,0,0
0,0,0,0,0,0,0,0,0,0,0,0,0,0,0,0,0,0,0,0,0,0,0,0,0,0,0,0,0,0,0
0,0,0,0,0,0,0,0,0,0,0,0,0,0,0,0,0,0,0,0,0,0,0,0,0,0,0,0,0,0,0
0,0,0,0,0,0,0,0,0,0,0,0,0,0,0,0,0,0,0,0,0,0,0,0,0,0,0,0,0,0,0
0,0,0,0,0,0,0,0,0,0,0,0,0,0,0,0,0,0,0,0,0,0,0,0,0,0,0,0,0,0,0
0,0,0,0,0,0,0,0,0,0,0,0,0,0,0,0,0,0,0,0,0,0,0,0,0,0,0,0,0,0,0
:endlayer
layer: 22
0,0,0,0,0,0,0,0,0,0,0,0,0,0,0,0,0,0,0,0,0,0,0,0,0,0,0,0,0,0,0
0,0,0,0,0,0,0,0,0,0,0,0,0,0,0,0,0,0,0,0,0,0,0,0,0,0,0,0,0,0,0
0,0,0,0,0,0,0,0,0,0,0,0,0,0,0,0,0,0,0,0,0,0,0,0,0,0,0,0,0,0,0
0,0,0,0,0,0,0,0,0,0,0,0,0,0,0,0,0,0,0,0,0,0,0,0,0,0,0,0,0,0,0
0,0,0,0,0,0,0,0,0,0,0,0,0,0,0,0,0,0,0,0,0,0,0,0,0,0,0,0,0,0,0
0,0,0,0,0,0,0,0,0,0,0,0,0,0,0,0,0,0,0,0,0,0,0,0,0,0,0,0,0,0,0
0,0,0,0,0,0,0,0,0,0,0,0,0,0,0,0,0,0,0,0,0,0,0,0,0,0,0,0,0,0,0
0,0,0,0,0,0,0,0,0,126,126,0,0,0,0,0,0,0,0,0,0,0,0,0,0,0,0,0,0,0,0
0,0,0,0,0,0,0,0,126,126,126,126,0,0,0,0,0,0,0,0,0,0,0,0,0,0,0,0,0,0,0
0,0,0,0,0,0,0,126,126,126,126,126,126,0,0,0,0,0,0,0,0,0,0,0,0,0,0,0,0,0,0
0,0,0,0,0,0,0,126,126,126,126,126,126,0,0,0,0,0,0,0,0,0,0,0,0,0,0,0,0,0,0
0,0,0,0,0,0,0,0,126,126,126,126,0,0,0,0,0,0,0,0,0,0,0,0,0,0,0,0,0,0,0
0,0,0,0,0,0,0,0,0,126,126,0,0,0,0,0,0,0,0,0,0,0,0,0,0,0,0,0,0,0,0
0,0,0,0,0,0,0,0,0,0,0,0,0,0,0,0,0,0,0,0,0,0,0,0,0,0,0,0,0,0,0
0,0,0,0,0,0,0,0,0,0,0,0,0,0,0,0,0,0,0,0,0,0,0,0,0,0,0,0,0,0,0
0,0,0,0,0,0,0,0,0,0,0,0,0,0,0,0,0,0,0,0,0,0,0,0,0,0,0,0,0,0,0
0,0,0,0,0,0,0,0,0,0,0,0,0,0,0,0,0,0,0,0,0,0,0,0,0,0,0,0,0,0,0
0,0,0,0,0,0,0,0,0,0,0,0,0,0,0,0,0,0,0,0,0,0,0,0,0,0,0,0,0,0,0
0,0,0,0,0,0,0,0,0,0,0,0,0,0,0,0,0,0,0,0,0,0,0,0,0,0,0,0,0,0,0
0,0,0,0,0,0,0,0,0,0,0,0,0,0,0,0,0,0,0,0,0,0,0,0,0,0,0,0,0,0,0
0,0,0,0,0,0,0,0,0,0,0,0,0,0,0,0,0,0,0,0,0,0,0,0,0,0,0,0,0,0,0
0,0,0,0,0,0,0,0,0,0,138,0,0,0,0,0,0,0,0,0,0,0,0,0,0,0,0,0,0,0,0
0,0,0,0,0,0,0,0,0,126,126,126,0,0,0,0,0,0,0,0,0,0,0,0,0,0,0,0,0,0,0
0,0,0,0,0,0,126,126,126,126,126,126,126,0,0,0,0,0,0,0,0,0,0,0,0,0,0,0,0,0,0
0,0,0,0,0,0,126,126,126,126,126,126,126,0,0,0,0,0,0,0,0,0,0,0,0,0,0,0,0,0,0
0,0,0,0,0,126,126,126,34,34,126,126,126,138,0,0,0,0,0,0,0,0,0,0,0,0,0,0,0,0,0
0,0,0,0,0,126,126,126,34,34,34,126,126,138,0,0,0,0,0,0,0,0,0,0,0,0,0,0,0,0,0
0,0,0,0,138,126,126,126,126,126,126,126,126,138,0,0,0,0,0,0,0,0,0,0,0,0,0,0,0,0,0
0,0,0,0,0,126,126,34,126,126,126,126,126,0,0,0,0,0,0,0,0,0,0,0,0,0,0,0,0,0,0
0,0,0,0,0,0,126,34,126,34,34,126,0,0,0,0,0,0,0,0,0,0,0,0,0,0,0,0,0,0,0
0,0,0,0,0,0,0,0,0,138,138,138,0,0,0,0,0,0,0,0,0,0,0,0,0,0,0,0,0,0,0
0,0,0,0,0,0,0,0,0,138,138,0,0,0,0,0,0,0,0,0,0,0,0,0,0,0,0,0,0,0,0
0,0,0,0,0,0,0,0,0,0,0,0,0,0,0,0,0,0,0,0,0,0,0,0,0,0,0,0,0,0,0
0,0,0,0,0,0,0,0,0,0,0,0,0,0,0,0,0,0,0,0,0,0,0,0,0,0,0,0,0,0,0
0,0,0,0,0,0,0,0,0,0,0,0,0,0,0,0,0,0,0,0,0,0,0,0,0,0,0,0,0,0,0
0,0,0,0,0,0,0,0,0,0,0,0,0,0,0,0,0,0,0,0,0,0,0,0,0,0,0,0,0,0,0
0,0,0,0,0,0,0,0,0,0,0,0,0,0,0,0,0,0,0,0,0,0,0,0,0,0,0,0,0,0,0
0,0,0,0,0,0,0,0,0,0,0,0,0,0,0,0,0,0,0,0,0,0,0,0,0,0,0,0,0,0,0
0,0,0,0,0,0,0,0,0,0,0,0,0,0,0,0,0,0,0,0,0,0,0,0,0,0,0,0,0,0,0
:endlayer
layer: 23
0,0,0,0,0,0,0,0,0,0,0,0,0,0,0,0,0,0,0,0,0,0,0,0,0,0,0,0,0,0,0
0,0,0,0,0,0,0,0,0,0,0,0,0,0,0,0,0,0,0,0,0,0,0,0,0,0,0,0,0,0,0
0,0,0,0,0,0,0,0,0,0,0,0,0,0,0,0,0,0,0,0,0,0,0,0,0,0,0,0,0,0,0
0,0,0,0,0,0,0,0,0,0,0,0,0,0,0,0,0,0,0,0,0,0,0,0,0,0,0,0,0,0,0
0,0,0,0,0,0,0,0,0,0,0,0,0,0,0,0,0,0,0,0,0,0,0,0,0,0,0,0,0,0,0
0,0,0,0,0,0,0,0,0,0,0,0,0,0,0,0,0,0,0,0,0,0,0,0,0,0,0,0,0,0,0
0,0,0,0,0,0,0,0,0,0,0,0,0,0,0,0,0,0,0,0,0,0,0,0,0,0,0,0,0,0,0
0,0,0,0,0,0,0,0,0,0,0,0,0,0,0,0,0,0,0,0,0,0,0,0,0,0,0,0,0,0,0
0,0,0,0,0,0,0,0,0,0,0,0,0,0,0,0,0,0,0,0,0,0,0,0,0,0,0,0,0,0,0
0,0,0,0,0,0,0,0,0,0,0,0,0,0,0,0,0,0,0,0,0,0,0,0,0,0,0,0,0,0,0
0,0,0,0,0,0,0,0,0,0,0,0,0,0,0,0,0,0,0,0,0,0,0,0,0,0,0,0,0,0,0
0,0,0,0,0,0,0,0,0,0,0,0,0,0,0,0,0,0,0,0,0,0,0,0,0,0,0,0,0,0,0
0,0,0,0,0,0,0,0,0,0,0,0,0,0,0,0,0,0,0,0,0,0,0,0,0,0,0,0,0,0,0
0,0,0,0,0,0,0,0,0,0,0,0,0,0,0,0,0,0,0,0,0,0,0,0,0,0,0,0,0,0,0
0,0,0,0,0,0,0,0,0,0,0,0,0,0,0,0,0,0,0,0,0,0,0,0,0,0,0,0,0,0,0
0,0,0,0,0,0,0,0,0,0,0,0,0,0,0,0,0,0,0,0,0,0,0,0,0,0,0,0,0,0,0
0,0,0,0,0,0,0,0,0,0,0,0,0,0,0,0,0,0,0,0,0,0,0,0,0,0,0,0,0,0,0
0,0,0,0,0,0,0,0,0,0,0,0,0,0,0,0,0,0,0,0,0,0,0,0,0,0,0,0,0,0,0
0,0,0,0,0,0,0,0,0,0,0,0,0,0,0,0,0,0,0,0,0,0,0,0,0,0,0,0,0,0,0
0,0,0,0,0,0,0,0,0,0,0,0,0,0,0,0,0,0,0,0,0,0,0,0,0,0,0,0,0,0,0
0,0,0,0,0,0,0,0,0,0,0,0,0,0,0,0,0,0,0,0,0,0,0,0,0,0,0,0,0,0,0
0,0,0,0,0,0,0,0,0,0,0,0,0,0,0,0,0,0,0,0,0,0,0,0,0,0,0,0,0,0,0
0,0,0,0,0,0,126,126,126,126,126,0,0,0,0,0,0,0,0,0,0,0,0,0,0,0,0,0,0,0,0
0,0,0,0,0,126,126,126,126,126,126,126,126,0,0,0,0,0,0,0,0,0,0,0,0,0,0,0,0,0,0
0,0,0,0,0,126,126,126,126,126,126,126,126,0,0,0,0,0,0,0,0,0,0,0,0,0,0,0,0,0,0
0,0,0,0,0,126,126,126,34,34,126,126,126,0,0,0,0,0,0,0,0,0,0,0,0,0,0,0,0,0,0
0,0,0,0,0,126,126,126,34,34,126,126,126,0,0,0,0,0,0,0,0,0,0,0,0,0,0,0,0,0,0
0,0,0,0,0,126,126,126,126,126,126,126,126,0,0,0,0,0,0,0,0,0,0,0,0,0,0,0,0,0,0
0,0,0,0,0,0,126,126,126,126,126,126,0,0,0,0,0,0,0,0,0,0,0,0,0,0,0,0,0,0,0
0,0,0,0,0,0,126,126,126,126,126,0,0,0,0,0,0,0,0,0,0,0,0,0,0,0,0,0,0,0,0
0,0,0,0,0,0,0,0,0,0,0,0,0,0,0,0,0,0,0,0,0,0,0,0,0,0,0,0,0,0,0
0,0,0,0,0,0,0,0,0,0,0,0,0,0,0,0,0,0,0,0,0,0,0,0,0,0,0,0,0,0,0
0,0,0,0,0,0,0,0,0,0,0,0,0,0,0,0,0,0,0,0,0,0,0,0,0,0,0,0,0,0,0
0,0,0,0,0,0,0,0,0,0,0,0,0,0,0,0,0,0,0,0,0,0,0,0,0,0,0,0,0,0,0
0,0,0,0,0,0,0,0,0,0,0,0,0,0,0,0,0,0,0,0,0,0,0,0,0,0,0,0,0,0,0
0,0,0,0,0,0,0,0,0,0,0,0,0,0,0,0,0,0,0,0,0,0,0,0,0,0,0,0,0,0,0
0,0,0,0,0,0,0,0,0,0,0,0,0,0,0,0,0,0,0,0,0,0,0,0,0,0,0,0,0,0,0
0,0,0,0,0,0,0,0,0,0,0,0,0,0,0,0,0,0,0,0,0,0,0,0,0,0,0,0,0,0,0
0,0,0,0,0,0,0,0,0,0,0,0,0,0,0,0,0,0,0,0,0,0,0,0,0,0,0,0,0,0,0
:endlayer
layer: 24
0,0,0,0,0,0,0,0,0,0,0,0,0,0,0,0,0,0,0,0,0,0,0,0,0,0,0,0,0,0,0
0,0,0,0,0,0,0,0,0,0,0,0,0,0,0,0,0,0,0,0,0,0,0,0,0,0,0,0,0,0,0
0,0,0,0,0,0,0,0,0,0,0,0,0,0,0,0,0,0,0,0,0,0,0,0,0,0,0,0,0,0,0
0,0,0,0,0,0,0,0,0,0,0,0,0,0,0,0,0,0,0,0,0,0,0,0,0,0,0,0,0,0,0
0,0,0,0,0,0,0,0,0,0,0,0,0,0,0,0,0,0,0,0,0,0,0,0,0,0,0,0,0,0,0
0,0,0,0,0,0,0,0,0,0,0,0,0,0,0,0,0,0,0,0,0,0,0,0,0,0,0,0,0,0,0
0,0,0,0,0,0,0,0,0,0,0,0,0,0,0,0,0,0,0,0,0,0,0,0,0,0,0,0,0,0,0
0,0,0,0,0,0,0,0,0,0,0,0,0,0,0,0,0,0,0,0,0,0,0,0,0,0,0,0,0,0,0
0,0,0,0,0,0,0,0,0,0,0,0,0,0,0,0,0,0,0,0,0,0,0,0,0,0,0,0,0,0,0
0,0,0,0,0,0,0,0,0,0,0,0,0,0,0,0,0,0,0,0,0,0,0,0,0,0,0,0,0,0,0
0,0,0,0,0,0,0,0,0,0,0,0,0,0,0,0,0,0,0,0,0,0,0,0,0,0,0,0,0,0,0
0,0,0,0,0,0,0,0,0,0,0,0,0,0,0,0,0,0,0,0,0,0,0,0,0,0,0,0,0,0,0
0,0,0,0,0,0,0,0,0,0,0,0,0,0,0,0,0,0,0,0,0,0,0,0,0,0,0,0,0,0,0
0,0,0,0,0,0,0,0,0,0,0,0,0,0,0,0,0,0,0,0,0,0,0,0,0,0,0,0,0,0,0
0,0,0,0,0,0,0,0,0,0,0,0,0,0,0,0,0,0,0,0,0,0,0,0,0,0,0,0,0,0,0
0,0,0,0,0,0,0,0,0,0,0,0,0,0,0,0,0,0,0,0,0,0,0,0,0,0,0,0,0,0,0
0,0,0,0,0,0,0,0,0,0,0,0,0,0,0,0,0,0,0,0,0,0,0,0,0,0,0,0,0,0,0
0,0,0,0,0,0,0,0,0,0,0,0,0,0,0,0,0,0,0,0,0,0,0,0,0,0,0,0,0,0,0
0,0,0,0,0,0,0,0,0,0,0,0,0,0,0,0,0,0,0,0,0,0,0,0,0,0,0,0,0,0,0
0,0,0,0,0,0,0,0,0,0,0,0,0,0,0,0,0,0,0,0,0,0,0,0,0,0,0,0,0,0,0
0,0,0,0,0,0,0,0,0,0,0,0,0,0,0,0,0,0,0,0,0,0,0,0,0,0,0,0,0,0,0
0,0,0,0,0,0,0,0,0,0,0,0,0,0,0,0,0,0,0,0,0,0,0,0,0,0,0,0,0,0,0
0,0,0,0,0,0,0,0,0,0,0,0,0,0,0,0,0,0,0,0,0,0,0,0,0,0,0,0,0,0,0
0,0,0,0,0,0,0,0,126,126,0,0,0,0,0,0,0,0,0,0,0,0,0,0,0,0,0,0,0,0,0
0,0,0,0,0,0,0,126,126,126,126,0,0,0,0,0,0,0,0,0,0,0,0,0,0,0,0,0,0,0,0
0,0,0,0,0,0,126,126,126,126,126,126,0,0,0,0,0,0,0,0,0,0,0,0,0,0,0,0,0,0,0
0,0,0,0,0,0,126,126,126,126,126,126,0,0,0,0,0,0,0,0,0,0,0,0,0,0,0,0,0,0,0
0,0,0,0,0,0,0,126,126,126,126,0,0,0,0,0,0,0,0,0,0,0,0,0,0,0,0,0,0,0,0
0,0,0,0,0,0,0,0,126,126,0,0,0,0,0,0,0,0,0,0,0,0,0,0,0,0,0,0,0,0,0
0,0,0,0,0,0,0,0,0,0,0,0,0,0,0,0,0,0,0,0,0,0,0,0,0,0,0,0,0,0,0
0,0,0,0,0,0,0,0,0,0,0,0,0,0,0,0,0,0,0,0,0,0,0,0,0,0,0,0,0,0,0
0,0,0,0,0,0,0,0,0,0,0,0,0,0,0,0,0,0,0,0,0,0,0,0,0,0,0,0,0,0,0
0,0,0,0,0,0,0,0,0,0,0,0,0,0,0,0,0,0,0,0,0,0,0,0,0,0,0,0,0,0,0
0,0,0,0,0,0,0,0,0,0,0,0,0,0,0,0,0,0,0,0,0,0,0,0,0,0,0,0,0,0,0
0,0,0,0,0,0,0,0,0,0,0,0,0,0,0,0,0,0,0,0,0,0,0,0,0,0,0,0,0,0,0
0,0,0,0,0,0,0,0,0,0,0,0,0,0,0,0,0,0,0,0,0,0,0,0,0,0,0,0,0,0,0
0,0,0,0,0,0,0,0,0,0,0,0,0,0,0,0,0,0,0,0,0,0,0,0,0,0,0,0,0,0,0
0,0,0,0,0,0,0,0,0,0,0,0,0,0,0,0,0,0,0,0,0,0,0,0,0,0,0,0,0,0,0
0,0,0,0,0,0,0,0,0,0,0,0,0,0,0,0,0,0,0,0,0,0,0,0,0,0,0,0,0,0,0
:endlayer

#### RULES ####
rule:
plugin=vanillaBlocks
number=1
data:
JSON:{blockState:{blockName:"minecraft:dirt",properties:{variant:"dirt",snowy:"false"}}}
:enddata
:endrule

rule:
plugin=vanillaBlocks
number=2
data:
JSON:{blockState:{blockName:"minecraft:grass",properties:{snowy:"false"}}}
:enddata
:endrule

rule:
plugin=vanillaBlocks
number=3
data:
JSON:{blockState:{blockName:"minecraft:cobblestone"}}
:enddata
:endrule

rule:
plugin=vanillaBlocks
number=4
data:
JSON:{blockState:{blockName:"minecraft:mossy_cobblestone"}}
:enddata
:endrule

rule:
plugin=vanillaBlocks
number=5
data:
JSON:{blockState:{blockName:"minecraft:stained_hardened_clay",properties:{color:"brown"}}}
:enddata
:endrule

rule:
plugin=vanillaBlocks
number=6
data:
JSON:{blockState:{blockName:"minecraft:wooden_slab",properties:{half:"bottom",variant:"dark_oak"}}}
:enddata
:endrule

rule:
plugin=vanillaBlocks
number=7
data:
JSON:{blockState:{blockName:"minecraft:stone_stairs",properties:{half:"bottom",shape:"straight",facing:"east"}}}
:enddata
:endrule

rule:
plugin=inventory
number=8
data:
JSON:{blockState:{blockName:"minecraft:chest",properties:{facing:"south"}},lootLevel:0,teData:{ForgeData:{},Items:[{Slot:5b,id:"minecraft:torch",Count:10b,Damage:0s},{Slot:7b,id:"minecraft:gold_nugget",Count:23b,Damage:0s},{Slot:10b,id:"ancientwarfarenpc:coin",Count:7b,tag:{metal:"gold"},Damage:0s},{Slot:11b,id:"ancientwarfarenpc:coin",Count:26b,tag:{metal:"silver"},Damage:0s},{Slot:12b,id:"minecraft:iron_chestplate",Count:1b,Damage:0s},{Slot:13b,id:"minecraft:iron_helmet",Count:1b,Damage:0s},{Slot:15b,id:"minecraft:diamond_sword",Count:1b,Damage:0s},{Slot:17b,id:"minecraft:bow",Count:1b,Damage:0s},{Slot:19b,id:"minecraft:dye",Count:21b,Damage:4s},{Slot:21b,id:"minecraft:iron_boots",Count:1b,Damage:0s},{Slot:22b,id:"minecraft:iron_leggings",Count:1b,Damage:0s},{Slot:26b,id:"minecraft:arrow",Count:32b,Damage:0s}],id:"minecraft:chest",Lock:""},inventoryData:{length:12,inventoryContents:[{id:"minecraft:torch",Count:10b,slot:0,Damage:0s},{id:"minecraft:gold_nugget",Count:23b,slot:1,Damage:0s},{id:"ancientwarfarenpc:coin",Count:7b,tag:{metal:"gold"},slot:2,Damage:0s},{id:"ancientwarfarenpc:coin",Count:26b,tag:{metal:"silver"},slot:3,Damage:0s},{id:"minecraft:iron_chestplate",Count:1b,slot:4,Damage:0s},{id:"minecraft:iron_helmet",Count:1b,slot:5,Damage:0s},{id:"minecraft:diamond_sword",Count:1b,slot:6,Damage:0s},{id:"minecraft:bow",Count:1b,slot:7,Damage:0s},{id:"minecraft:dye",Count:21b,slot:8,Damage:4s},{id:"minecraft:iron_boots",Count:1b,slot:9,Damage:0s},{id:"minecraft:iron_leggings",Count:1b,slot:10,Damage:0s},{id:"minecraft:arrow",Count:32b,slot:11,Damage:0s}]},legacyFeatures:1b}
:enddata
:endrule

rule:
plugin=vanillaBlocks
number=9
data:
JSON:{blockState:{blockName:"minecraft:planks",properties:{variant:"dark_oak"}}}
:enddata
:endrule

rule:
plugin=inventory
number=10
data:
JSON:{blockState:{blockName:"minecraft:chest",properties:{facing:"west"}},lootLevel:0,teData:{ForgeData:{},Items:[{Slot:2b,id:"ancientwarfarenpc:coin",Count:1b,tag:{metal:"gold"},Damage:0s},{Slot:3b,id:"ancientwarfarenpc:coin",Count:2b,tag:{metal:"silver"},Damage:0s},{Slot:4b,id:"ancientwarfarenpc:coin",Count:5b,tag:{metal:"copper"},Damage:0s},{Slot:6b,id:"minecraft:rotten_flesh",Count:4b,Damage:0s},{Slot:7b,id:"minecraft:rotten_flesh",Count:4b,Damage:0s},{Slot:10b,id:"minecraft:coal",Count:5b,Damage:0s},{Slot:12b,id:"minecraft:rotten_flesh",Count:14b,Damage:0s},{Slot:14b,id:"minecraft:bone",Count:15b,Damage:0s},{Slot:16b,id:"minecraft:gold_nugget",Count:7b,Damage:0s},{Slot:17b,id:"minecraft:red_mushroom",Count:19b,Damage:0s},{Slot:20b,id:"minecraft:slime_ball",Count:5b,Damage:0s},{Slot:21b,id:"minecraft:spider_eye",Count:4b,Damage:0s},{Slot:22b,id:"minecraft:dye",Count:4b,Damage:4s},{Slot:24b,id:"minecraft:rotten_flesh",Count:7b,Damage:0s},{Slot:26b,id:"minecraft:brown_mushroom",Count:15b,Damage:0s}],id:"minecraft:chest",Lock:""},inventoryData:{length:15,inventoryContents:[{id:"ancientwarfarenpc:coin",Count:1b,tag:{metal:"gold"},slot:0,Damage:0s},{id:"ancientwarfarenpc:coin",Count:2b,tag:{metal:"silver"},slot:1,Damage:0s},{id:"ancientwarfarenpc:coin",Count:5b,tag:{metal:"copper"},slot:2,Damage:0s},{id:"minecraft:rotten_flesh",Count:4b,slot:3,Damage:0s},{id:"minecraft:rotten_flesh",Count:4b,slot:4,Damage:0s},{id:"minecraft:coal",Count:5b,slot:5,Damage:0s},{id:"minecraft:rotten_flesh",Count:14b,slot:6,Damage:0s},{id:"minecraft:bone",Count:15b,slot:7,Damage:0s},{id:"minecraft:gold_nugget",Count:7b,slot:8,Damage:0s},{id:"minecraft:red_mushroom",Count:19b,slot:9,Damage:0s},{id:"minecraft:slime_ball",Count:5b,slot:10,Damage:0s},{id:"minecraft:spider_eye",Count:4b,slot:11,Damage:0s},{id:"minecraft:dye",Count:4b,slot:12,Damage:4s},{id:"minecraft:rotten_flesh",Count:7b,slot:13,Damage:0s},{id:"minecraft:brown_mushroom",Count:15b,slot:14,Damage:0s}]},legacyFeatures:1b}
:enddata
:endrule

rule:
plugin=vanillaBlocks
number=11
data:
JSON:{blockState:{blockName:"minecraft:crafting_table"}}
:enddata
:endrule

rule:
plugin=inventory
number=12
data:
JSON:{blockState:{blockName:"minecraft:furnace",properties:{facing:"west"}},lootLevel:0,teData:{CookTime:0,BurnTime:0,Items:[],id:"minecraft:furnace",CookTimeTotal:0,Lock:""},inventoryData:{length:0,inventoryContents:[]},legacyFeatures:0b}
:enddata
:endrule

rule:
plugin=vanillaBlocks
number=13
data:
JSON:{blockState:{blockName:"minecraft:fence",properties:{east:"false",south:"false",north:"false",west:"false"}}}
:enddata
:endrule

rule:
plugin=blockTile
number=14
data:
JSON:{blockState:{blockName:"ancientwarfarestructure:advanced_spawner",properties:{transparent:"true"}},teData:{id:"ancientwarfarestructure:advanced_spawner_tile",spawnerSettings:{minDelay:0,spawnDelay:0,lightSensitive:0b,spawnGroups:[{settingsList:[{remainingSpawnCount:1,hostile:1b,forced:1b,customTag:{factionName:"orc"},maxToSpawn:1,entityId:"ancientwarfarenpc:faction.archer",minToSpawn:1}],groupWeight:1}],playerRange:8,respondToRedstone:0b,inventory:{Size:9,Items:[]},spawnRange:0,transparent:1b,maxDelay:0,xpToDrop:0,mobRange:0,debugMode:0b,maxNearbyMonsters:0}}}
:enddata
:endrule

rule:
plugin=inventory
number=15
data:
JSON:{blockState:{blockName:"minecraft:chest",properties:{facing:"west"}},lootLevel:0,teData:{ForgeData:{},Items:[{Slot:0b,id:"minecraft:rotten_flesh",Count:3b,Damage:0s},{Slot:1b,id:"minecraft:rotten_flesh",Count:3b,Damage:0s},{Slot:2b,id:"minecraft:rotten_flesh",Count:1b,Damage:0s},{Slot:3b,id:"minecraft:spider_eye",Count:6b,Damage:0s},{Slot:4b,id:"ancientwarfarenpc:coin",Count:2b,tag:{metal:"gold"},Damage:0s},{Slot:6b,id:"minecraft:bone",Count:11b,Damage:0s},{Slot:8b,id:"minecraft:red_mushroom",Count:10b,Damage:0s},{Slot:9b,id:"minecraft:rotten_flesh",Count:2b,Damage:0s},{Slot:10b,id:"minecraft:rotten_flesh",Count:4b,Damage:0s},{Slot:11b,id:"minecraft:bone",Count:11b,Damage:0s},{Slot:13b,id:"ancientwarfarenpc:coin",Count:6b,tag:{metal:"silver"},Damage:0s},{Slot:15b,id:"minecraft:poisonous_potato",Count:27b,Damage:0s},{Slot:16b,id:"minecraft:gold_nugget",Count:6b,Damage:0s},{Slot:19b,id:"minecraft:rotten_flesh",Count:2b,Damage:0s},{Slot:20b,id:"minecraft:slime_ball",Count:6b,Damage:0s},{Slot:21b,id:"minecraft:dye",Count:6b,Damage:4s},{Slot:22b,id:"ancientwarfarenpc:coin",Count:9b,tag:{metal:"copper"},Damage:0s},{Slot:23b,id:"minecraft:coal",Count:8b,Damage:0s},{Slot:25b,id:"minecraft:bone",Count:12b,Damage:0s},{Slot:26b,id:"minecraft:brown_mushroom",Count:8b,Damage:0s}],id:"minecraft:chest",Lock:""},inventoryData:{length:20,inventoryContents:[{id:"minecraft:rotten_flesh",Count:3b,slot:0,Damage:0s},{id:"minecraft:rotten_flesh",Count:3b,slot:1,Damage:0s},{id:"minecraft:rotten_flesh",Count:1b,slot:2,Damage:0s},{id:"minecraft:spider_eye",Count:6b,slot:3,Damage:0s},{id:"ancientwarfarenpc:coin",Count:2b,tag:{metal:"gold"},slot:4,Damage:0s},{id:"minecraft:bone",Count:11b,slot:5,Damage:0s},{id:"minecraft:red_mushroom",Count:10b,slot:6,Damage:0s},{id:"minecraft:rotten_flesh",Count:2b,slot:7,Damage:0s},{id:"minecraft:rotten_flesh",Count:4b,slot:8,Damage:0s},{id:"minecraft:bone",Count:11b,slot:9,Damage:0s},{id:"ancientwarfarenpc:coin",Count:6b,tag:{metal:"silver"},slot:10,Damage:0s},{id:"minecraft:poisonous_potato",Count:27b,slot:11,Damage:0s},{id:"minecraft:gold_nugget",Count:6b,slot:12,Damage:0s},{id:"minecraft:rotten_flesh",Count:2b,slot:13,Damage:0s},{id:"minecraft:slime_ball",Count:6b,slot:14,Damage:0s},{id:"minecraft:dye",Count:6b,slot:15,Damage:4s},{id:"ancientwarfarenpc:coin",Count:9b,tag:{metal:"copper"},slot:16,Damage:0s},{id:"minecraft:coal",Count:8b,slot:17,Damage:0s},{id:"minecraft:bone",Count:12b,slot:18,Damage:0s},{id:"minecraft:brown_mushroom",Count:8b,slot:19,Damage:0s}]},legacyFeatures:1b}
:enddata
:endrule

rule:
plugin=inventory
number=16
data:
JSON:{blockState:{blockName:"minecraft:furnace",properties:{facing:"west"}},lootLevel:0,teData:{CookTime:0,BurnTime:0,Items:[],id:"minecraft:furnace",CookTimeTotal:0,Lock:""},inventoryData:{length:0,inventoryContents:[]},legacyFeatures:0b}
:enddata
:endrule

rule:
plugin=blockTile
number=17
data:
JSON:{blockState:{blockName:"ancientwarfarestructure:advanced_spawner",properties:{transparent:"true"}},teData:{id:"ancientwarfarestructure:advanced_spawner_tile",spawnerSettings:{minDelay:0,spawnDelay:0,lightSensitive:0b,spawnGroups:[{settingsList:[{remainingSpawnCount:1,hostile:1b,forced:1b,customTag:{factionName:"orc"},maxToSpawn:1,entityId:"ancientwarfarenpc:faction.soldier",minToSpawn:1}],groupWeight:1}],playerRange:6,respondToRedstone:0b,inventory:{Size:9,Items:[]},spawnRange:0,transparent:1b,maxDelay:0,xpToDrop:0,mobRange:0,debugMode:0b,maxNearbyMonsters:0}}}
:enddata
:endrule

rule:
plugin=blockTile
number=18
data:
JSON:{blockState:{blockName:"ancientwarfarestructure:advanced_spawner",properties:{transparent:"true"}},teData:{id:"ancientwarfarestructure:advanced_spawner_tile",spawnerSettings:{minDelay:0,spawnDelay:0,lightSensitive:0b,spawnGroups:[{settingsList:[{remainingSpawnCount:1,hostile:1b,forced:1b,customTag:{factionName:"orc"},maxToSpawn:1,entityId:"ancientwarfarenpc:faction.archer",minToSpawn:1}],groupWeight:1}],playerRange:8,respondToRedstone:0b,inventory:{Size:9,Items:[]},spawnRange:0,transparent:1b,maxDelay:0,xpToDrop:0,mobRange:0,debugMode:0b,maxNearbyMonsters:0}}}
:enddata
:endrule

rule:
plugin=blockTile
number=19
data:
JSON:{blockState:{blockName:"ancientwarfarestructure:advanced_spawner",properties:{transparent:"true"}},teData:{id:"ancientwarfarestructure:advanced_spawner_tile",spawnerSettings:{minDelay:0,spawnDelay:0,lightSensitive:0b,spawnGroups:[{settingsList:[{remainingSpawnCount:1,hostile:1b,forced:1b,customTag:{factionName:"orc"},maxToSpawn:1,entityId:"ancientwarfarenpc:faction.civilian.female",minToSpawn:1}],groupWeight:1}],playerRange:6,respondToRedstone:0b,inventory:{Size:9,Items:[]},spawnRange:0,transparent:1b,maxDelay:0,xpToDrop:0,mobRange:0,debugMode:0b,maxNearbyMonsters:0}}}
:enddata
:endrule

rule:
plugin=blockTile
number=20
data:
JSON:{blockState:{blockName:"ancientwarfarestructure:advanced_spawner",properties:{transparent:"true"}},teData:{id:"ancientwarfarestructure:advanced_spawner_tile",spawnerSettings:{minDelay:0,spawnDelay:0,lightSensitive:0b,spawnGroups:[{settingsList:[{remainingSpawnCount:1,hostile:1b,forced:1b,customTag:{factionName:"orc"},maxToSpawn:1,entityId:"ancientwarfarenpc:faction.soldier",minToSpawn:1}],groupWeight:1}],playerRange:6,respondToRedstone:0b,inventory:{Size:9,Items:[]},spawnRange:0,transparent:1b,maxDelay:0,xpToDrop:0,mobRange:0,debugMode:0b,maxNearbyMonsters:0}}}
:enddata
:endrule

rule:
plugin=vanillaBlocks
number=21
data:
JSON:{blockState:{blockName:"minecraft:stone_stairs",properties:{half:"bottom",shape:"straight",facing:"north"}}}
:enddata
:endrule

rule:
plugin=blockTile
number=22
data:
JSON:{blockState:{blockName:"ancientwarfarestructure:advanced_spawner",properties:{transparent:"true"}},teData:{id:"ancientwarfarestructure:advanced_spawner_tile",spawnerSettings:{minDelay:0,spawnDelay:0,lightSensitive:0b,spawnGroups:[{settingsList:[{remainingSpawnCount:1,hostile:1b,forced:1b,customTag:{factionName:"orc"},maxToSpawn:1,entityId:"ancientwarfarenpc:faction.soldier.elite",minToSpawn:1}],groupWeight:1}],playerRange:6,respondToRedstone:0b,inventory:{Size:9,Items:[]},spawnRange:0,transparent:1b,maxDelay:0,xpToDrop:0,mobRange:0,debugMode:0b,maxNearbyMonsters:0}}}
:enddata
:endrule

rule:
plugin=blockTile
number=23
data:
JSON:{blockState:{blockName:"ancientwarfarestructure:advanced_spawner",properties:{transparent:"true"}},teData:{id:"ancientwarfarestructure:advanced_spawner_tile",spawnerSettings:{minDelay:0,spawnDelay:0,lightSensitive:0b,spawnGroups:[{settingsList:[{remainingSpawnCount:1,hostile:1b,forced:1b,customTag:{factionName:"orc"},maxToSpawn:1,entityId:"ancientwarfarenpc:faction.soldier",minToSpawn:1}],groupWeight:1}],playerRange:6,respondToRedstone:0b,inventory:{Size:9,Items:[]},spawnRange:0,transparent:1b,maxDelay:0,xpToDrop:0,mobRange:0,debugMode:0b,maxNearbyMonsters:0}}}
:enddata
:endrule

rule:
plugin=blockTile
number=24
data:
JSON:{blockState:{blockName:"ancientwarfarestructure:advanced_spawner",properties:{transparent:"true"}},teData:{id:"ancientwarfarestructure:advanced_spawner_tile",spawnerSettings:{minDelay:0,spawnDelay:0,lightSensitive:0b,spawnGroups:[{settingsList:[{remainingSpawnCount:1,hostile:1b,forced:1b,customTag:{factionName:"orc"},maxToSpawn:1,entityId:"ancientwarfarenpc:faction.civilian.female",minToSpawn:1}],groupWeight:1}],playerRange:6,respondToRedstone:0b,inventory:{Size:9,Items:[]},spawnRange:0,transparent:1b,maxDelay:0,xpToDrop:0,mobRange:0,debugMode:0b,maxNearbyMonsters:0}}}
:enddata
:endrule

rule:
plugin=blockTile
number=25
data:
JSON:{blockState:{blockName:"ancientwarfarestructure:advanced_spawner",properties:{transparent:"true"}},teData:{id:"ancientwarfarestructure:advanced_spawner_tile",spawnerSettings:{minDelay:0,spawnDelay:0,lightSensitive:0b,spawnGroups:[{settingsList:[{remainingSpawnCount:1,hostile:1b,forced:1b,customTag:{factionName:"orc"},maxToSpawn:1,entityId:"ancientwarfarenpc:faction.archer",minToSpawn:1}],groupWeight:1}],playerRange:8,respondToRedstone:0b,inventory:{Size:9,Items:[]},spawnRange:0,transparent:1b,maxDelay:0,xpToDrop:0,mobRange:0,debugMode:0b,maxNearbyMonsters:0}}}
:enddata
:endrule

rule:
plugin=inventory
number=26
data:
JSON:{blockState:{blockName:"minecraft:furnace",properties:{facing:"east"}},lootLevel:0,teData:{CookTime:0,BurnTime:0,Items:[],id:"minecraft:furnace",CookTimeTotal:0,Lock:""},inventoryData:{length:0,inventoryContents:[]},legacyFeatures:0b}
:enddata
:endrule

rule:
plugin=inventory
number=27
data:
JSON:{blockState:{blockName:"minecraft:chest",properties:{facing:"east"}},lootLevel:0,teData:{ForgeData:{},Items:[{Slot:0b,id:"minecraft:rotten_flesh",Count:3b,Damage:0s},{Slot:1b,id:"minecraft:rotten_flesh",Count:5b,Damage:0s},{Slot:2b,id:"minecraft:dye",Count:4b,Damage:4s},{Slot:3b,id:"ancientwarfarenpc:coin",Count:4b,tag:{metal:"copper"},Damage:0s},{Slot:4b,id:"ancientwarfarenpc:coin",Count:2b,tag:{metal:"silver"},Damage:0s},{Slot:5b,id:"ancientwarfarenpc:coin",Count:1b,tag:{metal:"gold"},Damage:0s},{Slot:6b,id:"minecraft:bone",Count:3b,Damage:0s},{Slot:8b,id:"minecraft:red_mushroom",Count:9b,Damage:0s},{Slot:9b,id:"minecraft:rotten_flesh",Count:3b,Damage:0s},{Slot:10b,id:"minecraft:rotten_flesh",Count:4b,Damage:0s},{Slot:13b,id:"minecraft:bone",Count:8b,Damage:0s},{Slot:14b,id:"minecraft:bone",Count:2b,Damage:0s},{Slot:15b,id:"minecraft:bone",Count:1b,Damage:0s},{Slot:16b,id:"minecraft:coal",Count:8b,Damage:0s},{Slot:18b,id:"minecraft:rotten_flesh",Count:3b,Damage:0s},{Slot:19b,id:"minecraft:rotten_flesh",Count:3b,Damage:0s},{Slot:20b,id:"minecraft:slime_ball",Count:5b,Damage:0s},{Slot:21b,id:"minecraft:spider_eye",Count:3b,Damage:0s},{Slot:24b,id:"minecraft:gold_nugget",Count:5b,Damage:0s},{Slot:25b,id:"minecraft:bone",Count:3b,Damage:0s},{Slot:26b,id:"minecraft:brown_mushroom",Count:7b,Damage:0s}],id:"minecraft:chest",Lock:""},inventoryData:{length:21,inventoryContents:[{id:"minecraft:rotten_flesh",Count:3b,slot:0,Damage:0s},{id:"minecraft:rotten_flesh",Count:5b,slot:1,Damage:0s},{id:"minecraft:dye",Count:4b,slot:2,Damage:4s},{id:"ancientwarfarenpc:coin",Count:4b,tag:{metal:"copper"},slot:3,Damage:0s},{id:"ancientwarfarenpc:coin",Count:2b,tag:{metal:"silver"},slot:4,Damage:0s},{id:"ancientwarfarenpc:coin",Count:1b,tag:{metal:"gold"},slot:5,Damage:0s},{id:"minecraft:bone",Count:3b,slot:6,Damage:0s},{id:"minecraft:red_mushroom",Count:9b,slot:7,Damage:0s},{id:"minecraft:rotten_flesh",Count:3b,slot:8,Damage:0s},{id:"minecraft:rotten_flesh",Count:4b,slot:9,Damage:0s},{id:"minecraft:bone",Count:8b,slot:10,Damage:0s},{id:"minecraft:bone",Count:2b,slot:11,Damage:0s},{id:"minecraft:bone",Count:1b,slot:12,Damage:0s},{id:"minecraft:coal",Count:8b,slot:13,Damage:0s},{id:"minecraft:rotten_flesh",Count:3b,slot:14,Damage:0s},{id:"minecraft:rotten_flesh",Count:3b,slot:15,Damage:0s},{id:"minecraft:slime_ball",Count:5b,slot:16,Damage:0s},{id:"minecraft:spider_eye",Count:3b,slot:17,Damage:0s},{id:"minecraft:gold_nugget",Count:5b,slot:18,Damage:0s},{id:"minecraft:bone",Count:3b,slot:19,Damage:0s},{id:"minecraft:brown_mushroom",Count:7b,slot:20,Damage:0s}]},legacyFeatures:1b}
:enddata
:endrule

rule:
plugin=blockTile
number=28
data:
JSON:{blockState:{blockName:"ancientwarfarestructure:advanced_spawner",properties:{transparent:"true"}},teData:{id:"ancientwarfarestructure:advanced_spawner_tile",spawnerSettings:{minDelay:0,spawnDelay:0,lightSensitive:0b,spawnGroups:[{settingsList:[{remainingSpawnCount:1,hostile:1b,forced:1b,customTag:{factionName:"orc"},maxToSpawn:1,entityId:"ancientwarfarenpc:faction.soldier",minToSpawn:1}],groupWeight:1}],playerRange:6,respondToRedstone:0b,inventory:{Size:9,Items:[]},spawnRange:0,transparent:1b,maxDelay:0,xpToDrop:0,mobRange:0,debugMode:0b,maxNearbyMonsters:0}}}
:enddata
:endrule

rule:
plugin=blockTile
number=29
data:
JSON:{blockState:{blockName:"ancientwarfarestructure:advanced_spawner",properties:{transparent:"true"}},teData:{id:"ancientwarfarestructure:advanced_spawner_tile",spawnerSettings:{minDelay:0,spawnDelay:0,lightSensitive:0b,spawnGroups:[{settingsList:[{remainingSpawnCount:1,hostile:1b,forced:1b,customTag:{factionName:"orc"},maxToSpawn:1,entityId:"ancientwarfarenpc:faction.archer",minToSpawn:1}],groupWeight:1}],playerRange:8,respondToRedstone:0b,inventory:{Size:9,Items:[]},spawnRange:0,transparent:1b,maxDelay:0,xpToDrop:0,mobRange:0,debugMode:0b,maxNearbyMonsters:0}}}
:enddata
:endrule

rule:
plugin=blockTile
number=30
data:
JSON:{blockState:{blockName:"ancientwarfarestructure:advanced_spawner",properties:{transparent:"true"}},teData:{id:"ancientwarfarestructure:advanced_spawner_tile",spawnerSettings:{minDelay:0,spawnDelay:0,lightSensitive:0b,spawnGroups:[{settingsList:[{remainingSpawnCount:1,hostile:1b,forced:1b,customTag:{factionName:"orc"},maxToSpawn:1,entityId:"ancientwarfarenpc:faction.civilian.female",minToSpawn:1}],groupWeight:1}],playerRange:6,respondToRedstone:0b,inventory:{Size:9,Items:[]},spawnRange:0,transparent:1b,maxDelay:0,xpToDrop:0,mobRange:0,debugMode:0b,maxNearbyMonsters:0}}}
:enddata
:endrule

rule:
plugin=inventory
number=31
data:
JSON:{blockState:{blockName:"minecraft:furnace",properties:{facing:"east"}},lootLevel:0,teData:{CookTime:0,BurnTime:0,Items:[],id:"minecraft:furnace",CookTimeTotal:0,Lock:""},inventoryData:{length:0,inventoryContents:[]},legacyFeatures:0b}
:enddata
:endrule

rule:
plugin=inventory
number=32
data:
JSON:{blockState:{blockName:"minecraft:chest",properties:{facing:"east"}},lootLevel:0,teData:{ForgeData:{},Items:[{Slot:0b,id:"ancientwarfarenpc:coin",Count:2b,tag:{metal:"gold"},Damage:0s},{Slot:1b,id:"ancientwarfarenpc:coin",Count:5b,tag:{metal:"silver"},Damage:0s},{Slot:2b,id:"ancientwarfarenpc:coin",Count:10b,tag:{metal:"copper"},Damage:0s},{Slot:3b,id:"minecraft:rotten_flesh",Count:3b,Damage:0s},{Slot:4b,id:"minecraft:rotten_flesh",Count:3b,Damage:0s},{Slot:5b,id:"minecraft:rotten_flesh",Count:4b,Damage:0s},{Slot:8b,id:"minecraft:gold_nugget",Count:9b,Damage:0s},{Slot:10b,id:"minecraft:poisonous_potato",Count:3b,Damage:0s},{Slot:11b,id:"minecraft:poisonous_potato",Count:4b,Damage:0s},{Slot:13b,id:"minecraft:bone",Count:8b,Damage:0s},{Slot:14b,id:"minecraft:bone",Count:8b,Damage:0s},{Slot:15b,id:"minecraft:arrow",Count:3b,Damage:0s},{Slot:16b,id:"minecraft:red_mushroom",Count:3b,Damage:0s},{Slot:18b,id:"minecraft:spider_eye",Count:6b,Damage:0s},{Slot:20b,id:"minecraft:poisonous_potato",Count:4b,Damage:0s},{Slot:21b,id:"minecraft:dye",Count:3b,Damage:4s},{Slot:22b,id:"minecraft:bone",Count:2b,Damage:0s},{Slot:23b,id:"minecraft:bone",Count:1b,Damage:0s},{Slot:24b,id:"minecraft:brown_mushroom",Count:5b,Damage:0s},{Slot:25b,id:"minecraft:red_mushroom",Count:3b,Damage:0s},{Slot:26b,id:"minecraft:coal",Count:10b,Damage:0s}],id:"minecraft:chest",Lock:""},inventoryData:{length:21,inventoryContents:[{id:"ancientwarfarenpc:coin",Count:2b,tag:{metal:"gold"},slot:0,Damage:0s},{id:"ancientwarfarenpc:coin",Count:5b,tag:{metal:"silver"},slot:1,Damage:0s},{id:"ancientwarfarenpc:coin",Count:10b,tag:{metal:"copper"},slot:2,Damage:0s},{id:"minecraft:rotten_flesh",Count:3b,slot:3,Damage:0s},{id:"minecraft:rotten_flesh",Count:3b,slot:4,Damage:0s},{id:"minecraft:rotten_flesh",Count:4b,slot:5,Damage:0s},{id:"minecraft:gold_nugget",Count:9b,slot:6,Damage:0s},{id:"minecraft:poisonous_potato",Count:3b,slot:7,Damage:0s},{id:"minecraft:poisonous_potato",Count:4b,slot:8,Damage:0s},{id:"minecraft:bone",Count:8b,slot:9,Damage:0s},{id:"minecraft:bone",Count:8b,slot:10,Damage:0s},{id:"minecraft:arrow",Count:3b,slot:11,Damage:0s},{id:"minecraft:red_mushroom",Count:3b,slot:12,Damage:0s},{id:"minecraft:spider_eye",Count:6b,slot:13,Damage:0s},{id:"minecraft:poisonous_potato",Count:4b,slot:14,Damage:0s},{id:"minecraft:dye",Count:3b,slot:15,Damage:4s},{id:"minecraft:bone",Count:2b,slot:16,Damage:0s},{id:"minecraft:bone",Count:1b,slot:17,Damage:0s},{id:"minecraft:brown_mushroom",Count:5b,slot:18,Damage:0s},{id:"minecraft:red_mushroom",Count:3b,slot:19,Damage:0s},{id:"minecraft:coal",Count:10b,slot:20,Damage:0s}]},legacyFeatures:1b}
:enddata
:endrule

rule:
plugin=vanillaBlocks
number=33
data:
JSON:{blockState:{blockName:"minecraft:gravel"}}
:enddata
:endrule

rule:
plugin=vanillaBlocks
number=34
data:
JSON:{blockState:{blockName:"minecraft:log2",properties:{variant:"dark_oak",axis:"y"}}}
:enddata
:endrule

rule:
plugin=vanillaBlocks
number=35
data:
JSON:{blockState:{blockName:"minecraft:netherrack"}}
:enddata
:endrule

rule:
plugin=inventory
number=36
data:
JSON:{blockState:{blockName:"minecraft:chest",properties:{facing:"north"}},lootLevel:0,teData:{Items:[],id:"minecraft:chest",Lock:""},inventoryData:{length:0,inventoryContents:[]},legacyFeatures:1b}
:enddata
:endrule

rule:
plugin=vanillaBlocks
number=37
data:
JSON:{blockState:{blockName:"minecraft:tallgrass",properties:{type:"tall_grass"}}}
:enddata
:endrule

rule:
plugin=vanillaBlocks
number=38
data:
JSON:{blockState:{blockName:"minecraft:fence_gate",properties:{in_wall:"false",powered:"false",facing:"south",open:"false"}}}
:enddata
:endrule

rule:
plugin=vanillaBlocks
number=39
data:
JSON:{blockState:{blockName:"minecraft:stone_slab",properties:{half:"bottom",variant:"cobblestone"}}}
:enddata
:endrule

rule:
plugin=blockTile
number=40
data:
JSON:{blockState:{blockName:"ancientwarfarestructure:advanced_spawner",properties:{transparent:"true"}},teData:{id:"ancientwarfarestructure:advanced_spawner_tile",spawnerSettings:{minDelay:0,spawnDelay:0,lightSensitive:0b,spawnGroups:[{settingsList:[{remainingSpawnCount:1,hostile:1b,forced:1b,customTag:{factionName:"orc"},maxToSpawn:1,entityId:"ancientwarfarenpc:faction.archer",minToSpawn:1}],groupWeight:1}],playerRange:8,respondToRedstone:0b,inventory:{Size:9,Items:[]},spawnRange:0,transparent:1b,maxDelay:0,xpToDrop:0,mobRange:0,debugMode:0b,maxNearbyMonsters:0}}}
:enddata
:endrule

rule:
plugin=inventory
number=41
data:
JSON:{blockState:{blockName:"minecraft:chest",properties:{facing:"west"}},lootLevel:0,teData:{ForgeData:{},Items:[{Slot:1b,id:"minecraft:rotten_flesh",Count:7b,Damage:0s},{Slot:3b,id:"ancientwarfarenpc:coin",Count:14b,tag:{metal:"copper"},Damage:0s},{Slot:4b,id:"minecraft:poisonous_potato",Count:7b,Damage:0s},{Slot:5b,id:"minecraft:poisonous_potato",Count:3b,Damage:0s},{Slot:6b,id:"minecraft:poisonous_potato",Count:6b,Damage:0s},{Slot:7b,id:"minecraft:bone",Count:3b,Damage:0s},{Slot:8b,id:"minecraft:coal",Count:8b,Damage:0s},{Slot:9b,id:"minecraft:rotten_flesh",Count:7b,Damage:0s},{Slot:10b,id:"minecraft:rotten_flesh",Count:7b,Damage:0s},{Slot:11b,id:"minecraft:bone",Count:3b,Damage:0s},{Slot:12b,id:"ancientwarfarenpc:coin",Count:7b,tag:{metal:"silver"},Damage:0s},{Slot:13b,id:"ancientwarfarenpc:coin",Count:3b,tag:{metal:"gold"},Damage:0s},{Slot:14b,id:"minecraft:poisonous_potato",Count:4b,Damage:0s},{Slot:15b,id:"minecraft:poisonous_potato",Count:6b,Damage:0s},{Slot:16b,id:"minecraft:bone",Count:2b,Damage:0s},{Slot:17b,id:"minecraft:bone",Count:2b,Damage:0s},{Slot:19b,id:"minecraft:rotten_flesh",Count:7b,Damage:0s},{Slot:20b,id:"minecraft:slime_ball",Count:5b,Damage:0s},{Slot:21b,id:"minecraft:spider_eye",Count:7b,Damage:0s},{Slot:22b,id:"minecraft:dye",Count:5b,Damage:4s},{Slot:23b,id:"minecraft:gold_nugget",Count:8b,Damage:0s},{Slot:24b,id:"minecraft:brown_mushroom",Count:10b,Damage:0s},{Slot:25b,id:"minecraft:red_mushroom",Count:9b,Damage:0s},{Slot:26b,id:"minecraft:arrow",Count:13b,Damage:0s}],id:"minecraft:chest",Lock:""},inventoryData:{length:24,inventoryContents:[{id:"minecraft:rotten_flesh",Count:7b,slot:0,Damage:0s},{id:"ancientwarfarenpc:coin",Count:14b,tag:{metal:"copper"},slot:1,Damage:0s},{id:"minecraft:poisonous_potato",Count:7b,slot:2,Damage:0s},{id:"minecraft:poisonous_potato",Count:3b,slot:3,Damage:0s},{id:"minecraft:poisonous_potato",Count:6b,slot:4,Damage:0s},{id:"minecraft:bone",Count:3b,slot:5,Damage:0s},{id:"minecraft:coal",Count:8b,slot:6,Damage:0s},{id:"minecraft:rotten_flesh",Count:7b,slot:7,Damage:0s},{id:"minecraft:rotten_flesh",Count:7b,slot:8,Damage:0s},{id:"minecraft:bone",Count:3b,slot:9,Damage:0s},{id:"ancientwarfarenpc:coin",Count:7b,tag:{metal:"silver"},slot:10,Damage:0s},{id:"ancientwarfarenpc:coin",Count:3b,tag:{metal:"gold"},slot:11,Damage:0s},{id:"minecraft:poisonous_potato",Count:4b,slot:12,Damage:0s},{id:"minecraft:poisonous_potato",Count:6b,slot:13,Damage:0s},{id:"minecraft:bone",Count:2b,slot:14,Damage:0s},{id:"minecraft:bone",Count:2b,slot:15,Damage:0s},{id:"minecraft:rotten_flesh",Count:7b,slot:16,Damage:0s},{id:"minecraft:slime_ball",Count:5b,slot:17,Damage:0s},{id:"minecraft:spider_eye",Count:7b,slot:18,Damage:0s},{id:"minecraft:dye",Count:5b,slot:19,Damage:4s},{id:"minecraft:gold_nugget",Count:8b,slot:20,Damage:0s},{id:"minecraft:brown_mushroom",Count:10b,slot:21,Damage:0s},{id:"minecraft:red_mushroom",Count:9b,slot:22,Damage:0s},{id:"minecraft:arrow",Count:13b,slot:23,Damage:0s}]},legacyFeatures:1b}
:enddata
:endrule

rule:
plugin=inventory
number=42
data:
JSON:{blockState:{blockName:"minecraft:furnace",properties:{facing:"west"}},lootLevel:0,teData:{CookTime:0,BurnTime:0,Items:[],id:"minecraft:furnace",CookTimeTotal:0,Lock:""},inventoryData:{length:0,inventoryContents:[]},legacyFeatures:0b}
:enddata
:endrule

rule:
plugin=vanillaBlocks
number=43
data:
JSON:{blockState:{blockName:"minecraft:nether_brick_fence",properties:{east:"false",south:"false",north:"false",west:"false"}}}
:enddata
:endrule

rule:
plugin=vanillaBlocks
number=44
data:
JSON:{blockState:{blockName:"minecraft:cauldron",properties:{level:"3"}}}
:enddata
:endrule

rule:
plugin=blockTile
number=45
data:
JSON:{blockState:{blockName:"ancientwarfarestructure:advanced_spawner",properties:{transparent:"true"}},teData:{id:"ancientwarfarestructure:advanced_spawner_tile",spawnerSettings:{minDelay:0,spawnDelay:0,lightSensitive:0b,spawnGroups:[{settingsList:[{remainingSpawnCount:1,hostile:1b,forced:1b,customTag:{factionName:"orc"},maxToSpawn:1,entityId:"ancientwarfarenpc:faction.soldier.elite",minToSpawn:1}],groupWeight:1}],playerRange:6,respondToRedstone:0b,inventory:{Size:9,Items:[]},spawnRange:0,transparent:1b,maxDelay:0,xpToDrop:0,mobRange:0,debugMode:0b,maxNearbyMonsters:0}}}
:enddata
:endrule

rule:
plugin=vanillaBlocks
number=46
data:
JSON:{blockState:{blockName:"minecraft:fire",properties:{east:"false",south:"false",north:"false",west:"false",up:"false",age:"15"}}}
:enddata
:endrule

rule:
plugin=vanillaBlocks
number=47
data:
JSON:{blockState:{blockName:"minecraft:wooden_slab",properties:{half:"top",variant:"oak"}}}
:enddata
:endrule

rule:
plugin=blockTile
number=48
data:
JSON:{blockState:{blockName:"ancientwarfarestructure:advanced_spawner",properties:{transparent:"true"}},teData:{id:"ancientwarfarestructure:advanced_spawner_tile",spawnerSettings:{minDelay:0,spawnDelay:0,lightSensitive:0b,spawnGroups:[{settingsList:[{remainingSpawnCount:1,hostile:1b,forced:1b,customTag:{factionName:"orc"},maxToSpawn:1,entityId:"ancientwarfarenpc:faction.priest",minToSpawn:1}],groupWeight:1}],playerRange:6,respondToRedstone:0b,inventory:{Size:9,Items:[]},spawnRange:0,transparent:1b,maxDelay:0,xpToDrop:0,mobRange:0,debugMode:0b,maxNearbyMonsters:0}}}
:enddata
:endrule

rule:
plugin=inventory
number=49
data:
JSON:{blockState:{blockName:"minecraft:chest",properties:{facing:"north"}},lootLevel:0,teData:{ForgeData:{},Items:[{Slot:6b,id:"minecraft:arrow",Count:16b,Damage:0s},{Slot:13b,id:"minecraft:bone",Count:35b,Damage:0s},{Slot:16b,id:"minecraft:gold_nugget",Count:5b,Damage:0s},{Slot:25b,id:"minecraft:torch",Count:10b,Damage:0s}],id:"minecraft:chest",Lock:""},inventoryData:{length:4,inventoryContents:[{id:"minecraft:arrow",Count:16b,slot:0,Damage:0s},{id:"minecraft:bone",Count:35b,slot:1,Damage:0s},{id:"minecraft:gold_nugget",Count:5b,slot:2,Damage:0s},{id:"minecraft:torch",Count:10b,slot:3,Damage:0s}]},legacyFeatures:1b}
:enddata
:endrule

rule:
plugin=blockTile
number=50
data:
JSON:{blockState:{blockName:"ancientwarfarestructure:advanced_spawner",properties:{transparent:"true"}},teData:{id:"ancientwarfarestructure:advanced_spawner_tile",spawnerSettings:{minDelay:0,spawnDelay:0,lightSensitive:0b,spawnGroups:[{settingsList:[{remainingSpawnCount:1,hostile:1b,forced:1b,customTag:{factionName:"orc"},maxToSpawn:1,entityId:"ancientwarfarenpc:faction.soldier.elite",minToSpawn:1}],groupWeight:1}],playerRange:6,respondToRedstone:0b,inventory:{Size:9,Items:[]},spawnRange:0,transparent:1b,maxDelay:0,xpToDrop:0,mobRange:0,debugMode:0b,maxNearbyMonsters:0}}}
:enddata
:endrule

rule:
plugin=blockTile
number=51
data:
JSON:{blockState:{blockName:"ancientwarfarestructure:advanced_spawner",properties:{transparent:"true"}},teData:{id:"ancientwarfarestructure:advanced_spawner_tile",spawnerSettings:{minDelay:0,spawnDelay:0,lightSensitive:0b,spawnGroups:[{settingsList:[{remainingSpawnCount:1,hostile:1b,forced:1b,customTag:{factionName:"orc"},maxToSpawn:1,entityId:"ancientwarfarenpc:faction.soldier.elite",minToSpawn:1}],groupWeight:1}],playerRange:6,respondToRedstone:0b,inventory:{Size:9,Items:[]},spawnRange:0,transparent:1b,maxDelay:0,xpToDrop:0,mobRange:0,debugMode:0b,maxNearbyMonsters:0}}}
:enddata
:endrule

rule:
plugin=vanillaBlocks
number=52
data:
JSON:{blockState:{blockName:"minecraft:dark_oak_stairs",properties:{half:"top",shape:"straight",facing:"south"}}}
:enddata
:endrule

rule:
plugin=vanillaBlocks
number=53
data:
JSON:{blockState:{blockName:"minecraft:dark_oak_stairs",properties:{half:"top",shape:"straight",facing:"north"}}}
:enddata
:endrule

rule:
plugin=vanillaBlocks
number=54
data:
JSON:{blockState:{blockName:"minecraft:torch",properties:{facing:"west"}}}
:enddata
:endrule

rule:
plugin=vanillaBlocks
number=55
data:
JSON:{blockState:{blockName:"minecraft:dark_oak_stairs",properties:{half:"top",shape:"straight",facing:"east"}}}
:enddata
:endrule

rule:
plugin=vanillaSkull
number=56
data:
