# Ancient Warfare Structure Template File
# Auto-generated structure template file. created on: 8/19/2019 at: 10:23:14
# Lines beginning with # denote comments

header:
version=2.9
name=OrcVillageSmallRoofedForest
mods=
size=27,17,22
offset=14,5,21
:endheader

#### VALIDATION ####
validation:
type=ground
survival=false
worldGenEnabled=true
unique=false
preserveBlocks=false
selectionWeight=30
clusterValue=20
minDuplicateDistance=500
dimensionWhiteList=true
dimensionList=0
biomeWhiteList=true
biomeList=minecraft:roofed_forest
leveling=4
fill=4
border=4
blockSwap=false
:endvalidation

#### LAYERS ####
layer: 0
1,1,1,1,1,1,1,1,1,1,1,1,1,1,1,1,1,1,1,1,1,1,1,1,1,1,1
1,1,1,1,1,1,1,1,1,1,1,1,1,1,1,1,1,1,1,1,1,1,1,1,1,1,1
1,1,1,1,1,1,1,1,1,1,1,1,1,1,1,1,1,1,1,1,1,1,1,1,1,1,1
1,1,1,1,1,1,1,1,1,1,1,1,1,1,1,1,1,1,1,1,1,1,1,1,1,1,1
1,1,1,1,1,1,1,1,1,1,1,1,1,1,1,1,1,1,1,1,1,1,1,1,1,1,1
1,1,1,1,1,1,1,1,1,1,1,1,1,1,1,1,1,1,1,1,1,1,1,1,1,1,1
1,1,1,1,1,1,1,1,1,1,1,1,1,1,1,1,1,1,1,1,1,1,1,1,1,1,1
1,1,1,1,1,1,1,1,1,1,1,1,1,1,1,1,1,1,1,1,1,1,1,1,1,1,1
1,1,1,1,1,1,1,1,1,1,1,1,1,1,1,1,1,1,1,1,1,1,1,1,1,1,1
1,1,1,1,1,1,1,1,1,1,1,1,1,1,1,1,1,1,1,1,1,1,1,1,1,1,1
1,1,1,1,1,1,1,1,1,1,1,1,1,1,1,1,1,1,1,1,1,1,1,1,1,1,1
1,1,1,1,1,1,1,1,1,1,1,1,1,1,1,1,1,1,1,1,1,1,1,1,1,1,1
1,1,1,1,1,1,1,1,1,1,1,1,1,1,1,1,1,1,1,1,1,1,1,1,1,1,1
1,1,1,1,1,1,1,1,1,1,1,1,1,1,1,1,1,1,1,1,1,1,1,1,1,1,1
1,1,1,1,1,1,1,1,1,1,1,1,1,1,1,1,1,1,1,1,1,1,1,1,1,1,1
1,1,1,1,1,1,1,1,1,1,1,1,1,1,1,1,1,1,1,1,1,1,1,1,1,1,1
1,1,1,1,1,1,1,1,1,1,1,1,1,1,1,1,1,1,1,1,1,1,1,1,1,1,1
1,1,1,1,1,1,1,1,1,1,1,1,1,1,1,1,1,1,1,1,1,1,1,1,1,1,1
1,1,1,1,1,1,1,1,1,1,1,1,1,1,1,1,1,1,1,1,1,1,1,1,1,1,1
1,1,1,1,1,1,1,1,1,1,1,1,1,1,1,1,1,1,1,1,1,1,1,1,1,1,1
1,1,1,1,1,1,1,1,1,1,1,1,1,1,1,1,1,1,1,1,1,1,1,1,1,1,1
1,1,1,1,1,1,1,1,1,1,1,1,1,1,1,1,1,1,1,1,1,1,1,1,1,1,1
:endlayer
layer: 1
1,1,1,1,1,1,1,1,1,1,1,1,1,1,1,1,1,1,1,1,1,1,1,1,1,1,1
1,1,1,1,1,1,1,1,1,1,1,1,1,1,1,1,1,1,1,1,1,1,1,1,1,1,1
1,1,1,1,1,1,1,1,1,1,1,1,1,1,1,1,1,1,1,1,1,1,1,1,1,1,1
1,1,1,1,1,1,1,1,1,1,1,1,1,1,1,1,1,1,1,1,1,1,1,1,1,1,1
1,1,1,1,1,1,1,1,1,1,1,1,1,1,1,1,1,1,1,1,1,1,1,1,1,1,1
1,1,1,1,1,1,1,1,1,1,1,1,1,1,1,1,1,1,1,1,1,1,1,1,1,1,1
1,1,1,1,1,1,1,1,1,1,1,1,1,1,1,1,1,1,1,1,1,1,1,1,1,1,1
1,1,1,1,1,1,1,1,1,1,1,1,1,1,1,1,1,1,1,1,1,1,1,1,1,1,1
1,1,1,1,1,1,1,1,1,1,1,1,1,1,1,1,1,1,1,1,1,1,1,1,1,1,1
1,1,1,1,1,1,1,1,1,1,1,1,1,1,1,1,1,1,1,1,1,1,1,1,1,1,1
1,1,1,1,1,1,1,1,1,1,1,1,1,1,1,1,1,1,1,1,1,1,1,1,1,1,1
1,1,1,1,1,1,1,1,1,1,1,1,1,1,1,1,1,1,1,1,1,1,1,1,1,1,1
1,1,1,1,1,1,1,1,1,1,1,1,1,1,1,1,1,1,1,1,1,2,2,1,1,1,1
1,1,1,1,1,1,1,1,1,1,1,1,1,1,1,1,1,1,1,1,1,1,1,1,1,1,1
1,1,1,1,1,1,1,1,1,1,1,1,1,1,1,1,1,1,1,1,1,1,1,1,1,1,1
1,1,1,1,1,1,1,1,1,1,1,1,1,1,1,1,1,1,1,1,1,1,1,1,1,1,1
1,1,1,1,1,2,1,1,1,1,1,1,1,1,1,1,1,1,1,1,1,2,2,1,1,1,1
1,1,1,1,1,1,1,1,1,1,1,1,1,1,1,1,1,1,1,1,1,1,1,1,1,1,1
1,1,1,1,1,1,1,1,1,1,1,1,1,1,1,1,1,1,1,1,1,1,1,1,1,1,1
1,1,1,1,1,1,1,1,1,1,1,1,1,1,1,1,1,1,1,1,1,1,1,1,1,1,1
1,1,1,1,1,1,1,1,1,1,1,1,1,1,1,1,1,1,1,1,1,1,1,1,1,1,1
1,1,1,1,1,1,1,1,1,1,1,1,1,1,1,1,1,1,1,1,1,1,1,1,1,1,1
:endlayer
layer: 2
1,1,1,1,1,1,1,1,1,1,1,1,1,1,1,1,1,1,1,1,1,1,1,1,1,1,1
1,1,1,1,1,1,1,1,1,1,1,1,1,1,1,1,1,1,1,1,1,1,1,1,1,1,1
1,1,1,1,1,1,1,1,1,1,1,1,1,1,1,1,1,1,1,1,1,1,1,1,1,1,1
1,1,1,1,1,1,1,1,1,1,1,1,1,1,1,1,1,1,1,1,1,1,1,1,1,1,1
1,1,1,1,1,1,1,1,1,1,1,1,1,1,1,1,1,1,1,1,1,1,1,1,1,1,1
1,1,1,1,1,1,1,1,1,1,1,1,1,1,1,1,1,1,1,1,1,1,1,1,1,1,1
1,1,1,1,1,1,1,1,1,1,1,1,1,1,1,1,1,1,1,1,1,1,1,1,1,1,1
1,1,1,1,1,1,1,1,1,1,1,1,1,1,1,1,1,1,1,1,1,1,1,1,1,1,1
1,1,1,1,1,1,1,1,1,1,1,1,1,1,1,1,1,1,1,1,1,1,1,1,1,1,1
1,1,1,1,1,1,1,1,1,1,1,1,1,1,1,1,1,1,1,1,1,1,1,1,1,1,1
1,1,1,1,1,1,1,1,1,1,1,1,1,1,1,1,1,1,1,1,1,1,1,1,1,1,1
1,1,1,1,1,1,1,1,1,1,1,1,1,1,1,1,1,1,1,1,1,1,1,1,1,1,1
1,1,1,1,4,4,1,1,1,1,1,1,1,1,1,1,1,1,1,1,1,4,4,1,1,1,1
1,1,1,3,3,3,3,3,1,1,1,1,1,1,1,1,1,1,1,3,3,3,3,3,1,1,1
1,1,1,3,3,3,3,3,3,1,1,1,1,1,1,1,1,1,3,3,3,3,3,3,1,1,1
1,1,1,3,3,3,3,3,1,1,1,1,1,1,1,1,1,1,1,3,3,3,3,3,1,1,1
1,1,1,1,4,4,1,1,1,1,1,1,1,1,1,1,1,1,1,1,1,4,4,1,1,1,1
1,1,1,1,1,1,1,1,1,1,1,1,1,1,1,1,1,1,1,1,1,1,1,1,1,1,1
1,1,1,1,1,1,1,1,1,1,1,1,1,1,1,1,1,1,1,1,1,1,1,1,1,1,1
1,1,1,1,1,1,1,1,1,1,1,1,1,1,1,1,1,1,1,1,1,1,1,1,1,1,1
1,1,1,1,1,1,1,1,1,1,1,1,1,1,1,1,1,1,1,1,1,1,1,1,1,1,1
1,1,1,1,1,1,1,1,1,1,1,1,1,1,1,1,1,1,1,1,1,1,1,1,1,1,1
:endlayer
layer: 3
1,1,1,1,1,1,1,1,1,1,1,1,1,1,1,1,1,1,1,1,1,1,1,1,1,1,1
1,1,1,1,1,1,1,1,1,1,1,1,1,1,1,1,1,1,1,1,1,1,1,1,1,1,1
1,1,1,1,1,1,1,1,1,1,1,1,1,1,1,1,1,1,1,1,1,1,1,1,1,1,1
1,1,1,1,1,1,1,1,1,1,1,1,1,1,1,1,1,1,1,1,1,1,1,1,1,1,1
1,1,1,1,1,1,1,1,1,1,1,1,1,1,1,1,1,1,1,1,1,1,1,1,1,1,1
1,1,1,1,1,1,1,1,1,1,1,1,1,1,1,1,1,1,1,1,1,1,1,1,1,1,1
1,1,1,1,1,1,1,1,1,1,1,1,1,1,1,1,1,1,1,1,1,1,1,1,1,1,1
1,1,1,1,1,1,1,1,1,1,1,1,1,1,1,1,1,1,1,1,1,1,1,1,1,1,1
1,1,1,1,1,1,1,1,1,1,1,1,1,1,1,1,1,1,1,1,1,1,1,1,1,1,1
1,1,1,1,1,1,1,1,1,1,1,1,1,1,1,1,1,1,1,1,1,1,1,1,1,1,1
1,1,1,1,1,1,1,1,1,1,1,1,1,1,1,1,1,1,1,1,1,1,1,1,1,1,1
1,1,1,1,5,5,1,1,1,1,1,1,1,1,1,1,1,1,1,1,1,5,5,1,1,1,1
1,1,1,5,0,0,5,5,5,1,1,1,1,1,1,1,1,1,5,5,5,0,0,5,1,1,1
1,1,5,16,0,14,0,0,5,1,1,1,1,1,1,1,1,1,5,0,0,9,0,6,5,1,1
1,1,5,7,0,10,13,0,0,3,2,1,1,1,1,1,2,3,0,0,12,10,0,7,5,1,1
1,1,5,17,0,15,0,0,5,1,1,1,1,1,1,1,1,1,5,0,0,11,0,8,5,1,1
1,1,1,5,0,0,5,5,5,1,1,1,1,1,1,1,1,1,5,5,5,0,0,5,1,1,1
1,1,1,1,5,5,1,1,1,1,1,1,1,1,1,1,1,1,1,1,1,5,5,1,1,1,1
1,1,1,1,1,1,1,1,1,1,1,1,1,1,1,1,1,1,1,1,1,1,1,1,1,1,1
1,1,1,1,1,1,1,1,1,1,1,1,1,1,1,1,1,1,1,1,1,1,1,1,1,1,1
1,1,1,1,1,1,1,1,1,1,1,1,1,1,1,1,1,1,1,1,1,1,1,1,1,1,1
1,1,1,1,1,1,1,1,1,1,1,1,1,1,1,1,1,1,1,1,1,1,1,1,1,1,1
:endlayer
layer: 4
2,2,2,2,2,2,2,2,2,2,2,2,2,2,2,2,2,2,2,2,2,2,2,2,2,2,2
2,2,2,2,2,2,2,2,2,2,2,1,1,1,1,1,1,2,2,2,2,2,2,2,2,2,2
2,2,2,2,2,2,2,2,2,2,1,1,1,1,1,1,1,2,2,1,1,2,2,2,2,2,2
2,2,1,1,2,2,2,2,2,1,1,1,3,3,3,1,1,1,2,1,1,2,1,1,2,2,2
2,2,1,1,2,2,2,2,1,1,1,1,3,3,3,1,1,1,1,2,2,2,1,1,2,2,2
2,2,2,2,2,2,2,2,1,1,1,3,3,3,3,4,1,1,1,1,2,2,2,2,2,2,2
2,2,2,2,2,2,2,2,1,1,1,3,3,3,3,4,1,1,1,2,2,2,2,2,2,2,2
2,2,2,2,2,1,1,2,1,1,1,3,3,3,3,3,1,1,1,2,1,1,2,2,2,2,2
2,2,2,2,2,1,1,2,2,1,1,1,1,3,1,1,1,1,2,2,1,1,2,2,2,2,2
2,2,2,2,2,2,2,2,2,2,1,1,1,3,1,1,1,2,2,2,2,2,2,2,1,1,2
2,1,1,2,2,2,2,2,2,2,1,1,1,3,1,1,1,2,2,2,2,2,2,2,1,1,2
2,1,1,2,5,5,2,2,2,2,2,2,2,20,2,2,2,2,2,2,2,5,5,2,2,2,2
2,2,2,5,0,0,5,5,5,2,2,2,2,19,2,2,2,2,5,5,5,0,0,5,2,2,2
2,2,5,0,0,0,0,0,5,2,2,2,19,20,18,2,2,2,5,0,0,0,0,0,5,2,2
2,2,5,0,0,10,0,0,0,0,0,20,20,19,20,20,0,0,0,0,0,10,0,0,5,2,2
2,2,5,0,0,0,0,0,5,2,20,19,2,2,2,20,19,2,5,0,0,0,0,0,5,2,2
2,2,2,5,0,0,5,5,5,2,19,2,1,1,1,2,18,2,5,5,5,0,0,5,2,2,2
2,2,2,2,5,5,2,2,2,2,20,2,1,1,1,2,18,2,2,2,2,5,5,2,2,2,2
2,2,2,2,2,2,2,2,2,2,19,2,1,1,1,2,20,2,2,2,2,2,2,2,2,2,2
2,2,1,1,2,2,2,1,1,2,20,20,2,2,2,19,20,18,1,1,2,2,2,1,1,2,2
2,2,1,1,2,2,2,1,1,2,18,18,18,2,20,18,18,2,1,1,2,2,2,1,1,2,2
2,2,2,2,2,2,2,2,2,2,2,2,2,2,2,2,2,2,2,2,2,2,2,2,2,2,2
:endlayer
layer: 5
0,0,0,0,21,21,21,0,0,0,0,0,0,0,0,0,0,0,0,0,0,21,21,21,21,0,21
0,21,21,21,21,21,21,0,0,0,0,2,2,2,2,2,2,0,0,0,0,0,0,0,21,21,0
0,0,0,21,21,0,0,0,0,0,2,2,20,20,20,2,2,0,0,22,22,0,0,21,21,21,0
0,0,22,22,21,21,21,0,0,2,2,20,29,0,25,20,2,2,0,22,22,0,22,22,0,0,0
0,0,22,22,21,21,0,21,2,2,20,19,0,0,0,20,20,2,2,21,0,0,22,22,0,0,0
0,0,21,0,21,21,0,0,2,2,20,31,0,10,26,0,20,2,2,2,21,21,21,21,0,0,0
0,21,0,0,21,0,0,0,2,2,20,7,30,0,27,0,20,2,2,0,0,21,0,21,21,21,0
21,21,0,0,0,22,22,21,2,2,20,32,0,0,0,0,20,2,2,0,22,22,21,21,0,21,0
21,0,0,0,21,22,22,0,0,2,2,20,20,0,20,20,2,2,0,0,22,22,0,0,21,21,0
21,21,0,0,0,0,0,0,0,0,2,2,2,0,2,2,2,0,0,0,0,0,0,0,22,22,0
0,22,22,0,0,0,0,0,0,0,2,2,2,0,2,2,2,0,0,0,0,0,0,0,22,22,21
21,22,22,10,10,10,10,21,21,21,0,0,0,0,0,0,0,0,21,21,10,10,10,10,21,0,0
0,0,10,10,0,0,10,10,10,21,0,0,0,0,0,0,0,21,10,10,10,0,0,10,10,0,21
0,0,10,0,0,0,0,0,5,10,0,0,0,0,0,0,0,10,5,0,0,0,0,0,10,0,21
0,0,10,0,0,10,0,0,0,0,0,0,0,28,0,0,0,0,0,0,0,10,0,0,10,0,21
21,21,10,0,0,0,0,0,5,10,0,23,24,24,24,23,0,10,5,0,0,0,0,0,10,21,0
21,21,10,10,0,0,10,10,10,21,0,24,20,20,20,24,0,21,10,10,10,0,0,10,10,0,0
21,21,21,10,10,10,10,0,21,21,0,24,20,20,19,24,0,21,21,21,10,10,10,10,21,0,21
21,0,0,0,0,0,21,21,21,21,0,24,20,20,20,24,0,0,0,21,21,0,21,21,0,0,21
0,0,22,22,0,0,21,22,22,0,0,23,24,24,24,23,0,0,22,22,21,21,21,22,22,0,21
0,0,22,22,21,21,21,22,22,0,0,0,0,0,0,0,0,0,22,22,21,21,21,22,22,0,21
0,0,0,21,0,0,21,21,21,0,0,0,0,0,0,0,0,0,0,21,21,21,21,21,0,21,0
:endlayer
layer: 6
0,0,0,0,0,0,0,0,0,0,0,0,0,0,0,0,0,0,0,0,0,0,0,0,0,0,0
0,0,0,0,0,0,0,0,0,0,0,0,0,0,0,0,0,0,0,0,0,0,0,0,0,0,0
0,0,0,0,0,0,0,0,0,0,21,21,20,20,20,21,21,0,0,22,22,22,0,0,0,0,0
0,0,22,22,0,0,0,0,0,21,0,20,0,0,0,19,21,0,0,22,22,0,22,22,0,0,0
0,0,22,22,0,0,0,0,21,0,20,19,0,0,0,20,20,21,21,22,0,0,22,22,0,0,0
0,0,0,0,0,0,0,0,0,21,20,0,0,10,0,0,20,21,21,21,0,0,0,0,0,0,0
0,0,0,0,0,0,0,0,21,21,20,0,0,0,0,0,19,21,21,0,0,0,0,0,0,0,0
0,0,0,0,0,22,22,0,21,21,20,0,0,0,0,0,20,0,0,22,22,22,0,0,0,0,0
0,0,0,0,0,22,22,0,0,21,42,20,20,0,19,20,40,0,0,0,22,22,0,0,0,0,0
0,0,0,0,0,0,0,0,0,0,21,21,21,0,0,21,21,0,0,22,0,0,0,0,22,22,0
0,22,22,0,0,0,0,0,0,0,0,0,0,0,0,0,0,0,0,0,0,0,0,0,22,22,0
0,22,22,33,5,5,33,0,0,0,0,0,0,0,0,0,0,0,0,0,33,5,5,33,0,0,0
0,0,5,5,0,0,5,5,5,0,0,0,0,0,0,0,0,0,5,5,5,0,35,5,5,0,0
0,0,5,0,0,0,0,0,5,43,0,0,0,0,0,0,0,38,5,36,0,0,0,0,5,0,0
0,0,5,0,0,10,0,0,45,0,0,0,0,0,0,0,0,0,37,0,0,10,0,0,5,0,0
0,0,5,0,0,0,0,0,5,44,0,41,0,0,0,41,0,39,5,36,0,0,0,0,5,0,0
0,0,5,5,0,0,5,5,5,0,0,0,23,0,23,0,0,0,5,5,5,0,35,5,5,0,0
0,0,0,34,5,5,34,0,0,0,0,0,0,19,0,0,0,0,0,0,34,5,5,34,0,0,0
0,0,0,0,0,0,0,0,0,0,0,0,23,0,23,0,0,0,0,0,0,0,0,0,0,0,0
0,0,22,22,0,0,0,22,22,0,0,41,0,0,0,41,0,0,22,22,0,0,0,22,22,0,0
0,0,22,22,0,0,0,22,22,0,0,0,0,0,0,0,0,0,22,22,0,0,0,22,22,0,0
0,0,0,0,0,0,0,0,0,0,0,0,0,0,0,0,0,0,0,0,0,0,0,0,0,0,0
:endlayer
layer: 7
0,0,0,0,0,0,0,0,0,0,0,0,0,0,0,0,0,0,0,0,0,0,0,0,0,0,0
0,0,0,0,0,0,0,0,0,0,0,0,0,0,0,0,0,0,0,22,22,0,0,0,0,0,0
0,0,0,0,22,0,0,0,0,0,0,47,20,10,19,47,0,0,0,22,22,22,0,22,0,0,0
0,0,22,22,0,0,0,0,0,0,47,19,49,0,49,20,47,0,22,22,22,0,22,22,0,0,0
0,0,22,22,0,0,0,0,0,0,20,57,0,0,0,48,20,0,0,22,0,0,22,22,22,0,0
0,0,0,0,0,0,0,0,0,0,10,0,0,10,0,0,10,0,0,0,0,0,22,22,0,0,0
0,0,0,0,0,0,0,0,0,0,10,0,0,0,0,0,10,0,0,0,22,0,0,0,0,0,0
0,0,0,0,0,22,22,0,0,0,19,0,0,0,0,0,20,0,0,22,22,22,0,0,0,0,0
0,0,0,0,0,22,22,0,0,0,47,19,20,52,20,19,47,0,0,0,22,22,0,0,0,0,0
0,0,0,0,0,0,0,0,0,0,0,0,0,53,0,0,0,0,0,22,0,0,0,0,22,22,0
0,22,22,0,0,0,0,0,0,0,0,0,0,0,0,0,0,0,0,0,0,0,0,0,22,22,0
0,22,22,10,4,4,10,0,0,0,0,0,0,0,0,0,0,0,0,0,10,4,4,10,0,0,0
0,0,10,4,4,4,4,4,10,0,0,0,0,0,0,0,0,0,10,4,4,4,4,4,10,0,0
0,0,4,4,46,46,4,4,4,0,0,0,0,0,0,0,0,0,4,4,4,46,46,4,4,0,0
0,0,4,46,46,5,46,4,10,0,0,0,0,0,0,0,0,0,10,4,46,5,46,46,4,0,0
0,0,4,4,46,46,4,4,4,0,0,0,0,0,0,0,0,0,4,4,4,46,46,4,4,0,0
0,0,10,4,4,4,4,4,10,0,0,0,55,0,50,0,0,0,10,4,4,4,4,4,10,0,0
0,0,0,10,4,4,10,0,0,0,0,0,0,54,0,0,0,0,0,0,10,4,4,10,0,0,0
0,0,0,0,0,0,0,0,0,0,0,0,56,0,51,0,0,0,0,0,22,0,0,0,0,0,0
0,0,22,22,0,0,0,22,22,0,0,0,0,0,0,0,0,0,22,22,22,0,0,22,22,0,0
0,0,22,22,0,0,0,22,22,0,0,0,0,0,0,0,0,0,22,22,0,0,0,22,22,0,0
0,0,0,0,0,0,0,0,0,0,0,0,0,0,0,0,0,0,0,0,0,0,0,0,0,0,0
:endlayer
layer: 8
0,0,0,0,0,0,0,0,0,0,0,0,0,0,0,0,0,0,0,0,0,0,0,0,0,0,0
0,0,0,0,0,0,0,0,0,0,0,0,0,0,0,0,0,0,0,22,22,22,0,0,0,0,0
0,0,0,0,22,0,0,0,0,0,0,0,4,33,4,0,0,0,22,22,0,22,22,22,0,0,0
0,0,22,22,0,0,0,0,0,0,0,19,47,47,47,20,0,0,22,22,0,0,22,22,0,0,0
0,0,22,22,0,0,0,0,0,0,4,47,0,0,0,47,4,0,0,22,22,0,22,22,22,0,0
0,0,0,0,22,0,0,0,0,0,37,47,0,10,0,47,45,0,0,0,0,0,22,22,0,0,0
0,0,0,0,0,0,0,0,0,0,37,47,0,0,0,47,45,0,0,0,22,22,22,0,0,0,0
0,0,0,0,0,22,22,0,0,0,20,47,47,47,47,47,19,0,0,22,22,22,0,0,0,0,0
0,0,0,0,0,22,22,0,0,0,0,4,4,67,4,4,0,0,0,0,0,0,0,0,0,0,0
0,0,0,0,22,0,0,0,0,0,0,0,0,0,0,0,0,0,0,22,0,0,0,0,22,22,0
0,22,22,0,0,0,0,0,0,0,0,0,0,0,0,0,0,0,0,0,0,0,0,0,22,22,0
0,22,22,74,0,0,71,0,0,0,0,0,0,0,0,0,0,0,0,0,63,0,0,60,0,0,0
0,0,76,0,0,0,0,0,69,0,0,0,0,0,0,0,0,0,65,0,0,0,0,0,58,0,0
0,0,0,0,0,0,0,0,0,0,0,0,0,0,0,0,0,0,0,0,0,0,0,0,0,0,0
0,0,0,0,0,5,0,0,10,0,0,0,0,0,0,0,0,0,10,0,0,5,62,0,0,0,0
0,0,0,0,0,73,0,0,0,0,0,0,0,0,0,0,0,0,0,0,0,0,0,0,0,0,0
0,0,77,0,0,0,0,0,70,0,0,0,0,0,0,0,0,0,66,0,0,0,0,0,59,0,0
0,0,0,75,0,0,72,0,0,0,0,0,0,68,0,0,0,0,0,0,64,0,0,61,0,0,0
0,0,0,0,0,0,0,22,0,0,0,0,0,0,0,0,0,22,0,0,22,0,0,0,0,22,0
0,0,22,22,0,0,22,22,22,0,0,0,0,0,0,0,0,0,22,22,22,0,0,22,22,0,0
0,0,22,22,0,0,0,22,22,0,0,0,0,0,0,0,0,0,22,22,0,0,0,22,22,0,0
0,0,0,0,0,0,22,0,0,0,0,0,0,0,0,0,0,0,0,22,0,0,0,0,0,0,0
:endlayer
layer: 9
0,0,0,0,0,0,0,0,0,0,0,0,0,0,0,0,78,78,78,78,78,78,78,78,0,0,0
0,0,0,0,0,0,0,0,0,0,0,0,0,0,0,0,78,78,78,22,22,22,78,78,78,0,0
0,0,0,0,22,0,0,0,0,0,0,0,0,0,0,78,78,78,22,22,78,22,22,22,78,0,0
0,0,22,22,0,0,0,0,0,0,0,10,85,0,0,10,78,78,22,22,78,78,22,22,78,78,0
0,0,22,22,22,0,0,0,0,0,0,0,4,81,4,78,78,78,78,22,22,78,22,22,22,78,0
0,0,0,0,22,0,0,0,0,0,0,0,86,20,80,0,78,78,78,78,22,22,22,22,78,78,0
0,0,0,0,0,0,0,0,0,0,0,0,4,82,4,0,0,78,78,78,22,22,22,78,78,0,0
0,0,0,0,0,22,22,0,0,0,10,0,0,0,0,0,10,78,78,22,78,78,78,78,0,0,0
0,0,0,0,0,22,22,0,0,0,0,0,0,83,0,0,0,78,78,78,78,78,78,22,0,0,0
0,0,0,0,22,0,0,22,0,0,0,0,0,0,0,0,0,0,78,22,78,0,0,0,22,22,0
0,22,22,0,0,0,0,0,0,0,0,0,0,0,0,0,0,0,0,0,0,0,0,0,22,22,0
0,22,22,0,0,0,0,0,0,0,0,0,0,0,0,0,0,0,0,0,0,0,0,0,0,0,0
0,0,0,0,0,0,0,0,0,0,0,0,0,0,0,0,0,0,0,0,0,0,0,0,0,0,0
0,0,0,0,0,0,0,0,0,0,0,0,0,0,0,0,0,0,0,0,0,0,0,0,0,0,0
0,0,0,0,0,10,0,0,87,0,0,0,0,0,0,0,0,0,79,0,0,10,0,0,0,0,0
0,0,0,0,0,0,0,0,0,0,0,0,0,0,0,0,0,0,0,0,0,0,0,0,0,0,0
0,0,0,0,0,0,0,0,0,0,0,0,0,0,0,0,78,78,78,78,78,78,0,0,0,0,0
0,0,0,0,0,0,0,0,0,0,0,0,0,84,0,78,78,78,78,78,78,78,78,0,0,0,0
0,22,0,0,0,0,22,22,0,0,0,0,0,0,0,78,78,22,78,78,22,78,78,0,0,22,0
0,0,22,22,0,0,22,22,22,0,0,0,0,0,0,78,78,78,22,22,22,78,78,22,22,0,0
0,0,22,22,0,0,0,22,22,22,0,0,0,0,0,0,78,78,22,22,78,78,22,22,22,0,0
0,22,0,0,0,0,22,0,0,0,0,0,0,0,0,0,78,78,78,22,78,78,0,0,0,22,0
:endlayer
layer: 10
0,0,0,78,78,78,0,0,0,0,0,0,0,0,0,78,78,78,78,78,78,78,78,78,0,0,0
78,78,78,78,78,78,78,0,0,0,0,0,0,0,0,78,78,78,78,78,78,78,78,78,78,78,0
78,78,78,78,22,78,78,0,0,0,0,0,0,0,0,78,78,78,22,22,78,78,78,78,78,78,0
78,78,22,22,78,78,78,0,0,0,0,92,0,0,0,91,78,78,22,22,78,22,22,78,78,78,0
78,78,22,22,22,78,78,0,0,0,0,0,0,0,0,78,78,78,78,78,78,22,22,78,78,78,0
78,78,78,78,22,78,78,0,0,0,0,0,0,10,0,0,78,78,78,78,22,22,78,78,78,78,0
78,78,78,78,78,78,22,0,0,0,0,0,0,0,0,0,78,78,78,78,22,22,78,78,78,0,0
0,0,0,78,78,22,22,0,0,0,93,0,0,0,0,0,90,78,78,78,78,78,78,78,78,0,0
0,0,0,0,0,22,22,0,0,0,0,0,0,0,0,0,0,89,78,78,78,78,78,22,0,0,0
0,0,0,0,22,0,0,22,0,0,0,0,0,0,0,0,0,0,78,78,78,78,78,0,22,22,0
0,22,22,0,0,0,0,0,0,0,0,0,0,0,0,0,0,0,0,0,0,0,0,0,22,22,0
0,22,22,0,0,0,0,0,0,0,0,0,0,0,0,0,0,0,0,0,0,0,0,0,0,0,0
0,0,0,0,0,0,0,0,0,0,0,0,0,0,0,0,0,0,0,0,0,0,0,0,0,0,0
0,0,0,0,0,0,0,0,0,0,0,0,0,0,0,0,0,0,0,0,0,0,0,0,0,0,0
0,0,0,0,0,94,0,0,0,0,0,0,0,0,0,0,0,0,0,0,0,88,0,0,0,0,0
0,0,0,0,0,0,0,0,0,0,0,0,0,0,0,0,0,0,0,0,0,0,0,0,0,0,0
0,0,0,0,0,0,0,0,0,0,0,0,0,0,0,0,78,78,78,78,78,0,0,0,0,0,0
0,0,0,0,0,0,0,0,0,0,0,0,0,0,0,78,78,78,78,78,78,78,78,0,0,0,0
0,22,0,0,0,0,22,22,0,0,0,0,0,0,0,78,78,78,78,78,78,78,22,0,22,22,0
0,0,22,22,0,0,22,22,22,0,0,0,0,0,0,78,78,78,22,22,78,78,78,22,22,0,0
0,0,22,22,22,0,0,22,22,22,0,0,0,0,0,78,78,78,22,22,78,78,22,22,22,0,0
0,22,0,0,0,0,22,0,0,0,0,0,0,0,0,78,78,78,78,78,78,78,78,0,0,22,0
:endlayer
layer: 11
78,78,78,78,78,0,0,0,0,0,0,0,0,0,0,0,0,0,78,78,0,0,0,0,0,0,0
78,78,78,78,78,78,78,0,0,0,0,0,0,0,0,0,0,78,78,78,78,78,78,0,95,0,0
78,78,78,78,78,78,78,0,0,0,0,0,0,0,0,0,78,78,78,78,78,78,78,78,0,0,0
78,78,22,22,78,78,78,0,0,0,0,0,0,0,0,0,78,78,78,78,78,78,78,78,78,0,0
78,78,22,22,78,78,78,78,78,0,0,0,0,0,0,0,0,78,78,78,78,78,78,78,78,0,0
78,78,78,78,78,78,78,78,78,78,0,0,0,10,0,0,0,0,78,78,78,78,78,78,0,0,0
78,78,78,78,78,78,22,78,78,78,0,0,0,0,0,0,0,0,78,78,78,78,78,78,0,0,0
78,78,78,78,78,22,22,78,78,78,0,0,0,0,0,0,0,0,0,78,78,78,78,0,0,0,0
0,0,0,78,78,22,22,78,78,78,78,0,0,0,0,0,0,0,0,0,78,78,0,22,0,0,0
0,0,0,78,22,78,78,22,78,78,78,0,0,0,0,0,0,0,0,0,0,0,0,22,22,22,22
0,22,22,78,78,78,78,78,78,78,78,0,0,0,0,0,0,0,0,0,0,0,0,0,22,22,22
0,22,22,0,78,78,78,78,78,78,0,0,0,0,0,0,0,0,0,0,0,0,0,0,22,22,0
0,0,0,0,0,0,0,0,0,0,0,0,0,0,0,0,0,0,0,0,0,0,0,0,0,0,0
0,0,0,0,0,0,0,0,0,0,0,0,0,0,0,0,0,0,0,0,0,0,0,0,0,0,0
0,0,0,0,0,0,0,0,0,0,0,0,0,0,0,0,0,0,0,0,0,0,0,0,0,0,0
0,0,0,0,0,0,0,0,0,0,0,0,0,0,0,0,0,0,0,0,0,0,0,0,0,0,0
0,0,0,0,0,78,78,78,78,0,0,0,0,0,0,0,0,0,0,0,0,78,78,78,78,78,78
0,0,0,0,78,78,78,78,78,78,78,0,0,0,0,0,0,0,78,78,78,78,78,78,78,78,78
0,22,0,0,78,78,22,22,78,78,78,0,0,0,0,0,0,78,78,78,78,78,22,78,22,22,78
0,22,22,0,78,78,22,22,22,78,78,78,0,0,0,0,78,78,78,78,78,78,78,22,22,78,78
0,22,22,0,22,78,78,22,22,22,78,78,0,0,0,0,78,78,78,78,78,78,22,22,22,78,78
0,22,0,0,22,78,22,78,78,78,78,78,0,0,0,0,0,78,78,78,78,78,78,78,78,22,78
:endlayer
layer: 12
0,0,0,0,0,0,0,0,0,0,0,0,0,0,0,0,0,0,0,0,0,0,0,0,0,0,0
97,0,78,78,0,0,0,0,0,0,0,0,0,0,0,0,0,0,0,0,0,0,0,0,0,0,0
0,78,78,78,78,0,0,0,0,0,0,0,0,0,0,0,0,0,0,0,0,0,0,0,0,0,0
78,78,78,78,78,78,0,0,0,0,0,0,0,0,0,0,0,0,0,0,0,0,0,0,0,0,0
78,78,78,78,78,78,78,78,78,0,0,0,0,0,0,0,0,0,0,0,0,0,0,0,0,0,0
0,78,78,78,78,78,78,78,78,78,78,0,0,96,0,0,0,0,0,0,78,78,78,78,78,0,0
0,0,78,78,78,78,78,78,78,78,78,0,0,0,0,0,0,0,0,0,78,78,78,78,78,78,78
0,0,0,78,78,78,22,22,78,78,78,0,0,0,0,0,0,0,0,0,0,78,78,78,78,78,78
0,0,0,78,78,78,22,22,78,78,78,0,0,0,0,0,0,0,0,0,0,78,78,22,78,78,78
0,22,0,78,78,78,78,78,78,78,78,0,0,0,0,0,0,0,0,0,0,78,78,22,22,22,22
0,22,22,0,78,78,78,78,78,78,0,0,0,0,0,0,0,0,0,0,0,0,78,78,22,22,22
0,22,22,0,78,78,78,78,78,0,0,0,0,0,0,0,0,0,0,0,0,0,78,78,22,22,78
0,22,0,0,0,0,0,0,0,0,0,0,0,0,0,0,0,0,0,0,0,0,0,78,78,78,78
0,0,0,0,0,0,0,0,0,0,0,0,0,0,0,0,0,0,0,0,0,0,0,0,0,0,0
0,0,0,0,0,0,0,0,0,0,0,0,0,0,0,0,0,0,0,0,0,0,0,0,0,0,0
0,0,0,0,0,0,0,0,0,0,0,0,0,0,0,0,0,0,0,0,0,0,0,0,0,0,0
78,0,0,0,0,78,78,78,78,78,0,0,0,0,0,0,0,0,0,0,0,78,78,78,78,78,0
78,78,78,78,78,78,78,78,78,78,78,78,0,0,0,0,0,0,0,0,78,78,78,78,78,78,78
78,22,78,78,78,78,78,78,78,78,78,78,0,0,0,0,0,0,0,0,78,78,78,78,78,78,78
22,22,78,78,78,78,78,22,22,78,78,78,0,0,0,0,0,0,78,78,78,78,78,22,22,78,78
22,22,78,78,22,78,78,22,22,78,78,78,0,0,0,0,0,0,78,78,78,78,78,22,22,78,78
78,22,78,78,22,78,78,78,78,78,78,78,0,0,0,0,0,0,0,0,78,78,78,78,78,78,78
:endlayer
layer: 13
0,0,0,0,0,0,0,0,0,0,0,0,0,0,0,0,0,0,0,0,0,0,0,0,0,0,0
0,0,0,0,0,0,0,0,0,0,0,0,0,0,0,0,0,0,0,0,0,0,0,0,0,0,0
0,0,0,0,0,0,0,0,0,0,0,0,0,0,0,0,0,0,0,0,0,0,0,0,0,0,0
0,0,78,78,0,0,0,0,0,0,0,0,0,0,0,0,0,0,0,0,0,0,0,0,0,0,0
0,0,78,78,0,0,0,0,0,0,0,0,0,0,0,0,0,0,0,0,0,0,0,0,0,0,0
0,0,0,0,0,0,78,78,0,0,0,0,0,0,0,0,0,0,0,0,0,0,78,78,78,78,78
0,0,0,0,0,78,78,78,78,0,0,0,0,0,0,0,0,0,0,0,0,78,78,78,78,78,78
0,0,0,0,78,78,78,78,78,78,0,0,0,0,0,0,0,0,0,0,0,78,78,78,78,78,78
0,0,0,0,78,78,78,78,78,78,0,0,0,0,0,0,0,0,0,0,0,78,78,78,22,22,78
22,22,0,0,0,78,78,78,78,0,0,0,0,0,0,0,0,0,0,0,0,78,78,78,22,22,78
0,22,22,0,0,0,78,78,0,0,0,0,0,0,0,0,0,0,0,0,0,78,78,78,78,78,78
0,22,22,0,0,0,0,0,0,0,0,0,0,0,0,0,0,0,0,0,0,0,78,78,78,78,78
0,22,0,0,0,0,0,0,0,0,0,0,0,0,0,0,0,0,0,0,0,0,78,78,78,78,78
0,0,0,0,0,0,0,0,0,0,0,0,0,0,0,0,0,0,0,0,0,0,0,0,0,0,0
0,0,0,0,0,0,0,0,0,0,0,0,0,0,0,0,0,0,0,0,0,0,0,0,0,0,0
0,0,0,0,0,0,0,0,0,0,0,0,0,0,0,0,0,0,0,0,0,0,0,0,0,0,0
78,78,78,0,0,0,0,0,0,0,0,0,0,0,0,0,0,0,0,0,0,0,0,0,0,0,0
78,78,78,78,78,0,0,78,78,0,0,0,0,0,0,0,0,0,0,0,0,0,0,78,78,0,0
78,78,78,78,78,0,78,78,78,78,0,0,0,0,0,0,0,0,0,0,0,0,78,78,78,78,0
22,22,78,78,78,78,78,78,78,78,78,0,0,0,0,0,0,0,0,0,0,78,78,78,78,78,78
22,22,78,78,78,78,78,78,78,78,78,0,0,0,0,0,0,0,0,0,0,78,78,78,78,78,78
78,78,78,78,78,0,78,78,78,78,0,0,0,0,0,0,0,0,0,0,0,0,78,78,78,78,98
:endlayer
layer: 14
0,0,0,0,0,0,0,0,0,0,0,0,0,0,0,0,0,0,0,0,0,0,0,0,0,0,0
0,0,0,0,0,0,0,0,0,0,0,0,0,0,0,0,0,0,0,0,0,0,0,0,0,0,0
0,0,0,0,0,0,0,0,0,0,0,0,0,0,0,0,0,0,0,0,0,0,0,0,0,0,0
0,0,0,0,0,0,0,0,0,0,0,0,0,0,0,0,0,0,0,0,0,0,0,0,0,0,0
0,0,0,0,0,0,0,0,0,0,0,0,0,0,0,0,0,0,0,0,0,0,0,0,0,0,0
0,0,0,0,0,0,0,0,0,0,0,0,0,0,0,0,0,0,0,0,0,0,0,0,0,0,0
0,0,0,0,0,0,0,0,0,0,0,0,0,0,0,0,0,0,0,0,0,0,0,0,78,78,0
78,78,78,0,0,0,0,0,0,0,0,0,0,0,0,0,0,0,0,0,0,0,0,78,78,78,78
78,78,78,78,78,0,0,0,0,0,0,0,0,0,0,0,0,0,0,0,0,0,78,78,78,78,78
22,22,78,78,78,0,0,0,0,0,0,0,0,0,0,0,0,0,0,0,0,0,78,78,78,78,78
78,22,22,78,78,0,0,0,0,0,0,0,0,0,0,0,0,0,0,0,0,0,0,78,78,78,78
78,22,22,78,78,0,0,0,0,0,0,0,0,0,0,0,0,0,0,0,0,0,0,0,78,78,0
78,22,78,78,78,0,0,0,0,0,0,0,0,0,0,0,0,0,0,0,0,0,0,0,0,0,0
78,78,78,78,78,0,0,0,0,0,0,0,0,0,0,0,0,0,0,0,0,0,0,0,0,0,0
78,78,78,0,0,0,0,0,0,0,0,0,0,0,0,0,0,0,0,0,0,0,0,0,0,0,0
0,0,0,0,0,0,0,0,0,0,0,0,0,0,0,0,0,0,0,0,0,0,0,0,0,0,0
0,0,0,0,0,0,0,0,0,0,0,0,0,0,0,0,0,0,0,0,0,0,0,0,0,0,0
78,78,0,0,0,0,0,0,0,0,0,0,0,0,0,0,0,0,0,0,0,0,0,0,0,0,0
78,78,78,0,0,0,0,0,0,0,0,0,0,0,0,0,0,0,0,0,0,0,0,0,0,0,0
78,78,78,78,0,0,0,78,78,0,0,0,0,0,0,0,0,0,0,0,0,0,0,0,0,0,0
78,78,78,78,0,0,0,78,78,0,0,0,0,0,0,0,0,0,0,0,0,0,0,0,0,0,0
78,78,78,0,0,0,0,0,0,0,0,0,0,0,0,0,0,0,0,0,0,0,0,0,0,0,0
:endlayer
layer: 15
0,0,0,0,0,0,0,0,0,0,0,0,0,0,0,0,0,0,0,0,0,0,0,0,0,0,0
0,0,0,0,0,0,0,0,0,0,0,0,0,0,0,0,0,0,0,0,0,0,0,0,0,0,0
0,0,0,0,0,0,0,0,0,0,0,0,0,0,0,0,0,0,0,0,0,0,0,0,0,0,0
0,0,0,0,0,0,0,0,0,0,0,0,0,0,0,0,0,0,0,0,0,0,0,0,0,0,0
0,0,0,0,0,0,0,0,0,0,0,0,0,0,0,0,0,0,0,0,0,0,0,0,0,0,0
0,0,0,0,0,0,0,0,0,0,0,0,0,0,0,0,0,0,0,0,0,0,0,0,0,0,0
0,0,0,0,0,0,0,0,0,0,0,0,0,0,0,0,0,0,0,0,0,0,0,0,0,0,0
78,78,78,78,0,0,0,0,0,0,0,0,0,0,0,0,0,0,0,0,0,0,0,0,0,0,0
78,78,78,78,78,78,0,0,0,0,0,0,0,0,0,0,0,0,0,0,0,0,0,0,78,78,0
78,78,78,78,78,78,0,0,0,0,0,0,0,0,0,0,0,0,0,0,0,0,0,0,78,78,0
78,22,22,78,78,78,0,0,0,0,0,0,0,0,0,0,0,0,0,0,0,0,0,0,0,0,0
78,22,22,78,78,78,0,0,0,0,0,0,0,0,0,0,0,0,0,0,0,0,0,0,0,0,0
78,78,78,78,78,78,0,0,0,0,0,0,0,0,0,0,0,0,0,0,0,0,0,0,0,0,0
78,78,78,78,0,0,0,0,0,0,0,0,0,0,0,0,0,0,0,0,0,0,0,0,0,0,0
78,78,78,78,0,0,0,0,0,0,0,0,0,0,0,0,0,0,0,0,0,0,0,0,0,0,0
0,0,0,0,0,0,0,0,0,0,0,0,0,0,0,0,0,0,0,0,0,0,0,0,0,0,0
0,0,0,0,0,0,0,0,0,0,0,0,0,0,0,0,0,0,0,0,0,0,0,0,0,0,0
0,0,0,0,0,0,0,0,0,0,0,0,0,0,0,0,0,0,0,0,0,0,0,0,0,0,0
0,0,0,0,0,0,0,0,0,0,0,0,0,0,0,0,0,0,0,0,0,0,0,0,0,0,0
78,78,0,0,0,0,0,0,0,0,0,0,0,0,0,0,0,0,0,0,0,0,0,0,0,0,0
78,78,0,0,0,0,0,0,0,0,0,0,0,0,0,0,0,0,0,0,0,0,0,0,0,0,0
99,0,0,0,0,0,0,0,0,0,0,0,0,0,0,0,0,0,0,0,0,0,0,0,0,0,0
:endlayer
layer: 16
0,0,0,0,0,0,0,0,0,0,0,0,0,0,0,0,0,0,0,0,0,0,0,0,0,0,0
0,0,0,0,0,0,0,0,0,0,0,0,0,0,0,0,0,0,0,0,0,0,0,0,0,0,0
0,0,0,0,0,0,0,0,0,0,0,0,0,0,0,0,0,0,0,0,0,0,0,0,0,0,0
0,0,0,0,0,0,0,0,0,0,0,0,0,0,0,0,0,0,0,0,0,0,0,0,0,0,0
0,0,0,0,0,0,0,0,0,0,0,0,0,0,0,0,0,0,0,0,0,0,0,0,0,0,0
0,0,0,0,0,0,0,0,0,0,0,0,0,0,0,0,0,0,0,0,0,0,0,0,0,0,0
0,0,0,0,0,0,0,0,0,0,0,0,0,0,0,0,0,0,0,0,0,0,0,0,0,0,0
0,0,0,0,0,0,0,0,0,0,0,0,0,0,0,0,0,0,0,0,0,0,0,0,0,0,0
0,78,78,0,0,0,0,0,0,0,0,0,0,0,0,0,0,0,0,0,0,0,0,0,0,0,0
78,78,78,78,0,0,0,0,0,0,0,0,0,0,0,0,0,0,0,0,0,0,0,0,0,0,0
78,78,78,78,78,0,0,0,0,0,0,0,0,0,0,0,0,0,0,0,0,0,0,0,0,0,0
78,78,78,78,78,0,0,0,0,0,0,0,0,0,0,0,0,0,0,0,0,0,0,0,0,0,0
78,78,78,78,0,0,0,0,0,0,0,0,0,0,0,0,0,0,0,0,0,0,0,0,0,0,0
0,78,78,0,0,0,0,0,0,0,0,0,0,0,0,0,0,0,0,0,0,0,0,0,0,0,0
0,0,0,0,0,0,0,0,0,0,0,0,0,0,0,0,0,0,0,0,0,0,0,0,0,0,0
0,0,0,0,0,0,0,0,0,0,0,0,0,0,0,0,0,0,0,0,0,0,0,0,0,0,0
0,0,0,0,0,0,0,0,0,0,0,0,0,0,0,0,0,0,0,0,0,0,0,0,0,0,0
0,0,0,0,0,0,0,0,0,0,0,0,0,0,0,0,0,0,0,0,0,0,0,0,0,0,0
0,0,0,0,0,0,0,0,0,0,0,0,0,0,0,0,0,0,0,0,0,0,0,0,0,0,0
0,0,0,0,0,0,0,0,0,0,0,0,0,0,0,0,0,0,0,0,0,0,0,0,0,0,0
0,0,0,0,0,0,0,0,0,0,0,0,0,0,0,0,0,0,0,0,0,0,0,0,0,0,0
0,0,0,0,0,0,0,0,0,0,0,0,0,0,0,0,0,0,0,0,0,0,0,0,0,0,0
:endlayer

#### RULES ####
rule:
plugin=vanillaBlocks
number=1
data:
JSON:{blockState:{blockName:"minecraft:dirt",properties:{variant:"dirt",snowy:"false"}}}
:enddata
:endrule

rule:
plugin=vanillaBlocks
number=2
data:
JSON:{blockState:{blockName:"minecraft:grass",properties:{snowy:"false"}}}
:enddata
:endrule

rule:
plugin=vanillaBlocks
number=3
data:
JSON:{blockState:{blockName:"minecraft:stained_hardened_clay",properties:{color:"brown"}}}
:enddata
:endrule

rule:
plugin=vanillaBlocks
number=4
data:
JSON:{blockState:{blockName:"minecraft:wooden_slab",properties:{half:"bottom",variant:"dark_oak"}}}
:enddata
:endrule

rule:
plugin=vanillaBlocks
number=5
data:
JSON:{blockState:{blockName:"minecraft:planks",properties:{variant:"dark_oak"}}}
:enddata
:endrule

rule:
plugin=inventory
number=6
data:
JSON:{blockState:{blockName:"minecraft:chest",properties:{facing:"west"}},lootLevel:0,teData:{ForgeData:{},Items:[{Slot:1b,id:"minecraft:slime_ball",Count:2b,Damage:0s},{Slot:4b,id:"minecraft:spider_eye",Count:6b,Damage:0s},{Slot:7b,id:"minecraft:brown_mushroom",Count:5b,Damage:0s},{Slot:11b,id:"minecraft:coal",Count:6b,Damage:0s},{Slot:12b,id:"minecraft:gold_nugget",Count:3b,Damage:0s},{Slot:14b,id:"minecraft:rotten_flesh",Count:16b,Damage:0s},{Slot:19b,id:"minecraft:dye",Count:12b,Damage:4s},{Slot:26b,id:"minecraft:red_mushroom",Count:2b,Damage:0s}],id:"minecraft:chest",Lock:""},inventoryData:{length:8,inventoryContents:[{id:"minecraft:slime_ball",Count:2b,slot:0,Damage:0s},{id:"minecraft:spider_eye",Count:6b,slot:1,Damage:0s},{id:"minecraft:brown_mushroom",Count:5b,slot:2,Damage:0s},{id:"minecraft:coal",Count:6b,slot:3,Damage:0s},{id:"minecraft:gold_nugget",Count:3b,slot:4,Damage:0s},{id:"minecraft:rotten_flesh",Count:16b,slot:5,Damage:0s},{id:"minecraft:dye",Count:12b,slot:6,Damage:4s},{id:"minecraft:red_mushroom",Count:2b,slot:7,Damage:0s}]},legacyFeatures:1b}
:enddata
:endrule

rule:
plugin=vanillaBlocks
number=7
data:
JSON:{blockState:{blockName:"minecraft:crafting_table"}}
:enddata
:endrule

rule:
plugin=inventory
number=8
data:
JSON:{blockState:{blockName:"minecraft:furnace",properties:{facing:"west"}},lootLevel:0,teData:{CookTime:0,BurnTime:0,Items:[],id:"minecraft:furnace",CookTimeTotal:0,Lock:""},inventoryData:{length:0,inventoryContents:[]},legacyFeatures:0b}
:enddata
:endrule

rule:
plugin=blockTile
number=9
data:
JSON:{blockState:{blockName:"ancientwarfarestructure:advanced_spawner",properties:{transparent:"true"}},teData:{id:"ancientwarfarestructure:advanced_spawner_tile",spawnerSettings:{minDelay:0,spawnDelay:0,lightSensitive:0b,spawnGroups:[{settingsList:[{remainingSpawnCount:1,hostile:1b,forced:1b,customTag:{factionName:"orc"},maxToSpawn:1,entityId:"ancientwarfarenpc:faction.archer",minToSpawn:1}],groupWeight:1}],playerRange:8,respondToRedstone:0b,inventory:{Size:9,Items:[]},spawnRange:0,transparent:1b,maxDelay:0,xpToDrop:0,mobRange:0,debugMode:0b,maxNearbyMonsters:0}}}
:enddata
:endrule

rule:
plugin=vanillaBlocks
number=10
data:
JSON:{blockState:{blockName:"minecraft:fence",properties:{east:"false",south:"false",north:"false",west:"false"}}}
:enddata
:endrule

rule:
plugin=blockTile
number=11
data:
JSON:{blockState:{blockName:"ancientwarfarestructure:advanced_spawner",properties:{transparent:"true"}},teData:{id:"ancientwarfarestructure:advanced_spawner_tile",spawnerSettings:{minDelay:0,spawnDelay:0,lightSensitive:0b,spawnGroups:[{settingsList:[{remainingSpawnCount:1,hostile:1b,forced:1b,customTag:{factionName:"orc"},maxToSpawn:1,entityId:"ancientwarfarenpc:faction.civilian.female",minToSpawn:1}],groupWeight:1}],playerRange:6,respondToRedstone:0b,inventory:{Size:9,Items:[]},spawnRange:0,transparent:1b,maxDelay:0,xpToDrop:0,mobRange:0,debugMode:0b,maxNearbyMonsters:0}}}
:enddata
:endrule

rule:
plugin=blockTile
number=12
data:
JSON:{blockState:{blockName:"ancientwarfarestructure:advanced_spawner",properties:{transparent:"true"}},teData:{id:"ancientwarfarestructure:advanced_spawner_tile",spawnerSettings:{minDelay:0,spawnDelay:0,lightSensitive:0b,spawnGroups:[{settingsList:[{remainingSpawnCount:1,hostile:1b,forced:1b,customTag:{factionName:"orc"},maxToSpawn:1,entityId:"ancientwarfarenpc:faction.soldier",minToSpawn:1}],groupWeight:1}],playerRange:6,respondToRedstone:0b,inventory:{Size:9,Items:[]},spawnRange:0,transparent:1b,maxDelay:0,xpToDrop:0,mobRange:0,debugMode:0b,maxNearbyMonsters:0}}}
:enddata
:endrule

rule:
plugin=blockTile
number=13
data:
JSON:{blockState:{blockName:"ancientwarfarestructure:advanced_spawner",properties:{transparent:"true"}},teData:{id:"ancientwarfarestructure:advanced_spawner_tile",spawnerSettings:{minDelay:0,spawnDelay:0,lightSensitive:0b,spawnGroups:[{settingsList:[{remainingSpawnCount:1,hostile:1b,forced:1b,customTag:{factionName:"orc"},maxToSpawn:1,entityId:"ancientwarfarenpc:faction.soldier",minToSpawn:1}],groupWeight:1}],playerRange:6,respondToRedstone:0b,inventory:{Size:9,Items:[]},spawnRange:0,transparent:1b,maxDelay:0,xpToDrop:0,mobRange:0,debugMode:0b,maxNearbyMonsters:0}}}
:enddata
:endrule

rule:
plugin=blockTile
number=14
data:
JSON:{blockState:{blockName:"ancientwarfarestructure:advanced_spawner",properties:{transparent:"true"}},teData:{id:"ancientwarfarestructure:advanced_spawner_tile",spawnerSettings:{minDelay:0,spawnDelay:0,lightSensitive:0b,spawnGroups:[{settingsList:[{remainingSpawnCount:1,hostile:1b,forced:1b,customTag:{factionName:"orc"},maxToSpawn:1,entityId:"ancientwarfarenpc:faction.archer",minToSpawn:1}],groupWeight:1}],playerRange:8,respondToRedstone:0b,inventory:{Size:9,Items:[]},spawnRange:0,transparent:1b,maxDelay:0,xpToDrop:0,mobRange:0,debugMode:0b,maxNearbyMonsters:0}}}
:enddata
:endrule

rule:
plugin=blockTile
number=15
data:
JSON:{blockState:{blockName:"ancientwarfarestructure:advanced_spawner",properties:{transparent:"true"}},teData:{id:"ancientwarfarestructure:advanced_spawner_tile",spawnerSettings:{minDelay:0,spawnDelay:0,lightSensitive:0b,spawnGroups:[{settingsList:[{remainingSpawnCount:1,hostile:1b,forced:1b,customTag:{factionName:"orc"},maxToSpawn:1,entityId:"ancientwarfarenpc:faction.civilian.female",minToSpawn:1}],groupWeight:1}],playerRange:6,respondToRedstone:0b,inventory:{Size:9,Items:[]},spawnRange:0,transparent:1b,maxDelay:0,xpToDrop:0,mobRange:0,debugMode:0b,maxNearbyMonsters:0}}}
:enddata
:endrule

rule:
plugin=inventory
number=16
data:
JSON:{blockState:{blockName:"minecraft:furnace",properties:{facing:"east"}},lootLevel:0,teData:{CookTime:0,BurnTime:0,Items:[],id:"minecraft:furnace",CookTimeTotal:0,Lock:""},inventoryData:{length:0,inventoryContents:[]},legacyFeatures:0b}
:enddata
:endrule

rule:
plugin=inventory
number=17
data:
JSON:{blockState:{blockName:"minecraft:chest",properties:{facing:"east"}},lootLevel:0,teData:{ForgeData:{},Items:[{Slot:2b,id:"minecraft:slime_ball",Count:3b,Damage:0s},{Slot:4b,id:"minecraft:spider_eye",Count:11b,Damage:0s},{Slot:10b,id:"minecraft:dye",Count:8b,Damage:4s},{Slot:15b,id:"minecraft:brown_mushroom",Count:6b,Damage:0s},{Slot:17b,id:"minecraft:red_mushroom",Count:3b,Damage:0s},{Slot:21b,id:"minecraft:rotten_flesh",Count:16b,Damage:0s}],id:"minecraft:chest",Lock:""},inventoryData:{length:6,inventoryContents:[{id:"minecraft:slime_ball",Count:3b,slot:0,Damage:0s},{id:"minecraft:spider_eye",Count:11b,slot:1,Damage:0s},{id:"minecraft:dye",Count:8b,slot:2,Damage:4s},{id:"minecraft:brown_mushroom",Count:6b,slot:3,Damage:0s},{id:"minecraft:red_mushroom",Count:3b,slot:4,Damage:0s},{id:"minecraft:rotten_flesh",Count:16b,slot:5,Damage:0s}]},legacyFeatures:1b}
:enddata
:endrule

rule:
plugin=vanillaBlocks
number=18
data:
JSON:{blockState:{blockName:"minecraft:gravel"}}
:enddata
:endrule

rule:
plugin=vanillaBlocks
number=19
data:
JSON:{blockState:{blockName:"minecraft:mossy_cobblestone"}}
:enddata
:endrule

rule:
plugin=vanillaBlocks
number=20
data:
JSON:{blockState:{blockName:"minecraft:cobblestone"}}
:enddata
:endrule

rule:
plugin=vanillaBlocks
number=21
data:
JSON:{blockState:{blockName:"minecraft:tallgrass",properties:{type:"tall_grass"}}}
:enddata
:endrule

rule:
plugin=vanillaBlocks
number=22
data:
JSON:{blockState:{blockName:"minecraft:log2",properties:{variant:"dark_oak",axis:"y"}}}
:enddata
:endrule

rule:
plugin=vanillaBlocks
number=23
data:
JSON:{blockState:{blockName:"minecraft:nether_brick_fence",properties:{east:"false",south:"false",north:"false",west:"false"}}}
:enddata
:endrule

rule:
plugin=vanillaBlocks
number=24
data:
JSON:{blockState:{blockName:"minecraft:stone_slab",properties:{half:"bottom",variant:"cobblestone"}}}
:enddata
:endrule

rule:
plugin=inventory
number=25
data:
JSON:{blockState:{blockName:"minecraft:chest",properties:{facing:"south"}},lootLevel:0,teData:{ForgeData:{},Items:[{Slot:14b,id:"minecraft:rotten_flesh",Count:16b,Damage:0s},{Slot:20b,id:"minecraft:rotten_flesh",Count:11b,Damage:0s}],id:"minecraft:chest",Lock:""},inventoryData:{length:2,inventoryContents:[{id:"minecraft:rotten_flesh",Count:16b,slot:0,Damage:0s},{id:"minecraft:rotten_flesh",Count:11b,slot:1,Damage:0s}]},legacyFeatures:1b}
:enddata
:endrule

rule:
plugin=blockTile
number=26
data:
JSON:{blockState:{blockName:"ancientwarfarestructure:advanced_spawner",properties:{transparent:"true"}},teData:{id:"ancientwarfarestructure:advanced_spawner_tile",spawnerSettings:{minDelay:0,spawnDelay:0,lightSensitive:0b,spawnGroups:[{settingsList:[{remainingSpawnCount:1,hostile:1b,forced:1b,customTag:{factionName:"orc"},maxToSpawn:1,entityId:"ancientwarfarenpc:faction.soldier.elite",minToSpawn:1}],groupWeight:1}],playerRange:6,respondToRedstone:0b,inventory:{Size:9,Items:[]},spawnRange:0,transparent:1b,maxDelay:0,xpToDrop:0,mobRange:0,debugMode:0b,maxNearbyMonsters:0}}}
:enddata
:endrule

rule:
plugin=blockTile
number=27
data:
JSON:{blockState:{blockName:"ancientwarfarestructure:advanced_spawner",properties:{transparent:"true"}},teData:{id:"ancientwarfarestructure:advanced_spawner_tile",spawnerSettings:{minDelay:0,spawnDelay:0,lightSensitive:0b,spawnGroups:[{settingsList:[{remainingSpawnCount:1,hostile:1b,forced:1b,customTag:{factionName:"orc"},maxToSpawn:1,entityId:"ancientwarfarenpc:faction.soldier.elite",minToSpawn:1}],groupWeight:1}],playerRange:6,respondToRedstone:0b,inventory:{Size:9,Items:[]},spawnRange:0,transparent:1b,maxDelay:0,xpToDrop:0,mobRange:0,debugMode:0b,maxNearbyMonsters:0}}}
:enddata
:endrule

rule:
plugin=blockTile
number=28
data:
JSON:{blockState:{blockName:"ancientwarfarestructure:advanced_spawner",properties:{transparent:"true"}},teData:{id:"ancientwarfarestructure:advanced_spawner_tile",spawnerSettings:{minDelay:0,spawnDelay:0,lightSensitive:0b,spawnGroups:[{settingsList:[{remainingSpawnCount:1,hostile:1b,forced:1b,customTag:{factionName:"orc"},maxToSpawn:1,entityId:"ancientwarfarenpc:faction.soldier",minToSpawn:1}],groupWeight:1}],playerRange:8,respondToRedstone:0b,inventory:{Size:9,Items:[]},spawnRange:0,transparent:1b,maxDelay:0,xpToDrop:0,mobRange:0,debugMode:0b,maxNearbyMonsters:0}}}
:enddata
:endrule

rule:
plugin=inventory
number=29
data:
JSON:{blockState:{blockName:"minecraft:chest",properties:{facing:"south"}},lootLevel:0,teData:{ForgeData:{},Items:[{Slot:2b,id:"minecraft:rotten_flesh",Count:16b,Damage:0s},{Slot:10b,id:"minecraft:spider_eye",Count:5b,Damage:0s},{Slot:13b,id:"ancientwarfarenpc:coin",Count:3b,tag:{metal:"gold"},Damage:0s},{Slot:14b,id:"ancientwarfarenpc:coin",Count:15b,tag:{metal:"silver"},Damage:0s},{Slot:15b,id:"minecraft:coal",Count:14b,Damage:0s},{Slot:17b,id:"minecraft:brown_mushroom",Count:16b,Damage:0s},{Slot:21b,id:"minecraft:dye",Count:11b,Damage:4s},{Slot:23b,id:"ancientwarfarenpc:coin",Count:33b,tag:{metal:"copper"},Damage:0s},{Slot:25b,id:"minecraft:gold_nugget",Count:22b,Damage:0s}],id:"minecraft:chest",Lock:""},inventoryData:{length:9,inventoryContents:[{id:"minecraft:rotten_flesh",Count:16b,slot:0,Damage:0s},{id:"minecraft:spider_eye",Count:5b,slot:1,Damage:0s},{id:"ancientwarfarenpc:coin",Count:3b,tag:{metal:"gold"},slot:2,Damage:0s},{id:"ancientwarfarenpc:coin",Count:15b,tag:{metal:"silver"},slot:3,Damage:0s},{id:"minecraft:coal",Count:14b,slot:4,Damage:0s},{id:"minecraft:brown_mushroom",Count:16b,slot:5,Damage:0s},{id:"minecraft:dye",Count:11b,slot:6,Damage:4s},{id:"ancientwarfarenpc:coin",Count:33b,tag:{metal:"copper"},slot:7,Damage:0s},{id:"minecraft:gold_nugget",Count:22b,slot:8,Damage:0s}]},legacyFeatures:1b}
:enddata
:endrule

rule:
plugin=blockTile
number=30
data:
JSON:{blockState:{blockName:"ancientwarfarestructure:advanced_spawner",properties:{transparent:"true"}},teData:{id:"ancientwarfarestructure:advanced_spawner_tile",spawnerSettings:{minDelay:0,spawnDelay:0,lightSensitive:0b,spawnGroups:[{settingsList:[{remainingSpawnCount:1,hostile:1b,forced:1b,customTag:{factionName:"orc"},maxToSpawn:1,entityId:"ancientwarfarenpc:faction.priest",minToSpawn:1}],groupWeight:1}],playerRange:6,respondToRedstone:0b,inventory:{Size:9,Items:[]},spawnRange:0,transparent:1b,maxDelay:0,xpToDrop:0,mobRange:0,debugMode:0b,maxNearbyMonsters:0}}}
:enddata
:endrule

rule:
plugin=inventory
number=31
data:
JSON:{blockState:{blockName:"minecraft:furnace",properties:{facing:"east"}},lootLevel:0,teData:{CookTime:0,BurnTime:0,Items:[],id:"minecraft:furnace",CookTimeTotal:0,Lock:""},inventoryData:{length:0,inventoryContents:[]},legacyFeatures:0b}
:enddata
:endrule

rule:
plugin=vanillaBlocks
number=32
data:
JSON:{blockState:{blockName:"minecraft:cauldron",properties:{level:"3"}}}
:enddata
:endrule

rule:
plugin=vanillaBlocks
number=33
data:
JSON:{blockState:{blockName:"minecraft:dark_oak_stairs",properties:{half:"top",shape:"straight",facing:"south"}}}
:enddata
:endrule

rule:
plugin=vanillaBlocks
number=34
data:
JSON:{blockState:{blockName:"minecraft:dark_oak_stairs",properties:{half:"top",shape:"straight",facing:"north"}}}
:enddata
:endrule

rule:
plugin=vanillaBlocks
number=35
data:
JSON:{blockState:{blockName:"minecraft:torch",properties:{facing:"west"}}}
:enddata
:endrule

rule:
plugin=vanillaBlocks
number=36
data:
JSON:{blockState:{blockName:"minecraft:torch",properties:{facing:"east"}}}
:enddata
:endrule

rule:
plugin=vanillaBlocks
number=37
data:
JSON:{blockState:{blockName:"minecraft:dark_oak_stairs",properties:{half:"top",shape:"straight",facing:"east"}}}
:enddata
:endrule

rule:
plugin=vanillaSkull
number=38
data:
JSON:{blockState:{blockName:"minecraft:skull",properties:{nodrop:"false",facing:"up"}},skullRotation:12,teData:{Rot:8b,id:"minecraft:skull",SkullType:3b}}
:enddata
:endrule

rule:
plugin=vanillaSkull
number=39
data:
JSON:{blockState:{blockName:"minecraft:skull",properties:{nodrop:"false",facing:"up"}},skullRotation:12,teData:{Rot:8b,id:"minecraft:skull",SkullType:0b}}
:enddata
:endrule

rule:
plugin=vanillaSkull
number=40
data:
JSON:{blockState:{blockName:"minecraft:skull",properties:{nodrop:"false",facing:"up"}},skullRotation:0,teData:{Rot:12b,id:"minecraft:skull",SkullType:0b}}
:enddata
:endrule

rule:
plugin=vanillaBlocks
number=41
data:
JSON:{blockState:{blockName:"minecraft:torch",properties:{facing:"up"}}}
:enddata
:endrule

rule:
plugin=vanillaSkull
number=42
data:
JSON:{blockState:{blockName:"minecraft:skull",properties:{nodrop:"false",facing:"up"}},skullRotation:4,teData:{Rot:0b,id:"minecraft:skull",SkullType:0b}}
:enddata
:endrule

rule:
plugin=vanillaSkull
number=43
data:
JSON:{blockState:{blockName:"minecraft:skull",properties:{nodrop:"false",facing:"up"}},skullRotation:0,teData:{Rot:12b,id:"minecraft:skull",SkullType:0b}}
:enddata
:endrule

rule:
plugin=vanillaSkull
number=44
data:
JSON:{blockState:{blockName:"minecraft:skull",properties:{nodrop:"false",facing:"up"}},skullRotation:12,teData:{Rot:8b,id:"minecraft:skull",SkullType:3b}}
:enddata
:endrule

rule:
plugin=vanillaBlocks
number=45
data:
JSON:{blockState:{blockName:"minecraft:dark_oak_stairs",properties:{half:"top",shape:"straight",facing:"west"}}}
:enddata
:endrule

rule:
plugin=vanillaBlocks
number=46
data:
JSON:{blockState:{blockName:"minecraft:double_wooden_slab",properties:{variant:"dark_oak"}}}
:enddata
:endrule

rule:
plugin=vanillaBlocks
number=47
data:
JSON:{blockState:{blockName:"minecraft:wooden_slab",properties:{half:"top",variant:"spruce"}}}
:enddata
:endrule

rule:
plugin=inventory
number=48
data:
JSON:{blockState:{blockName:"minecraft:brewing_stand",properties:{has_bottle_0:"false",has_bottle_1:"false",has_bottle_2:"false"}},lootLevel:0,teData:{Fuel:0b,Items:[],id:"minecraft:brewing_stand",BrewTime:0s,Lock:""},inventoryData:{length:0,inventoryContents:[]},legacyFeatures:0b}
:enddata
:endrule

rule:
plugin=vanillaBlocks
number=49
data:
JSON:{blockState:{blockName:"minecraft:torch",properties:{facing:"south"}}}
:enddata
:endrule

rule:
plugin=vanillaSkull
number=50
data:
JSON:{blockState:{blockName:"minecraft:skull",properties:{nodrop:"false",facing:"up"}},skullRotation:0,teData:{Rot:12b,id:"minecraft:skull",SkullType:0b}}
:enddata
:endrule

rule:
plugin=vanillaSkull
number=51
data:
JSON:{blockState:{blockName:"minecraft:skull",properties:{nodrop:"false",facing:"up"}},skullRotation:4,teData:{Rot:0b,id:"minecraft:skull",SkullType:0b}}
:enddata
:endrule

rule:
plugin=vanillaBlocks
number=52
data:
JSON:{blockState:{blockName:"minecraft:stone_stairs",properties:{half:"top",shape:"straight",facing:"north"}}}
:enddata
:endrule

rule:
plugin=vanillaBlocks
number=53
data:
JSON:{blockState:{blockName:"minecraft:stone_slab",properties:{half:"top",variant:"cobblestone"}}}
:enddata
:endrule

rule:
plugin=vanillaBlocks
number=54
data:
JSON:{blockState:{blockName:"minecraft:monster_egg",properties:{variant:"stone_brick"}}}
:enddata
:endrule

rule:
plugin=vanillaSkull
number=55
data:
JSON:{blockState:{blockName:"minecraft:skull",properties:{nodrop:"false",facing:"up"}},skullRotation:12,teData:{Rot:8b,id:"minecraft:skull",SkullType:0b}}
:enddata
:endrule

rule:
plugin=vanillaSkull
number=56
data:
JSON:{blockState:{blockName:"minecraft:skull",properties:{nodrop:"false",facing:"up"}},skullRotation:8,teData:{Rot:4b,id:"minecraft:skull",SkullType:0b}}
:enddata
:endrule

rule:
plugin=vanillaSkull
number=57
data:
JSON:{blockState:{blockName:"minecraft:skull",properties:{nodrop:"false",facing:"up"}},skullRotation:0,teData:{Rot:12b,id:"minecraft:skull",SkullType:1b}}
:enddata
:endrule

rule:
plugin=vanillaSkull
number=58
data:
JSON:{blockState:{blockName:"minecraft:skull",properties:{nodrop:"false",facing:"up"}},skullRotation:4,teData:{Rot:0b,id:"minecraft:skull",SkullType:0b}}
:enddata
:endrule

rule:
plugin=vanillaSkull
number=59
data:
JSON:{blockState:{blockName:"minecraft:skull",properties:{nodrop:"false",facing:"up"}},skullRotation:4,teData:{Rot:0b,id:"minecraft:skull",SkullType:0b}}
:enddata
:endrule

rule:
plugin=vanillaSkull
number=60
data:
JSON:{blockState:{blockName:"minecraft:skull",properties:{nodrop:"false",facing:"up"}},skullRotation:0,teData:{Rot:12b,id:"minecraft:skull",SkullType:0b}}
:enddata
:endrule

rule:
plugin=vanillaSkull
number=61
data:
JSON:{blockState:{blockName:"minecraft:skull",properties:{nodrop:"false",facing:"up"}},skullRotation:4,teData:{Rot:0b,id:"minecraft:skull",SkullType:0b}}
:enddata
:endrule

rule:
plugin=blockTile
number=62
data:
JSON:{blockState:{blockName:"ancientwarfarestructure:advanced_spawner",properties:{transparent:"true"}},teData:{id:"ancientwarfarestructure:advanced_spawner_tile",spawnerSettings:{minDelay:0,spawnDelay:0,lightSensitive:0b,spawnGroups:[{settingsList:[{remainingSpawnCount:1,hostile:1b,forced:1b,customTag:{factionName:"orc"},maxToSpawn:1,entityId:"ancientwarfarenpc:faction.archer.elite",minToSpawn:1}],groupWeight:1}],playerRange:24,respondToRedstone:0b,inventory:{Size:9,Items:[]},spawnRange:0,transparent:1b,maxDelay:0,xpToDrop:0,mobRange:0,debugMode:0b,maxNearbyMonsters:0}}}
:enddata
:endrule

rule:
plugin=vanillaSkull
number=63
data:
JSON:{blockState:{blockName:"minecraft:skull",properties:{nodrop:"false",facing:"up"}},skullRotation:12,teData:{Rot:8b,id:"minecraft:skull",SkullType:0b}}
:enddata
:endrule

rule:
plugin=vanillaSkull
number=64
data:
JSON:{blockState:{blockName:"minecraft:skull",properties:{nodrop:"false",facing:"up"}},skullRotation:8,teData:{Rot:4b,id:"minecraft:skull",SkullType:0b}}
:enddata
:endrule

rule:
plugin=vanillaSkull
number=65
data:
JSON:{blockState:{blockName:"minecraft:skull",properties:{nodrop:"false",facing:"up"}},skullRotation:12,teData:{Rot:8b,id:"minecraft:skull",SkullType:0b}}
:enddata
:endrule

rule:
plugin=vanillaSkull
number=66
data:
JSON:{blockState:{blockName:"minecraft:skull",properties:{nodrop:"false",facing:"up"}},skullRotation:8,teData:{Rot:4b,id:"minecraft:skull",SkullType:0b}}
:enddata
:endrule

rule:
plugin=vanillaBlocks
number=67
data:
JSON:{blockState:{blockName:"minecraft:double_wooden_slab",properties:{variant:"oak"}}}
:enddata
:endrule

rule:
plugin=vanillaBlocks
number=68
data:
JSON:{blockState:{blockName:"minecraft:lit_pumpkin",properties:{facing:"east"}}}
:enddata
:endrule

rule:
plugin=vanillaSkull
number=69
data:
JSON:{blockState:{blockName:"minecraft:skull",properties:{nodrop:"false",facing:"up"}},skullRotation:8,teData:{Rot:4b,id:"minecraft:skull",SkullType:0b}}
:enddata
:endrule

rule:
plugin=vanillaSkull
number=70
data:
JSON:{blockState:{blockName:"minecraft:skull",properties:{nodrop:"false",facing:"up"}},skullRotation:12,teData:{Rot:8b,id:"minecraft:skull",SkullType:0b}}
:enddata
:endrule

rule:
plugin=vanillaSkull
number=71
data:
JSON:{blockState:{blockName:"minecraft:skull",properties:{nodrop:"false",facing:"up"}},skullRotation:8,teData:{Rot:4b,id:"minecraft:skull",SkullType:0b}}
:enddata
:endrule

rule:
plugin=vanillaSkull
number=72
data:
JSON:{blockState:{blockName:"minecraft:skull",properties:{nodrop:"false",facing:"up"}},skullRotation:12,teData:{Rot:8b,id:"minecraft:skull",SkullType:0b}}
:enddata
:endrule

rule:
plugin=blockTile
number=73
data:
JSON:{blockState:{blockName:"ancientwarfarestructure:advanced_spawner",properties:{transparent:"true"}},teData:{id:"ancientwarfarestructure:advanced_spawner_tile",spawnerSettings:{minDelay:0,spawnDelay:0,lightSensitive:0b,spawnGroups:[{settingsList:[{remainingSpawnCount:1,hostile:1b,forced:1b,customTag:{factionName:"orc"},maxToSpawn:1,entityId:"ancientwarfarenpc:faction.archer.elite",minToSpawn:1}],groupWeight:1}],playerRange:24,respondToRedstone:0b,inventory:{Size:9,Items:[]},spawnRange:0,transparent:1b,maxDelay:0,xpToDrop:0,mobRange:0,debugMode:0b,maxNearbyMonsters:0}}}
:enddata
:endrule

rule:
plugin=vanillaSkull
number=74
data:
JSON:{blockState:{blockName:"minecraft:skull",properties:{nodrop:"false",facing:"up"}},skullRotation:4,teData:{Rot:0b,id:"minecraft:skull",SkullType:0b}}
:enddata
:endrule

rule:
plugin=vanillaSkull
number=75
data:
JSON:{blockState:{blockName:"minecraft:skull",properties:{nodrop:"false",facing:"up"}},skullRotation:0,teData:{Rot:12b,id:"minecraft:skull",SkullType:0b}}
:enddata
:endrule

rule:
plugin=vanillaSkull
number=76
data:
JSON:{blockState:{blockName:"minecraft:skull",properties:{nodrop:"false",facing:"up"}},skullRotation:4,teData:{Rot:0b,id:"minecraft:skull",SkullType:0b}}
:enddata
:endrule

rule:
plugin=vanillaSkull
number=77
data:
JSON:{blockState:{blockName:"minecraft:skull",properties:{nodrop:"false",facing:"up"}},skullRotation:4,teData:{Rot:0b,id:"minecraft:skull",SkullType:0b}}
:enddata
:endrule

rule:
plugin=vanillaBlocks
number=78
data:
JSON:{blockState:{blockName:"minecraft:leaves2",properties:{check_decay:"false",decayable:"true",variant:"dark_oak"}}}
:enddata
:endrule

rule:
plugin=vanillaSkull
number=79
data:
JSON:{blockState:{blockName:"minecraft:skull",properties:{nodrop:"false",facing:"up"}},skullRotation:8,teData:{Rot:4b,id:"minecraft:skull",SkullType:0b}}
:enddata
:endrule

rule:
plugin=vanillaBlocks
number=80
data:
JSON:{blockState:{blockName:"minecraft:dark_oak_stairs",properties:{half:"bottom",shape:"straight",facing:"west"}}}
:enddata
:endrule

rule:
plugin=vanillaBlocks
number=81
data:
JSON:{blockState:{blockName:"minecraft:dark_oak_stairs",properties:{half:"bottom",shape:"straight",facing:"south"}}}
:enddata
:endrule

rule:
plugin=vanillaBlocks
number=82
data:
JSON:{blockState:{blockName:"minecraft:dark_oak_stairs",properties:{half:"bottom",shape:"straight",facing:"north"}}}
:enddata
:endrule

rule:
plugin=vanillaSkull
number=83
data:
JSON:{blockState:{blockName:"minecraft:skull",properties:{nodrop:"false",facing:"up"}},skullRotation:4,teData:{Rot:0b,id:"minecraft:skull",SkullType:0b}}
:enddata
:endrule

rule:
plugin=blockTile
number=84
data:
JSON:{blockState:{blockName:"ancientwarfarestructure:advanced_spawner",properties:{transparent:"true"}},teData:{id:"ancientwarfarestructure:advanced_spawner_tile",spawnerSettings:{minDelay:9,spawnDelay:278,lightSensitive:0b,spawnGroups:[{settingsList:[{remainingSpawnCount:1,hostile:1b,forced:1b,customTag:{factionName:"orc"},maxToSpawn:1,entityId:"ancientwarfarenpc:faction.soldier",minToSpawn:1}],groupWeight:1}],playerRange:12,respondToRedstone:0b,inventory:{Size:9,Items:[]},spawnRange:4,transparent:0b,maxDelay:900,xpToDrop:50,mobRange:12,debugMode:0b,maxNearbyMonsters:12}}}
:enddata
:endrule

rule:
plugin=blockTile
number=85
data:
JSON:{blockState:{blockName:"ancientwarfarestructure:advanced_spawner",properties:{transparent:"true"}},teData:{id:"ancientwarfarestructure:advanced_spawner_tile",spawnerSettings:{minDelay:0,spawnDelay:0,lightSensitive:0b,spawnGroups:[{settingsList:[{remainingSpawnCount:1,hostile:1b,forced:1b,customTag:{factionName:"orc"},maxToSpawn:1,entityId:"ancientwarfarenpc:faction.archer.elite",minToSpawn:1}],groupWeight:1}],playerRange:24,respondToRedstone:0b,inventory:{Size:9,Items:[]},spawnRange:0,transparent:1b,maxDelay:0,xpToDrop:0,mobRange:0,debugMode:0b,maxNearbyMonsters:0}}}
:enddata
:endrule

rule:
plugin=vanillaBlocks
number=86
data:
JSON:{blockState:{blockName:"minecraft:dark_oak_stairs",properties:{half:"bottom",shape:"straight",facing:"east"}}}
:enddata
:endrule

rule:
plugin=vanillaSkull
number=87
data:
JSON:{blockState:{blockName:"minecraft:skull",properties:{nodrop:"false",facing:"up"}},skullRotation:8,teData:{Rot:4b,id:"minecraft:skull",SkullType:0b}}
:enddata
:endrule

rule:
plugin=vanillaSkull
number=88
data:
JSON:{blockState:{blockName:"minecraft:skull",properties:{nodrop:"false",facing:"up"}},skullRotation:12,teData:{Rot:8b,id:"minecraft:skull",SkullType:0b}}
:enddata
:endrule

rule:
plugin=blockTile
number=89
data:
JSON:{blockState:{blockName:"ancientwarfarestructure:advanced_spawner",properties:{transparent:"true"}},teData:{id:"ancientwarfarestructure:advanced_spawner_tile",spawnerSettings:{minDelay:0,spawnDelay:0,lightSensitive:0b,spawnGroups:[{settingsList:[{remainingSpawnCount:1,hostile:1b,forced:1b,customTag:{factionName:"orc"},maxToSpawn:1,entityId:"ancientwarfarenpc:faction.archer.elite",minToSpawn:1}],groupWeight:1}],playerRange:24,respondToRedstone:0b,inventory:{Size:9,Items:[]},spawnRange:0,transparent:1b,maxDelay:0,xpToDrop:0,mobRange:0,debugMode:0b,maxNearbyMonsters:0}}}
:enddata
:endrule

rule:
plugin=vanillaSkull
number=90
data:
JSON:{blockState:{blockName:"minecraft:skull",properties:{nodrop:"false",facing:"up"}},skullRotation:0,teData:{Rot:12b,id:"minecraft:skull",SkullType:0b}}
:enddata
:endrule

rule:
plugin=vanillaSkull
number=91
data:
JSON:{blockState:{blockName:"minecraft:skull",properties:{nodrop:"false",facing:"up"}},skullRotation:12,teData:{Rot:8b,id:"minecraft:skull",SkullType:0b}}
:enddata
:endrule

rule:
plugin=vanillaSkull
number=92
data:
JSON:{blockState:{blockName:"minecraft:skull",properties:{nodrop:"false",facing:"up"}},skullRotation:8,teData:{Rot:4b,id:"minecraft:skull",SkullType:0b}}
:enddata
:endrule

rule:
plugin=vanillaSkull
number=93
data:
JSON:{blockState:{blockName:"minecraft:skull",properties:{nodrop:"false",facing:"up"}},skullRotation:4,teData:{Rot:0b,id:"minecraft:skull",SkullType:0b}}
:enddata
:endrule

rule:
plugin=vanillaSkull
number=94
data:
JSON:{blockState:{blockName:"minecraft:skull",properties:{nodrop:"false",facing:"up"}},skullRotation:12,teData:{Rot:8b,id:"minecraft:skull",SkullType:0b}}
:enddata
:endrule

rule:
plugin=blockTile
number=95
data:
JSON:{blockState:{blockName:"ancientwarfarestructure:advanced_spawner",properties:{transparent:"true"}},teData:{id:"ancientwarfarestructure:advanced_spawner_tile",spawnerSettings:{minDelay:0,spawnDelay:0,lightSensitive:0b,spawnGroups:[{settingsList:[{remainingSpawnCount:1,hostile:1b,forced:1b,customTag:{factionName:"orc"},maxToSpawn:1,entityId:"ancientwarfarenpc:faction.archer.elite",minToSpawn:1}],groupWeight:1}],playerRange:24,respondToRedstone:0b,inventory:{Size:9,Items:[]},spawnRange:0,transparent:1b,maxDelay:0,xpToDrop:0,mobRange:0,debugMode:0b,maxNearbyMonsters:0}}}
:enddata
:endrule

rule:
plugin=vanillaSkull
number=96
data:
JSON:{blockState:{blockName:"minecraft:skull",properties:{nodrop:"false",facing:"up"}},skullRotation:4,teData:{Rot:0b,id:"minecraft:skull",SkullType:0b}}
:enddata
:endrule

rule:
plugin=blockTile
number=97
data:
JSON:{blockState:{blockName:"ancientwarfarestructure:advanced_spawner",properties:{transparent:"true"}},teData:{id:"ancientwarfarestructure:advanced_spawner_tile",spawnerSettings:{minDelay:0,spawnDelay:0,lightSensitive:0b,spawnGroups:[{settingsList:[{remainingSpawnCount:1,hostile:1b,forced:1b,customTag:{factionName:"orc"},maxToSpawn:1,entityId:"ancientwarfarenpc:faction.archer.elite",minToSpawn:1}],groupWeight:1}],playerRange:24,respondToRedstone:0b,inventory:{Size:9,Items:[]},spawnRange:0,transparent:1b,maxDelay:0,xpToDrop:0,mobRange:0,debugMode:0b,maxNearbyMonsters:0}}}
:enddata
:endrule

rule:
plugin=blockTile
number=98
data:
JSON:{blockState:{blockName:"ancientwarfarestructure:advanced_spawner",properties:{transparent:"true"}},teData:{id:"ancientwarfarestructure:advanced_spawner_tile",spawnerSettings:{minDelay:0,spawnDelay:0,lightSensitive:0b,spawnGroups:[{settingsList:[{remainingSpawnCount:1,hostile:1b,forced:1b,customTag:{factionName:"orc"},maxToSpawn:1,entityId:"ancientwarfarenpc:faction.archer.elite",minToSpawn:1}],groupWeight:1}],playerRange:24,respondToRedstone:0b,inventory:{Size:9,Items:[]},spawnRange:0,transparent:1b,maxDelay:0,xpToDrop:0,mobRange:0,debugMode:0b,maxNearbyMonsters:0}}}
:enddata
:endrule

rule:
plugin=blockTile
number=99
data:
JSON:{blockState:{blockName:"ancientwarfarestructure:advanced_spawner",properties:{transparent:"true"}},teData:{id:"ancientwarfarestructure:advanced_spawner_tile",spawnerSettings:{minDelay:0,spawnDelay:0,lightSensitive:0b,spawnGroups:[{settingsList:[{remainingSpawnCount:1,hostile:1b,forced:1b,customTag:{factionName:"orc"},maxToSpawn:1,entityId:"ancientwarfarenpc:faction.archer.elite",minToSpawn:1}],groupWeight:1}],playerRange:24,respondToRedstone:0b,inventory:{Size:9,Items:[]},spawnRange:0,transparent:1b,maxDelay:0,xpToDrop:0,mobRange:0,debugMode:0b,maxNearbyMonsters:0}}}
:enddata
:endrule

#### ENTITIES ####
