# Ancient Warfare Structure Template File
# Auto-generated structure template file. created on: 8/19/2019 at: 10:23:14
# Lines beginning with # denote comments

header:
version=2.9
name=OrcVillageLargeRoofedForest
mods=
size=37,22,32
offset=20,6,31
:endheader

#### VALIDATION ####
validation:
type=ground
survival=false
worldGenEnabled=true
unique=false
preserveBlocks=false
selectionWeight=100
clusterValue=60
minDuplicateDistance=900
dimensionWhiteList=true
dimensionList=0
biomeWhiteList=true
biomeList=minecraft:roofed_forest
leveling=4
fill=3
border=4
blockSwap=false
:endvalidation

#### LAYERS ####
layer: 0
1,1,1,1,1,1,1,1,1,1,1,1,1,1,1,1,1,1,1,1,1,1,1,1,1,1,1,1,1,1,1,1,1,1,1,1,1
1,1,1,1,1,1,1,1,1,1,1,1,1,1,1,1,1,1,1,1,1,1,1,1,1,1,1,1,1,1,1,1,1,1,1,1,1
1,1,1,1,1,1,1,1,1,1,1,1,1,1,1,1,1,1,1,1,1,1,1,1,1,1,1,1,1,1,1,1,1,1,1,1,1
1,1,1,1,1,1,1,1,1,1,1,1,1,1,1,1,1,1,1,1,1,1,1,1,1,1,1,1,1,1,1,1,1,1,1,1,1
1,1,1,1,1,1,1,1,1,1,1,1,1,1,1,1,1,1,1,1,1,1,1,1,1,1,1,1,1,1,1,1,1,1,1,1,1
1,1,1,1,1,1,1,1,1,1,1,1,1,1,1,1,1,1,1,1,1,1,1,1,1,1,1,1,1,1,1,1,1,1,1,1,1
1,1,1,1,1,1,1,1,1,1,1,1,1,1,1,1,1,1,1,1,1,1,1,1,1,1,1,1,1,1,1,1,1,1,1,1,1
1,1,1,1,1,1,1,1,1,1,1,1,1,1,1,1,1,1,1,1,1,1,1,1,1,1,1,1,1,1,1,1,1,1,1,1,1
1,1,1,1,1,1,1,1,1,1,1,1,1,1,1,1,1,1,1,1,1,1,1,1,1,1,1,1,1,1,1,1,1,1,1,1,1
1,1,1,1,1,1,1,1,1,1,1,1,1,1,1,1,1,1,1,1,1,1,1,1,1,1,1,1,1,1,1,1,1,1,1,1,1
1,1,1,1,1,1,1,1,1,1,1,1,1,1,1,1,1,1,1,1,1,1,1,1,1,1,1,1,1,1,1,1,1,1,1,1,1
1,1,1,1,1,1,1,1,1,1,1,1,1,1,1,1,1,1,1,1,1,1,1,1,1,1,1,1,1,1,1,1,1,1,1,1,1
1,1,1,1,1,1,1,1,1,1,1,1,1,1,1,1,1,1,1,1,1,1,1,1,1,1,1,1,1,1,1,1,1,1,1,1,1
1,1,1,1,1,1,1,1,1,1,1,1,1,1,1,1,1,1,1,1,1,1,1,1,1,1,1,1,1,1,1,1,1,1,1,1,1
1,1,1,1,1,1,1,1,1,1,1,1,1,1,1,1,1,1,1,1,1,1,1,1,1,1,1,1,1,1,1,1,1,1,1,1,1
1,1,1,1,1,1,1,1,1,1,1,1,1,1,1,1,1,1,1,1,1,1,1,1,1,1,1,1,1,1,1,1,1,1,1,1,1
1,1,1,1,1,1,1,1,1,1,1,1,1,1,1,1,1,1,1,1,1,1,1,1,1,1,1,1,1,1,1,1,1,1,1,1,1
1,1,1,1,1,1,1,1,1,1,1,1,1,1,1,1,1,1,1,1,1,1,1,1,1,1,1,1,1,1,1,1,1,1,1,1,1
1,1,1,1,1,1,1,1,1,1,1,1,1,1,1,1,1,1,1,1,1,1,1,1,1,1,1,1,1,1,1,1,1,1,1,1,1
1,1,1,1,1,1,1,1,1,1,1,1,1,1,1,1,1,1,1,1,1,1,1,1,1,1,1,1,1,1,1,1,1,1,1,1,1
1,1,1,1,1,1,1,1,1,1,1,1,1,1,1,1,1,1,1,1,1,1,1,1,1,1,1,1,1,1,1,1,1,1,1,1,1
1,1,1,1,1,1,1,1,1,1,1,1,1,1,1,1,1,1,1,1,1,1,1,1,1,1,1,1,1,1,1,1,1,1,1,1,1
1,1,1,1,1,1,1,1,1,1,1,1,1,1,1,1,1,1,1,1,1,1,1,1,1,1,1,1,1,1,1,1,1,1,1,1,1
1,1,1,1,1,1,1,1,1,1,1,1,1,1,1,1,1,1,1,1,1,1,1,1,1,1,1,1,1,1,1,1,1,1,1,1,1
1,1,1,1,1,1,1,1,1,1,1,1,1,1,1,1,1,1,1,1,1,1,1,1,1,1,1,1,1,1,1,1,1,1,1,1,1
1,1,1,1,1,1,1,1,1,1,1,1,1,1,1,1,1,1,1,1,1,1,1,1,1,1,1,1,1,1,1,1,1,1,1,1,1
1,1,1,1,1,1,1,1,1,1,1,1,1,1,1,1,1,1,1,1,1,1,1,1,1,1,1,1,1,1,1,1,1,1,1,1,1
1,1,1,1,1,1,1,1,1,1,1,1,1,1,1,1,1,1,1,1,1,1,1,1,1,1,1,1,1,1,1,1,1,1,1,1,1
1,1,1,1,1,1,1,1,1,1,1,1,1,1,1,1,1,1,1,1,1,1,1,1,1,1,1,1,1,1,1,1,1,1,1,1,1
1,1,1,1,1,1,1,1,1,1,1,1,1,1,1,1,1,1,1,1,1,1,1,1,1,1,1,1,1,1,1,1,1,1,1,1,1
1,1,1,1,1,1,1,1,1,1,1,1,1,1,1,1,1,1,1,1,1,1,1,1,1,1,1,1,1,1,1,1,1,1,1,1,1
1,1,1,1,1,1,1,1,1,1,1,1,1,1,1,1,1,1,1,1,1,1,1,1,1,1,1,1,1,1,1,1,1,1,1,1,1
:endlayer
layer: 1
1,1,1,1,1,1,1,1,1,1,1,1,1,1,1,1,1,1,1,1,1,1,1,1,1,1,1,1,1,1,1,1,1,1,1,1,1
1,1,1,1,1,1,1,1,1,1,1,1,1,1,1,1,1,1,1,1,1,1,1,1,1,1,1,1,1,1,1,1,1,1,1,1,1
1,1,1,1,1,1,1,1,1,1,1,1,1,1,1,1,1,1,1,1,1,1,1,1,1,1,1,1,1,1,1,1,1,1,1,1,1
1,1,1,1,1,1,1,1,1,1,1,1,1,1,1,1,1,1,1,1,1,1,1,1,1,1,1,1,1,1,1,1,1,1,1,1,1
1,1,1,1,1,1,1,1,1,1,1,1,1,1,1,1,1,1,1,1,1,1,1,1,1,1,1,1,1,1,1,1,1,1,1,1,1
1,1,1,1,1,1,1,1,1,1,1,1,1,1,1,1,1,1,1,1,1,1,1,1,1,1,1,1,1,1,1,1,1,1,1,1,1
1,1,1,1,1,1,1,1,1,1,1,1,1,1,1,1,1,1,1,1,1,1,1,1,1,1,1,1,1,1,1,1,1,1,1,1,1
1,1,1,1,1,1,1,1,1,1,1,1,1,1,1,1,1,1,1,1,1,1,1,1,1,1,1,1,1,1,1,1,1,1,1,1,1
1,1,1,1,1,1,1,1,1,1,1,1,1,1,1,1,1,1,1,1,1,1,1,1,1,1,1,1,1,1,1,1,1,1,1,1,1
1,1,1,1,1,1,1,1,1,1,1,1,1,1,1,1,1,1,1,1,1,1,1,1,1,1,1,1,1,1,1,1,1,1,1,1,1
1,1,1,1,1,1,1,1,1,1,1,1,1,1,1,1,1,1,1,1,1,1,1,1,1,1,1,1,1,1,1,1,1,1,1,1,1
1,1,1,1,1,1,1,1,1,1,1,1,1,1,1,1,1,1,1,1,1,1,1,1,1,1,1,1,1,1,1,1,1,1,1,1,1
1,1,1,1,1,1,1,1,1,1,1,1,1,1,1,1,1,1,1,1,1,1,1,1,1,1,1,1,1,1,1,1,1,1,1,1,1
1,1,1,1,1,1,1,1,1,1,1,1,1,1,1,1,1,1,1,1,1,1,1,1,1,1,1,1,1,1,1,1,1,1,1,1,1
1,1,1,1,1,1,1,1,1,1,1,1,1,1,1,1,1,1,1,1,1,1,1,1,1,1,1,1,1,1,1,1,1,1,1,1,1
1,1,1,1,1,1,1,1,1,1,1,1,1,1,1,1,1,1,1,1,1,1,1,1,1,1,1,1,1,1,1,1,1,1,1,1,1
1,1,1,1,1,1,1,1,1,1,1,1,1,1,1,1,1,1,1,1,1,1,1,1,1,1,1,1,1,1,1,1,1,1,1,1,1
1,1,1,1,1,1,1,1,1,1,1,1,1,1,1,1,1,1,1,1,1,1,1,1,1,1,1,1,1,1,1,1,1,1,1,1,1
1,1,1,1,1,1,1,1,1,1,1,1,1,1,1,1,1,1,1,1,1,1,1,1,1,1,1,1,1,1,1,1,1,1,1,1,1
1,1,1,1,1,1,1,1,1,1,1,1,1,1,1,1,1,1,1,1,1,1,1,1,1,1,1,1,1,1,1,1,1,1,1,1,1
1,1,1,1,1,1,1,1,1,1,1,1,1,1,1,1,1,1,1,1,1,1,1,1,1,1,1,1,1,1,1,1,1,1,1,1,1
1,1,1,1,1,1,1,1,1,1,1,1,1,1,1,1,1,1,1,1,1,1,1,1,1,1,1,1,1,1,1,1,1,1,1,1,1
1,1,1,1,1,1,1,1,1,1,1,1,1,1,1,1,1,1,1,1,1,1,1,1,1,1,1,1,1,1,1,1,1,1,1,1,1
1,1,1,1,1,1,1,1,1,1,1,1,1,1,1,1,1,1,1,1,1,1,1,1,1,1,1,1,1,1,1,1,1,1,1,1,1
1,1,1,1,1,1,1,1,1,1,1,1,1,1,1,1,1,1,1,1,1,1,1,1,1,1,1,1,1,1,1,1,1,1,1,1,1
1,1,1,1,1,1,1,1,1,1,1,1,1,1,1,1,1,1,1,1,1,1,1,1,1,1,1,1,1,1,1,1,1,1,1,1,1
1,1,1,1,1,1,1,1,1,1,1,1,1,1,1,1,1,1,1,1,1,1,1,1,1,1,1,1,1,1,1,1,1,1,1,1,1
1,1,1,1,1,1,1,1,1,1,1,1,1,1,1,1,1,1,1,1,1,1,1,1,1,1,1,1,1,1,1,1,1,1,1,1,1
1,1,1,1,1,1,1,1,1,1,1,1,1,1,1,1,1,1,1,1,1,1,1,1,1,1,1,1,1,1,1,1,1,1,1,1,1
1,1,1,1,1,1,1,1,1,1,1,1,1,1,1,1,1,1,1,1,1,1,1,1,1,1,1,1,1,1,1,1,1,1,1,1,1
1,1,1,1,1,1,1,1,1,1,1,1,1,1,1,1,1,1,1,1,1,1,1,1,1,1,1,1,1,1,1,1,1,1,1,1,1
1,1,1,1,1,1,1,1,1,1,1,1,1,1,1,1,1,1,1,1,1,1,1,1,1,1,1,1,1,1,1,1,1,1,1,1,1
:endlayer
layer: 2
1,1,1,1,1,1,1,1,1,1,1,1,1,1,1,1,1,1,1,1,1,1,1,1,1,1,1,1,1,1,1,1,1,1,1,1,1
1,1,1,1,1,1,1,1,1,1,1,1,1,1,1,1,1,1,1,1,1,1,1,1,1,1,1,1,1,1,1,1,1,1,1,1,1
1,1,1,1,1,1,1,1,1,1,1,1,1,1,1,1,1,1,1,1,1,1,1,1,1,1,1,1,1,1,1,1,1,1,1,1,1
1,1,1,1,1,1,1,1,1,1,1,1,1,1,1,1,1,1,1,1,1,1,1,1,1,1,1,1,1,1,1,1,1,1,1,1,1
1,1,1,1,1,1,1,1,1,1,1,1,1,1,1,1,1,1,1,1,1,2,1,1,1,2,1,1,1,1,1,1,1,1,1,1,1
1,1,1,1,1,1,1,1,1,1,1,1,1,1,1,1,1,1,1,1,1,2,1,1,1,2,1,1,1,1,1,1,1,1,1,1,1
1,1,1,1,1,1,1,1,1,1,1,1,1,1,1,1,1,1,1,1,1,1,1,1,1,1,1,1,1,1,1,1,1,1,1,1,1
1,1,1,1,1,1,1,1,1,1,1,1,2,1,1,1,2,1,1,1,1,1,1,1,1,1,1,1,1,1,1,1,1,1,1,1,1
1,1,1,1,1,1,1,1,1,1,1,1,2,1,1,1,2,1,1,1,1,1,1,1,1,1,1,1,1,1,1,1,1,1,1,1,1
1,1,1,1,1,1,1,1,1,1,1,1,1,1,1,1,1,1,1,1,1,1,1,1,1,1,1,1,1,1,1,1,1,1,1,1,1
1,1,1,1,1,1,1,1,1,1,1,1,1,1,1,1,1,1,1,1,1,1,1,1,1,1,1,1,1,1,1,1,1,1,1,1,1
1,1,1,1,1,1,1,1,1,1,1,1,1,1,1,1,1,1,1,1,1,1,1,1,1,1,1,1,1,1,1,1,1,1,1,1,1
1,1,1,1,1,1,1,1,1,1,1,1,1,1,1,1,1,1,1,1,1,1,1,1,1,1,1,1,1,1,1,1,1,1,1,1,1
1,1,1,1,1,1,1,1,1,1,1,1,1,1,1,1,1,1,1,1,1,1,1,1,1,1,1,1,1,1,1,1,1,1,1,1,1
1,1,1,1,1,1,1,1,1,1,1,1,1,1,1,1,1,1,1,1,1,1,1,1,1,1,1,1,1,1,1,1,1,1,1,1,1
1,1,1,1,1,1,1,1,1,1,1,1,1,1,1,1,1,1,1,1,1,1,1,1,1,1,1,1,1,1,1,1,1,1,1,1,1
1,1,1,1,1,1,1,1,1,1,1,1,1,1,1,1,1,1,1,1,1,1,1,1,1,1,1,1,1,1,1,1,1,1,1,1,1
1,1,1,1,1,1,1,1,1,1,1,1,1,1,1,1,1,1,1,1,1,1,1,1,1,1,1,1,1,1,1,1,1,1,1,1,1
1,1,1,1,1,1,1,1,1,1,1,1,1,1,1,1,1,1,1,1,1,1,1,1,1,1,1,1,1,1,1,1,1,1,1,1,1
1,1,1,1,1,1,1,1,1,1,1,1,1,1,1,1,1,1,1,1,1,1,1,1,1,1,1,1,1,1,1,1,1,1,1,1,1
1,1,1,1,1,1,1,1,1,1,1,1,1,1,1,1,1,1,1,1,1,1,1,1,1,1,1,1,1,1,1,1,1,1,1,1,1
1,1,1,1,1,1,1,1,1,1,1,1,1,1,1,1,1,1,1,1,1,1,1,1,1,1,1,1,1,1,1,1,1,1,1,1,1
1,1,1,1,1,1,1,1,1,1,1,1,1,1,1,1,1,1,1,1,1,1,1,1,1,1,1,1,1,1,1,1,1,1,1,1,1
1,1,1,1,1,1,1,1,1,1,1,1,1,1,1,1,1,1,1,1,1,1,1,1,1,1,1,1,1,1,1,1,1,1,1,1,1
1,1,1,1,1,1,1,1,1,1,1,1,2,1,1,1,2,1,1,1,1,1,1,1,1,1,1,1,1,1,1,1,1,1,1,1,1
1,1,1,1,1,1,1,1,1,1,1,1,2,1,1,1,2,1,1,1,1,1,1,1,1,1,1,1,1,1,1,1,1,1,1,1,1
1,1,1,1,1,1,1,1,1,1,1,1,1,1,1,1,1,1,1,1,1,1,1,1,1,1,1,1,1,1,1,1,1,1,1,1,1
1,1,1,1,1,1,1,1,1,1,1,1,1,1,1,1,1,1,1,1,1,2,1,1,1,2,1,1,1,1,1,1,1,1,1,1,1
1,1,1,1,1,1,1,1,1,1,1,1,1,1,1,1,1,1,1,1,1,2,1,1,1,2,1,1,1,1,1,1,1,1,1,1,1
1,1,1,1,1,1,1,1,1,1,1,1,1,1,1,1,1,1,1,1,1,1,1,1,1,1,1,1,1,1,1,1,1,1,1,1,1
1,1,1,1,1,1,1,1,1,1,1,1,1,1,1,1,1,1,1,1,1,1,1,1,1,1,1,1,1,1,1,1,1,1,1,1,1
1,1,1,1,1,1,1,1,1,1,1,1,1,1,1,1,1,1,1,1,1,1,1,1,1,1,1,1,1,1,1,1,1,1,1,1,1
:endlayer
layer: 3
1,1,1,1,1,1,1,1,1,1,1,1,1,1,1,1,1,1,1,1,1,1,1,1,1,1,1,1,1,1,1,1,1,1,1,1,1
1,1,1,1,1,1,1,1,1,1,1,1,1,1,1,1,1,1,1,1,1,1,1,1,1,1,1,1,1,1,1,1,1,1,1,1,1
1,1,1,1,1,1,1,1,1,1,1,1,1,1,1,1,1,1,1,1,1,1,1,1,1,1,1,1,1,1,1,1,1,1,1,1,1
1,1,1,1,1,1,1,1,1,1,1,1,1,1,1,1,1,1,1,1,1,1,4,4,4,1,1,1,1,1,1,1,1,1,1,1,1
1,1,1,1,1,1,1,1,1,1,1,1,1,1,1,1,1,1,1,1,1,3,4,4,4,3,1,1,1,1,1,1,1,1,1,1,1
1,1,1,1,1,1,1,1,1,1,1,1,1,1,1,1,1,1,1,1,1,3,4,4,4,3,1,1,1,1,1,1,1,1,1,1,1
1,1,1,1,1,1,1,1,1,1,1,1,1,4,4,4,1,1,1,1,1,1,4,4,4,1,1,1,1,1,1,1,1,1,1,1,1
1,1,1,1,1,1,1,1,1,1,1,1,3,4,4,4,3,1,1,1,1,1,4,4,4,1,1,1,1,1,1,1,1,1,1,1,1
1,1,1,1,1,1,1,1,1,1,1,1,3,4,4,4,3,1,1,1,1,1,1,4,1,1,1,1,1,1,1,1,1,1,1,1,1
1,1,1,1,1,1,1,1,1,1,1,1,1,4,4,4,1,1,1,1,1,1,1,1,1,1,1,1,1,1,1,1,1,1,1,1,1
1,1,1,1,1,1,1,1,1,1,1,1,1,4,4,4,1,1,1,1,1,1,1,1,1,1,1,1,1,1,1,1,1,1,1,1,1
1,1,1,1,1,1,1,1,1,1,1,1,1,1,4,1,1,1,1,1,1,1,1,1,1,1,1,1,1,1,1,1,1,1,1,1,1
1,1,1,1,1,1,1,1,1,1,1,1,1,1,1,1,1,1,1,1,1,1,1,1,1,1,1,1,1,1,1,1,1,1,1,1,1
1,1,1,1,1,1,1,1,1,1,1,1,1,1,1,1,1,1,1,1,1,1,1,1,1,1,1,1,1,1,1,1,1,1,1,1,1
1,1,1,1,1,1,1,1,1,1,1,1,1,1,1,1,1,1,1,1,1,1,1,1,1,1,1,1,1,1,1,1,1,1,1,1,1
1,1,1,1,1,1,1,1,1,1,1,1,1,1,1,1,1,1,1,1,1,1,1,1,1,1,1,1,1,1,1,1,1,1,1,1,1
1,1,1,1,1,1,1,1,1,1,1,1,1,1,1,1,1,1,1,1,1,1,1,1,1,1,1,1,1,1,1,1,1,1,1,1,1
1,1,1,1,1,1,1,1,1,1,1,1,1,1,1,1,1,1,1,1,1,1,1,1,1,1,1,1,1,1,1,1,1,1,1,1,1
1,1,1,1,1,1,1,1,1,1,1,1,1,1,1,1,1,1,1,1,1,1,1,1,1,1,1,1,1,1,1,1,1,1,1,1,1
1,1,1,1,1,1,1,1,1,1,1,1,1,1,1,1,1,1,1,1,1,1,1,1,1,1,1,1,1,1,1,1,1,1,1,1,1
1,1,1,1,1,1,1,1,1,1,1,1,1,1,1,1,1,1,1,1,1,1,1,1,1,1,1,1,1,1,1,1,1,1,1,1,1
1,1,1,1,1,1,1,1,1,1,1,1,1,1,4,1,1,1,1,1,1,1,1,1,1,1,1,1,1,1,1,1,1,1,1,1,1
1,1,1,1,1,1,1,1,1,1,1,1,1,4,4,4,1,1,1,1,1,1,1,1,1,1,1,1,1,1,1,1,1,1,1,1,1
1,1,1,1,1,1,1,1,1,1,1,1,1,4,4,4,1,1,1,1,1,1,1,1,1,1,1,1,1,1,1,1,1,1,1,1,1
1,1,1,1,1,1,1,1,1,1,1,1,3,4,4,4,3,1,1,1,1,1,1,4,1,1,1,1,1,1,1,1,1,1,1,1,1
1,1,1,1,1,1,1,1,1,1,1,1,3,4,4,4,3,1,1,1,1,1,4,4,4,1,1,1,1,1,1,1,1,1,1,1,1
1,1,1,1,1,1,1,1,1,1,1,1,1,4,4,4,1,1,1,1,1,1,4,4,4,1,1,1,1,1,1,1,1,1,1,1,1
1,1,1,1,1,1,1,1,1,1,1,1,1,1,1,1,1,1,1,1,1,3,4,4,4,3,1,1,1,1,1,1,1,1,1,1,1
1,1,1,1,1,1,1,1,1,1,1,1,1,1,1,1,1,1,1,1,1,3,4,4,4,3,1,1,1,1,1,1,1,1,1,1,1
1,1,1,1,1,1,1,1,1,1,1,1,1,1,1,1,1,1,1,1,1,1,4,4,4,1,1,1,1,1,1,1,1,1,1,1,1
1,1,1,1,1,1,1,1,1,1,1,1,1,1,1,1,1,1,1,1,1,1,1,1,1,1,1,1,1,1,1,1,1,1,1,1,1
1,1,1,1,1,1,1,1,1,1,1,1,1,1,1,1,1,1,1,1,1,1,1,1,1,1,1,1,1,1,1,1,1,1,1,1,1
:endlayer
layer: 4
1,1,1,1,1,1,1,1,1,1,1,1,1,1,1,1,1,1,1,1,1,1,1,1,1,1,1,1,1,1,1,1,1,1,1,1,1
1,1,1,1,1,1,1,1,1,1,1,1,1,1,1,1,1,1,1,1,1,1,1,1,1,1,1,1,1,1,1,1,1,1,1,1,1
1,1,1,1,1,1,1,1,1,1,1,1,1,1,1,1,1,1,1,1,1,1,5,5,5,1,1,1,1,1,1,1,1,1,1,1,1
1,1,1,1,1,1,1,1,1,1,1,1,1,1,1,1,1,1,1,1,1,5,14,9,6,5,1,1,1,1,1,1,1,1,1,1,1
1,1,1,1,1,1,1,1,1,1,1,1,1,1,1,1,1,1,1,1,5,0,0,0,0,0,5,1,1,1,1,1,1,1,1,1,1
1,1,1,1,1,1,1,1,1,1,1,1,1,5,5,5,1,1,1,1,5,0,15,10,0,0,5,1,1,1,1,1,1,1,1,1,1
1,1,1,1,1,1,1,1,1,1,1,1,5,23,9,17,5,1,1,1,1,5,0,11,0,5,1,1,1,1,1,1,1,1,1,1,1
1,1,1,1,1,1,1,1,1,1,1,5,0,0,0,0,0,5,1,1,1,5,0,0,0,5,1,1,1,1,1,1,1,1,1,1,1
1,1,1,1,1,1,1,1,1,1,1,5,0,24,10,18,0,5,1,1,1,5,5,0,5,5,1,1,1,1,1,1,1,1,1,1,1
1,1,1,1,1,1,1,1,1,1,1,1,5,0,21,0,5,1,1,1,1,1,1,4,1,1,1,1,1,1,1,1,1,1,1,1,1
1,1,1,1,1,1,1,1,1,1,1,1,5,0,0,0,5,1,1,1,1,1,1,1,1,1,1,1,1,1,1,1,1,1,1,1,1
1,1,1,1,1,1,1,1,1,1,1,1,5,5,0,5,5,1,1,1,1,1,1,1,1,1,1,1,1,1,1,1,1,1,1,1,1
1,1,1,1,1,1,1,1,1,1,1,1,1,1,4,1,1,1,1,1,1,1,1,1,1,1,1,1,1,1,1,1,1,1,1,1,1
1,1,1,1,1,1,1,1,1,1,1,1,1,1,1,1,1,1,1,1,1,1,1,1,1,1,1,1,1,1,1,1,1,1,1,1,1
1,1,1,1,1,1,1,1,1,1,1,1,1,1,1,1,1,1,1,1,1,1,1,1,1,1,1,1,1,1,1,1,1,1,1,1,1
1,1,1,1,1,1,1,1,1,1,1,1,1,1,1,1,1,1,1,1,1,1,1,1,1,1,1,1,1,1,1,1,1,1,1,1,1
1,1,1,2,2,1,1,1,1,1,1,1,1,1,1,1,1,1,1,1,1,1,1,1,1,1,1,1,1,1,1,1,1,1,1,1,1
1,1,1,1,1,1,1,1,1,1,1,1,1,1,1,1,1,1,1,1,1,1,1,1,1,1,1,1,1,1,1,1,1,1,1,1,1
1,1,1,1,1,1,1,1,1,1,1,1,1,1,1,1,1,1,1,1,1,1,1,1,1,1,1,1,1,1,1,1,1,1,1,1,1
1,1,1,1,1,1,1,1,1,1,1,1,1,1,2,1,1,1,1,1,1,1,1,1,1,1,1,1,1,1,1,1,1,1,1,1,1
1,1,1,1,1,1,1,1,1,1,1,1,1,1,4,1,1,1,1,1,1,1,1,1,1,1,1,1,1,1,1,1,1,1,1,1,1
1,1,1,1,1,1,1,1,1,1,1,1,5,5,0,5,5,1,1,1,1,1,1,1,1,1,1,1,1,1,1,1,1,1,1,1,1
1,1,1,1,1,1,1,1,1,1,1,1,5,0,0,0,5,1,1,1,1,1,1,1,1,1,1,1,1,1,1,1,1,1,1,1,1
1,1,1,1,1,1,1,1,1,1,1,1,5,0,22,0,5,1,1,1,1,1,1,4,1,1,1,1,1,1,1,1,1,1,1,1,1
1,1,1,1,1,1,1,1,1,1,1,5,0,25,10,19,0,5,1,1,1,5,5,0,5,5,1,1,1,1,1,1,1,1,1,1,1
1,1,1,1,1,1,1,1,1,1,1,5,0,0,0,0,0,5,1,1,1,5,0,0,0,5,1,1,1,1,1,1,1,1,1,1,1
1,1,1,1,1,1,1,1,1,1,1,1,5,26,9,20,5,1,1,1,1,5,0,12,0,5,1,1,1,1,1,1,1,1,1,1,1
1,1,1,1,1,1,1,1,1,1,1,1,1,5,5,5,1,1,1,1,5,0,16,10,7,0,5,1,1,1,1,1,1,1,1,1,1
1,1,1,1,1,1,1,1,1,1,1,1,1,1,1,1,1,1,1,1,5,0,0,0,0,0,5,1,1,1,1,1,1,1,1,1,1
1,1,1,1,1,1,1,1,1,1,1,1,1,1,1,1,1,1,1,1,1,5,9,13,8,5,1,1,1,1,1,1,1,1,1,1,1
1,1,1,1,1,1,1,1,1,1,1,1,1,1,1,1,1,1,1,1,1,1,5,5,5,1,1,1,1,1,1,1,1,1,1,1,1
1,1,1,1,1,1,1,1,1,1,1,1,1,1,1,1,1,1,1,1,1,1,1,1,1,1,1,1,1,1,1,1,1,1,1,1,1
:endlayer
layer: 5
2,2,2,2,2,2,2,2,2,2,2,2,2,2,2,2,2,2,2,2,2,2,2,2,2,2,2,2,2,2,2,2,2,2,2,2,2
2,2,2,2,2,2,2,2,2,2,2,2,2,2,2,2,2,2,2,2,2,2,2,2,2,2,2,2,2,2,2,2,2,2,2,2,2
2,2,1,1,2,2,2,2,2,2,2,2,2,2,2,2,2,2,2,2,2,2,5,5,5,2,2,2,2,1,1,2,2,2,2,2,2
2,2,1,1,2,2,2,2,2,1,1,2,2,2,2,2,2,2,2,2,2,5,0,0,0,5,2,2,2,1,1,2,2,2,2,1,2
2,2,2,2,2,1,1,2,2,1,1,2,2,2,2,2,2,2,1,1,5,0,0,0,0,0,5,2,2,2,2,2,2,2,2,2,2
2,2,2,2,2,1,1,2,2,2,2,2,2,5,5,5,2,2,1,1,5,0,0,10,0,0,5,2,2,2,2,2,2,2,2,2,2
2,2,2,2,2,2,2,2,2,2,2,2,5,0,0,0,5,2,2,2,2,5,0,0,0,5,2,2,2,2,2,2,2,27,2,2,2
2,2,2,1,1,2,2,1,1,2,2,5,0,0,0,0,0,5,2,2,2,5,0,0,0,5,2,2,2,2,2,27,2,2,2,2,2
2,2,2,1,1,2,2,1,1,2,2,5,0,0,10,0,0,5,2,2,2,5,5,0,5,5,2,2,2,2,2,2,27,27,2,2,2
2,2,2,2,2,2,2,2,2,2,2,2,5,0,0,0,5,2,2,2,2,2,2,0,2,2,2,2,2,2,2,2,27,2,2,2,2
2,2,2,2,2,1,1,2,2,2,2,2,5,0,0,0,5,2,2,2,2,2,27,2,2,2,2,2,2,2,2,27,2,2,2,2,2
2,2,2,2,1,1,1,1,2,2,2,2,5,5,0,5,5,2,2,2,2,2,2,27,29,29,27,27,2,2,2,2,2,27,2,2,2
2,2,2,1,1,1,1,1,1,1,1,2,2,2,0,2,2,2,2,27,2,2,2,27,28,27,29,2,2,2,2,2,2,2,2,2,2
2,1,1,1,1,1,1,1,1,1,1,2,2,2,2,2,2,27,29,27,27,28,28,27,27,28,2,28,27,2,2,2,2,2,2,2,2
2,1,1,1,1,4,4,4,1,1,1,2,2,29,28,2,2,28,28,2,2,2,29,27,28,1,1,1,2,2,2,2,2,1,1,2,2
2,1,1,4,4,4,4,4,1,1,1,2,2,28,27,29,27,28,2,1,1,1,2,28,1,28,30,1,2,2,2,2,2,1,1,2,2
2,1,1,3,3,4,4,4,4,4,4,28,29,27,27,27,28,29,1,31,1,1,2,28,28,28,28,1,2,2,2,2,2,2,2,2,2
2,1,1,4,4,4,4,4,1,1,1,2,2,27,27,27,29,28,2,1,1,1,2,27,27,27,1,27,2,2,2,2,2,2,2,2,2
2,1,1,1,1,4,4,4,1,1,1,1,2,27,2,2,2,28,29,2,2,2,28,27,2,27,2,27,2,2,2,2,2,1,1,2,2
2,1,1,1,1,1,1,1,1,1,1,1,2,2,0,2,2,29,28,29,28,29,28,27,27,27,27,27,2,2,2,2,2,1,1,2,2
2,2,1,1,1,1,1,1,1,2,2,2,2,2,0,2,2,2,2,2,2,2,2,27,2,28,29,28,2,2,2,2,2,2,2,2,2
2,2,2,2,1,1,1,1,2,2,2,2,5,5,0,5,5,2,2,2,2,2,2,29,28,27,2,2,2,2,27,2,2,2,2,2,2
2,2,2,2,2,2,2,2,2,2,2,2,5,0,0,0,5,2,2,2,2,2,2,2,2,2,2,2,2,2,2,2,27,2,2,2,2
2,2,2,2,2,2,2,1,1,2,2,2,5,0,0,0,5,2,2,2,2,2,2,0,2,2,2,2,2,2,2,27,2,2,2,2,2
2,2,2,1,1,2,2,1,1,2,2,5,0,0,10,0,0,5,2,2,2,5,5,0,5,5,1,1,2,2,27,27,2,2,1,1,2
2,2,2,1,1,2,2,2,2,2,2,5,0,0,0,0,0,5,2,2,2,5,0,0,0,5,1,1,2,2,2,2,27,2,1,1,2
2,2,2,2,2,2,2,2,2,2,2,2,5,0,0,0,5,2,2,2,2,5,0,0,0,5,2,2,2,2,27,2,2,2,2,2,2
2,2,2,2,2,2,2,2,2,2,2,2,2,5,5,5,2,2,2,2,5,0,0,10,0,0,5,2,2,2,2,2,2,2,2,2,2
2,2,1,1,2,2,1,1,2,2,2,2,2,2,2,2,2,2,2,2,5,0,0,0,0,0,5,2,2,2,2,2,2,2,2,2,2
2,2,1,1,2,2,1,1,2,2,2,2,1,1,2,2,2,1,1,2,2,5,0,0,0,5,2,2,2,2,2,2,2,1,1,2,2
2,2,2,2,2,2,2,2,2,2,2,2,1,1,2,2,2,1,1,2,2,2,5,5,5,2,2,2,2,2,2,2,2,1,1,2,2
2,2,2,2,2,2,2,2,2,2,2,2,2,2,2,2,2,2,2,2,2,2,2,2,2,2,2,2,2,2,2,2,2,2,2,2,2
:endlayer
layer: 6
0,0,0,0,0,0,0,0,0,0,0,0,0,0,0,0,0,0,0,0,0,0,0,0,0,0,0,0,0,0,0,0,0,0,0,0,0
0,0,0,0,0,32,0,0,0,0,0,0,32,32,32,32,0,0,0,0,0,0,0,0,0,0,0,0,0,0,0,32,32,32,0,0,0
0,0,33,33,0,0,0,0,0,0,32,32,32,32,32,32,0,0,0,0,32,10,10,10,10,10,32,0,32,33,33,32,32,32,32,0,0
32,0,33,33,32,32,0,32,0,33,33,0,32,32,32,0,0,0,0,0,10,10,0,0,0,10,10,0,0,33,33,32,32,32,32,33,0
0,32,32,0,32,33,33,32,32,33,33,0,0,0,0,0,0,0,33,33,10,0,0,0,0,0,10,0,0,0,0,32,32,0,0,0,0
32,32,32,0,32,33,33,32,32,32,32,32,10,10,10,10,10,32,33,33,10,0,0,10,0,0,10,0,32,0,10,10,10,10,10,0,0
32,0,32,0,32,32,32,32,0,32,0,10,10,0,0,0,10,10,0,0,10,10,0,0,0,10,10,0,0,0,10,0,0,0,10,0,0
32,0,0,33,33,32,0,33,33,0,0,10,0,0,0,0,0,10,0,0,32,10,0,0,0,10,32,0,0,0,10,0,0,0,10,0,0
32,0,0,33,33,32,32,33,33,0,0,10,0,0,10,0,0,10,0,0,32,10,5,0,5,10,32,0,0,0,10,0,0,0,10,32,0
0,0,0,0,0,32,0,32,0,0,0,10,10,0,0,0,10,10,0,0,0,32,10,0,10,0,32,0,0,0,10,0,0,0,10,32,0
0,0,0,0,32,1,1,0,0,0,0,32,10,0,0,0,10,32,0,0,0,0,0,0,0,0,0,0,32,0,10,0,0,0,10,32,32
0,0,0,0,2,1,1,2,0,0,0,32,10,5,0,5,10,32,0,0,0,0,0,0,0,0,0,0,32,0,10,0,0,0,10,32,32
0,0,0,2,2,2,2,2,2,33,33,0,32,10,0,10,32,32,0,0,0,0,0,0,0,0,0,0,32,0,10,10,34,10,10,32,0
0,2,2,2,28,28,28,28,2,33,33,0,0,0,0,0,0,0,0,0,0,0,0,0,0,0,37,0,0,0,0,0,32,0,0,32,0
0,2,2,28,28,44,43,9,28,2,2,0,0,0,0,0,0,0,40,37,37,37,40,0,0,29,28,29,0,0,0,0,0,33,33,32,0
0,2,28,0,0,45,0,41,28,2,2,0,0,0,0,0,0,0,37,28,29,28,37,39,37,28,38,28,37,0,0,32,32,33,33,32,0
0,2,28,0,0,10,0,0,0,0,0,0,0,0,0,0,0,0,37,28,28,28,37,0,0,29,28,28,0,0,0,35,0,32,32,0,32
0,2,28,0,0,46,0,0,28,2,2,0,0,0,0,0,0,0,37,28,28,28,37,0,0,0,37,0,0,0,0,0,32,32,32,0,32
0,33,1,28,29,47,0,42,28,2,33,33,0,0,0,0,0,0,40,37,37,37,40,0,0,0,0,0,0,0,0,0,0,33,33,0,32
0,33,1,2,28,28,28,28,2,2,33,33,0,0,0,0,0,0,0,0,0,0,0,0,0,0,0,0,0,0,0,32,0,33,33,0,32
0,0,33,2,2,2,2,2,2,0,0,32,32,10,0,10,32,0,0,0,0,0,0,0,0,0,0,0,0,10,10,36,10,10,32,32,32
0,0,0,0,2,2,2,2,0,0,0,32,10,5,0,5,10,32,0,0,0,0,0,0,0,0,0,0,0,10,0,0,0,10,0,32,32
0,0,0,0,32,0,0,32,0,0,0,32,10,0,0,0,10,0,0,0,0,0,0,0,0,0,0,0,0,10,0,0,0,10,0,32,0
32,32,0,32,0,0,0,33,33,0,0,10,10,0,0,0,10,10,0,0,32,32,10,0,10,32,0,0,0,10,0,0,0,10,0,32,0
32,32,0,33,33,32,0,33,33,0,0,10,0,0,10,0,0,10,0,0,32,10,5,0,5,10,33,33,0,10,0,0,0,10,33,33,0
32,32,32,33,33,32,32,0,32,0,0,10,0,0,0,0,0,10,0,0,0,10,0,0,0,10,33,33,0,10,0,0,0,10,33,33,0
0,32,32,32,32,0,0,0,0,0,0,10,10,0,0,0,10,10,0,0,10,10,0,0,0,10,10,0,0,10,0,0,0,10,0,0,0
0,32,0,32,0,32,0,0,0,0,0,32,10,10,10,10,10,32,0,0,10,0,0,10,0,0,10,0,0,10,10,10,10,10,0,32,0
0,32,33,33,0,0,33,33,0,32,32,0,0,0,0,32,32,32,0,0,10,0,0,0,0,0,10,0,0,0,0,32,32,0,0,0,0
0,0,33,33,0,0,33,33,32,32,0,32,33,33,0,32,32,33,33,0,10,10,0,0,0,10,10,0,0,32,32,32,32,33,33,0,0
0,0,0,32,0,0,0,32,0,32,32,32,33,33,32,32,32,33,33,32,32,10,10,10,10,10,32,0,0,32,32,32,32,33,33,0,0
0,0,0,0,0,0,0,0,0,0,32,0,0,0,32,32,0,32,0,0,0,0,0,0,0,0,0,0,0,0,32,32,32,0,0,0,0
:endlayer
layer: 7
0,0,0,0,0,0,0,0,0,0,0,0,0,0,0,0,0,0,0,0,0,0,0,0,0,0,0,0,0,0,0,0,0,0,0,0,0
0,0,0,0,0,0,0,0,0,0,0,0,0,0,0,0,0,0,0,0,0,0,0,0,0,0,0,0,0,0,0,0,0,0,0,0,0
0,0,33,33,0,0,0,0,0,0,0,0,0,0,0,0,0,0,0,0,0,5,5,5,5,5,0,0,0,33,33,0,0,0,0,0,0
0,0,33,33,0,0,0,0,0,33,33,0,0,0,0,0,0,0,0,0,59,5,0,0,0,5,48,0,0,33,33,0,0,0,0,33,0
0,0,0,0,0,33,33,0,0,33,33,0,0,0,0,0,0,0,33,33,5,49,0,0,0,49,5,0,0,0,0,0,0,0,0,0,0
0,0,0,0,0,33,33,0,0,0,0,0,5,5,5,5,5,0,33,33,5,0,0,10,0,0,5,0,0,0,10,0,10,0,10,0,0
0,0,0,0,0,0,0,0,0,0,0,59,5,0,0,0,5,48,0,0,59,5,0,0,0,5,48,0,0,0,10,0,0,0,10,0,0
0,0,0,33,33,0,0,33,33,0,0,5,49,0,0,0,49,5,0,0,0,5,0,0,0,5,0,0,0,0,10,0,0,0,10,0,0
0,0,0,33,33,0,0,33,33,0,0,5,0,0,10,0,0,5,0,0,0,5,5,53,5,5,0,0,0,0,0,0,0,0,0,0,0
0,0,0,0,0,0,0,0,0,0,0,59,5,0,0,0,5,48,0,0,0,0,55,0,51,0,0,0,0,0,0,0,0,0,0,0,0
0,0,0,0,0,33,33,0,0,0,0,0,5,0,0,0,5,0,0,0,0,0,0,0,0,0,0,0,0,0,0,0,0,0,0,0,0
0,0,0,0,32,33,33,0,0,0,0,0,5,5,53,5,5,0,0,0,0,0,0,0,0,0,0,0,0,0,0,0,0,0,0,0,0
0,0,0,0,32,32,32,0,0,33,33,0,0,62,0,60,0,0,0,0,0,0,0,0,0,0,0,0,0,0,10,0,0,0,10,0,0
0,0,32,32,28,28,29,28,64,33,33,0,0,0,0,0,0,0,0,0,0,0,0,0,0,0,0,0,0,0,0,0,33,0,0,0,0
0,0,32,29,28,0,0,0,28,32,0,0,0,0,0,0,0,0,56,0,0,0,56,0,0,0,40,0,0,0,0,0,0,33,33,0,0
0,0,28,0,0,0,0,0,29,0,0,0,0,0,0,0,0,0,0,40,0,40,0,0,0,40,0,40,0,0,0,0,0,33,33,0,0
0,0,28,0,0,10,0,0,0,0,0,0,0,0,0,0,0,0,0,0,29,58,0,0,0,0,40,0,0,0,0,0,0,0,0,0,0
0,0,28,0,0,0,0,0,28,32,0,0,0,0,0,0,0,0,0,40,0,40,0,0,0,0,0,0,0,0,0,0,0,0,0,0,0
0,33,33,28,29,0,0,0,28,32,33,33,0,0,0,0,0,0,56,0,0,0,56,0,0,0,0,0,0,0,0,0,0,33,33,0,0
0,33,33,0,28,28,28,28,65,32,33,33,0,0,0,0,0,0,0,0,0,0,0,0,0,0,0,0,0,0,0,0,0,33,33,0,0
0,0,33,32,0,32,32,32,32,0,0,0,0,63,0,61,0,0,0,0,0,0,0,0,0,0,0,0,0,10,0,0,0,10,0,0,0
0,0,0,0,32,0,32,32,0,0,0,0,5,5,54,5,5,0,0,0,0,0,0,0,0,0,0,0,0,0,0,0,0,0,0,0,0
0,0,0,0,0,0,0,0,0,0,0,0,5,0,0,0,5,0,0,0,0,0,0,0,0,0,0,0,0,0,0,0,0,0,0,0,0
0,0,0,0,0,0,0,33,33,0,0,59,5,0,0,0,5,48,0,0,0,0,57,0,52,0,0,0,0,0,0,0,0,0,0,0,0
0,0,0,33,33,0,0,33,33,0,0,5,0,0,10,0,0,5,0,0,0,5,5,54,5,5,33,33,0,0,0,0,0,0,33,33,0
0,0,0,33,33,0,0,0,0,0,0,5,50,0,0,0,50,5,0,0,0,5,0,0,0,5,33,33,0,10,0,0,0,10,33,33,0
0,0,0,0,0,0,0,0,0,0,0,59,5,0,0,0,5,48,0,0,59,5,0,0,0,5,48,0,0,10,0,0,0,10,0,0,0
0,0,0,0,0,0,0,0,0,0,0,0,5,5,5,5,5,0,0,0,5,0,0,10,0,0,5,0,0,10,0,10,0,10,0,0,0
0,0,33,33,0,0,33,33,0,0,0,0,0,0,0,0,0,0,0,0,5,50,0,0,0,50,5,0,0,0,0,0,0,0,0,0,0
0,0,33,33,0,0,33,33,0,0,0,0,33,33,0,0,0,33,33,0,59,5,0,0,0,5,48,0,0,0,0,0,0,33,33,0,0
0,0,0,0,0,0,0,0,0,0,0,0,33,33,0,0,0,33,33,0,0,5,5,5,5,5,0,0,0,0,0,0,0,33,33,0,0
0,0,0,0,0,0,0,0,0,0,0,0,0,0,0,0,0,0,0,0,0,0,0,0,0,0,0,0,0,0,0,0,0,0,0,0,0
:endlayer
layer: 8
0,0,0,0,0,0,0,0,0,0,0,0,0,0,0,0,0,0,0,0,0,0,0,0,0,0,0,0,0,0,0,0,0,0,0,0,0
0,0,0,0,0,0,0,0,0,0,0,0,0,0,0,0,0,0,0,0,0,0,0,0,0,0,0,0,33,0,0,33,0,0,0,0,0
0,0,33,33,0,0,0,0,0,0,0,0,0,0,0,0,0,0,0,0,0,10,3,3,3,10,0,0,0,33,33,0,0,0,0,67,0
0,0,33,33,0,33,0,0,0,33,33,33,0,0,0,0,0,0,0,0,10,3,3,74,3,3,10,0,0,33,33,0,0,0,67,33,66
0,0,0,0,0,33,33,0,0,33,33,0,0,0,0,0,0,0,33,33,3,3,74,74,74,3,3,0,0,33,0,0,0,0,0,66,0
0,0,0,0,0,33,33,0,0,0,0,0,10,3,3,3,10,0,33,33,3,3,74,5,74,3,3,0,0,0,5,5,5,70,5,0,0
0,0,0,0,0,0,0,33,0,0,0,10,3,3,74,3,3,10,0,0,10,3,3,74,3,3,10,0,0,0,68,68,68,68,68,0,0
0,0,0,33,33,0,0,33,33,0,0,3,3,74,74,74,3,3,0,0,0,3,3,3,3,3,0,0,0,0,3,3,3,3,3,0,0
0,0,0,33,33,0,0,33,33,0,0,3,3,74,5,74,3,3,0,0,0,10,3,10,3,10,0,0,0,0,0,0,0,0,0,0,0
0,0,0,0,0,0,0,0,0,0,0,10,3,3,74,3,3,10,0,0,0,0,0,0,0,0,0,0,0,0,0,0,0,0,0,0,0
0,0,0,0,0,33,33,0,0,0,0,0,3,3,3,3,3,0,0,0,0,0,0,0,0,0,0,0,0,0,0,0,0,0,0,0,0
0,0,0,0,0,33,33,0,0,0,0,0,10,3,10,3,10,0,0,0,0,0,0,0,0,0,0,0,0,0,0,0,0,0,0,0,0
0,0,0,0,0,0,0,0,0,33,33,0,0,0,0,0,0,0,0,0,0,0,0,0,0,0,0,0,0,0,72,0,0,0,69,0,0
0,0,0,81,28,10,10,28,81,33,33,0,0,0,0,0,0,0,0,0,0,0,0,0,0,0,0,0,0,0,0,0,33,0,0,0,0
0,0,81,28,83,0,0,0,29,0,0,0,0,0,0,0,0,0,0,0,0,0,0,0,0,0,40,0,0,0,0,0,0,33,33,33,0
0,0,29,85,0,0,0,0,28,0,0,0,0,0,0,0,0,0,0,78,0,75,0,0,0,40,47,40,0,0,0,0,0,33,33,0,0
0,0,10,0,0,10,0,0,82,80,0,0,0,0,0,0,0,0,0,0,77,0,0,0,0,0,40,0,0,0,0,0,0,0,0,0,0
0,0,28,85,0,0,0,0,28,0,0,0,0,0,0,0,0,0,0,79,0,76,0,0,0,0,0,0,0,0,0,0,0,0,33,0,0
0,33,33,29,84,0,0,0,29,0,33,33,0,0,0,0,0,0,0,0,0,0,0,0,0,0,0,0,0,0,0,0,0,33,33,0,0
0,33,33,81,28,10,10,29,81,0,33,33,0,0,0,0,0,0,0,0,0,0,0,0,0,0,0,0,0,0,0,0,0,33,33,33,0
0,0,0,0,0,0,0,0,0,0,0,0,0,0,0,0,0,0,0,0,0,0,0,0,0,0,0,0,0,73,0,0,0,0,0,0,0
0,0,0,0,0,0,0,0,0,0,0,0,10,3,10,3,10,0,0,0,0,0,0,0,0,0,0,0,0,0,0,0,0,0,0,0,0
0,0,0,0,0,0,0,0,0,0,0,0,3,3,3,3,3,0,0,0,0,0,0,0,0,0,0,0,0,0,0,0,0,0,0,0,0
0,0,0,0,33,0,0,33,33,0,0,10,3,3,74,3,3,10,0,0,0,0,0,0,0,0,0,0,0,0,0,0,0,0,0,0,0
0,0,0,33,33,0,0,33,33,0,0,3,3,74,5,74,3,3,0,0,0,10,3,10,3,10,33,33,0,0,0,0,0,0,33,33,0
0,0,0,33,33,0,0,0,0,0,0,3,3,74,74,74,3,3,0,0,0,3,3,3,3,3,33,33,0,3,3,3,3,3,33,33,0
0,0,0,0,0,0,0,0,0,0,0,10,3,3,74,3,3,10,0,0,10,3,3,74,3,3,10,0,0,71,71,71,71,71,0,0,0
0,0,0,0,0,0,33,0,0,0,0,0,10,3,3,3,10,0,0,0,3,3,74,5,74,3,3,0,0,5,70,5,5,5,0,0,0
0,0,33,33,0,0,33,33,0,0,0,33,0,0,0,0,0,0,0,0,3,3,74,74,74,3,3,0,0,0,0,0,0,0,0,0,0
0,0,33,33,0,33,33,33,0,0,0,0,33,33,0,0,0,33,33,0,10,3,3,74,3,3,10,0,0,0,0,0,33,33,33,0,0
0,0,0,0,0,0,0,0,33,0,0,0,33,33,0,0,0,33,33,0,0,10,3,3,3,10,0,0,0,0,0,0,0,33,33,0,0
0,0,0,0,0,0,0,0,0,0,0,0,0,0,0,0,0,0,0,0,0,0,0,0,0,0,0,0,0,0,0,0,0,0,0,33,0
:endlayer
layer: 9
0,0,0,0,0,0,0,0,0,0,0,0,0,0,0,0,0,0,0,0,0,0,0,0,0,0,0,0,0,0,0,0,0,0,0,0,0
0,0,0,33,0,0,0,0,0,0,0,0,0,0,0,0,0,0,0,0,0,0,0,0,0,0,0,0,33,0,0,33,0,0,0,0,0
0,0,33,33,0,0,0,0,0,0,0,0,0,0,0,0,0,0,0,0,0,97,0,0,0,91,0,0,0,33,33,33,0,0,0,0,0
0,0,33,33,33,33,33,33,0,33,33,33,0,0,0,0,0,0,0,0,101,0,0,0,0,0,87,0,0,33,33,0,0,0,0,66,0
0,0,0,0,0,33,33,0,0,33,33,0,0,0,0,0,0,0,33,33,0,0,0,95,0,0,0,0,0,33,0,0,0,0,0,0,0
0,0,0,0,0,33,33,0,0,0,0,0,115,0,0,0,110,0,33,33,0,0,0,5,0,0,0,0,0,0,0,10,0,0,10,0,0
0,0,0,0,0,33,0,33,0,0,0,119,0,0,0,0,0,106,0,0,102,0,0,0,0,0,88,0,0,0,0,0,0,0,0,0,0
0,0,0,33,33,0,0,33,33,0,0,0,0,0,0,0,0,0,0,0,0,0,0,0,0,0,0,0,0,0,0,0,0,0,0,0,0
0,0,0,33,33,0,0,33,33,0,0,0,0,0,5,0,0,0,0,0,0,98,0,10,0,92,0,0,0,0,0,0,0,0,0,0,0
0,0,0,0,0,0,0,0,0,0,0,120,0,0,0,0,0,107,0,0,0,0,0,0,0,0,0,0,0,0,0,0,0,0,0,0,0
0,0,0,0,0,33,33,0,0,0,0,0,0,0,0,0,0,0,0,0,0,0,0,0,0,0,0,0,0,0,0,0,0,0,0,0,0
0,0,0,0,0,33,33,0,0,0,0,0,116,0,10,0,111,0,0,0,0,0,0,0,0,0,0,0,0,0,0,0,0,0,0,0,0
0,0,0,0,0,0,0,0,0,33,33,0,0,0,0,0,0,0,0,0,0,0,0,0,0,0,0,0,0,0,0,0,0,0,0,0,0
0,0,0,0,3,54,54,29,0,33,33,0,0,0,0,0,0,0,0,0,0,0,0,0,0,0,0,0,0,0,0,0,33,0,0,33,0
0,0,0,28,81,81,81,81,3,0,0,0,0,0,0,0,0,0,0,0,0,0,0,0,0,40,40,40,0,0,0,0,0,33,33,33,0
0,0,3,81,0,0,0,81,3,0,0,0,0,0,0,0,0,0,0,0,0,0,0,0,0,40,0,40,0,0,0,0,0,33,33,0,0
0,0,59,81,0,10,0,81,123,0,0,0,0,0,0,0,0,0,0,0,103,0,0,0,0,40,40,40,0,0,0,0,0,0,0,0,0
0,0,3,81,0,0,0,81,3,0,0,0,0,0,0,0,0,0,0,0,0,0,0,0,0,0,0,0,0,0,0,0,33,0,33,0,0
0,33,33,29,81,81,81,81,3,0,33,33,0,0,0,0,0,0,0,0,0,0,0,0,0,0,0,0,0,0,0,0,0,33,33,33,0
0,33,33,0,3,53,53,28,0,0,33,33,0,0,0,0,0,0,0,0,0,0,0,0,0,0,0,0,0,0,0,0,0,33,0,33,0
0,0,0,0,0,0,0,0,0,0,0,0,0,0,0,0,0,0,0,0,0,0,0,0,0,0,0,0,0,0,0,0,0,0,0,0,0
0,0,0,0,0,0,0,0,0,0,0,0,117,0,10,0,112,0,0,0,0,0,0,0,0,0,0,0,0,0,0,0,0,0,0,0,0
0,0,0,0,0,0,33,0,0,0,0,0,0,0,0,0,0,0,0,0,0,0,0,0,0,0,0,0,0,0,0,0,0,0,0,0,0
0,0,0,0,33,0,0,33,33,0,0,121,0,0,114,0,0,108,0,0,0,0,0,0,0,0,0,0,0,0,0,0,0,0,0,0,0
0,0,0,33,33,0,0,33,33,0,0,0,0,0,5,0,0,0,0,0,0,99,0,10,0,93,33,33,0,0,0,0,0,0,33,33,0
0,0,33,33,33,0,0,0,0,0,0,0,0,0,0,0,0,0,0,0,0,0,0,0,0,0,33,33,0,0,0,0,0,0,33,33,0
0,0,33,0,0,0,0,0,0,0,0,122,0,0,0,0,0,109,0,0,104,0,0,0,0,0,89,0,0,0,0,0,0,0,0,0,0
0,0,33,0,0,0,33,0,0,0,0,0,118,0,0,0,113,0,0,0,0,0,0,5,0,0,0,0,0,10,86,0,10,0,0,0,0
0,0,33,33,0,0,33,33,0,0,0,33,0,0,0,0,33,0,0,33,0,0,0,96,0,0,0,0,0,0,0,0,0,0,0,0,0
0,0,33,33,0,33,33,33,0,0,0,0,33,33,0,0,0,33,33,33,105,0,0,0,0,0,90,0,0,0,0,0,33,33,33,33,0
0,0,0,33,0,0,0,0,33,0,0,33,33,33,0,0,0,33,33,0,0,100,0,0,0,94,0,0,0,0,0,0,0,33,33,0,0
0,0,0,0,0,0,0,0,0,0,0,0,0,0,0,0,33,0,0,33,0,0,0,0,0,0,0,0,0,0,0,0,0,0,0,33,0
:endlayer
layer: 10
0,0,0,0,0,0,0,0,0,0,0,0,0,0,0,0,0,0,0,0,0,0,0,0,0,0,0,0,0,0,0,0,0,0,0,0,0
0,33,0,33,0,0,0,0,0,0,0,0,0,0,0,0,0,0,0,0,0,0,0,0,0,0,0,0,33,0,0,33,0,0,0,0,0
0,0,33,33,0,0,0,0,33,0,33,0,0,0,0,0,0,0,0,0,0,0,0,0,0,0,0,0,33,33,33,33,0,0,0,0,0
0,0,33,33,33,33,33,33,0,33,33,33,0,0,0,0,0,0,0,0,0,0,0,0,0,0,0,0,0,33,33,0,0,0,0,0,0
0,0,0,0,0,0,33,33,0,33,33,0,0,0,0,0,0,0,33,33,0,0,0,0,0,0,0,0,33,33,0,0,0,0,0,0,0
0,0,0,0,0,0,33,33,0,0,33,0,0,0,0,0,0,0,33,33,0,0,0,10,0,0,0,0,0,0,0,10,0,0,125,0,0
0,0,0,0,0,33,33,33,0,0,0,0,0,0,0,0,0,0,0,0,0,0,0,0,0,0,0,0,0,0,0,0,66,0,0,0,0
0,0,0,33,33,0,0,33,33,0,0,0,0,0,0,0,0,0,0,0,0,0,0,0,0,0,0,0,0,0,0,66,66,66,0,0,0
0,0,0,33,33,33,0,33,33,0,0,0,0,0,10,0,0,0,0,0,0,0,0,127,0,0,0,0,0,0,0,66,66,66,0,0,0
0,0,0,0,0,0,0,0,0,0,0,0,0,0,0,0,0,0,0,0,0,0,0,0,0,0,0,0,0,0,67,67,67,66,0,0,0
0,0,0,0,0,33,33,33,0,0,0,0,0,0,0,0,0,0,0,0,0,0,0,0,0,0,0,0,0,0,67,124,124,124,124,124,124
0,0,0,0,0,33,33,0,0,0,0,0,0,0,129,0,0,0,0,0,0,0,0,0,0,0,0,0,0,0,124,124,124,124,124,124,124
0,0,0,0,0,0,0,0,0,33,33,0,0,0,0,0,0,0,0,0,0,0,0,0,0,0,0,0,0,0,124,124,124,124,124,124,124
0,0,0,0,0,0,0,10,0,33,33,0,0,0,0,0,0,0,0,0,0,0,0,0,0,0,0,0,0,0,124,124,33,33,33,33,124
0,0,0,10,0,0,0,0,0,0,0,0,0,0,0,0,0,0,0,0,0,0,0,0,0,40,40,40,0,0,0,124,124,33,33,33,124
0,0,0,0,3,71,3,0,0,0,0,0,0,0,0,0,0,0,0,0,0,0,0,0,0,40,0,40,0,0,0,124,124,124,124,124,124
0,0,0,0,133,28,132,0,131,0,0,0,0,0,0,0,0,0,0,0,103,0,0,0,0,40,40,40,0,0,0,124,124,124,124,124,124
0,0,0,0,3,68,3,0,0,0,0,0,0,0,0,0,0,0,0,0,0,0,0,0,0,0,0,0,0,0,0,0,33,0,33,0,0
0,33,33,10,0,0,0,0,0,0,33,33,0,0,0,0,0,0,0,0,0,0,0,0,0,0,0,0,0,0,0,0,0,33,33,33,0
0,33,33,0,0,0,0,10,0,0,33,33,0,0,0,0,0,0,0,0,0,0,0,0,0,0,0,0,0,0,0,0,33,33,33,33,0
0,0,0,0,0,0,0,0,0,0,0,0,0,0,0,0,0,0,0,0,0,0,0,0,0,0,0,0,0,0,0,0,0,0,0,0,0
0,0,0,0,0,0,0,0,0,0,0,0,0,0,130,0,0,0,0,0,0,0,0,0,0,0,0,0,0,0,0,0,0,0,0,0,0
0,0,0,0,0,0,33,33,0,0,0,0,0,0,0,0,0,0,0,0,0,0,0,0,0,0,0,0,0,0,0,0,0,0,0,0,0
0,0,0,0,33,0,0,33,33,0,0,0,0,0,0,0,0,0,0,0,0,0,0,0,0,0,0,0,0,0,0,0,0,0,0,0,0
0,0,0,0,33,33,0,33,33,0,0,0,0,0,10,0,0,0,0,0,0,0,0,128,0,0,33,33,0,0,0,0,0,0,33,33,0
0,0,33,0,33,33,0,0,33,0,0,0,0,0,0,0,0,0,0,0,0,0,0,0,0,0,33,33,0,0,0,0,0,0,33,33,0
0,0,33,0,0,0,0,0,0,0,0,0,0,0,0,0,0,0,0,0,0,0,0,0,0,0,0,0,0,0,0,0,0,0,0,0,0
0,0,33,0,0,0,33,33,0,0,0,0,0,0,0,0,0,0,0,0,0,0,0,10,0,0,0,0,0,126,0,0,10,0,0,0,0
0,0,33,33,0,0,33,33,0,0,0,33,0,0,0,0,33,33,0,33,0,0,0,0,0,0,0,0,0,0,0,0,0,0,0,0,0
0,0,33,33,33,33,33,33,0,0,0,0,33,33,33,0,0,33,33,33,0,0,0,0,0,0,0,0,0,0,0,0,33,33,33,33,0
0,0,0,33,0,0,0,0,33,0,0,33,33,33,0,0,0,33,33,0,0,0,0,0,0,0,0,0,0,0,0,0,0,33,33,0,0
0,0,0,0,0,0,0,0,0,0,0,0,0,0,0,0,33,0,0,33,0,0,0,0,0,0,0,0,0,0,0,0,0,0,0,33,0
:endlayer
layer: 11
0,124,124,124,124,124,124,124,124,124,124,0,0,0,0,0,0,0,0,0,0,0,0,0,0,0,0,124,124,124,124,124,124,0,0,0,0
0,33,124,33,124,124,124,124,124,124,124,124,124,0,0,0,0,0,0,0,0,0,0,0,0,0,124,124,33,124,124,33,124,124,0,0,0
0,124,124,33,33,124,124,124,33,124,33,124,124,124,0,0,0,0,0,0,0,0,0,0,0,0,124,124,33,33,33,33,124,124,0,0,0
0,0,124,33,33,33,33,33,124,33,33,33,124,124,0,0,0,0,0,0,0,0,0,0,0,0,124,124,124,33,33,124,124,124,0,0,0
0,0,124,124,124,124,33,33,124,33,33,124,124,124,0,0,0,0,33,33,0,0,0,0,0,0,124,124,33,33,124,124,124,124,0,0,0
0,0,124,124,124,124,33,33,124,124,33,124,124,0,0,0,0,0,33,33,0,0,0,137,0,0,124,124,124,124,124,135,124,0,0,0,0
0,0,0,0,124,33,33,33,124,124,124,124,124,0,0,0,0,0,0,0,0,0,0,0,0,0,124,124,124,124,124,124,124,0,0,0,0
0,0,0,33,33,124,124,33,33,124,124,124,0,0,0,0,0,0,0,0,0,0,0,0,0,0,0,124,124,124,124,66,0,0,0,0,0
0,0,0,33,33,33,124,33,33,33,0,0,0,0,139,0,0,0,0,0,0,0,0,0,0,0,0,0,0,0,66,0,0,0,0,0,0
0,0,0,0,0,33,0,0,0,33,0,0,0,0,0,0,0,0,0,0,0,0,0,0,0,0,0,0,0,0,0,0,0,0,0,0,0
0,0,0,0,0,33,33,33,0,0,0,0,0,0,0,0,0,0,0,0,0,0,0,0,0,0,0,0,0,0,0,0,124,124,124,124,0
0,0,0,0,0,33,33,33,0,0,0,33,0,0,0,0,0,0,0,0,0,0,0,0,0,0,0,0,0,0,0,124,124,124,124,124,124
0,0,0,0,0,0,0,0,33,33,33,0,0,0,0,0,0,0,0,0,0,0,0,0,0,0,0,0,0,0,124,124,124,124,124,124,124
0,0,0,0,0,0,0,141,0,33,33,0,0,0,0,0,0,0,0,0,0,0,0,0,0,0,0,0,0,0,124,124,124,33,33,124,124
0,0,0,143,0,0,0,0,0,0,0,0,0,0,0,0,0,0,0,0,0,0,0,0,0,0,136,0,0,0,124,124,124,33,33,124,124
0,0,0,0,0,0,0,0,0,0,0,0,0,0,0,0,0,0,0,0,40,0,0,0,0,40,40,40,0,0,124,124,124,124,124,124,124
0,0,0,0,0,10,0,0,0,0,0,0,0,0,0,0,0,0,0,0,103,0,0,0,0,0,0,0,0,0,124,124,124,124,124,124,124
0,0,0,0,0,0,0,0,0,0,0,0,0,0,0,0,0,0,0,0,40,0,0,0,0,0,0,0,0,0,124,124,33,124,33,124,124
0,33,33,144,0,0,0,0,0,0,33,33,0,0,0,0,0,0,0,0,0,0,0,0,0,0,0,0,0,0,124,124,124,124,124,33,124
0,33,33,0,0,0,0,142,0,0,33,33,0,0,0,0,0,0,0,0,0,0,0,0,0,0,0,0,0,0,124,124,33,33,33,33,124
0,0,0,0,0,0,0,0,0,0,0,0,0,0,0,0,0,0,0,0,0,0,0,0,0,0,0,0,0,0,124,124,124,33,33,124,124
0,0,0,0,0,124,124,124,0,0,0,0,0,0,0,0,0,0,0,0,0,0,0,0,0,0,0,0,0,0,124,124,124,124,124,124,124
0,0,0,124,124,124,33,33,124,0,0,0,0,0,0,0,0,0,0,0,0,0,0,0,0,0,0,0,0,0,0,124,124,124,124,124,124
0,0,0,124,33,124,33,33,33,0,0,0,0,0,0,0,0,0,0,0,0,0,0,0,0,0,0,0,0,0,0,0,0,0,0,0,0
0,0,124,124,124,33,33,33,33,0,0,0,0,0,140,0,0,0,0,0,0,0,0,0,0,0,33,33,0,0,0,0,0,0,33,33,0
0,0,33,124,124,33,33,124,33,0,0,0,0,0,0,0,0,0,0,0,0,0,0,0,0,0,33,33,0,0,0,0,0,0,33,33,0
0,0,33,124,124,124,124,124,124,124,0,0,124,124,124,0,0,0,0,0,0,0,0,0,0,0,0,0,0,0,0,0,0,0,0,0,0
0,0,33,124,124,124,33,33,124,124,0,124,124,124,124,124,124,124,0,0,0,0,0,138,0,0,0,0,0,0,0,124,134,124,124,124,124
0,0,33,33,124,124,33,33,124,124,0,33,124,124,124,124,33,33,124,33,0,0,0,0,0,0,0,0,0,0,124,124,124,124,124,124,124
0,33,33,33,33,33,33,33,124,124,124,124,124,33,33,124,124,33,33,33,0,0,0,0,0,0,0,0,0,0,124,124,33,33,33,33,124
0,0,0,33,124,124,124,124,33,124,124,33,124,33,33,124,33,33,33,0,0,0,0,0,0,0,0,0,0,0,124,124,124,33,33,124,124
0,0,0,0,124,124,124,124,124,124,124,124,124,124,124,124,33,124,0,33,0,0,0,0,0,0,0,0,0,0,0,124,124,124,124,33,124
:endlayer
layer: 12
0,0,124,124,124,124,124,124,124,124,0,0,0,0,0,0,0,0,0,0,0,0,0,0,0,0,0,124,124,124,124,124,0,0,0,0,0
0,124,124,124,124,124,124,124,124,124,124,124,0,0,0,0,0,0,0,0,0,0,0,0,0,0,0,124,124,124,124,124,124,0,0,0,0
0,124,124,124,33,33,124,124,124,124,124,124,124,124,0,0,0,0,0,0,0,0,0,0,0,0,124,124,124,124,124,124,124,124,0,0,0
0,124,124,124,33,33,124,124,124,33,33,124,124,124,0,0,0,0,0,0,0,0,0,0,0,0,124,124,124,33,33,124,124,124,0,0,0
0,124,124,124,124,124,33,33,124,33,33,124,124,124,0,0,0,0,33,33,0,0,0,0,0,0,124,124,124,33,33,124,124,124,0,0,0
0,124,124,124,124,124,33,33,124,124,124,124,124,124,0,0,0,0,33,33,0,0,0,0,0,0,124,124,124,124,124,124,124,124,0,0,0
0,124,124,124,124,124,33,124,124,124,124,124,124,124,0,0,0,0,0,0,0,0,0,0,0,0,124,124,124,124,124,124,124,124,0,0,0
0,124,124,33,33,124,124,33,33,124,124,124,0,0,0,0,0,0,0,0,0,0,0,0,0,0,0,124,124,124,124,124,0,0,0,0,0
0,124,124,33,33,33,124,33,33,33,124,124,0,0,0,0,0,0,0,0,0,0,0,0,0,0,0,0,0,0,0,0,0,0,0,0,0
0,124,124,124,124,33,124,124,124,33,124,124,0,0,0,0,0,0,0,0,0,0,0,0,0,0,0,0,0,0,0,0,0,0,0,0,0
0,124,124,124,124,33,33,33,124,124,124,124,0,0,0,0,0,0,0,0,0,0,0,0,0,0,0,0,0,0,0,0,0,0,0,0,0
0,0,0,0,124,33,33,33,124,124,124,33,0,0,0,0,0,0,0,0,0,0,0,0,0,0,0,0,0,0,0,0,0,124,124,0,0
0,0,0,0,33,0,0,33,33,33,33,0,0,0,0,0,0,0,0,0,0,0,0,0,0,0,0,0,0,0,0,0,124,124,124,124,0
0,0,0,0,0,0,0,0,0,33,33,0,0,0,0,0,0,0,0,0,0,0,0,0,0,0,0,0,0,0,0,124,124,124,124,124,124
0,0,0,0,0,0,0,0,0,0,33,0,0,0,0,0,0,0,0,0,0,0,0,0,0,0,0,0,0,0,0,124,124,124,124,124,124
0,0,0,0,0,0,0,0,0,0,0,0,0,0,0,0,0,0,0,0,40,0,0,0,0,0,0,0,0,0,0,0,124,124,124,124,0
0,0,0,0,0,10,0,0,0,0,0,0,0,0,0,0,0,0,0,0,40,0,0,0,0,0,0,0,0,0,0,124,124,124,124,124,0
0,0,0,0,0,0,0,0,0,0,0,0,0,0,0,0,0,0,0,0,40,0,0,0,0,0,0,0,0,0,0,124,124,124,124,124,0
0,33,33,0,0,0,0,0,0,0,33,33,0,0,0,0,0,0,0,0,0,0,0,0,0,0,0,0,0,0,124,124,124,124,124,124,124
0,33,33,0,0,0,0,0,0,0,33,33,33,0,0,0,0,0,0,0,0,0,0,0,0,0,0,0,0,0,124,124,124,33,33,124,124
0,0,0,0,0,0,0,124,124,124,124,0,0,0,0,0,0,0,0,0,0,0,0,0,0,0,0,0,0,0,124,124,124,33,33,124,124
0,0,0,124,124,124,124,124,124,124,124,124,124,0,0,0,0,0,0,0,0,0,0,0,0,0,0,0,0,0,124,124,124,124,124,124,124
0,0,0,124,124,124,33,33,124,124,124,124,124,0,0,0,0,0,0,0,0,0,0,0,0,0,0,0,0,0,0,124,124,124,124,124,124
0,0,124,124,124,124,33,124,33,33,124,124,124,0,0,0,0,0,0,0,0,0,0,0,0,0,0,0,0,0,0,124,124,124,124,124,0
0,124,124,124,124,33,33,124,33,33,124,124,124,0,0,0,0,0,0,0,0,0,0,0,0,0,33,33,0,0,0,0,0,0,33,33,0
124,124,124,124,124,33,33,124,33,124,124,124,124,0,0,0,0,0,0,0,0,0,0,0,0,0,33,33,0,0,0,0,0,0,33,33,0
124,124,124,124,124,124,124,124,124,124,124,124,124,124,124,124,124,124,124,124,124,0,0,0,0,0,0,0,0,0,0,124,124,124,124,124,0
124,124,33,124,124,124,124,124,124,124,124,124,124,124,124,124,124,124,124,124,124,124,0,0,0,0,0,0,0,0,0,124,124,124,124,124,0
124,124,33,33,124,124,33,33,124,124,124,124,124,124,124,124,33,33,124,33,124,124,0,0,0,0,0,0,0,0,124,124,124,124,124,124,124
124,33,33,33,33,124,33,33,124,124,124,124,124,124,33,33,124,33,33,33,124,124,0,0,0,0,0,0,0,0,124,124,124,33,33,124,124
124,124,124,33,124,124,124,124,124,124,124,124,124,124,33,33,33,33,33,124,124,124,0,0,0,0,0,0,0,0,124,124,124,33,33,124,124
0,0,124,124,124,124,124,124,124,124,124,124,124,124,124,124,33,124,124,33,124,124,0,0,0,0,0,0,0,0,124,124,124,124,124,124,124
:endlayer
layer: 13
0,0,0,0,124,124,0,0,0,0,0,0,0,0,0,0,0,0,0,0,0,0,0,0,0,0,0,0,0,0,0,0,0,0,0,0,0
0,0,0,124,124,124,124,0,0,124,124,0,0,0,0,0,0,0,0,0,0,0,0,0,0,0,0,0,0,124,124,0,0,0,0,0,0
0,0,124,124,124,124,124,124,124,124,124,124,0,0,0,0,0,0,0,0,0,0,0,0,0,0,0,0,124,124,124,124,0,0,0,0,0
0,0,124,124,124,124,124,124,124,124,124,124,124,0,0,0,0,0,0,0,0,0,0,0,0,0,0,124,124,124,124,124,124,0,0,0,0
0,124,124,124,124,124,124,124,124,124,124,124,124,0,0,0,0,0,33,33,33,0,0,0,0,0,0,124,124,124,124,124,124,0,0,0,0
0,124,124,124,124,124,124,124,124,124,124,124,0,0,0,0,0,0,33,33,0,0,0,0,0,0,0,0,124,124,124,124,0,0,0,0,0
124,124,124,124,124,124,124,124,124,124,124,124,0,0,0,0,0,0,0,0,0,0,0,0,0,0,0,0,0,124,124,0,0,0,0,0,0
124,124,124,33,33,124,124,33,33,124,124,124,0,0,0,0,0,0,0,0,0,0,0,0,0,0,0,0,0,0,0,0,0,0,0,0,0
124,124,124,33,33,124,124,33,33,124,124,124,0,0,0,0,0,0,0,0,0,0,0,0,0,0,0,0,0,0,0,0,0,0,0,0,0
124,124,124,124,124,124,124,124,124,124,124,124,0,0,0,0,0,0,0,0,0,0,0,0,0,0,0,0,0,0,0,0,0,0,0,0,0
124,124,124,124,124,124,124,33,124,124,124,124,0,0,0,0,0,0,0,0,0,0,0,0,0,0,0,0,0,0,0,0,0,0,0,0,0
0,124,124,124,124,33,33,33,124,124,0,33,0,0,0,0,0,0,0,0,0,0,0,0,0,0,0,0,0,0,0,0,0,0,0,0,0
0,0,124,124,33,33,33,33,33,33,33,0,0,0,0,0,0,0,0,0,0,0,0,0,0,0,0,0,0,0,0,0,0,0,0,0,0
0,0,124,124,124,124,124,124,124,33,33,0,0,0,0,0,0,0,0,0,0,0,0,0,0,0,0,0,0,0,0,0,0,0,0,0,0
0,0,124,124,124,124,124,124,124,124,33,0,0,0,0,0,0,0,0,0,0,0,0,0,0,0,0,0,0,0,0,0,0,0,0,0,0
0,0,0,0,0,0,0,0,0,0,0,0,0,0,0,0,0,0,0,0,0,0,0,0,0,0,0,0,0,0,0,0,0,0,0,0,0
0,0,0,0,0,146,0,0,0,0,0,0,0,0,0,0,0,0,0,0,145,0,0,0,0,0,0,0,0,0,0,0,0,0,0,0,0
0,0,0,0,0,0,0,0,0,33,0,0,0,0,0,0,0,0,0,0,0,0,0,0,0,0,0,0,0,0,0,0,0,124,124,0,0
0,33,33,0,0,0,0,0,0,0,33,33,0,0,0,0,0,0,0,0,0,0,0,0,0,0,0,0,0,0,0,0,124,124,124,124,0
0,33,33,0,0,0,0,0,0,0,33,33,33,0,0,0,0,0,0,0,0,0,0,0,0,0,0,0,0,0,0,124,124,124,124,124,124
0,0,0,0,0,0,0,124,124,124,33,33,0,0,0,0,0,0,0,0,0,0,0,0,0,0,0,0,0,0,0,124,124,124,124,124,124
0,0,0,66,66,0,0,124,124,124,124,124,0,0,0,0,0,0,0,0,0,0,0,0,0,0,0,0,0,0,0,0,124,124,124,124,0
0,0,0,0,0,124,124,124,124,124,124,124,124,124,0,0,0,0,0,0,0,0,0,0,0,0,0,0,0,0,0,0,0,124,124,0,0
0,0,0,0,124,124,124,124,124,33,33,124,124,124,66,0,0,0,0,0,0,0,0,0,0,0,0,0,0,0,0,0,0,0,0,0,0
124,124,124,124,124,124,124,124,124,33,33,124,124,124,66,66,0,0,0,0,0,0,0,0,0,0,33,33,0,0,0,0,0,0,33,33,0
124,124,124,124,124,124,124,124,124,124,124,124,124,124,66,66,66,66,0,0,0,0,0,0,0,0,33,33,0,0,0,0,0,0,33,33,0
124,124,124,124,124,124,124,124,124,124,124,124,124,124,0,124,124,124,124,124,0,0,0,0,0,0,0,0,0,0,0,0,0,0,0,0,0
124,124,33,33,124,124,124,124,124,124,124,124,0,0,124,124,124,124,124,124,124,0,0,0,0,0,0,0,0,0,0,0,0,124,124,0,0
124,124,33,33,124,124,124,124,124,124,0,0,0,124,124,124,124,124,124,124,124,124,0,0,0,0,0,0,0,0,0,0,124,124,124,124,0
124,124,124,124,124,124,124,124,124,124,0,0,124,124,124,124,124,33,33,124,124,124,0,0,0,0,0,0,0,0,0,124,124,124,124,124,124
124,124,124,124,124,124,124,124,124,0,0,0,124,124,124,124,124,33,33,124,124,124,0,0,0,0,0,0,0,0,0,124,124,124,124,124,124
124,124,124,124,124,0,124,124,0,0,0,0,0,124,124,124,124,124,124,124,124,124,0,0,0,0,0,0,0,0,0,0,124,124,124,124,0
:endlayer
layer: 14
0,0,0,0,0,0,0,0,0,0,0,0,0,0,0,0,0,0,0,0,0,0,0,0,0,0,0,0,0,0,0,0,0,0,0,0,0
0,0,0,149,0,0,0,0,0,0,0,0,0,0,0,0,0,0,0,0,0,0,0,0,0,0,0,0,0,0,0,0,0,0,0,0,0
0,0,0,0,124,124,0,0,0,0,0,0,0,0,0,0,0,0,0,0,0,0,0,0,0,0,0,0,0,0,0,148,0,0,0,0,0
0,0,0,0,124,124,0,0,0,0,0,0,0,0,0,0,0,0,0,0,0,0,0,0,0,0,0,0,0,0,0,0,0,0,0,0,0
0,0,0,0,0,0,0,0,0,0,0,0,0,0,0,0,0,0,33,33,33,0,0,0,0,0,0,0,0,0,0,0,0,0,0,0,0
0,0,0,124,124,0,0,124,124,0,0,0,0,0,0,0,0,33,33,33,0,0,0,0,0,0,0,0,0,0,0,0,0,0,0,0,0
0,0,124,124,124,124,124,124,124,124,0,0,0,0,0,0,0,33,0,33,0,0,0,0,0,0,0,0,0,0,0,0,0,0,0,0,0
0,124,124,124,124,124,124,124,124,124,124,0,0,0,0,0,0,0,0,0,0,0,0,0,0,0,0,0,0,0,0,0,0,0,0,0,0
0,124,124,124,124,124,124,124,124,124,124,124,124,0,0,0,0,0,0,0,0,0,0,0,0,0,0,0,0,0,0,0,0,0,0,0,0
0,0,124,124,124,124,124,124,124,124,124,124,124,124,0,0,0,0,0,0,0,0,0,0,0,0,0,0,0,0,0,0,0,0,0,0,0
0,0,124,124,124,124,124,124,124,124,124,124,124,124,0,0,0,0,0,0,0,0,0,0,0,0,0,0,0,0,0,0,0,0,0,0,0
0,0,124,124,124,33,33,124,124,124,124,33,124,124,0,0,0,0,0,0,0,0,0,0,0,0,0,0,0,0,0,0,0,0,0,0,0
0,0,124,124,124,33,33,124,33,33,33,124,124,0,0,0,0,0,0,0,0,0,0,0,0,0,0,0,0,0,0,0,0,0,0,0,0
0,0,124,124,124,124,124,124,124,33,33,124,124,0,0,0,0,0,0,0,0,0,0,0,0,0,0,0,0,0,0,0,0,0,0,0,0
0,0,0,124,0,0,0,124,124,124,33,124,124,0,0,0,0,0,0,0,0,0,0,0,0,0,0,0,0,0,0,0,0,0,0,0,0
0,0,66,66,0,0,0,0,0,124,124,124,0,0,0,0,0,0,0,0,0,0,0,0,0,0,0,0,0,0,0,0,0,0,0,0,0
66,66,66,66,0,0,0,0,0,0,0,0,0,0,0,0,0,0,0,0,0,0,0,0,0,0,0,0,0,0,0,0,0,0,0,0,0
66,66,66,66,66,0,0,0,0,33,0,0,0,0,0,0,0,0,0,0,0,0,0,0,0,0,0,0,0,0,0,0,0,0,0,0,0
66,33,33,66,66,0,0,0,0,0,33,33,33,0,0,0,0,0,0,0,0,0,0,0,0,0,0,0,0,0,0,0,0,0,0,0,0
66,33,33,66,66,0,0,0,0,0,33,33,33,0,0,0,0,0,0,0,0,0,0,0,0,0,0,0,0,0,0,0,0,0,0,0,0
66,66,66,66,66,0,0,0,0,0,33,33,33,0,0,0,0,0,0,0,0,0,0,0,0,0,0,0,0,0,0,0,0,0,0,0,0
66,66,66,66,0,0,0,0,0,124,124,0,0,0,0,0,0,0,0,0,0,0,0,0,0,0,0,0,0,0,0,0,0,0,0,0,0
0,66,66,0,0,0,0,0,124,124,124,124,0,0,0,0,0,0,0,0,0,0,0,0,0,0,0,0,0,0,0,0,0,0,0,0,0
0,0,0,0,0,0,0,124,124,124,124,124,124,0,0,0,0,0,0,0,0,0,0,0,0,0,0,0,0,0,0,0,0,0,0,0,0
0,0,0,0,0,0,0,124,124,124,124,124,124,0,0,0,0,0,0,0,0,0,0,0,0,0,33,33,0,0,0,0,0,0,33,33,0
0,0,124,124,0,0,0,0,124,124,124,124,0,0,0,0,0,0,0,0,0,0,0,0,0,0,33,33,0,0,0,0,0,0,33,33,0
0,124,124,124,124,0,0,0,0,124,124,0,0,0,0,0,0,0,0,0,0,0,0,0,0,0,33,0,0,0,0,0,0,0,0,0,0
124,124,124,124,124,124,0,0,0,0,0,0,0,0,0,0,0,124,124,0,0,0,0,0,0,0,0,0,0,0,0,0,0,0,0,0,0
124,124,124,124,124,124,0,0,0,0,0,0,0,0,0,0,124,124,124,124,0,0,0,0,0,0,0,0,0,0,0,0,0,0,0,0,0
0,124,124,124,124,0,0,0,0,0,0,0,0,0,0,124,124,124,124,124,124,0,0,0,0,0,0,0,0,0,0,0,0,0,0,0,0
0,150,124,124,0,0,0,0,0,0,0,0,0,0,0,124,124,124,124,124,124,0,0,0,0,0,0,0,0,0,0,0,0,0,0,147,0
0,0,0,0,0,0,0,0,0,0,0,0,0,0,0,0,124,124,124,124,0,0,0,0,0,0,0,0,0,0,0,0,0,0,0,0,0
:endlayer
layer: 15
0,0,0,0,0,0,0,0,0,0,0,0,0,0,0,0,0,0,0,0,0,0,0,0,0,0,0,0,0,0,0,0,0,0,0,0,0
0,0,0,0,0,0,0,0,0,0,0,0,0,0,0,0,0,0,0,0,0,0,0,0,0,0,0,0,0,0,0,0,0,0,0,0,0
0,0,0,0,0,0,0,0,0,0,0,0,0,0,0,0,0,0,0,0,0,0,0,0,0,0,0,0,0,0,0,0,0,0,0,0,0
0,0,0,0,0,0,0,0,0,0,0,0,0,0,0,0,0,0,0,0,33,0,0,0,0,0,0,0,0,0,0,0,0,0,0,0,0
0,0,0,0,0,0,0,0,0,0,0,0,0,0,0,0,0,0,33,33,33,0,0,0,0,0,0,0,0,0,0,0,0,0,0,0,0
0,0,0,0,0,0,0,0,0,0,0,0,0,0,0,0,0,33,33,33,0,0,0,0,0,0,0,0,0,0,0,0,0,0,0,0,0
0,0,0,0,0,0,0,0,0,0,0,0,0,0,0,0,0,33,0,33,0,0,0,0,0,0,0,0,0,0,0,0,0,0,0,0,0
0,0,0,0,0,0,0,124,124,0,0,0,0,0,0,0,0,0,0,0,0,0,0,0,0,0,0,0,0,0,0,0,0,0,0,0,0
0,0,0,0,0,0,0,124,124,124,124,124,0,0,0,0,0,0,0,0,0,0,0,0,0,0,0,0,0,0,0,0,0,0,0,0,0
0,0,0,0,0,124,124,124,124,124,124,124,124,0,0,0,0,0,0,0,0,0,0,0,0,0,0,0,0,0,0,0,0,0,0,0,0
0,0,0,0,124,124,124,124,124,124,124,124,124,124,0,0,0,0,0,0,0,0,0,0,0,0,0,0,0,0,0,0,0,0,0,0,0
0,0,0,124,124,124,124,124,124,33,33,124,124,124,0,0,0,0,0,0,0,0,0,0,0,0,0,0,0,0,0,0,0,0,0,0,0
0,0,0,124,124,124,124,124,124,33,33,124,124,124,0,0,0,0,0,0,0,0,0,0,0,0,0,0,0,0,0,0,0,0,0,0,0
0,0,0,0,124,0,124,124,124,124,124,124,124,124,0,0,0,0,0,0,0,0,0,0,0,0,0,0,0,0,0,0,0,0,0,0,0
0,0,0,0,0,0,124,124,124,124,124,124,124,124,0,0,0,0,0,0,0,0,0,0,0,0,0,0,0,0,0,0,0,0,0,0,0
0,0,0,0,0,0,0,124,124,124,124,124,0,0,0,0,0,0,0,0,0,0,0,0,0,0,0,0,0,0,0,0,0,0,0,0,0
0,0,0,0,0,0,0,124,124,124,124,124,124,124,0,0,0,0,0,0,0,0,0,0,0,0,0,0,0,0,0,0,0,0,0,0,0
0,66,66,0,0,0,0,124,124,33,124,124,124,124,124,0,0,0,0,0,0,0,0,0,0,0,0,0,0,0,0,0,0,0,0,0,0
66,33,33,66,0,0,0,124,124,124,33,33,33,124,124,0,0,0,0,0,0,0,0,0,0,0,0,0,0,0,0,0,0,0,0,0,0
66,33,33,66,0,0,0,0,124,124,33,33,33,124,124,0,0,0,0,0,0,0,0,0,0,0,0,0,0,0,0,0,0,0,0,0,0
0,66,66,0,0,0,0,0,124,124,33,33,33,124,124,0,0,0,0,0,0,0,0,0,0,0,0,0,0,0,0,0,0,0,0,0,0
0,0,0,0,0,0,0,0,124,124,124,124,124,124,124,0,0,0,0,0,0,0,0,0,0,0,0,0,0,0,0,0,0,0,0,0,0
0,0,0,0,0,0,0,0,0,124,124,124,124,124,0,0,0,0,0,0,0,0,0,0,0,0,0,0,0,0,0,0,0,0,0,0,0
0,0,0,0,0,0,0,0,0,124,124,0,0,0,0,0,0,0,0,0,0,0,0,0,0,0,33,0,0,0,0,0,0,0,0,0,0
0,0,0,0,0,0,0,0,0,124,124,0,0,0,0,0,0,0,0,0,0,0,0,0,0,0,33,33,0,0,0,0,0,0,33,33,0
0,0,0,0,0,0,0,0,0,0,0,0,0,0,0,0,0,0,0,0,0,0,0,0,0,0,33,33,0,0,0,0,0,0,33,33,0
0,0,0,0,0,0,0,0,0,0,0,0,0,0,0,0,0,0,0,0,0,0,0,0,0,0,33,0,0,0,0,0,0,0,0,0,0
0,0,124,124,0,0,0,0,0,0,0,0,0,0,0,0,0,0,0,0,0,0,0,0,0,0,0,0,0,0,0,0,0,0,0,0,0
0,0,124,124,0,0,0,0,0,0,0,0,0,0,0,0,0,0,0,0,0,0,0,0,0,0,0,0,0,0,0,0,0,0,0,0,0
0,0,0,0,0,0,0,0,0,0,0,0,0,0,0,0,0,124,124,0,0,0,0,0,0,0,0,0,0,0,0,0,0,0,0,0,0
0,0,0,0,0,0,0,0,0,0,0,0,0,0,0,0,0,124,124,0,0,0,0,0,0,0,0,0,0,0,0,0,0,0,0,0,0
0,0,0,0,0,0,0,0,0,0,0,0,0,0,0,0,0,0,0,0,0,0,0,0,0,0,0,0,0,0,0,0,0,0,0,0,0
:endlayer
layer: 16
0,0,0,0,0,0,0,0,0,0,0,0,0,0,0,0,0,0,0,0,0,0,0,0,0,0,0,0,0,0,0,0,0,0,0,0,0
0,0,0,0,0,0,0,0,0,0,0,0,0,0,0,0,0,0,0,0,0,0,0,0,0,0,0,0,0,0,0,0,0,0,0,0,0
0,0,0,0,0,0,0,0,0,0,0,0,0,0,0,0,0,0,0,124,124,124,0,0,0,0,0,0,0,0,0,0,0,0,0,0,0
0,0,0,0,0,0,0,0,0,0,0,0,0,0,0,0,124,124,124,124,33,124,124,0,0,0,0,0,0,0,0,0,0,0,0,0,0
0,0,0,0,0,0,0,0,0,0,0,0,0,0,0,0,124,124,33,33,33,124,124,0,0,0,0,0,0,0,0,0,0,0,0,0,0
0,0,0,0,0,0,0,0,0,0,0,0,0,0,0,124,124,33,33,33,124,124,124,0,0,0,0,0,0,0,0,0,0,0,0,0,0
0,0,0,0,0,0,0,0,0,0,0,0,0,0,0,124,124,33,124,33,124,124,124,0,0,0,0,0,0,0,0,0,0,0,0,0,0
0,0,0,0,0,0,0,0,0,0,0,0,0,0,0,124,124,124,124,124,124,124,0,0,0,0,0,0,0,0,0,0,0,0,0,0,0
0,0,0,0,0,0,0,0,0,0,0,0,0,0,0,124,124,124,124,124,124,124,0,0,0,0,0,0,0,0,0,0,0,0,0,0,0
0,0,0,0,0,0,0,0,0,124,124,0,0,0,0,0,124,124,124,124,124,0,0,0,0,0,0,0,0,0,0,0,0,0,0,0,0
0,0,0,0,0,0,0,0,124,124,124,124,0,0,0,0,0,0,0,0,0,0,0,0,0,0,0,0,0,0,0,0,0,0,0,0,0
0,0,0,0,0,124,124,124,124,124,124,124,124,0,0,0,0,0,0,0,0,0,0,0,0,0,0,0,0,0,0,0,0,0,0,0,0
0,0,0,0,0,124,124,124,124,124,124,124,124,0,0,0,0,0,0,0,0,0,0,0,0,0,0,0,0,0,0,0,0,0,0,0,0
0,0,0,0,0,0,0,0,124,124,124,124,0,0,0,0,0,0,0,0,0,0,0,0,0,0,0,0,0,0,0,0,0,0,0,0,0
0,0,0,0,0,0,0,0,0,124,124,0,0,0,0,0,0,0,0,0,0,0,0,0,0,0,0,0,0,0,0,0,0,0,0,0,0
0,0,0,0,0,0,0,0,124,124,124,124,124,0,0,0,0,0,0,0,0,0,0,0,0,0,0,0,0,0,0,0,0,0,0,0,0
0,0,0,0,0,0,0,0,124,124,124,124,124,0,0,0,0,0,0,0,0,0,0,0,0,0,0,0,0,0,0,0,0,0,0,0,0
0,0,0,0,0,0,0,124,124,124,124,124,124,124,124,0,0,0,0,0,0,0,0,0,0,0,66,0,0,0,0,0,0,0,0,0,0
0,33,33,0,0,0,0,124,124,124,33,33,124,124,124,0,0,0,0,0,0,0,0,0,0,0,66,66,0,0,0,0,0,0,0,0,0
0,33,33,0,0,0,0,124,124,124,33,33,124,124,124,0,0,0,0,0,0,0,0,0,0,66,151,66,0,0,0,0,0,0,0,0,0
0,0,0,0,0,0,0,124,124,124,124,124,124,124,124,0,0,0,0,0,0,0,0,0,0,66,151,66,0,66,66,0,0,0,0,0,0
0,0,0,0,0,0,0,124,124,124,124,124,124,124,124,0,0,0,0,0,0,0,0,0,0,0,151,66,66,66,66,66,66,0,0,0,0
0,0,0,0,0,0,0,0,124,124,124,124,124,0,0,0,0,0,0,0,0,0,0,0,0,0,151,0,66,66,66,66,66,66,0,0,0
0,0,0,0,0,0,0,0,0,0,0,0,0,0,0,0,0,0,0,0,0,0,66,0,0,0,33,0,33,66,0,0,0,66,0,0,0
0,0,0,0,0,0,0,0,0,0,0,0,0,0,0,0,0,0,0,0,0,66,66,66,66,0,33,33,33,0,0,0,0,33,33,33,0
0,0,0,0,0,0,0,0,0,0,0,0,0,0,0,0,0,0,0,0,66,66,152,152,152,152,33,33,33,0,0,0,0,0,33,33,0
0,0,0,0,0,0,0,0,0,0,0,0,0,0,0,0,0,0,0,0,0,66,66,66,66,66,33,0,0,0,0,0,0,0,0,0,0
0,0,0,0,0,0,0,0,0,0,0,0,0,0,0,0,0,0,0,0,0,0,0,0,0,0,0,0,0,0,0,0,0,0,0,0,0
0,0,0,0,0,0,0,0,0,0,0,0,0,0,0,0,0,0,0,0,0,0,0,0,0,0,0,0,0,0,0,0,0,0,0,0,0
0,0,0,0,0,0,0,0,0,0,0,0,0,0,0,0,0,0,0,0,0,0,0,0,0,0,0,0,0,0,0,0,0,0,0,0,0
0,0,0,0,0,0,0,0,0,0,0,0,0,0,0,0,0,0,0,0,0,0,0,0,0,0,0,0,0,0,0,0,0,0,0,0,0
0,0,0,0,0,0,0,0,0,0,0,0,0,0,0,0,0,0,0,0,0,0,0,0,0,0,0,0,0,0,0,0,0,0,0,0,0
:endlayer
layer: 17
0,0,0,0,0,0,0,0,0,0,0,0,0,0,0,0,0,0,0,0,0,0,0,0,0,0,0,0,0,0,0,0,0,0,0,0,0
0,0,0,0,0,0,0,0,0,0,0,0,0,0,0,0,0,0,0,0,0,0,0,0,0,0,0,0,0,0,0,0,0,0,0,0,0
0,0,0,0,0,0,0,0,0,0,0,0,0,0,0,0,124,124,124,124,124,0,0,0,0,0,0,0,0,0,0,0,0,0,0,0,0
0,0,0,0,0,0,0,0,0,0,0,0,0,0,0,0,124,124,124,124,124,124,0,0,0,0,0,0,0,0,0,0,0,0,0,0,0
0,0,0,0,0,0,0,0,0,0,0,0,0,0,0,124,124,124,124,124,124,124,124,0,0,0,0,0,0,0,0,0,0,0,0,0,0
0,0,0,0,0,0,0,0,0,0,0,0,0,0,0,124,124,124,33,33,124,124,124,0,0,0,0,0,0,0,0,0,0,0,0,0,0
0,0,0,0,0,0,0,0,0,0,0,0,0,0,0,124,124,124,33,33,124,124,124,0,0,0,0,0,0,0,0,0,0,0,0,0,0
0,0,0,0,0,0,0,0,0,0,0,0,0,0,0,124,124,124,124,124,124,124,124,0,0,0,0,0,0,0,0,0,0,0,0,0,0
0,0,0,0,0,0,0,0,0,0,0,0,0,0,0,124,124,124,124,124,124,124,124,0,0,0,0,0,0,0,0,0,0,0,0,0,0
0,0,0,0,0,0,0,0,0,0,0,0,0,0,0,0,124,124,124,124,124,0,0,0,0,0,0,0,0,0,0,0,0,0,0,0,0
0,0,0,0,0,0,0,0,0,0,0,0,0,0,0,0,0,0,0,0,0,0,0,0,0,0,0,0,0,0,0,0,0,0,0,0,0
0,0,0,0,0,0,0,0,0,124,124,0,0,0,0,0,0,0,0,0,0,0,0,0,0,0,0,0,0,0,0,0,0,0,0,0,0
0,0,0,0,0,0,0,0,0,124,124,0,0,0,0,0,0,0,0,0,0,0,0,0,0,0,0,0,0,0,0,0,0,0,0,0,0
0,0,0,0,0,0,0,0,0,0,0,0,0,0,0,0,0,0,0,0,0,0,0,0,0,0,0,0,0,0,0,0,0,0,0,0,0
0,0,0,0,0,0,0,0,0,0,0,0,0,0,0,0,0,0,0,0,0,0,0,0,0,0,0,0,0,0,0,0,0,0,0,0,0
0,0,0,0,0,0,0,0,0,0,0,0,0,0,0,0,0,0,0,0,0,0,0,0,0,0,0,0,0,0,0,0,0,0,0,0,0
0,0,0,0,0,0,0,0,0,0,124,124,0,0,0,0,0,0,0,0,0,0,0,0,0,0,0,0,0,0,0,0,0,0,0,0,0
0,33,0,33,0,0,0,0,0,124,124,124,124,0,0,0,0,0,0,0,0,0,0,0,0,0,0,0,0,0,0,0,0,0,0,0,0
0,33,33,0,0,0,0,0,124,124,124,124,124,124,0,0,0,0,0,0,0,0,0,0,0,0,66,0,0,0,0,0,0,0,0,0,0
0,33,33,0,0,0,0,0,124,124,124,124,124,124,0,0,0,0,0,0,0,0,0,0,0,0,66,0,0,0,0,0,0,0,0,0,0
0,0,0,0,0,0,0,0,0,124,124,124,124,0,0,0,0,0,0,0,0,0,0,0,0,0,66,0,0,0,0,0,0,0,0,0,0
0,0,0,0,0,0,0,0,0,0,124,124,0,0,0,0,0,0,0,0,0,0,0,0,0,0,124,124,124,124,124,0,0,0,0,0,0
0,0,0,0,0,0,0,0,0,0,0,0,0,0,0,0,0,0,0,0,0,0,0,0,0,124,124,124,124,124,124,124,124,124,124,124,124
0,0,0,0,0,0,0,0,0,0,0,0,0,0,0,0,0,0,0,0,0,0,0,0,0,124,33,124,33,124,124,124,124,124,124,124,124
0,0,0,0,0,0,0,0,0,0,0,0,0,0,0,0,0,0,0,0,0,0,0,0,0,124,33,33,33,124,124,124,124,33,33,33,124
0,0,0,0,0,0,0,0,0,0,0,0,0,0,0,0,0,0,0,0,0,0,66,66,0,124,33,33,33,124,124,124,124,124,33,33,124
0,0,0,0,0,0,0,0,0,0,0,0,0,0,0,0,0,0,0,0,0,0,0,0,0,124,33,124,124,124,124,124,124,124,124,124,124
0,0,0,0,0,0,0,0,0,0,0,0,0,0,0,0,0,0,0,0,0,0,0,0,0,124,124,124,124,124,124,0,124,124,124,124,124
0,0,0,0,0,0,0,0,0,0,0,0,0,0,0,0,0,0,0,0,0,0,0,0,0,0,124,124,124,0,0,0,0,0,0,0,0
0,0,0,0,0,0,0,0,0,0,0,0,0,0,0,0,0,0,0,0,0,0,0,0,0,0,0,0,0,0,0,0,0,0,0,0,0
0,0,0,0,0,0,0,0,0,0,0,0,0,0,0,0,0,0,0,0,0,0,0,0,0,0,0,0,0,0,0,0,0,0,0,0,0
0,0,0,0,0,0,0,0,0,0,0,0,0,0,0,0,0,0,0,0,0,0,0,0,0,0,0,0,0,0,0,0,0,0,0,0,0
:endlayer
layer: 18
0,0,0,0,0,0,0,0,0,0,0,0,0,0,0,0,0,0,0,0,0,0,0,0,0,0,0,0,0,0,0,0,0,0,0,0,0
0,0,0,0,0,0,0,0,0,0,0,0,0,0,0,0,0,0,0,0,0,0,0,0,0,0,0,0,0,0,0,0,0,0,0,0,0
0,0,0,0,0,0,0,0,0,0,0,0,0,0,0,0,0,0,0,0,0,0,0,0,0,0,0,0,0,0,0,0,0,0,0,0,0
0,0,0,0,0,0,0,0,0,0,0,0,0,0,0,0,0,0,124,124,0,0,0,0,0,0,0,0,0,0,0,0,0,0,0,0,0
0,0,0,0,0,0,0,0,0,0,0,0,0,0,0,0,0,124,124,124,124,0,0,0,0,0,0,0,0,0,0,0,0,0,0,0,0
0,0,0,0,0,0,0,0,0,0,0,0,0,0,0,0,124,124,124,124,124,124,0,0,0,0,0,0,0,0,0,0,0,0,0,0,0
0,0,0,0,0,0,0,0,0,0,0,0,0,0,0,0,124,124,124,124,124,124,0,0,0,0,0,0,0,0,0,0,0,0,0,0,0
0,0,0,0,0,0,0,0,0,0,0,0,0,0,0,0,0,124,124,124,124,0,0,0,0,0,0,0,0,0,0,0,0,0,0,0,0
0,0,0,0,0,0,0,0,0,0,0,0,0,0,0,0,0,0,124,124,0,0,0,0,0,0,0,0,0,0,0,0,0,0,0,0,0
0,0,0,0,0,0,0,0,0,0,0,0,0,0,0,0,0,0,0,0,0,0,0,0,0,0,0,0,0,0,0,0,0,0,0,0,0
0,0,0,0,0,0,0,0,0,0,0,0,0,0,0,0,0,0,0,0,0,0,0,0,0,0,0,0,0,0,0,0,0,0,0,0,0
0,0,0,0,0,0,0,0,0,0,0,0,0,0,0,0,0,0,0,0,0,0,0,0,0,0,0,0,0,0,0,0,0,0,0,0,0
0,0,0,0,0,0,0,0,0,0,0,0,0,0,0,0,0,0,0,0,0,0,0,0,0,0,0,0,0,0,0,0,0,0,0,0,0
0,0,0,0,0,0,0,0,0,0,0,0,0,0,0,0,0,0,0,0,0,0,0,0,0,0,0,0,0,0,0,0,0,0,0,0,0
0,0,0,0,0,0,0,0,0,0,0,0,0,0,0,0,0,0,0,0,0,0,0,0,0,0,0,0,0,0,0,0,0,0,0,0,0
0,0,0,0,0,0,0,0,0,0,0,0,0,0,0,0,0,0,0,0,0,0,0,0,0,0,0,0,0,0,0,0,0,0,0,0,0
0,0,0,0,0,0,0,0,0,0,0,0,0,0,0,0,0,0,0,0,0,0,0,0,0,0,0,0,0,0,0,0,0,0,0,0,0
0,33,0,33,0,0,0,0,0,0,0,0,0,0,0,0,0,0,0,0,0,0,0,0,0,0,0,0,0,0,0,0,0,0,0,0,0
0,33,33,0,0,0,0,0,0,0,124,124,0,0,0,0,0,0,0,0,0,0,0,0,0,0,0,0,0,0,0,0,0,0,0,0,0
0,33,33,0,0,0,0,0,0,0,124,124,0,0,0,0,0,0,0,0,0,0,0,0,0,0,0,0,0,0,0,0,0,0,0,0,0
33,0,33,0,0,0,0,0,0,0,0,0,0,0,0,0,0,0,0,0,0,0,0,0,0,0,0,0,0,0,0,0,0,0,0,0,0
0,0,0,0,0,0,0,0,0,0,0,0,0,0,0,0,0,0,0,0,0,0,0,0,0,124,124,124,124,124,0,0,124,124,124,124,124
0,0,0,0,0,0,0,0,0,0,0,0,0,0,0,0,0,0,0,0,0,0,0,0,0,124,124,124,124,124,124,0,124,124,124,124,124
0,0,0,0,0,0,0,0,0,0,0,0,0,0,0,0,0,0,0,0,0,0,0,0,124,124,124,124,124,124,124,124,124,124,124,124,124
0,0,0,0,0,0,0,0,0,0,0,0,0,0,0,0,0,0,0,0,0,0,0,0,124,124,124,33,33,124,124,124,124,124,33,33,124
0,0,0,0,0,0,0,0,0,0,0,0,0,0,0,0,0,0,0,0,0,0,0,0,124,124,124,33,33,124,124,124,124,124,33,33,124
0,0,0,0,0,0,0,0,0,0,0,0,0,0,0,0,0,0,0,0,0,0,0,0,124,124,124,124,124,124,124,124,124,124,124,124,124
0,0,0,0,0,0,0,0,0,0,0,0,0,0,0,0,0,0,0,0,0,0,0,0,124,124,124,124,124,124,124,124,124,124,124,124,124
0,0,0,0,0,0,0,0,0,0,0,0,0,0,0,0,0,0,0,0,0,0,0,0,0,124,124,124,124,124,0,0,124,124,124,124,124
0,0,0,0,0,0,0,0,0,0,0,0,0,0,0,0,0,0,0,0,0,0,0,0,0,0,0,0,0,0,0,0,0,0,0,0,0
0,0,0,0,0,0,0,0,0,0,0,0,0,0,0,0,0,0,0,0,0,0,0,0,0,0,0,0,0,0,0,0,0,0,0,0,0
0,0,0,0,0,0,0,0,0,0,0,0,0,0,0,0,0,0,0,0,0,0,0,0,0,0,0,0,0,0,0,0,0,0,0,0,0
:endlayer
layer: 19
0,0,0,0,0,0,0,0,0,0,0,0,0,0,0,0,0,0,0,0,0,0,0,0,0,0,0,0,0,0,0,0,0,0,0,0,0
0,0,0,0,0,0,0,0,0,0,0,0,0,0,0,0,0,0,0,0,0,0,0,0,0,0,0,0,0,0,0,0,0,0,0,0,0
0,0,0,0,0,0,0,0,0,0,0,0,0,0,0,0,0,0,0,0,0,0,0,0,0,0,0,0,0,0,0,0,0,0,0,0,0
0,0,0,0,0,0,0,0,0,0,0,0,0,0,0,0,0,0,0,0,0,0,0,0,0,0,0,0,0,0,0,0,0,0,0,0,0
0,0,0,0,0,0,0,0,0,0,0,0,0,0,0,0,0,0,0,0,0,0,0,0,0,0,0,0,0,0,0,0,0,0,0,0,0
0,0,0,0,0,0,0,0,0,0,0,0,0,0,0,0,0,0,0,0,0,0,0,0,0,0,0,0,0,0,0,0,0,0,0,0,0
0,0,0,0,0,0,0,0,0,0,0,0,0,0,0,0,0,0,0,0,0,0,0,0,0,0,0,0,0,0,0,0,0,0,0,0,0
0,0,0,0,0,0,0,0,0,0,0,0,0,0,0,0,0,0,0,0,0,0,0,0,0,0,0,0,0,0,0,0,0,0,0,0,0
0,0,0,0,0,0,0,0,0,0,0,0,0,0,0,0,0,0,0,0,0,0,0,0,0,0,0,0,0,0,0,0,0,0,0,0,0
0,0,0,0,0,0,0,0,0,0,0,0,0,0,0,0,0,0,0,0,0,0,0,0,0,0,0,0,0,0,0,0,0,0,0,0,0
0,0,0,0,0,0,0,0,0,0,0,0,0,0,0,0,0,0,0,0,0,0,0,0,0,0,0,0,0,0,0,0,0,0,0,0,0
0,0,0,0,0,0,0,0,0,0,0,0,0,0,0,0,0,0,0,0,0,0,0,0,0,0,0,0,0,0,0,0,0,0,0,0,0
0,0,0,0,0,0,0,0,0,0,0,0,0,0,0,0,0,0,0,0,0,0,0,0,0,0,0,0,0,0,0,0,0,0,0,0,0
0,0,0,0,0,0,0,0,0,0,0,0,0,0,0,0,0,0,0,0,0,0,0,0,0,0,0,0,0,0,0,0,0,0,0,0,0
0,0,0,0,0,0,0,0,0,0,0,0,0,0,0,0,0,0,0,0,0,0,0,0,0,0,0,0,0,0,0,0,0,0,0,0,0
0,0,124,124,124,124,124,0,0,0,0,0,0,0,0,0,0,0,0,0,0,0,0,0,0,0,0,0,0,0,0,0,0,0,0,0,0
0,124,124,124,124,124,124,124,0,0,0,0,0,0,0,0,0,0,0,0,0,0,0,0,0,0,0,0,0,0,0,0,0,0,0,0,0
0,33,124,33,124,124,124,124,0,0,0,0,0,0,0,0,0,0,0,0,0,0,0,0,0,0,0,0,0,0,0,0,0,0,0,0,0
0,124,33,33,124,124,124,124,0,0,0,0,0,0,0,0,0,0,0,0,0,0,0,0,0,0,0,0,0,0,0,0,0,0,0,0,0
124,124,33,33,124,124,124,0,0,0,0,0,0,0,0,0,0,0,0,0,0,0,0,0,0,0,0,0,0,0,0,0,0,0,0,0,0
33,124,33,124,124,124,124,0,0,0,0,0,0,0,0,0,0,0,0,0,0,0,0,0,0,0,0,0,0,0,0,0,0,0,0,0,0
124,124,124,124,124,124,124,0,0,0,0,0,0,0,0,0,0,0,0,0,0,0,0,0,0,0,0,0,0,0,0,0,0,0,0,0,0
0,124,124,124,124,124,0,0,0,0,0,0,0,0,0,0,0,0,0,0,0,0,0,0,0,0,0,124,124,0,0,0,0,0,124,124,0
0,0,0,0,0,0,0,0,0,0,0,0,0,0,0,0,0,0,0,0,0,0,0,0,0,0,124,124,124,124,0,0,0,124,124,124,124
0,0,0,0,0,0,0,0,0,0,0,0,0,0,0,0,0,0,0,0,0,0,0,0,0,124,124,124,124,124,124,0,124,124,124,124,124
0,0,0,0,0,0,0,0,0,0,0,0,0,0,0,0,0,0,0,0,0,0,0,0,0,124,124,124,124,124,124,0,124,124,124,124,124
0,0,0,0,0,0,0,0,0,0,0,0,0,0,0,0,0,0,0,0,0,0,0,0,0,0,124,124,124,124,0,0,0,124,124,124,124
0,0,0,0,0,0,0,0,0,0,0,0,0,0,0,0,0,0,0,0,0,0,0,0,0,0,0,124,124,0,0,0,0,0,124,124,0
0,0,0,0,0,0,0,0,0,0,0,0,0,0,0,0,0,0,0,0,0,0,0,0,0,0,0,0,0,0,0,0,0,0,0,0,0
0,0,0,0,0,0,0,0,0,0,0,0,0,0,0,0,0,0,0,0,0,0,0,0,0,0,0,0,0,0,0,0,0,0,0,0,0
0,0,0,0,0,0,0,0,0,0,0,0,0,0,0,0,0,0,0,0,0,0,0,0,0,0,0,0,0,0,0,0,0,0,0,0,0
0,0,0,0,0,0,0,0,0,0,0,0,0,0,0,0,0,0,0,0,0,0,0,0,0,0,0,0,0,0,0,0,0,0,0,0,0
:endlayer
layer: 20
0,0,0,0,0,0,0,0,0,0,0,0,0,0,0,0,0,0,0,0,0,0,0,0,0,0,0,0,0,0,0,0,0,0,0,0,0
0,0,0,0,0,0,0,0,0,0,0,0,0,0,0,0,0,0,0,0,0,0,0,0,0,0,0,0,0,0,0,0,0,0,0,0,0
0,0,0,0,0,0,0,0,0,0,0,0,0,0,0,0,0,0,0,0,0,0,0,0,0,0,0,0,0,0,0,0,0,0,0,0,0
0,0,0,0,0,0,0,0,0,0,0,0,0,0,0,0,0,0,0,0,0,0,0,0,0,0,0,0,0,0,0,0,0,0,0,0,0
0,0,0,0,0,0,0,0,0,0,0,0,0,0,0,0,0,0,0,0,0,0,0,0,0,0,0,0,0,0,0,0,0,0,0,0,0
0,0,0,0,0,0,0,0,0,0,0,0,0,0,0,0,0,0,0,0,0,0,0,0,0,0,0,0,0,0,0,0,0,0,0,0,0
0,0,0,0,0,0,0,0,0,0,0,0,0,0,0,0,0,0,0,0,0,0,0,0,0,0,0,0,0,0,0,0,0,0,0,0,0
0,0,0,0,0,0,0,0,0,0,0,0,0,0,0,0,0,0,0,0,0,0,0,0,0,0,0,0,0,0,0,0,0,0,0,0,0
0,0,0,0,0,0,0,0,0,0,0,0,0,0,0,0,0,0,0,0,0,0,0,0,0,0,0,0,0,0,0,0,0,0,0,0,0
0,0,0,0,0,0,0,0,0,0,0,0,0,0,0,0,0,0,0,0,0,0,0,0,0,0,0,0,0,0,0,0,0,0,0,0,0
0,0,0,0,0,0,0,0,0,0,0,0,0,0,0,0,0,0,0,0,0,0,0,0,0,0,0,0,0,0,0,0,0,0,0,0,0
0,0,0,0,0,0,0,0,0,0,0,0,0,0,0,0,0,0,0,0,0,0,0,0,0,0,0,0,0,0,0,0,0,0,0,0,0
0,0,0,0,0,0,0,0,0,0,0,0,0,0,0,0,0,0,0,0,0,0,0,0,0,0,0,0,0,0,0,0,0,0,0,0,0
0,0,0,0,0,0,0,0,0,0,0,0,0,0,0,0,0,0,0,0,0,0,0,0,0,0,0,0,0,0,0,0,0,0,0,0,0
0,0,0,0,0,0,0,0,0,0,0,0,0,0,0,0,0,0,0,0,0,0,0,0,0,0,0,0,0,0,0,0,0,0,0,0,0
0,124,124,124,124,124,0,0,0,0,0,0,0,0,0,0,0,0,0,0,0,0,0,0,0,0,0,0,0,0,0,0,0,0,0,0,0
0,124,124,124,124,124,124,0,0,0,0,0,0,0,0,0,0,0,0,0,0,0,0,0,0,0,0,0,0,0,0,0,0,0,0,0,0
124,124,124,124,124,124,124,124,0,0,0,0,0,0,0,0,0,0,0,0,0,0,0,0,0,0,0,0,0,0,0,0,0,0,0,0,0
124,124,124,33,33,124,124,124,0,0,0,0,0,0,0,0,0,0,0,0,0,0,0,0,0,0,0,0,0,0,0,0,0,0,0,0,0
124,124,124,33,33,124,124,124,0,0,0,0,0,0,0,0,0,0,0,0,0,0,0,0,0,0,0,0,0,0,0,0,0,0,0,0,0
124,124,124,124,124,124,124,124,0,0,0,0,0,0,0,0,0,0,0,0,0,0,0,0,0,0,0,0,0,0,0,0,0,0,0,0,0
124,124,124,124,124,124,124,124,0,0,0,0,0,0,0,0,0,0,0,0,0,0,0,0,0,0,0,0,0,0,0,0,0,0,0,0,0
0,124,124,124,124,124,0,0,0,0,0,0,0,0,0,0,0,0,0,0,0,0,0,0,0,0,0,0,0,0,0,0,0,0,0,0,0
0,0,0,0,0,0,0,0,0,0,0,0,0,0,0,0,0,0,0,0,0,0,0,0,0,0,0,0,0,0,0,0,0,0,0,0,0
0,0,0,0,0,0,0,0,0,0,0,0,0,0,0,0,0,0,0,0,0,0,0,0,0,0,0,0,0,0,0,0,0,0,124,124,0
0,0,0,0,0,0,0,0,0,0,0,0,0,0,0,0,0,0,0,0,0,0,0,0,0,0,0,0,0,0,0,0,0,0,124,124,0
0,0,0,0,0,0,0,0,0,0,0,0,0,0,0,0,0,0,0,0,0,0,0,0,0,0,0,0,0,0,0,0,0,0,0,0,0
0,0,0,0,0,0,0,0,0,0,0,0,0,0,0,0,0,0,0,0,0,0,0,0,0,0,0,0,0,0,0,0,0,0,0,0,0
0,0,0,0,0,0,0,0,0,0,0,0,0,0,0,0,0,0,0,0,0,0,0,0,0,0,0,0,0,0,0,0,0,0,0,0,0
0,0,0,0,0,0,0,0,0,0,0,0,0,0,0,0,0,0,0,0,0,0,0,0,0,0,0,0,0,0,0,0,0,0,0,0,0
0,0,0,0,0,0,0,0,0,0,0,0,0,0,0,0,0,0,0,0,0,0,0,0,0,0,0,0,0,0,0,0,0,0,0,0,0
0,0,0,0,0,0,0,0,0,0,0,0,0,0,0,0,0,0,0,0,0,0,0,0,0,0,0,0,0,0,0,0,0,0,0,0,0
:endlayer
layer: 21
0,0,0,0,0,0,0,0,0,0,0,0,0,0,0,0,0,0,0,0,0,0,0,0,0,0,0,0,0,0,0,0,0,0,0,0,0
0,0,0,0,0,0,0,0,0,0,0,0,0,0,0,0,0,0,0,0,0,0,0,0,0,0,0,0,0,0,0,0,0,0,0,0,0
0,0,0,0,0,0,0,0,0,0,0,0,0,0,0,0,0,0,0,0,0,0,0,0,0,0,0,0,0,0,0,0,0,0,0,0,0
0,0,0,0,0,0,0,0,0,0,0,0,0,0,0,0,0,0,0,0,0,0,0,0,0,0,0,0,0,0,0,0,0,0,0,0,0
0,0,0,0,0,0,0,0,0,0,0,0,0,0,0,0,0,0,0,0,0,0,0,0,0,0,0,0,0,0,0,0,0,0,0,0,0
0,0,0,0,0,0,0,0,0,0,0,0,0,0,0,0,0,0,0,0,0,0,0,0,0,0,0,0,0,0,0,0,0,0,0,0,0
0,0,0,0,0,0,0,0,0,0,0,0,0,0,0,0,0,0,0,0,0,0,0,0,0,0,0,0,0,0,0,0,0,0,0,0,0
0,0,0,0,0,0,0,0,0,0,0,0,0,0,0,0,0,0,0,0,0,0,0,0,0,0,0,0,0,0,0,0,0,0,0,0,0
0,0,0,0,0,0,0,0,0,0,0,0,0,0,0,0,0,0,0,0,0,0,0,0,0,0,0,0,0,0,0,0,0,0,0,0,0
0,0,0,0,0,0,0,0,0,0,0,0,0,0,0,0,0,0,0,0,0,0,0,0,0,0,0,0,0,0,0,0,0,0,0,0,0
0,0,0,0,0,0,0,0,0,0,0,0,0,0,0,0,0,0,0,0,0,0,0,0,0,0,0,0,0,0,0,0,0,0,0,0,0
0,0,0,0,0,0,0,0,0,0,0,0,0,0,0,0,0,0,0,0,0,0,0,0,0,0,0,0,0,0,0,0,0,0,0,0,0
0,0,0,0,0,0,0,0,0,0,0,0,0,0,0,0,0,0,0,0,0,0,0,0,0,0,0,0,0,0,0,0,0,0,0,0,0
0,0,0,0,0,0,0,0,0,0,0,0,0,0,0,0,0,0,0,0,0,0,0,0,0,0,0,0,0,0,0,0,0,0,0,0,0
0,0,0,0,0,0,0,0,0,0,0,0,0,0,0,0,0,0,0,0,0,0,0,0,0,0,0,0,0,0,0,0,0,0,0,0,0
0,0,0,0,0,0,0,0,0,0,0,0,0,0,0,0,0,0,0,0,0,0,0,0,0,0,0,0,0,0,0,0,0,0,0,0,0
0,0,0,124,124,0,0,0,0,0,0,0,0,0,0,0,0,0,0,0,0,0,0,0,0,0,0,0,0,0,0,0,0,0,0,0,0
0,0,124,124,124,124,0,0,0,0,0,0,0,0,0,0,0,0,0,0,0,0,0,0,0,0,0,0,0,0,0,0,0,0,0,0,0
0,124,124,124,124,124,124,0,0,0,0,0,0,0,0,0,0,0,0,0,0,0,0,0,0,0,0,0,0,0,0,0,0,0,0,0,0
0,124,124,124,124,124,124,0,0,0,0,0,0,0,0,0,0,0,0,0,0,0,0,0,0,0,0,0,0,0,0,0,0,0,0,0,0
0,0,124,124,124,124,0,0,0,0,0,0,0,0,0,0,0,0,0,0,0,0,0,0,0,0,0,0,0,0,0,0,0,0,0,0,0
0,0,0,124,124,0,0,0,0,0,0,0,0,0,0,0,0,0,0,0,0,0,0,0,0,0,0,0,0,0,0,0,0,0,0,0,0
0,0,0,0,0,0,0,0,0,0,0,0,0,0,0,0,0,0,0,0,0,0,0,0,0,0,0,0,0,0,0,0,0,0,0,0,0
0,0,0,0,0,0,0,0,0,0,0,0,0,0,0,0,0,0,0,0,0,0,0,0,0,0,0,0,0,0,0,0,0,0,0,0,0
0,0,0,0,0,0,0,0,0,0,0,0,0,0,0,0,0,0,0,0,0,0,0,0,0,0,0,0,0,0,0,0,0,0,0,0,0
0,0,0,0,0,0,0,0,0,0,0,0,0,0,0,0,0,0,0,0,0,0,0,0,0,0,0,0,0,0,0,0,0,0,0,0,0
0,0,0,0,0,0,0,0,0,0,0,0,0,0,0,0,0,0,0,0,0,0,0,0,0,0,0,0,0,0,0,0,0,0,0,0,0
0,0,0,0,0,0,0,0,0,0,0,0,0,0,0,0,0,0,0,0,0,0,0,0,0,0,0,0,0,0,0,0,0,0,0,0,0
0,0,0,0,0,0,0,0,0,0,0,0,0,0,0,0,0,0,0,0,0,0,0,0,0,0,0,0,0,0,0,0,0,0,0,0,0
0,0,0,0,0,0,0,0,0,0,0,0,0,0,0,0,0,0,0,0,0,0,0,0,0,0,0,0,0,0,0,0,0,0,0,0,0
0,0,0,0,0,0,0,0,0,0,0,0,0,0,0,0,0,0,0,0,0,0,0,0,0,0,0,0,0,0,0,0,0,0,0,0,0
0,0,0,0,0,0,0,0,0,0,0,0,0,0,0,0,0,0,0,0,0,0,0,0,0,0,0,0,0,0,0,0,0,0,0,0,0
:endlayer

#### RULES ####
rule:
plugin=vanillaBlocks
number=1
data:
JSON:{blockState:{blockName:"minecraft:dirt",properties:{variant:"dirt",snowy:"false"}}}
:enddata
:endrule

rule:
plugin=vanillaBlocks
number=2
data:
JSON:{blockState:{blockName:"minecraft:grass",properties:{snowy:"false"}}}
:enddata
:endrule

rule:
plugin=vanillaBlocks
number=3
data:
JSON:{blockState:{blockName:"minecraft:wooden_slab",properties:{half:"bottom",variant:"dark_oak"}}}
:enddata
:endrule

rule:
plugin=vanillaBlocks
number=4
data:
JSON:{blockState:{blockName:"minecraft:stained_hardened_clay",properties:{color:"brown"}}}
:enddata
:endrule

rule:
plugin=vanillaBlocks
number=5
data:
JSON:{blockState:{blockName:"minecraft:planks",properties:{variant:"dark_oak"}}}
:enddata
:endrule

rule:
plugin=inventory
number=6
data:
JSON:{blockState:{blockName:"minecraft:furnace",properties:{facing:"south"}},lootLevel:0,teData:{CookTime:0,BurnTime:0,Items:[],id:"minecraft:furnace",CookTimeTotal:0,Lock:""},inventoryData:{length:0,inventoryContents:[]},legacyFeatures:0b}
:enddata
:endrule

rule:
plugin=blockTile
number=7
data:
JSON:{blockState:{blockName:"ancientwarfarestructure:advanced_spawner",properties:{transparent:"true"}},teData:{id:"ancientwarfarestructure:advanced_spawner_tile",spawnerSettings:{minDelay:0,spawnDelay:0,lightSensitive:0b,spawnGroups:[{settingsList:[{remainingSpawnCount:1,hostile:1b,forced:1b,customTag:{factionName:"orc"},maxToSpawn:1,entityId:"ancientwarfarenpc:faction.civilian.female",minToSpawn:1}],groupWeight:1}],playerRange:6,respondToRedstone:0b,inventory:{Size:9,Items:[]},spawnRange:0,transparent:1b,maxDelay:0,xpToDrop:0,mobRange:0,debugMode:0b,maxNearbyMonsters:0}}}
:enddata
:endrule

rule:
plugin=inventory
number=8
data:
JSON:{blockState:{blockName:"minecraft:chest",properties:{facing:"north"}},lootLevel:0,teData:{ForgeData:{},Items:[{Slot:2b,id:"minecraft:slime_ball",Count:9b,Damage:0s},{Slot:7b,id:"minecraft:gold_nugget",Count:6b,Damage:0s},{Slot:10b,id:"minecraft:rotten_flesh",Count:7b,Damage:0s},{Slot:13b,id:"minecraft:bone",Count:12b,Damage:0s},{Slot:14b,id:"minecraft:dye",Count:2b,Damage:4s},{Slot:15b,id:"minecraft:rotten_flesh",Count:8b,Damage:0s},{Slot:17b,id:"minecraft:coal",Count:6b,Damage:0s},{Slot:18b,id:"ancientwarfarenpc:coin",Count:6b,tag:{metal:"gold"},Damage:0s},{Slot:19b,id:"ancientwarfarenpc:coin",Count:8b,tag:{metal:"silver"},Damage:0s},{Slot:20b,id:"ancientwarfarenpc:coin",Count:18b,tag:{metal:"copper"},Damage:0s},{Slot:21b,id:"minecraft:spider_eye",Count:4b,Damage:0s},{Slot:23b,id:"minecraft:poisonous_potato",Count:12b,Damage:0s},{Slot:24b,id:"minecraft:poisonous_potato",Count:5b,Damage:0s},{Slot:25b,id:"minecraft:brown_mushroom",Count:5b,Damage:0s},{Slot:26b,id:"minecraft:red_mushroom",Count:5b,Damage:0s}],id:"minecraft:chest",Lock:""},inventoryData:{length:15,inventoryContents:[{id:"minecraft:slime_ball",Count:9b,slot:0,Damage:0s},{id:"minecraft:gold_nugget",Count:6b,slot:1,Damage:0s},{id:"minecraft:rotten_flesh",Count:7b,slot:2,Damage:0s},{id:"minecraft:bone",Count:12b,slot:3,Damage:0s},{id:"minecraft:dye",Count:2b,slot:4,Damage:4s},{id:"minecraft:rotten_flesh",Count:8b,slot:5,Damage:0s},{id:"minecraft:coal",Count:6b,slot:6,Damage:0s},{id:"ancientwarfarenpc:coin",Count:6b,tag:{metal:"gold"},slot:7,Damage:0s},{id:"ancientwarfarenpc:coin",Count:8b,tag:{metal:"silver"},slot:8,Damage:0s},{id:"ancientwarfarenpc:coin",Count:18b,tag:{metal:"copper"},slot:9,Damage:0s},{id:"minecraft:spider_eye",Count:4b,slot:10,Damage:0s},{id:"minecraft:poisonous_potato",Count:12b,slot:11,Damage:0s},{id:"minecraft:poisonous_potato",Count:5b,slot:12,Damage:0s},{id:"minecraft:brown_mushroom",Count:5b,slot:13,Damage:0s},{id:"minecraft:red_mushroom",Count:5b,slot:14,Damage:0s}]},legacyFeatures:1b}
:enddata
:endrule

rule:
plugin=vanillaBlocks
number=9
data:
JSON:{blockState:{blockName:"minecraft:crafting_table"}}
:enddata
:endrule

rule:
plugin=vanillaBlocks
number=10
data:
JSON:{blockState:{blockName:"minecraft:fence",properties:{east:"false",south:"false",north:"false",west:"false"}}}
:enddata
:endrule

rule:
plugin=blockTile
number=11
data:
JSON:{blockState:{blockName:"ancientwarfarestructure:advanced_spawner",properties:{transparent:"true"}},teData:{id:"ancientwarfarestructure:advanced_spawner_tile",spawnerSettings:{minDelay:0,spawnDelay:0,lightSensitive:0b,spawnGroups:[{settingsList:[{remainingSpawnCount:1,hostile:1b,forced:1b,customTag:{factionName:"orc"},maxToSpawn:1,entityId:"ancientwarfarenpc:faction.soldier",minToSpawn:1}],groupWeight:1}],playerRange:6,respondToRedstone:0b,inventory:{Size:9,Items:[]},spawnRange:0,transparent:1b,maxDelay:0,xpToDrop:0,mobRange:0,debugMode:0b,maxNearbyMonsters:0}}}
:enddata
:endrule

rule:
plugin=blockTile
number=12
data:
JSON:{blockState:{blockName:"ancientwarfarestructure:advanced_spawner",properties:{transparent:"true"}},teData:{id:"ancientwarfarestructure:advanced_spawner_tile",spawnerSettings:{minDelay:0,spawnDelay:0,lightSensitive:0b,spawnGroups:[{settingsList:[{remainingSpawnCount:1,hostile:1b,forced:1b,customTag:{factionName:"orc"},maxToSpawn:1,entityId:"ancientwarfarenpc:faction.soldier",minToSpawn:1}],groupWeight:1}],playerRange:6,respondToRedstone:0b,inventory:{Size:9,Items:[]},spawnRange:0,transparent:1b,maxDelay:0,xpToDrop:0,mobRange:0,debugMode:0b,maxNearbyMonsters:0}}}
:enddata
:endrule

rule:
plugin=inventory
number=13
data:
JSON:{blockState:{blockName:"minecraft:furnace",properties:{facing:"north"}},lootLevel:0,teData:{CookTime:0,BurnTime:0,Items:[],id:"minecraft:furnace",CookTimeTotal:0,Lock:""},inventoryData:{length:0,inventoryContents:[]},legacyFeatures:0b}
:enddata
:endrule

rule:
plugin=inventory
number=14
data:
JSON:{blockState:{blockName:"minecraft:chest",properties:{facing:"south"}},lootLevel:0,teData:{ForgeData:{},Items:[{Slot:1b,id:"minecraft:rotten_flesh",Count:2b,Damage:0s},{Slot:2b,id:"minecraft:rotten_flesh",Count:5b,Damage:0s},{Slot:3b,id:"minecraft:rotten_flesh",Count:5b,Damage:0s},{Slot:4b,id:"minecraft:rotten_flesh",Count:4b,Damage:0s},{Slot:5b,id:"minecraft:rotten_flesh",Count:1b,Damage:0s},{Slot:6b,id:"minecraft:brown_mushroom",Count:5b,Damage:0s},{Slot:8b,id:"minecraft:coal",Count:5b,Damage:0s},{Slot:11b,id:"minecraft:slime_ball",Count:8b,Damage:0s},{Slot:12b,id:"minecraft:poisonous_potato",Count:9b,Damage:0s},{Slot:13b,id:"minecraft:rotten_flesh",Count:3b,Damage:0s},{Slot:14b,id:"minecraft:rotten_flesh",Count:1b,Damage:0s},{Slot:16b,id:"minecraft:gold_nugget",Count:8b,Damage:0s},{Slot:18b,id:"minecraft:spider_eye",Count:8b,Damage:0s},{Slot:19b,id:"ancientwarfarenpc:coin",Count:2b,tag:{metal:"gold"},Damage:0s},{Slot:20b,id:"ancientwarfarenpc:coin",Count:3b,tag:{metal:"silver"},Damage:0s},{Slot:21b,id:"ancientwarfarenpc:coin",Count:5b,tag:{metal:"copper"},Damage:0s},{Slot:22b,id:"minecraft:bone",Count:6b,Damage:0s},{Slot:23b,id:"minecraft:bone",Count:6b,Damage:0s},{Slot:24b,id:"minecraft:dye",Count:5b,Damage:4s},{Slot:26b,id:"minecraft:red_mushroom",Count:6b,Damage:0s}],id:"minecraft:chest",Lock:""},inventoryData:{length:20,inventoryContents:[{id:"minecraft:rotten_flesh",Count:2b,slot:0,Damage:0s},{id:"minecraft:rotten_flesh",Count:5b,slot:1,Damage:0s},{id:"minecraft:rotten_flesh",Count:5b,slot:2,Damage:0s},{id:"minecraft:rotten_flesh",Count:4b,slot:3,Damage:0s},{id:"minecraft:rotten_flesh",Count:1b,slot:4,Damage:0s},{id:"minecraft:brown_mushroom",Count:5b,slot:5,Damage:0s},{id:"minecraft:coal",Count:5b,slot:6,Damage:0s},{id:"minecraft:slime_ball",Count:8b,slot:7,Damage:0s},{id:"minecraft:poisonous_potato",Count:9b,slot:8,Damage:0s},{id:"minecraft:rotten_flesh",Count:3b,slot:9,Damage:0s},{id:"minecraft:rotten_flesh",Count:1b,slot:10,Damage:0s},{id:"minecraft:gold_nugget",Count:8b,slot:11,Damage:0s},{id:"minecraft:spider_eye",Count:8b,slot:12,Damage:0s},{id:"ancientwarfarenpc:coin",Count:2b,tag:{metal:"gold"},slot:13,Damage:0s},{id:"ancientwarfarenpc:coin",Count:3b,tag:{metal:"silver"},slot:14,Damage:0s},{id:"ancientwarfarenpc:coin",Count:5b,tag:{metal:"copper"},slot:15,Damage:0s},{id:"minecraft:bone",Count:6b,slot:16,Damage:0s},{id:"minecraft:bone",Count:6b,slot:17,Damage:0s},{id:"minecraft:dye",Count:5b,slot:18,Damage:4s},{id:"minecraft:red_mushroom",Count:6b,slot:19,Damage:0s}]},legacyFeatures:1b}
:enddata
:endrule

rule:
plugin=blockTile
number=15
data:
JSON:{blockState:{blockName:"ancientwarfarestructure:advanced_spawner",properties:{transparent:"true"}},teData:{id:"ancientwarfarestructure:advanced_spawner_tile",spawnerSettings:{minDelay:0,spawnDelay:0,lightSensitive:0b,spawnGroups:[{settingsList:[{remainingSpawnCount:1,hostile:1b,forced:1b,customTag:{factionName:"orc"},maxToSpawn:1,entityId:"ancientwarfarenpc:faction.archer",minToSpawn:1}],groupWeight:1}],playerRange:8,respondToRedstone:0b,inventory:{Size:9,Items:[]},spawnRange:0,transparent:1b,maxDelay:0,xpToDrop:0,mobRange:0,debugMode:0b,maxNearbyMonsters:0}}}
:enddata
:endrule

rule:
plugin=blockTile
number=16
data:
JSON:{blockState:{blockName:"ancientwarfarestructure:advanced_spawner",properties:{transparent:"true"}},teData:{id:"ancientwarfarestructure:advanced_spawner_tile",spawnerSettings:{minDelay:0,spawnDelay:0,lightSensitive:0b,spawnGroups:[{settingsList:[{remainingSpawnCount:1,hostile:1b,forced:1b,customTag:{factionName:"orc"},maxToSpawn:1,entityId:"ancientwarfarenpc:faction.archer",minToSpawn:1}],groupWeight:1}],playerRange:8,respondToRedstone:0b,inventory:{Size:9,Items:[]},spawnRange:0,transparent:1b,maxDelay:0,xpToDrop:0,mobRange:0,debugMode:0b,maxNearbyMonsters:0}}}
:enddata
:endrule

rule:
plugin=inventory
number=17
data:
JSON:{blockState:{blockName:"minecraft:furnace",properties:{facing:"south"}},lootLevel:0,teData:{CookTime:0,BurnTime:0,Items:[],id:"minecraft:furnace",CookTimeTotal:0,Lock:""},inventoryData:{length:0,inventoryContents:[]},legacyFeatures:0b}
:enddata
:endrule

rule:
plugin=blockTile
number=18
data:
JSON:{blockState:{blockName:"ancientwarfarestructure:advanced_spawner",properties:{transparent:"true"}},teData:{id:"ancientwarfarestructure:advanced_spawner_tile",spawnerSettings:{minDelay:0,spawnDelay:0,lightSensitive:0b,spawnGroups:[{settingsList:[{remainingSpawnCount:1,hostile:1b,forced:1b,customTag:{factionName:"orc"},maxToSpawn:1,entityId:"ancientwarfarenpc:faction.archer",minToSpawn:1}],groupWeight:1}],playerRange:8,respondToRedstone:0b,inventory:{Size:9,Items:[]},spawnRange:0,transparent:1b,maxDelay:0,xpToDrop:0,mobRange:0,debugMode:0b,maxNearbyMonsters:0}}}
:enddata
:endrule

rule:
plugin=blockTile
number=19
data:
JSON:{blockState:{blockName:"ancientwarfarestructure:advanced_spawner",properties:{transparent:"true"}},teData:{id:"ancientwarfarestructure:advanced_spawner_tile",spawnerSettings:{minDelay:0,spawnDelay:0,lightSensitive:0b,spawnGroups:[{settingsList:[{remainingSpawnCount:1,hostile:1b,forced:1b,customTag:{factionName:"orc"},maxToSpawn:1,entityId:"ancientwarfarenpc:faction.civilian.female",minToSpawn:1}],groupWeight:1}],playerRange:6,respondToRedstone:0b,inventory:{Size:9,Items:[]},spawnRange:0,transparent:1b,maxDelay:0,xpToDrop:0,mobRange:0,debugMode:0b,maxNearbyMonsters:0}}}
:enddata
:endrule

rule:
plugin=inventory
number=20
data:
JSON:{blockState:{blockName:"minecraft:chest",properties:{facing:"north"}},lootLevel:0,teData:{ForgeData:{},Items:[{Slot:1b,id:"ancientwarfarenpc:coin",Count:12b,tag:{metal:"copper"},Damage:0s},{Slot:2b,id:"ancientwarfarenpc:coin",Count:5b,tag:{metal:"silver"},Damage:0s},{Slot:3b,id:"ancientwarfarenpc:coin",Count:3b,tag:{metal:"gold"},Damage:0s},{Slot:11b,id:"minecraft:slime_ball",Count:5b,Damage:0s},{Slot:13b,id:"minecraft:bone",Count:6b,Damage:0s},{Slot:14b,id:"minecraft:dye",Count:3b,Damage:4s},{Slot:15b,id:"minecraft:gold_nugget",Count:4b,Damage:0s},{Slot:16b,id:"minecraft:red_mushroom",Count:4b,Damage:0s},{Slot:19b,id:"minecraft:rotten_flesh",Count:14b,Damage:0s},{Slot:21b,id:"minecraft:spider_eye",Count:5b,Damage:0s},{Slot:23b,id:"minecraft:bone",Count:6b,Damage:0s},{Slot:25b,id:"minecraft:brown_mushroom",Count:4b,Damage:0s},{Slot:26b,id:"minecraft:coal",Count:7b,Damage:0s}],id:"minecraft:chest",Lock:""},inventoryData:{length:13,inventoryContents:[{id:"ancientwarfarenpc:coin",Count:12b,tag:{metal:"copper"},slot:0,Damage:0s},{id:"ancientwarfarenpc:coin",Count:5b,tag:{metal:"silver"},slot:1,Damage:0s},{id:"ancientwarfarenpc:coin",Count:3b,tag:{metal:"gold"},slot:2,Damage:0s},{id:"minecraft:slime_ball",Count:5b,slot:3,Damage:0s},{id:"minecraft:bone",Count:6b,slot:4,Damage:0s},{id:"minecraft:dye",Count:3b,slot:5,Damage:4s},{id:"minecraft:gold_nugget",Count:4b,slot:6,Damage:0s},{id:"minecraft:red_mushroom",Count:4b,slot:7,Damage:0s},{id:"minecraft:rotten_flesh",Count:14b,slot:8,Damage:0s},{id:"minecraft:spider_eye",Count:5b,slot:9,Damage:0s},{id:"minecraft:bone",Count:6b,slot:10,Damage:0s},{id:"minecraft:brown_mushroom",Count:4b,slot:11,Damage:0s},{id:"minecraft:coal",Count:7b,slot:12,Damage:0s}]},legacyFeatures:1b}
:enddata
:endrule

rule:
plugin=blockTile
number=21
data:
JSON:{blockState:{blockName:"ancientwarfarestructure:advanced_spawner",properties:{transparent:"true"}},teData:{id:"ancientwarfarestructure:advanced_spawner_tile",spawnerSettings:{minDelay:0,spawnDelay:0,lightSensitive:0b,spawnGroups:[{settingsList:[{remainingSpawnCount:1,hostile:1b,forced:1b,customTag:{factionName:"orc"},maxToSpawn:1,entityId:"ancientwarfarenpc:faction.soldier",minToSpawn:1}],groupWeight:1}],playerRange:6,respondToRedstone:0b,inventory:{Size:9,Items:[]},spawnRange:0,transparent:1b,maxDelay:0,xpToDrop:0,mobRange:0,debugMode:0b,maxNearbyMonsters:0}}}
:enddata
:endrule

rule:
plugin=blockTile
number=22
data:
JSON:{blockState:{blockName:"ancientwarfarestructure:advanced_spawner",properties:{transparent:"true"}},teData:{id:"ancientwarfarestructure:advanced_spawner_tile",spawnerSettings:{minDelay:0,spawnDelay:0,lightSensitive:0b,spawnGroups:[{settingsList:[{remainingSpawnCount:1,hostile:1b,forced:1b,customTag:{factionName:"orc"},maxToSpawn:1,entityId:"ancientwarfarenpc:faction.soldier",minToSpawn:1}],groupWeight:1}],playerRange:6,respondToRedstone:0b,inventory:{Size:9,Items:[]},spawnRange:0,transparent:1b,maxDelay:0,xpToDrop:0,mobRange:0,debugMode:0b,maxNearbyMonsters:0}}}
:enddata
:endrule

rule:
plugin=inventory
number=23
data:
JSON:{blockState:{blockName:"minecraft:chest",properties:{facing:"south"}},lootLevel:0,teData:{ForgeData:{},Items:[{Slot:5b,id:"minecraft:bone",Count:4b,Damage:0s},{Slot:6b,id:"ancientwarfarenpc:coin",Count:2b,tag:{metal:"gold"},Damage:0s},{Slot:7b,id:"ancientwarfarenpc:coin",Count:4b,tag:{metal:"silver"},Damage:0s},{Slot:8b,id:"ancientwarfarenpc:coin",Count:10b,tag:{metal:"copper"},Damage:0s},{Slot:11b,id:"minecraft:slime_ball",Count:7b,Damage:0s},{Slot:12b,id:"minecraft:spider_eye",Count:8b,Damage:0s},{Slot:13b,id:"minecraft:bone",Count:6b,Damage:0s},{Slot:14b,id:"minecraft:bone",Count:6b,Damage:0s},{Slot:15b,id:"minecraft:brown_mushroom",Count:5b,Damage:0s},{Slot:16b,id:"minecraft:red_mushroom",Count:5b,Damage:0s},{Slot:17b,id:"minecraft:coal",Count:5b,Damage:0s},{Slot:19b,id:"minecraft:rotten_flesh",Count:6b,Damage:0s},{Slot:20b,id:"minecraft:rotten_flesh",Count:5b,Damage:0s},{Slot:21b,id:"minecraft:rotten_flesh",Count:2b,Damage:0s},{Slot:22b,id:"minecraft:rotten_flesh",Count:1b,Damage:0s},{Slot:25b,id:"minecraft:dye",Count:4b,Damage:4s}],id:"minecraft:chest",Lock:""},inventoryData:{length:16,inventoryContents:[{id:"minecraft:bone",Count:4b,slot:0,Damage:0s},{id:"ancientwarfarenpc:coin",Count:2b,tag:{metal:"gold"},slot:1,Damage:0s},{id:"ancientwarfarenpc:coin",Count:4b,tag:{metal:"silver"},slot:2,Damage:0s},{id:"ancientwarfarenpc:coin",Count:10b,tag:{metal:"copper"},slot:3,Damage:0s},{id:"minecraft:slime_ball",Count:7b,slot:4,Damage:0s},{id:"minecraft:spider_eye",Count:8b,slot:5,Damage:0s},{id:"minecraft:bone",Count:6b,slot:6,Damage:0s},{id:"minecraft:bone",Count:6b,slot:7,Damage:0s},{id:"minecraft:brown_mushroom",Count:5b,slot:8,Damage:0s},{id:"minecraft:red_mushroom",Count:5b,slot:9,Damage:0s},{id:"minecraft:coal",Count:5b,slot:10,Damage:0s},{id:"minecraft:rotten_flesh",Count:6b,slot:11,Damage:0s},{id:"minecraft:rotten_flesh",Count:5b,slot:12,Damage:0s},{id:"minecraft:rotten_flesh",Count:2b,slot:13,Damage:0s},{id:"minecraft:rotten_flesh",Count:1b,slot:14,Damage:0s},{id:"minecraft:dye",Count:4b,slot:15,Damage:4s}]},legacyFeatures:1b}
:enddata
:endrule

rule:
plugin=blockTile
number=24
data:
JSON:{blockState:{blockName:"ancientwarfarestructure:advanced_spawner",properties:{transparent:"true"}},teData:{id:"ancientwarfarestructure:advanced_spawner_tile",spawnerSettings:{minDelay:0,spawnDelay:0,lightSensitive:0b,spawnGroups:[{settingsList:[{remainingSpawnCount:1,hostile:1b,forced:1b,customTag:{factionName:"orc"},maxToSpawn:1,entityId:"ancientwarfarenpc:faction.civilian.female",minToSpawn:1}],groupWeight:1}],playerRange:6,respondToRedstone:0b,inventory:{Size:9,Items:[]},spawnRange:0,transparent:1b,maxDelay:0,xpToDrop:0,mobRange:0,debugMode:0b,maxNearbyMonsters:0}}}
:enddata
:endrule

rule:
plugin=blockTile
number=25
data:
JSON:{blockState:{blockName:"ancientwarfarestructure:advanced_spawner",properties:{transparent:"true"}},teData:{id:"ancientwarfarestructure:advanced_spawner_tile",spawnerSettings:{minDelay:0,spawnDelay:0,lightSensitive:0b,spawnGroups:[{settingsList:[{remainingSpawnCount:1,hostile:1b,forced:1b,customTag:{factionName:"orc"},maxToSpawn:1,entityId:"ancientwarfarenpc:faction.archer",minToSpawn:1}],groupWeight:1}],playerRange:8,respondToRedstone:0b,inventory:{Size:9,Items:[]},spawnRange:0,transparent:1b,maxDelay:0,xpToDrop:0,mobRange:0,debugMode:0b,maxNearbyMonsters:0}}}
:enddata
:endrule

rule:
plugin=inventory
number=26
data:
JSON:{blockState:{blockName:"minecraft:furnace",properties:{facing:"north"}},lootLevel:0,teData:{CookTime:0,BurnTime:0,Items:[],id:"minecraft:furnace",CookTimeTotal:0,Lock:""},inventoryData:{length:0,inventoryContents:[]},legacyFeatures:0b}
:enddata
:endrule

rule:
plugin=vanillaBlocks
number=27
data:
JSON:{blockState:{blockName:"minecraft:gravel"}}
:enddata
:endrule

rule:
plugin=vanillaBlocks
number=28
data:
JSON:{blockState:{blockName:"minecraft:cobblestone"}}
:enddata
:endrule

rule:
plugin=vanillaBlocks
number=29
data:
JSON:{blockState:{blockName:"minecraft:mossy_cobblestone"}}
:enddata
:endrule

rule:
plugin=vanillaBlocks
number=30
data:
JSON:{blockState:{blockName:"minecraft:netherrack"}}
:enddata
:endrule

rule:
plugin=inventory
number=31
data:
JSON:{blockState:{blockName:"minecraft:chest",properties:{facing:"west"}},lootLevel:0,teData:{Items:[],id:"minecraft:chest",Lock:""},inventoryData:{length:0,inventoryContents:[]},legacyFeatures:1b}
:enddata
:endrule

rule:
plugin=vanillaBlocks
number=32
data:
JSON:{blockState:{blockName:"minecraft:tallgrass",properties:{type:"tall_grass"}}}
:enddata
:endrule

rule:
plugin=vanillaBlocks
number=33
data:
JSON:{blockState:{blockName:"minecraft:log2",properties:{variant:"dark_oak",axis:"y"}}}
:enddata
:endrule

rule:
plugin=vanillaBlocks
number=34
data:
JSON:{blockState:{blockName:"minecraft:fence_gate",properties:{in_wall:"false",powered:"false",facing:"north",open:"false"}}}
:enddata
:endrule

rule:
plugin=blockTile
number=35
data:
JSON:{blockState:{blockName:"ancientwarfarestructure:advanced_spawner",properties:{transparent:"true"}},teData:{id:"ancientwarfarestructure:advanced_spawner_tile",spawnerSettings:{minDelay:0,spawnDelay:0,lightSensitive:0b,spawnGroups:[{settingsList:[{remainingSpawnCount:1,hostile:1b,forced:1b,customTag:{factionName:"orc"},maxToSpawn:1,entityId:"ancientwarfarenpc:faction.archer",minToSpawn:1}],groupWeight:1}],playerRange:8,respondToRedstone:0b,inventory:{Size:9,Items:[]},spawnRange:0,transparent:1b,maxDelay:0,xpToDrop:0,mobRange:0,debugMode:0b,maxNearbyMonsters:0}}}
:enddata
:endrule

rule:
plugin=vanillaBlocks
number=36
data:
JSON:{blockState:{blockName:"minecraft:fence_gate",properties:{in_wall:"false",powered:"false",facing:"south",open:"false"}}}
:enddata
:endrule

rule:
plugin=vanillaBlocks
number=37
data:
JSON:{blockState:{blockName:"minecraft:stone_slab",properties:{half:"bottom",variant:"cobblestone"}}}
:enddata
:endrule

rule:
plugin=vanillaBlocks
number=38
data:
JSON:{blockState:{blockName:"minecraft:fire",properties:{east:"false",south:"false",north:"false",west:"false",up:"false",age:"15"}}}
:enddata
:endrule

rule:
plugin=blockTile
number=39
data:
JSON:{blockState:{blockName:"ancientwarfarestructure:advanced_spawner",properties:{transparent:"true"}},teData:{id:"ancientwarfarestructure:advanced_spawner_tile",spawnerSettings:{minDelay:0,spawnDelay:0,lightSensitive:0b,spawnGroups:[{settingsList:[{remainingSpawnCount:1,hostile:1b,forced:1b,customTag:{factionName:"orc"},maxToSpawn:1,entityId:"ancientwarfarenpc:faction.soldier.elite",minToSpawn:1}],groupWeight:1}],playerRange:8,respondToRedstone:0b,inventory:{Size:9,Items:[]},spawnRange:0,transparent:1b,maxDelay:0,xpToDrop:0,mobRange:0,debugMode:0b,maxNearbyMonsters:0}}}
:enddata
:endrule

rule:
plugin=vanillaBlocks
number=40
data:
JSON:{blockState:{blockName:"minecraft:nether_brick_fence",properties:{east:"false",south:"false",north:"false",west:"false"}}}
:enddata
:endrule

rule:
plugin=blockTile
number=41
data:
JSON:{blockState:{blockName:"ancientwarfarestructure:advanced_spawner",properties:{transparent:"true"}},teData:{id:"ancientwarfarestructure:advanced_spawner_tile",spawnerSettings:{minDelay:0,spawnDelay:0,lightSensitive:0b,spawnGroups:[{settingsList:[{remainingSpawnCount:1,hostile:1b,forced:1b,customTag:{factionName:"orc"},maxToSpawn:1,entityId:"ancientwarfarenpc:faction.soldier.elite",minToSpawn:1}],groupWeight:1}],playerRange:6,respondToRedstone:0b,inventory:{Size:9,Items:[]},spawnRange:0,transparent:1b,maxDelay:0,xpToDrop:0,mobRange:0,debugMode:0b,maxNearbyMonsters:0}}}
:enddata
:endrule

rule:
plugin=inventory
number=42
data:
JSON:{blockState:{blockName:"minecraft:furnace",properties:{facing:"north"}},lootLevel:0,teData:{CookTime:0,BurnTime:0,Items:[],id:"minecraft:furnace",CookTimeTotal:0,Lock:""},inventoryData:{length:0,inventoryContents:[]},legacyFeatures:0b}
:enddata
:endrule

rule:
plugin=inventory
number=43
data:
JSON:{blockState:{blockName:"minecraft:chest",properties:{facing:"south"}},lootLevel:0,teData:{ForgeData:{},Items:[{Slot:1b,id:"minecraft:poisonous_potato",Count:2b,Damage:0s},{Slot:6b,id:"ancientwarfarenpc:coin",Count:1b,tag:{metal:"gold"},Damage:0s},{Slot:8b,id:"minecraft:bone",Count:3b,Damage:0s},{Slot:10b,id:"minecraft:poisonous_potato",Count:4b,Damage:0s},{Slot:12b,id:"minecraft:rotten_flesh",Count:1b,Damage:0s},{Slot:13b,id:"minecraft:rotten_flesh",Count:1b,Damage:0s},{Slot:14b,id:"minecraft:rotten_flesh",Count:2b,Damage:0s},{Slot:15b,id:"ancientwarfarenpc:coin",Count:19b,tag:{metal:"copper"},Damage:0s},{Slot:16b,id:"ancientwarfarenpc:coin",Count:6b,tag:{metal:"silver"},Damage:0s},{Slot:18b,id:"minecraft:poisonous_potato",Count:2b,Damage:0s},{Slot:19b,id:"minecraft:poisonous_potato",Count:5b,Damage:0s},{Slot:22b,id:"minecraft:rotten_flesh",Count:1b,Damage:0s},{Slot:24b,id:"minecraft:rotten_flesh",Count:1b,Damage:0s},{Slot:26b,id:"minecraft:red_mushroom",Count:7b,Damage:0s}],id:"minecraft:chest",Lock:""},inventoryData:{length:14,inventoryContents:[{id:"minecraft:poisonous_potato",Count:2b,slot:0,Damage:0s},{id:"ancientwarfarenpc:coin",Count:1b,tag:{metal:"gold"},slot:1,Damage:0s},{id:"minecraft:bone",Count:3b,slot:2,Damage:0s},{id:"minecraft:poisonous_potato",Count:4b,slot:3,Damage:0s},{id:"minecraft:rotten_flesh",Count:1b,slot:4,Damage:0s},{id:"minecraft:rotten_flesh",Count:1b,slot:5,Damage:0s},{id:"minecraft:rotten_flesh",Count:2b,slot:6,Damage:0s},{id:"ancientwarfarenpc:coin",Count:19b,tag:{metal:"copper"},slot:7,Damage:0s},{id:"ancientwarfarenpc:coin",Count:6b,tag:{metal:"silver"},slot:8,Damage:0s},{id:"minecraft:poisonous_potato",Count:2b,slot:9,Damage:0s},{id:"minecraft:poisonous_potato",Count:5b,slot:10,Damage:0s},{id:"minecraft:rotten_flesh",Count:1b,slot:11,Damage:0s},{id:"minecraft:rotten_flesh",Count:1b,slot:12,Damage:0s},{id:"minecraft:red_mushroom",Count:7b,slot:13,Damage:0s}]},legacyFeatures:1b}
:enddata
:endrule

rule:
plugin=inventory
number=44
data:
JSON:{blockState:{blockName:"minecraft:chest",properties:{facing:"south"}},lootLevel:0,teData:{Items:[{Slot:1b,id:"minecraft:poisonous_potato",Count:2b,Damage:0s},{Slot:3b,id:"minecraft:rotten_flesh",Count:1b,Damage:0s},{Slot:4b,id:"minecraft:rotten_flesh",Count:1b,Damage:0s},{Slot:5b,id:"ancientwarfarenpc:diamond_halberd",Count:1b,Damage:0s},{Slot:7b,id:"minecraft:rotten_flesh",Count:7b,Damage:0s},{Slot:8b,id:"minecraft:brown_mushroom",Count:6b,Damage:0s},{Slot:10b,id:"minecraft:spider_eye",Count:9b,Damage:0s},{Slot:11b,id:"minecraft:slime_ball",Count:7b,Damage:0s},{Slot:13b,id:"minecraft:rotten_flesh",Count:1b,Damage:0s},{Slot:14b,id:"minecraft:rotten_flesh",Count:8b,Damage:0s},{Slot:16b,id:"minecraft:rotten_flesh",Count:8b,Damage:0s},{Slot:20b,id:"minecraft:coal",Count:7b,Damage:0s},{Slot:22b,id:"minecraft:bone",Count:6b,Damage:0s},{Slot:23b,id:"minecraft:gold_nugget",Count:6b,Damage:0s},{Slot:26b,id:"minecraft:bone",Count:3b,Damage:0s}],id:"minecraft:chest",Lock:""},inventoryData:{length:15,inventoryContents:[{id:"minecraft:poisonous_potato",Count:2b,slot:0,Damage:0s},{id:"minecraft:rotten_flesh",Count:1b,slot:1,Damage:0s},{id:"minecraft:rotten_flesh",Count:1b,slot:2,Damage:0s},{id:"ancientwarfarenpc:diamond_halberd",Count:1b,slot:3,Damage:0s},{id:"minecraft:rotten_flesh",Count:7b,slot:4,Damage:0s},{id:"minecraft:brown_mushroom",Count:6b,slot:5,Damage:0s},{id:"minecraft:spider_eye",Count:9b,slot:6,Damage:0s},{id:"minecraft:slime_ball",Count:7b,slot:7,Damage:0s},{id:"minecraft:rotten_flesh",Count:1b,slot:8,Damage:0s},{id:"minecraft:rotten_flesh",Count:8b,slot:9,Damage:0s},{id:"minecraft:rotten_flesh",Count:8b,slot:10,Damage:0s},{id:"minecraft:coal",Count:7b,slot:11,Damage:0s},{id:"minecraft:bone",Count:6b,slot:12,Damage:0s},{id:"minecraft:gold_nugget",Count:6b,slot:13,Damage:0s},{id:"minecraft:bone",Count:3b,slot:14,Damage:0s}]},legacyFeatures:1b}
:enddata
:endrule

rule:
plugin=blockTile
number=45
data:
JSON:{blockState:{blockName:"ancientwarfarestructure:advanced_spawner",properties:{transparent:"true"}},teData:{id:"ancientwarfarestructure:advanced_spawner_tile",spawnerSettings:{minDelay:0,spawnDelay:0,lightSensitive:0b,spawnGroups:[{settingsList:[{remainingSpawnCount:1,hostile:1b,forced:1b,customTag:{factionName:"orc"},maxToSpawn:1,entityId:"ancientwarfarenpc:faction.priest",minToSpawn:1}],groupWeight:1}],playerRange:6,respondToRedstone:0b,inventory:{Size:9,Items:[]},spawnRange:0,transparent:1b,maxDelay:0,xpToDrop:0,mobRange:0,debugMode:0b,maxNearbyMonsters:0}}}
:enddata
:endrule

rule:
plugin=blockTile
number=46
data:
JSON:{blockState:{blockName:"ancientwarfarestructure:advanced_spawner",properties:{transparent:"true"}},teData:{id:"ancientwarfarestructure:advanced_spawner_tile",spawnerSettings:{minDelay:0,spawnDelay:0,lightSensitive:0b,spawnGroups:[{settingsList:[{remainingSpawnCount:1,hostile:1b,forced:1b,customTag:{factionName:"orc"},maxToSpawn:1,entityId:"ancientwarfarenpc:faction.soldier.elite",minToSpawn:1}],groupWeight:1}],playerRange:6,respondToRedstone:0b,inventory:{Size:9,Items:[]},spawnRange:0,transparent:1b,maxDelay:0,xpToDrop:0,mobRange:0,debugMode:0b,maxNearbyMonsters:0}}}
:enddata
:endrule

rule:
plugin=vanillaBlocks
number=47
data:
JSON:{blockState:{blockName:"minecraft:cauldron",properties:{level:"3"}}}
:enddata
:endrule

rule:
plugin=vanillaBlocks
number=48
data:
JSON:{blockState:{blockName:"minecraft:dark_oak_stairs",properties:{half:"top",shape:"straight",facing:"west"}}}
:enddata
:endrule

rule:
plugin=vanillaBlocks
number=49
data:
JSON:{blockState:{blockName:"minecraft:torch",properties:{facing:"south"}}}
:enddata
:endrule

rule:
plugin=vanillaBlocks
number=50
data:
JSON:{blockState:{blockName:"minecraft:torch",properties:{facing:"north"}}}
:enddata
:endrule

rule:
plugin=vanillaSkull
number=51
data:
JSON:{blockState:{blockName:"minecraft:skull",properties:{nodrop:"false",facing:"up"}},skullRotation:8,teData:{Rot:4b,id:"minecraft:skull",SkullType:0b}}
:enddata
:endrule

rule:
plugin=vanillaSkull
number=52
data:
JSON:{blockState:{blockName:"minecraft:skull",properties:{nodrop:"false",facing:"up"}},skullRotation:8,teData:{Rot:4b,id:"minecraft:skull",SkullType:3b}}
:enddata
:endrule

rule:
plugin=vanillaBlocks
number=53
data:
JSON:{blockState:{blockName:"minecraft:dark_oak_stairs",properties:{half:"top",shape:"straight",facing:"north"}}}
:enddata
:endrule

rule:
plugin=vanillaBlocks
number=54
data:
JSON:{blockState:{blockName:"minecraft:dark_oak_stairs",properties:{half:"top",shape:"straight",facing:"south"}}}
:enddata
:endrule

rule:
plugin=vanillaSkull
number=55
data:
JSON:{blockState:{blockName:"minecraft:skull",properties:{nodrop:"false",facing:"up"}},skullRotation:8,teData:{Rot:4b,id:"minecraft:skull",SkullType:3b}}
:enddata
:endrule

rule:
plugin=vanillaBlocks
number=56
data:
JSON:{blockState:{blockName:"minecraft:torch",properties:{facing:"up"}}}
:enddata
:endrule

rule:
plugin=vanillaSkull
number=57
data:
JSON:{blockState:{blockName:"minecraft:skull",properties:{nodrop:"false",facing:"up"}},skullRotation:4,teData:{Rot:0b,id:"minecraft:skull",SkullType:3b}}
:enddata
:endrule

rule:
plugin=blockTile
number=58
data:
JSON:{blockState:{blockName:"ancientwarfarestructure:advanced_spawner",properties:{transparent:"true"}},teData:{id:"ancientwarfarestructure:advanced_spawner_tile",spawnerSettings:{minDelay:0,spawnDelay:0,lightSensitive:0b,spawnGroups:[{settingsList:[{remainingSpawnCount:1,hostile:1b,forced:1b,customTag:{factionName:"orc"},maxToSpawn:1,entityId:"ancientwarfarenpc:faction.leader.elite",minToSpawn:1}],groupWeight:1}],playerRange:6,respondToRedstone:0b,inventory:{Size:9,Items:[]},spawnRange:0,transparent:1b,maxDelay:0,xpToDrop:0,mobRange:0,debugMode:0b,maxNearbyMonsters:0}}}
:enddata
:endrule

rule:
plugin=vanillaBlocks
number=59
data:
JSON:{blockState:{blockName:"minecraft:dark_oak_stairs",properties:{half:"top",shape:"straight",facing:"east"}}}
:enddata
:endrule

rule:
plugin=vanillaSkull
number=60
data:
JSON:{blockState:{blockName:"minecraft:skull",properties:{nodrop:"false",facing:"up"}},skullRotation:8,teData:{Rot:4b,id:"minecraft:skull",SkullType:0b}}
:enddata
:endrule

rule:
plugin=vanillaSkull
number=61
data:
JSON:{blockState:{blockName:"minecraft:skull",properties:{nodrop:"false",facing:"up"}},skullRotation:8,teData:{Rot:4b,id:"minecraft:skull",SkullType:3b}}
:enddata
:endrule

rule:
plugin=vanillaSkull
number=62
data:
JSON:{blockState:{blockName:"minecraft:skull",properties:{nodrop:"false",facing:"up"}},skullRotation:8,teData:{Rot:4b,id:"minecraft:skull",SkullType:3b}}
:enddata
:endrule

rule:
plugin=vanillaSkull
number=63
data:
JSON:{blockState:{blockName:"minecraft:skull",properties:{nodrop:"false",facing:"up"}},skullRotation:12,teData:{Rot:8b,id:"minecraft:skull",SkullType:0b}}
:enddata
:endrule

rule:
plugin=vanillaSkull
number=64
data:
JSON:{blockState:{blockName:"minecraft:skull",properties:{nodrop:"false",facing:"up"}},skullRotation:12,teData:{Rot:8b,id:"minecraft:skull",SkullType:0b}}
:enddata
:endrule

rule:
plugin=vanillaSkull
number=65
data:
JSON:{blockState:{blockName:"minecraft:skull",properties:{nodrop:"false",facing:"up"}},skullRotation:0,teData:{Rot:12b,id:"minecraft:skull",SkullType:0b}}
:enddata
:endrule

rule:
plugin=vanillaBlocks
number=66
data:
JSON:{blockState:{blockName:"minecraft:leaves2",properties:{check_decay:"false",decayable:"false",variant:"dark_oak"}}}
:enddata
:endrule

rule:
plugin=vanillaBlocks
number=67
data:
JSON:{blockState:{blockName:"minecraft:leaves2",properties:{check_decay:"true",decayable:"false",variant:"dark_oak"}}}
:enddata
:endrule

rule:
plugin=vanillaBlocks
number=68
data:
JSON:{blockState:{blockName:"minecraft:dark_oak_stairs",properties:{half:"bottom",shape:"straight",facing:"north"}}}
:enddata
:endrule

rule:
plugin=vanillaSkull
number=69
data:
JSON:{blockState:{blockName:"minecraft:skull",properties:{nodrop:"false",facing:"up"}},skullRotation:8,teData:{Rot:4b,id:"minecraft:skull",SkullType:0b}}
:enddata
:endrule

rule:
plugin=vanillaBlocks
number=70
data:
JSON:{blockState:{blockName:"minecraft:planks",properties:{variant:"spruce"}}}
:enddata
:endrule

rule:
plugin=vanillaBlocks
number=71
data:
JSON:{blockState:{blockName:"minecraft:dark_oak_stairs",properties:{half:"bottom",shape:"straight",facing:"south"}}}
:enddata
:endrule

rule:
plugin=vanillaSkull
number=72
data:
JSON:{blockState:{blockName:"minecraft:skull",properties:{nodrop:"false",facing:"up"}},skullRotation:4,teData:{Rot:0b,id:"minecraft:skull",SkullType:0b}}
:enddata
:endrule

rule:
plugin=vanillaSkull
number=73
data:
JSON:{blockState:{blockName:"minecraft:skull",properties:{nodrop:"false",facing:"up"}},skullRotation:8,teData:{Rot:4b,id:"minecraft:skull",SkullType:0b}}
:enddata
:endrule

rule:
plugin=vanillaBlocks
number=74
data:
JSON:{blockState:{blockName:"minecraft:double_wooden_slab",properties:{variant:"dark_oak"}}}
:enddata
:endrule

rule:
plugin=vanillaSkull
number=75
data:
JSON:{blockState:{blockName:"minecraft:skull",properties:{nodrop:"false",facing:"up"}},skullRotation:0,teData:{Rot:12b,id:"minecraft:skull",SkullType:0b}}
:enddata
:endrule

rule:
plugin=vanillaSkull
number=76
data:
JSON:{blockState:{blockName:"minecraft:skull",properties:{nodrop:"false",facing:"up"}},skullRotation:4,teData:{Rot:0b,id:"minecraft:skull",SkullType:0b}}
:enddata
:endrule

rule:
plugin=vanillaBlocks
number=77
data:
JSON:{blockState:{blockName:"minecraft:obsidian"}}
:enddata
:endrule

rule:
plugin=vanillaSkull
number=78
data:
JSON:{blockState:{blockName:"minecraft:skull",properties:{nodrop:"false",facing:"up"}},skullRotation:12,teData:{Rot:8b,id:"minecraft:skull",SkullType:0b}}
:enddata
:endrule

rule:
plugin=vanillaSkull
number=79
data:
JSON:{blockState:{blockName:"minecraft:skull",properties:{nodrop:"false",facing:"up"}},skullRotation:8,teData:{Rot:4b,id:"minecraft:skull",SkullType:0b}}
:enddata
:endrule

rule:
plugin=vanillaBlocks
number=80
data:
JSON:{blockState:{blockName:"minecraft:stone_slab",properties:{half:"top",variant:"cobblestone"}}}
:enddata
:endrule

rule:
plugin=vanillaBlocks
number=81
data:
JSON:{blockState:{blockName:"minecraft:wooden_slab",properties:{half:"top",variant:"spruce"}}}
:enddata
:endrule

rule:
plugin=vanillaBlocks
number=82
data:
JSON:{blockState:{blockName:"minecraft:stone_stairs",properties:{half:"top",shape:"straight",facing:"west"}}}
:enddata
:endrule

rule:
plugin=inventory
number=83
data:
JSON:{blockState:{blockName:"minecraft:brewing_stand",properties:{has_bottle_0:"false",has_bottle_1:"false",has_bottle_2:"false"}},lootLevel:0,teData:{Fuel:0b,Items:[],id:"minecraft:brewing_stand",BrewTime:0s,Lock:""},inventoryData:{length:0,inventoryContents:[]},legacyFeatures:0b}
:enddata
:endrule

rule:
plugin=vanillaSkull
number=84
data:
JSON:{blockState:{blockName:"minecraft:skull",properties:{nodrop:"false",facing:"up"}},skullRotation:12,teData:{Rot:8b,id:"minecraft:skull",SkullType:1b}}
:enddata
:endrule

rule:
plugin=vanillaBlocks
number=85
data:
JSON:{blockState:{blockName:"minecraft:torch",properties:{facing:"east"}}}
:enddata
:endrule

rule:
plugin=blockTile
number=86
data:
JSON:{blockState:{blockName:"ancientwarfarestructure:advanced_spawner",properties:{transparent:"true"}},teData:{id:"ancientwarfarestructure:advanced_spawner_tile",spawnerSettings:{minDelay:0,spawnDelay:0,lightSensitive:0b,spawnGroups:[{settingsList:[{remainingSpawnCount:1,hostile:1b,forced:1b,customTag:{factionName:"orc"},maxToSpawn:1,entityId:"ancientwarfarenpc:faction.archer.elite",minToSpawn:1}],groupWeight:1}],playerRange:24,respondToRedstone:0b,inventory:{Size:9,Items:[]},spawnRange:0,transparent:1b,maxDelay:0,xpToDrop:0,mobRange:0,debugMode:0b,maxNearbyMonsters:0}}}
:enddata
:endrule

rule:
plugin=vanillaSkull
number=87
data:
JSON:{blockState:{blockName:"minecraft:skull",properties:{nodrop:"false",facing:"up"}},skullRotation:0,teData:{Rot:12b,id:"minecraft:skull",SkullType:0b}}
:enddata
:endrule

rule:
plugin=vanillaSkull
number=88
data:
JSON:{blockState:{blockName:"minecraft:skull",properties:{nodrop:"false",facing:"up"}},skullRotation:4,teData:{Rot:0b,id:"minecraft:skull",SkullType:0b}}
:enddata
:endrule

rule:
plugin=vanillaSkull
number=89
data:
JSON:{blockState:{blockName:"minecraft:skull",properties:{nodrop:"false",facing:"up"}},skullRotation:8,teData:{Rot:4b,id:"minecraft:skull",SkullType:0b}}
:enddata
:endrule

rule:
plugin=vanillaSkull
number=90
data:
JSON:{blockState:{blockName:"minecraft:skull",properties:{nodrop:"false",facing:"up"}},skullRotation:12,teData:{Rot:8b,id:"minecraft:skull",SkullType:0b}}
:enddata
:endrule

rule:
plugin=vanillaSkull
number=91
data:
JSON:{blockState:{blockName:"minecraft:skull",properties:{nodrop:"false",facing:"up"}},skullRotation:0,teData:{Rot:12b,id:"minecraft:skull",SkullType:0b}}
:enddata
:endrule

rule:
plugin=vanillaSkull
number=92
data:
JSON:{blockState:{blockName:"minecraft:skull",properties:{nodrop:"false",facing:"up"}},skullRotation:4,teData:{Rot:0b,id:"minecraft:skull",SkullType:0b}}
:enddata
:endrule

rule:
plugin=vanillaSkull
number=93
data:
JSON:{blockState:{blockName:"minecraft:skull",properties:{nodrop:"false",facing:"up"}},skullRotation:8,teData:{Rot:4b,id:"minecraft:skull",SkullType:0b}}
:enddata
:endrule

rule:
plugin=vanillaSkull
number=94
data:
JSON:{blockState:{blockName:"minecraft:skull",properties:{nodrop:"false",facing:"up"}},skullRotation:0,teData:{Rot:12b,id:"minecraft:skull",SkullType:0b}}
:enddata
:endrule

rule:
plugin=blockTile
number=95
data:
JSON:{blockState:{blockName:"ancientwarfarestructure:advanced_spawner",properties:{transparent:"true"}},teData:{id:"ancientwarfarestructure:advanced_spawner_tile",spawnerSettings:{minDelay:0,spawnDelay:0,lightSensitive:0b,spawnGroups:[{settingsList:[{remainingSpawnCount:1,hostile:1b,forced:1b,customTag:{factionName:"orc"},maxToSpawn:1,entityId:"ancientwarfarenpc:faction.archer.elite",minToSpawn:1}],groupWeight:1}],playerRange:24,respondToRedstone:0b,inventory:{Size:9,Items:[]},spawnRange:0,transparent:1b,maxDelay:0,xpToDrop:0,mobRange:0,debugMode:0b,maxNearbyMonsters:0}}}
:enddata
:endrule

rule:
plugin=blockTile
number=96
data:
JSON:{blockState:{blockName:"ancientwarfarestructure:advanced_spawner",properties:{transparent:"true"}},teData:{id:"ancientwarfarestructure:advanced_spawner_tile",spawnerSettings:{minDelay:0,spawnDelay:0,lightSensitive:0b,spawnGroups:[{settingsList:[{remainingSpawnCount:1,hostile:1b,forced:1b,customTag:{factionName:"orc"},maxToSpawn:1,entityId:"ancientwarfarenpc:faction.archer.elite",minToSpawn:1}],groupWeight:1}],playerRange:24,respondToRedstone:0b,inventory:{Size:9,Items:[]},spawnRange:0,transparent:1b,maxDelay:0,xpToDrop:0,mobRange:0,debugMode:0b,maxNearbyMonsters:0}}}
:enddata
:endrule

rule:
plugin=vanillaSkull
number=97
data:
JSON:{blockState:{blockName:"minecraft:skull",properties:{nodrop:"false",facing:"up"}},skullRotation:0,teData:{Rot:12b,id:"minecraft:skull",SkullType:0b}}
:enddata
:endrule

rule:
plugin=vanillaSkull
number=98
data:
JSON:{blockState:{blockName:"minecraft:skull",properties:{nodrop:"false",facing:"up"}},skullRotation:8,teData:{Rot:4b,id:"minecraft:skull",SkullType:0b}}
:enddata
:endrule

rule:
plugin=vanillaSkull
number=99
data:
JSON:{blockState:{blockName:"minecraft:skull",properties:{nodrop:"false",facing:"up"}},skullRotation:4,teData:{Rot:0b,id:"minecraft:skull",SkullType:0b}}
:enddata
:endrule

rule:
plugin=vanillaSkull
number=100
data:
JSON:{blockState:{blockName:"minecraft:skull",properties:{nodrop:"false",facing:"up"}},skullRotation:0,teData:{Rot:12b,id:"minecraft:skull",SkullType:0b}}
:enddata
:endrule

rule:
plugin=vanillaSkull
number=101
data:
JSON:{blockState:{blockName:"minecraft:skull",properties:{nodrop:"false",facing:"up"}},skullRotation:12,teData:{Rot:8b,id:"minecraft:skull",SkullType:0b}}
:enddata
:endrule

rule:
plugin=vanillaSkull
number=102
data:
JSON:{blockState:{blockName:"minecraft:skull",properties:{nodrop:"false",facing:"up"}},skullRotation:8,teData:{Rot:4b,id:"minecraft:skull",SkullType:0b}}
:enddata
:endrule

rule:
plugin=vanillaBlocks
number=103
data:
JSON:{blockState:{blockName:"minecraft:lit_pumpkin",properties:{facing:"east"}}}
:enddata
:endrule

rule:
plugin=vanillaSkull
number=104
data:
JSON:{blockState:{blockName:"minecraft:skull",properties:{nodrop:"false",facing:"up"}},skullRotation:4,teData:{Rot:0b,id:"minecraft:skull",SkullType:0b}}
:enddata
:endrule

rule:
plugin=vanillaSkull
number=105
data:
JSON:{blockState:{blockName:"minecraft:skull",properties:{nodrop:"false",facing:"up"}},skullRotation:0,teData:{Rot:12b,id:"minecraft:skull",SkullType:0b}}
:enddata
:endrule

rule:
plugin=vanillaSkull
number=106
data:
JSON:{blockState:{blockName:"minecraft:skull",properties:{nodrop:"false",facing:"up"}},skullRotation:0,teData:{Rot:12b,id:"minecraft:skull",SkullType:0b}}
:enddata
:endrule

rule:
plugin=vanillaSkull
number=107
data:
JSON:{blockState:{blockName:"minecraft:skull",properties:{nodrop:"false",facing:"up"}},skullRotation:4,teData:{Rot:0b,id:"minecraft:skull",SkullType:0b}}
