# Ancient Warfare Structure Template File
# Auto-generated structure template file. created on: 8/19/2019 at: 10:23:14
# Lines beginning with # denote comments

header:
version=2.9
name=OrcVillageMediumRoofedForest
mods=
size=31,20,40
offset=16,6,39
:endheader

#### VALIDATION ####
validation:
type=ground
survival=false
worldGenEnabled=true
unique=false
preserveBlocks=false
selectionWeight=40
clusterValue=50
minDuplicateDistance=800
dimensionWhiteList=true
dimensionList=0
biomeWhiteList=true
biomeList=minecraft:roofed_forest
leveling=4
fill=3
border=4
blockSwap=false
:endvalidation

#### LAYERS ####
layer: 0
1,1,1,1,1,1,1,1,1,1,1,1,1,1,1,1,1,1,1,1,1,1,1,1,1,1,1,1,1,1,1
1,1,1,1,1,1,1,1,1,1,1,1,1,1,1,1,1,1,1,1,1,1,1,1,1,1,1,1,1,1,1
1,1,1,1,1,1,1,1,1,1,1,1,1,1,1,1,1,1,1,1,1,1,1,1,1,1,1,1,1,1,1
1,1,1,1,1,1,1,1,1,1,1,1,1,1,1,1,1,1,1,1,1,1,1,1,1,1,1,1,1,1,1
1,1,1,1,1,1,1,1,1,1,1,1,1,1,1,1,1,1,1,1,1,1,1,1,1,1,1,1,1,1,1
1,1,1,1,1,1,1,1,1,1,1,1,1,1,1,1,1,1,1,1,1,1,1,1,1,1,1,1,1,1,1
1,1,1,1,1,1,1,1,1,1,1,1,1,1,1,1,1,1,1,1,1,1,1,1,1,1,1,1,1,1,1
1,1,1,1,1,1,1,1,1,1,1,1,1,1,1,1,1,1,1,1,1,1,1,1,1,1,1,1,1,1,1
1,1,1,1,1,1,1,1,1,1,1,1,1,1,1,1,1,1,1,1,1,1,1,1,1,1,1,1,1,1,1
1,1,1,1,1,1,1,1,1,1,1,1,1,1,1,1,1,1,1,1,1,1,1,1,1,1,1,1,1,1,1
1,1,1,1,1,1,1,1,1,1,1,1,1,1,1,1,1,1,1,1,1,1,1,1,1,1,1,1,1,1,1
1,1,1,1,1,1,1,1,1,1,1,1,1,1,1,1,1,1,1,1,1,1,1,1,1,1,1,1,1,1,1
1,1,1,1,1,1,1,1,1,1,1,1,1,1,1,1,1,1,1,1,1,1,1,1,1,1,1,1,1,1,1
1,1,1,1,1,1,1,1,1,1,1,1,1,1,1,1,1,1,1,1,1,1,1,1,1,1,1,1,1,1,1
1,1,1,1,1,1,1,1,1,1,1,1,1,1,1,1,1,1,1,1,1,1,1,1,1,1,1,1,1,1,1
1,1,1,1,1,1,1,1,1,1,1,1,1,1,1,1,1,1,1,1,1,1,1,1,1,1,1,1,1,1,1
1,1,1,1,1,1,1,1,1,1,1,1,1,1,1,1,1,1,1,1,1,1,1,1,1,1,1,1,1,1,1
1,1,1,1,1,1,1,1,1,1,1,1,1,1,1,1,1,1,1,1,1,1,1,1,1,1,1,1,1,1,1
1,1,1,1,1,1,1,1,1,1,1,1,1,1,1,1,1,1,1,1,1,1,1,1,1,1,1,1,1,1,1
1,1,1,1,1,1,1,1,1,1,1,1,1,1,1,1,1,1,1,1,1,1,1,1,1,1,1,1,1,1,1
1,1,1,1,1,1,1,1,1,1,1,1,1,1,1,1,1,1,1,1,1,1,1,1,1,1,1,1,1,1,1
1,1,1,1,1,1,1,1,1,1,1,1,1,1,1,1,1,1,1,1,1,1,1,1,1,1,1,1,1,1,1
1,1,1,1,1,1,1,1,1,1,1,1,1,1,1,1,1,1,1,1,1,1,1,1,1,1,1,1,1,1,1
1,1,1,1,1,1,1,1,1,1,1,1,1,1,1,1,1,1,1,1,1,1,1,1,1,1,1,1,1,1,1
1,1,1,1,1,1,1,1,1,1,1,1,1,1,1,1,1,1,1,1,1,1,1,1,1,1,1,1,1,1,1
1,1,1,1,1,1,1,1,1,1,1,1,1,1,1,1,1,1,1,1,1,1,1,1,1,1,1,1,1,1,1
1,1,1,1,1,1,1,1,1,1,1,1,1,1,1,1,1,1,1,1,1,1,1,1,1,1,1,1,1,1,1
1,1,1,1,1,1,1,1,1,1,1,1,1,1,1,1,1,1,1,1,1,1,1,1,1,1,1,1,1,1,1
1,1,1,1,1,1,1,1,1,1,1,1,1,1,1,1,1,1,1,1,1,1,1,1,1,1,1,1,1,1,1
1,1,1,1,1,1,1,1,1,1,1,1,1,1,1,1,1,1,1,1,1,1,1,1,1,1,1,1,1,1,1
1,1,1,1,1,1,1,1,1,1,1,1,1,1,1,1,1,1,1,1,1,1,1,1,1,1,1,1,1,1,1
1,1,1,1,1,1,1,1,1,1,1,1,1,1,1,1,1,1,1,1,1,1,1,1,1,1,1,1,1,1,1
1,1,1,1,1,1,1,1,1,1,1,1,1,1,1,1,1,1,1,1,1,1,1,1,1,1,1,1,1,1,1
1,1,1,1,1,1,1,1,1,1,1,1,1,1,1,1,1,1,1,1,1,1,1,1,1,1,1,1,1,1,1
1,1,1,1,1,1,1,1,1,1,1,1,1,1,1,1,1,1,1,1,1,1,1,1,1,1,1,1,1,1,1
1,1,1,1,1,1,1,1,1,1,1,1,1,1,1,1,1,1,1,1,1,1,1,1,1,1,1,1,1,1,1
1,1,1,1,1,1,1,1,1,1,1,1,1,1,1,1,1,1,1,1,1,1,1,1,1,1,1,1,1,1,1
1,1,1,1,1,1,1,1,1,1,1,1,1,1,1,1,1,1,1,1,1,1,1,1,1,1,1,1,1,1,1
1,1,1,1,1,1,1,1,1,1,1,1,1,1,1,1,1,1,1,1,1,1,1,1,1,1,1,1,1,1,1
1,1,1,1,1,1,1,1,1,1,1,1,1,1,1,1,1,1,1,1,1,1,1,1,1,1,1,1,1,1,1
:endlayer
layer: 1
1,1,1,1,1,1,1,1,1,1,1,1,1,1,1,1,1,1,1,1,1,1,1,1,1,1,1,1,1,1,1
1,1,1,1,1,1,1,1,1,1,1,1,1,1,1,1,1,1,1,1,1,1,1,1,1,1,1,1,1,1,1
1,1,1,1,1,1,1,1,1,1,1,1,1,1,1,1,1,1,1,1,1,1,1,1,1,1,1,1,1,1,1
1,1,1,1,1,1,1,1,1,1,1,1,1,1,1,1,1,1,1,1,1,1,1,1,1,1,1,1,1,1,1
1,1,1,1,1,1,1,1,1,1,1,1,1,1,1,1,1,1,1,1,1,1,1,1,1,1,1,1,1,1,1
1,1,1,1,1,1,1,1,1,1,1,1,1,1,1,1,1,1,1,1,1,1,1,1,1,1,1,1,1,1,1
1,1,1,1,1,1,1,1,1,1,1,1,1,1,1,1,1,1,1,1,1,1,1,1,1,1,1,1,1,1,1
1,1,1,1,1,1,1,1,1,1,1,1,1,1,1,1,1,1,1,1,1,1,1,1,1,1,1,1,1,1,1
1,1,1,1,1,1,1,1,1,1,1,1,1,1,1,1,1,1,1,1,1,1,1,1,1,1,1,1,1,1,1
1,1,1,1,1,1,1,1,1,1,1,1,1,1,1,1,1,1,1,1,1,1,1,1,1,1,1,1,1,1,1
1,1,1,1,1,1,1,1,1,1,1,1,1,1,1,1,1,1,1,1,1,1,1,1,1,1,1,1,1,1,1
1,1,1,1,1,1,1,1,1,1,1,1,1,1,1,1,1,1,1,1,1,1,1,1,1,1,1,1,1,1,1
1,1,1,1,1,1,1,1,1,1,1,1,1,1,1,1,1,1,1,1,1,1,1,1,1,1,1,1,1,1,1
1,1,1,1,1,1,1,1,1,1,1,1,1,1,1,1,1,1,1,1,1,1,1,1,1,1,1,1,1,1,1
1,1,1,1,1,1,1,1,1,1,1,1,1,1,1,1,1,1,1,1,1,1,1,1,1,1,1,1,1,1,1
1,1,1,1,1,1,1,1,1,1,1,1,1,1,1,1,1,1,1,1,1,1,1,1,1,1,1,1,1,1,1
1,1,1,1,1,1,1,1,1,1,1,1,1,1,1,1,1,1,1,1,1,1,1,1,1,1,1,1,1,1,1
1,1,1,1,1,1,1,1,1,1,1,1,1,1,1,1,1,1,1,1,1,1,1,1,1,1,1,1,1,1,1
1,1,1,1,1,1,1,1,1,1,1,1,1,1,1,1,1,1,1,1,1,1,1,1,1,1,1,1,1,1,1
1,1,1,1,1,1,1,1,1,1,1,1,1,1,1,1,1,1,1,1,1,1,1,1,1,1,1,1,1,1,1
1,1,1,1,1,1,1,1,1,1,1,1,1,1,1,1,1,1,1,1,1,1,1,1,1,1,1,1,1,1,1
1,1,1,1,1,1,1,1,1,1,1,1,1,1,1,1,1,1,1,1,1,1,1,1,1,1,1,1,1,1,1
1,1,1,1,1,1,1,1,1,1,1,1,1,1,1,1,1,1,1,1,1,1,1,1,1,1,1,1,1,1,1
1,1,1,1,1,1,1,1,1,1,1,1,1,1,1,1,1,1,1,1,1,1,1,1,1,1,1,1,1,1,1
1,1,1,1,1,1,1,1,1,1,1,1,1,1,1,1,1,1,1,1,1,1,1,1,1,1,1,1,1,1,1
1,1,1,1,1,1,1,1,1,1,1,1,1,1,1,1,1,1,1,1,1,1,1,1,1,1,1,1,1,1,1
1,1,1,1,1,1,1,1,1,1,1,1,1,1,1,1,1,1,1,1,1,1,1,1,1,1,1,1,1,1,1
1,1,1,1,1,1,1,1,1,1,1,1,1,1,1,1,1,1,1,1,1,1,1,1,1,1,1,1,1,1,1
1,1,1,1,1,1,1,1,1,1,1,1,1,1,1,1,1,1,1,1,1,1,1,1,1,1,1,1,1,1,1
1,1,1,1,1,1,1,1,1,1,1,1,1,1,1,1,1,1,1,1,1,1,1,1,1,1,1,1,1,1,1
1,1,1,1,1,1,1,1,1,1,1,1,1,1,1,1,1,1,1,1,1,1,1,1,1,1,1,1,1,1,1
1,1,1,1,1,1,1,1,1,1,1,1,1,1,1,1,1,1,1,1,1,1,1,1,1,1,1,1,1,1,1
1,1,1,1,1,1,1,1,1,1,1,1,1,1,1,1,1,1,1,1,1,1,1,1,1,1,1,1,1,1,1
1,1,1,1,1,1,1,1,1,1,1,1,1,1,1,1,1,1,1,1,1,1,1,1,1,1,1,1,1,1,1
1,1,1,1,1,1,1,1,1,1,1,1,1,1,1,1,1,1,1,1,1,1,1,1,1,1,1,1,1,1,1
1,1,1,1,1,1,1,1,1,1,1,1,1,1,1,1,1,1,1,1,1,1,1,1,1,1,1,1,1,1,1
1,1,1,1,1,1,1,1,1,1,1,1,1,1,1,1,1,1,1,1,1,1,1,1,1,1,1,1,1,1,1
1,1,1,1,1,1,1,1,1,1,1,1,1,1,1,1,1,1,1,1,1,1,1,1,1,1,1,1,1,1,1
1,1,1,1,1,1,1,1,1,1,1,1,1,1,1,1,1,1,1,1,1,1,1,1,1,1,1,1,1,1,1
1,1,1,1,1,1,1,1,1,1,1,1,1,1,1,1,1,1,1,1,1,1,1,1,1,1,1,1,1,1,1
:endlayer
layer: 2
1,1,1,1,1,1,1,1,1,1,1,1,1,1,1,1,1,1,1,1,1,1,1,1,1,1,1,1,1,1,1
1,1,1,1,1,1,1,1,1,1,1,1,1,1,1,1,1,1,1,1,1,1,1,1,1,1,1,1,1,1,1
1,1,1,1,1,1,1,1,1,1,1,1,1,1,1,1,1,1,1,1,1,1,1,1,1,1,1,1,1,1,1
1,1,1,1,1,1,1,1,1,1,1,1,1,1,1,1,1,1,1,1,1,1,1,1,1,1,1,1,1,1,1
1,1,1,1,1,1,1,1,1,1,1,1,1,1,1,1,1,1,1,1,1,1,1,1,1,1,1,1,1,1,1
1,1,1,1,1,1,1,1,1,1,1,1,1,1,1,1,1,1,1,1,1,1,1,1,1,1,1,1,1,1,1
1,1,1,1,1,1,1,1,1,1,1,1,1,1,1,1,1,1,1,1,1,1,1,1,1,1,1,1,1,1,1
1,1,1,1,1,1,1,1,1,1,1,1,1,1,1,1,1,1,1,1,1,1,1,1,1,1,1,1,1,1,1
1,1,1,1,1,1,1,1,1,1,1,1,1,1,1,1,1,1,1,1,1,1,1,1,1,1,1,1,1,1,1
1,1,1,1,1,1,1,1,1,1,1,1,1,1,1,1,1,1,1,1,1,1,1,1,1,1,1,1,1,1,1
1,1,1,1,1,1,1,1,1,1,1,1,1,1,1,1,1,1,1,1,1,1,1,1,1,1,1,1,1,1,1
1,1,1,1,1,1,1,1,1,1,1,1,1,1,1,1,1,1,1,1,1,1,1,1,1,1,1,1,1,1,1
1,1,1,1,1,1,2,2,1,1,1,1,1,1,1,1,1,1,1,1,1,1,1,2,2,1,1,1,1,1,1
1,1,1,1,1,1,1,1,1,1,1,1,1,1,1,1,1,1,1,1,1,1,1,1,1,1,1,1,1,1,1
1,1,1,1,1,1,1,1,1,1,1,1,1,1,1,1,1,1,1,1,1,1,1,1,1,1,1,1,1,1,1
1,1,1,1,1,1,1,1,1,1,1,1,1,1,1,1,1,1,1,1,1,1,1,1,1,1,1,1,1,1,1
1,1,1,1,1,1,2,2,1,1,1,1,1,1,1,1,1,1,1,1,1,1,1,2,2,1,1,1,1,1,1
1,1,1,1,1,1,1,1,1,1,1,1,1,1,1,1,1,1,1,1,1,1,1,1,1,1,1,1,1,1,1
1,1,1,1,1,1,1,1,1,1,1,1,1,1,1,1,1,1,1,1,1,1,1,1,1,1,1,1,1,1,1
1,1,1,1,1,1,1,1,1,1,1,1,1,1,1,1,1,1,1,1,1,1,1,1,1,1,1,1,1,1,1
1,1,1,1,1,1,1,1,1,1,1,1,1,1,1,1,1,1,1,1,1,1,1,1,1,1,1,1,1,1,1
1,1,1,2,2,1,1,1,1,1,1,1,1,1,1,1,1,1,1,1,1,1,1,1,1,1,2,2,1,1,1
1,1,1,1,1,1,1,1,1,1,1,1,1,1,1,1,1,1,1,1,1,1,1,1,1,1,1,1,1,1,1
1,1,1,1,1,1,1,1,1,1,1,1,1,1,1,1,1,1,1,1,1,1,1,1,1,1,1,1,1,1,1
1,1,1,1,1,1,1,1,1,1,1,1,1,1,1,1,1,1,1,1,1,1,1,1,1,1,1,1,1,1,1
1,1,1,2,2,1,1,1,1,1,1,1,1,1,1,1,1,1,1,1,1,1,1,1,1,1,2,2,1,1,1
1,1,1,1,1,1,1,1,1,1,1,1,1,1,1,1,1,1,1,1,1,1,1,1,1,1,1,1,1,1,1
1,1,1,1,1,1,1,1,1,1,1,1,1,1,1,1,1,1,1,1,1,1,1,1,1,1,1,1,1,1,1
1,1,1,1,1,1,1,1,1,1,1,1,1,1,1,1,1,1,1,1,1,1,1,1,1,1,1,1,1,1,1
1,1,1,1,1,1,1,1,1,1,1,1,1,1,1,1,1,1,1,1,1,1,1,1,1,1,1,1,1,1,1
1,1,1,1,1,1,1,1,1,1,1,1,1,1,1,1,1,1,1,1,1,1,1,1,1,1,1,1,1,1,1
1,1,1,1,1,1,1,1,1,1,1,1,1,3,3,3,3,1,1,1,1,1,1,1,1,1,1,1,1,1,1
1,1,1,1,2,1,1,1,2,1,1,1,1,3,3,3,3,1,1,1,2,1,1,1,2,1,1,1,1,1,1
1,1,1,1,2,1,1,1,2,1,1,1,1,3,3,3,3,1,1,1,2,1,1,1,2,1,1,1,1,1,1
1,1,1,1,1,1,1,1,1,1,1,1,1,3,3,3,3,1,1,1,1,1,1,1,1,1,1,1,1,1,1
1,1,1,1,1,1,1,1,1,1,1,1,1,1,1,1,1,1,1,1,1,1,1,1,1,1,1,1,1,1,1
1,1,1,1,1,1,1,1,1,1,1,1,1,1,1,1,1,1,1,1,1,1,1,1,1,1,1,1,1,1,1
1,1,1,1,1,1,1,1,1,1,1,1,1,1,1,1,1,1,1,1,1,1,1,1,1,1,1,1,1,1,1
1,1,1,1,1,1,1,1,1,1,1,1,1,1,1,1,1,1,1,1,1,1,1,1,1,1,1,1,1,1,1
1,1,1,1,1,1,1,1,1,1,1,1,1,1,1,1,1,1,1,1,1,1,1,1,1,1,1,1,1,1,1
:endlayer
layer: 3
1,1,1,1,1,1,1,1,1,1,1,1,1,1,1,1,1,1,1,1,1,1,1,1,1,1,1,1,1,1,1
1,1,1,1,1,1,1,1,1,1,1,1,1,1,1,1,1,1,1,1,1,1,1,1,1,1,1,1,1,1,1
1,1,1,1,1,1,1,1,1,1,1,1,1,1,1,1,1,1,1,1,1,1,1,1,1,1,1,1,1,1,1
1,1,1,1,1,1,1,1,1,1,1,1,1,1,1,1,1,1,1,1,1,1,1,1,1,1,1,1,1,1,1
1,1,1,1,1,1,1,1,1,1,1,1,1,1,1,1,1,1,1,1,1,1,1,1,1,1,1,1,1,1,1
1,1,1,1,1,1,1,1,1,1,1,1,1,1,1,1,1,1,1,1,1,1,1,1,1,1,1,1,1,1,1
1,1,1,1,1,1,1,1,1,1,1,1,1,1,1,1,1,1,1,1,1,1,1,1,1,1,1,1,1,1,1
1,1,1,1,1,1,1,1,1,1,1,1,1,1,1,1,1,1,1,1,1,1,1,1,1,1,1,1,1,1,1
1,1,1,1,1,1,1,1,1,1,1,1,1,1,1,1,1,1,1,1,1,1,1,1,1,1,1,1,1,1,1
1,1,1,1,1,1,1,1,1,1,1,1,1,1,1,1,1,1,1,1,1,1,1,1,1,1,1,1,1,1,1
1,1,1,1,1,1,1,1,1,1,1,1,1,1,1,1,1,1,1,1,1,1,1,1,1,1,1,1,1,1,1
1,1,1,1,1,1,1,1,1,1,1,1,1,1,1,1,1,1,1,1,1,1,1,1,1,1,1,1,1,1,1
1,1,1,1,1,1,5,5,1,1,1,1,1,1,1,1,1,1,1,1,1,1,1,5,5,1,1,1,1,1,1
1,1,1,1,1,4,4,4,4,4,1,1,1,1,1,1,1,1,1,1,1,4,4,4,4,4,1,1,1,1,1
1,1,1,1,1,4,4,4,4,4,4,4,1,1,1,1,1,1,1,1,4,4,4,4,4,4,1,1,1,1,1
1,1,1,1,1,4,4,4,4,4,1,1,1,1,1,1,1,1,1,1,1,4,4,4,4,4,1,1,1,1,1
1,1,1,1,1,1,5,5,1,1,1,1,1,1,1,1,1,1,1,1,1,1,1,5,5,1,1,1,1,1,1
1,1,1,1,1,1,1,1,1,1,1,1,1,1,1,1,1,1,1,1,1,1,1,1,1,1,1,1,1,1,1
1,1,1,1,1,1,1,1,1,1,1,1,1,1,1,1,1,1,1,1,1,1,1,1,1,1,1,1,1,1,1
1,1,1,1,1,1,1,1,1,1,1,1,1,1,1,1,1,1,1,1,1,1,1,1,1,1,1,1,1,1,1
1,1,1,1,1,1,1,1,1,1,1,1,1,1,1,1,1,1,1,1,1,1,1,1,1,1,1,1,1,1,1
1,1,1,5,5,1,1,1,1,1,1,1,1,1,1,1,1,1,1,1,1,1,1,1,1,1,5,5,1,1,1
1,1,4,4,4,4,4,1,1,1,1,1,1,1,1,1,1,1,1,1,1,1,1,1,4,4,4,4,4,1,1
1,1,4,4,4,4,4,4,1,1,1,1,1,1,1,1,1,1,1,1,1,1,1,4,4,4,4,4,4,1,1
1,1,4,4,4,4,4,1,1,1,1,1,1,1,1,1,1,1,1,1,1,1,1,1,4,4,4,4,4,1,1
1,1,1,5,5,1,1,1,1,1,1,1,1,1,1,1,1,1,1,1,1,1,1,1,1,1,5,5,1,1,1
1,1,1,1,1,1,1,1,1,1,1,1,1,1,1,1,1,1,1,1,1,1,1,1,1,1,1,1,1,1,1
1,1,1,1,1,1,1,1,1,1,1,1,1,1,1,1,1,1,1,1,1,1,1,1,1,1,1,1,1,1,1
1,1,1,1,1,1,1,1,1,1,1,1,1,1,1,1,1,1,1,1,1,1,1,1,1,1,1,1,1,1,1
1,1,1,1,1,1,4,1,1,1,1,1,1,1,1,1,1,1,1,1,1,1,4,1,1,1,1,1,1,1,1
1,1,1,1,1,4,4,4,1,1,1,1,1,1,1,1,1,1,1,1,1,4,4,4,1,1,1,1,1,1,1
1,1,1,1,1,4,4,4,1,1,1,1,1,3,3,3,3,1,1,1,1,4,4,4,1,1,1,1,1,1,1
1,1,1,1,5,4,4,4,5,1,1,1,1,3,0,0,3,1,1,1,5,4,4,4,5,1,1,1,1,1,1
1,1,1,1,5,4,4,4,5,1,1,1,1,3,0,0,3,1,1,1,5,4,4,4,5,1,1,1,1,1,1
1,1,1,1,1,4,4,4,1,1,1,1,1,3,6,6,6,1,1,1,1,4,4,4,1,1,1,1,1,1,1
1,1,1,1,1,1,1,1,1,1,1,1,1,1,1,1,1,1,1,1,1,1,1,1,1,1,1,1,1,1,1
1,1,1,1,1,1,1,1,1,1,1,1,1,1,1,1,1,1,1,1,1,1,1,1,1,1,1,1,1,1,1
1,1,1,1,1,1,1,1,1,1,1,1,1,1,1,1,1,1,1,1,1,1,1,1,1,1,1,1,1,1,1
1,1,1,1,1,1,1,1,1,1,1,1,1,1,1,1,1,1,1,1,1,1,1,1,1,1,1,1,1,1,1
1,1,1,1,1,1,1,1,1,1,1,1,1,1,1,1,1,1,1,1,1,1,1,1,1,1,1,1,1,1,1
:endlayer
layer: 4
1,1,1,1,1,1,1,1,1,1,1,1,1,1,1,1,1,1,1,1,1,1,1,1,1,1,1,1,1,1,1
1,1,1,1,1,1,1,1,1,1,1,1,1,1,1,1,1,1,1,1,1,1,1,1,1,1,1,1,1,1,1
1,1,1,1,1,1,1,1,1,1,1,1,1,1,1,1,1,1,1,1,1,1,1,1,1,1,1,1,1,1,1
1,1,1,1,1,1,1,1,1,1,1,1,1,1,1,1,1,1,1,1,1,1,1,1,1,1,1,1,1,1,1
1,1,1,1,1,1,1,1,1,1,1,1,1,1,1,1,1,1,1,1,1,1,1,1,1,1,1,1,1,1,1
1,1,1,1,1,1,1,1,1,1,1,1,1,1,1,4,1,1,1,1,1,1,1,1,1,1,1,1,1,1,1
1,1,1,1,1,1,1,1,1,1,1,1,1,1,1,1,1,1,1,1,1,1,1,1,1,1,1,1,1,1,1
1,1,1,1,1,1,1,1,1,1,1,1,1,1,1,1,1,1,1,1,1,1,1,1,1,1,1,1,1,1,1
1,1,1,1,1,1,1,1,1,1,1,1,1,1,1,1,1,1,1,1,1,1,1,1,1,1,1,1,1,1,1
1,1,1,1,1,1,1,1,1,1,1,1,1,1,1,1,1,1,1,1,1,1,1,1,1,1,1,1,1,1,1
1,1,1,1,1,1,1,1,1,1,1,1,1,1,1,1,1,1,1,1,1,1,1,1,1,1,1,1,1,1,1
1,1,1,1,1,1,7,7,1,1,1,1,1,1,1,1,1,1,1,1,1,1,1,7,7,1,1,1,1,1,1
1,1,1,1,1,7,0,0,7,7,7,1,1,1,1,1,1,1,1,1,7,7,7,0,0,7,1,1,1,1,1
1,1,1,1,7,30,0,26,24,0,7,1,1,1,1,1,1,1,1,1,7,0,0,16,0,13,7,1,1,1,1
1,1,1,1,7,9,0,11,0,0,0,0,2,1,1,1,1,1,2,4,0,0,0,11,0,9,7,1,1,1,1
1,1,1,1,7,31,0,0,25,0,7,1,1,1,1,1,1,1,1,1,7,0,20,17,0,14,7,1,1,1,1
1,1,1,1,1,7,0,0,7,7,7,1,1,1,1,1,1,1,1,1,7,7,7,0,0,7,1,1,1,1,1
1,1,1,1,1,1,7,7,1,1,1,1,1,1,1,1,1,1,1,1,1,1,1,7,7,1,1,1,1,1,1
1,1,1,1,1,1,1,1,1,1,1,1,1,1,1,1,1,1,1,1,1,1,1,1,1,1,1,1,1,1,1
1,1,1,1,1,1,1,1,1,1,1,1,1,1,1,1,1,1,1,1,1,1,1,1,1,1,1,1,1,1,1
1,1,1,7,7,1,1,1,1,1,1,1,1,1,1,1,1,1,1,1,1,1,1,1,1,1,7,7,1,1,1
1,1,7,0,0,7,7,7,1,1,1,1,1,1,1,1,1,1,1,1,1,1,1,7,7,7,0,0,7,1,1
1,7,36,0,35,0,0,7,1,1,1,1,1,1,1,1,1,1,1,1,1,1,1,7,0,0,0,0,8,7,1
1,7,9,0,11,32,0,0,4,2,1,1,1,1,1,1,1,1,1,1,1,2,4,0,0,15,11,0,9,7,1
1,7,37,0,0,0,0,7,1,1,1,1,1,1,1,1,1,1,1,1,1,1,1,7,0,0,12,0,10,7,1
1,1,7,0,0,7,7,7,1,1,1,1,1,1,1,1,1,1,1,1,1,1,1,7,7,7,0,0,7,1,1
1,1,1,7,7,1,1,1,1,1,1,1,1,1,1,1,1,1,1,1,1,1,1,1,1,1,7,7,1,1,1
1,1,1,1,1,1,1,1,1,1,1,1,1,1,1,1,1,1,1,1,1,1,1,1,1,1,1,1,1,1,1
1,1,1,1,1,1,4,1,1,1,1,1,1,1,1,1,1,1,1,1,1,1,4,1,1,1,1,1,1,1,1
1,1,1,1,7,7,0,7,7,1,1,1,1,1,1,1,1,1,1,1,7,7,0,7,7,1,1,1,1,1,1
1,1,1,1,7,0,0,0,7,1,1,1,1,1,1,1,1,1,1,1,7,0,0,0,7,1,1,1,1,1,1
1,1,1,1,7,0,29,0,7,1,1,1,1,6,3,6,6,1,1,1,7,0,21,0,7,1,1,1,1,1,1
1,1,1,7,0,33,11,27,0,7,1,1,1,6,0,0,3,1,1,7,0,22,11,18,0,7,1,1,1,1,1
1,1,1,7,0,0,0,0,0,7,1,1,1,3,0,0,3,1,1,7,0,0,0,0,0,7,1,1,1,1,1
1,1,1,1,7,34,9,28,7,1,1,1,1,6,6,3,6,1,1,1,7,23,9,19,7,1,1,1,1,1,1
1,1,1,1,1,7,7,7,1,1,1,1,1,1,1,1,1,1,1,1,1,7,7,7,1,1,1,1,1,1,1
1,1,1,1,1,1,1,1,1,1,1,1,1,1,1,1,1,1,1,1,1,1,1,1,1,1,1,1,1,1,1
1,1,1,1,1,1,1,1,1,1,1,1,1,1,1,1,1,1,1,1,1,1,1,1,1,1,1,1,1,1,1
1,1,1,1,1,1,1,1,1,1,1,1,1,1,1,1,1,1,1,1,1,1,1,1,1,1,1,1,1,1,1
1,1,1,1,1,1,1,1,1,1,1,1,1,1,1,1,1,1,1,1,1,1,1,1,1,1,1,1,1,1,1
:endlayer
layer: 5
2,2,2,2,2,2,2,2,2,2,2,2,2,2,2,2,2,2,2,2,2,2,2,2,2,2,2,2,2,2,2
2,2,2,2,2,2,2,2,2,2,2,2,2,1,1,1,1,1,1,2,2,2,2,2,2,2,2,2,2,2,2
2,2,1,1,2,2,1,1,2,2,2,2,1,1,1,1,1,1,1,2,2,2,2,1,1,2,2,2,2,2,2
2,2,1,1,2,2,1,1,2,2,2,1,1,1,4,4,4,1,1,1,2,2,2,1,1,2,2,2,2,2,2
2,2,2,2,2,2,2,2,2,2,1,1,1,1,4,4,4,1,1,1,1,2,2,2,2,2,2,1,1,2,2
2,2,2,2,2,2,2,2,2,2,1,1,1,5,4,4,4,4,1,1,1,1,2,2,2,2,2,1,1,2,2
2,2,2,1,1,2,2,2,2,2,1,1,1,5,4,4,4,4,1,1,1,1,2,2,2,2,2,2,2,2,2
2,2,2,1,1,2,2,1,1,2,1,1,1,4,4,4,4,4,1,1,1,2,2,1,1,2,2,2,2,2,2
2,2,2,2,2,2,2,1,1,2,2,1,1,1,1,4,1,1,1,1,2,2,2,1,1,2,2,1,1,2,2
2,2,2,2,2,2,2,2,2,2,2,2,1,1,1,4,1,1,1,2,2,2,2,2,2,2,2,1,1,2,2
2,2,2,2,2,2,2,2,2,2,2,1,1,1,2,4,2,1,1,1,1,2,2,2,2,2,2,2,2,2,2
2,2,2,2,2,2,7,7,2,2,2,1,1,2,2,6,2,2,2,1,1,2,2,7,7,2,2,2,2,2,2
2,2,2,2,2,7,0,0,7,7,7,2,2,2,2,3,2,2,2,2,7,7,7,0,0,7,2,2,2,2,2
2,1,1,2,7,0,0,0,0,0,7,2,2,38,38,38,6,3,2,2,7,0,0,0,0,0,7,2,2,2,2
2,1,1,2,7,0,0,11,0,0,0,0,0,6,38,38,38,6,0,0,0,0,0,11,0,0,7,2,2,2,2
2,2,2,2,7,0,0,0,0,0,7,2,2,2,38,38,3,2,2,2,7,0,0,0,0,0,7,2,2,2,2
2,2,2,2,2,7,0,0,7,7,7,2,2,2,3,6,38,2,2,2,7,7,7,0,0,7,2,2,2,2,2
2,1,1,2,2,2,7,7,2,2,2,2,3,6,6,3,6,6,38,2,2,2,2,7,7,2,2,1,1,2,2
2,1,1,2,2,2,2,2,2,2,2,2,6,3,2,2,2,6,3,2,2,2,2,2,2,2,2,1,1,2,2
2,2,2,2,2,2,2,2,41,41,2,2,3,2,1,1,1,2,38,38,2,2,2,2,2,2,2,2,2,2,2
2,2,2,7,7,2,2,2,41,41,2,2,6,2,1,40,1,2,38,2,1,1,2,2,2,2,7,7,2,2,2
2,2,7,0,0,7,7,7,2,2,2,2,3,2,1,1,1,2,6,2,1,1,2,7,7,7,0,0,7,2,2
2,7,0,0,0,0,0,7,2,2,2,2,6,6,2,2,2,3,6,2,2,38,2,7,0,0,0,0,0,7,2
2,7,0,0,11,0,0,0,0,0,3,38,38,38,38,6,6,38,38,38,38,0,0,0,0,0,11,0,0,7,2
2,7,0,0,0,0,0,7,2,2,6,2,38,2,38,6,1,6,38,6,3,2,2,7,0,0,0,0,0,7,2
2,2,7,0,0,7,7,7,2,2,38,6,38,38,38,6,6,1,6,38,3,2,2,7,7,7,0,0,7,2,2
2,1,1,7,7,2,2,2,38,38,2,3,38,2,1,6,39,1,2,3,38,38,2,2,2,2,7,7,2,2,2
2,1,1,2,2,2,38,38,38,2,2,6,38,38,38,1,1,1,6,2,38,38,38,2,2,2,2,2,2,2,2
2,2,2,2,2,2,0,38,38,38,2,38,2,2,38,2,2,6,38,2,3,2,0,2,2,2,2,2,2,2,2
2,2,1,1,7,7,0,7,7,2,2,2,2,38,2,38,2,2,38,2,7,7,0,7,7,2,2,1,1,2,2
2,2,1,1,7,0,0,0,7,2,2,2,1,2,38,2,2,1,38,2,7,0,0,0,7,2,2,1,1,2,2
2,2,2,2,7,0,0,0,7,2,2,2,2,3,6,6,6,2,38,2,7,0,0,0,7,2,2,2,2,2,2
2,2,2,7,0,0,11,0,0,7,2,2,38,6,11,11,3,6,6,7,0,0,11,0,0,7,2,2,2,2,2
2,2,2,7,0,0,0,0,0,7,2,2,38,3,11,11,3,38,38,7,0,0,0,0,0,7,2,2,2,2,2
2,2,2,2,7,0,0,0,7,2,2,2,2,6,6,6,6,3,38,2,7,0,0,0,7,2,1,1,2,2,2
2,2,1,1,2,7,7,7,2,1,1,2,1,2,2,2,2,1,6,2,2,7,7,7,2,2,1,1,2,2,2
2,2,1,1,2,1,1,2,2,1,1,2,2,2,2,2,1,1,2,2,2,1,1,2,2,2,2,1,1,2,2
2,2,2,2,2,1,1,2,2,2,2,2,2,2,2,2,1,1,2,2,2,1,1,2,2,2,2,1,1,2,2
2,2,2,2,2,2,2,2,2,2,2,2,2,2,2,2,2,2,2,2,2,2,2,2,2,2,2,2,2,2,2
2,2,2,2,2,2,2,2,2,2,2,2,2,2,2,2,2,2,2,2,2,2,2,2,2,2,2,2,2,2,2
:endlayer
layer: 6
0,0,0,0,0,0,42,42,42,0,0,0,0,0,0,0,0,0,0,0,0,0,0,42,42,42,42,0,42,0,0
0,0,0,42,42,42,42,42,42,0,0,0,0,2,2,2,2,2,2,0,0,0,0,0,0,0,42,42,0,0,0
0,0,41,41,0,42,41,41,0,0,0,0,2,2,6,6,6,2,2,0,0,0,0,41,41,42,42,42,0,0,0
0,42,41,41,42,42,41,41,42,0,0,2,2,6,55,9,47,6,2,2,0,0,0,41,41,0,0,0,0,0,0
0,0,0,0,0,42,42,42,0,42,2,2,6,3,0,0,0,6,6,2,2,42,0,0,42,42,0,41,41,0,0
0,0,0,0,42,0,42,42,0,0,2,2,6,0,0,11,48,0,6,2,2,2,42,42,42,42,0,41,41,0,0
0,0,0,41,41,0,42,0,0,0,2,2,6,0,56,0,49,0,6,2,2,2,0,42,0,43,42,42,0,0,0
0,42,42,41,41,0,0,41,41,42,2,2,6,0,0,0,0,45,6,2,2,0,42,41,41,42,0,42,0,0,0
0,0,42,0,0,0,42,41,41,0,0,2,2,6,6,0,6,6,2,2,0,0,0,41,41,0,42,41,41,0,0
0,42,42,42,0,0,0,0,0,0,0,0,2,2,2,0,2,2,2,0,0,0,0,0,0,0,0,41,41,0,0
42,42,0,42,0,0,0,0,0,0,0,41,41,2,0,0,0,2,2,41,41,0,0,0,0,0,42,42,42,42,0
0,42,42,0,42,11,11,11,11,42,42,41,41,0,0,0,0,0,0,41,41,42,11,11,11,11,42,0,0,42,0
0,0,0,0,11,11,0,0,11,11,11,42,0,0,0,0,0,0,0,42,11,11,11,0,0,11,11,0,42,42,42
0,41,41,0,11,0,0,0,0,0,7,11,0,0,0,0,0,0,0,11,7,0,0,0,0,0,11,0,42,42,42
42,41,41,0,11,0,0,11,0,0,0,0,0,0,0,0,0,0,0,0,0,0,0,11,0,0,11,0,42,42,42
42,42,42,42,11,0,0,0,0,0,7,11,0,0,0,0,0,0,0,11,7,0,0,0,0,0,11,0,0,42,42
0,42,42,42,11,11,0,0,11,11,11,42,0,0,0,0,0,0,0,42,11,11,11,0,0,11,11,0,0,0,0
42,41,41,42,42,11,11,11,11,0,42,0,0,0,0,52,0,0,0,42,42,42,11,11,11,11,42,41,41,0,0
0,41,41,0,0,0,0,0,0,0,0,0,0,46,44,44,44,46,0,0,0,0,0,0,0,0,0,41,41,0,0
0,42,0,0,0,0,0,0,41,41,0,0,0,44,6,6,6,44,0,0,0,0,0,0,0,0,0,0,0,0,0
0,42,11,11,11,11,0,42,41,41,0,0,0,44,6,0,3,44,0,0,41,41,0,42,42,11,11,11,11,42,0
0,11,11,0,0,11,11,11,42,0,0,0,0,44,6,6,6,44,0,0,41,41,42,11,11,11,0,0,11,11,0
0,11,0,0,0,0,0,7,11,0,0,0,0,46,44,44,44,46,0,0,0,0,11,7,0,0,0,0,0,11,0
0,11,0,0,11,0,0,0,0,0,0,0,0,0,0,53,0,0,0,0,0,0,0,0,0,0,11,0,0,11,0
0,11,0,0,0,0,0,7,11,0,0,0,0,0,0,0,44,0,0,0,0,0,11,7,0,0,0,0,0,11,0
0,11,11,0,0,11,11,11,42,0,0,0,0,0,0,3,6,3,0,0,0,0,0,11,11,11,0,0,11,11,0
0,41,41,11,11,11,42,42,0,0,0,0,0,0,44,6,50,6,44,0,0,0,42,42,42,11,11,11,11,42,0
0,41,41,0,0,0,0,0,0,0,0,0,0,0,0,6,6,3,0,0,0,0,0,0,0,0,0,0,0,0,0
0,0,0,0,0,0,0,0,0,0,0,0,0,0,0,0,44,0,0,0,0,0,0,0,0,0,0,0,0,42,0
0,0,41,41,11,7,0,7,11,42,0,0,0,0,0,0,0,0,0,42,11,7,0,7,11,42,42,41,41,0,0
0,42,41,41,11,0,0,0,11,42,0,0,3,42,57,0,42,3,0,42,11,0,0,0,11,42,0,41,41,42,42
42,42,0,11,11,0,0,0,11,11,0,0,42,6,11,0,3,42,0,11,11,0,0,0,11,11,0,42,42,0,42
42,42,0,11,0,0,11,0,0,11,0,0,0,59,58,54,51,0,0,11,0,0,11,0,0,11,0,42,42,42,42
42,42,42,11,0,0,0,0,0,11,0,0,0,59,58,54,51,0,0,11,0,0,0,0,0,11,0,0,42,42,42
42,42,42,11,11,0,0,0,11,11,0,0,42,3,0,11,6,0,0,11,11,0,0,0,11,11,41,41,42,0,42
42,0,41,41,11,11,11,11,11,41,41,0,6,42,0,0,42,6,0,42,11,11,11,11,11,42,41,41,0,42,0
0,42,41,41,0,41,41,0,0,41,41,0,0,0,0,0,41,41,0,0,0,41,41,0,0,0,0,41,41,0,0
0,0,0,0,0,41,41,0,0,0,0,0,0,0,0,0,41,41,0,0,0,41,41,0,0,0,0,41,41,0,0
0,0,0,0,0,0,0,0,0,0,0,0,0,0,0,0,0,0,0,0,0,0,0,0,0,0,0,0,0,0,0
0,0,0,0,0,0,0,0,0,0,0,0,0,0,0,0,0,0,0,0,0,0,0,0,0,0,0,0,0,0,0
:endlayer
layer: 7
0,0,0,0,0,0,0,0,0,0,0,0,0,0,0,0,0,0,0,0,0,0,0,0,0,0,0,0,0,0,0
0,0,0,0,0,0,0,0,0,0,0,0,0,0,0,0,0,0,0,0,0,0,0,0,0,0,0,0,0,0,0
0,0,41,41,0,0,41,41,0,0,0,0,42,42,6,6,6,42,42,0,0,0,0,41,41,0,0,0,0,0,0
0,0,41,41,0,0,41,41,0,0,0,42,0,6,0,0,0,3,42,0,0,0,0,41,41,0,0,0,0,0,0
0,0,0,0,0,0,0,0,0,0,42,0,6,3,0,0,0,6,6,42,42,0,0,0,0,0,0,41,41,0,0
0,0,0,0,0,0,0,0,0,0,0,42,6,0,0,11,0,0,6,42,42,42,0,0,0,0,0,41,41,0,0
0,0,0,41,41,0,0,0,0,0,42,42,6,0,0,0,0,0,3,42,42,42,0,0,0,63,0,0,0,0,0
0,0,0,41,41,0,0,41,41,0,42,42,6,0,0,0,0,0,6,0,0,0,0,41,41,0,0,0,0,0,0
0,0,0,0,0,0,0,41,41,0,0,42,75,6,6,0,3,6,72,0,0,0,0,41,41,0,0,41,41,0,0
0,0,0,0,0,0,0,0,0,0,0,0,42,42,42,0,0,42,42,0,0,0,0,0,0,0,0,41,41,0,0
0,0,0,0,0,0,0,0,0,0,0,41,41,0,0,0,0,0,0,41,41,0,0,0,0,0,0,0,0,0,0
0,0,0,0,0,60,7,7,60,0,0,41,41,0,0,0,0,0,0,41,41,0,60,7,7,60,0,0,0,0,0
0,0,0,0,7,7,80,0,7,7,7,0,0,0,0,0,0,0,0,0,7,7,7,0,62,7,7,0,0,0,0
0,41,41,0,7,0,0,0,0,0,7,76,0,0,0,0,0,0,0,70,7,0,0,0,0,0,7,0,0,0,0
0,41,41,0,7,0,0,11,0,0,64,0,0,0,0,0,0,0,0,0,67,0,0,11,0,0,7,0,0,0,0
0,0,0,0,7,0,0,0,0,0,7,77,0,0,0,0,0,0,0,71,7,0,0,0,0,7,7,0,0,0,0
0,0,0,0,7,7,80,0,7,7,7,0,0,0,0,0,0,0,0,0,7,7,7,0,62,7,7,0,0,0,0
0,41,41,0,0,61,7,7,61,0,0,0,0,0,0,0,0,0,0,0,0,0,61,7,7,61,0,41,41,0,0
0,41,41,0,0,0,0,0,0,0,0,0,0,73,0,0,0,73,0,0,0,0,0,0,0,0,0,41,41,0,0
0,0,0,0,0,0,0,0,41,41,0,0,0,0,46,0,46,0,0,0,0,0,0,0,0,0,0,0,0,0,0
0,0,60,7,7,60,0,0,41,41,0,0,0,0,0,3,0,0,0,0,41,41,0,0,0,60,7,7,60,0,0
0,7,7,80,0,7,7,7,0,0,0,0,0,0,46,0,46,0,0,0,41,41,0,7,7,7,0,62,7,7,0
0,7,0,0,0,0,0,7,78,0,0,0,0,73,0,74,0,73,0,0,0,0,68,7,65,0,0,0,0,7,0
0,7,0,0,11,0,0,64,0,0,0,0,0,0,0,0,0,0,0,0,0,0,0,67,0,0,11,0,0,7,0
0,7,0,0,0,0,0,7,79,0,0,0,0,0,0,0,0,0,0,0,0,0,69,7,66,0,0,0,0,7,0
0,7,7,80,0,7,7,7,0,0,0,0,0,0,0,0,46,0,0,0,0,0,0,7,7,7,0,62,7,7,0
0,41,41,7,7,61,0,0,0,0,0,0,0,0,0,46,0,46,0,0,0,0,0,0,0,61,7,7,61,0,0
0,41,41,0,0,0,0,0,0,0,0,0,0,0,0,0,46,0,0,0,0,0,0,0,0,0,0,0,0,0,0
0,0,0,0,0,0,0,0,0,0,0,0,0,0,0,0,0,0,0,0,0,0,0,0,0,0,0,0,0,0,0
0,0,41,41,7,7,60,7,7,0,0,0,0,0,0,0,0,0,0,0,7,7,60,7,7,0,0,41,41,0,0
0,0,41,41,7,0,0,0,7,0,0,0,11,0,0,0,0,11,0,0,7,0,0,0,7,0,0,41,41,0,0
0,0,0,67,7,0,0,0,7,64,0,0,0,73,0,0,73,0,0,67,7,0,0,0,7,64,0,0,0,0,0
0,0,0,7,0,0,11,0,0,7,0,0,0,0,0,0,0,0,0,7,0,0,11,0,0,7,0,0,0,0,0
0,0,0,7,66,0,0,0,66,7,0,0,0,0,0,0,0,0,0,7,66,0,0,0,66,7,0,0,0,0,0
0,0,0,67,7,0,0,0,7,64,0,0,0,73,0,0,73,0,0,67,7,0,0,0,7,64,41,41,0,0,0
0,0,41,41,7,7,7,7,7,41,41,0,11,0,0,0,0,11,0,0,7,7,7,7,7,0,41,41,0,0,0
0,0,41,41,0,41,41,0,0,41,41,0,0,0,0,0,41,41,0,0,0,41,41,0,0,0,0,41,41,0,0
0,0,0,0,0,41,41,0,0,0,0,0,0,0,0,0,41,41,0,0,0,41,41,0,0,0,0,41,41,0,0
0,0,0,0,0,0,0,0,0,0,0,0,0,0,0,0,0,0,0,0,0,0,0,0,0,0,0,0,0,0,0
0,0,0,0,0,0,0,0,0,0,0,0,0,0,0,0,0,0,0,0,0,0,0,0,0,0,0,0,0,0,0
:endlayer
layer: 8
0,0,0,0,0,0,0,0,0,0,0,0,0,0,0,0,0,0,0,0,0,0,0,0,0,0,0,0,0,0,0
0,41,0,0,0,0,0,0,0,0,0,0,0,0,0,0,0,0,0,0,0,0,0,0,0,0,0,0,0,0,0
0,41,41,41,0,0,41,41,0,0,0,0,0,82,6,11,3,82,0,0,0,0,0,41,41,0,0,0,0,0,0
0,0,41,41,0,0,41,41,0,0,0,0,82,3,65,0,65,6,82,0,0,0,0,41,41,0,0,0,0,0,0
0,0,0,0,0,0,0,0,0,0,0,0,6,93,0,0,0,83,6,0,0,0,0,0,0,0,0,41,41,0,0
0,0,0,0,0,0,0,0,0,0,0,0,11,0,0,11,0,0,11,0,0,0,0,0,0,0,0,41,41,0,0
0,0,0,41,41,0,0,0,0,0,0,0,11,0,0,0,0,0,11,0,0,0,0,0,0,0,0,0,0,0,0
0,0,0,41,41,0,0,41,41,0,0,0,3,0,0,66,0,0,6,0,0,0,0,41,41,0,0,0,0,0,0
0,0,0,0,0,0,0,41,41,0,0,0,82,3,6,88,6,3,82,0,0,0,0,41,41,0,0,41,41,0,0
0,0,0,0,0,0,41,41,0,0,0,0,0,0,0,89,0,0,0,0,0,0,0,0,0,0,0,41,41,0,0
0,0,0,0,0,0,0,0,0,0,0,41,41,0,0,0,0,0,0,41,41,0,0,0,0,0,0,0,0,0,0
0,0,0,0,0,11,5,5,11,0,0,41,41,0,0,0,0,0,0,41,41,0,11,5,5,11,0,0,0,0,0
0,0,0,0,11,5,5,5,5,5,11,0,0,0,0,0,0,0,0,0,11,5,5,5,5,5,11,0,0,0,0
0,41,41,0,5,5,81,81,5,5,5,0,0,0,0,0,0,0,0,0,5,5,5,81,81,5,5,0,0,0,0
0,41,41,0,5,81,81,7,81,5,11,0,0,0,0,0,0,0,0,0,11,5,81,7,81,81,5,0,0,0,0
0,0,0,0,5,5,81,81,5,5,5,0,0,0,0,0,0,0,0,0,5,5,5,81,81,5,5,0,0,0,0
0,0,0,0,11,5,5,5,5,5,11,0,0,0,0,0,0,0,0,0,11,5,5,5,5,5,0,0,0,0,0
0,41,41,0,0,11,5,5,11,0,0,0,0,0,0,0,0,0,0,0,0,0,11,5,5,11,0,41,41,0,0
0,41,41,0,0,0,0,0,0,0,0,0,0,0,0,0,0,0,0,0,0,0,0,0,0,0,0,41,41,0,0
0,0,0,0,0,0,0,0,41,41,0,0,0,0,91,0,85,0,0,0,0,0,0,0,0,0,0,0,0,0,0
0,0,11,5,5,11,0,0,41,41,0,0,0,0,0,90,0,0,0,0,41,41,0,0,0,11,5,5,11,0,0
0,11,5,5,5,5,5,11,0,0,0,0,0,0,92,0,86,0,0,0,41,41,0,11,5,5,5,5,5,11,0
0,5,5,81,81,5,5,5,0,0,0,0,0,0,0,0,0,0,0,0,0,0,0,5,5,5,81,81,5,5,0
0,5,81,81,7,81,5,11,0,0,0,0,0,0,0,0,0,0,0,0,0,0,0,11,5,81,7,81,81,5,0
0,5,5,81,81,5,5,5,0,0,0,0,0,0,0,0,0,0,0,0,0,0,0,5,5,5,81,81,5,5,0
0,11,5,5,5,5,5,11,0,0,0,0,0,0,0,0,46,0,0,0,0,0,0,11,5,5,5,5,5,11,0
0,41,41,5,5,11,0,0,0,0,0,0,0,0,0,46,87,46,0,0,0,0,0,0,0,11,5,5,11,0,0
0,41,41,41,0,0,0,0,0,0,0,0,0,0,0,0,46,0,0,0,0,0,0,0,0,0,0,0,0,0,0
0,0,41,41,0,0,0,0,0,0,0,0,0,0,0,0,0,0,0,0,0,0,0,0,0,0,0,0,0,0,0
0,0,41,41,11,5,11,5,11,0,0,0,0,0,0,0,0,0,0,0,11,5,11,5,11,0,0,41,41,0,0
0,0,41,41,5,5,5,5,5,0,0,0,94,0,0,0,0,11,0,0,5,5,5,5,5,0,0,41,41,0,0
0,0,0,11,5,5,81,5,5,11,0,0,0,0,0,0,0,0,0,11,5,5,81,5,5,11,0,0,0,0,0
0,0,0,5,5,81,7,81,5,5,0,0,0,0,0,0,0,0,0,5,5,81,7,81,5,5,0,0,0,0,0
0,0,0,5,5,81,81,81,5,5,0,0,0,0,0,0,0,0,0,5,5,81,81,81,5,5,0,0,0,0,0
0,0,0,11,5,5,81,5,5,11,0,0,0,0,0,0,0,0,0,11,5,5,81,5,5,11,41,41,0,0,0
0,0,41,41,11,5,5,5,11,41,41,0,11,0,0,0,0,84,0,0,11,5,5,5,11,0,41,41,0,0,0
0,0,41,41,0,41,41,0,0,41,41,0,0,0,0,0,41,41,0,0,0,41,41,0,0,0,0,41,41,0,0
0,0,0,0,0,41,41,0,0,0,0,0,0,0,0,0,41,41,0,0,0,41,41,0,0,0,0,41,41,0,0
0,0,0,0,0,0,0,0,0,0,0,0,0,0,0,0,0,0,0,0,0,0,0,0,0,0,0,0,0,0,0
0,0,0,0,0,0,0,0,0,0,0,0,0,0,0,0,0,0,0,0,0,0,0,0,0,0,0,0,0,0,0
:endlayer
layer: 9
0,0,0,0,0,0,0,0,0,0,0,0,0,0,0,0,0,0,0,0,0,0,0,0,0,0,0,0,0,0,0
0,41,0,0,0,0,0,0,41,0,0,0,0,0,0,0,0,0,0,0,0,0,0,0,0,41,0,0,0,0,0
0,41,41,41,0,0,41,41,0,0,0,0,0,0,5,60,5,0,0,0,0,0,0,41,41,0,0,0,0,0,0
0,0,41,41,0,0,41,41,0,0,0,0,0,3,82,82,82,6,0,0,0,0,0,41,41,0,0,0,0,0,0
0,0,0,0,0,41,0,0,0,0,0,0,5,82,0,0,0,82,5,0,0,0,0,0,0,0,0,41,41,0,0
0,0,0,0,41,0,0,0,0,0,0,0,67,82,0,11,0,82,64,0,0,0,0,0,0,0,0,41,41,0,0
0,0,0,41,41,0,0,0,0,0,0,0,67,82,0,0,0,82,64,0,0,0,0,0,0,0,0,0,0,0,0
0,0,0,41,41,0,0,41,41,0,0,0,6,82,82,82,82,82,3,0,0,0,0,41,41,0,0,0,0,0,0
0,0,0,41,0,0,0,41,41,0,0,0,0,5,5,121,5,5,0,0,0,0,0,41,41,0,0,41,41,0,0
0,0,0,0,0,0,41,41,0,0,0,0,0,0,0,0,0,0,0,0,0,0,0,0,0,0,0,41,41,0,0
0,0,0,0,0,0,0,0,0,0,0,41,41,0,0,0,0,0,0,41,41,0,0,0,0,0,0,0,0,0,0
0,0,0,0,0,135,0,0,128,0,0,41,41,0,0,0,0,0,0,41,41,0,112,0,0,101,0,0,0,0,0
0,0,0,0,139,0,0,0,0,0,124,0,0,0,0,0,0,0,0,0,114,0,0,0,0,0,100,0,0,0,0
0,41,41,0,0,0,0,0,0,0,0,0,0,0,0,0,0,0,0,0,0,0,0,0,0,0,0,0,0,0,0
0,41,41,0,0,0,0,7,0,0,11,0,0,0,0,0,0,0,0,0,11,0,0,7,0,0,0,0,0,0,0
0,0,41,0,0,0,0,0,0,0,0,0,0,0,0,0,0,0,0,0,0,0,0,0,0,0,0,0,0,0,0
0,0,0,0,140,0,0,0,0,0,125,0,0,0,0,0,0,0,0,0,115,0,0,0,0,0,0,0,0,0,0
0,41,41,0,0,136,0,0,129,0,0,0,0,0,0,0,0,0,0,0,0,0,113,0,0,102,0,41,41,0,0
0,41,41,0,0,0,0,0,0,0,0,0,0,0,0,0,0,0,0,0,0,0,0,0,0,0,0,41,41,0,0
0,0,0,0,0,0,0,0,41,41,0,0,0,0,0,0,0,0,0,0,0,0,0,0,0,0,0,0,0,0,0
0,0,146,0,0,137,0,0,41,41,0,0,0,0,0,122,0,0,0,0,41,41,0,0,0,103,0,0,97,0,0
0,147,0,0,0,0,0,132,0,0,0,0,0,0,0,0,0,0,0,0,41,41,0,109,0,0,0,0,0,95,0
0,0,0,0,0,0,0,0,0,0,0,0,0,0,0,0,0,0,0,0,0,0,0,0,0,0,0,0,0,0,0
0,0,0,143,7,0,0,11,0,0,0,0,0,0,0,0,0,0,0,0,0,0,0,11,0,0,7,99,0,0,0
0,0,0,0,0,0,0,0,0,0,0,0,0,0,0,0,0,0,0,0,0,0,0,0,0,0,0,0,0,0,0
0,148,0,0,0,0,0,133,0,0,0,0,0,0,0,46,46,46,0,0,0,0,0,110,0,0,0,0,0,96,0
0,41,41,0,0,138,0,0,0,0,0,0,0,0,0,46,0,46,0,0,0,0,0,0,0,104,0,0,98,0,0
0,41,41,41,0,0,0,0,0,0,0,0,0,0,0,46,46,46,0,0,0,0,0,0,0,0,0,0,0,0,0
0,0,41,41,0,0,0,0,0,0,0,0,0,0,0,0,0,0,0,0,0,0,0,0,0,0,0,0,0,0,0
0,0,41,41,141,0,11,0,130,0,0,0,0,0,0,0,0,0,0,0,116,0,11,0,107,0,0,41,41,0,0
0,0,41,41,0,0,0,0,0,0,0,0,0,0,0,0,0,120,0,0,0,0,0,0,0,0,0,41,41,0,0
0,0,0,144,0,0,0,0,0,126,0,0,0,0,0,0,0,0,0,118,0,0,0,0,0,105,0,0,41,0,0
0,0,0,0,0,0,7,0,0,0,0,0,0,0,0,0,0,0,0,0,0,0,7,0,0,0,0,0,0,0,0
0,0,0,0,0,0,134,0,0,0,0,0,0,0,0,0,0,0,0,0,0,0,0,0,0,0,0,0,0,0,0
0,0,0,145,0,0,0,0,0,127,0,0,0,0,0,0,0,0,0,119,0,0,0,0,0,106,41,41,0,0,0
0,0,41,41,142,0,0,0,131,41,41,0,123,0,0,0,0,0,0,0,117,0,0,111,108,0,41,41,0,0,0
0,0,41,41,0,41,41,0,0,41,41,0,0,0,0,0,41,41,0,0,0,41,41,0,0,0,0,41,41,0,0
0,0,0,0,0,41,41,0,0,0,0,0,0,0,0,0,41,41,0,0,0,41,41,0,0,0,0,41,41,0,0
0,0,0,0,0,0,0,0,0,0,0,0,0,0,0,0,0,0,0,0,0,0,0,0,0,0,0,0,0,0,0
0,0,0,0,0,0,0,0,0,0,0,0,0,0,0,0,0,0,0,0,0,0,0,0,0,0,0,0,0,0,0
:endlayer
layer: 10
0,0,0,0,0,0,0,0,0,0,0,0,0,0,0,0,0,0,0,0,0,0,0,0,0,0,0,0,0,0,0
0,41,0,0,0,41,0,0,41,0,0,0,0,0,0,0,0,0,0,0,0,0,41,0,0,41,0,0,0,0,0
0,41,41,41,0,0,41,41,0,0,0,0,0,0,0,0,0,0,0,0,0,0,0,41,41,0,0,0,0,0,0
0,0,41,41,0,0,41,41,0,0,0,0,0,11,0,153,0,11,0,0,0,0,0,41,41,0,0,0,0,0,0
0,0,0,41,0,41,0,0,0,0,0,0,0,0,5,154,5,0,0,0,0,0,0,0,0,0,0,41,41,0,0
0,0,0,0,41,159,159,159,159,159,159,0,0,0,158,6,152,0,0,0,0,0,0,0,0,0,0,41,41,0,0
0,0,0,41,41,159,159,159,159,159,159,0,0,0,5,155,5,0,0,0,0,0,0,0,0,0,0,0,0,41,0
0,0,41,41,41,159,159,41,41,159,159,0,11,0,0,0,0,0,11,0,0,0,0,41,41,41,0,0,0,0,0
0,0,0,41,159,159,159,41,41,159,159,0,0,0,0,156,0,0,0,0,0,0,0,41,41,0,0,41,41,0,0
0,0,0,0,159,159,41,41,159,159,159,0,0,0,0,0,0,0,0,0,0,0,0,0,0,0,0,41,41,0,0
0,0,0,0,159,159,159,159,159,159,159,41,41,0,0,0,0,0,0,41,41,0,0,0,0,0,0,0,0,0,0
0,0,0,0,0,159,159,159,159,0,0,41,41,0,0,0,0,0,0,41,41,0,0,0,0,0,0,0,0,0,0
0,41,41,0,0,0,0,0,0,0,0,0,0,0,0,0,0,0,0,0,0,0,0,0,0,0,0,0,0,0,0
0,41,41,41,0,0,0,0,0,0,0,0,0,0,0,0,0,0,0,0,0,0,0,0,0,0,0,0,0,0,0
41,0,0,41,0,0,0,11,0,0,160,0,0,0,0,0,0,0,0,0,151,0,0,11,0,0,0,0,0,0,0
41,0,41,0,0,0,0,0,0,0,0,0,0,0,0,0,0,0,0,0,0,0,0,0,0,0,0,0,0,0,0
0,0,0,0,0,0,0,0,0,0,0,0,0,0,0,0,0,0,0,0,0,0,0,0,0,0,0,0,0,0,0
0,41,41,0,0,0,0,0,0,0,0,0,0,0,0,0,0,0,0,0,0,0,0,0,0,0,0,41,41,0,0
0,41,41,0,0,0,0,0,0,0,0,0,0,0,0,0,0,0,0,0,0,0,0,0,0,0,0,41,41,0,0
0,41,0,41,0,0,0,0,41,41,0,0,0,0,0,0,0,0,0,0,0,0,0,0,0,0,0,0,0,0,0
0,0,0,0,0,0,0,0,41,41,0,0,0,0,0,157,0,0,0,0,41,41,0,0,0,0,0,0,0,0,0
0,0,0,0,0,0,0,0,0,0,0,0,0,0,0,0,0,0,0,0,41,41,0,0,0,0,0,0,0,0,0
0,0,0,0,0,0,0,0,0,0,0,0,0,0,0,0,0,0,0,0,0,0,0,0,0,0,0,0,0,0,0
0,0,0,0,11,0,0,161,0,0,0,0,0,0,0,0,0,0,0,0,0,0,0,149,0,0,11,0,0,0,0
0,0,0,0,0,0,0,0,0,0,0,0,0,0,0,0,0,0,0,0,0,0,0,0,0,0,0,0,0,0,0
0,0,0,0,0,0,0,0,0,0,0,0,0,0,0,46,46,46,0,0,0,0,0,0,0,0,0,0,0,0,0
0,41,41,0,0,0,0,0,0,0,0,0,0,0,0,46,0,46,0,0,0,0,0,0,0,0,0,0,0,0,0
0,41,41,41,0,0,0,0,0,0,0,0,0,0,0,46,46,46,0,0,0,0,0,0,0,0,0,0,0,0,0
0,0,41,41,0,0,0,0,0,0,0,0,0,0,0,0,0,0,0,0,0,0,0,0,0,0,0,0,0,41,0
0,0,41,41,0,0,162,0,0,0,0,0,0,0,0,0,0,0,0,0,0,0,150,0,0,0,0,41,41,0,0
0,0,41,41,0,0,0,0,0,0,0,0,0,0,0,0,0,0,0,0,0,0,0,0,0,0,0,41,41,0,0
0,0,0,0,0,0,0,0,0,0,0,0,0,0,0,0,0,0,0,0,0,0,0,0,0,0,0,0,41,0,0
0,0,0,0,0,0,11,0,0,0,0,0,0,0,0,0,0,0,0,0,0,0,11,0,0,0,0,0,0,0,0
0,0,0,0,0,0,0,0,0,0,0,0,0,0,0,0,0,0,0,0,0,0,0,0,0,0,0,0,0,0,0
0,0,0,0,0,0,0,0,0,0,0,0,0,0,0,0,0,0,0,0,0,0,0,0,0,0,41,41,0,0,0
0,0,41,41,0,0,0,0,0,41,41,0,0,0,0,0,0,0,0,0,0,0,0,0,0,0,41,41,0,0,0
0,0,41,41,0,41,41,0,0,41,41,0,0,0,0,0,41,41,0,0,0,41,41,0,0,0,0,41,41,0,0
0,0,0,0,0,41,41,0,0,0,0,0,0,0,0,0,41,41,0,0,0,41,41,0,0,0,0,41,41,0,0
0,0,0,0,0,0,0,0,0,0,0,0,0,0,0,0,0,0,0,0,0,0,0,0,0,0,0,0,0,0,0
0,0,0,0,0,0,0,0,0,0,0,0,0,0,0,0,0,0,0,0,0,0,0,0,0,0,0,0,0,0,0
:endlayer
layer: 11
159,159,159,0,0,0,0,0,0,0,0,0,0,0,0,0,0,0,0,0,159,159,159,159,159,159,159,159,0,0,0
159,41,159,159,159,41,0,41,41,0,0,0,0,0,0,0,0,0,0,0,159,159,41,159,159,41,159,159,0,0,0
159,41,41,41,159,159,41,41,0,0,0,0,0,0,0,0,0,0,0,0,159,159,159,41,41,159,159,159,0,0,0
159,159,41,41,159,159,41,41,0,0,0,0,0,168,0,0,0,166,0,0,0,159,159,41,41,159,159,0,0,0,0
159,159,159,41,159,41,159,159,159,159,0,0,0,0,0,0,0,0,0,0,0,159,159,159,159,159,159,41,41,0,0
159,159,159,159,41,159,159,159,159,159,159,159,0,0,0,11,0,0,0,0,0,159,159,159,159,159,159,41,41,0,0
159,159,159,41,41,159,159,159,159,159,159,159,0,0,0,0,0,0,0,0,0,0,0,0,0,0,0,0,0,41,0
0,0,41,41,41,159,159,41,41,159,159,159,169,0,0,0,0,0,165,0,0,0,41,41,41,41,0,0,0,0,0
0,0,0,41,159,159,159,41,41,159,159,159,0,0,0,0,0,0,0,0,0,0,0,41,41,0,0,41,41,0,0
0,0,0,0,159,159,159,159,159,159,159,159,0,0,0,0,0,0,0,0,0,0,0,0,0,0,0,41,41,0,0
159,159,159,159,159,159,159,159,159,159,0,41,41,0,0,0,0,0,41,41,41,0,0,0,0,0,0,0,0,0,0
159,159,159,159,159,159,159,159,159,159,0,41,41,0,0,0,0,0,0,41,41,0,0,0,0,0,0,0,0,0,0
159,41,41,159,159,159,0,0,0,0,0,0,0,0,0,0,0,0,0,0,0,41,0,0,0,0,0,0,0,0,0
159,41,41,41,159,159,0,0,0,0,0,0,0,0,0,0,0,0,0,0,0,0,0,0,0,0,0,0,0,0,0
41,159,159,41,159,159,0,170,0,0,0,0,0,0,0,0,0,0,0,0,0,0,0,164,0,0,0,0,0,0,0
41,159,41,159,159,0,0,0,0,0,0,0,0,0,0,0,0,0,0,0,0,0,0,0,0,0,0,0,0,0,0
159,159,159,159,0,0,0,0,0,0,0,0,0,0,0,0,0,0,0,0,0,0,0,0,0,0,0,0,0,0,0
0,41,41,0,0,0,0,0,0,0,0,0,0,0,0,0,0,0,0,0,0,0,0,0,0,0,0,41,41,0,0
41,41,41,0,0,0,0,0,0,0,41,0,0,0,0,0,0,0,0,0,0,0,0,0,0,0,0,41,41,0,0
41,41,0,41,0,0,0,0,41,41,0,0,0,0,0,0,0,0,0,0,0,0,0,0,0,0,0,0,0,0,0
0,0,0,0,0,0,0,0,41,41,0,0,0,0,0,0,0,0,0,0,41,41,0,0,0,0,0,0,0,0,0
0,0,0,0,0,0,0,0,0,0,0,0,0,0,0,0,0,0,0,0,41,41,0,0,0,0,0,0,0,0,0
0,0,0,0,0,0,0,0,0,0,0,0,0,0,0,0,0,0,0,0,0,0,0,0,0,0,0,0,0,0,0
0,0,0,0,171,0,0,0,0,0,0,0,0,0,0,0,0,0,0,0,0,0,0,0,0,0,163,0,0,0,0
0,0,0,0,0,0,0,0,0,0,0,0,0,0,0,0,0,0,0,0,0,0,0,0,0,0,0,0,0,0,0
0,0,0,0,0,0,0,0,0,0,0,0,0,0,0,0,46,0,0,0,0,0,0,0,0,0,0,0,0,0,0
0,41,41,0,0,0,0,0,0,0,0,0,0,0,0,0,46,167,0,0,0,0,0,0,0,0,0,0,0,0,0
0,41,41,41,0,0,0,0,0,0,0,0,0,0,0,0,46,0,0,0,0,0,0,0,0,0,0,0,0,0,0
0,0,41,41,0,0,0,0,0,0,0,0,0,0,0,0,0,0,0,0,0,0,0,0,0,0,0,0,0,41,0
0,0,41,41,0,0,0,0,0,0,0,0,0,0,0,0,0,0,0,0,0,0,0,0,0,0,0,41,41,0,0
0,0,41,41,0,0,0,0,0,0,0,0,0,0,0,0,0,0,0,0,0,0,0,0,0,0,0,41,41,0,0
0,0,0,0,0,0,0,0,0,0,0,0,0,0,0,0,0,0,0,0,0,0,0,0,0,0,0,0,41,0,0
0,0,0,0,0,0,0,0,0,0,0,0,0,0,0,0,0,0,0,0,0,0,0,0,0,0,0,0,0,0,0
0,0,0,0,0,0,0,0,0,0,0,0,0,0,0,0,0,0,0,0,0,0,0,0,0,0,0,0,0,0,0
0,0,0,0,0,0,0,0,0,0,0,0,0,0,0,0,0,0,0,0,0,0,0,0,0,0,41,41,0,0,0
0,0,41,41,0,0,0,0,0,41,41,0,0,0,0,0,0,0,0,0,0,0,0,0,0,0,41,41,0,0,0
0,0,41,41,0,41,41,0,0,41,41,0,0,0,0,0,41,41,0,0,41,41,41,0,0,0,0,41,41,41,0
0,0,0,0,0,41,41,0,0,0,0,0,0,0,0,0,41,41,0,0,0,41,41,0,0,0,0,41,41,0,0
0,0,0,0,0,0,0,0,0,0,0,0,0,0,0,0,0,0,0,0,0,0,0,0,0,0,0,0,0,0,0
0,0,0,0,0,0,0,0,0,0,0,0,0,0,0,0,0,0,0,0,0,0,0,0,0,0,0,0,0,0,0
:endlayer
layer: 12
159,159,159,159,159,159,159,159,159,159,159,0,0,0,0,0,0,0,0,0,159,159,159,159,159,159,159,159,0,0,0
159,159,159,159,159,41,159,41,41,159,159,0,0,0,0,0,0,0,0,0,159,159,159,159,159,159,159,159,0,0,0
159,159,159,159,159,159,41,41,159,159,159,0,0,0,0,0,0,0,0,0,159,159,159,41,41,159,159,159,0,0,0
159,159,41,41,159,159,41,41,159,159,0,0,0,0,0,0,0,0,0,0,159,159,159,41,41,159,159,159,0,0,0
159,159,41,41,159,41,159,159,159,159,0,0,0,0,0,0,0,0,0,0,159,159,159,159,159,159,41,41,0,0,0
159,159,159,159,41,159,159,159,159,159,0,0,0,0,0,11,0,0,0,0,0,159,159,159,159,159,41,41,0,0,0
159,159,159,41,41,159,159,159,159,159,0,0,0,0,0,0,0,0,0,0,0,159,159,159,159,41,0,41,0,41,0
159,159,41,41,41,159,159,159,159,159,159,0,0,0,0,0,0,0,0,0,0,0,41,41,41,41,0,0,0,0,0
0,159,159,41,159,159,159,159,159,159,159,0,0,0,0,0,0,0,0,0,0,0,0,41,41,0,41,41,41,0,0
159,159,159,159,159,0,159,159,159,159,41,0,0,0,0,0,0,0,0,0,0,0,0,0,0,0,0,41,41,0,0
159,159,159,159,159,159,0,159,159,0,0,41,41,0,0,0,0,0,41,41,41,41,0,0,0,0,0,0,0,0,0
159,159,159,159,159,159,0,0,0,0,0,41,41,0,0,0,0,0,0,41,41,0,0,0,0,0,0,0,0,0,0
159,41,41,159,159,159,0,0,0,0,0,0,0,41,0,0,0,0,41,0,0,41,0,0,0,0,0,0,0,0,0
159,41,41,159,159,159,0,0,0,0,0,0,0,0,0,0,0,0,0,0,0,0,0,0,0,0,0,0,0,0,0
159,159,159,159,159,159,0,0,0,0,0,0,0,0,0,0,0,0,0,0,0,0,0,0,0,0,0,0,0,0,0
159,159,159,159,0,0,0,0,0,0,0,0,0,0,0,0,0,0,0,0,0,0,0,0,0,0,0,0,0,0,0
41,159,41,41,0,0,0,0,0,0,0,0,0,0,0,0,0,0,0,0,0,0,0,0,0,0,0,41,0,0,0
41,41,41,0,0,0,0,0,0,0,0,0,0,0,0,0,0,0,0,0,0,0,0,0,0,0,0,41,41,41,0
41,41,41,0,0,0,0,0,41,0,41,0,0,0,0,0,0,0,0,0,0,0,0,0,0,0,0,41,41,41,0
41,41,0,41,0,0,0,0,41,41,0,0,0,0,0,0,0,0,0,0,0,0,0,0,0,0,41,0,0,41,0
0,0,0,0,0,0,0,41,41,41,0,0,0,0,0,0,0,0,0,0,41,41,0,0,0,0,0,0,0,0,0
0,0,0,0,0,0,0,0,0,0,0,0,0,0,0,0,0,0,0,0,41,41,0,0,0,0,0,0,0,0,0
0,0,0,0,0,0,0,0,0,0,0,0,0,0,0,0,0,0,0,0,0,0,0,0,0,0,0,0,0,0,0
0,0,0,0,0,0,0,0,0,0,0,0,0,0,0,0,0,0,0,0,0,0,0,0,0,0,0,0,0,0,0
0,0,0,0,0,0,0,0,0,0,0,0,0,0,0,0,0,0,0,0,0,0,0,0,0,0,0,0,0,0,0
0,0,0,41,0,0,0,0,0,0,0,0,0,0,0,0,0,0,0,0,0,0,0,0,0,0,0,0,0,0,0
0,41,41,0,0,0,0,0,0,0,0,0,0,0,0,0,0,0,0,0,0,0,0,0,0,0,0,0,159,159,159
41,41,41,0,0,0,0,0,0,0,0,0,0,0,0,0,0,0,0,0,0,0,0,0,0,159,159,159,159,159,159
0,0,41,41,0,0,0,0,0,0,0,0,0,0,0,0,0,0,0,0,0,0,0,0,0,159,159,159,159,41,159
0,0,41,41,0,0,0,0,0,0,0,0,0,0,0,0,0,0,0,0,0,0,0,0,0,159,159,41,41,159,159
0,0,41,41,0,0,0,0,0,0,0,0,0,0,0,0,0,0,0,0,0,0,0,0,0,159,159,41,41,159,159
0,0,0,0,0,0,0,0,0,0,0,0,0,0,0,0,0,0,0,0,0,0,0,0,0,159,159,159,41,159,159
0,0,0,0,0,0,0,0,0,0,0,0,0,0,0,0,0,0,0,0,0,0,0,0,0,159,159,159,159,159,159
0,0,0,0,0,0,0,0,0,0,0,0,0,0,0,0,0,0,0,0,0,0,0,0,0,0,0,159,159,159,0
0,0,0,0,0,0,0,0,0,0,0,0,0,0,0,0,0,0,0,0,0,0,0,0,0,41,41,41,0,0,0
0,0,41,41,0,0,0,0,0,41,41,0,0,0,0,0,0,0,0,0,41,0,0,41,0,0,41,41,0,41,0
0,0,41,41,0,41,41,0,0,41,41,0,0,0,0,0,41,41,0,0,41,41,41,0,0,0,41,41,41,41,0
0,0,0,0,0,41,41,0,0,0,0,0,0,0,0,0,41,41,0,0,0,41,41,0,0,0,0,41,41,0,0
0,0,0,0,0,0,0,0,0,0,0,0,0,0,0,0,0,0,0,0,0,0,0,0,0,0,0,0,0,0,0
0,0,0,0,0,0,0,0,0,0,0,0,0,0,0,0,0,0,0,0,0,0,0,0,0,0,0,0,0,0,0
:endlayer
layer: 13
173,0,0,159,159,159,159,159,159,159,159,0,0,0,0,0,0,0,0,0,0,0,0,159,159,0,0,0,0,0,0
0,0,159,159,159,159,159,159,159,159,159,0,0,0,0,0,0,0,0,0,0,0,159,159,159,159,0,0,0,0,0
0,159,159,159,159,159,41,41,159,159,159,0,0,0,0,0,0,0,0,0,0,159,159,159,159,159,159,159,159,0,0
159,159,159,159,159,159,41,41,159,159,159,0,0,0,0,0,0,0,0,0,0,159,159,159,159,159,159,159,159,0,0
159,159,159,159,159,159,159,159,159,159,159,0,0,0,0,0,0,0,0,0,0,0,159,159,159,41,41,159,159,0,0
159,159,159,41,41,159,159,159,159,0,0,0,0,0,0,172,0,0,0,0,0,159,159,159,159,41,41,159,159,159,0
159,159,159,41,41,159,159,159,159,0,0,0,0,0,0,0,0,0,0,0,159,159,159,159,159,41,159,41,159,41,159
159,159,159,159,159,159,159,159,0,0,0,0,0,0,0,0,0,0,0,0,159,159,41,41,41,41,159,159,159,159,159
0,159,159,159,159,159,0,0,0,0,0,0,0,0,0,0,0,0,0,0,159,159,159,41,41,159,41,41,41,159,159
0,159,159,159,159,159,0,0,0,0,41,0,0,41,0,0,0,0,0,41,0,159,159,159,159,159,159,41,41,159,159
0,159,159,0,0,0,0,0,0,0,0,41,41,0,0,0,0,0,41,41,41,41,159,159,159,159,159,159,159,159,159
159,159,159,159,0,0,0,0,0,0,0,41,41,0,0,0,0,0,41,41,41,0,0,0,0,159,159,159,159,159,159
159,159,159,159,159,0,0,0,0,0,0,0,0,41,0,0,0,0,41,0,0,41,0,0,0,0,0,0,0,0,0
159,159,159,159,159,0,0,0,0,0,0,0,0,0,0,0,0,0,0,0,0,0,0,0,0,0,0,0,0,0,0
159,159,159,159,159,0,0,0,0,0,0,0,0,0,0,0,0,0,0,0,0,0,0,0,0,0,0,0,0,0,0
159,159,159,159,159,159,0,0,0,0,0,0,0,0,0,0,0,0,0,0,0,0,0,0,0,0,0,0,0,0,0
41,159,41,41,159,159,0,0,0,0,0,0,0,0,0,0,0,0,0,0,0,0,0,0,0,0,159,41,159,0,0
41,41,41,159,159,159,0,0,0,0,0,0,0,0,0,0,0,0,0,0,0,0,0,0,0,159,159,159,159,41,159
41,41,41,159,159,159,0,0,41,0,41,0,0,0,0,0,0,0,0,0,0,0,0,0,0,159,159,41,41,41,159
41,41,159,41,159,159,0,41,41,41,0,0,0,0,0,0,0,0,0,41,0,0,0,0,0,159,41,41,41,41,159
159,159,159,159,159,159,0,41,41,41,41,0,0,0,0,0,0,0,0,0,41,41,0,0,159,159,159,159,159,159,159
159,159,159,159,159,0,0,0,0,0,41,0,0,0,0,0,0,0,0,0,41,41,0,0,159,159,159,159,159,159,159
0,0,0,0,0,0,0,0,0,0,0,0,0,0,0,0,0,0,0,41,0,0,0,0,159,159,159,159,159,159,159
0,0,0,0,0,0,0,0,0,0,0,0,0,0,0,0,0,0,0,0,0,0,0,0,0,159,159,159,159,159,159
0,0,0,0,0,0,0,0,0,0,0,0,0,0,0,0,0,0,0,0,0,0,0,0,0,0,0,0,0,0,0
0,0,0,41,0,0,0,0,0,0,0,0,0,0,0,0,0,0,0,0,0,0,0,0,0,0,0,0,0,0,0
0,41,41,0,0,0,0,0,0,0,0,0,0,0,0,0,0,0,0,0,0,0,0,0,0,159,159,159,159,159,0
41,41,41,41,0,0,0,0,0,0,0,0,0,0,0,0,0,0,0,0,0,0,0,0,159,159,159,159,159,159,159
0,41,41,41,0,0,0,0,0,0,0,0,0,0,0,0,0,0,0,0,0,0,0,0,159,159,159,159,159,159,159
0,41,41,41,0,0,0,0,0,0,0,0,0,0,0,0,0,0,0,0,0,0,0,0,159,159,159,41,41,159,159
0,0,41,41,0,0,0,0,0,0,0,0,0,0,0,0,0,0,0,0,0,0,0,0,159,159,159,41,41,159,159
0,0,0,0,0,0,0,0,0,0,0,0,0,0,0,0,0,0,0,0,0,0,0,0,159,159,159,159,159,159,159
0,0,0,0,0,0,0,0,0,0,0,0,0,0,0,0,0,0,0,0,0,0,0,0,0,159,159,159,159,159,0
0,0,0,0,0,0,0,0,0,0,0,0,0,0,0,0,0,0,0,0,0,0,0,0,0,159,159,159,159,159,0
0,0,0,0,0,0,0,0,0,41,0,0,0,0,0,0,0,0,0,0,0,0,0,0,0,41,41,41,41,0,0
0,0,41,41,41,0,0,41,0,41,41,0,0,0,0,0,0,0,0,0,41,0,41,41,0,0,41,41,0,41,0
0,0,41,41,41,41,41,0,0,41,41,0,0,0,0,0,41,41,0,0,41,41,41,41,0,41,41,41,41,41,0
0,41,0,0,41,41,41,0,41,0,0,41,0,0,0,0,41,41,0,0,0,41,41,0,0,0,0,41,41,41,0
0,0,0,0,0,0,0,0,0,0,0,0,0,0,0,0,0,41,0,0,0,41,0,0,0,0,0,41,0,0,0
0,0,0,0,0,0,0,0,0,0,0,0,0,0,0,0,0,0,0,0,0,0,0,0,0,0,0,0,0,0,0
:endlayer
layer: 14
0,0,0,0,0,0,159,159,0,0,0,0,0,0,0,0,0,0,0,0,0,0,0,0,0,0,0,0,0,0,0
0,0,0,0,0,159,159,159,159,0,0,0,0,0,0,0,0,0,0,0,0,0,0,159,159,159,159,159,0,0,0
0,0,0,0,159,159,159,159,159,159,0,0,0,0,0,0,0,0,0,0,0,0,159,159,159,159,159,159,159,159,0
0,0,0,159,159,159,159,159,159,159,0,0,0,0,0,0,0,0,0,0,0,0,159,159,159,159,159,159,159,159,0
0,0,159,159,159,159,159,159,159,0,0,0,0,0,0,0,0,0,0,0,0,159,159,159,159,41,41,159,159,159,0
0,159,159,159,159,159,159,159,0,0,0,0,0,0,0,0,0,0,0,0,159,159,159,159,159,41,41,159,159,159,0
0,159,159,159,159,159,159,0,0,0,0,0,0,0,0,0,0,0,0,0,159,159,159,159,159,159,159,159,159,159,159
0,0,159,159,159,159,0,0,0,0,0,0,0,0,0,0,0,0,0,159,159,159,159,41,41,159,159,159,159,159,159
0,0,0,159,159,0,0,0,0,0,0,0,0,0,0,0,0,0,159,159,159,159,159,41,41,159,159,41,41,159,159
0,0,0,0,0,0,0,0,0,0,41,0,0,41,0,0,0,159,159,41,159,159,159,159,159,159,159,41,41,159,159
0,0,0,0,0,0,0,0,0,0,0,41,41,0,0,0,0,159,41,41,41,41,159,159,159,159,159,159,159,159,159
0,0,0,0,0,0,0,0,0,0,0,41,41,0,0,0,0,159,41,41,41,159,159,159,159,159,159,159,159,159,0
0,159,159,0,0,0,0,0,0,0,0,0,0,41,0,0,0,159,41,159,159,41,159,159,159,159,159,159,159,159,0
0,159,159,0,0,0,0,0,0,0,0,0,0,0,0,0,0,159,159,159,159,159,159,159,159,0,0,0,0,0,0
159,159,159,159,0,0,0,0,0,0,0,0,0,0,0,0,0,0,159,159,159,159,159,159,0,0,0,0,0,0,0
159,159,159,159,159,159,0,159,159,159,159,159,0,0,0,0,0,0,0,0,0,0,0,0,0,0,0,0,0,0,0
159,159,159,159,159,159,159,159,159,159,159,159,159,0,0,0,0,0,0,0,0,0,0,0,0,159,159,159,159,159,0
159,41,41,159,159,159,159,159,159,159,159,159,159,0,0,0,0,0,0,0,0,0,0,0,159,159,159,159,159,159,159
159,41,41,159,159,159,159,159,41,159,41,159,159,0,0,0,0,0,0,0,0,0,0,0,159,159,159,159,159,159,159
159,159,159,159,159,159,159,41,41,41,159,159,159,0,0,0,0,0,0,41,0,0,0,0,159,159,159,41,41,159,159
159,159,159,159,159,159,159,41,41,41,41,159,159,0,0,0,0,0,0,0,41,41,41,0,159,159,159,41,41,159,159
159,159,159,159,0,0,159,159,159,159,41,159,159,0,0,0,0,0,0,0,41,41,0,0,159,159,159,159,159,159,159
0,0,0,0,0,0,0,0,0,159,159,159,0,0,0,0,0,0,0,41,0,0,0,0,0,159,159,159,159,159,159
0,0,159,159,159,0,0,0,0,0,0,0,0,0,0,0,0,0,0,0,0,0,0,0,0,159,159,159,159,159,0
159,159,159,159,159,159,0,0,0,0,0,0,0,0,0,0,0,0,0,0,0,0,0,0,0,0,0,0,0,0,0
159,159,159,41,159,159,0,0,0,0,0,0,0,0,0,0,0,0,0,0,0,0,0,0,0,0,0,0,0,0,0
159,41,41,159,159,159,0,0,0,0,0,0,0,0,0,0,0,0,0,0,0,0,0,0,0,0,0,0,0,0,0
41,41,41,41,159,159,0,0,0,0,0,0,0,0,0,0,0,0,0,0,0,0,0,0,0,0,0,159,159,0,0
159,41,41,41,159,159,0,0,0,0,0,0,0,0,0,0,0,0,0,0,0,0,0,0,0,0,159,159,159,159,0
159,41,41,41,159,159,0,0,0,0,0,0,0,0,0,0,0,0,0,0,0,0,0,0,0,159,159,159,159,159,159
0,159,41,41,159,0,0,0,0,0,0,0,0,0,0,0,0,0,0,0,0,0,0,0,0,159,159,159,159,159,159
0,0,0,0,0,0,0,0,0,0,0,0,0,0,0,0,0,0,0,0,0,0,0,0,0,0,159,159,159,159,0
0,0,0,0,0,0,0,0,0,0,0,0,0,0,0,0,0,0,0,0,0,0,0,0,0,0,0,159,159,0,0
0,0,0,0,0,0,0,0,0,0,0,0,0,0,0,0,0,0,0,159,159,159,159,159,159,0,41,159,41,159,159
0,0,0,0,0,0,0,0,0,41,0,0,0,0,0,0,0,0,159,159,159,159,159,159,159,41,41,41,41,159,159
0,0,41,41,41,0,41,41,0,41,41,0,0,0,0,0,0,0,159,159,41,159,41,41,159,159,41,41,159,41,159
0,0,41,41,41,41,41,0,0,41,41,0,0,0,0,0,41,41,159,159,41,41,41,41,159,41,41,41,41,41,159
0,41,0,41,41,41,41,0,41,0,0,41,0,0,0,0,41,41,159,159,159,41,41,159,159,159,159,41,41,41,159
0,0,0,0,0,0,0,0,0,0,0,0,0,0,0,0,0,41,41,159,159,41,159,159,159,159,159,41,159,159,159
0,0,0,0,0,0,0,0,0,0,0,0,0,0,0,0,0,0,0,159,159,159,159,159,159,159,159,159,159,159,159
:endlayer
layer: 15
0,0,0,0,0,0,0,0,0,0,0,0,0,0,0,0,0,0,0,0,0,0,0,0,0,0,0,0,0,0,0
0,0,0,0,0,0,0,0,0,0,0,0,0,0,0,0,0,0,0,0,0,0,0,0,0,0,0,0,0,0,0
0,0,0,0,0,0,0,0,0,0,0,0,0,0,0,0,0,0,0,0,0,0,0,0,0,159,159,0,174,0,0
0,0,0,0,0,0,0,0,0,0,0,0,0,0,0,0,0,0,0,0,0,0,0,0,159,159,159,159,0,0,0
0,0,0,0,0,0,0,0,0,0,0,0,0,0,0,0,0,0,0,0,0,0,0,159,159,159,159,159,159,0,0
0,0,0,0,0,0,0,0,0,0,0,0,0,0,0,0,0,0,0,0,0,0,0,159,159,159,159,159,159,0,0
0,0,0,0,0,0,0,0,0,0,0,0,0,0,0,0,0,0,0,0,0,0,159,159,159,159,159,159,159,0,0
0,0,0,0,0,0,0,0,0,159,159,159,159,159,159,0,0,0,159,159,159,159,159,159,159,159,159,159,159,159,0
0,0,0,0,0,0,0,0,159,159,159,159,159,159,159,159,0,159,159,159,159,159,159,159,159,159,159,159,159,159,159
0,0,0,0,0,0,0,0,159,159,41,159,159,41,159,159,0,159,159,159,159,159,159,159,159,159,159,159,159,159,159
0,0,0,0,0,0,0,0,159,159,159,41,41,159,159,159,0,159,159,159,41,41,159,159,159,0,159,159,159,159,0
0,0,0,0,0,0,0,0,0,159,159,41,41,159,159,159,0,159,159,159,41,41,159,159,159,0,0,159,159,0,0
0,0,0,0,0,0,0,0,0,159,159,159,159,41,159,159,0,159,159,159,159,159,159,159,159,0,0,0,0,0,0
0,0,0,0,0,0,0,0,0,159,159,159,159,159,159,159,0,0,159,159,159,159,159,159,0,0,0,0,0,0,0
0,0,0,0,0,0,0,0,0,0,0,0,159,159,159,0,0,0,159,159,159,159,159,0,0,0,0,0,0,0,0
0,159,159,0,0,0,159,159,159,159,159,0,0,0,0,0,0,0,0,0,0,0,0,0,0,0,0,0,0,0,0
159,159,159,159,0,159,159,159,159,159,159,159,159,0,0,0,0,0,0,0,0,0,0,0,0,0,0,0,0,0,0
159,159,159,159,159,159,159,159,159,159,159,159,159,0,0,0,0,0,0,0,0,0,0,0,0,0,0,159,159,0,0
159,159,159,159,159,159,159,159,41,41,159,159,159,0,0,0,0,0,0,0,0,0,0,0,0,0,159,159,159,159,0
159,159,159,159,0,159,159,159,41,41,159,159,159,0,0,0,0,0,0,41,0,0,0,0,0,159,159,159,159,159,159
0,159,159,0,0,159,159,159,159,159,159,159,159,0,0,0,0,0,0,41,41,41,41,0,0,159,159,159,159,159,159
0,0,0,0,0,0,159,159,159,159,159,159,0,0,0,0,0,0,0,0,41,41,0,0,0,0,159,159,159,159,0
0,0,0,0,0,0,159,159,159,159,159,175,0,0,0,0,0,0,0,41,0,0,0,0,0,0,0,159,159,0,0
159,159,159,159,0,0,0,0,0,0,0,0,0,0,0,0,0,0,0,0,0,0,0,0,0,0,0,0,0,0,0
159,159,159,159,159,159,0,0,0,0,0,0,0,0,0,0,0,0,0,0,0,0,0,0,0,0,0,0,0,0,0
159,159,159,159,159,159,0,0,0,0,0,0,0,0,0,0,0,0,0,0,0,0,0,0,0,0,0,0,0,0,0
159,41,41,159,159,159,0,0,0,0,0,0,0,0,0,0,0,0,0,0,0,0,0,0,0,0,0,0,0,0,0
159,41,41,159,159,159,0,0,0,0,0,0,0,0,0,0,0,0,0,0,0,0,0,0,0,0,0,0,0,0,0
159,41,41,41,159,159,0,0,0,0,0,0,0,0,0,0,0,0,0,0,0,0,0,0,0,0,0,0,0,0,0
159,41,41,41,159,0,0,0,0,0,0,0,0,0,0,0,0,0,0,0,0,0,0,0,0,0,0,0,0,0,0
159,159,41,41,159,0,0,0,0,0,0,0,0,0,0,0,0,0,0,0,0,0,0,0,0,0,0,0,0,0,0
159,159,159,159,159,0,0,0,0,0,0,0,0,0,0,0,0,0,0,0,0,0,0,0,0,159,159,159,159,159,0
159,159,159,159,159,0,0,0,0,0,0,0,0,0,0,0,0,0,0,0,0,0,0,0,159,159,159,159,159,159,159
159,159,159,159,159,159,159,159,159,159,0,0,0,0,0,0,0,0,0,159,159,159,159,159,159,159,41,159,41,159,159
159,159,159,159,159,159,159,159,159,41,159,0,0,0,0,0,0,0,159,159,159,159,159,159,159,41,41,41,41,159,159
159,159,41,41,41,159,41,41,41,41,41,0,0,0,0,0,41,41,159,159,159,159,159,159,159,159,41,41,159,159,159
159,159,41,41,41,41,41,159,159,41,41,0,0,0,0,0,41,41,159,159,159,41,41,159,159,41,41,41,41,159,159
159,41,159,41,41,41,41,159,41,159,0,41,0,0,0,0,41,41,159,159,159,41,41,159,159,159,159,41,41,159,159
159,159,159,159,159,159,159,159,159,159,0,0,0,0,0,0,0,41,41,159,159,159,159,159,159,159,159,159,159,159,159
159,159,159,159,159,159,159,159,159,159,0,0,0,0,0,0,0,0,0,159,159,159,159,159,0,159,159,159,159,159,0
:endlayer
layer: 16
0,0,0,0,0,0,0,0,0,0,0,0,0,0,0,0,0,0,0,0,0,0,0,0,0,0,0,0,0,0,0
0,0,0,0,0,0,0,0,0,0,0,0,0,0,0,0,0,0,0,0,0,0,0,0,0,0,0,0,0,0,0
0,0,0,0,0,0,0,0,0,0,0,0,0,0,0,0,0,0,0,0,0,0,0,0,0,0,0,0,0,0,0
0,0,0,0,0,0,0,0,0,0,0,0,0,0,0,0,0,0,0,0,0,0,0,0,0,0,0,0,0,0,0
0,0,0,0,0,0,0,0,0,0,0,0,0,0,0,0,0,0,0,0,0,0,0,0,0,0,0,0,0,0,0
0,0,0,0,0,0,0,0,0,0,0,0,0,0,0,0,0,0,0,0,0,0,0,0,0,0,0,0,0,0,0
0,0,0,0,0,0,0,0,0,0,0,0,0,0,0,0,0,0,0,0,0,0,0,0,0,0,0,0,0,0,0
0,0,0,0,0,0,0,0,0,159,159,159,159,159,0,0,0,0,0,0,0,0,0,159,159,0,0,0,0,0,0
0,0,0,0,0,0,0,0,159,159,159,159,159,159,159,159,0,0,0,0,159,159,0,159,159,0,0,0,0,0,0
0,0,0,0,0,0,0,0,159,159,159,159,159,159,159,159,0,0,0,159,159,159,159,0,0,0,0,0,0,0,0
0,0,0,0,0,0,0,0,159,159,159,41,41,159,159,159,0,0,159,159,159,159,159,159,0,0,0,0,0,0,0
0,0,0,0,0,0,0,0,159,159,159,41,41,159,159,159,0,0,159,159,159,159,159,159,0,0,0,0,0,0,0
0,0,0,0,0,0,0,0,159,159,159,159,159,159,159,159,0,0,0,159,159,159,159,0,0,0,0,0,0,0,0
0,0,0,0,0,0,0,0,0,159,159,159,159,159,159,0,0,0,0,0,159,159,0,0,0,0,0,0,0,0,0
0,0,0,0,0,0,0,0,0,159,159,159,159,159,0,0,0,0,0,0,0,0,0,0,0,0,0,0,0,0,0
0,0,0,0,0,0,0,0,0,0,0,0,0,0,0,0,0,0,0,0,0,0,0,0,0,0,0,0,0,0,0
0,0,0,0,0,0,0,0,159,159,0,0,0,0,0,0,0,0,0,0,0,0,0,0,0,0,0,0,0,0,0
0,159,159,0,0,0,0,159,159,159,159,0,0,0,0,0,0,0,0,0,0,0,0,0,0,0,0,0,0,0,0
0,159,159,0,0,0,159,159,159,159,159,159,0,0,0,0,0,0,159,159,159,0,0,0,0,0,0,0,0,0,0
0,0,0,0,0,0,159,159,159,159,159,159,0,0,0,0,0,159,159,41,159,159,159,159,0,0,0,0,0,0,0
0,0,0,0,0,0,0,159,159,159,159,0,0,0,0,0,0,159,159,41,41,41,41,159,159,0,0,0,0,0,0
0,0,0,0,0,0,0,0,159,159,0,0,0,0,0,0,0,159,159,159,41,41,159,159,159,0,0,0,0,0,0
0,0,0,0,0,0,0,0,0,0,0,0,0,0,0,0,0,159,159,41,159,159,159,159,159,0,0,0,0,0,0
0,0,0,0,0,0,0,0,0,0,0,0,0,0,0,0,0,159,159,159,159,159,159,159,0,0,0,0,0,0,0
0,159,159,0,0,0,0,0,0,0,0,0,0,0,0,0,0,159,159,159,159,159,159,159,0,0,0,0,0,0,0
159,159,159,159,0,0,0,0,0,0,0,0,0,0,0,0,0,0,159,159,159,0,0,0,0,0,0,0,0,0,0
159,159,159,159,159,0,0,0,0,0,0,0,0,0,0,0,0,0,0,0,0,0,0,0,0,0,0,0,0,0,0
159,159,159,159,159,159,0,0,0,0,0,0,0,0,0,0,0,0,0,0,0,0,0,0,0,0,0,0,0,0,0
159,159,159,159,159,159,0,0,0,0,0,0,0,0,0,0,0,0,0,0,0,0,0,0,0,0,0,0,0,0,0
159,41,41,159,159,159,0,0,0,0,0,0,0,0,0,0,0,0,0,0,0,0,0,0,0,0,0,0,0,0,0
159,41,41,159,159,159,0,0,0,0,0,0,0,0,0,0,0,0,0,0,0,0,0,0,0,0,0,0,0,0,0
159,159,159,159,159,159,0,0,0,0,0,0,0,0,0,0,0,0,0,0,0,0,0,0,159,159,159,159,159,0,0
159,159,159,159,159,0,0,0,0,0,159,159,159,0,0,0,0,0,0,0,0,0,0,159,159,159,159,159,159,159,159
159,159,159,159,159,159,159,159,159,159,159,159,159,159,159,159,159,159,159,0,0,176,0,159,159,159,159,159,159,159,159
159,159,159,159,159,159,159,159,159,41,159,159,159,159,159,159,159,159,159,159,0,159,159,159,159,159,41,41,159,159,159
159,159,41,41,159,159,159,159,41,159,41,41,159,159,159,159,41,41,159,159,159,159,159,159,159,159,41,41,159,159,159
159,159,41,41,159,159,41,41,159,159,41,41,159,159,159,159,41,41,159,159,159,159,159,159,159,159,159,159,159,159,159
159,159,159,159,159,159,41,41,41,159,159,41,159,159,159,159,41,41,159,159,159,159,159,159,159,159,159,159,159,159,159
159,159,159,159,159,159,159,159,159,159,159,159,159,159,159,159,159,41,41,159,159,159,159,159,159,159,159,159,159,159,0
159,159,159,159,159,159,159,159,159,159,159,159,159,159,159,159,159,159,159,159,159,159,159,0,0,0,0,159,159,0,0
:endlayer
layer: 17
0,0,0,0,0,0,0,0,0,0,0,0,0,0,0,0,0,0,0,0,0,0,0,0,0,0,0,0,0,0,0
0,0,0,0,0,0,0,0,0,0,0,0,0,0,0,0,0,0,0,0,0,0,0,0,0,0,0,0,0,0,0
0,0,0,0,0,0,0,0,0,0,0,0,0,0,0,0,0,0,0,0,0,0,0,0,0,0,0,0,0,0,0
0,0,0,0,0,0,0,0,0,0,0,0,0,0,0,0,0,0,0,0,0,0,0,0,0,0,0,0,0,0,0
0,0,0,0,0,0,0,0,0,0,0,0,0,0,0,0,0,0,0,0,0,0,0,0,0,0,0,0,0,0,0
0,0,0,0,0,0,0,0,0,0,0,0,0,0,0,0,0,0,0,0,0,0,0,0,0,0,0,0,0,0,0
0,0,0,0,0,0,0,0,0,0,0,0,0,0,0,0,0,0,0,0,0,0,0,0,0,0,0,0,0,0,0
0,0,0,0,0,0,0,0,0,0,0,0,0,0,0,0,0,0,0,0,0,0,0,0,0,0,0,0,0,0,0
0,0,0,0,0,0,0,0,0,0,0,159,159,0,0,0,0,0,0,0,0,0,0,0,0,0,0,0,0,0,0
0,0,0,0,0,0,0,0,0,0,159,159,159,159,0,0,0,0,0,0,0,0,0,0,0,0,0,0,0,0,0
0,0,0,0,0,0,0,0,0,159,159,159,159,159,159,0,0,0,0,0,159,159,0,0,0,0,0,0,0,0,0
0,0,0,0,0,0,0,0,0,159,159,159,159,159,159,0,0,0,0,0,159,159,0,0,0,0,0,0,0,0,0
0,0,0,0,0,0,0,0,0,0,159,159,159,159,0,0,0,0,0,0,0,0,0,0,0,0,0,0,0,0,0
0,0,0,0,0,0,0,0,0,0,0,159,159,0,0,0,0,0,0,0,0,0,0,0,0,0,0,0,0,0,0
0,0,0,0,0,0,0,0,0,0,0,0,0,0,0,0,0,0,0,0,0,0,0,0,0,0,0,0,0,0,0
0,0,0,0,0,0,0,0,0,0,0,0,0,0,0,0,0,0,0,0,0,0,0,0,0,0,0,0,0,0,0
0,0,0,0,0,0,0,0,0,0,0,0,0,0,0,0,0,0,0,0,0,0,0,0,0,0,0,0,0,0,0
0,0,0,0,0,0,0,0,0,0,0,0,0,0,0,0,0,0,0,0,0,0,0,0,0,0,0,0,0,0,0
0,0,0,0,0,0,0,0,159,159,0,0,0,0,0,0,0,0,159,159,159,159,159,0,0,0,0,0,0,0,0
0,0,0,0,0,0,0,0,159,159,0,0,0,0,0,0,0,159,159,159,159,159,159,159,159,0,0,0,0,0,0
0,0,0,0,0,0,0,0,0,0,0,0,0,0,0,0,0,159,159,159,159,159,159,159,159,0,0,0,0,0,0
0,0,0,0,0,0,0,0,0,0,0,0,0,0,0,0,0,159,159,159,41,41,159,159,159,0,0,0,0,0,0
0,0,0,0,0,0,0,0,0,0,0,0,0,0,0,0,0,159,159,159,41,41,159,159,159,0,0,0,0,0,0
0,0,0,0,0,0,0,0,0,0,0,0,0,0,0,0,0,159,159,159,159,159,159,159,159,0,0,0,0,0,0
0,0,0,0,0,0,0,0,0,0,0,0,0,0,0,0,0,0,159,159,159,159,159,0,0,0,0,0,0,0,0
0,0,0,0,0,0,0,0,0,0,0,0,0,0,0,0,0,0,159,159,159,159,159,0,0,0,0,0,0,0,0
0,0,0,0,0,0,0,0,0,0,0,0,0,0,0,0,0,0,0,0,0,0,0,0,0,0,0,0,0,0,0
0,159,159,0,0,0,0,0,0,0,0,0,0,0,0,0,0,0,0,0,0,0,0,0,0,0,0,0,0,0,0
159,159,159,159,0,0,0,0,0,0,0,0,0,0,0,0,0,0,0,0,0,0,0,0,0,0,0,0,0,0,0
159,159,159,159,159,0,0,0,0,0,0,0,0,0,0,0,0,0,0,0,0,0,0,0,0,0,0,0,0,0,0
159,159,159,159,159,0,0,0,0,0,0,0,0,0,0,0,0,0,0,0,0,0,0,0,0,0,0,0,0,0,0
159,159,159,159,0,0,0,0,0,0,0,0,0,0,0,0,0,0,0,0,0,0,0,0,0,0,0,0,0,0,0
0,159,159,0,0,0,0,0,0,159,159,159,159,159,0,0,0,0,0,0,0,0,0,0,0,0,159,159,0,0,0
0,0,159,159,0,0,0,0,159,159,159,159,159,159,159,159,159,159,159,0,0,0,0,0,0,159,159,159,159,0,0
0,159,159,159,159,0,159,159,159,159,159,159,159,159,159,159,159,159,159,159,159,0,0,0,159,159,159,159,159,159,0
159,159,159,159,159,159,159,159,159,159,159,41,41,159,159,159,159,159,159,159,159,0,0,0,159,159,159,159,159,159,0
159,159,159,159,159,159,159,159,159,159,159,41,41,159,159,159,41,41,159,159,159,0,0,0,0,159,159,159,159,0,0
0,159,159,159,159,159,159,159,159,159,159,159,159,159,159,159,41,41,159,159,159,0,0,0,0,0,159,159,0,0,0
0,0,159,159,0,159,159,159,159,159,159,159,159,159,159,159,159,159,159,159,159,0,0,0,0,0,0,0,0,177,0
0,178,0,0,0,0,159,159,0,159,159,159,159,159,159,159,159,159,159,159,0,0,0,0,0,0,0,0,0,0,0
:endlayer
layer: 18
0,0,0,0,0,0,0,0,0,0,0,0,0,0,0,0,0,0,0,0,0,0,0,0,0,0,0,0,0,0,0
0,0,0,0,0,0,0,0,0,0,0,0,0,0,0,0,0,0,0,0,0,0,0,0,0,0,0,0,0,0,0
0,0,0,0,0,0,0,0,0,0,0,0,0,0,0,0,0,0,0,0,0,0,0,0,0,0,0,0,0,0,0
0,0,0,0,0,0,0,0,0,0,0,0,0,0,0,0,0,0,0,0,0,0,0,0,0,0,0,0,0,0,0
0,0,0,0,0,0,0,0,0,0,0,0,0,0,0,0,0,0,0,0,0,0,0,0,0,0,0,0,0,0,0
0,0,0,0,0,0,0,0,0,0,0,0,0,0,0,0,0,0,0,0,0,0,0,0,0,0,0,0,0,0,0
0,0,0,0,0,0,0,0,0,0,0,0,0,0,0,0,0,0,0,0,0,0,0,0,0,0,0,0,0,0,0
0,0,0,0,0,0,0,0,0,0,0,0,0,0,0,0,0,0,0,0,0,0,0,0,0,0,0,0,0,0,0
0,0,0,0,0,0,0,0,0,0,0,0,0,0,0,0,0,0,0,0,0,0,0,0,0,0,0,0,0,0,0
0,0,0,0,0,0,0,0,0,0,0,0,0,0,0,0,0,0,0,0,0,0,0,0,0,0,0,0,0,0,0
0,0,0,0,0,0,0,0,0,0,0,159,159,0,0,0,0,0,0,0,0,0,0,0,0,0,0,0,0,0,0
0,0,0,0,0,0,0,0,0,0,0,159,159,0,0,0,0,0,0,0,0,0,0,0,0,0,0,0,0,0,0
0,0,0,0,0,0,0,0,0,0,0,0,0,0,0,0,0,0,0,0,0,0,0,0,0,0,0,0,0,0,0
0,0,0,0,0,0,0,0,0,0,0,0,0,0,0,0,0,0,0,0,0,0,0,0,0,0,0,0,0,0,0
0,0,0,0,0,0,0,0,0,0,0,0,0,0,0,0,0,0,0,0,0,0,0,0,0,0,0,0,0,0,0
0,0,0,0,0,0,0,0,0,0,0,0,0,0,0,0,0,0,0,0,0,0,0,0,0,0,0,0,0,0,0
0,0,0,0,0,0,0,0,0,0,0,0,0,0,0,0,0,0,0,0,0,0,0,0,0,0,0,0,0,0,0
0,0,0,0,0,0,0,0,0,0,0,0,0,0,0,0,0,0,0,0,0,0,0,0,0,0,0,0,0,0,0
0,0,0,0,0,0,0,0,0,0,0,0,0,0,0,0,0,0,0,0,0,0,0,0,0,0,0,0,0,0,0
0,0,0,0,0,0,0,0,0,0,0,0,0,0,0,0,0,0,0,0,159,159,0,0,0,0,0,0,0,0,0
0,0,0,0,0,0,0,0,0,0,0,0,0,0,0,0,0,0,0,159,159,159,159,0,0,0,0,0,0,0,0
0,0,0,0,0,0,0,0,0,0,0,0,0,0,0,0,0,0,159,159,159,159,159,159,0,0,0,0,0,0,0
0,0,0,0,0,0,0,0,0,0,0,0,0,0,0,0,0,0,159,159,159,159,159,159,0,0,0,0,0,0,0
0,0,0,0,0,0,0,0,0,0,0,0,0,0,0,0,0,0,0,159,159,159,159,0,0,0,0,0,0,0,0
0,0,0,0,0,0,0,0,0,0,0,0,0,0,0,0,0,0,0,0,159,159,0,0,0,0,0,0,0,0,0
0,0,0,0,0,0,0,0,0,0,0,0,0,0,0,0,0,0,0,0,0,0,0,0,0,0,0,0,0,0,0
0,0,0,0,0,0,0,0,0,0,0,0,0,0,0,0,0,0,0,0,0,0,0,0,0,0,0,0,0,0,0
0,0,0,0,0,0,0,0,0,0,0,0,0,0,0,0,0,0,0,0,0,0,0,0,0,0,0,0,0,0,0
0,0,0,0,0,0,0,0,0,0,0,0,0,0,0,0,0,0,0,0,0,0,0,0,0,0,0,0,0,0,0
0,0,0,0,0,0,0,0,0,0,0,0,0,0,0,0,0,0,0,0,0,0,0,0,0,0,0,0,0,0,0
0,0,0,0,0,0,0,0,0,0,0,0,0,0,0,0,0,0,0,0,0,0,0,0,0,0,0,0,0,0,0
0,0,0,0,0,0,0,0,0,0,0,0,0,0,0,0,0,0,0,0,0,0,0,0,0,0,0,0,0,0,0
0,0,0,0,0,0,0,0,0,0,0,0,0,0,0,0,0,0,0,0,0,0,0,0,0,0,0,0,0,0,0
0,0,0,0,0,0,0,0,0,0,0,159,159,0,0,0,0,0,0,0,0,0,0,0,0,0,0,0,0,0,0
0,0,0,0,0,0,0,0,0,0,159,159,159,159,0,0,159,159,0,0,0,0,0,0,0,0,159,159,0,0,0
0,0,159,159,0,0,0,0,0,159,159,159,159,159,159,159,159,159,159,0,0,0,0,0,0,0,159,159,0,0,0
0,0,159,159,0,0,0,0,0,159,159,159,159,159,159,159,159,159,159,159,0,0,0,0,0,0,0,0,0,0,0
0,0,0,0,0,0,0,0,0,0,159,159,159,159,159,159,159,159,159,159,0,0,0,0,0,0,0,0,0,0,0
0,0,0,0,0,0,0,0,0,0,0,159,159,0,0,159,159,159,159,0,0,0,0,0,0,0,0,0,0,0,0
0,0,0,0,0,0,0,0,0,0,0,0,0,0,0,0,159,159,0,0,0,0,0,0,0,0,0,0,0,0,0
:endlayer
layer: 19
0,0,0,0,0,0,0,0,0,0,0,0,0,0,0,0,0,0,0,0,0,0,0,0,0,0,0,0,0,0,0
0,0,0,0,0,0,0,0,0,0,0,0,0,0,0,0,0,0,0,0,0,0,0,0,0,0,0,0,0,0,0
0,0,0,0,0,0,0,0,0,0,0,0,0,0,0,0,0,0,0,0,0,0,0,0,0,0,0,0,0,0,0
0,0,0,0,0,0,0,0,0,0,0,0,0,0,0,0,0,0,0,0,0,0,0,0,0,0,0,0,0,0,0
0,0,0,0,0,0,0,0,0,0,0,0,0,0,0,0,0,0,0,0,0,0,0,0,0,0,0,0,0,0,0
0,0,0,0,0,0,0,0,0,0,0,0,0,0,0,0,0,0,0,0,0,0,0,0,0,0,0,0,0,0,0
0,0,0,0,0,0,0,0,0,0,0,0,0,0,0,0,0,0,0,0,0,0,0,0,0,0,0,0,0,0,0
0,0,0,0,0,0,0,0,0,0,0,0,0,0,0,0,0,0,0,0,0,0,0,0,0,0,0,0,0,0,0
0,0,0,0,0,0,0,0,0,0,0,0,0,0,0,0,0,0,0,0,0,0,0,0,0,0,0,0,0,0,0
0,0,0,0,0,0,0,0,0,0,0,0,0,0,0,0,0,0,0,0,0,0,0,0,0,0,0,0,0,0,0
0,0,0,0,0,0,0,0,0,0,0,0,0,0,0,0,0,0,0,0,0,0,0,0,0,0,0,0,0,0,0
0,0,0,0,0,0,0,0,0,0,0,0,0,0,0,0,0,0,0,0,0,0,0,0,0,0,0,0,0,0,0
0,0,0,0,0,0,0,0,0,0,0,0,0,0,0,0,0,0,0,0,0,0,0,0,0,0,0,0,0,0,0
0,0,0,0,0,0,0,0,0,0,0,0,0,0,0,0,0,0,0,0,0,0,0,0,0,0,0,0,0,0,0
0,0,0,0,0,0,0,0,0,0,0,0,0,0,0,0,0,0,0,0,0,0,0,0,0,0,0,0,0,0,0
0,0,0,0,0,0,0,0,0,0,0,0,0,0,0,0,0,0,0,0,0,0,0,0,0,0,0,0,0,0,0
0,0,0,0,0,0,0,0,0,0,0,0,0,0,0,0,0,0,0,0,0,0,0,0,0,0,0,0,0,0,0
0,0,0,0,0,0,0,0,0,0,0,0,0,0,0,0,0,0,0,0,0,0,0,0,0,0,0,0,0,0,0
0,0,0,0,0,0,0,0,0,0,0,0,0,0,0,0,0,0,0,0,0,0,0,0,0,0,0,0,0,0,0
0,0,0,0,0,0,0,0,0,0,0,0,0,0,0,0,0,0,0,0,0,0,0,0,0,0,0,0,0,0,0
0,0,0,0,0,0,0,0,0,0,0,0,0,0,0,0,0,0,0,0,0,0,0,0,0,0,0,0,0,0,0
0,0,0,0,0,0,0,0,0,0,0,0,0,0,0,0,0,0,0,0,159,159,0,0,0,0,0,0,0,0,0
0,0,0,0,0,0,0,0,0,0,0,0,0,0,0,0,0,0,0,0,159,159,0,0,0,0,0,0,0,0,0
0,0,0,0,0,0,0,0,0,0,0,0,0,0,0,0,0,0,0,0,0,0,0,0,0,0,0,0,0,0,0
0,0,0,0,0,0,0,0,0,0,0,0,0,0,0,0,0,0,0,0,0,0,0,0,0,0,0,0,0,0,0
0,0,0,0,0,0,0,0,0,0,0,0,0,0,0,0,0,0,0,0,0,0,0,0,0,0,0,0,0,0,0
0,0,0,0,0,0,0,0,0,0,0,0,0,0,0,0,0,0,0,0,0,0,0,0,0,0,0,0,0,0,0
0,0,0,0,0,0,0,0,0,0,0,0,0,0,0,0,0,0,0,0,0,0,0,0,0,0,0,0,0,0,0
0,0,0,0,0,0,0,0,0,0,0,0,0,0,0,0,0,0,0,0,0,0,0,0,0,0,0,0,0,0,0
0,0,0,0,0,0,0,0,0,0,0,0,0,0,0,0,0,0,0,0,0,0,0,0,0,0,0,0,0,0,0
0,0,0,0,0,0,0,0,0,0,0,0,0,0,0,0,0,0,0,0,0,0,0,0,0,0,0,0,0,0,0
0,0,0,0,0,0,0,0,0,0,0,0,0,0,0,0,0,0,0,0,0,0,0,0,0,0,0,0,0,0,0
0,0,0,0,0,0,0,0,0,0,0,0,0,0,0,0,0,0,0,0,0,0,0,0,0,0,0,0,0,0,0
0,0,0,0,0,0,0,0,0,0,0,0,0,0,0,0,0,0,0,0,0,0,0,0,0,0,0,0,0,0,0
0,0,0,0,0,0,0,0,0,0,0,0,0,0,0,0,0,0,0,0,0,0,0,0,0,0,0,0,0,0,0
0,0,0,0,0,0,0,0,0,0,0,159,159,0,0,0,0,0,0,0,0,0,0,0,0,0,0,0,0,0,0
0,0,0,0,0,0,0,0,0,0,0,159,159,0,0,0,0,0,0,0,0,0,0,0,0,0,0,0,0,0,0
0,0,0,0,0,0,0,0,0,0,0,0,0,0,0,0,0,0,0,0,0,0,0,0,0,0,0,0,0,0,0
0,0,0,0,0,0,0,0,0,0,0,0,0,0,0,0,0,0,0,0,0,0,0,0,0,0,0,0,0,0,0
0,0,0,0,0,0,0,0,0,0,0,0,0,0,0,0,0,0,0,0,0,0,0,0,0,0,0,0,0,0,0
:endlayer

#### RULES ####
rule:
plugin=vanillaBlocks
number=1
data:
JSON:{blockState:{blockName:"minecraft:dirt",properties:{variant:"dirt",snowy:"false"}}}
:enddata
:endrule

rule:
plugin=vanillaBlocks
number=2
data:
JSON:{blockState:{blockName:"minecraft:grass",properties:{snowy:"false"}}}
:enddata
:endrule

rule:
plugin=vanillaBlocks
number=3
data:
JSON:{blockState:{blockName:"minecraft:mossy_cobblestone"}}
:enddata
:endrule

rule:
plugin=vanillaBlocks
number=4
data:
JSON:{blockState:{blockName:"minecraft:stained_hardened_clay",properties:{color:"brown"}}}
:enddata
:endrule

rule:
plugin=vanillaBlocks
number=5
data:
JSON:{blockState:{blockName:"minecraft:wooden_slab",properties:{half:"bottom",variant:"dark_oak"}}}
:enddata
:endrule

rule:
plugin=vanillaBlocks
number=6
data:
JSON:{blockState:{blockName:"minecraft:cobblestone"}}
:enddata
:endrule

rule:
plugin=vanillaBlocks
number=7
data:
JSON:{blockState:{blockName:"minecraft:planks",properties:{variant:"dark_oak"}}}
:enddata
:endrule

rule:
plugin=inventory
number=8
data:
JSON:{blockState:{blockName:"minecraft:chest",properties:{facing:"west"}},lootLevel:0,teData:{ForgeData:{},Items:[{Slot:1b,id:"minecraft:bone",Count:1b,Damage:0s},{Slot:2b,id:"minecraft:bone",Count:2b,Damage:0s},{Slot:3b,id:"minecraft:bone",Count:1b,Damage:0s},{Slot:5b,id:"minecraft:poisonous_potato",Count:1b,Damage:0s},{Slot:6b,id:"minecraft:poisonous_potato",Count:2b,Damage:0s},{Slot:7b,id:"minecraft:poisonous_potato",Count:1b,Damage:0s},{Slot:8b,id:"minecraft:poisonous_potato",Count:2b,Damage:0s},{Slot:10b,id:"minecraft:bone",Count:1b,Damage:0s},{Slot:11b,id:"minecraft:bone",Count:2b,Damage:0s},{Slot:12b,id:"minecraft:bone",Count:1b,Damage:0s},{Slot:13b,id:"minecraft:rotten_flesh",Count:2b,Damage:0s},{Slot:14b,id:"minecraft:rotten_flesh",Count:2b,Damage:0s},{Slot:16b,id:"minecraft:rotten_flesh",Count:1b,Damage:0s},{Slot:20b,id:"minecraft:bone",Count:1b,Damage:0s},{Slot:21b,id:"minecraft:rotten_flesh",Count:1b,Damage:0s},{Slot:22b,id:"minecraft:brown_mushroom",Count:4b,Damage:0s},{Slot:23b,id:"minecraft:red_mushroom",Count:3b,Damage:0s},{Slot:24b,id:"minecraft:rotten_flesh",Count:3b,Damage:0s},{Slot:25b,id:"minecraft:rotten_flesh",Count:1b,Damage:0s},{Slot:26b,id:"minecraft:poisonous_potato",Count:2b,Damage:0s}],id:"minecraft:chest",Lock:""},inventoryData:{length:20,inventoryContents:[{id:"minecraft:bone",Count:1b,slot:0,Damage:0s},{id:"minecraft:bone",Count:2b,slot:1,Damage:0s},{id:"minecraft:bone",Count:1b,slot:2,Damage:0s},{id:"minecraft:poisonous_potato",Count:1b,slot:3,Damage:0s},{id:"minecraft:poisonous_potato",Count:2b,slot:4,Damage:0s},{id:"minecraft:poisonous_potato",Count:1b,slot:5,Damage:0s},{id:"minecraft:poisonous_potato",Count:2b,slot:6,Damage:0s},{id:"minecraft:bone",Count:1b,slot:7,Damage:0s},{id:"minecraft:bone",Count:2b,slot:8,Damage:0s},{id:"minecraft:bone",Count:1b,slot:9,Damage:0s},{id:"minecraft:rotten_flesh",Count:2b,slot:10,Damage:0s},{id:"minecraft:rotten_flesh",Count:2b,slot:11,Damage:0s},{id:"minecraft:rotten_flesh",Count:1b,slot:12,Damage:0s},{id:"minecraft:bone",Count:1b,slot:13,Damage:0s},{id:"minecraft:rotten_flesh",Count:1b,slot:14,Damage:0s},{id:"minecraft:brown_mushroom",Count:4b,slot:15,Damage:0s},{id:"minecraft:red_mushroom",Count:3b,slot:16,Damage:0s},{id:"minecraft:rotten_flesh",Count:3b,slot:17,Damage:0s},{id:"minecraft:rotten_flesh",Count:1b,slot:18,Damage:0s},{id:"minecraft:poisonous_potato",Count:2b,slot:19,Damage:0s}]},legacyFeatures:1b}
:enddata
:endrule

rule:
plugin=vanillaBlocks
number=9
data:
JSON:{blockState:{blockName:"minecraft:crafting_table"}}
:enddata
:endrule

rule:
plugin=inventory
number=10
data:
JSON:{blockState:{blockName:"minecraft:furnace",properties:{facing:"west"}},lootLevel:0,teData:{CookTime:0,BurnTime:0,Items:[],id:"minecraft:furnace",CookTimeTotal:0,Lock:""},inventoryData:{length:0,inventoryContents:[]},legacyFeatures:0b}
:enddata
:endrule

rule:
plugin=vanillaBlocks
number=11
data:
JSON:{blockState:{blockName:"minecraft:fence",properties:{east:"false",south:"false",north:"false",west:"false"}}}
:enddata
:endrule

rule:
plugin=blockTile
number=12
data:
JSON:{blockState:{blockName:"ancientwarfarestructure:advanced_spawner",properties:{transparent:"true"}},teData:{id:"ancientwarfarestructure:advanced_spawner_tile",spawnerSettings:{minDelay:0,spawnDelay:0,lightSensitive:0b,spawnGroups:[{settingsList:[{remainingSpawnCount:1,hostile:1b,forced:1b,customTag:{factionName:"orc"},maxToSpawn:1,entityId:"ancientwarfarenpc:faction.archer",minToSpawn:1}],groupWeight:1}],playerRange:8,respondToRedstone:0b,inventory:{Size:9,Items:[]},spawnRange:0,transparent:1b,maxDelay:0,xpToDrop:0,mobRange:0,debugMode:0b,maxNearbyMonsters:0}}}
:enddata
:endrule

rule:
plugin=inventory
number=13
data:
JSON:{blockState:{blockName:"minecraft:chest",properties:{facing:"west"}},lootLevel:0,teData:{ForgeData:{},Items:[{Slot:0b,id:"minecraft:bone",Count:2b,Damage:0s},{Slot:1b,id:"minecraft:bone",Count:2b,Damage:0s},{Slot:2b,id:"minecraft:golden_apple",Count:1b,Damage:1s},{Slot:5b,id:"minecraft:string",Count:1b,Damage:0s},{Slot:6b,id:"minecraft:string",Count:1b,Damage:0s},{Slot:8b,id:"minecraft:bone",Count:1b,Damage:0s},{Slot:9b,id:"minecraft:poisonous_potato",Count:2b,Damage:0s},{Slot:10b,id:"minecraft:poisonous_potato",Count:3b,Damage:0s},{Slot:11b,id:"minecraft:bucket",Count:1b,Damage:0s},{Slot:12b,id:"minecraft:bone",Count:2b,Damage:0s},{Slot:13b,id:"minecraft:bone",Count:1b,Damage:0s},{Slot:15b,id:"minecraft:rotten_flesh",Count:1b,Damage:0s},{Slot:16b,id:"minecraft:rotten_flesh",Count:1b,Damage:0s},{Slot:18b,id:"minecraft:string",Count:2b,Damage:0s},{Slot:19b,id:"minecraft:poisonous_potato",Count:2b,Damage:0s},{Slot:20b,id:"minecraft:poisonous_potato",Count:1b,Damage:0s},{Slot:21b,id:"minecraft:bone",Count:4b,Damage:0s},{Slot:22b,id:"minecraft:bone",Count:1b,Damage:0s},{Slot:23b,id:"minecraft:rotten_flesh",Count:1b,Damage:0s},{Slot:24b,id:"minecraft:rotten_flesh",Count:4b,Damage:0s},{Slot:25b,id:"minecraft:rotten_flesh",Count:3b,Damage:0s},{Slot:26b,id:"minecraft:string",Count:2b,Damage:0s}],id:"minecraft:chest",Lock:""},inventoryData:{length:22,inventoryContents:[{id:"minecraft:bone",Count:2b,slot:0,Damage:0s},{id:"minecraft:bone",Count:2b,slot:1,Damage:0s},{id:"minecraft:golden_apple",Count:1b,slot:2,Damage:1s},{id:"minecraft:string",Count:1b,slot:3,Damage:0s},{id:"minecraft:string",Count:1b,slot:4,Damage:0s},{id:"minecraft:bone",Count:1b,slot:5,Damage:0s},{id:"minecraft:poisonous_potato",Count:2b,slot:6,Damage:0s},{id:"minecraft:poisonous_potato",Count:3b,slot:7,Damage:0s},{id:"minecraft:bucket",Count:1b,slot:8,Damage:0s},{id:"minecraft:bone",Count:2b,slot:9,Damage:0s},{id:"minecraft:bone",Count:1b,slot:10,Damage:0s},{id:"minecraft:rotten_flesh",Count:1b,slot:11,Damage:0s},{id:"minecraft:rotten_flesh",Count:1b,slot:12,Damage:0s},{id:"minecraft:string",Count:2b,slot:13,Damage:0s},{id:"minecraft:poisonous_potato",Count:2b,slot:14,Damage:0s},{id:"minecraft:poisonous_potato",Count:1b,slot:15,Damage:0s},{id:"minecraft:bone",Count:4b,slot:16,Damage:0s},{id:"minecraft:bone",Count:1b,slot:17,Damage:0s},{id:"minecraft:rotten_flesh",Count:1b,slot:18,Damage:0s},{id:"minecraft:rotten_flesh",Count:4b,slot:19,Damage:0s},{id:"minecraft:rotten_flesh",Count:3b,slot:20,Damage:0s},{id:"minecraft:string",Count:2b,slot:21,Damage:0s}]},legacyFeatures:1b}
:enddata
:endrule

rule:
plugin=inventory
number=14
data:
JSON:{blockState:{blockName:"minecraft:furnace",properties:{facing:"west"}},lootLevel:0,teData:{CookTime:0,BurnTime:0,Items:[],id:"minecraft:furnace",CookTimeTotal:0,Lock:""},inventoryData:{length:0,inventoryContents:[]},legacyFeatures:0b}
:enddata
:endrule

rule:
plugin=blockTile
number=15
data:
JSON:{blockState:{blockName:"ancientwarfarestructure:advanced_spawner",properties:{transparent:"true"}},teData:{id:"ancientwarfarestructure:advanced_spawner_tile",spawnerSettings:{minDelay:0,spawnDelay:0,lightSensitive:0b,spawnGroups:[{settingsList:[{remainingSpawnCount:1,hostile:1b,forced:1b,customTag:{factionName:"orc"},maxToSpawn:1,entityId:"ancientwarfarenpc:faction.soldier",minToSpawn:1}],groupWeight:1}],playerRange:6,respondToRedstone:0b,inventory:{Size:9,Items:[]},spawnRange:0,transparent:1b,maxDelay:0,xpToDrop:0,mobRange:0,debugMode:0b,maxNearbyMonsters:0}}}
:enddata
:endrule

rule:
plugin=blockTile
number=16
data:
JSON:{blockState:{blockName:"ancientwarfarestructure:advanced_spawner",properties:{transparent:"true"}},teData:{id:"ancientwarfarestructure:advanced_spawner_tile",spawnerSettings:{minDelay:0,spawnDelay:0,lightSensitive:0b,spawnGroups:[{settingsList:[{remainingSpawnCount:1,hostile:1b,forced:1b,customTag:{factionName:"orc"},maxToSpawn:1,entityId:"ancientwarfarenpc:faction.civilian.female",minToSpawn:1}],groupWeight:1}],playerRange:6,respondToRedstone:0b,inventory:{Size:9,Items:[]},spawnRange:0,transparent:1b,maxDelay:0,xpToDrop:0,mobRange:0,debugMode:0b,maxNearbyMonsters:0}}}
:enddata
:endrule

rule:
plugin=blockTile
number=17
data:
JSON:{blockState:{blockName:"ancientwarfarestructure:advanced_spawner",properties:{transparent:"true"}},teData:{id:"ancientwarfarestructure:advanced_spawner_tile",spawnerSettings:{minDelay:0,spawnDelay:0,lightSensitive:0b,spawnGroups:[{settingsList:[{remainingSpawnCount:1,hostile:1b,forced:1b,customTag:{factionName:"orc"},maxToSpawn:1,entityId:"ancientwarfarenpc:faction.archer",minToSpawn:1}],groupWeight:1}],playerRange:8,respondToRedstone:0b,inventory:{Size:9,Items:[]},spawnRange:0,transparent:1b,maxDelay:0,xpToDrop:0,mobRange:0,debugMode:0b,maxNearbyMonsters:0}}}
:enddata
:endrule

rule:
plugin=blockTile
number=18
data:
JSON:{blockState:{blockName:"ancientwarfarestructure:advanced_spawner",properties:{transparent:"true"}},teData:{id:"ancientwarfarestructure:advanced_spawner_tile",spawnerSettings:{minDelay:0,spawnDelay:0,lightSensitive:0b,spawnGroups:[{settingsList:[{remainingSpawnCount:1,hostile:1b,forced:1b,customTag:{factionName:"orc"},maxToSpawn:1,entityId:"ancientwarfarenpc:faction.archer",minToSpawn:1}],groupWeight:1}],playerRange:8,respondToRedstone:0b,inventory:{Size:9,Items:[]},spawnRange:0,transparent:1b,maxDelay:0,xpToDrop:0,mobRange:0,debugMode:0b,maxNearbyMonsters:0}}}
:enddata
:endrule

rule:
plugin=inventory
number=19
data:
JSON:{blockState:{blockName:"minecraft:chest",properties:{facing:"north"}},lootLevel:0,teData:{ForgeData:{},Items:[{Slot:1b,id:"minecraft:bone",Count:2b,Damage:0s},{Slot:2b,id:"minecraft:bone",Count:2b,Damage:0s},{Slot:4b,id:"minecraft:poisonous_potato",Count:2b,Damage:0s},{Slot:5b,id:"minecraft:poisonous_potato",Count:2b,Damage:0s},{Slot:6b,id:"minecraft:poisonous_potato",Count:2b,Damage:0s},{Slot:7b,id:"minecraft:poisonous_potato",Count:2b,Damage:0s},{Slot:8b,id:"minecraft:poisonous_potato",Count:1b,Damage:0s},{Slot:9b,id:"minecraft:slime_ball",Count:3b,Damage:0s},{Slot:10b,id:"minecraft:bone",Count:2b,Damage:0s},{Slot:11b,id:"minecraft:bone",Count:2b,Damage:0s},{Slot:12b,id:"minecraft:spider_eye",Count:3b,Damage:0s},{Slot:14b,id:"ancientwarfarenpc:coin",Count:10b,tag:{metal:"copper"},Damage:0s},{Slot:15b,id:"minecraft:rotten_flesh",Count:1b,Damage:0s},{Slot:17b,id:"minecraft:poisonous_potato",Count:1b,Damage:0s},{Slot:19b,id:"minecraft:bone",Count:2b,Damage:0s},{Slot:20b,id:"minecraft:dye",Count:3b,Damage:4s},{Slot:21b,id:"minecraft:gold_nugget",Count:3b,Damage:0s},{Slot:22b,id:"minecraft:rotten_flesh",Count:4b,Damage:0s},{Slot:23b,id:"minecraft:rotten_flesh",Count:1b,Damage:0s},{Slot:24b,id:"minecraft:coal",Count:4b,Damage:0s},{Slot:25b,id:"minecraft:brown_mushroom",Count:4b,Damage:0s},{Slot:26b,id:"minecraft:red_mushroom",Count:4b,Damage:0s}],id:"minecraft:chest",Lock:""},inventoryData:{length:22,inventoryContents:[{id:"minecraft:bone",Count:2b,slot:0,Damage:0s},{id:"minecraft:bone",Count:2b,slot:1,Damage:0s},{id:"minecraft:poisonous_potato",Count:2b,slot:2,Damage:0s},{id:"minecraft:poisonous_potato",Count:2b,slot:3,Damage:0s},{id:"minecraft:poisonous_potato",Count:2b,slot:4,Damage:0s},{id:"minecraft:poisonous_potato",Count:2b,slot:5,Damage:0s},{id:"minecraft:poisonous_potato",Count:1b,slot:6,Damage:0s},{id:"minecraft:slime_ball",Count:3b,slot:7,Damage:0s},{id:"minecraft:bone",Count:2b,slot:8,Damage:0s},{id:"minecraft:bone",Count:2b,slot:9,Damage:0s},{id:"minecraft:spider_eye",Count:3b,slot:10,Damage:0s},{id:"ancientwarfarenpc:coin",Count:10b,tag:{metal:"copper"},slot:11,Damage:0s},{id:"minecraft:rotten_flesh",Count:1b,slot:12,Damage:0s},{id:"minecraft:poisonous_potato",Count:1b,slot:13,Damage:0s},{id:"minecraft:bone",Count:2b,slot:14,Damage:0s},{id:"minecraft:dye",Count:3b,slot:15,Damage:4s},{id:"minecraft:gold_nugget",Count:3b,slot:16,Damage:0s},{id:"minecraft:rotten_flesh",Count:4b,slot:17,Damage:0s},{id:"minecraft:rotten_flesh",Count:1b,slot:18,Damage:0s},{id:"minecraft:coal",Count:4b,slot:19,Damage:0s},{id:"minecraft:brown_mushroom",Count:4b,slot:20,Damage:0s},{id:"minecraft:red_mushroom",Count:4b,slot:21,Damage:0s}]},legacyFeatures:1b}
:enddata
:endrule

rule:
plugin=blockTile
number=20
data:
JSON:{blockState:{blockName:"ancientwarfarestructure:advanced_spawner",properties:{transparent:"true"}},teData:{id:"ancientwarfarestructure:advanced_spawner_tile",spawnerSettings:{minDelay:0,spawnDelay:0,lightSensitive:0b,spawnGroups:[{settingsList:[{remainingSpawnCount:1,hostile:1b,forced:1b,customTag:{factionName:"orc"},maxToSpawn:1,entityId:"ancientwarfarenpc:faction.soldier",minToSpawn:1}],groupWeight:1}],playerRange:6,respondToRedstone:0b,inventory:{Size:9,Items:[]},spawnRange:0,transparent:1b,maxDelay:0,xpToDrop:0,mobRange:0,debugMode:0b,maxNearbyMonsters:0}}}
:enddata
:endrule

rule:
plugin=blockTile
number=21
data:
JSON:{blockState:{blockName:"ancientwarfarestructure:advanced_spawner",properties:{transparent:"true"}},teData:{id:"ancientwarfarestructure:advanced_spawner_tile",spawnerSettings:{minDelay:0,spawnDelay:0,lightSensitive:0b,spawnGroups:[{settingsList:[{remainingSpawnCount:1,hostile:1b,forced:1b,customTag:{factionName:"orc"},maxToSpawn:1,entityId:"ancientwarfarenpc:faction.soldier",minToSpawn:1}],groupWeight:1}],playerRange:6,respondToRedstone:0b,inventory:{Size:9,Items:[]},spawnRange:0,transparent:1b,maxDelay:0,xpToDrop:0,mobRange:0,debugMode:0b,maxNearbyMonsters:0}}}
:enddata
:endrule

rule:
plugin=blockTile
number=22
data:
JSON:{blockState:{blockName:"ancientwarfarestructure:advanced_spawner",properties:{transparent:"true"}},teData:{id:"ancientwarfarestructure:advanced_spawner_tile",spawnerSettings:{minDelay:0,spawnDelay:0,lightSensitive:0b,spawnGroups:[{settingsList:[{remainingSpawnCount:1,hostile:1b,forced:1b,customTag:{factionName:"orc"},maxToSpawn:1,entityId:"ancientwarfarenpc:faction.civilian.female",minToSpawn:1}],groupWeight:1}],playerRange:6,respondToRedstone:0b,inventory:{Size:9,Items:[]},spawnRange:0,transparent:1b,maxDelay:0,xpToDrop:0,mobRange:0,debugMode:0b,maxNearbyMonsters:0}}}
:enddata
:endrule

rule:
plugin=inventory
number=23
data:
JSON:{blockState:{blockName:"minecraft:furnace",properties:{facing:"north"}},lootLevel:0,teData:{CookTime:0,BurnTime:0,Items:[],id:"minecraft:furnace",CookTimeTotal:0,Lock:""},inventoryData:{length:0,inventoryContents:[]},legacyFeatures:0b}
:enddata
:endrule

rule:
plugin=blockTile
number=24
data:
JSON:{blockState:{blockName:"ancientwarfarestructure:advanced_spawner",properties:{transparent:"true"}},teData:{id:"ancientwarfarestructure:advanced_spawner_tile",spawnerSettings:{minDelay:0,spawnDelay:0,lightSensitive:0b,spawnGroups:[{settingsList:[{remainingSpawnCount:1,hostile:1b,forced:1b,customTag:{factionName:"orc"},maxToSpawn:1,entityId:"ancientwarfarenpc:faction.soldier",minToSpawn:1}],groupWeight:1}],playerRange:6,respondToRedstone:0b,inventory:{Size:9,Items:[]},spawnRange:0,transparent:1b,maxDelay:0,xpToDrop:0,mobRange:0,debugMode:0b,maxNearbyMonsters:0}}}
:enddata
:endrule

rule:
plugin=blockTile
number=25
data:
JSON:{blockState:{blockName:"ancientwarfarestructure:advanced_spawner",properties:{transparent:"true"}},teData:{id:"ancientwarfarestructure:advanced_spawner_tile",spawnerSettings:{minDelay:0,spawnDelay:0,lightSensitive:0b,spawnGroups:[{settingsList:[{remainingSpawnCount:1,hostile:1b,forced:1b,customTag:{factionName:"orc"},maxToSpawn:1,entityId:"ancientwarfarenpc:faction.civilian.female",minToSpawn:1}],groupWeight:1}],playerRange:6,respondToRedstone:0b,inventory:{Size:9,Items:[]},spawnRange:0,transparent:1b,maxDelay:0,xpToDrop:0,mobRange:0,debugMode:0b,maxNearbyMonsters:0}}}
:enddata
:endrule

rule:
plugin=blockTile
number=26
data:
JSON:{blockState:{blockName:"ancientwarfarestructure:advanced_spawner",properties:{transparent:"true"}},teData:{id:"ancientwarfarestructure:advanced_spawner_tile",spawnerSettings:{minDelay:0,spawnDelay:0,lightSensitive:0b,spawnGroups:[{settingsList:[{remainingSpawnCount:1,hostile:1b,forced:1b,customTag:{factionName:"orc"},maxToSpawn:1,entityId:"ancientwarfarenpc:faction.archer",minToSpawn:1}],groupWeight:1}],playerRange:8,respondToRedstone:0b,inventory:{Size:9,Items:[]},spawnRange:0,transparent:1b,maxDelay:0,xpToDrop:0,mobRange:0,debugMode:0b,maxNearbyMonsters:0}}}
:enddata
:endrule

rule:
plugin=blockTile
number=27
data:
JSON:{blockState:{blockName:"ancientwarfarestructure:advanced_spawner",properties:{transparent:"true"}},teData:{id:"ancientwarfarestructure:advanced_spawner_tile",spawnerSettings:{minDelay:0,spawnDelay:0,lightSensitive:0b,spawnGroups:[{settingsList:[{remainingSpawnCount:1,hostile:1b,forced:1b,customTag:{factionName:"orc"},maxToSpawn:1,entityId:"ancientwarfarenpc:faction.civilian.female",minToSpawn:1}],groupWeight:1}],playerRange:6,respondToRedstone:0b,inventory:{Size:9,Items:[]},spawnRange:0,transparent:1b,maxDelay:0,xpToDrop:0,mobRange:0,debugMode:0b,maxNearbyMonsters:0}}}
:enddata
:endrule

rule:
plugin=inventory
number=28
data:
JSON:{blockState:{blockName:"minecraft:chest",properties:{facing:"north"}},lootLevel:0,teData:{ForgeData:{},Items:[{Slot:0b,id:"minecraft:rotten_flesh",Count:2b,Damage:0s},{Slot:1b,id:"minecraft:rotten_flesh",Count:4b,Damage:0s},{Slot:2b,id:"ancientwarfarenpc:coin",Count:10b,tag:{metal:"copper"},Damage:0s},{Slot:3b,id:"minecraft:bone",Count:1b,Damage:0s},{Slot:5b,id:"minecraft:bone",Count:1b,Damage:0s},{Slot:7b,id:"minecraft:poisonous_potato",Count:2b,Damage:0s},{Slot:8b,id:"minecraft:poisonous_potato",Count:5b,Damage:0s},{Slot:9b,id:"minecraft:rotten_flesh",Count:2b,Damage:0s},{Slot:10b,id:"minecraft:rotten_flesh",Count:4b,Damage:0s},{Slot:11b,id:"minecraft:rotten_flesh",Count:1b,Damage:0s},{Slot:13b,id:"minecraft:bone",Count:4b,Damage:0s},{Slot:14b,id:"minecraft:bone",Count:4b,Damage:0s},{Slot:15b,id:"minecraft:bone",Count:2b,Damage:0s},{Slot:16b,id:"minecraft:poisonous_potato",Count:3b,Damage:0s},{Slot:17b,id:"minecraft:red_mushroom",Count:6b,Damage:0s},{Slot:18b,id:"minecraft:dye",Count:2b,Damage:4s},{Slot:19b,id:"minecraft:slime_ball",Count:4b,Damage:0s},{Slot:20b,id:"minecraft:spider_eye",Count:4b,Damage:0s},{Slot:21b,id:"minecraft:gold_nugget",Count:2b,Damage:0s},{Slot:22b,id:"minecraft:bone",Count:3b,Damage:0s},{Slot:23b,id:"minecraft:bone",Count:1b,Damage:0s},{Slot:25b,id:"minecraft:poisonous_potato",Count:3b,Damage:0s},{Slot:26b,id:"minecraft:brown_mushroom",Count:4b,Damage:0s}],id:"minecraft:chest",Lock:""},inventoryData:{length:23,inventoryContents:[{id:"minecraft:rotten_flesh",Count:2b,slot:0,Damage:0s},{id:"minecraft:rotten_flesh",Count:4b,slot:1,Damage:0s},{id:"ancientwarfarenpc:coin",Count:10b,tag:{metal:"copper"},slot:2,Damage:0s},{id:"minecraft:bone",Count:1b,slot:3,Damage:0s},{id:"minecraft:bone",Count:1b,slot:4,Damage:0s},{id:"minecraft:poisonous_potato",Count:2b,slot:5,Damage:0s},{id:"minecraft:poisonous_potato",Count:5b,slot:6,Damage:0s},{id:"minecraft:rotten_flesh",Count:2b,slot:7,Damage:0s},{id:"minecraft:rotten_flesh",Count:4b,slot:8,Damage:0s},{id:"minecraft:rotten_flesh",Count:1b,slot:9,Damage:0s},{id:"minecraft:bone",Count:4b,slot:10,Damage:0s},{id:"minecraft:bone",Count:4b,slot:11,Damage:0s},{id:"minecraft:bone",Count:2b,slot:12,Damage:0s},{id:"minecraft:poisonous_potato",Count:3b,slot:13,Damage:0s},{id:"minecraft:red_mushroom",Count:6b,slot:14,Damage:0s},{id:"minecraft:dye",Count:2b,slot:15,Damage:4s},{id:"minecraft:slime_ball",Count:4b,slot:16,Damage:0s},{id:"minecraft:spider_eye",Count:4b,slot:17,Damage:0s},{id:"minecraft:gold_nugget",Count:2b,slot:18,Damage:0s},{id:"minecraft:bone",Count:3b,slot:19,Damage:0s},{id:"minecraft:bone",Count:1b,slot:20,Damage:0s},{id:"minecraft:poisonous_potato",Count:3b,slot:21,Damage:0s},{id:"minecraft:brown_mushroom",Count:4b,slot:22,Damage:0s}]},legacyFeatures:1b}
:enddata
:endrule

rule:
plugin=blockTile
number=29
data:
JSON:{blockState:{blockName:"ancientwarfarestructure:advanced_spawner",properties:{transparent:"true"}},teData:{id:"ancientwarfarestructure:advanced_spawner_tile",spawnerSettings:{minDelay:0,spawnDelay:0,lightSensitive:0b,spawnGroups:[{settingsList:[{remainingSpawnCount:1,hostile:1b,forced:1b,customTag:{factionName:"orc"},maxToSpawn:1,entityId:"ancientwarfarenpc:faction.soldier",minToSpawn:1}],groupWeight:1}],playerRange:6,respondToRedstone:0b,inventory:{Size:9,Items:[]},spawnRange:0,transparent:1b,maxDelay:0,xpToDrop:0,mobRange:0,debugMode:0b,maxNearbyMonsters:0}}}
:enddata
:endrule

rule:
plugin=inventory
number=30
data:
JSON:{blockState:{blockName:"minecraft:furnace",properties:{facing:"east"}},lootLevel:0,teData:{CookTime:0,BurnTime:0,Items:[],id:"minecraft:furnace",CookTimeTotal:0,Lock:""},inventoryData:{length:0,inventoryContents:[]},legacyFeatures:0b}
:enddata
:endrule

rule:
plugin=inventory
number=31
data:
JSON:{blockState:{blockName:"minecraft:chest",properties:{facing:"east"}},lootLevel:0,teData:{ForgeData:{},Items:[{Slot:3b,id:"minecraft:bone",Count:2b,Damage:0s},{Slot:7b,id:"minecraft:string",Count:1b,Damage:0s},{Slot:10b,id:"minecraft:bucket",Count:1b,Damage:0s},{Slot:18b,id:"minecraft:melon_seeds",Count:1b,Damage:0s},{Slot:20b,id:"minecraft:rotten_flesh",Count:2b,Damage:0s},{Slot:21b,id:"minecraft:bone",Count:2b,Damage:0s},{Slot:22b,id:"minecraft:bread",Count:1b,Damage:0s},{Slot:24b,id:"minecraft:rotten_flesh",Count:1b,Damage:0s},{Slot:26b,id:"minecraft:melon_seeds",Count:2b,Damage:0s}],id:"minecraft:chest",Lock:""},inventoryData:{length:9,inventoryContents:[{id:"minecraft:bone",Count:2b,slot:0,Damage:0s},{id:"minecraft:string",Count:1b,slot:1,Damage:0s},{id:"minecraft:bucket",Count:1b,slot:2,Damage:0s},{id:"minecraft:melon_seeds",Count:1b,slot:3,Damage:0s},{id:"minecraft:rotten_flesh",Count:2b,slot:4,Damage:0s},{id:"minecraft:bone",Count:2b,slot:5,Damage:0s},{id:"minecraft:bread",Count:1b,slot:6,Damage:0s},{id:"minecraft:rotten_flesh",Count:1b,slot:7,Damage:0s},{id:"minecraft:melon_seeds",Count:2b,slot:8,Damage:0s}]},legacyFeatures:1b}
:enddata
:endrule

rule:
plugin=blockTile
number=32
data:
JSON:{blockState:{blockName:"ancientwarfarestructure:advanced_spawner",properties:{transparent:"true"}},teData:{id:"ancientwarfarestructure:advanced_spawner_tile",spawnerSettings:{minDelay:0,spawnDelay:0,lightSensitive:0b,spawnGroups:[{settingsList:[{remainingSpawnCount:1,hostile:1b,forced:1b,customTag:{factionName:"orc"},maxToSpawn:1,entityId:"ancientwarfarenpc:faction.soldier",minToSpawn:1}],groupWeight:1}],playerRange:6,respondToRedstone:0b,inventory:{Size:9,Items:[]},spawnRange:0,transparent:1b,maxDelay:0,xpToDrop:0,mobRange:0,debugMode:0b,maxNearbyMonsters:0}}}
:enddata
:endrule

rule:
plugin=blockTile
number=33
data:
JSON:{blockState:{blockName:"ancientwarfarestructure:advanced_spawner",properties:{transparent:"true"}},teData:{id:"ancientwarfarestructure:advanced_spawner_tile",spawnerSettings:{minDelay:0,spawnDelay:0,lightSensitive:0b,spawnGroups:[{settingsList:[{remainingSpawnCount:1,hostile:1b,forced:1b,customTag:{factionName:"orc"},maxToSpawn:1,entityId:"ancientwarfarenpc:faction.archer",minToSpawn:1}],groupWeight:1}],playerRange:8,respondToRedstone:0b,inventory:{Size:9,Items:[]},spawnRange:0,transparent:1b,maxDelay:0,xpToDrop:0,mobRange:0,debugMode:0b,maxNearbyMonsters:0}}}
:enddata
:endrule

rule:
plugin=inventory
number=34
data:
JSON:{blockState:{blockName:"minecraft:furnace",properties:{facing:"north"}},lootLevel:0,teData:{CookTime:0,BurnTime:0,Items:[],id:"minecraft:furnace",CookTimeTotal:0,Lock:""},inventoryData:{length:0,inventoryContents:[]},legacyFeatures:0b}
:enddata
:endrule

rule:
plugin=blockTile
number=35
data:
JSON:{blockState:{blockName:"ancientwarfarestructure:advanced_spawner",properties:{transparent:"true"}},teData:{id:"ancientwarfarestructure:advanced_spawner_tile",spawnerSettings:{minDelay:0,spawnDelay:0,lightSensitive:0b,spawnGroups:[{settingsList:[{remainingSpawnCount:1,hostile:1b,forced:1b,customTag:{factionName:"orc"},maxToSpawn:1,entityId:"ancientwarfarenpc:faction.archer",minToSpawn:1}],groupWeight:1}],playerRange:8,respondToRedstone:0b,inventory:{Size:9,Items:[]},spawnRange:0,transparent:1b,maxDelay:0,xpToDrop:0,mobRange:0,debugMode:0b,maxNearbyMonsters:0}}}
:enddata
:endrule

rule:
plugin=inventory
number=36
data:
JSON:{blockState:{blockName:"minecraft:furnace",properties:{facing:"east"}},lootLevel:0,teData:{CookTime:0,BurnTime:0,Items:[],id:"minecraft:furnace",CookTimeTotal:0,Lock:""},inventoryData:{length:0,inventoryContents:[]},legacyFeatures:0b}
:enddata
:endrule

rule:
plugin=inventory
number=37
data:
JSON:{blockState:{blockName:"minecraft:chest",properties:{facing:"east"}},lootLevel:0,teData:{ForgeData:{},Items:[{Slot:0b,id:"minecraft:rotten_flesh",Count:2b,Damage:0s},{Slot:1b,id:"minecraft:rotten_flesh",Count:4b,Damage:0s},{Slot:2b,id:"minecraft:rotten_flesh",Count:2b,Damage:0s},{Slot:3b,id:"minecraft:bone",Count:1b,Damage:0s},{Slot:7b,id:"minecraft:red_mushroom",Count:5b,Damage:0s},{Slot:9b,id:"minecraft:rotten_flesh",Count:1b,Damage:0s},{Slot:10b,id:"minecraft:rotten_flesh",Count:3b,Damage:0s},{Slot:11b,id:"minecraft:rotten_flesh",Count:2b,Damage:0s},{Slot:13b,id:"minecraft:bone",Count:2b,Damage:0s},{Slot:14b,id:"minecraft:bone",Count:2b,Damage:0s},{Slot:15b,id:"minecraft:gold_nugget",Count:3b,Damage:0s},{Slot:17b,id:"minecraft:coal",Count:3b,Damage:0s},{Slot:19b,id:"minecraft:slime_ball",Count:2b,Damage:0s},{Slot:20b,id:"minecraft:dye",Count:2b,Damage:4s},{Slot:21b,id:"minecraft:spider_eye",Count:3b,Damage:0s},{Slot:23b,id:"minecraft:bone",Count:2b,Damage:0s},{Slot:25b,id:"minecraft:brown_mushroom",Count:4b,Damage:0s}],id:"minecraft:chest",Lock:""},inventoryData:{length:17,inventoryContents:[{id:"minecraft:rotten_flesh",Count:2b,slot:0,Damage:0s},{id:"minecraft:rotten_flesh",Count:4b,slot:1,Damage:0s},{id:"minecraft:rotten_flesh",Count:2b,slot:2,Damage:0s},{id:"minecraft:bone",Count:1b,slot:3,Damage:0s},{id:"minecraft:red_mushroom",Count:5b,slot:4,Damage:0s},{id:"minecraft:rotten_flesh",Count:1b,slot:5,Damage:0s},{id:"minecraft:rotten_flesh",Count:3b,slot:6,Damage:0s},{id:"minecraft:rotten_flesh",Count:2b,slot:7,Damage:0s},{id:"minecraft:bone",Count:2b,slot:8,Damage:0s},{id:"minecraft:bone",Count:2b,slot:9,Damage:0s},{id:"minecraft:gold_nugget",Count:3b,slot:10,Damage:0s},{id:"minecraft:coal",Count:3b,slot:11,Damage:0s},{id:"minecraft:slime_ball",Count:2b,slot:12,Damage:0s},{id:"minecraft:dye",Count:2b,slot:13,Damage:4s},{id:"minecraft:spider_eye",Count:3b,slot:14,Damage:0s},{id:"minecraft:bone",Count:2b,slot:15,Damage:0s},{id:"minecraft:brown_mushroom",Count:4b,slot:16,Damage:0s}]},legacyFeatures:1b}
:enddata
:endrule

rule:
plugin=vanillaBlocks
number=38
data:
JSON:{blockState:{blockName:"minecraft:gravel"}}
:enddata
:endrule

rule:
plugin=vanillaBlocks
number=39
data:
JSON:{blockState:{blockName:"minecraft:netherrack"}}
:enddata
:endrule

rule:
plugin=inventory
number=40
data:
JSON:{blockState:{blockName:"minecraft:chest",properties:{facing:"north"}},lootLevel:0,teData:{Items:[],id:"minecraft:chest",Lock:""},inventoryData:{length:0,inventoryContents:[]},legacyFeatures:1b}
:enddata
:endrule

rule:
plugin=vanillaBlocks
number=41
data:
JSON:{blockState:{blockName:"minecraft:log2",properties:{variant:"dark_oak",axis:"y"}}}
:enddata
:endrule

rule:
plugin=vanillaBlocks
number=42
data:
JSON:{blockState:{blockName:"minecraft:tallgrass",properties:{type:"tall_grass"}}}
:enddata
:endrule

rule:
plugin=vanillaBlocks
number=43
data:
JSON:{blockState:{blockName:"minecraft:double_plant",properties:{half:"lower",variant:"double_grass",facing:"east"}}}
:enddata
:endrule

rule:
plugin=vanillaBlocks
number=44
data:
JSON:{blockState:{blockName:"minecraft:stone_slab",properties:{half:"bottom",variant:"cobblestone"}}}
:enddata
:endrule

rule:
plugin=inventory
number=45
data:
JSON:{blockState:{blockName:"minecraft:chest",properties:{facing:"west"}},lootLevel:0,teData:{Items:[],id:"minecraft:chest",Lock:""},inventoryData:{length:0,inventoryContents:[]},legacyFeatures:1b}
:enddata
:endrule

rule:
plugin=vanillaBlocks
number=46
data:
JSON:{blockState:{blockName:"minecraft:nether_brick_fence",properties:{east:"false",south:"false",north:"false",west:"false"}}}
:enddata
:endrule

rule:
plugin=inventory
number=47
data:
JSON:{blockState:{blockName:"minecraft:chest",properties:{facing:"south"}},lootLevel:0,teData:{ForgeData:{},Items:[{Slot:2b,id:"ancientwarfarenpc:coin",Count:2b,tag:{metal:"gold"},Damage:0s},{Slot:3b,id:"ancientwarfarenpc:coin",Count:5b,tag:{metal:"silver"},Damage:0s},{Slot:4b,id:"ancientwarfarenpc:coin",Count:21b,tag:{metal:"copper"},Damage:0s},{Slot:7b,id:"minecraft:coal",Count:6b,Damage:0s},{Slot:10b,id:"minecraft:slime_ball",Count:6b,Damage:0s},{Slot:12b,id:"minecraft:spider_eye",Count:6b,Damage:0s},{Slot:15b,id:"minecraft:gold_nugget",Count:5b,Damage:0s},{Slot:20b,id:"minecraft:dye",Count:4b,Damage:4s},{Slot:22b,id:"minecraft:rotten_flesh",Count:11b,Damage:0s},{Slot:23b,id:"minecraft:bone",Count:16b,Damage:0s},{Slot:24b,id:"minecraft:brown_mushroom",Count:10b,Damage:0s},{Slot:25b,id:"minecraft:poisonous_potato",Count:25b,Damage:0s},{Slot:26b,id:"minecraft:red_mushroom",Count:5b,Damage:0s}],id:"minecraft:chest",Lock:""},inventoryData:{length:13,inventoryContents:[{id:"ancientwarfarenpc:coin",Count:2b,tag:{metal:"gold"},slot:0,Damage:0s},{id:"ancientwarfarenpc:coin",Count:5b,tag:{metal:"silver"},slot:1,Damage:0s},{id:"ancientwarfarenpc:coin",Count:21b,tag:{metal:"copper"},slot:2,Damage:0s},{id:"minecraft:coal",Count:6b,slot:3,Damage:0s},{id:"minecraft:slime_ball",Count:6b,slot:4,Damage:0s},{id:"minecraft:spider_eye",Count:6b,slot:5,Damage:0s},{id:"minecraft:gold_nugget",Count:5b,slot:6,Damage:0s},{id:"minecraft:dye",Count:4b,slot:7,Damage:4s},{id:"minecraft:rotten_flesh",Count:11b,slot:8,Damage:0s},{id:"minecraft:bone",Count:16b,slot:9,Damage:0s},{id:"minecraft:brown_mushroom",Count:10b,slot:10,Damage:0s},{id:"minecraft:poisonous_potato",Count:25b,slot:11,Damage:0s},{id:"minecraft:red_mushroom",Count:5b,slot:12,Damage:0s}]},legacyFeatures:1b}
:enddata
:endrule

rule:
plugin=blockTile
number=48
data:
JSON:{blockState:{blockName:"ancientwarfarestructure:advanced_spawner",properties:{transparent:"true"}},teData:{id:"ancientwarfarestructure:advanced_spawner_tile",spawnerSettings:{minDelay:0,spawnDelay:0,lightSensitive:0b,spawnGroups:[{settingsList:[{remainingSpawnCount:1,hostile:1b,forced:1b,customTag:{factionName:"orc"},maxToSpawn:1,entityId:"ancientwarfarenpc:faction.soldier.elite",minToSpawn:1}],groupWeight:1}],playerRange:6,respondToRedstone:0b,inventory:{Size:9,Items:[]},spawnRange:0,transparent:1b,maxDelay:0,xpToDrop:0,mobRange:0,debugMode:0b,maxNearbyMonsters:0}}}
:enddata
:endrule

rule:
plugin=blockTile
number=49
data:
JSON:{blockState:{blockName:"ancientwarfarestructure:advanced_spawner",properties:{transparent:"true"}},teData:{id:"ancientwarfarestructure:advanced_spawner_tile",spawnerSettings:{minDelay:0,spawnDelay:0,lightSensitive:0b,spawnGroups:[{settingsList:[{remainingSpawnCount:1,hostile:1b,forced:1b,customTag:{factionName:"orc"},maxToSpawn:1,entityId:"ancientwarfarenpc:faction.soldier.elite",minToSpawn:1}],groupWeight:1}],playerRange:6,respondToRedstone:0b,inventory:{Size:9,Items:[]},spawnRange:0,transparent:1b,maxDelay:0,xpToDrop:0,mobRange:0,debugMode:0b,maxNearbyMonsters:0}}}
:enddata
:endrule

rule:
plugin=vanillaBlocks
number=50
data:
JSON:{blockState:{blockName:"minecraft:fire",properties:{east:"false",south:"false",north:"false",west:"false",up:"false",age:"15"}}}
:enddata
:endrule

rule:
plugin=vanillaBlocks
number=51
data:
JSON:{blockState:{blockName:"minecraft:stone_stairs",properties:{half:"bottom",shape:"straight",facing:"west"}}}
:enddata
:endrule

rule:
plugin=blockTile
number=52
data:
JSON:{blockState:{blockName:"ancientwarfarestructure:advanced_spawner",properties:{transparent:"true"}},teData:{id:"ancientwarfarestructure:advanced_spawner_tile",spawnerSettings:{minDelay:0,spawnDelay:0,lightSensitive:0b,spawnGroups:[{settingsList:[{remainingSpawnCount:1,hostile:1b,forced:1b,customTag:{factionName:"orc"},maxToSpawn:1,entityId:"ancientwarfarenpc:faction.soldier.elite",minToSpawn:1}],groupWeight:1}],playerRange:6,respondToRedstone:0b,inventory:{Size:9,Items:[]},spawnRange:0,transparent:1b,maxDelay:0,xpToDrop:0,mobRange:0,debugMode:0b,maxNearbyMonsters:0}}}
:enddata
:endrule

rule:
plugin=blockTile
number=53
data:
JSON:{blockState:{blockName:"ancientwarfarestructure:advanced_spawner",properties:{transparent:"true"}},teData:{id:"ancientwarfarestructure:advanced_spawner_tile",spawnerSettings:{minDelay:0,spawnDelay:0,lightSensitive:0b,spawnGroups:[{settingsList:[{remainingSpawnCount:1,hostile:1b,forced:1b,customTag:{factionName:"orc"},maxToSpawn:1,entityId:"ancientwarfarenpc:faction.soldier.elite",minToSpawn:1}],groupWeight:1}],playerRange:8,respondToRedstone:0b,inventory:{Size:9,Items:[]},spawnRange:0,transparent:1b,maxDelay:0,xpToDrop:0,mobRange:0,debugMode:0b,maxNearbyMonsters:0}}}
:enddata
:endrule

rule:
plugin=vanillaBlocks
number=54
data:
JSON:{blockState:{blockName:"minecraft:trapdoor",properties:{half:"bottom",facing:"west",open:"false"}}}
:enddata
:endrule

rule:
plugin=inventory
number=55
data:
JSON:{blockState:{blockName:"minecraft:furnace",properties:{facing:"south"}},lootLevel:0,teData:{CookTime:0,BurnTime:0,Items:[],id:"minecraft:furnace",CookTimeTotal:0,Lock:""},inventoryData:{length:0,inventoryContents:[]},legacyFeatures:0b}
:enddata
:endrule

rule:
plugin=blockTile
number=56
data:
JSON:{blockState:{blockName:"ancientwarfarestructure:advanced_spawner",properties:{transparent:"true"}},teData:{id:"ancientwarfarestructure:advanced_spawner_tile",spawnerSettings:{minDelay:0,spawnDelay:0,lightSensitive:0b,spawnGroups:[{settingsList:[{remainingSpawnCount:1,hostile:1b,forced:1b,customTag:{factionName:"orc"},maxToSpawn:1,entityId:"ancientwarfarenpc:faction.priest",minToSpawn:1}],groupWeight:1}],playerRange:6,respondToRedstone:0b,inventory:{Size:9,Items:[]},spawnRange:0,transparent:1b,maxDelay:0,xpToDrop:0,mobRange:0,debugMode:0b,maxNearbyMonsters:0}}}
:enddata
:endrule

rule:
plugin=blockTile
number=57
data:
JSON:{blockState:{blockName:"ancientwarfarestructure:advanced_spawner",properties:{transparent:"true"}},teData:{id:"ancientwarfarestructure:advanced_spawner_tile",spawnerSettings:{minDelay:0,spawnDelay:0,lightSensitive:0b,spawnGroups:[{settingsList:[{remainingSpawnCount:1,hostile:1b,forced:1b,customTag:{factionName:"orc"},maxToSpawn:1,entityId:"ancientwarfarenpc:faction.soldier.elite",minToSpawn:1}],groupWeight:1}],playerRange:8,respondToRedstone:0b,inventory:{Size:9,Items:[]},spawnRange:0,transparent:1b,maxDelay:0,xpToDrop:0,mobRange:0,debugMode:0b,maxNearbyMonsters:0}}}
:enddata
:endrule

rule:
plugin=vanillaBlocks
number=58
data:
JSON:{blockState:{blockName:"minecraft:trapdoor",properties:{half:"bottom",facing:"east",open:"false"}}}
:enddata
:endrule

rule:
plugin=vanillaBlocks
number=59
data:
JSON:{blockState:{blockName:"minecraft:stone_stairs",properties:{half:"bottom",shape:"straight",facing:"east"}}}
:enddata
:endrule

rule:
plugin=vanillaBlocks
number=60
data:
JSON:{blockState:{blockName:"minecraft:dark_oak_stairs",properties:{half:"top",shape:"straight",facing:"south"}}}
:enddata
:endrule

rule:
plugin=vanillaBlocks
number=61
data:
JSON:{blockState:{blockName:"minecraft:dark_oak_stairs",properties:{half:"top",shape:"straight",facing:"north"}}}
:enddata
:endrule

rule:
plugin=vanillaBlocks
number=62
data:
JSON:{blockState:{blockName:"minecraft:torch",properties:{facing:"west"}}}
:enddata
:endrule

rule:
plugin=vanillaBlocks
number=63
data:
JSON:{blockState:{blockName:"minecraft:double_plant",properties:{half:"upper",variant:"sunflower",facing:"east"}}}
:enddata
:endrule

rule:
plugin=vanillaBlocks
number=64
data:
JSON:{blockState:{blockName:"minecraft:dark_oak_stairs",properties:{half:"top",shape:"straight",facing:"west"}}}
:enddata
:endrule

rule:
plugin=vanillaBlocks
number=65
data:
JSON:{blockState:{blockName:"minecraft:torch",properties:{facing:"south"}}}
:enddata
:endrule

rule:
plugin=vanillaBlocks
number=66
data:
JSON:{blockState:{blockName:"minecraft:torch",properties:{facing:"north"}}}
:enddata
:endrule

rule:
plugin=vanillaBlocks
number=67
data:
JSON:{blockState:{blockName:"minecraft:dark_oak_stairs",properties:{half:"top",shape:"straight",facing:"east"}}}
:enddata
:endrule

rule:
plugin=vanillaSkull
number=68
data:
JSON:{blockState:{blockName:"minecraft:skull",properties:{nodrop:"false",facing:"up"}},skullRotation:12,teData:{Rot:8b,id:"minecraft:skull",SkullType:3b}}
:enddata
:endrule

rule:
plugin=vanillaSkull
number=69
data:
JSON:{blockState:{blockName:"minecraft:skull",properties:{nodrop:"false",facing:"up"}},skullRotation:12,teData:{Rot:8b,id:"minecraft:skull",SkullType:0b}}
:enddata
:endrule

rule:
plugin=vanillaSkull
number=70
data:
JSON:{blockState:{blockName:"minecraft:skull",properties:{nodrop:"false",facing:"up"}},skullRotation:12,teData:{Rot:8b,id:"minecraft:skull",SkullType:3b}}
:enddata
:endrule

rule:
plugin=vanillaSkull
number=71
data:
JSON:{blockState:{blockName:"minecraft:skull",properties:{nodrop:"false",facing:"up"}},skullRotation:12,teData:{Rot:8b,id:"minecraft:skull",SkullType:0b}}
:enddata
:endrule

rule:
plugin=vanillaSkull
number=72
data:
JSON:{blockState:{blockName:"minecraft:skull",properties:{nodrop:"false",facing:"up"}},skullRotation:0,teData:{Rot:12b,id:"minecraft:skull",SkullType:0b}}
:enddata
:endrule

rule:
plugin=vanillaBlocks
number=73
data:
JSON:{blockState:{blockName:"minecraft:torch",properties:{facing:"up"}}}
:enddata
:endrule

rule:
plugin=blockTile
number=74
data:
JSON:{blockState:{blockName:"ancientwarfarestructure:advanced_spawner",properties:{transparent:"true"}},teData:{id:"ancientwarfarestructure:advanced_spawner_tile",spawnerSettings:{minDelay:0,spawnDelay:0,lightSensitive:0b,spawnGroups:[{settingsList:[{remainingSpawnCount:1,hostile:1b,forced:1b,customTag:{factionName:"orc"},maxToSpawn:1,entityId:"ancientwarfarenpc:faction.leader.elite",minToSpawn:1}],groupWeight:1}],playerRange:6,respondToRedstone:0b,inventory:{Size:9,Items:[]},spawnRange:0,transparent:1b,maxDelay:0,xpToDrop:0,mobRange:0,debugMode:0b,maxNearbyMonsters:0}}}
:enddata
:endrule

rule:
plugin=vanillaSkull
number=75
data:
JSON:{blockState:{blockName:"minecraft:skull",properties:{nodrop:"false",facing:"up"}},skullRotation:4,teData:{Rot:0b,id:"minecraft:skull",SkullType:0b}}
:enddata
:endrule

rule:
plugin=vanillaSkull
number=76
data:
JSON:{blockState:{blockName:"minecraft:skull",properties:{nodrop:"false",facing:"up"}},skullRotation:0,teData:{Rot:12b,id:"minecraft:skull",SkullType:0b}}
:enddata
:endrule

rule:
plugin=vanillaSkull
number=77
data:
JSON:{blockState:{blockName:"minecraft:skull",properties:{nodrop:"false",facing:"up"}},skullRotation:12,teData:{Rot:8b,id:"minecraft:skull",SkullType:3b}}
:enddata
:endrule

rule:
plugin=vanillaSkull
number=78
data:
JSON:{blockState:{blockName:"minecraft:skull",properties:{nodrop:"false",facing:"up"}},skullRotation:8,teData:{Rot:4b,id:"minecraft:skull",SkullType:3b}}
:enddata
:endrule

rule:
plugin=vanillaSkull
number=79
data:
JSON:{blockState:{blockName:"minecraft:skull",properties:{nodrop:"false",facing:"up"}},skullRotation:12,teData:{Rot:8b,id:"minecraft:skull",SkullType:3b}}
:enddata
:endrule

rule:
plugin=vanillaBlocks
number=80
data:
JSON:{blockState:{blockName:"minecraft:torch",properties:{facing:"east"}}}
:enddata
:endrule

rule:
plugin=vanillaBlocks
number=81
data:
JSON:{blockState:{blockName:"minecraft:double_wooden_slab",properties:{variant:"dark_oak"}}}
:enddata
:endrule

rule:
plugin=vanillaBlocks
number=82
data:
JSON:{blockState:{blockName:"minecraft:wooden_slab",properties:{half:"top",variant:"spruce"}}}
:enddata
:endrule

rule:
plugin=inventory
number=83
data:
JSON:{blockState:{blockName:"minecraft:brewing_stand",properties:{has_bottle_0:"false",has_bottle_1:"false",has_bottle_2:"false"}},lootLevel:0,teData:{Fuel:0b,Items:[],id:"minecraft:brewing_stand",BrewTime:0s,Lock:""},inventoryData:{length:0,inventoryContents:[]},legacyFeatures:0b}
:enddata
:endrule

rule:
plugin=vanillaSkull
number=84
data:
JSON:{blockState:{blockName:"minecraft:skull",properties:{nodrop:"false",facing:"up"}},skullRotation:4,teData:{Rot:0b,id:"minecraft:skull",SkullType:0b}}
:enddata
:endrule

rule:
plugin=vanillaSkull
number=85
data:
JSON:{blockState:{blockName:"minecraft:skull",properties:{nodrop:"false",facing:"up"}},skullRotation:0,teData:{Rot:12b,id:"minecraft:skull",SkullType:0b}}
:enddata
:endrule

rule:
plugin=vanillaSkull
number=86
data:
JSON:{blockState:{blockName:"minecraft:skull",properties:{nodrop:"false",facing:"up"}},skullRotation:4,teData:{Rot:0b,id:"minecraft:skull",SkullType:0b}}
:enddata
:endrule

rule:
plugin=vanillaBlocks
number=87
data:
JSON:{blockState:{blockName:"minecraft:cauldron",properties:{level:"3"}}}
:enddata
:endrule

rule:
plugin=vanillaBlocks
number=88
data:
JSON:{blockState:{blockName:"minecraft:stone_stairs",properties:{half:"top",shape:"straight",facing:"north"}}}
:enddata
:endrule

rule:
plugin=vanillaBlocks
number=89
data:
JSON:{blockState:{blockName:"minecraft:stone_slab",properties:{half:"top",variant:"cobblestone"}}}
:enddata
:endrule

rule:
plugin=vanillaBlocks
number=90
data:
JSON:{blockState:{blockName:"minecraft:obsidian"}}
:enddata
:endrule

rule:
plugin=vanillaSkull
number=91
data:
JSON:{blockState:{blockName:"minecraft:skull",properties:{nodrop:"false",facing:"up"}},skullRotation:12,teData:{Rot:8b,id:"minecraft:skull",SkullType:0b}}
:enddata
:endrule

rule:
plugin=vanillaSkull
number=92
data:
JSON:{blockState:{blockName:"minecraft:skull",properties:{nodrop:"false",facing:"up"}},skullRotation:8,teData:{Rot:4b,id:"minecraft:skull",SkullType:0b}}
:enddata
:endrule

rule:
plugin=vanillaSkull
number=93
data:
JSON:{blockState:{blockName:"minecraft:skull",properties:{nodrop:"false",facing:"up"}},skullRotation:0,teData:{Rot:12b,id:"minecraft:skull",SkullType:1b}}
:enddata
:endrule

rule:
plugin=vanillaSkull
number=94
data:
JSON:{blockState:{blockName:"minecraft:skull",properties:{nodrop:"false",facing:"up"}},skullRotation:12,teData:{Rot:8b,id:"minecraft:skull",SkullType:0b}}
:enddata
:endrule

rule:
plugin=vanillaSkull
number=95
data:
