# Ancient Warfare Structure Template File
# Auto-generated structure template file. created on: 8/19/2019 at: 10:23:14
# Lines beginning with # denote comments

header:
version=2.9
name=OrcWarrenTinyGeneric
mods=
size=18,29,18
offset=8,9,17
:endheader

#### VALIDATION ####
validation:
type=ground
survival=false
worldGenEnabled=true
unique=false
preserveBlocks=false
selectionWeight=30
clusterValue=10
minDuplicateDistance=900
dimensionWhiteList=true
dimensionList=0
biomeWhiteList=true
biomeList=biomesoplenty:shrubland,biomesoplenty:woodland,biomesoplenty:dead_swamp,biomesoplenty:dead_forest,traverse:woodlands,minecraft:forest,minecraft:extreme_hills,minecraft:redwood_taiga,minecraft:mutated_swampland,traverse:badlands,biomesoplenty:moor,traverse:rocky_plateau
leveling=3
fill=3
border=3
blockSwap=true
:endvalidation

#### LAYERS ####
layer: 0
1,1,1,1,1,1,1,1,1,1,1,1,1,1,1,1,1,1
1,1,4,1,1,1,1,1,1,1,1,1,1,1,1,1,1,1
1,1,1,1,1,1,1,1,1,1,1,1,1,1,1,1,1,1
1,1,1,1,1,1,1,1,1,1,1,1,1,1,1,1,1,1
1,1,1,1,1,1,1,1,1,1,1,1,1,1,1,1,1,1
1,1,1,1,1,1,1,1,1,1,1,1,1,1,1,1,1,1
1,1,1,1,1,1,1,1,1,1,1,1,1,1,1,1,1,1
1,1,1,1,1,1,1,1,1,1,1,1,1,1,1,1,1,1
1,1,1,1,1,1,1,1,1,1,1,1,1,1,1,1,1,1
1,1,1,1,1,1,1,1,1,1,1,1,1,1,1,1,1,1
1,1,1,1,1,1,1,1,1,1,1,1,1,1,1,1,1,1
1,1,1,1,1,1,1,1,1,1,1,1,1,1,1,1,1,1
1,1,1,1,1,1,1,1,1,1,1,1,1,1,1,1,1,1
1,1,1,1,1,1,1,1,1,1,1,1,1,1,1,1,1,1
1,1,1,1,1,1,1,1,1,1,1,1,1,1,1,1,1,1
1,1,1,1,2,2,1,1,1,1,1,1,1,1,1,1,1,1
1,1,1,1,3,3,1,1,1,1,1,1,1,1,1,1,1,1
1,1,1,1,1,1,1,1,1,1,1,1,1,1,1,1,1,1
:endlayer
layer: 1
1,1,1,1,1,1,1,1,1,1,1,1,1,1,1,1,1,1
1,1,0,0,0,0,20,15,2,0,12,2,0,0,0,6,1,1
1,1,0,19,19,19,0,0,2,0,0,2,0,0,0,0,1,1
1,1,0,19,2,19,0,0,0,0,0,2,0,0,0,0,1,1
1,1,0,19,19,19,0,0,2,0,0,0,0,0,0,0,1,1
1,1,23,0,0,0,0,16,2,0,0,2,0,0,0,0,1,1
1,1,2,2,0,2,2,2,11,11,11,2,2,0,2,2,1,1
1,1,21,2,0,0,0,0,0,13,2,11,2,0,0,0,5,1
1,1,21,2,0,2,2,2,2,2,2,11,8,0,0,7,5,1
1,1,0,2,0,2,21,17,2,11,2,2,9,0,0,0,5,1
1,1,0,0,0,0,0,0,2,2,11,2,2,0,0,0,5,1
1,1,2,2,0,2,2,2,11,11,2,2,2,2,0,2,1,1
1,1,0,0,0,0,0,0,2,0,0,2,10,0,0,0,1,1
1,1,24,0,0,0,0,0,0,0,0,2,0,0,0,0,1,1
1,1,11,0,0,0,0,18,2,0,0,0,0,0,0,0,1,1
1,1,11,19,19,19,19,19,2,14,0,2,0,0,0,0,1,1
1,1,1,1,22,22,1,1,1,1,1,1,1,1,1,1,1,1
1,1,1,1,1,1,1,1,1,1,1,1,1,1,1,1,1,1
:endlayer
layer: 2
1,1,1,1,1,1,1,1,1,1,1,1,1,1,1,1,1,1
1,1,0,0,0,0,0,0,2,0,0,2,0,0,0,0,1,1
1,1,0,0,0,0,0,0,2,0,0,2,0,0,0,0,1,1
1,1,0,0,31,0,0,0,0,0,0,2,0,0,0,0,1,1
1,1,0,0,0,0,0,0,2,0,0,0,0,0,0,0,1,1
1,1,0,0,0,0,0,0,2,0,0,2,0,0,0,0,1,1
1,1,2,2,0,2,2,2,2,2,2,11,2,0,2,2,1,1
1,1,32,2,0,0,0,0,0,0,0,2,26,0,0,0,5,1
1,1,0,2,0,2,2,2,11,2,24,11,27,0,0,0,5,1
1,1,0,2,0,2,0,0,2,2,11,2,28,0,0,0,5,1
1,1,0,0,0,0,0,0,11,2,11,2,29,0,0,0,5,1
1,1,2,2,0,2,2,2,11,11,2,2,2,2,0,2,1,1
1,1,0,0,0,0,0,0,2,0,0,2,0,0,0,0,1,1
1,1,0,0,0,0,0,0,0,0,0,2,0,0,0,0,1,1
1,1,24,0,0,0,0,0,2,0,0,0,0,0,0,0,1,1
1,1,11,0,0,0,0,0,2,0,0,2,0,0,0,25,1,1
1,1,1,1,30,30,1,1,1,1,1,1,1,1,1,1,1,1
1,1,1,1,1,1,1,1,1,1,1,1,1,1,1,1,1,1
:endlayer
layer: 3
1,1,1,1,1,1,1,1,1,1,1,1,1,1,1,1,1,1
1,1,0,0,37,0,37,0,2,34,34,2,0,36,0,0,1,1
1,1,37,0,38,0,0,0,2,8,8,2,0,0,0,0,1,1
1,1,0,0,31,0,0,0,2,8,8,2,0,0,0,0,1,1
1,1,37,0,38,0,0,0,2,8,0,2,0,0,0,0,1,1
1,1,0,0,0,0,0,0,2,8,8,2,0,0,0,0,1,1
1,1,2,2,2,2,2,2,2,2,2,2,2,2,2,2,1,1
1,1,0,2,28,0,0,0,0,0,0,11,8,34,34,33,1,1
1,1,0,2,0,2,2,2,2,2,0,11,8,0,0,33,2,1
1,1,0,2,0,2,0,0,2,11,24,2,8,0,0,33,1,1
1,1,0,2,0,2,0,0,2,11,2,2,8,35,35,33,2,1
1,1,2,2,2,2,2,2,11,2,2,2,2,2,2,2,1,1
1,1,0,2,2,2,2,2,2,0,0,2,8,8,8,8,1,1
1,1,0,2,2,2,2,2,2,0,0,2,8,0,0,8,1,1
1,1,0,2,2,2,2,2,2,0,0,2,8,0,0,8,1,1
1,1,24,2,2,2,2,2,2,0,0,2,8,8,8,8,1,1
1,1,1,1,1,1,1,1,1,1,1,1,1,1,1,1,1,1
1,1,1,1,1,1,1,1,1,1,1,1,1,1,1,1,1,1
:endlayer
layer: 4
1,1,1,1,1,1,1,1,1,1,1,1,1,1,1,1,1,1
1,1,0,0,55,0,53,0,2,0,0,2,19,19,19,19,1,1
1,1,58,0,0,0,0,0,2,0,0,2,19,0,0,19,1,1
1,1,0,0,56,0,0,0,2,0,0,2,19,0,0,19,1,1
1,1,59,0,0,0,0,0,2,0,0,2,19,0,0,19,1,1
1,1,0,0,0,0,0,0,2,0,0,2,19,19,19,19,1,1
1,1,2,2,2,2,2,2,2,2,2,2,2,2,2,2,1,1
1,1,0,2,0,0,0,0,0,0,0,2,44,0,0,0,2,1
1,1,0,2,0,2,2,2,2,2,0,11,45,0,0,0,39,2
1,1,0,2,0,2,0,0,2,2,0,11,46,0,0,0,2,1
1,1,0,2,0,2,0,0,11,50,0,2,47,0,0,0,40,2
1,1,2,2,2,2,2,2,11,2,2,2,2,2,2,2,2,1
1,1,0,21,57,21,54,21,2,0,0,2,0,0,42,0,1,1
1,1,0,21,0,21,0,21,2,0,0,2,48,0,0,0,0,1
1,1,0,0,0,0,0,51,2,0,0,2,0,0,0,41,0,1
1,1,0,0,0,0,0,52,2,0,0,2,49,43,0,0,1,1
1,1,1,1,1,1,1,1,1,1,1,1,1,0,0,1,1,1
1,1,1,1,1,1,1,1,1,1,1,1,1,1,1,1,1,1
:endlayer
layer: 5
1,1,1,1,1,1,1,1,1,1,1,1,1,1,1,1,1,1
1,1,0,0,0,0,0,0,2,0,0,2,0,0,0,0,1,1
1,1,0,0,0,0,0,0,2,0,0,2,0,0,0,0,1,1
1,1,0,0,0,0,0,0,2,0,0,2,0,0,0,0,1,1
1,1,0,0,0,0,0,0,2,0,0,2,0,0,0,0,1,1
1,1,0,0,0,0,0,0,2,0,0,2,0,0,0,0,1,1
1,1,2,2,2,2,2,2,11,2,11,2,2,2,2,2,1,1
1,1,0,2,0,0,0,0,11,0,0,11,0,0,0,0,2,1
1,1,0,2,0,2,2,2,2,2,0,11,0,0,0,0,0,2
1,1,0,2,0,2,0,0,2,2,0,2,0,0,0,0,2,1
1,1,0,2,0,2,0,0,50,0,0,2,0,0,0,0,0,2
1,1,2,2,2,2,2,2,2,11,2,2,2,2,2,2,2,1
1,1,0,0,0,0,0,60,2,0,0,2,0,0,0,0,1,1
1,1,0,0,0,0,0,0,2,0,0,2,0,0,0,0,0,1
1,1,0,0,0,0,0,0,2,0,0,2,0,0,0,0,0,1
1,1,0,0,0,0,0,0,2,0,0,2,0,0,0,0,1,1
1,1,1,1,1,1,1,1,1,1,1,1,1,0,0,1,1,1
1,1,1,1,1,1,1,1,1,1,1,1,1,1,1,1,1,1
:endlayer
layer: 6
1,1,1,1,1,1,1,1,1,1,1,1,1,1,1,1,1,1
1,1,1,1,1,1,1,1,1,1,1,1,1,1,1,1,1,1
1,1,1,1,1,1,1,1,1,1,1,1,1,1,1,1,1,1
1,1,1,1,1,1,1,1,1,1,1,1,1,1,1,1,1,1
1,1,1,1,1,1,1,1,1,1,1,1,1,1,1,1,1,1
1,1,1,1,1,1,1,1,1,1,1,1,1,1,1,1,1,1
1,1,1,1,1,1,1,1,1,1,1,1,1,1,1,1,1,1
1,1,1,1,1,1,1,1,1,1,1,1,1,1,1,1,1,1
1,1,1,1,1,1,1,1,1,1,11,1,1,1,1,1,1,1
1,1,1,1,1,1,1,11,2,2,0,11,1,1,1,1,1,1
1,1,1,1,1,1,1,50,0,0,0,11,1,1,1,1,1,1
1,1,1,1,1,1,2,2,2,2,11,11,1,1,1,1,1,1
1,1,1,1,1,1,1,1,1,1,1,1,1,1,1,1,1,1
1,1,1,1,1,1,1,1,1,1,1,1,1,1,1,1,1,1
1,1,1,1,1,1,1,1,1,1,1,1,1,1,1,1,1,1
1,1,1,1,1,1,1,1,1,1,1,1,1,1,1,1,1,1
1,1,1,1,1,1,1,1,1,1,1,1,1,1,1,1,1,1
1,1,1,1,1,1,1,1,1,1,1,1,1,1,1,1,1,1
:endlayer
layer: 7
61,61,61,61,61,61,61,61,61,61,61,61,61,61,61,61,61,61
61,63,61,61,61,61,61,61,64,62,61,61,61,61,61,61,62,61
61,61,61,61,61,61,61,61,61,61,61,61,61,61,61,61,61,61
61,61,61,61,61,61,61,61,61,61,61,61,61,61,61,61,61,61
61,61,61,61,61,61,61,61,61,61,61,61,61,61,61,61,61,61
61,61,61,61,61,61,61,61,61,61,61,61,61,61,61,61,61,61
61,61,61,61,61,61,61,61,61,61,61,61,61,61,61,61,61,61
61,61,61,61,61,61,61,61,61,61,61,61,61,61,61,61,61,61
61,64,61,61,61,61,61,61,64,64,11,61,61,61,61,61,63,61
61,64,61,61,61,61,61,61,64,64,11,61,61,61,61,61,63,61
61,61,61,61,61,61,50,0,0,0,11,61,61,61,61,61,61,61
61,61,61,61,61,61,2,61,61,61,61,61,61,61,61,61,61,61
61,61,61,61,61,61,61,61,61,61,61,61,61,61,61,61,61,61
61,61,61,61,61,61,61,61,61,61,61,61,61,61,61,61,61,61
61,61,61,61,61,61,61,61,61,61,61,61,61,61,61,61,61,61
61,61,61,61,61,61,61,61,61,61,61,61,61,61,61,61,61,61
61,64,61,61,61,61,61,61,65,64,61,61,61,61,61,61,63,61
61,61,61,61,61,61,61,61,61,61,61,61,61,61,61,61,61,61
:endlayer
layer: 8
66,66,66,66,66,66,66,66,66,66,66,66,66,66,66,66,66,66
66,62,61,61,61,61,61,61,64,64,61,61,61,61,61,61,63,66
66,61,61,61,61,61,61,61,61,61,61,61,61,61,61,61,61,66
66,61,61,61,61,61,61,61,61,61,61,61,61,61,61,61,61,66
66,61,61,61,61,61,61,61,61,61,61,61,61,61,61,61,66,66
66,61,61,61,61,61,61,61,61,61,61,61,61,61,61,61,61,66
66,61,61,61,61,61,61,61,61,61,61,61,61,61,61,61,66,66
66,61,61,61,61,61,61,61,61,61,61,61,61,61,66,61,61,66
66,62,61,61,61,61,61,61,64,64,61,66,66,61,66,66,62,66
66,64,61,61,61,61,61,61,64,64,66,66,66,66,66,66,63,66
66,61,61,61,66,50,0,0,0,11,66,66,66,66,66,66,62,66
66,61,61,61,61,61,61,61,61,61,66,66,66,67,66,66,66,66
66,61,61,61,66,66,66,66,66,66,66,66,67,67,67,66,62,66
66,61,61,66,66,66,66,66,61,66,66,66,67,67,67,66,62,66
66,61,61,66,66,66,66,66,66,66,66,66,66,67,67,66,62,66
66,61,61,66,66,66,66,66,66,66,66,66,66,67,66,66,62,66
66,63,63,63,63,66,63,63,63,63,63,63,63,63,63,63,65,66
66,66,66,66,66,66,66,66,66,66,66,66,66,66,66,66,66,66
:endlayer
layer: 9
0,0,0,0,0,0,0,0,0,0,0,0,0,0,0,0,0,0
0,63,63,66,63,63,63,63,64,62,62,62,62,66,62,62,62,0
0,63,66,61,61,66,66,66,66,66,66,66,66,66,66,66,62,0
0,63,66,66,61,61,66,66,66,66,66,66,66,66,66,66,62,0
0,63,66,66,61,61,66,66,66,66,66,66,66,66,66,66,68,68
0,63,66,66,66,66,66,66,66,61,66,66,66,66,66,66,66,0
0,63,66,66,66,66,66,66,66,66,66,66,66,66,66,66,0,0
0,63,66,66,66,66,66,66,66,66,66,66,66,66,0,66,66,0
0,63,66,66,66,66,66,66,64,64,66,0,0,66,0,0,63,0
0,63,66,66,66,66,66,66,66,64,0,0,0,0,0,0,63,0
0,63,66,66,68,0,0,0,66,66,0,0,68,68,0,0,0,0
0,63,66,66,66,66,66,66,66,66,0,68,0,0,0,68,0,68
0,63,66,11,68,68,68,68,0,0,68,68,0,0,0,68,0,0
0,63,66,0,0,0,68,0,11,0,0,68,0,0,0,0,0,0
0,63,66,68,0,68,68,68,0,68,0,68,68,0,0,0,0,0
0,63,66,68,68,0,68,0,0,68,68,68,68,0,0,0,0,0
0,63,63,63,0,0,63,63,63,63,63,63,63,63,0,63,64,0
0,0,0,0,0,0,0,0,0,0,0,0,0,0,0,0,0,0
:endlayer
layer: 10
0,0,0,0,0,0,0,0,0,0,0,0,0,0,0,0,0,0
0,69,0,0,0,0,0,0,64,62,0,0,0,0,0,0,63,0
0,0,0,66,66,0,0,0,0,0,0,0,0,0,0,0,0,0
0,0,68,0,66,66,68,0,0,0,0,0,0,0,0,0,0,0
0,0,0,0,66,11,0,68,0,0,0,68,0,0,0,0,0,0
0,0,0,68,68,0,0,0,0,11,0,0,68,68,68,0,0,0
0,0,68,68,68,68,68,0,68,0,0,0,68,0,0,0,0,0
0,0,0,0,68,68,0,68,0,68,0,68,0,0,0,0,0,0
0,63,68,68,68,0,0,0,64,64,68,0,0,0,0,0,62,0
0,63,68,68,68,0,68,0,68,64,0,0,0,0,0,0,63,0
0,0,0,68,0,0,0,0,0,0,0,0,0,0,0,0,0,0
0,0,0,68,0,68,68,68,68,0,0,0,0,0,0,0,0,0
0,0,0,11,0,0,0,0,0,0,0,0,0,0,0,0,0,0
0,0,0,0,0,0,0,0,11,0,0,0,0,0,0,0,0,0
0,0,0,0,0,0,0,0,0,0,0,0,0,0,0,0,0,0
0,0,0,0,0,0,0,0,0,0,0,0,0,0,0,0,0,0
0,11,0,0,0,0,0,0,63,63,63,63,63,0,0,0,64,0
0,0,0,0,0,0,0,0,0,0,0,0,0,0,0,0,0,0
:endlayer
layer: 11
0,0,0,0,0,0,0,0,0,0,0,0,0,0,0,0,0,0
0,64,0,0,0,0,0,0,64,63,0,0,0,0,0,0,62,0
0,0,0,0,0,0,0,0,0,0,0,0,0,0,0,0,0,0
0,0,0,0,0,0,0,0,0,0,0,0,0,0,0,0,0,0
0,0,0,0,0,0,0,0,0,0,0,0,0,0,0,0,0,0
0,0,0,0,0,0,0,0,0,0,0,0,0,0,0,0,0,0
0,0,0,0,0,0,0,0,0,0,0,0,0,0,0,0,0,0
0,0,0,0,0,0,0,0,0,0,0,0,0,0,0,0,0,0
0,64,0,0,0,0,0,0,64,64,0,0,0,0,0,0,63,0
0,62,0,0,0,0,0,0,0,62,0,0,0,0,0,0,63,0
0,0,0,0,0,0,0,0,0,0,0,0,0,0,0,0,0,0
0,0,0,0,0,0,0,0,0,0,0,0,0,0,0,0,0,0
0,0,0,11,0,0,0,0,0,0,0,0,0,0,0,0,0,0
0,0,0,0,0,0,0,0,0,0,0,0,0,0,0,0,0,0
0,0,0,0,0,0,0,0,0,0,0,0,0,0,0,0,0,0
0,0,0,0,0,0,0,0,0,0,0,0,0,0,0,0,0,0
0,0,0,0,0,0,0,0,62,63,63,63,0,0,0,0,65,0
0,0,0,0,0,0,0,0,0,0,0,0,0,0,0,0,0,0
:endlayer
layer: 12
0,0,0,0,0,0,0,0,0,0,0,0,0,0,0,0,0,0
0,64,0,0,0,0,0,0,64,63,0,0,0,0,0,0,64,0
0,0,0,0,0,0,0,0,0,0,0,0,0,0,0,0,0,0
0,0,0,0,0,0,0,0,0,0,0,0,0,0,0,0,0,0
0,0,0,0,0,0,0,0,0,0,0,0,0,0,0,0,0,0
0,0,0,0,0,0,0,0,0,0,0,0,0,0,0,0,0,0
0,0,0,0,0,0,0,0,0,0,0,0,0,0,0,0,0,0
0,0,0,0,0,0,0,0,0,0,0,0,0,0,0,0,0,0
0,64,0,0,0,0,0,0,63,63,0,0,0,0,0,0,64,0
0,62,0,0,0,0,0,0,0,63,0,0,0,0,0,0,64,0
0,0,0,0,0,0,0,0,0,0,0,0,0,0,0,0,0,0
0,0,0,0,0,0,0,0,0,0,0,0,0,0,0,0,0,0
0,0,0,0,0,0,0,0,0,0,0,0,0,0,0,0,0,0
0,0,0,0,0,0,0,0,0,0,0,0,0,0,0,0,0,0
0,0,0,0,0,0,0,0,0,0,0,0,0,0,0,0,0,0
0,0,0,0,0,0,0,0,0,0,0,0,0,0,0,0,0,0
0,0,0,0,0,0,0,0,64,63,0,0,0,0,0,0,70,0
0,0,0,0,0,0,0,0,0,0,0,0,0,0,0,0,0,0
:endlayer
layer: 13
0,0,0,0,0,0,0,0,0,0,0,0,0,0,0,0,0,0
0,64,0,0,0,0,0,0,64,63,0,0,0,0,0,0,62,0
0,0,0,0,0,0,0,0,0,0,0,0,0,0,0,0,0,0
0,0,0,0,0,0,0,0,0,0,0,0,0,0,0,0,0,0
0,0,0,0,0,0,0,0,0,0,0,0,0,0,0,0,0,0
0,0,0,0,0,0,0,0,0,0,0,0,0,0,0,0,0,0
0,0,0,0,0,0,0,0,0,0,0,0,0,0,0,0,0,0
0,0,0,0,0,0,0,0,0,0,0,0,0,0,0,0,0,0
0,64,0,0,0,0,0,0,63,63,0,0,0,0,0,0,63,0
0,62,0,0,0,0,0,0,0,63,0,0,0,0,0,0,64,0
0,0,0,0,0,0,0,0,0,0,0,0,0,0,0,0,0,0
0,0,0,0,0,0,0,0,0,0,0,0,0,0,0,0,0,0
0,0,0,0,0,0,0,0,0,0,0,0,0,0,0,0,0,0
0,0,0,0,0,0,0,0,0,0,0,0,0,0,0,0,0,0
0,0,0,0,0,0,0,0,0,0,0,0,0,0,0,0,0,0
0,0,0,0,0,0,0,0,0,0,0,0,0,0,0,0,0,0
0,0,0,0,0,0,0,0,62,63,0,0,0,0,0,0,64,0
0,0,0,0,0,0,0,0,0,0,0,0,0,0,0,0,0,0
:endlayer
layer: 14
0,0,0,0,0,0,0,0,0,0,0,0,0,0,0,0,0,0
0,64,0,0,0,0,0,0,64,64,0,0,0,0,0,0,63,0
0,0,0,0,0,0,0,0,0,0,0,0,0,0,0,0,0,0
0,0,0,0,0,0,0,0,0,0,0,0,0,0,0,0,0,0
0,0,0,0,0,0,0,0,0,0,0,0,0,0,0,0,0,0
0,0,0,0,0,0,0,0,0,0,0,0,0,0,0,0,0,0
0,0,0,0,0,0,0,0,0,0,0,0,0,0,0,0,0,0
0,0,0,0,0,0,0,0,0,0,0,0,0,0,0,0,0,0
0,62,0,0,0,0,0,0,64,62,0,0,0,0,0,0,64,0
0,65,0,0,0,0,0,0,0,62,0,0,0,0,0,0,64,0
0,0,0,0,0,0,0,0,0,0,0,0,0,0,0,0,0,0
0,0,0,0,0,0,0,0,0,0,0,0,0,0,0,0,0,0
0,0,0,0,0,0,0,0,0,0,0,0,0,0,0,0,0,0
0,0,0,0,0,0,0,0,0,0,0,0,0,0,0,0,0,0
0,0,0,0,0,0,0,0,0,0,0,0,0,0,0,0,0,0
0,0,0,0,0,0,0,0,0,0,0,0,0,0,0,0,0,0
0,0,0,0,0,0,0,0,63,63,0,0,0,0,0,0,64,0
0,0,0,0,0,0,0,0,0,0,0,0,0,0,0,0,0,0
:endlayer
layer: 15
0,0,0,0,0,0,0,0,0,0,0,0,0,0,0,0,0,0
0,64,0,0,0,0,0,0,64,64,0,0,0,0,0,0,63,0
0,0,0,0,0,0,0,0,0,0,0,0,0,0,0,0,0,0
0,0,0,0,0,0,0,0,0,0,0,0,0,0,0,0,0,0
0,0,0,0,0,0,0,0,0,0,0,0,0,0,0,0,0,0
0,0,0,0,0,0,0,0,0,0,0,0,0,0,0,0,0,0
0,0,0,0,0,0,0,0,0,0,0,0,0,0,0,0,0,0
0,0,0,0,0,0,0,0,0,0,0,0,0,0,0,0,0,0
0,62,0,0,0,0,0,0,64,64,0,0,0,0,0,0,64,0
0,0,0,0,0,0,0,0,0,64,0,0,0,0,0,0,63,0
0,0,0,0,0,0,0,0,0,0,0,0,0,0,0,0,0,0
0,0,0,0,0,0,0,0,0,0,0,0,0,0,0,0,0,0
0,0,0,0,0,0,0,0,0,0,0,0,0,0,0,0,0,0
0,0,0,0,0,0,0,0,0,0,0,0,0,0,0,0,0,0
0,0,0,0,0,0,0,0,0,0,0,0,0,0,0,0,0,0
0,0,0,0,0,0,0,0,0,0,0,0,0,0,0,0,0,0
0,0,0,0,0,0,0,0,0,62,0,0,0,0,0,0,63,0
0,0,0,0,0,0,0,0,0,0,0,0,0,0,0,0,0,0
:endlayer
layer: 16
0,0,0,0,0,0,0,0,0,0,0,0,0,0,0,0,0,0
0,64,0,0,0,0,0,0,63,63,0,0,0,0,0,0,64,0
0,0,0,0,0,0,0,0,0,0,0,0,0,0,0,0,0,0
0,0,0,0,0,0,0,0,0,0,0,0,0,0,0,0,0,0
0,0,0,0,0,0,0,0,0,0,0,0,0,0,0,0,0,0
0,0,0,0,0,0,0,0,0,0,0,0,0,0,0,0,0,0
0,0,0,0,0,0,0,0,0,0,0,0,0,0,0,0,0,0
0,0,0,0,0,0,0,0,0,0,0,0,0,0,0,0,0,0
0,64,0,0,0,0,0,0,64,64,0,0,0,0,0,0,63,0
0,0,0,0,0,0,0,0,0,64,0,0,0,0,0,0,63,0
0,0,0,0,0,0,0,0,0,0,0,0,0,0,0,0,0,0
0,0,0,0,0,0,0,0,0,0,0,0,0,0,0,0,0,0
0,0,0,0,0,0,0,0,0,0,0,0,0,0,0,0,0,0
0,0,0,0,0,0,0,0,0,0,0,0,0,0,0,0,0,0
0,0,0,0,0,0,0,0,0,0,0,0,0,0,0,0,0,0
0,0,0,0,0,0,0,0,0,0,0,0,0,0,0,0,0,0
0,0,0,0,0,0,0,0,0,62,0,0,0,0,0,0,62,0
0,0,0,0,0,0,0,0,0,0,0,0,0,0,0,0,0,0
:endlayer
layer: 17
0,0,0,0,0,0,0,0,0,0,0,0,0,0,0,0,0,0
0,63,74,0,0,0,0,73,64,65,74,0,0,0,0,73,64,0
0,71,0,0,0,0,0,0,71,71,0,0,0,0,0,0,71,0
0,0,0,0,0,0,0,0,0,0,0,0,0,0,0,0,0,0
0,0,0,0,0,0,0,0,0,0,0,0,0,0,0,0,0,0
0,0,0,0,0,0,0,0,0,0,0,0,0,0,0,0,0,0
0,0,0,0,0,0,0,0,0,0,0,0,0,0,0,0,0,0
0,72,0,0,0,0,0,0,72,72,0,0,0,0,0,0,72,0
0,64,74,0,0,0,0,73,64,64,74,0,0,0,0,73,62,0
0,0,0,0,0,0,0,0,0,64,74,0,0,0,0,73,63,0
0,0,0,0,0,0,0,0,0,71,0,0,0,0,0,0,71,0
0,0,0,0,0,0,0,0,0,0,0,0,0,0,0,0,0,0
0,0,0,0,0,0,0,0,0,0,0,0,0,0,0,0,0,0
0,0,0,0,0,0,0,0,0,0,0,0,0,0,0,0,0,0
0,0,0,0,0,0,0,0,0,0,0,0,0,0,0,0,0,0
0,0,0,0,0,0,0,0,0,72,0,0,0,0,0,0,72,0
0,0,0,0,0,0,0,0,0,62,74,0,0,0,0,73,65,0
0,0,0,0,0,0,0,0,0,0,0,0,0,0,0,0,0,0
:endlayer
layer: 18
0,0,0,0,0,0,0,0,0,0,0,0,0,0,0,0,0,0
0,63,62,74,0,0,73,64,65,64,64,74,0,0,73,64,64,0
0,62,0,0,0,0,0,0,64,64,0,0,0,0,0,0,64,0
0,71,0,0,0,0,0,0,71,71,0,0,0,0,0,0,71,0
0,0,0,0,0,0,0,0,0,0,0,0,0,0,0,0,0,0
0,0,0,0,0,0,0,0,0,0,0,0,0,0,0,0,0,0
0,72,0,0,0,0,0,0,72,72,0,0,0,0,0,0,72,0
0,64,0,0,0,0,0,0,63,62,0,0,0,0,0,0,63,0
0,63,62,74,0,0,73,64,65,63,63,74,0,0,73,63,62,0
0,0,0,0,0,0,0,0,0,62,64,74,0,0,73,62,63,0
0,0,0,0,0,0,0,0,0,63,0,0,0,0,0,0,64,0
0,0,0,0,0,0,0,0,0,71,0,0,0,0,0,0,71,0
0,0,0,0,0,0,0,0,0,0,0,0,0,0,0,0,0,0
0,0,0,0,0,0,0,0,0,0,0,0,0,0,0,0,0,0
0,0,0,0,0,0,0,0,0,72,0,0,0,0,0,0,72,0
0,0,0,0,0,0,0,0,0,65,0,0,0,0,0,0,62,0
0,0,0,0,0,0,0,0,0,63,64,74,0,0,73,64,64,0
0,0,0,0,0,0,0,0,0,0,0,0,0,0,0,0,0,0
:endlayer
layer: 19
0,0,0,0,0,0,0,0,0,0,0,0,0,0,0,0,0,0
0,65,75,19,0,19,19,19,65,75,0,0,0,0,0,19,65,0
0,0,0,0,0,0,0,0,19,19,0,0,0,0,0,0,0,0
0,19,0,0,0,0,0,0,0,0,0,0,0,0,0,0,0,0
0,0,0,0,0,0,0,0,0,0,0,0,0,0,0,0,19,0
0,0,0,0,0,0,0,0,19,0,0,0,0,0,0,0,0,0
0,19,0,0,0,0,0,0,0,19,0,0,0,0,0,0,0,0
0,0,0,0,0,0,0,0,19,0,0,0,0,0,0,0,75,0
0,65,0,19,19,0,75,19,64,65,19,19,75,75,0,19,65,0
0,0,0,0,0,0,0,0,0,65,19,19,0,0,0,19,65,0
0,0,0,0,0,0,0,0,0,0,0,0,0,0,0,0,0,0
0,0,0,0,0,0,0,0,0,0,0,0,0,0,0,0,0,0
0,0,0,0,0,0,0,0,0,19,0,0,0,0,0,0,0,0
0,0,0,0,0,0,0,0,0,19,0,0,0,0,0,0,0,0
0,0,0,0,0,0,0,0,0,75,0,0,0,0,0,0,19,0
0,0,0,0,0,0,0,0,0,0,0,0,0,0,0,0,75,0
0,0,0,0,0,0,0,0,0,65,0,0,0,0,0,0,65,0
0,0,0,0,0,0,0,0,0,0,0,0,0,0,0,0,0,0
:endlayer
layer: 20
0,0,0,0,0,0,0,0,0,0,0,0,0,0,0,0,0,0
0,65,0,0,0,0,0,0,65,0,0,0,0,0,0,0,65,0
0,0,0,0,0,0,0,0,0,0,0,0,0,0,0,0,0,0
0,0,0,0,0,0,0,0,0,0,0,0,0,0,0,0,0,0
0,0,0,0,0,0,0,0,0,0,0,0,0,0,0,0,0,0
0,0,0,0,0,0,0,0,0,0,0,0,0,0,0,0,0,0
0,0,0,0,0,0,0,0,0,0,0,0,0,0,0,0,0,0
0,0,0,0,0,0,0,0,0,0,0,0,0,0,0,0,0,0
0,65,0,0,0,0,0,0,0,65,0,0,0,0,0,0,65,0
0,0,0,0,0,0,0,0,0,65,0,0,0,0,0,0,65,0
0,0,0,0,0,0,0,0,0,0,0,0,0,0,0,0,0,0
0,0,0,0,0,0,0,0,0,0,0,0,0,0,0,0,0,0
0,0,0,0,0,0,0,0,0,0,0,0,0,0,0,0,0,0
0,0,0,0,0,0,0,0,0,0,0,0,0,0,0,0,0,0
0,0,0,0,0,0,0,0,0,0,0,0,0,0,0,0,0,0
0,0,0,0,0,0,0,0,0,0,0,0,0,0,0,0,0,0
0,0,0,0,0,0,0,0,0,65,0,0,0,0,0,0,65,0
0,0,0,0,0,0,0,0,0,0,0,0,0,0,0,0,0,0
:endlayer
layer: 21
0,0,0,0,0,0,0,0,0,0,0,0,0,0,0,0,0,0
0,65,0,0,0,0,0,0,65,0,0,0,0,0,0,0,65,0
0,0,0,0,0,0,0,0,0,0,0,0,0,0,0,0,0,0
0,0,0,0,0,0,0,0,0,0,0,0,0,0,0,0,0,0
0,0,0,0,0,0,0,0,0,0,0,0,0,0,0,0,0,0
0,0,0,0,0,0,0,0,0,0,0,0,0,0,0,0,0,0
0,0,0,0,0,0,0,0,0,0,0,0,0,0,0,0,0,0
0,0,0,0,0,0,0,0,0,0,0,0,0,0,0,0,0,0
0,65,0,0,0,0,0,0,0,65,0,0,0,0,0,0,65,0
0,0,0,0,0,0,0,0,0,65,0,0,0,0,0,0,0,0
0,0,0,0,0,0,0,0,0,0,0,0,0,0,0,0,0,0
0,0,0,0,0,0,0,0,0,0,0,0,0,0,0,0,0,0
0,0,0,0,0,0,0,0,0,0,0,0,0,0,0,0,0,0
0,0,0,0,0,0,0,0,0,0,0,0,0,0,0,0,0,0
0,0,0,0,0,0,0,0,0,0,0,0,0,0,0,0,0,0
0,0,0,0,0,0,0,0,0,0,0,0,0,0,0,0,0,0
0,0,0,0,0,0,0,0,0,65,0,0,0,0,0,0,65,0
0,0,0,0,0,0,0,0,0,0,0,0,0,0,0,0,0,0
:endlayer
layer: 22
0,0,0,0,0,0,0,0,0,0,0,0,0,0,0,0,0,0
0,65,0,0,0,0,0,0,65,0,0,0,0,0,0,0,65,0
0,0,0,0,0,0,0,0,0,0,0,0,0,0,0,0,0,0
0,0,0,0,0,0,0,0,0,0,0,0,0,0,0,0,0,0
0,0,0,0,0,0,0,0,0,0,0,0,0,0,0,0,0,0
0,0,0,0,0,0,0,0,0,0,0,0,0,0,0,0,0,0
0,0,0,0,0,0,0,0,0,0,0,0,0,0,0,0,0,0
0,0,0,0,0,0,0,0,0,0,0,0,0,0,0,0,0,0
0,65,0,0,0,0,0,0,0,65,0,0,0,0,0,0,65,0
0,0,0,0,0,0,0,0,0,65,0,0,0,0,0,0,0,0
0,0,0,0,0,0,0,0,0,0,0,0,0,0,0,0,0,0
0,0,0,0,0,0,0,0,0,0,0,0,0,0,0,0,0,0
0,0,0,0,0,0,0,0,0,0,0,0,0,0,0,0,0,0
0,0,0,0,0,0,0,0,0,0,0,0,0,0,0,0,0,0
0,0,0,0,0,0,0,0,0,0,0,0,0,0,0,0,0,0
0,0,0,0,0,0,0,0,0,0,0,0,0,0,0,0,0,0
0,0,0,0,0,0,0,0,0,65,0,0,0,0,0,0,65,0
0,0,0,0,0,0,0,0,0,0,0,0,0,0,0,0,0,0
:endlayer
layer: 23
0,0,0,0,0,0,0,0,0,0,0,0,0,0,0,0,0,0
0,65,0,0,0,0,0,0,65,0,0,0,0,0,0,0,65,0
0,0,0,0,0,0,0,0,0,0,0,0,0,0,0,0,0,0
0,0,0,0,0,0,0,0,0,0,0,0,0,0,0,0,0,0
0,0,0,0,0,0,0,0,0,0,0,0,0,0,0,0,0,0
0,0,0,0,0,0,0,0,0,0,0,0,0,0,0,0,0,0
0,0,0,0,0,0,0,0,0,0,0,0,0,0,0,0,0,0
0,72,0,0,0,0,0,0,0,0,0,0,0,0,0,0,0,0
0,65,74,0,0,0,0,0,73,65,0,0,0,0,0,0,65,0
0,71,0,0,0,0,0,0,0,65,0,0,0,0,0,0,0,0
0,0,0,0,0,0,0,0,0,71,0,0,0,0,0,0,0,0
0,0,0,0,0,0,0,0,0,0,0,0,0,0,0,0,0,0
0,0,0,0,0,0,0,0,0,0,0,0,0,0,0,0,0,0
0,0,0,0,0,0,0,0,0,0,0,0,0,0,0,0,0,0
0,0,0,0,0,0,0,0,0,72,0,0,0,0,0,0,0,0
0,0,0,0,0,0,0,0,0,65,0,0,0,0,0,0,0,0
0,0,0,0,0,0,0,0,73,65,74,0,0,0,0,73,65,0
0,0,0,0,0,0,0,0,0,0,0,0,0,0,0,0,0,0
:endlayer
layer: 24
0,0,0,0,0,0,0,0,0,0,0,0,0,0,0,0,0,0
0,65,74,0,0,0,0,73,65,74,0,0,0,0,0,73,65,0
0,71,0,0,0,0,0,0,71,0,0,0,0,0,0,0,71,0
0,0,0,0,0,0,0,0,0,0,0,0,0,0,0,0,0,0
0,0,0,0,0,0,0,0,0,0,0,0,0,0,0,0,0,0
0,0,0,0,0,0,0,0,0,0,0,0,0,0,0,0,0,0
0,0,0,0,0,0,0,0,0,0,0,0,0,0,0,0,0,0
0,0,0,0,0,0,0,0,72,72,74,0,0,0,0,0,72,0
0,65,65,65,65,65,65,65,65,65,74,0,0,0,0,73,65,0
0,0,0,0,0,0,0,0,0,65,74,0,0,0,0,0,71,0
0,0,0,0,0,0,0,0,0,65,0,0,0,0,0,0,0,0
0,0,0,0,0,0,0,0,0,65,0,0,0,0,0,0,0,0
0,0,0,0,0,0,0,0,0,65,0,0,0,0,0,0,0,0
0,0,0,0,0,0,0,0,0,65,0,0,0,0,0,0,0,0
0,0,0,0,0,0,0,0,0,65,0,0,0,0,0,0,0,0
0,0,0,0,0,0,0,0,0,65,0,0,0,0,0,0,72,0
0,0,0,0,0,0,0,0,0,65,0,0,0,0,0,0,65,0
0,0,0,0,0,0,0,0,0,0,0,0,0,0,0,0,0,0
:endlayer
layer: 25
0,0,0,0,0,0,0,0,0,0,0,0,0,0,0,0,0,0
0,65,0,0,0,0,0,0,65,0,0,0,0,0,0,0,65,0
0,0,0,0,0,0,0,0,0,0,0,0,0,0,0,0,0,0
0,0,0,0,0,0,0,0,0,0,0,0,0,0,0,0,0,0
0,0,0,0,0,0,0,0,0,0,0,0,0,0,0,0,0,0
0,0,0,0,0,0,0,0,0,0,0,0,0,0,0,0,0,0
0,0,0,0,0,0,0,0,0,0,0,0,0,0,0,0,0,0
0,0,0,0,0,0,0,0,0,0,0,0,0,0,0,0,0,0
0,65,0,0,0,0,0,0,65,65,0,0,0,0,0,0,0,0
0,0,0,0,0,0,0,0,0,65,0,0,0,0,0,0,0,0
0,0,0,0,0,0,0,0,0,0,0,0,0,0,0,0,0,0
0,0,0,0,0,0,0,0,0,0,0,0,0,0,0,0,0,0
0,0,0,0,0,0,0,0,0,0,0,0,0,0,0,0,0,0
0,0,0,0,0,0,0,0,0,0,0,0,0,0,0,0,0,0
0,0,0,0,0,0,0,0,0,0,0,0,0,0,0,0,0,0
0,0,0,0,0,0,0,0,0,0,0,0,0,0,0,0,0,0
0,0,0,0,0,0,0,0,0,65,0,0,0,0,0,0,65,0
0,0,0,0,0,0,0,0,0,0,0,0,0,0,0,0,0,0
:endlayer
layer: 26
0,0,0,0,0,0,0,0,0,0,0,0,0,0,0,0,0,0
0,65,0,0,0,0,0,0,0,0,0,0,0,0,0,0,65,0
0,0,0,0,0,0,0,0,0,0,0,0,0,0,0,0,0,0
0,0,0,0,0,0,0,0,0,0,0,0,0,0,0,0,0,0
0,0,0,0,0,0,0,0,0,0,0,0,0,0,0,0,0,0
0,0,0,0,0,0,0,0,0,0,0,0,0,0,0,0,0,0
0,0,0,0,0,0,0,0,0,0,0,0,0,0,0,0,0,0
0,0,0,0,0,0,0,0,0,0,0,0,0,0,0,0,0,0
0,65,0,0,0,0,0,0,0,65,0,0,0,0,0,0,0,0
0,0,0,0,0,0,0,0,0,0,0,0,0,0,0,0,0,0
0,0,0,0,0,0,0,0,0,0,0,0,0,0,0,0,0,0
0,0,0,0,0,0,0,0,0,0,0,0,0,0,0,0,0,0
0,0,0,0,0,0,0,0,0,0,0,0,0,0,0,0,0,0
0,0,0,0,0,0,0,0,0,0,0,0,0,0,0,0,0,0
0,0,0,0,0,0,0,0,0,0,0,0,0,0,0,0,0,0
0,0,0,0,0,0,0,0,0,0,0,0,0,0,0,0,0,0
0,0,0,0,0,0,0,0,0,0,0,0,0,0,0,0,0,0
0,0,0,0,0,0,0,0,0,0,0,0,0,0,0,0,0,0
:endlayer
layer: 27
0,0,0,0,0,0,0,0,0,0,0,0,0,0,0,0,0,0
0,65,0,0,0,0,0,0,0,0,0,0,0,0,0,0,65,0
0,0,0,0,0,0,0,0,0,0,0,0,0,0,0,0,0,0
0,0,0,0,0,0,0,0,0,0,0,0,0,0,0,0,0,0
0,0,0,0,0,0,0,0,0,0,0,0,0,0,0,0,0,0
0,0,0,0,0,0,0,0,0,0,0,0,0,0,0,0,0,0
0,0,0,0,0,0,0,0,0,0,0,0,0,0,0,0,0,0
0,0,0,0,0,0,0,0,0,0,0,0,0,0,0,0,0,0
0,0,0,0,0,0,0,0,0,65,0,0,0,0,0,0,0,0
0,0,0,0,0,0,0,0,0,0,0,0,0,0,0,0,0,0
0,0,0,0,0,0,0,0,0,0,0,0,0,0,0,0,0,0
0,0,0,0,0,0,0,0,0,0,0,0,0,0,0,0,0,0
0,0,0,0,0,0,0,0,0,0,0,0,0,0,0,0,0,0
0,0,0,0,0,0,0,0,0,0,0,0,0,0,0,0,0,0
0,0,0,0,0,0,0,0,0,0,0,0,0,0,0,0,0,0
0,0,0,0,0,0,0,0,0,0,0,0,0,0,0,0,0,0
0,0,0,0,0,0,0,0,0,0,0,0,0,0,0,0,0,0
0,0,0,0,0,0,0,0,0,0,0,0,0,0,0,0,0,0
:endlayer
layer: 28
0,0,0,0,0,0,0,0,0,0,0,0,0,0,0,0,0,0
0,65,0,0,0,0,0,0,0,0,0,0,0,0,0,0,0,0
0,65,0,0,0,0,0,0,0,0,0,0,0,0,0,0,0,0
0,0,0,0,0,0,0,0,0,0,0,0,0,0,0,0,0,0
0,0,0,0,0,0,0,0,0,0,0,0,0,0,0,0,0,0
0,0,0,0,0,0,0,0,0,0,0,0,0,0,0,0,0,0
0,0,0,0,0,0,0,0,0,0,0,0,0,0,0,0,0,0
0,0,0,0,0,0,0,0,0,0,0,0,0,0,0,0,0,0
0,0,0,0,0,0,0,0,0,0,0,0,0,0,0,0,0,0
0,0,0,0,0,0,0,0,0,0,0,0,0,0,0,0,0,0
0,0,0,0,0,0,0,0,0,0,0,0,0,0,0,0,0,0
0,0,0,0,0,0,0,0,0,0,0,0,0,0,0,0,0,0
0,0,0,0,0,0,0,0,0,0,0,0,0,0,0,0,0,0
0,0,0,0,0,0,0,0,0,0,0,0,0,0,0,0,0,0
0,0,0,0,0,0,0,0,0,0,0,0,0,0,0,0,0,0
0,0,0,0,0,0,0,0,0,0,0,0,0,0,0,0,0,0
0,0,0,0,0,0,0,0,0,0,0,0,0,0,0,0,0,0
0,0,0,0,0,0,0,0,0,0,0,0,0,0,0,0,0,0
:endlayer

#### RULES ####
rule:
plugin=vanillaBlocks
number=1
data:
JSON:{blockState:{blockName:"minecraft:stone",properties:{variant:"stone"}}}
:enddata
:endrule

rule:
plugin=vanillaBlocks
number=2
data:
JSON:{blockState:{blockName:"minecraft:cobblestone"}}
:enddata
:endrule

rule:
plugin=vanillaBlocks
number=3
data:
JSON:{blockState:{blockName:"minecraft:netherrack"}}
:enddata
:endrule

rule:
plugin=inventory
number=4
data:
JSON:{blockState:{blockName:"minecraft:chest",properties:{facing:"east"}},lootLevel:0,teData:{ForgeData:{},Items:[{Slot:0b,id:"minecraft:iron_ingot",Count:2b,Damage:0s},{Slot:1b,id:"minecraft:bone",Count:1b,Damage:0s},{Slot:6b,id:"minecraft:bone",Count:2b,Damage:0s},{Slot:7b,id:"minecraft:bone",Count:1b,Damage:0s},{Slot:10b,id:"minecraft:gunpowder",Count:2b,Damage:0s},{Slot:14b,id:"minecraft:iron_ingot",Count:1b,Damage:0s},{Slot:16b,id:"minecraft:bone",Count:1b,Damage:0s},{Slot:17b,id:"minecraft:bone",Count:1b,Damage:0s},{Slot:23b,id:"minecraft:bread",Count:2b,Damage:0s},{Slot:24b,id:"minecraft:bucket",Count:1b,Damage:0s},{Slot:26b,id:"minecraft:bone",Count:2b,Damage:0s}],id:"minecraft:chest",Lock:""},inventoryData:{length:11,inventoryContents:[{id:"minecraft:iron_ingot",Count:2b,slot:0,Damage:0s},{id:"minecraft:bone",Count:1b,slot:1,Damage:0s},{id:"minecraft:bone",Count:2b,slot:2,Damage:0s},{id:"minecraft:bone",Count:1b,slot:3,Damage:0s},{id:"minecraft:gunpowder",Count:2b,slot:4,Damage:0s},{id:"minecraft:iron_ingot",Count:1b,slot:5,Damage:0s},{id:"minecraft:bone",Count:1b,slot:6,Damage:0s},{id:"minecraft:bone",Count:1b,slot:7,Damage:0s},{id:"minecraft:bread",Count:2b,slot:8,Damage:0s},{id:"minecraft:bucket",Count:1b,slot:9,Damage:0s},{id:"minecraft:bone",Count:2b,slot:10,Damage:0s}]},legacyFeatures:1b}
:enddata
:endrule

rule:
plugin=vanillaBlocks
number=5
data:
JSON:{blockState:{blockName:"minecraft:bookshelf"}}
:enddata
:endrule

rule:
plugin=inventory
number=6
data:
JSON:{blockState:{blockName:"minecraft:chest",properties:{facing:"south"}},lootLevel:0,teData:{ForgeData:{},Items:[{Slot:3b,id:"minecraft:brown_mushroom",Count:6b,Damage:0s},{Slot:10b,id:"minecraft:rotten_flesh",Count:9b,Damage:0s},{Slot:15b,id:"minecraft:poisonous_potato",Count:9b,Damage:0s},{Slot:26b,id:"ancientwarfarenpc:coin",Count:7b,tag:{metal:"silver"},Damage:0s}],id:"minecraft:chest",Lock:""},inventoryData:{length:4,inventoryContents:[{id:"minecraft:brown_mushroom",Count:6b,slot:0,Damage:0s},{id:"minecraft:rotten_flesh",Count:9b,slot:1,Damage:0s},{id:"minecraft:poisonous_potato",Count:9b,slot:2,Damage:0s},{id:"ancientwarfarenpc:coin",Count:7b,tag:{metal:"silver"},slot:3,Damage:0s}]},legacyFeatures:1b}
:enddata
:endrule

rule:
plugin=blockTile
number=7
data:
JSON:{blockState:{blockName:"ancientwarfarestructure:advanced_spawner",properties:{transparent:"true"}},teData:{id:"ancientwarfarestructure:advanced_spawner_tile",spawnerSettings:{minDelay:0,spawnDelay:0,lightSensitive:0b,spawnGroups:[{settingsList:[{remainingSpawnCount:1,hostile:1b,forced:1b,customTag:{factionName:"orc"},maxToSpawn:1,entityId:"ancientwarfarenpc:faction.soldier",minToSpawn:1}],groupWeight:1}],playerRange:4,respondToRedstone:0b,inventory:{Size:9,Items:[]},spawnRange:0,transparent:1b,maxDelay:0,xpToDrop:0,mobRange:0,debugMode:0b,maxNearbyMonsters:0}}}
:enddata
:endrule

rule:
plugin=vanillaBlocks
number=8
data:
JSON:{blockState:{blockName:"minecraft:stone_slab",properties:{half:"top",variant:"cobblestone"}}}
:enddata
:endrule

rule:
plugin=vanillaBlocks
number=9
data:
JSON:{blockState:{blockName:"minecraft:cauldron",properties:{level:"3"}}}
:enddata
:endrule

rule:
plugin=blockTile
number=10
data:
JSON:{blockState:{blockName:"ancientwarfarestructure:advanced_spawner",properties:{transparent:"true"}},teData:{id:"ancientwarfarestructure:advanced_spawner_tile",spawnerSettings:{minDelay:0,spawnDelay:0,lightSensitive:0b,spawnGroups:[{settingsList:[{remainingSpawnCount:1,hostile:1b,forced:1b,customTag:{factionName:"orc"},maxToSpawn:1,entityId:"ancientwarfarenpc:faction.soldier",minToSpawn:1}],groupWeight:1}],playerRange:3,respondToRedstone:0b,inventory:{Size:9,Items:[]},spawnRange:0,transparent:1b,maxDelay:0,xpToDrop:0,mobRange:0,debugMode:0b,maxNearbyMonsters:0}}}
:enddata
:endrule

rule:
plugin=vanillaBlocks
number=11
data:
JSON:{blockState:{blockName:"minecraft:mossy_cobblestone"}}
:enddata
:endrule

rule:
plugin=inventory
number=12
data:
JSON:{blockState:{blockName:"minecraft:chest",properties:{facing:"south"}},lootLevel:0,teData:{ForgeData:{},Items:[{Slot:5b,id:"ancientwarfarenpc:coin",Count:7b,tag:{metal:"silver"},Damage:0s},{Slot:10b,id:"minecraft:brown_mushroom",Count:12b,Damage:0s},{Slot:13b,id:"minecraft:rotten_flesh",Count:18b,Damage:0s},{Slot:15b,id:"minecraft:poisonous_potato",Count:19b,Damage:0s}],id:"minecraft:chest",Lock:""},inventoryData:{length:4,inventoryContents:[{id:"ancientwarfarenpc:coin",Count:7b,tag:{metal:"silver"},slot:0,Damage:0s},{id:"minecraft:brown_mushroom",Count:12b,slot:1,Damage:0s},{id:"minecraft:rotten_flesh",Count:18b,slot:2,Damage:0s},{id:"minecraft:poisonous_potato",Count:19b,slot:3,Damage:0s}]},legacyFeatures:1b}
:enddata
:endrule

rule:
plugin=vanillaBlocks
number=13
data:
JSON:{blockState:{blockName:"minecraft:stone_stairs",properties:{half:"bottom",shape:"straight",facing:"east"}}}
:enddata
:endrule

rule:
plugin=blockTile
number=14
data:
JSON:{blockState:{blockName:"ancientwarfarestructure:advanced_spawner",properties:{transparent:"true"}},teData:{id:"ancientwarfarestructure:advanced_spawner_tile",spawnerSettings:{minDelay:0,spawnDelay:0,lightSensitive:0b,spawnGroups:[{settingsList:[{remainingSpawnCount:1,hostile:1b,forced:1b,customTag:{factionName:"orc"},maxToSpawn:1,entityId:"ancientwarfarenpc:faction.soldier",minToSpawn:1}],groupWeight:1}],playerRange:3,respondToRedstone:0b,inventory:{Size:9,Items:[]},spawnRange:0,transparent:1b,maxDelay:0,xpToDrop:0,mobRange:0,debugMode:0b,maxNearbyMonsters:0}}}
:enddata
:endrule

rule:
plugin=vanillaSkull
number=15
data:
JSON:{blockState:{blockName:"minecraft:skull",properties:{nodrop:"false",facing:"up"}},skullRotation:0,teData:{Rot:12b,id:"minecraft:skull",SkullType:0b}}
:enddata
:endrule

rule:
plugin=vanillaSkull
number=16
data:
JSON:{blockState:{blockName:"minecraft:skull",properties:{nodrop:"false",facing:"up"}},skullRotation:0,teData:{Rot:12b,id:"minecraft:skull",SkullType:0b}}
:enddata
:endrule

rule:
plugin=blockTile
number=17
data:
JSON:{blockState:{blockName:"ancientwarfarestructure:advanced_spawner",properties:{transparent:"true"}},teData:{id:"ancientwarfarestructure:advanced_spawner_tile",spawnerSettings:{minDelay:0,spawnDelay:0,lightSensitive:0b,spawnGroups:[{settingsList:[{remainingSpawnCount:1,hostile:1b,forced:1b,customTag:{factionName:"orc"},maxToSpawn:1,entityId:"ancientwarfarenpc:faction.soldier",minToSpawn:1}],groupWeight:1}],playerRange:3,respondToRedstone:0b,inventory:{Size:9,Items:[]},spawnRange:0,transparent:1b,maxDelay:0,xpToDrop:0,mobRange:0,debugMode:0b,maxNearbyMonsters:0}}}
:enddata
:endrule

rule:
plugin=blockTile
number=18
data:
JSON:{blockState:{blockName:"ancientwarfarestructure:advanced_spawner",properties:{transparent:"true"}},teData:{id:"ancientwarfarestructure:advanced_spawner_tile",spawnerSettings:{minDelay:0,spawnDelay:0,lightSensitive:0b,spawnGroups:[{settingsList:[{remainingSpawnCount:1,hostile:1b,forced:1b,customTag:{factionName:"orc"},maxToSpawn:1,entityId:"ancientwarfarenpc:faction.soldier",minToSpawn:1}],groupWeight:1}],playerRange:6,respondToRedstone:0b,inventory:{Size:9,Items:[]},spawnRange:0,transparent:1b,maxDelay:0,xpToDrop:0,mobRange:0,debugMode:0b,maxNearbyMonsters:0}}}
:enddata
:endrule

rule:
plugin=vanillaBlocks
number=19
data:
JSON:{blockState:{blockName:"minecraft:stone_slab",properties:{half:"bottom",variant:"cobblestone"}}}
:enddata
:endrule

rule:
plugin=blockTile
number=20
data:
JSON:{blockState:{blockName:"ancientwarfarestructure:advanced_spawner",properties:{transparent:"true"}},teData:{id:"ancientwarfarestructure:advanced_spawner_tile",spawnerSettings:{minDelay:0,spawnDelay:0,lightSensitive:0b,spawnGroups:[{settingsList:[{remainingSpawnCount:1,hostile:1b,forced:1b,customTag:{factionName:"orc"},maxToSpawn:1,entityId:"ancientwarfarenpc:faction.priest",minToSpawn:1}],groupWeight:1}],playerRange:6,respondToRedstone:0b,inventory:{Size:9,Items:[]},spawnRange:0,transparent:1b,maxDelay:0,xpToDrop:0,mobRange:0,debugMode:0b,maxNearbyMonsters:0}}}
:enddata
:endrule

rule:
plugin=vanillaBlocks
number=21
data:
JSON:{blockState:{blockName:"minecraft:wooden_slab",properties:{half:"bottom",variant:"oak"}}}
:enddata
:endrule

rule:
plugin=vanillaBlocks
number=22
data:
JSON:{blockState:{blockName:"minecraft:fire",properties:{east:"false",south:"false",north:"false",west:"false",up:"false",age:"15"}}}
:enddata
:endrule

rule:
plugin=vanillaSkull
number=23
data:
JSON:{blockState:{blockName:"minecraft:skull",properties:{nodrop:"false",facing:"up"}},skullRotation:0,teData:{Rot:12b,id:"minecraft:skull",SkullType:0b}}
:enddata
:endrule

rule:
plugin=vanillaBlocks
number=24
data:
JSON:{blockState:{blockName:"minecraft:stone_stairs",properties:{half:"bottom",shape:"straight",facing:"south"}}}
:enddata
:endrule

rule:
plugin=vanillaBlocks
number=25
data:
JSON:{blockState:{blockName:"minecraft:redstone_torch",properties:{facing:"north"}}}
:enddata
:endrule

rule:
plugin=vanillaSkull
number=26
data:
JSON:{blockState:{blockName:"minecraft:skull",properties:{nodrop:"false",facing:"up"}},skullRotation:0,teData:{Rot:12b,id:"minecraft:skull",SkullType:0b}}
:enddata
:endrule

rule:
plugin=inventory
number=27
data:
JSON:{blockState:{blockName:"minecraft:chest",properties:{facing:"east"}},lootLevel:0,teData:{ForgeData:{},Items:[{Slot:3b,id:"minecraft:rotten_flesh",Count:9b,Damage:0s},{Slot:10b,id:"minecraft:brown_mushroom",Count:6b,Damage:0s},{Slot:13b,id:"ancientwarfarenpc:coin",Count:5b,tag:{metal:"gold"},Damage:0s},{Slot:25b,id:"minecraft:poisonous_potato",Count:9b,Damage:0s}],id:"minecraft:chest",Lock:""},inventoryData:{length:4,inventoryContents:[{id:"minecraft:rotten_flesh",Count:9b,slot:0,Damage:0s},{id:"minecraft:brown_mushroom",Count:6b,slot:1,Damage:0s},{id:"ancientwarfarenpc:coin",Count:5b,tag:{metal:"gold"},slot:2,Damage:0s},{id:"minecraft:poisonous_potato",Count:9b,slot:3,Damage:0s}]},legacyFeatures:1b}
:enddata
:endrule

rule:
plugin=vanillaBlocks
number=28
data:
JSON:{blockState:{blockName:"minecraft:redstone_torch",properties:{facing:"east"}}}
:enddata
:endrule

rule:
plugin=inventory
number=29
data:
JSON:{blockState:{blockName:"minecraft:brewing_stand",properties:{has_bottle_0:"false",has_bottle_1:"false",has_bottle_2:"false"}},lootLevel:0,teData:{Fuel:0b,Items:[],id:"minecraft:brewing_stand",BrewTime:0s,Lock:""},inventoryData:{length:0,inventoryContents:[]},legacyFeatures:0b}
:enddata
:endrule

rule:
plugin=vanillaBlocks
number=30
data:
JSON:{blockState:{blockName:"minecraft:iron_bars",properties:{east:"false",south:"false",north:"false",west:"false"}}}
:enddata
:endrule

rule:
plugin=vanillaBlocks
number=31
data:
JSON:{blockState:{blockName:"minecraft:obsidian"}}
:enddata
:endrule

rule:
plugin=blockTile
number=32
data:
JSON:{blockState:{blockName:"ancientwarfarestructure:advanced_spawner",properties:{transparent:"true"}},teData:{id:"ancientwarfarestructure:advanced_spawner_tile",spawnerSettings:{minDelay:0,spawnDelay:0,lightSensitive:0b,spawnGroups:[{settingsList:[{remainingSpawnCount:1,hostile:1b,forced:1b,customTag:{factionName:"orc"},maxToSpawn:1,entityId:"ancientwarfarenpc:faction.soldier",minToSpawn:1}],groupWeight:1}],playerRange:3,respondToRedstone:0b,inventory:{Size:9,Items:[]},spawnRange:0,transparent:1b,maxDelay:0,xpToDrop:0,mobRange:0,debugMode:0b,maxNearbyMonsters:0}}}
:enddata
:endrule

rule:
plugin=vanillaBlocks
number=33
data:
JSON:{blockState:{blockName:"minecraft:stone_stairs",properties:{half:"top",shape:"straight",facing:"east"}}}
:enddata
:endrule

rule:
plugin=vanillaBlocks
number=34
data:
JSON:{blockState:{blockName:"minecraft:stone_stairs",properties:{half:"top",shape:"straight",facing:"north"}}}
:enddata
:endrule

rule:
plugin=vanillaBlocks
number=35
data:
JSON:{blockState:{blockName:"minecraft:stone_stairs",properties:{half:"top",shape:"straight",facing:"south"}}}
:enddata
:endrule

rule:
plugin=vanillaBlocks
number=36
data:
JSON:{blockState:{blockName:"minecraft:redstone_torch",properties:{facing:"south"}}}
:enddata
:endrule

rule:
plugin=vanillaBlocks
number=37
data:
JSON:{blockState:{blockName:"minecraft:fence",properties:{east:"false",south:"false",north:"false",west:"false"}}}
:enddata
:endrule

rule:
plugin=vanillaBlocks
number=38
data:
JSON:{blockState:{blockName:"minecraft:nether_brick_fence",properties:{east:"false",south:"false",north:"false",west:"false"}}}
:enddata
:endrule

rule:
plugin=blockTile
number=39
data:
JSON:{blockState:{blockName:"ancientwarfarestructure:advanced_spawner",properties:{transparent:"true"}},teData:{id:"ancientwarfarestructure:advanced_spawner_tile",spawnerSettings:{minDelay:0,spawnDelay:0,lightSensitive:0b,spawnGroups:[{settingsList:[{remainingSpawnCount:1,hostile:1b,forced:1b,customTag:{factionName:"orc"},maxToSpawn:1,entityId:"ancientwarfarenpc:faction.soldier",minToSpawn:1}],groupWeight:1}],playerRange:4,respondToRedstone:0b,inventory:{Size:9,Items:[]},spawnRange:0,transparent:1b,maxDelay:0,xpToDrop:0,mobRange:0,debugMode:0b,maxNearbyMonsters:0}}}
:enddata
:endrule

rule:
plugin=blockTile
number=40
data:
JSON:{blockState:{blockName:"ancientwarfarestructure:advanced_spawner",properties:{transparent:"true"}},teData:{id:"ancientwarfarestructure:advanced_spawner_tile",spawnerSettings:{minDelay:0,spawnDelay:0,lightSensitive:0b,spawnGroups:[{settingsList:[{remainingSpawnCount:1,hostile:1b,forced:1b,customTag:{factionName:"orc"},maxToSpawn:1,entityId:"ancientwarfarenpc:faction.soldier",minToSpawn:1}],groupWeight:1}],playerRange:4,respondToRedstone:0b,inventory:{Size:9,Items:[]},spawnRange:0,transparent:1b,maxDelay:0,xpToDrop:0,mobRange:0,debugMode:0b,maxNearbyMonsters:0}}}
:enddata
:endrule

rule:
plugin=vanillaSkull
number=41
data:
JSON:{blockState:{blockName:"minecraft:skull",properties:{nodrop:"false",facing:"up"}},skullRotation:0,teData:{Rot:12b,id:"minecraft:skull",SkullType:0b}}
:enddata
:endrule

rule:
plugin=vanillaSkull
number=42
data:
JSON:{blockState:{blockName:"minecraft:skull",properties:{nodrop:"false",facing:"up"}},skullRotation:0,teData:{Rot:12b,id:"minecraft:skull",SkullType:0b}}
:enddata
:endrule

rule:
plugin=vanillaSkull
number=43
data:
JSON:{blockState:{blockName:"minecraft:skull",properties:{nodrop:"false",facing:"up"}},skullRotation:0,teData:{Rot:12b,id:"minecraft:skull",SkullType:0b}}
:enddata
:endrule

rule:
plugin=vanillaSkull
number=44
data:
JSON:{blockState:{blockName:"minecraft:skull",properties:{nodrop:"false",facing:"up"}},skullRotation:0,teData:{Rot:12b,id:"minecraft:skull",SkullType:0b}}
:enddata
:endrule

rule:
plugin=vanillaSkull
number=45
data:
JSON:{blockState:{blockName:"minecraft:skull",properties:{nodrop:"false",facing:"up"}},skullRotation:0,teData:{Rot:12b,id:"minecraft:skull",SkullType:0b}}
:enddata
:endrule

rule:
plugin=vanillaSkull
number=46
data:
JSON:{blockState:{blockName:"minecraft:skull",properties:{nodrop:"false",facing:"up"}},skullRotation:0,teData:{Rot:12b,id:"minecraft:skull",SkullType:0b}}
:enddata
:endrule

rule:
plugin=vanillaSkull
number=47
data:
JSON:{blockState:{blockName:"minecraft:skull",properties:{nodrop:"false",facing:"up"}},skullRotation:0,teData:{Rot:12b,id:"minecraft:skull",SkullType:0b}}
:enddata
:endrule

rule:
plugin=vanillaSkull
number=48
data:
JSON:{blockState:{blockName:"minecraft:skull",properties:{nodrop:"false",facing:"up"}},skullRotation:0,teData:{Rot:12b,id:"minecraft:skull",SkullType:0b}}
:enddata
:endrule

rule:
plugin=vanillaSkull
number=49
data:
JSON:{blockState:{blockName:"minecraft:skull",properties:{nodrop:"false",facing:"up"}},skullRotation:0,teData:{Rot:12b,id:"minecraft:skull",SkullType:0b}}
:enddata
:endrule

rule:
plugin=vanillaBlocks
number=50
data:
JSON:{blockState:{blockName:"minecraft:stone_stairs",properties:{half:"bottom",shape:"straight",facing:"west"}}}
:enddata
:endrule

rule:
plugin=inventory
number=51
data:
JSON:{blockState:{blockName:"minecraft:chest",properties:{facing:"west"}},lootLevel:2,teData:{ForgeData:{},Items:[{Slot:13b,id:"minecraft:diamond",Count:2b,Damage:0s}],id:"minecraft:chest",Lock:""},inventoryData:{length:1,inventoryContents:[{id:"minecraft:diamond",Count:2b,slot:0,Damage:0s}]},legacyFeatures:1b}
:enddata
:endrule

rule:
plugin=blockTile
number=52
data:
JSON:{blockState:{blockName:"ancientwarfarestructure:advanced_spawner",properties:{transparent:"true"}},teData:{id:"ancientwarfarestructure:advanced_spawner_tile",spawnerSettings:{minDelay:0,spawnDelay:0,lightSensitive:0b,spawnGroups:[{settingsList:[{remainingSpawnCount:1,hostile:1b,forced:1b,customTag:{factionName:"orc"},maxToSpawn:1,entityId:"ancientwarfarenpc:faction.leader.elite",minToSpawn:1}],groupWeight:1}],playerRange:3,respondToRedstone:0b,inventory:{Size:9,Items:[]},spawnRange:0,transparent:1b,maxDelay:0,xpToDrop:0,mobRange:0,debugMode:0b,maxNearbyMonsters:0}}}
:enddata
:endrule

rule:
plugin=vanillaSkull
number=53
data:
JSON:{blockState:{blockName:"minecraft:skull",properties:{nodrop:"false",facing:"up"}},skullRotation:0,teData:{Rot:12b,id:"minecraft:skull",SkullType:0b}}
:enddata
:endrule

rule:
plugin=blockTile
number=54
data:
JSON:{blockState:{blockName:"ancientwarfarestructure:advanced_spawner",properties:{transparent:"true"}},teData:{id:"ancientwarfarestructure:advanced_spawner_tile",spawnerSettings:{minDelay:0,spawnDelay:0,lightSensitive:0b,spawnGroups:[{settingsList:[{remainingSpawnCount:1,hostile:1b,forced:1b,customTag:{factionName:"orc"},maxToSpawn:1,entityId:"ancientwarfarenpc:faction.soldier",minToSpawn:1}],groupWeight:1}],playerRange:3,respondToRedstone:0b,inventory:{Size:9,Items:[]},spawnRange:0,transparent:1b,maxDelay:0,xpToDrop:0,mobRange:0,debugMode:0b,maxNearbyMonsters:0}}}
:enddata
:endrule

rule:
plugin=vanillaSkull
number=55
data:
JSON:{blockState:{blockName:"minecraft:skull",properties:{nodrop:"false",facing:"up"}},skullRotation:0,teData:{Rot:12b,id:"minecraft:skull",SkullType:0b}}
:enddata
:endrule

rule:
plugin=vanillaBlocks
number=56
data:
JSON:{blockState:{blockName:"minecraft:lit_pumpkin",properties:{facing:"west"}}}
:enddata
:endrule

rule:
plugin=blockTile
number=57
data:
JSON:{blockState:{blockName:"ancientwarfarestructure:advanced_spawner",properties:{transparent:"true"}},teData:{id:"ancientwarfarestructure:advanced_spawner_tile",spawnerSettings:{minDelay:0,spawnDelay:0,lightSensitive:0b,spawnGroups:[{settingsList:[{remainingSpawnCount:1,hostile:1b,forced:1b,customTag:{factionName:"orc"},maxToSpawn:1,entityId:"ancientwarfarenpc:faction.soldier",minToSpawn:1}],groupWeight:1}],playerRange:3,respondToRedstone:0b,inventory:{Size:9,Items:[]},spawnRange:0,transparent:1b,maxDelay:0,xpToDrop:0,mobRange:0,debugMode:0b,maxNearbyMonsters:0}}}
:enddata
:endrule

rule:
plugin=vanillaSkull
number=58
data:
JSON:{blockState:{blockName:"minecraft:skull",properties:{nodrop:"false",facing:"up"}},skullRotation:0,teData:{Rot:12b,id:"minecraft:skull",SkullType:0b}}
:enddata
:endrule

rule:
plugin=vanillaSkull
number=59
data:
JSON:{blockState:{blockName:"minecraft:skull",properties:{nodrop:"false",facing:"up"}},skullRotation:0,teData:{Rot:12b,id:"minecraft:skull",SkullType:0b}}
:enddata
:endrule

rule:
plugin=vanillaBlocks
number=60
data:
JSON:{blockState:{blockName:"minecraft:redstone_torch",properties:{facing:"west"}}}
:enddata
:endrule

rule:
plugin=vanillaBlocks
number=61
data:
JSON:{blockState:{blockName:"minecraft:dirt",properties:{variant:"dirt",snowy:"false"}}}
:enddata
:endrule

rule:
plugin=vanillaBlocks
number=62
data:
JSON:{blockState:{blockName:"minecraft:stonebrick",properties:{variant:"stonebrick"}}}
:enddata
:endrule

rule:
plugin=vanillaBlocks
number=63
data:
JSON:{blockState:{blockName:"minecraft:monster_egg",properties:{variant:"stone_brick"}}}
:enddata
:endrule

rule:
plugin=vanillaBlocks
number=64
data:
JSON:{blockState:{blockName:"minecraft:stonebrick",properties:{variant:"mossy_stonebrick"}}}
:enddata
:endrule

rule:
plugin=vanillaBlocks
number=65
data:
JSON:{blockState:{blockName:"minecraft:stonebrick",properties:{variant:"cracked_stonebrick"}}}
:enddata
:endrule

rule:
plugin=vanillaBlocks
number=66
data:
JSON:{blockState:{blockName:"minecraft:grass",properties:{snowy:"false"}}}
:enddata
:endrule

rule:
plugin=fluid
number=67
data:
JSON:{blockState:{blockName:"minecraft:water",properties:{level:"0"}}}
:enddata
:endrule

rule:
plugin=vanillaBlocks
number=68
data:
JSON:{blockState:{blockName:"minecraft:tallgrass",properties:{type:"tall_grass"}}}
:enddata
:endrule

rule:
plugin=vanillaBlocks
number=69
data:
JSON:{blockState:{blockName:"minecraft:monster_egg",properties:{variant:"mossy_brick"}}}
:enddata
:endrule

rule:
plugin=vanillaBlocks
number=70
data:
JSON:{blockState:{blockName:"minecraft:stonebrick",properties:{variant:"chiseled_stonebrick"}}}
:enddata
:endrule

rule:
plugin=vanillaBlocks
number=71
data:
JSON:{blockState:{blockName:"minecraft:stone_brick_stairs",properties:{half:"top",shape:"straight",facing:"north"}}}
:enddata
:endrule

rule:
plugin=vanillaBlocks
number=72
data:
JSON:{blockState:{blockName:"minecraft:stone_brick_stairs",properties:{half:"top",shape:"straight",facing:"south"}}}
:enddata
:endrule

rule:
plugin=vanillaBlocks
number=73
data:
JSON:{blockState:{blockName:"minecraft:stone_brick_stairs",properties:{half:"top",shape:"straight",facing:"east"}}}
:enddata
:endrule

rule:
plugin=vanillaBlocks
number=74
data:
JSON:{blockState:{blockName:"minecraft:stone_brick_stairs",properties:{half:"top",shape:"straight",facing:"west"}}}
:enddata
:endrule

rule:
plugin=vanillaBlocks
number=75
data:
JSON:{blockState:{blockName:"minecraft:stone_slab",properties:{half:"bottom",variant:"stone_brick"}}}
:enddata
:endrule

#### ENTITIES ####
