# Ancient Warfare Structure Template File
# Auto-generated structure template file. created on: 12/9/2014 at: 14:25:15
# Lines beginning with # denote comments

header:
version=2.1
name=wall_2x2_t_1
size=16,28,19
offset=15,4,17
:endheader

#### VALIDATION ####
validation:
type=ground
survival=false
worldGenEnabled=false
unique=false
preserveBlocks=false
selectionWeight=0
clusterValue=0
minDuplicateDistance=0
dimensionWhiteList=false
dimensionList=
biomeWhiteList=false
biomeList=
leveling=0
fill=0
border=0
validTargetBlocks=
blockSwap=false
data:
:enddata
:endvalidation

#### LAYERS ####
layer: 0
2,2,2,2,2,2,2,2,2,2,2,2,2,2,2,2
2,2,2,2,2,2,2,2,2,2,2,2,2,2,2,2
2,2,2,2,2,2,2,2,2,2,2,2,2,2,2,2
2,2,2,2,2,2,2,2,2,2,2,2,2,2,2,2
2,2,2,2,2,2,2,2,2,2,2,2,2,2,2,2
2,2,2,2,2,2,2,2,2,2,2,2,2,2,2,2
2,2,2,2,2,2,2,2,2,2,2,2,2,2,2,2
2,2,2,2,2,2,2,2,2,2,2,2,2,2,2,2
2,2,2,2,2,2,2,2,2,2,2,2,2,2,2,2
2,2,2,2,2,2,2,2,2,2,2,2,2,2,2,2
2,2,2,2,2,2,2,2,2,2,2,2,2,2,2,2
2,2,2,2,2,2,2,2,2,2,2,2,2,2,2,2
1,1,1,1,1,1,1,1,1,1,1,1,1,1,1,1
1,1,1,1,1,1,1,1,1,1,1,1,1,1,1,1
1,1,1,1,1,1,1,1,1,1,1,1,1,1,1,1
1,1,1,1,1,1,1,1,1,1,1,1,1,1,1,1
1,1,1,1,1,1,1,1,1,1,1,1,1,1,1,1
1,1,1,1,1,1,1,1,1,1,1,1,1,1,1,1
1,1,1,1,1,1,1,1,1,1,1,1,1,1,1,1
:endlayer
layer: 1
2,2,2,2,2,2,2,2,2,2,2,2,2,2,2,2
2,2,2,2,2,2,2,2,2,2,2,2,2,2,2,2
2,2,2,2,2,2,2,2,2,2,2,2,2,2,2,2
2,2,2,2,2,2,2,2,2,2,2,2,2,2,2,2
2,2,2,2,2,2,2,2,2,2,2,2,2,2,2,2
2,2,2,2,2,2,2,2,2,2,2,2,2,2,2,2
2,2,2,2,2,2,2,2,2,2,2,2,2,2,2,2
2,2,2,2,2,2,2,2,2,2,2,2,2,2,2,2
2,2,2,2,2,2,2,2,2,2,2,2,2,2,2,2
2,2,2,2,2,2,2,2,2,2,2,2,2,2,2,2
2,2,2,2,2,2,2,2,2,2,2,2,2,2,2,2
2,2,2,2,2,2,2,2,2,2,2,2,2,2,2,2
1,1,1,1,1,1,1,1,1,1,1,1,1,1,1,1
1,1,1,1,1,1,1,1,1,1,1,1,1,1,1,1
1,1,1,1,1,1,1,1,1,1,1,1,1,1,1,1
1,1,1,1,1,1,1,1,1,1,1,1,1,1,1,1
1,1,1,1,1,1,1,1,1,1,1,1,1,1,1,1
1,1,1,1,1,1,1,1,1,1,1,1,1,1,1,1
1,1,1,1,1,1,1,1,1,1,1,1,1,1,1,1
:endlayer
layer: 2
2,2,2,2,1,1,4,4,4,4,2,2,2,2,2,2
2,2,2,2,4,4,4,4,4,4,2,2,2,2,2,2
2,2,2,4,4,5,4,4,5,4,2,2,2,2,2,2
4,4,2,5,4,4,6,5,4,4,4,4,4,4,4,4
4,6,4,4,4,4,4,4,4,4,4,6,4,6,6,4
4,4,4,4,4,4,4,6,4,4,4,4,4,4,4,4
4,5,4,4,4,4,4,4,4,4,4,4,4,5,5,4
4,4,4,6,5,4,4,4,5,5,4,4,4,4,4,4
4,4,2,4,4,4,4,6,4,4,5,6,4,4,4,4
2,2,2,6,5,4,4,4,4,6,4,4,2,2,2,2
2,2,2,1,4,4,4,4,4,5,4,4,2,2,2,2
3,3,3,3,3,3,4,4,4,4,3,3,3,3,3,3
3,3,3,3,3,3,3,3,3,3,3,3,3,3,3,3
3,3,3,3,3,3,3,3,3,3,3,3,3,3,3,3
3,3,3,3,3,3,3,3,3,3,3,3,3,3,3,3
3,3,3,3,3,3,3,3,3,3,3,3,3,3,3,3
3,3,3,3,3,3,3,3,3,3,3,3,3,3,3,3
1,1,1,1,1,1,1,1,1,1,1,1,1,1,1,1
1,1,1,1,1,1,1,1,1,1,1,1,1,1,1,1
:endlayer
layer: 3
8,8,8,2,2,2,5,4,5,5,2,2,2,8,8,8
8,8,2,2,6,4,4,4,4,4,4,4,2,2,8,8
2,2,2,4,4,4,4,4,6,6,4,4,4,2,2,2
4,4,8,4,4,4,4,4,4,4,4,4,4,4,4,4
4,4,4,4,4,4,4,4,4,4,6,4,4,4,4,4
4,4,4,4,4,4,4,4,5,4,4,4,5,4,4,4
4,4,4,4,4,4,4,4,4,4,6,4,4,4,4,4
5,4,4,4,5,4,4,4,4,4,4,6,4,4,4,5
6,4,8,4,4,4,4,4,4,4,5,4,4,4,4,6
2,2,1,4,4,4,4,4,4,5,4,4,2,2,2,2
2,2,2,2,4,4,6,5,4,4,4,4,2,2,2,2
3,3,3,3,3,3,4,4,4,4,3,3,3,3,3,3
3,3,3,3,3,3,3,3,3,3,3,3,3,3,3,3
3,3,3,3,3,3,3,3,3,3,3,3,3,3,3,3
3,3,3,3,3,3,3,3,3,3,3,3,3,3,3,3
3,3,3,3,3,3,3,3,3,3,3,3,3,3,3,3
3,3,3,3,3,3,3,3,3,3,3,3,3,3,3,3
7,7,7,7,7,7,7,7,7,7,7,7,7,7,7,7
7,7,7,7,7,7,7,7,7,7,7,7,7,7,7,7
:endlayer
layer: 4
0,0,0,0,0,0,4,17,4,4,0,0,0,0,0,0
0,0,0,0,4,4,0,0,0,0,4,4,0,0,0,0
0,0,0,4,12,0,0,0,0,0,0,0,4,0,0,0
4,4,4,4,0,0,14,16,19,0,0,0,4,4,4,4
4,4,4,4,0,0,14,16,19,0,0,0,0,4,4,4
0,0,0,9,0,0,14,16,19,0,0,0,0,22,0,0
4,4,4,4,0,0,14,16,19,0,0,10,10,4,4,4
4,4,4,4,10,0,0,15,0,0,0,0,21,4,4,4
4,4,4,4,11,0,0,0,0,0,0,10,4,4,4,4
0,0,4,4,10,10,0,10,0,10,20,10,4,4,0,0
0,0,0,0,4,4,13,10,18,10,4,4,0,0,0,0
0,0,0,0,0,0,4,4,4,4,0,0,0,0,0,0
0,0,0,0,0,0,0,0,0,0,0,0,0,0,0,0
0,0,0,0,0,0,0,0,0,0,0,0,0,0,0,0
0,0,0,0,0,0,0,0,0,0,0,0,0,0,0,0
0,0,0,0,0,0,0,0,0,0,0,0,0,0,0,0
0,0,0,0,0,0,0,0,0,0,0,0,0,0,0,0
0,0,0,0,0,0,0,0,0,0,0,0,0,0,0,0
0,0,0,0,0,0,0,0,0,0,0,0,0,0,0,0
:endlayer
layer: 5
0,0,0,0,0,0,4,26,6,4,0,0,0,0,0,0
0,0,0,0,4,4,0,0,0,0,4,4,0,0,0,0
0,0,0,4,0,0,0,0,0,0,0,0,4,0,0,0
4,4,4,4,0,0,0,25,0,0,0,0,4,4,4,4
4,6,23,4,0,0,0,25,0,0,0,0,0,6,6,4
0,0,0,24,0,0,0,25,0,0,0,0,0,27,0,0
4,4,4,4,0,0,0,25,0,0,0,0,0,4,4,4
4,4,4,4,0,0,0,0,0,0,0,0,0,4,4,4
5,4,4,4,0,0,0,0,0,0,0,0,4,4,4,5
0,0,4,6,0,0,0,0,0,0,0,0,4,4,0,0
0,0,0,0,4,4,0,0,0,0,4,4,0,0,0,0
0,0,0,0,0,0,4,4,4,6,0,0,0,0,0,0
0,0,0,0,0,0,0,0,0,0,0,0,0,0,0,0
0,0,0,0,0,0,0,0,0,0,0,0,0,0,0,0
0,0,0,0,0,0,0,0,0,0,0,0,0,0,0,0
0,0,0,0,0,0,0,0,0,0,0,0,0,0,0,0
0,0,0,0,0,0,0,0,0,0,0,0,0,0,0,0
0,0,0,0,0,0,0,0,0,0,0,0,0,0,0,0
0,0,0,0,0,0,0,0,0,0,0,0,0,0,0,0
:endlayer
layer: 6
0,0,0,0,0,0,4,4,4,4,0,0,0,0,0,0
0,0,0,0,4,4,0,0,0,0,4,4,0,0,0,0
0,0,0,5,0,0,0,0,0,0,0,0,4,0,0,0
4,4,4,4,0,0,0,0,0,0,0,0,4,4,4,4
4,4,4,4,0,0,0,0,0,0,0,0,0,4,4,4
4,5,4,4,28,0,0,0,0,0,0,0,30,5,5,4
4,4,4,4,0,0,0,0,0,0,0,0,0,4,4,4
4,4,4,4,0,0,0,0,0,0,0,0,29,4,4,4
4,4,4,4,0,0,0,0,0,0,0,0,4,4,4,4
0,0,4,4,0,0,0,0,0,0,0,0,4,4,0,0
0,0,0,0,6,4,0,0,0,0,4,4,0,0,0,0
0,0,0,0,0,0,4,4,4,4,0,0,0,0,0,0
0,0,0,0,0,0,0,0,0,0,0,0,0,0,0,0
0,0,0,0,0,0,0,0,0,0,0,0,0,0,0,0
0,0,0,0,0,0,0,0,0,0,0,0,0,0,0,0
0,0,0,0,0,0,0,0,0,0,0,0,0,0,0,0
0,0,0,0,0,0,0,0,0,0,0,0,0,0,0,0
0,0,0,0,0,0,0,0,0,0,0,0,0,0,0,0
0,0,0,0,0,0,0,0,0,0,0,0,0,0,0,0
:endlayer
layer: 7
0,0,0,0,0,0,4,4,4,4,0,0,0,0,0,0
0,0,0,0,4,4,23,0,0,0,4,4,0,0,0,0
0,0,0,6,0,0,0,0,0,0,0,29,4,0,0,0
4,4,4,4,0,0,0,0,0,0,0,0,4,4,4,4
4,4,4,4,32,0,0,0,0,0,0,0,0,4,4,4
4,4,4,4,0,0,0,0,0,0,0,0,0,4,4,4
4,4,4,4,0,0,0,0,0,0,0,0,0,4,4,4
4,4,4,4,0,0,0,0,0,0,0,0,0,4,4,4
4,4,4,4,0,0,0,0,0,0,0,0,6,4,4,4
0,0,4,4,31,0,0,0,0,0,0,0,4,4,0,0
0,0,0,0,4,4,0,0,0,31,5,5,0,0,0,0
0,0,0,0,0,0,4,4,4,4,0,0,0,0,0,0
0,0,0,0,0,0,0,0,0,0,0,0,0,0,0,0
0,0,0,0,0,0,0,0,0,0,0,0,0,0,0,0
0,0,0,0,0,0,0,0,0,0,0,0,0,0,0,0
0,0,0,0,0,0,0,0,0,0,0,0,0,0,0,0
0,0,0,0,0,0,0,0,0,0,0,0,0,0,0,0
0,0,0,0,0,0,0,0,0,0,0,0,0,0,0,0
0,0,0,0,0,0,0,0,0,0,0,0,0,0,0,0
:endlayer
layer: 8
0,0,0,0,0,0,4,4,4,4,0,0,0,0,0,0
0,0,0,0,4,4,4,4,4,4,4,4,0,0,0,0
0,0,0,4,4,4,6,4,4,5,4,4,4,0,0,0
4,4,4,4,4,4,5,4,4,4,4,4,4,4,4,4
4,4,4,4,4,4,4,4,6,4,4,4,4,4,4,4
4,4,4,4,4,4,4,6,4,4,4,4,4,4,4,4
4,4,4,4,4,4,4,4,4,6,4,4,5,4,4,4
4,4,4,4,4,4,4,4,4,4,4,5,5,4,4,4
6,4,4,4,4,4,6,4,4,4,4,4,4,4,4,6
0,0,4,4,4,4,4,4,4,4,4,4,6,4,0,0
0,0,23,29,4,4,4,4,4,4,4,4,32,23,0,0
0,0,0,0,0,29,6,4,6,4,32,0,0,0,0,0
0,0,0,0,0,0,0,0,0,0,0,0,0,0,0,0
0,0,0,0,0,0,0,0,0,0,0,0,0,0,0,0
0,0,0,0,0,0,0,0,0,0,0,0,0,0,0,0
0,0,0,0,0,0,0,0,0,0,0,0,0,0,0,0
0,0,0,0,0,0,0,0,0,0,0,0,0,0,0,0
0,0,0,0,0,0,0,0,0,0,0,0,0,0,0,0
0,0,0,0,0,0,0,0,0,0,0,0,0,0,0,0
:endlayer
layer: 9
0,0,0,0,0,0,4,4,4,4,0,0,0,0,0,0
0,0,0,0,4,4,0,0,33,0,4,4,0,0,0,0
0,0,0,4,0,0,0,0,0,0,0,0,4,0,0,0
4,4,4,4,0,0,0,0,0,0,0,0,4,4,4,4
4,4,4,4,0,0,0,0,0,0,0,0,0,4,4,4
4,4,4,4,0,0,0,0,0,0,0,0,0,4,4,4
4,4,4,4,0,0,0,0,0,0,0,0,0,4,4,4
4,4,4,4,0,0,0,0,0,0,0,0,0,4,4,4
4,4,4,4,0,0,0,0,0,0,0,0,4,4,4,4
0,0,4,4,0,0,0,0,0,0,0,0,4,4,0,0
0,0,0,0,4,5,0,0,0,0,4,4,0,0,0,0
0,0,0,0,0,0,4,6,4,6,0,0,0,0,0,0
0,0,0,0,0,0,0,0,0,0,0,0,0,0,0,0
0,0,0,0,0,0,0,0,0,0,0,0,0,0,0,0
0,0,0,0,0,0,0,0,0,0,0,0,0,0,0,0
0,0,0,0,0,0,0,0,0,0,0,0,0,0,0,0
0,0,0,0,0,0,0,0,0,0,0,0,0,0,0,0
0,0,0,0,0,0,0,0,0,0,0,0,0,0,0,0
0,0,0,0,0,0,0,0,0,0,0,0,0,0,0,0
:endlayer
layer: 10
0,0,0,0,0,0,4,4,4,4,0,0,0,0,0,0
0,0,0,0,4,4,0,0,33,0,4,4,0,0,0,0
0,0,0,5,0,0,0,0,0,0,0,0,4,0,0,0
4,4,4,4,0,0,0,0,0,0,0,0,4,4,4,4
4,4,4,4,0,0,0,0,0,0,0,0,0,4,4,4
4,4,4,4,0,0,0,0,0,0,0,0,0,4,4,4
4,6,4,4,0,0,0,0,0,0,0,0,0,6,6,4
4,4,4,4,0,0,0,0,0,0,0,0,0,4,4,4
4,4,4,4,0,0,0,0,0,0,0,0,4,4,4,4
0,0,34,4,0,0,0,0,0,0,0,0,4,34,0,0
0,0,0,0,4,4,0,0,0,0,4,4,0,0,0,0
0,0,0,0,0,0,4,4,6,4,0,0,0,0,0,0
0,0,0,0,0,0,0,0,0,0,0,0,0,0,0,0
0,0,0,0,0,0,0,0,0,0,0,0,0,0,0,0
0,0,0,0,0,0,0,0,0,0,0,0,0,0,0,0
0,0,0,0,0,0,0,0,0,0,0,0,0,0,0,0
0,0,0,0,0,0,0,0,0,0,0,0,0,0,0,0
0,0,0,0,0,0,0,0,0,0,0,0,0,0,0,0
0,0,0,0,0,0,0,0,0,0,0,0,0,0,0,0
:endlayer
layer: 11
0,0,0,0,0,0,4,4,4,4,0,0,0,0,0,0
0,0,0,0,4,5,0,0,0,0,4,4,0,0,0,0
0,0,0,4,0,0,0,0,0,0,0,0,4,0,0,0
4,4,4,4,0,0,0,0,0,0,0,0,4,4,4,4
4,4,4,4,0,0,0,0,0,0,0,0,0,4,4,4
4,6,4,4,0,0,0,0,0,0,0,0,0,6,6,4
4,4,4,4,0,0,0,0,0,0,0,0,0,4,4,4
4,4,4,4,0,0,0,0,0,0,0,0,29,4,4,4
4,4,4,4,0,0,0,0,0,0,0,0,4,4,4,4
35,35,35,4,0,0,0,0,0,0,0,0,4,35,35,35
0,0,0,0,4,4,0,0,0,0,4,4,0,0,0,0
0,0,0,0,0,0,6,4,4,4,0,0,0,0,0,0
0,0,0,0,0,0,0,0,0,0,0,0,0,0,0,0
0,0,0,0,0,0,0,0,0,0,0,0,0,0,0,0
0,0,0,0,0,0,0,0,0,0,0,0,0,0,0,0
0,0,0,0,0,0,0,0,0,0,0,0,0,0,0,0
0,0,0,0,0,0,0,0,0,0,0,0,0,0,0,0
0,0,0,0,0,0,0,0,0,0,0,0,0,0,0,0
0,0,0,0,0,0,0,0,0,0,0,0,0,0,0,0
:endlayer
layer: 12
0,0,0,0,0,0,4,4,6,6,0,0,0,0,0,0
0,0,0,0,4,4,4,4,4,4,4,4,0,0,0,0
0,0,0,4,4,4,4,4,4,4,4,4,4,0,0,0
4,4,4,4,4,4,4,4,4,4,4,4,4,4,4,4
0,4,4,4,4,4,5,4,4,4,4,4,4,4,4,0
0,4,4,4,4,4,6,4,4,4,4,4,4,4,4,0
0,36,4,4,4,4,4,4,4,6,4,4,4,37,0,0
0,4,4,4,5,4,5,4,4,4,4,4,4,4,4,0
0,0,4,4,4,4,4,4,4,4,4,4,6,4,0,0
4,4,4,4,4,4,4,4,4,4,4,4,4,4,4,4
0,0,0,0,4,4,4,4,4,4,4,4,0,0,0,0
0,0,0,0,0,0,4,6,6,4,0,0,0,0,0,0
0,0,0,0,0,0,0,0,0,0,0,0,0,0,0,0
0,0,0,0,0,0,0,0,0,0,0,0,0,0,0,0
0,0,0,0,0,0,0,0,0,0,0,0,0,0,0,0
0,0,0,0,0,0,0,0,0,0,0,0,0,0,0,0
0,0,0,0,0,0,0,0,0,0,0,0,0,0,0,0
0,0,0,0,0,0,0,0,0,0,0,0,0,0,0,0
0,0,0,0,0,0,0,0,0,0,0,0,0,0,0,0
:endlayer
layer: 13
0,0,0,0,0,0,4,4,4,4,0,0,0,0,0,0
0,0,0,0,4,4,0,0,0,0,4,4,0,0,0,0
0,0,0,4,0,0,0,0,0,0,0,0,4,0,0,0
0,36,4,4,0,0,0,0,0,0,4,4,4,4,36,0
0,4,4,4,0,0,0,0,0,0,4,4,4,4,4,0
0,4,4,4,0,0,0,0,0,0,34,34,0,4,4,0
0,0,0,0,0,0,0,0,0,0,0,0,0,0,0,0
0,4,4,4,0,0,0,0,0,0,0,0,0,4,4,0
0,0,4,4,0,0,0,0,0,0,0,0,4,4,0,0
36,0,36,4,0,0,0,0,0,0,0,0,4,36,36,0
0,0,0,0,4,5,0,0,0,0,4,4,0,0,0,0
0,0,0,0,0,0,5,4,4,4,0,0,0,0,0,0
0,0,0,0,0,0,0,0,0,0,0,0,0,0,0,0
0,0,0,0,0,0,0,0,0,0,0,0,0,0,0,0
0,0,0,0,0,0,0,0,0,0,0,0,0,0,0,0
0,0,0,0,0,0,0,0,0,0,0,0,0,0,0,0
0,0,0,0,0,0,0,0,0,0,0,0,0,0,0,0
0,0,0,0,0,0,0,0,0,0,0,0,0,0,0,0
0,0,0,0,0,0,0,0,0,0,0,0,0,0,0,0
:endlayer
layer: 14
0,0,0,0,0,0,4,0,4,4,0,0,0,0,0,0
0,0,0,0,4,6,0,0,0,0,4,4,0,0,0,0
0,0,0,6,0,0,0,0,0,0,0,0,4,0,0,0
0,0,4,4,0,0,0,0,0,0,4,4,4,4,0,0
0,4,4,4,0,0,0,0,0,0,34,34,0,4,4,0
0,4,4,4,0,0,0,0,0,0,0,0,0,4,4,0
0,0,0,0,0,0,0,0,0,0,0,0,0,0,0,0
0,4,4,4,0,0,0,0,0,0,0,0,0,4,4,0
0,0,4,4,0,0,0,0,0,0,0,0,4,4,0,0
0,0,0,6,0,0,0,0,0,0,0,0,4,0,0,0
0,0,0,0,4,4,0,0,0,0,4,4,0,0,0,0
0,0,0,0,0,0,4,0,4,4,0,0,0,0,0,0
0,0,0,0,0,0,0,0,0,0,0,0,0,0,0,0
0,0,0,0,0,0,0,0,0,0,0,0,0,0,0,0
0,0,0,0,0,0,0,0,0,0,0,0,0,0,0,0
0,0,0,0,0,0,0,0,0,0,0,0,0,0,0,0
0,0,0,0,0,0,0,0,0,0,0,0,0,0,0,0
0,0,0,0,0,0,0,0,0,0,0,0,0,0,0,0
0,0,0,0,0,0,0,0,0,0,0,0,0,0,0,0
:endlayer
layer: 15
0,0,0,0,0,0,4,0,6,4,0,0,0,0,0,0
0,0,0,0,4,4,0,0,0,29,4,4,0,0,0,0
0,0,0,4,0,0,0,0,0,0,4,4,4,0,0,0
0,0,4,4,0,0,0,0,0,0,34,34,4,4,0,0
0,6,4,4,0,0,0,0,0,0,0,0,0,6,6,0
0,4,4,4,0,0,0,0,0,0,0,0,0,4,4,0
29,4,4,4,32,0,0,0,0,0,0,0,0,4,4,32
0,4,4,4,0,0,0,0,0,0,0,0,29,4,4,0
0,0,4,4,0,0,0,0,0,0,0,0,4,4,0,0
0,0,0,4,0,31,0,0,0,0,0,0,4,0,0,0
0,0,0,0,4,4,0,0,0,0,4,4,0,0,0,0
0,0,0,0,0,0,4,0,4,4,0,0,0,0,0,0
0,0,0,0,0,0,0,0,0,0,0,0,0,0,0,0
0,0,0,0,0,0,0,0,0,0,0,0,0,0,0,0
0,0,0,0,0,0,0,0,0,0,0,0,0,0,0,0
0,0,0,0,0,0,0,0,0,0,0,0,0,0,0,0
0,0,0,0,0,0,0,0,0,0,0,0,0,0,0,0
0,0,0,0,0,0,0,0,0,0,0,0,0,0,0,0
0,0,0,0,0,0,0,0,0,0,0,0,0,0,0,0
:endlayer
layer: 16
0,0,0,0,0,0,4,4,4,4,0,0,0,0,0,0
0,0,0,0,4,4,4,4,4,4,4,4,0,0,0,0
39,39,39,4,4,6,4,4,4,4,34,34,4,39,39,39
0,39,4,4,4,4,4,4,4,4,0,0,4,4,0,0
0,4,4,4,5,4,4,4,4,4,0,0,4,4,4,0
0,4,4,4,6,4,6,4,4,4,0,0,4,4,4,0
0,4,4,4,4,4,4,4,4,4,4,4,6,4,4,0
0,4,4,4,4,4,4,4,4,4,4,4,4,4,4,0
0,31,4,4,4,4,4,5,4,4,4,4,4,4,0,0
38,38,10,5,6,4,4,4,4,5,5,4,5,38,38,38
0,0,0,0,4,4,4,4,6,4,4,4,0,0,0,0
0,0,0,0,0,0,4,4,4,4,0,0,0,0,0,0
0,0,0,0,0,0,0,0,0,0,0,0,0,0,0,0
0,0,0,0,0,0,0,0,0,0,0,0,0,0,0,0
0,0,0,0,0,0,0,0,0,0,0,0,0,0,0,0
0,0,0,0,0,0,0,0,0,0,0,0,0,0,0,0
0,0,0,0,0,0,0,0,0,0,0,0,0,0,0,0
0,0,0,0,0,0,0,0,0,0,0,0,0,0,0,0
0,0,0,0,0,0,0,0,0,0,0,0,0,0,0,0
:endlayer
layer: 17
0,0,0,0,0,0,4,4,4,4,0,0,0,0,0,0
0,0,0,0,4,4,0,0,0,4,4,4,0,0,0,0
0,0,0,4,0,0,0,0,0,0,0,0,4,0,0,0
15,0,4,4,0,0,0,0,0,0,0,0,4,4,15,15
40,4,4,4,0,0,0,0,0,4,0,0,0,4,4,40
40,4,4,4,0,0,0,0,0,4,0,0,0,4,4,40
40,4,4,4,0,0,0,0,0,34,0,0,0,4,4,40
40,4,4,4,0,0,0,0,0,0,0,0,0,4,4,40
38,38,4,4,0,0,0,0,0,0,0,0,4,4,38,38
0,0,0,4,0,0,0,0,0,0,0,0,4,0,0,0
0,0,0,0,4,4,0,0,0,0,4,4,0,0,0,0
0,0,0,0,0,0,4,6,4,4,0,0,0,0,0,0
0,0,0,0,0,0,0,0,0,0,0,0,0,0,0,0
0,0,0,0,0,0,0,0,0,0,0,0,0,0,0,0
0,0,0,0,0,0,0,0,0,0,0,0,0,0,0,0
0,0,0,0,0,0,0,0,0,0,0,0,0,0,0,0
0,0,0,0,0,0,0,0,0,0,0,0,0,0,0,0
0,0,0,0,0,0,0,0,0,0,0,0,0,0,0,0
0,0,0,0,0,0,0,0,0,0,0,0,0,0,0,0
:endlayer
layer: 18
0,0,0,0,0,0,4,4,4,4,0,0,0,0,0,0
0,0,0,0,4,4,0,0,0,4,4,4,0,0,0,0
0,0,0,4,0,0,0,0,0,0,0,0,4,0,0,0
0,0,4,4,0,0,0,0,0,0,0,0,4,4,0,0
15,4,4,4,0,0,0,0,0,4,0,0,0,4,4,15
40,4,4,4,0,0,0,0,0,34,0,0,0,4,4,40
40,4,4,4,0,0,0,0,0,0,0,0,0,4,4,40
38,4,4,4,0,0,0,0,0,0,0,0,0,4,4,38
0,0,4,4,0,0,0,0,0,0,0,0,4,4,0,0
0,0,0,4,0,0,0,0,0,0,0,0,4,0,0,0
0,0,0,0,4,4,0,0,0,0,4,4,0,0,0,0
0,0,0,0,0,0,4,0,4,5,0,0,0,0,0,0
0,0,0,0,0,0,0,0,0,0,0,0,0,0,0,0
0,0,0,0,0,0,0,0,0,0,0,0,0,0,0,0
0,0,0,0,0,0,0,0,0,0,0,0,0,0,0,0
0,0,0,0,0,0,0,0,0,0,0,0,0,0,0,0
0,0,0,0,0,0,0,0,0,0,0,0,0,0,0,0
0,0,0,0,0,0,0,0,0,0,0,0,0,0,0,0
0,0,0,0,0,0,0,0,0,0,0,0,0,0,0,0
:endlayer
layer: 19
0,0,0,0,0,0,4,4,5,4,0,0,0,0,0,0
0,0,0,0,4,4,32,0,0,4,4,4,0,0,0,0
0,0,0,6,0,23,0,0,0,0,0,0,4,0,0,0
0,0,4,4,0,0,0,0,0,0,0,29,4,4,0,0
0,4,4,4,0,0,0,0,0,34,0,0,0,4,4,0
0,4,4,4,0,0,0,0,0,0,0,0,0,4,4,32
0,4,4,4,0,0,0,0,0,0,0,0,0,4,4,0
0,4,4,4,0,0,0,0,0,0,0,0,29,4,4,0
0,0,4,4,0,0,0,0,0,0,0,0,4,4,0,0
0,0,0,4,0,31,0,0,0,0,0,0,4,0,0,0
0,0,0,0,4,4,0,0,0,0,4,4,0,0,0,0
0,0,0,0,0,0,4,0,4,4,0,0,0,0,0,0
0,0,0,0,0,0,0,0,0,0,0,0,0,0,0,0
0,0,0,0,0,0,0,0,0,0,0,0,0,0,0,0
0,0,0,0,0,0,0,0,0,0,0,0,0,0,0,0
0,0,0,0,0,0,0,0,0,0,0,0,0,0,0,0
0,0,0,0,0,0,0,0,0,0,0,0,0,0,0,0
0,0,0,0,0,0,0,0,0,0,0,0,0,0,0,0
0,0,0,0,0,0,0,0,0,0,0,0,0,0,0,0
:endlayer
layer: 20
0,0,0,0,0,0,5,4,4,4,0,0,0,0,0,0
0,0,0,0,4,4,4,4,4,4,4,4,0,0,0,0
0,0,0,5,4,6,4,4,4,4,5,4,4,0,0,0
0,0,4,4,4,4,4,4,4,34,4,4,4,4,0,0
0,4,4,4,4,4,4,4,4,0,4,4,4,4,4,0
0,6,4,4,4,4,4,4,4,0,4,4,4,6,6,0
0,4,4,4,4,4,4,4,4,0,4,4,4,4,4,0
0,4,4,4,4,4,4,4,4,4,4,4,4,4,4,0
0,0,4,4,4,6,4,4,4,6,4,4,4,4,0,0
0,0,0,4,4,4,6,4,4,4,4,4,4,0,0,0
0,0,0,0,4,4,4,4,4,4,4,5,0,0,0,0
0,0,0,0,0,0,4,4,4,4,0,0,0,0,0,0
0,0,0,0,0,0,0,0,0,0,0,0,0,0,0,0
0,0,0,0,0,0,0,0,0,0,0,0,0,0,0,0
0,0,0,0,0,0,0,0,0,0,0,0,0,0,0,0
0,0,0,0,0,0,0,0,0,0,0,0,0,0,0,0
0,0,0,0,0,0,0,0,0,0,0,0,0,0,0,0
0,0,0,0,0,0,0,0,0,0,0,0,0,0,0,0
0,0,0,0,0,0,0,0,0,0,0,0,0,0,0,0
:endlayer
layer: 21
0,0,0,0,0,0,4,4,4,4,0,0,0,0,0,0
0,0,0,0,4,4,0,0,0,0,4,4,0,0,0,0
0,0,0,4,0,0,0,0,0,0,0,0,4,0,0,0
0,0,4,4,0,0,0,0,0,0,0,0,4,4,0,0
0,4,4,4,0,0,0,0,4,0,0,0,0,4,4,0
0,4,4,4,0,0,0,0,4,0,0,0,0,4,4,0
0,4,4,4,0,0,0,0,34,0,0,0,0,4,4,0
0,4,4,4,0,0,0,0,0,0,0,0,0,4,4,0
0,0,4,4,0,0,0,0,0,0,0,0,4,4,0,0
0,0,0,4,0,0,0,0,0,0,0,0,4,0,0,0
0,0,0,0,4,4,0,0,0,0,4,5,0,0,0,0
0,0,0,0,0,0,6,4,4,4,0,0,0,0,0,0
0,0,0,0,0,0,0,0,0,0,0,0,0,0,0,0
0,0,0,0,0,0,0,0,0,0,0,0,0,0,0,0
0,0,0,0,0,0,0,0,0,0,0,0,0,0,0,0
0,0,0,0,0,0,0,0,0,0,0,0,0,0,0,0
0,0,0,0,0,0,0,0,0,0,0,0,0,0,0,0
0,0,0,0,0,0,0,0,0,0,0,0,0,0,0,0
0,0,0,0,0,0,0,0,0,0,0,0,0,0,0,0
:endlayer
layer: 22
0,0,0,0,0,0,4,0,4,4,0,0,0,0,0,0
0,0,0,0,4,4,0,0,0,0,4,4,0,0,0,0
0,0,0,4,0,0,0,0,0,0,0,0,4,0,0,0
0,0,4,4,0,0,0,0,0,0,0,0,4,4,0,0
0,4,4,4,0,0,0,0,4,0,0,0,0,4,4,0
0,4,4,4,0,0,0,0,34,0,0,0,0,4,4,0
0,0,4,4,0,0,0,0,0,0,0,0,0,0,0,0
0,4,4,4,0,0,0,0,0,0,0,0,0,4,4,0
0,0,4,4,0,0,0,0,0,0,0,0,4,4,0,0
0,0,0,4,0,0,0,0,0,0,0,0,4,0,0,0
0,0,0,0,4,4,0,0,0,0,4,4,0,0,0,0
0,0,0,0,0,0,4,0,4,4,0,0,0,0,0,0
0,0,0,0,0,0,0,0,0,0,0,0,0,0,0,0
0,0,0,0,0,0,0,0,0,0,0,0,0,0,0,0
0,0,0,0,0,0,0,0,0,0,0,0,0,0,0,0
0,0,0,0,0,0,0,0,0,0,0,0,0,0,0,0
0,0,0,0,0,0,0,0,0,0,0,0,0,0,0,0
0,0,0,0,0,0,0,0,0,0,0,0,0,0,0,0
0,0,0,0,0,0,0,0,0,0,0,0,0,0,0,0
:endlayer
layer: 23
0,0,0,0,0,0,4,0,4,4,0,0,0,0,0,0
0,0,0,0,4,4,0,0,23,0,4,4,0,0,0,0
0,0,0,4,0,23,0,0,0,0,0,0,4,0,0,0
0,0,4,4,0,0,0,0,0,0,0,0,4,4,0,0
0,4,4,4,0,0,0,0,34,0,0,0,0,4,4,0
0,4,4,4,0,0,0,0,0,0,0,0,0,4,4,0
0,0,4,4,0,0,0,0,0,0,0,0,0,0,0,0
0,6,4,4,0,0,0,0,0,0,0,0,29,6,6,0
0,0,4,4,0,0,0,0,0,0,0,0,5,4,0,0
0,0,0,4,0,31,0,0,0,0,31,0,4,0,0,0
0,0,0,0,5,4,0,0,0,0,5,4,0,0,0,0
0,0,0,0,0,0,5,0,4,4,0,0,0,0,0,0
0,0,0,0,0,0,0,0,0,0,0,0,0,0,0,0
0,0,0,0,0,0,0,0,0,0,0,0,0,0,0,0
0,0,0,0,0,0,0,0,0,0,0,0,0,0,0,0
0,0,0,0,0,0,0,0,0,0,0,0,0,0,0,0
0,0,0,0,0,0,0,0,0,0,0,0,0,0,0,0
0,0,0,0,0,0,0,0,0,0,0,0,0,0,0,0
0,0,0,0,0,0,0,0,0,0,0,0,0,0,0,0
:endlayer
layer: 24
0,0,0,0,0,0,4,4,4,4,0,0,0,0,0,0
0,0,0,0,4,4,4,4,4,4,4,5,0,0,0,0
0,0,0,4,4,4,4,4,4,4,4,5,4,0,0,0
0,0,4,4,4,4,4,4,34,4,4,4,4,4,0,0
0,4,4,4,6,4,4,4,0,5,4,4,4,4,4,0
0,4,4,4,4,4,4,4,0,6,4,4,4,4,4,0
0,4,4,4,4,4,4,4,0,6,4,4,4,4,4,0
0,5,4,4,4,4,4,4,4,4,4,4,4,5,5,0
0,0,4,4,4,4,4,4,4,4,4,4,4,4,0,0
0,0,0,4,4,4,4,4,4,4,5,6,4,0,0,0
0,0,0,0,4,4,5,4,4,4,4,4,0,0,0,0
0,0,0,0,0,0,4,4,4,4,0,0,0,0,0,0
0,0,0,0,0,0,0,0,0,0,0,0,0,0,0,0
0,0,0,0,0,0,0,0,0,0,0,0,0,0,0,0
0,0,0,0,0,0,0,0,0,0,0,0,0,0,0,0
0,0,0,0,0,0,0,0,0,0,0,0,0,0,0,0
0,0,0,0,0,0,0,0,0,0,0,0,0,0,0,0
0,0,0,0,0,0,0,0,0,0,0,0,0,0,0,0
0,0,0,0,0,0,0,0,0,0,0,0,0,0,0,0
:endlayer
layer: 25
0,0,0,0,0,0,4,4,4,4,0,0,0,0,0,0
0,0,0,0,4,4,0,0,0,0,4,4,0,0,0,0
0,0,0,4,0,0,0,0,0,0,0,0,4,0,0,0
0,0,4,4,0,0,0,0,0,0,0,0,4,4,0,0
0,4,0,0,0,0,0,0,0,0,0,0,0,0,4,0
0,4,0,0,0,0,0,0,0,0,0,0,0,0,4,0
0,5,0,0,0,0,0,0,0,0,0,0,0,0,5,0
0,4,0,0,0,0,0,0,0,0,0,0,0,4,4,0
0,0,4,0,0,0,0,0,0,0,0,0,0,4,0,0
0,0,0,4,0,0,0,0,0,0,0,0,4,0,0,0
0,0,0,0,4,4,0,0,0,0,4,4,0,0,0,0
0,0,0,0,0,0,4,4,4,4,0,0,0,0,0,0
0,0,0,0,0,0,0,0,0,0,0,0,0,0,0,0
0,0,0,0,0,0,0,0,0,0,0,0,0,0,0,0
0,0,0,0,0,0,0,0,0,0,0,0,0,0,0,0
0,0,0,0,0,0,0,0,0,0,0,0,0,0,0,0
0,0,0,0,0,0,0,0,0,0,0,0,0,0,0,0
0,0,0,0,0,0,0,0,0,0,0,0,0,0,0,0
0,0,0,0,0,0,0,0,0,0,0,0,0,0,0,0
:endlayer
layer: 26
0,0,0,0,0,0,4,0,4,0,0,0,0,0,0,0
0,0,0,0,4,0,0,0,0,0,4,0,0,0,0,0
0,0,0,0,0,0,0,0,0,0,0,0,4,0,0,0
0,0,4,0,0,0,0,0,0,0,0,0,0,0,0,0
0,0,0,0,0,0,0,0,0,0,0,0,0,0,4,0
0,4,0,0,0,0,0,0,0,0,0,0,0,0,0,0
0,0,0,0,0,0,0,0,0,0,0,0,0,0,4,0
0,4,0,0,0,0,0,0,0,0,0,0,0,0,0,0
0,0,0,0,0,0,0,0,0,0,0,0,0,4,0,0
0,0,0,4,0,0,0,0,0,0,0,0,0,0,0,0
0,0,0,0,0,4,0,0,0,0,0,4,0,0,0,0
0,0,0,0,0,0,0,4,0,4,0,0,0,0,0,0
0,0,0,0,0,0,0,0,0,0,0,0,0,0,0,0
0,0,0,0,0,0,0,0,0,0,0,0,0,0,0,0
0,0,0,0,0,0,0,0,0,0,0,0,0,0,0,0
0,0,0,0,0,0,0,0,0,0,0,0,0,0,0,0
0,0,0,0,0,0,0,0,0,0,0,0,0,0,0,0
0,0,0,0,0,0,0,0,0,0,0,0,0,0,0,0
0,0,0,0,0,0,0,0,0,0,0,0,0,0,0,0
:endlayer
layer: 27
0,0,0,0,0,0,0,0,0,0,0,0,0,0,0,0
0,0,0,0,41,0,0,0,0,0,41,0,0,0,0,0
0,0,0,0,0,0,0,0,0,0,0,0,0,0,0,0
0,0,0,0,0,0,0,0,0,0,0,0,0,0,0,0
0,0,0,0,0,0,0,0,0,0,0,0,0,0,0,0
0,0,0,0,0,0,0,0,0,0,0,0,0,0,0,0
0,0,0,0,0,0,0,0,0,0,0,0,0,0,41,0
0,41,0,0,0,0,0,0,0,0,0,0,0,0,0,0
0,0,0,0,0,0,0,0,0,0,0,0,0,0,0,0
0,0,0,0,0,0,0,0,0,0,0,0,0,0,0,0
0,0,0,0,0,41,0,0,0,0,0,41,0,0,0,0
0,0,0,0,0,0,0,0,0,0,0,0,0,0,0,0
0,0,0,0,0,0,0,0,0,0,0,0,0,0,0,0
0,0,0,0,0,0,0,0,0,0,0,0,0,0,0,0
0,0,0,0,0,0,0,0,0,0,0,0,0,0,0,0
0,0,0,0,0,0,0,0,0,0,0,0,0,0,0,0
0,0,0,0,0,0,0,0,0,0,0,0,0,0,0,0
0,0,0,0,0,0,0,0,0,0,0,0,0,0,0,0
0,0,0,0,0,0,0,0,0,0,0,0,0,0,0,0
:endlayer

#### RULES ####
rule:
plugin=vanillaBlocks
number=1
data:
JSON:{{"val":{"blockName":{"val":"minecraft:dirt","id":"ss"},"meta":{"val":"0","id":"pi"},"buildPass":{"val":"0","id":"pi"}},"id":"ct"}}
:enddata
:endrule

rule:
plugin=vanillaBlocks
number=2
data:
JSON:{{"val":{"blockName":{"val":"minecraft:cobblestone","id":"ss"},"meta":{"val":"0","id":"pi"},"buildPass":{"val":"0","id":"pi"}},"id":"ct"}}
:enddata
:endrule

rule:
plugin=vanillaBlocks
number=3
data:
JSON:{{"val":{"blockName":{"val":"minecraft:water","id":"ss"},"meta":{"val":"0","id":"pi"},"buildPass":{"val":"0","id":"pi"}},"id":"ct"}}
:enddata
:endrule

rule:
plugin=vanillaBlocks
number=4
data:
JSON:{{"val":{"blockName":{"val":"minecraft:stonebrick","id":"ss"},"meta":{"val":"0","id":"pi"},"buildPass":{"val":"0","id":"pi"}},"id":"ct"}}
:enddata
:endrule

rule:
plugin=vanillaBlocks
number=5
data:
JSON:{{"val":{"blockName":{"val":"minecraft:stonebrick","id":"ss"},"meta":{"val":"1","id":"pi"},"buildPass":{"val":"0","id":"pi"}},"id":"ct"}}
:enddata
:endrule

rule:
plugin=vanillaBlocks
number=6
data:
JSON:{{"val":{"blockName":{"val":"minecraft:stonebrick","id":"ss"},"meta":{"val":"2","id":"pi"},"buildPass":{"val":"0","id":"pi"}},"id":"ct"}}
:enddata
:endrule

rule:
plugin=vanillaBlocks
number=7
data:
JSON:{{"val":{"blockName":{"val":"minecraft:grass","id":"ss"},"meta":{"val":"0","id":"pi"},"buildPass":{"val":"0","id":"pi"}},"id":"ct"}}
:enddata
:endrule

rule:
plugin=vanillaBlocks
number=8
data:
JSON:{{"val":{"blockName":{"val":"minecraft:gravel","id":"ss"},"meta":{"val":"0","id":"pi"},"buildPass":{"val":"0","id":"pi"}},"id":"ct"}}
:enddata
:endrule

rule:
plugin=vanillaDoors
number=9
data:
JSON:{{"val":{"sideFlag":{"val":"15","id":"pb"},"blockName":{"val":"minecraft:iron_door","id":"ss"},"meta":{"val":"5","id":"pi"},"buildPass":{"val":"2","id":"pi"}},"id":"ct"}}
:enddata
:endrule

rule:
plugin=vanillaBlocks
number=10
data:
JSON:{{"val":{"blockName":{"val":"minecraft:wooden_slab","id":"ss"},"meta":{"val":"0","id":"pi"},"buildPass":{"val":"0","id":"pi"}},"id":"ct"}}
:enddata
:endrule

rule:
plugin=vanillaInventory
number=11
data:
JSON:{{"val":{"lootLevel":{"val":"0","id":"pi"},"inventoryData":{"val":{"length":{"val":"27","id":"pi"},"inventoryContents":{"val":[],"id":"ls"}},"id":"ct"},"teData":{"val":{"id":{"val":"Chest","id":"ss"},"z":{"val":"-31","id":"pi"},"y":{"val":"12","id":"pi"},"x":{"val":"-491","id":"pi"}},"id":"ct"},"blockName":{"val":"minecraft:chest","id":"ss"},"meta":{"val":"2","id":"pi"},"buildPass":{"val":"0","id":"pi"}},"id":"ct"}}
:enddata
:endrule

rule:
plugin=awAutomationLogic
number=12
data:
JSON:{{"val":{"teData":{"val":{"id":{"val":"Furnace","id":"ss"},"Items":{"val":[],"id":"ls"},"BurnTime":{"val":"0","id":"ps"},"z":{"val":"-31","id":"pi"},"y":{"val":"12","id":"pi"},"CookTime":{"val":"0","id":"ps"},"x":{"val":"-485","id":"pi"}},"id":"ct"},"blockName":{"val":"minecraft:furnace","id":"ss"},"meta":{"val":"5","id":"pi"},"buildPass":{"val":"0","id":"pi"}},"id":"ct"}}
:enddata
:endrule

rule:
plugin=vanillaInventory
number=13
data:
JSON:{{"val":{"lootLevel":{"val":"0","id":"pi"},"inventoryData":{"val":{"length":{"val":"27","id":"pi"},"inventoryContents":{"val":[],"id":"ls"}},"id":"ct"},"teData":{"val":{"id":{"val":"Chest","id":"ss"},"z":{"val":"-29","id":"pi"},"y":{"val":"12","id":"pi"},"x":{"val":"-493","id":"pi"}},"id":"ct"},"blockName":{"val":"minecraft:chest","id":"ss"},"meta":{"val":"2","id":"pi"},"buildPass":{"val":"0","id":"pi"}},"id":"ct"}}
:enddata
:endrule

rule:
plugin=vanillaBlocks
number=14
data:
JSON:{{"val":{"blockName":{"val":"minecraft:oak_stairs","id":"ss"},"meta":{"val":"1","id":"pi"},"buildPass":{"val":"0","id":"pi"}},"id":"ct"}}
:enddata
:endrule

rule:
plugin=vanillaBlocks
number=15
data:
JSON:{{"val":{"blockName":{"val":"minecraft:oak_stairs","id":"ss"},"meta":{"val":"2","id":"pi"},"buildPass":{"val":"0","id":"pi"}},"id":"ct"}}
:enddata
:endrule

rule:
plugin=vanillaBlocks
number=16
data:
JSON:{{"val":{"blockName":{"val":"minecraft:fence","id":"ss"},"meta":{"val":"0","id":"pi"},"buildPass":{"val":"0","id":"pi"}},"id":"ct"}}
:enddata
:endrule

rule:
plugin=vanillaDoors
number=17
data:
JSON:{{"val":{"sideFlag":{"val":"15","id":"pb"},"blockName":{"val":"minecraft:wooden_door","id":"ss"},"meta":{"val":"4","id":"pi"},"buildPass":{"val":"2","id":"pi"}},"id":"ct"}}
:enddata
:endrule

rule:
plugin=vanillaInventory
number=18
data:
JSON:{{"val":{"lootLevel":{"val":"0","id":"pi"},"inventoryData":{"val":{"length":{"val":"27","id":"pi"},"inventoryContents":{"val":[],"id":"ls"}},"id":"ct"},"teData":{"val":{"id":{"val":"Chest","id":"ss"},"z":{"val":"-27","id":"pi"},"y":{"val":"12","id":"pi"},"x":{"val":"-493","id":"pi"}},"id":"ct"},"blockName":{"val":"minecraft:chest","id":"ss"},"meta":{"val":"2","id":"pi"},"buildPass":{"val":"0","id":"pi"}},"id":"ct"}}
:enddata
:endrule

rule:
plugin=vanillaBlocks
number=19
data:
JSON:{{"val":{"blockName":{"val":"minecraft:oak_stairs","id":"ss"},"meta":{"val":"0","id":"pi"},"buildPass":{"val":"0","id":"pi"}},"id":"ct"}}
:enddata
:endrule

rule:
plugin=vanillaInventory
number=20
data:
JSON:{{"val":{"lootLevel":{"val":"0","id":"pi"},"inventoryData":{"val":{"length":{"val":"27","id":"pi"},"inventoryContents":{"val":[],"id":"ls"}},"id":"ct"},"teData":{"val":{"id":{"val":"Chest","id":"ss"},"z":{"val":"-25","id":"pi"},"y":{"val":"12","id":"pi"},"x":{"val":"-492","id":"pi"}},"id":"ct"},"blockName":{"val":"minecraft:chest","id":"ss"},"meta":{"val":"2","id":"pi"},"buildPass":{"val":"0","id":"pi"}},"id":"ct"}}
:enddata
:endrule

rule:
plugin=vanillaInventory
number=21
data:
JSON:{{"val":{"lootLevel":{"val":"0","id":"pi"},"inventoryData":{"val":{"length":{"val":"27","id":"pi"},"inventoryContents":{"val":[],"id":"ls"}},"id":"ct"},"teData":{"val":{"id":{"val":"Chest","id":"ss"},"z":{"val":"-23","id":"pi"},"y":{"val":"12","id":"pi"},"x":{"val":"-490","id":"pi"}},"id":"ct"},"blockName":{"val":"minecraft:chest","id":"ss"},"meta":{"val":"4","id":"pi"},"buildPass":{"val":"0","id":"pi"}},"id":"ct"}}
:enddata
:endrule

rule:
plugin=vanillaDoors
number=22
data:
JSON:{{"val":{"sideFlag":{"val":"15","id":"pb"},"blockName":{"val":"minecraft:iron_door","id":"ss"},"meta":{"val":"7","id":"pi"},"buildPass":{"val":"2","id":"pi"}},"id":"ct"}}
:enddata
:endrule

rule:
plugin=vanillaBlocks
number=23
data:
JSON:{{"val":{"blockName":{"val":"minecraft:torch","id":"ss"},"meta":{"val":"3","id":"pi"},"buildPass":{"val":"2","id":"pi"}},"id":"ct"}}
:enddata
:endrule

rule:
plugin=vanillaDoors
number=24
data:
JSON:{{"val":{"sideFlag":{"val":"0","id":"pb"},"blockName":{"val":"minecraft:iron_door","id":"ss"},"meta":{"val":"15","id":"pi"},"buildPass":{"val":"2","id":"pi"}},"id":"ct"}}
:enddata
:endrule

rule:
plugin=vanillaBlocks
number=25
data:
JSON:{{"val":{"blockName":{"val":"minecraft:carpet","id":"ss"},"meta":{"val":"12","id":"pi"},"buildPass":{"val":"2","id":"pi"}},"id":"ct"}}
:enddata
:endrule

rule:
plugin=vanillaDoors
number=26
data:
JSON:{{"val":{"sideFlag":{"val":"0","id":"pb"},"blockName":{"val":"minecraft:wooden_door","id":"ss"},"meta":{"val":"15","id":"pi"},"buildPass":{"val":"2","id":"pi"}},"id":"ct"}}
:enddata
:endrule

rule:
plugin=vanillaDoors
number=27
data:
JSON:{{"val":{"sideFlag":{"val":"0","id":"pb"},"blockName":{"val":"minecraft:iron_door","id":"ss"},"meta":{"val":"15","id":"pi"},"buildPass":{"val":"2","id":"pi"}},"id":"ct"}}
:enddata
:endrule

rule:
plugin=vanillaBlocks
number=28
data:
JSON:{{"val":{"blockName":{"val":"minecraft:lever","id":"ss"},"meta":{"val":"1","id":"pi"},"buildPass":{"val":"2","id":"pi"}},"id":"ct"}}
:enddata
:endrule

rule:
plugin=vanillaBlocks
number=29
data:
JSON:{{"val":{"blockName":{"val":"minecraft:torch","id":"ss"},"meta":{"val":"2","id":"pi"},"buildPass":{"val":"2","id":"pi"}},"id":"ct"}}
:enddata
:endrule

rule:
plugin=vanillaBlocks
number=30
data:
JSON:{{"val":{"blockName":{"val":"minecraft:lever","id":"ss"},"meta":{"val":"2","id":"pi"},"buildPass":{"val":"2","id":"pi"}},"id":"ct"}}
:enddata
:endrule

rule:
plugin=vanillaBlocks
number=31
data:
JSON:{{"val":{"blockName":{"val":"minecraft:torch","id":"ss"},"meta":{"val":"4","id":"pi"},"buildPass":{"val":"2","id":"pi"}},"id":"ct"}}
:enddata
:endrule

rule:
plugin=vanillaBlocks
number=32
data:
JSON:{{"val":{"blockName":{"val":"minecraft:torch","id":"ss"},"meta":{"val":"1","id":"pi"},"buildPass":{"val":"2","id":"pi"}},"id":"ct"}}
:enddata
:endrule

rule:
plugin=vanillaBlocks
number=33
data:
JSON:{{"val":{"blockName":{"val":"minecraft:ladder","id":"ss"},"meta":{"val":"3","id":"pi"},"buildPass":{"val":"2","id":"pi"}},"id":"ct"}}
:enddata
:endrule

rule:
plugin=vanillaBlocks
number=34
data:
JSON:{{"val":{"blockName":{"val":"minecraft:stone_brick_stairs","id":"ss"},"meta":{"val":"3","id":"pi"},"buildPass":{"val":"0","id":"pi"}},"id":"ct"}}
:enddata
:endrule

rule:
plugin=vanillaBlocks
number=35
data:
JSON:{{"val":{"blockName":{"val":"minecraft:stone_brick_stairs","id":"ss"},"meta":{"val":"7","id":"pi"},"buildPass":{"val":"0","id":"pi"}},"id":"ct"}}
:enddata
:endrule

rule:
plugin=vanillaBlocks
number=36
data:
JSON:{{"val":{"blockName":{"val":"minecraft:stone_slab","id":"ss"},"meta":{"val":"5","id":"pi"},"buildPass":{"val":"0","id":"pi"}},"id":"ct"}}
:enddata
:endrule

rule:
plugin=vanillaBlocks
number=37
data:
JSON:{{"val":{"blockName":{"val":"minecraft:stone_brick_stairs","id":"ss"},"meta":{"val":"1","id":"pi"},"buildPass":{"val":"0","id":"pi"}},"id":"ct"}}
:enddata
:endrule

rule:
plugin=vanillaBlocks
number=38
data:
JSON:{{"val":{"blockName":{"val":"minecraft:oak_stairs","id":"ss"},"meta":{"val":"3","id":"pi"},"buildPass":{"val":"0","id":"pi"}},"id":"ct"}}
:enddata
:endrule

rule:
plugin=vanillaBlocks
number=39
data:
JSON:{{"val":{"blockName":{"val":"minecraft:wooden_slab","id":"ss"},"meta":{"val":"8","id":"pi"},"buildPass":{"val":"0","id":"pi"}},"id":"ct"}}
:enddata
:endrule

rule:
plugin=vanillaBlocks
number=40
data:
JSON:{{"val":{"blockName":{"val":"minecraft:planks","id":"ss"},"meta":{"val":"0","id":"pi"},"buildPass":{"val":"0","id":"pi"}},"id":"ct"}}
:enddata
:endrule

rule:
plugin=vanillaBlocks
number=41
data:
JSON:{{"val":{"blockName":{"val":"minecraft:torch","id":"ss"},"meta":{"val":"5","id":"pi"},"buildPass":{"val":"2","id":"pi"}},"id":"ct"}}
:enddata
:endrule

#### ENTITIES ####
