# Ancient Warfare Structure Template File
# Auto-generated structure template file. created on: 12/4/2014 at: 10:18:31
# Lines beginning with # denote comments

header:
version=2.1
name=wall_moat_corner
size=16,6,16
offset=15,1,15
:endheader

#### VALIDATION ####
validation:
type=ground
survival=false
worldGenEnabled=false
unique=false
preserveBlocks=false
selectionWeight=0
clusterValue=0
minDuplicateDistance=0
dimensionWhiteList=false
dimensionList=
biomeWhiteList=false
biomeList=
leveling=0
fill=0
border=0
validTargetBlocks=
blockSwap=false
data:
:enddata
:endvalidation

#### LAYERS ####
layer: 0
1,2,2,2,2,2,3,3,2,1,1,1,1,4,4,4
2,2,2,2,2,2,3,3,2,1,2,2,1,4,4,4
2,2,2,2,2,2,3,3,2,1,2,2,1,4,4,4
2,2,2,2,2,2,3,3,2,1,2,2,1,4,4,4
2,2,2,2,2,2,3,3,2,1,2,2,1,4,4,4
2,2,2,2,2,2,3,3,2,1,2,2,1,4,4,4
3,3,3,3,3,3,3,3,3,3,3,3,3,4,4,4
3,3,3,3,3,3,3,3,3,3,3,3,3,4,4,4
2,2,2,2,2,2,3,3,2,1,2,2,1,4,4,4
1,1,1,1,1,1,1,1,1,1,1,1,1,4,4,4
1,2,2,2,2,2,2,2,2,2,2,2,1,4,4,4
1,2,2,2,2,2,2,2,2,2,2,2,1,4,4,4
1,1,1,1,1,1,1,1,1,1,1,1,1,4,4,4
4,4,4,4,4,4,4,4,4,4,4,4,4,4,4,4
4,4,4,4,4,4,4,4,4,4,4,4,4,4,4,4
4,4,4,4,4,4,4,4,4,4,4,4,4,4,4,4
:endlayer
layer: 1
0,0,0,0,0,0,0,0,0,5,5,5,5,0,0,0
0,0,0,0,0,0,0,0,0,5,0,0,5,0,0,0
0,0,0,0,0,0,0,0,0,5,0,0,5,0,0,0
0,0,0,0,0,0,0,0,0,5,0,0,5,0,0,0
0,0,0,0,0,0,0,0,0,5,0,0,5,0,0,0
0,0,0,0,0,0,0,0,0,5,0,0,5,0,0,0
0,0,0,0,0,0,0,0,0,5,0,0,5,0,0,0
0,0,0,0,0,0,0,0,0,5,0,0,5,0,0,0
0,0,0,0,0,0,0,0,0,5,0,0,5,0,0,0
5,5,5,5,5,5,5,5,5,5,5,5,5,0,0,0
5,0,0,0,0,0,0,0,0,0,0,0,5,0,0,0
5,0,0,0,0,0,0,0,0,0,0,0,5,0,0,0
5,5,5,5,5,5,5,5,5,5,5,5,5,0,0,0
0,0,0,0,0,0,0,0,0,0,0,0,0,0,0,0
0,0,0,0,0,0,0,0,0,0,0,0,0,0,0,0
0,0,0,0,0,0,0,0,0,0,0,0,0,0,0,0
:endlayer
layer: 2
0,0,0,0,0,0,0,0,0,5,5,5,5,0,0,0
0,0,0,0,0,0,0,0,0,5,0,0,5,0,0,0
0,0,0,0,0,0,0,0,0,5,0,0,5,0,0,0
0,0,0,0,0,0,0,0,0,5,0,0,5,0,0,0
0,0,0,0,0,0,0,0,0,5,0,0,5,0,0,0
0,0,0,0,0,0,0,0,0,5,0,0,5,0,0,0
0,0,0,0,0,0,0,0,0,5,0,0,5,0,0,0
0,0,0,0,0,0,0,0,0,5,0,0,5,0,0,0
0,0,0,0,0,0,0,0,0,5,0,0,5,0,0,0
5,5,5,5,5,5,5,5,5,5,5,5,5,0,0,0
5,0,0,0,0,0,0,0,0,0,0,0,5,0,0,0
5,0,0,0,0,0,0,0,0,0,0,0,5,0,0,0
5,5,5,5,5,5,5,5,5,5,5,5,5,0,0,0
0,0,0,0,0,0,0,0,0,0,0,0,0,0,0,0
0,0,0,0,0,0,0,0,0,0,0,0,0,0,0,0
0,0,0,0,0,0,0,0,0,0,0,0,0,0,0,0
:endlayer
layer: 3
0,0,0,0,0,0,0,0,0,5,5,5,5,0,0,0
0,0,0,0,0,0,0,0,0,5,0,0,5,0,0,0
0,0,0,0,0,0,0,0,0,5,0,0,5,0,0,0
0,0,0,0,0,0,0,0,0,5,0,0,5,0,0,0
0,0,0,0,0,0,0,0,0,5,0,0,5,0,0,0
0,0,0,0,0,0,0,0,0,5,0,0,5,0,0,0
0,0,0,0,0,0,0,0,0,5,0,0,5,0,0,0
0,0,0,0,0,0,0,0,0,5,0,0,5,0,0,0
0,0,0,0,0,0,0,0,0,5,0,0,5,0,0,0
5,5,5,5,5,5,5,5,5,5,5,5,5,0,0,0
5,0,0,0,0,0,0,0,0,0,0,0,5,0,0,0
5,0,0,0,0,0,0,0,0,0,0,0,5,0,0,0
5,5,5,5,5,5,5,5,5,5,5,5,5,0,0,0
0,0,0,0,0,0,0,0,0,0,0,0,0,0,0,0
0,0,0,0,0,0,0,0,0,0,0,0,0,0,0,0
0,0,0,0,0,0,0,0,0,0,0,0,0,0,0,0
:endlayer
layer: 4
0,0,0,0,0,0,0,0,5,5,5,5,5,5,0,0
0,0,0,0,0,0,0,0,5,5,5,5,5,5,0,0
0,0,0,0,0,0,0,0,5,5,5,5,5,5,0,0
0,0,0,0,0,0,0,0,5,5,5,5,5,5,0,0
0,0,0,0,0,0,0,0,5,5,5,5,5,5,0,0
0,0,0,0,0,0,0,0,5,5,5,5,5,5,0,0
0,0,0,0,0,0,0,0,5,5,5,5,5,5,0,0
0,0,0,0,0,0,0,0,5,5,5,5,5,5,0,0
5,5,5,5,5,5,5,5,5,5,5,5,5,5,0,0
5,5,5,5,5,5,5,5,5,5,5,5,5,5,0,0
5,5,5,5,5,5,5,5,5,5,5,5,5,5,0,0
5,5,5,5,5,5,5,5,5,5,5,5,5,5,0,0
5,5,5,5,5,5,5,5,5,5,5,5,5,5,0,0
5,5,5,5,5,5,5,5,5,5,5,5,5,5,0,0
0,0,0,0,0,0,0,0,0,0,0,0,0,0,0,0
0,0,0,0,0,0,0,0,0,0,0,0,0,0,0,0
:endlayer
layer: 5
0,0,0,0,0,0,0,0,5,0,0,0,0,5,0,0
0,0,0,0,0,0,0,0,5,0,0,0,0,5,0,0
0,0,0,0,0,0,0,0,5,0,0,0,0,5,0,0
0,0,0,0,0,0,0,0,5,0,0,0,0,5,0,0
0,0,0,0,0,0,0,0,5,0,0,0,0,5,0,0
0,0,0,0,0,0,0,0,5,0,0,0,0,5,0,0
0,0,0,0,0,0,0,0,5,0,0,0,0,5,0,0
0,0,0,0,0,0,0,0,5,0,0,0,0,5,0,0
5,5,5,5,5,5,5,5,5,0,0,0,0,5,0,0
0,0,0,0,0,0,0,0,0,0,0,0,0,5,0,0
0,0,0,0,0,0,0,0,0,0,0,0,0,5,0,0
0,0,0,0,0,0,0,0,0,0,0,0,0,5,0,0
0,0,0,0,0,0,0,0,0,0,0,0,0,5,0,0
5,5,5,5,5,5,5,5,5,5,5,5,5,5,0,0
0,0,0,0,0,0,0,0,0,0,0,0,0,0,0,0
0,0,0,0,0,0,0,0,0,0,0,0,0,0,0,0
:endlayer

#### RULES ####
rule:
plugin=vanillaBlocks
number=1
data:
JSON:{{"val":{"blockName":{"val":"minecraft:dirt","id":"ss"},"meta":{"val":"0","id":"pi"},"buildPass":{"val":"0","id":"pi"}},"id":"ct"}}
:enddata
:endrule

rule:
plugin=vanillaBlocks
number=2
data:
JSON:{{"val":{"blockName":{"val":"minecraft:grass","id":"ss"},"meta":{"val":"0","id":"pi"},"buildPass":{"val":"0","id":"pi"}},"id":"ct"}}
:enddata
:endrule

rule:
plugin=vanillaBlocks
number=3
data:
JSON:{{"val":{"blockName":{"val":"minecraft:gravel","id":"ss"},"meta":{"val":"0","id":"pi"},"buildPass":{"val":"0","id":"pi"}},"id":"ct"}}
:enddata
:endrule

rule:
plugin=vanillaBlocks
number=4
data:
JSON:{{"val":{"blockName":{"val":"minecraft:water","id":"ss"},"meta":{"val":"0","id":"pi"},"buildPass":{"val":"0","id":"pi"}},"id":"ct"}}
:enddata
:endrule

rule:
plugin=vanillaBlocks
number=5
data:
JSON:{{"val":{"blockName":{"val":"minecraft:stonebrick","id":"ss"},"meta":{"val":"0","id":"pi"},"buildPass":{"val":"0","id":"pi"}},"id":"ct"}}
:enddata
:endrule

#### ENTITIES ####
