# Ancient Warfare Structure Template File
# Auto-generated structure template file. created on: 12/3/2018 at: 12:14:20
# Lines beginning with # denote comments

header:
version=2.8
name=GiantMushroomVindicators
mods=
size=25,41,25
offset=13,11,24
:endheader

#### VALIDATION ####
validation:
type=ground
survival=false
worldGenEnabled=true
unique=false
preserveBlocks=false
selectionWeight=30
clusterValue=30
minDuplicateDistance=500
dimensionWhiteList=false
dimensionList=
biomeWhiteList=true
biomeList=minecraft:swampland,minecraft:mushroom_island_shore,biomesoplenty:bayou,biomesoplenty:dead_swamp,biomesoplenty:marsh,biomesoplenty:mangrove
leveling=0
fill=0
border=0
blockSwap=false
:endvalidation

#### LAYERS ####
layer: 0
1,1,1,1,1,1,1,1,1,1,1,1,1,1,1,1,1,1,1,1,1,1,1,1,1
1,1,1,1,1,1,1,1,1,1,1,1,1,1,1,1,1,1,1,1,1,1,1,1,1
1,1,1,1,1,1,1,1,1,1,1,1,1,1,1,1,1,1,1,1,1,1,1,1,1
1,1,1,1,1,1,1,1,1,1,1,1,1,1,1,1,1,1,1,1,1,1,1,1,1
1,1,1,1,1,1,1,1,1,1,1,1,1,1,1,1,1,1,1,1,1,1,1,1,1
1,1,1,1,1,1,1,1,1,1,1,1,1,1,1,1,1,1,1,1,1,1,1,1,1
1,1,1,1,1,1,1,1,1,1,1,1,1,1,1,1,1,1,1,1,1,1,1,1,1
1,1,1,1,1,1,1,1,1,1,1,1,1,1,1,1,1,1,1,1,1,1,1,1,1
1,1,1,1,1,1,1,1,1,1,1,1,1,1,1,1,1,1,1,1,1,1,1,1,1
1,1,1,1,1,1,1,1,1,1,1,1,1,1,1,1,1,1,1,1,1,1,1,1,1
1,1,1,1,1,1,1,1,1,1,1,1,1,1,1,1,1,1,1,1,1,1,1,1,1
1,1,1,1,1,1,1,1,1,1,1,1,1,1,1,1,1,1,1,1,1,1,1,1,1
1,1,1,1,1,1,1,1,1,1,1,1,1,1,1,1,1,1,1,1,1,1,1,1,1
1,1,1,1,1,1,1,1,1,1,1,1,1,1,1,1,1,1,1,1,1,1,1,1,1
1,1,1,1,1,1,1,1,1,1,1,1,1,1,1,1,1,1,1,1,1,1,1,1,1
1,1,1,1,1,1,1,1,1,1,1,1,1,1,1,1,1,1,1,1,1,1,1,1,1
1,1,1,1,1,1,1,1,1,1,1,1,1,1,1,1,1,1,1,1,1,1,1,1,1
1,1,1,1,1,1,1,1,1,1,1,1,1,1,1,1,1,1,1,1,1,1,1,1,1
1,1,1,1,1,1,1,1,1,1,1,1,1,1,1,1,1,1,1,1,1,1,1,1,1
1,1,1,1,1,1,1,1,1,1,1,1,1,1,1,1,1,1,1,1,1,1,1,1,1
1,1,1,1,1,1,1,1,1,1,1,1,1,1,1,1,1,1,1,1,1,1,1,1,1
1,1,1,1,1,1,1,1,1,1,1,1,1,1,1,1,1,1,1,1,1,1,1,1,1
1,1,1,1,1,1,1,1,1,1,1,1,1,1,1,1,1,1,1,1,1,1,1,1,1
1,1,1,1,1,1,1,1,1,1,1,1,1,1,1,1,1,1,1,1,1,1,1,1,1
1,1,1,1,1,1,1,1,1,1,1,1,1,1,1,1,1,1,1,1,1,1,1,1,1
:endlayer
layer: 1
1,1,1,1,1,1,1,1,1,1,1,1,1,1,1,1,1,1,1,1,1,1,1,1,1
1,1,1,1,1,1,1,1,1,1,1,1,1,1,1,1,1,1,1,1,1,1,1,1,1
1,1,1,1,1,1,1,1,1,1,1,1,1,1,1,1,1,1,1,1,1,1,1,1,1
1,1,1,1,1,1,1,1,1,1,1,1,1,1,1,1,1,1,1,1,1,1,1,1,1
1,1,1,1,1,1,1,1,1,1,1,1,1,1,1,1,1,1,1,1,1,1,1,1,1
1,1,1,1,1,1,1,1,1,1,1,1,1,1,1,1,1,1,1,1,1,1,1,1,1
1,1,1,1,1,1,1,1,1,1,1,1,1,1,1,1,1,1,1,1,1,1,1,1,1
1,1,1,1,1,1,1,1,1,1,1,1,1,1,1,1,1,1,1,1,1,1,1,1,1
1,1,1,1,1,1,1,1,1,1,1,1,1,1,1,1,1,1,1,1,1,1,1,1,1
1,1,1,1,1,1,1,1,1,1,1,1,1,1,1,1,1,1,1,1,1,1,1,1,1
1,1,1,1,1,1,1,1,1,1,1,1,1,1,1,1,1,1,1,1,1,1,1,1,1
1,1,1,1,1,1,1,1,1,1,1,1,1,1,1,1,1,1,1,1,1,1,1,1,1
1,1,1,1,1,1,1,1,1,1,1,1,1,1,1,1,1,1,1,1,1,1,1,1,1
1,1,1,1,1,1,1,1,1,1,1,1,1,1,1,1,1,1,1,1,1,1,1,1,1
1,1,1,1,1,1,1,1,1,1,1,1,1,1,1,1,1,1,1,1,1,1,1,1,1
1,1,1,1,1,1,1,1,1,1,1,1,1,1,1,1,1,1,1,1,1,1,1,1,1
1,1,1,1,1,1,1,1,1,1,1,1,1,1,1,1,1,1,1,1,1,1,1,1,1
1,1,1,1,1,1,1,1,1,1,1,1,1,1,1,1,1,1,1,1,1,1,1,1,1
1,1,1,1,1,1,1,1,1,1,1,1,1,1,1,1,1,1,1,1,1,1,1,1,1
1,1,1,1,1,1,1,1,1,1,1,1,1,1,1,1,1,1,1,1,1,1,1,1,1
1,1,1,1,1,1,1,1,1,1,1,1,1,1,1,1,1,1,1,1,1,1,1,1,1
1,1,1,1,1,1,1,1,1,1,1,1,1,1,1,1,1,1,1,1,1,1,1,1,1
1,1,1,1,1,1,1,1,1,1,1,1,1,1,1,1,1,1,1,1,1,1,1,1,1
1,1,1,1,1,1,1,1,1,1,1,1,1,1,1,1,1,1,1,1,1,1,1,1,1
1,1,1,1,1,1,1,1,1,1,1,1,1,1,1,1,1,1,1,1,1,1,1,1,1
:endlayer
layer: 2
1,1,1,1,1,1,1,1,1,1,1,1,1,1,1,1,1,1,1,1,1,1,1,1,1
1,1,1,1,1,1,1,1,1,1,1,1,1,1,1,1,1,1,1,1,1,1,1,1,1
1,1,1,1,1,1,1,1,1,1,1,1,1,1,1,1,1,1,1,1,1,1,1,1,1
1,1,1,1,1,1,1,1,1,1,1,1,1,1,1,1,1,1,1,1,1,1,1,1,1
1,1,1,1,1,1,1,1,1,1,1,1,1,1,1,1,1,1,1,1,1,1,1,1,1
1,1,1,1,1,1,1,1,1,1,1,1,1,1,1,1,1,1,1,1,1,1,1,1,1
1,1,1,1,1,1,1,1,1,1,1,1,1,1,1,1,1,1,1,1,1,1,1,1,1
1,1,1,1,1,1,1,1,1,1,1,1,1,1,1,1,1,1,1,1,1,1,1,1,1
1,1,1,1,1,1,1,1,1,1,1,1,1,1,1,1,1,1,1,1,1,1,1,1,1
1,1,1,1,1,1,1,1,1,1,1,1,1,1,1,1,1,1,1,1,1,1,1,1,1
1,1,1,1,1,1,1,1,1,1,1,1,1,1,1,1,1,1,1,1,1,1,1,1,1
1,1,1,1,1,1,1,1,1,1,1,1,1,1,1,1,1,1,1,1,1,1,1,1,1
1,1,1,1,1,1,1,1,1,1,1,1,1,1,1,1,1,1,1,1,1,1,1,1,1
1,1,1,1,1,1,1,1,1,1,1,1,1,1,1,1,1,1,1,1,1,1,1,1,1
1,1,1,1,1,1,1,1,1,1,1,1,1,1,1,1,1,1,1,1,1,1,1,1,1
1,1,1,1,1,1,1,1,1,1,1,1,1,1,1,1,1,1,1,1,1,1,1,1,1
1,1,1,1,1,1,1,1,1,1,1,1,1,1,1,1,1,1,1,1,1,1,1,1,1
1,1,1,1,1,1,1,1,1,1,1,1,1,1,1,1,1,1,1,1,1,1,1,1,1
1,1,1,1,1,1,1,1,1,1,1,1,1,1,1,1,1,1,1,1,1,1,1,1,1
1,1,1,1,1,1,1,1,1,1,1,1,1,1,1,1,1,1,1,1,1,1,1,1,1
1,1,1,1,1,1,1,1,1,1,1,1,1,1,1,1,1,1,1,1,1,1,1,1,1
1,1,1,1,1,1,1,1,1,1,1,1,1,1,1,1,1,1,1,1,1,1,1,1,1
1,1,1,1,1,1,1,1,1,1,1,1,1,1,1,1,1,1,1,1,1,1,1,1,1
1,1,1,1,1,1,1,1,1,1,1,1,1,1,1,1,1,1,1,1,1,1,1,1,1
1,1,1,1,1,1,1,1,1,1,1,1,1,1,1,1,1,1,1,1,1,1,1,1,1
:endlayer
layer: 3
1,1,1,1,1,1,1,1,1,1,1,1,1,1,1,1,1,1,1,1,1,1,1,1,1
1,1,1,1,1,1,1,1,1,1,1,1,1,1,1,1,1,1,1,1,1,1,1,1,1
1,1,1,1,1,1,1,1,1,1,1,1,1,1,1,1,1,1,1,1,1,1,1,1,1
1,1,1,1,1,1,1,1,1,1,1,1,1,1,1,1,1,1,1,1,1,1,1,1,1
1,1,1,1,1,1,1,1,1,1,1,1,1,1,1,1,1,1,1,1,1,1,1,1,1
1,1,1,1,1,1,1,1,1,1,1,1,1,1,1,1,1,1,1,1,1,1,1,1,1
1,1,1,1,1,1,1,1,1,1,1,1,1,1,1,1,1,1,1,1,1,1,1,1,1
1,1,1,1,1,1,1,1,1,1,1,1,1,1,1,1,1,1,1,1,1,1,1,1,1
1,1,1,1,1,1,1,1,1,1,1,1,1,1,1,1,1,1,1,1,1,1,1,1,1
1,1,1,1,1,1,1,1,1,1,1,1,1,1,1,1,1,1,1,1,1,1,1,1,1
1,1,1,1,1,1,1,1,1,1,1,1,1,1,1,1,1,1,1,1,1,1,1,1,1
1,1,1,1,1,1,1,1,1,1,1,1,1,1,1,1,1,1,1,1,1,1,1,1,1
1,1,1,1,1,1,1,1,1,1,1,1,1,1,1,1,1,1,1,1,1,1,1,1,1
1,1,1,1,1,1,1,1,1,1,1,1,1,1,1,1,1,1,1,1,1,1,1,1,1
1,1,1,1,1,1,1,1,1,1,1,1,1,1,1,1,1,1,1,1,1,1,1,1,1
1,1,1,1,1,1,1,1,1,1,1,1,1,1,1,1,1,1,1,1,1,1,1,1,1
1,1,1,1,1,1,1,1,1,1,1,1,1,1,1,1,1,1,1,1,1,1,1,1,1
1,1,1,1,1,1,1,1,1,1,1,1,1,1,1,1,1,1,1,1,1,1,1,1,1
1,1,1,1,1,1,1,1,1,1,1,1,1,1,1,1,1,1,1,1,1,1,1,1,1
1,1,1,1,1,1,1,1,1,1,1,1,1,1,1,1,1,1,1,1,1,1,1,1,1
1,1,1,1,1,1,1,1,1,1,1,1,1,1,1,1,1,1,1,1,1,1,1,1,1
1,1,1,1,1,1,1,1,1,1,1,1,1,1,1,1,1,1,1,1,1,1,1,1,1
1,1,1,1,1,1,1,1,1,1,1,1,1,1,1,1,1,1,1,1,1,1,1,1,1
1,1,1,1,1,1,1,1,1,1,1,1,1,1,1,1,1,1,1,1,1,1,1,1,1
1,1,1,1,1,1,1,1,1,1,1,1,1,1,1,1,1,1,1,1,1,1,1,1,1
:endlayer
layer: 4
1,1,1,1,1,1,1,1,1,1,1,1,1,1,1,1,1,1,1,1,1,1,1,1,1
1,1,1,1,1,1,1,1,1,1,1,1,1,1,1,1,1,1,1,1,1,1,1,1,1
1,1,1,1,1,1,1,1,1,1,1,1,1,1,1,1,1,1,1,1,1,1,1,1,1
1,1,1,1,1,1,1,1,1,1,1,1,1,1,1,1,1,1,1,1,1,1,1,1,1
1,1,1,1,1,1,1,1,1,1,1,1,1,1,1,1,1,1,1,1,1,1,1,1,1
1,1,1,1,1,1,1,1,1,1,1,1,1,1,1,1,1,1,1,1,1,1,1,1,1
1,1,1,1,1,1,1,1,1,1,1,1,1,1,1,1,1,1,1,1,1,1,1,1,1
1,1,1,1,1,1,1,1,1,1,1,1,1,1,1,1,1,1,1,1,1,1,1,1,1
1,1,1,1,1,1,1,1,1,1,1,1,1,1,1,1,1,1,1,1,1,1,1,1,1
1,1,1,1,1,1,1,1,1,1,1,1,1,1,1,1,1,1,1,1,1,1,1,1,1
1,1,1,1,1,1,1,1,1,1,1,1,1,1,1,1,1,1,1,1,1,1,1,1,1
1,1,1,1,1,1,1,1,1,1,1,1,1,1,1,1,1,1,1,1,1,1,1,1,1
1,1,1,1,1,1,1,1,1,1,1,1,1,1,1,1,1,1,1,1,1,1,1,1,1
1,1,1,1,1,1,1,1,1,1,1,1,1,1,1,1,1,1,1,1,1,1,1,1,1
1,1,1,1,1,1,1,1,1,1,1,1,1,1,1,1,1,1,1,1,1,1,1,1,1
1,1,1,1,1,1,1,1,1,1,1,1,1,1,1,1,1,1,1,1,1,1,1,1,1
1,1,1,1,1,1,1,1,1,1,1,1,1,1,1,1,1,1,1,1,1,1,1,1,1
1,1,1,1,1,1,1,1,1,1,1,1,1,1,1,1,1,1,1,1,1,1,1,1,1
1,1,1,1,1,1,1,1,1,1,1,1,1,1,1,1,1,1,1,1,1,1,1,1,1
1,1,1,1,1,1,1,1,1,1,1,1,1,1,1,1,1,1,1,1,1,1,1,1,1
1,1,1,1,1,1,1,1,1,1,1,1,1,1,1,1,1,1,1,1,1,1,1,1,1
1,1,1,1,1,1,1,1,1,1,1,1,1,1,1,1,1,1,1,1,1,1,1,1,1
1,1,1,1,1,1,1,1,1,1,1,1,1,1,1,1,1,1,1,1,1,1,1,1,1
1,1,1,1,1,1,1,1,1,1,1,1,1,1,1,1,1,1,1,1,1,1,1,1,1
1,1,1,1,1,1,1,1,1,1,1,1,1,1,1,1,1,1,1,1,1,1,1,1,1
:endlayer
layer: 5
1,1,1,1,1,1,1,1,1,1,1,1,1,1,1,1,1,1,1,1,1,1,1,1,1
1,1,1,1,1,1,1,1,1,1,1,1,1,1,1,1,1,1,1,1,1,1,1,1,1
1,1,1,1,1,1,1,1,1,1,1,1,1,1,1,1,1,1,1,1,1,1,1,1,1
1,1,1,1,1,1,1,1,1,1,1,1,1,1,1,1,1,1,1,1,1,1,1,1,1
1,1,1,1,1,1,1,1,1,1,1,1,1,1,1,1,1,1,1,1,1,1,1,1,1
1,1,1,1,1,1,1,1,1,1,1,1,1,1,1,1,1,1,1,1,1,1,1,1,1
1,1,1,1,1,1,1,1,1,1,1,1,1,1,1,1,1,1,1,1,1,1,1,1,1
1,1,1,1,1,1,1,1,1,1,1,1,1,1,1,1,1,1,1,1,1,1,1,1,1
1,1,1,1,1,1,1,1,1,1,1,1,1,1,1,1,1,1,1,1,1,1,1,1,1
1,1,1,1,1,1,1,1,1,1,1,1,1,1,1,1,1,1,1,1,1,1,1,1,1
1,1,1,1,1,1,1,1,1,1,1,1,1,1,1,1,1,1,1,1,1,1,1,1,1
1,1,1,1,1,1,1,1,1,1,1,1,1,1,1,1,1,1,1,1,1,1,1,1,1
1,1,1,1,1,1,1,1,1,1,1,1,1,1,1,1,1,1,1,1,1,1,1,1,1
1,1,1,1,1,1,1,1,1,1,1,1,1,1,1,1,1,1,1,1,1,1,1,1,1
1,1,1,1,1,1,1,1,1,1,1,1,1,1,1,1,1,1,1,1,1,1,1,1,1
1,1,1,1,1,1,1,1,1,1,1,1,1,1,1,1,1,1,1,1,1,1,1,1,1
1,1,1,1,1,1,1,1,1,1,1,1,1,1,1,1,1,1,1,1,1,1,1,1,1
1,1,1,1,1,1,1,1,1,1,1,1,1,1,1,1,1,1,1,1,1,1,1,1,1
1,1,1,1,1,1,1,1,1,1,1,1,1,1,1,1,1,1,1,1,1,1,1,1,1
1,1,1,1,1,1,1,1,1,1,1,1,1,1,1,1,1,1,1,1,1,1,1,1,1
1,1,1,1,1,1,1,1,1,1,1,1,1,1,1,1,1,1,1,1,1,1,1,1,1
1,1,1,1,1,1,1,1,1,1,1,1,1,1,1,1,1,1,1,1,1,1,1,1,1
1,1,1,1,1,1,1,1,1,1,1,1,1,1,1,1,1,1,1,1,1,1,1,1,1
1,1,1,1,1,1,1,1,1,1,1,1,1,1,1,1,1,1,1,1,1,1,1,1,1
1,1,1,1,1,1,1,1,1,1,1,1,1,1,1,1,1,1,1,1,1,1,1,1,1
:endlayer
layer: 6
1,1,1,1,1,1,1,1,1,1,1,1,1,1,1,1,1,1,1,1,1,1,1,1,1
1,1,1,1,1,1,1,1,1,1,1,1,1,1,1,1,1,1,1,1,1,1,1,1,1
1,1,1,1,1,1,1,1,1,1,1,1,1,1,1,1,1,1,1,1,1,1,1,1,1
1,1,1,1,1,1,1,1,1,1,1,1,1,1,1,1,1,1,1,1,1,1,1,1,1
1,1,1,1,1,1,1,1,1,1,1,1,1,1,1,1,1,1,1,1,1,1,1,1,1
1,1,1,1,1,1,1,1,1,1,1,1,1,1,1,1,1,1,1,1,1,1,1,1,1
1,1,1,1,1,1,1,1,1,1,1,1,1,1,1,1,1,1,1,1,1,1,1,1,1
1,1,1,1,1,1,1,1,1,1,1,1,1,1,1,1,1,1,1,1,1,1,1,1,1
1,1,1,1,1,1,1,1,1,1,1,1,1,1,1,1,1,1,1,1,1,1,1,1,1
1,1,1,1,1,1,1,1,1,1,1,1,1,1,1,1,1,1,1,1,1,1,1,1,1
1,1,1,1,1,1,1,1,1,1,1,1,1,1,1,1,1,1,1,1,1,1,1,1,1
1,1,1,1,1,1,1,1,1,1,1,1,1,1,1,1,1,1,1,1,1,1,1,1,1
1,1,1,1,1,1,1,1,1,1,1,1,1,1,1,1,1,1,1,1,1,1,1,1,1
1,1,1,1,1,1,1,1,1,1,1,1,1,1,1,1,1,1,1,1,1,1,1,1,1
1,1,1,1,1,1,1,1,1,1,1,1,1,1,1,1,1,1,1,1,1,1,1,1,1
1,1,1,1,1,1,1,1,1,1,1,1,1,1,1,1,1,1,1,1,1,1,1,1,1
1,1,1,1,1,1,1,1,1,1,1,1,1,1,1,1,1,1,1,1,1,1,1,1,1
1,1,1,1,1,1,1,1,1,1,1,1,1,1,1,1,1,1,1,1,1,1,1,1,1
1,1,1,1,1,1,1,1,1,1,1,1,1,1,1,1,1,1,1,1,1,1,1,1,1
1,1,1,1,1,1,1,1,1,1,1,1,1,1,1,1,1,1,1,1,1,1,1,1,1
1,1,1,1,1,1,1,1,1,1,1,1,1,1,1,1,1,1,1,1,1,1,1,1,1
1,1,1,1,1,1,1,1,1,1,1,1,1,1,1,1,1,1,1,1,1,1,1,1,1
1,1,1,1,1,1,1,1,1,1,1,1,1,1,1,1,1,1,1,1,1,1,1,1,1
1,1,1,1,1,1,1,1,1,1,1,1,1,1,1,1,1,1,1,1,1,1,1,1,1
1,1,1,1,1,1,1,1,1,1,1,1,1,1,1,1,1,1,1,1,1,1,1,1,1
:endlayer
layer: 7
1,1,1,1,1,1,1,1,1,1,1,1,1,1,1,1,1,1,1,1,1,1,1,1,1
1,1,1,1,1,1,1,1,1,1,1,1,1,1,1,1,1,1,1,1,1,1,1,1,1
1,1,1,1,1,1,1,1,1,1,1,1,1,1,1,1,1,1,1,1,1,1,1,1,1
1,1,1,1,1,1,1,1,1,1,1,1,1,1,1,1,1,1,1,1,1,1,1,1,1
1,1,1,1,1,1,1,1,1,1,1,1,1,1,1,1,1,1,1,1,1,1,1,1,1
1,1,1,1,1,1,1,1,1,1,1,1,1,1,1,1,1,1,1,1,1,1,1,1,1
1,1,1,1,1,1,1,1,1,1,1,1,1,1,1,1,1,1,1,1,1,1,1,1,1
1,1,1,1,1,1,1,1,1,1,1,1,1,1,1,1,1,1,1,1,1,1,1,1,1
1,1,1,1,1,1,1,1,1,1,1,1,1,1,1,1,1,1,1,1,1,1,1,1,1
1,1,1,1,1,1,1,1,1,1,1,1,1,1,1,1,1,1,1,1,1,1,1,1,1
1,1,1,1,1,1,1,1,1,1,1,1,1,1,1,1,1,1,1,1,1,1,1,1,1
1,1,1,1,1,1,1,1,1,1,1,1,1,1,1,1,1,1,1,1,1,1,1,1,1
1,1,1,1,1,1,1,1,1,1,1,1,1,1,1,1,1,1,1,1,1,1,1,1,1
1,1,1,1,1,1,1,1,1,1,1,1,1,1,1,1,1,1,1,1,1,1,1,1,1
1,1,1,1,1,1,1,1,1,1,1,1,1,1,1,1,1,1,1,1,1,1,1,1,1
1,1,1,1,1,1,1,1,1,1,1,1,1,1,1,1,1,1,1,1,1,1,1,1,1
1,1,1,1,1,1,1,1,1,1,1,1,1,1,1,1,1,1,1,1,1,1,1,1,1
1,1,1,1,1,1,1,1,1,1,1,1,1,1,1,1,1,1,1,1,1,1,1,1,1
1,1,1,1,1,1,1,1,1,1,1,1,1,1,1,1,1,1,1,1,1,1,1,1,1
1,1,1,1,1,1,1,1,1,1,1,1,1,1,1,1,1,1,1,1,1,1,1,1,1
1,1,1,1,1,1,1,1,1,1,1,1,1,1,1,1,1,1,1,1,1,1,1,1,1
1,1,1,1,1,1,1,1,1,1,1,1,1,1,1,1,1,1,1,1,1,1,1,1,1
1,1,1,1,1,1,1,1,1,1,1,1,1,1,1,1,1,1,1,1,1,1,1,1,1
1,1,1,1,1,1,1,1,1,1,1,1,1,1,1,1,1,1,1,1,1,1,1,1,1
1,1,1,1,1,1,1,1,1,1,1,1,1,1,1,1,1,1,1,1,1,1,1,1,1
:endlayer
layer: 8
1,1,1,1,1,1,1,1,1,1,1,1,1,1,1,1,1,1,1,1,1,1,1,1,1
1,1,1,1,1,1,1,1,1,1,1,1,1,1,1,1,1,1,1,1,1,1,1,1,1
1,1,1,1,1,1,1,1,1,1,1,1,1,1,1,1,1,1,1,1,1,1,1,1,1
1,1,1,1,1,1,1,1,1,1,1,1,1,1,1,1,1,1,1,1,1,1,1,1,1
1,1,1,1,1,1,1,1,1,1,1,1,1,1,1,1,1,1,1,1,1,1,1,1,1
1,1,1,1,1,1,1,1,1,1,1,1,1,1,1,1,1,1,1,1,1,1,1,1,1
1,1,1,1,1,1,1,1,1,1,1,1,1,1,1,1,1,1,1,1,1,1,1,1,1
1,1,1,1,1,1,1,1,1,1,1,1,1,1,1,1,1,1,1,1,1,1,1,1,1
1,1,1,1,1,1,1,1,1,1,1,1,1,1,1,1,1,1,1,1,1,1,1,1,1
1,1,1,1,1,1,1,1,1,1,1,1,1,1,1,1,1,1,1,1,1,1,1,1,1
1,1,1,1,1,1,1,1,1,1,1,1,1,1,1,1,1,1,1,1,1,1,1,1,1
1,1,1,1,1,1,1,1,1,1,1,1,1,1,1,1,1,1,1,1,1,1,1,1,1
1,1,1,1,1,1,1,1,1,1,1,1,1,1,1,1,1,1,1,1,1,1,1,1,1
1,1,1,1,1,1,1,1,1,1,1,1,1,1,1,1,1,1,1,1,1,1,1,1,1
1,1,1,1,1,1,1,1,1,1,1,1,1,1,1,1,1,1,1,1,1,1,1,1,1
1,1,1,1,1,1,1,1,1,1,1,1,1,1,1,1,1,1,1,1,1,1,1,1,1
1,1,1,1,1,1,1,1,1,1,1,1,1,1,1,1,1,1,1,1,1,1,1,1,1
1,1,1,1,1,1,1,1,1,1,1,1,1,1,1,1,1,1,1,1,1,1,1,1,1
1,1,1,1,1,1,1,1,1,1,1,1,1,1,1,1,1,1,1,1,1,1,1,1,1
1,1,1,1,1,1,1,1,1,1,1,1,1,1,1,1,1,1,1,1,1,1,1,1,1
1,1,1,1,1,1,1,1,1,1,1,1,1,1,1,1,1,1,1,1,1,1,1,1,1
1,1,1,1,1,1,1,1,1,1,1,1,1,1,1,1,1,1,1,1,1,1,1,1,1
1,1,1,1,1,1,1,1,1,1,1,1,1,1,1,1,1,1,1,1,1,1,1,1,1
1,1,1,1,1,1,1,1,1,1,1,1,1,1,1,1,1,1,1,1,1,1,1,1,1
1,1,1,1,1,1,1,1,1,1,1,1,1,1,1,1,1,1,1,1,1,1,1,1,1
:endlayer
layer: 9
1,1,1,1,1,1,1,1,1,1,1,1,1,1,1,1,1,1,1,1,1,1,1,1,1
1,1,1,1,1,1,1,1,1,1,1,1,1,1,1,1,1,1,1,1,1,1,1,1,1
1,1,1,1,1,1,1,1,1,1,1,1,1,1,1,1,1,1,1,1,1,1,1,1,1
1,1,1,1,1,1,1,1,1,1,1,1,1,1,1,1,1,1,1,1,1,1,1,1,1
1,1,1,1,1,1,1,1,1,1,1,1,1,1,1,1,1,1,1,1,1,1,1,1,1
1,1,1,1,1,1,1,1,1,1,1,1,1,1,1,1,1,1,1,1,1,1,1,1,1
1,1,1,1,1,1,1,1,1,1,1,1,1,1,1,1,1,1,1,1,1,1,1,1,1
1,1,1,1,1,1,1,1,1,1,1,1,1,1,1,1,1,1,1,1,1,1,1,1,1
1,1,1,1,1,1,1,1,1,1,1,1,1,1,1,1,1,1,1,1,1,1,1,1,1
1,1,1,1,1,1,1,1,1,1,1,1,1,1,1,1,1,1,1,1,1,1,1,1,1
1,1,1,1,1,1,1,1,1,1,1,1,1,1,1,1,1,1,1,1,1,1,1,1,1
1,1,1,1,1,1,1,1,1,1,1,1,1,1,1,1,1,1,1,1,1,1,1,1,1
1,1,1,1,1,1,1,1,1,1,1,1,1,1,1,1,1,1,1,1,1,1,1,1,1
1,1,1,1,1,1,1,1,1,1,1,1,1,1,1,1,1,1,1,1,1,1,1,1,1
1,1,1,1,1,1,1,1,1,1,1,1,1,1,1,1,1,1,1,1,1,1,1,1,1
1,1,1,1,1,1,1,1,1,1,1,1,1,1,1,1,1,1,1,1,1,1,1,1,1
1,1,1,1,1,1,1,1,1,1,1,1,1,1,1,1,1,1,1,1,1,1,1,1,1
1,1,1,1,1,1,1,1,1,1,1,1,1,1,1,1,1,1,1,1,1,1,1,1,1
1,1,1,1,1,1,1,1,1,1,1,1,1,1,1,1,1,1,1,1,1,1,1,1,1
1,1,1,1,1,1,1,1,1,1,1,1,1,1,1,1,1,1,1,1,1,1,1,1,1
1,1,1,1,1,1,1,1,1,1,1,1,1,1,1,1,1,1,1,1,1,1,1,1,1
1,1,1,1,1,1,1,1,1,1,1,1,1,1,1,1,1,1,1,1,1,1,1,1,1
1,1,1,1,1,1,1,1,1,1,1,1,1,1,1,1,1,1,1,1,1,1,1,1,1
1,1,1,1,1,1,1,1,1,1,1,1,1,1,1,1,1,1,1,1,1,1,1,1,1
1,1,1,1,1,1,1,1,1,1,1,1,1,1,1,1,1,1,1,1,1,1,1,1,1
:endlayer
layer: 10
2,2,2,2,2,2,3,3,2,2,2,2,2,2,2,2,2,2,2,2,2,2,2,2,2
2,2,2,2,2,3,1,1,3,3,1,1,3,3,2,2,2,2,2,2,2,2,2,2,2
2,2,2,2,3,1,1,1,3,1,1,1,1,3,3,3,3,3,2,2,2,2,2,2,2
2,2,2,2,1,1,1,1,1,1,1,1,1,1,1,1,1,3,2,2,2,2,2,2,2
2,2,2,3,1,1,1,1,1,1,1,1,1,1,1,1,1,1,3,3,2,2,2,2,2
2,2,3,1,1,1,1,1,1,1,1,1,1,1,1,1,1,1,1,3,2,2,2,2,2
2,2,1,1,1,1,1,1,1,1,1,1,1,1,1,1,4,4,4,3,2,2,2,2,2
2,2,1,1,1,1,1,1,1,1,1,1,1,1,4,4,4,4,4,3,2,2,2,2,2
2,2,1,1,1,1,1,1,1,1,1,1,4,4,4,4,4,4,4,3,3,2,2,2,2
2,3,1,1,1,1,1,1,1,1,1,4,4,4,4,4,4,4,4,4,3,2,2,2,2
2,3,1,1,1,1,1,1,1,1,4,4,4,4,4,4,4,4,4,4,4,1,3,2,2
2,1,1,1,1,1,4,4,1,1,4,4,4,4,4,4,4,4,4,4,4,1,3,2,2
3,1,1,1,1,1,1,4,1,1,4,4,4,4,4,4,4,4,4,4,4,1,3,2,2
3,1,1,1,1,4,4,4,1,4,4,4,4,4,4,4,4,4,4,4,4,1,3,2,2
3,3,1,1,1,4,4,4,1,1,1,4,4,4,4,4,4,4,4,4,4,3,2,2,2
3,3,1,1,1,4,4,1,1,1,1,4,4,4,4,4,4,4,4,4,4,1,2,2,2
3,3,1,1,1,4,4,4,1,1,1,1,4,4,4,4,4,4,4,4,4,3,2,2,2
3,1,1,1,1,1,4,4,1,1,1,1,1,4,4,4,4,4,4,4,4,1,3,2,2
3,1,1,1,1,1,4,4,1,1,1,1,1,1,1,4,4,4,4,4,4,1,3,2,2
3,1,1,1,1,1,1,1,1,1,1,1,1,1,1,1,1,1,4,4,4,1,3,2,2
3,3,1,1,1,1,1,1,1,1,1,1,1,1,1,1,1,1,1,1,4,4,4,3,2
3,3,1,1,1,3,3,1,1,1,1,1,1,1,1,1,1,1,1,1,1,1,4,3,2
2,3,3,1,1,3,3,3,1,1,3,3,3,3,3,1,1,1,1,1,1,3,3,2,2
2,3,3,3,3,3,3,3,3,3,3,3,3,3,3,3,3,3,3,3,3,3,3,2,2
2,2,2,2,2,2,2,2,2,2,2,2,2,2,2,2,2,2,2,2,2,2,2,2,2
:endlayer
layer: 11
0,0,0,0,0,0,0,0,0,0,0,0,0,0,0,0,0,0,0,0,0,0,0,0,0
0,0,0,0,0,0,3,3,0,0,3,3,0,0,0,0,0,0,0,0,0,0,0,0,0
0,0,0,0,0,3,3,3,0,3,3,3,3,0,0,0,0,0,0,0,0,0,0,0,0
0,0,0,0,3,3,3,3,3,3,3,3,3,3,3,3,3,0,0,0,0,0,0,0,0
0,0,0,0,3,3,3,3,3,3,3,3,3,3,3,3,3,3,0,0,0,0,0,0,0
0,0,0,3,3,3,3,3,3,3,1,1,1,1,1,3,3,3,3,0,0,0,0,0,0
0,0,3,3,3,3,3,3,1,1,1,1,1,1,1,1,1,3,3,7,0,0,0,0,0
0,0,3,3,3,3,3,1,1,1,1,1,1,1,1,1,1,1,3,0,0,0,0,0,0
0,0,3,3,3,3,1,1,1,1,1,1,1,1,1,1,1,1,1,8,0,0,0,0,0
0,0,3,3,3,3,1,1,1,1,1,1,1,1,1,1,1,1,1,3,7,6,0,0,0
0,10,3,3,3,1,1,1,1,1,1,1,1,1,1,1,1,1,1,1,3,3,0,0,0
0,3,3,3,3,1,1,1,1,1,1,1,1,1,1,1,1,1,1,1,3,3,0,0,5
0,3,3,3,3,1,1,1,1,1,1,1,4,1,1,1,1,1,1,1,3,3,0,0,0
0,3,3,3,3,1,1,1,1,1,1,1,1,1,1,1,1,1,1,1,3,3,0,0,0
0,0,3,3,3,1,1,1,1,1,1,1,1,1,1,1,1,1,1,1,3,0,0,0,0
0,0,3,3,3,3,1,1,1,1,1,1,1,1,1,1,1,1,1,3,3,3,0,0,0
0,0,3,3,3,3,1,1,1,1,1,1,1,1,1,1,1,1,1,3,3,0,0,0,0
0,3,3,3,3,3,3,1,1,1,1,1,1,1,1,1,1,1,3,3,3,3,0,0,0
0,3,3,3,3,3,3,3,1,1,1,1,1,1,1,1,1,3,3,3,3,3,0,0,0
0,3,3,3,3,3,3,3,3,3,1,1,1,1,1,3,3,3,3,3,3,3,0,0,0
0,0,3,3,3,3,3,3,3,3,3,3,3,3,3,3,3,3,3,3,3,3,3,0,0
0,0,3,3,3,0,0,3,3,3,3,3,3,3,3,3,3,3,3,3,3,3,3,0,0
0,0,0,3,3,0,0,0,3,3,0,0,0,0,0,3,3,3,3,3,3,0,0,0,0
0,0,0,0,0,0,0,0,0,0,9,0,0,0,0,0,0,0,0,0,0,0,0,0,0
0,0,0,0,0,0,0,0,0,0,0,0,0,0,0,0,0,0,0,0,0,0,0,0,0
:endlayer
layer: 12
0,0,0,0,0,0,0,0,0,0,0,0,0,0,0,0,0,0,0,0,0,0,0,0,0
0,0,0,0,0,0,0,0,0,0,0,0,0,0,0,0,0,0,0,0,0,0,0,0,0
0,0,0,0,0,13,0,0,0,0,0,0,0,0,0,0,0,13,0,0,0,0,0,0,0
0,0,0,0,0,0,0,0,0,7,8,0,0,0,8,0,7,0,0,0,0,0,0,0,0
0,0,0,0,0,0,8,0,8,7,0,7,0,8,0,8,0,0,0,0,0,0,0,0,0
0,0,0,0,0,0,0,8,7,0,11,11,11,11,11,0,8,7,7,0,0,0,0,0,0
0,0,0,0,0,0,0,0,11,11,12,12,12,12,12,11,11,0,8,0,10,0,0,0,0
0,0,0,0,0,8,7,11,12,12,12,12,12,12,12,12,12,11,0,0,0,0,0,0,0
0,0,0,9,7,8,11,12,11,12,12,12,12,12,12,11,11,12,11,0,0,0,0,0,0
0,0,0,8,7,0,11,12,11,12,12,12,12,12,12,12,12,12,11,0,0,10,0,0,0
0,10,0,8,0,11,12,12,12,12,12,12,12,12,12,12,12,12,12,11,0,0,0,0,0
0,10,0,0,0,11,12,12,12,12,12,12,12,12,12,12,12,12,12,11,8,8,0,0,5
0,0,0,0,7,11,12,12,12,12,12,12,12,12,12,12,12,12,12,11,0,7,0,0,0
0,0,0,7,0,11,12,12,12,12,12,12,12,12,12,12,12,12,12,11,8,0,0,5,0
0,0,0,8,8,11,12,12,12,12,12,12,12,12,12,12,12,12,12,11,7,0,0,0,0
0,0,0,8,0,0,11,12,12,12,12,12,12,12,12,12,12,12,11,0,0,8,0,0,0
0,0,0,7,0,0,11,12,11,11,12,12,12,12,12,12,11,12,11,7,8,0,0,0,0
0,0,10,0,0,0,0,11,12,12,12,12,12,12,12,12,12,11,0,0,7,0,0,0,0
0,0,0,0,0,8,7,0,11,11,12,12,12,12,12,11,11,0,7,0,8,0,0,0,0
0,0,0,0,0,7,0,7,0,0,11,11,11,11,11,0,8,0,8,8,0,0,0,0,0
0,0,0,10,0,0,8,0,8,7,0,8,8,8,0,0,0,8,7,0,0,0,0,0,0
0,0,0,0,0,0,0,0,0,8,7,7,0,7,13,8,8,0,0,0,0,0,0,0,0
0,0,0,0,0,0,0,0,0,0,0,0,0,0,0,0,0,0,0,0,0,0,0,0,0
0,0,0,0,0,0,0,0,0,0,9,0,0,0,0,0,0,0,0,0,0,0,0,0,0
0,0,0,0,0,0,0,0,0,0,0,0,0,0,0,0,0,0,0,0,0,0,0,0,0
:endlayer
layer: 13
0,0,0,0,0,0,0,0,0,13,0,0,0,0,0,0,0,0,0,0,0,0,0,0,0
0,0,0,0,0,0,0,0,0,0,0,0,0,0,0,0,0,0,0,0,0,0,0,0,0
0,0,0,0,0,13,0,0,0,0,0,0,0,0,0,0,0,13,0,0,0,0,0,0,0
0,0,0,0,0,0,0,0,0,0,0,0,0,0,0,0,0,0,0,0,0,0,0,0,0
0,0,0,0,0,0,0,0,0,0,0,0,0,0,0,0,0,0,0,0,0,0,0,0,0
0,0,0,0,0,0,0,0,0,0,0,0,0,0,0,0,0,0,0,0,0,0,0,0,0
0,0,0,0,0,0,0,0,0,0,11,11,11,11,11,0,0,0,0,0,10,0,0,0,0
0,0,0,0,0,0,0,0,11,11,12,12,12,12,12,11,11,0,0,0,0,0,0,0,0
0,0,0,9,0,0,0,11,11,12,12,12,12,12,12,11,11,11,0,0,0,0,0,0,0
0,0,0,0,0,0,0,11,11,12,12,12,12,12,12,12,12,11,0,0,0,10,0,0,0
0,10,0,0,0,0,11,12,12,12,12,12,12,12,12,12,12,12,11,0,0,0,0,0,0
0,10,0,0,0,8,11,12,12,12,12,12,12,12,12,12,12,12,11,0,0,10,0,0,5
0,0,0,0,0,0,11,12,12,12,12,12,12,12,12,12,12,12,11,5,0,0,0,0,0
0,0,0,0,0,0,11,12,12,12,12,12,12,12,12,12,12,12,11,0,0,0,0,5,0
0,0,0,0,0,0,11,12,12,12,12,12,12,12,12,12,12,12,11,0,0,0,0,0,0
0,0,0,5,0,0,0,11,12,12,12,12,12,12,12,12,12,11,0,0,0,0,0,0,0
0,0,0,0,0,0,0,11,11,11,12,12,12,12,12,12,11,11,0,0,0,0,0,0,0
0,0,10,0,0,0,0,0,11,11,12,12,12,12,12,11,11,0,0,0,0,0,0,0,0
0,0,0,0,0,0,0,0,0,0,11,11,11,11,11,0,0,0,0,0,0,0,0,0,0
0,0,0,0,0,0,0,0,0,0,0,0,9,0,0,0,0,0,0,0,0,0,0,0,0
0,0,0,10,0,0,0,0,0,0,0,0,0,0,0,0,0,0,0,0,9,0,0,0,0
0,0,0,0,0,0,0,0,0,0,0,0,0,13,13,0,0,0,0,5,0,0,0,0,0
0,0,0,0,0,0,0,0,0,0,0,0,0,0,0,0,0,0,0,0,0,0,0,0,0
0,0,0,0,0,0,0,0,0,0,9,0,0,0,0,0,0,0,0,0,0,0,0,0,0
0,0,0,0,0,0,0,0,0,0,0,0,0,0,0,0,0,0,0,0,0,0,0,0,0
:endlayer
layer: 14
0,0,0,0,0,0,0,0,0,13,0,13,0,0,0,13,0,0,0,0,0,0,0,0,0
0,0,0,0,0,0,0,0,13,0,0,0,0,0,0,0,0,0,0,0,0,0,0,0,0
0,0,0,0,0,13,0,0,0,0,0,0,0,0,0,0,0,13,0,0,0,0,0,0,0
0,0,0,0,0,0,0,0,0,0,0,0,0,0,9,0,0,0,0,0,0,0,0,0,0
0,0,0,0,0,0,0,0,0,0,0,0,0,0,0,0,0,0,0,0,0,0,0,0,0
0,0,13,0,0,0,0,0,0,0,0,0,0,0,0,0,0,0,0,0,0,0,0,0,0
0,0,0,0,0,0,0,0,0,0,11,11,11,11,11,0,0,0,0,0,10,0,0,0,0
0,0,0,0,0,0,0,0,11,11,12,12,12,12,12,11,11,0,0,0,0,0,0,0,0
10,0,0,9,0,0,0,11,11,12,12,12,12,12,12,11,11,11,0,0,0,0,0,0,0
0,10,0,0,0,0,0,11,11,12,12,12,12,12,12,12,12,11,0,0,0,10,0,0,5
0,10,0,0,0,0,11,12,12,12,12,12,17,12,12,12,12,12,11,0,0,0,0,0,0
0,10,0,0,0,0,11,12,12,12,12,20,0,14,12,12,12,12,11,0,0,10,0,0,5
10,0,0,0,0,0,11,12,12,12,12,21,18,15,12,12,12,12,11,5,0,0,0,0,5
0,0,0,0,0,0,11,12,12,12,12,22,19,16,12,12,12,12,11,0,0,10,0,5,0
0,0,0,0,0,0,11,12,12,12,12,12,12,12,12,12,12,12,11,0,0,0,0,0,0
0,0,0,5,0,0,0,11,12,12,12,12,12,12,12,12,12,11,0,0,0,0,0,0,0
10,0,0,0,0,0,0,11,11,11,12,12,12,12,12,12,11,11,0,0,0,0,0,0,0
0,0,10,0,0,0,0,0,11,11,12,12,12,12,12,11,11,0,0,0,0,0,0,0,0
0,0,0,0,0,0,0,0,0,0,11,11,11,11,11,0,0,0,0,0,0,0,0,0,0
0,0,0,0,0,0,0,0,0,0,0,0,9,0,0,0,0,0,0,0,0,0,0,0,0
0,0,0,10,0,0,5,0,0,0,0,0,0,0,0,0,0,13,0,0,9,9,0,0,0
0,0,0,0,0,0,0,0,0,0,0,0,0,13,13,0,0,0,0,5,0,0,0,0,0
0,0,0,0,0,0,0,0,0,0,0,0,0,0,0,0,0,0,0,0,0,0,0,0,0
0,0,0,0,0,0,0,0,0,0,9,0,0,0,0,0,0,0,0,0,0,0,0,0,0
0,0,0,0,0,0,0,0,0,0,0,0,0,0,0,9,0,0,0,0,0,0,0,0,0
:endlayer
layer: 15
0,0,0,0,0,0,0,0,0,13,0,13,0,0,0,13,0,0,0,0,0,0,0,0,0
0,0,0,0,0,0,0,0,13,0,0,0,0,0,13,0,0,0,0,0,0,0,0,0,0
0,0,0,0,0,13,0,0,0,0,0,0,0,0,0,0,0,13,0,0,0,0,0,0,0
0,0,0,0,0,0,0,0,0,0,0,9,0,0,9,0,0,0,0,0,5,0,0,0,0
0,0,0,0,0,0,0,0,0,0,0,0,0,0,0,0,0,9,0,0,13,13,0,0,0
0,0,13,0,0,9,0,0,0,0,0,0,0,0,0,0,0,0,0,0,0,0,0,0,0
0,0,0,0,0,0,0,0,0,0,0,0,0,0,0,0,0,0,0,0,10,0,0,0,0
0,10,0,0,0,0,0,0,0,0,11,11,11,11,11,0,0,0,0,0,0,0,0,0,0
10,0,0,9,0,0,0,0,0,11,11,11,11,11,11,11,0,0,0,0,0,0,0,5,0
0,10,0,0,0,0,0,0,11,11,12,12,12,12,12,11,11,0,0,0,0,10,0,0,5
0,10,0,0,0,0,0,11,11,12,12,12,0,12,12,12,11,11,0,0,0,0,0,0,0
0,10,0,0,0,0,0,11,11,12,12,0,0,0,12,12,11,11,0,0,0,10,0,0,5
10,0,0,5,0,0,10,11,11,12,12,0,0,0,12,12,11,11,0,0,0,0,0,0,5
0,0,0,0,0,0,0,11,11,12,12,0,0,0,12,12,11,11,5,0,0,10,0,5,0
0,0,0,0,0,0,0,11,11,12,12,25,0,23,12,12,11,11,0,0,0,0,0,0,0
0,0,0,5,0,0,0,0,11,11,12,12,24,12,12,11,11,0,0,0,0,0,0,0,0
10,0,0,0,0,0,0,0,0,11,11,11,0,11,11,11,0,0,0,0,0,0,0,0,5
0,0,10,0,0,0,0,0,0,0,11,11,0,11,11,0,0,0,0,0,0,0,0,0,0
0,0,0,0,0,0,0,0,0,0,0,0,0,9,0,0,0,0,0,0,0,0,0,0,0
0,0,0,0,0,5,0,0,0,0,0,0,0,0,0,0,0,0,0,13,0,0,0,0,0
0,0,0,10,0,0,5,0,0,0,0,0,0,0,0,0,0,13,0,0,9,9,0,0,0
0,0,0,0,0,0,0,0,0,0,13,0,0,13,13,0,0,0,0,5,0,0,0,0,0
0,0,0,0,0,0,0,0,0,0,0,0,0,0,0,0,0,0,0,0,0,0,0,0,0
0,0,0,0,0,0,0,0,0,0,9,0,0,0,9,0,0,0,0,0,0,0,0,0,0
0,0,0,0,0,0,0,0,0,0,0,0,9,0,0,9,0,0,0,0,0,0,0,0,0
:endlayer
layer: 16
0,0,0,0,0,0,0,0,0,13,0,13,0,0,0,13,0,0,0,0,0,0,0,0,0
0,0,0,0,0,0,0,0,13,0,0,0,0,0,13,0,0,0,0,0,0,0,0,0,0
0,0,0,0,0,13,0,0,0,0,0,0,0,0,0,0,0,13,0,0,0,0,0,0,0
0,0,0,0,0,0,0,0,0,9,0,9,0,0,9,0,0,0,0,0,5,0,0,0,0
0,0,0,10,0,0,0,0,0,0,0,0,0,0,0,0,0,9,0,0,13,13,0,0,0
0,0,13,13,0,9,0,0,0,0,0,0,0,0,0,0,0,0,0,9,0,0,0,0,0
0,0,0,0,0,0,0,0,0,0,0,0,0,0,0,0,0,0,0,0,10,0,0,0,0
0,10,0,0,0,0,0,0,0,0,0,0,13,0,0,0,0,0,0,0,0,0,0,13,0
10,0,0,9,0,0,0,0,0,0,11,11,11,11,11,0,0,0,0,0,0,0,0,5,0
0,10,0,0,0,0,0,0,0,11,12,12,12,12,12,11,0,0,0,0,0,10,0,0,5
0,10,0,0,0,0,0,10,11,12,12,12,0,12,12,12,11,0,0,0,0,0,0,0,0
0,10,0,0,0,0,0,0,11,12,12,0,0,0,12,12,11,5,0,0,0,10,0,0,5
10,0,0,5,0,0,0,0,11,12,12,28,0,0,12,12,11,0,0,0,0,0,0,0,5
0,0,0,0,0,0,0,10,11,12,12,0,0,26,12,12,11,0,0,0,0,10,0,5,0
0,0,0,0,0,0,0,0,11,12,12,0,0,0,12,12,11,0,0,0,0,0,0,0,0
0,0,0,5,0,0,0,0,0,11,12,12,27,12,12,11,5,0,0,0,0,0,0,5,0
10,0,0,0,0,0,0,0,0,0,11,11,0,11,11,0,0,0,0,0,0,13,0,0,5
0,0,10,0,0,0,0,0,0,0,0,9,9,0,0,0,0,0,0,0,0,0,0,0,0
0,0,0,0,5,0,0,0,0,0,0,0,0,0,0,0,0,0,0,0,0,0,0,0,0
0,0,0,10,0,5,0,0,0,0,0,0,0,0,0,0,0,0,0,13,0,0,0,0,0
0,0,0,10,0,0,5,0,0,0,0,0,0,0,0,0,0,13,0,0,9,9,0,0,0
0,0,0,0,9,0,0,0,0,0,13,0,0,13,13,0,0,0,0,5,0,0,0,0,0
0,0,0,0,0,10,0,0,0,0,0,0,0,0,0,0,0,0,0,5,0,0,0,0,0
0,0,0,0,0,0,0,0,0,0,9,0,0,0,9,0,0,0,9,0,0,0,0,0,0
0,0,0,0,0,0,0,0,0,0,0,0,9,0,0,9,0,0,0,0,0,0,0,0,0
:endlayer
layer: 17
0,0,0,0,0,0,0,0,0,13,0,13,13,0,0,13,0,0,0,0,0,0,0,0,0
0,0,0,0,0,0,0,10,13,0,0,0,0,0,13,0,0,0,0,0,0,0,0,0,0
0,0,0,0,0,13,0,0,0,0,0,0,0,0,0,0,0,13,0,5,0,0,0,0,0
0,0,0,0,0,0,0,0,0,9,0,9,0,0,9,0,0,0,0,0,5,0,0,0,0
0,0,0,10,0,0,0,0,0,0,0,0,0,0,0,0,0,9,9,0,13,13,0,0,0
0,0,13,13,0,9,0,0,0,0,0,0,0,0,0,0,0,0,0,9,0,0,0,0,0
0,0,0,0,0,0,0,0,0,0,0,0,0,0,0,0,0,0,0,0,10,0,0,0,0
0,10,0,0,0,0,0,0,0,0,0,0,13,0,0,0,0,0,0,0,0,0,0,13,0
10,0,0,9,0,0,0,0,0,0,11,11,11,11,11,0,0,0,0,0,0,0,0,5,0
0,10,0,0,0,0,0,0,0,11,12,12,12,12,12,11,0,0,0,0,0,10,0,0,5
0,10,0,0,0,0,0,10,11,12,12,12,12,12,12,12,11,0,0,0,0,0,0,0,0
0,10,0,0,0,0,0,0,11,12,12,12,12,12,12,12,11,5,0,0,0,10,0,0,5
10,0,0,5,0,0,0,0,11,12,12,12,12,12,12,12,11,0,0,0,0,0,0,0,5
10,0,0,0,0,0,0,10,11,12,12,12,12,12,12,12,11,0,0,0,0,10,0,5,0
0,0,0,0,0,0,0,0,11,12,12,12,12,12,12,12,11,0,0,0,0,0,0,0,0
0,0,0,5,0,0,0,0,0,11,12,12,12,12,12,11,5,0,0,0,0,0,0,5,0
10,0,0,0,0,0,0,0,0,0,11,11,11,11,11,0,0,0,0,0,0,13,0,0,5
0,0,10,0,0,0,0,0,0,0,0,0,9,0,0,0,0,0,0,0,0,0,0,0,0
0,0,0,0,5,0,0,0,0,0,0,0,0,0,0,0,0,0,0,0,0,0,0,0,0
0,0,0,10,0,5,0,0,0,0,0,0,0,0,0,0,0,0,0,13,0,0,0,0,0
0,0,0,10,0,0,5,0,0,0,0,0,0,0,0,0,0,13,0,0,9,9,0,0,0
0,0,0,0,9,0,0,0,5,0,13,0,0,13,13,0,0,0,0,5,0,0,0,0,0
0,0,0,0,0,10,0,0,0,0,0,0,0,0,0,0,0,0,0,5,0,0,0,0,0
0,0,0,0,0,0,0,0,0,0,9,0,0,0,9,0,0,0,9,0,0,0,0,0,0
0,0,0,0,0,0,0,0,9,0,0,0,9,0,0,9,0,0,0,0,0,0,0,0,0
:endlayer
layer: 18
0,0,0,0,0,0,0,0,0,13,0,13,13,0,0,13,0,0,0,0,0,0,0,0,0
0,0,0,0,0,0,0,10,13,0,0,0,0,0,13,0,0,0,0,0,0,0,0,0,0
0,0,0,0,0,13,0,0,34,32,32,32,32,32,32,32,29,13,0,5,0,0,0,0,0
0,0,0,0,0,0,34,32,0,9,0,9,0,0,9,0,10,32,29,0,5,0,0,0,0
0,0,0,10,0,34,0,0,0,0,0,0,0,0,0,0,0,9,9,29,13,13,0,0,0
0,0,13,13,34,9,0,0,0,0,0,0,0,0,0,0,0,0,0,9,29,0,0,0,0
0,0,0,34,0,0,0,0,0,0,0,0,0,0,0,0,0,0,0,0,10,29,0,5,0
0,10,0,36,0,0,0,0,0,0,13,0,13,0,0,0,0,0,0,0,0,30,0,13,0
10,0,34,9,0,0,0,0,0,0,11,11,11,11,11,0,0,0,0,0,0,0,29,5,0
0,10,36,0,0,0,0,0,0,11,12,12,12,12,12,11,0,0,0,0,0,10,30,0,5
0,10,36,0,0,0,0,10,11,12,12,12,12,12,12,12,11,0,0,0,0,0,30,0,0
0,10,36,0,0,0,0,0,11,12,12,12,12,12,12,12,11,5,0,0,0,10,30,0,5
10,0,36,5,0,0,0,0,11,12,12,12,12,12,12,12,11,0,0,0,0,0,30,0,5
10,0,36,0,0,0,0,10,11,12,12,12,12,12,12,12,11,0,0,0,0,10,30,5,0
0,10,36,0,0,0,0,0,11,12,12,12,12,12,12,12,11,0,0,0,0,0,30,0,0
0,0,36,5,0,0,0,0,0,11,12,12,12,12,12,11,5,0,0,0,0,0,30,5,0
10,0,35,0,0,0,0,0,0,0,11,11,11,11,11,0,0,0,0,0,0,13,31,0,5
0,0,10,36,0,0,0,0,0,0,0,0,9,0,0,0,0,0,0,0,0,30,0,0,0
0,10,0,35,5,0,0,0,0,0,0,0,0,0,0,0,0,0,0,0,0,31,0,0,0
0,0,0,10,35,5,0,0,0,0,0,0,0,0,0,0,0,0,0,13,31,0,0,0,0
0,0,0,10,0,35,5,0,0,0,0,0,0,0,0,0,0,13,0,31,9,9,0,0,0
0,0,0,0,9,0,35,33,5,0,13,0,0,13,13,0,0,33,31,5,0,0,0,0,0
0,0,0,0,0,10,0,0,35,33,33,33,33,33,33,33,31,0,0,5,0,0,0,0,0
0,0,0,0,0,0,0,0,0,0,9,0,0,0,9,0,0,0,9,0,0,0,0,0,0
0,0,0,0,0,0,0,0,9,0,0,0,9,0,0,9,0,0,0,0,0,0,0,0,0
:endlayer
layer: 19
0,0,0,0,0,0,0,0,0,13,0,13,13,0,0,13,0,0,0,0,0,0,0,0,0
0,0,0,0,0,0,0,6,34,32,32,32,32,32,32,32,29,0,0,0,0,0,0,0,0
0,0,0,0,0,13,34,32,0,0,0,0,0,0,0,0,0,32,29,5,0,0,0,0,0
0,0,0,0,0,34,0,0,0,0,0,0,0,0,0,0,0,0,0,29,5,0,0,0,0
0,0,0,10,34,0,0,0,0,0,0,0,0,0,0,0,0,0,0,0,29,13,0,0,0
0,0,13,34,0,0,0,0,0,0,0,0,0,0,0,0,0,0,0,0,0,29,0,0,0
0,0,34,0,0,0,0,0,0,0,0,0,0,0,0,0,0,0,0,0,0,0,29,5,0
0,10,36,0,0,0,0,0,0,0,13,13,0,0,0,0,0,0,0,0,0,0,30,13,0
10,34,0,0,0,0,0,0,0,0,11,11,11,11,11,0,0,0,0,0,0,0,0,29,0
0,36,0,0,0,0,0,0,0,11,12,12,12,12,12,11,0,0,0,0,0,0,0,30,5
0,36,0,0,0,0,0,0,11,12,12,12,12,12,12,12,11,0,0,0,0,0,0,30,0
0,36,0,0,0,0,0,0,11,12,12,12,12,12,12,12,11,5,0,0,0,0,0,30,5
10,36,0,0,0,0,0,0,11,12,12,12,12,12,12,12,11,0,0,0,0,0,0,30,5
10,36,0,0,0,0,0,0,11,12,12,12,12,12,12,12,11,0,0,0,0,0,0,30,0
0,36,0,0,0,0,0,0,11,12,12,12,12,12,12,12,11,0,0,0,0,0,0,30,0
0,35,0,0,0,0,0,0,0,11,12,12,12,12,12,11,5,0,0,0,0,0,0,30,0
10,35,0,0,0,0,0,0,0,0,11,11,11,11,11,0,0,0,0,0,0,0,0,31,5
0,0,36,0,0,0,0,0,0,0,0,0,9,0,0,0,0,0,0,0,0,0,30,0,0
0,10,35,0,0,0,0,0,0,0,0,0,0,0,0,0,0,0,0,0,0,0,31,0,0
0,0,0,35,0,0,0,0,0,0,0,0,0,0,0,0,0,0,0,0,0,31,0,0,0
0,0,0,10,35,0,0,0,0,0,0,0,0,0,0,0,0,0,0,0,31,9,0,0,0
0,0,0,0,9,35,0,0,0,0,0,0,0,0,0,0,0,0,0,31,0,0,0,0,0
0,0,0,0,0,10,35,33,0,0,0,0,0,0,0,0,0,33,31,5,0,0,0,0,0
0,0,0,0,0,0,0,0,35,33,33,33,33,33,33,33,31,0,9,0,0,0,0,0,0
0,0,0,0,0,0,0,0,9,0,0,0,9,0,0,9,0,0,0,0,0,0,0,0,0
:endlayer
layer: 20
0,0,0,0,0,0,0,0,0,13,0,13,13,0,0,13,0,0,0,0,0,0,0,0,0
0,0,0,0,0,0,0,6,34,32,32,32,32,32,32,32,29,0,0,0,0,0,0,0,0
0,0,0,0,0,13,34,32,0,0,0,0,0,0,0,0,0,32,29,5,0,0,0,0,0
0,0,0,0,0,34,0,0,0,0,0,0,0,0,0,0,0,0,0,29,5,0,0,0,0
0,0,0,10,34,0,0,0,0,0,0,0,0,0,0,0,0,0,0,0,29,13,0,0,0
0,0,13,34,0,0,0,0,0,0,0,0,0,0,0,0,0,0,0,0,0,29,0,0,0
0,0,34,0,0,0,0,0,0,0,0,0,0,0,0,0,0,0,0,0,0,0,29,5,0
0,10,36,0,0,0,0,0,0,0,13,13,0,0,0,0,0,0,0,0,0,0,30,13,0
10,34,0,0,0,0,0,0,0,0,11,11,11,11,11,0,0,0,0,0,0,0,0,29,0
0,36,0,0,0,0,0,0,0,11,12,12,12,12,12,11,37,0,0,0,0,0,0,30,5
0,36,0,0,0,0,0,0,11,12,12,12,12,12,12,12,11,5,0,0,0,0,0,30,0
0,36,0,0,0,0,0,0,11,12,12,12,12,12,12,12,11,5,0,0,0,0,0,30,5
10,36,0,0,0,0,0,0,11,12,12,12,12,12,12,12,11,0,0,0,0,0,0,30,5
10,36,0,0,0,0,0,0,11,12,12,12,12,12,12,12,11,0,0,0,0,0,0,30,5
0,36,0,0,0,0,0,0,11,12,12,12,12,12,12,12,11,0,0,0,0,0,0,30,0
0,35,0,0,0,0,0,0,0,11,12,12,12,12,12,11,5,0,0,0,0,0,0,30,0
10,35,0,0,0,0,0,0,0,0,11,11,11,11,11,0,0,0,0,0,0,0,0,31,5
0,0,36,0,0,0,0,0,0,0,0,0,9,9,0,0,0,0,0,0,0,0,30,0,0
0,10,35,0,0,0,0,0,0,0,0,0,0,0,0,0,0,0,0,0,0,0,31,0,0
0,0,0,35,0,0,0,0,0,0,0,0,0,0,0,0,0,0,0,0,0,31,0,0,0
0,0,0,10,35,0,0,0,0,0,0,0,0,0,0,0,0,0,0,0,31,9,0,0,0
0,0,0,0,9,35,0,0,0,0,0,0,0,0,0,0,0,0,0,31,0,0,0,0,0
0,0,0,0,0,10,35,33,0,0,0,0,0,0,0,0,0,33,31,5,0,0,0,0,0
0,0,0,0,0,0,0,0,35,33,33,33,33,33,33,33,31,0,9,0,0,0,0,0,0
0,0,0,0,0,0,0,0,9,0,0,0,9,0,0,9,0,0,0,0,0,0,0,0,0
:endlayer
layer: 21
0,0,0,0,0,0,0,0,0,13,0,13,13,0,0,13,0,0,0,0,0,0,0,0,0
0,0,0,0,0,0,0,6,34,32,32,32,32,32,32,32,29,0,0,0,0,0,0,0,0
0,0,0,0,0,13,34,32,0,0,0,0,0,0,0,0,0,32,29,37,0,0,0,0,0
0,0,0,0,0,34,0,0,0,0,0,0,0,0,0,0,0,0,0,29,5,0,0,0,0
0,0,0,10,34,0,0,0,0,0,0,0,0,0,0,0,0,0,0,0,29,13,0,0,0
0,0,13,34,0,0,0,0,0,0,0,0,0,0,0,0,0,0,0,0,0,29,0,0,0
0,0,34,0,0,0,0,0,0,0,0,0,0,0,0,0,0,0,0,0,0,0,29,5,0
0,10,36,0,0,0,0,0,0,0,13,13,0,0,0,0,0,0,0,0,0,0,30,13,0
10,34,0,0,0,0,0,0,0,0,11,11,11,11,11,0,0,0,0,0,0,0,0,29,0
0,36,0,0,0,0,0,0,0,11,12,12,12,12,12,11,5,0,0,0,0,0,0,30,5
0,36,0,0,0,0,0,0,11,12,12,12,12,12,12,12,11,0,0,0,0,0,0,30,0
0,36,0,0,0,0,0,0,11,12,12,12,12,12,12,12,11,5,0,0,0,0,0,30,5
10,36,0,0,0,0,0,0,11,12,12,12,12,12,12,12,11,5,0,0,0,0,0,30,5
10,36,0,0,0,0,0,0,11,12,12,12,12,12,12,12,11,0,0,0,0,0,0,30,5
0,36,0,0,0,0,0,0,11,12,12,12,12,12,12,12,11,0,0,0,0,0,0,30,0
0,35,0,0,0,0,0,0,0,11,12,12,12,12,12,11,0,0,0,0,0,0,0,30,0
10,35,0,0,0,0,0,0,0,0,11,11,11,11,11,0,0,0,0,0,0,0,0,31,5
0,0,36,0,0,0,0,0,0,0,0,0,9,9,0,0,0,0,0,0,0,0,30,0,0
0,10,35,0,0,0,0,0,0,0,0,0,0,0,0,0,0,0,0,0,0,0,31,0,0
0,0,0,35,0,0,0,0,0,0,0,0,0,0,0,0,0,0,0,0,0,31,0,0,0
0,0,0,10,35,0,0,0,0,0,0,0,0,0,0,0,0,0,0,0,31,9,0,0,0
0,0,0,0,9,35,0,0,0,0,0,0,0,0,0,0,0,0,0,31,0,0,0,0,0
0,0,0,0,0,10,35,33,0,0,0,0,0,0,0,0,0,33,31,5,0,0,0,0,0
0,0,0,0,0,0,0,0,35,33,33,33,33,33,33,33,31,0,9,0,0,0,0,0,0
0,0,0,0,0,0,0,0,9,0,0,0,9,0,0,9,0,0,0,0,0,0,0,0,0
:endlayer
layer: 22
0,0,0,0,0,0,0,0,0,13,0,13,13,0,0,13,0,0,0,0,0,0,0,0,0
0,0,0,0,0,0,0,13,6,34,32,32,32,32,32,29,0,0,0,0,0,0,0,0,0
0,0,0,0,0,13,0,34,32,0,0,0,0,0,0,0,32,29,0,13,0,0,0,0,0
0,0,0,0,0,34,34,0,0,0,0,0,0,0,0,0,0,0,29,29,5,0,0,0,0
0,0,0,10,34,0,0,0,0,0,0,0,0,0,0,0,0,0,0,0,29,5,0,0,0
0,0,10,34,0,0,0,0,0,0,0,0,0,0,0,0,0,0,0,0,0,29,0,0,0
0,0,0,34,0,0,0,0,0,0,0,0,0,0,0,0,0,0,0,0,0,30,0,0,0
0,10,34,0,0,0,0,0,0,0,13,0,0,0,0,0,0,0,0,0,0,0,29,5,0
0,0,36,0,0,0,0,0,0,0,11,11,11,11,11,0,0,0,0,0,0,0,30,0,0
0,34,0,0,0,0,0,0,0,11,12,12,12,12,12,11,0,0,0,0,0,0,0,29,5
0,36,0,0,0,0,0,0,11,12,12,12,12,12,12,12,11,0,0,0,0,0,0,30,0
0,36,0,0,0,0,0,0,11,12,12,12,12,12,12,12,11,5,0,0,0,0,0,30,0
10,36,0,0,0,0,0,0,11,12,12,12,12,12,12,12,11,5,0,0,0,0,0,30,5
10,36,0,0,0,0,0,0,11,12,12,12,12,12,12,12,11,0,0,0,0,0,0,30,5
0,36,0,0,0,0,0,0,11,12,12,12,12,12,12,12,11,0,0,0,0,0,0,30,0
0,35,0,0,0,0,0,0,0,11,12,12,12,12,12,11,0,0,0,0,0,0,0,31,0
0,0,36,0,0,0,0,0,0,0,11,11,11,11,11,0,0,0,0,0,0,0,30,0,0
0,0,35,0,0,0,0,0,0,0,0,0,9,0,0,0,0,0,0,0,0,0,31,0,0
0,0,0,36,0,0,0,0,0,0,0,0,0,0,0,0,0,0,0,0,0,30,0,0,0
0,0,0,35,0,0,0,0,0,0,0,0,0,0,0,0,0,0,0,0,0,31,0,0,0
0,0,0,10,35,0,0,0,0,0,0,0,0,0,0,0,0,0,0,0,31,9,0,0,0
0,0,0,0,9,35,33,0,0,0,0,0,0,0,0,0,0,0,33,31,0,0,0,0,0
0,0,0,0,0,0,38,35,33,0,0,0,0,0,0,0,33,31,0,9,0,0,0,0,0
0,0,0,0,0,0,0,0,0,35,33,33,33,33,33,31,9,0,0,0,0,0,0,0,0
0,0,0,0,0,0,0,0,0,0,0,0,9,0,0,9,0,0,0,0,0,0,0,0,0
:endlayer
layer: 23
0,0,0,0,0,0,0,0,0,0,0,0,0,0,0,0,0,0,0,0,0,0,0,0,0
0,0,0,0,0,0,0,0,13,0,0,0,0,0,0,0,0,0,0,0,0,0,0,0,0
0,0,0,0,0,0,0,6,34,32,32,32,32,32,32,32,29,0,0,0,0,0,0,0,0
0,0,0,0,0,0,34,32,0,0,0,0,0,0,0,0,0,32,29,0,0,0,0,0,0
0,0,0,0,0,34,0,0,0,0,0,0,0,0,0,0,0,0,0,29,0,0,0,0,0
0,0,0,0,34,0,0,0,0,0,0,0,0,0,0,0,0,0,0,0,29,0,0,0,0
0,0,0,34,0,0,0,0,0,0,0,0,0,0,0,0,0,0,0,0,0,29,0,0,0
0,0,0,36,0,0,0,0,0,0,13,13,13,0,0,0,0,0,0,0,0,30,0,0,0
0,0,34,0,0,0,0,0,0,0,11,11,11,11,11,0,0,0,0,0,0,0,29,0,0
0,0,36,0,0,0,0,0,0,11,12,12,12,12,12,11,0,0,0,0,0,0,30,0,0
0,0,36,0,0,0,0,0,11,12,12,12,12,12,12,12,11,0,0,0,0,0,30,0,0
0,0,36,0,0,0,0,0,11,12,12,12,12,12,12,12,11,0,0,0,0,0,30,0,0
0,0,36,0,0,0,0,0,11,12,12,12,12,12,12,12,11,0,0,0,0,0,30,0,0
0,0,36,0,0,0,0,0,11,12,12,12,12,12,12,12,11,0,0,0,0,0,30,0,0
0,0,36,0,0,0,0,0,11,12,12,12,12,12,12,12,11,0,0,0,0,0,30,0,0
0,0,36,0,0,0,0,0,0,11,12,12,12,12,12,11,0,0,0,0,0,0,30,0,0
0,0,35,0,0,0,0,0,0,0,11,11,11,11,11,0,0,0,0,0,0,0,31,0,0
0,0,0,36,0,0,0,0,0,0,0,0,0,0,0,0,0,0,0,0,0,30,0,0,0
0,0,0,35,0,0,0,0,0,0,0,0,0,0,0,0,0,0,0,0,0,31,0,0,0
0,0,0,0,35,0,0,0,0,0,0,0,0,0,0,0,0,0,0,0,31,0,0,0,0
0,0,0,0,0,35,0,0,0,0,0,0,0,0,0,0,0,0,0,31,0,0,0,0,0
0,0,0,0,0,10,35,33,0,0,0,0,0,0,0,0,0,33,31,0,0,0,0,0,0
0,0,0,0,0,0,9,0,35,33,33,33,33,33,33,33,31,0,0,0,0,0,0,0,0
0,0,0,0,0,0,0,0,0,0,0,0,0,9,9,0,9,0,0,0,0,0,0,0,0
0,0,0,0,0,0,0,0,0,0,0,0,0,0,0,0,0,0,0,0,0,0,0,0,0
:endlayer
layer: 24
0,0,0,0,0,0,0,0,0,0,0,0,0,0,0,0,0,0,0,0,0,0,0,0,0
0,0,0,0,0,0,0,0,0,0,0,0,0,0,0,0,0,0,0,0,0,0,0,0,0
0,0,0,0,0,0,0,13,13,13,34,32,32,32,29,0,0,0,0,0,0,0,0,0,0
0,0,0,0,0,0,0,34,32,32,0,0,0,0,0,32,32,29,0,0,0,0,0,0,0
0,0,0,0,0,0,34,0,0,0,0,0,0,0,0,0,0,0,29,0,0,0,0,0,0
0,0,0,0,0,34,0,0,0,0,0,0,0,0,0,0,0,0,0,29,0,0,0,0,0
0,0,0,0,34,0,0,0,0,0,0,0,0,0,0,0,0,0,0,0,29,0,0,0,0
0,0,0,34,0,0,0,0,0,0,0,13,13,0,0,0,0,0,0,0,0,29,0,0,0
0,0,0,36,0,0,0,0,0,0,11,11,11,11,11,0,0,0,0,0,0,30,0,0,0
0,0,0,36,0,0,0,0,0,11,12,12,12,12,12,11,0,0,0,0,0,30,0,0,0
0,0,34,0,0,0,0,0,11,12,12,12,12,12,12,12,11,0,0,0,0,0,29,0,0
0,0,36,0,0,0,0,0,11,12,12,12,12,12,12,12,11,0,0,0,0,0,30,0,0
0,0,36,0,0,0,0,0,11,12,12,12,12,12,12,12,11,0,0,0,0,0,30,0,0
0,0,36,0,0,0,0,0,11,12,12,12,12,12,12,12,11,0,0,0,0,0,30,0,0
0,0,35,0,0,0,0,0,11,12,12,12,12,12,12,12,11,0,0,0,0,0,31,0,0
0,0,0,36,0,0,0,0,0,11,12,12,12,12,12,11,0,0,0,0,0,30,0,0,0
0,0,0,36,0,0,0,0,0,0,11,11,11,11,11,0,0,0,0,0,0,30,0,0,0
0,0,0,35,0,0,0,0,0,0,0,0,0,0,0,0,0,0,0,0,0,31,0,0,0
0,0,0,0,35,0,0,0,0,0,0,0,0,0,0,0,0,0,0,0,31,0,0,0,0
0,0,0,0,0,35,0,0,0,0,0,0,0,0,0,0,0,0,0,31,0,0,0,0,0
0,0,0,0,0,0,35,0,0,0,0,0,0,0,0,0,0,0,31,0,0,0,0,0,0
0,0,0,0,0,10,35,35,33,33,0,0,0,0,0,33,33,31,0,0,0,0,0,0,0
0,0,0,0,0,0,9,0,0,0,35,33,33,33,31,0,0,0,0,0,0,0,0,0,0
0,0,0,0,0,0,0,0,0,0,0,0,0,9,9,0,0,0,0,0,0,0,0,0,0
0,0,0,0,0,0,0,0,0,0,0,0,0,0,0,0,0,0,0,0,0,0,0,0,0
:endlayer
layer: 25
0,0,0,0,0,0,0,0,0,0,0,0,0,0,0,0,0,0,0,0,0,0,0,0,0
0,0,0,0,0,0,0,0,0,0,0,0,0,0,0,0,0,0,0,0,0,0,0,0,0
0,0,0,0,0,0,0,0,0,0,0,0,0,0,0,0,0,0,0,0,0,0,0,0,0
0,0,0,0,0,0,0,0,0,34,32,32,32,32,32,29,0,0,0,0,0,0,0,0,0
0,0,0,0,0,0,0,34,32,39,39,39,39,39,39,39,32,29,0,0,0,0,0,0,0
0,0,0,0,0,0,34,39,39,39,0,0,0,0,0,39,39,39,29,0,0,0,0,0,0
0,0,0,0,0,34,39,39,0,0,0,0,0,0,0,0,0,39,39,29,0,0,0,0,0
0,0,0,0,34,39,39,0,0,40,12,12,12,12,12,40,0,0,39,39,29,0,0,0,0
0,0,0,0,36,39,0,0,40,12,11,11,11,11,11,12,40,0,0,39,30,0,0,0,0
0,0,0,34,39,39,0,40,12,11,12,12,12,12,12,11,12,40,0,39,39,29,0,0,0
0,0,0,36,39,0,0,12,11,12,12,12,12,12,12,12,11,12,0,0,39,30,0,0,0
0,0,0,36,39,0,0,12,11,12,12,12,12,12,12,12,11,12,0,0,39,30,0,0,0
0,0,0,36,39,0,0,12,11,12,12,12,12,12,12,12,11,12,0,0,39,30,0,0,0
0,0,0,36,39,0,0,12,11,12,12,12,12,12,12,12,11,12,0,0,39,30,0,0,0
0,0,0,36,39,0,0,12,11,12,12,12,12,12,12,12,11,12,0,0,39,30,0,0,0
0,0,0,35,39,39,0,40,12,11,12,12,12,12,12,11,12,40,0,39,39,31,0,0,0
0,0,0,0,36,39,0,0,40,12,11,11,11,11,11,12,40,0,0,39,30,0,0,0,0
0,0,0,0,35,39,39,0,0,40,12,12,12,12,12,40,0,0,39,39,31,0,0,0,0
0,0,0,0,0,35,39,39,0,0,0,0,0,0,0,0,0,39,39,31,0,0,0,0,0
0,0,0,0,0,0,35,39,39,39,0,0,0,0,0,39,39,39,31,0,0,0,0,0,0
0,0,0,0,0,0,0,35,33,39,39,39,39,39,39,39,33,31,0,0,0,0,0,0,0
0,0,0,0,0,0,0,0,0,35,33,33,33,33,33,31,0,0,0,0,0,0,0,0,0
0,0,0,0,0,0,0,0,0,0,0,0,0,0,0,0,0,0,0,0,0,0,0,0,0
0,0,0,0,0,0,0,0,0,0,0,0,0,0,0,0,0,0,0,0,0,0,0,0,0
0,0,0,0,0,0,0,0,0,0,0,0,0,0,0,0,0,0,0,0,0,0,0,0,0
:endlayer
layer: 26
0,0,0,0,0,0,0,0,0,0,0,0,0,0,0,0,0,0,0,0,0,0,0,0,0
0,0,0,0,0,0,0,0,0,0,0,0,0,0,0,0,0,0,0,0,0,0,0,0,0
0,0,0,0,0,0,0,0,0,0,0,0,0,0,0,0,0,0,0,0,0,0,0,0,0
0,0,0,0,0,0,0,0,0,0,0,0,0,0,0,0,0,0,0,0,0,0,0,0,0
0,0,0,0,0,0,0,0,0,0,0,0,0,0,0,0,0,0,0,0,0,0,0,0,0
0,0,0,0,0,0,0,0,0,0,34,32,32,32,29,0,0,0,0,0,0,0,0,0,0
0,0,0,0,0,0,0,0,34,32,39,39,39,39,39,32,29,0,0,0,0,0,0,0,0
0,0,0,0,0,0,0,34,39,39,39,39,39,39,39,39,39,29,0,0,0,0,0,0,0
0,0,0,0,0,0,34,39,39,39,39,39,39,39,39,39,39,39,29,0,0,0,0,0,0
0,0,0,0,0,0,36,39,39,39,39,39,39,39,39,39,39,39,30,0,0,0,0,0,0
0,0,0,0,0,34,39,39,39,39,39,39,39,39,39,39,39,39,39,29,0,0,0,0,0
0,0,0,0,0,36,39,39,39,39,39,39,39,39,39,39,39,39,39,30,0,0,0,0,0
0,0,0,0,0,36,39,39,39,39,39,39,39,39,39,39,39,39,39,30,0,0,0,0,0
0,0,0,0,0,36,39,39,39,39,39,39,39,39,39,39,39,39,39,30,0,0,0,0,0
0,0,0,0,0,35,39,39,39,39,39,39,39,39,39,39,39,39,39,31,0,0,0,0,0
0,0,0,0,0,0,36,39,39,39,39,39,39,39,39,39,39,39,30,0,0,0,0,0,0
0,0,0,0,0,0,35,39,39,39,39,39,39,39,39,39,39,39,31,0,0,0,0,0,0
0,0,0,0,0,0,0,35,39,39,39,39,39,39,39,39,39,31,0,0,0,0,0,0,0
0,0,0,0,0,0,0,0,35,33,39,39,39,39,39,33,31,0,0,0,0,0,0,0,0
0,0,0,0,0,0,0,0,0,0,35,33,33,33,31,0,0,0,0,0,0,0,0,0,0
0,0,0,0,0,0,0,0,0,0,0,0,0,0,0,0,0,0,0,0,0,0,0,0,0
0,0,0,0,0,0,0,0,0,0,0,0,0,0,0,0,0,0,0,0,0,0,0,0,0
0,0,0,0,0,0,0,0,0,0,0,0,0,0,0,0,0,0,0,0,0,0,0,0,0
0,0,0,0,0,0,0,0,0,0,0,0,0,0,0,0,0,0,0,0,0,0,0,0,0
0,0,0,0,0,0,0,0,0,0,0,0,0,0,0,0,0,0,0,0,0,0,0,0,0
:endlayer
layer: 27
0,0,0,0,0,0,0,0,0,0,0,0,0,0,0,0,0,0,0,0,0,0,0,0,0
0,0,0,0,0,0,0,0,0,0,0,0,0,0,0,0,0,0,0,0,0,0,0,0,0
0,0,0,0,0,0,0,0,0,0,0,0,0,0,0,0,0,0,0,0,0,0,0,0,0
0,0,0,0,0,0,0,0,0,0,0,0,0,0,0,0,0,0,0,0,0,0,0,0,0
0,0,0,0,0,0,0,0,0,0,0,0,0,0,0,0,0,0,0,0,0,0,0,0,0
0,0,0,0,0,0,0,0,0,0,0,0,0,0,0,0,0,0,0,0,0,0,0,0,0
0,0,0,0,0,0,0,0,0,0,0,0,0,0,0,0,0,0,0,0,0,0,0,0,0
0,0,0,0,0,0,0,0,0,0,0,0,0,0,0,0,0,0,0,0,0,0,0,0,0
0,0,0,0,0,0,0,0,0,0,0,0,0,0,0,0,0,0,0,0,0,0,0,0,0
0,0,0,0,0,0,0,0,0,0,0,0,0,0,0,0,0,0,0,0,0,0,0,0,0
0,0,0,0,0,0,0,0,0,0,0,0,0,0,0,0,0,0,0,0,0,0,0,0,0
0,0,0,0,0,0,0,0,0,0,0,0,0,0,0,0,0,0,0,0,0,0,0,0,0
0,0,0,0,0,0,0,0,0,0,0,0,0,0,0,0,0,0,0,0,0,0,0,0,0
0,0,0,0,0,0,0,0,0,0,0,0,0,0,0,0,0,0,0,0,0,0,0,0,0
0,0,0,0,0,0,0,0,0,0,0,0,0,0,0,0,0,0,0,0,0,0,0,0,0
0,0,0,0,0,0,0,0,0,0,0,0,0,0,0,0,0,0,0,0,0,0,0,0,0
0,0,0,0,0,0,0,0,0,0,0,0,0,0,0,0,0,0,0,0,0,0,0,0,0
0,0,0,0,0,0,0,0,0,0,0,0,0,0,0,0,0,0,0,0,0,0,0,0,0
0,0,0,0,0,0,0,0,0,0,0,0,0,0,0,0,0,0,0,0,0,0,0,0,0
0,0,0,0,0,0,0,0,0,0,0,0,0,0,0,0,0,0,0,0,0,0,0,0,0
0,0,0,0,0,0,0,0,0,0,0,0,0,0,0,0,0,0,0,0,0,0,0,0,0
0,0,0,0,0,0,0,0,0,0,0,0,0,0,0,0,0,0,0,0,0,0,0,0,0
0,0,0,0,0,0,0,0,0,0,0,0,0,0,0,0,0,0,0,0,0,0,0,0,0
0,0,0,0,0,0,0,0,0,0,0,0,0,0,0,0,0,0,0,0,0,0,0,0,0
0,0,0,0,0,0,0,0,0,0,0,0,0,0,0,0,0,0,0,0,0,0,0,0,0
:endlayer
layer: 28
0,0,0,0,0,0,0,0,0,0,0,0,0,0,0,0,0,0,0,0,0,0,0,0,0
0,0,0,0,0,0,0,0,0,0,0,0,0,0,0,0,0,0,0,0,0,0,0,0,0
0,0,0,0,0,0,0,0,0,0,0,0,0,0,0,0,0,0,0,0,0,0,0,0,0
0,0,0,0,0,0,0,0,0,0,0,0,0,0,0,0,0,0,0,0,0,0,0,0,0
0,0,0,0,0,0,0,0,0,0,0,0,0,0,0,0,0,0,0,0,0,0,0,0,0
0,0,0,0,0,0,0,0,0,0,0,0,0,0,0,0,0,0,0,0,0,0,0,0,0
0,0,0,0,0,0,0,0,0,0,0,0,0,0,0,0,0,0,0,0,0,0,0,0,0
0,0,0,0,0,0,0,0,0,0,0,0,0,0,0,0,0,0,0,0,0,0,0,0,0
0,0,0,0,0,0,0,0,0,0,0,0,0,0,0,0,0,0,0,0,0,0,0,0,0
0,0,0,0,0,0,0,0,0,0,0,0,0,0,0,0,0,0,0,0,0,0,0,0,0
0,0,0,0,0,0,0,0,0,0,0,0,0,0,0,0,0,0,0,0,0,0,0,0,0
0,0,0,0,0,0,0,0,0,0,0,0,0,0,0,0,0,0,0,0,0,0,0,0,0
0,0,0,0,0,0,0,0,0,0,0,0,0,0,0,0,0,0,0,0,0,0,0,0,0
0,0,0,0,0,0,0,0,0,0,0,0,0,0,0,0,0,0,0,0,0,0,0,0,0
0,0,0,0,0,0,0,0,0,0,0,0,0,0,0,0,0,0,0,0,0,0,0,0,0
0,0,0,0,0,0,0,0,0,0,0,0,0,0,0,0,0,0,0,0,0,0,0,0,0
0,0,0,0,0,0,0,0,0,0,0,0,0,0,0,0,0,0,0,0,0,0,0,0,0
0,0,0,0,0,0,0,0,0,0,0,0,0,0,0,0,0,0,0,0,0,0,0,0,0
0,0,0,0,0,0,0,0,0,0,0,0,0,0,0,0,0,0,0,0,0,0,0,0,0
0,0,0,0,0,0,0,0,0,0,0,0,0,0,0,0,0,0,0,0,0,0,0,0,0
0,0,0,0,0,0,0,0,0,0,0,0,0,0,0,0,0,0,0,0,0,0,0,0,0
0,0,0,0,0,0,0,0,0,0,0,0,0,0,0,0,0,0,0,0,0,0,0,0,0
0,0,0,0,0,0,0,0,0,0,0,0,0,0,0,0,0,0,0,0,0,0,0,0,0
0,0,0,0,0,0,0,0,0,0,0,0,0,0,0,0,0,0,0,0,0,0,0,0,0
0,0,0,0,0,0,0,0,0,0,0,0,0,0,0,0,0,0,0,0,0,0,0,0,0
:endlayer
layer: 29
0,0,0,0,0,0,0,0,0,0,0,0,0,0,0,0,0,0,0,0,0,0,0,0,0
0,0,0,0,0,0,0,0,0,0,0,0,0,0,0,0,0,0,0,0,0,0,0,0,0
0,0,0,0,0,0,0,0,0,0,0,0,0,0,0,0,0,0,0,0,0,0,0,0,0
0,0,0,0,0,0,0,0,0,0,0,0,0,0,0,0,0,0,0,0,0,0,0,0,0
0,0,0,0,0,0,0,0,0,0,0,0,0,0,0,0,0,0,0,0,0,0,0,0,0
0,0,0,0,0,0,0,0,0,0,0,0,0,0,0,0,0,0,0,0,0,0,0,0,0
0,0,0,0,0,0,0,0,0,0,0,0,0,0,0,0,0,0,0,0,0,0,0,0,0
0,0,0,0,0,0,0,0,0,0,0,0,0,0,0,0,0,0,0,0,0,0,0,0,0
0,0,0,0,0,0,0,0,0,0,0,0,0,0,0,0,0,0,0,0,0,0,0,0,0
0,0,0,0,0,0,0,0,0,0,0,0,0,0,0,0,0,0,0,0,0,0,0,0,0
0,0,0,0,0,0,0,0,0,0,0,0,0,0,0,0,0,0,0,0,0,0,0,0,0
0,0,0,0,0,0,0,0,0,0,0,0,0,0,0,0,0,0,0,0,0,0,0,0,0
0,0,0,0,0,0,0,0,0,0,0,0,0,0,0,0,0,0,0,0,0,0,0,0,0
0,0,0,0,0,0,0,0,0,0,0,0,0,0,0,0,0,0,0,0,0,0,0,0,0
0,0,0,0,0,0,0,0,0,0,0,0,0,0,0,0,0,0,0,0,0,0,0,0,0
0,0,0,0,0,0,0,0,0,0,0,0,0,0,0,0,0,0,0,0,0,0,0,0,0
0,0,0,0,0,0,0,0,0,0,0,0,0,0,0,0,0,0,0,0,0,0,0,0,0
0,0,0,0,0,0,0,0,0,0,0,0,0,0,0,0,0,0,0,0,0,0,0,0,0
0,0,0,0,0,0,0,0,0,0,0,0,0,0,0,0,0,0,0,0,0,0,0,0,0
0,0,0,0,0,0,0,0,0,0,0,0,0,0,0,0,0,0,0,0,0,0,0,0,0
0,0,0,0,0,0,0,0,0,0,0,0,0,0,0,0,0,0,0,0,0,0,0,0,0
0,0,0,0,0,0,0,0,0,0,0,0,0,0,0,0,0,0,0,0,0,0,0,0,0
0,0,0,0,0,0,0,0,0,0,0,0,0,0,0,0,0,0,0,0,0,0,0,0,0
0,0,0,0,0,0,0,0,0,0,0,0,0,0,0,0,0,0,0,0,0,0,0,0,0
0,0,0,0,0,0,0,0,0,0,0,0,0,0,0,0,0,0,0,0,0,0,0,0,0
:endlayer
layer: 30
0,0,0,0,0,0,0,0,0,0,0,0,0,0,0,0,0,0,0,0,0,0,0,0,0
0,0,0,0,0,0,0,0,0,0,0,0,0,0,0,0,0,0,0,0,0,0,0,0,0
0,0,0,0,0,0,0,0,0,0,0,0,0,0,0,0,0,0,0,0,0,0,0,0,0
0,0,0,0,0,0,0,0,0,0,0,0,0,0,0,0,0,0,0,0,0,0,0,0,0
0,0,0,0,0,0,0,0,0,0,0,0,0,0,0,0,0,0,0,0,0,0,0,0,0
0,0,0,0,0,0,0,0,0,0,0,0,0,0,0,0,0,0,0,0,0,0,0,0,0
0,0,0,0,0,0,0,0,0,0,0,0,0,0,0,0,0,0,0,0,0,0,0,0,0
0,0,0,0,0,0,0,0,0,0,0,0,0,0,0,0,0,0,0,0,0,0,0,0,0
0,0,0,0,0,0,0,0,0,0,0,0,0,0,0,0,0,0,0,0,0,0,0,0,0
0,0,0,0,0,0,0,0,0,0,0,0,0,0,0,0,0,0,0,0,0,0,0,0,0
0,0,0,0,0,0,0,0,0,0,0,0,0,0,0,0,0,0,0,0,0,0,0,0,0
0,0,0,0,0,0,0,0,0,0,0,0,0,0,0,0,0,0,0,0,0,0,0,0,0
0,0,0,0,0,0,0,0,0,0,0,0,0,0,0,0,0,0,0,0,0,0,0,0,0
0,0,0,0,0,0,0,0,0,0,0,0,0,0,0,0,0,0,0,0,0,0,0,0,0
0,0,0,0,0,0,0,0,0,0,0,0,0,0,0,0,0,0,0,0,0,0,0,0,0
0,0,0,0,0,0,0,0,0,0,0,0,0,0,0,0,0,0,0,0,0,0,0,0,0
0,0,0,0,0,0,0,0,0,0,0,0,0,0,0,0,0,0,0,0,0,0,0,0,0
0,0,0,0,0,0,0,0,0,0,0,0,0,0,0,0,0,0,0,0,0,0,0,0,0
0,0,0,0,0,0,0,0,0,0,0,0,0,0,0,0,0,0,0,0,0,0,0,0,0
0,0,0,0,0,0,0,0,0,0,0,0,0,0,0,0,0,0,0,0,0,0,0,0,0
0,0,0,0,0,0,0,0,0,0,0,0,0,0,0,0,0,0,0,0,0,0,0,0,0
0,0,0,0,0,0,0,0,0,0,0,0,0,0,0,0,0,0,0,0,0,0,0,0,0
0,0,0,0,0,0,0,0,0,0,0,0,0,0,0,0,0,0,0,0,0,0,0,0,0
0,0,0,0,0,0,0,0,0,0,0,0,0,0,0,0,0,0,0,0,0,0,0,0,0
0,0,0,0,0,0,0,0,0,0,0,0,0,0,0,0,0,0,0,0,0,0,0,0,0
:endlayer
layer: 31
0,0,0,0,0,0,0,0,0,0,0,0,0,0,0,0,0,0,0,0,0,0,0,0,0
0,0,0,0,0,0,0,0,0,0,0,0,0,0,0,0,0,0,0,0,0,0,0,0,0
0,0,0,0,0,0,0,0,0,0,0,0,0,0,0,0,0,0,0,0,0,0,0,0,0
0,0,0,0,0,0,0,0,0,0,0,0,0,0,0,0,0,0,0,0,0,0,0,0,0
0,0,0,0,0,0,0,0,0,0,0,0,0,0,0,0,0,0,0,0,0,0,0,0,0
0,0,0,0,0,0,0,0,0,0,0,0,0,0,0,0,0,0,0,0,0,0,0,0,0
0,0,0,0,0,0,0,0,0,0,0,0,0,0,0,0,0,0,0,0,0,0,0,0,0
0,0,0,0,0,0,0,0,0,0,0,0,0,0,0,0,0,0,0,0,0,0,0,0,0
0,0,0,0,0,0,0,0,0,0,0,0,0,0,0,0,0,0,0,0,0,0,0,0,0
0,0,0,0,0,0,0,0,0,0,0,0,0,0,0,0,0,0,0,0,0,0,0,0,0
0,0,0,0,0,0,0,0,0,0,0,0,0,0,0,0,0,0,0,0,0,0,0,0,0
0,0,0,0,0,0,0,0,0,0,0,0,0,0,0,0,0,0,0,0,0,0,0,0,0
0,0,0,0,0,0,0,0,0,0,0,0,0,0,0,0,0,0,0,0,0,0,0,0,0
0,0,0,0,0,0,0,0,0,0,0,0,0,0,0,0,0,0,0,0,0,0,0,0,0
0,0,0,0,0,0,0,0,0,0,0,0,0,0,0,0,0,0,0,0,0,0,0,0,0
0,0,0,0,0,0,0,0,0,0,0,0,0,0,0,0,0,0,0,0,0,0,0,0,0
0,0,0,0,0,0,0,0,0,0,0,0,0,0,0,0,0,0,0,0,0,0,0,0,0
0,0,0,0,0,0,0,0,0,0,0,0,0,0,0,0,0,0,0,0,0,0,0,0,0
0,0,0,0,0,0,0,0,0,0,0,0,0,0,0,0,0,0,0,0,0,0,0,0,0
0,0,0,0,0,0,0,0,0,0,0,0,0,0,0,0,0,0,0,0,0,0,0,0,0
0,0,0,0,0,0,0,0,0,0,0,0,0,0,0,0,0,0,0,0,0,0,0,0,0
0,0,0,0,0,0,0,0,0,0,0,0,0,0,0,0,0,0,0,0,0,0,0,0,0
0,0,0,0,0,0,0,0,0,0,0,0,0,0,0,0,0,0,0,0,0,0,0,0,0
0,0,0,0,0,0,0,0,0,0,0,0,0,0,0,0,0,0,0,0,0,0,0,0,0
0,0,0,0,0,0,0,0,0,0,0,0,0,0,0,0,0,0,0,0,0,0,0,0,0
:endlayer
layer: 32
0,0,0,0,0,0,0,0,0,0,0,0,0,0,0,0,0,0,0,0,0,0,0,0,0
0,0,0,0,0,0,0,0,0,0,0,0,0,0,0,0,0,0,0,0,0,0,0,0,0
0,0,0,0,0,0,0,0,0,0,0,0,0,0,0,0,0,0,0,0,0,0,0,0,0
0,0,0,0,0,0,0,0,0,0,0,0,0,0,0,0,0,0,0,0,0,0,0,0,0
0,0,0,0,0,0,0,0,0,0,0,0,0,0,0,0,0,0,0,0,0,0,0,0,0
0,0,0,0,0,0,0,0,0,0,0,0,0,0,0,0,0,0,0,0,0,0,0,0,0
0,0,0,0,0,0,0,0,0,0,0,0,0,0,0,0,0,0,0,0,0,0,0,0,0
0,0,0,0,0,0,0,0,0,0,0,0,0,0,0,0,0,0,0,0,0,0,0,0,0
0,0,0,0,0,0,0,0,0,0,0,0,0,0,0,0,0,0,0,0,0,0,0,0,0
0,0,0,0,0,0,0,0,0,0,0,0,0,0,0,0,0,0,0,0,0,0,0,0,0
0,0,0,0,0,0,0,0,0,0,0,0,0,0,0,0,0,0,0,0,0,0,0,0,0
0,0,0,0,0,0,0,0,0,0,0,0,0,0,0,0,0,0,0,0,0,0,0,0,0
0,0,0,0,0,0,0,0,0,0,0,0,0,0,0,0,0,0,0,0,0,0,0,0,0
0,0,0,0,0,0,0,0,0,0,0,0,0,0,0,0,0,0,0,0,0,0,0,0,0
0,0,0,0,0,0,0,0,0,0,0,0,0,0,0,0,0,0,0,0,0,0,0,0,0
0,0,0,0,0,0,0,0,0,0,0,0,0,0,0,0,0,0,0,0,0,0,0,0,0
0,0,0,0,0,0,0,0,0,0,0,0,0,0,0,0,0,0,0,0,0,0,0,0,0
0,0,0,0,0,0,0,0,0,0,0,0,0,0,0,0,0,0,0,0,0,0,0,0,0
0,0,0,0,0,0,0,0,0,0,0,0,0,0,0,0,0,0,0,0,0,0,0,0,0
0,0,0,0,0,0,0,0,0,0,0,0,0,0,0,0,0,0,0,0,0,0,0,0,0
0,0,0,0,0,0,0,0,0,0,0,0,0,0,0,0,0,0,0,0,0,0,0,0,0
0,0,0,0,0,0,0,0,0,0,0,0,0,0,0,0,0,0,0,0,0,0,0,0,0
0,0,0,0,0,0,0,0,0,0,0,0,0,0,0,0,0,0,0,0,0,0,0,0,0
0,0,0,0,0,0,0,0,0,0,0,0,0,0,0,0,0,0,0,0,0,0,0,0,0
0,0,0,0,0,0,0,0,0,0,0,0,0,0,0,0,0,0,0,0,0,0,0,0,0
:endlayer
layer: 33
0,0,0,0,0,0,0,0,0,0,0,0,0,0,0,0,0,0,0,0,0,0,0,0,0
0,0,0,0,0,0,0,0,0,0,0,0,0,0,0,0,0,0,0,0,0,0,0,0,0
0,0,0,0,0,0,0,0,0,0,0,0,0,0,0,0,0,0,0,0,0,0,0,0,0
0,0,0,0,0,0,0,0,0,0,0,0,0,0,0,0,0,0,0,0,0,0,0,0,0
0,0,0,0,0,0,0,0,0,0,0,0,0,0,0,0,0,0,0,0,0,0,0,0,0
0,0,0,0,0,0,0,0,0,0,0,0,0,0,0,0,0,0,0,0,0,0,0,0,0
0,0,0,0,0,0,0,0,0,0,0,0,0,0,0,0,0,0,0,0,0,0,0,0,0
0,0,0,0,0,0,0,0,0,0,0,0,0,0,0,0,0,0,0,0,0,0,0,0,0
0,0,0,0,0,0,0,0,0,0,0,0,0,0,0,0,0,0,0,0,0,0,0,0,0
0,0,0,0,0,0,0,0,0,0,0,0,0,0,0,0,0,0,0,0,0,0,0,0,0
0,0,0,0,0,0,0,0,0,0,0,0,0,0,0,0,0,0,0,0,0,0,0,0,0
0,0,0,0,0,0,0,0,0,0,0,0,0,0,0,0,0,0,0,0,0,0,0,0,0
0,0,0,0,0,0,0,0,0,0,0,0,0,0,0,0,0,0,0,0,0,0,0,0,0
0,0,0,0,0,0,0,0,0,0,0,0,0,0,0,0,0,0,0,0,0,0,0,0,0
0,0,0,0,0,0,0,0,0,0,0,0,0,0,0,0,0,0,0,0,0,0,0,0,0
0,0,0,0,0,0,0,0,0,0,0,0,0,0,0,0,0,0,0,0,0,0,0,0,0
0,0,0,0,0,0,0,0,0,0,0,0,0,0,0,0,0,0,0,0,0,0,0,0,0
0,0,0,0,0,0,0,0,0,0,0,0,0,0,0,0,0,0,0,0,0,0,0,0,0
0,0,0,0,0,0,0,0,0,0,0,0,0,0,0,0,0,0,0,0,0,0,0,0,0
0,0,0,0,0,0,0,0,0,0,0,0,0,0,0,0,0,0,0,0,0,0,0,0,0
0,0,0,0,0,0,0,0,0,0,0,0,0,0,0,0,0,0,0,0,0,0,0,0,0
0,0,0,0,0,0,0,0,0,0,0,0,0,0,0,0,0,0,0,0,0,0,0,0,0
0,0,0,0,0,0,0,0,0,0,0,0,0,0,0,0,0,0,0,0,0,0,0,0,0
0,0,0,0,0,0,0,0,0,0,0,0,0,0,0,0,0,0,0,0,0,0,0,0,0
0,0,0,0,0,0,0,0,0,0,0,0,0,0,0,0,0,0,0,0,0,0,0,0,0
:endlayer
layer: 34
0,0,0,0,0,0,0,0,0,0,0,0,0,0,0,0,0,0,0,0,0,0,0,0,0
0,0,0,0,0,0,0,0,0,0,0,0,0,0,0,0,0,0,0,0,0,0,0,0,0
0,0,0,0,0,0,0,0,0,0,0,0,0,0,0,0,0,0,0,0,0,0,0,0,0
0,0,0,0,0,0,0,0,0,0,0,0,0,0,0,0,0,0,0,0,0,0,0,0,0
0,0,0,0,0,0,0,0,0,0,0,0,0,0,0,0,0,0,0,0,0,0,0,0,0
0,0,0,0,0,0,0,0,0,0,0,0,0,0,0,0,0,0,0,0,0,0,0,0,0
0,0,0,0,0,0,0,0,0,0,0,0,0,0,0,0,0,0,0,0,0,0,0,0,0
0,0,0,0,0,0,0,0,0,0,0,0,0,0,0,0,0,0,0,0,0,0,0,0,0
0,0,0,0,0,0,0,0,0,0,0,0,0,0,0,0,0,0,0,0,0,0,0,0,0
0,0,0,0,0,0,0,0,0,0,0,0,0,0,0,0,0,0,0,0,0,0,0,0,0
0,0,0,0,0,0,0,0,0,0,0,0,0,0,0,0,0,0,0,0,0,0,0,0,0
0,0,0,0,0,0,0,0,0,0,0,0,0,0,0,0,0,0,0,0,0,0,0,0,0
0,0,0,0,0,0,0,0,0,0,0,0,0,0,0,0,0,0,0,0,0,0,0,0,0
0,0,0,0,0,0,0,0,0,0,0,0,0,0,0,0,0,0,0,0,0,0,0,0,0
0,0,0,0,0,0,0,0,0,0,0,0,0,0,0,0,0,0,0,0,0,0,0,0,0
0,0,0,0,0,0,0,0,0,0,0,0,0,0,0,0,0,0,0,0,0,0,0,0,0
0,0,0,0,0,0,0,0,0,0,0,0,0,0,0,0,0,0,0,0,0,0,0,0,0
0,0,0,0,0,0,0,0,0,0,0,0,0,0,0,0,0,0,0,0,0,0,0,0,0
0,0,0,0,0,0,0,0,0,0,0,0,0,0,0,0,0,0,0,0,0,0,0,0,0
0,0,0,0,0,0,0,0,0,0,0,0,0,0,0,0,0,0,0,0,0,0,0,0,0
0,0,0,0,0,0,0,0,0,0,0,0,0,0,0,0,0,0,0,0,0,0,0,0,0
0,0,0,0,0,0,0,0,0,0,0,0,0,0,0,0,0,0,0,0,0,0,0,0,0
0,0,0,0,0,0,0,0,0,0,0,0,0,0,0,0,0,0,0,0,0,0,0,0,0
0,0,0,0,0,0,0,0,0,0,0,0,0,0,0,0,0,0,0,0,0,0,0,0,0
0,0,0,0,0,0,0,0,0,0,0,0,0,0,0,0,0,0,0,0,0,0,0,0,0
:endlayer
layer: 35
0,0,0,0,0,0,0,0,0,0,0,0,0,0,0,0,0,0,0,0,0,0,0,0,0
0,0,0,0,0,0,0,0,0,0,0,0,0,0,0,0,0,0,0,0,0,0,0,0,0
0,0,0,0,0,0,0,0,0,0,0,0,0,0,0,0,0,0,0,0,0,0,0,0,0
0,0,0,0,0,0,0,0,0,0,0,0,0,0,0,0,0,0,0,0,0,0,0,0,0
0,0,0,0,0,0,0,0,0,0,0,0,0,0,0,0,0,0,0,0,0,0,0,0,0
0,0,0,0,0,0,0,0,0,0,0,0,0,0,0,0,0,0,0,0,0,0,0,0,0
0,0,0,0,0,0,0,0,0,0,0,0,0,0,0,0,0,0,0,0,0,0,0,0,0
0,0,0,0,0,0,0,0,0,0,0,0,0,0,0,0,0,0,0,0,0,0,0,0,0
0,0,0,0,0,0,0,0,0,0,0,0,0,0,0,0,0,0,0,0,0,0,0,0,0
0,0,0,0,0,0,0,0,0,0,0,0,0,0,0,0,0,0,0,0,0,0,0,0,0
0,0,0,0,0,0,0,0,0,0,0,0,0,0,0,0,0,0,0,0,0,0,0,0,0
0,0,0,0,0,0,0,0,0,0,0,0,0,0,0,0,0,0,0,0,0,0,0,0,0
0,0,0,0,0,0,0,0,0,0,0,0,0,0,0,0,0,0,0,0,0,0,0,0,0
0,0,0,0,0,0,0,0,0,0,0,0,0,0,0,0,0,0,0,0,0,0,0,0,0
0,0,0,0,0,0,0,0,0,0,0,0,0,0,0,0,0,0,0,0,0,0,0,0,0
0,0,0,0,0,0,0,0,0,0,0,0,0,0,0,0,0,0,0,0,0,0,0,0,0
0,0,0,0,0,0,0,0,0,0,0,0,0,0,0,0,0,0,0,0,0,0,0,0,0
0,0,0,0,0,0,0,0,0,0,0,0,0,0,0,0,0,0,0,0,0,0,0,0,0
0,0,0,0,0,0,0,0,0,0,0,0,0,0,0,0,0,0,0,0,0,0,0,0,0
0,0,0,0,0,0,0,0,0,0,0,0,0,0,0,0,0,0,0,0,0,0,0,0,0
0,0,0,0,0,0,0,0,0,0,0,0,0,0,0,0,0,0,0,0,0,0,0,0,0
0,0,0,0,0,0,0,0,0,0,0,0,0,0,0,0,0,0,0,0,0,0,0,0,0
0,0,0,0,0,0,0,0,0,0,0,0,0,0,0,0,0,0,0,0,0,0,0,0,0
0,0,0,0,0,0,0,0,0,0,0,0,0,0,0,0,0,0,0,0,0,0,0,0,0
0,0,0,0,0,0,0,0,0,0,0,0,0,0,0,0,0,0,0,0,0,0,0,0,0
:endlayer
layer: 36
0,0,0,0,0,0,0,0,0,0,0,0,0,0,0,0,0,0,0,0,0,0,0,0,0
0,0,0,0,0,0,0,0,0,0,0,0,0,0,0,0,0,0,0,0,0,0,0,0,0
0,0,0,0,0,0,0,0,0,0,0,0,0,0,0,0,0,0,0,0,0,0,0,0,0
0,0,0,0,0,0,0,0,0,0,0,0,0,0,0,0,0,0,0,0,0,0,0,0,0
0,0,0,0,0,0,0,0,0,0,0,0,0,0,0,0,0,0,0,0,0,0,0,0,0
0,0,0,0,0,0,0,0,0,0,0,0,0,0,0,0,0,0,0,0,0,0,0,0,0
0,0,0,0,0,0,0,0,0,0,0,0,0,0,0,0,0,0,0,0,0,0,0,0,0
0,0,0,0,0,0,0,0,0,0,0,0,0,0,0,0,0,0,0,0,0,0,0,0,0
0,0,0,0,0,0,0,0,0,0,0,0,0,0,0,0,0,0,0,0,0,0,0,0,0
0,0,0,0,0,0,0,0,0,0,0,0,0,0,0,0,0,0,0,0,0,0,0,0,0
0,0,0,0,0,0,0,0,0,0,0,0,0,0,0,0,0,0,0,0,0,0,0,0,0
0,0,0,0,0,0,0,0,0,0,0,0,0,0,0,0,0,0,0,0,0,0,0,0,0
0,0,0,0,0,0,0,0,0,0,0,0,0,0,0,0,0,0,0,0,0,0,0,0,0
0,0,0,0,0,0,0,0,0,0,0,0,0,0,0,0,0,0,0,0,0,0,0,0,0
0,0,0,0,0,0,0,0,0,0,0,0,0,0,0,0,0,0,0,0,0,0,0,0,0
0,0,0,0,0,0,0,0,0,0,0,0,0,0,0,0,0,0,0,0,0,0,0,0,0
0,0,0,0,0,0,0,0,0,0,0,0,0,0,0,0,0,0,0,0,0,0,0,0,0
0,0,0,0,0,0,0,0,0,0,0,0,0,0,0,0,0,0,0,0,0,0,0,0,0
0,0,0,0,0,0,0,0,0,0,0,0,0,0,0,0,0,0,0,0,0,0,0,0,0
0,0,0,0,0,0,0,0,0,0,0,0,0,0,0,0,0,0,0,0,0,0,0,0,0
0,0,0,0,0,0,0,0,0,0,0,0,0,0,0,0,0,0,0,0,0,0,0,0,0
0,0,0,0,0,0,0,0,0,0,0,0,0,0,0,0,0,0,0,0,0,0,0,0,0
0,0,0,0,0,0,0,0,0,0,0,0,0,0,0,0,0,0,0,0,0,0,0,0,0
0,0,0,0,0,0,0,0,0,0,0,0,0,0,0,0,0,0,0,0,0,0,0,0,0
0,0,0,0,0,0,0,0,0,0,0,0,0,0,0,0,0,0,0,0,0,0,0,0,0
:endlayer
layer: 37
0,0,0,0,0,0,0,0,0,0,0,0,0,0,0,0,0,0,0,0,0,0,0,0,0
0,0,0,0,0,0,0,0,0,0,0,0,0,0,0,0,0,0,0,0,0,0,0,0,0
0,0,0,0,0,0,0,0,0,0,0,0,0,0,0,0,0,0,0,0,0,0,0,0,0
0,0,0,0,0,0,0,0,0,0,0,0,0,0,0,0,0,0,0,0,0,0,0,0,0
0,0,0,0,0,0,0,0,0,0,0,0,0,0,0,0,0,0,0,0,0,0,0,0,0
0,0,0,0,0,0,0,0,0,0,0,0,0,0,0,0,0,0,0,0,0,0,0,0,0
0,0,0,0,0,0,0,0,0,0,0,0,0,0,0,0,0,0,0,0,0,0,0,0,0
0,0,0,0,0,0,0,0,0,0,0,0,0,0,0,0,0,0,0,0,0,0,0,0,0
0,0,0,0,0,0,0,0,0,0,0,0,0,0,0,0,0,0,0,0,0,0,0,0,0
0,0,0,0,0,0,0,0,0,0,0,0,0,0,0,0,0,0,0,0,0,0,0,0,0
0,0,0,0,0,0,0,0,0,0,0,0,0,0,0,0,0,0,0,0,0,0,0,0,0
0,0,0,0,0,0,0,0,0,0,0,0,0,0,0,0,0,0,0,0,0,0,0,0,0
0,0,0,0,0,0,0,0,0,0,0,0,0,0,0,0,0,0,0,0,0,0,0,0,0
0,0,0,0,0,0,0,0,0,0,0,0,0,0,0,0,0,0,0,0,0,0,0,0,0
0,0,0,0,0,0,0,0,0,0,0,0,0,0,0,0,0,0,0,0,0,0,0,0,0
0,0,0,0,0,0,0,0,0,0,0,0,0,0,0,0,0,0,0,0,0,0,0,0,0
0,0,0,0,0,0,0,0,0,0,0,0,0,0,0,0,0,0,0,0,0,0,0,0,0
0,0,0,0,0,0,0,0,0,0,0,0,0,0,0,0,0,0,0,0,0,0,0,0,0
0,0,0,0,0,0,0,0,0,0,0,0,0,0,0,0,0,0,0,0,0,0,0,0,0
0,0,0,0,0,0,0,0,0,0,0,0,0,0,0,0,0,0,0,0,0,0,0,0,0
0,0,0,0,0,0,0,0,0,0,0,0,0,0,0,0,0,0,0,0,0,0,0,0,0
0,0,0,0,0,0,0,0,0,0,0,0,0,0,0,0,0,0,0,0,0,0,0,0,0
0,0,0,0,0,0,0,0,0,0,0,0,0,0,0,0,0,0,0,0,0,0,0,0,0
0,0,0,0,0,0,0,0,0,0,0,0,0,0,0,0,0,0,0,0,0,0,0,0,0
0,0,0,0,0,0,0,0,0,0,0,0,0,0,0,0,0,0,0,0,0,0,0,0,0
:endlayer
layer: 38
0,0,0,0,0,0,0,0,0,0,0,0,0,0,0,0,0,0,0,0,0,0,0,0,0
0,0,0,0,0,0,0,0,0,0,0,0,0,0,0,0,0,0,0,0,0,0,0,0,0
0,0,0,0,0,0,0,0,0,0,0,0,0,0,0,0,0,0,0,0,0,0,0,0,0
0,0,0,0,0,0,0,0,0,0,0,0,0,0,0,0,0,0,0,0,0,0,0,0,0
0,0,0,0,0,0,0,0,0,0,0,0,0,0,0,0,0,0,0,0,0,0,0,0,0
0,0,0,0,0,0,0,0,0,0,0,0,0,0,0,0,0,0,0,0,0,0,0,0,0
0,0,0,0,0,0,0,0,0,0,0,0,0,0,0,0,0,0,0,0,0,0,0,0,0
0,0,0,0,0,0,0,0,0,0,0,0,0,0,0,0,0,0,0,0,0,0,0,0,0
0,0,0,0,0,0,0,0,0,0,0,0,0,0,0,0,0,0,0,0,0,0,0,0,0
0,0,0,0,0,0,0,0,0,0,0,0,0,0,0,0,0,0,0,0,0,0,0,0,0
0,0,0,0,0,0,0,0,0,0,0,0,0,0,0,0,0,0,0,0,0,0,0,0,0
0,0,0,0,0,0,0,0,0,0,0,0,0,0,0,0,0,0,0,0,0,0,0,0,0
0,0,0,0,0,0,0,0,0,0,0,0,0,0,0,0,0,0,0,0,0,0,0,0,0
0,0,0,0,0,0,0,0,0,0,0,0,0,0,0,0,0,0,0,0,0,0,0,0,0
0,0,0,0,0,0,0,0,0,0,0,0,0,0,0,0,0,0,0,0,0,0,0,0,0
0,0,0,0,0,0,0,0,0,0,0,0,0,0,0,0,0,0,0,0,0,0,0,0,0
0,0,0,0,0,0,0,0,0,0,0,0,0,0,0,0,0,0,0,0,0,0,0,0,0
0,0,0,0,0,0,0,0,0,0,0,0,0,0,0,0,0,0,0,0,0,0,0,0,0
0,0,0,0,0,0,0,0,0,0,0,0,0,0,0,0,0,0,0,0,0,0,0,0,0
0,0,0,0,0,0,0,0,0,0,0,0,0,0,0,0,0,0,0,0,0,0,0,0,0
0,0,0,0,0,0,0,0,0,0,0,0,0,0,0,0,0,0,0,0,0,0,0,0,0
0,0,0,0,0,0,0,0,0,0,0,0,0,0,0,0,0,0,0,0,0,0,0,0,0
0,0,0,0,0,0,0,0,0,0,0,0,0,0,0,0,0,0,0,0,0,0,0,0,0
0,0,0,0,0,0,0,0,0,0,0,0,0,0,0,0,0,0,0,0,0,0,0,0,0
0,0,0,0,0,0,0,0,0,0,0,0,0,0,0,0,0,0,0,0,0,0,0,0,0
:endlayer
layer: 39
0,0,0,0,0,0,0,0,0,0,0,0,0,0,0,0,0,0,0,0,0,0,0,0,0
0,0,0,0,0,0,0,0,0,0,0,0,0,0,0,0,0,0,0,0,0,0,0,0,0
0,0,0,0,0,0,0,0,0,0,0,0,0,0,0,0,0,0,0,0,0,0,0,0,0
0,0,0,0,0,0,0,0,0,0,0,0,0,0,0,0,0,0,0,0,0,0,0,0,0
0,0,0,0,0,0,0,0,0,0,0,0,0,0,0,0,0,0,0,0,0,0,0,0,0
0,0,0,0,0,0,0,0,0,0,0,0,0,0,0,0,0,0,0,0,0,0,0,0,0
0,0,0,0,0,0,0,0,0,0,0,0,0,0,0,0,0,0,0,0,0,0,0,0,0
0,0,0,0,0,0,0,0,0,0,0,0,0,0,0,0,0,0,0,0,0,0,0,0,0
0,0,0,0,0,0,0,0,0,0,0,0,0,0,0,0,0,0,0,0,0,0,0,0,0
0,0,0,0,0,0,0,0,0,0,0,0,0,0,0,0,0,0,0,0,0,0,0,0,0
0,0,0,0,0,0,0,0,0,0,0,0,0,0,0,0,0,0,0,0,0,0,0,0,0
0,0,0,0,0,0,0,0,0,0,0,0,0,0,0,0,0,0,0,0,0,0,0,0,0
0,0,0,0,0,0,0,0,0,0,0,0,0,0,0,0,0,0,0,0,0,0,0,0,0
0,0,0,0,0,0,0,0,0,0,0,0,0,0,0,0,0,0,0,0,0,0,0,0,0
0,0,0,0,0,0,0,0,0,0,0,0,0,0,0,0,0,0,0,0,0,0,0,0,0
0,0,0,0,0,0,0,0,0,0,0,0,0,0,0,0,0,0,0,0,0,0,0,0,0
0,0,0,0,0,0,0,0,0,0,0,0,0,0,0,0,0,0,0,0,0,0,0,0,0
0,0,0,0,0,0,0,0,0,0,0,0,0,0,0,0,0,0,0,0,0,0,0,0,0
0,0,0,0,0,0,0,0,0,0,0,0,0,0,0,0,0,0,0,0,0,0,0,0,0
0,0,0,0,0,0,0,0,0,0,0,0,0,0,0,0,0,0,0,0,0,0,0,0,0
0,0,0,0,0,0,0,0,0,0,0,0,0,0,0,0,0,0,0,0,0,0,0,0,0
0,0,0,0,0,0,0,0,0,0,0,0,0,0,0,0,0,0,0,0,0,0,0,0,0
0,0,0,0,0,0,0,0,0,0,0,0,0,0,0,0,0,0,0,0,0,0,0,0,0
0,0,0,0,0,0,0,0,0,0,0,0,0,0,0,0,0,0,0,0,0,0,0,0,0
0,0,0,0,0,0,0,0,0,0,0,0,0,0,0,0,0,0,0,0,0,0,0,0,0
:endlayer
layer: 40
0,0,0,0,0,0,0,0,0,0,0,0,0,0,0,0,0,0,0,0,0,0,0,0,0
0,0,0,0,0,0,0,0,0,0,0,0,0,0,0,0,0,0,0,0,0,0,0,0,0
0,0,0,0,0,0,0,0,0,0,0,0,0,0,0,0,0,0,0,0,0,0,0,0,0
0,0,0,0,0,0,0,0,0,0,0,0,0,0,0,0,0,0,0,0,0,0,0,0,0
0,0,0,0,0,0,0,0,0,0,0,0,0,0,0,0,0,0,0,0,0,0,0,0,0
0,0,0,0,0,0,0,0,0,0,0,0,0,0,0,0,0,0,0,0,0,0,0,0,0
0,0,0,0,0,0,0,0,0,0,0,0,0,0,0,0,0,0,0,0,0,0,0,0,0
0,0,0,0,0,0,0,0,0,0,0,0,0,0,0,0,0,0,0,0,0,0,0,0,0
0,0,0,0,0,0,0,0,0,0,0,0,0,0,0,0,0,0,0,0,0,0,0,0,0
0,0,0,0,0,0,0,0,0,0,0,0,0,0,0,0,0,0,0,0,0,0,0,0,0
0,0,0,0,0,0,0,0,0,0,0,0,0,0,0,0,0,0,0,0,0,0,0,0,0
0,0,0,0,0,0,0,0,0,0,0,0,0,0,0,0,0,0,0,0,0,0,0,0,0
0,0,0,0,0,0,0,0,0,0,0,0,0,0,0,0,0,0,0,0,0,0,0,0,0
0,0,0,0,0,0,0,0,0,0,0,0,0,0,0,0,0,0,0,0,0,0,0,0,0
0,0,0,0,0,0,0,0,0,0,0,0,0,0,0,0,0,0,0,0,0,0,0,0,0
0,0,0,0,0,0,0,0,0,0,0,0,0,0,0,0,0,0,0,0,0,0,0,0,0
0,0,0,0,0,0,0,0,0,0,0,0,0,0,0,0,0,0,0,0,0,0,0,0,0
0,0,0,0,0,0,0,0,0,0,0,0,0,0,0,0,0,0,0,0,0,0,0,0,0
0,0,0,0,0,0,0,0,0,0,0,0,0,0,0,0,0,0,0,0,0,0,0,0,0
0,0,0,0,0,0,0,0,0,0,0,0,0,0,0,0,0,0,0,0,0,0,0,0,0
0,0,0,0,0,0,0,0,0,0,0,0,0,0,0,0,0,0,0,0,0,0,0,0,0
0,0,0,0,0,0,0,0,0,0,0,0,0,0,0,0,0,0,0,0,0,0,0,0,0
0,0,0,0,0,0,0,0,0,0,0,0,0,0,0,0,0,0,0,0,0,0,0,0,0
0,0,0,0,0,0,0,0,0,0,0,0,0,0,0,0,0,0,0,0,0,0,0,0,0
0,0,0,0,0,0,0,0,0,0,0,0,0,0,0,0,0,0,0,0,0,0,0,0,0
:endlayer

#### RULES ####
rule:
plugin=vanillaBlocks
number=1
data:
JSON:{blockState:{blockName:"minecraft:dirt",properties:{variant:"dirt",snowy:"false"}}}
:enddata
:endrule

rule:
plugin=fluid
number=2
data:
JSON:{blockState:{blockName:"minecraft:water",properties:{level:"0"}}}
:enddata
:endrule

rule:
plugin=vanillaBlocks
number=3
data:
JSON:{blockState:{blockName:"minecraft:grass",properties:{snowy:"false"}}}
:enddata
:endrule

rule:
plugin=vanillaBlocks
number=4
data:
JSON:{blockState:{blockName:"minecraft:stone",properties:{variant:"stone"}}}
:enddata
:endrule

rule:
plugin=vanillaBlocks
number=5
data:
JSON:{blockState:{blockName:"minecraft:vine",properties:{east:"false",south:"true",north:"false",west:"false",up:"false"}}}
:enddata
:endrule

rule:
plugin=vanillaBlocks
number=6
data:
JSON:{blockState:{blockName:"minecraft:vine",properties:{east:"true",south:"false",north:"true",west:"false",up:"false"}}}
:enddata
:endrule

rule:
plugin=vanillaBlocks
number=7
data:
JSON:{blockState:{blockName:"minecraft:red_mushroom"}}
:enddata
:endrule

rule:
plugin=vanillaBlocks
number=8
data:
JSON:{blockState:{blockName:"minecraft:brown_mushroom"}}
:enddata
:endrule

rule:
plugin=vanillaBlocks
number=9
data:
JSON:{blockState:{blockName:"minecraft:vine",properties:{east:"false",south:"false",north:"false",west:"true",up:"false"}}}
:enddata
:endrule

rule:
plugin=vanillaBlocks
number=10
data:
JSON:{blockState:{blockName:"minecraft:vine",properties:{east:"false",south:"false",north:"true",west:"false",up:"false"}}}
:enddata
:endrule

rule:
plugin=vanillaBlocks
number=11
data:
JSON:{blockState:{blockName:"minecraft:red_mushroom_block",properties:{variant:"stem"}}}
:enddata
:endrule

rule:
plugin=vanillaBlocks
number=12
data:
JSON:{blockState:{blockName:"minecraft:red_mushroom_block",properties:{variant:"all_inside"}}}
:enddata
:endrule

rule:
plugin=vanillaBlocks
number=13
data:
JSON:{blockState:{blockName:"minecraft:vine",properties:{east:"true",south:"false",north:"false",west:"false",up:"false"}}}
:enddata
:endrule

rule:
plugin=blockTile
number=14
data:
JSON:{blockState:{blockName:"ancientwarfarestructure:advanced_spawner",properties:{transparent:"true"}},teData:{id:"ancientwarfarestructure:advanced_spawner_tile",spawnerSettings:{minDelay:0,spawnDelay:0,lightSensitive:0b,spawnGroups:[{settingsList:[{remainingSpawnCount:1,hostile:1b,forced:1b,customTag:{ArmorDropChances:[0.085f,0.085f,0.085f,0.085f],ArmorItems:[{},{},{},{}],HandDropChances:[0.085f,0.085f],HandItems:[{id:"minecraft:iron_axe",Count:1b,Damage:0s},{}]},maxToSpawn:1,entityId:"minecraft:vindication_illager",minToSpawn:1}],groupWeight:1}],playerRange:5,respondToRedstone:0b,inventory:{Size:9,Items:[]},spawnRange:0,transparent:1b,maxDelay:0,xpToDrop:0,mobRange:0,debugMode:0b,maxNearbyMonsters:0}}}
:enddata
:endrule

rule:
plugin=blockTile
number=15
data:
JSON:{blockState:{blockName:"ancientwarfarestructure:advanced_spawner",properties:{transparent:"true"}},teData:{id:"ancientwarfarestructure:advanced_spawner_tile",spawnerSettings:{minDelay:0,spawnDelay:0,lightSensitive:0b,spawnGroups:[{settingsList:[{remainingSpawnCount:1,hostile:1b,forced:1b,customTag:{ArmorDropChances:[0.085f,0.085f,0.085f,0.085f],ArmorItems:[{},{},{},{}],HandDropChances:[0.085f,0.085f],HandItems:[{id:"minecraft:iron_axe",Count:1b,Damage:0s},{}]},maxToSpawn:1,entityId:"minecraft:vindication_illager",minToSpawn:1}],groupWeight:1}],playerRange:5,respondToRedstone:0b,inventory:{Size:9,Items:[]},spawnRange:0,transparent:1b,maxDelay:0,xpToDrop:0,mobRange:0,debugMode:0b,maxNearbyMonsters:0}}}
:enddata
:endrule

rule:
plugin=blockTile
number=16
data:
JSON:{blockState:{blockName:"ancientwarfarestructure:advanced_spawner",properties:{transparent:"true"}},teData:{id:"ancientwarfarestructure:advanced_spawner_tile",spawnerSettings:{minDelay:0,spawnDelay:0,lightSensitive:0b,spawnGroups:[{settingsList:[{remainingSpawnCount:1,hostile:1b,forced:1b,customTag:{ArmorDropChances:[0.085f,0.085f,0.085f,0.085f],ArmorItems:[{},{},{},{}],HandDropChances:[0.085f,0.085f],HandItems:[{id:"minecraft:iron_axe",Count:1b,Damage:0s},{}]},maxToSpawn:1,entityId:"minecraft:vindication_illager",minToSpawn:1}],groupWeight:1}],playerRange:5,respondToRedstone:0b,inventory:{Size:9,Items:[]},spawnRange:0,transparent:1b,maxDelay:0,xpToDrop:0,mobRange:0,debugMode:0b,maxNearbyMonsters:0}}}
:enddata
:endrule

rule:
plugin=blockTile
number=17
data:
JSON:{blockState:{blockName:"ancientwarfarestructure:advanced_loot_chest",properties:{facing:"south"}},teData:{LootTable:"minecraft:chests/simple_dungeon",lootRolls:1b,id:"ancientwarfarestructure:advanced_loot_chest_tile",Lock:"",LootTableSeed:8356785610588424947L}}
:enddata
:endrule

rule:
plugin=blockTile
number=18
data:
JSON:{blockState:{blockName:"ancientwarfarestructure:advanced_spawner",properties:{transparent:"true"}},teData:{id:"ancientwarfarestructure:advanced_spawner_tile",spawnerSettings:{minDelay:0,spawnDelay:0,lightSensitive:0b,spawnGroups:[{settingsList:[{remainingSpawnCount:1,hostile:1b,forced:1b,customTag:{ArmorDropChances:[0.085f,0.085f,0.085f,0.085f],ArmorItems:[{},{},{},{}],HandDropChances:[0.085f,0.085f],HandItems:[{id:"minecraft:iron_axe",Count:1b,Damage:0s},{}]},maxToSpawn:1,entityId:"minecraft:vindication_illager",minToSpawn:1}],groupWeight:1}],playerRange:5,respondToRedstone:0b,inventory:{Size:9,Items:[]},spawnRange:0,transparent:1b,maxDelay:0,xpToDrop:0,mobRange:0,debugMode:0b,maxNearbyMonsters:0}}}
:enddata
:endrule

rule:
plugin=blockTile
number=19
data:
JSON:{blockState:{blockName:"ancientwarfarestructure:advanced_spawner",properties:{transparent:"true"}},teData:{id:"ancientwarfarestructure:advanced_spawner_tile",spawnerSettings:{minDelay:0,spawnDelay:0,lightSensitive:0b,spawnGroups:[{settingsList:[{remainingSpawnCount:1,hostile:1b,forced:1b,customTag:{ArmorDropChances:[0.085f,0.085f,0.085f,0.085f],ArmorItems:[{},{},{},{}],HandDropChances:[0.085f,0.085f],HandItems:[{},{}]},maxToSpawn:1,entityId:"minecraft:witch",minToSpawn:1}],groupWeight:1}],playerRange:5,respondToRedstone:0b,inventory:{Size:9,Items:[]},spawnRange:0,transparent:1b,maxDelay:0,xpToDrop:0,mobRange:0,debugMode:0b,maxNearbyMonsters:0}}}
:enddata
:endrule

rule:
plugin=blockTile
number=20
data:
JSON:{blockState:{blockName:"ancientwarfarestructure:advanced_spawner",properties:{transparent:"true"}},teData:{id:"ancientwarfarestructure:advanced_spawner_tile",spawnerSettings:{minDelay:0,spawnDelay:0,lightSensitive:0b,spawnGroups:[{settingsList:[{remainingSpawnCount:1,hostile:1b,forced:1b,customTag:{ArmorDropChances:[0.085f,0.085f,0.085f,0.085f],ArmorItems:[{},{},{},{}],HandDropChances:[0.085f,0.085f],HandItems:[{id:"minecraft:iron_axe",Count:1b,Damage:0s},{}]},maxToSpawn:1,entityId:"minecraft:vindication_illager",minToSpawn:1}],groupWeight:1}],playerRange:5,respondToRedstone:0b,inventory:{Size:9,Items:[]},spawnRange:0,transparent:1b,maxDelay:0,xpToDrop:0,mobRange:0,debugMode:0b,maxNearbyMonsters:0}}}
:enddata
:endrule

rule:
plugin=blockTile
number=21
data:
JSON:{blockState:{blockName:"ancientwarfarestructure:advanced_spawner",properties:{transparent:"true"}},teData:{id:"ancientwarfarestructure:advanced_spawner_tile",spawnerSettings:{minDelay:0,spawnDelay:0,lightSensitive:0b,spawnGroups:[{settingsList:[{remainingSpawnCount:1,hostile:1b,forced:1b,customTag:{ArmorDropChances:[0.085f,0.085f,0.085f,0.085f],ArmorItems:[{},{},{},{}],HandDropChances:[0.085f,0.085f],HandItems:[{id:"minecraft:iron_axe",Count:1b,Damage:0s},{}]},maxToSpawn:1,entityId:"minecraft:vindication_illager",minToSpawn:1}],groupWeight:1}],playerRange:5,respondToRedstone:0b,inventory:{Size:9,Items:[]},spawnRange:0,transparent:1b,maxDelay:0,xpToDrop:0,mobRange:0,debugMode:0b,maxNearbyMonsters:0}}}
:enddata
:endrule

rule:
plugin=blockTile
number=22
data:
JSON:{blockState:{blockName:"ancientwarfarestructure:advanced_spawner",properties:{transparent:"true"}},teData:{id:"ancientwarfarestructure:advanced_spawner_tile",spawnerSettings:{minDelay:0,spawnDelay:0,lightSensitive:0b,spawnGroups:[{settingsList:[{remainingSpawnCount:1,hostile:1b,forced:1b,customTag:{ArmorDropChances:[0.085f,0.085f,0.085f,0.085f],ArmorItems:[{},{},{},{}],HandDropChances:[0.085f,0.085f],HandItems:[{id:"minecraft:iron_axe",Count:1b,Damage:0s},{}]},maxToSpawn:1,entityId:"minecraft:vindication_illager",minToSpawn:1}],groupWeight:1}],playerRange:5,respondToRedstone:0b,inventory:{Size:9,Items:[]},spawnRange:0,transparent:1b,maxDelay:0,xpToDrop:0,mobRange:0,debugMode:0b,maxNearbyMonsters:0}}}
:enddata
:endrule

rule:
plugin=blockTile
number=23
data:
JSON:{blockState:{blockName:"ancientwarfarestructure:advanced_spawner",properties:{transparent:"true"}},teData:{id:"ancientwarfarestructure:advanced_spawner_tile",spawnerSettings:{minDelay:0,spawnDelay:0,lightSensitive:0b,spawnGroups:[{settingsList:[{remainingSpawnCount:1,hostile:1b,forced:1b,customTag:{ArmorDropChances:[0.085f,0.085f,0.085f,0.085f],ArmorItems:[{},{},{},{}],HandDropChances:[0.085f,0.085f],HandItems:[{id:"minecraft:iron_axe",Count:1b,Damage:0s},{}]},maxToSpawn:1,entityId:"minecraft:vindication_illager",minToSpawn:1}],groupWeight:1}],playerRange:5,respondToRedstone:0b,inventory:{Size:9,Items:[]},spawnRange:0,transparent:1b,maxDelay:0,xpToDrop:0,mobRange:0,debugMode:0b,maxNearbyMonsters:0}}}
:enddata
:endrule

rule:
plugin=doors
number=24
data:
JSON:{blockState:{blockName:"minecraft:jungle_door",properties:{hinge:"right",half:"lower",powered:"false",facing:"south",open:"false"}}}
:enddata
:endrule

rule:
plugin=blockTile
number=25
data:
JSON:{blockState:{blockName:"ancientwarfarestructure:advanced_spawner",properties:{transparent:"true"}},teData:{id:"ancientwarfarestructure:advanced_spawner_tile",spawnerSettings:{minDelay:0,spawnDelay:0,lightSensitive:0b,spawnGroups:[{settingsList:[{remainingSpawnCount:1,hostile:1b,forced:1b,customTag:{ArmorDropChances:[0.085f,0.085f,0.085f,0.085f],ArmorItems:[{},{},{},{}],HandDropChances:[0.085f,0.085f],HandItems:[{id:"minecraft:iron_axe",Count:1b,Damage:0s},{}]},maxToSpawn:1,entityId:"minecraft:vindication_illager",minToSpawn:1}],groupWeight:1}],playerRange:5,respondToRedstone:0b,inventory:{Size:9,Items:[]},spawnRange:0,transparent:1b,maxDelay:0,xpToDrop:0,mobRange:0,debugMode:0b,maxNearbyMonsters:0}}}
:enddata
:endrule

rule:
plugin=vanillaBlocks
number=26
data:
JSON:{blockState:{blockName:"minecraft:torch",properties:{facing:"west"}}}
:enddata
:endrule

rule:
plugin=doors
number=27
data:
JSON:{blockState:{blockName:"minecraft:jungle_door",properties:{hinge:"right",half:"upper",powered:"false",facing:"south",open:"false"}}}
:enddata
:endrule

rule:
plugin=vanillaBlocks
number=28
data:
JSON:{blockState:{blockName:"minecraft:torch",properties:{facing:"east"}}}
:enddata
:endrule

rule:
plugin=vanillaBlocks
number=29
data:
JSON:{blockState:{blockName:"minecraft:red_mushroom_block",properties:{variant:"north_west"}}}
:enddata
:endrule

rule:
plugin=vanillaBlocks
number=30
data:
JSON:{blockState:{blockName:"minecraft:red_mushroom_block",properties:{variant:"north"}}}
:enddata
:endrule

rule:
plugin=vanillaBlocks
number=31
data:
JSON:{blockState:{blockName:"minecraft:red_mushroom_block",properties:{variant:"north_east"}}}
:enddata
:endrule

rule:
plugin=vanillaBlocks
number=32
data:
JSON:{blockState:{blockName:"minecraft:red_mushroom_block",properties:{variant:"west"}}}
:enddata
:endrule

rule:
plugin=vanillaBlocks
number=33
data:
JSON:{blockState:{blockName:"minecraft:red_mushroom_block",properties:{variant:"east"}}}
:enddata
:endrule

rule:
plugin=vanillaBlocks
number=34
data:
JSON:{blockState:{blockName:"minecraft:red_mushroom_block",properties:{variant:"south_west"}}}
:enddata
:endrule

rule:
plugin=vanillaBlocks
number=35
data:
JSON:{blockState:{blockName:"minecraft:red_mushroom_block",properties:{variant:"south_east"}}}
:enddata
:endrule

rule:
plugin=vanillaBlocks
number=36
data:
JSON:{blockState:{blockName:"minecraft:red_mushroom_block",properties:{variant:"south"}}}
:enddata
:endrule

rule:
plugin=vanillaBlocks
number=37
data:
JSON:{blockState:{blockName:"minecraft:vine",properties:{east:"true",south:"true",north:"false",west:"false",up:"false"}}}
:enddata
:endrule

rule:
plugin=vanillaBlocks
number=38
data:
JSON:{blockState:{blockName:"minecraft:vine",properties:{east:"false",south:"false",north:"true",west:"true",up:"false"}}}
:enddata
:endrule

rule:
plugin=vanillaBlocks
number=39
data:
JSON:{blockState:{blockName:"minecraft:red_mushroom_block",properties:{variant:"center"}}}
:enddata
:endrule

rule:
plugin=vanillaBlocks
number=40
data:
JSON:{blockState:{blockName:"minecraft:brown_mushroom_block",properties:{variant:"all_inside"}}}
:enddata
:endrule

#### ENTITIES ####
entity:
plugin=entity
number=0
data:
JSON:{yOffset:0.0f,xOffset:0.9874886f,rotation:306.39417f,mobID:"minecraft:item",zOffset:0.79140764f,position:3299474407435L,entityData:{Motion:[4.9E-324d,-0.0d,4.9E-324d],Health:5s,Invulnerable:0b,Air:300s,OnGround:1b,Dimension:0,PortalCooldown:0,Rotation:[216.39417f,0.0f],UpdateBlocked:0b,FallDistance:0.0f,Item:{id:"ebwizardry:spell_book",Count:1b,Damage:20s},Pos:[-37.20859236746672d,108.0d,1215.0125113515073d],PickupDelay:0s,Fire:-1s,ForgeCaps:{"llibrary:extendedentitydatacapability":{}},Lifespan:6000,Age:5784s}}
:enddata
:endentity

entity:
plugin=entity
number=1
data:
JSON:{yOffset:0.0f,xOffset:0.875f,rotation:347.3498f,mobID:"minecraft:item",zOffset:0.6095967f,position:3574352314379L,entityData:{Motion:[-4.9E-324d,-0.0d,0.0d],Health:5s,Invulnerable:0b,Air:300s,OnGround:1b,Dimension:0,PortalCooldown:0,Rotation:[257.3498f,0.0f],UpdateBlocked:0b,FallDistance:0.0f,Item:{id:"ebwizardry:spell_book",Count:1b,Damage:1s},Pos:[-37.39040322641652d,108.0d,1214.125d],PickupDelay:0s,Fire:-1s,ForgeCaps:{"llibrary:extendedentitydatacapability":{}},Lifespan:6000,Age:5784s}}
:enddata
:endentity

entity:
plugin=entity
number=2
data:
JSON:{yOffset:0.0f,xOffset:0.47096592f,rotation:226.08163f,mobID:"minecraft:item",zOffset:0.875f,position:3299474407435L,entityData:{Motion:[0.0d,-0.0d,4.9E-324d],Health:5s,Invulnerable:0b,Air:300s,OnGround:1b,Dimension:0,PortalCooldown:0,Rotation:[136.08163f,0.0f],UpdateBlocked:0b,FallDistance:0.0f,Item:{id:"ebwizardry:firebomb",Count:2b,Damage:0s},Pos:[-37.125d,108.0d,1215.529034093491d],PickupDelay:0s,Fire:-1s,ForgeCaps:{"llibrary:extendedentitydatacapability":{}},Lifespan:6000,Age:5784s}}
:enddata
:endentity

entity:
plugin=entity
number=3
data:
JSON:{yOffset:0.0f,xOffset:0.76918375f,rotation:33.131165f,mobID:"minecraft:item",zOffset:0.22223473f,position:3574352314380L,entityData:{Motion:[4.9E-324d,-0.0d,-4.9E-324d],Health:5s,Invulnerable:0b,Air:300s,OnGround:1b,Dimension:0,PortalCooldown:0,Rotation:[303.13116f,0.0f],UpdateBlocked:0b,FallDistance:0.0f,Item:{id:"ebwizardry:scroll",Count:1b,Damage:1s},Pos:[-36.777765297905496d,108.0d,1214.230816273546d],PickupDelay:0s,Fire:-1s,ForgeCaps:{"llibrary:extendedentitydatacapability":{}},Lifespan:6000,Age:5784s}}
:enddata
:endentity

entity:
plugin=entity
number=4
data:
JSON:{yOffset:0.0f,xOffset:0.47136045f,rotation:62.852234f,mobID:"minecraft:item",zOffset:0.60340685f,position:3574352314379L,entityData:{Motion:[4.9E-324d,-0.0d,-4.9E-324d],Health:5s,Invulnerable:0b,Air:300s,OnGround:1b,Dimension:0,PortalCooldown:0,Rotation:[332.85223f,0.0f],UpdateBlocked:0b,FallDistance:0.0f,Item:{id:"minecraft:diamond_horse_armor",Count:1b,Damage:0s},Pos:[-37.396593141665825d,108.0d,1214.5286395718979d],PickupDelay:0s,Fire:-1s,ForgeCaps:{"llibrary:extendedentitydatacapability":{}},Lifespan:6000,Age:5784s}}
:enddata
:endentity

entity:
plugin=entity
number=5
data:
JSON:{yOffset:0.0f,xOffset:0.875f,rotation:143.36377f,mobID:"minecraft:item",zOffset:0.125f,position:3574352314379L,entityData:{Motion:[0.0d,-0.0d,0.0d],Health:5s,Invulnerable:0b,Air:300s,OnGround:1b,Dimension:0,PortalCooldown:0,Rotation:[53.363766f,0.0f],UpdateBlocked:0b,FallDistance:0.0f,Item:{id:"ancientwarfarenpc:iron_halberd",Count:1b,Damage:0s},Pos:[-37.875d,108.0d,1214.125d],PickupDelay:0s,Fire:-1s,ForgeCaps:{"llibrary:extendedentitydatacapability":{}},Lifespan:6000,Age:5784s}}
:enddata
:endentity

entity:
plugin=entity
number=6
data:
JSON:{yOffset:0.0f,xOffset:0.9581797f,rotation:310.8515f,mobID:"minecraft:item",zOffset:0.125f,position:3299474407435L,entityData:{Motion:[0.0d,-0.0d,4.9E-324d],Health:5s,Invulnerable:0b,Air:300s,OnGround:1b,Dimension:0,PortalCooldown:0,Rotation:[220.8515f,0.0f],UpdateBlocked:0b,FallDistance:0.0f,Item:{id:"minecraft:redstone",Count:3b,Damage:0s},Pos:[-37.875d,108.0d,1215.0418202742162d],PickupDelay:0s,Fire:-1s,ForgeCaps:{"llibrary:extendedentitydatacapability":{}},Lifespan:6000,Age:5784s}}
:enddata
:endentity

entity:
plugin=entity
number=7
data:
JSON:{yOffset:0.0f,xOffset:0.5613806f,rotation:31.305511f,mobID:"minecraft:item",zOffset:0.6061529f,position:3574352314379L,entityData:{Motion:[-4.9E-324d,-0.0d,-4.9E-324d],Health:5s,Invulnerable:0b,Air:300s,OnGround:1b,Dimension:0,PortalCooldown:0,Rotation:[301.3055f,0.0f],UpdateBlocked:0b,FallDistance:0.0f,Item:{id:"minecraft:string",Count:6b,Damage:0s},Pos:[-37.393847127687074d,108.0d,1214.4386193841701d],PickupDelay:0s,Fire:-1s,ForgeCaps:{"llibrary:extendedentitydatacapability":{}},Lifespan:6000,Age:5783s}}
:enddata
:endentity

entity:
plugin=entity
number=8
data:
JSON:{yOffset:0.0f,xOffset:0.875f,rotation:131.04625f,mobID:"minecraft:item",zOffset:0.125f,position:3574352314379L,entityData:{Motion:[0.0d,-0.0d,0.0d],Health:5s,Invulnerable:0b,Air:300s,OnGround:1b,Dimension:0,PortalCooldown:0,Rotation:[41.046246f,0.0f],UpdateBlocked:0b,FallDistance:0.0f,Item:{id:"minecraft:redstone",Count:1b,Damage:0s},Pos:[-37.875d,108.0d,1214.125d],PickupDelay:0s,Fire:-1s,ForgeCaps:{"llibrary:extendedentitydatacapability":{}},Lifespan:6000,Age:5784s}}
:enddata
:endentity

entity:
plugin=entity
number=9
data:
JSON:{yOffset:0.0f,xOffset:0.875f,rotation:268.52682f,mobID:"minecraft:item",zOffset:0.57046914f,position:3574352314379L,entityData:{Motion:[4.9E-324d,-0.0d,0.0d],Health:5s,Invulnerable:0b,Air:300s,OnGround:1b,Dimension:0,PortalCooldown:0,Rotation:[178.52682f,0.0f],UpdateBlocked:0b,FallDistance:0.0f,Item:{id:"ebwizardry:spell_book",Count:1b,Damage:8s},Pos:[-37.42953085161738d,108.0d,1214.125d],PickupDelay:0s,Fire:-1s,ForgeCaps:{"llibrary:extendedentitydatacapability":{}},Lifespan:6000,Age:5784s}}
:enddata
:endentity

entity:
plugin=entity
number=10
data:
JSON:{yOffset:0.0f,xOffset:0.8530401f,rotation:81.54947f,mobID:"minecraft:item",zOffset:0.8006987f,position:3574352314379L,entityData:{Motion:[4.9E-324d,-0.0d,-4.9E-324d],Health:5s,Invulnerable:0b,Air:300s,OnGround:1b,Dimension:0,PortalCooldown:0,Rotation:[351.54947f,0.0f],UpdateBlocked:0b,FallDistance:0.0f,Item:{id:"minecraft:bone",Count:4b,Damage:0s},Pos:[-37.19930131282216d,108.0d,1214.1469599161312d],PickupDelay:0s,Fire:-1s,ForgeCaps:{"llibrary:extendedentitydatacapability":{}},Lifespan:6000,Age:5784s}}
:enddata
:endentity

entity:
plugin=entity
number=11
data:
JSON:{yOffset:0.0f,xOffset:0.22970879f,rotation:315.02252f,mobID:"minecraft:item",zOffset:0.125f,position:3299474407435L,entityData:{Motion:[0.0d,-0.0d,4.9E-324d],Health:5s,Invulnerable:0b,Air:300s,OnGround:1b,Dimension:0,PortalCooldown:0,Rotation:[225.02254f,0.0f],UpdateBlocked:0b,FallDistance:0.0f,Item:{id:"exoticbirds:phoenix_dust",Count:2b,Damage:0s},Pos:[-37.875d,108.0d,1215.7702912027157d],PickupDelay:0s,Fire:-1s,ForgeCaps:{"llibrary:extendedentitydatacapability":{}},Lifespan:6000,Age:5784s}}
:enddata
:endentity

entity:
plugin=entity
number=12
data:
JSON:{yOffset:0.0f,xOffset:0.29544502f,rotation:107.08428f,mobID:"minecraft:item",zOffset:0.125f,position:3574352314379L,entityData:{Motion:[0.0d,-0.0d,4.9E-324d],Health:5s,Invulnerable:0b,Air:300s,OnGround:1b,Dimension:0,PortalCooldown:0,Rotation:[17.08428f,0.0f],UpdateBlocked:0b,FallDistance:0.0f,Item:{id:"ebwizardry:spell_book",Count:1b,Damage:44s},Pos:[-37.875d,108.0d,1214.7045549853765d],PickupDelay:0s,Fire:-1s,ForgeCaps:{"llibrary:extendedentitydatacapability":{}},Lifespan:6000,Age:5784s}}
:enddata
:endentity

entity:
plugin=entity
number=13
data:
JSON:{yOffset:0.0f,xOffset:0.6745185f,rotation:118.14343f,mobID:"minecraft:item",zOffset:0.125f,position:3574352314379L,entityData:{Motion:[0.0d,-0.0d,-4.9E-324d],Health:5s,Invulnerable:0b,Air:300s,OnGround:1b,Dimension:0,PortalCooldown:0,Rotation:[28.143433f,0.0f],UpdateBlocked:0b,FallDistance:0.0f,Item:{id:"minecraft:rotten_flesh",Count:4b,Damage:0s},Pos:[-37.875d,108.0d,1214.325481485687d],PickupDelay:0s,Fire:-1s,ForgeCaps:{"llibrary:extendedentitydatacapability":{}},Lifespan:6000,Age:5784s}}
:enddata
:endentity

entity:
plugin=entity
number=14
data:
JSON:{yOffset:0.0f,xOffset:0.501131f,rotation:0.15029907f,mobID:"minecraft:skeleton",zOffset:0.268713f,position:2199895670790L,entityData:{HurtByTimestamp:0,ForgeData:{},Attributes:[{Base:20.0d,Name:"generic.maxHealth"},{Base:0.0d,Name:"generic.knockbackResistance"},{Base:0.25d,Name:"generic.movementSpeed"},{Base:0.0d,Name:"generic.armor"},{Base:0.0d,Name:"generic.armorToughness"},{Base:1.0d,Name:"forge.swimSpeed"},{Base:16.0d,Modifiers:[{UUIDMost:-2068408778212487521L,UUIDLeast:-6114369483932914851L,Amount:-0.07345449915043406d,Operation:1,Name:"Random spawn bonus"}],Name:"generic.followRange"},{Base:2.0d,Name:"generic.attackDamage"}],Invulnerable:0b,FallFlying:0b,PortalCooldown:0,AbsorptionAmount:0.0f,FallDistance:0.0f,DeathTime:0s,ForgeCaps:{"dsurround:emojidata":{as:1,es:0,et:0},"llibrary:extendedentitydatacapability":{"mm:living":{frozenYaw:0.0f,freezeProgress:0.0f,frozenPitch:0.0f,frozenYawHead:0.0f,frozenEntityID:-1,frozenLimbSwingAmount:0.0f,frozenRenderYawOffset:0.0f,frozenSwingProgress:0.0f}}},HandDropChances:[0.085f,0.085f],PersistenceRequired:0b,Motion:[0.0d,-0.0784000015258789d,0.0d],Leashed:0b,Health:20.0f,LeftHanded:0b,Air:300s,OnGround:1b,Dimension:0,Rotation:[270.1503f,0.0f],UpdateBlocked:0b,HandItems:[{id:"minecraft:bow",Count:1b,Damage:0s},{}],ArmorDropChances:[0.085f,0.085f,0.085f,0.085f],Pos:[-42.73128702825727d,107.0d,1219.4988689933368d],Fire:-1s,ArmorItems:[{},{},{},{}],CanPickUpLoot:0b,HurtTime:0s}}
:enddata
:endentity

