# Ancient Warfare Structure Template File
# Auto-generated structure template file. created on: 12/21/2014 at: 14:19:20
# Lines beginning with # denote comments

header:
version=2.1
name=unique_giant_oak
size=12,17,11
offset=8,1,10
:endheader

#### VALIDATION ####
validation:
type=ground
survival=false
worldGenEnabled=false
unique=false
preserveBlocks=false
selectionWeight=0
clusterValue=0
minDuplicateDistance=0
dimensionWhiteList=false
dimensionList=
biomeWhiteList=false
biomeList=
leveling=0
fill=0
border=0
blockSwap=false
data:
:enddata
:endvalidation

#### LAYERS ####
layer: 0
1,1,1,1,1,1,1,1,1,1,1,1
1,1,1,1,1,1,1,1,1,1,1,1
1,1,1,1,1,1,1,1,1,1,1,1
1,1,1,1,1,1,1,1,1,1,1,1
1,1,1,1,1,2,2,1,1,1,1,1
1,1,1,1,1,2,2,1,1,1,1,1
1,1,1,1,1,1,1,1,1,1,1,1
1,1,1,1,1,1,1,1,1,1,1,1
1,1,1,1,1,1,1,1,1,1,1,1
1,1,1,1,1,1,1,1,1,1,1,1
1,1,1,1,1,1,1,1,1,1,1,1
:endlayer
layer: 1
0,0,0,3,0,0,0,0,0,0,0,0
3,0,0,0,3,4,5,3,6,0,3,0
0,3,3,5,0,3,3,0,7,0,3,0
3,4,6,0,3,0,3,0,6,0,0,6
0,3,0,3,0,8,8,0,0,0,3,0
3,0,0,0,5,8,8,0,9,0,0,9
0,5,3,4,0,0,3,0,9,7,0,0
0,9,0,0,0,6,7,0,0,0,6,0
0,3,0,3,3,9,0,3,0,4,3,0
0,6,3,0,5,0,0,0,0,0,7,0
0,0,0,0,0,0,3,0,6,0,0,0
:endlayer
layer: 2
0,0,0,0,0,0,0,0,0,0,0,0
0,0,0,0,0,0,0,0,10,0,0,0
0,0,0,0,0,0,0,0,0,0,0,0
0,0,11,0,0,0,0,0,10,0,0,11
0,0,0,0,0,8,8,0,0,0,0,0
0,0,0,0,0,8,8,0,12,0,0,11
0,0,0,0,0,0,0,0,12,0,0,0
0,12,0,0,0,12,0,0,0,0,11,0
0,0,0,0,0,13,0,0,0,0,0,0
0,13,0,0,0,0,0,0,0,0,0,0
0,0,0,0,0,0,0,0,13,0,0,0
:endlayer
layer: 3
0,0,0,0,0,0,0,0,0,0,0,0
0,0,0,0,0,0,0,0,0,0,0,0
0,0,0,0,0,0,0,0,0,0,0,0
0,0,0,0,0,0,0,0,0,0,0,0
0,0,0,0,0,8,8,0,0,0,0,0
0,0,0,0,0,8,8,0,0,0,0,0
0,0,0,0,0,14,15,16,0,0,0,0
0,0,0,0,0,0,16,0,0,0,0,0
0,0,0,0,0,0,0,0,0,0,0,0
0,0,0,0,0,0,0,0,0,0,0,0
0,0,0,0,0,0,0,0,0,0,0,0
:endlayer
layer: 4
0,0,0,0,0,0,0,0,0,0,0,0
0,0,0,0,0,0,0,0,0,0,0,0
0,0,0,0,0,0,0,0,0,0,0,0
0,0,0,0,0,0,0,16,0,0,0,0
0,0,0,0,16,8,8,17,16,0,0,0
0,0,0,16,17,8,8,16,16,0,0,0
0,0,0,0,16,16,14,0,0,0,0,0
0,0,0,0,0,0,0,0,0,0,0,0
0,0,0,0,0,0,0,0,0,0,0,0
0,0,0,0,0,0,0,0,0,0,0,0
0,0,0,0,0,0,0,0,0,0,0,0
:endlayer
layer: 5
0,0,0,0,0,0,0,0,0,0,0,0
0,0,0,0,0,0,0,0,0,0,0,0
0,0,0,0,0,16,0,0,0,0,0,0
0,0,0,0,18,15,16,0,0,0,0,0
0,0,0,0,18,8,8,16,0,0,0,0
0,0,0,0,18,8,8,0,0,0,0,0
0,0,0,0,0,0,0,0,0,0,0,0
0,0,0,0,0,0,0,0,0,0,0,0
0,0,0,0,0,0,0,0,0,0,0,0
0,0,0,0,0,0,0,0,0,0,0,0
0,0,0,0,0,0,0,0,0,0,0,0
:endlayer
layer: 6
0,0,0,0,0,0,0,0,0,0,0,0
0,0,0,0,0,0,0,0,0,0,0,0
0,0,0,0,0,0,0,0,0,0,0,0
0,0,0,0,18,18,0,0,0,0,0,0
0,0,0,0,0,8,8,0,0,0,0,0
0,0,0,0,0,8,8,0,0,0,0,0
0,0,0,0,0,0,0,0,0,0,0,0
0,0,0,0,0,0,0,0,0,0,0,0
0,0,0,0,0,0,0,0,0,0,0,0
0,0,0,0,0,0,0,0,0,0,0,0
0,0,0,0,0,0,0,0,0,0,0,0
:endlayer
layer: 7
0,0,0,0,0,0,0,0,0,0,0,0
0,0,0,0,0,0,0,0,0,0,0,0
0,0,0,0,0,0,0,0,0,0,0,0
0,0,18,18,18,0,0,16,18,18,0,0
0,0,0,18,18,8,8,16,18,18,18,0
0,0,0,17,17,8,8,17,17,17,18,0
0,0,0,18,16,15,18,15,18,16,0,0
0,0,0,18,16,15,16,15,18,0,0,0
0,0,0,18,18,15,18,18,0,0,0,0
0,0,0,0,0,16,0,0,0,0,0,0
0,0,0,0,0,0,0,0,0,0,0,0
:endlayer
layer: 8
0,0,0,0,0,0,0,0,0,0,0,0
0,0,0,0,18,16,16,0,0,0,0,0
0,0,18,18,18,15,16,16,0,16,0,0
0,0,18,18,18,15,16,16,18,15,16,0
0,18,18,18,18,8,8,16,18,15,18,16
0,18,17,8,18,8,8,16,18,8,17,16
0,18,18,18,16,16,16,16,16,16,16,16
0,0,18,18,16,16,16,8,17,16,16,0
0,0,18,18,18,8,18,18,15,18,0,0
0,0,0,18,18,15,18,18,18,0,0,0
0,0,0,0,18,18,18,0,0,0,0,0
:endlayer
layer: 9
0,0,0,0,16,16,16,0,0,0,0,0
0,0,0,18,16,15,16,16,0,0,0,0
0,0,18,18,16,8,16,16,0,0,0,0
0,0,16,16,16,16,16,0,0,16,0,0
0,18,18,18,18,8,8,16,18,18,18,0
0,18,18,18,18,8,8,16,18,18,18,16
0,16,16,16,16,16,16,16,16,16,16,0
0,0,18,18,16,16,16,16,16,16,0,0
0,0,0,18,18,16,16,16,18,18,0,0
0,0,0,0,18,16,16,0,0,0,0,0
0,0,0,0,0,16,0,0,0,0,0,0
:endlayer
layer: 10
0,0,0,0,0,0,0,0,0,0,0,0
0,0,0,0,0,16,0,0,0,0,0,0
0,0,0,0,0,16,0,0,0,0,0,0
0,18,16,16,16,16,0,0,0,0,0,0
0,18,17,17,17,8,16,16,0,0,0,0
0,18,18,18,18,8,8,17,16,0,0,0
0,0,18,16,16,15,16,16,0,0,0,0
0,0,0,0,0,16,0,0,0,0,0,0
0,0,0,0,0,0,0,0,0,0,0,0
0,0,0,0,0,0,0,0,0,0,0,0
0,0,0,0,0,0,0,0,0,0,0,0
:endlayer
layer: 11
0,0,0,0,0,0,0,0,0,0,0,0
0,0,0,0,0,0,0,0,0,0,0,0
0,0,0,0,0,0,0,0,0,0,0,0
18,16,16,16,16,16,0,0,0,0,0,0
18,17,8,16,16,8,16,16,18,0,0,0
0,16,16,16,16,16,16,8,17,18,0,0
0,0,18,17,17,8,16,15,18,0,0,0
0,0,18,15,16,16,16,15,0,0,0,0
0,0,18,16,16,0,0,16,0,0,0,0
0,0,0,0,0,0,0,0,0,0,0,0
0,0,0,0,0,0,0,0,0,0,0,0
:endlayer
layer: 12
0,16,16,16,16,16,16,16,0,0,0,0
0,16,17,15,16,16,15,17,16,0,0,0
0,16,16,15,16,15,17,16,16,16,0,0
0,16,16,16,17,15,16,16,15,17,16,0
0,16,18,16,18,8,16,16,15,18,16,16
0,16,18,18,18,16,16,16,8,17,17,16
0,16,18,18,18,16,16,16,16,16,16,16
0,18,17,8,18,16,16,8,16,16,0,0
0,18,18,18,18,0,16,15,17,16,0,0
0,0,0,0,0,0,0,16,16,16,0,0
0,0,0,0,0,0,0,0,0,0,0,0
:endlayer
layer: 13
0,0,0,0,0,0,0,0,0,0,0,0
0,16,16,16,0,0,16,16,0,0,0,0
0,0,16,16,0,16,16,0,0,0,0,0
0,0,0,0,16,16,16,16,16,16,0,0
0,0,0,0,18,8,17,16,18,16,0,0
0,0,0,16,18,16,15,16,18,16,16,0
0,0,18,18,18,16,16,16,16,16,0,0
0,18,18,18,18,0,16,16,16,0,0,0
0,0,0,0,18,0,0,16,16,0,0,0
0,0,0,0,0,0,0,0,0,0,0,0
0,0,0,0,0,0,0,0,0,0,0,0
:endlayer
layer: 14
0,0,0,0,0,0,0,0,0,0,0,0
0,0,0,0,0,0,0,0,0,0,0,0
0,0,0,0,16,0,0,0,0,0,0,0
0,0,0,16,15,16,16,0,0,0,0,0
0,0,0,18,17,8,16,16,0,0,0,0
0,0,0,0,18,16,8,17,16,0,0,0
0,0,0,0,18,17,15,16,0,0,0,0
0,0,0,0,16,16,16,0,0,0,0,0
0,0,0,0,0,16,16,0,0,0,0,0
0,0,0,0,0,0,0,0,0,0,0,0
0,0,0,0,0,0,0,0,0,0,0,0
:endlayer
layer: 15
0,0,0,0,0,0,0,0,0,0,0,0
0,0,0,0,0,16,0,0,0,0,0,0
0,0,0,16,16,15,16,16,0,0,0,0
0,0,16,16,8,16,16,16,16,0,0,0
0,0,16,16,16,16,16,15,16,0,0,0
0,0,0,0,0,0,16,8,16,0,0,0
0,0,0,0,0,16,16,16,16,0,0,0
0,0,0,0,0,0,0,0,0,0,0,0
0,0,0,0,0,0,0,0,0,0,0,0
0,0,0,0,0,0,0,0,0,0,0,0
0,0,0,0,0,0,0,0,0,0,0,0
:endlayer
layer: 16
0,0,0,0,0,0,0,0,0,0,0,0
0,0,0,0,0,0,0,0,0,0,0,0
0,0,0,0,0,16,0,0,0,0,0,0
0,0,0,0,16,16,16,16,0,0,0,0
0,0,0,0,0,16,16,16,0,0,0,0
0,0,0,0,0,0,0,16,0,0,0,0
0,0,0,0,0,0,0,0,0,0,0,0
0,0,0,0,0,0,0,0,0,0,0,0
0,0,0,0,0,0,0,0,0,0,0,0
0,0,0,0,0,0,0,0,0,0,0,0
0,0,0,0,0,0,0,0,0,0,0,0
:endlayer

#### RULES ####
rule:
plugin=vanillaBlocks
number=1
data:
JSON:{{"val":{"blockName":{"val":"minecraft:grass","id":"ss"},"meta":{"val":"0","id":"pi"},"buildPass":{"val":"0","id":"pi"}},"id":"ct"}}
:enddata
:endrule

rule:
plugin=vanillaBlocks
number=2
data:
JSON:{{"val":{"blockName":{"val":"minecraft:dirt","id":"ss"},"meta":{"val":"0","id":"pi"},"buildPass":{"val":"0","id":"pi"}},"id":"ct"}}
:enddata
:endrule

rule:
plugin=vanillaBlocks
number=3
data:
JSON:{{"val":{"blockName":{"val":"minecraft:tallgrass","id":"ss"},"meta":{"val":"1","id":"pi"},"buildPass":{"val":"2","id":"pi"}},"id":"ct"}}
:enddata
:endrule

rule:
plugin=vanillaBlocks
number=4
data:
JSON:{{"val":{"blockName":{"val":"minecraft:red_flower","id":"ss"},"meta":{"val":"0","id":"pi"},"buildPass":{"val":"2","id":"pi"}},"id":"ct"}}
:enddata
:endrule

rule:
plugin=vanillaBlocks
number=5
data:
JSON:{{"val":{"blockName":{"val":"minecraft:red_flower","id":"ss"},"meta":{"val":"5","id":"pi"},"buildPass":{"val":"2","id":"pi"}},"id":"ct"}}
:enddata
:endrule

rule:
plugin=vanillaBlocks
number=6
data:
JSON:{{"val":{"blockName":{"val":"minecraft:double_plant","id":"ss"},"meta":{"val":"3","id":"pi"},"buildPass":{"val":"2","id":"pi"}},"id":"ct"}}
:enddata
:endrule

rule:
plugin=vanillaBlocks
number=7
data:
JSON:{{"val":{"blockName":{"val":"minecraft:yellow_flower","id":"ss"},"meta":{"val":"0","id":"pi"},"buildPass":{"val":"2","id":"pi"}},"id":"ct"}}
:enddata
:endrule

rule:
plugin=vanillaBlocks
number=8
data:
JSON:{{"val":{"blockName":{"val":"minecraft:log","id":"ss"},"meta":{"val":"0","id":"pi"},"buildPass":{"val":"0","id":"pi"}},"id":"ct"}}
:enddata
:endrule

rule:
plugin=vanillaBlocks
number=9
data:
JSON:{{"val":{"blockName":{"val":"minecraft:double_plant","id":"ss"},"meta":{"val":"2","id":"pi"},"buildPass":{"val":"2","id":"pi"}},"id":"ct"}}
:enddata
:endrule

rule:
plugin=vanillaBlocks
number=10
data:
JSON:{{"val":{"blockName":{"val":"minecraft:double_plant","id":"ss"},"meta":{"val":"9","id":"pi"},"buildPass":{"val":"2","id":"pi"}},"id":"ct"}}
:enddata
:endrule

rule:
plugin=vanillaBlocks
number=11
data:
JSON:{{"val":{"blockName":{"val":"minecraft:double_plant","id":"ss"},"meta":{"val":"10","id":"pi"},"buildPass":{"val":"2","id":"pi"}},"id":"ct"}}
:enddata
:endrule

rule:
plugin=vanillaBlocks
number=12
data:
JSON:{{"val":{"blockName":{"val":"minecraft:double_plant","id":"ss"},"meta":{"val":"8","id":"pi"},"buildPass":{"val":"2","id":"pi"}},"id":"ct"}}
:enddata
:endrule

rule:
plugin=vanillaBlocks
number=13
data:
JSON:{{"val":{"blockName":{"val":"minecraft:double_plant","id":"ss"},"meta":{"val":"11","id":"pi"},"buildPass":{"val":"2","id":"pi"}},"id":"ct"}}
:enddata
:endrule

rule:
plugin=vanillaBlocks
number=14
data:
JSON:{{"val":{"blockName":{"val":"minecraft:leaves","id":"ss"},"meta":{"val":"0","id":"pi"},"buildPass":{"val":"0","id":"pi"}},"id":"ct"}}
:enddata
:endrule

rule:
plugin=vanillaBlocks
number=15
data:
JSON:{{"val":{"blockName":{"val":"minecraft:log","id":"ss"},"meta":{"val":"8","id":"pi"},"buildPass":{"val":"0","id":"pi"}},"id":"ct"}}
:enddata
:endrule

rule:
plugin=vanillaBlocks
number=16
data:
JSON:{{"val":{"blockName":{"val":"minecraft:leaves","id":"ss"},"meta":{"val":"4","id":"pi"},"buildPass":{"val":"0","id":"pi"}},"id":"ct"}}
:enddata
:endrule

rule:
plugin=vanillaBlocks
number=17
data:
JSON:{{"val":{"blockName":{"val":"minecraft:log","id":"ss"},"meta":{"val":"4","id":"pi"},"buildPass":{"val":"0","id":"pi"}},"id":"ct"}}
:enddata
:endrule

rule:
plugin=vanillaBlocks
number=18
data:
JSON:{{"val":{"blockName":{"val":"minecraft:leaves","id":"ss"},"meta":{"val":"12","id":"pi"},"buildPass":{"val":"0","id":"pi"}},"id":"ct"}}
:enddata
:endrule

#### ENTITIES ####
