# Ancient Warfare Structure Template File
# Auto-generated structure template file. created on: 9/22/2018 at: 16:7:2
# Lines beginning with # denote comments

header:
version=2.6
name=unique_creeper_church_dulciphi
size=25,16,29
offset=7,1,28
:endheader

#### VALIDATION ####
validation:
type=ground
survival=false
worldGenEnabled=false
unique=false
preserveBlocks=false
selectionWeight=0
clusterValue=0
minDuplicateDistance=0
dimensionWhiteList=false
dimensionList=
biomeWhiteList=false
biomeList=
leveling=0
fill=0
border=0
blockSwap=false
data:
:enddata
:endvalidation

#### LAYERS ####
layer: 0
1,1,1,1,1,1,1,1,1,1,1,1,1,1,1,1,1,1,1,1,1,1,1,1,1
1,2,2,2,2,2,2,2,2,2,2,2,2,1,1,1,1,1,1,1,1,1,1,1,1
1,2,1,1,1,1,1,1,1,1,2,2,2,2,2,2,2,2,2,2,2,2,1,1,1
1,2,1,1,1,1,1,1,1,1,1,2,2,2,2,2,2,1,2,2,2,2,1,1,1
1,2,1,1,1,1,1,2,2,2,1,1,1,1,2,2,2,2,2,2,2,2,1,1,1
1,2,1,1,1,1,2,1,2,2,2,2,1,2,2,2,2,2,2,2,2,2,1,1,1
1,2,2,2,2,1,1,2,2,1,2,2,1,1,2,2,2,2,2,2,2,2,1,1,1
1,2,2,1,2,1,1,1,2,2,2,2,1,2,2,2,2,2,2,2,1,2,1,1,1
1,2,1,1,1,1,1,1,1,2,2,1,2,1,2,2,2,2,2,2,1,2,1,1,1
1,2,2,2,2,1,1,1,1,1,1,1,2,2,1,2,2,2,2,2,1,2,1,1,1
1,2,2,2,2,2,2,2,2,2,2,1,2,2,2,2,2,2,2,2,2,2,1,1,1
1,2,2,2,2,2,2,2,2,2,2,2,2,1,1,1,1,1,1,1,1,1,1,1,1
1,2,2,2,2,2,2,2,2,2,2,2,2,1,1,1,1,1,1,3,1,1,1,1,1
1,2,1,2,2,2,2,2,2,2,2,2,2,1,1,1,1,1,1,3,1,1,1,1,1
1,2,1,2,2,2,2,2,2,2,2,2,2,1,1,2,1,1,1,3,1,1,1,1,1
1,2,2,2,2,2,2,2,2,2,2,2,2,1,1,1,1,1,1,3,1,1,1,1,1
1,2,2,2,2,2,2,2,2,2,2,2,2,1,1,1,1,1,1,3,1,1,1,1,1
1,2,2,1,2,1,2,2,2,2,2,2,2,1,1,1,1,1,1,3,1,1,1,1,1
1,2,2,2,2,2,2,2,2,2,2,2,2,1,1,1,1,1,1,3,1,1,1,1,1
1,2,2,2,2,2,2,2,2,2,2,2,2,1,1,1,1,1,1,3,1,1,1,1,1
1,2,2,2,2,2,2,2,2,2,2,2,2,1,1,1,1,1,1,3,1,1,1,1,1
1,2,2,2,2,2,2,2,2,2,2,2,2,1,1,1,1,1,1,3,1,1,1,1,1
1,2,2,2,2,2,2,2,2,2,1,2,2,1,1,1,1,1,1,3,1,1,1,1,1
1,2,2,2,2,2,2,2,2,2,2,2,2,1,1,1,1,1,1,3,1,1,1,1,1
1,2,1,2,2,2,2,2,1,2,2,2,2,1,1,1,1,1,1,1,1,1,1,1,1
1,2,2,1,2,2,2,2,2,2,2,2,2,1,1,1,1,1,1,1,1,1,1,1,1
1,2,2,2,2,2,2,2,2,2,2,2,2,1,1,1,1,1,1,1,1,1,1,1,1
1,1,1,1,1,1,2,2,1,1,1,1,1,1,1,1,1,1,1,1,1,1,1,1,1
1,1,1,1,1,1,1,1,1,1,1,1,1,1,1,1,1,1,1,1,1,1,1,1,1
:endlayer
layer: 1
4,0,0,0,0,0,0,0,0,0,0,0,0,4,0,0,0,0,0,0,0,0,0,0,5
0,6,7,7,7,7,7,7,7,7,7,7,6,0,0,0,0,0,0,0,0,0,0,0,0
0,7,8,8,8,8,8,8,8,8,8,8,8,7,7,7,7,7,7,7,7,7,0,0,0
0,7,8,8,8,8,8,8,8,8,8,8,8,8,8,8,8,8,8,8,8,7,0,0,0
0,7,8,8,8,8,8,8,8,8,8,8,8,8,9,9,9,9,9,9,8,7,0,0,0
0,7,8,8,8,8,8,8,8,8,8,8,8,8,9,9,9,9,9,9,8,7,0,0,0
0,6,7,7,7,8,8,8,8,8,8,8,8,8,9,9,9,9,9,9,8,7,0,0,0
0,7,8,8,8,8,8,8,8,8,8,8,8,8,9,9,9,9,9,9,8,7,0,0,0
0,7,8,8,8,8,8,8,8,8,8,8,8,8,9,9,9,9,9,9,8,7,0,0,0
0,7,7,7,7,8,8,8,8,8,8,8,7,8,8,8,8,8,8,8,8,7,0,0,0
0,7,10,11,7,8,8,8,8,8,8,8,6,7,7,7,7,7,7,7,7,7,4,4,0
4,6,10,10,8,8,8,8,8,8,8,8,6,0,0,0,0,0,12,13,14,0,0,4,0
0,7,10,8,8,8,8,8,8,8,8,8,7,0,0,0,0,0,0,0,0,0,0,4,0
0,7,8,8,8,8,8,8,8,8,8,8,7,0,0,0,0,0,0,0,0,0,0,4,0
0,7,8,8,8,8,8,8,8,8,8,8,7,0,0,15,0,0,0,0,0,0,0,16,0
0,7,8,9,9,9,9,9,9,9,9,8,7,0,0,0,0,0,0,0,0,0,0,4,0
0,7,8,9,9,9,9,9,9,9,9,8,7,0,0,0,0,0,0,0,0,0,0,4,0
0,7,8,8,8,8,9,9,8,8,8,8,7,0,0,0,0,0,0,0,0,0,0,4,0
0,7,8,8,8,8,9,9,8,8,8,8,7,0,0,0,0,0,0,0,0,0,0,4,0
0,7,8,8,8,8,9,9,8,8,8,8,7,0,0,0,0,0,0,0,0,0,0,4,0
0,7,8,8,8,8,9,9,8,8,8,8,7,0,0,5,0,0,0,0,0,0,0,4,0
0,7,8,8,8,8,9,9,8,8,8,8,7,0,0,0,0,0,0,0,0,0,0,4,0
0,7,8,8,8,8,9,9,8,8,8,8,7,0,0,0,0,0,0,0,0,0,0,4,0
0,7,8,8,8,8,9,9,8,8,8,8,7,0,0,0,0,0,0,0,0,0,0,4,0
0,7,8,8,8,8,9,9,8,8,8,8,7,4,4,4,4,4,4,17,4,4,4,4,0
0,7,8,8,8,8,9,9,8,8,8,8,7,0,0,0,0,0,0,0,0,0,0,0,0
0,6,7,7,7,6,6,6,6,7,7,7,6,0,0,0,0,0,0,0,0,0,0,0,0
5,0,0,0,0,0,13,13,0,0,0,0,0,0,0,0,0,0,0,0,0,0,0,0,5
0,0,4,0,0,0,0,0,0,0,0,4,0,0,0,0,0,0,0,0,0,0,0,0,0
:endlayer
layer: 2
4,0,0,0,0,0,0,0,0,0,0,0,0,4,0,0,0,0,0,0,0,0,0,0,18
0,6,7,19,19,19,19,19,19,19,19,7,6,20,0,0,0,0,0,0,0,0,0,0,0
0,7,5,0,0,0,0,0,0,0,0,21,6,7,7,7,7,7,7,7,7,7,0,0,0
0,22,0,0,0,0,0,0,0,0,0,21,6,0,0,0,0,0,0,0,0,7,0,0,0
0,22,0,0,0,0,0,0,0,0,0,0,0,0,0,23,23,23,23,0,0,7,0,0,0
0,7,0,0,0,0,0,0,0,0,0,0,0,0,0,5,5,5,5,0,0,7,0,0,0
0,6,24,24,24,0,0,0,0,0,0,0,0,0,0,5,5,5,5,0,0,7,0,0,0
0,7,0,0,6,0,0,0,0,0,0,0,0,0,0,5,5,5,5,0,0,7,0,0,0
0,7,0,0,25,0,0,0,0,0,0,0,6,0,0,26,26,26,26,0,0,7,0,0,0
0,7,7,7,7,0,0,0,0,0,0,0,6,0,0,0,0,0,0,0,0,7,0,0,0
0,7,0,0,25,0,0,0,0,0,0,0,6,7,7,7,7,7,7,27,7,7,0,0,0
4,6,28,29,6,0,0,0,0,0,0,0,6,0,0,0,0,0,0,0,0,30,0,0,0
0,7,31,12,6,6,6,6,6,6,0,0,7,0,32,32,32,0,0,0,0,0,0,0,0
0,7,0,6,6,6,6,6,6,6,0,0,7,32,32,32,32,32,0,0,0,0,0,18,0
0,7,33,6,34,34,35,35,34,34,0,0,7,32,32,15,32,32,0,0,0,0,0,0,0
0,7,0,0,0,0,0,0,0,0,0,0,7,32,32,32,32,32,0,0,0,0,0,18,0
0,7,0,0,0,0,0,0,0,0,0,0,7,0,32,32,32,0,0,0,0,0,0,0,0
0,7,0,0,0,0,0,0,0,0,0,0,7,0,0,0,0,0,0,0,0,0,0,0,0
0,22,0,0,0,0,0,0,0,0,0,0,7,0,0,0,0,0,0,0,0,0,0,0,0
0,7,0,36,36,36,0,0,36,36,36,0,7,0,0,0,0,0,0,0,0,0,0,0,0
0,22,0,0,0,0,0,0,0,0,0,0,7,0,0,5,0,0,0,0,0,0,0,0,0
0,7,0,36,36,36,0,0,36,36,36,0,7,0,0,0,0,0,0,0,0,0,0,0,0
0,22,0,0,0,0,0,0,0,0,0,0,7,0,0,0,0,0,0,0,0,0,0,0,0
0,7,0,36,36,36,0,0,36,36,36,0,7,0,0,0,0,0,0,0,0,0,0,0,0
0,22,0,0,0,0,0,0,0,0,0,0,7,18,0,0,0,0,18,0,18,0,0,18,0
0,7,0,0,0,0,0,0,0,0,0,0,7,0,0,0,0,0,0,0,0,0,0,0,0
0,6,7,22,7,6,37,27,6,7,22,7,6,0,0,0,0,0,0,0,0,0,0,0,0
18,0,0,0,30,0,0,0,0,30,0,0,0,0,0,0,0,0,0,0,0,0,0,0,18
0,0,4,0,0,0,0,0,0,0,0,4,0,0,0,0,0,0,0,0,0,0,0,0,0
:endlayer
layer: 3
4,0,0,0,0,0,0,0,0,0,0,0,0,4,0,0,0,0,0,0,0,0,0,0,0
0,6,7,19,19,38,19,19,38,19,19,7,6,0,0,0,0,0,0,0,0,0,0,0,0
0,7,39,0,0,0,0,0,0,0,0,0,6,7,7,7,7,7,7,7,7,7,0,0,0
0,22,0,0,0,0,0,0,0,0,0,0,6,20,0,0,0,0,0,0,0,7,0,0,0
0,22,0,0,0,0,0,0,0,0,0,0,0,0,0,0,0,0,0,0,0,7,0,0,0
0,7,0,0,0,0,0,0,0,0,0,0,0,0,0,39,39,39,39,0,0,7,0,0,0
0,6,0,0,0,0,0,0,0,0,0,0,0,0,0,39,39,39,39,0,0,7,20,0,0
0,7,24,24,24,0,0,0,0,0,0,0,0,0,0,39,39,39,39,0,0,7,0,0,0
0,7,40,0,41,0,0,0,0,0,0,0,6,0,0,0,0,0,0,0,0,7,0,0,0
0,7,7,7,7,0,0,0,0,0,0,0,6,20,0,0,0,0,0,0,0,7,0,0,0
0,7,0,0,42,0,0,0,0,0,0,0,6,7,7,22,22,22,7,43,7,7,0,0,0
4,6,44,45,6,46,0,0,0,0,0,0,6,0,0,0,0,0,0,0,0,0,0,0,0
0,7,47,0,6,48,48,48,48,48,0,0,7,0,0,0,0,0,0,0,0,0,0,0,0
0,7,0,6,0,0,0,0,0,0,0,0,7,0,0,32,0,0,0,0,0,0,0,0,0
0,7,49,6,0,0,5,5,0,0,0,0,7,0,32,15,32,0,0,0,0,0,0,0,0
0,7,0,50,0,0,0,0,0,0,0,0,7,0,0,32,0,0,0,0,0,0,0,0,0
0,7,0,0,0,0,0,0,0,0,0,0,7,0,0,0,0,0,0,0,0,0,0,0,0
0,7,20,0,0,0,0,0,0,0,0,51,7,0,0,0,0,0,0,0,0,0,0,0,0
0,22,0,0,0,0,0,0,0,0,0,0,7,0,0,0,0,0,0,0,0,0,0,0,0
0,7,20,0,0,0,0,0,0,0,0,51,7,0,0,0,0,0,0,0,0,0,0,0,0
0,22,0,0,0,0,0,0,0,0,0,0,7,0,0,52,0,0,0,0,0,0,0,0,0
0,7,20,0,0,0,0,0,0,0,0,51,7,0,0,0,0,0,0,0,0,0,0,0,0
0,22,0,0,0,0,0,0,0,0,0,0,7,0,0,0,0,0,0,0,0,0,0,0,0
0,7,20,0,0,0,0,0,0,0,0,51,7,0,0,0,0,0,0,0,0,0,0,0,0
0,22,0,0,0,0,0,0,0,0,0,0,7,0,0,0,0,0,0,0,0,0,0,0,0
0,7,0,0,0,0,0,0,0,0,0,0,7,0,0,0,0,0,0,0,0,0,0,0,0
0,6,7,22,7,6,53,54,6,7,22,7,6,0,0,0,0,0,0,0,0,0,0,0,0
0,0,0,0,0,0,0,0,0,0,0,0,0,0,0,0,0,0,0,0,0,0,0,0,0
0,0,4,0,0,0,0,0,0,0,0,4,0,0,0,0,0,0,0,0,0,0,0,0,0
:endlayer
layer: 4
4,0,0,0,0,0,0,0,0,0,0,0,0,4,0,0,0,0,0,0,0,0,0,0,0
0,6,7,19,19,55,55,55,55,19,19,7,6,0,0,0,0,0,0,0,0,0,0,0,0
0,7,20,0,0,0,0,0,0,0,0,0,6,7,7,7,7,7,7,7,7,7,0,0,0
0,22,0,0,0,0,0,0,0,0,0,51,6,0,0,0,0,0,0,0,0,7,0,0,0
0,22,0,0,0,0,0,0,0,0,0,0,0,0,0,0,0,0,0,0,0,7,0,0,0
0,7,0,0,0,0,0,0,0,0,0,0,0,0,0,0,0,0,0,0,0,7,0,0,0
0,6,0,0,0,0,0,0,0,0,0,0,0,0,0,0,0,0,0,0,0,7,0,0,0
0,7,0,0,0,0,0,0,0,0,0,0,0,0,0,0,0,0,0,0,0,7,0,0,0
0,7,24,24,24,0,0,0,0,0,0,51,6,0,0,0,0,0,0,0,0,7,0,0,0
0,7,11,11,11,8,8,8,8,8,8,8,6,0,0,0,0,0,0,0,0,7,0,0,0
0,7,8,8,11,8,8,8,8,8,8,8,6,7,7,22,22,22,7,7,7,7,0,0,0
4,6,8,8,11,8,8,8,8,8,8,8,6,0,0,0,0,0,0,0,0,0,0,0,0
0,7,11,11,18,0,0,0,0,0,8,8,7,0,32,32,32,0,0,0,0,0,0,0,0
0,7,8,11,0,0,0,0,0,0,8,8,7,32,32,32,32,32,0,0,0,0,0,0,0
0,7,11,11,0,0,56,56,0,0,8,8,7,32,32,15,32,32,0,0,0,0,0,0,0
0,7,8,8,0,0,0,0,0,0,8,8,7,32,32,32,32,32,0,0,0,0,0,0,0
0,7,8,8,0,0,0,0,0,0,8,8,7,0,32,32,32,0,0,0,0,0,0,0,0
0,7,8,8,0,0,0,0,0,0,8,8,7,0,0,0,0,0,0,0,0,0,0,0,0
0,7,8,8,0,0,0,0,0,0,8,8,7,0,0,0,0,0,0,0,0,0,0,0,0
0,7,8,8,0,0,0,0,0,0,8,8,7,0,0,0,0,0,0,0,0,0,0,0,0
0,7,8,8,0,0,0,0,0,0,8,8,7,0,0,0,0,0,0,0,0,0,0,0,0
0,7,8,8,0,0,0,0,0,0,8,8,7,0,0,0,0,0,0,0,0,0,0,0,0
0,7,8,8,0,0,0,0,0,0,8,8,7,0,0,0,0,0,0,0,0,0,0,0,0
0,7,8,8,8,8,8,8,8,8,8,8,7,0,0,0,0,0,0,0,0,0,0,0,0
0,7,8,8,8,8,8,8,8,8,8,8,7,0,0,0,0,0,0,0,0,0,0,0,0
0,7,8,8,8,8,57,57,8,8,8,8,7,0,0,0,0,0,0,0,0,0,0,0,0
0,6,7,7,7,6,58,59,6,7,7,7,6,0,0,0,0,0,0,0,0,0,0,0,0
0,8,8,8,8,8,8,8,8,8,8,8,8,0,0,0,0,0,0,0,0,0,0,0,0
0,8,11,8,8,8,8,8,8,8,8,11,8,0,0,0,0,0,0,0,0,0,0,0,0
:endlayer
layer: 5
4,0,0,0,0,0,0,0,0,0,0,0,0,4,0,0,0,0,0,0,0,0,0,0,0
0,6,7,19,19,19,55,55,19,19,19,7,6,0,0,0,0,0,0,0,0,0,0,0,0
0,7,0,0,0,0,0,0,0,0,0,0,6,7,7,7,7,7,7,7,7,7,0,0,0
0,22,0,0,0,0,0,0,0,0,0,0,6,0,0,0,0,0,0,0,0,7,0,0,0
0,22,0,0,0,0,0,0,0,0,0,0,0,0,0,0,0,0,0,0,0,7,0,0,0
0,7,0,0,0,0,0,0,0,0,0,0,0,0,0,0,0,0,0,0,0,7,0,0,0
0,6,0,0,0,0,0,0,0,0,0,0,0,0,0,0,0,0,0,60,61,7,0,0,0
0,7,0,0,0,0,0,0,0,0,0,0,0,0,0,0,0,0,0,0,0,7,0,0,0
0,7,0,0,0,0,0,0,0,0,0,0,6,0,0,0,0,0,0,0,0,7,0,0,0
0,7,0,0,0,48,48,48,48,48,48,48,6,0,0,0,0,0,0,0,0,7,0,0,0
0,7,0,0,0,0,0,0,0,0,0,0,6,7,7,7,7,7,7,7,7,7,0,0,0
4,6,0,48,48,48,48,48,48,48,48,0,6,0,0,0,0,0,0,0,0,0,0,0,0
0,7,0,48,0,0,0,0,0,0,48,0,7,0,0,0,0,0,0,0,0,0,0,0,0
0,7,0,48,0,0,0,0,0,0,48,0,7,0,0,32,0,0,0,0,0,0,0,0,0
0,7,0,48,0,0,0,0,0,0,48,0,7,0,32,15,32,0,0,0,0,0,0,0,0
0,7,0,48,0,0,0,0,0,0,48,0,7,0,0,32,0,0,0,0,0,0,0,0,0
0,7,0,48,0,0,0,0,0,0,48,0,7,0,0,0,0,0,0,0,0,0,0,0,0
0,7,0,48,0,0,0,0,0,0,48,0,22,0,0,0,0,0,0,0,0,0,0,0,0
0,7,0,48,0,0,0,0,0,0,48,0,22,0,0,0,0,0,0,0,0,0,0,0,0
0,7,0,48,0,0,0,0,0,0,48,0,22,0,0,0,0,0,0,0,0,0,0,0,0
0,7,0,48,0,0,0,0,0,0,48,0,22,0,0,0,0,0,0,0,0,0,0,0,0
0,22,0,48,0,62,0,0,62,0,48,0,7,0,0,0,0,0,0,0,0,0,0,0,0
0,22,0,48,0,0,0,0,0,0,48,0,7,0,0,0,0,0,0,0,0,0,0,0,0
0,22,0,48,48,48,48,48,48,48,48,0,7,0,0,0,0,0,0,0,0,0,0,0,0
0,7,0,0,0,0,0,0,0,0,0,0,7,0,0,0,0,0,0,0,0,0,0,0,0
0,7,21,0,0,0,0,0,0,0,0,0,7,0,0,0,0,0,0,0,0,0,0,0,0
0,6,7,7,63,63,19,19,63,63,7,64,6,0,0,0,0,0,0,0,0,0,0,0,0
0,65,0,0,0,0,0,0,0,0,0,0,65,0,0,0,0,0,0,0,0,0,0,0,0
0,65,65,65,65,65,65,65,65,65,65,65,65,0,0,0,0,0,0,0,0,0,0,0,0
:endlayer
layer: 6
4,0,0,0,0,0,0,0,0,0,0,0,0,4,0,0,0,0,0,0,0,0,0,0,0
0,6,7,19,19,19,38,38,19,19,19,7,6,6,24,24,24,24,24,24,24,24,0,0,0
59,7,0,0,0,0,0,0,0,0,0,0,6,7,7,7,7,7,7,7,7,7,0,0,0
66,22,0,0,0,0,0,0,0,0,0,0,6,0,0,0,0,0,0,0,0,7,0,0,0
57,22,0,0,0,0,0,0,0,0,0,0,0,0,0,0,0,0,0,0,0,7,0,0,0
59,7,0,0,0,67,0,0,67,0,0,0,0,0,0,0,0,0,0,0,0,7,0,0,0
0,6,0,0,0,60,0,0,60,0,0,0,0,0,0,0,0,0,0,5,0,7,0,0,0
0,7,0,0,0,0,0,0,0,0,0,0,0,0,0,0,0,0,0,0,0,7,0,0,0
0,7,0,0,0,0,0,0,0,0,0,0,6,0,0,0,0,0,0,0,0,7,0,0,0
0,7,0,0,0,0,0,0,0,0,0,0,6,0,0,0,0,0,0,0,0,7,0,0,0
0,7,0,0,0,0,0,0,0,0,0,0,6,7,7,7,7,7,7,7,7,7,0,0,0
4,6,0,0,0,0,0,0,0,0,0,0,6,23,23,23,23,23,23,23,23,13,0,0,0
0,7,0,0,0,0,0,0,0,0,0,0,7,0,0,0,0,0,0,0,0,0,0,0,0
0,7,0,0,0,0,0,0,0,0,0,0,7,0,0,0,0,0,0,0,0,0,0,0,0
0,7,0,0,0,0,0,0,0,0,0,0,7,0,0,15,0,0,0,0,0,0,0,0,0
0,7,0,0,0,0,0,0,0,0,0,0,7,0,0,0,0,0,0,0,0,0,0,0,0
0,7,0,0,0,0,0,0,0,0,0,0,7,0,0,0,0,0,0,0,0,0,0,0,0
0,7,0,0,0,0,0,0,0,0,0,0,22,0,0,0,0,0,0,0,0,0,0,0,0
0,7,0,0,0,0,0,0,0,0,0,0,22,0,0,0,0,0,0,0,0,0,0,0,0
0,7,0,0,0,0,0,0,0,0,0,0,22,0,0,0,0,0,0,0,0,0,0,0,0
0,7,0,0,0,0,0,0,0,0,0,0,22,0,0,0,0,0,0,0,0,0,0,0,0
0,22,0,0,0,60,0,0,60,0,0,0,7,0,0,0,0,0,0,0,0,0,0,0,0
0,22,0,0,0,0,0,0,0,0,0,0,7,0,0,0,0,0,0,0,0,0,0,0,0
0,22,0,0,0,0,0,0,0,0,0,0,7,0,0,0,0,0,0,0,0,0,0,0,0
0,7,0,0,0,0,0,0,0,0,0,0,7,0,0,0,0,0,0,0,0,0,0,0,0
0,7,0,0,0,0,0,0,0,0,68,0,7,0,0,0,0,0,0,0,0,0,0,0,0
0,6,7,7,63,63,19,19,63,63,7,69,6,0,0,0,0,0,0,0,0,0,0,0,0
0,0,0,0,0,0,0,0,0,0,0,0,0,0,0,0,0,0,0,0,0,0,0,0,0
0,0,0,0,0,0,0,0,0,0,0,0,0,0,0,0,0,0,0,0,0,0,0,0,0
:endlayer
layer: 7
12,0,0,0,0,0,0,0,0,0,0,0,0,14,0,0,0,0,0,0,0,0,0,0,0
12,6,7,19,38,55,19,19,55,38,19,7,6,14,0,0,0,0,0,0,0,0,0,0,0
12,7,0,0,0,0,0,0,0,0,0,0,6,70,26,26,26,26,26,26,26,24,0,0,0
12,7,0,0,0,0,0,0,0,0,0,0,6,0,0,0,0,0,0,0,0,6,0,0,0
12,7,0,0,0,0,0,0,0,0,0,0,6,0,0,0,0,0,0,0,0,7,0,0,0
12,7,0,0,0,0,0,0,0,0,0,0,6,0,0,0,0,0,0,0,0,7,0,0,0
12,6,0,0,0,5,0,0,5,0,0,0,6,0,0,0,0,0,0,5,5,7,0,0,0
12,7,0,0,0,0,0,0,0,0,0,0,6,0,0,0,0,0,0,0,0,7,0,0,0
12,7,0,0,0,0,0,0,0,0,0,0,6,0,0,0,0,0,0,0,0,7,0,0,0
12,7,0,0,0,0,0,0,0,0,0,0,6,0,0,0,0,0,0,0,0,6,0,0,0
12,7,0,0,0,0,0,0,0,0,0,0,6,23,23,23,23,23,23,23,23,13,0,0,0
12,6,0,0,0,0,0,0,0,0,0,0,6,0,0,0,0,0,0,0,0,0,0,0,0
0,7,0,0,0,0,0,0,0,0,0,0,7,0,0,0,0,0,0,0,0,0,0,0,0
0,7,0,0,0,0,0,0,0,0,0,0,7,0,0,32,0,0,0,0,0,0,0,0,0
0,7,0,0,0,0,0,0,0,0,0,0,7,0,32,32,32,0,0,0,0,0,0,0,0
0,7,0,0,0,0,0,0,0,0,0,0,7,0,0,32,0,0,0,0,0,0,0,0,0
0,7,0,0,0,0,0,0,0,0,0,0,7,0,0,0,0,0,0,0,0,0,0,0,0
0,7,0,0,0,0,0,0,0,0,0,0,22,0,0,0,0,0,0,0,0,0,0,0,0
0,7,0,0,0,0,0,0,0,0,0,0,22,0,0,0,0,0,0,0,0,0,0,0,0
0,7,0,0,0,0,0,0,0,0,0,0,22,0,0,0,0,0,0,0,0,0,0,0,0
0,7,0,0,0,0,0,0,0,0,0,0,22,0,0,0,0,0,0,0,0,0,0,0,0
0,7,0,0,0,5,0,0,5,0,0,0,7,0,0,0,0,0,0,0,0,0,0,0,0
0,7,0,0,0,0,0,0,0,0,0,0,7,0,0,0,0,0,0,0,0,0,0,0,0
0,7,0,0,0,0,0,0,0,0,0,0,7,0,0,0,0,0,0,0,0,0,0,0,0
0,7,0,0,0,0,0,0,0,0,0,0,7,0,0,0,0,0,0,0,0,0,0,0,0
0,7,0,0,0,0,0,0,0,0,0,0,7,0,0,0,0,0,0,0,0,0,0,0,0
0,6,7,7,63,63,19,19,63,63,7,7,6,0,0,0,0,0,0,0,0,0,0,0,0
0,0,0,0,0,0,0,0,0,0,0,0,0,0,0,0,0,0,0,0,0,0,0,0,0
0,0,0,0,0,0,0,0,0,0,0,0,0,0,0,0,0,0,0,0,0,0,0,0,0
:endlayer
layer: 8
0,12,0,0,0,0,0,0,0,0,0,0,14,0,0,0,0,0,0,0,0,0,0,0,0
0,12,7,19,38,38,19,19,38,38,19,7,14,0,0,0,0,0,0,0,0,0,0,0,0
0,71,0,0,0,0,0,0,0,0,0,0,70,0,0,0,0,0,0,0,0,0,0,0,0
0,71,0,0,0,0,0,0,0,0,0,0,70,26,26,26,26,26,26,26,26,24,0,0,0
0,71,0,0,0,0,0,0,0,0,0,0,6,0,0,0,0,0,0,0,0,6,0,0,0
0,71,0,0,0,0,0,0,0,0,0,0,6,0,0,0,0,0,0,0,0,7,0,0,0
0,71,0,0,0,5,0,0,5,0,0,0,6,0,0,0,0,0,0,0,0,7,0,0,0
0,71,0,0,0,0,0,0,0,0,0,0,6,0,0,0,0,0,0,0,0,7,0,0,0
0,71,0,0,0,0,0,0,0,0,0,0,6,0,0,0,0,0,0,0,0,6,0,0,0
0,71,0,0,0,0,0,0,0,0,0,0,70,23,23,23,23,23,23,23,23,13,0,0,0
0,71,0,0,0,0,0,0,0,0,0,0,70,0,0,0,0,0,0,0,0,0,0,0,0
0,71,0,0,0,0,0,0,0,0,0,0,70,0,0,0,0,0,0,0,0,0,0,0,0
0,71,0,0,0,0,0,0,0,0,0,0,70,0,0,0,0,0,0,0,0,0,0,0,0
0,71,0,0,0,0,0,0,0,0,0,0,70,0,0,0,0,0,0,0,0,0,0,0,0
0,71,0,0,0,0,0,0,0,0,0,0,70,0,0,0,0,0,0,0,0,0,0,0,0
0,71,0,0,0,0,0,0,0,0,0,0,70,0,0,0,0,0,0,0,0,0,0,0,0
0,71,0,0,0,0,0,0,0,0,0,0,70,0,0,0,0,0,0,0,0,0,0,0,0
0,71,0,0,0,0,0,0,0,0,0,0,70,0,0,0,0,0,0,0,0,0,0,0,0
0,71,0,0,0,0,0,0,0,0,0,0,70,0,0,0,0,0,0,0,0,0,0,0,0
0,71,0,0,0,0,0,0,0,0,0,0,70,0,0,0,0,0,0,0,0,0,0,0,0
0,71,0,0,0,0,0,0,0,0,0,0,70,0,0,0,0,0,0,0,0,0,0,0,0
0,71,0,0,0,5,0,0,5,0,0,0,70,0,0,0,0,0,0,0,0,0,0,0,0
0,71,0,0,0,0,0,0,0,0,0,0,70,0,0,0,0,0,0,0,0,0,0,0,0
0,71,0,0,0,0,0,0,0,0,0,0,70,0,0,0,0,0,0,0,0,0,0,0,0
0,71,0,0,0,0,0,0,0,0,0,0,70,0,0,0,0,0,0,0,0,0,0,0,0
0,71,0,0,0,0,0,0,0,0,0,0,70,0,0,0,0,0,0,0,0,0,0,0,0
0,12,6,7,63,19,19,19,19,63,7,6,14,0,0,0,0,0,0,0,0,0,0,0,0
0,12,0,0,0,0,0,0,0,0,0,0,14,0,0,0,0,0,0,0,0,0,0,0,0
0,0,0,0,0,0,0,0,0,0,0,0,0,0,0,0,0,0,0,0,0,0,0,0,0
:endlayer
layer: 9
0,0,12,0,0,0,0,0,0,0,0,14,0,0,0,0,0,0,0,0,0,0,0,0,0
0,0,12,7,19,19,19,19,19,19,7,14,0,0,0,0,0,0,0,0,0,0,0,0,0
0,0,71,0,0,0,0,0,0,0,0,70,0,0,0,0,0,0,0,0,0,0,0,0,0
0,0,71,0,0,0,0,0,0,0,0,70,0,0,0,0,0,0,0,0,0,0,0,0,0
0,0,71,0,0,0,0,0,0,0,0,70,26,26,26,26,26,26,26,26,26,24,0,0,0
0,0,71,0,0,0,0,0,0,0,0,0,6,0,0,0,0,0,0,0,0,6,0,0,0
0,0,71,0,0,5,0,0,5,0,0,0,6,0,0,0,0,0,0,0,0,7,0,0,0
0,0,71,0,0,0,0,0,0,0,0,0,6,0,0,0,0,0,0,0,0,6,0,0,0
0,0,71,0,0,0,0,0,0,0,0,23,23,23,23,23,23,23,23,23,23,13,0,0,0
0,0,71,0,0,0,0,0,0,0,0,70,0,0,0,0,0,0,0,0,0,0,0,0,0
0,0,71,0,0,0,0,0,0,0,0,70,0,0,0,0,0,0,0,0,0,0,0,0,0
0,0,71,0,0,0,0,0,0,0,0,70,0,0,0,0,0,0,0,0,0,0,0,0,0
0,0,71,0,0,0,0,0,0,0,0,70,0,0,0,0,0,0,0,0,0,0,0,0,0
0,0,71,0,0,0,0,0,0,0,0,70,0,0,0,0,0,0,0,0,0,0,0,0,0
0,0,71,0,0,0,0,0,0,0,0,70,0,0,0,0,0,0,0,0,0,0,0,0,0
0,0,71,0,0,0,0,0,0,0,0,70,0,0,0,0,0,0,0,0,0,0,0,0,0
0,0,71,0,0,0,0,0,0,0,0,70,0,0,0,0,0,0,0,0,0,0,0,0,0
0,0,71,0,72,60,0,0,60,61,0,70,0,0,0,0,0,0,0,0,0,0,0,0,0
0,0,71,0,0,0,0,0,0,0,0,70,0,0,0,0,0,0,0,0,0,0,0,0,0
0,0,71,0,0,0,0,0,0,0,0,70,0,0,0,0,0,0,0,0,0,0,0,0,0
0,0,71,0,0,0,0,0,0,0,0,70,0,0,0,0,0,0,0,0,0,0,0,0,0
0,0,71,0,0,5,0,0,5,0,0,70,0,0,0,0,0,0,0,0,0,0,0,0,0
0,0,71,0,0,0,0,0,0,0,0,70,0,0,0,0,0,0,0,0,0,0,0,0,0
0,0,71,0,0,0,0,0,0,0,0,70,0,0,0,0,0,0,0,0,0,0,0,0,0
0,0,71,0,0,0,0,0,0,0,0,70,0,0,0,0,0,0,0,0,0,0,0,0,0
0,0,71,0,0,0,0,0,0,0,0,70,0,0,0,0,0,0,0,0,0,0,0,0,0
0,0,12,7,63,63,19,19,63,63,7,14,0,0,0,0,0,0,0,0,0,0,0,0,0
0,0,12,0,0,0,0,0,0,0,0,14,0,0,0,0,0,0,0,0,0,0,0,0,0
0,0,0,0,0,0,0,0,0,0,0,0,0,0,0,0,0,0,0,0,0,0,0,0,0
:endlayer
layer: 10
0,0,0,12,0,0,0,0,0,0,14,0,0,0,0,0,0,0,0,0,0,0,0,0,0
0,0,0,12,7,19,19,19,19,7,14,0,0,0,0,0,0,0,0,0,0,0,0,0,0
0,0,0,71,0,0,0,0,0,0,70,0,0,0,0,0,0,0,0,0,0,0,0,0,0
0,0,0,71,0,0,0,0,0,0,70,0,0,0,0,0,0,0,0,0,0,0,0,0,0
0,0,0,71,0,0,0,0,0,0,70,0,0,0,0,0,0,0,0,0,0,0,0,0,0
0,0,0,71,0,0,0,0,0,0,26,26,26,26,26,26,26,26,26,26,26,24,0,0,0
0,0,0,71,0,5,0,0,5,0,6,6,6,6,6,6,6,6,6,6,6,6,0,0,0
0,0,0,71,0,0,0,0,0,0,70,23,23,23,23,23,23,23,23,23,23,13,0,0,0
0,0,0,71,0,0,0,0,0,0,70,0,0,0,0,0,0,0,0,0,0,0,0,0,0
0,0,0,71,0,0,0,0,0,0,70,0,0,0,0,0,0,0,0,0,0,0,0,0,0
0,0,0,71,0,0,0,0,0,0,70,0,0,0,0,0,0,0,0,0,0,0,0,0,0
0,0,0,71,0,0,0,0,0,0,70,0,0,0,0,0,0,0,0,0,0,0,0,0,0
0,0,0,71,0,0,0,0,0,0,70,0,0,0,0,0,0,0,0,0,0,0,0,0,0
0,0,0,71,0,0,0,0,0,0,70,0,0,0,0,0,0,0,0,0,0,0,0,0,0
0,0,0,71,0,0,0,0,0,0,70,0,0,0,0,0,0,0,0,0,0,0,0,0,0
0,0,0,71,0,0,0,0,0,0,70,0,0,0,0,0,0,0,0,0,0,0,0,0,0
0,0,0,71,0,0,0,0,0,0,70,0,0,0,0,0,0,0,0,0,0,0,0,0,0
0,0,0,71,0,5,0,0,5,0,70,0,0,0,0,0,0,0,0,0,0,0,0,0,0
0,0,0,71,0,0,0,0,0,0,70,0,0,0,0,0,0,0,0,0,0,0,0,0,0
0,0,0,71,0,0,0,0,0,0,70,0,0,0,0,0,0,0,0,0,0,0,0,0,0
0,0,0,71,0,0,0,0,0,0,70,0,0,0,0,0,0,0,0,0,0,0,0,0,0
0,0,0,71,0,5,0,0,5,0,70,0,0,0,0,0,0,0,0,0,0,0,0,0,0
0,0,0,71,0,0,0,0,0,0,70,0,0,0,0,0,0,0,0,0,0,0,0,0,0
0,0,0,71,0,0,0,0,0,0,70,0,0,0,0,0,0,0,0,0,0,0,0,0,0
0,0,0,71,0,0,0,0,0,0,70,0,0,0,0,0,0,0,0,0,0,0,0,0,0
0,0,0,71,0,0,0,0,0,0,70,0,0,0,0,0,0,0,0,0,0,0,0,0,0
0,0,0,12,7,63,19,19,63,7,14,0,0,0,0,0,0,0,0,0,0,0,0,0,0
0,0,0,12,0,0,0,0,0,0,14,0,0,0,0,0,0,0,0,0,0,0,0,0,0
0,0,0,0,0,0,0,0,0,0,0,0,0,0,0,0,0,0,0,0,0,0,0,0,0
:endlayer
layer: 11
0,0,0,0,12,0,0,0,0,14,0,0,0,0,0,0,0,0,0,0,0,0,0,0,0
0,0,0,0,12,7,7,7,7,14,0,0,0,0,0,0,0,0,0,0,0,0,0,0,0
0,0,0,0,71,0,0,0,0,70,0,0,0,0,0,0,0,0,0,0,0,0,0,0,0
0,0,0,0,71,0,0,0,0,70,0,0,0,0,0,0,0,0,0,0,0,0,0,0,0
0,0,0,0,71,0,0,0,0,70,0,0,0,0,0,0,0,0,0,0,0,0,0,0,0
0,0,0,0,71,0,0,0,0,70,0,0,0,0,0,0,0,0,0,0,0,0,0,0,0
0,0,0,0,71,5,0,0,5,70,73,73,73,73,73,73,73,73,73,73,73,6,0,0,0
0,0,0,0,71,0,0,0,0,70,0,0,0,0,0,0,0,0,0,0,0,0,0,0,0
0,0,0,0,71,0,0,0,0,70,0,0,0,0,0,0,0,0,0,0,0,0,0,0,0
0,0,0,0,71,0,0,0,0,70,0,0,0,0,0,0,0,0,0,0,0,0,0,0,0
0,0,0,0,71,0,0,0,0,70,0,0,0,0,0,0,0,0,0,0,0,0,0,0,0
0,0,0,0,71,0,0,0,0,70,0,0,0,0,0,0,0,0,0,0,0,0,0,0,0
0,0,0,0,71,0,0,0,0,70,0,0,0,0,0,0,0,0,0,0,0,0,0,0,0
0,0,0,0,71,0,0,0,0,70,0,0,0,0,0,0,0,0,0,0,0,0,0,0,0
0,0,0,0,71,0,0,0,0,70,0,0,0,0,0,0,0,0,0,0,0,0,0,0,0
0,0,0,0,71,0,0,0,0,70,0,0,0,0,0,0,0,0,0,0,0,0,0,0,0
0,0,0,0,71,0,0,0,0,70,0,0,0,0,0,0,0,0,0,0,0,0,0,0,0
0,0,0,0,71,5,0,0,5,70,0,0,0,0,0,0,0,0,0,0,0,0,0,0,0
0,0,0,0,71,0,0,0,0,70,0,0,0,0,0,0,0,0,0,0,0,0,0,0,0
0,0,0,0,71,0,0,0,0,70,0,0,0,0,0,0,0,0,0,0,0,0,0,0,0
0,0,0,0,71,0,0,0,0,70,0,0,0,0,0,0,0,0,0,0,0,0,0,0,0
0,0,0,0,71,5,0,0,5,70,0,0,0,0,0,0,0,0,0,0,0,0,0,0,0
0,0,0,0,71,0,0,0,0,70,0,0,0,0,0,0,0,0,0,0,0,0,0,0,0
0,0,0,0,71,0,0,0,0,70,0,0,0,0,0,0,0,0,0,0,0,0,0,0,0
0,0,0,0,71,0,0,0,0,70,0,0,0,0,0,0,0,0,0,0,0,0,0,0,0
0,0,0,0,71,0,0,0,0,70,0,0,0,0,0,0,0,0,0,0,0,0,0,0,0
0,0,0,0,12,7,63,63,7,14,0,0,0,0,0,0,0,0,0,0,0,0,0,0,0
0,0,0,0,12,0,0,0,0,14,0,0,0,0,0,0,0,0,0,0,0,0,0,0,0
0,0,0,0,0,0,0,0,0,0,0,0,0,0,0,0,0,0,0,0,0,0,0,0,0
:endlayer
layer: 12
0,0,0,0,0,12,0,0,14,0,0,0,0,0,0,0,0,0,0,0,0,0,0,0,0
0,0,0,0,0,12,7,7,14,0,0,0,0,0,0,0,0,0,0,0,0,0,0,0,0
0,0,0,0,0,71,58,59,70,0,0,0,0,0,0,0,0,0,0,0,0,0,0,0,0
0,0,0,0,0,71,58,59,70,0,0,0,0,0,0,0,0,0,0,0,0,0,0,0,0
0,0,0,0,0,71,58,59,70,0,0,0,0,0,0,0,0,0,0,0,0,0,0,0,0
0,0,0,0,0,71,58,59,70,0,0,0,0,0,0,0,0,0,0,0,0,0,0,0,0
0,0,0,0,0,71,58,59,70,0,0,0,0,0,0,0,0,0,0,0,0,0,0,0,0
0,0,0,0,0,71,58,59,70,0,0,0,0,0,0,0,0,0,0,0,0,0,0,0,0
0,0,0,0,0,71,58,59,70,0,0,0,0,0,0,0,0,0,0,0,0,0,0,0,0
0,0,0,0,0,71,58,59,70,0,0,0,0,0,0,0,0,0,0,0,0,0,0,0,0
0,0,0,0,0,71,58,59,70,0,0,0,0,0,0,0,0,0,0,0,0,0,0,0,0
0,0,0,0,0,71,58,59,70,0,0,0,0,0,0,0,0,0,0,0,0,0,0,0,0
0,0,0,0,0,71,58,59,70,0,0,0,0,0,0,0,0,0,0,0,0,0,0,0,0
0,0,0,0,0,71,58,59,70,0,0,0,0,0,0,0,0,0,0,0,0,0,0,0,0
0,0,0,0,0,71,58,59,70,0,0,0,0,0,0,0,0,0,0,0,0,0,0,0,0
0,0,0,0,0,71,58,59,70,0,0,0,0,0,0,0,0,0,0,0,0,0,0,0,0
0,0,0,0,0,71,58,59,70,0,0,0,0,0,0,0,0,0,0,0,0,0,0,0,0
0,0,0,0,0,71,58,59,70,0,0,0,0,0,0,0,0,0,0,0,0,0,0,0,0
0,0,0,0,0,71,58,59,70,0,0,0,0,0,0,0,0,0,0,0,0,0,0,0,0
0,0,0,0,0,71,58,59,70,0,0,0,0,0,0,0,0,0,0,0,0,0,0,0,0
0,0,0,0,0,71,58,59,70,0,0,0,0,0,0,0,0,0,0,0,0,0,0,0,0
0,0,0,0,0,71,58,59,70,0,0,0,0,0,0,0,0,0,0,0,0,0,0,0,0
0,0,0,0,0,71,58,59,70,0,0,0,0,0,0,0,0,0,0,0,0,0,0,0,0
0,0,0,0,0,71,58,59,70,0,0,0,0,0,0,0,0,0,0,0,0,0,0,0,0
0,0,0,0,0,71,58,59,70,0,0,0,0,0,0,0,0,0,0,0,0,0,0,0,0
0,0,0,0,0,71,58,59,70,0,0,0,0,0,0,0,0,0,0,0,0,0,0,0,0
0,0,0,0,0,12,6,6,14,0,0,0,0,0,0,0,0,0,0,0,0,0,0,0,0
0,0,0,0,0,12,0,0,14,0,0,0,0,0,0,0,0,0,0,0,0,0,0,0,0
0,0,0,0,0,0,0,0,0,0,0,0,0,0,0,0,0,0,0,0,0,0,0,0,0
:endlayer
layer: 13
0,0,0,0,0,0,12,14,0,0,0,0,0,0,0,0,0,0,0,0,0,0,0,0,0
0,0,0,0,0,0,12,14,0,0,0,0,0,0,0,0,0,0,0,0,0,0,0,0,0
0,0,0,0,0,0,12,14,0,0,0,0,0,0,0,0,0,0,0,0,0,0,0,0,0
0,0,0,0,0,0,12,14,0,0,0,0,0,0,0,0,0,0,0,0,0,0,0,0,0
0,0,0,0,0,0,12,14,0,0,0,0,0,0,0,0,0,0,0,0,0,0,0,0,0
0,0,0,0,0,0,12,14,0,0,0,0,0,0,0,0,0,0,0,0,0,0,0,0,0
0,0,0,0,0,0,12,14,0,0,0,0,0,0,0,0,0,0,0,0,0,0,0,0,0
0,0,0,0,0,0,12,14,0,0,0,0,0,0,0,0,0,0,0,0,0,0,0,0,0
0,0,0,0,0,0,12,14,0,0,0,0,0,0,0,0,0,0,0,0,0,0,0,0,0
0,0,0,0,0,0,12,14,0,0,0,0,0,0,0,0,0,0,0,0,0,0,0,0,0
0,0,0,0,0,0,12,14,0,0,0,0,0,0,0,0,0,0,0,0,0,0,0,0,0
0,0,0,0,0,0,12,14,0,0,0,0,0,0,0,0,0,0,0,0,0,0,0,0,0
0,0,0,0,0,0,12,14,0,0,0,0,0,0,0,0,0,0,0,0,0,0,0,0,0
0,0,0,0,0,0,12,14,0,0,0,0,0,0,0,0,0,0,0,0,0,0,0,0,0
0,0,0,0,0,0,12,14,0,0,0,0,0,0,0,0,0,0,0,0,0,0,0,0,0
0,0,0,0,0,0,12,14,0,0,0,0,0,0,0,0,0,0,0,0,0,0,0,0,0
0,0,0,0,0,0,12,14,0,0,0,0,0,0,0,0,0,0,0,0,0,0,0,0,0
0,0,0,0,0,0,12,14,0,0,0,0,0,0,0,0,0,0,0,0,0,0,0,0,0
0,0,0,0,0,0,12,14,0,0,0,0,0,0,0,0,0,0,0,0,0,0,0,0,0
0,0,0,0,0,0,12,14,0,0,0,0,0,0,0,0,0,0,0,0,0,0,0,0,0
0,0,0,0,0,0,12,14,0,0,0,0,0,0,0,0,0,0,0,0,0,0,0,0,0
0,0,0,0,0,0,12,14,0,0,0,0,0,0,0,0,0,0,0,0,0,0,0,0,0
0,0,0,0,0,0,12,14,0,0,0,0,0,0,0,0,0,0,0,0,0,0,0,0,0
0,0,0,0,0,0,12,14,0,0,0,0,0,0,0,0,0,0,0,0,0,0,0,0,0
0,0,0,0,0,0,12,14,0,0,0,0,0,0,0,0,0,0,0,0,0,0,0,0,0
0,0,0,0,0,0,12,14,0,0,0,0,0,0,0,0,0,0,0,0,0,0,0,0,0
0,0,0,0,0,0,12,14,0,0,0,0,0,0,0,0,0,0,0,0,0,0,0,0,0
0,0,0,0,0,0,13,13,0,0,0,0,0,0,0,0,0,0,0,0,0,0,0,0,0
0,0,0,0,0,0,0,0,0,0,0,0,0,0,0,0,0,0,0,0,0,0,0,0,0
:endlayer
layer: 14
0,0,0,0,0,0,0,0,0,0,0,0,0,0,0,0,0,0,0,0,0,0,0,0,0
0,0,0,0,0,0,0,0,0,0,0,0,0,0,0,0,0,0,0,0,0,0,0,0,0
0,0,0,0,0,0,0,0,0,0,0,0,0,0,0,0,0,0,0,0,0,0,0,0,0
0,0,0,0,0,0,0,0,0,0,0,0,0,0,0,0,0,0,0,0,0,0,0,0,0
0,0,0,0,0,0,0,0,0,0,0,0,0,0,0,0,0,0,0,0,0,0,0,0,0
0,0,0,0,0,0,0,0,0,0,0,0,0,0,0,0,0,0,0,0,0,0,0,0,0
0,0,0,0,0,0,0,0,0,0,0,0,0,0,0,0,0,0,0,0,0,0,0,0,0
0,0,0,0,0,0,0,0,0,0,0,0,0,0,0,0,0,0,0,0,0,0,0,0,0
0,0,0,0,0,0,0,0,0,0,0,0,0,0,0,0,0,0,0,0,0,0,0,0,0
0,0,0,0,0,0,0,0,0,0,0,0,0,0,0,0,0,0,0,0,0,0,0,0,0
0,0,0,0,0,0,0,0,0,0,0,0,0,0,0,0,0,0,0,0,0,0,0,0,0
0,0,0,0,0,0,0,0,0,0,0,0,0,0,0,0,0,0,0,0,0,0,0,0,0
0,0,0,0,0,0,0,0,0,0,0,0,0,0,0,0,0,0,0,0,0,0,0,0,0
0,0,0,0,0,0,0,0,0,0,0,0,0,0,0,0,0,0,0,0,0,0,0,0,0
0,0,0,0,0,0,0,0,0,0,0,0,0,0,0,0,0,0,0,0,0,0,0,0,0
0,0,0,0,0,0,0,0,0,0,0,0,0,0,0,0,0,0,0,0,0,0,0,0,0
0,0,0,0,0,0,0,0,0,0,0,0,0,0,0,0,0,0,0,0,0,0,0,0,0
0,0,0,0,0,0,0,0,0,0,0,0,0,0,0,0,0,0,0,0,0,0,0,0,0
0,0,0,0,0,0,0,0,0,0,0,0,0,0,0,0,0,0,0,0,0,0,0,0,0
0,0,0,0,0,0,0,0,0,0,0,0,0,0,0,0,0,0,0,0,0,0,0,0,0
0,0,0,0,0,0,0,0,0,0,0,0,0,0,0,0,0,0,0,0,0,0,0,0,0
0,0,0,0,0,0,0,0,0,0,0,0,0,0,0,0,0,0,0,0,0,0,0,0,0
0,0,0,0,0,0,0,0,0,0,0,0,0,0,0,0,0,0,0,0,0,0,0,0,0
0,0,0,0,0,0,0,0,0,0,0,0,0,0,0,0,0,0,0,0,0,0,0,0,0
0,0,0,0,0,0,0,0,0,0,0,0,0,0,0,0,0,0,0,0,0,0,0,0,0
0,0,0,0,0,0,0,0,0,0,0,0,0,0,0,0,0,0,0,0,0,0,0,0,0
0,0,0,0,0,0,0,0,0,0,0,0,0,0,0,0,0,0,0,0,0,0,0,0,0
0,0,0,0,0,0,0,0,0,0,0,0,0,0,0,0,0,0,0,0,0,0,0,0,0
0,0,0,0,0,0,0,0,0,0,0,0,0,0,0,0,0,0,0,0,0,0,0,0,0
:endlayer
layer: 15
0,0,0,0,0,0,0,0,0,0,0,0,0,0,0,0,0,0,0,0,0,0,0,0,0
0,0,0,0,0,0,0,0,0,0,0,0,0,0,0,0,0,0,0,0,0,0,0,0,0
0,0,0,0,0,0,0,0,0,0,0,0,0,0,0,0,0,0,0,0,0,0,0,0,0
0,0,0,0,0,0,0,0,0,0,0,0,0,0,0,0,0,0,0,0,0,0,0,0,0
0,0,0,0,0,0,0,0,0,0,0,0,0,0,0,0,0,0,0,0,0,0,0,0,0
0,0,0,0,0,0,0,0,0,0,0,0,0,0,0,0,0,0,0,0,0,0,0,0,0
0,0,0,0,0,0,0,0,0,0,0,0,0,0,0,0,0,0,0,0,0,0,0,0,0
0,0,0,0,0,0,0,0,0,0,0,0,0,0,0,0,0,0,0,0,0,0,0,0,0
0,0,0,0,0,0,0,0,0,0,0,0,0,0,0,0,0,0,0,0,0,0,0,0,0
0,0,0,0,0,0,0,0,0,0,0,0,0,0,0,0,0,0,0,0,0,0,0,0,0
0,0,0,0,0,0,0,0,0,0,0,0,0,0,0,0,0,0,0,0,0,0,0,0,0
0,0,0,0,0,0,0,0,0,0,0,0,0,0,0,0,0,0,0,0,0,0,0,0,0
0,0,0,0,0,0,0,0,0,0,0,0,0,0,0,0,0,0,0,0,0,0,0,0,0
0,0,0,0,0,0,0,0,0,0,0,0,0,0,0,0,0,0,0,0,0,0,0,0,0
0,0,0,0,0,0,0,0,0,0,0,0,0,0,0,0,0,0,0,0,0,0,0,0,0
0,0,0,0,0,0,0,0,0,0,0,0,0,0,0,0,0,0,0,0,0,0,0,0,0
0,0,0,0,0,0,0,0,0,0,0,0,0,0,0,0,0,0,0,0,0,0,0,0,0
0,0,0,0,0,0,0,0,0,0,0,0,0,0,0,0,0,0,0,0,0,0,0,0,0
0,0,0,0,0,0,0,0,0,0,0,0,0,0,0,0,0,0,0,0,0,0,0,0,0
0,0,0,0,0,0,0,0,0,0,0,0,0,0,0,0,0,0,0,0,0,0,0,0,0
0,0,0,0,0,0,0,0,0,0,0,0,0,0,0,0,0,0,0,0,0,0,0,0,0
0,0,0,0,0,0,0,0,0,0,0,0,0,0,0,0,0,0,0,0,0,0,0,0,0
0,0,0,0,0,0,0,0,0,0,0,0,0,0,0,0,0,0,0,0,0,0,0,0,0
0,0,0,0,0,0,0,0,0,0,0,0,0,0,0,0,0,0,0,0,0,0,0,0,0
0,0,0,0,0,0,0,0,0,0,0,0,0,0,0,0,0,0,0,0,0,0,0,0,0
0,0,0,0,0,0,0,0,0,0,0,0,0,0,0,0,0,0,0,0,0,0,0,0,0
0,0,0,0,0,0,0,0,0,0,0,0,0,0,0,0,0,0,0,0,0,0,0,0,0
0,0,0,0,0,0,0,0,0,0,0,0,0,0,0,0,0,0,0,0,0,0,0,0,0
0,0,0,0,0,0,0,0,0,0,0,0,0,0,0,0,0,0,0,0,0,0,0,0,0
:endlayer

#### RULES ####
rule:
plugin=vanillaBlocks
number=1
data:
JSON:{blockState:{blockName:"minecraft:grass",properties:{snowy:"false"}},buildPass:0}
:enddata
:endrule

rule:
plugin=vanillaBlocks
number=2
data:
JSON:{blockState:{blockName:"minecraft:dirt",properties:{variant:"dirt",snowy:"false"}},buildPass:0}
:enddata
:endrule

rule:
plugin=vanillaBlocks
number=3
data:
JSON:{blockState:{blockName:"minecraft:gravel",properties:{}},buildPass:0}
:enddata
:endrule

rule:
plugin=vanillaBlocks
number=4
data:
JSON:{blockState:{blockName:"minecraft:cobblestone_wall",properties:{east:"false",south:"false",north:"false",variant:"cobblestone",west:"false",up:"false"}},buildPass:0}
:enddata
:endrule

rule:
plugin=vanillaBlocks
number=5
data:
JSON:{blockState:{blockName:"minecraft:fence",properties:{east:"false",south:"false",north:"false",west:"false"}},buildPass:0}
:enddata
:endrule

rule:
plugin=vanillaBlocks
number=6
data:
JSON:{blockState:{blockName:"minecraft:stonebrick",properties:{variant:"stonebrick"}},buildPass:0}
:enddata
:endrule

rule:
plugin=vanillaBlocks
number=7
data:
JSON:{blockState:{blockName:"minecraft:stonebrick",properties:{variant:"cracked_stonebrick"}},buildPass:0}
:enddata
:endrule

rule:
plugin=vanillaBlocks
number=8
data:
JSON:{blockState:{blockName:"minecraft:stone_slab",properties:{half:"top",variant:"stone"}},buildPass:0}
:enddata
:endrule

rule:
plugin=vanillaBlocks
number=9
data:
JSON:{blockState:{blockName:"minecraft:wool",properties:{color:"green"}},buildPass:0}
:enddata
:endrule

rule:
plugin=vanillaBlocks
number=10
data:
JSON:{blockState:{blockName:"minecraft:soul_sand",properties:{}},buildPass:0}
:enddata
:endrule

rule:
plugin=vanillaBlocks
number=11
data:
JSON:{blockState:{blockName:"minecraft:double_stone_slab",properties:{seamless:"false",variant:"stone"}},buildPass:0}
:enddata
:endrule

rule:
plugin=vanillaBlocks
number=12
data:
JSON:{blockState:{blockName:"minecraft:stone_brick_stairs",properties:{half:"bottom",shape:"straight",facing:"east"}},buildPass:0}
:enddata
:endrule

rule:
plugin=vanillaBlocks
number=13
data:
JSON:{blockState:{blockName:"minecraft:stone_brick_stairs",properties:{half:"bottom",shape:"straight",facing:"north"}},buildPass:0}
:enddata
:endrule

rule:
plugin=vanillaBlocks
number=14
data:
JSON:{blockState:{blockName:"minecraft:stone_brick_stairs",properties:{half:"bottom",shape:"straight",facing:"west"}},buildPass:0}
:enddata
:endrule

rule:
plugin=vanillaBlocks
number=15
data:
JSON:{blockState:{blockName:"minecraft:log",properties:{variant:"spruce",axis:"y"}},buildPass:0}
:enddata
:endrule

rule:
plugin=vanillaBlocks
number=16
data:
JSON:{blockState:{blockName:"minecraft:fence_gate",properties:{in_wall:"false",powered:"false",facing:"east",open:"false"}},buildPass:0}
:enddata
:endrule

rule:
plugin=vanillaBlocks
number=17
data:
JSON:{blockState:{blockName:"minecraft:fence_gate",properties:{in_wall:"false",powered:"false",facing:"south",open:"false"}},buildPass:0}
:enddata
:endrule

rule:
plugin=vanillaBlocks
number=18
data:
JSON:{blockState:{blockName:"minecraft:torch",properties:{facing:"up"}},buildPass:2}
:enddata
:endrule

rule:
plugin=vanillaBlocks
number=19
data:
JSON:{blockState:{blockName:"minecraft:stained_glass_pane",properties:{east:"false",color:"green",south:"false",north:"false",west:"false"}},buildPass:0}
:enddata
:endrule

rule:
plugin=vanillaBlocks
number=20
data:
JSON:{blockState:{blockName:"minecraft:torch",properties:{facing:"east"}},buildPass:2}
:enddata
:endrule

rule:
plugin=vanillaBlocks
number=21
data:
JSON:{blockState:{blockName:"minecraft:bookshelf",properties:{}},buildPass:0}
:enddata
:endrule

rule:
plugin=vanillaBlocks
number=22
data:
JSON:{blockState:{blockName:"minecraft:glass_pane",properties:{east:"false",south:"false",north:"false",west:"false"}},buildPass:0}
:enddata
:endrule

rule:
plugin=vanillaBlocks
number=23
data:
JSON:{blockState:{blockName:"minecraft:birch_stairs",properties:{half:"bottom",shape:"straight",facing:"north"}},buildPass:0}
:enddata
:endrule

rule:
plugin=vanillaBlocks
number=24
data:
JSON:{blockState:{blockName:"minecraft:stone_brick_stairs",properties:{half:"bottom",shape:"straight",facing:"south"}},buildPass:0}
:enddata
:endrule

rule:
plugin=doors
number=25
data:
JSON:{blockState:{blockName:"minecraft:wooden_door",properties:{hinge:"left",half:"lower",powered:"false",facing:"west",open:"false"}},buildPass:2}
:enddata
:endrule

rule:
plugin=vanillaBlocks
number=26
data:
JSON:{blockState:{blockName:"minecraft:birch_stairs",properties:{half:"bottom",shape:"straight",facing:"south"}},buildPass:0}
:enddata
:endrule

rule:
plugin=doors
number=27
data:
JSON:{blockState:{blockName:"minecraft:wooden_door",properties:{hinge:"left",half:"lower",powered:"false",facing:"south",open:"false"}},buildPass:2}
:enddata
:endrule

rule:
plugin=doors
number=28
data:
JSON:{blockState:{blockName:"minecraft:iron_door",properties:{hinge:"left",half:"lower",powered:"false",facing:"north",open:"false"}},buildPass:2}
:enddata
:endrule

rule:
plugin=doors
number=29
data:
JSON:{blockState:{blockName:"minecraft:iron_door",properties:{hinge:"left",half:"lower",powered:"false",facing:"north",open:"false"}},buildPass:2}
:enddata
:endrule

rule:
plugin=vanillaBlocks
number=30
data:
JSON:{blockState:{blockName:"minecraft:torch",properties:{facing:"south"}},buildPass:2}
:enddata
:endrule

rule:
plugin=vanillaSign
number=31
data:
JSON:{signContents0:"",blockState:{blockName:"minecraft:wall_sign",properties:{facing:"east"}},signContents2:"did itÂ§r§r",buildPass:2,signContents1:"I know youÂ§r§r",signContents3:""}
:enddata
:endrule

rule:
plugin=vanillaBlocks
number=32
data:
JSON:{blockState:{blockName:"minecraft:leaves",properties:{check_decay:"false",decayable:"true",variant:"spruce"}},buildPass:0}
:enddata
:endrule

rule:
plugin=doors
number=33
data:
JSON:{blockState:{blockName:"minecraft:wooden_door",properties:{hinge:"left",half:"lower",powered:"false",facing:"north",open:"false"}},buildPass:2}
:enddata
:endrule

rule:
plugin=vanillaBlocks
number=34
data:
JSON:{blockState:{blockName:"minecraft:quartz_stairs",properties:{half:"bottom",shape:"straight",facing:"north"}},buildPass:0}
:enddata
:endrule

rule:
plugin=vanillaBlocks
number=35
data:
JSON:{blockState:{blockName:"minecraft:nether_brick_stairs",properties:{half:"bottom",shape:"straight",facing:"north"}},buildPass:0}
:enddata
:endrule

rule:
plugin=vanillaBlocks
number=36
data:
JSON:{blockState:{blockName:"minecraft:nether_brick_stairs",properties:{half:"bottom",shape:"straight",facing:"south"}},buildPass:0}
:enddata
:endrule

rule:
plugin=doors
number=37
data:
JSON:{blockState:{blockName:"minecraft:wooden_door",properties:{hinge:"left",half:"lower",powered:"false",facing:"south",open:"false"}},buildPass:2}
:enddata
:endrule

rule:
plugin=vanillaBlocks
number=38
data:
JSON:{blockState:{blockName:"minecraft:stained_glass_pane",properties:{east:"false",color:"gray",south:"false",north:"false",west:"false"}},buildPass:0}
:enddata
:endrule

rule:
plugin=vanillaBlocks
number=39
data:
JSON:{blockState:{blockName:"minecraft:carpet",properties:{color:"gray"}},buildPass:2}
:enddata
:endrule

rule:
plugin=vanillaSign
number=40
data:
JSON:{signContents0:"",blockState:{blockName:"minecraft:wall_sign",properties:{facing:"east"}},signContents2:"cornerÂ§r§r",buildPass:2,signContents1:"Time OutÂ§r§r",signContents3:""}
:enddata
:endrule

rule:
plugin=doors
number=41
data:
JSON:{blockState:{blockName:"minecraft:wooden_door",properties:{hinge:"left",half:"upper",powered:"false",facing:"north",open:"false"}},buildPass:2}
:enddata
:endrule

rule:
plugin=doors
number=42
data:
JSON:{blockState:{blockName:"minecraft:wooden_door",properties:{hinge:"left",half:"upper",powered:"false",facing:"north",open:"false"}},buildPass:2}
:enddata
:endrule

rule:
plugin=doors
number=43
data:
JSON:{blockState:{blockName:"minecraft:wooden_door",properties:{hinge:"left",half:"upper",powered:"false",facing:"north",open:"false"}},buildPass:2}
:enddata
:endrule

rule:
plugin=doors
number=44
data:
JSON:{blockState:{blockName:"minecraft:iron_door",properties:{hinge:"left",half:"upper",powered:"false",facing:"north",open:"false"}},buildPass:2}
:enddata
:endrule

rule:
plugin=doors
number=45
data:
JSON:{blockState:{blockName:"minecraft:iron_door",properties:{hinge:"right",half:"upper",powered:"false",facing:"north",open:"false"}},buildPass:2}
:enddata
:endrule

rule:
plugin=vanillaSign
number=46
data:
JSON:{signContents0:"Forgive meÂ§r§r",blockState:{blockName:"minecraft:wall_sign",properties:{facing:"east"}},signContents2:"am about to sinÂ§r§r",buildPass:2,signContents1:"Father for IÂ§r§r",signContents3:"..kthnxÂ§r§r"}
:enddata
:endrule

rule:
plugin=vanillaSign
number=47
data:
JSON:{signContents0:"",blockState:{blockName:"minecraft:wall_sign",properties:{facing:"east"}},signContents2:"",buildPass:2,signContents1:"CONFESS!Â§r§r",signContents3:""}
:enddata
:endrule

rule:
plugin=vanillaBlocks
number=48
data:
JSON:{blockState:{blockName:"minecraft:nether_brick_fence",properties:{east:"false",south:"false",north:"false",west:"false"}},buildPass:0}
:enddata
:endrule

rule:
plugin=doors
number=49
data:
JSON:{blockState:{blockName:"minecraft:wooden_door",properties:{hinge:"left",half:"upper",powered:"false",facing:"north",open:"false"}},buildPass:2}
:enddata
:endrule

rule:
plugin=vanillaSign
number=50
data:
JSON:{signContents0:"",blockState:{blockName:"minecraft:wall_sign",properties:{facing:"south"}},signContents2:"",buildPass:2,signContents1:"ConfessionÂ§r§r",signContents3:""}
:enddata
:endrule

rule:
plugin=vanillaBlocks
number=51
data:
JSON:{blockState:{blockName:"minecraft:torch",properties:{facing:"west"}},buildPass:2}
:enddata
:endrule

rule:
plugin=vanillaBlocks
number=52
data:
JSON:{blockState:{blockName:"minecraft:glowstone",properties:{}},buildPass:0}
:enddata
:endrule

rule:
plugin=doors
number=53
data:
JSON:{blockState:{blockName:"minecraft:wooden_door",properties:{hinge:"right",half:"upper",powered:"false",facing:"north",open:"false"}},buildPass:2}
:enddata
:endrule

rule:
plugin=doors
number=54
data:
JSON:{blockState:{blockName:"minecraft:wooden_door",properties:{hinge:"left",half:"upper",powered:"false",facing:"north",open:"false"}},buildPass:2}
:enddata
:endrule

rule:
plugin=vanillaBlocks
number=55
data:
JSON:{blockState:{blockName:"minecraft:stained_glass_pane",properties:{east:"false",color:"black",south:"false",north:"false",west:"false"}},buildPass:0}
:enddata
:endrule

rule:
plugin=vanillaBlocks
number=56
data:
JSON:{blockState:{blockName:"minecraft:carpet",properties:{color:"green"}},buildPass:2}
:enddata
:endrule

rule:
plugin=vanillaBlocks
number=57
data:
JSON:{blockState:{blockName:"minecraft:stone_brick_stairs",properties:{half:"top",shape:"straight",facing:"south"}},buildPass:0}
:enddata
:endrule

rule:
plugin=vanillaBlocks
number=58
data:
JSON:{blockState:{blockName:"minecraft:stone_brick_stairs",properties:{half:"top",shape:"straight",facing:"west"}},buildPass:0}
:enddata
:endrule

rule:
plugin=vanillaBlocks
number=59
data:
JSON:{blockState:{blockName:"minecraft:stone_brick_stairs",properties:{half:"top",shape:"straight",facing:"east"}},buildPass:0}
:enddata
:endrule

rule:
plugin=vanillaBlocks
number=60
data:
JSON:{blockState:{blockName:"minecraft:lit_redstone_lamp",properties:{}},buildPass:2}
:enddata
:endrule

rule:
plugin=vanillaBlocks
number=61
data:
JSON:{blockState:{blockName:"minecraft:lever",properties:{powered:"true",facing:"east"}},buildPass:2}
:enddata
:endrule

rule:
plugin=vanillaBlocks
number=62
data:
JSON:{blockState:{blockName:"minecraft:lever",properties:{powered:"true",facing:"down_z"}},buildPass:2}
:enddata
:endrule

rule:
plugin=vanillaBlocks
number=63
data:
JSON:{blockState:{blockName:"minecraft:stained_glass_pane",properties:{east:"false",color:"white",south:"false",north:"false",west:"false"}},buildPass:0}
:enddata
:endrule

rule:
plugin=doors
number=64
data:
JSON:{blockState:{blockName:"minecraft:iron_door",properties:{hinge:"left",half:"lower",powered:"false",facing:"south",open:"false"}},buildPass:2}
:enddata
:endrule

rule:
plugin=vanillaBlocks
number=65
data:
JSON:{blockState:{blockName:"minecraft:iron_bars",properties:{east:"false",south:"false",north:"false",west:"false"}},buildPass:0}
:enddata
:endrule

rule:
plugin=vanillaBlocks
number=66
data:
JSON:{blockState:{blockName:"minecraft:stone_brick_stairs",properties:{half:"top",shape:"straight",facing:"north"}},buildPass:0}
:enddata
:endrule

rule:
plugin=vanillaBlocks
number=67
data:
JSON:{blockState:{blockName:"minecraft:lever",properties:{powered:"true",facing:"north"}},buildPass:2}
:enddata
:endrule

rule:
plugin=vanillaBlocks
number=68
data:
JSON:{blockState:{blockName:"minecraft:stone_button",properties:{powered:"false",facing:"north"}},buildPass:2}
:enddata
:endrule

rule:
plugin=doors
number=69
data:
JSON:{blockState:{blockName:"minecraft:iron_door",properties:{hinge:"left",half:"upper",powered:"false",facing:"north",open:"false"}},buildPass:2}
:enddata
:endrule

rule:
plugin=vanillaBlocks
number=70
data:
JSON:{blockState:{blockName:"minecraft:birch_stairs",properties:{half:"bottom",shape:"straight",facing:"west"}},buildPass:0}
:enddata
:endrule

rule:
plugin=vanillaBlocks
number=71
data:
JSON:{blockState:{blockName:"minecraft:birch_stairs",properties:{half:"bottom",shape:"straight",facing:"east"}},buildPass:0}
:enddata
:endrule

rule:
plugin=vanillaBlocks
number=72
data:
JSON:{blockState:{blockName:"minecraft:lever",properties:{powered:"true",facing:"west"}},buildPass:2}
:enddata
:endrule

rule:
plugin=vanillaBlocks
number=73
data:
JSON:{blockState:{blockName:"minecraft:wooden_slab",properties:{half:"bottom",variant:"birch"}},buildPass:0}
:enddata
:endrule

#### ENTITIES ####
entity:
plugin=vanillaHangingEntity
number=0
data:
JSON:{xOffset:0.0f,rotation:180.0f,mobID:"minecraft:painting",zOffset:0.0625f,position:4673192853507L,entityData:{Motion:[0.0d,0.0d,0.0d],Invulnerable:0b,OnGround:0b,Dimension:0,Air:300s,Dir:2b,PortalCooldown:0,Direction:0b,Rotation:[180.0f,0.0f],Motive:"Creebet",FallDistance:0.0f,Pos:[93.0d,86.5d,-38.9375d],Fire:0s,TileY:86,TileX:92,TileZ:-40},direction:0b}
:enddata
:endentity

