# Ancient Warfare Structure Template File
# Auto-generated structure template file. created on: 8/28/2018 at: 17:29:59
# Lines beginning with # denote comments

header:
version=2.3
name=unique_mayors_mansion
size=23,18,21
offset=11,1,20
:endheader

#### VALIDATION ####
validation:
type=ground
survival=false
worldGenEnabled=false
unique=false
preserveBlocks=false
selectionWeight=0
clusterValue=0
minDuplicateDistance=0
dimensionWhiteList=false
dimensionList=
biomeWhiteList=false
biomeList=
leveling=0
fill=0
border=0
blockSwap=false
data:
:enddata
:endvalidation

#### LAYERS ####
layer: 0
1,1,1,1,1,1,1,1,1,1,1,1,1,1,1,1,1,1,1,1,1,1,1
1,2,2,2,2,2,2,2,2,2,2,2,2,2,2,2,2,2,2,2,2,2,1
1,2,3,3,3,3,3,3,3,4,4,4,4,4,4,4,4,4,4,4,4,2,1
1,2,3,3,3,3,3,3,3,4,4,4,4,4,4,4,4,4,4,4,4,2,1
1,2,3,3,3,3,3,3,3,4,4,4,4,4,4,4,4,4,4,4,4,2,1
1,2,3,3,3,3,3,3,3,4,4,4,4,4,4,4,4,4,4,4,4,2,1
1,2,3,3,3,3,3,3,3,4,4,4,4,4,4,4,4,4,4,4,4,2,1
1,2,3,3,3,4,3,3,3,4,4,4,4,4,4,4,4,4,4,4,4,2,1
1,2,3,3,3,3,3,3,3,4,4,4,4,4,4,4,4,4,4,4,4,2,1
1,2,3,3,3,3,3,3,4,4,4,4,4,4,4,4,4,4,4,4,4,2,1
1,2,4,4,4,4,4,4,4,4,4,4,4,4,4,4,4,4,4,4,4,2,1
1,2,4,4,4,4,4,4,4,4,4,4,4,4,4,4,4,4,4,4,4,2,1
1,2,4,4,4,4,4,4,4,4,4,4,4,4,4,4,4,4,4,4,4,2,1
1,2,4,4,4,4,4,4,4,4,4,4,4,4,4,4,4,4,4,4,4,2,1
1,2,4,4,4,4,4,4,4,4,4,4,4,4,4,4,4,4,4,4,4,2,1
1,2,4,4,4,4,4,4,4,4,4,4,4,4,4,4,4,4,4,4,4,2,1
1,2,4,4,4,4,4,4,4,4,4,4,4,4,4,4,4,4,4,4,4,2,1
1,2,4,4,4,4,4,4,4,4,4,4,4,4,4,4,4,4,4,4,4,2,1
1,2,4,4,4,4,4,4,4,2,5,5,5,2,4,4,4,4,4,4,4,2,1
1,2,2,2,2,2,2,2,2,2,5,5,5,2,2,2,2,2,2,2,2,2,1
1,1,1,1,1,1,1,1,1,1,5,5,5,1,1,1,1,1,1,1,1,1,1
:endlayer
layer: 1
0,0,0,0,0,0,0,0,0,0,0,0,0,0,0,0,0,0,0,0,0,0,0
0,6,6,6,6,6,6,6,6,6,6,6,6,6,6,6,6,6,6,6,6,6,0
0,6,4,0,0,0,0,0,7,4,8,0,4,4,9,0,10,2,2,11,12,6,0
0,6,0,0,13,13,0,0,7,4,14,0,4,4,9,0,0,15,15,0,16,6,0
0,6,0,17,18,18,19,0,20,4,0,21,0,4,22,0,0,16,0,10,2,6,0
0,6,0,0,18,18,0,0,23,4,24,0,0,4,0,0,10,2,11,10,2,6,0
0,6,0,17,18,18,19,0,25,4,26,0,0,27,0,28,10,2,11,10,2,6,0
0,6,0,0,29,29,0,0,7,30,4,4,4,30,0,0,10,2,11,10,2,6,0
0,6,0,0,0,0,0,0,0,0,0,0,0,0,0,0,0,15,0,28,15,6,0
0,6,7,31,31,7,0,0,0,0,0,0,0,0,0,0,0,28,28,0,31,6,0
0,6,4,4,4,4,30,0,0,0,0,21,0,0,0,0,30,4,4,4,4,6,0
0,6,4,32,33,34,35,35,0,0,0,0,0,0,0,36,36,12,12,12,12,6,0
0,6,33,35,35,35,35,35,35,0,0,0,0,0,36,36,36,36,36,36,36,6,0
0,6,32,35,35,35,35,35,35,30,0,0,0,30,36,36,36,36,17,36,19,6,0
0,6,32,35,35,12,35,35,33,4,0,0,0,4,17,36,19,36,17,18,19,6,0
0,6,32,35,35,12,35,35,34,4,0,0,0,4,17,18,19,36,17,18,19,6,0
0,6,32,35,35,35,35,35,34,4,0,0,0,4,17,36,19,36,17,36,19,6,0
0,6,37,35,35,35,35,35,37,4,6,38,6,4,36,36,36,36,36,36,36,6,0
0,6,4,32,37,37,37,34,4,6,0,0,0,6,17,29,19,12,17,29,19,6,0
0,6,6,6,6,6,6,6,6,6,0,0,0,6,6,6,6,6,6,6,6,6,0
0,0,0,0,0,0,0,0,0,0,0,0,0,0,0,0,0,0,0,0,0,0,0
:endlayer
layer: 2
0,0,0,0,0,0,0,0,0,0,0,0,0,0,0,0,0,0,0,0,0,0,0
0,6,6,39,39,6,6,39,39,6,6,6,6,6,39,39,6,6,39,39,6,6,0
0,6,40,0,0,0,0,0,0,4,0,41,9,0,0,0,0,42,43,0,12,6,0
0,39,0,0,0,0,0,0,0,4,0,41,9,0,0,0,0,0,0,0,0,39,0
0,39,0,0,44,44,0,0,0,4,0,0,4,4,0,0,0,0,0,0,45,39,0
0,6,0,0,44,44,0,0,0,4,46,0,0,4,0,0,0,47,0,0,48,6,0
0,6,0,0,44,44,0,0,0,4,49,0,0,50,0,0,0,51,0,0,52,6,0
0,39,0,0,0,0,0,0,0,30,4,4,4,30,0,0,0,28,0,0,53,39,0
0,39,0,0,0,0,0,0,0,0,0,0,0,0,0,0,0,0,0,0,0,39,0
0,6,0,0,0,0,0,0,0,0,0,0,0,0,0,0,0,0,0,0,0,6,0
0,6,4,4,4,4,30,0,0,0,0,0,0,0,0,0,30,4,4,4,4,6,0
0,6,54,0,0,0,0,0,0,0,0,0,0,0,0,0,0,12,12,12,12,6,0
0,39,0,0,0,0,0,0,0,0,0,0,0,0,0,0,0,0,0,0,0,39,0
0,39,0,0,0,0,0,0,0,30,0,0,0,30,0,0,0,0,0,55,0,39,0
0,6,0,0,0,0,0,0,0,4,0,0,0,4,0,55,0,0,0,55,0,6,0
0,6,0,0,0,0,0,0,0,4,0,0,0,4,0,55,0,0,0,55,0,6,0
0,39,0,0,0,0,0,0,0,4,0,0,0,4,0,55,0,0,0,55,0,39,0
0,39,0,0,0,0,0,0,0,4,6,56,6,4,0,0,0,0,0,0,0,39,0
0,6,57,0,0,0,0,0,58,6,0,0,0,6,0,0,0,12,0,0,0,6,0
0,6,39,39,6,6,39,39,6,6,0,0,0,6,6,39,39,6,6,39,39,6,0
0,0,0,0,0,0,0,0,0,0,0,0,0,0,0,0,0,0,0,0,0,0,0
:endlayer
layer: 3
0,59,0,0,0,0,59,0,0,0,59,0,59,0,0,0,59,0,0,0,0,59,0
60,6,6,39,39,6,6,39,39,6,6,6,6,6,39,39,6,6,39,39,6,6,61
0,6,0,0,0,62,0,0,0,4,4,9,0,62,0,0,0,62,0,0,0,6,0
0,39,0,0,0,0,0,0,0,4,4,9,0,0,0,0,0,0,0,0,0,39,0
0,39,0,0,18,0,0,0,0,4,0,4,4,4,0,0,0,0,0,0,0,39,0
60,6,0,18,18,18,0,0,0,4,63,0,0,4,0,0,0,0,0,0,0,6,61
0,6,61,0,18,0,0,0,0,4,64,0,0,4,61,0,0,0,0,0,60,6,0
0,39,0,0,0,0,0,0,0,30,4,4,4,30,0,0,0,0,0,0,0,39,0
0,39,0,0,0,0,0,0,0,0,0,0,0,0,0,0,0,0,0,0,0,39,0
0,6,0,0,0,0,59,0,0,0,0,0,0,0,0,0,0,59,0,0,0,6,0
60,6,4,4,4,4,30,0,0,0,0,0,0,0,0,0,30,4,4,4,4,6,61
0,6,0,0,0,62,0,0,0,0,0,0,0,0,0,0,0,12,12,12,12,6,0
0,39,0,0,0,0,0,0,0,0,0,0,0,0,0,0,0,0,0,0,0,39,0
0,39,0,0,0,0,0,0,0,30,0,0,0,30,0,0,0,0,0,0,0,39,0
0,6,0,0,0,0,0,0,60,4,0,0,0,4,61,0,0,0,0,0,60,6,0
60,6,61,0,0,0,0,0,0,4,0,0,0,4,0,0,0,0,0,0,0,6,61
0,39,0,0,0,0,0,0,0,4,59,0,59,4,0,0,0,0,0,0,0,39,0
0,39,0,0,0,0,0,0,0,4,6,6,6,4,0,0,0,0,0,0,0,39,0
0,6,0,0,59,0,0,0,0,6,65,66,65,6,0,0,0,59,0,0,0,6,0
60,6,39,39,6,6,39,39,6,6,0,0,0,6,6,39,39,6,6,39,39,6,61
0,62,0,0,0,62,0,0,0,62,0,0,0,62,0,0,0,62,0,0,0,62,0
:endlayer
layer: 4
0,0,0,0,0,0,0,0,0,0,0,0,0,0,0,0,0,0,0,0,0,0,0
0,6,6,6,6,6,6,6,6,6,6,6,6,6,6,6,6,6,6,6,6,6,0
0,6,0,0,0,0,67,0,0,4,9,0,0,0,0,0,67,0,0,0,0,6,0
0,6,0,0,0,0,67,0,0,4,9,0,0,0,0,0,67,0,0,0,0,6,0
0,6,0,0,21,0,67,0,0,4,4,4,4,4,0,0,67,0,0,0,0,6,0
0,6,0,21,18,21,67,0,0,4,0,0,0,4,0,0,67,0,0,0,0,6,0
0,6,0,0,21,0,67,0,0,4,0,0,0,4,0,0,67,0,0,0,0,6,0
0,6,68,68,68,68,68,68,68,67,68,68,68,68,68,68,68,68,68,68,68,6,0
0,6,0,0,0,0,67,0,0,67,0,0,0,67,0,0,67,0,0,0,0,6,0
0,6,0,0,0,0,67,0,0,67,0,0,0,67,0,0,67,0,0,0,0,6,0
0,6,4,4,4,4,68,68,68,68,68,68,68,68,68,68,4,4,4,4,4,6,0
0,6,0,0,0,0,67,0,0,67,0,0,0,67,0,0,67,4,4,4,4,6,0
0,6,0,0,0,0,67,0,0,67,0,0,0,67,0,0,67,0,0,0,0,6,0
0,6,68,68,68,68,68,68,68,67,68,68,68,67,68,68,68,68,68,68,68,6,0
0,6,0,0,0,0,67,0,0,4,0,0,0,4,0,0,67,0,0,0,0,6,0
0,6,0,0,0,0,67,0,0,4,0,0,0,4,0,0,67,0,0,0,0,6,0
0,6,0,0,0,0,67,0,0,4,0,0,0,4,0,0,67,0,0,0,0,6,0
0,6,0,0,0,0,67,0,0,4,6,6,6,4,0,0,67,0,0,0,0,6,0
0,6,0,0,0,0,67,0,0,6,6,6,6,6,0,0,67,0,0,0,0,6,0
0,6,6,6,6,6,6,6,6,6,69,65,70,6,6,6,6,6,6,6,6,6,0
0,0,0,0,0,0,0,0,0,0,0,0,0,0,0,0,0,0,0,0,0,0,0
:endlayer
layer: 5
0,0,0,0,0,0,0,0,0,0,0,0,0,0,0,0,0,0,0,0,0,0,0
0,6,6,6,6,6,6,6,6,6,6,6,6,6,6,6,6,6,6,6,6,6,0
0,6,6,6,6,6,6,6,6,9,0,0,0,0,6,6,6,6,6,6,6,6,0
0,6,6,6,6,6,6,6,6,9,0,0,0,0,6,6,6,6,6,6,6,6,0
0,6,6,6,6,6,6,6,6,6,6,6,6,6,6,6,6,6,6,6,6,6,0
0,6,6,6,6,6,6,6,6,6,6,6,6,6,6,6,6,6,6,6,6,6,0
0,6,6,6,6,6,6,6,6,6,6,6,6,6,6,6,6,6,6,6,6,6,0
0,6,6,6,6,6,6,6,6,6,6,6,6,6,6,6,6,6,6,6,6,6,0
0,6,6,6,6,6,6,6,6,6,6,6,6,6,6,6,6,6,6,6,6,6,0
0,6,6,6,6,6,6,6,6,6,6,6,6,6,6,6,6,6,6,6,6,6,0
0,6,6,6,6,6,6,6,6,6,6,6,6,6,6,6,6,6,6,6,6,6,0
0,6,6,6,6,6,6,6,6,6,6,6,6,6,6,6,6,6,6,6,6,6,0
0,6,6,6,6,6,6,6,6,6,6,6,6,6,6,6,6,6,6,6,6,6,0
0,6,6,6,6,6,6,6,6,6,6,6,6,6,6,6,6,6,6,6,6,6,0
0,6,6,6,6,6,6,6,6,6,6,6,6,6,6,6,6,6,6,6,6,6,0
0,6,6,6,6,6,6,6,6,6,6,6,6,6,6,6,6,6,6,6,6,6,0
0,6,6,6,6,6,6,6,6,6,6,6,6,6,6,6,6,6,6,6,6,6,0
0,6,6,6,6,6,6,6,6,6,6,6,6,6,6,6,6,6,6,6,6,6,0
0,6,6,6,6,6,6,6,6,6,6,6,6,6,6,6,6,6,6,6,6,6,0
0,6,6,6,6,6,6,6,6,6,6,6,6,6,6,6,6,6,6,6,6,6,0
0,0,0,0,0,0,0,0,0,0,0,0,0,0,0,0,0,0,0,0,0,0,0
:endlayer
layer: 6
0,0,0,0,0,0,0,0,0,0,0,0,0,0,0,0,0,0,0,0,0,0,0
0,71,18,18,6,6,6,6,6,6,6,6,6,6,6,6,6,6,6,18,18,71,0
0,18,0,0,6,0,0,0,0,0,0,0,0,0,18,0,72,73,6,0,0,18,0
0,18,0,0,6,0,0,0,0,0,0,0,0,0,18,0,0,0,6,0,0,18,0
0,18,0,0,6,0,0,0,18,18,18,18,18,18,18,0,0,0,6,0,0,18,0
0,18,0,0,6,0,0,0,0,0,0,0,0,0,0,0,0,12,6,0,0,18,0
0,18,0,0,6,74,74,74,0,35,35,35,35,0,0,0,0,75,6,0,0,18,0
0,18,0,0,6,4,4,9,0,35,76,44,35,0,4,77,77,4,6,0,0,18,0
0,18,0,0,6,4,4,9,0,35,44,76,35,0,77,78,79,80,6,0,0,18,0
0,18,0,0,6,81,81,0,0,35,76,44,35,0,77,78,79,80,6,0,0,18,0
0,71,0,0,6,82,83,0,0,35,44,76,35,0,4,77,77,4,6,0,0,71,0
0,18,0,0,6,0,0,0,0,35,76,44,35,0,0,0,0,84,6,0,0,18,0
0,18,0,0,6,12,0,0,0,35,44,76,35,0,0,0,0,4,6,0,0,18,0
0,18,0,0,6,12,0,0,0,35,35,35,35,0,0,0,0,33,6,0,0,18,0
0,18,0,0,6,0,21,0,0,0,0,0,0,0,0,0,0,34,6,0,0,18,0
0,18,0,0,6,4,0,0,0,0,0,0,0,32,37,37,37,34,6,0,0,18,0
0,18,0,0,6,6,6,6,6,6,6,38,6,6,6,6,6,6,6,0,0,18,0
0,18,0,0,0,0,0,0,0,0,0,0,0,0,0,0,0,0,0,0,0,18,0
0,18,0,0,0,0,0,0,0,0,0,0,0,0,0,0,0,0,0,0,0,18,0
0,71,18,18,18,18,18,18,18,71,18,18,18,71,18,18,18,18,18,18,18,71,0
0,0,0,0,0,0,0,0,0,0,0,0,0,0,0,0,0,0,0,0,0,0,0
:endlayer
layer: 7
0,0,0,0,0,0,0,0,0,0,0,0,0,0,0,0,0,0,0,0,0,0,0
0,85,0,0,6,6,39,39,6,6,39,39,39,6,6,39,39,6,6,0,0,85,0
0,0,0,0,6,0,0,0,0,0,0,0,0,0,0,0,0,0,6,0,0,0,0
0,0,0,0,39,0,0,0,0,0,0,0,0,0,0,0,0,0,39,0,0,0,0
0,0,0,0,39,0,0,0,21,0,0,0,0,0,21,0,0,0,39,0,0,0,0
0,0,0,0,39,0,0,0,0,0,0,0,0,0,0,0,0,0,39,0,0,0,0
0,0,0,0,6,0,0,0,0,0,0,0,0,0,0,0,0,0,6,0,0,0,0
0,0,0,0,6,0,0,0,0,0,0,0,0,0,18,0,0,18,6,0,0,0,0
0,0,0,0,6,0,0,0,0,0,0,0,0,0,0,0,0,0,6,0,0,0,0
0,0,0,0,6,74,74,0,0,0,0,0,0,0,0,0,0,0,6,0,0,0,0
0,85,0,0,6,81,81,0,0,0,0,0,0,0,18,0,0,18,6,0,0,85,0
0,0,0,0,6,0,0,0,0,0,0,0,0,0,0,0,0,0,6,0,0,0,0
0,0,0,0,39,0,0,0,0,0,0,0,0,0,0,0,0,86,39,0,0,0,0
0,0,0,0,39,0,0,0,0,0,0,0,0,0,0,0,0,0,39,0,0,0,0
0,0,0,0,39,0,0,0,0,0,0,0,0,0,0,0,0,0,39,0,0,0,0
0,0,0,0,6,87,0,0,0,0,0,0,0,0,0,0,0,0,6,0,0,0,0
0,0,0,0,6,6,39,39,39,6,6,88,6,6,39,39,39,6,6,0,0,0,0
0,0,0,0,0,0,0,0,0,0,0,0,0,0,0,0,0,0,0,0,0,0,0
0,0,0,0,0,0,0,0,0,0,0,0,0,0,0,0,0,0,0,0,0,0,0
0,85,0,0,0,0,0,0,0,85,0,0,0,85,0,0,0,0,0,0,0,85,0
0,0,0,0,0,0,0,0,0,0,0,0,0,0,0,0,0,0,0,0,0,0,0
:endlayer
layer: 8
0,0,0,0,0,0,0,0,0,0,0,0,0,0,0,0,0,0,0,0,0,0,0
0,85,0,0,6,6,39,39,6,6,39,39,39,6,6,39,39,6,6,0,0,85,0
0,0,0,60,6,0,0,0,0,0,0,0,0,0,0,0,0,0,6,61,0,0,0
0,0,0,0,39,0,0,0,0,0,0,0,0,0,0,0,0,0,39,0,0,0,0
0,0,0,0,39,0,0,0,0,0,0,0,0,0,0,0,0,0,39,0,0,0,0
0,0,0,0,39,0,0,0,0,0,0,0,0,0,0,0,0,0,39,0,0,0,0
0,0,0,60,6,61,0,0,0,0,89,0,0,0,0,0,0,60,6,0,0,0,0
0,0,0,0,6,0,0,0,0,0,0,0,0,0,18,0,0,18,6,61,0,0,0
0,0,0,0,6,0,0,0,0,0,0,0,0,0,0,0,0,0,6,0,0,0,0
0,0,0,0,6,0,0,0,0,0,0,0,0,0,0,0,0,0,6,0,0,0,0
0,85,0,0,6,74,74,0,0,0,0,0,0,0,18,0,0,18,6,0,0,85,0
0,0,0,60,6,81,81,0,0,0,89,0,0,0,0,0,0,60,6,61,0,0,0
0,0,0,0,39,0,0,0,0,0,0,0,0,0,0,0,0,0,39,0,0,0,0
0,0,0,0,39,0,0,0,0,0,0,0,0,0,0,0,0,0,39,0,0,0,0
0,0,0,0,39,0,0,0,0,0,0,0,0,0,0,0,0,0,39,0,0,0,0
0,0,0,60,6,0,0,0,0,59,0,0,0,59,0,0,0,0,6,61,0,0,0
0,0,0,0,6,6,39,39,39,6,6,6,6,6,39,39,39,6,6,0,0,0,0
0,0,0,0,0,62,0,0,0,62,0,0,0,62,0,0,0,62,0,0,0,0,0
0,0,0,0,0,0,0,0,0,0,0,0,0,0,0,0,0,0,0,0,0,0,0
0,85,0,0,0,0,0,0,0,85,0,0,0,85,0,0,0,0,0,0,0,85,0
0,0,0,0,0,0,0,0,0,0,0,0,0,0,0,0,0,0,0,0,0,0,0
:endlayer
layer: 9
0,0,0,0,0,0,0,0,0,0,0,0,0,0,0,0,0,0,0,0,0,0,0
0,85,0,0,6,6,6,6,6,6,6,6,6,6,6,6,6,6,6,0,0,85,0
0,0,0,0,6,0,0,0,0,0,0,0,0,0,0,0,0,0,6,0,0,0,0
0,0,0,0,6,0,0,0,0,0,0,0,0,0,0,0,0,0,6,0,0,0,0
0,0,0,0,6,0,0,0,0,0,0,0,0,0,0,0,0,0,6,0,0,0,0
0,0,0,0,6,0,0,0,0,0,0,0,0,0,0,0,0,0,6,0,0,0,0
0,0,0,0,6,0,0,0,0,0,18,0,0,0,0,0,0,0,6,0,0,0,0
0,0,0,0,6,0,0,0,0,0,0,0,0,60,80,90,90,80,6,0,0,0,0
0,0,0,0,6,0,0,0,0,0,0,0,0,0,90,90,90,90,6,0,0,0,0
0,0,0,0,6,0,0,0,0,0,0,0,0,0,90,90,90,90,6,0,0,0,0
0,85,0,0,6,0,0,0,0,0,0,0,0,60,80,90,90,80,6,0,0,85,0
0,0,0,0,6,74,74,0,0,0,18,0,0,0,0,0,0,0,6,0,0,0,0
0,0,0,0,6,81,81,0,0,0,0,0,0,0,0,0,0,0,6,0,0,0,0
0,0,0,0,6,0,0,0,0,0,0,0,0,0,0,0,0,0,6,0,0,0,0
0,0,0,0,6,0,0,0,0,0,0,0,0,0,0,0,0,0,6,0,0,0,0
0,0,0,0,6,0,0,0,0,0,0,0,0,0,0,0,0,0,6,0,0,0,0
0,0,0,0,6,6,6,6,6,6,6,6,6,6,6,6,6,6,6,0,0,0,0
0,0,0,0,0,0,0,0,0,0,0,0,0,0,0,0,0,0,0,0,0,0,0
0,0,0,0,0,0,0,0,0,0,0,0,0,0,0,0,0,0,0,0,0,0,0
0,85,0,0,0,0,0,0,0,85,0,0,0,85,0,0,0,0,0,0,0,85,0
0,0,0,0,0,0,0,0,0,0,0,0,0,0,0,0,0,0,0,0,0,0,0
:endlayer
layer: 10
74,74,74,74,74,74,74,74,74,74,74,74,74,74,74,74,74,74,74,74,74,74,74
91,4,4,4,4,4,4,4,4,4,4,4,4,4,4,4,4,4,4,4,4,4,9
91,4,4,4,4,4,4,4,4,4,4,4,4,4,4,4,4,4,4,4,4,4,9
91,4,4,4,4,4,4,4,4,4,4,4,4,4,4,4,4,4,4,4,4,4,9
91,4,4,4,4,4,4,4,4,4,4,4,4,4,4,4,4,4,4,4,4,4,9
91,4,4,4,4,4,4,4,4,4,4,4,4,4,4,4,4,4,4,4,4,4,9
91,4,4,4,4,4,4,4,4,4,4,4,4,4,4,4,4,4,4,4,4,4,9
91,4,4,4,4,0,0,4,4,4,4,4,4,4,4,4,4,4,4,4,4,4,9
91,4,4,4,4,0,0,4,4,4,4,4,4,4,4,4,4,4,4,4,4,4,9
91,4,4,4,4,0,0,4,4,4,4,4,4,4,4,4,4,4,4,4,4,4,9
91,4,4,4,4,0,0,4,4,4,4,4,4,4,4,4,4,4,4,4,4,4,9
91,4,4,4,4,0,0,4,4,4,4,4,4,4,4,4,4,4,4,4,4,4,9
91,4,4,4,4,74,74,4,4,4,4,4,4,4,4,4,4,4,4,4,4,4,9
91,4,4,4,4,4,4,4,4,4,4,4,4,4,4,4,4,4,4,4,4,4,9
91,4,4,4,4,4,4,4,4,4,4,4,4,4,4,4,4,4,4,4,4,4,9
91,4,4,4,4,4,4,4,4,4,4,4,4,4,4,4,4,4,4,4,4,4,9
91,4,4,4,4,4,4,4,4,4,4,4,4,4,4,4,4,4,4,4,4,4,9
91,4,4,4,4,4,4,4,4,4,4,4,4,4,4,4,4,4,4,4,4,4,9
91,4,4,4,4,4,4,4,4,4,4,4,4,4,4,4,4,4,4,4,4,4,9
91,4,4,4,4,4,4,4,4,4,4,4,4,4,4,4,4,4,4,4,4,4,9
22,22,22,22,22,22,22,22,22,22,22,22,22,22,22,22,22,22,22,22,22,22,9
:endlayer
layer: 11
0,0,0,0,0,0,0,0,0,0,0,0,0,0,0,0,0,0,0,0,0,0,0
0,91,74,74,74,74,74,74,74,74,74,74,74,74,74,74,74,74,74,74,74,74,0
0,91,4,4,4,4,4,4,4,4,4,4,4,4,4,4,4,4,4,4,4,9,0
0,91,4,4,4,4,4,4,4,4,4,4,4,4,4,4,4,4,4,4,4,9,0
0,91,4,4,12,0,92,93,94,94,94,94,94,95,12,12,12,94,96,4,4,9,0
0,91,4,4,12,21,0,0,0,0,0,0,0,0,0,0,0,21,96,4,4,9,0
0,91,4,4,18,18,18,18,0,0,0,0,0,0,0,0,0,0,25,4,4,9,0
0,91,4,4,0,0,0,18,0,0,96,97,97,97,97,98,0,0,99,4,4,9,0
0,91,4,12,0,0,0,18,0,0,96,94,94,94,94,94,0,0,0,0,4,9,0
0,91,4,0,0,0,0,18,0,0,0,0,0,0,0,0,0,0,0,0,4,9,0
0,91,4,0,0,0,0,18,0,0,0,0,0,0,0,0,0,0,0,0,4,9,0
0,91,4,0,0,0,0,18,0,0,0,0,0,0,0,0,0,0,0,0,4,9,0
0,91,4,12,0,0,0,18,0,0,97,97,97,97,97,98,0,0,0,0,4,9,0
0,91,4,4,0,0,0,18,0,0,94,94,94,94,94,94,0,0,100,4,4,9,0
0,91,4,4,0,0,0,0,0,0,0,0,0,0,0,0,0,0,96,4,4,9,0
0,91,4,4,0,21,0,0,0,0,0,21,0,0,0,0,0,21,96,4,4,9,0
0,91,4,4,0,0,0,0,0,0,0,0,0,0,101,12,12,97,97,4,4,9,0
0,91,4,4,4,4,4,4,4,98,97,97,97,96,4,4,4,4,4,4,4,9,0
0,91,4,4,4,4,4,4,4,4,4,4,4,4,4,4,4,4,4,4,4,9,0
0,22,22,22,22,22,22,22,22,22,22,22,22,22,22,22,22,22,22,22,22,9,0
0,0,0,0,0,0,0,0,0,0,0,0,0,0,0,0,0,0,0,0,0,0,0
:endlayer
layer: 12
0,0,0,0,0,0,0,0,0,0,0,0,0,0,0,0,0,0,0,0,0,0,0
0,0,0,0,0,0,0,0,0,0,0,0,0,0,0,0,0,0,0,0,0,0,0
0,0,74,74,74,74,74,74,74,74,74,74,74,74,74,74,74,74,74,74,9,0,0
0,0,91,4,4,4,4,4,4,4,4,4,4,4,4,4,4,4,4,4,9,0,0
0,0,91,4,12,0,0,0,0,102,0,0,0,0,12,12,12,0,103,4,9,0,0
0,0,91,4,12,0,0,0,0,0,0,0,0,0,0,0,0,0,0,4,9,0,0
0,0,91,4,0,0,0,0,0,0,0,0,0,0,0,0,0,0,0,4,9,0,0
0,0,91,4,0,0,0,0,0,0,0,44,104,0,0,103,0,0,0,4,9,0,0
0,0,4,12,0,0,0,0,0,0,104,0,0,102,0,0,0,0,0,0,4,0,0
0,0,39,0,0,0,0,0,0,0,0,0,0,0,0,0,0,0,0,0,39,0,0
0,0,39,0,0,0,0,0,0,0,0,0,0,0,0,0,0,0,0,0,39,0,0
0,0,39,0,0,0,0,0,0,0,0,0,0,0,0,0,0,0,0,0,39,0,0
0,0,4,12,0,0,0,0,0,0,105,36,0,35,0,104,0,0,0,0,4,0,0
0,0,91,4,0,0,0,0,0,0,0,104,0,0,106,0,0,0,0,4,9,0,0
0,0,91,4,0,0,0,0,0,0,0,0,0,0,0,0,0,0,106,4,9,0,0
0,0,91,4,0,0,0,0,0,0,0,0,0,0,0,0,0,0,0,4,9,0,0
0,0,91,4,0,0,0,0,0,0,0,0,0,0,0,12,12,104,0,4,9,0,0
0,0,91,4,4,4,4,4,4,0,0,0,0,0,4,4,4,4,4,4,9,0,0
0,0,91,22,22,22,22,22,22,4,39,39,39,4,22,22,22,22,22,22,22,0,0
0,0,0,0,0,0,0,0,0,0,0,0,0,0,0,0,0,0,0,0,0,0,0
0,0,0,0,0,0,0,0,0,0,0,0,0,0,0,0,0,0,0,0,0,0,0
:endlayer
layer: 13
0,0,0,0,0,0,0,0,0,0,0,0,0,0,0,0,0,0,0,0,0,0,0
0,0,0,0,0,0,0,0,0,0,0,0,0,0,0,0,0,0,0,0,0,0,0
0,0,0,0,0,0,0,0,0,0,0,0,0,0,0,0,0,0,0,0,0,0,0
0,0,0,91,74,74,74,74,74,74,74,74,74,74,74,74,74,74,74,74,0,0,0
0,0,0,91,81,81,81,81,81,81,81,81,81,81,81,81,81,81,41,9,0,0,0
0,0,0,91,107,0,0,0,0,0,0,0,0,0,0,0,0,0,41,9,0,0,0
0,0,0,91,107,0,0,0,0,0,0,0,0,0,0,0,0,0,41,9,0,0,0
0,0,0,91,107,0,0,0,0,0,0,0,89,0,0,0,0,0,41,9,0,0,0
0,60,4,81,81,0,0,0,0,0,0,0,0,0,0,0,0,0,81,81,4,61,0
0,0,39,0,0,0,0,0,0,0,0,0,0,0,0,0,0,0,0,0,39,0,0
0,0,39,0,0,0,0,0,0,89,0,0,0,0,0,89,0,0,0,0,39,0,0
0,0,39,0,0,0,0,0,0,0,0,0,0,0,0,0,0,0,0,0,39,0,0
0,60,4,108,107,0,0,0,0,0,0,0,0,0,0,0,0,0,108,108,4,61,0
0,0,0,91,107,0,0,0,0,0,0,0,89,0,0,0,0,0,41,9,0,0,0
0,0,0,91,107,0,0,0,0,0,0,0,0,0,0,0,0,0,41,9,0,0,0
0,0,0,91,107,0,0,0,0,0,0,0,0,0,0,0,0,0,41,9,0,0,0
0,0,0,91,108,108,108,108,108,107,0,0,0,41,108,108,108,108,41,9,0,0,0
0,0,0,22,22,22,22,22,22,107,0,0,0,41,22,22,22,22,22,9,0,0,0
0,0,0,0,0,0,0,0,0,4,39,39,39,4,0,0,0,0,0,0,0,0,0
0,0,0,0,0,0,0,0,0,62,0,0,0,62,0,0,0,0,0,0,0,0,0
0,0,0,0,0,0,0,0,0,0,0,0,0,0,0,0,0,0,0,0,0,0,0
:endlayer
layer: 14
0,0,0,0,0,0,0,0,0,0,0,0,0,0,0,0,0,0,0,0,0,0,0
0,0,0,0,0,0,0,0,0,0,0,0,0,0,0,0,0,0,0,0,0,0,0
0,0,0,0,0,0,0,0,0,0,0,0,0,0,0,0,0,0,0,0,0,0,0
0,0,0,0,0,0,0,0,0,0,0,0,0,0,0,0,0,0,0,0,0,0,0
0,0,0,0,91,74,74,74,74,74,74,74,74,74,74,74,74,74,74,0,0,0,0
0,0,0,0,91,4,4,4,4,4,4,4,4,4,4,4,4,4,9,0,0,0,0
0,0,0,0,91,4,0,0,0,0,0,0,0,0,0,0,0,4,9,0,0,0,0
0,0,0,0,91,4,0,0,0,0,0,0,18,0,0,0,0,4,9,0,0,0,0
0,0,74,74,74,4,0,0,0,0,0,0,0,0,0,0,0,4,74,74,9,0,0
0,0,91,4,4,4,0,0,0,0,0,0,0,0,0,0,0,4,4,4,9,0,0
0,0,91,4,4,4,0,0,0,18,0,0,0,0,0,18,0,4,4,4,9,0,0
0,0,91,4,4,4,0,0,0,0,0,0,0,0,0,0,0,4,4,4,9,0,0
0,0,91,22,22,4,0,0,0,0,0,0,0,0,0,0,0,4,22,22,9,0,0
0,0,0,0,91,4,0,0,0,0,0,0,18,0,0,0,0,4,9,0,0,0,0
0,0,0,0,91,4,0,0,0,0,0,0,0,0,0,0,0,4,9,0,0,0,0
0,0,0,0,91,4,4,4,4,4,4,4,4,4,4,4,4,4,9,0,0,0,0
0,0,0,0,22,22,22,22,22,91,4,4,4,9,22,22,22,22,9,0,0,0,0
0,0,0,0,0,0,0,0,0,91,4,4,4,9,0,0,0,0,0,0,0,0,0
0,0,0,0,0,0,0,0,0,91,22,22,22,22,0,0,0,0,0,0,0,0,0
0,0,0,0,0,0,0,0,0,0,0,0,0,0,0,0,0,0,0,0,0,0,0
0,0,0,0,0,0,0,0,0,0,0,0,0,0,0,0,0,0,0,0,0,0,0
:endlayer
layer: 15
0,0,0,0,0,0,0,0,0,0,0,0,0,0,0,0,0,0,0,0,0,0,0
0,0,0,0,0,0,0,0,0,0,0,0,0,0,0,0,0,0,0,0,0,0,0
0,0,0,0,0,0,0,0,0,0,0,0,0,0,0,0,0,0,0,0,0,0,0
0,0,0,0,0,0,0,0,0,0,0,0,0,0,0,0,0,0,0,0,0,0,0
0,0,0,0,0,0,0,0,0,0,0,0,0,0,0,0,0,0,0,0,0,0,0
0,0,0,0,0,74,74,74,74,74,74,74,74,74,74,74,74,9,0,0,0,0,0
0,0,0,0,0,91,4,4,4,4,4,4,4,4,4,4,4,9,0,0,0,0,0
0,0,0,0,0,91,4,0,0,0,0,0,18,0,0,0,4,9,0,0,0,0,0
0,0,0,0,0,91,4,0,0,0,0,0,0,0,0,0,4,9,0,0,0,0,0
0,0,0,74,74,74,4,0,0,0,0,0,0,0,0,0,4,74,74,74,0,0,0
0,0,0,91,4,4,4,0,0,18,0,0,0,0,0,18,4,4,4,9,0,0,0
0,0,0,91,22,22,4,0,0,0,0,0,0,0,0,0,4,22,22,22,0,0,0
0,0,0,0,0,91,4,0,0,0,0,0,0,0,0,0,4,9,0,0,0,0,0
0,0,0,0,0,91,4,0,0,0,0,0,18,0,0,0,4,9,0,0,0,0,0
0,0,0,0,0,91,4,4,4,4,4,4,4,4,4,4,4,9,0,0,0,0,0
0,0,0,0,0,91,22,22,22,22,91,4,9,22,22,22,22,9,0,0,0,0,0
0,0,0,0,0,0,0,0,0,0,91,4,9,0,0,0,0,0,0,0,0,0,0
0,0,0,0,0,0,0,0,0,0,91,22,22,0,0,0,0,0,0,0,0,0,0
0,0,0,0,0,0,0,0,0,0,0,0,0,0,0,0,0,0,0,0,0,0,0
0,0,0,0,0,0,0,0,0,0,0,0,0,0,0,0,0,0,0,0,0,0,0
0,0,0,0,0,0,0,0,0,0,0,0,0,0,0,0,0,0,0,0,0,0,0
:endlayer
layer: 16
0,0,0,0,0,0,0,0,0,0,0,0,0,0,0,0,0,0,0,0,0,0,0
0,0,0,0,0,0,0,0,0,0,0,0,0,0,0,0,0,0,0,0,0,0,0
0,0,0,0,0,0,0,0,0,0,0,0,0,0,0,0,0,0,0,0,0,0,0
0,0,0,0,0,0,0,0,0,0,0,0,0,0,0,0,0,0,0,0,0,0,0
0,0,0,0,0,0,0,0,0,0,0,0,0,0,0,0,0,0,0,0,0,0,0
0,0,0,0,0,0,0,0,0,0,0,0,0,0,0,0,0,0,0,0,0,0,0
0,0,0,0,0,0,74,74,74,74,74,74,74,74,74,74,9,0,0,0,0,0,0
0,0,0,0,0,0,91,4,4,4,4,4,4,4,4,4,9,0,0,0,0,0,0
0,0,0,0,0,0,91,4,4,4,4,4,4,4,4,4,9,0,0,0,0,0,0
0,0,0,0,0,0,91,4,4,4,4,4,4,4,4,4,9,0,0,0,0,0,0
0,0,0,0,77,77,91,4,4,4,4,4,4,4,4,4,9,77,77,0,0,0,0
0,0,0,0,0,0,91,4,4,4,4,4,4,4,4,4,9,0,0,0,0,0,0
0,0,0,0,0,0,91,4,4,4,4,4,4,4,4,4,9,0,0,0,0,0,0
0,0,0,0,0,0,91,4,4,4,4,4,4,4,4,4,9,0,0,0,0,0,0
0,0,0,0,0,0,91,22,22,22,22,22,22,22,22,22,22,0,0,0,0,0,0
0,0,0,0,0,0,0,0,0,0,0,77,0,0,0,0,0,0,0,0,0,0,0
0,0,0,0,0,0,0,0,0,0,0,77,0,0,0,0,0,0,0,0,0,0,0
0,0,0,0,0,0,0,0,0,0,0,0,0,0,0,0,0,0,0,0,0,0,0
0,0,0,0,0,0,0,0,0,0,0,0,0,0,0,0,0,0,0,0,0,0,0
0,0,0,0,0,0,0,0,0,0,0,0,0,0,0,0,0,0,0,0,0,0,0
0,0,0,0,0,0,0,0,0,0,0,0,0,0,0,0,0,0,0,0,0,0,0
:endlayer
layer: 17
0,0,0,0,0,0,0,0,0,0,0,0,0,0,0,0,0,0,0,0,0,0,0
0,0,0,0,0,0,0,0,0,0,0,0,0,0,0,0,0,0,0,0,0,0,0
0,0,0,0,0,0,0,0,0,0,0,0,0,0,0,0,0,0,0,0,0,0,0
0,0,0,0,0,0,0,0,0,0,0,0,0,0,0,0,0,0,0,0,0,0,0
0,0,0,0,0,0,0,0,0,0,0,0,0,0,0,0,0,0,0,0,0,0,0
0,0,0,0,0,0,0,0,0,0,0,0,0,0,0,0,0,0,0,0,0,0,0
0,0,0,0,0,0,0,0,0,0,0,0,0,0,0,0,0,0,0,0,0,0,0
0,0,0,0,0,0,0,21,0,0,0,21,0,0,0,21,0,0,0,0,0,0,0
0,0,0,0,0,0,0,0,0,0,0,0,0,0,0,0,0,0,0,0,0,0,0
0,0,0,0,0,0,0,0,0,0,0,0,0,0,0,0,0,0,0,0,0,0,0
0,0,0,0,0,0,0,21,0,0,0,21,0,0,0,21,0,0,0,0,0,0,0
0,0,0,0,0,0,0,0,0,0,0,0,0,0,0,0,0,0,0,0,0,0,0
0,0,0,0,0,0,0,0,0,0,0,0,0,0,0,0,0,0,0,0,0,0,0
0,0,0,0,0,0,0,21,0,0,0,21,0,0,0,21,0,0,0,0,0,0,0
0,0,0,0,0,0,0,0,0,0,0,0,0,0,0,0,0,0,0,0,0,0,0
0,0,0,0,0,0,0,0,0,0,0,0,0,0,0,0,0,0,0,0,0,0,0
0,0,0,0,0,0,0,0,0,0,0,0,0,0,0,0,0,0,0,0,0,0,0
0,0,0,0,0,0,0,0,0,0,0,0,0,0,0,0,0,0,0,0,0,0,0
0,0,0,0,0,0,0,0,0,0,0,0,0,0,0,0,0,0,0,0,0,0,0
0,0,0,0,0,0,0,0,0,0,0,0,0,0,0,0,0,0,0,0,0,0,0
0,0,0,0,0,0,0,0,0,0,0,0,0,0,0,0,0,0,0,0,0,0,0
:endlayer

#### RULES ####
rule:
plugin=vanillaBlocks
number=1
data:
JSON:{buildPass:0,blockName:"minecraft:grass",meta:0}
:enddata
:endrule

rule:
plugin=vanillaBlocks
number=2
data:
JSON:{buildPass:0,blockName:"minecraft:dirt",meta:0}
:enddata
:endrule

rule:
plugin=vanillaBlocks
number=3
data:
JSON:{buildPass:0,blockName:"minecraft:sandstone",meta:2}
:enddata
:endrule

rule:
plugin=vanillaBlocks
number=4
data:
JSON:{buildPass:0,blockName:"minecraft:planks",meta:0}
:enddata
:endrule

rule:
plugin=vanillaBlocks
number=5
data:
JSON:{buildPass:0,blockName:"minecraft:gravel",meta:0}
:enddata
:endrule

rule:
plugin=vanillaBlocks
number=6
data:
JSON:{buildPass:0,blockName:"minecraft:stonebrick",meta:0}
:enddata
:endrule

rule:
plugin=vanillaBlocks
number=7
data:
JSON:{buildPass:0,blockName:"minecraft:stone_slab",meta:15}
:enddata
:endrule

rule:
plugin=vanillaInventory
number=8
data:
JSON:{buildPass:0,blockName:"minecraft:chest",meta:5,lootLevel:1,teData:{x:30,y:83,z:-23,id:"Chest"},inventoryData:{length:27,inventoryContents:[]}}
:enddata
:endrule

rule:
plugin=vanillaBlocks
number=9
data:
JSON:{buildPass:0,blockName:"minecraft:oak_stairs",meta:1}
:enddata
:endrule

rule:
plugin=vanillaBlocks
number=10
data:
JSON:{buildPass:2,blockName:"minecraft:trapdoor",meta:14}
:enddata
:endrule

rule:
plugin=vanillaBlocks
number=11
data:
JSON:{buildPass:2,blockName:"minecraft:trapdoor",meta:15}
:enddata
:endrule

rule:
plugin=vanillaBlocks
number=12
data:
JSON:{buildPass:0,blockName:"minecraft:bookshelf",meta:0}
:enddata
:endrule

rule:
plugin=vanillaBlocks
number=13
data:
JSON:{buildPass:0,blockName:"minecraft:spruce_stairs",meta:3}
:enddata
:endrule

rule:
plugin=vanillaInventory
number=14
data:
JSON:{buildPass:0,blockName:"minecraft:chest",meta:5,lootLevel:1,teData:{x:30,y:83,z:-22,id:"Chest"},inventoryData:{length:27,inventoryContents:[]}}
:enddata
:endrule

rule:
plugin=vanillaBlocks
number=15
data:
JSON:{buildPass:2,blockName:"minecraft:trapdoor",meta:13}
:enddata
:endrule

rule:
plugin=vanillaBlocks
number=16
data:
JSON:{buildPass:2,blockName:"minecraft:trapdoor",meta:12}
:enddata
:endrule

rule:
plugin=vanillaBlocks
number=17
data:
JSON:{buildPass:0,blockName:"minecraft:spruce_stairs",meta:1}
:enddata
:endrule

rule:
plugin=vanillaBlocks
number=18
data:
JSON:{buildPass:0,blockName:"minecraft:fence",meta:0}
:enddata
:endrule

rule:
plugin=vanillaBlocks
number=19
data:
JSON:{buildPass:0,blockName:"minecraft:spruce_stairs",meta:0}
:enddata
:endrule

rule:
plugin=awAutomationLogic
number=20
data:
JSON:{buildPass:0,blockName:"minecraft:furnace",meta:4,teData:{CookTime:0s,BurnTime:0s,x:28,y:83,Items:[],z:-21,id:"Furnace"}}
:enddata
:endrule

rule:
plugin=vanillaBlocks
number=21
data:
JSON:{buildPass:2,blockName:"minecraft:torch",meta:5}
:enddata
:endrule

rule:
plugin=vanillaBlocks
number=22
data:
JSON:{buildPass:0,blockName:"minecraft:oak_stairs",meta:3}
:enddata
:endrule

rule:
plugin=awAutomationLogic
number=23
data:
JSON:{buildPass:0,blockName:"minecraft:furnace",meta:4,teData:{CookTime:0s,BurnTime:0s,x:28,y:83,Items:[],z:-20,id:"Furnace"}}
:enddata
:endrule

rule:
plugin=vanillaInventory
number=24
data:
JSON:{buildPass:0,blockName:"minecraft:chest",meta:5,lootLevel:1,teData:{x:30,y:83,z:-20,id:"Chest"},inventoryData:{length:27,inventoryContents:[]}}
:enddata
:endrule

rule:
plugin=vanillaBlocks
number=25
data:
JSON:{buildPass:0,blockName:"minecraft:crafting_table",meta:0}
:enddata
:endrule

rule:
plugin=vanillaInventory
number=26
data:
JSON:{buildPass:0,blockName:"minecraft:chest",meta:5,lootLevel:1,teData:{x:30,y:83,z:-19,id:"Chest"},inventoryData:{length:27,inventoryContents:[]}}
:enddata
:endrule

rule:
plugin=vanillaDoors
number=27
data:
JSON:{buildPass:2,blockName:"minecraft:wooden_door",meta:2,sideFlag:8b}
:enddata
:endrule

rule:
plugin=vanillaBlocks
number=28
data:
JSON:{buildPass:2,blockName:"minecraft:brown_mushroom",meta:0}
:enddata
:endrule

rule:
plugin=vanillaBlocks
number=29
data:
JSON:{buildPass:0,blockName:"minecraft:spruce_stairs",meta:2}
:enddata
:endrule

rule:
plugin=vanillaBlocks
number=30
data:
JSON:{buildPass:0,blockName:"minecraft:log",meta:0}
:enddata
:endrule

rule:
plugin=vanillaBlocks
number=31
data:
JSON:{buildPass:0,blockName:"minecraft:cauldron",meta:0}
:enddata
:endrule

rule:
plugin=vanillaBlocks
number=32
data:
JSON:{buildPass:0,blockName:"minecraft:birch_stairs",meta:1}
:enddata
:endrule

rule:
plugin=vanillaBlocks
number=33
data:
JSON:{buildPass:0,blockName:"minecraft:birch_stairs",meta:3}
:enddata
:endrule

rule:
plugin=vanillaBlocks
number=34
data:
JSON:{buildPass:0,blockName:"minecraft:birch_stairs",meta:0}
:enddata
:endrule

rule:
plugin=vanillaBlocks
number=35
data:
JSON:{buildPass:2,blockName:"minecraft:carpet",meta:13}
:enddata
:endrule

rule:
plugin=vanillaBlocks
number=36
data:
JSON:{buildPass:2,blockName:"minecraft:carpet",meta:3}
:enddata
:endrule

rule:
plugin=vanillaBlocks
number=37
data:
JSON:{buildPass:0,blockName:"minecraft:birch_stairs",meta:2}
:enddata
:endrule

rule:
plugin=vanillaDoors
number=38
data:
JSON:{buildPass:2,blockName:"minecraft:wooden_door",meta:3,sideFlag:8b}
:enddata
:endrule

rule:
plugin=vanillaBlocks
number=39
data:
JSON:{buildPass:0,blockName:"minecraft:stained_glass_pane",meta:0}
:enddata
:endrule

rule:
plugin=vanillaFlowerPot
number=40
data:
JSON:{itemName:"minecraft:red_flower",buildPass:0,itemMeta:3,blockName:"minecraft:flower_pot",meta:3}
:enddata
:endrule

rule:
plugin=vanillaBlocks
number=41
data:
JSON:{buildPass:0,blockName:"minecraft:oak_stairs",meta:4}
:enddata
:endrule

rule:
plugin=vanillaBlocks
number=42
data:
JSON:{buildPass:0,blockName:"minecraft:sapling",meta:1}
:enddata
:endrule

rule:
plugin=vanillaBlocks
number=43
data:
JSON:{buildPass:0,blockName:"minecraft:sapling",meta:8}
:enddata
:endrule

rule:
plugin=vanillaBlocks
number=44
data:
JSON:{buildPass:2,blockName:"minecraft:carpet",meta:8}
:enddata
:endrule

rule:
plugin=vanillaBlocks
number=45
data:
JSON:{buildPass:0,blockName:"minecraft:sapling",meta:11}
:enddata
:endrule

rule:
plugin=vanillaInventory
number=46
data:
JSON:{buildPass:0,blockName:"minecraft:chest",meta:5,lootLevel:1,teData:{x:30,y:84,z:-20,id:"Chest"},inventoryData:{length:27,inventoryContents:[]}}
:enddata
:endrule

rule:
plugin=vanillaBlocks
number=47
data:
JSON:{buildPass:2,blockName:"minecraft:red_mushroom",meta:0}
:enddata
:endrule

rule:
plugin=vanillaBlocks
number=48
data:
JSON:{buildPass:0,blockName:"minecraft:sapling",meta:4}
:enddata
:endrule

rule:
plugin=vanillaInventory
number=49
data:
JSON:{buildPass:0,blockName:"minecraft:chest",meta:5,lootLevel:1,teData:{x:30,y:84,z:-19,id:"Chest"},inventoryData:{length:27,inventoryContents:[]}}
:enddata
:endrule

rule:
plugin=vanillaDoors
number=50
data:
JSON:{buildPass:2,blockName:"minecraft:wooden_door",meta:8,sideFlag:0b}
:enddata
:endrule

rule:
plugin=vanillaBlocks
number=51
data:
JSON:{buildPass:2,blockName:"minecraft:red_flower",meta:1}
:enddata
:endrule

rule:
plugin=vanillaBlocks
number=52
data:
JSON:{buildPass:0,blockName:"minecraft:sapling",meta:10}
:enddata
:endrule

rule:
plugin=vanillaBlocks
number=53
data:
JSON:{buildPass:0,blockName:"minecraft:sapling",meta:13}
:enddata
:endrule

rule:
plugin=vanillaFlowerPot
number=54
data:
JSON:{itemName:"minecraft:sapling",buildPass:0,itemMeta:2,blockName:"minecraft:flower_pot",meta:2}
:enddata
:endrule

rule:
plugin=vanillaBlocks
number=55
data:
JSON:{buildPass:2,blockName:"minecraft:carpet",meta:11}
:enddata
:endrule

rule:
plugin=vanillaDoors
number=56
data:
JSON:{buildPass:2,blockName:"minecraft:wooden_door",meta:8,sideFlag:0b}
:enddata
:endrule

rule:
plugin=vanillaFlowerPot
number=57
data:
JSON:{itemName:"minecraft:red_flower",buildPass:0,itemMeta:0,blockName:"minecraft:flower_pot",meta:0}
:enddata
:endrule

rule:
plugin=vanillaFlowerPot
number=58
data:
JSON:{itemName:"minecraft:sapling",buildPass:0,itemMeta:3,blockName:"minecraft:flower_pot",meta:3}
:enddata
:endrule

rule:
plugin=vanillaBlocks
number=59
data:
JSON:{buildPass:2,blockName:"minecraft:torch",meta:4}
:enddata
:endrule

rule:
plugin=vanillaBlocks
number=60
data:
JSON:{buildPass:2,blockName:"minecraft:torch",meta:2}
:enddata
:endrule

rule:
plugin=vanillaBlocks
number=61
data:
JSON:{buildPass:2,blockName:"minecraft:torch",meta:1}
:enddata
:endrule

rule:
plugin=vanillaBlocks
number=62
data:
JSON:{buildPass:2,blockName:"minecraft:torch",meta:3}
:enddata
:endrule

rule:
plugin=vanillaInventory
number=63
data:
JSON:{buildPass:0,blockName:"minecraft:chest",meta:5,lootLevel:1,teData:{x:30,y:85,z:-20,id:"Chest"},inventoryData:{length:27,inventoryContents:[]}}
:enddata
:endrule

rule:
plugin=vanillaInventory
number=64
data:
JSON:{buildPass:0,blockName:"minecraft:chest",meta:5,lootLevel:1,teData:{x:30,y:85,z:-19,id:"Chest"},inventoryData:{length:27,inventoryContents:[]}}
:enddata
:endrule

rule:
plugin=vanillaBlocks
number=65
data:
JSON:{buildPass:0,blockName:"minecraft:stone_brick_stairs",meta:7}
:enddata
:endrule

rule:
plugin=vanillaBlocks
number=66
data:
JSON:{buildPass:0,blockName:"minecraft:stone_slab",meta:13}
:enddata
:endrule

rule:
plugin=vanillaBlocks
number=67
data:
JSON:{buildPass:0,blockName:"minecraft:log",meta:8}
:enddata
:endrule

rule:
plugin=vanillaBlocks
number=68
data:
JSON:{buildPass:0,blockName:"minecraft:log",meta:4}
:enddata
:endrule

rule:
plugin=vanillaBlocks
number=69
data:
JSON:{buildPass:0,blockName:"minecraft:stone_brick_stairs",meta:5}
:enddata
:endrule

rule:
plugin=vanillaBlocks
number=70
data:
JSON:{buildPass:0,blockName:"minecraft:stone_brick_stairs",meta:4}
:enddata
:endrule

rule:
plugin=vanillaBlocks
number=71
data:
JSON:{buildPass:0,blockName:"minecraft:cobblestone",meta:0}
:enddata
:endrule

rule:
plugin=vanillaInventory
number=72
data:
JSON:{buildPass:0,blockName:"minecraft:chest",meta:3,lootLevel:1,teData:{x:36,y:88,z:-23,id:"Chest"},inventoryData:{length:27,inventoryContents:[]}}
:enddata
:endrule

rule:
plugin=vanillaInventory
number=73
data:
JSON:{buildPass:0,blockName:"minecraft:chest",meta:3,lootLevel:1,teData:{x:37,y:88,z:-23,id:"Chest"},inventoryData:{length:27,inventoryContents:[]}}
:enddata
:endrule

rule:
plugin=vanillaBlocks
number=74
data:
JSON:{buildPass:0,blockName:"minecraft:oak_stairs",meta:2}
:enddata
:endrule

rule:
plugin=vanillaInventory
number=75
data:
JSON:{buildPass:0,blockName:"minecraft:chest",meta:4,lootLevel:1,teData:{x:37,y:88,z:-19,id:"Chest"},inventoryData:{length:27,inventoryContents:[]}}
:enddata
:endrule

rule:
plugin=vanillaBlocks
number=76
data:
JSON:{buildPass:2,blockName:"minecraft:carpet",meta:9}
:enddata
:endrule

rule:
plugin=vanillaBlocks
number=77
data:
JSON:{buildPass:0,blockName:"minecraft:wooden_slab",meta:0}
:enddata
:endrule

rule:
plugin=vanillaBlocks
number=78
data:
JSON:{buildPass:2,blockName:"minecraft:bed",meta:3}
:enddata
:endrule

rule:
plugin=vanillaBlocks
number=79
data:
JSON:{buildPass:2,blockName:"minecraft:bed",meta:11}
:enddata
:endrule

rule:
plugin=vanillaBlocks
number=80
data:
JSON:{buildPass:0,blockName:"minecraft:wool",meta:0}
:enddata
:endrule

rule:
plugin=vanillaBlocks
number=81
data:
JSON:{buildPass:0,blockName:"minecraft:oak_stairs",meta:7}
:enddata
:endrule

rule:
plugin=vanillaInventory
number=82
data:
JSON:{buildPass:0,blockName:"minecraft:chest",meta:3,lootLevel:1,teData:{x:25,y:88,z:-15,id:"Chest"},inventoryData:{length:27,inventoryContents:[]}}
:enddata
:endrule

rule:
plugin=vanillaInventory
number=83
data:
JSON:{buildPass:0,blockName:"minecraft:chest",meta:3,lootLevel:1,teData:{x:26,y:88,z:-15,id:"Chest"},inventoryData:{length:27,inventoryContents:[]}}
:enddata
:endrule

rule:
plugin=vanillaInventory
number=84
data:
JSON:{buildPass:0,blockName:"minecraft:chest",meta:4,lootLevel:1,teData:{x:37,y:88,z:-14,id:"Chest"},inventoryData:{length:27,inventoryContents:[]}}
:enddata
:endrule

rule:
plugin=vanillaBlocks
number=85
data:
JSON:{buildPass:0,blockName:"minecraft:cobblestone_wall",meta:0}
:enddata
:endrule

rule:
plugin=vanillaFlowerPot
number=86
data:
JSON:{itemName:"minecraft:red_flower",buildPass:0,itemMeta:4,blockName:"minecraft:flower_pot",meta:4}
:enddata
:endrule

rule:
plugin=vanillaFlowerPot
number=87
data:
JSON:{itemName:"minecraft:red_flower",buildPass:0,itemMeta:8,blockName:"minecraft:flower_pot",meta:8}
:enddata
:endrule

rule:
plugin=vanillaDoors
number=88
data:
JSON:{buildPass:2,blockName:"minecraft:wooden_door",meta:8,sideFlag:0b}
:enddata
:endrule

rule:
plugin=vanillaBlocks
number=89
data:
JSON:{buildPass:0,blockName:"minecraft:glowstone",meta:0}
:enddata
:endrule

rule:
plugin=vanillaBlocks
number=90
data:
JSON:{buildPass:0,blockName:"minecraft:wool",meta:11}
:enddata
:endrule

rule:
plugin=vanillaBlocks
number=91
data:
JSON:{buildPass:0,blockName:"minecraft:oak_stairs",meta:0}
:enddata
:endrule

rule:
plugin=vanillaInventory
number=92
data:
JSON:{buildPass:0,blockName:"minecraft:chest",meta:3,lootLevel:1,teData:{x:26,y:93,z:-21,id:"Chest"},inventoryData:{length:27,inventoryContents:[]}}
:enddata
:endrule

rule:
plugin=vanillaInventory
number=93
data:
JSON:{buildPass:0,blockName:"minecraft:chest",meta:3,lootLevel:1,teData:{x:27,y:93,z:-21,id:"Chest"},inventoryData:{length:27,inventoryContents:[]}}
:enddata
:endrule

rule:
plugin=vanillaBlocks
number=94
data:
JSON:{buildPass:0,blockName:"minecraft:spruce_stairs",meta:7}
:enddata
:endrule

rule:
plugin=vanillaInventory
number=95
data:
JSON:{buildPass:0,blockName:"minecraft:chest",meta:3,lootLevel:1,teData:{x:33,y:93,z:-21,id:"Chest"},inventoryData:{length:27,inventoryContents:[]}}
:enddata
:endrule

rule:
plugin=vanillaBlocks
number=96
data:
JSON:{buildPass:0,blockName:"minecraft:spruce_stairs",meta:4}
:enddata
:endrule

rule:
plugin=vanillaBlocks
number=97
data:
JSON:{buildPass:0,blockName:"minecraft:spruce_stairs",meta:6}
:enddata
:endrule

rule:
plugin=vanillaBlocks
number=98
data:
JSON:{buildPass:0,blockName:"minecraft:spruce_stairs",meta:5}
:enddata
:endrule

rule:
plugin=awAutomationLogic
number=99
data:
JSON:{buildPass:0,blockName:"minecraft:furnace",meta:4,teData:{CookTime:0s,BurnTime:0s,x:38,y:93,Items:[],z:-18,id:"Furnace"}}
:enddata
:endrule

rule:
plugin=vanillaInventory
number=100
data:
JSON:{buildPass:0,blockName:"minecraft:chest",meta:4,lootLevel:1,teData:{x:38,y:93,z:-12,id:"Chest"},inventoryData:{length:27,inventoryContents:[]}}
:enddata
:endrule

rule:
plugin=vanillaInventory
number=101
data:
JSON:{buildPass:0,blockName:"minecraft:chest",meta:2,lootLevel:1,teData:{x:34,y:93,z:-9,id:"Chest"},inventoryData:{length:27,inventoryContents:[]}}
:enddata
:endrule

rule:
plugin=vanillaBlocks
number=102
data:
JSON:{buildPass:2,blockName:"minecraft:carpet",meta:14}
:enddata
:endrule

rule:
plugin=vanillaBlocks
number=103
data:
JSON:{buildPass:2,blockName:"minecraft:carpet",meta:15}
:enddata
:endrule

rule:
plugin=vanillaBlocks
number=104
data:
JSON:{buildPass:2,blockName:"minecraft:carpet",meta:0}
:enddata
:endrule

rule:
plugin=vanillaInventory
number=105
data:
JSON:{buildPass:0,blockName:"minecraft:chest",meta:2,lootLevel:1,teData:{x:30,y:94,z:-13,id:"Chest"},inventoryData:{length:27,inventoryContents:[]}}
:enddata
:endrule

rule:
plugin=vanillaBlocks
number=106
data:
JSON:{buildPass:2,blockName:"minecraft:carpet",meta:1}
:enddata
:endrule

rule:
plugin=vanillaBlocks
number=107
data:
JSON:{buildPass:0,blockName:"minecraft:oak_stairs",meta:5}
:enddata
:endrule

rule:
plugin=vanillaBlocks
number=108
data:
JSON:{buildPass:0,blockName:"minecraft:oak_stairs",meta:6}
:enddata
:endrule

#### ENTITIES ####
entity:
plugin=vanillaHangingEntity
number=0
data:
position=8,3,6
JSON:{xOffset:0.9375f,rotation:90.0f,mobID:"minecraft:painting",zOffset:-0.0f,entityData:{Motion:[0.0d,0.0d,0.0d],Invulnerable:0b,OnGround:0b,Dimension:0,Air:300s,Dir:1b,PortalCooldown:0,Direction:1b,Rotation:[90.0f,0.0f],Motive:"Sunset",FallDistance:0.0f,Pos:[28.9375d,85.5d,-19.0d],Fire:0s,TileY:85,TileX:29,TileZ:-20},direction:1b}
:enddata
:endentity

entity:
plugin=vanillaHangingEntity
number=1
data:
position=5,4,9
JSON:{xOffset:0.0f,rotation:0.0f,mobID:"minecraft:painting",zOffset:0.9375f,entityData:{Motion:[0.0d,0.0d,0.0d],Invulnerable:0b,OnGround:0b,Dimension:0,Air:300s,Dir:0b,PortalCooldown:0,Direction:2b,Rotation:[0.0f,0.0f],Motive:"Bust",FallDistance:0.0f,Pos:[25.0d,86.0d,-15.0625d],Fire:0s,TileY:85,TileX:25,TileZ:-15},direction:2b}
:enddata
:endentity

entity:
plugin=vanillaHangingEntity
number=2
data:
position=17,8,9
JSON:{xOffset:0.9375f,rotation:90.0f,mobID:"minecraft:painting",zOffset:-0.0f,entityData:{Motion:[0.0d,0.0d,0.0d],Invulnerable:0b,OnGround:0b,Dimension:0,Air:300s,Dir:1b,PortalCooldown:0,Direction:1b,Rotation:[90.0f,0.0f],Motive:"Match",FallDistance:0.0f,Pos:[37.9375d,90.0d,-16.0d],Fire:0s,TileY:89,TileX:38,TileZ:-17},direction:1b}
:enddata
:endentity

