# Ancient Warfare Structure Template File
# Auto-generated structure template file. created on: 9/22/2018 at: 16:7:2
# Lines beginning with # denote comments

header:
version=2.6
name=unique_mayoral_manor_dulciphi
size=22,14,27
offset=10,1,26
:endheader

#### VALIDATION ####
validation:
type=ground
survival=false
worldGenEnabled=false
unique=false
preserveBlocks=false
selectionWeight=0
clusterValue=0
minDuplicateDistance=0
dimensionWhiteList=false
dimensionList=
biomeWhiteList=false
biomeList=
leveling=0
fill=0
border=0
blockSwap=false
data:
:enddata
:endvalidation

#### LAYERS ####
layer: 0
1,1,1,1,1,1,1,1,1,1,1,1,1,1,1,1,1,1,1,1,1,1
1,1,1,1,1,1,1,1,1,1,1,1,1,1,1,1,1,1,1,1,1,1
1,2,1,2,1,1,2,2,2,2,2,2,2,2,2,2,1,2,1,1,1,1
1,1,1,2,2,2,2,2,2,2,2,2,2,2,2,2,2,2,2,1,1,1
1,2,1,2,2,2,2,2,2,2,2,2,2,2,2,2,2,2,2,1,1,1
1,2,2,2,2,2,2,2,2,2,2,2,2,2,2,2,2,2,2,1,1,1
1,1,2,2,2,2,2,2,2,2,2,2,2,2,2,2,2,2,2,2,2,1
1,1,2,2,2,2,2,2,2,2,2,2,2,2,2,2,2,2,2,2,1,1
1,1,1,2,2,2,2,2,2,2,2,2,2,2,2,2,2,2,2,1,1,1
1,1,2,2,2,2,2,2,2,2,2,2,2,2,2,2,2,2,2,2,1,1
1,1,2,2,2,2,2,2,2,2,2,2,2,2,2,2,2,2,2,2,1,1
1,1,2,2,2,2,2,2,2,2,2,2,2,2,2,2,2,2,2,1,1,1
1,1,2,2,2,2,2,2,2,2,2,2,2,2,2,2,2,2,2,2,1,1
1,1,2,2,2,2,2,2,2,2,2,2,2,2,2,2,2,2,2,2,2,1
1,1,2,2,2,2,2,2,2,2,2,2,2,2,2,2,2,2,2,2,2,1
1,1,2,2,2,2,2,2,2,2,2,2,2,2,2,2,2,2,2,2,2,1
1,1,2,2,2,2,2,2,2,2,2,2,2,2,2,2,2,2,2,1,2,1
1,1,2,2,2,2,2,2,2,2,2,2,2,2,2,2,2,2,2,1,1,1
1,2,2,2,2,2,2,2,2,2,2,2,2,2,2,2,2,2,2,1,1,1
1,2,1,1,1,1,1,1,1,2,2,2,2,1,1,2,1,1,1,1,1,1
1,2,1,1,1,1,1,1,1,2,2,2,2,1,1,1,1,1,1,1,1,1
1,1,1,1,1,1,1,1,1,1,1,1,1,1,1,1,1,1,1,1,1,1
1,1,1,1,1,3,3,3,1,1,1,1,1,1,1,1,1,1,1,1,1,1
1,1,1,1,3,3,3,3,3,1,1,1,1,1,1,1,1,1,1,1,1,1
1,1,1,1,3,3,4,3,3,1,1,1,1,1,1,1,1,1,1,1,1,1
1,1,1,1,3,3,3,3,3,1,1,1,1,1,1,1,1,1,1,1,1,1
1,1,1,1,1,1,1,1,1,1,1,1,1,1,1,1,1,1,1,1,1,1
:endlayer
layer: 1
5,5,5,5,5,5,5,5,5,5,0,0,5,5,5,5,5,5,5,5,5,5
6,7,7,7,7,7,7,7,7,7,7,7,7,7,7,7,7,7,7,7,7,6
6,7,7,7,7,7,7,7,7,7,7,7,7,7,7,7,7,7,7,7,7,6
6,7,7,8,9,9,9,9,9,9,8,8,9,9,9,9,9,9,8,7,7,6
6,7,7,9,10,10,10,10,10,10,10,10,10,10,10,10,10,10,9,7,7,6
6,7,7,9,10,10,10,10,10,10,10,10,10,10,10,10,10,10,9,7,7,6
6,7,7,9,10,10,10,10,10,10,10,10,10,10,10,10,10,10,9,7,7,6
6,7,7,9,10,10,10,10,10,10,10,10,10,10,10,10,10,10,9,7,7,6
6,7,7,9,10,10,10,10,10,10,10,10,10,10,10,10,10,10,9,7,7,6
5,7,7,9,10,10,10,10,10,10,10,10,10,10,10,10,10,10,9,7,7,6
0,7,7,8,10,10,10,10,10,10,10,10,10,10,10,10,10,10,8,7,7,6
0,7,7,8,10,10,10,10,10,10,10,10,10,10,10,10,10,10,8,7,7,6
5,7,7,9,10,10,10,10,10,10,10,10,10,10,10,10,10,10,9,7,7,6
6,7,7,9,10,10,10,10,10,10,10,10,10,10,10,10,10,10,9,7,7,6
6,7,7,9,10,10,10,10,10,10,10,10,10,10,10,10,10,10,9,7,7,6
6,7,7,9,10,10,10,10,10,10,10,10,10,10,10,10,10,10,9,7,7,6
6,7,7,9,10,10,10,10,10,10,10,10,10,10,10,10,10,10,9,7,7,6
6,7,7,9,10,10,10,10,10,10,10,10,10,10,10,10,10,10,9,7,7,6
6,7,7,8,9,9,9,9,9,9,8,8,9,9,9,9,9,9,8,7,7,6
6,7,7,7,7,7,7,7,7,8,8,8,8,7,7,7,7,7,7,7,7,6
6,7,7,7,7,7,7,7,7,8,11,11,8,7,7,7,7,7,7,7,7,6
6,0,12,13,12,13,12,13,14,15,0,0,15,14,13,12,13,12,13,12,0,6
6,0,0,0,0,0,0,0,0,0,0,0,0,0,0,0,0,0,0,0,0,6
6,0,0,0,16,0,17,16,0,5,0,0,5,0,0,0,0,0,0,0,0,6
18,0,0,0,0,17,5,17,0,5,0,0,5,0,0,0,0,0,0,0,0,6
18,0,0,0,0,16,17,0,0,5,0,0,5,0,0,0,0,0,0,0,0,6
5,5,5,5,5,5,5,5,5,5,19,19,5,5,5,5,5,5,5,5,5,5
:endlayer
layer: 2
20,0,0,20,0,0,20,0,0,20,0,0,20,0,0,20,0,0,20,0,0,20
6,0,0,0,0,0,0,0,0,0,0,0,0,0,0,0,0,0,0,0,0,6
6,0,0,0,0,0,0,0,0,0,0,0,0,0,0,0,0,0,0,0,0,6
6,0,21,8,8,22,22,8,22,9,23,24,9,9,8,9,9,8,8,25,0,6
6,0,0,8,26,0,0,0,0,27,0,0,0,0,27,28,29,27,8,0,0,6
6,0,0,22,0,0,0,0,0,27,0,0,0,0,0,0,0,30,9,0,0,6
6,0,0,22,0,0,0,0,0,31,0,0,0,0,0,0,0,30,9,0,0,6
6,0,0,8,0,0,0,0,0,27,0,0,0,0,0,0,0,32,8,0,0,6
6,0,0,9,0,33,33,0,26,27,0,0,0,0,0,0,0,27,9,0,0,6
20,0,0,9,26,34,34,26,35,27,0,0,0,36,37,27,27,38,9,0,0,6
0,0,0,8,27,27,27,27,27,27,0,0,27,27,27,27,27,27,8,0,0,6
0,0,0,8,39,0,0,0,40,0,0,0,0,0,0,0,0,0,8,0,0,6
20,0,0,9,39,39,39,39,40,0,0,0,0,40,41,41,42,0,9,0,0,6
6,0,0,9,0,0,0,0,0,0,0,0,0,0,0,0,0,0,22,0,0,6
6,0,0,8,0,0,27,0,43,0,0,0,0,0,44,44,0,0,8,0,0,6
6,0,0,22,45,0,30,0,46,0,0,0,0,0,0,0,0,0,22,0,0,6
6,0,0,22,0,0,27,0,47,0,0,0,0,40,48,48,42,0,22,0,0,6
6,0,0,8,0,0,0,0,0,0,0,0,0,0,0,0,0,0,8,0,0,18
6,0,21,8,8,22,22,8,22,9,49,50,9,22,8,22,22,8,8,25,0,18
6,0,0,51,0,0,0,0,0,0,0,0,0,0,0,0,0,0,51,0,0,6
6,0,0,0,0,0,0,0,0,5,0,0,5,0,0,0,0,0,0,0,0,6
6,0,0,0,0,0,0,0,52,52,0,0,52,52,0,0,0,0,0,0,0,6
6,0,0,0,0,0,0,0,0,0,0,0,0,0,0,0,0,0,0,0,0,6
6,0,0,0,0,0,53,0,0,20,0,0,20,0,0,0,0,0,0,0,0,6
18,0,0,0,0,53,3,53,0,0,0,0,0,0,0,0,0,0,0,0,0,6
6,0,0,0,0,0,53,0,0,0,0,0,0,0,0,0,0,0,0,0,0,6
20,0,0,0,0,0,0,0,0,20,0,0,20,0,0,20,0,0,20,0,0,20
:endlayer
layer: 3
0,0,0,0,0,0,0,0,0,0,0,0,0,0,0,0,0,0,0,0,0,0
0,0,0,0,0,0,0,0,0,0,0,0,0,0,0,0,0,0,0,0,0,0
0,0,0,0,0,0,0,0,0,0,0,0,0,0,0,0,0,0,0,0,0,0
0,0,0,8,8,22,22,8,22,9,54,55,9,22,8,22,22,8,8,0,0,0
0,0,0,8,56,0,0,0,0,27,0,0,0,0,51,0,0,0,8,0,0,0
0,0,0,22,0,0,0,0,21,27,0,0,0,0,0,0,0,0,22,0,0,0
0,0,0,22,0,0,0,0,0,57,0,0,0,0,0,0,0,0,22,0,0,0
0,0,0,8,0,0,0,0,21,27,0,0,0,0,0,0,0,0,8,0,0,0
0,0,0,22,0,0,0,0,58,27,0,0,0,0,0,0,0,0,22,0,0,0
0,0,0,9,58,0,0,58,58,27,0,0,59,60,37,0,58,58,9,0,0,0
0,0,0,8,27,27,27,27,27,27,0,0,27,27,27,27,27,27,8,0,0,0
0,0,0,8,39,0,0,40,0,51,0,0,51,0,0,0,0,0,8,0,0,0
0,0,0,9,39,39,39,40,0,0,0,0,0,0,0,0,0,0,9,0,0,0
0,0,0,22,0,0,0,0,0,0,0,0,0,0,0,0,0,0,22,0,0,0
0,0,0,8,0,0,0,0,0,0,0,0,0,0,0,0,0,21,8,0,0,0
0,0,0,22,0,0,0,0,0,0,0,0,0,0,0,0,0,0,22,0,0,0
0,0,0,22,0,0,0,0,0,0,0,0,0,0,0,0,0,0,22,0,0,0
0,0,0,8,59,0,0,0,0,0,0,0,59,0,0,0,0,0,8,0,0,0
0,0,0,8,8,22,22,8,22,9,61,62,9,22,8,22,22,8,8,0,0,0
0,0,0,0,0,0,0,0,0,0,0,0,0,0,0,0,0,0,0,0,0,0
0,0,0,0,0,0,0,0,0,5,0,0,5,0,0,0,0,0,0,0,0,0
0,0,0,0,0,0,0,0,0,0,0,0,0,0,0,0,0,0,0,0,0,0
0,0,0,0,0,0,0,0,0,0,0,0,0,0,0,0,0,0,0,0,0,0
0,0,0,0,0,0,0,0,0,0,0,0,0,0,0,0,0,0,0,0,0,0
0,0,0,0,0,0,0,0,0,0,0,0,0,0,0,0,0,0,0,0,0,0
0,0,0,0,0,0,0,0,0,0,0,0,0,0,0,0,0,0,0,0,0,0
0,0,0,0,0,0,0,0,0,0,0,0,0,0,0,0,0,0,0,0,0,0
:endlayer
layer: 4
0,0,0,0,0,0,0,0,0,0,0,0,0,0,0,0,0,0,0,0,0,0
0,0,0,0,0,0,0,0,0,0,0,0,0,0,0,0,0,0,0,0,0,0
0,0,0,0,0,0,0,0,0,0,0,0,0,0,0,0,0,0,0,0,0,0
0,0,0,8,8,22,22,8,22,9,9,9,9,22,8,22,22,8,8,0,0,0
0,0,0,8,0,0,0,0,0,27,0,0,0,0,0,0,0,0,8,0,0,0
0,0,0,22,0,0,0,0,0,27,0,0,0,0,0,0,0,0,22,0,0,0
0,0,0,22,0,0,0,0,0,27,0,0,0,0,0,0,0,0,22,0,0,0
0,0,0,8,0,0,0,0,0,27,0,0,0,0,0,0,0,0,8,0,0,0
0,0,0,22,0,0,0,0,0,27,0,0,0,0,0,0,0,0,22,0,0,0
0,0,0,9,0,0,0,0,0,27,0,0,0,63,44,44,44,44,9,0,0,0
0,0,0,8,27,27,27,27,27,27,0,0,27,27,27,27,27,27,8,0,0,0
0,0,0,8,39,0,40,0,0,0,0,0,0,0,0,0,0,0,8,0,0,0
0,0,0,9,39,39,40,0,0,0,0,0,0,0,0,0,0,0,9,0,0,0
0,0,0,22,0,0,0,0,0,0,0,0,0,0,0,0,0,0,22,0,0,0
0,0,0,8,0,0,0,0,0,0,0,0,0,0,0,0,0,0,8,0,0,0
0,0,0,22,0,0,0,0,0,0,0,0,0,0,0,0,0,0,22,0,0,0
0,0,0,22,0,0,0,0,0,0,0,0,0,0,0,0,0,0,22,0,0,0
0,0,0,8,0,0,0,0,0,0,0,0,0,0,0,0,0,0,8,0,0,0
0,0,0,8,8,22,22,8,22,9,9,9,9,22,8,22,22,8,8,0,0,0
0,0,0,0,0,0,0,0,0,0,0,0,0,0,0,0,0,0,0,0,0,0
0,0,0,0,0,0,0,0,0,5,0,0,5,0,0,0,0,0,0,0,0,0
0,0,0,0,0,0,0,0,0,0,0,0,0,0,0,0,0,0,0,0,0,0
0,0,0,0,0,0,0,0,0,0,0,0,0,0,0,0,0,0,0,0,0,0
0,0,0,0,0,0,0,0,0,0,0,0,0,0,0,0,0,0,0,0,0,0
0,0,0,0,0,0,0,0,0,0,0,0,0,0,0,0,0,0,0,0,0,0
0,0,0,0,0,0,0,0,0,0,0,0,0,0,0,0,0,0,0,0,0,0
0,0,0,0,0,0,0,0,0,0,0,0,0,0,0,0,0,0,0,0,0,0
:endlayer
layer: 5
0,0,0,0,0,0,0,0,0,0,0,0,0,0,0,0,0,0,0,0,0,0
0,0,0,0,0,0,0,0,0,0,0,0,0,0,0,0,0,0,0,0,0,0
0,0,0,0,0,0,0,0,0,0,0,0,0,0,0,0,0,0,0,0,0,0
0,0,0,8,8,9,9,8,9,9,9,9,9,9,8,9,9,8,8,0,0,0
0,0,0,8,0,0,0,0,0,27,0,0,0,0,64,64,64,65,8,0,0,0
0,0,0,9,0,0,0,0,0,27,0,0,0,0,0,0,0,64,9,0,0,0
0,0,0,9,0,0,0,0,0,27,0,0,0,0,0,0,0,64,9,0,0,0
0,0,0,8,0,0,0,0,0,27,0,0,0,0,0,0,0,64,8,0,0,0
0,0,0,9,0,0,0,0,0,27,0,0,0,0,0,0,0,64,9,0,0,0
0,0,0,9,0,0,0,0,0,27,0,0,0,0,64,64,64,64,9,0,0,0
0,0,0,8,27,27,27,27,27,27,27,27,27,27,27,27,27,27,8,0,0,0
0,0,0,8,39,40,0,0,0,0,0,0,0,0,0,0,0,0,8,0,0,0
0,0,0,9,39,40,0,0,0,0,0,0,0,0,0,0,0,0,9,0,0,0
0,0,0,9,0,0,0,0,0,0,0,0,0,0,0,0,0,0,9,0,0,0
0,0,0,8,0,0,0,0,0,0,0,0,0,0,0,0,0,0,8,0,0,0
0,0,0,9,0,0,0,0,0,0,0,0,0,0,0,0,0,0,9,0,0,0
0,0,0,9,0,0,0,0,0,0,0,0,0,0,0,0,0,0,9,0,0,0
0,0,0,8,0,0,0,0,0,0,0,0,0,0,0,0,0,0,8,0,0,0
0,0,0,8,8,9,9,8,9,9,9,9,9,9,8,9,9,8,8,0,0,0
0,0,0,0,0,0,0,0,0,8,65,65,8,0,0,0,0,0,0,0,0,0
0,0,0,0,0,0,0,0,0,8,66,66,8,0,0,0,0,0,0,0,0,0
0,0,0,0,0,0,0,0,0,0,0,0,0,0,0,0,0,0,0,0,0,0
0,0,0,0,0,0,0,0,0,0,0,0,0,0,0,0,0,0,0,0,0,0
0,0,0,0,0,0,0,0,0,0,0,0,0,0,0,0,0,0,0,0,0,0
0,0,0,0,0,0,0,0,0,0,0,0,0,0,0,0,0,0,0,0,0,0
0,0,0,0,0,0,0,0,0,0,0,0,0,0,0,0,0,0,0,0,0,0
0,0,0,0,0,0,0,0,0,0,0,0,0,0,0,0,0,0,0,0,0,0
:endlayer
layer: 6
0,0,0,0,0,0,0,0,0,0,0,0,0,0,0,0,0,0,0,0,0,0
0,42,48,48,48,48,48,48,48,48,48,48,48,48,48,48,48,48,48,48,40,0
0,42,67,67,67,67,67,67,67,67,67,67,67,67,67,67,67,67,67,67,40,0
0,42,67,67,39,39,39,39,39,39,39,39,39,67,67,67,67,67,67,67,40,0
0,42,67,67,65,39,39,39,39,39,39,39,39,39,39,39,39,65,67,67,40,0
0,42,67,67,39,39,39,39,39,39,39,39,39,39,39,39,39,39,67,67,40,0
0,42,67,67,39,39,39,39,39,39,39,39,39,65,39,39,39,39,67,67,40,0
0,42,67,67,39,39,39,39,39,39,39,39,39,65,39,39,39,65,68,67,40,0
0,42,67,67,39,39,39,39,39,39,39,39,39,39,39,39,39,39,67,67,40,0
0,42,67,67,39,39,39,39,39,39,39,39,39,39,39,39,39,39,67,67,40,0
0,42,67,39,41,41,39,39,39,39,39,39,39,39,39,39,39,39,67,67,40,0
0,42,67,39,40,0,0,0,39,39,39,39,39,39,39,39,39,65,69,67,40,0
0,42,67,39,40,0,0,0,39,39,39,39,39,39,39,39,39,39,67,67,40,0
0,42,67,39,39,39,39,39,39,39,39,39,39,39,39,39,39,39,67,67,40,0
0,42,67,39,39,39,39,39,39,39,39,39,39,39,39,39,39,39,67,67,40,0
0,42,67,67,39,39,39,65,39,39,39,39,39,39,39,39,39,39,67,67,40,0
0,42,67,67,39,39,39,39,39,39,39,39,39,39,39,39,39,39,67,67,40,0
0,42,67,67,39,39,39,39,39,39,39,39,39,39,39,39,39,65,67,67,40,0
0,42,67,67,67,67,67,67,67,67,67,67,67,67,67,67,67,67,67,67,40,0
0,42,67,67,67,67,67,67,67,67,0,70,67,67,67,67,67,67,67,67,40,0
0,41,41,41,41,41,41,41,41,41,41,41,41,41,41,41,41,41,41,41,40,0
0,0,0,0,0,0,0,0,0,0,0,0,0,0,0,0,0,0,0,0,0,0
0,0,0,0,0,0,0,0,0,0,0,0,0,0,0,0,0,0,0,0,0,0
0,0,0,0,0,0,0,0,0,0,0,0,0,0,0,0,0,0,0,0,0,0
0,0,0,0,0,0,0,0,0,0,0,0,0,0,0,0,0,0,0,0,0,0
0,0,0,0,0,0,0,0,0,0,0,0,0,0,0,0,0,0,0,0,0,0
0,0,0,0,0,0,0,0,0,0,0,0,0,0,0,0,0,0,0,0,0,0
:endlayer
layer: 7
0,0,0,0,0,0,0,0,0,0,0,0,0,0,0,0,0,0,0,0,0,0
0,0,0,0,0,0,0,0,0,0,0,0,0,0,0,0,0,0,0,0,0,0
0,0,42,48,48,48,48,48,48,48,48,48,48,48,48,48,48,48,48,40,0,0
0,0,42,39,39,39,39,39,39,39,41,41,39,39,39,39,39,39,39,40,0,0
0,0,42,39,69,39,71,27,72,39,58,58,39,73,65,44,39,70,39,40,0,0
0,0,42,39,39,58,58,58,58,58,58,58,27,10,10,10,27,39,39,40,0,0
0,0,42,39,58,58,58,58,58,58,58,58,27,68,10,10,27,58,39,40,0,0
0,0,42,39,58,58,58,58,58,58,58,58,64,10,10,10,27,58,39,40,0,0
0,0,42,39,58,58,58,58,58,58,58,58,27,10,10,10,27,58,39,40,0,0
0,0,42,39,58,58,58,58,58,58,58,58,27,44,44,44,27,58,39,40,0,0
0,0,42,39,0,0,74,74,74,58,58,58,58,58,58,58,58,58,39,40,0,0
0,0,42,39,0,0,0,0,74,58,58,58,58,58,58,58,58,58,39,40,0,0
0,0,42,39,0,0,0,0,74,58,58,58,58,58,58,58,58,58,39,40,0,0
0,0,42,39,39,39,39,39,74,58,58,58,58,58,58,58,58,58,39,40,0,0
0,0,42,39,75,0,0,0,39,58,58,45,43,43,46,58,58,58,39,40,0,0
0,0,42,39,76,0,0,70,39,58,58,58,58,58,58,58,58,58,39,40,0,0
0,0,42,39,39,0,0,0,77,58,58,58,58,58,58,58,58,39,39,40,0,0
0,0,42,39,0,39,0,0,39,39,78,58,58,58,58,78,39,73,39,40,0,0
0,0,42,39,39,39,39,39,39,39,39,39,39,39,39,39,39,39,39,40,0,0
0,0,42,41,41,41,41,41,41,41,41,41,41,41,41,41,41,41,41,41,0,0
0,0,0,0,0,0,0,0,0,0,0,0,0,0,0,0,0,0,0,0,0,0
0,0,0,0,0,0,0,0,0,0,0,0,0,0,0,0,0,0,0,0,0,0
0,0,0,0,0,0,0,0,0,0,0,0,0,0,0,0,0,0,0,0,0,0
0,0,0,0,0,0,0,0,0,0,0,0,0,0,0,0,0,0,0,0,0,0
0,0,0,0,0,0,0,0,0,0,0,0,0,0,0,0,0,0,0,0,0,0
0,0,0,0,0,0,0,0,0,0,0,0,0,0,0,0,0,0,0,0,0,0
0,0,0,0,0,0,0,0,0,0,0,0,0,0,0,0,0,0,0,0,0,0
:endlayer
layer: 8
0,0,0,0,0,0,0,0,0,0,0,0,0,0,0,0,0,0,0,0,0,0
0,0,0,0,0,0,0,0,0,0,0,0,0,0,0,0,0,0,0,0,0,0
0,0,0,0,0,0,0,0,0,0,0,0,0,0,0,0,0,0,0,0,0,0
0,0,0,42,48,48,48,48,48,39,79,79,39,48,48,48,48,48,40,0,0,0
0,0,0,42,39,39,0,80,0,39,0,0,39,44,44,44,39,39,40,0,0,0
0,0,0,42,39,51,0,0,0,0,0,0,81,58,58,58,0,39,40,0,0,0
0,0,0,42,0,0,0,0,0,0,0,0,0,82,82,82,0,0,40,0,0,0
0,0,0,42,0,0,0,0,0,0,0,0,0,82,82,82,0,0,40,0,0,0
0,0,0,42,0,0,0,0,0,0,0,0,0,82,82,82,0,0,40,0,0,0
0,0,0,42,0,0,0,0,0,0,0,0,0,0,0,0,0,0,40,0,0,0
0,0,0,42,0,0,0,0,0,0,0,0,0,0,0,0,0,0,40,0,0,0
0,0,0,42,0,0,0,0,0,0,0,0,0,0,0,0,0,0,40,0,0,0
0,0,0,42,0,0,0,0,0,0,0,0,0,0,0,0,0,0,40,0,0,0
0,0,0,42,39,39,39,39,0,0,0,0,0,0,0,0,0,0,40,0,0,0
0,0,0,42,0,0,0,0,39,0,0,0,0,0,0,0,0,0,40,0,0,0
0,0,0,42,0,0,0,0,39,0,0,0,0,0,0,0,0,0,40,0,0,0
0,0,0,42,39,0,0,0,83,0,0,0,0,0,0,0,0,39,40,0,0,0
0,0,0,42,0,39,0,0,39,39,78,0,0,0,0,78,39,39,40,0,0,0
0,0,0,41,41,41,41,41,41,41,41,41,41,41,41,41,41,41,40,0,0,0
0,0,0,0,0,0,0,0,0,0,0,0,0,0,0,0,0,0,0,0,0,0
0,0,0,0,0,0,0,0,0,0,0,0,0,0,0,0,0,0,0,0,0,0
0,0,0,0,0,0,0,0,0,0,0,0,0,0,0,0,0,0,0,0,0,0
0,0,0,0,0,0,0,0,0,0,0,0,0,0,0,0,0,0,0,0,0,0
0,0,0,0,0,0,0,0,0,0,0,0,0,0,0,0,0,0,0,0,0,0
0,0,0,0,0,0,0,0,0,0,0,0,0,0,0,0,0,0,0,0,0,0
0,0,0,0,0,0,0,0,0,0,0,0,0,0,0,0,0,0,0,0,0,0
0,0,0,0,0,0,0,0,0,0,0,0,0,0,0,0,0,0,0,0,0,0
:endlayer
layer: 9
0,0,0,0,0,0,0,0,0,0,0,0,0,0,0,0,0,0,0,0,0,0
0,0,0,0,0,0,0,0,0,0,0,0,0,0,0,0,0,0,0,0,0,0
0,0,0,0,0,0,0,0,0,0,0,0,0,0,0,0,0,0,0,0,0,0
0,0,0,0,0,0,0,0,0,39,79,79,39,0,0,0,0,0,0,0,0,0
0,0,0,0,48,48,48,48,48,39,0,0,39,48,48,48,48,48,0,0,0,0
0,0,0,0,42,0,0,0,0,0,0,0,0,0,0,0,0,40,0,0,0,0
0,0,0,0,42,0,0,0,0,0,0,0,0,0,0,0,0,40,0,0,0,0
0,0,0,0,42,0,0,0,0,0,0,0,0,0,0,0,0,40,0,0,0,0
0,0,0,0,42,0,0,0,0,0,0,0,0,0,0,0,0,40,0,0,0,0
0,0,0,0,42,0,0,0,0,0,0,0,0,0,0,0,0,40,0,0,0,0
0,0,0,0,42,0,0,0,0,0,0,0,0,0,0,0,0,40,0,0,0,0
0,0,0,0,42,0,0,0,0,0,0,0,0,0,0,0,0,40,0,0,0,0
0,0,0,0,42,0,0,0,0,0,0,0,0,0,0,0,0,40,0,0,0,0
0,0,0,0,42,39,39,39,0,0,0,0,0,0,0,0,0,40,0,0,0,0
0,0,0,0,42,0,0,0,39,0,0,0,0,0,0,0,0,40,0,0,0,0
0,0,0,0,42,0,0,0,39,0,0,0,0,0,0,0,0,40,0,0,0,0
0,0,0,0,42,0,0,0,39,0,0,0,0,0,0,0,0,40,0,0,0,0
0,0,0,0,41,41,41,41,41,41,41,41,41,41,41,41,41,40,0,0,0,0
0,0,0,0,0,0,0,0,0,0,0,0,0,0,0,0,0,0,0,0,0,0
0,0,0,0,0,0,0,0,0,0,0,0,0,0,0,0,0,0,0,0,0,0
0,0,0,0,0,0,0,0,0,0,0,0,0,0,0,0,0,0,0,0,0,0
0,0,0,0,0,0,0,0,0,0,0,0,0,0,0,0,0,0,0,0,0,0
0,0,0,0,0,0,0,0,0,0,0,0,0,0,0,0,0,0,0,0,0,0
0,0,0,0,0,0,0,0,0,0,0,0,0,0,0,0,0,0,0,0,0,0
0,0,0,0,0,0,0,0,0,0,0,0,0,0,0,0,0,0,0,0,0,0
0,0,0,0,0,0,0,0,0,0,0,0,0,0,0,0,0,0,0,0,0,0
0,0,0,0,0,0,0,0,0,0,0,0,0,0,0,0,0,0,0,0,0,0
:endlayer
layer: 10
0,0,0,0,0,0,0,0,0,0,0,0,0,0,0,0,0,0,0,0,0,0
0,0,0,0,0,0,0,0,0,0,0,0,0,0,0,0,0,0,0,0,0,0
0,0,0,0,0,0,0,0,0,0,0,0,0,0,0,0,0,0,0,0,0,0
0,0,0,0,0,0,0,0,0,42,48,48,40,0,0,0,0,0,0,0,0,0
0,0,0,0,0,0,0,0,0,42,39,39,40,0,0,0,0,0,0,0,0,0
0,0,0,0,0,42,48,48,48,42,39,39,40,48,48,48,40,0,0,0,0,0
0,0,0,0,0,42,0,0,0,0,0,0,0,0,0,0,40,0,0,0,0,0
0,0,0,0,0,42,0,0,0,0,0,0,0,0,0,0,40,0,0,0,0,0
0,0,0,0,0,42,0,0,0,0,0,0,0,0,0,0,40,0,0,0,0,0
0,0,0,0,0,42,0,0,0,0,0,0,0,0,0,0,40,0,0,0,0,0
0,0,0,0,0,42,0,0,0,0,0,0,0,0,0,0,40,0,0,0,0,0
0,0,0,0,0,42,0,0,0,0,0,0,0,0,0,0,40,0,0,0,0,0
0,0,0,0,0,42,0,0,0,0,0,0,0,0,0,0,40,0,0,0,0,0
0,0,0,0,0,42,39,39,0,0,0,0,0,0,0,0,40,0,0,0,0,0
0,0,0,0,0,42,0,0,39,0,0,0,0,0,0,0,40,0,0,0,0,0
0,0,0,0,0,42,0,0,39,0,0,0,0,0,0,0,40,0,0,0,0,0
0,0,0,0,0,42,41,41,41,41,41,41,41,41,41,41,41,0,0,0,0,0
0,0,0,0,0,0,0,0,0,0,0,0,0,0,0,0,0,0,0,0,0,0
0,0,0,0,0,0,0,0,0,0,0,0,0,0,0,0,0,0,0,0,0,0
0,0,0,0,0,0,0,0,0,0,0,0,0,0,0,0,0,0,0,0,0,0
0,0,0,0,0,0,0,0,0,0,0,0,0,0,0,0,0,0,0,0,0,0
0,0,0,0,0,0,0,0,0,0,0,0,0,0,0,0,0,0,0,0,0,0
0,0,0,0,0,0,0,0,0,0,0,0,0,0,0,0,0,0,0,0,0,0
0,0,0,0,0,0,0,0,0,0,0,0,0,0,0,0,0,0,0,0,0,0
0,0,0,0,0,0,0,0,0,0,0,0,0,0,0,0,0,0,0,0,0,0
0,0,0,0,0,0,0,0,0,0,0,0,0,0,0,0,0,0,0,0,0,0
0,0,0,0,0,0,0,0,0,0,0,0,0,0,0,0,0,0,0,0,0,0
:endlayer
layer: 11
0,0,0,0,0,0,0,0,0,0,0,0,0,0,0,0,0,0,0,0,0,0
0,0,0,0,0,0,0,0,0,0,0,0,0,0,0,0,0,0,0,0,0,0
0,0,0,0,0,0,0,0,0,0,0,0,0,0,0,0,0,0,0,0,0,0
0,0,0,0,0,0,0,0,0,0,0,0,0,0,0,0,0,0,0,0,0,0
0,0,0,0,0,0,0,0,0,0,48,48,0,0,0,0,0,0,0,0,0,0
0,0,0,0,0,0,0,0,0,0,42,40,0,0,0,0,0,0,0,0,0,0
0,0,0,0,0,0,48,48,48,48,42,48,48,48,48,48,0,0,0,0,0,0
0,0,0,0,0,0,42,39,39,39,39,39,39,39,39,40,0,0,0,0,0,0
0,0,0,0,0,0,42,39,65,67,67,67,67,65,39,40,0,0,0,0,0,0
0,0,0,0,0,0,42,39,67,67,67,67,67,67,39,40,0,0,0,0,0,0
0,0,0,0,0,0,42,39,67,67,67,67,67,67,39,40,0,0,0,0,0,0
0,0,0,0,0,0,42,39,67,67,67,67,67,67,39,40,0,0,0,0,0,0
0,0,0,0,0,0,42,39,67,67,67,67,67,67,39,40,0,0,0,0,0,0
0,0,0,0,0,0,42,39,65,67,67,67,67,65,39,40,0,0,0,0,0,0
0,0,0,0,0,0,42,39,39,39,39,39,39,39,39,40,0,0,0,0,0,0
0,0,0,0,0,0,42,41,41,41,41,41,41,41,41,41,0,0,0,0,0,0
0,0,0,0,0,0,0,0,0,0,0,0,0,0,0,0,0,0,0,0,0,0
0,0,0,0,0,0,0,0,0,0,0,0,0,0,0,0,0,0,0,0,0,0
0,0,0,0,0,0,0,0,0,0,0,0,0,0,0,0,0,0,0,0,0,0
0,0,0,0,0,0,0,0,0,0,0,0,0,0,0,0,0,0,0,0,0,0
0,0,0,0,0,0,0,0,0,0,0,0,0,0,0,0,0,0,0,0,0,0
0,0,0,0,0,0,0,0,0,0,0,0,0,0,0,0,0,0,0,0,0,0
0,0,0,0,0,0,0,0,0,0,0,0,0,0,0,0,0,0,0,0,0,0
0,0,0,0,0,0,0,0,0,0,0,0,0,0,0,0,0,0,0,0,0,0
0,0,0,0,0,0,0,0,0,0,0,0,0,0,0,0,0,0,0,0,0,0
0,0,0,0,0,0,0,0,0,0,0,0,0,0,0,0,0,0,0,0,0,0
0,0,0,0,0,0,0,0,0,0,0,0,0,0,0,0,0,0,0,0,0,0
:endlayer
layer: 12
0,0,0,0,0,0,0,0,0,0,0,0,0,0,0,0,0,0,0,0,0,0
0,0,0,0,0,0,0,0,0,0,0,0,0,0,0,0,0,0,0,0,0,0
0,0,0,0,0,0,0,0,0,0,0,0,0,0,0,0,0,0,0,0,0,0
0,0,0,0,0,0,0,0,0,0,0,0,0,0,0,0,0,0,0,0,0,0
0,0,0,0,0,0,0,0,0,0,0,0,0,0,0,0,0,0,0,0,0,0
0,0,0,0,0,0,0,0,0,0,0,0,0,0,0,0,0,0,0,0,0,0
0,0,0,0,0,0,0,0,0,0,0,0,0,0,0,0,0,0,0,0,0,0
0,0,0,0,0,0,0,42,48,48,48,48,48,48,40,0,0,0,0,0,0,0
0,0,0,0,0,0,0,42,68,0,0,0,0,70,40,0,0,0,0,0,0,0
0,0,0,0,0,0,0,42,0,0,0,0,0,0,40,0,0,0,0,0,0,0
0,0,0,0,0,0,0,42,0,0,0,0,0,0,40,0,0,0,0,0,0,0
0,0,0,0,0,0,0,42,0,0,0,0,0,0,40,0,0,0,0,0,0,0
0,0,0,0,0,0,0,42,0,0,0,0,0,0,40,0,0,0,0,0,0,0
0,0,0,0,0,0,0,42,70,0,0,0,0,70,40,0,0,0,0,0,0,0
0,0,0,0,0,0,0,41,41,41,41,41,41,41,40,0,0,0,0,0,0,0
0,0,0,0,0,0,0,0,0,0,0,0,0,0,0,0,0,0,0,0,0,0
0,0,0,0,0,0,0,0,0,0,0,0,0,0,0,0,0,0,0,0,0,0
0,0,0,0,0,0,0,0,0,0,0,0,0,0,0,0,0,0,0,0,0,0
0,0,0,0,0,0,0,0,0,0,0,0,0,0,0,0,0,0,0,0,0,0
0,0,0,0,0,0,0,0,0,0,0,0,0,0,0,0,0,0,0,0,0,0
0,0,0,0,0,0,0,0,0,0,0,0,0,0,0,0,0,0,0,0,0,0
0,0,0,0,0,0,0,0,0,0,0,0,0,0,0,0,0,0,0,0,0,0
0,0,0,0,0,0,0,0,0,0,0,0,0,0,0,0,0,0,0,0,0,0
0,0,0,0,0,0,0,0,0,0,0,0,0,0,0,0,0,0,0,0,0,0
0,0,0,0,0,0,0,0,0,0,0,0,0,0,0,0,0,0,0,0,0,0
0,0,0,0,0,0,0,0,0,0,0,0,0,0,0,0,0,0,0,0,0,0
0,0,0,0,0,0,0,0,0,0,0,0,0,0,0,0,0,0,0,0,0,0
:endlayer
layer: 13
0,0,0,0,0,0,0,0,0,0,0,0,0,0,0,0,0,0,0,0,0,0
0,0,0,0,0,0,0,0,0,0,0,0,0,0,0,0,0,0,0,0,0,0
0,0,0,0,0,0,0,0,0,0,0,0,0,0,0,0,0,0,0,0,0,0
0,0,0,0,0,0,0,0,0,0,0,0,0,0,0,0,0,0,0,0,0,0
0,0,0,0,0,0,0,0,0,0,0,0,0,0,0,0,0,0,0,0,0,0
0,0,0,0,0,0,0,0,0,0,0,0,0,0,0,0,0,0,0,0,0,0
0,0,0,0,0,0,0,0,0,0,0,0,0,0,0,0,0,0,0,0,0,0
0,0,0,0,0,0,0,0,0,0,0,0,0,0,0,0,0,0,0,0,0,0
0,0,0,0,0,0,0,0,67,67,67,67,67,67,0,0,0,0,0,0,0,0
0,0,0,0,0,0,0,0,67,67,67,67,67,67,0,0,0,0,0,0,0,0
0,0,0,0,0,0,0,0,67,67,67,67,67,67,0,0,0,0,0,0,0,0
0,0,0,0,0,0,0,0,67,67,67,67,67,67,0,0,0,0,0,0,0,0
0,0,0,0,0,0,0,0,67,67,67,67,67,67,0,0,0,0,0,0,0,0
0,0,0,0,0,0,0,0,67,67,67,67,67,67,0,0,0,0,0,0,0,0
0,0,0,0,0,0,0,0,0,0,0,0,0,0,0,0,0,0,0,0,0,0
0,0,0,0,0,0,0,0,0,0,0,0,0,0,0,0,0,0,0,0,0,0
0,0,0,0,0,0,0,0,0,0,0,0,0,0,0,0,0,0,0,0,0,0
0,0,0,0,0,0,0,0,0,0,0,0,0,0,0,0,0,0,0,0,0,0
0,0,0,0,0,0,0,0,0,0,0,0,0,0,0,0,0,0,0,0,0,0
0,0,0,0,0,0,0,0,0,0,0,0,0,0,0,0,0,0,0,0,0,0
0,0,0,0,0,0,0,0,0,0,0,0,0,0,0,0,0,0,0,0,0,0
0,0,0,0,0,0,0,0,0,0,0,0,0,0,0,0,0,0,0,0,0,0
0,0,0,0,0,0,0,0,0,0,0,0,0,0,0,0,0,0,0,0,0,0
0,0,0,0,0,0,0,0,0,0,0,0,0,0,0,0,0,0,0,0,0,0
0,0,0,0,0,0,0,0,0,0,0,0,0,0,0,0,0,0,0,0,0,0
0,0,0,0,0,0,0,0,0,0,0,0,0,0,0,0,0,0,0,0,0,0
0,0,0,0,0,0,0,0,0,0,0,0,0,0,0,0,0,0,0,0,0,0
:endlayer

#### RULES ####
rule:
plugin=vanillaBlocks
number=1
data:
JSON:{blockState:{blockName:"minecraft:grass",properties:{snowy:"false"}},buildPass:0}
:enddata
:endrule

rule:
plugin=vanillaBlocks
number=2
data:
JSON:{blockState:{blockName:"minecraft:dirt",properties:{variant:"dirt",snowy:"false"}},buildPass:0}
:enddata
:endrule

rule:
plugin=vanillaBlocks
number=3
data:
JSON:{blockState:{blockName:"minecraft:water",properties:{level:"0"}},buildPass:0}
:enddata
:endrule

rule:
plugin=vanillaBlocks
number=4
data:
JSON:{blockState:{blockName:"minecraft:glowstone",properties:{}},buildPass:0}
:enddata
:endrule

rule:
plugin=vanillaBlocks
number=5
data:
JSON:{blockState:{blockName:"minecraft:cobblestone_wall",properties:{east:"false",south:"false",north:"false",variant:"cobblestone",west:"false",up:"false"}},buildPass:0}
:enddata
:endrule

rule:
plugin=vanillaBlocks
number=6
data:
JSON:{blockState:{blockName:"minecraft:leaves",properties:{check_decay:"false",decayable:"false",variant:"spruce"}},buildPass:0}
:enddata
:endrule

rule:
plugin=vanillaBlocks
number=7
data:
JSON:{blockState:{blockName:"minecraft:stone_slab",properties:{half:"bottom",variant:"stone_brick"}},buildPass:0}
:enddata
:endrule

rule:
plugin=vanillaBlocks
number=8
data:
JSON:{blockState:{blockName:"minecraft:stonebrick",properties:{variant:"stonebrick"}},buildPass:0}
:enddata
:endrule

rule:
plugin=vanillaBlocks
number=9
data:
JSON:{blockState:{blockName:"minecraft:stone",properties:{variant:"stone"}},buildPass:0}
:enddata
:endrule

rule:
plugin=vanillaBlocks
number=10
data:
JSON:{blockState:{blockName:"minecraft:wool",properties:{color:"red"}},buildPass:0}
:enddata
:endrule

rule:
plugin=vanillaBlocks
number=11
data:
JSON:{blockState:{blockName:"minecraft:stone_brick_stairs",properties:{half:"bottom",shape:"straight",facing:"north"}},buildPass:0}
:enddata
:endrule

rule:
plugin=vanillaBlocks
number=12
data:
JSON:{blockState:{blockName:"minecraft:tallgrass",properties:{type:"fern"}},buildPass:2}
:enddata
:endrule

rule:
plugin=vanillaBlocks
number=13
data:
JSON:{blockState:{blockName:"minecraft:red_flower",properties:{type:"poppy"}},buildPass:2}
:enddata
:endrule

rule:
plugin=vanillaBlocks
number=14
data:
JSON:{blockState:{blockName:"minecraft:double_plant",properties:{half:"lower",variant:"double_fern",facing:"north"}},buildPass:2}
:enddata
:endrule

rule:
plugin=vanillaBlocks
number=15
data:
JSON:{blockState:{blockName:"minecraft:double_plant",properties:{half:"lower",variant:"double_rose",facing:"north"}},buildPass:2}
:enddata
:endrule

rule:
plugin=vanillaBlocks
number=16
data:
JSON:{blockState:{blockName:"minecraft:waterlily",properties:{}},buildPass:2}
:enddata
:endrule

rule:
plugin=vanillaBlocks
number=17
data:
JSON:{blockState:{blockName:"minecraft:water",properties:{level:"9"}},buildPass:0}
:enddata
:endrule

rule:
plugin=vanillaBlocks
number=18
data:
JSON:{blockState:{blockName:"minecraft:leaves",properties:{check_decay:"true",decayable:"false",variant:"spruce"}},buildPass:0}
:enddata
:endrule

rule:
plugin=vanillaBlocks
number=19
data:
JSON:{blockState:{blockName:"minecraft:fence_gate",properties:{in_wall:"false",powered:"false",facing:"north",open:"false"}},buildPass:0}
:enddata
:endrule

rule:
plugin=vanillaBlocks
number=20
data:
JSON:{blockState:{blockName:"minecraft:torch",properties:{facing:"up"}},buildPass:2}
:enddata
:endrule

rule:
plugin=vanillaBlocks
number=21
data:
JSON:{blockState:{blockName:"minecraft:torch",properties:{facing:"west"}},buildPass:2}
:enddata
:endrule

rule:
plugin=vanillaBlocks
number=22
data:
JSON:{blockState:{blockName:"minecraft:glass",properties:{}},buildPass:0}
:enddata
:endrule

rule:
plugin=doors
number=23
data:
JSON:{blockState:{blockName:"minecraft:wooden_door",properties:{hinge:"left",half:"lower",powered:"false",facing:"south",open:"false"}},buildPass:2}
:enddata
:endrule

rule:
plugin=doors
number=24
data:
JSON:{blockState:{blockName:"minecraft:wooden_door",properties:{hinge:"left",half:"lower",powered:"false",facing:"south",open:"false"}},buildPass:2}
:enddata
:endrule

rule:
plugin=vanillaBlocks
number=25
data:
JSON:{blockState:{blockName:"minecraft:torch",properties:{facing:"east"}},buildPass:2}
:enddata
:endrule

rule:
plugin=vanillaBlocks
number=26
data:
JSON:{blockState:{blockName:"minecraft:planks",properties:{variant:"dark_oak"}},buildPass:0}
:enddata
:endrule

rule:
plugin=vanillaBlocks
number=27
data:
JSON:{blockState:{blockName:"minecraft:planks",properties:{variant:"birch"}},buildPass:0}
:enddata
:endrule

rule:
plugin=vanillaBlocks
number=28
data:
JSON:{blockState:{blockName:"minecraft:cauldron",properties:{level:"0"}},buildPass:0}
:enddata
:endrule

rule:
plugin=vanillaBlocks
number=29
data:
JSON:{blockState:{blockName:"minecraft:crafting_table",properties:{}},buildPass:0}
:enddata
:endrule

rule:
plugin=vanillaBlocks
number=30
data:
JSON:{blockState:{blockName:"minecraft:stone_slab",properties:{half:"top",variant:"stone"}},buildPass:0}
:enddata
:endrule

rule:
plugin=doors
number=31
data:
JSON:{blockState:{blockName:"minecraft:wooden_door",properties:{hinge:"left",half:"lower",powered:"false",facing:"east",open:"false"}},buildPass:2}
:enddata
:endrule

rule:
plugin=blockTile
number=32
data:
JSON:{blockState:{blockName:"minecraft:furnace",properties:{facing:"west"}},buildPass:0,teData:{CookTime:0s,BurnTime:0s,x:-519,y:5,Items:[],z:-924,id:"Furnace"}}
:enddata
:endrule

rule:
plugin=vanillaBlocks
number=33
data:
JSON:{blockState:{blockName:"minecraft:bed",properties:{part:"foot",facing:"south",occupied:"false"}},buildPass:2}
:enddata
:endrule

rule:
plugin=vanillaBlocks
number=34
data:
JSON:{blockState:{blockName:"minecraft:bed",properties:{part:"head",facing:"south",occupied:"false"}},buildPass:2}
:enddata
:endrule

rule:
plugin=inventory
number=35
data:
JSON:{blockState:{blockName:"minecraft:chest",properties:{facing:"north"}},buildPass:0,lootLevel:0,teData:{x:-528,y:5,z:-922,id:"Chest"},inventoryData:{length:27,inventoryContents:[{id:"minecraft:gold_nugget",Count:3b,slot:4,Damage:0s},{id:"minecraft:chainmail_leggings",Count:1b,slot:11,Damage:0s},{id:"minecraft:gold_nugget",Count:2b,slot:16,Damage:0s},{id:"minecraft:gold_nugget",Count:5b,slot:18,Damage:0s},{id:"ancientwarfare:research_note",Count:1b,tag:{researchName:"leadership"},slot:23,Damage:0s}]}}
:enddata
:endrule

rule:
plugin=inventory
number=36
data:
JSON:{blockState:{blockName:"minecraft:chest",properties:{facing:"north"}},buildPass:0,lootLevel:1,teData:{x:-523,y:5,z:-922,id:"Chest"},inventoryData:{length:27,inventoryContents:[{id:"minecraft:gold_ingot",Count:1b,slot:0,Damage:0s}]}}
:enddata
:endrule

rule:
plugin=vanillaBlocks
number=37
data:
JSON:{blockState:{blockName:"minecraft:double_stone_slab",properties:{seamless:"false",variant:"stone"}},buildPass:0}
:enddata
:endrule

rule:
plugin=inventory
number=38
data:
JSON:{blockState:{blockName:"minecraft:chest",properties:{facing:"west"}},buildPass:0,lootLevel:0,teData:{x:-519,y:5,z:-922,id:"Chest"},inventoryData:{length:27,inventoryContents:[]}}
:enddata
:endrule

rule:
plugin=vanillaBlocks
number=39
data:
JSON:{blockState:{blockName:"minecraft:planks",properties:{variant:"oak"}},buildPass:0}
:enddata
:endrule

rule:
plugin=vanillaBlocks
number=40
data:
JSON:{blockState:{blockName:"minecraft:oak_stairs",properties:{half:"bottom",shape:"straight",facing:"west"}},buildPass:0}
:enddata
:endrule

rule:
plugin=vanillaBlocks
number=41
data:
JSON:{blockState:{blockName:"minecraft:oak_stairs",properties:{half:"bottom",shape:"straight",facing:"north"}},buildPass:0}
:enddata
:endrule

rule:
plugin=vanillaBlocks
number=42
data:
JSON:{blockState:{blockName:"minecraft:oak_stairs",properties:{half:"bottom",shape:"straight",facing:"east"}},buildPass:0}
:enddata
:endrule

rule:
plugin=vanillaBlocks
number=43
data:
JSON:{blockState:{blockName:"minecraft:birch_stairs",properties:{half:"bottom",shape:"straight",facing:"north"}},buildPass:0}
:enddata
:endrule

rule:
plugin=vanillaBlocks
number=44
data:
JSON:{blockState:{blockName:"minecraft:wooden_slab",properties:{half:"bottom",variant:"birch"}},buildPass:0}
:enddata
:endrule

rule:
plugin=vanillaBlocks
number=45
data:
JSON:{blockState:{blockName:"minecraft:birch_stairs",properties:{half:"bottom",shape:"straight",facing:"west"}},buildPass:0}
:enddata
:endrule

rule:
plugin=vanillaBlocks
number=46
data:
JSON:{blockState:{blockName:"minecraft:birch_stairs",properties:{half:"bottom",shape:"straight",facing:"east"}},buildPass:0}
:enddata
:endrule

rule:
plugin=vanillaBlocks
number=47
data:
JSON:{blockState:{blockName:"minecraft:birch_stairs",properties:{half:"bottom",shape:"straight",facing:"south"}},buildPass:0}
:enddata
:endrule

rule:
plugin=vanillaBlocks
number=48
data:
JSON:{blockState:{blockName:"minecraft:oak_stairs",properties:{half:"bottom",shape:"straight",facing:"south"}},buildPass:0}
:enddata
:endrule

rule:
plugin=doors
number=49
data:
JSON:{blockState:{blockName:"minecraft:wooden_door",properties:{hinge:"left",half:"lower",powered:"false",facing:"north",open:"false"}},buildPass:2}
:enddata
:endrule

rule:
plugin=doors
number=50
data:
JSON:{blockState:{blockName:"minecraft:wooden_door",properties:{hinge:"left",half:"lower",powered:"false",facing:"north",open:"false"}},buildPass:2}
:enddata
:endrule

rule:
plugin=vanillaBlocks
number=51
data:
JSON:{blockState:{blockName:"minecraft:torch",properties:{facing:"south"}},buildPass:2}
:enddata
:endrule

rule:
plugin=vanillaBlocks
number=52
data:
JSON:{blockState:{blockName:"minecraft:double_plant",properties:{half:"upper",variant:"sunflower",facing:"north"}},buildPass:2}
:enddata
:endrule

rule:
plugin=vanillaBlocks
number=53
data:
JSON:{blockState:{blockName:"minecraft:water",properties:{level:"1"}},buildPass:0}
:enddata
:endrule

rule:
plugin=doors
number=54
data:
JSON:{blockState:{blockName:"minecraft:wooden_door",properties:{hinge:"right",half:"upper",powered:"false",facing:"north",open:"false"}},buildPass:2}
:enddata
:endrule

rule:
plugin=doors
number=55
data:
JSON:{blockState:{blockName:"minecraft:wooden_door",properties:{hinge:"left",half:"upper",powered:"false",facing:"north",open:"false"}},buildPass:2}
:enddata
:endrule

rule:
plugin=vanillaFlowerPot
number=56
data:
JSON:{blockState:{blockName:"minecraft:flower_pot",properties:{}},itemName:"minecraft:red_flower",buildPass:0,itemMeta:1}
:enddata
:endrule

rule:
plugin=doors
number=57
data:
JSON:{blockState:{blockName:"minecraft:wooden_door",properties:{hinge:"left",half:"upper",powered:"false",facing:"north",open:"false"}},buildPass:2}
:enddata
:endrule

rule:
plugin=vanillaBlocks
number=58
data:
JSON:{blockState:{blockName:"minecraft:carpet",properties:{color:"white"}},buildPass:2}
:enddata
:endrule

rule:
plugin=vanillaBlocks
number=59
data:
JSON:{blockState:{blockName:"minecraft:torch",properties:{facing:"north"}},buildPass:2}
:enddata
:endrule

rule:
plugin=inventory
number=60
data:
JSON:{blockState:{blockName:"minecraft:chest",properties:{facing:"north"}},buildPass:0,lootLevel:1,teData:{x:-523,y:6,z:-922,id:"Chest"},inventoryData:{length:27,inventoryContents:[{id:"minecraft:gold_ingot",Count:1b,slot:0,Damage:0s}]}}
:enddata
:endrule

rule:
plugin=doors
number=61
data:
JSON:{blockState:{blockName:"minecraft:wooden_door",properties:{hinge:"left",half:"upper",powered:"false",facing:"north",open:"false"}},buildPass:2}
:enddata
:endrule

rule:
plugin=doors
number=62
data:
JSON:{blockState:{blockName:"minecraft:wooden_door",properties:{hinge:"right",half:"upper",powered:"false",facing:"north",open:"false"}},buildPass:2}
:enddata
:endrule

rule:
plugin=inventory
number=63
data:
JSON:{blockState:{blockName:"minecraft:chest",properties:{facing:"north"}},buildPass:0,lootLevel:1,teData:{x:-523,y:7,z:-922,id:"Chest"},inventoryData:{length:27,inventoryContents:[{id:"minecraft:gold_ingot",Count:1b,slot:0,Damage:0s}]}}
:enddata
:endrule

rule:
plugin=vanillaBlocks
number=64
data:
JSON:{blockState:{blockName:"minecraft:wooden_slab",properties:{half:"top",variant:"birch"}},buildPass:0}
:enddata
:endrule

rule:
plugin=vanillaBlocks
number=65
data:
JSON:{blockState:{blockName:"minecraft:lit_redstone_lamp",properties:{}},buildPass:2}
:enddata
:endrule

rule:
plugin=vanillaBlocks
number=66
data:
JSON:{blockState:{blockName:"minecraft:stone_brick_stairs",properties:{half:"top",shape:"straight",facing:"north"}},buildPass:0}
:enddata
:endrule

rule:
plugin=vanillaBlocks
number=67
data:
JSON:{blockState:{blockName:"minecraft:wooden_slab",properties:{half:"bottom",variant:"oak"}},buildPass:0}
:enddata
:endrule

rule:
plugin=vanillaBlocks
number=68
data:
JSON:{blockState:{blockName:"minecraft:lever",properties:{powered:"true",facing:"up_x"}},buildPass:2}
:enddata
:endrule

rule:
plugin=vanillaBlocks
number=69
data:
JSON:{blockState:{blockName:"minecraft:lever",properties:{powered:"true",facing:"east"}},buildPass:2}
:enddata
:endrule

rule:
plugin=vanillaBlocks
number=70
data:
JSON:{blockState:{blockName:"minecraft:lever",properties:{powered:"true",facing:"up_z"}},buildPass:2}
:enddata
:endrule

rule:
plugin=inventory
number=71
data:
JSON:{blockState:{blockName:"minecraft:chest",properties:{facing:"south"}},buildPass:0,lootLevel:0,teData:{x:-530,y:10,z:-927,id:"Chest"},inventoryData:{length:27,inventoryContents:[]}}
:enddata
:endrule

rule:
plugin=inventory
number=72
data:
JSON:{blockState:{blockName:"minecraft:chest",properties:{facing:"south"}},buildPass:0,lootLevel:0,teData:{x:-528,y:10,z:-927,id:"Chest"},inventoryData:{length:27,inventoryContents:[]}}
:enddata
:endrule

rule:
plugin=vanillaBlocks
number=73
data:
JSON:{blockState:{blockName:"minecraft:lever",properties:{powered:"true",facing:"west"}},buildPass:2}
:enddata
:endrule

rule:
plugin=vanillaBlocks
number=74
data:
JSON:{blockState:{blockName:"minecraft:fence",properties:{east:"false",south:"false",north:"false",west:"false"}},buildPass:0}
:enddata
:endrule

rule:
plugin=inventory
number=75
data:
JSON:{blockState:{blockName:"minecraft:chest",properties:{facing:"east"}},buildPass:0,lootLevel:0,teData:{x:-532,y:10,z:-917,id:"Chest"},inventoryData:{length:27,inventoryContents:[]}}
:enddata
:endrule

rule:
plugin=inventory
number=76
data:
JSON:{blockState:{blockName:"minecraft:chest",properties:{facing:"east"}},buildPass:0,lootLevel:0,teData:{x:-532,y:10,z:-916,id:"Chest"},inventoryData:{length:27,inventoryContents:[]}}
:enddata
:endrule

rule:
plugin=doors
number=77
data:
JSON:{blockState:{blockName:"minecraft:wooden_door",properties:{hinge:"left",half:"lower",powered:"false",facing:"west",open:"false"}},buildPass:2}
:enddata
:endrule

rule:
plugin=vanillaBlocks
number=78
data:
JSON:{blockState:{blockName:"minecraft:noteblock",properties:{}},buildPass:0}
:enddata
:endrule

rule:
plugin=vanillaBlocks
number=79
data:
JSON:{blockState:{blockName:"minecraft:glass_pane",properties:{east:"false",south:"false",north:"false",west:"false"}},buildPass:0}
:enddata
:endrule

rule:
plugin=vanillaFlowerPot
number=80
data:
JSON:{blockState:{blockName:"minecraft:flower_pot",properties:{}},itemName:"minecraft:red_flower",buildPass:0,itemMeta:0}
:enddata
:endrule

rule:
plugin=vanillaFlowerPot
number=81
data:
JSON:{blockState:{blockName:"minecraft:flower_pot",properties:{}},itemName:"minecraft:red_flower",buildPass:0,itemMeta:8}
:enddata
:endrule

rule:
plugin=vanillaBlocks
number=82
data:
JSON:{blockState:{blockName:"minecraft:carpet",properties:{color:"red"}},buildPass:2}
:enddata
:endrule

rule:
plugin=doors
number=83
data:
JSON:{blockState:{blockName:"minecraft:wooden_door",properties:{hinge:"left",half:"upper",powered:"false",facing:"north",open:"false"}},buildPass:2}
:enddata
:endrule

#### ENTITIES ####
entity:
plugin=vanillaEntities
number=0
data:
JSON:{xOffset:0.49996805f,rotation:180.00543f,mobID:"minecraft:chicken",zOffset:0.8375f,position:274945015808L}
:enddata
:endentity

entity:
plugin=vanillaEntities
number=1
data:
JSON:{xOffset:0.14999998f,rotation:89.99756f,mobID:"minecraft:chicken",zOffset:0.49997282f,position:274945015810L}
:enddata
:endentity

entity:
plugin=vanillaHangingEntity
number=2
data:
JSON:{xOffset:0.5f,rotation:180.0f,mobID:"minecraft:painting",zOffset:0.0625f,position:1374590861325L,entityData:{Motion:[0.0d,0.0d,0.0d],Invulnerable:0b,OnGround:0b,Dimension:0,Air:300s,Dir:2b,PortalCooldown:0,Direction:0b,Rotation:[180.0f,0.0f],Motive:"Aztec2",FallDistance:0.0f,Pos:[-530.5d,6.5d,-917.9375d],Fire:0s,TileY:6,TileX:-531,TileZ:-919},direction:0b}
:enddata
:endentity

entity:
plugin=vanillaHangingEntity
number=3
data:
JSON:{xOffset:0.5f,rotation:0.0f,mobID:"minecraft:painting",zOffset:0.9375f,position:1649804312588L,entityData:{Motion:[0.0d,0.0d,0.0d],Invulnerable:0b,OnGround:0b,Dimension:0,Air:300s,Dir:0b,PortalCooldown:0,Direction:2b,Rotation:[0.0f,0.0f],Motive:"Aztec",FallDistance:0.0f,Pos:[-529.5d,11.5d,-918.0625d],Fire:0s,TileY:11,TileX:-530,TileZ:-918},direction:2b}
:enddata
:endentity

entity:
plugin=AWNpc
number=4
data:
JSON:{xOffset:0.59161377f,equipmentData:{equipmentContents:[{id:"minecraft:book",Count:1b,slot:0,Damage:0s}]},rotation:11.441376f,mobID:"ancientwarfarenpc:faction.trader",zOffset:0.039489746f,position:1099645845512L,entityData:{Attributes:[{Base:20.0d,Name:"generic.maxHealth"},{Base:0.0d,Name:"generic.knockbackResistance"},{Base:0.325d,Name:"generic.movementSpeed"},{Base:60.0d,Name:"generic.followRange"},{Base:2.0d,Name:"generic.attackDamage"}],Invulnerable:0b,AbsorptionAmount:0.0f,PortalCooldown:0,FallDistance:0.0f,levelingStats:{level:0,xp:0,entryList:[]},DeathTime:0s,DropChances:[1.0f,1.0f,1.0f,1.0f,1.0f],PersistenceRequired:1b,HealF:20.0f,owner:"Dulciphi",Motion:[0.0d,-0.0784000015258789d,0.0d],armorValueOverride:-1,Leashed:0b,Health:20s,OnGround:1b,Dimension:0,Air:300s,Rotation:[11.441376f,0.0f],CustomName:"Mayor Shadowmage",Pos:[-531.4083862304688d,5.0d,-922.9605102539062d],Fire:-1s,attackDamageOverride:-1,customTex:"",CanPickUpLoot:0b,factionName:"norska",HurtTime:0s,AttackTime:0s,tradeList:{ticks:46058,tradeList:[{refillFrequency:6000,currentAvailable:2,inputItems:[{id:"minecraft:gold_ingot",Count:10,slot:0,Damage:0}],ticksTilRefill:5766,outputItems:[{id:"AncientWarfareStructure:structure_builder_ticked",Count:1,tag:{structureName:"village_house_garden"},slot:0,Damage:0}],maxAvailable:2},{refillFrequency:6000,currentAvailable:1,inputItems:[{id:"minecraft:gold_ingot",Count:16,slot:0,Damage:0}],ticksTilRefill:5766,outputItems:[{id:"AncientWarfareStructure:structure_builder_ticked",Count:1,tag:{structureName:"village_house"},slot:0,Damage:0}],maxAvailable:1}]},CustomNameVisible:0b}}
:enddata
:endentity

entity:
plugin=vanillaEntities
number=5
data:
JSON:{xOffset:0.2167452f,rotation:198.703f,mobID:"minecraft:chicken",zOffset:0.45765507f,position:67108874L}
:enddata
:endentity

entity:
plugin=vanillaEntities
number=6
data:
JSON:{xOffset:0.5312381f,rotation:123.75368f,mobID:"minecraft:chicken",zOffset:0.52453494f,position:1099981389830L}
:enddata
:endentity

entity:
plugin=vanillaHangingEntity
number=7
data:
JSON:{xOffset:-0.0f,rotation:0.0f,mobID:"minecraft:painting",zOffset:0.9375f,position:3573949661201L,entityData:{Motion:[0.0d,0.0d,0.0d],Invulnerable:0b,OnGround:0b,Dimension:0,Air:300s,Dir:0b,PortalCooldown:0,Direction:2b,Rotation:[0.0f,0.0f],Motive:"Sunset",FallDistance:0.0f,Pos:[-523.0d,11.5d,-913.0625d],Fire:0s,TileY:11,TileX:-523,TileZ:-913},direction:2b}
:enddata
:endentity

entity:
plugin=vanillaHangingEntity
number=8
data:
JSON:{xOffset:0.9375f,rotation:90.0f,mobID:"minecraft:painting",zOffset:-0.0f,position:2199224582153L,entityData:{Motion:[0.0d,0.0d,0.0d],Invulnerable:0b,OnGround:0b,Dimension:0,Air:300s,Dir:1b,PortalCooldown:0,Direction:1b,Rotation:[90.0f,0.0f],Motive:"Pool",FallDistance:0.0f,Pos:[-527.0625d,6.5d,-922.0d],Fire:0s,TileY:6,TileX:-527,TileZ:-923},direction:1b}
:enddata
:endentity

entity:
plugin=vanillaHangingEntity
number=9
data:
JSON:{xOffset:-0.0f,rotation:180.0f,mobID:"minecraft:painting",zOffset:0.0625f,position:4398382055435L,entityData:{Motion:[0.0d,0.0d,0.0d],Invulnerable:0b,OnGround:0b,Dimension:0,Air:300s,Dir:2b,PortalCooldown:0,Direction:0b,Rotation:[180.0f,0.0f],Motive:"Bust",FallDistance:0.0f,Pos:[-520.0d,8.0d,-919.9375d],Fire:0s,TileY:7,TileX:-521,TileZ:-921},direction:0b}
:enddata
:endentity

entity:
plugin=vanillaEntities
number=10
data:
JSON:{xOffset:0.5002044f,rotation:0.041404724f,mobID:"minecraft:chicken",zOffset:0.44959575f,position:5222747340811L}
:enddata
:endentity

