# Ancient Warfare Structure Template File
# Auto-generated structure template file. created on: 9/22/2018 at: 16:7:2
# Lines beginning with # denote comments

header:
version=2.6
name=unique_mayors_mansion
size=23,18,21
offset=11,1,20
:endheader

#### VALIDATION ####
validation:
type=ground
survival=false
worldGenEnabled=false
unique=false
preserveBlocks=false
selectionWeight=0
clusterValue=0
minDuplicateDistance=0
dimensionWhiteList=false
dimensionList=
biomeWhiteList=false
biomeList=
leveling=0
fill=0
border=0
blockSwap=false
data:
:enddata
:endvalidation

#### LAYERS ####
layer: 0
1,1,1,1,1,1,1,1,1,1,1,1,1,1,1,1,1,1,1,1,1,1,1
1,2,2,2,2,2,2,2,2,2,2,2,2,2,2,2,2,2,2,2,2,2,1
1,2,3,3,3,3,3,3,3,4,4,4,4,4,4,4,4,4,4,4,4,2,1
1,2,3,3,3,3,3,3,3,4,4,4,4,4,4,4,4,4,4,4,4,2,1
1,2,3,3,3,3,3,3,3,4,4,4,4,4,4,4,4,4,4,4,4,2,1
1,2,3,3,3,3,3,3,3,4,4,4,4,4,4,4,4,4,4,4,4,2,1
1,2,3,3,3,3,3,3,3,4,4,4,4,4,4,4,4,4,4,4,4,2,1
1,2,3,3,3,4,3,3,3,4,4,4,4,4,4,4,4,4,4,4,4,2,1
1,2,3,3,3,3,3,3,3,4,4,4,4,4,4,4,4,4,4,4,4,2,1
1,2,3,3,3,3,3,3,4,4,4,4,4,4,4,4,4,4,4,4,4,2,1
1,2,4,4,4,4,4,4,4,4,4,4,4,4,4,4,4,4,4,4,4,2,1
1,2,4,4,4,4,4,4,4,4,4,4,4,4,4,4,4,4,4,4,4,2,1
1,2,4,4,4,4,4,4,4,4,4,4,4,4,4,4,4,4,4,4,4,2,1
1,2,4,4,4,4,4,4,4,4,4,4,4,4,4,4,4,4,4,4,4,2,1
1,2,4,4,4,4,4,4,4,4,4,4,4,4,4,4,4,4,4,4,4,2,1
1,2,4,4,4,4,4,4,4,4,4,4,4,4,4,4,4,4,4,4,4,2,1
1,2,4,4,4,4,4,4,4,4,4,4,4,4,4,4,4,4,4,4,4,2,1
1,2,4,4,4,4,4,4,4,4,4,4,4,4,4,4,4,4,4,4,4,2,1
1,2,4,4,4,4,4,4,4,2,5,5,5,2,4,4,4,4,4,4,4,2,1
1,2,2,2,2,2,2,2,2,2,5,5,5,2,2,2,2,2,2,2,2,2,1
1,1,1,1,1,1,1,1,1,1,5,5,5,1,1,1,1,1,1,1,1,1,1
:endlayer
layer: 1
0,0,0,0,0,0,0,0,0,0,0,0,0,0,0,0,0,0,0,0,0,0,0
0,6,6,6,6,6,6,6,6,6,6,6,6,6,6,6,6,6,6,6,6,6,0
0,6,4,0,0,0,0,0,7,4,8,0,4,4,9,0,10,2,2,11,12,6,0
0,6,0,0,13,13,0,0,7,4,14,0,4,4,9,0,0,15,15,0,16,6,0
0,6,0,17,18,18,19,0,20,4,0,21,0,4,22,0,0,16,0,10,2,6,0
0,6,0,0,18,18,0,0,23,4,24,0,0,4,0,0,10,2,11,10,2,6,0
0,6,0,17,18,18,19,0,25,4,26,0,0,27,0,28,10,2,11,10,2,6,0
0,6,0,0,29,29,0,0,7,30,4,4,4,30,0,0,10,2,11,10,2,6,0
0,6,0,0,0,0,0,0,0,0,0,0,0,0,0,0,0,15,0,28,15,6,0
0,6,7,31,31,7,0,0,0,0,0,0,0,0,0,0,0,28,28,0,31,6,0
0,6,4,4,4,4,30,0,0,0,0,21,0,0,0,0,30,4,4,4,4,6,0
0,6,4,32,33,34,35,35,0,0,0,0,0,0,0,36,36,12,12,12,12,6,0
0,6,33,35,35,35,35,35,35,0,0,0,0,0,36,36,36,36,36,36,36,6,0
0,6,32,35,35,35,35,35,35,30,0,0,0,30,36,36,36,36,17,36,19,6,0
0,6,32,35,35,12,35,35,33,4,0,0,0,4,17,36,19,36,17,18,19,6,0
0,6,32,35,35,12,35,35,34,4,0,0,0,4,17,18,19,36,17,18,19,6,0
0,6,32,35,35,35,35,35,34,4,0,0,0,4,17,36,19,36,17,36,19,6,0
0,6,37,35,35,35,35,35,37,4,6,38,6,4,36,36,36,36,36,36,36,6,0
0,6,4,32,37,37,37,34,4,6,0,0,0,6,17,29,19,12,17,29,19,6,0
0,6,6,6,6,6,6,6,6,6,0,0,0,6,6,6,6,6,6,6,6,6,0
0,0,0,0,0,0,0,0,0,0,0,0,0,0,0,0,0,0,0,0,0,0,0
:endlayer
layer: 2
0,0,0,0,0,0,0,0,0,0,0,0,0,0,0,0,0,0,0,0,0,0,0
0,6,6,39,39,6,6,39,39,6,6,6,6,6,39,39,6,6,39,39,6,6,0
0,6,40,0,0,0,0,0,0,4,0,41,9,0,0,0,0,42,43,0,12,6,0
0,39,0,0,0,0,0,0,0,4,0,41,9,0,0,0,0,0,0,0,0,39,0
0,39,0,0,44,44,0,0,0,4,0,0,4,4,0,0,0,0,0,0,45,39,0
0,6,0,0,44,44,0,0,0,4,46,0,0,4,0,0,0,47,0,0,48,6,0
0,6,0,0,44,44,0,0,0,4,49,0,0,50,0,0,0,51,0,0,52,6,0
0,39,0,0,0,0,0,0,0,30,4,4,4,30,0,0,0,28,0,0,53,39,0
0,39,0,0,0,0,0,0,0,0,0,0,0,0,0,0,0,0,0,0,0,39,0
0,6,0,0,0,0,0,0,0,0,0,0,0,0,0,0,0,0,0,0,0,6,0
0,6,4,4,4,4,30,0,0,0,0,0,0,0,0,0,30,4,4,4,4,6,0
0,6,54,0,0,0,0,0,0,0,0,0,0,0,0,0,0,12,12,12,12,6,0
0,39,0,0,0,0,0,0,0,0,0,0,0,0,0,0,0,0,0,0,0,39,0
0,39,0,0,0,0,0,0,0,30,0,0,0,30,0,0,0,0,0,55,0,39,0
0,6,0,0,0,0,0,0,0,4,0,0,0,4,0,55,0,0,0,55,0,6,0
0,6,0,0,0,0,0,0,0,4,0,0,0,4,0,55,0,0,0,55,0,6,0
0,39,0,0,0,0,0,0,0,4,0,0,0,4,0,55,0,0,0,55,0,39,0
0,39,0,0,0,0,0,0,0,4,6,56,6,4,0,0,0,0,0,0,0,39,0
0,6,57,0,0,0,0,0,58,6,0,0,0,6,0,0,0,12,0,0,0,6,0
0,6,39,39,6,6,39,39,6,6,0,0,0,6,6,39,39,6,6,39,39,6,0
0,0,0,0,0,0,0,0,0,0,0,0,0,0,0,0,0,0,0,0,0,0,0
:endlayer
layer: 3
0,59,0,0,0,0,59,0,0,0,59,0,59,0,0,0,59,0,0,0,0,59,0
60,6,6,39,39,6,6,39,39,6,6,6,6,6,39,39,6,6,39,39,6,6,61
0,6,0,0,0,62,0,0,0,4,4,9,0,62,0,0,0,62,0,0,0,6,0
0,39,0,0,0,0,0,0,0,4,4,9,0,0,0,0,0,0,0,0,0,39,0
0,39,0,0,18,0,0,0,0,4,0,4,4,4,0,0,0,0,0,0,0,39,0
60,6,0,18,18,18,0,0,0,4,63,0,0,4,0,0,0,0,0,0,0,6,61
0,6,61,0,18,0,0,0,0,4,64,0,0,4,61,0,0,0,0,0,60,6,0
0,39,0,0,0,0,0,0,0,30,4,4,4,30,0,0,0,0,0,0,0,39,0
0,39,0,0,0,0,0,0,0,0,0,0,0,0,0,0,0,0,0,0,0,39,0
0,6,0,0,0,0,59,0,0,0,0,0,0,0,0,0,0,59,0,0,0,6,0
60,6,4,4,4,4,30,0,0,0,0,0,0,0,0,0,30,4,4,4,4,6,61
0,6,0,0,0,62,0,0,0,0,0,0,0,0,0,0,0,12,12,12,12,6,0
0,39,0,0,0,0,0,0,0,0,0,0,0,0,0,0,0,0,0,0,0,39,0
0,39,0,0,0,0,0,0,0,30,0,0,0,30,0,0,0,0,0,0,0,39,0
0,6,0,0,0,0,0,0,60,4,0,0,0,4,61,0,0,0,0,0,60,6,0
60,6,61,0,0,0,0,0,0,4,0,0,0,4,0,0,0,0,0,0,0,6,61
0,39,0,0,0,0,0,0,0,4,59,0,59,4,0,0,0,0,0,0,0,39,0
0,39,0,0,0,0,0,0,0,4,6,6,6,4,0,0,0,0,0,0,0,39,0
0,6,0,0,59,0,0,0,0,6,65,66,65,6,0,0,0,59,0,0,0,6,0
60,6,39,39,6,6,39,39,6,6,0,0,0,6,6,39,39,6,6,39,39,6,61
0,62,0,0,0,62,0,0,0,62,0,0,0,62,0,0,0,62,0,0,0,62,0
:endlayer
layer: 4
0,0,0,0,0,0,0,0,0,0,0,0,0,0,0,0,0,0,0,0,0,0,0
0,6,6,6,6,6,6,6,6,6,6,6,6,6,6,6,6,6,6,6,6,6,0
0,6,0,0,0,0,67,0,0,4,9,0,0,0,0,0,67,0,0,0,0,6,0
0,6,0,0,0,0,67,0,0,4,9,0,0,0,0,0,67,0,0,0,0,6,0
0,6,0,0,21,0,67,0,0,4,4,4,4,4,0,0,67,0,0,0,0,6,0
0,6,0,21,18,21,67,0,0,4,0,0,0,4,0,0,67,0,0,0,0,6,0
0,6,0,0,21,0,67,0,0,4,0,0,0,4,0,0,67,0,0,0,0,6,0
0,6,68,68,68,68,68,68,68,67,68,68,68,68,68,68,68,68,68,68,68,6,0
0,6,0,0,0,0,67,0,0,67,0,0,0,67,0,0,67,0,0,0,0,6,0
0,6,0,0,0,0,67,0,0,67,0,0,0,67,0,0,67,0,0,0,0,6,0
0,6,4,4,4,4,68,68,68,68,68,68,68,68,68,68,4,4,4,4,4,6,0
0,6,0,0,0,0,67,0,0,67,0,0,0,67,0,0,67,4,4,4,4,6,0
0,6,0,0,0,0,67,0,0,67,0,0,0,67,0,0,67,0,0,0,0,6,0
0,6,68,68,68,68,68,68,68,67,68,68,68,67,68,68,68,68,68,68,68,6,0
0,6,0,0,0,0,67,0,0,4,0,0,0,4,0,0,67,0,0,0,0,6,0
0,6,0,0,0,0,67,0,0,4,0,0,0,4,0,0,67,0,0,0,0,6,0
0,6,0,0,0,0,67,0,0,4,0,0,0,4,0,0,67,0,0,0,0,6,0
0,6,0,0,0,0,67,0,0,4,6,6,6,4,0,0,67,0,0,0,0,6,0
0,6,0,0,0,0,67,0,0,6,6,6,6,6,0,0,67,0,0,0,0,6,0
0,6,6,6,6,6,6,6,6,6,69,65,70,6,6,6,6,6,6,6,6,6,0
0,0,0,0,0,0,0,0,0,0,0,0,0,0,0,0,0,0,0,0,0,0,0
:endlayer
layer: 5
0,0,0,0,0,0,0,0,0,0,0,0,0,0,0,0,0,0,0,0,0,0,0
0,6,6,6,6,6,6,6,6,6,6,6,6,6,6,6,6,6,6,6,6,6,0
0,6,6,6,6,6,6,6,6,9,0,0,0,0,6,6,6,6,6,6,6,6,0
0,6,6,6,6,6,6,6,6,9,0,0,0,0,6,6,6,6,6,6,6,6,0
0,6,6,6,6,6,6,6,6,6,6,6,6,6,6,6,6,6,6,6,6,6,0
0,6,6,6,6,6,6,6,6,6,6,6,6,6,6,6,6,6,6,6,6,6,0
0,6,6,6,6,6,6,6,6,6,6,6,6,6,6,6,6,6,6,6,6,6,0
0,6,6,6,6,6,6,6,6,6,6,6,6,6,6,6,6,6,6,6,6,6,0
0,6,6,6,6,6,6,6,6,6,6,6,6,6,6,6,6,6,6,6,6,6,0
0,6,6,6,6,6,6,6,6,6,6,6,6,6,6,6,6,6,6,6,6,6,0
0,6,6,6,6,6,6,6,6,6,6,6,6,6,6,6,6,6,6,6,6,6,0
0,6,6,6,6,6,6,6,6,6,6,6,6,6,6,6,6,6,6,6,6,6,0
0,6,6,6,6,6,6,6,6,6,6,6,6,6,6,6,6,6,6,6,6,6,0
0,6,6,6,6,6,6,6,6,6,6,6,6,6,6,6,6,6,6,6,6,6,0
0,6,6,6,6,6,6,6,6,6,6,6,6,6,6,6,6,6,6,6,6,6,0
0,6,6,6,6,6,6,6,6,6,6,6,6,6,6,6,6,6,6,6,6,6,0
0,6,6,6,6,6,6,6,6,6,6,6,6,6,6,6,6,6,6,6,6,6,0
0,6,6,6,6,6,6,6,6,6,6,6,6,6,6,6,6,6,6,6,6,6,0
0,6,6,6,6,6,6,6,6,6,6,6,6,6,6,6,6,6,6,6,6,6,0
0,6,6,6,6,6,6,6,6,6,6,6,6,6,6,6,6,6,6,6,6,6,0
0,0,0,0,0,0,0,0,0,0,0,0,0,0,0,0,0,0,0,0,0,0,0
:endlayer
layer: 6
0,0,0,0,0,0,0,0,0,0,0,0,0,0,0,0,0,0,0,0,0,0,0
0,71,18,18,6,6,6,6,6,6,6,6,6,6,6,6,6,6,6,18,18,71,0
0,18,0,0,6,0,0,0,0,0,0,0,0,0,18,0,72,73,6,0,0,18,0
0,18,0,0,6,0,0,0,0,0,0,0,0,0,18,0,0,0,6,0,0,18,0
0,18,0,0,6,0,0,0,18,18,18,18,18,18,18,0,0,0,6,0,0,18,0
0,18,0,0,6,0,0,0,0,0,0,0,0,0,0,0,0,12,6,0,0,18,0
0,18,0,0,6,74,74,74,0,35,35,35,35,0,0,0,0,75,6,0,0,18,0
0,18,0,0,6,4,4,9,0,35,76,44,35,0,4,77,77,4,6,0,0,18,0
0,18,0,0,6,4,4,9,0,35,44,76,35,0,77,78,79,80,6,0,0,18,0
0,18,0,0,6,81,81,0,0,35,76,44,35,0,77,78,79,80,6,0,0,18,0
0,71,0,0,6,82,83,0,0,35,44,76,35,0,4,77,77,4,6,0,0,71,0
0,18,0,0,6,0,0,0,0,35,76,44,35,0,0,0,0,84,6,0,0,18,0
0,18,0,0,6,12,0,0,0,35,44,76,35,0,0,0,0,4,6,0,0,18,0
0,18,0,0,6,12,0,0,0,35,35,35,35,0,0,0,0,33,6,0,0,18,0
0,18,0,0,6,0,21,0,0,0,0,0,0,0,0,0,0,34,6,0,0,18,0
0,18,0,0,6,4,0,0,0,0,0,0,0,32,37,37,37,34,6,0,0,18,0
0,18,0,0,6,6,6,6,6,6,6,38,6,6,6,6,6,6,6,0,0,18,0
0,18,0,0,0,0,0,0,0,0,0,0,0,0,0,0,0,0,0,0,0,18,0
0,18,0,0,0,0,0,0,0,0,0,0,0,0,0,0,0,0,0,0,0,18,0
0,71,18,18,18,18,18,18,18,71,18,18,18,71,18,18,18,18,18,18,18,71,0
0,0,0,0,0,0,0,0,0,0,0,0,0,0,0,0,0,0,0,0,0,0,0
:endlayer
layer: 7
0,0,0,0,0,0,0,0,0,0,0,0,0,0,0,0,0,0,0,0,0,0,0
0,85,0,0,6,6,39,39,6,6,39,39,39,6,6,39,39,6,6,0,0,85,0
0,0,0,0,6,0,0,0,0,0,0,0,0,0,0,0,0,0,6,0,0,0,0
0,0,0,0,39,0,0,0,0,0,0,0,0,0,0,0,0,0,39,0,0,0,0
0,0,0,0,39,0,0,0,21,0,0,0,0,0,21,0,0,0,39,0,0,0,0
0,0,0,0,39,0,0,0,0,0,0,0,0,0,0,0,0,0,39,0,0,0,0
0,0,0,0,6,0,0,0,0,0,0,0,0,0,0,0,0,0,6,0,0,0,0
0,0,0,0,6,0,0,0,0,0,0,0,0,0,18,0,0,18,6,0,0,0,0
0,0,0,0,6,0,0,0,0,0,0,0,0,0,0,0,0,0,6,0,0,0,0
0,0,0,0,6,74,74,0,0,0,0,0,0,0,0,0,0,0,6,0,0,0,0
0,85,0,0,6,81,81,0,0,0,0,0,0,0,18,0,0,18,6,0,0,85,0
0,0,0,0,6,0,0,0,0,0,0,0,0,0,0,0,0,0,6,0,0,0,0
0,0,0,0,39,0,0,0,0,0,0,0,0,0,0,0,0,86,39,0,0,0,0
0,0,0,0,39,0,0,0,0,0,0,0,0,0,0,0,0,0,39,0,0,0,0
0,0,0,0,39,0,0,0,0,0,0,0,0,0,0,0,0,0,39,0,0,0,0
0,0,0,0,6,87,0,0,0,0,0,0,0,0,0,0,0,0,6,0,0,0,0
0,0,0,0,6,6,39,39,39,6,6,88,6,6,39,39,39,6,6,0,0,0,0
0,0,0,0,0,0,0,0,0,0,0,0,0,0,0,0,0,0,0,0,0,0,0
0,0,0,0,0,0,0,0,0,0,0,0,0,0,0,0,0,0,0,0,0,0,0
0,85,0,0,0,0,0,0,0,85,0,0,0,85,0,0,0,0,0,0,0,85,0
0,0,0,0,0,0,0,0,0,0,0,0,0,0,0,0,0,0,0,0,0,0,0
:endlayer
layer: 8
0,0,0,0,0,0,0,0,0,0,0,0,0,0,0,0,0,0,0,0,0,0,0
0,85,0,0,6,6,39,39,6,6,39,39,39,6,6,39,39,6,6,0,0,85,0
0,0,0,60,6,0,0,0,0,0,0,0,0,0,0,0,0,0,6,61,0,0,0
0,0,0,0,39,0,0,0,0,0,0,0,0,0,0,0,0,0,39,0,0,0,0
0,0,0,0,39,0,0,0,0,0,0,0,0,0,0,0,0,0,39,0,0,0,0
0,0,0,0,39,0,0,0,0,0,0,0,0,0,0,0,0,0,39,0,0,0,0
0,0,0,60,6,61,0,0,0,0,89,0,0,0,0,0,0,60,6,0,0,0,0
0,0,0,0,6,0,0,0,0,0,0,0,0,0,18,0,0,18,6,61,0,0,0
0,0,0,0,6,0,0,0,0,0,0,0,0,0,0,0,0,0,6,0,0,0,0
0,0,0,0,6,0,0,0,0,0,0,0,0,0,0,0,0,0,6,0,0,0,0
0,85,0,0,6,74,74,0,0,0,0,0,0,0,18,0,0,18,6,0,0,85,0
0,0,0,60,6,81,81,0,0,0,89,0,0,0,0,0,0,60,6,61,0,0,0
0,0,0,0,39,0,0,0,0,0,0,0,0,0,0,0,0,0,39,0,0,0,0
0,0,0,0,39,0,0,0,0,0,0,0,0,0,0,0,0,0,39,0,0,0,0
0,0,0,0,39,0,0,0,0,0,0,0,0,0,0,0,0,0,39,0,0,0,0
0,0,0,60,6,0,0,0,0,59,0,0,0,59,0,0,0,0,6,61,0,0,0
0,0,0,0,6,6,39,39,39,6,6,6,6,6,39,39,39,6,6,0,0,0,0
0,0,0,0,0,62,0,0,0,62,0,0,0,62,0,0,0,62,0,0,0,0,0
0,0,0,0,0,0,0,0,0,0,0,0,0,0,0,0,0,0,0,0,0,0,0
0,85,0,0,0,0,0,0,0,85,0,0,0,85,0,0,0,0,0,0,0,85,0
0,0,0,0,0,0,0,0,0,0,0,0,0,0,0,0,0,0,0,0,0,0,0
:endlayer
layer: 9
0,0,0,0,0,0,0,0,0,0,0,0,0,0,0,0,0,0,0,0,0,0,0
0,85,0,0,6,6,6,6,6,6,6,6,6,6,6,6,6,6,6,0,0,85,0
0,0,0,0,6,0,0,0,0,0,0,0,0,0,0,0,0,0,6,0,0,0,0
0,0,0,0,6,0,0,0,0,0,0,0,0,0,0,0,0,0,6,0,0,0,0
0,0,0,0,6,0,0,0,0,0,0,0,0,0,0,0,0,0,6,0,0,0,0
0,0,0,0,6,0,0,0,0,0,0,0,0,0,0,0,0,0,6,0,0,0,0
0,0,0,0,6,0,0,0,0,0,18,0,0,0,0,0,0,0,6,0,0,0,0
0,0,0,0,6,0,0,0,0,0,0,0,0,60,80,90,90,80,6,0,0,0,0
0,0,0,0,6,0,0,0,0,0,0,0,0,0,90,90,90,90,6,0,0,0,0
0,0,0,0,6,0,0,0,0,0,0,0,0,0,90,90,90,90,6,0,0,0,0
0,85,0,0,6,0,0,0,0,0,0,0,0,60,80,90,90,80,6,0,0,85,0
0,0,0,0,6,74,74,0,0,0,18,0,0,0,0,0,0,0,6,0,0,0,0
0,0,0,0,6,81,81,0,0,0,0,0,0,0,0,0,0,0,6,0,0,0,0
0,0,0,0,6,0,0,0,0,0,0,0,0,0,0,0,0,0,6,0,0,0,0
0,0,0,0,6,0,0,0,0,0,0,0,0,0,0,0,0,0,6,0,0,0,0
0,0,0,0,6,0,0,0,0,0,0,0,0,0,0,0,0,0,6,0,0,0,0
0,0,0,0,6,6,6,6,6,6,6,6,6,6,6,6,6,6,6,0,0,0,0
0,0,0,0,0,0,0,0,0,0,0,0,0,0,0,0,0,0,0,0,0,0,0
0,0,0,0,0,0,0,0,0,0,0,0,0,0,0,0,0,0,0,0,0,0,0
0,85,0,0,0,0,0,0,0,85,0,0,0,85,0,0,0,0,0,0,0,85,0
0,0,0,0,0,0,0,0,0,0,0,0,0,0,0,0,0,0,0,0,0,0,0
:endlayer
layer: 10
74,74,74,74,74,74,74,74,74,74,74,74,74,74,74,74,74,74,74,74,74,74,74
91,4,4,4,4,4,4,4,4,4,4,4,4,4,4,4,4,4,4,4,4,4,9
91,4,4,4,4,4,4,4,4,4,4,4,4,4,4,4,4,4,4,4,4,4,9
91,4,4,4,4,4,4,4,4,4,4,4,4,4,4,4,4,4,4,4,4,4,9
91,4,4,4,4,4,4,4,4,4,4,4,4,4,4,4,4,4,4,4,4,4,9
91,4,4,4,4,4,4,4,4,4,4,4,4,4,4,4,4,4,4,4,4,4,9
91,4,4,4,4,4,4,4,4,4,4,4,4,4,4,4,4,4,4,4,4,4,9
91,4,4,4,4,0,0,4,4,4,4,4,4,4,4,4,4,4,4,4,4,4,9
91,4,4,4,4,0,0,4,4,4,4,4,4,4,4,4,4,4,4,4,4,4,9
91,4,4,4,4,0,0,4,4,4,4,4,4,4,4,4,4,4,4,4,4,4,9
91,4,4,4,4,0,0,4,4,4,4,4,4,4,4,4,4,4,4,4,4,4,9
91,4,4,4,4,0,0,4,4,4,4,4,4,4,4,4,4,4,4,4,4,4,9
91,4,4,4,4,74,74,4,4,4,4,4,4,4,4,4,4,4,4,4,4,4,9
91,4,4,4,4,4,4,4,4,4,4,4,4,4,4,4,4,4,4,4,4,4,9
91,4,4,4,4,4,4,4,4,4,4,4,4,4,4,4,4,4,4,4,4,4,9
91,4,4,4,4,4,4,4,4,4,4,4,4,4,4,4,4,4,4,4,4,4,9
91,4,4,4,4,4,4,4,4,4,4,4,4,4,4,4,4,4,4,4,4,4,9
91,4,4,4,4,4,4,4,4,4,4,4,4,4,4,4,4,4,4,4,4,4,9
91,4,4,4,4,4,4,4,4,4,4,4,4,4,4,4,4,4,4,4,4,4,9
91,4,4,4,4,4,4,4,4,4,4,4,4,4,4,4,4,4,4,4,4,4,9
22,22,22,22,22,22,22,22,22,22,22,22,22,22,22,22,22,22,22,22,22,22,9
:endlayer
layer: 11
0,0,0,0,0,0,0,0,0,0,0,0,0,0,0,0,0,0,0,0,0,0,0
0,91,74,74,74,74,74,74,74,74,74,74,74,74,74,74,74,74,74,74,74,74,0
0,91,4,4,4,4,4,4,4,4,4,4,4,4,4,4,4,4,4,4,4,9,0
0,91,4,4,4,4,4,4,4,4,4,4,4,4,4,4,4,4,4,4,4,9,0
0,91,4,4,12,0,92,93,94,94,94,94,94,95,12,12,12,94,96,4,4,9,0
0,91,4,4,12,21,0,0,0,0,0,0,0,0,0,0,0,21,96,4,4,9,0
0,91,4,4,18,18,18,18,0,0,0,0,0,0,0,0,0,0,25,4,4,9,0
0,91,4,4,0,0,0,18,0,0,96,97,97,97,97,98,0,0,99,4,4,9,0
0,91,4,12,0,0,0,18,0,0,96,94,94,94,94,94,0,0,0,0,4,9,0
0,91,4,0,0,0,0,18,0,0,0,0,0,0,0,0,0,0,0,0,4,9,0
0,91,4,0,0,0,0,18,0,0,0,0,0,0,0,0,0,0,0,0,4,9,0
0,91,4,0,0,0,0,18,0,0,0,0,0,0,0,0,0,0,0,0,4,9,0
0,91,4,12,0,0,0,18,0,0,97,97,97,97,97,98,0,0,0,0,4,9,0
0,91,4,4,0,0,0,18,0,0,94,94,94,94,94,94,0,0,100,4,4,9,0
0,91,4,4,0,0,0,0,0,0,0,0,0,0,0,0,0,0,96,4,4,9,0
0,91,4,4,0,21,0,0,0,0,0,21,0,0,0,0,0,21,96,4,4,9,0
0,91,4,4,0,0,0,0,0,0,0,0,0,0,101,12,12,97,97,4,4,9,0
0,91,4,4,4,4,4,4,4,98,97,97,97,96,4,4,4,4,4,4,4,9,0
0,91,4,4,4,4,4,4,4,4,4,4,4,4,4,4,4,4,4,4,4,9,0
0,22,22,22,22,22,22,22,22,22,22,22,22,22,22,22,22,22,22,22,22,9,0
0,0,0,0,0,0,0,0,0,0,0,0,0,0,0,0,0,0,0,0,0,0,0
:endlayer
layer: 12
0,0,0,0,0,0,0,0,0,0,0,0,0,0,0,0,0,0,0,0,0,0,0
0,0,0,0,0,0,0,0,0,0,0,0,0,0,0,0,0,0,0,0,0,0,0
0,0,74,74,74,74,74,74,74,74,74,74,74,74,74,74,74,74,74,74,9,0,0
0,0,91,4,4,4,4,4,4,4,4,4,4,4,4,4,4,4,4,4,9,0,0
0,0,91,4,12,0,0,0,0,102,0,0,0,0,12,12,12,0,103,4,9,0,0
0,0,91,4,12,0,0,0,0,0,0,0,0,0,0,0,0,0,0,4,9,0,0
0,0,91,4,0,0,0,0,0,0,0,0,0,0,0,0,0,0,0,4,9,0,0
0,0,91,4,0,0,0,0,0,0,0,44,104,0,0,103,0,0,0,4,9,0,0
0,0,4,12,0,0,0,0,0,0,104,0,0,102,0,0,0,0,0,0,4,0,0
0,0,39,0,0,0,0,0,0,0,0,0,0,0,0,0,0,0,0,0,39,0,0
0,0,39,0,0,0,0,0,0,0,0,0,0,0,0,0,0,0,0,0,39,0,0
0,0,39,0,0,0,0,0,0,0,0,0,0,0,0,0,0,0,0,0,39,0,0
0,0,4,12,0,0,0,0,0,0,105,36,0,35,0,104,0,0,0,0,4,0,0
0,0,91,4,0,0,0,0,0,0,0,104,0,0,106,0,0,0,0,4,9,0,0
0,0,91,4,0,0,0,0,0,0,0,0,0,0,0,0,0,0,106,4,9,0,0
0,0,91,4,0,0,0,0,0,0,0,0,0,0,0,0,0,0,0,4,9,0,0
0,0,91,4,0,0,0,0,0,0,0,0,0,0,0,12,12,104,0,4,9,0,0
0,0,91,4,4,4,4,4,4,0,0,0,0,0,4,4,4,4,4,4,9,0,0
0,0,91,22,22,22,22,22,22,4,39,39,39,4,22,22,22,22,22,22,22,0,0
0,0,0,0,0,0,0,0,0,0,0,0,0,0,0,0,0,0,0,0,0,0,0
0,0,0,0,0,0,0,0,0,0,0,0,0,0,0,0,0,0,0,0,0,0,0
:endlayer
layer: 13
0,0,0,0,0,0,0,0,0,0,0,0,0,0,0,0,0,0,0,0,0,0,0
0,0,0,0,0,0,0,0,0,0,0,0,0,0,0,0,0,0,0,0,0,0,0
0,0,0,0,0,0,0,0,0,0,0,0,0,0,0,0,0,0,0,0,0,0,0
0,0,0,91,74,74,74,74,74,74,74,74,74,74,74,74,74,74,74,74,0,0,0
0,0,0,91,81,81,81,81,81,81,81,81,81,81,81,81,81,81,41,9,0,0,0
0,0,0,91,107,0,0,0,0,0,0,0,0,0,0,0,0,0,41,9,0,0,0
0,0,0,91,107,0,0,0,0,0,0,0,0,0,0,0,0,0,41,9,0,0,0
0,0,0,91,107,0,0,0,0,0,0,0,89,0,0,0,0,0,41,9,0,0,0
0,60,4,81,81,0,0,0,0,0,0,0,0,0,0,0,0,0,81,81,4,61,0
0,0,39,0,0,0,0,0,0,0,0,0,0,0,0,0,0,0,0,0,39,0,0
0,0,39,0,0,0,0,0,0,89,0,0,0,0,0,89,0,0,0,0,39,0,0
0,0,39,0,0,0,0,0,0,0,0,0,0,0,0,0,0,0,0,0,39,0,0
0,60,4,108,107,0,0,0,0,0,0,0,0,0,0,0,0,0,108,108,4,61,0
0,0,0,91,107,0,0,0,0,0,0,0,89,0,0,0,0,0,41,9,0,0,0
0,0,0,91,107,0,0,0,0,0,0,0,0,0,0,0,0,0,41,9,0,0,0
0,0,0,91,107,0,0,0,0,0,0,0,0,0,0,0,0,0,41,9,0,0,0
0,0,0,91,108,108,108,108,108,107,0,0,0,41,108,108,108,108,41,9,0,0,0
0,0,0,22,22,22,22,22,22,107,0,0,0,41,22,22,22,22,22,9,0,0,0
0,0,0,0,0,0,0,0,0,4,39,39,39,4,0,0,0,0,0,0,0,0,0
0,0,0,0,0,0,0,0,0,62,0,0,0,62,0,0,0,0,0,0,0,0,0
0,0,0,0,0,0,0,0,0,0,0,0,0,0,0,0,0,0,0,0,0,0,0
:endlayer
layer: 14
0,0,0,0,0,0,0,0,0,0,0,0,0,0,0,0,0,0,0,0,0,0,0
0,0,0,0,0,0,0,0,0,0,0,0,0,0,0,0,0,0,0,0,0,0,0
0,0,0,0,0,0,0,0,0,0,0,0,0,0,0,0,0,0,0,0,0,0,0
0,0,0,0,0,0,0,0,0,0,0,0,0,0,0,0,0,0,0,0,0,0,0
0,0,0,0,91,74,74,74,74,74,74,74,74,74,74,74,74,74,74,0,0,0,0
0,0,0,0,91,4,4,4,4,4,4,4,4,4,4,4,4,4,9,0,0,0,0
0,0,0,0,91,4,0,0,0,0,0,0,0,0,0,0,0,4,9,0,0,0,0
0,0,0,0,91,4,0,0,0,0,0,0,18,0,0,0,0,4,9,0,0,0,0
0,0,74,74,74,4,0,0,0,0,0,0,0,0,0,0,0,4,74,74,9,0,0
0,0,91,4,4,4,0,0,0,0,0,0,0,0,0,0,0,4,4,4,9,0,0
0,0,91,4,4,4,0,0,0,18,0,0,0,0,0,18,0,4,4,4,9,0,0
0,0,91,4,4,4,0,0,0,0,0,0,0,0,0,0,0,4,4,4,9,0,0
0,0,91,22,22,4,0,0,0,0,0,0,0,0,0,0,0,4,22,22,9,0,0
0,0,0,0,91,4,0,0,0,0,0,0,18,0,0,0,0,4,9,0,0,0,0
0,0,0,0,91,4,0,0,0,0,0,0,0,0,0,0,0,4,9,0,0,0,0
0,0,0,0,91,4,4,4,4,4,4,4,4,4,4,4,4,4,9,0,0,0,0
0,0,0,0,22,22,22,22,22,91,4,4,4,9,22,22,22,22,9,0,0,0,0
0,0,0,0,0,0,0,0,0,91,4,4,4,9,0,0,0,0,0,0,0,0,0
0,0,0,0,0,0,0,0,0,91,22,22,22,22,0,0,0,0,0,0,0,0,0
0,0,0,0,0,0,0,0,0,0,0,0,0,0,0,0,0,0,0,0,0,0,0
0,0,0,0,0,0,0,0,0,0,0,0,0,0,0,0,0,0,0,0,0,0,0
:endlayer
layer: 15
0,0,0,0,0,0,0,0,0,0,0,0,0,0,0,0,0,0,0,0,0,0,0
0,0,0,0,0,0,0,0,0,0,0,0,0,0,0,0,0,0,0,0,0,0,0
0,0,0,0,0,0,0,0,0,0,0,0,0,0,0,0,0,0,0,0,0,0,0
0,0,0,0,0,0,0,0,0,0,0,0,0,0,0,0,0,0,0,0,0,0,0
0,0,0,0,0,0,0,0,0,0,0,0,0,0,0,0,0,0,0,0,0,0,0
0,0,0,0,0,74,74,74,74,74,74,74,74,74,74,74,74,9,0,0,0,0,0
0,0,0,0,0,91,4,4,4,4,4,4,4,4,4,4,4,9,0,0,0,0,0
0,0,0,0,0,91,4,0,0,0,0,0,18,0,0,0,4,9,0,0,0,0,0
0,0,0,0,0,91,4,0,0,0,0,0,0,0,0,0,4,9,0,0,0,0,0
0,0,0,74,74,74,4,0,0,0,0,0,0,0,0,0,4,74,74,74,0,0,0
0,0,0,91,4,4,4,0,0,18,0,0,0,0,0,18,4,4,4,9,0,0,0
0,0,0,91,22,22,4,0,0,0,0,0,0,0,0,0,4,22,22,22,0,0,0
0,0,0,0,0,91,4,0,0,0,0,0,0,0,0,0,4,9,0,0,0,0,0
0,0,0,0,0,91,4,0,0,0,0,0,18,0,0,0,4,9,0,0,0,0,0
0,0,0,0,0,91,4,4,4,4,4,4,4,4,4,4,4,9,0,0,0,0,0
0,0,0,0,0,91,22,22,22,22,91,4,9,22,22,22,22,9,0,0,0,0,0
0,0,0,0,0,0,0,0,0,0,91,4,9,0,0,0,0,0,0,0,0,0,0
0,0,0,0,0,0,0,0,0,0,91,22,22,0,0,0,0,0,0,0,0,0,0
0,0,0,0,0,0,0,0,0,0,0,0,0,0,0,0,0,0,0,0,0,0,0
0,0,0,0,0,0,0,0,0,0,0,0,0,0,0,0,0,0,0,0,0,0,0
0,0,0,0,0,0,0,0,0,0,0,0,0,0,0,0,0,0,0,0,0,0,0
:endlayer
layer: 16
0,0,0,0,0,0,0,0,0,0,0,0,0,0,0,0,0,0,0,0,0,0,0
0,0,0,0,0,0,0,0,0,0,0,0,0,0,0,0,0,0,0,0,0,0,0
0,0,0,0,0,0,0,0,0,0,0,0,0,0,0,0,0,0,0,0,0,0,0
0,0,0,0,0,0,0,0,0,0,0,0,0,0,0,0,0,0,0,0,0,0,0
0,0,0,0,0,0,0,0,0,0,0,0,0,0,0,0,0,0,0,0,0,0,0
0,0,0,0,0,0,0,0,0,0,0,0,0,0,0,0,0,0,0,0,0,0,0
0,0,0,0,0,0,74,74,74,74,74,74,74,74,74,74,9,0,0,0,0,0,0
0,0,0,0,0,0,91,4,4,4,4,4,4,4,4,4,9,0,0,0,0,0,0
0,0,0,0,0,0,91,4,4,4,4,4,4,4,4,4,9,0,0,0,0,0,0
0,0,0,0,0,0,91,4,4,4,4,4,4,4,4,4,9,0,0,0,0,0,0
0,0,0,0,77,77,91,4,4,4,4,4,4,4,4,4,9,77,77,0,0,0,0
0,0,0,0,0,0,91,4,4,4,4,4,4,4,4,4,9,0,0,0,0,0,0
0,0,0,0,0,0,91,4,4,4,4,4,4,4,4,4,9,0,0,0,0,0,0
0,0,0,0,0,0,91,4,4,4,4,4,4,4,4,4,9,0,0,0,0,0,0
0,0,0,0,0,0,91,22,22,22,22,22,22,22,22,22,22,0,0,0,0,0,0
0,0,0,0,0,0,0,0,0,0,0,77,0,0,0,0,0,0,0,0,0,0,0
0,0,0,0,0,0,0,0,0,0,0,77,0,0,0,0,0,0,0,0,0,0,0
0,0,0,0,0,0,0,0,0,0,0,0,0,0,0,0,0,0,0,0,0,0,0
0,0,0,0,0,0,0,0,0,0,0,0,0,0,0,0,0,0,0,0,0,0,0
0,0,0,0,0,0,0,0,0,0,0,0,0,0,0,0,0,0,0,0,0,0,0
0,0,0,0,0,0,0,0,0,0,0,0,0,0,0,0,0,0,0,0,0,0,0
:endlayer
layer: 17
0,0,0,0,0,0,0,0,0,0,0,0,0,0,0,0,0,0,0,0,0,0,0
0,0,0,0,0,0,0,0,0,0,0,0,0,0,0,0,0,0,0,0,0,0,0
0,0,0,0,0,0,0,0,0,0,0,0,0,0,0,0,0,0,0,0,0,0,0
0,0,0,0,0,0,0,0,0,0,0,0,0,0,0,0,0,0,0,0,0,0,0
0,0,0,0,0,0,0,0,0,0,0,0,0,0,0,0,0,0,0,0,0,0,0
0,0,0,0,0,0,0,0,0,0,0,0,0,0,0,0,0,0,0,0,0,0,0
0,0,0,0,0,0,0,0,0,0,0,0,0,0,0,0,0,0,0,0,0,0,0
0,0,0,0,0,0,0,21,0,0,0,21,0,0,0,21,0,0,0,0,0,0,0
0,0,0,0,0,0,0,0,0,0,0,0,0,0,0,0,0,0,0,0,0,0,0
0,0,0,0,0,0,0,0,0,0,0,0,0,0,0,0,0,0,0,0,0,0,0
0,0,0,0,0,0,0,21,0,0,0,21,0,0,0,21,0,0,0,0,0,0,0
0,0,0,0,0,0,0,0,0,0,0,0,0,0,0,0,0,0,0,0,0,0,0
0,0,0,0,0,0,0,0,0,0,0,0,0,0,0,0,0,0,0,0,0,0,0
0,0,0,0,0,0,0,21,0,0,0,21,0,0,0,21,0,0,0,0,0,0,0
0,0,0,0,0,0,0,0,0,0,0,0,0,0,0,0,0,0,0,0,0,0,0
0,0,0,0,0,0,0,0,0,0,0,0,0,0,0,0,0,0,0,0,0,0,0
0,0,0,0,0,0,0,0,0,0,0,0,0,0,0,0,0,0,0,0,0,0,0
0,0,0,0,0,0,0,0,0,0,0,0,0,0,0,0,0,0,0,0,0,0,0
0,0,0,0,0,0,0,0,0,0,0,0,0,0,0,0,0,0,0,0,0,0,0
0,0,0,0,0,0,0,0,0,0,0,0,0,0,0,0,0,0,0,0,0,0,0
0,0,0,0,0,0,0,0,0,0,0,0,0,0,0,0,0,0,0,0,0,0,0
:endlayer

#### RULES ####
rule:
plugin=vanillaBlocks
number=1
data:
JSON:{blockState:{blockName:"minecraft:grass",properties:{snowy:"false"}},buildPass:0}
:enddata
:endrule

rule:
plugin=vanillaBlocks
number=2
data:
JSON:{blockState:{blockName:"minecraft:dirt",properties:{variant:"dirt",snowy:"false"}},buildPass:0}
:enddata
:endrule

rule:
plugin=vanillaBlocks
number=3
data:
JSON:{blockState:{blockName:"minecraft:sandstone",properties:{type:"smooth_sandstone"}},buildPass:0}
:enddata
:endrule

rule:
plugin=vanillaBlocks
number=4
data:
JSON:{blockState:{blockName:"minecraft:planks",properties:{variant:"oak"}},buildPass:0}
:enddata
:endrule

rule:
plugin=vanillaBlocks
number=5
data:
JSON:{blockState:{blockName:"minecraft:gravel",properties:{}},buildPass:0}
:enddata
:endrule

rule:
plugin=vanillaBlocks
number=6
data:
JSON:{blockState:{blockName:"minecraft:stonebrick",properties:{variant:"stonebrick"}},buildPass:0}
:enddata
:endrule

rule:
plugin=vanillaBlocks
number=7
data:
JSON:{blockState:{blockName:"minecraft:stone_slab",properties:{half:"top",variant:"quartz"}},buildPass:0}
:enddata
:endrule

rule:
plugin=inventory
number=8
data:
JSON:{blockState:{blockName:"minecraft:chest",properties:{facing:"east"}},buildPass:0,lootLevel:1,teData:{x:30,y:83,z:-23,id:"Chest"},inventoryData:{length:27,inventoryContents:[]}}
:enddata
:endrule

rule:
plugin=vanillaBlocks
number=9
data:
JSON:{blockState:{blockName:"minecraft:oak_stairs",properties:{half:"bottom",shape:"straight",facing:"west"}},buildPass:0}
:enddata
:endrule

rule:
plugin=vanillaBlocks
number=10
data:
JSON:{blockState:{blockName:"minecraft:trapdoor",properties:{half:"top",facing:"west",open:"true"}},buildPass:2}
:enddata
:endrule

rule:
plugin=vanillaBlocks
number=11
data:
JSON:{blockState:{blockName:"minecraft:trapdoor",properties:{half:"top",facing:"east",open:"true"}},buildPass:2}
:enddata
:endrule

rule:
plugin=vanillaBlocks
number=12
data:
JSON:{blockState:{blockName:"minecraft:bookshelf",properties:{}},buildPass:0}
:enddata
:endrule

rule:
plugin=vanillaBlocks
number=13
data:
JSON:{blockState:{blockName:"minecraft:spruce_stairs",properties:{half:"bottom",shape:"straight",facing:"north"}},buildPass:0}
:enddata
:endrule

rule:
plugin=inventory
number=14
data:
JSON:{blockState:{blockName:"minecraft:chest",properties:{facing:"east"}},buildPass:0,lootLevel:1,teData:{x:30,y:83,z:-22,id:"Chest"},inventoryData:{length:27,inventoryContents:[]}}
:enddata
:endrule

rule:
plugin=vanillaBlocks
number=15
data:
JSON:{blockState:{blockName:"minecraft:trapdoor",properties:{half:"top",facing:"south",open:"true"}},buildPass:2}
:enddata
:endrule

rule:
plugin=vanillaBlocks
number=16
data:
JSON:{blockState:{blockName:"minecraft:trapdoor",properties:{half:"top",facing:"north",open:"true"}},buildPass:2}
:enddata
:endrule

rule:
plugin=vanillaBlocks
number=17
data:
JSON:{blockState:{blockName:"minecraft:spruce_stairs",properties:{half:"bottom",shape:"straight",facing:"west"}},buildPass:0}
:enddata
:endrule

rule:
plugin=vanillaBlocks
number=18
data:
JSON:{blockState:{blockName:"minecraft:fence",properties:{east:"false",south:"false",north:"false",west:"false"}},buildPass:0}
:enddata
:endrule

rule:
plugin=vanillaBlocks
number=19
data:
JSON:{blockState:{blockName:"minecraft:spruce_stairs",properties:{half:"bottom",shape:"straight",facing:"east"}},buildPass:0}
:enddata
:endrule

rule:
plugin=blockTile
number=20
data:
JSON:{blockState:{blockName:"minecraft:furnace",properties:{facing:"west"}},buildPass:0,teData:{CookTime:0s,BurnTime:0s,x:28,y:83,Items:[],z:-21,id:"Furnace"}}
:enddata
:endrule

rule:
plugin=vanillaBlocks
number=21
data:
JSON:{blockState:{blockName:"minecraft:torch",properties:{facing:"up"}},buildPass:2}
:enddata
:endrule

rule:
plugin=vanillaBlocks
number=22
data:
JSON:{blockState:{blockName:"minecraft:oak_stairs",properties:{half:"bottom",shape:"straight",facing:"north"}},buildPass:0}
:enddata
:endrule

rule:
plugin=blockTile
number=23
data:
JSON:{blockState:{blockName:"minecraft:furnace",properties:{facing:"west"}},buildPass:0,teData:{CookTime:0s,BurnTime:0s,x:28,y:83,Items:[],z:-20,id:"Furnace"}}
:enddata
:endrule

rule:
plugin=inventory
number=24
data:
JSON:{blockState:{blockName:"minecraft:chest",properties:{facing:"east"}},buildPass:0,lootLevel:1,teData:{x:30,y:83,z:-20,id:"Chest"},inventoryData:{length:27,inventoryContents:[]}}
:enddata
:endrule

rule:
plugin=vanillaBlocks
number=25
data:
JSON:{blockState:{blockName:"minecraft:crafting_table",properties:{}},buildPass:0}
:enddata
:endrule

rule:
plugin=inventory
number=26
data:
JSON:{blockState:{blockName:"minecraft:chest",properties:{facing:"east"}},buildPass:0,lootLevel:1,teData:{x:30,y:83,z:-19,id:"Chest"},inventoryData:{length:27,inventoryContents:[]}}
:enddata
:endrule

rule:
plugin=doors
number=27
data:
JSON:{blockState:{blockName:"minecraft:wooden_door",properties:{hinge:"left",half:"lower",powered:"false",facing:"west",open:"false"}},buildPass:2}
:enddata
:endrule

rule:
plugin=vanillaBlocks
number=28
data:
JSON:{blockState:{blockName:"minecraft:brown_mushroom",properties:{}},buildPass:2}
:enddata
:endrule

rule:
plugin=vanillaBlocks
number=29
data:
JSON:{blockState:{blockName:"minecraft:spruce_stairs",properties:{half:"bottom",shape:"straight",facing:"south"}},buildPass:0}
:enddata
:endrule

rule:
plugin=vanillaBlocks
number=30
data:
JSON:{blockState:{blockName:"minecraft:log",properties:{variant:"oak",axis:"y"}},buildPass:0}
:enddata
:endrule

rule:
plugin=vanillaBlocks
number=31
data:
JSON:{blockState:{blockName:"minecraft:cauldron",properties:{level:"0"}},buildPass:0}
:enddata
:endrule

rule:
plugin=vanillaBlocks
number=32
data:
JSON:{blockState:{blockName:"minecraft:birch_stairs",properties:{half:"bottom",shape:"straight",facing:"west"}},buildPass:0}
:enddata
:endrule

rule:
plugin=vanillaBlocks
number=33
data:
JSON:{blockState:{blockName:"minecraft:birch_stairs",properties:{half:"bottom",shape:"straight",facing:"north"}},buildPass:0}
:enddata
:endrule

rule:
plugin=vanillaBlocks
number=34
data:
JSON:{blockState:{blockName:"minecraft:birch_stairs",properties:{half:"bottom",shape:"straight",facing:"east"}},buildPass:0}
:enddata
:endrule

rule:
plugin=vanillaBlocks
number=35
data:
JSON:{blockState:{blockName:"minecraft:carpet",properties:{color:"green"}},buildPass:2}
:enddata
:endrule

rule:
plugin=vanillaBlocks
number=36
data:
JSON:{blockState:{blockName:"minecraft:carpet",properties:{color:"light_blue"}},buildPass:2}
:enddata
:endrule

rule:
plugin=vanillaBlocks
number=37
data:
JSON:{blockState:{blockName:"minecraft:birch_stairs",properties:{half:"bottom",shape:"straight",facing:"south"}},buildPass:0}
:enddata
:endrule

rule:
plugin=doors
number=38
data:
JSON:{blockState:{blockName:"minecraft:wooden_door",properties:{hinge:"left",half:"lower",powered:"false",facing:"north",open:"false"}},buildPass:2}
:enddata
:endrule

rule:
plugin=vanillaBlocks
number=39
data:
JSON:{blockState:{blockName:"minecraft:stained_glass_pane",properties:{east:"false",color:"white",south:"false",north:"false",west:"false"}},buildPass:0}
:enddata
:endrule

rule:
plugin=vanillaFlowerPot
number=40
data:
JSON:{blockState:{blockName:"minecraft:flower_pot",properties:{}},itemName:"minecraft:red_flower",buildPass:0,itemMeta:3}
:enddata
:endrule

rule:
plugin=vanillaBlocks
number=41
data:
JSON:{blockState:{blockName:"minecraft:oak_stairs",properties:{half:"top",shape:"straight",facing:"east"}},buildPass:0}
:enddata
:endrule

rule:
plugin=vanillaBlocks
number=42
data:
JSON:{blockState:{blockName:"minecraft:sapling",properties:{stage:"0",type:"spruce"}},buildPass:0}
:enddata
:endrule

rule:
plugin=vanillaBlocks
number=43
data:
JSON:{blockState:{blockName:"minecraft:sapling",properties:{stage:"1",type:"oak"}},buildPass:0}
:enddata
:endrule

rule:
plugin=vanillaBlocks
number=44
data:
JSON:{blockState:{blockName:"minecraft:carpet",properties:{color:"silver"}},buildPass:2}
:enddata
:endrule

rule:
plugin=vanillaBlocks
number=45
data:
JSON:{blockState:{blockName:"minecraft:sapling",properties:{stage:"1",type:"jungle"}},buildPass:0}
:enddata
:endrule

rule:
plugin=inventory
number=46
data:
JSON:{blockState:{blockName:"minecraft:chest",properties:{facing:"east"}},buildPass:0,lootLevel:1,teData:{x:30,y:84,z:-20,id:"Chest"},inventoryData:{length:27,inventoryContents:[]}}
:enddata
:endrule

rule:
plugin=vanillaBlocks
number=47
data:
JSON:{blockState:{blockName:"minecraft:red_mushroom",properties:{}},buildPass:2}
:enddata
:endrule

rule:
plugin=vanillaBlocks
number=48
data:
JSON:{blockState:{blockName:"minecraft:sapling",properties:{stage:"0",type:"acacia"}},buildPass:0}
:enddata
:endrule

rule:
plugin=inventory
number=49
data:
JSON:{blockState:{blockName:"minecraft:chest",properties:{facing:"east"}},buildPass:0,lootLevel:1,teData:{x:30,y:84,z:-19,id:"Chest"},inventoryData:{length:27,inventoryContents:[]}}
:enddata
:endrule

rule:
plugin=doors
number=50
data:
JSON:{blockState:{blockName:"minecraft:wooden_door",properties:{hinge:"left",half:"upper",powered:"false",facing:"north",open:"false"}},buildPass:2}
:enddata
:endrule

rule:
plugin=vanillaBlocks
number=51
data:
JSON:{blockState:{blockName:"minecraft:red_flower",properties:{type:"blue_orchid"}},buildPass:2}
:enddata
:endrule

rule:
plugin=vanillaBlocks
number=52
data:
JSON:{blockState:{blockName:"minecraft:sapling",properties:{stage:"1",type:"birch"}},buildPass:0}
:enddata
:endrule

rule:
plugin=vanillaBlocks
number=53
data:
JSON:{blockState:{blockName:"minecraft:sapling",properties:{stage:"1",type:"dark_oak"}},buildPass:0}
:enddata
:endrule

rule:
plugin=vanillaFlowerPot
number=54
data:
JSON:{blockState:{blockName:"minecraft:flower_pot",properties:{}},itemName:"minecraft:sapling",buildPass:0,itemMeta:2}
:enddata
:endrule

rule:
plugin=vanillaBlocks
number=55
data:
JSON:{blockState:{blockName:"minecraft:carpet",properties:{color:"blue"}},buildPass:2}
:enddata
:endrule

rule:
plugin=doors
number=56
data:
JSON:{blockState:{blockName:"minecraft:wooden_door",properties:{hinge:"left",half:"upper",powered:"false",facing:"north",open:"false"}},buildPass:2}
:enddata
:endrule

rule:
plugin=vanillaFlowerPot
number=57
data:
JSON:{blockState:{blockName:"minecraft:flower_pot",properties:{}},itemName:"minecraft:red_flower",buildPass:0,itemMeta:0}
:enddata
:endrule

rule:
plugin=vanillaFlowerPot
number=58
data:
JSON:{blockState:{blockName:"minecraft:flower_pot",properties:{}},itemName:"minecraft:sapling",buildPass:0,itemMeta:3}
:enddata
:endrule

rule:
plugin=vanillaBlocks
number=59
data:
JSON:{blockState:{blockName:"minecraft:torch",properties:{facing:"north"}},buildPass:2}
:enddata
:endrule

rule:
plugin=vanillaBlocks
number=60
data:
JSON:{blockState:{blockName:"minecraft:torch",properties:{facing:"west"}},buildPass:2}
:enddata
:endrule

rule:
plugin=vanillaBlocks
number=61
data:
JSON:{blockState:{blockName:"minecraft:torch",properties:{facing:"east"}},buildPass:2}
:enddata
:endrule

rule:
plugin=vanillaBlocks
number=62
data:
JSON:{blockState:{blockName:"minecraft:torch",properties:{facing:"south"}},buildPass:2}
:enddata
:endrule

rule:
plugin=inventory
number=63
data:
JSON:{blockState:{blockName:"minecraft:chest",properties:{facing:"east"}},buildPass:0,lootLevel:1,teData:{x:30,y:85,z:-20,id:"Chest"},inventoryData:{length:27,inventoryContents:[]}}
:enddata
:endrule

rule:
plugin=inventory
number=64
data:
JSON:{blockState:{blockName:"minecraft:chest",properties:{facing:"east"}},buildPass:0,lootLevel:1,teData:{x:30,y:85,z:-19,id:"Chest"},inventoryData:{length:27,inventoryContents:[]}}
:enddata
:endrule

rule:
plugin=vanillaBlocks
number=65
data:
JSON:{blockState:{blockName:"minecraft:stone_brick_stairs",properties:{half:"top",shape:"straight",facing:"north"}},buildPass:0}
:enddata
:endrule

rule:
plugin=vanillaBlocks
number=66
data:
JSON:{blockState:{blockName:"minecraft:stone_slab",properties:{half:"top",variant:"stone_brick"}},buildPass:0}
:enddata
:endrule

rule:
plugin=vanillaBlocks
number=67
data:
JSON:{blockState:{blockName:"minecraft:log",properties:{variant:"oak",axis:"z"}},buildPass:0}
:enddata
:endrule

rule:
plugin=vanillaBlocks
number=68
data:
JSON:{blockState:{blockName:"minecraft:log",properties:{variant:"oak",axis:"x"}},buildPass:0}
:enddata
:endrule

rule:
plugin=vanillaBlocks
number=69
data:
JSON:{blockState:{blockName:"minecraft:stone_brick_stairs",properties:{half:"top",shape:"straight",facing:"west"}},buildPass:0}
:enddata
:endrule

rule:
plugin=vanillaBlocks
number=70
data:
JSON:{blockState:{blockName:"minecraft:stone_brick_stairs",properties:{half:"top",shape:"straight",facing:"east"}},buildPass:0}
:enddata
:endrule

rule:
plugin=vanillaBlocks
number=71
data:
JSON:{blockState:{blockName:"minecraft:cobblestone",properties:{}},buildPass:0}
:enddata
:endrule

rule:
plugin=inventory
number=72
data:
JSON:{blockState:{blockName:"minecraft:chest",properties:{facing:"south"}},buildPass:0,lootLevel:1,teData:{x:36,y:88,z:-23,id:"Chest"},inventoryData:{length:27,inventoryContents:[]}}
:enddata
:endrule

rule:
plugin=inventory
number=73
data:
JSON:{blockState:{blockName:"minecraft:chest",properties:{facing:"south"}},buildPass:0,lootLevel:1,teData:{x:37,y:88,z:-23,id:"Chest"},inventoryData:{length:27,inventoryContents:[]}}
:enddata
:endrule

rule:
plugin=vanillaBlocks
number=74
data:
JSON:{blockState:{blockName:"minecraft:oak_stairs",properties:{half:"bottom",shape:"straight",facing:"south"}},buildPass:0}
:enddata
:endrule

rule:
plugin=inventory
number=75
data:
JSON:{blockState:{blockName:"minecraft:chest",properties:{facing:"west"}},buildPass:0,lootLevel:1,teData:{x:37,y:88,z:-19,id:"Chest"},inventoryData:{length:27,inventoryContents:[]}}
:enddata
:endrule

rule:
plugin=vanillaBlocks
number=76
data:
JSON:{blockState:{blockName:"minecraft:carpet",properties:{color:"cyan"}},buildPass:2}
:enddata
:endrule

rule:
plugin=vanillaBlocks
number=77
data:
JSON:{blockState:{blockName:"minecraft:wooden_slab",properties:{half:"bottom",variant:"oak"}},buildPass:0}
:enddata
:endrule

rule:
plugin=vanillaBlocks
number=78
data:
JSON:{blockState:{blockName:"minecraft:bed",properties:{part:"foot",facing:"east",occupied:"false"}},buildPass:2}
:enddata
:endrule

rule:
plugin=vanillaBlocks
number=79
data:
JSON:{blockState:{blockName:"minecraft:bed",properties:{part:"head",facing:"east",occupied:"false"}},buildPass:2}
:enddata
:endrule

rule:
plugin=vanillaBlocks
number=80
data:
JSON:{blockState:{blockName:"minecraft:wool",properties:{color:"white"}},buildPass:0}
:enddata
:endrule

rule:
plugin=vanillaBlocks
number=81
data:
JSON:{blockState:{blockName:"minecraft:oak_stairs",properties:{half:"top",shape:"straight",facing:"north"}},buildPass:0}
:enddata
:endrule

rule:
plugin=inventory
number=82
data:
JSON:{blockState:{blockName:"minecraft:chest",properties:{facing:"south"}},buildPass:0,lootLevel:1,teData:{x:25,y:88,z:-15,id:"Chest"},inventoryData:{length:27,inventoryContents:[]}}
:enddata
:endrule

rule:
plugin=inventory
number=83
data:
JSON:{blockState:{blockName:"minecraft:chest",properties:{facing:"south"}},buildPass:0,lootLevel:1,teData:{x:26,y:88,z:-15,id:"Chest"},inventoryData:{length:27,inventoryContents:[]}}
:enddata
:endrule

rule:
plugin=inventory
number=84
data:
JSON:{blockState:{blockName:"minecraft:chest",properties:{facing:"west"}},buildPass:0,lootLevel:1,teData:{x:37,y:88,z:-14,id:"Chest"},inventoryData:{length:27,inventoryContents:[]}}
:enddata
:endrule

rule:
plugin=vanillaBlocks
number=85
data:
JSON:{blockState:{blockName:"minecraft:cobblestone_wall",properties:{east:"false",south:"false",north:"false",variant:"cobblestone",west:"false",up:"false"}},buildPass:0}
:enddata
:endrule

rule:
plugin=vanillaFlowerPot
number=86
data:
JSON:{blockState:{blockName:"minecraft:flower_pot",properties:{}},itemName:"minecraft:red_flower",buildPass:0,itemMeta:4}
:enddata
:endrule

rule:
plugin=vanillaFlowerPot
number=87
data:
JSON:{blockState:{blockName:"minecraft:flower_pot",properties:{}},itemName:"minecraft:red_flower",buildPass:0,itemMeta:8}
:enddata
:endrule

rule:
plugin=doors
number=88
data:
JSON:{blockState:{blockName:"minecraft:wooden_door",properties:{hinge:"left",half:"upper",powered:"false",facing:"north",open:"false"}},buildPass:2}
:enddata
:endrule

rule:
plugin=vanillaBlocks
number=89
data:
JSON:{blockState:{blockName:"minecraft:glowstone",properties:{}},buildPass:0}
:enddata
:endrule

rule:
plugin=vanillaBlocks
number=90
data:
JSON:{blockState:{blockName:"minecraft:wool",properties:{color:"blue"}},buildPass:0}
:enddata
:endrule

rule:
plugin=vanillaBlocks
number=91
data:
JSON:{blockState:{blockName:"minecraft:oak_stairs",properties:{half:"bottom",shape:"straight",facing:"east"}},buildPass:0}
:enddata
:endrule

rule:
plugin=inventory
number=92
data:
JSON:{blockState:{blockName:"minecraft:chest",properties:{facing:"south"}},buildPass:0,lootLevel:1,teData:{x:26,y:93,z:-21,id:"Chest"},inventoryData:{length:27,inventoryContents:[]}}
:enddata
:endrule

rule:
plugin=inventory
number=93
data:
JSON:{blockState:{blockName:"minecraft:chest",properties:{facing:"south"}},buildPass:0,lootLevel:1,teData:{x:27,y:93,z:-21,id:"Chest"},inventoryData:{length:27,inventoryContents:[]}}
:enddata
:endrule

rule:
plugin=vanillaBlocks
number=94
data:
JSON:{blockState:{blockName:"minecraft:spruce_stairs",properties:{half:"top",shape:"straight",facing:"north"}},buildPass:0}
:enddata
:endrule

rule:
plugin=inventory
number=95
data:
JSON:{blockState:{blockName:"minecraft:chest",properties:{facing:"south"}},buildPass:0,lootLevel:1,teData:{x:33,y:93,z:-21,id:"Chest"},inventoryData:{length:27,inventoryContents:[]}}
:enddata
:endrule

rule:
plugin=vanillaBlocks
number=96
data:
JSON:{blockState:{blockName:"minecraft:spruce_stairs",properties:{half:"top",shape:"straight",facing:"east"}},buildPass:0}
:enddata
:endrule

rule:
plugin=vanillaBlocks
number=97
data:
JSON:{blockState:{blockName:"minecraft:spruce_stairs",properties:{half:"top",shape:"straight",facing:"south"}},buildPass:0}
:enddata
:endrule

rule:
plugin=vanillaBlocks
number=98
data:
JSON:{blockState:{blockName:"minecraft:spruce_stairs",properties:{half:"top",shape:"straight",facing:"west"}},buildPass:0}
:enddata
:endrule

rule:
plugin=blockTile
number=99
data:
JSON:{blockState:{blockName:"minecraft:furnace",properties:{facing:"west"}},buildPass:0,teData:{CookTime:0s,BurnTime:0s,x:38,y:93,Items:[],z:-18,id:"Furnace"}}
:enddata
:endrule

rule:
plugin=inventory
number=100
data:
JSON:{blockState:{blockName:"minecraft:chest",properties:{facing:"west"}},buildPass:0,lootLevel:1,teData:{x:38,y:93,z:-12,id:"Chest"},inventoryData:{length:27,inventoryContents:[]}}
:enddata
:endrule

rule:
plugin=inventory
number=101
data:
JSON:{blockState:{blockName:"minecraft:chest",properties:{facing:"north"}},buildPass:0,lootLevel:1,teData:{x:34,y:93,z:-9,id:"Chest"},inventoryData:{length:27,inventoryContents:[]}}
:enddata
:endrule

rule:
plugin=vanillaBlocks
number=102
data:
JSON:{blockState:{blockName:"minecraft:carpet",properties:{color:"red"}},buildPass:2}
:enddata
:endrule

rule:
plugin=vanillaBlocks
number=103
data:
JSON:{blockState:{blockName:"minecraft:carpet",properties:{color:"black"}},buildPass:2}
:enddata
:endrule

rule:
plugin=vanillaBlocks
number=104
data:
JSON:{blockState:{blockName:"minecraft:carpet",properties:{color:"white"}},buildPass:2}
:enddata
:endrule

rule:
plugin=inventory
number=105
data:
JSON:{blockState:{blockName:"minecraft:chest",properties:{facing:"north"}},buildPass:0,lootLevel:1,teData:{x:30,y:94,z:-13,id:"Chest"},inventoryData:{length:27,inventoryContents:[]}}
:enddata
:endrule

rule:
plugin=vanillaBlocks
number=106
data:
JSON:{blockState:{blockName:"minecraft:carpet",properties:{color:"orange"}},buildPass:2}
:enddata
:endrule

rule:
plugin=vanillaBlocks
number=107
data:
JSON:{blockState:{blockName:"minecraft:oak_stairs",properties:{half:"top",shape:"straight",facing:"west"}},buildPass:0}
:enddata
:endrule

rule:
plugin=vanillaBlocks
number=108
data:
JSON:{blockState:{blockName:"minecraft:oak_stairs",properties:{half:"top",shape:"straight",facing:"south"}},buildPass:0}
:enddata
:endrule

#### ENTITIES ####
entity:
plugin=vanillaHangingEntity
number=0
data:
JSON:{xOffset:0.9375f,rotation:90.0f,mobID:"minecraft:painting",zOffset:-0.0f,position:2199224582150L,entityData:{Motion:[0.0d,0.0d,0.0d],Invulnerable:0b,OnGround:0b,Dimension:0,Air:300s,Dir:1b,PortalCooldown:0,Direction:1b,Rotation:[90.0f,0.0f],Motive:"Sunset",FallDistance:0.0f,Pos:[28.9375d,85.5d,-19.0d],Fire:0s,TileY:85,TileX:29,TileZ:-20},direction:1b}
:enddata
:endentity

entity:
plugin=vanillaHangingEntity
number=1
data:
JSON:{xOffset:0.0f,rotation:0.0f,mobID:"minecraft:painting",zOffset:0.9375f,position:1374657970185L,entityData:{Motion:[0.0d,0.0d,0.0d],Invulnerable:0b,OnGround:0b,Dimension:0,Air:300s,Dir:0b,PortalCooldown:0,Direction:2b,Rotation:[0.0f,0.0f],Motive:"Bust",FallDistance:0.0f,Pos:[25.0d,86.0d,-15.0625d],Fire:0s,TileY:85,TileX:25,TileZ:-15},direction:2b}
:enddata
:endentity

entity:
plugin=vanillaHangingEntity
number=2
data:
JSON:{xOffset:0.9375f,rotation:90.0f,mobID:"minecraft:painting",zOffset:-0.0f,position:4673461288969L,entityData:{Motion:[0.0d,0.0d,0.0d],Invulnerable:0b,OnGround:0b,Dimension:0,Air:300s,Dir:1b,PortalCooldown:0,Direction:1b,Rotation:[90.0f,0.0f],Motive:"Match",FallDistance:0.0f,Pos:[37.9375d,90.0d,-16.0d],Fire:0s,TileY:89,TileX:38,TileZ:-17},direction:1b}
:enddata
:endentity

