# Ancient Warfare Structure Template File
# Auto-generated structure template file. created on: 8/28/2018 at: 17:29:59
# Lines beginning with # denote comments

header:
version=2.3
name=unique_ranchhouse_pelirow
size=20,18,16
offset=9,1,15
:endheader

#### VALIDATION ####
validation:
type=ground
survival=false
worldGenEnabled=false
unique=false
preserveBlocks=false
selectionWeight=0
clusterValue=0
minDuplicateDistance=0
dimensionWhiteList=false
dimensionList=
biomeWhiteList=false
biomeList=
leveling=0
fill=0
border=0
blockSwap=false
data:
:enddata
:endvalidation

#### LAYERS ####
layer: 0
1,1,1,1,1,1,1,1,1,1,1,1,1,1,1,1,1,1,1,1
1,1,1,1,1,1,1,1,1,1,1,1,1,1,1,1,1,1,1,1
1,1,1,1,1,1,1,1,1,1,1,1,1,1,1,1,1,1,1,1
1,1,1,1,1,1,1,1,1,1,1,1,1,1,1,1,1,1,1,1
1,1,1,1,1,1,1,1,1,1,1,1,1,1,1,1,1,1,1,1
1,1,1,1,1,1,1,1,1,1,1,1,1,1,1,1,1,1,1,1
1,1,1,1,1,1,1,1,1,1,1,1,1,1,1,1,1,1,1,1
1,1,1,1,1,1,1,1,1,2,2,1,1,1,1,1,1,1,1,1
1,1,1,1,1,1,1,1,1,1,1,1,1,1,1,1,1,1,1,1
1,1,1,1,1,1,1,1,1,1,1,1,1,1,1,1,1,1,1,1
1,1,1,1,1,1,1,1,1,1,1,1,1,1,1,1,1,1,1,1
1,1,1,1,1,1,1,1,1,1,1,1,1,1,1,1,1,1,1,1
1,1,1,1,1,1,1,1,1,1,1,1,1,1,1,1,1,1,1,1
1,1,1,1,1,1,1,1,2,2,2,2,1,1,1,1,1,1,1,1
1,1,1,1,1,1,1,1,1,1,1,1,1,1,1,1,1,1,1,1
1,1,1,1,1,1,1,1,1,1,1,1,1,1,1,1,1,1,1,1
:endlayer
layer: 1
0,0,3,0,0,3,0,0,3,0,0,3,0,0,3,0,0,3,0,0
0,0,0,0,0,0,0,0,0,0,0,0,0,0,0,0,0,0,0,0
0,0,0,0,0,0,0,0,0,0,0,0,0,0,0,0,0,0,0,0
0,0,0,0,0,0,0,0,0,0,0,0,0,0,0,0,0,0,0,0
0,0,0,0,0,0,0,0,0,0,0,0,0,0,0,0,0,0,0,0
0,0,0,0,0,0,0,0,0,0,0,0,0,0,0,0,0,0,0,0
0,0,0,0,0,0,0,0,0,0,0,0,0,0,0,0,0,0,0,0
0,0,0,0,0,0,0,0,0,0,0,0,0,0,0,0,0,0,0,0
0,0,0,0,0,0,0,0,0,0,0,0,0,0,0,0,0,0,0,0
0,0,3,0,0,3,0,0,3,0,0,3,0,0,3,0,0,3,0,0
0,0,3,0,0,0,0,0,0,0,0,0,0,0,0,0,0,3,0,0
0,0,3,0,0,0,0,0,0,0,0,0,0,0,0,0,0,3,0,0
0,0,3,3,3,3,3,3,3,3,3,3,3,3,3,3,3,3,0,0
0,0,0,0,0,0,0,3,4,4,4,4,3,0,0,0,0,0,0,0
0,0,0,0,0,0,0,3,0,0,0,0,3,0,0,0,0,0,0,0
0,0,0,0,0,0,0,3,0,0,0,0,3,0,0,0,0,0,0,0
:endlayer
layer: 2
0,0,5,5,5,5,5,5,5,5,5,5,5,5,5,5,5,5,0,0
0,0,5,5,5,5,5,5,5,5,5,5,5,5,5,5,5,5,0,0
0,0,5,5,5,5,5,5,5,5,5,5,5,5,5,5,5,5,0,0
0,0,5,5,5,5,5,5,5,5,5,5,5,5,5,5,5,5,0,0
0,0,5,5,5,5,5,5,5,5,5,5,5,5,5,5,6,6,0,0
0,0,5,5,5,5,5,5,5,5,5,5,5,5,5,5,5,5,0,0
0,0,5,5,5,5,5,5,5,5,5,5,5,5,5,5,5,5,0,0
0,0,5,5,5,5,5,5,5,5,5,5,5,5,5,5,5,5,0,0
0,3,5,5,5,5,5,5,5,5,5,5,5,5,5,5,5,5,3,0
0,3,7,7,7,7,7,8,8,8,8,8,8,8,8,8,8,8,3,0
0,3,7,7,7,7,5,8,8,8,8,8,8,8,8,8,8,8,3,0
0,3,7,7,7,7,7,8,8,8,8,8,8,8,8,8,8,8,3,0
0,3,7,7,7,7,7,8,8,8,8,8,8,8,8,8,8,8,3,0
0,3,3,3,3,3,3,3,0,0,0,0,3,3,3,3,3,3,3,0
0,0,0,0,0,0,0,3,0,0,0,0,3,0,0,0,0,0,0,0
0,0,0,0,0,0,0,0,0,0,0,0,0,0,0,0,0,0,0,0
:endlayer
layer: 3
0,0,9,10,10,10,10,10,10,10,10,10,10,10,10,10,10,9,0,0
0,0,10,0,11,3,12,0,5,13,14,5,0,15,0,16,0,10,0,0
0,0,10,0,0,0,0,0,3,4,4,3,0,0,0,0,0,10,0,0
0,0,10,17,0,0,0,0,0,0,0,0,0,0,4,0,18,6,6,0
0,0,10,19,0,0,0,0,20,20,20,20,0,0,11,0,0,0,6,0
0,0,10,21,0,0,0,0,20,22,22,20,0,0,23,0,18,6,6,0
0,0,10,0,0,0,0,0,20,20,20,20,0,0,0,0,0,10,0,0
0,0,10,0,0,24,0,0,0,0,0,0,0,25,0,26,0,10,0,0
0,3,9,5,5,5,5,5,9,27,28,9,5,5,5,5,5,9,3,0
0,3,0,0,4,0,0,0,0,0,0,0,0,0,0,0,0,0,3,0
0,3,0,11,3,0,0,0,0,0,0,0,0,11,4,12,0,0,3,0
0,3,0,0,23,0,0,0,0,0,0,0,0,0,0,0,0,0,3,0
0,3,0,0,0,0,0,0,0,0,0,0,0,0,0,0,0,0,3,0
0,3,3,3,3,3,3,3,0,0,0,0,3,3,3,3,3,3,3,0
0,0,0,0,0,0,0,0,0,0,0,0,0,0,0,0,0,0,0,0
0,0,0,0,0,0,0,0,0,0,0,0,0,0,0,0,0,0,0,0
:endlayer
layer: 4
0,0,9,10,29,29,29,10,5,5,5,5,10,29,29,29,10,9,0,0
0,0,29,30,0,31,0,30,11,8,8,12,30,0,0,0,30,10,0,0
0,0,29,0,0,0,0,0,3,0,0,3,0,0,0,0,0,10,0,0
0,0,10,32,0,0,0,0,0,0,0,0,0,0,0,0,33,6,6,0
0,0,29,0,0,0,0,0,0,0,0,0,0,0,0,0,33,0,6,0
0,0,10,32,0,0,0,0,0,0,0,0,0,0,0,0,33,6,6,0
0,0,29,0,0,0,0,0,0,0,0,0,0,0,0,0,34,10,0,0
0,0,29,0,0,35,0,0,35,0,0,35,0,0,35,0,0,10,0,0
0,0,9,29,29,5,29,29,9,36,37,9,29,29,5,29,29,9,0,0
0,0,0,0,0,0,0,0,30,0,0,30,0,0,0,0,0,30,0,0
0,0,0,0,38,0,0,0,0,0,0,0,0,3,0,3,0,0,0,0
0,0,0,0,0,0,0,0,0,0,0,0,0,0,0,0,0,0,0,0
0,0,0,0,0,0,0,0,0,0,0,0,0,0,0,0,0,0,0,0
0,0,3,0,0,0,0,3,0,0,0,0,3,0,0,0,0,3,0,0
0,0,0,0,0,0,0,0,0,0,0,0,0,0,0,0,0,0,0,0
0,0,0,0,0,0,0,0,0,0,0,0,0,0,0,0,0,0,0,0
:endlayer
layer: 5
0,0,9,10,10,10,10,5,10,10,10,10,5,10,10,10,10,9,0,0
0,0,10,0,0,0,0,11,0,0,0,0,12,0,0,0,0,10,0,0
0,0,10,0,0,0,0,0,3,0,0,3,0,0,0,0,0,10,0,0
0,0,10,0,0,0,0,0,0,0,0,0,0,0,0,0,39,6,6,0
0,0,10,0,0,0,0,0,0,0,0,0,0,0,0,0,0,6,6,0
0,0,10,0,0,0,0,0,0,0,0,0,0,0,0,0,40,6,6,0
0,0,10,0,0,0,0,0,0,0,0,0,0,0,0,0,0,10,0,0
0,0,10,0,0,0,0,0,0,0,0,0,0,0,0,0,0,10,0,0
0,0,9,5,5,5,5,5,9,9,9,9,5,5,5,5,5,9,0,0
0,0,30,0,0,0,0,0,0,0,0,0,0,0,0,0,0,0,0,0
0,0,0,0,0,0,0,0,0,0,0,0,0,3,0,3,0,0,0,0
0,0,0,0,0,0,0,0,0,0,0,0,0,0,0,0,0,0,0,0
0,0,0,0,0,0,0,0,0,0,0,0,0,0,0,0,0,0,0,0
0,0,3,0,0,0,0,3,0,0,0,0,3,0,0,0,0,3,0,0
0,0,0,0,0,0,0,0,0,0,0,0,0,0,0,0,0,0,0,0
0,0,0,0,0,0,0,0,0,0,0,0,0,0,0,0,0,0,0,0
:endlayer
layer: 6
0,0,9,5,5,5,5,10,10,10,10,10,10,5,5,5,5,9,0,0
0,0,5,5,5,5,11,0,0,0,0,0,0,12,5,5,5,5,0,0
0,0,5,5,5,5,5,5,3,0,0,3,5,5,5,5,5,5,0,0
0,0,5,5,5,5,5,5,0,0,0,0,5,5,5,5,6,6,6,0
0,0,5,5,5,5,5,5,0,0,0,0,5,5,5,5,6,41,6,0
0,0,5,5,5,5,5,5,0,0,0,0,5,5,5,5,6,6,6,0
0,0,5,5,5,5,5,5,0,0,0,0,5,5,5,5,5,5,0,0
0,0,5,5,5,5,5,5,0,0,0,0,5,5,5,5,5,5,0,0
0,0,9,42,42,42,42,42,42,42,42,42,42,42,42,42,42,9,0,0
0,0,0,0,0,0,0,0,0,0,0,0,0,0,0,0,0,0,0,0
0,0,0,0,0,0,0,0,0,0,0,0,0,3,0,3,0,0,0,0
0,0,0,0,0,0,0,0,0,0,0,0,0,0,0,0,0,0,0,0
0,0,0,0,0,0,0,0,0,0,0,0,0,0,0,0,0,0,0,0
0,0,3,0,0,0,0,3,0,0,0,0,3,0,0,0,0,3,0,0
0,0,0,0,0,0,0,0,0,0,0,0,0,0,0,0,0,0,0,0
0,0,0,0,0,0,0,0,0,0,0,0,0,0,0,0,0,0,0,0
:endlayer
layer: 7
0,0,9,10,10,10,10,10,10,29,29,10,10,10,10,10,10,9,0,0
0,0,10,43,0,0,0,0,0,0,0,0,0,0,0,0,0,10,0,0
0,0,10,44,45,0,0,3,0,0,0,0,3,0,0,0,0,10,0,0
0,0,10,44,45,0,0,3,0,0,0,0,3,0,0,18,6,6,6,0
0,0,10,43,0,0,0,3,0,0,0,0,3,46,0,0,0,41,6,0
0,0,10,0,0,0,0,3,0,0,0,0,3,0,0,18,6,6,6,0
0,0,10,8,8,8,8,3,0,0,0,0,3,0,0,0,0,10,0,0
0,0,10,5,5,5,8,3,0,47,48,0,3,0,43,43,0,10,0,0
0,0,9,5,5,5,5,5,5,5,5,5,5,5,5,5,5,9,0,0
0,0,7,7,7,7,8,8,8,8,8,8,8,8,8,8,8,7,0,0
0,0,7,8,8,8,8,8,8,8,8,8,8,8,8,8,8,7,0,0
0,0,7,8,8,8,8,8,8,8,8,8,8,8,8,8,8,7,0,0
0,0,7,8,8,8,8,8,8,8,8,8,8,8,8,8,8,7,0,0
0,0,7,7,7,7,7,7,7,7,7,7,7,7,7,7,7,7,0,0
0,0,0,0,0,0,0,0,0,0,0,0,0,0,0,0,0,0,0,0
0,0,0,0,0,0,0,0,0,0,0,0,0,0,0,0,0,0,0,0
:endlayer
layer: 8
0,0,9,10,29,29,10,10,29,29,29,29,10,10,29,29,10,9,0,0
0,0,10,49,0,0,0,30,0,0,0,0,30,0,0,0,34,10,0,0
0,0,29,0,0,0,0,0,0,0,0,0,0,0,0,0,0,10,0,0
0,0,29,0,0,0,0,0,0,0,0,0,0,0,0,33,6,6,6,0
0,0,10,49,0,0,0,0,0,0,0,0,0,0,0,33,50,0,6,0
0,0,29,0,0,0,0,0,0,0,0,0,0,0,0,33,6,6,6,0
0,0,29,0,0,0,0,0,0,0,0,0,0,0,0,0,0,10,0,0
0,0,10,0,0,0,0,0,0,0,0,0,0,0,0,0,34,10,0,0
0,0,9,5,51,5,9,29,29,29,29,29,29,9,29,29,29,9,0,0
0,0,3,0,0,0,0,0,0,0,0,0,0,0,0,0,0,3,0,0
0,0,3,0,0,0,0,0,0,0,0,0,0,0,0,0,0,3,0,0
0,0,3,0,0,0,0,0,0,0,0,0,0,0,0,0,0,3,0,0
0,0,3,0,0,0,0,0,0,0,0,0,0,0,0,0,0,3,0,0
0,0,3,3,3,3,3,3,3,3,3,3,3,3,3,3,3,3,0,0
0,0,0,0,0,0,0,0,0,0,0,0,0,0,0,0,0,0,0,0
0,0,0,0,0,0,0,0,0,0,0,0,0,0,0,0,0,0,0,0
:endlayer
layer: 9
52,10,9,10,29,29,10,10,10,29,29,10,10,10,29,29,10,9,10,53
52,54,10,0,0,0,0,0,0,0,0,0,0,0,0,0,0,10,10,53
52,54,10,0,0,0,0,0,0,0,0,0,0,0,0,0,0,10,10,53
52,54,10,0,0,0,0,0,0,0,0,0,0,0,0,55,6,6,6,53
52,54,10,0,0,0,0,0,0,0,0,0,0,0,0,0,6,0,6,53
52,54,10,0,0,0,0,0,0,0,0,0,0,0,0,56,6,6,6,53
52,54,10,0,0,0,0,0,0,0,0,0,0,0,0,0,0,10,10,53
52,54,10,35,0,35,0,0,0,0,0,0,0,0,0,0,0,10,10,53
52,54,9,5,57,5,9,29,29,29,29,29,29,9,29,29,29,9,10,53
0,0,0,0,0,0,0,0,0,0,0,0,0,0,0,0,0,0,0,0
0,0,0,0,0,0,0,0,0,0,0,0,0,0,0,0,0,0,0,0
0,0,0,0,0,0,0,0,0,0,0,0,0,0,0,0,0,0,0,0
0,0,0,0,0,0,0,0,0,0,0,0,0,0,0,0,0,0,0,0
0,0,3,0,0,0,0,3,0,0,0,0,3,0,0,0,0,3,0,0
0,0,0,0,0,0,0,0,0,0,0,0,0,0,0,0,0,0,0,0
0,0,0,0,0,0,0,0,0,0,0,0,0,0,0,0,0,0,0,0
:endlayer
layer: 10
0,52,9,42,42,42,42,42,42,42,42,42,42,42,42,42,42,9,53,0
0,52,58,0,0,0,0,0,0,0,0,0,0,0,0,0,0,58,53,0
0,52,58,0,0,0,0,0,0,0,0,0,0,0,0,0,0,58,53,0
0,52,58,0,0,0,0,0,0,0,0,0,0,0,0,0,6,6,6,0
0,52,58,0,0,0,0,0,0,0,0,0,0,0,0,0,6,0,6,0
0,52,58,0,0,0,0,0,0,0,0,0,0,0,0,0,6,6,6,0
0,52,58,0,0,0,0,0,0,0,0,0,0,0,0,0,0,58,53,0
0,52,58,0,0,0,0,0,0,0,0,0,0,0,0,0,0,58,53,0
0,52,9,42,42,42,42,42,42,42,42,42,42,42,42,42,42,42,53,0
0,52,0,0,0,0,30,0,0,0,0,0,0,30,0,0,0,30,53,0
0,52,0,0,0,0,0,0,0,0,0,0,0,0,0,0,0,0,53,0
0,52,0,0,0,0,0,0,0,0,0,0,0,0,0,0,0,0,53,0
0,52,0,0,0,0,0,0,0,0,0,0,0,0,0,0,0,0,53,0
0,52,3,0,0,0,0,3,0,0,0,0,3,0,0,0,0,3,53,0
0,52,59,59,59,59,59,59,59,59,59,59,59,59,59,59,59,59,59,0
0,0,0,0,0,0,0,0,0,0,0,0,0,0,0,0,0,0,0,0
:endlayer
layer: 11
0,0,52,10,60,60,60,60,60,60,60,60,60,60,60,60,10,53,0,0
0,0,52,10,10,10,10,10,10,10,10,10,10,10,10,10,10,53,0,0
0,0,52,10,10,10,10,10,10,10,10,10,10,10,10,10,10,53,0,0
0,0,52,10,10,10,10,10,10,10,10,10,10,10,10,10,6,6,6,0
0,0,52,10,10,10,10,10,10,10,10,10,10,10,10,10,6,0,6,0
0,0,52,10,10,10,10,10,10,10,10,10,10,10,10,10,6,6,6,0
0,0,52,10,10,10,10,10,10,10,10,10,10,10,61,10,10,53,0,0
0,0,52,10,10,10,10,10,10,10,10,10,10,10,10,10,10,53,0,0
0,0,52,10,10,10,10,10,10,10,10,10,10,10,10,10,10,53,0,0
0,0,52,10,10,10,10,10,10,10,10,10,10,10,10,10,10,53,0,0
0,0,52,10,10,10,10,10,10,10,10,10,10,10,10,10,10,53,0,0
0,0,52,10,10,10,10,10,10,10,10,10,10,10,10,10,10,53,0,0
0,0,52,10,10,10,10,10,10,10,10,10,10,10,10,10,10,53,0,0
0,0,52,10,59,59,59,59,59,59,59,59,59,59,59,59,10,59,0,0
0,0,0,0,0,0,0,0,0,0,0,0,0,0,0,0,0,0,0,0
0,0,0,0,0,0,0,0,0,0,0,0,0,0,0,0,0,0,0,0
:endlayer
layer: 12
0,0,0,52,54,0,0,0,0,0,0,0,0,0,0,62,53,0,0,0
0,0,0,52,10,60,60,60,60,60,60,60,60,60,60,10,53,0,0,0
0,0,0,52,10,10,10,10,10,10,10,10,10,10,10,10,53,0,0,0
0,0,0,52,0,0,0,63,64,0,0,65,66,0,0,10,6,6,6,0
0,0,0,52,67,0,0,0,0,0,0,0,0,0,0,10,6,0,6,0
0,0,0,52,0,0,0,0,0,0,0,0,0,0,0,10,6,6,6,0
0,0,0,52,68,0,0,0,0,0,0,0,0,0,0,10,53,0,0,0
0,0,0,52,69,0,0,49,0,0,0,49,0,0,0,10,53,0,0,0
0,0,0,52,0,0,0,0,0,0,0,0,0,0,0,10,53,0,0,0
0,0,0,52,70,0,0,0,0,0,0,0,0,0,0,10,53,0,0,0
0,0,0,52,71,0,0,72,73,0,0,74,75,0,0,10,53,0,0,0
0,0,0,52,10,10,10,10,10,10,10,10,10,10,10,10,53,0,0,0
0,0,0,52,53,59,59,59,59,59,59,59,59,59,59,52,53,0,0,0
0,0,0,52,54,0,0,0,0,0,0,0,0,0,0,62,53,0,0,0
0,0,0,0,0,0,0,0,0,0,0,0,0,0,0,0,0,0,0,0
0,0,0,0,0,0,0,0,0,0,0,0,0,0,0,0,0,0,0,0
:endlayer
layer: 13
0,0,0,0,52,54,0,0,0,0,0,0,0,0,62,53,0,0,0,0
0,0,0,0,52,54,0,0,0,0,0,0,0,0,62,53,0,0,0,0
0,0,0,0,52,10,10,29,29,10,10,29,29,10,10,53,0,0,0,0
0,0,0,0,52,0,30,0,0,0,0,0,0,30,0,53,6,6,6,0
0,0,0,0,52,0,0,0,0,0,0,0,0,0,0,53,6,0,6,0
0,0,0,0,52,0,0,0,0,0,0,0,0,0,0,53,6,6,6,0
0,0,0,0,52,0,0,0,0,0,0,0,0,0,0,53,0,0,0,0
0,0,0,0,52,0,0,0,0,0,0,0,0,0,0,53,0,0,0,0
0,0,0,0,52,0,0,0,0,0,0,0,0,0,0,53,0,0,0,0
0,0,0,0,52,0,0,0,0,0,0,0,0,0,0,53,0,0,0,0
0,0,0,0,52,0,35,0,0,0,0,0,0,35,0,53,0,0,0,0
0,0,0,0,52,10,10,29,29,10,10,29,29,10,10,53,0,0,0,0
0,0,0,0,52,54,0,0,0,0,0,0,0,0,62,53,0,0,0,0
0,0,0,0,52,54,0,0,0,0,0,0,0,0,62,53,0,0,0,0
0,0,0,0,0,0,0,0,0,0,0,0,0,0,0,0,0,0,0,0
0,0,0,0,0,0,0,0,0,0,0,0,0,0,0,0,0,0,0,0
:endlayer
layer: 14
0,0,0,0,0,52,54,0,0,0,0,0,0,62,53,0,0,0,0,0
0,0,0,0,0,52,54,0,0,0,0,0,0,62,53,0,0,0,0,0
0,0,0,0,0,52,10,29,29,10,10,29,29,10,53,0,0,0,0,0
0,0,0,0,0,52,0,0,0,0,0,0,0,0,53,0,6,6,6,0
0,0,0,0,0,52,0,0,0,0,0,0,0,0,53,0,6,0,6,0
0,0,0,0,0,52,0,0,0,0,0,0,0,0,53,0,6,6,6,0
0,0,0,0,0,52,0,0,0,0,0,0,0,0,53,0,0,0,0,0
0,0,0,0,0,52,0,0,0,0,0,0,0,0,53,0,0,0,0,0
0,0,0,0,0,52,0,0,0,0,0,0,0,0,53,0,0,0,0,0
0,0,0,0,0,52,0,0,0,0,0,0,0,0,53,0,0,0,0,0
0,0,0,0,0,52,0,0,0,0,0,0,0,71,53,0,0,0,0,0
0,0,0,0,0,52,10,29,29,10,10,29,29,10,53,0,0,0,0,0
0,0,0,0,0,52,54,0,0,0,0,0,0,62,53,0,0,0,0,0
0,0,0,0,0,52,54,0,0,0,0,0,0,62,53,0,0,0,0,0
0,0,0,0,0,0,0,0,0,0,0,0,0,0,0,0,0,0,0,0
0,0,0,0,0,0,0,0,0,0,0,0,0,0,0,0,0,0,0,0
:endlayer
layer: 15
0,0,0,0,0,0,52,54,0,0,0,0,62,53,0,0,0,0,0,0
0,0,0,0,0,0,52,54,76,76,76,76,62,53,0,0,0,0,0,0
0,0,0,0,0,0,52,10,10,10,10,10,10,53,0,0,0,0,0,0
0,0,0,0,0,0,52,0,0,0,0,0,0,53,0,0,6,6,6,0
0,0,0,0,0,0,52,0,0,0,0,0,0,53,0,0,6,0,6,0
0,0,0,0,0,0,52,0,0,0,0,0,0,53,0,0,6,6,6,0
0,0,0,0,0,0,52,0,0,0,0,0,0,53,0,0,0,0,0,0
0,0,0,0,0,0,52,0,0,0,0,0,0,53,0,0,0,0,0,0
0,0,0,0,0,0,52,0,0,0,0,0,0,53,0,0,0,0,0,0
0,0,0,0,0,0,52,71,0,0,0,0,0,53,0,0,0,0,0,0
0,0,0,0,0,0,52,71,0,0,0,0,0,53,0,0,0,0,0,0
0,0,0,0,0,0,52,10,10,10,10,10,10,53,0,0,0,0,0,0
0,0,0,0,0,0,52,54,0,0,0,0,62,53,0,0,0,0,0,0
0,0,0,0,0,0,52,54,0,0,0,0,62,53,0,0,0,0,0,0
0,0,0,0,0,0,0,0,0,0,0,0,0,0,0,0,0,0,0,0
0,0,0,0,0,0,0,0,0,0,0,0,0,0,0,0,0,0,0,0
:endlayer
layer: 16
0,0,0,0,0,0,0,52,54,77,77,62,53,0,0,0,0,0,0,0
0,0,0,0,0,0,0,52,10,10,10,10,53,0,0,0,0,0,0,0
0,0,0,0,0,0,0,52,10,10,10,10,53,0,0,0,0,0,0,0
0,0,0,0,0,0,0,52,10,10,10,10,53,0,0,0,78,78,79,0
0,0,0,0,0,0,0,52,10,10,10,10,53,0,0,0,18,0,79,0
0,0,0,0,0,0,0,52,10,10,10,10,53,0,0,0,18,80,80,0
0,0,0,0,0,0,0,52,10,81,81,10,53,0,0,0,0,0,0,0
0,0,0,0,0,0,0,52,10,81,81,10,53,0,0,0,0,0,0,0
0,0,0,0,0,0,0,52,10,10,10,10,53,0,0,0,0,0,0,0
0,0,0,0,0,0,0,52,10,10,10,10,53,0,0,0,0,0,0,0
0,0,0,0,0,0,0,52,10,10,10,10,53,0,0,0,0,0,0,0
0,0,0,0,0,0,0,52,10,10,10,10,53,0,0,0,0,0,0,0
0,0,0,0,0,0,0,52,54,82,82,62,53,0,0,0,0,0,0,0
0,0,0,0,0,0,0,52,54,77,77,62,53,0,0,0,0,0,0,0
0,0,0,0,0,0,0,0,0,0,0,0,0,0,0,0,0,0,0,0
0,0,0,0,0,0,0,0,0,0,0,0,0,0,0,0,0,0,0,0
:endlayer
layer: 17
0,0,0,0,0,0,0,0,83,83,83,83,0,0,0,0,0,0,0,0
0,0,0,0,0,0,0,0,83,83,83,83,0,0,0,0,0,0,0,0
0,0,0,0,0,0,0,0,83,83,83,83,0,0,0,0,0,0,0,0
0,0,0,0,0,0,0,0,83,83,83,83,0,0,0,0,0,0,0,0
0,0,0,0,0,0,0,0,83,83,83,83,0,0,0,0,0,0,0,0
0,0,0,0,0,0,0,0,83,83,83,83,0,0,0,0,0,0,0,0
0,0,0,0,0,0,0,0,83,83,83,83,0,0,0,0,0,0,0,0
0,0,0,0,0,0,0,0,83,83,83,83,0,0,0,0,0,0,0,0
0,0,0,0,0,0,0,0,83,83,83,83,0,0,0,0,0,0,0,0
0,0,0,0,0,0,0,0,83,83,83,83,0,0,0,0,0,0,0,0
0,0,0,0,0,0,0,0,83,83,83,83,0,0,0,0,0,0,0,0
0,0,0,0,0,0,0,0,83,83,83,83,0,0,0,0,0,0,0,0
0,0,0,0,0,0,0,0,83,83,83,83,0,0,0,0,0,0,0,0
0,0,0,0,0,0,0,0,83,83,83,83,0,0,0,0,0,0,0,0
0,0,0,0,0,0,0,0,0,0,0,0,0,0,0,0,0,0,0,0
0,0,0,0,0,0,0,0,0,0,0,0,0,0,0,0,0,0,0,0
:endlayer

#### RULES ####
rule:
plugin=vanillaBlocks
number=1
data:
JSON:{buildPass:0,blockName:"minecraft:grass",meta:0}
:enddata
:endrule

rule:
plugin=vanillaBlocks
number=2
data:
JSON:{buildPass:0,blockName:"minecraft:dirt",meta:0}
:enddata
:endrule

rule:
plugin=vanillaBlocks
number=3
data:
JSON:{buildPass:0,blockName:"minecraft:fence",meta:0}
:enddata
:endrule

rule:
plugin=vanillaBlocks
number=4
data:
JSON:{buildPass:0,blockName:"minecraft:spruce_stairs",meta:3}
:enddata
:endrule

rule:
plugin=vanillaBlocks
number=5
data:
JSON:{buildPass:0,blockName:"minecraft:planks",meta:1}
:enddata
:endrule

rule:
plugin=vanillaBlocks
number=6
data:
JSON:{buildPass:0,blockName:"minecraft:brick_block",meta:0}
:enddata
:endrule

rule:
plugin=vanillaBlocks
number=7
data:
JSON:{buildPass:0,blockName:"minecraft:double_wooden_slab",meta:1}
:enddata
:endrule

rule:
plugin=vanillaBlocks
number=8
data:
JSON:{buildPass:0,blockName:"minecraft:wooden_slab",meta:1}
:enddata
:endrule

rule:
plugin=vanillaBlocks
number=9
data:
JSON:{buildPass:0,blockName:"minecraft:log",meta:1}
:enddata
:endrule

rule:
plugin=vanillaBlocks
number=10
data:
JSON:{buildPass:0,blockName:"minecraft:planks",meta:0}
:enddata
:endrule

rule:
plugin=vanillaBlocks
number=11
data:
JSON:{buildPass:0,blockName:"minecraft:spruce_stairs",meta:1}
:enddata
:endrule

rule:
plugin=vanillaBlocks
number=12
data:
JSON:{buildPass:0,blockName:"minecraft:spruce_stairs",meta:0}
:enddata
:endrule

rule:
plugin=vanillaInventory
number=13
data:
JSON:{buildPass:0,blockName:"minecraft:chest",meta:3,lootLevel:0,teData:{x:32,y:85,z:-41,id:"Chest"},inventoryData:{length:27,inventoryContents:[{id:"minecraft:iron_chestplate",Count:1b,slot:0,Damage:0s},{id:"minecraft:iron_sword",Count:1b,slot:1,Damage:0s},{id:"minecraft:iron_ingot",Count:2b,slot:2,Damage:0s},{id:"minecraft:iron_axe",Count:1b,slot:3,Damage:0s}]}}
:enddata
:endrule

rule:
plugin=vanillaInventory
number=14
data:
JSON:{buildPass:0,blockName:"minecraft:chest",meta:3,lootLevel:2,teData:{x:33,y:85,z:-41,id:"Chest"},inventoryData:{length:27,inventoryContents:[{id:"minecraft:diamond",Count:2b,slot:0,Damage:0s}]}}
:enddata
:endrule

rule:
plugin=vanillaFlowerPot
number=15
data:
JSON:{itemName:"minecraft:red_flower",buildPass:0,itemMeta:1,blockName:"minecraft:flower_pot",meta:1}
:enddata
:endrule

rule:
plugin=vanillaFlowerPot
number=16
data:
JSON:{itemName:"minecraft:red_flower",buildPass:0,itemMeta:5,blockName:"minecraft:flower_pot",meta:5}
:enddata
:endrule

rule:
plugin=vanillaBlocks
number=17
data:
JSON:{buildPass:0,blockName:"minecraft:cauldron",meta:0}
:enddata
:endrule

rule:
plugin=vanillaBlocks
number=18
data:
JSON:{buildPass:0,blockName:"minecraft:brick_stairs",meta:0}
:enddata
:endrule

rule:
plugin=vanillaBlocks
number=19
data:
JSON:{buildPass:0,blockName:"minecraft:crafting_table",meta:0}
:enddata
:endrule

rule:
plugin=vanillaBlocks
number=20
data:
JSON:{buildPass:2,blockName:"minecraft:carpet",meta:15}
:enddata
:endrule

rule:
plugin=awAutomationLogic
number=21
data:
JSON:{buildPass:0,blockName:"minecraft:furnace",meta:5,teData:{CookTime:0s,BurnTime:0s,x:26,y:85,Items:[],z:-37,id:"Furnace"}}
:enddata
:endrule

rule:
plugin=vanillaBlocks
number=22
data:
JSON:{buildPass:2,blockName:"minecraft:carpet",meta:14}
:enddata
:endrule

rule:
plugin=vanillaBlocks
number=23
data:
JSON:{buildPass:0,blockName:"minecraft:spruce_stairs",meta:2}
:enddata
:endrule

rule:
plugin=vanillaBlocks
number=24
data:
JSON:{buildPass:0,blockName:"minecraft:anvil",meta:3}
:enddata
:endrule

rule:
plugin=vanillaFlowerPot
number=25
data:
JSON:{itemName:"minecraft:red_flower",buildPass:0,itemMeta:5,blockName:"minecraft:flower_pot",meta:5}
:enddata
:endrule

rule:
plugin=vanillaFlowerPot
number=26
data:
JSON:{itemName:"minecraft:red_flower",buildPass:0,itemMeta:1,blockName:"minecraft:flower_pot",meta:1}
:enddata
:endrule

rule:
plugin=vanillaDoors
number=27
data:
JSON:{buildPass:2,blockName:"minecraft:wooden_door",meta:3,sideFlag:8b}
:enddata
:endrule

rule:
plugin=vanillaDoors
number=28
data:
JSON:{buildPass:2,blockName:"minecraft:wooden_door",meta:3,sideFlag:9b}
:enddata
:endrule

rule:
plugin=vanillaBlocks
number=29
data:
JSON:{buildPass:0,blockName:"minecraft:glass_pane",meta:0}
:enddata
:endrule

rule:
plugin=vanillaBlocks
number=30
data:
JSON:{buildPass:2,blockName:"minecraft:torch",meta:3}
:enddata
:endrule

rule:
plugin=vanillaBlocks
number=31
data:
JSON:{buildPass:2,blockName:"minecraft:heavy_weighted_pressure_plate",meta:0}
:enddata
:endrule

rule:
plugin=vanillaBlocks
number=32
data:
JSON:{buildPass:2,blockName:"minecraft:torch",meta:1}
:enddata
:endrule

rule:
plugin=vanillaBlocks
number=33
data:
JSON:{buildPass:0,blockName:"minecraft:brick_stairs",meta:4}
:enddata
:endrule

rule:
plugin=vanillaBlocks
number=34
data:
JSON:{buildPass:2,blockName:"minecraft:torch",meta:2}
:enddata
:endrule

rule:
plugin=vanillaBlocks
number=35
data:
JSON:{buildPass:2,blockName:"minecraft:torch",meta:4}
:enddata
:endrule

rule:
plugin=vanillaDoors
number=36
data:
JSON:{buildPass:2,blockName:"minecraft:wooden_door",meta:8,sideFlag:0b}
:enddata
:endrule

rule:
plugin=vanillaDoors
number=37
data:
JSON:{buildPass:2,blockName:"minecraft:wooden_door",meta:9,sideFlag:0b}
:enddata
:endrule

rule:
plugin=vanillaBlocks
number=38
data:
JSON:{buildPass:2,blockName:"minecraft:wooden_pressure_plate",meta:0}
:enddata
:endrule

rule:
plugin=vanillaSkull
number=39
data:
JSON:{buildPass:0,blockName:"minecraft:skull",meta:4,teData:{Rot:12,x:39,y:87,z:-39,id:"Skull",SkullType:4b}}
:enddata
:endrule

rule:
plugin=vanillaSkull
number=40
data:
JSON:{buildPass:0,blockName:"minecraft:skull",meta:4,teData:{Rot:12,x:39,y:87,z:-37,id:"Skull",SkullType:2b}}
:enddata
:endrule

rule:
plugin=vanillaBlocks
number=41
data:
JSON:{buildPass:0,blockName:"minecraft:iron_bars",meta:0}
:enddata
:endrule

rule:
plugin=vanillaBlocks
number=42
data:
JSON:{buildPass:0,blockName:"minecraft:log",meta:5}
:enddata
:endrule

rule:
plugin=vanillaBlocks
number=43
data:
JSON:{buildPass:0,blockName:"minecraft:bookshelf",meta:0}
:enddata
:endrule

rule:
plugin=vanillaBlocks
number=44
data:
JSON:{buildPass:2,blockName:"minecraft:bed",meta:9}
:enddata
:endrule

rule:
plugin=vanillaBlocks
number=45
data:
JSON:{buildPass:2,blockName:"minecraft:bed",meta:1}
:enddata
:endrule

rule:
plugin=vanillaBlocks
number=46
data:
JSON:{buildPass:0,blockName:"minecraft:acacia_stairs",meta:1}
:enddata
:endrule

rule:
plugin=vanillaSkull
number=47
data:
JSON:{buildPass:0,blockName:"minecraft:skull",meta:2,teData:{Rot:0,x:32,y:89,z:-35,id:"Skull",SkullType:0b}}
:enddata
:endrule

rule:
plugin=vanillaSkull
number=48
data:
JSON:{buildPass:0,blockName:"minecraft:skull",meta:2,teData:{Rot:0,x:33,y:89,z:-35,id:"Skull",SkullType:0b}}
:enddata
:endrule

rule:
plugin=vanillaBlocks
number=49
data:
JSON:{buildPass:2,blockName:"minecraft:torch",meta:5}
:enddata
:endrule

rule:
plugin=vanillaBlocks
number=50
data:
JSON:{buildPass:0,blockName:"minecraft:brick_stairs",meta:5}
:enddata
:endrule

rule:
plugin=vanillaDoors
number=51
data:
JSON:{buildPass:2,blockName:"minecraft:wooden_door",meta:1,sideFlag:8b}
:enddata
:endrule

rule:
plugin=vanillaBlocks
number=52
data:
JSON:{buildPass:0,blockName:"minecraft:oak_stairs",meta:0}
:enddata
:endrule

rule:
plugin=vanillaBlocks
number=53
data:
JSON:{buildPass:0,blockName:"minecraft:oak_stairs",meta:1}
:enddata
:endrule

rule:
plugin=vanillaBlocks
number=54
data:
JSON:{buildPass:0,blockName:"minecraft:oak_stairs",meta:5}
:enddata
:endrule

rule:
plugin=vanillaSkull
number=55
data:
JSON:{buildPass:0,blockName:"minecraft:skull",meta:4,teData:{Rot:12,x:38,y:91,z:-39,id:"Skull",SkullType:1b}}
:enddata
:endrule

rule:
plugin=vanillaSkull
number=56
data:
JSON:{buildPass:0,blockName:"minecraft:skull",meta:4,teData:{Rot:12,x:38,y:91,z:-37,id:"Skull",SkullType:0b}}
:enddata
:endrule

rule:
plugin=vanillaDoors
number=57
data:
JSON:{buildPass:2,blockName:"minecraft:wooden_door",meta:8,sideFlag:0b}
:enddata
:endrule

rule:
plugin=vanillaBlocks
number=58
data:
JSON:{buildPass:0,blockName:"minecraft:log",meta:9}
:enddata
:endrule

rule:
plugin=vanillaBlocks
number=59
data:
JSON:{buildPass:0,blockName:"minecraft:oak_stairs",meta:3}
:enddata
:endrule

rule:
plugin=vanillaBlocks
number=60
data:
JSON:{buildPass:0,blockName:"minecraft:oak_stairs",meta:2}
:enddata
:endrule

rule:
plugin=vanillaBlocks
number=61
data:
JSON:{buildPass:2,blockName:"minecraft:trapdoor",meta:2}
:enddata
:endrule

rule:
plugin=vanillaBlocks
number=62
data:
JSON:{buildPass:0,blockName:"minecraft:oak_stairs",meta:4}
:enddata
:endrule

rule:
plugin=vanillaInventory
number=63
data:
JSON:{buildPass:0,blockName:"minecraft:chest",meta:3,lootLevel:0,teData:{x:30,y:94,z:-39,id:"Chest"},inventoryData:{length:27,inventoryContents:[{id:"minecraft:redstone_lamp",Count:6b,slot:0,Damage:0s}]}}
:enddata
:endrule

rule:
plugin=vanillaInventory
number=64
data:
JSON:{buildPass:0,blockName:"minecraft:chest",meta:3,lootLevel:0,teData:{x:31,y:94,z:-39,id:"Chest"},inventoryData:{length:27,inventoryContents:[]}}
:enddata
:endrule

rule:
plugin=vanillaInventory
number=65
data:
JSON:{buildPass:0,blockName:"minecraft:chest",meta:3,lootLevel:0,teData:{x:34,y:94,z:-39,id:"Chest"},inventoryData:{length:27,inventoryContents:[{id:"minecraft:redstone_lamp",Count:6b,slot:0,Damage:0s}]}}
:enddata
:endrule

rule:
plugin=vanillaInventory
number=66
data:
JSON:{buildPass:0,blockName:"minecraft:chest",meta:3,lootLevel:0,teData:{x:35,y:94,z:-39,id:"Chest"},inventoryData:{length:27,inventoryContents:[]}}
:enddata
:endrule

rule:
plugin=vanillaInventory
number=67
data:
JSON:{buildPass:0,blockName:"minecraft:chest",meta:5,lootLevel:0,teData:{x:27,y:94,z:-38,id:"Chest"},inventoryData:{length:27,inventoryContents:[{id:"minecraft:ender_pearl",Count:4b,slot:0,Damage:0s},{id:"minecraft:fermented_spider_eye",Count:16b,slot:1,Damage:0s}]}}
:enddata
:endrule

rule:
plugin=vanillaInventory
number=68
data:
JSON:{buildPass:0,blockName:"minecraft:chest",meta:5,lootLevel:0,teData:{x:27,y:94,z:-36,id:"Chest"},inventoryData:{length:27,inventoryContents:[{id:"minecraft:redstone_lamp",Count:6b,slot:0,Damage:0s}]}}
:enddata
:endrule

rule:
plugin=vanillaInventory
number=69
data:
JSON:{buildPass:0,blockName:"minecraft:chest",meta:5,lootLevel:0,teData:{x:27,y:94,z:-35,id:"Chest"},inventoryData:{length:27,inventoryContents:[]}}
:enddata
:endrule

rule:
plugin=vanillaInventory
number=70
data:
JSON:{buildPass:0,blockName:"minecraft:chest",meta:5,lootLevel:0,teData:{x:27,y:94,z:-33,id:"Chest"},inventoryData:{length:27,inventoryContents:[{id:"minecraft:ender_pearl",Count:4b,slot:0,Damage:0s},{id:"minecraft:fermented_spider_eye",Count:16b,slot:1,Damage:0s}]}}
:enddata
:endrule

rule:
plugin=vanillaBlocks
number=71
data:
JSON:{buildPass:0,blockName:"minecraft:web",meta:0}
:enddata
:endrule

rule:
plugin=vanillaInventory
number=72
data:
JSON:{buildPass:0,blockName:"minecraft:chest",meta:2,lootLevel:0,teData:{x:30,y:94,z:-32,id:"Chest"},inventoryData:{length:27,inventoryContents:[{id:"minecraft:golden_rail",Count:16b,slot:0,Damage:0s},{id:"minecraft:redstone_block",Count:3b,slot:1,Damage:0s}]}}
:enddata
:endrule

rule:
plugin=vanillaInventory
number=73
data:
JSON:{buildPass:0,blockName:"minecraft:chest",meta:2,lootLevel:0,teData:{x:31,y:94,z:-32,id:"Chest"},inventoryData:{length:27,inventoryContents:[]}}
:enddata
:endrule

rule:
plugin=vanillaInventory
number=74
data:
JSON:{buildPass:0,blockName:"minecraft:chest",meta:2,lootLevel:0,teData:{x:34,y:94,z:-32,id:"Chest"},inventoryData:{length:27,inventoryContents:[{id:"minecraft:dirt",Count:64b,slot:0,Damage:0s},{id:"minecraft:golden_apple",Count:3b,slot:1,Damage:1s}]}}
:enddata
:endrule

rule:
plugin=vanillaInventory
number=75
data:
JSON:{buildPass:0,blockName:"minecraft:chest",meta:2,lootLevel:0,teData:{x:35,y:94,z:-32,id:"Chest"},inventoryData:{length:27,inventoryContents:[]}}
:enddata
:endrule

rule:
plugin=vanillaBlocks
number=76
data:
JSON:{buildPass:0,blockName:"minecraft:oak_stairs",meta:6}
:enddata
:endrule

rule:
plugin=vanillaBlocks
number=77
data:
JSON:{buildPass:0,blockName:"minecraft:wooden_slab",meta:8}
:enddata
:endrule

rule:
plugin=vanillaBlocks
number=78
data:
JSON:{buildPass:0,blockName:"minecraft:brick_stairs",meta:2}
:enddata
:endrule

rule:
plugin=vanillaBlocks
number=79
data:
JSON:{buildPass:0,blockName:"minecraft:brick_stairs",meta:1}
:enddata
:endrule

rule:
plugin=vanillaBlocks
number=80
data:
JSON:{buildPass:0,blockName:"minecraft:brick_stairs",meta:3}
:enddata
:endrule

rule:
plugin=vanillaBlocks
number=81
data:
JSON:{buildPass:2,blockName:"minecraft:redstone_lamp",meta:0}
:enddata
:endrule

rule:
plugin=vanillaBlocks
number=82
data:
JSON:{buildPass:0,blockName:"minecraft:oak_stairs",meta:7}
:enddata
:endrule

rule:
plugin=vanillaBlocks
number=83
data:
JSON:{buildPass:0,blockName:"minecraft:wooden_slab",meta:0}
:enddata
:endrule

#### ENTITIES ####
