# Ancient Warfare Structure Template File
# Auto-generated structure template file. created on: 9/22/2018 at: 16:7:2
# Lines beginning with # denote comments

header:
version=2.6
name=unique_ranchhouse_pelirow
size=20,18,16
offset=9,1,15
:endheader

#### VALIDATION ####
validation:
type=ground
survival=false
worldGenEnabled=false
unique=false
preserveBlocks=false
selectionWeight=0
clusterValue=0
minDuplicateDistance=0
dimensionWhiteList=false
dimensionList=
biomeWhiteList=false
biomeList=
leveling=0
fill=0
border=0
blockSwap=false
data:
:enddata
:endvalidation

#### LAYERS ####
layer: 0
1,1,1,1,1,1,1,1,1,1,1,1,1,1,1,1,1,1,1,1
1,1,1,1,1,1,1,1,1,1,1,1,1,1,1,1,1,1,1,1
1,1,1,1,1,1,1,1,1,1,1,1,1,1,1,1,1,1,1,1
1,1,1,1,1,1,1,1,1,1,1,1,1,1,1,1,1,1,1,1
1,1,1,1,1,1,1,1,1,1,1,1,1,1,1,1,1,1,1,1
1,1,1,1,1,1,1,1,1,1,1,1,1,1,1,1,1,1,1,1
1,1,1,1,1,1,1,1,1,1,1,1,1,1,1,1,1,1,1,1
1,1,1,1,1,1,1,1,1,2,2,1,1,1,1,1,1,1,1,1
1,1,1,1,1,1,1,1,1,1,1,1,1,1,1,1,1,1,1,1
1,1,1,1,1,1,1,1,1,1,1,1,1,1,1,1,1,1,1,1
1,1,1,1,1,1,1,1,1,1,1,1,1,1,1,1,1,1,1,1
1,1,1,1,1,1,1,1,1,1,1,1,1,1,1,1,1,1,1,1
1,1,1,1,1,1,1,1,1,1,1,1,1,1,1,1,1,1,1,1
1,1,1,1,1,1,1,1,2,2,2,2,1,1,1,1,1,1,1,1
1,1,1,1,1,1,1,1,1,1,1,1,1,1,1,1,1,1,1,1
1,1,1,1,1,1,1,1,1,1,1,1,1,1,1,1,1,1,1,1
:endlayer
layer: 1
0,0,3,0,0,3,0,0,3,0,0,3,0,0,3,0,0,3,0,0
0,0,0,0,0,0,0,0,0,0,0,0,0,0,0,0,0,0,0,0
0,0,0,0,0,0,0,0,0,0,0,0,0,0,0,0,0,0,0,0
0,0,0,0,0,0,0,0,0,0,0,0,0,0,0,0,0,0,0,0
0,0,0,0,0,0,0,0,0,0,0,0,0,0,0,0,0,0,0,0
0,0,0,0,0,0,0,0,0,0,0,0,0,0,0,0,0,0,0,0
0,0,0,0,0,0,0,0,0,0,0,0,0,0,0,0,0,0,0,0
0,0,0,0,0,0,0,0,0,0,0,0,0,0,0,0,0,0,0,0
0,0,0,0,0,0,0,0,0,0,0,0,0,0,0,0,0,0,0,0
0,0,3,0,0,3,0,0,3,0,0,3,0,0,3,0,0,3,0,0
0,0,3,0,0,0,0,0,0,0,0,0,0,0,0,0,0,3,0,0
0,0,3,0,0,0,0,0,0,0,0,0,0,0,0,0,0,3,0,0
0,0,3,3,3,3,3,3,3,3,3,3,3,3,3,3,3,3,0,0
0,0,0,0,0,0,0,3,4,4,4,4,3,0,0,0,0,0,0,0
0,0,0,0,0,0,0,3,0,0,0,0,3,0,0,0,0,0,0,0
0,0,0,0,0,0,0,3,0,0,0,0,3,0,0,0,0,0,0,0
:endlayer
layer: 2
0,0,5,5,5,5,5,5,5,5,5,5,5,5,5,5,5,5,0,0
0,0,5,5,5,5,5,5,5,5,5,5,5,5,5,5,5,5,0,0
0,0,5,5,5,5,5,5,5,5,5,5,5,5,5,5,5,5,0,0
0,0,5,5,5,5,5,5,5,5,5,5,5,5,5,5,5,5,0,0
0,0,5,5,5,5,5,5,5,5,5,5,5,5,5,5,6,6,0,0
0,0,5,5,5,5,5,5,5,5,5,5,5,5,5,5,5,5,0,0
0,0,5,5,5,5,5,5,5,5,5,5,5,5,5,5,5,5,0,0
0,0,5,5,5,5,5,5,5,5,5,5,5,5,5,5,5,5,0,0
0,3,5,5,5,5,5,5,5,5,5,5,5,5,5,5,5,5,3,0
0,3,7,7,7,7,7,8,8,8,8,8,8,8,8,8,8,8,3,0
0,3,7,7,7,7,5,8,8,8,8,8,8,8,8,8,8,8,3,0
0,3,7,7,7,7,7,8,8,8,8,8,8,8,8,8,8,8,3,0
0,3,7,7,7,7,7,8,8,8,8,8,8,8,8,8,8,8,3,0
0,3,3,3,3,3,3,3,0,0,0,0,3,3,3,3,3,3,3,0
0,0,0,0,0,0,0,3,0,0,0,0,3,0,0,0,0,0,0,0
0,0,0,0,0,0,0,0,0,0,0,0,0,0,0,0,0,0,0,0
:endlayer
layer: 3
0,0,9,10,10,10,10,10,10,10,10,10,10,10,10,10,10,9,0,0
0,0,10,0,11,3,12,0,5,13,14,5,0,15,0,16,0,10,0,0
0,0,10,0,0,0,0,0,3,4,4,3,0,0,0,0,0,10,0,0
0,0,10,17,0,0,0,0,0,0,0,0,0,0,4,0,18,6,6,0
0,0,10,19,0,0,0,0,20,20,20,20,0,0,11,0,0,0,6,0
0,0,10,21,0,0,0,0,20,22,22,20,0,0,23,0,18,6,6,0
0,0,10,0,0,0,0,0,20,20,20,20,0,0,0,0,0,10,0,0
0,0,10,0,0,24,0,0,0,0,0,0,0,25,0,26,0,10,0,0
0,3,9,5,5,5,5,5,9,27,28,9,5,5,5,5,5,9,3,0
0,3,0,0,4,0,0,0,0,0,0,0,0,0,0,0,0,0,3,0
0,3,0,11,3,0,0,0,0,0,0,0,0,11,4,12,0,0,3,0
0,3,0,0,23,0,0,0,0,0,0,0,0,0,0,0,0,0,3,0
0,3,0,0,0,0,0,0,0,0,0,0,0,0,0,0,0,0,3,0
0,3,3,3,3,3,3,3,0,0,0,0,3,3,3,3,3,3,3,0
0,0,0,0,0,0,0,0,0,0,0,0,0,0,0,0,0,0,0,0
0,0,0,0,0,0,0,0,0,0,0,0,0,0,0,0,0,0,0,0
:endlayer
layer: 4
0,0,9,10,29,29,29,10,5,5,5,5,10,29,29,29,10,9,0,0
0,0,29,30,0,31,0,30,11,8,8,12,30,0,0,0,30,10,0,0
0,0,29,0,0,0,0,0,3,0,0,3,0,0,0,0,0,10,0,0
0,0,10,32,0,0,0,0,0,0,0,0,0,0,0,0,33,6,6,0
0,0,29,0,0,0,0,0,0,0,0,0,0,0,0,0,33,0,6,0
0,0,10,32,0,0,0,0,0,0,0,0,0,0,0,0,33,6,6,0
0,0,29,0,0,0,0,0,0,0,0,0,0,0,0,0,34,10,0,0
0,0,29,0,0,35,0,0,35,0,0,35,0,0,35,0,0,10,0,0
0,0,9,29,29,5,29,29,9,36,37,9,29,29,5,29,29,9,0,0
0,0,0,0,0,0,0,0,30,0,0,30,0,0,0,0,0,30,0,0
0,0,0,0,38,0,0,0,0,0,0,0,0,3,0,3,0,0,0,0
0,0,0,0,0,0,0,0,0,0,0,0,0,0,0,0,0,0,0,0
0,0,0,0,0,0,0,0,0,0,0,0,0,0,0,0,0,0,0,0
0,0,3,0,0,0,0,3,0,0,0,0,3,0,0,0,0,3,0,0
0,0,0,0,0,0,0,0,0,0,0,0,0,0,0,0,0,0,0,0
0,0,0,0,0,0,0,0,0,0,0,0,0,0,0,0,0,0,0,0
:endlayer
layer: 5
0,0,9,10,10,10,10,5,10,10,10,10,5,10,10,10,10,9,0,0
0,0,10,0,0,0,0,11,0,0,0,0,12,0,0,0,0,10,0,0
0,0,10,0,0,0,0,0,3,0,0,3,0,0,0,0,0,10,0,0
0,0,10,0,0,0,0,0,0,0,0,0,0,0,0,0,39,6,6,0
0,0,10,0,0,0,0,0,0,0,0,0,0,0,0,0,0,6,6,0
0,0,10,0,0,0,0,0,0,0,0,0,0,0,0,0,40,6,6,0
0,0,10,0,0,0,0,0,0,0,0,0,0,0,0,0,0,10,0,0
0,0,10,0,0,0,0,0,0,0,0,0,0,0,0,0,0,10,0,0
0,0,9,5,5,5,5,5,9,9,9,9,5,5,5,5,5,9,0,0
0,0,30,0,0,0,0,0,0,0,0,0,0,0,0,0,0,0,0,0
0,0,0,0,0,0,0,0,0,0,0,0,0,3,0,3,0,0,0,0
0,0,0,0,0,0,0,0,0,0,0,0,0,0,0,0,0,0,0,0
0,0,0,0,0,0,0,0,0,0,0,0,0,0,0,0,0,0,0,0
0,0,3,0,0,0,0,3,0,0,0,0,3,0,0,0,0,3,0,0
0,0,0,0,0,0,0,0,0,0,0,0,0,0,0,0,0,0,0,0
0,0,0,0,0,0,0,0,0,0,0,0,0,0,0,0,0,0,0,0
:endlayer
layer: 6
0,0,9,5,5,5,5,10,10,10,10,10,10,5,5,5,5,9,0,0
0,0,5,5,5,5,11,0,0,0,0,0,0,12,5,5,5,5,0,0
0,0,5,5,5,5,5,5,3,0,0,3,5,5,5,5,5,5,0,0
0,0,5,5,5,5,5,5,0,0,0,0,5,5,5,5,6,6,6,0
0,0,5,5,5,5,5,5,0,0,0,0,5,5,5,5,6,41,6,0
0,0,5,5,5,5,5,5,0,0,0,0,5,5,5,5,6,6,6,0
0,0,5,5,5,5,5,5,0,0,0,0,5,5,5,5,5,5,0,0
0,0,5,5,5,5,5,5,0,0,0,0,5,5,5,5,5,5,0,0
0,0,9,42,42,42,42,42,42,42,42,42,42,42,42,42,42,9,0,0
0,0,0,0,0,0,0,0,0,0,0,0,0,0,0,0,0,0,0,0
0,0,0,0,0,0,0,0,0,0,0,0,0,3,0,3,0,0,0,0
0,0,0,0,0,0,0,0,0,0,0,0,0,0,0,0,0,0,0,0
0,0,0,0,0,0,0,0,0,0,0,0,0,0,0,0,0,0,0,0
0,0,3,0,0,0,0,3,0,0,0,0,3,0,0,0,0,3,0,0
0,0,0,0,0,0,0,0,0,0,0,0,0,0,0,0,0,0,0,0
0,0,0,0,0,0,0,0,0,0,0,0,0,0,0,0,0,0,0,0
:endlayer
layer: 7
0,0,9,10,10,10,10,10,10,29,29,10,10,10,10,10,10,9,0,0
0,0,10,43,0,0,0,0,0,0,0,0,0,0,0,0,0,10,0,0
0,0,10,44,45,0,0,3,0,0,0,0,3,0,0,0,0,10,0,0
0,0,10,44,45,0,0,3,0,0,0,0,3,0,0,18,6,6,6,0
0,0,10,43,0,0,0,3,0,0,0,0,3,46,0,0,0,41,6,0
0,0,10,0,0,0,0,3,0,0,0,0,3,0,0,18,6,6,6,0
0,0,10,8,8,8,8,3,0,0,0,0,3,0,0,0,0,10,0,0
0,0,10,5,5,5,8,3,0,47,48,0,3,0,43,43,0,10,0,0
0,0,9,5,5,5,5,5,5,5,5,5,5,5,5,5,5,9,0,0
0,0,7,7,7,7,8,8,8,8,8,8,8,8,8,8,8,7,0,0
0,0,7,8,8,8,8,8,8,8,8,8,8,8,8,8,8,7,0,0
0,0,7,8,8,8,8,8,8,8,8,8,8,8,8,8,8,7,0,0
0,0,7,8,8,8,8,8,8,8,8,8,8,8,8,8,8,7,0,0
0,0,7,7,7,7,7,7,7,7,7,7,7,7,7,7,7,7,0,0
0,0,0,0,0,0,0,0,0,0,0,0,0,0,0,0,0,0,0,0
0,0,0,0,0,0,0,0,0,0,0,0,0,0,0,0,0,0,0,0
:endlayer
layer: 8
0,0,9,10,29,29,10,10,29,29,29,29,10,10,29,29,10,9,0,0
0,0,10,49,0,0,0,30,0,0,0,0,30,0,0,0,34,10,0,0
0,0,29,0,0,0,0,0,0,0,0,0,0,0,0,0,0,10,0,0
0,0,29,0,0,0,0,0,0,0,0,0,0,0,0,33,6,6,6,0
0,0,10,49,0,0,0,0,0,0,0,0,0,0,0,33,50,0,6,0
0,0,29,0,0,0,0,0,0,0,0,0,0,0,0,33,6,6,6,0
0,0,29,0,0,0,0,0,0,0,0,0,0,0,0,0,0,10,0,0
0,0,10,0,0,0,0,0,0,0,0,0,0,0,0,0,34,10,0,0
0,0,9,5,51,5,9,29,29,29,29,29,29,9,29,29,29,9,0,0
0,0,3,0,0,0,0,0,0,0,0,0,0,0,0,0,0,3,0,0
0,0,3,0,0,0,0,0,0,0,0,0,0,0,0,0,0,3,0,0
0,0,3,0,0,0,0,0,0,0,0,0,0,0,0,0,0,3,0,0
0,0,3,0,0,0,0,0,0,0,0,0,0,0,0,0,0,3,0,0
0,0,3,3,3,3,3,3,3,3,3,3,3,3,3,3,3,3,0,0
0,0,0,0,0,0,0,0,0,0,0,0,0,0,0,0,0,0,0,0
0,0,0,0,0,0,0,0,0,0,0,0,0,0,0,0,0,0,0,0
:endlayer
layer: 9
52,10,9,10,29,29,10,10,10,29,29,10,10,10,29,29,10,9,10,53
52,54,10,0,0,0,0,0,0,0,0,0,0,0,0,0,0,10,10,53
52,54,10,0,0,0,0,0,0,0,0,0,0,0,0,0,0,10,10,53
52,54,10,0,0,0,0,0,0,0,0,0,0,0,0,55,6,6,6,53
52,54,10,0,0,0,0,0,0,0,0,0,0,0,0,0,6,0,6,53
52,54,10,0,0,0,0,0,0,0,0,0,0,0,0,56,6,6,6,53
52,54,10,0,0,0,0,0,0,0,0,0,0,0,0,0,0,10,10,53
52,54,10,35,0,35,0,0,0,0,0,0,0,0,0,0,0,10,10,53
52,54,9,5,57,5,9,29,29,29,29,29,29,9,29,29,29,9,10,53
0,0,0,0,0,0,0,0,0,0,0,0,0,0,0,0,0,0,0,0
0,0,0,0,0,0,0,0,0,0,0,0,0,0,0,0,0,0,0,0
0,0,0,0,0,0,0,0,0,0,0,0,0,0,0,0,0,0,0,0
0,0,0,0,0,0,0,0,0,0,0,0,0,0,0,0,0,0,0,0
0,0,3,0,0,0,0,3,0,0,0,0,3,0,0,0,0,3,0,0
0,0,0,0,0,0,0,0,0,0,0,0,0,0,0,0,0,0,0,0
0,0,0,0,0,0,0,0,0,0,0,0,0,0,0,0,0,0,0,0
:endlayer
layer: 10
0,52,9,42,42,42,42,42,42,42,42,42,42,42,42,42,42,9,53,0
0,52,58,0,0,0,0,0,0,0,0,0,0,0,0,0,0,58,53,0
0,52,58,0,0,0,0,0,0,0,0,0,0,0,0,0,0,58,53,0
0,52,58,0,0,0,0,0,0,0,0,0,0,0,0,0,6,6,6,0
0,52,58,0,0,0,0,0,0,0,0,0,0,0,0,0,6,0,6,0
0,52,58,0,0,0,0,0,0,0,0,0,0,0,0,0,6,6,6,0
0,52,58,0,0,0,0,0,0,0,0,0,0,0,0,0,0,58,53,0
0,52,58,0,0,0,0,0,0,0,0,0,0,0,0,0,0,58,53,0
0,52,9,42,42,42,42,42,42,42,42,42,42,42,42,42,42,42,53,0
0,52,0,0,0,0,30,0,0,0,0,0,0,30,0,0,0,30,53,0
0,52,0,0,0,0,0,0,0,0,0,0,0,0,0,0,0,0,53,0
0,52,0,0,0,0,0,0,0,0,0,0,0,0,0,0,0,0,53,0
0,52,0,0,0,0,0,0,0,0,0,0,0,0,0,0,0,0,53,0
0,52,3,0,0,0,0,3,0,0,0,0,3,0,0,0,0,3,53,0
0,52,59,59,59,59,59,59,59,59,59,59,59,59,59,59,59,59,59,0
0,0,0,0,0,0,0,0,0,0,0,0,0,0,0,0,0,0,0,0
:endlayer
layer: 11
0,0,52,10,60,60,60,60,60,60,60,60,60,60,60,60,10,53,0,0
0,0,52,10,10,10,10,10,10,10,10,10,10,10,10,10,10,53,0,0
0,0,52,10,10,10,10,10,10,10,10,10,10,10,10,10,10,53,0,0
0,0,52,10,10,10,10,10,10,10,10,10,10,10,10,10,6,6,6,0
0,0,52,10,10,10,10,10,10,10,10,10,10,10,10,10,6,0,6,0
0,0,52,10,10,10,10,10,10,10,10,10,10,10,10,10,6,6,6,0
0,0,52,10,10,10,10,10,10,10,10,10,10,10,61,10,10,53,0,0
0,0,52,10,10,10,10,10,10,10,10,10,10,10,10,10,10,53,0,0
0,0,52,10,10,10,10,10,10,10,10,10,10,10,10,10,10,53,0,0
0,0,52,10,10,10,10,10,10,10,10,10,10,10,10,10,10,53,0,0
0,0,52,10,10,10,10,10,10,10,10,10,10,10,10,10,10,53,0,0
0,0,52,10,10,10,10,10,10,10,10,10,10,10,10,10,10,53,0,0
0,0,52,10,10,10,10,10,10,10,10,10,10,10,10,10,10,53,0,0
0,0,52,10,59,59,59,59,59,59,59,59,59,59,59,59,10,59,0,0
0,0,0,0,0,0,0,0,0,0,0,0,0,0,0,0,0,0,0,0
0,0,0,0,0,0,0,0,0,0,0,0,0,0,0,0,0,0,0,0
:endlayer
layer: 12
0,0,0,52,54,0,0,0,0,0,0,0,0,0,0,62,53,0,0,0
0,0,0,52,10,60,60,60,60,60,60,60,60,60,60,10,53,0,0,0
0,0,0,52,10,10,10,10,10,10,10,10,10,10,10,10,53,0,0,0
0,0,0,52,0,0,0,63,64,0,0,65,66,0,0,10,6,6,6,0
0,0,0,52,67,0,0,0,0,0,0,0,0,0,0,10,6,0,6,0
0,0,0,52,0,0,0,0,0,0,0,0,0,0,0,10,6,6,6,0
0,0,0,52,68,0,0,0,0,0,0,0,0,0,0,10,53,0,0,0
0,0,0,52,69,0,0,49,0,0,0,49,0,0,0,10,53,0,0,0
0,0,0,52,0,0,0,0,0,0,0,0,0,0,0,10,53,0,0,0
0,0,0,52,70,0,0,0,0,0,0,0,0,0,0,10,53,0,0,0
0,0,0,52,71,0,0,72,73,0,0,74,75,0,0,10,53,0,0,0
0,0,0,52,10,10,10,10,10,10,10,10,10,10,10,10,53,0,0,0
0,0,0,52,53,59,59,59,59,59,59,59,59,59,59,52,53,0,0,0
0,0,0,52,54,0,0,0,0,0,0,0,0,0,0,62,53,0,0,0
0,0,0,0,0,0,0,0,0,0,0,0,0,0,0,0,0,0,0,0
0,0,0,0,0,0,0,0,0,0,0,0,0,0,0,0,0,0,0,0
:endlayer
layer: 13
0,0,0,0,52,54,0,0,0,0,0,0,0,0,62,53,0,0,0,0
0,0,0,0,52,54,0,0,0,0,0,0,0,0,62,53,0,0,0,0
0,0,0,0,52,10,10,29,29,10,10,29,29,10,10,53,0,0,0,0
0,0,0,0,52,0,30,0,0,0,0,0,0,30,0,53,6,6,6,0
0,0,0,0,52,0,0,0,0,0,0,0,0,0,0,53,6,0,6,0
0,0,0,0,52,0,0,0,0,0,0,0,0,0,0,53,6,6,6,0
0,0,0,0,52,0,0,0,0,0,0,0,0,0,0,53,0,0,0,0
0,0,0,0,52,0,0,0,0,0,0,0,0,0,0,53,0,0,0,0
0,0,0,0,52,0,0,0,0,0,0,0,0,0,0,53,0,0,0,0
0,0,0,0,52,0,0,0,0,0,0,0,0,0,0,53,0,0,0,0
0,0,0,0,52,0,35,0,0,0,0,0,0,35,0,53,0,0,0,0
0,0,0,0,52,10,10,29,29,10,10,29,29,10,10,53,0,0,0,0
0,0,0,0,52,54,0,0,0,0,0,0,0,0,62,53,0,0,0,0
0,0,0,0,52,54,0,0,0,0,0,0,0,0,62,53,0,0,0,0
0,0,0,0,0,0,0,0,0,0,0,0,0,0,0,0,0,0,0,0
0,0,0,0,0,0,0,0,0,0,0,0,0,0,0,0,0,0,0,0
:endlayer
layer: 14
0,0,0,0,0,52,54,0,0,0,0,0,0,62,53,0,0,0,0,0
0,0,0,0,0,52,54,0,0,0,0,0,0,62,53,0,0,0,0,0
0,0,0,0,0,52,10,29,29,10,10,29,29,10,53,0,0,0,0,0
0,0,0,0,0,52,0,0,0,0,0,0,0,0,53,0,6,6,6,0
0,0,0,0,0,52,0,0,0,0,0,0,0,0,53,0,6,0,6,0
0,0,0,0,0,52,0,0,0,0,0,0,0,0,53,0,6,6,6,0
0,0,0,0,0,52,0,0,0,0,0,0,0,0,53,0,0,0,0,0
0,0,0,0,0,52,0,0,0,0,0,0,0,0,53,0,0,0,0,0
0,0,0,0,0,52,0,0,0,0,0,0,0,0,53,0,0,0,0,0
0,0,0,0,0,52,0,0,0,0,0,0,0,0,53,0,0,0,0,0
0,0,0,0,0,52,0,0,0,0,0,0,0,71,53,0,0,0,0,0
0,0,0,0,0,52,10,29,29,10,10,29,29,10,53,0,0,0,0,0
0,0,0,0,0,52,54,0,0,0,0,0,0,62,53,0,0,0,0,0
0,0,0,0,0,52,54,0,0,0,0,0,0,62,53,0,0,0,0,0
0,0,0,0,0,0,0,0,0,0,0,0,0,0,0,0,0,0,0,0
0,0,0,0,0,0,0,0,0,0,0,0,0,0,0,0,0,0,0,0
:endlayer
layer: 15
0,0,0,0,0,0,52,54,0,0,0,0,62,53,0,0,0,0,0,0
0,0,0,0,0,0,52,54,76,76,76,76,62,53,0,0,0,0,0,0
0,0,0,0,0,0,52,10,10,10,10,10,10,53,0,0,0,0,0,0
0,0,0,0,0,0,52,0,0,0,0,0,0,53,0,0,6,6,6,0
0,0,0,0,0,0,52,0,0,0,0,0,0,53,0,0,6,0,6,0
0,0,0,0,0,0,52,0,0,0,0,0,0,53,0,0,6,6,6,0
0,0,0,0,0,0,52,0,0,0,0,0,0,53,0,0,0,0,0,0
0,0,0,0,0,0,52,0,0,0,0,0,0,53,0,0,0,0,0,0
0,0,0,0,0,0,52,0,0,0,0,0,0,53,0,0,0,0,0,0
0,0,0,0,0,0,52,71,0,0,0,0,0,53,0,0,0,0,0,0
0,0,0,0,0,0,52,71,0,0,0,0,0,53,0,0,0,0,0,0
0,0,0,0,0,0,52,10,10,10,10,10,10,53,0,0,0,0,0,0
0,0,0,0,0,0,52,54,0,0,0,0,62,53,0,0,0,0,0,0
0,0,0,0,0,0,52,54,0,0,0,0,62,53,0,0,0,0,0,0
0,0,0,0,0,0,0,0,0,0,0,0,0,0,0,0,0,0,0,0
0,0,0,0,0,0,0,0,0,0,0,0,0,0,0,0,0,0,0,0
:endlayer
layer: 16
0,0,0,0,0,0,0,52,54,77,77,62,53,0,0,0,0,0,0,0
0,0,0,0,0,0,0,52,10,10,10,10,53,0,0,0,0,0,0,0
0,0,0,0,0,0,0,52,10,10,10,10,53,0,0,0,0,0,0,0
0,0,0,0,0,0,0,52,10,10,10,10,53,0,0,0,78,78,79,0
0,0,0,0,0,0,0,52,10,10,10,10,53,0,0,0,18,0,79,0
0,0,0,0,0,0,0,52,10,10,10,10,53,0,0,0,18,80,80,0
0,0,0,0,0,0,0,52,10,81,81,10,53,0,0,0,0,0,0,0
0,0,0,0,0,0,0,52,10,81,81,10,53,0,0,0,0,0,0,0
0,0,0,0,0,0,0,52,10,10,10,10,53,0,0,0,0,0,0,0
0,0,0,0,0,0,0,52,10,10,10,10,53,0,0,0,0,0,0,0
0,0,0,0,0,0,0,52,10,10,10,10,53,0,0,0,0,0,0,0
0,0,0,0,0,0,0,52,10,10,10,10,53,0,0,0,0,0,0,0
0,0,0,0,0,0,0,52,54,82,82,62,53,0,0,0,0,0,0,0
0,0,0,0,0,0,0,52,54,77,77,62,53,0,0,0,0,0,0,0
0,0,0,0,0,0,0,0,0,0,0,0,0,0,0,0,0,0,0,0
0,0,0,0,0,0,0,0,0,0,0,0,0,0,0,0,0,0,0,0
:endlayer
layer: 17
0,0,0,0,0,0,0,0,83,83,83,83,0,0,0,0,0,0,0,0
0,0,0,0,0,0,0,0,83,83,83,83,0,0,0,0,0,0,0,0
0,0,0,0,0,0,0,0,83,83,83,83,0,0,0,0,0,0,0,0
0,0,0,0,0,0,0,0,83,83,83,83,0,0,0,0,0,0,0,0
0,0,0,0,0,0,0,0,83,83,83,83,0,0,0,0,0,0,0,0
0,0,0,0,0,0,0,0,83,83,83,83,0,0,0,0,0,0,0,0
0,0,0,0,0,0,0,0,83,83,83,83,0,0,0,0,0,0,0,0
0,0,0,0,0,0,0,0,83,83,83,83,0,0,0,0,0,0,0,0
0,0,0,0,0,0,0,0,83,83,83,83,0,0,0,0,0,0,0,0
0,0,0,0,0,0,0,0,83,83,83,83,0,0,0,0,0,0,0,0
0,0,0,0,0,0,0,0,83,83,83,83,0,0,0,0,0,0,0,0
0,0,0,0,0,0,0,0,83,83,83,83,0,0,0,0,0,0,0,0
0,0,0,0,0,0,0,0,83,83,83,83,0,0,0,0,0,0,0,0
0,0,0,0,0,0,0,0,83,83,83,83,0,0,0,0,0,0,0,0
0,0,0,0,0,0,0,0,0,0,0,0,0,0,0,0,0,0,0,0
0,0,0,0,0,0,0,0,0,0,0,0,0,0,0,0,0,0,0,0
:endlayer

#### RULES ####
rule:
plugin=vanillaBlocks
number=1
data:
JSON:{blockState:{blockName:"minecraft:grass",properties:{snowy:"false"}},buildPass:0}
:enddata
:endrule

rule:
plugin=vanillaBlocks
number=2
data:
JSON:{blockState:{blockName:"minecraft:dirt",properties:{variant:"dirt",snowy:"false"}},buildPass:0}
:enddata
:endrule

rule:
plugin=vanillaBlocks
number=3
data:
JSON:{blockState:{blockName:"minecraft:fence",properties:{east:"false",south:"false",north:"false",west:"false"}},buildPass:0}
:enddata
:endrule

rule:
plugin=vanillaBlocks
number=4
data:
JSON:{blockState:{blockName:"minecraft:spruce_stairs",properties:{half:"bottom",shape:"straight",facing:"north"}},buildPass:0}
:enddata
:endrule

rule:
plugin=vanillaBlocks
number=5
data:
JSON:{blockState:{blockName:"minecraft:planks",properties:{variant:"spruce"}},buildPass:0}
:enddata
:endrule

rule:
plugin=vanillaBlocks
number=6
data:
JSON:{blockState:{blockName:"minecraft:brick_block",properties:{}},buildPass:0}
:enddata
:endrule

rule:
plugin=vanillaBlocks
number=7
data:
JSON:{blockState:{blockName:"minecraft:double_wooden_slab",properties:{variant:"spruce"}},buildPass:0}
:enddata
:endrule

rule:
plugin=vanillaBlocks
number=8
data:
JSON:{blockState:{blockName:"minecraft:wooden_slab",properties:{half:"bottom",variant:"spruce"}},buildPass:0}
:enddata
:endrule

rule:
plugin=vanillaBlocks
number=9
data:
JSON:{blockState:{blockName:"minecraft:log",properties:{variant:"spruce",axis:"y"}},buildPass:0}
:enddata
:endrule

rule:
plugin=vanillaBlocks
number=10
data:
JSON:{blockState:{blockName:"minecraft:planks",properties:{variant:"oak"}},buildPass:0}
:enddata
:endrule

rule:
plugin=vanillaBlocks
number=11
data:
JSON:{blockState:{blockName:"minecraft:spruce_stairs",properties:{half:"bottom",shape:"straight",facing:"west"}},buildPass:0}
:enddata
:endrule

rule:
plugin=vanillaBlocks
number=12
data:
JSON:{blockState:{blockName:"minecraft:spruce_stairs",properties:{half:"bottom",shape:"straight",facing:"east"}},buildPass:0}
:enddata
:endrule

rule:
plugin=inventory
number=13
data:
JSON:{blockState:{blockName:"minecraft:chest",properties:{facing:"south"}},buildPass:0,lootLevel:0,teData:{x:32,y:85,z:-41,id:"Chest"},inventoryData:{length:27,inventoryContents:[{id:"minecraft:iron_chestplate",Count:1b,slot:0,Damage:0s},{id:"minecraft:iron_sword",Count:1b,slot:1,Damage:0s},{id:"minecraft:iron_ingot",Count:2b,slot:2,Damage:0s},{id:"minecraft:iron_axe",Count:1b,slot:3,Damage:0s}]}}
:enddata
:endrule

rule:
plugin=inventory
number=14
data:
JSON:{blockState:{blockName:"minecraft:chest",properties:{facing:"south"}},buildPass:0,lootLevel:2,teData:{x:33,y:85,z:-41,id:"Chest"},inventoryData:{length:27,inventoryContents:[{id:"minecraft:diamond",Count:2b,slot:0,Damage:0s}]}}
:enddata
:endrule

rule:
plugin=vanillaFlowerPot
number=15
data:
JSON:{blockState:{blockName:"minecraft:flower_pot",properties:{}},itemName:"minecraft:red_flower",buildPass:0,itemMeta:1}
:enddata
:endrule

rule:
plugin=vanillaFlowerPot
number=16
data:
JSON:{blockState:{blockName:"minecraft:flower_pot",properties:{}},itemName:"minecraft:red_flower",buildPass:0,itemMeta:5}
:enddata
:endrule

rule:
plugin=vanillaBlocks
number=17
data:
JSON:{blockState:{blockName:"minecraft:cauldron",properties:{level:"0"}},buildPass:0}
:enddata
:endrule

rule:
plugin=vanillaBlocks
number=18
data:
JSON:{blockState:{blockName:"minecraft:brick_stairs",properties:{half:"bottom",shape:"straight",facing:"east"}},buildPass:0}
:enddata
:endrule

rule:
plugin=vanillaBlocks
number=19
data:
JSON:{blockState:{blockName:"minecraft:crafting_table",properties:{}},buildPass:0}
:enddata
:endrule

rule:
plugin=vanillaBlocks
number=20
data:
JSON:{blockState:{blockName:"minecraft:carpet",properties:{color:"black"}},buildPass:2}
:enddata
:endrule

rule:
plugin=blockTile
number=21
data:
JSON:{blockState:{blockName:"minecraft:furnace",properties:{facing:"east"}},buildPass:0,teData:{CookTime:0s,BurnTime:0s,x:26,y:85,Items:[],z:-37,id:"Furnace"}}
:enddata
:endrule

rule:
plugin=vanillaBlocks
number=22
data:
JSON:{blockState:{blockName:"minecraft:carpet",properties:{color:"red"}},buildPass:2}
:enddata
:endrule

rule:
plugin=vanillaBlocks
number=23
data:
JSON:{blockState:{blockName:"minecraft:spruce_stairs",properties:{half:"bottom",shape:"straight",facing:"south"}},buildPass:0}
:enddata
:endrule

rule:
plugin=vanillaBlocks
number=24
data:
JSON:{blockState:{blockName:"minecraft:anvil",properties:{damage:"0",facing:"east"}},buildPass:0}
:enddata
:endrule

rule:
plugin=vanillaFlowerPot
number=25
data:
JSON:{blockState:{blockName:"minecraft:flower_pot",properties:{}},itemName:"minecraft:red_flower",buildPass:0,itemMeta:5}
:enddata
:endrule

rule:
plugin=vanillaFlowerPot
number=26
data:
JSON:{blockState:{blockName:"minecraft:flower_pot",properties:{}},itemName:"minecraft:red_flower",buildPass:0,itemMeta:1}
:enddata
:endrule

rule:
plugin=doors
number=27
data:
JSON:{blockState:{blockName:"minecraft:wooden_door",properties:{hinge:"left",half:"lower",powered:"false",facing:"north",open:"false"}},buildPass:2}
:enddata
:endrule

rule:
plugin=doors
number=28
data:
JSON:{blockState:{blockName:"minecraft:wooden_door",properties:{hinge:"left",half:"lower",powered:"false",facing:"north",open:"false"}},buildPass:2}
:enddata
:endrule

rule:
plugin=vanillaBlocks
number=29
data:
JSON:{blockState:{blockName:"minecraft:glass_pane",properties:{east:"false",south:"false",north:"false",west:"false"}},buildPass:0}
:enddata
:endrule

rule:
plugin=vanillaBlocks
number=30
data:
JSON:{blockState:{blockName:"minecraft:torch",properties:{facing:"south"}},buildPass:2}
:enddata
:endrule

rule:
plugin=vanillaBlocks
number=31
data:
JSON:{blockState:{blockName:"minecraft:heavy_weighted_pressure_plate",properties:{power:"0"}},buildPass:2}
:enddata
:endrule

rule:
plugin=vanillaBlocks
number=32
data:
JSON:{blockState:{blockName:"minecraft:torch",properties:{facing:"east"}},buildPass:2}
:enddata
:endrule

rule:
plugin=vanillaBlocks
number=33
data:
JSON:{blockState:{blockName:"minecraft:brick_stairs",properties:{half:"top",shape:"straight",facing:"east"}},buildPass:0}
:enddata
:endrule

rule:
plugin=vanillaBlocks
number=34
data:
JSON:{blockState:{blockName:"minecraft:torch",properties:{facing:"west"}},buildPass:2}
:enddata
:endrule

rule:
plugin=vanillaBlocks
number=35
data:
JSON:{blockState:{blockName:"minecraft:torch",properties:{facing:"north"}},buildPass:2}
:enddata
:endrule

rule:
plugin=doors
number=36
data:
JSON:{blockState:{blockName:"minecraft:wooden_door",properties:{hinge:"left",half:"upper",powered:"false",facing:"north",open:"false"}},buildPass:2}
:enddata
:endrule

rule:
plugin=doors
number=37
data:
JSON:{blockState:{blockName:"minecraft:wooden_door",properties:{hinge:"right",half:"upper",powered:"false",facing:"north",open:"false"}},buildPass:2}
:enddata
:endrule

rule:
plugin=vanillaBlocks
number=38
data:
JSON:{blockState:{blockName:"minecraft:wooden_pressure_plate",properties:{powered:"false"}},buildPass:2}
:enddata
:endrule

rule:
plugin=vanillaSkull
number=39
data:
JSON:{blockState:{blockName:"minecraft:skull",properties:{nodrop:"false",facing:"west"}},buildPass:0,teData:{Rot:12,x:39,y:87,z:-39,id:"Skull",SkullType:4b}}
:enddata
:endrule

rule:
plugin=vanillaSkull
number=40
data:
JSON:{blockState:{blockName:"minecraft:skull",properties:{nodrop:"false",facing:"west"}},buildPass:0,teData:{Rot:12,x:39,y:87,z:-37,id:"Skull",SkullType:2b}}
:enddata
:endrule

rule:
plugin=vanillaBlocks
number=41
data:
JSON:{blockState:{blockName:"minecraft:iron_bars",properties:{east:"false",south:"false",north:"false",west:"false"}},buildPass:0}
:enddata
:endrule

rule:
plugin=vanillaBlocks
number=42
data:
JSON:{blockState:{blockName:"minecraft:log",properties:{variant:"spruce",axis:"x"}},buildPass:0}
:enddata
:endrule

rule:
plugin=vanillaBlocks
number=43
data:
JSON:{blockState:{blockName:"minecraft:bookshelf",properties:{}},buildPass:0}
:enddata
:endrule

rule:
plugin=vanillaBlocks
number=44
data:
JSON:{blockState:{blockName:"minecraft:bed",properties:{part:"head",facing:"west",occupied:"false"}},buildPass:2}
:enddata
:endrule

rule:
plugin=vanillaBlocks
number=45
data:
JSON:{blockState:{blockName:"minecraft:bed",properties:{part:"foot",facing:"west",occupied:"false"}},buildPass:2}
:enddata
:endrule

rule:
plugin=vanillaBlocks
number=46
data:
JSON:{blockState:{blockName:"minecraft:acacia_stairs",properties:{half:"bottom",shape:"straight",facing:"west"}},buildPass:0}
:enddata
:endrule

rule:
plugin=vanillaSkull
number=47
data:
JSON:{blockState:{blockName:"minecraft:skull",properties:{nodrop:"false",facing:"north"}},buildPass:0,teData:{Rot:0,x:32,y:89,z:-35,id:"Skull",SkullType:0b}}
:enddata
:endrule

rule:
plugin=vanillaSkull
number=48
data:
JSON:{blockState:{blockName:"minecraft:skull",properties:{nodrop:"false",facing:"north"}},buildPass:0,teData:{Rot:0,x:33,y:89,z:-35,id:"Skull",SkullType:0b}}
:enddata
:endrule

rule:
plugin=vanillaBlocks
number=49
data:
JSON:{blockState:{blockName:"minecraft:torch",properties:{facing:"up"}},buildPass:2}
:enddata
:endrule

rule:
plugin=vanillaBlocks
number=50
data:
JSON:{blockState:{blockName:"minecraft:brick_stairs",properties:{half:"top",shape:"straight",facing:"west"}},buildPass:0}
:enddata
:endrule

rule:
plugin=doors
number=51
data:
JSON:{blockState:{blockName:"minecraft:wooden_door",properties:{hinge:"left",half:"lower",powered:"false",facing:"south",open:"false"}},buildPass:2}
:enddata
:endrule

rule:
plugin=vanillaBlocks
number=52
data:
JSON:{blockState:{blockName:"minecraft:oak_stairs",properties:{half:"bottom",shape:"straight",facing:"east"}},buildPass:0}
:enddata
:endrule

rule:
plugin=vanillaBlocks
number=53
data:
JSON:{blockState:{blockName:"minecraft:oak_stairs",properties:{half:"bottom",shape:"straight",facing:"west"}},buildPass:0}
:enddata
:endrule

rule:
plugin=vanillaBlocks
number=54
data:
JSON:{blockState:{blockName:"minecraft:oak_stairs",properties:{half:"top",shape:"straight",facing:"west"}},buildPass:0}
:enddata
:endrule

rule:
plugin=vanillaSkull
number=55
data:
JSON:{blockState:{blockName:"minecraft:skull",properties:{nodrop:"false",facing:"west"}},buildPass:0,teData:{Rot:12,x:38,y:91,z:-39,id:"Skull",SkullType:1b}}
:enddata
:endrule

rule:
plugin=vanillaSkull
number=56
data:
JSON:{blockState:{blockName:"minecraft:skull",properties:{nodrop:"false",facing:"west"}},buildPass:0,teData:{Rot:12,x:38,y:91,z:-37,id:"Skull",SkullType:0b}}
:enddata
:endrule

rule:
plugin=doors
number=57
data:
JSON:{blockState:{blockName:"minecraft:wooden_door",properties:{hinge:"left",half:"upper",powered:"false",facing:"north",open:"false"}},buildPass:2}
:enddata
:endrule

rule:
plugin=vanillaBlocks
number=58
data:
JSON:{blockState:{blockName:"minecraft:log",properties:{variant:"spruce",axis:"z"}},buildPass:0}
:enddata
:endrule

rule:
plugin=vanillaBlocks
number=59
data:
JSON:{blockState:{blockName:"minecraft:oak_stairs",properties:{half:"bottom",shape:"straight",facing:"north"}},buildPass:0}
:enddata
:endrule

rule:
plugin=vanillaBlocks
number=60
data:
JSON:{blockState:{blockName:"minecraft:oak_stairs",properties:{half:"bottom",shape:"straight",facing:"south"}},buildPass:0}
:enddata
:endrule

rule:
plugin=vanillaBlocks
number=61
data:
JSON:{blockState:{blockName:"minecraft:trapdoor",properties:{half:"bottom",facing:"west",open:"false"}},buildPass:2}
:enddata
:endrule

rule:
plugin=vanillaBlocks
number=62
data:
JSON:{blockState:{blockName:"minecraft:oak_stairs",properties:{half:"top",shape:"straight",facing:"east"}},buildPass:0}
:enddata
:endrule

rule:
plugin=inventory
number=63
data:
JSON:{blockState:{blockName:"minecraft:chest",properties:{facing:"south"}},buildPass:0,lootLevel:0,teData:{x:30,y:94,z:-39,id:"Chest"},inventoryData:{length:27,inventoryContents:[{id:"minecraft:redstone_lamp",Count:6b,slot:0,Damage:0s}]}}
:enddata
:endrule

rule:
plugin=inventory
number=64
data:
JSON:{blockState:{blockName:"minecraft:chest",properties:{facing:"south"}},buildPass:0,lootLevel:0,teData:{x:31,y:94,z:-39,id:"Chest"},inventoryData:{length:27,inventoryContents:[]}}
:enddata
:endrule

rule:
plugin=inventory
number=65
data:
JSON:{blockState:{blockName:"minecraft:chest",properties:{facing:"south"}},buildPass:0,lootLevel:0,teData:{x:34,y:94,z:-39,id:"Chest"},inventoryData:{length:27,inventoryContents:[{id:"minecraft:redstone_lamp",Count:6b,slot:0,Damage:0s}]}}
:enddata
:endrule

rule:
plugin=inventory
number=66
data:
JSON:{blockState:{blockName:"minecraft:chest",properties:{facing:"south"}},buildPass:0,lootLevel:0,teData:{x:35,y:94,z:-39,id:"Chest"},inventoryData:{length:27,inventoryContents:[]}}
:enddata
:endrule

rule:
plugin=inventory
number=67
data:
JSON:{blockState:{blockName:"minecraft:chest",properties:{facing:"east"}},buildPass:0,lootLevel:0,teData:{x:27,y:94,z:-38,id:"Chest"},inventoryData:{length:27,inventoryContents:[{id:"minecraft:ender_pearl",Count:4b,slot:0,Damage:0s},{id:"minecraft:fermented_spider_eye",Count:16b,slot:1,Damage:0s}]}}
:enddata
:endrule

rule:
plugin=inventory
number=68
data:
JSON:{blockState:{blockName:"minecraft:chest",properties:{facing:"east"}},buildPass:0,lootLevel:0,teData:{x:27,y:94,z:-36,id:"Chest"},inventoryData:{length:27,inventoryContents:[{id:"minecraft:redstone_lamp",Count:6b,slot:0,Damage:0s}]}}
:enddata
:endrule

rule:
plugin=inventory
number=69
data:
JSON:{blockState:{blockName:"minecraft:chest",properties:{facing:"east"}},buildPass:0,lootLevel:0,teData:{x:27,y:94,z:-35,id:"Chest"},inventoryData:{length:27,inventoryContents:[]}}
:enddata
:endrule

rule:
plugin=inventory
number=70
data:
JSON:{blockState:{blockName:"minecraft:chest",properties:{facing:"east"}},buildPass:0,lootLevel:0,teData:{x:27,y:94,z:-33,id:"Chest"},inventoryData:{length:27,inventoryContents:[{id:"minecraft:ender_pearl",Count:4b,slot:0,Damage:0s},{id:"minecraft:fermented_spider_eye",Count:16b,slot:1,Damage:0s}]}}
:enddata
:endrule

rule:
plugin=vanillaBlocks
number=71
data:
JSON:{blockState:{blockName:"minecraft:web",properties:{}},buildPass:0}
:enddata
:endrule

rule:
plugin=inventory
number=72
data:
JSON:{blockState:{blockName:"minecraft:chest",properties:{facing:"north"}},buildPass:0,lootLevel:0,teData:{x:30,y:94,z:-32,id:"Chest"},inventoryData:{length:27,inventoryContents:[{id:"minecraft:golden_rail",Count:16b,slot:0,Damage:0s},{id:"minecraft:redstone_block",Count:3b,slot:1,Damage:0s}]}}
:enddata
:endrule

rule:
plugin=inventory
number=73
data:
JSON:{blockState:{blockName:"minecraft:chest",properties:{facing:"north"}},buildPass:0,lootLevel:0,teData:{x:31,y:94,z:-32,id:"Chest"},inventoryData:{length:27,inventoryContents:[]}}
:enddata
:endrule

rule:
plugin=inventory
number=74
data:
JSON:{blockState:{blockName:"minecraft:chest",properties:{facing:"north"}},buildPass:0,lootLevel:0,teData:{x:34,y:94,z:-32,id:"Chest"},inventoryData:{length:27,inventoryContents:[{id:"minecraft:dirt",Count:64b,slot:0,Damage:0s},{id:"minecraft:golden_apple",Count:3b,slot:1,Damage:1s}]}}
:enddata
:endrule

rule:
plugin=inventory
number=75
data:
JSON:{blockState:{blockName:"minecraft:chest",properties:{facing:"north"}},buildPass:0,lootLevel:0,teData:{x:35,y:94,z:-32,id:"Chest"},inventoryData:{length:27,inventoryContents:[]}}
:enddata
:endrule

rule:
plugin=vanillaBlocks
number=76
data:
JSON:{blockState:{blockName:"minecraft:oak_stairs",properties:{half:"top",shape:"straight",facing:"south"}},buildPass:0}
:enddata
:endrule

rule:
plugin=vanillaBlocks
number=77
data:
JSON:{blockState:{blockName:"minecraft:wooden_slab",properties:{half:"top",variant:"oak"}},buildPass:0}
:enddata
:endrule

rule:
plugin=vanillaBlocks
number=78
data:
JSON:{blockState:{blockName:"minecraft:brick_stairs",properties:{half:"bottom",shape:"straight",facing:"south"}},buildPass:0}
:enddata
:endrule

rule:
plugin=vanillaBlocks
number=79
data:
JSON:{blockState:{blockName:"minecraft:brick_stairs",properties:{half:"bottom",shape:"straight",facing:"west"}},buildPass:0}
:enddata
:endrule

rule:
plugin=vanillaBlocks
number=80
data:
JSON:{blockState:{blockName:"minecraft:brick_stairs",properties:{half:"bottom",shape:"straight",facing:"north"}},buildPass:0}
:enddata
:endrule

rule:
plugin=vanillaBlocks
number=81
data:
JSON:{blockState:{blockName:"minecraft:redstone_lamp",properties:{}},buildPass:2}
:enddata
:endrule

rule:
plugin=vanillaBlocks
number=82
data:
JSON:{blockState:{blockName:"minecraft:oak_stairs",properties:{half:"top",shape:"straight",facing:"north"}},buildPass:0}
:enddata
:endrule

rule:
plugin=vanillaBlocks
number=83
data:
JSON:{blockState:{blockName:"minecraft:wooden_slab",properties:{half:"bottom",variant:"oak"}},buildPass:0}
:enddata
:endrule

#### ENTITIES ####
