# Ancient Warfare Structure Template File
# Auto-generated structure template file. created on: 8/28/2018 at: 17:29:59
# Lines beginning with # denote comments

header:
version=2.3
name=unique_creeper_church_dulciphi
size=25,16,29
offset=7,1,28
:endheader

#### VALIDATION ####
validation:
type=ground
survival=false
worldGenEnabled=false
unique=false
preserveBlocks=false
selectionWeight=0
clusterValue=0
minDuplicateDistance=0
dimensionWhiteList=false
dimensionList=
biomeWhiteList=false
biomeList=
leveling=0
fill=0
border=0
blockSwap=false
data:
:enddata
:endvalidation

#### LAYERS ####
layer: 0
1,1,1,1,1,1,1,1,1,1,1,1,1,1,1,1,1,1,1,1,1,1,1,1,1
1,2,2,2,2,2,2,2,2,2,2,2,2,1,1,1,1,1,1,1,1,1,1,1,1
1,2,1,1,1,1,1,1,1,1,2,2,2,2,2,2,2,2,2,2,2,2,1,1,1
1,2,1,1,1,1,1,1,1,1,1,2,2,2,2,2,2,1,2,2,2,2,1,1,1
1,2,1,1,1,1,1,2,2,2,1,1,1,1,2,2,2,2,2,2,2,2,1,1,1
1,2,1,1,1,1,2,1,2,2,2,2,1,2,2,2,2,2,2,2,2,2,1,1,1
1,2,2,2,2,1,1,2,2,1,2,2,1,1,2,2,2,2,2,2,2,2,1,1,1
1,2,2,1,2,1,1,1,2,2,2,2,1,2,2,2,2,2,2,2,1,2,1,1,1
1,2,1,1,1,1,1,1,1,2,2,1,2,1,2,2,2,2,2,2,1,2,1,1,1
1,2,2,2,2,1,1,1,1,1,1,1,2,2,1,2,2,2,2,2,1,2,1,1,1
1,2,2,2,2,2,2,2,2,2,2,1,2,2,2,2,2,2,2,2,2,2,1,1,1
1,2,2,2,2,2,2,2,2,2,2,2,2,1,1,1,1,1,1,1,1,1,1,1,1
1,2,2,2,2,2,2,2,2,2,2,2,2,1,1,1,1,1,1,3,1,1,1,1,1
1,2,1,2,2,2,2,2,2,2,2,2,2,1,1,1,1,1,1,3,1,1,1,1,1
1,2,1,2,2,2,2,2,2,2,2,2,2,1,1,2,1,1,1,3,1,1,1,1,1
1,2,2,2,2,2,2,2,2,2,2,2,2,1,1,1,1,1,1,3,1,1,1,1,1
1,2,2,2,2,2,2,2,2,2,2,2,2,1,1,1,1,1,1,3,1,1,1,1,1
1,2,2,1,2,1,2,2,2,2,2,2,2,1,1,1,1,1,1,3,1,1,1,1,1
1,2,2,2,2,2,2,2,2,2,2,2,2,1,1,1,1,1,1,3,1,1,1,1,1
1,2,2,2,2,2,2,2,2,2,2,2,2,1,1,1,1,1,1,3,1,1,1,1,1
1,2,2,2,2,2,2,2,2,2,2,2,2,1,1,1,1,1,1,3,1,1,1,1,1
1,2,2,2,2,2,2,2,2,2,2,2,2,1,1,1,1,1,1,3,1,1,1,1,1
1,2,2,2,2,2,2,2,2,2,1,2,2,1,1,1,1,1,1,3,1,1,1,1,1
1,2,2,2,2,2,2,2,2,2,2,2,2,1,1,1,1,1,1,3,1,1,1,1,1
1,2,1,2,2,2,2,2,1,2,2,2,2,1,1,1,1,1,1,1,1,1,1,1,1
1,2,2,1,2,2,2,2,2,2,2,2,2,1,1,1,1,1,1,1,1,1,1,1,1
1,2,2,2,2,2,2,2,2,2,2,2,2,1,1,1,1,1,1,1,1,1,1,1,1
1,1,1,1,1,1,2,2,1,1,1,1,1,1,1,1,1,1,1,1,1,1,1,1,1
1,1,1,1,1,1,1,1,1,1,1,1,1,1,1,1,1,1,1,1,1,1,1,1,1
:endlayer
layer: 1
4,0,0,0,0,0,0,0,0,0,0,0,0,4,0,0,0,0,0,0,0,0,0,0,5
0,6,7,7,7,7,7,7,7,7,7,7,6,0,0,0,0,0,0,0,0,0,0,0,0
0,7,8,8,8,8,8,8,8,8,8,8,8,7,7,7,7,7,7,7,7,7,0,0,0
0,7,8,8,8,8,8,8,8,8,8,8,8,8,8,8,8,8,8,8,8,7,0,0,0
0,7,8,8,8,8,8,8,8,8,8,8,8,8,9,9,9,9,9,9,8,7,0,0,0
0,7,8,8,8,8,8,8,8,8,8,8,8,8,9,9,9,9,9,9,8,7,0,0,0
0,6,7,7,7,8,8,8,8,8,8,8,8,8,9,9,9,9,9,9,8,7,0,0,0
0,7,8,8,8,8,8,8,8,8,8,8,8,8,9,9,9,9,9,9,8,7,0,0,0
0,7,8,8,8,8,8,8,8,8,8,8,8,8,9,9,9,9,9,9,8,7,0,0,0
0,7,7,7,7,8,8,8,8,8,8,8,7,8,8,8,8,8,8,8,8,7,0,0,0
0,7,10,11,7,8,8,8,8,8,8,8,6,7,7,7,7,7,7,7,7,7,4,4,0
4,6,10,10,8,8,8,8,8,8,8,8,6,0,0,0,0,0,12,13,14,0,0,4,0
0,7,10,8,8,8,8,8,8,8,8,8,7,0,0,0,0,0,0,0,0,0,0,4,0
0,7,8,8,8,8,8,8,8,8,8,8,7,0,0,0,0,0,0,0,0,0,0,4,0
0,7,8,8,8,8,8,8,8,8,8,8,7,0,0,15,0,0,0,0,0,0,0,16,0
0,7,8,9,9,9,9,9,9,9,9,8,7,0,0,0,0,0,0,0,0,0,0,4,0
0,7,8,9,9,9,9,9,9,9,9,8,7,0,0,0,0,0,0,0,0,0,0,4,0
0,7,8,8,8,8,9,9,8,8,8,8,7,0,0,0,0,0,0,0,0,0,0,4,0
0,7,8,8,8,8,9,9,8,8,8,8,7,0,0,0,0,0,0,0,0,0,0,4,0
0,7,8,8,8,8,9,9,8,8,8,8,7,0,0,0,0,0,0,0,0,0,0,4,0
0,7,8,8,8,8,9,9,8,8,8,8,7,0,0,5,0,0,0,0,0,0,0,4,0
0,7,8,8,8,8,9,9,8,8,8,8,7,0,0,0,0,0,0,0,0,0,0,4,0
0,7,8,8,8,8,9,9,8,8,8,8,7,0,0,0,0,0,0,0,0,0,0,4,0
0,7,8,8,8,8,9,9,8,8,8,8,7,0,0,0,0,0,0,0,0,0,0,4,0
0,7,8,8,8,8,9,9,8,8,8,8,7,4,4,4,4,4,4,17,4,4,4,4,0
0,7,8,8,8,8,9,9,8,8,8,8,7,0,0,0,0,0,0,0,0,0,0,0,0
0,6,7,7,7,6,6,6,6,7,7,7,6,0,0,0,0,0,0,0,0,0,0,0,0
5,0,0,0,0,0,13,13,0,0,0,0,0,0,0,0,0,0,0,0,0,0,0,0,5
0,0,4,0,0,0,0,0,0,0,0,4,0,0,0,0,0,0,0,0,0,0,0,0,0
:endlayer
layer: 2
4,0,0,0,0,0,0,0,0,0,0,0,0,4,0,0,0,0,0,0,0,0,0,0,18
0,6,7,19,19,19,19,19,19,19,19,7,6,20,0,0,0,0,0,0,0,0,0,0,0
0,7,5,0,0,0,0,0,0,0,0,21,6,7,7,7,7,7,7,7,7,7,0,0,0
0,22,0,0,0,0,0,0,0,0,0,21,6,0,0,0,0,0,0,0,0,7,0,0,0
0,22,0,0,0,0,0,0,0,0,0,0,0,0,0,23,23,23,23,0,0,7,0,0,0
0,7,0,0,0,0,0,0,0,0,0,0,0,0,0,5,5,5,5,0,0,7,0,0,0
0,6,24,24,24,0,0,0,0,0,0,0,0,0,0,5,5,5,5,0,0,7,0,0,0
0,7,0,0,6,0,0,0,0,0,0,0,0,0,0,5,5,5,5,0,0,7,0,0,0
0,7,0,0,25,0,0,0,0,0,0,0,6,0,0,26,26,26,26,0,0,7,0,0,0
0,7,7,7,7,0,0,0,0,0,0,0,6,0,0,0,0,0,0,0,0,7,0,0,0
0,7,0,0,25,0,0,0,0,0,0,0,6,7,7,7,7,7,7,27,7,7,0,0,0
4,6,28,29,6,0,0,0,0,0,0,0,6,0,0,0,0,0,0,0,0,30,0,0,0
0,7,31,12,6,6,6,6,6,6,0,0,7,0,32,32,32,0,0,0,0,0,0,0,0
0,7,0,6,6,6,6,6,6,6,0,0,7,32,32,32,32,32,0,0,0,0,0,18,0
0,7,33,6,34,34,35,35,34,34,0,0,7,32,32,15,32,32,0,0,0,0,0,0,0
0,7,0,0,0,0,0,0,0,0,0,0,7,32,32,32,32,32,0,0,0,0,0,18,0
0,7,0,0,0,0,0,0,0,0,0,0,7,0,32,32,32,0,0,0,0,0,0,0,0
0,7,0,0,0,0,0,0,0,0,0,0,7,0,0,0,0,0,0,0,0,0,0,0,0
0,22,0,0,0,0,0,0,0,0,0,0,7,0,0,0,0,0,0,0,0,0,0,0,0
0,7,0,36,36,36,0,0,36,36,36,0,7,0,0,0,0,0,0,0,0,0,0,0,0
0,22,0,0,0,0,0,0,0,0,0,0,7,0,0,5,0,0,0,0,0,0,0,0,0
0,7,0,36,36,36,0,0,36,36,36,0,7,0,0,0,0,0,0,0,0,0,0,0,0
0,22,0,0,0,0,0,0,0,0,0,0,7,0,0,0,0,0,0,0,0,0,0,0,0
0,7,0,36,36,36,0,0,36,36,36,0,7,0,0,0,0,0,0,0,0,0,0,0,0
0,22,0,0,0,0,0,0,0,0,0,0,7,18,0,0,0,0,18,0,18,0,0,18,0
0,7,0,0,0,0,0,0,0,0,0,0,7,0,0,0,0,0,0,0,0,0,0,0,0
0,6,7,22,7,6,37,27,6,7,22,7,6,0,0,0,0,0,0,0,0,0,0,0,0
18,0,0,0,30,0,0,0,0,30,0,0,0,0,0,0,0,0,0,0,0,0,0,0,18
0,0,4,0,0,0,0,0,0,0,0,4,0,0,0,0,0,0,0,0,0,0,0,0,0
:endlayer
layer: 3
4,0,0,0,0,0,0,0,0,0,0,0,0,4,0,0,0,0,0,0,0,0,0,0,0
0,6,7,19,19,38,19,19,38,19,19,7,6,0,0,0,0,0,0,0,0,0,0,0,0
0,7,39,0,0,0,0,0,0,0,0,0,6,7,7,7,7,7,7,7,7,7,0,0,0
0,22,0,0,0,0,0,0,0,0,0,0,6,20,0,0,0,0,0,0,0,7,0,0,0
0,22,0,0,0,0,0,0,0,0,0,0,0,0,0,0,0,0,0,0,0,7,0,0,0
0,7,0,0,0,0,0,0,0,0,0,0,0,0,0,39,39,39,39,0,0,7,0,0,0
0,6,0,0,0,0,0,0,0,0,0,0,0,0,0,39,39,39,39,0,0,7,20,0,0
0,7,24,24,24,0,0,0,0,0,0,0,0,0,0,39,39,39,39,0,0,7,0,0,0
0,7,40,0,41,0,0,0,0,0,0,0,6,0,0,0,0,0,0,0,0,7,0,0,0
0,7,7,7,7,0,0,0,0,0,0,0,6,20,0,0,0,0,0,0,0,7,0,0,0
0,7,0,0,42,0,0,0,0,0,0,0,6,7,7,22,22,22,7,43,7,7,0,0,0
4,6,44,45,6,46,0,0,0,0,0,0,6,0,0,0,0,0,0,0,0,0,0,0,0
0,7,47,0,6,48,48,48,48,48,0,0,7,0,0,0,0,0,0,0,0,0,0,0,0
0,7,0,6,0,0,0,0,0,0,0,0,7,0,0,32,0,0,0,0,0,0,0,0,0
0,7,49,6,0,0,5,5,0,0,0,0,7,0,32,15,32,0,0,0,0,0,0,0,0
0,7,0,50,0,0,0,0,0,0,0,0,7,0,0,32,0,0,0,0,0,0,0,0,0
0,7,0,0,0,0,0,0,0,0,0,0,7,0,0,0,0,0,0,0,0,0,0,0,0
0,7,20,0,0,0,0,0,0,0,0,51,7,0,0,0,0,0,0,0,0,0,0,0,0
0,22,0,0,0,0,0,0,0,0,0,0,7,0,0,0,0,0,0,0,0,0,0,0,0
0,7,20,0,0,0,0,0,0,0,0,51,7,0,0,0,0,0,0,0,0,0,0,0,0
0,22,0,0,0,0,0,0,0,0,0,0,7,0,0,52,0,0,0,0,0,0,0,0,0
0,7,20,0,0,0,0,0,0,0,0,51,7,0,0,0,0,0,0,0,0,0,0,0,0
0,22,0,0,0,0,0,0,0,0,0,0,7,0,0,0,0,0,0,0,0,0,0,0,0
0,7,20,0,0,0,0,0,0,0,0,51,7,0,0,0,0,0,0,0,0,0,0,0,0
0,22,0,0,0,0,0,0,0,0,0,0,7,0,0,0,0,0,0,0,0,0,0,0,0
0,7,0,0,0,0,0,0,0,0,0,0,7,0,0,0,0,0,0,0,0,0,0,0,0
0,6,7,22,7,6,53,54,6,7,22,7,6,0,0,0,0,0,0,0,0,0,0,0,0
0,0,0,0,0,0,0,0,0,0,0,0,0,0,0,0,0,0,0,0,0,0,0,0,0
0,0,4,0,0,0,0,0,0,0,0,4,0,0,0,0,0,0,0,0,0,0,0,0,0
:endlayer
layer: 4
4,0,0,0,0,0,0,0,0,0,0,0,0,4,0,0,0,0,0,0,0,0,0,0,0
0,6,7,19,19,55,55,55,55,19,19,7,6,0,0,0,0,0,0,0,0,0,0,0,0
0,7,20,0,0,0,0,0,0,0,0,0,6,7,7,7,7,7,7,7,7,7,0,0,0
0,22,0,0,0,0,0,0,0,0,0,51,6,0,0,0,0,0,0,0,0,7,0,0,0
0,22,0,0,0,0,0,0,0,0,0,0,0,0,0,0,0,0,0,0,0,7,0,0,0
0,7,0,0,0,0,0,0,0,0,0,0,0,0,0,0,0,0,0,0,0,7,0,0,0
0,6,0,0,0,0,0,0,0,0,0,0,0,0,0,0,0,0,0,0,0,7,0,0,0
0,7,0,0,0,0,0,0,0,0,0,0,0,0,0,0,0,0,0,0,0,7,0,0,0
0,7,24,24,24,0,0,0,0,0,0,51,6,0,0,0,0,0,0,0,0,7,0,0,0
0,7,11,11,11,8,8,8,8,8,8,8,6,0,0,0,0,0,0,0,0,7,0,0,0
0,7,8,8,11,8,8,8,8,8,8,8,6,7,7,22,22,22,7,7,7,7,0,0,0
4,6,8,8,11,8,8,8,8,8,8,8,6,0,0,0,0,0,0,0,0,0,0,0,0
0,7,11,11,18,0,0,0,0,0,8,8,7,0,32,32,32,0,0,0,0,0,0,0,0
0,7,8,11,0,0,0,0,0,0,8,8,7,32,32,32,32,32,0,0,0,0,0,0,0
0,7,11,11,0,0,56,56,0,0,8,8,7,32,32,15,32,32,0,0,0,0,0,0,0
0,7,8,8,0,0,0,0,0,0,8,8,7,32,32,32,32,32,0,0,0,0,0,0,0
0,7,8,8,0,0,0,0,0,0,8,8,7,0,32,32,32,0,0,0,0,0,0,0,0
0,7,8,8,0,0,0,0,0,0,8,8,7,0,0,0,0,0,0,0,0,0,0,0,0
0,7,8,8,0,0,0,0,0,0,8,8,7,0,0,0,0,0,0,0,0,0,0,0,0
0,7,8,8,0,0,0,0,0,0,8,8,7,0,0,0,0,0,0,0,0,0,0,0,0
0,7,8,8,0,0,0,0,0,0,8,8,7,0,0,0,0,0,0,0,0,0,0,0,0
0,7,8,8,0,0,0,0,0,0,8,8,7,0,0,0,0,0,0,0,0,0,0,0,0
0,7,8,8,0,0,0,0,0,0,8,8,7,0,0,0,0,0,0,0,0,0,0,0,0
0,7,8,8,8,8,8,8,8,8,8,8,7,0,0,0,0,0,0,0,0,0,0,0,0
0,7,8,8,8,8,8,8,8,8,8,8,7,0,0,0,0,0,0,0,0,0,0,0,0
0,7,8,8,8,8,57,57,8,8,8,8,7,0,0,0,0,0,0,0,0,0,0,0,0
0,6,7,7,7,6,58,59,6,7,7,7,6,0,0,0,0,0,0,0,0,0,0,0,0
0,8,8,8,8,8,8,8,8,8,8,8,8,0,0,0,0,0,0,0,0,0,0,0,0
0,8,11,8,8,8,8,8,8,8,8,11,8,0,0,0,0,0,0,0,0,0,0,0,0
:endlayer
layer: 5
4,0,0,0,0,0,0,0,0,0,0,0,0,4,0,0,0,0,0,0,0,0,0,0,0
0,6,7,19,19,19,55,55,19,19,19,7,6,0,0,0,0,0,0,0,0,0,0,0,0
0,7,0,0,0,0,0,0,0,0,0,0,6,7,7,7,7,7,7,7,7,7,0,0,0
0,22,0,0,0,0,0,0,0,0,0,0,6,0,0,0,0,0,0,0,0,7,0,0,0
0,22,0,0,0,0,0,0,0,0,0,0,0,0,0,0,0,0,0,0,0,7,0,0,0
0,7,0,0,0,0,0,0,0,0,0,0,0,0,0,0,0,0,0,0,0,7,0,0,0
0,6,0,0,0,0,0,0,0,0,0,0,0,0,0,0,0,0,0,60,61,7,0,0,0
0,7,0,0,0,0,0,0,0,0,0,0,0,0,0,0,0,0,0,0,0,7,0,0,0
0,7,0,0,0,0,0,0,0,0,0,0,6,0,0,0,0,0,0,0,0,7,0,0,0
0,7,0,0,0,48,48,48,48,48,48,48,6,0,0,0,0,0,0,0,0,7,0,0,0
0,7,0,0,0,0,0,0,0,0,0,0,6,7,7,7,7,7,7,7,7,7,0,0,0
4,6,0,48,48,48,48,48,48,48,48,0,6,0,0,0,0,0,0,0,0,0,0,0,0
0,7,0,48,0,0,0,0,0,0,48,0,7,0,0,0,0,0,0,0,0,0,0,0,0
0,7,0,48,0,0,0,0,0,0,48,0,7,0,0,32,0,0,0,0,0,0,0,0,0
0,7,0,48,0,0,0,0,0,0,48,0,7,0,32,15,32,0,0,0,0,0,0,0,0
0,7,0,48,0,0,0,0,0,0,48,0,7,0,0,32,0,0,0,0,0,0,0,0,0
0,7,0,48,0,0,0,0,0,0,48,0,7,0,0,0,0,0,0,0,0,0,0,0,0
0,7,0,48,0,0,0,0,0,0,48,0,22,0,0,0,0,0,0,0,0,0,0,0,0
0,7,0,48,0,0,0,0,0,0,48,0,22,0,0,0,0,0,0,0,0,0,0,0,0
0,7,0,48,0,0,0,0,0,0,48,0,22,0,0,0,0,0,0,0,0,0,0,0,0
0,7,0,48,0,0,0,0,0,0,48,0,22,0,0,0,0,0,0,0,0,0,0,0,0
0,22,0,48,0,62,0,0,62,0,48,0,7,0,0,0,0,0,0,0,0,0,0,0,0
0,22,0,48,0,0,0,0,0,0,48,0,7,0,0,0,0,0,0,0,0,0,0,0,0
0,22,0,48,48,48,48,48,48,48,48,0,7,0,0,0,0,0,0,0,0,0,0,0,0
0,7,0,0,0,0,0,0,0,0,0,0,7,0,0,0,0,0,0,0,0,0,0,0,0
0,7,21,0,0,0,0,0,0,0,0,0,7,0,0,0,0,0,0,0,0,0,0,0,0
0,6,7,7,63,63,19,19,63,63,7,64,6,0,0,0,0,0,0,0,0,0,0,0,0
0,65,0,0,0,0,0,0,0,0,0,0,65,0,0,0,0,0,0,0,0,0,0,0,0
0,65,65,65,65,65,65,65,65,65,65,65,65,0,0,0,0,0,0,0,0,0,0,0,0
:endlayer
layer: 6
4,0,0,0,0,0,0,0,0,0,0,0,0,4,0,0,0,0,0,0,0,0,0,0,0
0,6,7,19,19,19,38,38,19,19,19,7,6,6,24,24,24,24,24,24,24,24,0,0,0
59,7,0,0,0,0,0,0,0,0,0,0,6,7,7,7,7,7,7,7,7,7,0,0,0
66,22,0,0,0,0,0,0,0,0,0,0,6,0,0,0,0,0,0,0,0,7,0,0,0
57,22,0,0,0,0,0,0,0,0,0,0,0,0,0,0,0,0,0,0,0,7,0,0,0
59,7,0,0,0,67,0,0,67,0,0,0,0,0,0,0,0,0,0,0,0,7,0,0,0
0,6,0,0,0,60,0,0,60,0,0,0,0,0,0,0,0,0,0,5,0,7,0,0,0
0,7,0,0,0,0,0,0,0,0,0,0,0,0,0,0,0,0,0,0,0,7,0,0,0
0,7,0,0,0,0,0,0,0,0,0,0,6,0,0,0,0,0,0,0,0,7,0,0,0
0,7,0,0,0,0,0,0,0,0,0,0,6,0,0,0,0,0,0,0,0,7,0,0,0
0,7,0,0,0,0,0,0,0,0,0,0,6,7,7,7,7,7,7,7,7,7,0,0,0
4,6,0,0,0,0,0,0,0,0,0,0,6,23,23,23,23,23,23,23,23,13,0,0,0
0,7,0,0,0,0,0,0,0,0,0,0,7,0,0,0,0,0,0,0,0,0,0,0,0
0,7,0,0,0,0,0,0,0,0,0,0,7,0,0,0,0,0,0,0,0,0,0,0,0
0,7,0,0,0,0,0,0,0,0,0,0,7,0,0,15,0,0,0,0,0,0,0,0,0
0,7,0,0,0,0,0,0,0,0,0,0,7,0,0,0,0,0,0,0,0,0,0,0,0
0,7,0,0,0,0,0,0,0,0,0,0,7,0,0,0,0,0,0,0,0,0,0,0,0
0,7,0,0,0,0,0,0,0,0,0,0,22,0,0,0,0,0,0,0,0,0,0,0,0
0,7,0,0,0,0,0,0,0,0,0,0,22,0,0,0,0,0,0,0,0,0,0,0,0
0,7,0,0,0,0,0,0,0,0,0,0,22,0,0,0,0,0,0,0,0,0,0,0,0
0,7,0,0,0,0,0,0,0,0,0,0,22,0,0,0,0,0,0,0,0,0,0,0,0
0,22,0,0,0,60,0,0,60,0,0,0,7,0,0,0,0,0,0,0,0,0,0,0,0
0,22,0,0,0,0,0,0,0,0,0,0,7,0,0,0,0,0,0,0,0,0,0,0,0
0,22,0,0,0,0,0,0,0,0,0,0,7,0,0,0,0,0,0,0,0,0,0,0,0
0,7,0,0,0,0,0,0,0,0,0,0,7,0,0,0,0,0,0,0,0,0,0,0,0
0,7,0,0,0,0,0,0,0,0,68,0,7,0,0,0,0,0,0,0,0,0,0,0,0
0,6,7,7,63,63,19,19,63,63,7,69,6,0,0,0,0,0,0,0,0,0,0,0,0
0,0,0,0,0,0,0,0,0,0,0,0,0,0,0,0,0,0,0,0,0,0,0,0,0
0,0,0,0,0,0,0,0,0,0,0,0,0,0,0,0,0,0,0,0,0,0,0,0,0
:endlayer
layer: 7
12,0,0,0,0,0,0,0,0,0,0,0,0,14,0,0,0,0,0,0,0,0,0,0,0
12,6,7,19,38,55,19,19,55,38,19,7,6,14,0,0,0,0,0,0,0,0,0,0,0
12,7,0,0,0,0,0,0,0,0,0,0,6,70,26,26,26,26,26,26,26,24,0,0,0
12,7,0,0,0,0,0,0,0,0,0,0,6,0,0,0,0,0,0,0,0,6,0,0,0
12,7,0,0,0,0,0,0,0,0,0,0,6,0,0,0,0,0,0,0,0,7,0,0,0
12,7,0,0,0,0,0,0,0,0,0,0,6,0,0,0,0,0,0,0,0,7,0,0,0
12,6,0,0,0,5,0,0,5,0,0,0,6,0,0,0,0,0,0,5,5,7,0,0,0
12,7,0,0,0,0,0,0,0,0,0,0,6,0,0,0,0,0,0,0,0,7,0,0,0
12,7,0,0,0,0,0,0,0,0,0,0,6,0,0,0,0,0,0,0,0,7,0,0,0
12,7,0,0,0,0,0,0,0,0,0,0,6,0,0,0,0,0,0,0,0,6,0,0,0
12,7,0,0,0,0,0,0,0,0,0,0,6,23,23,23,23,23,23,23,23,13,0,0,0
12,6,0,0,0,0,0,0,0,0,0,0,6,0,0,0,0,0,0,0,0,0,0,0,0
0,7,0,0,0,0,0,0,0,0,0,0,7,0,0,0,0,0,0,0,0,0,0,0,0
0,7,0,0,0,0,0,0,0,0,0,0,7,0,0,32,0,0,0,0,0,0,0,0,0
0,7,0,0,0,0,0,0,0,0,0,0,7,0,32,32,32,0,0,0,0,0,0,0,0
0,7,0,0,0,0,0,0,0,0,0,0,7,0,0,32,0,0,0,0,0,0,0,0,0
0,7,0,0,0,0,0,0,0,0,0,0,7,0,0,0,0,0,0,0,0,0,0,0,0
0,7,0,0,0,0,0,0,0,0,0,0,22,0,0,0,0,0,0,0,0,0,0,0,0
0,7,0,0,0,0,0,0,0,0,0,0,22,0,0,0,0,0,0,0,0,0,0,0,0
0,7,0,0,0,0,0,0,0,0,0,0,22,0,0,0,0,0,0,0,0,0,0,0,0
0,7,0,0,0,0,0,0,0,0,0,0,22,0,0,0,0,0,0,0,0,0,0,0,0
0,7,0,0,0,5,0,0,5,0,0,0,7,0,0,0,0,0,0,0,0,0,0,0,0
0,7,0,0,0,0,0,0,0,0,0,0,7,0,0,0,0,0,0,0,0,0,0,0,0
0,7,0,0,0,0,0,0,0,0,0,0,7,0,0,0,0,0,0,0,0,0,0,0,0
0,7,0,0,0,0,0,0,0,0,0,0,7,0,0,0,0,0,0,0,0,0,0,0,0
0,7,0,0,0,0,0,0,0,0,0,0,7,0,0,0,0,0,0,0,0,0,0,0,0
0,6,7,7,63,63,19,19,63,63,7,7,6,0,0,0,0,0,0,0,0,0,0,0,0
0,0,0,0,0,0,0,0,0,0,0,0,0,0,0,0,0,0,0,0,0,0,0,0,0
0,0,0,0,0,0,0,0,0,0,0,0,0,0,0,0,0,0,0,0,0,0,0,0,0
:endlayer
layer: 8
0,12,0,0,0,0,0,0,0,0,0,0,14,0,0,0,0,0,0,0,0,0,0,0,0
0,12,7,19,38,38,19,19,38,38,19,7,14,0,0,0,0,0,0,0,0,0,0,0,0
0,71,0,0,0,0,0,0,0,0,0,0,70,0,0,0,0,0,0,0,0,0,0,0,0
0,71,0,0,0,0,0,0,0,0,0,0,70,26,26,26,26,26,26,26,26,24,0,0,0
0,71,0,0,0,0,0,0,0,0,0,0,6,0,0,0,0,0,0,0,0,6,0,0,0
0,71,0,0,0,0,0,0,0,0,0,0,6,0,0,0,0,0,0,0,0,7,0,0,0
0,71,0,0,0,5,0,0,5,0,0,0,6,0,0,0,0,0,0,0,0,7,0,0,0
0,71,0,0,0,0,0,0,0,0,0,0,6,0,0,0,0,0,0,0,0,7,0,0,0
0,71,0,0,0,0,0,0,0,0,0,0,6,0,0,0,0,0,0,0,0,6,0,0,0
0,71,0,0,0,0,0,0,0,0,0,0,70,23,23,23,23,23,23,23,23,13,0,0,0
0,71,0,0,0,0,0,0,0,0,0,0,70,0,0,0,0,0,0,0,0,0,0,0,0
0,71,0,0,0,0,0,0,0,0,0,0,70,0,0,0,0,0,0,0,0,0,0,0,0
0,71,0,0,0,0,0,0,0,0,0,0,70,0,0,0,0,0,0,0,0,0,0,0,0
0,71,0,0,0,0,0,0,0,0,0,0,70,0,0,0,0,0,0,0,0,0,0,0,0
0,71,0,0,0,0,0,0,0,0,0,0,70,0,0,0,0,0,0,0,0,0,0,0,0
0,71,0,0,0,0,0,0,0,0,0,0,70,0,0,0,0,0,0,0,0,0,0,0,0
0,71,0,0,0,0,0,0,0,0,0,0,70,0,0,0,0,0,0,0,0,0,0,0,0
0,71,0,0,0,0,0,0,0,0,0,0,70,0,0,0,0,0,0,0,0,0,0,0,0
0,71,0,0,0,0,0,0,0,0,0,0,70,0,0,0,0,0,0,0,0,0,0,0,0
0,71,0,0,0,0,0,0,0,0,0,0,70,0,0,0,0,0,0,0,0,0,0,0,0
0,71,0,0,0,0,0,0,0,0,0,0,70,0,0,0,0,0,0,0,0,0,0,0,0
0,71,0,0,0,5,0,0,5,0,0,0,70,0,0,0,0,0,0,0,0,0,0,0,0
0,71,0,0,0,0,0,0,0,0,0,0,70,0,0,0,0,0,0,0,0,0,0,0,0
0,71,0,0,0,0,0,0,0,0,0,0,70,0,0,0,0,0,0,0,0,0,0,0,0
0,71,0,0,0,0,0,0,0,0,0,0,70,0,0,0,0,0,0,0,0,0,0,0,0
0,71,0,0,0,0,0,0,0,0,0,0,70,0,0,0,0,0,0,0,0,0,0,0,0
0,12,6,7,63,19,19,19,19,63,7,6,14,0,0,0,0,0,0,0,0,0,0,0,0
0,12,0,0,0,0,0,0,0,0,0,0,14,0,0,0,0,0,0,0,0,0,0,0,0
0,0,0,0,0,0,0,0,0,0,0,0,0,0,0,0,0,0,0,0,0,0,0,0,0
:endlayer
layer: 9
0,0,12,0,0,0,0,0,0,0,0,14,0,0,0,0,0,0,0,0,0,0,0,0,0
0,0,12,7,19,19,19,19,19,19,7,14,0,0,0,0,0,0,0,0,0,0,0,0,0
0,0,71,0,0,0,0,0,0,0,0,70,0,0,0,0,0,0,0,0,0,0,0,0,0
0,0,71,0,0,0,0,0,0,0,0,70,0,0,0,0,0,0,0,0,0,0,0,0,0
0,0,71,0,0,0,0,0,0,0,0,70,26,26,26,26,26,26,26,26,26,24,0,0,0
0,0,71,0,0,0,0,0,0,0,0,0,6,0,0,0,0,0,0,0,0,6,0,0,0
0,0,71,0,0,5,0,0,5,0,0,0,6,0,0,0,0,0,0,0,0,7,0,0,0
0,0,71,0,0,0,0,0,0,0,0,0,6,0,0,0,0,0,0,0,0,6,0,0,0
0,0,71,0,0,0,0,0,0,0,0,23,23,23,23,23,23,23,23,23,23,13,0,0,0
0,0,71,0,0,0,0,0,0,0,0,70,0,0,0,0,0,0,0,0,0,0,0,0,0
0,0,71,0,0,0,0,0,0,0,0,70,0,0,0,0,0,0,0,0,0,0,0,0,0
0,0,71,0,0,0,0,0,0,0,0,70,0,0,0,0,0,0,0,0,0,0,0,0,0
0,0,71,0,0,0,0,0,0,0,0,70,0,0,0,0,0,0,0,0,0,0,0,0,0
0,0,71,0,0,0,0,0,0,0,0,70,0,0,0,0,0,0,0,0,0,0,0,0,0
0,0,71,0,0,0,0,0,0,0,0,70,0,0,0,0,0,0,0,0,0,0,0,0,0
0,0,71,0,0,0,0,0,0,0,0,70,0,0,0,0,0,0,0,0,0,0,0,0,0
0,0,71,0,0,0,0,0,0,0,0,70,0,0,0,0,0,0,0,0,0,0,0,0,0
0,0,71,0,72,60,0,0,60,61,0,70,0,0,0,0,0,0,0,0,0,0,0,0,0
0,0,71,0,0,0,0,0,0,0,0,70,0,0,0,0,0,0,0,0,0,0,0,0,0
0,0,71,0,0,0,0,0,0,0,0,70,0,0,0,0,0,0,0,0,0,0,0,0,0
0,0,71,0,0,0,0,0,0,0,0,70,0,0,0,0,0,0,0,0,0,0,0,0,0
0,0,71,0,0,5,0,0,5,0,0,70,0,0,0,0,0,0,0,0,0,0,0,0,0
0,0,71,0,0,0,0,0,0,0,0,70,0,0,0,0,0,0,0,0,0,0,0,0,0
0,0,71,0,0,0,0,0,0,0,0,70,0,0,0,0,0,0,0,0,0,0,0,0,0
0,0,71,0,0,0,0,0,0,0,0,70,0,0,0,0,0,0,0,0,0,0,0,0,0
0,0,71,0,0,0,0,0,0,0,0,70,0,0,0,0,0,0,0,0,0,0,0,0,0
0,0,12,7,63,63,19,19,63,63,7,14,0,0,0,0,0,0,0,0,0,0,0,0,0
0,0,12,0,0,0,0,0,0,0,0,14,0,0,0,0,0,0,0,0,0,0,0,0,0
0,0,0,0,0,0,0,0,0,0,0,0,0,0,0,0,0,0,0,0,0,0,0,0,0
:endlayer
layer: 10
0,0,0,12,0,0,0,0,0,0,14,0,0,0,0,0,0,0,0,0,0,0,0,0,0
0,0,0,12,7,19,19,19,19,7,14,0,0,0,0,0,0,0,0,0,0,0,0,0,0
0,0,0,71,0,0,0,0,0,0,70,0,0,0,0,0,0,0,0,0,0,0,0,0,0
0,0,0,71,0,0,0,0,0,0,70,0,0,0,0,0,0,0,0,0,0,0,0,0,0
0,0,0,71,0,0,0,0,0,0,70,0,0,0,0,0,0,0,0,0,0,0,0,0,0
0,0,0,71,0,0,0,0,0,0,26,26,26,26,26,26,26,26,26,26,26,24,0,0,0
0,0,0,71,0,5,0,0,5,0,6,6,6,6,6,6,6,6,6,6,6,6,0,0,0
0,0,0,71,0,0,0,0,0,0,70,23,23,23,23,23,23,23,23,23,23,13,0,0,0
0,0,0,71,0,0,0,0,0,0,70,0,0,0,0,0,0,0,0,0,0,0,0,0,0
0,0,0,71,0,0,0,0,0,0,70,0,0,0,0,0,0,0,0,0,0,0,0,0,0
0,0,0,71,0,0,0,0,0,0,70,0,0,0,0,0,0,0,0,0,0,0,0,0,0
0,0,0,71,0,0,0,0,0,0,70,0,0,0,0,0,0,0,0,0,0,0,0,0,0
0,0,0,71,0,0,0,0,0,0,70,0,0,0,0,0,0,0,0,0,0,0,0,0,0
0,0,0,71,0,0,0,0,0,0,70,0,0,0,0,0,0,0,0,0,0,0,0,0,0
0,0,0,71,0,0,0,0,0,0,70,0,0,0,0,0,0,0,0,0,0,0,0,0,0
0,0,0,71,0,0,0,0,0,0,70,0,0,0,0,0,0,0,0,0,0,0,0,0,0
0,0,0,71,0,0,0,0,0,0,70,0,0,0,0,0,0,0,0,0,0,0,0,0,0
0,0,0,71,0,5,0,0,5,0,70,0,0,0,0,0,0,0,0,0,0,0,0,0,0
0,0,0,71,0,0,0,0,0,0,70,0,0,0,0,0,0,0,0,0,0,0,0,0,0
0,0,0,71,0,0,0,0,0,0,70,0,0,0,0,0,0,0,0,0,0,0,0,0,0
0,0,0,71,0,0,0,0,0,0,70,0,0,0,0,0,0,0,0,0,0,0,0,0,0
0,0,0,71,0,5,0,0,5,0,70,0,0,0,0,0,0,0,0,0,0,0,0,0,0
0,0,0,71,0,0,0,0,0,0,70,0,0,0,0,0,0,0,0,0,0,0,0,0,0
0,0,0,71,0,0,0,0,0,0,70,0,0,0,0,0,0,0,0,0,0,0,0,0,0
0,0,0,71,0,0,0,0,0,0,70,0,0,0,0,0,0,0,0,0,0,0,0,0,0
0,0,0,71,0,0,0,0,0,0,70,0,0,0,0,0,0,0,0,0,0,0,0,0,0
0,0,0,12,7,63,19,19,63,7,14,0,0,0,0,0,0,0,0,0,0,0,0,0,0
0,0,0,12,0,0,0,0,0,0,14,0,0,0,0,0,0,0,0,0,0,0,0,0,0
0,0,0,0,0,0,0,0,0,0,0,0,0,0,0,0,0,0,0,0,0,0,0,0,0
:endlayer
layer: 11
0,0,0,0,12,0,0,0,0,14,0,0,0,0,0,0,0,0,0,0,0,0,0,0,0
0,0,0,0,12,7,7,7,7,14,0,0,0,0,0,0,0,0,0,0,0,0,0,0,0
0,0,0,0,71,0,0,0,0,70,0,0,0,0,0,0,0,0,0,0,0,0,0,0,0
0,0,0,0,71,0,0,0,0,70,0,0,0,0,0,0,0,0,0,0,0,0,0,0,0
0,0,0,0,71,0,0,0,0,70,0,0,0,0,0,0,0,0,0,0,0,0,0,0,0
0,0,0,0,71,0,0,0,0,70,0,0,0,0,0,0,0,0,0,0,0,0,0,0,0
0,0,0,0,71,5,0,0,5,70,73,73,73,73,73,73,73,73,73,73,73,6,0,0,0
0,0,0,0,71,0,0,0,0,70,0,0,0,0,0,0,0,0,0,0,0,0,0,0,0
0,0,0,0,71,0,0,0,0,70,0,0,0,0,0,0,0,0,0,0,0,0,0,0,0
0,0,0,0,71,0,0,0,0,70,0,0,0,0,0,0,0,0,0,0,0,0,0,0,0
0,0,0,0,71,0,0,0,0,70,0,0,0,0,0,0,0,0,0,0,0,0,0,0,0
0,0,0,0,71,0,0,0,0,70,0,0,0,0,0,0,0,0,0,0,0,0,0,0,0
0,0,0,0,71,0,0,0,0,70,0,0,0,0,0,0,0,0,0,0,0,0,0,0,0
0,0,0,0,71,0,0,0,0,70,0,0,0,0,0,0,0,0,0,0,0,0,0,0,0
0,0,0,0,71,0,0,0,0,70,0,0,0,0,0,0,0,0,0,0,0,0,0,0,0
0,0,0,0,71,0,0,0,0,70,0,0,0,0,0,0,0,0,0,0,0,0,0,0,0
0,0,0,0,71,0,0,0,0,70,0,0,0,0,0,0,0,0,0,0,0,0,0,0,0
0,0,0,0,71,5,0,0,5,70,0,0,0,0,0,0,0,0,0,0,0,0,0,0,0
0,0,0,0,71,0,0,0,0,70,0,0,0,0,0,0,0,0,0,0,0,0,0,0,0
0,0,0,0,71,0,0,0,0,70,0,0,0,0,0,0,0,0,0,0,0,0,0,0,0
0,0,0,0,71,0,0,0,0,70,0,0,0,0,0,0,0,0,0,0,0,0,0,0,0
0,0,0,0,71,5,0,0,5,70,0,0,0,0,0,0,0,0,0,0,0,0,0,0,0
0,0,0,0,71,0,0,0,0,70,0,0,0,0,0,0,0,0,0,0,0,0,0,0,0
0,0,0,0,71,0,0,0,0,70,0,0,0,0,0,0,0,0,0,0,0,0,0,0,0
0,0,0,0,71,0,0,0,0,70,0,0,0,0,0,0,0,0,0,0,0,0,0,0,0
0,0,0,0,71,0,0,0,0,70,0,0,0,0,0,0,0,0,0,0,0,0,0,0,0
0,0,0,0,12,7,63,63,7,14,0,0,0,0,0,0,0,0,0,0,0,0,0,0,0
0,0,0,0,12,0,0,0,0,14,0,0,0,0,0,0,0,0,0,0,0,0,0,0,0
0,0,0,0,0,0,0,0,0,0,0,0,0,0,0,0,0,0,0,0,0,0,0,0,0
:endlayer
layer: 12
0,0,0,0,0,12,0,0,14,0,0,0,0,0,0,0,0,0,0,0,0,0,0,0,0
0,0,0,0,0,12,7,7,14,0,0,0,0,0,0,0,0,0,0,0,0,0,0,0,0
0,0,0,0,0,71,58,59,70,0,0,0,0,0,0,0,0,0,0,0,0,0,0,0,0
0,0,0,0,0,71,58,59,70,0,0,0,0,0,0,0,0,0,0,0,0,0,0,0,0
0,0,0,0,0,71,58,59,70,0,0,0,0,0,0,0,0,0,0,0,0,0,0,0,0
0,0,0,0,0,71,58,59,70,0,0,0,0,0,0,0,0,0,0,0,0,0,0,0,0
0,0,0,0,0,71,58,59,70,0,0,0,0,0,0,0,0,0,0,0,0,0,0,0,0
0,0,0,0,0,71,58,59,70,0,0,0,0,0,0,0,0,0,0,0,0,0,0,0,0
0,0,0,0,0,71,58,59,70,0,0,0,0,0,0,0,0,0,0,0,0,0,0,0,0
0,0,0,0,0,71,58,59,70,0,0,0,0,0,0,0,0,0,0,0,0,0,0,0,0
0,0,0,0,0,71,58,59,70,0,0,0,0,0,0,0,0,0,0,0,0,0,0,0,0
0,0,0,0,0,71,58,59,70,0,0,0,0,0,0,0,0,0,0,0,0,0,0,0,0
0,0,0,0,0,71,58,59,70,0,0,0,0,0,0,0,0,0,0,0,0,0,0,0,0
0,0,0,0,0,71,58,59,70,0,0,0,0,0,0,0,0,0,0,0,0,0,0,0,0
0,0,0,0,0,71,58,59,70,0,0,0,0,0,0,0,0,0,0,0,0,0,0,0,0
0,0,0,0,0,71,58,59,70,0,0,0,0,0,0,0,0,0,0,0,0,0,0,0,0
0,0,0,0,0,71,58,59,70,0,0,0,0,0,0,0,0,0,0,0,0,0,0,0,0
0,0,0,0,0,71,58,59,70,0,0,0,0,0,0,0,0,0,0,0,0,0,0,0,0
0,0,0,0,0,71,58,59,70,0,0,0,0,0,0,0,0,0,0,0,0,0,0,0,0
0,0,0,0,0,71,58,59,70,0,0,0,0,0,0,0,0,0,0,0,0,0,0,0,0
0,0,0,0,0,71,58,59,70,0,0,0,0,0,0,0,0,0,0,0,0,0,0,0,0
0,0,0,0,0,71,58,59,70,0,0,0,0,0,0,0,0,0,0,0,0,0,0,0,0
0,0,0,0,0,71,58,59,70,0,0,0,0,0,0,0,0,0,0,0,0,0,0,0,0
0,0,0,0,0,71,58,59,70,0,0,0,0,0,0,0,0,0,0,0,0,0,0,0,0
0,0,0,0,0,71,58,59,70,0,0,0,0,0,0,0,0,0,0,0,0,0,0,0,0
0,0,0,0,0,71,58,59,70,0,0,0,0,0,0,0,0,0,0,0,0,0,0,0,0
0,0,0,0,0,12,6,6,14,0,0,0,0,0,0,0,0,0,0,0,0,0,0,0,0
0,0,0,0,0,12,0,0,14,0,0,0,0,0,0,0,0,0,0,0,0,0,0,0,0
0,0,0,0,0,0,0,0,0,0,0,0,0,0,0,0,0,0,0,0,0,0,0,0,0
:endlayer
layer: 13
0,0,0,0,0,0,12,14,0,0,0,0,0,0,0,0,0,0,0,0,0,0,0,0,0
0,0,0,0,0,0,12,14,0,0,0,0,0,0,0,0,0,0,0,0,0,0,0,0,0
0,0,0,0,0,0,12,14,0,0,0,0,0,0,0,0,0,0,0,0,0,0,0,0,0
0,0,0,0,0,0,12,14,0,0,0,0,0,0,0,0,0,0,0,0,0,0,0,0,0
0,0,0,0,0,0,12,14,0,0,0,0,0,0,0,0,0,0,0,0,0,0,0,0,0
0,0,0,0,0,0,12,14,0,0,0,0,0,0,0,0,0,0,0,0,0,0,0,0,0
0,0,0,0,0,0,12,14,0,0,0,0,0,0,0,0,0,0,0,0,0,0,0,0,0
0,0,0,0,0,0,12,14,0,0,0,0,0,0,0,0,0,0,0,0,0,0,0,0,0
0,0,0,0,0,0,12,14,0,0,0,0,0,0,0,0,0,0,0,0,0,0,0,0,0
0,0,0,0,0,0,12,14,0,0,0,0,0,0,0,0,0,0,0,0,0,0,0,0,0
0,0,0,0,0,0,12,14,0,0,0,0,0,0,0,0,0,0,0,0,0,0,0,0,0
0,0,0,0,0,0,12,14,0,0,0,0,0,0,0,0,0,0,0,0,0,0,0,0,0
0,0,0,0,0,0,12,14,0,0,0,0,0,0,0,0,0,0,0,0,0,0,0,0,0
0,0,0,0,0,0,12,14,0,0,0,0,0,0,0,0,0,0,0,0,0,0,0,0,0
0,0,0,0,0,0,12,14,0,0,0,0,0,0,0,0,0,0,0,0,0,0,0,0,0
0,0,0,0,0,0,12,14,0,0,0,0,0,0,0,0,0,0,0,0,0,0,0,0,0
0,0,0,0,0,0,12,14,0,0,0,0,0,0,0,0,0,0,0,0,0,0,0,0,0
0,0,0,0,0,0,12,14,0,0,0,0,0,0,0,0,0,0,0,0,0,0,0,0,0
0,0,0,0,0,0,12,14,0,0,0,0,0,0,0,0,0,0,0,0,0,0,0,0,0
0,0,0,0,0,0,12,14,0,0,0,0,0,0,0,0,0,0,0,0,0,0,0,0,0
0,0,0,0,0,0,12,14,0,0,0,0,0,0,0,0,0,0,0,0,0,0,0,0,0
0,0,0,0,0,0,12,14,0,0,0,0,0,0,0,0,0,0,0,0,0,0,0,0,0
0,0,0,0,0,0,12,14,0,0,0,0,0,0,0,0,0,0,0,0,0,0,0,0,0
0,0,0,0,0,0,12,14,0,0,0,0,0,0,0,0,0,0,0,0,0,0,0,0,0
0,0,0,0,0,0,12,14,0,0,0,0,0,0,0,0,0,0,0,0,0,0,0,0,0
0,0,0,0,0,0,12,14,0,0,0,0,0,0,0,0,0,0,0,0,0,0,0,0,0
0,0,0,0,0,0,12,14,0,0,0,0,0,0,0,0,0,0,0,0,0,0,0,0,0
0,0,0,0,0,0,13,13,0,0,0,0,0,0,0,0,0,0,0,0,0,0,0,0,0
0,0,0,0,0,0,0,0,0,0,0,0,0,0,0,0,0,0,0,0,0,0,0,0,0
:endlayer
layer: 14
0,0,0,0,0,0,0,0,0,0,0,0,0,0,0,0,0,0,0,0,0,0,0,0,0
0,0,0,0,0,0,0,0,0,0,0,0,0,0,0,0,0,0,0,0,0,0,0,0,0
0,0,0,0,0,0,0,0,0,0,0,0,0,0,0,0,0,0,0,0,0,0,0,0,0
0,0,0,0,0,0,0,0,0,0,0,0,0,0,0,0,0,0,0,0,0,0,0,0,0
0,0,0,0,0,0,0,0,0,0,0,0,0,0,0,0,0,0,0,0,0,0,0,0,0
0,0,0,0,0,0,0,0,0,0,0,0,0,0,0,0,0,0,0,0,0,0,0,0,0
0,0,0,0,0,0,0,0,0,0,0,0,0,0,0,0,0,0,0,0,0,0,0,0,0
0,0,0,0,0,0,0,0,0,0,0,0,0,0,0,0,0,0,0,0,0,0,0,0,0
0,0,0,0,0,0,0,0,0,0,0,0,0,0,0,0,0,0,0,0,0,0,0,0,0
0,0,0,0,0,0,0,0,0,0,0,0,0,0,0,0,0,0,0,0,0,0,0,0,0
0,0,0,0,0,0,0,0,0,0,0,0,0,0,0,0,0,0,0,0,0,0,0,0,0
0,0,0,0,0,0,0,0,0,0,0,0,0,0,0,0,0,0,0,0,0,0,0,0,0
0,0,0,0,0,0,0,0,0,0,0,0,0,0,0,0,0,0,0,0,0,0,0,0,0
0,0,0,0,0,0,0,0,0,0,0,0,0,0,0,0,0,0,0,0,0,0,0,0,0
0,0,0,0,0,0,0,0,0,0,0,0,0,0,0,0,0,0,0,0,0,0,0,0,0
0,0,0,0,0,0,0,0,0,0,0,0,0,0,0,0,0,0,0,0,0,0,0,0,0
0,0,0,0,0,0,0,0,0,0,0,0,0,0,0,0,0,0,0,0,0,0,0,0,0
0,0,0,0,0,0,0,0,0,0,0,0,0,0,0,0,0,0,0,0,0,0,0,0,0
0,0,0,0,0,0,0,0,0,0,0,0,0,0,0,0,0,0,0,0,0,0,0,0,0
0,0,0,0,0,0,0,0,0,0,0,0,0,0,0,0,0,0,0,0,0,0,0,0,0
0,0,0,0,0,0,0,0,0,0,0,0,0,0,0,0,0,0,0,0,0,0,0,0,0
0,0,0,0,0,0,0,0,0,0,0,0,0,0,0,0,0,0,0,0,0,0,0,0,0
0,0,0,0,0,0,0,0,0,0,0,0,0,0,0,0,0,0,0,0,0,0,0,0,0
0,0,0,0,0,0,0,0,0,0,0,0,0,0,0,0,0,0,0,0,0,0,0,0,0
0,0,0,0,0,0,0,0,0,0,0,0,0,0,0,0,0,0,0,0,0,0,0,0,0
0,0,0,0,0,0,0,0,0,0,0,0,0,0,0,0,0,0,0,0,0,0,0,0,0
0,0,0,0,0,0,0,0,0,0,0,0,0,0,0,0,0,0,0,0,0,0,0,0,0
0,0,0,0,0,0,0,0,0,0,0,0,0,0,0,0,0,0,0,0,0,0,0,0,0
0,0,0,0,0,0,0,0,0,0,0,0,0,0,0,0,0,0,0,0,0,0,0,0,0
:endlayer
layer: 15
0,0,0,0,0,0,0,0,0,0,0,0,0,0,0,0,0,0,0,0,0,0,0,0,0
0,0,0,0,0,0,0,0,0,0,0,0,0,0,0,0,0,0,0,0,0,0,0,0,0
0,0,0,0,0,0,0,0,0,0,0,0,0,0,0,0,0,0,0,0,0,0,0,0,0
0,0,0,0,0,0,0,0,0,0,0,0,0,0,0,0,0,0,0,0,0,0,0,0,0
0,0,0,0,0,0,0,0,0,0,0,0,0,0,0,0,0,0,0,0,0,0,0,0,0
0,0,0,0,0,0,0,0,0,0,0,0,0,0,0,0,0,0,0,0,0,0,0,0,0
0,0,0,0,0,0,0,0,0,0,0,0,0,0,0,0,0,0,0,0,0,0,0,0,0
0,0,0,0,0,0,0,0,0,0,0,0,0,0,0,0,0,0,0,0,0,0,0,0,0
0,0,0,0,0,0,0,0,0,0,0,0,0,0,0,0,0,0,0,0,0,0,0,0,0
0,0,0,0,0,0,0,0,0,0,0,0,0,0,0,0,0,0,0,0,0,0,0,0,0
0,0,0,0,0,0,0,0,0,0,0,0,0,0,0,0,0,0,0,0,0,0,0,0,0
0,0,0,0,0,0,0,0,0,0,0,0,0,0,0,0,0,0,0,0,0,0,0,0,0
0,0,0,0,0,0,0,0,0,0,0,0,0,0,0,0,0,0,0,0,0,0,0,0,0
0,0,0,0,0,0,0,0,0,0,0,0,0,0,0,0,0,0,0,0,0,0,0,0,0
0,0,0,0,0,0,0,0,0,0,0,0,0,0,0,0,0,0,0,0,0,0,0,0,0
0,0,0,0,0,0,0,0,0,0,0,0,0,0,0,0,0,0,0,0,0,0,0,0,0
0,0,0,0,0,0,0,0,0,0,0,0,0,0,0,0,0,0,0,0,0,0,0,0,0
0,0,0,0,0,0,0,0,0,0,0,0,0,0,0,0,0,0,0,0,0,0,0,0,0
0,0,0,0,0,0,0,0,0,0,0,0,0,0,0,0,0,0,0,0,0,0,0,0,0
0,0,0,0,0,0,0,0,0,0,0,0,0,0,0,0,0,0,0,0,0,0,0,0,0
0,0,0,0,0,0,0,0,0,0,0,0,0,0,0,0,0,0,0,0,0,0,0,0,0
0,0,0,0,0,0,0,0,0,0,0,0,0,0,0,0,0,0,0,0,0,0,0,0,0
0,0,0,0,0,0,0,0,0,0,0,0,0,0,0,0,0,0,0,0,0,0,0,0,0
0,0,0,0,0,0,0,0,0,0,0,0,0,0,0,0,0,0,0,0,0,0,0,0,0
0,0,0,0,0,0,0,0,0,0,0,0,0,0,0,0,0,0,0,0,0,0,0,0,0
0,0,0,0,0,0,0,0,0,0,0,0,0,0,0,0,0,0,0,0,0,0,0,0,0
0,0,0,0,0,0,0,0,0,0,0,0,0,0,0,0,0,0,0,0,0,0,0,0,0
0,0,0,0,0,0,0,0,0,0,0,0,0,0,0,0,0,0,0,0,0,0,0,0,0
0,0,0,0,0,0,0,0,0,0,0,0,0,0,0,0,0,0,0,0,0,0,0,0,0
:endlayer

#### RULES ####
rule:
plugin=vanillaBlocks
number=1
data:
JSON:{buildPass:0,blockName:"minecraft:grass",meta:0}
:enddata
:endrule

rule:
plugin=vanillaBlocks
number=2
data:
JSON:{buildPass:0,blockName:"minecraft:dirt",meta:0}
:enddata
:endrule

rule:
plugin=vanillaBlocks
number=3
data:
JSON:{buildPass:0,blockName:"minecraft:gravel",meta:0}
:enddata
:endrule

rule:
plugin=vanillaBlocks
number=4
data:
JSON:{buildPass:0,blockName:"minecraft:cobblestone_wall",meta:0}
:enddata
:endrule

rule:
plugin=vanillaBlocks
number=5
data:
JSON:{buildPass:0,blockName:"minecraft:fence",meta:0}
:enddata
:endrule

rule:
plugin=vanillaBlocks
number=6
data:
JSON:{buildPass:0,blockName:"minecraft:stonebrick",meta:0}
:enddata
:endrule

rule:
plugin=vanillaBlocks
number=7
data:
JSON:{buildPass:0,blockName:"minecraft:stonebrick",meta:2}
:enddata
:endrule

rule:
plugin=vanillaBlocks
number=8
data:
JSON:{buildPass:0,blockName:"minecraft:stone_slab",meta:8}
:enddata
:endrule

rule:
plugin=vanillaBlocks
number=9
data:
JSON:{buildPass:0,blockName:"minecraft:wool",meta:13}
:enddata
:endrule

rule:
plugin=vanillaBlocks
number=10
data:
JSON:{buildPass:0,blockName:"minecraft:soul_sand",meta:0}
:enddata
:endrule

rule:
plugin=vanillaBlocks
number=11
data:
JSON:{buildPass:0,blockName:"minecraft:double_stone_slab",meta:0}
:enddata
:endrule

rule:
plugin=vanillaBlocks
number=12
data:
JSON:{buildPass:0,blockName:"minecraft:stone_brick_stairs",meta:0}
:enddata
:endrule

rule:
plugin=vanillaBlocks
number=13
data:
JSON:{buildPass:0,blockName:"minecraft:stone_brick_stairs",meta:3}
:enddata
:endrule

rule:
plugin=vanillaBlocks
number=14
data:
JSON:{buildPass:0,blockName:"minecraft:stone_brick_stairs",meta:1}
:enddata
:endrule

rule:
plugin=vanillaBlocks
number=15
data:
JSON:{buildPass:0,blockName:"minecraft:log",meta:1}
:enddata
:endrule

rule:
plugin=vanillaBlocks
number=16
data:
JSON:{buildPass:0,blockName:"minecraft:fence_gate",meta:3}
:enddata
:endrule

rule:
plugin=vanillaBlocks
number=17
data:
JSON:{buildPass:0,blockName:"minecraft:fence_gate",meta:0}
:enddata
:endrule

rule:
plugin=vanillaBlocks
number=18
data:
JSON:{buildPass:2,blockName:"minecraft:torch",meta:5}
:enddata
:endrule

rule:
plugin=vanillaBlocks
number=19
data:
JSON:{buildPass:0,blockName:"minecraft:stained_glass_pane",meta:13}
:enddata
:endrule

rule:
plugin=vanillaBlocks
number=20
data:
JSON:{buildPass:2,blockName:"minecraft:torch",meta:1}
:enddata
:endrule

rule:
plugin=vanillaBlocks
number=21
data:
JSON:{buildPass:0,blockName:"minecraft:bookshelf",meta:0}
:enddata
:endrule

rule:
plugin=vanillaBlocks
number=22
data:
JSON:{buildPass:0,blockName:"minecraft:glass_pane",meta:0}
:enddata
:endrule

rule:
plugin=vanillaBlocks
number=23
data:
JSON:{buildPass:0,blockName:"minecraft:birch_stairs",meta:3}
:enddata
:endrule

rule:
plugin=vanillaBlocks
number=24
data:
JSON:{buildPass:0,blockName:"minecraft:stone_brick_stairs",meta:2}
:enddata
:endrule

rule:
plugin=vanillaDoors
number=25
data:
JSON:{buildPass:2,blockName:"minecraft:wooden_door",meta:2,sideFlag:8b}
:enddata
:endrule

rule:
plugin=vanillaBlocks
number=26
data:
JSON:{buildPass:0,blockName:"minecraft:birch_stairs",meta:2}
:enddata
:endrule

rule:
plugin=vanillaDoors
number=27
data:
JSON:{buildPass:2,blockName:"minecraft:wooden_door",meta:1,sideFlag:8b}
:enddata
:endrule

rule:
plugin=vanillaDoors
number=28
data:
JSON:{buildPass:2,blockName:"minecraft:iron_door",meta:3,sideFlag:8b}
:enddata
:endrule

rule:
plugin=vanillaDoors
number=29
data:
JSON:{buildPass:2,blockName:"minecraft:iron_door",meta:3,sideFlag:9b}
:enddata
:endrule

rule:
plugin=vanillaBlocks
number=30
data:
JSON:{buildPass:2,blockName:"minecraft:torch",meta:3}
:enddata
:endrule

rule:
plugin=vanillaSign
number=31
data:
JSON:{signContents0:"",signContents2:"did it§r",buildPass:2,signContents1:"I know you§r",blockName:"minecraft:wall_sign",signContents3:"",meta:5}
:enddata
:endrule

rule:
plugin=vanillaBlocks
number=32
data:
JSON:{buildPass:0,blockName:"minecraft:leaves",meta:1}
:enddata
:endrule

rule:
plugin=vanillaDoors
number=33
data:
JSON:{buildPass:2,blockName:"minecraft:wooden_door",meta:3,sideFlag:8b}
:enddata
:endrule

rule:
plugin=vanillaBlocks
number=34
data:
JSON:{buildPass:0,blockName:"minecraft:quartz_stairs",meta:3}
:enddata
:endrule

rule:
plugin=vanillaBlocks
number=35
data:
JSON:{buildPass:0,blockName:"minecraft:nether_brick_stairs",meta:3}
:enddata
:endrule

rule:
plugin=vanillaBlocks
number=36
data:
JSON:{buildPass:0,blockName:"minecraft:nether_brick_stairs",meta:2}
:enddata
:endrule

rule:
plugin=vanillaDoors
number=37
data:
JSON:{buildPass:2,blockName:"minecraft:wooden_door",meta:1,sideFlag:9b}
:enddata
:endrule

rule:
plugin=vanillaBlocks
number=38
data:
JSON:{buildPass:0,blockName:"minecraft:stained_glass_pane",meta:7}
:enddata
:endrule

rule:
plugin=vanillaBlocks
number=39
data:
JSON:{buildPass:2,blockName:"minecraft:carpet",meta:7}
:enddata
:endrule

rule:
plugin=vanillaSign
number=40
data:
JSON:{signContents0:"",signContents2:"corner§r",buildPass:2,signContents1:"Time Out§r",blockName:"minecraft:wall_sign",signContents3:"",meta:5}
:enddata
:endrule

rule:
plugin=vanillaDoors
number=41
data:
JSON:{buildPass:2,blockName:"minecraft:wooden_door",meta:8,sideFlag:0b}
:enddata
:endrule

rule:
plugin=vanillaDoors
number=42
data:
JSON:{buildPass:2,blockName:"minecraft:wooden_door",meta:8,sideFlag:0b}
:enddata
:endrule

rule:
plugin=vanillaDoors
number=43
data:
JSON:{buildPass:2,blockName:"minecraft:wooden_door",meta:8,sideFlag:0b}
:enddata
:endrule

rule:
plugin=vanillaDoors
number=44
data:
JSON:{buildPass:2,blockName:"minecraft:iron_door",meta:8,sideFlag:0b}
:enddata
:endrule

rule:
plugin=vanillaDoors
number=45
data:
JSON:{buildPass:2,blockName:"minecraft:iron_door",meta:9,sideFlag:0b}
:enddata
:endrule

rule:
plugin=vanillaSign
number=46
data:
JSON:{signContents0:"Forgive me§r",signContents2:"am about to sin§r",buildPass:2,signContents1:"Father for I§r",blockName:"minecraft:wall_sign",signContents3:"..kthnx§r",meta:5}
:enddata
:endrule

rule:
plugin=vanillaSign
number=47
data:
JSON:{signContents0:"",signContents2:"",buildPass:2,signContents1:"CONFESS!§r",blockName:"minecraft:wall_sign",signContents3:"",meta:5}
:enddata
:endrule

rule:
plugin=vanillaBlocks
number=48
data:
JSON:{buildPass:0,blockName:"minecraft:nether_brick_fence",meta:0}
:enddata
:endrule

rule:
plugin=vanillaDoors
number=49
data:
JSON:{buildPass:2,blockName:"minecraft:wooden_door",meta:8,sideFlag:0b}
:enddata
:endrule

rule:
plugin=vanillaSign
number=50
data:
JSON:{signContents0:"",signContents2:"",buildPass:2,signContents1:"Confession§r",blockName:"minecraft:wall_sign",signContents3:"",meta:3}
:enddata
:endrule

rule:
plugin=vanillaBlocks
number=51
data:
JSON:{buildPass:2,blockName:"minecraft:torch",meta:2}
:enddata
:endrule

rule:
plugin=vanillaBlocks
number=52
data:
JSON:{buildPass:0,blockName:"minecraft:glowstone",meta:0}
:enddata
:endrule

rule:
plugin=vanillaDoors
number=53
data:
JSON:{buildPass:2,blockName:"minecraft:wooden_door",meta:9,sideFlag:0b}
:enddata
:endrule

rule:
plugin=vanillaDoors
number=54
data:
JSON:{buildPass:2,blockName:"minecraft:wooden_door",meta:8,sideFlag:0b}
:enddata
:endrule

rule:
plugin=vanillaBlocks
number=55
data:
JSON:{buildPass:0,blockName:"minecraft:stained_glass_pane",meta:15}
:enddata
:endrule

rule:
plugin=vanillaBlocks
number=56
data:
JSON:{buildPass:2,blockName:"minecraft:carpet",meta:13}
:enddata
:endrule

rule:
plugin=vanillaBlocks
number=57
data:
JSON:{buildPass:0,blockName:"minecraft:stone_brick_stairs",meta:6}
:enddata
:endrule

rule:
plugin=vanillaBlocks
number=58
data:
JSON:{buildPass:0,blockName:"minecraft:stone_brick_stairs",meta:5}
:enddata
:endrule

rule:
plugin=vanillaBlocks
number=59
data:
JSON:{buildPass:0,blockName:"minecraft:stone_brick_stairs",meta:4}
:enddata
:endrule

rule:
plugin=vanillaBlocks
number=60
data:
JSON:{buildPass:2,blockName:"minecraft:lit_redstone_lamp",meta:0}
:enddata
:endrule

rule:
plugin=vanillaBlocks
number=61
data:
JSON:{buildPass:2,blockName:"minecraft:lever",meta:9}
:enddata
:endrule

rule:
plugin=vanillaBlocks
number=62
data:
JSON:{buildPass:2,blockName:"minecraft:lever",meta:15}
:enddata
:endrule

rule:
plugin=vanillaBlocks
number=63
data:
JSON:{buildPass:0,blockName:"minecraft:stained_glass_pane",meta:0}
:enddata
:endrule

rule:
plugin=vanillaDoors
number=64
data:
JSON:{buildPass:2,blockName:"minecraft:iron_door",meta:1,sideFlag:8b}
:enddata
:endrule

rule:
plugin=vanillaBlocks
number=65
data:
JSON:{buildPass:0,blockName:"minecraft:iron_bars",meta:0}
:enddata
:endrule

rule:
plugin=vanillaBlocks
number=66
data:
JSON:{buildPass:0,blockName:"minecraft:stone_brick_stairs",meta:7}
:enddata
:endrule

rule:
plugin=vanillaBlocks
number=67
data:
JSON:{buildPass:2,blockName:"minecraft:lever",meta:12}
:enddata
:endrule

rule:
plugin=vanillaBlocks
number=68
data:
JSON:{buildPass:2,blockName:"minecraft:stone_button",meta:4}
:enddata
:endrule

rule:
plugin=vanillaDoors
number=69
data:
JSON:{buildPass:2,blockName:"minecraft:iron_door",meta:8,sideFlag:0b}
:enddata
:endrule

rule:
plugin=vanillaBlocks
number=70
data:
JSON:{buildPass:0,blockName:"minecraft:birch_stairs",meta:1}
:enddata
:endrule

rule:
plugin=vanillaBlocks
number=71
data:
JSON:{buildPass:0,blockName:"minecraft:birch_stairs",meta:0}
:enddata
:endrule

rule:
plugin=vanillaBlocks
number=72
data:
JSON:{buildPass:2,blockName:"minecraft:lever",meta:10}
:enddata
:endrule

rule:
plugin=vanillaBlocks
number=73
data:
JSON:{buildPass:0,blockName:"minecraft:wooden_slab",meta:2}
:enddata
:endrule

#### ENTITIES ####
entity:
plugin=vanillaHangingEntity
number=0
data:
position=17,4,3
JSON:{xOffset:0.0f,rotation:180.0f,mobID:"minecraft:painting",zOffset:0.0625f,entityData:{Motion:[0.0d,0.0d,0.0d],Invulnerable:0b,OnGround:0b,Dimension:0,Air:300s,Dir:2b,PortalCooldown:0,Direction:0b,Rotation:[180.0f,0.0f],Motive:"Creebet",FallDistance:0.0f,Pos:[93.0d,86.5d,-38.9375d],Fire:0s,TileY:86,TileX:92,TileZ:-40},direction:0b}
:enddata
:endentity

