# Ancient Warfare Structure Template File
# Auto-generated structure template file. created on: 12/21/2014 at: 14:29:43
# Lines beginning with # denote comments

header:
version=2.1
name=unique_creeper_church_dulciphi
size=25,16,29
offset=7,1,28
:endheader

#### VALIDATION ####
validation:
type=ground
survival=false
worldGenEnabled=false
unique=false
preserveBlocks=false
selectionWeight=0
clusterValue=0
minDuplicateDistance=0
dimensionWhiteList=false
dimensionList=
biomeWhiteList=false
biomeList=
leveling=0
fill=0
border=0
blockSwap=false
data:
:enddata
:endvalidation

#### LAYERS ####
layer: 0
1,1,1,1,1,1,1,1,1,1,1,1,1,1,1,1,1,1,1,1,1,1,1,1,1
1,2,2,2,2,2,2,2,2,2,2,2,2,1,1,1,1,1,1,1,1,1,1,1,1
1,2,1,1,1,1,1,1,1,1,2,2,2,2,2,2,2,2,2,2,2,2,1,1,1
1,2,1,1,1,1,1,1,1,1,1,2,2,2,2,2,2,1,2,2,2,2,1,1,1
1,2,1,1,1,1,1,2,2,2,1,1,1,1,2,2,2,2,2,2,2,2,1,1,1
1,2,1,1,1,1,2,1,2,2,2,2,1,2,2,2,2,2,2,2,2,2,1,1,1
1,2,2,2,2,1,1,2,2,1,2,2,1,1,2,2,2,2,2,2,2,2,1,1,1
1,2,2,1,2,1,1,1,2,2,2,2,1,2,2,2,2,2,2,2,1,2,1,1,1
1,2,1,1,1,1,1,1,1,2,2,1,2,1,2,2,2,2,2,2,1,2,1,1,1
1,2,2,2,2,1,1,1,1,1,1,1,2,2,1,2,2,2,2,2,1,2,1,1,1
1,2,2,2,2,2,2,2,2,2,2,1,2,2,2,2,2,2,2,2,2,2,1,1,1
1,2,2,2,2,2,2,2,2,2,2,2,2,1,1,1,1,1,1,1,1,1,1,1,1
1,2,2,2,2,2,2,2,2,2,2,2,2,1,1,1,1,1,1,3,1,1,1,1,1
1,2,1,2,2,2,2,2,2,2,2,2,2,1,1,1,1,1,1,3,1,1,1,1,1
1,2,1,2,2,2,2,2,2,2,2,2,2,1,1,2,1,1,1,3,1,1,1,1,1
1,2,2,2,2,2,2,2,2,2,2,2,2,1,1,1,1,1,1,3,1,1,1,1,1
1,2,2,2,2,2,2,2,2,2,2,2,2,1,1,1,1,1,1,3,1,1,1,1,1
1,2,2,1,2,1,2,2,2,2,2,2,2,1,1,1,1,1,1,3,1,1,1,1,1
1,2,2,2,2,2,2,2,2,2,2,2,2,1,1,1,1,1,1,3,1,1,1,1,1
1,2,2,2,2,2,2,2,2,2,2,2,2,1,1,1,1,1,1,3,1,1,1,1,1
1,2,2,2,2,2,2,2,2,2,2,2,2,1,1,1,1,1,1,3,1,1,1,1,1
1,2,2,2,2,2,2,2,2,2,2,2,2,1,1,1,1,1,1,3,1,1,1,1,1
1,2,2,2,2,2,2,2,2,2,1,2,2,1,1,1,1,1,1,3,1,1,1,1,1
1,2,2,2,2,2,2,2,2,2,2,2,2,1,1,1,1,1,1,3,1,1,1,1,1
1,2,1,2,2,2,2,2,1,2,2,2,2,1,1,1,1,1,1,1,1,1,1,1,1
1,2,2,1,2,2,2,2,2,2,2,2,2,1,1,1,1,1,1,1,1,1,1,1,1
1,2,2,2,2,2,2,2,2,2,2,2,2,1,1,1,1,1,1,1,1,1,1,1,1
1,1,1,1,1,1,2,2,1,1,1,1,1,1,1,1,1,1,1,1,1,1,1,1,1
1,1,1,1,1,1,1,1,1,1,1,1,1,1,1,1,1,1,1,1,1,1,1,1,1
:endlayer
layer: 1
4,0,0,0,0,0,0,0,0,0,0,0,0,4,0,0,0,0,0,0,0,0,0,0,5
0,6,7,7,7,7,7,7,7,7,7,7,6,0,0,0,0,0,0,0,0,0,0,0,0
0,7,8,8,8,8,8,8,8,8,8,8,8,7,7,7,7,7,7,7,7,7,0,0,0
0,7,8,8,8,8,8,8,8,8,8,8,8,8,8,8,8,8,8,8,8,7,0,0,0
0,7,8,8,8,8,8,8,8,8,8,8,8,8,9,9,9,9,9,9,8,7,0,0,0
0,7,8,8,8,8,8,8,8,8,8,8,8,8,9,9,9,9,9,9,8,7,0,0,0
0,6,7,7,7,8,8,8,8,8,8,8,8,8,9,9,9,9,9,9,8,7,0,0,0
0,7,8,8,8,8,8,8,8,8,8,8,8,8,9,9,9,9,9,9,8,7,0,0,0
0,7,8,8,8,8,8,8,8,8,8,8,8,8,9,9,9,9,9,9,8,7,0,0,0
0,7,7,7,7,8,8,8,8,8,8,8,7,8,8,8,8,8,8,8,8,7,0,0,0
0,7,10,11,7,8,8,8,8,8,8,8,6,7,7,7,7,7,7,7,7,7,4,4,0
4,6,10,10,8,8,8,8,8,8,8,8,6,0,0,0,0,0,12,13,14,0,0,4,0
0,7,10,8,8,8,8,8,8,8,8,8,7,0,0,0,0,0,0,0,0,0,0,4,0
0,7,8,8,8,8,8,8,8,8,8,8,7,0,0,0,0,0,0,0,0,0,0,4,0
0,7,8,8,8,8,8,8,8,8,8,8,7,0,0,15,0,0,0,0,0,0,0,16,0
0,7,8,9,9,9,9,9,9,9,9,8,7,0,0,0,0,0,0,0,0,0,0,4,0
0,7,8,9,9,9,9,9,9,9,9,8,7,0,0,0,0,0,0,0,0,0,0,4,0
0,7,8,8,8,8,9,9,8,8,8,8,7,0,0,0,0,0,0,0,0,0,0,4,0
0,7,8,8,8,8,9,9,8,8,8,8,7,0,0,0,0,0,0,0,0,0,0,4,0
0,7,8,8,8,8,9,9,8,8,8,8,7,0,0,0,0,0,0,0,0,0,0,4,0
0,7,8,8,8,8,9,9,8,8,8,8,7,0,0,5,0,0,0,0,0,0,0,4,0
0,7,8,8,8,8,9,9,8,8,8,8,7,0,0,0,0,0,0,0,0,0,0,4,0
0,7,8,8,8,8,9,9,8,8,8,8,7,0,0,0,0,0,0,0,0,0,0,4,0
0,7,8,8,8,8,9,9,8,8,8,8,7,0,0,0,0,0,0,0,0,0,0,4,0
0,7,8,8,8,8,9,9,8,8,8,8,7,4,4,4,4,4,4,17,4,4,4,4,0
0,7,8,8,8,8,9,9,8,8,8,8,7,0,0,0,0,0,0,0,0,0,0,0,0
0,6,7,7,7,6,6,6,6,7,7,7,6,0,0,0,0,0,0,0,0,0,0,0,0
5,0,0,0,0,0,13,13,0,0,0,0,0,0,0,0,0,0,0,0,0,0,0,0,5
0,0,4,0,0,0,0,0,0,0,0,4,0,0,0,0,0,0,0,0,0,0,0,0,0
:endlayer
layer: 2
4,0,0,0,0,0,0,0,0,0,0,0,0,4,0,0,0,0,0,0,0,0,0,0,18
0,6,7,19,19,19,19,19,19,19,19,7,6,20,0,0,0,0,0,0,0,0,0,0,0
0,7,5,0,0,0,0,0,0,0,0,21,6,7,7,7,7,7,7,7,7,7,0,0,0
0,22,0,0,0,0,0,0,0,0,0,21,6,0,0,0,0,0,0,0,0,7,0,0,0
0,22,0,0,0,0,0,0,0,0,0,0,0,0,0,23,23,23,23,0,0,7,0,0,0
0,7,0,0,0,0,0,0,0,0,0,0,0,0,0,5,5,5,5,0,0,7,0,0,0
0,6,24,24,24,0,0,0,0,0,0,0,0,0,0,5,5,5,5,0,0,7,0,0,0
0,7,0,0,6,0,0,0,0,0,0,0,0,0,0,5,5,5,5,0,0,7,0,0,0
0,7,0,0,25,0,0,0,0,0,0,0,6,0,0,26,26,26,26,0,0,7,0,0,0
0,7,7,7,7,0,0,0,0,0,0,0,6,0,0,0,0,0,0,0,0,7,0,0,0
0,7,0,0,25,0,0,0,0,0,0,0,6,7,7,7,7,7,7,27,7,7,0,0,0
4,6,28,29,6,0,0,0,0,0,0,0,6,0,0,0,0,0,0,0,0,30,0,0,0
0,7,31,12,6,6,6,6,6,6,0,0,7,0,32,32,32,0,0,0,0,0,0,0,0
0,7,0,6,6,6,6,6,6,6,0,0,7,32,32,32,32,32,0,0,0,0,0,18,0
0,7,33,6,34,34,35,35,34,34,0,0,7,32,32,15,32,32,0,0,0,0,0,0,0
0,7,0,0,0,0,0,0,0,0,0,0,7,32,32,32,32,32,0,0,0,0,0,18,0
0,7,0,0,0,0,0,0,0,0,0,0,7,0,32,32,32,0,0,0,0,0,0,0,0
0,7,0,0,0,0,0,0,0,0,0,0,7,0,0,0,0,0,0,0,0,0,0,0,0
0,22,0,0,0,0,0,0,0,0,0,0,7,0,0,0,0,0,0,0,0,0,0,0,0
0,7,0,36,36,36,0,0,36,36,36,0,7,0,0,0,0,0,0,0,0,0,0,0,0
0,22,0,0,0,0,0,0,0,0,0,0,7,0,0,5,0,0,0,0,0,0,0,0,0
0,7,0,36,36,36,0,0,36,36,36,0,7,0,0,0,0,0,0,0,0,0,0,0,0
0,22,0,0,0,0,0,0,0,0,0,0,7,0,0,0,0,0,0,0,0,0,0,0,0
0,7,0,36,36,36,0,0,36,36,36,0,7,0,0,0,0,0,0,0,0,0,0,0,0
0,22,0,0,0,0,0,0,0,0,0,0,7,18,0,0,0,0,18,0,18,0,0,18,0
0,7,0,0,0,0,0,0,0,0,0,0,7,0,0,0,0,0,0,0,0,0,0,0,0
0,6,7,22,7,6,37,27,6,7,22,7,6,0,0,0,0,0,0,0,0,0,0,0,0
18,0,0,0,30,0,0,0,0,30,0,0,0,0,0,0,0,0,0,0,0,0,0,0,18
0,0,4,0,0,0,0,0,0,0,0,4,0,0,0,0,0,0,0,0,0,0,0,0,0
:endlayer
layer: 3
4,0,0,0,0,0,0,0,0,0,0,0,0,4,0,0,0,0,0,0,0,0,0,0,0
0,6,7,19,19,38,19,19,38,19,19,7,6,0,0,0,0,0,0,0,0,0,0,0,0
0,7,39,0,0,0,0,0,0,0,0,0,6,7,7,7,7,7,7,7,7,7,0,0,0
0,22,0,0,0,0,0,0,0,0,0,0,6,20,0,0,0,0,0,0,0,7,0,0,0
0,22,0,0,0,0,0,0,0,0,0,0,0,0,0,0,0,0,0,0,0,7,0,0,0
0,7,0,0,0,0,0,0,0,0,0,0,0,0,0,39,39,39,39,0,0,7,0,0,0
0,6,0,0,0,0,0,0,0,0,0,0,0,0,0,39,39,39,39,0,0,7,20,0,0
0,7,24,24,24,0,0,0,0,0,0,0,0,0,0,39,39,39,39,0,0,7,0,0,0
0,7,40,0,41,0,0,0,0,0,0,0,6,0,0,0,0,0,0,0,0,7,0,0,0
0,7,7,7,7,0,0,0,0,0,0,0,6,20,0,0,0,0,0,0,0,7,0,0,0
0,7,0,0,42,0,0,0,0,0,0,0,6,7,7,22,22,22,7,43,7,7,0,0,0
4,6,44,45,6,46,0,0,0,0,0,0,6,0,0,0,0,0,0,0,0,0,0,0,0
0,7,47,0,6,48,48,48,48,48,0,0,7,0,0,0,0,0,0,0,0,0,0,0,0
0,7,0,6,0,0,0,0,0,0,0,0,7,0,0,32,0,0,0,0,0,0,0,0,0
0,7,49,6,0,0,5,5,0,0,0,0,7,0,32,15,32,0,0,0,0,0,0,0,0
0,7,0,50,0,0,0,0,0,0,0,0,7,0,0,32,0,0,0,0,0,0,0,0,0
0,7,0,0,0,0,0,0,0,0,0,0,7,0,0,0,0,0,0,0,0,0,0,0,0
0,7,20,0,0,0,0,0,0,0,0,51,7,0,0,0,0,0,0,0,0,0,0,0,0
0,22,0,0,0,0,0,0,0,0,0,0,7,0,0,0,0,0,0,0,0,0,0,0,0
0,7,20,0,0,0,0,0,0,0,0,51,7,0,0,0,0,0,0,0,0,0,0,0,0
0,22,0,0,0,0,0,0,0,0,0,0,7,0,0,52,0,0,0,0,0,0,0,0,0
0,7,20,0,0,0,0,0,0,0,0,51,7,0,0,0,0,0,0,0,0,0,0,0,0
0,22,0,0,0,0,0,0,0,0,0,0,7,0,0,0,0,0,0,0,0,0,0,0,0
0,7,20,0,0,0,0,0,0,0,0,51,7,0,0,0,0,0,0,0,0,0,0,0,0
0,22,0,0,0,0,0,0,0,0,0,0,7,0,0,0,0,0,0,0,0,0,0,0,0
0,7,0,0,0,0,0,0,0,0,0,0,7,0,0,0,0,0,0,0,0,0,0,0,0
0,6,7,22,7,6,53,54,6,7,22,7,6,0,0,0,0,0,0,0,0,0,0,0,0
0,0,0,0,0,0,0,0,0,0,0,0,0,0,0,0,0,0,0,0,0,0,0,0,0
0,0,4,0,0,0,0,0,0,0,0,4,0,0,0,0,0,0,0,0,0,0,0,0,0
:endlayer
layer: 4
4,0,0,0,0,0,0,0,0,0,0,0,0,4,0,0,0,0,0,0,0,0,0,0,0
0,6,7,19,19,55,55,55,55,19,19,7,6,0,0,0,0,0,0,0,0,0,0,0,0
0,7,20,0,0,0,0,0,0,0,0,0,6,7,7,7,7,7,7,7,7,7,0,0,0
0,22,0,0,0,0,0,0,0,0,0,51,6,0,0,0,0,0,0,0,0,7,0,0,0
0,22,0,0,0,0,0,0,0,0,0,0,0,0,0,0,0,0,0,0,0,7,0,0,0
0,7,0,0,0,0,0,0,0,0,0,0,0,0,0,0,0,0,0,0,0,7,0,0,0
0,6,0,0,0,0,0,0,0,0,0,0,0,0,0,0,0,0,0,0,0,7,0,0,0
0,7,0,0,0,0,0,0,0,0,0,0,0,0,0,0,0,0,0,0,0,7,0,0,0
0,7,24,24,24,0,0,0,0,0,0,51,6,0,0,0,0,0,0,0,0,7,0,0,0
0,7,11,11,11,8,8,8,8,8,8,8,6,0,0,0,0,0,0,0,0,7,0,0,0
0,7,8,8,11,8,8,8,8,8,8,8,6,7,7,22,22,22,7,7,7,7,0,0,0
4,6,8,8,11,8,8,8,8,8,8,8,6,0,0,0,0,0,0,0,0,0,0,0,0
0,7,11,11,18,0,0,0,0,0,8,8,7,0,32,32,32,0,0,0,0,0,0,0,0
0,7,8,11,0,0,0,0,0,0,8,8,7,32,32,32,32,32,0,0,0,0,0,0,0
0,7,11,11,0,0,56,56,0,0,8,8,7,32,32,15,32,32,0,0,0,0,0,0,0
0,7,8,8,0,0,0,0,0,0,8,8,7,32,32,32,32,32,0,0,0,0,0,0,0
0,7,8,8,0,0,0,0,0,0,8,8,7,0,32,32,32,0,0,0,0,0,0,0,0
0,7,8,8,0,0,0,0,0,0,8,8,7,0,0,0,0,0,0,0,0,0,0,0,0
0,7,8,8,0,0,0,0,0,0,8,8,7,0,0,0,0,0,0,0,0,0,0,0,0
0,7,8,8,0,0,0,0,0,0,8,8,7,0,0,0,0,0,0,0,0,0,0,0,0
0,7,8,8,0,0,0,0,0,0,8,8,7,0,0,0,0,0,0,0,0,0,0,0,0
0,7,8,8,0,0,0,0,0,0,8,8,7,0,0,0,0,0,0,0,0,0,0,0,0
0,7,8,8,0,0,0,0,0,0,8,8,7,0,0,0,0,0,0,0,0,0,0,0,0
0,7,8,8,8,8,8,8,8,8,8,8,7,0,0,0,0,0,0,0,0,0,0,0,0
0,7,8,8,8,8,8,8,8,8,8,8,7,0,0,0,0,0,0,0,0,0,0,0,0
0,7,8,8,8,8,57,57,8,8,8,8,7,0,0,0,0,0,0,0,0,0,0,0,0
0,6,7,7,7,6,58,59,6,7,7,7,6,0,0,0,0,0,0,0,0,0,0,0,0
0,8,8,8,8,8,8,8,8,8,8,8,8,0,0,0,0,0,0,0,0,0,0,0,0
0,8,11,8,8,8,8,8,8,8,8,11,8,0,0,0,0,0,0,0,0,0,0,0,0
:endlayer
layer: 5
4,0,0,0,0,0,0,0,0,0,0,0,0,4,0,0,0,0,0,0,0,0,0,0,0
0,6,7,19,19,19,55,55,19,19,19,7,6,0,0,0,0,0,0,0,0,0,0,0,0
0,7,0,0,0,0,0,0,0,0,0,0,6,7,7,7,7,7,7,7,7,7,0,0,0
0,22,0,0,0,0,0,0,0,0,0,0,6,0,0,0,0,0,0,0,0,7,0,0,0
0,22,0,0,0,0,0,0,0,0,0,0,0,0,0,0,0,0,0,0,0,7,0,0,0
0,7,0,0,0,0,0,0,0,0,0,0,0,0,0,0,0,0,0,0,0,7,0,0,0
0,6,0,0,0,0,0,0,0,0,0,0,0,0,0,0,0,0,0,60,61,7,0,0,0
0,7,0,0,0,0,0,0,0,0,0,0,0,0,0,0,0,0,0,0,0,7,0,0,0
0,7,0,0,0,0,0,0,0,0,0,0,6,0,0,0,0,0,0,0,0,7,0,0,0
0,7,0,0,0,48,48,48,48,48,48,48,6,0,0,0,0,0,0,0,0,7,0,0,0
0,7,0,0,0,0,0,0,0,0,0,0,6,7,7,7,7,7,7,7,7,7,0,0,0
4,6,0,48,48,48,48,48,48,48,48,0,6,0,0,0,0,0,0,0,0,0,0,0,0
0,7,0,48,0,0,0,0,0,0,48,0,7,0,0,0,0,0,0,0,0,0,0,0,0
0,7,0,48,0,0,0,0,0,0,48,0,7,0,0,32,0,0,0,0,0,0,0,0,0
0,7,0,48,0,0,0,0,0,0,48,0,7,0,32,15,32,0,0,0,0,0,0,0,0
0,7,0,48,0,0,0,0,0,0,48,0,7,0,0,32,0,0,0,0,0,0,0,0,0
0,7,0,48,0,0,0,0,0,0,48,0,7,0,0,0,0,0,0,0,0,0,0,0,0
0,7,0,48,0,0,0,0,0,0,48,0,22,0,0,0,0,0,0,0,0,0,0,0,0
0,7,0,48,0,0,0,0,0,0,48,0,22,0,0,0,0,0,0,0,0,0,0,0,0
0,7,0,48,0,0,0,0,0,0,48,0,22,0,0,0,0,0,0,0,0,0,0,0,0
0,7,0,48,0,0,0,0,0,0,48,0,22,0,0,0,0,0,0,0,0,0,0,0,0
0,22,0,48,0,62,0,0,62,0,48,0,7,0,0,0,0,0,0,0,0,0,0,0,0
0,22,0,48,0,0,0,0,0,0,48,0,7,0,0,0,0,0,0,0,0,0,0,0,0
0,22,0,48,48,48,48,48,48,48,48,0,7,0,0,0,0,0,0,0,0,0,0,0,0
0,7,0,0,0,0,0,0,0,0,0,0,7,0,0,0,0,0,0,0,0,0,0,0,0
0,7,21,0,0,0,0,0,0,0,0,0,7,0,0,0,0,0,0,0,0,0,0,0,0
0,6,7,7,63,63,19,19,63,63,7,64,6,0,0,0,0,0,0,0,0,0,0,0,0
0,65,0,0,0,0,0,0,0,0,0,0,65,0,0,0,0,0,0,0,0,0,0,0,0
0,65,65,65,65,65,65,65,65,65,65,65,65,0,0,0,0,0,0,0,0,0,0,0,0
:endlayer
layer: 6
4,0,0,0,0,0,0,0,0,0,0,0,0,4,0,0,0,0,0,0,0,0,0,0,0
0,6,7,19,19,19,38,38,19,19,19,7,6,6,24,24,24,24,24,24,24,24,0,0,0
59,7,0,0,0,0,0,0,0,0,0,0,6,7,7,7,7,7,7,7,7,7,0,0,0
66,22,0,0,0,0,0,0,0,0,0,0,6,0,0,0,0,0,0,0,0,7,0,0,0
57,22,0,0,0,0,0,0,0,0,0,0,0,0,0,0,0,0,0,0,0,7,0,0,0
59,7,0,0,0,67,0,0,67,0,0,0,0,0,0,0,0,0,0,0,0,7,0,0,0
0,6,0,0,0,60,0,0,60,0,0,0,0,0,0,0,0,0,0,5,0,7,0,0,0
0,7,0,0,0,0,0,0,0,0,0,0,0,0,0,0,0,0,0,0,0,7,0,0,0
0,7,0,0,0,0,0,0,0,0,0,0,6,0,0,0,0,0,0,0,0,7,0,0,0
0,7,0,0,0,0,0,0,0,0,0,0,6,0,0,0,0,0,0,0,0,7,0,0,0
0,7,0,0,0,0,0,0,0,0,0,0,6,7,7,7,7,7,7,7,7,7,0,0,0
4,6,0,0,0,0,0,0,0,0,0,0,6,23,23,23,23,23,23,23,23,13,0,0,0
0,7,0,0,0,0,0,0,0,0,0,0,7,0,0,0,0,0,0,0,0,0,0,0,0
0,7,0,0,0,0,0,0,0,0,0,0,7,0,0,0,0,0,0,0,0,0,0,0,0
0,7,0,0,0,0,0,0,0,0,0,0,7,0,0,15,0,0,0,0,0,0,0,0,0
0,7,0,0,0,0,0,0,0,0,0,0,7,0,0,0,0,0,0,0,0,0,0,0,0
0,7,0,0,0,0,0,0,0,0,0,0,7,0,0,0,0,0,0,0,0,0,0,0,0
0,7,0,0,0,0,0,0,0,0,0,0,22,0,0,0,0,0,0,0,0,0,0,0,0
0,7,0,0,0,0,0,0,0,0,0,0,22,0,0,0,0,0,0,0,0,0,0,0,0
0,7,0,0,0,0,0,0,0,0,0,0,22,0,0,0,0,0,0,0,0,0,0,0,0
0,7,0,0,0,0,0,0,0,0,0,0,22,0,0,0,0,0,0,0,0,0,0,0,0
0,22,0,0,0,60,0,0,60,0,0,0,7,0,0,0,0,0,0,0,0,0,0,0,0
0,22,0,0,0,0,0,0,0,0,0,0,7,0,0,0,0,0,0,0,0,0,0,0,0
0,22,0,0,0,0,0,0,0,0,0,0,7,0,0,0,0,0,0,0,0,0,0,0,0
0,7,0,0,0,0,0,0,0,0,0,0,7,0,0,0,0,0,0,0,0,0,0,0,0
0,7,0,0,0,0,0,0,0,0,68,0,7,0,0,0,0,0,0,0,0,0,0,0,0
0,6,7,7,63,63,19,19,63,63,7,69,6,0,0,0,0,0,0,0,0,0,0,0,0
0,0,0,0,0,0,0,0,0,0,0,0,0,0,0,0,0,0,0,0,0,0,0,0,0
0,0,0,0,0,0,0,0,0,0,0,0,0,0,0,0,0,0,0,0,0,0,0,0,0
:endlayer
layer: 7
12,0,0,0,0,0,0,0,0,0,0,0,0,14,0,0,0,0,0,0,0,0,0,0,0
12,6,7,19,38,55,19,19,55,38,19,7,6,14,0,0,0,0,0,0,0,0,0,0,0
12,7,0,0,0,0,0,0,0,0,0,0,6,70,26,26,26,26,26,26,26,24,0,0,0
12,7,0,0,0,0,0,0,0,0,0,0,6,0,0,0,0,0,0,0,0,6,0,0,0
12,7,0,0,0,0,0,0,0,0,0,0,6,0,0,0,0,0,0,0,0,7,0,0,0
12,7,0,0,0,0,0,0,0,0,0,0,6,0,0,0,0,0,0,0,0,7,0,0,0
12,6,0,0,0,5,0,0,5,0,0,0,6,0,0,0,0,0,0,5,5,7,0,0,0
12,7,0,0,0,0,0,0,0,0,0,0,6,0,0,0,0,0,0,0,0,7,0,0,0
12,7,0,0,0,0,0,0,0,0,0,0,6,0,0,0,0,0,0,0,0,7,0,0,0
12,7,0,0,0,0,0,0,0,0,0,0,6,0,0,0,0,0,0,0,0,6,0,0,0
12,7,0,0,0,0,0,0,0,0,0,0,6,23,23,23,23,23,23,23,23,13,0,0,0
12,6,0,0,0,0,0,0,0,0,0,0,6,0,0,0,0,0,0,0,0,0,0,0,0
0,7,0,0,0,0,0,0,0,0,0,0,7,0,0,0,0,0,0,0,0,0,0,0,0
0,7,0,0,0,0,0,0,0,0,0,0,7,0,0,32,0,0,0,0,0,0,0,0,0
0,7,0,0,0,0,0,0,0,0,0,0,7,0,32,32,32,0,0,0,0,0,0,0,0
0,7,0,0,0,0,0,0,0,0,0,0,7,0,0,32,0,0,0,0,0,0,0,0,0
0,7,0,0,0,0,0,0,0,0,0,0,7,0,0,0,0,0,0,0,0,0,0,0,0
0,7,0,0,0,0,0,0,0,0,0,0,22,0,0,0,0,0,0,0,0,0,0,0,0
0,7,0,0,0,0,0,0,0,0,0,0,22,0,0,0,0,0,0,0,0,0,0,0,0
0,7,0,0,0,0,0,0,0,0,0,0,22,0,0,0,0,0,0,0,0,0,0,0,0
0,7,0,0,0,0,0,0,0,0,0,0,22,0,0,0,0,0,0,0,0,0,0,0,0
0,7,0,0,0,5,0,0,5,0,0,0,7,0,0,0,0,0,0,0,0,0,0,0,0
0,7,0,0,0,0,0,0,0,0,0,0,7,0,0,0,0,0,0,0,0,0,0,0,0
0,7,0,0,0,0,0,0,0,0,0,0,7,0,0,0,0,0,0,0,0,0,0,0,0
0,7,0,0,0,0,0,0,0,0,0,0,7,0,0,0,0,0,0,0,0,0,0,0,0
0,7,0,0,0,0,0,0,0,0,0,0,7,0,0,0,0,0,0,0,0,0,0,0,0
0,6,7,7,63,63,19,19,63,63,7,7,6,0,0,0,0,0,0,0,0,0,0,0,0
0,0,0,0,0,0,0,0,0,0,0,0,0,0,0,0,0,0,0,0,0,0,0,0,0
0,0,0,0,0,0,0,0,0,0,0,0,0,0,0,0,0,0,0,0,0,0,0,0,0
:endlayer
layer: 8
0,12,0,0,0,0,0,0,0,0,0,0,14,0,0,0,0,0,0,0,0,0,0,0,0
0,12,7,19,38,38,19,19,38,38,19,7,14,0,0,0,0,0,0,0,0,0,0,0,0
0,71,0,0,0,0,0,0,0,0,0,0,70,0,0,0,0,0,0,0,0,0,0,0,0
0,71,0,0,0,0,0,0,0,0,0,0,70,26,26,26,26,26,26,26,26,24,0,0,0
0,71,0,0,0,0,0,0,0,0,0,0,6,0,0,0,0,0,0,0,0,6,0,0,0
0,71,0,0,0,0,0,0,0,0,0,0,6,0,0,0,0,0,0,0,0,7,0,0,0
0,71,0,0,0,5,0,0,5,0,0,0,6,0,0,0,0,0,0,0,0,7,0,0,0
0,71,0,0,0,0,0,0,0,0,0,0,6,0,0,0,0,0,0,0,0,7,0,0,0
0,71,0,0,0,0,0,0,0,0,0,0,6,0,0,0,0,0,0,0,0,6,0,0,0
0,71,0,0,0,0,0,0,0,0,0,0,70,23,23,23,23,23,23,23,23,13,0,0,0
0,71,0,0,0,0,0,0,0,0,0,0,70,0,0,0,0,0,0,0,0,0,0,0,0
0,71,0,0,0,0,0,0,0,0,0,0,70,0,0,0,0,0,0,0,0,0,0,0,0
0,71,0,0,0,0,0,0,0,0,0,0,70,0,0,0,0,0,0,0,0,0,0,0,0
0,71,0,0,0,0,0,0,0,0,0,0,70,0,0,0,0,0,0,0,0,0,0,0,0
0,71,0,0,0,0,0,0,0,0,0,0,70,0,0,0,0,0,0,0,0,0,0,0,0
0,71,0,0,0,0,0,0,0,0,0,0,70,0,0,0,0,0,0,0,0,0,0,0,0
0,71,0,0,0,0,0,0,0,0,0,0,70,0,0,0,0,0,0,0,0,0,0,0,0
0,71,0,0,0,0,0,0,0,0,0,0,70,0,0,0,0,0,0,0,0,0,0,0,0
0,71,0,0,0,0,0,0,0,0,0,0,70,0,0,0,0,0,0,0,0,0,0,0,0
0,71,0,0,0,0,0,0,0,0,0,0,70,0,0,0,0,0,0,0,0,0,0,0,0
0,71,0,0,0,0,0,0,0,0,0,0,70,0,0,0,0,0,0,0,0,0,0,0,0
0,71,0,0,0,5,0,0,5,0,0,0,70,0,0,0,0,0,0,0,0,0,0,0,0
0,71,0,0,0,0,0,0,0,0,0,0,70,0,0,0,0,0,0,0,0,0,0,0,0
0,71,0,0,0,0,0,0,0,0,0,0,70,0,0,0,0,0,0,0,0,0,0,0,0
0,71,0,0,0,0,0,0,0,0,0,0,70,0,0,0,0,0,0,0,0,0,0,0,0
0,71,0,0,0,0,0,0,0,0,0,0,70,0,0,0,0,0,0,0,0,0,0,0,0
0,12,6,7,63,19,19,19,19,63,7,6,14,0,0,0,0,0,0,0,0,0,0,0,0
0,12,0,0,0,0,0,0,0,0,0,0,14,0,0,0,0,0,0,0,0,0,0,0,0
0,0,0,0,0,0,0,0,0,0,0,0,0,0,0,0,0,0,0,0,0,0,0,0,0
:endlayer
layer: 9
0,0,12,0,0,0,0,0,0,0,0,14,0,0,0,0,0,0,0,0,0,0,0,0,0
0,0,12,7,19,19,19,19,19,19,7,14,0,0,0,0,0,0,0,0,0,0,0,0,0
0,0,71,0,0,0,0,0,0,0,0,70,0,0,0,0,0,0,0,0,0,0,0,0,0
0,0,71,0,0,0,0,0,0,0,0,70,0,0,0,0,0,0,0,0,0,0,0,0,0
0,0,71,0,0,0,0,0,0,0,0,70,26,26,26,26,26,26,26,26,26,24,0,0,0
0,0,71,0,0,0,0,0,0,0,0,0,6,0,0,0,0,0,0,0,0,6,0,0,0
0,0,71,0,0,5,0,0,5,0,0,0,6,0,0,0,0,0,0,0,0,7,0,0,0
0,0,71,0,0,0,0,0,0,0,0,0,6,0,0,0,0,0,0,0,0,6,0,0,0
0,0,71,0,0,0,0,0,0,0,0,23,23,23,23,23,23,23,23,23,23,13,0,0,0
0,0,71,0,0,0,0,0,0,0,0,70,0,0,0,0,0,0,0,0,0,0,0,0,0
0,0,71,0,0,0,0,0,0,0,0,70,0,0,0,0,0,0,0,0,0,0,0,0,0
0,0,71,0,0,0,0,0,0,0,0,70,0,0,0,0,0,0,0,0,0,0,0,0,0
0,0,71,0,0,0,0,0,0,0,0,70,0,0,0,0,0,0,0,0,0,0,0,0,0
0,0,71,0,0,0,0,0,0,0,0,70,0,0,0,0,0,0,0,0,0,0,0,0,0
0,0,71,0,0,0,0,0,0,0,0,70,0,0,0,0,0,0,0,0,0,0,0,0,0
0,0,71,0,0,0,0,0,0,0,0,70,0,0,0,0,0,0,0,0,0,0,0,0,0
0,0,71,0,0,0,0,0,0,0,0,70,0,0,0,0,0,0,0,0,0,0,0,0,0
0,0,71,0,72,60,0,0,60,61,0,70,0,0,0,0,0,0,0,0,0,0,0,0,0
0,0,71,0,0,0,0,0,0,0,0,70,0,0,0,0,0,0,0,0,0,0,0,0,0
0,0,71,0,0,0,0,0,0,0,0,70,0,0,0,0,0,0,0,0,0,0,0,0,0
0,0,71,0,0,0,0,0,0,0,0,70,0,0,0,0,0,0,0,0,0,0,0,0,0
0,0,71,0,0,5,0,0,5,0,0,70,0,0,0,0,0,0,0,0,0,0,0,0,0
0,0,71,0,0,0,0,0,0,0,0,70,0,0,0,0,0,0,0,0,0,0,0,0,0
0,0,71,0,0,0,0,0,0,0,0,70,0,0,0,0,0,0,0,0,0,0,0,0,0
0,0,71,0,0,0,0,0,0,0,0,70,0,0,0,0,0,0,0,0,0,0,0,0,0
0,0,71,0,0,0,0,0,0,0,0,70,0,0,0,0,0,0,0,0,0,0,0,0,0
0,0,12,7,63,63,19,19,63,63,7,14,0,0,0,0,0,0,0,0,0,0,0,0,0
0,0,12,0,0,0,0,0,0,0,0,14,0,0,0,0,0,0,0,0,0,0,0,0,0
0,0,0,0,0,0,0,0,0,0,0,0,0,0,0,0,0,0,0,0,0,0,0,0,0
:endlayer
layer: 10
0,0,0,12,0,0,0,0,0,0,14,0,0,0,0,0,0,0,0,0,0,0,0,0,0
0,0,0,12,7,19,19,19,19,7,14,0,0,0,0,0,0,0,0,0,0,0,0,0,0
0,0,0,71,0,0,0,0,0,0,70,0,0,0,0,0,0,0,0,0,0,0,0,0,0
0,0,0,71,0,0,0,0,0,0,70,0,0,0,0,0,0,0,0,0,0,0,0,0,0
0,0,0,71,0,0,0,0,0,0,70,0,0,0,0,0,0,0,0,0,0,0,0,0,0
0,0,0,71,0,0,0,0,0,0,26,26,26,26,26,26,26,26,26,26,26,24,0,0,0
0,0,0,71,0,5,0,0,5,0,6,6,6,6,6,6,6,6,6,6,6,6,0,0,0
0,0,0,71,0,0,0,0,0,0,70,23,23,23,23,23,23,23,23,23,23,13,0,0,0
0,0,0,71,0,0,0,0,0,0,70,0,0,0,0,0,0,0,0,0,0,0,0,0,0
0,0,0,71,0,0,0,0,0,0,70,0,0,0,0,0,0,0,0,0,0,0,0,0,0
0,0,0,71,0,0,0,0,0,0,70,0,0,0,0,0,0,0,0,0,0,0,0,0,0
0,0,0,71,0,0,0,0,0,0,70,0,0,0,0,0,0,0,0,0,0,0,0,0,0
0,0,0,71,0,0,0,0,0,0,70,0,0,0,0,0,0,0,0,0,0,0,0,0,0
0,0,0,71,0,0,0,0,0,0,70,0,0,0,0,0,0,0,0,0,0,0,0,0,0
0,0,0,71,0,0,0,0,0,0,70,0,0,0,0,0,0,0,0,0,0,0,0,0,0
0,0,0,71,0,0,0,0,0,0,70,0,0,0,0,0,0,0,0,0,0,0,0,0,0
0,0,0,71,0,0,0,0,0,0,70,0,0,0,0,0,0,0,0,0,0,0,0,0,0
0,0,0,71,0,5,0,0,5,0,70,0,0,0,0,0,0,0,0,0,0,0,0,0,0
0,0,0,71,0,0,0,0,0,0,70,0,0,0,0,0,0,0,0,0,0,0,0,0,0
0,0,0,71,0,0,0,0,0,0,70,0,0,0,0,0,0,0,0,0,0,0,0,0,0
0,0,0,71,0,0,0,0,0,0,70,0,0,0,0,0,0,0,0,0,0,0,0,0,0
0,0,0,71,0,5,0,0,5,0,70,0,0,0,0,0,0,0,0,0,0,0,0,0,0
0,0,0,71,0,0,0,0,0,0,70,0,0,0,0,0,0,0,0,0,0,0,0,0,0
0,0,0,71,0,0,0,0,0,0,70,0,0,0,0,0,0,0,0,0,0,0,0,0,0
0,0,0,71,0,0,0,0,0,0,70,0,0,0,0,0,0,0,0,0,0,0,0,0,0
0,0,0,71,0,0,0,0,0,0,70,0,0,0,0,0,0,0,0,0,0,0,0,0,0
0,0,0,12,7,63,19,19,63,7,14,0,0,0,0,0,0,0,0,0,0,0,0,0,0
0,0,0,12,0,0,0,0,0,0,14,0,0,0,0,0,0,0,0,0,0,0,0,0,0
0,0,0,0,0,0,0,0,0,0,0,0,0,0,0,0,0,0,0,0,0,0,0,0,0
:endlayer
layer: 11
0,0,0,0,12,0,0,0,0,14,0,0,0,0,0,0,0,0,0,0,0,0,0,0,0
0,0,0,0,12,7,7,7,7,14,0,0,0,0,0,0,0,0,0,0,0,0,0,0,0
0,0,0,0,71,0,0,0,0,70,0,0,0,0,0,0,0,0,0,0,0,0,0,0,0
0,0,0,0,71,0,0,0,0,70,0,0,0,0,0,0,0,0,0,0,0,0,0,0,0
0,0,0,0,71,0,0,0,0,70,0,0,0,0,0,0,0,0,0,0,0,0,0,0,0
0,0,0,0,71,0,0,0,0,70,0,0,0,0,0,0,0,0,0,0,0,0,0,0,0
0,0,0,0,71,5,0,0,5,70,73,73,73,73,73,73,73,73,73,73,73,6,0,0,0
0,0,0,0,71,0,0,0,0,70,0,0,0,0,0,0,0,0,0,0,0,0,0,0,0
0,0,0,0,71,0,0,0,0,70,0,0,0,0,0,0,0,0,0,0,0,0,0,0,0
0,0,0,0,71,0,0,0,0,70,0,0,0,0,0,0,0,0,0,0,0,0,0,0,0
0,0,0,0,71,0,0,0,0,70,0,0,0,0,0,0,0,0,0,0,0,0,0,0,0
0,0,0,0,71,0,0,0,0,70,0,0,0,0,0,0,0,0,0,0,0,0,0,0,0
0,0,0,0,71,0,0,0,0,70,0,0,0,0,0,0,0,0,0,0,0,0,0,0,0
0,0,0,0,71,0,0,0,0,70,0,0,0,0,0,0,0,0,0,0,0,0,0,0,0
0,0,0,0,71,0,0,0,0,70,0,0,0,0,0,0,0,0,0,0,0,0,0,0,0
0,0,0,0,71,0,0,0,0,70,0,0,0,0,0,0,0,0,0,0,0,0,0,0,0
0,0,0,0,71,0,0,0,0,70,0,0,0,0,0,0,0,0,0,0,0,0,0,0,0
0,0,0,0,71,5,0,0,5,70,0,0,0,0,0,0,0,0,0,0,0,0,0,0,0
0,0,0,0,71,0,0,0,0,70,0,0,0,0,0,0,0,0,0,0,0,0,0,0,0
0,0,0,0,71,0,0,0,0,70,0,0,0,0,0,0,0,0,0,0,0,0,0,0,0
0,0,0,0,71,0,0,0,0,70,0,0,0,0,0,0,0,0,0,0,0,0,0,0,0
0,0,0,0,71,5,0,0,5,70,0,0,0,0,0,0,0,0,0,0,0,0,0,0,0
0,0,0,0,71,0,0,0,0,70,0,0,0,0,0,0,0,0,0,0,0,0,0,0,0
0,0,0,0,71,0,0,0,0,70,0,0,0,0,0,0,0,0,0,0,0,0,0,0,0
0,0,0,0,71,0,0,0,0,70,0,0,0,0,0,0,0,0,0,0,0,0,0,0,0
0,0,0,0,71,0,0,0,0,70,0,0,0,0,0,0,0,0,0,0,0,0,0,0,0
0,0,0,0,12,7,63,63,7,14,0,0,0,0,0,0,0,0,0,0,0,0,0,0,0
0,0,0,0,12,0,0,0,0,14,0,0,0,0,0,0,0,0,0,0,0,0,0,0,0
0,0,0,0,0,0,0,0,0,0,0,0,0,0,0,0,0,0,0,0,0,0,0,0,0
:endlayer
layer: 12
0,0,0,0,0,12,0,0,14,0,0,0,0,0,0,0,0,0,0,0,0,0,0,0,0
0,0,0,0,0,12,7,7,14,0,0,0,0,0,0,0,0,0,0,0,0,0,0,0,0
0,0,0,0,0,71,58,59,70,0,0,0,0,0,0,0,0,0,0,0,0,0,0,0,0
0,0,0,0,0,71,58,59,70,0,0,0,0,0,0,0,0,0,0,0,0,0,0,0,0
0,0,0,0,0,71,58,59,70,0,0,0,0,0,0,0,0,0,0,0,0,0,0,0,0
0,0,0,0,0,71,58,59,70,0,0,0,0,0,0,0,0,0,0,0,0,0,0,0,0
0,0,0,0,0,71,58,59,70,0,0,0,0,0,0,0,0,0,0,0,0,0,0,0,0
0,0,0,0,0,71,58,59,70,0,0,0,0,0,0,0,0,0,0,0,0,0,0,0,0
0,0,0,0,0,71,58,59,70,0,0,0,0,0,0,0,0,0,0,0,0,0,0,0,0
0,0,0,0,0,71,58,59,70,0,0,0,0,0,0,0,0,0,0,0,0,0,0,0,0
0,0,0,0,0,71,58,59,70,0,0,0,0,0,0,0,0,0,0,0,0,0,0,0,0
0,0,0,0,0,71,58,59,70,0,0,0,0,0,0,0,0,0,0,0,0,0,0,0,0
0,0,0,0,0,71,58,59,70,0,0,0,0,0,0,0,0,0,0,0,0,0,0,0,0
0,0,0,0,0,71,58,59,70,0,0,0,0,0,0,0,0,0,0,0,0,0,0,0,0
0,0,0,0,0,71,58,59,70,0,0,0,0,0,0,0,0,0,0,0,0,0,0,0,0
0,0,0,0,0,71,58,59,70,0,0,0,0,0,0,0,0,0,0,0,0,0,0,0,0
0,0,0,0,0,71,58,59,70,0,0,0,0,0,0,0,0,0,0,0,0,0,0,0,0
0,0,0,0,0,71,58,59,70,0,0,0,0,0,0,0,0,0,0,0,0,0,0,0,0
0,0,0,0,0,71,58,59,70,0,0,0,0,0,0,0,0,0,0,0,0,0,0,0,0
0,0,0,0,0,71,58,59,70,0,0,0,0,0,0,0,0,0,0,0,0,0,0,0,0
0,0,0,0,0,71,58,59,70,0,0,0,0,0,0,0,0,0,0,0,0,0,0,0,0
0,0,0,0,0,71,58,59,70,0,0,0,0,0,0,0,0,0,0,0,0,0,0,0,0
0,0,0,0,0,71,58,59,70,0,0,0,0,0,0,0,0,0,0,0,0,0,0,0,0
0,0,0,0,0,71,58,59,70,0,0,0,0,0,0,0,0,0,0,0,0,0,0,0,0
0,0,0,0,0,71,58,59,70,0,0,0,0,0,0,0,0,0,0,0,0,0,0,0,0
0,0,0,0,0,71,58,59,70,0,0,0,0,0,0,0,0,0,0,0,0,0,0,0,0
0,0,0,0,0,12,6,6,14,0,0,0,0,0,0,0,0,0,0,0,0,0,0,0,0
0,0,0,0,0,12,0,0,14,0,0,0,0,0,0,0,0,0,0,0,0,0,0,0,0
0,0,0,0,0,0,0,0,0,0,0,0,0,0,0,0,0,0,0,0,0,0,0,0,0
:endlayer
layer: 13
0,0,0,0,0,0,12,14,0,0,0,0,0,0,0,0,0,0,0,0,0,0,0,0,0
0,0,0,0,0,0,12,14,0,0,0,0,0,0,0,0,0,0,0,0,0,0,0,0,0
0,0,0,0,0,0,12,14,0,0,0,0,0,0,0,0,0,0,0,0,0,0,0,0,0
0,0,0,0,0,0,12,14,0,0,0,0,0,0,0,0,0,0,0,0,0,0,0,0,0
0,0,0,0,0,0,12,14,0,0,0,0,0,0,0,0,0,0,0,0,0,0,0,0,0
0,0,0,0,0,0,12,14,0,0,0,0,0,0,0,0,0,0,0,0,0,0,0,0,0
0,0,0,0,0,0,12,14,0,0,0,0,0,0,0,0,0,0,0,0,0,0,0,0,0
0,0,0,0,0,0,12,14,0,0,0,0,0,0,0,0,0,0,0,0,0,0,0,0,0
0,0,0,0,0,0,12,14,0,0,0,0,0,0,0,0,0,0,0,0,0,0,0,0,0
0,0,0,0,0,0,12,14,0,0,0,0,0,0,0,0,0,0,0,0,0,0,0,0,0
0,0,0,0,0,0,12,14,0,0,0,0,0,0,0,0,0,0,0,0,0,0,0,0,0
0,0,0,0,0,0,12,14,0,0,0,0,0,0,0,0,0,0,0,0,0,0,0,0,0
0,0,0,0,0,0,12,14,0,0,0,0,0,0,0,0,0,0,0,0,0,0,0,0,0
0,0,0,0,0,0,12,14,0,0,0,0,0,0,0,0,0,0,0,0,0,0,0,0,0
0,0,0,0,0,0,12,14,0,0,0,0,0,0,0,0,0,0,0,0,0,0,0,0,0
0,0,0,0,0,0,12,14,0,0,0,0,0,0,0,0,0,0,0,0,0,0,0,0,0
0,0,0,0,0,0,12,14,0,0,0,0,0,0,0,0,0,0,0,0,0,0,0,0,0
0,0,0,0,0,0,12,14,0,0,0,0,0,0,0,0,0,0,0,0,0,0,0,0,0
0,0,0,0,0,0,12,14,0,0,0,0,0,0,0,0,0,0,0,0,0,0,0,0,0
0,0,0,0,0,0,12,14,0,0,0,0,0,0,0,0,0,0,0,0,0,0,0,0,0
0,0,0,0,0,0,12,14,0,0,0,0,0,0,0,0,0,0,0,0,0,0,0,0,0
0,0,0,0,0,0,12,14,0,0,0,0,0,0,0,0,0,0,0,0,0,0,0,0,0
0,0,0,0,0,0,12,14,0,0,0,0,0,0,0,0,0,0,0,0,0,0,0,0,0
0,0,0,0,0,0,12,14,0,0,0,0,0,0,0,0,0,0,0,0,0,0,0,0,0
0,0,0,0,0,0,12,14,0,0,0,0,0,0,0,0,0,0,0,0,0,0,0,0,0
0,0,0,0,0,0,12,14,0,0,0,0,0,0,0,0,0,0,0,0,0,0,0,0,0
0,0,0,0,0,0,12,14,0,0,0,0,0,0,0,0,0,0,0,0,0,0,0,0,0
0,0,0,0,0,0,13,13,0,0,0,0,0,0,0,0,0,0,0,0,0,0,0,0,0
0,0,0,0,0,0,0,0,0,0,0,0,0,0,0,0,0,0,0,0,0,0,0,0,0
:endlayer
layer: 14
0,0,0,0,0,0,0,0,0,0,0,0,0,0,0,0,0,0,0,0,0,0,0,0,0
0,0,0,0,0,0,0,0,0,0,0,0,0,0,0,0,0,0,0,0,0,0,0,0,0
0,0,0,0,0,0,0,0,0,0,0,0,0,0,0,0,0,0,0,0,0,0,0,0,0
0,0,0,0,0,0,0,0,0,0,0,0,0,0,0,0,0,0,0,0,0,0,0,0,0
0,0,0,0,0,0,0,0,0,0,0,0,0,0,0,0,0,0,0,0,0,0,0,0,0
0,0,0,0,0,0,0,0,0,0,0,0,0,0,0,0,0,0,0,0,0,0,0,0,0
0,0,0,0,0,0,0,0,0,0,0,0,0,0,0,0,0,0,0,0,0,0,0,0,0
0,0,0,0,0,0,0,0,0,0,0,0,0,0,0,0,0,0,0,0,0,0,0,0,0
0,0,0,0,0,0,0,0,0,0,0,0,0,0,0,0,0,0,0,0,0,0,0,0,0
0,0,0,0,0,0,0,0,0,0,0,0,0,0,0,0,0,0,0,0,0,0,0,0,0
0,0,0,0,0,0,0,0,0,0,0,0,0,0,0,0,0,0,0,0,0,0,0,0,0
0,0,0,0,0,0,0,0,0,0,0,0,0,0,0,0,0,0,0,0,0,0,0,0,0
0,0,0,0,0,0,0,0,0,0,0,0,0,0,0,0,0,0,0,0,0,0,0,0,0
0,0,0,0,0,0,0,0,0,0,0,0,0,0,0,0,0,0,0,0,0,0,0,0,0
0,0,0,0,0,0,0,0,0,0,0,0,0,0,0,0,0,0,0,0,0,0,0,0,0
0,0,0,0,0,0,0,0,0,0,0,0,0,0,0,0,0,0,0,0,0,0,0,0,0
0,0,0,0,0,0,0,0,0,0,0,0,0,0,0,0,0,0,0,0,0,0,0,0,0
0,0,0,0,0,0,0,0,0,0,0,0,0,0,0,0,0,0,0,0,0,0,0,0,0
0,0,0,0,0,0,0,0,0,0,0,0,0,0,0,0,0,0,0,0,0,0,0,0,0
0,0,0,0,0,0,0,0,0,0,0,0,0,0,0,0,0,0,0,0,0,0,0,0,0
0,0,0,0,0,0,0,0,0,0,0,0,0,0,0,0,0,0,0,0,0,0,0,0,0
0,0,0,0,0,0,0,0,0,0,0,0,0,0,0,0,0,0,0,0,0,0,0,0,0
0,0,0,0,0,0,0,0,0,0,0,0,0,0,0,0,0,0,0,0,0,0,0,0,0
0,0,0,0,0,0,0,0,0,0,0,0,0,0,0,0,0,0,0,0,0,0,0,0,0
0,0,0,0,0,0,0,0,0,0,0,0,0,0,0,0,0,0,0,0,0,0,0,0,0
0,0,0,0,0,0,0,0,0,0,0,0,0,0,0,0,0,0,0,0,0,0,0,0,0
0,0,0,0,0,0,0,0,0,0,0,0,0,0,0,0,0,0,0,0,0,0,0,0,0
0,0,0,0,0,0,0,0,0,0,0,0,0,0,0,0,0,0,0,0,0,0,0,0,0
0,0,0,0,0,0,0,0,0,0,0,0,0,0,0,0,0,0,0,0,0,0,0,0,0
:endlayer
layer: 15
0,0,0,0,0,0,0,0,0,0,0,0,0,0,0,0,0,0,0,0,0,0,0,0,0
0,0,0,0,0,0,0,0,0,0,0,0,0,0,0,0,0,0,0,0,0,0,0,0,0
0,0,0,0,0,0,0,0,0,0,0,0,0,0,0,0,0,0,0,0,0,0,0,0,0
0,0,0,0,0,0,0,0,0,0,0,0,0,0,0,0,0,0,0,0,0,0,0,0,0
0,0,0,0,0,0,0,0,0,0,0,0,0,0,0,0,0,0,0,0,0,0,0,0,0
0,0,0,0,0,0,0,0,0,0,0,0,0,0,0,0,0,0,0,0,0,0,0,0,0
0,0,0,0,0,0,0,0,0,0,0,0,0,0,0,0,0,0,0,0,0,0,0,0,0
0,0,0,0,0,0,0,0,0,0,0,0,0,0,0,0,0,0,0,0,0,0,0,0,0
0,0,0,0,0,0,0,0,0,0,0,0,0,0,0,0,0,0,0,0,0,0,0,0,0
0,0,0,0,0,0,0,0,0,0,0,0,0,0,0,0,0,0,0,0,0,0,0,0,0
0,0,0,0,0,0,0,0,0,0,0,0,0,0,0,0,0,0,0,0,0,0,0,0,0
0,0,0,0,0,0,0,0,0,0,0,0,0,0,0,0,0,0,0,0,0,0,0,0,0
0,0,0,0,0,0,0,0,0,0,0,0,0,0,0,0,0,0,0,0,0,0,0,0,0
0,0,0,0,0,0,0,0,0,0,0,0,0,0,0,0,0,0,0,0,0,0,0,0,0
0,0,0,0,0,0,0,0,0,0,0,0,0,0,0,0,0,0,0,0,0,0,0,0,0
0,0,0,0,0,0,0,0,0,0,0,0,0,0,0,0,0,0,0,0,0,0,0,0,0
0,0,0,0,0,0,0,0,0,0,0,0,0,0,0,0,0,0,0,0,0,0,0,0,0
0,0,0,0,0,0,0,0,0,0,0,0,0,0,0,0,0,0,0,0,0,0,0,0,0
0,0,0,0,0,0,0,0,0,0,0,0,0,0,0,0,0,0,0,0,0,0,0,0,0
0,0,0,0,0,0,0,0,0,0,0,0,0,0,0,0,0,0,0,0,0,0,0,0,0
0,0,0,0,0,0,0,0,0,0,0,0,0,0,0,0,0,0,0,0,0,0,0,0,0
0,0,0,0,0,0,0,0,0,0,0,0,0,0,0,0,0,0,0,0,0,0,0,0,0
0,0,0,0,0,0,0,0,0,0,0,0,0,0,0,0,0,0,0,0,0,0,0,0,0
0,0,0,0,0,0,0,0,0,0,0,0,0,0,0,0,0,0,0,0,0,0,0,0,0
0,0,0,0,0,0,0,0,0,0,0,0,0,0,0,0,0,0,0,0,0,0,0,0,0
0,0,0,0,0,0,0,0,0,0,0,0,0,0,0,0,0,0,0,0,0,0,0,0,0
0,0,0,0,0,0,0,0,0,0,0,0,0,0,0,0,0,0,0,0,0,0,0,0,0
0,0,0,0,0,0,0,0,0,0,0,0,0,0,0,0,0,0,0,0,0,0,0,0,0
0,0,0,0,0,0,0,0,0,0,0,0,0,0,0,0,0,0,0,0,0,0,0,0,0
:endlayer

#### RULES ####
rule:
plugin=vanillaBlocks
number=1
data:
JSON:{{"val":{"blockName":{"val":"minecraft:grass","id":"ss"},"meta":{"val":"0","id":"pi"},"buildPass":{"val":"0","id":"pi"}},"id":"ct"}}
:enddata
:endrule

rule:
plugin=vanillaBlocks
number=2
data:
JSON:{{"val":{"blockName":{"val":"minecraft:dirt","id":"ss"},"meta":{"val":"0","id":"pi"},"buildPass":{"val":"0","id":"pi"}},"id":"ct"}}
:enddata
:endrule

rule:
plugin=vanillaBlocks
number=3
data:
JSON:{{"val":{"blockName":{"val":"minecraft:gravel","id":"ss"},"meta":{"val":"0","id":"pi"},"buildPass":{"val":"0","id":"pi"}},"id":"ct"}}
:enddata
:endrule

rule:
plugin=vanillaBlocks
number=4
data:
JSON:{{"val":{"blockName":{"val":"minecraft:cobblestone_wall","id":"ss"},"meta":{"val":"0","id":"pi"},"buildPass":{"val":"0","id":"pi"}},"id":"ct"}}
:enddata
:endrule

rule:
plugin=vanillaBlocks
number=5
data:
JSON:{{"val":{"blockName":{"val":"minecraft:fence","id":"ss"},"meta":{"val":"0","id":"pi"},"buildPass":{"val":"0","id":"pi"}},"id":"ct"}}
:enddata
:endrule

rule:
plugin=vanillaBlocks
number=6
data:
JSON:{{"val":{"blockName":{"val":"minecraft:stonebrick","id":"ss"},"meta":{"val":"0","id":"pi"},"buildPass":{"val":"0","id":"pi"}},"id":"ct"}}
:enddata
:endrule

rule:
plugin=vanillaBlocks
number=7
data:
JSON:{{"val":{"blockName":{"val":"minecraft:stonebrick","id":"ss"},"meta":{"val":"2","id":"pi"},"buildPass":{"val":"0","id":"pi"}},"id":"ct"}}
:enddata
:endrule

rule:
plugin=vanillaBlocks
number=8
data:
JSON:{{"val":{"blockName":{"val":"minecraft:stone_slab","id":"ss"},"meta":{"val":"8","id":"pi"},"buildPass":{"val":"0","id":"pi"}},"id":"ct"}}
:enddata
:endrule

rule:
plugin=vanillaBlocks
number=9
data:
JSON:{{"val":{"blockName":{"val":"minecraft:wool","id":"ss"},"meta":{"val":"13","id":"pi"},"buildPass":{"val":"0","id":"pi"}},"id":"ct"}}
:enddata
:endrule

rule:
plugin=vanillaBlocks
number=10
data:
JSON:{{"val":{"blockName":{"val":"minecraft:soul_sand","id":"ss"},"meta":{"val":"0","id":"pi"},"buildPass":{"val":"0","id":"pi"}},"id":"ct"}}
:enddata
:endrule

rule:
plugin=vanillaBlocks
number=11
data:
JSON:{{"val":{"blockName":{"val":"minecraft:double_stone_slab","id":"ss"},"meta":{"val":"0","id":"pi"},"buildPass":{"val":"0","id":"pi"}},"id":"ct"}}
:enddata
:endrule

rule:
plugin=vanillaBlocks
number=12
data:
JSON:{{"val":{"blockName":{"val":"minecraft:stone_brick_stairs","id":"ss"},"meta":{"val":"0","id":"pi"},"buildPass":{"val":"0","id":"pi"}},"id":"ct"}}
:enddata
:endrule

rule:
plugin=vanillaBlocks
number=13
data:
JSON:{{"val":{"blockName":{"val":"minecraft:stone_brick_stairs","id":"ss"},"meta":{"val":"3","id":"pi"},"buildPass":{"val":"0","id":"pi"}},"id":"ct"}}
:enddata
:endrule

rule:
plugin=vanillaBlocks
number=14
data:
JSON:{{"val":{"blockName":{"val":"minecraft:stone_brick_stairs","id":"ss"},"meta":{"val":"1","id":"pi"},"buildPass":{"val":"0","id":"pi"}},"id":"ct"}}
:enddata
:endrule

rule:
plugin=vanillaBlocks
number=15
data:
JSON:{{"val":{"blockName":{"val":"minecraft:log","id":"ss"},"meta":{"val":"1","id":"pi"},"buildPass":{"val":"0","id":"pi"}},"id":"ct"}}
:enddata
:endrule

rule:
plugin=vanillaBlocks
number=16
data:
JSON:{{"val":{"blockName":{"val":"minecraft:fence_gate","id":"ss"},"meta":{"val":"3","id":"pi"},"buildPass":{"val":"0","id":"pi"}},"id":"ct"}}
:enddata
:endrule

rule:
plugin=vanillaBlocks
number=17
data:
JSON:{{"val":{"blockName":{"val":"minecraft:fence_gate","id":"ss"},"meta":{"val":"0","id":"pi"},"buildPass":{"val":"0","id":"pi"}},"id":"ct"}}
:enddata
:endrule

rule:
plugin=vanillaBlocks
number=18
data:
JSON:{{"val":{"blockName":{"val":"minecraft:torch","id":"ss"},"meta":{"val":"5","id":"pi"},"buildPass":{"val":"2","id":"pi"}},"id":"ct"}}
:enddata
:endrule

rule:
plugin=vanillaBlocks
number=19
data:
JSON:{{"val":{"blockName":{"val":"minecraft:stained_glass_pane","id":"ss"},"meta":{"val":"13","id":"pi"},"buildPass":{"val":"0","id":"pi"}},"id":"ct"}}
:enddata
:endrule

rule:
plugin=vanillaBlocks
number=20
data:
JSON:{{"val":{"blockName":{"val":"minecraft:torch","id":"ss"},"meta":{"val":"1","id":"pi"},"buildPass":{"val":"2","id":"pi"}},"id":"ct"}}
:enddata
:endrule

rule:
plugin=vanillaBlocks
number=21
data:
JSON:{{"val":{"blockName":{"val":"minecraft:bookshelf","id":"ss"},"meta":{"val":"0","id":"pi"},"buildPass":{"val":"0","id":"pi"}},"id":"ct"}}
:enddata
:endrule

rule:
plugin=vanillaBlocks
number=22
data:
JSON:{{"val":{"blockName":{"val":"minecraft:glass_pane","id":"ss"},"meta":{"val":"0","id":"pi"},"buildPass":{"val":"0","id":"pi"}},"id":"ct"}}
:enddata
:endrule

rule:
plugin=vanillaBlocks
number=23
data:
JSON:{{"val":{"blockName":{"val":"minecraft:birch_stairs","id":"ss"},"meta":{"val":"3","id":"pi"},"buildPass":{"val":"0","id":"pi"}},"id":"ct"}}
:enddata
:endrule

rule:
plugin=vanillaBlocks
number=24
data:
JSON:{{"val":{"blockName":{"val":"minecraft:stone_brick_stairs","id":"ss"},"meta":{"val":"2","id":"pi"},"buildPass":{"val":"0","id":"pi"}},"id":"ct"}}
:enddata
:endrule

rule:
plugin=vanillaDoors
number=25
data:
JSON:{{"val":{"sideFlag":{"val":"8","id":"pb"},"blockName":{"val":"minecraft:wooden_door","id":"ss"},"meta":{"val":"2","id":"pi"},"buildPass":{"val":"2","id":"pi"}},"id":"ct"}}
:enddata
:endrule

rule:
plugin=vanillaBlocks
number=26
data:
JSON:{{"val":{"blockName":{"val":"minecraft:birch_stairs","id":"ss"},"meta":{"val":"2","id":"pi"},"buildPass":{"val":"0","id":"pi"}},"id":"ct"}}
:enddata
:endrule

rule:
plugin=vanillaDoors
number=27
data:
JSON:{{"val":{"sideFlag":{"val":"8","id":"pb"},"blockName":{"val":"minecraft:wooden_door","id":"ss"},"meta":{"val":"1","id":"pi"},"buildPass":{"val":"2","id":"pi"}},"id":"ct"}}
:enddata
:endrule

rule:
plugin=vanillaDoors
number=28
data:
JSON:{{"val":{"sideFlag":{"val":"8","id":"pb"},"blockName":{"val":"minecraft:iron_door","id":"ss"},"meta":{"val":"3","id":"pi"},"buildPass":{"val":"2","id":"pi"}},"id":"ct"}}
:enddata
:endrule

rule:
plugin=vanillaDoors
number=29
data:
JSON:{{"val":{"sideFlag":{"val":"9","id":"pb"},"blockName":{"val":"minecraft:iron_door","id":"ss"},"meta":{"val":"3","id":"pi"},"buildPass":{"val":"2","id":"pi"}},"id":"ct"}}
:enddata
:endrule

rule:
plugin=vanillaBlocks
number=30
data:
JSON:{{"val":{"blockName":{"val":"minecraft:torch","id":"ss"},"meta":{"val":"3","id":"pi"},"buildPass":{"val":"2","id":"pi"}},"id":"ct"}}
:enddata
:endrule

rule:
plugin=vanillaSign
number=31
data:
JSON:{{"val":{"blockName":{"val":"minecraft:wall_sign","id":"ss"},"signContents1":{"val":"I know you","id":"ss"},"signContents2":{"val":"did it","id":"ss"},"signContents0":{"val":"","id":"ss"},"meta":{"val":"5","id":"pi"},"signContents3":{"val":"","id":"ss"},"buildPass":{"val":"2","id":"pi"}},"id":"ct"}}
:enddata
:endrule

rule:
plugin=vanillaBlocks
number=32
data:
JSON:{{"val":{"blockName":{"val":"minecraft:leaves","id":"ss"},"meta":{"val":"1","id":"pi"},"buildPass":{"val":"0","id":"pi"}},"id":"ct"}}
:enddata
:endrule

rule:
plugin=vanillaDoors
number=33
data:
JSON:{{"val":{"sideFlag":{"val":"8","id":"pb"},"blockName":{"val":"minecraft:wooden_door","id":"ss"},"meta":{"val":"3","id":"pi"},"buildPass":{"val":"2","id":"pi"}},"id":"ct"}}
:enddata
:endrule

rule:
plugin=vanillaBlocks
number=34
data:
JSON:{{"val":{"blockName":{"val":"minecraft:quartz_stairs","id":"ss"},"meta":{"val":"3","id":"pi"},"buildPass":{"val":"0","id":"pi"}},"id":"ct"}}
:enddata
:endrule

rule:
plugin=vanillaBlocks
number=35
data:
JSON:{{"val":{"blockName":{"val":"minecraft:nether_brick_stairs","id":"ss"},"meta":{"val":"3","id":"pi"},"buildPass":{"val":"0","id":"pi"}},"id":"ct"}}
:enddata
:endrule

rule:
plugin=vanillaBlocks
number=36
data:
JSON:{{"val":{"blockName":{"val":"minecraft:nether_brick_stairs","id":"ss"},"meta":{"val":"2","id":"pi"},"buildPass":{"val":"0","id":"pi"}},"id":"ct"}}
:enddata
:endrule

rule:
plugin=vanillaDoors
number=37
data:
JSON:{{"val":{"sideFlag":{"val":"9","id":"pb"},"blockName":{"val":"minecraft:wooden_door","id":"ss"},"meta":{"val":"1","id":"pi"},"buildPass":{"val":"2","id":"pi"}},"id":"ct"}}
:enddata
:endrule

rule:
plugin=vanillaBlocks
number=38
data:
JSON:{{"val":{"blockName":{"val":"minecraft:stained_glass_pane","id":"ss"},"meta":{"val":"7","id":"pi"},"buildPass":{"val":"0","id":"pi"}},"id":"ct"}}
:enddata
:endrule

rule:
plugin=vanillaBlocks
number=39
data:
JSON:{{"val":{"blockName":{"val":"minecraft:carpet","id":"ss"},"meta":{"val":"7","id":"pi"},"buildPass":{"val":"2","id":"pi"}},"id":"ct"}}
:enddata
:endrule

rule:
plugin=vanillaSign
number=40
data:
JSON:{{"val":{"blockName":{"val":"minecraft:wall_sign","id":"ss"},"signContents1":{"val":"Time Out","id":"ss"},"signContents2":{"val":"corner","id":"ss"},"signContents0":{"val":"","id":"ss"},"meta":{"val":"5","id":"pi"},"signContents3":{"val":"","id":"ss"},"buildPass":{"val":"2","id":"pi"}},"id":"ct"}}
:enddata
:endrule

rule:
plugin=vanillaDoors
number=41
data:
JSON:{{"val":{"sideFlag":{"val":"0","id":"pb"},"blockName":{"val":"minecraft:wooden_door","id":"ss"},"meta":{"val":"8","id":"pi"},"buildPass":{"val":"2","id":"pi"}},"id":"ct"}}
:enddata
:endrule

rule:
plugin=vanillaDoors
number=42
data:
JSON:{{"val":{"sideFlag":{"val":"0","id":"pb"},"blockName":{"val":"minecraft:wooden_door","id":"ss"},"meta":{"val":"8","id":"pi"},"buildPass":{"val":"2","id":"pi"}},"id":"ct"}}
:enddata
:endrule

rule:
plugin=vanillaDoors
number=43
data:
JSON:{{"val":{"sideFlag":{"val":"0","id":"pb"},"blockName":{"val":"minecraft:wooden_door","id":"ss"},"meta":{"val":"8","id":"pi"},"buildPass":{"val":"2","id":"pi"}},"id":"ct"}}
:enddata
:endrule

rule:
plugin=vanillaDoors
number=44
data:
JSON:{{"val":{"sideFlag":{"val":"0","id":"pb"},"blockName":{"val":"minecraft:iron_door","id":"ss"},"meta":{"val":"8","id":"pi"},"buildPass":{"val":"2","id":"pi"}},"id":"ct"}}
:enddata
:endrule

rule:
plugin=vanillaDoors
number=45
data:
JSON:{{"val":{"sideFlag":{"val":"0","id":"pb"},"blockName":{"val":"minecraft:iron_door","id":"ss"},"meta":{"val":"9","id":"pi"},"buildPass":{"val":"2","id":"pi"}},"id":"ct"}}
:enddata
:endrule

rule:
plugin=vanillaSign
number=46
data:
JSON:{{"val":{"blockName":{"val":"minecraft:wall_sign","id":"ss"},"signContents1":{"val":"Father for I","id":"ss"},"signContents2":{"val":"am about to sin","id":"ss"},"signContents0":{"val":"Forgive me","id":"ss"},"meta":{"val":"5","id":"pi"},"signContents3":{"val":"..kthnx","id":"ss"},"buildPass":{"val":"2","id":"pi"}},"id":"ct"}}
:enddata
:endrule

rule:
plugin=vanillaSign
number=47
data:
JSON:{{"val":{"blockName":{"val":"minecraft:wall_sign","id":"ss"},"signContents1":{"val":"CONFESS!","id":"ss"},"signContents2":{"val":"","id":"ss"},"signContents0":{"val":"","id":"ss"},"meta":{"val":"5","id":"pi"},"signContents3":{"val":"","id":"ss"},"buildPass":{"val":"2","id":"pi"}},"id":"ct"}}
:enddata
:endrule

rule:
plugin=vanillaBlocks
number=48
data:
JSON:{{"val":{"blockName":{"val":"minecraft:nether_brick_fence","id":"ss"},"meta":{"val":"0","id":"pi"},"buildPass":{"val":"0","id":"pi"}},"id":"ct"}}
:enddata
:endrule

rule:
plugin=vanillaDoors
number=49
data:
JSON:{{"val":{"sideFlag":{"val":"0","id":"pb"},"blockName":{"val":"minecraft:wooden_door","id":"ss"},"meta":{"val":"8","id":"pi"},"buildPass":{"val":"2","id":"pi"}},"id":"ct"}}
:enddata
:endrule

rule:
plugin=vanillaSign
number=50
data:
JSON:{{"val":{"blockName":{"val":"minecraft:wall_sign","id":"ss"},"signContents1":{"val":"Confession","id":"ss"},"signContents2":{"val":"","id":"ss"},"signContents0":{"val":"","id":"ss"},"meta":{"val":"3","id":"pi"},"signContents3":{"val":"","id":"ss"},"buildPass":{"val":"2","id":"pi"}},"id":"ct"}}
:enddata
:endrule

rule:
plugin=vanillaBlocks
number=51
data:
JSON:{{"val":{"blockName":{"val":"minecraft:torch","id":"ss"},"meta":{"val":"2","id":"pi"},"buildPass":{"val":"2","id":"pi"}},"id":"ct"}}
:enddata
:endrule

rule:
plugin=vanillaBlocks
number=52
data:
JSON:{{"val":{"blockName":{"val":"minecraft:glowstone","id":"ss"},"meta":{"val":"0","id":"pi"},"buildPass":{"val":"0","id":"pi"}},"id":"ct"}}
:enddata
:endrule

rule:
plugin=vanillaDoors
number=53
data:
JSON:{{"val":{"sideFlag":{"val":"0","id":"pb"},"blockName":{"val":"minecraft:wooden_door","id":"ss"},"meta":{"val":"9","id":"pi"},"buildPass":{"val":"2","id":"pi"}},"id":"ct"}}
:enddata
:endrule

rule:
plugin=vanillaDoors
number=54
data:
JSON:{{"val":{"sideFlag":{"val":"0","id":"pb"},"blockName":{"val":"minecraft:wooden_door","id":"ss"},"meta":{"val":"8","id":"pi"},"buildPass":{"val":"2","id":"pi"}},"id":"ct"}}
:enddata
:endrule

rule:
plugin=vanillaBlocks
number=55
data:
JSON:{{"val":{"blockName":{"val":"minecraft:stained_glass_pane","id":"ss"},"meta":{"val":"15","id":"pi"},"buildPass":{"val":"0","id":"pi"}},"id":"ct"}}
:enddata
:endrule

rule:
plugin=vanillaBlocks
number=56
data:
JSON:{{"val":{"blockName":{"val":"minecraft:carpet","id":"ss"},"meta":{"val":"13","id":"pi"},"buildPass":{"val":"2","id":"pi"}},"id":"ct"}}
:enddata
:endrule

rule:
plugin=vanillaBlocks
number=57
data:
JSON:{{"val":{"blockName":{"val":"minecraft:stone_brick_stairs","id":"ss"},"meta":{"val":"6","id":"pi"},"buildPass":{"val":"0","id":"pi"}},"id":"ct"}}
:enddata
:endrule

rule:
plugin=vanillaBlocks
number=58
data:
JSON:{{"val":{"blockName":{"val":"minecraft:stone_brick_stairs","id":"ss"},"meta":{"val":"5","id":"pi"},"buildPass":{"val":"0","id":"pi"}},"id":"ct"}}
:enddata
:endrule

rule:
plugin=vanillaBlocks
number=59
data:
JSON:{{"val":{"blockName":{"val":"minecraft:stone_brick_stairs","id":"ss"},"meta":{"val":"4","id":"pi"},"buildPass":{"val":"0","id":"pi"}},"id":"ct"}}
:enddata
:endrule

rule:
plugin=vanillaBlocks
number=60
data:
JSON:{{"val":{"blockName":{"val":"minecraft:lit_redstone_lamp","id":"ss"},"meta":{"val":"0","id":"pi"},"buildPass":{"val":"2","id":"pi"}},"id":"ct"}}
:enddata
:endrule

rule:
plugin=vanillaBlocks
number=61
data:
JSON:{{"val":{"blockName":{"val":"minecraft:lever","id":"ss"},"meta":{"val":"9","id":"pi"},"buildPass":{"val":"2","id":"pi"}},"id":"ct"}}
:enddata
:endrule

rule:
plugin=vanillaBlocks
number=62
data:
JSON:{{"val":{"blockName":{"val":"minecraft:lever","id":"ss"},"meta":{"val":"15","id":"pi"},"buildPass":{"val":"2","id":"pi"}},"id":"ct"}}
:enddata
:endrule

rule:
plugin=vanillaBlocks
number=63
data:
JSON:{{"val":{"blockName":{"val":"minecraft:stained_glass_pane","id":"ss"},"meta":{"val":"0","id":"pi"},"buildPass":{"val":"0","id":"pi"}},"id":"ct"}}
:enddata
:endrule

rule:
plugin=vanillaDoors
number=64
data:
JSON:{{"val":{"sideFlag":{"val":"8","id":"pb"},"blockName":{"val":"minecraft:iron_door","id":"ss"},"meta":{"val":"1","id":"pi"},"buildPass":{"val":"2","id":"pi"}},"id":"ct"}}
:enddata
:endrule

rule:
plugin=vanillaBlocks
number=65
data:
JSON:{{"val":{"blockName":{"val":"minecraft:iron_bars","id":"ss"},"meta":{"val":"0","id":"pi"},"buildPass":{"val":"0","id":"pi"}},"id":"ct"}}
:enddata
:endrule

rule:
plugin=vanillaBlocks
number=66
data:
JSON:{{"val":{"blockName":{"val":"minecraft:stone_brick_stairs","id":"ss"},"meta":{"val":"7","id":"pi"},"buildPass":{"val":"0","id":"pi"}},"id":"ct"}}
:enddata
:endrule

rule:
plugin=vanillaBlocks
number=67
data:
JSON:{{"val":{"blockName":{"val":"minecraft:lever","id":"ss"},"meta":{"val":"12","id":"pi"},"buildPass":{"val":"2","id":"pi"}},"id":"ct"}}
:enddata
:endrule

rule:
plugin=vanillaBlocks
number=68
data:
JSON:{{"val":{"blockName":{"val":"minecraft:stone_button","id":"ss"},"meta":{"val":"4","id":"pi"},"buildPass":{"val":"2","id":"pi"}},"id":"ct"}}
:enddata
:endrule

rule:
plugin=vanillaDoors
number=69
data:
JSON:{{"val":{"sideFlag":{"val":"0","id":"pb"},"blockName":{"val":"minecraft:iron_door","id":"ss"},"meta":{"val":"8","id":"pi"},"buildPass":{"val":"2","id":"pi"}},"id":"ct"}}
:enddata
:endrule

rule:
plugin=vanillaBlocks
number=70
data:
JSON:{{"val":{"blockName":{"val":"minecraft:birch_stairs","id":"ss"},"meta":{"val":"1","id":"pi"},"buildPass":{"val":"0","id":"pi"}},"id":"ct"}}
:enddata
:endrule

rule:
plugin=vanillaBlocks
number=71
data:
JSON:{{"val":{"blockName":{"val":"minecraft:birch_stairs","id":"ss"},"meta":{"val":"0","id":"pi"},"buildPass":{"val":"0","id":"pi"}},"id":"ct"}}
:enddata
:endrule

rule:
plugin=vanillaBlocks
number=72
data:
JSON:{{"val":{"blockName":{"val":"minecraft:lever","id":"ss"},"meta":{"val":"10","id":"pi"},"buildPass":{"val":"2","id":"pi"}},"id":"ct"}}
:enddata
:endrule

rule:
plugin=vanillaBlocks
number=73
data:
JSON:{{"val":{"blockName":{"val":"minecraft:wooden_slab","id":"ss"},"meta":{"val":"2","id":"pi"},"buildPass":{"val":"0","id":"pi"}},"id":"ct"}}
:enddata
:endrule

#### ENTITIES ####
entity:
plugin=vanillaHangingEntity
number=0
data:
position=17,4,3
JSON:{{"val":{"entityData":{"val":{"Dir":{"val":"2","id":"pb"},"Motion":{"val":[{"val":"0.0","id":"pd"},{"val":"0.0","id":"pd"},{"val":"0.0","id":"pd"}],"id":"ls"},"OnGround":{"val":"0","id":"pb"},"TileY":{"val":"86","id":"pi"},"Dimension":{"val":"0","id":"pi"},"TileX":{"val":"92","id":"pi"},"Air":{"val":"300","id":"ps"},"TileZ":{"val":"-40","id":"pi"},"Motive":{"val":"Creebet","id":"ss"},"Direction":{"val":"0","id":"pb"},"Pos":{"val":[{"val":"93.0","id":"pd"},{"val":"86.5","id":"pd"},{"val":"-38.9375","id":"pd"}],"id":"ls"},"PortalCooldown":{"val":"0","id":"pi"},"Fire":{"val":"0","id":"ps"},"FallDistance":{"val":"0.0","id":"pf"},"Rotation":{"val":[{"val":"180.0","id":"pf"},{"val":"0.0","id":"pf"}],"id":"ls"},"Invulnerable":{"val":"0","id":"pb"}},"id":"ct"},"xOffset":{"val":"0.0","id":"pf"},"mobID":{"val":"painting","id":"ss"},"zOffset":{"val":"0.0625","id":"pf"},"rotation":{"val":"180.0","id":"pf"},"direction":{"val":"0","id":"pi"}},"id":"ct"}}
:enddata
:endentity

