# Ancient Warfare Structure Template File
# Auto-generated structure template file. created on: 8/28/2018 at: 17:29:59
# Lines beginning with # denote comments

header:
version=2.3
name=cosmetic_tree_swing_dulciphi
size=11,12,9
offset=6,1,8
:endheader

#### VALIDATION ####
validation:
type=ground
survival=false
worldGenEnabled=false
unique=false
preserveBlocks=false
selectionWeight=0
clusterValue=0
minDuplicateDistance=0
dimensionWhiteList=false
dimensionList=
biomeWhiteList=false
biomeList=
leveling=0
fill=0
border=0
blockSwap=false
data:
:enddata
:endvalidation

#### LAYERS ####
layer: 0
1,1,1,1,1,1,1,1,1,1,1
1,1,1,1,1,1,1,1,1,1,1
1,1,1,1,1,1,1,1,1,1,1
1,2,2,1,1,2,2,1,1,1,1
1,1,1,1,1,2,2,1,1,1,1
1,1,1,1,1,1,1,1,1,1,1
1,1,1,1,1,1,1,1,1,1,1
1,1,1,1,1,1,1,1,1,1,1
1,1,1,1,1,1,1,1,1,1,1
:endlayer
layer: 1
0,0,0,0,0,0,3,10,0,0,0
0,0,0,0,0,0,3,9,0,0,0
0,0,0,0,0,3,3,3,3,0,0
0,4,4,4,5,7,7,6,0,3,0
0,0,0,0,0,7,7,3,10,0,0
0,0,0,0,3,6,8,0,0,0,0
0,0,0,0,0,3,0,0,3,0,11
0,0,0,0,0,0,0,0,0,0,11
0,3,0,0,0,0,0,0,11,11,11
:endlayer
layer: 2
0,0,0,0,0,0,0,0,0,0,0
0,0,0,0,0,0,0,0,0,0,0
0,0,0,0,0,0,0,0,0,0,0
0,11,0,11,12,7,7,14,0,0,0
0,0,0,0,0,7,7,0,0,0,0
0,0,0,0,0,13,0,0,0,0,0
0,0,0,0,0,0,0,0,0,0,0
0,0,0,0,0,0,0,0,0,0,15
0,0,0,0,0,0,0,0,0,0,0
:endlayer
layer: 3
0,0,0,0,0,0,0,0,0,0,0
0,0,0,0,0,0,0,0,0,0,0
0,0,0,0,0,0,0,0,0,0,0
0,11,0,11,0,7,7,0,0,0,0
0,0,0,0,0,7,7,0,0,0,0
0,0,0,0,0,0,0,0,0,0,0
0,0,0,0,0,0,0,0,0,0,0
0,0,0,0,0,0,0,0,0,0,0
0,0,0,0,0,0,0,0,0,0,0
:endlayer
layer: 4
0,0,0,0,0,0,0,0,0,0,0
0,0,0,0,0,0,0,0,0,0,0
0,0,0,0,0,0,0,0,0,0,0
0,11,0,11,0,7,7,0,0,0,0
0,0,0,0,0,7,7,0,0,0,0
0,0,0,0,0,0,0,0,0,0,0
0,0,0,0,0,0,0,0,0,0,0
0,0,0,0,0,0,0,0,0,0,0
0,0,0,0,0,0,0,0,0,0,0
:endlayer
layer: 5
0,0,0,0,0,0,0,0,0,0,0
0,0,0,0,0,0,0,0,0,0,0
0,0,0,0,0,0,0,0,0,0,0
0,11,0,11,0,7,7,0,0,0,0
0,0,0,0,0,7,7,0,0,0,0
0,0,0,0,0,0,0,0,0,0,0
0,0,0,0,0,0,0,0,0,0,0
0,0,0,0,0,0,0,0,0,0,0
0,0,0,0,0,0,0,0,0,0,0
:endlayer
layer: 6
0,0,0,0,0,0,0,0,0,0,0
0,0,0,0,0,0,0,0,0,0,0
0,0,0,0,0,0,0,0,0,0,0
0,11,0,11,7,7,7,0,0,0,0
0,0,0,0,7,7,7,0,0,0,0
0,0,0,0,0,0,0,0,0,0,0
0,0,0,0,0,0,0,0,0,0,0
0,0,0,0,0,0,0,0,0,0,0
0,0,0,0,0,0,0,0,0,0,0
:endlayer
layer: 7
0,0,0,0,0,0,0,0,0,0,0
0,0,0,0,0,0,0,0,0,0,0
0,0,0,0,0,0,0,0,0,0,0
0,11,0,7,7,7,7,0,0,0,0
0,0,0,16,16,7,7,7,0,0,0
0,0,0,0,16,0,0,0,0,0,0
0,0,0,0,0,0,0,0,0,0,0
0,0,0,0,0,0,0,0,0,0,0
0,0,0,0,0,0,0,0,0,0,0
:endlayer
layer: 8
0,0,0,0,0,0,0,0,0,0,0
0,0,16,19,18,18,19,18,18,0,0
0,16,16,18,18,18,18,18,18,0,0
16,17,17,18,18,7,7,18,18,0,0
16,16,16,18,18,7,7,18,18,0,0
0,16,18,18,7,18,18,18,18,0,0
0,0,18,18,18,18,18,18,18,0,0
0,0,0,18,18,18,0,0,0,0,0
0,0,0,0,0,0,0,0,0,0,0
:endlayer
layer: 9
0,0,0,0,0,0,0,0,0,0,0
0,0,0,19,19,18,18,19,0,0,0
0,16,18,18,18,18,18,18,18,18,0
16,16,16,18,18,7,7,18,18,18,0
0,16,18,18,18,7,7,18,18,18,0
0,16,18,18,18,18,18,18,18,18,0
0,0,18,18,18,18,18,18,18,0,0
0,0,0,18,18,18,18,18,0,0,0
0,0,0,0,0,0,0,0,0,0,0
:endlayer
layer: 10
0,0,0,0,0,0,0,0,0,0,0
0,0,0,0,16,19,18,0,0,0,0
0,0,20,16,18,18,18,18,0,0,0
16,20,16,18,18,18,18,18,18,0,0
0,20,16,18,18,18,18,18,18,0,0
0,0,16,16,18,18,18,18,0,0,0
0,0,0,0,16,18,18,0,0,0,0
0,0,0,0,0,0,0,0,0,0,0
0,0,0,0,0,0,0,0,0,0,0
:endlayer
layer: 11
0,0,0,0,0,0,0,0,0,0,0
0,0,0,0,0,0,0,0,0,0,0
0,0,0,0,0,20,0,0,0,0,0
0,0,0,20,16,18,18,0,0,0,0
0,0,20,20,16,18,18,0,0,0,0
0,0,0,0,0,0,0,0,0,0,0
0,0,0,0,0,0,0,0,0,0,0
0,0,0,0,0,0,0,0,0,0,0
0,0,0,0,0,0,0,0,0,0,0
:endlayer

#### RULES ####
rule:
plugin=vanillaBlocks
number=1
data:
JSON:{buildPass:0,blockName:"minecraft:grass",meta:0}
:enddata
:endrule

rule:
plugin=vanillaBlocks
number=2
data:
JSON:{buildPass:0,blockName:"minecraft:dirt",meta:0}
:enddata
:endrule

rule:
plugin=vanillaBlocks
number=3
data:
JSON:{buildPass:2,blockName:"minecraft:tallgrass",meta:1}
:enddata
:endrule

rule:
plugin=vanillaBlocks
number=4
data:
JSON:{buildPass:0,blockName:"minecraft:wooden_slab",meta:8}
:enddata
:endrule

rule:
plugin=vanillaBlocks
number=5
data:
JSON:{buildPass:2,blockName:"minecraft:red_flower",meta:5}
:enddata
:endrule

rule:
plugin=vanillaBlocks
number=6
data:
JSON:{buildPass:2,blockName:"minecraft:double_plant",meta:2}
:enddata
:endrule

rule:
plugin=vanillaBlocks
number=7
data:
JSON:{buildPass:0,blockName:"minecraft:log2",meta:1}
:enddata
:endrule

rule:
plugin=vanillaBlocks
number=8
data:
JSON:{buildPass:2,blockName:"minecraft:red_flower",meta:4}
:enddata
:endrule

rule:
plugin=vanillaBlocks
number=9
data:
JSON:{buildPass:2,blockName:"minecraft:red_flower",meta:8}
:enddata
:endrule

rule:
plugin=vanillaBlocks
number=10
data:
JSON:{buildPass:2,blockName:"minecraft:yellow_flower",meta:0}
:enddata
:endrule

rule:
plugin=vanillaBlocks
number=11
data:
JSON:{buildPass:0,blockName:"minecraft:fence",meta:0}
:enddata
:endrule

rule:
plugin=vanillaBlocks
number=12
data:
JSON:{buildPass:2,blockName:"minecraft:torch",meta:2}
:enddata
:endrule

rule:
plugin=vanillaBlocks
number=13
data:
JSON:{buildPass:2,blockName:"minecraft:double_plant",meta:9}
:enddata
:endrule

rule:
plugin=vanillaBlocks
number=14
data:
JSON:{buildPass:2,blockName:"minecraft:double_plant",meta:8}
:enddata
:endrule

rule:
plugin=vanillaBlocks
number=15
data:
JSON:{buildPass:2,blockName:"minecraft:torch",meta:5}
:enddata
:endrule

rule:
plugin=vanillaBlocks
number=16
data:
JSON:{buildPass:0,blockName:"minecraft:leaves2",meta:13}
:enddata
:endrule

rule:
plugin=vanillaBlocks
number=17
data:
JSON:{buildPass:0,blockName:"minecraft:log2",meta:5}
:enddata
:endrule

rule:
plugin=vanillaBlocks
number=18
data:
JSON:{buildPass:0,blockName:"minecraft:leaves2",meta:1}
:enddata
:endrule

rule:
plugin=vanillaBlocks
number=19
data:
JSON:{buildPass:0,blockName:"minecraft:leaves2",meta:9}
:enddata
:endrule

rule:
plugin=vanillaBlocks
number=20
data:
JSON:{buildPass:0,blockName:"minecraft:leaves2",meta:5}
:enddata
:endrule

#### ENTITIES ####
