# Ancient Warfare Structure Template File
# Auto-generated structure template file. created on: 12/7/2018 at: 11:37:40
# Lines beginning with # denote comments

header:
version=2.8
name=BridgeEmpireMediumFoot33Blockspan
mods=
size=6,20,33
offset=2,6,32
:endheader

#### VALIDATION ####
validation:
type=ground
survival=true
worldGenEnabled=false
unique=false
preserveBlocks=true
selectionWeight=0
clusterValue=0
minDuplicateDistance=0
dimensionWhiteList=false
dimensionList=
biomeWhiteList=false
biomeList=
leveling=0
fill=0
border=0
blockSwap=false
:endvalidation

#### LAYERS ####
layer: 0
0,0,0,0,0,0
0,0,0,0,0,0
0,0,0,0,0,0
0,0,0,0,0,0
0,0,0,0,0,0
0,0,0,0,0,0
0,0,0,0,0,0
0,0,0,0,0,0
0,1,3,1,0,0
1,1,0,2,1,1
0,0,0,0,0,0
0,0,0,0,0,0
0,0,0,0,0,0
3,1,0,1,3,2
0,0,0,0,0,0
0,0,0,0,0,0
0,0,0,0,0,0
0,0,0,0,0,0
0,0,0,0,0,0
3,2,0,1,1,1
0,0,0,0,0,0
0,0,0,0,0,0
0,0,0,0,0,0
1,1,0,1,3,1
0,1,3,3,0,0
0,0,0,0,0,0
0,0,0,0,0,0
0,0,0,0,0,0
0,0,0,0,0,0
0,0,0,0,0,0
0,0,0,0,0,0
0,0,0,0,0,0
0,0,0,0,0,0
:endlayer
layer: 1
0,0,0,0,0,0
0,0,0,0,0,0
0,0,0,0,0,0
0,0,0,0,0,0
0,0,0,0,0,0
0,0,0,0,0,0
0,0,0,0,0,0
0,0,0,0,0,0
0,3,1,1,0,0
1,6,0,5,2,0
0,0,0,0,0,0
0,0,0,0,0,0
0,0,0,0,0,0
3,6,0,5,1,4
0,0,0,0,0,0
0,0,0,0,0,0
0,0,0,0,0,0
0,0,0,0,0,0
0,0,0,0,0,0
1,6,0,5,3,4
0,0,0,0,0,0
0,0,0,0,0,0
0,0,0,0,0,0
1,6,0,5,1,4
0,1,1,1,0,0
0,0,0,0,0,0
0,0,0,0,0,0
0,0,0,0,0,0
0,0,0,0,0,0
0,0,0,0,0,0
0,0,0,0,0,0
0,0,0,0,0,0
0,0,0,0,0,0
:endlayer
layer: 2
0,0,0,0,0,0
0,0,0,0,0,0
0,0,0,0,0,0
0,0,0,0,0,0
0,0,0,0,0,0
0,0,0,0,0,0
0,0,0,0,0,0
0,0,0,0,0,0
0,1,3,1,0,0
2,0,0,0,1,4
0,0,0,0,0,0
0,0,0,0,0,0
0,0,0,0,0,0
3,0,0,0,3,4
0,0,0,0,0,0
0,0,0,0,0,0
0,0,0,0,0,0
0,0,0,0,0,0
0,0,0,0,0,0
1,0,0,0,3,4
0,0,0,0,0,0
0,0,0,0,0,0
0,0,0,0,0,0
3,0,0,0,3,4
0,3,3,1,0,0
0,0,0,0,0,0
0,0,0,0,0,0
0,0,0,0,0,0
0,0,0,0,0,0
0,0,0,0,0,0
0,0,0,0,0,0
0,0,0,0,0,0
0,0,0,0,0,0
:endlayer
layer: 3
0,0,0,0,0,0
0,0,0,0,0,0
0,0,0,0,0,0
0,0,0,0,0,0
0,0,0,0,0,0
0,0,0,0,0,0
0,0,0,0,0,0
0,1,8,1,0,0
0,1,9,3,0,0
2,0,0,0,2,7
0,0,0,0,0,0
0,0,0,0,0,0
0,0,0,0,0,0
3,0,0,0,3,7
0,0,0,0,0,0
0,0,0,0,0,0
0,0,0,0,0,0
0,0,0,0,0,0
0,0,0,0,0,0
3,0,0,0,3,7
0,0,0,0,0,0
0,0,0,0,0,0
0,0,0,0,0,0
3,0,0,0,3,7
0,3,3,3,0,0
0,1,3,1,0,0
0,0,0,0,0,0
0,0,0,0,0,0
0,0,0,0,0,0
0,0,0,0,0,0
0,0,0,0,0,0
0,0,0,0,0,0
0,0,0,0,0,0
:endlayer
layer: 4
0,0,0,0,0,0
0,0,0,0,0,0
0,0,0,0,0,0
0,0,0,0,0,0
0,0,0,0,0,0
0,0,0,0,0,0
0,0,0,0,0,0
0,3,8,3,0,0
0,9,3,9,0,0
2,0,0,0,2,4
0,0,0,0,0,0
0,0,0,0,0,0
0,0,0,0,0,0
3,0,0,0,3,4
0,0,0,0,0,0
0,0,0,0,0,0
0,0,0,0,0,0
0,0,0,0,0,0
0,0,0,0,0,0
3,0,0,0,3,4
0,0,0,0,0,0
0,0,0,0,0,0
0,0,0,0,0,0
3,0,0,0,3,4
0,9,3,9,0,0
0,3,0,3,0,0
0,0,0,0,0,0
0,0,0,0,0,0
0,0,0,0,0,0
0,0,0,0,0,0
0,0,0,0,0,0
0,0,0,0,0,0
0,0,0,0,0,0
:endlayer
layer: 5
3,3,3,3,3,0
0,0,10,0,0,0
0,0,0,0,0,0
0,0,0,0,0,0
0,0,0,0,0,0
2,0,0,0,2,0
0,9,0,9,0,0
0,3,0,3,0,0
0,3,3,9,0,0
2,0,0,0,2,7
0,0,0,0,0,0
0,0,0,0,0,0
0,0,0,0,0,0
3,0,0,0,3,7
0,0,0,0,0,0
0,0,0,0,0,0
0,0,0,0,0,0
0,0,0,0,0,0
0,0,0,0,0,0
3,0,0,0,3,7
0,0,0,0,0,0
0,0,0,0,0,0
0,0,0,0,0,0
3,0,0,0,3,7
0,9,9,3,0,0
0,3,0,9,0,0
0,9,0,9,0,0
2,0,0,0,2,0
0,0,0,0,0,0
0,0,0,0,0,0
0,0,0,0,0,0
0,0,10,0,0,0
3,3,3,3,3,0
:endlayer
layer: 6
7,0,0,0,7,0
11,15,15,15,11,0
2,10,16,10,2,0
1,0,10,0,1,0
1,0,0,0,2,0
2,0,0,0,1,0
12,3,0,3,12,0
0,9,0,9,0,0
13,3,9,3,13,0
2,0,0,0,2,4
0,0,0,0,0,0
0,0,0,0,0,0
0,0,0,0,0,0
2,0,0,0,2,4
0,0,0,0,0,0
0,0,0,0,0,0
0,0,0,0,0,0
0,0,0,0,0,0
0,0,0,0,0,0
2,0,0,0,2,4
0,0,0,0,0,0
0,0,0,0,0,0
0,0,0,0,0,0
2,0,0,0,2,4
12,3,3,9,12,0
0,9,0,3,0,0
13,3,0,3,13,0
1,0,0,0,1,0
1,0,0,0,2,0
2,0,10,0,1,0
1,10,16,10,1,0
14,15,15,15,14,0
7,0,0,0,7,0
:endlayer
layer: 7
0,0,0,0,0,0
17,0,0,0,17,0
12,0,0,0,12,0
11,15,15,15,11,0
11,15,15,15,11,0
2,10,16,10,2,0
2,10,10,10,2,0
2,0,10,0,2,0
2,3,3,3,2,0
2,18,19,18,2,4
12,0,0,0,12,0
0,0,0,0,0,0
13,0,0,0,13,0
2,18,0,18,2,4
0,0,0,0,0,0
0,0,0,0,0,0
0,0,0,0,0,0
0,0,0,0,0,0
0,0,0,0,0,0
2,18,0,18,2,4
12,0,0,0,12,0
0,0,0,0,0,0
13,0,0,0,13,0
2,18,20,18,2,4
2,3,9,3,2,0
2,3,10,3,2,0
2,10,10,10,2,0
2,10,16,10,2,0
14,15,15,15,14,0
14,15,15,15,14,0
13,0,0,0,13,0
17,0,0,0,17,0
0,0,0,0,0,0
:endlayer
layer: 8
0,0,0,0,0,0
0,0,0,0,0,0
0,0,0,0,0,0
17,0,0,0,17,0
17,0,0,0,17,0
12,0,0,0,12,0
12,0,0,0,12,0
11,15,15,15,11,0
11,15,15,15,11,0
2,15,15,15,2,6
2,10,16,10,2,0
2,10,10,10,2,0
2,10,10,10,2,0
2,2,10,2,2,6
12,0,0,0,12,0
0,0,0,0,0,0
0,0,0,0,0,0
0,0,0,0,0,0
13,0,0,0,13,0
2,2,10,2,2,6
2,10,10,10,2,0
2,10,10,10,2,0
2,10,16,10,2,0
2,15,15,15,2,6
14,15,15,15,14,0
14,15,15,15,14,0
13,0,0,0,13,0
13,0,0,0,13,0
17,0,0,0,17,0
17,0,0,0,17,0
0,0,0,0,0,0
0,0,0,0,0,0
0,0,0,0,0,0
:endlayer
layer: 9
0,0,0,0,0,0
0,0,0,0,0,0
0,0,0,0,0,0
0,0,0,0,0,0
0,0,0,0,0,0
0,0,0,0,0,0
7,0,0,0,7,0
17,0,0,0,17,0
17,0,0,0,17,0
12,0,0,0,12,0
12,0,0,0,12,0
11,0,0,0,11,0
11,0,0,0,11,0
2,15,15,15,2,0
2,15,15,15,2,0
2,15,15,15,2,0
18,15,15,15,18,0
2,15,15,15,2,0
2,15,15,15,2,0
2,15,15,15,2,0
14,0,0,0,14,0
14,0,0,0,14,0
13,0,0,0,13,0
13,0,0,0,13,0
17,0,0,0,17,0
17,0,0,0,17,0
7,0,0,0,7,0
0,0,0,0,0,0
0,0,0,0,0,0
0,0,0,0,0,0
0,0,0,0,0,0
0,0,0,0,0,0
0,0,0,0,0,0
:endlayer
layer: 10
0,0,0,0,0,0
0,0,0,0,0,0
0,0,0,0,0,0
0,0,0,0,0,0
0,0,0,0,0,0
0,0,0,0,0,0
4,0,0,0,4,0
0,0,0,0,0,0
0,0,0,0,0,0
0,0,0,0,0,0
0,0,0,0,0,0
17,0,0,0,17,0
17,0,0,0,17,0
12,0,0,0,12,0
12,0,0,0,12,0
12,0,0,0,12,0
7,0,0,0,7,0
13,0,0,0,13,0
13,0,0,0,13,0
13,0,0,0,13,0
17,0,0,0,17,0
17,0,0,0,17,0
0,0,0,0,0,0
0,0,0,0,0,0
0,0,0,0,0,0
0,0,0,0,0,0
4,0,0,0,4,0
0,0,0,0,0,0
0,0,0,0,0,0
0,0,0,0,0,0
0,0,0,0,0,0
0,0,0,0,0,0
0,0,0,0,0,0
:endlayer
layer: 11
0,0,0,0,0,0
0,0,0,0,0,0
0,0,0,0,0,0
0,0,0,0,0,0
0,0,0,0,0,0
0,0,0,0,0,0
21,0,0,0,21,0
0,0,0,0,0,0
0,0,0,0,0,0
0,0,0,0,0,0
0,0,0,0,0,0
0,0,0,0,0,0
0,0,0,0,0,0
0,0,0,0,0,0
0,0,0,0,0,0
17,0,0,0,17,0
17,0,0,0,17,0
17,0,0,0,17,0
0,0,0,0,0,0
0,0,0,0,0,0
0,0,0,0,0,0
0,0,0,0,0,0
0,0,0,0,0,0
0,0,0,0,0,0
0,0,0,0,0,0
0,0,0,0,0,0
21,0,0,0,21,0
0,0,0,0,0,0
0,0,0,0,0,0
0,0,0,0,0,0
0,0,0,0,0,0
0,0,0,0,0,0
0,0,0,0,0,0
:endlayer
layer: 12
0,0,0,0,0,0
0,0,0,0,0,0
0,0,0,0,0,0
0,0,0,0,0,0
0,0,0,0,0,0
0,0,0,0,0,0
0,0,0,0,0,0
0,0,0,0,0,0
0,0,0,0,0,0
0,0,0,0,0,0
0,0,0,0,0,0
0,0,0,0,0,0
0,0,0,0,0,0
0,0,0,0,0,0
0,0,0,0,0,0
0,0,0,0,0,0
0,0,0,0,0,0
0,0,0,0,0,0
0,0,0,0,0,0
0,0,0,0,0,0
0,0,0,0,0,0
0,0,0,0,0,0
0,0,0,0,0,0
0,0,0,0,0,0
0,0,0,0,0,0
0,0,0,0,0,0
0,0,0,0,0,0
0,0,0,0,0,0
0,0,0,0,0,0
0,0,0,0,0,0
0,0,0,0,0,0
0,0,0,0,0,0
0,0,0,0,0,0
:endlayer
layer: 13
0,0,0,0,0,0
0,0,0,0,0,0
0,0,0,0,0,0
0,0,0,0,0,0
0,0,0,0,0,0
0,0,0,0,0,0
0,0,0,0,0,0
0,0,0,0,0,0
0,0,0,0,0,0
0,0,0,0,0,0
0,0,0,0,0,0
0,0,0,0,0,0
0,0,0,0,0,0
0,0,0,0,0,0
0,0,0,0,0,0
0,0,0,0,0,0
0,0,0,0,0,0
0,0,0,0,0,0
0,0,0,0,0,0
0,0,0,0,0,0
0,0,0,0,0,0
0,0,0,0,0,0
0,0,0,0,0,0
0,0,0,0,0,0
0,0,0,0,0,0
0,0,0,0,0,0
0,0,0,0,0,0
0,0,0,0,0,0
0,0,0,0,0,0
0,0,0,0,0,0
0,0,0,0,0,0
0,0,0,0,0,0
0,0,0,0,0,0
:endlayer
layer: 14
0,0,0,0,0,0
0,0,0,0,0,0
0,0,0,0,0,0
0,0,0,0,0,0
0,0,0,0,0,0
0,0,0,0,0,0
0,0,0,0,0,0
0,0,0,0,0,0
0,0,0,0,0,0
0,0,0,0,0,0
0,0,0,0,0,0
0,0,0,0,0,0
0,0,0,0,0,0
0,0,0,0,0,0
0,0,0,0,0,0
0,0,0,0,0,0
0,0,0,0,0,0
0,0,0,0,0,0
0,0,0,0,0,0
0,0,0,0,0,0
0,0,0,0,0,0
0,0,0,0,0,0
0,0,0,0,0,0
0,0,0,0,0,0
0,0,0,0,0,0
0,0,0,0,0,0
0,0,0,0,0,0
0,0,0,0,0,0
0,0,0,0,0,0
0,0,0,0,0,0
0,0,0,0,0,0
0,0,0,0,0,0
0,0,0,0,0,0
:endlayer
layer: 15
0,0,0,0,0,0
0,0,0,0,0,0
0,0,0,0,0,0
0,0,0,0,0,0
0,0,0,0,0,0
0,0,0,0,0,0
0,0,0,0,0,0
0,0,0,0,0,0
0,0,0,0,0,0
0,0,0,0,0,0
0,0,0,0,0,0
0,0,0,0,0,0
0,0,0,0,0,0
0,0,0,0,0,0
0,0,0,0,0,0
0,0,0,0,0,0
0,0,0,0,0,0
0,0,0,0,0,0
0,0,0,0,0,0
0,0,0,0,0,0
0,0,0,0,0,0
0,0,0,0,0,0
0,0,0,0,0,0
0,0,0,0,0,0
0,0,0,0,0,0
0,0,0,0,0,0
0,0,0,0,0,0
0,0,0,0,0,0
0,0,0,0,0,0
0,0,0,0,0,0
0,0,0,0,0,0
0,0,0,0,0,0
0,0,0,0,0,0
:endlayer
layer: 16
0,0,0,0,0,0
0,0,0,0,0,0
0,0,0,0,0,0
0,0,0,0,0,0
0,0,0,0,0,0
0,0,0,0,0,0
0,0,0,0,0,0
0,0,0,0,0,0
0,0,0,0,0,0
0,0,0,0,0,0
0,0,0,0,0,0
0,0,0,0,0,0
0,0,0,0,0,0
0,0,0,0,0,0
0,0,0,0,0,0
0,0,0,0,0,0
0,0,0,0,0,0
0,0,0,0,0,0
0,0,0,0,0,0
0,0,0,0,0,0
0,0,0,0,0,0
0,0,0,0,0,0
0,0,0,0,0,0
0,0,0,0,0,0
0,0,0,0,0,0
0,0,0,0,0,0
0,0,0,0,0,0
0,0,0,0,0,0
0,0,0,0,0,0
0,0,0,0,0,0
0,0,0,0,0,0
0,0,0,0,0,0
0,0,0,0,0,0
:endlayer
layer: 17
0,0,0,0,0,0
0,0,0,0,0,0
0,0,0,0,0,0
0,0,0,0,0,0
0,0,0,0,0,0
0,0,0,0,0,0
0,0,0,0,0,0
0,0,0,0,0,0
0,0,0,0,0,0
0,0,0,0,0,0
0,0,0,0,0,0
0,0,0,0,0,0
0,0,0,0,0,0
0,0,0,0,0,0
0,0,0,0,0,0
0,0,0,0,0,0
0,0,0,0,0,0
0,0,0,0,0,0
0,0,0,0,0,0
0,0,0,0,0,0
0,0,0,0,0,0
0,0,0,0,0,0
0,0,0,0,0,0
0,0,0,0,0,0
0,0,0,0,0,0
0,0,0,0,0,0
0,0,0,0,0,0
0,0,0,0,0,0
0,0,0,0,0,0
0,0,0,0,0,0
0,0,0,0,0,0
0,0,0,0,0,0
0,0,0,0,0,0
:endlayer
layer: 18
0,0,0,0,0,0
0,0,0,0,0,0
0,0,0,0,0,0
0,0,0,0,0,0
0,0,0,0,0,0
0,0,0,0,0,0
0,0,0,0,0,0
0,0,0,0,0,0
0,0,0,0,0,0
0,0,0,0,0,0
0,0,0,0,0,0
0,0,0,0,0,0
0,0,0,0,0,0
0,0,0,0,0,0
0,0,0,0,0,0
0,0,0,0,0,0
0,0,0,0,0,0
0,0,0,0,0,0
0,0,0,0,0,0
0,0,0,0,0,0
0,0,0,0,0,0
0,0,0,0,0,0
0,0,0,0,0,0
0,0,0,0,0,0
0,0,0,0,0,0
0,0,0,0,0,0
0,0,0,0,0,0
0,0,0,0,0,0
0,0,0,0,0,0
0,0,0,0,0,0
0,0,0,0,0,0
0,0,0,0,0,0
0,0,0,0,0,0
:endlayer
layer: 19
0,0,0,0,0,0
0,0,0,0,0,0
0,0,0,0,0,0
0,0,0,0,0,0
0,0,0,0,0,0
0,0,0,0,0,0
0,0,0,0,0,0
0,0,0,0,0,0
0,0,0,0,0,0
0,0,0,0,0,0
0,0,0,0,0,0
0,0,0,0,0,0
0,0,0,0,0,0
0,0,0,0,0,0
0,0,0,0,0,0
0,0,0,0,0,0
0,0,0,0,0,0
0,0,0,0,0,0
0,0,0,0,0,0
0,0,0,0,0,0
0,0,0,0,0,0
0,0,0,0,0,0
0,0,0,0,0,0
0,0,0,0,0,0
0,0,0,0,0,0
0,0,0,0,0,0
0,0,0,0,0,0
0,0,0,0,0,0
0,0,0,0,0,0
0,0,0,0,0,0
0,0,0,0,0,0
0,0,0,0,0,0
0,0,0,0,0,0
:endlayer

#### RULES ####
rule:
plugin=vanillaBlocks
number=1
data:
JSON:{blockState:{blockName:"minecraft:stonebrick",properties:{variant:"mossy_stonebrick"}}}
:enddata
:endrule

rule:
plugin=vanillaBlocks
number=2
data:
JSON:{blockState:{blockName:"minecraft:double_stone_slab",properties:{seamless:"false",variant:"stone_brick"}}}
:enddata
:endrule

rule:
plugin=vanillaBlocks
number=3
data:
JSON:{blockState:{blockName:"minecraft:stonebrick",properties:{variant:"stonebrick"}}}
:enddata
:endrule

rule:
plugin=vanillaBlocks
number=4
data:
JSON:{blockState:{blockName:"minecraft:cobblestone_wall",properties:{east:"false",south:"false",north:"false",variant:"mossy_cobblestone",west:"false",up:"false"}}}
:enddata
:endrule

rule:
plugin=vanillaBlocks
number=5
data:
JSON:{blockState:{blockName:"minecraft:stone_brick_stairs",properties:{half:"bottom",shape:"straight",facing:"east"}}}
:enddata
:endrule

rule:
plugin=vanillaBlocks
number=6
data:
JSON:{blockState:{blockName:"minecraft:stone_brick_stairs",properties:{half:"bottom",shape:"straight",facing:"west"}}}
:enddata
:endrule

rule:
plugin=vanillaBlocks
number=7
data:
JSON:{blockState:{blockName:"minecraft:cobblestone_wall",properties:{east:"false",south:"false",north:"false",variant:"cobblestone",west:"false",up:"false"}}}
:enddata
:endrule

rule:
plugin=vanillaBlocks
number=8
data:
JSON:{blockState:{blockName:"minecraft:clay"}}
:enddata
:endrule

rule:
plugin=vanillaBlocks
number=9
data:
JSON:{blockState:{blockName:"minecraft:stonebrick",properties:{variant:"cracked_stonebrick"}}}
:enddata
:endrule

rule:
plugin=vanillaBlocks
number=10
data:
JSON:{blockState:{blockName:"minecraft:stone_slab",properties:{half:"top",variant:"stone"}}}
:enddata
:endrule

rule:
plugin=vanillaBlocks
number=11
data:
JSON:{blockState:{blockName:"minecraft:stone_brick_stairs",properties:{half:"bottom",shape:"straight",facing:"north"}}}
:enddata
:endrule

rule:
plugin=vanillaBlocks
number=12
data:
JSON:{blockState:{blockName:"minecraft:stone_brick_stairs",properties:{half:"top",shape:"straight",facing:"north"}}}
:enddata
:endrule

rule:
plugin=vanillaBlocks
number=13
data:
JSON:{blockState:{blockName:"minecraft:stone_brick_stairs",properties:{half:"top",shape:"straight",facing:"south"}}}
:enddata
:endrule

rule:
plugin=vanillaBlocks
number=14
data:
JSON:{blockState:{blockName:"minecraft:stone_brick_stairs",properties:{half:"bottom",shape:"straight",facing:"south"}}}
:enddata
:endrule

rule:
plugin=vanillaBlocks
number=15
data:
JSON:{blockState:{blockName:"minecraft:stone_slab",properties:{half:"bottom",variant:"stone"}}}
:enddata
:endrule

rule:
plugin=vanillaBlocks
number=16
data:
JSON:{blockState:{blockName:"minecraft:double_stone_slab",properties:{seamless:"false",variant:"stone"}}}
:enddata
:endrule

rule:
plugin=vanillaBlocks
number=17
data:
JSON:{blockState:{blockName:"minecraft:stone_slab",properties:{half:"bottom",variant:"stone_brick"}}}
:enddata
:endrule

rule:
plugin=vanillaBlocks
number=18
data:
JSON:{blockState:{blockName:"minecraft:stone_brick_stairs",properties:{half:"top",shape:"straight",facing:"east"}}}
:enddata
:endrule

rule:
plugin=vanillaBlocks
number=19
data:
JSON:{blockState:{blockName:"minecraft:torch",properties:{facing:"south"}}}
:enddata
:endrule

rule:
plugin=vanillaBlocks
number=20
data:
JSON:{blockState:{blockName:"minecraft:torch",properties:{facing:"north"}}}
:enddata
:endrule

rule:
plugin=vanillaBlocks
number=21
data:
JSON:{blockState:{blockName:"minecraft:torch",properties:{facing:"up"}}}
:enddata
:endrule

#### ENTITIES ####
