# Ancient Warfare Structure Template File
# Auto-generated structure template file. created on: 11/20/2014 at: 12:31:26
# Lines beginning with # denote comments

header:
version=2.1
name=wall_straight2
size=16,9,7
offset=15,0,6
:endheader

#### VALIDATION ####
validation:
type=ground
survival=false
worldGenEnabled=false
unique=false
preserveBlocks=false
selectionWeight=0
clusterValue=0
minDuplicateDistance=0
dimensionWhiteList=false
dimensionList=
biomeWhiteList=false
biomeList=
leveling=0
fill=0
border=0
validTargetBlocks=
blockSwap=false
data:
:enddata
:endvalidation

#### LAYERS ####
layer: 0
0,0,0,0,0,0,0,0,0,0,0,0,0,0,0,0
0,0,0,0,0,1,1,1,1,1,1,0,0,0,0,0
0,0,0,0,0,1,0,0,0,0,1,0,0,0,0,0
1,1,1,1,1,1,1,1,1,1,1,1,1,1,1,1
1,0,0,0,0,0,0,0,0,0,0,0,0,0,0,1
1,1,1,1,1,1,1,1,1,1,1,1,1,1,1,1
0,0,0,0,0,1,1,1,1,1,1,0,0,0,0,0
:endlayer
layer: 1
0,0,0,0,0,0,0,0,0,0,0,0,0,0,0,0
0,0,0,0,0,1,1,1,1,1,1,0,0,0,0,0
0,0,0,0,0,1,0,0,0,0,1,0,0,0,0,0
1,1,1,1,1,1,1,1,1,1,1,1,1,1,1,1
1,0,0,0,0,0,0,0,0,0,0,0,0,0,0,1
1,1,1,1,1,1,1,1,1,1,1,1,1,1,1,1
0,0,0,0,0,1,1,1,1,1,1,0,0,0,0,0
:endlayer
layer: 2
0,0,0,0,0,0,0,0,0,0,0,0,0,0,0,0
0,0,0,0,0,1,1,1,1,1,1,0,0,0,0,0
0,0,0,0,0,1,0,0,0,0,1,0,0,0,0,0
1,1,1,1,1,1,1,1,1,1,1,1,1,1,1,1
1,0,0,0,0,0,0,0,0,0,0,0,0,0,0,1
1,1,1,1,1,1,1,1,1,1,1,1,1,1,1,1
0,0,0,0,0,1,1,1,1,1,1,0,0,0,0,0
:endlayer
layer: 3
0,0,0,0,0,0,0,0,0,0,0,0,0,0,0,0
0,0,0,0,0,1,1,1,1,1,1,0,0,0,0,0
0,0,0,0,0,1,0,0,0,0,1,0,0,0,0,0
1,1,1,1,1,1,1,1,1,1,1,1,1,1,1,1
1,0,0,0,0,0,0,0,0,0,0,0,0,0,0,1
1,1,1,1,1,1,1,1,1,1,1,1,1,1,1,1
0,0,0,0,0,1,1,1,1,1,1,0,0,0,0,0
:endlayer
layer: 4
0,0,0,0,0,0,0,0,0,0,0,0,0,0,0,0
0,0,0,0,0,1,1,1,1,1,1,0,0,0,0,0
0,0,0,0,0,1,0,0,0,0,1,0,0,0,0,0
1,1,1,1,1,1,1,1,1,1,1,1,1,1,1,1
1,1,1,1,1,1,1,1,1,1,1,1,1,1,1,1
1,1,1,1,1,1,1,1,1,1,1,1,1,1,1,1
1,1,1,1,1,1,1,1,1,1,1,1,1,1,1,1
:endlayer
layer: 5
0,0,0,0,0,0,0,0,0,0,0,0,0,0,0,0
0,0,0,0,0,1,1,1,1,1,1,0,0,0,0,0
0,0,0,0,0,1,0,0,0,0,1,0,0,0,0,0
1,1,1,1,1,1,1,1,1,1,1,1,1,1,1,1
0,0,0,0,0,1,0,0,0,0,1,0,0,0,0,0
0,0,0,0,0,1,0,0,0,0,1,0,0,0,0,0
1,0,1,0,1,1,1,1,1,1,1,0,1,0,1,0
:endlayer
layer: 6
0,0,0,0,0,0,0,0,0,0,0,0,0,0,0,0
0,0,0,0,0,1,1,1,1,1,1,0,0,0,0,0
0,0,0,0,0,1,0,0,0,0,1,0,0,0,0,0
0,0,0,0,0,1,0,0,0,0,1,0,0,0,0,0
0,0,0,0,0,1,0,0,0,0,1,0,0,0,0,0
0,0,0,0,0,1,0,0,0,0,1,0,0,0,0,0
0,0,0,0,0,1,1,1,1,1,1,0,0,0,0,0
:endlayer
layer: 7
0,0,0,0,0,0,0,0,0,0,0,0,0,0,0,0
0,0,0,0,0,1,1,1,1,1,1,0,0,0,0,0
0,0,0,0,0,1,0,0,0,0,1,0,0,0,0,0
0,0,0,0,0,1,0,0,0,0,1,0,0,0,0,0
0,0,0,0,0,1,0,0,0,0,1,0,0,0,0,0
0,0,0,0,0,1,0,0,0,0,1,0,0,0,0,0
0,0,0,0,0,1,1,1,1,1,1,0,0,0,0,0
:endlayer
layer: 8
0,0,0,0,0,0,0,0,0,0,0,0,0,0,0,0
0,0,0,0,0,1,0,1,0,1,0,0,0,0,0,0
0,0,0,0,0,0,0,0,0,0,1,0,0,0,0,0
0,0,0,0,0,1,0,0,0,0,0,0,0,0,0,0
0,0,0,0,0,0,0,0,0,0,1,0,0,0,0,0
0,0,0,0,0,1,0,0,0,0,0,0,0,0,0,0
0,0,0,0,0,0,1,0,1,0,1,0,0,0,0,0
:endlayer

#### RULES ####
rule:
plugin=vanillaBlocks
number=1
data:
JSON:{{"val":{"blockName":{"val":"minecraft:stonebrick","id":"ss"},"meta":{"val":"0","id":"pi"},"buildPass":{"val":"0","id":"pi"}},"id":"ct"}}
:enddata
:endrule

#### ENTITIES ####
