# Ancient Warfare Structure Template File
# Auto-generated structure template file. created on: 11/25/2014 at: 20:12:51
# Lines beginning with # denote comments

header:
version=2.1
name=TownBlocksSingleHouse1
size=17,25,17
offset=10,2,13
:endheader

#### VALIDATION ####
validation:
type=ground
survival=false
worldGenEnabled=false
unique=false
preserveBlocks=false
selectionWeight=0
clusterValue=0
minDuplicateDistance=0
dimensionWhiteList=false
dimensionList=
biomeWhiteList=false
biomeList=
leveling=0
fill=0
border=0
validTargetBlocks=
blockSwap=false
data:
:enddata
:endvalidation

#### LAYERS ####
layer: 0
1,1,1,1,1,1,1,1,1,1,1,1,1,1,1,1,1
1,2,2,2,2,2,2,2,2,2,2,2,2,2,2,2,1
1,2,2,2,2,2,2,2,2,2,2,2,2,2,2,2,1
1,2,2,2,2,2,2,2,2,2,2,2,2,2,2,2,1
1,2,2,2,2,2,2,2,2,2,2,2,2,2,2,2,1
1,2,2,2,2,2,2,2,2,2,2,2,2,2,2,2,1
1,2,2,2,2,2,2,2,2,2,2,2,2,2,2,2,1
1,2,2,2,2,2,2,2,2,2,2,2,2,2,2,2,1
1,2,2,2,2,2,2,2,2,2,2,2,2,2,2,2,1
1,2,2,2,2,2,2,2,2,2,2,2,2,2,2,2,1
1,2,2,2,2,2,2,2,2,2,2,2,2,2,2,2,1
1,2,2,2,2,2,2,2,2,2,2,2,2,2,2,2,1
1,2,2,2,2,2,2,2,2,2,2,2,2,2,2,2,1
1,2,2,2,2,2,2,2,2,2,2,2,2,2,2,2,1
1,2,2,2,2,2,2,2,2,2,2,2,2,2,2,2,1
1,2,2,2,2,2,2,2,2,2,2,2,2,2,2,2,1
1,1,1,1,1,1,1,1,1,1,1,1,1,1,1,1,1
:endlayer
layer: 1
4,4,4,4,4,4,4,4,4,4,4,4,4,4,4,4,4
4,4,4,4,4,4,4,4,4,4,4,4,4,4,4,4,4
4,4,4,4,4,4,4,4,4,4,4,4,4,4,4,4,4
4,4,4,1,1,1,1,1,1,1,1,1,1,1,4,4,4
4,4,4,1,1,1,1,1,1,1,1,1,1,1,4,4,4
4,4,4,1,1,1,1,1,1,1,1,1,1,1,4,4,4
4,4,4,1,1,1,1,1,1,1,1,1,1,1,4,4,4
4,4,4,1,1,1,1,1,1,1,1,1,1,1,4,4,4
4,4,4,1,1,1,1,1,1,1,1,1,1,1,4,4,4
4,4,4,1,1,1,1,1,1,4,4,3,4,4,4,4,4
4,4,4,1,1,1,1,1,1,4,4,3,4,4,4,4,4
4,4,4,1,1,1,1,1,1,4,4,3,4,4,4,4,4
4,4,4,1,1,1,1,1,1,4,4,3,4,4,4,4,4
4,4,4,1,1,1,1,1,1,4,4,3,4,4,4,4,4
3,3,3,3,3,3,3,3,3,3,3,3,3,3,3,3,3
3,3,3,3,3,3,3,3,3,3,3,3,3,3,3,3,3
3,3,3,3,3,3,3,3,3,3,3,3,3,3,3,3,3
:endlayer
layer: 2
0,0,0,0,0,0,0,0,0,0,0,0,0,0,0,0,0
0,0,0,0,0,0,0,0,0,0,0,0,0,0,0,0,0
0,0,0,0,0,0,0,0,0,0,0,0,0,0,0,0,0
0,0,0,7,7,7,7,7,7,7,7,7,7,7,0,0,0
0,0,0,7,8,8,8,8,8,8,8,8,8,7,0,0,0
0,0,0,7,8,8,8,8,8,8,8,8,8,7,0,0,0
0,0,0,7,8,8,8,8,8,8,8,8,8,7,0,0,0
0,0,0,7,8,8,8,8,8,8,8,8,8,7,0,0,0
0,0,0,7,8,8,8,8,7,7,7,10,7,7,0,0,0
0,0,0,7,8,8,8,8,7,0,0,9,0,5,0,0,0
0,0,0,7,8,8,8,8,7,0,0,0,0,5,0,0,0
0,0,0,7,8,8,8,8,7,0,0,0,0,5,0,0,0
0,0,0,7,8,8,8,8,7,0,0,0,0,5,0,0,0
0,0,0,7,7,7,7,7,7,5,5,6,5,5,0,0,0
0,0,0,0,0,0,0,0,0,0,0,0,0,0,0,0,0
0,0,0,0,0,0,0,0,0,0,0,0,0,0,0,0,0
0,0,0,0,0,0,0,0,0,0,0,0,0,0,0,0,0
:endlayer
layer: 3
0,0,0,0,0,0,0,0,0,0,0,0,0,0,0,0,0
0,0,0,0,0,0,0,0,0,0,0,0,0,0,0,0,0
0,0,0,0,0,0,0,0,0,0,0,0,0,0,0,0,0
0,0,0,7,10,10,10,10,7,10,10,10,10,7,0,0,0
0,0,0,10,0,0,0,0,0,0,0,0,0,10,0,0,0
0,0,0,10,0,0,0,0,0,0,0,0,0,10,0,0,0
0,0,0,10,0,0,0,0,0,0,0,0,0,10,0,0,0
0,0,0,10,0,0,0,0,0,0,0,0,0,10,0,0,0
0,0,0,7,15,0,0,0,7,10,10,14,10,7,0,0,0
0,0,0,10,8,0,0,0,10,0,0,0,0,0,0,0,0
0,0,0,10,0,0,0,0,10,0,0,0,0,0,0,0,0
0,0,0,10,13,0,0,0,10,0,0,0,0,0,0,0,0
0,0,0,10,0,0,12,0,10,0,0,0,0,0,0,0,0
0,0,0,7,10,10,10,10,7,0,0,0,0,11,0,0,0
0,0,0,0,0,0,0,0,0,0,0,0,0,0,0,0,0
0,0,0,0,0,0,0,0,0,0,0,0,0,0,0,0,0
0,0,0,0,0,0,0,0,0,0,0,0,0,0,0,0,0
:endlayer
layer: 4
0,0,0,0,0,0,0,0,0,0,0,0,0,0,0,0,0
0,0,0,0,0,0,0,0,0,0,0,0,0,0,0,0,0
0,0,0,0,0,0,0,0,0,0,0,0,0,0,0,0,0
0,0,0,7,10,10,10,10,7,10,10,10,10,7,0,0,0
0,0,0,10,0,0,0,0,0,0,0,0,0,10,0,0,0
0,0,0,10,0,0,0,0,0,0,0,0,0,10,0,0,0
0,0,0,10,0,0,0,0,0,0,0,0,0,10,0,0,0
0,0,0,10,0,0,0,0,0,0,0,0,0,10,0,0,0
0,0,0,7,0,0,0,0,7,10,10,19,10,7,0,0,0
0,0,0,10,15,0,0,0,10,0,0,0,0,0,0,0,0
0,0,0,10,18,0,0,0,10,0,0,0,0,0,0,0,0
0,0,0,10,17,0,0,0,10,0,0,0,0,0,0,0,0
0,0,0,10,16,0,0,0,10,0,0,0,0,0,0,0,0
0,0,0,7,10,10,10,10,7,0,0,0,0,0,0,0,0
0,0,0,0,0,0,0,0,0,0,0,0,0,0,0,0,0
0,0,0,0,0,0,0,0,0,0,0,0,0,0,0,0,0
0,0,0,0,0,0,0,0,0,0,0,0,0,0,0,0,0
:endlayer
layer: 5
0,0,0,0,0,0,0,0,0,0,0,0,0,0,0,0,0
0,0,0,0,0,0,0,0,0,0,0,0,0,0,0,0,0
0,0,0,23,0,0,0,0,0,0,0,0,0,23,0,0,0
0,0,21,7,10,10,10,10,7,10,10,10,10,7,22,0,0
0,0,0,10,0,0,0,0,0,0,0,0,0,10,0,0,0
0,0,0,10,0,0,0,0,0,0,0,0,0,10,0,0,0
0,0,0,10,0,0,0,0,0,0,0,0,0,10,0,0,0
0,0,0,10,0,0,0,0,0,0,0,0,0,10,0,0,0
0,0,0,7,0,0,0,0,7,10,10,10,10,7,22,0,0
0,0,0,10,0,0,0,0,10,0,0,20,0,20,0,0,0
0,0,0,10,15,0,0,0,10,0,0,0,0,0,0,0,0
0,0,0,10,8,0,0,0,10,0,0,0,0,0,0,0,0
0,0,0,10,8,0,0,0,10,0,0,0,0,0,0,0,0
0,0,21,7,10,10,10,10,7,0,0,0,0,0,0,0,0
0,0,0,20,0,0,0,0,0,0,0,0,0,0,0,0,0
0,0,0,0,0,0,0,0,0,0,0,0,0,0,0,0,0
0,0,0,0,0,0,0,0,0,0,0,0,0,0,0,0,0
:endlayer
layer: 6
0,0,0,0,0,0,0,0,0,0,0,0,0,0,0,0,0
0,0,0,0,0,0,0,0,0,0,0,0,0,0,0,0,0
0,0,5,7,5,5,5,5,7,5,5,5,5,7,5,0,0
0,0,7,7,7,7,7,7,7,7,7,7,7,7,7,0,0
0,0,5,7,22,0,0,0,7,0,0,0,21,7,5,0,0
0,0,5,7,0,0,0,0,7,0,0,0,0,7,5,0,0
0,0,5,7,0,0,0,0,7,0,0,0,0,7,5,0,0
0,0,5,7,22,0,0,0,7,0,0,0,21,7,5,0,0
0,0,7,7,0,0,0,0,7,7,7,7,7,7,7,0,0
0,0,5,7,0,0,0,0,7,7,5,5,5,7,5,0,0
0,0,5,7,0,0,0,0,7,5,0,0,0,0,0,0,0
0,0,5,7,15,0,0,0,7,5,0,0,0,0,0,0,0
0,0,5,7,8,0,0,23,7,5,0,0,0,0,0,0,0
0,0,7,7,7,7,7,7,7,7,0,0,0,0,0,0,0
0,0,5,7,5,5,5,5,7,5,0,0,0,0,0,0,0
0,0,0,0,0,0,0,0,0,0,0,0,0,0,0,0,0
0,0,0,0,0,0,0,0,0,0,0,0,0,0,0,0,0
:endlayer
layer: 7
0,0,0,0,0,0,0,0,0,0,0,0,0,0,0,0,0
0,0,0,0,0,0,0,0,0,0,0,0,0,0,0,0,0
0,0,5,7,7,7,7,7,7,7,7,7,7,7,5,0,0
0,0,7,8,8,8,8,8,8,8,8,8,8,8,7,0,0
0,0,7,8,8,8,8,8,8,8,8,8,8,8,7,0,0
0,0,7,8,8,8,8,8,8,8,8,8,8,8,7,0,0
0,0,7,8,8,8,8,8,8,8,8,8,8,8,7,0,0
0,0,7,8,8,8,8,8,8,8,8,8,8,8,7,0,0
0,0,7,8,8,8,8,8,8,8,8,8,8,8,7,0,0
0,0,7,8,0,8,8,8,8,7,7,7,7,7,5,0,0
0,0,7,8,0,8,8,8,8,7,0,0,0,0,0,0,0
0,0,7,8,0,8,8,8,8,7,0,0,0,0,0,0,0
0,0,7,8,15,8,8,8,8,7,0,0,0,0,0,0,0
0,0,7,8,8,8,8,8,8,7,0,0,0,0,0,0,0
0,0,5,7,7,7,7,7,7,5,0,0,0,0,0,0,0
0,0,0,0,0,0,0,0,0,0,0,0,0,0,0,0,0
0,0,0,0,0,0,0,0,0,0,0,0,0,0,0,0,0
:endlayer
layer: 8
0,0,0,0,0,0,0,0,0,0,0,0,0,0,0,0,0
0,0,0,0,0,0,0,0,0,0,0,0,0,0,0,0,0
0,0,5,7,8,24,24,8,7,8,24,24,8,7,5,0,0
0,0,7,0,0,0,0,0,0,0,0,0,0,0,7,0,0
0,0,8,0,0,0,0,0,0,0,0,0,0,0,8,0,0
0,0,24,0,0,0,0,0,0,0,26,25,0,0,24,0,0
0,0,24,0,0,0,0,0,0,0,26,25,0,0,24,0,0
0,0,8,0,0,0,0,0,0,0,0,0,0,0,8,0,0
0,0,7,0,0,0,0,0,0,0,0,0,0,0,7,0,0
0,0,8,0,0,0,0,0,0,7,8,24,8,7,5,0,0
0,0,24,0,0,0,0,0,0,8,0,0,0,0,0,0,0
0,0,24,0,0,0,0,0,0,24,0,0,0,0,0,0,0
0,0,8,0,0,0,0,0,0,8,0,0,0,0,0,0,0
0,0,7,0,0,0,0,0,0,7,0,0,0,0,0,0,0
0,0,5,7,8,24,24,8,7,5,0,0,0,0,0,0,0
0,0,0,0,0,0,0,0,0,0,0,0,0,0,0,0,0
0,0,0,0,0,0,0,0,0,0,0,0,0,0,0,0,0
:endlayer
layer: 9
0,0,0,0,0,0,0,0,0,0,0,0,0,0,0,0,0
0,0,0,0,0,0,0,0,0,0,0,0,0,0,0,0,0
0,0,5,7,8,24,24,8,7,8,24,24,8,7,5,0,0
0,0,7,0,0,0,0,0,0,0,0,0,0,0,7,0,0
0,0,8,0,0,0,0,0,0,0,0,0,0,0,8,0,0
0,0,24,0,0,0,0,0,0,0,0,0,0,0,24,0,0
0,0,24,0,0,0,0,0,0,0,0,0,0,0,24,0,0
0,0,8,0,0,0,0,0,0,0,0,0,0,0,8,0,0
0,0,7,0,0,0,0,0,0,0,0,0,0,0,7,0,0
0,0,8,0,0,0,0,0,0,7,8,24,8,7,5,0,0
0,0,24,0,0,0,0,0,0,8,0,0,0,0,0,0,0
0,0,24,0,0,0,0,0,0,24,0,0,0,0,0,0,0
0,0,8,0,0,0,0,0,0,8,0,0,0,0,0,0,0
0,0,7,0,0,0,0,0,0,7,0,0,0,0,0,0,0
0,0,5,7,8,24,24,8,7,5,0,0,0,0,0,0,0
0,0,0,0,0,0,0,0,0,0,0,0,0,0,0,0,0
0,0,0,0,0,0,0,0,0,0,0,0,0,0,0,0,0
:endlayer
layer: 10
0,0,0,0,0,0,0,0,0,0,0,0,0,0,0,0,0
0,0,0,0,0,0,0,0,0,0,0,0,0,0,0,0,0
0,0,5,7,8,24,24,8,7,8,24,24,8,7,5,0,0
0,0,7,0,0,0,0,0,0,0,0,0,0,0,7,0,0
0,0,8,0,0,0,0,0,0,0,0,0,0,0,8,0,0
0,0,24,0,0,0,0,0,0,0,0,0,0,0,24,0,0
0,0,24,0,0,0,0,0,0,0,0,0,0,0,24,0,0
0,0,8,0,0,0,0,0,0,0,0,0,0,0,8,0,0
0,0,7,0,0,0,0,0,0,0,0,0,0,0,7,0,0
0,0,8,0,0,0,0,0,0,7,8,24,8,7,5,0,0
0,0,24,0,0,0,0,0,0,8,0,0,0,0,0,0,0
0,0,24,0,0,0,0,0,0,24,0,0,0,0,0,0,0
0,0,8,0,0,0,0,0,0,8,0,0,0,0,0,0,0
0,0,7,0,0,0,0,0,0,7,0,0,0,0,0,0,0
0,0,5,7,8,24,24,8,7,5,0,0,0,0,0,0,0
0,0,0,0,0,0,0,0,0,0,0,0,0,0,0,0,0
0,0,0,0,0,0,0,0,0,0,0,0,0,0,0,0,0
:endlayer
layer: 11
0,0,0,0,0,0,0,0,0,0,0,0,0,0,0,0,0
0,28,15,15,15,15,15,15,15,15,15,15,15,15,15,15,0
0,31,7,7,7,7,7,7,7,7,7,7,7,7,7,28,0
0,31,7,0,0,0,0,0,0,0,0,0,0,0,7,28,0
0,31,7,0,0,0,0,0,0,0,0,0,0,0,7,29,0
0,31,7,0,0,0,0,0,0,0,0,0,0,0,7,27,0
0,31,7,0,0,0,0,0,0,0,0,0,0,0,7,27,0
0,31,7,0,0,0,0,0,0,0,0,0,0,0,7,29,0
0,31,7,0,0,0,0,0,0,0,0,0,0,0,7,28,0
0,31,7,0,0,0,0,0,0,7,7,7,7,7,7,28,0
0,31,7,0,0,0,0,0,0,7,29,30,30,30,30,30,0
0,31,7,0,0,0,0,0,0,7,27,0,0,0,0,0,0
0,31,7,0,0,0,0,0,0,7,27,0,0,0,0,0,0
0,31,7,0,0,0,0,0,0,7,27,0,0,0,0,0,0
0,31,7,7,7,7,7,7,7,7,27,0,0,0,0,0,0
0,31,28,28,29,30,30,29,28,28,27,0,0,0,0,0,0
0,0,0,0,0,0,0,0,0,0,0,0,0,0,0,0,0
:endlayer
layer: 12
0,0,0,0,0,0,0,0,0,0,0,0,0,0,0,0,0
0,0,0,0,0,0,0,0,0,0,0,0,0,0,0,0,0
0,0,28,15,15,15,15,15,15,15,15,15,15,15,15,15,0
0,0,31,0,0,0,0,0,0,0,0,0,0,0,7,0,0
0,0,31,0,0,0,0,0,0,0,0,0,0,0,8,5,0
0,0,31,0,0,0,0,0,0,0,0,0,0,0,24,0,0
0,0,31,0,0,0,0,0,0,0,0,0,0,0,24,0,0
0,0,31,0,0,0,0,0,0,0,0,0,0,0,8,5,0
0,0,31,0,0,0,0,0,0,0,0,0,0,0,7,0,0
0,0,31,0,0,0,0,0,0,29,30,30,30,30,30,30,0
0,0,31,0,0,0,0,0,0,27,0,0,0,0,0,0,0
0,0,31,0,0,0,0,0,0,27,0,0,0,0,0,0,0
0,0,31,0,0,0,0,0,0,27,0,0,0,0,0,0,0
0,0,31,0,0,0,0,0,0,27,0,0,0,0,0,0,0
0,0,31,7,8,24,24,8,7,27,0,0,0,0,0,0,0
0,0,31,0,5,0,0,5,0,27,0,0,0,0,0,0,0
0,0,0,0,0,0,0,0,0,0,0,0,0,0,0,0,0
:endlayer
layer: 13
0,0,0,0,0,0,0,0,0,0,0,0,0,0,0,0,0
0,0,0,0,0,0,0,0,0,0,0,0,0,0,0,0,0
0,0,0,0,0,0,0,0,0,0,0,0,0,0,0,0,0
0,0,0,28,15,15,15,15,15,15,15,15,15,15,15,15,0
0,0,0,31,0,0,0,0,0,0,0,0,0,0,7,5,0
0,0,0,31,0,0,0,0,0,0,0,0,0,0,24,0,0
0,0,0,31,0,0,0,0,0,0,0,0,0,0,24,0,0
0,0,0,31,0,0,0,0,0,0,0,0,0,0,7,5,0
0,0,0,31,0,0,0,0,29,30,30,30,30,30,30,30,0
0,0,0,31,0,0,0,0,27,0,0,0,0,0,0,0,0
0,0,0,31,0,0,0,0,27,0,0,0,0,0,0,0,0
0,0,0,31,0,0,0,0,27,0,0,0,0,0,0,0,0
0,0,0,31,0,0,0,0,27,0,0,0,0,0,0,0,0
0,0,0,31,0,0,0,0,27,0,0,0,0,0,0,0,0
0,0,0,31,7,24,24,7,27,0,0,0,0,0,0,0,0
0,0,0,31,5,0,0,5,27,0,0,0,0,0,0,0,0
0,0,0,0,0,0,0,0,0,0,0,0,0,0,0,0,0
:endlayer
layer: 14
0,0,0,0,0,0,0,0,0,0,0,0,0,0,0,0,0
0,0,0,0,0,0,0,0,0,0,0,0,0,0,0,0,0
0,0,0,0,0,0,0,0,0,0,0,0,0,0,0,0,0
0,0,0,0,0,0,0,0,0,0,0,0,0,0,0,0,0
0,0,0,0,28,15,15,15,15,15,15,15,15,15,15,15,0
0,0,0,0,31,0,0,0,0,0,0,0,0,0,7,0,0
0,0,0,0,31,0,0,0,0,0,0,0,0,0,7,0,0
0,0,0,0,31,0,0,29,30,30,30,30,30,30,30,30,0
0,0,0,0,31,0,0,27,0,0,0,0,0,0,0,0,0
0,0,0,0,31,0,0,27,0,0,0,0,0,0,0,0,0
0,0,0,0,31,0,0,27,0,0,0,0,0,0,0,0,0
0,0,0,0,31,0,0,27,0,0,0,0,0,0,0,0,0
0,0,0,0,31,0,0,27,0,0,0,0,0,0,0,0,0
0,0,0,0,31,0,0,27,0,0,0,0,0,0,0,0,0
0,0,0,0,31,7,7,27,0,0,0,0,0,0,0,0,0
0,0,0,0,31,0,0,27,0,0,0,0,0,0,0,0,0
0,0,0,0,0,0,0,0,0,0,0,0,0,0,0,0,0
:endlayer
layer: 15
0,0,0,0,0,0,0,0,0,0,0,0,0,0,0,0,0
0,0,0,0,0,0,0,0,0,0,0,0,0,0,0,0,0
0,0,0,0,0,0,0,0,0,0,0,0,0,0,0,0,0
0,0,0,0,0,0,0,0,0,0,0,0,0,0,0,0,0
0,0,0,0,0,0,0,0,0,0,0,0,0,0,0,0,0
0,0,0,0,0,28,15,15,15,15,15,15,15,15,15,28,0
0,0,0,0,0,31,32,30,30,30,30,30,30,30,30,28,0
0,0,0,0,0,31,27,0,0,0,0,0,0,0,0,0,0
0,0,0,0,0,31,27,0,0,0,0,0,0,0,0,0,0
0,0,0,0,0,31,27,0,0,0,0,0,0,0,0,0,0
0,0,0,0,0,31,27,0,0,0,0,0,0,0,0,0,0
0,0,0,0,0,31,27,0,0,0,0,0,0,0,0,0,0
0,0,0,0,0,31,27,0,0,0,0,0,0,0,0,0,0
0,0,0,0,0,31,27,0,0,0,0,0,0,0,0,0,0
0,0,0,0,0,31,27,0,0,0,0,0,0,0,0,0,0
0,0,0,0,0,28,28,0,0,0,0,0,0,0,0,0,0
0,0,0,0,0,0,0,0,0,0,0,0,0,0,0,0,0
:endlayer
layer: 16
0,0,0,0,0,0,0,0,0,0,0,0,0,0,0,0,0
0,0,0,0,0,0,0,0,0,0,0,0,0,0,0,0,0
0,0,0,0,0,0,0,0,0,0,0,0,0,0,0,0,0
0,0,0,0,0,0,0,0,0,0,0,0,0,0,0,0,0
0,0,0,0,0,0,0,0,0,0,0,0,0,0,0,0,0
0,0,0,0,0,0,0,0,0,0,0,0,0,0,0,0,0
0,0,0,0,0,0,0,0,0,0,0,0,0,0,0,0,0
0,0,0,0,0,0,0,0,0,0,0,0,0,0,0,0,0
0,0,0,0,0,0,0,0,0,0,0,0,0,0,0,0,0
0,0,0,0,0,0,0,0,0,0,0,0,0,0,0,0,0
0,0,0,0,0,0,0,0,0,0,0,0,0,0,0,0,0
0,0,0,0,0,0,0,0,0,0,0,0,0,0,0,0,0
0,0,0,0,0,0,0,0,0,0,0,0,0,0,0,0,0
0,0,0,0,0,0,0,0,0,0,0,0,0,0,0,0,0
0,0,0,0,0,0,0,0,0,0,0,0,0,0,0,0,0
0,0,0,0,0,0,0,0,0,0,0,0,0,0,0,0,0
0,0,0,0,0,0,0,0,0,0,0,0,0,0,0,0,0
:endlayer
layer: 17
0,0,0,0,0,0,0,0,0,0,0,0,0,0,0,0,0
0,0,0,0,0,0,0,0,0,0,0,0,0,0,0,0,0
0,0,0,0,0,0,0,0,0,0,0,0,0,0,0,0,0
0,0,0,0,0,0,0,0,0,0,0,0,0,0,0,0,0
0,0,0,0,0,0,0,0,0,0,0,0,0,0,0,0,0
0,0,0,0,0,0,0,0,0,0,0,0,0,0,0,0,0
0,0,0,0,0,0,0,0,0,0,0,0,0,0,0,0,0
0,0,0,0,0,0,0,0,0,0,0,0,0,0,0,0,0
0,0,0,0,0,0,0,0,0,0,0,0,0,0,0,0,0
0,0,0,0,0,0,0,0,0,0,0,0,0,0,0,0,0
0,0,0,0,0,0,0,0,0,0,0,0,0,0,0,0,0
0,0,0,0,0,0,0,0,0,0,0,0,0,0,0,0,0
0,0,0,0,0,0,0,0,0,0,0,0,0,0,0,0,0
0,0,0,0,0,0,0,0,0,0,0,0,0,0,0,0,0
0,0,0,0,0,0,0,0,0,0,0,0,0,0,0,0,0
0,0,0,0,0,0,0,0,0,0,0,0,0,0,0,0,0
0,0,0,0,0,0,0,0,0,0,0,0,0,0,0,0,0
:endlayer
layer: 18
0,0,0,0,0,0,0,0,0,0,0,0,0,0,0,0,0
0,0,0,0,0,0,0,0,0,0,0,0,0,0,0,0,0
0,0,0,0,0,0,0,0,0,0,0,0,0,0,0,0,0
0,0,0,0,0,0,0,0,0,0,0,0,0,0,0,0,0
0,0,0,0,0,0,0,0,0,0,0,0,0,0,0,0,0
0,0,0,0,0,0,0,0,0,0,0,0,0,0,0,0,0
0,0,0,0,0,0,0,0,0,0,0,0,0,0,0,0,0
0,0,0,0,0,0,0,0,0,0,0,0,0,0,0,0,0
0,0,0,0,0,0,0,0,0,0,0,0,0,0,0,0,0
0,0,0,0,0,0,0,0,0,0,0,0,0,0,0,0,0
0,0,0,0,0,0,0,0,0,0,0,0,0,0,0,0,0
0,0,0,0,0,0,0,0,0,0,0,0,0,0,0,0,0
0,0,0,0,0,0,0,0,0,0,0,0,0,0,0,0,0
0,0,0,0,0,0,0,0,0,0,0,0,0,0,0,0,0
0,0,0,0,0,0,0,0,0,0,0,0,0,0,0,0,0
0,0,0,0,0,0,0,0,0,0,0,0,0,0,0,0,0
0,0,0,0,0,0,0,0,0,0,0,0,0,0,0,0,0
:endlayer
layer: 19
0,0,0,0,0,0,0,0,0,0,0,0,0,0,0,0,0
0,0,0,0,0,0,0,0,0,0,0,0,0,0,0,0,0
0,0,0,0,0,0,0,0,0,0,0,0,0,0,0,0,0
0,0,0,0,0,0,0,0,0,0,0,0,0,0,0,0,0
0,0,0,0,0,0,0,0,0,0,0,0,0,0,0,0,0
0,0,0,0,0,0,0,0,0,0,0,0,0,0,0,0,0
0,0,0,0,0,0,0,0,0,0,0,0,0,0,0,0,0
0,0,0,0,0,0,0,0,0,0,0,0,0,0,0,0,0
0,0,0,0,0,0,0,0,0,0,0,0,0,0,0,0,0
0,0,0,0,0,0,0,0,0,0,0,0,0,0,0,0,0
0,0,0,0,0,0,0,0,0,0,0,0,0,0,0,0,0
0,0,0,0,0,0,0,0,0,0,0,0,0,0,0,0,0
0,0,0,0,0,0,0,0,0,0,0,0,0,0,0,0,0
0,0,0,0,0,0,0,0,0,0,0,0,0,0,0,0,0
0,0,0,0,0,0,0,0,0,0,0,0,0,0,0,0,0
0,0,0,0,0,0,0,0,0,0,0,0,0,0,0,0,0
0,0,0,0,0,0,0,0,0,0,0,0,0,0,0,0,0
:endlayer
layer: 20
0,0,0,0,0,0,0,0,0,0,0,0,0,0,0,0,0
0,0,0,0,0,0,0,0,0,0,0,0,0,0,0,0,0
0,0,0,0,0,0,0,0,0,0,0,0,0,0,0,0,0
0,0,0,0,0,0,0,0,0,0,0,0,0,0,0,0,0
0,0,0,0,0,0,0,0,0,0,0,0,0,0,0,0,0
0,0,0,0,0,0,0,0,0,0,0,0,0,0,0,0,0
0,0,0,0,0,0,0,0,0,0,0,0,0,0,0,0,0
0,0,0,0,0,0,0,0,0,0,0,0,0,0,0,0,0
0,0,0,0,0,0,0,0,0,0,0,0,0,0,0,0,0
0,0,0,0,0,0,0,0,0,0,0,0,0,0,0,0,0
0,0,0,0,0,0,0,0,0,0,0,0,0,0,0,0,0
0,0,0,0,0,0,0,0,0,0,0,0,0,0,0,0,0
0,0,0,0,0,0,0,0,0,0,0,0,0,0,0,0,0
0,0,0,0,0,0,0,0,0,0,0,0,0,0,0,0,0
0,0,0,0,0,0,0,0,0,0,0,0,0,0,0,0,0
0,0,0,0,0,0,0,0,0,0,0,0,0,0,0,0,0
0,0,0,0,0,0,0,0,0,0,0,0,0,0,0,0,0
:endlayer
layer: 21
0,0,0,0,0,0,0,0,0,0,0,0,0,0,0,0,0
0,0,0,0,0,0,0,0,0,0,0,0,0,0,0,0,0
0,0,0,0,0,0,0,0,0,0,0,0,0,0,0,0,0
0,0,0,0,0,0,0,0,0,0,0,0,0,0,0,0,0
0,0,0,0,0,0,0,0,0,0,0,0,0,0,0,0,0
0,0,0,0,0,0,0,0,0,0,0,0,0,0,0,0,0
0,0,0,0,0,0,0,0,0,0,0,0,0,0,0,0,0
0,0,0,0,0,0,0,0,0,0,0,0,0,0,0,0,0
0,0,0,0,0,0,0,0,0,0,0,0,0,0,0,0,0
0,0,0,0,0,0,0,0,0,0,0,0,0,0,0,0,0
0,0,0,0,0,0,0,0,0,0,0,0,0,0,0,0,0
0,0,0,0,0,0,0,0,0,0,0,0,0,0,0,0,0
0,0,0,0,0,0,0,0,0,0,0,0,0,0,0,0,0
0,0,0,0,0,0,0,0,0,0,0,0,0,0,0,0,0
0,0,0,0,0,0,0,0,0,0,0,0,0,0,0,0,0
0,0,0,0,0,0,0,0,0,0,0,0,0,0,0,0,0
0,0,0,0,0,0,0,0,0,0,0,0,0,0,0,0,0
:endlayer
layer: 22
0,0,0,0,0,0,0,0,0,0,0,0,0,0,0,0,0
0,0,0,0,0,0,0,0,0,0,0,0,0,0,0,0,0
0,0,0,0,0,0,0,0,0,0,0,0,0,0,0,0,0
0,0,0,0,0,0,0,0,0,0,0,0,0,0,0,0,0
0,0,0,0,0,0,0,0,0,0,0,0,0,0,0,0,0
0,0,0,0,0,0,0,0,0,0,0,0,0,0,0,0,0
0,0,0,0,0,0,0,0,0,0,0,0,0,0,0,0,0
0,0,0,0,0,0,0,0,0,0,0,0,0,0,0,0,0
0,0,0,0,0,0,0,0,0,0,0,0,0,0,0,0,0
0,0,0,0,0,0,0,0,0,0,0,0,0,0,0,0,0
0,0,0,0,0,0,0,0,0,0,0,0,0,0,0,0,0
0,0,0,0,0,0,0,0,0,0,0,0,0,0,0,0,0
0,0,0,0,0,0,0,0,0,0,0,0,0,0,0,0,0
0,0,0,0,0,0,0,0,0,0,0,0,0,0,0,0,0
0,0,0,0,0,0,0,0,0,0,0,0,0,0,0,0,0
0,0,0,0,0,0,0,0,0,0,0,0,0,0,0,0,0
0,0,0,0,0,0,0,0,0,0,0,0,0,0,0,0,0
:endlayer
layer: 23
0,0,0,0,0,0,0,0,0,0,0,0,0,0,0,0,0
0,0,0,0,0,0,0,0,0,0,0,0,0,0,0,0,0
0,0,0,0,0,0,0,0,0,0,0,0,0,0,0,0,0
0,0,0,0,0,0,0,0,0,0,0,0,0,0,0,0,0
0,0,0,0,0,0,0,0,0,0,0,0,0,0,0,0,0
0,0,0,0,0,0,0,0,0,0,0,0,0,0,0,0,0
0,0,0,0,0,0,0,0,0,0,0,0,0,0,0,0,0
0,0,0,0,0,0,0,0,0,0,0,0,0,0,0,0,0
0,0,0,0,0,0,0,0,0,0,0,0,0,0,0,0,0
0,0,0,0,0,0,0,0,0,0,0,0,0,0,0,0,0
0,0,0,0,0,0,0,0,0,0,0,0,0,0,0,0,0
0,0,0,0,0,0,0,0,0,0,0,0,0,0,0,0,0
0,0,0,0,0,0,0,0,0,0,0,0,0,0,0,0,0
0,0,0,0,0,0,0,0,0,0,0,0,0,0,0,0,0
0,0,0,0,0,0,0,0,0,0,0,0,0,0,0,0,0
0,0,0,0,0,0,0,0,0,0,0,0,0,0,0,0,0
0,0,0,0,0,0,0,0,0,0,0,0,0,0,0,0,0
:endlayer
layer: 24
0,0,0,0,0,0,0,0,0,0,0,0,0,0,0,0,0
0,0,0,0,0,0,0,0,0,0,0,0,0,0,0,0,0
0,0,0,0,0,0,0,0,0,0,0,0,0,0,0,0,0
0,0,0,0,0,0,0,0,0,0,0,0,0,0,0,0,0
0,0,0,0,0,0,0,0,0,0,0,0,0,0,0,0,0
0,0,0,0,0,0,0,0,0,0,0,0,0,0,0,0,0
0,0,0,0,0,0,0,0,0,0,0,0,0,0,0,0,0
0,0,0,0,0,0,0,0,0,0,0,0,0,0,0,0,0
0,0,0,0,0,0,0,0,0,0,0,0,0,0,0,0,0
0,0,0,0,0,0,0,0,0,0,0,0,0,0,0,0,0
0,0,0,0,0,0,0,0,0,0,0,0,0,0,0,0,0
0,0,0,0,0,0,0,0,0,0,0,0,0,0,0,0,0
0,0,0,0,0,0,0,0,0,0,0,0,0,0,0,0,0
0,0,0,0,0,0,0,0,0,0,0,0,0,0,0,0,0
0,0,0,0,0,0,0,0,0,0,0,0,0,0,0,0,0
0,0,0,0,0,0,0,0,0,0,0,0,0,0,0,0,0
0,0,0,0,0,0,0,0,0,0,0,0,0,0,0,0,0
:endlayer

#### RULES ####
rule:
plugin=vanillaBlocks
number=1
data:
JSON:{{"val":{"blockName":{"val":"minecraft:dirt","id":"ss"},"meta":{"val":"0","id":"pi"},"buildPass":{"val":"0","id":"pi"}},"id":"ct"}}
:enddata
:endrule

rule:
plugin=vanillaBlocks
number=2
data:
JSON:{{"val":{"blockName":{"val":"minecraft:cobblestone","id":"ss"},"meta":{"val":"0","id":"pi"},"buildPass":{"val":"0","id":"pi"}},"id":"ct"}}
:enddata
:endrule

rule:
plugin=vanillaBlocks
number=3
data:
JSON:{{"val":{"blockName":{"val":"minecraft:gravel","id":"ss"},"meta":{"val":"0","id":"pi"},"buildPass":{"val":"0","id":"pi"}},"id":"ct"}}
:enddata
:endrule

rule:
plugin=vanillaBlocks
number=4
data:
JSON:{{"val":{"blockName":{"val":"minecraft:grass","id":"ss"},"meta":{"val":"0","id":"pi"},"buildPass":{"val":"0","id":"pi"}},"id":"ct"}}
:enddata
:endrule

rule:
plugin=vanillaBlocks
number=5
data:
JSON:{{"val":{"blockName":{"val":"minecraft:fence","id":"ss"},"meta":{"val":"0","id":"pi"},"buildPass":{"val":"0","id":"pi"}},"id":"ct"}}
:enddata
:endrule

rule:
plugin=vanillaBlocks
number=6
data:
JSON:{{"val":{"blockName":{"val":"minecraft:fence_gate","id":"ss"},"meta":{"val":"2","id":"pi"},"buildPass":{"val":"0","id":"pi"}},"id":"ct"}}
:enddata
:endrule

rule:
plugin=vanillaBlocks
number=7
data:
JSON:{{"val":{"blockName":{"val":"minecraft:log","id":"ss"},"meta":{"val":"0","id":"pi"},"buildPass":{"val":"0","id":"pi"}},"id":"ct"}}
:enddata
:endrule

rule:
plugin=vanillaBlocks
number=8
data:
JSON:{{"val":{"blockName":{"val":"minecraft:planks","id":"ss"},"meta":{"val":"0","id":"pi"},"buildPass":{"val":"0","id":"pi"}},"id":"ct"}}
:enddata
:endrule

rule:
plugin=vanillaBlocks
number=9
data:
JSON:{{"val":{"blockName":{"val":"minecraft:stone_stairs","id":"ss"},"meta":{"val":"3","id":"pi"},"buildPass":{"val":"0","id":"pi"}},"id":"ct"}}
:enddata
:endrule

rule:
plugin=vanillaBlocks
number=10
data:
JSON:{{"val":{"blockName":{"val":"minecraft:stonebrick","id":"ss"},"meta":{"val":"0","id":"pi"},"buildPass":{"val":"0","id":"pi"}},"id":"ct"}}
:enddata
:endrule

rule:
plugin=vanillaBlocks
number=11
data:
JSON:{{"val":{"blockName":{"val":"minecraft:torch","id":"ss"},"meta":{"val":"5","id":"pi"},"buildPass":{"val":"2","id":"pi"}},"id":"ct"}}
:enddata
:endrule

rule:
plugin=vanillaBlocks
number=12
data:
JSON:{{"val":{"blockName":{"val":"minecraft:crafting_table","id":"ss"},"meta":{"val":"0","id":"pi"},"buildPass":{"val":"0","id":"pi"}},"id":"ct"}}
:enddata
:endrule

rule:
plugin=awAutomationLogic
number=13
data:
JSON:{{"val":{"teData":{"val":{"id":{"val":"Furnace","id":"ss"},"Items":{"val":[],"id":"ls"},"BurnTime":{"val":"0","id":"ps"},"z":{"val":"839","id":"pi"},"y":{"val":"79","id":"pi"},"CookTime":{"val":"0","id":"ps"},"x":{"val":"1453","id":"pi"}},"id":"ct"},"blockName":{"val":"minecraft:furnace","id":"ss"},"meta":{"val":"5","id":"pi"},"buildPass":{"val":"0","id":"pi"}},"id":"ct"}}
:enddata
:endrule

rule:
plugin=vanillaDoors
number=14
data:
JSON:{{"val":{"sideFlag":{"val":"8","id":"pb"},"blockName":{"val":"minecraft:wooden_door","id":"ss"},"meta":{"val":"1","id":"pi"},"buildPass":{"val":"2","id":"pi"}},"id":"ct"}}
:enddata
:endrule

rule:
plugin=vanillaBlocks
number=15
data:
JSON:{{"val":{"blockName":{"val":"minecraft:oak_stairs","id":"ss"},"meta":{"val":"2","id":"pi"},"buildPass":{"val":"0","id":"pi"}},"id":"ct"}}
:enddata
:endrule

rule:
plugin=vanillaBlocks
number=16
data:
JSON:{{"val":{"blockName":{"val":"minecraft:oak_stairs","id":"ss"},"meta":{"val":"6","id":"pi"},"buildPass":{"val":"0","id":"pi"}},"id":"ct"}}
:enddata
:endrule

rule:
plugin=awAutomationLogic
number=17
data:
JSON:{{"val":{"teData":{"val":{"id":{"val":"Furnace","id":"ss"},"Items":{"val":[],"id":"ls"},"BurnTime":{"val":"0","id":"ps"},"z":{"val":"839","id":"pi"},"y":{"val":"80","id":"pi"},"CookTime":{"val":"0","id":"ps"},"x":{"val":"1453","id":"pi"}},"id":"ct"},"blockName":{"val":"minecraft:furnace","id":"ss"},"meta":{"val":"5","id":"pi"},"buildPass":{"val":"0","id":"pi"}},"id":"ct"}}
:enddata
:endrule

rule:
plugin=vanillaBlocks
number=18
data:
JSON:{{"val":{"blockName":{"val":"minecraft:oak_stairs","id":"ss"},"meta":{"val":"7","id":"pi"},"buildPass":{"val":"0","id":"pi"}},"id":"ct"}}
:enddata
:endrule

rule:
plugin=vanillaDoors
number=19
data:
JSON:{{"val":{"sideFlag":{"val":"0","id":"pb"},"blockName":{"val":"minecraft:wooden_door","id":"ss"},"meta":{"val":"8","id":"pi"},"buildPass":{"val":"2","id":"pi"}},"id":"ct"}}
:enddata
:endrule

rule:
plugin=vanillaBlocks
number=20
data:
JSON:{{"val":{"blockName":{"val":"minecraft:torch","id":"ss"},"meta":{"val":"3","id":"pi"},"buildPass":{"val":"2","id":"pi"}},"id":"ct"}}
:enddata
:endrule

rule:
plugin=vanillaBlocks
number=21
data:
JSON:{{"val":{"blockName":{"val":"minecraft:torch","id":"ss"},"meta":{"val":"2","id":"pi"},"buildPass":{"val":"2","id":"pi"}},"id":"ct"}}
:enddata
:endrule

rule:
plugin=vanillaBlocks
number=22
data:
JSON:{{"val":{"blockName":{"val":"minecraft:torch","id":"ss"},"meta":{"val":"1","id":"pi"},"buildPass":{"val":"2","id":"pi"}},"id":"ct"}}
:enddata
:endrule

rule:
plugin=vanillaBlocks
number=23
data:
JSON:{{"val":{"blockName":{"val":"minecraft:torch","id":"ss"},"meta":{"val":"4","id":"pi"},"buildPass":{"val":"2","id":"pi"}},"id":"ct"}}
:enddata
:endrule

rule:
plugin=vanillaBlocks
number=24
data:
JSON:{{"val":{"blockName":{"val":"minecraft:glass_pane","id":"ss"},"meta":{"val":"0","id":"pi"},"buildPass":{"val":"0","id":"pi"}},"id":"ct"}}
:enddata
:endrule

rule:
plugin=vanillaBlocks
number=25
data:
JSON:{{"val":{"blockName":{"val":"minecraft:bed","id":"ss"},"meta":{"val":"11","id":"pi"},"buildPass":{"val":"2","id":"pi"}},"id":"ct"}}
:enddata
:endrule

rule:
plugin=vanillaBlocks
number=26
data:
JSON:{{"val":{"blockName":{"val":"minecraft:bed","id":"ss"},"meta":{"val":"3","id":"pi"},"buildPass":{"val":"2","id":"pi"}},"id":"ct"}}
:enddata
:endrule

rule:
plugin=vanillaBlocks
number=27
data:
JSON:{{"val":{"blockName":{"val":"minecraft:oak_stairs","id":"ss"},"meta":{"val":"1","id":"pi"},"buildPass":{"val":"0","id":"pi"}},"id":"ct"}}
:enddata
:endrule

rule:
plugin=vanillaBlocks
number=28
data:
JSON:{{"val":{"blockName":{"val":"minecraft:wooden_slab","id":"ss"},"meta":{"val":"0","id":"pi"},"buildPass":{"val":"0","id":"pi"}},"id":"ct"}}
:enddata
:endrule

rule:
plugin=vanillaBlocks
number=29
data:
JSON:{{"val":{"blockName":{"val":"minecraft:double_wooden_slab","id":"ss"},"meta":{"val":"0","id":"pi"},"buildPass":{"val":"0","id":"pi"}},"id":"ct"}}
:enddata
:endrule

rule:
plugin=vanillaBlocks
number=30
data:
JSON:{{"val":{"blockName":{"val":"minecraft:oak_stairs","id":"ss"},"meta":{"val":"3","id":"pi"},"buildPass":{"val":"0","id":"pi"}},"id":"ct"}}
:enddata
:endrule

rule:
plugin=vanillaBlocks
number=31
data:
JSON:{{"val":{"blockName":{"val":"minecraft:oak_stairs","id":"ss"},"meta":{"val":"0","id":"pi"},"buildPass":{"val":"0","id":"pi"}},"id":"ct"}}
:enddata
:endrule

rule:
plugin=vanillaBlocks
number=32
data:
JSON:{{"val":{"blockName":{"val":"minecraft:wooden_slab","id":"ss"},"meta":{"val":"8","id":"pi"},"buildPass":{"val":"0","id":"pi"}},"id":"ct"}}
:enddata
:endrule

#### ENTITIES ####
