# Ancient Warfare Structure Template File
# Auto-generated structure template file. created on: 11/25/2014 at: 20:13:52
# Lines beginning with # denote comments

header:
version=2.1
name=TownblocksSingleHouse2
size=17,30,17
offset=8,2,13
:endheader

#### VALIDATION ####
validation:
type=ground
survival=false
worldGenEnabled=false
unique=false
preserveBlocks=false
selectionWeight=0
clusterValue=0
minDuplicateDistance=0
dimensionWhiteList=false
dimensionList=
biomeWhiteList=false
biomeList=
leveling=0
fill=0
border=0
validTargetBlocks=
blockSwap=false
data:
:enddata
:endvalidation

#### LAYERS ####
layer: 0
1,1,1,1,1,1,1,1,1,1,1,1,1,1,1,1,1
1,2,2,2,2,2,2,2,2,2,2,2,2,2,2,2,1
1,2,2,2,2,2,2,2,2,2,2,2,2,2,2,2,1
1,2,2,2,2,2,2,2,2,2,2,2,2,2,2,2,1
1,2,2,2,2,2,2,2,2,2,2,2,2,2,2,2,1
1,2,2,2,2,2,2,2,2,2,2,2,2,2,2,2,1
1,2,2,2,2,2,2,2,2,2,2,2,2,2,2,2,1
1,2,2,2,2,2,2,2,2,2,2,2,2,2,2,2,1
1,2,2,2,2,2,2,2,2,2,2,2,2,2,2,2,1
1,2,2,2,2,2,2,2,2,2,2,2,2,2,2,2,1
1,2,2,2,2,2,2,2,2,2,2,2,2,2,2,2,1
1,2,2,2,2,2,2,2,2,2,2,2,2,2,2,2,1
1,2,2,2,2,2,2,2,2,2,2,2,2,2,2,2,1
1,2,2,2,2,2,2,2,2,2,2,2,2,2,2,2,1
1,2,2,2,2,2,2,2,2,2,2,2,2,2,2,2,1
1,2,2,2,2,2,2,2,2,2,2,2,2,2,2,2,1
1,1,1,1,1,1,1,1,1,1,1,1,1,1,1,1,1
:endlayer
layer: 1
4,4,4,4,4,4,4,4,4,4,4,4,4,4,4,4,4
4,4,4,4,4,4,4,4,4,4,4,4,4,4,4,4,4
4,4,4,4,4,4,4,4,4,4,4,4,4,4,4,4,4
4,4,4,1,1,1,1,1,1,1,1,1,1,1,4,4,4
4,4,4,1,1,5,5,1,1,1,1,1,1,1,4,4,4
4,4,4,1,1,5,5,1,1,1,1,1,1,1,4,4,4
4,4,4,1,1,1,1,1,1,1,1,1,1,1,4,4,4
4,4,4,1,1,1,1,1,1,1,1,1,1,1,4,4,4
4,4,4,1,1,1,1,1,1,1,1,1,1,1,4,4,4
4,4,4,1,1,1,1,1,1,4,1,3,1,4,4,4,4
4,4,4,1,1,1,1,1,1,4,4,3,4,4,4,4,4
4,4,4,1,1,1,1,1,1,4,4,3,4,4,4,4,4
4,4,4,1,1,1,1,1,1,4,4,3,4,4,4,4,4
4,4,4,1,1,1,1,1,1,4,4,3,4,4,4,4,4
3,3,3,3,3,3,3,3,3,3,3,3,3,3,3,3,3
3,3,3,3,3,3,3,3,3,3,3,3,3,3,3,3,3
3,3,3,3,3,3,3,3,3,3,3,3,3,3,3,3,3
:endlayer
layer: 2
0,0,0,0,0,0,0,0,0,0,0,0,0,0,0,0,0
0,6,6,6,6,0,6,0,0,0,6,6,0,0,7,0,0
0,0,0,0,0,0,0,0,0,0,0,0,0,0,0,6,0
0,0,0,8,8,8,8,8,8,8,8,8,8,8,0,0,0
0,0,0,8,5,5,5,5,5,5,5,5,5,8,7,6,0
0,6,0,8,5,5,5,5,5,5,5,5,5,8,0,6,0
0,6,6,8,5,5,5,5,5,5,5,5,5,8,0,6,0
0,6,6,8,5,5,5,5,5,5,5,5,5,8,6,6,0
0,6,0,8,5,5,5,5,8,8,8,5,8,8,6,6,0
0,6,6,8,5,5,5,5,8,10,8,12,8,9,0,6,0
0,0,7,8,5,5,5,5,8,10,0,0,0,9,6,6,0
0,0,0,8,5,5,5,5,8,10,0,0,0,9,6,6,0
0,0,0,8,5,5,5,5,8,10,0,0,0,9,6,6,0
0,0,0,8,8,8,8,8,8,9,9,11,9,9,6,0,0
0,0,0,0,0,0,0,0,0,0,0,0,0,0,0,0,0
0,0,0,0,0,0,0,0,0,0,0,0,0,0,0,0,0
0,0,0,0,0,0,0,0,0,0,0,0,0,0,0,0,0
:endlayer
layer: 3
0,0,0,0,0,0,0,0,0,0,0,0,0,0,0,0,0
0,0,0,0,0,0,0,0,0,0,0,0,0,0,0,0,0
0,0,0,0,0,0,0,0,0,0,0,0,0,0,0,0,0
0,0,0,8,13,13,13,13,8,13,13,13,13,8,0,0,0
0,0,0,13,18,0,0,24,8,25,25,25,25,13,0,0,0
0,0,0,13,18,0,0,24,0,0,0,0,25,13,0,0,0
0,0,0,13,17,0,0,23,0,0,0,0,12,13,0,0,0
0,0,0,13,0,0,0,0,0,0,0,0,0,13,0,0,0
0,0,0,8,13,20,13,13,8,13,13,26,13,8,0,0,0
0,0,0,13,0,0,0,22,13,0,9,0,9,0,0,0,0
0,0,0,13,16,0,0,21,13,0,0,0,0,0,0,0,0
0,0,0,13,15,0,0,19,13,0,0,0,0,0,0,0,0
0,0,0,13,14,19,19,19,13,0,0,0,0,0,0,0,0
0,0,0,8,13,13,13,13,8,0,0,0,0,27,0,0,0
0,0,0,0,0,0,0,0,0,0,0,0,0,0,0,0,0
0,0,0,0,0,0,0,0,0,0,0,0,0,0,0,0,0
0,0,0,0,0,0,0,0,0,0,0,0,0,0,0,0,0
:endlayer
layer: 4
0,0,0,0,0,0,0,0,0,0,0,0,0,0,0,0,0
0,0,0,0,0,0,0,0,0,0,0,0,0,0,0,0,0
0,0,0,0,0,0,0,0,0,0,0,0,0,0,0,0,0
0,0,0,8,13,13,13,13,8,13,13,13,13,8,0,0,0
0,0,0,13,0,0,0,0,8,25,25,25,25,13,0,0,0
0,0,0,13,0,0,0,0,0,0,0,0,12,13,0,0,0
0,0,0,13,0,0,0,0,0,0,0,0,0,13,0,0,0
0,0,0,13,0,0,0,0,0,0,0,0,0,13,0,0,0
0,0,0,8,13,28,13,13,8,13,13,29,13,8,0,0,0
0,0,0,13,0,0,0,0,13,0,0,0,0,0,0,0,0
0,0,0,13,0,0,0,0,13,0,0,0,0,0,0,0,0
0,0,0,13,0,0,0,0,13,0,0,0,0,0,0,0,0
0,0,0,13,0,0,0,0,13,0,0,0,0,0,0,0,0
0,0,0,8,13,13,13,13,8,0,0,0,0,0,0,0,0
0,0,0,0,0,0,0,0,0,0,0,0,0,0,0,0,0
0,0,0,0,0,0,0,0,0,0,0,0,0,0,0,0,0
0,0,0,0,0,0,0,0,0,0,0,0,0,0,0,0,0
:endlayer
layer: 5
0,0,0,0,0,0,0,0,0,0,0,0,0,0,0,0,0
0,0,0,0,0,0,0,0,0,0,0,0,0,0,0,0,0
0,0,0,32,0,0,0,0,0,0,0,0,0,32,0,0,0
0,0,30,8,13,13,13,13,8,13,13,13,13,8,33,0,0
0,0,0,13,0,0,0,0,8,25,25,18,0,13,0,0,0
0,0,0,13,0,0,0,0,0,0,0,0,0,13,0,0,0
0,0,0,13,0,0,0,0,0,0,0,0,0,13,0,0,0
0,0,0,13,0,0,0,0,0,0,0,0,0,13,0,0,0
0,0,0,8,13,13,13,13,8,13,13,13,13,8,33,0,0
0,0,0,13,0,0,0,0,13,0,0,31,0,31,0,0,0
0,0,0,13,0,0,0,0,13,0,0,0,0,0,0,0,0
0,0,0,13,0,0,0,0,13,0,0,0,0,0,0,0,0
0,0,0,13,0,0,0,0,13,0,0,0,0,0,0,0,0
0,0,30,8,13,13,13,13,8,33,0,0,0,0,0,0,0
0,0,0,31,0,0,0,0,31,0,0,0,0,0,0,0,0
0,0,0,0,0,0,0,0,0,0,0,0,0,0,0,0,0
0,0,0,0,0,0,0,0,0,0,0,0,0,0,0,0,0
:endlayer
layer: 6
0,0,0,0,0,0,0,0,0,0,0,0,0,0,0,0,0
0,0,0,0,0,0,0,0,0,0,0,0,0,0,0,0,0
0,0,9,8,9,9,9,9,8,9,9,9,9,8,9,0,0
0,0,8,8,8,8,8,8,8,8,8,8,8,8,8,0,0
0,0,9,8,33,0,0,30,8,25,18,0,30,8,9,0,0
0,0,9,8,0,0,0,0,8,0,0,0,0,8,9,0,0
0,0,9,8,0,0,0,0,8,0,0,0,0,8,9,0,0
0,0,9,8,33,0,0,30,8,33,0,0,30,8,9,0,0
0,0,8,8,8,8,8,8,8,8,8,8,8,8,8,0,0
0,0,9,8,33,0,0,30,8,8,9,9,9,8,9,0,0
0,0,9,8,0,0,0,0,8,9,0,0,0,0,0,0,0
0,0,9,8,0,0,0,0,8,9,0,0,0,0,0,0,0
0,0,9,8,33,0,0,30,8,9,0,0,0,0,0,0,0
0,0,8,8,8,8,8,8,8,8,0,0,0,0,0,0,0
0,0,9,8,0,0,0,0,8,9,0,0,0,0,0,0,0
0,0,0,0,0,0,0,0,0,0,0,0,0,0,0,0,0
0,0,0,0,0,0,0,0,0,0,0,0,0,0,0,0,0
:endlayer
layer: 7
0,0,0,0,0,0,0,0,0,0,0,0,0,0,0,0,0
0,0,0,0,0,0,0,0,0,0,0,0,0,0,0,0,0
0,0,9,8,8,8,8,8,8,8,8,8,8,8,9,0,0
0,0,8,5,5,5,5,5,5,5,5,5,5,5,8,0,0
0,0,8,5,5,5,5,5,5,18,0,0,0,5,8,0,0
0,0,8,5,5,5,5,5,5,5,5,5,5,5,8,0,0
0,0,8,5,5,5,5,5,5,5,5,5,5,5,8,0,0
0,0,8,5,5,5,5,5,5,5,5,5,5,5,8,0,0
0,0,8,5,5,5,5,5,5,5,5,5,5,5,8,0,0
0,0,8,5,5,5,5,5,5,8,8,8,8,8,9,0,0
0,0,8,5,5,5,5,5,5,8,0,0,0,0,0,0,0
0,0,8,5,5,5,5,5,5,8,0,0,0,0,0,0,0
0,0,8,5,5,5,5,5,5,8,0,0,0,0,0,0,0
0,0,8,5,5,5,5,5,5,8,0,0,0,0,0,0,0
0,0,9,8,8,8,8,8,8,9,0,0,0,0,0,0,0
0,0,0,0,0,0,0,0,0,0,0,0,0,0,0,0,0
0,0,0,0,0,0,0,0,0,0,0,0,0,0,0,0,0
:endlayer
layer: 8
0,0,0,0,0,0,0,0,0,0,0,0,0,0,0,0,0
0,0,0,0,0,0,0,0,0,0,0,0,0,0,0,0,0
0,0,9,8,5,34,34,5,8,5,34,34,5,8,9,0,0
0,0,8,0,0,0,0,0,0,0,9,9,9,9,8,0,0
0,0,5,0,0,12,0,0,0,0,0,0,0,9,5,0,0
0,0,34,0,18,9,24,0,0,0,9,9,9,9,34,0,0
0,0,34,0,0,37,0,0,0,0,0,0,0,9,34,0,0
0,0,5,0,0,0,0,0,0,0,0,0,0,12,5,0,0
0,0,8,0,0,0,0,0,0,0,0,0,0,0,8,0,0
0,0,5,5,20,5,5,5,5,8,5,34,5,8,9,0,0
0,0,34,0,0,0,38,39,0,5,0,0,0,0,0,0,0
0,0,34,0,0,0,38,39,0,34,0,0,0,0,0,0,0
0,0,5,0,0,0,0,0,0,5,0,0,0,0,0,0,0
0,0,8,35,36,0,0,0,14,8,0,0,0,0,0,0,0
0,0,9,8,5,34,34,5,8,9,0,0,0,0,0,0,0
0,0,0,0,0,0,0,0,0,0,0,0,0,0,0,0,0
0,0,0,0,0,0,0,0,0,0,0,0,0,0,0,0,0
:endlayer
layer: 9
0,0,0,0,0,0,0,0,0,0,0,0,0,0,0,0,0
0,0,0,0,0,0,0,0,0,0,0,0,0,0,0,0,0
0,0,9,8,5,34,34,5,8,5,34,34,5,8,9,0,0
0,0,8,0,0,0,0,0,0,0,0,0,0,0,8,0,0
0,0,5,0,0,0,0,0,0,0,0,0,0,0,5,0,0
0,0,34,0,0,41,0,0,0,0,0,0,0,0,34,0,0
0,0,34,0,0,0,0,0,0,0,0,0,0,12,34,0,0
0,0,5,0,0,0,0,0,0,0,0,0,0,0,5,0,0
0,0,8,0,0,0,0,0,0,0,0,0,0,0,8,0,0
0,0,5,5,40,5,5,5,5,8,5,34,5,8,9,0,0
0,0,34,0,0,0,0,0,0,5,0,0,0,0,0,0,0
0,0,34,0,0,0,0,0,0,34,0,0,0,0,0,0,0
0,0,5,0,0,0,0,0,0,5,0,0,0,0,0,0,0
0,0,8,0,0,0,0,0,0,8,0,0,0,0,0,0,0
0,0,9,8,5,34,34,5,8,9,0,0,0,0,0,0,0
0,0,0,0,0,0,0,0,0,0,0,0,0,0,0,0,0
0,0,0,0,0,0,0,0,0,0,0,0,0,0,0,0,0
:endlayer
layer: 10
0,0,0,0,0,0,0,0,0,0,0,0,0,0,0,0,0
0,0,0,0,0,0,0,0,0,0,0,0,0,0,0,0,0
0,0,9,8,5,34,34,5,8,5,34,34,5,8,9,0,0
0,0,8,0,0,0,0,0,31,0,0,0,0,31,8,0,0
0,0,5,0,0,0,0,0,0,0,0,0,0,0,5,0,0
0,0,34,0,0,0,0,0,0,0,0,0,0,12,34,0,0
0,0,34,0,0,0,0,0,0,0,0,0,0,0,34,0,0
0,0,5,0,0,0,0,0,0,0,0,0,0,0,5,0,0
0,0,8,33,0,0,0,0,0,32,0,0,0,32,8,0,0
0,0,5,5,5,5,5,5,5,8,5,34,5,8,9,0,0
0,0,34,0,0,0,0,0,0,5,0,0,0,0,0,0,0
0,0,34,0,0,0,0,0,0,34,0,0,0,0,0,0,0
0,0,5,0,0,0,0,0,0,5,0,0,0,0,0,0,0
0,0,8,33,0,0,0,0,30,8,0,0,0,0,0,0,0
0,0,9,8,5,34,34,5,8,9,0,0,0,0,0,0,0
0,0,0,0,0,0,0,0,0,0,0,0,0,0,0,0,0
0,0,0,0,0,0,0,0,0,0,0,0,0,0,0,0,0
:endlayer
layer: 11
0,0,0,0,0,0,0,0,0,0,0,0,0,0,0,0,0
0,42,37,37,37,37,37,37,37,37,37,37,37,37,37,37,0
0,24,9,8,8,8,8,8,8,8,8,8,8,8,9,42,0
0,24,8,31,0,0,0,31,8,5,5,5,5,5,8,42,0
0,24,8,0,0,0,0,0,8,5,5,5,5,45,8,43,0
0,24,8,0,0,0,0,0,8,5,5,5,5,0,8,18,0
0,24,8,0,0,0,0,0,8,5,5,5,5,0,8,18,0
0,24,8,32,0,0,0,32,8,5,5,5,5,0,8,43,0
0,24,8,8,8,8,8,8,8,5,5,5,5,5,8,42,0
0,24,8,5,5,5,5,5,5,8,8,8,8,8,9,42,0
0,24,8,5,5,5,5,5,5,8,44,12,12,12,12,12,0
0,24,8,5,5,5,5,5,5,8,18,0,0,0,0,0,0
0,24,8,5,5,5,5,5,5,8,18,0,0,0,0,0,0
0,24,8,5,5,5,5,5,5,8,18,0,0,0,0,0,0
0,24,9,8,8,8,8,8,8,9,18,0,0,0,0,0,0
0,24,42,42,43,12,12,43,42,42,18,0,0,0,0,0,0
0,0,0,0,0,0,0,0,0,0,0,0,0,0,0,0,0
:endlayer
layer: 12
0,0,0,0,0,0,0,0,0,0,0,0,0,0,0,0,0
0,0,0,0,0,0,0,0,0,0,0,0,0,0,0,0,0
0,0,42,37,37,37,37,37,37,37,37,37,37,37,37,37,0
0,0,24,8,8,8,8,8,8,8,9,9,9,9,8,0,0
0,0,24,8,5,5,5,5,8,9,0,0,0,0,5,9,0
0,0,24,8,5,5,5,5,18,0,0,0,9,0,34,0,0
0,0,24,8,5,5,5,5,18,0,0,0,9,0,34,0,0
0,0,24,8,5,5,5,5,8,9,0,0,9,0,5,9,0
0,0,24,8,8,48,48,8,8,8,9,9,9,9,8,0,0
0,0,24,8,9,12,12,9,8,44,12,12,12,12,12,12,0
0,0,24,9,47,0,0,50,9,18,0,0,0,0,0,0,0
0,0,24,9,46,0,0,49,9,18,0,0,0,0,0,0,0
0,0,24,9,0,0,0,0,9,18,0,0,0,0,0,0,0
0,0,24,9,0,0,0,0,9,18,0,0,0,0,0,0,0
0,0,24,8,5,34,34,5,8,18,0,0,0,0,0,0,0
0,0,24,0,9,0,0,9,0,18,0,0,0,0,0,0,0
0,0,0,0,0,0,0,0,0,0,0,0,0,0,0,0,0
:endlayer
layer: 13
0,0,0,0,0,0,0,0,0,0,0,0,0,0,0,0,0
0,0,0,0,0,0,0,0,0,0,0,0,0,0,0,0,0
0,0,0,0,0,0,0,0,0,0,0,0,0,0,0,0,0
0,0,0,8,5,34,34,5,8,37,37,37,37,37,37,37,0
0,0,0,5,0,0,0,0,5,8,33,0,0,30,8,9,0
0,0,0,34,0,0,0,0,0,0,0,0,0,0,34,0,0
0,0,0,34,0,0,0,0,0,0,0,0,0,0,34,0,0
0,0,0,5,0,0,0,0,5,8,33,0,0,30,8,9,0
0,0,0,8,5,51,20,5,8,12,12,12,12,12,12,12,0
0,0,0,24,8,0,0,8,18,0,0,0,0,0,0,0,0
0,0,0,24,31,0,0,31,18,0,0,0,0,0,0,0,0
0,0,0,24,0,0,0,0,18,0,0,0,0,0,0,0,0
0,0,0,24,0,0,0,0,18,0,0,0,0,0,0,0,0
0,0,0,24,0,0,0,0,18,0,0,0,0,0,0,0,0
0,0,0,24,8,34,34,8,18,0,0,0,0,0,0,0,0
0,0,0,24,9,0,0,9,18,0,0,0,0,0,0,0,0
0,0,0,0,0,0,0,0,0,0,0,0,0,0,0,0,0
:endlayer
layer: 14
0,0,0,0,0,0,0,0,0,0,0,0,0,0,0,0,0
0,0,0,0,0,0,0,0,0,0,0,0,0,0,0,0,0
0,0,0,0,0,0,0,0,0,0,0,0,0,0,0,0,0
0,0,0,8,5,34,34,5,8,0,0,0,0,0,0,0,0
0,0,0,5,0,0,0,0,5,37,37,37,37,37,37,37,0
0,0,0,34,0,0,0,0,0,0,0,0,0,0,8,0,0
0,0,0,34,0,0,0,0,0,0,0,0,0,0,8,0,0
0,0,0,5,0,0,0,0,5,12,12,12,12,12,12,12,0
0,0,0,8,5,52,53,5,8,0,0,0,0,0,0,0,0
0,0,0,0,24,0,0,18,0,0,0,0,0,0,0,0,0
0,0,0,0,24,0,0,18,0,0,0,0,0,0,0,0,0
0,0,0,0,24,0,0,18,0,0,0,0,0,0,0,0,0
0,0,0,0,24,0,0,18,0,0,0,0,0,0,0,0,0
0,0,0,0,24,0,0,18,0,0,0,0,0,0,0,0,0
0,0,0,0,24,8,8,18,0,0,0,0,0,0,0,0,0
0,0,0,0,24,0,0,18,0,0,0,0,0,0,0,0,0
0,0,0,0,0,0,0,0,0,0,0,0,0,0,0,0,0
:endlayer
layer: 15
0,0,0,0,0,0,0,0,0,0,0,0,0,0,0,0,0
0,0,0,0,0,0,0,0,0,0,0,0,0,0,0,0,0
0,0,0,0,0,0,0,0,0,0,0,0,0,0,0,0,0
0,0,0,8,5,34,34,5,8,0,0,0,0,0,0,0,0
0,0,0,5,0,0,0,0,5,0,0,0,0,0,0,0,0
0,0,0,34,0,0,0,0,5,37,37,37,37,37,37,37,0
0,0,0,34,0,0,0,0,5,12,12,12,12,12,12,12,0
0,0,0,5,0,0,0,0,5,0,0,0,0,0,0,0,0
0,0,0,8,5,5,5,5,8,0,0,0,0,0,0,0,0
0,0,0,0,0,24,18,0,0,0,0,0,0,0,0,0,0
0,0,0,0,0,24,18,0,0,0,0,0,0,0,0,0,0
0,0,0,0,0,24,18,0,0,0,0,0,0,0,0,0,0
0,0,0,0,0,24,18,0,0,0,0,0,0,0,0,0,0
0,0,0,0,0,24,18,0,0,0,0,0,0,0,0,0,0
0,0,0,0,0,24,18,0,0,0,0,0,0,0,0,0,0
0,0,0,0,0,24,18,0,0,0,0,0,0,0,0,0,0
0,0,0,0,0,0,0,0,0,0,0,0,0,0,0,0,0
:endlayer
layer: 16
0,0,0,0,0,0,0,0,0,0,0,0,0,0,0,0,0
0,0,0,0,0,0,0,0,0,0,0,0,0,0,0,0,0
0,0,43,42,42,42,42,42,42,43,0,0,0,0,0,0,0
0,0,42,8,8,8,8,8,8,42,0,0,0,0,0,0,0
0,0,42,8,33,0,0,30,8,42,0,0,0,0,0,0,0
0,0,42,8,0,0,0,0,8,42,0,0,0,0,0,0,0
0,0,42,8,0,0,0,0,8,42,0,0,0,0,0,0,0
0,0,42,8,33,0,0,30,8,42,0,0,0,0,0,0,0
0,0,42,8,8,8,8,8,8,42,0,0,0,0,0,0,0
0,0,43,42,42,42,42,42,42,43,0,0,0,0,0,0,0
0,0,0,0,0,0,0,0,0,0,0,0,0,0,0,0,0
0,0,0,0,0,0,0,0,0,0,0,0,0,0,0,0,0
0,0,0,0,0,0,0,0,0,0,0,0,0,0,0,0,0
0,0,0,0,0,0,0,0,0,0,0,0,0,0,0,0,0
0,0,0,0,0,0,0,0,0,0,0,0,0,0,0,0,0
0,0,0,0,0,0,0,0,0,0,0,0,0,0,0,0,0
0,0,0,0,0,0,0,0,0,0,0,0,0,0,0,0,0
:endlayer
layer: 17
0,0,0,0,0,0,0,0,0,0,0,0,0,0,0,0,0
0,0,0,0,0,0,0,0,0,0,0,0,0,0,0,0,0
0,0,0,24,0,0,0,0,18,0,0,0,0,0,0,0,0
0,0,37,44,8,34,34,8,44,37,0,0,0,0,0,0,0
0,0,0,8,0,0,0,0,8,0,0,0,0,0,0,0,0
0,0,0,34,0,0,0,0,34,0,0,0,0,0,0,0,0
0,0,0,34,0,0,0,0,34,0,0,0,0,0,0,0,0
0,0,0,8,0,0,0,0,8,0,0,0,0,0,0,0,0
0,0,12,44,8,34,34,8,44,12,0,0,0,0,0,0,0
0,0,0,24,0,0,0,0,18,0,0,0,0,0,0,0,0
0,0,0,0,0,0,0,0,0,0,0,0,0,0,0,0,0
0,0,0,0,0,0,0,0,0,0,0,0,0,0,0,0,0
0,0,0,0,0,0,0,0,0,0,0,0,0,0,0,0,0
0,0,0,0,0,0,0,0,0,0,0,0,0,0,0,0,0
0,0,0,0,0,0,0,0,0,0,0,0,0,0,0,0,0
0,0,0,0,0,0,0,0,0,0,0,0,0,0,0,0,0
0,0,0,0,0,0,0,0,0,0,0,0,0,0,0,0,0
:endlayer
layer: 18
0,0,0,0,0,0,0,0,0,0,0,0,0,0,0,0,0
0,0,0,0,0,0,0,0,0,0,0,0,0,0,0,0,0
0,0,0,0,24,0,0,18,0,0,0,0,0,0,0,0,0
0,0,0,0,24,8,8,18,0,0,0,0,0,0,0,0,0
0,0,37,37,44,0,0,44,37,37,0,0,0,0,0,0,0
0,0,0,8,0,0,0,0,8,0,0,0,0,0,0,0,0
0,0,0,8,0,0,0,0,8,0,0,0,0,0,0,0,0
0,0,12,12,44,0,0,44,12,12,0,0,0,0,0,0,0
0,0,0,0,24,8,8,18,0,0,0,0,0,0,0,0,0
0,0,0,0,24,0,0,18,0,0,0,0,0,0,0,0,0
0,0,0,0,0,0,0,0,0,0,0,0,0,0,0,0,0
0,0,0,0,0,0,0,0,0,0,0,0,0,0,0,0,0
0,0,0,0,0,0,0,0,0,0,0,0,0,0,0,0,0
0,0,0,0,0,0,0,0,0,0,0,0,0,0,0,0,0
0,0,0,0,0,0,0,0,0,0,0,0,0,0,0,0,0
0,0,0,0,0,0,0,0,0,0,0,0,0,0,0,0,0
0,0,0,0,0,0,0,0,0,0,0,0,0,0,0,0,0
:endlayer
layer: 19
0,0,0,0,0,0,0,0,0,0,0,0,0,0,0,0,0
0,0,0,0,0,0,0,0,0,0,0,0,0,0,0,0,0
0,0,0,0,0,24,18,0,0,0,0,0,0,0,0,0,0
0,0,0,0,0,24,18,0,0,0,0,0,0,0,0,0,0
0,0,0,0,0,24,18,0,0,0,0,0,0,0,0,0,0
0,0,37,37,37,43,43,37,37,37,0,0,0,0,0,0,0
0,0,12,12,12,43,43,12,12,12,0,0,0,0,0,0,0
0,0,0,0,0,24,18,0,0,0,0,0,0,0,0,0,0
0,0,0,0,0,24,18,0,0,0,0,0,0,0,0,0,0
0,0,0,0,0,24,18,0,0,0,0,0,0,0,0,0,0
0,0,0,0,0,0,0,0,0,0,0,0,0,0,0,0,0
0,0,0,0,0,0,0,0,0,0,0,0,0,0,0,0,0
0,0,0,0,0,0,0,0,0,0,0,0,0,0,0,0,0
0,0,0,0,0,0,0,0,0,0,0,0,0,0,0,0,0
0,0,0,0,0,0,0,0,0,0,0,0,0,0,0,0,0
0,0,0,0,0,0,0,0,0,0,0,0,0,0,0,0,0
0,0,0,0,0,0,0,0,0,0,0,0,0,0,0,0,0
:endlayer
layer: 20
0,0,0,0,0,0,0,0,0,0,0,0,0,0,0,0,0
0,0,0,0,0,0,0,0,0,0,0,0,0,0,0,0,0
0,0,0,0,0,0,0,0,0,0,0,0,0,0,0,0,0
0,0,0,0,0,0,0,0,0,0,0,0,0,0,0,0,0
0,0,0,0,0,0,0,0,0,0,0,0,0,0,0,0,0
0,0,0,0,0,42,42,0,0,0,0,0,0,0,0,0,0
0,0,0,0,0,42,42,0,0,0,0,0,0,0,0,0,0
0,0,0,0,0,0,0,0,0,0,0,0,0,0,0,0,0
0,0,0,0,0,0,0,0,0,0,0,0,0,0,0,0,0
0,0,0,0,0,0,0,0,0,0,0,0,0,0,0,0,0
0,0,0,0,0,0,0,0,0,0,0,0,0,0,0,0,0
0,0,0,0,0,0,0,0,0,0,0,0,0,0,0,0,0
0,0,0,0,0,0,0,0,0,0,0,0,0,0,0,0,0
0,0,0,0,0,0,0,0,0,0,0,0,0,0,0,0,0
0,0,0,0,0,0,0,0,0,0,0,0,0,0,0,0,0
0,0,0,0,0,0,0,0,0,0,0,0,0,0,0,0,0
0,0,0,0,0,0,0,0,0,0,0,0,0,0,0,0,0
:endlayer
layer: 21
0,0,0,0,0,0,0,0,0,0,0,0,0,0,0,0,0
0,0,0,0,0,0,0,0,0,0,0,0,0,0,0,0,0
0,0,0,0,0,0,0,0,0,0,0,0,0,0,0,0,0
0,0,0,0,0,0,0,0,0,0,0,0,0,0,0,0,0
0,0,0,0,0,0,0,0,0,0,0,0,0,0,0,0,0
0,0,0,0,0,0,0,0,0,0,0,0,0,0,0,0,0
0,0,0,0,0,0,0,0,0,0,0,0,0,0,0,0,0
0,0,0,0,0,0,0,0,0,0,0,0,0,0,0,0,0
0,0,0,0,0,0,0,0,0,0,0,0,0,0,0,0,0
0,0,0,0,0,0,0,0,0,0,0,0,0,0,0,0,0
0,0,0,0,0,0,0,0,0,0,0,0,0,0,0,0,0
0,0,0,0,0,0,0,0,0,0,0,0,0,0,0,0,0
0,0,0,0,0,0,0,0,0,0,0,0,0,0,0,0,0
0,0,0,0,0,0,0,0,0,0,0,0,0,0,0,0,0
0,0,0,0,0,0,0,0,0,0,0,0,0,0,0,0,0
0,0,0,0,0,0,0,0,0,0,0,0,0,0,0,0,0
0,0,0,0,0,0,0,0,0,0,0,0,0,0,0,0,0
:endlayer
layer: 22
0,0,0,0,0,0,0,0,0,0,0,0,0,0,0,0,0
0,0,0,0,0,0,0,0,0,0,0,0,0,0,0,0,0
0,0,0,0,0,0,0,0,0,0,0,0,0,0,0,0,0
0,0,0,0,0,0,0,0,0,0,0,0,0,0,0,0,0
0,0,0,0,0,0,0,0,0,0,0,0,0,0,0,0,0
0,0,0,0,0,0,0,0,0,0,0,0,0,0,0,0,0
0,0,0,0,0,0,0,0,0,0,0,0,0,0,0,0,0
0,0,0,0,0,0,0,0,0,0,0,0,0,0,0,0,0
0,0,0,0,0,0,0,0,0,0,0,0,0,0,0,0,0
0,0,0,0,0,0,0,0,0,0,0,0,0,0,0,0,0
0,0,0,0,0,0,0,0,0,0,0,0,0,0,0,0,0
0,0,0,0,0,0,0,0,0,0,0,0,0,0,0,0,0
0,0,0,0,0,0,0,0,0,0,0,0,0,0,0,0,0
0,0,0,0,0,0,0,0,0,0,0,0,0,0,0,0,0
0,0,0,0,0,0,0,0,0,0,0,0,0,0,0,0,0
0,0,0,0,0,0,0,0,0,0,0,0,0,0,0,0,0
0,0,0,0,0,0,0,0,0,0,0,0,0,0,0,0,0
:endlayer
layer: 23
0,0,0,0,0,0,0,0,0,0,0,0,0,0,0,0,0
0,0,0,0,0,0,0,0,0,0,0,0,0,0,0,0,0
0,0,0,0,0,0,0,0,0,0,0,0,0,0,0,0,0
0,0,0,0,0,0,0,0,0,0,0,0,0,0,0,0,0
0,0,0,0,0,0,0,0,0,0,0,0,0,0,0,0,0
0,0,0,0,0,0,0,0,0,0,0,0,0,0,0,0,0
0,0,0,0,0,0,0,0,0,0,0,0,0,0,0,0,0
0,0,0,0,0,0,0,0,0,0,0,0,0,0,0,0,0
0,0,0,0,0,0,0,0,0,0,0,0,0,0,0,0,0
0,0,0,0,0,0,0,0,0,0,0,0,0,0,0,0,0
0,0,0,0,0,0,0,0,0,0,0,0,0,0,0,0,0
0,0,0,0,0,0,0,0,0,0,0,0,0,0,0,0,0
0,0,0,0,0,0,0,0,0,0,0,0,0,0,0,0,0
0,0,0,0,0,0,0,0,0,0,0,0,0,0,0,0,0
0,0,0,0,0,0,0,0,0,0,0,0,0,0,0,0,0
0,0,0,0,0,0,0,0,0,0,0,0,0,0,0,0,0
0,0,0,0,0,0,0,0,0,0,0,0,0,0,0,0,0
:endlayer
layer: 24
0,0,0,0,0,0,0,0,0,0,0,0,0,0,0,0,0
0,0,0,0,0,0,0,0,0,0,0,0,0,0,0,0,0
0,0,0,0,0,0,0,0,0,0,0,0,0,0,0,0,0
0,0,0,0,0,0,0,0,0,0,0,0,0,0,0,0,0
0,0,0,0,0,0,0,0,0,0,0,0,0,0,0,0,0
0,0,0,0,0,0,0,0,0,0,0,0,0,0,0,0,0
0,0,0,0,0,0,0,0,0,0,0,0,0,0,0,0,0
0,0,0,0,0,0,0,0,0,0,0,0,0,0,0,0,0
0,0,0,0,0,0,0,0,0,0,0,0,0,0,0,0,0
0,0,0,0,0,0,0,0,0,0,0,0,0,0,0,0,0
0,0,0,0,0,0,0,0,0,0,0,0,0,0,0,0,0
0,0,0,0,0,0,0,0,0,0,0,0,0,0,0,0,0
0,0,0,0,0,0,0,0,0,0,0,0,0,0,0,0,0
0,0,0,0,0,0,0,0,0,0,0,0,0,0,0,0,0
0,0,0,0,0,0,0,0,0,0,0,0,0,0,0,0,0
0,0,0,0,0,0,0,0,0,0,0,0,0,0,0,0,0
0,0,0,0,0,0,0,0,0,0,0,0,0,0,0,0,0
:endlayer
layer: 25
0,0,0,0,0,0,0,0,0,0,0,0,0,0,0,0,0
0,0,0,0,0,0,0,0,0,0,0,0,0,0,0,0,0
0,0,0,0,0,0,0,0,0,0,0,0,0,0,0,0,0
0,0,0,0,0,0,0,0,0,0,0,0,0,0,0,0,0
0,0,0,0,0,0,0,0,0,0,0,0,0,0,0,0,0
0,0,0,0,0,0,0,0,0,0,0,0,0,0,0,0,0
0,0,0,0,0,0,0,0,0,0,0,0,0,0,0,0,0
0,0,0,0,0,0,0,0,0,0,0,0,0,0,0,0,0
0,0,0,0,0,0,0,0,0,0,0,0,0,0,0,0,0
0,0,0,0,0,0,0,0,0,0,0,0,0,0,0,0,0
0,0,0,0,0,0,0,0,0,0,0,0,0,0,0,0,0
0,0,0,0,0,0,0,0,0,0,0,0,0,0,0,0,0
0,0,0,0,0,0,0,0,0,0,0,0,0,0,0,0,0
0,0,0,0,0,0,0,0,0,0,0,0,0,0,0,0,0
0,0,0,0,0,0,0,0,0,0,0,0,0,0,0,0,0
0,0,0,0,0,0,0,0,0,0,0,0,0,0,0,0,0
0,0,0,0,0,0,0,0,0,0,0,0,0,0,0,0,0
:endlayer
layer: 26
0,0,0,0,0,0,0,0,0,0,0,0,0,0,0,0,0
0,0,0,0,0,0,0,0,0,0,0,0,0,0,0,0,0
0,0,0,0,0,0,0,0,0,0,0,0,0,0,0,0,0
0,0,0,0,0,0,0,0,0,0,0,0,0,0,0,0,0
0,0,0,0,0,0,0,0,0,0,0,0,0,0,0,0,0
0,0,0,0,0,0,0,0,0,0,0,0,0,0,0,0,0
0,0,0,0,0,0,0,0,0,0,0,0,0,0,0,0,0
0,0,0,0,0,0,0,0,0,0,0,0,0,0,0,0,0
0,0,0,0,0,0,0,0,0,0,0,0,0,0,0,0,0
0,0,0,0,0,0,0,0,0,0,0,0,0,0,0,0,0
0,0,0,0,0,0,0,0,0,0,0,0,0,0,0,0,0
0,0,0,0,0,0,0,0,0,0,0,0,0,0,0,0,0
0,0,0,0,0,0,0,0,0,0,0,0,0,0,0,0,0
0,0,0,0,0,0,0,0,0,0,0,0,0,0,0,0,0
0,0,0,0,0,0,0,0,0,0,0,0,0,0,0,0,0
0,0,0,0,0,0,0,0,0,0,0,0,0,0,0,0,0
0,0,0,0,0,0,0,0,0,0,0,0,0,0,0,0,0
:endlayer
layer: 27
0,0,0,0,0,0,0,0,0,0,0,0,0,0,0,0,0
0,0,0,0,0,0,0,0,0,0,0,0,0,0,0,0,0
0,0,0,0,0,0,0,0,0,0,0,0,0,0,0,0,0
0,0,0,0,0,0,0,0,0,0,0,0,0,0,0,0,0
0,0,0,0,0,0,0,0,0,0,0,0,0,0,0,0,0
0,0,0,0,0,0,0,0,0,0,0,0,0,0,0,0,0
0,0,0,0,0,0,0,0,0,0,0,0,0,0,0,0,0
0,0,0,0,0,0,0,0,0,0,0,0,0,0,0,0,0
0,0,0,0,0,0,0,0,0,0,0,0,0,0,0,0,0
0,0,0,0,0,0,0,0,0,0,0,0,0,0,0,0,0
0,0,0,0,0,0,0,0,0,0,0,0,0,0,0,0,0
0,0,0,0,0,0,0,0,0,0,0,0,0,0,0,0,0
0,0,0,0,0,0,0,0,0,0,0,0,0,0,0,0,0
0,0,0,0,0,0,0,0,0,0,0,0,0,0,0,0,0
0,0,0,0,0,0,0,0,0,0,0,0,0,0,0,0,0
0,0,0,0,0,0,0,0,0,0,0,0,0,0,0,0,0
0,0,0,0,0,0,0,0,0,0,0,0,0,0,0,0,0
:endlayer
layer: 28
0,0,0,0,0,0,0,0,0,0,0,0,0,0,0,0,0
0,0,0,0,0,0,0,0,0,0,0,0,0,0,0,0,0
0,0,0,0,0,0,0,0,0,0,0,0,0,0,0,0,0
0,0,0,0,0,0,0,0,0,0,0,0,0,0,0,0,0
0,0,0,0,0,0,0,0,0,0,0,0,0,0,0,0,0
0,0,0,0,0,0,0,0,0,0,0,0,0,0,0,0,0
0,0,0,0,0,0,0,0,0,0,0,0,0,0,0,0,0
0,0,0,0,0,0,0,0,0,0,0,0,0,0,0,0,0
0,0,0,0,0,0,0,0,0,0,0,0,0,0,0,0,0
0,0,0,0,0,0,0,0,0,0,0,0,0,0,0,0,0
0,0,0,0,0,0,0,0,0,0,0,0,0,0,0,0,0
0,0,0,0,0,0,0,0,0,0,0,0,0,0,0,0,0
0,0,0,0,0,0,0,0,0,0,0,0,0,0,0,0,0
0,0,0,0,0,0,0,0,0,0,0,0,0,0,0,0,0
0,0,0,0,0,0,0,0,0,0,0,0,0,0,0,0,0
0,0,0,0,0,0,0,0,0,0,0,0,0,0,0,0,0
0,0,0,0,0,0,0,0,0,0,0,0,0,0,0,0,0
:endlayer
layer: 29
0,0,0,0,0,0,0,0,0,0,0,0,0,0,0,0,0
0,0,0,0,0,0,0,0,0,0,0,0,0,0,0,0,0
0,0,0,0,0,0,0,0,0,0,0,0,0,0,0,0,0
0,0,0,0,0,0,0,0,0,0,0,0,0,0,0,0,0
0,0,0,0,0,0,0,0,0,0,0,0,0,0,0,0,0
0,0,0,0,0,0,0,0,0,0,0,0,0,0,0,0,0
0,0,0,0,0,0,0,0,0,0,0,0,0,0,0,0,0
0,0,0,0,0,0,0,0,0,0,0,0,0,0,0,0,0
0,0,0,0,0,0,0,0,0,0,0,0,0,0,0,0,0
0,0,0,0,0,0,0,0,0,0,0,0,0,0,0,0,0
0,0,0,0,0,0,0,0,0,0,0,0,0,0,0,0,0
0,0,0,0,0,0,0,0,0,0,0,0,0,0,0,0,0
0,0,0,0,0,0,0,0,0,0,0,0,0,0,0,0,0
0,0,0,0,0,0,0,0,0,0,0,0,0,0,0,0,0
0,0,0,0,0,0,0,0,0,0,0,0,0,0,0,0,0
0,0,0,0,0,0,0,0,0,0,0,0,0,0,0,0,0
0,0,0,0,0,0,0,0,0,0,0,0,0,0,0,0,0
:endlayer

#### RULES ####
rule:
plugin=vanillaBlocks
number=1
data:
JSON:{{"val":{"blockName":{"val":"minecraft:dirt","id":"ss"},"meta":{"val":"0","id":"pi"},"buildPass":{"val":"0","id":"pi"}},"id":"ct"}}
:enddata
:endrule

rule:
plugin=vanillaBlocks
number=2
data:
JSON:{{"val":{"blockName":{"val":"minecraft:cobblestone","id":"ss"},"meta":{"val":"0","id":"pi"},"buildPass":{"val":"0","id":"pi"}},"id":"ct"}}
:enddata
:endrule

rule:
plugin=vanillaBlocks
number=3
data:
JSON:{{"val":{"blockName":{"val":"minecraft:gravel","id":"ss"},"meta":{"val":"0","id":"pi"},"buildPass":{"val":"0","id":"pi"}},"id":"ct"}}
:enddata
:endrule

rule:
plugin=vanillaBlocks
number=4
data:
JSON:{{"val":{"blockName":{"val":"minecraft:grass","id":"ss"},"meta":{"val":"0","id":"pi"},"buildPass":{"val":"0","id":"pi"}},"id":"ct"}}
:enddata
:endrule

rule:
plugin=vanillaBlocks
number=5
data:
JSON:{{"val":{"blockName":{"val":"minecraft:planks","id":"ss"},"meta":{"val":"0","id":"pi"},"buildPass":{"val":"0","id":"pi"}},"id":"ct"}}
:enddata
:endrule

rule:
plugin=vanillaBlocks
number=6
data:
JSON:{{"val":{"blockName":{"val":"minecraft:tallgrass","id":"ss"},"meta":{"val":"1","id":"pi"},"buildPass":{"val":"2","id":"pi"}},"id":"ct"}}
:enddata
:endrule

rule:
plugin=vanillaBlocks
number=7
data:
JSON:{{"val":{"blockName":{"val":"minecraft:red_flower","id":"ss"},"meta":{"val":"0","id":"pi"},"buildPass":{"val":"2","id":"pi"}},"id":"ct"}}
:enddata
:endrule

rule:
plugin=vanillaBlocks
number=8
data:
JSON:{{"val":{"blockName":{"val":"minecraft:log","id":"ss"},"meta":{"val":"0","id":"pi"},"buildPass":{"val":"0","id":"pi"}},"id":"ct"}}
:enddata
:endrule

rule:
plugin=vanillaBlocks
number=9
data:
JSON:{{"val":{"blockName":{"val":"minecraft:fence","id":"ss"},"meta":{"val":"0","id":"pi"},"buildPass":{"val":"0","id":"pi"}},"id":"ct"}}
:enddata
:endrule

rule:
plugin=vanillaBlocks
number=10
data:
JSON:{{"val":{"blockName":{"val":"minecraft:tallgrass","id":"ss"},"meta":{"val":"2","id":"pi"},"buildPass":{"val":"2","id":"pi"}},"id":"ct"}}
:enddata
:endrule

rule:
plugin=vanillaBlocks
number=11
data:
JSON:{{"val":{"blockName":{"val":"minecraft:fence_gate","id":"ss"},"meta":{"val":"2","id":"pi"},"buildPass":{"val":"0","id":"pi"}},"id":"ct"}}
:enddata
:endrule

rule:
plugin=vanillaBlocks
number=12
data:
JSON:{{"val":{"blockName":{"val":"minecraft:oak_stairs","id":"ss"},"meta":{"val":"3","id":"pi"},"buildPass":{"val":"0","id":"pi"}},"id":"ct"}}
:enddata
:endrule

rule:
plugin=vanillaBlocks
number=13
data:
JSON:{{"val":{"blockName":{"val":"minecraft:stonebrick","id":"ss"},"meta":{"val":"0","id":"pi"},"buildPass":{"val":"0","id":"pi"}},"id":"ct"}}
:enddata
:endrule

rule:
plugin=vanillaBlocks
number=14
data:
JSON:{{"val":{"blockName":{"val":"minecraft:cauldron","id":"ss"},"meta":{"val":"3","id":"pi"},"buildPass":{"val":"0","id":"pi"}},"id":"ct"}}
:enddata
:endrule

rule:
plugin=vanillaInventory
number=15
data:
JSON:{{"val":{"lootLevel":{"val":"0","id":"pi"},"inventoryData":{"val":{"length":{"val":"27","id":"pi"},"inventoryContents":{"val":[],"id":"ls"}},"id":"ct"},"teData":{"val":{"id":{"val":"Chest","id":"ss"},"z":{"val":"861","id":"pi"},"y":{"val":"79","id":"pi"},"x":{"val":"1446","id":"pi"}},"id":"ct"},"blockName":{"val":"minecraft:chest","id":"ss"},"meta":{"val":"5","id":"pi"},"buildPass":{"val":"0","id":"pi"}},"id":"ct"}}
:enddata
:endrule

rule:
plugin=vanillaInventory
number=16
data:
JSON:{{"val":{"lootLevel":{"val":"0","id":"pi"},"inventoryData":{"val":{"length":{"val":"27","id":"pi"},"inventoryContents":{"val":[],"id":"ls"}},"id":"ct"},"teData":{"val":{"id":{"val":"Chest","id":"ss"},"z":{"val":"861","id":"pi"},"y":{"val":"79","id":"pi"},"x":{"val":"1447","id":"pi"}},"id":"ct"},"blockName":{"val":"minecraft:chest","id":"ss"},"meta":{"val":"5","id":"pi"},"buildPass":{"val":"0","id":"pi"}},"id":"ct"}}
:enddata
:endrule

rule:
plugin=vanillaSign
number=17
data:
JSON:{{"val":{"blockName":{"val":"minecraft:wall_sign","id":"ss"},"signContents1":{"val":"","id":"ss"},"signContents2":{"val":"","id":"ss"},"signContents0":{"val":"","id":"ss"},"meta":{"val":"3","id":"pi"},"signContents3":{"val":"","id":"ss"},"buildPass":{"val":"2","id":"pi"}},"id":"ct"}}
:enddata
:endrule

rule:
plugin=vanillaBlocks
number=18
data:
JSON:{{"val":{"blockName":{"val":"minecraft:oak_stairs","id":"ss"},"meta":{"val":"1","id":"pi"},"buildPass":{"val":"0","id":"pi"}},"id":"ct"}}
:enddata
:endrule

rule:
plugin=vanillaBlocks
number=19
data:
JSON:{{"val":{"blockName":{"val":"minecraft:double_stone_slab","id":"ss"},"meta":{"val":"0","id":"pi"},"buildPass":{"val":"0","id":"pi"}},"id":"ct"}}
:enddata
:endrule

rule:
plugin=vanillaDoors
number=20
data:
JSON:{{"val":{"sideFlag":{"val":"10","id":"pb"},"blockName":{"val":"minecraft:wooden_door","id":"ss"},"meta":{"val":"1","id":"pi"},"buildPass":{"val":"2","id":"pi"}},"id":"ct"}}
:enddata
:endrule

rule:
plugin=awAutomationLogic
number=21
data:
JSON:{{"val":{"teData":{"val":{"id":{"val":"Furnace","id":"ss"},"Items":{"val":[],"id":"ls"},"BurnTime":{"val":"0","id":"ps"},"z":{"val":"864","id":"pi"},"y":{"val":"79","id":"pi"},"CookTime":{"val":"0","id":"ps"},"x":{"val":"1447","id":"pi"}},"id":"ct"},"blockName":{"val":"minecraft:furnace","id":"ss"},"meta":{"val":"4","id":"pi"},"buildPass":{"val":"0","id":"pi"}},"id":"ct"}}
:enddata
:endrule

rule:
plugin=vanillaBlocks
number=22
data:
JSON:{{"val":{"blockName":{"val":"minecraft:crafting_table","id":"ss"},"meta":{"val":"0","id":"pi"},"buildPass":{"val":"0","id":"pi"}},"id":"ct"}}
:enddata
:endrule

rule:
plugin=vanillaSign
number=23
data:
JSON:{{"val":{"blockName":{"val":"minecraft:wall_sign","id":"ss"},"signContents1":{"val":"","id":"ss"},"signContents2":{"val":"","id":"ss"},"signContents0":{"val":"","id":"ss"},"meta":{"val":"3","id":"pi"},"signContents3":{"val":"","id":"ss"},"buildPass":{"val":"2","id":"pi"}},"id":"ct"}}
:enddata
:endrule

rule:
plugin=vanillaBlocks
number=24
data:
JSON:{{"val":{"blockName":{"val":"minecraft:oak_stairs","id":"ss"},"meta":{"val":"0","id":"pi"},"buildPass":{"val":"0","id":"pi"}},"id":"ct"}}
:enddata
:endrule

rule:
plugin=vanillaBlocks
number=25
data:
JSON:{{"val":{"blockName":{"val":"minecraft:bookshelf","id":"ss"},"meta":{"val":"0","id":"pi"},"buildPass":{"val":"0","id":"pi"}},"id":"ct"}}
:enddata
:endrule

rule:
plugin=vanillaDoors
number=26
data:
JSON:{{"val":{"sideFlag":{"val":"10","id":"pb"},"blockName":{"val":"minecraft:wooden_door","id":"ss"},"meta":{"val":"3","id":"pi"},"buildPass":{"val":"2","id":"pi"}},"id":"ct"}}
:enddata
:endrule

rule:
plugin=vanillaBlocks
number=27
data:
JSON:{{"val":{"blockName":{"val":"minecraft:torch","id":"ss"},"meta":{"val":"5","id":"pi"},"buildPass":{"val":"2","id":"pi"}},"id":"ct"}}
:enddata
:endrule

rule:
plugin=vanillaDoors
number=28
data:
JSON:{{"val":{"sideFlag":{"val":"0","id":"pb"},"blockName":{"val":"minecraft:wooden_door","id":"ss"},"meta":{"val":"10","id":"pi"},"buildPass":{"val":"2","id":"pi"}},"id":"ct"}}
:enddata
:endrule

rule:
plugin=vanillaDoors
number=29
data:
JSON:{{"val":{"sideFlag":{"val":"0","id":"pb"},"blockName":{"val":"minecraft:wooden_door","id":"ss"},"meta":{"val":"10","id":"pi"},"buildPass":{"val":"2","id":"pi"}},"id":"ct"}}
:enddata
:endrule

rule:
plugin=vanillaBlocks
number=30
data:
JSON:{{"val":{"blockName":{"val":"minecraft:torch","id":"ss"},"meta":{"val":"2","id":"pi"},"buildPass":{"val":"2","id":"pi"}},"id":"ct"}}
:enddata
:endrule

rule:
plugin=vanillaBlocks
number=31
data:
JSON:{{"val":{"blockName":{"val":"minecraft:torch","id":"ss"},"meta":{"val":"3","id":"pi"},"buildPass":{"val":"2","id":"pi"}},"id":"ct"}}
:enddata
:endrule

rule:
plugin=vanillaBlocks
number=32
data:
JSON:{{"val":{"blockName":{"val":"minecraft:torch","id":"ss"},"meta":{"val":"4","id":"pi"},"buildPass":{"val":"2","id":"pi"}},"id":"ct"}}
:enddata
:endrule

rule:
plugin=vanillaBlocks
number=33
data:
JSON:{{"val":{"blockName":{"val":"minecraft:torch","id":"ss"},"meta":{"val":"1","id":"pi"},"buildPass":{"val":"2","id":"pi"}},"id":"ct"}}
:enddata
:endrule

rule:
plugin=vanillaBlocks
number=34
data:
JSON:{{"val":{"blockName":{"val":"minecraft:glass_pane","id":"ss"},"meta":{"val":"0","id":"pi"},"buildPass":{"val":"0","id":"pi"}},"id":"ct"}}
:enddata
:endrule

rule:
plugin=vanillaInventory
number=35
data:
JSON:{{"val":{"lootLevel":{"val":"0","id":"pi"},"inventoryData":{"val":{"length":{"val":"27","id":"pi"},"inventoryContents":{"val":[],"id":"ls"}},"id":"ct"},"teData":{"val":{"id":{"val":"Chest","id":"ss"},"z":{"val":"860","id":"pi"},"y":{"val":"84","id":"pi"},"x":{"val":"1444","id":"pi"}},"id":"ct"},"blockName":{"val":"minecraft:chest","id":"ss"},"meta":{"val":"2","id":"pi"},"buildPass":{"val":"0","id":"pi"}},"id":"ct"}}
:enddata
:endrule

rule:
plugin=vanillaInventory
number=36
data:
JSON:{{"val":{"lootLevel":{"val":"0","id":"pi"},"inventoryData":{"val":{"length":{"val":"27","id":"pi"},"inventoryContents":{"val":[],"id":"ls"}},"id":"ct"},"teData":{"val":{"id":{"val":"Chest","id":"ss"},"z":{"val":"861","id":"pi"},"y":{"val":"84","id":"pi"},"x":{"val":"1444","id":"pi"}},"id":"ct"},"blockName":{"val":"minecraft:chest","id":"ss"},"meta":{"val":"2","id":"pi"},"buildPass":{"val":"0","id":"pi"}},"id":"ct"}}
:enddata
:endrule

rule:
plugin=vanillaBlocks
number=37
data:
JSON:{{"val":{"blockName":{"val":"minecraft:oak_stairs","id":"ss"},"meta":{"val":"2","id":"pi"},"buildPass":{"val":"0","id":"pi"}},"id":"ct"}}
:enddata
:endrule

rule:
plugin=vanillaBlocks
number=38
data:
JSON:{{"val":{"blockName":{"val":"minecraft:bed","id":"ss"},"meta":{"val":"3","id":"pi"},"buildPass":{"val":"2","id":"pi"}},"id":"ct"}}
:enddata
:endrule

rule:
plugin=vanillaBlocks
number=39
data:
JSON:{{"val":{"blockName":{"val":"minecraft:bed","id":"ss"},"meta":{"val":"11","id":"pi"},"buildPass":{"val":"2","id":"pi"}},"id":"ct"}}
:enddata
:endrule

rule:
plugin=vanillaDoors
number=40
data:
JSON:{{"val":{"sideFlag":{"val":"0","id":"pb"},"blockName":{"val":"minecraft:wooden_door","id":"ss"},"meta":{"val":"10","id":"pi"},"buildPass":{"val":"2","id":"pi"}},"id":"ct"}}
:enddata
:endrule

rule:
plugin=vanillaBlocks
number=41
data:
JSON:{{"val":{"blockName":{"val":"minecraft:stone_pressure_plate","id":"ss"},"meta":{"val":"0","id":"pi"},"buildPass":{"val":"2","id":"pi"}},"id":"ct"}}
:enddata
:endrule

rule:
plugin=vanillaBlocks
number=42
data:
JSON:{{"val":{"blockName":{"val":"minecraft:wooden_slab","id":"ss"},"meta":{"val":"0","id":"pi"},"buildPass":{"val":"0","id":"pi"}},"id":"ct"}}
:enddata
:endrule

rule:
plugin=vanillaBlocks
number=43
data:
JSON:{{"val":{"blockName":{"val":"minecraft:double_wooden_slab","id":"ss"},"meta":{"val":"0","id":"pi"},"buildPass":{"val":"0","id":"pi"}},"id":"ct"}}
:enddata
:endrule

rule:
plugin=vanillaBlocks
number=44
data:
JSON:{{"val":{"blockName":{"val":"minecraft:wooden_slab","id":"ss"},"meta":{"val":"8","id":"pi"},"buildPass":{"val":"0","id":"pi"}},"id":"ct"}}
:enddata
:endrule

rule:
plugin=vanillaBlocks
number=45
data:
JSON:{{"val":{"blockName":{"val":"minecraft:stone_slab","id":"ss"},"meta":{"val":"2","id":"pi"},"buildPass":{"val":"0","id":"pi"}},"id":"ct"}}
:enddata
:endrule

rule:
plugin=vanillaInventory
number=46
data:
JSON:{{"val":{"lootLevel":{"val":"1","id":"pi"},"inventoryData":{"val":{"length":{"val":"27","id":"pi"},"inventoryContents":{"val":[{"val":{"item":{"val":"minecraft:gold_ingot","id":"ss"},"damage":{"val":"0","id":"pi"},"quantity":{"val":"1","id":"pi"},"slot":{"val":"0","id":"pi"}},"id":"ct"}],"id":"ls"}},"id":"ct"},"teData":{"val":{"id":{"val":"Chest","id":"ss"},"z":{"val":"861","id":"pi"},"y":{"val":"88","id":"pi"},"x":{"val":"1446","id":"pi"}},"id":"ct"},"blockName":{"val":"minecraft:chest","id":"ss"},"meta":{"val":"5","id":"pi"},"buildPass":{"val":"0","id":"pi"}},"id":"ct"}}
:enddata
:endrule

rule:
plugin=vanillaInventory
number=47
data:
JSON:{{"val":{"lootLevel":{"val":"0","id":"pi"},"inventoryData":{"val":{"length":{"val":"27","id":"pi"},"inventoryContents":{"val":[],"id":"ls"}},"id":"ct"},"teData":{"val":{"id":{"val":"Chest","id":"ss"},"z":{"val":"861","id":"pi"},"y":{"val":"88","id":"pi"},"x":{"val":"1447","id":"pi"}},"id":"ct"},"blockName":{"val":"minecraft:chest","id":"ss"},"meta":{"val":"5","id":"pi"},"buildPass":{"val":"0","id":"pi"}},"id":"ct"}}
:enddata
:endrule

rule:
plugin=vanillaBlocks
number=48
data:
JSON:{{"val":{"blockName":{"val":"minecraft:double_stone_slab","id":"ss"},"meta":{"val":"2","id":"pi"},"buildPass":{"val":"0","id":"pi"}},"id":"ct"}}
:enddata
:endrule

rule:
plugin=vanillaInventory
number=49
data:
JSON:{{"val":{"lootLevel":{"val":"3","id":"pi"},"inventoryData":{"val":{"length":{"val":"27","id":"pi"},"inventoryContents":{"val":[{"val":{"item":{"val":"minecraft:emerald","id":"ss"},"damage":{"val":"0","id":"pi"},"quantity":{"val":"1","id":"pi"},"slot":{"val":"0","id":"pi"}},"id":"ct"}],"id":"ls"}},"id":"ct"},"teData":{"val":{"id":{"val":"Chest","id":"ss"},"z":{"val":"864","id":"pi"},"y":{"val":"88","id":"pi"},"x":{"val":"1446","id":"pi"}},"id":"ct"},"blockName":{"val":"minecraft:chest","id":"ss"},"meta":{"val":"4","id":"pi"},"buildPass":{"val":"0","id":"pi"}},"id":"ct"}}
:enddata
:endrule

rule:
plugin=vanillaInventory
number=50
data:
JSON:{{"val":{"lootLevel":{"val":"0","id":"pi"},"inventoryData":{"val":{"length":{"val":"27","id":"pi"},"inventoryContents":{"val":[],"id":"ls"}},"id":"ct"},"teData":{"val":{"id":{"val":"Chest","id":"ss"},"z":{"val":"864","id":"pi"},"y":{"val":"88","id":"pi"},"x":{"val":"1447","id":"pi"}},"id":"ct"},"blockName":{"val":"minecraft:chest","id":"ss"},"meta":{"val":"4","id":"pi"},"buildPass":{"val":"0","id":"pi"}},"id":"ct"}}
:enddata
:endrule

rule:
plugin=vanillaDoors
number=51
data:
JSON:{{"val":{"sideFlag":{"val":"11","id":"pb"},"blockName":{"val":"minecraft:wooden_door","id":"ss"},"meta":{"val":"1","id":"pi"},"buildPass":{"val":"2","id":"pi"}},"id":"ct"}}
:enddata
:endrule

rule:
plugin=vanillaDoors
number=52
data:
JSON:{{"val":{"sideFlag":{"val":"0","id":"pb"},"blockName":{"val":"minecraft:wooden_door","id":"ss"},"meta":{"val":"11","id":"pi"},"buildPass":{"val":"2","id":"pi"}},"id":"ct"}}
:enddata
:endrule

rule:
plugin=vanillaDoors
number=53
data:
JSON:{{"val":{"sideFlag":{"val":"0","id":"pb"},"blockName":{"val":"minecraft:wooden_door","id":"ss"},"meta":{"val":"10","id":"pi"},"buildPass":{"val":"2","id":"pi"}},"id":"ct"}}
:enddata
:endrule

#### ENTITIES ####
