# Ancient Warfare Structure Template File
# Auto-generated structure template file. created on: 11/3/2014 at: 17:36:24
# Lines beginning with # denote comments

header:
version=2.1
name=big_fortress
size=49,25,56
offset=24,6,55
:endheader

#### VALIDATION ####
validation:
type=ground
survival=false
worldGenEnabled=true
unique=false
preserveBlocks=false
selectionWeight=10
clusterValue=125
minDuplicateDistance=40
dimensionWhiteList=true
dimensionList=0
biomeWhiteList=true
biomeList=desert,plains,forest
leveling=8
fill=8
border=8
validTargetBlocks=minecraft:sand,minecraft:stone,minecraft:gravel,minecraft:redstone_ore,minecraft:lapis_ore,minecraft:stained_hardened_clay,minecraft:gold_ore,minecraft:clay,minecraft:iron_ore,minecraft:grass,minecraft:mycelium,minecraft:dirt,minecraft:diamond_ore,minecraft:snow,minecraft:coal_ore
blockSwap=false
data:
:enddata
:endvalidation

#### LAYERS ####
layer: 0
1,1,1,2,1,1,1,1,1,1,1,1,1,1,1,1,1,1,1,3,3,3,3,1,4,4,1,1,1,1,1,1,1,1,1,1,1,1,1,1,1,1,1,1,1,1,1,1,1
1,1,1,2,1,1,1,1,1,1,1,1,1,1,1,1,1,1,3,3,3,3,1,1,1,4,1,1,1,1,1,1,1,1,1,1,1,1,1,1,1,1,1,1,1,1,1,1,1
1,1,1,1,1,1,1,1,1,1,1,1,1,1,1,1,1,1,3,3,3,3,1,1,1,1,1,1,1,1,1,1,1,1,1,1,1,1,4,4,1,1,1,1,1,1,1,1,1
1,1,1,1,1,1,1,1,1,1,1,1,1,1,1,1,1,3,3,3,3,1,1,1,1,1,1,1,1,1,1,1,1,1,1,1,1,1,1,2,1,1,1,1,1,1,1,1,1
1,1,3,3,3,3,1,1,1,1,1,1,1,1,1,1,1,3,3,3,1,1,1,1,1,1,1,1,1,1,1,1,1,1,1,1,1,1,2,2,1,1,1,1,1,1,1,1,1
1,1,3,3,3,3,3,3,1,1,1,1,1,1,1,1,1,1,1,1,1,1,1,1,1,1,1,1,1,1,1,1,1,1,1,1,1,1,2,2,2,1,1,1,1,1,1,1,1
1,1,3,3,3,3,3,3,3,1,1,1,1,1,1,1,1,1,1,1,1,1,1,1,1,1,1,1,1,1,1,1,1,1,1,1,1,1,2,2,1,1,1,1,1,1,1,1,1
1,1,1,3,3,3,3,3,3,3,1,1,1,1,1,1,1,1,1,1,1,1,1,1,1,1,1,1,1,1,1,1,1,1,1,1,1,1,2,2,1,1,1,1,1,1,1,1,1
1,1,1,1,3,3,3,3,3,3,1,1,1,1,1,1,1,1,1,1,1,1,1,1,1,1,1,1,1,1,1,1,1,1,1,1,1,1,2,1,1,1,1,1,1,1,1,1,1
1,1,1,1,1,1,3,3,3,3,1,1,1,1,1,1,1,1,1,1,1,1,1,1,1,1,1,1,1,1,1,1,1,1,1,1,1,1,1,1,1,1,1,1,1,1,1,1,1
1,1,1,1,1,1,1,1,1,1,1,1,1,1,1,1,1,2,2,1,1,1,1,1,1,1,1,1,1,1,1,1,1,1,1,1,1,1,1,1,1,1,1,1,1,1,1,1,1
1,1,1,1,1,1,1,1,1,1,1,1,1,1,1,1,2,2,2,1,1,1,1,1,1,1,1,1,1,1,1,1,1,1,1,1,1,1,1,1,1,1,1,1,1,1,1,1,1
1,1,1,1,1,1,1,1,1,1,1,1,1,1,1,1,2,2,1,1,1,1,1,1,1,1,1,1,1,1,1,1,1,1,1,1,1,1,1,1,1,1,1,1,1,1,1,1,2
1,1,1,1,1,1,3,1,1,1,1,1,1,1,1,1,1,1,1,1,1,1,1,1,1,1,1,1,1,1,1,1,1,1,1,1,1,1,1,1,1,1,1,1,1,1,1,1,2
1,1,1,1,1,3,3,3,1,1,1,1,1,1,1,1,1,1,1,1,1,1,1,1,1,1,1,1,1,1,1,1,1,1,1,1,1,1,1,1,1,1,1,1,1,1,1,1,1
1,1,1,1,1,3,3,3,1,1,1,1,1,1,1,1,1,1,1,1,1,1,1,1,1,1,1,1,1,1,1,1,1,1,1,1,1,1,1,1,1,1,1,1,1,1,1,1,1
1,1,1,1,1,3,3,3,3,1,1,1,1,1,1,1,1,1,1,1,4,4,1,1,1,1,1,1,1,1,1,5,5,1,1,1,1,1,5,5,5,5,1,1,1,1,1,1,5
1,1,1,1,1,3,3,3,3,1,1,1,1,1,1,1,1,1,1,1,4,4,1,1,1,1,1,1,1,1,1,5,5,1,1,1,1,5,5,5,5,5,5,5,1,1,1,1,5
1,1,1,1,1,3,3,3,3,1,1,1,1,1,1,1,1,1,1,1,1,1,1,1,1,1,1,1,1,1,5,5,5,1,1,1,1,1,5,5,5,5,5,5,5,1,1,1,1
1,1,1,1,1,5,5,3,3,1,1,1,1,1,1,1,1,1,1,1,1,1,1,1,1,1,1,1,1,5,5,5,5,1,1,1,1,1,1,5,5,5,5,5,5,5,1,1,1
1,1,1,1,1,5,5,5,5,1,1,1,1,1,1,1,1,1,1,1,1,1,1,1,1,1,1,1,1,5,5,5,5,1,1,1,1,1,1,1,5,5,5,5,5,5,1,1,1
1,1,1,1,1,1,5,5,5,5,1,1,1,1,1,1,1,1,1,1,1,1,1,1,1,1,1,1,5,5,5,5,1,1,1,1,1,1,1,1,1,1,5,5,5,5,1,1,1
1,1,1,1,1,1,5,5,5,5,5,1,1,1,1,1,1,1,1,1,1,1,1,1,1,1,1,1,5,5,5,5,1,1,1,1,1,1,1,1,1,1,1,1,1,1,1,1,1
1,1,1,1,1,1,1,5,5,5,5,1,1,1,1,1,1,1,1,1,1,1,1,1,1,1,1,1,5,5,5,1,1,1,1,1,1,1,1,1,1,1,1,1,1,1,1,1,1
1,1,1,1,1,1,1,1,5,5,5,1,1,1,1,1,1,1,1,1,1,1,1,1,1,1,1,1,1,5,1,1,1,1,1,1,1,1,1,1,1,1,1,1,1,1,1,1,1
1,1,1,1,1,1,1,4,4,1,1,1,1,1,1,1,1,1,1,1,1,1,1,1,1,1,1,1,1,1,1,1,1,1,1,1,1,1,1,1,1,1,1,1,1,1,1,1,1
1,1,1,1,1,1,1,4,4,1,1,1,4,1,1,1,1,1,1,1,1,1,1,1,1,1,1,1,1,1,1,1,1,1,1,1,1,1,1,1,1,1,1,1,1,1,1,1,1
1,1,1,1,1,1,1,1,1,1,1,1,4,1,1,1,1,1,1,1,1,1,1,1,1,1,1,1,1,1,1,1,1,1,1,1,1,1,1,1,1,1,1,1,1,1,1,2,2
5,5,5,1,1,1,1,1,1,1,1,1,1,1,1,1,1,1,1,1,1,1,1,1,1,1,1,1,1,1,1,1,1,1,1,1,1,1,1,1,1,1,1,1,1,1,1,2,2
5,5,5,1,1,1,1,1,1,1,1,1,1,1,1,1,1,1,1,1,1,1,1,5,5,5,5,5,5,1,1,1,1,1,1,1,1,1,1,1,1,1,1,1,1,1,1,1,2
5,5,5,1,1,1,1,1,1,1,1,1,1,1,1,1,1,1,1,1,1,1,1,5,5,5,5,5,5,1,1,1,1,1,1,1,1,1,1,1,1,1,1,1,1,1,1,1,1
5,5,5,1,1,1,1,1,1,1,1,1,1,1,1,1,1,1,1,1,1,1,1,5,5,5,5,5,5,1,1,1,1,1,1,1,1,2,2,1,1,1,1,1,1,1,1,1,1
5,5,1,1,1,1,1,1,1,1,1,1,1,1,1,1,1,1,1,1,3,3,1,5,5,5,1,1,1,1,1,1,1,1,1,1,2,2,1,1,1,1,1,1,1,1,1,1,1
5,1,1,1,1,1,1,1,1,1,1,1,1,1,1,1,1,1,1,3,3,3,3,1,1,1,1,1,1,1,1,1,1,1,1,1,2,2,1,4,4,1,1,1,5,1,1,1,1
5,1,1,1,1,1,1,1,1,1,1,1,1,1,1,1,1,1,1,3,3,3,3,1,1,1,1,1,1,1,1,1,1,1,1,1,1,1,1,1,4,5,5,5,5,5,1,1,1
5,1,1,1,1,1,1,1,1,1,1,1,1,1,1,1,1,1,1,3,3,3,3,1,1,1,1,1,1,1,1,1,1,1,1,1,1,1,1,5,5,5,5,5,5,1,1,1,1
1,1,1,1,1,1,1,1,1,1,1,1,1,1,1,1,1,1,1,3,3,3,3,1,1,1,1,1,1,1,1,1,1,1,1,1,1,1,5,5,5,5,5,5,5,1,1,1,1
1,6,6,6,6,6,6,6,6,6,6,1,1,1,1,1,1,1,1,3,3,3,3,1,1,1,1,1,1,1,1,1,1,1,1,1,1,1,5,5,5,5,5,1,2,1,1,1,1
1,6,6,6,6,6,6,6,6,6,6,1,1,1,1,1,1,1,1,3,3,3,3,1,1,1,1,1,1,1,1,1,1,1,1,1,1,1,5,5,5,5,1,2,3,2,1,1,1
1,6,6,6,6,6,6,6,6,6,6,1,1,1,1,1,1,1,1,1,3,3,1,1,1,1,1,1,1,1,1,1,1,1,1,1,1,1,1,1,1,1,2,2,3,1,1,1,1
1,6,6,6,6,6,6,6,6,6,6,1,1,1,1,1,1,1,1,1,3,3,1,1,1,1,1,1,1,1,1,1,1,1,1,1,1,1,1,1,1,1,2,2,1,1,1,1,1
1,6,6,6,6,6,6,6,6,6,6,1,1,1,1,1,1,1,1,1,1,1,1,1,1,1,1,1,1,1,1,1,1,1,1,1,1,1,1,1,1,1,1,1,2,1,1,1,1
1,6,6,6,6,6,6,6,6,6,6,1,1,1,1,1,1,1,1,1,1,1,1,1,1,1,1,1,1,1,1,1,1,1,1,1,1,1,1,1,1,1,1,1,2,1,1,1,1
1,6,6,6,6,6,6,6,6,6,6,1,1,1,1,1,1,1,1,1,1,1,1,1,1,1,0,1,1,1,1,1,1,1,1,1,1,1,1,1,1,1,3,3,3,1,1,1,1
1,6,6,6,6,6,6,6,6,6,6,1,1,1,1,1,1,1,1,1,1,1,1,1,1,1,0,1,1,1,1,1,1,1,1,1,1,1,1,1,1,1,3,3,3,3,1,1,1
1,6,6,6,6,6,6,6,6,6,6,1,1,1,1,1,1,1,1,1,1,1,1,1,1,1,0,1,1,1,1,1,1,1,1,1,1,1,1,1,1,1,1,3,3,3,3,1,1
1,1,1,1,1,1,1,1,1,1,1,1,1,1,1,1,1,1,1,1,1,1,1,1,1,1,0,1,1,1,1,1,1,1,1,1,1,1,1,1,1,1,1,1,3,3,3,3,1
1,1,1,1,1,1,1,1,1,1,1,1,1,1,1,1,1,1,1,1,1,1,1,1,1,1,0,1,1,1,1,1,1,1,1,1,1,1,1,1,1,1,1,1,1,1,1,1,1
1,1,1,1,1,1,1,1,1,1,1,1,1,1,1,1,1,1,1,1,1,1,1,1,1,1,0,1,1,1,1,1,1,1,1,1,1,1,1,1,1,1,1,1,1,1,1,1,1
1,1,1,1,1,1,1,1,1,1,1,1,1,1,1,1,1,1,1,1,1,1,1,1,1,1,0,1,1,1,1,1,1,2,2,2,1,1,1,1,1,1,1,1,1,1,1,1,1
1,1,1,1,4,1,1,1,1,1,1,1,1,1,1,1,1,1,1,1,1,1,1,1,1,1,0,1,1,1,1,1,1,1,1,1,1,1,1,1,1,1,1,1,1,1,1,1,1
1,1,1,1,4,4,1,1,1,1,1,1,1,1,1,1,1,1,1,1,1,1,1,1,1,1,0,1,1,1,1,1,1,1,1,1,1,1,1,1,1,1,1,1,1,1,1,1,1
1,1,1,1,1,1,1,1,1,1,1,1,1,1,1,1,1,1,1,1,1,1,1,1,1,1,1,1,1,1,1,1,4,1,1,1,1,1,1,1,1,1,1,1,1,1,1,1,1
1,1,1,1,1,1,1,1,1,1,1,1,2,1,1,1,1,1,1,1,1,1,1,1,1,5,1,1,1,1,1,4,1,1,1,1,1,1,1,1,1,1,1,1,1,1,1,1,1
1,1,1,1,1,1,1,1,1,1,1,1,1,1,1,1,1,1,1,1,1,1,1,1,5,5,5,1,1,1,1,1,1,1,1,1,1,1,1,1,1,2,2,1,1,1,1,1,5
1,1,1,1,5,5,5,5,5,1,1,1,1,1,1,1,1,1,1,1,1,1,1,5,5,5,1,1,1,1,1,1,1,1,1,1,1,1,1,1,2,2,1,1,1,1,1,5,5
:endlayer
layer: 1
1,1,1,2,1,1,1,1,1,1,1,1,1,1,1,1,1,1,1,1,1,1,1,1,1,1,1,1,1,1,1,1,1,1,1,1,1,1,1,1,1,3,3,3,3,3,1,1,1
1,2,2,2,1,1,1,1,1,1,1,1,1,1,1,1,1,1,1,1,1,1,1,1,1,1,1,1,1,1,1,1,1,1,1,1,1,1,1,1,1,1,1,1,1,1,1,1,1
2,2,2,1,1,1,1,1,1,1,1,1,1,1,1,1,1,1,1,1,1,1,1,1,1,1,1,1,1,1,1,1,1,1,1,1,1,1,1,1,1,1,1,1,1,1,1,1,1
2,2,2,2,1,1,1,1,1,1,1,1,1,1,1,1,1,1,1,1,1,1,1,1,1,1,1,1,1,1,1,1,1,1,1,1,1,1,1,1,1,1,1,1,1,1,1,1,1
2,2,2,3,3,3,1,1,1,1,1,1,1,1,1,1,1,1,1,1,1,1,1,1,1,1,1,1,1,1,1,1,1,1,1,1,1,1,1,1,1,1,1,1,1,1,1,1,1
1,1,3,3,3,3,3,3,1,1,1,1,1,1,1,1,1,1,1,1,1,1,1,1,1,1,1,1,1,1,1,1,1,1,1,1,1,1,2,2,1,1,1,1,1,1,1,1,1
4,1,3,3,3,3,3,3,3,1,1,1,1,1,1,1,1,1,1,1,1,1,1,1,1,1,1,1,1,1,1,1,1,1,1,1,1,1,2,2,1,1,1,1,1,1,1,1,1
4,1,1,3,3,3,3,3,3,3,1,1,1,1,1,1,1,1,1,1,1,1,1,1,1,1,1,1,1,1,1,1,1,1,1,1,1,1,2,1,1,1,1,1,1,1,1,1,1
1,1,1,1,3,3,3,3,3,3,1,1,1,1,1,1,1,1,1,1,1,1,1,1,1,1,1,1,1,3,1,1,1,1,1,1,1,1,2,1,1,1,1,1,1,1,1,1,1
1,1,1,1,1,1,3,3,3,3,1,1,1,1,1,1,1,1,1,1,1,1,1,1,1,1,1,1,1,3,3,1,1,1,1,1,1,1,1,1,1,1,1,1,1,1,1,1,1
1,1,1,1,1,1,1,1,1,1,1,1,1,1,1,1,1,1,1,1,1,1,1,1,1,1,1,1,1,3,3,3,1,1,1,1,1,1,1,1,1,1,1,1,1,1,1,1,1
1,1,1,1,1,1,1,1,1,1,1,1,1,1,1,1,2,2,1,1,1,1,1,1,1,1,1,1,1,3,3,3,1,1,1,1,1,1,1,1,1,1,1,1,1,1,1,1,1
1,1,1,1,1,1,1,1,1,1,1,1,1,1,1,1,2,2,1,1,1,1,1,1,1,1,1,1,1,1,3,3,1,1,1,1,1,1,1,1,1,1,1,1,1,1,1,1,1
1,1,1,1,1,1,1,1,1,1,1,1,1,1,2,2,2,1,1,1,1,1,1,1,1,1,1,1,1,1,1,3,1,1,1,1,1,1,1,1,1,1,1,1,1,1,1,1,1
1,1,1,1,1,1,1,1,1,1,1,1,1,1,2,2,2,1,1,1,1,1,1,1,1,1,1,1,1,1,1,1,1,1,1,1,1,1,1,1,1,1,1,1,1,1,1,1,1
1,1,1,1,1,1,1,1,1,1,1,1,1,1,1,1,1,1,1,1,1,1,1,1,1,1,1,1,1,1,1,1,5,5,1,1,1,1,1,1,1,1,1,1,2,2,1,1,1
1,1,1,1,1,5,5,5,1,1,1,1,1,1,1,1,1,1,1,1,1,1,1,1,1,1,1,1,1,1,1,5,5,5,1,1,1,1,5,5,5,5,1,1,2,2,1,1,1
1,1,1,5,5,5,5,5,1,1,1,1,1,1,1,1,1,1,1,1,1,1,1,1,1,1,1,1,1,1,5,5,5,5,1,1,1,5,5,5,5,5,5,5,1,1,2,1,1
1,1,5,5,5,5,1,1,1,1,1,1,1,1,1,1,1,1,1,1,1,1,1,1,1,1,1,1,1,5,5,5,5,5,1,1,1,1,5,5,5,5,5,5,5,1,1,1,1
1,1,5,5,5,1,1,1,1,1,1,1,1,1,1,0,0,0,0,1,1,1,1,1,1,1,1,1,1,5,5,5,5,5,1,1,1,1,1,5,5,5,5,5,5,5,1,1,1
1,1,1,1,1,1,1,1,1,1,1,1,1,1,1,0,0,0,0,1,1,1,1,1,1,1,1,1,1,5,5,5,5,1,1,1,1,1,1,1,5,5,5,5,5,5,1,1,1
1,1,1,1,1,1,1,5,5,1,1,1,1,1,1,1,0,0,1,1,1,1,1,1,1,1,1,1,5,5,5,5,5,1,1,1,1,1,1,1,1,1,5,5,5,5,1,1,1
1,1,1,1,1,1,1,5,5,1,1,1,1,1,1,1,1,1,1,1,1,1,1,1,1,1,1,1,5,5,5,5,1,1,1,1,1,1,1,1,1,1,1,1,1,1,1,1,1
1,1,1,1,1,1,1,1,1,1,1,1,1,1,1,1,1,1,1,1,1,1,1,1,1,1,1,1,5,5,5,1,1,1,1,1,1,1,1,1,1,1,1,1,1,1,1,1,1
1,1,1,1,1,1,1,1,1,1,1,1,1,1,1,1,1,1,1,1,1,1,1,1,1,1,1,1,1,5,1,1,1,1,1,1,1,1,1,1,1,1,1,1,1,1,1,1,1
1,1,1,1,1,1,1,4,4,1,1,1,1,1,1,1,1,1,1,1,1,1,1,1,1,1,1,1,1,1,1,1,1,1,1,1,1,1,1,1,1,1,1,1,1,1,1,1,1
1,1,1,1,1,1,1,4,4,1,1,1,1,1,1,1,1,1,1,1,1,1,1,1,1,1,1,1,1,1,1,1,1,1,1,1,1,1,1,1,1,1,1,1,1,1,1,1,1
1,1,1,1,1,1,1,1,1,1,1,2,2,1,1,1,1,1,1,1,1,1,1,1,1,1,1,1,1,1,1,1,1,1,1,1,1,1,1,1,1,1,1,1,1,1,1,1,1
1,1,1,1,1,1,1,1,1,1,1,2,2,1,1,1,1,1,1,1,1,1,1,1,1,1,1,1,1,1,1,1,1,1,1,1,1,1,1,1,1,1,5,5,5,5,1,1,1
1,5,1,1,1,1,1,1,1,1,1,2,1,1,1,1,1,1,1,1,1,1,1,1,1,1,1,1,1,1,1,1,1,1,1,1,1,1,1,1,1,1,5,5,5,5,5,1,1
5,5,1,1,1,1,1,1,1,1,1,3,1,1,1,1,1,1,1,1,1,1,1,1,1,5,5,1,1,1,1,1,1,1,1,1,1,1,1,1,1,1,5,5,5,5,5,5,1
5,5,1,1,1,1,1,1,1,1,1,3,1,1,1,1,1,1,1,1,1,1,1,1,1,1,1,1,1,1,1,1,1,1,1,1,1,1,1,1,1,1,1,1,5,5,5,5,1
5,5,1,1,1,1,1,1,1,1,1,3,1,1,3,1,1,1,1,1,1,1,1,1,1,1,1,1,1,1,1,1,1,1,1,1,1,1,1,1,1,1,1,1,1,1,1,3,3
5,5,1,1,1,1,1,1,1,1,1,1,1,1,1,1,1,1,1,1,3,3,1,1,1,1,1,1,1,1,1,1,1,1,1,1,1,1,1,1,1,1,1,1,1,1,1,3,3
5,1,1,1,1,1,1,1,1,1,1,1,1,1,1,1,1,1,1,1,3,3,1,1,1,1,1,1,1,1,1,1,1,1,1,1,1,1,1,1,1,1,1,1,1,1,1,3,3
5,1,1,1,1,1,1,1,1,1,1,1,1,1,1,1,1,1,1,1,3,3,1,1,1,1,1,1,1,1,1,1,1,1,1,1,1,1,1,1,1,5,5,1,1,1,1,1,3
1,1,1,1,1,1,1,1,1,1,1,1,1,1,1,1,1,1,1,1,3,3,1,1,1,1,1,5,1,1,1,1,1,1,1,1,1,1,1,5,5,5,5,1,1,1,1,1,3
1,6,6,6,6,6,6,6,6,6,6,1,1,1,1,1,1,1,1,1,3,3,1,1,1,1,5,5,1,1,1,1,1,1,1,1,1,1,1,5,5,1,1,1,2,1,1,1,1
1,6,0,0,0,7,0,0,0,0,6,1,1,1,1,1,1,1,1,1,3,3,1,1,1,1,1,1,1,1,1,1,1,1,1,2,2,1,1,1,1,1,1,2,2,2,1,1,1
1,6,0,0,0,7,0,0,0,0,6,1,1,1,1,1,1,1,1,1,1,1,1,1,1,1,1,1,1,1,1,1,1,1,1,2,2,1,1,1,1,1,2,2,2,1,1,1,1
1,6,0,0,6,7,7,7,6,8,6,1,1,1,1,1,1,1,1,1,1,1,1,1,1,1,1,1,1,1,1,1,1,1,1,2,2,1,1,1,1,1,2,2,1,1,1,1,1
1,6,0,0,9,10,0,0,0,10,6,1,1,1,1,1,1,1,1,1,1,1,1,1,1,1,1,1,1,1,1,1,1,1,1,2,1,1,1,1,1,1,1,1,1,1,1,1,1
1,6,6,6,6,0,0,0,0,0,6,1,1,1,1,1,1,1,1,1,1,1,1,1,1,1,1,1,5,5,5,1,1,1,1,1,1,1,1,1,1,1,1,1,1,1,1,1,1
1,6,6,6,6,11,0,0,0,0,6,1,1,1,1,1,1,1,1,1,1,1,1,1,1,1,0,12,13,1,1,1,1,1,1,1,1,1,1,1,1,1,1,1,1,1,1,1,1
1,6,6,6,6,11,0,0,0,0,6,1,1,1,1,1,1,1,1,1,1,1,1,1,1,1,0,12,5,1,1,3,1,1,1,1,1,1,1,1,1,1,1,1,1,1,1,1,1
1,6,6,6,6,6,6,6,6,6,6,1,1,1,1,1,1,1,1,1,1,1,1,1,1,1,0,12,1,1,1,1,1,1,1,1,1,1,1,1,1,1,1,1,1,1,1,1,1
1,1,5,1,1,1,1,1,1,1,1,1,1,1,1,1,1,1,1,1,1,1,1,1,1,1,0,12,1,1,1,3,1,1,1,1,1,1,1,1,1,1,1,1,1,1,1,1,1
1,1,1,1,1,1,1,1,1,1,1,1,1,1,1,1,1,1,1,1,1,1,1,1,1,1,0,12,1,1,1,3,1,1,1,1,1,1,1,1,1,1,1,1,1,1,1,1,1
1,1,1,1,1,1,1,1,1,1,1,1,1,1,1,1,1,1,1,1,1,1,1,1,1,1,0,12,1,1,1,1,1,1,1,1,1,1,1,1,1,1,1,1,1,1,1,1,1
1,1,1,1,1,1,1,1,1,1,1,1,1,1,1,1,1,1,1,1,1,1,1,1,1,1,0,12,1,1,1,1,1,2,2,2,2,1,1,1,1,1,1,1,1,1,1,1,1
1,1,1,1,1,1,1,1,1,1,1,1,1,1,1,1,1,1,1,1,1,1,1,1,1,1,0,12,1,1,1,1,1,1,2,2,2,2,1,1,1,1,1,1,1,1,1,1,1
1,1,1,1,1,1,1,1,1,1,1,1,2,2,1,1,1,1,1,1,1,1,1,1,1,1,0,14,1,1,1,1,1,1,1,1,1,1,1,1,1,1,1,1,1,1,1,1,1
1,1,1,1,1,1,1,1,1,1,1,1,2,2,1,1,1,1,1,1,1,1,1,1,1,5,5,5,2,1,1,1,1,1,1,1,1,1,1,1,1,1,1,1,1,1,1,1,1
1,1,1,1,1,1,1,1,1,1,1,1,2,1,1,1,1,1,1,1,1,1,1,5,5,5,5,15,1,1,1,1,1,1,1,1,1,1,1,1,1,1,1,1,1,1,1,1,1
1,1,1,1,1,1,1,1,1,1,1,1,1,1,1,1,1,1,1,1,1,1,1,5,5,5,5,5,1,1,1,1,1,1,1,1,1,1,1,1,1,1,1,1,1,1,1,1,5
1,1,1,1,5,5,5,5,5,1,1,1,1,1,1,1,1,1,1,1,1,1,5,5,5,5,5,1,1,1,1,1,1,1,1,1,1,1,1,1,1,1,1,1,1,1,1,5,5
:endlayer
layer: 2
5,5,5,5,5,5,5,5,5,5,5,5,5,5,5,5,5,5,5,5,5,5,5,5,5,5,5,5,5,5,5,5,5,5,5,5,5,5,5,5,5,5,5,5,5,5,5,5,5
5,5,5,5,5,5,5,5,5,5,5,5,5,5,5,5,5,5,5,5,5,5,5,5,5,5,5,5,5,5,5,5,5,5,5,5,5,5,5,5,5,5,5,5,5,5,5,5,5
5,5,5,5,5,5,5,5,5,5,5,5,5,5,5,5,5,5,5,5,5,5,5,5,5,5,5,5,5,5,5,5,5,5,5,5,5,5,5,5,5,5,5,5,5,5,5,5,5
5,5,5,5,5,5,5,5,5,5,5,5,5,5,5,5,5,5,5,5,5,5,5,5,5,5,5,5,5,5,5,5,5,5,5,5,5,5,5,5,5,5,5,5,5,5,5,5,5
5,5,5,5,5,5,5,5,5,5,5,5,5,5,5,5,5,5,5,5,5,5,5,5,5,5,5,5,5,5,5,5,5,5,5,5,5,5,5,5,5,5,5,5,5,5,5,5,5
5,5,5,5,5,5,5,5,5,5,5,5,5,5,5,5,5,5,5,5,5,5,5,5,5,5,5,5,5,5,5,5,5,5,5,5,5,5,5,5,5,5,5,5,5,5,5,5,5
5,5,5,5,5,5,5,5,5,5,5,5,5,5,5,5,5,5,5,5,5,5,5,5,5,5,5,5,5,5,5,5,5,5,5,5,5,5,5,5,5,5,5,5,5,5,5,5,5
5,5,5,5,5,5,5,5,5,5,5,5,5,5,5,5,5,5,16,16,16,16,16,16,17,16,16,5,5,5,5,5,5,5,5,5,5,5,5,5,5,5,5,5,5,5,5,5,5
5,5,5,5,5,5,5,5,5,5,5,5,5,5,5,5,5,5,16,0,0,0,0,0,0,17,16,5,5,5,5,5,5,5,5,5,5,5,5,5,5,5,5,5,5,5,5,5,5
5,5,5,5,5,5,5,5,5,5,5,5,5,5,5,5,5,5,16,0,0,0,0,0,0,18,5,5,5,5,5,5,5,5,5,5,5,5,5,5,5,5,5,5,5,5,5,5,5
5,5,5,5,5,5,5,5,5,5,5,5,5,5,5,5,5,5,17,0,19,0,0,0,0,6,20,5,5,5,5,5,5,5,5,5,5,5,5,5,5,5,5,5,5,5,5,5,5
5,5,5,5,5,5,5,5,5,5,5,5,5,5,5,5,5,5,16,6,20,0,0,0,6,6,6,21,20,5,5,5,5,5,5,5,5,5,5,5,5,5,5,5,5,5,5,5,5
5,5,5,5,5,5,5,5,5,5,5,5,5,5,5,5,5,5,16,20,22,0,0,0,0,6,6,6,6,5,5,5,5,5,5,5,5,5,5,5,5,5,5,5,5,5,5,5,5
5,5,5,5,5,5,5,5,5,5,5,5,5,5,5,5,5,5,16,6,6,0,0,0,0,0,0,6,6,5,5,5,5,5,5,5,5,5,5,5,5,5,5,5,5,5,5,5,5
5,5,5,5,5,5,5,5,5,5,5,5,5,5,5,5,5,5,5,6,6,0,10,0,0,10,0,6,6,5,5,5,5,5,5,5,5,5,5,5,5,5,5,5,5,5,5,5,5
5,5,5,5,5,5,5,5,5,5,5,5,5,5,5,5,5,5,5,6,6,0,0,0,0,0,0,6,6,5,5,5,5,5,5,5,5,5,5,5,5,5,5,5,5,5,5,5,5
5,5,5,5,5,5,5,5,5,5,5,5,5,5,5,5,5,5,5,6,6,0,0,0,0,0,0,6,6,5,5,5,5,5,5,5,5,5,5,5,5,5,5,5,5,5,5,5,5
5,5,5,5,5,5,5,5,5,5,5,5,5,5,5,5,5,5,5,6,6,0,10,0,0,10,0,6,6,5,5,5,5,5,5,5,5,5,5,5,5,5,5,5,5,5,5,5,5
5,5,5,5,5,5,5,5,5,5,5,5,5,5,5,5,5,5,5,6,6,0,0,0,0,0,0,6,6,5,5,5,5,5,5,5,5,5,5,5,5,5,5,5,5,5,5,5,5
5,5,5,5,5,5,5,5,5,5,5,5,5,5,5,0,0,0,0,6,6,6,6,6,6,6,6,6,6,5,5,5,5,5,5,5,5,5,5,5,5,5,5,5,5,5,5,5,5
5,5,5,5,5,5,5,5,5,5,5,5,5,5,5,0,0,0,0,6,6,6,6,6,6,6,6,6,6,5,5,5,5,5,5,5,5,5,5,5,5,5,5,5,5,5,5,5,5
5,5,5,5,5,5,5,5,5,5,5,5,5,5,5,5,0,0,5,1,1,1,1,1,1,1,1,5,5,5,5,5,5,5,5,5,5,5,5,5,5,5,5,5,5,5,5,5,5
5,5,5,5,5,5,5,5,5,5,5,5,5,5,5,5,5,5,5,1,1,1,1,1,1,1,1,5,5,5,5,5,5,5,5,5,5,5,5,5,5,5,5,5,5,5,5,5,5
5,5,5,5,5,5,5,5,5,5,5,5,5,5,5,5,5,5,5,1,1,1,1,1,1,1,1,5,5,5,5,5,5,5,5,5,5,5,5,5,5,5,5,5,5,5,5,5,5
5,5,5,5,5,5,5,5,5,5,5,5,5,5,5,5,5,5,5,1,1,1,1,1,1,1,5,5,5,5,5,5,5,5,5,5,5,5,5,5,5,5,5,5,5,5,5,5,5
5,5,5,5,5,5,5,5,5,5,5,5,5,5,5,5,5,5,5,1,1,1,1,1,1,5,5,5,5,5,5,5,5,5,5,5,5,5,5,5,5,5,5,5,5,5,5,5,5
5,5,5,5,5,5,5,5,5,5,5,5,5,5,5,5,5,5,5,1,1,1,1,1,1,5,5,5,5,5,5,5,5,5,5,5,5,5,5,5,5,5,5,5,5,5,5,5,5
5,5,5,5,5,5,5,5,5,5,5,5,5,5,5,5,5,5,5,1,1,1,1,1,1,5,5,5,5,5,5,5,5,5,5,5,5,5,5,5,5,5,5,5,5,5,5,5,5
5,5,5,5,5,5,5,5,5,5,5,5,5,5,5,5,5,5,5,5,5,1,1,5,5,5,5,5,5,5,5,5,5,5,5,5,5,5,5,5,5,5,5,5,5,5,5,5,5
5,5,5,5,5,5,5,5,5,5,5,5,5,5,5,5,5,5,5,5,5,5,5,5,5,5,5,5,5,5,5,5,5,5,5,5,5,5,5,5,5,5,5,5,5,5,5,5,5
5,5,5,5,5,5,5,5,5,5,5,5,5,5,5,5,5,5,5,5,5,5,5,5,5,5,5,5,5,5,5,5,5,5,5,5,5,5,5,5,5,5,5,5,5,5,5,5,5
5,5,5,5,5,5,5,5,5,5,5,5,5,5,5,5,5,5,5,5,5,5,5,5,5,5,5,5,5,5,5,5,5,5,5,5,5,5,5,5,5,5,5,5,5,5,5,5,5
5,5,5,5,5,5,5,5,5,5,5,5,5,5,5,5,5,5,5,5,5,5,5,5,5,5,5,5,5,5,5,5,5,5,5,5,5,5,5,5,5,5,5,5,5,5,5,5,5
5,5,5,5,5,5,5,5,5,5,5,5,5,5,5,5,5,5,5,5,5,5,5,5,5,5,5,5,5,5,5,5,5,5,5,5,5,5,5,5,5,5,5,5,5,5,5,5,5
5,5,5,5,5,5,5,5,5,5,5,5,5,5,5,5,5,5,5,5,5,5,5,5,5,5,5,5,5,5,5,5,5,5,5,5,5,5,5,5,5,5,5,5,5,5,5,5,5
5,5,5,5,5,5,5,5,5,5,5,5,5,5,5,5,5,5,5,5,5,5,5,5,5,5,5,5,5,5,5,5,5,5,5,5,5,5,5,5,5,5,5,5,5,5,5,5,5
5,5,5,5,5,5,5,5,5,5,5,5,5,5,5,5,5,5,5,5,5,5,5,5,5,5,5,5,5,5,5,5,5,5,5,5,5,5,5,5,5,5,5,5,5,5,5,5,5
5,6,6,6,6,6,6,6,6,6,6,5,5,5,5,5,5,5,5,5,5,5,5,5,5,5,5,5,5,5,5,5,5,5,5,5,5,5,5,5,5,5,5,5,5,5,5,5,5
5,6,0,0,0,7,0,0,0,0,6,5,5,5,5,5,5,5,5,5,5,5,5,5,5,5,5,5,5,5,5,5,5,5,5,5,5,5,6,6,6,6,6,6,6,6,6,5,5
5,6,0,0,0,7,0,0,0,0,6,5,5,5,5,5,5,5,5,5,5,5,5,5,5,5,5,5,5,5,5,5,5,5,5,5,5,5,6,6,6,6,6,6,6,6,6,5,5
5,6,0,0,6,7,7,7,6,23,6,5,5,5,5,5,5,5,5,5,5,5,5,5,5,5,5,5,5,5,5,5,5,5,5,5,5,5,6,6,6,6,6,6,6,6,6,5,5
5,6,0,0,24,0,0,0,25,0,6,5,5,5,5,5,5,5,5,5,5,5,5,5,5,5,5,5,5,5,5,5,5,5,5,5,5,5,6,6,6,6,6,6,6,6,6,5,5
5,6,6,6,6,26,0,0,0,0,6,5,5,5,5,5,5,5,5,5,5,5,5,5,5,5,5,5,5,5,5,5,5,5,5,5,5,5,6,6,6,6,6,6,6,6,6,5,5
5,6,6,6,11,0,0,0,0,0,6,5,5,5,5,5,5,5,5,5,5,5,5,5,5,5,0,0,5,12,5,5,5,5,5,5,5,5,5,6,6,6,6,6,6,6,6,5,5
5,6,6,6,11,0,27,0,0,0,6,5,5,5,5,5,5,5,5,5,5,5,5,5,5,5,5,0,5,5,5,5,5,5,5,5,5,5,5,6,6,6,6,6,6,6,6,5,5
5,6,6,6,6,6,6,6,6,6,6,5,5,5,5,5,5,5,5,5,5,5,5,5,5,5,5,0,5,5,5,5,5,5,5,5,5,5,5,6,6,6,6,6,6,6,5,5,5
5,5,5,5,5,5,5,5,5,5,5,5,5,5,5,5,5,5,5,5,5,5,5,5,5,5,5,0,5,5,5,5,5,5,5,5,5,5,5,5,5,6,6,6,6,6,5,5,5
5,5,5,5,5,5,5,5,5,5,5,5,5,5,5,5,5,5,5,5,5,5,5,5,5,5,5,5,5,5,5,5,5,5,5,5,5,5,5,5,5,5,5,5,5,5,5,5,5
5,5,5,5,5,5,5,5,5,5,5,5,5,5,5,5,5,5,5,5,5,5,5,5,5,5,5,5,5,5,5,5,5,5,5,5,5,5,5,5,5,5,5,5,5,5,5,5,5
5,5,5,5,5,5,5,5,5,5,5,5,5,5,5,5,5,5,5,5,5,5,5,5,5,5,5,5,5,5,5,5,5,5,5,5,5,5,5,5,5,5,5,5,5,5,5,5,5
5,5,5,5,5,5,5,5,5,5,5,5,5,5,5,5,5,5,5,5,5,5,5,5,5,5,5,5,5,5,5,5,5,5,5,5,5,5,5,5,5,5,5,5,5,5,5,5,5
5,5,5,5,5,5,5,5,5,5,5,5,5,5,5,5,5,5,5,5,5,5,5,5,5,5,5,5,5,5,5,5,5,5,5,5,5,5,5,5,5,5,5,5,5,5,5,5,5
5,5,5,5,5,5,5,5,5,5,5,5,5,5,5,5,5,5,5,5,5,5,5,5,5,5,5,5,5,5,5,5,5,5,5,5,5,5,5,5,5,5,5,5,5,5,5,5,5
5,5,5,5,5,5,5,5,5,5,5,5,5,5,5,5,5,5,5,5,5,5,5,5,5,5,5,0,5,5,5,5,5,5,5,5,5,5,5,5,5,5,5,5,5,5,5,5,5
5,5,5,5,5,5,5,5,5,5,5,5,5,5,5,5,5,5,5,5,5,5,5,5,5,5,5,28,5,29,5,5,5,5,5,5,5,5,5,5,5,5,5,5,5,5,5,5,5
5,5,5,5,5,5,5,5,5,5,5,5,5,5,5,5,5,5,5,5,5,5,5,5,5,5,5,5,5,5,5,5,5,5,5,5,5,5,5,5,5,5,5,5,5,5,5,5,5
:endlayer
layer: 3
5,5,5,5,5,5,5,5,5,5,5,5,5,5,5,5,5,5,5,5,5,5,5,5,5,5,5,5,5,5,5,5,5,5,5,5,5,5,5,5,5,5,5,5,5,5,5,5,5
5,5,5,5,5,5,5,5,5,5,5,5,5,5,5,5,5,5,5,5,5,5,5,5,5,5,5,5,5,5,5,5,5,5,5,5,5,5,5,5,5,5,5,5,5,5,5,5,5
5,5,5,5,5,5,5,5,5,5,5,5,5,5,5,5,5,5,5,5,5,5,5,5,5,5,5,5,5,5,5,5,5,5,5,5,5,5,5,5,5,5,5,5,5,5,5,5,5
5,5,5,5,5,5,5,5,5,5,5,5,5,5,5,5,5,5,5,5,5,5,5,5,5,5,5,5,5,5,5,5,5,5,5,5,5,5,5,5,5,5,5,5,5,5,5,5,5
5,5,5,5,5,5,5,5,5,5,5,5,5,5,5,5,5,5,5,5,5,5,5,5,5,5,5,5,5,5,5,5,5,5,5,5,5,5,5,5,5,5,5,5,5,5,5,5,5
5,5,5,5,5,5,5,5,5,5,5,5,5,5,5,5,5,5,5,5,5,5,5,5,5,5,5,5,5,5,5,5,5,5,5,5,5,5,5,5,5,5,5,5,5,5,5,5,5
5,5,5,5,5,5,5,5,5,5,5,5,5,5,5,5,5,5,5,5,5,5,5,5,5,5,5,5,5,5,5,5,5,5,5,5,5,5,5,5,5,5,5,5,5,5,5,5,5
5,5,5,5,5,5,5,5,5,5,5,5,5,5,5,5,5,5,16,16,16,17,16,16,16,16,5,5,5,5,5,5,5,5,5,5,5,5,5,5,5,5,5,5,5,5,5,5,5
5,5,5,5,5,5,5,5,5,5,5,5,5,5,5,5,5,5,17,0,0,0,0,0,0,16,16,5,5,5,5,5,5,5,5,5,5,5,5,5,5,5,5,5,5,5,5,5,5
5,5,5,5,5,5,5,5,5,5,5,5,5,5,5,5,5,5,16,0,0,0,0,0,0,0,18,6,5,5,5,5,5,5,5,5,5,5,5,5,5,5,5,5,5,5,5,5,5
5,5,5,5,5,5,5,5,5,5,5,5,5,5,5,5,5,5,16,0,0,0,0,0,0,6,6,5,5,5,5,5,5,5,5,5,5,5,5,5,5,5,5,5,5,5,5,5,5
5,5,5,5,5,5,5,5,5,5,5,5,5,5,5,5,5,5,16,6,6,0,0,0,6,6,6,6,6,5,5,5,5,5,5,5,5,5,5,5,5,5,5,5,5,5,5,5,5
5,5,5,5,5,5,5,5,5,5,5,5,5,5,5,5,5,5,16,6,0,0,0,0,0,30,31,0,6,5,5,5,5,5,5,5,5,5,5,5,5,5,5,5,5,5,5,5,5
5,5,5,5,5,5,5,5,5,5,5,5,5,5,5,5,5,5,16,6,32,0,0,0,0,0,0,33,6,5,5,5,5,5,5,5,5,5,5,5,5,5,5,5,5,5,5,5,5
5,5,5,5,5,5,5,5,5,5,5,5,5,5,5,5,5,5,5,6,34,0,0,0,0,0,0,35,6,5,5,5,5,5,5,5,5,5,5,5,5,5,5,5,5,5,5,5,5
5,5,5,5,5,5,5,5,5,5,5,5,5,5,5,5,5,5,5,6,0,0,0,0,0,0,0,0,6,5,5,5,5,5,5,5,5,5,5,5,5,5,5,5,5,5,5,5,5
5,5,5,5,5,5,5,5,5,5,5,5,5,5,5,5,5,5,5,6,0,0,0,0,0,0,0,0,6,5,5,5,5,5,5,5,5,5,5,5,5,5,5,5,5,5,5,5,5
5,5,5,5,5,5,5,5,5,5,5,5,5,5,5,5,5,5,5,6,36,0,0,0,0,0,0,37,6,5,5,5,5,5,5,5,5,5,5,5,5,5,5,5,5,5,5,5,5
5,5,5,5,5,5,5,5,5,5,5,5,5,5,5,5,5,5,5,6,38,0,0,0,0,0,0,39,6,5,5,5,5,5,5,5,5,5,5,5,5,5,5,5,5,5,5,5,5
5,5,5,5,5,5,5,5,5,5,5,5,5,5,5,5,5,5,5,6,0,40,41,0,0,42,43,0,6,5,5,5,5,5,5,5,5,5,5,5,5,5,5,5,5,5,5,5,5
5,5,5,5,5,5,5,5,5,5,5,5,5,5,5,5,5,5,5,6,6,6,6,6,6,6,6,6,6,5,5,5,5,5,5,5,5,5,5,5,5,5,5,5,5,5,5,5,5
5,5,5,5,5,5,5,5,5,5,5,5,5,5,5,5,5,5,5,5,1,1,1,1,1,1,5,5,5,5,5,5,5,5,5,5,5,5,5,5,5,5,5,5,5,5,5,5,5
5,5,5,5,5,5,5,5,5,5,5,5,5,5,5,5,5,5,5,1,1,1,1,1,1,1,5,5,5,5,5,5,5,5,5,5,5,5,5,5,5,5,5,5,5,5,5,5,5
5,5,5,5,5,5,5,5,5,5,5,5,5,5,5,5,5,5,5,5,1,1,1,1,1,1,5,5,5,5,5,5,5,5,5,5,5,5,5,5,5,5,5,5,5,5,5,5,5
5,5,5,5,5,5,5,5,5,5,5,5,5,5,5,5,5,5,5,1,1,1,1,1,1,5,5,5,5,5,5,5,5,5,5,5,5,5,5,5,5,5,5,5,5,5,5,5,5
5,5,5,5,5,5,5,5,5,5,5,5,5,5,5,5,5,5,5,5,1,5,1,5,5,5,5,5,5,5,5,5,5,5,5,5,5,5,5,5,5,5,5,5,5,5,5,5,5
5,5,5,5,5,5,5,5,5,5,5,5,5,5,5,5,5,5,5,5,5,5,5,5,5,5,5,5,5,5,5,5,5,5,5,5,5,5,5,5,5,5,5,5,5,5,5,5,5
5,5,5,5,5,5,5,5,5,5,5,5,5,5,5,5,5,5,5,5,5,5,5,5,5,5,5,5,5,5,5,5,5,5,5,5,5,5,5,5,5,5,5,5,5,5,5,5,5
5,5,5,5,5,5,5,5,5,5,5,5,5,5,5,5,5,5,5,5,5,5,5,5,5,5,5,5,5,5,5,5,5,5,5,5,5,5,5,5,5,5,5,5,5,5,5,5,5
5,5,5,5,5,5,5,5,5,5,5,5,5,5,5,5,5,5,5,5,5,5,5,5,5,5,5,5,5,5,5,5,5,5,5,5,5,5,5,5,5,5,5,5,5,5,5,5,5
5,5,5,5,5,5,5,5,5,5,5,5,5,5,5,5,5,5,5,5,5,5,5,5,5,5,5,5,5,5,5,5,5,5,5,5,5,5,5,5,5,5,5,5,5,5,5,5,5
5,5,5,5,5,5,5,5,5,5,5,5,5,5,5,5,5,5,5,5,5,5,5,5,5,5,5,5,5,5,5,5,5,5,5,5,5,5,5,5,5,5,5,5,5,5,5,5,5
5,5,5,5,5,5,5,5,5,5,5,5,5,5,5,5,5,5,5,5,5,5,5,5,5,5,5,5,5,5,5,5,5,5,5,5,5,5,5,5,5,5,5,5,5,5,5,5,5
5,5,5,5,5,5,5,5,5,5,5,5,5,5,5,5,5,5,5,5,5,5,5,5,5,5,5,5,5,5,5,5,5,5,5,5,5,5,5,5,5,5,5,5,5,5,5,5,5
5,5,5,5,5,5,5,5,5,5,5,5,5,5,5,5,5,5,5,5,5,5,5,5,5,5,5,5,5,5,5,5,5,5,5,5,5,5,5,5,5,5,5,5,5,5,5,5,5
5,5,5,5,5,5,5,5,5,5,5,5,5,5,5,5,5,5,5,5,5,5,5,5,5,5,5,5,5,5,5,5,5,5,5,5,5,5,5,5,5,5,5,5,5,5,5,5,5
5,5,5,5,5,5,5,5,5,5,5,5,5,5,5,5,5,5,5,5,5,5,5,5,5,5,5,5,5,5,5,5,5,5,5,5,5,5,5,5,5,5,5,5,5,5,5,5,5
5,6,6,6,6,6,6,6,6,6,6,5,5,5,5,5,5,5,5,5,5,5,5,5,5,5,5,5,5,5,5,5,5,5,5,5,5,5,5,5,5,5,5,5,5,5,5,5,5
5,6,0,0,0,7,0,0,0,0,6,5,5,5,5,5,5,5,5,5,5,5,5,5,5,5,5,5,5,5,5,5,5,5,5,5,5,5,6,6,6,6,6,6,6,6,6,5,5
5,6,0,0,0,7,0,0,0,0,6,5,5,5,5,5,5,5,5,5,5,5,5,5,5,5,5,5,5,5,5,5,5,5,5,5,5,5,6,44,45,0,46,47,0,48,6,5,5
5,6,0,0,6,7,7,7,6,6,6,5,5,5,5,5,5,5,5,5,5,5,5,5,5,5,5,5,5,5,5,5,5,5,5,5,5,5,6,0,0,0,0,0,0,49,6,5,5
5,6,0,0,6,0,0,0,0,0,6,5,5,5,5,5,5,5,5,5,5,5,5,5,5,5,5,5,5,5,5,5,5,5,5,5,5,5,6,50,0,0,0,0,6,6,6,5,5
5,6,6,6,6,0,0,0,0,0,6,5,5,5,5,5,5,5,5,5,5,5,5,5,5,5,5,5,5,5,5,5,5,5,5,5,5,5,6,51,0,0,0,0,6,6,6,5,5
5,6,52,11,0,0,0,0,0,0,6,5,53,53,53,53,53,53,5,5,5,5,5,5,5,5,5,5,5,54,5,53,53,53,53,53,53,5,6,0,0,0,0,0,6,6,6,5,5
5,6,0,0,0,0,0,0,0,0,6,5,53,53,53,53,53,53,5,5,5,5,5,5,5,5,5,5,5,12,5,53,53,53,53,53,53,5,6,55,0,0,0,0,52,52,6,5,5
5,6,6,6,6,6,6,6,6,6,5,53,53,53,53,53,53,53,53,5,5,5,5,5,5,5,5,5,5,5,53,53,53,53,53,53,53,53,5,6,56,57,0,0,0,0,6,5,5
5,5,5,5,5,5,5,5,5,5,53,53,53,53,53,53,53,53,53,53,53,5,5,5,5,5,5,5,53,53,53,53,53,53,53,53,53,53,53,5,6,6,6,6,6,6,5,5,5
5,5,5,5,5,5,5,5,5,53,53,53,53,53,53,53,53,53,53,53,53,53,53,53,53,53,53,53,53,53,53,53,53,53,53,53,53,53,53,53,5,5,5,5,5,5,5,5,5
5,5,5,5,5,5,5,5,5,5,53,53,53,53,53,53,53,53,53,53,53,53,53,53,53,53,53,53,53,53,53,53,53,53,53,53,53,53,53,5,5,5,5,5,5,5,5,5,5
5,5,5,5,5,5,5,5,5,5,5,53,53,53,53,53,53,53,53,53,53,53,53,53,53,53,53,53,53,53,53,53,53,53,53,53,53,53,5,5,5,5,5,5,5,5,5,5,5
5,5,5,5,5,5,5,5,5,5,5,5,53,53,53,53,53,53,53,53,53,53,53,53,53,53,53,53,53,53,53,53,53,53,53,53,53,5,5,5,5,5,5,5,5,5,5,5,5
5,5,5,5,5,5,5,5,5,5,5,5,5,53,53,53,53,53,53,53,53,53,53,53,53,53,53,53,53,53,53,53,53,53,53,53,5,5,5,5,5,5,5,5,5,5,5,5,5
5,5,5,5,5,5,5,5,5,5,5,5,5,5,53,53,53,53,53,53,53,53,53,53,53,53,53,53,53,53,53,53,53,53,53,5,5,5,5,5,5,5,5,5,5,5,5,5,5
5,5,5,5,5,5,5,5,5,5,5,5,5,5,5,5,5,5,5,5,5,5,5,5,5,5,5,5,5,5,5,5,5,5,5,5,5,5,5,5,5,5,5,5,5,5,5,5,5
5,5,5,5,5,5,5,5,5,5,5,5,5,5,5,5,5,5,5,5,5,5,5,5,5,5,5,58,29,0,5,5,5,5,5,5,5,5,5,5,5,5,5,5,5,5,5,5,5
5,5,5,5,5,5,5,5,5,5,5,5,5,5,5,5,5,5,5,5,5,5,5,5,5,5,5,5,5,5,5,5,5,5,5,5,5,5,5,5,5,5,5,5,5,5,5,5,5
:endlayer
layer: 4
5,5,5,5,5,5,5,5,5,5,5,5,5,5,5,5,5,5,5,5,5,5,5,5,5,5,5,5,5,5,5,5,5,5,5,5,5,5,5,5,5,5,5,5,5,5,5,5,5
5,5,5,5,5,5,5,5,5,5,5,5,5,5,5,5,5,5,5,5,5,5,5,5,5,5,5,5,5,5,5,5,5,5,5,5,5,5,5,5,5,5,5,5,5,5,5,5,5
5,5,5,5,5,5,5,5,5,5,5,5,5,5,5,5,5,5,5,5,5,5,5,5,5,5,5,5,5,5,5,5,5,5,5,5,5,5,5,5,5,5,5,5,5,5,5,5,5
5,5,5,5,5,5,5,5,5,5,5,5,5,5,5,5,5,5,5,5,5,5,5,5,5,5,5,5,5,5,5,5,5,5,5,5,5,5,5,5,5,5,5,5,5,5,5,5,5
5,5,5,5,5,5,5,5,5,5,5,5,5,5,5,5,5,5,5,5,5,5,5,5,5,5,5,5,5,5,5,5,5,5,5,5,5,5,5,5,5,5,5,5,5,5,5,5,5
5,5,5,5,5,5,5,5,5,5,5,5,5,5,5,5,5,5,5,5,5,5,5,5,5,5,5,5,5,5,5,5,5,5,5,5,5,5,5,5,5,5,5,5,5,5,5,5,5
5,5,5,5,5,5,5,5,5,5,5,5,5,5,5,5,5,5,5,5,5,5,5,5,5,5,5,5,5,5,5,5,5,5,5,5,5,5,5,5,5,5,5,5,5,5,5,5,5
5,5,5,5,5,5,5,5,5,5,5,5,5,5,5,5,5,5,5,16,16,16,17,16,16,16,5,5,5,5,5,5,5,5,5,5,5,5,5,5,5,5,5,5,5,5,5,5,5
5,5,5,5,5,5,5,5,5,5,5,5,5,5,5,5,5,5,16,0,59,0,0,0,59,16,16,16,5,5,5,5,5,5,5,5,5,5,5,5,5,5,5,5,5,5,5,5,5
5,5,5,5,5,5,5,5,5,5,5,5,5,5,5,5,5,5,17,0,0,0,0,0,0,0,0,18,6,5,5,5,5,5,5,5,5,5,5,5,5,5,5,5,5,5,5,5,5
5,5,5,5,5,5,5,5,5,5,5,5,5,5,5,5,5,5,16,0,27,0,0,0,27,6,21,6,5,5,5,5,5,5,5,5,5,5,5,5,5,5,5,5,5,5,5,5,5
5,5,5,5,5,5,5,5,5,5,5,5,5,5,5,5,5,5,16,20,6,0,0,0,6,6,20,6,21,5,5,5,5,5,5,5,5,5,5,5,5,5,5,5,5,5,5,5,5
5,5,5,5,5,5,5,5,5,5,5,5,5,5,5,5,5,5,16,6,0,0,0,0,0,0,59,0,6,5,5,5,5,5,5,5,5,5,5,5,5,5,5,5,5,5,5,5,5
5,5,5,5,5,5,5,5,5,5,5,5,5,5,5,5,5,5,16,6,60,0,0,0,0,0,0,61,6,5,5,5,5,5,5,5,5,5,5,5,5,5,5,5,5,5,5,5,5
5,5,5,5,5,5,5,5,5,5,5,5,5,5,5,5,5,5,5,6,0,0,0,0,0,0,0,0,6,5,5,5,5,5,5,5,5,5,5,5,5,5,5,5,5,5,5,5,5
5,5,5,5,5,5,5,5,5,5,5,5,5,5,5,5,5,5,5,6,0,0,0,0,0,0,0,0,6,5,5,5,5,5,5,5,5,5,5,5,5,5,5,5,5,5,5,5,5
5,5,5,5,5,5,5,5,5,5,5,5,5,5,5,5,5,5,5,6,0,0,0,0,0,0,0,0,6,5,5,5,5,5,5,5,5,5,5,5,5,5,5,5,5,5,5,5,5
5,5,5,5,5,5,5,5,5,5,5,5,5,5,5,5,5,5,5,6,0,0,0,0,0,0,0,0,6,5,5,5,5,5,5,5,5,5,5,5,5,5,5,5,5,5,5,5,5
5,5,5,5,5,5,5,5,5,29,5,5,29,5,5,5,5,5,5,6,60,0,0,0,0,0,0,61,6,5,5,5,5,5,5,5,29,5,5,29,5,5,5,5,5,5,5,5,5
5,5,5,5,5,5,5,5,5,5,5,5,5,5,5,5,5,5,5,6,0,27,0,0,0,0,27,0,6,5,5,5,5,5,5,5,5,5,5,5,5,5,5,5,5,5,5,5,5
5,5,5,5,5,5,5,5,5,5,5,5,5,5,5,5,5,5,5,6,6,6,6,6,6,6,6,6,6,5,5,5,5,5,5,5,5,5,5,5,5,5,5,5,5,5,5,5,5
5,5,5,5,5,5,5,5,5,5,5,5,5,5,5,5,5,5,5,5,5,5,5,5,5,5,5,5,5,5,5,5,5,5,5,5,5,5,5,5,5,5,5,5,5,5,5,5,5
5,5,5,5,5,5,5,5,5,5,5,5,5,5,5,5,5,5,5,5,5,5,5,5,5,5,5,5,5,5,5,5,5,5,5,5,5,5,5,5,5,5,5,5,5,5,5,5,5
5,5,5,5,5,5,5,5,5,29,5,5,29,5,5,5,5,5,5,5,5,5,5,5,5,5,5,5,5,5,5,5,5,5,5,5,5,5,5,5,5,5,5,5,5,5,5,5,5
5,5,5,5,5,5,5,5,5,5,5,5,5,5,5,5,5,5,5,5,5,5,5,5,5,5,5,5,5,5,5,5,5,5,5,5,5,5,5,5,5,5,5,5,5,5,5,5,5
5,5,5,5,5,5,5,5,5,5,5,5,5,5,5,5,5,5,5,5,5,5,5,5,5,5,5,5,5,5,5,5,5,5,5,5,5,5,5,5,5,5,5,5,5,5,5,5,5
5,5,5,5,5,5,5,5,5,5,5,5,5,5,5,5,5,5,5,5,5,5,5,5,5,5,5,5,5,5,5,5,5,5,5,5,5,5,5,5,5,5,5,5,5,5,5,5,5
5,5,5,5,5,5,5,5,5,5,5,5,5,5,5,5,5,5,5,5,5,5,5,5,5,5,5,5,5,5,5,5,5,5,5,5,5,5,5,5,5,5,5,5,5,5,5,5,5
5,5,5,5,5,5,5,5,5,29,5,5,29,5,5,5,5,5,5,5,5,5,5,5,5,5,5,5,5,5,5,5,5,5,5,5,5,5,5,5,5,5,5,5,5,5,5,5,5
5,5,5,5,5,5,5,5,5,5,5,5,5,5,5,5,5,5,5,5,5,5,5,5,5,5,5,5,5,5,5,5,5,5,5,5,5,5,5,5,5,5,5,5,5,5,5,5,5
5,5,5,5,5,5,5,5,5,5,5,5,5,5,5,5,5,5,5,5,5,5,5,5,5,5,5,5,5,5,5,5,5,5,5,5,5,5,5,5,5,5,5,5,5,5,5,5,5
5,5,5,5,5,5,5,5,5,5,5,5,5,5,5,5,5,5,5,5,5,5,5,5,5,5,5,5,5,5,5,5,5,5,5,5,5,5,5,5,5,5,5,5,5,5,5,5,5
5,5,5,5,5,5,5,5,5,5,5,5,5,5,5,5,5,5,5,5,5,5,5,5,5,5,5,5,5,5,5,5,5,5,5,5,5,5,5,5,5,5,5,5,5,5,5,5,5
5,5,5,5,5,5,5,5,5,29,5,5,29,5,5,5,5,5,5,5,5,5,5,5,5,5,5,5,5,5,5,5,5,5,5,5,5,5,5,5,5,5,5,5,5,5,5,5,5
5,5,5,5,5,5,5,5,5,5,5,5,5,5,5,5,5,5,5,5,5,5,5,5,5,5,5,5,5,5,5,5,5,5,5,5,5,5,5,5,5,5,5,5,5,5,5,5,5
5,5,5,5,5,5,5,5,5,5,5,5,5,5,5,5,5,5,5,5,5,5,5,5,5,5,5,5,5,5,5,5,5,5,5,5,5,5,5,5,5,5,5,5,5,5,5,5,5
5,5,5,5,5,5,5,5,5,5,5,5,5,5,5,5,5,5,5,5,5,5,5,5,5,5,5,5,5,5,5,5,5,5,5,5,5,5,5,5,5,5,5,5,5,5,5,5,5
5,6,6,6,6,6,6,6,6,6,6,5,5,5,5,5,5,5,5,5,5,5,5,5,5,5,5,5,5,5,5,5,5,5,5,5,5,5,5,5,5,5,5,5,5,5,5,5,5
5,6,6,6,6,6,6,6,6,6,6,5,5,5,5,5,5,5,5,5,5,5,5,5,5,5,5,5,5,5,5,5,5,5,5,5,5,5,6,6,6,6,6,6,6,6,6,5,5
5,6,6,6,6,6,6,6,6,6,6,5,5,5,5,5,5,5,5,5,5,5,5,5,5,5,5,5,5,5,5,5,5,5,5,5,5,5,6,0,0,0,59,0,0,0,6,5,5
5,6,6,6,6,6,6,6,6,6,6,5,5,5,5,5,5,5,5,5,5,5,5,5,5,5,5,5,5,5,5,5,5,5,5,5,5,5,6,0,0,0,0,0,0,0,6,5,5
5,6,6,6,6,6,6,6,6,6,6,5,5,5,5,5,5,5,5,5,5,5,5,5,5,5,5,5,5,5,5,5,5,5,5,5,5,5,6,0,0,0,0,0,6,6,6,5,5
5,6,52,52,6,62,63,6,6,6,6,5,5,5,5,5,5,5,5,5,5,5,5,5,5,5,5,5,5,5,5,5,5,5,5,5,5,5,6,60,0,0,0,0,6,6,6,5,5
5,6,0,0,0,0,63,6,6,6,6,5,53,53,53,53,53,53,5,5,5,5,5,5,5,5,5,5,12,5,5,53,53,53,53,53,53,5,6,0,0,0,0,0,52,52,6,5,5
5,6,27,0,0,0,63,6,6,6,6,5,53,53,53,53,53,53,5,5,5,5,5,5,5,5,5,5,12,54,5,53,53,53,53,53,53,5,6,0,0,0,0,0,0,0,6,5,5
5,6,6,6,6,6,6,6,6,6,5,53,53,53,53,53,53,53,53,5,5,5,5,5,5,5,5,5,5,5,53,53,53,53,53,53,53,53,5,6,0,0,27,0,0,0,6,5,5
5,5,5,5,5,5,5,5,5,5,53,53,53,53,53,53,53,53,53,53,53,5,5,5,5,5,5,5,53,53,53,53,53,53,53,53,53,53,53,5,6,6,6,6,6,6,5,5,5
5,5,5,5,5,5,5,5,5,53,53,53,53,53,53,53,53,53,53,53,53,53,53,53,53,53,53,53,53,53,53,53,53,53,53,53,53,53,53,53,5,5,5,5,5,5,5,5,5
5,5,5,5,5,5,5,5,5,5,53,53,53,53,53,53,53,53,53,53,53,53,53,53,53,53,53,53,53,53,53,53,53,53,53,53,53,53,53,5,5,5,5,5,5,5,5,5,5
5,5,5,5,5,5,5,5,5,5,5,53,53,53,53,53,53,53,53,53,53,53,53,53,53,53,53,53,53,53,53,53,53,53,53,53,53,53,5,5,5,5,5,5,5,5,5,5,5
5,5,5,5,5,5,5,5,5,5,5,5,53,53,53,53,53,53,53,53,53,53,53,53,53,53,53,53,53,53,53,53,53,53,53,53,53,5,5,5,5,5,5,5,5,5,5,5,5
5,5,5,5,5,5,5,5,5,5,5,5,5,53,53,53,53,53,53,53,53,53,53,53,53,53,53,53,53,53,53,53,53,53,53,53,5,5,5,5,5,5,5,5,5,5,5,5,5
5,5,5,5,5,5,5,5,5,5,5,5,5,5,53,53,53,53,53,53,53,53,53,53,53,53,53,53,53,53,53,53,53,53,53,5,5,5,5,5,5,5,5,5,5,5,5,5,5
5,5,5,5,5,5,5,5,5,5,5,5,5,5,5,5,5,5,5,5,5,5,5,5,5,5,5,5,5,5,5,5,5,5,5,5,5,5,5,5,5,5,5,5,5,5,5,5,5
5,5,5,5,5,5,5,5,5,5,5,5,5,5,5,5,5,5,5,5,5,5,5,5,5,5,5,0,12,29,5,5,5,5,5,5,5,5,5,5,5,5,5,5,5,5,5,5,5
5,5,5,5,5,5,5,5,5,5,5,5,5,5,5,5,5,5,5,5,5,5,5,5,5,5,5,5,5,5,5,5,5,5,5,5,5,5,5,5,5,5,5,5,5,5,5,5,5
:endlayer
layer: 5
29,29,29,29,29,29,29,29,29,29,29,29,29,29,29,29,29,29,29,29,29,29,29,29,29,29,29,29,29,29,29,29,29,29,29,29,29,29,29,29,29,29,29,29,29,29,29,29,29
29,29,29,29,5,5,5,5,5,29,29,29,29,29,29,29,29,29,29,29,29,29,29,29,29,29,29,29,29,29,29,29,29,29,29,29,29,29,29,29,5,5,5,5,5,29,29,29,29
29,29,29,5,5,5,5,5,5,5,29,29,29,29,29,29,29,29,29,29,29,29,29,29,29,29,29,29,29,29,29,29,29,29,29,29,29,29,29,5,5,5,5,5,5,5,29,29,29
29,29,5,5,5,5,5,5,5,5,5,29,29,29,29,29,29,29,29,29,29,29,29,29,29,29,29,29,29,29,29,29,29,29,29,29,29,29,5,5,5,5,5,5,5,5,5,29,29
29,5,5,5,5,5,5,5,5,5,5,5,29,29,29,29,29,29,29,29,29,29,29,29,29,29,29,29,29,29,29,29,29,29,29,29,29,5,5,5,5,5,5,5,5,5,5,5,29
29,5,5,5,5,5,5,5,5,5,5,5,29,29,29,29,29,29,29,29,29,29,29,29,29,29,29,29,29,29,29,29,29,29,29,29,29,5,5,5,5,5,5,5,5,5,5,5,29
29,5,5,5,5,5,5,5,5,5,5,5,5,5,5,5,5,5,5,5,5,5,5,5,5,5,5,5,5,5,5,5,5,5,5,5,5,5,5,5,5,5,5,5,5,5,5,5,29
29,5,5,5,5,5,5,5,5,5,5,5,5,5,5,5,5,5,5,17,16,16,16,16,17,16,5,5,5,5,5,5,5,5,5,5,5,5,5,5,5,5,5,5,5,5,5,5,29
29,5,5,5,5,5,5,5,5,5,5,5,5,5,5,5,64,5,16,0,0,0,0,0,0,16,16,16,16,5,5,5,5,5,5,5,5,5,5,5,5,5,5,5,5,5,5,5,29
29,29,5,5,5,5,5,5,5,5,5,5,5,5,5,5,5,5,17,0,0,0,0,0,0,0,0,0,18,6,5,5,5,5,5,5,5,5,5,5,5,5,5,5,5,5,5,29,29
29,29,29,5,5,5,5,5,5,5,5,5,5,5,5,5,5,5,16,0,0,0,0,0,0,6,6,20,6,5,5,5,5,5,5,5,5,5,5,5,5,5,5,5,5,5,29,29,29
29,29,29,29,5,5,5,5,5,5,5,5,5,5,5,5,5,5,16,6,6,6,21,6,6,6,6,20,6,5,5,5,5,5,5,5,5,5,5,5,5,5,5,5,5,29,29,29,29
29,29,29,29,29,29,5,5,5,5,5,5,5,5,5,5,5,5,16,6,6,6,6,6,6,6,6,6,6,5,5,5,5,5,5,5,5,5,5,5,5,5,5,29,29,29,29,29,29
29,29,29,29,29,29,5,5,5,64,5,5,64,5,5,5,64,5,16,21,6,6,6,6,6,6,6,6,6,5,5,5,64,5,5,5,64,5,5,64,5,5,5,29,29,29,29,29,29
29,29,29,29,29,29,5,5,5,5,5,5,5,5,5,5,5,5,5,6,6,6,6,6,6,6,6,6,6,5,5,5,5,5,5,5,5,5,5,5,5,5,5,29,29,29,29,29,29
29,29,29,29,29,29,5,5,5,5,5,5,5,5,5,5,5,5,5,6,6,6,6,6,6,6,6,6,6,5,5,5,5,5,5,5,5,5,5,5,5,5,5,29,29,29,29,29,29
29,29,29,29,29,29,5,5,5,5,5,5,5,5,5,5,5,5,5,6,6,6,6,6,6,6,6,6,6,5,5,5,5,5,5,5,5,5,5,5,5,5,5,29,29,29,29,29,29
29,29,29,29,29,29,5,5,5,5,5,5,5,5,5,5,5,5,5,6,6,6,6,6,6,6,6,6,6,5,5,5,5,5,5,5,5,5,5,5,5,5,5,29,29,29,29,29,29
29,29,29,29,29,29,5,5,5,64,5,5,64,5,5,5,64,5,5,6,6,6,6,6,6,6,6,6,6,5,5,5,64,5,5,5,64,5,5,64,5,5,5,29,29,29,29,29,29
29,29,29,29,29,29,5,5,5,5,5,5,5,5,5,5,5,5,5,6,6,6,6,6,6,6,6,6,6,5,5,5,5,5,5,5,5,5,5,5,5,5,5,29,29,29,29,29,29
29,29,29,29,29,29,5,5,5,5,5,5,5,5,5,5,5,5,5,6,6,6,6,6,6,6,6,6,6,5,5,5,5,5,5,5,5,5,5,5,5,5,5,29,29,29,29,29,29
29,29,29,29,29,29,5,5,5,5,5,5,5,5,5,5,5,5,5,5,5,5,5,5,5,5,5,5,5,5,5,5,5,5,5,5,5,5,5,5,5,5,5,29,29,29,29,29,29
29,29,29,29,29,29,5,5,5,5,5,5,5,5,5,5,5,5,5,5,5,5,5,5,5,5,5,5,5,5,5,5,5,5,5,5,5,5,5,5,5,5,5,29,29,29,29,29,29
29,29,29,29,29,29,5,5,5,64,5,5,64,5,5,5,64,5,5,5,5,64,5,5,5,5,5,64,5,5,5,5,64,5,5,5,5,5,5,5,5,5,5,29,29,29,29,29,29
29,29,29,29,29,29,5,5,5,5,5,5,5,5,5,5,5,5,5,5,5,5,5,5,5,5,5,5,5,5,5,5,5,5,5,5,5,5,5,5,5,5,5,29,29,29,29,29,29
29,29,29,29,29,29,5,5,5,5,5,5,5,5,5,5,5,5,5,5,5,5,5,5,5,5,5,5,5,5,5,5,5,5,5,5,5,5,5,5,5,5,5,29,29,29,29,29,29
29,29,29,29,29,29,5,5,5,5,5,5,5,5,5,5,5,5,5,5,5,5,5,5,5,5,5,5,5,5,5,5,5,5,5,5,5,5,5,5,5,5,5,29,29,29,29,29,29
29,29,29,29,29,29,5,5,5,5,5,5,5,5,5,5,5,5,5,5,5,5,5,5,5,5,5,5,5,5,5,5,5,5,5,5,5,5,5,5,5,5,5,29,29,29,29,29,29
29,29,29,29,29,29,5,5,5,64,5,5,64,5,5,5,64,5,5,5,5,5,5,5,5,5,5,5,5,5,5,5,64,5,5,5,64,5,5,64,5,5,5,29,29,29,29,29,29
29,29,29,29,29,29,5,5,5,5,5,5,5,5,5,5,5,5,5,5,5,5,5,5,5,5,5,5,5,5,5,5,5,5,5,5,5,5,5,5,5,5,5,29,29,29,29,29,29
29,29,29,29,29,29,5,5,5,5,5,5,5,5,5,5,5,5,5,5,5,5,5,5,5,5,5,5,5,5,5,5,5,5,5,5,5,5,5,5,5,5,5,29,29,29,29,29,29
29,29,29,29,29,29,5,5,5,5,5,5,5,5,5,5,5,5,5,5,5,5,5,5,5,5,5,5,5,5,5,5,5,5,5,5,5,5,5,5,5,5,5,29,29,29,29,29,29
29,29,29,29,29,29,5,5,5,5,5,5,5,5,5,5,5,5,5,5,5,5,5,5,5,5,5,5,5,5,5,5,5,5,5,5,5,5,5,5,5,5,5,29,29,29,29,29,29
29,29,29,29,29,29,5,5,5,64,5,5,64,5,5,5,64,5,5,5,5,5,5,5,5,5,5,5,5,5,5,5,64,5,5,5,5,5,5,5,5,5,5,29,29,29,29,29,29
29,29,29,29,29,29,5,5,5,5,5,5,5,5,5,5,5,5,5,5,5,5,5,5,5,5,5,5,5,5,5,5,5,5,5,5,5,5,5,5,5,5,5,29,29,29,29,29,29
29,29,29,29,29,29,5,5,5,5,5,5,5,5,5,5,5,5,5,5,5,5,5,5,5,5,5,5,5,5,5,5,5,5,5,5,5,5,5,5,5,5,5,29,29,29,29,29,29
29,29,29,29,29,29,5,5,5,5,5,5,5,5,5,5,5,5,5,5,5,5,5,5,5,5,5,5,5,5,5,5,5,5,5,5,5,5,5,5,5,5,5,29,29,29,29,29,29
29,29,29,29,5,5,5,5,5,5,5,5,64,5,5,5,64,5,5,5,5,64,5,5,5,5,5,64,5,5,5,5,64,5,5,5,65,5,5,5,5,5,5,5,5,29,29,29,29
29,29,29,5,5,5,5,5,5,5,5,5,5,5,5,5,5,5,5,5,5,5,5,5,5,5,5,5,5,5,5,5,5,5,5,5,5,5,6,6,6,6,6,6,6,6,29,29,29
29,29,5,5,5,5,5,5,5,5,5,5,5,5,5,5,5,5,5,5,5,5,5,5,5,5,5,5,5,5,5,5,5,5,5,5,5,5,6,0,0,0,0,0,0,0,6,29,29
29,6,29,29,5,5,5,5,5,5,5,5,5,5,5,5,5,5,5,5,5,5,5,5,5,5,5,5,5,5,5,5,5,5,5,5,5,5,6,0,0,0,0,0,0,0,6,5,29
29,6,52,52,6,5,5,5,5,5,5,5,5,5,5,5,5,5,5,5,5,5,5,5,5,5,5,12,12,5,5,5,5,5,5,5,5,5,6,0,0,0,0,0,6,6,6,5,29
29,6,0,0,6,6,5,5,5,5,5,5,5,5,5,5,5,5,5,5,5,5,5,5,5,5,5,5,12,5,5,5,5,5,5,5,5,5,6,0,0,0,0,0,52,52,6,5,29
29,6,0,0,0,63,5,5,5,5,5,5,53,53,53,53,53,53,5,5,5,5,5,5,5,5,5,5,54,5,5,53,53,53,53,53,53,5,6,0,0,0,0,0,0,0,6,5,29
29,6,0,0,0,63,5,5,5,5,5,5,53,53,53,53,53,53,5,5,5,5,5,5,5,5,5,5,5,5,5,53,53,53,53,53,53,5,6,0,0,0,0,0,0,0,6,5,29
29,29,6,6,6,6,6,6,6,5,5,53,53,53,53,53,53,53,53,5,5,5,5,5,5,5,5,29,5,5,53,53,53,53,53,53,53,53,5,6,0,0,0,0,0,0,6,29,29
29,29,29,5,5,5,5,5,5,5,53,53,53,53,53,53,53,53,53,53,53,29,29,29,29,29,29,29,53,53,53,53,53,53,53,53,53,53,53,5,6,6,6,6,6,6,29,29,29
29,29,29,29,5,5,5,5,5,53,53,53,53,53,53,53,53,53,53,53,53,53,53,53,53,53,53,53,53,53,53,53,53,53,53,53,53,53,53,53,5,5,5,5,5,29,29,29,29
29,29,29,29,29,29,29,29,29,29,53,53,53,53,53,53,53,53,53,53,53,53,53,53,53,53,53,53,53,53,53,53,53,53,53,53,53,53,53,29,29,29,29,29,29,29,29,29,29
29,29,29,29,29,29,29,29,29,29,29,53,53,53,53,53,53,53,53,53,53,53,53,53,53,53,53,53,53,53,53,53,53,53,53,53,53,53,29,29,29,29,29,29,29,29,29,29,29
29,29,29,29,29,29,29,29,29,29,29,29,53,53,53,53,53,53,53,53,53,53,53,53,53,53,53,53,53,53,53,53,53,53,53,53,53,29,29,29,29,29,29,29,29,29,29,29,29
29,29,29,29,29,29,29,29,29,29,29,29,29,53,53,53,53,53,53,53,53,53,53,53,53,53,53,53,53,53,53,53,53,53,53,53,29,29,29,29,29,29,29,29,29,29,29,29,29
29,29,29,29,29,29,29,29,29,29,29,29,29,29,53,53,53,53,53,53,53,53,53,53,53,53,53,53,53,53,53,53,53,53,53,29,29,29,29,29,29,29,29,29,29,29,29,29,29
29,29,29,29,29,29,29,29,29,29,29,29,29,29,29,29,29,29,29,5,29,29,29,29,29,29,29,5,29,5,29,29,29,29,29,29,29,29,29,29,29,29,29,29,29,29,29,29,29
29,29,29,29,29,29,29,29,29,29,29,29,29,29,29,29,29,29,5,5,5,29,29,29,29,29,29,29,0,12,5,29,29,29,29,29,29,29,29,29,29,29,29,29,29,29,29,29,29
29,29,29,29,29,29,29,29,29,29,29,29,29,29,29,29,29,29,29,29,29,29,29,29,29,29,29,29,29,29,29,29,29,29,29,29,29,29,29,29,29,29,29,29,29,29,29,29,29
:endlayer
layer: 6
66,66,0,0,66,0,0,0,0,0,0,0,0,0,0,66,0,0,0,66,0,0,0,0,0,0,0,0,0,66,0,66,66,66,66,0,66,0,0,0,0,66,0,0,0,0,0,0,0
0,0,0,0,6,6,6,6,6,0,0,0,0,0,0,66,66,66,66,0,0,0,0,0,0,0,0,66,0,66,66,0,66,0,0,0,0,0,0,0,6,6,6,6,6,0,0,0,0
0,0,0,6,6,6,6,6,6,6,0,0,0,0,0,66,0,0,66,66,0,0,0,0,0,66,0,0,66,0,66,66,0,0,0,0,0,0,0,6,6,6,6,6,6,6,0,0,0
0,0,6,6,6,6,6,6,6,6,6,0,0,0,0,66,66,0,66,0,66,66,66,66,0,66,0,0,66,66,66,66,0,66,0,0,0,0,6,6,6,6,6,6,6,6,6,0,0
0,6,6,6,6,6,6,6,6,6,6,6,0,0,0,66,66,66,66,66,66,0,0,0,66,0,66,66,0,66,66,66,0,66,0,0,0,6,6,6,6,6,6,6,6,6,6,6,66
0,6,6,6,6,6,6,6,6,6,6,6,0,0,0,0,0,0,0,0,0,0,0,0,0,0,0,0,0,0,0,0,0,0,0,0,0,6,6,6,6,6,6,6,6,6,6,6,0
0,6,6,6,6,6,6,6,6,6,6,6,6,6,6,6,6,6,6,6,6,6,6,6,6,6,6,6,6,6,6,6,6,6,6,6,6,6,6,6,6,6,6,6,6,6,6,6,0
66,6,6,6,6,6,6,6,6,6,6,6,6,6,6,6,6,6,6,6,6,6,6,6,6,6,6,6,6,6,6,29,29,29,29,29,29,6,6,6,6,6,6,6,6,6,6,6,0
0,6,6,6,6,6,6,6,6,6,6,6,6,6,6,6,67,6,6,6,6,6,6,6,6,6,6,6,6,6,6,29,29,29,29,29,29,6,6,6,6,6,6,6,6,6,6,6,0
0,0,6,6,6,6,6,6,6,6,6,6,6,6,6,6,6,6,6,6,6,6,6,6,6,6,26,0,0,18,6,29,29,29,29,29,6,6,6,6,6,6,6,6,6,6,6,0,0
0,0,0,6,6,6,6,6,6,6,6,6,6,6,6,6,6,6,6,6,6,6,6,6,6,6,6,6,6,6,6,29,29,29,29,6,6,6,6,6,6,6,6,6,6,6,0,0,0
0,0,0,0,6,6,6,6,6,6,6,6,6,6,6,6,6,6,6,6,6,6,6,6,6,6,6,6,6,6,6,29,29,29,6,6,6,6,6,6,6,6,6,6,6,0,0,0,0
66,0,0,0,0,0,6,6,6,6,6,6,6,6,6,6,6,6,6,6,6,6,6,6,68,6,6,6,6,6,6,6,6,6,6,6,6,6,6,6,6,6,6,0,0,0,0,0,0
0,66,0,0,0,0,6,6,6,67,6,6,67,6,6,6,67,6,6,6,6,6,6,6,6,6,6,6,6,6,6,6,67,6,6,6,67,6,6,67,6,6,6,0,0,0,0,0,0
66,0,0,0,0,0,6,6,6,6,6,6,6,6,6,6,6,6,6,6,6,6,6,6,6,6,6,6,6,6,6,6,6,6,6,6,6,6,6,6,6,6,6,0,0,0,0,0,66
0,0,0,66,66,0,6,29,29,29,29,29,29,29,29,6,6,6,6,6,6,68,6,6,6,6,68,6,6,6,6,6,6,6,6,29,29,29,29,29,29,29,6,0,0,0,0,0,66
0,0,66,0,0,0,6,29,29,29,29,29,29,29,29,6,6,6,6,6,6,6,6,6,6,6,6,6,6,6,6,6,6,6,6,29,29,29,29,29,29,29,6,0,0,0,0,0,66
0,0,0,66,0,0,6,29,29,29,29,29,29,29,29,6,6,6,6,6,6,6,6,6,6,6,6,6,6,6,6,6,6,6,6,29,29,29,29,29,29,29,6,0,0,0,66,0,66
0,0,0,0,0,0,6,29,29,67,29,29,67,29,29,6,67,6,6,6,6,6,6,6,6,6,6,6,6,6,6,6,67,6,6,29,67,29,29,67,29,29,6,0,0,0,0,66,66
0,0,0,0,66,0,6,29,29,29,29,29,29,29,29,6,6,6,6,6,6,6,6,6,6,6,6,6,6,6,6,6,6,6,6,29,29,29,29,29,29,29,6,0,0,0,0,0,0
0,0,0,66,0,0,6,29,29,29,29,29,29,29,29,6,6,6,6,6,6,6,6,6,6,6,6,6,6,6,6,6,6,6,6,29,29,29,29,29,29,29,6,0,0,0,0,66,66
66,66,0,0,66,0,6,29,29,29,29,29,29,29,29,6,6,6,6,6,6,6,6,6,6,6,6,6,6,6,6,6,6,6,6,29,29,29,29,29,29,29,6,0,0,0,0,0,0
0,0,0,0,0,0,6,29,29,29,29,29,29,29,29,6,6,6,6,6,6,6,6,6,6,6,6,6,6,6,6,6,6,6,6,29,29,29,29,29,29,29,6,0,0,0,0,0,66
66,66,0,0,0,0,6,29,29,67,29,29,67,29,29,6,67,6,6,6,6,67,6,69,69,69,6,67,6,6,6,6,67,6,6,6,6,6,6,6,6,6,6,0,0,0,0,66,66
0,0,0,0,0,0,6,29,29,29,29,29,29,29,29,6,6,6,6,6,6,6,6,69,69,69,6,6,6,6,6,6,6,6,6,6,6,6,6,6,6,6,6,0,0,0,0,0,0
66,0,0,0,0,0,6,29,29,29,29,29,29,29,29,6,6,6,6,6,6,6,6,69,69,69,6,6,6,6,6,6,6,6,6,6,6,6,6,6,6,6,6,0,0,0,0,0,66
66,66,0,0,66,0,6,29,29,29,29,29,29,29,29,6,6,6,6,6,6,6,6,69,69,69,6,6,6,6,6,6,6,6,6,6,6,6,6,6,6,6,6,0,66,0,0,66,66
66,66,0,0,0,0,6,29,29,29,29,29,29,29,29,6,6,6,6,6,6,6,6,69,69,69,6,6,6,6,6,6,6,6,6,6,6,6,6,6,6,6,6,0,0,0,66,0,66
66,66,0,0,0,0,6,29,29,67,29,29,67,29,29,6,67,6,6,6,6,6,6,69,69,69,6,6,6,6,6,6,67,6,6,6,67,6,6,67,6,6,6,0,0,66,66,0,66
0,66,0,0,0,0,6,29,29,29,29,29,29,29,29,6,6,6,6,6,6,6,6,69,69,69,6,6,6,6,6,6,6,6,6,6,6,6,6,6,6,6,6,0,66,0,66,66,66
66,0,66,0,0,0,6,29,29,29,29,29,29,29,29,6,6,6,6,6,6,6,6,69,69,69,6,6,6,6,6,6,6,6,6,6,6,6,6,6,6,6,6,0,66,0,66,66,66
66,66,0,66,0,0,6,29,29,29,29,29,29,29,29,6,6,6,6,6,6,6,6,69,69,69,6,6,6,6,6,6,6,6,6,6,6,6,6,6,6,6,6,0,0,0,66,0,66
66,66,66,0,0,0,6,29,29,29,29,29,29,29,29,6,6,6,6,6,6,6,6,69,69,69,6,6,6,6,6,6,6,6,6,6,6,6,6,6,6,6,6,0,0,66,0,0,66
66,66,0,66,0,0,6,29,29,67,29,29,67,29,29,6,67,6,6,6,6,6,6,69,69,69,6,6,6,6,6,6,67,6,6,6,6,6,6,6,6,6,6,0,0,0,66,0,0
66,66,66,0,0,0,6,6,6,6,6,6,6,6,6,6,6,6,6,6,6,6,6,69,69,69,6,6,6,6,6,6,6,6,6,6,6,6,6,6,6,6,6,0,0,0,0,0,0
0,0,66,66,0,0,6,6,6,6,6,6,6,6,6,6,6,6,6,6,6,6,6,69,69,69,6,6,6,6,6,6,6,6,6,6,6,6,6,6,6,6,6,0,0,0,0,0,0
0,0,0,0,0,0,6,6,6,6,6,6,6,6,6,6,6,6,6,6,6,6,6,69,69,69,6,6,6,6,6,6,6,6,6,6,6,6,6,6,6,6,6,0,0,66,0,66,66
0,0,0,0,6,6,6,6,6,6,6,6,67,6,6,6,67,6,6,6,6,67,6,69,69,69,6,67,6,6,6,6,67,6,6,6,67,6,6,6,6,6,6,6,6,0,0,0,0
0,0,0,6,6,6,6,6,6,6,6,6,6,6,6,6,6,6,6,6,6,6,6,69,69,69,6,6,6,6,6,6,6,6,6,6,6,6,6,6,6,6,6,6,6,6,0,0,0
0,0,6,6,6,6,6,6,6,6,6,6,6,6,6,6,6,6,6,6,6,6,6,69,69,69,6,6,6,6,6,6,6,6,6,6,6,6,6,6,6,6,6,6,6,6,6,0,0
0,6,52,52,6,6,6,6,6,6,6,6,6,6,6,6,6,6,6,6,6,65,6,6,6,6,6,6,6,6,6,6,6,6,6,6,6,6,6,6,6,6,6,6,6,6,6,6,0
0,6,0,0,6,6,6,6,6,6,6,6,6,6,6,6,6,6,6,6,6,6,6,6,6,6,6,54,6,6,6,6,6,6,6,6,6,6,6,6,6,6,6,6,52,52,6,6,0
0,6,0,0,6,6,6,6,6,6,6,6,6,6,6,6,6,6,6,6,6,12,6,6,6,6,6,12,6,6,6,6,6,6,6,6,6,6,6,6,6,6,6,6,0,0,6,6,0
0,6,0,0,63,6,6,6,6,6,6,6,0,0,0,0,0,0,6,6,6,12,6,6,6,6,6,70,6,6,6,0,0,0,0,0,0,6,6,6,6,6,6,6,0,0,6,6,0
66,6,71,71,63,6,6,6,6,6,6,6,0,0,0,0,0,0,6,6,6,6,6,6,6,6,6,6,6,6,6,0,0,0,0,0,0,6,6,6,6,6,6,6,0,0,6,6,0
0,0,6,6,6,6,6,6,6,6,6,0,0,0,0,0,0,0,0,6,6,6,6,6,6,6,6,72,6,6,0,0,0,0,0,0,0,0,6,6,6,6,6,6,6,6,6,0,0
0,0,0,6,6,6,6,6,6,6,0,0,0,0,0,0,0,0,0,0,0,0,0,0,0,0,0,0,0,0,0,0,0,0,0,0,0,0,0,6,6,6,6,6,6,6,0,0,0
66,0,0,0,6,6,6,6,6,0,0,0,0,0,0,0,0,0,0,0,0,0,0,0,0,0,0,0,0,0,0,0,0,0,0,0,0,0,0,0,6,6,6,6,6,0,0,0,0
66,0,0,0,0,0,0,66,0,0,0,0,0,0,0,0,0,0,0,0,0,0,0,0,0,0,0,0,0,0,0,0,0,0,0,0,0,0,0,0,0,0,0,66,0,0,0,0,66
0,0,66,66,0,0,66,0,0,0,0,0,0,0,0,0,0,0,0,0,0,0,0,0,0,0,0,0,0,0,0,0,0,0,0,0,0,0,66,0,0,0,66,66,66,0,66,66,66
0,0,66,0,66,0,66,66,0,0,66,0,0,0,0,0,0,0,0,0,0,0,0,0,0,0,0,0,0,0,0,0,0,0,0,0,0,0,66,0,0,0,66,66,66,66,66,66,66
0,66,66,0,66,0,0,0,0,0,0,66,0,0,0,0,0,0,0,0,0,0,0,0,0,0,0,0,0,0,0,0,0,0,0,0,0,0,0,0,0,66,66,0,66,66,66,66,0
0,66,0,0,0,0,0,66,0,66,0,0,0,66,0,0,0,0,0,0,0,0,0,0,0,0,0,0,0,0,0,0,0,0,0,0,0,0,0,66,0,0,0,66,0,66,66,0,0
66,66,0,0,66,0,0,66,0,0,0,0,66,73,0,0,0,0,74,6,74,75,75,75,75,75,75,75,74,6,74,0,0,0,0,0,0,0,0,0,0,0,66,66,66,66,0,0,0
0,66,0,0,66,66,66,0,0,0,0,66,0,0,0,0,0,0,6,6,6,75,75,75,75,75,75,75,6,6,6,0,0,0,0,0,0,0,0,0,0,0,0,0,66,0,66,66,66
0,0,66,0,0,0,66,66,66,0,0,0,0,0,0,0,0,0,0,0,0,0,0,0,0,0,0,0,0,22,0,0,0,0,0,0,0,0,0,66,66,0,0,66,0,66,66,0,0
:endlayer
layer: 7
0,0,0,0,0,0,0,0,0,0,0,0,0,0,0,0,0,0,0,0,0,0,0,0,0,0,0,0,0,0,0,0,0,0,0,0,0,0,0,0,0,0,0,0,0,0,0,0,0
0,0,0,0,6,6,6,6,6,0,0,0,0,0,0,0,0,0,0,0,0,0,0,0,0,0,0,0,0,0,0,0,0,0,0,0,0,0,0,0,6,6,6,6,6,0,0,0,0
0,0,0,6,6,6,6,11,0,6,0,0,0,0,0,0,0,0,0,0,0,0,0,0,0,0,0,0,0,0,0,0,0,0,0,0,0,0,0,6,0,18,6,6,6,6,0,0,0
0,0,6,6,6,6,6,11,0,0,6,0,0,0,0,0,0,0,0,0,0,0,0,0,0,0,0,0,0,0,0,0,0,0,0,0,0,0,6,0,0,18,6,6,6,6,6,0,0
0,6,76,0,0,0,0,0,0,0,77,6,0,0,0,0,0,0,0,0,0,0,0,0,0,0,0,0,0,0,0,0,0,0,0,0,0,6,78,0,0,0,0,0,0,0,79,6,0
0,6,80,81,0,0,0,0,0,82,83,6,0,0,0,0,0,0,0,0,0,0,0,0,0,0,0,0,0,0,0,0,0,0,0,0,0,6,80,81,0,0,0,0,0,82,83,6,0
0,6,0,0,0,0,10,0,0,0,0,6,6,6,6,6,6,6,6,6,6,6,6,6,6,6,6,6,6,6,6,6,6,6,6,6,6,6,0,0,0,0,10,0,0,0,0,6,0
0,6,80,81,0,0,0,0,0,0,0,84,0,0,0,0,0,0,6,0,0,18,28,15,6,65,6,85,85,85,6,73,0,73,0,0,86,6,80,81,0,0,0,0,0,82,83,6,0
0,6,87,0,0,0,0,0,0,0,0,6,0,0,0,0,0,0,6,0,0,18,65,0,0,6,0,88,88,88,6,0,86,0,86,73,0,6,89,0,0,0,0,0,0,0,90,6,0
0,0,6,0,0,91,0,91,0,0,6,0,0,0,0,0,0,0,6,0,0,6,6,6,6,12,6,6,6,6,6,0,73,73,0,0,0,0,6,0,0,0,0,91,0,0,6,0,0
0,0,0,6,92,93,0,93,94,6,0,0,0,0,0,0,0,0,6,0,0,0,25,95,95,95,25,95,95,0,6,86,86,0,86,0,0,0,0,6,0,0,0,93,96,6,0,0,0
0,0,0,0,6,6,6,6,6,0,0,0,0,0,0,0,0,0,6,0,0,0,0,97,75,98,95,75,95,0,6,73,73,86,0,0,0,0,0,0,6,99,6,6,6,0,0,0,0
0,0,0,0,0,0,6,0,0,0,0,0,0,0,0,0,0,0,6,0,0,0,0,0,0,0,0,0,0,0,6,0,0,0,0,0,0,0,0,0,0,0,6,0,0,0,0,0,0
0,0,0,0,0,0,6,0,0,0,0,0,0,0,0,0,0,0,6,0,0,0,0,0,0,0,0,0,0,0,6,0,0,0,0,0,0,0,0,0,0,0,6,0,0,0,0,0,0
0,0,0,0,0,0,6,100,100,100,100,100,100,100,100,100,0,0,6,0,0,0,0,0,0,0,0,0,0,0,6,0,0,0,100,100,100,100,100,100,100,100,6,0,0,0,0,0,0
0,0,0,0,0,0,6,0,0,0,0,0,0,0,0,100,0,0,6,0,0,0,0,0,0,0,0,0,0,0,6,0,0,0,100,0,0,0,0,0,0,0,6,0,0,0,0,0,0
0,0,0,0,0,0,6,0,0,0,0,0,0,0,0,100,0,0,6,0,0,0,0,0,0,0,0,0,0,0,6,0,0,0,100,0,0,0,0,0,0,0,6,0,0,0,0,0,0
0,0,0,0,0,0,6,0,0,0,0,0,0,0,0,100,0,0,6,101,0,0,0,0,0,0,0,0,0,101,6,0,0,0,100,0,0,0,0,0,0,0,6,0,0,0,0,0,0
0,0,0,0,0,0,6,0,0,0,0,0,0,0,0,100,0,0,6,97,0,0,0,0,0,0,0,0,0,98,6,0,0,0,100,0,0,0,0,0,0,0,6,0,0,0,0,0,0
0,0,0,0,0,0,6,0,0,0,0,0,0,0,0,100,0,0,6,97,0,0,0,0,0,0,0,0,0,98,6,0,0,0,102,0,0,0,0,0,0,0,6,0,0,0,0,0,0
0,0,0,0,0,0,6,0,0,0,0,0,0,0,0,100,0,0,6,97,0,0,0,0,0,0,0,0,0,98,6,0,0,0,100,0,0,0,0,0,0,0,6,0,0,0,0,0,0
0,0,0,0,0,0,6,0,0,0,0,0,0,0,0,100,0,0,6,103,103,98,0,0,0,0,19,97,103,103,6,0,0,0,100,0,0,0,0,0,0,0,6,0,0,0,0,0,0
0,0,0,0,0,0,6,0,0,0,0,0,0,0,0,100,0,0,6,6,6,6,6,0,0,0,6,6,6,6,6,0,0,0,100,0,0,0,0,0,0,0,6,0,0,0,0,0,0
0,0,0,0,0,0,6,0,0,0,0,0,0,0,0,100,0,0,0,0,0,0,0,0,0,0,22,0,0,0,0,0,0,0,100,0,0,0,0,0,0,0,6,0,0,0,0,0,0
0,0,0,0,0,0,6,0,0,0,0,0,0,0,0,100,0,0,0,0,0,0,0,0,0,0,0,0,0,0,0,0,0,0,6,6,6,6,6,6,6,6,6,0,0,0,0,0,0
0,0,0,0,0,0,6,0,0,0,0,0,0,0,0,100,0,0,0,0,0,0,0,0,0,0,0,0,0,0,0,0,0,0,0,0,0,0,0,0,0,0,6,0,0,0,0,0,0
0,0,0,0,0,0,6,0,0,0,0,0,0,0,0,100,0,0,0,0,0,0,0,0,0,0,0,0,0,0,0,0,0,0,0,0,0,0,0,0,0,0,6,0,0,0,0,0,0
0,0,0,0,0,0,6,0,0,0,0,0,0,0,0,100,0,0,0,0,0,0,0,0,0,0,0,0,0,0,0,0,0,0,0,0,0,0,0,0,0,0,6,0,0,0,0,0,0
0,0,0,0,0,0,6,0,0,0,0,0,0,0,0,100,0,0,0,0,0,0,100,0,0,0,100,0,0,0,0,0,0,0,0,0,0,0,0,0,0,0,6,0,0,0,0,0,0
0,0,0,0,0,0,6,0,0,0,0,0,0,0,0,100,0,74,74,74,74,11,0,0,0,0,0,74,74,74,74,11,0,0,0,0,0,0,0,0,0,0,6,0,0,0,0,0,0
0,0,0,0,0,0,6,0,0,0,0,0,0,0,0,104,0,18,105,106,105,11,0,0,0,0,0,18,105,106,105,11,0,0,0,0,0,0,0,0,0,0,6,0,0,0,0,0,0
0,0,0,0,0,0,6,0,0,0,0,0,0,0,0,100,0,18,106,107,106,11,0,0,0,0,0,18,106,107,106,11,0,0,6,6,6,6,6,6,6,6,6,0,0,0,0,0,0
0,0,0,0,0,0,6,0,0,0,0,0,0,0,0,100,0,18,105,106,105,11,0,0,0,0,0,18,105,106,105,11,0,0,6,6,6,6,6,6,6,6,6,0,0,0,0,0,0
0,0,0,0,0,0,6,0,0,0,0,0,0,0,0,100,0,18,52,52,52,52,100,0,0,0,100,52,52,52,52,52,0,0,0,0,0,0,0,0,0,108,6,0,0,0,0,0,0
0,0,0,0,0,0,6,100,100,100,100,100,100,100,100,100,0,0,0,0,0,0,0,0,0,0,0,0,0,0,0,0,0,0,0,0,0,0,0,0,0,109,6,0,0,0,0,0,0
0,0,0,0,0,0,6,0,0,0,0,0,0,0,0,0,0,0,0,0,0,0,0,0,0,0,0,0,0,0,0,0,0,0,0,0,0,0,0,0,0,110,6,0,0,0,0,0,0
0,0,0,0,0,0,6,0,0,0,0,0,0,0,0,0,0,0,0,0,0,0,0,0,0,0,0,0,0,0,0,0,0,0,0,0,0,0,0,0,0,111,6,0,0,0,0,0,0
0,0,0,0,6,6,6,0,6,0,0,0,0,0,0,0,0,0,0,0,0,0,0,0,0,0,0,0,0,0,0,0,0,0,0,0,0,6,6,6,6,21,6,6,6,0,0,0,0
0,0,0,6,0,0,0,0,0,6,0,0,0,0,0,0,0,0,0,0,0,0,0,0,0,0,0,0,0,0,0,0,0,0,6,6,6,6,6,6,0,0,0,0,0,6,0,0,0
0,0,6,0,0,0,0,0,0,0,6,0,0,0,0,0,0,0,0,0,0,0,0,0,0,0,0,19,0,0,0,0,0,0,0,0,0,0,6,0,0,0,0,0,0,0,6,0,0
0,6,0,0,0,0,0,0,0,0,0,6,0,0,0,0,0,0,6,6,6,6,0,0,0,0,0,6,6,6,6,0,0,0,0,0,0,6,0,0,0,0,0,0,0,0,0,6,0
0,6,0,0,0,0,0,0,0,0,0,112,0,0,0,0,0,0,113,0,0,6,0,0,0,0,114,6,0,0,115,0,0,0,0,0,0,116,0,0,0,0,0,0,0,0,0,6,0
0,6,0,0,0,0,10,0,0,0,0,6,6,6,6,6,6,6,6,0,117,6,0,0,0,0,0,6,26,0,6,6,6,6,6,6,6,6,0,0,0,0,0,0,0,0,0,6,0
0,6,0,0,0,0,0,0,0,0,0,6,0,0,0,0,0,0,6,0,0,6,0,0,0,0,0,6,0,0,6,0,0,0,0,0,0,6,0,0,0,0,10,0,0,0,0,6,0
0,6,0,0,0,0,0,0,0,0,0,6,0,0,0,0,0,0,6,0,0,6,0,0,0,0,0,6,0,0,6,0,0,0,0,0,0,6,0,0,0,0,0,0,0,0,0,6,0
0,0,6,6,6,6,6,11,0,0,6,0,0,0,0,0,0,0,0,6,6,6,0,0,0,0,0,6,6,6,0,0,0,0,0,0,0,0,6,0,0,18,6,6,6,6,6,0,0
0,0,0,6,6,6,6,11,0,6,0,0,0,0,0,0,0,0,0,0,0,0,0,0,0,0,0,0,0,0,0,0,0,0,0,0,0,0,0,6,0,18,6,6,6,6,0,0,0
0,0,0,0,6,6,6,6,6,0,0,0,0,0,0,0,0,0,0,0,0,0,0,0,0,0,0,0,0,0,0,0,0,0,0,0,0,0,0,0,6,6,6,6,6,0,0,0,0
0,0,0,0,0,0,0,0,0,0,0,0,0,0,0,0,0,0,0,0,0,0,0,0,0,0,0,0,0,0,0,0,0,0,0,0,0,0,0,0,0,0,0,0,0,0,0,0,0
0,0,0,0,0,0,0,0,0,0,0,0,0,0,0,0,0,0,0,0,0,0,0,0,0,0,0,0,0,0,0,0,0,0,0,0,0,0,0,0,0,0,0,0,0,0,0,0,0
0,0,0,0,0,0,0,0,0,0,0,0,0,0,0,0,0,0,0,0,0,0,0,0,0,0,0,0,0,0,0,0,0,0,0,0,0,0,0,0,0,0,0,0,0,0,0,0,0
0,0,0,0,0,0,0,0,0,0,0,0,0,0,0,0,0,0,0,0,0,0,0,0,0,0,0,0,0,0,0,0,0,0,0,0,0,0,0,0,0,0,0,0,0,0,0,0,0
0,0,0,0,0,0,0,0,0,0,0,0,0,0,0,0,0,0,0,0,0,0,0,0,0,0,0,0,0,0,0,0,0,0,0,0,0,0,0,0,0,0,0,0,0,0,0,0,0
0,0,0,0,0,0,0,0,0,0,0,0,0,0,0,0,0,0,0,74,0,0,0,0,0,0,0,0,0,74,0,0,0,0,0,0,0,0,0,0,0,0,0,0,0,0,0,0,0
0,0,0,0,0,0,0,0,0,0,0,0,0,0,0,0,0,0,18,6,11,0,0,0,0,0,0,0,18,6,11,0,0,0,0,0,0,0,0,0,0,0,0,0,0,0,0,0,0
0,0,0,0,0,0,0,0,0,0,0,0,0,0,0,0,0,0,0,0,0,0,0,0,0,0,0,0,0,0,0,0,0,0,0,0,0,0,0,0,0,0,0,0,0,0,0,0,0
:endlayer
layer: 8
0,0,0,0,0,0,0,0,0,0,0,0,0,0,0,0,0,0,0,0,0,0,0,0,0,0,0,0,0,0,0,0,0,0,0,0,0,0,0,0,0,0,0,0,0,0,0,0,0
0,0,0,0,6,6,6,6,6,0,0,0,0,0,0,0,0,0,0,0,0,0,0,0,0,0,0,0,0,0,0,0,0,0,0,0,0,0,0,0,6,6,6,6,6,0,0,0,0
0,0,0,6,6,6,11,0,0,6,0,0,0,0,0,0,0,0,0,0,0,0,0,0,0,0,0,0,0,0,0,0,0,0,0,0,0,0,0,6,0,0,18,6,6,6,0,0,0
0,0,6,6,6,6,11,0,0,0,6,0,0,0,0,0,0,0,0,0,0,0,0,0,0,0,0,0,0,0,0,0,0,0,0,0,0,0,6,0,0,0,18,6,6,6,6,0,0
0,6,0,0,0,0,0,0,0,0,0,6,0,0,0,0,0,0,0,0,0,0,0,0,0,0,0,0,0,0,0,0,0,0,0,0,0,6,0,0,0,0,0,0,0,0,0,6,0
0,6,0,0,0,0,0,0,0,0,0,6,0,0,0,0,0,0,0,0,0,0,0,0,0,0,0,0,0,0,0,0,0,0,0,0,0,6,0,0,0,0,0,0,0,0,0,6,0
0,6,0,0,0,0,0,0,0,0,0,6,6,6,6,6,6,6,6,6,6,6,6,6,6,6,6,6,6,6,6,6,6,6,6,6,6,6,0,0,0,0,0,0,0,0,0,6,0
0,6,0,0,0,0,0,0,0,0,0,118,0,0,0,0,0,0,6,0,0,0,18,0,28,6,6,85,85,85,6,0,0,0,0,0,0,6,0,0,0,0,0,0,0,0,0,6,0
0,6,0,0,0,0,0,0,0,0,0,6,0,0,0,0,0,0,6,0,0,0,18,27,0,0,0,88,88,88,6,0,0,0,0,0,0,6,0,0,0,0,0,0,0,0,0,6,0
0,0,6,0,0,0,0,0,0,0,6,0,0,0,0,0,0,0,6,0,0,6,6,6,6,6,6,6,6,6,6,0,0,0,0,0,0,0,6,0,0,0,0,0,0,0,6,0,0
0,0,0,6,0,0,0,0,0,6,0,0,0,0,0,0,0,0,6,0,0,0,0,119,120,121,119,101,121,0,6,0,0,0,0,0,0,0,0,6,0,0,0,0,0,6,0,0,0
0,0,0,0,6,6,6,6,6,0,0,0,0,0,0,0,0,0,6,0,0,0,0,0,0,0,0,0,0,0,6,0,0,0,0,0,0,0,0,0,6,122,6,6,6,0,0,0,0
0,0,0,0,0,0,6,0,0,0,0,0,0,0,0,0,0,0,6,0,0,0,0,0,0,0,0,0,0,0,6,0,0,0,0,0,0,0,0,0,0,0,6,0,0,0,0,0,0
0,0,0,0,0,0,6,0,0,0,0,0,0,0,0,0,0,0,6,0,0,0,0,0,0,0,0,0,0,0,6,0,0,0,0,0,0,0,0,0,0,0,6,0,0,0,0,0,0
0,0,0,0,0,0,6,100,100,100,100,100,100,100,100,100,0,0,6,0,0,0,0,0,0,0,0,0,0,0,6,0,0,0,100,100,100,100,100,100,100,100,6,0,0,0,0,0,0
0,0,0,0,0,0,6,0,0,0,0,0,0,0,0,100,0,0,6,0,0,0,0,0,0,0,0,0,0,0,6,0,0,0,100,0,0,0,0,0,0,0,6,0,0,0,0,0,0
0,0,0,0,0,0,6,0,0,0,0,0,0,0,0,100,0,0,123,0,0,0,0,0,0,0,0,0,0,0,123,0,0,0,100,0,0,0,0,0,0,0,6,0,0,0,0,0,0
0,0,0,0,0,0,6,0,0,0,0,0,0,0,0,100,0,0,123,0,0,0,0,0,0,0,0,0,0,0,123,0,0,0,100,0,0,0,0,0,0,0,6,0,0,0,0,0,0
0,0,0,0,0,0,6,0,0,0,0,0,0,0,0,100,0,0,123,0,0,0,0,0,0,0,0,0,0,0,123,0,0,0,100,0,0,0,0,0,0,0,6,0,0,0,0,0,0
0,0,0,0,0,0,6,0,0,0,0,0,0,0,0,100,0,0,123,0,0,0,0,0,0,0,0,0,0,0,123,0,0,0,0,0,0,0,0,0,0,0,6,0,0,0,0,0,0
0,0,0,0,0,0,6,0,0,0,0,0,0,0,0,100,0,0,6,0,0,0,0,0,0,0,0,0,0,0,6,0,0,0,100,0,0,0,0,0,0,0,6,0,0,0,0,0,0
0,0,0,0,0,0,6,0,0,0,0,0,0,0,0,100,0,0,6,0,0,0,0,0,0,0,0,0,0,0,6,0,0,0,100,0,0,0,0,0,0,0,6,0,0,0,0,0,0
0,0,0,0,0,0,6,0,0,0,0,0,0,0,0,100,0,0,6,6,123,123,6,0,0,0,6,123,123,6,6,0,0,0,100,0,0,0,0,0,0,0,6,0,0,0,0,0,0
0,0,0,0,0,0,6,0,0,0,0,0,0,0,0,100,0,0,0,0,0,0,0,0,0,0,0,0,0,0,0,0,0,0,100,0,0,0,0,0,0,0,6,0,0,0,0,0,0
0,0,0,0,0,0,6,0,0,0,0,0,0,0,0,100,0,0,0,0,0,0,0,0,0,0,0,0,0,0,0,0,0,0,6,6,6,6,6,6,6,6,6,0,0,0,0,0,0
0,0,0,0,0,0,6,0,0,0,0,0,0,0,0,100,0,0,0,0,0,0,0,0,0,0,0,0,0,0,0,0,0,0,0,0,0,0,0,0,0,0,6,0,0,0,0,0,0
0,0,0,0,0,0,6,0,0,0,0,0,0,0,0,100,0,0,0,0,0,0,0,0,0,0,0,0,0,0,0,0,0,0,0,0,0,0,0,0,0,0,6,0,0,0,0,0,0
0,0,0,0,0,0,6,0,0,0,0,0,0,0,0,100,0,0,0,0,0,0,0,0,0,0,0,0,0,0,0,0,0,0,0,0,0,0,0,0,0,0,6,0,0,0,0,0,0
0,0,0,0,0,0,6,0,0,0,0,0,0,0,0,100,0,0,0,0,0,0,100,0,0,0,100,0,0,0,0,0,0,0,0,0,0,0,0,0,0,0,6,0,0,0,0,0,0
0,0,0,0,0,0,6,0,0,0,0,0,0,0,0,100,0,0,0,0,0,0,0,0,0,0,0,0,0,0,0,0,0,0,0,0,0,0,0,0,0,0,6,0,0,0,0,0,0
0,0,0,0,0,0,6,0,0,0,0,0,0,0,0,0,0,0,0,106,0,0,0,0,0,0,0,0,0,106,0,0,0,0,0,0,0,0,0,0,0,0,6,0,0,0,0,0,0
0,0,0,0,0,0,6,0,0,0,0,0,0,0,0,100,0,0,106,107,106,0,0,0,0,0,0,0,106,107,106,0,0,0,6,6,6,6,6,6,6,6,6,0,0,0,0,0,0
0,0,0,0,0,0,6,0,0,0,0,0,0,0,0,100,0,0,0,106,0,0,0,0,0,0,0,0,0,106,0,0,0,0,6,6,6,6,6,6,6,6,6,0,0,0,0,0,0
0,0,0,0,0,0,6,0,0,0,0,0,0,0,0,100,0,0,0,0,0,0,100,0,0,0,100,0,0,0,0,0,0,0,0,0,0,0,0,0,0,0,6,0,0,0,0,0,0
0,0,0,0,0,0,6,100,100,100,100,100,100,100,100,100,0,0,0,0,0,0,0,0,0,0,0,0,0,0,0,0,0,0,0,0,0,0,0,0,0,0,6,0,0,0,0,0,0
0,0,0,0,0,0,6,0,0,0,0,0,0,0,0,0,0,0,0,0,0,0,0,0,0,0,0,0,0,0,0,0,0,0,0,0,0,0,0,0,0,0,6,0,0,0,0,0,0
0,0,0,0,0,0,6,0,0,0,0,0,0,0,0,0,0,0,0,0,0,0,0,0,0,0,0,0,0,0,0,0,0,0,0,0,0,0,0,0,0,0,6,0,0,0,0,0,0
0,0,0,0,6,6,6,0,6,0,0,0,0,0,0,0,0,0,0,0,0,0,0,0,0,0,0,0,0,0,0,0,0,0,0,0,0,124,7,125,6,6,6,6,6,0,0,0,0
0,0,0,6,0,0,0,0,0,6,0,0,0,0,0,0,0,0,0,0,0,0,0,0,0,0,0,0,0,0,0,0,0,0,6,6,6,6,6,6,0,0,0,0,0,6,0,0,0
0,0,6,0,0,0,0,0,0,0,6,0,0,0,0,0,0,0,0,0,0,0,0,0,0,0,0,0,0,0,0,0,0,0,0,0,0,0,6,0,0,0,0,0,0,0,6,0,0
0,6,0,0,0,0,0,0,0,0,0,6,0,0,0,0,0,0,6,6,6,6,0,0,0,0,0,6,6,6,6,0,0,0,0,0,0,6,0,0,0,0,0,0,0,0,0,6,0
0,6,0,0,0,0,0,0,0,0,0,126,0,0,0,0,0,0,127,0,0,6,0,0,0,0,0,6,0,0,128,0,0,0,0,0,0,129,0,0,0,0,0,0,0,0,0,6,0
0,6,0,0,0,0,0,0,0,0,0,6,6,6,6,6,6,6,6,0,0,0,0,0,0,0,0,0,0,0,6,6,6,6,6,6,6,6,0,0,0,0,0,0,0,0,0,6,0
0,6,0,0,0,0,0,0,0,0,0,6,0,0,0,0,0,0,6,0,0,0,0,0,0,0,0,0,0,0,6,0,0,0,0,0,0,6,0,0,0,0,0,0,0,0,0,6,0
0,6,0,0,0,0,0,0,0,0,0,6,0,0,0,0,0,0,6,0,0,6,0,0,0,0,0,6,0,0,6,0,0,0,0,0,0,6,0,0,0,0,0,0,0,0,0,6,0
0,0,6,6,6,6,11,0,0,0,6,0,0,0,0,0,0,0,0,6,6,6,0,0,0,0,0,6,6,6,0,0,0,0,0,0,0,0,6,0,0,0,18,6,6,6,6,0,0
0,0,0,6,6,6,11,0,0,6,0,0,0,0,0,0,0,0,0,0,0,0,0,0,0,0,0,0,0,0,0,0,0,0,0,0,0,0,0,6,0,0,18,6,6,6,0,0,0
0,0,0,0,6,6,6,6,6,0,0,0,0,0,0,0,0,0,0,0,0,0,0,0,0,0,0,0,0,0,0,0,0,0,0,0,0,0,0,0,6,6,6,6,6,0,0,0,0
0,0,0,0,0,0,0,0,0,0,0,0,0,0,0,0,0,0,0,0,0,0,0,0,0,0,0,0,0,0,0,0,0,0,0,0,0,0,0,0,0,0,0,0,0,0,0,0,0
0,0,0,0,0,0,0,0,0,0,0,0,0,0,0,0,0,0,0,0,0,0,0,0,0,0,0,0,0,0,0,0,0,0,0,0,0,0,0,0,0,0,0,0,0,0,0,0,0
0,0,0,0,0,0,0,0,0,0,0,0,0,0,0,0,0,0,0,0,0,0,0,0,0,0,0,0,0,0,0,0,0,0,0,0,0,0,0,0,0,0,0,0,0,0,0,0,0
0,0,0,0,0,0,0,0,0,0,0,0,0,0,0,0,0,0,0,0,0,0,0,0,0,0,0,0,0,0,0,0,0,0,0,0,0,0,0,0,0,0,0,0,0,0,0,0,0
0,0,0,0,0,0,0,0,0,0,0,0,0,0,0,0,0,0,0,0,0,0,0,0,0,0,0,0,0,0,0,0,0,0,0,0,0,0,0,0,0,0,0,0,0,0,0,0,0
0,0,0,0,0,0,0,0,0,0,0,0,0,0,0,0,0,0,0,0,0,0,0,0,0,0,0,0,0,0,0,0,0,0,0,0,0,0,0,0,0,0,0,0,0,0,0,0,0
0,0,0,0,0,0,0,0,0,0,0,0,0,0,0,0,0,0,0,10,0,0,0,0,0,0,0,0,0,10,0,0,0,0,0,0,0,0,0,0,0,0,0,0,0,0,0,0,0
0,0,0,0,0,0,0,0,0,0,0,0,0,0,0,0,0,0,0,0,0,0,0,0,0,0,0,0,0,0,0,0,0,0,0,0,0,0,0,0,0,0,0,0,0,0,0,0,0
:endlayer
layer: 9
0,0,0,0,0,0,0,0,0,0,0,0,0,0,0,0,0,0,0,0,0,0,0,0,0,0,0,0,0,0,0,0,0,0,0,0,0,0,0,0,0,0,0,0,0,0,0,0,0
0,0,0,0,6,6,6,6,6,0,0,0,0,0,0,0,0,0,0,0,0,0,0,0,0,0,0,0,0,0,0,0,0,0,0,0,0,0,0,0,6,6,6,6,6,0,0,0,0
0,0,0,6,6,11,59,0,0,6,0,0,0,0,0,0,0,0,0,0,0,0,0,0,0,0,0,0,0,0,0,0,0,0,0,0,0,0,0,6,0,0,59,18,6,6,0,0,0
0,0,6,6,6,11,0,0,0,0,6,0,0,0,0,0,0,0,0,0,0,0,0,0,0,0,0,0,0,0,0,0,0,0,0,0,0,0,6,0,0,0,0,18,6,6,6,0,0
0,6,0,0,0,0,0,0,0,0,0,6,0,0,0,0,0,0,0,0,0,0,0,0,0,0,0,0,0,0,0,0,0,0,0,0,0,6,0,0,0,0,0,0,0,0,0,6,0
0,6,0,0,0,0,0,0,0,0,0,6,0,0,0,0,0,0,0,0,0,0,0,0,0,0,0,0,0,0,0,0,0,0,0,0,0,6,0,0,0,0,0,0,0,0,0,6,0
0,6,60,0,0,0,0,0,0,0,61,6,6,6,6,6,6,6,6,6,6,6,6,6,6,6,6,6,6,6,6,6,6,6,6,6,6,6,60,0,0,0,0,0,0,0,61,6,0
0,6,0,0,0,0,0,0,0,0,0,6,0,0,0,0,59,0,6,59,0,0,0,18,0,28,15,6,6,6,6,0,0,0,59,0,0,6,0,0,0,0,0,0,0,0,0,6,0
0,6,0,0,0,0,0,0,0,0,0,6,60,0,0,0,0,0,6,0,0,0,0,18,0,0,0,0,0,0,6,0,0,0,0,0,61,6,0,0,0,0,0,0,0,0,0,6,0
0,0,6,0,0,0,0,0,0,0,6,0,0,0,0,0,0,0,6,130,63,6,6,6,6,6,6,6,6,6,6,0,0,0,0,0,0,0,6,0,0,0,0,0,0,0,6,0,0
0,0,0,6,0,0,27,0,0,6,0,0,0,0,0,0,0,0,6,0,0,0,0,98,131,97,98,131,97,0,6,0,0,0,0,0,0,0,0,6,0,0,27,0,0,6,0,0,0
0,0,0,0,6,6,6,6,6,59,0,0,0,0,0,0,0,0,6,0,0,0,0,0,0,0,0,0,0,0,6,0,0,0,0,0,0,0,0,59,6,6,6,6,6,0,0,0,0
0,0,0,0,0,0,6,0,0,0,0,0,0,0,0,0,0,0,6,0,0,0,0,0,0,0,0,0,0,0,6,0,0,0,0,0,0,0,0,0,0,0,6,0,0,0,0,0,0
0,0,0,0,0,0,6,60,0,0,0,0,0,0,0,0,0,0,6,0,0,0,0,0,0,0,0,0,0,0,6,0,0,0,0,0,0,0,0,0,0,61,6,0,0,0,0,0,0
0,0,0,0,0,0,6,0,0,0,0,0,0,0,0,0,0,0,6,0,0,0,0,0,0,0,0,0,0,0,6,0,0,0,0,0,0,0,0,0,0,0,6,0,0,0,0,0,0
0,0,0,0,0,0,6,0,0,0,0,0,0,0,0,0,0,0,6,0,0,0,0,0,0,0,0,0,0,0,6,0,0,0,0,0,0,0,0,0,0,0,6,0,0,0,0,0,0
0,0,0,0,0,0,6,0,0,0,0,0,0,0,0,0,0,0,123,0,0,0,0,0,0,0,0,0,0,0,123,0,0,0,0,0,0,0,0,0,0,0,6,0,0,0,0,0,0
0,0,0,0,0,0,6,0,0,0,0,0,0,0,0,0,0,0,123,0,0,0,0,0,0,0,0,0,0,0,123,0,0,0,0,0,0,0,0,0,0,0,6,0,0,0,0,0,0
0,0,0,0,0,0,6,60,0,0,0,0,0,0,0,0,0,0,123,0,0,0,0,0,0,0,0,0,0,0,123,0,0,0,0,0,0,0,0,0,0,61,6,0,0,0,0,0,0
0,0,0,0,0,0,6,0,0,0,0,0,0,0,0,0,0,0,123,0,0,0,0,0,0,0,0,0,0,0,123,0,0,0,0,0,0,0,0,0,0,0,6,0,0,0,0,0,0
0,0,0,0,0,0,6,0,0,0,0,0,0,0,0,0,0,0,6,0,0,0,0,0,0,0,0,0,0,0,6,0,0,0,0,0,0,0,0,0,0,0,6,0,0,0,0,0,0
0,0,0,0,0,0,6,0,0,0,0,0,0,0,0,0,0,0,6,0,0,0,0,0,0,0,0,0,0,0,6,0,0,0,0,0,0,0,0,0,0,0,6,0,0,0,0,0,0
0,0,0,0,0,0,6,0,0,0,0,0,0,0,0,0,0,0,6,6,123,123,6,0,0,0,6,123,123,6,6,0,0,0,0,0,0,0,0,0,0,0,6,0,0,0,0,0,0
0,0,0,0,0,0,6,60,0,0,0,0,0,0,0,0,0,0,0,0,0,0,0,0,0,0,0,0,0,0,0,0,0,0,0,0,0,0,0,0,0,61,6,0,0,0,0,0,0
0,0,0,0,0,0,6,0,0,0,0,0,0,0,0,0,0,0,0,0,0,0,0,0,0,0,0,0,0,0,0,0,0,0,6,6,6,6,6,6,6,6,6,0,0,0,0,0,0
0,0,0,0,0,0,6,0,0,0,0,0,0,0,0,0,0,0,0,0,0,0,0,0,0,0,0,0,0,0,0,0,0,0,0,0,0,0,0,0,0,0,6,0,0,0,0,0,0
0,0,0,0,0,0,6,0,0,0,0,0,0,0,0,0,0,0,0,0,0,0,0,0,0,0,0,0,0,0,0,0,0,0,0,0,0,0,0,0,0,0,6,0,0,0,0,0,0
0,0,0,0,0,0,6,0,0,0,0,0,0,0,0,0,0,0,0,0,0,0,0,0,0,0,0,0,0,0,0,0,0,0,0,0,0,0,0,0,0,0,6,0,0,0,0,0,0
0,0,0,0,0,0,6,60,0,0,0,0,0,0,0,0,0,0,0,0,0,0,100,0,0,0,100,0,0,0,0,0,0,0,0,0,0,0,0,0,0,61,6,0,0,0,0,0,0
0,0,0,0,0,0,6,0,0,0,0,0,0,0,0,0,0,0,0,0,0,0,0,0,0,0,0,0,0,0,0,0,0,0,0,0,0,0,0,0,0,0,6,0,0,0,0,0,0
0,0,0,0,0,0,6,0,0,0,0,0,0,0,0,0,0,0,0,106,0,0,0,0,0,0,0,0,0,106,0,0,0,0,0,0,0,0,0,0,0,0,6,0,0,0,0,0,0
0,0,0,0,0,0,6,0,0,0,0,0,0,0,0,0,0,0,106,107,106,0,0,0,0,0,0,0,106,107,106,0,0,0,6,6,6,6,6,6,6,6,6,0,0,0,0,0,0
0,0,0,0,0,0,6,0,0,0,0,0,0,0,0,0,0,0,0,106,0,0,0,0,0,0,0,0,0,106,0,0,0,0,6,6,6,6,6,6,6,6,6,0,0,0,0,0,0
0,0,0,0,0,0,6,60,0,0,0,0,0,0,0,0,0,0,0,0,0,0,100,0,0,0,100,0,0,0,0,0,0,0,0,0,0,0,0,0,0,61,6,0,0,0,0,0,0
0,0,0,0,0,0,6,0,0,0,0,0,0,0,0,0,0,0,0,0,0,0,0,0,0,0,0,0,0,0,0,0,0,0,0,0,0,0,0,0,0,0,6,0,0,0,0,0,0
0,0,0,0,0,0,6,0,0,0,0,0,0,0,0,0,0,0,0,0,0,0,0,0,0,0,0,0,0,0,0,0,0,0,0,0,0,0,0,0,0,0,6,0,0,0,0,0,0
0,0,0,0,0,0,6,0,0,0,0,0,0,0,0,0,0,0,0,0,0,0,0,0,0,0,0,0,0,0,0,0,0,0,0,0,0,0,0,27,0,0,6,0,0,0,0,0,0
0,0,0,0,6,6,6,6,6,27,0,0,0,0,0,0,0,0,0,0,0,0,0,0,0,0,0,0,0,0,0,0,0,0,0,0,0,6,6,6,6,6,6,6,6,0,0,0,0
0,0,0,6,0,0,59,0,0,6,0,0,0,0,0,0,0,0,0,0,0,0,0,0,0,0,0,0,0,0,0,0,0,0,6,6,6,6,6,6,0,0,59,0,0,6,0,0,0
0,0,6,0,0,0,0,0,0,0,6,0,0,0,0,0,0,0,0,0,0,27,0,0,0,0,0,27,0,0,0,0,0,0,0,0,0,0,6,0,0,0,0,0,0,0,6,0,0
0,6,0,0,0,0,0,0,0,0,0,6,60,0,0,0,0,0,6,6,6,6,0,0,0,0,0,6,6,6,6,0,0,0,0,0,61,6,0,0,0,0,0,0,0,0,0,6,0
0,6,0,0,0,0,0,0,0,0,0,6,0,0,0,0,27,0,6,0,0,6,0,0,0,0,0,6,0,0,6,0,27,0,0,0,0,6,0,0,0,0,0,0,0,0,0,6,0
0,6,60,0,0,0,0,0,0,0,61,6,6,6,6,6,6,6,6,60,0,6,0,0,0,0,0,6,0,61,6,6,6,6,6,6,6,6,60,0,0,0,0,0,0,0,61,6,0
0,6,0,0,0,0,0,0,0,0,0,6,0,0,0,0,0,0,6,0,0,6,0,0,0,0,0,6,0,0,6,0,0,0,0,0,0,6,0,0,0,0,0,0,0,0,0,6,0
0,6,0,0,0,0,0,0,0,0,0,6,0,0,0,0,0,0,6,0,0,6,0,0,0,0,0,6,0,0,6,0,0,0,0,0,0,6,0,0,0,0,0,0,0,0,0,6,0
0,0,6,6,6,11,0,0,0,0,6,0,0,0,0,0,0,0,0,6,6,6,0,0,0,0,0,6,6,6,0,0,0,0,0,0,0,0,6,0,0,0,0,18,6,6,6,0,0
0,0,0,6,6,11,27,0,0,6,0,0,0,0,0,0,0,0,0,0,0,0,0,0,0,0,0,0,0,0,0,0,0,0,0,0,0,0,0,6,0,0,27,18,6,6,0,0,0
0,0,0,0,6,6,6,6,6,0,0,0,0,0,0,0,0,0,0,0,0,0,0,0,0,0,0,0,0,0,0,0,0,0,0,0,0,0,0,0,6,6,6,6,6,0,0,0,0
0,0,0,0,0,0,0,0,0,0,0,0,0,0,0,0,0,0,0,0,0,0,0,0,0,0,0,0,0,0,0,0,0,0,0,0,0,0,0,0,0,0,0,0,0,0,0,0,0
0,0,0,0,0,0,0,0,0,0,0,0,0,0,0,0,0,0,0,0,0,0,0,0,0,0,0,0,0,0,0,0,0,0,0,0,0,0,0,0,0,0,0,0,0,0,0,0,0
0,0,0,0,0,0,0,0,0,0,0,0,0,0,0,0,0,0,0,0,0,0,0,0,0,0,0,0,0,0,0,0,0,0,0,0,0,0,0,0,0,0,0,0,0,0,0,0,0
0,0,0,0,0,0,0,0,0,0,0,0,0,0,0,0,0,0,0,0,0,0,0,0,0,0,0,0,0,0,0,0,0,0,0,0,0,0,0,0,0,0,0,0,0,0,0,0,0
0,0,0,0,0,0,0,0,0,0,0,0,0,0,0,0,0,0,0,0,0,0,0,0,0,0,0,0,0,0,0,0,0,0,0,0,0,0,0,0,0,0,0,0,0,0,0,0,0
0,0,0,0,0,0,0,0,0,0,0,0,0,0,0,0,0,0,0,0,0,0,0,0,0,0,0,0,0,0,0,0,0,0,0,0,0,0,0,0,0,0,0,0,0,0,0,0,0
0,0,0,0,0,0,0,0,0,0,0,0,0,0,0,0,0,0,0,0,0,0,0,0,0,0,0,0,0,0,0,0,0,0,0,0,0,0,0,0,0,0,0,0,0,0,0,0,0
0,0,0,0,0,0,0,0,0,0,0,0,0,0,0,0,0,0,0,0,0,0,0,0,0,0,0,0,0,0,0,0,0,0,0,0,0,0,0,0,0,0,0,0,0,0,0,0,0
:endlayer
layer: 10
0,0,0,0,0,0,0,0,0,0,0,0,0,0,0,0,0,0,0,0,0,0,0,0,0,0,0,0,0,0,0,0,0,0,0,0,0,0,0,0,0,0,0,0,0,0,0,0,0
0,0,0,0,6,6,6,6,6,0,0,0,0,0,0,0,0,0,0,0,0,0,0,0,0,0,0,0,0,0,0,0,0,0,0,0,0,0,0,0,6,6,6,6,6,0,0,0,0
0,0,0,6,11,0,0,0,0,6,0,0,0,0,0,0,0,0,0,0,0,0,0,0,0,0,0,0,0,0,0,0,0,0,0,0,0,0,0,6,0,0,0,0,18,6,0,0,0
0,0,6,6,11,0,0,0,0,0,6,0,0,0,0,0,0,0,0,0,0,0,0,0,0,0,0,0,0,0,0,0,0,0,0,0,0,0,6,0,0,0,0,0,18,6,6,0,0
0,6,0,0,0,0,0,0,0,0,0,6,0,0,0,0,0,0,0,0,0,0,0,0,0,0,0,0,0,0,0,0,0,0,0,0,0,6,0,0,0,0,0,0,0,0,0,6,0
0,6,0,0,0,0,0,0,0,0,0,6,0,0,0,0,0,0,0,0,0,0,0,0,0,0,0,0,0,0,0,0,0,0,0,0,0,6,0,0,0,0,0,0,0,0,0,6,0
0,6,0,0,0,0,0,0,0,0,0,6,6,6,6,6,6,6,6,6,6,6,6,6,6,6,6,6,6,6,6,6,6,6,6,6,6,6,0,0,0,0,0,0,0,0,0,6,0
0,6,0,0,0,0,0,0,0,0,0,6,0,0,0,0,0,0,6,0,0,0,0,0,18,0,0,132,133,134,6,0,0,0,0,0,0,6,0,0,0,0,0,0,0,0,0,6,0
0,6,0,0,0,0,0,0,0,0,0,6,0,0,0,0,0,0,6,0,0,27,0,0,18,27,0,0,0,61,6,0,0,0,0,0,0,6,0,0,0,0,0,0,0,0,0,6,0
0,0,6,0,0,0,0,0,0,0,6,0,0,0,0,0,0,0,6,6,6,6,6,6,6,6,6,6,6,6,6,0,0,0,0,0,0,0,6,0,0,0,0,0,0,0,6,0,0
0,0,0,6,0,0,0,0,0,6,0,0,0,0,0,0,0,0,6,0,0,59,0,0,0,0,0,59,0,0,6,0,0,0,0,0,0,0,0,6,0,0,0,0,0,6,0,0,0
0,0,0,0,6,6,6,6,6,0,0,0,0,0,0,0,0,0,6,0,0,0,0,0,0,0,0,0,0,0,6,0,0,0,0,0,0,0,0,0,6,6,6,6,6,0,0,0,0
0,0,0,0,0,0,6,0,0,0,0,0,0,0,0,0,0,0,6,60,0,0,0,0,0,0,0,0,0,61,6,0,0,0,0,0,0,0,0,0,0,0,6,0,0,0,0,0,0
0,0,0,0,0,0,6,0,0,0,0,0,0,0,0,0,0,0,6,0,0,0,0,0,0,0,0,0,0,0,6,0,0,0,0,0,0,0,0,0,0,0,6,0,0,0,0,0,0
0,0,0,0,0,0,6,0,0,0,0,0,0,0,0,0,0,0,6,0,0,0,0,0,0,0,0,0,0,0,6,0,0,0,0,0,0,0,0,0,0,0,6,0,0,0,0,0,0
0,0,0,0,0,0,6,0,0,0,0,0,0,0,0,0,0,0,6,0,0,0,0,0,0,0,0,0,0,0,6,0,0,0,0,0,0,0,0,0,0,0,6,0,0,0,0,0,0
0,0,0,0,0,0,6,0,0,0,0,0,0,0,0,0,0,0,6,0,0,0,0,0,0,0,0,0,0,0,6,0,0,0,0,0,0,0,0,0,0,0,6,0,0,0,0,0,0
0,0,0,0,0,0,6,0,0,0,0,0,0,0,0,0,0,0,6,0,0,0,0,0,0,0,0,0,0,0,6,0,0,0,0,0,0,0,0,0,0,0,6,0,0,0,0,0,0
0,0,0,0,0,0,6,0,0,0,0,0,0,0,0,0,0,0,6,0,0,0,0,0,0,0,0,0,0,0,6,0,0,0,0,0,0,0,0,0,0,0,6,0,0,0,0,0,0
0,0,0,0,0,0,6,0,0,0,0,0,0,0,0,0,0,0,6,60,0,0,0,0,0,0,0,0,0,61,6,0,0,0,0,0,0,0,0,0,0,0,6,0,0,0,0,0,0
0,0,0,0,0,0,6,0,0,0,0,0,0,0,0,0,0,0,6,0,0,0,0,0,0,0,0,0,0,0,6,0,0,0,0,0,0,0,0,0,0,0,6,0,0,0,0,0,0
0,0,0,0,0,0,6,0,0,0,0,0,0,0,0,0,0,0,6,0,0,27,0,0,0,0,0,27,0,0,6,0,0,0,0,0,0,0,0,0,0,0,6,0,0,0,0,0,0
0,0,0,0,0,0,6,0,0,0,0,0,0,0,0,0,0,0,6,6,6,6,6,6,6,6,6,6,6,6,6,0,0,0,0,0,0,0,0,0,0,0,6,0,0,0,0,0,0
0,0,0,0,0,0,6,0,0,0,0,0,0,0,0,0,0,0,0,0,0,0,0,0,0,0,0,0,0,0,0,0,0,0,0,0,0,0,0,0,0,0,6,0,0,0,0,0,0
0,0,0,0,0,0,6,0,0,0,0,0,0,0,0,0,0,0,0,0,0,0,0,0,0,0,0,0,0,0,0,0,0,0,6,6,6,6,6,6,6,6,6,0,0,0,0,0,0
0,0,0,0,0,0,6,0,0,0,0,0,0,0,0,0,0,0,0,0,0,0,0,0,0,0,0,0,0,0,0,0,0,0,62,0,0,0,0,0,0,0,6,0,0,0,0,0,0
0,0,0,0,0,0,6,0,0,0,0,0,0,0,0,0,0,0,0,0,0,0,0,0,0,0,0,0,0,0,0,0,0,0,0,0,0,0,0,0,0,0,6,0,0,0,0,0,0
0,0,0,0,0,0,6,0,0,0,0,0,0,0,0,0,0,0,0,0,0,0,27,0,0,0,27,0,0,0,0,0,0,0,0,0,0,0,0,0,0,0,6,0,0,0,0,0,0
0,0,0,0,0,0,6,0,0,0,0,0,0,0,0,0,0,0,0,0,0,61,135,60,0,0,135,60,0,0,0,0,0,0,0,0,0,0,0,0,0,0,6,0,0,0,0,0,0
0,0,0,0,0,0,6,0,0,0,0,0,0,0,0,0,0,0,0,0,0,0,59,0,0,0,59,0,0,0,0,0,0,0,0,0,0,0,0,0,0,0,6,0,0,0,0,0,0
0,0,0,0,0,0,6,0,0,0,0,0,0,0,0,0,0,0,0,106,0,0,0,0,0,0,0,0,0,106,0,0,0,0,71,0,0,0,0,0,0,0,6,0,0,0,0,0,0
0,0,0,0,0,0,6,0,0,0,0,0,0,0,0,0,0,0,106,107,106,0,0,0,0,0,0,0,106,107,106,0,0,0,6,6,6,6,6,6,6,6,6,0,0,0,0,0,0
0,0,0,0,0,0,6,0,0,0,0,0,0,0,0,0,0,0,0,106,0,0,27,0,0,0,27,0,0,106,0,0,0,0,6,6,6,6,6,6,6,6,6,0,0,0,0,0,0
0,0,0,0,0,0,6,0,0,0,0,0,0,0,0,0,0,0,0,0,0,61,135,60,0,61,135,60,0,0,0,0,0,0,62,0,59,0,0,0,0,0,6,0,0,0,0,0,0
0,0,0,0,0,0,6,0,0,0,0,0,0,0,0,0,0,0,0,0,0,0,59,0,0,0,59,0,0,0,0,0,0,0,0,0,0,0,0,0,0,0,6,0,0,0,0,0,0
0,0,0,0,0,0,6,0,0,0,0,0,0,0,0,0,0,0,0,0,0,0,0,0,0,0,0,0,0,0,0,0,0,0,0,0,0,0,0,0,0,0,6,0,0,0,0,0,0
0,0,0,0,0,0,6,0,0,0,0,0,0,0,0,0,0,0,0,0,0,0,0,0,0,0,0,0,0,0,0,0,0,0,0,0,0,0,0,0,0,0,6,0,0,0,0,0,0
0,0,0,0,6,6,6,6,6,0,0,0,0,0,0,0,0,0,0,0,0,0,0,0,0,0,0,0,0,0,0,0,0,0,71,0,0,18,6,6,6,6,6,6,6,0,0,0,0
0,0,0,6,0,0,0,0,0,6,0,0,0,0,0,0,0,0,0,0,0,0,0,0,0,0,0,0,0,0,0,0,0,0,6,6,6,6,6,6,0,0,0,0,0,6,0,0,0
0,0,6,0,0,0,0,0,0,0,6,0,0,0,0,0,0,0,0,0,0,0,0,0,0,0,0,0,0,0,0,0,0,0,0,0,0,0,6,0,0,0,0,0,0,0,6,0,0
0,6,0,0,0,0,0,0,0,0,0,6,0,0,0,0,0,0,6,6,6,6,0,0,0,0,0,6,6,6,6,0,0,0,0,0,0,6,0,0,0,0,0,0,0,0,0,6,0
0,6,0,0,0,0,0,0,0,0,0,6,0,0,0,0,0,0,6,0,0,6,60,0,0,0,61,6,0,0,6,0,0,0,0,0,0,6,0,0,0,0,0,0,0,0,0,6,0
0,6,0,0,0,0,0,0,0,0,0,6,6,6,6,6,6,6,6,0,0,6,0,0,0,0,0,6,0,0,6,6,6,6,6,6,6,6,0,0,0,0,0,0,0,0,0,6,0
0,6,0,0,0,0,0,0,0,0,0,6,0,0,0,0,0,0,6,0,0,6,0,0,0,0,0,6,0,0,6,0,0,0,0,0,0,6,0,0,0,0,0,0,0,0,0,6,0
0,6,0,0,0,0,0,0,0,0,0,6,0,0,0,0,0,0,6,0,0,6,60,0,0,0,61,6,0,0,6,0,0,0,0,0,0,6,0,0,0,0,0,0,0,0,0,6,0
0,0,6,6,11,0,0,0,0,0,6,0,0,0,0,0,0,0,0,6,6,6,0,0,0,0,0,6,6,6,0,0,0,0,0,0,0,0,6,0,0,0,0,0,18,6,6,0,0
0,0,0,6,11,0,0,0,0,6,0,0,0,0,0,0,0,0,0,0,0,0,0,0,0,0,0,0,0,0,0,0,0,0,0,0,0,0,0,6,0,0,0,0,18,6,0,0,0
0,0,0,0,6,6,6,6,6,0,0,0,0,0,0,0,0,0,0,0,0,0,0,0,0,0,0,0,0,0,0,0,0,0,0,0,0,0,0,0,6,6,6,6,6,0,0,0,0
0,0,0,0,0,0,0,0,0,0,0,0,0,0,0,0,0,0,0,0,0,0,0,0,0,0,0,0,0,0,0,0,0,0,0,0,0,0,0,0,0,0,0,0,0,0,0,0,0
0,0,0,0,0,0,0,0,0,0,0,0,0,0,0,0,0,0,0,0,0,0,0,0,0,0,0,0,0,0,0,0,0,0,0,0,0,0,0,0,0,0,0,0,0,0,0,0,0
0,0,0,0,0,0,0,0,0,0,0,0,0,0,0,0,0,0,0,0,0,0,0,0,0,0,0,0,0,0,0,0,0,0,0,0,0,0,0,0,0,0,0,0,0,0,0,0,0
0,0,0,0,0,0,0,0,0,0,0,0,0,0,0,0,0,0,0,0,0,0,0,0,0,0,0,0,0,0,0,0,0,0,0,0,0,0,0,0,0,0,0,0,0,0,0,0,0
0,0,0,0,0,0,0,0,0,0,0,0,0,0,0,0,0,0,0,0,0,0,0,0,0,0,0,0,0,0,0,0,0,0,0,0,0,0,0,0,0,0,0,0,0,0,0,0,0
0,0,0,0,0,0,0,0,0,0,0,0,0,0,0,0,0,0,0,0,0,0,0,0,0,0,0,0,0,0,0,0,0,0,0,0,0,0,0,0,0,0,0,0,0,0,0,0,0
0,0,0,0,0,0,0,0,0,0,0,0,0,0,0,0,0,0,0,0,0,0,0,0,0,0,0,0,0,0,0,0,0,0,0,0,0,0,0,0,0,0,0,0,0,0,0,0,0
0,0,0,0,0,0,0,0,0,0,0,0,0,0,0,0,0,0,0,0,0,0,0,0,0,0,0,0,0,0,0,0,0,0,0,0,0,0,0,0,0,0,0,0,0,0,0,0,0
:endlayer
layer: 11
0,0,0,0,0,0,0,0,0,0,0,0,0,0,0,0,0,0,0,0,0,0,0,0,0,0,0,0,0,0,0,0,0,0,0,0,0,0,0,0,0,0,0,0,0,0,0,0,0
0,0,0,0,6,6,6,6,6,0,0,0,0,0,0,0,0,0,0,0,0,0,0,0,0,0,0,0,0,0,0,0,0,0,0,0,0,0,0,0,6,6,6,6,6,0,0,0,0
0,0,0,6,0,0,0,6,6,6,0,0,0,0,0,0,0,0,0,0,0,0,0,0,0,0,0,0,0,0,0,0,0,0,0,0,0,0,0,6,6,6,0,0,0,6,0,0,0
0,0,6,0,0,0,0,6,6,6,6,0,0,0,0,0,0,0,0,0,0,0,0,0,0,0,0,0,0,0,0,0,0,0,0,0,0,0,6,6,6,6,0,0,0,0,6,0,0
0,6,6,74,18,6,6,6,6,6,6,6,0,0,0,0,0,0,0,0,0,0,0,0,0,0,0,0,0,0,0,0,0,0,0,0,0,6,6,6,6,6,6,6,11,74,6,6,0
0,6,6,6,6,6,6,6,6,6,6,6,0,0,0,0,0,0,0,0,0,0,0,0,0,0,0,0,0,0,0,0,0,0,0,0,0,6,6,6,6,6,6,6,6,6,6,6,0
0,6,6,6,6,6,6,6,6,6,6,6,6,6,6,6,6,6,6,6,6,6,6,6,6,6,6,6,6,6,6,6,6,6,6,6,6,6,6,6,6,6,6,6,6,6,6,6,0
0,6,6,6,6,6,6,6,6,6,6,6,0,0,0,0,0,0,6,0,0,0,0,0,0,18,6,6,6,6,6,0,0,0,0,0,0,6,6,6,6,6,6,6,6,6,6,6,0
0,6,6,6,6,6,6,6,6,6,6,6,0,0,0,0,0,61,6,0,0,0,0,0,0,18,6,6,6,6,6,60,0,0,0,0,0,6,6,6,6,6,6,6,6,6,6,6,0
0,0,6,6,6,6,6,6,6,6,6,0,0,0,0,0,0,0,6,6,6,6,6,6,6,6,6,6,6,6,6,0,0,0,0,0,0,0,6,6,6,6,6,6,6,6,6,0,0
0,0,0,6,6,6,6,6,6,6,0,0,0,0,0,0,0,0,6,6,6,6,6,6,6,6,6,6,6,6,6,0,0,0,0,0,0,0,0,6,6,6,6,6,6,6,0,0,0
0,0,0,0,6,6,6,6,6,6,0,0,0,0,0,0,0,0,6,6,6,6,6,6,6,6,6,6,6,6,6,0,0,0,0,0,0,0,0,6,6,6,6,6,6,0,0,0,0
0,0,0,0,0,0,6,6,6,6,0,0,0,0,0,0,0,0,6,6,6,6,6,6,68,6,6,6,6,6,6,0,0,0,0,0,0,0,0,6,6,6,6,0,0,0,0,0,0
0,0,0,0,0,0,6,6,6,6,0,0,0,0,0,0,0,61,6,6,6,6,6,6,6,6,6,6,6,6,6,60,0,0,0,0,0,0,0,6,6,6,6,0,0,0,0,0,0
0,0,0,0,0,0,6,6,6,6,0,0,0,0,0,0,0,0,6,6,6,6,6,6,6,6,6,6,6,6,6,0,0,0,0,0,0,0,0,6,6,6,6,0,0,0,0,0,0
0,0,0,0,0,0,6,6,6,6,0,0,0,0,0,0,0,0,6,6,6,68,6,6,6,6,68,6,6,6,6,0,0,0,0,0,0,0,0,6,6,6,6,0,0,0,0,0,0
0,0,0,0,0,0,6,6,6,6,0,0,0,0,0,0,0,0,6,6,6,6,6,6,6,6,6,6,6,6,6,0,0,0,0,0,0,0,0,6,6,6,6,0,0,0,0,0,0
0,0,0,0,0,0,6,6,6,6,0,0,0,0,0,0,0,0,6,6,6,6,6,6,6,6,6,6,6,6,6,0,0,0,0,0,0,0,0,6,6,6,6,0,0,0,0,0,0
0,0,0,0,0,0,6,6,6,6,0,0,0,0,0,0,0,61,6,6,6,6,6,6,6,6,6,6,6,6,6,60,0,0,0,0,0,0,0,6,6,6,6,0,0,0,0,0,0
0,0,0,0,0,0,6,6,6,6,0,0,0,0,0,0,0,0,6,6,6,6,6,6,6,6,6,6,6,6,6,0,0,0,0,0,0,0,0,6,6,6,6,0,0,0,0,0,0
0,0,0,0,0,0,6,6,6,6,0,0,0,0,0,0,0,0,6,6,6,6,6,6,6,6,6,6,6,6,6,0,0,0,0,0,0,0,0,6,6,6,6,0,0,0,0,0,0
0,0,0,0,0,0,6,6,6,6,0,0,0,0,0,0,0,0,6,6,6,6,6,6,6,6,6,6,6,6,6,0,0,0,0,0,0,0,0,6,6,6,6,0,0,0,0,0,0
0,0,0,0,0,0,6,6,6,6,0,0,0,0,0,0,0,0,6,6,6,6,6,6,6,6,6,6,6,6,6,0,0,0,0,0,0,0,0,6,6,6,6,0,0,0,0,0,0
0,0,0,0,0,0,6,6,6,6,0,0,0,0,0,0,0,0,0,0,0,59,0,0,0,0,0,59,0,0,0,0,0,0,0,0,0,0,0,6,6,6,6,0,0,0,0,0,0
0,0,0,0,0,0,6,6,6,6,0,0,0,0,0,0,0,0,0,0,0,0,0,0,0,0,0,0,0,0,0,0,0,0,6,6,6,6,6,6,6,6,6,0,0,0,0,0,0
0,0,0,0,0,0,6,6,6,6,0,0,0,0,0,0,0,0,0,0,0,0,0,0,0,0,0,0,0,0,0,0,0,61,6,6,6,6,6,6,6,6,6,0,0,0,0,0,0
0,0,0,0,0,0,6,6,6,6,0,0,0,0,0,0,0,0,0,0,0,0,0,0,0,0,0,0,0,0,0,0,0,0,6,6,6,6,6,6,6,6,6,0,0,0,0,0,0
0,0,0,0,0,0,6,6,6,6,0,0,0,0,0,0,0,0,0,0,0,0,0,0,0,0,0,0,0,0,0,0,0,0,6,6,6,6,6,6,6,6,6,0,0,0,0,0,0
0,0,0,0,0,0,6,6,6,6,0,0,0,0,0,0,0,0,0,0,0,0,0,0,0,0,0,0,0,0,0,0,0,0,6,6,6,6,6,6,6,6,6,0,0,0,0,0,0
0,0,0,0,0,0,6,6,6,6,0,0,0,0,0,0,0,0,0,0,0,0,0,0,0,0,0,0,0,0,0,0,0,0,6,6,6,6,6,6,6,6,6,0,0,0,0,0,0
0,0,0,0,0,0,6,6,6,6,0,0,0,0,0,0,0,0,0,105,0,0,0,0,0,0,0,0,0,105,0,0,0,61,6,6,6,6,6,6,6,6,6,0,0,0,0,0,0
0,0,0,0,0,0,6,6,6,6,0,0,0,0,0,0,0,0,105,53,105,0,0,0,0,0,0,0,105,53,105,0,0,0,6,6,6,6,6,6,6,6,6,0,0,0,0,0,0
0,0,0,0,0,0,6,6,6,6,0,0,0,0,0,0,0,0,0,105,0,0,0,0,0,0,0,0,0,105,0,0,0,0,6,6,6,6,6,6,6,6,6,0,0,0,0,0,0
0,0,0,0,0,0,6,6,6,6,0,0,0,0,0,0,0,0,0,0,0,0,0,0,0,0,0,0,0,0,0,0,0,61,6,0,0,0,6,6,6,6,6,0,0,0,0,0,0
0,0,0,0,0,0,6,6,6,6,0,0,0,0,0,0,0,0,0,0,0,0,0,0,0,0,0,0,0,0,0,0,0,0,6,0,0,0,6,6,6,6,6,0,0,0,0,0,0
0,0,0,0,0,0,6,6,6,6,0,0,0,0,0,0,0,0,0,0,0,0,0,0,0,0,0,0,0,0,0,0,0,0,6,0,0,0,6,6,6,6,6,0,0,0,0,0,0
0,0,0,0,0,0,6,6,6,6,0,0,0,0,0,0,0,0,0,0,0,0,0,0,0,0,0,0,0,0,0,0,0,0,6,0,0,0,6,6,6,6,6,0,0,0,0,0,0
0,0,0,0,6,6,6,6,6,6,0,0,0,0,0,0,0,0,0,0,0,0,0,0,0,0,0,0,0,0,0,0,0,61,6,0,0,0,6,6,6,6,6,6,6,0,0,0,0
0,0,0,6,6,6,6,6,6,6,0,0,0,0,0,0,0,0,0,0,0,0,0,0,0,0,0,0,0,0,0,0,0,0,6,6,6,6,6,6,6,6,6,6,6,6,0,0,0
0,0,6,6,6,6,6,6,6,6,6,6,6,6,6,6,6,6,6,6,6,6,6,6,6,6,6,6,6,6,6,6,6,6,6,6,6,6,6,6,6,6,6,6,6,6,6,0,0
0,6,6,6,6,6,6,6,6,6,6,6,6,6,6,6,6,6,6,6,6,6,6,6,6,6,6,6,6,6,6,6,6,6,6,6,6,6,6,6,6,6,6,6,6,6,6,6,0
0,6,6,6,6,6,6,6,6,6,6,6,6,6,6,6,6,6,6,6,6,6,6,0,6,0,6,6,6,6,6,6,6,6,6,6,6,6,6,6,6,6,6,6,6,6,6,6,0
0,6,6,6,6,6,6,6,6,6,6,6,6,6,6,6,6,6,6,6,6,6,6,6,6,6,6,6,6,6,6,6,6,6,6,6,6,6,6,6,6,6,6,6,6,6,6,6,0
0,6,6,6,6,6,6,6,6,6,6,6,0,0,0,0,0,0,6,0,0,6,0,0,0,0,0,6,0,0,6,0,0,0,0,0,0,6,6,6,6,6,6,6,6,6,6,6,0
0,6,6,52,18,6,6,6,6,6,6,6,0,0,0,0,0,0,6,0,0,6,0,0,0,0,0,6,0,0,6,0,0,0,0,0,0,6,6,6,6,6,6,6,11,52,6,6,0
0,0,6,0,0,0,0,0,6,6,6,0,0,0,0,0,0,0,0,6,6,6,0,0,0,0,0,6,6,6,0,0,0,0,0,0,0,0,6,6,6,0,0,0,0,0,6,0,0
0,0,0,6,0,0,0,0,6,6,0,0,0,0,0,0,0,0,0,0,59,0,0,0,0,0,0,0,59,0,0,0,0,0,0,0,0,0,0,6,6,0,0,0,0,6,0,0,0
0,0,0,0,6,6,6,6,6,0,0,0,0,0,0,0,0,0,0,0,0,0,0,0,0,0,0,0,0,0,0,0,0,0,0,0,0,0,0,0,6,6,6,6,6,0,0,0,0
0,0,0,0,0,0,0,0,0,0,0,0,0,0,0,0,0,0,0,0,0,0,0,0,0,0,0,0,0,0,0,0,0,0,0,0,0,0,0,0,0,0,0,0,0,0,0,0,0
0,0,0,0,0,0,0,0,0,0,0,0,0,0,0,0,0,0,0,0,0,0,0,0,0,0,0,0,0,0,0,0,0,0,0,0,0,0,0,0,0,0,0,0,0,0,0,0,0
0,0,0,0,0,0,0,0,0,0,0,0,0,0,0,0,0,0,0,0,0,0,0,0,0,0,0,0,0,0,0,0,0,0,0,0,0,0,0,0,0,0,0,0,0,0,0,0,0
0,0,0,0,0,0,0,0,0,0,0,0,0,0,0,0,0,0,0,0,0,0,0,0,0,0,0,0,0,0,0,0,0,0,0,0,0,0,0,0,0,0,0,0,0,0,0,0,0
0,0,0,0,0,0,0,0,0,0,0,0,0,0,0,0,0,0,0,0,0,0,0,0,0,0,0,0,0,0,0,0,0,0,0,0,0,0,0,0,0,0,0,0,0,0,0,0,0
0,0,0,0,0,0,0,0,0,0,0,0,0,0,0,0,0,0,0,0,0,0,0,0,0,0,0,0,0,0,0,0,0,0,0,0,0,0,0,0,0,0,0,0,0,0,0,0,0
0,0,0,0,0,0,0,0,0,0,0,0,0,0,0,0,0,0,0,0,0,0,0,0,0,0,0,0,0,0,0,0,0,0,0,0,0,0,0,0,0,0,0,0,0,0,0,0,0
0,0,0,0,0,0,0,0,0,0,0,0,0,0,0,0,0,0,0,0,0,0,0,0,0,0,0,0,0,0,0,0,0,0,0,0,0,0,0,0,0,0,0,0,0,0,0,0,0
:endlayer
layer: 12
0,0,0,0,0,0,0,0,0,0,0,0,0,0,0,0,0,0,0,0,0,0,0,0,0,0,0,0,0,0,0,0,0,0,0,0,0,0,0,0,0,0,0,0,0,0,0,0,0
0,0,0,0,6,6,6,6,6,0,0,0,0,0,0,0,0,0,0,0,0,0,0,0,0,0,0,0,0,0,0,0,0,0,0,0,0,0,0,0,6,6,6,6,6,0,0,0,0
0,0,0,6,0,0,0,0,0,6,0,0,0,0,0,0,0,0,0,0,0,0,0,0,0,0,0,0,0,0,0,0,0,0,0,0,0,0,0,6,0,0,0,0,0,6,0,0,0
0,0,6,0,0,0,0,0,0,0,6,0,0,0,0,0,0,0,0,0,0,0,0,0,0,0,0,0,0,0,0,0,0,0,0,0,0,0,6,0,0,0,0,0,0,0,6,0,0
0,6,0,0,0,0,0,0,0,0,136,6,0,0,0,0,0,0,0,0,0,0,0,0,0,0,0,0,0,0,0,0,0,0,0,0,0,6,137,0,0,0,0,0,0,0,0,6,0
0,6,74,74,0,0,0,0,0,82,83,6,0,0,0,0,0,0,0,0,0,0,0,0,0,0,0,0,0,0,0,0,0,0,0,0,0,6,80,81,0,0,0,0,0,74,74,6,0
0,6,6,6,0,0,10,0,0,0,0,6,6,6,6,6,6,6,6,6,6,6,6,6,6,6,6,6,6,6,6,6,6,6,6,6,6,6,0,0,0,0,10,0,0,6,6,6,0
0,6,6,6,0,0,0,0,0,82,83,6,0,0,0,0,0,0,6,0,0,0,0,0,0,0,0,0,0,0,6,0,0,0,0,0,0,6,80,81,0,0,0,0,0,6,6,6,0
0,6,6,6,0,0,0,0,0,0,138,6,0,0,0,0,0,0,6,0,0,0,0,0,0,0,0,0,0,0,6,0,0,0,0,0,0,6,139,0,0,0,0,0,0,6,6,6,0
0,0,6,6,0,91,0,0,0,0,6,0,0,0,0,0,0,0,6,100,100,100,100,100,100,100,0,0,0,0,6,0,0,0,0,0,0,0,6,0,0,0,0,91,0,6,6,0,0
0,0,0,6,140,93,0,0,0,6,0,0,0,0,0,0,0,0,6,0,0,0,0,0,0,0,0,0,0,0,6,0,0,0,0,0,0,0,0,6,0,0,0,93,141,6,0,0,0
0,0,0,0,6,6,6,142,6,6,0,0,0,0,0,0,0,0,6,0,0,0,0,0,0,0,0,0,0,0,6,0,0,0,0,0,0,0,0,6,6,143,6,6,6,0,0,0,0
0,0,0,0,0,0,6,0,0,6,0,0,0,0,0,0,0,0,6,0,0,0,0,0,0,0,0,0,0,0,6,0,0,0,0,0,0,0,0,6,0,0,6,0,0,0,0,0,0
0,0,0,0,0,0,6,0,0,6,0,0,0,0,0,0,0,0,6,101,0,0,0,0,0,0,0,0,0,101,6,0,0,0,0,0,0,0,0,6,0,0,6,0,0,0,0,0,0
0,0,0,0,0,0,6,0,0,6,0,0,0,0,0,0,0,0,6,97,0,0,0,0,0,0,0,0,0,98,6,0,0,0,0,0,0,0,0,6,0,0,6,0,0,0,0,0,0
0,0,0,0,0,0,6,0,0,6,0,0,0,0,0,0,0,0,6,103,0,0,0,0,0,0,0,0,0,103,6,0,0,0,0,0,0,0,0,6,0,0,6,0,0,0,0,0,0
0,0,0,0,0,0,6,0,0,6,0,0,0,0,0,0,0,0,6,0,0,0,0,0,0,0,0,0,0,0,6,0,0,0,0,0,0,0,0,6,0,0,6,0,0,0,0,0,0
0,0,0,0,0,0,6,0,0,6,0,0,0,0,0,0,0,0,6,0,0,0,0,0,0,0,0,0,0,0,6,0,0,0,0,0,0,0,0,6,0,0,6,0,0,0,0,0,0
0,0,0,0,0,0,6,0,0,6,0,0,0,0,0,0,0,0,6,0,0,0,95,75,75,75,95,0,0,0,6,0,0,0,0,0,0,0,0,6,0,0,6,0,0,0,0,0,0
0,0,0,0,0,0,6,0,0,6,0,0,0,0,0,0,0,0,6,0,0,0,98,91,91,91,97,0,0,0,6,0,0,0,0,0,0,0,0,6,0,0,6,0,0,0,0,0,0
0,0,0,0,0,0,6,0,0,6,0,0,0,0,0,0,0,0,6,0,0,0,98,93,93,93,97,0,0,0,6,0,0,0,0,0,0,0,0,6,0,0,6,0,0,0,0,0,0
0,0,0,0,0,0,6,0,0,6,0,0,0,0,0,0,0,0,6,144,10,145,95,95,95,95,95,146,10,147,6,0,0,0,0,0,0,0,0,6,0,0,6,0,0,0,0,0,0
0,0,0,0,0,0,6,0,0,6,0,0,0,0,0,0,0,0,6,6,6,6,6,6,6,6,6,6,6,6,6,0,0,0,0,0,0,0,0,6,0,0,6,0,0,0,0,0,0
0,0,0,0,0,0,6,0,0,6,0,0,0,0,0,0,0,0,0,0,0,0,0,0,0,0,0,0,0,0,0,0,0,0,0,0,0,0,0,6,0,0,6,0,0,0,0,0,0
0,0,0,0,0,0,6,0,0,6,0,0,0,0,0,0,0,0,0,0,0,0,0,0,0,0,0,0,0,0,0,0,0,0,103,103,103,103,103,6,0,0,6,0,0,0,0,0,0
0,0,0,0,0,0,6,0,0,6,0,0,0,0,0,0,0,0,0,0,0,0,0,0,0,0,0,0,0,0,0,0,0,0,98,95,0,0,97,6,0,0,6,0,0,0,0,0,0
0,0,0,0,0,0,6,0,0,6,0,0,0,0,0,0,0,0,0,0,0,0,0,0,0,0,0,0,0,0,0,0,0,0,98,95,0,0,97,6,0,0,6,0,0,0,0,0,0
0,0,0,0,0,0,6,0,0,6,0,0,0,0,0,0,0,0,0,0,0,0,0,0,0,0,0,0,0,0,0,0,0,0,98,95,0,0,97,6,0,0,6,0,0,0,0,0,0
0,0,0,0,0,0,6,0,0,6,0,0,0,0,0,0,0,0,0,0,0,0,0,0,0,0,0,0,0,0,0,0,0,0,98,95,0,0,97,6,0,0,6,0,0,0,0,0,0
0,0,0,0,0,0,6,0,0,6,0,0,0,0,0,0,0,0,0,0,0,0,0,0,0,0,0,0,0,0,0,0,0,0,98,95,0,0,97,6,0,0,6,0,0,0,0,0,0
0,0,0,0,0,0,6,0,0,6,0,0,0,0,0,0,0,0,0,0,0,0,0,0,0,0,0,0,0,0,0,0,0,0,98,95,0,0,97,6,0,0,6,0,0,0,0,0,0
0,0,0,0,0,0,6,0,0,6,0,0,0,0,0,0,0,0,0,0,0,0,0,0,0,0,0,0,0,0,0,0,0,0,101,101,101,101,101,6,0,0,6,0,0,0,0,0,0
0,0,0,0,0,0,6,0,0,6,0,0,0,0,0,0,0,0,0,0,0,0,0,0,0,0,0,0,0,0,0,0,0,0,103,103,103,103,103,6,0,0,6,0,0,0,0,0,0
0,0,0,0,0,0,6,0,0,6,0,0,0,0,0,0,0,0,0,0,0,0,0,0,0,0,0,0,0,0,0,0,0,0,95,0,0,0,95,6,0,0,6,0,0,0,0,0,0
0,0,0,0,0,0,6,0,0,6,0,0,0,0,0,0,0,0,0,0,0,0,0,0,0,0,0,0,0,0,0,0,0,0,6,0,0,0,95,6,0,0,6,0,0,0,0,0,0
0,0,0,0,0,0,6,0,0,6,0,0,0,0,0,0,0,0,0,0,0,0,0,0,0,0,0,0,0,0,0,0,0,0,6,0,0,0,95,6,0,0,6,0,0,0,0,0,0
0,0,0,0,0,0,6,0,0,6,0,0,0,0,0,0,0,0,0,0,0,0,0,0,0,0,0,0,0,0,0,0,0,0,6,0,0,0,95,6,0,0,6,0,0,0,0,0,0
0,0,0,0,6,6,6,148,6,6,0,0,0,0,0,0,0,0,0,0,0,0,0,0,0,0,0,0,0,0,0,0,0,0,95,0,0,0,95,6,6,149,6,6,6,0,0,0,0
0,0,0,6,0,0,0,0,0,6,0,0,0,0,0,0,0,0,0,0,0,0,0,0,0,0,0,0,0,0,0,0,0,0,101,101,101,101,101,6,0,0,0,0,0,6,0,0,0
0,0,6,6,0,0,0,0,0,0,6,6,6,6,6,6,6,6,6,6,6,6,6,6,6,6,6,6,6,6,6,6,6,6,6,6,6,6,6,0,0,0,0,0,0,6,6,0,0
0,6,6,6,0,0,0,0,0,0,0,6,0,0,0,0,0,0,0,0,0,0,0,0,0,0,0,0,0,0,0,0,0,0,0,0,0,6,0,0,0,0,0,0,0,6,6,6,0
0,6,6,6,0,0,0,0,0,0,0,150,0,0,0,0,0,0,6,6,6,6,0,0,0,0,0,6,6,6,0,0,0,0,0,0,0,151,0,0,0,0,0,0,0,6,6,6,0
0,6,6,6,0,0,10,0,0,0,0,6,6,6,6,6,6,6,6,6,6,6,6,6,6,6,6,6,6,6,6,6,6,6,6,6,6,6,0,0,0,0,10,0,0,6,6,6,0
0,6,52,52,0,0,0,0,0,0,0,6,0,0,0,0,0,0,6,0,0,6,6,6,6,6,6,6,0,0,6,0,0,0,0,0,0,6,0,0,0,0,0,0,0,52,52,6,0
0,6,0,0,0,0,0,0,0,0,0,6,0,0,0,0,0,0,6,0,0,6,0,0,0,0,0,6,0,0,6,0,0,0,0,0,0,6,0,0,0,0,0,0,0,0,0,6,0
0,0,6,0,0,0,0,0,0,0,6,0,0,0,0,0,0,0,0,6,6,6,0,0,0,0,0,6,6,6,0,0,0,0,0,0,0,0,6,0,0,0,0,0,0,0,6,0,0
0,0,0,6,0,0,0,0,0,6,0,0,0,0,0,0,0,0,0,0,0,0,0,0,0,0,0,0,0,0,0,0,0,0,0,0,0,0,0,6,0,0,0,0,0,6,0,0,0
0,0,0,0,6,6,6,6,6,0,0,0,0,0,0,0,0,0,0,0,0,0,0,0,0,0,0,0,0,0,0,0,0,0,0,0,0,0,0,0,6,6,6,6,6,0,0,0,0
0,0,0,0,0,0,0,0,0,0,0,0,0,0,0,0,0,0,0,0,0,0,0,0,0,0,0,0,0,0,0,0,0,0,0,0,0,0,0,0,0,0,0,0,0,0,0,0,0
0,0,0,0,0,0,0,0,0,0,0,0,0,0,0,0,0,0,0,0,0,0,0,0,0,0,0,0,0,0,0,0,0,0,0,0,0,0,0,0,0,0,0,0,0,0,0,0,0
0,0,0,0,0,0,0,0,0,0,0,0,0,0,0,0,0,0,0,0,0,0,0,0,0,0,0,0,0,0,0,0,0,0,0,0,0,0,0,0,0,0,0,0,0,0,0,0,0
0,0,0,0,0,0,0,0,0,0,0,0,0,0,0,0,0,0,0,0,0,0,0,0,0,0,0,0,0,0,0,0,0,0,0,0,0,0,0,0,0,0,0,0,0,0,0,0,0
0,0,0,0,0,0,0,0,0,0,0,0,0,0,0,0,0,0,0,0,0,0,0,0,0,0,0,0,0,0,0,0,0,0,0,0,0,0,0,0,0,0,0,0,0,0,0,0,0
0,0,0,0,0,0,0,0,0,0,0,0,0,0,0,0,0,0,0,0,0,0,0,0,0,0,0,0,0,0,0,0,0,0,0,0,0,0,0,0,0,0,0,0,0,0,0,0,0
0,0,0,0,0,0,0,0,0,0,0,0,0,0,0,0,0,0,0,0,0,0,0,0,0,0,0,0,0,0,0,0,0,0,0,0,0,0,0,0,0,0,0,0,0,0,0,0,0
0,0,0,0,0,0,0,0,0,0,0,0,0,0,0,0,0,0,0,0,0,0,0,0,0,0,0,0,0,0,0,0,0,0,0,0,0,0,0,0,0,0,0,0,0,0,0,0,0
:endlayer
layer: 13
0,0,0,0,0,0,0,0,0,0,0,0,0,0,0,0,0,0,0,0,0,0,0,0,0,0,0,0,0,0,0,0,0,0,0,0,0,0,0,0,0,0,0,0,0,0,0,0,0
0,0,0,0,6,6,6,6,6,0,0,0,0,0,0,0,0,0,0,0,0,0,0,0,0,0,0,0,0,0,0,0,0,0,0,0,0,0,0,0,6,6,6,6,6,0,0,0,0
0,0,0,6,0,0,0,0,0,6,0,0,0,0,0,0,0,0,0,0,0,0,0,0,0,0,0,0,0,0,0,0,0,0,0,0,0,0,0,6,0,0,0,0,0,6,0,0,0
0,0,6,0,0,0,0,0,0,0,6,0,0,0,0,0,0,0,0,0,0,0,0,0,0,0,0,0,0,0,0,0,0,0,0,0,0,0,6,0,0,0,0,0,0,0,6,0,0
0,6,0,0,0,0,0,0,0,0,0,6,0,0,0,0,0,0,0,0,0,0,0,0,0,0,0,0,0,0,0,0,0,0,0,0,0,6,0,0,0,0,0,0,0,0,0,6,0
0,6,0,0,0,0,0,0,0,0,0,6,0,0,0,0,0,0,0,0,0,0,0,0,0,0,0,0,0,0,0,0,0,0,0,0,0,6,0,0,0,0,0,0,0,0,0,6,0
0,6,74,74,0,0,0,0,0,0,0,6,6,6,6,6,6,6,6,6,6,6,6,6,6,6,6,6,6,6,6,6,6,6,6,6,6,6,0,0,0,0,0,0,0,74,74,6,0
0,6,6,6,0,0,0,0,0,0,0,6,0,0,0,0,0,0,6,0,0,0,0,0,0,0,0,0,0,0,6,0,0,0,0,0,0,6,0,0,0,0,0,0,0,6,6,6,0
0,6,6,6,0,0,0,0,0,0,0,6,0,0,0,0,0,0,6,0,0,0,0,0,0,0,0,0,0,0,6,0,0,0,0,0,0,6,0,0,0,0,0,0,0,6,6,6,0
0,0,6,6,0,0,0,0,0,0,6,0,0,0,0,0,0,0,6,0,0,0,0,0,0,0,0,0,0,0,6,0,0,0,0,0,0,0,6,0,0,0,0,0,0,6,6,0,0
0,0,0,6,0,0,0,0,0,6,0,0,0,0,0,0,0,0,6,0,0,0,0,0,0,0,0,0,0,0,6,0,0,0,0,0,0,0,0,6,0,0,0,0,0,6,0,0,0
0,0,0,0,6,6,6,152,6,153,0,0,0,0,0,0,0,0,123,0,0,0,0,0,0,0,0,0,0,0,123,0,0,0,0,0,0,0,0,153,6,154,6,6,6,0,0,0,0
0,0,0,0,0,0,6,0,0,153,0,0,0,0,0,0,0,0,123,0,0,0,0,0,0,0,0,0,0,0,123,0,0,0,0,0,0,0,0,153,0,0,6,0,0,0,0,0,0
0,0,0,0,0,0,6,0,0,153,0,0,0,0,0,0,0,0,123,0,0,0,0,0,0,0,0,0,0,0,123,0,0,0,0,0,0,0,0,153,0,0,6,0,0,0,0,0,0
0,0,0,0,0,0,6,0,0,153,0,0,0,0,0,0,0,0,6,0,0,0,0,0,0,0,0,0,0,0,6,0,0,0,0,0,0,0,0,153,0,0,6,0,0,0,0,0,0
0,0,0,0,0,0,6,0,0,153,0,0,0,0,0,0,0,0,6,0,0,0,0,0,0,0,0,0,0,0,6,0,0,0,0,0,0,0,0,153,0,0,6,0,0,0,0,0,0
0,0,0,0,0,0,6,0,0,153,0,0,0,0,0,0,0,0,6,0,0,0,0,0,0,0,0,0,0,0,6,0,0,0,0,0,0,0,0,153,0,0,6,0,0,0,0,0,0
0,0,0,0,0,0,6,0,0,153,0,0,0,0,0,0,0,0,6,0,0,0,0,0,0,0,0,0,0,0,6,0,0,0,0,0,0,0,0,153,0,0,6,0,0,0,0,0,0
0,0,0,0,0,0,6,0,0,153,0,0,0,0,0,0,0,0,123,0,0,0,100,0,0,0,100,0,0,0,123,0,0,0,0,0,0,0,0,153,0,0,6,0,0,0,0,0,0
0,0,0,0,0,0,6,0,0,153,0,0,0,0,0,0,0,0,123,0,0,0,0,0,0,0,0,0,0,0,123,0,0,0,0,0,0,0,0,153,0,0,6,0,0,0,0,0,0
0,0,0,0,0,0,6,0,0,153,0,0,0,0,0,0,0,0,123,0,0,0,0,0,0,0,0,0,0,0,123,0,0,0,0,0,0,0,0,153,0,0,6,0,0,0,0,0,0
0,0,0,0,0,0,6,0,0,153,0,0,0,0,0,0,0,0,6,0,0,0,100,103,103,103,100,0,0,0,6,0,0,0,0,0,0,0,0,153,0,0,6,0,0,0,0,0,0
0,0,0,0,0,0,6,0,0,153,0,0,0,0,0,0,0,0,6,6,123,123,6,6,6,6,6,123,123,6,6,0,0,0,0,0,0,0,0,153,0,0,6,0,0,0,0,0,0
0,0,0,0,0,0,6,0,0,153,0,0,0,0,0,0,0,0,0,0,0,0,0,0,0,0,0,0,0,0,0,0,0,0,0,0,0,0,0,153,0,0,6,0,0,0,0,0,0
0,0,0,0,0,0,6,0,0,153,0,0,0,0,0,0,0,0,0,0,0,0,0,0,0,0,0,0,0,0,0,0,0,0,0,0,0,0,0,153,0,0,6,0,0,0,0,0,0
0,0,0,0,0,0,6,0,0,153,0,0,0,0,0,0,0,0,0,0,0,0,0,0,0,0,0,0,0,0,0,0,0,0,0,98,103,97,0,153,0,0,6,0,0,0,0,0,0
0,0,0,0,0,0,6,0,0,153,0,0,0,0,0,0,0,0,0,0,0,0,0,0,0,0,0,0,0,0,0,0,0,0,0,98,95,97,0,153,0,0,6,0,0,0,0,0,0
0,0,0,0,0,0,6,0,0,153,0,0,0,0,0,0,0,0,0,0,0,0,0,0,0,0,0,0,0,0,0,0,0,0,0,98,95,97,0,153,0,0,6,0,0,0,0,0,0
0,0,0,0,0,0,6,0,0,153,0,0,0,0,0,0,0,0,0,0,0,0,0,0,0,0,0,0,0,0,0,0,0,0,0,98,95,97,0,153,0,0,6,0,0,0,0,0,0
0,0,0,0,0,0,6,0,0,153,0,0,0,0,0,0,0,0,0,0,0,0,0,0,0,0,0,0,0,0,0,0,0,0,0,98,95,97,0,153,0,0,6,0,0,0,0,0,0
0,0,0,0,0,0,6,0,0,153,0,0,0,0,0,0,0,0,0,0,0,0,0,0,0,0,0,0,0,0,0,0,0,0,0,98,101,97,0,153,0,0,6,0,0,0,0,0,0
0,0,0,0,0,0,6,0,0,153,0,0,0,0,0,0,0,0,0,0,0,0,0,0,0,0,0,0,0,0,0,0,0,0,0,0,0,0,0,153,0,0,6,0,0,0,0,0,0
0,0,0,0,0,0,6,0,0,153,0,0,0,0,0,0,0,0,0,0,0,0,0,0,0,0,0,0,0,0,0,0,0,0,0,0,0,0,0,153,0,0,6,0,0,0,0,0,0
0,0,0,0,0,0,6,0,0,153,0,0,0,0,0,0,0,0,0,0,0,0,0,0,0,0,0,0,0,0,0,0,0,0,103,103,103,103,103,153,0,0,6,0,0,0,0,0,0
0,0,0,0,0,0,6,0,0,153,0,0,0,0,0,0,0,0,0,0,0,0,0,0,0,0,0,0,0,0,0,0,0,0,95,0,0,0,95,153,0,0,6,0,0,0,0,0,0
0,0,0,0,0,0,6,0,0,153,0,0,0,0,0,0,0,0,0,0,0,0,0,0,0,0,0,0,0,0,0,0,0,0,95,0,0,0,95,153,0,0,6,0,0,0,0,0,0
0,0,0,0,0,0,6,0,0,153,0,0,0,0,0,0,0,0,0,0,0,0,0,0,0,0,0,0,0,0,0,0,0,0,95,0,0,0,95,153,0,0,6,0,0,0,0,0,0
0,0,0,0,6,6,6,155,6,153,0,0,0,0,0,0,0,0,0,0,0,0,0,0,0,0,0,0,0,0,0,0,0,0,101,101,101,101,101,153,6,156,6,6,6,0,0,0,0
0,0,0,6,0,0,0,0,0,6,0,0,0,0,0,0,0,0,0,0,0,0,0,0,0,0,0,0,0,0,0,0,0,0,0,0,0,0,0,6,0,0,0,0,0,6,0,0,0
0,0,6,6,0,0,0,0,0,0,6,153,153,153,153,153,153,153,153,153,153,153,153,153,153,153,153,153,153,153,153,153,153,153,153,153,153,153,6,0,0,0,0,0,0,6,6,0,0
0,6,6,6,0,0,0,0,0,0,0,6,0,0,0,0,0,0,0,0,0,0,0,0,0,0,0,0,0,0,0,0,0,0,0,0,0,6,0,0,0,0,0,0,0,6,6,6,0
0,6,6,6,0,0,0,0,0,0,0,157,0,0,0,0,0,0,6,6,6,6,0,0,0,0,0,6,6,6,0,0,0,0,0,0,0,158,0,0,0,0,0,0,0,6,6,6,0
0,6,52,52,0,0,0,0,0,0,0,6,6,6,6,6,6,6,6,6,6,6,6,6,6,6,6,6,6,6,6,6,6,6,6,6,6,6,0,0,0,0,0,0,0,52,52,6,0
0,6,0,0,0,0,0,0,0,0,0,6,0,0,0,0,0,6,6,6,6,6,6,6,6,6,6,6,6,6,6,6,0,0,0,0,0,6,0,0,0,0,0,0,0,0,0,6,0
0,6,0,0,0,0,0,0,0,0,0,6,0,0,0,0,0,6,6,6,6,6,6,0,6,0,6,6,6,6,6,6,0,0,0,0,0,6,0,0,0,0,0,0,0,0,0,6,0
0,0,6,0,0,0,0,0,0,0,6,0,0,0,0,0,0,6,6,6,6,6,6,6,6,6,6,6,6,6,6,6,0,0,0,0,0,0,6,0,0,0,0,0,0,0,6,0,0
0,0,0,6,0,0,0,0,0,6,0,0,0,0,0,0,0,0,6,6,6,6,6,6,6,6,6,6,6,6,6,0,0,0,0,0,0,0,0,6,0,0,0,0,0,6,0,0,0
0,0,0,0,6,6,6,6,6,0,0,0,0,0,0,0,0,0,0,0,0,0,0,0,0,0,0,0,0,0,0,0,0,0,0,0,0,0,0,0,6,6,6,6,6,0,0,0,0
0,0,0,0,0,0,0,0,0,0,0,0,0,0,0,0,0,0,0,0,0,0,0,0,0,0,0,0,0,0,0,0,0,0,0,0,0,0,0,0,0,0,0,0,0,0,0,0,0
0,0,0,0,0,0,0,0,0,0,0,0,0,0,0,0,0,0,0,0,0,0,0,0,0,0,0,0,0,0,0,0,0,0,0,0,0,0,0,0,0,0,0,0,0,0,0,0,0
0,0,0,0,0,0,0,0,0,0,0,0,0,0,0,0,0,0,0,0,0,0,0,0,0,0,0,0,0,0,0,0,0,0,0,0,0,0,0,0,0,0,0,0,0,0,0,0,0
0,0,0,0,0,0,0,0,0,0,0,0,0,0,0,0,0,0,0,0,0,0,0,0,0,0,0,0,0,0,0,0,0,0,0,0,0,0,0,0,0,0,0,0,0,0,0,0,0
0,0,0,0,0,0,0,0,0,0,0,0,0,0,0,0,0,0,0,0,0,0,0,0,0,0,0,0,0,0,0,0,0,0,0,0,0,0,0,0,0,0,0,0,0,0,0,0,0
0,0,0,0,0,0,0,0,0,0,0,0,0,0,0,0,0,0,0,0,0,0,0,0,0,0,0,0,0,0,0,0,0,0,0,0,0,0,0,0,0,0,0,0,0,0,0,0,0
0,0,0,0,0,0,0,0,0,0,0,0,0,0,0,0,0,0,0,0,0,0,0,0,0,0,0,0,0,0,0,0,0,0,0,0,0,0,0,0,0,0,0,0,0,0,0,0,0
0,0,0,0,0,0,0,0,0,0,0,0,0,0,0,0,0,0,0,0,0,0,0,0,0,0,0,0,0,0,0,0,0,0,0,0,0,0,0,0,0,0,0,0,0,0,0,0,0
:endlayer
layer: 14
0,0,0,0,0,0,0,0,0,0,0,0,0,0,0,0,0,0,0,0,0,0,0,0,0,0,0,0,0,0,0,0,0,0,0,0,0,0,0,0,0,0,0,0,0,0,0,0,0
0,0,0,0,6,6,6,6,6,0,0,0,0,0,0,0,0,0,0,0,0,0,0,0,0,0,0,0,0,0,0,0,0,0,0,0,0,0,0,0,6,6,6,6,6,0,0,0,0
0,0,0,6,0,0,59,0,0,6,0,0,0,0,0,0,0,0,0,0,0,0,0,0,0,0,0,0,0,0,0,0,0,0,0,0,0,0,0,6,0,0,59,0,0,6,0,0,0
0,0,6,0,0,0,0,0,0,0,6,0,0,0,0,0,0,0,0,0,0,0,0,0,0,0,0,0,0,0,0,0,0,0,0,0,0,0,6,0,0,0,0,0,0,0,6,0,0
0,6,0,0,0,0,0,0,0,0,0,6,0,0,0,0,0,0,0,0,0,0,0,0,0,0,0,0,0,0,0,0,0,0,0,0,0,6,0,0,0,0,0,0,0,0,0,6,0
0,6,0,0,0,0,0,0,0,0,0,6,0,0,0,0,0,0,0,0,0,0,0,0,0,0,0,0,0,0,0,0,0,0,0,0,0,6,0,0,0,0,0,0,0,0,0,6,0
0,6,60,0,0,0,0,0,0,0,61,6,6,6,6,6,6,6,6,6,6,6,6,6,6,6,6,6,6,6,6,6,6,6,6,6,6,6,60,0,0,0,0,0,0,0,61,6,0
0,6,74,74,0,0,0,0,0,0,0,6,0,0,0,0,0,0,6,0,59,0,0,0,59,0,0,0,59,0,6,0,0,0,0,0,0,6,0,0,0,0,0,0,0,74,74,6,0
0,6,6,6,0,0,0,0,0,0,0,6,0,0,0,0,0,0,6,0,0,0,0,0,0,0,0,0,0,0,6,0,0,0,0,0,0,6,0,0,0,0,0,0,0,6,6,6,0
0,0,6,6,0,0,0,0,0,0,6,0,0,0,0,0,0,0,6,0,0,0,0,0,0,0,0,0,0,0,6,0,0,0,0,0,0,0,6,0,0,0,0,0,0,6,6,0,0
0,0,0,6,0,0,27,0,0,6,0,0,0,0,0,0,0,0,6,60,0,0,0,0,0,0,0,0,0,61,6,0,0,0,0,0,0,0,0,6,0,0,27,0,0,6,0,0,0
0,0,0,0,6,6,6,6,6,0,0,0,0,0,0,0,0,0,123,0,0,0,0,0,0,0,0,0,0,0,123,0,0,0,0,0,0,0,0,0,6,6,6,6,6,0,0,0,0
0,0,0,0,0,0,6,0,0,0,0,0,0,0,0,0,0,0,123,0,0,0,0,0,0,0,0,0,0,0,123,0,0,0,0,0,0,0,0,0,0,0,6,0,0,0,0,0,0
0,0,0,0,0,0,6,60,0,0,0,0,0,0,0,0,0,0,123,0,0,0,0,0,0,0,0,0,0,0,123,0,0,0,0,0,0,0,0,0,0,61,6,0,0,0,0,0,0
0,0,0,0,0,0,6,0,0,0,0,0,0,0,0,0,0,0,6,0,0,0,0,0,0,0,0,0,0,0,6,0,0,0,0,0,0,0,0,0,0,0,6,0,0,0,0,0,0
0,0,0,0,0,0,6,0,0,0,0,0,0,0,0,0,0,0,6,0,0,0,0,0,0,0,0,0,0,0,6,0,0,0,0,0,0,0,0,0,0,0,6,0,0,0,0,0,0
0,0,0,0,0,0,6,0,0,0,0,0,0,0,0,0,0,0,6,0,0,0,0,0,0,0,0,0,0,0,6,0,0,0,0,0,0,0,0,0,0,0,6,0,0,0,0,0,0
0,0,0,0,0,0,6,0,0,0,0,0,0,0,0,0,0,0,6,0,0,0,0,0,0,0,0,0,0,0,6,0,0,0,0,0,0,0,0,0,0,0,6,0,0,0,0,0,0
0,0,0,0,0,0,6,60,0,0,0,0,0,0,0,0,0,0,123,0,0,0,100,0,0,0,100,0,0,0,123,0,0,0,0,0,0,0,0,0,0,61,6,0,0,0,0,0,0
0,0,0,0,0,0,6,0,0,0,0,0,0,0,0,0,0,0,123,0,0,0,0,0,0,0,0,0,0,0,123,0,0,0,0,0,0,0,0,0,0,0,6,0,0,0,0,0,0
0,0,0,0,0,0,6,0,0,0,0,0,0,0,0,0,0,0,123,0,0,0,0,0,0,0,0,0,0,0,123,0,0,0,0,0,0,0,0,0,0,0,6,0,0,0,0,0,0
0,0,0,0,0,0,6,0,0,0,0,0,0,0,0,0,0,0,6,0,0,0,100,159,159,159,100,0,0,0,6,0,0,0,0,0,0,0,0,0,0,0,6,0,0,0,0,0,0
0,0,0,0,0,0,6,0,0,0,0,0,0,0,0,0,0,0,6,6,123,123,6,6,6,6,6,123,123,6,6,0,0,0,0,0,0,0,0,0,0,0,6,0,0,0,0,0,0
0,0,0,0,0,0,6,60,0,0,0,0,0,0,0,0,0,0,0,0,0,0,0,0,0,0,0,0,0,0,0,0,0,0,0,0,0,0,0,0,0,61,6,0,0,0,0,0,0
0,0,0,0,0,0,6,0,0,0,0,0,0,0,0,0,0,0,0,0,0,0,0,0,0,0,0,0,0,0,0,0,0,0,0,0,0,0,0,0,0,0,6,0,0,0,0,0,0
0,0,0,0,0,0,6,0,0,0,0,0,0,0,0,0,0,0,0,0,0,0,0,0,0,0,0,0,0,0,0,0,0,0,0,0,0,0,0,0,0,0,6,0,0,0,0,0,0
0,0,0,0,0,0,6,0,0,0,0,0,0,0,0,0,0,0,0,0,0,0,0,0,0,0,0,0,0,0,0,0,0,0,0,0,10,0,0,0,0,0,6,0,0,0,0,0,0
0,0,0,0,0,0,6,0,0,0,0,0,0,0,0,0,0,0,0,0,0,0,0,0,0,0,0,0,0,0,0,0,0,0,0,0,0,0,0,0,0,0,6,0,0,0,0,0,0
0,0,0,0,0,0,6,60,0,0,0,0,0,0,0,0,0,0,0,0,0,0,0,0,0,0,0,0,0,0,0,0,0,0,0,0,0,0,0,0,0,61,6,0,0,0,0,0,0
0,0,0,0,0,0,6,0,0,0,0,0,0,0,0,0,0,0,0,0,0,0,0,0,0,0,0,0,0,0,0,0,0,0,0,0,10,0,0,0,0,0,6,0,0,0,0,0,0
0,0,0,0,0,0,6,0,0,0,0,0,0,0,0,0,0,0,0,0,0,0,0,0,0,0,0,0,0,0,0,0,0,0,0,0,0,0,0,0,0,0,6,0,0,0,0,0,0
0,0,0,0,0,0,6,0,0,0,0,0,0,0,0,0,0,0,0,0,0,0,0,0,0,0,0,0,0,0,0,0,0,0,0,0,0,0,0,0,0,0,6,0,0,0,0,0,0
0,0,0,0,0,0,6,0,0,0,0,0,0,0,0,0,0,0,0,0,0,0,0,0,0,0,0,0,0,0,0,0,0,0,0,0,0,0,0,0,0,0,6,0,0,0,0,0,0
0,0,0,0,0,0,6,60,0,0,0,0,0,0,0,0,0,0,0,0,0,0,0,0,0,0,0,0,0,0,0,0,0,0,0,0,0,0,0,0,0,61,6,0,0,0,0,0,0
0,0,0,0,0,0,6,0,0,0,0,0,0,0,0,0,0,0,0,0,0,0,0,0,0,0,0,0,0,0,0,0,0,0,103,103,103,103,103,0,0,0,6,0,0,0,0,0,0
0,0,0,0,0,0,6,0,0,0,0,0,0,0,0,0,0,0,0,0,0,0,0,0,0,0,0,0,0,0,0,0,0,0,95,95,95,95,95,0,0,0,6,0,0,0,0,0,0
0,0,0,0,0,0,6,0,0,0,0,0,0,0,0,0,0,0,0,0,0,0,0,0,0,0,0,0,0,0,0,0,0,0,101,101,101,101,101,0,0,0,6,0,0,0,0,0,0
0,0,0,0,6,6,6,6,6,27,0,0,0,0,0,0,0,0,0,0,0,0,0,0,0,0,0,0,0,0,0,0,0,0,0,0,0,0,0,27,6,6,6,6,6,0,0,0,0
0,0,0,6,0,0,59,0,0,6,0,0,0,0,0,0,0,0,0,0,0,0,0,0,0,0,0,0,0,0,0,0,0,0,0,0,0,0,0,6,0,0,59,0,0,6,0,0,0
0,0,6,6,0,0,0,0,0,0,6,0,0,0,0,0,0,0,0,0,0,0,0,0,0,0,0,0,0,0,0,0,0,0,0,0,0,0,6,0,0,0,0,0,0,6,6,0,0
0,6,6,6,0,0,0,0,0,0,0,6,0,0,0,0,0,0,0,0,0,0,0,0,0,0,0,0,0,0,0,0,0,0,0,0,0,6,0,0,0,0,0,0,0,6,6,6,0
0,6,52,52,0,0,0,0,0,0,0,6,27,0,0,0,27,0,6,6,6,6,27,0,0,0,27,6,6,6,0,0,27,0,0,0,27,6,0,0,0,0,0,0,0,52,52,6,0
0,6,60,0,0,0,0,0,0,0,61,6,6,6,6,6,6,6,6,6,11,0,6,6,6,6,6,0,18,6,6,6,6,6,6,6,6,6,60,0,0,0,0,0,0,0,61,6,0
0,6,0,0,0,0,0,0,0,0,0,6,0,0,0,0,0,6,0,0,0,0,0,0,10,0,0,0,0,0,0,6,0,0,0,0,0,6,0,0,0,0,0,0,0,0,0,6,0
0,6,0,0,0,0,0,0,0,0,0,6,0,0,0,0,0,0,0,0,0,0,0,0,0,0,0,0,0,0,0,0,0,0,0,0,0,6,0,0,0,0,0,0,0,0,0,6,0
0,0,6,0,0,0,0,0,0,0,6,0,0,0,0,0,0,6,6,10,0,0,0,0,0,0,0,0,0,10,6,6,0,0,0,0,0,0,6,0,0,0,0,0,0,0,6,0,0
0,0,0,6,0,0,27,0,0,6,0,0,0,0,0,0,0,0,6,11,0,18,6,6,0,6,6,11,0,18,6,0,0,0,0,0,0,0,0,6,0,0,27,0,0,6,0,0,0
0,0,0,0,6,6,6,6,6,0,0,0,0,0,0,0,0,0,0,0,0,0,0,0,0,0,0,0,0,0,0,0,0,0,0,0,0,0,0,0,6,6,6,6,6,0,0,0,0
0,0,0,0,0,0,0,0,0,0,0,0,0,0,0,0,0,0,0,0,0,0,0,0,0,0,0,0,0,0,0,0,0,0,0,0,0,0,0,0,0,0,0,0,0,0,0,0,0
0,0,0,0,0,0,0,0,0,0,0,0,0,0,0,0,0,0,0,0,0,0,0,0,0,0,0,0,0,0,0,0,0,0,0,0,0,0,0,0,0,0,0,0,0,0,0,0,0
0,0,0,0,0,0,0,0,0,0,0,0,0,0,0,0,0,0,0,0,0,0,0,0,0,0,0,0,0,0,0,0,0,0,0,0,0,0,0,0,0,0,0,0,0,0,0,0,0
0,0,0,0,0,0,0,0,0,0,0,0,0,0,0,0,0,0,0,0,0,0,0,0,0,0,0,0,0,0,0,0,0,0,0,0,0,0,0,0,0,0,0,0,0,0,0,0,0
0,0,0,0,0,0,0,0,0,0,0,0,0,0,0,0,0,0,0,0,0,0,0,0,0,0,0,0,0,0,0,0,0,0,0,0,0,0,0,0,0,0,0,0,0,0,0,0,0
0,0,0,0,0,0,0,0,0,0,0,0,0,0,0,0,0,0,0,0,0,0,0,0,0,0,0,0,0,0,0,0,0,0,0,0,0,0,0,0,0,0,0,0,0,0,0,0,0
0,0,0,0,0,0,0,0,0,0,0,0,0,0,0,0,0,0,0,0,0,0,0,0,0,0,0,0,0,0,0,0,0,0,0,0,0,0,0,0,0,0,0,0,0,0,0,0,0
0,0,0,0,0,0,0,0,0,0,0,0,0,0,0,0,0,0,0,0,0,0,0,0,0,0,0,0,0,0,0,0,0,0,0,0,0,0,0,0,0,0,0,0,0,0,0,0,0
:endlayer
layer: 15
0,0,0,0,0,0,0,0,0,0,0,0,0,0,0,0,0,0,0,0,0,0,0,0,0,0,0,0,0,0,0,0,0,0,0,0,0,0,0,0,0,0,0,0,0,0,0,0,0
0,0,0,0,6,6,6,6,6,0,0,0,0,0,0,0,0,0,0,0,0,0,0,0,0,0,0,0,0,0,0,0,0,0,0,0,0,0,0,0,6,6,6,6,6,0,0,0,0
0,0,0,6,0,0,0,0,0,6,0,0,0,0,0,0,0,0,0,0,0,0,0,0,0,0,0,0,0,0,0,0,0,0,0,0,0,0,0,6,0,0,0,0,0,6,0,0,0
0,0,6,0,0,0,0,0,0,0,6,0,0,0,0,0,0,0,0,0,0,0,0,0,0,0,0,0,0,0,0,0,0,0,0,0,0,0,6,0,0,0,0,0,0,0,6,0,0
0,6,0,0,0,0,0,0,0,0,0,6,0,0,0,0,0,0,0,0,0,0,0,0,0,0,0,0,0,0,0,0,0,0,0,0,0,6,0,0,0,0,0,0,0,0,0,6,0
0,6,0,0,0,0,0,0,0,0,0,6,0,0,0,0,0,0,0,0,0,0,0,0,0,0,0,0,0,0,0,0,0,0,0,0,0,6,0,0,0,0,0,0,0,0,0,6,0
0,6,0,0,0,0,0,0,0,0,0,6,6,6,6,6,6,6,6,6,6,6,6,6,6,6,6,6,6,6,6,6,6,6,6,6,6,6,0,0,0,0,0,0,0,0,0,6,0
0,6,0,0,0,0,0,0,0,0,0,6,0,0,0,0,0,0,6,0,0,0,0,0,0,0,0,0,0,0,6,0,0,0,0,0,0,6,0,0,0,0,0,0,0,0,0,6,0
0,6,74,74,0,0,0,0,0,0,0,6,0,0,0,0,0,0,6,0,0,0,0,0,0,0,0,0,0,0,6,0,0,0,0,0,0,6,0,0,0,0,0,0,0,74,74,6,0
0,0,6,6,0,0,0,0,0,0,6,0,0,0,0,0,0,0,6,0,0,0,0,0,0,0,0,0,0,0,6,0,0,0,0,0,0,0,6,0,0,0,0,0,0,6,6,0,0
0,0,0,6,0,0,0,0,0,6,0,0,0,0,0,0,0,0,6,0,0,0,0,0,0,0,0,0,0,0,6,0,0,0,0,0,0,0,0,6,0,0,0,0,0,6,0,0,0
0,0,0,0,6,6,6,6,6,0,0,0,0,0,0,0,0,0,6,0,0,0,0,0,0,0,0,0,0,0,6,0,0,0,0,0,0,0,0,0,6,6,6,6,6,0,0,0,0
0,0,0,0,0,0,6,0,0,0,0,0,0,0,0,0,0,0,6,0,0,0,0,0,0,0,0,0,0,0,6,0,0,0,0,0,0,0,0,0,0,0,6,0,0,0,0,0,0
0,0,0,0,0,0,6,0,0,0,0,0,0,0,0,0,0,0,6,0,0,0,0,0,0,0,0,0,0,0,6,0,0,0,0,0,0,0,0,0,0,0,6,0,0,0,0,0,0
0,0,0,0,0,0,6,0,0,0,0,0,0,0,0,0,0,0,6,0,0,0,0,0,0,0,0,0,0,0,6,0,0,0,0,0,0,0,0,0,0,0,6,0,0,0,0,0,0
0,0,0,0,0,0,6,0,0,0,0,0,0,0,0,0,0,0,6,0,0,0,0,0,0,0,0,0,0,0,6,0,0,0,0,0,0,0,0,0,0,0,6,0,0,0,0,0,0
0,0,0,0,0,0,6,0,0,0,0,0,0,0,0,0,0,0,6,0,0,0,0,0,0,0,0,0,0,0,6,0,0,0,0,0,0,0,0,0,0,0,6,0,0,0,0,0,0
0,0,0,0,0,0,6,0,0,0,0,0,0,0,0,0,0,0,6,0,0,0,0,0,0,0,0,0,0,0,6,0,0,0,0,0,0,0,0,0,0,0,6,0,0,0,0,0,0
0,0,0,0,0,0,6,0,0,0,0,0,0,0,0,0,0,0,6,0,0,0,98,135,135,135,97,0,0,0,6,0,0,0,0,0,0,0,0,0,0,0,6,0,0,0,0,0,0
0,0,0,0,0,0,6,0,0,0,0,0,0,0,0,0,0,0,6,0,0,0,98,135,135,135,97,0,0,0,6,0,0,0,0,0,0,0,0,0,0,0,6,0,0,0,0,0,0
0,0,0,0,0,0,6,0,0,0,0,0,0,0,0,0,0,0,6,0,0,0,98,135,135,135,97,0,0,0,6,0,0,0,0,0,0,0,0,0,0,0,6,0,0,0,0,0,0
0,0,0,0,0,0,6,0,0,0,0,0,0,0,0,0,0,0,6,0,0,27,98,135,135,135,97,27,0,0,6,0,0,0,0,0,0,0,0,0,0,0,6,0,0,0,0,0,0
0,0,0,0,0,0,6,0,0,0,0,0,0,0,0,0,0,0,6,6,6,6,6,6,6,6,6,6,6,6,6,0,0,0,0,0,0,0,0,0,0,0,6,0,0,0,0,0,0
0,0,0,0,0,0,6,0,0,0,0,0,0,0,0,0,0,0,0,0,0,0,0,0,0,0,0,0,0,0,0,0,0,0,0,0,0,0,0,0,0,0,6,0,0,0,0,0,0
0,0,0,0,0,0,6,0,0,0,0,0,0,0,0,0,0,0,0,0,0,0,0,0,0,0,0,0,0,0,0,0,0,0,0,0,0,0,0,0,0,0,6,0,0,0,0,0,0
0,0,0,0,0,0,6,0,0,0,0,0,0,0,0,0,0,0,0,0,0,0,0,0,0,0,0,0,0,0,0,0,0,0,0,0,0,0,0,0,0,0,6,0,0,0,0,0,0
0,0,0,0,0,0,6,0,0,0,0,0,0,0,0,0,0,0,0,0,0,0,0,0,0,0,0,0,0,0,0,0,0,0,0,0,0,0,0,0,0,0,6,0,0,0,0,0,0
0,0,0,0,0,0,6,0,0,0,0,0,0,0,0,0,0,0,0,0,0,0,0,0,0,0,0,0,0,0,0,0,0,0,0,0,0,0,0,0,0,0,6,0,0,0,0,0,0
0,0,0,0,0,0,6,0,0,0,0,0,0,0,0,0,0,0,0,0,0,0,0,0,0,0,0,0,0,0,0,0,0,0,0,0,0,0,0,0,0,0,6,0,0,0,0,0,0
0,0,0,0,0,0,6,0,0,0,0,0,0,0,0,0,0,0,0,0,0,0,0,0,0,0,0,0,0,0,0,0,0,0,0,0,0,0,0,0,0,0,6,0,0,0,0,0,0
0,0,0,0,0,0,6,0,0,0,0,0,0,0,0,0,0,0,0,0,0,0,0,0,0,0,0,0,0,0,0,0,0,0,0,0,0,0,0,0,0,0,6,0,0,0,0,0,0
0,0,0,0,0,0,6,0,0,0,0,0,0,0,0,0,0,0,0,0,0,0,0,0,0,0,0,0,0,0,0,0,0,0,0,0,0,0,0,0,0,0,6,0,0,0,0,0,0
0,0,0,0,0,0,6,0,0,0,0,0,0,0,0,0,0,0,0,0,0,0,0,0,0,0,0,0,0,0,0,0,0,0,0,0,0,0,0,0,0,0,6,0,0,0,0,0,0
0,0,0,0,0,0,6,0,0,0,0,0,0,0,0,0,0,0,0,0,0,0,0,0,0,0,0,0,0,0,0,0,0,0,0,0,0,0,0,0,0,0,6,0,0,0,0,0,0
0,0,0,0,0,0,6,0,0,0,0,0,0,0,0,0,0,0,0,0,0,0,0,0,0,0,0,0,0,0,0,0,0,0,0,0,0,0,0,0,0,0,6,0,0,0,0,0,0
0,0,0,0,0,0,6,0,0,0,0,0,0,0,0,0,0,0,0,0,0,0,0,0,0,0,0,0,0,0,0,0,0,0,0,0,10,0,0,0,0,0,6,0,0,0,0,0,0
0,0,0,0,0,0,6,0,0,0,0,0,0,0,0,0,0,0,0,0,0,0,0,0,0,0,0,0,0,0,0,0,0,0,0,0,0,0,0,0,0,0,6,0,0,0,0,0,0
0,0,0,0,6,6,6,6,6,0,0,0,0,0,0,0,0,0,0,0,0,0,0,0,0,0,0,0,0,0,0,0,0,0,0,0,0,0,0,0,6,6,6,6,6,0,0,0,0
0,0,0,6,0,0,0,0,0,6,0,0,0,0,0,0,0,0,0,0,0,0,0,0,0,0,0,0,0,0,0,0,0,0,0,0,0,0,0,6,0,0,0,0,0,6,0,0,0
0,0,6,6,0,0,0,0,0,0,6,0,0,0,0,0,0,0,0,0,0,0,0,0,0,0,0,0,0,0,0,0,0,0,0,0,0,0,6,0,0,0,0,0,0,6,6,0,0
0,6,52,52,0,0,0,0,0,0,0,6,0,0,0,0,0,0,0,0,0,0,0,0,0,0,0,0,0,0,0,0,0,0,0,0,0,6,0,0,0,0,0,0,0,52,52,6,0
0,6,0,0,0,0,0,0,0,0,0,6,0,0,0,0,0,0,6,6,6,6,0,0,0,0,0,6,6,6,0,0,0,0,0,0,0,6,0,0,0,0,0,0,0,0,0,6,0
0,6,0,0,0,0,0,0,0,0,0,6,6,6,6,6,6,6,6,11,0,0,6,6,6,6,6,0,0,18,6,6,6,6,6,6,6,6,0,0,0,0,0,0,0,0,0,6,0
0,6,0,0,0,0,0,0,0,0,0,6,0,0,0,0,0,6,0,0,0,0,0,0,0,0,0,0,0,0,0,6,0,0,0,0,0,6,0,0,0,0,0,0,0,0,0,6,0
0,6,0,0,0,0,0,0,0,0,0,6,0,0,0,0,0,0,0,0,0,0,0,0,0,0,0,0,0,0,0,0,0,0,0,0,0,6,0,0,0,0,0,0,0,0,0,6,0
0,0,6,0,0,0,0,0,0,0,6,0,0,0,0,0,0,6,6,0,0,0,0,0,0,0,0,0,0,0,6,6,0,0,0,0,0,0,6,0,0,0,0,0,0,0,6,0,0
0,0,0,6,0,0,0,0,0,6,0,0,0,0,0,0,0,0,6,0,0,0,6,0,0,0,6,0,0,0,6,0,0,0,0,0,0,0,0,6,0,0,0,0,0,6,0,0,0
0,0,0,0,6,6,6,6,6,0,0,0,0,0,0,0,0,0,0,0,0,0,0,0,0,0,0,0,0,0,0,0,0,0,0,0,0,0,0,0,6,6,6,6,6,0,0,0,0
0,0,0,0,0,0,0,0,0,0,0,0,0,0,0,0,0,0,0,0,0,0,0,0,0,0,0,0,0,0,0,0,0,0,0,0,0,0,0,0,0,0,0,0,0,0,0,0,0
0,0,0,0,0,0,0,0,0,0,0,0,0,0,0,0,0,0,0,0,0,0,0,0,0,0,0,0,0,0,0,0,0,0,0,0,0,0,0,0,0,0,0,0,0,0,0,0,0
0,0,0,0,0,0,0,0,0,0,0,0,0,0,0,0,0,0,0,0,0,0,0,0,0,0,0,0,0,0,0,0,0,0,0,0,0,0,0,0,0,0,0,0,0,0,0,0,0
0,0,0,0,0,0,0,0,0,0,0,0,0,0,0,0,0,0,0,0,0,0,0,0,0,0,0,0,0,0,0,0,0,0,0,0,0,0,0,0,0,0,0,0,0,0,0,0,0
0,0,0,0,0,0,0,0,0,0,0,0,0,0,0,0,0,0,0,0,0,0,0,0,0,0,0,0,0,0,0,0,0,0,0,0,0,0,0,0,0,0,0,0,0,0,0,0,0
0,0,0,0,0,0,0,0,0,0,0,0,0,0,0,0,0,0,0,0,0,0,0,0,0,0,0,0,0,0,0,0,0,0,0,0,0,0,0,0,0,0,0,0,0,0,0,0,0
0,0,0,0,0,0,0,0,0,0,0,0,0,0,0,0,0,0,0,0,0,0,0,0,0,0,0,0,0,0,0,0,0,0,0,0,0,0,0,0,0,0,0,0,0,0,0,0,0
0,0,0,0,0,0,0,0,0,0,0,0,0,0,0,0,0,0,0,0,0,0,0,0,0,0,0,0,0,0,0,0,0,0,0,0,0,0,0,0,0,0,0,0,0,0,0,0,0
:endlayer
layer: 16
0,0,0,0,0,0,0,0,0,0,0,0,0,0,0,0,0,0,0,0,0,0,0,0,0,0,0,0,0,0,0,0,0,0,0,0,0,0,0,0,0,0,0,0,0,0,0,0,0
0,0,0,0,6,6,6,6,6,0,0,0,0,0,0,0,0,0,0,0,0,0,0,0,0,0,0,0,0,0,0,0,0,0,0,0,0,0,0,0,6,6,6,6,6,0,0,0,0
0,0,0,6,6,6,6,6,6,6,0,0,0,0,0,0,0,0,0,0,0,0,0,0,0,0,0,0,0,0,0,0,0,0,0,0,0,0,0,6,6,6,6,6,6,6,0,0,0
0,0,6,6,6,6,6,6,6,6,6,0,0,0,0,0,0,0,0,0,0,0,0,0,0,0,0,0,0,0,0,0,0,0,0,0,0,0,6,6,6,6,6,6,6,6,6,0,0
0,6,6,6,6,6,6,6,6,6,6,6,0,0,0,0,0,0,0,0,0,0,0,0,0,0,0,0,0,0,0,0,0,0,0,0,0,6,6,6,6,6,6,6,6,6,6,6,0
0,6,6,6,6,6,6,6,6,6,6,6,6,6,6,6,6,6,6,6,6,6,6,6,6,6,6,6,6,6,6,6,6,6,6,6,6,6,6,6,6,6,6,6,6,6,6,6,0
0,6,0,0,6,6,6,6,6,6,6,6,6,6,6,6,6,6,6,6,6,6,6,6,6,6,6,6,6,6,6,6,6,6,6,6,6,6,6,6,6,6,6,6,6,0,0,6,0
0,6,0,0,6,6,6,6,6,6,6,6,6,6,6,6,6,6,6,6,6,6,6,6,6,6,6,6,6,6,6,6,6,6,6,6,6,6,6,6,6,6,6,6,6,0,0,6,0
0,6,0,0,52,6,6,6,6,6,6,6,6,6,6,6,6,6,6,6,6,6,6,6,6,6,6,6,6,6,6,6,6,6,6,6,6,6,6,6,6,6,6,6,52,0,0,6,0
0,0,6,0,18,6,6,6,6,6,6,6,6,6,6,6,6,6,6,6,6,6,6,6,6,6,6,6,6,6,6,6,6,6,6,6,6,6,6,6,6,6,6,6,11,0,6,0,0
0,0,0,6,6,6,6,6,6,6,0,0,0,0,0,0,0,0,6,6,6,6,6,6,6,6,6,6,6,6,6,0,0,0,0,0,0,0,0,6,6,6,6,6,6,6,0,0,0
0,0,0,0,6,6,6,6,6,6,0,0,0,0,0,0,0,0,6,6,6,6,6,6,6,6,6,6,6,6,6,0,0,0,0,0,0,0,0,6,6,6,6,6,6,0,0,0,0
0,0,0,0,0,6,6,6,6,6,0,0,0,0,0,0,0,0,6,6,6,6,6,6,6,6,6,6,6,6,6,0,0,0,0,0,0,0,0,6,6,6,6,6,0,0,0,0,0
0,0,0,0,0,6,6,6,6,6,0,0,0,0,0,0,0,0,6,6,6,6,6,6,6,6,6,6,6,6,6,0,0,0,0,0,0,0,0,6,6,6,6,6,0,0,0,0,0
0,0,0,0,0,6,6,6,6,6,0,0,0,0,0,0,0,0,6,6,6,6,6,6,6,6,6,6,6,6,6,0,0,0,0,0,0,0,0,6,6,6,6,6,0,0,0,0,0
0,0,0,0,0,6,6,6,6,6,0,0,0,0,0,0,0,0,6,6,6,6,6,6,6,6,6,6,6,6,6,0,0,0,0,0,0,0,0,6,6,6,6,6,0,0,0,0,0
0,0,0,0,0,6,6,6,6,6,0,0,0,0,0,0,0,0,6,6,6,6,6,6,6,6,6,6,6,6,6,0,0,0,0,0,0,0,0,6,6,6,6,6,0,0,0,0,0
0,0,0,0,0,6,6,6,6,6,0,0,0,0,0,0,0,0,6,6,6,6,6,6,6,6,6,6,6,6,6,0,0,0,0,0,0,0,0,6,6,6,6,6,0,0,0,0,0
0,0,0,0,0,6,6,6,6,6,0,0,0,0,0,0,0,0,6,6,6,6,6,6,6,6,6,6,6,6,6,0,0,0,0,0,0,0,0,6,6,6,6,6,0,0,0,0,0
0,0,0,0,0,6,6,6,6,6,0,0,0,0,0,0,0,0,6,6,6,6,6,6,6,6,6,6,6,6,6,0,0,0,0,0,0,0,0,6,6,6,6,6,0,0,0,0,0
0,0,0,0,0,6,6,6,6,6,0,0,0,0,0,0,0,0,6,6,6,6,6,6,6,6,6,6,6,6,6,0,0,0,0,0,0,0,0,6,6,6,6,6,0,0,0,0,0
0,0,0,0,0,6,6,6,6,6,0,0,0,0,0,0,0,0,6,6,6,6,6,6,6,6,6,6,6,6,6,0,0,0,0,0,0,0,0,6,6,6,6,6,0,0,0,0,0
0,0,0,0,0,6,6,6,6,6,0,0,0,0,0,0,0,0,6,6,6,6,6,6,6,6,6,6,6,6,6,0,0,0,0,0,0,0,0,6,6,6,6,6,0,0,0,0,0
0,0,0,0,0,6,6,6,6,6,0,0,0,0,0,0,0,0,0,0,0,0,0,0,0,0,0,0,0,0,0,0,0,0,0,0,0,0,0,6,6,6,6,6,0,0,0,0,0
0,0,0,0,0,6,6,6,6,6,0,0,0,0,0,0,0,0,0,0,0,0,0,0,0,0,0,0,0,0,0,0,0,0,0,0,0,0,0,6,6,6,6,6,0,0,0,0,0
0,0,0,0,0,6,6,6,6,6,0,0,0,0,0,0,0,0,0,0,0,0,0,0,0,0,0,0,0,0,0,0,0,0,0,0,0,0,0,6,6,6,6,6,0,0,0,0,0
0,0,0,0,0,6,6,6,6,6,0,0,0,0,0,0,0,0,0,0,0,0,0,0,0,0,0,0,0,0,0,0,0,0,0,0,0,0,0,6,6,6,6,6,0,0,0,0,0
0,0,0,0,0,6,6,6,6,6,0,0,0,0,0,0,0,0,0,0,0,0,0,0,0,0,0,0,0,0,0,0,0,0,0,0,0,0,0,6,6,6,6,6,0,0,0,0,0
0,0,0,0,0,6,6,6,6,6,0,0,0,0,0,0,0,0,0,0,0,0,0,0,0,0,0,0,0,0,0,0,0,0,0,0,0,0,0,6,6,6,6,6,0,0,0,0,0
0,0,0,0,0,6,6,6,6,6,0,0,0,0,0,0,0,0,0,0,0,0,0,0,0,0,0,0,0,0,0,0,0,0,0,0,0,0,0,6,6,6,6,6,0,0,0,0,0
0,0,0,0,0,6,6,6,6,6,0,0,0,0,0,0,0,0,0,0,0,0,0,0,0,0,0,0,0,0,0,0,0,0,0,0,0,0,0,6,6,6,6,6,0,0,0,0,0
0,0,0,0,0,6,6,6,6,6,0,0,0,0,0,0,0,0,0,0,0,0,0,0,0,0,0,0,0,0,0,0,0,0,0,0,0,0,0,6,6,6,6,6,0,0,0,0,0
0,0,0,0,0,6,6,6,6,6,0,0,0,0,0,0,0,0,0,0,0,0,0,0,0,0,0,0,0,0,0,0,0,0,0,0,0,0,0,6,6,6,6,6,0,0,0,0,0
0,0,0,0,0,6,6,6,6,6,0,0,0,0,0,0,0,0,0,0,0,0,0,0,0,0,0,0,0,0,0,0,0,0,0,0,0,0,0,6,6,6,6,6,0,0,0,0,0
0,0,0,0,0,6,6,6,6,6,0,0,0,0,0,0,0,0,0,0,0,0,0,0,0,0,0,0,0,0,0,0,0,0,0,0,0,0,0,6,6,6,6,6,0,0,0,0,0
0,0,0,0,0,6,6,6,6,6,0,0,0,0,0,0,0,0,0,0,0,0,0,0,0,0,0,0,0,0,0,0,0,0,0,0,0,0,0,6,6,6,6,6,0,0,0,0,0
0,0,0,0,0,6,6,6,6,6,0,0,0,0,0,0,0,0,0,0,0,0,0,0,0,0,0,0,0,0,0,0,0,0,0,0,0,0,0,6,6,6,6,6,0,0,0,0,0
0,0,0,0,6,6,6,6,6,6,0,0,0,0,0,0,0,0,0,0,0,0,0,0,0,0,0,0,0,0,0,0,0,0,0,0,0,0,0,6,6,6,6,6,6,0,0,0,0
0,0,0,6,6,6,6,6,6,6,0,0,0,0,0,0,0,0,0,0,0,0,0,0,0,0,0,0,0,0,0,0,0,0,0,0,0,0,0,6,6,6,6,6,6,6,0,0,0
0,0,6,0,18,6,6,6,6,6,6,6,6,6,6,6,6,6,6,6,6,6,6,6,6,6,6,6,6,6,6,6,6,6,6,6,6,6,6,6,6,6,6,6,11,0,6,0,0
0,6,0,0,74,6,6,6,6,6,6,6,6,6,6,6,6,6,6,6,6,6,6,6,6,6,6,6,6,6,6,6,6,6,6,6,6,6,6,6,6,6,6,6,74,0,0,6,0
0,6,0,0,6,6,6,6,6,6,6,6,6,6,6,6,6,6,6,6,6,6,6,6,6,6,6,6,6,6,6,6,6,6,6,6,6,6,6,6,6,6,6,6,6,0,0,6,0
0,6,0,0,6,6,6,6,6,6,6,6,6,6,6,6,6,6,11,0,0,0,6,6,6,6,6,0,0,0,18,6,6,6,6,6,6,6,6,6,6,6,6,6,6,0,0,6,0
0,6,6,6,6,6,6,6,6,6,6,6,6,6,6,6,6,6,6,6,6,6,6,6,6,6,6,6,6,6,6,6,6,6,6,6,6,6,6,6,6,6,6,6,6,6,6,6,0
0,6,6,6,6,6,6,6,6,6,6,6,0,0,0,0,0,0,0,0,0,0,0,0,0,0,0,0,0,0,0,0,0,0,0,0,0,6,6,6,6,6,6,6,6,6,6,6,0
0,0,6,6,6,6,6,6,6,6,6,0,0,0,0,0,0,0,0,0,0,0,0,0,0,0,0,0,0,0,0,0,0,0,0,0,0,0,6,6,6,6,6,6,6,6,6,0,0
0,0,0,6,6,6,6,6,6,6,0,0,0,0,0,0,0,0,0,0,0,0,0,0,0,0,0,0,0,0,0,0,0,0,0,0,0,0,0,6,6,6,6,6,6,6,0,0,0
0,0,0,0,6,6,6,6,6,0,0,0,0,0,0,0,0,0,0,0,0,0,0,0,0,0,0,0,0,0,0,0,0,0,0,0,0,0,0,0,6,6,6,6,6,0,0,0,0
0,0,0,0,0,0,0,0,0,0,0,0,0,0,0,0,0,0,0,0,0,0,0,0,0,0,0,0,0,0,0,0,0,0,0,0,0,0,0,0,0,0,0,0,0,0,0,0,0
0,0,0,0,0,0,0,0,0,0,0,0,0,0,0,0,0,0,0,0,0,0,0,0,0,0,0,0,0,0,0,0,0,0,0,0,0,0,0,0,0,0,0,0,0,0,0,0,0
0,0,0,0,0,0,0,0,0,0,0,0,0,0,0,0,0,0,0,0,0,0,0,0,0,0,0,0,0,0,0,0,0,0,0,0,0,0,0,0,0,0,0,0,0,0,0,0,0
0,0,0,0,0,0,0,0,0,0,0,0,0,0,0,0,0,0,0,0,0,0,0,0,0,0,0,0,0,0,0,0,0,0,0,0,0,0,0,0,0,0,0,0,0,0,0,0,0
0,0,0,0,0,0,0,0,0,0,0,0,0,0,0,0,0,0,0,0,0,0,0,0,0,0,0,0,0,0,0,0,0,0,0,0,0,0,0,0,0,0,0,0,0,0,0,0,0
0,0,0,0,0,0,0,0,0,0,0,0,0,0,0,0,0,0,0,0,0,0,0,0,0,0,0,0,0,0,0,0,0,0,0,0,0,0,0,0,0,0,0,0,0,0,0,0,0
0,0,0,0,0,0,0,0,0,0,0,0,0,0,0,0,0,0,0,0,0,0,0,0,0,0,0,0,0,0,0,0,0,0,0,0,0,0,0,0,0,0,0,0,0,0,0,0,0
0,0,0,0,0,0,0,0,0,0,0,0,0,0,0,0,0,0,0,0,0,0,0,0,0,0,0,0,0,0,0,0,0,0,0,0,0,0,0,0,0,0,0,0,0,0,0,0,0
:endlayer
layer: 17
0,0,0,0,0,0,0,0,0,0,0,0,0,0,0,0,0,0,0,0,0,0,0,0,0,0,0,0,0,0,0,0,0,0,0,0,0,0,0,0,0,0,0,0,0,0,0,0,0
0,0,0,0,6,6,6,6,6,0,0,0,0,0,0,0,0,0,0,0,0,0,0,0,0,0,0,0,0,0,0,0,0,0,0,0,0,0,0,0,6,6,6,6,6,0,0,0,0
0,0,0,6,0,6,0,0,6,6,0,0,0,0,0,0,0,0,0,0,0,0,0,0,0,0,0,0,0,0,0,0,0,0,0,0,0,0,0,6,6,0,0,6,0,6,0,0,0
0,0,6,0,0,0,0,0,6,6,6,0,0,0,0,0,0,0,0,0,0,0,0,0,0,0,0,0,0,0,0,0,0,0,0,0,0,0,6,6,6,0,0,0,0,0,6,0,0
0,6,0,0,0,6,6,6,6,0,6,6,0,0,0,0,0,0,0,0,0,0,0,0,0,0,0,0,0,0,0,0,0,0,0,0,0,6,6,6,6,6,6,6,0,0,0,6,0
0,6,0,0,0,0,0,0,0,52,52,6,6,6,11,0,18,6,6,6,11,0,18,6,6,6,11,0,18,6,6,6,11,0,18,6,6,6,52,52,0,0,0,0,0,0,0,6,0
0,6,0,0,0,0,10,0,0,0,0,6,0,0,0,0,0,0,0,0,0,0,0,0,0,0,0,0,0,0,0,0,0,0,0,0,0,6,0,0,0,0,0,0,0,0,0,6,0
