# Ancient Warfare Structure Template File
# Auto-generated structure template file. created on: 8/19/2019 at: 10:23:17
# Lines beginning with # denote comments

header:
version=2.9
name=ArsMagicaOldTowerMobSpawner
mods=ebwizardry
size=18,65,18
offset=6,6,17
:endheader

#### VALIDATION ####
validation:
type=ground
survival=false
worldGenEnabled=true
unique=false
preserveBlocks=false
selectionWeight=40
clusterValue=40
minDuplicateDistance=1000
dimensionWhiteList=true
dimensionList=0
biomeWhiteList=true
biomeList=minecraft:swampland,biomesoplenty:woodland,minecraft:roofed_forest,biomesoplenty:bayou,biomesoplenty:dead_forest,minecraft:forest,minecraft:extreme_hills,biomesoplenty:ominous_woods,biomesoplenty:land_of_lakes,minecraft:taiga_cold,biomesoplenty:dead_swamp,biomesoplenty:marsh,minecraft:jungle,minecraft:birch_forest,minecraft:ice_flats,biomesoplenty:steppe,minecraft:plains
leveling=6
fill=6
border=6
blockSwap=false
:endvalidation

#### LAYERS ####
layer: 0
1,1,1,1,1,1,1,1,1,1,1,1,1,1,1,1,1,1
1,2,2,2,2,2,2,2,2,2,2,2,2,2,2,2,2,1
1,2,2,2,6,2,2,2,2,2,2,2,2,2,2,2,2,1
1,2,2,1,1,1,2,2,2,2,2,2,1,1,1,2,2,1
1,2,2,1,4,1,2,2,2,2,2,2,1,2,1,2,2,1
1,2,2,1,1,1,4,2,2,2,2,2,1,1,1,2,2,1
1,2,2,4,4,4,4,4,4,4,4,4,2,2,2,2,3,1
1,2,2,4,4,4,4,4,4,4,4,4,4,4,4,4,4,1
1,2,2,2,4,4,4,4,1,1,4,4,4,4,4,4,4,1
1,2,2,2,4,4,4,4,1,1,4,4,4,4,4,4,4,1
1,2,2,2,2,4,4,4,4,4,4,4,4,4,4,4,4,1
1,2,2,2,2,2,2,2,4,4,2,2,1,4,4,4,4,1
1,2,2,1,1,1,2,5,5,5,5,2,1,1,1,4,4,1
1,4,2,1,2,1,2,5,5,5,5,5,1,2,1,4,4,1
1,4,2,1,1,1,2,2,5,5,5,5,1,1,1,2,4,1
1,4,4,2,2,2,2,2,5,5,5,5,2,2,2,2,2,1
1,4,4,2,2,2,2,2,2,5,5,5,5,2,2,2,2,1
1,1,1,1,1,1,1,1,1,1,1,1,1,1,1,1,1,1
:endlayer
layer: 1
1,1,1,1,1,9,1,1,1,1,1,1,1,9,1,1,1,1
1,7,7,7,7,7,7,7,7,7,7,7,7,7,7,7,7,1
1,7,6,6,6,6,6,7,8,8,7,6,6,6,6,6,7,1
1,7,6,1,1,1,6,7,8,8,7,6,1,1,1,6,7,1
1,7,6,1,6,1,6,8,8,8,8,6,1,6,1,6,7,1
1,7,6,1,1,1,6,7,8,8,7,6,1,1,1,6,7,1
1,7,6,6,6,6,6,7,8,8,7,6,6,6,6,6,7,1
1,7,7,7,8,7,7,7,8,8,7,7,7,8,7,7,7,1
1,7,8,8,8,8,8,8,1,1,8,8,8,8,8,8,8,1
1,7,8,8,8,8,8,8,1,1,8,8,8,8,8,8,8,1
1,7,7,7,8,7,7,7,8,8,7,7,7,8,7,7,7,1
1,7,6,6,6,6,6,7,8,8,7,6,1,6,6,6,7,1
1,7,6,1,1,1,6,7,8,8,7,6,1,1,1,6,7,1
1,7,6,1,6,1,6,8,8,8,8,6,1,6,1,6,7,1
1,7,6,1,1,1,6,7,8,8,7,6,1,1,1,6,7,1
1,7,6,6,6,6,6,7,8,8,7,6,6,6,6,6,7,1
1,7,7,7,7,7,7,7,7,7,7,7,7,7,7,7,7,1
1,1,1,1,9,1,1,1,1,1,1,1,1,1,1,1,1,1
:endlayer
layer: 2
1,1,1,1,1,20,1,1,1,1,1,1,1,13,1,1,1,1
1,7,7,7,7,1,7,7,7,7,7,7,7,1,7,7,7,1
1,7,24,0,21,0,0,7,0,0,7,0,0,0,0,10,7,1
1,7,0,0,0,0,0,7,0,0,7,0,0,0,0,0,7,1
1,7,11,0,0,0,0,0,0,0,0,0,0,14,0,0,7,1
1,7,0,0,0,0,0,7,0,0,7,0,0,0,0,0,7,1
1,7,11,11,11,11,18,7,0,0,7,16,11,11,11,11,7,1
1,7,7,7,1,7,7,7,0,0,7,7,7,1,7,7,7,1
1,7,0,0,0,0,0,0,0,0,0,0,0,0,0,0,7,1
1,7,0,0,0,0,0,0,0,0,0,0,0,0,0,0,7,1
1,7,7,1,1,7,7,7,0,0,7,7,7,1,7,7,7,1
1,7,11,11,11,11,19,7,0,0,7,17,11,11,11,11,7,1
1,7,0,0,0,0,0,7,0,0,7,0,0,0,0,0,7,1
1,7,0,0,22,0,0,0,0,0,0,0,0,15,0,0,1,0
1,7,0,0,0,0,0,7,0,0,7,0,0,0,0,0,7,1
1,7,25,0,0,0,0,7,0,0,7,0,0,0,0,12,7,1
1,7,7,7,1,7,7,7,7,7,7,7,7,7,7,7,7,1
1,1,1,1,23,1,1,1,1,1,1,1,1,1,1,1,1,1
:endlayer
layer: 3
1,1,1,1,1,1,1,1,1,1,1,1,1,1,1,1,1,1
1,7,7,7,7,1,7,7,7,7,7,7,7,1,7,7,7,1
1,7,0,0,0,0,0,7,0,0,7,0,0,0,0,0,7,1
1,7,0,0,0,0,0,7,0,0,7,0,0,0,0,0,7,1
1,7,26,0,0,0,0,0,0,0,0,0,0,0,0,0,7,1
1,7,0,0,0,0,0,7,0,0,7,0,0,0,0,0,7,1
1,7,11,11,11,11,18,7,0,0,7,16,11,11,11,11,7,1
1,7,7,7,1,7,7,7,0,0,7,7,7,1,7,7,7,1
1,7,0,0,0,0,0,0,0,0,0,0,0,0,0,0,7,1
1,7,0,0,0,0,0,0,0,0,0,0,0,0,0,0,7,1
1,7,7,1,1,7,7,7,0,0,7,7,7,1,7,7,7,1
1,7,11,11,11,11,19,7,0,0,7,17,11,11,11,11,7,1
1,7,0,0,0,0,0,7,0,0,7,0,0,0,0,0,7,1
1,7,0,0,0,0,0,0,0,0,0,0,0,0,0,0,1,1
1,7,0,0,0,0,0,7,0,0,7,0,0,0,0,0,7,1
1,7,0,0,0,0,0,7,0,0,7,0,0,0,0,0,7,1
1,7,7,7,1,7,7,7,7,7,7,7,7,7,7,7,7,1
1,1,1,1,1,1,1,1,1,1,1,1,1,1,1,1,1,1
:endlayer
layer: 4
1,1,1,1,1,1,1,1,1,1,1,1,1,1,1,1,1,1
1,7,7,7,7,7,7,7,7,7,7,7,7,7,7,7,7,1
1,7,0,0,0,0,0,7,0,0,7,0,0,0,0,0,7,1
1,7,0,0,0,0,0,7,0,0,7,0,0,0,0,0,7,1
1,7,0,0,0,0,0,7,0,0,7,0,0,0,0,0,7,1
1,1,0,0,0,0,0,7,0,0,7,0,0,0,0,0,7,1
1,7,11,11,11,11,18,7,0,0,7,16,11,11,11,11,7,1
1,7,7,7,1,7,7,7,0,0,7,7,7,7,7,7,7,1
1,7,0,0,0,0,0,0,0,0,0,0,0,0,0,0,7,1
1,7,0,0,0,0,0,0,0,0,0,0,0,0,0,0,7,1
1,7,7,7,1,7,7,7,0,0,7,7,7,7,7,7,7,1
1,7,11,11,11,11,19,7,0,0,7,17,11,11,11,11,7,1
1,7,0,0,0,0,0,7,0,0,7,0,0,0,0,0,7,1
1,7,0,0,0,0,0,7,0,0,7,0,0,0,0,0,7,1
1,7,0,0,0,0,0,7,0,0,7,0,0,0,0,0,7,1
1,7,0,0,0,0,0,7,0,0,7,0,0,0,0,0,7,1
1,7,7,7,7,7,7,7,7,7,7,7,7,7,7,7,7,1
1,1,1,1,1,1,1,1,1,1,1,1,1,1,1,1,1,1
:endlayer
layer: 5
27,27,27,27,27,27,27,27,27,27,27,27,27,27,27,27,27,27
27,7,7,7,7,7,7,7,7,7,7,7,7,7,7,7,7,27
27,7,0,0,0,0,0,7,0,0,7,0,0,0,0,0,7,27
27,7,0,0,0,0,0,7,0,0,7,0,0,0,0,0,7,27
27,7,0,0,0,0,0,7,0,0,7,0,0,0,0,0,7,27
27,7,0,0,0,0,0,7,0,0,7,0,0,0,0,0,7,27
27,7,11,11,11,11,18,7,0,0,7,16,11,11,11,11,7,27
27,7,7,7,7,7,7,7,0,0,7,7,7,7,7,7,7,27
27,7,0,0,0,0,0,0,0,0,0,0,0,0,0,0,7,27
27,7,0,0,0,0,0,0,0,0,0,0,0,0,0,0,7,27
27,7,7,7,7,7,7,7,0,0,7,7,7,7,7,7,7,27
27,7,11,11,11,11,19,7,0,0,1,17,11,11,11,11,7,27
27,7,0,0,0,0,0,7,0,0,7,0,0,0,0,0,7,27
27,7,0,0,0,0,0,7,0,0,7,0,0,0,0,0,7,27
27,7,0,0,0,0,0,7,0,0,7,0,0,0,0,0,7,27
27,7,0,0,0,0,0,7,0,0,7,0,0,0,0,0,7,27
27,7,7,7,7,7,7,7,7,7,7,7,7,7,7,7,7,27
27,27,27,27,27,27,27,27,27,27,27,27,27,27,27,27,27,27
:endlayer
layer: 6
31,28,28,28,28,28,28,28,28,28,28,28,28,28,28,28,28,28
31,6,7,7,6,7,7,6,7,7,6,7,7,6,7,7,6,29
31,7,6,6,6,6,6,6,6,6,6,6,6,6,7,6,7,29
31,7,7,7,7,7,7,7,7,7,7,7,7,6,7,6,7,29
31,6,6,6,6,6,6,6,6,6,6,6,7,6,7,6,6,29
31,7,6,7,7,7,7,7,7,7,7,6,7,6,7,6,7,29
31,7,6,7,6,6,18,6,6,6,7,0,7,6,7,6,7,29
31,6,6,7,6,7,7,7,7,6,7,6,7,6,7,6,6,29
31,7,6,7,6,7,6,1,1,1,1,1,1,1,7,6,7,29
31,7,6,7,6,7,6,7,6,1,6,6,7,6,7,6,7,29
31,6,6,7,6,7,6,7,6,1,7,7,7,6,7,6,6,29
31,7,6,7,6,7,19,7,6,6,6,17,1,1,7,6,7,29
31,7,6,7,6,7,6,7,7,7,7,7,7,7,7,6,7,29
31,6,6,7,6,7,6,6,6,6,6,6,6,6,6,6,6,29
31,7,6,7,6,7,7,7,7,7,7,7,7,7,7,7,7,29
31,7,6,7,6,6,6,6,6,6,6,6,6,6,6,6,7,29
31,6,7,7,6,7,7,6,7,7,6,7,7,6,7,7,6,29
31,30,30,30,30,30,30,30,30,30,30,30,30,30,30,30,30,29
:endlayer
layer: 7
0,0,0,0,0,0,0,0,0,0,0,0,0,0,0,0,0,0
0,6,0,0,6,0,0,6,0,0,6,0,0,6,0,0,6,0
0,0,0,0,0,0,0,0,0,0,0,0,0,0,0,0,0,0
0,0,0,0,0,0,0,0,0,0,0,0,0,0,0,0,0,0
0,6,0,0,0,0,0,0,32,32,0,0,0,0,0,0,6,0
0,0,0,0,0,33,6,1,37,37,1,6,33,0,0,0,0,0
0,0,0,0,0,6,41,0,32,32,0,35,6,0,0,0,0,0
0,6,0,0,0,1,0,0,0,0,0,0,1,0,0,0,6,0
0,0,0,0,32,42,32,0,0,0,0,32,34,32,0,0,0,0
0,0,0,0,32,42,32,0,1,0,0,32,34,32,0,0,0,0
0,6,0,0,0,1,0,0,0,30,0,0,1,0,0,0,6,0
0,0,0,0,0,6,41,0,39,32,0,36,6,0,0,0,0,0
0,0,0,0,0,33,6,1,40,38,1,6,33,0,0,0,0,0
0,6,0,0,0,0,0,0,32,32,0,0,0,0,0,0,6,0
0,0,0,0,0,0,0,0,0,0,0,0,0,0,0,0,0,0
0,0,0,0,0,0,0,0,0,0,0,0,0,0,0,0,0,0
0,6,0,0,6,0,0,6,0,0,6,0,0,6,0,0,6,0
0,0,0,0,0,0,0,0,0,0,0,0,0,0,0,0,0,0
:endlayer
layer: 8
0,0,0,0,0,0,0,0,0,0,0,0,0,0,0,0,0,0
0,6,0,0,6,49,45,6,0,0,6,49,45,6,0,0,6,0
0,43,0,0,0,0,0,0,0,0,0,0,0,0,0,0,43,0
0,44,0,0,0,0,0,0,0,0,0,0,0,0,0,0,44,0
0,6,0,0,0,0,0,0,0,0,0,0,0,0,0,0,6,0
0,0,0,0,0,33,46,1,47,48,1,46,33,0,0,0,0,0
0,0,0,0,0,46,0,0,0,0,0,0,46,0,0,0,0,0
0,6,0,0,0,1,0,0,0,0,0,0,1,0,0,0,6,0
0,0,0,0,0,48,0,0,0,1,0,0,47,0,0,0,43,0
0,0,0,0,0,47,0,0,1,30,0,0,48,0,0,0,44,0
0,6,0,0,0,1,0,0,0,0,0,0,1,0,0,0,6,0
0,0,0,0,0,46,0,0,0,0,0,0,46,0,0,0,0,0
0,0,0,0,0,33,46,1,50,47,1,46,33,0,0,0,0,0
0,6,0,0,0,0,0,0,0,0,0,0,0,0,0,0,6,0
0,43,0,0,0,0,0,0,0,0,0,0,0,0,0,0,43,0
0,44,0,0,0,0,0,0,0,0,0,0,0,0,0,0,44,0
0,6,0,0,6,49,45,6,0,0,6,49,45,6,0,0,6,0
0,0,0,0,0,0,0,0,0,0,0,0,0,0,0,0,0,0
:endlayer
layer: 9
0,0,0,0,0,0,0,0,0,0,0,0,0,0,0,0,0,0
0,6,0,0,6,29,31,6,0,0,6,29,31,6,0,0,6,0
0,30,0,0,0,0,0,0,0,0,0,0,0,0,0,0,30,0
0,28,0,0,0,0,0,0,0,0,0,0,0,0,0,0,28,0
0,6,0,0,0,0,0,0,0,0,0,0,0,0,0,0,6,0
0,0,0,0,0,33,46,1,29,31,1,46,33,0,0,0,0,0
0,0,0,0,0,46,0,0,0,0,0,0,46,0,0,0,0,0
0,6,0,0,0,1,0,0,0,0,0,0,1,0,0,0,6,0
0,30,0,0,0,30,0,1,29,0,0,0,30,0,0,0,30,0
0,28,0,0,0,28,0,0,1,0,0,0,28,0,0,0,28,0
0,6,0,0,0,1,0,0,0,0,0,0,1,0,0,0,6,0
0,0,0,0,0,46,0,0,0,0,0,0,46,0,0,0,0,0
0,0,0,0,0,33,46,1,29,31,1,46,33,0,0,0,0,0
0,6,0,0,0,0,0,0,0,0,0,0,0,0,0,0,6,0
0,30,0,0,0,0,0,0,0,0,0,0,0,0,0,0,30,0
0,28,0,0,0,0,0,0,0,0,0,0,0,0,0,0,28,0
0,6,0,0,6,29,31,6,0,0,6,29,31,6,0,0,6,0
0,0,0,0,0,0,0,0,0,0,0,0,0,0,0,0,0,0
:endlayer
layer: 10
0,0,0,0,0,0,0,0,0,0,0,0,0,0,0,0,0,0
0,6,49,45,6,0,0,6,49,45,6,0,0,6,49,45,6,0
0,0,0,0,0,0,0,0,0,0,0,0,0,0,0,0,0,0
0,0,0,0,0,0,0,0,0,0,0,0,0,0,0,0,0,0
0,6,0,0,0,0,0,0,0,0,0,0,0,0,0,0,6,0
0,43,0,0,0,33,46,1,49,45,1,46,33,0,0,0,43,0
0,44,0,0,0,46,0,0,0,0,0,0,46,0,0,0,44,0
0,6,0,0,0,1,0,0,0,0,0,0,1,0,0,0,6,0
0,0,0,0,0,43,0,0,0,0,0,0,43,0,0,0,0,0
0,0,0,0,0,44,0,28,1,0,0,0,44,0,0,0,0,0
0,6,0,0,0,1,0,0,0,0,0,0,1,0,0,0,6,0
0,43,0,0,0,46,0,0,0,0,0,0,46,0,0,0,43,0
0,44,0,0,0,33,46,1,49,45,1,46,33,0,0,0,44,0
0,6,0,0,0,0,0,0,0,0,0,0,0,0,0,0,6,0
0,0,0,0,0,0,0,0,0,0,0,0,0,0,0,0,0,0
0,0,0,0,0,0,0,0,0,0,0,0,0,0,0,0,0,0
0,6,49,45,6,0,0,6,49,45,6,0,0,6,49,45,6,0
0,0,0,0,0,0,0,0,0,0,0,0,0,0,0,0,0,0
:endlayer
layer: 11
0,0,0,0,0,0,0,0,0,0,0,0,0,0,0,0,0,0
0,6,29,31,6,0,0,6,29,31,6,0,0,6,29,31,6,0
0,0,0,0,0,0,0,0,0,0,0,0,0,0,0,0,0,0
0,0,0,0,0,0,0,0,0,0,0,0,0,0,0,0,0,0
0,6,0,0,0,0,0,0,0,0,0,0,0,0,0,0,6,0
0,30,0,0,0,33,33,33,33,33,33,33,33,0,0,0,30,0
0,28,0,0,0,33,7,7,7,7,7,7,33,0,0,0,28,0
0,6,0,0,0,33,7,1,1,1,1,7,33,0,0,0,6,0
0,0,0,0,0,33,7,0,0,0,1,7,33,0,0,0,0,0
0,0,0,0,0,33,7,0,1,0,1,7,33,0,0,0,0,0
0,6,0,0,0,33,7,28,1,1,1,7,33,0,0,0,6,0
0,30,0,0,0,33,7,7,7,7,7,7,33,0,0,0,30,0
0,28,0,0,0,33,33,33,33,33,33,33,33,0,0,0,28,0
0,6,0,0,0,0,0,0,0,0,0,0,0,0,0,0,6,0
0,0,0,0,0,0,0,0,0,0,0,0,0,0,0,0,0,0
0,0,0,0,0,0,0,0,0,0,0,0,0,0,0,0,0,0
0,6,29,31,6,0,0,6,29,31,6,0,0,6,29,31,6,0
0,0,0,0,0,0,0,0,0,0,0,0,0,0,0,0,0,0
:endlayer
layer: 12
0,0,0,0,0,0,0,0,0,0,0,0,0,0,0,0,0,0
0,6,0,0,6,49,45,6,0,0,6,49,45,6,0,0,6,0
0,43,0,0,0,0,0,0,0,0,0,0,0,0,0,0,43,0
0,44,0,0,0,0,0,0,0,0,0,0,0,0,0,0,44,0
0,6,0,0,0,0,0,0,0,0,0,0,0,0,0,0,6,0
0,0,0,0,0,1,1,6,1,1,6,1,1,0,0,0,0,0
0,0,0,0,0,1,0,0,0,0,0,0,1,0,0,0,0,0
0,6,0,0,0,6,0,0,0,0,0,0,6,0,0,0,6,0
0,43,0,0,0,1,0,0,0,1,0,0,1,0,0,0,43,0
0,44,0,0,0,1,0,0,1,30,0,0,1,0,0,0,44,0
0,6,0,0,0,6,0,0,0,0,0,0,6,0,0,0,6,0
0,0,0,0,0,1,0,0,0,0,0,0,1,0,0,0,0,0
0,0,0,0,0,1,1,6,1,1,6,1,1,0,0,0,0,0
0,6,0,0,0,0,0,0,0,0,0,0,0,0,0,0,6,0
0,43,0,0,0,0,0,0,0,0,0,0,0,0,0,0,43,0
0,44,0,0,0,0,0,0,0,0,0,0,0,0,0,0,44,0
0,6,0,0,6,49,45,6,0,0,6,49,45,6,0,0,6,0
0,0,0,0,0,0,0,0,0,0,0,0,0,0,0,0,0,0
:endlayer
layer: 13
0,0,0,0,0,0,0,0,0,0,0,0,0,0,0,0,0,0
0,6,0,0,6,29,31,6,0,0,6,29,31,6,0,0,6,0
0,30,0,0,0,0,0,0,0,0,0,0,0,0,0,0,30,0
0,28,0,0,0,0,0,0,0,0,0,0,0,0,0,0,28,0
0,6,0,0,0,0,0,0,0,0,0,0,0,0,0,0,6,0
0,0,0,0,0,1,46,6,46,46,6,46,1,0,0,0,0,0
0,0,0,0,0,46,0,0,0,0,0,0,46,0,0,0,0,0
0,6,0,0,0,6,0,0,0,0,0,0,6,0,0,0,6,0
0,30,0,0,0,46,0,1,29,0,0,0,46,0,0,0,30,0
0,28,0,0,0,46,0,0,1,0,0,0,46,0,0,0,28,0
0,6,0,0,0,6,0,0,0,0,0,0,6,0,0,0,6,0
0,0,0,0,0,46,0,0,0,0,0,0,46,0,0,0,0,0
0,0,0,0,0,1,46,6,46,46,6,46,1,0,0,0,0,0
0,6,0,0,0,0,0,0,0,0,0,0,0,0,0,0,6,0
0,30,0,0,0,0,0,0,0,0,0,0,0,0,0,0,30,0
0,28,0,0,0,0,0,0,0,0,0,0,0,0,0,0,28,0
0,6,0,0,6,29,31,6,0,0,6,29,31,6,0,0,6,0
0,0,0,0,0,0,0,0,0,0,0,0,0,0,0,0,0,0
:endlayer
layer: 14
0,0,0,0,0,0,0,0,0,0,0,0,0,0,0,0,0,0
0,6,49,45,6,0,0,6,49,45,6,0,0,6,49,45,6,0
0,0,0,0,0,0,0,0,0,0,0,0,0,0,0,0,0,0
0,0,0,0,0,0,0,0,0,0,0,0,0,0,0,0,0,0
0,6,0,0,0,0,0,0,0,0,0,0,0,0,0,0,6,0
0,43,0,0,0,1,46,6,46,46,6,46,1,0,0,0,43,0
0,44,0,0,0,46,0,0,0,0,0,0,46,0,0,0,44,0
0,6,0,0,0,6,0,0,0,0,0,0,6,0,0,0,6,0
0,0,0,0,0,46,0,0,0,0,0,0,46,0,0,0,0,0
0,0,0,0,0,46,0,28,1,0,0,0,46,0,0,0,0,0
0,6,0,0,0,6,0,1,0,0,0,0,6,0,0,0,6,0
0,43,0,0,0,46,0,0,0,0,0,0,46,0,0,0,43,0
0,44,0,0,0,1,46,6,46,46,6,46,1,0,0,0,44,0
0,6,0,0,0,0,0,0,0,0,0,0,0,0,0,0,6,0
0,0,0,0,0,0,0,0,0,0,0,0,0,0,0,0,0,0
0,0,0,0,0,0,0,0,0,0,0,0,0,0,0,0,0,0
0,6,49,45,6,0,0,6,49,45,6,0,0,6,49,45,6,0
0,0,0,0,0,0,0,0,0,0,0,0,0,0,0,0,0,0
:endlayer
layer: 15
0,0,0,0,0,0,0,0,0,0,0,0,0,0,0,0,0,0
0,6,0,0,6,0,0,6,0,0,6,0,0,6,0,0,6,0
0,0,0,0,0,0,0,0,0,0,0,0,0,0,0,0,0,0
0,0,0,0,0,0,0,0,0,0,0,0,0,0,0,0,0,0
0,6,0,0,0,0,0,0,0,0,0,0,0,0,0,0,6,0
0,0,0,0,0,1,49,6,49,45,6,45,1,0,0,0,0,0
0,0,0,0,0,43,0,0,0,0,0,0,43,0,0,0,0,0
0,6,0,0,0,6,0,0,0,0,0,0,6,0,0,0,6,0
0,0,0,0,0,43,0,0,0,0,0,0,43,0,0,0,0,0
0,0,0,0,0,44,0,0,1,0,0,0,44,0,0,0,0,0
0,6,0,0,0,6,0,0,31,1,0,0,6,0,0,0,6,0
0,0,0,0,0,44,0,0,0,0,0,0,44,0,0,0,0,0
0,0,0,0,0,1,49,6,49,45,6,45,1,0,0,0,0,0
0,6,0,0,0,0,0,0,0,0,0,0,0,0,0,0,6,0
0,0,0,0,0,0,0,0,0,0,0,0,0,0,0,0,0,0
0,0,0,0,0,0,0,0,0,0,0,0,0,0,0,0,0,0
0,6,0,0,6,0,0,6,0,0,6,0,0,6,0,0,6,0
0,0,0,0,0,0,0,0,0,0,0,0,0,0,0,0,0,0
:endlayer
layer: 16
0,0,0,0,0,0,0,0,0,0,0,0,0,0,0,0,0,0
0,6,0,0,6,0,0,6,0,0,6,0,0,6,0,0,6,0
0,0,0,0,0,0,0,0,0,0,0,0,0,0,0,0,0,0
0,0,0,0,0,0,0,0,0,0,0,0,0,0,0,0,0,0
0,6,0,0,0,0,0,0,0,0,0,0,0,0,0,0,6,0
0,0,0,0,0,1,1,6,1,1,6,1,1,0,0,0,0,0
0,0,0,0,0,1,0,0,0,0,0,0,1,0,0,0,0,0
0,6,0,0,0,6,0,0,0,0,0,0,6,0,0,0,6,0
0,0,0,0,0,1,0,0,0,1,0,0,1,0,0,0,0,0
0,0,0,0,0,1,0,0,1,30,0,0,1,0,0,0,0,0
0,6,0,0,0,6,0,0,0,0,0,0,6,0,0,0,6,0
0,0,0,0,0,1,0,0,0,0,0,0,1,0,0,0,0,0
0,0,0,0,0,1,1,6,1,1,6,1,1,0,0,0,0,0
0,6,0,0,0,0,0,0,0,0,0,0,0,0,0,0,6,0
0,0,0,0,0,0,0,0,0,0,0,0,0,0,0,0,0,0
0,0,0,0,0,0,0,0,0,0,0,0,0,0,0,0,0,0
0,6,0,0,6,0,0,6,0,0,6,0,0,6,0,0,6,0
0,0,0,0,0,0,0,0,0,0,0,0,0,0,0,0,0,0
:endlayer
layer: 17
0,0,0,0,0,0,0,0,0,0,0,0,0,0,0,0,0,0
0,1,1,1,1,1,1,1,1,1,1,1,1,1,1,1,1,0
0,1,53,1,1,1,1,1,1,1,1,1,1,1,1,51,1,0
0,1,8,1,1,1,1,1,1,1,1,1,1,1,1,8,1,0
0,1,1,1,1,1,1,1,1,1,1,1,1,1,1,1,1,0
0,1,1,1,1,33,7,6,7,7,6,7,33,1,1,1,1,0
0,1,1,1,1,7,7,7,7,7,7,7,7,1,1,1,1,0
0,1,1,1,1,6,7,1,1,1,1,7,6,1,1,1,1,0
0,1,1,1,1,7,7,1,29,0,1,7,7,1,1,1,1,0
0,1,1,1,1,7,7,0,1,0,1,7,7,1,1,1,1,0
0,1,1,1,1,6,7,0,0,0,1,7,6,1,1,1,1,0
0,1,1,1,1,7,7,7,7,7,7,7,7,1,1,1,1,0
0,1,1,1,1,33,7,6,7,7,6,7,33,1,1,1,1,0
0,1,1,1,1,1,1,1,1,1,1,1,1,1,1,1,1,0
0,1,1,1,1,1,1,1,1,1,1,1,1,1,1,8,1,0
0,1,54,8,1,1,1,1,1,1,1,1,1,1,1,52,1,0
0,1,1,1,1,1,1,1,1,1,1,1,1,1,1,1,1,0
0,0,0,0,0,0,0,0,0,0,0,0,0,0,0,0,0,0
:endlayer
layer: 18
0,0,0,0,0,0,0,0,0,0,0,0,0,0,0,0,0,0
0,6,28,28,28,28,28,28,28,28,28,28,28,28,28,28,6,0
0,31,55,56,0,0,0,0,0,0,0,0,0,0,56,55,29,0
0,31,56,0,0,0,0,0,0,0,0,0,0,0,0,56,29,0
0,31,0,0,0,0,0,0,0,0,0,0,0,0,0,0,29,0
0,31,0,0,0,33,1,6,1,1,6,1,33,0,0,0,29,0
0,31,0,0,0,1,0,0,0,0,0,0,1,0,0,0,29,0
0,31,0,0,0,6,0,0,0,0,0,0,6,0,0,0,29,0
0,31,0,0,0,1,0,0,0,0,0,32,34,32,0,0,29,0
0,31,0,0,0,1,0,28,1,0,0,32,34,32,0,0,29,0
0,31,0,0,0,6,0,1,0,0,0,0,6,0,0,0,29,0
0,31,0,0,0,1,0,0,0,0,0,0,1,0,0,0,29,0
0,31,0,0,0,33,1,6,1,1,6,1,33,0,0,0,29,0
0,31,0,0,0,0,0,0,0,0,0,0,0,0,0,0,29,0
0,31,56,0,0,0,0,0,0,0,0,0,0,0,0,56,29,0
0,31,55,56,0,0,0,0,0,0,0,0,0,0,56,55,29,0
0,6,30,30,30,30,30,30,30,30,30,30,30,30,30,30,6,0
0,0,0,0,0,0,0,0,0,0,0,0,0,0,0,0,0,0
:endlayer
layer: 19
0,0,0,0,0,0,0,0,0,0,0,0,0,0,0,0,0,0
0,6,0,0,0,0,0,0,0,0,0,0,0,0,0,0,6,0
0,0,0,0,0,0,0,0,0,0,0,0,0,0,0,0,0,0
0,0,0,0,0,0,0,0,0,0,0,0,0,0,0,0,0,0
0,0,0,0,0,0,0,0,0,0,0,0,0,0,0,0,0,0
0,0,0,0,0,33,46,6,46,46,6,46,33,0,0,0,0,0
0,0,0,0,0,46,0,0,0,0,0,0,46,0,0,0,0,0
0,0,0,0,0,6,0,0,0,0,0,0,6,0,0,0,0,0
0,0,0,0,0,46,0,0,0,0,0,0,47,0,0,0,0,0
0,0,0,0,0,46,0,0,1,0,0,0,48,0,0,0,0,0
0,0,0,0,0,6,0,0,31,1,0,0,6,0,0,0,0,0
0,0,0,0,0,46,0,0,0,0,0,0,46,0,0,0,0,0
0,0,0,0,0,33,46,6,46,46,6,46,33,0,0,0,0,0
0,0,0,0,0,0,0,0,0,0,0,0,0,0,0,0,0,0
0,0,0,0,0,0,0,0,0,0,0,0,0,0,0,0,0,0
0,0,0,0,0,0,0,0,0,0,0,0,0,0,0,0,0,0
0,6,0,0,0,0,0,0,0,0,0,0,0,0,0,0,6,0
0,0,0,0,0,0,0,0,0,0,0,0,0,0,0,0,0,0
:endlayer
layer: 20
0,0,0,0,0,0,0,0,0,0,0,0,0,0,0,0,0,0
0,0,0,0,0,0,0,0,0,0,0,0,0,0,0,0,0,0
0,0,0,0,0,0,0,0,0,0,0,0,0,0,0,0,0,0
0,0,0,0,0,0,0,0,0,0,0,0,0,0,0,0,0,0
0,0,0,0,0,0,0,0,0,0,0,0,0,0,0,0,0,0
0,0,0,0,0,33,46,6,46,46,6,46,33,0,0,0,0,0
0,0,0,0,0,46,0,0,0,0,0,0,46,0,0,0,0,0
0,0,0,0,0,6,0,0,0,0,0,0,6,0,0,0,0,0
0,0,0,0,0,46,0,0,0,1,0,0,1,0,0,0,0,0
0,0,0,0,0,46,0,0,1,30,0,0,1,0,0,0,0,0
0,0,0,0,0,6,0,0,0,0,0,0,6,0,0,0,0,0
0,0,0,0,0,46,0,0,0,0,0,0,46,0,0,0,0,0
0,0,0,0,0,33,46,6,46,46,6,46,33,0,0,0,0,0
0,0,0,0,0,0,0,0,0,0,0,0,0,0,0,0,0,0
0,0,0,0,0,0,0,0,0,0,0,0,0,0,0,0,0,0
0,0,0,0,0,0,0,0,0,0,0,0,0,0,0,0,0,0
0,0,0,0,0,0,0,0,0,0,0,0,0,0,0,0,0,0
0,0,0,0,0,0,0,0,0,0,0,0,0,0,0,0,0,0
:endlayer
layer: 21
0,0,0,0,0,0,0,0,0,0,0,0,0,0,0,0,0,0
0,0,0,0,0,0,0,0,0,0,0,0,0,0,0,0,0,0
0,0,0,0,0,0,0,0,0,0,0,0,0,0,0,0,0,0
0,0,0,0,0,0,0,0,0,0,0,0,0,0,0,0,0,0
0,0,0,0,0,0,0,0,0,0,0,0,0,0,0,0,0,0
0,0,0,0,0,33,46,6,46,46,6,46,33,0,0,0,0,0
0,0,0,0,0,46,0,0,0,0,0,0,46,0,0,0,0,0
0,0,0,0,0,1,0,0,0,0,0,0,6,0,0,0,0,0
0,0,0,0,0,46,0,1,29,0,0,0,46,0,0,0,0,0
0,0,0,0,0,46,0,0,1,0,0,0,46,0,0,0,0,0
0,0,0,0,0,1,0,0,0,0,0,0,6,0,0,0,0,0
0,0,0,0,0,46,0,0,0,0,0,0,46,0,0,0,0,0
0,0,0,0,0,33,46,1,46,46,1,46,33,0,0,0,0,0
0,0,0,0,0,0,0,0,0,0,0,0,0,0,0,0,0,0
0,0,0,0,0,0,0,0,0,0,0,0,0,0,0,0,0,0
0,0,0,0,0,0,0,0,0,0,0,0,0,0,0,0,0,0
0,0,0,0,0,0,0,0,0,0,0,0,0,0,0,0,0,0
0,0,0,0,0,0,0,0,0,0,0,0,0,0,0,0,0,0
:endlayer
layer: 22
0,0,0,0,0,0,0,0,0,0,0,0,0,0,0,0,0,0
0,0,0,0,0,0,0,0,0,0,0,0,0,0,0,0,0,0
0,0,0,0,0,0,0,0,0,0,0,0,0,0,0,0,0,0
0,0,0,0,0,0,0,0,0,0,0,0,0,0,0,0,0,0
0,0,0,0,0,0,0,0,0,0,0,0,0,0,0,0,0,0
0,0,0,0,0,6,49,1,49,45,1,45,6,0,0,0,0,0
0,0,0,0,0,43,0,0,0,0,0,0,43,0,0,0,0,0
0,0,0,0,0,1,0,0,0,0,0,0,1,0,0,0,0,0
0,0,0,0,0,43,0,0,0,0,0,0,43,0,0,0,0,0
0,0,0,0,0,44,0,28,1,0,0,0,44,0,0,0,0,0
0,0,0,0,0,1,0,0,0,0,0,0,1,0,0,0,0,0
0,0,0,0,0,44,0,0,0,0,0,0,44,0,0,0,0,0
0,0,0,0,0,6,49,1,49,45,1,45,6,0,0,0,0,0
0,0,0,0,0,0,0,0,0,0,0,0,0,0,0,0,0,0
0,0,0,0,0,0,0,0,0,0,0,0,0,0,0,0,0,0
0,0,0,0,0,0,0,0,0,0,0,0,0,0,0,0,0,0
0,0,0,0,0,0,0,0,0,0,0,0,0,0,0,0,0,0
0,0,0,0,0,0,0,0,0,0,0,0,0,0,0,0,0,0
:endlayer
layer: 23
0,0,0,0,0,0,0,0,0,0,0,0,0,0,0,0,0,0
0,0,0,0,0,0,0,0,0,0,0,0,0,0,0,0,0,0
0,0,0,0,0,0,0,0,0,0,0,0,0,0,0,0,0,0
0,0,0,0,0,0,0,0,0,0,0,0,0,0,0,0,0,0
0,0,0,0,0,0,0,0,0,0,0,0,0,0,0,0,0,0
0,0,0,0,0,6,6,1,6,6,1,6,6,0,0,0,0,0
0,0,0,0,0,6,6,6,6,6,6,6,6,0,0,0,0,0
0,0,0,0,0,1,6,1,1,1,1,6,1,0,0,0,0,0
0,0,0,0,0,6,6,0,0,0,1,6,6,0,0,0,0,0
0,0,0,0,0,6,6,0,1,1,1,6,6,0,0,0,0,0
0,0,0,0,0,1,6,28,1,1,1,6,1,0,0,0,0,0
0,0,0,0,0,6,6,6,6,6,6,6,6,0,0,0,0,0
0,0,0,0,0,6,6,1,6,6,1,6,6,0,0,0,0,0
0,0,0,0,0,0,0,0,0,0,0,0,0,0,0,0,0,0
0,0,0,0,0,0,0,0,0,0,0,0,0,0,0,0,0,0
0,0,0,0,0,0,0,0,0,0,0,0,0,0,0,0,0,0
0,0,0,0,0,0,0,0,0,0,0,0,0,0,0,0,0,0
0,0,0,0,0,0,0,0,0,0,0,0,0,0,0,0,0,0
:endlayer
layer: 24
0,0,0,0,0,0,0,0,0,0,0,0,0,0,0,0,0,0
0,0,0,0,0,0,0,0,0,0,0,0,0,0,0,0,0,0
0,0,0,0,0,0,0,0,0,0,0,0,0,0,0,0,0,0
0,0,0,0,0,0,0,0,0,0,0,0,0,0,0,0,0,0
0,0,0,0,0,0,0,0,0,0,0,0,0,0,0,0,0,0
0,0,0,0,0,6,1,1,1,1,1,1,6,0,0,0,0,0
0,0,0,0,0,1,64,0,63,61,0,57,1,0,0,0,0,0
0,0,0,0,0,1,0,0,0,0,0,0,1,0,0,0,0,0
0,0,0,0,0,1,0,0,0,0,0,58,1,0,0,0,0,0
0,0,0,0,0,1,0,0,0,62,0,59,1,0,0,0,0,0
0,0,0,0,0,1,61,0,0,0,0,0,1,0,0,0,0,0
0,0,0,0,0,1,65,0,0,0,0,60,1,0,0,0,0,0
0,0,0,0,0,6,1,1,1,1,1,1,6,0,0,0,0,0
0,0,0,0,0,0,0,0,0,0,0,0,0,0,0,0,0,0
0,0,0,0,0,0,0,0,0,0,0,0,0,0,0,0,0,0
0,0,0,0,0,0,0,0,0,0,0,0,0,0,0,0,0,0
0,0,0,0,0,0,0,0,0,0,0,0,0,0,0,0,0,0
0,0,0,0,0,0,0,0,0,0,0,0,0,0,0,0,0,0
:endlayer
layer: 25
0,0,0,0,0,0,0,0,0,0,0,0,0,0,0,0,0,0
0,0,0,0,0,0,0,0,0,0,0,0,0,0,0,0,0,0
0,0,0,0,0,0,0,0,0,0,0,0,0,0,0,0,0,0
0,0,0,0,0,0,0,0,0,0,0,0,0,0,0,0,0,0
0,0,0,0,0,0,0,0,0,0,0,0,0,0,0,0,0,0
0,0,0,0,0,6,46,1,46,46,1,46,6,0,0,0,0,0
0,0,0,0,0,46,0,0,0,0,61,61,46,0,0,0,0,0
0,0,0,0,0,1,0,0,0,0,0,0,1,0,0,0,0,0
0,0,0,0,0,46,0,0,0,0,0,0,46,0,0,0,0,0
0,0,0,0,0,46,0,0,0,0,0,0,46,0,0,0,0,0
0,0,0,0,0,1,0,0,0,0,0,0,1,0,0,0,0,0
0,0,0,0,0,46,61,0,0,0,0,0,46,0,0,0,0,0
0,0,0,0,0,6,46,1,46,46,1,46,6,0,0,0,0,0
0,0,0,0,0,0,0,0,0,0,0,0,0,0,0,0,0,0
0,0,0,0,0,0,0,0,0,0,0,0,0,0,0,0,0,0
0,0,0,0,0,0,0,0,0,0,0,0,0,0,0,0,0,0
0,0,0,0,0,0,0,0,0,0,0,0,0,0,0,0,0,0
0,0,0,0,0,0,0,0,0,0,0,0,0,0,0,0,0,0
:endlayer
layer: 26
0,0,0,0,0,0,0,0,0,0,0,0,0,0,0,0,0,0
0,0,0,0,0,0,0,0,0,0,0,0,0,0,0,0,0,0
0,0,0,0,0,0,0,0,0,0,0,0,0,0,0,0,0,0
0,0,0,0,0,0,0,0,0,0,0,0,0,0,0,0,0,0
0,0,0,0,0,0,0,0,0,0,0,0,0,0,0,0,0,0
0,0,0,0,0,6,46,1,46,46,1,46,6,0,0,0,0,0
0,0,0,0,0,46,0,0,0,0,0,61,46,0,0,0,0,0
0,0,0,0,0,1,0,0,0,0,0,0,1,0,0,0,0,0
0,0,0,0,0,46,0,0,0,0,0,0,46,0,0,0,0,0
0,0,0,0,0,46,0,0,0,0,0,0,46,0,0,0,0,0
0,0,0,0,0,1,0,0,0,0,0,0,1,0,0,0,0,0
0,0,0,0,0,46,61,0,0,0,61,0,46,0,0,0,0,0
0,0,0,0,0,6,46,1,46,46,1,46,6,0,0,0,0,0
0,0,0,0,0,0,0,0,0,0,0,0,0,0,0,0,0,0
0,0,0,0,0,0,0,0,0,0,0,0,0,0,0,0,0,0
0,0,0,0,0,0,0,0,0,0,0,0,0,0,0,0,0,0
0,0,0,0,0,0,0,0,0,0,0,0,0,0,0,0,0,0
0,0,0,0,0,0,0,0,0,0,0,0,0,0,0,0,0,0
:endlayer
layer: 27
0,0,0,0,0,0,0,0,0,0,0,0,0,0,0,0,0,0
0,0,0,0,0,0,0,0,0,0,0,0,0,0,0,0,0,0
0,0,0,0,0,0,0,0,0,0,0,0,0,0,0,0,0,0
0,0,0,0,0,0,0,0,0,0,0,0,0,0,0,0,0,0
0,0,0,0,0,0,0,0,0,0,0,0,0,0,0,0,0,0
0,0,0,0,0,33,46,6,46,46,6,46,33,0,0,0,0,0
0,0,0,0,0,46,0,0,0,0,61,61,46,0,0,0,0,0
0,0,0,0,0,6,0,0,0,0,0,0,6,0,0,0,0,0
0,0,0,0,0,46,0,0,0,0,0,0,46,0,0,0,0,0
0,0,0,0,0,46,0,0,0,0,0,0,46,0,0,0,0,0
0,0,0,0,0,6,0,0,0,0,0,0,6,0,0,0,0,0
0,0,0,0,0,46,0,0,0,0,61,0,46,0,0,0,0,0
0,0,0,0,0,33,46,6,46,46,6,46,33,0,0,0,0,0
0,0,0,0,0,0,0,0,0,0,0,0,0,0,0,0,0,0
0,0,0,0,0,0,0,0,0,0,0,0,0,0,0,0,0,0
0,0,0,0,0,0,0,0,0,0,0,0,0,0,0,0,0,0
0,0,0,0,0,0,0,0,0,0,0,0,0,0,0,0,0,0
0,0,0,0,0,0,0,0,0,0,0,0,0,0,0,0,0,0
:endlayer
layer: 28
0,0,0,0,0,0,0,0,0,0,0,0,0,0,0,0,0,0
0,0,0,0,0,0,0,0,0,0,0,0,0,0,0,0,0,0
0,0,0,0,0,0,0,0,0,0,0,0,0,0,0,0,0,0
0,0,0,0,0,0,0,0,0,0,0,0,0,0,0,0,0,0
0,0,0,0,0,0,0,0,0,0,0,0,0,0,0,0,0,0
0,0,0,0,0,33,49,6,49,45,6,45,33,0,0,0,0,0
0,0,0,0,0,43,0,0,0,0,0,0,43,0,0,0,0,0
0,0,0,0,0,6,0,0,0,0,0,61,6,0,0,0,0,0
0,0,0,0,0,43,0,0,0,0,0,61,43,0,0,0,0,0
0,0,0,0,0,44,0,0,0,0,0,0,44,0,0,0,0,0
0,0,0,0,0,6,0,0,0,0,0,0,6,0,0,0,0,0
0,0,0,0,0,44,61,0,61,61,0,61,44,0,0,0,0,0
0,0,0,0,0,33,49,6,49,45,6,45,33,0,0,0,0,0
0,0,0,0,0,0,0,0,0,0,0,0,0,0,0,0,0,0
0,0,0,0,0,0,0,0,0,0,0,0,0,0,0,0,0,0
0,0,0,0,0,0,0,0,0,0,0,0,0,0,0,0,0,0
0,0,0,0,0,0,0,0,0,0,0,0,0,0,0,0,0,0
0,0,0,0,0,0,0,0,0,0,0,0,0,0,0,0,0,0
:endlayer
layer: 29
0,0,0,0,0,0,0,0,0,0,0,0,0,0,0,0,0,0
0,0,0,0,0,0,0,0,0,0,0,0,0,0,0,0,0,0
0,0,0,0,0,0,0,0,0,0,0,0,0,0,0,0,0,0
0,0,0,0,0,0,0,0,0,0,0,0,0,0,0,0,0,0
0,0,0,0,0,0,0,0,0,0,0,0,0,0,0,0,0,0
0,0,0,0,0,33,33,6,33,33,6,33,33,0,0,0,0,0
0,0,0,0,0,33,7,7,7,7,6,7,33,0,0,0,0,0
0,0,0,0,0,6,6,6,6,7,6,7,6,0,0,0,0,0
0,0,0,0,0,33,7,7,0,0,6,7,33,0,0,0,0,0
0,0,0,0,0,33,7,6,0,0,7,7,33,0,0,0,0,0
0,0,0,0,0,6,7,6,7,6,6,6,6,0,0,0,0,0
0,0,0,0,0,33,7,6,7,7,7,7,33,0,0,0,0,0
0,0,0,0,0,33,33,6,33,33,6,33,33,0,0,0,0,0
0,0,0,0,0,0,0,0,0,0,0,0,0,0,0,0,0,0
0,0,0,0,0,0,0,0,0,0,0,0,0,0,0,0,0,0
0,0,0,0,0,0,0,0,0,0,0,0,0,0,0,0,0,0
0,0,0,0,0,0,0,0,0,0,0,0,0,0,0,0,0,0
0,0,0,0,0,0,0,0,0,0,0,0,0,0,0,0,0,0
:endlayer
layer: 30
0,0,0,0,0,0,0,0,0,0,0,0,0,0,0,0,0,0
0,0,0,0,0,0,0,0,0,0,0,0,0,0,0,0,0,0
0,0,0,0,0,0,0,0,0,0,0,0,0,0,0,0,0,0
0,0,0,0,0,0,0,0,0,0,0,0,0,0,0,0,0,0
0,0,0,0,31,28,28,28,28,28,28,28,28,29,0,0,0,0
0,0,0,0,31,27,27,27,27,27,27,27,27,29,0,0,0,0
0,0,0,0,31,27,1,0,68,0,0,1,27,29,0,0,0,0
0,0,0,0,31,27,0,0,0,0,0,66,27,29,0,0,0,0
0,0,0,0,31,27,70,0,0,0,0,67,27,29,0,0,0,0
0,0,0,0,31,27,0,0,0,0,0,0,27,29,0,0,0,0
0,0,0,0,31,27,71,0,0,0,0,0,27,29,0,0,0,0
0,0,0,0,31,27,1,0,69,0,0,1,27,29,0,0,0,0
0,0,0,0,31,27,27,27,27,27,27,27,27,29,0,0,0,0
0,0,0,0,30,30,30,30,30,30,30,30,30,29,0,0,0,0
0,0,0,0,0,0,0,0,0,0,0,0,0,0,0,0,0,0
0,0,0,0,0,0,0,0,0,0,0,0,0,0,0,0,0,0
0,0,0,0,0,0,0,0,0,0,0,0,0,0,0,0,0,0
0,0,0,0,0,0,0,0,0,0,0,0,0,0,0,0,0,0
:endlayer
layer: 31
0,0,0,0,0,0,0,0,0,0,0,0,0,0,0,0,0,0
0,0,0,0,0,0,0,0,0,0,0,0,0,0,0,0,0,0
0,0,0,0,0,0,0,0,0,0,0,0,0,0,0,0,0,0
0,0,0,0,0,0,0,0,0,0,0,0,0,0,0,0,0,0
0,0,0,0,0,0,0,0,0,0,0,0,0,0,0,0,0,0
0,0,0,0,0,31,28,28,28,28,28,28,29,0,0,0,0,0
0,0,0,0,0,31,1,0,0,0,0,1,29,0,0,0,0,0
0,0,0,0,0,31,0,0,0,0,0,0,29,0,0,0,0,0
0,0,0,0,0,31,0,0,0,0,0,0,29,0,0,0,0,0
0,0,0,0,0,31,0,0,0,0,0,0,29,0,0,0,0,0
0,0,0,0,0,31,0,0,0,0,0,0,29,0,0,0,0,0
0,0,0,0,0,31,1,0,0,0,0,1,29,0,0,0,0,0
0,0,0,0,0,31,30,30,30,30,30,30,29,0,0,0,0,0
0,0,0,0,0,0,0,0,0,0,0,0,0,0,0,0,0,0
0,0,0,0,0,0,0,0,0,0,0,0,0,0,0,0,0,0
0,0,0,0,0,0,0,0,0,0,0,0,0,0,0,0,0,0
0,0,0,0,0,0,0,0,0,0,0,0,0,0,0,0,0,0
0,0,0,0,0,0,0,0,0,0,0,0,0,0,0,0,0,0
:endlayer
layer: 32
0,0,0,0,0,0,0,0,0,0,0,0,0,0,0,0,0,0
0,0,0,0,0,0,0,0,0,0,0,0,0,0,0,0,0,0
0,0,0,0,0,0,0,0,0,0,0,0,0,0,0,0,0,0
0,0,0,0,0,0,0,0,0,0,0,0,0,0,0,0,0,0
0,0,0,0,0,0,0,0,0,0,0,0,0,0,0,0,0,0
0,0,0,0,0,0,0,0,0,0,0,0,0,0,0,0,0,0
0,0,0,0,0,0,28,28,28,28,28,29,0,0,0,0,0,0
0,0,0,0,0,0,31,6,0,0,6,29,0,0,0,0,0,0
0,0,0,0,0,0,31,0,0,0,0,29,0,0,0,0,0,0
0,0,0,0,0,0,31,0,0,0,0,29,0,0,0,0,0,0
0,0,0,0,0,0,31,6,0,0,6,29,0,0,0,0,0,0
0,0,0,0,0,0,31,30,30,30,30,29,0,0,0,0,0,0
0,0,0,0,0,0,0,0,0,0,0,0,0,0,0,0,0,0
0,0,0,0,0,0,0,0,0,0,0,0,0,0,0,0,0,0
0,0,0,0,0,0,0,0,0,0,0,0,0,0,0,0,0,0
0,0,0,0,0,0,0,0,0,0,0,0,0,0,0,0,0,0
0,0,0,0,0,0,0,0,0,0,0,0,0,0,0,0,0,0
0,0,0,0,0,0,0,0,0,0,0,0,0,0,0,0,0,0
:endlayer
layer: 33
0,0,0,0,0,0,0,0,0,0,0,0,0,0,0,0,0,0
0,0,0,0,0,0,0,0,0,0,0,0,0,0,0,0,0,0
0,0,0,0,0,0,0,0,0,0,0,0,0,0,0,0,0,0
0,0,0,0,0,0,0,0,0,0,0,0,0,0,0,0,0,0
0,0,0,0,0,0,0,0,0,0,0,0,0,0,0,0,0,0
0,0,0,0,0,0,0,0,0,0,0,0,0,0,0,0,0,0
0,0,0,0,0,0,0,0,0,0,0,0,0,0,0,0,0,0
0,0,0,0,0,0,0,28,28,28,28,0,0,0,0,0,0,0
0,0,0,0,0,0,0,31,8,8,29,0,0,0,0,0,0,0
0,0,0,0,0,0,0,31,8,8,29,0,0,0,0,0,0,0
0,0,0,0,0,0,0,30,30,30,30,0,0,0,0,0,0,0
0,0,0,0,0,0,0,0,0,0,0,0,0,0,0,0,0,0
0,0,0,0,0,0,0,0,0,0,0,0,0,0,0,0,0,0
0,0,0,0,0,0,0,0,0,0,0,0,0,0,0,0,0,0
0,0,0,0,0,0,0,0,0,0,0,0,0,0,0,0,0,0
0,0,0,0,0,0,0,0,0,0,0,0,0,0,0,0,0,0
0,0,0,0,0,0,0,0,0,0,0,0,0,0,0,0,0,0
0,0,0,0,0,0,0,0,0,0,0,0,0,0,0,0,0,0
:endlayer
layer: 34
0,0,0,0,0,0,0,0,0,0,0,0,0,0,0,0,0,0
0,0,0,0,0,0,0,0,0,0,0,0,0,0,0,0,0,0
0,0,0,0,0,0,0,0,0,0,0,0,0,0,0,0,0,0
0,0,0,0,0,0,0,0,0,0,0,0,0,0,0,0,0,0
0,0,0,0,0,0,0,0,0,0,0,0,0,0,0,0,0,0
0,0,0,0,0,0,0,0,0,0,0,0,0,0,0,0,0,0
0,0,0,0,0,0,0,0,0,0,0,0,0,0,0,0,0,0
0,0,0,0,0,0,0,0,0,0,0,0,0,0,0,0,0,0
0,0,0,0,0,0,0,0,8,8,0,0,0,0,0,0,0,0
0,0,0,0,0,0,0,0,8,8,0,0,0,0,0,0,0,0
0,0,0,0,0,0,0,0,0,0,0,0,0,0,0,0,0,0
0,0,0,0,0,0,0,0,0,0,0,0,0,0,0,0,0,0
0,0,0,0,0,0,0,0,0,0,0,0,0,0,0,0,0,0
0,0,0,0,0,0,0,0,0,0,0,0,0,0,0,0,0,0
0,0,0,0,0,0,0,0,0,0,0,0,0,0,0,0,0,0
0,0,0,0,0,0,0,0,0,0,0,0,0,0,0,0,0,0
0,0,0,0,0,0,0,0,0,0,0,0,0,0,0,0,0,0
0,0,0,0,0,0,0,0,0,0,0,0,0,0,0,0,0,0
:endlayer
layer: 35
0,0,0,0,0,0,0,0,0,0,0,0,0,0,0,0,0,0
0,0,0,0,0,0,0,0,0,0,0,0,0,0,0,0,0,0
0,0,0,0,0,0,0,0,0,0,0,0,0,0,0,0,0,0
0,0,0,0,0,0,0,0,0,0,0,0,0,0,0,0,0,0
0,0,0,0,0,0,0,0,0,0,0,0,0,0,0,0,0,0
0,0,0,0,0,0,0,0,0,0,0,0,0,0,0,0,0,0
0,0,0,0,0,0,0,0,0,0,0,0,0,0,0,0,0,0
0,0,0,0,0,0,0,0,0,0,0,0,0,0,0,0,0,0
0,0,0,0,0,0,0,0,0,0,0,0,0,0,0,0,0,0
0,0,0,0,0,0,0,0,0,0,0,0,0,0,0,0,0,0
0,0,0,0,0,0,0,0,0,0,0,0,0,0,0,0,0,0
0,0,0,0,0,0,0,0,0,0,0,0,0,0,0,0,0,0
0,0,0,0,0,0,0,0,0,0,0,0,0,0,0,0,0,0
0,0,0,0,0,0,0,0,0,0,0,0,0,0,0,0,0,0
0,0,0,0,0,0,0,0,0,0,0,0,0,0,0,0,0,0
0,0,0,0,0,0,0,0,0,0,0,0,0,0,0,0,0,0
0,0,0,0,0,0,0,0,0,0,0,0,0,0,0,0,0,0
0,0,0,0,0,0,0,0,0,0,0,0,0,0,0,0,0,0
:endlayer
layer: 36
0,0,0,0,0,0,0,0,0,0,0,0,0,0,0,0,0,0
0,0,0,0,0,0,0,0,0,0,0,0,0,0,0,0,0,0
0,0,0,0,0,0,0,0,0,0,0,0,0,0,0,0,0,0
0,0,0,0,0,0,0,0,0,0,0,0,0,0,0,0,0,0
0,0,0,0,0,0,0,0,0,0,0,0,0,0,0,0,0,0
0,0,0,0,0,0,0,0,0,0,0,0,0,0,0,0,0,0
0,0,0,0,0,0,0,0,0,0,0,0,0,0,0,0,0,0
0,0,0,0,0,0,0,0,0,0,0,0,0,0,0,0,0,0
0,0,0,0,0,0,0,0,0,0,0,0,0,0,0,0,0,0
0,0,0,0,0,0,0,0,0,0,0,0,0,0,0,0,0,0
0,0,0,0,0,0,0,0,0,0,0,0,0,0,0,0,0,0
0,0,0,0,0,0,0,0,0,0,0,0,0,0,0,0,0,0
0,0,0,0,0,0,0,0,0,0,0,0,0,0,0,0,0,0
0,0,0,0,0,0,0,0,0,0,0,0,0,0,0,0,0,0
0,0,0,0,0,0,0,0,0,0,0,0,0,0,0,0,0,0
0,0,0,0,0,0,0,0,0,0,0,0,0,0,0,0,0,0
0,0,0,0,0,0,0,0,0,0,0,0,0,0,0,0,0,0
0,0,0,0,0,0,0,0,0,0,0,0,0,0,0,0,0,0
:endlayer
layer: 37
0,0,0,0,0,0,0,0,0,0,0,0,0,0,0,0,0,0
0,0,0,0,0,0,0,0,0,0,0,0,0,0,0,0,0,0
0,0,0,0,0,0,0,0,0,0,0,0,0,0,0,0,0,0
0,0,0,0,0,0,0,0,0,0,0,0,0,0,0,0,0,0
0,0,0,0,0,0,0,0,0,0,0,0,0,0,0,0,0,0
0,0,0,0,0,0,0,0,0,0,0,0,0,0,0,0,0,0
0,0,0,0,0,0,0,0,0,0,0,0,0,0,0,0,0,0
0,0,0,0,0,0,0,0,0,0,0,0,0,0,0,0,0,0
0,0,0,0,0,0,0,0,0,0,0,0,0,0,0,0,0,0
0,0,0,0,0,0,0,0,0,0,0,0,0,0,0,0,0,0
0,0,0,0,0,0,0,0,0,0,0,0,0,0,0,0,0,0
0,0,0,0,0,0,0,0,0,0,0,0,0,0,0,0,0,0
0,0,0,0,0,0,0,0,0,0,0,0,0,0,0,0,0,0
0,0,0,0,0,0,0,0,0,0,0,0,0,0,0,0,0,0
0,0,0,0,0,0,0,0,0,0,0,0,0,0,0,0,0,0
0,0,0,0,0,0,0,0,0,0,0,0,0,0,0,0,0,0
0,0,0,0,0,0,0,0,0,0,0,0,0,0,0,0,0,0
0,0,0,0,0,0,0,0,0,0,0,0,0,0,0,0,0,0
:endlayer
layer: 38
0,0,0,0,0,0,0,0,0,0,0,0,0,0,0,0,0,0
0,0,0,0,0,0,0,0,0,0,0,0,0,0,0,0,0,0
0,0,0,0,0,0,0,0,0,0,0,0,0,0,0,0,0,0
0,0,0,0,0,0,0,0,0,0,0,0,0,0,0,0,0,0
0,0,0,0,0,0,0,0,0,0,0,0,0,0,0,0,0,0
0,0,0,0,0,0,0,0,0,0,0,0,0,0,0,0,0,0
0,0,0,0,0,0,0,0,0,0,0,0,0,0,0,0,0,0
0,0,0,0,0,0,0,0,0,0,0,0,0,0,0,0,0,0
0,0,0,0,0,0,0,0,0,0,0,0,0,0,0,0,0,0
0,0,0,0,0,0,0,0,0,0,0,0,0,0,0,0,0,0
0,0,0,0,0,0,0,0,0,0,0,0,0,0,0,0,0,0
0,0,0,0,0,0,0,0,0,0,0,0,0,0,0,0,0,0
0,0,0,0,0,0,0,0,0,0,0,0,0,0,0,0,0,0
0,0,0,0,0,0,0,0,0,0,0,0,0,0,0,0,0,0
0,0,0,0,0,0,0,0,0,0,0,0,0,0,0,0,0,0
0,0,0,0,0,0,0,0,0,0,0,0,0,0,0,0,0,0
0,0,0,0,0,0,0,0,0,0,0,0,0,0,0,0,0,0
0,0,0,0,0,0,0,0,0,0,0,0,0,0,0,0,0,0
:endlayer
layer: 39
0,0,0,0,0,0,0,0,0,0,0,0,0,0,0,0,0,0
0,0,0,0,0,0,0,0,0,0,0,0,0,0,0,0,0,0
0,0,0,0,0,0,0,0,0,0,0,0,0,0,0,0,0,0
0,0,0,0,0,0,0,0,0,0,0,0,0,0,0,0,0,0
0,0,0,0,0,0,0,0,0,0,0,0,0,0,0,0,0,0
0,0,0,0,0,0,0,0,0,0,0,0,0,0,0,0,0,0
0,0,0,0,0,0,0,0,0,0,0,0,0,0,0,0,0,0
0,0,0,0,0,0,0,0,0,0,0,0,0,0,0,0,0,0
0,0,0,0,0,0,0,0,0,0,0,0,0,0,0,0,0,0
0,0,0,0,0,0,0,0,0,0,0,0,0,0,0,0,0,0
0,0,0,0,0,0,0,0,0,0,0,0,0,0,0,0,0,0
0,0,0,0,0,0,0,0,0,0,0,0,0,0,0,0,0,0
0,0,0,0,0,0,0,0,0,0,0,0,0,0,0,0,0,0
0,0,0,0,0,0,0,0,0,0,0,0,0,0,0,0,0,0
0,0,0,0,0,0,0,0,0,0,0,0,0,0,0,0,0,0
0,0,0,0,0,0,0,0,0,0,0,0,0,0,0,0,0,0
0,0,0,0,0,0,0,0,0,0,0,0,0,0,0,0,0,0
0,0,0,0,0,0,0,0,0,0,0,0,0,0,0,0,0,0
:endlayer
layer: 40
0,0,0,0,0,0,0,0,0,0,0,0,0,0,0,0,0,0
0,0,0,0,0,0,0,0,0,0,0,0,0,0,0,0,0,0
0,0,0,0,0,0,0,0,0,0,0,0,0,0,0,0,0,0
0,0,0,0,0,0,0,0,0,0,0,0,0,0,0,0,0,0
0,0,0,0,0,0,0,0,0,0,0,0,0,0,0,0,0,0
0,0,0,0,0,0,0,0,0,0,0,0,0,0,0,0,0,0
0,0,0,0,0,0,0,0,0,0,0,0,0,0,0,0,0,0
0,0,0,0,0,0,0,0,0,0,0,0,0,0,0,0,0,0
0,0,0,0,0,0,0,0,0,0,0,0,0,0,0,0,0,0
0,0,0,0,0,0,0,0,0,0,0,0,0,0,0,0,0,0
0,0,0,0,0,0,0,0,0,0,0,0,0,0,0,0,0,0
0,0,0,0,0,0,0,0,0,0,0,0,0,0,0,0,0,0
0,0,0,0,0,0,0,0,0,0,0,0,0,0,0,0,0,0
0,0,0,0,0,0,0,0,0,0,0,0,0,0,0,0,0,0
0,0,0,0,0,0,0,0,0,0,0,0,0,0,0,0,0,0
0,0,0,0,0,0,0,0,0,0,0,0,0,0,0,0,0,0
0,0,0,0,0,0,0,0,0,0,0,0,0,0,0,0,0,0
0,0,0,0,0,0,0,0,0,0,0,0,0,0,0,0,0,0
:endlayer
layer: 41
0,0,0,0,0,0,0,0,0,0,0,0,0,0,0,0,0,0
0,0,0,0,0,0,0,0,0,0,0,0,0,0,0,0,0,0
0,0,0,0,0,0,0,0,0,0,0,0,0,0,0,0,0,0
0,0,0,0,0,0,0,0,0,0,0,0,0,0,0,0,0,0
0,0,0,0,0,0,0,0,0,0,0,0,0,0,0,0,0,0
0,0,0,0,0,0,0,0,0,0,0,0,0,0,0,0,0,0
0,0,0,0,0,0,0,0,0,0,0,0,0,0,0,0,0,0
0,0,0,0,0,0,0,0,0,0,0,0,0,0,0,0,0,0
0,0,0,0,0,0,0,0,0,0,0,0,0,0,0,0,0,0
0,0,0,0,0,0,0,0,0,0,0,0,0,0,0,0,0,0
0,0,0,0,0,0,0,0,0,0,0,0,0,0,0,0,0,0
0,0,0,0,0,0,0,0,0,0,0,0,0,0,0,0,0,0
0,0,0,0,0,0,0,0,0,0,0,0,0,0,0,0,0,0
0,0,0,0,0,0,0,0,0,0,0,0,0,0,0,0,0,0
0,0,0,0,0,0,0,0,0,0,0,0,0,0,0,0,0,0
0,0,0,0,0,0,0,0,0,0,0,0,0,0,0,0,0,0
0,0,0,0,0,0,0,0,0,0,0,0,0,0,0,0,0,0
0,0,0,0,0,0,0,0,0,0,0,0,0,0,0,0,0,0
:endlayer
layer: 42
0,0,0,0,0,0,0,0,0,0,0,0,0,0,0,0,0,0
0,0,0,0,0,0,0,0,0,0,0,0,0,0,0,0,0,0
0,0,0,0,0,0,0,0,0,0,0,0,0,0,0,0,0,0
0,0,0,0,0,0,0,0,0,0,0,0,0,0,0,0,0,0
0,0,0,0,0,0,0,0,0,0,0,0,0,0,0,0,0,0
0,0,0,0,0,0,0,0,0,0,0,0,0,0,0,0,0,0
0,0,0,0,0,0,0,0,0,0,0,0,0,0,0,0,0,0
0,0,0,0,0,0,0,0,0,0,0,0,0,0,0,0,0,0
0,0,0,0,0,0,0,0,0,0,0,0,0,0,0,0,0,0
0,0,0,0,0,0,0,0,0,0,0,0,0,0,0,0,0,0
0,0,0,0,0,0,0,0,0,0,0,0,0,0,0,0,0,0
0,0,0,0,0,0,0,0,0,0,0,0,0,0,0,0,0,0
0,0,0,0,0,0,0,0,0,0,0,0,0,0,0,0,0,0
0,0,0,0,0,0,0,0,0,0,0,0,0,0,0,0,0,0
0,0,0,0,0,0,0,0,0,0,0,0,0,0,0,0,0,0
0,0,0,0,0,0,0,0,0,0,0,0,0,0,0,0,0,0
0,0,0,0,0,0,0,0,0,0,0,0,0,0,0,0,0,0
0,0,0,0,0,0,0,0,0,0,0,0,0,0,0,0,0,0
:endlayer
layer: 43
0,0,0,0,0,0,0,0,0,0,0,0,0,0,0,0,0,0
0,0,0,0,0,0,0,0,0,0,0,0,0,0,0,0,0,0
0,0,0,0,0,0,0,0,0,0,0,0,0,0,0,0,0,0
0,0,0,0,0,0,0,0,0,0,0,0,0,0,0,0,0,0
0,0,0,0,0,0,0,0,0,0,0,0,0,0,0,0,0,0
0,0,0,0,0,0,0,0,0,0,0,0,0,0,0,0,0,0
0,0,0,0,0,0,0,0,0,0,0,0,0,0,0,0,0,0
0,0,0,0,0,0,0,0,0,0,0,0,0,0,0,0,0,0
0,0,0,0,0,0,0,0,0,0,0,0,0,0,0,0,0,0
0,0,0,0,0,0,0,0,0,0,0,0,0,0,0,0,0,0
0,0,0,0,0,0,0,0,0,0,0,0,0,0,0,0,0,0
0,0,0,0,0,0,0,0,0,0,0,0,0,0,0,0,0,0
0,0,0,0,0,0,0,0,0,0,0,0,0,0,0,0,0,0
0,0,0,0,0,0,0,0,0,0,0,0,0,0,0,0,0,0
0,0,0,0,0,0,0,0,0,0,0,0,0,0,0,0,0,0
0,0,0,0,0,0,0,0,0,0,0,0,0,0,0,0,0,0
0,0,0,0,0,0,0,0,0,0,0,0,0,0,0,0,0,0
0,0,0,0,0,0,0,0,0,0,0,0,0,0,0,0,0,0
:endlayer
layer: 44
0,0,0,0,0,0,0,0,0,0,0,0,0,0,0,0,0,0
0,0,0,0,0,0,0,0,0,0,0,0,0,0,0,0,0,0
0,0,0,0,0,0,0,0,0,0,0,0,0,0,0,0,0,0
0,0,0,0,0,0,0,0,0,0,0,0,0,0,0,0,0,0
0,0,0,0,0,0,0,0,0,0,0,0,0,0,0,0,0,0
0,0,0,0,0,0,0,0,0,0,0,0,0,0,0,0,0,0
0,0,0,0,0,0,0,0,0,0,0,0,0,0,0,0,0,0
0,0,0,0,0,0,0,0,0,0,0,0,0,0,0,0,0,0
0,0,0,0,0,0,0,0,0,0,0,0,0,0,0,0,0,0
0,0,0,0,0,0,0,0,0,0,0,0,0,0,0,0,0,0
0,0,0,0,0,0,0,0,0,0,0,0,0,0,0,0,0,0
0,0,0,0,0,0,0,0,0,0,0,0,0,0,0,0,0,0
0,0,0,0,0,0,0,0,0,0,0,0,0,0,0,0,0,0
0,0,0,0,0,0,0,0,0,0,0,0,0,0,0,0,0,0
0,0,0,0,0,0,0,0,0,0,0,0,0,0,0,0,0,0
0,0,0,0,0,0,0,0,0,0,0,0,0,0,0,0,0,0
0,0,0,0,0,0,0,0,0,0,0,0,0,0,0,0,0,0
0,0,0,0,0,0,0,0,0,0,0,0,0,0,0,0,0,0
:endlayer
layer: 45
0,0,0,0,0,0,0,0,0,0,0,0,0,0,0,0,0,0
0,0,0,0,0,0,0,0,0,0,0,0,0,0,0,0,0,0
0,0,0,0,0,0,0,0,0,0,0,0,0,0,0,0,0,0
0,0,0,0,0,0,0,0,0,0,0,0,0,0,0,0,0,0
0,0,0,0,0,0,0,0,0,0,0,0,0,0,0,0,0,0
0,0,0,0,0,0,0,0,0,0,0,0,0,0,0,0,0,0
0,0,0,0,0,0,0,0,0,0,0,0,0,0,0,0,0,0
0,0,0,0,0,0,0,0,0,0,0,0,0,0,0,0,0,0
0,0,0,0,0,0,0,0,0,0,0,0,0,0,0,0,0,0
0,0,0,0,0,0,0,0,0,0,0,0,0,0,0,0,0,0
0,0,0,0,0,0,0,0,0,0,0,0,0,0,0,0,0,0
0,0,0,0,0,0,0,0,0,0,0,0,0,0,0,0,0,0
0,0,0,0,0,0,0,0,0,0,0,0,0,0,0,0,0,0
0,0,0,0,0,0,0,0,0,0,0,0,0,0,0,0,0,0
0,0,0,0,0,0,0,0,0,0,0,0,0,0,0,0,0,0
0,0,0,0,0,0,0,0,0,0,0,0,0,0,0,0,0,0
0,0,0,0,0,0,0,0,0,0,0,0,0,0,0,0,0,0
0,0,0,0,0,0,0,0,0,0,0,0,0,0,0,0,0,0
:endlayer
layer: 46
0,0,0,0,0,0,0,0,0,0,0,0,0,0,0,0,0,0
0,0,0,0,0,0,0,0,0,0,0,0,0,0,0,0,0,0
0,0,0,0,0,0,0,0,0,0,0,0,0,0,0,0,0,0
0,0,0,0,0,0,0,0,0,0,0,0,0,0,0,0,0,0
0,0,0,0,0,0,0,0,0,0,0,0,0,0,0,0,0,0
0,0,0,0,0,0,0,0,0,0,0,0,0,0,0,0,0,0
0,0,0,0,0,0,0,0,0,0,0,0,0,0,0,0,0,0
0,0,0,0,0,0,0,0,0,0,0,0,0,0,0,0,0,0
0,0,0,0,0,0,0,0,0,0,0,0,0,0,0,0,0,0
0,0,0,0,0,0,0,0,0,0,0,0,0,0,0,0,0,0
0,0,0,0,0,0,0,0,0,0,0,0,0,0,0,0,0,0
0,0,0,0,0,0,0,0,0,0,0,0,0,0,0,0,0,0
0,0,0,0,0,0,0,0,0,0,0,0,0,0,0,0,0,0
0,0,0,0,0,0,0,0,0,0,0,0,0,0,0,0,0,0
0,0,0,0,0,0,0,0,0,0,0,0,0,0,0,0,0,0
0,0,0,0,0,0,0,0,0,0,0,0,0,0,0,0,0,0
0,0,0,0,0,0,0,0,0,0,0,0,0,0,0,0,0,0
0,0,0,0,0,0,0,0,0,0,0,0,0,0,0,0,0,0
:endlayer
layer: 47
0,0,0,0,0,0,0,0,0,0,0,0,0,0,0,0,0,0
0,0,0,0,0,0,0,0,0,0,0,0,0,0,0,0,0,0
0,0,0,0,0,0,0,0,0,0,0,0,0,0,0,0,0,0
0,0,0,0,0,0,0,0,0,0,0,0,0,0,0,0,0,0
0,0,0,0,0,0,0,0,0,0,0,0,0,0,0,0,0,0
0,0,0,0,0,0,0,0,0,0,0,0,0,0,0,0,0,0
0,0,0,0,0,0,0,0,0,0,0,0,0,0,0,0,0,0
0,0,0,0,0,0,0,0,0,0,0,0,0,0,0,0,0,0
0,0,0,0,0,0,0,0,0,0,0,0,0,0,0,0,0,0
0,0,0,0,0,0,0,0,0,0,0,0,0,0,0,0,0,0
0,0,0,0,0,0,0,0,0,0,0,0,0,0,0,0,0,0
0,0,0,0,0,0,0,0,0,0,0,0,0,0,0,0,0,0
0,0,0,0,0,0,0,0,0,0,0,0,0,0,0,0,0,0
0,0,0,0,0,0,0,0,0,0,0,0,0,0,0,0,0,0
0,0,0,0,0,0,0,0,0,0,0,0,0,0,0,0,0,0
0,0,0,0,0,0,0,0,0,0,0,0,0,0,0,0,0,0
0,0,0,0,0,0,0,0,0,0,0,0,0,0,0,0,0,0
0,0,0,0,0,0,0,0,0,0,0,0,0,0,0,0,0,0
:endlayer
layer: 48
0,0,0,0,0,0,0,0,0,0,0,0,0,0,0,0,0,0
0,0,0,0,0,0,0,0,0,0,0,0,0,0,0,0,0,0
0,0,0,0,0,0,0,0,0,0,0,0,0,0,0,0,0,0
0,0,0,0,0,0,0,0,0,0,0,0,0,0,0,0,0,0
0,0,0,0,0,0,0,0,0,0,0,0,0,0,0,0,0,0
0,0,0,0,0,0,0,0,0,0,0,0,0,0,0,0,0,0
0,0,0,0,0,0,0,0,0,0,0,0,0,0,0,0,0,0
0,0,0,0,0,0,0,0,0,0,0,0,0,0,0,0,0,0
0,0,0,0,0,0,0,0,0,0,0,0,0,0,0,0,0,0
0,0,0,0,0,0,0,0,0,0,0,0,0,0,0,0,0,0
0,0,0,0,0,0,0,0,0,0,0,0,0,0,0,0,0,0
0,0,0,0,0,0,0,0,0,0,0,0,0,0,0,0,0,0
0,0,0,0,0,0,0,0,0,0,0,0,0,0,0,0,0,0
0,0,0,0,0,0,0,0,0,0,0,0,0,0,0,0,0,0
0,0,0,0,0,0,0,0,0,0,0,0,0,0,0,0,0,0
0,0,0,0,0,0,0,0,0,0,0,0,0,0,0,0,0,0
0,0,0,0,0,0,0,0,0,0,0,0,0,0,0,0,0,0
0,0,0,0,0,0,0,0,0,0,0,0,0,0,0,0,0,0
:endlayer
layer: 49
0,0,0,0,0,0,0,0,0,0,0,0,0,0,0,0,0,0
0,0,0,0,0,0,0,0,0,0,0,0,0,0,0,0,0,0
0,0,0,0,0,0,0,0,0,0,0,0,0,0,0,0,0,0
0,0,0,0,0,0,0,0,0,0,0,0,0,0,0,0,0,0
0,0,0,0,0,0,0,0,0,0,0,0,0,0,0,0,0,0
0,0,0,0,0,0,0,0,0,0,0,0,0,0,0,0,0,0
0,0,0,0,0,0,0,0,0,0,0,0,0,0,0,0,0,0
0,0,0,0,0,0,0,0,0,0,0,0,0,0,0,0,0,0
0,0,0,0,0,0,0,0,0,0,0,0,0,0,0,0,0,0
0,0,0,0,0,0,0,0,0,0,0,0,0,0,0,0,0,0
0,0,0,0,0,0,0,0,0,0,0,0,0,0,0,0,0,0
0,0,0,0,0,0,0,0,0,0,0,0,0,0,0,0,0,0
0,0,0,0,0,0,0,0,0,0,0,0,0,0,0,0,0,0
0,0,0,0,0,0,0,0,0,0,0,0,0,0,0,0,0,0
0,0,0,0,0,0,0,0,0,0,0,0,0,0,0,0,0,0
0,0,0,0,0,0,0,0,0,0,0,0,0,0,0,0,0,0
0,0,0,0,0,0,0,0,0,0,0,0,0,0,0,0,0,0
0,0,0,0,0,0,0,0,0,0,0,0,0,0,0,0,0,0
:endlayer
layer: 50
0,0,0,0,0,0,0,0,0,0,0,0,0,0,0,0,0,0
0,0,0,0,0,0,0,0,0,0,0,0,0,0,0,0,0,0
0,0,0,0,0,0,0,0,0,0,0,0,0,0,0,0,0,0
0,0,0,0,0,0,0,0,0,0,0,0,0,0,0,0,0,0
0,0,0,0,0,0,0,0,0,0,0,0,0,0,0,0,0,0
0,0,0,0,0,0,0,0,0,0,0,0,0,0,0,0,0,0
0,0,0,0,0,0,0,0,0,0,0,0,0,0,0,0,0,0
0,0,0,0,0,0,0,0,0,0,0,0,0,0,0,0,0,0
0,0,0,0,0,0,0,0,0,0,0,0,0,0,0,0,0,0
0,0,0,0,0,0,0,0,0,0,0,0,0,0,0,0,0,0
0,0,0,0,0,0,0,0,0,0,0,0,0,0,0,0,0,0
0,0,0,0,0,0,0,0,0,0,0,0,0,0,0,0,0,0
0,0,0,0,0,0,0,0,0,0,0,0,0,0,0,0,0,0
0,0,0,0,0,0,0,0,0,0,0,0,0,0,0,0,0,0
0,0,0,0,0,0,0,0,0,0,0,0,0,0,0,0,0,0
0,0,0,0,0,0,0,0,0,0,0,0,0,0,0,0,0,0
0,0,0,0,0,0,0,0,0,0,0,0,0,0,0,0,0,0
0,0,0,0,0,0,0,0,0,0,0,0,0,0,0,0,0,0
:endlayer
layer: 51
0,0,0,0,0,0,0,0,0,0,0,0,0,0,0,0,0,0
0,0,0,0,0,0,0,0,0,0,0,0,0,0,0,0,0,0
0,0,0,0,0,0,0,0,0,0,0,0,0,0,0,0,0,0
0,0,0,0,0,0,0,0,0,0,0,0,0,0,0,0,0,0
0,0,0,0,0,0,0,0,0,0,0,0,0,0,0,0,0,0
0,0,0,0,0,0,0,0,0,0,0,0,0,0,0,0,0,0
0,0,0,0,0,0,0,0,0,0,0,0,0,0,0,0,0,0
0,0,0,0,0,0,0,0,0,0,0,0,0,0,0,0,0,0
0,0,0,0,0,0,0,0,0,0,0,0,0,0,0,0,0,0
0,0,0,0,0,0,0,0,0,0,0,0,0,0,0,0,0,0
0,0,0,0,0,0,0,0,0,0,0,0,0,0,0,0,0,0
0,0,0,0,0,0,0,0,0,0,0,0,0,0,0,0,0,0
0,0,0,0,0,0,0,0,0,0,0,0,0,0,0,0,0,0
0,0,0,0,0,0,0,0,0,0,0,0,0,0,0,0,0,0
0,0,0,0,0,0,0,0,0,0,0,0,0,0,0,0,0,0
0,0,0,0,0,0,0,0,0,0,0,0,0,0,0,0,0,0
0,0,0,0,0,0,0,0,0,0,0,0,0,0,0,0,0,0
0,0,0,0,0,0,0,0,0,0,0,0,0,0,0,0,0,0
:endlayer
layer: 52
0,0,0,0,0,0,0,0,0,0,0,0,0,0,0,0,0,0
0,0,0,0,0,0,0,0,0,0,0,0,0,0,0,0,0,0
0,0,0,0,0,0,0,0,0,0,0,0,0,0,0,0,0,0
0,0,0,0,0,0,0,0,0,0,0,0,0,0,0,0,0,0
0,0,0,0,0,0,0,0,0,0,0,0,0,0,0,0,0,0
0,0,0,0,0,0,0,0,0,0,0,0,0,0,0,0,0,0
0,0,0,0,0,0,0,0,0,0,0,0,0,0,0,0,0,0
0,0,0,0,0,0,0,0,0,0,0,0,0,0,0,0,0,0
0,0,0,0,0,0,0,0,0,0,0,0,0,0,0,0,0,0
0,0,0,0,0,0,0,0,0,0,0,0,0,0,0,0,0,0
0,0,0,0,0,0,0,0,0,0,0,0,0,0,0,0,0,0
0,0,0,0,0,0,0,0,0,0,0,0,0,0,0,0,0,0
0,0,0,0,0,0,0,0,0,0,0,0,0,0,0,0,0,0
0,0,0,0,0,0,0,0,0,0,0,0,0,0,0,0,0,0
0,0,0,0,0,0,0,0,0,0,0,0,0,0,0,0,0,0
0,0,0,0,0,0,0,0,0,0,0,0,0,0,0,0,0,0
0,0,0,0,0,0,0,0,0,0,0,0,0,0,0,0,0,0
0,0,0,0,0,0,0,0,0,0,0,0,0,0,0,0,0,0
:endlayer
layer: 53
0,0,0,0,0,0,0,0,0,0,0,0,0,0,0,0,0,0
0,0,0,0,0,0,0,0,0,0,0,0,0,0,0,0,0,0
0,0,0,0,0,0,0,0,0,0,0,0,0,0,0,0,0,0
0,0,0,0,0,0,0,0,0,0,0,0,0,0,0,0,0,0
0,0,0,0,0,0,0,0,0,0,0,0,0,0,0,0,0,0
0,0,0,0,0,0,0,0,0,0,0,0,0,0,0,0,0,0
0,0,0,0,0,0,0,0,0,0,0,0,0,0,0,0,0,0
0,0,0,0,0,0,0,0,0,0,0,0,0,0,0,0,0,0
0,0,0,0,0,0,0,0,0,0,0,0,0,0,0,0,0,0
0,0,0,0,0,0,0,0,0,0,0,0,0,0,0,0,0,0
0,0,0,0,0,0,0,0,0,0,0,0,0,0,0,0,0,0
0,0,0,0,0,0,0,0,0,0,0,0,0,0,0,0,0,0
0,0,0,0,0,0,0,0,0,0,0,0,0,0,0,0,0,0
0,0,0,0,0,0,0,0,0,0,0,0,0,0,0,0,0,0
0,0,0,0,0,0,0,0,0,0,0,0,0,0,0,0,0,0
0,0,0,0,0,0,0,0,0,0,0,0,0,0,0,0,0,0
0,0,0,0,0,0,0,0,0,0,0,0,0,0,0,0,0,0
0,0,0,0,0,0,0,0,0,0,0,0,0,0,0,0,0,0
:endlayer
layer: 54
0,0,0,0,0,0,0,0,0,0,0,0,0,0,0,0,0,0
0,0,0,0,0,0,0,0,0,0,0,0,0,0,0,0,0,0
0,0,0,0,0,0,0,0,0,0,0,0,0,0,0,0,0,0
0,0,0,0,0,0,0,0,0,0,0,0,0,0,0,0,0,0
0,0,0,0,0,0,0,0,0,0,0,0,0,0,0,0,0,0
0,0,0,0,0,0,0,0,0,0,0,0,0,0,0,0,0,0
0,0,0,0,0,0,0,0,0,0,0,0,0,0,0,0,0,0
0,0,0,0,0,0,0,0,0,0,0,0,0,0,0,0,0,0
0,0,0,0,0,0,0,0,0,0,0,0,0,0,0,0,0,0
0,0,0,0,0,0,0,0,0,0,0,0,0,0,0,0,0,0
0,0,0,0,0,0,0,0,0,0,0,0,0,0,0,0,0,0
0,0,0,0,0,0,0,0,0,0,0,0,0,0,0,0,0,0
0,0,0,0,0,0,0,0,0,0,0,0,0,0,0,0,0,0
0,0,0,0,0,0,0,0,0,0,0,0,0,0,0,0,0,0
0,0,0,0,0,0,0,0,0,0,0,0,0,0,0,0,0,0
0,0,0,0,0,0,0,0,0,0,0,0,0,0,0,0,0,0
0,0,0,0,0,0,0,0,0,0,0,0,0,0,0,0,0,0
0,0,0,0,0,0,0,0,0,0,0,0,0,0,0,0,0,0
:endlayer
layer: 55
0,0,0,0,0,0,0,0,0,0,0,0,0,0,0,0,0,0
0,0,0,0,0,0,0,0,0,0,0,0,0,0,0,0,0,0
0,0,0,0,0,0,0,0,0,0,0,0,0,0,0,0,0,0
0,0,0,0,0,0,0,0,0,0,0,0,0,0,0,0,0,0
0,0,0,0,0,0,0,0,0,0,0,0,0,0,0,0,0,0
0,0,0,0,0,0,0,0,0,0,0,0,0,0,0,0,0,0
0,0,0,0,0,0,0,0,0,0,0,0,0,0,0,0,0,0
0,0,0,0,0,0,0,0,0,0,0,0,0,0,0,0,0,0
0,0,0,0,0,0,0,0,0,0,0,0,0,0,0,0,0,0
0,0,0,0,0,0,0,0,0,0,0,0,0,0,0,0,0,0
0,0,0,0,0,0,0,0,0,0,0,0,0,0,0,0,0,0
0,0,0,0,0,0,0,0,0,0,0,0,0,0,0,0,0,0
0,0,0,0,0,0,0,0,0,0,0,0,0,0,0,0,0,0
0,0,0,0,0,0,0,0,0,0,0,0,0,0,0,0,0,0
0,0,0,0,0,0,0,0,0,0,0,0,0,0,0,0,0,0
0,0,0,0,0,0,0,0,0,0,0,0,0,0,0,0,0,0
0,0,0,0,0,0,0,0,0,0,0,0,0,0,0,0,0,0
0,0,0,0,0,0,0,0,0,0,0,0,0,0,0,0,0,0
:endlayer
layer: 56
0,0,0,0,0,0,0,0,0,0,0,0,0,0,0,0,0,0
0,0,0,0,0,0,0,0,0,0,0,0,0,0,0,0,0,0
0,0,0,0,0,0,0,0,0,0,0,0,0,0,0,0,0,0
0,0,0,0,0,0,0,0,0,0,0,0,0,0,0,0,0,0
0,0,0,0,0,0,0,0,0,0,0,0,0,0,0,0,0,0
0,0,0,0,0,0,0,0,0,0,0,0,0,0,0,0,0,0
0,0,0,0,0,0,0,0,0,0,0,0,0,0,0,0,0,0
0,0,0,0,0,0,0,0,0,0,0,0,0,0,0,0,0,0
0,0,0,0,0,0,0,0,0,0,0,0,0,0,0,0,0,0
0,0,0,0,0,0,0,0,0,0,0,0,0,0,0,0,0,0
0,0,0,0,0,0,0,0,0,0,0,0,0,0,0,0,0,0
0,0,0,0,0,0,0,0,0,0,0,0,0,0,0,0,0,0
0,0,0,0,0,0,0,0,0,0,0,0,0,0,0,0,0,0
0,0,0,0,0,0,0,0,0,0,0,0,0,0,0,0,0,0
0,0,0,0,0,0,0,0,0,0,0,0,0,0,0,0,0,0
0,0,0,0,0,0,0,0,0,0,0,0,0,0,0,0,0,0
0,0,0,0,0,0,0,0,0,0,0,0,0,0,0,0,0,0
0,0,0,0,0,0,0,0,0,0,0,0,0,0,0,0,0,0
:endlayer
layer: 57
0,0,0,0,0,0,0,0,0,0,0,0,0,0,0,0,0,0
0,0,0,0,0,0,0,0,0,0,0,0,0,0,0,0,0,0
0,0,0,0,0,0,0,0,0,0,0,0,0,0,0,0,0,0
0,0,0,0,0,0,0,0,0,0,0,0,0,0,0,0,0,0
0,0,0,0,0,0,0,0,0,0,0,0,0,0,0,0,0,0
0,0,0,0,0,0,0,0,0,0,0,0,0,0,0,0,0,0
0,0,0,0,0,0,0,0,0,0,0,0,0,0,0,0,0,0
0,0,0,0,0,0,0,0,0,0,0,0,0,0,0,0,0,0
0,0,0,0,0,0,0,0,0,0,0,0,0,0,0,0,0,0
0,0,0,0,0,0,0,0,0,0,0,0,0,0,0,0,0,0
0,0,0,0,0,0,0,0,0,0,0,0,0,0,0,0,0,0
0,0,0,0,0,0,0,0,0,0,0,0,0,0,0,0,0,0
0,0,0,0,0,0,0,0,0,0,0,0,0,0,0,0,0,0
0,0,0,0,0,0,0,0,0,0,0,0,0,0,0,0,0,0
0,0,0,0,0,0,0,0,0,0,0,0,0,0,0,0,0,0
0,0,0,0,0,0,0,0,0,0,0,0,0,0,0,0,0,0
0,0,0,0,0,0,0,0,0,0,0,0,0,0,0,0,0,0
0,0,0,0,0,0,0,0,0,0,0,0,0,0,0,0,0,0
:endlayer
layer: 58
0,0,0,0,0,0,0,0,0,0,0,0,0,0,0,0,0,0
0,0,0,0,0,0,0,0,0,0,0,0,0,0,0,0,0,0
0,0,0,0,0,0,0,0,0,0,0,0,0,0,0,0,0,0
0,0,0,0,0,0,0,0,0,0,0,0,0,0,0,0,0,0
0,0,0,0,0,0,0,0,0,0,0,0,0,0,0,0,0,0
0,0,0,0,0,0,0,0,0,0,0,0,0,0,0,0,0,0
0,0,0,0,0,0,0,0,0,0,0,0,0,0,0,0,0,0
0,0,0,0,0,0,0,0,0,0,0,0,0,0,0,0,0,0
0,0,0,0,0,0,0,0,0,0,0,0,0,0,0,0,0,0
0,0,0,0,0,0,0,0,0,0,0,0,0,0,0,0,0,0
0,0,0,0,0,0,0,0,0,0,0,0,0,0,0,0,0,0
0,0,0,0,0,0,0,0,0,0,0,0,0,0,0,0,0,0
0,0,0,0,0,0,0,0,0,0,0,0,0,0,0,0,0,0
0,0,0,0,0,0,0,0,0,0,0,0,0,0,0,0,0,0
0,0,0,0,0,0,0,0,0,0,0,0,0,0,0,0,0,0
0,0,0,0,0,0,0,0,0,0,0,0,0,0,0,0,0,0
0,0,0,0,0,0,0,0,0,0,0,0,0,0,0,0,0,0
0,0,0,0,0,0,0,0,0,0,0,0,0,0,0,0,0,0
:endlayer
layer: 59
0,0,0,0,0,0,0,0,0,0,0,0,0,0,0,0,0,0
0,0,0,0,0,0,0,0,0,0,0,0,0,0,0,0,0,0
0,0,0,0,0,0,0,0,0,0,0,0,0,0,0,0,0,0
0,0,0,0,0,0,0,0,0,0,0,0,0,0,0,0,0,0
0,0,0,0,0,0,0,0,0,0,0,0,0,0,0,0,0,0
0,0,0,0,0,0,0,0,0,0,0,0,0,0,0,0,0,0
0,0,0,0,0,0,0,0,0,0,0,0,0,0,0,0,0,0
0,0,0,0,0,0,0,0,0,0,0,0,0,0,0,0,0,0
0,0,0,0,0,0,0,0,0,0,0,0,0,0,0,0,0,0
0,0,0,0,0,0,0,0,0,0,0,0,0,0,0,0,0,0
0,0,0,0,0,0,0,0,0,0,0,0,0,0,0,0,0,0
0,0,0,0,0,0,0,0,0,0,0,0,0,0,0,0,0,0
0,0,0,0,0,0,0,0,0,0,0,0,0,0,0,0,0,0
0,0,0,0,0,0,0,0,0,0,0,0,0,0,0,0,0,0
0,0,0,0,0,0,0,0,0,0,0,0,0,0,0,0,0,0
0,0,0,0,0,0,0,0,0,0,0,0,0,0,0,0,0,0
0,0,0,0,0,0,0,0,0,0,0,0,0,0,0,0,0,0
0,0,0,0,0,0,0,0,0,0,0,0,0,0,0,0,0,0
:endlayer
layer: 60
0,0,0,0,0,0,0,0,0,0,0,0,0,0,0,0,0,0
0,0,0,0,0,0,0,0,0,0,0,0,0,0,0,0,0,0
0,0,0,0,0,0,0,0,0,0,0,0,0,0,0,0,0,0
0,0,0,0,0,0,0,0,0,0,0,0,0,0,0,0,0,0
0,0,0,0,0,0,0,0,0,0,0,0,0,0,0,0,0,0
0,0,0,0,0,0,0,0,0,0,0,0,0,0,0,0,0,0
0,0,0,0,0,0,0,0,0,0,0,0,0,0,0,0,0,0
0,0,0,0,0,0,0,0,0,0,0,0,0,0,0,0,0,0
0,0,0,0,0,0,0,0,0,0,0,0,0,0,0,0,0,0
0,0,0,0,0,0,0,0,0,0,0,0,0,0,0,0,0,0
0,0,0,0,0,0,0,0,0,0,0,0,0,0,0,0,0,0
0,0,0,0,0,0,0,0,0,0,0,0,0,0,0,0,0,0
0,0,0,0,0,0,0,0,0,0,0,0,0,0,0,0,0,0
0,0,0,0,0,0,0,0,0,0,0,0,0,0,0,0,0,0
0,0,0,0,0,0,0,0,0,0,0,0,0,0,0,0,0,0
0,0,0,0,0,0,0,0,0,0,0,0,0,0,0,0,0,0
0,0,0,0,0,0,0,0,0,0,0,0,0,0,0,0,0,0
0,0,0,0,0,0,0,0,0,0,0,0,0,0,0,0,0,0
:endlayer
layer: 61
0,0,0,0,0,0,0,0,0,0,0,0,0,0,0,0,0,0
0,0,0,0,0,0,0,0,0,0,0,0,0,0,0,0,0,0
0,0,0,0,0,0,0,0,0,0,0,0,0,0,0,0,0,0
0,0,0,0,0,0,0,0,0,0,0,0,0,0,0,0,0,0
0,0,0,0,0,0,0,0,0,0,0,0,0,0,0,0,0,0
0,0,0,0,0,0,0,0,0,0,0,0,0,0,0,0,0,0
0,0,0,0,0,0,0,0,0,0,0,0,0,0,0,0,0,0
0,0,0,0,0,0,0,0,0,0,0,0,0,0,0,0,0,0
0,0,0,0,0,0,0,0,0,0,0,0,0,0,0,0,0,0
0,0,0,0,0,0,0,0,0,0,0,0,0,0,0,0,0,0
0,0,0,0,0,0,0,0,0,0,0,0,0,0,0,0,0,0
0,0,0,0,0,0,0,0,0,0,0,0,0,0,0,0,0,0
0,0,0,0,0,0,0,0,0,0,0,0,0,0,0,0,0,0
0,0,0,0,0,0,0,0,0,0,0,0,0,0,0,0,0,0
0,0,0,0,0,0,0,0,0,0,0,0,0,0,0,0,0,0
0,0,0,0,0,0,0,0,0,0,0,0,0,0,0,0,0,0
0,0,0,0,0,0,0,0,0,0,0,0,0,0,0,0,0,0
0,0,0,0,0,0,0,0,0,0,0,0,0,0,0,0,0,0
:endlayer
layer: 62
0,0,0,0,0,0,0,0,0,0,0,0,0,0,0,0,0,0
0,0,0,0,0,0,0,0,0,0,0,0,0,0,0,0,0,0
0,0,0,0,0,0,0,0,0,0,0,0,0,0,0,0,0,0
0,0,0,0,0,0,0,0,0,0,0,0,0,0,0,0,0,0
0,0,0,0,0,0,0,0,0,0,0,0,0,0,0,0,0,0
0,0,0,0,0,0,0,0,0,0,0,0,0,0,0,0,0,0
0,0,0,0,0,0,0,0,0,0,0,0,0,0,0,0,0,0
0,0,0,0,0,0,0,0,0,0,0,0,0,0,0,0,0,0
0,0,0,0,0,0,0,0,0,0,0,0,0,0,0,0,0,0
0,0,0,0,0,0,0,0,0,0,0,0,0,0,0,0,0,0
0,0,0,0,0,0,0,0,0,0,0,0,0,0,0,0,0,0
0,0,0,0,0,0,0,0,0,0,0,0,0,0,0,0,0,0
0,0,0,0,0,0,0,0,0,0,0,0,0,0,0,0,0,0
0,0,0,0,0,0,0,0,0,0,0,0,0,0,0,0,0,0
0,0,0,0,0,0,0,0,0,0,0,0,0,0,0,0,0,0
0,0,0,0,0,0,0,0,0,0,0,0,0,0,0,0,0,0
0,0,0,0,0,0,0,0,0,0,0,0,0,0,0,0,0,0
0,0,0,0,0,0,0,0,0,0,0,0,0,0,0,0,0,0
:endlayer
layer: 63
0,0,0,0,0,0,0,0,0,0,0,0,0,0,0,0,0,0
0,0,0,0,0,0,0,0,0,0,0,0,0,0,0,0,0,0
0,0,0,0,0,0,0,0,0,0,0,0,0,0,0,0,0,0
0,0,0,0,0,0,0,0,0,0,0,0,0,0,0,0,0,0
0,0,0,0,0,0,0,0,0,0,0,0,0,0,0,0,0,0
0,0,0,0,0,0,0,0,0,0,0,0,0,0,0,0,0,0
0,0,0,0,0,0,0,0,0,0,0,0,0,0,0,0,0,0
0,0,0,0,0,0,0,0,0,0,0,0,0,0,0,0,0,0
0,0,0,0,0,0,0,0,0,0,0,0,0,0,0,0,0,0
0,0,0,0,0,0,0,0,0,0,0,0,0,0,0,0,0,0
0,0,0,0,0,0,0,0,0,0,0,0,0,0,0,0,0,0
0,0,0,0,0,0,0,0,0,0,0,0,0,0,0,0,0,0
0,0,0,0,0,0,0,0,0,0,0,0,0,0,0,0,0,0
0,0,0,0,0,0,0,0,0,0,0,0,0,0,0,0,0,0
0,0,0,0,0,0,0,0,0,0,0,0,0,0,0,0,0,0
0,0,0,0,0,0,0,0,0,0,0,0,0,0,0,0,0,0
0,0,0,0,0,0,0,0,0,0,0,0,0,0,0,0,0,0
0,0,0,0,0,0,0,0,0,0,0,0,0,0,0,0,0,0
:endlayer
layer: 64
0,0,0,0,0,0,0,0,0,0,0,0,0,0,0,0,0,0
0,0,0,0,0,0,0,0,0,0,0,0,0,0,0,0,0,0
0,0,0,0,0,0,0,0,0,0,0,0,0,0,0,0,0,0
0,0,0,0,0,0,0,0,0,0,0,0,0,0,0,0,0,0
0,0,0,0,0,0,0,0,0,0,0,0,0,0,0,0,0,0
0,0,0,0,0,0,0,0,0,0,0,0,0,0,0,0,0,0
0,0,0,0,0,0,0,0,0,0,0,0,0,0,0,0,0,0
0,0,0,0,0,0,0,0,0,0,0,0,0,0,0,0,0,0
0,0,0,0,0,0,0,0,0,0,0,0,0,0,0,0,0,0
0,0,0,0,0,0,0,0,0,0,0,0,0,0,0,0,0,0
0,0,0,0,0,0,0,0,0,0,0,0,0,0,0,0,0,0
0,0,0,0,0,0,0,0,0,0,0,0,0,0,0,0,0,0
0,0,0,0,0,0,0,0,0,0,0,0,0,0,0,0,0,0
0,0,0,0,0,0,0,0,0,0,0,0,0,0,0,0,0,0
0,0,0,0,0,0,0,0,0,0,0,0,0,0,0,0,0,0
0,0,0,0,0,0,0,0,0,0,0,0,0,0,0,0,0,0
0,0,0,0,0,0,0,0,0,0,0,0,0,0,0,0,0,0
0,0,0,0,0,0,0,0,0,0,0,0,0,0,0,0,0,0
:endlayer

#### RULES ####
rule:
plugin=vanillaBlocks
number=1
data:
JSON:{blockState:{blockName:"minecraft:stonebrick",properties:{variant:"stonebrick"}}}
:enddata
:endrule

rule:
plugin=vanillaBlocks
number=2
data:
JSON:{blockState:{blockName:"minecraft:stone",properties:{variant:"stone"}}}
:enddata
:endrule

rule:
plugin=vanillaBlocks
number=3
data:
JSON:{blockState:{blockName:"minecraft:clay"}}
:enddata
:endrule

rule:
plugin=vanillaBlocks
number=4
data:
JSON:{blockState:{blockName:"minecraft:dirt",properties:{variant:"dirt",snowy:"false"}}}
:enddata
:endrule

rule:
plugin=vanillaBlocks
number=5
data:
JSON:{blockState:{blockName:"minecraft:gravel"}}
:enddata
:endrule

rule:
plugin=vanillaBlocks
number=6
data:
JSON:{blockState:{blockName:"minecraft:stonebrick",properties:{variant:"chiseled_stonebrick"}}}
:enddata
:endrule

rule:
plugin=vanillaBlocks
number=7
data:
JSON:{blockState:{blockName:"minecraft:stonebrick",properties:{variant:"mossy_stonebrick"}}}
:enddata
:endrule

rule:
plugin=vanillaBlocks
number=8
data:
JSON:{blockState:{blockName:"minecraft:stonebrick",properties:{variant:"cracked_stonebrick"}}}
:enddata
:endrule

rule:
plugin=vanillaBlocks
number=9
data:
JSON:{blockState:{blockName:"minecraft:mossy_cobblestone"}}
:enddata
:endrule

rule:
plugin=inventory
number=10
data:
JSON:{blockState:{blockName:"minecraft:chest",properties:{facing:"west"}},lootLevel:0,teData:{ForgeData:{},Items:[{Slot:2b,id:"minecraft:gold_ingot",Count:1b,Damage:0s},{Slot:3b,id:"minecraft:gold_ingot",Count:1b,Damage:0s},{Slot:4b,id:"minecraft:gold_ingot",Count:1b,Damage:0s},{Slot:5b,id:"minecraft:gold_ingot",Count:2b,Damage:0s},{Slot:12b,id:"minecraft:gold_ingot",Count:1b,Damage:0s},{Slot:13b,id:"minecraft:gold_ingot",Count:1b,Damage:0s},{Slot:22b,id:"minecraft:gold_ingot",Count:1b,Damage:0s}],id:"minecraft:chest",Lock:""},inventoryData:{length:7,inventoryContents:[{id:"minecraft:gold_ingot",Count:1b,slot:0,Damage:0s},{id:"minecraft:gold_ingot",Count:1b,slot:1,Damage:0s},{id:"minecraft:gold_ingot",Count:1b,slot:2,Damage:0s},{id:"minecraft:gold_ingot",Count:2b,slot:3,Damage:0s},{id:"minecraft:gold_ingot",Count:1b,slot:4,Damage:0s},{id:"minecraft:gold_ingot",Count:1b,slot:5,Damage:0s},{id:"minecraft:gold_ingot",Count:1b,slot:6,Damage:0s}]},legacyFeatures:1b}
:enddata
:endrule

rule:
plugin=vanillaBlocks
number=11
data:
JSON:{blockState:{blockName:"minecraft:bookshelf"}}
:enddata
:endrule

rule:
plugin=inventory
number=12
data:
JSON:{blockState:{blockName:"minecraft:chest",properties:{facing:"west"}},lootLevel:0,teData:{ForgeData:{},Items:[{Slot:3b,id:"minecraft:golden_apple",Count:1b,Damage:1s},{Slot:5b,id:"minecraft:bread",Count:2b,Damage:0s},{Slot:6b,id:"minecraft:bread",Count:1b,Damage:0s},{Slot:12b,id:"minecraft:golden_apple",Count:1b,Damage:1s},{Slot:15b,id:"minecraft:bread",Count:1b,Damage:0s},{Slot:16b,id:"minecraft:bread",Count:1b,Damage:0s},{Slot:22b,id:"minecraft:golden_apple",Count:1b,Damage:1s},{Slot:24b,id:"minecraft:wheat_seeds",Count:2b,Damage:0s},{Slot:25b,id:"minecraft:bread",Count:1b,Damage:0s}],id:"minecraft:chest",Lock:""},inventoryData:{length:9,inventoryContents:[{id:"minecraft:golden_apple",Count:1b,slot:0,Damage:1s},{id:"minecraft:bread",Count:2b,slot:1,Damage:0s},{id:"minecraft:bread",Count:1b,slot:2,Damage:0s},{id:"minecraft:golden_apple",Count:1b,slot:3,Damage:1s},{id:"minecraft:bread",Count:1b,slot:4,Damage:0s},{id:"minecraft:bread",Count:1b,slot:5,Damage:0s},{id:"minecraft:golden_apple",Count:1b,slot:6,Damage:1s},{id:"minecraft:wheat_seeds",Count:2b,slot:7,Damage:0s},{id:"minecraft:bread",Count:1b,slot:8,Damage:0s}]},legacyFeatures:1b}
:enddata
:endrule

rule:
plugin=blockTile
number=13
data:
JSON:{blockState:{blockName:"minecraft:mob_spawner"},teData:{MaxNearbyEntities:6s,RequiredPlayerRange:16s,SpawnCount:4s,SpawnData:{id:"minecraft:zombie"},MaxSpawnDelay:800s,id:"minecraft:mob_spawner",SpawnRange:4s,Delay:44s,MinSpawnDelay:200s,SpawnPotentials:[{Entity:{id:"minecraft:zombie"},Weight:1}]}}
:enddata
:endrule

rule:
plugin=blockTile
number=14
data:
JSON:{blockState:{blockName:"minecraft:air"},teData:{InvList:[],id:"minecraft:eplus.advanced.table"}}
:enddata
:endrule

rule:
plugin=blockTile
number=15
data:
JSON:{blockState:{blockName:"minecraft:enchanting_table"},teData:{id:"minecraft:enchanting_table"}}
:enddata
:endrule

rule:
plugin=vanillaBlocks
number=16
data:
JSON:{blockState:{blockName:"minecraft:ladder",properties:{facing:"north"}}}
:enddata
:endrule

rule:
plugin=vanillaBlocks
number=17
data:
JSON:{blockState:{blockName:"minecraft:ladder",properties:{facing:"east"}}}
:enddata
:endrule

rule:
plugin=vanillaBlocks
number=18
data:
JSON:{blockState:{blockName:"minecraft:ladder",properties:{facing:"west"}}}
:enddata
:endrule

rule:
plugin=vanillaBlocks
number=19
data:
JSON:{blockState:{blockName:"minecraft:ladder",properties:{facing:"south"}}}
:enddata
:endrule

rule:
plugin=blockTile
number=20
data:
JSON:{blockState:{blockName:"minecraft:mob_spawner"},teData:{MaxNearbyEntities:6s,RequiredPlayerRange:16s,SpawnCount:4s,SpawnData:{id:"minecraft:skeleton"},MaxSpawnDelay:800s,id:"minecraft:mob_spawner",SpawnRange:4s,Delay:495s,MinSpawnDelay:200s,SpawnPotentials:[{Entity:{id:"minecraft:skeleton"},Weight:1}]}}
:enddata
:endrule

rule:
plugin=vanillaBlocks
number=21
data:
JSON:{blockState:{blockName:"minecraft:cauldron",properties:{level:"0"}}}
:enddata
:endrule

rule:
plugin=blockTile
number=22
data:
JSON:{blockState:{blockName:"ebwizardry:arcane_workbench"},teData:{id:"minecraft:ebwizardryarcaneworkbenchtileentity",Inventory:[]}}
:enddata
:endrule

rule:
plugin=blockTile
number=23
data:
JSON:{blockState:{blockName:"minecraft:mob_spawner"},teData:{MaxNearbyEntities:6s,RequiredPlayerRange:16s,SpawnCount:4s,SpawnData:{id:"minecraft:zombie"},MaxSpawnDelay:800s,id:"minecraft:mob_spawner",SpawnRange:4s,Delay:526s,MinSpawnDelay:200s,SpawnPotentials:[{Entity:{id:"minecraft:zombie"},Weight:1}]}}
:enddata
:endrule

rule:
plugin=inventory
number=24
data:
JSON:{blockState:{blockName:"minecraft:chest",properties:{facing:"south"}},lootLevel:0,teData:{ForgeData:{},Items:[],id:"minecraft:chest",Lock:""},inventoryData:{length:0,inventoryContents:[]},legacyFeatures:1b}
:enddata
:endrule

rule:
plugin=inventory
number=25
data:
JSON:{blockState:{blockName:"minecraft:chest",properties:{facing:"east"}},lootLevel:0,teData:{Items:[],id:"minecraft:chest",Lock:""},inventoryData:{length:0,inventoryContents:[]},legacyFeatures:1b}
:enddata
:endrule

rule:
plugin=inventory
number=26
data:
JSON:{blockState:{blockName:"minecraft:brewing_stand",properties:{has_bottle_0:"false",has_bottle_1:"false",has_bottle_2:"false"}},lootLevel:0,teData:{Fuel:0b,Items:[],id:"minecraft:brewing_stand",BrewTime:0s,Lock:""},inventoryData:{length:0,inventoryContents:[]},legacyFeatures:0b}
:enddata
:endrule

rule:
plugin=vanillaBlocks
number=27
data:
JSON:{blockState:{blockName:"minecraft:monster_egg",properties:{variant:"stone_brick"}}}
:enddata
:endrule

rule:
plugin=vanillaBlocks
number=28
data:
JSON:{blockState:{blockName:"minecraft:stone_brick_stairs",properties:{half:"bottom",shape:"straight",facing:"south"}}}
:enddata
:endrule

rule:
plugin=vanillaBlocks
number=29
data:
JSON:{blockState:{blockName:"minecraft:stone_brick_stairs",properties:{half:"bottom",shape:"straight",facing:"west"}}}
:enddata
:endrule

rule:
plugin=vanillaBlocks
number=30
data:
JSON:{blockState:{blockName:"minecraft:stone_brick_stairs",properties:{half:"bottom",shape:"straight",facing:"north"}}}
:enddata
:endrule

rule:
plugin=vanillaBlocks
number=31
data:
JSON:{blockState:{blockName:"minecraft:stone_brick_stairs",properties:{half:"bottom",shape:"straight",facing:"east"}}}
:enddata
:endrule

rule:
plugin=vanillaBlocks
number=32
data:
JSON:{blockState:{blockName:"minecraft:stone_pressure_plate",properties:{powered:"false"}}}
:enddata
:endrule

rule:
plugin=vanillaBlocks
number=33
data:
JSON:{blockState:{blockName:"minecraft:double_stone_slab",properties:{seamless:"false",variant:"stone"}}}
:enddata
:endrule

rule:
plugin=doors
number=34
data:
JSON:{blockState:{blockName:"minecraft:iron_door",properties:{hinge:"left",half:"lower",powered:"false",facing:"west",open:"false"}}}
:enddata
:endrule

rule:
plugin=vanillaBlocks
number=35
data:
JSON:{blockState:{blockName:"minecraft:trapdoor",properties:{half:"bottom",facing:"south",open:"true"}}}
:enddata
:endrule

rule:
plugin=vanillaBlocks
number=36
data:
JSON:{blockState:{blockName:"minecraft:trapdoor",properties:{half:"bottom",facing:"north",open:"false"}}}
:enddata
:endrule

rule:
plugin=doors
number=37
data:
JSON:{blockState:{blockName:"minecraft:iron_door",properties:{hinge:"left",half:"lower",powered:"false",facing:"south",open:"false"}}}
:enddata
:endrule

rule:
plugin=doors
number=38
data:
JSON:{blockState:{blockName:"minecraft:iron_door",properties:{hinge:"left",half:"lower",powered:"false",facing:"north",open:"false"}}}
:enddata
:endrule

rule:
plugin=vanillaBlocks
number=39
data:
JSON:{blockState:{blockName:"minecraft:stone_pressure_plate",properties:{powered:"true"}}}
:enddata
:endrule

rule:
plugin=doors
number=40
data:
JSON:{blockState:{blockName:"minecraft:iron_door",properties:{hinge:"left",half:"lower",powered:"false",facing:"north",open:"true"}}}
:enddata
:endrule

rule:
plugin=vanillaBlocks
number=41
data:
JSON:{blockState:{blockName:"minecraft:trapdoor",properties:{half:"bottom",facing:"east",open:"false"}}}
:enddata
:endrule

rule:
plugin=doors
number=42
data:
JSON:{blockState:{blockName:"minecraft:iron_door",properties:{hinge:"left",half:"lower",powered:"false",facing:"east",open:"false"}}}
:enddata
:endrule

rule:
plugin=vanillaBlocks
number=43
data:
JSON:{blockState:{blockName:"minecraft:stone_brick_stairs",properties:{half:"top",shape:"straight",facing:"north"}}}
:enddata
:endrule

rule:
plugin=vanillaBlocks
number=44
data:
JSON:{blockState:{blockName:"minecraft:stone_brick_stairs",properties:{half:"top",shape:"straight",facing:"south"}}}
:enddata
:endrule

rule:
plugin=vanillaBlocks
number=45
data:
JSON:{blockState:{blockName:"minecraft:stone_brick_stairs",properties:{half:"top",shape:"straight",facing:"east"}}}
:enddata
:endrule

rule:
plugin=vanillaBlocks
number=46
data:
JSON:{blockState:{blockName:"minecraft:glass"}}
:enddata
:endrule

rule:
plugin=doors
number=47
data:
JSON:{blockState:{blockName:"minecraft:iron_door",properties:{hinge:"right",half:"upper",powered:"false",facing:"east",open:"false"}}}
:enddata
:endrule

rule:
plugin=doors
number=48
data:
JSON:{blockState:{blockName:"minecraft:iron_door",properties:{hinge:"left",half:"upper",powered:"false",facing:"east",open:"false"}}}
:enddata
:endrule

rule:
plugin=vanillaBlocks
number=49
data:
JSON:{blockState:{blockName:"minecraft:stone_brick_stairs",properties:{half:"top",shape:"straight",facing:"west"}}}
:enddata
:endrule

rule:
plugin=doors
number=50
data:
JSON:{blockState:{blockName:"minecraft:iron_door",properties:{hinge:"left",half:"upper",powered:"true",facing:"east",open:"false"}}}
:enddata
:endrule

rule:
plugin=blockTile
number=51
data:
JSON:{blockState:{blockName:"minecraft:mob_spawner"},teData:{MaxNearbyEntities:6s,RequiredPlayerRange:16s,SpawnCount:4s,SpawnData:{id:"minecraft:zombie"},MaxSpawnDelay:800s,id:"minecraft:mob_spawner",SpawnRange:4s,Delay:64s,MinSpawnDelay:200s,SpawnPotentials:[{Entity:{id:"minecraft:zombie"},Weight:1}]}}
:enddata
:endrule

rule:
plugin=blockTile
number=52
data:
JSON:{blockState:{blockName:"minecraft:mob_spawner"},teData:{MaxNearbyEntities:6s,RequiredPlayerRange:16s,SpawnCount:4s,SpawnData:{id:"minecraft:zombie"},MaxSpawnDelay:800s,id:"minecraft:mob_spawner",SpawnRange:4s,Delay:53s,MinSpawnDelay:200s,SpawnPotentials:[{Entity:{id:"minecraft:zombie"},Weight:1}]}}
:enddata
:endrule

rule:
plugin=blockTile
number=53
data:
JSON:{blockState:{blockName:"minecraft:mob_spawner"},teData:{MaxNearbyEntities:6s,RequiredPlayerRange:16s,SpawnCount:4s,SpawnData:{id:"minecraft:zombie"},MaxSpawnDelay:800s,id:"minecraft:mob_spawner",SpawnRange:4s,Delay:211s,MinSpawnDelay:200s,SpawnPotentials:[{Entity:{id:"minecraft:zombie"},Weight:1}]}}
:enddata
:endrule

rule:
plugin=blockTile
number=54
data:
JSON:{blockState:{blockName:"minecraft:mob_spawner"},teData:{MaxNearbyEntities:6s,RequiredPlayerRange:16s,SpawnCount:4s,SpawnData:{IsBaby:1b,id:"minecraft:zombie"},MaxSpawnDelay:800s,id:"minecraft:mob_spawner",SpawnRange:4s,Delay:72s,MinSpawnDelay:200s,SpawnPotentials:[{Entity:{IsBaby:1b,id:"minecraft:zombie"},Weight:1}]}}
:enddata
:endrule

rule:
plugin=vanillaBlocks
number=55
data:
JSON:{blockState:{blockName:"minecraft:stone_slab",properties:{half:"top",variant:"stone_brick"}}}
:enddata
:endrule

rule:
plugin=vanillaBlocks
number=56
data:
JSON:{blockState:{blockName:"minecraft:stone_slab",properties:{half:"bottom",variant:"stone_brick"}}}
:enddata
:endrule

rule:
plugin=inventory
number=57
data:
JSON:{blockState:{blockName:"minecraft:chest",properties:{facing:"south"}},lootLevel:0,teData:{ForgeData:{},Items:[{Slot:0b,id:"minecraft:blaze_rod",Count:1b,Damage:0s},{Slot:1b,id:"minecraft:blaze_rod",Count:1b,Damage:0s},{Slot:2b,id:"minecraft:blaze_rod",Count:1b,Damage:0s},{Slot:5b,id:"minecraft:blaze_powder",Count:1b,Damage:0s},{Slot:10b,id:"minecraft:blaze_rod",Count:1b,Damage:0s},{Slot:13b,id:"minecraft:blaze_powder",Count:1b,Damage:0s},{Slot:15b,id:"minecraft:blaze_powder",Count:1b,Damage:0s},{Slot:16b,id:"minecraft:blaze_powder",Count:1b,Damage:0s},{Slot:20b,id:"minecraft:blaze_powder",Count:1b,Damage:0s},{Slot:25b,id:"minecraft:blaze_powder",Count:1b,Damage:0s}],id:"minecraft:chest",Lock:""},inventoryData:{length:10,inventoryContents:[{id:"minecraft:blaze_rod",Count:1b,slot:0,Damage:0s},{id:"minecraft:blaze_rod",Count:1b,slot:1,Damage:0s},{id:"minecraft:blaze_rod",Count:1b,slot:2,Damage:0s},{id:"minecraft:blaze_powder",Count:1b,slot:3,Damage:0s},{id:"minecraft:blaze_rod",Count:1b,slot:4,Damage:0s},{id:"minecraft:blaze_powder",Count:1b,slot:5,Damage:0s},{id:"minecraft:blaze_powder",Count:1b,slot:6,Damage:0s},{id:"minecraft:blaze_powder",Count:1b,slot:7,Damage:0s},{id:"minecraft:blaze_powder",Count:1b,slot:8,Damage:0s},{id:"minecraft:blaze_powder",Count:1b,slot:9,Damage:0s}]},legacyFeatures:1b}
:enddata
:endrule

rule:
plugin=vanillaBlocks
number=58
data:
JSON:{blockState:{blockName:"minecraft:cauldron",properties:{level:"3"}}}
:enddata
:endrule

rule:
plugin=inventory
number=59
data:
JSON:{blockState:{blockName:"minecraft:brewing_stand",properties:{has_bottle_0:"false",has_bottle_1:"false",has_bottle_2:"false"}},lootLevel:0,teData:{Fuel:0b,Items:[],id:"minecraft:brewing_stand",BrewTime:0s,Lock:""},inventoryData:{length:0,inventoryContents:[]},legacyFeatures:0b}
:enddata
:endrule

rule:
plugin=inventory
number=60
data:
JSON:{blockState:{blockName:"minecraft:chest",properties:{facing:"north"}},lootLevel:0,teData:{ForgeData:{},Items:[{Slot:0b,id:"minecraft:clay_ball",Count:1b,Damage:0s},{Slot:1b,id:"minecraft:clay_ball",Count:1b,Damage:0s},{Slot:2b,id:"minecraft:clay_ball",Count:1b,Damage:0s},{Slot:8b,id:"minecraft:magma_cream",Count:1b,Damage:0s},{Slot:9b,id:"minecraft:clay_ball",Count:1b,Damage:0s},{Slot:10b,id:"minecraft:clay_ball",Count:1b,Damage:0s},{Slot:13b,id:"minecraft:magma_cream",Count:1b,Damage:0s},{Slot:14b,id:"minecraft:magma_cream",Count:1b,Damage:0s},{Slot:15b,id:"minecraft:magma_cream",Count:1b,Damage:0s},{Slot:16b,id:"minecraft:magma_cream",Count:1b,Damage:0s},{Slot:18b,id:"minecraft:clay_ball",Count:1b,Damage:0s},{Slot:19b,id:"minecraft:clay_ball",Count:1b,Damage:0s},{Slot:20b,id:"minecraft:clay_ball",Count:1b,Damage:0s},{Slot:24b,id:"minecraft:magma_cream",Count:1b,Damage:0s},{Slot:25b,id:"minecraft:magma_cream",Count:1b,Damage:0s}],id:"minecraft:chest",Lock:""},inventoryData:{length:15,inventoryContents:[{id:"minecraft:clay_ball",Count:1b,slot:0,Damage:0s},{id:"minecraft:clay_ball",Count:1b,slot:1,Damage:0s},{id:"minecraft:clay_ball",Count:1b,slot:2,Damage:0s},{id:"minecraft:magma_cream",Count:1b,slot:3,Damage:0s},{id:"minecraft:clay_ball",Count:1b,slot:4,Damage:0s},{id:"minecraft:clay_ball",Count:1b,slot:5,Damage:0s},{id:"minecraft:magma_cream",Count:1b,slot:6,Damage:0s},{id:"minecraft:magma_cream",Count:1b,slot:7,Damage:0s},{id:"minecraft:magma_cream",Count:1b,slot:8,Damage:0s},{id:"minecraft:magma_cream",Count:1b,slot:9,Damage:0s},{id:"minecraft:clay_ball",Count:1b,slot:10,Damage:0s},{id:"minecraft:clay_ball",Count:1b,slot:11,Damage:0s},{id:"minecraft:clay_ball",Count:1b,slot:12,Damage:0s},{id:"minecraft:magma_cream",Count:1b,slot:13,Damage:0s},{id:"minecraft:magma_cream",Count:1b,slot:14,Damage:0s}]},legacyFeatures:1b}
:enddata
:endrule

rule:
plugin=vanillaBlocks
number=61
data:
JSON:{blockState:{blockName:"minecraft:web"}}
:enddata
:endrule

rule:
plugin=blockTile
number=62
data:
JSON:{blockState:{blockName:"minecraft:mob_spawner"},teData:{MaxNearbyEntities:6s,RequiredPlayerRange:16s,SpawnCount:4s,SpawnData:{id:"minecraft:bat"},MaxSpawnDelay:800s,id:"minecraft:mob_spawner",SpawnRange:4s,Delay:0s,MinSpawnDelay:200s,SpawnPotentials:[{Entity:{id:"minecraft:bat"},Weight:1}]}}
:enddata
:endrule

rule:
plugin=blockTile
number=63
data:
JSON:{blockState:{blockName:"ancientwarfarestructure:advanced_loot_chest",properties:{facing:"south"}},teData:{LootTable:"ebwizardry:chests/wizard_tower",lootRolls:1b,lootSettings:{lootRolls:1,splashPotion:0b,hasLoot:1b,lootTableName:"ebwizardry:chests/wizard_tower",spawnEntity:0b},id:"ancientwarfarestructure:advanced_loot_chest_tile",Lock:"",LootTableSeed:4025060219959235775L}}
:enddata
:endrule

rule:
plugin=inventory
number=64
data:
JSON:{blockState:{blockName:"minecraft:chest",properties:{facing:"east"}},lootLevel:0,teData:{ForgeData:{},Items:[{Slot:0b,id:"minecraft:glowstone_dust",Count:1b,Damage:0s},{Slot:1b,id:"minecraft:glowstone_dust",Count:1b,Damage:0s},{Slot:2b,id:"minecraft:glowstone_dust",Count:1b,Damage:0s},{Slot:3b,id:"minecraft:fermented_spider_eye",Count:1b,Damage:0s},{Slot:4b,id:"minecraft:nether_wart",Count:1b,Damage:0s},{Slot:5b,id:"minecraft:nether_wart",Count:1b,Damage:0s},{Slot:6b,id:"minecraft:nether_wart",Count:1b,Damage:0s},{Slot:7b,id:"minecraft:nether_wart",Count:1b,Damage:0s},{Slot:8b,id:"minecraft:nether_wart",Count:1b,Damage:0s},{Slot:9b,id:"minecraft:glowstone_dust",Count:1b,Damage:0s},{Slot:10b,id:"minecraft:glowstone_dust",Count:1b,Damage:0s},{Slot:12b,id:"minecraft:fermented_spider_eye",Count:1b,Damage:0s},{Slot:13b,id:"minecraft:fermented_spider_eye",Count:1b,Damage:0s},{Slot:14b,id:"minecraft:fermented_spider_eye",Count:1b,Damage:0s},{Slot:15b,id:"minecraft:fermented_spider_eye",Count:1b,Damage:0s},{Slot:17b,id:"minecraft:nether_wart",Count:1b,Damage:0s},{Slot:18b,id:"minecraft:glowstone_dust",Count:1b,Damage:0s},{Slot:19b,id:"minecraft:glowstone_dust",Count:1b,Damage:0s},{Slot:20b,id:"minecraft:fermented_spider_eye",Count:1b,Damage:0s},{Slot:22b,id:"minecraft:fermented_spider_eye",Count:1b,Damage:0s},{Slot:23b,id:"minecraft:fermented_spider_eye",Count:1b,Damage:0s},{Slot:24b,id:"minecraft:fermented_spider_eye",Count:1b,Damage:0s},{Slot:26b,id:"minecraft:nether_wart",Count:1b,Damage:0s}],id:"minecraft:chest",Lock:""},inventoryData:{length:23,inventoryContents:[{id:"minecraft:glowstone_dust",Count:1b,slot:0,Damage:0s},{id:"minecraft:glowstone_dust",Count:1b,slot:1,Damage:0s},{id:"minecraft:glowstone_dust",Count:1b,slot:2,Damage:0s},{id:"minecraft:fermented_spider_eye",Count:1b,slot:3,Damage:0s},{id:"minecraft:nether_wart",Count:1b,slot:4,Damage:0s},{id:"minecraft:nether_wart",Count:1b,slot:5,Damage:0s},{id:"minecraft:nether_wart",Count:1b,slot:6,Damage:0s},{id:"minecraft:nether_wart",Count:1b,slot:7,Damage:0s},{id:"minecraft:nether_wart",Count:1b,slot:8,Damage:0s},{id:"minecraft:glowstone_dust",Count:1b,slot:9,Damage:0s},{id:"minecraft:glowstone_dust",Count:1b,slot:10,Damage:0s},{id:"minecraft:fermented_spider_eye",Count:1b,slot:11,Damage:0s},{id:"minecraft:fermented_spider_eye",Count:1b,slot:12,Damage:0s},{id:"minecraft:fermented_spider_eye",Count:1b,slot:13,Damage:0s},{id:"minecraft:fermented_spider_eye",Count:1b,slot:14,Damage:0s},{id:"minecraft:nether_wart",Count:1b,slot:15,Damage:0s},{id:"minecraft:glowstone_dust",Count:1b,slot:16,Damage:0s},{id:"minecraft:glowstone_dust",Count:1b,slot:17,Damage:0s},{id:"minecraft:fermented_spider_eye",Count:1b,slot:18,Damage:0s},{id:"minecraft:fermented_spider_eye",Count:1b,slot:19,Damage:0s},{id:"minecraft:fermented_spider_eye",Count:1b,slot:20,Damage:0s},{id:"minecraft:fermented_spider_eye",Count:1b,slot:21,Damage:0s},{id:"minecraft:nether_wart",Count:1b,slot:22,Damage:0s}]},legacyFeatures:1b}
:enddata
:endrule

rule:
plugin=inventory
number=65
data:
JSON:{blockState:{blockName:"minecraft:chest",properties:{facing:"north"}},lootLevel:0,teData:{ForgeData:{},Items:[{Slot:0b,id:"minecraft:quartz",Count:1b,Damage:0s},{Slot:1b,id:"minecraft:quartz",Count:1b,Damage:0s},{Slot:2b,id:"minecraft:quartz",Count:1b,Damage:0s},{Slot:3b,id:"minecraft:quartz",Count:1b,Damage:0s},{Slot:4b,id:"minecraft:quartz",Count:1b,Damage:0s},{Slot:11b,id:"minecraft:speckled_melon",Count:1b,Damage:0s},{Slot:12b,id:"minecraft:speckled_melon",Count:1b,Damage:0s},{Slot:14b,id:"minecraft:speckled_melon",Count:1b,Damage:0s},{Slot:15b,id:"minecraft:speckled_melon",Count:1b,Damage:0s},{Slot:16b,id:"minecraft:speckled_melon",Count:1b,Damage:0s},{Slot:19b,id:"minecraft:speckled_melon",Count:1b,Damage:0s},{Slot:26b,id:"minecraft:speckled_melon",Count:1b,Damage:0s}],id:"minecraft:chest",Lock:""},inventoryData:{length:12,inventoryContents:[{id:"minecraft:quartz",Count:1b,slot:0,Damage:0s},{id:"minecraft:quartz",Count:1b,slot:1,Damage:0s},{id:"minecraft:quartz",Count:1b,slot:2,Damage:0s},{id:"minecraft:quartz",Count:1b,slot:3,Damage:0s},{id:"minecraft:quartz",Count:1b,slot:4,Damage:0s},{id:"minecraft:speckled_melon",Count:1b,slot:5,Damage:0s},{id:"minecraft:speckled_melon",Count:1b,slot:6,Damage:0s},{id:"minecraft:speckled_melon",Count:1b,slot:7,Damage:0s},{id:"minecraft:speckled_melon",Count:1b,slot:8,Damage:0s},{id:"minecraft:speckled_melon",Count:1b,slot:9,Damage:0s},{id:"minecraft:speckled_melon",Count:1b,slot:10,Damage:0s},{id:"minecraft:speckled_melon",Count:1b,slot:11,Damage:0s}]},legacyFeatures:1b}
:enddata
:endrule

rule:
plugin=blockTile
number=66
data:
JSON:{blockState:{blockName:"minecraft:mob_spawner"},teData:{MaxNearbyEntities:6s,RequiredPlayerRange:16s,SpawnCount:4s,SpawnData:{id:"minecraft:zombie"},MaxSpawnDelay:800s,id:"minecraft:mob_spawner",SpawnRange:4s,Delay:8s,MinSpawnDelay:200s,SpawnPotentials:[{Entity:{id:"minecraft:zombie"},Weight:1}]}}
:enddata
:endrule

rule:
plugin=inventory
number=67
data:
JSON:{blockState:{blockName:"minecraft:chest",properties:{facing:"west"}},lootLevel:0,teData:{ForgeData:{},Items:[{Slot:13b,id:"ancientwarfarenpc:coin",Count:23b,tag:{metal:"gold"},Damage:0s},{Slot:15b,id:"minecraft:diamond",Count:1b,Damage:0s},{Slot:22b,id:"minecraft:diamond",Count:1b,Damage:0s}],id:"minecraft:chest",Lock:""},inventoryData:{length:3,inventoryContents:[{id:"ancientwarfarenpc:coin",Count:23b,tag:{metal:"gold"},slot:0,Damage:0s},{id:"minecraft:diamond",Count:1b,slot:1,Damage:0s},{id:"minecraft:diamond",Count:1b,slot:2,Damage:0s}]},legacyFeatures:1b}
:enddata
:endrule

rule:
plugin=inventory
number=68
data:
JSON:{blockState:{blockName:"minecraft:chest",properties:{facing:"south"}},lootLevel:0,teData:{ForgeData:{},Items:[{Slot:2b,id:"minecraft:emerald",Count:1b,Damage:0s},{Slot:5b,id:"minecraft:emerald",Count:1b,Damage:0s},{Slot:8b,id:"minecraft:emerald",Count:1b,Damage:0s},{Slot:10b,id:"minecraft:emerald",Count:1b,Damage:0s},{Slot:12b,id:"minecraft:emerald",Count:1b,Damage:0s},{Slot:14b,id:"minecraft:emerald",Count:1b,Damage:0s},{Slot:15b,id:"minecraft:emerald",Count:1b,Damage:0s},{Slot:16b,id:"minecraft:emerald",Count:1b,Damage:0s},{Slot:18b,id:"minecraft:emerald",Count:1b,Damage:0s},{Slot:21b,id:"minecraft:emerald",Count:1b,Damage:0s},{Slot:24b,id:"minecraft:emerald",Count:1b,Damage:0s},{Slot:26b,id:"minecraft:emerald",Count:1b,Damage:0s}],id:"minecraft:chest",Lock:""},inventoryData:{length:12,inventoryContents:[{id:"minecraft:emerald",Count:1b,slot:0,Damage:0s},{id:"minecraft:emerald",Count:1b,slot:1,Damage:0s},{id:"minecraft:emerald",Count:1b,slot:2,Damage:0s},{id:"minecraft:emerald",Count:1b,slot:3,Damage:0s},{id:"minecraft:emerald",Count:1b,slot:4,Damage:0s},{id:"minecraft:emerald",Count:1b,slot:5,Damage:0s},{id:"minecraft:emerald",Count:1b,slot:6,Damage:0s},{id:"minecraft:emerald",Count:1b,slot:7,Damage:0s},{id:"minecraft:emerald",Count:1b,slot:8,Damage:0s},{id:"minecraft:emerald",Count:1b,slot:9,Damage:0s},{id:"minecraft:emerald",Count:1b,slot:10,Damage:0s},{id:"minecraft:emerald",Count:1b,slot:11,Damage:0s}]},legacyFeatures:1b}
:enddata
:endrule

rule:
plugin=inventory
number=69
data:
JSON:{blockState:{blockName:"minecraft:chest",properties:{facing:"north"}},lootLevel:0,teData:{ForgeData:{},Items:[{Slot:13b,id:"minecraft:ender_pearl",Count:1b,Damage:0s},{Slot:22b,id:"ancientwarfarenpc:coin",Count:23b,tag:{metal:"gold"},Damage:0s}],id:"minecraft:chest",Lock:""},inventoryData:{length:2,inventoryContents:[{id:"minecraft:ender_pearl",Count:1b,slot:0,Damage:0s},{id:"ancientwarfarenpc:coin",Count:23b,tag:{metal:"gold"},slot:1,Damage:0s}]},legacyFeatures:1b}
:enddata
:endrule

rule:
plugin=inventory
number=70
data:
JSON:{blockState:{blockName:"minecraft:chest",properties:{facing:"east"}},lootLevel:0,teData:{ForgeData:{},Items:[{Slot:0b,id:"minecraft:gold_nugget",Count:1b,Damage:0s},{Slot:1b,id:"minecraft:gold_ingot",Count:1b,Damage:0s},{Slot:2b,id:"minecraft:gold_nugget",Count:1b,Damage:0s},{Slot:3b,id:"minecraft:gold_nugget",Count:1b,Damage:0s},{Slot:4b,id:"minecraft:gold_nugget",Count:1b,Damage:0s},{Slot:5b,id:"minecraft:gold_ingot",Count:1b,Damage:0s},{Slot:6b,id:"minecraft:gold_ingot",Count:1b,Damage:0s},{Slot:7b,id:"minecraft:gold_ingot",Count:1b,Damage:0s},{Slot:8b,id:"minecraft:gold_nugget",Count:1b,Damage:0s},{Slot:9b,id:"minecraft:gold_nugget",Count:1b,Damage:0s},{Slot:10b,id:"minecraft:gold_ingot",Count:1b,Damage:0s},{Slot:11b,id:"minecraft:gold_nugget",Count:1b,Damage:0s},{Slot:12b,id:"minecraft:gold_ingot",Count:1b,Damage:0s},{Slot:13b,id:"minecraft:gold_ingot",Count:1b,Damage:0s},{Slot:14b,id:"minecraft:gold_nugget",Count:1b,Damage:0s},{Slot:15b,id:"minecraft:gold_nugget",Count:1b,Damage:0s},{Slot:16b,id:"minecraft:gold_ingot",Count:1b,Damage:0s},{Slot:17b,id:"minecraft:gold_nugget",Count:1b,Damage:0s},{Slot:18b,id:"minecraft:gold_nugget",Count:1b,Damage:0s},{Slot:19b,id:"minecraft:gold_ingot",Count:1b,Damage:0s},{Slot:20b,id:"minecraft:gold_nugget",Count:1b,Damage:0s},{Slot:21b,id:"minecraft:gold_ingot",Count:1b,Damage:0s},{Slot:22b,id:"minecraft:gold_nugget",Count:1b,Damage:0s},{Slot:23b,id:"minecraft:gold_nugget",Count:1b,Damage:0s},{Slot:24b,id:"minecraft:gold_nugget",Count:1b,Damage:0s},{Slot:25b,id:"minecraft:gold_ingot",Count:1b,Damage:0s},{Slot:26b,id:"minecraft:gold_nugget",Count:1b,Damage:0s}],id:"minecraft:chest",Lock:""},inventoryData:{length:27,inventoryContents:[{id:"minecraft:gold_nugget",Count:1b,slot:0,Damage:0s},{id:"minecraft:gold_ingot",Count:1b,slot:1,Damage:0s},{id:"minecraft:gold_nugget",Count:1b,slot:2,Damage:0s},{id:"minecraft:gold_nugget",Count:1b,slot:3,Damage:0s},{id:"minecraft:gold_nugget",Count:1b,slot:4,Damage:0s},{id:"minecraft:gold_ingot",Count:1b,slot:5,Damage:0s},{id:"minecraft:gold_ingot",Count:1b,slot:6,Damage:0s},{id:"minecraft:gold_ingot",Count:1b,slot:7,Damage:0s},{id:"minecraft:gold_nugget",Count:1b,slot:8,Damage:0s},{id:"minecraft:gold_nugget",Count:1b,slot:9,Damage:0s},{id:"minecraft:gold_ingot",Count:1b,slot:10,Damage:0s},{id:"minecraft:gold_nugget",Count:1b,slot:11,Damage:0s},{id:"minecraft:gold_ingot",Count:1b,slot:12,Damage:0s},{id:"minecraft:gold_ingot",Count:1b,slot:13,Damage:0s},{id:"minecraft:gold_nugget",Count:1b,slot:14,Damage:0s},{id:"minecraft:gold_nugget",Count:1b,slot:15,Damage:0s},{id:"minecraft:gold_ingot",Count:1b,slot:16,Damage:0s},{id:"minecraft:gold_nugget",Count:1b,slot:17,Damage:0s},{id:"minecraft:gold_nugget",Count:1b,slot:18,Damage:0s},{id:"minecraft:gold_ingot",Count:1b,slot:19,Damage:0s},{id:"minecraft:gold_nugget",Count:1b,slot:20,Damage:0s},{id:"minecraft:gold_ingot",Count:1b,slot:21,Damage:0s},{id:"minecraft:gold_nugget",Count:1b,slot:22,Damage:0s},{id:"minecraft:gold_nugget",Count:1b,slot:23,Damage:0s},{id:"minecraft:gold_nugget",Count:1b,slot:24,Damage:0s},{id:"minecraft:gold_ingot",Count:1b,slot:25,Damage:0s},{id:"minecraft:gold_nugget",Count:1b,slot:26,Damage:0s}]},legacyFeatures:1b}
:enddata
:endrule

rule:
plugin=blockTile
number=71
data:
JSON:{blockState:{blockName:"minecraft:mob_spawner"},teData:{MaxNearbyEntities:6s,RequiredPlayerRange:16s,SpawnCount:4s,SpawnData:{id:"minecraft:spider"},MaxSpawnDelay:800s,id:"minecraft:mob_spawner",SpawnRange:4s,Delay:60s,MinSpawnDelay:200s,SpawnPotentials:[{Entity:{id:"minecraft:spider"},Weight:1}]}}
:enddata
:endrule

#### ENTITIES ####
entity:
plugin=entity
number=0
data:
JSON:{yOffset:0.0f,xOffset:0.23583722f,rotation:284.34128f,mobID:"minecraft:zombie",zOffset:0.43845242f,position:4123302821892L,entityData:{HurtByTimestamp:0,ForgeData:{},Attributes:[{Base:20.0d,Name:"generic.maxHealth"},{Base:0.0d,Modifiers:[{UUIDMost:5134156250471416190L,UUIDLeast:-4715779870416074320L,Amount:0.0035129534645333945d,Operation:0,Name:"Random spawn bonus"}],Name:"generic.knockbackResistance"},{Base:0.23000000417232513d,Name:"generic.movementSpeed"},{Base:2.0d,Name:"generic.armor"},{Base:0.0d,Name:"generic.armorToughness"},{Base:1.0d,Name:"forge.swimSpeed"},{Base:35.0d,Modifiers:[{UUIDMost:7131384350217030652L,UUIDLeast:-6228083310285366921L,Amount:1.6850324132069647E-4d,Operation:1,Name:"Random spawn bonus"}],Name:"generic.followRange"},{Base:3.0d,Name:"generic.attackDamage"},{Base:0.05649929228624059d,Name:"zombie.spawnReinforcements"}],Invulnerable:0b,FallFlying:0b,PortalCooldown:0,AbsorptionAmount:0.0f,FallDistance:0.0f,DeathTime:0s,ForgeCaps:{"dsurround:emojidata":{as:0,es:0,et:0},"llibrary:extendedentitydatacapability":{"mm:living":{frozenYaw:0.0f,freezeProgress:0.0f,frozenPitch:0.0f,frozenYawHead:0.0f,frozenEntityID:-1,frozenLimbSwingAmount:0.0f,frozenRenderYawOffset:0.0f,frozenSwingProgress:0.0f}}},HandDropChances:[0.085f,0.085f],PersistenceRequired:0b,Motion:[0.0d,-0.0784000015258789d,0.0d],Leashed:0b,Health:20.0f,LeftHanded:0b,Air:300s,OnGround:1b,Dimension:0,Rotation:[194.34128f,0.0f],UpdateBlocked:0b,HandItems:[{},{}],ArmorDropChances:[0.085f,0.085f,0.085f,0.085f],Pos:[875.4384524132834d,94.0d,325.76416277107364d],CanBreakDoors:0b,Fire:-1s,ArmorItems:[{},{},{},{}],CanPickUpLoot:0b,HurtTime:0s}}
:enddata
:endentity

entity:
plugin=entity
number=1
data:
JSON:{yOffset:0.0f,xOffset:0.2454986f,rotation:106.3276f,mobID:"minecraft:zombie",zOffset:0.60556835f,position:2474035380227L,entityData:{HurtByTimestamp:0,ForgeData:{},Attributes:[{Base:20.0d,Name:"generic.maxHealth"},{Base:0.0d,Modifiers:[{UUIDMost:-2267792433069338815L,UUIDLeast:-7636737747208525419L,Amount:0.027261675849548264d,Operation:0,Name:"Random spawn bonus"}],Name:"generic.knockbackResistance"},{Base:0.23000000417232513d,Name:"generic.movementSpeed"},{Base:2.0d,Name:"generic.armor"},{Base:0.0d,Name:"generic.armorToughness"},{Base:1.0d,Name:"forge.swimSpeed"},{Base:35.0d,Modifiers:[{UUIDMost:-6652307622498515013L,UUIDLeast:-8255788187157121798L,Amount:-0.052241707097327665d,Operation:1,Name:"Random spawn bonus"}],Name:"generic.followRange"},{Base:3.0d,Name:"generic.attackDamage"},{Base:0.09846331341344416d,Name:"zombie.spawnReinforcements"}],Invulnerable:0b,FallFlying:0b,PortalCooldown:0,AbsorptionAmount:0.0f,FallDistance:0.0f,DeathTime:0s,ForgeCaps:{"dsurround:emojidata":{as:1,es:0,et:0},"llibrary:extendedentitydatacapability":{"mm:living":{frozenYaw:0.0f,freezeProgress:0.0f,frozenPitch:0.0f,frozenYawHead:0.0f,frozenEntityID:-1,frozenLimbSwingAmount:0.0f,frozenRenderYawOffset:0.0f,frozenSwingProgress:0.0f}}},HandDropChances:[0.085f,0.085f],PersistenceRequired:0b,Motion:[0.0d,-0.0784000015258789d,0.0d],Leashed:0b,Health:20.0f,LeftHanded:0b,Air:300s,OnGround:1b,Dimension:0,Rotation:[16.327599f,0.0f],UpdateBlocked:0b,HandItems:[{},{}],ArmorDropChances:[0.085f,0.085f,0.085f,0.085f],Pos:[874.6055683586542d,94.0d,331.754501381775d],CanBreakDoors:1b,Fire:-1s,ArmorItems:[{},{},{},{}],CanPickUpLoot:0b,HurtTime:0s}}
:enddata
:endentity

entity:
plugin=entity
number=2
data:
JSON:{yOffset:0.0f,xOffset:0.36014372f,rotation:76.65137f,mobID:"minecraft:skeleton",zOffset:0.33856186f,position:3023791194116L,entityData:{HurtByTimestamp:0,ForgeData:{},Attributes:[{Base:20.0d,Name:"generic.maxHealth"},{Base:0.0d,Name:"generic.knockbackResistance"},{Base:0.25d,Name:"generic.movementSpeed"},{Base:0.0d,Name:"generic.armor"},{Base:0.0d,Name:"generic.armorToughness"},{Base:1.0d,Name:"forge.swimSpeed"},{Base:16.0d,Modifiers:[{UUIDMost:-5202194192701634606L,UUIDLeast:-7765284554206431987L,Amount:-0.04249182076261776d,Operation:1,Name:"Random spawn bonus"}],Name:"generic.followRange"},{Base:2.0d,Name:"generic.attackDamage"}],Invulnerable:0b,FallFlying:0b,PortalCooldown:0,AbsorptionAmount:0.0f,FallDistance:0.0f,DeathTime:0s,ForgeCaps:{"dsurround:emojidata":{as:0,es:0,et:0},"llibrary:extendedentitydatacapability":{"mm:living":{frozenYaw:0.0f,freezeProgress:0.0f,frozenPitch:0.0f,frozenYawHead:0.0f,frozenEntityID:-1,frozenLimbSwingAmount:0.0f,frozenRenderYawOffset:0.0f,frozenSwingProgress:0.0f}}},HandDropChances:[0.085f,0.085f],PersistenceRequired:0b,Motion:[0.03514767932099998d,-0.0784000015258789d,0.04995581593740804d],Leashed:0b,Health:20.0f,LeftHanded:0b,Air:300s,OnGround:1b,Dimension:0,Rotation:[346.65137f,0.0f],UpdateBlocked:0b,HandItems:[{id:"minecraft:bow",Count:1b,Damage:0s},{}],ArmorDropChances:[0.085f,0.085f,0.085f,0.085f],Pos:[875.3385618595639d,94.0d,329.6398562699316d],Fire:-1s,ArmorItems:[{},{},{},{}],CanPickUpLoot:0b,HurtTime:0s}}
:enddata
:endentity

entity:
plugin=entity
number=3
data:
JSON:{yOffset:0.0f,xOffset:0.97144246f,rotation:84.65622f,mobID:"minecraft:zombie",zOffset:0.40806141f,position:3573547008008L,entityData:{HurtByTimestamp:0,ForgeData:{},Attributes:[{Base:20.0d,Name:"generic.maxHealth"},{Base:0.0d,Modifiers:[{UUIDMost:7805320343237839991L,UUIDLeast:-9110735915960129204L,Amount:0.028252705760193262d,Operation:0,Name:"Random spawn bonus"}],Name:"generic.knockbackResistance"},{Base:0.23000000417232513d,Name:"generic.movementSpeed"},{Base:2.0d,Name:"generic.armor"},{Base:0.0d,Name:"generic.armorToughness"},{Base:1.0d,Name:"forge.swimSpeed"},{Base:35.0d,Modifiers:[{UUIDMost:-1149716658707873558L,UUIDLeast:-5916681045943588238L,Amount:0.024652568798626852d,Operation:1,Name:"Random spawn bonus"}],Name:"generic.followRange"},{Base:3.0d,Name:"generic.attackDamage"},{Base:0.07790487614720959d,Name:"zombie.spawnReinforcements"}],Invulnerable:0b,FallFlying:0b,PortalCooldown:0,AbsorptionAmount:0.0f,FallDistance:0.0f,DeathTime:0s,ForgeCaps:{"dsurround:emojidata":{as:1,es:0,et:0},"llibrary:extendedentitydatacapability":{"mm:living":{frozenYaw:0.0f,freezeProgress:0.0f,frozenPitch:0.0f,frozenYawHead:0.0f,frozenEntityID:-1,frozenLimbSwingAmount:0.0f,frozenRenderYawOffset:0.0f,frozenSwingProgress:0.0f}}},HandDropChances:[0.085f,0.085f],PersistenceRequired:0b,Motion:[0.0d,-0.0784000015258789d,0.0d],Leashed:0b,Health:20.0f,LeftHanded:0b,Air:300s,OnGround:1b,Dimension:0,Rotation:[354.65622f,0.0f],UpdateBlocked:0b,HandItems:[{},{}],ArmorDropChances:[0.085f,0.085f,0.085f,0.085f],Pos:[879.4080614032947d,94.0d,327.02855751970355d],CanBreakDoors:0b,Fire:-1s,ArmorItems:[{},{},{},{}],CanPickUpLoot:0b,HurtTime:0s}}
:enddata
:endentity

entity:
plugin=entity
number=4
data:
JSON:{yOffset:0.0f,xOffset:0.22819722f,rotation:255.44131f,mobID:"minecraft:skeleton",zOffset:0.3f,position:3573547008008L,entityData:{HurtByTimestamp:3295,ForgeData:{},Attributes:[{Base:20.0d,Name:"generic.maxHealth"},{Base:0.0d,Name:"generic.knockbackResistance"},{Base:0.25d,Name:"generic.movementSpeed"},{Base:0.0d,Name:"generic.armor"},{Base:0.0d,Name:"generic.armorToughness"},{Base:1.0d,Name:"forge.swimSpeed"},{Base:16.0d,Modifiers:[{UUIDMost:-1402744765794530896L,UUIDLeast:-7731622547052527814L,Amount:-0.07221931910636711d,Operation:1,Name:"Random spawn bonus"}],Name:"generic.followRange"},{Base:2.0d,Name:"generic.attackDamage"}],Invulnerable:0b,FallFlying:0b,PortalCooldown:0,AbsorptionAmount:0.0f,FallDistance:0.0f,DeathTime:0s,ForgeCaps:{"dsurround:emojidata":{as:0,es:0,et:0},"llibrary:extendedentitydatacapability":{"mm:living":{frozenYaw:0.0f,freezeProgress:0.0f,frozenPitch:0.0f,frozenYawHead:0.0f,frozenEntityID:-1,frozenLimbSwingAmount:0.0f,frozenRenderYawOffset:0.0f,frozenSwingProgress:0.0f}}},HandDropChances:[0.085f,0.085f],PersistenceRequired:0b,Motion:[0.0d,-0.0784000015258789d,0.0d],Leashed:0b,Health:19.0f,LeftHanded:0b,Air:300s,OnGround:1b,Dimension:0,Rotation:[165.44131f,0.0f],UpdateBlocked:0b,HandItems:[{id:"minecraft:bow",Count:1b,Damage:0s},{}],ArmorDropChances:[0.085f,0.085f,0.085f,0.085f],Pos:[879.3000000119209d,94.0d,327.7718027690469d],Fire:-1s,ArmorItems:[{},{},{},{}],CanPickUpLoot:0b,HurtTime:0s}}
:enddata
:endentity

entity:
plugin=entity
number=5
data:
JSON:{yOffset:0.0f,xOffset:0.28347874f,rotation:268.52078f,mobID:"minecraft:zombie",zOffset:0.5106486f,position:4123302821893L,entityData:{HurtByTimestamp:0,ForgeData:{},Attributes:[{Base:20.0d,Name:"generic.maxHealth"},{Base:0.0d,Modifiers:[{UUIDMost:3465707508285391231L,UUIDLeast:-6307708080862402966L,Amount:0.04504766618362671d,Operation:0,Name:"Random spawn bonus"}],Name:"generic.knockbackResistance"},{Base:0.23000000417232513d,Name:"generic.movementSpeed"},{Base:2.0d,Name:"generic.armor"},{Base:0.0d,Name:"generic.armorToughness"},{Base:1.0d,Name:"forge.swimSpeed"},{Base:35.0d,Modifiers:[{UUIDMost:1117116185177508684L,UUIDLeast:-6994132025857872451L,Amount:-0.007515965723157521d,Operation:1,Name:"Random spawn bonus"}],Name:"generic.followRange"},{Base:3.0d,Name:"generic.attackDamage"},{Base:0.00796373923595125d,Name:"zombie.spawnReinforcements"}],Invulnerable:0b,FallFlying:0b,PortalCooldown:0,AbsorptionAmount:0.0f,FallDistance:0.0f,DeathTime:0s,ForgeCaps:{"dsurround:emojidata":{as:0,es:0,et:0},"llibrary:extendedentitydatacapability":{"mm:living":{frozenYaw:0.0f,freezeProgress:0.0f,frozenPitch:0.0f,frozenYawHead:0.0f,frozenEntityID:-1,frozenLimbSwingAmount:0.0f,frozenRenderYawOffset:0.0f,frozenSwingProgress:0.0f}}},HandDropChances:[0.085f,0.085f],PersistenceRequired:0b,Motion:[0.0d,-0.0784000015258789d,0.0d],Leashed:0b,Health:20.0f,LeftHanded:0b,Air:300s,OnGround:1b,Dimension:0,Rotation:[178.52078f,0.0f],UpdateBlocked:0b,HandItems:[{},{}],ArmorDropChances:[0.085f,0.085f,0.085f,0.085f],Pos:[876.5106486041268d,94.0d,325.7165212624511d],CanBreakDoors:1b,Fire:-1s,ArmorItems:[{},{},{},{}],CanPickUpLoot:0b,HurtTime:0s}}
:enddata
:endentity

entity:
plugin=entity
number=6
data:
JSON:{yOffset:0.0f,xOffset:0.62102425f,rotation:79.542786f,mobID:"minecraft:skeleton",zOffset:0.7f,position:1924279566340L,entityData:{HurtByTimestamp:0,ForgeData:{},Attributes:[{Base:20.0d,Name:"generic.maxHealth"},{Base:0.0d,Name:"generic.knockbackResistance"},{Base:0.25d,Name:"generic.movementSpeed"},{Base:0.0d,Name:"generic.armor"},{Base:0.0d,Name:"generic.armorToughness"},{Base:1.0d,Name:"forge.swimSpeed"},{Base:16.0d,Modifiers:[{UUIDMost:-5387515498456987754L,UUIDLeast:-8495644430663484284L,Amount:0.07297868445012956d,Operation:1,Name:"Random spawn bonus"}],Name:"generic.followRange"},{Base:2.0d,Name:"generic.attackDamage"}],Invulnerable:0b,FallFlying:0b,PortalCooldown:0,AbsorptionAmount:0.0f,FallDistance:0.0f,DeathTime:0s,ForgeCaps:{"dsurround:emojidata":{as:1,es:0,et:0},"llibrary:extendedentitydatacapability":{"mm:living":{frozenYaw:0.0f,freezeProgress:0.0f,frozenPitch:0.0f,frozenYawHead:0.0f,frozenEntityID:-1,frozenLimbSwingAmount:0.0f,frozenRenderYawOffset:0.0f,frozenSwingProgress:0.0f}}},HandDropChances:[0.085f,0.085f],PersistenceRequired:0b,Motion:[0.0d,-0.0784000015258789d,0.00181581510396305d],Leashed:0b,Health:20.0f,LeftHanded:0b,Air:300s,OnGround:1b,Dimension:0,Rotation:[349.5428f,0.0f],UpdateBlocked:0b,HandItems:[{id:"minecraft:bow",Count:1b,Damage:0s},{}],ArmorDropChances:[0.085f,0.085f,0.085f,0.085f],Pos:[875.6999999880791d,94.0d,333.3789757347539d],Fire:-1s,ArmorItems:[{},{},{},{}],CanPickUpLoot:0b,HurtTime:0s}}
:enddata
:endentity

entity:
plugin=entity
number=7
data:
JSON:{yOffset:0.0f,xOffset:0.7454052f,rotation:113.780464f,mobID:"minecraft:skeleton",zOffset:0.6103612f,position:2199157473287L,entityData:{HurtByTimestamp:0,ForgeData:{},Attributes:[{Base:20.0d,Name:"generic.maxHealth"},{Base:0.0d,Name:"generic.knockbackResistance"},{Base:0.25d,Name:"generic.movementSpeed"},{Base:0.0d,Name:"generic.armor"},{Base:0.0d,Name:"generic.armorToughness"},{Base:1.0d,Name:"forge.swimSpeed"},{Base:16.0d,Modifiers:[{UUIDMost:3012923179118053509L,UUIDLeast:-6378692496152110661L,Amount:-0.06289703468774323d,Operation:1,Name:"Random spawn bonus"}],Name:"generic.followRange"},{Base:2.0d,Name:"generic.attackDamage"}],Invulnerable:0b,FallFlying:0b,PortalCooldown:0,AbsorptionAmount:0.0f,FallDistance:0.0f,DeathTime:0s,ForgeCaps:{"dsurround:emojidata":{as:0,es:0,et:0},"llibrary:extendedentitydatacapability":{"mm:living":{frozenYaw:0.0f,freezeProgress:0.0f,frozenPitch:0.0f,frozenYawHead:0.0f,frozenEntityID:-1,frozenLimbSwingAmount:0.0f,frozenRenderYawOffset:0.0f,frozenSwingProgress:0.0f}}},HandDropChances:[0.085f,0.085f],PersistenceRequired:0b,Motion:[0.0d,-0.0784000015258789d,0.0d],Leashed:0b,Health:20.0f,LeftHanded:0b,Air:300s,OnGround:1b,Dimension:0,Rotation:[23.780464f,0.0f],UpdateBlocked:0b,HandItems:[{id:"minecraft:bow",Count:1b,Damage:0s},{}],ArmorDropChances:[0.085f,0.085f,0.085f,0.085f],Pos:[878.6103612378545d,94.0d,332.25459477313484d],Fire:-1s,ArmorItems:[{},{},{},{}],CanPickUpLoot:0b,HurtTime:0s}}
:enddata
:endentity

entity:
plugin=entity
number=8
data:
JSON:{yOffset:0.0f,xOffset:0.3f,rotation:181.60542f,mobID:"minecraft:skeleton",zOffset:0.05208019f,position:2199157473286L,entityData:{HurtByTimestamp:0,ForgeData:{},Attributes:[{Base:20.0d,Name:"generic.maxHealth"},{Base:0.0d,Name:"generic.knockbackResistance"},{Base:0.25d,Name:"generic.movementSpeed"},{Base:0.0d,Name:"generic.armor"},{Base:0.0d,Name:"generic.armorToughness"},{Base:1.0d,Name:"forge.swimSpeed"},{Base:16.0d,Modifiers:[{UUIDMost:-1035571341862352555L,UUIDLeast:-6022676918742206747L,Amount:-0.03478190399060815d,Operation:1,Name:"Random spawn bonus"}],Name:"generic.followRange"},{Base:2.0d,Name:"generic.attackDamage"}],Invulnerable:0b,FallFlying:0b,PortalCooldown:0,AbsorptionAmount:0.0f,FallDistance:0.0f,DeathTime:0s,ForgeCaps:{"dsurround:emojidata":{as:0,es:0,et:0},"llibrary:extendedentitydatacapability":{"mm:living":{frozenYaw:0.0f,freezeProgress:0.0f,frozenPitch:0.0f,frozenYawHead:0.0f,frozenEntityID:-1,frozenLimbSwingAmount:0.0f,frozenRenderYawOffset:0.0f,frozenSwingProgress:0.0f}}},HandDropChances:[0.085f,0.085f],PersistenceRequired:0b,Motion:[0.0d,-0.0784000015258789d,0.0d],Leashed:0b,Health:20.0f,LeftHanded:0b,Air:300s,OnGround:1b,Dimension:0,Rotation:[91.60542f,0.0f],UpdateBlocked:0b,HandItems:[{id:"minecraft:bow",Count:1b,Damage:0s},{}],ArmorDropChances:[0.085f,0.085f,0.085f,0.085f],Pos:[877.0520801910229d,94.0d,332.69999998807907d],Fire:-1s,ArmorItems:[{},{},{},{}],CanPickUpLoot:0b,HurtTime:0s}}
:enddata
:endentity

entity:
plugin=entity
number=9
data:
JSON:{yOffset:0.0f,xOffset:0.8366435f,rotation:108.33442f,mobID:"minecraft:skeleton",zOffset:0.34694904f,position:2199157473285L,entityData:{HurtByTimestamp:0,ForgeData:{},Attributes:[{Base:20.0d,Name:"generic.maxHealth"},{Base:0.0d,Name:"generic.knockbackResistance"},{Base:0.25d,Name:"generic.movementSpeed"},{Base:0.0d,Name:"generic.armor"},{Base:0.0d,Name:"generic.armorToughness"},{Base:1.0d,Name:"forge.swimSpeed"},{Base:16.0d,Modifiers:[{UUIDMost:3445651937808435779L,UUIDLeast:-8893998257319406414L,Amount:0.0368368295410219d,Operation:1,Name:"Random spawn bonus"}],Name:"generic.followRange"},{Base:2.0d,Name:"generic.attackDamage"}],Invulnerable:0b,FallFlying:0b,PortalCooldown:0,AbsorptionAmount:0.0f,FallDistance:0.0f,DeathTime:0s,ForgeCaps:{"dsurround:emojidata":{as:0,es:0,et:0},"llibrary:extendedentitydatacapability":{"mm:living":{frozenYaw:0.0f,freezeProgress:0.0f,frozenPitch:0.0f,frozenYawHead:0.0f,frozenEntityID:-1,frozenLimbSwingAmount:0.0f,frozenRenderYawOffset:0.0f,frozenSwingProgress:0.0f}}},HandDropChances:[0.085f,0.085f],PersistenceRequired:0b,Motion:[0.0d,-0.0784000015258789d,0.0d],Leashed:0b,Health:20.0f,LeftHanded:0b,Air:300s,OnGround:1b,Dimension:0,Rotation:[18.33442f,0.0f],UpdateBlocked:0b,HandItems:[{id:"minecraft:bow",Count:1b,Damage:0s},{}],ArmorDropChances:[0.085f,0.085f,0.085f,0.085f],Pos:[876.3469490415314d,94.0d,332.1633564771294d],Fire:-1s,ArmorItems:[{},{},{},{}],CanPickUpLoot:0b,HurtTime:0s}}
:enddata
:endentity

entity:
plugin=entity
number=10
data:
JSON:{yOffset:0.0f,xOffset:0.7625f,rotation:18.652283f,mobID:"minecraft:zombie",zOffset:0.9476007f,position:3848424914946L,entityData:{HurtByTimestamp:0,ForgeData:{},Attributes:[{Base:20.0d,Name:"generic.maxHealth"},{Base:0.0d,Modifiers:[{UUIDMost:-5464874507916195894L,UUIDLeast:-7260580793333381884L,Amount:0.01201767267578001d,Operation:0,Name:"Random spawn bonus"}],Name:"generic.knockbackResistance"},{Base:0.23000000417232513d,Name:"generic.movementSpeed"},{Base:2.0d,Name:"generic.armor"},{Base:0.0d,Name:"generic.armorToughness"},{Base:1.0d,Name:"forge.swimSpeed"},{Base:35.0d,Modifiers:[{UUIDMost:-6616582537322476466L,UUIDLeast:-8836177718575054692L,Amount:8.158676217033876E-4d,Operation:1,Name:"Random spawn bonus"}],Name:"generic.followRange"},{Base:3.0d,Name:"generic.attackDamage"},{Base:0.0510404755025336d,Name:"zombie.spawnReinforcements"}],Invulnerable:0b,FallFlying:0b,PortalCooldown:0,AbsorptionAmount:0.0f,FallDistance:0.0f,DeathTime:0s,ForgeCaps:{"dsurround:emojidata":{as:0,es:0,et:0},"llibrary:extendedentitydatacapability":{"mm:living":{frozenYaw:0.0f,freezeProgress:0.0f,frozenPitch:0.0f,frozenYawHead:0.0f,frozenEntityID:-1,frozenLimbSwingAmount:0.0f,frozenRenderYawOffset:0.0f,frozenSwingProgress:0.0f}}},HandDropChances:[0.085f,0.085f],PersistenceRequired:0b,Motion:[0.0d,-0.0784000015258789d,0.0d],Leashed:0b,Health:20.0f,LeftHanded:0b,Air:300s,OnGround:1b,Dimension:0,Rotation:[288.65228f,0.0f],UpdateBlocked:0b,HandItems:[{},{}],ArmorDropChances:[0.085f,0.085f,0.085f,0.085f],Pos:[873.94760071163d,94.0d,326.23750001192093d],CanBreakDoors:0b,Fire:-1s,ArmorItems:[{},{},{},{}],CanPickUpLoot:0b,HurtTime:0s}}
:enddata
:endentity

entity:
plugin=entity
number=11
data:
JSON:{yOffset:0.0f,xOffset:0.3f,rotation:72.9321f,mobID:"minecraft:skeleton",zOffset:0.29834285f,position:2199157473284L,entityData:{HurtByTimestamp:0,ForgeData:{},Attributes:[{Base:20.0d,Name:"generic.maxHealth"},{Base:0.0d,Name:"generic.knockbackResistance"},{Base:0.25d,Name:"generic.movementSpeed"},{Base:0.0d,Name:"generic.armor"},{Base:0.0d,Name:"generic.armorToughness"},{Base:1.0d,Name:"forge.swimSpeed"},{Base:16.0d,Modifiers:[{UUIDMost:-1072563545965838207L,UUIDLeast:-5172342916285458007L,Amount:0.0733985774833394d,Operation:1,Name:"Random spawn bonus"}],Name:"generic.followRange"},{Base:2.0d,Name:"generic.attackDamage"}],Invulnerable:0b,FallFlying:0b,PortalCooldown:0,AbsorptionAmount:0.0f,FallDistance:0.0f,DeathTime:0s,ForgeCaps:{"dsurround:emojidata":{as:0,es:0,et:0},"llibrary:extendedentitydatacapability":{"mm:living":{frozenYaw:0.0f,freezeProgress:0.0f,frozenPitch:0.0f,frozenYawHead:0.0f,frozenEntityID:-1,frozenLimbSwingAmount:0.0f,frozenRenderYawOffset:0.0f,frozenSwingProgress:0.0f}}},HandDropChances:[0.085f,0.085f],PersistenceRequired:0b,Motion:[0.024004981672617443d,-0.0784000015258789d,0.0d],Leashed:0b,Health:20.0f,LeftHanded:0b,Air:300s,OnGround:1b,Dimension:0,Rotation:[342.9321f,0.0f],UpdateBlocked:0b,HandItems:[{id:"minecraft:bow",Count:1b,Damage:0s},{}],ArmorDropChances:[0.085f,0.085f,0.085f,0.085f],Pos:[875.2983428671274d,94.0d,332.69999998807907d],Fire:-1s,ArmorItems:[{},{},{},{}],CanPickUpLoot:1b,HurtTime:0s}}
:enddata
:endentity

entity:
plugin=entity
number=12
data:
JSON:{yOffset:0.0f,xOffset:0.97164047f,rotation:268.45117f,mobID:"minecraft:zombie",zOffset:0.7f,position:3573547008003L,entityData:{HurtByTimestamp:0,ForgeData:{},Attributes:[{Base:20.0d,Name:"generic.maxHealth"},{Base:0.0d,Modifiers:[{UUIDMost:2700673399828398307L,UUIDLeast:-6208842486668105508L,Amount:0.0021179664338005764d,Operation:0,Name:"Random spawn bonus"}],Name:"generic.knockbackResistance"},{Base:0.23000000417232513d,Name:"generic.movementSpeed"},{Base:2.0d,Name:"generic.armor"},{Base:0.0d,Name:"generic.armorToughness"},{Base:1.0d,Name:"forge.swimSpeed"},{Base:35.0d,Modifiers:[{UUIDMost:-3728819140424613719L,UUIDLeast:-8441200050651377931L,Amount:-0.04361226392451638d,Operation:1,Name:"Random spawn bonus"}],Name:"generic.followRange"},{Base:3.0d,Name:"generic.attackDamage"},{Base:0.049488547919041594d,Name:"zombie.spawnReinforcements"}],Invulnerable:0b,FallFlying:0b,PortalCooldown:0,AbsorptionAmount:0.0f,FallDistance:0.0f,DeathTime:0s,ForgeCaps:{"dsurround:emojidata":{as:0,es:0,et:0},"llibrary:extendedentitydatacapability":{"mm:living":{frozenYaw:0.0f,freezeProgress:0.0f,frozenPitch:0.0f,frozenYawHead:0.0f,frozenEntityID:-1,frozenLimbSwingAmount:0.0f,frozenRenderYawOffset:0.0f,frozenSwingProgress:0.0f}}},HandDropChances:[0.085f,0.085f],PersistenceRequired:0b,Motion:[0.0d,-0.0784000015258789d,0.0d],Leashed:0b,Health:20.0f,LeftHanded:0b,Air:300s,OnGround:1b,Dimension:0,Rotation:[178.45116f,0.0f],UpdateBlocked:0b,HandItems:[{},{}],ArmorDropChances:[0.085f,0.085f,0.085f,0.085f],Pos:[874.6999999880791d,94.0d,327.0283595207832d],CanBreakDoors:0b,Fire:-1s,ArmorItems:[{},{},{},{}],CanPickUpLoot:0b,HurtTime:0s}}
:enddata
:endentity

entity:
plugin=entity
number=13
data:
JSON:{yOffset:0.0f,xOffset:0.03719306f,rotation:352.71863f,mobID:"minecraft:zombie",zOffset:0.9641578f,position:2474035380232L,entityData:{HurtByTimestamp:0,ForgeData:{},IsBaby:1b,Attributes:[{Base:20.0d,Name:"generic.maxHealth"},{Base:0.0d,Modifiers:[{UUIDMost:-4398304528109514868L,UUIDLeast:-6121292719266527733L,Amount:0.03517777581939924d,Operation:0,Name:"Random spawn bonus"}],Name:"generic.knockbackResistance"},{Base:0.23000000417232513d,Modifiers:[{UUIDMost:-5082757096938257406L,UUIDLeast:-4891139119377885130L,Amount:0.5d,Operation:1,Name:"Baby speed boost"}],Name:"generic.movementSpeed"},{Base:2.0d,Name:"generic.armor"},{Base:0.0d,Name:"generic.armorToughness"},{Base:1.0d,Name:"forge.swimSpeed"},{Base:35.0d,Modifiers:[{UUIDMost:-8498988003517052768L,UUIDLeast:-8772122019229926139L,Amount:-0.003771769248349181d,Operation:1,Name:"Random spawn bonus"}],Name:"generic.followRange"},{Base:3.0d,Name:"generic.attackDamage"},{Base:0.0769666046786428d,Name:"zombie.spawnReinforcements"}],Invulnerable:0b,FallFlying:0b,PortalCooldown:0,AbsorptionAmount:0.0f,FallDistance:0.0f,DeathTime:0s,ForgeCaps:{"dsurround:emojidata":{as:0,es:0,et:0},"llibrary:extendedentitydatacapability":{"mm:living":{frozenYaw:0.0f,freezeProgress:0.0f,frozenPitch:0.0f,frozenYawHead:0.0f,frozenEntityID:-1,frozenLimbSwingAmount:0.0f,frozenRenderYawOffset:0.0f,frozenSwingProgress:0.0f}}},HandDropChances:[0.085f,0.085f],PersistenceRequired:0b,Motion:[0.0d,-0.0784000015258789d,0.0d],Leashed:0b,Health:20.0f,LeftHanded:0b,Air:300s,OnGround:1b,Dimension:0,Rotation:[262.71863f,0.0f],UpdateBlocked:0b,HandItems:[{},{}],ArmorDropChances:[0.085f,0.085f,0.085f,0.085f],Pos:[879.964157831106d,94.0d,331.9628069680295d],CanBreakDoors:0b,Fire:-1s,ArmorItems:[{},{},{},{}],CanPickUpLoot:0b,HurtTime:0s}}
:enddata
:endentity

entity:
plugin=entity
number=14
data:
JSON:{yOffset:0.0f,xOffset:0.5568522f,rotation:180.04712f,mobID:"minecraft:zombie",zOffset:0.010143576f,position:3573882552324L,entityData:{HurtByTimestamp:0,ForgeData:{},Attributes:[{Base:20.0d,Name:"generic.maxHealth"},{Base:0.0d,Modifiers:[{UUIDMost:-5224354064291576744L,UUIDLeast:-5392843529519861960L,Amount:0.04763696984129988d,Operation:0,Name:"Random spawn bonus"}],Name:"generic.knockbackResistance"},{Base:0.23000000417232513d,Name:"generic.movementSpeed"},{Base:2.0d,Name:"generic.armor"},{Base:0.0d,Name:"generic.armorToughness"},{Base:1.0d,Name:"forge.swimSpeed"},{Base:35.0d,Modifiers:[{UUIDMost:1358340297288206240L,UUIDLeast:-6480871801990082070L,Amount:0.05470119088796443d,Operation:1,Name:"Random spawn bonus"}],Name:"generic.followRange"},{Base:3.0d,Name:"generic.attackDamage"},{Base:0.056443513147687974d,Name:"zombie.spawnReinforcements"}],Invulnerable:0b,FallFlying:0b,PortalCooldown:0,AbsorptionAmount:0.0f,FallDistance:0.0f,DeathTime:0s,ForgeCaps:{"dsurround:emojidata":{as:1,es:0,et:0},"llibrary:extendedentitydatacapability":{"mm:living":{frozenYaw:0.0f,freezeProgress:0.0f,frozenPitch:0.0f,frozenYawHead:0.0f,frozenEntityID:-1,frozenLimbSwingAmount:0.0f,frozenRenderYawOffset:0.0f,frozenSwingProgress:0.0f}}},HandDropChances:[0.085f,0.085f],PersistenceRequired:0b,Motion:[0.0d,-0.0784000015258789d,0.0d],Leashed:0b,Health:12.0f,LeftHanded:0b,Air:300s,OnGround:1b,Dimension:0,Rotation:[90.04712f,0.0f],UpdateBlocked:0b,HandItems:[{},{}],ArmorDropChances:[0.085f,0.085f,0.085f,0.085f],Pos:[875.010143576174d,99.0d,327.443147819081d],CanBreakDoors:0b,Fire:-1s,ArmorItems:[{},{},{},{}],CanPickUpLoot:0b,HurtTime:0s}}
:enddata
:endentity

entity:
plugin=entity
number=15
data:
