# Ancient Warfare Structure Template File
# Auto-generated structure template file. created on: 8/19/2019 at: 10:23:17
# Lines beginning with # denote comments

header:
version=2.9
name=ELBWizardsTowerGeneric
mods=ebwizardry
size=20,104,28
offset=9,13,27
:endheader

#### VALIDATION ####
validation:
type=ground
survival=false
worldGenEnabled=true
unique=false
preserveBlocks=false
selectionWeight=50
clusterValue=50
minDuplicateDistance=997
dimensionWhiteList=true
dimensionList=0
biomeWhiteList=true
biomeList=minecraft:extreme_hills,minecraft:taiga,biomesoplenty:mountain_foothills,biomesoplenty:mystic_grove,minecraft:redwood_taiga_hills,biomesoplenty:moor,minecraft:forest_hills,minecraft:birch_forest_hills,biomesoplenty:alps_foothills
leveling=5
fill=5
border=5
blockSwap=false
:endvalidation

#### LAYERS ####
layer: 0
1,1,1,1,1,1,1,1,1,1,1,1,1,1,1,1,1,1,1,1
1,1,1,1,1,1,1,1,1,1,1,1,1,1,1,1,1,1,1,1
1,1,1,1,1,1,1,1,1,1,1,1,1,1,1,1,1,1,1,1
1,1,2,1,1,1,1,1,0,1,1,1,1,1,1,1,1,1,1,1
1,1,1,1,1,1,1,1,1,1,1,1,3,3,1,1,1,1,1,1
1,1,1,1,1,1,1,1,1,1,4,3,3,3,1,1,1,1,1,1
1,1,1,1,1,1,1,1,1,1,1,3,3,1,1,1,1,1,1,1
1,1,1,1,1,1,1,1,1,1,1,1,1,1,1,1,1,1,1,1
1,1,1,1,1,1,1,1,1,1,1,1,1,1,1,1,1,1,1,1
1,1,1,1,1,1,1,1,1,1,1,1,1,1,1,1,1,1,1,1
1,1,1,1,1,1,1,1,1,1,1,1,1,1,1,1,1,1,1,1
1,1,1,0,1,1,3,3,1,1,1,1,1,1,1,1,1,1,1,1
1,1,0,0,1,1,3,3,1,1,1,1,1,1,1,1,1,1,1,1
1,1,0,0,1,0,0,1,1,1,1,1,1,1,1,1,1,1,1,1
1,1,0,0,1,0,0,1,1,1,1,1,1,1,1,1,1,1,1,1
1,1,0,0,1,0,0,0,1,1,1,1,1,1,1,1,1,1,1,1
1,1,0,1,1,0,0,0,0,1,1,1,1,1,1,1,1,1,1,1
1,1,1,1,1,0,0,0,0,0,1,1,1,1,1,1,1,1,1,1
1,1,1,1,1,1,0,0,0,1,1,1,1,1,1,1,1,1,1,1
1,1,1,1,1,1,0,0,1,1,1,1,1,1,1,1,1,1,1,1
1,1,1,1,1,1,1,1,1,1,1,1,1,5,1,1,1,1,1,1
1,1,1,1,1,1,1,1,1,1,5,5,5,5,1,1,1,1,1,1
1,1,1,1,1,1,1,1,1,5,5,5,5,5,1,1,1,1,1,1
1,1,1,1,1,1,1,1,1,1,5,5,1,1,1,1,1,1,1,1
1,1,1,1,1,1,1,1,1,1,1,1,1,1,1,1,1,1,1,1
1,1,1,1,1,1,1,1,1,1,1,1,1,1,1,1,1,1,1,1
1,1,1,1,1,1,1,1,1,1,1,1,1,1,1,1,1,1,1,1
1,1,1,1,1,1,1,1,1,1,1,1,1,1,1,1,1,1,1,1
:endlayer
layer: 1
1,1,1,1,1,1,1,1,1,1,1,1,1,1,1,1,1,1,1,1
1,1,1,1,1,1,1,1,1,1,1,1,1,1,1,1,1,1,1,1
1,1,1,1,1,1,1,1,1,1,1,1,1,1,1,1,1,1,1,1
1,1,2,1,1,1,1,1,1,1,1,1,1,1,1,1,1,1,1,1
1,1,1,1,1,1,1,1,1,1,4,4,3,3,1,1,1,1,1,1
1,1,1,1,1,1,1,1,4,4,4,3,3,3,1,1,1,1,1,1
1,1,1,1,1,1,1,1,4,4,4,3,3,1,1,1,1,1,1,1
1,1,1,1,1,1,1,4,4,4,4,4,1,1,1,1,1,1,1,1
1,1,1,1,1,1,1,4,4,4,1,1,1,1,1,1,1,1,1,1
1,1,1,1,1,1,1,1,1,1,1,1,1,1,1,1,1,1,1,1
1,1,1,1,1,1,1,1,1,1,1,1,1,1,1,1,4,1,1,1
1,1,1,6,6,6,1,1,1,1,1,1,1,1,1,4,4,4,1,1
1,1,6,0,6,1,1,1,1,1,1,1,1,1,1,1,4,4,1,1
1,1,1,1,1,1,1,1,1,1,1,1,1,1,1,1,1,4,1,1
1,1,0,1,1,1,1,1,1,1,1,1,1,1,1,1,1,1,1,1
1,1,0,1,1,1,1,1,1,1,1,1,1,1,1,1,1,1,1,1
1,1,0,1,1,1,1,1,1,1,1,1,1,1,1,1,1,1,1,1
1,1,1,1,1,1,1,1,1,1,1,1,1,1,1,1,1,1,1,1
1,1,1,1,1,1,1,1,1,1,1,1,1,1,1,1,1,1,1,1
1,1,1,1,1,1,1,1,1,1,1,1,1,1,1,1,1,1,1,1
1,1,1,1,1,1,1,1,1,1,1,1,1,1,1,1,1,1,1,1
1,1,1,1,1,1,1,0,1,1,1,1,5,5,1,1,1,1,1,1
1,1,1,1,1,1,1,1,0,1,0,1,5,1,1,1,1,1,1,1
1,1,1,1,1,1,1,1,1,1,1,1,1,1,1,1,1,1,1,1
1,1,1,1,1,1,1,1,1,1,1,1,1,1,1,1,5,5,1,1
1,1,1,1,1,1,1,1,1,1,1,1,1,1,1,1,5,5,1,1
1,1,1,1,1,1,1,1,1,1,1,1,1,1,1,1,1,1,1,1
1,1,1,1,1,1,1,1,1,1,1,1,1,1,1,1,1,1,1,1
:endlayer
layer: 2
1,1,1,1,1,1,1,1,1,1,1,1,1,1,1,1,1,1,1,1
1,1,1,1,1,1,1,1,1,1,1,1,1,1,1,1,1,1,1,1
1,1,1,1,1,1,1,1,1,1,1,1,1,1,1,1,1,1,1,1
1,1,1,1,1,1,1,1,1,1,1,1,1,1,1,1,1,1,1,1
1,1,1,1,1,1,1,1,1,4,4,4,4,1,1,1,1,1,1,1
1,1,1,1,1,1,1,1,4,4,4,4,4,1,1,1,1,1,1,1
1,1,1,1,1,1,4,4,4,4,4,3,4,1,1,1,1,1,1,1
1,1,1,1,1,1,4,4,4,4,4,4,1,1,1,1,1,1,1,1
1,1,1,1,1,1,4,4,4,4,4,1,1,1,1,1,1,1,1,1
1,1,1,1,1,1,1,4,4,1,1,1,1,1,4,4,4,1,1,1
1,1,1,1,1,1,1,1,1,1,1,1,1,1,4,4,4,4,1,1
1,1,1,1,6,6,1,1,1,1,1,1,1,1,4,4,4,4,1,1
1,1,1,6,1,1,1,1,1,1,1,1,1,1,1,4,4,4,1,1
1,1,1,1,1,1,1,1,1,1,1,1,1,1,1,1,4,4,1,1
1,1,1,1,1,1,1,1,1,1,1,1,1,1,1,3,4,4,1,1
1,1,1,1,1,1,1,1,1,1,1,1,1,1,1,1,1,1,1,1
1,1,1,1,1,1,1,1,1,1,1,1,1,1,1,1,1,1,1,1
1,1,1,1,1,1,1,1,1,1,1,1,1,1,1,1,1,1,1,1
1,1,1,1,1,1,1,1,1,1,1,1,1,1,1,1,1,1,1,1
1,1,1,1,1,1,1,1,1,1,1,1,1,1,1,1,1,1,1,1
1,1,1,1,0,1,1,1,1,1,1,1,1,1,1,1,1,1,1,1
1,1,1,1,1,1,1,0,1,1,1,1,1,1,1,1,4,1,1,1
1,1,1,1,1,1,1,1,0,0,0,1,1,1,4,4,4,1,1,1
1,1,1,1,1,1,1,1,1,0,0,1,1,1,4,4,4,1,1,1
1,1,1,1,1,1,1,1,1,1,1,1,1,1,4,5,5,5,1,1
1,1,1,1,1,1,1,1,1,1,4,4,1,1,1,1,5,5,1,1
1,1,1,1,1,1,1,1,1,1,1,1,1,1,1,1,1,1,1,1
1,1,1,1,1,1,1,1,1,1,1,1,1,1,1,1,1,1,1,1
:endlayer
layer: 3
1,1,1,1,1,1,1,1,1,1,1,1,1,1,1,1,1,1,1,1
1,1,1,1,1,1,1,1,1,1,1,1,1,1,1,1,1,1,1,1
1,1,1,1,1,1,1,1,1,1,1,7,7,7,7,7,1,1,1,1
1,1,1,1,1,1,1,1,1,1,1,1,7,7,7,7,1,1,1,1
1,1,1,1,1,1,1,1,1,4,4,4,1,1,1,1,1,1,1,1
1,1,1,1,1,1,1,1,4,4,4,4,4,1,1,1,1,1,1,1
1,1,1,1,1,1,4,4,4,4,4,4,4,1,1,1,1,1,1,1
1,1,1,1,1,4,4,4,4,4,4,4,1,1,1,1,1,1,1,1
1,1,1,1,1,4,4,4,4,4,4,1,1,1,1,1,1,1,1,1
1,1,1,1,4,4,4,4,4,1,1,1,1,1,4,4,4,1,1,1
1,1,3,1,1,1,1,1,1,1,1,1,1,1,4,4,4,4,1,1
1,1,1,1,1,1,1,1,1,1,1,1,1,1,4,4,4,4,1,1
1,1,1,1,1,1,1,1,1,1,1,1,1,1,1,4,4,4,1,1
1,1,1,1,1,0,0,1,1,1,1,1,1,1,1,4,4,4,1,1
1,1,1,1,1,0,1,1,1,1,1,1,1,1,1,3,4,4,1,1
1,1,1,1,1,1,1,1,1,1,1,1,1,1,1,1,1,4,1,1
1,1,1,1,1,1,1,1,1,1,1,1,1,1,1,1,1,1,1,1
1,1,1,1,1,1,1,1,1,1,1,1,1,1,1,1,1,1,1,1
1,1,1,1,1,1,1,1,1,1,1,1,1,1,1,1,1,1,1,1
1,1,1,0,1,1,0,0,1,1,1,1,1,1,1,4,4,4,1,1
1,1,1,1,1,1,0,0,1,1,1,1,1,5,5,4,4,4,1,1
1,1,1,1,1,1,1,1,1,1,1,1,1,5,4,4,4,4,1,1
1,1,1,1,1,1,1,1,1,1,1,1,1,4,4,4,4,4,1,1
1,1,1,1,1,1,1,1,1,0,1,1,1,4,4,4,4,1,1,1
1,1,1,1,1,1,1,1,1,1,1,1,1,4,4,4,4,5,1,1
1,1,1,1,1,1,1,1,1,1,4,4,4,4,4,1,5,5,1,1
1,1,1,1,1,1,1,1,1,1,1,1,1,1,1,1,1,1,1,1
1,1,1,1,1,1,1,1,1,1,1,1,1,1,1,1,1,1,1,1
:endlayer
layer: 4
1,1,1,1,1,1,1,1,1,1,1,1,1,1,1,1,1,1,1,1
1,1,1,1,1,1,1,1,1,1,1,1,1,1,1,1,1,1,1,1
1,1,1,1,1,1,1,1,1,1,7,7,7,7,7,7,7,1,1,1
1,1,1,1,1,1,1,1,1,1,1,7,7,7,7,7,7,1,1,1
1,1,1,1,1,1,1,1,1,1,1,1,1,1,7,7,7,1,1,1
1,1,1,1,1,1,1,1,4,4,4,1,1,1,1,1,1,1,1,1
1,1,1,1,1,1,1,4,4,4,4,1,1,1,1,1,1,1,1,1
1,1,1,1,1,1,4,4,4,4,4,1,1,1,1,1,1,1,1,1
1,1,1,1,1,4,4,4,4,4,1,1,1,1,1,1,1,1,1,1
1,1,3,3,4,4,4,1,1,1,1,1,1,1,1,1,1,1,1,1
1,1,3,3,1,1,1,1,1,1,1,1,1,1,1,4,4,4,1,1
1,1,1,1,1,1,1,1,1,1,1,1,1,1,1,4,4,4,1,1
1,1,1,1,1,1,1,1,1,1,1,1,1,1,1,4,4,4,1,1
1,1,1,1,1,1,1,1,1,1,1,1,1,1,1,1,4,4,1,1
1,1,1,1,1,1,1,1,1,1,1,1,1,1,1,1,4,4,1,1
1,1,1,1,1,1,1,1,1,1,1,1,1,1,1,1,1,1,1,1
1,1,1,0,1,1,1,1,1,1,1,1,1,1,1,1,1,1,1,1
1,1,1,1,1,1,1,1,1,1,1,1,1,1,1,1,1,1,1,1
1,1,1,1,1,1,1,1,1,1,1,1,1,1,1,1,4,4,1,1
1,1,1,1,1,1,1,1,1,1,1,1,1,1,1,4,4,4,1,1
1,1,1,1,1,1,1,1,1,1,1,1,1,5,4,4,4,4,1,1
1,1,1,1,1,1,1,1,1,1,1,1,1,5,4,4,4,4,1,1
1,1,1,1,1,1,1,1,1,1,1,1,1,4,4,4,4,4,1,1
1,1,1,1,1,1,1,1,1,1,1,1,1,4,4,4,4,4,1,1
1,1,1,1,1,1,1,1,1,1,1,1,1,4,4,4,4,1,1,1
1,1,1,1,1,1,1,1,1,1,1,1,4,4,4,4,1,1,1,1
1,1,1,1,1,1,1,1,1,1,1,1,1,1,1,1,1,1,1,1
1,1,1,1,1,1,1,1,1,1,1,1,1,1,1,1,1,1,1,1
:endlayer
layer: 5
1,1,1,1,1,1,1,1,1,1,1,1,1,1,1,1,1,1,1,1
1,1,1,1,1,1,1,1,1,1,1,1,1,1,1,1,1,1,1,1
1,1,1,1,1,1,1,1,1,1,7,7,7,7,7,7,7,1,1,1
1,1,1,1,1,1,1,1,1,1,1,7,7,7,7,7,7,1,1,1
1,1,1,1,1,1,1,1,1,1,1,1,1,0,7,7,7,1,1,1
1,1,1,1,1,1,1,1,1,1,1,1,0,0,1,1,1,1,1,1
1,1,1,1,1,1,1,1,1,1,1,1,1,1,1,1,1,1,1,1
1,1,1,1,1,1,1,1,1,1,1,1,1,1,0,0,1,1,1,1
1,1,1,1,1,1,1,1,1,1,1,1,1,1,0,0,1,1,1,1
1,1,1,3,1,1,1,1,1,1,1,1,1,1,1,1,1,1,1,1
1,1,1,1,1,1,1,1,1,1,1,1,1,1,1,1,1,1,1,1
1,1,1,1,1,1,1,1,1,1,1,1,1,1,1,1,1,1,1,1
1,1,1,1,1,1,1,1,1,1,1,1,1,1,1,1,1,4,1,1
1,1,1,1,1,1,1,1,1,1,1,1,1,1,1,1,1,4,1,1
1,1,1,1,1,1,1,1,1,1,1,1,1,1,1,1,1,1,1,1
1,1,1,1,1,1,1,1,1,1,1,1,1,1,1,1,1,1,1,1
1,1,1,0,1,1,1,1,1,1,1,1,1,1,1,1,1,1,1,1
1,1,5,1,1,1,1,1,1,1,1,1,1,1,1,1,1,1,1,1
1,1,1,1,1,1,1,1,1,1,1,1,1,1,1,1,4,4,1,1
1,1,1,1,1,1,1,1,1,1,1,1,1,1,1,4,4,4,1,1
1,1,1,1,1,1,1,1,1,1,1,1,1,1,1,4,4,4,1,1
1,1,1,1,1,1,1,1,1,1,1,1,1,1,4,4,4,4,1,1
1,1,1,1,1,1,1,1,1,1,1,1,1,4,4,4,4,4,1,1
1,1,1,1,1,1,1,1,1,1,1,1,1,4,4,4,4,1,1,1
1,1,1,1,1,1,1,1,1,1,1,1,1,1,4,4,4,1,1,1
1,1,1,1,1,1,1,1,1,1,1,1,1,1,1,1,1,1,1,1
1,1,1,1,1,1,1,1,1,1,1,1,1,1,1,1,1,1,1,1
1,1,1,1,1,1,1,1,1,1,1,1,1,1,1,1,1,1,1,1
:endlayer
layer: 6
1,1,1,1,1,1,1,1,1,1,1,1,1,1,1,1,1,1,1,1
1,1,1,1,1,1,1,1,1,1,1,1,1,1,1,1,1,1,1,1
1,1,1,1,1,1,1,1,1,1,1,7,7,7,7,7,1,1,1,1
1,1,1,1,1,1,1,1,1,1,1,1,7,7,7,7,1,1,1,1
1,1,1,1,1,1,1,1,1,1,1,1,1,0,1,1,1,1,1,1
1,1,1,1,1,1,1,1,1,1,1,1,0,0,1,1,1,1,1,1
1,1,1,1,1,1,1,1,1,1,1,1,0,0,1,1,1,1,1,1
1,1,1,1,1,1,1,1,1,1,1,1,0,1,1,1,1,1,1,1
1,1,1,1,1,1,1,1,1,1,1,1,1,1,3,1,1,1,1,1
1,1,1,1,1,1,1,1,1,1,1,1,1,3,3,1,1,1,1,1
1,1,1,1,1,1,1,1,1,1,1,1,1,1,1,1,1,1,1,1
1,1,1,1,1,1,1,1,1,1,1,1,1,1,1,1,1,1,1,1
1,1,1,1,1,1,1,1,1,1,1,1,1,1,1,1,1,1,1,1
1,1,1,1,1,1,1,1,1,1,1,1,1,1,1,1,1,1,1,1
1,1,1,1,1,1,1,1,1,1,1,1,1,1,1,1,1,1,1,1
1,1,1,1,1,1,1,1,1,1,1,1,1,1,1,1,1,1,1,1
1,1,1,1,1,1,1,1,1,1,1,1,1,1,1,1,1,1,1,1
1,1,5,1,1,1,1,1,1,1,1,1,1,1,1,1,1,1,1,1
1,1,1,1,1,1,1,1,1,1,1,1,1,1,1,1,1,1,1,1
1,1,1,1,1,1,1,1,1,1,1,1,1,1,1,1,4,4,1,1
1,1,1,1,1,1,1,1,1,1,1,1,1,1,1,1,4,4,1,1
1,1,1,1,1,1,1,1,1,1,1,1,1,1,1,4,4,4,1,1
1,1,1,1,1,1,1,1,1,1,1,1,1,1,1,4,1,1,1,1
1,1,1,1,1,1,1,1,1,1,1,1,1,1,1,4,1,1,1,1
1,1,1,1,1,1,1,1,1,1,1,1,1,1,1,1,1,1,1,1
1,1,1,1,1,1,1,1,1,1,1,1,1,1,1,1,1,1,1,1
1,1,1,1,1,1,1,1,1,1,1,1,1,1,1,1,1,1,1,1
1,1,1,1,1,1,1,1,1,1,1,1,1,1,1,1,1,1,1,1
:endlayer
layer: 7
1,1,1,1,1,1,1,1,1,1,1,1,1,1,1,1,1,1,1,1
1,1,1,1,1,1,1,1,1,1,1,1,1,1,1,1,1,1,1,1
1,1,3,3,1,1,1,1,1,1,1,1,1,1,1,1,1,1,1,1
1,1,3,3,1,1,1,1,1,1,1,1,1,1,1,1,1,1,1,1
1,1,1,1,1,1,1,1,1,1,1,1,1,1,1,1,1,1,1,1
1,1,1,1,1,1,1,1,1,1,1,1,1,0,1,1,1,1,1,1
1,1,1,1,1,1,1,1,1,1,1,1,0,0,1,1,1,1,1,1
1,1,1,1,1,1,1,1,1,1,1,1,0,1,1,1,1,1,1,1
1,1,1,1,1,1,1,1,1,1,1,1,1,1,3,1,1,1,1,1
1,1,1,1,1,1,1,1,1,1,1,1,1,3,3,1,1,1,1,1
1,1,1,3,1,1,1,1,1,1,1,1,1,1,1,1,1,1,1,1
1,1,1,1,1,1,1,1,1,1,1,1,1,1,1,1,1,1,1,1
1,1,1,1,1,1,1,1,1,1,1,1,1,1,1,1,1,1,1,1
1,1,1,1,1,1,1,1,1,1,1,1,1,1,1,1,1,1,1,1
1,1,1,1,1,1,1,1,1,1,1,1,1,1,1,1,1,1,1,1
1,1,1,1,1,1,1,1,1,1,1,6,6,6,1,1,1,1,1,1
1,1,1,1,1,1,1,1,1,1,1,1,6,6,6,1,1,1,1,1
1,1,1,1,1,1,1,1,1,1,1,1,1,1,1,1,1,1,1,1
1,1,1,1,1,1,1,1,1,1,1,1,1,1,1,1,1,1,1,1
1,1,1,1,1,1,1,1,1,1,1,1,1,1,1,1,1,1,1,1
1,1,1,1,1,1,1,1,1,1,1,1,1,1,1,1,1,1,1,1
1,1,1,1,1,1,1,1,1,1,1,1,1,1,1,1,1,1,1,1
1,1,1,1,1,1,1,1,1,1,1,1,1,1,1,1,1,1,1,1
1,1,1,1,1,1,1,1,1,1,1,1,1,1,1,1,1,1,1,1
1,1,1,1,1,1,1,1,1,1,1,1,1,1,1,1,1,1,1,1
1,1,1,1,1,1,1,1,1,1,1,1,1,1,1,1,1,1,1,1
1,1,1,1,1,1,1,1,1,1,1,1,1,1,1,1,1,1,1,1
1,1,1,1,1,1,1,1,1,1,1,1,1,1,1,1,1,1,1,1
:endlayer
layer: 8
1,1,1,1,1,1,1,1,1,1,1,1,1,1,1,1,1,1,1,1
1,1,1,1,1,1,1,1,1,1,1,1,1,1,1,1,1,1,1,1
1,1,1,1,1,1,1,1,1,1,1,1,1,1,1,1,1,1,1,1
1,1,1,1,1,1,1,1,1,1,1,1,1,1,1,1,1,1,1,1
1,1,1,1,1,1,1,1,1,1,1,1,1,1,1,1,1,1,1,1
1,1,1,1,1,1,1,1,1,1,1,1,1,1,1,1,1,1,1,1
1,1,1,1,1,1,1,1,1,1,1,1,1,1,1,1,1,1,1,1
1,1,1,1,1,1,1,1,1,1,1,1,1,1,1,1,1,1,1,1
1,1,1,1,1,1,1,1,1,1,1,1,1,1,1,1,1,1,1,1
1,1,1,1,1,1,1,1,1,1,1,1,1,1,1,1,1,1,1,1
1,1,1,3,3,1,1,1,1,1,1,1,1,1,1,1,1,1,1,1
1,1,4,4,4,1,1,1,1,1,1,1,1,1,1,1,1,1,1,1
1,1,4,4,4,1,1,1,1,1,1,1,1,1,1,1,1,1,1,1
1,1,4,4,4,1,1,1,1,1,1,1,1,1,1,1,1,1,1,1
1,1,4,4,4,1,1,1,1,1,1,1,1,1,1,1,1,1,1,1
1,1,4,4,4,1,1,1,1,1,1,6,6,6,1,1,1,1,1,1
1,1,4,4,4,1,1,1,1,1,1,1,6,6,6,1,1,1,1,1
1,1,4,4,4,1,1,1,1,1,1,1,1,1,1,1,1,1,1,1
1,1,4,4,4,1,1,0,0,1,1,1,1,1,1,1,1,1,1,1
1,1,4,4,4,1,1,0,0,1,1,1,1,1,1,1,1,1,1,1
1,1,4,4,4,1,1,1,1,1,1,1,1,1,1,1,1,1,1,1
1,1,4,4,4,1,1,1,1,1,1,1,1,1,1,1,1,1,1,1
1,1,4,4,4,1,1,1,1,1,1,1,1,1,1,1,1,1,1,1
1,1,4,4,4,1,1,1,1,1,1,1,1,1,1,1,1,1,1,1
1,1,4,4,4,1,1,1,1,1,1,1,1,1,1,1,1,1,1,1
1,1,1,1,1,1,1,1,1,1,1,1,1,1,1,1,1,1,1,1
1,1,1,1,1,1,1,1,1,1,1,1,1,1,1,1,1,1,1,1
1,1,1,1,1,1,1,1,1,1,1,1,1,1,1,1,1,1,1,1
:endlayer
layer: 9
4,4,4,4,4,4,4,4,4,4,4,4,4,4,4,4,4,4,4,4
4,4,4,4,4,4,4,4,4,4,4,4,4,4,4,4,4,4,4,4
4,4,4,4,4,4,4,4,4,4,4,4,4,4,4,4,4,4,4,4
4,4,4,4,4,4,4,4,4,4,4,4,4,4,4,4,4,4,4,4
4,4,4,4,4,4,4,4,4,4,4,4,4,4,4,4,4,4,4,4
4,4,4,4,4,4,4,4,4,4,4,4,4,4,4,4,4,4,4,4
4,4,4,4,4,4,4,4,4,4,4,4,4,4,4,4,4,4,4,4
4,4,4,4,4,4,4,4,4,4,4,4,4,4,4,4,4,4,4,4
4,4,4,4,4,4,4,4,4,4,4,4,4,4,4,4,4,4,4,4
4,4,4,4,4,4,4,4,4,4,4,4,4,4,4,4,4,4,4,4
4,4,4,4,4,4,4,4,4,4,4,4,4,4,4,4,4,4,4,4
4,4,4,4,4,4,4,4,4,4,4,4,4,4,4,4,4,4,4,4
4,4,4,4,4,4,4,4,4,4,4,4,4,4,4,4,4,4,4,4
4,4,4,4,4,4,4,4,4,4,4,4,4,4,4,4,4,4,4,4
4,4,4,4,4,4,4,4,4,4,4,4,4,4,4,4,4,4,4,4
4,4,4,4,4,4,4,4,4,4,4,4,4,4,4,4,4,4,4,4
4,4,4,4,4,4,4,4,4,4,4,4,4,4,4,4,4,4,4,4
4,4,4,4,4,4,4,4,4,4,4,4,4,4,4,4,4,4,4,4
4,4,4,4,4,4,4,4,4,4,4,4,4,4,4,4,4,4,4,4
4,4,4,4,4,4,4,4,4,4,4,4,4,4,4,4,4,4,4,4
4,4,4,4,4,4,4,4,4,4,4,4,4,4,4,4,4,4,4,4
4,4,4,4,4,4,4,4,4,4,4,4,4,4,4,4,4,4,4,4
4,4,4,4,4,4,4,4,4,4,4,4,4,4,4,4,4,4,4,4
4,4,4,4,4,4,4,4,4,4,4,4,4,4,4,4,4,4,4,4
4,4,4,4,4,4,4,4,4,4,4,4,4,4,4,4,4,4,4,4
4,4,4,4,4,4,4,4,4,4,4,4,4,4,4,4,4,4,4,4
4,4,4,4,4,4,4,4,4,4,4,4,4,4,4,4,4,4,4,4
4,4,4,4,4,4,4,4,4,4,4,4,4,4,4,4,4,4,4,4
:endlayer
layer: 10
4,4,4,4,4,4,4,4,4,4,4,4,4,4,4,4,4,4,4,4
4,4,4,4,4,4,4,4,4,4,4,4,4,4,4,4,4,4,4,4
4,4,4,4,4,4,4,4,4,4,4,4,4,4,4,4,4,4,4,4
4,4,4,4,4,4,4,4,4,4,4,4,4,4,4,4,4,4,4,4
4,4,4,4,4,4,4,4,4,4,4,4,4,4,4,4,4,4,4,4
4,4,4,4,4,4,4,4,4,4,4,4,4,4,4,4,4,4,4,4
4,4,4,4,4,4,4,4,4,4,4,4,4,4,4,4,4,4,4,4
4,4,4,4,4,4,4,4,4,4,4,4,4,4,4,4,4,4,4,4
4,4,4,4,4,4,4,4,4,4,4,4,4,4,4,4,4,4,4,4
4,4,4,4,4,4,4,4,4,4,4,4,4,4,4,4,4,4,4,4
4,4,4,4,4,4,4,4,4,4,4,4,4,4,4,4,4,4,4,4
4,4,4,4,4,4,4,4,4,4,4,4,4,4,4,4,4,4,4,4
4,4,4,4,4,4,4,4,4,4,4,4,4,4,4,4,4,4,4,4
4,4,4,4,4,4,4,4,4,4,4,4,4,4,4,4,4,4,4,4
4,4,4,4,4,4,4,4,4,4,4,4,4,4,4,4,4,4,4,4
4,4,4,4,4,4,4,4,4,4,4,4,4,4,4,4,4,4,4,4
4,4,4,4,4,4,4,4,4,4,4,4,4,4,4,4,4,4,4,4
4,4,4,4,4,4,4,4,4,4,4,4,4,4,4,4,4,4,4,4
4,4,4,4,4,4,4,4,4,4,4,4,4,4,4,4,4,4,4,4
4,4,4,4,4,4,4,4,4,4,4,4,4,4,4,4,4,4,4,4
4,4,4,4,4,4,4,4,4,4,4,4,4,4,4,4,4,4,4,4
4,4,4,4,4,4,4,4,4,4,4,4,4,4,4,4,4,4,4,4
4,4,4,4,4,4,4,4,4,4,4,4,4,4,4,4,4,4,4,4
4,4,4,4,4,4,4,4,4,4,4,4,4,4,4,4,4,4,4,4
4,4,4,4,4,4,4,4,4,4,4,4,4,4,4,4,4,4,4,4
4,4,4,4,4,4,4,4,4,4,4,4,4,4,4,4,4,4,4,4
4,4,4,4,4,4,4,4,4,4,4,4,4,4,4,4,4,4,4,4
4,4,4,4,4,4,4,4,4,4,4,4,4,4,4,4,4,4,4,4
:endlayer
layer: 11
4,4,4,4,4,4,4,4,4,4,4,4,4,4,4,4,4,4,4,4
4,4,4,4,4,4,4,4,4,4,4,4,4,4,4,4,4,4,4,4
4,4,4,4,4,4,4,4,4,4,4,4,4,4,4,4,4,4,4,4
4,4,4,4,4,4,4,4,4,4,4,4,4,4,4,4,4,4,4,4
4,4,4,4,4,4,4,4,4,4,4,4,4,4,4,4,4,4,4,4
4,4,4,4,4,4,4,4,4,4,4,4,4,4,4,4,4,4,4,4
4,4,4,4,4,4,4,4,4,4,4,4,4,4,4,4,4,4,4,4
4,4,4,4,4,4,4,4,4,4,4,4,4,4,4,4,4,4,4,4
4,4,4,4,4,4,4,4,4,4,4,4,4,4,4,4,4,4,4,4
4,4,4,4,4,4,4,4,4,4,4,4,4,4,4,4,4,4,4,4
4,4,4,4,4,4,4,4,4,4,4,4,4,4,4,4,4,4,4,4
4,4,4,4,4,4,4,4,4,4,4,4,4,4,4,4,4,4,4,4
4,4,4,4,4,4,4,4,4,4,4,4,4,4,4,4,4,4,4,4
4,4,4,4,4,4,4,4,4,4,4,4,4,4,4,4,4,4,4,4
4,4,4,4,4,4,4,4,4,4,4,4,4,4,4,4,4,4,4,4
4,4,4,4,4,4,4,4,4,4,4,4,4,4,4,4,4,4,4,4
4,4,4,4,4,4,4,4,4,4,4,4,4,4,4,4,4,4,4,4
4,4,4,4,4,4,4,4,4,4,4,4,4,4,4,4,4,4,4,4
4,4,4,4,4,4,4,4,4,4,4,4,4,4,4,4,4,4,4,4
4,4,4,4,4,4,4,4,4,4,4,4,4,4,4,4,4,4,4,4
4,4,4,4,4,4,4,4,4,4,4,4,4,4,4,4,4,4,4,4
4,4,4,4,4,4,4,4,4,4,4,4,4,4,4,4,4,4,4,4
4,4,4,4,4,4,4,4,4,4,4,4,4,4,4,4,4,4,4,4
4,4,4,4,4,4,4,4,4,4,4,4,4,4,4,4,4,4,4,4
4,4,4,4,4,4,4,4,4,4,4,4,4,4,4,4,4,4,4,4
4,4,4,4,4,4,4,4,4,4,4,4,4,4,4,4,4,4,4,4
4,4,4,4,4,4,4,4,4,4,4,4,4,4,4,4,4,4,4,4
4,4,4,4,4,4,4,4,4,4,4,4,4,4,4,4,4,4,4,4
:endlayer
layer: 12
8,8,8,8,8,8,8,8,8,8,8,8,8,8,8,8,8,8,8,8
8,8,8,8,8,8,8,8,8,8,8,8,8,8,8,8,8,8,8,8
8,8,8,8,8,8,8,8,8,8,8,8,8,8,8,8,8,8,8,8
8,8,8,8,8,8,8,8,8,8,8,8,8,8,8,8,8,8,8,8
8,8,8,8,4,4,4,4,4,4,4,4,8,8,8,8,8,8,8,8
8,8,8,4,4,4,4,4,4,4,4,4,4,4,8,8,8,8,8,8
8,8,4,4,4,4,4,4,4,4,4,4,4,4,8,8,8,8,8,8
8,8,4,4,4,4,4,4,4,4,4,4,4,4,8,8,8,8,8,8
8,8,4,4,4,4,4,4,4,4,4,4,4,4,8,8,8,8,8,8
8,8,4,4,4,4,4,4,4,4,4,4,4,4,4,8,8,8,8,8
8,8,4,4,4,4,4,4,4,4,4,4,4,4,4,8,4,4,4,8
8,8,4,4,4,4,4,4,4,4,4,4,4,4,4,4,4,4,4,8
8,8,4,4,4,4,4,4,4,4,4,4,4,4,4,4,4,4,4,8
8,8,4,4,4,4,4,4,4,4,4,4,4,4,4,4,4,4,8,8
8,8,8,4,4,4,4,4,4,4,4,4,4,4,4,4,4,4,8,8
8,8,8,4,4,4,4,4,4,4,4,4,4,4,4,4,4,4,8,8
8,8,8,4,4,4,4,4,4,4,4,4,4,4,4,4,4,4,8,8
8,8,8,4,4,4,4,4,4,4,4,4,4,4,4,4,4,8,8,8
8,8,8,8,4,4,4,4,4,4,4,4,4,4,4,4,4,8,8,8
8,8,8,8,8,8,4,4,4,4,4,4,4,4,4,8,8,8,8,8
8,8,8,8,8,8,8,8,4,4,4,4,4,4,8,8,8,8,8,8
8,8,8,8,8,8,8,8,8,8,4,4,4,8,8,8,8,8,8,8
8,8,8,8,8,8,8,8,8,8,8,8,8,8,8,8,8,8,8,8
8,8,8,8,8,8,8,8,8,8,8,8,8,8,8,8,8,8,8,8
8,8,8,8,8,8,8,8,8,8,8,8,8,8,8,8,8,8,8,8
8,8,8,8,8,8,8,8,8,8,8,8,8,8,8,8,8,8,8,8
8,8,8,8,8,8,8,8,8,8,8,8,8,8,8,8,8,8,8,8
8,8,8,8,8,8,8,8,8,8,8,8,8,8,8,8,8,8,8,8
:endlayer
layer: 13
9,10,9,0,0,0,0,0,0,0,0,0,0,0,0,9,9,9,0,0
9,9,9,9,0,0,0,0,0,0,0,0,9,9,9,0,11,9,0,0
9,9,11,9,0,12,0,0,0,0,0,0,0,9,9,9,9,12,0,9
0,0,0,0,0,0,0,0,0,0,0,0,0,0,0,9,0,9,0,0
0,0,9,0,8,8,8,8,8,8,8,8,0,9,0,0,9,9,0,0
0,0,0,8,8,4,4,4,4,4,4,4,4,4,0,0,0,0,0,0
0,0,8,4,4,4,4,1,1,1,1,1,4,4,0,0,0,0,0,0
0,0,8,4,4,4,1,4,1,1,1,1,1,4,0,0,0,0,0,0
0,0,8,4,4,1,1,1,1,1,1,1,1,1,0,0,0,0,9,0
0,0,8,4,1,1,1,1,1,1,1,1,1,1,1,0,0,0,0,0
9,9,8,8,1,1,1,1,1,1,1,1,1,1,1,0,4,4,8,0
9,9,8,8,1,1,1,1,1,1,1,1,1,1,1,1,4,4,8,0
9,9,8,8,1,1,1,1,1,1,1,1,1,1,1,1,4,4,8,13
13,9,8,8,1,1,1,1,1,1,1,1,1,1,1,1,4,4,9,9
9,0,0,8,8,1,1,1,1,1,1,1,1,1,1,1,4,8,0,9
0,0,0,8,8,4,1,1,1,1,1,1,1,1,1,4,4,8,13,0
0,0,0,8,8,8,8,1,1,1,1,1,1,1,4,4,4,8,0,0
0,0,0,8,8,8,8,8,8,8,8,1,4,4,4,4,8,0,0,0
0,0,0,0,8,8,8,8,8,8,8,8,4,4,4,8,8,0,0,0
0,0,0,0,0,0,8,8,8,8,8,4,4,4,8,0,0,0,0,0
0,0,0,0,0,0,0,0,8,8,8,4,4,8,0,0,0,0,0,0
0,0,0,0,0,0,0,0,0,0,8,8,8,0,0,0,9,0,0,0
0,0,0,0,0,0,0,0,0,0,0,0,0,0,0,0,0,0,0,0
0,9,0,0,0,0,0,0,0,0,0,0,0,0,0,0,9,0,0,0
14,9,0,9,0,9,0,0,0,0,0,0,0,0,0,0,0,9,9,0
0,9,9,0,0,0,0,0,0,0,0,0,0,0,0,9,0,9,9,9
14,9,9,9,9,9,0,0,0,0,0,0,0,0,9,0,9,9,9,9
0,10,9,9,9,9,0,0,0,0,0,0,0,0,0,0,9,9,0,9
:endlayer
layer: 14
0,0,0,0,0,0,0,0,0,0,0,0,0,0,0,0,0,0,0,0
0,0,0,0,0,0,0,0,0,0,0,0,0,0,0,0,0,0,0,0
0,0,0,0,0,0,0,0,0,0,0,0,0,0,0,0,0,0,0,0
0,0,0,0,0,0,0,0,0,0,0,0,0,0,0,0,0,0,0,0
0,0,0,0,0,0,0,0,0,0,0,0,0,0,0,0,0,0,0,0
0,0,0,0,0,8,8,4,4,4,4,4,8,8,0,0,0,0,0,0
0,0,0,8,4,4,4,1,1,1,1,1,4,4,0,0,0,0,0,0
0,0,0,4,4,4,1,1,1,1,1,1,1,4,0,0,0,0,0,0
0,0,0,4,4,1,4,1,1,1,1,1,1,1,0,0,0,0,0,0
0,0,0,4,1,4,1,1,1,1,1,1,1,1,8,0,0,0,0,0
0,0,0,0,1,1,1,1,1,1,1,1,1,1,1,0,4,8,0,0
0,0,0,0,1,1,1,1,1,1,1,1,1,1,1,1,4,8,0,0
0,0,0,0,1,1,1,1,1,1,1,1,1,1,1,1,4,8,0,0
0,0,0,0,8,1,1,1,1,1,1,1,1,1,1,1,4,8,15,0
0,0,0,0,0,8,1,1,1,1,1,1,1,1,1,0,4,16,0,0
0,0,0,0,0,17,1,1,1,1,1,1,1,1,1,4,8,15,0,0
0,0,0,0,0,0,0,8,1,1,1,1,1,1,4,4,8,0,0,0
0,0,0,0,0,0,0,0,0,0,0,1,1,4,4,8,0,0,0,0
0,0,0,0,0,0,0,0,0,0,0,0,4,4,8,0,0,0,0,0
0,0,0,0,0,0,0,0,0,0,18,8,4,8,0,0,0,0,0,0
0,0,0,0,0,0,0,0,0,0,19,8,8,0,0,0,0,0,0,0
0,0,0,0,0,0,0,0,0,0,0,20,0,0,0,0,0,0,0,0
0,0,0,0,0,0,0,0,0,0,0,0,0,0,0,0,0,0,0,0
0,0,0,0,0,0,0,0,0,0,0,0,0,0,0,0,0,0,0,0
0,0,0,0,0,0,0,0,0,0,0,0,0,0,0,0,0,0,0,0
0,0,0,0,0,0,0,0,0,0,0,0,0,0,0,0,0,0,0,0
0,0,0,0,0,0,0,0,0,0,0,0,0,0,0,0,0,0,0,0
0,0,0,0,0,0,0,0,0,0,0,0,0,0,0,0,0,0,0,0
:endlayer
layer: 15
0,0,0,0,0,0,0,0,0,0,0,0,0,0,0,0,0,0,0,0
0,0,0,0,0,0,0,0,0,0,0,0,0,0,0,0,0,0,0,0
0,0,0,0,0,0,0,0,0,0,0,0,0,0,0,0,0,0,0,0
0,0,0,0,0,0,0,0,0,0,0,0,0,0,0,0,0,0,0,0
0,0,0,0,0,0,0,0,0,0,0,0,0,0,0,0,0,0,0,0
0,0,0,0,0,0,0,8,8,8,8,8,0,0,0,0,0,0,0,0
0,0,0,0,8,4,4,1,1,1,1,1,4,8,0,0,0,0,0,0
0,0,0,4,4,4,1,1,1,1,1,1,8,4,0,0,0,0,0,0
0,0,0,4,4,1,1,1,1,1,1,1,1,1,0,0,0,0,0,0
0,0,0,4,1,1,1,1,1,1,1,1,1,1,0,0,0,0,0,0
0,0,0,0,1,1,1,1,1,1,1,1,1,1,1,1,4,0,0,0
0,0,0,0,8,1,1,1,1,1,1,1,1,1,1,1,4,0,0,0
0,0,0,0,8,1,1,1,1,1,1,1,1,1,1,1,4,15,0,0
0,0,0,0,0,1,1,1,1,1,1,1,1,1,1,1,4,15,0,0
0,0,0,0,0,0,1,1,1,1,1,1,1,1,1,0,8,15,0,0
0,0,0,0,0,17,1,1,1,1,1,1,1,1,1,4,0,15,0,0
0,0,0,0,0,0,0,0,1,1,1,1,1,1,4,8,0,0,0,0
0,0,0,0,0,0,0,0,0,1,1,1,8,4,4,0,0,0,0,0
0,0,0,0,0,0,0,0,0,0,0,0,4,8,0,0,0,0,0,0
0,0,0,0,0,0,0,0,0,0,20,20,8,0,0,0,0,0,0,0
0,0,0,0,0,0,0,0,0,0,0,0,0,0,0,0,0,0,0,0
0,0,0,0,0,0,0,0,0,0,0,0,0,0,0,0,0,0,0,0
0,0,0,0,0,0,0,0,0,0,0,0,0,0,0,0,0,0,0,0
0,0,0,0,0,0,0,0,0,0,0,0,0,0,0,0,0,0,0,0
0,0,0,0,0,0,0,0,0,0,0,0,0,0,0,0,0,0,0,0
0,0,0,0,0,0,0,0,0,0,0,0,0,0,0,0,0,0,0,0
0,0,0,0,0,0,0,0,0,0,0,0,0,0,0,0,0,0,0,0
0,0,0,0,0,0,0,0,0,0,0,0,0,0,0,0,0,0,0,0
:endlayer
layer: 16
0,0,0,0,0,0,0,0,0,0,0,0,0,0,0,0,0,0,0,0
0,0,0,0,0,0,0,0,0,0,0,0,0,0,0,0,0,0,0,0
0,0,0,0,0,0,0,0,0,0,0,0,0,0,0,0,0,0,0,0
0,0,0,0,0,0,0,0,0,0,0,0,0,0,0,0,0,0,0,0
0,0,0,0,0,0,0,0,0,0,0,0,0,0,0,0,0,0,0,0
0,0,0,0,0,0,0,21,21,21,21,0,0,0,0,0,0,0,0,0
0,0,0,0,0,8,4,1,1,1,1,1,8,0,0,0,0,0,0,0
0,0,0,8,4,4,1,1,4,1,4,1,0,4,0,0,0,0,0,0
0,0,0,4,4,1,1,1,1,1,1,1,1,1,0,0,0,0,0,0
0,0,0,4,1,1,1,1,1,1,1,1,1,1,1,0,0,0,0,0
0,0,0,0,1,1,1,1,1,1,1,1,1,1,1,1,8,0,0,0
0,0,0,0,0,1,1,1,1,1,1,1,1,1,1,1,8,0,0,0
0,0,0,0,0,1,1,1,1,1,1,1,1,1,1,1,8,15,0,0
0,0,0,0,0,1,1,1,1,1,1,1,1,1,1,1,8,15,0,0
0,0,0,0,0,1,1,1,1,1,1,1,1,1,1,1,22,0,0,0
0,0,0,0,0,17,1,1,1,1,1,1,1,1,8,8,0,15,0,0
0,0,0,0,0,0,0,1,1,1,1,1,1,1,4,0,0,0,0,0
0,0,0,0,0,0,0,0,1,1,1,1,0,8,8,0,0,0,0,0
0,0,0,0,0,0,0,0,0,0,0,0,4,0,0,0,0,0,0,0
0,0,0,0,0,0,0,0,0,0,20,20,0,0,0,0,0,0,0,0
0,0,0,0,0,0,0,0,0,0,0,0,0,0,0,0,0,0,0,0
0,0,0,0,0,0,0,0,0,0,0,0,0,0,0,0,0,0,0,0
0,0,0,0,0,0,0,0,0,0,0,0,0,0,0,0,0,0,0,0
0,0,0,0,0,0,0,0,0,0,0,0,0,0,0,0,0,0,0,0
0,0,0,0,0,0,0,0,0,0,0,0,0,0,0,0,0,0,0,0
0,0,0,0,0,0,0,0,0,0,0,0,0,0,0,0,0,0,0,0
0,0,0,0,0,0,0,0,0,0,0,0,0,0,0,0,0,0,0,0
0,0,0,0,0,0,0,0,0,0,0,0,0,0,0,0,0,0,0,0
:endlayer
layer: 17
0,0,0,0,0,0,0,0,0,0,0,0,0,0,0,0,0,0,0,0
0,0,0,0,0,0,0,0,0,0,0,0,0,0,0,0,0,0,0,0
0,0,0,0,0,0,0,0,0,0,0,0,0,0,0,0,0,0,0,0
0,0,0,0,0,0,0,0,0,0,0,0,0,0,0,0,0,0,0,0
0,0,0,0,0,0,0,0,0,0,0,0,0,0,0,0,0,0,0,0
0,0,0,0,0,0,0,21,21,21,21,0,0,0,0,0,0,0,0,0
0,0,0,0,0,0,8,8,1,1,8,8,0,0,0,0,0,0,0,0
0,0,0,0,8,4,1,1,1,1,1,1,1,4,0,0,0,0,0,0
0,0,0,4,4,1,1,4,1,1,1,1,1,1,0,0,0,0,0,0
0,0,0,4,1,1,1,1,1,1,1,1,1,1,1,0,0,0,0,0
0,0,0,0,1,1,1,1,1,1,1,1,1,1,1,1,0,0,0,0
0,0,0,0,0,1,1,1,1,1,1,1,1,1,1,1,0,0,0,0
0,0,0,0,0,1,1,1,1,1,1,1,1,1,1,1,15,0,0,0
0,0,0,0,23,1,1,1,1,1,1,1,1,1,1,1,15,0,0,0
0,0,0,23,23,1,1,1,1,1,1,1,1,1,1,1,24,0,0,0
0,0,0,23,23,17,1,1,1,1,1,1,1,1,0,0,0,15,0,0
0,0,0,0,23,23,23,1,1,1,1,1,1,1,8,0,0,0,0,0
0,0,0,0,23,23,23,23,1,1,1,1,1,0,0,0,0,0,0,0
0,0,0,0,0,0,0,0,0,0,0,0,8,0,0,0,0,0,0,0
0,0,0,0,0,0,0,0,0,0,20,20,0,0,0,0,0,0,0,0
0,0,0,0,0,0,0,0,0,0,0,0,0,0,0,0,0,0,0,0
0,0,0,0,0,0,0,0,0,0,0,0,0,0,0,0,0,0,0,0
0,0,0,0,0,0,0,0,0,0,0,0,0,0,0,0,0,0,0,0
0,0,0,0,0,0,0,0,0,0,0,0,0,0,0,0,0,0,0,0
0,0,0,0,0,0,0,0,0,0,0,0,0,0,0,0,0,0,0,0
0,0,0,0,0,0,0,0,0,0,0,0,0,0,0,0,0,0,0,0
0,0,0,0,0,0,0,0,0,0,0,0,0,0,0,0,0,0,0,0
0,0,0,0,0,0,0,0,0,0,0,0,0,0,0,0,0,0,0,0
:endlayer
layer: 18
0,0,0,0,0,0,0,0,0,0,0,0,0,0,0,0,0,0,0,0
0,0,0,0,0,0,0,0,0,0,0,0,0,0,0,0,0,0,0,0
0,0,0,0,0,0,0,0,0,0,0,0,0,0,0,0,0,0,0,0
0,0,0,0,0,0,0,0,0,0,0,0,0,0,0,0,0,0,0,0
0,0,0,0,0,0,0,0,0,0,0,0,0,0,0,0,0,0,0,0
0,0,0,0,0,0,0,21,21,21,21,0,0,0,0,0,0,0,0,0
0,0,0,0,0,0,0,0,8,8,0,0,0,0,0,0,0,0,0,0
0,0,0,0,0,8,1,1,1,1,1,1,8,8,0,0,0,0,0,0
0,0,0,8,4,1,1,1,1,1,1,1,1,1,0,0,0,0,0,0
0,0,0,4,1,1,1,1,1,1,1,1,1,1,1,0,0,0,0,0
0,0,0,0,1,4,1,1,1,1,1,1,1,1,1,1,0,0,0,0
0,0,0,0,0,1,1,1,1,1,1,1,1,1,1,1,0,0,0,0
0,0,0,0,0,1,1,1,1,1,1,1,1,1,1,1,15,0,0,0
0,0,0,23,23,1,1,1,1,1,1,1,1,1,1,8,15,0,0,0
0,0,0,23,23,1,1,1,1,1,1,1,1,1,1,8,24,0,0,0
0,0,0,23,23,17,1,1,1,1,1,1,1,1,1,0,0,15,0,0
0,0,0,23,23,23,23,1,1,1,1,1,1,1,0,0,0,0,0,0
0,0,0,0,23,23,23,0,1,1,1,1,1,0,0,0,0,0,0,0
0,0,0,0,0,0,0,0,0,0,0,8,0,0,0,0,0,0,0,0
0,0,0,0,0,0,0,0,0,0,20,20,0,0,0,0,0,0,0,0
0,0,0,0,0,0,0,0,0,0,0,0,0,0,0,0,0,0,0,0
0,0,0,0,0,0,0,0,0,0,0,0,0,0,0,0,0,0,0,0
0,0,0,0,0,0,0,0,0,0,0,0,0,0,0,0,0,0,0,0
0,0,0,0,0,0,0,0,0,0,0,0,0,0,0,0,0,0,0,0
0,0,0,0,0,0,0,0,0,0,0,0,0,0,0,0,0,0,0,0
0,0,0,0,0,0,0,0,0,0,0,0,0,0,0,0,0,0,0,0
0,0,0,0,0,0,0,0,0,0,0,0,0,0,0,0,0,0,0,0
0,0,0,0,0,0,0,0,0,0,0,0,0,0,0,0,0,0,0,0
:endlayer
layer: 19
0,0,0,0,0,0,0,0,0,0,0,0,0,0,0,0,0,0,0,0
0,0,0,0,0,0,0,0,0,0,0,0,0,0,0,0,0,0,0,0
0,0,0,0,0,0,0,0,0,0,0,0,0,0,0,0,0,0,0,0
0,0,0,0,0,0,0,0,0,0,0,0,0,0,0,0,0,0,0,0
0,0,0,0,0,0,0,0,0,0,0,0,0,0,0,0,0,0,0,0
0,0,0,0,0,0,0,21,21,21,21,0,0,0,0,0,0,0,0,0
0,0,0,0,0,0,0,0,0,0,0,0,0,0,0,0,0,0,0,0
0,0,0,0,0,0,1,1,1,1,1,8,0,0,0,0,0,0,0,0
0,0,0,0,8,1,1,1,1,1,1,8,1,1,0,0,0,0,0,0
0,0,0,4,1,1,1,1,1,1,1,1,1,1,1,0,0,0,0,0
0,0,0,0,1,1,1,1,1,1,1,1,1,1,1,8,0,0,0,0
0,0,0,0,1,1,1,1,1,1,1,1,1,1,1,8,0,0,0,0
0,0,0,0,0,1,1,1,1,1,1,1,1,1,1,8,15,0,0,0
0,0,0,0,0,1,1,1,1,1,1,1,1,1,1,0,15,0,0,0
0,0,0,0,23,1,1,1,1,1,1,1,1,1,1,16,24,0,0,0
0,0,0,0,23,1,1,1,1,1,1,1,1,1,8,0,0,15,0,0
0,0,0,0,23,23,1,1,1,1,1,1,1,8,0,0,0,0,0,0
0,0,0,0,0,0,0,1,1,1,1,1,8,0,0,0,0,0,0,0
0,0,0,0,0,0,0,0,0,0,0,15,0,0,0,0,0,0,0,0
0,0,0,0,0,0,0,0,0,0,20,20,0,0,0,0,0,0,0,0
0,0,0,0,0,0,0,0,0,0,0,0,0,0,0,0,0,0,0,0
0,0,0,0,0,0,0,0,0,0,0,0,0,0,0,0,0,0,0,0
0,0,0,0,0,0,0,0,0,0,0,0,0,0,0,0,0,0,0,0
0,0,0,0,0,0,0,0,0,0,0,0,0,0,0,0,0,0,0,0
0,0,0,0,0,0,0,0,0,0,0,0,0,0,0,0,0,0,0,0
0,0,0,0,0,0,0,0,0,0,0,0,0,0,0,0,0,0,0,0
0,0,0,0,0,0,0,0,0,0,0,0,0,0,0,0,0,0,0,0
0,0,0,0,0,0,0,0,0,0,0,0,0,0,0,0,0,0,0,0
:endlayer
layer: 20
0,0,0,0,0,0,0,0,0,0,0,0,0,0,0,0,0,0,0,0
0,0,0,0,0,0,0,0,0,0,0,0,0,0,0,0,0,0,0,0
0,0,0,0,0,0,0,0,0,0,0,0,0,0,0,0,0,0,0,0
0,0,0,0,0,0,0,0,0,0,0,0,0,0,0,0,0,0,0,0
0,0,0,0,0,0,0,0,0,0,0,0,0,0,0,0,0,0,0,0
0,0,0,0,0,0,0,21,21,21,21,0,0,0,0,0,0,0,0,0
0,0,0,0,0,0,0,0,0,0,0,0,0,0,0,0,0,0,0,0
0,0,0,0,0,0,8,1,1,1,1,0,0,0,0,0,0,0,0,0
0,0,0,0,9,1,1,1,1,1,1,0,1,8,0,0,0,0,0,0
0,0,0,8,1,1,1,1,1,1,1,1,1,1,8,0,0,0,0,0
0,0,0,0,1,1,1,1,1,1,1,1,1,1,1,0,0,0,0,0
0,0,0,0,1,1,1,1,1,1,1,1,1,1,1,0,0,0,0,0
0,0,0,0,1,1,1,1,1,1,1,1,1,1,1,0,15,0,0,0
0,0,0,0,1,1,1,1,1,1,1,1,1,1,1,0,15,0,0,0
0,0,0,0,0,1,1,1,1,1,1,1,1,1,8,16,24,0,0,0
0,0,0,0,23,1,1,1,1,1,1,1,1,1,16,0,0,15,0,0
0,0,0,0,0,1,1,1,1,1,1,1,1,0,0,0,0,0,0,0
0,0,0,0,0,0,1,1,1,1,1,8,0,0,0,0,0,0,0,0
0,0,0,0,0,0,0,0,1,1,1,15,0,0,0,0,0,0,0,0
0,0,0,0,0,0,0,0,0,0,20,20,0,0,0,0,0,0,0,0
0,0,0,0,0,0,0,0,0,0,0,0,0,0,0,0,0,0,0,0
0,0,0,0,0,0,0,0,0,0,0,0,0,0,0,0,0,0,0,0
0,0,0,0,0,0,0,0,0,0,0,0,0,0,0,0,0,0,0,0
0,0,0,0,0,0,0,0,0,0,0,0,0,0,0,0,0,0,0,0
0,0,0,0,0,0,0,0,0,0,0,0,0,0,0,0,0,0,0,0
0,0,0,0,0,0,0,0,0,0,0,0,0,0,0,0,0,0,0,0
0,0,0,0,0,0,0,0,0,0,0,0,0,0,0,0,0,0,0,0
0,0,0,0,0,0,0,0,0,0,0,0,0,0,0,0,0,0,0,0
:endlayer
layer: 21
0,0,0,0,0,0,0,0,0,0,0,0,0,0,0,0,0,0,0,0
0,0,0,0,0,0,0,0,0,0,0,0,0,0,0,0,0,0,0,0
0,0,0,0,0,0,0,0,0,0,0,0,0,0,0,0,0,0,0,0
0,0,0,0,0,0,0,0,0,0,0,0,0,0,0,0,0,0,0,0
0,0,0,0,0,0,0,0,0,0,0,0,0,0,0,0,0,0,0,0
0,0,0,0,0,0,0,21,21,21,21,0,0,0,0,0,0,0,0,0
0,0,0,0,0,0,0,0,0,0,0,0,0,0,0,0,0,0,0,0
0,0,0,0,0,0,9,8,1,1,8,0,0,0,0,0,0,0,0,0
0,0,0,0,0,8,1,1,1,1,1,1,8,0,0,0,0,0,0,0
0,0,0,9,1,1,1,1,1,1,1,1,1,1,0,0,0,0,0,0
0,0,0,0,1,1,1,1,1,1,1,1,1,1,8,0,0,0,0,0
0,0,0,0,1,1,1,1,1,1,1,1,1,1,1,0,0,0,0,0
0,0,0,0,1,1,1,1,1,1,1,1,1,1,8,0,15,0,0,0
0,0,0,0,1,1,1,1,1,1,1,1,1,1,8,0,15,0,0,0
0,0,0,0,0,1,1,1,1,1,1,1,1,1,0,16,24,0,0,0
0,0,0,0,0,1,1,1,1,1,1,1,1,8,16,0,0,15,0,0
0,0,0,0,0,1,1,1,1,1,1,1,0,0,0,0,0,0,0,0
0,0,0,0,0,0,1,1,1,1,1,0,0,0,0,0,0,0,0,0
0,0,0,0,0,0,0,1,1,1,1,15,0,0,0,0,0,0,0,0
0,0,0,0,0,0,0,0,0,0,20,20,0,0,0,0,0,0,0,0
0,0,0,0,0,0,0,0,0,0,0,0,0,0,0,0,0,0,0,0
0,0,0,0,0,0,0,0,0,0,0,0,0,0,0,0,0,0,0,0
0,0,0,0,0,0,0,0,0,0,0,0,0,0,0,0,0,0,0,0
0,0,0,0,0,0,0,0,0,0,0,0,0,0,0,0,0,0,0,0
0,0,0,0,0,0,0,0,0,0,0,0,0,0,0,0,0,0,0,0
0,0,0,0,0,0,0,0,0,0,0,0,0,0,0,0,0,0,0,0
0,0,0,0,0,0,0,0,0,0,0,0,0,0,0,0,0,0,0,0
0,0,0,0,0,0,0,0,0,0,0,0,0,0,0,0,0,0,0,0
:endlayer
layer: 22
0,0,0,0,0,0,0,0,0,0,0,0,0,0,0,0,0,0,0,0
0,0,0,0,0,0,0,0,0,0,0,0,0,0,0,0,0,0,0,0
0,0,0,0,0,0,0,0,0,0,0,0,0,0,0,0,0,0,0,0
0,0,0,0,0,0,0,0,0,0,0,0,0,0,0,0,0,0,0,0
0,0,0,0,0,0,0,0,0,0,0,0,0,0,0,0,0,0,0,0
0,0,0,0,0,0,0,21,21,21,21,0,0,0,0,0,0,0,0,0
0,0,0,0,0,0,0,0,0,0,0,0,0,0,0,0,0,0,0,0
0,0,0,0,0,0,0,9,8,8,9,0,0,0,0,0,0,0,0,0
0,0,0,0,0,9,1,1,1,1,1,1,13,0,0,0,0,0,0,0
0,0,0,0,8,1,1,1,1,1,1,1,1,8,0,0,0,0,0,0
0,0,0,0,1,1,1,1,1,1,1,1,1,8,9,0,0,0,0,0
0,0,0,0,1,1,1,1,1,1,1,1,1,1,8,0,0,0,0,0
0,0,0,0,1,1,1,1,1,1,1,1,1,1,9,0,15,0,0,0
0,0,0,0,1,1,1,1,1,1,1,1,1,1,0,0,15,0,0,0
0,0,0,0,1,1,1,1,1,1,1,1,1,1,0,16,24,0,0,0
0,0,0,0,0,1,1,1,1,1,1,1,1,9,16,0,0,15,0,0
0,0,0,0,0,1,1,1,1,1,1,1,0,0,0,0,0,0,0,0
0,0,0,0,0,0,1,1,1,1,1,0,0,0,0,0,0,0,0,0
0,0,0,0,0,0,0,1,1,1,1,15,0,0,0,0,0,0,0,0
0,0,0,0,0,0,0,0,0,0,20,20,0,0,0,0,0,0,0,0
0,0,0,0,0,0,0,0,0,0,0,0,0,0,0,0,0,0,0,0
0,0,0,0,0,0,0,0,0,0,0,0,0,0,0,0,0,0,0,0
0,0,0,0,0,0,0,0,0,0,0,0,0,0,0,0,0,0,0,0
0,0,0,0,0,0,0,0,0,0,0,0,0,0,0,0,0,0,0,0
0,0,0,0,0,0,0,0,0,0,0,0,0,0,0,0,0,0,0,0
0,0,0,0,0,0,0,0,0,0,0,0,0,0,0,0,0,0,0,0
0,0,0,0,0,0,0,0,0,0,0,0,0,0,0,0,0,0,0,0
0,0,0,0,0,0,0,0,0,0,0,0,0,0,0,0,0,0,0,0
:endlayer
layer: 23
0,0,0,0,0,0,0,0,0,0,0,0,0,0,0,0,0,0,0,0
0,0,0,0,0,0,0,0,0,0,0,0,0,0,0,0,0,0,0,0
0,0,0,0,0,0,0,0,0,0,0,0,0,0,0,0,0,0,0,0
0,0,0,0,0,0,0,0,0,0,0,0,0,0,0,0,0,0,0,0
0,0,0,0,0,0,0,0,0,0,0,0,0,0,0,0,0,0,0,0
0,0,0,0,0,0,0,21,21,21,21,0,0,0,0,0,0,0,0,0
0,0,0,0,0,0,0,0,0,0,0,0,0,0,0,0,0,0,0,0
0,0,0,0,0,0,0,0,9,9,0,0,0,0,0,0,0,0,0,0
0,0,0,0,0,0,8,1,1,1,1,8,0,0,0,0,0,0,0,0
0,0,0,0,9,8,1,1,1,1,1,1,1,14,0,0,0,0,0,0
0,0,0,0,1,1,1,1,1,1,1,1,1,14,0,0,0,0,0,0
0,0,0,0,1,1,1,1,1,1,1,1,1,1,9,0,0,0,0,0
0,0,0,0,1,1,1,1,1,1,1,1,1,1,0,0,15,0,0,0
0,0,0,0,1,1,1,1,1,1,1,1,1,1,0,0,15,0,0,0
0,0,0,0,1,1,1,1,1,1,1,1,1,1,0,16,24,0,0,0
0,0,0,0,0,1,1,1,1,1,1,1,1,0,16,0,0,15,0,0
0,0,0,0,0,1,1,1,1,1,1,8,0,0,0,0,0,0,0,0
0,0,0,0,0,0,1,1,1,1,1,0,0,0,0,0,0,0,0,0
0,0,0,0,0,0,0,8,1,1,1,15,0,0,0,0,0,0,0,0
0,0,0,0,0,0,0,0,0,0,20,20,0,0,0,0,0,0,0,0
0,0,0,0,0,0,0,0,0,0,0,0,0,0,0,0,0,0,0,0
0,0,0,0,0,0,0,0,0,0,0,0,0,0,0,0,0,0,0,0
0,0,0,0,0,0,0,0,0,0,0,0,0,0,0,0,0,0,0,0
0,0,0,0,0,0,0,0,0,0,0,0,0,0,0,0,0,0,0,0
0,0,0,0,0,0,0,0,0,0,0,0,0,0,0,0,0,0,0,0
0,0,0,0,0,0,0,0,0,0,0,0,0,0,0,0,0,0,0,0
0,0,0,0,0,0,0,0,0,0,0,0,0,0,0,0,0,0,0,0
0,0,0,0,0,0,0,0,0,0,0,0,0,0,0,0,0,0,0,0
:endlayer
layer: 24
0,0,0,0,0,0,0,0,0,0,0,0,0,0,0,0,0,0,0,0
0,0,0,0,0,0,0,0,0,0,0,0,0,0,0,0,0,0,0,0
0,0,0,0,0,0,0,0,0,0,0,0,0,0,0,0,0,0,0,0
0,0,0,0,0,0,0,0,0,0,0,0,0,0,0,0,0,0,0,0
0,0,0,0,0,0,0,0,0,0,0,0,0,0,0,0,0,0,0,0
0,0,0,0,0,0,0,21,21,21,21,0,0,0,0,0,0,0,0,0
0,0,0,0,0,0,0,0,0,0,0,0,0,0,0,0,0,0,0,0
0,0,0,0,0,0,0,0,0,0,0,0,0,0,0,0,0,0,0,0
0,0,0,0,0,0,9,8,8,8,8,9,0,0,0,0,0,0,0,0
0,0,0,0,0,9,8,1,1,1,1,1,8,0,0,0,0,0,0,0
0,0,0,0,8,1,1,1,1,1,1,1,1,8,0,0,0,0,0,0
0,0,0,0,1,1,1,1,1,1,1,1,1,1,0,0,0,0,0,0
0,0,0,0,1,1,1,1,1,1,1,1,1,1,0,0,15,0,0,0
0,0,0,0,1,1,1,1,1,1,1,1,1,8,0,0,15,0,0,0
0,0,0,0,1,1,1,1,1,1,1,1,1,8,0,16,24,0,0,0
0,0,0,0,0,1,1,1,1,1,1,1,8,0,16,0,0,15,0,0
0,0,0,0,0,1,1,1,1,1,1,0,0,0,0,0,0,0,0,0
0,0,0,0,0,0,8,1,1,1,1,0,0,0,0,0,0,0,0,0
0,0,0,0,0,0,0,13,8,8,8,15,0,0,0,0,0,0,0,0
0,0,0,0,0,0,0,0,0,0,20,20,0,0,0,0,0,0,0,0
0,0,0,0,0,0,0,0,0,0,0,0,0,0,0,0,0,0,0,0
0,0,0,0,0,0,0,0,0,0,0,0,0,0,0,0,0,0,0,0
0,0,0,0,0,0,0,0,0,0,0,0,0,0,0,0,0,0,0,0
0,0,0,0,0,0,0,0,0,0,0,0,0,0,0,0,0,0,0,0
0,0,0,0,0,0,0,0,0,0,0,0,0,0,0,0,0,0,0,0
0,0,0,0,0,0,0,0,0,0,0,0,0,0,0,0,0,0,0,0
0,0,0,0,0,0,0,0,0,0,0,0,0,0,0,0,0,0,0,0
0,0,0,0,0,0,0,0,0,0,0,0,0,0,0,0,0,0,0,0
:endlayer
layer: 25
0,0,0,0,0,0,0,0,0,0,0,0,0,0,0,0,0,0,0,0
0,0,0,0,0,0,0,0,0,0,0,0,0,0,0,0,0,0,0,0
0,0,0,0,0,0,0,0,0,0,0,0,0,0,0,0,0,0,0,0
0,0,0,0,0,0,0,0,0,0,0,0,0,0,0,0,0,0,0,0
0,0,0,0,0,0,0,0,0,0,0,0,0,0,0,0,0,0,0,0
0,0,0,0,0,0,0,21,21,21,21,0,0,0,0,0,0,0,0,0
0,0,0,0,0,0,0,0,0,0,0,0,0,0,0,0,0,0,0,0
0,0,0,0,0,0,0,0,0,0,0,0,0,0,0,0,0,0,0,0
0,0,0,0,0,0,0,9,9,0,9,0,0,0,0,0,0,0,0,0
0,0,0,0,0,0,9,8,1,1,1,8,9,0,0,0,0,0,0,0
0,0,0,0,0,8,1,1,1,1,1,1,8,0,0,0,0,0,0,0
0,0,0,0,1,1,1,1,1,1,1,1,1,8,0,0,0,0,0,0
0,0,0,0,1,1,1,1,1,1,1,1,1,8,0,0,15,0,0,0
0,0,0,1,1,1,1,1,1,1,1,1,1,9,0,0,15,0,0,0
0,0,0,0,1,1,1,1,1,1,1,1,8,0,0,16,24,0,0,0
0,0,0,0,1,1,1,1,1,1,1,8,0,0,16,0,0,15,0,0
0,0,0,0,0,1,1,1,1,1,1,0,0,0,0,0,0,0,0,0
0,0,0,0,0,0,9,1,1,1,1,0,0,0,0,0,0,0,0,0
0,0,0,0,0,0,0,0,9,9,9,15,0,0,0,0,0,0,0,0
0,0,0,0,0,0,0,0,0,0,20,20,0,0,0,0,0,0,0,0
0,0,0,0,0,0,0,0,0,0,0,0,0,0,0,0,0,0,0,0
0,0,0,0,0,0,0,0,0,0,0,0,0,0,0,0,0,0,0,0
0,0,0,0,0,0,0,0,0,0,0,0,0,0,0,0,0,0,0,0
0,0,0,0,0,0,0,0,0,0,0,0,0,0,0,0,0,0,0,0
0,0,0,0,0,0,0,0,0,0,0,0,0,0,0,0,0,0,0,0
0,0,0,0,0,0,0,0,0,0,0,0,0,0,0,0,0,0,0,0
0,0,0,0,0,0,0,0,0,0,0,0,0,0,0,0,0,0,0,0
0,0,0,0,0,0,0,0,0,0,0,0,0,0,0,0,0,0,0,0
:endlayer
layer: 26
0,0,0,0,0,0,0,0,0,0,0,0,0,0,0,0,0,0,0,0
0,0,0,0,0,0,0,0,0,0,0,0,0,0,0,0,0,0,0,0
0,0,0,0,0,0,0,0,0,0,0,0,0,0,0,0,0,0,0,0
0,0,0,0,0,0,0,0,0,0,0,0,0,0,0,0,0,0,0,0
0,0,0,0,0,0,0,0,0,0,0,0,0,0,0,0,0,0,0,0
0,0,0,0,0,0,0,21,21,21,21,0,0,0,0,0,0,0,0,0
0,0,0,0,0,0,0,0,0,0,0,0,0,0,0,0,0,0,0,0
0,0,0,0,0,0,0,0,0,0,0,0,0,0,0,0,0,0,0,0
0,0,0,0,0,0,0,0,0,0,0,0,0,0,0,0,0,0,0,0
0,0,0,0,0,0,0,9,1,1,1,9,0,0,0,0,0,0,0,0
0,0,0,0,0,9,1,1,1,1,1,1,9,0,0,0,0,0,0,0
0,0,0,0,1,1,1,1,1,1,1,1,1,9,0,0,0,0,0,0
0,0,0,1,1,1,1,1,1,1,1,1,1,0,0,0,15,0,0,0
0,0,0,1,1,1,1,1,1,1,1,1,0,0,0,0,15,0,0,0
0,0,0,1,1,1,1,1,1,1,1,1,9,0,0,16,24,0,0,0
0,0,0,0,1,1,1,1,1,1,1,0,0,0,16,0,0,15,0,0
0,0,0,0,0,1,1,1,1,1,1,0,0,0,0,0,0,0,0,0
0,0,0,0,0,0,1,1,1,1,1,0,0,0,0,0,0,0,0,0
0,0,0,0,0,0,0,0,0,0,0,15,0,0,0,0,0,0,0,0
0,0,0,0,0,0,0,0,0,0,20,20,0,0,0,0,0,0,0,0
0,0,0,0,0,0,0,0,0,0,0,0,0,0,0,0,0,0,0,0
0,0,0,0,0,0,0,0,0,0,0,0,0,0,0,0,0,0,0,0
0,0,0,0,0,0,0,0,0,0,0,0,0,0,0,0,0,0,0,0
0,0,0,0,0,0,0,0,0,0,0,0,0,0,0,0,0,0,0,0
0,0,0,0,0,0,0,0,0,0,0,0,0,0,0,0,0,0,0,0
0,0,0,0,0,0,0,0,0,0,0,0,0,0,0,0,0,0,0,0
0,0,0,0,0,0,0,0,0,0,0,0,0,0,0,0,0,0,0,0
0,0,0,0,0,0,0,0,0,0,0,0,0,0,0,0,0,0,0,0
:endlayer
layer: 27
0,0,0,0,0,0,0,0,0,0,0,0,0,0,0,0,0,0,0,0
0,0,0,0,0,0,0,0,0,0,0,0,0,0,0,0,0,0,0,0
0,0,0,0,0,0,0,0,0,0,0,0,0,0,0,0,0,0,0,0
0,0,0,0,0,0,0,0,0,0,0,0,0,0,0,0,0,0,0,0
0,0,0,0,0,0,0,0,0,0,0,0,0,0,0,0,0,0,0,0
0,0,0,0,0,0,0,21,21,21,21,0,0,0,0,0,0,0,0,0
0,0,0,0,0,0,0,0,0,0,0,0,0,0,0,0,0,0,0,0
0,0,0,0,0,0,0,0,0,0,0,0,0,0,0,0,0,0,0,0
0,0,0,0,0,0,0,1,1,1,1,0,0,0,0,0,0,0,0,0
0,0,0,0,0,0,1,1,1,1,1,1,0,0,0,0,0,0,0,0
0,0,0,0,0,1,1,1,1,1,1,1,0,0,0,0,0,0,0,0
0,0,0,1,1,1,1,1,1,1,1,1,1,0,0,0,0,0,0,0
0,0,0,1,1,1,1,1,1,1,1,1,1,0,0,0,15,0,0,0
0,0,0,1,1,1,1,1,1,1,1,1,1,0,0,0,15,0,0,0
0,0,0,1,1,1,1,1,1,1,1,1,0,0,0,16,24,0,0,0
0,0,0,0,1,1,1,1,1,1,1,0,0,0,16,0,0,15,0,0
0,0,0,0,0,1,1,1,1,1,1,0,0,0,0,0,0,0,0,0
0,0,0,0,0,0,1,1,1,1,1,0,0,0,0,0,0,0,0,0
0,0,0,0,0,0,0,0,0,0,0,15,0,0,0,0,0,0,0,0
0,0,0,0,0,0,0,0,0,0,20,20,0,0,0,0,0,0,0,0
0,0,0,0,0,0,0,0,0,0,0,0,0,0,0,0,0,0,0,0
0,0,0,0,0,0,0,0,0,0,0,0,0,0,0,0,0,0,0,0
0,0,0,0,0,0,0,0,0,0,0,0,0,0,0,0,0,0,0,0
0,0,0,0,0,0,0,0,0,0,0,0,0,0,0,0,0,0,0,0
0,0,0,0,0,0,0,0,0,0,0,0,0,0,0,0,0,0,0,0
0,0,0,0,0,0,0,0,0,0,0,0,0,0,0,0,0,0,0,0
0,0,0,0,0,0,0,0,0,0,0,0,0,0,0,0,0,0,0,0
0,0,0,0,0,0,0,0,0,0,0,0,0,0,0,0,0,0,0,0
:endlayer
layer: 28
0,0,0,0,0,0,0,0,0,0,0,0,0,0,0,0,0,0,0,0
0,0,0,0,0,0,0,0,0,0,0,0,0,0,0,0,0,0,0,0
0,0,0,0,0,0,0,0,0,0,0,0,0,0,0,0,0,0,0,0
0,0,0,0,0,0,0,0,0,0,0,0,0,0,0,0,0,0,0,0
0,0,0,0,0,0,0,0,0,0,0,0,0,0,0,0,0,0,0,0
0,0,0,0,0,0,0,21,21,21,21,0,0,0,0,0,0,0,0,0
0,0,0,0,0,0,0,0,0,0,0,0,0,0,0,0,0,0,0,0
0,0,0,0,0,0,0,1,1,0,1,0,0,0,0,0,0,0,0,0
0,0,0,0,0,1,1,1,1,1,1,1,0,0,0,0,0,0,0,0
0,0,0,0,1,1,1,1,1,1,1,1,1,0,0,0,0,0,0,0
0,0,0,0,1,1,1,1,1,1,1,1,1,1,0,0,0,0,0,0
0,0,0,8,1,1,1,1,1,1,1,1,1,1,0,0,0,0,0,0
0,0,0,1,1,1,1,1,1,1,1,1,1,1,0,0,15,0,0,0
0,0,0,1,1,1,1,1,1,1,1,1,1,1,0,0,15,0,0,0
0,0,0,8,1,1,1,1,1,1,1,1,1,8,0,16,24,0,0,0
0,0,0,0,1,1,1,1,1,1,1,1,1,0,16,0,0,15,0,0
0,0,0,0,0,1,1,1,1,1,1,1,0,0,0,0,0,0,0,0
0,0,0,0,0,0,8,1,1,1,8,0,0,0,0,0,0,0,0,0
0,0,0,0,0,0,0,0,0,0,0,15,0,0,0,0,0,0,0,0
0,0,0,0,0,0,0,0,0,0,20,20,0,0,0,0,0,0,0,0
0,0,0,0,0,0,0,0,0,0,0,0,0,0,0,0,0,0,0,0
0,0,0,0,0,0,0,0,0,0,0,0,0,0,0,0,0,0,0,0
0,0,0,0,0,0,0,0,0,0,0,0,0,0,0,0,0,0,0,0
0,0,0,0,0,0,0,0,0,0,0,0,0,0,0,0,0,0,0,0
0,0,0,0,0,0,0,0,0,0,0,0,0,0,0,0,0,0,0,0
0,0,0,0,0,0,0,0,0,0,0,0,0,0,0,0,0,0,0,0
0,0,0,0,0,0,0,0,0,0,0,0,0,0,0,0,0,0,0,0
0,0,0,0,0,0,0,0,0,0,0,0,0,0,0,0,0,0,0,0
:endlayer
layer: 29
0,0,0,0,0,0,0,0,0,0,0,0,0,0,0,0,0,0,0,0
0,0,0,0,0,0,0,0,0,0,0,0,0,0,0,0,0,0,0,0
0,0,0,0,0,0,0,0,0,0,0,0,0,0,0,0,0,0,0,0
0,0,0,0,0,0,0,0,0,0,0,0,0,0,0,0,0,0,0,0
0,0,0,0,0,0,0,0,0,0,0,0,0,0,0,0,0,0,0,0
0,0,0,0,0,0,0,21,21,21,21,0,0,0,0,0,0,0,0,0
0,0,0,0,0,0,0,0,0,0,0,0,0,0,0,0,0,0,0,0
0,0,0,0,0,0,0,1,1,1,1,1,0,0,0,0,0,0,0,0
0,0,0,0,0,1,1,1,1,1,1,1,1,0,0,0,0,0,0,0
0,0,0,0,8,1,1,1,1,1,1,1,1,1,0,0,0,0,0,0
0,0,0,0,1,1,1,1,1,1,1,1,1,1,0,0,0,0,0,0
0,0,0,0,1,1,1,1,1,1,1,1,1,1,0,0,0,0,0,0
0,0,0,8,1,1,1,1,1,1,1,1,1,1,0,0,15,0,0,0
0,0,0,8,1,1,1,1,1,1,1,1,1,1,0,0,15,0,0,0
0,0,0,9,1,1,1,1,1,1,1,1,1,9,0,16,24,0,0,0
0,0,0,0,8,1,1,1,1,1,1,1,1,0,16,0,0,15,0,0
0,0,0,0,0,8,1,1,1,1,1,8,0,0,0,0,0,0,0,0
0,0,0,0,0,0,0,8,8,8,0,0,0,0,0,0,0,0,0,0
0,0,0,0,0,0,0,0,0,0,0,15,0,0,0,0,0,0,0,0
0,0,0,0,0,0,0,0,0,0,20,20,0,0,0,0,0,0,0,0
0,0,0,0,0,0,0,0,0,0,0,0,0,0,0,0,0,0,0,0
0,0,0,0,0,0,0,0,0,0,0,0,0,0,0,0,0,0,0,0
0,0,0,0,0,0,0,0,0,0,0,0,0,0,0,0,0,0,0,0
0,0,0,0,0,0,0,0,0,0,0,0,0,0,0,0,0,0,0,0
0,0,0,0,0,0,0,0,0,0,0,0,0,0,0,0,0,0,0,0
0,0,0,0,0,0,0,0,0,0,0,0,0,0,0,0,0,0,0,0
0,0,0,0,0,0,0,0,0,0,0,0,0,0,0,0,0,0,0,0
0,0,0,0,0,0,0,0,0,0,0,0,0,0,0,0,0,0,0,0
:endlayer
layer: 30
0,0,0,0,0,0,0,0,0,0,0,0,0,0,0,0,0,0,0,0
0,0,0,0,0,0,0,0,0,0,0,0,0,0,0,0,0,0,0,0
0,0,0,0,0,0,0,0,0,0,0,0,0,0,0,0,0,0,0,0
0,0,0,0,0,0,0,0,0,0,0,0,0,0,0,0,0,0,0,0
0,0,0,0,0,0,0,0,0,0,0,0,0,0,0,0,0,0,0,0
0,0,0,0,0,0,0,21,21,21,21,0,0,0,0,0,0,0,0,0
0,0,0,0,0,0,0,0,1,0,0,0,0,0,0,0,0,0,0,0
0,0,0,0,0,0,1,1,1,1,1,1,1,0,0,0,0,0,0,0
0,0,0,0,0,1,1,1,1,1,1,1,1,1,0,0,0,0,0,0
0,0,0,0,9,1,1,1,1,1,1,1,1,1,0,0,0,0,0,0
0,0,0,0,1,1,1,1,1,1,1,1,1,1,1,0,0,0,0,0
0,0,0,0,1,1,1,1,1,1,1,1,1,1,0,0,0,0,0,0
0,0,0,0,1,1,1,1,1,1,1,1,1,1,0,0,15,0,0,0
0,0,0,0,1,1,1,1,1,1,1,1,1,1,0,0,15,0,0,0
0,0,0,0,8,1,1,1,1,1,1,1,1,1,0,16,24,0,0,0
0,0,0,0,0,8,1,1,1,1,1,1,1,0,16,0,0,15,0,0
0,0,0,0,0,13,8,1,1,1,1,0,0,0,0,0,0,0,0,0
0,0,0,0,0,0,0,9,9,9,0,0,0,0,0,0,0,0,0,0
0,0,0,0,0,0,0,0,0,0,0,15,0,0,0,0,0,0,0,0
0,0,0,0,0,0,0,0,0,0,20,20,0,0,0,0,0,0,0,0
0,0,0,0,0,0,0,0,0,0,0,0,0,0,0,0,0,0,0,0
0,0,0,0,0,0,0,0,0,0,0,0,0,0,0,0,0,0,0,0
0,0,0,0,0,0,0,0,0,0,0,0,0,0,0,0,0,0,0,0
0,0,0,0,0,0,0,0,0,0,0,0,0,0,0,0,0,0,0,0
0,0,0,0,0,0,0,0,0,0,0,0,0,0,0,0,0,0,0,0
0,0,0,0,0,0,0,0,0,0,0,0,0,0,0,0,0,0,0,0
0,0,0,0,0,0,0,0,0,0,0,0,0,0,0,0,0,0,0,0
0,0,0,0,0,0,0,0,0,0,0,0,0,0,0,0,0,0,0,0
:endlayer
layer: 31
0,0,0,0,0,0,0,0,0,0,0,0,0,0,0,0,0,0,0,0
0,0,0,0,0,0,0,0,0,0,0,0,0,0,0,0,0,0,0,0
0,0,0,0,0,0,0,0,0,0,0,0,0,0,0,0,0,0,0,0
0,0,0,0,0,0,0,0,0,0,0,0,0,0,0,0,0,0,0,0
0,0,0,0,0,0,0,0,0,0,0,0,0,0,0,0,0,0,0,0
0,0,0,0,0,0,0,21,21,21,21,0,0,0,0,0,0,0,0,0
0,0,0,0,0,0,0,1,1,1,1,0,0,0,0,0,0,0,0,0
0,0,0,0,0,0,1,1,1,1,1,1,1,0,0,0,0,0,0,0
0,0,0,0,0,1,1,1,1,1,1,1,1,1,0,0,0,0,0,0
0,0,0,0,1,1,1,1,1,1,1,1,1,1,1,0,0,0,0,0
0,0,0,0,1,1,1,1,1,1,1,1,1,1,1,0,0,0,0,0
0,0,0,0,1,1,1,1,1,1,1,1,1,1,1,0,0,0,0,0
0,0,0,0,1,1,1,1,1,1,1,1,1,1,0,0,15,0,0,0
0,0,0,0,1,1,1,1,1,1,1,1,1,1,0,0,15,0,0,0
0,0,0,0,9,1,1,1,1,1,1,1,1,1,0,16,24,0,0,0
0,0,0,0,0,0,1,1,1,1,1,1,1,0,16,0,0,15,0,0
0,0,0,0,0,0,13,1,1,1,1,1,0,0,0,0,0,0,0,0
0,0,0,0,0,0,0,0,0,0,0,0,0,0,0,0,0,0,0,0
0,0,0,0,0,0,0,0,0,0,0,15,0,0,0,0,0,0,0,0
0,0,0,0,0,0,0,0,0,0,20,20,0,0,0,0,0,0,0,0
0,0,0,0,0,0,0,0,0,0,0,0,0,0,0,0,0,0,0,0
0,0,0,0,0,0,0,0,0,0,0,0,0,0,0,0,0,0,0,0
0,0,0,0,0,0,0,0,0,0,0,0,0,0,0,0,0,0,0,0
0,0,0,0,0,0,0,0,0,0,0,0,0,0,0,0,0,0,0,0
0,0,0,0,0,0,0,0,0,0,0,0,0,0,0,0,0,0,0,0
0,0,0,0,0,0,0,0,0,0,0,0,0,0,0,0,0,0,0,0
0,0,0,0,0,0,0,0,0,0,0,0,0,0,0,0,0,0,0,0
0,0,0,0,0,0,0,0,0,0,0,0,0,0,0,0,0,0,0,0
:endlayer
layer: 32
0,0,0,0,0,0,0,0,0,0,0,0,0,0,0,0,0,0,0,0
0,0,0,0,0,0,0,0,0,0,0,0,0,0,0,0,0,0,0,0
0,0,0,0,0,0,0,0,0,0,0,0,0,0,0,0,0,0,0,0
0,0,0,0,0,0,0,0,0,0,0,0,0,0,0,0,0,0,0,0
0,0,0,0,0,0,0,0,0,0,0,0,0,0,0,0,0,0,0,0
0,0,0,0,0,0,0,21,21,21,21,0,0,0,0,0,0,0,0,0
0,0,0,0,0,0,0,1,1,1,1,1,0,0,0,0,0,0,0,0
0,0,0,0,0,0,1,1,1,1,1,1,1,0,0,0,0,0,0,0
0,0,0,0,0,1,1,1,1,1,1,1,1,1,0,0,0,0,0,0
0,0,0,0,1,1,1,1,1,1,1,1,1,1,1,0,0,0,0,0
0,0,0,0,1,1,1,1,1,1,1,1,1,1,1,0,0,0,0,0
0,0,0,0,1,1,1,1,1,1,1,1,1,1,1,0,0,0,0,0
0,0,0,0,1,1,1,1,1,1,1,1,1,1,1,0,15,0,0,0
0,0,0,0,1,1,1,1,1,1,1,1,1,1,0,0,15,0,0,0
0,0,0,0,0,1,1,1,1,1,1,1,1,1,0,16,24,0,0,0
0,0,0,0,0,0,1,1,1,1,1,1,1,0,16,0,0,15,0,0
0,0,0,0,0,0,0,1,1,1,1,1,0,0,0,0,0,0,0,0
0,0,0,0,0,0,0,0,0,0,0,0,0,0,0,0,0,0,0,0
0,0,0,0,0,0,0,0,0,0,0,15,0,0,0,0,0,0,0,0
0,0,0,0,0,0,0,0,0,0,20,20,0,0,0,0,0,0,0,0
0,0,0,0,0,0,0,0,0,0,0,0,0,0,0,0,0,0,0,0
0,0,0,0,0,0,0,0,0,0,0,0,0,0,0,0,0,0,0,0
0,0,0,0,0,0,0,0,0,0,0,0,0,0,0,0,0,0,0,0
0,0,0,0,0,0,0,0,0,0,0,0,0,0,0,0,0,0,0,0
0,0,0,0,0,0,0,0,0,0,0,0,0,0,0,0,0,0,0,0
0,0,0,0,0,0,0,0,0,0,0,0,0,0,0,0,0,0,0,0
0,0,0,0,0,0,0,0,0,0,0,0,0,0,0,0,0,0,0,0
0,0,0,0,0,0,0,0,0,0,0,0,0,0,0,0,0,0,0,0
:endlayer
layer: 33
0,0,0,0,0,0,0,0,0,0,0,0,0,0,0,0,0,0,0,0
0,0,0,0,0,0,0,0,0,0,0,0,0,0,0,0,0,0,0,0
0,0,0,0,0,0,0,0,0,0,0,0,0,0,0,0,0,0,0,0
0,0,0,0,0,0,0,0,0,0,0,0,0,0,0,0,0,0,0,0
0,0,0,0,0,0,0,0,0,0,0,0,0,0,0,0,0,0,0,0
0,0,0,0,0,0,0,21,21,21,21,0,0,0,0,0,0,0,0,0
0,0,0,0,0,0,0,8,1,1,1,8,0,0,0,0,0,0,0,0
0,0,0,0,0,0,1,1,1,1,1,1,1,0,0,0,0,0,0,0
0,0,0,0,0,1,1,1,1,1,1,1,1,1,0,0,0,0,0,0
0,0,0,0,8,1,1,1,1,1,1,1,1,1,1,0,0,0,0,0
0,0,0,0,1,1,1,1,1,1,1,1,1,1,1,0,0,0,0,0
0,0,0,0,1,1,1,1,1,1,1,1,1,1,1,0,0,0,0,0
0,0,0,0,1,1,1,1,1,1,1,1,1,1,1,0,15,0,0,0
0,0,0,0,8,1,1,1,1,1,1,1,1,1,0,0,15,0,0,0
0,0,0,0,0,1,1,1,1,1,1,1,1,1,0,16,24,0,0,0
0,0,0,0,0,0,1,1,1,1,1,1,1,0,16,0,0,15,0,0
0,0,0,0,0,0,0,8,1,1,1,8,0,0,0,0,0,0,0,0
0,0,0,0,0,0,0,0,0,0,0,0,0,0,0,0,0,0,0,0
0,0,0,0,0,0,0,0,0,0,0,15,0,0,0,0,0,0,0,0
0,0,0,0,0,0,0,0,0,0,20,20,0,0,0,0,0,0,0,0
0,0,0,0,0,0,0,0,0,0,0,0,0,0,0,0,0,0,0,0
0,0,0,0,0,0,0,0,0,0,0,0,0,0,0,0,0,0,0,0
0,0,0,0,0,0,0,0,0,0,0,0,0,0,0,0,0,0,0,0
0,0,0,0,0,0,0,0,0,0,0,0,0,0,0,0,0,0,0,0
0,0,0,0,0,0,0,0,0,0,0,0,0,0,0,0,0,0,0,0
0,0,0,0,0,0,0,0,0,0,0,0,0,0,0,0,0,0,0,0
0,0,0,0,0,0,0,0,0,0,0,0,0,0,0,0,0,0,0,0
0,0,0,0,0,0,0,0,0,0,0,0,0,0,0,0,0,0,0,0
:endlayer
layer: 34
0,0,0,0,0,0,0,0,0,0,0,0,0,0,0,0,0,0,0,0
0,0,0,0,0,0,0,0,0,0,0,0,0,0,0,0,0,0,0,0
0,0,0,0,0,0,0,0,0,0,0,0,0,0,0,0,0,0,0,0
0,0,0,0,0,0,0,0,0,0,0,0,0,0,0,0,0,0,0,0
0,0,0,0,0,0,0,0,0,0,0,0,0,0,0,0,0,0,0,0
0,0,0,0,0,0,0,0,21,21,21,0,0,0,0,0,0,0,0,0
0,0,0,0,0,0,0,9,8,1,1,0,0,0,0,0,0,0,0,0
0,0,0,0,0,0,8,1,1,1,1,1,1,0,0,0,0,0,0,0
0,0,0,0,0,8,1,1,1,1,1,1,1,1,0,0,0,0,0,0
0,0,0,0,0,1,1,1,1,1,1,1,1,1,1,0,0,0,0,0
0,0,0,0,8,1,1,1,1,1,1,1,1,1,1,0,0,0,0,0
0,0,0,0,8,1,1,1,1,1,1,1,1,1,1,0,0,0,0,0
0,0,0,0,8,1,1,1,1,1,1,1,1,1,1,0,15,0,0,0
0,0,0,0,9,1,1,1,1,1,1,1,1,1,1,0,15,0,0,0
0,0,0,0,0,1,1,1,1,1,1,1,1,1,0,16,24,0,0,0
0,0,0,0,0,0,1,1,1,1,1,1,1,0,16,0,0,15,0,0
0,0,0,0,0,0,0,9,8,1,1,0,0,0,0,0,0,0,0,0
0,0,0,0,0,0,0,0,0,0,0,0,0,0,0,0,0,0,0,0
0,0,0,0,0,0,0,0,0,0,0,15,0,0,0,0,0,0,0,0
0,0,0,0,0,0,0,0,0,0,20,20,0,0,0,0,0,0,0,0
0,0,0,0,0,0,0,0,0,0,0,0,0,0,0,0,0,0,0,0
0,0,0,0,0,0,0,0,0,0,0,0,0,0,0,0,0,0,0,0
0,0,0,0,0,0,0,0,0,0,0,0,0,0,0,0,0,0,0,0
0,0,0,0,0,0,0,0,0,0,0,0,0,0,0,0,0,0,0,0
0,0,0,0,0,0,0,0,0,0,0,0,0,0,0,0,0,0,0,0
0,0,0,0,0,0,0,0,0,0,0,0,0,0,0,0,0,0,0,0
0,0,0,0,0,0,0,0,0,0,0,0,0,0,0,0,0,0,0,0
0,0,0,0,0,0,0,0,0,0,0,0,0,0,0,0,0,0,0,0
:endlayer
layer: 35
0,0,0,0,0,0,0,0,0,0,0,0,0,0,0,0,0,0,0,0
0,0,0,0,0,0,0,0,0,0,0,0,0,0,0,0,0,0,0,0
0,0,0,0,0,0,0,0,0,0,0,0,0,0,0,0,0,0,0,0
0,0,0,0,0,0,0,0,0,0,0,0,0,0,0,0,0,0,0,0
0,0,0,0,0,0,0,0,0,0,0,0,0,0,0,0,0,0,0,0
0,0,0,0,0,0,0,0,21,21,21,0,0,0,0,0,0,0,0,0
0,0,0,0,0,0,0,25,9,1,1,0,0,0,0,0,0,0,0,0
0,0,0,0,0,0,9,1,1,1,1,1,1,1,0,0,0,0,0,0
0,0,0,0,0,9,1,1,1,1,1,1,1,1,1,0,0,0,0,0
0,0,0,0,0,1,1,1,1,1,1,1,1,1,1,0,0,0,0,0
0,0,0,0,9,1,1,1,1,1,1,1,1,1,1,1,0,0,0,0
0,0,0,0,9,1,1,1,1,1,1,1,1,1,1,0,0,0,0,0
0,0,0,0,9,1,1,1,1,1,1,1,1,1,1,0,15,0,0,0
0,0,0,0,0,1,1,1,1,1,1,1,1,1,1,0,15,0,0,0
0,0,0,0,0,8,1,1,1,1,1,1,1,1,1,16,24,0,0,0
0,0,0,0,0,0,8,1,1,1,1,1,1,1,16,0,0,15,0,0
0,0,0,0,0,0,0,0,0,1,1,1,0,0,0,0,0,0,0,0
0,0,0,0,0,0,0,0,0,0,0,0,0,0,0,0,0,0,0,0
0,0,0,0,0,0,0,0,0,0,0,15,0,0,0,0,0,0,0,0
0,0,0,0,0,0,0,0,0,0,20,20,0,0,0,0,0,0,0,0
0,0,0,0,0,0,0,0,0,0,0,0,0,0,0,0,0,0,0,0
0,0,0,0,0,0,0,0,0,0,0,0,0,0,0,0,0,0,0,0
0,0,0,0,0,0,0,0,0,0,0,0,0,0,0,0,0,0,0,0
0,0,0,0,0,0,0,0,0,0,0,0,0,0,0,0,0,0,0,0
0,0,0,0,0,0,0,0,0,0,0,0,0,0,0,0,0,0,0,0
0,0,0,0,0,0,0,0,0,0,0,0,0,0,0,0,0,0,0,0
0,0,0,0,0,0,0,0,0,0,0,0,0,0,0,0,0,0,0,0
0,0,0,0,0,0,0,0,0,0,0,0,0,0,0,0,0,0,0,0
:endlayer
layer: 36
0,0,0,0,0,0,0,0,0,0,0,0,0,0,0,0,0,0,0,0
0,0,0,0,0,0,0,0,0,0,0,0,0,0,0,0,0,0,0,0
0,0,0,0,0,0,0,0,0,0,0,0,0,0,0,0,0,0,0,0
0,0,0,0,0,0,0,0,0,0,0,0,0,0,0,0,0,0,0,0
0,0,0,0,0,0,0,0,0,0,0,0,0,0,0,0,0,0,0,0
0,0,0,0,0,0,0,0,21,21,21,0,0,0,0,0,0,0,0,0
0,0,0,0,0,0,0,25,1,1,1,1,0,0,0,0,0,0,0,0
0,0,0,0,0,0,25,1,1,1,1,1,1,1,0,0,0,0,0,0
0,0,0,0,0,0,1,1,1,1,1,1,1,1,1,0,0,0,0,0
0,0,0,0,0,1,1,1,1,1,1,1,1,1,1,1,0,0,0,0
0,0,0,0,0,1,1,1,1,1,1,1,1,1,1,1,0,0,0,0
0,0,0,0,0,1,1,1,1,1,1,1,1,1,1,1,0,0,0,0
0,0,0,0,0,1,1,1,1,1,1,1,1,1,1,1,15,0,0,0
0,0,0,0,0,1,1,1,1,1,1,1,1,1,1,8,15,0,0,0
0,0,0,0,0,9,1,1,1,1,1,1,1,1,1,16,24,0,0,0
0,0,0,0,0,0,9,1,1,1,1,1,1,1,16,0,0,15,0,0
0,0,0,0,0,0,0,0,1,1,1,1,0,0,0,0,0,0,0,0
0,0,0,0,0,0,0,0,0,0,0,0,0,0,0,0,0,0,0,0
0,0,0,0,0,0,0,0,0,0,0,15,0,0,0,0,0,0,0,0
0,0,0,0,0,0,0,0,0,0,20,20,0,0,0,0,0,0,0,0
0,0,0,0,0,0,0,0,0,0,0,0,0,0,0,0,0,0,0,0
0,0,0,0,0,0,0,0,0,0,0,0,0,0,0,0,0,0,0,0
0,0,0,0,0,0,0,0,0,0,0,0,0,0,0,0,0,0,0,0
0,0,0,0,0,0,0,0,0,0,0,0,0,0,0,0,0,0,0,0
0,0,0,0,0,0,0,0,0,0,0,0,0,0,0,0,0,0,0,0
0,0,0,0,0,0,0,0,0,0,0,0,0,0,0,0,0,0,0,0
0,0,0,0,0,0,0,0,0,0,0,0,0,0,0,0,0,0,0,0
0,0,0,0,0,0,0,0,0,0,0,0,0,0,0,0,0,0,0,0
:endlayer
layer: 37
0,0,0,0,0,0,0,0,0,0,0,0,0,0,0,0,0,0,0,0
0,0,0,0,0,0,0,0,0,0,0,0,0,0,0,0,0,0,0,0
0,0,0,0,0,0,0,0,0,0,0,0,0,0,0,0,0,0,0,0
0,0,0,0,0,0,0,0,0,0,0,0,0,0,0,0,0,0,0,0
0,0,0,0,0,0,0,0,0,0,0,0,0,0,0,0,0,0,0,0
0,0,0,0,0,0,0,0,21,21,21,0,0,0,0,0,0,0,0,0
0,0,0,0,0,0,0,25,1,1,1,1,1,0,0,0,0,0,0,0
0,0,0,0,0,0,25,1,1,1,1,1,1,1,0,0,0,0,0,0
0,0,0,0,0,0,1,1,1,1,1,1,1,1,1,0,0,0,0,0
0,0,0,0,0,1,1,1,1,1,1,1,1,1,1,1,0,0,0,0
0,0,0,0,0,1,1,1,1,1,1,1,1,1,1,1,0,0,0,0
0,0,0,0,0,1,1,1,1,1,1,1,1,1,1,1,0,0,0,0
0,0,0,0,0,1,1,1,1,1,1,1,1,1,1,1,15,0,0,0
0,0,0,0,0,8,1,1,1,1,1,1,1,1,1,16,15,0,0,0
0,0,0,0,0,0,1,1,1,1,1,1,1,1,8,16,24,0,0,0
0,0,0,0,0,0,0,1,1,1,1,1,1,8,16,0,0,15,0,0
0,0,0,0,0,0,0,0,1,1,1,1,0,0,0,0,0,0,0,0
0,0,0,0,0,0,0,0,0,0,0,0,0,0,0,0,0,0,0,0
0,0,0,0,0,0,0,0,0,0,0,15,0,0,0,0,0,0,0,0
0,0,0,0,0,0,0,0,0,0,20,20,0,0,0,0,0,0,0,0
0,0,0,0,0,0,0,0,0,0,0,0,0,0,0,0,0,0,0,0
0,0,0,0,0,0,0,0,0,0,0,0,0,0,0,0,0,0,0,0
0,0,0,0,0,0,0,0,0,0,0,0,0,0,0,0,0,0,0,0
0,0,0,0,0,0,0,0,0,0,0,0,0,0,0,0,0,0,0,0
0,0,0,0,0,0,0,0,0,0,0,0,0,0,0,0,0,0,0,0
0,0,0,0,0,0,0,0,0,0,0,0,0,0,0,0,0,0,0,0
0,0,0,0,0,0,0,0,0,0,0,0,0,0,0,0,0,0,0,0
0,0,0,0,0,0,0,0,0,0,0,0,0,0,0,0,0,0,0,0
:endlayer
layer: 38
0,0,0,0,0,0,0,0,0,0,0,0,0,0,0,0,0,0,0,0
0,0,0,0,0,0,0,0,0,0,0,0,0,0,0,0,0,0,0,0
0,0,0,0,0,0,0,0,0,0,0,0,0,0,0,0,0,0,0,0
0,0,0,0,0,0,0,0,0,0,0,0,0,0,0,0,0,0,0,0
0,0,0,0,0,0,0,0,0,0,0,0,0,0,0,0,0,0,0,0
0,0,0,0,0,0,0,0,21,21,21,0,0,0,0,0,0,0,0,0
0,0,0,0,0,0,0,25,8,1,1,1,8,0,0,0,0,0,0,0
0,0,0,0,0,0,25,1,1,1,1,1,1,1,0,0,0,0,0,0
0,0,0,0,0,0,1,1,1,1,1,1,1,1,1,0,0,0,0,0
0,0,0,0,0,8,1,1,1,1,1,1,1,1,1,8,0,0,0,0
0,0,0,0,0,1,1,1,1,1,1,1,1,1,1,1,0,0,0,0
0,0,0,0,0,1,1,1,1,1,1,1,1,1,1,1,0,0,0,0
0,0,0,0,0,1,1,1,1,1,1,1,1,1,1,1,15,0,0,0
0,0,0,0,0,0,1,1,1,1,1,1,1,1,1,15,15,0,0,0
0,0,0,0,0,0,1,1,1,1,1,1,1,1,0,16,24,0,0,0
0,0,0,0,0,0,0,1,1,1,1,1,1,0,16,0,0,15,0,0
0,0,0,0,0,0,0,0,1,1,1,1,8,0,0,0,0,0,0,0
0,0,0,0,0,0,0,0,0,0,0,0,0,0,0,0,0,0,0,0
0,0,0,0,0,0,0,0,0,0,0,15,0,0,0,0,0,0,0,0
0,0,0,0,0,0,0,0,0,0,20,20,0,0,0,0,0,0,0,0
0,0,0,0,0,0,0,0,0,0,0,0,0,0,0,0,0,0,0,0
0,0,0,0,0,0,0,0,0,0,0,0,0,0,0,0,0,0,0,0
0,0,0,0,0,0,0,0,0,0,0,0,0,0,0,0,0,0,0,0
0,0,0,0,0,0,0,0,0,0,0,0,0,0,0,0,0,0,0,0
0,0,0,0,0,0,0,0,0,0,0,0,0,0,0,0,0,0,0,0
0,0,0,0,0,0,0,0,0,0,0,0,0,0,0,0,0,0,0,0
0,0,0,0,0,0,0,0,0,0,0,0,0,0,0,0,0,0,0,0
0,0,0,0,0,0,0,0,0,0,0,0,0,0,0,0,0,0,0,0
:endlayer
layer: 39
0,0,0,0,0,0,0,0,0,0,0,0,0,0,0,0,0,0,0,0
0,0,0,0,0,0,0,0,0,0,0,0,0,0,0,0,0,0,0,0
0,0,0,0,0,0,0,0,0,0,0,0,0,0,0,0,0,0,0,0
0,0,0,0,0,0,0,0,0,0,0,0,0,0,0,0,0,0,0,0
0,0,0,0,0,0,0,0,0,0,0,0,0,0,0,0,0,0,0,0
0,0,0,0,0,0,0,0,0,21,21,0,0,0,0,0,0,0,0,0
0,0,0,0,0,0,0,21,9,8,8,8,9,0,0,0,0,0,0,0
0,0,0,0,0,0,25,8,1,1,1,1,1,8,0,0,0,0,0,0
0,0,0,0,0,0,1,1,1,1,1,1,1,1,8,0,0,0,0,0
0,0,0,0,0,0,1,1,1,1,1,1,1,1,1,9,0,0,0,0
0,0,0,0,0,1,1,1,1,1,1,1,1,1,1,8,0,0,0,0
0,0,0,0,0,1,1,1,1,1,1,1,1,1,1,8,0,0,0,0
0,0,0,0,0,1,1,1,1,1,1,1,1,1,1,8,15,0,0,0
0,0,0,0,0,0,1,1,1,1,1,1,1,1,1,15,15,0,0,0
0,0,0,0,0,0,1,1,1,1,1,1,1,1,1,16,24,0,0,0
0,0,0,0,0,0,1,1,1,1,1,1,1,1,16,0,0,15,0,0
0,0,0,0,0,0,0,1,1,1,1,1,9,0,0,0,0,0,0,0
0,0,0,0,0,0,0,0,0,0,0,0,0,0,0,0,0,0,0,0
0,0,0,0,0,0,0,0,0,0,0,15,0,0,0,0,0,0,0,0
0,0,0,0,0,0,0,0,0,0,20,20,0,0,0,0,0,0,0,0
0,0,0,0,0,0,0,0,0,0,0,0,0,0,0,0,0,0,0,0
0,0,0,0,0,0,0,0,0,0,0,0,0,0,0,0,0,0,0,0
0,0,0,0,0,0,0,0,0,0,0,0,0,0,0,0,0,0,0,0
0,0,0,0,0,0,0,0,0,0,0,0,0,0,0,0,0,0,0,0
0,0,0,0,0,0,0,0,0,0,0,0,0,0,0,0,0,0,0,0
0,0,0,0,0,0,0,0,0,0,0,0,0,0,0,0,0,0,0,0
0,0,0,0,0,0,0,0,0,0,0,0,0,0,0,0,0,0,0,0
0,0,0,0,0,0,0,0,0,0,0,0,0,0,0,0,0,0,0,0
:endlayer
layer: 40
0,0,0,0,0,0,0,0,0,0,0,0,0,0,0,0,0,0,0,0
0,0,0,0,0,0,0,0,0,0,0,0,0,0,0,0,0,0,0,0
0,0,0,0,0,0,0,0,0,0,0,0,0,0,0,0,0,0,0,0
0,0,0,0,0,0,0,0,0,0,0,0,0,0,0,0,0,0,0,0
0,0,0,0,0,0,0,0,0,0,0,0,0,0,0,0,0,0,0,0
0,0,0,0,0,0,0,0,0,0,0,0,0,0,0,0,0,0,0,0
0,0,0,0,0,0,0,21,21,9,9,14,0,0,0,0,0,0,0,0
0,0,0,0,0,0,25,9,1,1,1,1,8,0,0,0,0,0,0,0
0,0,0,0,0,0,1,1,1,1,1,1,1,8,0,0,0,0,0,0
0,0,0,0,0,1,1,1,1,1,1,1,1,1,8,0,0,0,0,0
0,0,0,0,0,1,1,1,1,1,1,1,1,1,1,9,0,0,0,0
0,0,0,0,1,1,1,1,1,1,1,1,1,1,1,9,0,0,0,0
0,0,0,0,0,1,1,1,1,1,1,1,1,1,1,9,15,0,0,0
0,0,0,0,0,1,1,1,1,1,1,1,1,1,1,15,15,0,0,0
0,0,0,0,0,0,1,1,1,1,1,1,1,1,8,16,24,0,0,0
0,0,0,0,0,0,1,1,1,1,1,1,1,1,16,0,0,15,0,0
0,0,0,0,0,0,1,1,1,1,1,1,1,0,0,0,0,0,0,0
0,0,0,0,0,0,0,0,0,0,1,0,0,0,0,0,0,0,0,0
0,0,0,0,0,0,0,0,0,0,0,15,0,0,0,0,0,0,0,0
0,0,0,0,0,0,0,0,0,0,20,20,0,0,0,0,0,0,0,0
0,0,0,0,0,0,0,0,0,0,0,0,0,0,0,0,0,0,0,0
0,0,0,0,0,0,0,0,0,0,0,0,0,0,0,0,0,0,0,0
0,0,0,0,0,0,0,0,0,0,0,0,0,0,0,0,0,0,0,0
0,0,0,0,0,0,0,0,0,0,0,0,0,0,0,0,0,0,0,0
0,0,0,0,0,0,0,0,0,0,0,0,0,0,0,0,0,0,0,0
0,0,0,0,0,0,0,0,0,0,0,0,0,0,0,0,0,0,0,0
0,0,0,0,0,0,0,0,0,0,0,0,0,0,0,0,0,0,0,0
0,0,0,0,0,0,0,0,0,0,0,0,0,0,0,0,0,0,0,0
:endlayer
layer: 41
0,0,0,0,0,0,0,0,0,0,0,0,0,0,0,0,0,0,0,0
0,0,0,0,0,0,0,0,0,0,0,0,0,0,0,0,0,0,0,0
0,0,0,0,0,0,0,0,0,0,0,0,0,0,0,0,0,0,0,0
0,0,0,0,0,0,0,0,0,0,0,0,0,0,0,0,0,0,0,0
0,0,0,0,0,0,0,0,0,0,0,0,0,0,0,0,0,0,0,0
0,0,0,0,0,0,0,0,0,0,0,0,0,0,0,0,0,0,0,0
0,0,0,0,0,0,0,21,21,21,21,21,0,0,0,0,0,0,0,0
0,0,0,0,0,0,25,1,1,1,1,1,24,0,0,0,0,0,0,0
0,0,0,0,0,0,1,1,1,1,1,1,1,9,0,0,0,0,0,0
0,0,0,0,0,1,1,1,1,1,1,1,1,1,9,0,0,0,0,0
0,0,0,0,0,1,1,1,1,1,1,1,1,1,1,0,0,0,0,0
0,0,0,0,1,1,1,1,1,1,1,1,1,1,1,0,0,0,0,0
0,0,0,0,1,1,1,1,1,1,1,1,1,1,1,0,15,0,0,0
0,0,0,0,0,1,1,1,1,1,1,1,1,1,1,15,15,0,0,0
0,0,0,0,0,0,1,1,1,1,1,1,1,1,9,16,24,0,0,0
0,0,0,0,0,0,1,1,1,1,1,1,1,1,16,0,0,15,0,0
0,0,0,0,0,0,1,1,1,1,1,1,1,0,0,0,0,0,0,0
0,0,0,0,0,0,0,0,0,1,1,1,0,0,0,0,0,0,0,0
0,0,0,0,0,0,0,0,0,0,0,15,0,0,0,0,0,0,0,0
0,0,0,0,0,0,0,0,0,0,20,20,0,0,0,0,0,0,0,0
0,0,0,0,0,0,0,0,0,0,0,0,0,0,0,0,0,0,0,0
0,0,0,0,0,0,0,0,0,0,0,0,0,0,0,0,0,0,0,0
0,0,0,0,0,0,0,0,0,0,0,0,0,0,0,0,0,0,0,0
0,0,0,0,0,0,0,0,0,0,0,0,0,0,0,0,0,0,0,0
0,0,0,0,0,0,0,0,0,0,0,0,0,0,0,0,0,0,0,0
0,0,0,0,0,0,0,0,0,0,0,0,0,0,0,0,0,0,0,0
0,0,0,0,0,0,0,0,0,0,0,0,0,0,0,0,0,0,0,0
0,0,0,0,0,0,0,0,0,0,0,0,0,0,0,0,0,0,0,0
:endlayer
layer: 42
0,0,0,0,0,0,0,0,0,0,0,0,0,0,0,0,0,0,0,0
0,0,0,0,0,0,0,0,0,0,0,0,0,0,0,0,0,0,0,0
0,0,0,0,0,0,0,0,0,0,0,0,0,0,0,0,0,0,0,0
0,0,0,0,0,0,0,0,0,0,0,0,0,0,0,0,0,0,0,0
0,0,0,0,0,0,0,0,0,0,0,0,0,0,0,0,0,0,0,0
0,0,0,0,0,0,0,0,0,0,0,0,0,0,0,0,0,0,0,0
0,0,0,0,0,0,0,21,21,21,21,21,0,0,0,0,0,0,0,0
0,0,0,0,0,0,25,1,1,1,1,1,24,0,0,0,0,0,0,0
0,0,0,0,0,0,1,1,1,1,1,1,1,0,0,0,0,0,0,0
0,0,0,0,0,1,1,1,1,1,1,1,1,1,0,0,0,0,0,0
0,0,0,0,1,1,1,1,1,1,1,1,1,1,1,0,0,0,0,0
0,0,0,0,1,1,1,1,1,1,1,1,1,1,1,0,0,0,0,0
0,0,0,0,1,1,1,1,1,1,1,1,1,1,1,0,15,0,0,0
0,0,0,0,1,1,1,1,1,1,1,1,1,1,1,15,15,0,0,0
0,0,0,0,0,1,1,1,1,1,1,1,1,1,1,16,24,0,0,0
0,0,0,0,0,0,1,1,1,1,1,1,1,1,16,0,0,15,0,0
0,0,0,0,0,0,1,1,1,1,1,1,1,0,0,0,0,0,0,0
0,0,0,0,0,0,0,0,1,1,1,1,0,0,0,0,0,0,0,0
0,0,0,0,0,0,0,0,0,0,0,15,0,0,0,0,0,0,0,0
0,0,0,0,0,0,0,0,0,0,20,20,0,0,0,0,0,0,0,0
0,0,0,0,0,0,0,0,0,0,0,0,0,0,0,0,0,0,0,0
0,0,0,0,0,0,0,0,0,0,0,0,0,0,0,0,0,0,0,0
0,0,0,0,0,0,0,0,0,0,0,0,0,0,0,0,0,0,0,0
0,0,0,0,0,0,0,0,0,0,0,0,0,0,0,0,0,0,0,0
0,0,0,0,0,0,0,0,0,0,0,0,0,0,0,0,0,0,0,0
0,0,0,0,0,0,0,0,0,0,0,0,0,0,0,0,0,0,0,0
0,0,0,0,0,0,0,0,0,0,0,0,0,0,0,0,0,0,0,0
0,0,0,0,0,0,0,0,0,0,0,0,0,0,0,0,0,0,0,0
:endlayer
layer: 43
0,0,0,0,0,0,0,0,0,0,0,0,0,0,0,0,0,0,0,0
0,0,0,0,0,0,0,0,0,0,0,0,0,0,0,0,0,0,0,0
0,0,0,0,0,0,0,0,0,0,0,0,0,0,0,0,0,0,0,0
0,0,0,0,0,0,0,0,0,0,0,0,0,0,0,0,0,0,0,0
0,0,0,0,0,0,0,0,0,0,0,0,0,0,0,0,0,0,0,0
0,0,0,0,0,0,0,0,0,0,0,0,0,0,0,0,0,0,0,0
0,0,0,0,0,0,0,21,21,21,21,21,0,0,0,0,0,0,0,0
0,0,0,0,0,0,25,1,1,1,1,1,24,0,0,0,0,0,0,0
0,0,0,0,0,0,1,1,1,1,1,1,1,0,0,0,0,0,0,0
0,0,0,0,0,1,1,1,1,1,1,1,1,1,0,0,0,0,0,0
0,0,0,0,1,1,1,1,1,1,1,1,1,1,1,0,0,0,0,0
0,0,0,0,1,1,1,1,1,1,1,1,1,1,1,0,0,0,0,0
0,0,0,0,1,1,1,1,1,1,1,1,1,1,1,0,15,0,0,0
0,0,0,0,1,1,1,1,1,1,1,1,1,1,1,15,15,0,0,0
0,0,0,0,1,1,1,1,1,1,1,1,1,1,8,16,24,0,0,0
0,0,0,0,0,1,1,1,1,1,1,1,1,1,16,0,0,15,0,0
0,0,0,0,0,0,1,1,1,1,1,1,1,0,0,0,0,0,0,0
0,0,0,0,0,0,0,1,1,1,1,1,0,0,0,0,0,0,0,0
0,0,0,0,0,0,0,0,0,0,0,15,0,0,0,0,0,0,0,0
0,0,0,0,0,0,0,0,0,0,20,20,0,0,0,0,0,0,0,0
0,0,0,0,0,0,0,0,0,0,0,0,0,0,0,0,0,0,0,0
0,0,0,0,0,0,0,0,0,0,0,0,0,0,0,0,0,0,0,0
0,0,0,0,0,0,0,0,0,0,0,0,0,0,0,0,0,0,0,0
0,0,0,0,0,0,0,0,0,0,0,0,0,0,0,0,0,0,0,0
0,0,0,0,0,0,0,0,0,0,0,0,0,0,0,0,0,0,0,0
0,0,0,0,0,0,0,0,0,0,0,0,0,0,0,0,0,0,0,0
0,0,0,0,0,0,0,0,0,0,0,0,0,0,0,0,0,0,0,0
0,0,0,0,0,0,0,0,0,0,0,0,0,0,0,0,0,0,0,0
:endlayer
layer: 44
0,0,0,0,0,0,0,0,0,0,0,0,0,0,0,0,0,0,0,0
0,0,0,0,0,0,0,0,0,0,0,0,0,0,0,0,0,0,0,0
0,0,0,0,0,0,0,0,0,0,0,0,0,0,0,0,0,0,0,0
0,0,0,0,0,0,0,0,0,0,0,0,0,0,0,0,0,0,0,0
0,0,0,0,0,0,0,0,0,0,0,0,0,0,0,0,0,0,0,0
0,0,0,0,0,0,0,0,0,0,0,0,0,0,0,0,0,0,0,0
0,0,0,0,0,0,0,21,21,21,21,0,0,0,0,0,0,0,0,0
0,0,0,0,0,0,25,8,1,1,1,8,24,0,0,0,0,0,0,0
0,0,0,0,0,0,1,1,1,1,1,1,1,0,0,0,0,0,0,0
0,0,0,0,0,1,1,1,1,1,1,1,1,1,0,0,0,0,0,0
0,0,0,0,8,1,1,1,1,1,1,1,1,1,8,0,0,0,0,0
0,0,0,0,1,1,1,1,1,1,1,1,1,1,1,0,0,0,0,0
0,0,0,0,1,1,1,1,1,1,1,1,1,1,1,0,15,0,0,0
0,0,0,0,1,1,1,1,1,1,1,1,1,1,1,15,15,0,0,0
0,0,0,0,8,1,1,1,1,1,1,1,1,1,9,16,24,0,0,0
0,0,0,0,0,1,1,1,1,1,1,1,1,1,16,0,0,15,0,0
0,0,0,0,0,0,1,1,1,1,1,1,1,0,0,0,0,0,0,0
0,0,0,0,0,0,0,8,1,1,1,8,0,0,0,0,0,0,0,0
0,0,0,0,0,0,0,0,0,0,0,15,0,0,0,0,0,0,0,0
0,0,0,0,0,0,0,0,0,0,20,20,0,0,0,0,0,0,0,0
0,0,0,0,0,0,0,0,0,0,0,0,0,0,0,0,0,0,0,0
0,0,0,0,0,0,0,0,0,0,0,0,0,0,0,0,0,0,0,0
0,0,0,0,0,0,0,0,0,0,0,0,0,0,0,0,0,0,0,0
0,0,0,0,0,0,0,0,0,0,0,0,0,0,0,0,0,0,0,0
0,0,0,0,0,0,0,0,0,0,0,0,0,0,0,0,0,0,0,0
0,0,0,0,0,0,0,0,0,0,0,0,0,0,0,0,0,0,0,0
0,0,0,0,0,0,0,0,0,0,0,0,0,0,0,0,0,0,0,0
0,0,0,0,0,0,0,0,0,0,0,0,0,0,0,0,0,0,0,0
:endlayer
layer: 45
0,0,0,0,0,0,0,0,0,0,0,0,0,0,0,0,0,0,0,0
0,0,0,0,0,0,0,0,0,0,0,0,0,0,0,0,0,0,0,0
0,0,0,0,0,0,0,0,0,0,0,0,0,0,0,0,0,0,0,0
0,0,0,0,0,0,0,0,0,0,0,0,0,0,0,0,0,0,0,0
0,0,0,0,0,0,0,0,0,0,0,0,0,0,0,0,0,0,0,0
0,0,0,0,0,0,0,0,0,0,0,0,0,0,0,0,0,0,0,0
0,0,0,0,0,0,0,21,21,21,21,0,0,0,0,0,0,0,0,0
0,0,0,0,0,0,25,0,1,1,1,9,24,0,0,0,0,0,0,0
0,0,0,0,0,0,1,1,1,1,1,1,1,0,0,0,0,0,0,0
0,0,0,0,0,1,1,1,1,1,1,1,1,1,0,0,0,0,0,0
0,0,0,0,0,1,1,1,1,1,1,1,1,1,9,0,0,0,0,0
0,0,0,0,1,1,1,1,1,1,1,1,1,1,26,0,0,0,0,0
0,0,0,0,1,1,1,1,1,1,1,1,1,1,26,0,15,0,0,0
0,0,0,0,8,1,1,1,1,1,1,1,1,1,1,15,15,0,0,0
0,0,0,0,0,1,1,1,1,1,1,1,1,1,0,16,24,0,0,0
0,0,0,0,0,1,1,1,1,1,1,1,1,1,16,0,0,15,0,0
0,0,0,0,0,0,1,1,1,1,1,1,1,0,0,0,0,0,0,0
0,0,0,0,0,0,0,0,1,1,1,0,0,0,0,0,0,0,0,0
0,0,0,0,0,0,0,0,0,0,0,15,0,0,0,0,0,0,0,0
0,0,0,0,0,0,0,0,0,0,20,20,0,0,0,0,0,0,0,0
0,0,0,0,0,0,0,0,0,0,0,0,0,0,0,0,0,0,0,0
0,0,0,0,0,0,0,0,0,0,0,0,0,0,0,0,0,0,0,0
0,0,0,0,0,0,0,0,0,0,0,0,0,0,0,0,0,0,0,0
0,0,0,0,0,0,0,0,0,0,0,0,0,0,0,0,0,0,0,0
0,0,0,0,0,0,0,0,0,0,0,0,0,0,0,0,0,0,0,0
0,0,0,0,0,0,0,0,0,0,0,0,0,0,0,0,0,0,0,0
0,0,0,0,0,0,0,0,0,0,0,0,0,0,0,0,0,0,0,0
0,0,0,0,0,0,0,0,0,0,0,0,0,0,0,0,0,0,0,0
:endlayer
layer: 46
0,0,0,0,0,0,0,0,0,0,0,0,0,0,0,0,0,0,0,0
0,0,0,0,0,0,0,0,0,0,0,0,0,0,0,0,0,0,0,0
0,0,0,0,0,0,0,0,0,0,0,0,0,0,0,0,0,0,0,0
0,0,0,0,0,0,0,0,0,0,0,0,0,0,0,0,0,0,0,0
0,0,0,0,0,0,0,0,0,0,0,0,0,0,0,0,0,0,0,0
0,0,0,0,0,0,0,0,0,0,0,0,0,0,0,0,0,0,0,0
0,0,0,0,0,0,0,21,21,21,21,0,0,0,0,0,0,0,0,0
0,0,0,0,0,0,25,1,1,1,1,1,15,0,0,0,0,0,0,0
0,0,0,0,0,0,1,1,1,1,1,1,1,0,0,0,0,0,0,0
0,0,0,0,0,1,1,1,1,1,1,1,1,1,0,0,0,0,0,0
0,0,0,0,1,1,1,1,1,1,1,1,1,1,26,0,0,0,0,0
0,0,0,0,1,1,1,1,1,1,1,1,1,1,26,0,0,0,0,0
0,0,0,0,1,1,1,1,1,1,1,1,1,1,1,0,15,0,0,0
0,0,0,0,0,1,1,1,1,1,1,1,1,1,26,15,15,0,0,0
0,0,0,0,0,1,1,1,1,1,1,1,1,1,1,16,24,0,0,0
0,0,0,0,0,1,1,1,1,1,1,1,1,1,16,0,0,15,0,0
0,0,0,0,0,0,1,1,1,1,1,1,1,0,0,0,0,0,0,0
0,0,0,0,0,0,0,1,1,1,1,0,0,0,0,0,0,0,0,0
0,0,0,0,0,0,0,0,0,0,0,15,0,0,0,0,0,0,0,0
0,0,0,0,0,0,0,0,0,0,20,20,0,0,0,0,0,0,0,0
0,0,0,0,0,0,0,0,0,0,0,0,0,0,0,0,0,0,0,0
0,0,0,0,0,0,0,0,0,0,0,0,0,0,0,0,0,0,0,0
0,0,0,0,0,0,0,0,0,0,0,0,0,0,0,0,0,0,0,0
0,0,0,0,0,0,0,0,0,0,0,0,0,0,0,0,0,0,0,0
0,0,0,0,0,0,0,0,0,0,0,0,0,0,0,0,0,0,0,0
0,0,0,0,0,0,0,0,0,0,0,0,0,0,0,0,0,0,0,0
0,0,0,0,0,0,0,0,0,0,0,0,0,0,0,0,0,0,0,0
0,0,0,0,0,0,0,0,0,0,0,0,0,0,0,0,0,0,0,0
:endlayer
layer: 47
0,0,0,0,0,0,0,0,0,0,0,0,0,0,0,0,0,0,0,0
0,0,0,0,0,0,0,0,0,0,0,0,0,0,0,0,0,0,0,0
0,0,0,0,0,0,0,0,0,0,0,0,0,0,0,0,0,0,0,0
0,0,0,0,0,0,0,0,0,0,0,0,0,0,0,0,0,0,0,0
0,0,0,0,0,0,0,0,0,0,0,0,0,0,0,0,0,0,0,0
0,0,0,0,0,0,0,0,0,0,0,0,0,0,0,0,0,0,0,0
0,0,0,0,0,0,0,21,21,21,21,0,0,0,0,0,0,0,0,0
0,0,0,0,0,0,21,1,1,1,1,1,0,0,0,0,0,0,0,0
0,0,0,0,0,0,1,1,1,1,1,1,1,0,0,0,0,0,0,0
0,0,0,0,0,1,1,1,1,1,1,1,1,1,0,0,0,0,0,0
0,0,0,0,1,1,1,1,1,1,1,1,1,1,26,0,0,0,0,0
0,0,0,0,1,1,1,1,1,1,1,1,1,1,1,0,0,0,0,0
0,0,0,0,1,1,1,1,1,1,1,1,1,1,1,0,15,0,0,0
0,0,0,0,0,1,1,1,1,1,1,1,1,1,26,0,15,0,0,0
0,0,0,0,0,1,1,1,1,1,1,1,1,1,1,20,24,0,0,0
0,0,0,0,0,1,1,1,1,1,1,1,1,1,16,0,0,15,0,0
0,0,0,0,0,0,1,1,1,1,1,1,1,0,0,0,0,0,0,0
0,0,0,0,0,0,0,1,1,1,1,1,0,0,0,0,0,0,0,0
0,0,0,0,0,0,0,0,0,0,0,15,0,0,0,0,0,0,0,0
0,0,0,0,0,0,0,0,0,0,20,20,0,0,0,0,0,0,0,0
0,0,0,0,0,0,0,0,0,0,0,0,0,0,0,0,0,0,0,0
0,0,0,0,0,0,0,0,0,0,0,0,0,0,0,0,0,0,0,0
0,0,0,0,0,0,0,0,0,0,0,0,0,0,0,0,0,0,0,0
0,0,0,0,0,0,0,0,0,0,0,0,0,0,0,0,0,0,0,0
0,0,0,0,0,0,0,0,0,0,0,0,0,0,0,0,0,0,0,0
0,0,0,0,0,0,0,0,0,0,0,0,0,0,0,0,0,0,0,0
0,0,0,0,0,0,0,0,0,0,0,0,0,0,0,0,0,0,0,0
0,0,0,0,0,0,0,0,0,0,0,0,0,0,0,0,0,0,0,0
:endlayer
layer: 48
0,0,0,0,0,0,0,0,0,0,0,0,0,0,0,0,0,0,0,0
0,0,0,0,0,0,0,0,0,0,0,0,0,0,0,0,0,0,0,0
0,0,0,0,0,0,0,0,0,0,0,0,0,0,0,0,0,0,0,0
0,0,0,0,0,0,0,0,0,0,0,0,0,0,0,0,0,0,0,0
0,0,0,0,0,0,0,0,0,0,0,0,0,0,0,0,0,0,0,0
0,0,0,0,0,0,0,0,0,0,0,0,0,0,0,0,0,0,0,0
0,0,0,0,0,0,0,21,21,21,21,0,0,0,0,0,0,0,0,0
0,0,0,0,0,0,21,8,1,1,1,8,0,0,0,0,0,0,0,0
0,0,0,0,0,0,1,1,1,1,1,1,1,0,0,0,0,0,0,0
0,0,0,0,0,1,1,1,1,1,1,1,1,1,0,0,0,0,0,0
0,0,0,0,8,1,1,1,1,1,1,1,1,1,1,0,0,0,0,0
0,0,0,0,1,1,1,1,1,1,1,1,1,1,26,0,0,0,0,0
0,0,0,0,1,1,1,1,1,1,1,1,1,1,26,0,15,0,0,0
0,0,0,0,1,1,1,1,1,1,1,1,1,1,1,0,15,0,0,0
0,0,0,0,1,1,1,1,1,1,1,1,1,1,1,20,24,0,0,0
0,0,0,0,0,1,1,1,1,1,1,1,1,1,16,0,0,15,0,0
0,0,0,0,0,0,1,1,1,1,1,1,1,0,0,0,0,0,0,0
0,0,0,0,0,0,0,1,1,1,1,8,0,0,0,0,0,0,0,0
0,0,0,0,0,0,0,0,0,0,0,15,0,0,0,0,0,0,0,0
0,0,0,0,0,0,0,0,0,0,20,18,0,0,0,0,0,0,0,0
0,0,0,0,0,0,0,0,0,0,0,0,0,0,0,0,0,0,0,0
0,0,0,0,0,0,0,0,0,0,0,0,0,0,0,0,0,0,0,0
0,0,0,0,0,0,0,0,0,0,0,0,0,0,0,0,0,0,0,0
0,0,0,0,0,0,0,0,0,0,0,0,0,0,0,0,0,0,0,0
0,0,0,0,0,0,0,0,0,0,0,0,0,0,0,0,0,0,0,0
0,0,0,0,0,0,0,0,0,0,0,0,0,0,0,0,0,0,0,0
0,0,0,0,0,0,0,0,0,0,0,0,0,0,0,0,0,0,0,0
0,0,0,0,0,0,0,0,0,0,0,0,0,0,0,0,0,0,0,0
:endlayer
layer: 49
0,0,0,0,0,0,0,0,0,0,0,0,0,0,0,0,0,0,0,0
0,0,0,0,0,0,0,0,0,0,0,0,0,0,0,0,0,0,0,0
0,0,0,0,0,0,0,0,0,0,0,0,0,0,0,0,0,0,0,0
0,0,0,0,0,0,0,0,0,0,0,0,0,0,0,0,0,0,0,0
0,0,0,0,0,0,0,0,0,0,0,0,0,0,0,0,0,0,0,0
0,0,0,0,0,0,0,0,0,0,0,0,0,0,0,0,0,0,0,0
0,0,0,0,0,0,0,0,21,21,21,0,0,0,0,0,0,0,0,0
0,0,0,0,0,0,21,13,1,1,1,9,0,0,0,0,0,0,0,0
0,0,0,0,0,0,8,1,1,1,1,1,1,0,0,0,0,0,0,0
0,0,0,0,0,8,1,1,1,1,1,1,1,1,0,0,0,0,0,0
0,0,0,0,9,1,1,1,1,1,1,1,1,1,1,0,0,0,0,0
0,0,0,0,1,1,1,1,1,1,1,1,1,1,1,0,0,0,0,0
0,0,0,0,1,1,1,1,1,1,1,1,1,1,1,0,15,0,0,0
0,0,0,0,1,1,1,1,1,1,1,1,1,1,1,0,15,0,0,0
0,0,0,0,8,1,1,1,1,1,1,1,1,1,1,20,24,0,0,0
0,0,0,0,0,1,1,1,1,1,1,1,1,1,16,0,0,15,0,0
0,0,0,0,0,0,1,1,1,1,1,1,1,0,0,0,0,0,0,0
0,0,0,0,0,0,0,8,1,1,1,0,0,0,0,0,0,0,0,0
0,0,0,0,0,0,0,0,0,0,0,15,0,0,0,0,0,0,0,0
0,0,0,0,0,0,0,0,0,0,20,18,0,0,0,0,0,0,0,0
0,0,0,0,0,0,0,0,0,0,0,0,0,0,0,0,0,0,0,0
0,0,0,0,0,0,0,0,0,0,0,0,0,0,0,0,0,0,0,0
0,0,0,0,0,0,0,0,0,0,0,0,0,0,0,0,0,0,0,0
0,0,0,0,0,0,0,0,0,0,0,0,0,0,0,0,0,0,0,0
0,0,0,0,0,0,0,0,0,0,0,0,0,0,0,0,0,0,0,0
0,0,0,0,0,0,0,0,0,0,0,0,0,0,0,0,0,0,0,0
0,0,0,0,0,0,0,0,0,0,0,0,0,0,0,0,0,0,0,0
0,0,0,0,0,0,0,0,0,0,0,0,0,0,0,0,0,0,0,0
:endlayer
layer: 50
0,0,0,0,0,0,0,0,0,0,0,0,0,0,0,0,0,0,0,0
0,0,0,0,0,0,0,0,0,0,0,0,0,0,0,0,0,0,0,0
0,0,0,0,0,0,0,0,0,0,0,0,0,0,0,0,0,0,0,0
0,0,0,0,0,0,0,0,0,0,0,0,0,0,0,0,0,0,0,0
0,0,0,0,0,0,0,0,0,0,0,0,0,0,0,0,0,0,0,0
0,0,0,0,0,0,0,0,0,0,0,0,0,0,0,0,0,0,0,0
0,0,0,0,0,0,0,0,21,21,21,0,0,0,0,0,0,0,0,0
0,0,0,0,0,0,0,0,8,1,1,1,0,0,0,0,0,0,0,0
0,0,0,0,0,0,9,1,1,1,1,1,1,1,0,0,0,0,0,0
0,0,0,0,0,9,1,1,1,1,1,1,1,1,1,0,0,0,0,0
0,0,0,0,0,1,1,1,1,1,1,1,1,1,1,0,0,0,0,0
0,0,0,0,8,1,1,1,1,1,1,1,1,1,1,1,0,0,0,0
0,0,0,0,8,1,1,1,1,1,1,1,1,1,1,0,15,0,0,0
0,0,0,0,8,1,1,1,1,1,1,1,1,1,1,0,15,0,0,0
0,0,0,0,0,1,1,1,1,1,1,1,1,1,1,20,24,0,0,0
0,0,0,0,0,8,1,1,1,1,1,1,1,1,1,0,0,15,0,0
0,0,0,0,0,0,8,1,1,1,1,1,1,1,0,0,0,0,0,0
0,0,0,0,0,0,0,9,8,1,1,0,0,0,0,0,0,0,0,0
0,0,0,0,0,0,0,0,0,0,0,15,0,0,0,0,0,0,0,0
0,0,0,0,0,0,0,0,0,0,20,18,0,0,0,0,0,0,0,0
0,0,0,0,0,0,0,0,0,0,0,0,0,0,0,0,0,0,0,0
0,0,0,0,0,0,0,0,0,0,0,0,0,0,0,0,0,0,0,0
0,0,0,0,0,0,0,0,0,0,0,0,0,0,0,0,0,0,0,0
0,0,0,0,0,0,0,0,0,0,0,0,0,0,0,0,0,0,0,0
0,0,0,0,0,0,0,0,0,0,0,0,0,0,0,0,0,0,0,0
0,0,0,0,0,0,0,0,0,0,0,0,0,0,0,0,0,0,0,0
0,0,0,0,0,0,0,0,0,0,0,0,0,0,0,0,0,0,0,0
0,0,0,0,0,0,0,0,0,0,0,0,0,0,0,0,0,0,0,0
:endlayer
layer: 51
0,0,0,0,0,0,0,0,0,0,0,0,0,0,0,0,0,0,0,0
0,0,0,0,0,0,0,0,0,0,0,0,0,0,0,0,0,0,0,0
0,0,0,0,0,0,0,0,0,0,0,0,0,0,0,0,0,0,0,0
0,0,0,0,0,0,0,0,0,0,0,0,0,0,0,0,0,0,0,0
0,0,0,0,0,0,0,0,0,0,0,0,0,0,0,0,0,0,0,0
0,0,0,0,0,0,0,0,0,0,0,0,0,0,0,0,0,0,0,0
0,0,0,0,0,0,0,0,0,21,21,0,0,0,0,0,0,0,0,0
0,0,0,0,0,0,0,0,9,1,1,1,1,0,0,0,0,0,0,0
0,0,0,0,0,0,0,1,1,1,1,1,1,1,0,0,0,0,0,0
0,0,0,0,0,0,1,1,1,1,1,1,1,1,1,0,0,0,0,0
0,0,0,0,0,1,1,1,1,1,1,1,1,1,1,1,0,0,0,0
0,0,0,0,9,1,1,1,1,1,1,1,1,1,1,1,0,0,0,0
0,0,0,0,9,1,1,1,1,1,1,1,1,1,1,1,15,0,0,0
0,0,0,0,9,1,1,1,1,1,1,1,1,1,1,0,15,0,0,0
0,0,0,0,0,1,1,1,1,1,1,1,1,1,1,20,24,0,0,0
0,0,0,0,0,9,1,1,1,1,1,1,1,1,1,0,0,15,0,0
0,0,0,0,0,0,9,1,1,1,1,1,1,1,0,0,0,0,0,0
0,0,0,0,0,0,0,0,9,1,1,0,0,0,0,0,0,0,0,0
0,0,0,0,0,0,0,0,0,0,0,15,0,0,0,0,0,0,0,0
0,0,0,0,0,0,0,0,0,0,20,18,0,0,0,0,0,0,0,0
0,0,0,0,0,0,0,0,0,0,0,0,0,0,0,0,0,0,0,0
0,0,0,0,0,0,0,0,0,0,0,0,0,0,0,0,0,0,0,0
0,0,0,0,0,0,0,0,0,0,0,0,0,0,0,0,0,0,0,0
0,0,0,0,0,0,0,0,0,0,0,0,0,0,0,0,0,0,0,0
0,0,0,0,0,0,0,0,0,0,0,0,0,0,0,0,0,0,0,0
0,0,0,0,0,0,0,0,0,0,0,0,0,0,0,0,0,0,0,0
0,0,0,0,0,0,0,0,0,0,0,0,0,0,0,0,0,0,0,0
0,0,0,0,0,0,0,0,0,0,0,0,0,0,0,0,0,0,0,0
:endlayer
layer: 52
0,0,0,0,0,0,0,0,0,0,0,0,0,0,0,0,0,0,0,0
0,0,0,0,0,0,0,0,0,0,0,0,0,0,0,0,0,0,0,0
0,0,0,0,0,0,0,0,0,0,0,0,0,0,0,0,0,0,0,0
0,0,0,0,0,0,0,0,0,0,0,0,0,0,0,0,0,0,0,0
0,0,0,0,0,0,0,0,0,0,0,0,0,0,0,0,0,0,0,0
0,0,0,0,0,0,0,0,0,0,0,0,0,0,0,0,0,0,0,0
0,0,0,0,0,0,0,0,0,21,21,0,0,0,0,0,0,0,0,0
0,0,0,0,0,0,0,0,1,1,1,1,1,0,0,0,0,0,0,0
0,0,0,0,0,0,0,1,1,1,1,1,1,1,0,0,0,0,0,0
0,0,0,0,0,0,1,1,1,1,1,1,1,1,1,0,0,0,0,0
0,0,0,0,0,1,1,1,1,1,1,1,1,1,1,1,0,0,0,0
0,0,0,0,0,1,1,1,1,1,1,1,1,1,1,1,0,0,0,0
0,0,0,0,0,1,1,1,1,1,1,1,1,1,1,1,15,0,0,0
0,0,0,0,0,1,1,1,1,1,1,1,1,1,1,1,15,0,0,0
0,0,0,0,0,1,1,1,1,1,1,1,1,1,1,20,24,0,0,0
0,0,0,0,0,0,1,1,1,1,1,1,1,1,1,0,0,15,0,0
0,0,0,0,0,0,0,1,1,1,1,1,1,1,0,0,0,0,0,0
0,0,0,0,0,0,0,0,1,1,1,1,0,0,0,0,0,0,0,0
0,0,0,0,0,0,0,0,0,0,0,15,0,0,0,0,0,0,0,0
0,0,0,0,0,0,0,0,0,0,20,18,0,0,0,0,0,0,0,0
0,0,0,0,0,0,0,0,0,0,0,0,0,0,0,0,0,0,0,0
0,0,0,0,0,0,0,0,0,0,0,0,0,0,0,0,0,0,0,0
0,0,0,0,0,0,0,0,0,0,0,0,0,0,0,0,0,0,0,0
0,0,0,0,0,0,0,0,0,0,0,0,0,0,0,0,0,0,0,0
0,0,0,0,0,0,0,0,0,0,0,0,0,0,0,0,0,0,0,0
0,0,0,0,0,0,0,0,0,0,0,0,0,0,0,0,0,0,0,0
0,0,0,0,0,0,0,0,0,0,0,0,0,0,0,0,0,0,0,0
0,0,0,0,0,0,0,0,0,0,0,0,0,0,0,0,0,0,0,0
:endlayer
layer: 53
0,0,0,0,0,0,0,0,0,0,0,0,0,0,0,0,0,0,0,0
0,0,0,0,0,0,0,0,0,0,0,0,0,0,0,0,0,0,0,0
0,0,0,0,0,0,0,0,0,0,0,0,0,0,0,0,0,0,0,0
0,0,0,0,0,0,0,0,0,0,0,0,0,0,0,0,0,0,0,0
0,0,0,0,0,0,0,0,0,0,0,0,0,0,0,0,0,0,0,0
0,0,0,0,0,0,0,0,0,0,0,0,0,0,0,0,0,0,0,0
0,0,0,0,0,0,0,0,0,21,21,0,0,0,0,0,0,0,0,0
0,0,0,0,0,0,0,0,8,1,1,1,8,0,0,0,0,0,0,0
0,0,0,0,0,0,0,1,1,1,1,1,1,1,0,0,0,0,0,0
0,0,0,0,0,0,1,1,1,1,1,1,1,1,1,0,0,0,0,0
0,0,0,0,0,1,1,1,1,1,1,1,1,1,1,8,0,0,0,0
0,0,0,0,0,1,1,1,1,1,1,1,1,1,1,1,0,0,0,0
0,0,0,0,0,1,1,1,1,1,1,1,1,1,1,1,15,0,0,0
0,0,0,0,0,1,1,1,1,1,1,1,1,1,1,1,15,0,0,0
0,0,0,0,0,1,1,1,1,1,1,1,1,1,1,1,24,0,0,0
0,0,0,0,0,0,1,1,1,1,1,1,1,1,1,0,0,15,0,0
0,0,0,0,0,0,0,1,1,1,1,1,1,1,0,0,0,0,0,0
0,0,0,0,0,0,0,0,1,1,1,1,1,0,0,0,0,0,0,0
0,0,0,0,0,0,0,0,0,0,0,15,0,0,0,0,0,0,0,0
0,0,0,0,0,0,0,0,0,0,20,18,0,0,0,0,0,0,0,0
0,0,0,0,0,0,0,0,0,0,0,0,0,0,0,0,0,0,0,0
0,0,0,0,0,0,0,0,0,0,0,0,0,0,0,0,0,0,0,0
0,0,0,0,0,0,0,0,0,0,0,0,0,0,0,0,0,0,0,0
0,0,0,0,0,0,0,0,0,0,0,0,0,0,0,0,0,0,0,0
0,0,0,0,0,0,0,0,0,0,0,0,0,0,0,0,0,0,0,0
0,0,0,0,0,0,0,0,0,0,0,0,0,0,0,0,0,0,0,0
0,0,0,0,0,0,0,0,0,0,0,0,0,0,0,0,0,0,0,0
0,0,0,0,0,0,0,0,0,0,0,0,0,0,0,0,0,0,0,0
:endlayer
layer: 54
0,0,0,0,0,0,0,0,0,0,0,0,0,0,0,0,0,0,0,0
0,0,0,0,0,0,0,0,0,0,0,0,0,0,0,0,0,0,0,0
0,0,0,0,0,0,0,0,0,0,0,0,0,0,0,0,0,0,0,0
0,0,0,0,0,0,0,0,0,0,0,0,0,0,0,0,0,0,0,0
0,0,0,0,0,0,0,0,0,0,0,0,0,0,0,0,0,0,0,0
0,0,0,0,0,0,0,0,0,0,0,0,0,0,0,0,0,0,0,0
0,0,0,0,0,0,0,0,0,21,21,0,0,0,0,0,0,0,0,0
0,0,0,0,0,0,0,0,25,8,8,8,0,0,0,0,0,0,0,0
0,0,0,0,0,0,0,8,1,1,1,1,1,8,0,0,0,0,0,0
0,0,0,0,0,0,1,1,1,1,1,1,1,1,8,0,0,0,0,0
0,0,0,0,0,8,1,1,1,1,1,1,1,1,1,0,0,0,0,0
0,0,0,0,0,1,1,1,1,1,1,1,1,1,1,1,0,0,0,0
0,0,0,0,0,1,1,1,1,1,1,1,1,1,1,1,15,0,0,0
0,0,0,0,0,1,1,1,1,1,1,1,1,1,1,1,15,0,0,0
0,0,0,0,0,8,1,1,1,1,1,1,1,1,1,27,24,0,0,0
0,0,0,0,0,0,1,1,1,1,1,1,1,1,1,0,0,15,0,0
0,0,0,0,0,0,0,1,1,1,1,1,1,1,0,0,0,0,0,0
0,0,0,0,0,0,0,0,1,1,1,1,1,0,0,0,0,0,0,0
0,0,0,0,0,0,0,0,0,0,0,15,0,0,0,0,0,0,0,0
0,0,0,0,0,0,0,0,0,0,20,18,0,0,0,0,0,0,0,0
0,0,0,0,0,0,0,0,0,0,0,0,0,0,0,0,0,0,0,0
0,0,0,0,0,0,0,0,0,0,0,0,0,0,0,0,0,0,0,0
0,0,0,0,0,0,0,0,0,0,0,0,0,0,0,0,0,0,0,0
0,0,0,0,0,0,0,0,0,0,0,0,0,0,0,0,0,0,0,0
0,0,0,0,0,0,0,0,0,0,0,0,0,0,0,0,0,0,0,0
0,0,0,0,0,0,0,0,0,0,0,0,0,0,0,0,0,0,0,0
0,0,0,0,0,0,0,0,0,0,0,0,0,0,0,0,0,0,0,0
0,0,0,0,0,0,0,0,0,0,0,0,0,0,0,0,0,0,0,0
:endlayer
layer: 55
0,0,0,0,0,0,0,0,0,0,0,0,0,0,0,0,0,0,0,0
0,0,0,0,0,0,0,0,0,0,0,0,0,0,0,0,0,0,0,0
0,0,0,0,0,0,0,0,0,0,0,0,0,0,0,0,0,0,0,0
0,0,0,0,0,0,0,0,0,0,0,0,0,0,0,0,0,0,0,0
0,0,0,0,0,0,0,0,0,0,0,0,0,0,0,0,0,0,0,0
0,0,0,0,0,0,0,0,0,0,0,0,0,0,0,0,0,0,0,0
0,0,0,0,0,0,0,0,0,0,0,0,0,0,0,0,0,0,0,0
0,0,0,0,0,0,0,0,21,24,28,21,0,0,0,0,0,0,0,0
0,0,0,0,0,0,0,0,1,1,1,1,1,0,0,0,0,0,0,0
0,0,0,0,0,0,8,1,1,1,1,1,1,1,0,0,0,0,0,0
0,0,0,0,0,0,1,1,1,1,1,1,1,1,1,0,0,0,0,0
0,0,0,0,0,8,1,1,1,1,1,1,1,1,1,8,0,0,0,0
0,0,0,0,0,1,1,1,1,1,1,1,1,1,1,1,15,0,0,0
0,0,0,0,0,1,1,1,1,1,1,1,1,1,1,1,15,0,0,0
0,0,0,0,0,0,1,1,1,1,1,1,1,1,1,20,24,0,0,0
0,0,0,0,0,0,1,1,1,1,1,1,1,1,1,0,0,15,0,0
0,0,0,0,0,0,1,1,1,1,1,1,1,1,1,0,0,0,0,0
0,0,0,0,0,0,0,1,1,1,1,1,1,1,0,0,0,0,0,0
0,0,0,0,0,0,0,0,0,1,0,15,0,0,0,0,0,0,0,0
0,0,0,0,0,0,0,0,0,0,20,18,0,0,0,0,0,0,0,0
0,0,0,0,0,0,0,0,0,0,0,0,0,0,0,0,0,0,0,0
0,0,0,0,0,0,0,0,0,0,0,0,0,0,0,0,0,0,0,0
0,0,0,0,0,0,0,0,0,0,0,0,0,0,0,0,0,0,0,0
0,0,0,0,0,0,0,0,0,0,0,0,0,0,0,0,0,0,0,0
0,0,0,0,0,0,0,0,0,0,0,0,0,0,0,0,0,0,0,0
0,0,0,0,0,0,0,0,0,0,0,0,0,0,0,0,0,0,0,0
0,0,0,0,0,0,0,0,0,0,0,0,0,0,0,0,0,0,0,0
0,0,0,0,0,0,0,0,0,0,0,0,0,0,0,0,0,0,0,0
:endlayer
layer: 56
0,0,0,0,0,0,0,0,0,0,0,0,0,0,0,0,0,0,0,0
0,0,0,0,0,0,0,0,0,0,0,0,0,0,0,0,0,0,0,0
0,0,0,0,0,0,0,0,0,0,0,0,0,0,0,0,0,0,0,0
0,0,0,0,0,0,0,0,0,0,0,0,0,0,0,0,0,0,0,0
0,0,0,0,0,0,0,0,0,0,0,0,0,0,0,0,0,0,0,0
0,0,0,0,0,0,0,0,0,0,0,0,0,0,0,0,0,0,0,0
0,0,0,0,0,0,0,0,0,0,0,0,0,0,0,0,0,0,0,0
0,0,0,0,0,0,0,0,21,24,28,21,0,0,0,0,0,0,0,0
0,0,0,0,0,0,0,0,1,1,1,1,1,0,0,0,0,0,0,0
0,0,0,0,0,0,0,1,1,1,1,1,1,1,0,0,0,0,0,0
0,0,0,0,0,0,1,1,1,1,1,1,1,1,1,0,0,0,0,0
0,0,0,0,0,0,1,1,1,1,1,1,1,1,1,0,0,0,0,0
0,0,0,0,0,1,1,1,1,1,1,1,1,1,1,1,15,0,0,0
0,0,0,0,0,1,1,1,1,1,1,1,1,1,1,1,15,0,0,0
0,0,0,0,0,0,1,1,1,1,1,1,1,1,1,1,24,0,0,0
0,0,0,0,0,0,1,1,1,1,1,1,1,1,1,0,0,15,0,0
0,0,0,0,0,0,1,1,1,1,1,1,1,1,1,0,0,0,0,0
0,0,0,0,0,0,0,1,1,1,1,1,1,1,0,0,0,0,0,0
0,0,0,0,0,0,0,0,0,1,0,15,0,0,0,0,0,0,0,0
0,0,0,0,0,0,0,0,0,0,20,18,0,0,0,0,0,0,0,0
0,0,0,0,0,0,0,0,0,0,0,0,0,0,0,0,0,0,0,0
0,0,0,0,0,0,0,0,0,0,0,0,0,0,0,0,0,0,0,0
0,0,0,0,0,0,0,0,0,0,0,0,0,0,0,0,0,0,0,0
0,0,0,0,0,0,0,0,0,0,0,0,0,0,0,0,0,0,0,0
0,0,0,0,0,0,0,0,0,0,0,0,0,0,0,0,0,0,0,0
0,0,0,0,0,0,0,0,0,0,0,0,0,0,0,0,0,0,0,0
0,0,0,0,0,0,0,0,0,0,0,0,0,0,0,0,0,0,0,0
0,0,0,0,0,0,0,0,0,0,0,0,0,0,0,0,0,0,0,0
:endlayer
layer: 57
0,0,0,0,0,0,0,0,0,0,0,0,0,0,0,0,0,0,0,0
0,0,0,0,0,0,0,0,0,0,0,0,0,0,0,0,0,0,0,0
0,0,0,0,0,0,0,0,0,0,0,0,0,0,0,0,0,0,0,0
0,0,0,0,0,0,0,0,0,0,0,0,0,0,0,0,0,0,0,0
0,0,0,0,0,0,0,0,0,0,0,0,0,0,0,0,0,0,0,0
0,0,0,0,0,0,0,0,0,0,0,0,0,0,0,0,0,0,0,0
0,0,0,0,0,0,0,0,0,0,0,0,0,0,0,0,0,0,0,0
0,0,0,0,0,0,0,0,21,24,28,21,0,0,0,0,0,0,0,0
0,0,0,0,0,0,0,0,1,1,1,1,1,0,0,0,0,0,0,0
0,0,0,0,0,0,0,1,1,1,1,1,1,1,0,0,0,0,0,0
0,0,0,0,0,0,1,1,1,1,1,1,1,1,1,0,0,0,0,0
0,0,0,0,0,1,1,1,1,1,1,1,1,1,1,1,0,0,0,0
0,0,0,0,0,1,1,1,1,1,1,1,1,1,1,1,15,0,0,0
0,0,0,0,0,1,1,1,1,1,1,1,1,1,1,1,15,0,0,0
0,0,0,0,0,0,1,1,1,1,1,1,1,1,1,1,24,0,0,0
0,0,0,0,0,0,1,1,1,1,1,1,1,1,1,1,0,15,0,0
0,0,0,0,0,0,1,1,1,1,1,1,1,1,1,0,0,0,0,0
0,0,0,0,0,0,0,1,1,1,1,1,1,1,0,0,0,0,0,0
0,0,0,0,0,0,0,0,0,1,1,15,0,0,0,0,0,0,0,0
0,0,0,0,0,0,0,0,0,0,20,18,0,0,0,0,0,0,0,0
0,0,0,0,0,0,0,0,0,0,0,0,0,0,0,0,0,0,0,0
0,0,0,0,0,0,0,0,0,0,0,0,0,0,0,0,0,0,0,0
0,0,0,0,0,0,0,0,0,0,0,0,0,0,0,0,0,0,0,0
0,0,0,0,0,0,0,0,0,0,0,0,0,0,0,0,0,0,0,0
0,0,0,0,0,0,0,0,0,0,0,0,0,0,0,0,0,0,0,0
0,0,0,0,0,0,0,0,0,0,0,0,0,0,0,0,0,0,0,0
0,0,0,0,0,0,0,0,0,0,0,0,0,0,0,0,0,0,0,0
0,0,0,0,0,0,0,0,0,0,0,0,0,0,0,0,0,0,0,0
:endlayer
layer: 58
0,0,0,0,0,0,0,0,0,0,0,0,0,0,0,0,0,0,0,0
0,0,0,0,0,0,0,0,0,0,0,0,0,0,0,0,0,0,0,0
0,0,0,0,0,0,0,0,0,0,0,0,0,0,0,0,0,0,0,0
0,0,0,0,0,0,0,0,0,0,0,0,0,0,0,0,0,0,0,0
0,0,0,0,0,0,0,0,0,0,0,0,0,0,0,0,0,0,0,0
0,0,0,0,0,0,0,0,0,0,0,0,0,0,0,0,0,0,0,0
0,0,0,0,0,0,0,0,0,0,0,0,0,0,0,0,0,0,0,0
0,0,0,0,0,0,0,0,21,24,28,21,0,0,0,0,0,0,0,0
0,0,0,0,0,0,0,0,1,1,1,1,1,0,0,0,0,0,0,0
0,0,0,0,0,0,0,1,1,1,1,1,1,1,0,0,0,0,0,0
0,0,0,0,0,0,1,1,1,1,1,1,1,1,1,0,0,0,0,0
0,0,0,0,0,1,1,1,1,1,1,1,1,1,1,1,0,0,0,0
0,0,0,0,0,1,1,1,1,1,1,1,1,1,1,1,15,0,0,0
0,0,0,0,0,1,1,1,1,1,1,1,1,1,1,1,15,0,0,0
0,0,0,0,0,1,1,1,1,1,1,1,1,1,1,1,24,0,0,0
0,0,0,0,0,0,1,1,1,1,1,1,1,1,1,1,0,15,0,0
0,0,0,0,0,0,1,1,1,1,1,1,1,1,1,0,0,0,0,0
0,0,0,0,0,0,1,1,1,1,1,1,1,1,0,0,0,0,0,0
0,0,0,0,0,0,0,0,1,1,1,1,1,0,0,0,0,0,0,0
0,0,0,0,0,0,0,0,0,0,20,18,0,0,0,0,0,0,0,0
0,0,0,0,0,0,0,0,0,0,0,0,0,0,0,0,0,0,0,0
0,0,0,0,0,0,0,0,0,0,0,0,0,0,0,0,0,0,0,0
0,0,0,0,0,0,0,0,0,0,0,0,0,0,0,0,0,0,0,0
0,0,0,0,0,0,0,0,0,0,0,0,0,0,0,0,0,0,0,0
0,0,0,0,0,0,0,0,0,0,0,0,0,0,0,0,0,0,0,0
0,0,0,0,0,0,0,0,0,0,0,0,0,0,0,0,0,0,0,0
0,0,0,0,0,0,0,0,0,0,0,0,0,0,0,0,0,0,0,0
0,0,0,0,0,0,0,0,0,0,0,0,0,0,0,0,0,0,0,0
:endlayer
layer: 59
0,0,0,0,0,0,0,0,0,0,0,0,0,0,0,0,0,0,0,0
0,0,0,0,0,0,0,0,0,0,0,0,0,0,0,0,0,0,0,0
0,0,0,0,0,0,0,0,0,0,0,0,0,0,0,0,0,0,0,0
0,0,0,0,0,0,0,0,0,0,0,0,0,0,0,0,0,0,0,0
0,0,0,0,0,0,0,0,0,0,0,0,0,0,0,0,0,0,0,0
0,0,0,0,0,0,0,0,0,0,0,0,0,0,0,0,0,0,0,0
0,0,0,0,0,0,0,0,0,0,0,0,0,0,0,0,0,0,0,0
0,0,0,0,0,0,0,0,21,24,28,21,0,0,0,0,0,0,0,0
0,0,0,0,0,0,0,0,8,1,1,1,8,0,0,0,0,0,0,0
0,0,0,0,0,0,0,1,1,1,1,1,1,1,0,0,0,0,0,0
0,0,0,0,0,0,1,1,1,1,1,1,1,1,1,0,0,0,0,0
0,0,0,0,0,1,1,1,1,1,1,1,1,1,1,8,0,0,0,0
0,0,0,0,1,1,1,1,1,1,1,1,1,1,1,1,15,0,0,0
0,0,0,0,0,1,1,1,1,1,1,1,1,1,1,1,15,0,0,0
0,0,0,0,0,1,1,1,1,1,1,1,1,1,1,1,24,0,0,0
0,0,0,0,0,1,1,1,1,1,1,1,1,1,1,8,0,15,0,0
0,0,0,0,0,0,1,1,1,1,1,1,1,1,1,0,0,0,0,0
0,0,0,0,0,1,1,1,1,1,1,1,1,1,0,0,0,0,0,0
0,0,0,0,0,0,0,1,1,1,1,1,8,0,0,0,0,0,0,0
0,0,0,0,0,0,0,0,0,0,20,18,0,0,0,0,0,0,0,0
0,0,0,0,0,0,0,0,0,0,0,0,0,0,0,0,0,0,0,0
0,0,0,0,0,0,0,0,0,0,0,0,0,0,0,0,0,0,0,0
0,0,0,0,0,0,0,0,0,0,0,0,0,0,0,0,0,0,0,0
0,0,0,0,0,0,0,0,0,0,0,0,0,0,0,0,0,0,0,0
0,0,0,0,0,0,0,0,0,0,0,0,0,0,0,0,0,0,0,0
0,0,0,0,0,0,0,0,0,0,0,0,0,0,0,0,0,0,0,0
0,0,0,0,0,0,0,0,0,0,0,0,0,0,0,0,0,0,0,0
0,0,0,0,0,0,0,0,0,0,0,0,0,0,0,0,0,0,0,0
:endlayer
layer: 60
0,0,0,0,0,0,0,0,0,0,0,0,0,0,0,0,0,0,0,0
0,0,0,0,0,0,0,0,0,0,0,0,0,0,0,0,0,0,0,0
0,0,0,0,0,0,0,0,0,0,0,0,0,0,0,0,0,0,0,0
0,0,0,0,0,0,0,0,0,0,0,0,0,0,0,0,0,0,0,0
0,0,0,0,0,0,0,0,0,0,0,0,0,0,0,0,0,0,0,0
0,0,0,0,0,0,0,0,0,0,0,0,0,0,0,0,0,0,0,0
0,0,0,0,0,0,0,0,0,0,0,0,0,0,0,0,0,0,0,0
0,0,0,0,0,0,0,0,0,24,28,21,0,0,0,0,0,0,0,0
0,0,0,0,0,0,0,0,0,8,8,8,0,0,0,0,0,0,0,0
0,0,0,0,0,0,0,1,1,1,1,1,1,8,0,0,0,0,0,0
0,0,0,0,0,1,1,1,1,1,1,1,1,1,8,0,0,0,0,0
0,0,0,0,1,1,1,1,1,1,1,1,1,1,1,9,0,0,0,0
0,0,0,0,1,1,1,1,1,1,1,1,1,1,1,8,15,0,0,0
0,0,0,0,0,1,1,1,1,1,1,1,1,1,1,8,15,0,0,0
0,0,0,0,0,1,1,1,1,1,1,1,1,1,1,8,24,0,0,0
0,0,0,0,0,1,1,1,1,1,1,1,1,1,1,9,0,15,0,0
0,0,0,0,0,1,1,1,1,1,1,1,1,1,8,0,0,0,0,0
0,0,0,0,0,1,1,1,1,1,1,1,1,8,0,0,0,0,0,0
0,0,0,0,0,0,1,1,1,1,1,1,9,0,0,0,0,0,0,0
0,0,0,0,0,0,0,0,0,0,20,18,0,0,0,0,0,0,0,0
0,0,0,0,0,0,0,0,0,0,0,0,0,0,0,0,0,0,0,0
0,0,0,0,0,0,0,0,0,0,0,0,0,0,0,0,0,0,0,0
0,0,0,0,0,0,0,0,0,0,0,0,0,0,0,0,0,0,0,0
0,0,0,0,0,0,0,0,0,0,0,0,0,0,0,0,0,0,0,0
0,0,0,0,0,0,0,0,0,0,0,0,0,0,0,0,0,0,0,0
0,0,0,0,0,0,0,0,0,0,0,0,0,0,0,0,0,0,0,0
0,0,0,0,0,0,0,0,0,0,0,0,0,0,0,0,0,0,0,0
0,0,0,0,0,0,0,0,0,0,0,0,0,0,0,0,0,0,0,0
:endlayer
layer: 61
0,0,0,0,0,0,0,0,0,0,0,0,0,0,0,0,0,0,0,0
0,0,0,0,0,0,0,0,0,0,0,0,0,0,0,0,0,0,0,0
0,0,0,0,0,0,0,0,0,0,0,0,0,0,0,0,0,0,0,0
0,0,0,0,0,0,0,0,0,0,0,0,0,0,0,0,0,0,0,0
0,0,0,0,0,0,0,0,0,0,0,0,0,0,0,0,0,0,0,0
0,0,0,0,0,0,0,0,0,0,0,0,0,0,0,0,0,0,0,0
0,0,0,0,0,0,0,0,0,0,0,0,0,0,0,0,0,0,0,0
0,0,0,0,0,0,0,0,0,24,28,21,0,0,0,0,0,0,0,0
0,0,0,0,0,0,0,0,0,0,0,0,0,0,0,0,0,0,0,0
0,0,0,0,0,0,1,1,1,1,1,8,8,14,0,0,0,0,0,0
0,0,0,0,0,1,1,1,1,1,1,1,1,8,0,0,0,0,0,0
0,0,0,0,1,1,1,1,1,1,1,1,1,1,8,0,0,0,0,0
0,0,0,1,1,1,1,1,1,1,1,1,1,1,8,9,0,0,0,0
0,0,0,0,1,1,1,1,1,1,1,1,1,1,8,9,15,0,0,0
0,0,0,0,1,1,1,1,1,1,1,1,1,1,8,9,24,0,0,0
0,0,0,0,0,1,1,1,1,1,1,1,1,1,8,0,0,15,0,0
0,0,0,0,1,1,1,1,1,1,1,1,1,1,9,0,0,0,0,0
0,0,0,0,0,1,1,1,1,1,1,1,1,9,0,0,0,0,0,0
0,0,0,0,0,1,1,1,1,1,1,1,16,0,0,0,0,0,0,0
0,0,0,0,0,0,0,0,0,1,20,18,0,0,0,0,0,0,0,0
0,0,0,0,0,0,0,0,0,0,0,0,0,0,0,0,0,0,0,0
0,0,0,0,0,0,0,0,0,0,0,0,0,0,0,0,0,0,0,0
0,0,0,0,0,0,0,0,0,0,0,0,0,0,0,0,0,0,0,0
0,0,0,0,0,0,0,0,0,0,0,0,0,0,0,0,0,0,0,0
0,0,0,0,0,0,0,0,0,0,0,0,0,0,0,0,0,0,0,0
0,0,0,0,0,0,0,0,0,0,0,0,0,0,0,0,0,0,0,0
0,0,0,0,0,0,0,0,0,0,0,0,0,0,0,0,0,0,0,0
0,0,0,0,0,0,0,0,0,0,0,0,0,0,0,0,0,0,0,0
:endlayer
layer: 62
0,0,0,0,0,0,0,0,0,0,0,0,0,0,0,0,0,0,0,0
0,0,0,0,0,0,0,0,0,0,0,0,0,0,0,0,0,0,0,0
0,0,0,0,0,0,0,0,0,0,0,0,0,0,0,0,0,0,0,0
0,0,0,0,0,0,0,0,0,0,0,0,0,0,0,0,0,0,0,0
0,0,0,0,0,0,0,0,0,0,0,0,0,0,0,0,0,0,0,0
0,0,0,0,0,0,0,0,0,0,0,0,0,0,0,0,0,0,0,0
0,0,0,0,0,0,0,0,0,0,0,0,0,0,0,0,0,0,0,0
0,0,0,0,0,0,0,0,0,24,28,21,0,0,0,0,0,0,0,0
0,0,0,0,0,0,0,0,0,0,0,0,0,0,0,0,0,0,0,0
0,0,0,0,0,0,1,1,1,1,1,0,0,0,0,0,0,0,0,0
0,0,0,0,0,1,1,1,1,1,1,1,8,0,0,0,0,0,0,0
0,0,0,0,1,1,1,1,1,1,1,1,1,8,9,0,0,0,0,0
0,0,0,1,1,1,1,1,1,1,1,1,1,1,9,0,0,0,0,0
0,0,0,1,1,1,1,1,1,1,1,1,1,1,9,0,15,0,0,0
0,0,0,0,1,1,1,1,1,1,1,1,1,1,9,0,24,0,0,0
0,0,0,0,1,1,1,1,1,1,1,1,1,1,9,0,0,15,0,0
0,0,0,1,1,1,1,1,1,1,1,1,1,1,0,0,0,0,0,0
0,0,0,0,1,1,1,1,1,1,1,1,1,0,0,0,0,0,0,0
0,0,0,0,0,1,1,1,1,1,1,1,16,0,0,0,0,0,0,0
0,0,0,0,0,0,1,1,0,1,1,18,0,0,0,0,0,0,0,0
0,0,0,0,0,0,0,0,0,0,0,0,0,0,0,0,0,0,0,0
0,0,0,0,0,0,0,0,0,0,0,0,0,0,0,0,0,0,0,0
0,0,0,0,0,0,0,0,0,0,0,0,0,0,0,0,0,0,0,0
0,0,0,0,0,0,0,0,0,0,0,0,0,0,0,0,0,0,0,0
0,0,0,0,0,0,0,0,0,0,0,0,0,0,0,0,0,0,0,0
0,0,0,0,0,0,0,0,0,0,0,0,0,0,0,0,0,0,0,0
0,0,0,0,0,0,0,0,0,0,0,0,0,0,0,0,0,0,0,0
0,0,0,0,0,0,0,0,0,0,0,0,0,0,0,0,0,0,0,0
:endlayer
layer: 63
0,0,0,0,0,0,0,0,0,0,0,0,0,0,0,0,0,0,0,0
0,0,0,0,0,0,0,0,0,0,0,0,0,0,0,0,0,0,0,0
0,0,0,0,0,0,0,0,0,0,0,0,0,0,0,0,0,0,0,0
0,0,0,0,0,0,0,0,0,0,0,0,0,0,0,0,0,0,0,0
0,0,0,0,0,0,0,0,0,0,0,0,0,0,0,0,0,0,0,0
0,0,0,0,0,0,0,0,0,0,0,0,0,0,0,0,0,0,0,0
0,0,0,0,0,0,0,0,0,0,0,0,0,0,0,0,0,0,0,0
0,0,0,0,0,0,0,0,0,24,28,21,0,0,0,0,0,0,0,0
0,0,0,0,0,0,0,0,0,0,0,0,0,0,0,0,0,0,0,0
0,0,0,0,0,0,1,1,1,1,1,0,0,0,0,0,0,0,0,0
0,0,0,0,0,1,1,1,1,1,1,1,0,0,0,0,0,0,0,0
0,0,0,0,1,1,1,1,1,1,1,1,1,0,0,0,0,0,0,0
0,0,0,8,1,1,1,1,1,1,1,1,1,1,0,0,0,0,0,0
0,0,0,1,1,1,1,1,1,1,1,1,1,1,0,0,15,0,0,0
0,0,0,1,1,1,1,1,1,1,1,1,1,1,0,0,24,0,0,0
0,0,0,1,1,1,1,1,1,1,1,1,1,1,0,0,0,15,0,0
0,0,0,8,1,1,1,1,1,1,1,1,1,1,0,0,0,0,0,0
0,0,0,0,1,1,1,1,1,1,1,1,1,0,0,0,0,0,0,0
0,0,0,0,0,1,1,1,1,1,1,1,16,0,0,0,0,0,0,0
0,0,0,0,0,0,8,1,1,1,8,18,0,0,0,0,0,0,0,0
0,0,0,0,0,0,0,0,0,0,0,0,0,0,0,0,0,0,0,0
0,0,0,0,0,0,0,0,0,0,0,0,0,0,0,0,0,0,0,0
0,0,0,0,0,0,0,0,0,0,0,0,0,0,0,0,0,0,0,0
0,0,0,0,0,0,0,0,0,0,0,0,0,0,0,0,0,0,0,0
0,0,0,0,0,0,0,0,0,0,0,0,0,0,0,0,0,0,0,0
0,0,0,0,0,0,0,0,0,0,0,0,0,0,0,0,0,0,0,0
0,0,0,0,0,0,0,0,0,0,0,0,0,0,0,0,0,0,0,0
0,0,0,0,0,0,0,0,0,0,0,0,0,0,0,0,0,0,0,0
:endlayer
layer: 64
0,0,0,0,0,0,0,0,0,0,0,0,0,0,0,0,0,0,0,0
0,0,0,0,0,0,0,0,0,0,0,0,0,0,0,0,0,0,0,0
0,0,0,0,0,0,0,0,0,0,0,0,0,0,0,0,0,0,0,0
0,0,0,0,0,0,0,0,0,0,0,0,0,0,0,0,0,0,0,0
0,0,0,0,0,0,0,0,0,0,0,0,0,0,0,0,0,0,0,0
0,0,0,0,0,0,0,0,0,0,0,0,0,0,0,0,0,0,0,0
0,0,0,0,0,0,0,0,0,0,0,0,0,0,0,0,0,0,0,0
0,0,0,0,0,0,0,0,0,24,28,21,0,0,0,0,0,0,0,0
0,0,0,0,0,0,0,0,0,0,0,0,0,0,0,0,0,0,0,0
0,0,0,0,0,0,8,1,1,1,1,1,1,0,0,0,0,0,0,0
0,0,0,0,0,8,1,1,1,1,1,1,1,1,0,0,0,0,0,0
0,0,0,0,8,1,1,1,1,1,1,1,1,1,1,0,0,0,0,0
0,0,0,9,1,1,1,1,1,1,1,1,1,1,1,0,0,0,0,0
0,0,0,8,1,1,1,1,1,1,1,1,1,1,1,0,15,0,0,0
0,0,0,8,1,1,1,1,1,1,1,1,1,1,1,0,24,0,0,0
0,0,0,8,1,1,1,1,1,1,1,1,1,1,1,0,0,15,0,0
0,0,0,9,1,1,1,1,1,1,1,1,1,1,0,0,0,0,0,0
0,0,0,0,8,1,1,1,1,1,1,1,1,0,0,0,0,0,0,0
0,0,0,0,0,8,1,1,1,1,1,1,16,0,0,0,0,0,0,0
0,0,0,0,0,0,9,8,8,8,20,18,0,0,0,0,0,0,0,0
0,0,0,0,0,0,0,0,0,0,0,0,0,0,0,0,0,0,0,0
0,0,0,0,0,0,0,0,0,0,0,0,0,0,0,0,0,0,0,0
0,0,0,0,0,0,0,0,0,0,0,0,0,0,0,0,0,0,0,0
0,0,0,0,0,0,0,0,0,0,0,0,0,0,0,0,0,0,0,0
0,0,0,0,0,0,0,0,0,0,0,0,0,0,0,0,0,0,0,0
0,0,0,0,0,0,0,0,0,0,0,0,0,0,0,0,0,0,0,0
0,0,0,0,0,0,0,0,0,0,0,0,0,0,0,0,0,0,0,0
0,0,0,0,0,0,0,0,0,0,0,0,0,0,0,0,0,0,0,0
:endlayer
layer: 65
0,0,0,0,0,0,0,0,0,0,0,0,0,0,0,0,0,0,0,0
0,0,0,0,0,0,0,0,0,0,0,0,0,0,0,0,0,0,0,0
0,0,0,0,0,0,0,0,0,0,0,0,0,0,0,0,0,0,0,0
0,0,0,0,0,0,0,0,0,0,0,0,0,0,0,0,0,0,0,0
0,0,0,0,0,0,0,0,0,0,0,0,0,0,0,0,0,0,0,0
0,0,0,0,0,0,0,0,0,0,0,0,0,0,0,0,0,0,0,0
0,0,0,0,0,0,0,0,0,0,0,0,0,0,0,0,0,0,0,0
0,0,0,0,0,0,0,0,0,24,28,21,0,0,0,0,0,0,0,0
0,0,0,0,0,0,0,0,0,1,1,1,0,0,0,0,0,0,0,0
0,0,0,0,0,0,13,1,1,1,1,1,1,1,0,0,0,0,0,0
0,0,0,0,0,9,1,1,1,1,1,1,1,1,1,0,0,0,0,0
0,0,0,0,9,1,1,1,1,1,1,1,1,1,1,0,0,0,0,0
0,0,0,0,8,1,1,1,1,1,1,1,1,1,1,1,0,0,0,0
0,0,0,9,8,1,1,1,1,1,1,1,1,1,1,1,15,0,0,0
0,0,0,9,8,1,1,1,1,1,1,1,1,1,1,1,24,0,0,0
0,0,0,9,8,1,1,1,1,1,1,1,1,1,1,0,0,15,0,0
0,0,0,0,8,1,1,1,1,1,1,1,1,1,1,0,0,0,0,0
0,0,0,0,9,8,1,1,1,1,1,1,1,1,0,0,0,0,0,0
0,0,0,0,0,0,8,8,1,1,1,1,20,0,0,0,0,0,0,0
0,0,0,0,0,0,0,20,9,13,20,18,0,0,0,0,0,0,0,0
0,0,0,0,0,0,0,0,0,0,0,0,0,0,0,0,0,0,0,0
0,0,0,0,0,0,0,0,0,0,0,0,0,0,0,0,0,0,0,0
0,0,0,0,0,0,0,0,0,0,0,0,0,0,0,0,0,0,0,0
0,0,0,0,0,0,0,0,0,0,0,0,0,0,0,0,0,0,0,0
0,0,0,0,0,0,0,0,0,0,0,0,0,0,0,0,0,0,0,0
0,0,0,0,0,0,0,0,0,0,0,0,0,0,0,0,0,0,0,0
0,0,0,0,0,0,0,0,0,0,0,0,0,0,0,0,0,0,0,0
0,0,0,0,0,0,0,0,0,0,0,0,0,0,0,0,0,0,0,0
:endlayer
layer: 66
0,0,0,0,0,0,0,0,0,0,0,0,0,0,0,0,0,0,0,0
0,0,0,0,0,0,0,0,0,0,0,0,0,0,0,0,0,0,0,0
0,0,0,0,0,0,0,0,0,0,0,0,0,0,0,0,0,0,0,0
0,0,0,0,0,0,0,0,0,0,0,0,0,0,0,0,0,0,0,0
0,0,0,0,0,0,0,0,0,0,0,0,0,0,0,0,0,0,0,0
0,0,0,0,0,0,0,0,0,0,0,0,0,0,0,0,0,0,0,0
0,0,0,0,0,0,0,0,0,0,0,0,0,0,0,0,0,0,0,0
0,0,0,0,0,0,0,0,0,24,28,21,0,0,0,0,0,0,0,0
0,0,0,0,0,0,0,0,1,1,1,1,1,0,0,0,0,0,0,0
0,0,0,0,0,0,0,1,1,1,1,1,1,1,0,0,0,0,0,0
0,0,0,0,0,21,1,1,1,1,1,1,1,1,1,0,0,0,0,0
0,0,0,0,19,1,1,1,1,1,1,1,1,1,1,1,0,0,0,0
0,0,0,0,18,1,1,1,1,1,1,1,1,1,1,1,0,0,0,0
0,0,0,0,29,1,1,1,1,1,1,1,1,1,1,1,15,0,0,0
0,0,0,0,9,1,1,1,1,1,1,1,1,1,1,1,24,0,0,0
0,0,0,0,9,1,1,1,1,1,1,1,1,1,1,1,0,15,0,0
0,0,0,0,13,8,1,1,1,1,1,1,1,1,1,0,0,0,0,0
0,0,0,0,0,13,1,1,1,1,1,1,1,1,0,0,0,0,0,0
0,0,0,0,0,0,9,9,1,1,1,1,1,0,0,0,0,0,0,0
0,0,0,0,0,0,0,20,20,20,20,18,0,0,0,0,0,0,0,0
0,0,0,0,0,0,0,0,0,0,0,0,0,0,0,0,0,0,0,0
0,0,0,0,0,0,0,0,0,0,0,0,0,0,0,0,0,0,0,0
0,0,0,0,0,0,0,0,0,0,0,0,0,0,0,0,0,0,0,0
0,0,0,0,0,0,0,0,0,0,0,0,0,0,0,0,0,0,0,0
0,0,0,0,0,0,0,0,0,0,0,0,0,0,0,0,0,0,0,0
0,0,0,0,0,0,0,0,0,0,0,0,0,0,0,0,0,0,0,0
0,0,0,0,0,0,0,0,0,0,0,0,0,0,0,0,0,0,0,0
0,0,0,0,0,0,0,0,0,0,0,0,0,0,0,0,0,0,0,0
:endlayer
layer: 67
0,0,0,0,0,0,0,0,0,0,0,0,0,0,0,0,0,0,0,0
0,0,0,0,0,0,0,0,0,0,0,0,0,0,0,0,0,0,0,0
0,0,0,0,0,0,0,0,0,0,0,0,0,0,0,0,0,0,0,0
0,0,0,0,0,0,0,0,0,0,0,0,0,0,0,0,0,0,0,0
0,0,0,0,0,0,0,0,0,0,0,0,0,0,0,0,0,0,0,0
0,0,0,0,0,0,0,0,0,0,0,0,0,0,0,0,0,0,0,0
0,0,0,0,0,0,0,0,0,0,0,0,0,0,0,0,0,0,0,0
0,0,0,0,0,0,0,0,0,24,28,21,0,0,0,0,0,0,0,0
0,0,0,0,0,0,0,0,1,1,1,1,1,0,0,0,0,0,0,0
0,0,0,0,0,0,1,1,1,1,1,1,1,1,0,0,0,0,0,0
0,0,0,0,0,21,1,1,1,1,1,1,1,1,1,0,0,0,0,0
0,0,0,0,19,1,1,1,1,1,1,1,1,1,1,1,0,0,0,0
0,0,0,0,18,1,1,1,1,1,1,1,1,1,1,1,0,0,0,0
0,0,0,0,29,1,1,1,1,1,1,1,1,1,1,1,15,0,0,0
0,0,0,0,0,1,1,1,1,1,1,1,1,1,1,1,24,0,0,0
0,0,0,0,0,1,1,1,1,1,1,1,1,1,1,1,0,15,0,0
0,0,0,0,0,9,1,1,1,1,1,1,1,1,1,0,0,0,0,0
0,0,0,0,0,0,1,1,1,1,1,1,1,1,1,0,0,0,0,0
0,0,0,0,0,0,0,0,1,1,1,1,1,0,0,0,0,0,0,0
0,0,0,0,0,0,0,20,20,20,20,18,0,0,0,0,0,0,0,0
0,0,0,0,0,0,0,0,0,0,0,0,0,0,0,0,0,0,0,0
0,0,0,0,0,0,0,0,0,0,0,0,0,0,0,0,0,0,0,0
0,0,0,0,0,0,0,0,0,0,0,0,0,0,0,0,0,0,0,0
0,0,0,0,0,0,0,0,0,0,0,0,0,0,0,0,0,0,0,0
0,0,0,0,0,0,0,0,0,0,0,0,0,0,0,0,0,0,0,0
0,0,0,0,0,0,0,0,0,0,0,0,0,0,0,0,0,0,0,0
0,0,0,0,0,0,0,0,0,0,0,0,0,0,0,0,0,0,0,0
0,0,0,0,0,0,0,0,0,0,0,0,0,0,0,0,0,0,0,0
:endlayer
layer: 68
0,0,0,0,0,0,0,0,0,0,0,0,0,0,0,0,0,0,0,0
0,0,0,0,0,0,0,0,0,0,0,0,0,0,0,0,0,0,0,0
0,0,0,0,0,0,0,0,0,0,0,0,0,0,0,0,0,0,0,0
0,0,0,0,0,0,0,0,0,0,0,0,0,0,0,0,0,0,0,0
0,0,0,0,0,0,0,0,0,0,0,0,0,0,0,0,0,0,0,0
0,0,0,0,0,0,0,0,0,0,0,0,0,0,0,0,0,0,0,0
0,0,0,0,0,0,0,0,0,0,0,0,0,0,0,0,0,0,0,0
0,0,0,0,0,0,0,0,0,24,28,21,0,0,0,0,0,0,0,0
0,0,0,0,0,1,1,1,1,1,1,1,1,0,0,0,0,0,0,0
0,0,0,0,0,1,1,1,1,1,1,1,1,1,0,0,0,0,0,0
0,0,0,0,0,1,1,1,1,1,1,1,1,1,1,0,0,0,0,0
0,0,0,0,19,1,1,1,1,1,1,1,1,1,1,8,0,0,0,0
0,0,0,0,18,1,1,1,1,1,1,1,1,1,1,1,0,0,0,0
0,0,0,0,29,1,1,1,1,1,1,1,1,1,1,1,15,0,0,0
0,0,0,0,0,1,1,1,1,1,1,1,1,1,1,1,24,0,0,0
0,0,0,0,0,1,1,1,1,1,1,1,1,1,1,1,0,15,0,0
0,0,0,0,0,1,1,1,1,1,1,1,1,1,1,1,0,0,0,0
0,0,0,0,0,1,1,1,1,1,1,1,1,1,1,1,0,0,0,0
0,0,0,0,0,0,1,1,1,1,1,1,1,1,1,0,0,0,0,0
0,0,0,0,0,0,0,20,20,20,20,18,0,0,0,0,0,0,0,0
0,0,0,0,0,0,0,0,0,0,0,0,0,0,0,0,0,0,0,0
0,0,0,0,0,0,0,0,0,0,0,0,0,0,0,0,0,0,0,0
0,0,0,0,0,0,0,0,0,0,0,0,0,0,0,0,0,0,0,0
0,0,0,0,0,0,0,0,0,0,0,0,0,0,0,0,0,0,0,0
0,0,0,0,0,0,0,0,0,0,0,0,0,0,0,0,0,0,0,0
0,0,0,0,0,0,0,0,0,0,0,0,0,0,0,0,0,0,0,0
0,0,0,0,0,0,0,0,0,0,0,0,0,0,0,0,0,0,0,0
0,0,0,0,0,0,0,0,0,0,0,0,0,0,0,0,0,0,0,0
:endlayer
layer: 69
0,0,0,0,0,0,0,0,0,0,0,0,0,0,0,0,0,0,0,0
0,0,0,0,0,0,0,0,0,0,0,0,0,0,0,0,0,0,0,0
0,0,0,0,0,0,0,0,0,0,0,0,0,0,0,0,0,0,0,0
0,0,0,0,0,0,0,0,0,0,0,0,0,0,0,0,0,0,0,0
0,0,0,0,0,0,0,0,0,0,0,0,0,0,0,0,0,0,0,0
0,0,0,0,0,0,0,0,0,0,0,0,0,0,0,0,0,0,0,0
0,0,0,0,0,0,0,0,0,0,0,0,0,0,0,0,0,0,0,0
0,0,0,0,0,0,1,1,1,24,28,21,0,0,0,0,0,0,0,0
0,0,0,0,0,1,1,1,1,1,1,1,1,1,0,0,0,0,0,0
0,0,0,0,0,1,1,1,1,1,1,1,1,1,1,0,0,0,0,0
0,0,0,0,0,1,1,1,1,1,1,1,1,1,1,0,0,0,0,0
0,0,0,0,1,1,1,1,1,1,1,1,1,1,1,9,0,0,0,0
0,0,0,0,18,1,1,1,1,1,1,1,1,1,1,8,0,0,0,0
0,0,0,0,19,30,1,1,1,1,1,1,1,1,1,8,15,0,0,0
0,0,0,0,0,1,1,1,1,1,1,1,1,1,1,1,24,0,0,0
0,0,0,0,1,1,1,1,1,1,1,1,1,1,1,1,1,15,0,0
0,0,0,0,0,1,1,1,1,1,1,1,1,1,1,1,0,0,0,0
0,0,0,0,1,1,1,1,1,1,1,1,1,1,1,1,0,0,0,0
0,0,0,0,0,1,1,1,1,1,8,1,1,1,1,0,0,0,0,0
0,0,0,0,0,0,1,1,8,20,20,19,8,1,0,0,0,0,0,0
0,0,0,0,0,0,0,0,0,0,0,0,0,0,0,0,0,0,0,0
0,0,0,0,0,0,0,0,0,0,0,0,0,0,0,0,0,0,0,0
0,0,0,0,0,0,0,0,0,0,0,0,0,0,0,0,0,0,0,0
0,0,0,0,0,0,0,0,0,0,0,0,0,0,0,0,0,0,0,0
0,0,0,0,0,0,0,0,0,0,0,0,0,0,0,0,0,0,0,0
0,0,0,0,0,0,0,0,0,0,0,0,0,0,0,0,0,0,0,0
0,0,0,0,0,0,0,0,0,0,0,0,0,0,0,0,0,0,0,0
0,0,0,0,0,0,0,0,0,0,0,0,0,0,0,0,0,0,0,0
:endlayer
layer: 70
0,0,0,0,0,0,0,0,0,0,0,0,0,0,0,0,0,0,0,0
0,0,0,0,0,0,0,0,0,0,0,0,0,0,0,0,0,0,0,0
0,0,0,0,0,0,0,0,0,0,0,0,0,0,0,0,0,0,0,0
0,0,0,0,0,0,0,0,0,0,0,0,0,0,0,0,0,0,0,0
0,0,0,0,0,0,0,0,0,0,0,0,0,0,0,0,0,0,0,0
0,0,0,0,0,0,0,0,0,0,0,0,0,0,0,0,0,0,0,0
0,0,0,0,0,0,0,0,0,0,0,0,0,0,0,0,0,0,0,0
0,0,0,0,0,0,1,1,1,24,28,1,1,0,0,0,0,0,0,0
0,0,0,0,0,1,1,1,1,1,1,1,1,1,1,0,0,0,0,0
0,0,0,0,1,1,1,1,1,1,1,1,1,1,1,1,0,0,0,0
0,0,0,0,1,1,1,1,1,1,1,1,1,1,1,0,0,0,0,0
0,0,0,0,1,1,1,1,1,1,1,1,1,1,1,0,0,0,0,0
0,0,0,0,18,1,1,1,1,1,1,1,1,1,1,9,0,0,0,0
0,0,0,0,19,31,30,1,1,1,1,1,1,1,1,13,0,0,0,0
0,0,0,0,0,1,1,1,1,1,1,1,1,1,1,1,15,0,0,0
0,0,0,0,1,1,1,1,1,1,1,1,1,1,1,1,1,15,0,0
0,0,0,0,1,1,1,1,1,1,1,1,1,1,1,1,1,0,0,0
0,0,0,0,8,1,1,1,1,1,1,1,1,1,1,1,1,0,0,0
0,0,0,0,0,8,1,1,1,1,32,32,1,1,1,1,0,0,0,0
0,0,0,0,0,0,8,8,16,20,20,0,9,0,1,0,0,0,0,0
0,0,0,0,0,0,0,0,0,0,0,0,0,0,0,0,0,0,0,0
0,0,0,0,0,0,0,0,0,0,0,0,0,0,0,0,0,0,0,0
0,0,0,0,0,0,0,0,0,0,0,0,0,0,0,0,0,0,0,0
0,0,0,0,0,0,0,0,0,0,0,0,0,0,0,0,0,0,0,0
0,0,0,0,0,0,0,0,0,0,0,0,0,0,0,0,0,0,0,0
0,0,0,0,0,0,0,0,0,0,0,0,0,0,0,0,0,0,0,0
0,0,0,0,0,0,0,0,0,0,0,0,0,0,0,0,0,0,0,0
0,0,0,0,0,0,0,0,0,0,0,0,0,0,0,0,0,0,0,0
:endlayer
layer: 71
0,0,0,0,0,0,0,0,0,0,0,0,0,0,0,0,0,0,0,0
0,0,0,0,0,0,0,0,0,0,0,0,0,0,0,0,0,0,0,0
0,0,0,0,0,0,0,0,0,0,0,0,0,0,0,0,0,0,0,0
0,0,0,0,0,0,0,0,0,0,0,0,0,0,0,0,0,0,0,0
0,0,0,0,0,0,0,0,0,0,0,0,0,0,0,0,0,0,0,0
0,0,0,0,0,0,0,0,0,0,0,0,0,0,0,0,0,0,0,0
0,0,0,0,0,0,0,0,0,0,0,0,0,0,0,0,0,0,0,0
0,0,0,0,0,0,8,33,4,33,24,8,8,0,0,0,0,0,0,0
0,0,0,0,0,1,1,1,1,1,1,1,1,1,1,0,0,0,0,0
0,0,0,0,8,1,1,34,1,1,1,1,1,1,1,8,0,0,0,0
0,0,0,0,8,1,1,1,1,1,1,1,1,34,1,1,0,0,0,0
0,0,0,0,8,1,1,1,1,1,1,1,1,1,1,1,0,0,0,0
0,0,0,0,18,4,1,1,1,1,1,1,1,1,1,22,0,0,0,0
0,0,0,0,19,31,24,35,1,1,1,1,1,1,1,24,0,0,0,0
0,0,0,0,0,4,1,1,1,1,1,1,1,1,1,1,15,0,0,0
0,0,0,0,8,1,1,1,1,1,1,1,1,1,1,1,8,15,0,0
0,0,0,0,8,1,1,1,1,1,1,1,1,1,1,1,8,0,0,0
0,0,0,0,9,1,1,1,1,1,1,1,1,1,1,1,8,0,0,0
0,0,0,0,0,0,1,1,1,32,34,1,1,1,4,1,0,0,0,0
0,0,0,0,0,0,9,13,20,20,32,32,0,32,0,0,0,0,0,0
0,0,0,0,0,0,0,0,0,0,0,0,0,0,0,0,0,0,0,0
0,0,0,0,0,0,0,0,0,0,0,0,0,0,0,0,0,0,0,0
0,0,0,0,0,0,0,0,0,0,0,0,0,0,0,0,0,0,0,0
0,0,0,0,0,0,0,0,0,0,0,0,0,0,0,0,0,0,0,0
0,0,0,0,0,0,0,0,0,0,0,0,0,0,0,0,0,0,0,0
0,0,0,0,0,0,0,0,0,0,0,0,0,0,0,0,0,0,0,0
0,0,0,0,0,0,0,0,0,0,0,0,0,0,0,0,0,0,0,0
0,0,0,0,0,0,0,0,0,0,0,0,0,0,0,0,0,0,0,0
:endlayer
layer: 72
0,0,0,0,0,0,0,0,0,0,0,0,0,0,0,0,0,0,0,0
0,0,0,0,0,0,0,0,0,0,0,0,0,0,0,0,0,0,0,0
0,0,0,0,0,0,0,0,0,0,0,0,0,0,0,0,0,0,0,0
0,0,0,0,0,0,0,0,0,0,0,0,0,0,0,0,0,0,0,0
0,0,0,0,0,0,0,0,0,0,0,0,0,0,0,0,0,0,0,0
0,0,0,0,0,0,0,0,0,0,0,0,0,0,0,0,0,0,0,0
0,0,0,0,0,0,0,33,0,33,0,0,0,0,0,0,0,0,0,0
0,0,0,0,0,0,9,36,8,36,24,21,31,0,0,0,0,0,0,0
0,0,0,0,0,8,4,8,8,8,36,1,1,8,8,0,0,0,0,0
0,0,0,0,9,8,1,0,1,37,38,38,30,1,8,0,0,0,0,0
0,0,0,0,9,8,1,1,36,38,35,35,30,0,1,8,0,0,0,0
0,0,0,0,9,8,8,35,35,35,35,35,30,1,1,8,0,0,0,0
0,0,0,0,19,4,8,0,1,39,35,35,30,1,1,22,0,0,0,0
0,0,0,0,19,31,24,0,1,37,35,35,30,1,4,24,0,0,0,0
0,0,0,0,0,4,8,1,1,37,35,35,30,1,8,4,15,0,0,0
0,0,0,0,13,4,8,1,1,37,35,35,30,1,36,4,9,0,0,0
0,0,0,0,9,4,1,1,1,37,39,39,39,1,1,4,0,0,0,0
0,0,0,0,0,4,8,1,1,8,36,8,1,1,1,4,9,0,0,0
0,0,0,0,0,0,4,8,8,8,0,8,8,8,36,4,0,0,0,0
0,0,0,0,0,0,0,20,20,32,1,36,0,36,40,0,0,0,0,0
0,0,0,0,0,0,0,0,0,41,32,32,0,0,0,0,0,0,0,0
0,0,0,0,0,0,0,0,0,0,0,0,0,0,0,0,0,0,0,0
0,0,0,0,0,0,0,0,0,0,0,0,0,0,0,0,0,0,0,0
0,0,0,0,0,0,0,0,0,0,0,0,0,0,0,0,0,0,0,0
0,0,0,0,0,0,0,0,0,0,0,0,0,0,0,0,0,0,0,0
0,0,0,0,0,0,0,0,0,0,0,0,0,0,0,0,0,0,0,0
0,0,0,0,0,0,0,0,0,0,0,0,0,0,0,0,0,0,0,0
0,0,0,0,0,0,0,0,0,0,0,0,0,0,0,0,0,0,0,0
:endlayer
layer: 73
0,0,0,0,0,0,0,0,0,0,0,0,0,0,0,0,0,0,0,0
0,0,0,0,0,0,0,0,0,0,0,0,0,0,0,0,0,0,0,0
0,0,0,0,0,0,0,0,0,0,0,0,0,0,0,0,0,0,0,0
0,0,0,0,0,0,0,0,0,0,0,0,0,0,0,0,0,0,0,0
0,0,0,0,0,0,0,0,0,0,0,0,0,0,0,0,0,0,0,0
0,0,0,0,0,0,0,33,0,33,0,0,0,0,0,0,0,0,0,0
0,0,0,0,0,0,0,36,8,36,0,0,0,0,0,0,0,0,0,0
0,0,0,0,0,0,8,38,9,38,8,21,31,0,0,0,0,0,0,0
0,0,0,0,0,0,8,9,9,9,0,8,8,15,0,0,0,0,0,0
0,0,0,0,0,9,42,0,0,0,43,0,0,30,40,0,0,0,0,0
0,0,0,0,0,13,8,36,0,0,44,45,0,0,8,9,0,0,0,0
0,0,0,0,41,35,0,0,0,0,0,46,0,30,40,9,0,0,0,0
0,0,0,0,19,8,13,0,39,0,0,47,0,0,8,24,0,0,0,0
0,0,0,0,19,8,15,0,30,0,0,0,0,30,36,40,0,0,0,0
0,0,0,0,0,8,9,0,38,0,48,49,0,0,9,8,15,0,0,0
0,0,0,0,0,8,14,0,39,0,0,50,0,0,0,8,15,0,0,0
0,0,0,0,0,8,0,0,30,0,51,0,0,30,36,40,0,0,0,0
0,0,0,0,0,8,0,0,38,0,0,0,0,0,0,8,0,0,0,0
0,0,0,0,0,0,8,0,52,0,0,0,0,0,53,8,0,0,0,0
0,0,0,0,0,0,0,0,42,36,0,39,0,30,36,40,0,0,0,0
0,0,0,0,0,0,0,0,0,0,0,36,32,32,40,0,0,0,0,0
0,0,0,0,0,0,0,0,42,36,32,32,0,0,0,0,0,0,0,0
0,0,0,0,0,0,0,0,0,0,0,0,0,0,0,0,0,0,0,0
0,0,0,0,0,0,0,0,0,0,0,0,0,0,0,0,0,0,0,0
0,0,0,0,0,0,0,0,0,0,0,0,0,0,0,0,0,0,0,0
0,0,0,0,0,0,0,0,0,0,0,0,0,0,0,0,0,0,0,0
0,0,0,0,0,0,0,0,0,0,0,0,0,0,0,0,0,0,0,0
0,0,0,0,0,0,0,0,0,0,0,0,0,0,0,0,0,0,0,0
:endlayer
layer: 74
0,0,0,0,0,0,0,0,0,0,0,0,0,0,0,0,0,0,0,0
0,0,0,0,0,0,0,0,0,0,0,0,0,0,0,0,0,0,0,0
0,0,0,0,0,0,0,0,0,0,0,0,0,0,0,0,0,0,0,0
0,0,0,0,0,0,0,0,0,0,0,0,0,0,0,0,0,0,0,0
0,0,0,0,0,0,0,33,0,33,0,0,0,0,0,0,0,0,0,0
0,0,0,0,0,0,0,36,0,36,0,0,41,0,0,0,0,0,0,0
0,0,0,0,0,42,33,38,9,38,0,0,0,0,0,0,0,0,0,0
0,0,0,0,0,42,9,0,0,0,9,0,0,0,0,0,0,0,0,0
0,0,0,0,0,42,9,0,0,0,0,0,0,0,0,0,0,0,0,0
0,0,0,0,0,42,36,0,0,0,0,0,0,0,30,40,0,0,0,0
0,0,0,41,0,0,9,36,0,0,0,0,0,0,9,0,0,0,0,0
0,0,41,35,0,0,0,0,0,0,0,0,0,0,30,40,0,0,0,0
0,0,0,41,35,0,0,0,33,0,0,0,0,0,9,21,0,0,0,0
0,0,0,0,0,9,0,0,42,40,0,0,0,0,30,36,40,0,0,0
0,0,0,0,0,9,0,0,32,0,0,0,0,0,0,9,0,0,0,0
0,0,0,0,0,9,0,0,33,0,0,0,0,0,0,9,0,0,0,0
0,0,0,0,0,9,0,0,42,40,0,0,0,0,30,36,40,0,0,0
0,0,0,0,0,0,0,0,32,0,0,0,0,0,0,13,0,0,0,0
0,0,0,0,0,0,0,0,0,0,0,0,0,0,0,9,0,0,0,0
0,0,0,0,0,0,0,42,36,37,0,0,0,0,30,36,40,0,0,0
0,0,0,0,0,0,0,0,40,0,0,39,36,36,36,40,0,0,0,0
0,0,0,0,0,0,0,42,36,37,30,36,32,36,32,40,0,0,0,0
0,0,0,0,0,0,0,0,0,0,0,32,0,0,0,0,0,0,0,0
0,0,0,0,0,0,0,0,0,0,0,0,0,0,0,0,0,0,0,0
0,0,0,0,0,0,0,0,0,0,0,0,0,0,0,0,0,0,0,0
0,0,0,0,0,0,0,0,0,0,0,0,0,0,0,0,0,0,0,0
0,0,0,0,0,0,0,0,0,0,0,0,0,0,0,0,0,0,0,0
0,0,0,0,0,0,0,0,0,0,0,0,0,0,0,0,0,0,0,0
:endlayer
layer: 75
0,0,0,0,0,0,0,0,0,0,0,0,0,0,0,0,0,0,0,0
0,0,0,0,0,0,0,0,0,0,0,0,0,0,0,0,0,0,0,0
0,0,0,0,0,0,0,0,0,0,0,0,0,0,0,0,0,0,0,0
0,0,0,0,0,0,0,0,0,0,0,0,0,0,0,0,0,0,0,0
0,0,0,0,0,0,0,36,38,36,0,0,0,0,0,0,0,0,0,0
0,0,0,0,0,0,36,38,35,38,36,36,37,0,0,0,0,0,0,0
0,0,0,0,0,36,38,37,35,30,38,30,36,0,0,0,0,0,0,0
0,0,0,42,36,39,39,35,35,35,35,38,30,36,39,0,0,0,0,0
0,0,0,42,36,36,37,35,35,35,35,35,38,30,36,0,0,0,0,0
0,0,41,35,36,36,36,39,39,35,35,35,35,30,36,37,0,0,0,0
0,0,35,0,42,32,32,36,37,35,35,35,35,38,30,36,0,0,0,0
0,0,0,0,0,0,0,41,37,35,35,35,35,35,35,30,0,0,0,0
0,0,0,0,0,0,0,42,36,37,39,30,36,36,36,36,0,0,0,0
0,0,0,0,0,0,0,42,54,54,54,55,54,54,54,54,36,0,0,0
0,0,0,0,0,0,0,42,54,54,54,54,54,54,54,36,0,0,0,0
0,0,0,0,0,0,0,42,54,54,54,54,54,54,54,36,0,0,0,0
0,0,0,0,0,0,0,42,54,54,54,54,54,54,54,36,36,0,0,0
0,0,0,0,0,0,0,36,55,54,54,54,54,54,54,36,0,0,0,0
0,0,0,0,0,0,0,0,36,54,54,54,54,54,54,36,0,0,0,0
0,0,0,0,0,0,0,36,36,54,54,54,54,54,54,54,36,0,0,0
0,0,0,0,0,0,0,42,4,54,54,54,54,54,54,8,40,0,0,0
0,0,0,0,0,0,0,36,4,8,4,54,8,55,54,4,40,0,0,0
0,0,0,0,0,0,0,42,32,32,32,36,32,32,32,32,40,0,0,0
0,0,0,0,0,0,0,0,0,0,0,0,0,0,0,0,0,0,0,0
0,0,0,0,0,0,0,0,0,0,0,0,0,0,0,0,0,0,0,0
0,0,0,0,0,0,0,0,0,0,0,0,0,0,0,0,0,0,0,0
0,0,0,0,0,0,0,0,0,0,0,0,0,0,0,0,0,0,0,0
0,0,0,0,0,0,0,0,0,0,0,0,0,0,0,0,0,0,0,0
:endlayer
layer: 76
0,0,0,0,0,0,0,0,0,0,0,0,0,0,0,0,0,0,0,0
0,0,0,0,0,0,0,0,0,0,0,0,0,0,0,0,0,0,0,0
0,0,0,0,0,0,0,0,0,0,0,0,0,0,0,0,0,0,0,0
0,0,0,0,0,0,0,0,0,0,0,0,0,0,0,0,0,0,0,0
0,0,0,0,0,0,0,36,56,36,0,0,0,0,0,0,0,0,0,0
0,0,0,0,0,0,36,0,0,0,57,56,36,0,0,0,0,0,0,0
0,0,0,0,0,36,0,0,0,0,0,0,30,0,0,0,0,0,0,0
0,0,0,36,36,0,0,0,0,0,0,0,0,38,36,0,0,0,0,0
0,0,0,36,58,59,0,0,0,0,0,0,0,0,56,0,0,0,0,0
0,0,0,0,0,60,36,0,0,0,0,0,0,0,36,0,0,0,0,0
0,0,0,0,35,35,8,37,0,0,0,0,0,0,0,36,0,0,0,0
0,0,0,0,0,0,0,37,0,0,0,0,0,0,0,56,0,0,0,0
0,0,0,0,0,0,0,36,37,0,0,0,0,0,30,36,0,0,0,0
0,0,0,0,0,0,0,37,0,0,0,0,0,0,0,0,36,0,0,0
0,0,0,0,0,0,0,37,0,0,0,0,0,61,0,0,30,0,0,0
0,0,0,0,0,0,0,37,0,0,0,0,62,0,0,0,30,0,0,0
0,0,0,0,0,0,0,37,0,0,0,63,36,0,0,36,36,0,0,0
0,0,0,0,0,0,0,36,0,0,0,0,64,0,0,30,0,0,0,0
0,0,0,0,0,0,0,0,36,39,0,0,0,0,0,30,0,0,0,0
0,0,0,0,0,0,42,8,36,0,0,0,0,0,0,36,36,0,0,0
0,0,0,0,0,0,0,8,36,0,0,0,0,0,0,30,8,0,0,0
0,0,0,0,0,0,0,8,36,39,36,0,38,0,0,36,8,0,0,0
0,0,0,0,0,0,0,36,8,8,39,39,39,36,0,30,8,0,0,0
0,0,0,0,0,0,0,0,0,0,0,0,0,36,39,36,0,0,0,0
0,0,0,0,0,0,0,0,0,0,0,0,0,0,0,0,0,0,0,0
0,0,0,0,0,0,0,0,0,0,0,0,0,0,0,0,0,0,0,0
0,0,0,0,0,0,0,0,0,0,0,0,0,0,0,0,0,0,0,0
0,0,0,0,0,0,0,0,0,0,0,0,0,0,0,0,0,0,0,0
:endlayer
layer: 77
0,0,0,0,0,0,0,0,0,0,0,0,0,0,0,0,0,0,0,0
0,0,0,0,0,0,0,0,0,0,0,0,0,0,0,0,0,0,0,0
0,0,0,0,0,0,0,0,0,0,0,0,0,0,0,0,0,0,0,0
0,0,0,0,0,0,0,0,0,0,0,0,0,0,0,0,0,0,0,0
0,0,0,0,0,0,0,36,56,36,0,0,0,0,0,0,0,0,0,0
0,0,0,0,0,0,36,0,0,0,36,56,36,0,0,0,0,0,0,0
0,0,0,33,0,36,0,0,0,0,0,0,42,0,0,0,0,0,0,0
0,0,42,36,65,0,0,0,0,0,0,0,0,32,36,0,0,0,0,0
0,0,0,0,66,0,0,0,0,0,0,0,0,0,56,0,0,0,0,0
0,0,0,0,0,67,65,0,0,0,0,0,0,68,36,0,0,0,0,0
0,0,0,0,0,0,9,40,0,0,0,0,0,0,0,36,0,0,0,0
0,0,0,0,0,0,0,40,0,0,0,0,0,0,0,56,0,0,0,0
0,0,0,0,0,0,0,36,0,0,0,0,0,0,0,36,0,0,0,0
0,0,0,0,0,0,0,56,0,0,0,0,0,0,0,0,36,40,0,0
0,0,0,0,0,0,0,56,0,0,0,0,0,0,0,0,56,0,0,0
0,0,0,0,0,0,0,56,0,0,0,0,0,0,0,0,56,0,0,0
0,0,0,0,0,0,0,56,0,0,0,0,36,0,68,36,36,40,0,0
0,0,0,0,0,0,0,36,0,0,0,0,0,0,0,56,0,0,0,0
0,0,0,0,0,0,0,0,36,0,0,0,0,0,0,56,0,0,0,0
0,0,0,0,0,42,36,9,37,39,0,0,0,0,0,36,36,40,0,0
0,0,0,0,0,0,0,9,37,0,0,0,69,0,0,56,9,0,0,0
0,0,0,0,0,0,0,13,36,56,36,0,32,0,0,36,9,0,0,0
0,0,0,0,0,0,42,36,9,9,56,56,56,36,0,56,9,0,0,0
0,0,0,0,0,0,0,0,0,0,0,0,0,36,56,56,0,0,0,0
0,0,0,0,0,0,0,0,0,0,0,0,0,0,0,0,0,0,0,0
0,0,0,0,0,0,0,0,0,0,0,0,0,0,0,0,0,0,0,0
0,0,0,0,0,0,0,0,0,0,0,0,0,0,0,0,0,0,0,0
0,0,0,0,0,0,0,0,0,0,0,0,0,0,0,0,0,0,0,0
:endlayer
layer: 78
0,0,0,0,0,0,0,39,39,39,0,0,0,0,0,0,0,0,0,0
0,0,0,0,0,0,39,70,70,70,37,39,40,0,0,0,0,0,0,0
0,0,0,0,0,30,70,71,71,71,70,70,37,0,0,0,0,0,0,0
0,0,0,0,39,70,0,33,0,33,0,71,70,40,0,0,0,0,0,0
0,0,0,39,70,0,33,36,56,36,0,0,71,70,40,0,0,0,0,0
0,0,30,70,71,42,36,0,0,0,36,56,36,71,70,33,0,0,0,0
0,0,33,70,71,36,72,0,0,0,72,42,36,0,71,70,39,0,0,0
0,30,70,36,36,0,0,0,0,0,0,0,0,36,36,71,70,39,0,0
0,30,70,71,73,36,0,0,0,0,0,0,0,32,56,0,71,70,37,0
0,30,70,71,0,74,36,0,0,0,0,0,0,0,36,40,0,70,39,0
0,0,30,70,71,0,0,36,0,0,0,0,0,0,41,36,40,71,70,37
0,0,0,30,70,71,0,36,0,0,0,0,0,75,75,42,40,71,70,40
0,0,0,0,42,70,71,36,76,0,0,0,41,75,42,36,33,71,70,37
0,0,0,42,70,42,40,40,0,0,0,0,41,41,42,36,36,70,37,0
0,0,0,0,42,70,71,40,0,0,0,0,41,75,75,0,42,71,70,37
0,0,0,42,70,71,0,40,0,0,0,0,33,75,75,0,42,71,70,40
0,0,0,30,70,71,0,40,0,0,0,42,36,40,42,77,36,0,70,37
0,0,0,30,70,71,42,33,0,0,0,0,32,75,75,36,40,71,70,40
0,0,0,0,30,70,71,0,37,0,0,0,41,75,75,36,40,71,70,37
0,0,0,0,30,70,36,65,0,0,75,41,41,41,42,77,36,70,37,0
0,0,0,0,30,70,71,65,0,39,75,41,75,75,75,42,0,71,70,37
0,0,0,0,30,70,71,0,36,33,37,41,30,0,0,42,40,71,70,37
0,0,0,0,0,42,70,71,0,42,33,33,33,40,0,42,71,71,70,40
0,0,0,0,0,30,70,71,71,71,71,71,71,40,33,36,71,70,32,0
0,0,0,0,0,0,32,70,70,70,70,70,71,71,71,71,70,32,0,0
0,0,0,0,0,0,0,38,38,38,38,38,70,70,71,70,40,0,0,0
0,0,0,0,0,0,0,0,0,0,0,30,38,30,70,38,0,0,0,0
0,0,0,0,0,0,0,0,0,0,0,0,0,0,38,0,0,0,0,0
:endlayer
layer: 79
0,0,0,0,0,0,0,0,0,0,0,0,0,0,0,0,0,0,0,0
0,0,0,0,0,0,0,39,39,39,0,0,0,0,0,0,0,0,0,0
0,0,0,0,0,0,30,78,78,78,37,39,0,0,0,0,0,0,0,0
0,0,0,0,0,39,78,78,0,78,78,78,39,0,0,0,0,0,0,0
0,0,0,0,30,78,78,71,32,71,71,78,78,37,0,0,0,0,0,0
0,0,0,30,78,78,36,0,41,0,36,36,71,78,37,0,0,0,0,0
0,0,0,39,78,78,0,41,41,41,32,36,36,36,78,39,0,0,0,0
0,0,30,78,78,71,0,41,75,75,75,75,32,36,71,78,37,0,0,0
0,0,30,78,78,71,0,41,75,75,75,75,75,36,36,71,78,37,0,0
0,0,30,78,78,36,71,0,41,75,75,75,75,42,36,71,78,37,0,0
0,0,0,30,78,78,78,71,0,75,75,75,75,79,0,34,78,78,37,0
0,0,0,0,38,78,78,71,0,0,0,0,79,0,0,0,78,78,37,0
0,0,0,0,0,30,78,36,41,0,0,0,0,0,80,42,78,78,37,0
0,0,0,0,35,30,78,36,40,0,0,0,0,0,0,0,36,37,0,0
0,0,0,0,0,30,78,36,41,0,0,0,0,0,0,42,78,78,37,0
0,0,0,0,30,78,78,36,40,0,0,0,0,0,0,42,78,78,37,0
0,0,0,0,30,78,0,36,41,0,0,0,0,0,0,0,36,78,37,0
0,0,0,0,30,78,78,36,40,0,0,0,0,0,0,42,78,78,37,0
0,0,0,0,0,30,78,78,41,0,0,0,0,0,81,42,78,78,37,0
0,0,0,0,0,35,30,78,40,0,0,0,0,0,0,0,36,37,0,0
0,0,0,0,0,30,78,78,40,0,0,0,0,0,0,42,78,78,37,0
0,0,0,0,0,30,78,78,71,71,71,71,71,0,0,34,78,78,37,0
0,0,0,0,0,0,30,78,78,78,78,78,71,35,33,35,78,78,37,0
0,0,0,0,0,0,30,78,78,78,78,78,78,36,35,78,78,38,0,0
0,0,0,0,0,0,0,38,38,38,38,38,78,78,78,78,38,0,0,0
0,0,0,0,0,0,0,0,0,0,0,0,38,38,78,38,0,0,0,0
0,0,0,0,0,0,0,0,0,0,0,0,0,0,38,0,0,0,0,0
0,0,0,0,0,0,0,0,0,0,0,0,0,0,0,0,0,0,0,0
:endlayer
layer: 80
0,0,0,0,0,0,0,0,0,0,0,0,0,0,0,0,0,0,0,0
0,0,0,0,0,0,0,0,0,0,0,0,0,0,0,0,0,0,0,0
0,0,0,0,0,0,0,39,39,39,0,0,0,0,0,0,0,0,0,0
0,0,0,0,0,0,30,0,78,37,39,35,0,0,0,0,0,0,0,0
0,0,0,0,0,39,30,78,36,78,78,39,39,0,0,0,0,0,0,0
0,0,0,0,30,82,78,71,83,71,78,78,78,39,0,0,0,0,0,0
0,0,0,0,30,82,78,0,83,83,83,42,36,78,39,0,0,0,0,0
0,0,0,30,39,78,71,83,0,0,83,83,83,78,78,37,0,0,0,0
0,0,0,30,82,78,71,83,0,84,0,0,0,83,36,78,37,0,0,0
0,0,0,30,82,78,78,71,0,0,85,86,0,83,36,78,37,0,0,0
0,0,0,0,38,38,30,78,71,0,0,0,0,0,0,78,37,37,0,0
0,0,0,0,0,35,30,78,71,0,0,0,0,0,0,0,78,37,0,0
0,0,0,0,0,0,30,78,78,0,0,0,0,0,0,78,37,38,0,0
0,0,0,0,0,0,35,30,78,0,0,0,0,0,0,0,37,0,0,0
0,0,0,0,0,0,30,78,78,0,0,0,0,0,0,78,35,35,0,0
0,0,0,0,0,35,30,78,71,0,0,0,0,0,0,78,35,35,0,0
0,0,0,0,0,30,78,71,0,0,0,0,0,0,0,0,37,35,0,0
0,0,0,0,0,35,30,78,71,0,0,0,0,0,0,78,35,35,0,0
0,0,0,0,0,0,35,30,78,0,0,0,0,0,0,78,35,35,0,0
0,0,0,0,0,0,0,30,78,0,0,0,0,0,0,0,37,0,0,0
0,0,0,0,0,0,35,30,78,0,0,0,0,0,0,78,37,35,0,0
0,0,0,0,0,0,35,30,78,78,78,78,78,71,71,78,37,35,0,0
0,0,0,0,0,0,0,30,38,38,38,38,38,78,78,78,37,35,0,0
0,0,0,0,0,0,0,35,35,35,35,35,30,78,78,38,37,0,0,0
0,0,0,0,0,0,0,0,0,0,0,0,38,38,38,37,0,0,0,0
0,0,0,0,0,0,0,0,0,0,0,0,0,0,35,0,0,0,0,0
0,0,0,0,0,0,0,0,0,0,0,0,0,0,0,0,0,0,0,0
0,0,0,0,0,0,0,0,0,0,0,0,0,0,0,0,0,0,0,0
:endlayer
layer: 81
0,0,0,0,0,0,0,0,0,0,0,0,0,0,0,0,0,0,0,0
0,0,0,0,0,0,0,0,0,0,0,0,0,0,0,0,0,0,0,0
0,0,0,0,0,0,0,0,0,0,0,0,0,0,0,0,0,0,0,0
0,0,0,0,0,0,0,0,39,0,0,0,0,0,0,0,0,0,0,0
0,0,0,0,0,0,0,39,78,39,37,0,0,0,0,0,0,0,0,0
0,0,0,0,0,0,30,78,83,78,37,39,39,0,0,0,0,0,0,0
0,0,0,0,0,0,30,78,83,83,78,78,78,37,0,0,0,0,0,0
0,0,0,0,0,30,78,83,0,0,83,83,83,78,37,0,0,0,0,0
0,0,0,0,0,30,78,83,0,0,0,0,0,83,78,37,0,0,0,0
0,0,0,0,0,30,38,78,0,0,0,0,0,83,78,37,0,0,0,0
0,0,0,0,0,0,0,30,78,0,0,0,0,0,78,37,0,0,0,0
0,0,0,0,0,0,0,30,78,0,0,0,0,0,71,78,37,0,0,0
0,0,0,0,0,0,0,35,30,78,0,0,0,0,78,37,0,0,0,0
0,0,0,0,0,0,0,0,30,78,0,0,0,78,37,35,30,41,0,0
0,0,0,0,0,0,0,35,30,78,0,0,0,0,78,37,0,0,0,0
0,0,0,0,0,0,0,30,78,0,0,0,0,0,78,37,0,0,0,0
0,0,0,0,0,0,30,78,71,0,0,0,0,78,37,35,30,41,0,0
0,0,0,0,0,0,0,30,78,0,0,0,0,0,78,37,0,0,0,0
0,0,0,0,0,0,0,0,30,78,0,0,0,0,78,37,0,0,0,0
0,0,0,0,0,0,0,0,30,78,0,0,0,78,37,35,30,41,0,0
0,0,0,0,0,0,0,0,30,78,78,78,78,78,78,37,0,0,0,0
0,0,0,0,0,0,0,0,30,38,38,38,38,78,78,37,0,0,0,0
0,0,0,0,0,0,0,0,0,0,0,0,0,38,38,37,0,0,0,0
0,0,0,0,0,0,0,0,0,0,0,0,0,35,35,0,0,0,0,0
0,0,0,0,0,0,0,0,0,0,0,0,0,0,0,0,0,0,0,0
0,0,0,0,0,0,0,0,0,0,0,0,0,0,0,0,0,0,0,0
0,0,0,0,0,0,0,0,0,0,0,0,0,0,0,0,0,0,0,0
0,0,0,0,0,0,0,0,0,0,0,0,0,0,0,0,0,0,0,0
:endlayer
layer: 82
0,0,0,0,0,0,0,0,0,0,0,0,0,0,0,0,0,0,0,0
0,0,0,0,0,0,0,0,0,0,0,0,0,0,0,0,0,0,0,0
0,0,0,0,0,0,0,0,0,0,0,0,0,0,0,0,0,0,0,0
0,0,0,0,0,0,0,0,0,0,0,0,0,0,0,0,0,0,0,0
0,0,0,0,0,0,0,0,39,0,0,0,0,0,0,0,0,0,0,0
0,0,0,0,0,0,0,30,78,37,0,0,0,0,0,0,0,0,0,0
0,0,0,0,0,0,0,30,78,78,39,39,39,0,0,0,0,0,0,0
0,0,0,0,0,0,30,78,78,71,78,78,78,39,0,0,0,0,0,0
0,0,0,0,0,0,30,78,71,0,0,0,0,78,37,0,0,0,0,0
0,0,0,0,0,0,0,30,78,0,0,0,0,71,78,0,0,0,0,0
0,0,0,0,0,0,0,0,30,78,0,0,0,78,37,0,0,0,0,0
0,0,0,0,0,0,0,0,30,78,0,0,0,71,78,37,0,0,0,0
0,0,0,0,0,0,0,0,0,30,78,0,0,78,37,0,0,0,0,0
0,0,0,0,0,0,0,0,0,35,78,0,78,35,0,0,0,0,0,0
0,0,0,0,0,0,0,0,0,30,78,0,71,78,37,0,0,0,0,0
0,0,0,0,0,0,0,0,30,78,0,0,71,78,37,0,0,0,0,0
0,0,0,0,0,0,0,30,78,71,0,0,78,35,0,0,0,0,0,0
0,0,0,0,0,0,0,0,30,78,0,0,71,78,37,0,0,0,0,0
0,0,0,0,0,0,0,0,0,35,78,0,71,78,37,0,0,0,0,0
0,0,0,0,0,0,0,0,0,35,78,78,78,37,0,0,0,0,0,0
0,0,0,0,0,0,0,0,0,35,38,38,38,37,35,0,0,0,0,0
0,0,0,0,0,0,0,0,0,0,0,0,0,35,35,0,0,0,0,0
0,0,0,0,0,0,0,0,0,0,0,0,0,0,0,0,0,0,0,0
0,0,0,0,0,0,0,0,0,0,0,0,0,0,0,0,0,0,0,0
0,0,0,0,0,0,0,0,0,0,0,0,0,0,0,0,0,0,0,0
0,0,0,0,0,0,0,0,0,0,0,0,0,0,0,0,0,0,0,0
0,0,0,0,0,0,0,0,0,0,0,0,0,0,0,0,0,0,0,0
0,0,0,0,0,0,0,0,0,0,0,0,0,0,0,0,0,0,0,0
:endlayer
layer: 83
0,0,0,0,0,0,0,0,0,0,0,0,0,0,0,0,0,0,0,0
0,0,0,0,0,0,0,0,0,0,0,0,0,0,0,0,0,0,0,0
0,0,0,0,0,0,0,0,0,0,0,0,0,0,0,0,0,0,0,0
0,0,0,0,0,0,0,0,0,0,0,0,0,0,0,0,0,0,0,0
0,0,0,0,0,0,0,0,0,0,0,0,0,0,0,0,0,0,0,0
0,0,0,0,0,0,0,0,39,0,0,0,0,0,0,0,0,0,0,0
0,0,0,0,0,0,0,0,0,39,0,0,0,0,0,0,0,0,0,0
0,0,0,0,0,0,0,30,78,78,37,39,39,0,0,0,0,0,0,0
0,0,0,0,0,0,0,30,78,34,78,78,78,39,0,0,0,0,0,0
0,0,0,0,0,0,0,0,30,78,0,0,0,78,37,0,0,0,0,0
0,0,0,0,0,0,0,0,0,30,78,0,78,37,0,0,0,0,0,0
0,0,0,0,0,0,0,0,0,30,78,78,78,78,37,0,0,0,0,0
0,0,0,0,0,0,0,0,0,0,30,78,78,37,0,0,0,0,0,0
0,0,0,0,0,0,0,0,0,0,30,78,37,0,0,0,0,0,0,0
0,0,0,0,0,0,0,0,0,0,30,78,78,37,0,0,0,0,0,0
0,0,0,0,0,0,0,0,0,30,78,78,78,37,0,0,0,0,0,0
0,0,0,0,0,0,0,0,30,78,78,78,37,0,0,0,0,0,0,0
0,0,0,0,0,0,0,0,0,30,78,78,78,37,0,0,0,0,0,0
0,0,0,0,0,0,0,0,0,0,30,78,78,37,0,0,0,0,0,0
0,0,0,0,0,0,0,0,0,0,38,38,38,0,0,0,0,0,0,0
0,0,0,0,0,0,0,0,0,0,0,0,0,0,0,0,0,0,0,0
0,0,0,0,0,0,0,0,0,0,0,0,0,0,0,0,0,0,0,0
0,0,0,0,0,0,0,0,0,0,0,0,0,0,0,0,0,0,0,0
0,0,0,0,0,0,0,0,0,0,0,0,0,0,0,0,0,0,0,0
0,0,0,0,0,0,0,0,0,0,0,0,0,0,0,0,0,0,0,0
0,0,0,0,0,0,0,0,0,0,0,0,0,0,0,0,0,0,0,0
0,0,0,0,0,0,0,0,0,0,0,0,0,0,0,0,0,0,0,0
0,0,0,0,0,0,0,0,0,0,0,0,0,0,0,0,0,0,0,0
:endlayer
layer: 84
0,0,0,0,0,0,0,0,0,0,0,0,0,0,0,0,0,0,0,0
0,0,0,0,0,0,0,0,0,0,0,0,0,0,0,0,0,0,0,0
0,0,0,0,0,0,0,0,0,0,0,0,0,0,0,0,0,0,0,0
0,0,0,0,0,0,0,0,0,0,0,0,0,0,0,0,0,0,0,0
0,0,0,0,0,0,0,0,0,0,0,0,0,0,0,0,0,0,0,0
0,0,0,0,0,0,0,0,0,0,0,0,0,0,0,0,0,0,0,0
0,0,0,0,0,0,0,0,39,0,0,0,0,0,0,0,0,0,0,0
0,0,0,0,0,0,0,0,30,39,0,0,0,0,0,0,0,0,0,0
0,0,0,0,0,0,0,0,30,78,39,39,39,0,0,0,0,0,0,0
0,0,0,0,0,0,0,0,0,30,78,78,78,37,0,0,0,0,0,0
0,0,0,0,0,0,0,0,0,0,30,78,37,0,0,0,0,0,0,0
0,0,0,0,0,0,0,0,0,0,30,78,37,35,0,0,0,0,0,0
0,0,0,0,0,0,0,0,0,0,0,30,37,0,0,0,0,0,0,0
0,0,0,0,0,0,0,0,0,0,0,35,0,0,0,0,0,0,0,0
0,0,0,0,0,0,0,0,0,0,0,30,37,0,0,0,0,0,0,0
0,0,0,0,0,0,0,0,0,0,39,30,37,0,0,0,0,0,0,0
0,0,0,0,0,0,0,0,0,30,78,39,0,0,0,0,0,0,0,0
0,0,0,0,0,0,0,0,0,0,38,78,37,0,0,0,0,0,0,0
0,0,0,0,0,0,0,0,0,0,0,38,37,0,0,0,0,0,0,0
0,0,0,0,0,0,0,0,0,0,0,0,0,0,0,0,0,0,0,0
0,0,0,0,0,0,0,0,0,0,0,0,0,0,0,0,0,0,0,0
0,0,0,0,0,0,0,0,0,0,0,0,0,0,0,0,0,0,0,0
0,0,0,0,0,0,0,0,0,0,0,0,0,0,0,0,0,0,0,0
0,0,0,0,0,0,0,0,0,0,0,0,0,0,0,0,0,0,0,0
0,0,0,0,0,0,0,0,0,0,0,0,0,0,0,0,0,0,0,0
0,0,0,0,0,0,0,0,0,0,0,0,0,0,0,0,0,0,0,0
0,0,0,0,0,0,0,0,0,0,0,0,0,0,0,0,0,0,0,0
0,0,0,0,0,0,0,0,0,0,0,0,0,0,0,0,0,0,0,0
:endlayer
layer: 85
