# Ancient Warfare Structure Template File
# Auto-generated structure template file. created on: 12/7/2018 at: 22:22:23
# Lines beginning with # denote comments

header:
version=2.8
name=ELBWizardsTowerGeneric
mods=ebwizardry
size=20,104,28
offset=9,13,27
:endheader

#### VALIDATION ####
validation:
type=ground
survival=false
worldGenEnabled=true
unique=false
preserveBlocks=false
selectionWeight=50
clusterValue=50
minDuplicateDistance=997
dimensionWhiteList=false
dimensionList=
biomeWhiteList=true
biomeList=minecraft:extreme_hills,minecraft:taiga,biomesoplenty:mountain_foothills,biomesoplenty:mystic_grove,minecraft:redwood_taiga_hills,biomesoplenty:moor,minecraft:forest_hills,minecraft:birch_forest_hills,biomesoplenty:alps_foothills
leveling=5
fill=5
border=5
blockSwap=false
:endvalidation

#### LAYERS ####
layer: 0
1,1,1,1,1,1,1,1,1,1,1,1,1,1,1,1,1,1,1,1
1,1,1,1,1,1,1,1,1,1,1,1,1,1,1,1,1,1,1,1
1,1,1,1,1,1,1,1,1,1,1,1,1,1,1,1,1,1,1,1
1,1,2,1,1,1,1,1,0,1,1,1,1,1,1,1,1,1,1,1
1,1,1,1,1,1,1,1,1,1,1,1,3,3,1,1,1,1,1,1
1,1,1,1,1,1,1,1,1,1,4,3,3,3,1,1,1,1,1,1
1,1,1,1,1,1,1,1,1,1,1,3,3,1,1,1,1,1,1,1
1,1,1,1,1,1,1,1,1,1,1,1,1,1,1,1,1,1,1,1
1,1,1,1,1,1,1,1,1,1,1,1,1,1,1,1,1,1,1,1
1,1,1,1,1,1,1,1,1,1,1,1,1,1,1,1,1,1,1,1
1,1,1,1,1,1,1,1,1,1,1,1,1,1,1,1,1,1,1,1
1,1,1,0,1,1,3,3,1,1,1,1,1,1,1,1,1,1,1,1
1,1,0,0,1,1,3,3,1,1,1,1,1,1,1,1,1,1,1,1
1,1,0,0,1,0,0,1,1,1,1,1,1,1,1,1,1,1,1,1
1,1,0,0,1,0,0,1,1,1,1,1,1,1,1,1,1,1,1,1
1,1,0,0,1,0,0,0,1,1,1,1,1,1,1,1,1,1,1,1
1,1,0,1,1,0,0,0,0,1,1,1,1,1,1,1,1,1,1,1
1,1,1,1,1,0,0,0,0,0,1,1,1,1,1,1,1,1,1,1
1,1,1,1,1,1,0,0,0,1,1,1,1,1,1,1,1,1,1,1
1,1,1,1,1,1,0,0,1,1,1,1,1,1,1,1,1,1,1,1
1,1,1,1,1,1,1,1,1,1,1,1,1,5,1,1,1,1,1,1
1,1,1,1,1,1,1,1,1,1,5,5,5,5,1,1,1,1,1,1
1,1,1,1,1,1,1,1,1,5,5,5,5,5,1,1,1,1,1,1
1,1,1,1,1,1,1,1,1,1,5,5,1,1,1,1,1,1,1,1
1,1,1,1,1,1,1,1,1,1,1,1,1,1,1,1,1,1,1,1
1,1,1,1,1,1,1,1,1,1,1,1,1,1,1,1,1,1,1,1
1,1,1,1,1,1,1,1,1,1,1,1,1,1,1,1,1,1,1,1
1,1,1,1,1,1,1,1,1,1,1,1,1,1,1,1,1,1,1,1
:endlayer
layer: 1
1,1,1,1,1,1,1,1,1,1,1,1,1,1,1,1,1,1,1,1
1,1,1,1,1,1,1,1,1,1,1,1,1,1,1,1,1,1,1,1
1,1,1,1,1,1,1,1,1,1,1,1,1,1,1,1,1,1,1,1
1,1,2,1,1,1,1,1,1,1,1,1,1,1,1,1,1,1,1,1
1,1,1,1,1,1,1,1,1,1,4,4,3,3,1,1,1,1,1,1
1,1,1,1,1,1,1,1,4,4,4,3,3,3,1,1,1,1,1,1
1,1,1,1,1,1,1,1,4,4,4,3,3,1,1,1,1,1,1,1
1,1,1,1,1,1,1,4,4,4,4,4,1,1,1,1,1,1,1,1
1,1,1,1,1,1,1,4,4,4,1,1,1,1,1,1,1,1,1,1
1,1,1,1,1,1,1,1,1,1,1,1,1,1,1,1,1,1,1,1
1,1,1,1,1,1,1,1,1,1,1,1,1,1,1,1,4,1,1,1
1,1,1,6,6,6,1,1,1,1,1,1,1,1,1,4,4,4,1,1
1,1,6,0,6,1,1,1,1,1,1,1,1,1,1,1,4,4,1,1
1,1,1,1,1,1,1,1,1,1,1,1,1,1,1,1,1,4,1,1
1,1,0,1,1,1,1,1,1,1,1,1,1,1,1,1,1,1,1,1
1,1,0,1,1,1,1,1,1,1,1,1,1,1,1,1,1,1,1,1
1,1,0,1,1,1,1,1,1,1,1,1,1,1,1,1,1,1,1,1
1,1,1,1,1,1,1,1,1,1,1,1,1,1,1,1,1,1,1,1
1,1,1,1,1,1,1,1,1,1,1,1,1,1,1,1,1,1,1,1
1,1,1,1,1,1,1,1,1,1,1,1,1,1,1,1,1,1,1,1
1,1,1,1,1,1,1,1,1,1,1,1,1,1,1,1,1,1,1,1
1,1,1,1,1,1,1,0,1,1,1,1,5,5,1,1,1,1,1,1
1,1,1,1,1,1,1,1,0,1,7,1,5,1,1,1,1,1,1,1
1,1,1,1,1,1,1,1,1,1,1,1,1,1,1,1,1,1,1,1
1,1,1,1,1,1,1,1,1,1,1,1,1,1,1,1,5,5,1,1
1,1,1,1,1,1,1,1,1,1,1,1,1,1,1,1,5,5,1,1
1,1,1,1,1,1,1,1,1,1,1,1,1,1,1,1,1,1,1,1
1,1,1,1,1,1,1,1,1,1,1,1,1,1,1,1,1,1,1,1
:endlayer
layer: 2
1,1,1,1,1,1,1,1,1,1,1,1,1,1,1,1,1,1,1,1
1,1,1,1,1,1,1,1,1,1,1,1,1,1,1,1,1,1,1,1
1,1,1,1,1,1,1,1,1,1,1,1,1,1,1,1,1,1,1,1
1,1,1,1,1,1,1,1,1,1,1,1,1,1,1,1,1,1,1,1
1,1,1,1,1,1,1,1,1,4,4,4,4,1,1,1,1,1,1,1
1,1,1,1,1,1,1,1,4,4,4,4,4,1,1,1,1,1,1,1
1,1,1,1,1,1,4,4,4,4,4,3,4,1,1,1,1,1,1,1
1,1,1,1,1,1,4,4,4,4,4,4,1,1,1,1,1,1,1,1
1,1,1,1,1,1,4,4,4,4,4,1,1,1,1,1,1,1,1,1
1,1,1,1,1,1,1,4,4,1,1,1,1,1,4,4,4,1,1,1
1,1,1,1,1,1,1,1,1,1,1,1,1,1,4,4,4,4,1,1
1,1,1,1,6,6,1,1,1,1,1,1,1,1,4,4,4,4,1,1
1,1,1,6,1,1,1,1,1,1,1,1,1,1,1,4,4,4,1,1
1,1,1,1,1,1,1,1,1,1,1,1,1,1,1,1,4,4,1,1
1,1,1,1,1,1,1,1,1,1,1,1,1,1,1,3,4,4,1,1
1,1,1,1,1,1,1,1,1,1,1,1,1,1,1,1,1,1,1,1
1,1,1,1,1,1,1,1,1,1,1,1,1,1,1,1,1,1,1,1
1,1,1,1,1,1,1,1,1,1,1,1,1,1,1,1,1,1,1,1
1,1,1,1,1,1,1,1,1,1,1,1,1,1,1,1,1,1,1,1
1,1,1,1,1,1,1,1,1,1,1,1,1,1,1,1,1,1,1,1
1,1,1,1,0,1,1,1,1,1,1,1,1,1,1,1,1,1,1,1
1,1,1,1,1,1,1,0,1,1,1,1,1,1,1,1,4,1,1,1
1,1,1,1,1,1,1,1,0,8,9,1,1,1,4,4,4,1,1,1
1,1,1,1,1,1,1,1,1,10,11,1,1,1,4,4,4,1,1,1
1,1,1,1,1,1,1,1,1,1,1,1,1,1,4,5,5,5,1,1
1,1,1,1,1,1,1,1,1,1,4,4,1,1,1,1,5,5,1,1
1,1,1,1,1,1,1,1,1,1,1,1,1,1,1,1,1,1,1,1
1,1,1,1,1,1,1,1,1,1,1,1,1,1,1,1,1,1,1,1
:endlayer
layer: 3
1,1,1,1,1,1,1,1,1,1,1,1,1,1,1,1,1,1,1,1
1,1,1,1,1,1,1,1,1,1,1,1,1,1,1,1,1,1,1,1
1,1,1,1,1,1,1,1,1,1,1,12,12,12,12,12,1,1,1,1
1,1,1,1,1,1,1,1,1,1,1,1,12,12,12,12,1,1,1,1
1,1,1,1,1,1,1,1,1,4,4,4,1,1,1,1,1,1,1,1
1,1,1,1,1,1,1,1,4,4,4,4,4,1,1,1,1,1,1,1
1,1,1,1,1,1,4,4,4,4,4,4,4,1,1,1,1,1,1,1
1,1,1,1,1,4,4,4,4,4,4,4,1,1,1,1,1,1,1,1
1,1,1,1,1,4,4,4,4,4,4,1,1,1,1,1,1,1,1,1
1,1,1,1,4,4,4,4,4,1,1,1,1,1,4,4,4,1,1,1
1,1,3,1,1,1,1,1,1,1,1,1,1,1,4,4,4,4,1,1
1,1,1,1,1,1,1,1,1,1,1,1,1,1,4,4,4,4,1,1
1,1,1,1,1,1,1,1,1,1,1,1,1,1,1,4,4,4,1,1
1,1,1,1,1,0,0,1,1,1,1,1,1,1,1,4,4,4,1,1
1,1,1,1,1,0,1,1,1,1,1,1,1,1,1,3,4,4,1,1
1,1,1,1,1,1,1,1,1,1,1,1,1,1,1,1,1,4,1,1
1,1,1,1,1,1,1,1,1,1,1,1,1,1,1,1,1,1,1,1
1,1,1,1,1,1,1,1,1,1,1,1,1,1,1,1,1,1,1,1
1,1,1,1,1,1,1,1,1,1,1,1,1,1,1,1,1,1,1,1
1,1,1,0,1,1,0,0,1,1,1,1,1,1,1,4,4,4,1,1
1,1,1,1,1,1,0,0,1,1,1,1,1,5,5,4,4,4,1,1
1,1,1,1,1,1,1,1,1,1,1,1,1,5,4,4,4,4,1,1
1,1,1,1,1,1,1,1,1,1,1,1,1,4,4,4,4,4,1,1
1,1,1,1,1,1,1,1,1,13,1,1,1,4,4,4,4,1,1,1
1,1,1,1,1,1,1,1,1,1,1,1,1,4,4,4,4,5,1,1
1,1,1,1,1,1,1,1,1,1,4,4,4,4,4,1,5,5,1,1
1,1,1,1,1,1,1,1,1,1,1,1,1,1,1,1,1,1,1,1
1,1,1,1,1,1,1,1,1,1,1,1,1,1,1,1,1,1,1,1
:endlayer
layer: 4
1,1,1,1,1,1,1,1,1,1,1,1,1,1,1,1,1,1,1,1
1,1,1,1,1,1,1,1,1,1,1,1,1,1,1,1,1,1,1,1
1,1,1,1,1,1,1,1,1,1,12,12,12,12,12,12,12,1,1,1
1,1,1,1,1,1,1,1,1,1,1,12,12,12,12,12,12,1,1,1
1,1,1,1,1,1,1,1,1,1,1,1,1,1,12,12,12,1,1,1
1,1,1,1,1,1,1,1,4,4,4,1,1,1,1,1,1,1,1,1
1,1,1,1,1,1,1,4,4,4,4,1,1,1,1,1,1,1,1,1
1,1,1,1,1,1,4,4,4,4,4,1,1,1,1,1,1,1,1,1
1,1,1,1,1,4,4,4,4,4,1,1,1,1,1,1,1,1,1,1
1,1,3,3,4,4,4,1,1,1,1,1,1,1,1,1,1,1,1,1
1,1,3,3,1,1,1,1,1,1,1,1,1,1,1,4,4,4,1,1
1,1,1,1,1,1,1,1,1,1,1,1,1,1,1,4,4,4,1,1
1,1,1,1,1,1,1,1,1,1,1,1,1,1,1,4,4,4,1,1
1,1,1,1,1,1,1,1,1,1,1,1,1,1,1,1,4,4,1,1
1,1,1,1,1,1,1,1,1,1,1,1,1,1,1,1,4,4,1,1
1,1,1,1,1,1,1,1,1,1,1,1,1,1,1,1,1,1,1,1
1,1,1,0,1,1,1,1,1,1,1,1,1,1,1,1,1,1,1,1
1,1,1,1,1,1,1,1,1,1,1,1,1,1,1,1,1,1,1,1
1,1,1,1,1,1,1,1,1,1,1,1,1,1,1,1,4,4,1,1
1,1,1,1,1,1,1,1,1,1,1,1,1,1,1,4,4,4,1,1
1,1,1,1,1,1,1,1,1,1,1,1,1,5,4,4,4,4,1,1
1,1,1,1,1,1,1,1,1,1,1,1,1,5,4,4,4,4,1,1
1,1,1,1,1,1,1,1,1,1,1,1,1,4,4,4,4,4,1,1
1,1,1,1,1,1,1,1,1,1,1,1,1,4,4,4,4,4,1,1
1,1,1,1,1,1,1,1,1,1,1,1,1,4,4,4,4,1,1,1
1,1,1,1,1,1,1,1,1,1,1,1,4,4,4,4,1,1,1,1
1,1,1,1,1,1,1,1,1,1,1,1,1,1,1,1,1,1,1,1
1,1,1,1,1,1,1,1,1,1,1,1,1,1,1,1,1,1,1,1
:endlayer
layer: 5
1,1,1,1,1,1,1,1,1,1,1,1,1,1,1,1,1,1,1,1
1,1,1,1,1,1,1,1,1,1,1,1,1,1,1,1,1,1,1,1
1,1,1,1,1,1,1,1,1,1,12,12,12,12,12,12,12,1,1,1
1,1,1,1,1,1,1,1,1,1,1,12,12,12,12,12,12,1,1,1
1,1,1,1,1,1,1,1,1,1,1,1,1,0,12,12,12,1,1,1
1,1,1,1,1,1,1,1,1,1,1,1,0,0,1,1,1,1,1,1
1,1,1,1,1,1,1,1,1,1,1,1,1,1,1,1,1,1,1,1
1,1,1,1,1,1,1,1,1,1,1,1,1,1,0,0,1,1,1,1
1,1,1,1,1,1,1,1,1,1,1,1,1,1,0,0,1,1,1,1
1,1,1,3,1,1,1,1,1,1,1,1,1,1,1,1,1,1,1,1
1,1,1,1,1,1,1,1,1,1,1,1,1,1,1,1,1,1,1,1
1,1,1,1,1,1,1,1,1,1,1,1,1,1,1,1,1,1,1,1
1,1,1,1,1,1,1,1,1,1,1,1,1,1,1,1,1,4,1,1
1,1,1,1,1,1,1,1,1,1,1,1,1,1,1,1,1,4,1,1
1,1,1,1,1,1,1,1,1,1,1,1,1,1,1,1,1,1,1,1
1,1,1,1,1,1,1,1,1,1,1,1,1,1,1,1,1,1,1,1
1,1,1,0,1,1,1,1,1,1,1,1,1,1,1,1,1,1,1,1
1,1,5,1,1,1,1,1,1,1,1,1,1,1,1,1,1,1,1,1
1,1,1,1,1,1,1,1,1,1,1,1,1,1,1,1,4,4,1,1
1,1,1,1,1,1,1,1,1,1,1,1,1,1,1,4,4,4,1,1
1,1,1,1,1,1,1,1,1,1,1,1,1,1,1,4,4,4,1,1
1,1,1,1,1,1,1,1,1,1,1,1,1,1,4,4,4,4,1,1
1,1,1,1,1,1,1,1,1,1,1,1,1,4,4,4,4,4,1,1
1,1,1,1,1,1,1,1,1,1,1,1,1,4,4,4,4,1,1,1
1,1,1,1,1,1,1,1,1,1,1,1,1,1,4,4,4,1,1,1
1,1,1,1,1,1,1,1,1,1,1,1,1,1,1,1,1,1,1,1
1,1,1,1,1,1,1,1,1,1,1,1,1,1,1,1,1,1,1,1
1,1,1,1,1,1,1,1,1,1,1,1,1,1,1,1,1,1,1,1
:endlayer
layer: 6
1,1,1,1,1,1,1,1,1,1,1,1,1,1,1,1,1,1,1,1
1,1,1,1,1,1,1,1,1,1,1,1,1,1,1,1,1,1,1,1
1,1,1,1,1,1,1,1,1,1,1,12,12,12,12,12,1,1,1,1
1,1,1,1,1,1,1,1,1,1,1,1,12,12,12,12,1,1,1,1
1,1,1,1,1,1,1,1,1,1,1,1,1,0,1,1,1,1,1,1
1,1,1,1,1,1,1,1,1,1,1,1,0,0,1,1,1,1,1,1
1,1,1,1,1,1,1,1,1,1,1,1,0,0,1,1,1,1,1,1
1,1,1,1,1,1,1,1,1,1,1,1,0,1,1,1,1,1,1,1
1,1,1,1,1,1,1,1,1,1,1,1,1,1,3,1,1,1,1,1
1,1,1,1,1,1,1,1,1,1,1,1,1,3,3,1,1,1,1,1
1,1,1,1,1,1,1,1,1,1,1,1,1,1,1,1,1,1,1,1
1,1,1,1,1,1,1,1,1,1,1,1,1,1,1,1,1,1,1,1
1,1,1,1,1,1,1,1,1,1,1,1,1,1,1,1,1,1,1,1
1,1,1,1,1,1,1,1,1,1,1,1,1,1,1,1,1,1,1,1
1,1,1,1,1,1,1,1,1,1,1,1,1,1,1,1,1,1,1,1
1,1,1,1,1,1,1,1,1,1,1,1,1,1,1,1,1,1,1,1
1,1,1,1,1,1,1,1,1,1,1,1,1,1,1,1,1,1,1,1
1,1,5,1,1,1,1,1,1,1,1,1,1,1,1,1,1,1,1,1
1,1,1,1,1,1,1,1,1,1,1,1,1,1,1,1,1,1,1,1
1,1,1,1,1,1,1,1,1,1,1,1,1,1,1,1,4,4,1,1
1,1,1,1,1,1,1,1,1,1,1,1,1,1,1,1,4,4,1,1
1,1,1,1,1,1,1,1,1,1,1,1,1,1,1,4,4,4,1,1
1,1,1,1,1,1,1,1,1,1,1,1,1,1,1,4,1,1,1,1
1,1,1,1,1,1,1,1,1,1,1,1,1,1,1,4,1,1,1,1
1,1,1,1,1,1,1,1,1,1,1,1,1,1,1,1,1,1,1,1
1,1,1,1,1,1,1,1,1,1,1,1,1,1,1,1,1,1,1,1
1,1,1,1,1,1,1,1,1,1,1,1,1,1,1,1,1,1,1,1
1,1,1,1,1,1,1,1,1,1,1,1,1,1,1,1,1,1,1,1
:endlayer
layer: 7
1,1,1,1,1,1,1,1,1,1,1,1,1,1,1,1,1,1,1,1
1,1,1,1,1,1,1,1,1,1,1,1,1,1,1,1,1,1,1,1
1,1,3,3,1,1,1,1,1,1,1,1,1,1,1,1,1,1,1,1
1,1,3,3,1,1,1,1,1,1,1,1,1,1,1,1,1,1,1,1
1,1,1,1,1,1,1,1,1,1,1,1,1,1,1,1,1,1,1,1
1,1,1,1,1,1,1,1,1,1,1,1,1,0,1,1,1,1,1,1
1,1,1,1,1,1,1,1,1,1,1,1,0,0,1,1,1,1,1,1
1,1,1,1,1,1,1,1,1,1,1,1,0,1,1,1,1,1,1,1
1,1,1,1,1,1,1,1,1,1,1,1,1,1,3,1,1,1,1,1
1,1,1,1,1,1,1,1,1,1,1,1,1,3,3,1,1,1,1,1
1,1,1,3,1,1,1,1,1,1,1,1,1,1,1,1,1,1,1,1
1,1,1,1,1,1,1,1,1,1,1,1,1,1,1,1,1,1,1,1
1,1,1,1,1,1,1,1,1,1,1,1,1,1,1,1,1,1,1,1
1,1,1,1,1,1,1,1,1,1,1,1,1,1,1,1,1,1,1,1
1,1,1,1,1,1,1,1,1,1,1,1,1,1,1,1,1,1,1,1
1,1,1,1,1,1,1,1,1,1,1,6,6,6,1,1,1,1,1,1
1,1,1,1,1,1,1,1,1,1,1,1,6,6,6,1,1,1,1,1
1,1,1,1,1,1,1,1,1,1,1,1,1,1,1,1,1,1,1,1
1,1,1,1,1,1,1,1,1,1,1,1,1,1,1,1,1,1,1,1
1,1,1,1,1,1,1,1,1,1,1,1,1,1,1,1,1,1,1,1
1,1,1,1,1,1,1,1,1,1,1,1,1,1,1,1,1,1,1,1
1,1,1,1,1,1,1,1,1,1,1,1,1,1,1,1,1,1,1,1
1,1,1,1,1,1,1,1,1,1,1,1,1,1,1,1,1,1,1,1
1,1,1,1,1,1,1,1,1,1,1,1,1,1,1,1,1,1,1,1
1,1,1,1,1,1,1,1,1,1,1,1,1,1,1,1,1,1,1,1
1,1,1,1,1,1,1,1,1,1,1,1,1,1,1,1,1,1,1,1
1,1,1,1,1,1,1,1,1,1,1,1,1,1,1,1,1,1,1,1
1,1,1,1,1,1,1,1,1,1,1,1,1,1,1,1,1,1,1,1
:endlayer
layer: 8
1,1,1,1,1,1,1,1,1,1,1,1,1,1,1,1,1,1,1,1
1,1,1,1,1,1,1,1,1,1,1,1,1,1,1,1,1,1,1,1
1,1,1,1,1,1,1,1,1,1,1,1,1,1,1,1,1,1,1,1
1,1,1,1,1,1,1,1,1,1,1,1,1,1,1,1,1,1,1,1
1,1,1,1,1,1,1,1,1,1,1,1,1,1,1,1,1,1,1,1
1,1,1,1,1,1,1,1,1,1,1,1,1,1,1,1,1,1,1,1
1,1,1,1,1,1,1,1,1,1,1,1,1,1,1,1,1,1,1,1
1,1,1,1,1,1,1,1,1,1,1,1,1,1,1,1,1,1,1,1
1,1,1,1,1,1,1,1,1,1,1,1,1,1,1,1,1,1,1,1
1,1,1,1,1,1,1,1,1,1,1,1,1,1,1,1,1,1,1,1
1,1,1,3,3,1,1,1,1,1,1,1,1,1,1,1,1,1,1,1
1,1,4,4,4,1,1,1,1,1,1,1,1,1,1,1,1,1,1,1
1,1,4,4,4,1,1,1,1,1,1,1,1,1,1,1,1,1,1,1
1,1,4,4,4,1,1,1,1,1,1,1,1,1,1,1,1,1,1,1
1,1,4,4,4,1,1,1,1,1,1,1,1,1,1,1,1,1,1,1
1,1,4,4,4,1,1,1,1,1,1,6,6,6,1,1,1,1,1,1
1,1,4,4,4,1,1,1,1,1,1,1,6,6,6,1,1,1,1,1
1,1,4,4,4,1,1,1,1,1,1,1,1,1,1,1,1,1,1,1
1,1,4,4,4,1,1,0,0,1,1,1,1,1,1,1,1,1,1,1
1,1,4,4,4,1,1,0,0,1,1,1,1,1,1,1,1,1,1,1
1,1,4,4,4,1,1,1,1,1,1,1,1,1,1,1,1,1,1,1
1,1,4,4,4,1,1,1,1,1,1,1,1,1,1,1,1,1,1,1
1,1,4,4,4,1,1,1,1,1,1,1,1,1,1,1,1,1,1,1
1,1,4,4,4,1,1,1,1,1,1,1,1,1,1,1,1,1,1,1
1,1,4,4,4,1,1,1,1,1,1,1,1,1,1,1,1,1,1,1
1,1,1,1,1,1,1,1,1,1,1,1,1,1,1,1,1,1,1,1
1,1,1,1,1,1,1,1,1,1,1,1,1,1,1,1,1,1,1,1
1,1,1,1,1,1,1,1,1,1,1,1,1,1,1,1,1,1,1,1
:endlayer
layer: 9
4,4,4,4,4,4,4,4,4,4,4,4,4,4,4,4,4,4,4,4
4,4,4,4,4,4,4,4,4,4,4,4,4,4,4,4,4,4,4,4
4,4,4,4,4,4,4,4,4,4,4,4,4,4,4,4,4,4,4,4
4,4,4,4,4,4,4,4,4,4,4,4,4,4,4,4,4,4,4,4
4,4,4,4,4,4,4,4,4,4,4,4,4,4,4,4,4,4,4,4
4,4,4,4,4,4,4,4,4,4,4,4,4,4,4,4,4,4,4,4
4,4,4,4,4,4,4,4,4,4,4,4,4,4,4,4,4,4,4,4
4,4,4,4,4,4,4,4,4,4,4,4,4,4,4,4,4,4,4,4
4,4,4,4,4,4,4,4,4,4,4,4,4,4,4,4,4,4,4,4
4,4,4,4,4,4,4,4,4,4,4,4,4,4,4,4,4,4,4,4
4,4,4,4,4,4,4,4,4,4,4,4,4,4,4,4,4,4,4,4
4,4,4,4,4,4,4,4,4,4,4,4,4,4,4,4,4,4,4,4
4,4,4,4,4,4,4,4,4,4,4,4,4,4,4,4,4,4,4,4
4,4,4,4,4,4,4,4,4,4,4,4,4,4,4,4,4,4,4,4
4,4,4,4,4,4,4,4,4,4,4,4,4,4,4,4,4,4,4,4
4,4,4,4,4,4,4,4,4,4,4,4,4,4,4,4,4,4,4,4
4,4,4,4,4,4,4,4,4,4,4,4,4,4,4,4,4,4,4,4
4,4,4,4,4,4,4,4,4,4,4,4,4,4,4,4,4,4,4,4
4,4,4,4,4,4,4,4,4,4,4,4,4,4,4,4,4,4,4,4
4,4,4,4,4,4,4,4,4,4,4,4,4,4,4,4,4,4,4,4
4,4,4,4,4,4,4,4,4,4,4,4,4,4,4,4,4,4,4,4
4,4,4,4,4,4,4,4,4,4,4,4,4,4,4,4,4,4,4,4
4,4,4,4,4,4,4,4,4,4,4,4,4,4,4,4,4,4,4,4
4,4,4,4,4,4,4,4,4,4,4,4,4,4,4,4,4,4,4,4
4,4,4,4,4,4,4,4,4,4,4,4,4,4,4,4,4,4,4,4
4,4,4,4,4,4,4,4,4,4,4,4,4,4,4,4,4,4,4,4
4,4,4,4,4,4,4,4,4,4,4,4,4,4,4,4,4,4,4,4
4,4,4,4,4,4,4,4,4,4,4,4,4,4,4,4,4,4,4,4
:endlayer
layer: 10
4,4,4,4,4,4,4,4,4,4,4,4,4,4,4,4,4,4,4,4
4,4,4,4,4,4,4,4,4,4,4,4,4,4,4,4,4,4,4,4
4,4,4,4,4,4,4,4,4,4,4,4,4,4,4,4,4,4,4,4
4,4,4,4,4,4,4,4,4,4,4,4,4,4,4,4,4,4,4,4
4,4,4,4,4,4,4,4,4,4,4,4,4,4,4,4,4,4,4,4
4,4,4,4,4,4,4,4,4,4,4,4,4,4,4,4,4,4,4,4
4,4,4,4,4,4,4,4,4,4,4,4,4,4,4,4,4,4,4,4
4,4,4,4,4,4,4,4,4,4,4,4,4,4,4,4,4,4,4,4
4,4,4,4,4,4,4,4,4,4,4,4,4,4,4,4,4,4,4,4
4,4,4,4,4,4,4,4,4,4,4,4,4,4,4,4,4,4,4,4
4,4,4,4,4,4,4,4,4,4,4,4,4,4,4,4,4,4,4,4
4,4,4,4,4,4,4,4,4,4,4,4,4,4,4,4,4,4,4,4
4,4,4,4,4,4,4,4,4,4,4,4,4,4,4,4,4,4,4,4
4,4,4,4,4,4,4,4,4,4,4,4,4,4,4,4,4,4,4,4
4,4,4,4,4,4,4,4,4,4,4,4,4,4,4,4,4,4,4,4
4,4,4,4,4,4,4,4,4,4,4,4,4,4,4,4,4,4,4,4
4,4,4,4,4,4,4,4,4,4,4,4,4,4,4,4,4,4,4,4
4,4,4,4,4,4,4,4,4,4,4,4,4,4,4,4,4,4,4,4
4,4,4,4,4,4,4,4,4,4,4,4,4,4,4,4,4,4,4,4
4,4,4,4,4,4,4,4,4,4,4,4,4,4,4,4,4,4,4,4
4,4,4,4,4,4,4,4,4,4,4,4,4,4,4,4,4,4,4,4
4,4,4,4,4,4,4,4,4,4,4,4,4,4,4,4,4,4,4,4
4,4,4,4,4,4,4,4,4,4,4,4,4,4,4,4,4,4,4,4
4,4,4,4,4,4,4,4,4,4,4,4,4,4,4,4,4,4,4,4
4,4,4,4,4,4,4,4,4,4,4,4,4,4,4,4,4,4,4,4
4,4,4,4,4,4,4,4,4,4,4,4,4,4,4,4,4,4,4,4
4,4,4,4,4,4,4,4,4,4,4,4,4,4,4,4,4,4,4,4
4,4,4,4,4,4,4,4,4,4,4,4,4,4,4,4,4,4,4,4
:endlayer
layer: 11
4,4,4,4,4,4,4,4,4,4,4,4,4,4,4,4,4,4,4,4
4,4,4,4,4,4,4,4,4,4,4,4,4,4,4,4,4,4,4,4
4,4,4,4,4,4,4,4,4,4,4,4,4,4,4,4,4,4,4,4
4,4,4,4,4,4,4,4,4,4,4,4,4,4,4,4,4,4,4,4
4,4,4,4,4,4,4,4,4,4,4,4,4,4,4,4,4,4,4,4
4,4,4,4,4,4,4,4,4,4,4,4,4,4,4,4,4,4,4,4
4,4,4,4,4,4,4,4,4,4,4,4,4,4,4,4,4,4,4,4
4,4,4,4,4,4,4,4,4,4,4,4,4,4,4,4,4,4,4,4
4,4,4,4,4,4,4,4,4,4,4,4,4,4,4,4,4,4,4,4
4,4,4,4,4,4,4,4,4,4,4,4,4,4,4,4,4,4,4,4
4,4,4,4,4,4,4,4,4,4,4,4,4,4,4,4,4,4,4,4
4,4,4,4,4,4,4,4,4,4,4,4,4,4,4,4,4,4,4,4
4,4,4,4,4,4,4,4,4,4,4,4,4,4,4,4,4,4,4,4
4,4,4,4,4,4,4,4,4,4,4,4,4,4,4,4,4,4,4,4
4,4,4,4,4,4,4,4,4,4,4,4,4,4,4,4,4,4,4,4
4,4,4,4,4,4,4,4,4,4,4,4,4,4,4,4,4,4,4,4
4,4,4,4,4,4,4,4,4,4,4,4,4,4,4,4,4,4,4,4
4,4,4,4,4,4,4,4,4,4,4,4,4,4,4,4,4,4,4,4
4,4,4,4,4,4,4,4,4,4,4,4,4,4,4,4,4,4,4,4
4,4,4,4,4,4,4,4,4,4,4,4,4,4,4,4,4,4,4,4
4,4,4,4,4,4,4,4,4,4,4,4,4,4,4,4,4,4,4,4
4,4,4,4,4,4,4,4,4,4,4,4,4,4,4,4,4,4,4,4
4,4,4,4,4,4,4,4,4,4,4,4,4,4,4,4,4,4,4,4
4,4,4,4,4,4,4,4,4,4,4,4,4,4,4,4,4,4,4,4
4,4,4,4,4,4,4,4,4,4,4,4,4,4,4,4,4,4,4,4
4,4,4,4,4,4,4,4,4,4,4,4,4,4,4,4,4,4,4,4
4,4,4,4,4,4,4,4,4,4,4,4,4,4,4,4,4,4,4,4
4,4,4,4,4,4,4,4,4,4,4,4,4,4,4,4,4,4,4,4
:endlayer
layer: 12
14,14,14,14,14,14,14,14,14,14,14,14,14,14,14,14,14,14,14,14
14,14,14,14,14,14,14,14,14,14,14,14,14,14,14,14,14,14,14,14
14,14,14,14,14,14,14,14,14,14,14,14,14,14,14,14,14,14,14,14
14,14,14,14,14,14,14,14,14,14,14,14,14,14,14,14,14,14,14,14
14,14,14,14,4,4,4,4,4,4,4,4,14,14,14,14,14,14,14,14
14,14,14,4,4,4,4,4,4,4,4,4,4,4,14,14,14,14,14,14
14,14,4,4,4,4,4,4,4,4,4,4,4,4,14,14,14,14,14,14
14,14,4,4,4,4,4,4,4,4,4,4,4,4,14,14,14,14,14,14
14,14,4,4,4,4,4,4,4,4,4,4,4,4,14,14,14,14,14,14
14,14,4,4,4,4,4,4,4,4,4,4,4,4,4,14,14,14,14,14
14,14,4,4,4,4,4,4,4,4,4,4,4,4,4,14,4,4,4,14
14,14,4,4,4,4,4,4,4,4,4,4,4,4,4,4,4,4,4,14
14,14,4,4,4,4,4,4,4,4,4,4,4,4,4,4,4,4,4,14
14,14,4,4,4,4,4,4,4,4,4,4,4,4,4,4,4,4,14,14
14,14,14,4,4,4,4,4,4,4,4,4,4,4,4,4,4,4,14,14
14,14,14,4,4,4,4,4,4,4,4,4,4,4,4,4,4,4,14,14
14,14,14,4,4,4,4,4,4,4,4,4,4,4,4,4,4,4,14,14
14,14,14,4,4,4,4,4,4,4,4,4,4,4,4,4,4,14,14,14
14,14,14,14,4,4,4,4,4,4,4,4,4,4,4,4,4,14,14,14
14,14,14,14,14,14,4,4,4,4,4,4,4,4,4,14,14,14,14,14
14,14,14,14,14,14,14,14,4,4,4,4,4,4,14,14,14,14,14,14
14,14,14,14,14,14,14,14,14,14,4,4,4,14,14,14,14,14,14,14
14,14,14,14,14,14,14,14,14,14,14,14,14,14,14,14,14,14,14,14
14,14,14,14,14,14,14,14,14,14,14,14,14,14,14,14,14,14,14,14
14,14,14,14,14,14,14,14,14,14,14,14,14,14,14,14,14,14,14,14
14,14,14,14,14,14,14,14,14,14,14,14,14,14,14,14,14,14,14,14
14,14,14,14,14,14,14,14,14,14,14,14,14,14,14,14,14,14,14,14
14,14,14,14,14,14,14,14,14,14,14,14,14,14,14,14,14,14,14,14
:endlayer
layer: 13
15,16,15,0,0,0,0,0,0,0,0,0,0,0,0,15,15,15,0,0
15,15,15,15,0,0,0,0,0,0,0,0,15,15,15,0,17,15,18,0
15,15,17,15,0,19,0,0,0,0,0,0,0,15,15,15,15,19,0,15
0,0,0,0,0,0,0,0,0,0,0,0,0,0,0,15,0,15,0,0
0,0,15,0,14,14,14,14,14,14,14,14,0,15,0,0,15,15,0,0
0,0,0,14,14,4,4,4,4,4,4,4,4,4,0,0,0,0,0,0
0,0,14,4,4,4,4,1,1,1,1,1,4,4,0,0,0,0,0,0
0,0,14,4,4,4,1,4,1,1,1,1,1,4,0,0,0,0,0,0
0,0,14,4,4,1,1,1,1,1,1,1,1,1,0,0,0,0,15,0
0,0,14,4,1,1,1,1,1,1,1,1,1,1,1,0,0,0,0,0
15,15,14,14,1,1,1,1,1,1,1,1,1,1,1,0,4,4,14,0
15,15,14,14,1,1,1,1,1,1,1,1,1,1,1,1,4,4,14,0
15,15,14,14,1,1,1,1,1,1,1,1,1,1,1,1,4,4,14,20
20,15,14,14,1,1,1,1,1,1,1,1,1,1,1,1,4,4,15,15
15,0,0,14,14,1,1,1,1,1,1,1,1,1,1,1,4,14,0,15
0,0,0,14,14,4,1,1,1,1,1,1,1,1,1,4,4,14,20,0
0,0,0,14,14,14,14,1,1,1,1,1,1,1,4,4,4,14,0,0
0,0,0,14,14,14,14,14,14,14,14,1,4,4,4,4,14,0,0,0
0,0,0,0,14,14,14,14,14,14,14,14,4,4,4,14,14,0,0,0
0,0,0,0,0,0,14,14,14,14,14,4,4,4,14,0,0,0,0,0
0,0,0,0,0,0,0,0,14,14,14,4,4,14,0,0,0,0,0,0
0,0,0,0,0,0,0,0,0,0,14,14,14,0,0,0,15,0,0,0
0,0,0,0,0,0,0,0,0,0,0,0,0,0,0,0,0,0,0,0
0,15,0,0,0,0,0,0,0,0,0,0,0,0,0,0,15,0,0,0
21,15,0,15,0,15,0,0,0,0,0,0,0,0,0,0,0,15,15,0
0,15,15,0,0,0,0,0,0,0,0,0,0,0,0,15,0,15,15,15
21,15,15,15,15,15,0,0,0,0,0,0,0,0,15,0,15,15,15,15
0,16,15,15,15,15,0,0,0,0,0,0,0,0,0,0,15,15,0,15
:endlayer
layer: 14
0,0,0,0,0,0,0,0,0,0,0,0,0,0,0,0,0,0,0,0
0,0,0,0,0,0,0,0,0,0,0,0,0,0,0,0,0,0,0,0
0,0,0,0,0,0,0,0,0,0,0,0,0,0,0,0,0,0,0,0
0,0,0,0,0,0,0,0,0,0,0,0,0,0,0,0,0,0,0,0
0,0,0,0,0,0,0,0,0,0,0,0,0,0,0,0,0,0,0,0
0,0,0,0,0,14,14,4,4,4,4,4,14,14,0,0,0,0,0,0
0,0,0,14,4,4,4,1,1,1,1,1,4,4,0,0,0,0,0,0
0,0,0,4,4,4,1,1,1,1,1,1,1,4,0,0,0,0,0,0
0,0,0,4,4,1,4,1,1,1,1,1,1,1,0,0,0,0,0,0
0,0,0,4,1,4,1,1,1,1,1,1,1,1,14,0,0,0,0,0
0,0,0,0,1,1,1,1,1,1,1,1,1,1,1,0,4,14,0,0
0,0,0,0,1,1,1,1,1,1,1,1,1,1,1,1,4,14,0,0
0,0,0,0,1,1,1,1,1,1,1,1,1,1,1,1,4,14,0,0
0,0,0,0,14,1,1,1,1,1,1,1,1,1,1,1,4,14,22,0
0,0,0,0,0,14,1,1,1,1,1,1,1,1,1,0,4,23,0,0
0,0,0,0,0,24,1,1,1,1,1,1,1,1,1,4,14,0,0,0
0,0,0,0,0,0,0,14,1,1,1,1,1,1,4,4,14,0,0,0
0,0,0,0,0,0,0,0,0,0,0,1,1,4,4,14,0,0,0,0
0,0,0,0,0,0,0,0,0,0,0,0,4,4,14,0,0,0,0,0
0,0,0,0,0,0,0,0,0,0,25,14,4,14,0,0,0,0,0,0
0,0,0,0,0,0,0,0,0,0,26,14,14,0,0,0,0,0,0,0
0,0,0,0,0,0,0,0,0,0,0,27,0,0,0,0,0,0,0,0
0,0,0,0,0,0,0,0,0,0,0,0,0,0,0,0,0,0,0,0
0,0,0,0,0,0,0,0,0,0,0,0,0,0,0,0,0,0,0,0
0,0,0,0,0,0,0,0,0,0,0,0,0,0,0,0,0,0,0,0
0,0,0,0,0,0,0,0,0,0,0,0,0,0,0,0,0,0,0,0
0,0,0,0,0,0,0,0,0,0,0,0,0,0,0,0,0,0,0,0
0,0,0,0,0,0,0,0,0,0,0,0,0,0,0,0,0,0,0,0
:endlayer
layer: 15
0,0,0,0,0,0,0,0,0,0,0,0,0,0,0,0,0,0,0,0
0,0,0,0,0,0,0,0,0,0,0,0,0,0,0,0,0,0,0,0
0,0,0,0,0,0,0,0,0,0,0,0,0,0,0,0,0,0,0,0
0,0,0,0,0,0,0,0,0,0,0,0,0,0,0,0,0,0,0,0
0,0,0,0,0,0,0,0,0,0,0,0,0,0,0,0,0,0,0,0
0,0,0,0,0,0,0,14,14,14,14,14,0,0,0,0,0,0,0,0
0,0,0,0,14,4,4,1,1,1,1,1,4,14,0,0,0,0,0,0
0,0,0,4,4,4,1,1,1,1,1,1,14,4,0,0,0,0,0,0
0,0,0,4,4,1,1,1,1,1,1,1,1,1,0,0,0,0,0,0
0,0,0,4,1,1,1,1,1,1,1,1,1,1,0,0,0,0,0,0
0,0,0,0,1,1,1,1,1,1,1,1,1,1,1,1,4,0,0,0
0,0,0,0,14,1,1,1,1,1,1,1,1,1,1,1,4,0,0,0
0,0,0,0,14,1,1,1,1,1,1,1,1,1,1,1,4,22,0,0
0,0,0,0,0,1,1,1,1,1,1,1,1,1,1,1,4,22,0,0
0,0,0,0,0,0,1,1,1,1,1,1,1,1,1,0,14,22,0,0
0,0,0,0,0,24,1,1,1,1,1,1,1,1,1,4,0,0,0,0
0,0,0,0,0,0,0,0,1,1,1,1,1,1,4,14,0,0,0,0
0,0,0,0,0,0,0,0,0,1,1,1,14,4,4,0,0,0,0,0
0,0,0,0,0,0,0,0,0,0,0,0,4,14,0,0,0,0,0,0
0,0,0,0,0,0,0,0,0,0,27,27,14,0,0,0,0,0,0,0
0,0,0,0,0,0,0,0,0,0,0,0,0,0,0,0,0,0,0,0
0,0,0,0,0,0,0,0,0,0,0,0,0,0,0,0,0,0,0,0
0,0,0,0,0,0,0,0,0,0,0,0,0,0,0,0,0,0,0,0
0,0,0,0,0,0,0,0,0,0,0,0,0,0,0,0,0,0,0,0
0,0,0,0,0,0,0,0,0,0,0,0,0,0,0,0,0,0,0,0
0,0,0,0,0,0,0,0,0,0,0,0,0,0,0,0,0,0,0,0
0,0,0,0,0,0,0,0,0,0,0,0,0,0,0,0,0,0,0,0
0,0,0,0,0,0,0,0,0,0,0,0,0,0,0,0,0,0,0,0
:endlayer
layer: 16
0,0,0,0,0,0,0,0,0,0,0,0,0,0,0,0,0,0,0,0
0,0,0,0,0,0,0,0,0,0,0,0,0,0,0,0,0,0,0,0
0,0,0,0,0,0,0,0,0,0,0,0,0,0,0,0,0,0,0,0
0,0,0,0,0,0,0,0,0,0,0,0,0,0,0,0,0,0,0,0
0,0,0,0,0,0,0,0,0,0,0,0,0,0,0,0,0,0,0,0
0,0,0,0,0,0,0,28,28,28,28,0,0,0,0,0,0,0,0,0
0,0,0,0,0,14,4,1,1,1,1,1,14,0,0,0,0,0,0,0
0,0,0,14,4,4,1,1,4,1,4,1,0,4,0,0,0,0,0,0
0,0,0,4,4,1,1,1,1,1,1,1,1,1,0,0,0,0,0,0
0,0,0,4,1,1,1,1,1,1,1,1,1,1,1,0,0,0,0,0
0,0,0,0,1,1,1,1,1,1,1,1,1,1,1,1,14,0,0,0
0,0,0,0,0,1,1,1,1,1,1,1,1,1,1,1,14,0,0,0
0,0,0,0,0,1,1,1,1,1,1,1,1,1,1,1,14,22,0,0
0,0,0,0,0,1,1,1,1,1,1,1,1,1,1,1,14,22,0,0
0,0,0,0,0,1,1,1,1,1,1,1,1,1,1,1,29,0,0,0
0,0,0,0,0,24,1,1,1,1,1,1,1,1,14,14,0,0,0,0
0,0,0,0,0,0,0,1,1,1,1,1,1,1,4,0,0,0,0,0
0,0,0,0,0,0,0,0,1,1,1,1,0,14,14,0,0,0,0,0
0,0,0,0,0,0,0,0,0,0,0,0,4,0,0,0,0,0,0,0
0,0,0,0,0,0,0,0,0,0,27,27,0,0,0,0,0,0,0,0
0,0,0,0,0,0,0,0,0,0,0,0,0,0,0,0,0,0,0,0
0,0,0,0,0,0,0,0,0,0,0,0,0,0,0,0,0,0,0,0
0,0,0,0,0,0,0,0,0,0,0,0,0,0,0,0,0,0,0,0
0,0,0,0,0,0,0,0,0,0,0,0,0,0,0,0,0,0,0,0
0,0,0,0,0,0,0,0,0,0,0,0,0,0,0,0,0,0,0,0
0,0,0,0,0,0,0,0,0,0,0,0,0,0,0,0,0,0,0,0
0,0,0,0,0,0,0,0,0,0,0,0,0,0,0,0,0,0,0,0
0,0,0,0,0,0,0,0,0,0,0,0,0,0,0,0,0,0,0,0
:endlayer
layer: 17
0,0,0,0,0,0,0,0,0,0,0,0,0,0,0,0,0,0,0,0
0,0,0,0,0,0,0,0,0,0,0,0,0,0,0,0,0,0,0,0
0,0,0,0,0,0,0,0,0,0,0,0,0,0,0,0,0,0,0,0
0,0,0,0,0,0,0,0,0,0,0,0,0,0,0,0,0,0,0,0
0,0,0,0,0,0,0,0,0,0,0,0,0,0,0,0,0,0,0,0
0,0,0,0,0,0,0,28,28,28,28,0,0,0,0,0,0,0,0,0
0,0,0,0,0,0,14,14,1,1,14,14,0,0,0,0,0,0,0,0
0,0,0,0,14,4,1,1,1,1,1,1,1,4,0,0,0,0,0,0
0,0,0,4,4,1,1,4,1,1,1,1,1,1,0,0,0,0,0,0
0,0,0,4,1,1,1,1,1,1,1,1,1,1,1,0,0,0,0,0
0,0,0,0,1,1,1,1,1,1,1,1,1,1,1,1,0,0,0,0
0,0,0,0,0,1,1,1,1,1,1,1,1,1,1,1,0,0,0,0
0,0,0,0,0,1,1,1,1,1,1,1,1,1,1,1,22,0,0,0
0,0,0,0,30,1,1,1,1,1,1,1,1,1,1,1,22,0,0,0
0,0,0,30,30,1,1,1,1,1,1,1,1,1,1,1,31,0,0,0
0,0,0,30,30,24,1,1,1,1,1,1,1,1,0,0,0,0,0,0
0,0,0,0,30,30,30,1,1,1,1,1,1,1,14,0,0,0,0,0
0,0,0,0,30,30,30,30,1,1,1,1,1,0,0,0,0,0,0,0
0,0,0,0,0,0,0,0,0,0,0,0,14,0,0,0,0,0,0,0
0,0,0,0,0,0,0,0,0,0,27,27,0,0,0,0,0,0,0,0
0,0,0,0,0,0,0,0,0,0,0,0,0,0,0,0,0,0,0,0
0,0,0,0,0,0,0,0,0,0,0,0,0,0,0,0,0,0,0,0
0,0,0,0,0,0,0,0,0,0,0,0,0,0,0,0,0,0,0,0
0,0,0,0,0,0,0,0,0,0,0,0,0,0,0,0,0,0,0,0
0,0,0,0,0,0,0,0,0,0,0,0,0,0,0,0,0,0,0,0
0,0,0,0,0,0,0,0,0,0,0,0,0,0,0,0,0,0,0,0
0,0,0,0,0,0,0,0,0,0,0,0,0,0,0,0,0,0,0,0
0,0,0,0,0,0,0,0,0,0,0,0,0,0,0,0,0,0,0,0
:endlayer
layer: 18
0,0,0,0,0,0,0,0,0,0,0,0,0,0,0,0,0,0,0,0
0,0,0,0,0,0,0,0,0,0,0,0,0,0,0,0,0,0,0,0
0,0,0,0,0,0,0,0,0,0,0,0,0,0,0,0,0,0,0,0
0,0,0,0,0,0,0,0,0,0,0,0,0,0,0,0,0,0,0,0
0,0,0,0,0,0,0,0,0,0,0,0,0,0,0,0,0,0,0,0
0,0,0,0,0,0,0,28,28,28,28,0,0,0,0,0,0,0,0,0
0,0,0,0,0,0,0,0,14,14,0,0,0,0,0,0,0,0,0,0
0,0,0,0,0,14,1,1,1,1,1,1,14,14,0,0,0,0,0,0
0,0,0,14,4,1,1,1,1,1,1,1,1,1,0,0,0,0,0,0
0,0,0,4,1,1,1,1,1,1,1,1,1,1,1,0,0,0,0,0
0,0,0,0,1,4,1,1,1,1,1,1,1,1,1,1,0,0,0,0
0,0,0,0,0,1,1,1,1,1,1,1,1,1,1,1,0,0,0,0
0,0,0,0,0,1,1,1,1,1,1,1,1,1,1,1,22,0,0,0
0,0,0,30,30,1,1,1,1,1,1,1,1,1,1,14,22,0,0,0
0,0,0,30,30,1,1,1,1,1,1,1,1,1,1,14,31,0,0,0
0,0,0,30,30,24,1,1,1,1,1,1,1,1,1,0,0,0,0,0
0,0,0,30,30,30,30,1,1,1,1,1,1,1,0,0,0,0,0,0
0,0,0,0,30,30,30,0,1,1,1,1,1,0,0,0,0,0,0,0
0,0,0,0,0,0,0,0,0,0,0,14,0,0,0,0,0,0,0,0
0,0,0,0,0,0,0,0,0,0,27,27,0,0,0,0,0,0,0,0
0,0,0,0,0,0,0,0,0,0,0,0,0,0,0,0,0,0,0,0
0,0,0,0,0,0,0,0,0,0,0,0,0,0,0,0,0,0,0,0
0,0,0,0,0,0,0,0,0,0,0,0,0,0,0,0,0,0,0,0
0,0,0,0,0,0,0,0,0,0,0,0,0,0,0,0,0,0,0,0
0,0,0,0,0,0,0,0,0,0,0,0,0,0,0,0,0,0,0,0
0,0,0,0,0,0,0,0,0,0,0,0,0,0,0,0,0,0,0,0
0,0,0,0,0,0,0,0,0,0,0,0,0,0,0,0,0,0,0,0
0,0,0,0,0,0,0,0,0,0,0,0,0,0,0,0,0,0,0,0
:endlayer
layer: 19
0,0,0,0,0,0,0,0,0,0,0,0,0,0,0,0,0,0,0,0
0,0,0,0,0,0,0,0,0,0,0,0,0,0,0,0,0,0,0,0
0,0,0,0,0,0,0,0,0,0,0,0,0,0,0,0,0,0,0,0
0,0,0,0,0,0,0,0,0,0,0,0,0,0,0,0,0,0,0,0
0,0,0,0,0,0,0,0,0,0,0,0,0,0,0,0,0,0,0,0
0,0,0,0,0,0,0,28,28,28,28,0,0,0,0,0,0,0,0,0
0,0,0,0,0,0,0,0,0,0,0,0,0,0,0,0,0,0,0,0
0,0,0,0,0,0,1,1,1,1,1,14,0,0,0,0,0,0,0,0
0,0,0,0,14,1,1,1,1,1,1,14,1,1,0,0,0,0,0,0
0,0,0,4,1,1,1,1,1,1,1,1,1,1,1,0,0,0,0,0
0,0,0,0,1,1,1,1,1,1,1,1,1,1,1,14,0,0,0,0
0,0,0,0,1,1,1,1,1,1,1,1,1,1,1,14,0,0,0,0
0,0,0,0,0,1,1,1,1,1,1,1,1,1,1,14,22,0,0,0
0,0,0,0,0,1,1,1,1,1,1,1,1,1,1,0,22,0,0,0
0,0,0,0,30,1,1,1,1,1,1,1,1,1,1,23,31,0,0,0
0,0,0,0,30,1,1,1,1,1,1,1,1,1,14,0,0,0,0,0
0,0,0,0,30,30,1,1,1,1,1,1,1,14,0,0,0,0,0,0
0,0,0,0,0,0,0,1,1,1,1,1,14,0,0,0,0,0,0,0
0,0,0,0,0,0,0,0,0,0,0,22,0,0,0,0,0,0,0,0
0,0,0,0,0,0,0,0,0,0,27,27,0,0,0,0,0,0,0,0
0,0,0,0,0,0,0,0,0,0,0,0,0,0,0,0,0,0,0,0
0,0,0,0,0,0,0,0,0,0,0,0,0,0,0,0,0,0,0,0
0,0,0,0,0,0,0,0,0,0,0,0,0,0,0,0,0,0,0,0
0,0,0,0,0,0,0,0,0,0,0,0,0,0,0,0,0,0,0,0
0,0,0,0,0,0,0,0,0,0,0,0,0,0,0,0,0,0,0,0
0,0,0,0,0,0,0,0,0,0,0,0,0,0,0,0,0,0,0,0
0,0,0,0,0,0,0,0,0,0,0,0,0,0,0,0,0,0,0,0
0,0,0,0,0,0,0,0,0,0,0,0,0,0,0,0,0,0,0,0
:endlayer
layer: 20
0,0,0,0,0,0,0,0,0,0,0,0,0,0,0,0,0,0,0,0
0,0,0,0,0,0,0,0,0,0,0,0,0,0,0,0,0,0,0,0
0,0,0,0,0,0,0,0,0,0,0,0,0,0,0,0,0,0,0,0
0,0,0,0,0,0,0,0,0,0,0,0,0,0,0,0,0,0,0,0
0,0,0,0,0,0,0,0,0,0,0,0,0,0,0,0,0,0,0,0
0,0,0,0,0,0,0,28,28,28,28,0,0,0,0,0,0,0,0,0
0,0,0,0,0,0,0,0,0,0,0,0,0,0,0,0,0,0,0,0
0,0,0,0,0,0,14,1,1,1,1,0,0,0,0,0,0,0,0,0
0,0,0,0,15,1,1,1,1,1,1,0,1,14,0,0,0,0,0,0
0,0,0,14,1,1,1,1,1,1,1,1,1,1,14,0,0,0,0,0
0,0,0,0,1,1,1,1,1,1,1,1,1,1,1,0,0,0,0,0
0,0,0,0,1,1,1,1,1,1,1,1,1,1,1,0,0,0,0,0
0,0,0,0,1,1,1,1,1,1,1,1,1,1,1,0,22,0,0,0
0,0,0,0,1,1,1,1,1,1,1,1,1,1,1,0,22,0,0,0
0,0,0,0,0,1,1,1,1,1,1,1,1,1,14,23,31,0,0,0
0,0,0,0,30,1,1,1,1,1,1,1,1,1,0,0,0,0,0,0
0,0,0,0,0,1,1,1,1,1,1,1,1,0,0,0,0,0,0,0
0,0,0,0,0,0,1,1,1,1,1,14,0,0,0,0,0,0,0,0
0,0,0,0,0,0,0,0,1,1,1,22,0,0,0,0,0,0,0,0
0,0,0,0,0,0,0,0,0,0,27,27,0,0,0,0,0,0,0,0
0,0,0,0,0,0,0,0,0,0,0,0,0,0,0,0,0,0,0,0
0,0,0,0,0,0,0,0,0,0,0,0,0,0,0,0,0,0,0,0
0,0,0,0,0,0,0,0,0,0,0,0,0,0,0,0,0,0,0,0
0,0,0,0,0,0,0,0,0,0,0,0,0,0,0,0,0,0,0,0
0,0,0,0,0,0,0,0,0,0,0,0,0,0,0,0,0,0,0,0
0,0,0,0,0,0,0,0,0,0,0,0,0,0,0,0,0,0,0,0
0,0,0,0,0,0,0,0,0,0,0,0,0,0,0,0,0,0,0,0
0,0,0,0,0,0,0,0,0,0,0,0,0,0,0,0,0,0,0,0
:endlayer
layer: 21
0,0,0,0,0,0,0,0,0,0,0,0,0,0,0,0,0,0,0,0
0,0,0,0,0,0,0,0,0,0,0,0,0,0,0,0,0,0,0,0
0,0,0,0,0,0,0,0,0,0,0,0,0,0,0,0,0,0,0,0
0,0,0,0,0,0,0,0,0,0,0,0,0,0,0,0,0,0,0,0
0,0,0,0,0,0,0,0,0,0,0,0,0,0,0,0,0,0,0,0
0,0,0,0,0,0,0,28,28,28,28,0,0,0,0,0,0,0,0,0
0,0,0,0,0,0,0,0,0,0,0,0,0,0,0,0,0,0,0,0
0,0,0,0,0,0,15,14,1,1,14,0,0,0,0,0,0,0,0,0
0,0,0,0,0,14,1,1,1,1,1,1,14,0,0,0,0,0,0,0
0,0,0,15,1,1,1,1,1,1,1,1,1,1,0,0,0,0,0,0
0,0,0,0,1,1,1,1,1,1,1,1,1,1,14,0,0,0,0,0
0,0,0,0,1,1,1,1,1,1,1,1,1,1,1,0,0,0,0,0
0,0,0,0,1,1,1,1,1,1,1,1,1,1,14,0,22,0,0,0
0,0,0,0,1,1,1,1,1,1,1,1,1,1,14,0,22,0,0,0
0,0,0,0,0,1,1,1,1,1,1,1,1,1,0,23,31,0,0,0
0,0,0,0,0,1,1,1,1,1,1,1,1,14,27,0,0,0,0,0
0,0,0,0,0,1,1,1,1,1,1,1,0,0,0,0,0,0,0,0
0,0,0,0,0,0,1,1,1,1,1,0,0,0,0,0,0,0,0,0
0,0,0,0,0,0,0,1,1,1,1,22,0,0,0,0,0,0,0,0
0,0,0,0,0,0,0,0,0,0,27,27,0,0,0,0,0,0,0,0
0,0,0,0,0,0,0,0,0,0,0,0,0,0,0,0,0,0,0,0
0,0,0,0,0,0,0,0,0,0,0,0,0,0,0,0,0,0,0,0
0,0,0,0,0,0,0,0,0,0,0,0,0,0,0,0,0,0,0,0
0,0,0,0,0,0,0,0,0,0,0,0,0,0,0,0,0,0,0,0
0,0,0,0,0,0,0,0,0,0,0,0,0,0,0,0,0,0,0,0
0,0,0,0,0,0,0,0,0,0,0,0,0,0,0,0,0,0,0,0
0,0,0,0,0,0,0,0,0,0,0,0,0,0,0,0,0,0,0,0
0,0,0,0,0,0,0,0,0,0,0,0,0,0,0,0,0,0,0,0
:endlayer
layer: 22
0,0,0,0,0,0,0,0,0,0,0,0,0,0,0,0,0,0,0,0
0,0,0,0,0,0,0,0,0,0,0,0,0,0,0,0,0,0,0,0
0,0,0,0,0,0,0,0,0,0,0,0,0,0,0,0,0,0,0,0
0,0,0,0,0,0,0,0,0,0,0,0,0,0,0,0,0,0,0,0
0,0,0,0,0,0,0,0,0,0,0,0,0,0,0,0,0,0,0,0
0,0,0,0,0,0,0,28,28,28,28,0,0,0,0,0,0,0,0,0
0,0,0,0,0,0,0,0,0,0,0,0,0,0,0,0,0,0,0,0
0,0,0,0,0,0,0,15,14,14,15,0,0,0,0,0,0,0,0,0
0,0,0,0,0,15,1,1,1,1,1,1,20,0,0,0,0,0,0,0
0,0,0,0,14,1,1,1,1,1,1,1,1,14,0,0,0,0,0,0
0,0,0,0,1,1,1,1,1,1,1,1,1,14,15,0,0,0,0,0
0,0,0,0,1,1,1,1,1,1,1,1,1,1,14,0,0,0,0,0
0,0,0,0,1,1,1,1,1,1,1,1,1,1,15,0,22,0,0,0
0,0,0,0,1,1,1,1,1,1,1,1,1,1,0,0,22,0,0,0
0,0,0,0,1,1,1,1,1,1,1,1,1,1,0,23,31,0,0,0
0,0,0,0,0,1,1,1,1,1,1,1,1,15,27,0,0,22,0,0
0,0,0,0,0,1,1,1,1,1,1,1,0,0,0,0,0,0,0,0
0,0,0,0,0,0,1,1,1,1,1,0,0,0,0,0,0,0,0,0
0,0,0,0,0,0,0,1,1,1,1,22,0,0,0,0,0,0,0,0
0,0,0,0,0,0,0,0,0,0,27,27,0,0,0,0,0,0,0,0
0,0,0,0,0,0,0,0,0,0,0,0,0,0,0,0,0,0,0,0
0,0,0,0,0,0,0,0,0,0,0,0,0,0,0,0,0,0,0,0
0,0,0,0,0,0,0,0,0,0,0,0,0,0,0,0,0,0,0,0
0,0,0,0,0,0,0,0,0,0,0,0,0,0,0,0,0,0,0,0
0,0,0,0,0,0,0,0,0,0,0,0,0,0,0,0,0,0,0,0
0,0,0,0,0,0,0,0,0,0,0,0,0,0,0,0,0,0,0,0
0,0,0,0,0,0,0,0,0,0,0,0,0,0,0,0,0,0,0,0
0,0,0,0,0,0,0,0,0,0,0,0,0,0,0,0,0,0,0,0
:endlayer
layer: 23
0,0,0,0,0,0,0,0,0,0,0,0,0,0,0,0,0,0,0,0
0,0,0,0,0,0,0,0,0,0,0,0,0,0,0,0,0,0,0,0
0,0,0,0,0,0,0,0,0,0,0,0,0,0,0,0,0,0,0,0
0,0,0,0,0,0,0,0,0,0,0,0,0,0,0,0,0,0,0,0
0,0,0,0,0,0,0,0,0,0,0,0,0,0,0,0,0,0,0,0
0,0,0,0,0,0,0,28,28,28,28,0,0,0,0,0,0,0,0,0
0,0,0,0,0,0,0,0,0,0,0,0,0,0,0,0,0,0,0,0
0,0,0,0,0,0,0,0,15,15,0,0,0,0,0,0,0,0,0,0
0,0,0,0,0,0,14,1,1,1,1,14,0,0,0,0,0,0,0,0
0,0,0,0,15,14,1,1,1,1,1,1,1,21,0,0,0,0,0,0
0,0,0,0,1,1,1,1,1,1,1,1,1,21,0,0,0,0,0,0
0,0,0,0,1,1,1,1,1,1,1,1,1,1,15,0,0,0,0,0
0,0,0,0,1,1,1,1,1,1,1,1,1,1,0,0,22,0,0,0
0,0,0,0,1,1,1,1,1,1,1,1,1,1,0,0,22,0,0,0
0,0,0,0,1,1,1,1,1,1,1,1,1,1,0,23,31,0,0,0
0,0,0,0,0,1,1,1,1,1,1,1,1,0,27,0,0,22,0,0
0,0,0,0,0,1,1,1,1,1,1,14,0,0,0,0,0,0,0,0
0,0,0,0,0,0,1,1,1,1,1,0,0,0,0,0,0,0,0,0
0,0,0,0,0,0,0,14,1,1,1,22,0,0,0,0,0,0,0,0
0,0,0,0,0,0,0,0,0,0,27,27,0,0,0,0,0,0,0,0
0,0,0,0,0,0,0,0,0,0,0,0,0,0,0,0,0,0,0,0
0,0,0,0,0,0,0,0,0,0,0,0,0,0,0,0,0,0,0,0
0,0,0,0,0,0,0,0,0,0,0,0,0,0,0,0,0,0,0,0
0,0,0,0,0,0,0,0,0,0,0,0,0,0,0,0,0,0,0,0
0,0,0,0,0,0,0,0,0,0,0,0,0,0,0,0,0,0,0,0
0,0,0,0,0,0,0,0,0,0,0,0,0,0,0,0,0,0,0,0
0,0,0,0,0,0,0,0,0,0,0,0,0,0,0,0,0,0,0,0
0,0,0,0,0,0,0,0,0,0,0,0,0,0,0,0,0,0,0,0
:endlayer
layer: 24
0,0,0,0,0,0,0,0,0,0,0,0,0,0,0,0,0,0,0,0
0,0,0,0,0,0,0,0,0,0,0,0,0,0,0,0,0,0,0,0
0,0,0,0,0,0,0,0,0,0,0,0,0,0,0,0,0,0,0,0
0,0,0,0,0,0,0,0,0,0,0,0,0,0,0,0,0,0,0,0
0,0,0,0,0,0,0,0,0,0,0,0,0,0,0,0,0,0,0,0
0,0,0,0,0,0,0,28,28,28,28,0,0,0,0,0,0,0,0,0
0,0,0,0,0,0,0,0,0,0,0,0,0,0,0,0,0,0,0,0
0,0,0,0,0,0,0,0,0,0,0,0,0,0,0,0,0,0,0,0
0,0,0,0,0,0,15,14,14,14,14,15,0,0,0,0,0,0,0,0
0,0,0,0,0,15,14,1,1,1,1,1,14,0,0,0,0,0,0,0
0,0,0,0,14,1,1,1,1,1,1,1,1,14,0,0,0,0,0,0
0,0,0,0,1,1,1,1,1,1,1,1,1,1,0,0,0,0,0,0
0,0,0,0,1,1,1,1,1,1,1,1,1,1,0,0,22,0,0,0
0,0,0,0,1,1,1,1,1,1,1,1,1,14,0,0,22,0,0,0
0,0,0,0,1,1,1,1,1,1,1,1,1,14,0,23,31,0,0,0
0,0,0,0,0,1,1,1,1,1,1,1,14,0,27,0,0,22,0,0
0,0,0,0,0,1,1,1,1,1,1,0,0,0,0,0,0,0,0,0
0,0,0,0,0,0,14,1,1,1,1,0,0,0,0,0,0,0,0,0
0,0,0,0,0,0,0,20,14,14,14,22,0,0,0,0,0,0,0,0
0,0,0,0,0,0,0,0,0,0,27,27,0,0,0,0,0,0,0,0
0,0,0,0,0,0,0,0,0,0,0,0,0,0,0,0,0,0,0,0
0,0,0,0,0,0,0,0,0,0,0,0,0,0,0,0,0,0,0,0
0,0,0,0,0,0,0,0,0,0,0,0,0,0,0,0,0,0,0,0
0,0,0,0,0,0,0,0,0,0,0,0,0,0,0,0,0,0,0,0
0,0,0,0,0,0,0,0,0,0,0,0,0,0,0,0,0,0,0,0
0,0,0,0,0,0,0,0,0,0,0,0,0,0,0,0,0,0,0,0
0,0,0,0,0,0,0,0,0,0,0,0,0,0,0,0,0,0,0,0
0,0,0,0,0,0,0,0,0,0,0,0,0,0,0,0,0,0,0,0
:endlayer
layer: 25
0,0,0,0,0,0,0,0,0,0,0,0,0,0,0,0,0,0,0,0
0,0,0,0,0,0,0,0,0,0,0,0,0,0,0,0,0,0,0,0
0,0,0,0,0,0,0,0,0,0,0,0,0,0,0,0,0,0,0,0
0,0,0,0,0,0,0,0,0,0,0,0,0,0,0,0,0,0,0,0
0,0,0,0,0,0,0,0,0,0,0,0,0,0,0,0,0,0,0,0
0,0,0,0,0,0,0,28,28,28,28,0,0,0,0,0,0,0,0,0
0,0,0,0,0,0,0,0,0,0,0,0,0,0,0,0,0,0,0,0
0,0,0,0,0,0,0,0,0,0,0,0,0,0,0,0,0,0,0,0
0,0,0,0,0,0,0,15,15,0,15,0,0,0,0,0,0,0,0,0
0,0,0,0,0,0,15,14,1,1,1,14,15,0,0,0,0,0,0,0
0,0,0,0,0,14,1,1,1,1,1,1,14,0,0,0,0,0,0,0
0,0,0,0,1,1,1,1,1,1,1,1,1,14,0,0,0,0,0,0
0,0,0,0,1,1,1,1,1,1,1,1,1,14,0,0,22,0,0,0
0,0,0,1,1,1,1,1,1,1,1,1,1,15,0,0,22,0,0,0
0,0,0,0,1,1,1,1,1,1,1,1,14,0,0,23,31,0,0,0
0,0,0,0,1,1,1,1,1,1,1,14,0,0,27,0,0,22,0,0
0,0,0,0,0,1,1,1,1,1,1,0,0,0,0,0,0,0,0,0
0,0,0,0,0,0,15,1,1,1,1,0,0,0,0,0,0,0,0,0
0,0,0,0,0,0,0,0,15,15,15,22,0,0,0,0,0,0,0,0
0,0,0,0,0,0,0,0,0,0,27,27,0,0,0,0,0,0,0,0
0,0,0,0,0,0,0,0,0,0,0,0,0,0,0,0,0,0,0,0
0,0,0,0,0,0,0,0,0,0,0,0,0,0,0,0,0,0,0,0
0,0,0,0,0,0,0,0,0,0,0,0,0,0,0,0,0,0,0,0
0,0,0,0,0,0,0,0,0,0,0,0,0,0,0,0,0,0,0,0
0,0,0,0,0,0,0,0,0,0,0,0,0,0,0,0,0,0,0,0
0,0,0,0,0,0,0,0,0,0,0,0,0,0,0,0,0,0,0,0
0,0,0,0,0,0,0,0,0,0,0,0,0,0,0,0,0,0,0,0
0,0,0,0,0,0,0,0,0,0,0,0,0,0,0,0,0,0,0,0
:endlayer
layer: 26
0,0,0,0,0,0,0,0,0,0,0,0,0,0,0,0,0,0,0,0
0,0,0,0,0,0,0,0,0,0,0,0,0,0,0,0,0,0,0,0
0,0,0,0,0,0,0,0,0,0,0,0,0,0,0,0,0,0,0,0
0,0,0,0,0,0,0,0,0,0,0,0,0,0,0,0,0,0,0,0
0,0,0,0,0,0,0,0,0,0,0,0,0,0,0,0,0,0,0,0
0,0,0,0,0,0,0,28,28,28,28,0,0,0,0,0,0,0,0,0
0,0,0,0,0,0,0,0,0,0,0,0,0,0,0,0,0,0,0,0
0,0,0,0,0,0,0,0,0,0,0,0,0,0,0,0,0,0,0,0
0,0,0,0,0,0,0,0,0,0,0,0,0,0,0,0,0,0,0,0
0,0,0,0,0,0,0,15,1,1,1,15,0,0,0,0,0,0,0,0
0,0,0,0,0,15,1,1,1,1,1,1,15,0,0,0,0,0,0,0
0,0,0,0,1,1,1,1,1,1,1,1,1,15,0,0,0,0,0,0
0,0,0,1,1,1,1,1,1,1,1,1,1,0,0,0,22,0,0,0
0,0,0,1,1,1,1,1,1,1,1,1,0,0,0,0,22,0,0,0
0,0,0,1,1,1,1,1,1,1,1,1,15,0,0,23,31,0,0,0
0,0,0,0,1,1,1,1,1,1,1,0,0,0,27,0,0,22,0,0
0,0,0,0,0,1,1,1,1,1,1,0,0,0,0,0,0,0,0,0
0,0,0,0,0,0,1,1,1,1,1,0,0,0,0,0,0,0,0,0
0,0,0,0,0,0,0,0,0,0,0,22,0,0,0,0,0,0,0,0
0,0,0,0,0,0,0,0,0,0,27,27,0,0,0,0,0,0,0,0
0,0,0,0,0,0,0,0,0,0,0,0,0,0,0,0,0,0,0,0
0,0,0,0,0,0,0,0,0,0,0,0,0,0,0,0,0,0,0,0
0,0,0,0,0,0,0,0,0,0,0,0,0,0,0,0,0,0,0,0
0,0,0,0,0,0,0,0,0,0,0,0,0,0,0,0,0,0,0,0
0,0,0,0,0,0,0,0,0,0,0,0,0,0,0,0,0,0,0,0
0,0,0,0,0,0,0,0,0,0,0,0,0,0,0,0,0,0,0,0
0,0,0,0,0,0,0,0,0,0,0,0,0,0,0,0,0,0,0,0
0,0,0,0,0,0,0,0,0,0,0,0,0,0,0,0,0,0,0,0
:endlayer
layer: 27
0,0,0,0,0,0,0,0,0,0,0,0,0,0,0,0,0,0,0,0
0,0,0,0,0,0,0,0,0,0,0,0,0,0,0,0,0,0,0,0
0,0,0,0,0,0,0,0,0,0,0,0,0,0,0,0,0,0,0,0
0,0,0,0,0,0,0,0,0,0,0,0,0,0,0,0,0,0,0,0
0,0,0,0,0,0,0,0,0,0,0,0,0,0,0,0,0,0,0,0
0,0,0,0,0,0,0,28,28,28,28,0,0,0,0,0,0,0,0,0
0,0,0,0,0,0,0,0,0,0,0,0,0,0,0,0,0,0,0,0
0,0,0,0,0,0,0,0,0,0,0,0,0,0,0,0,0,0,0,0
0,0,0,0,0,0,0,1,1,1,1,0,0,0,0,0,0,0,0,0
0,0,0,0,0,0,1,1,1,1,1,1,0,0,0,0,0,0,0,0
0,0,0,0,0,1,1,1,1,1,1,1,0,0,0,0,0,0,0,0
0,0,0,1,1,1,1,1,1,1,1,1,1,0,0,0,0,0,0,0
0,0,0,1,1,1,1,1,1,1,1,1,1,0,0,0,22,0,0,0
0,0,0,1,1,1,1,1,1,1,1,1,1,0,0,0,22,0,0,0
0,0,0,1,1,1,1,1,1,1,1,1,0,0,0,23,31,0,0,0
0,0,0,0,1,1,1,1,1,1,1,0,0,0,27,0,0,22,0,0
0,0,0,0,0,1,1,1,1,1,1,0,0,0,0,0,0,0,0,0
0,0,0,0,0,0,1,1,1,1,1,0,0,0,0,0,0,0,0,0
0,0,0,0,0,0,0,0,0,0,0,22,0,0,0,0,0,0,0,0
0,0,0,0,0,0,0,0,0,0,27,27,0,0,0,0,0,0,0,0
0,0,0,0,0,0,0,0,0,0,0,0,0,0,0,0,0,0,0,0
0,0,0,0,0,0,0,0,0,0,0,0,0,0,0,0,0,0,0,0
0,0,0,0,0,0,0,0,0,0,0,0,0,0,0,0,0,0,0,0
0,0,0,0,0,0,0,0,0,0,0,0,0,0,0,0,0,0,0,0
0,0,0,0,0,0,0,0,0,0,0,0,0,0,0,0,0,0,0,0
0,0,0,0,0,0,0,0,0,0,0,0,0,0,0,0,0,0,0,0
0,0,0,0,0,0,0,0,0,0,0,0,0,0,0,0,0,0,0,0
0,0,0,0,0,0,0,0,0,0,0,0,0,0,0,0,0,0,0,0
:endlayer
layer: 28
0,0,0,0,0,0,0,0,0,0,0,0,0,0,0,0,0,0,0,0
0,0,0,0,0,0,0,0,0,0,0,0,0,0,0,0,0,0,0,0
0,0,0,0,0,0,0,0,0,0,0,0,0,0,0,0,0,0,0,0
0,0,0,0,0,0,0,0,0,0,0,0,0,0,0,0,0,0,0,0
0,0,0,0,0,0,0,0,0,0,0,0,0,0,0,0,0,0,0,0
0,0,0,0,0,0,0,28,28,28,28,0,0,0,0,0,0,0,0,0
0,0,0,0,0,0,0,0,0,0,0,0,0,0,0,0,0,0,0,0
0,0,0,0,0,0,0,1,1,0,1,0,0,0,0,0,0,0,0,0
0,0,0,0,0,1,1,1,1,1,1,1,0,0,0,0,0,0,0,0
0,0,0,0,1,1,1,1,1,1,1,1,1,0,0,0,0,0,0,0
0,0,0,0,1,1,1,1,1,1,1,1,1,1,0,0,0,0,0,0
0,0,0,14,1,1,1,1,1,1,1,1,1,1,0,0,0,0,0,0
0,0,0,1,1,1,1,1,1,1,1,1,1,1,0,0,22,0,0,0
0,0,0,1,1,1,1,1,1,1,1,1,1,1,0,0,22,0,0,0
0,0,0,14,1,1,1,1,1,1,1,1,1,14,0,23,31,0,0,0
0,0,0,0,1,1,1,1,1,1,1,1,1,0,27,0,0,22,0,0
0,0,0,0,0,1,1,1,1,1,1,1,0,0,0,0,0,0,0,0
0,0,0,0,0,0,14,1,1,1,14,0,0,0,0,0,0,0,0,0
0,0,0,0,0,0,0,0,0,0,0,22,0,0,0,0,0,0,0,0
0,0,0,0,0,0,0,0,0,0,27,27,0,0,0,0,0,0,0,0
0,0,0,0,0,0,0,0,0,0,0,0,0,0,0,0,0,0,0,0
0,0,0,0,0,0,0,0,0,0,0,0,0,0,0,0,0,0,0,0
0,0,0,0,0,0,0,0,0,0,0,0,0,0,0,0,0,0,0,0
0,0,0,0,0,0,0,0,0,0,0,0,0,0,0,0,0,0,0,0
0,0,0,0,0,0,0,0,0,0,0,0,0,0,0,0,0,0,0,0
0,0,0,0,0,0,0,0,0,0,0,0,0,0,0,0,0,0,0,0
0,0,0,0,0,0,0,0,0,0,0,0,0,0,0,0,0,0,0,0
0,0,0,0,0,0,0,0,0,0,0,0,0,0,0,0,0,0,0,0
:endlayer
layer: 29
0,0,0,0,0,0,0,0,0,0,0,0,0,0,0,0,0,0,0,0
0,0,0,0,0,0,0,0,0,0,0,0,0,0,0,0,0,0,0,0
0,0,0,0,0,0,0,0,0,0,0,0,0,0,0,0,0,0,0,0
0,0,0,0,0,0,0,0,0,0,0,0,0,0,0,0,0,0,0,0
0,0,0,0,0,0,0,0,0,0,0,0,0,0,0,0,0,0,0,0
0,0,0,0,0,0,0,28,28,28,28,0,0,0,0,0,0,0,0,0
0,0,0,0,0,0,0,0,0,0,0,0,0,0,0,0,0,0,0,0
0,0,0,0,0,0,0,1,1,1,1,1,0,0,0,0,0,0,0,0
0,0,0,0,0,1,1,1,1,1,1,1,1,0,0,0,0,0,0,0
0,0,0,0,14,1,1,1,1,1,1,1,1,1,0,0,0,0,0,0
0,0,0,0,1,1,1,1,1,1,1,1,1,1,0,0,0,0,0,0
0,0,0,0,1,1,1,1,1,1,1,1,1,1,0,0,0,0,0,0
0,0,0,14,1,1,1,1,1,1,1,1,1,1,0,0,22,0,0,0
0,0,0,14,1,1,1,1,1,1,1,1,1,1,0,0,22,0,0,0
0,0,0,15,1,1,1,1,1,1,1,1,1,15,0,23,31,0,0,0
0,0,0,0,14,1,1,1,1,1,1,1,1,0,23,0,0,22,0,0
0,0,0,0,0,14,1,1,1,1,1,14,0,0,0,0,0,0,0,0
0,0,0,0,0,0,0,14,14,14,0,0,0,0,0,0,0,0,0,0
0,0,0,0,0,0,0,0,0,0,0,22,0,0,0,0,0,0,0,0
0,0,0,0,0,0,0,0,0,0,27,27,0,0,0,0,0,0,0,0
0,0,0,0,0,0,0,0,0,0,0,0,0,0,0,0,0,0,0,0
0,0,0,0,0,0,0,0,0,0,0,0,0,0,0,0,0,0,0,0
0,0,0,0,0,0,0,0,0,0,0,0,0,0,0,0,0,0,0,0
0,0,0,0,0,0,0,0,0,0,0,0,0,0,0,0,0,0,0,0
0,0,0,0,0,0,0,0,0,0,0,0,0,0,0,0,0,0,0,0
0,0,0,0,0,0,0,0,0,0,0,0,0,0,0,0,0,0,0,0
0,0,0,0,0,0,0,0,0,0,0,0,0,0,0,0,0,0,0,0
0,0,0,0,0,0,0,0,0,0,0,0,0,0,0,0,0,0,0,0
:endlayer
layer: 30
0,0,0,0,0,0,0,0,0,0,0,0,0,0,0,0,0,0,0,0
0,0,0,0,0,0,0,0,0,0,0,0,0,0,0,0,0,0,0,0
0,0,0,0,0,0,0,0,0,0,0,0,0,0,0,0,0,0,0,0
0,0,0,0,0,0,0,0,0,0,0,0,0,0,0,0,0,0,0,0
0,0,0,0,0,0,0,0,0,0,0,0,0,0,0,0,0,0,0,0
0,0,0,0,0,0,0,28,28,28,28,0,0,0,0,0,0,0,0,0
0,0,0,0,0,0,0,0,1,0,0,0,0,0,0,0,0,0,0,0
0,0,0,0,0,0,1,1,1,1,1,1,1,0,0,0,0,0,0,0
0,0,0,0,0,1,1,1,1,1,1,1,1,1,0,0,0,0,0,0
0,0,0,0,15,1,1,1,1,1,1,1,1,1,0,0,0,0,0,0
0,0,0,0,1,1,1,1,1,1,1,1,1,1,1,0,0,0,0,0
0,0,0,0,1,1,1,1,1,1,1,1,1,1,0,0,0,0,0,0
0,0,0,0,1,1,1,1,1,1,1,1,1,1,0,0,22,0,0,0
0,0,0,0,1,1,1,1,1,1,1,1,1,1,0,0,22,0,0,0
0,0,0,0,14,1,1,1,1,1,1,1,1,1,0,23,31,0,0,0
0,0,0,0,0,14,1,1,1,1,1,1,1,0,23,0,0,22,0,0
0,0,0,0,0,20,14,1,1,1,1,0,0,0,0,0,0,0,0,0
0,0,0,0,0,0,0,15,15,15,0,0,0,0,0,0,0,0,0,0
0,0,0,0,0,0,0,0,0,0,0,22,0,0,0,0,0,0,0,0
0,0,0,0,0,0,0,0,0,0,27,27,0,0,0,0,0,0,0,0
0,0,0,0,0,0,0,0,0,0,0,0,0,0,0,0,0,0,0,0
0,0,0,0,0,0,0,0,0,0,0,0,0,0,0,0,0,0,0,0
0,0,0,0,0,0,0,0,0,0,0,0,0,0,0,0,0,0,0,0
0,0,0,0,0,0,0,0,0,0,0,0,0,0,0,0,0,0,0,0
0,0,0,0,0,0,0,0,0,0,0,0,0,0,0,0,0,0,0,0
0,0,0,0,0,0,0,0,0,0,0,0,0,0,0,0,0,0,0,0
0,0,0,0,0,0,0,0,0,0,0,0,0,0,0,0,0,0,0,0
0,0,0,0,0,0,0,0,0,0,0,0,0,0,0,0,0,0,0,0
:endlayer
layer: 31
0,0,0,0,0,0,0,0,0,0,0,0,0,0,0,0,0,0,0,0
0,0,0,0,0,0,0,0,0,0,0,0,0,0,0,0,0,0,0,0
0,0,0,0,0,0,0,0,0,0,0,0,0,0,0,0,0,0,0,0
0,0,0,0,0,0,0,0,0,0,0,0,0,0,0,0,0,0,0,0
0,0,0,0,0,0,0,0,0,0,0,0,0,0,0,0,0,0,0,0
0,0,0,0,0,0,0,28,28,28,28,0,0,0,0,0,0,0,0,0
0,0,0,0,0,0,0,1,1,1,1,0,0,0,0,0,0,0,0,0
0,0,0,0,0,0,1,1,1,1,1,1,1,0,0,0,0,0,0,0
0,0,0,0,0,1,1,1,1,1,1,1,1,1,0,0,0,0,0,0
0,0,0,0,1,1,1,1,1,1,1,1,1,1,1,0,0,0,0,0
0,0,0,0,1,1,1,1,1,1,1,1,1,1,1,0,0,0,0,0
0,0,0,0,1,1,1,1,1,1,1,1,1,1,1,0,0,0,0,0
0,0,0,0,1,1,1,1,1,1,1,1,1,1,0,0,22,0,0,0
0,0,0,0,1,1,1,1,1,1,1,1,1,1,0,0,22,0,0,0
0,0,0,0,15,1,1,1,1,1,1,1,1,1,0,23,31,0,0,0
0,0,0,0,0,0,1,1,1,1,1,1,1,0,23,0,0,22,0,0
0,0,0,0,0,0,20,1,1,1,1,1,0,0,0,0,0,0,0,0
0,0,0,0,0,0,0,0,0,0,0,0,0,0,0,0,0,0,0,0
0,0,0,0,0,0,0,0,0,0,0,22,0,0,0,0,0,0,0,0
0,0,0,0,0,0,0,0,0,0,27,27,0,0,0,0,0,0,0,0
0,0,0,0,0,0,0,0,0,0,0,0,0,0,0,0,0,0,0,0
0,0,0,0,0,0,0,0,0,0,0,0,0,0,0,0,0,0,0,0
0,0,0,0,0,0,0,0,0,0,0,0,0,0,0,0,0,0,0,0
0,0,0,0,0,0,0,0,0,0,0,0,0,0,0,0,0,0,0,0
0,0,0,0,0,0,0,0,0,0,0,0,0,0,0,0,0,0,0,0
0,0,0,0,0,0,0,0,0,0,0,0,0,0,0,0,0,0,0,0
0,0,0,0,0,0,0,0,0,0,0,0,0,0,0,0,0,0,0,0
0,0,0,0,0,0,0,0,0,0,0,0,0,0,0,0,0,0,0,0
:endlayer
layer: 32
0,0,0,0,0,0,0,0,0,0,0,0,0,0,0,0,0,0,0,0
0,0,0,0,0,0,0,0,0,0,0,0,0,0,0,0,0,0,0,0
0,0,0,0,0,0,0,0,0,0,0,0,0,0,0,0,0,0,0,0
0,0,0,0,0,0,0,0,0,0,0,0,0,0,0,0,0,0,0,0
0,0,0,0,0,0,0,0,0,0,0,0,0,0,0,0,0,0,0,0
0,0,0,0,0,0,0,28,28,28,28,0,0,0,0,0,0,0,0,0
0,0,0,0,0,0,0,1,1,1,1,1,0,0,0,0,0,0,0,0
0,0,0,0,0,0,1,1,1,1,1,1,1,0,0,0,0,0,0,0
0,0,0,0,0,1,1,1,1,1,1,1,1,1,0,0,0,0,0,0
0,0,0,0,1,1,1,1,1,1,1,1,1,1,1,0,0,0,0,0
0,0,0,0,1,1,1,1,1,1,1,1,1,1,1,0,0,0,0,0
0,0,0,0,1,1,1,1,1,1,1,1,1,1,1,0,0,0,0,0
0,0,0,0,1,1,1,1,1,1,1,1,1,1,1,0,22,0,0,0
0,0,0,0,1,1,1,1,1,1,1,1,1,1,0,0,22,0,0,0
0,0,0,0,0,1,1,1,1,1,1,1,1,1,0,23,31,0,0,0
0,0,0,0,0,0,1,1,1,1,1,1,1,0,23,0,0,22,0,0
0,0,0,0,0,0,0,1,1,1,1,1,0,0,0,0,0,0,0,0
0,0,0,0,0,0,0,0,0,0,0,0,0,0,0,0,0,0,0,0
0,0,0,0,0,0,0,0,0,0,0,22,0,0,0,0,0,0,0,0
0,0,0,0,0,0,0,0,0,0,27,27,0,0,0,0,0,0,0,0
0,0,0,0,0,0,0,0,0,0,0,0,0,0,0,0,0,0,0,0
0,0,0,0,0,0,0,0,0,0,0,0,0,0,0,0,0,0,0,0
0,0,0,0,0,0,0,0,0,0,0,0,0,0,0,0,0,0,0,0
0,0,0,0,0,0,0,0,0,0,0,0,0,0,0,0,0,0,0,0
0,0,0,0,0,0,0,0,0,0,0,0,0,0,0,0,0,0,0,0
0,0,0,0,0,0,0,0,0,0,0,0,0,0,0,0,0,0,0,0
0,0,0,0,0,0,0,0,0,0,0,0,0,0,0,0,0,0,0,0
0,0,0,0,0,0,0,0,0,0,0,0,0,0,0,0,0,0,0,0
:endlayer
layer: 33
0,0,0,0,0,0,0,0,0,0,0,0,0,0,0,0,0,0,0,0
0,0,0,0,0,0,0,0,0,0,0,0,0,0,0,0,0,0,0,0
0,0,0,0,0,0,0,0,0,0,0,0,0,0,0,0,0,0,0,0
0,0,0,0,0,0,0,0,0,0,0,0,0,0,0,0,0,0,0,0
0,0,0,0,0,0,0,0,0,0,0,0,0,0,0,0,0,0,0,0
0,0,0,0,0,0,0,28,28,28,28,0,0,0,0,0,0,0,0,0
0,0,0,0,0,0,0,14,1,1,1,14,0,0,0,0,0,0,0,0
0,0,0,0,0,0,1,1,1,1,1,1,1,0,0,0,0,0,0,0
0,0,0,0,0,1,1,1,1,1,1,1,1,1,0,0,0,0,0,0
0,0,0,0,14,1,1,1,1,1,1,1,1,1,1,0,0,0,0,0
0,0,0,0,1,1,1,1,1,1,1,1,1,1,1,0,0,0,0,0
0,0,0,0,1,1,1,1,1,1,1,1,1,1,1,0,0,0,0,0
0,0,0,0,1,1,1,1,1,1,1,1,1,1,1,0,22,0,0,0
0,0,0,0,14,1,1,1,1,1,1,1,1,1,0,0,22,0,0,0
0,0,0,0,0,1,1,1,1,1,1,1,1,1,0,23,31,0,0,0
0,0,0,0,0,0,1,1,1,1,1,1,1,0,23,0,0,22,0,0
0,0,0,0,0,0,0,14,1,1,1,14,0,0,0,0,0,0,0,0
0,0,0,0,0,0,0,0,0,0,0,0,0,0,0,0,0,0,0,0
0,0,0,0,0,0,0,0,0,0,0,22,0,0,0,0,0,0,0,0
0,0,0,0,0,0,0,0,0,0,27,27,0,0,0,0,0,0,0,0
0,0,0,0,0,0,0,0,0,0,0,0,0,0,0,0,0,0,0,0
0,0,0,0,0,0,0,0,0,0,0,0,0,0,0,0,0,0,0,0
0,0,0,0,0,0,0,0,0,0,0,0,0,0,0,0,0,0,0,0
0,0,0,0,0,0,0,0,0,0,0,0,0,0,0,0,0,0,0,0
0,0,0,0,0,0,0,0,0,0,0,0,0,0,0,0,0,0,0,0
0,0,0,0,0,0,0,0,0,0,0,0,0,0,0,0,0,0,0,0
0,0,0,0,0,0,0,0,0,0,0,0,0,0,0,0,0,0,0,0
0,0,0,0,0,0,0,0,0,0,0,0,0,0,0,0,0,0,0,0
:endlayer
layer: 34
0,0,0,0,0,0,0,0,0,0,0,0,0,0,0,0,0,0,0,0
0,0,0,0,0,0,0,0,0,0,0,0,0,0,0,0,0,0,0,0
0,0,0,0,0,0,0,0,0,0,0,0,0,0,0,0,0,0,0,0
0,0,0,0,0,0,0,0,0,0,0,0,0,0,0,0,0,0,0,0
0,0,0,0,0,0,0,0,0,0,0,0,0,0,0,0,0,0,0,0
0,0,0,0,0,0,0,0,28,28,28,0,0,0,0,0,0,0,0,0
0,0,0,0,0,0,0,15,14,1,1,0,0,0,0,0,0,0,0,0
0,0,0,0,0,0,14,1,1,1,1,1,1,0,0,0,0,0,0,0
0,0,0,0,0,14,1,1,1,1,1,1,1,1,0,0,0,0,0,0
0,0,0,0,0,1,1,1,1,1,1,1,1,1,1,0,0,0,0,0
0,0,0,0,14,1,1,1,1,1,1,1,1,1,1,0,0,0,0,0
0,0,0,0,14,1,1,1,1,1,1,1,1,1,1,0,0,0,0,0
0,0,0,0,14,1,1,1,1,1,1,1,1,1,1,0,22,0,0,0
0,0,0,0,15,1,1,1,1,1,1,1,1,1,1,0,22,0,0,0
0,0,0,0,0,1,1,1,1,1,1,1,1,1,0,23,31,0,0,0
0,0,0,0,0,0,1,1,1,1,1,1,1,0,23,0,0,22,0,0
0,0,0,0,0,0,0,15,14,1,1,0,0,0,0,0,0,0,0,0
0,0,0,0,0,0,0,0,0,0,0,0,0,0,0,0,0,0,0,0
0,0,0,0,0,0,0,0,0,0,0,22,0,0,0,0,0,0,0,0
0,0,0,0,0,0,0,0,0,0,27,27,0,0,0,0,0,0,0,0
0,0,0,0,0,0,0,0,0,0,0,0,0,0,0,0,0,0,0,0
0,0,0,0,0,0,0,0,0,0,0,0,0,0,0,0,0,0,0,0
0,0,0,0,0,0,0,0,0,0,0,0,0,0,0,0,0,0,0,0
0,0,0,0,0,0,0,0,0,0,0,0,0,0,0,0,0,0,0,0
0,0,0,0,0,0,0,0,0,0,0,0,0,0,0,0,0,0,0,0
0,0,0,0,0,0,0,0,0,0,0,0,0,0,0,0,0,0,0,0
0,0,0,0,0,0,0,0,0,0,0,0,0,0,0,0,0,0,0,0
0,0,0,0,0,0,0,0,0,0,0,0,0,0,0,0,0,0,0,0
:endlayer
layer: 35
0,0,0,0,0,0,0,0,0,0,0,0,0,0,0,0,0,0,0,0
0,0,0,0,0,0,0,0,0,0,0,0,0,0,0,0,0,0,0,0
0,0,0,0,0,0,0,0,0,0,0,0,0,0,0,0,0,0,0,0
0,0,0,0,0,0,0,0,0,0,0,0,0,0,0,0,0,0,0,0
0,0,0,0,0,0,0,0,0,0,0,0,0,0,0,0,0,0,0,0
0,0,0,0,0,0,0,0,28,28,28,0,0,0,0,0,0,0,0,0
0,0,0,0,0,0,0,32,15,1,1,0,0,0,0,0,0,0,0,0
0,0,0,0,0,0,15,1,1,1,1,1,1,1,0,0,0,0,0,0
0,0,0,0,0,15,1,1,1,1,1,1,1,1,1,0,0,0,0,0
0,0,0,0,0,1,1,1,1,1,1,1,1,1,1,0,0,0,0,0
0,0,0,0,15,1,1,1,1,1,1,1,1,1,1,1,0,0,0,0
0,0,0,0,15,1,1,1,1,1,1,1,1,1,1,0,0,0,0,0
0,0,0,0,15,1,1,1,1,1,1,1,1,1,1,0,22,0,0,0
0,0,0,0,0,1,1,1,1,1,1,1,1,1,1,0,22,0,0,0
0,0,0,0,0,14,1,1,1,1,1,1,1,1,1,23,31,0,0,0
0,0,0,0,0,0,14,1,1,1,1,1,1,1,23,0,0,22,0,0
0,0,0,0,0,0,0,0,0,1,1,1,0,0,0,0,0,0,0,0
0,0,0,0,0,0,0,0,0,0,0,0,0,0,0,0,0,0,0,0
0,0,0,0,0,0,0,0,0,0,0,22,0,0,0,0,0,0,0,0
0,0,0,0,0,0,0,0,0,0,27,27,0,0,0,0,0,0,0,0
0,0,0,0,0,0,0,0,0,0,0,0,0,0,0,0,0,0,0,0
0,0,0,0,0,0,0,0,0,0,0,0,0,0,0,0,0,0,0,0
0,0,0,0,0,0,0,0,0,0,0,0,0,0,0,0,0,0,0,0
0,0,0,0,0,0,0,0,0,0,0,0,0,0,0,0,0,0,0,0
0,0,0,0,0,0,0,0,0,0,0,0,0,0,0,0,0,0,0,0
0,0,0,0,0,0,0,0,0,0,0,0,0,0,0,0,0,0,0,0
0,0,0,0,0,0,0,0,0,0,0,0,0,0,0,0,0,0,0,0
0,0,0,0,0,0,0,0,0,0,0,0,0,0,0,0,0,0,0,0
:endlayer
layer: 36
0,0,0,0,0,0,0,0,0,0,0,0,0,0,0,0,0,0,0,0
0,0,0,0,0,0,0,0,0,0,0,0,0,0,0,0,0,0,0,0
0,0,0,0,0,0,0,0,0,0,0,0,0,0,0,0,0,0,0,0
0,0,0,0,0,0,0,0,0,0,0,0,0,0,0,0,0,0,0,0
0,0,0,0,0,0,0,0,0,0,0,0,0,0,0,0,0,0,0,0
0,0,0,0,0,0,0,0,28,28,28,0,0,0,0,0,0,0,0,0
0,0,0,0,0,0,0,32,1,1,1,1,0,0,0,0,0,0,0,0
0,0,0,0,0,0,32,1,1,1,1,1,1,1,0,0,0,0,0,0
0,0,0,0,0,0,1,1,1,1,1,1,1,1,1,0,0,0,0,0
0,0,0,0,0,1,1,1,1,1,1,1,1,1,1,1,0,0,0,0
0,0,0,0,0,1,1,1,1,1,1,1,1,1,1,1,0,0,0,0
0,0,0,0,0,1,1,1,1,1,1,1,1,1,1,1,0,0,0,0
0,0,0,0,0,1,1,1,1,1,1,1,1,1,1,1,22,0,0,0
0,0,0,0,0,1,1,1,1,1,1,1,1,1,1,14,22,0,0,0
0,0,0,0,0,15,1,1,1,1,1,1,1,1,1,23,31,0,0,0
0,0,0,0,0,0,15,1,1,1,1,1,1,1,23,0,0,22,0,0
0,0,0,0,0,0,0,0,1,1,1,1,0,0,0,0,0,0,0,0
0,0,0,0,0,0,0,0,0,0,0,0,0,0,0,0,0,0,0,0
0,0,0,0,0,0,0,0,0,0,0,22,0,0,0,0,0,0,0,0
0,0,0,0,0,0,0,0,0,0,27,27,0,0,0,0,0,0,0,0
0,0,0,0,0,0,0,0,0,0,0,0,0,0,0,0,0,0,0,0
0,0,0,0,0,0,0,0,0,0,0,0,0,0,0,0,0,0,0,0
0,0,0,0,0,0,0,0,0,0,0,0,0,0,0,0,0,0,0,0
0,0,0,0,0,0,0,0,0,0,0,0,0,0,0,0,0,0,0,0
0,0,0,0,0,0,0,0,0,0,0,0,0,0,0,0,0,0,0,0
0,0,0,0,0,0,0,0,0,0,0,0,0,0,0,0,0,0,0,0
0,0,0,0,0,0,0,0,0,0,0,0,0,0,0,0,0,0,0,0
0,0,0,0,0,0,0,0,0,0,0,0,0,0,0,0,0,0,0,0
:endlayer
layer: 37
0,0,0,0,0,0,0,0,0,0,0,0,0,0,0,0,0,0,0,0
0,0,0,0,0,0,0,0,0,0,0,0,0,0,0,0,0,0,0,0
0,0,0,0,0,0,0,0,0,0,0,0,0,0,0,0,0,0,0,0
0,0,0,0,0,0,0,0,0,0,0,0,0,0,0,0,0,0,0,0
0,0,0,0,0,0,0,0,0,0,0,0,0,0,0,0,0,0,0,0
0,0,0,0,0,0,0,0,28,28,28,0,0,0,0,0,0,0,0,0
0,0,0,0,0,0,0,32,1,1,1,1,1,0,0,0,0,0,0,0
0,0,0,0,0,0,32,1,1,1,1,1,1,1,0,0,0,0,0,0
0,0,0,0,0,0,1,1,1,1,1,1,1,1,1,0,0,0,0,0
0,0,0,0,0,1,1,1,1,1,1,1,1,1,1,1,0,0,0,0
0,0,0,0,0,1,1,1,1,1,1,1,1,1,1,1,0,0,0,0
0,0,0,0,0,1,1,1,1,1,1,1,1,1,1,1,0,0,0,0
0,0,0,0,0,1,1,1,1,1,1,1,1,1,1,1,22,0,0,0
0,0,0,0,0,14,1,1,1,1,1,1,1,1,1,23,22,0,0,0
0,0,0,0,0,0,1,1,1,1,1,1,1,1,14,23,31,0,0,0
0,0,0,0,0,0,0,1,1,1,1,1,1,14,23,0,0,22,0,0
0,0,0,0,0,0,0,0,1,1,1,1,0,0,0,0,0,0,0,0
0,0,0,0,0,0,0,0,0,0,0,0,0,0,0,0,0,0,0,0
0,0,0,0,0,0,0,0,0,0,0,22,0,0,0,0,0,0,0,0
0,0,0,0,0,0,0,0,0,0,27,27,0,0,0,0,0,0,0,0
0,0,0,0,0,0,0,0,0,0,0,0,0,0,0,0,0,0,0,0
0,0,0,0,0,0,0,0,0,0,0,0,0,0,0,0,0,0,0,0
0,0,0,0,0,0,0,0,0,0,0,0,0,0,0,0,0,0,0,0
0,0,0,0,0,0,0,0,0,0,0,0,0,0,0,0,0,0,0,0
0,0,0,0,0,0,0,0,0,0,0,0,0,0,0,0,0,0,0,0
0,0,0,0,0,0,0,0,0,0,0,0,0,0,0,0,0,0,0,0
0,0,0,0,0,0,0,0,0,0,0,0,0,0,0,0,0,0,0,0
0,0,0,0,0,0,0,0,0,0,0,0,0,0,0,0,0,0,0,0
:endlayer
layer: 38
0,0,0,0,0,0,0,0,0,0,0,0,0,0,0,0,0,0,0,0
0,0,0,0,0,0,0,0,0,0,0,0,0,0,0,0,0,0,0,0
0,0,0,0,0,0,0,0,0,0,0,0,0,0,0,0,0,0,0,0
0,0,0,0,0,0,0,0,0,0,0,0,0,0,0,0,0,0,0,0
0,0,0,0,0,0,0,0,0,0,0,0,0,0,0,0,0,0,0,0
0,0,0,0,0,0,0,0,28,28,28,0,0,0,0,0,0,0,0,0
0,0,0,0,0,0,0,32,14,1,1,1,14,0,0,0,0,0,0,0
0,0,0,0,0,0,32,1,1,1,1,1,1,1,0,0,0,0,0,0
0,0,0,0,0,0,1,1,1,1,1,1,1,1,1,0,0,0,0,0
0,0,0,0,0,14,1,1,1,1,1,1,1,1,1,14,0,0,0,0
0,0,0,0,0,1,1,1,1,1,1,1,1,1,1,1,0,0,0,0
0,0,0,0,0,1,1,1,1,1,1,1,1,1,1,1,0,0,0,0
0,0,0,0,0,1,1,1,1,1,1,1,1,1,1,1,22,0,0,0
0,0,0,0,0,0,1,1,1,1,1,1,1,1,1,22,22,0,0,0
0,0,0,0,0,0,1,1,1,1,1,1,1,1,0,23,31,0,0,0
0,0,0,0,0,0,0,1,1,1,1,1,1,0,23,0,0,22,0,0
0,0,0,0,0,0,0,0,1,1,1,1,14,0,0,0,0,0,0,0
0,0,0,0,0,0,0,0,0,0,0,0,0,0,0,0,0,0,0,0
0,0,0,0,0,0,0,0,0,0,0,22,0,0,0,0,0,0,0,0
0,0,0,0,0,0,0,0,0,0,27,27,0,0,0,0,0,0,0,0
0,0,0,0,0,0,0,0,0,0,0,0,0,0,0,0,0,0,0,0
0,0,0,0,0,0,0,0,0,0,0,0,0,0,0,0,0,0,0,0
0,0,0,0,0,0,0,0,0,0,0,0,0,0,0,0,0,0,0,0
0,0,0,0,0,0,0,0,0,0,0,0,0,0,0,0,0,0,0,0
0,0,0,0,0,0,0,0,0,0,0,0,0,0,0,0,0,0,0,0
0,0,0,0,0,0,0,0,0,0,0,0,0,0,0,0,0,0,0,0
0,0,0,0,0,0,0,0,0,0,0,0,0,0,0,0,0,0,0,0
0,0,0,0,0,0,0,0,0,0,0,0,0,0,0,0,0,0,0,0
:endlayer
layer: 39
0,0,0,0,0,0,0,0,0,0,0,0,0,0,0,0,0,0,0,0
0,0,0,0,0,0,0,0,0,0,0,0,0,0,0,0,0,0,0,0
0,0,0,0,0,0,0,0,0,0,0,0,0,0,0,0,0,0,0,0
0,0,0,0,0,0,0,0,0,0,0,0,0,0,0,0,0,0,0,0
0,0,0,0,0,0,0,0,0,0,0,0,0,0,0,0,0,0,0,0
0,0,0,0,0,0,0,0,0,28,28,0,0,0,0,0,0,0,0,0
0,0,0,0,0,0,0,28,15,14,14,14,15,0,0,0,0,0,0,0
0,0,0,0,0,0,32,14,1,1,1,1,1,14,0,0,0,0,0,0
0,0,0,0,0,0,1,1,1,1,1,1,1,1,14,0,0,0,0,0
0,0,0,0,0,0,1,1,1,1,1,1,1,1,1,15,0,0,0,0
0,0,0,0,0,1,1,1,1,1,1,1,1,1,1,14,0,0,0,0
0,0,0,0,0,1,1,1,1,1,1,1,1,1,1,14,0,0,0,0
0,0,0,0,0,1,1,1,1,1,1,1,1,1,1,14,22,0,0,0
0,0,0,0,0,0,1,1,1,1,1,1,1,1,1,22,22,0,0,0
0,0,0,0,0,0,1,1,1,1,1,1,1,1,1,23,31,0,0,0
0,0,0,0,0,0,1,1,1,1,1,1,1,1,23,0,0,22,0,0
0,0,0,0,0,0,0,1,1,1,1,1,15,0,0,0,0,0,0,0
0,0,0,0,0,0,0,0,0,0,0,0,0,0,0,0,0,0,0,0
0,0,0,0,0,0,0,0,0,0,0,22,0,0,0,0,0,0,0,0
0,0,0,0,0,0,0,0,0,0,27,27,0,0,0,0,0,0,0,0
0,0,0,0,0,0,0,0,0,0,0,0,0,0,0,0,0,0,0,0
0,0,0,0,0,0,0,0,0,0,0,0,0,0,0,0,0,0,0,0
0,0,0,0,0,0,0,0,0,0,0,0,0,0,0,0,0,0,0,0
0,0,0,0,0,0,0,0,0,0,0,0,0,0,0,0,0,0,0,0
0,0,0,0,0,0,0,0,0,0,0,0,0,0,0,0,0,0,0,0
0,0,0,0,0,0,0,0,0,0,0,0,0,0,0,0,0,0,0,0
0,0,0,0,0,0,0,0,0,0,0,0,0,0,0,0,0,0,0,0
0,0,0,0,0,0,0,0,0,0,0,0,0,0,0,0,0,0,0,0
:endlayer
layer: 40
0,0,0,0,0,0,0,0,0,0,0,0,0,0,0,0,0,0,0,0
0,0,0,0,0,0,0,0,0,0,0,0,0,0,0,0,0,0,0,0
0,0,0,0,0,0,0,0,0,0,0,0,0,0,0,0,0,0,0,0
0,0,0,0,0,0,0,0,0,0,0,0,0,0,0,0,0,0,0,0
0,0,0,0,0,0,0,0,0,0,0,0,0,0,0,0,0,0,0,0
0,0,0,0,0,0,0,0,0,0,0,0,0,0,0,0,0,0,0,0
0,0,0,0,0,0,0,28,28,15,15,21,0,0,0,0,0,0,0,0
0,0,0,0,0,0,32,15,1,1,1,1,14,0,0,0,0,0,0,0
0,0,0,0,0,0,1,1,1,1,1,1,1,14,0,0,0,0,0,0
0,0,0,0,0,1,1,1,1,1,1,1,1,1,14,0,0,0,0,0
0,0,0,0,0,1,1,1,1,1,1,1,1,1,1,15,0,0,0,0
0,0,0,0,1,1,1,1,1,1,1,1,1,1,1,15,0,0,0,0
0,0,0,0,0,1,1,1,1,1,1,1,1,1,1,15,22,0,0,0
0,0,0,0,0,1,1,1,1,1,1,1,1,1,1,22,22,0,0,0
0,0,0,0,0,0,1,1,1,1,1,1,1,1,14,23,31,0,0,0
0,0,0,0,0,0,1,1,1,1,1,1,1,1,23,0,0,22,0,0
0,0,0,0,0,0,1,1,1,1,1,1,1,0,0,0,0,0,0,0
0,0,0,0,0,0,0,0,0,0,1,0,0,0,0,0,0,0,0,0
0,0,0,0,0,0,0,0,0,0,0,22,0,0,0,0,0,0,0,0
0,0,0,0,0,0,0,0,0,0,27,27,0,0,0,0,0,0,0,0
0,0,0,0,0,0,0,0,0,0,0,0,0,0,0,0,0,0,0,0
0,0,0,0,0,0,0,0,0,0,0,0,0,0,0,0,0,0,0,0
0,0,0,0,0,0,0,0,0,0,0,0,0,0,0,0,0,0,0,0
0,0,0,0,0,0,0,0,0,0,0,0,0,0,0,0,0,0,0,0
0,0,0,0,0,0,0,0,0,0,0,0,0,0,0,0,0,0,0,0
0,0,0,0,0,0,0,0,0,0,0,0,0,0,0,0,0,0,0,0
0,0,0,0,0,0,0,0,0,0,0,0,0,0,0,0,0,0,0,0
0,0,0,0,0,0,0,0,0,0,0,0,0,0,0,0,0,0,0,0
:endlayer
layer: 41
0,0,0,0,0,0,0,0,0,0,0,0,0,0,0,0,0,0,0,0
0,0,0,0,0,0,0,0,0,0,0,0,0,0,0,0,0,0,0,0
0,0,0,0,0,0,0,0,0,0,0,0,0,0,0,0,0,0,0,0
0,0,0,0,0,0,0,0,0,0,0,0,0,0,0,0,0,0,0,0
0,0,0,0,0,0,0,0,0,0,0,0,0,0,0,0,0,0,0,0
0,0,0,0,0,0,0,0,0,0,0,0,0,0,0,0,0,0,0,0
0,0,0,0,0,0,0,28,28,28,28,28,0,0,0,0,0,0,0,0
0,0,0,0,0,0,32,1,1,1,1,1,31,0,0,0,0,0,0,0
0,0,0,0,0,0,1,1,1,1,1,1,1,15,0,0,0,0,0,0
0,0,0,0,0,1,1,1,1,1,1,1,1,1,15,0,0,0,0,0
0,0,0,0,0,1,1,1,1,1,1,1,1,1,1,0,0,0,0,0
0,0,0,0,1,1,1,1,1,1,1,1,1,1,1,0,0,0,0,0
0,0,0,0,1,1,1,1,1,1,1,1,1,1,1,0,22,0,0,0
0,0,0,0,0,1,1,1,1,1,1,1,1,1,1,22,22,0,0,0
0,0,0,0,0,0,1,1,1,1,1,1,1,1,15,23,31,0,0,0
0,0,0,0,0,0,1,1,1,1,1,1,1,1,23,0,0,22,0,0
0,0,0,0,0,0,1,1,1,1,1,1,1,0,0,0,0,0,0,0
0,0,0,0,0,0,0,0,0,1,1,1,0,0,0,0,0,0,0,0
0,0,0,0,0,0,0,0,0,0,0,22,0,0,0,0,0,0,0,0
0,0,0,0,0,0,0,0,0,0,27,27,0,0,0,0,0,0,0,0
0,0,0,0,0,0,0,0,0,0,0,0,0,0,0,0,0,0,0,0
0,0,0,0,0,0,0,0,0,0,0,0,0,0,0,0,0,0,0,0
0,0,0,0,0,0,0,0,0,0,0,0,0,0,0,0,0,0,0,0
0,0,0,0,0,0,0,0,0,0,0,0,0,0,0,0,0,0,0,0
0,0,0,0,0,0,0,0,0,0,0,0,0,0,0,0,0,0,0,0
0,0,0,0,0,0,0,0,0,0,0,0,0,0,0,0,0,0,0,0
0,0,0,0,0,0,0,0,0,0,0,0,0,0,0,0,0,0,0,0
0,0,0,0,0,0,0,0,0,0,0,0,0,0,0,0,0,0,0,0
:endlayer
layer: 42
0,0,0,0,0,0,0,0,0,0,0,0,0,0,0,0,0,0,0,0
0,0,0,0,0,0,0,0,0,0,0,0,0,0,0,0,0,0,0,0
0,0,0,0,0,0,0,0,0,0,0,0,0,0,0,0,0,0,0,0
0,0,0,0,0,0,0,0,0,0,0,0,0,0,0,0,0,0,0,0
0,0,0,0,0,0,0,0,0,0,0,0,0,0,0,0,0,0,0,0
0,0,0,0,0,0,0,0,0,0,0,0,0,0,0,0,0,0,0,0
0,0,0,0,0,0,0,28,28,28,28,28,0,0,0,0,0,0,0,0
0,0,0,0,0,0,32,1,1,1,1,1,31,0,0,0,0,0,0,0
0,0,0,0,0,0,1,1,1,1,1,1,1,0,0,0,0,0,0,0
0,0,0,0,0,1,1,1,1,1,1,1,1,1,0,0,0,0,0,0
0,0,0,0,1,1,1,1,1,1,1,1,1,1,1,0,0,0,0,0
0,0,0,0,1,1,1,1,1,1,1,1,1,1,1,0,0,0,0,0
0,0,0,0,1,1,1,1,1,1,1,1,1,1,1,0,22,0,0,0
0,0,0,0,1,1,1,1,1,1,1,1,1,1,1,22,22,0,0,0
0,0,0,0,0,1,1,1,1,1,1,1,1,1,1,23,31,0,0,0
0,0,0,0,0,0,1,1,1,1,1,1,1,1,23,0,0,22,0,0
0,0,0,0,0,0,1,1,1,1,1,1,1,0,0,0,0,0,0,0
0,0,0,0,0,0,0,0,1,1,1,1,0,0,0,0,0,0,0,0
0,0,0,0,0,0,0,0,0,0,0,22,0,0,0,0,0,0,0,0
0,0,0,0,0,0,0,0,0,0,27,27,0,0,0,0,0,0,0,0
0,0,0,0,0,0,0,0,0,0,0,0,0,0,0,0,0,0,0,0
0,0,0,0,0,0,0,0,0,0,0,0,0,0,0,0,0,0,0,0
0,0,0,0,0,0,0,0,0,0,0,0,0,0,0,0,0,0,0,0
0,0,0,0,0,0,0,0,0,0,0,0,0,0,0,0,0,0,0,0
0,0,0,0,0,0,0,0,0,0,0,0,0,0,0,0,0,0,0,0
0,0,0,0,0,0,0,0,0,0,0,0,0,0,0,0,0,0,0,0
0,0,0,0,0,0,0,0,0,0,0,0,0,0,0,0,0,0,0,0
0,0,0,0,0,0,0,0,0,0,0,0,0,0,0,0,0,0,0,0
:endlayer
layer: 43
0,0,0,0,0,0,0,0,0,0,0,0,0,0,0,0,0,0,0,0
0,0,0,0,0,0,0,0,0,0,0,0,0,0,0,0,0,0,0,0
0,0,0,0,0,0,0,0,0,0,0,0,0,0,0,0,0,0,0,0
0,0,0,0,0,0,0,0,0,0,0,0,0,0,0,0,0,0,0,0
0,0,0,0,0,0,0,0,0,0,0,0,0,0,0,0,0,0,0,0
0,0,0,0,0,0,0,0,0,0,0,0,0,0,0,0,0,0,0,0
0,0,0,0,0,0,0,28,28,28,28,0,0,0,0,0,0,0,0,0
0,0,0,0,0,0,32,1,1,1,1,1,28,0,0,0,0,0,0,0
0,0,0,0,0,0,1,1,1,1,1,1,1,0,0,0,0,0,0,0
0,0,0,0,0,1,1,1,1,1,1,1,1,1,0,0,0,0,0,0
0,0,0,0,1,1,1,1,1,1,1,1,1,1,1,0,0,0,0,0
0,0,0,0,1,1,1,1,1,1,1,1,1,1,1,0,0,0,0,0
0,0,0,0,1,1,1,1,1,1,1,1,1,1,1,0,22,0,0,0
0,0,0,0,1,1,1,1,1,1,1,1,1,1,1,22,22,0,0,0
0,0,0,0,1,1,1,1,1,1,1,1,1,1,14,23,31,0,0,0
0,0,0,0,0,1,1,1,1,1,1,1,1,1,23,0,0,22,0,0
0,0,0,0,0,0,1,1,1,1,1,1,1,0,0,0,0,0,0,0
0,0,0,0,0,0,0,1,1,1,1,1,0,0,0,0,0,0,0,0
0,0,0,0,0,0,0,0,0,0,0,22,0,0,0,0,0,0,0,0
0,0,0,0,0,0,0,0,0,0,27,27,0,0,0,0,0,0,0,0
0,0,0,0,0,0,0,0,0,0,0,0,0,0,0,0,0,0,0,0
0,0,0,0,0,0,0,0,0,0,0,0,0,0,0,0,0,0,0,0
0,0,0,0,0,0,0,0,0,0,0,0,0,0,0,0,0,0,0,0
0,0,0,0,0,0,0,0,0,0,0,0,0,0,0,0,0,0,0,0
0,0,0,0,0,0,0,0,0,0,0,0,0,0,0,0,0,0,0,0
0,0,0,0,0,0,0,0,0,0,0,0,0,0,0,0,0,0,0,0
0,0,0,0,0,0,0,0,0,0,0,0,0,0,0,0,0,0,0,0
0,0,0,0,0,0,0,0,0,0,0,0,0,0,0,0,0,0,0,0
:endlayer
layer: 44
0,0,0,0,0,0,0,0,0,0,0,0,0,0,0,0,0,0,0,0
0,0,0,0,0,0,0,0,0,0,0,0,0,0,0,0,0,0,0,0
0,0,0,0,0,0,0,0,0,0,0,0,0,0,0,0,0,0,0,0
0,0,0,0,0,0,0,0,0,0,0,0,0,0,0,0,0,0,0,0
0,0,0,0,0,0,0,0,0,0,0,0,0,0,0,0,0,0,0,0
0,0,0,0,0,0,0,0,0,0,0,0,0,0,0,0,0,0,0,0
0,0,0,0,0,0,0,28,28,28,28,0,0,0,0,0,0,0,0,0
0,0,0,0,0,0,32,14,1,1,1,14,31,0,0,0,0,0,0,0
0,0,0,0,0,0,1,1,1,1,1,1,1,0,0,0,0,0,0,0
0,0,0,0,0,1,1,1,1,1,1,1,1,1,0,0,0,0,0,0
0,0,0,0,14,1,1,1,1,1,1,1,1,1,14,0,0,0,0,0
0,0,0,0,1,1,1,1,1,1,1,1,1,1,1,0,0,0,0,0
0,0,0,0,1,1,1,1,1,1,1,1,1,1,1,0,22,0,0,0
0,0,0,0,1,1,1,1,1,1,1,1,1,1,1,22,22,0,0,0
0,0,0,0,14,1,1,1,1,1,1,1,1,1,15,23,31,0,0,0
0,0,0,0,0,1,1,1,1,1,1,1,1,1,23,0,0,22,0,0
0,0,0,0,0,0,1,1,1,1,1,1,1,0,0,0,0,0,0,0
0,0,0,0,0,0,0,14,1,1,1,14,0,0,0,0,0,0,0,0
0,0,0,0,0,0,0,0,0,0,0,22,0,0,0,0,0,0,0,0
0,0,0,0,0,0,0,0,0,0,27,27,0,0,0,0,0,0,0,0
0,0,0,0,0,0,0,0,0,0,0,0,0,0,0,0,0,0,0,0
0,0,0,0,0,0,0,0,0,0,0,0,0,0,0,0,0,0,0,0
0,0,0,0,0,0,0,0,0,0,0,0,0,0,0,0,0,0,0,0
0,0,0,0,0,0,0,0,0,0,0,0,0,0,0,0,0,0,0,0
0,0,0,0,0,0,0,0,0,0,0,0,0,0,0,0,0,0,0,0
0,0,0,0,0,0,0,0,0,0,0,0,0,0,0,0,0,0,0,0
0,0,0,0,0,0,0,0,0,0,0,0,0,0,0,0,0,0,0,0
0,0,0,0,0,0,0,0,0,0,0,0,0,0,0,0,0,0,0,0
:endlayer
layer: 45
0,0,0,0,0,0,0,0,0,0,0,0,0,0,0,0,0,0,0,0
0,0,0,0,0,0,0,0,0,0,0,0,0,0,0,0,0,0,0,0
0,0,0,0,0,0,0,0,0,0,0,0,0,0,0,0,0,0,0,0
0,0,0,0,0,0,0,0,0,0,0,0,0,0,0,0,0,0,0,0
0,0,0,0,0,0,0,0,0,0,0,0,0,0,0,0,0,0,0,0
0,0,0,0,0,0,0,0,0,0,0,0,0,0,0,0,0,0,0,0
0,0,0,0,0,0,0,28,28,28,28,0,0,0,0,0,0,0,0,0
0,0,0,0,0,0,28,0,1,1,1,15,31,0,0,0,0,0,0,0
0,0,0,0,0,0,1,1,1,1,1,1,1,0,0,0,0,0,0,0
0,0,0,0,0,1,1,1,1,1,1,1,1,1,0,0,0,0,0,0
0,0,0,0,0,1,1,1,1,1,1,1,1,1,15,0,0,0,0,0
0,0,0,0,1,1,1,1,1,1,1,1,1,1,33,0,0,0,0,0
0,0,0,0,1,1,1,1,1,1,1,1,1,1,33,0,22,0,0,0
0,0,0,0,14,1,1,1,1,1,1,1,1,1,1,0,22,0,0,0
0,0,0,0,0,1,1,1,1,1,1,1,1,1,0,23,31,0,0,0
0,0,0,0,0,1,1,1,1,1,1,1,1,1,23,0,0,22,0,0
0,0,0,0,0,0,1,1,1,1,1,1,1,0,0,0,0,0,0,0
0,0,0,0,0,0,0,0,1,1,1,0,0,0,0,0,0,0,0,0
0,0,0,0,0,0,0,0,0,0,0,22,0,0,0,0,0,0,0,0
0,0,0,0,0,0,0,0,0,0,27,27,0,0,0,0,0,0,0,0
0,0,0,0,0,0,0,0,0,0,0,0,0,0,0,0,0,0,0,0
0,0,0,0,0,0,0,0,0,0,0,0,0,0,0,0,0,0,0,0
0,0,0,0,0,0,0,0,0,0,0,0,0,0,0,0,0,0,0,0
0,0,0,0,0,0,0,0,0,0,0,0,0,0,0,0,0,0,0,0
0,0,0,0,0,0,0,0,0,0,0,0,0,0,0,0,0,0,0,0
0,0,0,0,0,0,0,0,0,0,0,0,0,0,0,0,0,0,0,0
0,0,0,0,0,0,0,0,0,0,0,0,0,0,0,0,0,0,0,0
0,0,0,0,0,0,0,0,0,0,0,0,0,0,0,0,0,0,0,0
:endlayer
layer: 46
0,0,0,0,0,0,0,0,0,0,0,0,0,0,0,0,0,0,0,0
0,0,0,0,0,0,0,0,0,0,0,0,0,0,0,0,0,0,0,0
0,0,0,0,0,0,0,0,0,0,0,0,0,0,0,0,0,0,0,0
0,0,0,0,0,0,0,0,0,0,0,0,0,0,0,0,0,0,0,0
0,0,0,0,0,0,0,0,0,0,0,0,0,0,0,0,0,0,0,0
0,0,0,0,0,0,0,0,0,0,0,0,0,0,0,0,0,0,0,0
0,0,0,0,0,0,0,28,28,28,28,0,0,0,0,0,0,0,0,0
0,0,0,0,0,0,0,1,1,1,1,1,22,0,0,0,0,0,0,0
0,0,0,0,0,0,1,1,1,1,1,1,1,0,0,0,0,0,0,0
0,0,0,0,0,1,1,1,1,1,1,1,1,1,0,0,0,0,0,0
0,0,0,0,1,1,1,1,1,1,1,1,1,1,33,0,0,0,0,0
0,0,0,0,1,1,1,1,1,1,1,1,1,1,33,0,0,0,0,0
0,0,0,0,1,1,1,1,1,1,1,1,1,1,1,0,22,0,0,0
0,0,0,0,0,1,1,1,1,1,1,1,1,1,33,0,22,0,0,0
0,0,0,0,0,1,1,1,1,1,1,1,1,1,1,23,31,0,0,0
0,0,0,0,0,1,1,1,1,1,1,1,1,1,23,0,0,22,0,0
0,0,0,0,0,0,1,1,1,1,1,1,1,0,0,0,0,0,0,0
0,0,0,0,0,0,0,1,1,1,1,0,0,0,0,0,0,0,0,0
0,0,0,0,0,0,0,0,0,0,0,22,0,0,0,0,0,0,0,0
0,0,0,0,0,0,0,0,0,0,27,27,0,0,0,0,0,0,0,0
0,0,0,0,0,0,0,0,0,0,0,0,0,0,0,0,0,0,0,0
0,0,0,0,0,0,0,0,0,0,0,0,0,0,0,0,0,0,0,0
0,0,0,0,0,0,0,0,0,0,0,0,0,0,0,0,0,0,0,0
0,0,0,0,0,0,0,0,0,0,0,0,0,0,0,0,0,0,0,0
0,0,0,0,0,0,0,0,0,0,0,0,0,0,0,0,0,0,0,0
0,0,0,0,0,0,0,0,0,0,0,0,0,0,0,0,0,0,0,0
0,0,0,0,0,0,0,0,0,0,0,0,0,0,0,0,0,0,0,0
0,0,0,0,0,0,0,0,0,0,0,0,0,0,0,0,0,0,0,0
:endlayer
layer: 47
0,0,0,0,0,0,0,0,0,0,0,0,0,0,0,0,0,0,0,0
0,0,0,0,0,0,0,0,0,0,0,0,0,0,0,0,0,0,0,0
0,0,0,0,0,0,0,0,0,0,0,0,0,0,0,0,0,0,0,0
0,0,0,0,0,0,0,0,0,0,0,0,0,0,0,0,0,0,0,0
0,0,0,0,0,0,0,0,0,0,0,0,0,0,0,0,0,0,0,0
0,0,0,0,0,0,0,0,0,0,0,0,0,0,0,0,0,0,0,0
0,0,0,0,0,0,0,28,28,28,28,0,0,0,0,0,0,0,0,0
0,0,0,0,0,0,0,1,1,1,1,1,0,0,0,0,0,0,0,0
0,0,0,0,0,0,1,1,1,1,1,1,1,0,0,0,0,0,0,0
0,0,0,0,0,1,1,1,1,1,1,1,1,1,0,0,0,0,0,0
0,0,0,0,1,1,1,1,1,1,1,1,1,1,33,0,0,0,0,0
0,0,0,0,1,1,1,1,1,1,1,1,1,1,1,0,0,0,0,0
0,0,0,0,1,1,1,1,1,1,1,1,1,1,1,0,22,0,0,0
0,0,0,0,0,1,1,1,1,1,1,1,1,1,33,0,22,0,0,0
0,0,0,0,0,1,1,1,1,1,1,1,1,1,1,27,31,0,0,0
0,0,0,0,0,1,1,1,1,1,1,1,1,1,23,0,0,22,0,0
0,0,0,0,0,0,1,1,1,1,1,1,1,0,0,0,0,0,0,0
0,0,0,0,0,0,0,1,1,1,1,1,0,0,0,0,0,0,0,0
0,0,0,0,0,0,0,0,0,0,0,22,0,0,0,0,0,0,0,0
0,0,0,0,0,0,0,0,0,0,27,27,0,0,0,0,0,0,0,0
0,0,0,0,0,0,0,0,0,0,0,0,0,0,0,0,0,0,0,0
0,0,0,0,0,0,0,0,0,0,0,0,0,0,0,0,0,0,0,0
0,0,0,0,0,0,0,0,0,0,0,0,0,0,0,0,0,0,0,0
0,0,0,0,0,0,0,0,0,0,0,0,0,0,0,0,0,0,0,0
0,0,0,0,0,0,0,0,0,0,0,0,0,0,0,0,0,0,0,0
0,0,0,0,0,0,0,0,0,0,0,0,0,0,0,0,0,0,0,0
0,0,0,0,0,0,0,0,0,0,0,0,0,0,0,0,0,0,0,0
0,0,0,0,0,0,0,0,0,0,0,0,0,0,0,0,0,0,0,0
:endlayer
layer: 48
0,0,0,0,0,0,0,0,0,0,0,0,0,0,0,0,0,0,0,0
0,0,0,0,0,0,0,0,0,0,0,0,0,0,0,0,0,0,0,0
0,0,0,0,0,0,0,0,0,0,0,0,0,0,0,0,0,0,0,0
0,0,0,0,0,0,0,0,0,0,0,0,0,0,0,0,0,0,0,0
0,0,0,0,0,0,0,0,0,0,0,0,0,0,0,0,0,0,0,0
0,0,0,0,0,0,0,0,0,0,0,0,0,0,0,0,0,0,0,0
0,0,0,0,0,0,0,28,28,28,28,0,0,0,0,0,0,0,0,0
0,0,0,0,0,0,0,14,1,1,1,14,0,0,0,0,0,0,0,0
0,0,0,0,0,0,1,1,1,1,1,1,1,0,0,0,0,0,0,0
0,0,0,0,0,1,1,1,1,1,1,1,1,1,0,0,0,0,0,0
0,0,0,0,14,1,1,1,1,1,1,1,1,1,1,0,0,0,0,0
0,0,0,0,1,1,1,1,1,1,1,1,1,1,33,0,0,0,0,0
0,0,0,0,1,1,1,1,1,1,1,1,1,1,33,0,22,0,0,0
0,0,0,0,1,1,1,1,1,1,1,1,1,1,1,0,22,0,0,0
0,0,0,0,1,1,1,1,1,1,1,1,1,1,1,27,31,0,0,0
0,0,0,0,0,1,1,1,1,1,1,1,1,1,23,0,0,22,0,0
0,0,0,0,0,0,1,1,1,1,1,1,1,0,0,0,0,0,0,0
0,0,0,0,0,0,0,1,1,1,1,14,0,0,0,0,0,0,0,0
0,0,0,0,0,0,0,0,0,0,0,22,0,0,0,0,0,0,0,0
0,0,0,0,0,0,0,0,0,0,27,27,0,0,0,0,0,0,0,0
0,0,0,0,0,0,0,0,0,0,0,0,0,0,0,0,0,0,0,0
0,0,0,0,0,0,0,0,0,0,0,0,0,0,0,0,0,0,0,0
0,0,0,0,0,0,0,0,0,0,0,0,0,0,0,0,0,0,0,0
0,0,0,0,0,0,0,0,0,0,0,0,0,0,0,0,0,0,0,0
0,0,0,0,0,0,0,0,0,0,0,0,0,0,0,0,0,0,0,0
0,0,0,0,0,0,0,0,0,0,0,0,0,0,0,0,0,0,0,0
0,0,0,0,0,0,0,0,0,0,0,0,0,0,0,0,0,0,0,0
0,0,0,0,0,0,0,0,0,0,0,0,0,0,0,0,0,0,0,0
:endlayer
layer: 49
0,0,0,0,0,0,0,0,0,0,0,0,0,0,0,0,0,0,0,0
0,0,0,0,0,0,0,0,0,0,0,0,0,0,0,0,0,0,0,0
0,0,0,0,0,0,0,0,0,0,0,0,0,0,0,0,0,0,0,0
0,0,0,0,0,0,0,0,0,0,0,0,0,0,0,0,0,0,0,0
0,0,0,0,0,0,0,0,0,0,0,0,0,0,0,0,0,0,0,0
0,0,0,0,0,0,0,0,0,0,0,0,0,0,0,0,0,0,0,0
0,0,0,0,0,0,0,0,28,28,28,0,0,0,0,0,0,0,0,0
0,0,0,0,0,0,0,20,1,1,1,15,0,0,0,0,0,0,0,0
0,0,0,0,0,0,14,1,1,1,1,1,1,0,0,0,0,0,0,0
0,0,0,0,0,14,1,1,1,1,1,1,1,1,0,0,0,0,0,0
0,0,0,0,15,1,1,1,1,1,1,1,1,1,1,0,0,0,0,0
0,0,0,0,1,1,1,1,1,1,1,1,1,1,1,0,0,0,0,0
0,0,0,0,1,1,1,1,1,1,1,1,1,1,1,0,22,0,0,0
0,0,0,0,1,1,1,1,1,1,1,1,1,1,1,0,22,0,0,0
0,0,0,0,14,1,1,1,1,1,1,1,1,1,1,27,31,0,0,0
0,0,0,0,0,1,1,1,1,1,1,1,1,1,23,0,0,22,0,0
0,0,0,0,0,0,1,1,1,1,1,1,1,0,0,0,0,0,0,0
0,0,0,0,0,0,0,14,1,1,1,0,0,0,0,0,0,0,0,0
0,0,0,0,0,0,0,0,0,0,0,22,0,0,0,0,0,0,0,0
0,0,0,0,0,0,0,0,0,0,27,27,0,0,0,0,0,0,0,0
0,0,0,0,0,0,0,0,0,0,0,0,0,0,0,0,0,0,0,0
0,0,0,0,0,0,0,0,0,0,0,0,0,0,0,0,0,0,0,0
0,0,0,0,0,0,0,0,0,0,0,0,0,0,0,0,0,0,0,0
0,0,0,0,0,0,0,0,0,0,0,0,0,0,0,0,0,0,0,0
0,0,0,0,0,0,0,0,0,0,0,0,0,0,0,0,0,0,0,0
0,0,0,0,0,0,0,0,0,0,0,0,0,0,0,0,0,0,0,0
0,0,0,0,0,0,0,0,0,0,0,0,0,0,0,0,0,0,0,0
0,0,0,0,0,0,0,0,0,0,0,0,0,0,0,0,0,0,0,0
:endlayer
layer: 50
0,0,0,0,0,0,0,0,0,0,0,0,0,0,0,0,0,0,0,0
0,0,0,0,0,0,0,0,0,0,0,0,0,0,0,0,0,0,0,0
0,0,0,0,0,0,0,0,0,0,0,0,0,0,0,0,0,0,0,0
0,0,0,0,0,0,0,0,0,0,0,0,0,0,0,0,0,0,0,0
0,0,0,0,0,0,0,0,0,0,0,0,0,0,0,0,0,0,0,0
0,0,0,0,0,0,0,0,0,0,0,0,0,0,0,0,0,0,0,0
0,0,0,0,0,0,0,0,28,28,28,0,0,0,0,0,0,0,0,0
0,0,0,0,0,0,0,0,14,1,1,1,0,0,0,0,0,0,0,0
0,0,0,0,0,0,15,1,1,1,1,1,1,1,0,0,0,0,0,0
0,0,0,0,0,15,1,1,1,1,1,1,1,1,1,0,0,0,0,0
0,0,0,0,0,1,1,1,1,1,1,1,1,1,1,0,0,0,0,0
0,0,0,0,14,1,1,1,1,1,1,1,1,1,1,1,0,0,0,0
0,0,0,0,14,1,1,1,1,1,1,1,1,1,1,0,22,0,0,0
0,0,0,0,14,1,1,1,1,1,1,1,1,1,1,0,22,0,0,0
0,0,0,0,0,1,1,1,1,1,1,1,1,1,1,27,31,0,0,0
0,0,0,0,0,14,1,1,1,1,1,1,1,1,1,0,0,22,0,0
0,0,0,0,0,0,14,1,1,1,1,1,1,1,0,0,0,0,0,0
0,0,0,0,0,0,0,15,14,1,1,0,0,0,0,0,0,0,0,0
0,0,0,0,0,0,0,0,0,0,0,22,0,0,0,0,0,0,0,0
0,0,0,0,0,0,0,0,0,0,27,27,0,0,0,0,0,0,0,0
0,0,0,0,0,0,0,0,0,0,0,0,0,0,0,0,0,0,0,0
0,0,0,0,0,0,0,0,0,0,0,0,0,0,0,0,0,0,0,0
0,0,0,0,0,0,0,0,0,0,0,0,0,0,0,0,0,0,0,0
0,0,0,0,0,0,0,0,0,0,0,0,0,0,0,0,0,0,0,0
0,0,0,0,0,0,0,0,0,0,0,0,0,0,0,0,0,0,0,0
0,0,0,0,0,0,0,0,0,0,0,0,0,0,0,0,0,0,0,0
0,0,0,0,0,0,0,0,0,0,0,0,0,0,0,0,0,0,0,0
0,0,0,0,0,0,0,0,0,0,0,0,0,0,0,0,0,0,0,0
:endlayer
layer: 51
0,0,0,0,0,0,0,0,0,0,0,0,0,0,0,0,0,0,0,0
0,0,0,0,0,0,0,0,0,0,0,0,0,0,0,0,0,0,0,0
0,0,0,0,0,0,0,0,0,0,0,0,0,0,0,0,0,0,0,0
0,0,0,0,0,0,0,0,0,0,0,0,0,0,0,0,0,0,0,0
0,0,0,0,0,0,0,0,0,0,0,0,0,0,0,0,0,0,0,0
0,0,0,0,0,0,0,0,0,0,0,0,0,0,0,0,0,0,0,0
0,0,0,0,0,0,0,0,0,28,28,0,0,0,0,0,0,0,0,0
0,0,0,0,0,0,0,0,15,1,1,1,1,0,0,0,0,0,0,0
0,0,0,0,0,0,0,1,1,1,1,1,1,1,0,0,0,0,0,0
0,0,0,0,0,0,1,1,1,1,1,1,1,1,1,0,0,0,0,0
0,0,0,0,0,1,1,1,1,1,1,1,1,1,1,1,0,0,0,0
0,0,0,0,15,1,1,1,1,1,1,1,1,1,1,1,0,0,0,0
0,0,0,0,15,1,1,1,1,1,1,1,1,1,1,1,22,0,0,0
0,0,0,0,15,1,1,1,1,1,1,1,1,1,1,0,22,0,0,0
0,0,0,0,0,1,1,1,1,1,1,1,1,1,1,27,31,0,0,0
0,0,0,0,0,15,1,1,1,1,1,1,1,1,1,0,0,22,0,0
0,0,0,0,0,0,15,1,1,1,1,1,1,1,0,0,0,0,0,0
0,0,0,0,0,0,0,0,15,1,1,0,0,0,0,0,0,0,0,0
0,0,0,0,0,0,0,0,0,0,0,22,0,0,0,0,0,0,0,0
0,0,0,0,0,0,0,0,0,0,27,27,0,0,0,0,0,0,0,0
0,0,0,0,0,0,0,0,0,0,0,0,0,0,0,0,0,0,0,0
0,0,0,0,0,0,0,0,0,0,0,0,0,0,0,0,0,0,0,0
0,0,0,0,0,0,0,0,0,0,0,0,0,0,0,0,0,0,0,0
0,0,0,0,0,0,0,0,0,0,0,0,0,0,0,0,0,0,0,0
0,0,0,0,0,0,0,0,0,0,0,0,0,0,0,0,0,0,0,0
0,0,0,0,0,0,0,0,0,0,0,0,0,0,0,0,0,0,0,0
0,0,0,0,0,0,0,0,0,0,0,0,0,0,0,0,0,0,0,0
0,0,0,0,0,0,0,0,0,0,0,0,0,0,0,0,0,0,0,0
:endlayer
layer: 52
0,0,0,0,0,0,0,0,0,0,0,0,0,0,0,0,0,0,0,0
0,0,0,0,0,0,0,0,0,0,0,0,0,0,0,0,0,0,0,0
0,0,0,0,0,0,0,0,0,0,0,0,0,0,0,0,0,0,0,0
0,0,0,0,0,0,0,0,0,0,0,0,0,0,0,0,0,0,0,0
0,0,0,0,0,0,0,0,0,0,0,0,0,0,0,0,0,0,0,0
0,0,0,0,0,0,0,0,0,0,0,0,0,0,0,0,0,0,0,0
0,0,0,0,0,0,0,0,0,28,28,0,0,0,0,0,0,0,0,0
0,0,0,0,0,0,0,0,1,1,1,1,1,0,0,0,0,0,0,0
0,0,0,0,0,0,0,1,1,1,1,1,1,1,0,0,0,0,0,0
0,0,0,0,0,0,1,1,1,1,1,1,1,1,1,0,0,0,0,0
0,0,0,0,0,1,1,1,1,1,1,1,1,1,1,1,0,0,0,0
0,0,0,0,0,1,1,1,1,1,1,1,1,1,1,1,0,0,0,0
0,0,0,0,0,1,1,1,1,1,1,1,1,1,1,1,22,0,0,0
0,0,0,0,0,1,1,1,1,1,1,1,1,1,1,1,22,0,0,0
0,0,0,0,0,1,1,1,1,1,1,1,1,1,1,27,31,0,0,0
0,0,0,0,0,0,1,1,1,1,1,1,1,1,1,0,0,22,0,0
0,0,0,0,0,0,0,1,1,1,1,1,1,1,0,0,0,0,0,0
0,0,0,0,0,0,0,0,1,1,1,1,0,0,0,0,0,0,0,0
0,0,0,0,0,0,0,0,0,0,0,22,0,0,0,0,0,0,0,0
0,0,0,0,0,0,0,0,0,0,27,27,0,0,0,0,0,0,0,0
0,0,0,0,0,0,0,0,0,0,0,0,0,0,0,0,0,0,0,0
0,0,0,0,0,0,0,0,0,0,0,0,0,0,0,0,0,0,0,0
0,0,0,0,0,0,0,0,0,0,0,0,0,0,0,0,0,0,0,0
0,0,0,0,0,0,0,0,0,0,0,0,0,0,0,0,0,0,0,0
0,0,0,0,0,0,0,0,0,0,0,0,0,0,0,0,0,0,0,0
0,0,0,0,0,0,0,0,0,0,0,0,0,0,0,0,0,0,0,0
0,0,0,0,0,0,0,0,0,0,0,0,0,0,0,0,0,0,0,0
0,0,0,0,0,0,0,0,0,0,0,0,0,0,0,0,0,0,0,0
:endlayer
layer: 53
0,0,0,0,0,0,0,0,0,0,0,0,0,0,0,0,0,0,0,0
0,0,0,0,0,0,0,0,0,0,0,0,0,0,0,0,0,0,0,0
0,0,0,0,0,0,0,0,0,0,0,0,0,0,0,0,0,0,0,0
0,0,0,0,0,0,0,0,0,0,0,0,0,0,0,0,0,0,0,0
0,0,0,0,0,0,0,0,0,0,0,0,0,0,0,0,0,0,0,0
0,0,0,0,0,0,0,0,0,0,0,0,0,0,0,0,0,0,0,0
0,0,0,0,0,0,0,0,0,28,28,0,0,0,0,0,0,0,0,0
0,0,0,0,0,0,0,0,14,1,1,1,14,0,0,0,0,0,0,0
0,0,0,0,0,0,0,1,1,1,1,1,1,1,0,0,0,0,0,0
0,0,0,0,0,0,1,1,1,1,1,1,1,1,1,0,0,0,0,0
0,0,0,0,0,1,1,1,1,1,1,1,1,1,1,14,0,0,0,0
0,0,0,0,0,1,1,1,1,1,1,1,1,1,1,1,0,0,0,0
0,0,0,0,0,1,1,1,1,1,1,1,1,1,1,1,22,0,0,0
0,0,0,0,0,1,1,1,1,1,1,1,1,1,1,1,22,0,0,0
0,0,0,0,0,1,1,1,1,1,1,1,1,1,1,1,31,0,0,0
0,0,0,0,0,0,1,1,1,1,1,1,1,1,1,0,0,22,0,0
0,0,0,0,0,0,0,1,1,1,1,1,1,1,0,0,0,0,0,0
0,0,0,0,0,0,0,0,1,1,1,1,1,0,0,0,0,0,0,0
0,0,0,0,0,0,0,0,0,0,0,22,0,0,0,0,0,0,0,0
0,0,0,0,0,0,0,0,0,0,27,27,0,0,0,0,0,0,0,0
0,0,0,0,0,0,0,0,0,0,0,0,0,0,0,0,0,0,0,0
0,0,0,0,0,0,0,0,0,0,0,0,0,0,0,0,0,0,0,0
0,0,0,0,0,0,0,0,0,0,0,0,0,0,0,0,0,0,0,0
0,0,0,0,0,0,0,0,0,0,0,0,0,0,0,0,0,0,0,0
0,0,0,0,0,0,0,0,0,0,0,0,0,0,0,0,0,0,0,0
0,0,0,0,0,0,0,0,0,0,0,0,0,0,0,0,0,0,0,0
0,0,0,0,0,0,0,0,0,0,0,0,0,0,0,0,0,0,0,0
0,0,0,0,0,0,0,0,0,0,0,0,0,0,0,0,0,0,0,0
:endlayer
layer: 54
0,0,0,0,0,0,0,0,0,0,0,0,0,0,0,0,0,0,0,0
0,0,0,0,0,0,0,0,0,0,0,0,0,0,0,0,0,0,0,0
0,0,0,0,0,0,0,0,0,0,0,0,0,0,0,0,0,0,0,0
0,0,0,0,0,0,0,0,0,0,0,0,0,0,0,0,0,0,0,0
0,0,0,0,0,0,0,0,0,0,0,0,0,0,0,0,0,0,0,0
0,0,0,0,0,0,0,0,0,0,0,0,0,0,0,0,0,0,0,0
0,0,0,0,0,0,0,0,0,28,28,0,0,0,0,0,0,0,0,0
0,0,0,0,0,0,0,0,32,14,14,14,0,0,0,0,0,0,0,0
0,0,0,0,0,0,0,14,1,1,1,1,1,14,0,0,0,0,0,0
0,0,0,0,0,0,1,1,1,1,1,1,1,1,14,0,0,0,0,0
0,0,0,0,0,14,1,1,1,1,1,1,1,1,1,0,0,0,0,0
0,0,0,0,0,1,1,1,1,1,1,1,1,1,1,1,0,0,0,0
0,0,0,0,0,1,1,1,1,1,1,1,1,1,1,1,22,0,0,0
0,0,0,0,0,1,1,1,1,1,1,1,1,1,1,1,22,0,0,0
0,0,0,0,0,14,1,1,1,1,1,1,1,1,1,34,31,0,0,0
0,0,0,0,0,0,1,1,1,1,1,1,1,1,1,0,0,22,0,0
0,0,0,0,0,0,0,1,1,1,1,1,1,1,0,0,0,0,0,0
0,0,0,0,0,0,0,0,1,1,1,1,1,0,0,0,0,0,0,0
0,0,0,0,0,0,0,0,0,0,0,22,0,0,0,0,0,0,0,0
0,0,0,0,0,0,0,0,0,0,27,27,0,0,0,0,0,0,0,0
0,0,0,0,0,0,0,0,0,0,0,0,0,0,0,0,0,0,0,0
0,0,0,0,0,0,0,0,0,0,0,0,0,0,0,0,0,0,0,0
0,0,0,0,0,0,0,0,0,0,0,0,0,0,0,0,0,0,0,0
0,0,0,0,0,0,0,0,0,0,0,0,0,0,0,0,0,0,0,0
0,0,0,0,0,0,0,0,0,0,0,0,0,0,0,0,0,0,0,0
0,0,0,0,0,0,0,0,0,0,0,0,0,0,0,0,0,0,0,0
0,0,0,0,0,0,0,0,0,0,0,0,0,0,0,0,0,0,0,0
0,0,0,0,0,0,0,0,0,0,0,0,0,0,0,0,0,0,0,0
:endlayer
layer: 55
0,0,0,0,0,0,0,0,0,0,0,0,0,0,0,0,0,0,0,0
0,0,0,0,0,0,0,0,0,0,0,0,0,0,0,0,0,0,0,0
0,0,0,0,0,0,0,0,0,0,0,0,0,0,0,0,0,0,0,0
0,0,0,0,0,0,0,0,0,0,0,0,0,0,0,0,0,0,0,0
0,0,0,0,0,0,0,0,0,0,0,0,0,0,0,0,0,0,0,0
0,0,0,0,0,0,0,0,0,0,0,0,0,0,0,0,0,0,0,0
0,0,0,0,0,0,0,0,0,0,0,0,0,0,0,0,0,0,0,0
0,0,0,0,0,0,0,0,28,31,35,28,0,0,0,0,0,0,0,0
0,0,0,0,0,0,0,0,1,1,1,1,1,0,0,0,0,0,0,0
0,0,0,0,0,0,14,1,1,1,1,1,1,1,0,0,0,0,0,0
0,0,0,0,0,0,1,1,1,1,1,1,1,1,1,0,0,0,0,0
0,0,0,0,0,14,1,1,1,1,1,1,1,1,1,14,0,0,0,0
0,0,0,0,0,1,1,1,1,1,1,1,1,1,1,1,22,0,0,0
0,0,0,0,0,1,1,1,1,1,1,1,1,1,1,1,22,0,0,0
0,0,0,0,0,0,1,1,1,1,1,1,1,1,1,27,31,0,0,0
0,0,0,0,0,0,1,1,1,1,1,1,1,1,1,0,0,22,0,0
0,0,0,0,0,0,1,1,1,1,1,1,1,1,1,0,0,0,0,0
0,0,0,0,0,0,0,1,1,1,1,1,1,1,0,0,0,0,0,0
0,0,0,0,0,0,0,0,0,1,0,22,0,0,0,0,0,0,0,0
0,0,0,0,0,0,0,0,0,0,27,27,0,0,0,0,0,0,0,0
0,0,0,0,0,0,0,0,0,0,0,0,0,0,0,0,0,0,0,0
0,0,0,0,0,0,0,0,0,0,0,0,0,0,0,0,0,0,0,0
0,0,0,0,0,0,0,0,0,0,0,0,0,0,0,0,0,0,0,0
0,0,0,0,0,0,0,0,0,0,0,0,0,0,0,0,0,0,0,0
0,0,0,0,0,0,0,0,0,0,0,0,0,0,0,0,0,0,0,0
0,0,0,0,0,0,0,0,0,0,0,0,0,0,0,0,0,0,0,0
0,0,0,0,0,0,0,0,0,0,0,0,0,0,0,0,0,0,0,0
0,0,0,0,0,0,0,0,0,0,0,0,0,0,0,0,0,0,0,0
:endlayer
layer: 56
0,0,0,0,0,0,0,0,0,0,0,0,0,0,0,0,0,0,0,0
0,0,0,0,0,0,0,0,0,0,0,0,0,0,0,0,0,0,0,0
0,0,0,0,0,0,0,0,0,0,0,0,0,0,0,0,0,0,0,0
0,0,0,0,0,0,0,0,0,0,0,0,0,0,0,0,0,0,0,0
0,0,0,0,0,0,0,0,0,0,0,0,0,0,0,0,0,0,0,0
0,0,0,0,0,0,0,0,0,0,0,0,0,0,0,0,0,0,0,0
0,0,0,0,0,0,0,0,0,0,0,0,0,0,0,0,0,0,0,0
0,0,0,0,0,0,0,0,28,31,35,28,0,0,0,0,0,0,0,0
0,0,0,0,0,0,0,0,1,1,1,1,1,0,0,0,0,0,0,0
0,0,0,0,0,0,0,1,1,1,1,1,1,1,0,0,0,0,0,0
0,0,0,0,0,0,1,1,1,1,1,1,1,1,1,0,0,0,0,0
0,0,0,0,0,0,1,1,1,1,1,1,1,1,1,0,0,0,0,0
0,0,0,0,0,1,1,1,1,1,1,1,1,1,1,1,22,0,0,0
0,0,0,0,0,1,1,1,1,1,1,1,1,1,1,1,22,0,0,0
0,0,0,0,0,0,1,1,1,1,1,1,1,1,1,1,31,0,0,0
0,0,0,0,0,0,1,1,1,1,1,1,1,1,1,0,0,22,0,0
0,0,0,0,0,0,1,1,1,1,1,1,1,1,1,0,0,0,0,0
0,0,0,0,0,0,0,1,1,1,1,1,1,1,0,0,0,0,0,0
0,0,0,0,0,0,0,0,0,1,0,22,0,0,0,0,0,0,0,0
0,0,0,0,0,0,0,0,0,0,27,27,0,0,0,0,0,0,0,0
0,0,0,0,0,0,0,0,0,0,0,0,0,0,0,0,0,0,0,0
0,0,0,0,0,0,0,0,0,0,0,0,0,0,0,0,0,0,0,0
0,0,0,0,0,0,0,0,0,0,0,0,0,0,0,0,0,0,0,0
0,0,0,0,0,0,0,0,0,0,0,0,0,0,0,0,0,0,0,0
0,0,0,0,0,0,0,0,0,0,0,0,0,0,0,0,0,0,0,0
0,0,0,0,0,0,0,0,0,0,0,0,0,0,0,0,0,0,0,0
0,0,0,0,0,0,0,0,0,0,0,0,0,0,0,0,0,0,0,0
0,0,0,0,0,0,0,0,0,0,0,0,0,0,0,0,0,0,0,0
:endlayer
layer: 57
0,0,0,0,0,0,0,0,0,0,0,0,0,0,0,0,0,0,0,0
0,0,0,0,0,0,0,0,0,0,0,0,0,0,0,0,0,0,0,0
0,0,0,0,0,0,0,0,0,0,0,0,0,0,0,0,0,0,0,0
0,0,0,0,0,0,0,0,0,0,0,0,0,0,0,0,0,0,0,0
0,0,0,0,0,0,0,0,0,0,0,0,0,0,0,0,0,0,0,0
0,0,0,0,0,0,0,0,0,0,0,0,0,0,0,0,0,0,0,0
0,0,0,0,0,0,0,0,0,0,0,0,0,0,0,0,0,0,0,0
0,0,0,0,0,0,0,0,28,31,35,28,0,0,0,0,0,0,0,0
0,0,0,0,0,0,0,0,1,1,1,1,1,0,0,0,0,0,0,0
0,0,0,0,0,0,0,1,1,1,1,1,1,1,0,0,0,0,0,0
0,0,0,0,0,0,1,1,1,1,1,1,1,1,1,0,0,0,0,0
0,0,0,0,0,1,1,1,1,1,1,1,1,1,1,1,0,0,0,0
0,0,0,0,0,1,1,1,1,1,1,1,1,1,1,1,22,0,0,0
0,0,0,0,0,1,1,1,1,1,1,1,1,1,1,1,22,0,0,0
0,0,0,0,0,0,1,1,1,1,1,1,1,1,1,1,31,0,0,0
0,0,0,0,0,0,1,1,1,1,1,1,1,1,1,1,0,22,0,0
0,0,0,0,0,0,1,1,1,1,1,1,1,1,1,0,0,0,0,0
0,0,0,0,0,0,0,1,1,1,1,1,1,1,0,0,0,0,0,0
0,0,0,0,0,0,0,0,0,1,1,22,0,0,0,0,0,0,0,0
0,0,0,0,0,0,0,0,0,0,27,27,0,0,0,0,0,0,0,0
0,0,0,0,0,0,0,0,0,0,0,0,0,0,0,0,0,0,0,0
0,0,0,0,0,0,0,0,0,0,0,0,0,0,0,0,0,0,0,0
0,0,0,0,0,0,0,0,0,0,0,0,0,0,0,0,0,0,0,0
0,0,0,0,0,0,0,0,0,0,0,0,0,0,0,0,0,0,0,0
0,0,0,0,0,0,0,0,0,0,0,0,0,0,0,0,0,0,0,0
0,0,0,0,0,0,0,0,0,0,0,0,0,0,0,0,0,0,0,0
0,0,0,0,0,0,0,0,0,0,0,0,0,0,0,0,0,0,0,0
0,0,0,0,0,0,0,0,0,0,0,0,0,0,0,0,0,0,0,0
:endlayer
layer: 58
0,0,0,0,0,0,0,0,0,0,0,0,0,0,0,0,0,0,0,0
0,0,0,0,0,0,0,0,0,0,0,0,0,0,0,0,0,0,0,0
0,0,0,0,0,0,0,0,0,0,0,0,0,0,0,0,0,0,0,0
0,0,0,0,0,0,0,0,0,0,0,0,0,0,0,0,0,0,0,0
0,0,0,0,0,0,0,0,0,0,0,0,0,0,0,0,0,0,0,0
0,0,0,0,0,0,0,0,0,0,0,0,0,0,0,0,0,0,0,0
0,0,0,0,0,0,0,0,0,0,0,0,0,0,0,0,0,0,0,0
0,0,0,0,0,0,0,0,28,31,35,28,0,0,0,0,0,0,0,0
0,0,0,0,0,0,0,0,1,1,1,1,1,0,0,0,0,0,0,0
0,0,0,0,0,0,0,1,1,1,1,1,1,1,0,0,0,0,0,0
0,0,0,0,0,0,1,1,1,1,1,1,1,1,1,0,0,0,0,0
0,0,0,0,0,1,1,1,1,1,1,1,1,1,1,1,0,0,0,0
0,0,0,0,0,1,1,1,1,1,1,1,1,1,1,1,22,0,0,0
0,0,0,0,0,1,1,1,1,1,1,1,1,1,1,1,22,0,0,0
0,0,0,0,0,1,1,1,1,1,1,1,1,1,1,1,31,0,0,0
0,0,0,0,0,0,1,1,1,1,1,1,1,1,1,1,0,22,0,0
0,0,0,0,0,0,1,1,1,1,1,1,1,1,1,0,0,0,0,0
0,0,0,0,0,0,1,1,1,1,1,1,1,1,0,0,0,0,0,0
0,0,0,0,0,0,0,0,1,1,1,1,1,0,0,0,0,0,0,0
0,0,0,0,0,0,0,0,0,0,27,27,0,0,0,0,0,0,0,0
0,0,0,0,0,0,0,0,0,0,0,0,0,0,0,0,0,0,0,0
0,0,0,0,0,0,0,0,0,0,0,0,0,0,0,0,0,0,0,0
0,0,0,0,0,0,0,0,0,0,0,0,0,0,0,0,0,0,0,0
0,0,0,0,0,0,0,0,0,0,0,0,0,0,0,0,0,0,0,0
0,0,0,0,0,0,0,0,0,0,0,0,0,0,0,0,0,0,0,0
0,0,0,0,0,0,0,0,0,0,0,0,0,0,0,0,0,0,0,0
0,0,0,0,0,0,0,0,0,0,0,0,0,0,0,0,0,0,0,0
0,0,0,0,0,0,0,0,0,0,0,0,0,0,0,0,0,0,0,0
:endlayer
layer: 59
0,0,0,0,0,0,0,0,0,0,0,0,0,0,0,0,0,0,0,0
0,0,0,0,0,0,0,0,0,0,0,0,0,0,0,0,0,0,0,0
0,0,0,0,0,0,0,0,0,0,0,0,0,0,0,0,0,0,0,0
0,0,0,0,0,0,0,0,0,0,0,0,0,0,0,0,0,0,0,0
0,0,0,0,0,0,0,0,0,0,0,0,0,0,0,0,0,0,0,0
0,0,0,0,0,0,0,0,0,0,0,0,0,0,0,0,0,0,0,0
0,0,0,0,0,0,0,0,0,0,0,0,0,0,0,0,0,0,0,0
0,0,0,0,0,0,0,0,28,31,35,28,0,0,0,0,0,0,0,0
0,0,0,0,0,0,0,0,14,1,1,1,14,0,0,0,0,0,0,0
0,0,0,0,0,0,0,1,1,1,1,1,1,1,0,0,0,0,0,0
0,0,0,0,0,0,1,1,1,1,1,1,1,1,1,0,0,0,0,0
0,0,0,0,0,1,1,1,1,1,1,1,1,1,1,14,0,0,0,0
0,0,0,0,1,1,1,1,1,1,1,1,1,1,1,1,22,0,0,0
0,0,0,0,0,1,1,1,1,1,1,1,1,1,1,1,22,0,0,0
0,0,0,0,0,1,1,1,1,1,1,1,1,1,1,1,31,0,0,0
0,0,0,0,0,1,1,1,1,1,1,1,1,1,1,14,0,22,0,0
0,0,0,0,0,0,1,1,1,1,1,1,1,1,1,0,0,0,0,0
0,0,0,0,0,1,1,1,1,1,1,1,1,1,0,0,0,0,0,0
0,0,0,0,0,0,0,1,1,1,1,1,14,0,0,0,0,0,0,0
0,0,0,0,0,0,0,0,0,0,27,27,0,0,0,0,0,0,0,0
0,0,0,0,0,0,0,0,0,0,0,0,0,0,0,0,0,0,0,0
0,0,0,0,0,0,0,0,0,0,0,0,0,0,0,0,0,0,0,0
0,0,0,0,0,0,0,0,0,0,0,0,0,0,0,0,0,0,0,0
0,0,0,0,0,0,0,0,0,0,0,0,0,0,0,0,0,0,0,0
0,0,0,0,0,0,0,0,0,0,0,0,0,0,0,0,0,0,0,0
0,0,0,0,0,0,0,0,0,0,0,0,0,0,0,0,0,0,0,0
0,0,0,0,0,0,0,0,0,0,0,0,0,0,0,0,0,0,0,0
0,0,0,0,0,0,0,0,0,0,0,0,0,0,0,0,0,0,0,0
:endlayer
layer: 60
0,0,0,0,0,0,0,0,0,0,0,0,0,0,0,0,0,0,0,0
0,0,0,0,0,0,0,0,0,0,0,0,0,0,0,0,0,0,0,0
0,0,0,0,0,0,0,0,0,0,0,0,0,0,0,0,0,0,0,0
0,0,0,0,0,0,0,0,0,0,0,0,0,0,0,0,0,0,0,0
0,0,0,0,0,0,0,0,0,0,0,0,0,0,0,0,0,0,0,0
0,0,0,0,0,0,0,0,0,0,0,0,0,0,0,0,0,0,0,0
0,0,0,0,0,0,0,0,0,0,0,0,0,0,0,0,0,0,0,0
0,0,0,0,0,0,0,0,0,31,35,28,0,0,0,0,0,0,0,0
0,0,0,0,0,0,0,0,0,14,14,14,0,0,0,0,0,0,0,0
0,0,0,0,0,0,0,1,1,1,1,1,1,14,0,0,0,0,0,0
0,0,0,0,0,1,1,1,1,1,1,1,1,1,14,0,0,0,0,0
0,0,0,0,1,1,1,1,1,1,1,1,1,1,1,15,0,0,0,0
0,0,0,0,1,1,1,1,1,1,1,1,1,1,1,14,22,0,0,0
0,0,0,0,0,1,1,1,1,1,1,1,1,1,1,14,22,0,0,0
0,0,0,0,0,1,1,1,1,1,1,1,1,1,1,14,31,0,0,0
0,0,0,0,0,1,1,1,1,1,1,1,1,1,1,15,0,22,0,0
0,0,0,0,0,1,1,1,1,1,1,1,1,1,14,0,0,0,0,0
0,0,0,0,0,1,1,1,1,1,1,1,1,14,0,0,0,0,0,0
0,0,0,0,0,0,1,1,1,1,1,1,15,0,0,0,0,0,0,0
0,0,0,0,0,0,0,0,0,0,27,27,0,0,0,0,0,0,0,0
0,0,0,0,0,0,0,0,0,0,0,0,0,0,0,0,0,0,0,0
0,0,0,0,0,0,0,0,0,0,0,0,0,0,0,0,0,0,0,0
0,0,0,0,0,0,0,0,0,0,0,0,0,0,0,0,0,0,0,0
0,0,0,0,0,0,0,0,0,0,0,0,0,0,0,0,0,0,0,0
0,0,0,0,0,0,0,0,0,0,0,0,0,0,0,0,0,0,0,0
0,0,0,0,0,0,0,0,0,0,0,0,0,0,0,0,0,0,0,0
0,0,0,0,0,0,0,0,0,0,0,0,0,0,0,0,0,0,0,0
0,0,0,0,0,0,0,0,0,0,0,0,0,0,0,0,0,0,0,0
:endlayer
layer: 61
0,0,0,0,0,0,0,0,0,0,0,0,0,0,0,0,0,0,0,0
0,0,0,0,0,0,0,0,0,0,0,0,0,0,0,0,0,0,0,0
0,0,0,0,0,0,0,0,0,0,0,0,0,0,0,0,0,0,0,0
0,0,0,0,0,0,0,0,0,0,0,0,0,0,0,0,0,0,0,0
0,0,0,0,0,0,0,0,0,0,0,0,0,0,0,0,0,0,0,0
0,0,0,0,0,0,0,0,0,0,0,0,0,0,0,0,0,0,0,0
0,0,0,0,0,0,0,0,0,0,0,0,0,0,0,0,0,0,0,0
0,0,0,0,0,0,0,0,0,31,35,28,0,0,0,0,0,0,0,0
0,0,0,0,0,0,0,0,0,0,0,0,0,0,0,0,0,0,0,0
0,0,0,0,0,0,1,1,1,1,1,14,14,21,0,0,0,0,0,0
0,0,0,0,0,1,1,1,1,1,1,1,1,14,0,0,0,0,0,0
0,0,0,0,1,1,1,1,1,1,1,1,1,1,14,0,0,0,0,0
0,0,0,1,1,1,1,1,1,1,1,1,1,1,14,15,0,0,0,0
0,0,0,0,1,1,1,1,1,1,1,1,1,1,14,15,22,0,0,0
0,0,0,0,1,1,1,1,1,1,1,1,1,1,14,15,31,0,0,0
0,0,0,0,0,1,1,1,1,1,1,1,1,1,14,0,0,22,0,0
0,0,0,0,1,1,1,1,1,1,1,1,1,1,15,0,0,0,0,0
0,0,0,0,0,1,1,1,1,1,1,1,1,15,0,0,0,0,0,0
0,0,0,0,0,1,1,1,1,1,1,1,23,0,0,0,0,0,0,0
0,0,0,0,0,0,0,0,0,1,27,27,0,0,0,0,0,0,0,0
0,0,0,0,0,0,0,0,0,0,0,0,0,0,0,0,0,0,0,0
0,0,0,0,0,0,0,0,0,0,0,0,0,0,0,0,0,0,0,0
0,0,0,0,0,0,0,0,0,0,0,0,0,0,0,0,0,0,0,0
0,0,0,0,0,0,0,0,0,0,0,0,0,0,0,0,0,0,0,0
0,0,0,0,0,0,0,0,0,0,0,0,0,0,0,0,0,0,0,0
0,0,0,0,0,0,0,0,0,0,0,0,0,0,0,0,0,0,0,0
0,0,0,0,0,0,0,0,0,0,0,0,0,0,0,0,0,0,0,0
0,0,0,0,0,0,0,0,0,0,0,0,0,0,0,0,0,0,0,0
:endlayer
layer: 62
0,0,0,0,0,0,0,0,0,0,0,0,0,0,0,0,0,0,0,0
0,0,0,0,0,0,0,0,0,0,0,0,0,0,0,0,0,0,0,0
0,0,0,0,0,0,0,0,0,0,0,0,0,0,0,0,0,0,0,0
0,0,0,0,0,0,0,0,0,0,0,0,0,0,0,0,0,0,0,0
0,0,0,0,0,0,0,0,0,0,0,0,0,0,0,0,0,0,0,0
0,0,0,0,0,0,0,0,0,0,0,0,0,0,0,0,0,0,0,0
0,0,0,0,0,0,0,0,0,0,0,0,0,0,0,0,0,0,0,0
0,0,0,0,0,0,0,0,0,31,35,28,0,0,0,0,0,0,0,0
0,0,0,0,0,0,0,0,0,0,0,0,0,0,0,0,0,0,0,0
0,0,0,0,0,0,1,1,1,1,1,0,0,0,0,0,0,0,0,0
0,0,0,0,0,1,1,1,1,1,1,1,14,0,0,0,0,0,0,0
0,0,0,0,1,1,1,1,1,1,1,1,1,14,15,0,0,0,0,0
0,0,0,1,1,1,1,1,1,1,1,1,1,1,15,0,0,0,0,0
0,0,0,1,1,1,1,1,1,1,1,1,1,1,15,0,22,0,0,0
0,0,0,0,1,1,1,1,1,1,1,1,1,1,15,0,31,0,0,0
0,0,0,0,1,1,1,1,1,1,1,1,1,1,15,0,0,22,0,0
0,0,0,1,1,1,1,1,1,1,1,1,1,1,0,0,0,0,0,0
0,0,0,0,1,1,1,1,1,1,1,1,1,0,0,0,0,0,0,0
0,0,0,0,0,1,1,1,1,1,1,1,23,0,0,0,0,0,0,0
0,0,0,0,0,0,1,1,0,1,1,27,0,0,0,0,0,0,0,0
0,0,0,0,0,0,0,0,0,0,0,0,0,0,0,0,0,0,0,0
0,0,0,0,0,0,0,0,0,0,0,0,0,0,0,0,0,0,0,0
0,0,0,0,0,0,0,0,0,0,0,0,0,0,0,0,0,0,0,0
0,0,0,0,0,0,0,0,0,0,0,0,0,0,0,0,0,0,0,0
0,0,0,0,0,0,0,0,0,0,0,0,0,0,0,0,0,0,0,0
0,0,0,0,0,0,0,0,0,0,0,0,0,0,0,0,0,0,0,0
0,0,0,0,0,0,0,0,0,0,0,0,0,0,0,0,0,0,0,0
0,0,0,0,0,0,0,0,0,0,0,0,0,0,0,0,0,0,0,0
:endlayer
layer: 63
0,0,0,0,0,0,0,0,0,0,0,0,0,0,0,0,0,0,0,0
0,0,0,0,0,0,0,0,0,0,0,0,0,0,0,0,0,0,0,0
0,0,0,0,0,0,0,0,0,0,0,0,0,0,0,0,0,0,0,0
0,0,0,0,0,0,0,0,0,0,0,0,0,0,0,0,0,0,0,0
0,0,0,0,0,0,0,0,0,0,0,0,0,0,0,0,0,0,0,0
0,0,0,0,0,0,0,0,0,0,0,0,0,0,0,0,0,0,0,0
0,0,0,0,0,0,0,0,0,0,0,0,0,0,0,0,0,0,0,0
0,0,0,0,0,0,0,0,0,31,35,28,0,0,0,0,0,0,0,0
0,0,0,0,0,0,0,0,0,0,0,0,0,0,0,0,0,0,0,0
0,0,0,0,0,0,1,1,1,1,1,0,0,0,0,0,0,0,0,0
0,0,0,0,0,1,1,1,1,1,1,1,0,0,0,0,0,0,0,0
0,0,0,0,1,1,1,1,1,1,1,1,1,0,0,0,0,0,0,0
0,0,0,14,1,1,1,1,1,1,1,1,1,1,0,0,0,0,0,0
0,0,0,1,1,1,1,1,1,1,1,1,1,1,0,0,22,0,0,0
0,0,0,1,1,1,1,1,1,1,1,1,1,1,0,0,31,0,0,0
0,0,0,1,1,1,1,1,1,1,1,1,1,1,0,0,0,22,0,0
0,0,0,14,1,1,1,1,1,1,1,1,1,1,0,0,0,0,0,0
0,0,0,0,1,1,1,1,1,1,1,1,1,0,0,0,0,0,0,0
0,0,0,0,0,1,1,1,1,1,1,1,23,0,0,0,0,0,0,0
0,0,0,0,0,0,14,1,1,1,14,27,0,0,0,0,0,0,0,0
0,0,0,0,0,0,0,0,0,0,0,0,0,0,0,0,0,0,0,0
0,0,0,0,0,0,0,0,0,0,0,0,0,0,0,0,0,0,0,0
0,0,0,0,0,0,0,0,0,0,0,0,0,0,0,0,0,0,0,0
0,0,0,0,0,0,0,0,0,0,0,0,0,0,0,0,0,0,0,0
0,0,0,0,0,0,0,0,0,0,0,0,0,0,0,0,0,0,0,0
0,0,0,0,0,0,0,0,0,0,0,0,0,0,0,0,0,0,0,0
0,0,0,0,0,0,0,0,0,0,0,0,0,0,0,0,0,0,0,0
0,0,0,0,0,0,0,0,0,0,0,0,0,0,0,0,0,0,0,0
:endlayer
layer: 64
0,0,0,0,0,0,0,0,0,0,0,0,0,0,0,0,0,0,0,0
0,0,0,0,0,0,0,0,0,0,0,0,0,0,0,0,0,0,0,0
0,0,0,0,0,0,0,0,0,0,0,0,0,0,0,0,0,0,0,0
0,0,0,0,0,0,0,0,0,0,0,0,0,0,0,0,0,0,0,0
0,0,0,0,0,0,0,0,0,0,0,0,0,0,0,0,0,0,0,0
0,0,0,0,0,0,0,0,0,0,0,0,0,0,0,0,0,0,0,0
0,0,0,0,0,0,0,0,0,0,0,0,0,0,0,0,0,0,0,0
0,0,0,0,0,0,0,0,0,31,35,28,0,0,0,0,0,0,0,0
0,0,0,0,0,0,0,0,0,0,0,0,0,0,0,0,0,0,0,0
0,0,0,0,0,0,14,1,1,1,1,1,1,0,0,0,0,0,0,0
0,0,0,0,0,14,1,1,1,1,1,1,1,1,0,0,0,0,0,0
0,0,0,0,14,1,1,1,1,1,1,1,1,1,1,0,0,0,0,0
0,0,0,15,1,1,1,1,1,1,1,1,1,1,1,0,0,0,0,0
0,0,0,14,1,1,1,1,1,1,1,1,1,1,1,0,22,0,0,0
0,0,0,14,1,1,1,1,1,1,1,1,1,1,1,0,31,0,0,0
0,0,0,14,1,1,1,1,1,1,1,1,1,1,1,0,0,22,0,0
0,0,0,15,1,1,1,1,1,1,1,1,1,1,0,0,0,0,0,0
0,0,0,0,14,1,1,1,1,1,1,1,1,0,0,0,0,0,0,0
0,0,0,0,0,14,1,1,1,1,1,1,23,0,0,0,0,0,0,0
0,0,0,0,0,0,15,14,14,14,27,27,0,0,0,0,0,0,0,0
0,0,0,0,0,0,0,0,0,0,0,0,0,0,0,0,0,0,0,0
0,0,0,0,0,0,0,0,0,0,0,0,0,0,0,0,0,0,0,0
0,0,0,0,0,0,0,0,0,0,0,0,0,0,0,0,0,0,0,0
0,0,0,0,0,0,0,0,0,0,0,0,0,0,0,0,0,0,0,0
0,0,0,0,0,0,0,0,0,0,0,0,0,0,0,0,0,0,0,0
0,0,0,0,0,0,0,0,0,0,0,0,0,0,0,0,0,0,0,0
0,0,0,0,0,0,0,0,0,0,0,0,0,0,0,0,0,0,0,0
0,0,0,0,0,0,0,0,0,0,0,0,0,0,0,0,0,0,0,0
:endlayer
layer: 65
0,0,0,0,0,0,0,0,0,0,0,0,0,0,0,0,0,0,0,0
0,0,0,0,0,0,0,0,0,0,0,0,0,0,0,0,0,0,0,0
0,0,0,0,0,0,0,0,0,0,0,0,0,0,0,0,0,0,0,0
0,0,0,0,0,0,0,0,0,0,0,0,0,0,0,0,0,0,0,0
0,0,0,0,0,0,0,0,0,0,0,0,0,0,0,0,0,0,0,0
0,0,0,0,0,0,0,0,0,0,0,0,0,0,0,0,0,0,0,0
0,0,0,0,0,0,0,0,0,0,0,0,0,0,0,0,0,0,0,0
0,0,0,0,0,0,0,0,0,31,35,28,0,0,0,0,0,0,0,0
0,0,0,0,0,0,0,0,0,1,1,1,0,0,0,0,0,0,0,0
0,0,0,0,0,0,20,1,1,1,1,1,1,1,0,0,0,0,0,0
0,0,0,0,0,15,1,1,1,1,1,1,1,1,1,0,0,0,0,0
0,0,0,0,15,1,1,1,1,1,1,1,1,1,1,0,0,0,0,0
0,0,0,0,14,1,1,1,1,1,1,1,1,1,1,1,0,0,0,0
0,0,0,15,14,1,1,1,1,1,1,1,1,1,1,1,22,0,0,0
0,0,0,15,14,1,1,1,1,1,1,1,1,1,1,1,31,0,0,0
0,0,0,15,14,1,1,1,1,1,1,1,1,1,1,0,0,22,0,0
0,0,0,0,14,1,1,1,1,1,1,1,1,1,1,0,0,0,0,0
0,0,0,0,15,14,1,1,1,1,1,1,1,1,0,0,0,0,0,0
0,0,0,0,0,0,14,14,1,1,1,1,27,0,0,0,0,0,0,0
0,0,0,0,0,0,0,27,15,20,27,27,0,0,0,0,0,0,0,0
0,0,0,0,0,0,0,0,0,0,0,0,0,0,0,0,0,0,0,0
0,0,0,0,0,0,0,0,0,0,0,0,0,0,0,0,0,0,0,0
0,0,0,0,0,0,0,0,0,0,0,0,0,0,0,0,0,0,0,0
0,0,0,0,0,0,0,0,0,0,0,0,0,0,0,0,0,0,0,0
0,0,0,0,0,0,0,0,0,0,0,0,0,0,0,0,0,0,0,0
0,0,0,0,0,0,0,0,0,0,0,0,0,0,0,0,0,0,0,0
0,0,0,0,0,0,0,0,0,0,0,0,0,0,0,0,0,0,0,0
0,0,0,0,0,0,0,0,0,0,0,0,0,0,0,0,0,0,0,0
:endlayer
layer: 66
0,0,0,0,0,0,0,0,0,0,0,0,0,0,0,0,0,0,0,0
0,0,0,0,0,0,0,0,0,0,0,0,0,0,0,0,0,0,0,0
0,0,0,0,0,0,0,0,0,0,0,0,0,0,0,0,0,0,0,0
0,0,0,0,0,0,0,0,0,0,0,0,0,0,0,0,0,0,0,0
0,0,0,0,0,0,0,0,0,0,0,0,0,0,0,0,0,0,0,0
0,0,0,0,0,0,0,0,0,0,0,0,0,0,0,0,0,0,0,0
0,0,0,0,0,0,0,0,0,0,0,0,0,0,0,0,0,0,0,0
0,0,0,0,0,0,0,0,0,31,35,28,0,0,0,0,0,0,0,0
0,0,0,0,0,0,0,0,1,1,1,1,1,0,0,0,0,0,0,0
0,0,0,0,0,0,0,1,1,1,1,1,1,1,0,0,0,0,0,0
0,0,0,0,0,28,1,1,1,1,1,1,1,1,1,0,0,0,0,0
0,0,0,0,26,1,1,1,1,1,1,1,1,1,1,1,0,0,0,0
0,0,0,0,25,1,1,1,1,1,1,1,1,1,1,1,0,0,0,0
0,0,0,0,36,1,1,1,1,1,1,1,1,1,1,1,22,0,0,0
0,0,0,0,15,1,1,1,1,1,1,1,1,1,1,1,31,0,0,0
0,0,0,0,15,1,1,1,1,1,1,1,1,1,1,1,0,22,0,0
0,0,0,0,20,14,1,1,1,1,1,1,1,1,1,0,0,0,0,0
0,0,0,0,0,20,1,1,1,1,1,1,1,1,0,0,0,0,0,0
0,0,0,0,0,0,15,15,1,1,1,1,1,0,0,0,0,0,0,0
0,0,0,0,0,0,0,27,27,27,27,25,0,0,0,0,0,0,0,0
0,0,0,0,0,0,0,0,0,0,0,0,0,0,0,0,0,0,0,0
0,0,0,0,0,0,0,0,0,0,0,0,0,0,0,0,0,0,0,0
0,0,0,0,0,0,0,0,0,0,0,0,0,0,0,0,0,0,0,0
0,0,0,0,0,0,0,0,0,0,0,0,0,0,0,0,0,0,0,0
0,0,0,0,0,0,0,0,0,0,0,0,0,0,0,0,0,0,0,0
0,0,0,0,0,0,0,0,0,0,0,0,0,0,0,0,0,0,0,0
0,0,0,0,0,0,0,0,0,0,0,0,0,0,0,0,0,0,0,0
0,0,0,0,0,0,0,0,0,0,0,0,0,0,0,0,0,0,0,0
:endlayer
layer: 67
0,0,0,0,0,0,0,0,0,0,0,0,0,0,0,0,0,0,0,0
0,0,0,0,0,0,0,0,0,0,0,0,0,0,0,0,0,0,0,0
0,0,0,0,0,0,0,0,0,0,0,0,0,0,0,0,0,0,0,0
0,0,0,0,0,0,0,0,0,0,0,0,0,0,0,0,0,0,0,0
0,0,0,0,0,0,0,0,0,0,0,0,0,0,0,0,0,0,0,0
0,0,0,0,0,0,0,0,0,0,0,0,0,0,0,0,0,0,0,0
0,0,0,0,0,0,0,0,0,0,0,0,0,0,0,0,0,0,0,0
0,0,0,0,0,0,0,0,0,31,35,28,0,0,0,0,0,0,0,0
0,0,0,0,0,0,0,0,1,1,1,1,1,0,0,0,0,0,0,0
0,0,0,0,0,0,1,1,1,1,1,1,1,1,0,0,0,0,0,0
0,0,0,0,0,28,1,1,1,1,1,1,1,1,1,0,0,0,0,0
0,0,0,0,26,1,1,1,1,1,1,1,1,1,1,1,0,0,0,0
0,0,0,0,25,1,1,1,1,1,1,1,1,1,1,1,0,0,0,0
0,0,0,0,36,1,1,1,1,1,1,1,1,1,1,1,22,0,0,0
0,0,0,0,0,1,1,1,1,1,1,1,1,1,1,1,31,0,0,0
0,0,0,0,0,1,1,1,1,1,1,1,1,1,1,1,0,22,0,0
0,0,0,0,0,15,1,1,1,1,1,1,1,1,1,0,0,0,0,0
0,0,0,0,0,0,1,1,1,1,1,1,1,1,1,0,0,0,0,0
0,0,0,0,0,0,0,0,1,1,1,1,1,0,0,0,0,0,0,0
0,0,0,0,0,0,0,27,27,27,27,25,0,0,0,0,0,0,0,0
0,0,0,0,0,0,0,0,0,0,0,0,0,0,0,0,0,0,0,0
0,0,0,0,0,0,0,0,0,0,0,0,0,0,0,0,0,0,0,0
0,0,0,0,0,0,0,0,0,0,0,0,0,0,0,0,0,0,0,0
0,0,0,0,0,0,0,0,0,0,0,0,0,0,0,0,0,0,0,0
0,0,0,0,0,0,0,0,0,0,0,0,0,0,0,0,0,0,0,0
0,0,0,0,0,0,0,0,0,0,0,0,0,0,0,0,0,0,0,0
0,0,0,0,0,0,0,0,0,0,0,0,0,0,0,0,0,0,0,0
0,0,0,0,0,0,0,0,0,0,0,0,0,0,0,0,0,0,0,0
:endlayer
layer: 68
0,0,0,0,0,0,0,0,0,0,0,0,0,0,0,0,0,0,0,0
0,0,0,0,0,0,0,0,0,0,0,0,0,0,0,0,0,0,0,0
0,0,0,0,0,0,0,0,0,0,0,0,0,0,0,0,0,0,0,0
0,0,0,0,0,0,0,0,0,0,0,0,0,0,0,0,0,0,0,0
0,0,0,0,0,0,0,0,0,0,0,0,0,0,0,0,0,0,0,0
0,0,0,0,0,0,0,0,0,0,0,0,0,0,0,0,0,0,0,0
0,0,0,0,0,0,0,0,0,0,0,0,0,0,0,0,0,0,0,0
0,0,0,0,0,0,0,0,0,31,35,28,0,0,0,0,0,0,0,0
0,0,0,0,0,1,1,1,1,1,1,1,1,0,0,0,0,0,0,0
0,0,0,0,0,1,1,1,1,1,1,1,1,1,0,0,0,0,0,0
0,0,0,0,0,1,1,1,1,1,1,1,1,1,1,0,0,0,0,0
0,0,0,0,26,1,1,1,1,1,1,1,1,1,1,14,0,0,0,0
0,0,0,0,25,1,1,1,1,1,1,1,1,1,1,1,0,0,0,0
0,0,0,0,36,1,1,1,1,1,1,1,1,1,1,1,22,0,0,0
0,0,0,0,0,1,1,1,1,1,1,1,1,1,1,1,31,0,0,0
0,0,0,0,0,1,1,1,1,1,1,1,1,1,1,1,0,22,0,0
0,0,0,0,0,1,1,1,1,1,1,1,1,1,1,1,0,0,0,0
0,0,0,0,0,1,1,1,1,1,1,1,1,1,1,1,0,0,0,0
0,0,0,0,0,0,1,1,1,1,1,1,1,1,1,0,0,0,0,0
0,0,0,0,0,0,0,27,27,27,27,25,0,0,0,0,0,0,0,0
0,0,0,0,0,0,0,0,0,0,0,0,0,0,0,0,0,0,0,0
0,0,0,0,0,0,0,0,0,0,0,0,0,0,0,0,0,0,0,0
0,0,0,0,0,0,0,0,0,0,0,0,0,0,0,0,0,0,0,0
0,0,0,0,0,0,0,0,0,0,0,0,0,0,0,0,0,0,0,0
0,0,0,0,0,0,0,0,0,0,0,0,0,0,0,0,0,0,0,0
0,0,0,0,0,0,0,0,0,0,0,0,0,0,0,0,0,0,0,0
0,0,0,0,0,0,0,0,0,0,0,0,0,0,0,0,0,0,0,0
0,0,0,0,0,0,0,0,0,0,0,0,0,0,0,0,0,0,0,0
:endlayer
layer: 69
0,0,0,0,0,0,0,0,0,0,0,0,0,0,0,0,0,0,0,0
0,0,0,0,0,0,0,0,0,0,0,0,0,0,0,0,0,0,0,0
0,0,0,0,0,0,0,0,0,0,0,0,0,0,0,0,0,0,0,0
0,0,0,0,0,0,0,0,0,0,0,0,0,0,0,0,0,0,0,0
0,0,0,0,0,0,0,0,0,0,0,0,0,0,0,0,0,0,0,0
0,0,0,0,0,0,0,0,0,0,0,0,0,0,0,0,0,0,0,0
0,0,0,0,0,0,0,0,0,0,0,0,0,0,0,0,0,0,0,0
0,0,0,0,0,0,1,1,1,31,35,28,0,0,0,0,0,0,0,0
0,0,0,0,0,1,1,1,1,1,1,1,1,1,0,0,0,0,0,0
0,0,0,0,0,1,1,1,1,1,1,1,1,1,1,0,0,0,0,0
0,0,0,0,0,1,1,1,1,1,1,1,1,1,1,0,0,0,0,0
0,0,0,0,1,1,1,1,1,1,1,1,1,1,1,15,0,0,0,0
0,0,0,0,25,1,1,1,1,1,1,1,1,1,1,14,0,0,0,0
0,0,0,0,26,37,1,1,1,1,1,1,1,1,1,14,22,0,0,0
0,0,0,0,0,1,1,1,1,1,1,1,1,1,1,1,31,0,0,0
0,0,0,0,1,1,1,1,1,1,1,1,1,1,1,1,1,22,0,0
0,0,0,0,0,1,1,1,1,1,1,1,1,1,1,1,0,0,0,0
0,0,0,0,1,1,1,1,1,1,1,1,1,1,1,1,0,0,0,0
0,0,0,0,0,1,1,1,1,1,14,1,1,1,1,0,0,0,0,0
0,0,0,0,0,0,1,1,14,27,27,26,14,1,0,0,0,0,0,0
0,0,0,0,0,0,0,0,0,0,0,0,0,0,0,0,0,0,0,0
0,0,0,0,0,0,0,0,0,0,0,0,0,0,0,0,0,0,0,0
0,0,0,0,0,0,0,0,0,0,0,0,0,0,0,0,0,0,0,0
0,0,0,0,0,0,0,0,0,0,0,0,0,0,0,0,0,0,0,0
0,0,0,0,0,0,0,0,0,0,0,0,0,0,0,0,0,0,0,0
0,0,0,0,0,0,0,0,0,0,0,0,0,0,0,0,0,0,0,0
0,0,0,0,0,0,0,0,0,0,0,0,0,0,0,0,0,0,0,0
0,0,0,0,0,0,0,0,0,0,0,0,0,0,0,0,0,0,0,0
:endlayer
layer: 70
0,0,0,0,0,0,0,0,0,0,0,0,0,0,0,0,0,0,0,0
0,0,0,0,0,0,0,0,0,0,0,0,0,0,0,0,0,0,0,0
0,0,0,0,0,0,0,0,0,0,0,0,0,0,0,0,0,0,0,0
0,0,0,0,0,0,0,0,0,0,0,0,0,0,0,0,0,0,0,0
0,0,0,0,0,0,0,0,0,0,0,0,0,0,0,0,0,0,0,0
0,0,0,0,0,0,0,0,0,0,0,0,0,0,0,0,0,0,0,0
0,0,0,0,0,0,0,0,0,0,0,0,0,0,0,0,0,0,0,0
0,0,0,0,0,0,1,1,1,31,35,1,1,0,0,0,0,0,0,0
0,0,0,0,0,1,1,1,1,1,1,1,1,1,1,0,0,0,0,0
0,0,0,0,1,1,1,1,1,1,1,1,1,1,1,1,0,0,0,0
0,0,0,0,1,1,1,1,1,1,1,1,1,1,1,0,0,0,0,0
0,0,0,0,1,1,1,1,1,1,1,1,1,1,1,0,0,0,0,0
0,0,0,0,25,1,1,1,1,1,1,1,1,1,1,15,0,0,0,0
0,0,0,0,26,38,37,1,1,1,1,1,1,1,1,20,0,0,0,0
0,0,0,0,0,1,1,1,1,1,1,1,1,1,1,1,22,0,0,0
0,0,0,0,1,1,1,1,1,1,1,1,1,1,1,1,1,22,0,0
0,0,0,0,1,1,1,1,1,1,1,1,1,1,1,1,1,0,0,0
0,0,0,0,14,1,1,1,1,1,1,1,1,1,1,1,1,0,0,0
0,0,0,0,0,14,1,1,1,1,39,39,1,1,1,1,0,0,0,0
0,0,0,0,0,0,14,14,23,27,27,0,15,0,1,0,0,0,0,0
0,0,0,0,0,0,0,0,0,0,0,0,0,0,0,0,0,0,0,0
0,0,0,0,0,0,0,0,0,0,0,0,0,0,0,0,0,0,0,0
0,0,0,0,0,0,0,0,0,0,0,0,0,0,0,0,0,0,0,0
0,0,0,0,0,0,0,0,0,0,0,0,0,0,0,0,0,0,0,0
0,0,0,0,0,0,0,0,0,0,0,0,0,0,0,0,0,0,0,0
0,0,0,0,0,0,0,0,0,0,0,0,0,0,0,0,0,0,0,0
0,0,0,0,0,0,0,0,0,0,0,0,0,0,0,0,0,0,0,0
0,0,0,0,0,0,0,0,0,0,0,0,0,0,0,0,0,0,0,0
:endlayer
layer: 71
0,0,0,0,0,0,0,0,0,0,0,0,0,0,0,0,0,0,0,0
0,0,0,0,0,0,0,0,0,0,0,0,0,0,0,0,0,0,0,0
0,0,0,0,0,0,0,0,0,0,0,0,0,0,0,0,0,0,0,0
0,0,0,0,0,0,0,0,0,0,0,0,0,0,0,0,0,0,0,0
0,0,0,0,0,0,0,0,0,0,0,0,0,0,0,0,0,0,0,0
0,0,0,0,0,0,0,0,0,0,0,0,0,0,0,0,0,0,0,0
0,0,0,0,0,0,0,0,0,0,0,0,0,0,0,0,0,0,0,0
0,0,0,0,0,0,14,40,4,40,31,14,14,0,0,0,0,0,0,0
0,0,0,0,0,1,1,1,1,1,1,1,1,1,1,0,0,0,0,0
0,0,0,0,14,1,1,41,1,1,1,1,1,1,1,14,0,0,0,0
0,0,0,0,14,1,1,1,1,1,1,1,1,42,1,1,0,0,0,0
0,0,0,0,14,1,1,1,1,1,1,1,1,1,1,1,0,0,0,0
0,0,0,0,25,4,1,1,1,1,1,1,1,1,1,29,0,0,0,0
0,0,0,0,26,38,31,43,1,1,1,1,1,1,1,31,0,0,0,0
0,0,0,0,0,4,1,1,1,1,1,1,1,1,1,1,22,0,0,0
0,0,0,0,14,1,1,1,1,1,1,1,1,1,1,1,14,22,0,0
0,0,0,0,14,1,1,1,1,1,1,1,1,1,1,1,14,0,0,0
0,0,0,0,15,1,1,1,1,1,1,1,1,1,1,1,14,0,0,0
0,0,0,0,0,0,1,1,1,39,44,1,1,1,4,1,0,0,0,0
0,0,0,0,0,0,15,20,0,0,39,39,0,39,0,0,0,0,0,0
0,0,0,0,0,0,0,0,0,0,0,0,0,0,0,0,0,0,0,0
0,0,0,0,0,0,0,0,0,0,0,0,0,0,0,0,0,0,0,0
0,0,0,0,0,0,0,0,0,0,0,0,0,0,0,0,0,0,0,0
0,0,0,0,0,0,0,0,0,0,0,0,0,0,0,0,0,0,0,0
0,0,0,0,0,0,0,0,0,0,0,0,0,0,0,0,0,0,0,0
0,0,0,0,0,0,0,0,0,0,0,0,0,0,0,0,0,0,0,0
0,0,0,0,0,0,0,0,0,0,0,0,0,0,0,0,0,0,0,0
0,0,0,0,0,0,0,0,0,0,0,0,0,0,0,0,0,0,0,0
:endlayer
layer: 72
0,0,0,0,0,0,0,0,0,0,0,0,0,0,0,0,0,0,0,0
0,0,0,0,0,0,0,0,0,0,0,0,0,0,0,0,0,0,0,0
0,0,0,0,0,0,0,0,0,0,0,0,0,0,0,0,0,0,0,0
0,0,0,0,0,0,0,0,0,0,0,0,0,0,0,0,0,0,0,0
0,0,0,0,0,0,0,0,0,0,0,0,0,0,0,0,0,0,0,0
0,0,0,0,0,0,0,0,0,0,0,0,0,0,0,0,0,0,0,0
0,0,0,0,0,0,0,40,0,40,0,0,0,0,0,0,0,0,0,0
0,0,0,0,0,0,15,45,14,45,31,28,38,0,0,0,0,0,0,0
0,0,0,0,0,14,4,14,14,14,45,1,1,14,14,0,0,0,0,0
0,0,0,0,15,14,1,0,1,46,47,47,37,1,14,0,0,0,0,0
0,0,0,0,15,14,1,1,45,47,43,43,37,0,1,14,0,0,0,0
0,0,0,0,15,14,14,43,43,43,43,43,37,1,1,14,0,0,0,0
0,0,0,0,26,4,14,0,1,48,43,43,37,1,1,29,0,0,0,0
0,0,0,0,26,38,31,0,1,46,43,43,37,1,4,31,0,0,0,0
0,0,0,0,0,4,14,1,1,46,43,43,37,1,14,4,22,0,0,0
0,0,0,0,20,4,14,1,1,46,43,43,37,1,45,4,15,0,0,0
0,0,0,0,15,4,1,1,1,46,48,48,48,1,1,4,0,0,0,0
0,0,0,0,0,4,14,1,1,14,45,14,1,1,1,4,15,0,0,0
0,0,0,0,0,0,4,14,14,14,0,14,14,14,45,4,0,0,0,0
0,0,0,0,0,0,0,0,0,39,1,45,0,45,49,0,0,0,0,0
0,0,0,0,0,0,0,0,0,50,39,39,0,0,0,0,0,0,0,0
0,0,0,0,0,0,0,0,0,0,0,0,0,0,0,0,0,0,0,0
0,0,0,0,0,0,0,0,0,0,0,0,0,0,0,0,0,0,0,0
0,0,0,0,0,0,0,0,0,0,0,0,0,0,0,0,0,0,0,0
0,0,0,0,0,0,0,0,0,0,0,0,0,0,0,0,0,0,0,0
0,0,0,0,0,0,0,0,0,0,0,0,0,0,0,0,0,0,0,0
0,0,0,0,0,0,0,0,0,0,0,0,0,0,0,0,0,0,0,0
0,0,0,0,0,0,0,0,0,0,0,0,0,0,0,0,0,0,0,0
:endlayer
layer: 73
0,0,0,0,0,0,0,0,0,0,0,0,0,0,0,0,0,0,0,0
0,0,0,0,0,0,0,0,0,0,0,0,0,0,0,0,0,0,0,0
0,0,0,0,0,0,0,0,0,0,0,0,0,0,0,0,0,0,0,0
0,0,0,0,0,0,0,0,0,0,0,0,0,0,0,0,0,0,0,0
0,0,0,0,0,0,0,0,0,0,0,0,0,0,0,0,0,0,0,0
0,0,0,0,0,0,0,40,0,40,0,0,0,0,0,0,0,0,0,0
0,0,0,0,0,0,0,45,14,45,0,0,0,0,0,0,0,0,0,0
0,0,0,0,0,0,14,47,15,47,14,28,38,0,0,0,0,0,0,0
0,0,0,0,0,0,14,15,15,15,0,14,14,22,0,0,0,0,0,0
0,0,0,0,0,15,51,0,0,0,52,0,0,37,49,0,0,0,0,0
0,0,0,0,0,20,14,45,0,0,53,54,0,0,14,15,0,0,0,0
0,0,0,0,50,43,0,0,0,0,0,55,0,37,49,15,0,0,0,0
0,0,0,0,26,14,20,0,48,0,0,56,0,0,14,31,0,0,0,0
0,0,0,0,26,14,22,0,37,0,0,0,0,37,45,49,0,0,0,0
0,0,0,0,0,14,15,0,47,0,57,58,0,0,15,14,22,0,0,0
0,0,0,0,0,14,21,0,48,0,0,59,0,0,0,14,22,0,0,0
0,0,0,0,0,14,0,0,37,0,60,0,0,37,45,49,0,0,0,0
0,0,0,0,0,14,0,0,47,0,0,0,0,0,0,14,0,0,0,0
0,0,0,0,0,0,14,0,61,0,0,0,0,0,62,14,0,0,0,0
0,0,0,0,0,0,0,0,51,45,0,48,0,37,45,49,0,0,0,0
0,0,0,0,0,0,0,0,0,0,0,45,39,39,49,0,0,0,0,0
0,0,0,0,0,0,0,0,51,45,39,39,0,0,0,0,0,0,0,0
0,0,0,0,0,0,0,0,0,0,0,0,0,0,0,0,0,0,0,0
0,0,0,0,0,0,0,0,0,0,0,0,0,0,0,0,0,0,0,0
0,0,0,0,0,0,0,0,0,0,0,0,0,0,0,0,0,0,0,0
0,0,0,0,0,0,0,0,0,0,0,0,0,0,0,0,0,0,0,0
0,0,0,0,0,0,0,0,0,0,0,0,0,0,0,0,0,0,0,0
0,0,0,0,0,0,0,0,0,0,0,0,0,0,0,0,0,0,0,0
:endlayer
layer: 74
0,0,0,0,0,0,0,0,0,0,0,0,0,0,0,0,0,0,0,0
0,0,0,0,0,0,0,0,0,0,0,0,0,0,0,0,0,0,0,0
0,0,0,0,0,0,0,0,0,0,0,0,0,0,0,0,0,0,0,0
0,0,0,0,0,0,0,0,0,0,0,0,0,0,0,0,0,0,0,0
0,0,0,0,0,0,0,40,0,40,0,0,0,0,0,0,0,0,0,0
0,0,0,0,0,0,0,45,0,45,0,0,50,0,0,0,0,0,0,0
0,0,0,0,0,51,40,47,15,47,0,0,0,0,0,0,0,0,0,0
0,0,0,0,0,51,15,0,0,0,15,0,0,0,0,0,0,0,0,0
0,0,0,0,0,51,15,0,0,0,0,0,0,0,0,0,0,0,0,0
0,0,0,0,0,51,45,0,0,0,0,0,0,0,37,49,0,0,0,0
0,0,0,50,0,0,15,45,0,0,0,0,0,0,15,0,0,0,0,0
0,0,50,43,0,0,0,0,0,0,0,0,0,0,37,49,0,0,0,0
0,0,0,50,43,0,0,0,40,0,0,0,0,0,15,28,0,0,0,0
0,0,0,0,0,15,0,0,51,49,0,0,0,0,37,45,49,0,0,0
0,0,0,0,0,15,0,0,39,0,0,0,0,0,0,15,0,0,0,0
0,0,0,0,0,15,0,0,40,0,0,0,0,0,0,15,0,0,0,0
0,0,0,0,0,15,0,0,51,49,0,0,0,0,37,45,49,0,0,0
0,0,0,0,0,0,0,0,39,0,0,0,0,0,0,20,0,0,0,0
0,0,0,0,0,0,0,0,0,0,0,0,0,0,0,15,0,0,0,0
0,0,0,0,0,0,0,51,45,46,0,0,0,0,37,45,49,0,0,0
0,0,0,0,0,0,0,0,49,0,0,48,45,45,45,49,0,0,0,0
0,0,0,0,0,0,0,51,45,46,37,45,39,45,39,49,0,0,0,0
0,0,0,0,0,0,0,0,0,0,0,39,0,0,0,0,0,0,0,0
0,0,0,0,0,0,0,0,0,0,0,0,0,0,0,0,0,0,0,0
0,0,0,0,0,0,0,0,0,0,0,0,0,0,0,0,0,0,0,0
0,0,0,0,0,0,0,0,0,0,0,0,0,0,0,0,0,0,0,0
0,0,0,0,0,0,0,0,0,0,0,0,0,0,0,0,0,0,0,0
0,0,0,0,0,0,0,0,0,0,0,0,0,0,0,0,0,0,0,0
:endlayer
layer: 75
0,0,0,0,0,0,0,0,0,0,0,0,0,0,0,0,0,0,0,0
0,0,0,0,0,0,0,0,0,0,0,0,0,0,0,0,0,0,0,0
0,0,0,0,0,0,0,0,0,0,0,0,0,0,0,0,0,0,0,0
0,0,0,0,0,0,0,0,0,0,0,0,0,0,0,0,0,0,0,0
0,0,0,0,0,0,0,45,47,45,0,0,0,0,0,0,0,0,0,0
0,0,0,0,0,0,45,47,43,47,45,45,46,0,0,0,0,0,0,0
0,0,0,0,0,45,47,46,43,37,47,37,45,0,0,0,0,0,0,0
0,0,0,51,45,48,48,43,43,43,43,47,37,45,48,0,0,0,0,0
0,0,0,51,45,45,46,43,43,43,43,43,47,37,45,0,0,0,0,0
0,0,50,43,45,45,45,48,48,43,43,43,43,37,45,46,0,0,0,0
0,0,43,0,51,39,39,45,46,43,43,43,43,47,37,45,0,0,0,0
0,0,0,0,0,0,0,50,46,43,43,43,43,43,43,37,0,0,0,0
0,0,0,0,0,0,0,51,45,46,48,37,45,45,45,45,0,0,0,0
0,0,0,0,0,0,0,51,63,63,63,64,63,63,63,63,45,0,0,0
0,0,0,0,0,0,0,51,63,63,63,63,63,63,63,45,0,0,0,0
0,0,0,0,0,0,0,51,63,63,63,63,63,63,63,45,0,0,0,0
0,0,0,0,0,0,0,51,63,63,63,63,63,63,63,45,45,0,0,0
0,0,0,0,0,0,0,45,64,63,63,63,63,63,63,45,0,0,0,0
0,0,0,0,0,0,0,0,45,63,63,63,63,63,63,45,0,0,0,0
0,0,0,0,0,0,0,45,45,63,63,63,63,63,63,63,45,0,0,0
0,0,0,0,0,0,0,51,4,63,63,63,63,63,63,14,49,0,0,0
0,0,0,0,0,0,0,45,4,14,4,63,14,64,63,4,49,0,0,0
0,0,0,0,0,0,0,51,39,39,39,45,39,39,39,39,49,0,0,0
0,0,0,0,0,0,0,0,0,0,0,0,0,0,0,0,0,0,0,0
0,0,0,0,0,0,0,0,0,0,0,0,0,0,0,0,0,0,0,0
0,0,0,0,0,0,0,0,0,0,0,0,0,0,0,0,0,0,0,0
0,0,0,0,0,0,0,0,0,0,0,0,0,0,0,0,0,0,0,0
0,0,0,0,0,0,0,0,0,0,0,0,0,0,0,0,0,0,0,0
:endlayer
layer: 76
0,0,0,0,0,0,0,0,0,0,0,0,0,0,0,0,0,0,0,0
0,0,0,0,0,0,0,0,0,0,0,0,0,0,0,0,0,0,0,0
0,0,0,0,0,0,0,0,0,0,0,0,0,0,0,0,0,0,0,0
0,0,0,0,0,0,0,0,0,0,0,0,0,0,0,0,0,0,0,0
0,0,0,0,0,0,0,45,65,45,0,0,0,0,0,0,0,0,0,0
0,0,0,0,0,0,45,0,0,0,66,65,45,0,0,0,0,0,0,0
0,0,0,0,0,45,0,0,0,0,0,0,37,0,0,0,0,0,0,0
0,0,0,45,45,0,0,0,0,0,0,0,0,47,45,0,0,0,0,0
0,0,0,45,67,68,0,0,0,0,0,0,0,0,65,0,0,0,0,0
0,0,0,0,0,69,45,0,0,0,0,0,0,0,45,0,0,0,0,0
0,0,0,0,43,43,14,46,0,0,0,0,0,0,0,45,0,0,0,0
0,0,0,0,0,0,0,46,0,0,0,0,0,0,0,65,0,0,0,0
0,0,0,0,0,0,0,45,46,0,0,0,0,0,37,45,0,0,0,0
0,0,0,0,0,0,0,46,0,0,0,0,0,0,0,0,45,0,0,0
0,0,0,0,0,0,0,46,0,0,0,0,0,70,0,0,37,0,0,0
0,0,0,0,0,0,0,46,0,0,0,0,71,0,0,0,37,0,0,0
0,0,0,0,0,0,0,46,0,0,0,72,45,0,0,45,45,0,0,0
0,0,0,0,0,0,0,45,0,0,0,0,73,0,0,37,0,0,0,0
0,0,0,0,0,0,0,0,45,48,0,0,0,0,0,37,0,0,0,0
0,0,0,0,0,0,51,14,45,0,0,0,0,0,0,45,45,0,0,0
0,0,0,0,0,0,0,14,45,0,0,0,0,0,0,37,14,0,0,0
0,0,0,0,0,0,0,14,45,48,45,0,47,0,0,45,14,0,0,0
0,0,0,0,0,0,0,45,14,14,48,48,48,45,0,37,14,0,0,0
0,0,0,0,0,0,0,0,0,0,0,0,0,45,48,45,0,0,0,0
0,0,0,0,0,0,0,0,0,0,0,0,0,0,0,0,0,0,0,0
0,0,0,0,0,0,0,0,0,0,0,0,0,0,0,0,0,0,0,0
0,0,0,0,0,0,0,0,0,0,0,0,0,0,0,0,0,0,0,0
0,0,0,0,0,0,0,0,0,0,0,0,0,0,0,0,0,0,0,0
:endlayer
layer: 77
0,0,0,0,0,0,0,0,0,0,0,0,0,0,0,0,0,0,0,0
0,0,0,0,0,0,0,0,0,0,0,0,0,0,0,0,0,0,0,0
0,0,0,0,0,0,0,0,0,0,0,0,0,0,0,0,0,0,0,0
0,0,0,0,0,0,0,0,0,0,0,0,0,0,0,0,0,0,0,0
0,0,0,0,0,0,0,45,65,45,0,0,0,0,0,0,0,0,0,0
0,0,0,0,0,0,45,0,0,0,45,65,45,0,0,0,0,0,0,0
0,0,0,40,0,45,0,0,0,0,0,0,51,0,0,0,0,0,0,0
0,0,51,45,74,0,0,0,0,0,0,0,0,39,45,0,0,0,0,0
0,0,0,0,75,0,0,0,0,0,0,0,0,0,65,0,0,0,0,0
0,0,0,0,0,76,74,0,0,0,0,0,0,77,45,0,0,0,0,0
0,0,0,0,0,0,15,49,0,0,0,0,0,0,0,45,0,0,0,0
0,0,0,0,0,0,0,49,0,0,0,0,0,0,0,65,0,0,0,0
0,0,0,0,0,0,0,45,0,0,0,0,0,0,0,45,0,0,0,0
0,0,0,0,0,0,0,65,0,0,0,0,0,0,0,0,45,49,0,0
0,0,0,0,0,0,0,65,0,0,0,0,0,0,0,0,65,0,0,0
0,0,0,0,0,0,0,65,0,0,0,0,0,0,0,0,65,0,0,0
0,0,0,0,0,0,0,65,0,0,0,0,45,0,77,45,45,49,0,0
0,0,0,0,0,0,0,45,0,0,0,0,0,0,0,65,0,0,0,0
0,0,0,0,0,0,0,0,45,0,0,0,0,0,0,65,0,0,0,0
0,0,0,0,0,51,45,15,46,48,0,0,0,0,0,45,45,49,0,0
0,0,0,0,0,0,0,15,46,0,0,0,78,0,0,65,15,0,0,0
0,0,0,0,0,0,0,20,45,65,45,0,39,0,0,45,15,0,0,0
0,0,0,0,0,0,51,45,15,15,65,65,65,45,0,65,15,0,0,0
0,0,0,0,0,0,0,0,0,0,0,0,0,45,65,65,0,0,0,0
0,0,0,0,0,0,0,0,0,0,0,0,0,0,0,0,0,0,0,0
0,0,0,0,0,0,0,0,0,0,0,0,0,0,0,0,0,0,0,0
0,0,0,0,0,0,0,0,0,0,0,0,0,0,0,0,0,0,0,0
0,0,0,0,0,0,0,0,0,0,0,0,0,0,0,0,0,0,0,0
:endlayer
layer: 78
0,0,0,0,0,0,0,48,48,48,0,0,0,0,0,0,0,0,0,0
0,0,0,0,0,0,48,79,79,79,46,48,49,0,0,0,0,0,0,0
0,0,0,0,0,37,79,80,80,80,79,79,46,0,0,0,0,0,0,0
0,0,0,0,48,79,0,40,0,40,0,80,79,49,0,0,0,0,0,0
0,0,0,48,79,0,40,45,65,45,0,0,80,79,49,0,0,0,0,0
0,0,37,79,80,51,45,0,0,0,45,65,45,80,79,40,0,0,0,0
0,0,40,79,80,45,81,0,0,0,81,51,45,0,80,79,48,0,0,0
0,37,79,45,45,0,0,0,0,0,0,0,0,45,45,80,79,48,0,0
0,37,79,80,82,45,0,0,0,0,0,0,0,39,65,0,80,79,46,0
0,37,79,80,0,83,45,0,0,0,0,0,0,0,45,49,0,79,48,0
0,0,37,79,80,0,0,45,0,0,0,0,0,0,50,45,49,80,79,46
0,0,0,37,79,80,0,45,0,0,0,0,0,84,84,51,49,80,79,49
0,0,0,0,51,79,80,45,85,0,0,0,50,84,51,45,40,80,79,46
0,0,0,51,79,51,49,49,0,0,0,0,50,50,51,45,45,79,46,0
0,0,0,0,51,79,80,49,0,0,0,0,50,84,84,0,51,80,79,46
0,0,0,51,79,80,0,49,0,0,0,0,40,84,84,0,51,80,79,49
0,0,0,37,79,80,0,49,0,0,0,51,45,49,51,86,45,0,79,46
0,0,0,37,79,80,51,40,0,0,0,0,39,84,84,45,49,80,79,49
0,0,0,0,37,79,80,0,46,0,0,0,50,84,84,45,49,80,79,46
0,0,0,0,37,79,45,74,0,0,84,50,50,50,51,86,45,79,46,0
0,0,0,0,37,79,80,74,0,48,84,50,84,84,84,51,0,80,79,46
0,0,0,0,37,79,80,0,45,40,46,50,37,0,0,51,49,80,79,46
0,0,0,0,0,51,79,80,0,51,40,40,40,49,0,51,80,80,79,49
0,0,0,0,0,37,79,80,80,80,80,80,80,49,40,45,80,79,39,0
0,0,0,0,0,0,39,79,79,79,79,79,80,80,80,80,79,39,0,0
0,0,0,0,0,0,0,47,47,47,47,47,79,79,80,79,49,0,0,0
0,0,0,0,0,0,0,0,0,0,0,37,47,37,79,47,0,0,0,0
0,0,0,0,0,0,0,0,0,0,0,0,0,0,47,0,0,0,0,0
:endlayer
layer: 79
0,0,0,0,0,0,0,0,0,0,0,0,0,0,0,0,0,0,0,0
0,0,0,0,0,0,0,48,48,48,0,0,0,0,0,0,0,0,0,0
0,0,0,0,0,0,37,87,87,87,46,48,0,0,0,0,0,0,0,0
0,0,0,0,0,48,87,87,0,87,87,87,48,0,0,0,0,0,0,0
0,0,0,0,37,87,87,80,39,80,80,87,87,46,0,0,0,0,0,0
0,0,0,37,87,87,45,0,50,0,45,45,80,87,46,0,0,0,0,0
0,0,0,48,87,87,0,50,50,50,39,45,45,45,87,48,0,0,0,0
0,0,37,87,87,80,0,50,84,84,84,84,39,45,80,87,46,0,0,0
0,0,37,87,87,80,0,50,84,84,84,84,84,45,45,80,87,46,0,0
0,0,37,87,87,45,80,0,50,84,84,84,84,51,45,80,87,46,0,0
0,0,0,37,87,87,87,80,0,84,84,84,84,88,0,89,87,87,46,0
0,0,0,0,47,87,87,80,0,0,0,0,88,0,0,0,87,87,46,0
0,0,0,0,0,37,87,45,50,0,0,0,0,0,90,51,87,87,46,0
0,0,0,0,43,37,87,45,49,0,0,0,0,0,0,0,45,46,0,0
0,0,0,0,0,37,87,45,50,0,0,0,0,0,0,51,87,87,46,0
0,0,0,0,37,87,87,45,49,0,0,0,0,0,0,51,87,87,46,0
0,0,0,0,37,87,0,45,50,0,0,0,0,0,0,0,45,87,46,0
0,0,0,0,37,87,87,45,49,0,0,0,0,0,0,51,87,87,46,0
0,0,0,0,0,37,87,87,50,0,0,0,0,0,91,51,87,87,46,0
0,0,0,0,0,43,37,87,49,0,0,0,0,0,0,0,45,46,0,0
0,0,0,0,0,37,87,87,49,0,0,0,0,0,0,51,87,87,46,0
0,0,0,0,0,37,87,87,80,80,80,80,80,0,0,92,87,87,46,0
0,0,0,0,0,0,37,87,87,87,87,87,80,43,40,43,87,87,46,0
0,0,0,0,0,0,37,87,87,87,87,87,87,45,43,87,87,47,0,0
0,0,0,0,0,0,0,47,47,47,47,47,87,87,87,87,47,0,0,0
0,0,0,0,0,0,0,0,0,0,0,0,47,47,87,47,0,0,0,0
0,0,0,0,0,0,0,0,0,0,0,0,0,0,47,0,0,0,0,0
0,0,0,0,0,0,0,0,0,0,0,0,0,0,0,0,0,0,0,0
:endlayer
layer: 80
0,0,0,0,0,0,0,0,0,0,0,0,0,0,0,0,0,0,0,0
0,0,0,0,0,0,0,0,0,0,0,0,0,0,0,0,0,0,0,0
0,0,0,0,0,0,0,48,48,48,0,0,0,0,0,0,0,0,0,0
0,0,0,0,0,0,37,0,87,46,48,43,0,0,0,0,0,0,0,0
0,0,0,0,0,48,37,87,45,87,87,48,48,0,0,0,0,0,0,0
0,0,0,0,37,93,87,80,94,80,87,87,87,48,0,0,0,0,0,0
0,0,0,0,37,93,87,0,94,94,94,51,45,87,48,0,0,0,0,0
0,0,0,37,48,87,80,94,0,0,94,94,94,87,87,46,0,0,0,0
0,0,0,37,93,87,80,94,0,95,0,0,0,94,45,87,46,0,0,0
0,0,0,37,93,87,87,80,0,0,96,97,0,94,45,87,46,0,0,0
0,0,0,0,47,47,37,87,80,0,0,0,0,0,0,87,46,46,0,0
0,0,0,0,0,43,37,87,80,0,0,0,0,0,0,0,87,46,0,0
0,0,0,0,0,0,37,87,87,0,0,0,0,0,0,87,46,47,0,0
0,0,0,0,0,0,43,37,87,0,0,0,0,0,0,0,46,0,0,0
0,0,0,0,0,0,37,87,87,0,0,0,0,0,0,87,43,43,0,0
0,0,0,0,0,43,37,87,80,0,0,0,0,0,0,87,43,43,0,0
0,0,0,0,0,37,87,80,0,0,0,0,0,0,0,0,46,43,0,0
0,0,0,0,0,43,37,87,80,0,0,0,0,0,0,87,43,43,0,0
0,0,0,0,0,0,43,37,87,0,0,0,0,0,0,87,43,43,0,0
0,0,0,0,0,0,0,37,87,0,0,0,0,0,0,0,46,0,0,0
0,0,0,0,0,0,43,37,87,0,0,0,0,0,0,87,46,43,0,0
0,0,0,0,0,0,43,37,87,87,87,87,87,80,80,87,46,43,0,0
0,0,0,0,0,0,0,37,47,47,47,47,47,87,87,87,46,43,0,0
0,0,0,0,0,0,0,43,43,43,43,43,37,87,87,47,46,0,0,0
0,0,0,0,0,0,0,0,0,0,0,0,47,47,47,46,0,0,0,0
0,0,0,0,0,0,0,0,0,0,0,0,0,0,43,0,0,0,0,0
0,0,0,0,0,0,0,0,0,0,0,0,0,0,0,0,0,0,0,0
0,0,0,0,0,0,0,0,0,0,0,0,0,0,0,0,0,0,0,0
:endlayer
layer: 81
0,0,0,0,0,0,0,0,0,0,0,0,0,0,0,0,0,0,0,0
0,0,0,0,0,0,0,0,0,0,0,0,0,0,0,0,0,0,0,0
0,0,0,0,0,0,0,0,0,0,0,0,0,0,0,0,0,0,0,0
0,0,0,0,0,0,0,0,48,0,0,0,0,0,0,0,0,0,0,0
0,0,0,0,0,0,0,48,87,48,46,0,0,0,0,0,0,0,0,0
0,0,0,0,0,0,37,87,94,87,46,48,48,0,0,0,0,0,0,0
0,0,0,0,0,0,37,87,94,94,87,87,87,46,0,0,0,0,0,0
0,0,0,0,0,37,87,94,0,0,94,94,94,87,46,0,0,0,0,0
0,0,0,0,0,37,87,94,0,0,0,0,0,94,87,46,0,0,0,0
0,0,0,0,0,37,47,87,0,0,0,0,0,94,87,46,0,0,0,0
0,0,0,0,0,0,0,37,87,0,0,0,0,0,87,46,0,0,0,0
0,0,0,0,0,0,0,37,87,0,0,0,0,0,80,87,46,0,0,0
0,0,0,0,0,0,0,43,37,87,0,0,0,0,87,46,0,0,0,0
0,0,0,0,0,0,0,0,37,87,0,0,0,87,46,43,37,50,0,0
0,0,0,0,0,0,0,43,37,87,0,0,0,0,87,46,0,0,0,0
0,0,0,0,0,0,0,37,87,0,0,0,0,0,87,46,0,0,0,0
0,0,0,0,0,0,37,87,80,0,0,0,0,87,46,43,37,50,0,0
0,0,0,0,0,0,0,37,87,0,0,0,0,0,87,46,0,0,0,0
0,0,0,0,0,0,0,0,37,87,0,0,0,0,87,46,0,0,0,0
0,0,0,0,0,0,0,0,37,87,0,0,0,87,46,43,37,50,0,0
0,0,0,0,0,0,0,0,37,87,87,87,87,87,87,46,0,0,0,0
0,0,0,0,0,0,0,0,37,47,47,47,47,87,87,46,0,0,0,0
0,0,0,0,0,0,0,0,0,0,0,0,0,47,47,46,0,0,0,0
0,0,0,0,0,0,0,0,0,0,0,0,0,43,43,0,0,0,0,0
0,0,0,0,0,0,0,0,0,0,0,0,0,0,0,0,0,0,0,0
0,0,0,0,0,0,0,0,0,0,0,0,0,0,0,0,0,0,0,0
0,0,0,0,0,0,0,0,0,0,0,0,0,0,0,0,0,0,0,0
0,0,0,0,0,0,0,0,0,0,0,0,0,0,0,0,0,0,0,0
:endlayer
layer: 82
0,0,0,0,0,0,0,0,0,0,0,0,0,0,0,0,0,0,0,0
0,0,0,0,0,0,0,0,0,0,0,0,0,0,0,0,0,0,0,0
0,0,0,0,0,0,0,0,0,0,0,0,0,0,0,0,0,0,0,0
0,0,0,0,0,0,0,0,0,0,0,0,0,0,0,0,0,0,0,0
0,0,0,0,0,0,0,0,48,0,0,0,0,0,0,0,0,0,0,0
0,0,0,0,0,0,0,37,87,46,0,0,0,0,0,0,0,0,0,0
0,0,0,0,0,0,0,37,87,87,48,48,48,0,0,0,0,0,0,0
0,0,0,0,0,0,37,87,87,80,87,87,87,48,0,0,0,0,0,0
0,0,0,0,0,0,37,87,80,0,0,0,0,87,46,0,0,0,0,0
0,0,0,0,0,0,0,37,87,0,0,0,0,80,87,0,0,0,0,0
0,0,0,0,0,0,0,0,37,87,0,0,0,87,46,0,0,0,0,0
0,0,0,0,0,0,0,0,37,87,0,0,0,80,87,46,0,0,0,0
0,0,0,0,0,0,0,0,0,37,87,0,0,87,46,0,0,0,0,0
0,0,0,0,0,0,0,0,0,43,87,0,87,43,0,0,0,0,0,0
0,0,0,0,0,0,0,0,0,37,87,0,80,87,46,0,0,0,0,0
0,0,0,0,0,0,0,0,37,87,0,0,80,87,46,0,0,0,0,0
0,0,0,0,0,0,0,37,87,80,0,0,87,43,0,0,0,0,0,0
0,0,0,0,0,0,0,0,37,87,0,0,80,87,46,0,0,0,0,0
0,0,0,0,0,0,0,0,0,43,87,0,80,87,46,0,0,0,0,0
0,0,0,0,0,0,0,0,0,43,87,87,87,46,0,0,0,0,0,0
0,0,0,0,0,0,0,0,0,43,47,47,47,46,43,0,0,0,0,0
0,0,0,0,0,0,0,0,0,0,0,0,0,43,43,0,0,0,0,0
0,0,0,0,0,0,0,0,0,0,0,0,0,0,0,0,0,0,0,0
0,0,0,0,0,0,0,0,0,0,0,0,0,0,0,0,0,0,0,0
0,0,0,0,0,0,0,0,0,0,0,0,0,0,0,0,0,0,0,0
0,0,0,0,0,0,0,0,0,0,0,0,0,0,0,0,0,0,0,0
0,0,0,0,0,0,0,0,0,0,0,0,0,0,0,0,0,0,0,0
0,0,0,0,0,0,0,0,0,0,0,0,0,0,0,0,0,0,0,0
:endlayer
layer: 83
0,0,0,0,0,0,0,0,0,0,0,0,0,0,0,0,0,0,0,0
0,0,0,0,0,0,0,0,0,0,0,0,0,0,0,0,0,0,0,0
0,0,0,0,0,0,0,0,0,0,0,0,0,0,0,0,0,0,0,0
0,0,0,0,0,0,0,0,0,0,0,0,0,0,0,0,0,0,0,0
0,0,0,0,0,0,0,0,0,0,0,0,0,0,0,0,0,0,0,0
0,0,0,0,0,0,0,0,48,0,0,0,0,0,0,0,0,0,0,0
0,0,0,0,0,0,0,0,0,48,0,0,0,0,0,0,0,0,0,0
0,0,0,0,0,0,0,37,87,87,46,48,48,0,0,0,0,0,0,0
0,0,0,0,0,0,0,37,87,98,87,87,87,48,0,0,0,0,0,0
0,0,0,0,0,0,0,0,37,87,0,0,0,87,46,0,0,0,0,0
0,0,0,0,0,0,0,0,0,37,87,0,87,46,0,0,0,0,0,0
0,0,0,0,0,0,0,0,0,37,87,87,87,87,46,0,0,0,0,0
0,0,0,0,0,0,0,0,0,0,37,87,87,46,0,0,0,0,0,0
0,0,0,0,0,0,0,0,0,0,37,87,46,0,0,0,0,0,0,0
0,0,0,0,0,0,0,0,0,0,37,87,87,46,0,0,0,0,0,0
0,0,0,0,0,0,0,0,0,37,87,87,87,46,0,0,0,0,0,0
0,0,0,0,0,0,0,0,37,87,87,87,46,0,0,0,0,0,0,0
0,0,0,0,0,0,0,0,0,37,87,87,87,46,0,0,0,0,0,0
0,0,0,0,0,0,0,0,0,0,37,87,87,46,0,0,0,0,0,0
0,0,0,0,0,0,0,0,0,0,47,47,47,0,0,0,0,0,0,0
0,0,0,0,0,0,0,0,0,0,0,0,0,0,0,0,0,0,0,0
0,0,0,0,0,0,0,0,0,0,0,0,0,0,0,0,0,0,0,0
0,0,0,0,0,0,0,0,0,0,0,0,0,0,0,0,0,0,0,0
0,0,0,0,0,0,0,0,0,0,0,0,0,0,0,0,0,0,0,0
0,0,0,0,0,0,0,0,0,0,0,0,0,0,0,0,0,0,0,0
0,0,0,0,0,0,0,0,0,0,0,0,0,0,0,0,0,0,0,0
0,0,0,0,0,0,0,0,0,0,0,0,0,0,0,0,0,0,0,0
0,0,0,0,0,0,0,0,0,0,0,0,0,0,0,0,0,0,0,0
:endlayer
layer: 84
0,0,0,0,0,0,0,0,0,0,0,0,0,0,0,0,0,0,0,0
0,0,0,0,0,0,0,0,0,0,0,0,0,0,0,0,0,0,0,0
0,0,0,0,0,0,0,0,0,0,0,0,0,0,0,0,0,0,0,0
0,0,0,0,0,0,0,0,0,0,0,0,0,0,0,0,0,0,0,0
