# Ancient Warfare Structure Template File
# Auto-generated structure template file. created on: 8/19/2019 at: 10:23:11
# Lines beginning with # denote comments

header:
version=2.9
name=KongTrader
mods=
size=14,21,16
offset=8,4,15
:endheader

#### VALIDATION ####
validation:
type=ground
survival=false
worldGenEnabled=true
unique=false
preserveBlocks=false
selectionWeight=30
clusterValue=40
minDuplicateDistance=900
dimensionWhiteList=true
dimensionList=0
biomeWhiteList=true
biomeList=minecraft:jungle
leveling=3
fill=2
border=3
blockSwap=false
:endvalidation

#### LAYERS ####
layer: 0
1,1,1,1,1,1,1,1,1,1,1,1,1,1
1,1,1,1,1,1,1,1,1,1,1,1,1,1
1,1,1,1,1,1,1,1,1,1,1,1,1,1
1,1,1,1,1,1,1,1,1,1,1,1,1,1
1,1,1,1,1,1,1,1,1,1,1,1,1,1
1,1,1,1,1,1,1,1,1,1,1,1,1,1
1,1,1,1,1,1,1,1,1,1,1,1,1,1
1,1,1,1,1,1,1,1,1,1,1,1,1,1
1,1,1,1,1,1,1,1,1,1,1,1,1,1
1,1,1,1,1,1,1,1,1,1,1,1,1,1
1,1,1,1,1,1,1,1,1,1,1,1,1,1
1,1,1,1,1,1,1,1,1,1,1,1,1,1
1,1,1,1,1,1,1,1,1,1,1,1,1,1
1,1,1,1,1,1,1,1,1,1,1,1,1,1
1,1,1,1,1,1,1,1,1,1,1,1,1,1
1,1,1,1,1,1,1,1,1,1,1,1,1,1
:endlayer
layer: 1
1,1,1,1,1,1,1,1,1,1,1,1,1,1
1,1,1,1,1,1,1,1,1,1,1,1,1,1
1,1,1,1,1,1,1,1,1,1,1,1,1,1
1,1,1,1,1,1,1,1,1,1,1,1,1,1
1,1,1,1,1,1,1,1,1,1,1,1,1,1
1,1,1,1,1,1,1,1,1,1,1,1,1,1
1,1,1,1,1,1,1,1,1,1,1,1,1,1
1,1,1,1,1,1,1,1,1,1,1,1,1,1
1,1,1,1,1,1,1,1,1,1,1,1,1,1
1,1,1,1,1,1,1,1,1,1,1,1,1,1
1,1,1,1,1,1,1,1,1,1,1,1,1,1
1,1,1,1,1,1,1,1,1,1,1,1,1,1
1,1,1,1,1,1,1,1,1,1,1,1,1,1
1,1,1,1,1,1,1,1,1,1,1,1,1,1
1,1,1,1,1,1,1,1,1,1,1,1,1,1
1,1,1,1,1,1,1,1,1,1,1,1,1,1
:endlayer
layer: 2
1,1,1,1,1,1,1,1,1,1,1,1,1,1
1,1,1,1,1,1,1,1,1,1,1,1,1,1
1,1,1,1,1,1,1,1,1,1,1,1,1,1
1,1,1,1,1,1,1,1,1,1,1,1,1,1
1,1,1,1,1,1,1,1,1,1,1,1,1,1
1,1,1,1,1,1,1,1,1,1,1,1,1,1
1,1,1,1,1,1,1,1,1,1,1,1,1,1
1,1,1,1,1,1,1,1,1,1,1,1,1,1
1,1,1,1,1,1,1,1,1,1,1,1,1,1
1,1,1,1,1,1,1,1,1,1,1,1,1,1
1,1,1,1,1,1,1,1,1,1,1,1,1,1
1,1,1,1,1,1,1,1,1,1,1,1,1,1
1,1,1,1,1,1,1,1,1,1,1,1,1,1
1,1,1,1,1,1,1,1,1,1,1,1,1,1
1,1,1,1,1,1,1,1,1,1,1,1,1,1
1,1,1,1,1,1,1,1,1,1,1,1,1,1
:endlayer
layer: 3
2,2,2,2,2,2,2,2,2,2,2,2,2,2
2,2,2,2,2,2,2,2,2,2,2,2,2,2
2,2,2,2,2,2,2,2,2,2,2,2,2,2
2,2,2,2,2,2,2,2,2,2,2,2,2,2
2,2,2,2,2,2,2,2,2,2,2,2,2,2
2,2,2,2,2,2,2,2,2,2,2,2,2,2
2,2,2,2,2,2,2,2,2,2,2,2,2,2
2,2,2,2,2,2,2,2,2,2,2,2,2,2
2,2,2,2,2,2,1,1,2,2,2,2,2,2
2,2,2,2,2,2,1,1,2,2,2,2,2,2
2,2,2,2,2,2,2,2,2,2,2,2,2,2
2,2,2,2,2,2,2,2,2,2,2,2,2,2
2,2,2,2,2,2,2,2,2,2,2,2,2,2
2,2,2,2,2,2,2,2,2,2,2,2,2,2
2,2,2,2,2,2,1,2,2,2,2,2,1,2
2,2,2,2,2,2,2,2,2,2,2,2,2,2
:endlayer
layer: 4
0,0,0,0,3,0,0,0,0,0,0,3,0,0
0,3,0,3,0,3,0,0,3,0,3,3,3,0
0,0,0,0,0,4,3,3,3,3,3,3,3,3
0,0,0,3,0,3,3,3,0,0,3,3,3,3
0,0,0,0,0,3,3,3,0,3,3,0,0,0
0,0,0,0,0,0,3,3,0,3,0,3,0,0
3,0,0,0,3,5,0,0,3,3,3,0,0,0
0,0,0,0,3,0,3,6,3,3,3,3,0,3
0,3,0,0,5,0,7,7,8,3,3,3,0,0
3,3,3,3,3,9,7,7,0,3,3,0,0,0
0,0,3,0,3,0,0,10,3,3,3,3,0,0
3,3,3,0,0,0,3,3,3,0,3,0,0,0
0,0,3,0,11,3,0,0,3,3,12,0,0,0
0,0,0,11,12,0,3,3,3,3,3,0,0,0
0,0,0,0,0,0,13,0,0,3,0,3,13,0
0,0,0,0,0,0,0,0,0,0,0,0,0,0
:endlayer
layer: 5
0,0,0,0,0,0,0,0,0,0,0,0,0,0
0,0,0,0,0,0,0,0,0,0,0,0,0,0
0,0,0,0,0,0,0,0,0,0,0,0,0,0
0,0,0,0,0,0,0,0,0,0,0,0,0,0
0,0,0,0,0,0,0,0,0,0,0,0,0,0
0,0,0,0,0,0,0,0,0,0,0,0,0,0
0,0,0,0,0,0,0,0,0,0,0,0,0,0
0,0,0,0,0,7,0,6,0,0,0,0,0,0
0,0,0,0,0,0,7,7,8,0,0,0,0,0
0,0,0,0,0,9,7,7,14,0,0,0,0,0
0,0,0,0,0,0,0,10,0,0,0,0,0,0
0,0,0,0,0,0,0,0,0,0,0,0,0,0
0,0,0,0,11,0,0,0,0,0,12,0,0,0
0,0,0,11,12,0,0,0,0,0,0,0,0,0
0,0,0,0,0,0,13,0,0,0,0,0,13,0
0,0,0,0,0,0,0,0,0,0,0,0,0,0
:endlayer
layer: 6
0,0,0,0,0,0,0,0,0,0,0,0,0,0
0,0,0,0,0,0,0,0,0,0,0,0,0,0
0,0,0,0,0,0,0,0,0,0,0,0,0,0
0,0,0,0,15,0,0,0,0,0,0,0,0,0
0,0,15,0,15,0,0,0,0,0,0,0,0,0
0,15,15,15,15,15,0,15,0,0,0,0,0,0
0,0,0,15,7,15,0,15,0,0,0,0,0,0
0,15,15,15,7,15,15,15,0,0,0,0,0,0
0,0,0,15,15,15,7,7,8,0,0,0,0,0
0,15,15,15,15,15,7,7,16,0,0,0,0,0
0,0,15,15,15,0,0,10,0,0,0,0,0,0
0,0,0,0,0,0,0,0,0,0,0,0,0,0
0,0,0,0,11,0,0,0,0,0,17,0,0,0
0,0,0,11,12,0,0,0,0,0,0,0,0,0
0,0,0,0,0,0,13,0,0,0,0,0,13,0
0,0,0,0,0,0,0,0,0,0,0,0,0,0
:endlayer
layer: 7
0,0,0,0,0,0,0,0,0,0,0,0,0,0
0,0,0,0,0,0,0,0,0,0,0,0,0,0
0,0,0,0,0,0,0,0,0,0,0,0,0,0
0,0,0,0,0,0,0,0,0,0,0,0,0,0
0,0,0,0,15,0,0,0,0,0,0,0,0,0
0,0,15,0,15,0,15,0,0,0,0,0,0,0
0,0,15,7,15,15,0,0,0,0,0,0,0,0
0,15,0,15,15,15,15,0,0,0,0,0,0,0
0,0,15,15,15,15,7,7,8,0,0,0,0,0
0,0,15,0,15,9,7,7,8,0,0,0,0,0
0,0,0,9,0,0,18,10,0,0,0,0,0,0
0,0,0,0,0,0,0,0,0,0,0,0,0,0
0,0,0,0,11,0,0,0,0,0,0,0,0,0
0,0,0,11,17,0,0,0,0,0,0,0,0,0
0,0,0,0,0,0,19,0,0,0,0,0,19,0
0,0,0,0,0,0,0,0,0,0,0,0,0,0
:endlayer
layer: 8
0,0,0,0,0,0,0,0,0,0,0,0,0,0
0,0,0,0,0,0,0,0,0,0,0,0,0,0
0,0,0,0,0,0,0,0,0,0,0,0,0,0
0,0,0,0,0,0,0,0,0,0,0,0,0,0
0,0,0,0,0,0,0,0,0,0,0,0,0,0
0,0,0,0,15,0,0,0,0,0,0,0,0,0
0,0,0,15,15,15,0,0,0,0,0,0,0,0
0,0,15,15,15,15,0,7,0,0,0,0,0,0
0,0,0,15,15,9,7,7,8,0,0,0,0,0
0,0,0,0,0,9,7,7,8,0,0,0,0,0
0,0,0,9,0,0,11,10,0,0,0,0,0,0
0,0,0,0,0,0,0,0,0,0,0,0,0,0
0,0,0,0,11,0,0,0,0,0,0,0,0,0
0,0,0,11,11,0,0,0,0,0,0,0,0,0
0,0,0,0,0,0,0,0,0,0,0,0,0,0
0,0,0,0,0,0,0,0,0,0,0,0,0,0
:endlayer
layer: 9
0,0,0,0,0,0,0,0,0,0,0,0,0,0
0,0,0,0,0,0,0,0,0,0,0,0,0,0
0,0,0,0,0,0,0,0,0,15,0,0,0,0
0,0,0,0,0,0,0,15,15,15,15,15,0,0
0,0,0,0,0,0,15,15,0,15,15,15,15,0
0,0,0,0,0,0,0,0,15,15,15,15,15,0
0,0,0,0,0,15,15,7,15,15,15,15,15,0
0,0,0,0,0,0,0,6,15,15,15,0,0,0
0,0,0,0,0,9,7,7,15,15,0,15,0,0
0,0,0,0,0,9,7,7,15,15,0,0,0,0
0,0,0,9,0,0,11,10,0,0,0,0,0,0
0,0,0,0,0,0,0,0,0,0,0,0,0,0
0,0,0,0,11,0,0,0,0,0,0,0,0,0
0,0,0,11,11,0,0,0,0,0,0,0,0,0
0,0,0,0,0,0,0,0,0,0,0,0,0,0
0,0,0,0,0,0,0,0,0,0,0,0,0,0
:endlayer
layer: 10
0,0,0,0,0,0,0,0,0,0,0,0,0,0
0,0,0,0,0,0,0,0,0,0,0,0,0,0
0,0,0,0,0,0,0,0,0,0,0,0,0,0
0,0,0,0,0,0,0,0,0,0,0,0,0,0
0,0,0,0,0,0,0,15,15,15,0,0,0,0
0,0,0,0,0,0,0,15,7,15,15,15,0,0
0,0,0,0,0,0,15,15,15,15,15,15,0,0
0,0,0,0,0,0,0,15,0,15,15,0,0,0
0,0,0,0,0,9,7,7,0,0,0,0,0,0
0,0,0,0,0,9,7,7,8,0,0,0,0,0
0,0,0,9,0,0,11,10,0,0,0,0,0,0
0,0,0,0,0,0,0,0,0,0,0,0,0,0
0,0,0,0,11,0,0,0,0,0,0,0,0,0
0,0,0,11,11,0,0,0,0,0,0,0,0,0
0,0,0,0,0,0,0,0,0,0,0,0,0,0
0,0,0,0,0,0,0,0,0,0,0,0,0,0
:endlayer
layer: 11
0,0,0,0,0,0,0,0,0,0,0,0,0,0
0,0,0,0,0,0,0,0,0,0,0,0,0,0
0,0,0,0,0,0,0,0,0,0,0,0,0,0
0,0,0,0,0,0,0,15,0,0,0,0,0,0
0,0,0,0,0,0,15,15,15,15,15,0,0,0
0,0,0,20,20,15,20,15,15,15,0,0,0,0
0,0,20,0,20,15,15,15,15,15,15,0,0,0
0,0,0,15,15,15,15,15,15,15,15,0,0,0
0,0,15,15,15,15,7,7,15,15,15,15,0,0
0,0,15,15,15,15,7,7,15,15,15,15,0,0
0,0,0,9,15,15,15,10,15,15,15,0,0,0
0,0,0,0,15,15,15,15,15,15,0,0,0,0
0,0,0,0,11,15,15,15,15,0,0,0,0,0
0,0,0,11,11,0,15,15,0,0,0,0,0,0
0,0,0,0,0,0,0,0,0,0,0,0,0,0
0,0,0,0,0,0,0,0,0,0,0,0,0,0
:endlayer
layer: 12
0,0,0,0,0,0,0,0,0,0,0,0,0,0
0,0,0,0,0,0,0,0,0,0,0,0,0,0
0,0,0,0,0,0,0,0,0,0,0,0,0,0
0,0,0,0,0,0,0,0,0,0,0,0,0,0
0,0,0,0,0,0,0,0,0,0,0,0,0,0
0,0,0,0,0,0,0,0,15,15,15,0,0,0
0,0,0,0,20,15,15,15,15,15,0,0,0,0
0,0,0,0,20,15,15,15,15,15,0,0,0,0
0,0,0,15,0,15,15,15,15,15,15,0,0,0
0,0,0,15,15,15,15,7,15,15,15,15,0,0
0,0,0,9,15,15,15,10,15,15,0,0,0,0
0,0,0,0,0,15,15,15,15,15,0,0,0,0
0,0,0,0,0,0,0,15,15,0,0,0,0,0
0,0,0,11,11,0,11,15,0,0,0,0,0,0
0,0,0,0,0,0,0,0,0,0,0,0,0,0
0,0,0,0,0,0,0,0,0,0,0,0,0,0
:endlayer
layer: 13
0,0,0,0,0,0,0,0,0,0,0,0,0,0
0,0,0,0,0,0,0,0,0,0,0,0,0,0
0,0,0,0,0,0,0,0,0,0,0,0,0,0
0,0,0,0,0,0,0,0,0,0,0,0,0,0
0,0,0,0,0,0,0,0,0,0,0,0,0,0
0,0,0,21,21,21,21,21,21,21,21,0,0,0
0,0,0,21,21,21,21,21,21,21,21,0,0,0
0,0,0,21,21,21,21,21,21,21,21,0,0,0
0,0,0,21,21,21,21,21,21,21,21,0,0,0
0,0,0,21,21,21,21,21,21,21,21,0,0,0
0,0,0,21,21,21,21,10,21,21,21,0,0,0
0,0,0,21,21,21,21,21,21,21,21,0,0,0
0,0,0,21,21,21,21,21,21,21,21,0,0,0
0,0,0,11,11,0,11,0,0,0,0,0,0,0
0,0,0,0,0,0,0,0,0,0,0,0,0,0
0,0,0,0,0,0,0,0,0,0,0,0,0,0
:endlayer
layer: 14
0,0,0,0,0,0,0,0,0,0,0,0,0,0
0,0,0,0,0,0,0,0,0,0,0,0,0,0
0,0,0,0,0,0,0,0,0,0,0,0,0,0
0,0,0,0,0,0,0,0,0,0,0,0,0,0
0,0,0,0,0,0,0,0,0,0,0,0,0,0
0,0,0,7,7,12,7,7,12,7,7,0,0,0
0,0,0,7,0,0,0,0,0,0,7,0,0,0
0,0,0,12,0,0,22,0,0,0,12,0,0,0
0,0,0,7,0,0,0,0,0,0,7,0,0,0
0,0,0,7,12,12,12,12,12,12,7,0,0,0
0,0,0,12,0,0,0,0,0,0,12,0,0,0
0,0,0,7,0,0,0,0,0,0,7,0,0,0
0,0,0,7,7,12,7,7,12,7,7,0,0,0
0,0,0,11,11,0,11,0,0,0,0,0,0,0
0,0,0,0,0,0,0,0,0,0,0,0,0,0
0,0,0,0,0,0,0,0,0,0,0,0,0,0
:endlayer
layer: 15
0,0,0,0,0,0,0,0,0,0,0,0,0,0
0,0,0,0,0,0,0,0,0,0,0,0,0,0
0,0,0,0,0,0,0,0,0,0,0,0,0,0
0,0,0,0,0,0,0,0,0,0,0,0,0,0
0,0,0,0,0,0,0,0,0,0,0,0,0,0
0,0,0,7,7,17,7,7,17,7,7,0,0,0
0,0,0,7,0,0,0,0,0,0,7,0,0,0
0,0,0,17,0,0,0,0,0,0,17,0,0,0
0,0,0,7,0,0,0,0,0,0,7,0,0,0
0,0,0,7,0,0,0,0,0,0,7,0,0,0
0,0,0,17,0,0,0,0,0,0,17,0,0,0
0,0,0,7,0,0,0,0,0,0,7,0,0,0
0,0,0,7,7,17,7,7,17,7,7,0,0,0
0,0,0,11,11,0,11,0,0,0,0,0,0,0
0,0,0,0,0,0,0,0,0,0,0,0,0,0
0,0,0,0,0,0,0,0,0,0,0,0,0,0
:endlayer
layer: 16
0,0,0,0,0,0,0,0,0,0,0,0,0,0
0,0,0,0,0,0,0,0,0,0,0,0,0,0
0,0,0,0,0,0,0,0,0,0,0,0,0,0
0,0,0,0,0,0,0,0,0,0,0,0,0,0
0,0,0,0,0,0,0,0,0,0,0,0,0,0
0,0,0,7,7,7,7,7,7,7,7,0,0,0
0,0,0,7,0,0,0,0,0,0,7,0,0,0
0,0,0,7,0,0,0,0,0,0,7,0,0,0
0,0,0,7,0,0,0,0,0,0,7,0,0,0
0,0,0,7,12,12,12,12,12,12,7,0,0,0
0,0,0,7,0,0,0,0,0,0,7,0,0,0
0,0,0,7,0,0,0,0,0,0,7,0,0,0
0,0,0,7,7,7,7,7,7,7,7,0,0,0
0,0,0,11,11,0,11,0,0,0,0,0,0,0
0,0,0,0,0,0,0,0,0,0,0,0,0,0
0,0,0,0,0,0,0,0,0,0,0,0,0,0
:endlayer
layer: 17
0,0,0,0,0,0,0,0,0,0,0,0,0,0
0,0,0,0,0,0,0,0,0,0,0,0,0,0
0,0,0,0,0,0,0,0,0,0,0,0,0,0
0,0,0,0,0,0,0,0,0,0,0,0,0,0
0,0,0,0,0,0,0,0,0,0,0,0,0,0
0,0,0,21,21,21,21,21,21,21,21,0,0,0
0,0,0,21,0,0,0,0,0,0,21,0,0,0
0,0,0,21,0,0,0,0,0,0,21,0,0,0
0,0,0,21,0,0,0,0,0,0,21,0,0,0
0,0,0,21,12,12,12,12,12,12,21,0,0,0
0,0,0,21,0,0,0,0,0,0,21,0,0,0
0,0,0,21,0,0,0,0,0,0,21,0,0,0
0,0,0,21,21,21,21,21,21,21,21,0,0,0
0,0,0,11,11,0,11,0,0,0,0,0,0,0
0,0,0,0,0,0,0,0,0,0,0,0,0,0
0,0,0,0,0,0,0,0,0,0,0,0,0,0
:endlayer
layer: 18
0,0,0,0,0,0,0,0,0,0,0,0,0,0
0,0,0,0,0,0,0,0,0,0,0,0,0,0
0,0,0,0,0,0,0,0,0,0,0,0,0,0
0,0,0,0,0,0,0,0,0,0,0,0,0,0
0,0,0,0,0,0,0,0,0,0,0,0,0,0
0,0,0,0,0,0,0,0,0,0,0,0,0,0
0,0,0,0,7,7,7,7,7,7,0,0,0,0
0,0,0,0,7,0,0,0,0,7,0,0,0,0
0,0,0,0,7,0,0,0,0,7,0,0,0,0
0,0,0,0,7,12,12,12,12,7,0,0,0,0
0,0,0,0,7,0,0,0,0,7,0,0,0,0
0,0,0,0,7,7,7,7,7,7,0,0,0,0
0,0,0,0,0,0,0,0,0,0,0,0,0,0
0,0,0,0,0,0,0,0,0,0,0,0,0,0
0,0,0,0,0,0,0,0,0,0,0,0,0,0
0,0,0,0,0,0,0,0,0,0,0,0,0,0
:endlayer
layer: 19
0,0,0,0,0,0,0,0,0,0,0,0,0,0
0,0,0,0,0,0,0,0,0,0,0,0,0,0
0,0,0,0,0,0,0,0,0,0,0,0,0,0
0,0,0,0,0,0,0,0,0,0,0,0,0,0
0,0,0,0,0,0,0,0,0,0,0,0,0,0
0,0,0,0,0,0,0,0,0,0,0,0,0,0
0,0,0,0,0,0,0,0,0,0,0,0,0,0
0,0,0,0,0,7,7,7,7,0,0,0,0,0
0,0,0,0,0,7,0,0,7,0,0,0,0,0
0,0,0,0,0,7,12,12,7,0,0,0,0,0
0,0,0,0,0,7,7,7,7,0,0,0,0,0
0,0,0,0,0,0,0,0,0,0,0,0,0,0
0,0,0,0,0,0,0,0,0,0,0,0,0,0
0,0,0,0,0,0,0,0,0,0,0,0,0,0
0,0,0,0,0,0,0,0,0,0,0,0,0,0
0,0,0,0,0,0,0,0,0,0,0,0,0,0
:endlayer
layer: 20
0,0,0,0,0,0,0,0,0,0,0,0,0,0
0,0,0,0,0,0,0,0,0,0,0,0,0,0
0,0,0,0,0,0,0,0,0,0,0,0,0,0
0,0,0,0,0,0,0,0,0,0,0,0,0,0
0,0,0,0,0,0,0,0,0,0,0,0,0,0
0,0,0,0,0,0,0,0,0,0,0,0,0,0
0,0,0,0,0,0,0,0,0,0,0,0,0,0
0,0,0,0,0,0,0,0,0,0,0,0,0,0
0,0,0,0,0,0,7,7,0,0,0,0,0,0
0,0,0,0,0,0,7,7,0,0,0,0,0,0
0,0,0,0,0,0,0,0,0,0,0,0,0,0
0,0,0,0,0,0,0,0,0,0,0,0,0,0
0,0,0,0,0,0,0,0,0,0,0,0,0,0
0,0,0,0,0,0,0,0,0,0,0,0,0,0
0,0,0,0,0,0,0,0,0,0,0,0,0,0
0,0,0,0,0,0,0,0,0,0,0,0,0,0
:endlayer

#### RULES ####
rule:
plugin=vanillaBlocks
number=1
data:
JSON:{blockState:{blockName:"minecraft:dirt",properties:{variant:"dirt",snowy:"false"}}}
:enddata
:endrule

rule:
plugin=vanillaBlocks
number=2
data:
JSON:{blockState:{blockName:"minecraft:grass",properties:{snowy:"false"}}}
:enddata
:endrule

rule:
plugin=vanillaBlocks
number=3
data:
JSON:{blockState:{blockName:"minecraft:tallgrass",properties:{type:"tall_grass"}}}
:enddata
:endrule

rule:
plugin=vanillaBlocks
number=4
data:
JSON:{blockState:{blockName:"minecraft:red_flower",properties:{type:"poppy"}}}
:enddata
:endrule

rule:
plugin=vanillaBlocks
number=5
data:
JSON:{blockState:{blockName:"minecraft:red_flower",properties:{type:"houstonia"}}}
:enddata
:endrule

rule:
plugin=vine
number=6
data:
JSON:{blockState:{blockName:"minecraft:vine",properties:{east:"false",south:"true",north:"false",west:"false",up:"false"}}}
:enddata
:endrule

rule:
plugin=vanillaBlocks
number=7
data:
JSON:{blockState:{blockName:"minecraft:log",properties:{variant:"jungle",axis:"y"}}}
:enddata
:endrule

rule:
plugin=vine
number=8
data:
JSON:{blockState:{blockName:"minecraft:vine",properties:{east:"false",south:"false",north:"false",west:"true",up:"false"}}}
:enddata
:endrule

rule:
plugin=vine
number=9
data:
JSON:{blockState:{blockName:"minecraft:vine",properties:{east:"true",south:"false",north:"false",west:"false",up:"false"}}}
:enddata
:endrule

rule:
plugin=vanillaBlocks
number=10
data:
JSON:{blockState:{blockName:"minecraft:ladder",properties:{facing:"south"}}}
:enddata
:endrule

rule:
plugin=vine
number=11
data:
JSON:{blockState:{blockName:"minecraft:vine",properties:{east:"false",south:"false",north:"true",west:"false",up:"false"}}}
:enddata
:endrule

rule:
plugin=vanillaBlocks
number=12
data:
JSON:{blockState:{blockName:"minecraft:fence",properties:{east:"false",south:"false",north:"false",west:"false"}}}
:enddata
:endrule

rule:
plugin=vanillaBlocks
number=13
data:
JSON:{blockState:{blockName:"minecraft:stone",properties:{variant:"stone"}}}
:enddata
:endrule

rule:
plugin=vanillaSign
number=14
data:
JSON:{signContents0:"KONG§r§r",blockState:{blockName:"minecraft:wall_sign",properties:{facing:"east"}},signContents2:"WELCOME§r§r",signContents1:"TRADER§r§r",signContents3:"ALL§r§r",rotation:0}
:enddata
:endrule

rule:
plugin=vanillaBlocks
number=15
data:
JSON:{blockState:{blockName:"minecraft:leaves",properties:{check_decay:"false",decayable:"true",variant:"jungle"}}}
:enddata
:endrule

rule:
plugin=vanillaBlocks
number=16
data:
JSON:{blockState:{blockName:"minecraft:torch",properties:{facing:"east"}}}
:enddata
:endrule

rule:
plugin=vanillaBlocks
number=17
data:
JSON:{blockState:{blockName:"minecraft:torch",properties:{facing:"up"}}}
:enddata
:endrule

rule:
plugin=vanillaBlocks
number=18
data:
JSON:{blockState:{blockName:"minecraft:torch",properties:{facing:"south"}}}
:enddata
:endrule

rule:
plugin=vanillaBlocks
number=19
data:
JSON:{blockState:{blockName:"ancientwarfarestructure:fire_pit",properties:{lit:"true",variant:"default"}}}
:enddata
:endrule

rule:
plugin=vanillaBlocks
number=20
data:
JSON:{blockState:{blockName:"minecraft:leaves",properties:{check_decay:"true",decayable:"false",variant:"oak"}}}
:enddata
:endrule

rule:
plugin=vanillaBlocks
number=21
data:
JSON:{blockState:{blockName:"minecraft:planks",properties:{variant:"jungle"}}}
:enddata
:endrule

rule:
plugin=blockTile
number=22
data:
JSON:{blockState:{blockName:"ancientwarfarestructure:advanced_spawner",properties:{transparent:"true"}},teData:{id:"ancientwarfarestructure:advanced_spawner_tile",spawnerSettings:{minDelay:0,spawnDelay:0,lightSensitive:0b,spawnGroups:[{settingsList:[{remainingSpawnCount:1,hostile:1b,forced:1b,customTag:{factionName:"kong",tradeList:{ticks:91,tradeList:[{refillFrequency:6000,currentAvailable:5,ticksTilRefill:6000,inputItems:[{id:"minecraft:rotten_flesh",Count:16b,slot:5,Damage:0s}],outputItems:[{id:"minecraft:gold_nugget",Count:8b,slot:3,Damage:0s}],maxAvailable:5},{refillFrequency:5993,currentAvailable:5,ticksTilRefill:5993,inputItems:[{id:"minecraft:rotten_flesh",Count:32b,slot:5,Damage:0s}],outputItems:[{id:"minecraft:dye",Count:16b,slot:3,Damage:3s}],maxAvailable:5},{refillFrequency:6012,currentAvailable:5,ticksTilRefill:6012,inputItems:[{id:"minecraft:rotten_flesh",Count:32b,slot:5,Damage:0s}],outputItems:[{id:"minecraft:feather",Count:32b,slot:3,Damage:0s}],maxAvailable:5},{refillFrequency:6000,currentAvailable:5,ticksTilRefill:6000,inputItems:[{id:"minecraft:rotten_flesh",Count:32b,slot:5,Damage:0s}],outputItems:[{id:"minecraft:dye",Count:24b,slot:3,Damage:4s}],maxAvailable:5},{refillFrequency:6000,currentAvailable:5,ticksTilRefill:6000,inputItems:[{id:"minecraft:bone",Count:32b,slot:5,Damage:0s}],outputItems:[{id:"minecraft:gold_nugget",Count:24b,slot:3,Damage:0s}],maxAvailable:5},{refillFrequency:6000,currentAvailable:1,ticksTilRefill:6000,inputItems:[{id:"minecraft:rotten_flesh",Count:64b,slot:5,Damage:0s}],outputItems:[{id:"minecraft:diamond",Count:1b,slot:3,Damage:0s}],maxAvailable:1}]}},maxToSpawn:1,entityId:"ancientwarfarenpc:faction.trader",minToSpawn:1}],groupWeight:1}],playerRange:6,respondToRedstone:0b,inventory:{Size:9,Items:[]},spawnRange:0,transparent:1b,maxDelay:0,xpToDrop:0,mobRange:0,debugMode:0b,maxNearbyMonsters:0}}}
:enddata
:endrule

#### ENTITIES ####
