# Ancient Warfare Structure Template File
# Auto-generated structure template file. created on: 8/19/2019 at: 10:23:11
# Lines beginning with # denote comments

header:
version=2.9
name=KongTreehouse2
mods=
size=18,30,19
offset=9,4,18
:endheader

#### VALIDATION ####
validation:
type=ground
survival=false
worldGenEnabled=true
unique=false
preserveBlocks=false
selectionWeight=30
clusterValue=40
minDuplicateDistance=900
dimensionWhiteList=true
dimensionList=0
biomeWhiteList=true
biomeList=minecraft:jungle
leveling=3
fill=2
border=3
blockSwap=false
:endvalidation

#### LAYERS ####
layer: 0
1,1,1,1,1,1,1,1,1,1,1,1,1,1,1,1,1,1
1,1,1,1,1,1,1,1,1,1,1,1,1,1,1,1,1,1
1,1,1,1,1,1,1,1,1,1,1,1,1,1,1,1,1,1
1,1,1,1,1,1,1,1,1,1,1,1,1,1,1,1,1,1
1,1,1,1,1,1,1,1,1,1,1,1,1,1,1,1,1,1
1,1,1,1,1,1,1,1,1,1,1,1,1,1,1,1,1,1
1,1,1,1,1,1,1,1,1,1,1,1,1,1,1,1,1,1
1,1,1,1,1,1,1,1,1,1,1,1,1,1,1,1,1,1
1,1,1,1,1,1,1,1,1,1,1,1,1,1,1,1,1,1
1,1,1,1,1,1,1,1,1,1,1,1,1,1,1,1,1,1
1,1,1,1,1,1,1,1,1,1,1,1,1,1,1,1,1,1
1,1,1,1,1,1,1,1,1,1,1,1,1,1,1,1,1,1
1,1,1,1,1,1,1,1,1,1,1,1,1,1,1,1,1,1
1,1,1,1,1,1,1,1,1,1,1,1,1,1,1,1,1,1
1,1,1,1,1,1,1,1,1,1,1,1,1,1,1,1,1,1
1,1,1,1,1,1,1,1,1,1,1,1,1,1,1,1,1,1
1,1,1,1,1,1,1,1,1,1,1,1,1,1,1,1,1,1
1,1,1,1,1,1,1,1,1,1,1,1,1,1,1,1,1,1
1,1,1,1,1,1,1,1,1,1,1,1,1,1,1,1,1,1
:endlayer
layer: 1
1,1,1,1,1,1,1,1,1,1,1,1,1,1,1,1,1,1
1,1,1,1,1,1,1,1,1,1,1,1,1,1,1,1,1,1
1,1,1,1,1,1,1,1,1,1,1,1,1,1,1,1,1,1
1,1,1,1,1,1,1,1,1,1,1,1,1,1,1,1,1,1
1,1,1,1,1,1,1,1,1,1,1,1,1,1,1,1,1,1
1,1,1,1,1,1,1,1,1,1,1,1,1,1,1,1,1,1
1,1,1,1,1,1,1,1,1,1,1,1,1,1,1,1,1,1
1,1,1,1,1,1,1,1,1,1,1,1,1,1,1,1,1,1
1,1,1,1,1,1,1,1,1,1,1,1,1,1,1,1,1,1
1,1,1,1,1,1,1,1,1,1,1,1,1,1,1,1,1,1
1,1,1,1,1,1,1,1,1,1,1,1,1,1,1,1,1,1
1,1,1,1,1,1,1,1,1,1,1,1,1,1,1,1,1,1
1,1,1,1,1,1,1,1,1,1,1,1,1,1,1,1,1,1
1,1,1,1,1,1,1,1,1,1,1,1,1,1,1,1,1,1
1,1,1,1,1,1,1,1,1,1,1,1,1,1,1,1,1,1
1,1,1,1,1,1,1,1,1,1,1,1,1,1,1,1,1,1
1,1,1,1,1,1,1,1,1,1,1,1,1,1,1,1,1,1
1,1,1,1,1,1,1,1,1,1,1,1,1,1,1,1,1,1
1,1,1,1,1,1,1,1,1,1,1,1,1,1,1,1,1,1
:endlayer
layer: 2
1,1,1,1,1,1,1,1,1,1,1,1,1,1,1,1,1,1
1,1,1,1,1,1,1,1,1,1,1,1,1,1,1,1,1,1
1,1,1,1,1,1,1,1,1,1,1,1,1,1,1,1,1,1
1,1,1,1,1,1,1,1,1,1,1,1,1,1,1,1,1,1
1,1,1,1,1,1,1,1,1,1,1,1,1,1,1,1,1,1
1,1,1,1,1,1,1,1,1,1,1,1,1,1,1,1,1,1
1,1,1,1,1,1,1,1,1,1,1,1,1,1,1,1,1,1
1,1,1,1,1,1,1,1,1,1,1,1,1,1,1,1,1,1
1,1,1,1,1,1,1,1,1,1,1,1,1,1,1,1,1,1
1,1,1,1,1,1,1,1,1,1,1,1,1,1,1,1,1,1
1,1,1,1,1,1,1,1,1,1,1,1,1,1,1,1,1,1
1,1,1,1,1,1,1,1,1,1,1,1,1,1,1,1,1,1
1,1,1,1,1,1,1,1,1,1,1,1,1,1,1,1,1,1
1,1,1,1,1,1,1,1,1,1,1,1,1,1,1,1,1,1
1,1,1,1,1,1,1,1,1,1,1,1,1,1,1,1,1,1
1,1,1,1,1,1,1,1,1,1,1,1,1,1,1,1,1,1
1,1,1,1,1,1,1,1,1,1,1,1,1,1,1,1,1,1
1,1,1,1,1,1,1,1,1,1,1,1,1,1,1,1,1,1
1,1,1,1,1,1,1,1,1,1,1,1,1,1,1,1,1,1
:endlayer
layer: 3
2,2,2,2,2,2,2,2,2,2,2,2,2,2,2,2,2,2
2,2,2,2,2,2,2,2,2,2,2,2,2,2,2,2,2,2
2,2,2,2,2,2,2,2,2,2,2,2,2,2,2,2,2,2
2,2,2,2,2,2,2,2,2,2,2,2,2,2,2,2,2,2
2,2,2,2,2,2,2,2,2,2,2,2,2,2,2,2,2,2
2,2,2,2,2,2,2,2,2,2,2,2,2,2,2,2,2,2
2,2,2,2,2,2,2,2,2,2,2,2,2,2,2,2,2,2
2,2,2,2,2,2,2,2,2,2,2,1,1,2,2,2,2,2
2,2,2,2,2,2,2,2,2,2,2,1,1,2,2,2,2,2
2,2,2,2,2,2,2,2,2,2,2,2,2,2,2,2,2,2
2,2,2,2,2,2,1,1,2,2,2,2,2,2,2,2,2,2
2,2,2,2,2,2,1,1,2,2,2,2,2,2,2,2,2,2
2,2,2,2,2,2,2,2,2,2,2,2,2,2,2,2,2,2
2,2,2,2,2,2,2,2,2,2,2,2,2,2,2,2,2,2
2,2,2,2,2,2,2,2,2,2,2,2,2,2,2,2,2,2
2,2,2,2,2,2,2,2,2,2,2,2,2,2,2,2,2,2
2,2,2,2,2,2,2,2,2,2,2,2,2,2,2,2,2,2
2,2,2,2,2,2,2,2,2,2,2,2,2,2,2,2,2,2
2,2,2,2,2,2,2,2,2,2,2,2,2,2,2,2,2,2
:endlayer
layer: 4
0,0,0,3,0,0,0,3,3,0,3,3,0,0,0,0,0,0
3,3,3,3,3,0,0,0,0,3,3,3,3,3,0,0,0,0
3,3,3,3,3,0,0,0,3,3,3,3,3,3,0,0,3,0
3,4,0,3,0,0,0,0,3,0,0,3,4,0,0,5,0,0
0,3,3,0,6,0,3,0,0,0,0,0,0,0,0,0,0,0
0,3,0,0,0,0,3,0,3,3,0,0,3,3,0,3,3,0
0,0,3,0,0,3,3,0,3,3,0,0,7,3,3,3,3,0
0,3,0,0,3,3,3,3,3,3,0,8,8,9,3,3,3,0
0,0,3,3,3,3,0,3,3,0,0,8,8,9,3,3,3,0
3,3,0,3,3,3,7,7,0,0,0,0,10,3,3,0,0,0
3,3,3,3,11,12,8,8,9,0,0,13,14,3,0,0,0,0
0,0,3,3,0,12,8,8,15,0,0,16,3,17,3,0,0,0
3,3,3,3,0,0,18,19,3,3,3,3,3,16,3,0,0,0
0,0,0,0,3,3,3,3,3,0,3,3,3,0,3,0,0,0
0,0,0,0,0,20,3,3,3,0,0,3,21,22,3,9,0,0
0,0,3,0,23,0,3,3,0,3,0,0,0,0,9,9,0,0
0,0,0,0,0,0,3,0,0,3,0,20,0,3,3,3,4,0
0,0,0,0,3,3,3,3,3,0,0,0,3,19,3,3,0,3
0,0,0,3,3,3,3,0,0,0,0,0,3,3,3,3,3,0
:endlayer
layer: 5
0,0,0,0,0,0,0,0,0,0,0,0,0,0,0,0,0,0
0,0,0,0,0,0,0,0,0,0,0,0,0,0,0,0,0,0
0,0,0,0,0,0,0,0,0,0,0,0,0,0,0,0,0,0
0,0,0,0,0,0,0,0,0,0,0,0,0,0,0,0,0,0
0,0,0,0,0,0,0,0,0,0,0,0,0,0,0,0,0,0
0,0,0,0,0,0,0,0,0,0,0,0,0,0,0,0,0,0
0,0,0,0,0,0,0,0,0,0,0,0,7,0,0,0,0,0
0,0,0,0,0,0,0,0,0,0,0,8,8,9,0,0,0,0
0,0,0,0,0,0,0,0,0,0,0,8,8,9,0,0,0,0
0,0,0,0,0,0,7,7,0,0,0,0,10,0,0,0,0,0
0,0,0,0,0,12,8,8,9,0,0,0,0,0,0,0,0,0
0,0,0,0,0,12,8,8,15,0,0,0,0,0,0,0,0,0
0,0,0,0,0,0,18,19,0,0,0,0,0,0,0,0,0,0
0,0,0,0,0,0,0,0,0,0,0,0,0,0,0,0,0,0
0,0,0,0,0,0,0,0,0,0,0,0,21,0,9,9,0,0
0,0,0,0,0,0,0,0,0,0,0,0,0,0,9,9,0,0
0,0,0,0,0,0,0,0,0,0,0,0,0,19,0,9,0,0
0,0,0,0,0,0,0,0,0,0,0,0,0,19,0,0,0,0
0,0,0,0,0,0,0,0,0,0,0,0,0,0,0,0,0,0
:endlayer
layer: 6
0,0,0,0,0,0,0,0,0,0,0,0,0,0,0,0,0,0
0,0,0,0,0,0,0,0,0,0,0,0,0,0,0,0,0,0
0,0,0,0,0,0,0,0,0,0,0,0,0,0,0,0,0,0
0,0,0,0,0,0,0,0,0,0,0,0,0,0,0,0,0,0
0,0,0,0,0,0,0,0,0,0,0,0,0,0,0,0,0,0
0,0,0,0,0,0,0,0,0,0,0,0,0,0,0,0,0,0
0,0,0,0,0,0,0,0,0,0,0,0,7,0,0,0,0,0
0,0,0,0,0,0,0,0,0,0,0,8,8,9,0,0,0,0
0,0,0,0,0,0,0,0,0,0,0,8,8,9,0,0,0,0
0,0,0,0,0,0,7,7,0,0,0,0,10,0,0,0,0,0
0,0,0,0,0,12,8,8,9,0,0,0,0,0,0,0,0,0
0,0,0,0,0,12,8,8,15,0,0,0,0,0,0,0,0,0
0,0,0,0,0,0,18,19,0,0,0,0,0,0,0,0,0,0
0,0,0,0,0,0,0,0,0,0,0,0,0,0,0,0,0,0
0,0,0,0,0,0,0,0,0,0,0,0,21,0,9,9,0,0
0,0,0,0,0,0,0,0,0,0,0,0,0,0,9,9,0,0
0,0,0,0,0,0,0,0,0,0,0,0,0,19,0,9,0,0
0,0,0,0,0,0,0,0,0,0,0,0,0,19,0,0,0,0
0,0,0,0,0,0,0,0,0,0,0,0,0,0,0,0,0,0
:endlayer
layer: 7
0,0,0,0,0,0,0,0,0,0,0,0,0,0,0,0,0,0
0,0,0,0,0,0,0,0,0,0,0,0,0,0,0,0,0,0
0,0,0,0,0,0,0,0,0,0,0,0,0,0,0,0,0,0
0,0,0,0,0,0,0,0,0,0,0,0,0,0,0,0,0,0
0,0,0,0,0,0,0,0,0,0,0,0,0,0,0,0,0,0
0,0,0,0,0,0,0,0,0,0,0,0,0,0,0,0,0,0
0,0,0,0,0,0,0,0,0,0,0,0,7,0,0,0,0,0
0,0,0,0,0,0,0,0,0,0,0,8,8,9,0,0,0,0
0,0,0,0,0,0,0,0,24,24,24,8,8,9,0,0,0,0
0,0,0,0,0,0,7,7,24,24,24,24,9,0,0,0,0,0
0,0,0,0,0,12,8,8,24,24,24,24,0,0,0,0,0,0
0,0,0,0,0,12,8,8,15,24,24,24,0,0,0,0,0,0
0,0,0,0,0,0,18,19,24,24,24,24,0,0,0,0,0,0
0,0,0,0,0,0,0,0,24,24,24,24,0,0,0,0,0,0
0,0,0,0,0,0,0,0,0,0,0,0,21,0,9,9,0,0
0,0,0,0,0,0,0,0,0,0,0,0,0,0,9,9,0,0
0,0,0,0,0,0,0,0,0,0,0,0,0,19,0,9,0,0
0,0,0,0,0,0,0,0,0,0,0,0,0,19,0,0,0,0
0,0,0,0,0,0,0,0,0,0,0,0,0,0,0,0,0,0
:endlayer
layer: 8
0,0,0,0,0,0,0,0,0,0,0,0,0,0,0,0,0,0
0,0,0,0,0,0,0,0,0,0,0,0,0,0,0,0,0,0
0,0,0,0,0,0,0,0,0,0,0,0,0,0,0,0,0,0
0,0,0,0,0,0,0,0,0,0,0,0,0,0,0,0,0,0
0,0,0,0,0,0,0,0,0,0,0,0,0,0,0,0,0,0
0,0,0,0,0,0,0,0,0,0,0,0,0,0,0,0,0,0
0,0,0,0,0,0,0,0,0,0,0,0,7,0,0,0,0,0
0,0,0,0,0,0,0,24,24,24,24,8,8,9,0,0,0,0
0,0,0,0,0,0,0,24,24,24,24,8,8,9,0,0,0,0
0,0,0,0,0,0,7,24,24,24,24,24,24,0,0,0,0,0
0,0,0,0,0,12,8,8,24,24,24,24,24,0,0,0,0,0
0,0,0,0,0,12,8,8,15,24,24,24,24,0,0,0,0,0
0,0,0,0,0,0,18,24,24,24,24,24,24,0,0,0,0,0
0,0,0,0,0,0,0,24,24,24,24,24,24,0,0,0,0,0
0,0,0,0,0,0,0,24,24,24,24,24,24,0,9,9,0,0
0,0,0,0,0,0,0,0,0,0,0,0,0,0,9,9,0,0
0,0,0,0,0,0,0,0,0,0,0,0,0,19,0,9,0,0
0,0,0,0,0,0,0,0,0,0,0,0,0,19,0,0,0,0
0,0,0,0,0,0,0,0,0,0,0,0,0,0,0,0,0,0
:endlayer
layer: 9
0,0,0,0,0,0,0,0,0,0,0,0,0,0,0,0,0,0
0,0,0,0,0,0,0,0,0,0,0,0,0,0,0,0,0,0
0,0,0,0,0,0,0,0,0,0,0,0,0,0,0,0,0,0
0,0,0,0,0,0,0,0,0,0,0,0,0,0,0,0,0,0
0,0,0,0,0,0,0,0,0,0,0,0,0,0,0,0,0,0
0,0,0,0,0,0,0,0,0,0,0,0,0,0,0,0,0,0
0,0,0,0,0,0,0,0,0,0,0,0,7,0,0,0,0,0
0,0,0,0,0,0,0,21,21,25,21,8,8,9,0,0,0,0
0,0,0,0,0,0,0,21,0,0,12,8,8,9,0,0,0,0
0,0,0,0,0,0,7,21,0,0,26,19,21,0,0,0,0,0
0,0,0,0,0,12,8,8,9,0,27,0,21,0,0,0,0,0
0,0,0,0,0,12,8,8,15,0,28,0,21,0,0,0,0,0
0,0,0,0,0,0,18,21,0,29,0,0,21,0,0,0,0,0
0,0,0,0,0,0,0,21,0,0,0,0,21,0,0,0,0,0
0,0,0,0,0,0,0,21,21,30,21,21,21,0,9,9,0,0
0,0,0,0,0,0,0,0,0,0,0,0,0,0,9,9,0,0
0,0,0,0,0,0,0,0,0,0,0,0,0,19,0,9,0,0
0,0,0,0,0,0,0,0,0,0,0,0,0,19,0,0,0,0
0,0,0,0,0,0,0,0,0,0,0,0,0,0,0,0,0,0
:endlayer
layer: 10
0,0,0,0,0,0,0,0,0,0,0,0,0,0,0,0,0,0
0,0,0,0,0,0,0,0,0,0,0,0,0,0,0,0,0,0
0,0,0,0,0,0,0,0,0,0,0,0,0,0,0,0,0,0
0,0,0,0,0,0,0,0,0,0,0,0,0,0,0,0,0,0
0,0,0,0,0,0,0,0,0,0,0,0,0,0,0,0,0,0
0,0,0,0,0,0,0,0,0,0,0,0,0,0,0,0,0,0
0,0,0,0,0,0,0,0,0,0,0,0,7,0,0,0,0,0
0,0,0,0,0,0,0,31,0,0,12,8,8,9,0,0,0,0
0,0,0,0,0,0,0,0,0,0,12,8,8,9,0,0,0,0
0,0,0,0,0,0,7,7,0,0,0,19,19,0,0,0,0,0
0,0,0,0,0,12,8,8,9,0,0,0,0,0,0,0,0,0
0,0,0,0,0,12,8,8,15,0,0,0,0,0,0,0,0,0
0,0,0,0,0,0,18,19,0,0,0,0,0,0,0,0,0,0
0,0,0,0,0,0,0,0,0,0,0,0,0,0,0,0,0,0
0,0,0,0,0,0,0,31,0,0,0,0,31,0,9,9,0,0
0,0,0,0,0,0,0,0,0,0,0,0,0,0,9,9,0,0
0,0,0,0,0,0,0,0,0,0,0,0,0,19,0,9,0,0
0,0,0,0,0,0,0,0,0,0,0,0,0,19,0,0,0,0
0,0,0,0,0,0,0,0,0,0,0,0,0,0,0,0,0,0
:endlayer
layer: 11
0,0,0,0,0,0,0,0,0,0,0,0,0,0,0,0,0,0
0,0,0,0,0,0,0,0,0,0,0,0,0,0,0,0,0,0
0,0,0,0,0,0,0,0,0,0,0,0,0,0,0,0,0,0
0,0,0,0,0,0,0,0,0,0,0,0,0,0,0,0,0,0
0,0,0,0,0,0,0,0,0,0,0,0,0,0,0,0,0,0
0,0,0,0,0,0,0,0,0,0,0,0,0,0,0,0,0,0
0,0,0,0,0,0,0,0,0,0,0,0,0,0,0,0,0,0
0,0,0,0,0,0,0,0,0,0,12,8,8,9,0,0,0,0
0,0,0,0,0,0,0,0,0,0,12,8,8,9,0,0,0,0
0,0,0,0,0,0,7,7,0,0,0,19,19,0,0,0,0,0
0,0,0,0,0,12,8,8,9,0,0,0,0,0,0,0,0,0
0,0,0,0,0,12,8,8,15,0,0,0,0,0,0,0,0,0
0,0,0,0,0,0,18,19,0,0,0,0,0,0,0,0,0,0
0,0,0,0,0,0,0,0,0,0,0,0,0,0,0,0,0,0
0,0,0,0,0,0,0,0,0,0,0,0,0,0,9,9,0,0
0,0,0,0,0,0,0,0,0,0,0,0,0,0,9,9,0,0
0,0,0,0,0,0,0,0,0,0,0,0,0,19,0,9,0,0
0,0,0,0,0,0,0,0,0,0,0,0,0,19,0,0,0,0
0,0,0,0,0,0,0,0,0,0,0,0,0,0,0,0,0,0
:endlayer
layer: 12
0,0,0,0,0,0,0,0,0,0,0,0,0,0,0,0,0,0
0,0,0,0,0,0,0,0,0,0,0,0,0,0,0,0,0,0
0,0,0,0,0,0,0,0,0,0,0,0,0,0,0,0,0,0
0,0,0,0,0,0,0,0,0,0,0,0,0,0,0,0,0,0
0,0,0,0,0,0,0,0,0,0,0,0,0,0,0,0,0,0
0,0,0,0,0,0,0,0,0,0,0,0,0,0,0,0,0,0
0,0,0,0,0,0,0,0,0,0,0,0,0,0,0,0,0,0
0,0,0,0,0,0,0,0,0,0,12,8,8,9,0,0,0,0
0,0,0,0,0,0,0,0,0,0,12,8,8,9,0,0,0,0
0,0,0,0,0,0,7,7,0,0,0,19,19,0,0,0,0,0
0,0,0,0,0,12,8,8,9,0,0,0,0,0,0,0,0,0
0,0,0,0,0,12,8,8,15,0,0,0,0,0,0,0,0,0
0,0,0,0,0,0,18,19,0,0,0,0,0,0,0,0,0,0
0,0,0,0,0,0,0,0,0,0,0,0,0,0,0,0,0,0
0,0,0,0,0,0,0,0,0,0,0,0,0,0,9,9,0,0
0,0,0,0,0,0,0,0,0,0,0,0,0,0,9,9,0,0
0,0,0,0,0,0,0,0,0,0,0,0,0,19,0,9,0,0
0,0,0,0,0,0,0,0,0,0,0,0,0,19,0,0,0,0
0,0,0,0,0,0,0,0,0,0,0,0,0,0,0,0,0,0
:endlayer
layer: 13
0,0,0,0,0,0,0,0,0,0,0,0,0,0,0,0,0,0
0,0,0,0,0,0,0,0,0,0,0,0,0,0,0,0,0,0
0,0,0,0,0,0,0,0,0,0,0,0,0,0,0,0,0,0
0,0,0,0,0,0,0,0,0,0,0,0,0,0,0,0,0,0
0,0,0,0,0,0,0,0,0,0,0,0,0,0,0,0,0,0
0,0,0,0,0,0,0,0,0,0,0,0,0,0,0,0,0,0
0,0,0,0,0,0,0,24,24,24,24,24,24,24,0,0,0,0
0,0,0,0,0,0,0,24,24,24,24,24,24,24,0,0,0,0
0,0,0,0,0,0,0,24,24,24,24,24,24,24,0,0,0,0
0,0,0,0,0,0,7,24,24,24,24,24,24,24,0,0,0,0
0,0,0,0,0,12,8,8,24,24,24,24,24,24,0,0,0,0
0,0,0,0,0,12,8,8,15,24,24,24,24,24,0,0,0,0
0,0,0,0,0,0,12,24,24,24,24,24,24,24,0,0,0,0
0,0,0,0,0,0,0,24,24,24,24,24,24,24,0,0,0,0
0,0,0,0,0,0,0,24,24,24,24,24,24,24,9,9,0,0
0,0,0,0,0,0,0,24,24,24,24,24,24,24,9,9,0,0
0,0,0,0,0,0,0,0,0,0,0,0,0,19,0,9,0,0
0,0,0,0,0,0,0,0,0,0,0,0,0,19,0,0,0,0
0,0,0,0,0,0,0,0,0,0,0,0,0,0,0,0,0,0
:endlayer
layer: 14
0,0,0,0,0,0,0,0,0,0,0,0,0,0,0,0,0,0
0,0,0,0,0,0,0,0,0,0,0,0,0,0,0,0,0,0
0,0,0,0,0,0,0,0,0,0,0,0,0,0,0,0,0,0
0,0,0,0,0,0,0,0,0,0,0,0,0,0,0,0,0,0
0,0,0,0,0,0,0,0,0,0,0,0,0,0,0,0,0,0
0,0,0,0,0,0,8,8,8,8,8,8,8,8,8,0,0,0
0,0,0,0,0,0,8,32,33,33,33,33,33,32,8,0,0,0
0,0,0,0,0,0,8,33,0,0,0,0,0,33,8,0,0,0
0,0,0,0,0,0,8,34,0,35,21,36,0,33,8,0,0,0
0,0,0,0,0,0,8,33,0,0,0,0,0,33,8,0,0,0
0,0,0,0,0,12,8,8,9,0,0,0,37,33,8,0,0,0
0,0,0,0,0,12,8,8,15,0,0,28,38,33,8,0,0,0
0,0,0,0,0,0,8,33,0,0,0,0,0,33,8,0,0,0
0,0,0,0,0,0,8,39,0,35,21,36,0,33,8,0,0,0
0,0,0,0,0,0,8,33,0,0,0,0,0,33,8,9,0,0
0,0,0,0,0,0,8,32,33,33,33,33,33,32,8,9,0,0
0,0,0,0,0,0,8,8,8,8,8,8,8,8,8,9,0,0
0,0,0,0,0,0,0,0,0,0,0,0,0,19,0,0,0,0
0,0,0,0,0,0,0,0,0,0,0,0,0,0,0,0,0,0
:endlayer
layer: 15
0,0,0,0,0,0,0,0,0,0,0,0,0,0,0,0,0,0
0,0,0,0,0,0,0,0,0,0,0,0,0,0,0,0,0,0
0,0,0,0,0,0,0,0,0,0,0,0,0,0,0,0,0,0
0,0,0,0,0,0,0,0,0,0,0,0,0,0,0,0,0,0
0,0,0,0,0,0,0,0,0,0,0,0,0,0,0,0,0,0
0,0,0,0,0,0,21,8,21,8,21,8,21,8,21,0,0,0
0,0,0,0,0,0,8,32,0,0,0,0,0,32,8,0,0,0
0,0,0,0,0,0,21,0,0,0,0,0,0,0,21,0,0,0
0,0,0,0,0,0,8,0,0,0,40,0,0,0,8,0,0,0
0,0,0,0,0,0,21,0,0,0,0,0,0,41,21,0,0,0
0,0,0,0,0,12,8,8,9,0,0,0,0,0,21,0,0,0
0,0,0,0,0,12,8,8,15,0,0,0,0,0,21,0,0,0
0,0,0,0,0,0,21,19,0,0,0,0,0,42,21,0,0,0
0,0,0,0,0,0,8,0,0,0,40,0,0,0,8,0,0,0
0,0,0,0,0,0,21,0,0,0,0,0,0,0,21,9,0,0
0,0,0,0,0,0,8,32,0,0,0,0,0,32,8,9,0,0
0,0,0,0,0,0,21,8,21,8,21,8,21,8,21,9,0,0
0,0,0,0,0,0,0,0,0,0,0,0,0,19,0,0,0,0
0,0,0,0,0,0,0,0,0,0,0,0,0,0,0,0,0,0
:endlayer
layer: 16
0,0,0,0,0,0,0,0,0,0,0,0,0,0,0,0,0,0
0,0,0,0,0,0,0,0,0,0,0,0,0,0,0,0,0,0
0,0,0,0,0,0,0,0,0,0,0,0,0,0,0,0,0,0
0,0,0,0,0,0,0,0,0,0,0,0,0,0,0,0,0,0
0,0,0,0,0,0,0,0,0,0,0,0,0,0,0,0,0,0
0,0,0,0,0,0,31,8,0,8,0,8,0,8,31,0,0,0
0,0,0,0,0,0,8,32,0,0,0,0,0,32,8,0,0,0
0,0,0,0,0,0,0,0,0,0,0,0,0,0,0,0,0,0
0,0,0,0,0,0,8,0,0,0,0,0,0,0,8,0,0,0
0,0,0,0,0,0,31,0,0,0,0,0,0,0,21,0,0,0
0,0,0,0,0,12,8,8,9,0,0,0,0,0,0,0,0,0
0,0,0,0,0,12,8,8,15,0,0,0,0,0,0,0,0,0
0,0,0,0,0,43,31,19,0,0,0,0,0,0,21,0,0,0
0,0,0,43,43,8,8,0,0,0,0,0,0,0,8,0,0,0
0,0,43,43,43,0,0,0,0,0,0,0,0,0,0,9,0,0
0,0,0,0,43,43,8,32,0,0,0,0,0,32,8,9,0,0
0,0,43,43,43,43,31,8,0,8,0,8,0,8,31,9,0,0
0,0,0,43,43,0,0,0,0,0,0,0,0,19,0,0,0,0
0,0,0,0,0,0,0,0,0,0,0,0,0,0,0,0,0,0
:endlayer
layer: 17
0,0,0,0,0,0,0,0,0,0,0,0,0,0,0,0,0,0
0,0,0,0,0,0,0,0,0,0,0,0,0,0,0,0,0,0
0,0,0,0,0,0,0,0,0,0,0,0,0,0,0,0,0,0
0,0,0,0,0,0,0,0,0,0,0,0,0,0,0,0,0,0
0,0,0,0,0,0,0,0,0,0,0,0,0,0,0,0,0,0
0,0,0,0,0,0,8,8,8,8,8,8,8,8,8,0,0,0
0,0,0,0,0,0,8,32,32,32,32,32,32,32,8,0,0,0
0,0,0,0,0,0,8,32,0,0,0,0,0,0,8,0,0,0
0,0,0,0,0,0,8,32,0,0,0,0,0,0,8,0,0,0
0,0,0,0,0,0,8,32,0,0,0,0,0,0,21,0,0,0
0,0,0,0,0,12,8,8,9,0,0,0,0,0,0,0,0,0
0,0,0,0,0,12,8,8,15,0,0,0,0,0,0,0,0,0
0,0,0,43,0,43,8,32,0,0,0,0,0,0,21,0,0,0
0,0,0,43,43,43,8,32,0,0,0,0,0,0,8,0,0,0
0,0,0,43,43,43,8,32,0,0,0,0,0,0,8,9,0,0
0,0,0,43,8,43,8,32,32,32,32,32,32,32,8,9,0,0
0,0,0,43,43,43,8,8,8,8,8,8,8,8,8,9,0,0
0,0,0,0,0,0,0,0,0,0,0,0,0,19,0,0,0,0
0,0,0,0,0,0,0,0,0,0,0,0,0,0,0,0,0,0
:endlayer
layer: 18
0,0,0,0,0,0,0,0,0,0,0,0,0,0,0,0,0,0
0,0,0,0,0,0,0,0,0,0,0,0,0,0,0,0,0,0
0,0,0,0,0,0,0,0,0,0,0,0,0,0,0,0,0,0
0,0,0,0,0,0,0,0,0,0,0,0,0,0,0,0,0,0
0,0,0,0,0,0,0,0,0,0,0,0,0,0,0,0,0,0
0,0,0,0,0,0,24,24,24,24,24,24,24,24,24,0,0,0
0,0,0,0,0,0,24,24,24,24,24,24,24,24,24,0,0,0
0,0,0,0,0,0,24,24,33,44,44,44,33,24,24,0,0,0
0,0,0,0,0,0,24,24,33,33,33,33,33,24,8,0,0,0
0,0,0,0,0,0,24,24,33,33,33,33,33,24,8,0,0,0
0,0,0,0,0,12,8,8,33,33,33,33,33,24,24,0,0,0
0,0,0,0,0,12,8,8,15,33,33,45,33,24,8,0,0,0
0,0,0,0,0,0,24,24,33,33,33,33,33,24,8,0,0,0
0,0,0,0,43,43,24,24,33,33,33,33,33,24,8,0,0,0
0,0,0,0,43,43,24,24,33,44,44,44,33,24,24,9,0,0
0,0,0,0,0,43,24,24,24,24,24,24,24,24,24,9,0,0
0,0,0,0,0,0,24,24,24,24,24,24,24,24,24,9,0,0
0,0,0,0,0,0,0,0,0,0,0,0,0,19,0,0,0,0
0,0,0,0,0,0,0,0,0,0,0,0,0,0,0,0,0,0
:endlayer
layer: 19
0,0,0,0,0,0,0,0,0,0,0,0,0,0,0,0,0,0
0,0,0,0,0,0,0,0,0,0,0,0,0,0,0,0,0,0
0,0,0,0,0,0,0,0,0,0,0,0,0,0,0,0,0,0
0,0,0,0,0,0,0,0,0,0,0,0,0,0,0,0,0,0
0,0,0,0,0,0,0,0,0,0,0,0,0,0,0,0,0,0
0,0,0,0,0,0,0,0,0,0,0,0,0,0,0,0,0,0
0,0,0,0,0,0,0,24,24,0,24,0,24,24,0,0,0,0
0,0,0,0,0,0,0,24,0,0,0,0,0,24,0,0,0,0
0,0,0,0,0,0,0,24,0,0,0,0,0,0,0,0,0,0
0,0,0,0,0,0,0,24,0,0,0,0,0,24,0,0,0,0
0,0,0,0,0,8,8,8,21,0,0,0,0,24,0,0,0,0
0,0,0,0,0,12,8,8,15,0,0,28,0,0,0,0,0,0
0,0,0,0,0,0,0,24,0,0,0,0,0,24,0,0,0,0
0,0,0,0,0,0,0,0,0,0,0,0,0,0,0,0,0,0
0,0,0,0,0,0,0,24,0,0,0,0,0,24,0,0,0,0
0,0,0,0,0,0,0,24,24,0,24,0,24,24,0,0,0,0
0,0,0,0,0,0,0,0,0,0,0,0,0,0,0,0,0,0
0,0,0,0,0,0,0,0,0,0,0,0,0,0,0,0,0,0
0,0,0,0,0,0,0,0,0,0,0,0,0,0,0,0,0,0
:endlayer
layer: 20
0,0,0,0,0,0,0,0,0,0,0,0,0,0,0,0,0,0
0,0,0,0,0,0,0,0,0,0,0,0,0,0,0,0,0,0
0,0,0,0,0,0,0,0,0,0,0,0,0,0,0,0,0,0
0,0,0,0,0,0,0,0,0,0,0,0,0,0,0,0,0,0
0,0,0,0,0,0,0,0,0,0,0,0,0,0,0,0,0,0
0,0,0,0,0,0,0,0,0,0,0,0,0,0,0,0,0,0
0,0,0,0,43,0,0,24,24,24,24,24,24,24,0,0,0,0
0,0,43,0,43,43,43,24,0,0,0,0,0,24,0,0,0,0
0,43,43,43,43,43,43,24,0,0,0,0,0,24,0,0,0,0
43,43,43,43,43,43,43,24,0,0,0,0,0,24,0,0,0,0
0,43,43,8,8,43,8,8,31,0,0,0,0,24,0,0,0,0
0,43,43,43,43,12,8,8,15,0,0,0,0,0,0,0,0,0
0,0,43,0,0,0,43,24,46,0,0,0,0,24,0,0,0,0
0,0,0,0,0,0,0,24,0,0,0,0,0,24,0,0,0,0
0,0,0,0,0,0,0,24,0,0,0,0,0,24,0,0,0,0
0,0,0,0,0,0,0,24,24,24,24,24,24,24,0,0,0,0
0,0,0,0,0,0,0,0,0,0,0,0,0,0,0,0,0,0
0,0,0,0,0,0,0,0,0,0,0,0,0,0,0,0,0,0
0,0,0,0,0,0,0,0,0,0,0,0,0,0,0,0,0,0
:endlayer
layer: 21
0,0,0,0,0,0,0,0,0,0,0,0,0,0,0,0,0,0
0,0,0,0,0,0,0,0,0,0,0,0,0,0,0,0,0,0
0,0,0,0,0,0,0,0,0,0,0,0,0,0,0,0,0,0
0,0,0,0,0,0,0,0,0,0,0,0,0,0,0,0,0,0
0,0,0,0,0,0,0,0,0,0,0,0,0,0,0,0,0,0
0,0,0,0,0,0,0,0,0,0,0,0,0,0,0,0,0,0
0,0,0,0,0,0,0,0,0,0,0,0,0,0,0,0,0,0
0,0,43,43,43,0,0,0,8,8,8,8,8,0,0,0,0,0
0,0,43,43,43,0,0,0,8,0,0,0,8,0,0,0,0,0
0,43,0,43,43,43,43,7,8,0,0,0,8,24,0,0,0,0
0,0,43,8,43,43,8,8,8,0,0,0,8,24,0,0,0,0
0,0,43,43,0,43,8,8,15,0,0,0,8,24,0,0,0,0
0,0,0,0,0,0,19,19,8,0,0,0,8,24,0,0,0,0
0,0,0,0,0,0,0,0,8,0,0,0,8,0,0,0,0,0
0,0,0,0,0,0,0,0,8,8,8,8,8,0,0,0,0,0
0,0,0,0,0,0,0,0,0,0,0,0,0,0,0,0,0,0
0,0,0,0,0,0,0,0,0,0,0,0,0,0,0,0,0,0
0,0,0,0,0,0,0,0,0,0,0,0,0,0,0,0,0,0
0,0,0,0,0,0,0,0,0,0,0,0,0,0,0,0,0,0
:endlayer
layer: 22
0,0,0,0,0,0,0,0,0,0,0,0,0,0,0,0,0,0
0,0,0,0,0,0,0,0,0,0,0,0,0,0,0,0,0,0
0,0,0,0,0,0,0,0,0,0,0,0,0,0,0,0,0,0
0,0,0,0,0,0,0,0,0,0,0,0,0,0,0,0,0,0
0,0,0,0,0,0,0,0,0,0,0,0,0,0,0,0,0,0
0,0,0,0,0,0,0,0,0,0,0,0,0,0,0,0,0,0
0,0,0,0,0,0,0,0,0,0,0,0,0,0,0,0,0,0
0,0,0,0,0,0,0,0,0,0,0,0,0,0,0,0,0,0
0,0,0,43,43,0,0,0,0,8,8,8,0,0,0,0,0,0
0,0,43,43,43,43,7,7,0,8,8,8,0,0,0,0,0,0
0,0,0,0,43,12,8,8,9,8,8,8,0,0,0,0,0,0
0,0,0,0,43,12,8,8,15,8,8,8,0,0,0,0,0,0
0,0,0,0,0,0,19,19,0,8,8,8,0,0,0,0,0,0
0,0,0,0,0,0,0,0,0,8,8,8,0,0,0,0,0,0
0,0,0,0,0,0,0,0,0,0,0,0,0,0,0,0,0,0
0,0,0,0,0,0,0,0,0,0,0,0,0,0,0,0,0,0
0,0,0,0,0,0,0,0,0,0,0,0,0,0,0,0,0,0
0,0,0,0,0,0,0,0,0,0,0,0,0,0,0,0,0,0
0,0,0,0,0,0,0,0,0,0,0,0,0,0,0,0,0,0
:endlayer
layer: 23
0,0,0,0,0,0,0,0,0,0,0,0,0,0,0,0,0,0
0,0,0,0,0,0,0,0,0,0,0,0,0,0,0,0,0,0
0,0,0,0,0,0,0,0,0,0,0,0,0,0,0,0,0,0
0,0,0,0,0,0,0,0,0,0,0,0,0,0,0,0,0,0
0,0,0,0,0,0,0,0,0,0,0,0,0,0,0,0,0,0
0,0,0,0,0,0,0,0,0,0,0,0,0,0,0,0,0,0
0,0,0,0,0,0,0,0,0,0,0,0,0,0,0,0,0,0
0,0,0,0,0,0,0,0,0,0,0,0,0,0,0,0,0,0
0,0,0,0,0,0,0,0,0,0,0,0,0,0,0,0,0,0
0,0,0,0,0,0,7,7,0,0,0,0,0,0,0,0,0,0
0,0,0,0,0,12,8,8,9,0,0,0,0,0,0,0,0,0
0,0,0,0,0,12,8,8,9,0,0,0,0,0,0,0,0,0
0,0,0,0,0,0,8,19,0,0,0,0,0,0,0,0,0,0
0,0,0,0,0,0,0,0,0,0,0,0,0,0,0,0,0,0
0,0,0,0,0,0,0,0,0,0,0,0,0,0,0,0,0,0
0,0,0,0,0,0,0,0,0,0,0,0,0,0,0,0,0,0
0,0,0,0,0,0,0,0,0,0,0,0,0,0,0,0,0,0
0,0,0,0,0,0,0,0,0,0,0,0,0,0,0,0,0,0
0,0,0,0,0,0,0,0,0,0,0,0,0,0,0,0,0,0
:endlayer
layer: 24
0,0,0,0,0,0,0,0,0,0,0,0,0,0,0,0,0,0
0,0,0,0,0,0,0,0,0,0,0,0,0,0,0,0,0,0
0,0,0,0,0,0,0,0,0,0,0,0,0,0,0,0,0,0
0,0,0,0,0,0,0,0,0,0,0,0,0,0,0,0,0,0
0,0,0,0,0,0,0,0,0,0,0,0,0,0,0,0,0,0
0,0,0,0,0,0,0,0,0,0,0,0,0,0,0,0,0,0
0,0,0,0,0,0,0,0,0,0,0,0,0,0,0,0,0,0
0,0,0,0,0,0,0,0,0,0,0,0,0,0,0,0,0,0
0,0,0,0,0,0,0,0,0,0,0,0,0,0,0,0,0,0
0,0,0,0,0,0,7,7,0,0,0,0,0,0,0,0,0,0
0,0,0,0,0,12,8,8,9,0,0,0,0,0,0,0,0,0
0,0,0,0,0,12,8,8,43,0,0,0,0,0,0,0,0,0
0,0,0,0,0,0,43,43,43,43,43,0,0,0,0,0,0,0
0,0,0,0,0,43,43,8,43,43,43,0,0,0,0,0,0,0
0,0,0,0,43,43,43,8,43,43,43,0,0,0,0,0,0,0
0,0,0,0,0,43,43,43,43,43,43,0,0,0,0,0,0,0
0,0,0,0,0,43,0,43,43,43,0,0,0,0,0,0,0,0
0,0,0,0,0,0,0,43,0,0,0,0,0,0,0,0,0,0
0,0,0,0,0,0,0,0,0,0,0,0,0,0,0,0,0,0
:endlayer
layer: 25
0,0,0,0,0,0,0,0,0,0,0,0,0,0,0,0,0,0
0,0,0,0,0,0,0,0,0,0,0,0,0,0,0,0,0,0
0,0,0,0,0,0,0,0,0,0,0,0,0,0,0,0,0,0
0,0,0,0,0,0,0,0,0,0,0,0,0,0,0,0,0,0
0,0,0,0,0,0,0,0,0,0,0,0,0,0,0,0,0,0
0,0,0,0,0,0,0,0,0,0,0,0,0,0,0,0,0,0
0,0,0,0,0,0,0,0,0,0,0,0,0,0,0,0,0,0
0,0,0,0,0,0,0,0,0,0,0,0,0,0,0,0,0,0
0,0,0,0,0,0,0,0,0,0,0,0,0,0,0,0,0,0
0,0,0,0,0,0,7,7,0,0,0,0,0,0,0,0,0,0
0,0,0,0,0,12,8,8,9,0,0,0,0,0,0,0,0,0
0,0,0,0,0,12,8,8,9,0,0,0,0,0,0,0,0,0
0,0,0,0,0,0,19,43,43,0,0,0,0,0,0,0,0,0
0,0,0,0,0,0,43,0,43,43,0,0,0,0,0,0,0,0
0,0,0,0,0,43,43,43,43,43,43,0,0,0,0,0,0,0
0,0,0,0,0,0,43,8,43,43,43,0,0,0,0,0,0,0
0,0,0,0,0,0,0,0,43,43,0,0,0,0,0,0,0,0
0,0,0,0,0,0,0,0,43,0,0,0,0,0,0,0,0,0
0,0,0,0,0,0,0,0,0,0,0,0,0,0,0,0,0,0
:endlayer
layer: 26
0,0,0,0,0,0,0,0,0,0,0,0,0,0,0,0,0,0
0,0,0,0,0,0,0,0,0,0,0,0,0,0,0,0,0,0
0,0,0,0,0,0,0,0,0,0,0,0,0,0,0,0,0,0
0,0,0,0,0,0,0,0,0,0,0,0,0,0,0,0,0,0
0,0,0,0,0,0,0,0,0,0,0,0,0,0,0,0,0,0
0,0,0,0,0,0,0,0,0,0,0,0,0,0,0,0,0,0
0,0,0,0,0,0,0,0,0,0,0,0,0,0,0,0,0,0
0,0,0,0,0,0,0,0,0,0,0,0,0,0,0,0,0,0
0,0,0,0,0,0,0,0,0,0,0,0,0,0,0,0,0,0
0,0,0,0,0,0,7,7,0,0,0,0,0,0,0,0,0,0
0,0,0,0,0,12,8,8,9,0,0,0,0,0,0,0,0,0
0,0,0,0,0,12,8,8,9,0,0,0,0,0,0,0,0,0
0,0,0,0,0,0,19,0,0,0,0,0,0,0,0,0,0,0
0,0,0,0,0,0,0,43,43,0,0,0,0,0,0,0,0,0
0,0,0,0,0,0,0,43,43,43,0,0,0,0,0,0,0,0
0,0,0,0,0,0,0,43,0,43,0,0,0,0,0,0,0,0
0,0,0,0,0,0,0,0,43,0,0,0,0,0,0,0,0,0
0,0,0,0,0,0,0,0,0,0,0,0,0,0,0,0,0,0
0,0,0,0,0,0,0,0,0,0,0,0,0,0,0,0,0,0
:endlayer
layer: 27
0,0,0,0,0,0,0,0,0,0,0,0,0,0,0,0,0,0
0,0,0,0,0,0,0,0,0,0,0,0,0,0,0,0,0,0
0,0,0,0,0,0,0,0,0,0,0,0,0,0,0,0,0,0
0,0,0,0,0,0,0,0,0,0,0,0,0,0,0,0,0,0
0,0,0,0,0,0,0,0,0,0,0,0,0,0,0,0,0,0
0,0,0,0,0,43,43,0,0,0,0,0,0,0,0,0,0,0
0,0,0,43,0,43,43,43,43,0,43,0,0,0,0,0,0,0
0,0,43,0,43,43,43,43,43,43,0,43,0,0,0,0,0,0
0,0,43,43,43,43,43,43,43,43,43,0,0,0,0,0,0,0
0,0,43,43,43,43,43,43,43,43,43,43,0,0,0,0,0,0
0,0,43,43,43,43,8,8,43,43,43,43,43,0,0,0,0,0
0,0,43,43,43,43,8,8,43,43,43,0,43,0,0,0,0,0
0,0,0,43,43,43,43,43,43,43,43,43,43,0,0,0,0,0
0,0,43,43,43,43,43,43,43,43,43,43,0,0,0,0,0,0
0,0,0,43,43,43,43,43,0,43,43,43,0,0,0,0,0,0
0,0,0,0,43,0,43,0,0,0,43,0,0,0,0,0,0,0
0,0,0,0,0,0,0,0,0,0,0,0,0,0,0,0,0,0
0,0,0,0,0,0,0,0,0,0,0,0,0,0,0,0,0,0
0,0,0,0,0,0,0,0,0,0,0,0,0,0,0,0,0,0
:endlayer
layer: 28
0,0,0,0,0,0,0,0,0,0,0,0,0,0,0,0,0,0
0,0,0,0,0,0,0,0,0,0,0,0,0,0,0,0,0,0
0,0,0,0,0,0,0,0,0,0,0,0,0,0,0,0,0,0
0,0,0,0,0,0,0,0,0,0,0,0,0,0,0,0,0,0
0,0,0,0,0,0,0,0,0,0,0,0,0,0,0,0,0,0
0,0,0,0,0,0,0,0,0,0,0,0,0,0,0,0,0,0
0,0,0,0,43,43,43,43,0,0,0,0,0,0,0,0,0,0
0,0,0,43,0,43,0,43,43,43,0,0,0,0,0,0,0,0
0,0,0,43,43,43,43,43,43,43,43,0,0,0,0,0,0,0
0,0,0,43,43,43,43,43,43,43,0,0,0,0,0,0,0,0
0,0,43,43,43,43,43,8,43,43,43,43,0,0,0,0,0,0
0,0,0,0,43,43,43,43,43,43,43,0,0,0,0,0,0,0
0,0,0,43,43,43,43,43,43,43,43,0,0,0,0,0,0,0
0,0,0,43,43,0,43,43,43,0,43,43,0,0,0,0,0,0
0,0,0,0,43,43,43,0,43,43,43,0,0,0,0,0,0,0
0,0,0,0,0,0,0,43,0,0,0,0,0,0,0,0,0,0
0,0,0,0,0,0,0,0,0,0,0,0,0,0,0,0,0,0
0,0,0,0,0,0,0,0,0,0,0,0,0,0,0,0,0,0
0,0,0,0,0,0,0,0,0,0,0,0,0,0,0,0,0,0
:endlayer
layer: 29
0,0,0,0,0,0,0,0,0,0,0,0,0,0,0,0,0,0
0,0,0,0,0,0,0,0,0,0,0,0,0,0,0,0,0,0
0,0,0,0,0,0,0,0,0,0,0,0,0,0,0,0,0,0
0,0,0,0,0,0,0,0,0,0,0,0,0,0,0,0,0,0
0,0,0,0,0,0,0,0,0,0,0,0,0,0,0,0,0,0
0,0,0,0,0,0,0,0,0,0,0,0,0,0,0,0,0,0
0,0,0,0,0,0,0,0,0,0,0,0,0,0,0,0,0,0
0,0,0,0,0,0,43,43,0,0,0,0,0,0,0,0,0,0
0,0,0,0,43,43,43,43,43,0,0,0,0,0,0,0,0,0
0,0,0,0,43,0,43,43,43,43,0,0,0,0,0,0,0,0
0,0,0,0,43,43,43,43,43,43,43,0,0,0,0,0,0,0
0,0,0,0,43,43,43,43,43,43,43,0,0,0,0,0,0,0
0,0,0,0,43,43,43,43,43,43,0,0,0,0,0,0,0,0
0,0,0,0,0,43,43,43,43,43,0,0,0,0,0,0,0,0
0,0,0,0,0,0,0,0,0,0,0,0,0,0,0,0,0,0
0,0,0,0,0,0,0,0,0,0,0,0,0,0,0,0,0,0
0,0,0,0,0,0,0,0,0,0,0,0,0,0,0,0,0,0
0,0,0,0,0,0,0,0,0,0,0,0,0,0,0,0,0,0
0,0,0,0,0,0,0,0,0,0,0,0,0,0,0,0,0,0
:endlayer

#### RULES ####
rule:
plugin=vanillaBlocks
number=1
data:
JSON:{blockState:{blockName:"minecraft:dirt",properties:{variant:"dirt",snowy:"false"}}}
:enddata
:endrule

rule:
plugin=vanillaBlocks
number=2
data:
JSON:{blockState:{blockName:"minecraft:grass",properties:{snowy:"false"}}}
:enddata
:endrule

rule:
plugin=vanillaBlocks
number=3
data:
JSON:{blockState:{blockName:"minecraft:tallgrass",properties:{type:"tall_grass"}}}
:enddata
:endrule

rule:
plugin=vanillaBlocks
number=4
data:
JSON:{blockState:{blockName:"minecraft:yellow_flower",properties:{type:"dandelion"}}}
:enddata
:endrule

rule:
plugin=blockTile
number=5
data:
JSON:{blockState:{blockName:"ancientwarfarestructure:advanced_spawner",properties:{transparent:"true"}},teData:{id:"ancientwarfarestructure:advanced_spawner_tile",spawnerSettings:{minDelay:0,spawnDelay:0,lightSensitive:0b,spawnGroups:[{settingsList:[{remainingSpawnCount:1,hostile:1b,forced:1b,customTag:{factionName:"kong"},maxToSpawn:1,entityId:"ancientwarfarenpc:faction.soldier",minToSpawn:1}],groupWeight:1}],playerRange:16,respondToRedstone:0b,inventory:{Size:9,Items:[]},spawnRange:0,transparent:1b,maxDelay:0,xpToDrop:0,mobRange:0,debugMode:0b,maxNearbyMonsters:0}}}
:enddata
:endrule

rule:
plugin=blockTile
number=6
data:
JSON:{blockState:{blockName:"ancientwarfarestructure:advanced_spawner",properties:{transparent:"true"}},teData:{id:"ancientwarfarestructure:advanced_spawner_tile",spawnerSettings:{minDelay:0,spawnDelay:0,lightSensitive:0b,spawnGroups:[{settingsList:[{remainingSpawnCount:1,hostile:1b,forced:1b,customTag:{factionName:"kong"},maxToSpawn:1,entityId:"ancientwarfarenpc:faction.soldier",minToSpawn:1}],groupWeight:1}],playerRange:16,respondToRedstone:0b,inventory:{Size:9,Items:[]},spawnRange:0,transparent:1b,maxDelay:0,xpToDrop:0,mobRange:0,debugMode:0b,maxNearbyMonsters:0}}}
:enddata
:endrule

rule:
plugin=vine
number=7
data:
JSON:{blockState:{blockName:"minecraft:vine",properties:{east:"false",south:"true",north:"false",west:"false",up:"false"}}}
:enddata
:endrule

rule:
plugin=vanillaBlocks
number=8
data:
JSON:{blockState:{blockName:"minecraft:log",properties:{variant:"jungle",axis:"y"}}}
:enddata
:endrule

rule:
plugin=vine
number=9
data:
JSON:{blockState:{blockName:"minecraft:vine",properties:{east:"false",south:"false",north:"false",west:"true",up:"false"}}}
:enddata
:endrule

rule:
plugin=vine
number=10
data:
JSON:{blockState:{blockName:"minecraft:vine",properties:{east:"false",south:"false",north:"true",west:"true",up:"false"}}}
:enddata
:endrule

rule:
plugin=blockTile
number=11
data:
JSON:{blockState:{blockName:"ancientwarfarestructure:advanced_spawner",properties:{transparent:"true"}},teData:{id:"ancientwarfarestructure:advanced_spawner_tile",spawnerSettings:{minDelay:0,spawnDelay:0,lightSensitive:0b,spawnGroups:[{settingsList:[{remainingSpawnCount:1,hostile:1b,forced:1b,customTag:{factionName:"kong"},maxToSpawn:1,entityId:"ancientwarfarenpc:faction.archer.elite",minToSpawn:1}],groupWeight:1}],playerRange:32,respondToRedstone:0b,inventory:{Size:9,Items:[]},spawnRange:0,transparent:1b,maxDelay:0,xpToDrop:0,mobRange:0,debugMode:0b,maxNearbyMonsters:0}}}
:enddata
:endrule

rule:
plugin=vine
number=12
data:
JSON:{blockState:{blockName:"minecraft:vine",properties:{east:"true",south:"false",north:"false",west:"false",up:"false"}}}
:enddata
:endrule

rule:
plugin=blockTile
number=13
data:
JSON:{blockState:{blockName:"ancientwarfarestructure:advanced_spawner",properties:{transparent:"true"}},teData:{id:"ancientwarfarestructure:advanced_spawner_tile",spawnerSettings:{minDelay:0,spawnDelay:0,lightSensitive:0b,spawnGroups:[{settingsList:[{remainingSpawnCount:1,hostile:1b,forced:1b,customTag:{factionName:"kong"},maxToSpawn:1,entityId:"ancientwarfarenpc:faction.archer.elite",minToSpawn:1}],groupWeight:1}],playerRange:32,respondToRedstone:0b,inventory:{Size:9,Items:[]},spawnRange:0,transparent:1b,maxDelay:0,xpToDrop:0,mobRange:0,debugMode:0b,maxNearbyMonsters:0}}}
:enddata
:endrule

rule:
plugin=vanillaBlocks
number=14
data:
JSON:{blockState:{blockName:"minecraft:red_flower",properties:{type:"red_tulip"}}}
:enddata
:endrule

rule:
plugin=vanillaBlocks
number=15
data:
JSON:{blockState:{blockName:"minecraft:ladder",properties:{facing:"east"}}}
:enddata
:endrule

rule:
plugin=vanillaBlocks
number=16
data:
JSON:{blockState:{blockName:"minecraft:red_flower",properties:{type:"houstonia"}}}
:enddata
:endrule

rule:
plugin=vanillaBlocks
number=17
data:
JSON:{blockState:{blockName:"minecraft:red_flower",properties:{type:"oxeye_daisy"}}}
:enddata
:endrule

rule:
plugin=vine
number=18
data:
JSON:{blockState:{blockName:"minecraft:vine",properties:{east:"true",south:"false",north:"true",west:"false",up:"false"}}}
:enddata
:endrule

rule:
plugin=vine
number=19
data:
JSON:{blockState:{blockName:"minecraft:vine",properties:{east:"false",south:"false",north:"true",west:"false",up:"false"}}}
:enddata
:endrule

rule:
plugin=vanillaBlocks
number=20
data:
JSON:{blockState:{blockName:"minecraft:red_flower",properties:{type:"poppy"}}}
:enddata
:endrule

rule:
plugin=vanillaBlocks
number=21
data:
JSON:{blockState:{blockName:"minecraft:fence",properties:{east:"false",south:"false",north:"false",west:"false"}}}
:enddata
:endrule

rule:
plugin=blockTile
number=22
data:
JSON:{blockState:{blockName:"ancientwarfarestructure:advanced_spawner",properties:{transparent:"true"}},teData:{id:"ancientwarfarestructure:advanced_spawner_tile",spawnerSettings:{minDelay:0,spawnDelay:0,lightSensitive:0b,spawnGroups:[{settingsList:[{remainingSpawnCount:1,hostile:1b,forced:1b,customTag:{factionName:"kong"},maxToSpawn:1,entityId:"ancientwarfarenpc:faction.soldier",minToSpawn:1}],groupWeight:1}],playerRange:16,respondToRedstone:0b,inventory:{Size:9,Items:[]},spawnRange:0,transparent:1b,maxDelay:0,xpToDrop:0,mobRange:0,debugMode:0b,maxNearbyMonsters:0}}}
:enddata
:endrule

rule:
plugin=blockTile
number=23
data:
JSON:{blockState:{blockName:"ancientwarfarestructure:advanced_spawner",properties:{transparent:"true"}},teData:{id:"ancientwarfarestructure:advanced_spawner_tile",spawnerSettings:{minDelay:0,spawnDelay:0,lightSensitive:0b,spawnGroups:[{settingsList:[{remainingSpawnCount:1,hostile:1b,forced:1b,customTag:{factionName:"kong"},maxToSpawn:1,entityId:"ancientwarfarenpc:faction.soldier",minToSpawn:1}],groupWeight:1}],playerRange:16,respondToRedstone:0b,inventory:{Size:9,Items:[]},spawnRange:0,transparent:1b,maxDelay:0,xpToDrop:0,mobRange:0,debugMode:0b,maxNearbyMonsters:0}}}
:enddata
:endrule

rule:
plugin=vanillaBlocks
number=24
data:
JSON:{blockState:{blockName:"minecraft:planks",properties:{variant:"jungle"}}}
:enddata
:endrule

rule:
plugin=blockTile
number=25
data:
JSON:{blockState:{blockName:"ancientwarfarestructure:advanced_spawner",properties:{transparent:"true"}},teData:{id:"ancientwarfarestructure:advanced_spawner_tile",spawnerSettings:{minDelay:0,spawnDelay:0,lightSensitive:0b,spawnGroups:[{settingsList:[{remainingSpawnCount:1,hostile:1b,forced:1b,customTag:{factionName:"kong"},maxToSpawn:1,entityId:"ancientwarfarenpc:faction.archer.elite",minToSpawn:1}],groupWeight:1}],playerRange:32,respondToRedstone:0b,inventory:{Size:9,Items:[]},spawnRange:0,transparent:1b,maxDelay:0,xpToDrop:0,mobRange:0,debugMode:0b,maxNearbyMonsters:0}}}
:enddata
:endrule

rule:
plugin=blockTile
number=26
data:
JSON:{blockState:{blockName:"ancientwarfarestructure:advanced_spawner",properties:{transparent:"true"}},teData:{id:"ancientwarfarestructure:advanced_spawner_tile",spawnerSettings:{minDelay:0,spawnDelay:0,lightSensitive:0b,spawnGroups:[{settingsList:[{remainingSpawnCount:1,hostile:1b,forced:1b,customTag:{factionName:"kong"},maxToSpawn:1,entityId:"ancientwarfarenpc:faction.leader",minToSpawn:1}],groupWeight:1}],playerRange:6,respondToRedstone:0b,inventory:{Size:9,Items:[]},spawnRange:0,transparent:1b,maxDelay:0,xpToDrop:0,mobRange:0,debugMode:0b,maxNearbyMonsters:0}}}
:enddata
:endrule

rule:
plugin=blockTile
number=27
data:
JSON:{blockState:{blockName:"ancientwarfarestructure:advanced_spawner",properties:{transparent:"true"}},teData:{id:"ancientwarfarestructure:advanced_spawner_tile",spawnerSettings:{minDelay:0,spawnDelay:0,lightSensitive:0b,spawnGroups:[{settingsList:[{remainingSpawnCount:1,hostile:1b,forced:1b,customTag:{factionName:"kong"},maxToSpawn:1,entityId:"ancientwarfarenpc:faction.soldier",minToSpawn:1}],groupWeight:1}],playerRange:6,respondToRedstone:0b,inventory:{Size:9,Items:[]},spawnRange:0,transparent:1b,maxDelay:0,xpToDrop:0,mobRange:0,debugMode:0b,maxNearbyMonsters:0}}}
:enddata
:endrule

rule:
plugin=vanillaBlocks
number=28
data:
JSON:{blockState:{blockName:"ancientwarfarestructure:fire_pit",properties:{lit:"true",variant:"default"}}}
:enddata
:endrule

rule:
plugin=blockTile
number=29
data:
JSON:{blockState:{blockName:"ancientwarfarestructure:advanced_spawner",properties:{transparent:"true"}},teData:{id:"ancientwarfarestructure:advanced_spawner_tile",spawnerSettings:{minDelay:0,spawnDelay:0,lightSensitive:0b,spawnGroups:[{settingsList:[{remainingSpawnCount:1,hostile:1b,forced:1b,customTag:{factionName:"kong"},maxToSpawn:1,entityId:"ancientwarfarenpc:faction.soldier",minToSpawn:1}],groupWeight:1}],playerRange:6,respondToRedstone:0b,inventory:{Size:9,Items:[]},spawnRange:0,transparent:1b,maxDelay:0,xpToDrop:0,mobRange:0,debugMode:0b,maxNearbyMonsters:0}}}
:enddata
:endrule

rule:
plugin=blockTile
number=30
data:
JSON:{blockState:{blockName:"ancientwarfarestructure:advanced_spawner",properties:{transparent:"true"}},teData:{id:"ancientwarfarestructure:advanced_spawner_tile",spawnerSettings:{minDelay:0,spawnDelay:0,lightSensitive:0b,spawnGroups:[{settingsList:[{remainingSpawnCount:1,hostile:1b,forced:1b,customTag:{factionName:"kong"},maxToSpawn:1,entityId:"ancientwarfarenpc:faction.archer.elite",minToSpawn:1}],groupWeight:1}],playerRange:32,respondToRedstone:0b,inventory:{Size:9,Items:[]},spawnRange:0,transparent:1b,maxDelay:0,xpToDrop:0,mobRange:0,debugMode:0b,maxNearbyMonsters:0}}}
:enddata
:endrule

rule:
plugin=vanillaBlocks
number=31
data:
JSON:{blockState:{blockName:"minecraft:torch",properties:{facing:"up"}}}
:enddata
:endrule

rule:
plugin=vanillaBlocks
number=32
data:
JSON:{blockState:{blockName:"minecraft:bookshelf"}}
:enddata
:endrule

rule:
plugin=vanillaBlocks
number=33
data:
JSON:{blockState:{blockName:"minecraft:stone_slab",properties:{half:"bottom",variant:"wood_old"}}}
:enddata
:endrule

rule:
plugin=inventory
number=34
data:
JSON:{blockState:{blockName:"minecraft:chest",properties:{facing:"east"}},lootLevel:0,teData:{ForgeData:{},Items:[{Slot:0b,id:"minecraft:string",Count:2b,Damage:0s},{Slot:1b,id:"minecraft:dye",Count:2b,Damage:3s},{Slot:2b,id:"minecraft:dye",Count:2b,Damage:3s},{Slot:5b,id:"ancientwarfarenpc:coin",Count:4b,tag:{metal:"copper"},Damage:0s},{Slot:6b,id:"ancientwarfarenpc:coin",Count:7b,tag:{metal:"copper"},Damage:0s},{Slot:7b,id:"minecraft:feather",Count:2b,Damage:0s},{Slot:9b,id:"minecraft:string",Count:2b,Damage:0s},{Slot:10b,id:"minecraft:dye",Count:9b,Damage:3s},{Slot:11b,id:"minecraft:dye",Count:2b,Damage:3s},{Slot:14b,id:"minecraft:bone",Count:6b,Damage:0s},{Slot:15b,id:"minecraft:rotten_flesh",Count:2b,Damage:0s},{Slot:16b,id:"minecraft:feather",Count:2b,Damage:0s},{Slot:17b,id:"minecraft:feather",Count:3b,Damage:0s},{Slot:18b,id:"minecraft:string",Count:2b,Damage:0s},{Slot:19b,id:"minecraft:string",Count:1b,Damage:0s},{Slot:23b,id:"minecraft:bone",Count:4b,Damage:0s},{Slot:24b,id:"minecraft:rotten_flesh",Count:8b,Damage:0s},{Slot:25b,id:"minecraft:feather",Count:2b,Damage:0s},{Slot:26b,id:"minecraft:feather",Count:2b,Damage:0s}],id:"minecraft:chest",Lock:""},inventoryData:{length:19,inventoryContents:[{id:"minecraft:string",Count:2b,slot:0,Damage:0s},{id:"minecraft:dye",Count:2b,slot:1,Damage:3s},{id:"minecraft:dye",Count:2b,slot:2,Damage:3s},{id:"ancientwarfarenpc:coin",Count:4b,tag:{metal:"copper"},slot:3,Damage:0s},{id:"ancientwarfarenpc:coin",Count:7b,tag:{metal:"copper"},slot:4,Damage:0s},{id:"minecraft:feather",Count:2b,slot:5,Damage:0s},{id:"minecraft:string",Count:2b,slot:6,Damage:0s},{id:"minecraft:dye",Count:9b,slot:7,Damage:3s},{id:"minecraft:dye",Count:2b,slot:8,Damage:3s},{id:"minecraft:bone",Count:6b,slot:9,Damage:0s},{id:"minecraft:rotten_flesh",Count:2b,slot:10,Damage:0s},{id:"minecraft:feather",Count:2b,slot:11,Damage:0s},{id:"minecraft:feather",Count:3b,slot:12,Damage:0s},{id:"minecraft:string",Count:2b,slot:13,Damage:0s},{id:"minecraft:string",Count:1b,slot:14,Damage:0s},{id:"minecraft:bone",Count:4b,slot:15,Damage:0s},{id:"minecraft:rotten_flesh",Count:8b,slot:16,Damage:0s},{id:"minecraft:feather",Count:2b,slot:17,Damage:0s},{id:"minecraft:feather",Count:2b,slot:18,Damage:0s}]},legacyFeatures:1b}
:enddata
:endrule

rule:
plugin=vanillaBlocks
number=35
data:
JSON:{blockState:{blockName:"minecraft:jungle_stairs",properties:{half:"bottom",shape:"straight",facing:"west"}}}
:enddata
:endrule

rule:
plugin=vanillaBlocks
number=36
data:
JSON:{blockState:{blockName:"minecraft:jungle_stairs",properties:{half:"bottom",shape:"straight",facing:"east"}}}
:enddata
:endrule

rule:
plugin=blockTile
number=37
data:
JSON:{blockState:{blockName:"ancientwarfarestructure:advanced_spawner",properties:{transparent:"true"}},teData:{id:"ancientwarfarestructure:advanced_spawner_tile",spawnerSettings:{minDelay:0,spawnDelay:0,lightSensitive:0b,spawnGroups:[{settingsList:[{remainingSpawnCount:1,hostile:1b,forced:1b,customTag:{factionName:"kong"},maxToSpawn:1,entityId:"ancientwarfarenpc:faction.soldier",minToSpawn:1}],groupWeight:1}],playerRange:6,respondToRedstone:0b,inventory:{Size:9,Items:[]},spawnRange:0,transparent:1b,maxDelay:0,xpToDrop:0,mobRange:0,debugMode:0b,maxNearbyMonsters:0}}}
:enddata
:endrule

rule:
plugin=blockTile
number=38
data:
JSON:{blockState:{blockName:"ancientwarfarestructure:advanced_spawner",properties:{transparent:"true"}},teData:{id:"ancientwarfarestructure:advanced_spawner_tile",spawnerSettings:{minDelay:0,spawnDelay:0,lightSensitive:0b,spawnGroups:[{settingsList:[{remainingSpawnCount:1,hostile:1b,forced:1b,customTag:{factionName:"kong"},maxToSpawn:1,entityId:"ancientwarfarenpc:faction.soldier",minToSpawn:1}],groupWeight:1}],playerRange:6,respondToRedstone:0b,inventory:{Size:9,Items:[]},spawnRange:0,transparent:1b,maxDelay:0,xpToDrop:0,mobRange:0,debugMode:0b,maxNearbyMonsters:0}}}
:enddata
:endrule

rule:
plugin=inventory
number=39
data:
JSON:{blockState:{blockName:"minecraft:chest",properties:{facing:"east"}},lootLevel:0,teData:{ForgeData:{},Items:[{Slot:14b,id:"minecraft:emerald",Count:1b,Damage:0s},{Slot:19b,id:"minecraft:dye",Count:6b,Damage:4s}],id:"minecraft:chest",Lock:""},inventoryData:{length:2,inventoryContents:[{id:"minecraft:emerald",Count:1b,slot:0,Damage:0s},{id:"minecraft:dye",Count:6b,slot:1,Damage:4s}]},legacyFeatures:1b}
:enddata
:endrule

rule:
plugin=vanillaBlocks
number=40
data:
JSON:{blockState:{blockName:"minecraft:wooden_pressure_plate",properties:{powered:"false"}}}
:enddata
:endrule

rule:
plugin=blockTile
number=41
data:
JSON:{blockState:{blockName:"ancientwarfarestructure:advanced_spawner",properties:{transparent:"true"}},teData:{id:"ancientwarfarestructure:advanced_spawner_tile",spawnerSettings:{minDelay:0,spawnDelay:0,lightSensitive:0b,spawnGroups:[{settingsList:[{remainingSpawnCount:1,hostile:1b,forced:1b,customTag:{factionName:"kong"},maxToSpawn:1,entityId:"ancientwarfarenpc:faction.civilian.female",minToSpawn:1}],groupWeight:1}],playerRange:16,respondToRedstone:0b,inventory:{Size:9,Items:[]},spawnRange:0,transparent:1b,maxDelay:0,xpToDrop:0,mobRange:0,debugMode:0b,maxNearbyMonsters:0}}}
:enddata
:endrule

rule:
plugin=blockTile
number=42
data:
JSON:{blockState:{blockName:"ancientwarfarestructure:advanced_spawner",properties:{transparent:"true"}},teData:{id:"ancientwarfarestructure:advanced_spawner_tile",spawnerSettings:{minDelay:0,spawnDelay:0,lightSensitive:0b,spawnGroups:[{settingsList:[{remainingSpawnCount:1,hostile:1b,forced:1b,customTag:{factionName:"kong"},maxToSpawn:1,entityId:"ancientwarfarenpc:faction.civilian.female",minToSpawn:1}],groupWeight:1}],playerRange:16,respondToRedstone:0b,inventory:{Size:9,Items:[]},spawnRange:0,transparent:1b,maxDelay:0,xpToDrop:0,mobRange:0,debugMode:0b,maxNearbyMonsters:0}}}
:enddata
:endrule

rule:
plugin=vanillaBlocks
number=43
data:
JSON:{blockState:{blockName:"minecraft:leaves",properties:{check_decay:"false",decayable:"true",variant:"jungle"}}}
:enddata
:endrule

rule:
plugin=vanillaBlocks
number=44
data:
JSON:{blockState:{blockName:"minecraft:double_stone_slab",properties:{seamless:"false",variant:"wood_old"}}}
:enddata
:endrule

rule:
plugin=vanillaBlocks
number=45
data:
JSON:{blockState:{blockName:"minecraft:cobblestone"}}
:enddata
:endrule

rule:
plugin=vine
number=46
data:
JSON:{blockState:{blockName:"minecraft:vine",properties:{east:"false",south:"false",north:"false",west:"false",up:"false"}}}
:enddata
:endrule

#### ENTITIES ####
