# Ancient Warfare Structure Template File
# Auto-generated structure template file. created on: 11/18/2018 at: 19:35:5
# Lines beginning with # denote comments

header:
version=2.7
name=KongMetalWorker
mods=
size=19,74,23
offset=12,4,22
:endheader

#### VALIDATION ####
validation:
type=ground
survival=false
worldGenEnabled=true
unique=false
preserveBlocks=false
selectionWeight=30
clusterValue=40
minDuplicateDistance=900
dimensionWhiteList=false
dimensionList=
biomeWhiteList=true
biomeList=minecraft:jungle
leveling=3
fill=2
border=3
blockSwap=false
data:
:enddata
:endvalidation

#### LAYERS ####
layer: 0
1,1,1,1,1,1,1,1,1,1,1,1,1,1,1,1,1,1,1
1,1,1,1,1,1,1,1,1,1,1,1,1,1,1,1,1,1,1
1,1,1,1,1,1,1,1,1,1,1,1,1,1,1,1,1,1,1
1,1,1,1,1,1,1,1,1,1,1,1,1,1,1,1,1,1,1
1,1,1,1,1,1,1,1,1,1,1,1,1,1,1,1,1,1,1
1,1,1,1,1,1,1,1,1,1,1,1,1,1,1,1,1,1,1
1,1,1,1,1,1,1,1,1,1,1,1,1,1,1,1,1,1,1
1,1,1,1,1,1,1,1,1,1,1,1,1,1,1,1,1,1,1
1,1,1,1,1,1,1,1,1,1,1,1,1,1,1,1,1,1,1
1,1,1,1,1,1,1,1,1,1,1,1,1,1,1,1,1,1,1
1,1,1,1,1,1,1,1,1,1,1,1,1,1,1,1,1,1,1
1,1,1,1,1,1,1,1,1,1,1,1,1,1,1,1,1,1,1
1,1,1,1,1,1,1,1,1,1,1,1,1,1,1,1,1,1,1
1,1,1,1,1,1,1,1,1,1,1,1,1,1,1,1,1,1,1
1,1,1,1,1,1,1,1,1,1,1,1,1,1,1,1,1,1,1
1,1,1,1,1,1,1,1,1,1,1,1,1,1,1,1,1,1,1
1,1,1,1,1,1,1,1,1,1,1,1,1,1,1,1,1,1,1
1,1,1,1,1,1,1,1,1,1,1,1,1,1,1,1,1,1,1
1,1,1,1,1,1,1,1,1,1,1,1,1,1,1,1,1,1,1
1,1,1,1,1,1,1,1,1,1,1,1,1,1,1,1,1,1,1
1,1,1,1,1,1,1,1,1,1,1,1,1,1,1,1,1,1,1
1,1,1,1,1,1,1,1,1,1,1,1,1,1,1,1,1,1,1
1,1,1,1,1,1,1,1,1,1,1,1,1,1,1,1,1,1,1
:endlayer
layer: 1
1,1,1,1,1,1,1,1,1,1,1,1,1,1,1,1,1,1,1
1,1,1,1,1,1,1,1,1,1,1,1,1,1,1,1,1,1,1
1,1,1,1,1,1,1,1,1,1,1,1,1,1,1,1,1,1,1
1,1,1,1,1,1,1,1,1,1,1,1,1,1,1,1,1,1,1
1,1,1,1,1,1,1,1,1,1,1,1,1,1,1,1,1,1,1
1,1,1,1,1,1,1,1,1,1,1,1,1,1,1,1,1,1,1
1,1,1,1,1,1,1,1,1,1,1,1,1,1,1,1,1,1,1
1,1,1,1,1,1,1,1,1,1,1,1,1,1,1,1,1,1,1
1,1,1,1,1,1,1,1,1,1,1,1,1,1,1,1,1,1,1
1,1,1,1,1,1,1,1,1,1,1,1,1,1,1,1,1,1,1
1,1,1,1,1,1,1,1,1,1,1,1,1,1,1,1,1,1,1
1,1,1,1,1,1,1,1,1,1,1,1,1,1,1,1,1,1,1
1,1,1,1,1,1,1,1,1,1,1,1,1,1,1,1,1,1,1
1,1,1,1,1,1,1,1,1,1,1,1,1,1,1,1,1,1,1
1,1,1,1,1,1,1,1,1,1,1,1,1,1,1,1,1,1,1
1,1,1,1,1,1,1,1,1,1,1,1,1,1,1,1,1,1,1
1,1,1,1,1,1,1,1,1,1,1,1,1,1,1,1,1,1,1
1,1,1,1,1,1,1,1,1,1,1,1,1,1,1,1,1,1,1
1,1,1,1,1,1,1,1,1,1,1,1,1,1,1,1,1,1,1
1,1,1,1,1,1,1,1,1,1,1,1,1,1,1,1,1,1,1
1,1,1,1,1,1,1,1,1,1,1,1,1,1,1,1,1,1,1
1,1,1,1,1,1,1,1,1,1,1,1,1,1,1,1,1,1,1
1,1,1,1,1,1,1,1,1,1,1,1,1,1,1,1,1,1,1
:endlayer
layer: 2
1,1,1,1,1,1,1,1,1,1,1,1,1,1,1,1,1,1,1
1,1,1,1,1,1,1,1,1,1,1,1,1,1,1,1,1,1,1
1,1,1,1,1,1,1,1,1,1,1,1,1,1,1,1,1,1,1
1,1,1,1,1,1,1,1,1,1,1,1,1,1,1,1,1,1,1
1,1,1,1,1,1,1,1,1,1,1,1,1,1,1,1,1,1,1
1,1,1,1,1,1,1,1,1,1,1,1,1,1,1,1,1,1,1
1,1,1,1,1,1,1,1,1,1,1,1,1,1,1,1,1,1,1
1,1,1,1,1,1,1,1,1,1,1,1,1,1,1,1,1,1,1
1,1,1,1,1,1,1,1,1,1,1,1,1,1,1,1,1,1,1
1,1,1,1,1,1,1,1,1,1,1,1,1,1,1,1,1,1,1
1,1,1,1,1,1,1,1,1,1,1,1,1,1,1,1,1,1,1
1,1,1,1,1,1,1,1,1,1,1,1,1,1,1,1,1,1,1
1,1,1,1,1,1,1,1,1,1,1,1,1,1,1,1,1,1,1
1,1,1,1,1,1,1,1,1,1,1,1,1,1,1,1,1,1,1
1,1,1,1,1,1,1,1,1,1,1,1,1,1,1,1,1,1,1
1,1,1,1,1,1,1,1,1,1,1,1,1,1,1,1,1,1,1
1,1,1,1,1,1,1,1,1,1,1,1,1,1,1,1,1,1,1
1,1,1,1,1,1,1,1,1,1,1,1,1,1,1,1,1,1,1
1,1,1,1,1,1,1,1,1,1,1,1,1,1,1,1,1,1,1
1,1,1,1,1,1,1,1,1,1,1,1,1,1,1,1,1,1,1
1,1,1,1,1,1,1,1,1,1,1,1,1,1,1,1,1,1,1
1,1,1,1,1,1,1,1,1,1,1,1,1,1,1,1,1,1,1
1,1,1,1,1,1,1,1,1,1,1,1,1,1,1,1,1,1,1
:endlayer
layer: 3
2,2,2,2,2,2,2,2,2,2,2,2,2,2,2,2,2,2,2
2,2,2,2,2,2,2,2,2,2,2,2,2,2,2,2,2,2,2
2,2,2,2,2,2,2,2,2,2,2,2,2,2,2,2,2,2,2
2,2,2,2,2,2,2,2,2,2,2,2,2,2,2,2,2,2,2
2,2,2,2,2,2,2,2,2,2,2,2,2,2,2,2,2,2,2
2,2,2,2,1,2,2,2,2,2,2,2,2,2,1,2,2,2,2
2,2,2,2,2,2,2,2,1,1,2,2,2,2,2,2,2,2,2
2,2,2,2,2,2,2,2,1,1,2,2,2,2,2,2,2,2,2
2,2,2,2,2,2,2,2,2,2,2,2,2,2,2,2,2,2,2
2,2,2,2,2,3,2,2,2,2,2,2,2,2,2,2,2,2,2
2,2,2,2,2,1,2,2,2,1,1,2,2,2,1,1,2,2,2
2,2,2,2,2,1,1,1,1,1,1,2,2,2,1,1,2,2,2
2,2,2,2,2,1,1,1,1,1,1,2,2,1,1,2,2,2,2
2,2,2,2,2,1,1,1,1,1,1,2,2,1,1,2,2,2,2
2,2,2,2,1,2,2,2,2,1,2,2,2,2,2,2,2,2,2
2,2,2,2,2,2,1,1,2,2,2,2,2,2,1,2,2,2,2
2,2,2,2,2,2,1,1,2,2,2,2,2,2,2,2,2,2,2
2,2,2,2,2,2,2,2,2,2,2,2,2,2,2,2,2,2,2
2,2,2,2,2,2,2,2,2,2,2,2,2,2,2,2,2,2,2
2,2,2,2,2,2,2,2,2,2,2,2,2,2,2,2,2,2,2
2,2,2,2,2,2,2,2,2,2,2,2,2,2,2,2,2,2,2
2,2,2,2,2,2,2,2,2,2,2,2,2,2,2,2,2,2,2
2,2,2,2,2,2,2,2,2,2,2,2,2,2,2,2,2,2,2
:endlayer
layer: 4
4,0,4,0,0,4,0,0,0,0,4,0,5,0,0,0,0,0,0
4,4,4,0,0,6,6,6,6,6,6,6,6,6,0,0,0,4,0
0,4,0,4,0,6,4,0,0,0,0,0,4,6,4,0,0,4,0
4,4,4,7,0,8,4,0,0,4,0,4,4,6,4,0,9,0,0
0,0,0,0,0,6,4,4,4,4,4,4,0,6,0,0,0,0,0
0,0,0,4,10,6,6,6,6,6,6,6,6,6,10,11,0,0,0
0,0,0,0,4,6,4,0,10,10,0,4,4,6,0,4,0,0,0
0,0,0,4,0,4,0,12,10,10,13,4,4,0,0,0,0,0,0
0,4,0,4,0,4,0,0,14,14,15,4,0,0,0,0,5,0,0
0,4,4,4,0,3,0,0,0,0,0,0,0,0,6,4,4,4,0
4,0,4,4,4,3,4,0,0,3,3,0,0,0,10,10,4,4,4
0,0,4,4,4,3,3,3,3,3,3,0,0,0,10,10,4,4,4
0,0,0,4,0,3,3,3,3,3,3,0,0,16,16,0,4,4,0
0,4,0,4,0,3,3,3,3,3,3,0,4,16,16,0,0,0,0
4,4,4,0,10,4,4,0,0,10,4,4,4,4,0,0,0,0,0
4,4,4,4,0,12,10,10,13,4,4,4,4,0,10,0,5,0,0
4,4,4,0,0,4,10,10,4,4,0,4,4,4,4,4,0,0,0
4,4,4,4,0,0,4,4,4,0,0,4,4,4,0,0,0,0,0
4,4,0,0,17,0,0,4,4,4,4,4,4,4,4,4,4,0,0
0,4,0,0,0,0,0,4,4,0,4,0,4,4,4,4,0,0,0
4,4,0,0,4,4,4,4,4,4,4,4,4,4,4,0,0,4,4
4,0,4,4,0,0,0,0,4,4,4,0,0,0,4,4,4,4,4
0,4,18,4,0,0,4,4,4,4,0,4,0,0,0,0,4,4,4
:endlayer
layer: 5
0,0,0,0,0,0,0,0,0,0,0,0,0,0,0,0,0,0,0
0,0,0,0,0,6,0,0,0,0,0,0,0,6,0,0,0,0,0
0,0,0,0,0,0,0,0,0,0,0,0,0,0,0,0,0,0,0
0,0,0,0,0,0,0,0,0,0,0,0,0,0,0,0,0,0,0
0,0,0,0,0,0,0,0,0,0,0,0,0,0,0,0,0,0,0
0,0,0,0,10,0,0,0,0,0,0,0,0,0,10,19,0,0,0
0,0,0,0,0,16,16,16,16,16,16,16,16,16,0,0,0,0,0
0,0,0,0,0,16,16,16,16,16,16,16,16,16,0,0,0,0,0
0,0,0,0,0,16,16,16,16,16,16,16,16,16,0,0,0,0,0
0,0,0,0,0,16,16,16,16,16,16,16,16,16,6,0,0,0,0
0,0,0,0,0,16,16,16,16,16,16,16,16,16,10,0,0,0,0
0,0,0,0,0,3,3,3,3,3,16,16,16,16,10,10,0,0,0
0,0,0,0,0,3,3,3,3,3,16,16,16,16,0,0,0,0,0
0,0,0,0,0,3,3,3,3,3,16,16,16,16,0,0,0,0,0
0,0,0,0,10,0,0,0,0,10,0,0,0,0,0,0,0,0,0
0,0,0,0,0,12,10,10,13,0,0,0,0,0,10,0,0,0,0
0,0,0,0,0,12,10,10,13,0,0,0,0,0,0,0,0,0,0
0,0,0,0,0,0,14,14,0,0,0,0,0,0,0,0,0,0,0
0,0,0,0,0,0,0,0,0,0,0,0,0,0,0,0,0,0,0
0,0,0,0,0,0,0,0,0,0,0,0,0,0,0,0,0,0,0
0,0,0,0,0,0,0,0,0,0,0,0,0,0,0,0,0,0,0
0,0,0,0,0,0,0,0,0,0,0,0,0,0,0,0,0,0,0
0,0,0,0,0,0,0,0,0,0,0,0,0,0,0,0,0,0,0
:endlayer
layer: 6
0,0,0,0,0,0,0,0,0,0,0,0,0,0,0,0,0,0,0
0,0,0,0,0,6,0,0,0,0,0,0,0,6,0,0,0,0,0
0,0,0,0,0,0,0,0,0,0,0,0,0,0,0,0,0,0,0
0,0,0,0,0,0,0,0,0,0,0,0,0,0,0,0,0,0,0
0,0,0,0,20,0,0,0,0,0,0,0,0,0,20,0,0,0,0
0,0,0,0,16,16,16,16,16,16,16,16,16,16,16,0,0,0,0
0,0,0,0,16,0,0,21,0,0,0,22,0,0,16,0,0,0,0
0,0,0,0,16,0,0,0,0,23,0,0,0,0,16,0,0,0,0
0,0,0,0,16,0,24,25,0,0,0,0,0,0,16,0,0,0,0
0,0,0,0,16,26,27,28,29,16,10,0,0,6,16,0,0,0,0
0,0,0,0,16,30,30,30,30,30,0,0,0,0,10,0,0,0,0
0,0,0,0,16,3,31,32,0,0,0,0,0,0,10,10,0,0,0
0,0,0,0,16,3,33,0,34,35,0,0,0,0,0,0,0,0,0
0,0,0,0,16,3,3,3,3,30,0,0,0,0,0,0,0,0,0
0,0,0,0,16,16,16,16,16,10,0,0,0,0,0,0,0,0,0
0,0,0,0,0,12,10,10,13,0,0,0,0,0,36,0,0,0,0
0,0,0,0,0,12,10,10,13,0,0,0,0,0,0,0,0,0,0
0,0,0,0,0,0,14,14,0,0,0,0,0,0,0,0,0,0,0
0,0,0,0,0,0,0,0,0,0,0,0,0,0,0,0,0,0,0
0,0,0,0,0,0,0,0,0,0,0,0,0,0,0,0,0,0,0
0,0,0,0,0,0,0,0,0,0,0,0,0,0,0,0,0,0,0
0,0,0,0,0,0,0,0,0,0,0,0,0,0,0,0,0,0,0
0,0,0,0,0,0,0,0,0,0,0,0,0,0,0,0,0,0,0
:endlayer
layer: 7
0,0,0,0,0,0,0,0,0,0,0,0,0,0,0,0,0,0,0
0,0,0,0,0,6,0,0,0,0,0,0,0,6,0,0,0,0,0
0,0,0,0,0,0,0,0,0,0,0,0,0,0,0,0,0,0,0
0,0,0,0,0,0,0,0,0,0,0,0,0,0,0,0,0,0,0
0,0,0,0,0,0,0,0,0,0,0,0,0,0,0,0,0,0,0
0,0,0,0,10,10,10,10,10,10,10,10,10,10,10,0,0,0,0
0,0,0,0,10,0,0,0,0,0,0,0,0,0,10,0,0,0,0
0,0,0,0,10,0,0,0,0,0,0,0,0,0,10,0,0,0,0
0,0,0,0,10,0,0,0,0,0,0,0,0,0,10,0,0,0,0
0,0,0,0,10,0,0,0,0,10,10,0,0,37,10,0,0,0,0
0,0,0,0,10,30,30,30,30,30,0,0,0,0,10,0,0,0,0
0,0,0,0,10,3,38,0,0,0,0,0,0,0,10,10,0,0,0
0,0,0,0,10,3,39,0,0,0,0,0,0,0,0,0,0,0,0
0,0,0,0,10,3,3,3,3,30,0,0,0,0,0,0,0,0,0
0,0,0,0,10,10,10,10,10,0,0,0,0,0,0,0,0,0,0
0,0,0,0,0,12,10,10,13,0,0,0,0,0,0,0,0,0,0
0,0,0,0,0,12,10,10,13,0,0,0,0,0,0,0,0,0,0
0,0,0,0,0,0,14,14,0,0,0,0,0,0,0,0,0,0,0
0,0,0,0,0,0,0,0,0,0,0,0,0,0,0,0,0,0,0
0,0,0,0,0,0,0,0,0,0,0,0,0,0,0,0,0,0,0
0,0,0,0,0,0,0,0,0,0,0,0,0,0,0,0,0,0,0
0,0,0,0,0,0,0,0,0,0,0,0,0,0,0,0,0,0,0
0,0,0,0,0,0,0,0,0,0,0,0,0,0,0,0,0,0,0
:endlayer
layer: 8
0,0,0,0,0,0,0,0,0,0,0,0,0,0,0,0,0,0,0
0,0,0,0,0,16,16,16,16,16,16,16,16,16,0,0,0,0,0
0,0,0,0,0,16,16,16,16,16,16,16,16,16,0,0,0,0,0
0,0,0,0,0,16,16,16,16,16,16,16,16,16,0,0,0,0,0
0,0,0,0,0,0,0,0,0,0,0,0,0,0,0,0,0,0,0
0,0,0,0,10,10,10,10,10,10,10,10,10,10,10,0,0,0,0
0,0,0,0,10,40,0,0,0,0,0,0,0,41,10,0,0,0,0
0,0,0,0,10,0,0,0,0,0,0,0,0,0,10,0,0,0,0
0,0,0,0,10,0,0,0,0,0,0,0,0,0,10,0,0,0,0
0,0,0,0,10,0,0,0,42,10,10,16,16,16,10,0,0,0,0
0,0,0,0,10,30,30,30,30,30,0,0,0,0,10,0,0,0,0
0,0,0,0,10,3,43,0,41,0,0,0,0,0,0,10,0,0,0
0,0,0,0,0,3,44,0,20,0,0,0,0,0,0,0,0,0,0
0,0,0,0,0,3,3,3,3,30,0,0,0,0,0,0,0,0,0
0,0,0,0,10,10,10,10,0,0,0,0,0,0,0,0,0,0,0
0,0,0,0,0,12,10,10,13,0,0,0,0,0,0,0,0,0,0
0,0,0,0,0,12,10,10,13,0,0,0,0,0,0,0,0,0,0
0,0,0,0,0,0,14,14,0,0,0,0,0,0,0,0,0,0,0
0,0,0,0,0,0,0,0,0,0,0,0,0,0,0,0,0,0,0
0,0,0,0,0,0,0,0,0,0,0,0,0,0,0,0,0,0,0
0,0,0,0,0,0,0,0,0,0,0,0,0,0,0,0,0,0,0
0,0,0,0,0,0,0,0,0,0,0,0,0,0,0,0,0,0,0
0,0,0,0,0,0,0,0,0,0,0,0,0,0,0,0,0,0,0
:endlayer
layer: 9
0,0,0,0,0,0,0,0,0,0,0,0,0,0,0,0,0,0,0
0,0,0,0,0,0,0,0,0,0,0,0,0,0,0,0,0,0,0
0,0,0,0,0,0,0,0,0,0,0,0,0,0,0,0,0,0,0
0,0,0,0,0,16,16,16,16,16,16,16,16,16,0,0,0,0,0
0,0,0,0,0,16,16,16,16,16,16,16,16,16,0,0,0,0,0
0,0,0,0,6,16,16,16,16,16,16,16,16,16,6,0,0,0,0
0,0,0,0,6,45,45,45,10,10,45,45,45,45,6,0,0,0,0
0,0,0,0,6,45,45,45,10,10,45,45,45,45,6,0,0,0,0
0,0,0,0,6,45,45,45,45,45,45,45,45,45,6,0,0,0,0
0,0,0,0,6,46,46,46,46,46,46,46,46,46,46,0,0,0,0
0,0,0,0,10,30,30,30,30,30,0,0,0,0,10,0,0,0,0
0,0,0,0,0,30,30,30,30,30,40,0,0,0,0,10,0,0,0
0,0,0,0,0,30,30,30,30,30,40,0,0,0,0,0,0,0,0
0,0,0,0,0,30,30,30,30,30,0,0,0,0,0,0,0,0,0
0,0,0,0,6,0,47,47,0,6,0,0,0,0,0,0,0,0,0
0,0,0,0,0,12,10,10,13,0,0,0,0,0,0,0,0,0,0
0,0,0,0,0,12,10,10,13,0,0,0,0,0,0,0,0,0,0
0,0,0,0,0,0,14,14,0,0,0,0,0,0,0,0,0,0,0
0,0,0,0,0,0,0,0,0,0,0,0,0,0,0,0,0,0,0
0,0,0,0,0,0,0,0,0,0,0,0,0,0,0,0,0,0,0
0,0,0,0,0,0,0,0,0,0,0,0,0,0,0,0,0,0,0
0,0,0,0,0,0,0,0,0,0,0,0,0,0,0,0,0,0,0
0,0,0,0,0,0,0,0,0,0,0,0,0,0,0,0,0,0,0
:endlayer
layer: 10
0,0,0,0,0,0,0,0,0,0,0,0,0,0,0,0,0,0,0
0,0,0,0,0,0,0,0,0,0,0,0,0,0,0,0,0,0,0
0,0,0,0,0,0,0,0,0,0,0,0,0,0,0,0,0,0,0
0,0,0,0,0,0,0,0,0,0,0,0,0,0,0,0,0,0,0
0,0,0,0,0,48,0,0,0,0,0,0,0,49,0,0,0,0,0
0,0,0,0,0,0,0,0,47,50,0,0,0,0,37,0,0,0,0
0,0,0,0,0,0,0,12,10,10,13,0,0,0,0,0,0,0,0
0,0,0,0,0,0,0,12,10,10,13,0,0,0,0,0,0,0,0
0,0,0,0,0,0,0,0,14,14,0,0,0,0,0,0,0,0,0
0,0,0,0,51,0,0,0,0,52,0,0,0,0,0,0,0,0,0
0,0,0,0,53,16,16,16,16,16,0,0,0,0,10,0,0,0,0
0,0,0,0,0,16,0,0,0,16,0,0,0,0,0,10,0,0,0
0,0,0,0,0,16,0,0,0,16,0,0,0,0,0,0,0,0,0
0,0,0,0,0,16,16,16,16,16,0,0,0,0,0,0,0,0,0
0,0,0,0,54,0,47,47,0,55,0,0,0,0,0,0,0,0,0
0,0,0,0,0,12,10,10,13,0,0,0,0,0,0,0,0,0,0
0,0,0,0,0,12,10,10,13,0,0,0,0,0,0,0,0,0,0
0,0,0,0,0,0,14,14,0,0,0,0,0,0,0,0,0,0,0
0,0,0,0,0,0,0,0,0,0,0,0,0,0,0,0,0,0,0
0,0,0,0,0,0,0,0,0,0,0,0,0,0,0,0,0,0,0
0,0,0,0,0,0,0,0,0,0,0,0,0,0,0,0,0,0,0
0,0,0,0,0,0,0,0,0,0,0,0,0,0,0,0,0,0,0
0,0,0,0,0,0,0,0,0,0,0,0,0,0,0,0,0,0,0
:endlayer
layer: 11
0,0,0,0,0,0,0,0,0,0,0,0,0,0,0,0,0,0,0
0,0,0,0,0,0,0,0,0,0,0,0,0,0,0,0,0,0,0
0,0,0,0,0,0,0,0,0,0,0,0,0,0,0,0,0,0,0
0,0,0,0,0,0,0,0,0,0,0,0,0,0,0,0,0,0,0
0,0,0,0,0,0,0,0,0,0,0,0,0,0,0,0,0,0,0
0,0,0,0,0,0,0,0,47,50,0,0,0,0,0,0,0,0,0
0,0,0,0,0,0,0,12,10,10,13,0,0,0,0,0,0,0,0
0,0,0,0,0,0,0,12,10,10,13,0,0,0,0,0,0,0,0
0,0,0,0,0,0,0,0,14,14,0,0,0,0,0,0,0,0,0
0,0,0,0,0,0,0,0,0,0,0,0,0,0,0,0,0,0,0
0,0,0,0,0,0,0,0,0,0,0,0,0,0,10,0,0,0,0
0,0,0,0,0,0,0,0,0,0,0,0,0,0,0,10,0,0,0
0,0,0,0,0,0,0,0,0,0,0,0,0,0,0,0,0,0,0
0,0,0,0,0,0,0,0,0,56,0,0,0,0,0,0,0,0,0
0,0,0,0,0,0,47,47,0,0,0,0,0,0,0,0,0,0,0
0,0,0,0,0,12,10,10,13,0,0,0,0,0,0,0,0,0,0
0,0,0,0,0,12,10,10,13,0,0,0,0,0,0,0,0,0,0
0,0,0,0,0,0,14,14,0,0,0,0,0,0,0,0,0,0,0
0,0,0,0,0,0,0,0,0,0,0,0,0,0,0,0,0,0,0
0,0,0,0,0,0,0,0,0,0,0,0,0,0,0,0,0,0,0
0,0,0,0,0,0,0,0,0,0,0,0,0,0,0,0,0,0,0
0,0,0,0,0,0,0,0,0,0,0,0,0,0,0,0,0,0,0
0,0,0,0,0,0,0,0,0,0,0,0,0,0,0,0,0,0,0
:endlayer
layer: 12
0,0,0,0,0,0,0,0,0,0,0,0,0,0,0,0,0,0,0
0,0,0,0,0,0,0,0,0,0,0,0,0,0,0,0,0,0,0
0,0,0,0,0,0,0,0,0,0,0,0,0,0,0,0,0,0,0
0,0,0,0,0,0,0,0,0,0,0,0,0,0,0,0,0,0,0
0,0,0,0,0,0,0,0,0,0,0,0,0,0,0,0,0,0,0
0,0,0,0,0,0,0,0,47,50,0,0,0,0,0,0,0,0,0
0,0,0,0,0,0,0,12,10,10,13,0,0,0,0,0,0,0,0
0,0,0,0,0,0,0,12,10,10,13,0,0,0,0,0,0,0,0
0,0,0,0,0,0,0,0,14,14,0,0,0,0,0,0,0,0,0
0,0,0,0,0,0,0,0,0,0,0,0,0,57,57,57,57,57,0
0,0,0,0,0,0,0,0,0,0,0,0,0,57,57,57,57,57,0
0,0,0,0,0,0,0,0,0,0,0,0,0,57,57,10,57,57,0
0,0,0,0,0,0,0,0,0,0,0,0,0,57,57,57,57,57,0
0,0,0,0,0,0,0,0,0,0,0,0,0,57,57,57,57,57,0
0,0,0,0,0,0,47,47,0,0,0,0,0,0,0,0,0,0,0
0,0,0,0,0,12,10,10,13,0,0,0,0,0,0,0,0,0,0
0,0,0,0,0,12,10,10,13,0,0,0,0,0,0,0,0,0,0
0,0,0,0,0,0,14,14,0,0,0,0,0,0,0,0,0,0,0
0,0,0,0,0,0,0,0,0,0,0,0,0,0,0,0,0,0,0
0,0,0,0,0,0,0,0,0,0,0,0,0,0,0,0,0,0,0
0,0,0,0,0,0,0,0,0,0,0,0,0,0,0,0,0,0,0
0,0,0,0,0,0,0,0,0,0,0,0,0,0,0,0,0,0,0
0,0,0,0,0,0,0,0,0,0,0,0,0,0,0,0,0,0,0
:endlayer
layer: 13
0,0,0,0,0,0,0,0,0,0,0,0,0,0,0,0,0,0,0
0,0,0,0,0,0,0,0,0,0,0,0,0,0,0,0,0,0,0
0,0,0,0,0,0,0,0,0,0,0,0,0,0,0,0,0,0,0
0,0,0,0,0,0,0,0,0,0,0,0,0,0,0,0,0,0,0
0,0,0,0,0,0,0,0,0,0,0,0,0,0,0,0,0,0,0
0,0,0,0,0,0,0,0,47,50,0,0,0,0,0,0,0,0,0
0,0,0,0,0,0,0,12,10,10,13,0,0,0,0,0,0,0,0
0,0,0,0,0,0,0,12,10,10,13,0,0,0,0,0,0,0,0
0,0,0,0,0,0,0,0,14,14,0,0,0,0,0,0,0,0,0
0,0,0,0,0,0,0,0,0,0,0,0,0,0,57,57,57,0,0
0,0,0,0,0,0,0,0,0,0,0,0,0,57,57,57,57,57,0
0,0,0,0,0,0,0,0,0,0,0,0,0,57,57,10,57,57,0
0,0,0,0,0,0,0,0,0,0,0,0,0,57,57,57,57,57,0
0,0,0,0,0,0,0,0,0,0,0,0,0,57,57,57,57,0,0
0,0,0,0,0,0,47,47,0,0,0,0,0,0,0,0,0,0,0
0,0,0,0,0,12,10,10,13,0,0,0,0,0,0,0,0,0,0
0,0,0,0,0,12,10,10,13,0,0,0,0,0,0,0,0,0,0
0,0,0,0,0,0,14,14,0,0,0,0,0,0,0,0,0,0,0
0,0,0,0,0,0,0,0,0,0,0,0,0,0,0,0,0,0,0
0,0,0,0,0,0,0,0,0,0,0,0,0,0,0,0,0,0,0
0,0,0,0,0,0,0,0,0,0,0,0,0,0,0,0,0,0,0
0,0,0,0,0,0,0,0,0,0,0,0,0,0,0,0,0,0,0
0,0,0,0,0,0,0,0,0,0,0,0,0,0,0,0,0,0,0
:endlayer
layer: 14
0,0,0,0,0,0,0,0,0,0,0,0,0,0,0,0,0,0,0
0,0,0,0,0,0,0,0,0,0,0,0,0,0,0,0,0,0,0
0,0,0,0,0,0,0,0,0,0,0,0,0,0,0,0,0,0,0
0,0,0,0,0,0,0,0,0,0,0,0,0,0,0,0,0,0,0
0,0,0,0,0,0,0,0,0,0,0,0,0,0,0,0,0,0,0
0,0,0,0,0,0,0,0,47,50,0,0,0,0,0,0,0,0,0
0,0,0,0,0,0,0,12,10,10,13,0,0,0,0,0,0,0,0
0,0,0,0,0,0,0,12,10,10,13,0,0,0,0,0,0,0,0
0,0,0,0,0,0,0,0,14,14,0,0,0,0,0,0,0,0,0
0,0,0,0,0,0,0,0,0,0,0,0,0,0,0,0,0,0,0
0,0,0,0,0,0,0,0,0,0,0,0,0,0,57,57,57,0,0
0,0,0,0,0,0,0,0,0,0,0,0,0,0,57,10,57,0,0
0,0,0,0,0,0,0,0,0,0,0,0,0,0,0,57,57,0,0
0,0,0,0,0,0,0,0,0,0,0,0,0,0,0,0,0,0,0
0,0,0,0,0,0,47,47,0,0,0,0,0,0,0,0,0,0,0
0,0,0,0,0,12,10,10,13,0,0,0,0,0,0,0,0,0,0
0,0,0,0,0,12,10,10,13,0,0,0,0,0,0,0,0,0,0
0,0,0,0,0,0,14,14,0,0,0,0,0,0,0,0,0,0,0
0,0,0,0,0,0,0,0,0,0,0,0,0,0,0,0,0,0,0
0,0,0,0,0,0,0,0,0,0,0,0,0,0,0,0,0,0,0
0,0,0,0,0,0,0,0,0,0,0,0,0,0,0,0,0,0,0
0,0,0,0,0,0,0,0,0,0,0,0,0,0,0,0,0,0,0
0,0,0,0,0,0,0,0,0,0,0,0,0,0,0,0,0,0,0
:endlayer
layer: 15
0,0,0,0,0,0,0,0,0,0,0,0,0,0,0,0,0,0,0
0,0,0,0,0,0,0,0,0,0,0,0,0,0,0,0,0,0,0
0,0,0,0,0,0,0,0,0,0,0,0,0,0,0,0,0,0,0
0,0,0,0,0,0,0,0,0,0,0,0,0,0,0,0,0,0,0
0,0,0,0,0,0,0,0,0,0,0,0,0,0,0,0,0,0,0
0,0,0,0,0,0,0,0,47,50,0,0,0,0,0,0,0,0,0
0,0,0,0,0,0,0,12,10,10,13,0,0,0,0,0,0,0,0
0,0,0,0,0,0,0,12,10,10,13,0,0,0,0,0,0,0,0
0,0,0,0,0,0,0,0,14,14,0,0,0,0,0,0,0,0,0
0,0,0,0,0,0,0,0,0,0,0,0,0,0,0,0,0,0,0
0,0,0,0,0,0,0,0,0,0,0,0,0,0,0,57,0,0,0
0,0,0,0,0,0,0,0,0,0,0,0,0,0,57,57,57,0,0
0,0,0,0,0,0,0,0,0,0,0,0,0,0,0,57,0,0,0
0,0,0,0,0,0,0,0,0,0,0,0,0,0,0,0,0,0,0
0,0,0,0,0,0,47,47,0,0,0,0,0,0,0,0,0,0,0
0,0,0,0,0,12,10,10,13,0,0,0,0,0,0,0,0,0,0
0,0,0,0,0,12,10,10,13,0,0,0,0,0,0,0,0,0,0
0,0,0,0,0,0,14,14,0,0,0,0,0,0,0,0,0,0,0
0,0,0,0,0,0,0,0,0,0,0,0,0,0,0,0,0,0,0
0,0,0,0,0,0,0,0,0,0,0,0,0,0,0,0,0,0,0
0,0,0,0,0,0,0,0,0,0,0,0,0,0,0,0,0,0,0
0,0,0,0,0,0,0,0,0,0,0,0,0,0,0,0,0,0,0
0,0,0,0,0,0,0,0,0,0,0,0,0,0,0,0,0,0,0
:endlayer
layer: 16
0,0,0,0,0,0,0,0,0,0,0,0,0,0,0,0,0,0,0
0,0,0,0,0,0,0,0,0,0,0,0,0,0,0,0,0,0,0
0,0,0,0,0,0,0,0,0,0,0,0,0,0,0,0,0,0,0
0,0,0,0,0,0,0,0,0,0,0,0,0,0,0,0,0,0,0
0,0,0,0,0,0,0,0,0,0,0,0,0,0,0,0,0,0,0
0,0,0,0,0,0,0,0,47,50,0,0,0,0,0,0,0,0,0
0,0,0,0,0,0,0,12,10,10,13,0,0,0,0,0,0,0,0
0,0,0,0,0,0,0,12,10,10,13,0,0,0,0,0,0,0,0
0,0,0,0,0,0,0,0,14,14,0,0,0,0,0,0,0,0,0
0,0,0,0,0,0,0,0,0,0,0,0,0,0,0,0,0,0,0
0,0,0,0,0,0,0,0,0,0,0,0,0,0,0,0,0,0,0
0,0,0,0,0,0,0,0,0,0,0,0,0,0,0,0,0,0,0
0,0,0,0,0,0,0,0,0,0,0,0,0,0,0,0,0,0,0
0,0,0,0,0,0,0,0,0,0,0,0,0,0,0,0,0,0,0
0,0,0,0,0,0,47,47,0,0,0,0,0,0,0,0,0,0,0
0,0,0,0,0,12,10,10,13,0,0,0,0,0,0,0,0,0,0
0,0,0,0,0,12,10,10,13,0,0,0,0,0,0,0,0,0,0
0,0,0,0,0,0,14,14,0,0,0,0,0,0,0,0,0,0,0
0,0,0,0,0,0,0,0,0,0,0,0,0,0,0,0,0,0,0
0,0,0,0,0,0,0,0,0,0,0,0,0,0,0,0,0,0,0
0,0,0,0,0,0,0,0,0,0,0,0,0,0,0,0,0,0,0
0,0,0,0,0,0,0,0,0,0,0,0,0,0,0,0,0,0,0
0,0,0,0,0,0,0,0,0,0,0,0,0,0,0,0,0,0,0
:endlayer
layer: 17
0,0,0,0,0,0,0,0,0,0,0,0,0,0,0,0,0,0,0
0,0,0,0,0,0,0,0,0,0,0,0,0,0,0,0,0,0,0
0,0,0,0,0,0,0,0,0,0,0,0,0,0,0,0,0,0,0
0,0,0,0,0,0,0,0,0,0,0,0,0,0,0,0,0,0,0
0,0,0,0,0,0,0,0,0,0,0,0,0,0,0,0,0,0,0
0,0,0,0,0,0,0,0,47,50,0,0,0,0,0,0,0,0,0
0,0,0,0,0,0,0,58,10,10,13,0,0,0,0,0,0,0,0
0,0,0,0,0,0,0,12,10,10,13,0,0,0,0,0,0,0,0
0,0,0,0,0,0,0,0,14,14,0,0,0,0,0,0,0,0,0
0,0,0,0,0,0,0,0,0,0,0,0,0,0,0,0,0,0,0
0,0,0,0,0,0,0,0,0,0,0,0,0,0,0,0,0,0,0
0,0,0,0,0,0,0,0,0,57,0,0,0,0,0,0,0,0,0
0,0,0,0,0,0,0,57,57,57,57,57,0,0,0,0,0,0,0
0,0,0,0,0,0,0,57,57,57,57,57,0,0,0,0,0,0,0
0,0,0,0,0,0,57,10,10,57,57,57,57,0,0,0,0,0,0
0,0,0,0,0,12,10,10,57,57,57,57,0,0,0,0,0,0,0
0,0,0,0,0,12,10,10,57,57,57,57,0,0,0,0,0,0,0
0,0,0,0,0,0,14,14,0,57,0,0,0,0,0,0,0,0,0
0,0,0,0,0,0,0,0,0,0,0,0,0,0,0,0,0,0,0
0,0,0,0,0,0,0,0,0,0,0,0,0,0,0,0,0,0,0
0,0,0,0,0,0,0,0,0,0,0,0,0,0,0,0,0,0,0
0,0,0,0,0,0,0,0,0,0,0,0,0,0,0,0,0,0,0
0,0,0,0,0,0,0,0,0,0,0,0,0,0,0,0,0,0,0
:endlayer
layer: 18
0,0,0,0,0,0,0,0,0,0,0,0,0,0,0,0,0,0,0
0,0,0,0,0,0,0,0,0,0,0,0,0,0,0,0,0,0,0
0,0,0,0,0,0,0,0,0,0,0,0,0,0,0,0,0,0,0
0,0,0,0,0,0,0,0,0,0,0,0,0,0,0,0,0,0,0
0,0,0,0,0,0,0,0,0,0,0,0,0,0,0,0,0,0,0
0,0,0,0,0,0,0,0,47,50,0,0,0,0,0,0,0,0,0
0,0,0,0,0,0,0,58,10,10,13,0,0,0,0,0,0,0,0
0,0,0,0,0,0,0,12,10,10,13,0,0,0,0,0,0,0,0
0,0,0,0,0,0,0,0,14,14,0,0,0,0,0,0,0,0,0
0,0,0,0,0,0,0,0,0,0,0,0,0,0,0,0,0,0,0
0,0,0,0,0,0,0,0,0,0,0,0,0,0,0,0,0,0,0
0,0,0,0,0,0,0,0,0,0,0,0,0,0,0,0,0,0,0
0,0,0,0,0,0,0,0,0,57,0,0,0,0,0,0,0,0,0
0,0,0,0,0,0,0,0,57,57,57,0,0,0,0,0,0,0,0
0,0,0,0,0,0,59,57,57,10,57,57,0,0,0,0,0,0,0
0,0,0,0,0,12,10,10,57,57,57,0,0,0,0,0,0,0,0
0,0,0,0,0,12,10,10,13,57,0,0,0,0,0,0,0,0,0
0,0,0,0,0,0,14,14,0,0,0,0,0,0,0,0,0,0,0
0,0,0,0,0,0,0,0,0,0,0,0,0,0,0,0,0,0,0
0,0,0,0,0,0,0,0,0,0,0,0,0,0,0,0,0,0,0
0,0,0,0,0,0,0,0,0,0,0,0,0,0,0,0,0,0,0
0,0,0,0,0,0,0,0,0,0,0,0,0,0,0,0,0,0,0
0,0,0,0,0,0,0,0,0,0,0,0,0,0,0,0,0,0,0
:endlayer
layer: 19
0,0,0,0,0,0,0,0,0,0,0,0,0,0,0,0,0,0,0
0,0,0,0,0,0,0,0,0,0,0,0,0,0,0,0,0,0,0
0,0,0,0,0,0,0,0,0,0,0,0,0,0,0,0,0,0,0
0,0,0,0,0,0,0,0,0,0,0,0,0,0,0,0,0,0,0
0,0,0,0,0,0,0,0,0,0,0,0,0,0,0,0,0,0,0
0,0,0,0,0,0,0,0,47,50,0,0,0,0,0,0,0,0,0
0,0,0,0,0,0,0,58,10,10,13,0,0,0,0,0,0,0,0
0,0,0,0,0,0,0,12,10,10,13,0,0,0,0,0,0,0,0
0,0,0,0,0,0,0,0,14,14,0,0,0,0,0,0,0,0,0
0,0,0,0,0,0,0,0,0,0,0,0,0,0,0,0,0,0,0
0,0,0,0,0,0,0,0,0,0,0,0,0,0,0,0,0,0,0
0,0,0,0,0,0,0,0,0,0,0,0,0,0,0,0,0,0,0
0,0,0,0,0,0,0,0,0,0,0,0,0,0,0,0,0,0,0
0,0,0,0,0,0,0,0,0,57,0,0,0,0,0,0,0,0,0
0,0,0,0,0,10,59,47,57,57,57,0,0,0,0,0,0,0,0
0,0,0,0,0,12,10,10,13,57,0,0,0,0,0,0,0,0,0
0,0,0,0,0,12,10,10,13,0,0,0,0,0,0,0,0,0,0
0,0,0,0,0,0,14,14,0,0,0,0,0,0,0,0,0,0,0
0,0,0,0,0,0,0,0,0,0,0,0,0,0,0,0,0,0,0
0,0,0,0,0,0,0,0,0,0,0,0,0,0,0,0,0,0,0
0,0,0,0,0,0,0,0,0,0,0,0,0,0,0,0,0,0,0
0,0,0,0,0,0,0,0,0,0,0,0,0,0,0,0,0,0,0
0,0,0,0,0,0,0,0,0,0,0,0,0,0,0,0,0,0,0
:endlayer
layer: 20
0,0,0,0,0,0,0,0,0,0,0,0,0,0,0,0,0,0,0
0,0,0,0,0,0,0,0,0,0,0,0,0,0,0,0,0,0,0
0,0,0,0,0,0,0,0,0,0,0,0,0,0,0,0,0,0,0
0,0,0,0,0,0,0,0,0,0,0,0,0,0,0,0,0,0,0
0,0,0,0,0,0,0,0,0,0,0,0,0,0,0,0,0,0,0
0,0,0,0,0,0,0,0,47,50,0,0,0,0,0,0,0,0,0
0,0,0,0,0,0,0,58,10,10,13,0,0,0,0,0,0,0,0
0,0,0,0,0,0,0,12,10,10,13,0,0,0,0,0,0,0,0
0,0,0,0,0,0,0,0,14,14,0,0,0,0,0,0,0,0,0
0,0,0,0,57,0,0,0,0,0,0,0,0,0,0,0,0,0,0
0,0,57,57,57,57,57,0,0,0,0,0,0,0,0,0,0,0,0
0,0,57,57,57,57,57,0,0,0,0,0,0,0,0,0,0,0,0
0,57,57,57,57,57,57,57,0,0,0,0,0,0,0,0,0,0,0
0,0,57,57,10,10,57,0,0,0,0,0,0,0,0,0,0,0,0
0,0,57,57,57,57,57,47,0,0,0,0,0,0,0,0,0,0,0
0,0,0,0,57,12,10,10,13,0,0,0,0,0,0,0,0,0,0
0,0,0,0,0,12,10,10,13,0,0,0,0,0,0,0,0,0,0
0,0,0,0,0,0,14,14,0,0,0,0,0,0,0,0,0,0,0
0,0,0,0,0,0,0,0,0,0,0,0,0,0,0,0,0,0,0
0,0,0,0,0,0,0,0,0,0,0,0,0,0,0,0,0,0,0
0,0,0,0,0,0,0,0,0,0,0,0,0,0,0,0,0,0,0
0,0,0,0,0,0,0,0,0,0,0,0,0,0,0,0,0,0,0
0,0,0,0,0,0,0,0,0,0,0,0,0,0,0,0,0,0,0
:endlayer
layer: 21
0,0,0,0,0,0,0,0,0,0,0,0,0,0,0,0,0,0,0
0,0,0,0,0,0,0,0,0,0,0,0,0,0,0,0,0,0,0
0,0,0,0,0,0,0,0,0,0,0,0,0,0,0,0,0,0,0
0,0,0,0,0,0,0,0,0,0,0,0,0,0,0,0,0,0,0
0,0,0,0,0,0,0,0,0,0,0,0,0,0,0,0,0,0,0
0,0,0,0,0,0,0,0,47,50,0,0,0,0,0,0,0,0,0
0,0,0,0,0,0,0,58,10,10,13,0,0,0,0,0,0,0,0
0,0,0,0,0,0,0,12,10,10,13,0,0,0,0,0,0,0,0
0,0,0,0,0,0,0,0,14,14,0,0,0,0,0,0,0,0,0
0,0,0,0,0,0,0,0,0,0,0,0,0,0,0,0,0,0,0
0,0,0,0,57,0,0,0,0,0,0,0,0,0,0,0,0,0,0
0,0,0,57,57,57,0,0,0,0,0,0,0,0,0,0,0,0,0
0,0,57,57,10,57,57,0,0,0,0,0,0,0,0,0,0,0,0
0,0,0,57,57,57,0,0,0,0,0,0,0,0,0,0,0,0,0
0,0,0,0,57,0,47,47,0,0,0,0,0,0,0,0,0,0,0
0,0,0,0,0,12,10,10,13,0,0,0,0,0,0,0,0,0,0
0,0,0,0,0,12,10,10,13,0,0,0,0,0,0,0,0,0,0
0,0,0,0,0,0,14,14,0,0,0,0,0,0,0,0,0,0,0
0,0,0,0,0,0,0,0,0,0,0,0,0,0,0,0,0,0,0
0,0,0,0,0,0,0,0,0,0,0,0,0,0,0,0,0,0,0
0,0,0,0,0,0,0,0,0,0,0,0,0,0,0,0,0,0,0
0,0,0,0,0,0,0,0,0,0,0,0,0,0,0,0,0,0,0
0,0,0,0,0,0,0,0,0,0,0,0,0,0,0,0,0,0,0
:endlayer
layer: 22
0,0,0,0,0,0,0,0,0,0,0,0,0,0,0,0,0,0,0
0,0,0,0,0,0,0,0,0,0,0,0,0,0,0,0,0,0,0
0,0,0,0,0,0,0,0,0,0,0,0,0,0,0,0,0,0,0
0,0,0,0,0,0,0,0,0,0,0,0,0,0,0,0,0,0,0
0,0,0,0,0,0,0,0,0,0,0,0,0,0,0,0,0,0,0
0,0,0,0,0,0,0,0,47,50,0,0,0,0,0,0,0,0,0
0,0,0,0,0,0,0,58,10,10,13,0,0,0,0,0,0,0,0
0,0,0,0,0,0,0,12,10,10,13,0,0,0,0,0,0,0,0
0,0,0,0,0,0,0,0,14,14,0,0,0,0,0,0,0,0,0
0,0,0,0,0,0,0,0,0,0,0,0,0,0,0,0,0,0,0
0,0,0,0,0,0,0,0,0,0,0,0,0,0,0,0,0,0,0
0,0,0,0,57,0,0,0,0,0,0,0,0,0,0,0,0,0,0
0,0,0,57,57,57,0,0,0,0,0,0,0,0,0,0,0,0,0
0,0,0,0,57,0,0,0,0,0,0,0,0,0,0,0,0,0,0
0,0,0,0,0,0,47,47,0,0,0,0,0,0,0,0,0,0,0
0,0,0,0,0,12,10,10,13,0,0,0,0,0,0,0,0,0,0
0,0,0,0,0,12,10,10,13,0,0,0,0,0,0,0,0,0,0
0,0,0,0,0,0,14,14,0,0,0,0,0,0,0,0,0,0,0
0,0,0,0,0,0,0,0,0,0,0,0,0,0,0,0,0,0,0
0,0,0,0,0,0,0,0,0,0,0,0,0,0,0,0,0,0,0
0,0,0,0,0,0,0,0,0,0,0,0,0,0,0,0,0,0,0
0,0,0,0,0,0,0,0,0,0,0,0,0,0,0,0,0,0,0
0,0,0,0,0,0,0,0,0,0,0,0,0,0,0,0,0,0,0
:endlayer
layer: 23
0,0,0,0,0,0,0,0,0,0,0,0,0,0,0,0,0,0,0
0,0,0,0,0,0,0,0,0,0,0,0,0,0,0,0,0,0,0
0,0,0,0,0,0,0,0,0,0,0,0,0,0,0,0,0,0,0
0,0,0,0,0,0,0,0,0,0,0,0,0,0,0,0,0,0,0
0,0,0,0,0,0,0,0,0,0,0,0,0,0,0,0,0,0,0
0,0,0,0,0,0,0,0,47,50,0,0,0,0,0,0,0,0,0
0,0,0,0,0,0,0,58,10,10,13,0,0,0,0,0,0,0,0
0,0,0,0,0,0,0,12,10,10,13,0,0,0,0,0,0,0,0
0,0,0,0,0,0,0,0,14,14,0,0,0,0,0,0,0,0,0
0,0,0,0,0,0,0,0,0,0,0,0,0,0,0,0,0,0,0
0,0,0,0,0,0,0,0,0,0,0,0,0,0,0,0,0,0,0
0,0,0,0,0,0,0,0,0,0,0,0,0,0,0,0,0,0,0
0,0,0,0,0,0,0,0,0,0,0,0,0,0,0,0,0,0,0
0,0,0,0,0,0,0,0,0,0,0,0,0,0,0,0,0,0,0
0,0,0,0,0,0,47,47,0,0,0,0,0,0,0,0,0,0,0
0,0,0,0,0,12,10,10,13,0,0,0,0,0,0,0,0,0,0
0,0,0,0,0,12,10,10,13,0,0,0,0,0,0,0,0,0,0
0,0,0,0,0,0,14,14,0,0,0,0,0,0,0,0,0,0,0
0,0,0,0,0,0,0,0,0,0,0,0,0,0,0,0,0,0,0
0,0,0,0,0,0,0,0,0,0,0,0,0,0,0,0,0,0,0
0,0,0,0,0,0,0,0,0,0,0,0,0,0,0,0,0,0,0
0,0,0,0,0,0,0,0,0,0,0,0,0,0,0,0,0,0,0
0,0,0,0,0,0,0,0,0,0,0,0,0,0,0,0,0,0,0
:endlayer
layer: 24
0,0,0,0,0,0,0,0,0,0,0,0,0,0,0,0,0,0,0
0,0,0,0,0,0,0,0,0,0,0,0,0,0,0,0,0,0,0
0,0,0,0,0,0,0,0,0,0,0,0,0,0,0,0,0,0,0
0,0,0,0,0,0,0,0,0,0,0,0,0,0,0,0,0,0,0
0,0,0,0,0,0,0,0,0,0,0,0,0,0,0,0,0,0,0
0,0,0,0,0,0,0,0,47,50,0,0,0,0,0,0,0,0,0
0,0,0,0,0,0,0,58,10,10,13,0,0,0,0,0,0,0,0
0,0,0,0,0,0,0,12,10,10,13,0,0,0,0,0,0,0,0
0,0,0,0,0,0,0,0,14,14,0,0,0,0,0,0,0,0,0
0,0,0,0,0,0,0,0,0,0,0,0,0,0,0,0,0,0,0
0,0,0,0,0,0,57,57,0,0,0,0,0,0,0,0,0,0,0
0,0,0,57,57,57,57,57,57,57,57,0,0,0,0,0,0,0,0
0,0,57,57,57,57,57,57,57,57,57,57,0,0,0,0,0,0,0
0,0,57,57,57,57,57,57,57,57,57,57,0,0,0,0,0,0,0
0,0,57,57,57,57,57,57,57,57,57,57,0,0,0,0,0,0,0
0,57,57,57,57,57,10,10,57,57,57,57,57,0,0,0,0,0,0
0,57,57,57,57,57,10,10,57,57,57,57,57,0,0,0,0,0,0
0,0,57,57,57,57,57,57,57,57,57,57,0,0,0,0,0,0,0
0,0,57,57,57,57,57,57,57,57,57,57,0,0,0,0,0,0,0
0,0,57,57,57,57,57,57,57,57,57,57,0,0,0,0,0,0,0
0,0,0,57,57,57,57,57,57,57,57,0,0,0,0,0,0,0,0
0,0,0,0,0,0,57,57,0,0,0,0,0,0,0,0,0,0,0
0,0,0,0,0,0,0,0,0,0,0,0,0,0,0,0,0,0,0
:endlayer
layer: 25
0,0,0,0,0,0,0,0,0,0,0,0,0,0,0,0,0,0,0
0,0,0,0,0,0,0,0,0,0,0,0,0,0,0,0,0,0,0
0,0,0,0,0,0,0,0,0,0,0,0,0,0,0,0,0,0,0
0,0,0,0,0,0,0,0,0,0,0,0,0,0,0,0,0,0,0
0,0,0,0,0,0,0,0,0,0,0,0,0,0,0,0,0,0,0
0,0,0,0,0,0,0,0,47,50,0,0,0,0,0,0,0,0,0
0,0,0,0,0,0,0,58,10,10,13,0,0,0,0,0,0,0,0
0,0,0,0,0,0,0,12,10,10,13,0,0,0,0,0,0,0,0
0,0,0,0,0,0,0,0,14,14,0,0,0,0,0,0,0,0,0
0,0,0,0,0,0,0,0,0,0,0,0,0,0,0,0,0,0,0
0,0,0,0,0,0,0,0,0,0,0,0,0,0,0,0,0,0,0
0,0,0,0,0,0,57,57,0,0,0,0,0,0,0,0,0,0,0
0,0,0,0,57,57,57,57,57,57,0,0,0,0,0,0,0,0,0
0,0,0,57,57,57,57,57,57,57,57,0,0,0,0,0,0,0,0
0,0,0,57,57,57,57,57,57,57,57,0,0,0,0,0,0,0,0
0,0,57,57,57,57,57,57,57,57,57,57,0,0,0,0,0,0,0
0,0,57,57,57,57,57,10,57,57,57,57,0,0,0,0,0,0,0
0,0,0,57,57,57,57,57,57,57,57,0,0,0,0,0,0,0,0
0,0,0,57,57,57,57,57,57,57,57,0,0,0,0,0,0,0,0
0,0,0,0,57,57,57,57,57,57,0,0,0,0,0,0,0,0,0
0,0,0,0,0,0,57,57,0,0,0,0,0,0,0,0,0,0,0
0,0,0,0,0,0,0,0,0,0,0,0,0,0,0,0,0,0,0
0,0,0,0,0,0,0,0,0,0,0,0,0,0,0,0,0,0,0
:endlayer
layer: 26
0,0,0,0,0,0,0,0,0,0,0,0,0,0,0,0,0,0,0
0,0,0,0,0,0,0,0,0,0,0,0,0,0,0,0,0,0,0
0,0,0,0,0,0,0,0,0,0,0,0,0,0,0,0,0,0,0
0,0,0,0,0,0,0,0,0,0,0,0,0,0,0,0,0,0,0
0,0,0,0,0,0,0,0,0,0,0,0,0,0,0,0,0,0,0
0,0,0,0,0,0,0,10,47,50,0,0,0,0,0,0,0,0,0
0,0,0,0,0,0,0,58,10,10,13,0,0,0,0,0,0,0,0
0,0,0,0,0,0,0,12,10,10,13,0,0,0,0,0,0,0,0
0,0,0,0,0,0,0,0,14,14,0,0,0,0,0,0,0,0,0
0,0,0,0,0,0,0,0,0,0,0,0,0,0,0,0,0,0,0
0,0,0,0,0,0,0,0,0,0,0,0,0,0,0,0,0,0,0
0,0,0,0,0,0,0,0,0,0,0,0,0,0,0,0,0,0,0
0,0,0,0,0,0,57,57,0,0,0,0,0,0,0,0,0,0,0
0,0,0,0,57,57,57,57,57,57,0,0,0,0,0,0,0,0,0
0,0,0,0,57,57,57,57,57,57,0,0,0,0,0,0,0,0,0
0,0,0,57,57,57,57,57,57,57,57,0,0,0,0,0,0,0,0
0,0,0,57,57,57,57,57,57,57,57,0,0,0,0,0,0,0,0
0,0,0,0,57,57,57,57,57,57,0,0,0,0,0,0,0,0,0
0,0,0,0,57,57,57,57,57,57,0,0,0,0,0,0,0,0,0
0,0,0,0,0,0,57,57,0,0,0,0,0,0,0,0,0,0,0
0,0,0,0,0,0,0,0,0,0,0,0,0,0,0,0,0,0,0
0,0,0,0,0,0,0,0,0,0,0,0,0,0,0,0,0,0,0
0,0,0,0,0,0,0,0,0,0,0,0,0,0,0,0,0,0,0
:endlayer
layer: 27
0,0,0,0,0,0,0,0,0,0,0,0,0,0,0,0,0,0,0
0,0,0,0,0,57,0,0,0,0,0,0,0,0,0,0,0,0,0
0,0,0,57,57,57,57,57,0,0,0,0,0,0,0,0,0,0,0
0,0,0,57,57,57,57,57,0,0,0,0,0,0,0,0,0,0,0
0,0,57,57,57,57,10,57,57,0,0,0,0,0,0,0,0,0,0
0,0,0,57,57,57,10,57,47,50,0,0,0,0,0,0,0,0,0
0,0,0,57,57,57,57,57,10,10,13,0,0,0,0,0,0,0,0
0,0,0,0,0,57,0,12,10,10,13,0,0,0,0,0,0,0,0
0,0,0,0,0,0,0,0,14,14,0,0,0,0,0,0,0,0,0
0,0,0,0,0,0,0,0,0,0,0,0,0,0,0,0,0,0,0
0,0,0,0,0,0,0,0,0,0,0,0,0,0,0,0,0,0,0
0,0,0,0,0,0,0,0,0,0,0,0,0,0,0,0,0,0,0
0,0,0,0,0,0,0,0,0,0,0,0,0,0,0,0,0,0,0
0,0,0,0,0,0,0,0,0,0,0,0,0,0,0,0,0,0,0
0,0,0,0,0,0,0,0,0,0,0,0,0,0,0,0,0,0,0
0,0,0,0,0,0,0,0,0,0,0,0,0,0,0,0,0,0,0
0,0,0,0,0,0,0,0,0,0,0,0,0,0,0,0,0,0,0
0,0,0,0,0,0,0,0,0,0,0,0,0,0,0,0,0,0,0
0,0,0,0,0,0,0,0,0,0,0,0,0,0,0,0,0,0,0
0,0,0,0,0,0,0,0,0,0,0,0,0,0,0,0,0,0,0
0,0,0,0,0,0,0,0,0,0,0,0,0,0,0,0,0,0,0
0,0,0,0,0,0,0,0,0,0,0,0,0,0,0,0,0,0,0
0,0,0,0,0,0,0,0,0,0,0,0,0,0,0,0,0,0,0
:endlayer
layer: 28
0,0,0,0,0,0,0,0,0,0,0,0,0,0,0,0,0,0,0
0,0,0,0,0,0,0,0,0,0,0,0,0,0,0,0,0,0,0
0,0,0,0,0,57,0,0,0,0,0,0,0,0,0,0,0,0,0
0,0,0,0,57,57,57,0,0,0,0,0,0,0,0,0,0,0,0
0,0,0,57,57,10,57,57,0,0,0,0,0,0,0,0,0,0,0
0,0,0,0,57,57,57,0,47,50,0,0,0,0,0,0,0,0,0
0,0,0,0,0,57,0,12,10,10,13,0,0,0,0,0,0,0,0
0,0,0,0,0,0,0,12,10,10,13,0,0,0,0,0,0,0,0
0,0,0,0,0,0,0,0,14,14,0,0,0,0,0,0,0,0,0
0,0,0,0,0,0,0,0,0,0,0,0,0,0,0,0,0,0,0
0,0,0,0,0,0,0,0,0,0,0,0,0,0,0,0,0,0,0
0,0,0,0,0,0,0,0,0,0,0,0,0,0,0,0,0,0,0
0,0,0,0,0,0,0,0,0,0,0,0,0,0,0,0,0,0,0
0,0,0,0,0,0,0,0,0,0,0,0,0,0,0,0,0,0,0
0,0,0,0,0,0,0,0,0,0,0,0,0,0,0,0,0,0,0
0,0,0,0,0,0,0,0,0,0,0,0,0,0,0,0,0,0,0
0,0,0,0,0,0,0,0,0,0,0,0,0,0,0,0,0,0,0
0,0,0,0,0,0,0,0,0,0,0,0,0,0,0,0,0,0,0
0,0,0,0,0,0,0,0,0,0,0,0,0,0,0,0,0,0,0
0,0,0,0,0,0,0,0,0,0,0,0,0,0,0,0,0,0,0
0,0,0,0,0,0,0,0,0,0,0,0,0,0,0,0,0,0,0
0,0,0,0,0,0,0,0,0,0,0,0,0,0,0,0,0,0,0
0,0,0,0,0,0,0,0,0,0,0,0,0,0,0,0,0,0,0
:endlayer
layer: 29
0,0,0,0,0,0,0,0,0,0,0,0,0,0,0,0,0,0,0
0,0,0,0,0,0,0,0,0,0,0,0,0,0,0,0,0,0,0
0,0,0,0,0,0,0,0,0,0,0,0,0,0,0,0,0,0,0
0,0,0,0,0,57,0,0,0,0,0,0,0,0,0,0,0,0,0
0,0,0,0,57,57,57,0,0,0,0,0,0,0,0,0,0,0,0
0,0,0,0,0,57,0,0,47,50,0,0,0,0,0,0,0,0,0
0,0,0,0,0,0,0,12,10,10,10,0,0,0,0,0,0,0,0
0,0,0,0,0,0,0,12,10,10,13,0,0,0,0,0,0,0,0
0,0,0,0,0,0,0,0,14,14,0,0,0,0,0,0,0,0,0
0,0,0,0,0,0,0,0,0,0,0,0,0,0,0,0,0,0,0
0,0,0,0,0,0,0,0,0,0,0,0,0,0,0,0,0,0,0
0,0,0,0,0,0,0,0,0,0,0,0,0,0,0,0,0,0,0
0,0,0,0,0,0,0,0,0,0,0,0,0,0,0,0,0,0,0
0,0,0,0,0,0,0,0,0,0,0,0,0,0,0,0,0,0,0
0,0,0,0,0,0,0,0,0,0,0,0,0,0,0,0,0,0,0
0,0,0,0,0,0,0,0,0,0,0,0,0,0,0,0,0,0,0
0,0,0,0,0,0,0,0,0,0,0,0,0,0,0,0,0,0,0
0,0,0,0,0,0,0,0,0,0,0,0,0,0,0,0,0,0,0
0,0,0,0,0,0,0,0,0,0,0,0,0,0,0,0,0,0,0
0,0,0,0,0,0,0,0,0,0,0,0,0,0,0,0,0,0,0
0,0,0,0,0,0,0,0,0,0,0,0,0,0,0,0,0,0,0
0,0,0,0,0,0,0,0,0,0,0,0,0,0,0,0,0,0,0
0,0,0,0,0,0,0,0,0,0,0,0,0,0,0,0,0,0,0
:endlayer
layer: 30
0,0,0,0,0,0,0,0,0,0,0,0,0,0,0,0,0,0,0
0,0,0,0,0,0,0,0,0,0,0,0,0,0,0,0,0,0,0
0,0,0,0,0,0,0,0,0,0,0,0,0,0,0,0,0,0,0
0,0,0,0,0,0,0,0,0,0,0,0,0,0,0,0,0,0,0
0,0,0,0,0,0,0,0,0,0,0,57,0,0,0,0,0,0,0
0,0,0,0,0,0,0,0,47,50,57,57,57,0,0,0,0,0,0
0,0,0,0,0,0,0,12,10,10,57,10,57,57,0,0,0,0,0
0,0,0,0,0,0,0,12,10,10,57,57,57,0,0,0,0,0,0
0,0,0,0,0,0,0,0,14,14,0,57,0,0,0,0,0,0,0
0,0,0,0,0,0,0,0,0,0,0,0,0,0,0,0,0,0,0
0,0,0,0,0,0,0,0,0,0,0,0,0,0,0,0,0,0,0
0,0,0,0,0,0,0,0,0,0,0,0,0,0,0,0,0,0,0
0,0,0,0,0,0,0,0,0,0,0,0,0,0,0,0,0,0,0
0,0,0,0,0,0,0,0,0,0,0,0,0,0,0,0,0,0,0
0,0,0,0,0,0,0,0,0,0,0,0,0,0,0,0,0,0,0
0,0,0,0,0,0,0,0,0,0,0,0,0,0,0,0,0,0,0
0,0,0,0,0,0,0,0,0,0,0,0,0,0,0,0,0,0,0
0,0,0,0,0,0,0,0,0,0,0,0,0,0,0,0,0,0,0
0,0,0,0,0,0,0,0,0,0,0,0,0,0,0,0,0,0,0
0,0,0,0,0,0,0,0,0,0,0,0,0,0,0,0,0,0,0
0,0,0,0,0,0,0,0,0,0,0,0,0,0,0,0,0,0,0
0,0,0,0,0,0,0,0,0,0,0,0,0,0,0,0,0,0,0
0,0,0,0,0,0,0,0,0,0,0,0,0,0,0,0,0,0,0
:endlayer
layer: 31
0,0,0,0,0,0,0,0,0,0,0,0,0,0,0,0,0,0,0
0,0,0,0,0,0,0,0,0,0,0,0,0,0,0,0,0,0,0
0,0,0,0,0,0,0,0,0,0,0,0,0,0,0,0,0,0,0
0,0,0,0,0,0,0,0,0,0,0,0,0,0,0,0,0,0,0
0,0,0,0,0,0,0,0,0,0,0,0,0,0,0,0,0,0,0
0,0,0,0,0,0,0,0,47,50,0,57,0,0,0,0,0,0,0
0,0,0,0,0,0,0,12,10,10,57,57,57,0,0,0,0,0,0
0,0,0,0,0,0,0,12,10,10,0,57,0,0,0,0,0,0,0
0,0,0,0,0,0,0,0,14,14,0,0,0,0,0,0,0,0,0
0,0,0,0,0,0,0,0,0,0,0,0,0,0,0,0,0,0,0
0,0,0,0,0,0,0,0,0,0,0,0,0,0,0,0,0,0,0
0,0,0,0,0,0,0,0,0,0,0,0,0,0,0,0,0,0,0
0,0,0,0,0,0,0,0,0,0,0,0,0,0,0,0,0,0,0
0,0,0,0,0,0,0,0,0,0,0,0,0,0,0,0,0,0,0
0,0,0,0,0,0,0,0,0,0,0,0,0,0,0,0,0,0,0
0,0,0,0,0,0,0,0,0,0,0,0,0,0,0,0,0,0,0
0,0,0,0,0,0,0,0,0,0,0,0,0,0,0,0,0,0,0
0,0,0,0,0,0,0,0,0,0,0,0,0,0,0,0,0,0,0
0,0,0,0,0,0,0,0,0,0,0,0,0,0,0,0,0,0,0
0,0,0,0,0,0,0,0,0,0,0,0,0,0,0,0,0,0,0
0,0,0,0,0,0,0,0,0,0,0,0,0,0,0,0,0,0,0
0,0,0,0,0,0,0,0,0,0,0,0,0,0,0,0,0,0,0
0,0,0,0,0,0,0,0,0,0,0,0,0,0,0,0,0,0,0
:endlayer
layer: 32
0,0,0,0,0,0,0,0,0,0,0,0,0,0,0,0,0,0,0
0,0,0,0,0,0,0,0,0,0,0,0,0,0,0,0,0,0,0
0,0,0,0,0,0,0,0,0,0,0,0,0,0,0,0,0,0,0
0,0,0,0,0,0,0,0,0,0,0,0,0,0,0,0,0,0,0
0,0,0,0,0,0,0,0,0,0,0,0,0,0,0,0,0,0,0
0,0,0,0,0,0,0,0,47,50,0,0,0,0,0,0,0,0,0
0,0,0,0,0,0,0,12,10,10,13,0,0,0,0,0,0,0,0
0,0,0,0,0,0,0,12,10,10,0,0,0,0,0,0,0,0,0
0,0,0,0,0,0,0,0,14,14,0,0,0,0,0,0,0,0,0
0,0,0,0,0,0,0,0,0,0,0,0,0,0,0,0,0,0,0
0,0,0,0,0,0,0,0,0,0,0,0,0,0,0,0,0,0,0
0,0,0,0,0,0,0,0,0,0,0,0,0,0,0,0,0,0,0
0,0,0,0,0,0,0,0,0,0,0,0,0,0,0,0,0,0,0
0,0,0,0,0,0,0,0,0,0,0,0,0,0,0,0,0,0,0
0,0,0,0,0,0,0,0,0,0,0,0,0,0,0,0,0,0,0
0,0,0,0,0,0,0,0,0,0,0,0,0,0,0,0,0,0,0
0,0,0,0,0,0,0,0,0,0,0,0,0,0,0,0,0,0,0
0,0,0,0,0,0,0,0,0,0,0,0,0,0,0,0,0,0,0
0,0,0,0,0,0,0,0,0,0,0,0,0,0,0,0,0,0,0
0,0,0,0,0,0,0,0,0,0,0,0,0,0,0,0,0,0,0
0,0,0,0,0,0,0,0,0,0,0,0,0,0,0,0,0,0,0
0,0,0,0,0,0,0,0,0,0,0,0,0,0,0,0,0,0,0
0,0,0,0,0,0,0,0,0,0,0,0,0,0,0,0,0,0,0
:endlayer
layer: 33
0,0,0,0,0,0,0,0,0,0,0,0,0,0,0,0,0,0,0
0,0,0,0,0,0,0,0,0,0,0,0,0,0,0,0,0,0,0
0,0,0,0,0,0,0,0,0,0,0,0,0,0,0,0,0,0,0
0,0,0,0,0,0,0,0,0,0,0,0,0,0,0,0,0,0,0
0,0,0,0,0,0,0,16,16,16,16,16,0,0,0,0,0,0,0
0,0,0,0,0,0,0,16,16,50,16,16,16,0,0,0,0,0,0
0,0,0,0,0,0,16,16,10,10,16,16,16,0,0,0,0,0,0
0,0,0,0,0,0,16,16,10,10,16,16,16,0,0,0,0,0,0
0,0,0,0,0,0,16,16,16,16,16,16,0,0,0,0,0,0,0
0,0,0,0,0,0,0,16,16,16,16,0,0,0,0,0,0,0,0
0,0,0,0,0,0,0,0,0,0,0,0,0,0,0,0,0,0,0
0,0,0,0,0,0,0,0,0,0,0,0,0,0,0,0,0,0,0
0,0,0,0,0,0,0,0,0,0,0,0,0,0,0,0,0,0,0
0,0,0,0,0,0,0,0,0,0,0,0,0,0,0,0,0,0,0
0,0,0,0,0,0,0,0,0,0,0,0,0,0,0,0,0,0,0
0,0,0,0,0,0,0,0,0,0,0,0,0,0,0,0,0,0,0
0,0,0,0,0,0,0,0,0,0,0,0,0,0,0,0,0,0,0
0,0,0,0,0,0,0,0,0,0,0,0,0,0,0,0,0,0,0
0,0,0,0,0,0,0,0,0,0,0,0,0,0,0,0,0,0,0
0,0,0,0,0,0,0,0,0,0,0,0,0,0,0,0,0,0,0
0,0,0,0,0,0,0,0,0,0,0,0,0,0,0,0,0,0,0
0,0,0,0,0,0,0,0,0,0,0,0,0,0,0,0,0,0,0
0,0,0,0,0,0,0,0,0,0,0,0,0,0,0,0,0,0,0
:endlayer
layer: 34
0,0,0,0,0,0,0,0,0,0,0,0,0,0,0,0,0,0,0
0,0,0,0,0,0,0,0,0,0,0,0,0,0,0,0,0,0,0
0,0,0,0,0,0,0,0,0,0,0,0,0,0,0,0,0,0,0
0,0,0,0,0,0,0,0,0,0,0,0,0,0,0,0,0,0,0
0,0,0,0,0,0,0,0,0,0,0,0,0,0,0,0,0,0,0
0,0,0,0,0,0,0,0,47,50,0,0,0,0,0,0,0,0,0
0,0,0,0,0,0,0,12,10,10,10,0,0,0,0,0,0,0,0
0,0,0,0,0,0,0,12,10,10,13,0,0,0,0,0,0,0,0
0,0,0,0,0,0,0,0,14,14,0,0,0,0,0,0,0,0,0
0,0,0,0,0,0,0,0,0,0,0,0,0,0,0,0,0,0,0
0,0,0,0,0,0,0,0,0,0,0,0,0,0,0,0,0,0,0
0,0,0,0,0,0,0,0,0,0,0,0,0,0,0,0,0,0,0
0,0,0,0,0,0,0,0,0,0,0,0,0,0,0,0,0,0,0
0,0,0,0,0,0,0,0,0,0,0,0,0,0,0,0,0,0,0
0,0,0,0,0,0,0,0,0,0,0,0,0,0,0,0,0,0,0
0,0,0,0,0,0,0,0,0,0,0,0,0,0,0,0,0,0,0
0,0,0,0,0,0,0,0,0,0,0,0,0,0,0,0,0,0,0
0,0,0,0,0,0,0,0,0,0,0,0,0,0,0,0,0,0,0
0,0,0,0,0,0,0,0,0,0,0,0,0,0,0,0,0,0,0
0,0,0,0,0,0,0,0,0,0,0,0,0,0,0,0,0,0,0
0,0,0,0,0,0,0,0,0,0,0,0,0,0,0,0,0,0,0
0,0,0,0,0,0,0,0,0,0,0,0,0,0,0,0,0,0,0
0,0,0,0,0,0,0,0,0,0,0,0,0,0,0,0,0,0,0
:endlayer
layer: 35
0,0,0,0,0,0,0,0,0,0,0,0,0,0,0,0,0,0,0
0,0,0,0,0,0,0,0,0,0,0,0,0,0,0,0,0,0,0
0,0,0,0,0,0,0,0,0,0,0,0,0,0,0,0,0,0,0
0,0,0,0,0,0,0,0,0,0,0,0,0,0,0,0,0,0,0
0,0,0,0,0,0,0,0,0,0,57,0,0,0,0,0,0,0,0
0,0,0,0,0,0,0,0,47,50,57,0,0,0,0,0,0,0,0
0,0,0,0,0,0,0,12,10,10,57,0,0,0,0,0,0,0,0
0,0,0,0,0,0,0,12,10,10,13,0,0,0,0,0,0,0,0
0,0,0,0,0,0,0,0,14,14,0,0,0,0,0,0,0,0,0
0,0,0,0,0,0,0,0,0,0,0,0,0,0,0,0,0,0,0
0,0,0,0,0,0,0,0,0,0,0,0,0,0,0,0,0,0,0
0,0,0,0,0,0,0,0,0,0,0,0,0,0,0,0,0,0,0
0,0,0,0,0,0,0,0,0,0,0,0,0,0,0,0,0,0,0
0,0,0,0,0,0,0,0,0,0,0,0,0,0,0,0,0,0,0
0,0,0,0,0,0,0,0,0,0,0,0,0,0,0,0,0,0,0
0,0,0,0,0,0,0,0,0,0,0,0,0,0,0,0,0,0,0
0,0,0,0,0,0,0,0,0,0,0,0,0,0,0,0,0,0,0
0,0,0,0,0,0,0,0,0,0,0,0,0,0,0,0,0,0,0
0,0,0,0,0,0,0,0,0,0,0,0,0,0,0,0,0,0,0
0,0,0,0,0,0,0,0,0,0,0,0,0,0,0,0,0,0,0
0,0,0,0,0,0,0,0,0,0,0,0,0,0,0,0,0,0,0
0,0,0,0,0,0,0,0,0,0,0,0,0,0,0,0,0,0,0
0,0,0,0,0,0,0,0,0,0,0,0,0,0,0,0,0,0,0
:endlayer
layer: 36
0,0,0,0,0,0,0,0,0,0,0,0,0,0,0,0,0,0,0
0,0,0,0,0,0,0,0,0,0,0,0,0,0,0,0,0,0,0
0,0,0,0,0,0,0,0,0,0,0,0,0,0,0,0,0,0,0
0,0,0,0,0,0,0,0,0,0,0,0,0,0,0,0,0,0,0
0,0,0,0,0,0,0,0,0,0,0,0,0,0,0,0,0,0,0
0,0,0,0,0,0,0,0,47,47,57,57,0,0,0,0,0,0,0
0,0,0,0,0,0,0,12,10,10,13,0,0,0,0,0,0,0,0
0,0,0,0,0,0,0,12,10,10,13,0,0,0,0,0,0,0,0
0,0,0,0,0,0,0,0,14,14,0,0,0,0,0,0,0,0,0
0,0,0,0,0,0,0,0,0,0,0,0,0,0,0,0,0,0,0
0,0,0,0,0,0,0,0,0,0,0,0,0,0,0,0,0,0,0
0,0,0,0,0,0,0,0,0,0,0,0,0,0,0,0,0,0,0
0,0,0,0,0,0,0,0,0,0,0,0,0,0,0,0,0,0,0
0,0,0,0,0,0,0,0,0,0,0,0,0,0,0,0,0,0,0
0,0,0,0,0,0,0,0,0,0,0,0,0,0,0,0,0,0,0
0,0,0,0,0,0,0,0,0,0,0,0,0,0,0,0,0,0,0
0,0,0,0,0,0,0,0,0,0,0,0,0,0,0,0,0,0,0
0,0,0,0,0,0,0,0,0,0,0,0,0,0,0,0,0,0,0
0,0,0,0,0,0,0,0,0,0,0,0,0,0,0,0,0,0,0
0,0,0,0,0,0,0,0,0,0,0,0,0,0,0,0,0,0,0
0,0,0,0,0,0,0,0,0,0,0,0,0,0,0,0,0,0,0
0,0,0,0,0,0,0,0,0,0,0,0,0,0,0,0,0,0,0
0,0,0,0,0,0,0,0,0,0,0,0,0,0,0,0,0,0,0
:endlayer
layer: 37
0,0,0,0,0,0,0,0,0,0,0,0,0,0,0,0,0,0,0
0,0,0,0,0,0,0,0,0,0,0,0,0,0,0,0,0,0,0
0,0,0,0,0,0,0,0,0,0,0,0,0,0,0,0,0,0,0
0,0,0,0,0,0,0,0,0,0,0,0,0,0,0,0,0,0,0
0,0,0,0,0,0,0,0,0,0,0,0,0,0,0,0,0,0,0
0,0,0,0,0,0,0,0,47,47,0,0,0,0,0,0,0,0,0
0,0,0,0,0,0,0,12,10,10,13,0,0,0,0,0,0,0,0
0,0,0,0,0,0,0,12,10,10,13,0,0,0,0,0,0,0,0
0,0,0,0,0,0,0,0,14,14,0,0,0,0,0,0,0,0,0
0,0,0,0,0,0,0,0,0,0,0,0,0,0,0,0,0,0,0
0,0,0,0,0,0,0,0,0,0,0,0,0,0,0,0,0,0,0
0,0,0,0,0,0,0,0,0,0,0,0,0,0,0,0,0,0,0
0,0,0,0,0,0,0,0,0,0,0,0,0,0,0,0,0,0,0
0,0,0,0,0,0,0,0,0,0,0,0,0,0,0,0,0,0,0
0,0,0,0,0,0,0,0,0,0,0,0,0,0,0,0,0,0,0
0,0,0,0,0,0,0,0,0,0,0,0,0,0,0,0,0,0,0
0,0,0,0,0,0,0,0,0,0,0,0,0,0,0,0,0,0,0
0,0,0,0,0,0,0,0,0,0,0,0,0,0,0,0,0,0,0
0,0,0,0,0,0,0,0,0,0,0,0,0,0,0,0,0,0,0
0,0,0,0,0,0,0,0,0,0,0,0,0,0,0,0,0,0,0
0,0,0,0,0,0,0,0,0,0,0,0,0,0,0,0,0,0,0
0,0,0,0,0,0,0,0,0,0,0,0,0,0,0,0,0,0,0
0,0,0,0,0,0,0,0,0,0,0,0,0,0,0,0,0,0,0
:endlayer
layer: 38
0,0,0,0,0,0,0,0,0,0,0,0,0,0,0,0,0,0,0
0,0,0,0,0,0,0,0,0,0,0,0,0,0,0,0,0,0,0
0,0,0,0,0,0,0,0,57,57,0,0,0,0,0,0,0,0,0
0,0,0,0,0,0,0,57,57,57,57,0,0,0,0,0,0,0,0
0,0,0,0,0,0,57,57,57,57,57,57,0,0,0,0,0,0,0
0,0,0,0,0,57,57,57,57,57,57,57,57,0,0,0,0,0,0
0,0,0,0,57,57,57,57,10,10,57,57,57,57,0,0,0,0,0
0,0,0,0,57,57,57,57,10,10,57,57,57,57,0,0,0,0,0
0,0,0,0,0,57,57,57,57,57,57,57,57,0,0,0,0,0,0
0,0,0,0,0,0,57,57,57,57,57,57,0,0,0,0,0,0,0
0,0,0,0,0,0,0,57,57,57,57,0,0,0,0,0,0,0,0
0,0,0,0,0,0,0,0,57,57,0,0,0,0,0,0,0,0,0
0,0,0,0,0,0,0,0,0,0,0,0,0,0,0,0,0,0,0
0,0,0,0,0,0,0,0,0,0,0,0,0,0,0,0,0,0,0
0,0,0,0,0,0,0,0,0,0,0,0,0,0,0,0,0,0,0
0,0,0,0,0,0,0,0,0,0,0,0,0,0,0,0,0,0,0
0,0,0,0,0,0,0,0,0,0,0,0,0,0,0,0,0,0,0
0,0,0,0,0,0,0,0,0,0,0,0,0,0,0,0,0,0,0
0,0,0,0,0,0,0,0,0,0,0,0,0,0,0,0,0,0,0
0,0,0,0,0,0,0,0,0,0,0,0,0,0,0,0,0,0,0
0,0,0,0,0,0,0,0,0,0,0,0,0,0,0,0,0,0,0
0,0,0,0,0,0,0,0,0,0,0,0,0,0,0,0,0,0,0
0,0,0,0,0,0,0,0,0,0,0,0,0,0,0,0,0,0,0
:endlayer
layer: 39
0,0,0,0,0,0,0,0,0,0,0,0,0,0,0,0,0,0,0
0,0,0,0,0,0,0,0,0,0,0,0,0,0,0,0,0,0,0
0,0,0,0,0,0,0,0,0,0,0,0,0,0,0,0,0,0,0
0,0,0,0,0,0,0,0,57,57,0,0,0,0,0,0,0,0,0
0,0,0,0,0,0,0,57,57,57,57,0,0,0,0,0,0,0,0
0,0,0,0,0,0,57,57,57,57,57,57,0,0,0,0,0,0,0
0,0,0,0,0,57,57,57,57,57,57,57,57,0,0,0,0,0,0
0,0,0,0,0,57,57,57,57,10,57,57,57,57,0,0,0,0,0
0,0,0,0,0,0,57,57,57,57,57,57,57,0,0,0,0,0,0
0,0,0,0,0,0,0,57,57,57,57,57,0,0,0,0,0,0,0
0,0,0,0,0,0,0,0,57,57,57,0,0,0,0,0,0,0,0
0,0,0,0,0,0,0,0,0,57,0,0,0,0,0,0,0,0,0
0,0,0,0,0,0,0,0,0,0,0,0,0,0,0,0,0,0,0
0,0,0,0,0,0,0,0,0,0,0,0,0,0,0,0,0,0,0
0,0,0,0,0,0,0,0,0,0,0,0,0,0,0,0,0,0,0
0,0,0,0,0,0,0,0,0,0,0,0,0,0,0,0,0,0,0
0,0,0,0,0,0,0,0,0,0,0,0,0,0,0,0,0,0,0
0,0,0,0,0,0,0,0,0,0,0,0,0,0,0,0,0,0,0
0,0,0,0,0,0,0,0,0,0,0,0,0,0,0,0,0,0,0
0,0,0,0,0,0,0,0,0,0,0,0,0,0,0,0,0,0,0
0,0,0,0,0,0,0,0,0,0,0,0,0,0,0,0,0,0,0
0,0,0,0,0,0,0,0,0,0,0,0,0,0,0,0,0,0,0
0,0,0,0,0,0,0,0,0,0,0,0,0,0,0,0,0,0,0
:endlayer
layer: 40
0,0,0,0,0,0,0,0,0,0,0,0,0,0,0,0,0,0,0
0,0,0,0,0,0,0,0,0,0,0,0,0,0,0,0,0,0,0
0,0,0,0,0,0,0,0,0,0,0,0,0,0,0,0,0,0,0
0,0,0,0,0,0,0,0,0,0,0,0,0,0,0,0,0,0,0
0,0,0,0,0,0,0,0,57,57,0,0,0,0,0,0,0,0,0
0,0,0,0,0,0,0,57,57,57,57,0,0,0,0,0,0,0,0
0,0,0,0,0,0,57,57,57,57,57,57,0,0,0,0,0,0,0
0,0,0,0,0,0,57,57,57,57,57,57,57,0,0,0,0,0,0
0,0,0,0,0,0,0,57,57,57,57,57,0,0,0,0,0,0,0
0,0,0,0,0,0,0,0,57,57,57,0,0,0,0,0,0,0,0
0,0,0,0,0,0,0,0,0,57,0,0,0,0,0,0,0,0,0
0,0,0,0,0,0,0,0,0,0,0,0,0,0,0,0,0,0,0
0,0,0,0,0,0,0,0,0,0,0,0,0,0,0,0,0,0,0
0,0,0,0,0,0,0,0,0,0,0,0,0,0,0,0,0,0,0
0,0,0,0,0,0,0,0,0,0,0,0,0,0,0,0,0,0,0
0,0,0,0,0,0,0,0,0,0,0,0,0,0,0,0,0,0,0
0,0,0,0,0,0,0,0,0,0,0,0,0,0,0,0,0,0,0
0,0,0,0,0,0,0,0,0,0,0,0,0,0,0,0,0,0,0
0,0,0,0,0,0,0,0,0,0,0,0,0,0,0,0,0,0,0
0,0,0,0,0,0,0,0,0,0,0,0,0,0,0,0,0,0,0
0,0,0,0,0,0,0,0,0,0,0,0,0,0,0,0,0,0,0
0,0,0,0,0,0,0,0,0,0,0,0,0,0,0,0,0,0,0
0,0,0,0,0,0,0,0,0,0,0,0,0,0,0,0,0,0,0
:endlayer
layer: 41
0,0,0,0,0,0,0,0,0,0,0,0,0,0,0,0,0,0,0
0,0,0,0,0,0,0,0,0,0,0,0,0,0,0,0,0,0,0
0,0,0,0,0,0,0,0,0,0,0,0,0,0,0,0,0,0,0
0,0,0,0,0,0,0,0,0,0,0,0,0,0,0,0,0,0,0
0,0,0,0,0,0,0,0,0,0,0,0,0,0,0,0,0,0,0
0,0,0,0,0,0,0,0,0,0,0,0,0,0,0,0,0,0,0
0,0,0,0,0,0,0,0,0,0,0,0,0,0,0,0,0,0,0
0,0,0,0,0,0,0,0,0,0,0,0,0,0,0,0,0,0,0
0,0,0,0,0,0,0,0,0,0,0,0,0,0,0,0,0,0,0
0,0,0,0,0,0,0,0,0,0,0,0,0,0,0,0,0,0,0
0,0,0,0,0,0,0,0,0,0,0,0,0,0,0,0,0,0,0
0,0,0,0,0,0,0,0,0,0,0,0,0,0,0,0,0,0,0
0,0,0,0,0,0,0,0,0,0,0,0,0,0,0,0,0,0,0
0,0,0,0,0,0,0,0,0,0,0,0,0,0,0,0,0,0,0
0,0,0,0,0,0,0,0,0,0,0,0,0,0,0,0,0,0,0
0,0,0,0,0,0,0,0,0,0,0,0,0,0,0,0,0,0,0
0,0,0,0,0,0,0,0,0,0,0,0,0,0,0,0,0,0,0
0,0,0,0,0,0,0,0,0,0,0,0,0,0,0,0,0,0,0
0,0,0,0,0,0,0,0,0,0,0,0,0,0,0,0,0,0,0
0,0,0,0,0,0,0,0,0,0,0,0,0,0,0,0,0,0,0
0,0,0,0,0,0,0,0,0,0,0,0,0,0,0,0,0,0,0
0,0,0,0,0,0,0,0,0,0,0,0,0,0,0,0,0,0,0
0,0,0,0,0,0,0,0,0,0,0,0,0,0,0,0,0,0,0
:endlayer
layer: 42
0,0,0,0,0,0,0,0,0,0,0,0,0,0,0,0,0,0,0
0,0,0,0,0,0,0,0,0,0,0,0,0,0,0,0,0,0,0
0,0,0,0,0,0,0,0,0,0,0,0,0,0,0,0,0,0,0
0,0,0,0,0,0,0,0,0,0,0,0,0,0,0,0,0,0,0
0,0,0,0,0,0,0,0,0,0,0,0,0,0,0,0,0,0,0
0,0,0,0,0,0,0,0,0,0,0,0,0,0,0,0,0,0,0
0,0,0,0,0,0,0,0,0,0,0,0,0,0,0,0,0,0,0
0,0,0,0,0,0,0,0,0,0,0,0,0,0,0,0,0,0,0
0,0,0,0,0,0,0,0,0,0,0,0,0,0,0,0,0,0,0
0,0,0,0,0,0,0,0,0,0,0,0,0,0,0,0,0,0,0
0,0,0,0,0,0,0,0,0,0,0,0,0,0,0,0,0,0,0
0,0,0,0,0,0,0,0,0,0,0,0,0,0,0,0,0,0,0
0,0,0,0,0,0,0,0,0,0,0,0,0,0,0,0,0,0,0
0,0,0,0,0,0,0,0,0,0,0,0,0,0,0,0,0,0,0
0,0,0,0,0,0,0,0,0,0,0,0,0,0,0,0,0,0,0
0,0,0,0,0,0,0,0,0,0,0,0,0,0,0,0,0,0,0
0,0,0,0,0,0,0,0,0,0,0,0,0,0,0,0,0,0,0
0,0,0,0,0,0,0,0,0,0,0,0,0,0,0,0,0,0,0
0,0,0,0,0,0,0,0,0,0,0,0,0,0,0,0,0,0,0
0,0,0,0,0,0,0,0,0,0,0,0,0,0,0,0,0,0,0
0,0,0,0,0,0,0,0,0,0,0,0,0,0,0,0,0,0,0
0,0,0,0,0,0,0,0,0,0,0,0,0,0,0,0,0,0,0
0,0,0,0,0,0,0,0,0,0,0,0,0,0,0,0,0,0,0
:endlayer
layer: 43
0,0,0,0,0,0,0,0,0,0,0,0,0,0,0,0,0,0,0
0,0,0,0,0,0,0,0,0,0,0,0,0,0,0,0,0,0,0
0,0,0,0,0,0,0,0,0,0,0,0,0,0,0,0,0,0,0
0,0,0,0,0,0,0,0,0,0,0,0,0,0,0,0,0,0,0
0,0,0,0,0,0,0,0,0,0,0,0,0,0,0,0,0,0,0
0,0,0,0,0,0,0,0,0,0,0,0,0,0,0,0,0,0,0
0,0,0,0,0,0,0,0,0,0,0,0,0,0,0,0,0,0,0
0,0,0,0,0,0,0,0,0,0,0,0,0,0,0,0,0,0,0
0,0,0,0,0,0,0,0,0,0,0,0,0,0,0,0,0,0,0
0,0,0,0,0,0,0,0,0,0,0,0,0,0,0,0,0,0,0
0,0,0,0,0,0,0,0,0,0,0,0,0,0,0,0,0,0,0
0,0,0,0,0,0,0,0,0,0,0,0,0,0,0,0,0,0,0
0,0,0,0,0,0,0,0,0,0,0,0,0,0,0,0,0,0,0
0,0,0,0,0,0,0,0,0,0,0,0,0,0,0,0,0,0,0
0,0,0,0,0,0,0,0,0,0,0,0,0,0,0,0,0,0,0
0,0,0,0,0,0,0,0,0,0,0,0,0,0,0,0,0,0,0
0,0,0,0,0,0,0,0,0,0,0,0,0,0,0,0,0,0,0
0,0,0,0,0,0,0,0,0,0,0,0,0,0,0,0,0,0,0
0,0,0,0,0,0,0,0,0,0,0,0,0,0,0,0,0,0,0
0,0,0,0,0,0,0,0,0,0,0,0,0,0,0,0,0,0,0
0,0,0,0,0,0,0,0,0,0,0,0,0,0,0,0,0,0,0
0,0,0,0,0,0,0,0,0,0,0,0,0,0,0,0,0,0,0
0,0,0,0,0,0,0,0,0,0,0,0,0,0,0,0,0,0,0
:endlayer
layer: 44
0,0,0,0,0,0,0,0,0,0,0,0,0,0,0,0,0,0,0
0,0,0,0,0,0,0,0,0,0,0,0,0,0,0,0,0,0,0
0,0,0,0,0,0,0,0,0,0,0,0,0,0,0,0,0,0,0
0,0,0,0,0,0,0,0,0,0,0,0,0,0,0,0,0,0,0
0,0,0,0,0,0,0,0,0,0,0,0,0,0,0,0,0,0,0
0,0,0,0,0,0,0,0,0,0,0,0,0,0,0,0,0,0,0
0,0,0,0,0,0,0,0,0,0,0,0,0,0,0,0,0,0,0
0,0,0,0,0,0,0,0,0,0,0,0,0,0,0,0,0,0,0
0,0,0,0,0,0,0,0,0,0,0,0,0,0,0,0,0,0,0
0,0,0,0,0,0,0,0,0,0,0,0,0,0,0,0,0,0,0
0,0,0,0,0,0,0,0,0,0,0,0,0,0,0,0,0,0,0
0,0,0,0,0,0,0,0,0,0,0,0,0,0,0,0,0,0,0
0,0,0,0,0,0,0,0,0,0,0,0,0,0,0,0,0,0,0
0,0,0,0,0,0,0,0,0,0,0,0,0,0,0,0,0,0,0
0,0,0,0,0,0,0,0,0,0,0,0,0,0,0,0,0,0,0
0,0,0,0,0,0,0,0,0,0,0,0,0,0,0,0,0,0,0
0,0,0,0,0,0,0,0,0,0,0,0,0,0,0,0,0,0,0
0,0,0,0,0,0,0,0,0,0,0,0,0,0,0,0,0,0,0
0,0,0,0,0,0,0,0,0,0,0,0,0,0,0,0,0,0,0
0,0,0,0,0,0,0,0,0,0,0,0,0,0,0,0,0,0,0
0,0,0,0,0,0,0,0,0,0,0,0,0,0,0,0,0,0,0
0,0,0,0,0,0,0,0,0,0,0,0,0,0,0,0,0,0,0
0,0,0,0,0,0,0,0,0,0,0,0,0,0,0,0,0,0,0
:endlayer
layer: 45
0,0,0,0,0,0,0,0,0,0,0,0,0,0,0,0,0,0,0
0,0,0,0,0,0,0,0,0,0,0,0,0,0,0,0,0,0,0
0,0,0,0,0,0,0,0,0,0,0,0,0,0,0,0,0,0,0
0,0,0,0,0,0,0,0,0,0,0,0,0,0,0,0,0,0,0
0,0,0,0,0,0,0,0,0,0,0,0,0,0,0,0,0,0,0
0,0,0,0,0,0,0,0,0,0,0,0,0,0,0,0,0,0,0
0,0,0,0,0,0,0,0,0,0,0,0,0,0,0,0,0,0,0
0,0,0,0,0,0,0,0,0,0,0,0,0,0,0,0,0,0,0
0,0,0,0,0,0,0,0,0,0,0,0,0,0,0,0,0,0,0
0,0,0,0,0,0,0,0,0,0,0,0,0,0,0,0,0,0,0
0,0,0,0,0,0,0,0,0,0,0,0,0,0,0,0,0,0,0
0,0,0,0,0,0,0,0,0,0,0,0,0,0,0,0,0,0,0
0,0,0,0,0,0,0,0,0,0,0,0,0,0,0,0,0,0,0
0,0,0,0,0,0,0,0,0,0,0,0,0,0,0,0,0,0,0
0,0,0,0,0,0,0,0,0,0,0,0,0,0,0,0,0,0,0
0,0,0,0,0,0,0,0,0,0,0,0,0,0,0,0,0,0,0
0,0,0,0,0,0,0,0,0,0,0,0,0,0,0,0,0,0,0
0,0,0,0,0,0,0,0,0,0,0,0,0,0,0,0,0,0,0
0,0,0,0,0,0,0,0,0,0,0,0,0,0,0,0,0,0,0
0,0,0,0,0,0,0,0,0,0,0,0,0,0,0,0,0,0,0
0,0,0,0,0,0,0,0,0,0,0,0,0,0,0,0,0,0,0
0,0,0,0,0,0,0,0,0,0,0,0,0,0,0,0,0,0,0
0,0,0,0,0,0,0,0,0,0,0,0,0,0,0,0,0,0,0
:endlayer
layer: 46
0,0,0,0,0,0,0,0,0,0,0,0,0,0,0,0,0,0,0
0,0,0,0,0,0,0,0,0,0,0,0,0,0,0,0,0,0,0
0,0,0,0,0,0,0,0,0,0,0,0,0,0,0,0,0,0,0
0,0,0,0,0,0,0,0,0,0,0,0,0,0,0,0,0,0,0
0,0,0,0,0,0,0,0,0,0,0,0,0,0,0,0,0,0,0
0,0,0,0,0,0,0,0,0,0,0,0,0,0,0,0,0,0,0
0,0,0,0,0,0,0,0,0,0,0,0,0,0,0,0,0,0,0
0,0,0,0,0,0,0,0,0,0,0,0,0,0,0,0,0,0,0
0,0,0,0,0,0,0,0,0,0,0,0,0,0,0,0,0,0,0
0,0,0,0,0,0,0,0,0,0,0,0,0,0,0,0,0,0,0
0,0,0,0,0,0,0,0,0,0,0,0,0,0,0,0,0,0,0
0,0,0,0,0,0,0,0,0,0,0,0,0,0,0,0,0,0,0
0,0,0,0,0,0,0,0,0,0,0,0,0,0,0,0,0,0,0
0,0,0,0,0,0,0,0,0,0,0,0,0,0,0,0,0,0,0
0,0,0,0,0,0,0,0,0,0,0,0,0,0,0,0,0,0,0
0,0,0,0,0,0,0,0,0,0,0,0,0,0,0,0,0,0,0
0,0,0,0,0,0,0,0,0,0,0,0,0,0,0,0,0,0,0
0,0,0,0,0,0,0,0,0,0,0,0,0,0,0,0,0,0,0
0,0,0,0,0,0,0,0,0,0,0,0,0,0,0,0,0,0,0
0,0,0,0,0,0,0,0,0,0,0,0,0,0,0,0,0,0,0
0,0,0,0,0,0,0,0,0,0,0,0,0,0,0,0,0,0,0
0,0,0,0,0,0,0,0,0,0,0,0,0,0,0,0,0,0,0
0,0,0,0,0,0,0,0,0,0,0,0,0,0,0,0,0,0,0
:endlayer
layer: 47
0,0,0,0,0,0,0,0,0,0,0,0,0,0,0,0,0,0,0
0,0,0,0,0,0,0,0,0,0,0,0,0,0,0,0,0,0,0
0,0,0,0,0,0,0,0,0,0,0,0,0,0,0,0,0,0,0
0,0,0,0,0,0,0,0,0,0,0,0,0,0,0,0,0,0,0
0,0,0,0,0,0,0,0,0,0,0,0,0,0,0,0,0,0,0
0,0,0,0,0,0,0,0,0,0,0,0,0,0,0,0,0,0,0
0,0,0,0,0,0,0,0,0,0,0,0,0,0,0,0,0,0,0
0,0,0,0,0,0,0,0,0,0,0,0,0,0,0,0,0,0,0
0,0,0,0,0,0,0,0,0,0,0,0,0,0,0,0,0,0,0
0,0,0,0,0,0,0,0,0,0,0,0,0,0,0,0,0,0,0
0,0,0,0,0,0,0,0,0,0,0,0,0,0,0,0,0,0,0
0,0,0,0,0,0,0,0,0,0,0,0,0,0,0,0,0,0,0
0,0,0,0,0,0,0,0,0,0,0,0,0,0,0,0,0,0,0
0,0,0,0,0,0,0,0,0,0,0,0,0,0,0,0,0,0,0
0,0,0,0,0,0,0,0,0,0,0,0,0,0,0,0,0,0,0
0,0,0,0,0,0,0,0,0,0,0,0,0,0,0,0,0,0,0
0,0,0,0,0,0,0,0,0,0,0,0,0,0,0,0,0,0,0
0,0,0,0,0,0,0,0,0,0,0,0,0,0,0,0,0,0,0
0,0,0,0,0,0,0,0,0,0,0,0,0,0,0,0,0,0,0
0,0,0,0,0,0,0,0,0,0,0,0,0,0,0,0,0,0,0
0,0,0,0,0,0,0,0,0,0,0,0,0,0,0,0,0,0,0
0,0,0,0,0,0,0,0,0,0,0,0,0,0,0,0,0,0,0
0,0,0,0,0,0,0,0,0,0,0,0,0,0,0,0,0,0,0
:endlayer
layer: 48
0,0,0,0,0,0,0,0,0,0,0,0,0,0,0,0,0,0,0
0,0,0,0,0,0,0,0,0,0,0,0,0,0,0,0,0,0,0
0,0,0,0,0,0,0,0,0,0,0,0,0,0,0,0,0,0,0
0,0,0,0,0,0,0,0,0,0,0,0,0,0,0,0,0,0,0
0,0,0,0,0,0,0,0,0,0,0,0,0,0,0,0,0,0,0
0,0,0,0,0,0,0,0,0,0,0,0,0,0,0,0,0,0,0
0,0,0,0,0,0,0,0,0,0,0,0,0,0,0,0,0,0,0
0,0,0,0,0,0,0,0,0,0,0,0,0,0,0,0,0,0,0
0,0,0,0,0,0,0,0,0,0,0,0,0,0,0,0,0,0,0
0,0,0,0,0,0,0,0,0,0,0,0,0,0,0,0,0,0,0
0,0,0,0,0,0,0,0,0,0,0,0,0,0,0,0,0,0,0
0,0,0,0,0,0,0,0,0,0,0,0,0,0,0,0,0,0,0
0,0,0,0,0,0,0,0,0,0,0,0,0,0,0,0,0,0,0
0,0,0,0,0,0,0,0,0,0,0,0,0,0,0,0,0,0,0
0,0,0,0,0,0,0,0,0,0,0,0,0,0,0,0,0,0,0
0,0,0,0,0,0,0,0,0,0,0,0,0,0,0,0,0,0,0
0,0,0,0,0,0,0,0,0,0,0,0,0,0,0,0,0,0,0
0,0,0,0,0,0,0,0,0,0,0,0,0,0,0,0,0,0,0
0,0,0,0,0,0,0,0,0,0,0,0,0,0,0,0,0,0,0
0,0,0,0,0,0,0,0,0,0,0,0,0,0,0,0,0,0,0
0,0,0,0,0,0,0,0,0,0,0,0,0,0,0,0,0,0,0
0,0,0,0,0,0,0,0,0,0,0,0,0,0,0,0,0,0,0
0,0,0,0,0,0,0,0,0,0,0,0,0,0,0,0,0,0,0
:endlayer
layer: 49
0,0,0,0,0,0,0,0,0,0,0,0,0,0,0,0,0,0,0
0,0,0,0,0,0,0,0,0,0,0,0,0,0,0,0,0,0,0
0,0,0,0,0,0,0,0,0,0,0,0,0,0,0,0,0,0,0
0,0,0,0,0,0,0,0,0,0,0,0,0,0,0,0,0,0,0
0,0,0,0,0,0,0,0,0,0,0,0,0,0,0,0,0,0,0
0,0,0,0,0,0,0,0,0,0,0,0,0,0,0,0,0,0,0
0,0,0,0,0,0,0,0,0,0,0,0,0,0,0,0,0,0,0
0,0,0,0,0,0,0,0,0,0,0,0,0,0,0,0,0,0,0
0,0,0,0,0,0,0,0,0,0,0,0,0,0,0,0,0,0,0
0,0,0,0,0,0,0,0,0,0,0,0,0,0,0,0,0,0,0
0,0,0,0,0,0,0,0,0,0,0,0,0,0,0,0,0,0,0
0,0,0,0,0,0,0,0,0,0,0,0,0,0,0,0,0,0,0
0,0,0,0,0,0,0,0,0,0,0,0,0,0,0,0,0,0,0
0,0,0,0,0,0,0,0,0,0,0,0,0,0,0,0,0,0,0
0,0,0,0,0,0,0,0,0,0,0,0,0,0,0,0,0,0,0
0,0,0,0,0,0,0,0,0,0,0,0,0,0,0,0,0,0,0
0,0,0,0,0,0,0,0,0,0,0,0,0,0,0,0,0,0,0
0,0,0,0,0,0,0,0,0,0,0,0,0,0,0,0,0,0,0
0,0,0,0,0,0,0,0,0,0,0,0,0,0,0,0,0,0,0
0,0,0,0,0,0,0,0,0,0,0,0,0,0,0,0,0,0,0
0,0,0,0,0,0,0,0,0,0,0,0,0,0,0,0,0,0,0
0,0,0,0,0,0,0,0,0,0,0,0,0,0,0,0,0,0,0
0,0,0,0,0,0,0,0,0,0,0,0,0,0,0,0,0,0,0
:endlayer
layer: 50
0,0,0,0,0,0,0,0,0,0,0,0,0,0,0,0,0,0,0
0,0,0,0,0,0,0,0,0,0,0,0,0,0,0,0,0,0,0
0,0,0,0,0,0,0,0,0,0,0,0,0,0,0,0,0,0,0
0,0,0,0,0,0,0,0,0,0,0,0,0,0,0,0,0,0,0
0,0,0,0,0,0,0,0,0,0,0,0,0,0,0,0,0,0,0
0,0,0,0,0,0,0,0,0,0,0,0,0,0,0,0,0,0,0
0,0,0,0,0,0,0,0,0,0,0,0,0,0,0,0,0,0,0
0,0,0,0,0,0,0,0,0,0,0,0,0,0,0,0,0,0,0
0,0,0,0,0,0,0,0,0,0,0,0,0,0,0,0,0,0,0
0,0,0,0,0,0,0,0,0,0,0,0,0,0,0,0,0,0,0
0,0,0,0,0,0,0,0,0,0,0,0,0,0,0,0,0,0,0
0,0,0,0,0,0,0,0,0,0,0,0,0,0,0,0,0,0,0
0,0,0,0,0,0,0,0,0,0,0,0,0,0,0,0,0,0,0
0,0,0,0,0,0,0,0,0,0,0,0,0,0,0,0,0,0,0
0,0,0,0,0,0,0,0,0,0,0,0,0,0,0,0,0,0,0
0,0,0,0,0,0,0,0,0,0,0,0,0,0,0,0,0,0,0
0,0,0,0,0,0,0,0,0,0,0,0,0,0,0,0,0,0,0
0,0,0,0,0,0,0,0,0,0,0,0,0,0,0,0,0,0,0
0,0,0,0,0,0,0,0,0,0,0,0,0,0,0,0,0,0,0
0,0,0,0,0,0,0,0,0,0,0,0,0,0,0,0,0,0,0
0,0,0,0,0,0,0,0,0,0,0,0,0,0,0,0,0,0,0
0,0,0,0,0,0,0,0,0,0,0,0,0,0,0,0,0,0,0
0,0,0,0,0,0,0,0,0,0,0,0,0,0,0,0,0,0,0
:endlayer
layer: 51
0,0,0,0,0,0,0,0,0,0,0,0,0,0,0,0,0,0,0
0,0,0,0,0,0,0,0,0,0,0,0,0,0,0,0,0,0,0
0,0,0,0,0,0,0,0,0,0,0,0,0,0,0,0,0,0,0
0,0,0,0,0,0,0,0,0,0,0,0,0,0,0,0,0,0,0
0,0,0,0,0,0,0,0,0,0,0,0,0,0,0,0,0,0,0
0,0,0,0,0,0,0,0,0,0,0,0,0,0,0,0,0,0,0
0,0,0,0,0,0,0,0,0,0,0,0,0,0,0,0,0,0,0
0,0,0,0,0,0,0,0,0,0,0,0,0,0,0,0,0,0,0
0,0,0,0,0,0,0,0,0,0,0,0,0,0,0,0,0,0,0
0,0,0,0,0,0,0,0,0,0,0,0,0,0,0,0,0,0,0
0,0,0,0,0,0,0,0,0,0,0,0,0,0,0,0,0,0,0
0,0,0,0,0,0,0,0,0,0,0,0,0,0,0,0,0,0,0
0,0,0,0,0,0,0,0,0,0,0,0,0,0,0,0,0,0,0
0,0,0,0,0,0,0,0,0,0,0,0,0,0,0,0,0,0,0
0,0,0,0,0,0,0,0,0,0,0,0,0,0,0,0,0,0,0
0,0,0,0,0,0,0,0,0,0,0,0,0,0,0,0,0,0,0
0,0,0,0,0,0,0,0,0,0,0,0,0,0,0,0,0,0,0
0,0,0,0,0,0,0,0,0,0,0,0,0,0,0,0,0,0,0
0,0,0,0,0,0,0,0,0,0,0,0,0,0,0,0,0,0,0
0,0,0,0,0,0,0,0,0,0,0,0,0,0,0,0,0,0,0
0,0,0,0,0,0,0,0,0,0,0,0,0,0,0,0,0,0,0
0,0,0,0,0,0,0,0,0,0,0,0,0,0,0,0,0,0,0
0,0,0,0,0,0,0,0,0,0,0,0,0,0,0,0,0,0,0
:endlayer
layer: 52
0,0,0,0,0,0,0,0,0,0,0,0,0,0,0,0,0,0,0
0,0,0,0,0,0,0,0,0,0,0,0,0,0,0,0,0,0,0
0,0,0,0,0,0,0,0,0,0,0,0,0,0,0,0,0,0,0
0,0,0,0,0,0,0,0,0,0,0,0,0,0,0,0,0,0,0
0,0,0,0,0,0,0,0,0,0,0,0,0,0,0,0,0,0,0
0,0,0,0,0,0,0,0,0,0,0,0,0,0,0,0,0,0,0
0,0,0,0,0,0,0,0,0,0,0,0,0,0,0,0,0,0,0
0,0,0,0,0,0,0,0,0,0,0,0,0,0,0,0,0,0,0
0,0,0,0,0,0,0,0,0,0,0,0,0,0,0,0,0,0,0
0,0,0,0,0,0,0,0,0,0,0,0,0,0,0,0,0,0,0
0,0,0,0,0,0,0,0,0,0,0,0,0,0,0,0,0,0,0
0,0,0,0,0,0,0,0,0,0,0,0,0,0,0,0,0,0,0
0,0,0,0,0,0,0,0,0,0,0,0,0,0,0,0,0,0,0
0,0,0,0,0,0,0,0,0,0,0,0,0,0,0,0,0,0,0
0,0,0,0,0,0,0,0,0,0,0,0,0,0,0,0,0,0,0
0,0,0,0,0,0,0,0,0,0,0,0,0,0,0,0,0,0,0
0,0,0,0,0,0,0,0,0,0,0,0,0,0,0,0,0,0,0
0,0,0,0,0,0,0,0,0,0,0,0,0,0,0,0,0,0,0
0,0,0,0,0,0,0,0,0,0,0,0,0,0,0,0,0,0,0
0,0,0,0,0,0,0,0,0,0,0,0,0,0,0,0,0,0,0
0,0,0,0,0,0,0,0,0,0,0,0,0,0,0,0,0,0,0
0,0,0,0,0,0,0,0,0,0,0,0,0,0,0,0,0,0,0
0,0,0,0,0,0,0,0,0,0,0,0,0,0,0,0,0,0,0
:endlayer
layer: 53
0,0,0,0,0,0,0,0,0,0,0,0,0,0,0,0,0,0,0
0,0,0,0,0,0,0,0,0,0,0,0,0,0,0,0,0,0,0
0,0,0,0,0,0,0,0,0,0,0,0,0,0,0,0,0,0,0
0,0,0,0,0,0,0,0,0,0,0,0,0,0,0,0,0,0,0
0,0,0,0,0,0,0,0,0,0,0,0,0,0,0,0,0,0,0
0,0,0,0,0,0,0,0,0,0,0,0,0,0,0,0,0,0,0
0,0,0,0,0,0,0,0,0,0,0,0,0,0,0,0,0,0,0
0,0,0,0,0,0,0,0,0,0,0,0,0,0,0,0,0,0,0
0,0,0,0,0,0,0,0,0,0,0,0,0,0,0,0,0,0,0
0,0,0,0,0,0,0,0,0,0,0,0,0,0,0,0,0,0,0
0,0,0,0,0,0,0,0,0,0,0,0,0,0,0,0,0,0,0
0,0,0,0,0,0,0,0,0,0,0,0,0,0,0,0,0,0,0
0,0,0,0,0,0,0,0,0,0,0,0,0,0,0,0,0,0,0
0,0,0,0,0,0,0,0,0,0,0,0,0,0,0,0,0,0,0
0,0,0,0,0,0,0,0,0,0,0,0,0,0,0,0,0,0,0
0,0,0,0,0,0,0,0,0,0,0,0,0,0,0,0,0,0,0
0,0,0,0,0,0,0,0,0,0,0,0,0,0,0,0,0,0,0
0,0,0,0,0,0,0,0,0,0,0,0,0,0,0,0,0,0,0
0,0,0,0,0,0,0,0,0,0,0,0,0,0,0,0,0,0,0
0,0,0,0,0,0,0,0,0,0,0,0,0,0,0,0,0,0,0
0,0,0,0,0,0,0,0,0,0,0,0,0,0,0,0,0,0,0
0,0,0,0,0,0,0,0,0,0,0,0,0,0,0,0,0,0,0
0,0,0,0,0,0,0,0,0,0,0,0,0,0,0,0,0,0,0
:endlayer
layer: 54
0,0,0,0,0,0,0,0,0,0,0,0,0,0,0,0,0,0,0
0,0,0,0,0,0,0,0,0,0,0,0,0,0,0,0,0,0,0
0,0,0,0,0,0,0,0,0,0,0,0,0,0,0,0,0,0,0
0,0,0,0,0,0,0,0,0,0,0,0,0,0,0,0,0,0,0
0,0,0,0,0,0,0,0,0,0,0,0,0,0,0,0,0,0,0
0,0,0,0,0,0,0,0,0,0,0,0,0,0,0,0,0,0,0
0,0,0,0,0,0,0,0,0,0,0,0,0,0,0,0,0,0,0
0,0,0,0,0,0,0,0,0,0,0,0,0,0,0,0,0,0,0
0,0,0,0,0,0,0,0,0,0,0,0,0,0,0,0,0,0,0
0,0,0,0,0,0,0,0,0,0,0,0,0,0,0,0,0,0,0
0,0,0,0,0,0,0,0,0,0,0,0,0,0,0,0,0,0,0
0,0,0,0,0,0,0,0,0,0,0,0,0,0,0,0,0,0,0
0,0,0,0,0,0,0,0,0,0,0,0,0,0,0,0,0,0,0
0,0,0,0,0,0,0,0,0,0,0,0,0,0,0,0,0,0,0
0,0,0,0,0,0,0,0,0,0,0,0,0,0,0,0,0,0,0
0,0,0,0,0,0,0,0,0,0,0,0,0,0,0,0,0,0,0
0,0,0,0,0,0,0,0,0,0,0,0,0,0,0,0,0,0,0
0,0,0,0,0,0,0,0,0,0,0,0,0,0,0,0,0,0,0
0,0,0,0,0,0,0,0,0,0,0,0,0,0,0,0,0,0,0
0,0,0,0,0,0,0,0,0,0,0,0,0,0,0,0,0,0,0
0,0,0,0,0,0,0,0,0,0,0,0,0,0,0,0,0,0,0
0,0,0,0,0,0,0,0,0,0,0,0,0,0,0,0,0,0,0
0,0,0,0,0,0,0,0,0,0,0,0,0,0,0,0,0,0,0
:endlayer
layer: 55
0,0,0,0,0,0,0,0,0,0,0,0,0,0,0,0,0,0,0
0,0,0,0,0,0,0,0,0,0,0,0,0,0,0,0,0,0,0
0,0,0,0,0,0,0,0,0,0,0,0,0,0,0,0,0,0,0
0,0,0,0,0,0,0,0,0,0,0,0,0,0,0,0,0,0,0
0,0,0,0,0,0,0,0,0,0,0,0,0,0,0,0,0,0,0
0,0,0,0,0,0,0,0,0,0,0,0,0,0,0,0,0,0,0
0,0,0,0,0,0,0,0,0,0,0,0,0,0,0,0,0,0,0
0,0,0,0,0,0,0,0,0,0,0,0,0,0,0,0,0,0,0
0,0,0,0,0,0,0,0,0,0,0,0,0,0,0,0,0,0,0
0,0,0,0,0,0,0,0,0,0,0,0,0,0,0,0,0,0,0
0,0,0,0,0,0,0,0,0,0,0,0,0,0,0,0,0,0,0
0,0,0,0,0,0,0,0,0,0,0,0,0,0,0,0,0,0,0
0,0,0,0,0,0,0,0,0,0,0,0,0,0,0,0,0,0,0
0,0,0,0,0,0,0,0,0,0,0,0,0,0,0,0,0,0,0
0,0,0,0,0,0,0,0,0,0,0,0,0,0,0,0,0,0,0
0,0,0,0,0,0,0,0,0,0,0,0,0,0,0,0,0,0,0
0,0,0,0,0,0,0,0,0,0,0,0,0,0,0,0,0,0,0
0,0,0,0,0,0,0,0,0,0,0,0,0,0,0,0,0,0,0
0,0,0,0,0,0,0,0,0,0,0,0,0,0,0,0,0,0,0
0,0,0,0,0,0,0,0,0,0,0,0,0,0,0,0,0,0,0
0,0,0,0,0,0,0,0,0,0,0,0,0,0,0,0,0,0,0
0,0,0,0,0,0,0,0,0,0,0,0,0,0,0,0,0,0,0
0,0,0,0,0,0,0,0,0,0,0,0,0,0,0,0,0,0,0
:endlayer
layer: 56
0,0,0,0,0,0,0,0,0,0,0,0,0,0,0,0,0,0,0
0,0,0,0,0,0,0,0,0,0,0,0,0,0,0,0,0,0,0
0,0,0,0,0,0,0,0,0,0,0,0,0,0,0,0,0,0,0
0,0,0,0,0,0,0,0,0,0,0,0,0,0,0,0,0,0,0
0,0,0,0,0,0,0,0,0,0,0,0,0,0,0,0,0,0,0
0,0,0,0,0,0,0,0,0,0,0,0,0,0,0,0,0,0,0
0,0,0,0,0,0,0,0,0,0,0,0,0,0,0,0,0,0,0
0,0,0,0,0,0,0,0,0,0,0,0,0,0,0,0,0,0,0
0,0,0,0,0,0,0,0,0,0,0,0,0,0,0,0,0,0,0
0,0,0,0,0,0,0,0,0,0,0,0,0,0,0,0,0,0,0
0,0,0,0,0,0,0,0,0,0,0,0,0,0,0,0,0,0,0
0,0,0,0,0,0,0,0,0,0,0,0,0,0,0,0,0,0,0
0,0,0,0,0,0,0,0,0,0,0,0,0,0,0,0,0,0,0
0,0,0,0,0,0,0,0,0,0,0,0,0,0,0,0,0,0,0
0,0,0,0,0,0,0,0,0,0,0,0,0,0,0,0,0,0,0
0,0,0,0,0,0,0,0,0,0,0,0,0,0,0,0,0,0,0
0,0,0,0,0,0,0,0,0,0,0,0,0,0,0,0,0,0,0
0,0,0,0,0,0,0,0,0,0,0,0,0,0,0,0,0,0,0
0,0,0,0,0,0,0,0,0,0,0,0,0,0,0,0,0,0,0
0,0,0,0,0,0,0,0,0,0,0,0,0,0,0,0,0,0,0
0,0,0,0,0,0,0,0,0,0,0,0,0,0,0,0,0,0,0
0,0,0,0,0,0,0,0,0,0,0,0,0,0,0,0,0,0,0
0,0,0,0,0,0,0,0,0,0,0,0,0,0,0,0,0,0,0
:endlayer
layer: 57
0,0,0,0,0,0,0,0,0,0,0,0,0,0,0,0,0,0,0
0,0,0,0,0,0,0,0,0,0,0,0,0,0,0,0,0,0,0
0,0,0,0,0,0,0,0,0,0,0,0,0,0,0,0,0,0,0
0,0,0,0,0,0,0,0,0,0,0,0,0,0,0,0,0,0,0
0,0,0,0,0,0,0,0,0,0,0,0,0,0,0,0,0,0,0
0,0,0,0,0,0,0,0,0,0,0,0,0,0,0,0,0,0,0
0,0,0,0,0,0,0,0,0,0,0,0,0,0,0,0,0,0,0
0,0,0,0,0,0,0,0,0,0,0,0,0,0,0,0,0,0,0
0,0,0,0,0,0,0,0,0,0,0,0,0,0,0,0,0,0,0
0,0,0,0,0,0,0,0,0,0,0,0,0,0,0,0,0,0,0
0,0,0,0,0,0,0,0,0,0,0,0,0,0,0,0,0,0,0
0,0,0,0,0,0,0,0,0,0,0,0,0,0,0,0,0,0,0
0,0,0,0,0,0,0,0,0,0,0,0,0,0,0,0,0,0,0
0,0,0,0,0,0,0,0,0,0,0,0,0,0,0,0,0,0,0
0,0,0,0,0,0,0,0,0,0,0,0,0,0,0,0,0,0,0
0,0,0,0,0,0,0,0,0,0,0,0,0,0,0,0,0,0,0
0,0,0,0,0,0,0,0,0,0,0,0,0,0,0,0,0,0,0
0,0,0,0,0,0,0,0,0,0,0,0,0,0,0,0,0,0,0
0,0,0,0,0,0,0,0,0,0,0,0,0,0,0,0,0,0,0
0,0,0,0,0,0,0,0,0,0,0,0,0,0,0,0,0,0,0
0,0,0,0,0,0,0,0,0,0,0,0,0,0,0,0,0,0,0
0,0,0,0,0,0,0,0,0,0,0,0,0,0,0,0,0,0,0
0,0,0,0,0,0,0,0,0,0,0,0,0,0,0,0,0,0,0
:endlayer
layer: 58
0,0,0,0,0,0,0,0,0,0,0,0,0,0,0,0,0,0,0
0,0,0,0,0,0,0,0,0,0,0,0,0,0,0,0,0,0,0
0,0,0,0,0,0,0,0,0,0,0,0,0,0,0,0,0,0,0
0,0,0,0,0,0,0,0,0,0,0,0,0,0,0,0,0,0,0
0,0,0,0,0,0,0,0,0,0,0,0,0,0,0,0,0,0,0
0,0,0,0,0,0,0,0,0,0,0,0,0,0,0,0,0,0,0
0,0,0,0,0,0,0,0,0,0,0,0,0,0,0,0,0,0,0
0,0,0,0,0,0,0,0,0,0,0,0,0,0,0,0,0,0,0
0,0,0,0,0,0,0,0,0,0,0,0,0,0,0,0,0,0,0
0,0,0,0,0,0,0,0,0,0,0,0,0,0,0,0,0,0,0
0,0,0,0,0,0,0,0,0,0,0,0,0,0,0,0,0,0,0
0,0,0,0,0,0,0,0,0,0,0,0,0,0,0,0,0,0,0
0,0,0,0,0,0,0,0,0,0,0,0,0,0,0,0,0,0,0
0,0,0,0,0,0,0,0,0,0,0,0,0,0,0,0,0,0,0
0,0,0,0,0,0,0,0,0,0,0,0,0,0,0,0,0,0,0
0,0,0,0,0,0,0,0,0,0,0,0,0,0,0,0,0,0,0
0,0,0,0,0,0,0,0,0,0,0,0,0,0,0,0,0,0,0
0,0,0,0,0,0,0,0,0,0,0,0,0,0,0,0,0,0,0
0,0,0,0,0,0,0,0,0,0,0,0,0,0,0,0,0,0,0
0,0,0,0,0,0,0,0,0,0,0,0,0,0,0,0,0,0,0
0,0,0,0,0,0,0,0,0,0,0,0,0,0,0,0,0,0,0
0,0,0,0,0,0,0,0,0,0,0,0,0,0,0,0,0,0,0
0,0,0,0,0,0,0,0,0,0,0,0,0,0,0,0,0,0,0
:endlayer
layer: 59
0,0,0,0,0,0,0,0,0,0,0,0,0,0,0,0,0,0,0
0,0,0,0,0,0,0,0,0,0,0,0,0,0,0,0,0,0,0
0,0,0,0,0,0,0,0,0,0,0,0,0,0,0,0,0,0,0
0,0,0,0,0,0,0,0,0,0,0,0,0,0,0,0,0,0,0
0,0,0,0,0,0,0,0,0,0,0,0,0,0,0,0,0,0,0
0,0,0,0,0,0,0,0,0,0,0,0,0,0,0,0,0,0,0
0,0,0,0,0,0,0,0,0,0,0,0,0,0,0,0,0,0,0
0,0,0,0,0,0,0,0,0,0,0,0,0,0,0,0,0,0,0
0,0,0,0,0,0,0,0,0,0,0,0,0,0,0,0,0,0,0
0,0,0,0,0,0,0,0,0,0,0,0,0,0,0,0,0,0,0
0,0,0,0,0,0,0,0,0,0,0,0,0,0,0,0,0,0,0
0,0,0,0,0,0,0,0,0,0,0,0,0,0,0,0,0,0,0
0,0,0,0,0,0,0,0,0,0,0,0,0,0,0,0,0,0,0
0,0,0,0,0,0,0,0,0,0,0,0,0,0,0,0,0,0,0
0,0,0,0,0,0,0,0,0,0,0,0,0,0,0,0,0,0,0
0,0,0,0,0,0,0,0,0,0,0,0,0,0,0,0,0,0,0
0,0,0,0,0,0,0,0,0,0,0,0,0,0,0,0,0,0,0
0,0,0,0,0,0,0,0,0,0,0,0,0,0,0,0,0,0,0
0,0,0,0,0,0,0,0,0,0,0,0,0,0,0,0,0,0,0
0,0,0,0,0,0,0,0,0,0,0,0,0,0,0,0,0,0,0
0,0,0,0,0,0,0,0,0,0,0,0,0,0,0,0,0,0,0
0,0,0,0,0,0,0,0,0,0,0,0,0,0,0,0,0,0,0
0,0,0,0,0,0,0,0,0,0,0,0,0,0,0,0,0,0,0
:endlayer
layer: 60
0,0,0,0,0,0,0,0,0,0,0,0,0,0,0,0,0,0,0
0,0,0,0,0,0,0,0,0,0,0,0,0,0,0,0,0,0,0
0,0,0,0,0,0,0,0,0,0,0,0,0,0,0,0,0,0,0
0,0,0,0,0,0,0,0,0,0,0,0,0,0,0,0,0,0,0
0,0,0,0,0,0,0,0,0,0,0,0,0,0,0,0,0,0,0
0,0,0,0,0,0,0,0,0,0,0,0,0,0,0,0,0,0,0
0,0,0,0,0,0,0,0,0,0,0,0,0,0,0,0,0,0,0
0,0,0,0,0,0,0,0,0,0,0,0,0,0,0,0,0,0,0
0,0,0,0,0,0,0,0,0,0,0,0,0,0,0,0,0,0,0
0,0,0,0,0,0,0,0,0,0,0,0,0,0,0,0,0,0,0
0,0,0,0,0,0,0,0,0,0,0,0,0,0,0,0,0,0,0
0,0,0,0,0,0,0,0,0,0,0,0,0,0,0,0,0,0,0
0,0,0,0,0,0,0,0,0,0,0,0,0,0,0,0,0,0,0
0,0,0,0,0,0,0,0,0,0,0,0,0,0,0,0,0,0,0
0,0,0,0,0,0,0,0,0,0,0,0,0,0,0,0,0,0,0
0,0,0,0,0,0,0,0,0,0,0,0,0,0,0,0,0,0,0
0,0,0,0,0,0,0,0,0,0,0,0,0,0,0,0,0,0,0
0,0,0,0,0,0,0,0,0,0,0,0,0,0,0,0,0,0,0
0,0,0,0,0,0,0,0,0,0,0,0,0,0,0,0,0,0,0
0,0,0,0,0,0,0,0,0,0,0,0,0,0,0,0,0,0,0
0,0,0,0,0,0,0,0,0,0,0,0,0,0,0,0,0,0,0
0,0,0,0,0,0,0,0,0,0,0,0,0,0,0,0,0,0,0
0,0,0,0,0,0,0,0,0,0,0,0,0,0,0,0,0,0,0
:endlayer
layer: 61
0,0,0,0,0,0,0,0,0,0,0,0,0,0,0,0,0,0,0
0,0,0,0,0,0,0,0,0,0,0,0,0,0,0,0,0,0,0
0,0,0,0,0,0,0,0,0,0,0,0,0,0,0,0,0,0,0
0,0,0,0,0,0,0,0,0,0,0,0,0,0,0,0,0,0,0
0,0,0,0,0,0,0,0,0,0,0,0,0,0,0,0,0,0,0
0,0,0,0,0,0,0,0,0,0,0,0,0,0,0,0,0,0,0
0,0,0,0,0,0,0,0,0,0,0,0,0,0,0,0,0,0,0
0,0,0,0,0,0,0,0,0,0,0,0,0,0,0,0,0,0,0
0,0,0,0,0,0,0,0,0,0,0,0,0,0,0,0,0,0,0
0,0,0,0,0,0,0,0,0,0,0,0,0,0,0,0,0,0,0
0,0,0,0,0,0,0,0,0,0,0,0,0,0,0,0,0,0,0
0,0,0,0,0,0,0,0,0,0,0,0,0,0,0,0,0,0,0
0,0,0,0,0,0,0,0,0,0,0,0,0,0,0,0,0,0,0
0,0,0,0,0,0,0,0,0,0,0,0,0,0,0,0,0,0,0
0,0,0,0,0,0,0,0,0,0,0,0,0,0,0,0,0,0,0
0,0,0,0,0,0,0,0,0,0,0,0,0,0,0,0,0,0,0
0,0,0,0,0,0,0,0,0,0,0,0,0,0,0,0,0,0,0
0,0,0,0,0,0,0,0,0,0,0,0,0,0,0,0,0,0,0
0,0,0,0,0,0,0,0,0,0,0,0,0,0,0,0,0,0,0
0,0,0,0,0,0,0,0,0,0,0,0,0,0,0,0,0,0,0
0,0,0,0,0,0,0,0,0,0,0,0,0,0,0,0,0,0,0
0,0,0,0,0,0,0,0,0,0,0,0,0,0,0,0,0,0,0
0,0,0,0,0,0,0,0,0,0,0,0,0,0,0,0,0,0,0
:endlayer
layer: 62
0,0,0,0,0,0,0,0,0,0,0,0,0,0,0,0,0,0,0
0,0,0,0,0,0,0,0,0,0,0,0,0,0,0,0,0,0,0
0,0,0,0,0,0,0,0,0,0,0,0,0,0,0,0,0,0,0
0,0,0,0,0,0,0,0,0,0,0,0,0,0,0,0,0,0,0
0,0,0,0,0,0,0,0,0,0,0,0,0,0,0,0,0,0,0
0,0,0,0,0,0,0,0,0,0,0,0,0,0,0,0,0,0,0
0,0,0,0,0,0,0,0,0,0,0,0,0,0,0,0,0,0,0
0,0,0,0,0,0,0,0,0,0,0,0,0,0,0,0,0,0,0
0,0,0,0,0,0,0,0,0,0,0,0,0,0,0,0,0,0,0
0,0,0,0,0,0,0,0,0,0,0,0,0,0,0,0,0,0,0
0,0,0,0,0,0,0,0,0,0,0,0,0,0,0,0,0,0,0
0,0,0,0,0,0,0,0,0,0,0,0,0,0,0,0,0,0,0
0,0,0,0,0,0,0,0,0,0,0,0,0,0,0,0,0,0,0
0,0,0,0,0,0,0,0,0,0,0,0,0,0,0,0,0,0,0
0,0,0,0,0,0,0,0,0,0,0,0,0,0,0,0,0,0,0
0,0,0,0,0,0,0,0,0,0,0,0,0,0,0,0,0,0,0
0,0,0,0,0,0,0,0,0,0,0,0,0,0,0,0,0,0,0
0,0,0,0,0,0,0,0,0,0,0,0,0,0,0,0,0,0,0
0,0,0,0,0,0,0,0,0,0,0,0,0,0,0,0,0,0,0
0,0,0,0,0,0,0,0,0,0,0,0,0,0,0,0,0,0,0
0,0,0,0,0,0,0,0,0,0,0,0,0,0,0,0,0,0,0
0,0,0,0,0,0,0,0,0,0,0,0,0,0,0,0,0,0,0
0,0,0,0,0,0,0,0,0,0,0,0,0,0,0,0,0,0,0
:endlayer
layer: 63
0,0,0,0,0,0,0,0,0,0,0,0,0,0,0,0,0,0,0
0,0,0,0,0,0,0,0,0,0,0,0,0,0,0,0,0,0,0
0,0,0,0,0,0,0,0,0,0,0,0,0,0,0,0,0,0,0
0,0,0,0,0,0,0,0,0,0,0,0,0,0,0,0,0,0,0
0,0,0,0,0,0,0,0,0,0,0,0,0,0,0,0,0,0,0
0,0,0,0,0,0,0,0,0,0,0,0,0,0,0,0,0,0,0
0,0,0,0,0,0,0,0,0,0,0,0,0,0,0,0,0,0,0
0,0,0,0,0,0,0,0,0,0,0,0,0,0,0,0,0,0,0
0,0,0,0,0,0,0,0,0,0,0,0,0,0,0,0,0,0,0
0,0,0,0,0,0,0,0,0,0,0,0,0,0,0,0,0,0,0
0,0,0,0,0,0,0,0,0,0,0,0,0,0,0,0,0,0,0
0,0,0,0,0,0,0,0,0,0,0,0,0,0,0,0,0,0,0
0,0,0,0,0,0,0,0,0,0,0,0,0,0,0,0,0,0,0
0,0,0,0,0,0,0,0,0,0,0,0,0,0,0,0,0,0,0
0,0,0,0,0,0,0,0,0,0,0,0,0,0,0,0,0,0,0
0,0,0,0,0,0,0,0,0,0,0,0,0,0,0,0,0,0,0
0,0,0,0,0,0,0,0,0,0,0,0,0,0,0,0,0,0,0
0,0,0,0,0,0,0,0,0,0,0,0,0,0,0,0,0,0,0
0,0,0,0,0,0,0,0,0,0,0,0,0,0,0,0,0,0,0
0,0,0,0,0,0,0,0,0,0,0,0,0,0,0,0,0,0,0
0,0,0,0,0,0,0,0,0,0,0,0,0,0,0,0,0,0,0
0,0,0,0,0,0,0,0,0,0,0,0,0,0,0,0,0,0,0
0,0,0,0,0,0,0,0,0,0,0,0,0,0,0,0,0,0,0
:endlayer
layer: 64
0,0,0,0,0,0,0,0,0,0,0,0,0,0,0,0,0,0,0
0,0,0,0,0,0,0,0,0,0,0,0,0,0,0,0,0,0,0
0,0,0,0,0,0,0,0,0,0,0,0,0,0,0,0,0,0,0
0,0,0,0,0,0,0,0,0,0,0,0,0,0,0,0,0,0,0
0,0,0,0,0,0,0,0,0,0,0,0,0,0,0,0,0,0,0
0,0,0,0,0,0,0,0,0,0,0,0,0,0,0,0,0,0,0
0,0,0,0,0,0,0,0,0,0,0,0,0,0,0,0,0,0,0
0,0,0,0,0,0,0,0,0,0,0,0,0,0,0,0,0,0,0
0,0,0,0,0,0,0,0,0,0,0,0,0,0,0,0,0,0,0
0,0,0,0,0,0,0,0,0,0,0,0,0,0,0,0,0,0,0
0,0,0,0,0,0,0,0,0,0,0,0,0,0,0,0,0,0,0
0,0,0,0,0,0,0,0,0,0,0,0,0,0,0,0,0,0,0
0,0,0,0,0,0,0,0,0,0,0,0,0,0,0,0,0,0,0
0,0,0,0,0,0,0,0,0,0,0,0,0,0,0,0,0,0,0
0,0,0,0,0,0,0,0,0,0,0,0,0,0,0,0,0,0,0
0,0,0,0,0,0,0,0,0,0,0,0,0,0,0,0,0,0,0
0,0,0,0,0,0,0,0,0,0,0,0,0,0,0,0,0,0,0
0,0,0,0,0,0,0,0,0,0,0,0,0,0,0,0,0,0,0
0,0,0,0,0,0,0,0,0,0,0,0,0,0,0,0,0,0,0
0,0,0,0,0,0,0,0,0,0,0,0,0,0,0,0,0,0,0
0,0,0,0,0,0,0,0,0,0,0,0,0,0,0,0,0,0,0
0,0,0,0,0,0,0,0,0,0,0,0,0,0,0,0,0,0,0
0,0,0,0,0,0,0,0,0,0,0,0,0,0,0,0,0,0,0
:endlayer
layer: 65
0,0,0,0,0,0,0,0,0,0,0,0,0,0,0,0,0,0,0
0,0,0,0,0,0,0,0,0,0,0,0,0,0,0,0,0,0,0
0,0,0,0,0,0,0,0,0,0,0,0,0,0,0,0,0,0,0
0,0,0,0,0,0,0,0,0,0,0,0,0,0,0,0,0,0,0
0,0,0,0,0,0,0,0,0,0,0,0,0,0,0,0,0,0,0
0,0,0,0,0,0,0,0,0,0,0,0,0,0,0,0,0,0,0
0,0,0,0,0,0,0,0,0,0,0,0,0,0,0,0,0,0,0
0,0,0,0,0,0,0,0,0,0,0,0,0,0,0,0,0,0,0
0,0,0,0,0,0,0,0,0,0,0,0,0,0,0,0,0,0,0
0,0,0,0,0,0,0,0,0,0,0,0,0,0,0,0,0,0,0
0,0,0,0,0,0,0,0,0,0,0,0,0,0,0,0,0,0,0
0,0,0,0,0,0,0,0,0,0,0,0,0,0,0,0,0,0,0
0,0,0,0,0,0,0,0,0,0,0,0,0,0,0,0,0,0,0
0,0,0,0,0,0,0,0,0,0,0,0,0,0,0,0,0,0,0
0,0,0,0,0,0,0,0,0,0,0,0,0,0,0,0,0,0,0
0,0,0,0,0,0,0,0,0,0,0,0,0,0,0,0,0,0,0
0,0,0,0,0,0,0,0,0,0,0,0,0,0,0,0,0,0,0
0,0,0,0,0,0,0,0,0,0,0,0,0,0,0,0,0,0,0
0,0,0,0,0,0,0,0,0,0,0,0,0,0,0,0,0,0,0
0,0,0,0,0,0,0,0,0,0,0,0,0,0,0,0,0,0,0
0,0,0,0,0,0,0,0,0,0,0,0,0,0,0,0,0,0,0
0,0,0,0,0,0,0,0,0,0,0,0,0,0,0,0,0,0,0
0,0,0,0,0,0,0,0,0,0,0,0,0,0,0,0,0,0,0
:endlayer
layer: 66
0,0,0,0,0,0,0,0,0,0,0,0,0,0,0,0,0,0,0
0,0,0,0,0,0,0,0,0,0,0,0,0,0,0,0,0,0,0
0,0,0,0,0,0,0,0,0,0,0,0,0,0,0,0,0,0,0
0,0,0,0,0,0,0,0,0,0,0,0,0,0,0,0,0,0,0
0,0,0,0,0,0,0,0,0,0,0,0,0,0,0,0,0,0,0
0,0,0,0,0,0,0,0,0,0,0,0,0,0,0,0,0,0,0
0,0,0,0,0,0,0,0,0,0,0,0,0,0,0,0,0,0,0
0,0,0,0,0,0,0,0,0,0,0,0,0,0,0,0,0,0,0
0,0,0,0,0,0,0,0,0,0,0,0,0,0,0,0,0,0,0
0,0,0,0,0,0,0,0,0,0,0,0,0,0,0,0,0,0,0
0,0,0,0,0,0,0,0,0,0,0,0,0,0,0,0,0,0,0
0,0,0,0,0,0,0,0,0,0,0,0,0,0,0,0,0,0,0
0,0,0,0,0,0,0,0,0,0,0,0,0,0,0,0,0,0,0
0,0,0,0,0,0,0,0,0,0,0,0,0,0,0,0,0,0,0
0,0,0,0,0,0,0,0,0,0,0,0,0,0,0,0,0,0,0
0,0,0,0,0,0,0,0,0,0,0,0,0,0,0,0,0,0,0
0,0,0,0,0,0,0,0,0,0,0,0,0,0,0,0,0,0,0
0,0,0,0,0,0,0,0,0,0,0,0,0,0,0,0,0,0,0
0,0,0,0,0,0,0,0,0,0,0,0,0,0,0,0,0,0,0
0,0,0,0,0,0,0,0,0,0,0,0,0,0,0,0,0,0,0
0,0,0,0,0,0,0,0,0,0,0,0,0,0,0,0,0,0,0
0,0,0,0,0,0,0,0,0,0,0,0,0,0,0,0,0,0,0
0,0,0,0,0,0,0,0,0,0,0,0,0,0,0,0,0,0,0
:endlayer
layer: 67
0,0,0,0,0,0,0,0,0,0,0,0,0,0,0,0,0,0,0
0,0,0,0,0,0,0,0,0,0,0,0,0,0,0,0,0,0,0
0,0,0,0,0,0,0,0,0,0,0,0,0,0,0,0,0,0,0
0,0,0,0,0,0,0,0,0,0,0,0,0,0,0,0,0,0,0
0,0,0,0,0,0,0,0,0,0,0,0,0,0,0,0,0,0,0
0,0,0,0,0,0,0,0,0,0,0,0,0,0,0,0,0,0,0
0,0,0,0,0,0,0,0,0,0,0,0,0,0,0,0,0,0,0
0,0,0,0,0,0,0,0,0,0,0,0,0,0,0,0,0,0,0
0,0,0,0,0,0,0,0,0,0,0,0,0,0,0,0,0,0,0
0,0,0,0,0,0,0,0,0,0,0,0,0,0,0,0,0,0,0
0,0,0,0,0,0,0,0,0,0,0,0,0,0,0,0,0,0,0
0,0,0,0,0,0,0,0,0,0,0,0,0,0,0,0,0,0,0
0,0,0,0,0,0,0,0,0,0,0,0,0,0,0,0,0,0,0
0,0,0,0,0,0,0,0,0,0,0,0,0,0,0,0,0,0,0
0,0,0,0,0,0,0,0,0,0,0,0,0,0,0,0,0,0,0
0,0,0,0,0,0,0,0,0,0,0,0,0,0,0,0,0,0,0
0,0,0,0,0,0,0,0,0,0,0,0,0,0,0,0,0,0,0
0,0,0,0,0,0,0,0,0,0,0,0,0,0,0,0,0,0,0
0,0,0,0,0,0,0,0,0,0,0,0,0,0,0,0,0,0,0
0,0,0,0,0,0,0,0,0,0,0,0,0,0,0,0,0,0,0
0,0,0,0,0,0,0,0,0,0,0,0,0,0,0,0,0,0,0
0,0,0,0,0,0,0,0,0,0,0,0,0,0,0,0,0,0,0
0,0,0,0,0,0,0,0,0,0,0,0,0,0,0,0,0,0,0
:endlayer
layer: 68
0,0,0,0,0,0,0,0,0,0,0,0,0,0,0,0,0,0,0
0,0,0,0,0,0,0,0,0,0,0,0,0,0,0,0,0,0,0
0,0,0,0,0,0,0,0,0,0,0,0,0,0,0,0,0,0,0
0,0,0,0,0,0,0,0,0,0,0,0,0,0,0,0,0,0,0
0,0,0,0,0,0,0,0,0,0,0,0,0,0,0,0,0,0,0
0,0,0,0,0,0,0,0,0,0,0,0,0,0,0,0,0,0,0
0,0,0,0,0,0,0,0,0,0,0,0,0,0,0,0,0,0,0
0,0,0,0,0,0,0,0,0,0,0,0,0,0,0,0,0,0,0
0,0,0,0,0,0,0,0,0,0,0,0,0,0,0,0,0,0,0
0,0,0,0,0,0,0,0,0,0,0,0,0,0,0,0,0,0,0
0,0,0,0,0,0,0,0,0,0,0,0,0,0,0,0,0,0,0
0,0,0,0,0,0,0,0,0,0,0,0,0,0,0,0,0,0,0
0,0,0,0,0,0,0,0,0,0,0,0,0,0,0,0,0,0,0
0,0,0,0,0,0,0,0,0,0,0,0,0,0,0,0,0,0,0
0,0,0,0,0,0,0,0,0,0,0,0,0,0,0,0,0,0,0
0,0,0,0,0,0,0,0,0,0,0,0,0,0,0,0,0,0,0
0,0,0,0,0,0,0,0,0,0,0,0,0,0,0,0,0,0,0
0,0,0,0,0,0,0,0,0,0,0,0,0,0,0,0,0,0,0
0,0,0,0,0,0,0,0,0,0,0,0,0,0,0,0,0,0,0
0,0,0,0,0,0,0,0,0,0,0,0,0,0,0,0,0,0,0
0,0,0,0,0,0,0,0,0,0,0,0,0,0,0,0,0,0,0
0,0,0,0,0,0,0,0,0,0,0,0,0,0,0,0,0,0,0
0,0,0,0,0,0,0,0,0,0,0,0,0,0,0,0,0,0,0
:endlayer
layer: 69
0,0,0,0,0,0,0,0,0,0,0,0,0,0,0,0,0,0,0
0,0,0,0,0,0,0,0,0,0,0,0,0,0,0,0,0,0,0
0,0,0,0,0,0,0,0,0,0,0,0,0,0,0,0,0,0,0
0,0,0,0,0,0,0,0,0,0,0,0,0,0,0,0,0,0,0
0,0,0,0,0,0,0,0,0,0,0,0,0,0,0,0,0,0,0
0,0,0,0,0,0,0,0,0,0,0,0,0,0,0,0,0,0,0
0,0,0,0,0,0,0,0,0,0,0,0,0,0,0,0,0,0,0
0,0,0,0,0,0,0,0,0,0,0,0,0,0,0,0,0,0,0
0,0,0,0,0,0,0,0,0,0,0,0,0,0,0,0,0,0,0
0,0,0,0,0,0,0,0,0,0,0,0,0,0,0,0,0,0,0
0,0,0,0,0,0,0,0,0,0,0,0,0,0,0,0,0,0,0
0,0,0,0,0,0,0,0,0,0,0,0,0,0,0,0,0,0,0
0,0,0,0,0,0,0,0,0,0,0,0,0,0,0,0,0,0,0
0,0,0,0,0,0,0,0,0,0,0,0,0,0,0,0,0,0,0
0,0,0,0,0,0,0,0,0,0,0,0,0,0,0,0,0,0,0
0,0,0,0,0,0,0,0,0,0,0,0,0,0,0,0,0,0,0
0,0,0,0,0,0,0,0,0,0,0,0,0,0,0,0,0,0,0
0,0,0,0,0,0,0,0,0,0,0,0,0,0,0,0,0,0,0
0,0,0,0,0,0,0,0,0,0,0,0,0,0,0,0,0,0,0
0,0,0,0,0,0,0,0,0,0,0,0,0,0,0,0,0,0,0
0,0,0,0,0,0,0,0,0,0,0,0,0,0,0,0,0,0,0
0,0,0,0,0,0,0,0,0,0,0,0,0,0,0,0,0,0,0
0,0,0,0,0,0,0,0,0,0,0,0,0,0,0,0,0,0,0
:endlayer
layer: 70
0,0,0,0,0,0,0,0,0,0,0,0,0,0,0,0,0,0,0
0,0,0,0,0,0,0,0,0,0,0,0,0,0,0,0,0,0,0
0,0,0,0,0,0,0,0,0,0,0,0,0,0,0,0,0,0,0
0,0,0,0,0,0,0,0,0,0,0,0,0,0,0,0,0,0,0
0,0,0,0,0,0,0,0,0,0,0,0,0,0,0,0,0,0,0
0,0,0,0,0,0,0,0,0,0,0,0,0,0,0,0,0,0,0
0,0,0,0,0,0,0,0,0,0,0,0,0,0,0,0,0,0,0
0,0,0,0,0,0,0,0,0,0,0,0,0,0,0,0,0,0,0
0,0,0,0,0,0,0,0,0,0,0,0,0,0,0,0,0,0,0
0,0,0,0,0,0,0,0,0,0,0,0,0,0,0,0,0,0,0
0,0,0,0,0,0,0,0,0,0,0,0,0,0,0,0,0,0,0
0,0,0,0,0,0,0,0,0,0,0,0,0,0,0,0,0,0,0
0,0,0,0,0,0,0,0,0,0,0,0,0,0,0,0,0,0,0
0,0,0,0,0,0,0,0,0,0,0,0,0,0,0,0,0,0,0
0,0,0,0,0,0,0,0,0,0,0,0,0,0,0,0,0,0,0
0,0,0,0,0,0,0,0,0,0,0,0,0,0,0,0,0,0,0
0,0,0,0,0,0,0,0,0,0,0,0,0,0,0,0,0,0,0
0,0,0,0,0,0,0,0,0,0,0,0,0,0,0,0,0,0,0
0,0,0,0,0,0,0,0,0,0,0,0,0,0,0,0,0,0,0
0,0,0,0,0,0,0,0,0,0,0,0,0,0,0,0,0,0,0
0,0,0,0,0,0,0,0,0,0,0,0,0,0,0,0,0,0,0
0,0,0,0,0,0,0,0,0,0,0,0,0,0,0,0,0,0,0
0,0,0,0,0,0,0,0,0,0,0,0,0,0,0,0,0,0,0
:endlayer
layer: 71
0,0,0,0,0,0,0,0,0,0,0,0,0,0,0,0,0,0,0
0,0,0,0,0,0,0,0,0,0,0,0,0,0,0,0,0,0,0
0,0,0,0,0,0,0,0,0,0,0,0,0,0,0,0,0,0,0
0,0,0,0,0,0,0,0,0,0,0,0,0,0,0,0,0,0,0
0,0,0,0,0,0,0,0,0,0,0,0,0,0,0,0,0,0,0
0,0,0,0,0,0,0,0,0,0,0,0,0,0,0,0,0,0,0
0,0,0,0,0,0,0,0,0,0,0,0,0,0,0,0,0,0,0
0,0,0,0,0,0,0,0,0,0,0,0,0,0,0,0,0,0,0
0,0,0,0,0,0,0,0,0,0,0,0,0,0,0,0,0,0,0
0,0,0,0,0,0,0,0,0,0,0,0,0,0,0,0,0,0,0
0,0,0,0,0,0,0,0,0,0,0,0,0,0,0,0,0,0,0
0,0,0,0,0,0,0,0,0,0,0,0,0,0,0,0,0,0,0
0,0,0,0,0,0,0,0,0,0,0,0,0,0,0,0,0,0,0
0,0,0,0,0,0,0,0,0,0,0,0,0,0,0,0,0,0,0
0,0,0,0,0,0,0,0,0,0,0,0,0,0,0,0,0,0,0
0,0,0,0,0,0,0,0,0,0,0,0,0,0,0,0,0,0,0
0,0,0,0,0,0,0,0,0,0,0,0,0,0,0,0,0,0,0
0,0,0,0,0,0,0,0,0,0,0,0,0,0,0,0,0,0,0
0,0,0,0,0,0,0,0,0,0,0,0,0,0,0,0,0,0,0
0,0,0,0,0,0,0,0,0,0,0,0,0,0,0,0,0,0,0
0,0,0,0,0,0,0,0,0,0,0,0,0,0,0,0,0,0,0
0,0,0,0,0,0,0,0,0,0,0,0,0,0,0,0,0,0,0
0,0,0,0,0,0,0,0,0,0,0,0,0,0,0,0,0,0,0
:endlayer
layer: 72
0,0,0,0,0,0,0,0,0,0,0,0,0,0,0,0,0,0,0
0,0,0,0,0,0,0,0,0,0,0,0,0,0,0,0,0,0,0
0,0,0,0,0,0,0,0,0,0,0,0,0,0,0,0,0,0,0
0,0,0,0,0,0,0,0,0,0,0,0,0,0,0,0,0,0,0
0,0,0,0,0,0,0,0,0,0,0,0,0,0,0,0,0,0,0
0,0,0,0,0,0,0,0,0,0,0,0,0,0,0,0,0,0,0
0,0,0,0,0,0,0,0,0,0,0,0,0,0,0,0,0,0,0
0,0,0,0,0,0,0,0,0,0,0,0,0,0,0,0,0,0,0
0,0,0,0,0,0,0,0,0,0,0,0,0,0,0,0,0,0,0
0,0,0,0,0,0,0,0,0,0,0,0,0,0,0,0,0,0,0
0,0,0,0,0,0,0,0,0,0,0,0,0,0,0,0,0,0,0
0,0,0,0,0,0,0,0,0,0,0,0,0,0,0,0,0,0,0
0,0,0,0,0,0,0,0,0,0,0,0,0,0,0,0,0,0,0
0,0,0,0,0,0,0,0,0,0,0,0,0,0,0,0,0,0,0
0,0,0,0,0,0,0,0,0,0,0,0,0,0,0,0,0,0,0
0,0,0,0,0,0,0,0,0,0,0,0,0,0,0,0,0,0,0
0,0,0,0,0,0,0,0,0,0,0,0,0,0,0,0,0,0,0
0,0,0,0,0,0,0,0,0,0,0,0,0,0,0,0,0,0,0
0,0,0,0,0,0,0,0,0,0,0,0,0,0,0,0,0,0,0
0,0,0,0,0,0,0,0,0,0,0,0,0,0,0,0,0,0,0
0,0,0,0,0,0,0,0,0,0,0,0,0,0,0,0,0,0,0
0,0,0,0,0,0,0,0,0,0,0,0,0,0,0,0,0,0,0
0,0,0,0,0,0,0,0,0,0,0,0,0,0,0,0,0,0,0
:endlayer
layer: 73
0,0,0,0,0,0,0,0,0,0,0,0,0,0,0,0,0,0,0
0,0,0,0,0,0,0,0,0,0,0,0,0,0,0,0,0,0,0
0,0,0,0,0,0,0,0,0,0,0,0,0,0,0,0,0,0,0
0,0,0,0,0,0,0,0,0,0,0,0,0,0,0,0,0,0,0
0,0,0,0,0,0,0,0,0,0,0,0,0,0,0,0,0,0,0
0,0,0,0,0,0,0,0,0,0,0,0,0,0,0,0,0,0,0
0,0,0,0,0,0,0,0,0,0,0,0,0,0,0,0,0,0,0
0,0,0,0,0,0,0,0,0,0,0,0,0,0,0,0,0,0,0
0,0,0,0,0,0,0,0,0,0,0,0,0,0,0,0,0,0,0
0,0,0,0,0,0,0,0,0,0,0,0,0,0,0,0,0,0,0
0,0,0,0,0,0,0,0,0,0,0,0,0,0,0,0,0,0,0
0,0,0,0,0,0,0,0,0,0,0,0,0,0,0,0,0,0,0
0,0,0,0,0,0,0,0,0,0,0,0,0,0,0,0,0,0,0
0,0,0,0,0,0,0,0,0,0,0,0,0,0,0,0,0,0,0
0,0,0,0,0,0,0,0,0,0,0,0,0,0,0,0,0,0,0
0,0,0,0,0,0,0,0,0,0,0,0,0,0,0,0,0,0,0
0,0,0,0,0,0,0,0,0,0,0,0,0,0,0,0,0,0,0
0,0,0,0,0,0,0,0,0,0,0,0,0,0,0,0,0,0,0
0,0,0,0,0,0,0,0,0,0,0,0,0,0,0,0,0,0,0
0,0,0,0,0,0,0,0,0,0,0,0,0,0,0,0,0,0,0
0,0,0,0,0,0,0,0,0,0,0,0,0,0,0,0,0,0,0
0,0,0,0,0,0,0,0,0,0,0,0,0,0,0,0,0,0,0
0,0,0,0,0,0,0,0,0,0,0,0,0,0,0,0,0,0,0
:endlayer

#### RULES ####
rule:
plugin=vanillaBlocks
number=1
data:
JSON:{blockState:{blockName:"minecraft:dirt",properties:{variant:"dirt",snowy:"false"}},buildPass:0}
:enddata
:endrule

rule:
plugin=vanillaBlocks
number=2
data:
JSON:{blockState:{blockName:"minecraft:grass",properties:{snowy:"false"}},buildPass:0}
:enddata
:endrule

rule:
plugin=vanillaBlocks
number=3
data:
JSON:{blockState:{blockName:"minecraft:stone",properties:{variant:"stone"}},buildPass:0}
:enddata
:endrule

rule:
plugin=vanillaBlocks
number=4
data:
JSON:{blockState:{blockName:"minecraft:tallgrass",properties:{type:"tall_grass"}},buildPass:0}
:enddata
:endrule

rule:
plugin=vanillaBlocks
number=5
data:
JSON:{blockState:{blockName:"minecraft:red_flower",properties:{type:"poppy"}},buildPass:0}
:enddata
:endrule

rule:
plugin=vanillaBlocks
number=6
data:
JSON:{blockState:{blockName:"minecraft:fence",properties:{east:"false",south:"false",north:"false",west:"false"}},buildPass:0}
:enddata
:endrule

rule:
plugin=blockTile
number=7
data:
JSON:{blockState:{blockName:"ancientwarfarestructure:advanced_spawner",properties:{transparent:"true"}},buildPass:0,teData:{id:"ancientwarfarestructure:advanced_spawner_tile",spawnerSettings:{minDelay:0,spawnDelay:0,lightSensitive:0b,spawnGroups:[{settingsList:[{remainingSpawnCount:1,hostile:1b,forced:1b,customTag:{factionName:"kong"},maxToSpawn:1,entityId:"ancientwarfarenpc:faction.soldier",minToSpawn:1}],groupWeight:1}],playerRange:16,respondToRedstone:0b,inventory:{Size:9,Items:[]},spawnRange:0,transparent:1b,maxDelay:0,xpToDrop:0,mobRange:0,debugMode:0b,maxNearbyMonsters:0}}}
:enddata
:endrule

rule:
plugin=vanillaBlocks
number=8
data:
JSON:{blockState:{blockName:"minecraft:fence_gate",properties:{in_wall:"false",powered:"false",facing:"east",open:"false"}},buildPass:0}
:enddata
:endrule

rule:
plugin=blockTile
number=9
data:
JSON:{blockState:{blockName:"ancientwarfarestructure:advanced_spawner",properties:{transparent:"true"}},buildPass:0,teData:{id:"ancientwarfarestructure:advanced_spawner_tile",spawnerSettings:{minDelay:0,spawnDelay:0,lightSensitive:0b,spawnGroups:[{settingsList:[{remainingSpawnCount:1,hostile:1b,forced:1b,customTag:{factionName:"kong"},maxToSpawn:1,entityId:"ancientwarfarenpc:faction.soldier",minToSpawn:1}],groupWeight:1}],playerRange:16,respondToRedstone:0b,inventory:{Size:9,Items:[]},spawnRange:0,transparent:1b,maxDelay:0,xpToDrop:0,mobRange:0,debugMode:0b,maxNearbyMonsters:0}}}
:enddata
:endrule

rule:
plugin=vanillaBlocks
number=10
data:
JSON:{blockState:{blockName:"minecraft:log",properties:{variant:"jungle",axis:"y"}},buildPass:0}
:enddata
:endrule

rule:
plugin=vanillaBlocks
number=11
data:
JSON:{blockState:{blockName:"minecraft:double_plant",properties:{half:"lower",variant:"double_grass",facing:"north"}},buildPass:0}
:enddata
:endrule

rule:
plugin=vanillaBlocks
number=12
data:
JSON:{blockState:{blockName:"minecraft:vine",properties:{east:"true",south:"false",north:"false",west:"false",up:"false"}},buildPass:0}
:enddata
:endrule

rule:
plugin=vanillaBlocks
number=13
data:
JSON:{blockState:{blockName:"minecraft:vine",properties:{east:"false",south:"false",north:"false",west:"true",up:"false"}},buildPass:0}
:enddata
:endrule

rule:
plugin=vanillaBlocks
number=14
data:
JSON:{blockState:{blockName:"minecraft:vine",properties:{east:"false",south:"false",north:"true",west:"false",up:"false"}},buildPass:0}
:enddata
:endrule

rule:
plugin=vanillaBlocks
number=15
data:
JSON:{blockState:{blockName:"minecraft:vine",properties:{east:"false",south:"false",north:"false",west:"false",up:"false"}},buildPass:0}
:enddata
:endrule

rule:
plugin=vanillaBlocks
number=16
data:
JSON:{blockState:{blockName:"minecraft:planks",properties:{variant:"jungle"}},buildPass:0}
:enddata
:endrule

rule:
plugin=blockTile
number=17
data:
JSON:{blockState:{blockName:"ancientwarfarestructure:advanced_spawner",properties:{transparent:"true"}},buildPass:0,teData:{id:"ancientwarfarestructure:advanced_spawner_tile",spawnerSettings:{minDelay:0,spawnDelay:0,lightSensitive:0b,spawnGroups:[{settingsList:[{remainingSpawnCount:1,hostile:1b,forced:1b,customTag:{factionName:"kong"},maxToSpawn:1,entityId:"ancientwarfarenpc:faction.soldier",minToSpawn:1}],groupWeight:1}],playerRange:16,respondToRedstone:0b,inventory:{Size:9,Items:[]},spawnRange:0,transparent:1b,maxDelay:0,xpToDrop:0,mobRange:0,debugMode:0b,maxNearbyMonsters:0}}}
:enddata
:endrule

rule:
plugin=vanillaBlocks
number=18
data:
JSON:{blockState:{blockName:"minecraft:yellow_flower",properties:{type:"dandelion"}},buildPass:0}
:enddata
:endrule

rule:
plugin=vanillaBlocks
number=19
data:
JSON:{blockState:{blockName:"minecraft:double_plant",properties:{half:"upper",variant:"sunflower",facing:"north"}},buildPass:0}
:enddata
:endrule

rule:
plugin=vanillaBlocks
number=20
data:
JSON:{blockState:{blockName:"minecraft:torch",properties:{facing:"north"}},buildPass:0}
:enddata
:endrule

rule:
plugin=blockTile
number=21
data:
JSON:{blockState:{blockName:"ancientwarfarestructure:advanced_spawner",properties:{transparent:"true"}},buildPass:0,teData:{id:"ancientwarfarestructure:advanced_spawner_tile",spawnerSettings:{minDelay:0,spawnDelay:0,lightSensitive:0b,spawnGroups:[{settingsList:[{remainingSpawnCount:1,hostile:1b,forced:1b,customTag:{factionName:"kong"},maxToSpawn:1,entityId:"ancientwarfarenpc:faction.soldier",minToSpawn:1}],groupWeight:1}],playerRange:6,respondToRedstone:0b,inventory:{Size:9,Items:[]},spawnRange:0,transparent:1b,maxDelay:0,xpToDrop:0,mobRange:0,debugMode:0b,maxNearbyMonsters:0}}}
:enddata
:endrule

rule:
plugin=blockTile
number=22
data:
JSON:{blockState:{blockName:"ancientwarfarestructure:advanced_spawner",properties:{transparent:"true"}},buildPass:0,teData:{id:"ancientwarfarestructure:advanced_spawner_tile",spawnerSettings:{minDelay:0,spawnDelay:0,lightSensitive:0b,spawnGroups:[{settingsList:[{remainingSpawnCount:1,hostile:1b,forced:1b,customTag:{factionName:"kong"},maxToSpawn:1,entityId:"ancientwarfarenpc:faction.civilian.female",minToSpawn:1}],groupWeight:1}],playerRange:16,respondToRedstone:0b,inventory:{Size:9,Items:[]},spawnRange:0,transparent:1b,maxDelay:0,xpToDrop:0,mobRange:0,debugMode:0b,maxNearbyMonsters:0}}}
:enddata
:endrule

rule:
plugin=vanillaBlocks
number=23
data:
JSON:{blockState:{blockName:"ancientwarfarestructure:fire_pit",properties:{lit:"true",variant:"default"}},buildPass:0}
:enddata
:endrule

rule:
plugin=blockTile
number=24
data:
JSON:{blockState:{blockName:"ancientwarfarestructure:advanced_spawner",properties:{transparent:"true"}},buildPass:0,teData:{id:"ancientwarfarestructure:advanced_spawner_tile",spawnerSettings:{minDelay:0,spawnDelay:0,lightSensitive:0b,spawnGroups:[{settingsList:[{remainingSpawnCount:1,hostile:1b,forced:1b,customTag:{factionName:"kong"},maxToSpawn:1,entityId:"ancientwarfarenpc:faction.leader",minToSpawn:1}],groupWeight:1}],playerRange:5,respondToRedstone:0b,inventory:{Size:9,Items:[]},spawnRange:0,transparent:1b,maxDelay:0,xpToDrop:0,mobRange:0,debugMode:0b,maxNearbyMonsters:0}}}
:enddata
:endrule

rule:
plugin=blockTile
number=25
data:
JSON:{blockState:{blockName:"ancientwarfarestructure:advanced_spawner",properties:{transparent:"true"}},buildPass:0,teData:{id:"ancientwarfarestructure:advanced_spawner_tile",spawnerSettings:{minDelay:0,spawnDelay:0,lightSensitive:0b,spawnGroups:[{settingsList:[{remainingSpawnCount:1,hostile:1b,forced:1b,customTag:{factionName:"kong"},maxToSpawn:1,entityId:"ancientwarfarenpc:faction.soldier",minToSpawn:1}],groupWeight:1}],playerRange:6,respondToRedstone:0b,inventory:{Size:9,Items:[]},spawnRange:0,transparent:1b,maxDelay:0,xpToDrop:0,mobRange:0,debugMode:0b,maxNearbyMonsters:0}}}
:enddata
:endrule

rule:
plugin=inventory
number=26
data:
JSON:{blockState:{blockName:"minecraft:chest",properties:{facing:"north"}},buildPass:0,lootLevel:0,teData:{ForgeData:{},Items:[{Slot:2b,id:"minecraft:dye",Count:16b,Damage:15s},{Slot:4b,id:"minecraft:bone",Count:16b,Damage:0s},{Slot:6b,id:"minecraft:bone",Count:16b,Damage:0s},{Slot:10b,id:"minecraft:rotten_flesh",Count:16b,Damage:0s},{Slot:18b,id:"minecraft:flint",Count:24b,Damage:0s},{Slot:21b,id:"minecraft:rotten_flesh",Count:16b,Damage:0s},{Slot:25b,id:"minecraft:dye",Count:16b,Damage:15s}],id:"minecraft:chest",Lock:""},inventoryData:{length:7,inventoryContents:[{id:"minecraft:dye",Count:16b,slot:0,Damage:15s},{id:"minecraft:bone",Count:16b,slot:1,Damage:0s},{id:"minecraft:bone",Count:16b,slot:2,Damage:0s},{id:"minecraft:rotten_flesh",Count:16b,slot:3,Damage:0s},{id:"minecraft:flint",Count:24b,slot:4,Damage:0s},{id:"minecraft:rotten_flesh",Count:16b,slot:5,Damage:0s},{id:"minecraft:dye",Count:16b,slot:6,Damage:15s}]},legacyFeatures:1b}
:enddata
:endrule

rule:
plugin=vanillaBlocks
number=27
data:
JSON:{blockState:{blockName:"minecraft:crafting_table",properties:{}},buildPass:0}
:enddata
:endrule

rule:
plugin=inventory
number=28
data:
JSON:{blockState:{blockName:"minecraft:chest",properties:{facing:"north"}},buildPass:0,lootLevel:0,teData:{ForgeData:{},Items:[{Slot:3b,id:"minecraft:coal",Count:1b,Damage:1s},{Slot:4b,id:"minecraft:coal",Count:1b,Damage:1s},{Slot:12b,id:"minecraft:coal",Count:1b,Damage:1s},{Slot:16b,id:"minecraft:iron_ingot",Count:1b,Damage:0s},{Slot:20b,id:"minecraft:coal",Count:2b,Damage:1s},{Slot:23b,id:"minecraft:iron_ingot",Count:2b,Damage:0s},{Slot:24b,id:"minecraft:iron_ingot",Count:1b,Damage:0s}],id:"minecraft:chest",Lock:""},inventoryData:{length:7,inventoryContents:[{id:"minecraft:coal",Count:1b,slot:0,Damage:1s},{id:"minecraft:coal",Count:1b,slot:1,Damage:1s},{id:"minecraft:coal",Count:1b,slot:2,Damage:1s},{id:"minecraft:iron_ingot",Count:1b,slot:3,Damage:0s},{id:"minecraft:coal",Count:2b,slot:4,Damage:1s},{id:"minecraft:iron_ingot",Count:2b,slot:5,Damage:0s},{id:"minecraft:iron_ingot",Count:1b,slot:6,Damage:0s}]},legacyFeatures:1b}
:enddata
:endrule

rule:
plugin=inventory
number=29
data:
JSON:{blockState:{blockName:"minecraft:chest",properties:{facing:"north"}},buildPass:0,lootLevel:0,teData:{Items:[{Slot:1b,id:"minecraft:coal",Count:1b,Damage:1s},{Slot:2b,id:"minecraft:coal",Count:2b,Damage:1s},{Slot:8b,id:"ancientwarfarenpc:coin",Count:16b,tag:{metal:"gold"},Damage:0s},{Slot:10b,id:"minecraft:coal",Count:1b,Damage:1s},{Slot:11b,id:"minecraft:coal",Count:1b,Damage:1s},{Slot:13b,id:"minecraft:iron_ingot",Count:4b,Damage:0s},{Slot:17b,id:"ancientwarfarenpc:coin",Count:24b,tag:{metal:"silver"},Damage:0s},{Slot:18b,id:"minecraft:coal",Count:4b,Damage:1s},{Slot:19b,id:"minecraft:coal",Count:1b,Damage:1s},{Slot:20b,id:"minecraft:coal",Count:1b,Damage:1s},{Slot:21b,id:"minecraft:coal",Count:16b,Damage:1s},{Slot:24b,id:"minecraft:iron_ingot",Count:8b,Damage:0s},{Slot:26b,id:"ancientwarfarenpc:coin",Count:32b,tag:{metal:"copper"},Damage:0s}],id:"minecraft:chest",Lock:""},inventoryData:{length:13,inventoryContents:[{id:"minecraft:coal",Count:1b,slot:0,Damage:1s},{id:"minecraft:coal",Count:2b,slot:1,Damage:1s},{id:"ancientwarfarenpc:coin",Count:16b,tag:{metal:"gold"},slot:2,Damage:0s},{id:"minecraft:coal",Count:1b,slot:3,Damage:1s},{id:"minecraft:coal",Count:1b,slot:4,Damage:1s},{id:"minecraft:iron_ingot",Count:4b,slot:5,Damage:0s},{id:"ancientwarfarenpc:coin",Count:24b,tag:{metal:"silver"},slot:6,Damage:0s},{id:"minecraft:coal",Count:4b,slot:7,Damage:1s},{id:"minecraft:coal",Count:1b,slot:8,Damage:1s},{id:"minecraft:coal",Count:1b,slot:9,Damage:1s},{id:"minecraft:coal",Count:16b,slot:10,Damage:1s},{id:"minecraft:iron_ingot",Count:8b,slot:11,Damage:0s},{id:"ancientwarfarenpc:coin",Count:32b,tag:{metal:"copper"},slot:12,Damage:0s}]},legacyFeatures:1b}
:enddata
:endrule

rule:
plugin=vanillaBlocks
number=30
data:
JSON:{blockState:{blockName:"minecraft:cobblestone",properties:{}},buildPass:0}
:enddata
:endrule

rule:
plugin=inventory
number=31
data:
JSON:{blockState:{blockName:"minecraft:furnace",properties:{facing:"east"}},buildPass:0,lootLevel:0,teData:{CookTime:0,BurnTime:0,Items:[],id:"minecraft:furnace",CookTimeTotal:0,Lock:""},inventoryData:{length:0,inventoryContents:[]},legacyFeatures:0b}
:enddata
:endrule

rule:
plugin=blockTile
number=32
data:
JSON:{blockState:{blockName:"ancientwarfarestructure:advanced_spawner",properties:{transparent:"true"}},buildPass:0,teData:{id:"ancientwarfarestructure:advanced_spawner_tile",spawnerSettings:{minDelay:0,spawnDelay:0,lightSensitive:0b,spawnGroups:[{settingsList:[{remainingSpawnCount:1,hostile:1b,forced:1b,customTag:{factionName:"kong"},maxToSpawn:1,entityId:"ancientwarfarenpc:faction.soldier",minToSpawn:1}],groupWeight:1}],playerRange:6,respondToRedstone:0b,inventory:{Size:9,Items:[]},spawnRange:0,transparent:1b,maxDelay:0,xpToDrop:0,mobRange:0,debugMode:0b,maxNearbyMonsters:0}}}
:enddata
:endrule

rule:
plugin=inventory
number=33
data:
JSON:{blockState:{blockName:"minecraft:furnace",properties:{facing:"east"}},buildPass:0,lootLevel:0,teData:{CookTime:0,BurnTime:0,Items:[],id:"minecraft:furnace",CookTimeTotal:0,Lock:""},inventoryData:{length:0,inventoryContents:[]},legacyFeatures:0b}
:enddata
:endrule

rule:
plugin=blockTile
number=34
data:
JSON:{blockState:{blockName:"ancientwarfarestructure:advanced_spawner",properties:{transparent:"true"}},buildPass:0,teData:{id:"ancientwarfarestructure:advanced_spawner_tile",spawnerSettings:{minDelay:0,spawnDelay:0,lightSensitive:0b,spawnGroups:[{settingsList:[{remainingSpawnCount:1,hostile:1b,forced:1b,customTag:{factionName:"kong"},maxToSpawn:1,entityId:"ancientwarfarenpc:faction.soldier",minToSpawn:1}],groupWeight:1}],playerRange:6,respondToRedstone:0b,inventory:{Size:9,Items:[]},spawnRange:0,transparent:1b,maxDelay:0,xpToDrop:0,mobRange:0,debugMode:0b,maxNearbyMonsters:0}}}
:enddata
:endrule

rule:
plugin=vanillaBlocks
number=35
data:
JSON:{blockState:{blockName:"minecraft:anvil",properties:{damage:"0",facing:"north"}},buildPass:0}
:enddata
:endrule

rule:
plugin=blockTile
number=36
data:
JSON:{blockState:{blockName:"ancientwarfarestructure:advanced_spawner",properties:{transparent:"true"}},buildPass:0,teData:{id:"ancientwarfarestructure:advanced_spawner_tile",spawnerSettings:{minDelay:0,spawnDelay:0,lightSensitive:0b,spawnGroups:[{settingsList:[{remainingSpawnCount:1,hostile:1b,forced:1b,customTag:{factionName:"kong"},maxToSpawn:1,entityId:"ancientwarfarenpc:faction.archer.elite",minToSpawn:1}],groupWeight:1}],playerRange:32,respondToRedstone:0b,inventory:{Size:9,Items:[]},spawnRange:0,transparent:1b,maxDelay:0,xpToDrop:0,mobRange:0,debugMode:0b,maxNearbyMonsters:0}}}
:enddata
:endrule

rule:
plugin=vanillaBlocks
number=37
data:
JSON:{blockState:{blockName:"minecraft:torch",properties:{facing:"up"}},buildPass:0}
:enddata
:endrule

rule:
plugin=inventory
number=38
data:
JSON:{blockState:{blockName:"minecraft:furnace",properties:{facing:"east"}},buildPass:0,lootLevel:0,teData:{CookTime:0,BurnTime:0,Items:[],id:"minecraft:furnace",CookTimeTotal:0,Lock:""},inventoryData:{length:0,inventoryContents:[]},legacyFeatures:0b}
:enddata
:endrule

rule:
plugin=inventory
number=39
data:
JSON:{blockState:{blockName:"minecraft:furnace",properties:{facing:"east"}},buildPass:0,lootLevel:0,teData:{CookTime:0,BurnTime:0,Items:[],id:"minecraft:furnace",CookTimeTotal:0,Lock:""},inventoryData:{length:0,inventoryContents:[]},legacyFeatures:0b}
:enddata
:endrule

rule:
plugin=vanillaBlocks
number=40
data:
JSON:{blockState:{blockName:"minecraft:torch",properties:{facing:"east"}},buildPass:0}
:enddata
:endrule

rule:
plugin=vanillaBlocks
number=41
data:
JSON:{blockState:{blockName:"minecraft:torch",properties:{facing:"south"}},buildPass:0}
:enddata
:endrule

rule:
plugin=vanillaBlocks
number=42
data:
JSON:{blockState:{blockName:"minecraft:torch",properties:{facing:"west"}},buildPass:0}
:enddata
:endrule

rule:
plugin=inventory
number=43
data:
JSON:{blockState:{blockName:"minecraft:furnace",properties:{facing:"east"}},buildPass:0,lootLevel:0,teData:{CookTime:0,BurnTime:0,Items:[],id:"minecraft:furnace",CookTimeTotal:0,Lock:""},inventoryData:{length:0,inventoryContents:[]},legacyFeatures:0b}
:enddata
:endrule

rule:
plugin=inventory
number=44
data:
JSON:{blockState:{blockName:"minecraft:furnace",properties:{facing:"east"}},buildPass:0,lootLevel:0,teData:{CookTime:0,BurnTime:0,Items:[],id:"minecraft:furnace",CookTimeTotal:0,Lock:""},inventoryData:{length:0,inventoryContents:[]},legacyFeatures:0b}
:enddata
:endrule

rule:
plugin=vanillaBlocks
number=45
data:
JSON:{blockState:{blockName:"minecraft:stone_slab",properties:{half:"bottom",variant:"wood_old"}},buildPass:0}
:enddata
:endrule

rule:
plugin=vanillaBlocks
number=46
data:
JSON:{blockState:{blockName:"minecraft:log",properties:{variant:"jungle",axis:"x"}},buildPass:0}
:enddata
:endrule

rule:
plugin=vanillaBlocks
number=47
data:
JSON:{blockState:{blockName:"minecraft:vine",properties:{east:"false",south:"true",north:"false",west:"false",up:"false"}},buildPass:0}
:enddata
:endrule

rule:
plugin=blockTile
number=48
data:
JSON:{blockState:{blockName:"ancientwarfarestructure:advanced_spawner",properties:{transparent:"true"}},buildPass:0,teData:{id:"ancientwarfarestructure:advanced_spawner_tile",spawnerSettings:{minDelay:0,spawnDelay:0,lightSensitive:0b,spawnGroups:[{settingsList:[{remainingSpawnCount:1,hostile:1b,forced:1b,customTag:{factionName:"kong"},maxToSpawn:1,entityId:"ancientwarfarenpc:faction.archer.elite",minToSpawn:1}],groupWeight:1}],playerRange:32,respondToRedstone:0b,inventory:{Size:9,Items:[]},spawnRange:0,transparent:1b,maxDelay:0,xpToDrop:0,mobRange:0,debugMode:0b,maxNearbyMonsters:0}}}
:enddata
:endrule

rule:
plugin=blockTile
number=49
data:
JSON:{blockState:{blockName:"ancientwarfarestructure:advanced_spawner",properties:{transparent:"true"}},buildPass:0,teData:{id:"ancientwarfarestructure:advanced_spawner_tile",spawnerSettings:{minDelay:0,spawnDelay:0,lightSensitive:0b,spawnGroups:[{settingsList:[{remainingSpawnCount:1,hostile:1b,forced:1b,customTag:{factionName:"kong"},maxToSpawn:1,entityId:"ancientwarfarenpc:faction.archer.elite",minToSpawn:1}],groupWeight:1}],playerRange:32,respondToRedstone:0b,inventory:{Size:9,Items:[]},spawnRange:0,transparent:1b,maxDelay:0,xpToDrop:0,mobRange:0,debugMode:0b,maxNearbyMonsters:0}}}
:enddata
:endrule

rule:
plugin=vanillaBlocks
number=50
data:
JSON:{blockState:{blockName:"minecraft:ladder",properties:{facing:"north"}},buildPass:0}
:enddata
:endrule

rule:
plugin=vanillaSkull
number=51
data:
JSON:{blockState:{blockName:"minecraft:skull",properties:{nodrop:"false",facing:"up"}},buildPass:0,skullRotation:12,teData:{Rot:12b,id:"minecraft:skull",SkullType:0b}}
:enddata
:endrule

rule:
plugin=vanillaSkull
number=52
data:
JSON:{blockState:{blockName:"minecraft:skull",properties:{nodrop:"false",facing:"up"}},buildPass:0,skullRotation:12,teData:{Rot:12b,id:"minecraft:skull",SkullType:0b}}
:enddata
:endrule

rule:
plugin=blockTile
number=53
data:
JSON:{blockState:{blockName:"ancientwarfarestructure:advanced_spawner",properties:{transparent:"true"}},buildPass:0,teData:{id:"ancientwarfarestructure:advanced_spawner_tile",spawnerSettings:{minDelay:0,spawnDelay:0,lightSensitive:0b,spawnGroups:[{settingsList:[{remainingSpawnCount:1,hostile:1b,forced:1b,customTag:{factionName:"kong"},maxToSpawn:1,entityId:"ancientwarfarenpc:faction.archer.elite",minToSpawn:1}],groupWeight:1}],playerRange:32,respondToRedstone:0b,inventory:{Size:9,Items:[]},spawnRange:0,transparent:1b,maxDelay:0,xpToDrop:0,mobRange:0,debugMode:0b,maxNearbyMonsters:0}}}
:enddata
:endrule

rule:
plugin=vanillaSkull
number=54
data:
JSON:{blockState:{blockName:"minecraft:skull",properties:{nodrop:"false",facing:"up"}},buildPass:0,skullRotation:12,teData:{Rot:12b,id:"minecraft:skull",SkullType:0b}}
:enddata
:endrule

rule:
plugin=vanillaSkull
number=55
data:
JSON:{blockState:{blockName:"minecraft:skull",properties:{nodrop:"false",facing:"up"}},buildPass:0,skullRotation:12,teData:{Rot:12b,id:"minecraft:skull",SkullType:0b}}
:enddata
:endrule

rule:
plugin=blockTile
number=56
data:
JSON:{blockState:{blockName:"ancientwarfarestructure:advanced_spawner",properties:{transparent:"true"}},buildPass:0,teData:{id:"ancientwarfarestructure:advanced_spawner_tile",spawnerSettings:{minDelay:0,spawnDelay:0,lightSensitive:0b,spawnGroups:[{settingsList:[{remainingSpawnCount:1,hostile:1b,forced:1b,customTag:{factionName:"kong"},maxToSpawn:1,entityId:"ancientwarfarenpc:faction.archer.elite",minToSpawn:1}],groupWeight:1}],playerRange:32,respondToRedstone:0b,inventory:{Size:9,Items:[]},spawnRange:0,transparent:1b,maxDelay:0,xpToDrop:0,mobRange:0,debugMode:0b,maxNearbyMonsters:0}}}
:enddata
:endrule

rule:
plugin=vanillaBlocks
number=57
data:
JSON:{blockState:{blockName:"minecraft:leaves",properties:{check_decay:"false",decayable:"true",variant:"jungle"}},buildPass:0}
:enddata
:endrule

rule:
plugin=vanillaBlocks
number=58
data:
JSON:{blockState:{blockName:"minecraft:vine",properties:{east:"true",south:"false",north:"true",west:"false",up:"false"}},buildPass:0}
:enddata
:endrule

rule:
plugin=vanillaBlocks
number=59
data:
JSON:{blockState:{blockName:"minecraft:vine",properties:{east:"false",south:"true",north:"false",west:"true",up:"false"}},buildPass:0}
:enddata
:endrule

#### ENTITIES ####
entity:
plugin=entity
number=0
data:
JSON:{yOffset:0.0f,xOffset:0.22900328f,rotation:36.187927f,mobID:"minecraft:pig",zOffset:0.39403352f,position:1924413784066L,entityData:{HurtByTimestamp:0,ForgeData:{cnpcmarkdata:{marks:[]}},Attributes:[{Base:10.0d,Name:"generic.maxHealth"},{Base:0.0d,Name:"generic.knockbackResistance"},{Base:0.25d,Name:"generic.movementSpeed"},{Base:0.0d,Name:"generic.armor"},{Base:0.0d,Name:"generic.armorToughness"},{Base:1.0d,Name:"forge.swimSpeed"},{Base:16.0d,Name:"generic.followRange"}],Invulnerable:0b,FallFlying:0b,ForcedAge:0,PortalCooldown:0,AbsorptionAmount:0.0f,Saddle:0b,FallDistance:0.0f,InLove:0,DeathTime:0s,ForgeCaps:{"dsurround:emojidata":{as:1,es:0,et:0},"llibrary:extendedentitydatacapability":{"mm:living":{frozenYaw:0.0f,freezeProgress:0.0f,frozenPitch:0.0f,frozenYawHead:0.0f,frozenEntityID:-1,frozenLimbSwingAmount:0.0f,frozenRenderYawOffset:0.0f,frozenSwingProgress:0.0f}},"twilightforest:cap_shield":{permshields:0,tempshields:0}},HandDropChances:[0.085f,0.085f],PersistenceRequired:0b,Age:0,Motion:[0.0d,-0.0784000015258789d,0.0d],Leashed:0b,Health:10.0f,LeftHanded:0b,Air:300s,OnGround:1b,Dimension:0,Rotation:[36.187927f,0.0f],UpdateBlocked:0b,HandItems:[{},{}],ArmorDropChances:[0.085f,0.085f,0.085f,0.085f],Pos:[229.22900327714214d,119.0d,782.3940335340073d],Fire:-1s,ArmorItems:[{},{},{},{}],CanPickUpLoot:0b,HurtTime:0s}}
:enddata
:endentity

entity:
plugin=entity
number=1
data:
JSON:{yOffset:0.0f,xOffset:0.29724273f,rotation:269.06815f,mobID:"minecraft:pig",zOffset:0.5070631f,position:3023925411842L,entityData:{HurtByTimestamp:0,ForgeData:{cnpcmarkdata:{marks:[]}},Attributes:[{Base:10.0d,Name:"generic.maxHealth"},{Base:0.0d,Name:"generic.knockbackResistance"},{Base:0.25d,Name:"generic.movementSpeed"},{Base:0.0d,Name:"generic.armor"},{Base:0.0d,Name:"generic.armorToughness"},{Base:1.0d,Name:"forge.swimSpeed"},{Base:16.0d,Name:"generic.followRange"}],Invulnerable:0b,FallFlying:0b,ForcedAge:0,PortalCooldown:0,AbsorptionAmount:0.0f,Saddle:0b,FallDistance:0.0f,InLove:0,DeathTime:0s,ForgeCaps:{"dsurround:emojidata":{as:0,es:0,et:0},"llibrary:extendedentitydatacapability":{"mm:living":{frozenYaw:0.0f,freezeProgress:0.0f,frozenPitch:0.0f,frozenYawHead:0.0f,frozenEntityID:-1,frozenLimbSwingAmount:0.0f,frozenRenderYawOffset:0.0f,frozenSwingProgress:0.0f}},"twilightforest:cap_shield":{permshields:0,tempshields:0}},HandDropChances:[0.085f,0.085f],PersistenceRequired:0b,Age:0,Motion:[0.0d,-0.0784000015258789d,0.0d],Leashed:0b,Health:10.0f,LeftHanded:0b,Air:300s,OnGround:1b,Dimension:0,Rotation:[269.06815f,0.0f],UpdateBlocked:0b,HandItems:[{},{}],ArmorDropChances:[0.085f,0.085f,0.085f,0.085f],Pos:[233.29724273582588d,119.0d,782.5070631141738d],Fire:-1s,ArmorItems:[{},{},{},{}],CanPickUpLoot:0b,HurtTime:0s}}
:enddata
:endentity

entity:
plugin=entity
number=2
data:
JSON:{yOffset:0.0f,xOffset:0.32445028f,rotation:206.47824f,mobID:"minecraft:pig",zOffset:0.8079436f,position:1649535877122L,entityData:{HurtByTimestamp:0,ForgeData:{cnpcmarkdata:{marks:[]}},Attributes:[{Base:10.0d,Name:"generic.maxHealth"},{Base:0.0d,Name:"generic.knockbackResistance"},{Base:0.25d,Name:"generic.movementSpeed"},{Base:0.0d,Name:"generic.armor"},{Base:0.0d,Name:"generic.armorToughness"},{Base:1.0d,Name:"forge.swimSpeed"},{Base:16.0d,Name:"generic.followRange"}],Invulnerable:0b,FallFlying:0b,ForcedAge:0,PortalCooldown:0,AbsorptionAmount:0.0f,Saddle:0b,FallDistance:0.0f,InLove:0,DeathTime:0s,ForgeCaps:{"dsurround:emojidata":{as:1,es:0,et:0},"llibrary:extendedentitydatacapability":{"mm:living":{frozenYaw:0.0f,freezeProgress:0.0f,frozenPitch:0.0f,frozenYawHead:0.0f,frozenEntityID:-1,frozenLimbSwingAmount:0.0f,frozenRenderYawOffset:0.0f,frozenSwingProgress:0.0f}},"twilightforest:cap_shield":{permshields:0,tempshields:0}},HandDropChances:[0.085f,0.085f],PersistenceRequired:0b,Age:0,Motion:[0.0d,-0.0784000015258789d,0.0d],Leashed:0b,Health:10.0f,LeftHanded:0b,Air:300s,OnGround:1b,Dimension:0,Rotation:[206.47824f,0.0f],UpdateBlocked:0b,HandItems:[{},{}],ArmorDropChances:[0.085f,0.085f,0.085f,0.085f],Pos:[228.32445029704374d,119.0d,782.8079436047087d],Fire:-1s,ArmorItems:[{},{},{},{}],CanPickUpLoot:0b,HurtTime:0s}}
:enddata
:endentity

entity:
plugin=entity
number=3
data:
JSON:{yOffset:0.0f,xOffset:0.55f,rotation:251.11386f,mobID:"minecraft:pig",zOffset:0.825f,position:3573681225732L,entityData:{HurtByTimestamp:0,ForgeData:{cnpcmarkdata:{marks:[]}},Attributes:[{Base:10.0d,Name:"generic.maxHealth"},{Base:0.0d,Name:"generic.knockbackResistance"},{Base:0.25d,Name:"generic.movementSpeed"},{Base:0.0d,Name:"generic.armor"},{Base:0.0d,Name:"generic.armorToughness"},{Base:1.0d,Name:"forge.swimSpeed"},{Base:16.0d,Name:"generic.followRange"}],Invulnerable:0b,FallFlying:0b,ForcedAge:0,PortalCooldown:0,AbsorptionAmount:0.0f,Saddle:0b,FallDistance:0.0f,InLove:0,DeathTime:0s,ForgeCaps:{"dsurround:emojidata":{as:0,es:0,et:0},"llibrary:extendedentitydatacapability":{"mm:living":{frozenYaw:0.0f,freezeProgress:0.0f,frozenPitch:0.0f,frozenYawHead:0.0f,frozenEntityID:-1,frozenLimbSwingAmount:0.0f,frozenRenderYawOffset:0.0f,frozenSwingProgress:0.0f}},"twilightforest:cap_shield":{permshields:0,tempshields:0}},HandDropChances:[0.085f,0.085f],PersistenceRequired:0b,Age:0,Motion:[0.0d,-0.0784000015258789d,0.0d],Leashed:0b,Health:10.0f,LeftHanded:0b,Air:300s,OnGround:1b,Dimension:0,Rotation:[251.11386f,0.0f],UpdateBlocked:0b,HandItems:[{},{}],ArmorDropChances:[0.085f,0.085f,0.085f,0.085f],Pos:[235.55000001192093d,119.0d,784.8249999880791d],Fire:-1s,ArmorItems:[{},{},{},{}],CanPickUpLoot:0b,HurtTime:0s}}
:enddata
:endentity

entity:
plugin=entity
number=4
data:
JSON:{yOffset:0.0f,xOffset:0.75429434f,rotation:63.260666f,mobID:"minecraft:pig",zOffset:0.36756256f,position:1649535877124L,entityData:{HurtByTimestamp:0,ForgeData:{cnpcmarkdata:{marks:[]}},Attributes:[{Base:10.0d,Name:"generic.maxHealth"},{Base:0.0d,Name:"generic.knockbackResistance"},{Base:0.25d,Name:"generic.movementSpeed"},{Base:0.0d,Name:"generic.armor"},{Base:0.0d,Name:"generic.armorToughness"},{Base:1.0d,Name:"forge.swimSpeed"},{Base:16.0d,Name:"generic.followRange"}],Invulnerable:0b,FallFlying:0b,ForcedAge:0,PortalCooldown:0,AbsorptionAmount:0.0f,Saddle:0b,FallDistance:0.0f,InLove:0,DeathTime:0s,ForgeCaps:{"dsurround:emojidata":{as:0,es:0,et:0},"llibrary:extendedentitydatacapability":{"mm:living":{frozenYaw:0.0f,freezeProgress:0.0f,frozenPitch:0.0f,frozenYawHead:0.0f,frozenEntityID:-1,frozenLimbSwingAmount:0.0f,frozenRenderYawOffset:0.0f,frozenSwingProgress:0.0f}},"twilightforest:cap_shield":{permshields:0,tempshields:0}},HandDropChances:[0.085f,0.085f],PersistenceRequired:0b,Age:0,Motion:[0.0d,-0.0784000015258789d,0.0d],Leashed:0b,Health:10.0f,LeftHanded:0b,Air:300s,OnGround:1b,Dimension:0,Rotation:[63.260666f,0.0f],UpdateBlocked:0b,HandItems:[{},{}],ArmorDropChances:[0.085f,0.085f,0.085f,0.085f],Pos:[228.75429435476153d,119.0d,784.3675625499945d],Fire:-1s,ArmorItems:[{},{},{},{}],CanPickUpLoot:0b,HurtTime:0s}}
:enddata
:endentity

