# Ancient Warfare Structure Template File
# Auto-generated structure template file. created on: 8/19/2019 at: 10:23:11
# Lines beginning with # denote comments

header:
version=2.9
name=KongTreehouse3
mods=
size=20,19,26
offset=10,4,25
:endheader

#### VALIDATION ####
validation:
type=ground
survival=false
worldGenEnabled=true
unique=false
preserveBlocks=false
selectionWeight=30
clusterValue=40
minDuplicateDistance=900
dimensionWhiteList=true
dimensionList=0
biomeWhiteList=true
biomeList=minecraft:jungle
leveling=3
fill=2
border=3
blockSwap=false
:endvalidation

#### LAYERS ####
layer: 0
1,1,1,1,1,1,1,1,1,1,1,1,1,1,1,1,1,1,1,1
1,1,1,1,1,1,1,1,1,1,1,1,1,1,1,1,1,1,1,1
1,1,1,1,1,1,1,1,1,1,1,1,1,1,1,1,1,1,1,1
1,1,1,1,1,1,1,1,1,1,1,1,1,1,1,1,1,1,1,1
1,1,1,1,1,1,1,1,1,1,1,1,1,1,1,1,1,1,1,1
1,1,1,1,1,1,1,1,1,1,1,1,1,1,1,1,1,1,1,1
1,1,1,1,1,1,1,1,1,1,1,1,1,1,1,1,1,1,1,1
1,1,1,1,1,1,1,1,1,1,1,1,1,1,1,1,1,1,1,1
1,1,1,1,1,1,1,1,1,1,1,1,1,1,1,1,1,1,1,1
1,1,1,1,1,1,1,1,1,1,1,1,1,1,1,1,1,1,1,1
1,1,1,1,1,1,1,1,1,1,1,1,1,1,1,1,1,1,1,1
1,1,1,1,1,1,1,1,1,1,1,1,1,1,1,1,1,1,1,1
1,1,1,1,1,1,1,1,1,1,1,1,1,1,1,1,1,1,1,1
1,1,1,1,1,1,1,1,1,1,1,1,1,1,1,1,1,1,1,1
1,1,1,1,1,1,1,1,1,1,1,1,1,1,1,1,1,1,1,1
1,1,1,1,1,1,1,1,1,1,1,1,1,1,1,1,1,1,1,1
1,1,1,1,1,1,1,1,1,1,1,1,1,1,1,1,1,1,1,1
1,1,1,1,1,1,1,1,1,1,1,1,1,1,1,1,1,1,1,1
1,1,1,1,1,1,1,1,1,1,1,1,1,1,1,1,1,1,1,1
1,1,1,1,1,1,1,1,1,1,1,1,1,1,1,1,1,1,1,1
1,1,1,1,1,1,1,1,1,1,1,1,1,1,1,1,1,1,1,1
1,1,1,1,1,1,1,1,1,1,1,1,1,1,1,1,1,1,1,1
1,1,1,1,1,1,1,1,1,1,1,1,1,1,1,1,1,1,1,1
1,1,1,1,1,1,1,1,1,1,1,1,1,1,1,1,1,1,1,1
1,1,1,1,1,1,1,1,1,1,1,1,1,1,1,1,1,1,1,1
1,1,1,1,1,1,1,1,1,1,1,1,1,1,1,1,1,1,1,1
:endlayer
layer: 1
1,1,1,1,1,1,1,1,1,1,1,1,1,1,1,1,1,1,1,1
1,1,1,1,1,1,1,1,1,1,1,1,1,1,1,1,1,1,1,1
1,1,1,1,1,1,1,1,1,1,1,1,1,1,1,1,1,1,1,1
1,1,1,1,1,1,1,1,1,1,1,1,1,1,1,1,1,1,1,1
1,1,1,1,1,1,1,1,1,1,1,1,1,1,1,1,1,1,1,1
1,1,1,1,1,1,1,1,1,1,1,1,1,1,1,1,1,1,1,1
1,1,1,1,1,1,1,1,1,1,1,1,1,1,1,1,1,1,1,1
1,1,1,1,1,1,1,1,1,1,1,1,1,1,1,1,1,1,1,1
1,1,1,1,1,1,1,1,1,1,1,1,1,1,1,1,1,1,1,1
1,1,1,1,1,1,1,1,1,1,1,1,1,1,1,1,1,1,1,1
1,1,1,1,1,1,1,1,1,1,1,1,1,1,1,1,1,1,1,1
1,1,1,1,1,1,1,1,1,1,1,1,1,1,1,1,1,1,1,1
1,1,1,1,1,1,1,1,1,1,1,1,1,1,1,1,1,1,1,1
1,1,1,1,1,1,1,1,1,1,1,1,1,1,1,1,1,1,1,1
1,1,1,1,1,1,1,1,1,1,1,1,1,1,1,1,1,1,1,1
1,1,1,1,1,1,1,1,1,1,1,1,1,1,1,1,1,1,1,1
1,1,1,1,1,1,1,1,1,1,1,1,1,1,1,1,1,1,1,1
1,1,1,1,1,1,1,1,1,1,1,1,1,1,1,1,1,1,1,1
1,1,1,1,1,1,1,1,1,1,1,1,1,1,1,1,1,1,1,1
1,1,1,1,1,1,1,1,1,1,1,1,1,1,1,1,1,1,1,1
1,1,1,1,1,1,1,1,1,1,1,1,1,1,1,1,1,1,1,1
1,1,1,1,1,1,1,1,1,1,1,1,1,1,1,1,1,1,1,1
1,1,1,1,1,1,1,1,1,1,1,1,1,1,1,1,1,1,1,1
1,1,1,1,1,1,1,1,1,1,1,1,1,1,1,1,1,1,1,1
1,1,1,1,1,1,1,1,1,1,1,1,1,1,1,1,1,1,1,1
1,1,1,1,1,1,1,1,1,1,1,1,1,1,1,1,1,1,1,1
:endlayer
layer: 2
1,1,1,1,1,1,1,1,1,1,1,1,1,1,1,1,1,1,1,1
1,1,1,1,1,1,1,1,1,1,1,1,1,1,1,1,1,1,1,1
1,1,1,1,1,1,1,1,1,1,1,1,1,1,1,1,1,1,1,1
1,1,1,1,1,1,1,1,1,1,1,1,1,1,1,1,1,1,1,1
1,1,1,1,1,1,1,1,1,1,1,1,1,1,1,1,1,1,1,1
1,1,1,1,1,1,1,1,1,1,1,1,1,1,1,1,1,1,1,1
1,1,1,1,1,1,1,1,1,1,1,1,1,1,1,1,1,1,1,1
1,1,1,1,1,1,1,1,1,1,1,1,1,1,1,1,1,1,1,1
1,1,1,1,1,1,1,1,1,1,1,1,1,1,1,1,1,1,1,1
1,1,1,1,1,1,1,1,1,1,1,1,1,1,1,1,1,1,1,1
1,1,1,1,1,1,1,1,1,1,1,1,1,1,1,1,1,1,1,1
1,1,1,1,1,1,1,1,1,1,1,1,1,1,1,1,1,1,1,1
1,1,1,1,1,1,1,1,1,1,1,1,1,1,1,1,1,1,1,1
1,1,1,1,1,1,1,1,1,1,1,1,1,1,1,1,1,1,1,1
1,1,1,1,1,1,1,1,1,1,1,1,1,1,1,1,1,1,1,1
1,1,1,1,1,1,1,1,1,1,1,1,1,1,1,1,1,1,1,1
1,1,1,1,1,1,1,1,1,1,1,1,1,1,1,1,1,1,1,1
1,1,1,1,1,1,1,1,1,1,1,1,1,1,1,1,1,1,1,1
1,1,1,1,1,1,1,1,1,1,1,1,1,1,1,1,1,1,1,1
1,1,1,1,1,1,1,1,1,1,1,1,1,1,1,1,1,1,1,1
1,1,1,1,1,1,1,1,1,1,1,1,1,1,1,1,1,1,1,1
1,1,1,1,1,1,1,1,1,1,1,1,1,1,1,1,1,1,1,1
1,1,1,1,1,1,1,1,1,1,1,1,1,1,1,1,1,1,1,1
1,1,1,1,1,1,1,1,1,1,1,1,1,1,1,1,1,1,1,1
1,1,1,1,1,1,1,1,1,1,1,1,1,1,1,1,1,1,1,1
1,1,1,1,1,1,1,1,1,1,1,1,1,1,1,1,1,1,1,1
:endlayer
layer: 3
2,2,2,2,2,2,2,2,2,2,2,2,2,2,2,2,2,2,2,2
2,2,2,2,2,2,2,2,2,2,2,2,2,2,2,2,2,2,2,2
2,2,2,2,2,2,2,2,2,2,2,2,2,2,2,2,2,2,2,2
2,2,2,2,2,2,2,2,2,2,2,2,2,2,2,2,2,2,2,2
2,2,2,2,2,2,2,2,2,2,2,2,2,2,2,2,2,2,2,2
2,2,2,2,2,2,2,2,2,2,2,2,2,2,2,2,2,2,2,2
2,2,2,2,2,2,2,2,2,2,2,2,2,2,2,2,2,2,2,2
2,2,2,2,2,2,2,2,2,2,2,2,2,2,2,2,2,2,2,2
2,2,2,1,1,2,2,2,2,2,2,2,2,1,2,2,2,2,2,2
2,2,2,2,2,2,2,2,2,1,1,2,2,2,2,2,2,2,2,2
2,2,2,2,2,2,2,2,2,1,1,2,2,2,2,2,2,2,2,2
2,2,2,2,2,2,2,2,2,2,2,2,2,2,2,2,2,2,2,2
2,2,2,2,2,2,2,2,2,2,2,2,2,2,2,2,2,2,2,2
2,2,2,2,2,2,2,2,2,2,2,2,2,2,2,2,2,2,2,2
2,2,2,2,2,2,2,2,2,2,2,2,2,2,2,2,2,2,2,2
2,2,2,2,2,2,2,2,2,2,2,2,2,2,2,2,2,2,2,2
2,2,2,2,2,2,2,2,2,2,2,2,2,2,2,2,2,2,2,2
2,2,2,1,1,1,2,2,2,2,2,2,2,2,2,2,2,2,2,2
2,2,2,2,1,2,2,2,2,2,2,2,2,1,1,2,2,2,2,2
2,2,2,2,2,2,2,2,2,2,2,2,2,1,1,2,2,2,2,2
2,2,2,2,2,2,2,2,2,2,2,2,2,2,2,2,2,2,2,2
2,2,2,2,2,2,2,2,2,2,2,2,2,2,2,2,2,2,2,2
2,2,2,2,2,2,2,2,2,2,2,2,2,2,2,2,2,2,2,2
2,2,2,2,2,2,2,2,2,2,2,2,2,2,2,2,2,2,2,2
2,2,2,2,2,2,2,2,2,2,2,2,2,2,2,2,2,2,2,2
2,2,2,2,2,2,2,2,2,2,2,2,2,2,2,2,2,2,2,2
:endlayer
layer: 4
0,0,3,0,0,0,3,3,3,3,0,0,0,3,3,3,0,0,0,0
0,0,0,3,3,0,0,3,3,3,3,0,3,3,0,3,3,0,0,0
0,3,3,0,0,3,3,3,3,3,3,0,3,3,3,3,3,0,0,0
0,3,3,3,3,3,0,3,3,3,4,3,3,3,3,0,3,0,3,0
3,3,3,3,3,3,3,0,0,0,3,0,0,0,3,3,0,0,0,3
3,3,3,0,0,3,0,0,0,3,0,3,3,3,0,3,3,3,3,3
0,0,0,3,3,0,3,3,3,0,0,3,3,3,3,3,3,0,3,0
0,0,0,0,3,3,0,0,0,5,3,0,3,0,3,3,3,3,3,0
0,3,3,6,6,3,3,3,3,0,7,3,3,6,3,3,3,0,0,3
3,0,0,3,3,3,3,3,8,6,6,9,10,3,3,3,0,0,0,0
3,3,11,3,0,0,0,12,13,6,6,14,0,3,3,0,0,0,0,0
3,0,0,0,3,3,0,0,0,15,14,14,0,0,0,0,0,0,0,0
3,0,0,3,3,3,0,0,0,15,14,14,3,0,0,3,0,3,0,0
3,3,0,3,3,3,0,0,0,14,14,0,0,0,0,3,0,3,3,3
0,0,3,3,3,3,16,3,0,0,3,16,3,3,0,3,3,3,3,0
3,3,3,3,3,3,0,0,0,3,3,3,3,3,0,0,3,3,3,0
3,3,3,3,3,3,0,0,0,0,0,3,3,3,3,0,0,0,3,0
3,3,3,6,6,6,0,0,0,0,17,3,3,3,7,0,3,0,3,0
0,0,0,0,6,0,0,0,0,0,18,19,3,6,6,9,0,0,0,0
3,3,3,3,3,0,0,0,3,3,0,0,8,6,6,9,0,0,0,0
3,3,3,3,0,3,3,3,3,3,3,0,0,20,20,0,0,0,0,0
3,3,4,0,3,4,3,3,3,3,3,3,0,0,3,0,0,3,4,0
3,3,3,21,22,3,0,3,3,3,11,3,3,3,0,0,0,3,3,3
0,3,0,3,3,3,3,3,3,3,3,11,3,0,0,3,11,22,3,0
0,0,0,3,3,3,0,0,3,3,3,3,3,3,3,3,3,0,3,0
0,0,0,0,0,3,0,0,0,0,0,3,3,0,0,3,0,0,3,0
:endlayer
layer: 5
0,0,0,0,0,0,0,0,0,0,0,0,0,0,0,0,0,0,0,0
0,0,0,0,0,0,0,0,0,0,0,0,0,0,0,0,0,0,0,0
0,0,0,0,0,0,0,0,0,0,0,0,0,0,0,0,0,0,0,0
0,0,0,0,0,0,0,0,0,0,0,0,0,0,0,0,0,0,0,0
0,0,0,0,0,0,0,0,0,0,0,0,0,0,0,0,0,0,0,0
0,0,0,0,0,0,0,0,0,0,0,0,0,0,0,0,0,0,0,0
0,0,0,0,0,0,0,0,0,0,0,0,0,0,0,0,0,0,0,0
0,0,0,0,0,0,0,0,0,0,0,0,0,0,0,0,0,0,0,0
0,0,0,6,6,0,0,0,0,0,7,0,0,6,0,0,0,0,0,0
0,0,0,0,0,0,0,0,8,6,6,14,0,0,0,0,0,0,0,0
0,0,0,0,0,0,0,0,13,6,6,14,14,0,0,0,0,0,0,0
0,0,0,0,0,0,0,15,15,15,14,14,14,0,0,0,0,0,0,0
0,0,0,0,0,0,0,15,15,15,14,14,0,0,0,0,0,0,0,0
0,0,0,0,0,0,0,0,15,15,15,0,0,0,0,0,0,0,0,0
0,0,0,0,0,0,0,0,0,14,15,0,0,0,0,0,0,0,0,0
0,0,0,0,0,0,0,0,0,0,0,0,0,0,0,0,0,0,0,0
0,0,0,0,0,0,0,0,0,0,0,0,0,0,0,0,0,0,0,0
0,0,0,6,6,6,0,0,0,0,0,0,0,0,7,0,0,0,0,0
0,0,0,0,6,0,0,0,0,0,0,0,8,6,6,9,0,0,0,0
0,0,0,0,0,0,0,0,0,0,0,0,8,6,6,9,0,0,0,0
0,0,0,0,0,0,0,0,0,0,0,0,0,20,20,0,0,0,0,0
0,0,0,0,0,0,0,0,0,0,0,0,0,0,0,0,0,0,0,0
0,0,0,0,23,0,0,0,0,0,0,0,0,0,0,0,0,0,0,0
0,0,0,0,0,0,0,0,0,0,0,0,0,0,0,0,0,23,0,0
0,0,0,0,0,0,0,0,0,0,0,0,0,0,0,0,0,0,0,0
0,0,0,0,0,0,0,0,0,0,0,0,0,0,0,0,0,0,0,0
:endlayer
layer: 6
0,0,0,0,0,0,0,0,0,0,0,0,0,0,0,0,0,0,0,0
0,0,0,0,0,0,0,0,0,0,0,0,0,0,0,0,0,0,0,0
0,0,0,0,0,0,0,0,0,0,0,0,0,0,0,0,0,0,0,0
0,0,0,0,0,0,0,0,0,0,0,0,0,0,0,0,0,0,0,0
0,0,0,0,0,0,0,0,0,0,0,0,0,0,0,0,0,0,0,0
0,0,0,0,0,0,0,0,0,0,0,0,0,0,0,0,0,0,0,0
0,0,0,0,0,0,0,0,0,0,0,0,0,0,0,0,0,0,0,0
0,0,0,0,0,0,0,0,0,0,0,0,0,0,0,0,0,0,0,0
0,0,0,6,6,24,24,24,24,24,24,24,24,6,0,0,0,0,0,0
0,0,0,0,0,24,24,24,24,6,6,24,24,24,0,0,0,0,0,0
0,0,0,0,0,24,24,24,13,6,6,24,24,24,0,0,0,0,0,0
0,0,0,0,0,24,24,24,24,24,24,24,24,24,0,0,0,0,0,0
0,0,0,0,0,24,24,24,24,24,24,24,24,24,0,0,0,0,0,0
0,0,0,0,0,24,24,24,24,24,24,24,24,24,0,0,0,0,0,0
0,0,0,0,0,24,24,24,24,24,24,24,24,24,0,0,0,0,0,0
0,0,0,0,0,24,24,24,24,24,24,24,24,24,0,0,0,0,0,0
0,0,0,0,0,24,24,24,24,24,24,24,24,24,0,0,0,0,0,0
0,0,0,6,6,24,24,24,24,24,24,24,24,24,7,0,0,0,0,0
0,0,0,0,0,0,0,0,0,0,0,0,8,6,6,9,0,0,0,0
0,0,0,0,0,0,0,0,0,0,0,0,8,6,6,9,0,0,0,0
0,0,0,0,0,0,0,0,0,0,0,0,0,20,20,0,0,0,0,0
0,0,0,0,0,0,0,0,0,0,0,0,0,0,0,0,0,0,0,0
0,0,0,0,0,0,0,0,0,0,0,0,0,0,0,0,0,0,0,0
0,0,0,0,0,0,0,0,0,0,0,0,0,0,0,0,0,0,0,0
0,0,0,0,0,0,0,0,0,0,0,0,0,0,0,0,0,0,0,0
0,0,0,0,0,0,0,0,0,0,0,0,0,0,0,0,0,0,0,0
:endlayer
layer: 7
0,0,0,0,0,0,0,0,0,0,0,0,0,0,0,0,0,0,0,0
0,0,0,0,0,0,0,0,0,0,0,0,0,0,0,0,0,0,0,0
0,0,0,0,0,0,0,0,0,0,0,0,0,0,0,0,0,0,0,0
0,0,0,0,0,0,0,0,0,0,0,0,0,0,0,0,0,0,0,0
0,0,0,0,0,0,0,0,0,0,0,0,0,0,0,0,0,0,0,0
0,0,0,0,0,0,0,0,0,0,0,0,0,0,0,0,0,0,0,0
0,0,0,0,0,0,0,0,0,0,0,0,0,0,0,0,0,0,0,0
0,0,0,0,0,0,0,0,0,0,0,0,0,0,0,0,0,0,0,0
0,0,0,6,6,6,6,6,6,6,6,6,6,6,0,0,0,0,0,0
0,0,0,0,0,25,26,0,0,6,6,27,0,25,0,0,0,0,0,0
0,0,0,0,0,6,0,0,13,6,6,9,0,6,0,0,0,0,0,0
0,0,0,0,0,25,0,0,0,20,28,0,0,25,0,0,0,0,0,0
0,0,0,0,0,6,29,0,0,0,0,0,0,6,0,0,0,0,0,0
0,0,0,0,0,6,0,0,0,0,0,0,0,6,0,0,0,0,0,0
0,0,0,0,0,25,0,30,0,31,0,0,0,25,0,0,0,0,0,0
0,0,0,0,0,6,0,0,0,0,0,32,0,6,0,0,0,0,0,0
0,0,0,0,0,25,0,0,0,0,0,0,0,25,0,0,0,0,0,0
0,0,0,6,6,6,6,6,6,6,6,6,6,6,7,0,0,0,0,0
0,0,0,0,0,0,0,0,0,0,0,0,8,6,6,9,0,0,0,0
0,0,0,0,0,0,0,0,0,0,0,0,8,6,6,9,0,0,0,0
0,0,0,0,0,0,0,0,0,0,0,0,0,20,20,0,0,0,0,0
0,0,0,0,0,0,0,0,0,0,0,0,0,0,0,0,0,0,0,0
0,0,0,0,0,0,0,0,0,0,0,0,0,0,0,0,0,0,0,0
0,0,0,0,0,0,0,0,0,0,0,0,0,0,0,0,0,0,0,0
0,0,0,0,0,0,0,0,0,0,0,0,0,0,0,0,0,0,0,0
0,0,0,0,0,0,0,0,0,0,0,0,0,0,0,0,0,0,0,0
:endlayer
layer: 8
0,0,0,0,0,0,0,0,0,0,0,0,0,0,0,0,0,0,0,0
0,0,0,0,0,0,0,0,0,0,0,0,0,0,0,0,0,0,0,0
0,0,0,0,0,0,0,0,33,0,0,0,0,0,0,0,0,0,0,0
0,0,0,0,0,0,33,33,33,33,0,0,0,0,0,0,0,0,0,0
0,0,0,0,0,0,33,33,33,33,33,0,0,0,0,0,0,0,0,0
0,0,0,0,0,33,0,33,33,33,0,0,0,0,0,0,0,0,0,0
0,0,0,0,33,33,33,33,6,33,33,33,0,0,0,0,0,0,0,0
0,0,0,0,0,33,33,33,6,0,0,0,0,0,0,0,0,0,0,0
0,0,0,6,6,6,6,6,6,6,6,6,6,6,0,0,0,0,0,0
0,0,0,0,0,34,0,0,0,6,6,27,0,34,0,0,0,0,0,0
0,0,0,0,0,6,0,0,13,6,6,9,0,6,0,0,0,0,0,0
0,0,0,0,0,34,0,0,0,20,20,0,0,34,0,0,0,0,0,0
0,0,0,0,0,6,0,0,0,0,0,0,0,6,0,0,0,0,0,0
0,0,0,0,0,6,0,0,0,0,0,0,0,6,0,0,0,0,0,0
0,0,0,0,0,34,0,0,0,0,0,0,0,34,0,0,0,0,0,0
0,0,0,0,0,6,0,0,0,0,0,0,0,6,0,0,0,0,0,0
0,0,0,0,0,34,0,0,0,0,0,0,0,34,0,0,0,0,0,0
0,0,0,6,6,6,6,25,25,25,25,25,6,6,7,0,0,0,0,0
0,0,0,0,0,0,0,0,0,0,0,0,8,6,6,9,0,0,0,0
0,0,0,0,0,0,0,0,0,0,0,0,8,6,6,9,0,0,0,0
0,0,0,0,0,0,0,0,0,0,0,0,0,20,20,0,0,0,0,0
0,0,0,0,0,0,0,0,0,0,0,0,0,0,0,0,0,0,0,0
0,0,0,0,0,0,0,0,0,0,0,0,0,0,0,0,0,0,0,0
0,0,0,0,0,0,0,0,0,0,0,0,0,0,0,0,0,0,0,0
0,0,0,0,0,0,0,0,0,0,0,0,0,0,0,0,0,0,0,0
0,0,0,0,0,0,0,0,0,0,0,0,0,0,0,0,0,0,0,0
:endlayer
layer: 9
0,0,0,0,0,0,0,0,0,0,0,0,0,0,0,0,0,0,0,0
0,0,0,0,0,0,0,0,0,0,0,0,0,0,0,0,0,0,0,0
0,0,0,0,0,0,0,0,0,0,0,0,0,0,0,0,0,0,0,0
0,0,0,0,0,0,0,0,33,0,0,0,0,0,0,0,0,0,0,0
0,0,0,0,0,0,33,33,33,33,33,0,0,0,0,0,0,0,0,0
0,0,0,0,0,0,33,6,33,33,33,0,0,0,0,0,0,0,0,0
0,0,0,0,0,0,33,33,33,33,33,0,0,0,0,0,0,0,0,0
0,0,0,0,0,0,33,0,33,0,0,0,0,0,0,0,0,0,0,0
0,0,0,6,0,6,6,6,6,6,6,6,6,6,0,0,0,0,0,0
0,0,0,0,0,6,0,0,0,6,6,27,0,6,0,0,0,0,0,0
0,0,0,0,0,6,0,0,8,6,6,9,0,6,0,0,0,0,0,0
0,0,0,0,0,6,0,0,0,20,20,0,0,6,0,0,0,0,0,0
0,0,0,0,0,6,0,0,0,0,0,0,0,6,0,0,0,0,0,0
0,0,0,0,0,6,0,0,0,0,0,0,0,6,0,0,0,0,0,0
0,0,0,0,0,6,0,0,0,0,0,0,0,6,0,0,0,0,0,0
0,33,33,33,33,6,0,0,0,0,0,0,0,6,0,0,0,0,0,0
0,33,33,33,33,6,0,0,0,0,0,0,0,6,0,0,0,0,0,0
0,33,33,6,33,6,6,6,6,6,6,6,6,6,7,0,0,0,0,0
0,33,33,33,33,33,0,0,0,0,0,0,8,6,6,9,0,0,0,0
0,33,33,33,33,0,0,0,0,0,0,0,8,6,6,9,0,0,0,0
0,0,0,0,0,0,0,0,0,0,0,0,0,20,20,0,0,0,0,0
0,0,0,0,0,0,0,0,0,0,0,0,0,0,0,0,0,0,0,0
0,0,0,0,0,0,0,0,0,0,0,0,0,0,0,0,0,0,0,0
0,0,0,0,0,0,0,0,0,0,0,0,0,0,0,0,0,0,0,0
0,0,0,0,0,0,0,0,0,0,0,0,0,0,0,0,0,0,0,0
0,0,0,0,0,0,0,0,0,0,0,0,0,0,0,0,0,0,0,0
:endlayer
layer: 10
0,0,0,0,0,0,0,0,0,0,0,0,0,0,0,0,0,0,0,0
0,0,0,0,0,0,0,0,0,0,0,0,0,0,0,0,0,0,0,0
0,0,0,0,0,0,0,0,0,0,0,0,0,0,0,0,0,0,0,0
0,0,0,0,0,0,0,0,0,0,0,0,0,0,0,0,0,0,0,0
0,0,0,0,0,0,0,0,33,0,0,0,0,0,0,0,0,0,0,0
0,0,0,0,0,0,0,33,33,33,0,0,0,0,0,0,0,0,0,0
0,0,33,33,33,0,33,33,33,0,0,0,0,0,0,0,0,0,0,0
0,33,33,33,33,33,0,0,33,0,0,0,0,0,0,0,0,0,0,0
0,33,33,6,33,35,35,35,35,35,35,35,35,35,0,0,0,0,0,0
0,33,33,33,33,35,24,24,24,6,6,24,24,35,0,0,0,0,0,0
0,0,33,33,33,35,24,24,24,6,6,24,24,35,0,0,0,0,0,0
0,0,0,0,0,35,24,24,24,24,24,24,24,35,0,0,0,0,0,0
0,0,0,0,0,35,24,24,24,24,24,24,24,35,0,0,0,0,0,0
0,0,0,0,0,35,24,24,24,24,24,24,24,35,0,0,0,0,0,0
0,0,0,0,0,35,24,24,24,24,24,24,24,35,0,0,0,0,0,0
0,0,33,33,33,35,24,24,24,24,24,24,24,35,0,0,0,0,0,0
0,33,33,33,33,35,24,24,24,24,24,24,24,35,0,0,0,0,0,0
0,33,33,6,33,35,35,35,35,35,35,35,6,6,7,0,0,0,0,0
0,33,33,33,33,33,0,0,0,0,0,0,8,6,6,9,0,0,0,0
0,33,33,33,33,0,0,0,0,0,0,0,8,6,6,9,0,0,0,0
0,0,0,0,0,0,0,0,0,0,0,0,0,20,20,0,0,0,0,0
0,0,0,0,0,0,0,0,0,0,0,0,0,0,0,0,0,0,0,0
0,0,0,0,0,0,0,0,0,0,0,0,0,0,0,0,0,0,0,0
0,0,0,0,0,0,0,0,0,0,0,0,0,0,0,0,0,0,0,0
0,0,0,0,0,0,0,0,0,0,0,0,0,0,0,0,0,0,0,0
0,0,0,0,0,0,0,0,0,0,0,0,0,0,0,0,0,0,0,0
:endlayer
layer: 11
0,0,0,0,0,0,0,0,0,0,0,0,0,0,0,0,0,0,0,0
0,0,0,0,0,0,0,0,0,0,0,0,0,0,0,0,0,0,0,0
0,0,0,0,0,0,0,0,0,0,0,0,0,0,0,0,0,0,0,0
0,0,0,0,0,0,0,0,0,0,0,0,0,0,0,0,0,0,0,0
0,0,0,0,0,0,0,0,36,0,0,0,0,0,0,0,0,0,0,0
0,0,0,0,0,0,0,0,0,0,0,0,0,0,0,0,0,0,0,0
0,33,33,33,33,0,0,0,0,0,0,0,0,0,0,0,0,0,0,0
0,33,33,33,33,33,0,0,0,0,0,0,0,0,0,0,0,0,0,0
0,33,33,6,33,33,0,0,0,0,7,0,0,0,0,0,0,0,0,0
0,33,33,33,33,33,0,0,8,6,6,9,0,0,0,0,0,0,0,0
0,0,33,33,33,0,0,0,0,6,6,9,0,0,0,0,0,0,0,0
0,0,0,0,0,0,0,0,0,0,20,0,0,0,0,0,0,0,0,0
0,0,0,0,0,0,0,0,0,0,33,0,0,0,0,0,0,0,0,0
0,0,0,0,0,0,0,0,0,33,33,33,33,0,0,0,0,0,0,0
0,0,0,0,0,0,0,0,33,33,33,33,33,0,0,0,0,0,0,0
0,0,0,0,0,0,0,33,33,33,33,33,33,33,0,0,0,0,0,0
0,0,33,33,33,0,0,0,33,33,33,6,33,0,0,0,0,0,0,0
0,0,33,6,33,0,0,0,33,33,33,33,6,7,7,0,0,0,0,0
0,0,0,33,33,0,0,0,0,0,33,0,8,6,6,9,0,0,0,0
0,0,0,37,0,0,0,0,0,0,0,0,8,6,6,9,0,0,0,0
0,0,0,0,0,0,0,0,0,0,0,0,0,20,20,0,0,0,0,0
0,0,0,0,0,0,0,0,0,0,0,0,0,0,0,0,0,0,0,0
0,0,0,0,0,0,0,0,0,0,0,0,0,0,0,0,0,0,0,0
0,0,0,0,0,0,0,0,0,0,0,0,0,0,0,0,0,0,0,0
0,0,0,0,0,0,0,0,0,0,0,0,0,0,0,0,0,0,0,0
0,0,0,0,0,0,0,0,0,0,0,0,0,0,0,0,0,0,0,0
:endlayer
layer: 12
0,0,0,0,0,0,0,0,0,0,0,0,0,0,0,0,0,0,0,0
0,0,0,0,0,0,0,0,0,0,0,0,0,0,0,0,0,0,0,0
0,0,0,0,0,0,0,0,0,0,0,0,0,0,0,0,0,0,0,0
0,0,0,0,0,0,0,0,0,0,0,0,0,0,0,0,0,0,0,0
0,0,0,0,0,0,0,0,0,0,0,0,0,0,0,0,0,0,0,0
0,0,0,0,0,0,0,0,0,0,0,0,0,0,0,0,0,0,0,0
0,0,0,0,0,0,0,0,0,0,33,33,0,0,0,0,0,0,0,0
0,0,0,33,0,0,0,33,33,33,33,33,33,0,0,0,0,0,0,0
0,0,33,6,33,0,0,33,33,33,33,33,33,33,0,0,0,0,0,0
0,0,0,33,33,0,0,33,33,6,6,33,33,33,0,0,0,0,0,0
0,0,38,0,0,0,33,33,33,6,6,33,33,33,33,0,0,0,0,0
0,0,0,0,0,0,33,33,33,33,33,33,33,33,0,0,0,0,0,0
0,0,0,0,0,0,0,33,33,33,33,33,33,0,0,0,0,0,0,0
0,0,0,0,0,0,0,0,33,33,33,33,0,0,0,0,0,0,0,0
0,0,0,0,0,0,0,0,0,33,33,33,0,0,0,0,0,0,0,0
0,0,0,0,0,0,0,0,33,33,6,33,33,0,0,0,0,0,0,0
0,0,0,33,0,0,0,0,0,33,33,33,0,0,0,0,0,0,0,0
0,0,33,33,33,0,0,0,0,0,33,0,0,7,7,0,0,0,0,0
0,0,0,33,0,0,0,0,0,0,0,0,8,6,6,9,0,0,0,0
0,0,0,0,0,0,0,0,0,0,0,0,8,6,6,9,0,0,0,0
0,0,0,0,0,0,0,0,0,0,0,0,0,20,20,0,0,0,0,0
0,0,0,0,0,0,0,0,0,0,0,0,0,0,0,0,0,0,0,0
0,0,0,0,0,0,0,0,0,0,0,0,0,0,0,0,0,0,0,0
0,0,0,0,0,0,0,0,0,0,0,0,0,0,0,0,0,0,0,0
0,0,0,0,0,0,0,0,0,0,0,0,0,0,0,0,0,0,0,0
0,0,0,0,0,0,0,0,0,0,0,0,0,0,0,0,0,0,0,0
:endlayer
layer: 13
0,0,0,0,0,0,0,0,0,0,0,0,0,0,0,0,0,0,0,0
0,0,0,0,0,0,0,0,0,0,0,0,0,0,0,0,0,0,0,0
0,0,0,0,0,0,0,0,0,0,0,0,0,0,0,0,0,0,0,0
0,0,0,0,0,0,0,0,0,0,0,0,0,0,0,0,0,0,0,0
0,0,0,0,0,0,0,0,0,0,0,0,0,0,0,0,0,0,0,0
0,0,0,0,0,0,0,0,0,0,0,0,0,0,0,0,0,0,0,0
0,0,0,0,0,0,0,0,0,33,33,0,0,0,0,0,0,0,0,0
0,0,0,33,0,0,0,0,33,33,33,33,0,0,0,0,0,0,0,0
0,0,33,33,33,0,0,0,33,33,33,33,33,0,0,0,0,0,0,0
0,0,0,33,0,0,33,33,33,33,33,33,33,0,0,0,0,0,0,0
0,0,0,0,0,0,0,33,33,33,6,33,33,33,33,0,0,0,0,0
0,0,0,0,0,0,0,33,33,33,33,33,33,33,0,0,0,0,0,0
0,0,0,0,0,0,0,0,33,33,33,33,33,0,0,0,0,0,0,0
0,0,0,0,0,0,0,0,0,33,33,0,0,0,0,0,0,0,0,0
0,0,0,0,0,0,0,0,0,0,33,0,0,0,0,0,0,0,0,0
0,0,0,0,0,0,0,0,0,33,33,33,0,0,0,0,0,0,0,0
0,0,0,0,0,0,0,0,0,0,33,0,0,0,0,0,0,0,0,0
0,0,0,0,0,0,0,0,0,0,0,0,0,7,7,0,0,0,0,0
0,0,0,0,0,0,0,0,0,0,0,0,8,6,6,9,0,0,0,0
0,0,0,0,0,0,0,0,0,0,0,0,8,6,6,9,0,0,0,0
0,0,0,0,0,0,0,0,0,0,0,0,0,20,20,0,0,0,0,0
0,0,0,0,0,0,0,0,0,0,0,0,0,0,0,0,0,0,0,0
0,0,0,0,0,0,0,0,0,0,0,0,0,0,0,0,0,0,0,0
0,0,0,0,0,0,0,0,0,0,0,0,0,0,0,0,0,0,0,0
0,0,0,0,0,0,0,0,0,0,0,0,0,0,0,0,0,0,0,0
0,0,0,0,0,0,0,0,0,0,0,0,0,0,0,0,0,0,0,0
:endlayer
layer: 14
0,0,0,0,0,0,0,0,0,0,0,0,0,0,0,0,0,0,0,0
0,0,0,0,0,0,0,0,0,0,0,0,0,0,0,0,0,0,0,0
0,0,0,0,0,0,0,0,0,0,0,0,0,0,0,0,0,0,0,0
0,0,0,0,0,0,0,0,0,0,0,0,0,0,0,0,0,0,0,0
0,0,0,0,0,0,0,0,0,0,0,0,0,0,0,0,0,0,0,0
0,0,0,0,0,0,0,0,0,0,0,0,0,0,0,0,0,0,0,0
0,0,0,0,0,0,0,0,0,0,0,0,0,0,0,0,0,0,0,0
0,0,0,0,0,0,0,0,0,0,33,0,0,0,0,0,0,0,0,0
0,0,0,0,0,0,0,0,33,33,33,33,0,0,0,0,0,0,0,0
0,0,0,0,0,0,0,33,33,33,33,33,33,0,0,0,0,0,0,0
0,0,0,0,0,0,0,33,33,33,33,33,33,33,0,0,0,0,0,0
0,0,0,0,0,0,0,0,33,33,33,33,33,0,0,0,0,0,0,0
0,0,0,0,0,0,0,0,0,0,33,33,0,0,0,0,0,0,0,0
0,0,0,0,0,0,0,0,0,0,33,0,0,0,0,0,0,0,0,0
0,0,0,0,0,0,0,0,0,0,0,0,0,0,0,0,0,0,0,0
0,0,0,0,0,0,0,0,0,0,0,0,0,0,0,0,0,0,0,0
0,0,0,0,0,0,0,0,0,0,0,0,0,0,0,0,0,0,0,0
0,0,0,0,0,0,0,0,0,0,0,0,0,7,7,0,0,0,0,0
0,0,0,0,0,0,0,0,0,0,0,0,8,6,6,9,0,0,0,0
0,0,0,0,0,0,0,0,0,0,0,0,8,6,6,9,0,0,0,0
0,0,0,0,0,0,0,0,0,0,0,0,0,20,20,0,0,0,0,0
0,0,0,0,0,0,0,0,0,0,0,0,0,0,0,0,0,0,0,0
0,0,0,0,0,0,0,0,0,0,0,0,0,0,0,0,0,0,0,0
0,0,0,0,0,0,0,0,0,0,0,0,0,0,0,0,0,0,0,0
0,0,0,0,0,0,0,0,0,0,0,0,0,0,0,0,0,0,0,0
0,0,0,0,0,0,0,0,0,0,0,0,0,0,0,0,0,0,0,0
:endlayer
layer: 15
0,0,0,0,0,0,0,0,0,0,0,0,0,0,0,0,0,0,0,0
0,0,0,0,0,0,0,0,0,0,0,0,0,0,0,0,0,0,0,0
0,0,0,0,0,0,0,0,0,0,0,0,0,0,0,0,0,0,0,0
0,0,0,0,0,0,0,0,0,0,0,0,0,0,0,0,0,0,0,0
0,0,0,0,0,0,0,0,0,0,0,0,0,0,0,0,0,0,0,0
0,0,0,0,0,0,0,0,0,0,0,0,0,0,0,0,0,0,0,0
0,0,0,0,0,0,0,0,0,0,0,0,0,0,0,0,0,0,0,0
0,0,0,0,0,0,0,0,0,0,0,0,0,0,0,0,0,0,0,0
0,0,0,0,0,0,0,0,0,0,0,0,0,0,0,0,0,0,0,0
0,0,0,0,0,0,0,0,0,0,0,0,0,0,0,0,0,0,0,0
0,0,0,0,0,0,0,0,0,0,0,0,0,0,0,0,0,0,0,0
0,0,0,0,0,0,0,0,0,0,0,0,0,0,0,0,0,0,0,0
0,0,0,0,0,0,0,0,0,0,0,0,0,0,0,0,0,0,0,0
0,0,0,0,0,0,0,0,0,0,0,0,0,0,0,0,0,0,0,0
0,0,0,0,0,0,0,0,0,0,0,0,0,0,0,0,0,0,0,0
0,0,0,0,0,0,0,0,0,0,0,0,0,0,0,0,0,0,0,0
0,0,0,0,0,0,0,0,0,0,0,0,0,0,0,0,0,0,0,0
0,0,0,0,0,0,0,0,0,0,0,0,0,7,7,0,0,0,0,0
0,0,0,0,0,0,0,0,0,0,0,0,8,6,6,9,0,0,0,0
0,0,0,0,0,0,0,0,0,0,0,0,8,6,6,9,0,0,0,0
0,0,0,0,0,0,0,0,0,0,0,0,0,20,20,0,0,0,0,0
0,0,0,0,0,0,0,0,0,0,0,0,0,0,0,0,0,0,0,0
0,0,0,0,0,0,0,0,0,0,0,0,0,0,0,0,0,0,0,0
0,0,0,0,0,0,0,0,0,0,0,0,0,0,0,0,0,0,0,0
0,0,0,0,0,0,0,0,0,0,0,0,0,0,0,0,0,0,0,0
0,0,0,0,0,0,0,0,0,0,0,0,0,0,0,0,0,0,0,0
:endlayer
layer: 16
0,0,0,0,0,0,0,0,0,0,0,0,0,0,0,0,0,0,0,0
0,0,0,0,0,0,0,0,0,0,0,0,0,0,0,0,0,0,0,0
0,0,0,0,0,0,0,0,0,0,0,0,0,0,0,0,0,0,0,0
0,0,0,0,0,0,0,0,0,0,0,0,0,0,0,0,0,0,0,0
0,0,0,0,0,0,0,0,0,0,0,0,0,0,0,0,0,0,0,0
0,0,0,0,0,0,0,0,0,0,0,0,0,0,0,0,0,0,0,0
0,0,0,0,0,0,0,0,0,0,0,0,0,0,0,0,0,0,0,0
0,0,0,0,0,0,0,0,0,0,0,0,0,0,0,0,0,0,0,0
0,0,0,0,0,0,0,0,0,0,0,0,0,0,0,0,0,0,0,0
0,0,0,0,0,0,0,0,0,0,0,0,0,0,0,0,0,0,0,0
0,0,0,0,0,0,0,0,0,0,0,0,0,0,0,0,0,0,0,0
0,0,0,0,0,0,0,0,0,0,0,0,0,0,0,0,0,0,0,0
0,0,0,0,0,0,0,0,0,0,0,0,0,0,0,0,0,0,0,0
0,0,0,0,0,0,0,0,0,0,0,0,0,33,33,0,0,0,0,0
0,0,0,0,0,0,0,0,0,0,33,33,33,33,33,33,33,33,0,0
0,0,0,0,0,0,0,0,0,33,33,33,33,33,33,33,33,33,33,0
0,0,0,0,0,0,0,0,0,33,33,33,33,33,33,33,33,33,33,0
0,0,0,0,0,0,0,0,0,33,33,33,33,33,33,33,33,33,33,0
0,0,0,0,0,0,0,0,33,33,33,33,33,6,6,33,33,33,33,33
0,0,0,0,0,0,0,0,33,33,33,33,33,6,6,33,33,33,33,33
0,0,0,0,0,0,0,0,0,33,33,33,33,33,33,33,33,33,33,0
0,0,0,0,0,0,0,0,0,33,33,33,33,33,33,33,33,33,33,0
0,0,0,0,0,0,0,0,0,33,33,33,33,33,33,33,33,33,33,0
0,0,0,0,0,0,0,0,0,0,33,33,33,33,33,33,33,33,0,0
0,0,0,0,0,0,0,0,0,0,0,0,0,33,33,0,0,0,0,0
0,0,0,0,0,0,0,0,0,0,0,0,0,0,0,0,0,0,0,0
:endlayer
layer: 17
0,0,0,0,0,0,0,0,0,0,0,0,0,0,0,0,0,0,0,0
0,0,0,0,0,0,0,0,0,0,0,0,0,0,0,0,0,0,0,0
0,0,0,0,0,0,0,0,0,0,0,0,0,0,0,0,0,0,0,0
0,0,0,0,0,0,0,0,0,0,0,0,0,0,0,0,0,0,0,0
0,0,0,0,0,0,0,0,0,0,0,0,0,0,0,0,0,0,0,0
0,0,0,0,0,0,0,0,0,0,0,0,0,0,0,0,0,0,0,0
0,0,0,0,0,0,0,0,0,0,0,0,0,0,0,0,0,0,0,0
0,0,0,0,0,0,0,0,0,0,0,0,0,0,0,0,0,0,0,0
0,0,0,0,0,0,0,0,0,0,0,0,0,0,0,0,0,0,0,0
0,0,0,0,0,0,0,0,0,0,0,0,0,0,0,0,0,0,0,0
0,0,0,0,0,0,0,0,0,0,0,0,0,0,0,0,0,0,0,0
0,0,0,0,0,0,0,0,0,0,0,0,0,0,0,0,0,0,0,0
0,0,0,0,0,0,0,0,0,0,0,0,0,0,0,0,0,0,0,0
0,0,0,0,0,0,0,0,0,0,0,0,0,0,0,0,0,0,0,0
0,0,0,0,0,0,0,0,0,0,0,0,0,33,33,0,0,0,0,0
0,0,0,0,0,0,0,0,0,0,0,33,33,33,33,33,33,0,0,0
0,0,0,0,0,0,0,0,0,0,33,33,33,33,33,33,33,33,0,0
0,0,0,0,0,0,0,0,0,0,33,33,33,33,33,33,33,33,0,0
0,0,0,0,0,0,0,0,0,33,33,33,33,33,33,33,33,33,33,0
0,0,0,0,0,0,0,0,0,33,33,33,33,33,6,33,33,33,33,0
0,0,0,0,0,0,0,0,0,0,33,33,33,33,33,33,33,33,0,0
0,0,0,0,0,0,0,0,0,0,33,33,33,33,33,33,33,33,0,0
0,0,0,0,0,0,0,0,0,0,0,33,33,33,33,33,33,0,0,0
0,0,0,0,0,0,0,0,0,0,0,0,0,33,33,0,0,0,0,0
0,0,0,0,0,0,0,0,0,0,0,0,0,0,0,0,0,0,0,0
0,0,0,0,0,0,0,0,0,0,0,0,0,0,0,0,0,0,0,0
:endlayer
layer: 18
0,0,0,0,0,0,0,0,0,0,0,0,0,0,0,0,0,0,0,0
0,0,0,0,0,0,0,0,0,0,0,0,0,0,0,0,0,0,0,0
0,0,0,0,0,0,0,0,0,0,0,0,0,0,0,0,0,0,0,0
0,0,0,0,0,0,0,0,0,0,0,0,0,0,0,0,0,0,0,0
0,0,0,0,0,0,0,0,0,0,0,0,0,0,0,0,0,0,0,0
0,0,0,0,0,0,0,0,0,0,0,0,0,0,0,0,0,0,0,0
0,0,0,0,0,0,0,0,0,0,0,0,0,0,0,0,0,0,0,0
0,0,0,0,0,0,0,0,0,0,0,0,0,0,0,0,0,0,0,0
0,0,0,0,0,0,0,0,0,0,0,0,0,0,0,0,0,0,0,0
0,0,0,0,0,0,0,0,0,0,0,0,0,0,0,0,0,0,0,0
0,0,0,0,0,0,0,0,0,0,0,0,0,0,0,0,0,0,0,0
0,0,0,0,0,0,0,0,0,0,0,0,0,0,0,0,0,0,0,0
0,0,0,0,0,0,0,0,0,0,0,0,0,0,0,0,0,0,0,0
0,0,0,0,0,0,0,0,0,0,0,0,0,0,0,0,0,0,0,0
0,0,0,0,0,0,0,0,0,0,0,0,0,0,0,0,0,0,0,0
0,0,0,0,0,0,0,0,0,0,0,0,0,33,33,0,0,0,0,0
0,0,0,0,0,0,0,0,0,0,0,33,33,33,33,33,33,0,0,0
0,0,0,0,0,0,0,0,0,0,0,33,33,33,33,33,33,0,0,0
0,0,0,0,0,0,0,0,0,0,33,33,33,33,33,33,33,33,0,0
0,0,0,0,0,0,0,0,0,0,33,33,33,33,33,33,33,33,0,0
0,0,0,0,0,0,0,0,0,0,0,33,33,33,33,33,33,0,0,0
0,0,0,0,0,0,0,0,0,0,0,33,33,33,33,33,33,0,0,0
0,0,0,0,0,0,0,0,0,0,0,0,0,33,33,0,0,0,0,0
0,0,0,0,0,0,0,0,0,0,0,0,0,0,0,0,0,0,0,0
0,0,0,0,0,0,0,0,0,0,0,0,0,0,0,0,0,0,0,0
0,0,0,0,0,0,0,0,0,0,0,0,0,0,0,0,0,0,0,0
:endlayer

#### RULES ####
rule:
plugin=vanillaBlocks
number=1
data:
JSON:{blockState:{blockName:"minecraft:dirt",properties:{variant:"dirt",snowy:"false"}}}
:enddata
:endrule

rule:
plugin=vanillaBlocks
number=2
data:
JSON:{blockState:{blockName:"minecraft:grass",properties:{snowy:"false"}}}
:enddata
:endrule

rule:
plugin=vanillaBlocks
number=3
data:
JSON:{blockState:{blockName:"minecraft:tallgrass",properties:{type:"tall_grass"}}}
:enddata
:endrule

rule:
plugin=vanillaBlocks
number=4
data:
JSON:{blockState:{blockName:"minecraft:red_flower",properties:{type:"poppy"}}}
:enddata
:endrule

rule:
plugin=blockTile
number=5
data:
JSON:{blockState:{blockName:"ancientwarfarestructure:advanced_spawner",properties:{transparent:"true"}},teData:{id:"ancientwarfarestructure:advanced_spawner_tile",spawnerSettings:{minDelay:0,spawnDelay:0,lightSensitive:0b,spawnGroups:[{settingsList:[{remainingSpawnCount:1,hostile:1b,forced:1b,customTag:{factionName:"kong"},maxToSpawn:1,entityId:"ancientwarfarenpc:faction.soldier",minToSpawn:1}],groupWeight:1}],playerRange:16,respondToRedstone:0b,inventory:{Size:9,Items:[]},spawnRange:0,transparent:1b,maxDelay:0,xpToDrop:0,mobRange:0,debugMode:0b,maxNearbyMonsters:0}}}
:enddata
:endrule

rule:
plugin=vanillaBlocks
number=6
data:
JSON:{blockState:{blockName:"minecraft:log",properties:{variant:"jungle",axis:"y"}}}
:enddata
:endrule

rule:
plugin=vine
number=7
data:
JSON:{blockState:{blockName:"minecraft:vine",properties:{east:"false",south:"true",north:"false",west:"false",up:"false"}}}
:enddata
:endrule

rule:
plugin=vine
number=8
data:
JSON:{blockState:{blockName:"minecraft:vine",properties:{east:"true",south:"false",north:"false",west:"false",up:"false"}}}
:enddata
:endrule

rule:
plugin=vine
number=9
data:
JSON:{blockState:{blockName:"minecraft:vine",properties:{east:"false",south:"false",north:"false",west:"true",up:"false"}}}
:enddata
:endrule

rule:
plugin=blockTile
number=10
data:
JSON:{blockState:{blockName:"ancientwarfarestructure:advanced_spawner",properties:{transparent:"true"}},teData:{id:"ancientwarfarestructure:advanced_spawner_tile",spawnerSettings:{minDelay:0,spawnDelay:0,lightSensitive:0b,spawnGroups:[{settingsList:[{remainingSpawnCount:1,hostile:1b,forced:1b,customTag:{factionName:"kong"},maxToSpawn:1,entityId:"ancientwarfarenpc:faction.soldier",minToSpawn:1}],groupWeight:1}],playerRange:16,respondToRedstone:0b,inventory:{Size:9,Items:[]},spawnRange:0,transparent:1b,maxDelay:0,xpToDrop:0,mobRange:0,debugMode:0b,maxNearbyMonsters:0}}}
:enddata
:endrule

rule:
plugin=vanillaBlocks
number=11
data:
JSON:{blockState:{blockName:"minecraft:yellow_flower",properties:{type:"dandelion"}}}
:enddata
:endrule

rule:
plugin=blockTile
number=12
data:
JSON:{blockState:{blockName:"ancientwarfarestructure:advanced_spawner",properties:{transparent:"true"}},teData:{id:"ancientwarfarestructure:advanced_spawner_tile",spawnerSettings:{minDelay:0,spawnDelay:0,lightSensitive:0b,spawnGroups:[{settingsList:[{remainingSpawnCount:1,hostile:1b,forced:1b,customTag:{factionName:"kong"},maxToSpawn:1,entityId:"ancientwarfarenpc:faction.leader",minToSpawn:1}],groupWeight:1}],playerRange:6,respondToRedstone:0b,inventory:{Size:9,Items:[]},spawnRange:0,transparent:1b,maxDelay:0,xpToDrop:0,mobRange:0,debugMode:0b,maxNearbyMonsters:0}}}
:enddata
:endrule

rule:
plugin=vanillaBlocks
number=13
data:
JSON:{blockState:{blockName:"minecraft:ladder",properties:{facing:"west"}}}
:enddata
:endrule

rule:
plugin=vanillaBlocks
number=14
data:
JSON:{blockState:{blockName:"minecraft:leaves",properties:{check_decay:"true",decayable:"false",variant:"jungle"}}}
:enddata
:endrule

rule:
plugin=vanillaBlocks
number=15
data:
JSON:{blockState:{blockName:"minecraft:leaves",properties:{check_decay:"true",decayable:"false",variant:"oak"}}}
:enddata
:endrule

rule:
plugin=vanillaBlocks
number=16
data:
JSON:{blockState:{blockName:"minecraft:red_flower",properties:{type:"houstonia"}}}
:enddata
:endrule

rule:
plugin=blockTile
number=17
data:
JSON:{blockState:{blockName:"ancientwarfarestructure:advanced_spawner",properties:{transparent:"true"}},teData:{id:"ancientwarfarestructure:advanced_spawner_tile",spawnerSettings:{minDelay:0,spawnDelay:0,lightSensitive:0b,spawnGroups:[{settingsList:[{remainingSpawnCount:1,hostile:1b,forced:1b,customTag:{factionName:"kong"},maxToSpawn:1,entityId:"ancientwarfarenpc:faction.soldier",minToSpawn:1}],groupWeight:1}],playerRange:16,respondToRedstone:0b,inventory:{Size:9,Items:[]},spawnRange:0,transparent:1b,maxDelay:0,xpToDrop:0,mobRange:0,debugMode:0b,maxNearbyMonsters:0}}}
:enddata
:endrule

rule:
plugin=blockTile
number=18
data:
JSON:{blockState:{blockName:"ancientwarfarestructure:advanced_spawner",properties:{transparent:"true"}},teData:{id:"ancientwarfarestructure:advanced_spawner_tile",spawnerSettings:{minDelay:0,spawnDelay:0,lightSensitive:0b,spawnGroups:[{settingsList:[{remainingSpawnCount:1,hostile:1b,forced:1b,customTag:{factionName:"kong"},maxToSpawn:1,entityId:"ancientwarfarenpc:faction.soldier",minToSpawn:1}],groupWeight:1}],playerRange:16,respondToRedstone:0b,inventory:{Size:9,Items:[]},spawnRange:0,transparent:1b,maxDelay:0,xpToDrop:0,mobRange:0,debugMode:0b,maxNearbyMonsters:0}}}
:enddata
:endrule

rule:
plugin=blockTile
number=19
data:
JSON:{blockState:{blockName:"ancientwarfarestructure:advanced_spawner",properties:{transparent:"true"}},teData:{id:"ancientwarfarestructure:advanced_spawner_tile",spawnerSettings:{minDelay:0,spawnDelay:0,lightSensitive:0b,spawnGroups:[{settingsList:[{remainingSpawnCount:1,hostile:1b,forced:1b,customTag:{factionName:"kong"},maxToSpawn:1,entityId:"ancientwarfarenpc:faction.soldier",minToSpawn:1}],groupWeight:1}],playerRange:16,respondToRedstone:0b,inventory:{Size:9,Items:[]},spawnRange:0,transparent:1b,maxDelay:0,xpToDrop:0,mobRange:0,debugMode:0b,maxNearbyMonsters:0}}}
:enddata
:endrule

rule:
plugin=vine
number=20
data:
JSON:{blockState:{blockName:"minecraft:vine",properties:{east:"false",south:"false",north:"true",west:"false",up:"false"}}}
:enddata
:endrule

rule:
plugin=blockTile
number=21
data:
JSON:{blockState:{blockName:"ancientwarfarestructure:advanced_spawner",properties:{transparent:"true"}},teData:{id:"ancientwarfarestructure:advanced_spawner_tile",spawnerSettings:{minDelay:0,spawnDelay:0,lightSensitive:0b,spawnGroups:[{settingsList:[{remainingSpawnCount:1,hostile:1b,forced:1b,customTag:{factionName:"kong"},maxToSpawn:1,entityId:"ancientwarfarenpc:faction.soldier",minToSpawn:1}],groupWeight:1}],playerRange:16,respondToRedstone:0b,inventory:{Size:9,Items:[]},spawnRange:0,transparent:1b,maxDelay:0,xpToDrop:0,mobRange:0,debugMode:0b,maxNearbyMonsters:0}}}
:enddata
:endrule

rule:
plugin=vanillaBlocks
number=22
data:
JSON:{blockState:{blockName:"minecraft:double_plant",properties:{half:"lower",variant:"double_grass",facing:"north"}}}
:enddata
:endrule

rule:
plugin=vanillaBlocks
number=23
data:
JSON:{blockState:{blockName:"minecraft:double_plant",properties:{half:"upper",variant:"sunflower",facing:"north"}}}
:enddata
:endrule

rule:
plugin=vanillaBlocks
number=24
data:
JSON:{blockState:{blockName:"minecraft:planks",properties:{variant:"jungle"}}}
:enddata
:endrule

rule:
plugin=vanillaBlocks
number=25
data:
JSON:{blockState:{blockName:"minecraft:fence",properties:{east:"false",south:"false",north:"false",west:"false"}}}
:enddata
:endrule

rule:
plugin=blockTile
number=26
data:
JSON:{blockState:{blockName:"ancientwarfarestructure:advanced_spawner",properties:{transparent:"true"}},teData:{id:"ancientwarfarestructure:advanced_spawner_tile",spawnerSettings:{minDelay:0,spawnDelay:0,lightSensitive:0b,spawnGroups:[{settingsList:[{remainingSpawnCount:1,hostile:1b,forced:1b,customTag:{factionName:"kong"},maxToSpawn:1,entityId:"ancientwarfarenpc:faction.civilian.female",minToSpawn:1}],groupWeight:1}],playerRange:16,respondToRedstone:0b,inventory:{Size:9,Items:[]},spawnRange:0,transparent:1b,maxDelay:0,xpToDrop:0,mobRange:0,debugMode:0b,maxNearbyMonsters:0}}}
:enddata
:endrule

rule:
plugin=vine
number=27
data:
JSON:{blockState:{blockName:"minecraft:vine",properties:{east:"false",south:"false",north:"true",west:"true",up:"false"}}}
:enddata
:endrule

rule:
plugin=inventory
number=28
data:
JSON:{blockState:{blockName:"minecraft:chest",properties:{facing:"south"}},lootLevel:0,teData:{ForgeData:{},Items:[{Slot:19b,id:"ancientwarfarenpc:coin",Count:8b,tag:{metal:"copper"},Damage:0s}],id:"minecraft:chest",Lock:""},inventoryData:{length:1,inventoryContents:[{id:"ancientwarfarenpc:coin",Count:8b,tag:{metal:"copper"},slot:0,Damage:0s}]},legacyFeatures:1b}
:enddata
:endrule

rule:
plugin=inventory
number=29
data:
JSON:{blockState:{blockName:"minecraft:furnace",properties:{facing:"east"}},lootLevel:0,teData:{CookTime:0,BurnTime:0,Items:[],id:"minecraft:furnace",CookTimeTotal:0,Lock:""},inventoryData:{length:0,inventoryContents:[]},legacyFeatures:0b}
:enddata
:endrule

rule:
plugin=vanillaBlocks
number=30
data:
JSON:{blockState:{blockName:"ancientwarfarestructure:fire_pit",properties:{lit:"true",variant:"default"}}}
:enddata
:endrule

rule:
plugin=inventory
number=31
data:
JSON:{blockState:{blockName:"minecraft:chest",properties:{facing:"north"}},lootLevel:0,teData:{ForgeData:{},Items:[{Slot:2b,id:"minecraft:dye",Count:7b,Damage:4s},{Slot:5b,id:"minecraft:string",Count:8b,Damage:0s},{Slot:8b,id:"ancientwarfarenpc:coin",Count:7b,tag:{metal:"copper"},Damage:0s},{Slot:9b,id:"minecraft:emerald",Count:3b,Damage:0s},{Slot:15b,id:"minecraft:rotten_flesh",Count:8b,Damage:0s},{Slot:16b,id:"minecraft:rotten_flesh",Count:6b,Damage:0s},{Slot:18b,id:"minecraft:dye",Count:11b,Damage:3s},{Slot:21b,id:"minecraft:feather",Count:5b,Damage:0s},{Slot:25b,id:"minecraft:bone",Count:8b,Damage:0s}],id:"minecraft:chest",Lock:""},inventoryData:{length:9,inventoryContents:[{id:"minecraft:dye",Count:7b,slot:0,Damage:4s},{id:"minecraft:string",Count:8b,slot:1,Damage:0s},{id:"ancientwarfarenpc:coin",Count:7b,tag:{metal:"copper"},slot:2,Damage:0s},{id:"minecraft:emerald",Count:3b,slot:3,Damage:0s},{id:"minecraft:rotten_flesh",Count:8b,slot:4,Damage:0s},{id:"minecraft:rotten_flesh",Count:6b,slot:5,Damage:0s},{id:"minecraft:dye",Count:11b,slot:6,Damage:3s},{id:"minecraft:feather",Count:5b,slot:7,Damage:0s},{id:"minecraft:bone",Count:8b,slot:8,Damage:0s}]},legacyFeatures:1b}
:enddata
:endrule

rule:
plugin=blockTile
number=32
data:
JSON:{blockState:{blockName:"ancientwarfarestructure:advanced_spawner",properties:{transparent:"true"}},teData:{id:"ancientwarfarestructure:advanced_spawner_tile",spawnerSettings:{minDelay:0,spawnDelay:0,lightSensitive:0b,spawnGroups:[{settingsList:[{remainingSpawnCount:1,hostile:1b,forced:1b,customTag:{factionName:"kong"},maxToSpawn:1,entityId:"ancientwarfarenpc:faction.civilian.female",minToSpawn:1}],groupWeight:1}],playerRange:16,respondToRedstone:0b,inventory:{Size:9,Items:[]},spawnRange:0,transparent:1b,maxDelay:0,xpToDrop:0,mobRange:0,debugMode:0b,maxNearbyMonsters:0}}}
:enddata
:endrule

rule:
plugin=vanillaBlocks
number=33
data:
JSON:{blockState:{blockName:"minecraft:leaves",properties:{check_decay:"false",decayable:"true",variant:"jungle"}}}
:enddata
:endrule

rule:
plugin=vanillaBlocks
number=34
data:
JSON:{blockState:{blockName:"minecraft:torch",properties:{facing:"up"}}}
:enddata
:endrule

rule:
plugin=vanillaBlocks
number=35
data:
JSON:{blockState:{blockName:"minecraft:stone_slab",properties:{half:"bottom",variant:"wood_old"}}}
:enddata
:endrule

rule:
plugin=blockTile
number=36
data:
JSON:{blockState:{blockName:"ancientwarfarestructure:advanced_spawner",properties:{transparent:"true"}},teData:{id:"ancientwarfarestructure:advanced_spawner_tile",spawnerSettings:{minDelay:0,spawnDelay:0,lightSensitive:0b,spawnGroups:[{settingsList:[{remainingSpawnCount:1,hostile:1b,forced:1b,customTag:{factionName:"kong"},maxToSpawn:1,entityId:"ancientwarfarenpc:faction.archer.elite",minToSpawn:1}],groupWeight:1}],playerRange:32,respondToRedstone:0b,inventory:{Size:9,Items:[]},spawnRange:0,transparent:1b,maxDelay:0,xpToDrop:0,mobRange:0,debugMode:0b,maxNearbyMonsters:0}}}
:enddata
:endrule

rule:
plugin=blockTile
number=37
data:
JSON:{blockState:{blockName:"ancientwarfarestructure:advanced_spawner",properties:{transparent:"true"}},teData:{id:"ancientwarfarestructure:advanced_spawner_tile",spawnerSettings:{minDelay:0,spawnDelay:0,lightSensitive:0b,spawnGroups:[{settingsList:[{remainingSpawnCount:1,hostile:1b,forced:1b,customTag:{factionName:"kong"},maxToSpawn:1,entityId:"ancientwarfarenpc:faction.archer.elite",minToSpawn:1}],groupWeight:1}],playerRange:32,respondToRedstone:0b,inventory:{Size:9,Items:[]},spawnRange:0,transparent:1b,maxDelay:0,xpToDrop:0,mobRange:0,debugMode:0b,maxNearbyMonsters:0}}}
:enddata
:endrule

rule:
plugin=blockTile
number=38
data:
JSON:{blockState:{blockName:"ancientwarfarestructure:advanced_spawner",properties:{transparent:"true"}},teData:{id:"ancientwarfarestructure:advanced_spawner_tile",spawnerSettings:{minDelay:0,spawnDelay:0,lightSensitive:0b,spawnGroups:[{settingsList:[{remainingSpawnCount:1,hostile:1b,forced:1b,customTag:{factionName:"kong"},maxToSpawn:1,entityId:"ancientwarfarenpc:faction.archer.elite",minToSpawn:1}],groupWeight:1}],playerRange:32,respondToRedstone:0b,inventory:{Size:9,Items:[]},spawnRange:0,transparent:1b,maxDelay:0,xpToDrop:0,mobRange:0,debugMode:0b,maxNearbyMonsters:0}}}
:enddata
:endrule

#### ENTITIES ####
entity:
plugin=entity
number=0
data:
JSON:{yOffset:0.0f,xOffset:0.5f,rotation:102.05584f,mobID:"primitivemobs:harpy",zOffset:0.5f,position:268435458L,entityData:{HurtByTimestamp:0,ForgeData:{},Attributes:[{Base:20.0d,Name:"generic.maxHealth"},{Base:0.0d,Name:"generic.knockbackResistance"},{Base:0.20000000298023224d,Name:"generic.movementSpeed"},{Base:0.0d,Name:"generic.armor"},{Base:0.0d,Name:"generic.armorToughness"},{Base:1.0d,Name:"forge.swimSpeed"},{Base:16.0d,Modifiers:[{UUIDMost:-960796599643979329L,UUIDLeast:-7469621959238401193L,Amount:0.014333625624342108d,Operation:1,Name:"Random spawn bonus"}],Name:"generic.followRange"},{Base:2.0d,Name:"generic.attackDamage"},{Base:0.5000000059604645d,Name:"generic.flyingSpeed"}],Invulnerable:0b,FallFlying:0b,PortalCooldown:0,AbsorptionAmount:0.0f,FallDistance:0.0f,DeathTime:0s,ForgeCaps:{"dsurround:emojidata":{as:0,es:0,et:0},"llibrary:extendedentitydatacapability":{"mm:living":{frozenYaw:0.0f,freezeProgress:0.0f,frozenPitch:0.0f,frozenYawHead:0.0f,frozenEntityID:-1,frozenLimbSwingAmount:0.0f,frozenRenderYawOffset:0.0f,frozenSwingProgress:0.0f}}},HandDropChances:[0.085f,0.085f],PersistenceRequired:0b,Motion:[0.0d,-0.0784000015258789d,0.0d],Leashed:0b,Health:20.0f,LeftHanded:0b,Air:300s,OnGround:1b,Dimension:0,Rotation:[102.05584f,0.0f],UpdateBlocked:0b,HandItems:[{},{}],Variant:1,ArmorDropChances:[0.085f,0.085f,0.085f,0.085f],Pos:[404.5d,111.0d,784.5d],Fire:-1s,ArmorItems:[{},{},{},{}],CanPickUpLoot:0b,HurtTime:0s}}
:enddata
:endentity

entity:
plugin=entity
number=1
data:
JSON:{yOffset:0.0f,xOffset:0.5f,rotation:268.93152f,mobID:"primitivemobs:harpy",zOffset:0.5f,position:5222948667410L,entityData:{HurtByTimestamp:0,ForgeData:{},Attributes:[{Base:20.0d,Name:"generic.maxHealth"},{Base:0.0d,Name:"generic.knockbackResistance"},{Base:0.20000000298023224d,Name:"generic.movementSpeed"},{Base:0.0d,Name:"generic.armor"},{Base:0.0d,Name:"generic.armorToughness"},{Base:1.0d,Name:"forge.swimSpeed"},{Base:16.0d,Modifiers:[{UUIDMost:2344318698960339515L,UUIDLeast:-7540555201714512978L,Amount:-0.005131047914601239d,Operation:1,Name:"Random spawn bonus"}],Name:"generic.followRange"},{Base:2.0d,Name:"generic.attackDamage"},{Base:0.5000000059604645d,Name:"generic.flyingSpeed"}],Invulnerable:0b,FallFlying:0b,PortalCooldown:0,AbsorptionAmount:0.0f,FallDistance:0.0f,DeathTime:0s,ForgeCaps:{"dsurround:emojidata":{as:0,es:0,et:0},"llibrary:extendedentitydatacapability":{"mm:living":{frozenYaw:0.0f,freezeProgress:0.0f,frozenPitch:0.0f,frozenYawHead:0.0f,frozenEntityID:-1,frozenLimbSwingAmount:0.0f,frozenRenderYawOffset:0.0f,frozenSwingProgress:0.0f}}},HandDropChances:[0.085f,0.085f],PersistenceRequired:0b,Motion:[0.0d,-0.0784000015258789d,0.0d],Leashed:0b,Health:20.0f,LeftHanded:0b,Air:300s,OnGround:1b,Dimension:0,Rotation:[268.93152f,0.0f],UpdateBlocked:0b,HandItems:[{},{}],Variant:0,ArmorDropChances:[0.085f,0.085f,0.085f,0.085f],Pos:[423.5d,111.0d,800.5d],Fire:-1s,ArmorItems:[{},{},{},{}],CanPickUpLoot:0b,HurtTime:0s}}
:enddata
:endentity

