# Ancient Warfare Structure Template File
# Auto-generated structure template file. created on: 8/19/2019 at: 10:23:12
# Lines beginning with # denote comments

header:
version=2.9
name=KongTreehouse8
mods=
size=25,35,21
offset=15,3,20
:endheader

#### VALIDATION ####
validation:
type=ground
survival=false
worldGenEnabled=true
unique=false
preserveBlocks=false
selectionWeight=30
clusterValue=40
minDuplicateDistance=900
dimensionWhiteList=true
dimensionList=0
biomeWhiteList=true
biomeList=minecraft:jungle
leveling=3
fill=2
border=3
blockSwap=false
:endvalidation

#### LAYERS ####
layer: 0
1,1,1,1,1,1,1,1,1,1,1,1,1,1,1,1,1,1,1,1,1,1,1,1,1
1,1,1,1,1,1,1,1,1,1,1,1,1,1,1,1,1,1,1,1,1,1,1,1,1
1,1,1,1,1,1,1,1,1,1,1,1,1,1,1,1,1,1,1,1,1,1,1,1,1
1,1,1,1,1,1,1,1,1,1,1,1,1,1,1,1,1,1,1,1,1,1,1,1,1
1,1,1,1,1,1,1,1,1,1,1,1,1,1,1,1,1,1,1,1,1,1,1,1,1
1,1,1,1,1,1,1,1,1,1,1,1,1,1,1,1,1,1,1,1,1,1,1,1,1
1,1,1,1,1,1,1,1,1,1,1,1,1,1,1,1,1,1,1,1,1,1,1,1,1
1,1,1,1,1,1,1,1,1,1,1,1,1,1,1,1,1,1,1,1,1,1,1,1,1
1,1,1,1,1,1,1,1,1,1,1,1,1,1,1,1,1,1,1,1,1,1,1,1,1
1,1,1,1,1,1,1,1,1,1,1,1,1,1,1,1,1,1,1,1,1,1,1,1,1
1,1,1,1,1,1,1,1,1,1,1,1,1,1,1,1,1,1,1,1,1,1,1,1,1
1,1,1,1,1,1,1,1,1,1,1,1,1,1,1,1,1,1,1,1,1,1,1,1,1
1,1,1,1,1,1,1,1,1,1,1,1,1,1,1,1,1,1,1,1,1,1,1,1,1
1,1,1,1,1,1,1,1,1,1,1,1,1,1,1,1,1,1,1,1,1,1,1,1,1
1,1,1,1,1,1,1,1,1,1,1,1,1,1,1,1,1,1,1,1,1,1,1,1,1
1,1,1,1,1,1,1,1,1,1,1,1,1,1,1,1,1,1,1,1,1,1,1,1,1
1,1,1,1,1,1,1,1,1,1,1,1,1,1,1,1,1,1,1,1,1,1,1,1,1
1,1,1,1,1,1,1,1,1,1,1,1,1,1,1,1,1,1,1,1,1,1,1,1,1
1,1,1,1,1,1,1,1,1,1,1,1,1,1,1,1,1,1,1,1,1,1,1,1,1
1,1,1,1,1,1,1,1,1,1,1,1,1,1,1,1,1,1,1,1,1,1,1,1,1
1,1,1,1,1,1,1,1,1,1,1,1,1,1,1,1,1,1,1,1,1,1,1,1,1
:endlayer
layer: 1
1,1,1,1,1,1,1,1,1,1,1,1,1,1,1,1,1,1,1,1,1,1,1,1,1
1,1,1,1,1,1,1,1,1,1,1,1,1,1,1,1,1,1,1,1,1,1,1,1,1
1,1,1,1,1,1,1,1,1,1,1,1,1,1,1,1,1,1,1,1,1,1,1,1,1
1,1,1,1,1,1,1,1,1,1,1,1,1,1,1,1,1,1,1,1,1,1,1,1,1
1,1,1,1,1,1,1,1,1,1,1,1,1,1,1,1,1,1,1,1,1,1,1,1,1
1,1,1,1,1,1,1,1,1,1,1,1,1,1,1,1,1,1,1,1,1,1,1,1,1
1,1,1,1,1,1,1,1,1,1,1,1,1,1,1,1,1,1,1,1,1,1,1,1,1
1,1,1,1,1,1,1,1,1,1,1,1,1,1,1,1,1,1,1,1,1,1,1,1,1
1,1,1,1,1,1,1,1,1,1,1,1,1,1,1,1,1,1,1,1,1,1,1,1,1
1,1,1,1,1,1,1,1,1,1,1,1,1,1,1,1,1,1,1,1,1,1,1,1,1
1,1,1,1,1,1,1,1,1,1,1,1,1,1,1,1,1,1,1,1,1,1,1,1,1
1,1,1,1,1,1,1,1,1,1,1,1,1,1,1,1,1,1,1,1,1,1,1,1,1
1,1,1,1,1,1,1,1,1,1,1,1,1,1,1,1,1,1,1,1,1,1,1,1,1
1,1,1,1,1,1,1,1,1,1,1,1,1,1,1,1,1,1,1,1,1,1,1,1,1
1,1,1,1,1,1,1,1,1,1,1,1,1,1,1,1,1,1,1,1,1,1,1,1,1
1,1,1,1,1,1,1,1,1,1,1,1,1,1,1,1,1,1,1,1,1,1,1,1,1
1,1,1,1,1,1,1,1,1,1,1,1,1,1,1,1,1,1,1,1,1,1,1,1,1
1,1,1,1,1,1,1,1,1,1,1,1,1,1,1,1,1,1,1,1,1,1,1,1,1
1,1,1,1,1,1,1,1,1,1,1,1,1,1,1,1,1,1,1,1,1,1,1,1,1
1,1,1,1,1,1,1,1,1,1,1,1,1,1,1,1,1,1,1,1,1,1,1,1,1
1,1,1,1,1,1,1,1,1,1,1,1,1,1,1,1,1,1,1,1,1,1,1,1,1
:endlayer
layer: 2
2,2,2,2,2,2,2,2,2,2,2,2,2,2,2,2,2,2,2,2,2,2,2,2,2
2,2,2,2,2,2,2,2,2,2,2,2,2,2,2,2,2,2,2,2,2,2,2,2,2
2,2,2,1,2,2,2,1,2,2,2,2,2,2,2,2,2,2,2,2,2,2,2,2,2
2,2,2,2,2,2,2,2,2,2,2,2,2,2,1,1,2,1,1,1,1,1,2,2,2
2,2,2,2,2,2,2,2,2,2,2,2,1,1,1,1,1,1,1,1,1,1,1,2,2
2,2,2,2,2,2,2,2,2,1,1,1,1,1,1,1,1,1,1,1,1,1,1,1,2
2,2,2,2,2,2,1,1,1,1,1,1,1,1,1,1,1,1,1,1,1,1,1,1,2
2,2,2,2,2,2,1,1,1,1,1,1,1,1,1,1,1,1,1,1,1,1,1,2,2
2,2,2,1,1,1,1,1,1,1,1,1,1,1,1,1,1,1,1,1,1,1,2,2,2
2,1,1,1,1,1,1,1,1,1,1,1,1,1,1,1,1,1,1,1,1,1,2,2,2
2,1,1,1,1,1,1,1,1,1,1,1,1,1,1,1,1,1,1,1,1,1,2,2,2
2,1,1,1,1,1,1,1,1,1,1,1,1,1,1,1,1,1,1,1,1,2,2,2,2
2,1,1,1,1,1,1,1,1,1,1,1,1,1,1,1,1,1,1,1,1,1,2,2,2
2,1,1,1,1,1,1,1,1,1,1,1,1,1,1,1,1,1,1,1,1,1,2,2,2
2,2,1,1,1,1,1,1,1,1,1,1,1,1,1,1,1,1,1,1,1,1,2,2,2
2,2,1,1,1,1,1,1,1,1,1,1,1,1,1,1,1,1,1,1,1,1,1,2,2
2,2,1,1,1,1,1,2,2,1,2,2,1,1,1,1,1,1,1,1,1,1,1,1,2
2,2,2,1,1,1,1,1,2,2,2,2,2,2,1,1,1,1,1,1,1,1,1,2,2
2,2,2,1,2,2,2,2,2,2,2,2,2,2,2,2,2,2,2,2,1,1,2,1,2
2,2,2,2,2,2,1,2,2,2,2,2,2,2,2,2,2,2,2,2,2,2,2,2,2
2,2,2,2,2,2,2,2,2,2,2,2,2,2,2,2,2,2,2,2,2,2,2,2,2
:endlayer
layer: 3
3,0,3,3,0,0,4,4,5,0,3,0,3,3,0,0,0,0,4,0,0,0,0,0,0
0,5,5,3,0,4,4,4,4,5,0,3,3,0,0,0,3,0,4,3,3,0,3,3,3
3,5,6,7,0,4,4,7,4,4,5,0,4,5,3,0,3,4,4,4,3,3,8,3,3
0,3,5,9,0,5,4,4,4,4,8,5,4,4,2,2,4,2,7,2,2,2,3,3,0
3,0,3,3,5,3,3,4,5,4,4,4,2,2,2,2,2,2,2,2,2,2,2,3,5
0,3,5,5,0,3,10,10,0,2,2,2,2,2,1,2,7,7,1,1,2,2,2,2,0
0,0,0,3,0,3,7,7,2,2,2,1,2,2,2,2,7,7,1,2,2,2,2,2,5
0,4,3,3,11,3,7,7,2,2,2,1,1,2,2,2,1,2,1,2,2,2,2,4,0
4,4,8,2,2,2,2,2,2,2,2,1,1,1,2,2,2,2,2,2,2,1,4,4,5
4,12,2,2,2,2,2,2,2,2,2,7,7,1,1,1,2,2,2,1,2,2,4,0,0
4,2,2,2,2,1,2,2,1,2,2,7,7,1,1,1,2,1,2,2,2,7,4,4,3
4,2,2,2,2,2,2,2,2,2,2,1,1,1,1,1,1,1,1,2,2,4,4,4,0
0,2,2,2,1,2,1,2,2,2,2,2,1,1,1,1,7,7,1,2,2,2,0,0,5
3,2,2,2,1,7,7,2,2,2,2,1,2,1,1,1,7,7,1,2,2,2,3,0,3
0,0,2,2,1,7,7,2,2,2,2,2,2,2,1,1,1,1,1,7,2,2,0,3,0
3,0,2,2,2,1,2,2,2,2,2,2,2,2,2,2,1,1,1,2,2,2,2,0,3
0,3,2,2,2,2,2,3,0,2,0,3,2,2,2,1,2,2,2,2,2,2,2,2,3
5,0,0,2,2,2,2,2,3,3,0,5,3,3,2,2,2,13,2,2,2,2,2,4,0
0,3,0,2,14,14,4,4,3,8,3,5,0,5,3,3,4,4,4,0,2,2,4,7,4
5,0,3,0,4,4,7,4,4,5,0,3,3,0,3,3,3,4,3,3,3,0,0,14,14
0,0,0,3,3,4,4,3,4,3,3,0,5,3,0,0,5,0,5,3,0,5,3,3,0
:endlayer
layer: 4
0,0,0,0,0,0,0,0,0,0,0,0,0,0,0,0,0,0,0,0,0,0,0,0,0
0,0,0,10,0,0,4,0,0,0,0,0,0,0,0,0,0,0,0,0,0,0,0,0,0
0,0,6,7,0,0,4,4,4,0,0,0,0,0,0,0,0,0,4,0,0,0,0,0,0
0,0,0,9,0,0,0,4,0,0,0,0,0,4,4,8,0,4,4,4,4,0,0,0,0
0,0,0,0,0,0,0,0,0,0,0,4,4,14,14,14,3,14,14,14,3,0,3,0,0
0,0,0,0,0,0,10,10,0,4,3,5,14,14,7,14,7,7,2,2,3,4,0,3,0
0,0,0,0,0,6,7,7,15,4,4,2,14,14,14,14,7,7,2,0,4,4,4,8,0
0,0,0,0,0,6,7,7,3,4,4,7,2,14,14,14,2,3,2,4,4,4,4,0,0
0,0,0,4,0,5,9,9,0,14,14,7,2,2,14,14,14,0,4,4,4,7,4,0,0
4,4,4,4,5,3,3,14,14,14,14,7,7,2,2,7,14,3,4,2,4,4,0,0,0
4,4,4,0,3,2,0,14,7,14,14,7,7,2,1,2,14,2,4,4,4,4,4,0,0
0,3,3,5,0,0,3,14,14,14,14,2,2,2,2,2,1,2,2,0,4,4,0,0,0
0,3,5,3,2,10,2,14,14,14,4,4,2,2,2,1,7,7,2,4,3,8,0,0,0
0,8,5,0,2,7,7,15,14,14,3,2,4,1,2,2,7,7,2,14,4,5,0,0,0
0,0,5,3,2,7,7,3,0,5,0,5,4,4,2,1,1,2,2,4,14,4,0,0,0
0,0,0,5,0,2,3,3,5,3,3,5,3,3,0,0,2,2,2,14,14,3,0,0,0
0,0,5,0,3,3,3,0,0,5,0,0,5,3,0,2,3,4,4,4,0,3,5,0,0
0,0,0,5,0,3,4,4,0,0,0,0,0,0,8,3,4,4,8,3,0,5,8,0,0
0,0,0,8,0,14,4,4,0,0,0,0,0,0,0,0,0,4,0,0,0,0,0,4,0
0,0,0,0,0,4,4,4,0,0,0,0,0,0,0,0,0,0,0,0,0,0,0,0,0
0,0,0,0,0,0,0,0,0,0,0,0,0,0,0,0,0,0,0,0,0,0,0,0,0
:endlayer
layer: 5
0,0,0,0,0,0,0,0,0,0,0,0,0,0,0,0,0,0,0,0,0,0,0,0,0
0,0,0,10,0,0,0,0,0,0,0,0,0,0,0,0,0,0,0,0,0,0,0,0,0
0,0,16,7,17,0,0,0,0,0,0,0,0,0,0,0,0,0,0,0,0,0,0,0,0
0,0,0,9,0,0,0,0,0,0,0,0,0,0,0,0,0,0,4,0,0,0,0,0,0
0,0,0,0,0,0,0,0,0,0,0,0,0,0,4,0,18,10,0,0,0,0,0,0,0
0,0,0,0,0,0,10,10,0,0,0,0,0,0,14,4,7,7,5,0,0,0,0,0,0
0,0,0,0,0,6,7,7,15,0,4,14,0,0,4,6,7,7,3,0,0,0,0,0,0
0,0,0,0,0,6,7,7,15,14,14,14,4,0,0,0,5,9,0,0,0,4,0,0,0
0,0,0,0,0,0,9,9,0,14,19,20,5,0,0,0,0,0,0,0,4,4,4,0,0
0,4,0,0,0,0,0,0,0,14,14,7,7,14,14,4,0,0,0,4,4,4,0,0,0
0,0,0,0,0,5,0,0,14,14,12,7,7,14,7,14,21,3,0,0,4,0,0,0,0
0,0,0,0,0,0,0,0,0,14,14,14,5,14,14,0,2,3,3,0,0,0,0,0,0
0,0,0,0,0,10,3,0,0,0,0,0,14,14,14,2,7,7,15,0,0,0,0,0,0
0,0,0,0,22,7,7,15,0,0,0,0,4,7,4,4,7,7,15,0,0,0,0,0,0
0,0,0,0,3,7,7,15,0,0,0,0,0,4,4,2,2,9,4,4,0,0,0,0,0
0,0,0,0,0,3,9,0,0,0,0,0,0,0,0,0,0,0,3,0,0,0,0,0,0
0,0,0,0,0,0,0,0,0,0,0,0,0,0,0,3,0,0,0,0,0,0,0,0,0
0,0,0,0,0,0,0,0,0,0,0,0,0,0,0,0,0,0,0,0,0,0,0,0,0
0,0,0,0,0,0,0,0,0,0,0,0,0,0,0,0,0,0,0,0,0,0,0,0,0
0,0,0,0,0,0,0,0,0,0,0,0,0,0,0,0,0,0,0,0,0,0,0,0,0
0,0,0,0,0,0,0,0,0,0,0,0,0,0,0,0,0,0,0,0,0,0,0,0,0
:endlayer
layer: 6
0,0,0,0,0,0,0,0,0,0,0,0,0,0,0,0,0,0,0,0,0,0,0,0,0
0,0,0,10,0,0,0,0,0,0,0,0,0,0,0,0,0,0,0,0,0,0,0,0,0
0,0,0,7,15,0,0,0,0,0,0,0,0,0,0,0,0,0,0,0,0,0,0,0,0
0,0,0,9,0,0,0,0,0,0,0,0,0,0,0,0,0,0,0,0,0,0,0,0,0
0,0,0,0,0,0,0,0,0,0,0,0,0,0,23,0,10,10,0,0,0,0,0,0,0
0,0,0,0,0,0,10,18,0,0,0,0,0,0,0,6,7,7,15,0,0,0,0,0,0
0,0,0,0,0,6,7,7,15,0,4,0,0,0,0,6,7,7,15,0,0,0,0,0,0
0,0,0,0,0,4,7,7,4,14,14,14,4,0,0,0,24,9,0,0,0,0,0,0,0
0,0,0,0,0,0,24,9,0,14,0,0,0,0,0,0,0,0,0,0,0,4,0,0,0
0,25,0,0,0,0,0,0,0,14,26,7,7,14,0,0,0,0,0,0,0,0,0,0,0
0,0,0,0,0,0,0,0,14,14,14,7,7,14,14,0,0,0,0,0,0,0,0,0,0
0,0,0,0,0,0,0,0,0,14,14,14,14,0,0,0,10,10,0,0,0,0,0,0,0
0,0,0,0,0,10,10,0,0,0,0,0,14,14,14,3,7,7,15,0,0,0,0,0,0
0,0,0,0,6,7,7,17,0,0,0,0,0,4,0,16,7,7,15,0,0,0,0,0,0
0,0,0,0,6,7,7,15,0,0,0,0,0,0,27,3,9,9,0,0,0,0,0,0,0
0,0,0,0,0,28,9,0,0,0,0,0,0,0,0,0,0,4,4,4,0,0,0,0,0
0,0,0,0,0,0,0,0,0,0,0,0,0,0,0,0,0,0,0,0,0,0,0,0,0
0,0,0,0,0,0,0,0,0,0,0,0,0,0,0,0,0,0,0,0,0,0,0,0,0
0,0,0,0,0,0,0,0,0,0,0,0,0,0,0,0,0,0,0,0,0,0,0,0,0
0,0,0,0,0,0,0,0,0,0,0,0,0,0,0,0,0,0,0,0,0,0,0,0,0
0,0,0,0,0,0,0,0,0,0,0,0,0,0,0,0,0,0,0,0,0,0,0,0,0
:endlayer
layer: 7
0,0,0,0,0,0,0,0,0,0,0,0,0,0,0,0,0,0,0,0,0,0,0,0,0
0,0,0,10,0,0,0,0,0,0,0,0,0,0,0,0,0,0,0,0,0,0,0,0,0
0,0,29,7,15,0,0,0,0,0,0,0,0,0,0,0,0,0,0,0,0,0,0,0,0
0,0,0,9,0,0,0,0,0,0,0,0,0,0,0,0,0,0,0,0,0,0,0,0,0
0,0,0,0,0,0,0,0,0,0,0,0,0,0,0,0,10,10,0,0,0,0,0,0,0
0,0,0,0,0,0,10,0,0,0,0,0,0,0,0,6,7,7,15,0,0,0,0,0,0
0,0,0,0,0,4,7,7,14,0,0,0,0,0,0,6,7,7,15,0,0,0,0,0,0
0,0,0,0,4,4,7,7,4,0,4,14,14,0,0,0,9,9,0,0,0,0,0,0,0
0,0,0,0,14,4,4,9,0,4,0,0,0,0,0,0,0,0,0,0,0,30,0,0,0
0,0,0,0,0,14,0,0,0,14,0,7,7,12,14,0,0,0,0,0,0,0,0,0,0
0,0,0,0,0,0,0,0,14,14,26,7,7,14,14,0,0,0,0,0,0,0,0,0,0
0,0,0,0,0,0,0,0,0,14,19,13,14,14,0,0,10,10,0,0,0,0,0,0,0
0,0,0,0,0,10,10,0,0,14,14,14,0,14,0,31,7,7,15,0,0,0,0,0,0
0,0,0,0,6,7,7,0,0,0,0,0,0,0,0,6,7,7,15,0,0,0,0,0,0
0,0,0,0,6,7,7,15,0,0,0,0,0,0,0,0,4,13,4,4,4,0,0,0,0
0,0,0,0,0,28,9,0,0,0,0,0,0,0,0,0,4,13,12,12,4,0,0,0,0
0,0,0,0,0,0,0,0,0,0,0,0,0,0,0,0,4,4,4,4,0,0,0,0,0
0,0,0,0,0,0,0,0,0,0,0,0,0,0,0,0,0,0,0,0,0,0,0,0,0
0,0,0,0,0,0,0,0,0,0,0,0,0,0,0,0,0,0,0,0,0,0,0,0,0
0,0,0,0,0,0,0,0,0,0,0,0,0,0,0,0,0,0,0,0,0,0,0,0,0
0,0,0,0,0,0,0,0,0,0,0,0,0,0,0,0,0,0,0,0,0,0,0,0,0
:endlayer
layer: 8
0,0,0,0,0,0,0,0,0,0,0,0,0,0,0,0,0,0,0,0,0,0,0,0,0
0,0,4,4,4,0,0,0,0,0,0,0,0,0,0,0,0,0,0,0,0,0,0,0,0
0,0,14,7,14,4,0,0,0,0,0,0,0,0,0,0,0,0,0,0,0,0,0,0,0
0,4,14,7,14,4,0,0,0,0,0,0,0,0,0,0,0,0,0,0,0,0,0,0,0
0,0,14,14,14,0,0,0,0,0,0,0,0,0,0,0,10,10,0,0,0,0,0,0,0
0,0,0,0,0,4,14,14,4,0,0,0,0,0,0,29,7,7,15,0,0,0,0,0,0
0,0,0,0,4,4,7,7,14,0,0,0,0,0,0,6,7,7,15,0,0,0,0,0,0
0,0,0,4,4,4,7,7,15,0,4,4,14,4,0,0,9,9,0,0,0,0,0,0,0
0,0,0,0,14,4,4,9,0,14,0,0,0,14,0,0,0,0,0,0,0,0,0,0,0
0,0,0,0,14,14,0,0,0,14,0,7,7,14,14,0,0,0,0,0,0,0,0,0,0
0,0,0,0,0,0,0,0,32,14,0,7,7,14,14,0,0,0,0,0,0,0,0,0,0
0,0,0,0,0,0,0,0,0,14,0,33,13,14,0,0,10,34,0,0,0,0,0,0,0
0,0,0,0,0,10,10,0,0,14,14,14,14,0,0,31,7,7,15,0,0,0,0,0,0
0,0,0,0,6,7,7,4,4,4,0,0,0,0,0,4,7,7,15,4,4,14,0,0,0
0,0,0,0,6,7,7,15,4,0,0,0,0,0,0,0,4,4,4,4,13,4,0,0,0
0,0,0,0,0,9,9,0,0,0,0,0,0,0,0,0,0,4,4,7,12,4,0,0,0
0,0,0,0,0,0,0,0,0,0,0,0,0,0,0,0,4,4,4,4,4,0,0,0,0
0,0,0,0,0,0,0,0,0,0,0,0,0,0,0,0,0,4,4,0,0,0,0,0,0
0,0,0,0,0,0,0,0,0,0,0,0,0,0,0,0,0,0,0,0,0,0,0,0,0
0,0,0,0,0,0,0,0,0,0,0,0,0,0,0,0,0,0,0,0,0,0,0,0,0
0,0,0,0,0,0,0,0,0,0,0,0,0,0,0,0,0,0,0,0,0,0,0,0,0
:endlayer
layer: 9
0,0,0,0,0,0,0,0,0,0,0,0,0,0,0,0,0,0,0,0,0,0,0,0,0
0,0,0,10,0,0,0,0,0,0,0,0,0,0,0,0,0,0,0,0,0,0,0,0,0
0,0,6,7,0,0,0,0,0,0,0,0,0,0,0,4,4,0,0,0,0,0,0,0,0
0,4,14,4,14,0,0,0,0,0,0,0,0,0,0,0,4,0,0,0,0,0,0,0,0
0,4,4,7,4,0,0,0,0,0,0,0,0,0,0,0,4,4,4,0,0,0,0,0,0
0,4,4,4,4,0,4,10,0,0,0,0,0,0,0,6,7,7,4,4,4,0,0,0,0
0,0,4,4,0,6,7,7,15,0,0,0,0,0,0,6,7,7,15,4,4,0,0,0,0
0,0,0,0,0,4,7,7,15,0,14,4,4,0,0,0,9,9,0,0,0,0,0,0,0
0,0,0,0,0,4,9,9,0,14,4,13,4,4,0,0,0,0,0,0,0,0,0,0,0
0,0,0,0,0,0,0,0,0,14,0,7,7,14,0,0,0,0,0,0,0,0,0,0,0
0,0,0,0,0,0,0,0,0,14,0,7,7,12,14,0,0,0,0,0,0,0,0,0,0
0,0,0,0,0,0,4,4,0,14,0,0,33,19,14,0,10,34,0,0,0,0,0,0,0
0,0,0,0,0,10,4,4,4,4,14,14,14,14,14,31,7,7,15,0,0,14,0,0,0
0,0,0,0,6,7,7,12,12,4,0,0,0,0,0,4,7,7,15,0,4,14,14,0,0
0,0,0,0,6,7,7,4,4,4,0,0,0,0,0,4,4,4,4,4,14,14,0,0,0
0,0,0,0,0,9,9,0,4,4,0,0,0,0,0,0,4,4,4,4,14,14,0,0,0
0,0,0,0,0,0,0,0,0,0,0,0,0,0,0,0,0,4,4,4,14,14,0,0,0
0,0,0,0,0,0,0,0,0,0,0,0,0,0,0,0,0,0,0,4,0,0,0,0,0
0,0,0,0,0,0,0,0,0,0,0,0,0,0,0,0,0,0,0,0,0,0,0,0,0
0,0,0,0,0,0,0,0,0,0,0,0,0,0,0,0,0,0,0,0,0,0,0,0,0
0,0,0,0,0,0,0,0,0,0,0,0,0,0,0,0,0,0,0,0,0,0,0,0,0
:endlayer
layer: 10
0,0,0,0,0,0,0,0,0,0,0,0,0,0,0,0,0,0,0,0,0,0,0,0,0
0,0,0,10,0,0,0,0,0,0,0,0,0,0,0,4,4,4,0,0,0,0,0,0,0
0,0,6,7,35,0,0,0,0,0,0,0,0,4,4,12,13,4,0,0,0,0,0,0,0
0,0,4,0,0,0,0,0,0,0,0,0,0,4,4,4,13,4,4,4,0,0,0,0,0
0,4,4,4,4,0,0,0,0,0,0,0,0,0,4,4,13,4,4,4,4,4,4,0,0
0,0,4,4,0,0,10,10,0,0,0,0,0,0,0,6,7,7,4,13,12,4,0,0,0
0,0,0,0,0,6,7,7,15,0,14,0,0,0,0,6,7,7,12,12,4,4,0,0,0
0,0,0,0,0,6,7,7,15,14,14,4,4,4,0,0,9,9,4,4,4,0,0,0,0
0,0,0,0,0,0,9,9,0,14,4,14,14,14,0,0,0,0,0,4,0,0,0,0,0
0,0,0,0,0,0,0,0,0,14,4,7,7,14,14,0,0,0,0,0,0,0,0,0,0
0,0,0,0,0,0,0,0,0,14,0,7,7,36,14,4,0,0,0,0,0,0,0,0,0
0,0,0,0,0,0,0,0,0,14,0,0,0,0,14,0,10,10,0,0,0,0,0,0,0
0,0,0,0,0,10,10,4,0,14,14,14,14,14,14,31,7,7,15,0,0,0,14,0,0
0,0,0,0,29,7,7,4,4,4,0,4,0,0,0,6,7,7,15,0,0,14,14,4,0
0,0,0,0,6,7,7,15,4,0,0,0,0,0,0,0,4,9,0,0,14,14,14,0,0
0,0,0,4,4,13,4,4,0,0,0,0,0,0,0,0,0,0,0,4,4,0,0,0,0
0,0,4,4,12,13,4,0,0,0,0,0,0,0,0,0,0,0,0,0,0,0,0,0,0
0,0,0,4,4,4,4,0,0,0,0,0,0,0,0,0,0,0,0,0,0,0,0,0,0
0,0,0,4,0,4,0,0,0,0,0,0,0,0,0,0,0,0,0,0,0,0,0,0,0
0,0,0,0,0,0,0,0,0,0,0,0,0,0,0,0,0,0,0,0,0,0,0,0,0
0,0,0,0,0,0,0,0,0,0,0,0,0,0,0,0,0,0,0,0,0,0,0,0,0
:endlayer
layer: 11
0,0,0,0,0,0,0,0,0,0,0,0,0,0,4,4,4,0,0,0,0,0,0,0,0
0,0,0,10,0,0,0,0,0,0,0,0,0,4,4,13,4,0,0,0,0,0,0,0,0
0,0,4,7,0,0,0,0,0,0,0,0,0,0,4,7,4,4,0,0,0,0,0,0,0
0,0,0,0,0,0,0,0,0,0,0,0,0,0,4,4,4,0,0,0,0,0,0,0,0
0,0,0,0,0,0,0,0,0,0,0,0,0,0,0,0,4,4,0,0,0,0,0,0,0
0,0,0,0,0,0,10,10,0,0,4,0,0,0,0,6,7,7,4,4,4,0,0,0,0
0,0,0,0,0,6,7,7,15,4,4,4,0,0,0,6,7,7,4,4,0,0,0,0,0
0,0,0,0,0,6,7,7,15,4,13,4,14,14,14,0,9,9,0,0,0,0,0,0,0
0,0,0,0,0,0,9,9,0,14,13,14,13,19,14,0,0,0,0,0,0,0,0,0,0
0,0,0,0,0,0,0,0,0,14,12,7,7,36,14,4,0,0,0,0,0,0,0,0,0
0,0,0,0,0,0,0,0,0,14,4,7,7,0,14,4,4,0,0,0,0,0,0,0,0
0,0,0,0,0,0,0,0,0,14,0,0,0,0,14,4,10,10,0,0,0,0,0,0,0
0,0,0,0,0,10,10,0,0,14,14,14,14,14,0,31,7,7,15,0,0,0,0,0,0
0,0,0,0,6,7,7,15,0,0,0,4,0,0,0,6,7,7,35,0,0,0,4,0,0
0,0,0,0,6,7,7,15,0,0,0,0,0,0,0,0,9,9,0,0,0,0,0,0,0
0,0,0,0,0,4,9,0,0,0,0,0,0,0,0,0,0,0,0,0,0,0,0,0,0
0,0,0,0,4,4,0,0,0,0,0,0,0,0,0,0,0,0,0,0,0,0,0,0,0
0,0,0,4,4,4,4,0,0,0,0,0,0,0,0,0,0,0,0,0,0,0,0,0,0
0,0,0,0,0,0,0,0,0,0,0,0,0,0,0,0,0,0,0,0,0,0,0,0,0
0,0,0,0,0,0,0,0,0,0,0,0,0,0,0,0,0,0,0,0,0,0,0,0,0
0,0,0,0,0,0,0,0,0,0,0,0,0,0,0,0,0,0,0,0,0,0,0,0,0
:endlayer
layer: 12
0,0,0,0,0,0,0,0,0,0,0,0,0,0,0,0,0,0,0,0,0,0,0,0,0
0,4,4,4,0,0,0,0,0,0,0,0,0,0,0,4,0,0,0,0,0,0,0,0,0
0,4,7,7,0,0,0,0,0,0,0,0,0,0,0,4,0,0,0,0,0,0,0,0,0
0,4,4,4,0,4,0,4,0,0,0,0,0,0,0,0,0,0,0,0,0,0,0,0,0
0,0,0,4,0,4,4,4,4,4,4,0,0,4,0,0,10,10,0,4,0,0,0,0,0
0,0,0,0,0,0,10,4,0,4,4,0,0,4,0,6,7,7,15,4,0,0,0,0,0
0,0,0,0,0,29,7,7,15,0,4,4,0,4,4,4,7,7,15,0,0,0,0,0,0
0,0,0,0,0,6,7,7,15,0,4,14,14,14,14,0,9,9,0,0,0,0,0,0,0
0,0,0,0,0,4,4,4,0,0,14,13,20,0,14,4,0,0,4,4,0,0,0,0,0
0,0,0,0,4,4,4,0,14,14,14,7,7,0,14,4,4,4,4,0,0,0,0,0,0
0,0,0,0,0,0,4,0,14,14,4,7,7,0,14,4,4,4,0,0,0,0,0,0,0
0,0,0,0,0,0,0,0,0,14,4,24,0,0,14,4,10,10,0,0,0,0,0,0,0
0,0,0,0,0,10,10,0,0,14,14,14,14,14,14,37,7,7,15,0,0,0,0,0,0
0,0,0,4,4,7,7,4,4,4,4,4,4,0,4,6,7,7,4,0,0,0,0,0,0
0,0,0,4,6,7,7,15,0,4,0,0,0,0,0,0,9,9,4,4,0,0,0,0,0
0,0,0,0,0,9,9,4,0,0,0,0,0,0,0,0,4,0,0,0,0,0,0,0,0
0,0,0,0,4,0,0,0,0,0,0,0,0,4,4,4,4,0,0,0,0,0,0,0,0
0,0,0,0,0,0,0,0,0,0,0,0,0,0,0,0,0,0,0,0,0,0,0,0,0
0,0,0,0,0,0,0,0,0,0,0,0,0,0,0,0,0,0,0,0,0,0,0,0,0
0,0,0,0,0,0,0,0,0,0,0,0,0,0,0,0,0,0,0,0,0,0,0,0,0
0,0,0,0,0,0,0,0,0,0,0,0,0,0,0,0,0,0,0,0,0,0,0,0,0
:endlayer
layer: 13
0,0,0,0,0,0,0,0,0,0,0,0,0,0,0,0,0,0,0,0,0,0,0,0,0
0,4,4,4,0,0,4,0,4,0,0,0,0,0,0,0,0,0,0,0,0,0,0,0,0
4,4,4,7,4,4,4,4,4,4,0,0,0,4,0,0,0,0,0,4,0,0,0,0,0
0,4,4,13,4,13,4,13,4,4,4,0,4,14,4,0,0,0,4,4,4,0,0,0,0
0,0,4,13,4,12,12,13,12,12,14,0,14,13,14,0,10,4,4,13,4,4,0,0,0
0,0,0,4,4,4,4,13,14,14,4,4,14,13,14,6,7,7,12,12,4,4,0,0,0
0,0,0,4,0,4,7,7,14,0,4,4,14,12,12,12,7,7,15,4,4,4,0,0,0
0,0,0,0,0,4,7,7,14,0,14,14,4,4,14,14,9,9,4,4,4,4,0,0,0
0,0,4,4,4,4,13,9,14,14,14,20,0,0,14,13,14,4,13,12,4,4,0,0,0
0,0,4,4,12,12,13,4,12,12,12,7,7,0,14,12,12,13,12,4,4,0,0,0,0
0,0,4,4,4,4,13,4,14,13,14,7,7,0,14,14,14,13,4,0,0,0,0,0,0
0,0,4,4,4,4,4,0,0,14,14,13,14,14,14,14,14,13,4,0,0,0,0,0,0
0,0,4,4,4,4,10,4,14,13,14,13,12,14,12,12,7,7,4,0,0,0,0,0,0
0,0,4,12,12,7,7,12,12,12,12,4,4,4,13,4,7,7,12,4,4,0,0,0,0
0,0,4,13,4,7,7,4,4,13,4,0,0,0,4,4,13,4,13,12,4,0,0,0,0
0,0,4,4,0,9,4,7,4,4,0,0,4,4,4,4,13,4,4,4,4,0,0,0,0
0,0,0,0,0,0,4,4,4,0,0,0,4,12,12,12,13,4,0,4,0,0,0,0,0
0,0,0,0,0,0,0,4,4,4,0,0,4,14,14,14,14,4,0,0,0,0,0,0,0
0,0,0,0,0,0,0,0,4,4,0,0,0,0,4,0,4,0,0,0,0,0,0,0,0
0,0,0,0,0,0,0,0,0,0,0,0,0,0,0,0,0,0,0,0,0,0,0,0,0
0,0,0,0,0,0,0,0,0,0,0,0,0,0,0,0,0,0,0,0,0,0,0,0,0
:endlayer
layer: 14
0,0,0,0,0,0,0,0,0,0,0,0,0,0,0,0,0,0,0,0,0,0,0,0,0
0,0,6,4,4,0,38,38,38,38,38,38,38,38,38,38,38,0,0,0,0,0,0,0,0
0,4,39,7,40,38,41,42,42,42,42,42,42,42,42,42,40,38,40,4,0,0,0,0,0
0,0,4,42,42,42,42,42,42,42,42,42,42,42,42,42,42,42,42,40,4,0,0,0,0
0,0,4,42,42,42,42,42,42,42,42,42,42,42,42,42,42,42,42,40,4,4,0,0,0
0,0,41,42,42,42,42,42,42,42,42,42,42,42,42,42,7,7,42,38,40,0,0,0,0
0,0,41,42,42,42,7,7,42,42,42,42,42,42,42,42,7,7,42,42,40,0,0,0,0
0,0,41,42,42,42,7,7,42,42,42,42,42,42,42,42,42,42,42,42,40,0,0,0,0
0,0,41,42,42,42,42,42,42,42,20,10,0,0,42,42,42,42,42,42,40,0,0,0,0
0,0,41,42,42,42,42,42,42,42,42,7,7,19,42,42,42,42,42,42,40,0,0,0,0
0,0,41,42,42,42,42,42,42,42,42,7,7,38,42,42,42,42,42,42,40,0,0,0,0
0,0,41,42,42,42,42,42,42,42,42,42,42,42,42,42,42,42,42,42,40,0,0,0,0
0,0,41,42,42,42,42,42,42,42,42,42,42,42,42,42,7,7,42,42,40,0,0,0,0
0,0,41,43,42,7,7,42,42,42,42,42,42,42,42,42,7,7,42,40,43,0,0,0,0
0,0,4,41,42,7,7,42,42,42,42,42,42,42,42,42,42,42,42,40,4,0,0,0,0
0,0,0,41,43,42,42,42,42,42,42,42,42,42,42,42,42,42,40,43,0,0,0,0,0
0,0,0,0,41,43,43,7,42,42,42,42,42,42,42,42,40,43,40,0,0,0,0,0,0
0,0,0,0,0,0,4,14,7,42,43,43,43,43,43,43,43,4,0,0,0,0,0,0,0
0,0,0,0,0,0,44,44,44,44,44,0,0,0,0,4,4,0,0,0,0,0,0,0,0
0,0,0,0,0,0,44,44,44,44,44,0,0,0,0,0,0,0,0,0,0,0,0,0,0
0,0,0,0,0,0,0,0,44,0,0,0,0,0,0,0,0,0,0,0,0,0,0,0,0
:endlayer
layer: 15
0,0,0,0,0,0,0,0,0,0,0,0,0,0,0,0,0,0,0,0,0,0,0,0,0
0,0,0,10,0,0,42,42,42,42,42,42,42,42,42,42,42,0,0,0,0,0,0,0,0
0,45,6,7,42,42,0,0,41,20,0,0,0,0,0,0,0,42,42,4,0,0,0,0,0
0,0,0,42,0,0,46,0,0,0,0,8,47,0,0,0,0,0,8,42,0,0,0,0,0
0,0,0,42,8,0,0,0,0,0,0,0,0,0,0,0,10,10,0,42,4,0,0,0,0
0,0,42,0,0,0,10,10,0,0,0,0,48,0,49,6,7,7,15,0,42,0,0,0,0
0,0,42,0,0,6,7,7,15,50,0,0,0,0,0,0,7,7,15,0,42,0,0,0,0
0,0,42,0,0,0,7,7,15,0,0,8,0,0,0,0,0,9,0,0,42,0,0,0,0
0,0,42,0,0,0,9,37,0,0,0,10,0,14,4,0,0,41,20,0,42,0,0,0,0
0,0,42,0,8,0,0,0,0,0,6,7,7,14,14,0,0,0,51,0,42,0,0,0,0
0,0,42,0,0,0,0,0,0,0,6,7,7,4,0,0,0,0,0,0,42,0,0,0,0
0,0,42,0,0,0,0,0,0,0,0,9,4,4,0,0,10,10,0,0,42,0,0,0,0
0,0,42,0,0,10,10,0,52,0,0,0,0,0,0,6,7,7,15,0,42,0,0,0,0
0,0,42,42,6,7,7,15,0,0,0,0,0,0,0,6,7,7,8,42,42,0,0,0,0
0,0,4,42,6,7,7,15,0,0,0,0,42,0,0,0,9,8,7,42,0,0,0,0,0
0,0,0,42,0,53,9,0,0,0,0,0,42,0,0,0,0,0,0,42,0,0,0,0,0
0,0,0,0,42,42,42,42,0,0,0,0,42,0,0,0,0,42,42,0,0,0,0,0,0
0,0,0,0,0,4,14,44,7,14,4,42,42,42,42,42,42,4,0,0,0,0,0,0,0
0,0,0,0,0,0,4,44,44,44,0,0,0,0,0,4,4,0,0,0,0,0,0,0,0
0,0,0,0,0,0,0,0,44,4,0,0,0,0,0,0,0,0,0,0,0,0,0,0,0
0,0,0,0,0,0,0,0,0,0,0,0,0,0,0,0,0,0,0,0,0,0,0,0,0
:endlayer
layer: 16
0,0,0,0,0,0,0,0,0,0,0,0,0,0,0,0,0,0,0,0,0,0,0,0,0
0,0,0,10,0,0,0,54,0,0,55,0,0,0,0,0,0,0,0,0,0,0,0,0,0
0,0,6,7,15,0,0,41,20,0,0,0,0,0,0,0,0,0,56,0,0,0,0,0,0
0,0,0,0,0,0,0,0,0,0,0,0,0,0,0,0,0,0,0,0,0,0,0,0,0
0,0,0,4,0,0,0,0,0,0,0,0,0,0,0,0,10,10,0,0,0,0,0,0,0
0,0,4,0,0,0,10,10,0,0,0,0,0,0,0,6,7,7,15,0,0,0,0,0,0
0,0,4,0,0,6,7,7,15,0,0,0,0,0,0,0,7,7,15,0,0,0,0,0,0
0,0,4,0,0,0,7,7,15,0,0,0,0,14,0,0,0,9,0,0,0,0,0,0,0
0,0,4,0,0,0,9,37,0,0,0,10,0,7,4,0,41,20,0,0,0,0,0,0,0
0,0,4,0,0,0,0,0,0,0,6,7,7,7,14,0,0,0,0,0,57,0,0,0,0
0,0,4,0,0,0,0,0,0,0,6,7,7,4,0,0,0,0,0,0,0,0,0,0,0
0,0,4,0,0,0,0,0,0,0,0,9,9,4,0,0,10,10,0,0,0,0,0,0,0
0,0,4,0,0,10,10,0,0,0,0,0,0,0,0,6,7,7,15,0,4,0,0,0,0
0,0,14,0,6,7,7,15,0,0,0,0,0,0,0,6,7,7,15,0,4,0,0,0,0
0,0,4,4,6,7,7,15,0,0,0,0,8,0,0,0,9,9,0,7,4,0,0,0,0
0,0,0,4,0,53,9,0,0,0,0,0,0,0,0,0,0,0,0,7,4,0,0,0,0
0,0,0,0,4,14,14,14,0,0,0,0,0,0,0,0,0,4,4,4,0,0,0,0,0
0,0,0,0,0,4,4,44,44,44,4,0,58,0,4,4,4,0,0,0,0,0,0,0,0
0,0,0,0,0,0,0,14,44,4,0,0,0,0,0,0,4,0,0,0,0,0,0,0,0
0,0,0,0,0,0,0,0,0,0,0,0,0,0,0,0,0,0,0,0,0,0,0,0,0
0,0,0,0,0,0,0,0,0,0,0,0,0,0,0,0,0,0,0,0,0,0,0,0,0
:endlayer
layer: 17
0,0,0,0,0,0,0,0,0,0,0,0,0,0,0,0,0,0,0,0,0,0,0,0,0
0,0,0,10,0,0,0,0,0,0,0,0,0,0,0,0,0,0,0,0,0,0,0,0,0
0,0,6,7,15,0,41,20,0,0,0,0,0,0,0,0,0,0,0,0,0,0,0,0,0
0,0,0,0,0,0,0,0,0,0,0,0,0,0,0,0,0,0,0,0,0,0,0,0,0
0,0,0,4,44,0,0,0,0,0,0,0,0,0,0,0,10,10,0,0,0,0,0,0,0
0,0,44,44,44,44,44,10,0,0,0,0,0,0,0,6,7,7,15,0,0,0,0,0,0
0,0,44,44,44,44,7,7,15,0,0,0,44,0,0,0,7,7,15,0,0,0,0,0,0
0,44,44,44,44,7,7,7,15,0,0,44,44,14,0,0,0,9,0,0,0,0,0,0,0
0,0,44,44,44,44,44,15,0,0,0,10,44,44,14,41,20,0,0,0,0,0,0,0,0
0,0,4,44,44,44,44,0,0,0,6,7,7,44,0,0,0,0,0,0,0,0,0,0,0
0,0,4,0,44,0,0,0,0,0,6,7,7,15,0,0,0,0,0,0,0,0,0,0,0
0,0,4,0,0,0,0,0,0,0,0,9,9,0,0,0,10,10,0,0,0,0,0,0,0
0,0,4,0,0,10,10,0,0,0,0,0,0,0,0,6,7,7,15,0,4,0,0,0,0
0,0,14,0,6,7,7,17,0,0,0,0,0,0,0,6,7,7,15,0,44,0,0,0,0
0,0,0,4,6,7,7,15,0,0,0,0,0,0,0,0,9,7,0,44,44,44,0,0,0
0,0,0,4,0,10,9,0,0,0,0,0,0,0,0,0,0,0,44,44,7,44,44,0,0
0,0,0,0,4,14,14,14,0,0,0,0,0,0,0,0,0,4,4,44,44,44,0,0,0
0,0,0,0,0,0,4,4,14,14,0,0,0,0,4,4,4,0,0,4,44,0,0,0,0
0,0,0,0,0,0,0,0,14,0,0,0,0,0,0,0,0,0,0,0,0,0,0,0,0
0,0,0,0,0,0,0,0,0,0,0,0,0,0,0,0,0,0,0,0,0,0,0,0,0
0,0,0,0,0,0,0,0,0,0,0,0,0,0,0,0,0,0,0,0,0,0,0,0,0
:endlayer
layer: 18
0,0,0,0,0,0,0,0,0,0,0,0,0,0,0,0,0,0,0,0,0,0,0,0,0
0,0,0,10,0,0,0,0,0,0,0,0,0,0,0,0,0,0,0,0,0,0,0,0,0
0,0,6,7,15,41,20,0,0,0,0,0,0,0,0,0,0,0,0,0,0,0,0,0,0
0,0,0,0,0,38,38,38,38,40,0,0,0,0,0,38,38,38,38,0,0,0,0,0,0
0,0,0,0,0,41,42,42,42,38,40,0,0,0,38,41,42,42,40,38,0,0,0,0,0
0,0,0,0,44,41,42,42,42,42,40,0,0,0,41,42,7,7,42,40,0,0,0,0,0
0,0,0,44,44,42,7,7,42,42,40,0,0,0,41,42,7,7,42,40,0,0,0,0,0
0,0,44,44,7,42,7,7,42,42,42,4,44,14,41,42,42,42,42,40,38,0,0,0,0
0,0,4,44,44,42,42,42,42,42,42,14,14,14,41,20,0,0,0,41,40,0,0,0,0
0,0,0,4,44,42,42,42,42,40,43,7,7,14,41,42,42,42,42,42,40,0,0,0,0
0,0,42,42,42,42,42,42,42,40,6,7,7,15,43,41,42,42,42,42,40,0,0,0,0
0,0,42,42,42,42,42,42,42,40,0,9,9,0,0,41,42,42,42,42,40,0,0,0,0
0,0,42,42,42,42,42,42,42,40,0,0,0,0,0,6,7,7,42,42,42,0,0,0,0
0,0,42,42,42,7,7,7,42,40,0,0,0,0,0,4,7,7,42,40,42,0,0,0,0
0,0,0,42,42,7,7,42,42,40,0,0,0,0,0,0,9,41,43,43,44,0,0,0,0
0,0,0,42,42,42,42,42,43,40,0,0,0,0,0,44,44,7,44,44,44,44,0,0,0
0,0,0,0,42,42,42,42,40,0,0,0,0,0,0,44,44,7,44,44,44,0,0,0,0
0,0,0,0,0,0,59,4,4,0,0,0,0,0,44,44,44,44,44,44,44,0,0,0,0
0,0,0,0,0,0,0,0,0,0,0,0,0,0,0,44,44,44,44,44,0,0,0,0,0
0,0,0,0,0,0,0,0,0,0,0,0,0,0,0,44,44,44,44,44,0,0,0,0,0
0,0,0,0,0,0,0,0,0,0,0,0,0,0,0,0,0,44,0,0,0,0,0,0,0
:endlayer
layer: 19
0,0,0,0,0,0,0,0,0,0,0,0,0,0,0,0,0,0,0,0,0,0,0,0,0
0,0,0,10,0,0,0,0,0,0,0,0,0,0,0,0,0,0,0,0,0,0,0,0,0
0,0,6,7,15,0,0,0,0,0,0,0,0,0,0,0,0,0,0,0,0,0,0,0,0
0,0,0,0,0,0,0,0,0,0,0,0,0,0,0,0,0,0,0,0,0,0,0,0,0
0,0,0,0,0,0,0,8,0,0,0,0,0,0,0,0,0,10,8,0,0,0,0,0,0
0,0,0,0,0,0,0,10,60,0,0,0,0,0,0,6,7,7,15,0,0,0,0,0,0
0,0,0,0,44,6,7,7,15,0,0,14,0,0,38,0,7,7,15,0,0,0,0,0,0
0,0,0,44,44,39,7,7,15,8,14,14,14,0,36,8,0,9,0,0,0,0,0,0,0
0,0,0,4,44,26,9,9,0,0,14,7,14,0,0,0,0,0,0,0,0,0,0,0,0
0,0,0,0,0,43,0,0,0,0,61,7,7,15,0,0,0,0,0,0,0,0,0,0,0
0,0,8,0,0,0,0,0,0,0,6,7,7,15,0,62,0,0,48,0,0,0,0,0,0
0,0,0,0,0,0,0,0,0,0,0,9,9,0,0,0,63,10,0,0,0,0,0,0,0
0,0,0,0,0,10,0,4,4,4,0,0,0,0,0,6,7,7,15,0,0,0,0,0,0
0,0,64,0,6,7,7,7,7,4,0,0,0,0,0,4,7,7,0,0,0,0,0,0,0
0,0,0,0,6,7,7,4,14,14,0,0,0,0,0,4,4,9,0,8,0,0,0,0,0
0,0,0,0,8,9,0,0,0,0,0,0,0,0,0,0,0,44,0,0,0,0,0,0,0
0,0,0,0,0,0,0,0,0,0,0,0,0,0,0,0,44,44,44,0,0,0,0,0,0
0,0,0,0,0,0,0,0,0,0,0,0,0,0,0,44,44,7,44,44,0,0,0,0,0
0,0,0,0,0,0,0,0,0,0,0,0,0,0,0,0,44,44,44,0,0,0,0,0,0
0,0,0,0,0,0,0,0,0,0,0,0,0,0,0,0,0,44,0,0,0,0,0,0,0
0,0,0,0,0,0,0,0,0,0,0,0,0,0,0,0,0,0,0,0,0,0,0,0,0
:endlayer
layer: 20
0,0,0,0,0,0,0,0,0,0,0,0,0,0,0,0,0,0,0,0,0,0,0,0,0
0,0,0,10,0,0,0,0,0,0,0,0,0,0,0,0,0,0,0,0,0,0,0,0,0
0,0,6,7,35,0,0,0,0,0,0,0,0,0,0,0,0,0,0,0,0,0,0,0,0
0,0,0,0,0,0,0,0,0,0,0,0,0,0,0,0,0,0,0,0,0,0,0,0,0
0,0,0,0,0,0,0,0,0,0,0,0,0,0,0,0,0,10,0,0,0,0,0,0,0
0,0,0,0,0,0,0,10,0,0,0,44,0,0,38,6,7,7,15,0,0,0,0,0,0
0,0,0,0,0,6,7,7,15,0,44,44,44,0,36,0,7,7,15,0,0,0,0,0,0
0,0,0,0,0,39,7,7,15,0,44,7,44,44,0,0,0,9,0,0,0,0,0,0,0
0,0,0,0,0,0,9,9,0,0,44,44,44,0,0,0,0,0,0,0,0,0,0,0,0
0,0,0,0,0,26,0,0,0,0,6,7,7,15,0,0,0,0,0,0,0,0,0,0,0
0,0,0,0,0,43,0,0,0,0,6,7,7,15,44,0,0,0,0,0,0,0,0,0,0
0,0,0,0,0,0,0,0,0,0,0,9,44,44,44,0,10,10,0,0,0,0,0,0,0
0,0,0,0,0,10,0,0,0,0,0,0,44,44,44,44,7,7,15,0,0,0,0,0,0
0,0,0,0,6,7,7,44,44,44,0,44,44,44,44,7,7,7,0,0,0,0,0,0,0
0,0,0,0,6,7,7,15,44,4,0,4,44,44,44,44,44,9,0,0,0,0,0,0,0
0,0,0,0,0,9,0,0,0,4,14,4,4,44,44,44,44,0,0,0,0,0,0,0,0
0,0,0,0,0,0,0,0,0,0,14,4,4,4,44,4,4,44,0,0,0,0,0,0,0
0,0,0,0,0,0,0,0,0,0,4,4,4,4,4,0,44,44,44,0,0,0,0,0,0
0,0,0,0,0,0,0,0,0,0,0,4,4,0,0,0,0,44,0,0,0,0,0,0,0
0,0,0,0,0,0,0,0,0,0,0,0,0,0,0,0,0,0,0,0,0,0,0,0,0
0,0,0,0,0,0,0,0,0,0,0,0,0,0,0,0,0,0,0,0,0,0,0,0,0
:endlayer
layer: 21
0,0,0,0,0,0,0,0,0,0,0,0,0,0,0,0,0,0,0,0,0,0,0,0,0
0,0,0,10,65,0,0,0,0,0,0,0,0,0,0,0,0,0,0,0,0,0,0,0,0
0,0,6,7,15,0,0,0,0,0,0,0,0,0,0,0,0,0,0,0,0,0,0,0,0
0,0,0,0,0,0,0,38,38,0,0,0,0,0,0,41,38,38,38,0,0,0,0,0,0
0,0,0,0,0,38,38,41,40,38,0,0,0,0,41,38,42,42,40,0,0,0,0,0,0
0,0,0,0,38,41,42,42,42,40,38,0,0,0,36,42,7,7,42,40,0,0,0,0,0
0,0,0,0,41,43,7,7,42,42,40,44,4,0,0,43,7,7,42,40,0,0,0,0,0
0,0,0,41,38,15,7,7,42,42,40,44,44,4,0,41,42,42,42,40,0,0,0,0,0
0,0,0,41,42,0,42,42,42,42,40,44,14,14,0,41,42,42,43,40,0,0,0,0,0
0,0,0,41,42,0,42,42,42,42,42,7,7,15,0,43,43,43,40,0,0,0,0,0,0
0,0,0,41,42,26,42,42,42,42,42,7,7,14,14,0,0,0,0,0,0,0,0,0,0
0,0,0,41,42,42,42,42,42,42,42,42,40,4,44,14,10,10,0,0,0,0,0,0,0
0,0,0,41,42,42,42,42,42,42,42,40,43,44,44,44,7,7,15,0,0,0,0,0,0
0,0,0,41,43,7,7,42,42,42,43,43,44,44,7,44,7,7,0,0,4,0,0,0,0
0,0,0,0,41,7,7,42,42,42,40,4,14,44,44,44,9,4,4,14,14,0,0,0,0
0,0,0,4,43,41,42,42,40,43,43,4,4,14,44,14,4,4,0,0,0,0,0,0,0
0,0,0,0,4,43,43,43,43,0,0,4,4,4,0,0,0,0,0,0,0,0,0,0,0
0,0,0,0,0,0,0,0,0,0,0,0,4,0,0,0,0,0,0,0,0,0,0,0,0
0,0,0,0,0,0,0,0,0,0,0,0,0,0,0,0,0,0,0,0,0,0,0,0,0
0,0,0,0,0,0,0,0,0,0,0,0,0,0,0,0,0,0,0,0,0,0,0,0,0
0,0,0,0,0,0,0,0,0,0,0,0,0,0,0,0,0,0,0,0,0,0,0,0,0
:endlayer
layer: 22
0,0,0,4,4,4,0,0,0,0,0,0,0,0,0,0,0,0,0,0,0,0,0,0,0
0,0,4,14,14,14,4,4,0,0,0,0,0,0,0,0,0,0,0,0,0,0,0,0,0
0,4,4,7,4,4,4,4,4,0,0,0,0,0,0,0,0,0,0,0,0,0,0,0,0
0,4,4,4,14,44,14,0,0,0,0,0,0,0,0,0,0,0,0,0,0,0,0,0,0
0,0,4,14,44,44,44,0,0,0,0,0,0,0,0,0,10,66,8,0,0,0,0,0,0
0,0,0,44,44,7,44,10,8,0,67,0,0,0,0,0,7,7,15,0,0,0,0,0,0
0,0,0,4,44,44,7,7,15,0,0,0,0,0,0,7,7,7,15,0,0,0,0,0,0
0,0,0,0,0,44,7,7,0,0,0,0,0,4,0,68,9,9,0,0,0,0,0,0,0
0,0,0,0,0,0,9,9,0,69,0,10,10,0,14,8,0,0,0,0,0,0,0,0,0
0,0,0,0,0,0,0,0,0,8,6,7,7,15,14,0,0,0,0,0,0,0,0,0,0
0,0,0,0,0,0,0,48,0,0,0,7,7,7,14,0,0,0,0,0,0,0,0,0,0
0,0,0,0,0,8,0,0,70,0,0,71,4,4,14,0,10,10,0,0,0,44,0,0,0
0,0,0,0,0,10,0,0,0,0,0,8,0,14,44,6,7,7,15,44,44,44,44,44,0
0,0,0,0,6,7,7,15,0,0,0,0,0,4,14,6,7,7,4,44,44,44,44,44,0
0,0,0,0,4,7,7,15,8,0,0,0,0,4,4,0,14,13,12,7,7,44,44,44,44
0,0,0,4,7,4,9,0,0,0,0,0,4,4,0,0,4,4,4,44,44,44,44,44,0
0,0,0,14,4,4,0,0,0,0,0,0,4,0,0,0,0,0,0,44,44,44,44,44,0
0,0,0,14,0,0,0,0,0,0,0,0,0,0,0,0,0,0,0,0,0,44,0,0,0
0,0,0,0,0,0,0,0,0,0,0,0,0,0,0,0,0,0,0,0,0,0,0,0,0
0,0,0,0,0,0,0,0,0,0,0,0,0,0,0,0,0,0,0,0,0,0,0,0,0
0,0,0,0,0,0,0,0,0,0,0,0,0,0,0,0,0,0,0,0,0,0,0,0,0
:endlayer
layer: 23
0,0,0,0,0,0,0,0,0,0,0,0,0,0,0,0,0,0,0,0,0,0,0,0,0
0,0,0,14,14,0,0,0,0,0,0,0,0,0,0,0,0,0,0,0,0,0,0,0,0
0,0,14,14,14,4,0,0,0,0,0,0,0,0,0,0,0,0,0,0,0,0,0,0,0
0,0,0,14,0,0,0,0,0,0,0,0,0,0,0,0,0,0,0,0,0,0,0,0,0
0,0,0,0,0,44,14,0,0,0,0,0,0,0,0,0,10,10,0,0,0,0,0,0,0
0,0,0,0,44,44,44,10,0,0,0,0,0,0,0,44,7,7,15,0,0,0,0,0,0
0,0,0,0,0,44,7,7,15,0,0,0,0,44,0,44,7,7,15,0,0,0,0,0,0
0,0,0,0,0,6,7,7,0,0,0,0,0,44,44,0,9,9,0,0,0,0,0,0,0
0,0,0,0,0,0,9,9,0,0,0,10,10,0,44,0,0,0,0,0,0,0,0,0,0
0,0,0,0,0,0,0,0,0,0,6,7,7,15,44,44,0,0,0,0,0,0,0,0,0
0,0,0,0,0,0,0,0,0,0,29,7,7,44,7,7,44,44,44,44,0,0,0,0,0
0,0,0,0,0,0,0,0,0,0,0,9,4,4,44,0,10,10,44,0,0,0,0,0,0
0,0,0,0,0,10,0,0,0,0,0,0,0,0,44,6,7,7,15,0,0,44,0,0,0
0,0,0,44,6,7,7,15,0,0,0,0,0,0,0,6,7,7,4,0,44,44,44,0,0
0,0,44,44,44,7,7,15,0,0,0,0,0,0,0,0,9,4,4,44,44,7,44,44,0
0,44,44,7,44,44,9,0,0,0,0,0,0,4,0,0,0,4,4,4,44,44,44,0,0
0,0,44,44,44,4,0,0,0,0,0,0,0,0,0,0,0,0,0,0,0,44,0,0,0
0,0,0,44,4,0,0,0,0,0,0,0,0,0,0,0,0,0,0,0,0,0,0,0,0
0,0,0,0,0,0,0,0,0,0,0,0,0,0,0,0,0,0,0,0,0,0,0,0,0
0,0,0,0,0,0,0,0,0,0,0,0,0,0,0,0,0,0,0,0,0,0,0,0,0
0,0,0,0,0,0,0,0,0,0,0,0,0,0,0,0,0,0,0,0,0,0,0,0,0
:endlayer
layer: 24
0,0,0,0,0,0,0,0,0,0,0,0,0,0,0,0,0,0,0,0,0,0,0,0,0
0,0,0,0,0,0,0,0,0,0,0,0,0,0,0,0,0,0,0,0,0,0,0,0,0
0,0,0,0,0,0,0,0,0,0,0,0,0,0,0,0,0,0,0,0,0,0,0,0,0
0,0,0,0,0,0,0,0,0,0,0,0,0,0,0,0,0,0,0,0,0,0,0,0,0
0,0,0,0,0,0,0,0,0,0,0,0,0,0,0,0,10,10,0,0,0,0,0,0,0
0,0,0,0,0,0,10,10,0,0,0,0,0,0,44,6,7,7,15,0,0,0,0,0,0
0,0,0,0,0,6,7,7,15,0,0,0,0,44,44,44,7,7,15,0,0,0,0,0,0
0,0,0,0,0,6,7,7,0,0,0,0,0,4,44,0,44,44,0,0,0,0,0,0,0
0,0,0,0,0,44,44,9,0,0,0,10,10,44,44,44,44,44,44,44,4,0,0,0,0
0,0,44,44,44,44,44,44,44,44,6,7,7,44,44,44,44,44,44,44,14,0,0,0,0
0,44,44,44,44,44,44,44,44,44,44,7,7,44,44,44,7,44,44,44,44,0,0,0,0
0,44,44,44,44,44,44,44,44,44,44,9,44,44,44,44,44,44,44,44,44,44,0,0,0
0,44,44,44,44,44,44,44,44,44,44,44,44,44,44,44,7,7,44,44,44,44,44,0,0
44,44,44,44,44,7,7,44,44,44,44,44,44,44,44,44,7,7,44,44,44,44,44,0,0
44,44,44,44,44,7,7,44,44,44,44,4,44,44,44,44,44,44,44,44,44,44,44,0,0
0,44,44,44,44,44,44,44,44,44,4,4,0,0,44,44,44,44,44,44,44,44,0,0,0
0,44,44,44,44,44,44,44,44,4,4,0,0,0,0,44,44,44,44,44,44,44,0,0,0
0,0,44,44,44,44,44,44,4,0,0,0,0,0,0,0,44,44,0,0,0,0,0,0,0
0,0,0,44,0,44,44,0,0,0,0,0,0,0,0,0,0,0,0,0,0,0,0,0,0
0,0,0,0,0,0,0,0,0,0,0,0,0,0,0,0,0,0,0,0,0,0,0,0,0
0,0,0,0,0,0,0,0,0,0,0,0,0,0,0,0,0,0,0,0,0,0,0,0,0
:endlayer
layer: 25
0,0,0,0,0,0,0,0,0,0,0,0,0,0,0,0,0,0,0,0,0,0,0,0,0
0,0,0,0,0,0,0,0,0,0,0,0,0,0,0,0,0,0,0,0,0,0,0,0,0
0,0,0,0,0,0,0,0,0,0,0,0,0,0,0,0,0,0,0,0,0,0,0,0,0
0,0,0,0,44,0,0,0,0,0,0,0,0,0,0,0,0,0,0,0,0,0,0,0,0
0,0,44,44,44,44,44,0,0,0,0,0,0,0,0,0,10,10,0,0,0,0,0,0,0
0,0,44,44,44,44,44,10,0,0,0,0,0,0,0,6,7,7,15,0,0,0,0,0,0
0,44,44,44,44,7,7,7,15,0,0,0,0,0,0,6,7,7,15,0,0,0,0,0,0
0,0,44,44,44,44,7,7,35,0,0,0,0,0,0,0,9,9,0,0,0,0,0,0,0
0,0,44,44,44,44,44,9,0,0,0,10,10,4,4,0,44,44,0,0,0,0,0,0,0
0,0,0,0,44,44,44,0,0,0,6,7,7,4,44,44,44,44,44,14,0,0,0,0,0
0,0,0,44,44,44,44,44,44,0,0,7,7,44,44,44,44,44,44,44,0,0,0,0,0
0,0,44,44,44,44,44,44,0,44,0,9,0,44,44,44,44,44,44,44,14,0,0,0,0
0,0,44,44,44,44,44,44,44,0,0,0,44,44,44,44,7,44,44,44,44,44,0,0,0
0,44,44,44,44,7,44,44,44,44,0,0,44,44,44,44,44,44,44,44,44,44,0,0,0
0,44,44,44,44,44,44,44,44,44,0,0,0,0,44,44,44,44,44,44,44,0,0,0,0
0,0,44,44,44,44,44,44,44,4,0,0,0,0,0,44,44,44,44,44,44,0,0,0,0
0,0,44,44,44,44,44,44,4,0,0,0,0,0,0,0,44,44,0,0,0,0,0,0,0
0,0,0,44,0,44,44,0,0,0,0,0,0,0,0,0,0,0,0,0,0,0,0,0,0
0,0,0,0,0,0,0,0,0,0,0,0,0,0,0,0,0,0,0,0,0,0,0,0,0
0,0,0,0,0,0,0,0,0,0,0,0,0,0,0,0,0,0,0,0,0,0,0,0,0
0,0,0,0,0,0,0,0,0,0,0,0,0,0,0,0,0,0,0,0,0,0,0,0,0
:endlayer
layer: 26
0,0,0,0,0,0,0,0,0,0,0,0,0,0,0,0,0,0,0,0,0,0,0,0,0
0,0,0,0,0,0,0,0,0,0,0,0,0,0,0,0,0,0,0,0,0,0,0,0,0
0,0,0,0,0,0,0,0,0,0,0,0,0,0,0,0,0,0,0,0,0,0,0,0,0
0,0,0,0,0,0,0,0,0,0,0,4,0,0,0,0,0,0,0,0,0,0,0,0,0
0,0,0,0,44,0,0,0,0,0,4,4,4,0,0,0,10,10,0,0,0,0,0,0,0
0,0,0,44,44,44,10,10,44,44,44,44,44,0,0,6,7,7,15,0,0,0,0,0,0
0,0,44,44,7,44,7,7,44,44,44,44,44,44,0,6,7,7,15,0,0,0,0,0,0
0,0,0,44,44,44,7,7,44,44,44,44,44,44,44,0,9,9,0,0,0,0,0,0,0
0,0,0,0,44,0,9,44,44,44,44,44,44,44,44,44,44,0,0,0,0,0,0,0,0
0,0,0,0,0,0,44,44,44,44,44,7,7,44,44,44,44,44,0,0,0,0,0,0,0
0,0,0,0,0,44,44,44,44,44,44,7,7,44,44,44,44,44,44,0,0,0,0,0,0
0,0,0,44,44,44,44,44,44,44,44,44,44,44,44,44,44,44,44,14,0,0,0,0,0
0,0,0,44,44,44,44,44,0,44,44,44,44,44,44,44,44,44,44,44,0,0,0,0,0
0,0,44,44,44,44,44,44,44,0,44,44,44,44,44,44,44,44,44,44,0,0,0,0,0
0,0,44,44,44,44,44,44,44,0,0,44,44,0,0,44,44,44,44,44,0,0,0,0,0
0,0,0,44,44,44,44,44,0,0,0,0,0,0,0,0,44,44,0,0,0,0,0,0,0
0,0,0,44,0,44,44,0,0,0,0,0,0,0,0,0,0,0,0,0,0,0,0,0,0
0,0,0,0,0,0,0,0,0,0,0,0,0,0,0,0,0,0,0,0,0,0,0,0,0
0,0,0,0,0,0,0,0,0,0,0,0,0,0,0,0,0,0,0,0,0,0,0,0,0
0,0,0,0,0,0,0,0,0,0,0,0,0,0,0,0,0,0,0,0,0,0,0,0,0
0,0,0,0,0,0,0,0,0,0,0,0,0,0,0,0,0,0,0,0,0,0,0,0,0
:endlayer
layer: 27
0,0,0,0,0,0,0,0,0,0,0,0,0,0,0,0,4,44,0,0,0,0,0,0,0
0,0,0,0,0,0,0,0,0,0,0,0,0,0,0,44,44,44,44,44,0,0,0,0,0
0,0,0,0,0,0,0,0,0,0,0,0,0,0,4,44,44,44,44,44,0,0,0,0,0
0,0,0,0,0,0,0,0,0,0,0,0,0,0,44,44,44,44,44,44,44,0,0,0,0
0,0,0,0,0,0,0,0,0,0,0,0,0,0,0,44,44,7,44,44,0,0,0,0,0
0,0,0,0,44,0,10,10,0,0,0,44,0,0,0,44,7,7,44,44,0,0,0,0,0
0,0,0,44,44,44,7,7,15,44,44,44,44,0,0,6,7,7,4,0,0,0,0,0,0
0,0,0,0,44,6,7,7,44,44,44,44,44,44,0,0,9,9,0,0,0,0,0,0,0
0,0,0,0,0,0,9,9,44,44,44,44,44,44,44,0,0,0,0,0,0,0,0,0,0
0,0,0,0,0,0,0,44,44,44,44,7,44,44,44,44,44,0,0,0,0,0,0,0,0
0,0,0,0,0,0,0,44,44,44,44,44,44,44,44,44,44,0,0,0,0,0,0,0,0
0,0,0,0,0,0,0,0,0,44,44,44,44,44,44,44,0,0,0,0,0,0,0,0,0
0,0,0,0,0,0,0,0,0,0,44,44,44,44,44,44,0,0,0,0,0,0,0,0,0
0,0,0,0,0,0,0,0,0,0,0,44,44,0,0,0,0,0,0,0,0,0,0,0,0
0,0,0,0,0,0,0,0,0,0,0,0,0,0,0,0,0,0,0,0,0,0,0,0,0
0,0,0,0,0,0,0,0,0,0,0,0,0,0,0,0,0,0,0,0,0,0,0,0,0
0,0,0,0,0,0,0,0,0,0,0,0,0,0,0,0,0,0,0,0,0,0,0,0,0
0,0,0,0,0,0,0,0,0,0,0,0,0,0,0,0,0,0,0,0,0,0,0,0,0
0,0,0,0,0,0,0,0,0,0,0,0,0,0,0,0,0,0,0,0,0,0,0,0,0
0,0,0,0,0,0,0,0,0,0,0,0,0,0,0,0,0,0,0,0,0,0,0,0,0
0,0,0,0,0,0,0,0,0,0,0,0,0,0,0,0,0,0,0,0,0,0,0,0,0
:endlayer
layer: 28
0,0,0,0,0,0,0,0,0,0,0,0,0,0,0,0,0,0,0,0,0,0,0,0,0
0,0,0,0,0,0,0,0,0,0,0,0,0,0,0,0,0,44,0,0,0,0,0,0,0
0,0,0,0,0,0,0,0,0,0,0,0,0,0,0,0,44,44,44,0,0,0,0,0,0
0,0,0,0,0,0,0,0,0,0,0,0,0,0,0,44,44,7,44,44,0,0,0,0,0
0,0,0,0,0,0,0,0,0,0,0,0,0,0,0,0,44,44,44,0,0,0,0,0,0
0,0,0,0,0,0,10,10,0,0,0,0,0,0,0,6,7,7,4,0,0,0,0,0,0
0,0,0,0,0,6,7,7,15,0,0,44,0,0,0,6,7,7,7,4,0,0,0,0,0
0,0,0,0,0,6,7,7,15,44,44,44,44,0,0,0,9,9,4,4,0,0,0,0,0
0,0,0,0,0,0,9,9,0,44,44,44,44,44,0,0,0,0,0,0,0,0,0,0,0
0,0,0,0,0,0,0,0,44,44,44,44,44,44,44,0,0,0,0,0,0,0,0,0,0
0,0,0,0,0,0,0,0,0,44,44,44,44,44,44,0,0,0,0,0,0,0,0,0,0
0,0,0,0,0,0,0,0,0,0,44,44,44,44,0,0,0,0,0,0,0,0,0,0,0
0,0,0,0,0,0,0,0,0,0,0,44,44,0,0,0,0,0,0,0,0,0,0,0,0
0,0,0,0,0,0,0,0,0,0,0,0,0,0,0,0,0,0,0,0,0,0,0,0,0
0,0,0,0,0,0,0,0,0,0,0,0,0,0,0,0,0,0,0,0,0,0,0,0,0
0,0,0,0,0,0,0,0,0,0,0,0,0,0,0,0,0,0,0,0,0,0,0,0,0
0,0,0,0,0,0,0,0,0,0,0,0,0,0,0,0,0,0,0,0,0,0,0,0,0
0,0,0,0,0,0,0,0,0,0,0,0,0,0,0,0,0,0,0,0,0,0,0,0,0
0,0,0,0,0,0,0,0,0,0,0,0,0,0,0,0,0,0,0,0,0,0,0,0,0
0,0,0,0,0,0,0,0,0,0,0,0,0,0,0,0,0,0,0,0,0,0,0,0,0
0,0,0,0,0,0,0,0,0,0,0,0,0,0,0,0,0,0,0,0,0,0,0,0,0
:endlayer
layer: 29
0,0,0,0,0,0,0,0,0,0,0,0,0,0,0,0,0,0,0,0,0,0,0,0,0
0,0,0,0,0,4,4,4,4,4,4,0,0,0,0,0,0,0,0,0,0,0,0,0,0
0,0,0,0,4,4,44,44,4,4,4,4,0,0,0,0,0,44,4,0,0,0,0,0,0
0,0,0,4,4,44,44,44,44,4,4,4,0,0,0,0,44,44,44,4,4,0,0,0,0
0,0,4,4,44,44,44,44,44,44,4,4,4,0,0,0,10,44,4,4,4,0,0,0,0
0,0,4,44,44,44,44,44,44,44,44,4,4,0,0,6,7,7,4,7,7,0,0,0,0
0,0,44,44,44,44,7,7,44,44,44,44,4,0,0,6,7,7,4,4,4,0,0,0,0
0,0,44,44,44,44,7,7,44,44,44,44,4,0,0,0,9,9,4,4,4,0,0,0,0
0,0,0,44,44,44,44,44,44,44,44,44,4,0,0,0,0,0,0,0,4,0,0,0,0
0,0,0,0,44,44,44,44,44,44,44,44,0,0,0,0,0,0,0,0,0,0,0,0,0
0,0,0,0,0,44,44,44,44,0,44,44,0,0,0,0,0,0,0,0,0,0,0,0,0
0,0,0,0,0,0,44,44,0,0,0,0,0,0,0,0,0,0,0,0,0,0,0,0,0
0,0,0,0,0,0,0,0,0,0,0,0,0,0,0,0,0,0,0,0,0,0,0,0,0
0,0,0,0,0,0,0,0,0,0,0,0,0,0,0,0,0,0,0,0,0,0,0,0,0
0,0,0,0,0,0,0,0,0,0,0,0,0,0,0,0,0,0,0,0,0,0,0,0,0
0,0,0,0,0,0,0,0,0,0,0,0,0,0,0,0,0,0,0,0,0,0,0,0,0
0,0,0,0,0,0,0,0,0,0,0,0,0,0,0,0,0,0,0,0,0,0,0,0,0
0,0,0,0,0,0,0,0,0,0,0,0,0,0,0,0,0,0,0,0,0,0,0,0,0
0,0,0,0,0,0,0,0,0,0,0,0,0,0,0,0,0,0,0,0,0,0,0,0,0
0,0,0,0,0,0,0,0,0,0,0,0,0,0,0,0,0,0,0,0,0,0,0,0,0
0,0,0,0,0,0,0,0,0,0,0,0,0,0,0,0,0,0,0,0,0,0,0,0,0
:endlayer
layer: 30
0,0,0,0,0,0,0,0,0,0,0,0,0,0,0,0,0,0,0,0,0,0,0,0,0
0,0,0,0,0,0,0,0,0,0,0,0,0,0,0,0,0,0,0,0,0,0,0,0,0
0,0,0,0,0,4,44,4,4,4,0,0,0,0,0,0,0,0,0,4,0,0,0,0,0
0,0,0,0,4,44,44,44,4,4,4,0,0,0,0,0,0,0,4,4,4,44,0,0,0
0,0,0,4,44,44,44,44,44,4,4,4,0,0,0,0,10,10,0,4,44,44,44,0,0
0,0,4,44,44,44,44,44,44,44,4,4,0,0,0,6,7,7,15,44,44,7,44,44,0
0,0,44,44,44,44,7,44,44,44,44,4,0,0,0,6,7,7,15,0,44,44,44,0,0
0,0,0,44,44,44,44,44,44,44,44,0,0,0,0,0,9,9,0,0,4,44,0,0,0
0,0,0,0,44,44,44,44,44,44,0,0,0,0,0,0,0,0,0,0,4,0,0,0,0
0,0,0,0,0,44,44,44,44,0,44,0,0,0,0,0,0,0,0,0,0,0,0,0,0
0,0,0,0,0,0,44,44,0,0,0,0,0,0,0,0,0,0,0,0,0,0,0,0,0
0,0,0,0,0,0,0,0,0,0,0,0,0,0,0,0,0,0,0,0,0,0,0,0,0
0,0,0,0,0,0,0,0,0,0,0,0,0,0,0,0,0,0,0,0,0,0,0,0,0
0,0,0,0,0,0,0,0,0,0,0,0,0,0,0,0,0,0,0,0,0,0,0,0,0
0,0,0,0,0,0,0,0,0,0,0,0,0,0,0,0,0,0,0,0,0,0,0,0,0
0,0,0,0,0,0,0,0,0,0,0,0,0,0,0,0,0,0,0,0,0,0,0,0,0
0,0,0,0,0,0,0,0,0,0,0,0,0,0,0,0,0,0,0,0,0,0,0,0,0
0,0,0,0,0,0,0,0,0,0,0,0,0,0,0,0,0,0,0,0,0,0,0,0,0
0,0,0,0,0,0,0,0,0,0,0,0,0,0,0,0,0,0,0,0,0,0,0,0,0
0,0,0,0,0,0,0,0,0,0,0,0,0,0,0,0,0,0,0,0,0,0,0,0,0
0,0,0,0,0,0,0,0,0,0,0,0,0,0,0,0,0,0,0,0,0,0,0,0,0
:endlayer
layer: 31
0,0,0,0,0,0,0,0,0,0,0,0,0,0,0,0,0,0,0,0,0,0,0,0,0
0,0,0,0,0,0,0,0,0,0,0,0,0,0,0,0,0,0,0,0,0,0,0,0,0
0,0,0,0,0,0,0,0,0,0,0,0,0,0,0,0,0,0,0,0,0,0,0,0,0
0,0,0,0,0,0,44,14,14,0,0,0,0,0,0,0,0,0,0,0,0,0,0,0,0
0,0,0,0,0,44,44,44,14,4,0,0,0,0,0,0,10,10,0,0,14,44,0,0,0
0,0,0,0,44,44,44,44,44,4,4,0,0,0,0,6,7,7,15,0,44,44,44,0,0
0,0,0,44,44,44,44,44,44,44,4,0,0,0,0,6,7,7,15,0,0,44,0,0,0
0,0,0,0,44,44,44,44,44,44,0,0,0,0,0,0,9,9,0,0,0,4,0,0,0
0,0,0,0,0,44,44,44,44,0,0,0,0,0,0,0,0,0,0,0,0,0,0,0,0
0,0,0,0,0,0,44,44,0,0,0,0,0,0,0,0,0,0,0,0,0,0,0,0,0
0,0,0,0,0,0,0,0,0,0,0,0,0,0,0,0,0,0,0,0,0,0,0,0,0
0,0,0,0,0,0,0,0,0,0,0,0,0,0,0,0,0,0,0,0,0,0,0,0,0
0,0,0,0,0,0,0,0,0,0,0,0,0,0,0,0,0,0,0,0,0,0,0,0,0
0,0,0,0,0,0,0,0,0,0,0,0,0,0,0,0,0,0,0,0,0,0,0,0,0
0,0,0,0,0,0,0,0,0,0,0,0,0,0,0,0,0,0,0,0,0,0,0,0,0
0,0,0,0,0,0,0,0,0,0,0,0,0,0,0,0,0,0,0,0,0,0,0,0,0
0,0,0,0,0,0,0,0,0,0,0,0,0,0,0,0,0,0,0,0,0,0,0,0,0
0,0,0,0,0,0,0,0,0,0,0,0,0,0,0,0,0,0,0,0,0,0,0,0,0
0,0,0,0,0,0,0,0,0,0,0,0,0,0,0,0,0,0,0,0,0,0,0,0,0
0,0,0,0,0,0,0,0,0,0,0,0,0,0,0,0,0,0,0,0,0,0,0,0,0
0,0,0,0,0,0,0,0,0,0,0,0,0,0,0,0,0,0,0,0,0,0,0,0,0
:endlayer
layer: 32
0,0,0,0,0,0,0,0,0,0,0,0,4,4,4,4,4,4,0,0,0,0,0,0,0
0,0,0,0,0,0,0,0,0,0,0,4,4,4,4,4,44,44,14,0,0,0,0,0,0
0,0,0,0,0,0,0,0,0,0,4,4,4,4,4,44,44,44,0,0,0,0,0,0,0
0,0,0,0,0,0,0,0,0,0,4,4,4,4,44,44,44,44,0,0,0,0,0,0,0
0,0,0,0,0,0,0,0,0,0,4,4,4,44,44,44,44,44,44,44,0,44,0,0,0
0,0,0,0,0,0,0,0,0,0,4,4,44,44,44,44,7,7,44,44,44,44,44,0,0
0,0,0,0,0,0,0,0,0,0,4,4,44,44,44,44,7,7,44,44,44,44,44,0,0
0,0,0,0,0,0,0,0,0,0,0,4,4,44,44,44,44,44,44,44,44,44,0,0,0
0,0,0,0,0,0,0,0,0,0,0,0,4,4,44,44,44,44,44,44,4,0,0,0,0
0,0,0,0,0,0,0,0,0,0,0,0,0,4,4,44,44,44,44,4,0,0,0,0,0
0,0,0,0,0,0,0,0,0,0,0,0,0,0,0,4,44,44,4,0,0,0,0,0,0
0,0,0,0,0,0,0,0,0,0,0,0,0,0,0,0,0,0,0,0,0,0,0,0,0
0,0,0,0,0,0,0,0,0,0,0,0,0,0,0,0,0,0,0,0,0,0,0,0,0
0,0,0,0,0,0,0,0,0,0,0,0,0,0,0,0,0,0,0,0,0,0,0,0,0
0,0,0,0,0,0,0,0,0,0,0,0,0,0,0,0,0,0,0,0,0,0,0,0,0
0,0,0,0,0,0,0,0,0,0,0,0,0,0,0,0,0,0,0,0,0,0,0,0,0
0,0,0,0,0,0,0,0,0,0,0,0,0,0,0,0,0,0,0,0,0,0,0,0,0
0,0,0,0,0,0,0,0,0,0,0,0,0,0,0,0,0,0,0,0,0,0,0,0,0
0,0,0,0,0,0,0,0,0,0,0,0,0,0,0,0,0,0,0,0,0,0,0,0,0
0,0,0,0,0,0,0,0,0,0,0,0,0,0,0,0,0,0,0,0,0,0,0,0,0
0,0,0,0,0,0,0,0,0,0,0,0,0,0,0,0,0,0,0,0,0,0,0,0,0
:endlayer
layer: 33
0,0,0,0,0,0,0,0,0,0,0,0,0,0,4,0,0,0,0,0,0,0,0,0,0
0,0,0,0,0,0,0,0,0,0,0,0,4,4,4,4,44,0,0,0,0,0,0,0,0
0,0,0,0,0,0,0,0,0,0,0,4,4,4,4,44,44,44,0,0,0,0,0,0,0
0,0,0,0,0,0,0,0,0,0,0,4,4,4,44,44,44,44,44,0,0,0,0,0,0
0,0,0,0,0,0,0,0,0,0,0,4,4,44,44,44,44,44,44,44,0,0,0,0,0
0,0,0,0,0,0,0,0,0,0,0,4,44,44,44,44,7,44,44,44,44,44,0,0,0
0,0,0,0,0,0,0,0,0,0,0,0,4,44,44,44,44,44,44,44,44,44,0,0,0
0,0,0,0,0,0,0,0,0,0,0,0,4,4,44,44,44,44,44,44,4,0,0,0,0
0,0,0,0,0,0,0,0,0,0,0,0,0,4,4,44,44,44,44,4,0,0,0,0,0
0,0,0,0,0,0,0,0,0,0,0,0,0,0,0,4,44,44,4,0,0,0,0,0,0
0,0,0,0,0,0,0,0,0,0,0,0,0,0,0,0,0,0,0,0,0,0,0,0,0
0,0,0,0,0,0,0,0,0,0,0,0,0,0,0,0,0,0,0,0,0,0,0,0,0
0,0,0,0,0,0,0,0,0,0,0,0,0,0,0,0,0,0,0,0,0,0,0,0,0
0,0,0,0,0,0,0,0,0,0,0,0,0,0,0,0,0,0,0,0,0,0,0,0,0
0,0,0,0,0,0,0,0,0,0,0,0,0,0,0,0,0,0,0,0,0,0,0,0,0
0,0,0,0,0,0,0,0,0,0,0,0,0,0,0,0,0,0,0,0,0,0,0,0,0
0,0,0,0,0,0,0,0,0,0,0,0,0,0,0,0,0,0,0,0,0,0,0,0,0
0,0,0,0,0,0,0,0,0,0,0,0,0,0,0,0,0,0,0,0,0,0,0,0,0
0,0,0,0,0,0,0,0,0,0,0,0,0,0,0,0,0,0,0,0,0,0,0,0,0
0,0,0,0,0,0,0,0,0,0,0,0,0,0,0,0,0,0,0,0,0,0,0,0,0
0,0,0,0,0,0,0,0,0,0,0,0,0,0,0,0,0,0,0,0,0,0,0,0,0
:endlayer
layer: 34
0,0,0,0,0,0,0,0,0,0,0,0,0,0,0,0,0,0,0,0,0,0,0,0,0
0,0,0,0,0,0,0,0,0,0,0,0,0,0,4,0,0,0,0,0,0,0,0,0,0
0,0,0,0,0,0,0,0,0,0,0,0,0,4,4,4,44,0,0,0,0,0,0,0,0
0,0,0,0,0,0,0,0,0,0,0,0,4,4,4,44,44,44,0,0,0,0,0,0,0
0,0,0,0,0,0,0,0,0,0,0,0,4,4,44,44,44,44,44,0,0,0,0,0,0
0,0,0,0,0,0,0,0,0,0,0,0,4,44,44,44,44,44,44,44,0,0,0,0,0
0,0,0,0,0,0,0,0,0,0,0,0,0,4,44,44,44,44,44,44,4,0,0,0,0
0,0,0,0,0,0,0,0,0,0,0,0,0,4,4,44,44,44,44,4,0,0,0,0,0
0,0,0,0,0,0,0,0,0,0,0,0,0,0,0,4,44,44,4,0,0,0,0,0,0
0,0,0,0,0,0,0,0,0,0,0,0,0,0,0,0,4,4,0,0,0,0,0,0,0
0,0,0,0,0,0,0,0,0,0,0,0,0,0,0,0,0,0,0,0,0,0,0,0,0
0,0,0,0,0,0,0,0,0,0,0,0,0,0,0,0,0,0,0,0,0,0,0,0,0
0,0,0,0,0,0,0,0,0,0,0,0,0,0,0,0,0,0,0,0,0,0,0,0,0
0,0,0,0,0,0,0,0,0,0,0,0,0,0,0,0,0,0,0,0,0,0,0,0,0
0,0,0,0,0,0,0,0,0,0,0,0,0,0,0,0,0,0,0,0,0,0,0,0,0
0,0,0,0,0,0,0,0,0,0,0,0,0,0,0,0,0,0,0,0,0,0,0,0,0
0,0,0,0,0,0,0,0,0,0,0,0,0,0,0,0,0,0,0,0,0,0,0,0,0
0,0,0,0,0,0,0,0,0,0,0,0,0,0,0,0,0,0,0,0,0,0,0,0,0
0,0,0,0,0,0,0,0,0,0,0,0,0,0,0,0,0,0,0,0,0,0,0,0,0
0,0,0,0,0,0,0,0,0,0,0,0,0,0,0,0,0,0,0,0,0,0,0,0,0
0,0,0,0,0,0,0,0,0,0,0,0,0,0,0,0,0,0,0,0,0,0,0,0,0
:endlayer

#### RULES ####
rule:
plugin=vanillaBlocks
number=1
data:
JSON:{blockState:{blockName:"minecraft:dirt",properties:{variant:"dirt",snowy:"false"}}}
:enddata
:endrule

rule:
plugin=vanillaBlocks
number=2
data:
JSON:{blockState:{blockName:"minecraft:grass",properties:{snowy:"false"}}}
:enddata
:endrule

rule:
plugin=vanillaBlocks
number=3
data:
JSON:{blockState:{blockName:"minecraft:tallgrass",properties:{type:"tall_grass"}}}
:enddata
:endrule

rule:
plugin=vanillaBlocks
number=4
data:
JSON:{blockState:{blockName:"minecraft:leaves",properties:{check_decay:"false",decayable:"false",variant:"jungle"}}}
:enddata
:endrule

rule:
plugin=vanillaBlocks
number=5
data:
JSON:{blockState:{blockName:"minecraft:tallgrass",properties:{type:"fern"}}}
:enddata
:endrule

rule:
plugin=vine
number=6
data:
JSON:{blockState:{blockName:"minecraft:vine",properties:{east:"true",south:"false",north:"false",west:"false",up:"false"}}}
:enddata
:endrule

rule:
plugin=vanillaBlocks
number=7
data:
JSON:{blockState:{blockName:"minecraft:log",properties:{variant:"jungle",axis:"y"}}}
:enddata
:endrule

rule:
plugin=vanillaBlocks
number=8
data:
JSON:{blockState:{blockName:"minecraft:torch",properties:{facing:"up"}}}
:enddata
:endrule

rule:
plugin=vine
number=9
data:
JSON:{blockState:{blockName:"minecraft:vine",properties:{east:"false",south:"false",north:"true",west:"false",up:"false"}}}
:enddata
:endrule

rule:
plugin=vine
number=10
data:
JSON:{blockState:{blockName:"minecraft:vine",properties:{east:"false",south:"true",north:"false",west:"false",up:"false"}}}
:enddata
:endrule

rule:
plugin=blockTile
number=11
data:
JSON:{blockState:{blockName:"ancientwarfarestructure:advanced_spawner",properties:{transparent:"true"}},teData:{id:"ancientwarfarestructure:advanced_spawner_tile",spawnerSettings:{minDelay:0,spawnDelay:0,lightSensitive:0b,spawnGroups:[{settingsList:[{remainingSpawnCount:1,hostile:1b,forced:1b,customTag:{factionName:"kong"},maxToSpawn:1,entityId:"ancientwarfarenpc:faction.soldier",minToSpawn:1}],groupWeight:1}],playerRange:16,respondToRedstone:0b,inventory:{Size:9,Items:[]},spawnRange:0,transparent:1b,maxDelay:0,xpToDrop:0,mobRange:0,debugMode:0b,maxNearbyMonsters:0}}}
:enddata
:endrule

rule:
plugin=vanillaBlocks
number=12
data:
JSON:{blockState:{blockName:"minecraft:log",properties:{variant:"jungle",axis:"x"}}}
:enddata
:endrule

rule:
plugin=vanillaBlocks
number=13
data:
JSON:{blockState:{blockName:"minecraft:log",properties:{variant:"jungle",axis:"z"}}}
:enddata
:endrule

rule:
plugin=vanillaBlocks
number=14
data:
JSON:{blockState:{blockName:"minecraft:leaves",properties:{check_decay:"true",decayable:"false",variant:"jungle"}}}
:enddata
:endrule

rule:
plugin=vine
number=15
data:
JSON:{blockState:{blockName:"minecraft:vine",properties:{east:"false",south:"false",north:"false",west:"true",up:"false"}}}
:enddata
:endrule

rule:
plugin=vanillaBlocks
number=16
data:
JSON:{blockState:{blockName:"minecraft:torch",properties:{facing:"west"}}}
:enddata
:endrule

rule:
plugin=vanillaBlocks
number=17
data:
JSON:{blockState:{blockName:"minecraft:torch",properties:{facing:"east"}}}
:enddata
:endrule

rule:
plugin=vanillaBlocks
number=18
data:
JSON:{blockState:{blockName:"minecraft:torch",properties:{facing:"north"}}}
:enddata
:endrule

rule:
plugin=vanillaBlocks
number=19
data:
JSON:{blockState:{blockName:"minecraft:wooden_slab",properties:{half:"top",variant:"jungle"}}}
:enddata
:endrule

rule:
plugin=vanillaBlocks
number=20
data:
JSON:{blockState:{blockName:"minecraft:jungle_stairs",properties:{half:"bottom",shape:"straight",facing:"west"}}}
:enddata
:endrule

rule:
plugin=blockTile
number=21
data:
JSON:{blockState:{blockName:"ancientwarfarestructure:advanced_spawner",properties:{transparent:"true"}},teData:{id:"ancientwarfarestructure:advanced_spawner_tile",spawnerSettings:{minDelay:0,spawnDelay:0,lightSensitive:0b,spawnGroups:[{settingsList:[{remainingSpawnCount:1,hostile:1b,forced:1b,customTag:{factionName:"kong"},maxToSpawn:1,entityId:"ancientwarfarenpc:faction.soldier",minToSpawn:1}],groupWeight:1}],playerRange:16,respondToRedstone:0b,inventory:{Size:9,Items:[]},spawnRange:0,transparent:1b,maxDelay:0,xpToDrop:0,mobRange:0,debugMode:0b,maxNearbyMonsters:0}}}
:enddata
:endrule

rule:
plugin=blockTile
number=22
data:
JSON:{blockState:{blockName:"ancientwarfarestructure:advanced_spawner",properties:{transparent:"true"}},teData:{id:"ancientwarfarestructure:advanced_spawner_tile",spawnerSettings:{minDelay:0,spawnDelay:0,lightSensitive:0b,spawnGroups:[{settingsList:[{remainingSpawnCount:1,hostile:1b,forced:1b,customTag:{factionName:"kong"},maxToSpawn:1,entityId:"ancientwarfarenpc:faction.soldier",minToSpawn:1}],groupWeight:1}],playerRange:16,respondToRedstone:0b,inventory:{Size:9,Items:[]},spawnRange:0,transparent:1b,maxDelay:0,xpToDrop:0,mobRange:0,debugMode:0b,maxNearbyMonsters:0}}}
:enddata
:endrule

rule:
plugin=blockTile
number=23
data:
JSON:{blockState:{blockName:"ancientwarfarestructure:advanced_spawner",properties:{transparent:"true"}},teData:{id:"ancientwarfarestructure:advanced_spawner_tile",spawnerSettings:{minDelay:0,spawnDelay:0,lightSensitive:0b,spawnGroups:[{settingsList:[{remainingSpawnCount:1,hostile:1b,forced:1b,customTag:{factionName:"kong"},maxToSpawn:1,entityId:"ancientwarfarenpc:faction.archer.elite",minToSpawn:1}],groupWeight:1}],playerRange:32,respondToRedstone:0b,inventory:{Size:9,Items:[]},spawnRange:0,transparent:1b,maxDelay:0,xpToDrop:0,mobRange:0,debugMode:0b,maxNearbyMonsters:0}}}
:enddata
:endrule

rule:
plugin=vanillaBlocks
number=24
data:
JSON:{blockState:{blockName:"minecraft:torch",properties:{facing:"south"}}}
:enddata
:endrule

rule:
plugin=blockTile
number=25
data:
JSON:{blockState:{blockName:"ancientwarfarestructure:advanced_spawner",properties:{transparent:"true"}},teData:{id:"ancientwarfarestructure:advanced_spawner_tile",spawnerSettings:{minDelay:0,spawnDelay:0,lightSensitive:0b,spawnGroups:[{settingsList:[{remainingSpawnCount:1,hostile:1b,forced:1b,customTag:{factionName:"kong"},maxToSpawn:1,entityId:"ancientwarfarenpc:faction.archer.elite",minToSpawn:1}],groupWeight:1}],playerRange:32,respondToRedstone:0b,inventory:{Size:9,Items:[]},spawnRange:0,transparent:1b,maxDelay:0,xpToDrop:0,mobRange:0,debugMode:0b,maxNearbyMonsters:0}}}
:enddata
:endrule

rule:
plugin=vanillaBlocks
number=26
data:
JSON:{blockState:{blockName:"minecraft:jungle_stairs",properties:{half:"bottom",shape:"straight",facing:"south"}}}
:enddata
:endrule

rule:
plugin=blockTile
number=27
data:
JSON:{blockState:{blockName:"ancientwarfarestructure:advanced_spawner",properties:{transparent:"true"}},teData:{id:"ancientwarfarestructure:advanced_spawner_tile",spawnerSettings:{minDelay:0,spawnDelay:0,lightSensitive:0b,spawnGroups:[{settingsList:[{remainingSpawnCount:1,hostile:1b,forced:1b,customTag:{factionName:"kong"},maxToSpawn:1,entityId:"ancientwarfarenpc:faction.soldier",minToSpawn:1}],groupWeight:1}],playerRange:16,respondToRedstone:0b,inventory:{Size:9,Items:[]},spawnRange:0,transparent:1b,maxDelay:0,xpToDrop:0,mobRange:0,debugMode:0b,maxNearbyMonsters:0}}}
:enddata
:endrule

rule:
plugin=vanillaBlocks
number=28
data:
JSON:{blockState:{blockName:"minecraft:cocoa",properties:{facing:"north",age:"2"}}}
:enddata
:endrule

rule:
plugin=vanillaBlocks
number=29
data:
JSON:{blockState:{blockName:"minecraft:cocoa",properties:{facing:"east",age:"2"}}}
:enddata
:endrule

rule:
plugin=blockTile
number=30
data:
JSON:{blockState:{blockName:"ancientwarfarestructure:advanced_spawner",properties:{transparent:"true"}},teData:{id:"ancientwarfarestructure:advanced_spawner_tile",spawnerSettings:{minDelay:0,spawnDelay:0,lightSensitive:0b,spawnGroups:[{settingsList:[{remainingSpawnCount:1,hostile:1b,forced:1b,customTag:{factionName:"kong"},maxToSpawn:1,entityId:"ancientwarfarenpc:faction.archer.elite",minToSpawn:1}],groupWeight:1}],playerRange:32,respondToRedstone:0b,inventory:{Size:9,Items:[]},spawnRange:0,transparent:1b,maxDelay:0,xpToDrop:0,mobRange:0,debugMode:0b,maxNearbyMonsters:0}}}
:enddata
:endrule

rule:
plugin=vine
number=31
data:
JSON:{blockState:{blockName:"minecraft:vine",properties:{east:"true",south:"false",north:"true",west:"true",up:"false"}}}
:enddata
:endrule

rule:
plugin=blockTile
number=32
data:
JSON:{blockState:{blockName:"ancientwarfarestructure:advanced_spawner",properties:{transparent:"true"}},teData:{id:"ancientwarfarestructure:advanced_spawner_tile",spawnerSettings:{minDelay:0,spawnDelay:0,lightSensitive:0b,spawnGroups:[{settingsList:[{remainingSpawnCount:1,hostile:1b,forced:1b,customTag:{factionName:"kong"},maxToSpawn:1,entityId:"ancientwarfarenpc:faction.leader",minToSpawn:1}],groupWeight:1}],playerRange:10,respondToRedstone:0b,inventory:{Size:9,Items:[]},spawnRange:0,transparent:1b,maxDelay:0,xpToDrop:0,mobRange:0,debugMode:0b,maxNearbyMonsters:0}}}
:enddata
:endrule

rule:
plugin=vanillaBlocks
number=33
data:
JSON:{blockState:{blockName:"minecraft:jungle_stairs",properties:{half:"bottom",shape:"straight",facing:"east"}}}
:enddata
:endrule

rule:
plugin=vanillaBlocks
number=34
data:
JSON:{blockState:{blockName:"minecraft:cocoa",properties:{facing:"south",age:"2"}}}
:enddata
:endrule

rule:
plugin=vanillaBlocks
number=35
data:
JSON:{blockState:{blockName:"minecraft:cocoa",properties:{facing:"west",age:"2"}}}
:enddata
:endrule

rule:
plugin=vanillaBlocks
number=36
data:
JSON:{blockState:{blockName:"minecraft:jungle_stairs",properties:{half:"bottom",shape:"straight",facing:"north"}}}
:enddata
:endrule

rule:
plugin=vine
number=37
data:
JSON:{blockState:{blockName:"minecraft:vine",properties:{east:"false",south:"false",north:"true",west:"true",up:"false"}}}
:enddata
:endrule

rule:
plugin=vanillaBlocks
number=38
data:
JSON:{blockState:{blockName:"minecraft:jungle_stairs",properties:{half:"top",shape:"straight",facing:"south"}}}
:enddata
:endrule

rule:
plugin=vine
number=39
data:
JSON:{blockState:{blockName:"minecraft:vine",properties:{east:"true",south:"false",north:"false",west:"true",up:"false"}}}
:enddata
:endrule

rule:
plugin=vanillaBlocks
number=40
data:
JSON:{blockState:{blockName:"minecraft:jungle_stairs",properties:{half:"top",shape:"straight",facing:"west"}}}
:enddata
:endrule

rule:
plugin=vanillaBlocks
number=41
data:
JSON:{blockState:{blockName:"minecraft:jungle_stairs",properties:{half:"top",shape:"straight",facing:"east"}}}
:enddata
:endrule

rule:
plugin=vanillaBlocks
number=42
data:
JSON:{blockState:{blockName:"minecraft:planks",properties:{variant:"jungle"}}}
:enddata
:endrule

rule:
plugin=vanillaBlocks
number=43
data:
JSON:{blockState:{blockName:"minecraft:jungle_stairs",properties:{half:"top",shape:"straight",facing:"north"}}}
:enddata
:endrule

rule:
plugin=vanillaBlocks
number=44
data:
JSON:{blockState:{blockName:"minecraft:leaves",properties:{check_decay:"false",decayable:"true",variant:"jungle"}}}
:enddata
:endrule

rule:
plugin=blockTile
number=45
data:
JSON:{blockState:{blockName:"ancientwarfarestructure:advanced_spawner",properties:{transparent:"true"}},teData:{id:"ancientwarfarestructure:advanced_spawner_tile",spawnerSettings:{minDelay:0,spawnDelay:0,lightSensitive:0b,spawnGroups:[{settingsList:[{remainingSpawnCount:1,hostile:1b,forced:1b,customTag:{factionName:"kong"},maxToSpawn:1,entityId:"ancientwarfarenpc:faction.archer.elite",minToSpawn:1}],groupWeight:1}],playerRange:32,respondToRedstone:0b,inventory:{Size:9,Items:[]},spawnRange:0,transparent:1b,maxDelay:0,xpToDrop:0,mobRange:0,debugMode:0b,maxNearbyMonsters:0}}}
:enddata
:endrule

rule:
plugin=blockTile
number=46
data:
JSON:{blockState:{blockName:"ancientwarfarestructure:advanced_spawner",properties:{transparent:"true"}},teData:{id:"ancientwarfarestructure:advanced_spawner_tile",spawnerSettings:{minDelay:0,spawnDelay:0,lightSensitive:0b,spawnGroups:[{settingsList:[{remainingSpawnCount:1,hostile:1b,forced:1b,customTag:{factionName:"kong"},maxToSpawn:1,entityId:"ancientwarfarenpc:faction.civilian.female",minToSpawn:1}],groupWeight:1}],playerRange:16,respondToRedstone:0b,inventory:{Size:9,Items:[]},spawnRange:0,transparent:1b,maxDelay:0,xpToDrop:0,mobRange:0,debugMode:0b,maxNearbyMonsters:0}}}
:enddata
:endrule

rule:
plugin=blockTile
number=47
data:
JSON:{blockState:{blockName:"ancientwarfarestructure:advanced_spawner",properties:{transparent:"true"}},teData:{id:"ancientwarfarestructure:advanced_spawner_tile",spawnerSettings:{minDelay:0,spawnDelay:0,lightSensitive:0b,spawnGroups:[{settingsList:[{remainingSpawnCount:1,hostile:1b,forced:1b,customTag:{factionName:"kong"},maxToSpawn:1,entityId:"ancientwarfarenpc:faction.civilian.female",minToSpawn:1}],groupWeight:1}],playerRange:16,respondToRedstone:0b,inventory:{Size:9,Items:[]},spawnRange:0,transparent:1b,maxDelay:0,xpToDrop:0,mobRange:0,debugMode:0b,maxNearbyMonsters:0}}}
:enddata
:endrule

rule:
plugin=vanillaBlocks
number=48
data:
JSON:{blockState:{blockName:"ancientwarfarestructure:fire_pit",properties:{lit:"true",variant:"default"}}}
:enddata
:endrule

rule:
plugin=blockTile
number=49
data:
JSON:{blockState:{blockName:"ancientwarfarestructure:advanced_spawner",properties:{transparent:"true"}},teData:{id:"ancientwarfarestructure:advanced_spawner_tile",spawnerSettings:{minDelay:0,spawnDelay:0,lightSensitive:0b,spawnGroups:[{settingsList:[{remainingSpawnCount:1,hostile:1b,forced:1b,customTag:{factionName:"kong"},maxToSpawn:1,entityId:"ancientwarfarenpc:faction.soldier",minToSpawn:1}],groupWeight:1}],playerRange:8,respondToRedstone:0b,inventory:{Size:9,Items:[]},spawnRange:0,transparent:1b,maxDelay:0,xpToDrop:0,mobRange:0,debugMode:0b,maxNearbyMonsters:0}}}
:enddata
:endrule

rule:
plugin=blockTile
number=50
data:
JSON:{blockState:{blockName:"ancientwarfarestructure:advanced_spawner",properties:{transparent:"true"}},teData:{id:"ancientwarfarestructure:advanced_spawner_tile",spawnerSettings:{minDelay:0,spawnDelay:0,lightSensitive:0b,spawnGroups:[{settingsList:[{remainingSpawnCount:1,hostile:1b,forced:1b,customTag:{factionName:"kong"},maxToSpawn:1,entityId:"ancientwarfarenpc:faction.soldier",minToSpawn:1}],groupWeight:1}],playerRange:16,respondToRedstone:0b,inventory:{Size:9,Items:[]},spawnRange:0,transparent:1b,maxDelay:0,xpToDrop:0,mobRange:0,debugMode:0b,maxNearbyMonsters:0}}}
:enddata
:endrule

rule:
plugin=blockTile
number=51
data:
JSON:{blockState:{blockName:"ancientwarfarestructure:advanced_spawner",properties:{transparent:"true"}},teData:{id:"ancientwarfarestructure:advanced_spawner_tile",spawnerSettings:{minDelay:0,spawnDelay:0,lightSensitive:0b,spawnGroups:[{settingsList:[{remainingSpawnCount:1,hostile:1b,forced:1b,customTag:{factionName:"kong"},maxToSpawn:1,entityId:"ancientwarfarenpc:faction.civilian.female",minToSpawn:1}],groupWeight:1}],playerRange:16,respondToRedstone:0b,inventory:{Size:9,Items:[]},spawnRange:0,transparent:1b,maxDelay:0,xpToDrop:0,mobRange:0,debugMode:0b,maxNearbyMonsters:0}}}
:enddata
:endrule

rule:
plugin=blockTile
number=52
data:
JSON:{blockState:{blockName:"ancientwarfarestructure:advanced_spawner",properties:{transparent:"true"}},teData:{id:"ancientwarfarestructure:advanced_spawner_tile",spawnerSettings:{minDelay:0,spawnDelay:0,lightSensitive:0b,spawnGroups:[{settingsList:[{remainingSpawnCount:1,hostile:1b,forced:1b,customTag:{factionName:"kong"},maxToSpawn:1,entityId:"ancientwarfarenpc:faction.soldier",minToSpawn:1}],groupWeight:1}],playerRange:16,respondToRedstone:0b,inventory:{Size:9,Items:[]},spawnRange:0,transparent:1b,maxDelay:0,xpToDrop:0,mobRange:0,debugMode:0b,maxNearbyMonsters:0}}}
:enddata
:endrule

rule:
plugin=vine
number=53
data:
JSON:{blockState:{blockName:"minecraft:vine",properties:{east:"false",south:"true",north:"true",west:"false",up:"false"}}}
:enddata
:endrule

rule:
plugin=vanillaSkull
number=54
data:
JSON:{blockState:{blockName:"minecraft:skull",properties:{nodrop:"false",facing:"up"}},skullRotation:12,teData:{Rot:12b,id:"minecraft:skull",SkullType:0b}}
:enddata
:endrule

rule:
plugin=blockTile
number=55
data:
JSON:{blockState:{blockName:"ancientwarfarestructure:advanced_spawner",properties:{transparent:"true"}},teData:{id:"ancientwarfarestructure:advanced_spawner_tile",spawnerSettings:{minDelay:0,spawnDelay:0,lightSensitive:0b,spawnGroups:[{settingsList:[{remainingSpawnCount:1,hostile:1b,forced:1b,customTag:{factionName:"kong"},maxToSpawn:1,entityId:"ancientwarfarenpc:faction.archer.elite",minToSpawn:1}],groupWeight:1}],playerRange:32,respondToRedstone:0b,inventory:{Size:9,Items:[]},spawnRange:0,transparent:1b,maxDelay:0,xpToDrop:0,mobRange:0,debugMode:0b,maxNearbyMonsters:0}}}
:enddata
:endrule

rule:
plugin=blockTile
number=56
data:
JSON:{blockState:{blockName:"ancientwarfarestructure:advanced_spawner",properties:{transparent:"true"}},teData:{id:"ancientwarfarestructure:advanced_spawner_tile",spawnerSettings:{minDelay:0,spawnDelay:0,lightSensitive:0b,spawnGroups:[{settingsList:[{remainingSpawnCount:1,hostile:1b,forced:1b,customTag:{factionName:"kong"},maxToSpawn:1,entityId:"ancientwarfarenpc:faction.archer.elite",minToSpawn:1}],groupWeight:1}],playerRange:32,respondToRedstone:0b,inventory:{Size:9,Items:[]},spawnRange:0,transparent:1b,maxDelay:0,xpToDrop:0,mobRange:0,debugMode:0b,maxNearbyMonsters:0}}}
:enddata
:endrule

rule:
plugin=blockTile
number=57
data:
JSON:{blockState:{blockName:"ancientwarfarestructure:advanced_spawner",properties:{transparent:"true"}},teData:{id:"ancientwarfarestructure:advanced_spawner_tile",spawnerSettings:{minDelay:0,spawnDelay:0,lightSensitive:0b,spawnGroups:[{settingsList:[{remainingSpawnCount:1,hostile:1b,forced:1b,customTag:{factionName:"kong"},maxToSpawn:1,entityId:"ancientwarfarenpc:faction.archer.elite",minToSpawn:1}],groupWeight:1}],playerRange:32,respondToRedstone:0b,inventory:{Size:9,Items:[]},spawnRange:0,transparent:1b,maxDelay:0,xpToDrop:0,mobRange:0,debugMode:0b,maxNearbyMonsters:0}}}
:enddata
:endrule

rule:
plugin=blockTile
number=58
data:
JSON:{blockState:{blockName:"ancientwarfarestructure:advanced_spawner",properties:{transparent:"true"}},teData:{id:"ancientwarfarestructure:advanced_spawner_tile",spawnerSettings:{minDelay:0,spawnDelay:0,lightSensitive:0b,spawnGroups:[{settingsList:[{remainingSpawnCount:1,hostile:1b,forced:1b,customTag:{factionName:"kong"},maxToSpawn:1,entityId:"ancientwarfarenpc:faction.archer.elite",minToSpawn:1}],groupWeight:1}],playerRange:32,respondToRedstone:0b,inventory:{Size:9,Items:[]},spawnRange:0,transparent:1b,maxDelay:0,xpToDrop:0,mobRange:0,debugMode:0b,maxNearbyMonsters:0}}}
:enddata
:endrule

rule:
plugin=blockTile
number=59
data:
JSON:{blockState:{blockName:"ancientwarfarestructure:advanced_spawner",properties:{transparent:"true"}},teData:{id:"ancientwarfarestructure:advanced_spawner_tile",spawnerSettings:{minDelay:0,spawnDelay:0,lightSensitive:0b,spawnGroups:[{settingsList:[{remainingSpawnCount:1,hostile:1b,forced:1b,customTag:{factionName:"kong"},maxToSpawn:1,entityId:"ancientwarfarenpc:faction.archer.elite",minToSpawn:1}],groupWeight:1}],playerRange:32,respondToRedstone:0b,inventory:{Size:9,Items:[]},spawnRange:0,transparent:1b,maxDelay:0,xpToDrop:0,mobRange:0,debugMode:0b,maxNearbyMonsters:0}}}
:enddata
:endrule

rule:
plugin=blockTile
number=60
data:
JSON:{blockState:{blockName:"ancientwarfarestructure:advanced_spawner",properties:{transparent:"true"}},teData:{id:"ancientwarfarestructure:advanced_spawner_tile",spawnerSettings:{minDelay:0,spawnDelay:0,lightSensitive:0b,spawnGroups:[{settingsList:[{remainingSpawnCount:1,hostile:1b,forced:1b,customTag:{factionName:"kong"},maxToSpawn:1,entityId:"ancientwarfarenpc:faction.soldier",minToSpawn:1}],groupWeight:1}],playerRange:5,respondToRedstone:0b,inventory:{Size:9,Items:[]},spawnRange:0,transparent:1b,maxDelay:0,xpToDrop:0,mobRange:0,debugMode:0b,maxNearbyMonsters:0}}}
:enddata
:endrule

rule:
plugin=inventory
number=61
data:
JSON:{blockState:{blockName:"minecraft:chest",properties:{facing:"west"}},lootLevel:0,teData:{Items:[],id:"minecraft:chest",Lock:""},inventoryData:{length:0,inventoryContents:[]},legacyFeatures:1b}
:enddata
:endrule

rule:
plugin=blockTile
number=62
data:
JSON:{blockState:{blockName:"ancientwarfarestructure:advanced_spawner",properties:{transparent:"true"}},teData:{id:"ancientwarfarestructure:advanced_spawner_tile",spawnerSettings:{minDelay:0,spawnDelay:0,lightSensitive:0b,spawnGroups:[{settingsList:[{remainingSpawnCount:1,hostile:1b,forced:1b,customTag:{factionName:"kong"},maxToSpawn:1,entityId:"ancientwarfarenpc:faction.soldier",minToSpawn:1}],groupWeight:1}],playerRange:6,respondToRedstone:0b,inventory:{Size:9,Items:[]},spawnRange:0,transparent:1b,maxDelay:0,xpToDrop:0,mobRange:0,debugMode:0b,maxNearbyMonsters:0}}}
:enddata
:endrule

rule:
plugin=inventory
number=63
data:
JSON:{blockState:{blockName:"minecraft:chest",properties:{facing:"north"}},lootLevel:0,teData:{Items:[],id:"minecraft:chest",Lock:""},inventoryData:{length:0,inventoryContents:[]},legacyFeatures:1b}
:enddata
:endrule

rule:
plugin=blockTile
number=64
data:
JSON:{blockState:{blockName:"ancientwarfarestructure:advanced_spawner",properties:{transparent:"true"}},teData:{id:"ancientwarfarestructure:advanced_spawner_tile",spawnerSettings:{minDelay:0,spawnDelay:0,lightSensitive:0b,spawnGroups:[{settingsList:[{remainingSpawnCount:1,hostile:1b,forced:1b,customTag:{factionName:"kong"},maxToSpawn:1,entityId:"ancientwarfarenpc:faction.archer.elite",minToSpawn:1}],groupWeight:1}],playerRange:32,respondToRedstone:0b,inventory:{Size:9,Items:[]},spawnRange:0,transparent:1b,maxDelay:0,xpToDrop:0,mobRange:0,debugMode:0b,maxNearbyMonsters:0}}}
:enddata
:endrule

rule:
plugin=vine
number=65
data:
JSON:{blockState:{blockName:"minecraft:vine",properties:{east:"false",south:"false",north:"false",west:"false",up:"false"}}}
:enddata
:endrule

rule:
plugin=blockTile
number=66
data:
JSON:{blockState:{blockName:"ancientwarfarestructure:advanced_spawner",properties:{transparent:"true"}},teData:{id:"ancientwarfarestructure:advanced_spawner_tile",spawnerSettings:{minDelay:0,spawnDelay:0,lightSensitive:0b,spawnGroups:[{settingsList:[{remainingSpawnCount:1,hostile:1b,forced:1b,customTag:{factionName:"kong"},maxToSpawn:1,entityId:"ancientwarfarenpc:faction.soldier",minToSpawn:1}],groupWeight:1}],playerRange:6,respondToRedstone:0b,inventory:{Size:9,Items:[]},spawnRange:0,transparent:1b,maxDelay:0,xpToDrop:0,mobRange:0,debugMode:0b,maxNearbyMonsters:0}}}
:enddata
:endrule

rule:
plugin=vanillaSkull
number=67
data:
JSON:{blockState:{blockName:"minecraft:skull",properties:{nodrop:"false",facing:"up"}},skullRotation:12,teData:{Rot:12b,id:"minecraft:skull",SkullType:0b}}
:enddata
:endrule

rule:
plugin=inventory
number=68
data:
JSON:{blockState:{blockName:"minecraft:chest",properties:{facing:"east"}},lootLevel:0,teData:{ForgeData:{},Items:[],id:"minecraft:chest",Lock:""},inventoryData:{length:0,inventoryContents:[]},legacyFeatures:1b}
:enddata
:endrule

rule:
plugin=blockTile
number=69
data:
JSON:{blockState:{blockName:"ancientwarfarestructure:advanced_spawner",properties:{transparent:"true"}},teData:{id:"ancientwarfarestructure:advanced_spawner_tile",spawnerSettings:{minDelay:0,spawnDelay:0,lightSensitive:0b,spawnGroups:[{settingsList:[{remainingSpawnCount:1,hostile:1b,forced:1b,customTag:{factionName:"kong"},maxToSpawn:1,entityId:"ancientwarfarenpc:faction.soldier",minToSpawn:1}],groupWeight:1}],playerRange:6,respondToRedstone:0b,inventory:{Size:9,Items:[]},spawnRange:0,transparent:1b,maxDelay:0,xpToDrop:0,mobRange:0,debugMode:0b,maxNearbyMonsters:0}}}
:enddata
:endrule

rule:
plugin=blockTile
number=70
data:
JSON:{blockState:{blockName:"ancientwarfarestructure:advanced_spawner",properties:{transparent:"true"}},teData:{id:"ancientwarfarestructure:advanced_spawner_tile",spawnerSettings:{minDelay:0,spawnDelay:0,lightSensitive:0b,spawnGroups:[{settingsList:[{remainingSpawnCount:1,hostile:1b,forced:1b,customTag:{factionName:"kong"},maxToSpawn:1,entityId:"ancientwarfarenpc:faction.civilian.female",minToSpawn:1}],groupWeight:1}],playerRange:16,respondToRedstone:0b,inventory:{Size:9,Items:[]},spawnRange:0,transparent:1b,maxDelay:0,xpToDrop:0,mobRange:0,debugMode:0b,maxNearbyMonsters:0}}}
:enddata
:endrule

rule:
plugin=inventory
number=71
data:
JSON:{blockState:{blockName:"minecraft:chest",properties:{facing:"west"}},lootLevel:0,teData:{ForgeData:{},Items:[{Slot:0b,id:"minecraft:reeds",Count:12b,Damage:0s},{Slot:2b,id:"minecraft:feather",Count:12b,Damage:0s},{Slot:4b,id:"minecraft:string",Count:24b,Damage:0s},{Slot:7b,id:"minecraft:dye",Count:32b,Damage:15s},{Slot:10b,id:"minecraft:rotten_flesh",Count:32b,Damage:0s},{Slot:12b,id:"minecraft:spider_eye",Count:12b,Damage:0s},{Slot:13b,id:"minecraft:coal",Count:8b,Damage:1s},{Slot:14b,id:"minecraft:red_mushroom",Count:16b,Damage:0s},{Slot:19b,id:"minecraft:dye",Count:16b,Damage:3s},{Slot:23b,id:"minecraft:bone",Count:32b,Damage:0s},{Slot:24b,id:"minecraft:brown_mushroom",Count:16b,Damage:0s},{Slot:25b,id:"minecraft:flint",Count:12b,Damage:0s},{Slot:26b,id:"minecraft:rotten_flesh",Count:32b,Damage:0s}],id:"minecraft:chest",Lock:""},inventoryData:{length:13,inventoryContents:[{id:"minecraft:reeds",Count:12b,slot:0,Damage:0s},{id:"minecraft:feather",Count:12b,slot:1,Damage:0s},{id:"minecraft:string",Count:24b,slot:2,Damage:0s},{id:"minecraft:dye",Count:32b,slot:3,Damage:15s},{id:"minecraft:rotten_flesh",Count:32b,slot:4,Damage:0s},{id:"minecraft:spider_eye",Count:12b,slot:5,Damage:0s},{id:"minecraft:coal",Count:8b,slot:6,Damage:1s},{id:"minecraft:red_mushroom",Count:16b,slot:7,Damage:0s},{id:"minecraft:dye",Count:16b,slot:8,Damage:3s},{id:"minecraft:bone",Count:32b,slot:9,Damage:0s},{id:"minecraft:brown_mushroom",Count:16b,slot:10,Damage:0s},{id:"minecraft:flint",Count:12b,slot:11,Damage:0s},{id:"minecraft:rotten_flesh",Count:32b,slot:12,Damage:0s}]},legacyFeatures:1b}
:enddata
:endrule

#### ENTITIES ####
