# Ancient Warfare Structure Template File
# Auto-generated structure template file. created on: 1/5/2019 at: 21:30:58
# Lines beginning with # denote comments

header:
version=2.8
name=KongJungleTempleSmall
mods=
size=17,19,25
offset=7,3,24
:endheader

#### VALIDATION ####
validation:
type=ground
survival=false
worldGenEnabled=true
unique=false
preserveBlocks=false
selectionWeight=50
clusterValue=50
minDuplicateDistance=1000
dimensionWhiteList=true
dimensionList=0
biomeWhiteList=true
biomeList=minecraft:jungle
leveling=12
fill=4
border=6
blockSwap=false
:endvalidation

#### LAYERS ####
layer: 0
1,1,1,1,1,1,1,1,1,1,1,1,1,1,1,1,1
1,1,2,2,2,2,2,2,2,2,2,2,2,2,2,1,1
1,1,1,1,1,1,2,2,2,2,2,2,2,2,2,1,1
1,1,1,3,3,3,3,3,3,3,3,3,3,3,2,1,1
1,2,1,3,3,3,3,3,3,3,3,3,3,3,1,2,1
1,2,2,3,3,3,3,3,3,3,3,3,3,3,1,1,1
1,2,2,3,3,3,3,3,3,3,3,3,3,3,1,1,1
1,2,2,3,3,3,3,3,3,3,3,3,3,3,1,1,1
1,2,1,3,3,3,3,3,3,3,3,3,3,3,1,1,1
1,1,1,4,3,3,3,3,3,3,3,3,3,3,1,1,1
1,1,1,4,3,3,3,3,3,3,5,5,5,5,1,1,1
1,1,1,4,3,3,3,3,3,3,5,5,5,5,5,5,1
1,1,1,4,3,3,3,3,3,3,5,5,6,6,6,6,1
1,1,1,4,3,3,3,3,3,3,5,5,5,5,5,5,1
1,1,1,4,3,3,3,3,3,3,5,5,5,5,1,1,1
1,1,3,3,3,3,3,3,3,3,3,3,3,1,1,1,1
1,1,3,3,3,3,3,3,3,3,3,3,3,3,1,1,1
1,1,3,3,3,3,3,3,3,3,3,3,3,3,1,1,1
1,1,3,3,3,3,3,3,3,3,3,3,3,3,1,1,1
1,1,3,3,3,3,3,3,3,3,3,3,3,3,1,1,1
1,1,3,3,3,3,3,3,3,3,3,3,3,3,1,1,1
1,1,3,3,3,3,3,3,3,3,3,3,3,3,1,1,1
1,1,1,1,1,1,1,1,1,1,3,1,1,1,1,1,1
1,1,1,1,1,1,1,1,1,1,1,1,1,1,1,1,1
1,1,1,1,1,1,1,1,1,1,1,1,1,1,1,1,1
:endlayer
layer: 1
1,1,1,1,1,1,1,1,1,1,1,1,1,1,1,1,1
1,1,2,2,1,2,2,2,1,1,1,1,1,1,1,1,1
1,1,1,1,1,1,2,1,1,1,1,1,1,1,1,1,1
1,1,1,3,3,3,3,3,3,3,3,3,3,3,1,1,1
1,1,1,3,3,3,3,3,3,3,3,3,3,3,1,7,1
1,1,1,3,3,3,3,0,3,3,3,3,3,3,3,1,1
1,1,1,3,3,3,3,0,3,3,3,3,3,3,1,1,1
1,1,1,3,8,9,3,0,3,3,3,3,3,3,1,1,1
1,1,1,3,3,10,3,0,3,3,3,3,3,3,1,1,1
1,1,1,3,3,11,3,0,3,3,3,3,3,3,1,1,1
1,1,1,3,3,12,3,13,3,3,5,5,5,5,1,1,1
1,1,1,3,3,14,3,0,3,3,5,6,6,5,5,5,1
1,1,1,3,3,15,3,0,3,3,5,6,6,6,16,0,1
1,1,1,3,3,17,3,0,3,3,5,6,6,5,5,5,1
1,1,1,3,3,18,3,0,3,3,5,5,5,5,1,1,1
1,1,3,3,3,3,3,0,3,3,3,3,3,3,1,1,1
1,3,3,3,3,3,3,0,3,3,3,3,3,3,1,1,1
1,1,3,3,3,3,0,0,0,0,0,0,19,3,1,1,1
1,1,3,3,3,3,0,0,0,0,0,0,20,3,1,1,1
1,1,3,3,3,3,0,0,0,0,0,21,20,3,1,1,1
1,1,1,3,3,22,0,0,0,0,0,0,23,3,1,1,1
1,1,1,3,3,3,3,3,3,3,3,3,3,3,1,1,1
1,1,1,1,1,1,1,1,1,1,1,1,1,1,1,1,1
1,1,1,1,1,1,1,1,1,1,1,1,1,1,1,1,1
1,1,1,1,1,1,1,1,1,1,1,1,1,1,1,1,1
:endlayer
layer: 2
24,24,24,24,24,24,24,24,24,24,24,24,24,24,24,24,24
24,4,4,4,4,4,4,4,4,4,4,4,4,4,4,4,24
24,4,4,4,25,25,25,25,25,25,25,25,25,25,4,4,24
24,4,4,4,25,25,25,4,4,4,4,4,4,4,4,4,24
24,4,4,4,26,27,28,29,3,3,3,3,3,4,4,4,24
24,4,4,4,30,3,3,0,3,3,3,3,3,4,4,4,24
24,3,4,4,30,3,3,0,3,3,3,3,3,4,4,4,24
24,3,4,4,0,0,3,0,3,3,3,3,3,4,4,4,24
24,3,4,4,4,4,3,0,3,3,3,3,3,4,4,4,24
24,3,4,4,4,4,3,0,3,3,3,3,3,4,4,4,24
24,3,4,4,4,4,3,0,3,3,31,32,32,4,4,4,24
24,3,3,4,4,4,3,0,3,3,32,6,6,4,4,4,24
24,3,3,4,4,4,3,0,3,3,32,33,6,4,4,4,24
24,3,3,4,4,4,3,0,3,3,32,6,6,4,4,4,24
24,3,4,4,4,0,3,0,3,3,31,32,32,4,4,4,24
24,3,4,4,3,34,3,0,3,3,3,3,3,4,4,4,24
24,3,4,4,3,3,3,0,3,3,3,3,3,4,4,4,24
24,3,4,4,3,3,0,0,0,0,0,0,0,4,4,4,24
24,3,4,4,3,3,0,0,0,0,0,0,0,4,4,4,24
24,3,4,4,3,3,0,0,0,0,0,0,0,4,4,4,24
24,3,4,4,35,0,0,0,0,0,0,0,0,4,4,4,24
24,3,4,4,3,3,3,3,4,4,4,4,4,4,4,4,24
24,4,4,4,4,4,4,4,4,4,4,4,4,4,4,4,24
24,4,4,4,4,4,4,4,4,4,4,4,4,4,4,4,24
24,24,24,24,24,24,24,24,24,24,24,24,24,24,24,24,24
:endlayer
layer: 3
36,0,0,0,0,0,0,0,0,0,0,0,0,0,0,0,37
0,38,38,38,38,38,38,38,38,38,38,38,38,38,38,22,0
0,39,4,4,4,4,4,4,4,4,4,4,4,4,4,22,0
0,39,4,4,4,4,4,4,4,4,4,4,4,4,4,22,0
0,39,4,4,0,0,3,0,3,3,3,3,3,4,4,22,0
0,39,4,4,3,3,3,3,3,3,3,3,3,4,4,22,0
0,39,4,4,3,3,3,3,3,3,3,3,3,4,4,22,0
0,39,4,4,3,3,3,3,3,3,3,3,3,4,4,22,0
0,39,4,4,4,4,3,3,3,3,3,3,3,4,4,22,0
0,39,4,30,30,40,3,3,3,3,32,32,32,4,4,22,0
0,39,4,41,0,4,3,3,3,32,6,6,6,4,4,22,0
0,42,3,30,30,4,3,3,3,32,6,6,6,4,4,22,0
0,42,3,4,30,4,3,3,3,32,6,6,6,4,4,22,0
0,42,3,4,4,4,3,3,3,32,6,6,6,4,4,22,0
0,39,4,4,4,0,3,3,3,32,6,6,6,4,4,22,0
0,39,4,4,3,0,3,3,3,3,32,32,32,4,4,22,0
0,39,4,4,3,43,3,3,3,3,3,3,3,4,4,22,0
0,39,4,4,3,44,45,46,46,46,46,46,47,4,4,22,0
0,39,4,4,3,40,45,0,0,0,0,0,47,4,4,22,0
0,39,4,4,3,3,45,0,0,0,0,0,47,4,4,22,0
0,39,4,4,35,0,0,48,49,49,49,49,47,4,4,22,0
0,39,4,4,3,3,3,3,4,4,4,4,4,4,4,22,0
0,39,4,4,4,4,4,4,4,4,4,4,4,4,4,22,0
0,39,50,50,50,50,50,50,50,50,50,50,50,50,50,22,0
51,0,0,0,0,0,0,0,0,0,0,0,0,0,0,0,52
:endlayer
layer: 4
0,0,0,0,0,0,0,0,0,0,0,0,0,0,0,0,0
0,0,0,0,0,0,0,0,0,0,0,0,0,0,0,0,0
0,0,0,4,0,38,0,0,38,0,4,0,4,0,4,0,0
0,0,4,4,4,4,4,4,4,4,4,4,4,4,4,0,0
0,0,0,4,3,3,3,0,3,3,3,3,3,4,0,0,0
0,0,39,4,3,3,3,3,3,3,3,3,3,4,4,0,0
0,0,0,4,3,3,3,3,3,3,3,3,3,4,0,0,0
0,0,0,4,3,3,3,3,3,3,3,3,3,4,4,0,0
0,0,39,4,4,4,3,3,3,3,3,3,3,4,0,0,0
0,0,53,4,4,54,4,3,3,3,32,32,32,4,4,0,0
0,0,4,4,0,4,4,3,3,32,6,6,6,4,0,0,0
0,0,0,42,4,4,4,3,3,32,6,6,6,4,4,0,0
0,0,0,42,4,4,3,3,3,32,6,6,6,4,0,0,0
0,0,0,42,4,4,4,3,3,32,6,6,6,4,4,0,0
0,0,4,4,4,4,4,3,3,32,6,6,6,4,0,0,0
0,0,55,4,3,3,3,3,3,3,32,32,32,4,4,0,0
0,0,39,4,3,3,3,3,3,3,3,3,3,4,0,0,0
0,0,0,4,3,3,3,3,3,3,3,3,3,4,4,0,0
0,0,0,4,3,56,3,3,3,3,3,3,3,4,0,0,0
0,0,39,4,3,0,3,3,3,3,3,3,3,4,4,0,0
0,0,0,4,35,3,3,3,3,3,3,3,3,4,0,0,0
0,0,4,4,4,4,4,4,4,4,4,4,4,4,4,0,0
0,0,0,4,0,50,0,0,50,0,4,0,4,0,4,0,0
0,0,0,0,0,0,0,0,0,0,0,0,0,0,0,0,0
0,0,0,0,0,0,0,0,0,0,0,0,0,0,0,0,0
:endlayer
layer: 5
0,0,0,0,0,0,0,0,0,0,0,0,0,0,0,0,0
0,0,0,0,0,0,0,0,0,0,0,0,0,0,0,0,0
0,0,0,4,0,0,0,0,0,0,4,0,4,0,4,0,0
0,0,4,4,4,4,4,4,4,4,3,4,3,4,4,0,0
0,0,0,4,3,3,39,0,22,3,22,57,39,4,0,0,0
0,0,0,4,3,3,50,50,50,3,0,0,0,4,4,0,0
0,0,0,4,3,3,3,58,3,3,3,0,3,4,0,0,0
0,0,0,4,3,3,0,0,0,0,0,0,0,4,4,0,0
0,0,0,4,4,3,59,0,0,0,0,0,0,4,0,0,0
0,0,0,4,4,40,3,0,0,25,38,38,3,4,4,0,0
0,0,4,4,4,60,3,0,0,39,6,6,6,4,0,0,0
0,0,0,0,4,61,3,0,0,39,6,6,6,4,4,0,0
0,0,0,0,62,4,63,0,0,39,6,6,6,4,0,0,0
0,0,0,0,4,4,3,0,0,39,6,6,6,4,4,0,0
0,0,4,4,4,4,3,0,0,39,6,6,6,4,0,0,0
0,0,0,4,3,3,22,0,0,25,50,50,3,4,4,0,0
0,0,0,4,3,64,0,0,0,0,0,0,0,4,0,0,0
0,0,0,4,3,3,0,0,0,0,0,0,65,4,4,0,0
0,0,0,4,66,40,3,0,3,3,3,0,3,4,0,0,0
0,0,0,4,3,3,0,0,0,3,0,0,0,4,4,0,0
0,0,0,4,0,0,0,0,0,67,22,68,39,4,0,0,0
0,0,4,4,4,4,4,4,4,4,4,4,4,4,4,0,0
0,0,0,4,0,0,0,0,0,0,4,0,4,0,4,0,0
0,0,0,0,0,0,0,0,0,0,0,0,0,0,0,0,0
0,0,0,0,0,0,0,0,0,0,0,0,0,0,0,0,0
:endlayer
layer: 6
0,0,0,0,0,0,0,0,0,0,0,0,0,0,0,0,0
0,0,0,0,0,0,0,0,0,0,0,0,0,0,0,0,0
0,0,0,4,0,49,0,0,49,0,4,0,4,0,4,0,0
0,0,4,4,4,4,4,4,4,4,3,4,3,4,4,0,0
0,0,0,4,3,3,0,0,0,3,45,0,47,4,0,0,0
0,0,47,4,3,3,0,0,0,3,0,0,0,4,4,0,0
0,0,0,4,3,3,3,0,3,3,3,0,3,4,0,0,0
0,0,0,4,3,3,0,0,0,0,0,0,0,4,4,0,0
0,0,47,4,4,3,0,0,0,0,0,0,0,4,0,0,0
0,0,0,4,4,9,3,0,0,20,0,0,3,4,4,0,0
0,0,4,4,4,60,3,0,0,0,0,0,0,4,0,0,0
0,0,0,0,4,61,3,0,0,0,0,0,0,4,4,0,0
0,0,0,0,0,25,0,0,0,0,0,0,0,4,0,0,0
0,0,0,0,4,4,3,0,0,69,0,0,0,4,4,0,0
0,0,4,4,3,3,3,0,0,0,0,0,0,4,0,0,0
0,0,0,4,3,22,0,0,0,20,0,0,3,4,4,0,0
0,0,47,4,3,0,0,0,0,0,0,0,0,4,0,0,0
0,0,0,4,3,3,0,0,0,0,0,0,0,4,4,0,0
0,0,0,4,66,30,3,0,3,3,3,0,3,4,0,0,0
0,0,47,4,3,3,0,0,0,3,0,0,0,4,4,0,0
0,0,0,4,0,0,0,0,0,0,45,0,47,4,0,0,0
0,0,4,4,4,4,4,4,4,4,4,4,4,4,4,0,0
0,0,0,4,0,46,0,0,46,0,4,0,4,0,4,0,0
0,0,0,0,0,0,0,0,0,0,0,0,0,0,0,0,0
0,0,0,0,0,0,0,0,0,0,0,0,0,0,0,0,0
:endlayer
layer: 7
0,0,0,0,0,0,0,0,0,0,0,0,0,0,0,0,0
0,0,0,0,0,0,0,0,0,0,0,0,0,0,0,0,0
0,0,48,4,48,4,48,48,4,48,4,48,4,48,4,0,0
0,0,4,4,4,4,4,4,4,4,3,3,3,4,4,0,0
0,0,48,4,4,3,48,0,0,3,3,3,3,4,48,0,0
0,0,4,4,4,3,48,0,48,3,3,3,3,4,4,0,0
0,0,48,4,3,3,3,3,3,3,3,3,3,4,48,0,0
0,0,48,4,3,3,48,48,0,46,0,0,48,4,4,0,0
0,0,4,4,3,3,0,0,0,0,0,0,47,4,48,0,0
0,0,48,4,3,3,3,0,0,0,0,0,3,4,4,0,0
0,0,4,4,3,4,3,0,0,0,0,0,0,4,48,0,0
0,0,48,47,3,3,3,45,0,0,0,0,47,4,4,0,0
0,0,48,48,4,3,3,0,0,0,0,0,0,4,48,0,0
0,0,48,47,3,3,3,45,0,0,0,0,47,4,4,0,0
0,0,4,4,50,3,3,0,0,0,0,0,0,4,48,0,0
0,0,48,4,0,0,0,0,0,0,0,0,3,3,4,0,0
0,0,4,4,38,0,0,0,0,0,0,0,47,4,48,0,0
0,0,48,4,3,3,48,48,48,49,0,48,48,4,4,0,0
0,0,48,4,3,3,3,3,3,3,3,3,3,4,48,0,0
0,0,4,4,3,3,3,3,3,3,3,3,3,4,4,0,0
0,0,48,4,3,3,3,3,3,3,3,3,3,4,48,0,0
0,0,4,4,4,4,4,4,4,4,4,4,4,4,4,0,0
0,0,48,4,48,4,48,48,4,48,4,48,4,48,4,0,0
0,0,0,0,0,0,0,0,0,0,0,0,0,0,0,0,0
0,0,0,0,0,0,0,0,0,0,0,0,0,0,0,0,0
:endlayer
layer: 8
0,0,0,0,0,0,0,0,0,0,0,0,0,0,0,0,0
0,0,0,0,0,0,0,0,0,0,0,0,0,0,0,0,0
0,0,0,4,0,4,70,0,4,0,4,0,4,0,4,0,0
0,0,4,4,4,4,4,4,4,4,4,71,4,4,4,0,0
0,0,0,4,72,3,0,0,0,3,0,0,0,4,0,0,0
0,0,4,4,0,3,0,0,0,3,0,0,0,4,4,0,0
0,0,0,4,0,3,3,0,3,3,3,0,3,4,0,0,0
0,0,0,4,0,0,0,0,0,0,0,0,0,4,4,0,0
0,0,4,4,0,0,0,0,0,0,0,0,0,4,0,0,0
0,0,0,4,0,0,0,0,0,0,0,0,3,4,4,0,0
0,0,4,4,0,3,3,0,0,0,0,0,0,71,0,0,0
0,0,0,4,0,0,3,73,0,0,0,0,73,4,4,0,0
0,0,74,4,0,0,3,0,0,0,0,0,0,71,0,0,0
0,0,0,4,0,0,3,73,0,0,0,0,73,4,4,0,0
0,0,4,4,0,4,3,0,0,0,0,0,0,71,0,0,0
0,0,0,4,0,0,0,0,0,0,0,0,3,4,4,0,0
0,0,4,4,0,0,0,0,0,0,0,0,0,4,0,0,0
0,0,0,4,0,0,0,0,0,0,0,0,0,4,4,0,0
0,0,0,4,0,3,3,0,3,3,3,0,3,4,0,0,0
0,0,4,4,0,3,0,0,0,3,0,0,0,4,4,0,0
0,0,0,4,35,3,0,75,0,3,0,0,0,4,0,0,0
0,0,4,4,4,4,4,4,4,4,4,71,4,4,4,0,0
0,0,0,4,0,4,0,76,4,0,4,0,4,0,4,0,0
0,0,0,0,0,0,0,0,0,0,0,0,0,0,0,0,0
0,0,0,0,0,0,0,0,0,0,0,0,0,0,0,0,0
:endlayer
layer: 9
0,0,0,0,0,0,0,0,0,0,0,0,0,0,0,0,0
0,0,0,0,0,0,0,0,0,0,0,0,0,0,0,0,0
0,0,0,38,0,38,0,0,38,0,38,0,38,0,0,0,0
0,0,39,4,4,4,4,4,4,4,4,71,4,4,22,0,0
0,0,0,4,0,4,0,0,0,3,0,0,0,4,0,0,0
0,0,39,4,0,4,0,0,0,3,0,0,0,4,22,0,0
0,0,0,4,0,3,3,0,3,3,3,0,3,4,0,0,0
0,0,0,4,0,0,0,0,0,0,0,0,0,4,22,0,0
0,0,39,4,0,0,0,0,0,0,0,0,0,4,0,0,0
0,0,0,4,0,0,0,0,0,0,0,0,3,4,4,0,0
0,0,39,4,0,4,3,0,0,0,0,0,0,71,0,0,0
0,0,0,71,0,0,3,73,0,0,0,0,73,4,4,0,0
0,0,0,4,0,0,3,0,0,0,0,0,0,71,0,0,0
0,0,0,71,0,0,3,73,0,0,0,0,73,4,4,0,0
0,0,39,4,0,4,3,0,0,0,0,0,0,71,0,0,0
0,0,0,4,0,0,0,0,0,0,0,0,3,4,4,0,0
0,0,39,4,0,0,0,0,0,0,0,0,0,4,0,0,0
0,0,0,4,0,0,0,0,0,0,0,0,0,4,22,0,0
0,0,0,4,0,3,3,0,3,3,3,0,3,4,0,0,0
0,0,39,4,0,3,0,0,0,3,0,0,0,4,22,0,0
0,0,0,4,35,3,0,0,0,3,0,0,0,4,0,0,0
0,0,39,4,4,4,4,4,4,4,4,71,4,4,22,0,0
0,0,0,50,0,50,0,0,50,0,50,0,50,0,0,0,0
0,0,0,0,0,0,0,0,0,0,0,0,0,0,0,0,0
0,0,0,0,0,0,0,0,0,0,0,0,0,0,0,0,0
:endlayer
layer: 10
0,0,0,0,0,0,0,0,0,0,0,0,0,0,0,0,0
0,0,0,0,0,0,0,0,0,0,0,0,0,0,0,0,0
0,0,0,0,0,0,0,0,0,0,0,0,0,0,0,0,0
0,0,0,4,4,4,38,38,38,38,38,38,38,22,0,0,0
0,0,0,4,0,4,3,3,3,3,0,0,0,22,0,0,0
0,0,0,4,4,4,3,3,3,3,0,0,0,22,0,0,0
0,0,0,39,0,3,3,3,3,3,3,3,3,22,0,0,0
0,0,0,39,0,0,0,0,0,0,0,0,47,22,0,0,0
0,0,0,39,0,0,0,0,0,0,0,0,47,22,0,0,0
0,0,0,39,0,0,0,0,0,0,0,0,3,4,4,0,0
0,0,0,4,4,4,3,0,0,0,0,0,0,4,0,0,0
0,0,0,71,0,0,3,22,0,0,0,0,39,4,4,0,0
0,0,0,4,0,0,3,0,0,0,0,0,0,4,0,0,0
0,0,0,71,0,0,3,22,0,0,0,0,39,4,4,0,0
0,0,0,4,4,4,3,0,0,0,0,0,0,4,0,0,0
0,0,0,39,45,0,0,0,0,0,0,0,3,4,4,0,0
0,0,0,39,45,0,0,0,0,0,0,0,47,22,0,0,0
0,0,0,39,45,0,0,0,0,0,0,0,47,22,0,0,0
0,0,0,39,3,3,3,3,3,3,3,3,3,22,0,0,0
0,0,0,4,3,3,0,0,0,3,0,0,0,22,0,0,0
0,0,0,3,35,3,0,0,0,3,0,0,0,22,0,0,0
0,0,0,4,3,4,50,50,50,50,50,50,50,22,0,0,0
0,0,0,0,0,0,0,0,0,0,0,0,0,0,0,0,0
0,0,0,0,0,0,0,0,0,0,0,0,0,0,0,0,0
0,0,0,0,0,0,0,0,0,0,0,0,0,0,0,0,0
:endlayer
layer: 11
0,0,0,0,0,0,0,0,0,0,0,0,0,0,0,0,0
0,0,0,0,0,0,0,0,0,0,0,0,0,0,0,0,0
0,0,0,0,0,0,0,0,0,0,0,0,0,0,0,0,0
0,0,0,4,4,4,0,0,0,0,0,0,0,0,0,0,0
0,0,0,4,0,4,38,38,38,38,38,38,38,0,0,0,0
0,0,0,4,4,4,3,3,3,3,3,3,22,0,0,0,0
0,0,0,0,39,3,3,3,3,3,3,3,22,0,0,0,0
0,0,0,0,39,45,46,46,46,46,46,47,22,0,0,0,0
0,0,0,0,39,45,0,0,0,0,0,47,22,0,0,0,0
0,0,0,0,39,45,0,0,0,0,0,47,4,4,4,0,0
0,0,0,4,4,4,3,0,0,0,0,0,0,4,0,0,0
0,0,0,71,0,0,3,0,0,0,0,0,0,4,4,0,0
0,0,0,4,0,0,3,0,0,0,0,0,0,4,0,0,0
0,0,0,71,0,0,3,0,0,0,0,0,0,4,4,0,0
0,0,0,4,4,4,3,0,0,0,0,0,0,4,0,0,0
0,0,0,0,39,45,0,0,0,0,0,47,4,4,4,0,0
0,0,0,0,39,45,0,0,0,0,0,47,22,0,0,0,0
0,0,0,0,39,45,49,49,49,49,49,47,22,0,0,0,0
0,0,0,0,39,3,3,3,3,3,3,3,22,0,0,0,0
0,0,0,4,3,3,3,3,3,3,3,3,22,0,0,0,0
0,0,0,3,35,3,50,50,50,50,50,50,22,0,0,0,0
0,0,0,4,3,4,0,0,0,0,0,0,0,0,0,0,0
0,0,0,0,0,0,0,0,0,0,0,0,0,0,0,0,0
0,0,0,0,0,0,0,0,0,0,0,0,0,0,0,0,0
0,0,0,0,0,0,0,0,0,0,0,0,0,0,0,0,0
:endlayer
layer: 12
0,0,0,0,0,0,0,0,0,0,0,0,0,0,0,0,0
0,0,0,0,0,0,0,0,0,0,0,0,0,0,0,0,0
0,0,0,0,0,0,0,0,0,0,0,0,0,0,0,0,0
0,0,0,4,4,4,0,0,0,0,0,0,0,0,0,0,0
0,0,0,4,0,4,0,0,0,0,0,0,0,0,0,0,0
0,0,0,4,4,4,38,38,38,38,38,22,0,0,0,0,0
0,0,0,0,0,39,3,3,3,3,3,22,0,0,0,0,0
0,0,0,0,0,39,3,3,3,3,3,22,0,0,0,0,0
0,0,0,0,0,39,46,46,46,46,47,22,0,0,0,0,0
0,0,0,0,0,39,45,0,0,0,47,4,4,4,4,0,0
0,0,0,4,4,4,3,0,0,0,46,46,46,4,45,0,0
0,0,0,4,45,46,3,0,0,0,0,0,47,4,4,0,0
0,0,0,4,45,0,3,0,0,0,0,0,47,4,45,0,0
0,0,0,4,45,49,3,0,0,0,0,0,47,4,4,0,0
0,0,0,4,4,4,3,0,0,0,49,49,49,4,45,0,0
0,0,0,0,0,39,45,0,0,0,47,4,4,4,4,0,0
0,0,0,0,0,39,45,49,49,49,47,22,0,0,0,0,0
0,0,0,0,0,39,3,3,3,3,3,22,0,0,0,0,0
0,0,0,0,0,39,3,3,3,3,3,22,0,0,0,0,0
0,0,0,4,4,4,50,50,50,50,50,22,0,0,0,0,0
0,0,0,4,35,4,0,0,0,0,0,0,0,0,0,0,0
0,0,0,4,4,4,0,0,0,0,0,0,0,0,0,0,0
0,0,0,0,0,0,0,0,0,0,0,0,0,0,0,0,0
0,0,0,0,0,0,0,0,0,0,0,0,0,0,0,0,0
0,0,0,0,0,0,0,0,0,0,0,0,0,0,0,0,0
:endlayer
layer: 13
0,0,0,0,0,0,0,0,0,0,0,0,0,0,0,0,0
0,0,0,0,0,0,0,0,0,0,0,0,0,0,0,0,0
0,0,0,0,0,0,0,0,0,0,0,0,0,0,0,0,0
0,0,0,4,4,4,0,0,0,0,0,0,0,0,0,0,0
0,0,0,4,0,4,0,0,0,0,0,0,0,0,0,0,0
0,0,0,4,4,4,0,0,0,0,0,0,0,0,0,0,0
0,0,0,0,0,0,39,38,38,38,22,0,0,0,0,0,0
0,0,0,0,0,0,39,3,3,3,22,0,0,0,0,0,0
0,0,0,0,0,0,39,3,77,3,22,0,0,0,0,0,0
0,0,0,0,0,0,3,45,0,47,38,38,38,38,22,0,0
0,0,0,4,4,4,4,45,0,47,3,3,3,3,22,0,0
0,0,0,4,3,3,3,45,0,47,3,3,3,3,22,0,0
0,0,0,4,3,3,3,45,0,47,3,3,3,3,22,0,0
0,0,0,4,3,3,3,45,0,47,3,3,3,3,22,0,0
0,0,0,4,4,4,4,45,0,47,3,3,3,3,22,0,0
0,0,0,0,0,0,4,45,0,47,22,50,50,50,22,0,0
0,0,0,0,0,0,39,3,77,3,22,0,0,0,0,0,0
0,0,0,0,0,0,39,3,3,3,22,0,0,0,0,0,0
0,0,0,0,0,0,50,50,50,50,22,0,0,0,0,0,0
0,0,0,4,4,4,0,0,0,0,0,0,0,0,0,0,0
0,0,0,4,35,4,0,0,0,0,0,0,0,0,0,0,0
0,0,0,4,4,4,0,0,0,0,0,0,0,0,0,0,0
0,0,0,0,0,0,0,0,0,0,0,0,0,0,0,0,0
0,0,0,0,0,0,0,0,0,0,0,0,0,0,0,0,0
0,0,0,0,0,0,0,0,0,0,0,0,0,0,0,0,0
:endlayer
layer: 14
0,0,0,0,0,0,0,0,0,0,0,0,0,0,0,0,0
0,0,0,0,0,0,0,0,0,0,0,0,0,0,0,0,0
0,0,0,0,0,0,0,0,0,0,0,0,0,0,0,0,0
0,0,0,4,71,4,0,0,0,0,0,0,0,0,0,0,0
0,0,0,71,0,71,0,0,0,0,0,0,0,0,0,0,0
0,0,0,4,71,4,0,0,0,0,0,0,0,0,0,0,0
0,0,0,0,0,0,0,0,0,0,0,0,0,0,0,0,0
0,0,0,0,0,0,0,39,38,22,0,0,0,0,0,0,0
0,0,0,0,0,0,0,39,3,22,0,0,0,0,0,0,0
0,0,0,0,0,0,0,39,46,22,0,0,0,0,0,0,0
0,0,0,42,42,42,42,39,48,22,42,42,42,42,0,0,0
0,0,0,42,3,3,3,3,48,3,3,3,3,42,0,0,0
0,0,0,42,3,3,3,3,48,3,3,3,3,42,0,0,0
0,0,0,42,3,3,3,3,48,3,3,3,3,42,0,0,0
0,0,0,42,42,42,42,39,48,22,42,42,42,42,0,0,0
0,0,0,0,0,0,0,39,49,22,0,0,0,0,0,0,0
0,0,0,0,0,0,0,39,3,22,0,0,0,0,0,0,0
0,0,0,0,0,0,0,39,50,22,0,0,0,0,0,0,0
0,0,0,0,0,0,0,0,0,0,0,0,0,0,0,0,0
0,0,0,4,71,4,0,0,0,0,0,0,0,0,0,0,0
0,0,0,71,0,71,0,0,0,0,0,0,0,0,0,0,0
0,0,0,4,71,4,0,0,0,0,0,0,0,0,0,0,0
0,0,0,0,0,0,0,0,0,0,0,0,0,0,0,0,0
0,0,0,0,0,0,0,0,0,0,0,0,0,0,0,0,0
0,0,0,0,0,0,0,0,0,0,0,0,0,0,0,0,0
:endlayer
layer: 15
0,0,0,0,0,0,0,0,0,0,0,0,0,0,0,0,0
0,0,0,0,0,0,0,0,0,0,0,0,0,0,0,0,0
0,0,0,0,0,0,0,0,0,0,0,0,0,0,0,0,0
0,0,0,4,71,4,0,0,0,0,0,0,0,0,0,0,0
0,0,0,71,0,71,0,0,0,0,0,0,0,0,0,0,0
0,0,0,4,71,4,0,0,0,0,0,0,0,0,0,0,0
0,0,0,0,0,0,0,0,0,0,0,0,0,0,0,0,0
0,0,0,0,0,0,0,0,0,0,0,0,0,0,0,0,0
0,0,0,0,0,0,0,0,42,0,0,0,0,0,0,0,0
0,0,0,0,0,0,0,0,42,0,0,0,0,0,0,0,0
0,0,0,0,0,0,0,0,42,0,0,0,0,0,0,0,0
0,0,0,0,0,0,0,0,42,0,0,0,0,0,0,0,0
0,0,0,78,0,42,42,42,42,42,42,42,0,79,0,0,0
0,0,0,0,0,0,0,0,42,0,0,0,0,0,0,0,0
0,0,0,0,0,0,0,0,42,0,0,0,0,0,0,0,0
0,0,0,0,0,0,0,0,42,0,0,0,0,0,0,0,0
0,0,0,0,0,0,0,0,42,0,0,0,0,0,0,0,0
0,0,0,0,0,0,0,0,0,0,0,0,0,0,0,0,0
0,0,0,0,0,0,0,0,0,0,0,0,0,0,0,0,0
0,0,0,4,71,4,0,0,0,0,0,0,0,0,0,0,0
0,0,0,71,0,71,0,0,0,0,0,0,0,0,0,0,0
0,0,0,4,71,4,0,0,0,0,0,0,0,0,0,0,0
0,0,0,0,0,0,0,0,0,0,0,0,0,0,0,0,0
0,0,0,0,0,0,0,0,0,0,0,0,0,0,0,0,0
0,0,0,0,0,0,0,0,0,0,0,0,0,0,0,0,0
:endlayer
layer: 16
0,0,0,0,0,0,0,0,0,0,0,0,0,0,0,0,0
0,0,0,0,0,0,0,0,0,0,0,0,0,0,0,0,0
0,0,0,0,0,0,0,0,0,0,0,0,0,0,0,0,0
0,0,0,4,4,4,0,0,0,0,0,0,0,0,0,0,0
0,0,0,4,0,4,0,0,0,0,0,0,0,0,0,0,0
0,0,0,4,4,4,0,0,0,0,0,0,0,0,0,0,0
0,0,0,0,0,0,0,0,0,0,0,0,0,0,0,0,0
0,0,0,0,0,0,0,0,0,0,0,0,0,0,0,0,0
0,0,0,0,0,0,0,0,0,0,0,0,0,0,0,0,0
0,0,0,0,0,0,0,0,0,0,0,0,0,0,0,0,0
0,0,0,0,0,0,0,0,0,0,0,0,0,0,0,0,0
0,0,0,0,0,0,0,0,0,0,0,0,0,0,0,0,0
0,0,0,0,0,0,0,0,0,0,0,0,0,0,0,0,0
0,0,0,0,0,0,0,0,0,0,0,0,0,0,0,0,0
0,0,0,0,0,0,0,0,0,0,0,0,0,0,0,0,0
0,0,0,0,0,0,0,0,0,0,0,0,0,0,0,0,0
0,0,0,0,0,0,0,0,0,0,0,0,0,0,0,0,0
0,0,0,0,0,0,0,0,0,0,0,0,0,0,0,0,0
0,0,0,0,0,0,0,0,0,0,0,0,0,0,0,0,0
0,0,0,4,4,4,0,0,0,0,0,0,0,0,0,0,0
0,0,0,4,48,4,0,0,0,0,0,0,0,0,0,0,0
0,0,0,4,4,4,0,0,0,0,0,0,0,0,0,0,0
0,0,0,0,0,0,0,0,0,0,0,0,0,0,0,0,0
0,0,0,0,0,0,0,0,0,0,0,0,0,0,0,0,0
0,0,0,0,0,0,0,0,0,0,0,0,0,0,0,0,0
:endlayer
layer: 17
0,0,0,0,0,0,0,0,0,0,0,0,0,0,0,0,0
0,0,0,0,0,0,0,0,0,0,0,0,0,0,0,0,0
0,0,0,0,0,0,0,0,0,0,0,0,0,0,0,0,0
0,0,0,39,38,38,0,0,0,0,0,0,0,0,0,0,0
0,0,0,39,4,22,0,0,0,0,0,0,0,0,0,0,0
0,0,0,50,50,22,0,0,0,0,0,0,0,0,0,0,0
0,0,0,0,0,0,0,0,0,0,0,0,0,0,0,0,0
0,0,0,0,0,0,0,0,0,0,0,0,0,0,0,0,0
0,0,0,0,0,0,0,0,0,0,0,0,0,0,0,0,0
0,0,0,0,0,0,0,0,0,0,0,0,0,0,0,0,0
0,0,0,0,0,0,0,0,0,0,0,0,0,0,0,0,0
0,0,0,0,0,0,0,0,0,0,0,0,0,0,0,0,0
0,0,0,0,0,0,0,0,0,0,0,0,0,0,0,0,0
0,0,0,0,0,0,0,0,0,0,0,0,0,0,0,0,0
0,0,0,0,0,0,0,0,0,0,0,0,0,0,0,0,0
0,0,0,0,0,0,0,0,0,0,0,0,0,0,0,0,0
0,0,0,0,0,0,0,0,0,0,0,0,0,0,0,0,0
0,0,0,0,0,0,0,0,0,0,0,0,0,0,0,0,0
0,0,0,0,0,0,0,0,0,0,0,0,0,0,0,0,0
0,0,0,39,38,38,0,0,0,0,0,0,0,0,0,0,0
0,0,0,39,4,22,0,0,0,0,0,0,0,0,0,0,0
0,0,0,39,50,22,0,0,0,0,0,0,0,0,0,0,0
0,0,0,0,0,0,0,0,0,0,0,0,0,0,0,0,0
0,0,0,0,0,0,0,0,0,0,0,0,0,0,0,0,0
0,0,0,0,0,0,0,0,0,0,0,0,0,0,0,0,0
:endlayer
layer: 18
0,0,0,0,0,0,0,0,0,0,0,0,0,0,0,0,0
0,0,0,0,0,0,0,0,0,0,0,0,0,0,0,0,0
0,0,0,0,0,0,0,0,0,0,0,0,0,0,0,0,0
0,0,0,0,0,0,0,0,0,0,0,0,0,0,0,0,0
0,0,0,0,42,0,0,0,0,0,0,0,0,0,0,0,0
0,0,0,0,0,0,0,0,0,0,0,0,0,0,0,0,0
0,0,0,0,0,0,0,0,0,0,0,0,0,0,0,0,0
0,0,0,0,0,0,0,0,0,0,0,0,0,0,0,0,0
0,0,0,0,0,0,0,0,0,0,0,0,0,0,0,0,0
0,0,0,0,0,0,0,0,0,0,0,0,0,0,0,0,0
0,0,0,0,0,0,0,0,0,0,0,0,0,0,0,0,0
0,0,0,0,0,0,0,0,0,0,0,0,0,0,0,0,0
0,0,0,0,0,0,0,0,0,0,0,0,0,0,0,0,0
0,0,0,0,0,0,0,0,0,0,0,0,0,0,0,0,0
0,0,0,0,0,0,0,0,0,0,0,0,0,0,0,0,0
0,0,0,0,0,0,0,0,0,0,0,0,0,0,0,0,0
0,0,0,0,0,0,0,0,0,0,0,0,0,0,0,0,0
0,0,0,0,0,0,0,0,0,0,0,0,0,0,0,0,0
0,0,0,0,0,0,0,0,0,0,0,0,0,0,0,0,0
0,0,0,0,0,0,0,0,0,0,0,0,0,0,0,0,0
0,0,0,0,42,0,0,0,0,0,0,0,0,0,0,0,0
0,0,0,0,0,0,0,0,0,0,0,0,0,0,0,0,0
0,0,0,0,0,0,0,0,0,0,0,0,0,0,0,0,0
0,0,0,0,0,0,0,0,0,0,0,0,0,0,0,0,0
0,0,0,0,0,0,0,0,0,0,0,0,0,0,0,0,0
:endlayer

#### RULES ####
rule:
plugin=vanillaBlocks
number=1
data:
JSON:{blockState:{blockName:"minecraft:dirt",properties:{variant:"dirt",snowy:"false"}}}
:enddata
:endrule

rule:
plugin=vanillaBlocks
number=2
data:
JSON:{blockState:{blockName:"minecraft:stone",properties:{variant:"stone"}}}
:enddata
:endrule

rule:
plugin=vanillaBlocks
number=3
data:
JSON:{blockState:{blockName:"minecraft:stonebrick",properties:{variant:"stonebrick"}}}
:enddata
:endrule

rule:
plugin=vanillaBlocks
number=4
data:
JSON:{blockState:{blockName:"minecraft:stonebrick",properties:{variant:"mossy_stonebrick"}}}
:enddata
:endrule

rule:
plugin=vanillaBlocks
number=5
data:
JSON:{blockState:{blockName:"minecraft:stained_hardened_clay",properties:{color:"black"}}}
:enddata
:endrule

rule:
plugin=fluid
number=6
data:
JSON:{blockState:{blockName:"minecraft:water",properties:{level:"0"}}}
:enddata
:endrule

rule:
plugin=vanillaBlocks
number=7
data:
JSON:{blockState:{blockName:"minecraft:sand",properties:{variant:"sand"}}}
:enddata
:endrule

rule:
plugin=vanillaBlocks
number=8
data:
JSON:{blockState:{blockName:"minecraft:redstone_torch",properties:{facing:"south"}}}
:enddata
:endrule

rule:
plugin=vanillaBlocks
number=9
data:
JSON:{blockState:{blockName:"minecraft:redstone_wire",properties:{east:"none",south:"none",north:"none",west:"none",power:"15"}}}
:enddata
:endrule

rule:
plugin=vanillaBlocks
number=10
data:
JSON:{blockState:{blockName:"minecraft:redstone_wire",properties:{east:"none",south:"none",north:"none",west:"none",power:"14"}}}
:enddata
:endrule

rule:
plugin=vanillaBlocks
number=11
data:
JSON:{blockState:{blockName:"minecraft:redstone_wire",properties:{east:"none",south:"none",north:"none",west:"none",power:"13"}}}
:enddata
:endrule

rule:
plugin=vanillaBlocks
number=12
data:
JSON:{blockState:{blockName:"minecraft:redstone_wire",properties:{east:"none",south:"none",north:"none",west:"none",power:"12"}}}
:enddata
:endrule

rule:
plugin=blockTile
number=13
data:
JSON:{blockState:{blockName:"ancientwarfarestructure:advanced_spawner",properties:{transparent:"true"}},teData:{id:"ancientwarfarestructure:advanced_spawner_tile",spawnerSettings:{minDelay:0,spawnDelay:0,lightSensitive:0b,spawnGroups:[{settingsList:[{remainingSpawnCount:1,hostile:1b,forced:1b,customTag:{factionName:"kong"},maxToSpawn:1,entityId:"ancientwarfarenpc:faction.soldier.elite",minToSpawn:1}],groupWeight:1}],playerRange:3,respondToRedstone:0b,inventory:{Size:9,Items:[]},spawnRange:0,transparent:1b,maxDelay:0,xpToDrop:0,mobRange:0,debugMode:0b,maxNearbyMonsters:0}}}
:enddata
:endrule

rule:
plugin=vanillaBlocks
number=14
data:
JSON:{blockState:{blockName:"minecraft:redstone_wire",properties:{east:"none",south:"none",north:"none",west:"none",power:"11"}}}
:enddata
:endrule

rule:
plugin=vanillaBlocks
number=15
data:
JSON:{blockState:{blockName:"minecraft:redstone_wire",properties:{east:"none",south:"none",north:"none",west:"none",power:"10"}}}
:enddata
:endrule

rule:
plugin=fluid
number=16
data:
JSON:{blockState:{blockName:"minecraft:water",properties:{level:"1"}}}
:enddata
:endrule

rule:
plugin=vanillaBlocks
number=17
data:
JSON:{blockState:{blockName:"minecraft:redstone_wire",properties:{east:"none",south:"none",north:"none",west:"none",power:"9"}}}
:enddata
:endrule

rule:
plugin=vanillaBlocks
number=18
data:
JSON:{blockState:{blockName:"minecraft:redstone_wire",properties:{east:"none",south:"none",north:"none",west:"none",power:"8"}}}
:enddata
:endrule

rule:
plugin=blockTile
number=19
data:
JSON:{blockState:{blockName:"ancientwarfarestructure:advanced_loot_chest",properties:{facing:"west"}},teData:{LootTable:"ancientwarfare:inject/chests/jungle_temple",lootRolls:2b,id:"ancientwarfarestructure:advanced_loot_chest_tile",Lock:"",LootTableSeed:3579877664757362315L}}
:enddata
:endrule

rule:
plugin=vanillaBlocks
number=20
data:
JSON:{blockState:{blockName:"ancientwarfarestructure:fire_pit",properties:{lit:"true",variant:"default"}}}
:enddata
:endrule

rule:
plugin=blockTile
number=21
data:
JSON:{blockState:{blockName:"ancientwarfarestructure:advanced_spawner",properties:{transparent:"true"}},teData:{id:"ancientwarfarestructure:advanced_spawner_tile",spawnerSettings:{minDelay:0,spawnDelay:0,lightSensitive:0b,spawnGroups:[{settingsList:[{remainingSpawnCount:12,hostile:1b,forced:1b,customTag:{},maxToSpawn:12,entityId:"minecraft:bat",minToSpawn:6}],groupWeight:1}],playerRange:2,respondToRedstone:0b,inventory:{Size:9,Items:[]},spawnRange:0,transparent:1b,maxDelay:0,xpToDrop:20,mobRange:0,debugMode:0b,maxNearbyMonsters:0}}}
:enddata
:endrule

rule:
plugin=vanillaBlocks
number=22
data:
JSON:{blockState:{blockName:"minecraft:stone_brick_stairs",properties:{half:"bottom",shape:"straight",facing:"west"}}}
:enddata
:endrule

rule:
plugin=blockTile
number=23
data:
JSON:{blockState:{blockName:"ancientwarfarestructure:advanced_loot_chest",properties:{facing:"west"}},teData:{LootTable:"ancientwarfare:inject/chests/jungle_temple",lootRolls:2b,id:"ancientwarfarestructure:advanced_loot_chest_tile",Lock:"",LootTableSeed:3574920215107309931L}}
:enddata
:endrule

rule:
plugin=vanillaBlocks
number=24
data:
JSON:{blockState:{blockName:"minecraft:grass",properties:{snowy:"false"}}}
:enddata
:endrule

rule:
plugin=vanillaBlocks
number=25
data:
JSON:{blockState:{blockName:"minecraft:stonebrick",properties:{variant:"cracked_stonebrick"}}}
:enddata
:endrule

rule:
plugin=vanillaBlocks
number=26
data:
JSON:{blockState:{blockName:"minecraft:unlit_redstone_torch",properties:{facing:"west"}}}
:enddata
:endrule

rule:
plugin=vanillaBlocks
number=27
data:
JSON:{blockState:{blockName:"minecraft:stone",properties:{variant:"smooth_andesite"}}}
:enddata
:endrule

rule:
plugin=vanillaBlocks
number=28
data:
JSON:{blockState:{blockName:"minecraft:redstone_wire",properties:{east:"none",south:"none",north:"none",west:"none",power:"1"}}}
:enddata
:endrule

rule:
plugin=vanillaBlocks
number=29
data:
JSON:{blockState:{blockName:"minecraft:heavy_weighted_pressure_plate",properties:{power:"1"}}}
:enddata
:endrule

rule:
plugin=vanillaBlocks
number=30
data:
JSON:{blockState:{blockName:"minecraft:redstone_wire",properties:{east:"none",south:"none",north:"none",west:"none",power:"0"}}}
:enddata
:endrule

rule:
plugin=vanillaBlocks
number=31
data:
JSON:{blockState:{blockName:"minecraft:sea_lantern"}}
:enddata
:endrule

rule:
plugin=vanillaBlocks
number=32
data:
JSON:{blockState:{blockName:"minecraft:prismarine",properties:{variant:"prismarine"}}}
:enddata
:endrule

rule:
plugin=inventory
number=33
data:
JSON:{blockState:{blockName:"minecraft:chest",properties:{facing:"east"}},lootLevel:2,teData:{ForgeData:{},Items:[{Slot:13b,id:"minecraft:diamond",Count:8b,Damage:0s}],id:"minecraft:chest",Lock:""},inventoryData:{length:1,inventoryContents:[{id:"minecraft:diamond",Count:8b,slot:0,Damage:0s}]},legacyFeatures:1b}
:enddata
:endrule

rule:
plugin=vanillaBlocks
number=34
data:
JSON:{blockState:{blockName:"minecraft:redstone_wire",properties:{east:"none",south:"none",north:"none",west:"none",power:"7"}}}
:enddata
:endrule

rule:
plugin=vanillaBlocks
number=35
data:
JSON:{blockState:{blockName:"minecraft:ladder",properties:{facing:"north"}}}
:enddata
:endrule

rule:
plugin=blockTile
number=36
data:
JSON:{blockState:{blockName:"ancientwarfarestructure:advanced_spawner",properties:{transparent:"true"}},teData:{id:"ancientwarfarestructure:advanced_spawner_tile",spawnerSettings:{minDelay:0,spawnDelay:0,lightSensitive:0b,spawnGroups:[{settingsList:[{remainingSpawnCount:1,hostile:1b,forced:1b,customTag:{factionName:"kong"},maxToSpawn:1,entityId:"ancientwarfarenpc:faction.soldier",minToSpawn:1}],groupWeight:1}],playerRange:16,respondToRedstone:0b,inventory:{Size:9,Items:[]},spawnRange:0,transparent:1b,maxDelay:0,xpToDrop:0,mobRange:0,debugMode:0b,maxNearbyMonsters:0}}}
:enddata
:endrule

rule:
plugin=blockTile
number=37
data:
JSON:{blockState:{blockName:"ancientwarfarestructure:advanced_spawner",properties:{transparent:"true"}},teData:{id:"ancientwarfarestructure:advanced_spawner_tile",spawnerSettings:{minDelay:0,spawnDelay:0,lightSensitive:0b,spawnGroups:[{settingsList:[{remainingSpawnCount:1,hostile:1b,forced:1b,customTag:{factionName:"kong"},maxToSpawn:1,entityId:"ancientwarfarenpc:faction.soldier",minToSpawn:1}],groupWeight:1}],playerRange:16,respondToRedstone:0b,inventory:{Size:9,Items:[]},spawnRange:0,transparent:1b,maxDelay:0,xpToDrop:0,mobRange:0,debugMode:0b,maxNearbyMonsters:0}}}
:enddata
:endrule

rule:
plugin=vanillaBlocks
number=38
data:
JSON:{blockState:{blockName:"minecraft:stone_brick_stairs",properties:{half:"bottom",shape:"straight",facing:"south"}}}
:enddata
:endrule

rule:
plugin=vanillaBlocks
number=39
data:
JSON:{blockState:{blockName:"minecraft:stone_brick_stairs",properties:{half:"bottom",shape:"straight",facing:"east"}}}
:enddata
:endrule

rule:
plugin=vanillaBlocks
number=40
data:
JSON:{blockState:{blockName:"minecraft:wool",properties:{color:"blue"}}}
:enddata
:endrule

rule:
plugin=vanillaBlocks
number=41
data:
JSON:{blockState:{blockName:"minecraft:unpowered_repeater",properties:{delay:"4",facing:"south",locked:"false"}}}
:enddata
:endrule

rule:
plugin=vanillaBlocks
number=42
data:
JSON:{blockState:{blockName:"minecraft:stone_slab",properties:{half:"bottom",variant:"stone_brick"}}}
:enddata
:endrule

rule:
plugin=vanillaBlocks
number=43
data:
JSON:{blockState:{blockName:"minecraft:redstone_wire",properties:{east:"none",south:"none",north:"none",west:"none",power:"6"}}}
:enddata
:endrule

rule:
plugin=vanillaBlocks
number=44
data:
JSON:{blockState:{blockName:"minecraft:redstone_wire",properties:{east:"none",south:"none",north:"none",west:"none",power:"5"}}}
:enddata
:endrule

rule:
plugin=vanillaBlocks
number=45
data:
JSON:{blockState:{blockName:"minecraft:stone_brick_stairs",properties:{half:"top",shape:"straight",facing:"west"}}}
:enddata
:endrule

rule:
plugin=vanillaBlocks
number=46
data:
JSON:{blockState:{blockName:"minecraft:stone_brick_stairs",properties:{half:"top",shape:"straight",facing:"north"}}}
:enddata
:endrule

rule:
plugin=vanillaBlocks
number=47
data:
JSON:{blockState:{blockName:"minecraft:stone_brick_stairs",properties:{half:"top",shape:"straight",facing:"east"}}}
:enddata
:endrule

rule:
plugin=vanillaBlocks
number=48
data:
JSON:{blockState:{blockName:"minecraft:stone_slab",properties:{half:"top",variant:"stone_brick"}}}
:enddata
:endrule

rule:
plugin=vanillaBlocks
number=49
data:
JSON:{blockState:{blockName:"minecraft:stone_brick_stairs",properties:{half:"top",shape:"straight",facing:"south"}}}
:enddata
:endrule

rule:
plugin=vanillaBlocks
number=50
data:
JSON:{blockState:{blockName:"minecraft:stone_brick_stairs",properties:{half:"bottom",shape:"straight",facing:"north"}}}
:enddata
:endrule

rule:
plugin=blockTile
number=51
data:
JSON:{blockState:{blockName:"ancientwarfarestructure:advanced_spawner",properties:{transparent:"true"}},teData:{id:"ancientwarfarestructure:advanced_spawner_tile",spawnerSettings:{minDelay:0,spawnDelay:0,lightSensitive:0b,spawnGroups:[{settingsList:[{remainingSpawnCount:1,hostile:1b,forced:1b,customTag:{factionName:"kong"},maxToSpawn:1,entityId:"ancientwarfarenpc:faction.soldier",minToSpawn:1}],groupWeight:1}],playerRange:16,respondToRedstone:0b,inventory:{Size:9,Items:[]},spawnRange:0,transparent:1b,maxDelay:0,xpToDrop:0,mobRange:0,debugMode:0b,maxNearbyMonsters:0}}}
:enddata
:endrule

rule:
plugin=blockTile
number=52
data:
JSON:{blockState:{blockName:"ancientwarfarestructure:advanced_spawner",properties:{transparent:"true"}},teData:{id:"ancientwarfarestructure:advanced_spawner_tile",spawnerSettings:{minDelay:0,spawnDelay:0,lightSensitive:0b,spawnGroups:[{settingsList:[{remainingSpawnCount:1,hostile:1b,forced:1b,customTag:{factionName:"kong"},maxToSpawn:1,entityId:"ancientwarfarenpc:faction.soldier",minToSpawn:1}],groupWeight:1}],playerRange:16,respondToRedstone:0b,inventory:{Size:9,Items:[]},spawnRange:0,transparent:1b,maxDelay:0,xpToDrop:0,mobRange:0,debugMode:0b,maxNearbyMonsters:0}}}
:enddata
:endrule

rule:
plugin=blockTile
number=53
data:
JSON:{blockState:{blockName:"ancientwarfarestructure:advanced_spawner",properties:{transparent:"true"}},teData:{id:"ancientwarfarestructure:advanced_spawner_tile",spawnerSettings:{minDelay:0,spawnDelay:0,lightSensitive:0b,spawnGroups:[{settingsList:[{remainingSpawnCount:1,hostile:1b,forced:1b,customTag:{factionName:"kong"},maxToSpawn:1,entityId:"ancientwarfarenpc:faction.archer.elite",minToSpawn:1}],groupWeight:1}],playerRange:32,respondToRedstone:0b,inventory:{Size:9,Items:[]},spawnRange:0,transparent:1b,maxDelay:0,xpToDrop:0,mobRange:0,debugMode:0b,maxNearbyMonsters:0}}}
:enddata
:endrule

rule:
plugin=vanillaBlocks
number=54
data:
JSON:{blockState:{blockName:"minecraft:redstone_torch",properties:{facing:"up"}}}
:enddata
:endrule

rule:
plugin=blockTile
number=55
data:
JSON:{blockState:{blockName:"ancientwarfarestructure:advanced_spawner",properties:{transparent:"true"}},teData:{id:"ancientwarfarestructure:advanced_spawner_tile",spawnerSettings:{minDelay:0,spawnDelay:0,lightSensitive:0b,spawnGroups:[{settingsList:[{remainingSpawnCount:1,hostile:1b,forced:1b,customTag:{factionName:"kong"},maxToSpawn:1,entityId:"ancientwarfarenpc:faction.archer.elite",minToSpawn:1}],groupWeight:1}],playerRange:32,respondToRedstone:0b,inventory:{Size:9,Items:[]},spawnRange:0,transparent:1b,maxDelay:0,xpToDrop:0,mobRange:0,debugMode:0b,maxNearbyMonsters:0}}}
:enddata
:endrule

rule:
plugin=vanillaBlocks
number=56
data:
JSON:{blockState:{blockName:"minecraft:unlit_redstone_torch",properties:{facing:"up"}}}
:enddata
:endrule

rule:
plugin=blockTile
number=57
data:
JSON:{blockState:{blockName:"ancientwarfarestructure:advanced_spawner",properties:{transparent:"true"}},teData:{id:"ancientwarfarestructure:advanced_spawner_tile",spawnerSettings:{minDelay:0,spawnDelay:0,lightSensitive:0b,spawnGroups:[{settingsList:[{remainingSpawnCount:1,hostile:1b,forced:1b,customTag:{factionName:"kong"},maxToSpawn:1,entityId:"ancientwarfarenpc:faction.soldier.elite",minToSpawn:1}],groupWeight:1}],playerRange:2,respondToRedstone:0b,inventory:{Size:9,Items:[]},spawnRange:0,transparent:1b,maxDelay:0,xpToDrop:0,mobRange:0,debugMode:0b,maxNearbyMonsters:0}}}
:enddata
:endrule

rule:
plugin=blockTile
number=58
data:
JSON:{blockState:{blockName:"ancientwarfarestructure:advanced_spawner",properties:{transparent:"true"}},teData:{id:"ancientwarfarestructure:advanced_spawner_tile",spawnerSettings:{minDelay:0,spawnDelay:0,lightSensitive:0b,spawnGroups:[{settingsList:[{remainingSpawnCount:1,hostile:1b,forced:1b,customTag:{factionName:"kong"},maxToSpawn:1,entityId:"ancientwarfarenpc:faction.soldier.elite",minToSpawn:1}],groupWeight:1}],playerRange:2,respondToRedstone:0b,inventory:{Size:9,Items:[]},spawnRange:0,transparent:1b,maxDelay:0,xpToDrop:0,mobRange:0,debugMode:0b,maxNearbyMonsters:0}}}
:enddata
:endrule

rule:
plugin=blockTile
number=59
data:
JSON:{blockState:{blockName:"ancientwarfarestructure:advanced_loot_chest",properties:{facing:"east"}},teData:{LootTable:"ancientwarfare:inject/chests/jungle_temple",lootRolls:2b,id:"ancientwarfarestructure:advanced_loot_chest_tile",Lock:"",LootTableSeed:-461744199363873301L}}
:enddata
:endrule

rule:
plugin=vanillaBlocks
number=60
data:
JSON:{blockState:{blockName:"minecraft:sticky_piston",properties:{facing:"south",extended:"true"}}}
:enddata
:endrule

rule:
plugin=vanillaBlocks
number=61
data:
JSON:{blockState:{blockName:"minecraft:piston_head",properties:{facing:"south",short:"false",type:"sticky"}}}
:enddata
:endrule

rule:
plugin=vanillaBlocks
number=62
data:
JSON:{blockState:{blockName:"minecraft:stone_pressure_plate",properties:{powered:"false"}}}
:enddata
:endrule

rule:
plugin=blockTile
number=63
data:
JSON:{blockState:{blockName:"ancientwarfarestructure:advanced_spawner",properties:{transparent:"true"}},teData:{id:"ancientwarfarestructure:advanced_spawner_tile",spawnerSettings:{minDelay:0,spawnDelay:0,lightSensitive:0b,spawnGroups:[{settingsList:[{remainingSpawnCount:1,hostile:1b,forced:1b,customTag:{factionName:"kong"},maxToSpawn:1,entityId:"ancientwarfarenpc:faction.soldier.elite",minToSpawn:1}],groupWeight:1}],playerRange:2,respondToRedstone:0b,inventory:{Size:9,Items:[]},spawnRange:0,transparent:1b,maxDelay:0,xpToDrop:0,mobRange:0,debugMode:0b,maxNearbyMonsters:0}}}
:enddata
:endrule

rule:
plugin=blockTile
number=64
data:
JSON:{blockState:{blockName:"ancientwarfarestructure:advanced_loot_chest",properties:{facing:"east"}},teData:{LootTable:"ancientwarfare:inject/chests/jungle_temple",lootRolls:2b,id:"ancientwarfarestructure:advanced_loot_chest_tile",Lock:"",LootTableSeed:6784838531636007659L}}
:enddata
:endrule

rule:
plugin=vanillaSkull
number=65
data:
JSON:{blockState:{blockName:"minecraft:skull",properties:{nodrop:"false",facing:"up"}},skullRotation:14,teData:{Rot:14b,id:"minecraft:skull",SkullType:0b}}
:enddata
:endrule

rule:
plugin=vanillaBlocks
number=66
data:
JSON:{blockState:{blockName:"minecraft:sticky_piston",properties:{facing:"south",extended:"false"}}}
:enddata
:endrule

rule:
plugin=blockTile
number=67
data:
JSON:{blockState:{blockName:"ancientwarfarestructure:advanced_spawner",properties:{transparent:"true"}},teData:{id:"ancientwarfarestructure:advanced_spawner_tile",spawnerSettings:{minDelay:0,spawnDelay:0,lightSensitive:0b,spawnGroups:[{settingsList:[{remainingSpawnCount:1,hostile:1b,forced:1b,customTag:{factionName:"kong"},maxToSpawn:1,entityId:"ancientwarfarenpc:faction.soldier.elite",minToSpawn:1}],groupWeight:1}],playerRange:2,respondToRedstone:0b,inventory:{Size:9,Items:[]},spawnRange:0,transparent:1b,maxDelay:0,xpToDrop:0,mobRange:0,debugMode:0b,maxNearbyMonsters:0}}}
:enddata
:endrule

rule:
plugin=blockTile
number=68
data:
JSON:{blockState:{blockName:"ancientwarfarestructure:advanced_spawner",properties:{transparent:"true"}},teData:{id:"ancientwarfarestructure:advanced_spawner_tile",spawnerSettings:{minDelay:0,spawnDelay:0,lightSensitive:0b,spawnGroups:[{settingsList:[{remainingSpawnCount:1,hostile:1b,forced:1b,customTag:{factionName:"kong"},maxToSpawn:1,entityId:"ancientwarfarenpc:faction.soldier.elite",minToSpawn:1}],groupWeight:1}],playerRange:2,respondToRedstone:0b,inventory:{Size:9,Items:[]},spawnRange:0,transparent:1b,maxDelay:0,xpToDrop:0,mobRange:0,debugMode:0b,maxNearbyMonsters:0}}}
:enddata
:endrule

rule:
plugin=blockTile
number=69
data:
JSON:{blockState:{blockName:"ancientwarfarestructure:advanced_spawner",properties:{transparent:"true"}},teData:{id:"ancientwarfarestructure:advanced_spawner_tile",spawnerSettings:{minDelay:0,spawnDelay:0,lightSensitive:0b,spawnGroups:[{settingsList:[{remainingSpawnCount:12,hostile:1b,forced:1b,customTag:{},maxToSpawn:12,entityId:"minecraft:bat",minToSpawn:6}],groupWeight:1}],playerRange:2,respondToRedstone:0b,inventory:{Size:9,Items:[]},spawnRange:0,transparent:1b,maxDelay:0,xpToDrop:0,mobRange:0,debugMode:0b,maxNearbyMonsters:0}}}
:enddata
:endrule

rule:
plugin=blockTile
number=70
data:
JSON:{blockState:{blockName:"ancientwarfarestructure:advanced_spawner",properties:{transparent:"true"}},teData:{id:"ancientwarfarestructure:advanced_spawner_tile",spawnerSettings:{minDelay:0,spawnDelay:0,lightSensitive:0b,spawnGroups:[{settingsList:[{remainingSpawnCount:1,hostile:1b,forced:1b,customTag:{factionName:"kong"},maxToSpawn:1,entityId:"ancientwarfarenpc:faction.archer.elite",minToSpawn:1}],groupWeight:1}],playerRange:32,respondToRedstone:0b,inventory:{Size:9,Items:[]},spawnRange:0,transparent:1b,maxDelay:0,xpToDrop:0,mobRange:0,debugMode:0b,maxNearbyMonsters:0}}}
:enddata
:endrule

rule:
plugin=vanillaBlocks
number=71
data:
JSON:{blockState:{blockName:"minecraft:iron_bars",properties:{east:"false",south:"false",north:"false",west:"false"}}}
:enddata
:endrule

rule:
plugin=blockTile
number=72
data:
JSON:{blockState:{blockName:"ancientwarfarestructure:advanced_spawner",properties:{transparent:"true"}},teData:{id:"ancientwarfarestructure:advanced_spawner_tile",spawnerSettings:{minDelay:0,spawnDelay:0,lightSensitive:0b,spawnGroups:[{settingsList:[{remainingSpawnCount:1,hostile:1b,forced:1b,customTag:{factionName:"kong"},maxToSpawn:1,entityId:"ancientwarfarenpc:faction.soldier.elite",minToSpawn:1}],groupWeight:1}],playerRange:2,respondToRedstone:0b,inventory:{Size:9,Items:[]},spawnRange:0,transparent:1b,maxDelay:0,xpToDrop:0,mobRange:0,debugMode:0b,maxNearbyMonsters:0}}}
:enddata
:endrule

rule:
plugin=vanillaBlocks
number=73
data:
JSON:{blockState:{blockName:"minecraft:cobblestone_wall",properties:{east:"false",south:"false",north:"false",variant:"cobblestone",west:"false",up:"false"}}}
:enddata
:endrule

rule:
plugin=blockTile
number=74
data:
JSON:{blockState:{blockName:"ancientwarfarestructure:advanced_spawner",properties:{transparent:"true"}},teData:{id:"ancientwarfarestructure:advanced_spawner_tile",spawnerSettings:{minDelay:0,spawnDelay:0,lightSensitive:0b,spawnGroups:[{settingsList:[{remainingSpawnCount:1,hostile:1b,forced:1b,customTag:{factionName:"kong"},maxToSpawn:1,entityId:"ancientwarfarenpc:faction.archer.elite",minToSpawn:1}],groupWeight:1}],playerRange:32,respondToRedstone:0b,inventory:{Size:9,Items:[]},spawnRange:0,transparent:1b,maxDelay:0,xpToDrop:0,mobRange:0,debugMode:0b,maxNearbyMonsters:0}}}
:enddata
:endrule

rule:
plugin=blockTile
number=75
data:
JSON:{blockState:{blockName:"ancientwarfarestructure:advanced_spawner",properties:{transparent:"true"}},teData:{id:"ancientwarfarestructure:advanced_spawner_tile",spawnerSettings:{minDelay:0,spawnDelay:0,lightSensitive:0b,spawnGroups:[{settingsList:[{remainingSpawnCount:1,hostile:1b,forced:1b,customTag:{factionName:"kong"},maxToSpawn:1,entityId:"ancientwarfarenpc:faction.soldier.elite",minToSpawn:1}],groupWeight:1}],playerRange:2,respondToRedstone:0b,inventory:{Size:9,Items:[]},spawnRange:0,transparent:1b,maxDelay:0,xpToDrop:0,mobRange:0,debugMode:0b,maxNearbyMonsters:0}}}
:enddata
:endrule

rule:
plugin=blockTile
number=76
data:
JSON:{blockState:{blockName:"ancientwarfarestructure:advanced_spawner",properties:{transparent:"true"}},teData:{id:"ancientwarfarestructure:advanced_spawner_tile",spawnerSettings:{minDelay:0,spawnDelay:0,lightSensitive:0b,spawnGroups:[{settingsList:[{remainingSpawnCount:1,hostile:1b,forced:1b,customTag:{factionName:"kong"},maxToSpawn:1,entityId:"ancientwarfarenpc:faction.archer.elite",minToSpawn:1}],groupWeight:1}],playerRange:32,respondToRedstone:0b,inventory:{Size:9,Items:[]},spawnRange:0,transparent:1b,maxDelay:0,xpToDrop:0,mobRange:0,debugMode:0b,maxNearbyMonsters:0}}}
:enddata
:endrule

rule:
plugin=vanillaBlocks
number=77
data:
JSON:{blockState:{blockName:"minecraft:glowstone"}}
:enddata
:endrule

rule:
plugin=blockTile
number=78
data:
JSON:{blockState:{blockName:"ancientwarfarestructure:advanced_spawner",properties:{transparent:"true"}},teData:{id:"ancientwarfarestructure:advanced_spawner_tile",spawnerSettings:{minDelay:0,spawnDelay:0,lightSensitive:0b,spawnGroups:[{settingsList:[{remainingSpawnCount:1,hostile:1b,forced:1b,customTag:{factionName:"kong"},maxToSpawn:1,entityId:"ancientwarfarenpc:faction.archer.elite",minToSpawn:1}],groupWeight:1}],playerRange:32,respondToRedstone:0b,inventory:{Size:9,Items:[]},spawnRange:0,transparent:1b,maxDelay:0,xpToDrop:0,mobRange:0,debugMode:0b,maxNearbyMonsters:0}}}
:enddata
:endrule

rule:
plugin=blockTile
number=79
data:
JSON:{blockState:{blockName:"ancientwarfarestructure:advanced_spawner",properties:{transparent:"true"}},teData:{id:"ancientwarfarestructure:advanced_spawner_tile",spawnerSettings:{minDelay:0,spawnDelay:0,lightSensitive:0b,spawnGroups:[{settingsList:[{remainingSpawnCount:1,hostile:1b,forced:1b,customTag:{factionName:"kong"},maxToSpawn:1,entityId:"ancientwarfarenpc:faction.archer.elite",minToSpawn:1}],groupWeight:1}],playerRange:32,respondToRedstone:0b,inventory:{Size:9,Items:[]},spawnRange:0,transparent:1b,maxDelay:0,xpToDrop:0,mobRange:0,debugMode:0b,maxNearbyMonsters:0}}}
:enddata
:endrule

#### ENTITIES ####
