# Ancient Warfare Structure Template File
# Auto-generated structure template file. created on: 8/19/2019 at: 10:23:12
# Lines beginning with # denote comments

header:
version=2.9
name=KongTreehouse4
mods=
size=23,26,23
offset=15,4,22
:endheader

#### VALIDATION ####
validation:
type=ground
survival=false
worldGenEnabled=true
unique=false
preserveBlocks=false
selectionWeight=30
clusterValue=40
minDuplicateDistance=900
dimensionWhiteList=true
dimensionList=0
biomeWhiteList=true
biomeList=minecraft:jungle
leveling=3
fill=2
border=3
blockSwap=false
:endvalidation

#### LAYERS ####
layer: 0
1,1,1,1,1,1,1,1,1,1,1,1,1,1,1,1,1,1,1,1,1,1,1
1,1,1,1,1,1,1,1,1,1,1,1,1,1,1,1,1,1,1,1,1,1,1
1,1,1,1,1,1,1,1,1,1,1,1,1,1,1,1,1,1,1,1,1,1,1
1,1,1,1,1,1,1,1,1,1,1,1,1,1,1,1,1,1,1,1,1,1,1
1,1,1,1,1,1,1,1,1,1,1,1,1,1,1,1,1,1,1,1,1,1,1
1,1,1,1,1,1,1,1,1,1,1,1,1,1,1,1,1,1,1,1,1,1,1
1,1,1,1,1,1,1,1,1,1,1,1,1,1,1,1,1,1,1,1,1,1,1
1,1,1,1,1,1,1,1,1,1,1,1,1,1,1,1,1,1,1,1,1,1,1
1,1,1,1,1,1,1,1,1,1,1,1,1,1,1,1,1,1,1,1,1,1,1
1,1,1,1,1,1,1,1,1,1,1,1,1,1,1,1,1,1,1,1,1,1,1
1,1,1,1,1,1,1,1,1,1,1,1,1,1,1,1,1,1,1,1,1,1,1
1,1,1,1,1,1,1,1,1,1,1,1,1,1,1,1,1,1,1,1,1,1,1
1,1,1,1,1,1,1,1,1,1,1,1,1,1,1,1,1,1,1,1,1,1,1
1,1,1,1,1,1,1,1,1,1,1,1,1,1,1,1,1,1,1,1,1,1,1
1,1,1,1,1,1,1,1,1,1,1,1,1,1,1,1,1,1,1,1,1,1,1
1,1,1,1,1,1,1,1,1,1,1,1,1,1,1,1,1,1,1,1,1,1,1
1,1,1,1,1,1,1,1,1,1,1,1,1,1,1,1,1,1,1,1,1,1,1
1,1,1,1,1,1,1,1,1,1,1,1,1,1,1,1,1,1,1,1,1,1,1
1,1,1,1,1,1,1,1,1,1,1,1,1,1,1,1,1,1,1,1,1,1,1
1,1,1,1,1,1,1,1,1,1,1,1,1,1,1,1,1,1,1,1,1,1,1
1,1,1,1,1,1,1,1,1,1,1,1,1,1,1,1,1,1,1,1,1,1,1
1,1,1,1,1,1,1,1,1,1,1,1,1,1,1,1,1,1,1,1,1,1,1
1,1,1,1,1,1,1,1,1,1,1,1,1,1,1,1,1,1,1,1,1,1,1
:endlayer
layer: 1
1,1,1,1,1,1,1,1,1,1,1,1,1,1,1,1,1,1,1,1,1,1,1
1,1,1,1,1,1,1,1,1,1,1,1,1,1,1,1,1,1,1,1,1,1,1
1,1,1,1,1,1,1,1,1,1,1,1,1,1,1,1,1,1,1,1,1,1,1
1,1,1,1,1,1,1,1,1,1,1,1,1,1,1,1,1,1,1,1,1,1,1
1,1,1,1,1,1,1,1,1,1,1,1,1,1,1,1,1,1,1,1,1,1,1
1,1,1,1,1,1,1,1,1,1,1,1,1,1,1,1,1,1,1,1,1,1,1
1,1,1,1,1,1,1,1,1,1,1,1,1,1,1,1,1,1,1,1,1,1,1
1,1,1,1,1,1,1,1,1,1,1,1,1,1,1,1,1,1,1,1,1,1,1
1,1,1,1,1,1,1,1,1,1,1,1,1,1,1,1,1,1,1,1,1,1,1
1,1,1,1,1,1,1,1,1,1,1,1,1,1,1,1,1,1,1,1,1,1,1
1,1,1,1,1,1,1,1,1,1,1,1,1,1,1,1,1,1,1,1,1,1,1
1,1,1,1,1,1,1,1,1,1,1,1,1,1,1,1,1,1,1,1,1,1,1
1,1,1,1,1,1,1,1,1,1,1,1,1,1,1,1,1,1,1,1,1,1,1
1,1,1,1,1,1,1,1,1,1,1,1,1,1,1,1,1,1,1,1,1,1,1
1,1,1,1,1,1,1,1,1,1,1,1,1,1,1,1,1,1,1,1,1,1,1
1,1,1,1,1,1,1,1,1,1,1,1,1,1,1,1,1,1,1,1,1,1,1
1,1,1,1,1,1,1,1,1,1,1,1,1,1,1,1,1,1,1,1,1,1,1
1,1,1,1,1,1,1,1,1,1,1,1,1,1,1,1,1,1,1,1,1,1,1
1,1,1,1,1,1,1,1,1,1,1,1,1,1,1,1,1,1,1,1,1,1,1
1,1,1,1,1,1,1,1,1,1,1,1,1,1,1,1,1,1,1,1,1,1,1
1,1,1,1,1,1,1,1,1,1,1,1,1,1,1,1,1,1,1,1,1,1,1
1,1,1,1,1,1,1,1,1,1,1,1,1,1,1,1,1,1,1,1,1,1,1
1,1,1,1,1,1,1,1,1,1,1,1,1,1,1,1,1,1,1,1,1,1,1
:endlayer
layer: 2
1,1,1,1,1,1,1,1,1,1,1,1,1,1,1,1,1,1,1,1,1,1,1
1,1,1,1,1,1,1,1,1,1,1,1,1,1,1,1,1,1,1,1,1,1,1
1,1,1,1,1,1,1,1,1,1,1,1,1,1,1,1,1,1,1,1,1,1,1
1,1,1,1,1,1,1,1,1,1,1,1,1,1,1,1,1,1,1,1,1,1,1
1,1,1,1,1,1,1,1,1,1,1,1,1,1,1,1,1,1,1,1,1,1,1
1,1,1,1,1,1,1,1,1,1,1,1,1,1,1,1,1,1,1,1,1,1,1
1,1,1,1,1,1,1,1,1,1,1,1,1,1,1,1,1,1,1,1,1,1,1
1,1,1,1,1,1,1,1,1,1,1,1,1,1,1,1,1,1,1,1,1,1,1
1,1,1,1,1,1,1,1,1,1,1,1,1,1,1,1,1,1,1,1,1,1,1
1,1,1,1,1,1,1,1,1,1,1,1,1,1,1,1,1,1,1,1,1,1,1
1,1,1,1,1,1,1,1,1,1,1,1,1,1,1,1,1,1,1,1,1,1,1
1,1,1,1,1,1,1,1,1,1,1,1,1,1,1,1,1,1,1,1,1,1,1
1,1,1,1,1,1,1,1,1,1,1,1,1,1,1,1,1,1,1,1,1,1,1
1,1,1,1,1,1,1,1,1,1,1,1,1,1,1,1,1,1,1,1,1,1,1
1,1,1,1,1,1,1,1,1,1,1,1,1,1,1,1,1,1,1,1,1,1,1
1,1,1,1,1,1,1,1,1,1,1,1,1,1,1,1,1,1,1,1,1,1,1
1,1,1,1,1,1,1,1,1,1,1,1,1,1,1,1,1,1,1,1,1,1,1
1,1,1,1,1,1,1,1,1,1,1,1,1,1,1,1,1,1,1,1,1,1,1
1,1,1,1,1,1,1,1,1,1,1,1,1,1,1,1,1,1,1,1,1,1,1
1,1,1,1,1,1,1,1,1,1,1,1,1,1,1,1,1,1,1,1,1,1,1
1,1,1,1,1,1,1,1,1,1,1,1,1,1,1,1,1,1,1,1,1,1,1
1,1,1,1,1,1,1,1,1,1,1,1,1,1,1,1,1,1,1,1,1,1,1
1,1,1,1,1,1,1,1,1,1,1,1,1,1,1,1,1,1,1,1,1,1,1
:endlayer
layer: 3
2,2,2,2,2,2,2,2,2,2,2,2,2,2,2,2,2,2,2,2,2,2,2
2,2,2,2,2,2,2,2,2,2,2,2,2,2,2,2,2,2,2,2,2,2,2
2,2,2,2,2,2,2,2,2,2,2,2,2,2,2,2,2,2,2,2,2,2,2
2,2,2,2,2,2,2,2,2,2,2,2,2,2,2,2,2,2,2,2,2,2,2
2,2,2,2,2,2,2,2,2,2,2,2,2,2,2,1,1,2,2,2,2,2,2
2,2,2,2,2,2,2,2,2,2,2,2,2,2,2,1,1,2,2,2,2,2,2
2,2,2,2,2,2,1,1,2,2,2,2,2,2,2,2,2,2,2,2,2,2,2
2,2,2,2,2,2,1,1,2,1,2,2,2,2,2,2,2,2,2,2,2,2,2
2,2,2,2,2,2,2,2,2,2,2,2,2,2,2,2,2,2,2,2,2,2,2
2,2,2,2,2,2,2,2,2,2,2,2,2,2,2,2,2,2,2,2,2,2,2
2,2,2,2,2,2,2,2,2,2,2,2,2,2,2,2,2,2,2,2,2,2,2
2,2,2,2,2,2,2,2,2,2,2,2,2,2,2,2,2,2,2,2,2,2,2
2,2,2,2,2,2,2,2,2,2,2,2,1,1,2,2,2,2,2,2,2,2,2
2,2,2,2,2,2,2,2,2,2,2,2,1,1,2,2,2,2,2,2,2,2,2
2,2,2,2,2,2,2,2,2,2,2,2,2,2,2,2,2,2,2,2,2,2,2
2,2,2,2,2,2,2,2,2,2,2,2,2,2,2,2,2,2,2,2,2,2,2
2,2,2,2,2,2,2,1,2,2,2,2,2,2,2,2,2,2,2,2,2,2,2
2,2,2,2,2,1,1,2,2,2,2,2,2,2,2,2,2,2,2,2,2,2,2
2,2,2,2,2,1,1,2,2,2,2,2,2,2,2,2,2,2,2,1,2,2,2
2,2,2,2,2,2,2,2,2,2,2,2,2,2,2,2,2,2,2,2,2,2,2
2,2,2,2,2,2,2,2,2,2,2,2,2,2,2,2,2,2,2,2,2,2,2
2,2,2,2,2,2,2,2,2,2,2,2,2,2,2,2,2,2,2,2,2,2,2
2,2,2,2,2,2,2,2,2,2,2,2,2,2,2,2,2,2,2,2,2,2,2
:endlayer
layer: 4
3,3,0,0,3,0,0,0,0,0,0,0,3,0,3,0,4,3,3,0,0,0,0
0,0,0,0,0,0,0,0,0,0,0,0,0,0,0,3,3,3,3,3,3,5,0
0,0,0,0,0,0,0,0,0,6,0,0,3,0,3,0,3,0,0,3,0,0,0
0,0,0,0,7,0,0,0,0,0,0,8,3,9,3,4,4,3,0,10,0,0,0
0,0,0,0,0,0,0,0,0,0,11,3,0,9,8,12,12,13,3,3,3,3,0
0,0,0,0,0,0,3,4,0,14,14,14,14,14,14,12,12,13,0,0,3,13,0
3,3,3,3,0,0,12,12,3,14,3,15,0,0,14,16,17,0,0,18,17,0,5
0,3,0,3,3,8,12,12,14,12,0,3,0,3,14,0,0,0,3,13,3,0,3
3,3,3,3,3,0,14,17,0,3,3,3,0,0,19,0,20,0,0,13,3,3,0
0,3,0,3,3,0,14,0,3,3,3,3,0,0,14,0,0,0,0,13,0,3,0
3,0,0,3,0,0,14,0,0,0,15,0,3,0,14,0,0,3,3,13,3,3,3
0,0,0,0,0,0,14,0,0,3,0,0,4,11,14,3,0,3,13,3,0,3,0
0,0,0,0,21,0,14,0,0,0,3,8,12,12,14,0,3,3,3,0,5,0,0
0,0,0,0,0,0,14,0,3,3,0,8,12,12,13,0,3,3,3,5,3,0,0
0,0,0,0,0,0,14,3,3,3,0,0,14,17,3,0,0,0,3,3,0,0,0
0,0,0,0,0,0,14,14,22,0,3,0,14,3,3,0,3,3,0,3,0,0,0
0,0,3,0,0,11,4,12,14,14,14,14,14,3,0,0,0,0,23,0,0,3,0
0,0,0,0,8,12,12,13,0,3,0,17,17,24,3,0,3,25,26,0,0,3,0
0,3,3,3,8,12,12,13,0,3,0,3,3,3,3,3,0,0,0,12,0,0,0
0,3,3,3,0,3,17,0,3,0,0,3,0,3,3,0,0,0,0,3,0,3,3
0,3,3,27,0,0,0,0,0,0,0,0,0,0,3,0,3,0,0,3,0,3,3
3,24,3,3,0,0,0,0,0,0,3,3,28,0,3,0,0,0,0,3,3,5,3
0,0,0,0,3,0,0,0,3,3,0,0,0,3,3,0,0,0,3,3,0,0,0
:endlayer
layer: 5
0,0,0,0,0,0,0,0,0,0,0,0,0,0,0,0,4,0,0,0,0,0,0
0,0,0,0,0,0,0,0,0,0,0,0,0,0,0,0,0,0,0,0,0,0,0
0,0,0,0,0,0,0,0,0,0,0,0,0,0,0,0,0,0,0,0,0,0,0
0,0,0,0,0,0,0,0,0,0,0,8,0,0,0,4,4,0,0,0,0,0,0
0,0,0,0,0,0,0,0,0,0,11,0,0,0,8,12,12,13,0,0,0,0,0
0,0,0,0,0,0,4,4,0,0,0,0,0,0,8,12,12,13,0,0,0,13,0
0,0,0,0,0,0,12,12,13,0,0,0,0,0,0,16,17,0,0,18,17,0,0
0,0,0,0,0,8,12,12,13,12,0,0,0,0,29,0,0,0,0,13,0,0,0
0,0,0,0,0,0,17,17,0,0,0,0,0,0,0,0,0,0,0,13,0,0,0
0,0,0,0,0,0,0,0,0,0,0,0,0,0,29,0,0,0,0,13,0,0,0
0,0,0,0,0,0,0,0,0,0,0,0,0,0,0,0,0,0,0,13,0,0,0
0,0,0,0,0,0,0,0,0,0,0,0,4,11,0,0,0,0,13,0,0,0,0
0,0,0,0,0,0,0,0,0,0,0,8,12,12,0,0,0,0,0,0,0,0,0
0,0,0,0,0,0,0,0,0,0,0,8,12,12,13,0,0,0,0,0,0,0,0
0,0,0,0,0,0,0,0,0,0,0,0,17,17,0,0,0,0,0,0,0,0,0
0,0,0,0,0,0,0,0,30,0,0,0,0,0,0,0,0,0,0,0,0,0,0
0,0,0,0,0,11,4,12,0,0,0,0,0,0,0,0,0,0,0,0,0,0,0
0,0,0,0,8,12,12,13,0,0,0,17,17,0,0,0,0,0,0,0,0,0,0
0,0,0,0,8,12,12,13,0,0,0,0,0,0,0,0,0,0,0,12,0,0,0
0,0,0,0,0,17,17,0,0,0,0,0,0,0,0,0,0,0,0,0,0,0,0
0,0,0,0,0,0,0,0,0,0,0,0,0,0,0,0,0,0,0,0,0,0,0
0,0,0,0,0,0,0,0,0,0,0,0,0,0,0,0,0,0,0,0,0,0,0
0,0,0,0,0,0,0,0,0,0,0,0,0,0,0,0,0,0,0,0,0,0,0
:endlayer
layer: 6
0,0,0,0,0,0,0,0,0,0,0,0,0,0,0,0,4,0,0,0,0,0,0
0,0,0,0,0,0,0,0,0,0,0,0,0,0,0,0,0,0,0,0,0,0,0
0,0,0,0,0,0,0,0,0,0,0,0,0,0,0,0,0,0,0,0,0,0,0
0,0,0,0,0,0,0,0,0,0,0,8,0,0,0,4,4,0,0,0,0,0,0
0,0,0,0,0,0,0,0,0,0,11,0,0,0,8,12,12,13,0,0,0,0,0
0,0,0,0,0,0,4,4,0,0,0,0,0,0,8,12,12,13,0,0,0,13,0
0,0,0,0,0,0,12,12,13,0,0,0,0,0,0,16,17,0,0,18,17,0,0
0,0,0,0,0,8,12,12,13,12,0,0,0,0,0,0,0,0,0,13,0,0,0
0,0,0,0,0,0,17,17,0,0,0,0,0,0,0,0,0,0,0,13,0,0,0
0,0,0,0,0,0,0,0,0,0,0,0,0,0,31,31,31,31,0,13,0,0,0
0,0,0,0,0,0,0,0,0,0,0,0,0,0,31,31,31,31,0,13,0,0,0
0,0,0,0,0,0,0,0,0,0,0,0,4,11,31,31,31,31,13,0,0,0,0
0,0,0,0,0,0,0,0,0,0,0,8,12,12,31,31,31,31,0,0,0,0,0
0,0,0,0,0,0,0,0,0,0,0,8,12,12,31,31,31,31,0,0,0,0,0
0,0,0,0,0,0,0,0,0,0,0,0,17,17,31,31,31,31,0,0,0,0,0
0,0,0,0,0,0,0,0,0,0,0,0,0,0,31,31,31,31,0,0,0,0,0
0,0,0,0,0,11,4,12,0,0,0,0,0,0,31,31,31,31,0,0,0,0,0
0,0,0,0,8,12,12,13,0,0,0,17,17,0,0,0,0,0,0,0,0,0,0
0,0,0,0,8,12,12,13,0,0,0,0,0,0,0,0,0,0,0,12,0,0,0
0,0,0,0,0,17,17,0,0,0,0,0,0,0,0,0,0,0,0,0,0,0,0
0,0,0,0,0,0,0,0,0,0,0,0,0,0,0,0,0,0,0,0,0,0,0
0,0,0,0,0,0,0,0,0,0,0,0,0,0,0,0,0,0,0,0,0,0,0
0,0,0,0,0,0,0,0,0,0,0,0,0,0,0,0,0,0,0,0,0,0,0
:endlayer
layer: 7
0,0,0,0,0,0,0,0,0,0,0,0,0,0,0,0,4,0,0,0,0,0,0
0,0,0,0,0,0,0,0,0,0,0,0,0,0,0,0,0,0,0,0,0,0,0
0,0,0,0,0,0,0,0,0,0,0,0,0,31,31,31,31,31,31,0,0,0,0
0,0,0,0,0,0,0,0,0,0,0,8,0,31,31,31,31,31,31,0,0,0,0
0,0,0,0,0,0,0,0,0,0,11,0,0,31,31,12,12,31,31,0,0,0,0
0,0,0,0,0,0,4,4,0,0,0,0,0,31,31,12,12,31,31,0,0,13,0
0,0,0,0,0,0,12,12,13,0,0,0,0,31,31,16,31,31,31,18,17,0,0
0,0,0,0,0,8,12,12,13,12,31,31,31,31,31,31,31,31,31,13,0,0,0
0,0,0,0,0,0,17,17,0,0,31,31,31,31,31,31,31,31,31,13,0,0,0
0,0,0,0,0,0,0,0,0,0,31,31,31,31,32,32,32,32,31,13,0,0,0
0,0,0,0,0,0,0,0,0,0,31,31,31,31,32,33,33,32,31,13,0,0,0
0,0,0,0,0,0,0,0,0,0,31,31,31,31,32,32,32,32,31,0,0,0,0
0,0,0,0,0,0,0,0,0,0,31,31,12,12,32,32,32,32,31,0,0,0,0
0,0,0,0,0,0,0,0,0,0,31,31,12,12,32,32,32,32,31,0,0,0,0
0,0,0,0,0,0,0,0,0,0,31,31,31,31,32,32,32,32,31,0,0,0,0
0,0,0,0,0,0,0,0,0,0,31,31,31,31,32,33,33,32,31,0,0,0,0
0,0,0,0,0,11,4,12,0,0,0,0,0,31,32,32,32,32,31,0,0,0,0
0,0,0,0,8,12,12,13,0,0,0,17,17,31,31,31,31,31,31,0,0,0,0
0,0,0,0,8,12,12,13,0,0,0,0,0,0,0,0,0,0,0,12,0,0,0
0,0,0,0,0,17,17,0,0,0,0,0,0,0,0,0,0,0,0,0,0,0,0
0,0,0,0,0,0,0,0,0,0,0,0,0,0,0,0,0,0,0,0,0,0,0
0,0,0,0,0,0,0,0,0,0,0,0,0,0,0,0,0,0,0,0,0,0,0
0,0,0,0,0,0,0,0,0,0,0,0,0,0,0,0,0,0,0,0,0,0,0
:endlayer
layer: 8
0,0,0,0,0,0,0,0,0,0,0,0,0,0,0,0,4,0,0,0,0,0,0
0,0,0,0,0,0,0,0,0,0,0,0,0,0,0,0,0,0,0,0,0,0,0
0,0,0,0,0,0,0,0,0,0,0,0,0,14,14,14,14,14,14,0,0,0,0
0,0,0,0,0,0,0,0,0,0,0,8,0,14,0,4,34,0,14,0,0,0,0
0,0,0,0,0,0,0,0,0,0,11,0,0,14,0,12,12,13,14,0,0,0,0
0,0,0,0,0,0,4,4,0,0,0,0,0,14,8,12,12,13,14,0,0,13,0
0,0,0,0,0,0,12,12,13,0,0,0,0,14,0,16,17,0,14,18,17,0,0
0,0,0,0,0,8,12,12,13,12,14,14,14,14,0,0,0,0,14,13,0,0,0
0,0,0,0,0,0,17,17,0,0,14,0,0,0,0,35,0,0,14,0,0,0,0
0,0,0,0,0,0,0,0,0,0,14,0,0,14,36,36,36,36,14,0,0,0,0
0,0,0,0,0,0,0,0,0,0,14,0,0,14,36,0,0,36,14,0,0,0,0
0,0,0,0,0,0,0,0,0,0,14,0,4,14,36,36,36,36,14,0,0,0,0
0,0,0,0,0,0,0,0,0,0,14,8,12,12,36,36,36,36,14,0,0,0,0
0,0,0,0,0,0,0,0,0,0,14,8,12,12,36,36,36,36,14,0,0,0,0
0,0,0,0,0,0,0,0,0,0,14,0,16,37,36,36,36,36,14,0,0,0,0
0,0,0,0,0,0,0,0,0,0,14,14,14,14,36,0,0,36,14,0,0,0,0
0,0,0,0,0,11,4,12,0,0,0,0,0,14,36,36,36,36,14,0,0,0,0
0,0,0,0,8,12,12,13,0,0,0,17,17,14,14,14,14,14,31,0,0,0,0
0,0,0,0,8,12,12,13,0,0,0,0,0,0,0,0,0,0,0,12,0,0,0
0,0,0,0,0,17,17,0,0,0,0,0,0,0,0,0,0,0,0,0,0,0,0
0,0,0,0,0,0,0,0,0,0,0,0,0,0,0,0,0,0,0,0,0,0,0
0,0,0,0,0,0,0,0,0,0,0,0,0,0,0,0,0,0,0,0,0,0,0
0,0,0,0,0,0,0,0,0,0,0,0,0,0,0,0,0,0,0,0,0,0,0
:endlayer
layer: 9
0,0,0,0,0,0,0,0,0,0,0,0,0,0,0,0,4,0,0,0,0,0,0
0,0,0,0,0,0,0,0,0,0,0,0,0,0,0,0,0,0,0,0,0,0,0
0,0,0,0,0,0,0,0,0,0,0,0,0,29,0,0,0,0,29,0,0,0,0
0,0,0,0,0,0,0,0,0,0,0,8,0,0,0,4,4,0,0,0,0,0,0
0,0,0,0,0,0,0,0,0,0,11,0,0,0,0,12,12,13,0,0,0,0,0
0,0,0,0,0,0,4,4,0,0,0,0,0,0,8,12,12,13,0,0,0,13,0
0,0,0,0,0,0,12,12,13,0,0,0,0,0,0,16,17,0,0,18,17,0,0
0,0,0,0,0,8,12,12,13,12,29,0,0,0,0,0,0,0,0,13,0,0,0
0,0,0,0,0,0,17,17,0,0,0,0,0,0,0,0,0,0,13,0,0,0,0
0,0,0,0,0,0,0,0,0,0,0,0,0,29,0,0,0,0,29,0,0,0,0
0,0,0,0,0,0,0,0,0,0,0,0,0,0,0,0,0,0,0,0,0,0,0
0,0,0,0,0,0,0,0,0,0,0,0,4,4,0,0,0,0,0,0,0,0,0
0,0,0,0,0,0,0,0,0,0,0,8,12,12,13,0,13,0,0,0,0,0,0
0,0,0,0,0,0,0,0,0,0,0,8,12,12,13,0,0,0,0,0,0,0,0
0,0,0,0,0,0,0,0,0,0,0,0,16,17,0,0,13,0,0,0,0,0,0
0,0,0,0,0,0,0,0,0,0,29,0,0,0,0,0,0,0,0,0,0,0,0
0,0,0,0,0,11,4,12,0,0,0,0,0,0,0,0,0,0,0,0,0,0,0
0,0,0,0,8,12,12,13,0,0,0,17,17,29,0,0,0,0,0,0,0,0,0
0,0,0,0,8,12,12,13,0,0,0,0,0,0,0,0,0,0,0,12,0,0,0
0,0,0,0,0,17,17,0,0,0,0,0,0,0,0,0,0,0,0,0,0,0,0
0,0,0,0,0,0,0,0,0,0,0,0,0,0,0,0,0,0,0,0,0,0,0
0,0,0,0,0,0,0,0,0,0,0,0,0,0,0,0,0,0,0,0,0,0,0
0,0,0,0,0,0,0,0,0,0,0,0,0,0,0,0,0,0,0,0,0,0,0
:endlayer
layer: 10
0,0,0,0,0,0,0,0,0,0,0,0,0,0,0,0,4,0,0,0,0,0,0
0,0,0,0,0,0,0,0,0,0,0,0,0,0,0,0,0,0,0,0,0,0,0
0,0,0,0,0,0,0,0,0,0,0,0,0,0,0,0,0,0,0,0,0,0,0
0,0,0,0,0,0,0,0,0,0,0,8,38,0,0,38,4,0,0,0,0,0,0
0,0,0,0,0,0,0,0,0,0,11,38,38,38,38,12,12,13,0,0,0,0,0
0,0,0,0,0,0,4,4,0,0,38,38,38,39,12,12,12,13,0,0,0,13,0
0,0,0,0,0,0,12,12,13,0,0,38,39,39,39,16,17,0,0,18,17,0,0
0,0,0,0,0,8,12,12,13,12,0,0,38,39,0,0,0,0,0,13,0,0,0
0,0,0,0,0,0,17,17,0,0,0,0,0,0,0,0,0,0,13,0,0,0,0
0,0,0,0,0,0,0,0,0,0,0,0,0,0,0,0,0,0,0,0,0,0,0
0,0,0,0,0,0,0,0,0,0,39,39,0,0,0,0,0,0,0,0,0,0,0
0,0,0,0,0,0,0,0,0,39,39,39,39,4,0,0,0,0,0,0,0,0,0
0,0,0,0,0,0,0,0,0,39,39,39,12,12,13,0,13,0,0,0,0,0,0
0,0,0,0,0,0,0,0,0,39,39,39,12,12,13,0,0,0,0,0,0,0,0
0,0,0,0,0,0,0,0,0,0,39,0,16,17,0,0,13,0,0,0,0,0,0
0,0,0,0,0,0,0,0,0,0,0,0,0,0,0,0,0,0,0,0,0,0,0
0,0,0,0,0,11,4,12,0,0,0,0,0,0,0,0,0,0,0,0,0,0,0
0,0,0,0,8,12,12,13,0,0,0,17,17,0,0,0,0,0,0,0,0,0,0
0,0,0,0,8,12,12,13,0,0,0,0,0,0,0,0,0,0,0,12,0,0,0
0,0,0,0,0,17,17,0,0,0,0,0,0,0,0,0,0,0,0,0,0,0,0
0,0,0,0,0,0,0,0,0,0,0,0,0,0,0,0,0,0,0,0,0,0,0
0,0,0,0,0,0,0,0,0,0,0,0,0,0,0,0,0,0,0,0,0,0,0
0,0,0,0,0,0,0,0,0,0,0,0,0,0,0,0,0,0,0,0,0,0,0
:endlayer
layer: 11
0,0,0,0,0,0,0,0,0,0,0,0,0,0,0,0,4,0,0,0,0,0,0
0,0,0,0,0,0,0,0,0,0,0,0,0,0,0,0,0,0,0,0,0,0,0
0,0,0,0,0,0,0,0,0,0,0,0,0,0,0,0,0,0,0,0,0,0,0
0,0,0,0,0,0,0,0,0,0,0,38,38,38,38,4,4,0,0,0,0,0,0
0,0,0,0,38,0,0,0,0,0,8,38,38,39,12,12,12,13,0,0,0,0,0
0,0,38,38,38,38,38,4,0,0,0,38,38,39,39,12,12,13,0,0,0,13,0
0,0,38,38,38,38,12,12,13,0,0,0,38,39,0,16,17,0,0,18,17,0,0
0,38,38,38,38,12,12,12,31,12,0,0,0,0,0,0,0,0,0,13,0,0,0
0,0,38,38,38,38,38,31,31,0,0,0,0,0,0,0,0,0,13,0,0,0,0
0,0,38,38,38,38,38,0,31,31,31,31,31,31,0,0,0,0,0,0,0,0,0
0,0,0,0,38,0,0,0,31,31,31,31,31,31,0,0,0,0,0,0,0,0,0
0,0,0,0,0,0,0,0,31,31,31,31,31,31,0,0,0,0,0,0,0,0,0
0,0,0,0,0,0,0,0,31,31,31,31,12,12,13,0,13,0,0,0,0,0,0
0,0,0,0,0,0,0,0,31,31,31,31,12,12,13,0,0,0,0,0,0,0,0
0,0,0,0,0,0,0,0,31,31,31,31,16,31,0,0,13,0,0,0,0,0,0
0,0,0,0,0,0,0,0,31,31,31,31,31,31,0,0,0,0,0,0,0,0,0
0,0,0,0,0,11,12,12,31,31,31,31,31,31,0,0,0,0,38,38,38,38,0
0,0,0,0,8,12,12,13,0,0,0,17,17,0,0,0,0,38,38,38,38,38,0
0,0,0,0,8,12,12,13,0,0,0,0,0,0,0,0,0,38,38,12,38,38,0
0,0,0,0,0,17,17,0,0,0,0,0,0,0,0,0,0,38,38,38,38,38,0
0,0,0,0,0,0,0,0,0,0,0,0,0,0,0,0,0,0,38,38,38,38,0
0,0,0,0,0,0,0,0,0,0,0,0,0,0,0,0,0,0,0,0,0,0,0
0,0,0,0,0,0,0,0,0,0,0,0,0,0,0,0,0,0,0,0,0,0,0
:endlayer
layer: 12
0,0,0,0,0,0,0,0,0,0,0,0,0,0,0,0,4,0,0,0,0,0,0
0,0,0,0,0,0,0,0,0,0,0,0,0,0,0,0,0,0,0,0,0,0,0
0,0,0,0,0,0,0,0,0,0,0,0,0,0,0,0,0,0,0,0,0,0,0
0,0,0,0,0,0,0,0,0,0,0,0,38,0,0,4,4,0,0,0,0,0,0
0,0,0,0,0,0,0,0,0,0,8,38,38,39,39,12,12,13,0,0,0,0,0
0,0,0,0,38,0,4,4,0,0,0,0,38,39,8,12,12,13,0,0,0,13,0
0,0,0,38,38,38,12,12,13,0,0,0,0,0,0,16,17,0,0,18,17,0,0
0,0,38,38,12,38,12,12,40,12,0,0,0,0,0,0,0,0,0,13,0,0,0
0,0,0,38,38,38,17,17,31,0,0,0,0,0,0,0,0,0,13,0,0,0,0
0,0,0,0,38,0,0,0,12,12,12,12,12,12,0,0,0,0,0,0,0,0,0
0,0,0,0,0,0,0,0,12,41,42,43,44,14,0,0,0,0,0,0,0,0,0
0,0,0,0,0,0,0,0,14,45,0,0,4,12,0,0,0,0,0,0,0,0,0
0,0,0,0,0,0,0,0,12,46,0,47,12,12,13,0,13,0,0,0,0,0,0
0,0,0,0,0,0,0,0,12,48,0,8,12,12,13,0,0,0,0,0,0,0,0
0,0,0,0,0,0,12,0,14,0,0,0,16,12,0,0,13,0,0,0,0,0,0
0,0,0,0,0,0,12,0,12,0,0,0,49,14,0,0,0,0,0,0,0,0,0
0,0,0,0,0,11,4,12,12,12,12,12,12,12,0,0,0,38,38,38,38,0,0
0,0,0,0,8,12,12,13,0,0,0,17,17,0,0,0,0,38,38,38,38,38,0
0,0,0,0,8,12,12,13,0,0,0,0,0,0,0,0,0,38,38,12,38,38,0
0,0,0,0,0,17,17,0,0,0,0,0,0,0,0,0,0,38,38,38,38,38,0
0,0,0,0,0,0,0,0,0,0,0,0,0,0,0,0,0,0,38,38,38,0,0
0,0,0,0,0,0,0,0,0,0,0,0,0,0,0,0,0,0,0,0,0,0,0
0,0,0,0,0,0,0,0,0,0,0,0,0,0,0,0,0,0,0,0,0,0,0
:endlayer
layer: 13
0,0,0,0,0,0,0,0,0,0,0,0,0,0,0,0,4,0,0,0,0,0,0
0,0,0,0,0,0,0,0,0,0,0,0,0,0,0,0,0,0,0,0,0,0,0
0,0,0,0,0,0,0,0,0,0,0,0,0,0,0,0,0,0,0,0,0,0,0
0,0,0,0,0,0,0,0,0,0,0,0,0,0,0,4,4,0,0,0,0,0,0
0,0,0,0,0,0,0,0,0,0,0,0,0,0,0,12,12,13,0,0,0,0,0
0,0,0,0,0,0,4,4,0,0,0,0,0,0,8,12,12,13,0,0,0,13,0
0,0,0,0,38,11,12,12,13,0,0,0,0,0,0,16,17,0,0,18,17,0,0
0,0,0,38,38,38,12,12,40,12,0,0,0,0,0,0,0,0,0,13,0,0,0
0,0,0,0,38,0,17,17,0,0,0,0,0,0,0,0,0,0,13,0,0,0,0
0,0,0,0,0,0,0,0,12,12,0,0,12,12,0,0,0,0,0,0,0,0,0
0,0,0,0,0,0,0,0,12,0,0,0,0,29,0,0,0,0,0,0,0,0,0
0,0,0,0,0,0,0,38,29,0,0,0,4,12,0,0,0,0,0,0,0,0,0
0,0,0,0,0,0,38,38,12,0,0,8,12,12,13,0,13,0,0,0,0,0,0
0,0,0,0,0,38,38,12,12,0,0,8,12,12,13,0,0,0,0,0,0,0,0
0,0,0,0,0,0,38,38,29,0,0,0,16,12,0,0,13,0,0,0,0,0,0
0,0,0,0,0,0,0,38,12,0,0,0,0,29,0,0,0,0,0,0,0,0,0
0,0,0,0,0,11,4,12,12,12,12,12,12,12,0,0,0,0,0,0,0,0,0
0,0,0,0,8,12,12,13,0,0,0,17,17,0,0,0,0,0,0,38,38,0,0
0,0,0,0,8,12,12,13,0,0,0,0,0,0,0,0,0,0,38,12,38,0,0
0,0,0,0,0,17,17,0,0,0,0,0,0,0,0,0,0,0,0,38,0,0,0
0,0,0,0,0,0,0,0,0,0,0,0,0,0,0,0,0,0,0,0,0,0,0
0,0,0,0,0,0,0,0,0,0,0,0,0,0,0,0,0,0,0,0,0,0,0
0,0,0,0,0,0,0,0,0,0,0,0,0,0,0,0,0,0,0,0,0,0,0
:endlayer
layer: 14
0,0,0,0,0,0,0,0,0,0,0,0,0,0,0,38,4,0,0,0,0,0,0
0,0,0,0,0,0,0,0,0,0,0,0,0,0,38,38,38,38,0,0,0,0,0
0,0,0,0,0,0,0,0,0,0,0,0,0,38,38,38,38,38,38,0,0,0,0
0,0,0,0,0,0,0,0,0,0,0,0,38,38,38,38,38,38,38,38,0,0,0
0,0,0,0,0,0,0,0,0,0,0,38,38,38,38,12,12,38,38,38,38,0,0
0,0,0,0,0,0,4,4,0,0,0,38,38,38,38,12,12,38,38,38,38,13,0
0,0,0,0,0,11,12,12,13,0,0,0,38,38,38,16,38,38,38,18,17,0,0
0,0,0,0,0,8,12,12,40,12,0,0,0,38,38,38,38,38,38,13,0,0,0
0,0,0,0,0,0,17,17,0,0,0,0,0,0,38,38,38,38,13,0,0,0,0
0,0,0,0,0,0,0,0,12,12,12,12,12,12,0,0,38,0,0,0,0,0,0
0,0,0,0,0,0,0,0,12,0,0,0,0,12,0,0,0,0,0,0,0,0,0
0,0,0,0,0,0,0,0,12,0,0,0,4,12,0,0,0,0,0,0,0,0,0
0,0,0,0,0,0,0,38,12,0,0,8,12,12,13,0,13,0,0,0,0,0,0
0,0,0,0,0,0,38,38,12,0,0,8,12,12,13,0,0,0,0,0,0,0,0
0,0,0,0,0,0,0,38,12,0,0,0,16,12,0,0,13,0,0,0,0,0,0
0,0,0,0,0,0,0,0,12,0,0,0,0,12,0,0,0,0,0,0,0,0,0
0,0,0,0,0,11,12,50,12,12,12,12,12,12,0,0,0,0,0,0,0,0,0
0,0,0,0,8,12,12,13,0,0,0,17,17,0,0,0,0,0,0,38,0,0,0
0,0,0,0,8,12,12,13,0,0,0,0,0,0,0,0,0,0,38,38,38,0,0
0,0,0,0,0,17,17,0,0,0,0,0,0,0,0,0,0,0,0,38,0,0,0
0,0,0,0,0,0,0,0,0,0,0,0,0,0,0,0,0,0,0,0,0,0,0
0,0,0,0,0,0,0,0,0,0,0,0,0,0,0,0,0,0,0,0,0,0,0
0,0,0,0,0,0,0,0,0,0,0,0,0,0,0,0,0,0,0,0,0,0,0
:endlayer
layer: 15
0,0,0,0,0,0,0,0,0,0,0,0,0,0,0,0,4,0,0,0,0,0,0
0,0,0,0,0,0,0,0,0,0,0,0,0,0,4,11,38,13,0,0,0,0,0
0,0,0,0,0,0,0,0,0,0,0,0,0,0,38,38,38,38,0,0,0,0,0
0,0,0,0,0,0,0,0,0,0,0,0,0,38,38,38,38,38,38,0,0,0,0
0,0,0,0,0,0,0,0,0,0,0,0,38,38,38,38,38,38,0,38,0,0,0
0,0,0,0,0,0,4,4,0,0,0,0,38,38,38,12,38,38,38,38,0,0,0
0,0,0,0,0,4,12,12,13,0,0,0,38,38,38,16,38,38,38,17,0,0,0
0,0,0,0,0,12,12,12,40,12,0,0,0,38,38,38,38,38,0,0,0,0,0
0,0,0,0,0,0,17,17,0,0,0,0,0,0,38,0,38,0,0,0,0,0,0
0,0,0,0,0,0,0,0,51,0,0,0,0,0,0,0,0,0,0,0,0,0,0
0,0,0,0,0,38,0,0,0,52,52,52,52,0,0,0,0,0,0,0,0,0,0
0,0,0,38,38,38,38,38,0,52,52,52,52,4,0,0,0,0,0,0,0,0,0
0,0,0,38,38,38,38,38,0,52,52,52,12,12,13,0,13,0,0,0,0,0,0
0,0,38,38,38,38,38,38,38,52,52,52,12,12,13,0,0,0,0,0,0,0,0
0,0,0,38,38,12,38,38,0,52,52,52,52,17,0,0,13,0,0,0,0,0,0
0,0,0,38,38,12,38,38,0,52,52,52,52,0,0,0,0,0,0,0,0,0,0
0,0,0,0,0,38,0,0,0,0,0,0,0,53,0,0,0,0,0,0,0,0,0
0,0,0,0,8,12,12,13,0,0,0,0,0,0,0,0,0,0,0,0,0,0,0
0,0,0,0,8,12,12,13,0,0,0,0,0,0,0,0,0,0,0,0,0,0,0
0,0,0,0,0,17,17,0,0,0,0,0,0,0,0,0,0,0,0,0,0,0,0
0,0,0,0,0,0,0,0,0,0,0,0,0,0,0,0,0,0,0,0,0,0,0
0,0,0,0,0,0,0,0,0,0,0,0,0,0,0,0,0,0,0,0,0,0,0
0,0,0,0,0,0,0,0,0,0,0,0,0,0,0,0,0,0,0,0,0,0,0
:endlayer
layer: 16
0,0,0,0,0,0,0,0,0,0,0,0,0,0,0,0,0,0,0,0,0,0,0
0,0,0,0,0,0,0,0,0,0,0,0,0,0,0,4,0,0,0,0,0,0,0
0,0,0,0,0,0,0,0,0,0,0,0,0,0,0,38,38,0,0,0,0,0,0
0,0,0,0,0,0,0,0,0,0,0,0,0,0,38,38,38,0,0,0,0,0,0
0,0,0,0,0,0,0,0,0,0,0,0,0,38,38,38,38,38,38,0,0,0,0
0,0,0,0,38,0,4,4,0,0,0,0,38,38,38,0,38,38,38,0,0,0,0
0,0,0,38,38,38,12,12,13,0,0,0,0,0,38,0,38,38,0,0,0,0,0
0,0,38,38,12,38,12,12,8,12,0,0,0,0,38,0,38,0,0,0,0,0,0
0,0,0,38,38,38,17,17,0,0,0,0,0,0,0,0,0,0,0,0,0,0,0
0,0,0,0,38,0,0,0,0,0,0,0,0,0,0,0,0,0,0,0,0,0,0
0,0,0,0,0,0,0,0,0,8,0,0,0,0,0,0,0,0,0,0,0,0,0
0,0,0,0,0,38,0,0,0,4,0,0,0,4,0,0,0,0,0,0,0,0,0
0,0,0,0,38,38,38,0,0,0,0,0,12,12,13,0,13,0,0,0,0,0,0
0,0,0,38,38,12,38,38,0,0,0,0,12,12,13,0,0,0,0,0,0,0,0
0,0,0,0,38,38,38,0,0,0,0,0,0,17,0,0,13,0,0,0,0,0,0
0,0,0,0,0,38,0,0,0,0,0,0,0,0,0,0,0,0,0,0,0,0,0
0,0,0,0,0,4,12,50,50,50,0,0,0,0,0,0,0,0,0,0,0,0,0
0,0,0,0,8,12,12,13,0,0,0,0,0,0,0,0,0,0,0,0,0,0,0
0,0,0,0,8,12,12,13,0,0,0,0,0,0,0,0,0,0,0,0,0,0,0
0,0,0,0,0,17,17,0,0,0,0,0,0,0,0,0,0,0,0,0,0,0,0
0,0,0,0,0,0,0,0,0,0,0,0,0,0,0,0,0,0,0,0,0,0,0
0,0,0,0,0,0,0,0,0,0,0,0,0,0,0,0,0,0,0,0,0,0,0
0,0,0,0,0,0,0,0,0,0,0,0,0,0,0,0,0,0,0,0,0,0,0
:endlayer
layer: 17
0,0,0,0,0,0,0,0,0,0,0,0,0,0,0,0,0,0,0,0,0,0,0
0,0,0,0,0,0,0,0,0,0,0,0,0,0,0,0,0,0,0,0,0,0,0
0,0,0,0,0,0,0,0,0,0,0,0,0,0,0,0,0,0,0,0,0,0,0
0,0,0,0,0,0,0,0,0,0,0,0,0,0,0,0,0,0,0,0,0,0,0
0,0,0,0,0,0,0,0,0,0,0,0,0,0,0,0,0,0,0,0,0,0,0
0,0,0,0,0,0,4,4,0,0,0,0,0,0,0,0,0,0,0,0,0,0,0
0,0,0,0,38,8,12,12,13,0,0,0,0,0,0,0,0,0,0,0,0,0,0
0,0,0,38,38,38,12,12,8,12,0,0,0,0,0,0,0,0,0,0,0,0,0
0,0,0,0,38,0,17,17,0,0,0,0,0,0,0,0,0,0,0,0,0,0,0
0,0,0,0,0,0,0,0,0,0,0,0,0,0,0,0,0,0,0,0,0,0,0
0,0,0,0,0,0,0,0,0,8,38,0,0,0,0,0,0,0,0,0,0,0,0
0,0,0,0,0,0,0,0,0,4,38,38,38,4,0,0,0,0,0,0,0,0,0
0,0,0,0,0,38,0,0,0,38,38,38,12,12,13,0,13,0,0,0,0,0,0
0,0,0,0,38,38,38,0,0,38,38,38,12,12,13,0,0,0,0,0,0,0,0
0,0,0,0,0,12,0,0,0,38,38,38,38,38,38,0,13,0,0,0,0,0,0
0,0,0,0,0,12,0,0,0,0,38,38,38,38,0,0,0,0,0,0,0,0,0
0,0,0,0,0,4,4,0,0,0,0,38,0,38,0,0,0,0,0,0,0,0,0
0,0,0,0,8,12,12,13,0,0,0,0,0,0,0,0,0,0,0,0,0,0,0
0,0,0,0,8,12,12,13,0,0,0,0,0,0,0,0,0,0,0,0,0,0,0
0,0,0,0,0,17,17,0,0,0,0,0,0,0,0,0,0,0,0,0,0,0,0
0,0,0,0,0,0,0,0,0,0,0,0,0,0,0,0,0,0,0,0,0,0,0
0,0,0,0,0,0,0,0,0,0,0,0,0,0,0,0,0,0,0,0,0,0,0
0,0,0,0,0,0,0,0,0,0,0,0,0,0,0,0,0,0,0,0,0,0,0
:endlayer
layer: 18
0,0,0,0,0,0,0,0,0,0,0,0,0,0,0,0,0,0,0,0,0,0,0
0,0,0,0,0,0,38,38,0,0,0,0,0,0,0,0,0,0,0,0,0,0,0
0,0,0,38,38,38,38,38,38,38,38,0,0,0,0,0,0,0,0,0,0,0,0
0,0,38,38,38,38,38,38,38,38,38,38,0,0,0,0,0,0,0,0,0,0,0
0,0,38,38,38,38,38,38,38,38,38,38,0,0,0,0,0,0,0,0,0,0,0
0,0,38,38,38,38,38,38,38,38,38,38,0,0,0,0,0,0,0,0,0,0,0
0,38,38,38,38,38,12,12,38,38,38,38,38,0,0,0,0,0,0,0,0,0,0
0,38,38,38,38,38,12,12,38,38,38,38,38,0,0,0,0,0,0,0,0,0,0
0,0,38,38,38,38,38,38,38,38,38,38,0,0,0,0,0,0,0,0,0,0,0
0,0,38,38,38,38,38,38,38,38,38,38,0,0,0,0,0,0,0,0,0,0,0
0,0,38,38,38,38,38,38,38,38,38,38,0,0,0,0,0,0,0,0,0,0,0
0,0,0,38,38,38,38,38,38,38,38,0,4,4,0,0,0,0,0,0,0,0,0
0,0,0,0,38,38,38,38,0,0,0,8,12,12,13,0,13,0,0,0,0,0,0
0,0,0,38,38,12,38,38,0,0,38,38,12,12,38,0,0,0,0,0,0,0,0
0,0,0,0,38,38,38,0,0,0,0,38,38,12,38,38,13,0,0,0,0,0,0
0,0,0,0,0,38,0,0,0,0,0,38,38,38,38,38,39,0,0,0,0,0,0
0,0,0,0,0,4,4,0,0,0,0,38,38,38,38,38,39,0,0,0,0,0,0
0,0,0,0,8,12,12,13,0,0,0,0,38,38,0,0,39,0,0,0,0,0,0
0,0,0,0,8,12,12,13,0,0,0,0,0,38,0,0,0,0,0,0,0,0,0
0,0,0,0,0,17,17,0,0,0,0,0,0,0,0,0,0,0,0,0,0,0,0
0,0,0,0,0,0,0,0,0,0,0,0,0,0,0,0,0,0,0,0,0,0,0
0,0,0,0,0,0,0,0,0,0,0,0,0,0,0,0,0,0,0,0,0,0,0
0,0,0,0,0,0,0,0,0,0,0,0,0,0,0,0,0,0,0,0,0,0,0
:endlayer
layer: 19
0,0,0,0,0,0,0,0,0,0,0,0,0,0,0,0,0,0,0,0,0,0,0
0,0,0,0,0,0,0,0,0,0,0,0,0,0,0,0,0,0,0,0,0,0,0
0,0,0,0,0,0,38,38,0,0,0,0,0,0,0,0,0,0,0,0,0,0,0
0,0,0,0,38,38,38,38,38,38,0,0,0,0,0,0,0,0,0,0,0,0,0
0,0,0,38,38,38,38,38,38,38,38,0,0,0,0,0,0,0,0,0,0,0,0
0,0,0,38,38,38,38,38,38,38,38,0,0,0,0,0,0,0,0,0,0,0,0
0,0,38,38,38,38,38,38,38,38,38,38,0,0,0,0,0,0,0,0,0,0,0
0,0,38,38,38,38,12,38,38,38,38,38,0,0,0,0,0,0,0,0,0,0,0
0,0,0,38,38,38,38,38,38,38,38,0,0,0,0,0,0,0,0,0,0,0,0
0,0,0,38,38,38,38,38,38,38,38,0,0,0,0,0,0,0,0,0,0,0,0
0,0,0,0,38,38,38,38,38,38,0,0,0,0,0,0,0,0,0,0,0,0,0
0,0,0,0,0,0,38,38,0,0,0,0,4,4,0,0,0,0,0,0,0,0,0
0,0,0,0,0,38,0,0,0,0,0,8,12,12,13,0,13,0,0,0,0,0,0
0,0,0,0,38,38,38,0,0,0,0,8,12,12,0,0,0,0,0,0,0,0,0
0,0,0,0,0,38,0,0,0,0,38,38,38,38,0,0,0,0,0,0,0,0,0
0,0,0,0,0,0,0,0,0,0,38,38,38,12,0,0,0,0,0,0,0,0,0
0,0,0,0,0,4,4,0,0,0,38,38,38,38,38,0,0,0,0,0,0,0,0
0,0,0,0,8,12,12,13,0,0,0,38,38,38,38,0,0,0,0,0,0,0,0
0,0,0,0,38,12,12,38,38,0,0,0,0,38,38,0,0,0,0,0,0,0,0
0,0,0,0,38,38,12,38,38,0,0,0,0,0,0,0,0,0,0,0,0,0,0
0,0,0,38,38,38,38,38,38,38,0,0,0,0,0,0,0,0,0,0,0,0,0
0,0,0,0,38,38,38,38,38,0,0,0,0,0,0,0,0,0,0,0,0,0,0
0,0,0,0,38,38,38,38,38,0,0,0,0,0,0,0,0,0,0,0,0,0,0
:endlayer
layer: 20
0,0,0,0,0,0,0,0,0,0,0,0,0,0,0,0,0,0,0,0,0,0,0
0,0,0,0,0,0,0,0,0,0,0,0,0,0,0,0,0,0,0,0,0,0,0
0,0,0,0,0,0,0,0,0,0,0,0,0,0,0,0,0,0,0,0,0,0,0
0,0,0,0,0,0,38,38,0,0,0,0,0,0,0,0,0,0,0,0,0,0,0
0,0,0,0,38,38,38,38,38,38,0,0,0,0,0,0,0,0,0,0,0,0,0
0,0,0,0,38,38,38,38,38,38,0,0,0,0,0,0,0,0,0,0,0,0,0
0,0,0,38,38,38,38,38,38,38,38,0,0,0,0,0,0,0,0,0,0,0,0
0,0,0,38,38,38,38,38,38,38,38,0,0,0,0,0,0,0,0,0,0,0,0
0,0,0,0,38,38,38,38,38,38,0,0,0,0,0,0,0,0,0,0,0,0,0
0,0,0,0,38,38,38,38,38,38,0,0,0,0,0,0,0,0,0,0,0,0,0
0,0,0,0,0,0,38,38,0,0,0,0,0,0,0,0,0,0,0,0,0,0,0
0,0,0,0,0,0,0,0,0,0,0,0,4,4,0,0,0,0,0,0,0,0,0
0,0,0,0,0,0,0,0,0,0,0,8,12,12,38,0,13,0,0,0,0,0,0
0,0,0,0,0,0,0,0,0,0,0,8,12,12,12,38,38,0,0,0,0,0,0
0,0,0,0,0,0,0,0,0,0,0,38,38,38,12,38,38,0,0,0,0,0,0
0,0,0,0,0,0,0,0,0,0,0,38,38,38,38,38,38,54,0,0,0,0,0
0,0,0,0,0,4,4,0,0,0,0,38,38,38,38,38,38,54,0,0,0,0,0
0,0,0,0,8,12,12,13,0,0,0,0,38,38,38,38,39,39,0,0,0,0,0
0,0,0,0,8,12,12,13,0,0,0,0,0,38,38,39,0,0,0,0,0,0,0
0,0,0,0,0,38,38,38,0,0,0,0,0,0,0,0,0,0,0,0,0,0,0
0,0,0,0,38,38,12,38,38,0,0,0,0,0,0,0,0,0,0,0,0,0,0
0,0,0,0,0,38,38,38,0,0,0,0,0,0,0,0,0,0,0,0,0,0,0
0,0,0,0,0,0,38,0,0,0,0,0,0,0,0,0,0,0,0,0,0,0,0
:endlayer
layer: 21
0,0,0,0,0,0,0,0,0,0,0,0,0,0,0,0,0,0,0,0,0,0,0
0,0,0,0,0,0,0,0,0,0,0,0,0,0,0,0,0,0,0,0,0,0,0
0,0,0,0,0,0,0,0,0,0,0,0,0,0,0,0,0,0,0,0,0,0,0
0,0,0,0,0,0,0,0,0,0,0,0,0,0,0,0,0,0,0,0,0,0,0
0,0,0,0,0,0,0,0,0,0,0,0,0,0,0,0,0,0,0,0,0,0,0
0,0,0,0,0,0,0,0,0,0,0,0,0,0,0,0,0,0,0,0,0,0,0
0,0,0,0,0,0,0,0,0,0,0,0,0,0,0,0,0,0,0,0,0,0,0
0,0,0,0,0,0,0,0,0,0,0,0,0,0,0,0,0,0,0,0,0,0,0
0,0,0,0,0,0,0,0,0,0,0,0,0,0,0,0,0,0,0,0,0,0,0
0,0,0,0,0,0,0,0,0,0,0,0,0,0,0,0,0,0,0,0,0,0,0
0,0,0,0,0,0,0,0,0,0,0,0,0,0,0,0,0,0,0,0,0,0,0
0,0,0,0,0,0,0,0,0,0,0,0,4,4,0,0,0,0,0,0,0,0,0
0,0,0,0,0,38,38,0,0,0,0,8,12,12,0,0,13,0,0,0,0,0,0
0,0,38,38,38,38,38,38,38,38,0,8,12,12,38,0,0,0,0,0,0,0,0
0,38,38,38,38,38,38,38,38,38,38,0,38,38,38,0,38,0,0,0,0,0,0
0,38,38,38,38,38,38,38,38,38,38,0,38,0,38,12,38,0,0,0,0,0,0
0,38,38,38,38,38,38,38,38,38,38,0,38,38,38,38,38,0,0,0,0,0,0
38,38,38,38,38,12,12,38,38,38,38,38,0,0,38,0,38,0,0,0,0,0,0
38,38,38,38,38,12,12,38,38,38,38,38,0,0,38,0,38,0,0,0,0,0,0
0,38,38,38,38,38,38,38,38,38,38,0,0,0,0,0,0,0,0,0,0,0,0
0,38,38,38,38,38,38,38,38,38,38,0,0,0,0,0,0,0,0,0,0,0,0
0,38,38,38,38,38,38,38,38,38,38,0,0,0,0,0,0,0,0,0,0,0,0
0,0,38,38,38,38,38,38,38,38,0,0,0,0,0,0,0,0,0,0,0,0,0
:endlayer
layer: 22
0,0,0,0,0,0,0,0,0,0,0,0,0,0,0,0,0,0,0,0,0,0,0
0,0,0,0,0,0,0,0,0,0,0,0,0,0,0,0,0,0,0,0,0,0,0
0,0,0,0,0,0,0,0,0,0,0,0,0,0,0,0,0,0,0,0,0,0,0
0,0,0,0,0,0,0,0,0,0,0,0,0,0,0,0,0,0,0,0,0,0,0
0,0,0,0,0,0,0,0,0,0,0,0,0,0,0,0,0,0,0,0,0,0,0
0,0,0,0,0,0,0,0,0,0,0,0,0,0,0,0,0,0,0,0,0,0,0
0,0,0,0,0,0,0,0,0,0,0,0,0,0,0,0,0,0,0,0,0,0,0
0,0,0,0,0,0,0,0,0,0,0,0,0,0,0,0,0,0,0,0,0,0,0
0,0,0,0,0,0,0,0,0,0,0,0,0,0,0,0,0,0,0,0,0,0,0
0,0,0,0,0,0,0,0,0,0,0,0,0,0,0,0,0,0,0,0,0,0,0
0,0,0,0,0,0,0,0,0,0,0,0,0,0,0,0,0,0,0,0,0,0,0
0,0,0,0,0,0,0,0,0,0,0,0,4,4,0,0,0,0,0,0,0,0,0
0,0,0,0,0,0,0,0,0,0,0,55,12,12,0,0,13,0,0,0,0,0,0
0,0,0,0,0,38,38,0,0,0,0,8,12,12,13,0,0,0,0,0,0,0,0
0,0,0,38,38,38,38,38,38,0,0,0,17,17,38,0,0,0,0,0,0,0,0
0,0,38,38,38,38,38,38,38,38,0,0,0,38,38,38,0,0,0,0,0,0,0
0,0,38,38,38,38,38,38,38,38,0,0,0,38,38,38,0,0,0,0,0,0,0
0,38,38,38,38,38,38,38,38,38,38,0,0,0,38,38,0,0,0,0,0,0,0
0,38,38,38,38,12,38,38,38,38,38,0,0,0,0,0,0,0,0,0,0,0,0
0,0,38,38,38,38,38,38,38,38,0,0,0,0,0,0,0,0,0,0,0,0,0
0,0,38,38,38,38,38,38,38,38,0,0,0,0,0,0,0,0,0,0,0,0,0
0,0,0,38,38,38,38,38,38,0,0,0,0,0,0,0,0,0,0,0,0,0,0
0,0,0,0,0,38,38,0,0,0,0,0,0,0,0,0,0,0,0,0,0,0,0
:endlayer
layer: 23
0,0,0,0,0,0,0,0,0,0,0,0,0,0,0,0,0,0,0,0,0,0,0
0,0,0,0,0,0,0,0,0,0,0,0,0,0,0,0,0,0,0,0,0,0,0
0,0,0,0,0,0,0,0,0,0,0,0,0,0,0,0,0,0,0,0,0,0,0
0,0,0,0,0,0,0,0,0,0,0,0,0,0,0,0,0,0,0,0,0,0,0
0,0,0,0,0,0,0,0,0,0,0,0,0,0,0,0,0,0,0,0,0,0,0
0,0,0,0,0,0,0,0,0,0,0,0,0,0,0,0,0,0,0,0,0,0,0
0,0,0,0,0,0,0,0,0,0,0,0,0,0,0,0,0,0,0,0,0,0,0
0,0,0,0,0,0,0,0,0,0,0,0,0,0,0,0,0,0,0,0,0,0,0
0,0,0,0,0,0,0,0,0,0,0,0,38,0,0,0,0,0,0,0,0,0,0
0,0,0,0,0,0,0,0,0,0,0,0,38,0,38,0,0,0,0,0,0,0,0
0,0,0,0,0,0,0,0,0,0,38,38,38,38,38,38,0,0,0,0,0,0,0
0,0,0,0,0,0,0,0,0,38,38,38,38,38,38,38,38,0,0,0,0,0,0
0,0,0,0,0,0,0,0,38,38,38,38,12,12,38,38,13,0,0,0,0,0,0
0,0,0,0,0,0,0,0,38,38,38,38,12,12,38,38,38,38,0,0,0,0,0
0,0,0,0,0,38,38,0,0,38,38,38,38,38,38,38,38,0,0,0,0,0,0
0,0,0,38,38,38,38,38,38,38,38,38,38,38,38,38,38,38,0,0,0,0,0
0,0,0,38,38,38,38,38,38,38,38,38,38,38,38,38,38,0,0,0,0,0,0
0,0,38,38,38,38,38,38,38,38,38,0,38,38,38,38,0,0,0,0,0,0,0
0,0,38,38,38,38,38,38,38,38,0,0,38,38,38,38,0,0,0,0,0,0,0
0,0,0,38,38,38,38,38,38,0,0,0,0,0,0,0,0,0,0,0,0,0,0
0,0,0,38,38,38,38,38,38,0,0,0,0,0,0,0,0,0,0,0,0,0,0
0,0,0,0,0,38,38,0,0,0,0,0,0,0,0,0,0,0,0,0,0,0,0
0,0,0,0,0,0,0,0,0,0,0,0,0,0,0,0,0,0,0,0,0,0,0
:endlayer
layer: 24
0,0,0,0,0,0,0,0,0,0,0,0,0,0,0,0,0,0,0,0,0,0,0
0,0,0,0,0,0,0,0,0,0,0,0,0,0,0,0,0,0,0,0,0,0,0
0,0,0,0,0,0,0,0,0,0,0,0,0,0,0,0,0,0,0,0,0,0,0
0,0,0,0,0,0,0,0,0,0,0,0,0,0,0,0,0,0,0,0,0,0,0
0,0,0,0,0,0,0,0,0,0,0,0,0,0,0,0,0,0,0,0,0,0,0
0,0,0,0,0,0,0,0,0,0,0,0,0,0,0,0,0,0,0,0,0,0,0
0,0,0,0,0,0,0,0,0,0,0,0,0,0,0,0,0,0,0,0,0,0,0
0,0,0,0,0,0,0,0,0,0,0,0,0,0,0,0,0,0,0,0,0,0,0
0,0,0,0,0,0,0,0,0,0,0,0,0,0,0,0,0,0,0,0,0,0,0
0,0,0,0,0,0,0,0,0,0,0,0,38,0,0,0,0,0,0,0,0,0,0
0,0,0,0,0,0,0,0,0,0,0,38,38,0,38,0,0,0,0,0,0,0,0
0,0,0,0,0,0,0,0,0,0,38,38,38,38,38,38,0,0,0,0,0,0,0
0,0,0,0,0,0,0,0,0,38,38,38,38,38,38,38,38,0,0,0,0,0,0
0,0,0,0,0,0,0,0,38,38,38,38,12,38,38,38,38,0,0,0,0,0,0
0,0,0,0,0,0,0,0,0,38,38,38,38,38,38,0,0,0,0,0,0,0,0
0,0,0,0,0,0,0,0,0,38,38,38,38,38,38,38,38,0,0,0,0,0,0
0,0,0,0,0,0,0,0,0,0,0,38,38,38,38,0,0,0,0,0,0,0,0
0,0,0,0,0,0,0,0,0,0,0,0,38,38,38,38,0,0,0,0,0,0,0
0,0,0,0,0,0,0,0,0,0,0,0,0,0,0,0,0,0,0,0,0,0,0
0,0,0,0,0,0,0,0,0,0,0,0,0,0,0,0,0,0,0,0,0,0,0
0,0,0,0,0,0,0,0,0,0,0,0,0,0,0,0,0,0,0,0,0,0,0
0,0,0,0,0,0,0,0,0,0,0,0,0,0,0,0,0,0,0,0,0,0,0
0,0,0,0,0,0,0,0,0,0,0,0,0,0,0,0,0,0,0,0,0,0,0
:endlayer
layer: 25
0,0,0,0,0,0,0,0,0,0,0,0,0,0,0,0,0,0,0,0,0,0,0
0,0,0,0,0,0,0,0,0,0,0,0,0,0,0,0,0,0,0,0,0,0,0
0,0,0,0,0,0,0,0,0,0,0,0,0,0,0,0,0,0,0,0,0,0,0
0,0,0,0,0,0,0,0,0,0,0,0,0,0,0,0,0,0,0,0,0,0,0
0,0,0,0,0,0,0,0,0,0,0,0,0,0,0,0,0,0,0,0,0,0,0
0,0,0,0,0,0,0,0,0,0,0,0,0,0,0,0,0,0,0,0,0,0,0
0,0,0,0,0,0,0,0,0,0,0,0,0,0,0,0,0,0,0,0,0,0,0
0,0,0,0,0,0,0,0,0,0,0,0,0,0,0,0,0,0,0,0,0,0,0
0,0,0,0,0,0,0,0,0,0,0,0,0,0,0,0,0,0,0,0,0,0,0
0,0,0,0,0,0,0,0,0,0,0,0,0,0,0,0,0,0,0,0,0,0,0
0,0,0,0,0,0,0,0,0,0,0,0,38,38,0,0,0,0,0,0,0,0,0
0,0,0,0,0,0,0,0,0,0,0,38,38,38,38,0,0,0,0,0,0,0,0
0,0,0,0,0,0,0,0,0,0,38,38,38,38,0,38,0,0,0,0,0,0,0
0,0,0,0,0,0,0,0,0,38,38,38,38,38,38,38,0,0,0,0,0,0,0
0,0,0,0,0,0,0,0,0,0,38,38,38,38,38,0,0,0,0,0,0,0,0
0,0,0,0,0,0,0,0,0,0,38,38,38,38,38,38,0,0,0,0,0,0,0
0,0,0,0,0,0,0,0,0,0,0,0,38,38,38,0,0,0,0,0,0,0,0
0,0,0,0,0,0,0,0,0,0,0,0,0,0,0,0,0,0,0,0,0,0,0
0,0,0,0,0,0,0,0,0,0,0,0,0,0,0,0,0,0,0,0,0,0,0
0,0,0,0,0,0,0,0,0,0,0,0,0,0,0,0,0,0,0,0,0,0,0
0,0,0,0,0,0,0,0,0,0,0,0,0,0,0,0,0,0,0,0,0,0,0
0,0,0,0,0,0,0,0,0,0,0,0,0,0,0,0,0,0,0,0,0,0,0
0,0,0,0,0,0,0,0,0,0,0,0,0,0,0,0,0,0,0,0,0,0,0
:endlayer

#### RULES ####
rule:
plugin=vanillaBlocks
number=1
data:
JSON:{blockState:{blockName:"minecraft:dirt",properties:{variant:"dirt",snowy:"false"}}}
:enddata
:endrule

rule:
plugin=vanillaBlocks
number=2
data:
JSON:{blockState:{blockName:"minecraft:grass",properties:{snowy:"false"}}}
:enddata
:endrule

rule:
plugin=vanillaBlocks
number=3
data:
JSON:{blockState:{blockName:"minecraft:tallgrass",properties:{type:"tall_grass"}}}
:enddata
:endrule

rule:
plugin=vine
number=4
data:
JSON:{blockState:{blockName:"minecraft:vine",properties:{east:"false",south:"true",north:"false",west:"false",up:"false"}}}
:enddata
:endrule

rule:
plugin=vanillaBlocks
number=5
data:
JSON:{blockState:{blockName:"minecraft:red_flower",properties:{type:"poppy"}}}
:enddata
:endrule

rule:
plugin=blockTile
number=6
data:
JSON:{blockState:{blockName:"ancientwarfarestructure:advanced_spawner",properties:{transparent:"true"}},teData:{id:"ancientwarfarestructure:advanced_spawner_tile",spawnerSettings:{minDelay:0,spawnDelay:0,lightSensitive:0b,spawnGroups:[{settingsList:[{remainingSpawnCount:1,hostile:1b,forced:1b,customTag:{factionName:"kong"},maxToSpawn:1,entityId:"ancientwarfarenpc:faction.archer.elite",minToSpawn:1}],groupWeight:1}],playerRange:32,respondToRedstone:0b,inventory:{Size:9,Items:[]},spawnRange:0,transparent:1b,maxDelay:0,xpToDrop:0,mobRange:0,debugMode:0b,maxNearbyMonsters:0}}}
:enddata
:endrule

rule:
plugin=blockTile
number=7
data:
JSON:{blockState:{blockName:"ancientwarfarestructure:advanced_spawner",properties:{transparent:"true"}},teData:{id:"ancientwarfarestructure:advanced_spawner_tile",spawnerSettings:{minDelay:0,spawnDelay:0,lightSensitive:0b,spawnGroups:[{settingsList:[{remainingSpawnCount:1,hostile:1b,forced:1b,customTag:{factionName:"kong"},maxToSpawn:1,entityId:"ancientwarfarenpc:faction.soldier",minToSpawn:1}],groupWeight:1}],playerRange:16,respondToRedstone:0b,inventory:{Size:9,Items:[]},spawnRange:0,transparent:1b,maxDelay:0,xpToDrop:0,mobRange:0,debugMode:0b,maxNearbyMonsters:0}}}
:enddata
:endrule

rule:
plugin=vine
number=8
data:
JSON:{blockState:{blockName:"minecraft:vine",properties:{east:"true",south:"false",north:"false",west:"false",up:"false"}}}
:enddata
:endrule

rule:
plugin=vanillaBlocks
number=9
data:
JSON:{blockState:{blockName:"minecraft:red_flower",properties:{type:"houstonia"}}}
:enddata
:endrule

rule:
plugin=blockTile
number=10
data:
JSON:{blockState:{blockName:"ancientwarfarestructure:advanced_spawner",properties:{transparent:"true"}},teData:{id:"ancientwarfarestructure:advanced_spawner_tile",spawnerSettings:{minDelay:0,spawnDelay:0,lightSensitive:0b,spawnGroups:[{settingsList:[{remainingSpawnCount:1,hostile:1b,forced:1b,customTag:{factionName:"kong"},maxToSpawn:1,entityId:"ancientwarfarenpc:faction.soldier",minToSpawn:1}],groupWeight:1}],playerRange:16,respondToRedstone:0b,inventory:{Size:9,Items:[]},spawnRange:0,transparent:1b,maxDelay:0,xpToDrop:0,mobRange:0,debugMode:0b,maxNearbyMonsters:0}}}
:enddata
:endrule

rule:
plugin=vine
number=11
data:
JSON:{blockState:{blockName:"minecraft:vine",properties:{east:"true",south:"true",north:"false",west:"false",up:"false"}}}
:enddata
:endrule

rule:
plugin=vanillaBlocks
number=12
data:
JSON:{blockState:{blockName:"minecraft:log",properties:{variant:"jungle",axis:"y"}}}
:enddata
:endrule

rule:
plugin=vine
number=13
data:
JSON:{blockState:{blockName:"minecraft:vine",properties:{east:"false",south:"false",north:"false",west:"true",up:"false"}}}
:enddata
:endrule

rule:
plugin=vanillaBlocks
number=14
data:
JSON:{blockState:{blockName:"minecraft:fence",properties:{east:"false",south:"false",north:"false",west:"false"}}}
:enddata
:endrule

rule:
plugin=vanillaBlocks
number=15
data:
JSON:{blockState:{blockName:"minecraft:red_flower",properties:{type:"pink_tulip"}}}
:enddata
:endrule

rule:
plugin=vanillaBlocks
number=16
data:
JSON:{blockState:{blockName:"minecraft:ladder",properties:{facing:"south"}}}
:enddata
:endrule

rule:
plugin=vine
number=17
data:
JSON:{blockState:{blockName:"minecraft:vine",properties:{east:"false",south:"false",north:"true",west:"false",up:"false"}}}
:enddata
:endrule

rule:
plugin=vine
number=18
data:
JSON:{blockState:{blockName:"minecraft:vine",properties:{east:"false",south:"false",north:"true",west:"true",up:"false"}}}
:enddata
:endrule

rule:
plugin=vanillaBlocks
number=19
data:
JSON:{blockState:{blockName:"minecraft:fence_gate",properties:{in_wall:"false",powered:"false",facing:"west",open:"false"}}}
:enddata
:endrule

rule:
plugin=blockTile
number=20
data:
JSON:{blockState:{blockName:"ancientwarfarestructure:advanced_spawner",properties:{transparent:"true"}},teData:{id:"ancientwarfarestructure:advanced_spawner_tile",spawnerSettings:{minDelay:0,spawnDelay:0,lightSensitive:0b,spawnGroups:[{settingsList:[{remainingSpawnCount:1,hostile:1b,forced:1b,customTag:{factionName:"kong"},maxToSpawn:1,entityId:"ancientwarfarenpc:faction.archer.elite",minToSpawn:1}],groupWeight:1}],playerRange:32,respondToRedstone:0b,inventory:{Size:9,Items:[]},spawnRange:0,transparent:1b,maxDelay:0,xpToDrop:0,mobRange:0,debugMode:0b,maxNearbyMonsters:0}}}
:enddata
:endrule

rule:
plugin=blockTile
number=21
data:
JSON:{blockState:{blockName:"ancientwarfarestructure:advanced_spawner",properties:{transparent:"true"}},teData:{id:"ancientwarfarestructure:advanced_spawner_tile",spawnerSettings:{minDelay:0,spawnDelay:0,lightSensitive:0b,spawnGroups:[{settingsList:[{remainingSpawnCount:1,hostile:1b,forced:1b,customTag:{factionName:"kong"},maxToSpawn:1,entityId:"ancientwarfarenpc:faction.archer.elite",minToSpawn:1}],groupWeight:1}],playerRange:32,respondToRedstone:0b,inventory:{Size:9,Items:[]},spawnRange:0,transparent:1b,maxDelay:0,xpToDrop:0,mobRange:0,debugMode:0b,maxNearbyMonsters:0}}}
:enddata
:endrule

rule:
plugin=vanillaBlocks
number=22
data:
JSON:{blockState:{blockName:"minecraft:double_plant",properties:{half:"lower",variant:"double_grass",facing:"north"}}}
:enddata
:endrule

rule:
plugin=blockTile
number=23
data:
JSON:{blockState:{blockName:"ancientwarfarestructure:advanced_spawner",properties:{transparent:"true"}},teData:{id:"ancientwarfarestructure:advanced_spawner_tile",spawnerSettings:{minDelay:0,spawnDelay:0,lightSensitive:0b,spawnGroups:[{settingsList:[{remainingSpawnCount:1,hostile:1b,forced:1b,customTag:{factionName:"kong"},maxToSpawn:1,entityId:"ancientwarfarenpc:faction.soldier",minToSpawn:1}],groupWeight:1}],playerRange:16,respondToRedstone:0b,inventory:{Size:9,Items:[]},spawnRange:0,transparent:1b,maxDelay:0,xpToDrop:0,mobRange:0,debugMode:0b,maxNearbyMonsters:0}}}
:enddata
:endrule

rule:
plugin=vanillaBlocks
number=24
data:
JSON:{blockState:{blockName:"minecraft:yellow_flower",properties:{type:"dandelion"}}}
:enddata
:endrule

rule:
plugin=blockTile
number=25
data:
JSON:{blockState:{blockName:"ancientwarfarestructure:advanced_spawner",properties:{transparent:"true"}},teData:{id:"ancientwarfarestructure:advanced_spawner_tile",spawnerSettings:{minDelay:0,spawnDelay:0,lightSensitive:0b,spawnGroups:[{settingsList:[{remainingSpawnCount:1,hostile:1b,forced:1b,customTag:{factionName:"kong"},maxToSpawn:1,entityId:"ancientwarfarenpc:faction.soldier",minToSpawn:1}],groupWeight:1}],playerRange:16,respondToRedstone:0b,inventory:{Size:9,Items:[]},spawnRange:0,transparent:1b,maxDelay:0,xpToDrop:0,mobRange:0,debugMode:0b,maxNearbyMonsters:0}}}
:enddata
:endrule

rule:
plugin=blockTile
number=26
data:
JSON:{blockState:{blockName:"ancientwarfarestructure:advanced_spawner",properties:{transparent:"true"}},teData:{id:"ancientwarfarestructure:advanced_spawner_tile",spawnerSettings:{minDelay:0,spawnDelay:0,lightSensitive:0b,spawnGroups:[{settingsList:[{remainingSpawnCount:1,hostile:1b,forced:1b,customTag:{factionName:"kong"},maxToSpawn:1,entityId:"ancientwarfarenpc:faction.soldier",minToSpawn:1}],groupWeight:1}],playerRange:16,respondToRedstone:0b,inventory:{Size:9,Items:[]},spawnRange:0,transparent:1b,maxDelay:0,xpToDrop:0,mobRange:0,debugMode:0b,maxNearbyMonsters:0}}}
:enddata
:endrule

rule:
plugin=blockTile
number=27
data:
JSON:{blockState:{blockName:"ancientwarfarestructure:advanced_spawner",properties:{transparent:"true"}},teData:{id:"ancientwarfarestructure:advanced_spawner_tile",spawnerSettings:{minDelay:0,spawnDelay:0,lightSensitive:0b,spawnGroups:[{settingsList:[{remainingSpawnCount:1,hostile:1b,forced:1b,customTag:{factionName:"kong"},maxToSpawn:1,entityId:"ancientwarfarenpc:faction.soldier",minToSpawn:1}],groupWeight:1}],playerRange:16,respondToRedstone:0b,inventory:{Size:9,Items:[]},spawnRange:0,transparent:1b,maxDelay:0,xpToDrop:0,mobRange:0,debugMode:0b,maxNearbyMonsters:0}}}
:enddata
:endrule

rule:
plugin=vanillaBlocks
number=28
data:
JSON:{blockState:{blockName:"minecraft:red_flower",properties:{type:"oxeye_daisy"}}}
:enddata
:endrule

rule:
plugin=vanillaBlocks
number=29
data:
JSON:{blockState:{blockName:"minecraft:torch",properties:{facing:"up"}}}
:enddata
:endrule

rule:
plugin=vanillaBlocks
number=30
data:
JSON:{blockState:{blockName:"minecraft:double_plant",properties:{half:"upper",variant:"sunflower",facing:"north"}}}
:enddata
:endrule

rule:
plugin=vanillaBlocks
number=31
data:
JSON:{blockState:{blockName:"minecraft:planks",properties:{variant:"jungle"}}}
:enddata
:endrule

rule:
plugin=vanillaBlocks
number=32
data:
JSON:{blockState:{blockName:"minecraft:farmland",properties:{moisture:"7"}}}
:enddata
:endrule

rule:
plugin=fluid
number=33
data:
JSON:{blockState:{blockName:"minecraft:water",properties:{level:"0"}}}
:enddata
:endrule

rule:
plugin=blockTile
number=34
data:
JSON:{blockState:{blockName:"ancientwarfarestructure:advanced_spawner",properties:{transparent:"true"}},teData:{id:"ancientwarfarestructure:advanced_spawner_tile",spawnerSettings:{minDelay:0,spawnDelay:0,lightSensitive:0b,spawnGroups:[{settingsList:[{remainingSpawnCount:1,hostile:1b,forced:1b,customTag:{factionName:"kong"},maxToSpawn:1,entityId:"ancientwarfarenpc:faction.soldier",minToSpawn:1}],groupWeight:1}],playerRange:3,respondToRedstone:0b,inventory:{Size:9,Items:[]},spawnRange:0,transparent:1b,maxDelay:0,xpToDrop:0,mobRange:0,debugMode:0b,maxNearbyMonsters:0}}}
:enddata
:endrule

rule:
plugin=blockTile
number=35
data:
JSON:{blockState:{blockName:"ancientwarfarestructure:advanced_spawner",properties:{transparent:"true"}},teData:{id:"ancientwarfarestructure:advanced_spawner_tile",spawnerSettings:{minDelay:0,spawnDelay:0,lightSensitive:0b,spawnGroups:[{settingsList:[{remainingSpawnCount:1,hostile:1b,forced:1b,customTag:{factionName:"kong"},maxToSpawn:1,entityId:"ancientwarfarenpc:faction.soldier",minToSpawn:1}],groupWeight:1}],playerRange:6,respondToRedstone:0b,inventory:{Size:9,Items:[]},spawnRange:0,transparent:1b,maxDelay:0,xpToDrop:0,mobRange:0,debugMode:0b,maxNearbyMonsters:0}}}
:enddata
:endrule

rule:
plugin=vanillaBlocks
number=36
data:
JSON:{blockState:{blockName:"minecraft:wheat",properties:{age:"7"}}}
:enddata
:endrule

rule:
plugin=blockTile
number=37
data:
JSON:{blockState:{blockName:"ancientwarfarestructure:advanced_spawner",properties:{transparent:"true"}},teData:{id:"ancientwarfarestructure:advanced_spawner_tile",spawnerSettings:{minDelay:0,spawnDelay:0,lightSensitive:0b,spawnGroups:[{settingsList:[{remainingSpawnCount:1,hostile:1b,forced:1b,customTag:{factionName:"kong"},maxToSpawn:1,entityId:"ancientwarfarenpc:faction.soldier",minToSpawn:1}],groupWeight:1}],playerRange:6,respondToRedstone:0b,inventory:{Size:9,Items:[]},spawnRange:0,transparent:1b,maxDelay:0,xpToDrop:0,mobRange:0,debugMode:0b,maxNearbyMonsters:0}}}
:enddata
:endrule

rule:
plugin=vanillaBlocks
number=38
data:
JSON:{blockState:{blockName:"minecraft:leaves",properties:{check_decay:"false",decayable:"true",variant:"jungle"}}}
:enddata
:endrule

rule:
plugin=vanillaBlocks
number=39
data:
JSON:{blockState:{blockName:"minecraft:leaves",properties:{check_decay:"true",decayable:"false",variant:"oak"}}}
:enddata
:endrule

rule:
plugin=vine
number=40
data:
JSON:{blockState:{blockName:"minecraft:vine",properties:{east:"true",south:"false",north:"false",west:"true",up:"false"}}}
:enddata
:endrule

rule:
plugin=inventory
number=41
data:
JSON:{blockState:{blockName:"minecraft:furnace",properties:{facing:"south"}},lootLevel:0,teData:{CookTime:0,BurnTime:0,Items:[],id:"minecraft:furnace",CookTimeTotal:0,Lock:""},inventoryData:{length:0,inventoryContents:[]},legacyFeatures:0b}
:enddata
:endrule

rule:
plugin=inventory
number=42
data:
JSON:{blockState:{blockName:"minecraft:chest",properties:{facing:"south"}},lootLevel:0,teData:{ForgeData:{},Items:[{Slot:8b,id:"ancientwarfarenpc:coin",Count:17b,tag:{metal:"copper"},Damage:0s},{Slot:9b,id:"minecraft:dye",Count:6b,Damage:4s},{Slot:11b,id:"minecraft:dye",Count:14b,Damage:3s},{Slot:13b,id:"minecraft:emerald",Count:3b,Damage:0s}],id:"minecraft:chest",Lock:""},inventoryData:{length:4,inventoryContents:[{id:"ancientwarfarenpc:coin",Count:17b,tag:{metal:"copper"},slot:0,Damage:0s},{id:"minecraft:dye",Count:6b,slot:1,Damage:4s},{id:"minecraft:dye",Count:14b,slot:2,Damage:3s},{id:"minecraft:emerald",Count:3b,slot:3,Damage:0s}]},legacyFeatures:1b}
:enddata
:endrule

rule:
plugin=inventory
number=43
data:
JSON:{blockState:{blockName:"minecraft:chest",properties:{facing:"south"}},lootLevel:0,teData:{Items:[{Slot:10b,id:"minecraft:string",Count:13b,Damage:0s},{Slot:12b,id:"minecraft:rotten_flesh",Count:7b,Damage:0s},{Slot:14b,id:"minecraft:bone",Count:4b,Damage:0s},{Slot:15b,id:"minecraft:bone",Count:9b,Damage:0s},{Slot:17b,id:"minecraft:feather",Count:13b,Damage:0s},{Slot:20b,id:"minecraft:rotten_flesh",Count:8b,Damage:0s},{Slot:21b,id:"minecraft:rotten_flesh",Count:4b,Damage:0s}],id:"minecraft:chest",Lock:""},inventoryData:{length:7,inventoryContents:[{id:"minecraft:string",Count:13b,slot:0,Damage:0s},{id:"minecraft:rotten_flesh",Count:7b,slot:1,Damage:0s},{id:"minecraft:bone",Count:4b,slot:2,Damage:0s},{id:"minecraft:bone",Count:9b,slot:3,Damage:0s},{id:"minecraft:feather",Count:13b,slot:4,Damage:0s},{id:"minecraft:rotten_flesh",Count:8b,slot:5,Damage:0s},{id:"minecraft:rotten_flesh",Count:4b,slot:6,Damage:0s}]},legacyFeatures:1b}
:enddata
:endrule

rule:
plugin=blockTile
number=44
data:
JSON:{blockState:{blockName:"ancientwarfarestructure:advanced_spawner",properties:{transparent:"true"}},teData:{id:"ancientwarfarestructure:advanced_spawner_tile",spawnerSettings:{minDelay:0,spawnDelay:0,lightSensitive:0b,spawnGroups:[{settingsList:[{remainingSpawnCount:1,hostile:1b,forced:1b,customTag:{factionName:"kong"},maxToSpawn:1,entityId:"ancientwarfarenpc:faction.soldier",minToSpawn:1}],groupWeight:1}],playerRange:3,respondToRedstone:0b,inventory:{Size:9,Items:[]},spawnRange:0,transparent:1b,maxDelay:0,xpToDrop:0,mobRange:0,debugMode:0b,maxNearbyMonsters:0}}}
:enddata
:endrule

rule:
plugin=blockTile
number=45
data:
JSON:{blockState:{blockName:"ancientwarfarestructure:advanced_spawner",properties:{transparent:"true"}},teData:{id:"ancientwarfarestructure:advanced_spawner_tile",spawnerSettings:{minDelay:0,spawnDelay:0,lightSensitive:0b,spawnGroups:[{settingsList:[{remainingSpawnCount:1,hostile:1b,forced:1b,customTag:{factionName:"kong"},maxToSpawn:1,entityId:"ancientwarfarenpc:faction.soldier",minToSpawn:1}],groupWeight:1}],playerRange:5,respondToRedstone:0b,inventory:{Size:9,Items:[]},spawnRange:0,transparent:1b,maxDelay:0,xpToDrop:0,mobRange:0,debugMode:0b,maxNearbyMonsters:0}}}
:enddata
:endrule

rule:
plugin=blockTile
number=46
data:
JSON:{blockState:{blockName:"ancientwarfarestructure:advanced_spawner",properties:{transparent:"true"}},teData:{id:"ancientwarfarestructure:advanced_spawner_tile",spawnerSettings:{minDelay:0,spawnDelay:0,lightSensitive:0b,spawnGroups:[{settingsList:[{remainingSpawnCount:1,hostile:1b,forced:1b,customTag:{factionName:"kong"},maxToSpawn:1,entityId:"ancientwarfarenpc:faction.civilian.female",minToSpawn:1}],groupWeight:1}],playerRange:16,respondToRedstone:0b,inventory:{Size:9,Items:[]},spawnRange:0,transparent:1b,maxDelay:0,xpToDrop:0,mobRange:0,debugMode:0b,maxNearbyMonsters:0}}}
:enddata
:endrule

rule:
plugin=blockTile
number=47
data:
JSON:{blockState:{blockName:"ancientwarfarestructure:advanced_spawner",properties:{transparent:"true"}},teData:{id:"ancientwarfarestructure:advanced_spawner_tile",spawnerSettings:{minDelay:0,spawnDelay:0,lightSensitive:0b,spawnGroups:[{settingsList:[{remainingSpawnCount:1,hostile:1b,forced:1b,customTag:{factionName:"kong"},maxToSpawn:1,entityId:"ancientwarfarenpc:faction.civilian.female",minToSpawn:1}],groupWeight:1}],playerRange:16,respondToRedstone:0b,inventory:{Size:9,Items:[]},spawnRange:0,transparent:1b,maxDelay:0,xpToDrop:0,mobRange:0,debugMode:0b,maxNearbyMonsters:0}}}
:enddata
:endrule

rule:
plugin=blockTile
number=48
data:
JSON:{blockState:{blockName:"ancientwarfarestructure:advanced_spawner",properties:{transparent:"true"}},teData:{id:"ancientwarfarestructure:advanced_spawner_tile",spawnerSettings:{minDelay:0,spawnDelay:0,lightSensitive:0b,spawnGroups:[{settingsList:[{remainingSpawnCount:1,hostile:1b,forced:1b,customTag:{factionName:"kong"},maxToSpawn:1,entityId:"ancientwarfarenpc:faction.leader",minToSpawn:1}],groupWeight:1}],playerRange:4,respondToRedstone:0b,inventory:{Size:9,Items:[]},spawnRange:0,transparent:1b,maxDelay:0,xpToDrop:0,mobRange:0,debugMode:0b,maxNearbyMonsters:0}}}
:enddata
:endrule

rule:
plugin=blockTile
number=49
data:
JSON:{blockState:{blockName:"ancientwarfarestructure:advanced_spawner",properties:{transparent:"true"}},teData:{id:"ancientwarfarestructure:advanced_spawner_tile",spawnerSettings:{minDelay:0,spawnDelay:0,lightSensitive:0b,spawnGroups:[{settingsList:[{remainingSpawnCount:1,hostile:1b,forced:1b,customTag:{factionName:"kong"},maxToSpawn:1,entityId:"ancientwarfarenpc:faction.soldier",minToSpawn:1}],groupWeight:1}],playerRange:1,respondToRedstone:0b,inventory:{Size:9,Items:[]},spawnRange:0,transparent:1b,maxDelay:0,xpToDrop:0,mobRange:0,debugMode:0b,maxNearbyMonsters:0}}}
:enddata
:endrule

rule:
plugin=vanillaBlocks
number=50
data:
JSON:{blockState:{blockName:"minecraft:log",properties:{variant:"jungle",axis:"x"}}}
:enddata
:endrule

rule:
plugin=blockTile
number=51
data:
JSON:{blockState:{blockName:"ancientwarfarestructure:advanced_spawner",properties:{transparent:"true"}},teData:{id:"ancientwarfarestructure:advanced_spawner_tile",spawnerSettings:{minDelay:0,spawnDelay:0,lightSensitive:0b,spawnGroups:[{settingsList:[{remainingSpawnCount:1,hostile:1b,forced:1b,customTag:{factionName:"kong"},maxToSpawn:1,entityId:"ancientwarfarenpc:faction.archer.elite",minToSpawn:1}],groupWeight:1}],playerRange:32,respondToRedstone:0b,inventory:{Size:9,Items:[]},spawnRange:0,transparent:1b,maxDelay:0,xpToDrop:0,mobRange:0,debugMode:0b,maxNearbyMonsters:0}}}
:enddata
:endrule

rule:
plugin=vanillaBlocks
number=52
data:
JSON:{blockState:{blockName:"minecraft:stone_slab",properties:{half:"bottom",variant:"wood_old"}}}
:enddata
:endrule

rule:
plugin=blockTile
number=53
data:
JSON:{blockState:{blockName:"ancientwarfarestructure:advanced_spawner",properties:{transparent:"true"}},teData:{id:"ancientwarfarestructure:advanced_spawner_tile",spawnerSettings:{minDelay:0,spawnDelay:0,lightSensitive:0b,spawnGroups:[{settingsList:[{remainingSpawnCount:1,hostile:1b,forced:1b,customTag:{factionName:"kong"},maxToSpawn:1,entityId:"ancientwarfarenpc:faction.archer.elite",minToSpawn:1}],groupWeight:1}],playerRange:32,respondToRedstone:0b,inventory:{Size:9,Items:[]},spawnRange:0,transparent:1b,maxDelay:0,xpToDrop:0,mobRange:0,debugMode:0b,maxNearbyMonsters:0}}}
:enddata
:endrule

rule:
plugin=vanillaBlocks
number=54
data:
JSON:{blockState:{blockName:"minecraft:leaves",properties:{check_decay:"false",decayable:"false",variant:"jungle"}}}
:enddata
:endrule

rule:
plugin=vanillaBlocks
number=55
data:
JSON:{blockState:{blockName:"minecraft:torch",properties:{facing:"west"}}}
:enddata
:endrule

#### ENTITIES ####
