# Ancient Warfare Structure Template File
# Auto-generated structure template file. created on: 11/18/2018 at: 19:56:36
# Lines beginning with # denote comments

header:
version=2.7
name=KongJungleWizardsTower
mods=
size=24,80,37
offset=11,5,36
:endheader

#### VALIDATION ####
validation:
type=ground
survival=false
worldGenEnabled=true
unique=false
preserveBlocks=false
selectionWeight=30
clusterValue=60
minDuplicateDistance=1000
dimensionWhiteList=false
dimensionList=
biomeWhiteList=true
biomeList=minecraft:jungle
leveling=12
fill=4
border=8
blockSwap=false
data:
:enddata
:endvalidation

#### LAYERS ####
layer: 0
1,1,1,1,1,1,1,1,1,1,1,1,1,1,1,1,1,1,1,1,1,1,1,1
1,1,1,1,1,1,1,1,1,1,1,1,1,1,1,1,1,1,1,1,1,1,1,1
1,1,1,1,1,1,1,1,1,1,1,1,1,1,1,1,1,1,1,1,1,1,1,1
1,1,1,1,1,1,1,1,1,1,1,1,1,1,1,1,1,1,1,1,1,1,1,1
1,1,1,1,1,1,1,1,1,1,1,1,1,1,1,1,1,1,1,1,1,1,1,1
1,1,1,1,1,1,1,1,1,1,1,1,1,1,1,1,1,1,1,1,1,1,1,1
1,1,1,1,1,1,1,1,1,1,1,1,1,1,1,1,1,1,1,1,1,1,1,1
1,1,1,1,1,1,1,1,1,1,1,1,1,1,1,1,1,1,1,1,1,1,1,1
1,1,1,1,1,1,1,1,1,1,1,1,1,1,1,1,1,1,1,1,1,1,1,1
1,1,1,1,1,1,1,1,1,1,1,1,1,1,1,1,1,1,1,1,1,1,1,1
1,1,1,1,1,1,1,1,1,1,1,1,1,1,1,1,1,1,1,1,1,1,1,1
1,1,1,1,1,1,1,1,1,1,1,1,1,1,1,1,1,1,1,1,1,1,1,1
1,1,1,1,1,1,1,1,1,1,1,1,1,1,1,1,1,1,1,1,1,1,1,1
1,1,1,1,1,1,1,1,1,1,1,1,1,1,1,1,1,1,1,1,1,1,1,1
1,1,1,1,1,1,1,1,1,1,1,1,1,1,1,1,1,1,1,1,1,1,1,1
1,1,1,1,1,1,1,1,1,1,1,1,1,1,1,1,1,1,1,1,1,1,1,1
1,1,1,1,1,1,1,1,1,1,1,1,1,1,1,1,1,1,1,1,1,1,1,1
1,1,1,1,1,1,1,1,1,1,1,1,1,1,1,1,1,1,1,1,1,1,1,1
1,1,1,1,1,1,1,1,1,1,1,1,1,1,1,1,1,1,1,1,1,1,1,1
1,1,1,1,1,1,1,1,1,1,1,1,1,1,1,1,1,1,1,1,1,1,1,1
1,1,1,1,1,1,1,1,1,1,1,1,1,1,1,1,1,1,1,1,1,1,1,1
1,1,1,1,1,1,1,1,1,1,1,1,1,1,1,1,1,1,1,1,1,1,1,1
1,1,1,1,1,1,1,1,1,1,1,1,1,1,1,1,1,1,1,1,1,1,1,1
1,1,1,1,1,1,1,1,1,1,1,1,1,1,1,1,1,1,1,1,1,1,1,1
1,1,1,1,1,1,1,1,1,1,1,1,1,1,1,1,1,1,1,1,1,1,1,1
1,1,1,1,1,1,1,1,1,1,1,1,1,1,1,1,1,1,1,1,1,1,1,1
1,1,1,1,1,1,1,1,1,1,1,1,1,1,1,1,1,1,1,1,1,1,1,1
1,1,1,1,1,1,1,1,1,1,1,1,1,1,1,1,1,1,1,1,1,1,1,1
1,1,1,1,1,1,1,1,1,1,1,1,1,1,1,1,1,1,1,1,1,1,1,1
1,1,1,1,1,1,1,1,1,1,1,1,1,1,1,1,1,1,1,1,1,1,1,1
1,1,1,1,1,1,1,1,1,1,1,1,1,1,1,1,1,1,1,1,1,1,1,1
1,1,1,1,1,1,1,1,1,1,1,1,1,1,1,1,1,1,1,1,1,1,1,1
1,1,1,1,1,1,1,1,1,1,1,1,1,1,1,1,1,1,1,1,1,1,1,1
1,1,1,1,1,1,1,1,1,1,1,1,1,1,1,1,1,1,1,1,1,1,1,1
1,1,1,1,1,1,1,1,1,1,1,1,1,1,1,1,1,1,1,1,1,1,1,1
1,1,1,1,1,1,1,1,1,1,1,1,1,1,1,1,1,1,1,1,1,1,1,1
1,1,1,1,1,1,1,1,1,1,1,1,1,1,1,1,1,1,1,1,1,1,1,1
:endlayer
layer: 1
1,1,1,1,1,1,1,1,1,1,1,1,1,1,1,1,1,1,1,1,1,1,1,1
1,1,1,1,1,1,1,1,1,1,1,1,1,1,1,1,1,1,1,1,1,1,1,1
1,1,1,1,1,1,1,1,1,1,1,1,1,1,1,1,1,1,1,1,1,1,1,1
1,1,1,1,1,1,1,1,1,1,1,1,1,1,1,1,1,1,1,1,1,1,1,1
1,1,1,1,1,1,1,1,1,1,1,1,1,1,1,1,1,1,1,1,1,1,1,1
1,1,1,1,1,1,1,1,1,1,1,1,1,1,1,1,1,1,1,1,1,1,1,1
1,1,1,1,1,1,1,1,1,1,1,1,1,1,1,1,1,1,1,1,1,1,1,1
1,1,1,1,1,1,1,1,1,1,1,1,1,1,1,1,1,1,1,1,1,1,1,1
1,1,1,1,1,1,1,1,1,1,1,1,1,1,1,1,1,1,1,1,1,1,1,1
1,1,1,1,1,1,1,1,1,1,1,1,1,1,1,1,1,1,1,1,1,1,1,1
1,1,1,1,1,1,1,1,1,1,1,1,1,1,1,1,1,1,1,1,1,1,1,1
1,1,1,1,1,1,1,1,1,1,1,1,1,1,1,1,1,1,1,1,1,1,1,1
1,1,1,1,1,1,1,1,1,1,1,1,1,1,1,1,1,1,1,1,1,1,1,1
1,1,1,1,1,1,1,1,1,1,1,1,1,1,1,1,1,1,1,1,1,1,1,1
1,1,1,1,1,1,1,1,1,1,1,1,1,1,1,1,1,1,1,1,1,1,1,1
1,1,1,1,1,1,1,1,1,1,1,1,1,1,1,1,1,1,1,1,1,1,1,1
1,1,1,1,1,1,1,1,1,1,1,1,1,1,1,1,1,1,1,1,1,1,1,1
1,1,1,1,1,1,1,1,1,1,1,1,1,1,1,1,1,1,1,1,1,1,1,1
1,1,1,1,1,1,1,1,1,1,1,1,1,1,1,1,1,1,1,1,1,1,1,1
1,1,1,1,1,1,1,1,1,1,1,1,1,1,1,1,1,1,1,1,1,1,1,1
1,1,1,1,1,1,1,1,1,1,1,1,1,1,1,1,1,1,1,1,1,1,1,1
1,1,1,1,1,1,1,1,1,1,1,1,1,1,1,1,1,1,1,1,1,1,1,1
1,1,1,1,1,1,1,1,1,1,1,1,1,1,1,1,1,1,1,1,1,1,1,1
1,1,1,1,1,1,1,1,1,1,1,1,1,1,1,1,1,1,1,1,1,1,1,1
1,1,1,1,1,1,1,1,1,1,1,1,1,1,1,1,1,1,1,1,1,1,1,1
1,1,1,1,1,1,1,1,1,1,1,1,1,1,1,1,1,1,1,1,1,1,1,1
1,1,1,1,1,1,1,1,1,1,1,1,1,1,1,1,1,1,1,1,1,1,1,1
1,1,1,1,1,1,1,1,1,1,1,1,1,1,1,1,1,1,1,1,1,1,1,1
1,1,1,1,1,1,1,1,1,1,1,1,1,1,1,1,1,1,1,1,1,1,1,1
1,1,1,1,1,1,1,1,1,1,1,1,1,1,1,1,1,1,1,1,1,1,1,1
1,1,1,1,1,1,1,1,1,1,1,1,1,1,1,1,1,1,1,1,1,1,1,1
1,1,1,1,1,1,1,1,1,1,1,1,1,1,1,1,1,1,1,1,1,1,1,1
1,1,1,1,1,1,1,1,1,1,1,1,1,1,1,1,1,1,1,1,1,1,1,1
1,1,1,1,1,1,1,1,1,1,1,1,1,1,1,1,1,1,1,1,1,1,1,1
1,1,1,1,1,1,1,1,1,1,1,1,1,1,1,1,1,1,1,1,1,1,1,1
1,1,1,1,1,1,1,1,1,1,1,1,1,1,1,1,1,1,1,1,1,1,1,1
1,1,1,1,1,1,1,1,1,1,1,1,1,1,1,1,1,1,1,1,1,1,1,1
:endlayer
layer: 2
1,1,1,1,1,1,1,1,1,1,1,1,1,1,1,1,1,1,1,1,1,1,1,1
1,2,2,2,2,2,2,2,2,2,2,2,2,2,2,2,2,2,2,2,2,2,2,1
1,2,2,2,2,2,2,2,2,2,2,2,2,2,2,2,2,2,2,2,2,2,2,1
1,2,2,2,2,1,1,1,1,1,1,1,1,1,1,1,1,1,1,2,2,2,2,1
1,2,2,2,2,1,1,1,1,1,1,1,1,1,1,1,1,1,1,2,2,2,2,1
1,2,2,2,2,1,1,1,1,1,1,1,1,1,1,1,1,1,1,2,2,2,2,1
1,2,2,2,2,1,1,1,1,1,1,1,1,1,1,1,1,1,1,2,2,2,2,1
1,2,2,2,2,1,1,1,1,1,1,1,1,1,1,1,1,1,1,2,2,2,2,1
1,2,2,2,2,1,1,1,1,1,1,1,1,1,1,1,1,1,1,2,2,2,2,1
1,2,2,2,2,1,1,1,1,1,1,1,1,1,1,1,1,1,1,2,2,2,2,1
1,2,2,2,2,1,1,1,1,1,1,1,1,1,1,1,1,1,1,2,2,2,2,1
1,2,2,2,2,1,1,1,1,1,1,1,1,1,1,1,1,1,1,2,2,2,2,1
1,2,2,2,2,1,1,1,1,1,1,1,1,1,1,1,1,1,1,2,2,2,2,1
1,2,2,2,2,1,1,1,1,1,1,1,1,1,1,1,1,1,1,2,2,2,2,1
1,2,2,2,2,1,1,1,1,1,1,1,1,1,1,1,1,1,1,2,2,2,2,1
1,2,2,2,2,1,1,1,1,1,1,1,1,1,1,1,1,1,1,2,2,2,2,1
1,2,2,2,2,2,2,2,2,2,2,2,2,2,2,2,2,2,2,2,2,2,2,1
1,2,2,2,2,2,2,2,2,2,2,2,2,2,2,2,2,2,2,2,2,2,2,1
1,2,2,2,2,2,2,2,2,2,2,2,2,2,2,2,2,2,2,2,2,2,2,1
1,2,2,2,2,2,2,2,2,2,2,2,2,2,2,2,2,2,2,2,2,2,2,1
1,2,2,2,2,2,2,2,2,2,2,2,2,2,2,2,2,2,2,2,2,2,2,1
1,2,2,2,2,2,2,2,2,2,2,2,2,2,2,2,2,2,2,2,2,2,2,1
1,2,2,2,2,2,2,2,2,2,2,2,2,2,2,2,2,2,2,2,2,2,2,1
1,1,1,1,1,1,1,1,1,1,1,1,1,1,1,1,1,1,1,1,1,1,1,1
1,1,1,1,1,1,1,1,1,1,1,1,1,1,1,1,1,1,1,1,1,1,1,1
1,1,1,1,1,1,1,1,1,1,1,1,1,1,1,1,1,1,1,1,1,1,1,1
1,1,1,1,1,1,1,1,1,1,1,1,1,1,1,1,1,1,1,1,1,1,1,1
1,1,1,1,1,1,1,1,1,1,1,1,1,1,1,1,1,1,1,1,1,1,1,1
1,1,1,1,1,1,1,1,1,1,1,1,1,1,1,1,1,1,1,1,1,1,1,1
1,1,1,1,1,1,1,1,1,1,1,1,1,1,1,1,1,1,1,1,1,1,1,1
1,1,1,1,1,1,1,1,1,1,1,1,1,1,1,1,1,1,1,1,1,1,1,1
1,1,1,1,1,1,1,1,1,1,1,1,1,1,1,1,1,1,1,1,1,1,1,1
1,1,1,1,1,1,1,1,1,1,1,1,1,1,1,1,1,1,1,1,1,1,1,1
1,1,1,1,1,1,1,1,1,1,1,1,1,1,1,1,1,1,1,1,1,1,1,1
1,1,1,1,1,1,1,1,1,1,1,1,1,1,1,1,1,1,1,1,1,1,1,1
1,1,1,1,1,1,1,1,1,1,1,1,1,1,1,1,1,1,1,1,1,1,1,1
1,1,1,1,1,1,1,1,1,1,1,1,1,1,1,1,1,1,1,1,1,1,1,1
:endlayer
layer: 3
1,1,1,1,1,1,1,1,1,1,1,1,1,1,1,1,1,1,1,1,1,1,1,1
1,3,3,3,3,3,3,3,3,3,3,3,3,3,3,4,3,3,3,3,3,3,3,1
1,3,4,4,4,4,4,4,4,4,4,4,4,4,4,3,4,3,4,4,4,4,3,1
1,3,4,5,5,6,6,6,6,6,6,6,6,6,6,6,6,6,6,5,5,4,3,1
1,3,4,5,7,6,6,6,6,6,6,6,6,6,6,6,6,6,6,7,5,4,3,1
1,3,4,5,7,6,6,1,1,1,1,1,1,1,1,1,6,6,6,5,5,4,3,1
1,3,4,5,7,6,6,1,1,1,1,1,1,1,1,1,6,6,6,4,5,4,3,1
1,3,4,5,5,6,6,1,1,1,1,1,1,1,1,1,6,6,6,3,4,4,3,1
1,3,4,5,4,6,6,1,1,1,1,1,1,1,1,1,6,6,6,3,4,4,3,1
1,4,5,4,3,6,6,1,1,1,1,1,1,1,1,1,6,6,6,3,4,4,3,1
1,3,4,5,4,6,6,1,1,1,1,1,1,1,1,1,6,6,6,3,4,4,3,1
1,3,4,5,5,6,6,1,1,1,1,1,1,1,1,1,6,6,6,3,4,4,3,1
1,3,4,5,4,6,6,1,1,1,1,1,1,1,1,1,6,6,6,3,4,4,3,1
1,3,4,4,3,6,6,1,1,1,1,1,1,1,1,1,6,6,6,4,5,4,3,1
1,3,4,5,4,6,6,6,6,6,6,6,6,6,6,6,6,6,6,5,5,5,4,1
1,3,4,5,5,6,6,6,6,6,6,6,6,6,6,6,6,6,6,4,4,4,4,1
1,3,4,5,4,3,3,3,3,3,3,3,3,3,3,3,3,4,3,3,3,3,3,1
1,3,4,5,4,3,3,4,4,4,4,4,4,4,4,4,4,5,4,4,4,4,3,1
1,3,4,5,4,3,3,4,5,5,5,5,5,5,5,5,5,7,5,5,5,4,3,1
1,3,4,5,5,4,4,5,7,7,7,7,7,7,7,7,7,7,7,7,5,4,3,1
1,3,4,5,5,5,5,5,5,5,5,5,5,5,5,5,5,5,5,5,5,4,3,1
1,3,3,4,4,4,4,4,4,4,4,4,4,4,4,4,4,4,4,4,4,4,3,1
1,3,3,3,3,3,3,3,3,3,3,3,3,3,3,3,3,3,3,3,3,3,3,1
1,1,1,1,1,1,1,1,1,1,1,1,1,1,1,1,1,1,1,1,1,1,1,1
1,1,1,1,1,1,1,1,1,1,1,1,1,1,1,1,1,1,1,1,1,1,1,1
1,1,1,1,1,1,1,1,1,1,1,1,1,1,1,1,1,1,1,1,1,1,1,1
1,1,1,1,1,1,1,1,1,1,1,2,2,1,1,1,1,1,1,1,1,1,1,1
1,1,1,1,1,1,1,1,1,1,2,2,2,2,1,1,1,1,1,1,1,1,1,1
1,1,1,1,1,1,1,1,1,1,1,1,1,1,1,1,1,1,1,1,1,1,1,1
1,1,1,1,1,1,1,1,1,1,1,1,2,1,1,1,1,1,1,1,1,1,1,1
1,1,1,1,1,1,1,1,1,1,1,1,1,1,1,1,1,1,1,1,1,1,1,1
1,1,1,1,1,1,1,1,1,1,1,1,1,1,1,1,1,1,1,1,1,1,1,1
1,1,1,1,1,1,1,1,1,1,1,1,1,1,1,1,1,1,1,1,1,1,1,1
1,1,1,1,1,1,1,1,1,1,1,1,1,1,1,1,1,1,1,1,1,1,1,1
1,1,1,1,1,1,1,1,1,1,1,1,1,1,1,1,1,1,1,1,1,1,1,1
1,1,1,1,1,1,1,1,1,1,1,1,1,1,1,1,1,1,1,1,1,1,1,1
1,1,1,1,1,1,1,1,1,1,1,1,1,1,1,1,1,1,1,1,1,1,1,1
:endlayer
layer: 4
2,2,2,2,2,2,2,2,2,2,2,2,2,2,2,2,2,2,2,2,2,2,2,2
2,0,0,0,0,0,0,0,0,0,0,0,0,0,0,0,0,0,0,0,0,0,0,2
2,0,0,0,8,8,8,8,8,8,8,8,8,8,8,8,8,8,8,8,0,0,0,2
2,0,0,0,8,6,6,6,6,6,6,6,6,6,6,6,6,6,6,8,0,0,0,2
2,0,0,0,8,6,6,6,6,6,6,6,6,6,6,6,6,6,6,8,0,0,0,2
2,0,0,0,8,6,6,1,1,1,9,6,9,6,1,1,6,6,6,8,0,0,0,2
2,0,0,0,8,6,6,6,1,1,6,6,10,6,1,1,6,6,6,8,0,0,0,2
2,0,0,0,8,6,6,6,9,6,9,9,6,9,6,10,6,6,6,8,0,0,0,2
2,0,0,0,8,6,6,6,9,6,6,6,10,6,6,9,6,6,6,8,0,0,0,2
2,0,0,0,8,6,6,6,10,6,10,6,6,10,6,6,6,6,6,8,0,0,0,2
2,0,0,0,8,6,6,6,6,6,6,6,9,10,6,10,6,6,6,8,0,0,0,2
2,0,0,0,8,6,6,6,1,1,6,6,6,6,1,1,6,6,6,8,0,0,0,2
2,0,0,0,8,6,6,1,1,1,10,10,6,6,1,1,6,6,6,8,0,0,0,2
2,0,0,0,8,6,6,1,1,6,6,6,6,6,6,1,6,6,6,8,0,0,0,2
2,0,0,0,8,6,6,6,6,6,6,6,6,6,6,6,6,6,6,8,0,0,0,2
2,0,0,0,8,6,6,6,6,6,6,6,6,6,6,6,6,6,6,8,0,0,0,2
2,0,0,0,8,8,8,8,8,8,8,8,8,8,8,8,8,8,8,8,0,0,0,2
2,0,0,0,0,0,0,0,0,0,0,0,0,0,0,0,0,0,0,0,0,0,0,2
2,0,0,0,0,0,0,0,0,0,0,0,0,0,0,0,0,0,0,0,0,0,0,2
2,0,0,0,0,0,0,0,0,0,0,0,0,0,0,0,0,0,0,0,0,0,0,2
2,0,0,0,0,0,0,0,0,0,0,0,0,0,0,0,0,0,0,0,0,0,0,2
2,0,0,0,0,0,0,0,0,0,0,0,0,0,0,0,0,0,0,0,0,0,0,2
2,0,0,0,0,0,0,0,0,0,0,0,0,0,0,0,0,0,0,0,0,0,0,2
2,2,2,2,2,2,2,2,2,2,2,2,2,2,2,2,2,2,2,2,2,2,2,2
2,2,2,2,2,2,2,2,2,2,2,6,6,2,2,2,2,2,2,2,2,2,2,2
2,2,2,2,2,2,2,2,2,2,6,6,6,6,2,2,2,2,2,2,2,2,2,2
2,2,2,2,2,2,2,2,2,6,6,0,0,6,6,2,2,2,2,2,2,2,2,2
2,2,2,2,2,2,2,6,6,6,0,0,0,0,6,6,6,2,2,2,2,2,2,2
2,2,2,2,2,2,2,6,6,2,6,6,6,6,2,6,6,2,2,2,2,2,2,2
2,2,2,2,2,2,6,6,2,2,6,6,0,6,2,2,6,6,2,2,2,2,2,2
2,2,2,2,2,2,6,6,2,2,6,6,6,6,2,2,6,6,2,2,2,2,2,2
2,2,2,2,2,2,2,6,6,2,6,6,6,6,2,6,6,2,2,2,2,2,2,2
2,2,2,2,2,2,2,6,6,2,2,6,6,2,2,6,6,2,2,2,2,2,2,2
2,2,2,2,2,2,2,2,2,2,2,6,6,2,2,2,2,2,2,2,2,2,2,2
2,2,2,2,2,2,2,2,2,2,2,6,6,2,2,2,2,2,2,2,2,2,2,2
2,2,2,2,2,2,2,2,2,2,2,6,6,2,2,2,2,2,2,2,2,2,2,2
2,2,2,2,2,2,2,2,2,2,2,6,6,2,2,2,2,2,2,2,2,2,2,2
:endlayer
layer: 5
0,0,0,0,0,0,0,0,0,0,0,0,0,0,0,0,0,0,0,0,0,0,0,0
0,0,0,0,0,0,0,0,0,0,0,0,0,0,0,0,0,0,0,0,0,0,0,0
0,0,0,0,8,0,0,0,0,0,0,0,0,0,0,0,0,0,0,8,0,0,0,0
0,0,0,0,0,0,0,6,0,0,0,0,0,0,0,0,6,0,0,0,0,0,0,0
0,0,0,0,0,0,6,6,6,0,0,0,0,0,0,6,6,6,0,0,0,0,0,0
0,0,0,0,0,0,11,6,6,6,0,0,0,0,6,6,6,0,0,0,0,0,0,0
0,0,0,0,0,0,0,0,6,6,0,12,0,0,6,6,0,0,0,0,0,0,0,0
0,0,0,0,0,0,0,0,0,0,13,13,13,13,0,0,0,0,0,0,0,0,0,0
0,0,0,0,0,0,0,0,0,0,13,0,0,13,14,0,0,0,0,0,0,0,0,0
0,0,0,0,0,0,0,0,0,15,13,0,0,13,0,0,0,0,0,0,0,0,0,0
0,0,0,0,0,0,0,0,0,0,13,13,13,13,0,0,0,0,0,0,0,0,0,0
0,0,0,0,0,0,0,0,6,6,0,0,16,0,6,6,0,17,0,0,0,0,0,0
0,0,0,0,0,0,0,6,6,6,0,0,0,0,6,6,6,0,0,0,0,0,0,0
0,0,0,0,0,0,6,6,6,0,0,0,0,0,0,6,6,6,0,0,0,0,0,0
0,0,0,0,0,0,0,6,0,0,0,18,0,0,0,0,6,0,0,0,0,0,0,0
0,0,0,0,0,0,0,0,0,0,0,0,0,0,0,0,0,0,0,0,0,0,0,0
0,0,0,0,8,0,0,0,0,0,0,0,0,0,0,0,0,0,0,8,0,0,0,0
0,0,0,0,0,0,0,0,0,0,0,0,0,0,0,0,0,0,0,0,0,0,0,0
0,0,0,0,0,0,0,0,0,0,0,0,0,0,0,0,0,0,0,0,0,0,0,0
0,0,0,0,0,0,0,0,0,0,0,0,0,0,0,0,0,0,0,0,0,0,0,0
0,0,0,0,0,0,0,0,0,0,0,0,0,0,0,0,0,0,0,0,0,0,0,0
0,0,0,0,0,0,0,0,0,0,0,0,0,0,0,0,0,0,0,0,0,0,0,0
0,0,0,0,0,0,0,0,0,0,0,0,0,0,0,0,0,0,0,0,0,0,0,0
0,0,0,0,0,0,0,0,0,0,0,0,0,0,0,0,0,0,0,0,0,0,0,0
0,0,0,0,0,0,0,0,0,0,0,6,6,0,0,0,0,0,0,0,0,0,0,0
19,19,0,19,19,19,0,0,0,0,6,6,6,6,0,19,0,0,0,0,0,0,0,19
19,19,19,19,0,19,19,19,19,6,6,0,0,6,6,0,0,0,0,0,0,0,0,0
19,19,19,19,19,19,0,0,6,6,0,0,0,0,6,6,0,0,0,0,0,19,0,0
19,19,19,19,19,0,19,6,6,20,6,6,6,6,21,6,6,0,0,19,0,19,0,0
19,19,19,0,19,0,6,6,22,23,6,6,24,6,25,26,6,6,0,0,0,19,0,0
0,0,19,0,0,0,6,6,27,28,6,0,0,6,29,30,6,6,0,19,0,0,0,19
0,0,19,0,0,0,0,6,6,19,6,0,0,6,0,6,6,0,19,19,19,0,0,0
19,19,19,0,0,0,0,0,6,0,0,0,0,0,19,6,0,0,19,19,19,19,0,0
19,19,19,19,0,0,19,0,0,19,19,0,0,19,19,19,0,19,0,19,19,19,19,0
0,19,19,19,0,0,0,19,19,19,0,0,0,19,19,0,19,0,19,19,19,19,19,0
19,19,19,19,19,19,19,0,19,19,0,0,0,19,19,19,19,0,0,19,19,0,0,0
0,0,19,19,0,0,0,19,0,19,19,0,0,19,19,19,19,0,0,0,0,19,19,0
:endlayer
layer: 6
0,0,0,0,0,0,0,0,0,0,0,0,0,0,0,0,0,0,0,0,0,0,0,0
0,0,0,0,0,0,0,0,0,0,0,0,0,0,0,0,0,0,0,0,0,0,0,0
0,0,0,0,0,0,0,0,0,0,0,0,0,0,0,0,0,0,0,0,0,0,0,0
0,0,0,0,0,0,0,0,0,0,0,0,0,0,0,31,31,0,0,0,0,0,0,0
0,0,0,0,0,0,0,6,0,0,0,0,0,0,0,11,6,17,0,0,0,0,0,0
0,0,0,0,0,0,11,0,6,0,0,0,0,0,0,6,32,0,0,0,0,0,0,0
0,0,0,0,0,0,0,0,0,6,0,0,0,0,6,32,0,0,0,0,0,0,0,0
0,0,0,0,0,0,0,0,0,0,13,13,13,13,0,0,0,0,0,0,0,0,0,0
0,0,0,0,0,0,0,0,0,0,13,0,0,13,0,0,0,0,0,0,0,0,0,0
0,0,0,0,0,0,0,0,0,0,13,0,0,13,0,0,0,0,0,0,0,0,0,0
0,0,0,0,0,0,0,0,0,0,13,13,13,13,0,0,0,0,0,0,0,0,0,0
0,0,0,0,0,0,0,0,0,6,0,0,0,0,6,32,0,17,0,0,0,0,0,0
0,0,0,0,0,0,0,0,6,32,0,0,0,0,0,6,32,0,0,0,0,0,0,0
0,0,0,0,0,0,0,6,32,0,0,0,0,0,0,33,6,17,0,0,0,0,0,0
0,0,0,0,0,0,0,0,0,0,0,18,0,0,0,0,18,0,0,0,0,0,0,0
0,0,0,0,0,0,0,0,0,0,0,0,0,0,0,0,0,0,0,0,0,0,0,0
0,0,0,0,0,0,0,0,0,0,0,0,0,0,0,0,0,0,0,0,0,0,0,0
0,0,0,0,0,0,0,0,0,0,0,0,0,0,0,0,0,0,0,0,0,0,0,0
0,0,0,0,0,0,0,0,0,0,0,0,0,0,0,0,0,0,0,0,0,0,0,0
0,0,0,0,0,0,0,0,0,0,0,0,0,0,0,0,0,0,0,0,0,0,0,0
0,0,0,0,0,0,0,0,0,0,0,0,0,0,0,0,0,0,0,0,0,0,0,0
0,0,0,0,0,0,0,0,0,0,0,0,0,0,0,0,0,0,0,0,0,0,0,0
0,0,0,0,0,0,0,0,0,0,0,0,0,0,0,0,0,0,0,0,0,0,0,0
0,0,0,0,0,0,0,0,0,0,0,0,0,0,0,0,0,0,0,0,0,0,0,0
0,0,0,0,0,0,0,0,0,0,0,6,6,0,0,0,0,0,0,0,0,0,0,0
0,0,0,0,0,0,0,0,0,0,6,6,6,6,0,0,0,0,0,0,0,0,0,0
0,0,0,0,0,0,0,0,0,6,6,0,0,6,6,0,0,0,0,0,0,0,0,0
0,0,0,0,0,0,0,0,6,6,0,0,0,0,6,6,0,0,0,0,0,0,0,0
0,0,0,0,0,0,0,6,6,0,6,6,6,6,0,6,6,0,0,0,0,0,0,0
0,0,0,0,0,0,6,6,0,0,6,34,0,6,0,0,6,6,0,0,0,0,0,0
0,0,0,0,0,0,6,6,0,0,6,0,0,6,0,0,6,6,0,0,0,0,0,0
0,0,0,0,0,0,0,6,6,0,6,0,0,6,0,6,6,0,0,0,0,0,0,0
0,0,0,0,0,0,0,0,6,0,35,0,0,35,0,6,0,0,0,0,0,0,0,0
0,0,0,0,0,0,0,0,0,0,0,0,0,0,0,0,0,0,0,0,0,0,0,0
0,0,0,0,0,0,0,0,0,0,0,0,0,0,0,0,0,0,0,0,0,0,0,0
0,0,0,0,0,0,0,0,0,0,0,0,0,0,0,0,0,0,0,0,0,0,0,0
0,0,0,0,0,0,0,0,0,0,0,0,0,0,0,0,0,0,0,0,0,0,0,0
:endlayer
layer: 7
0,0,0,0,0,0,0,0,0,0,0,0,0,0,0,0,0,0,0,0,0,0,0,0
0,0,0,0,0,0,0,0,0,0,0,0,0,0,0,0,0,0,0,0,0,0,0,0
0,0,0,0,0,0,0,0,0,0,0,0,0,0,0,0,0,0,0,0,0,0,0,0
0,0,0,0,0,0,0,0,0,0,0,0,0,0,0,31,31,0,0,0,0,0,0,0
0,0,0,0,0,0,0,6,0,0,0,0,0,0,0,11,6,17,0,0,0,0,0,0
0,0,0,0,0,0,11,0,6,0,0,0,0,0,0,6,32,0,0,0,0,0,0,0
0,0,0,0,0,0,0,0,0,6,36,0,0,37,6,32,0,0,0,0,0,0,0,0
0,0,0,0,0,0,0,0,0,35,13,13,13,13,35,0,0,0,0,0,0,0,0,0
0,0,0,0,0,0,0,0,0,0,13,0,0,13,0,0,0,0,0,0,0,0,0,0
0,0,0,0,0,0,0,0,0,0,13,0,0,13,0,0,0,0,0,0,0,0,0,0
0,0,0,0,0,0,0,0,0,38,13,13,13,13,38,0,0,0,0,0,0,0,0,0
0,0,0,0,0,0,0,0,0,6,36,0,0,37,6,32,0,17,0,0,0,0,0,0
0,0,0,0,0,0,0,0,6,32,0,0,0,0,0,6,32,0,0,0,0,0,0,0
0,0,0,0,0,0,0,6,32,0,0,0,0,0,0,33,6,17,0,0,0,0,0,0
0,0,0,0,0,0,0,0,0,0,0,18,0,0,0,0,18,0,0,0,0,0,0,0
0,0,0,0,0,0,0,0,0,0,0,0,0,0,0,0,0,0,0,0,0,0,0,0
0,0,0,0,0,0,0,0,0,0,0,0,0,0,0,0,0,0,0,0,0,0,0,0
0,0,0,0,0,0,0,0,0,0,0,0,0,0,0,0,0,0,0,0,0,0,0,0
0,0,0,0,0,0,0,0,0,0,0,0,0,0,0,0,0,0,0,0,0,0,0,0
0,0,0,0,0,0,0,0,0,0,0,0,0,0,0,0,0,0,0,0,0,0,0,0
0,0,0,0,0,0,0,0,0,0,0,0,0,0,0,0,0,0,0,0,0,0,0,0
0,0,0,0,0,0,0,0,0,0,0,0,0,0,0,0,0,0,0,0,0,0,0,0
0,0,0,0,0,0,0,0,0,0,0,0,0,0,0,0,0,0,0,0,0,0,0,0
0,0,0,0,0,0,0,0,0,0,0,0,0,0,0,0,0,0,0,0,0,0,0,0
0,0,0,0,0,0,0,0,0,0,0,6,6,0,0,0,0,0,0,0,0,0,0,0
0,0,0,0,0,0,0,0,0,0,6,6,6,6,0,0,0,0,0,0,0,0,0,0
0,0,0,0,0,0,0,0,0,6,6,0,0,6,6,0,0,0,0,0,0,0,0,0
0,0,0,0,0,0,0,0,39,6,38,0,0,38,6,39,0,0,0,0,0,0,0,0
0,0,0,0,0,0,0,39,6,0,6,6,6,6,0,6,39,0,0,0,0,0,0,0
0,0,0,0,0,0,6,6,0,0,6,0,0,6,0,0,6,6,0,0,0,0,0,0
0,0,0,0,0,0,6,6,0,0,6,40,0,6,0,0,6,6,0,0,0,0,0,0
0,0,0,0,0,0,0,39,6,0,6,6,6,6,0,6,39,0,0,0,0,0,0,0
0,0,0,0,0,0,0,0,39,0,0,0,0,0,0,39,0,0,0,0,0,0,0,0
0,0,0,0,0,0,0,0,0,0,0,0,0,0,0,0,0,0,0,0,0,0,0,0
0,0,0,0,0,0,0,0,0,0,0,0,0,0,0,0,0,0,0,0,0,0,0,0
0,0,0,0,0,0,0,0,0,0,0,0,0,0,0,0,0,0,0,0,0,0,0,0
0,0,0,0,0,0,0,0,0,0,0,0,0,0,0,0,0,0,0,0,0,0,0,0
:endlayer
layer: 8
0,0,0,0,0,0,0,0,0,0,0,0,0,0,0,0,0,0,0,0,0,0,0,0
0,0,0,0,0,0,0,0,0,0,0,0,0,0,0,0,0,0,0,0,0,0,0,0
0,0,0,0,0,0,0,0,0,0,0,0,0,0,0,0,0,0,0,0,0,0,0,0
0,0,0,0,0,0,0,0,0,0,0,0,0,0,0,31,31,0,0,0,0,0,0,0
0,0,0,0,0,0,0,6,0,0,0,0,0,0,0,33,6,17,0,0,0,0,0,0
0,0,0,0,0,0,11,0,6,0,0,0,0,0,0,6,32,0,0,0,0,0,0,0
0,0,0,0,0,0,33,0,0,6,32,32,32,32,6,32,0,0,0,0,0,0,0,0
0,0,0,0,0,0,0,0,0,32,13,13,13,13,32,0,0,0,0,0,0,0,0,0
0,0,0,0,0,0,0,0,0,32,13,0,0,13,32,0,0,0,0,0,0,0,0,0
0,0,0,0,0,0,0,0,0,32,13,0,0,13,32,0,0,0,0,0,0,0,0,0
0,0,0,0,0,0,0,0,0,32,13,13,13,13,32,0,0,0,0,0,0,0,0,0
0,0,0,0,0,0,0,0,0,6,32,32,32,32,6,32,0,17,0,0,0,0,0,0
0,0,0,0,0,0,0,0,6,32,0,0,0,0,0,6,32,0,0,0,0,0,0,0
0,0,0,0,0,0,0,6,32,0,0,0,0,0,0,33,6,17,0,0,0,0,0,0
0,0,0,0,0,0,0,0,0,0,0,18,0,0,0,0,18,0,0,0,0,0,0,0
0,0,0,0,0,0,0,0,0,0,0,0,0,0,0,0,0,0,0,0,0,0,0,0
0,0,0,0,0,0,0,0,0,0,0,0,0,0,0,0,0,0,0,0,0,0,0,0
0,0,0,0,0,0,0,0,0,0,0,0,0,0,0,0,0,0,0,0,0,0,0,0
0,0,0,0,0,0,0,0,0,0,0,0,0,0,0,0,0,0,0,0,0,0,0,0
0,0,0,0,0,0,0,0,0,0,0,0,0,0,0,0,0,0,0,0,0,0,0,0
0,0,0,0,0,0,0,0,0,0,0,0,0,0,0,0,0,0,0,0,0,0,0,0
0,0,0,0,0,0,0,0,0,0,0,0,0,0,0,0,0,0,0,0,0,0,0,0
0,0,0,0,0,0,0,0,0,0,0,0,0,0,0,0,0,0,0,0,0,0,0,0
0,0,0,0,0,0,0,0,0,0,0,0,0,0,0,0,0,0,0,0,0,0,0,0
0,0,0,0,0,0,0,0,0,0,0,6,6,0,0,0,0,0,0,0,0,0,0,0
0,0,0,0,0,0,0,0,0,0,6,6,6,6,0,0,0,0,0,0,0,0,0,0
0,0,0,0,0,0,0,0,0,0,6,0,0,6,0,0,0,0,0,0,0,0,0,0
0,0,0,0,0,0,0,0,0,6,0,0,0,0,6,0,0,0,0,0,0,0,0,0
0,0,0,0,0,0,0,0,6,0,6,6,6,6,0,6,0,0,0,0,0,0,0,0
0,0,0,0,0,0,6,6,0,0,6,0,0,6,0,0,6,6,0,0,0,0,0,0
0,0,0,0,0,0,6,6,0,0,6,0,41,6,0,0,6,6,0,0,0,0,0,0
0,0,0,0,0,0,0,0,6,0,6,6,6,6,0,6,0,0,0,0,0,0,0,0
0,0,0,0,0,0,0,0,0,0,0,0,0,0,0,0,0,0,0,0,0,0,0,0
0,0,0,0,0,0,0,0,0,0,0,0,0,0,0,0,0,0,0,0,0,0,0,0
0,0,0,0,0,0,0,0,0,0,0,0,0,0,0,0,0,0,0,0,0,0,0,0
0,0,0,0,0,0,0,0,0,0,0,0,0,0,0,0,0,0,0,0,0,0,0,0
0,0,0,0,0,0,0,0,0,0,0,0,0,0,0,0,0,0,0,0,0,0,0,0
:endlayer
layer: 9
0,0,0,0,0,0,0,0,0,0,0,0,0,0,0,0,0,0,0,0,0,0,0,0
0,0,0,0,0,0,0,0,0,0,0,0,0,0,0,0,0,0,0,0,0,0,0,0
0,0,0,0,0,0,0,0,0,0,0,0,0,0,0,0,0,0,0,0,0,0,0,0
0,0,0,0,0,0,0,0,0,0,0,0,0,0,0,31,31,0,0,0,0,0,0,0
0,0,0,0,0,0,0,6,6,0,0,0,0,0,0,6,6,17,0,0,0,0,0,0
0,0,0,0,0,0,33,6,0,6,0,0,0,0,6,0,6,0,0,0,0,0,0,0
0,0,0,0,0,0,33,0,6,0,6,32,32,6,0,6,0,0,0,0,0,0,0,0
0,0,0,0,0,0,0,0,0,6,6,13,13,6,6,0,0,0,0,0,0,0,0,0
0,0,0,0,0,0,0,0,0,32,13,0,0,13,32,0,0,0,0,0,0,0,0,0
0,0,0,0,0,0,0,0,0,32,13,0,0,13,32,0,0,0,0,0,0,0,0,0
0,0,0,0,0,0,0,0,0,6,6,13,13,6,6,0,0,0,0,0,0,0,0,0
0,0,0,0,0,0,0,0,6,0,6,32,32,6,0,6,0,17,0,0,0,0,0,0
0,0,0,0,0,0,0,6,0,6,0,0,0,0,6,0,6,0,0,0,0,0,0,0
0,0,0,0,0,0,0,6,6,0,0,0,0,0,0,6,6,17,0,0,0,0,0,0
0,0,0,0,0,0,0,0,0,0,0,18,0,0,0,0,18,0,0,0,0,0,0,0
0,0,0,0,0,0,0,0,0,0,0,0,0,0,0,0,0,0,0,0,0,0,0,0
0,0,0,0,0,0,0,0,0,0,0,0,0,0,0,0,0,0,0,0,0,0,0,0
0,0,0,0,0,0,0,0,0,0,0,0,0,0,0,0,0,0,0,0,0,0,0,0
0,0,0,0,0,0,0,0,0,0,0,0,0,0,0,0,0,0,0,0,0,0,0,0
0,0,0,0,0,0,0,0,0,0,0,0,0,0,0,0,0,0,0,0,0,0,0,0
0,0,0,0,0,0,0,0,0,0,0,0,0,0,0,0,0,0,0,0,0,0,0,0
0,0,0,0,0,0,0,0,0,0,0,0,0,0,0,0,0,0,0,0,0,0,0,0
0,0,0,0,0,0,0,0,0,0,0,0,0,0,0,0,0,0,0,0,0,0,0,0
0,0,0,0,0,0,0,0,0,0,0,0,0,0,0,0,0,0,0,0,0,0,0,0
0,0,0,0,0,0,0,0,0,0,0,6,6,0,0,0,0,0,0,0,0,0,0,0
0,0,0,0,0,0,0,0,0,0,6,6,6,6,0,0,0,0,0,0,0,0,0,0
0,0,0,0,0,0,0,0,0,0,6,0,0,6,0,0,0,0,0,0,0,0,0,0
0,0,0,0,0,0,0,0,0,6,0,0,0,0,6,0,0,0,0,0,0,0,0,0
0,0,0,0,0,0,0,0,6,0,6,6,6,6,0,6,0,0,0,0,0,0,0,0
0,0,0,0,0,0,0,6,0,0,6,0,24,6,0,0,6,0,0,0,0,0,0,0
0,0,0,0,0,0,0,6,0,0,6,0,0,6,0,0,6,0,0,0,0,0,0,0
0,0,0,0,0,0,0,0,6,0,6,6,6,6,0,6,0,0,0,0,0,0,0,0
0,0,0,0,0,0,0,0,0,0,0,0,0,0,0,0,0,0,0,0,0,0,0,0
0,0,0,0,0,0,0,0,0,0,0,0,0,0,0,0,0,0,0,0,0,0,0,0
0,0,0,0,0,0,0,0,0,0,0,0,0,0,0,0,0,0,0,0,0,0,0,0
0,0,0,0,0,0,0,0,0,0,0,0,0,0,0,0,0,0,0,0,0,0,0,0
0,0,0,0,0,0,0,0,0,0,0,0,0,0,0,0,0,0,0,0,0,0,0,0
:endlayer
layer: 10
0,0,0,0,0,0,0,0,0,0,0,0,0,0,0,0,0,0,0,0,0,0,0,0
0,0,0,0,0,0,0,0,0,0,0,0,0,0,0,0,0,0,0,0,0,0,0,0
0,0,0,0,0,0,0,0,0,0,0,0,0,0,0,0,0,0,0,0,0,0,0,0
0,0,0,0,0,0,0,0,0,0,0,0,0,0,0,31,31,0,0,0,0,0,0,0
0,0,0,0,0,0,0,6,6,6,0,0,0,0,6,6,6,17,0,0,0,0,0,0
0,0,0,0,0,0,0,6,0,0,6,0,0,6,0,0,6,0,0,0,0,0,0,0
0,0,0,0,0,0,33,6,0,0,0,6,6,0,0,0,6,0,0,0,0,0,0,0
0,0,0,0,0,0,0,0,6,0,6,6,6,6,0,6,0,0,0,0,0,0,0,0
0,0,0,0,0,0,0,0,0,6,6,6,6,6,6,0,0,0,0,0,0,0,0,0
0,0,0,0,0,0,0,0,0,6,6,6,6,6,6,0,0,0,0,0,0,0,0,0
0,0,0,0,0,0,0,0,6,0,6,6,6,6,0,6,0,0,0,0,0,0,0,0
0,0,0,0,0,0,0,6,0,0,0,6,6,0,0,0,6,17,0,0,0,0,0,0
0,0,0,0,0,0,0,6,0,0,6,0,0,6,0,0,6,0,0,0,0,0,0,0
0,0,0,0,0,0,0,6,6,6,0,0,0,0,6,6,6,17,0,0,0,0,0,0
0,0,0,0,0,0,0,0,0,0,0,18,0,0,0,0,18,0,0,0,0,0,0,0
0,0,0,0,0,0,0,0,0,0,0,0,0,0,0,0,0,0,0,0,0,0,0,0
0,0,0,0,0,0,0,0,0,0,0,0,0,0,0,0,0,0,0,0,0,0,0,0
0,0,0,0,0,0,0,0,0,0,0,0,0,0,0,0,0,0,0,0,0,0,0,0
0,0,0,0,0,0,0,0,0,0,0,0,0,0,0,0,0,0,0,0,0,0,0,0
0,0,0,0,0,0,0,0,0,0,0,0,0,0,0,0,0,0,0,0,0,0,0,0
0,0,0,0,0,0,0,0,0,0,0,0,0,0,0,0,0,0,0,0,0,0,0,0
0,0,0,0,0,0,0,0,0,0,0,0,0,0,0,0,0,0,0,0,0,0,0,0
0,0,0,0,0,0,0,0,0,0,0,0,0,0,0,0,0,0,0,0,0,0,0,0
0,0,0,0,0,0,0,0,0,0,0,0,0,0,0,0,0,0,0,0,0,0,0,0
0,0,0,0,0,0,0,0,0,0,0,6,6,0,0,0,0,0,0,0,0,0,0,0
0,0,0,0,0,0,0,0,0,0,6,6,6,6,0,0,0,0,0,0,0,0,0,0
0,0,0,0,0,0,0,0,0,0,6,0,0,6,0,0,0,0,0,0,0,0,0,0
0,0,0,0,0,0,0,0,0,6,0,0,0,0,6,0,0,0,0,0,0,0,0,0
0,0,0,0,0,0,0,0,6,0,6,6,6,6,0,6,0,0,0,0,0,0,0,0
0,0,0,0,0,0,0,6,0,0,6,34,0,6,0,0,6,0,0,0,0,0,0,0
0,0,0,0,0,0,0,6,0,0,6,0,0,6,0,0,6,0,0,0,0,0,0,0
0,0,0,0,0,0,0,0,6,0,6,8,8,6,0,6,0,0,0,0,0,0,0,0
0,0,0,0,0,0,0,0,0,0,0,0,0,0,0,0,0,0,0,0,0,0,0,0
0,0,0,0,0,0,0,0,0,0,0,0,0,0,0,0,0,0,0,0,0,0,0,0
0,0,0,0,0,0,0,0,0,0,0,0,0,0,0,0,0,0,0,0,0,0,0,0
0,0,0,0,0,0,0,0,0,0,0,0,0,0,0,0,0,0,0,0,0,0,0,0
0,0,0,0,0,0,0,0,0,0,0,0,0,0,0,0,0,0,0,0,0,0,0,0
:endlayer
layer: 11
0,0,0,0,0,0,0,0,0,0,0,0,0,0,0,0,0,0,0,0,0,0,0,0
0,0,0,0,0,0,0,0,0,0,0,0,0,0,0,0,0,0,0,0,0,0,0,0
0,0,0,0,0,0,0,0,0,0,0,0,0,0,0,0,0,0,0,0,0,0,0,0
0,0,0,0,0,0,0,0,0,0,0,0,0,0,0,31,31,0,0,0,0,0,0,0
0,0,0,0,0,0,0,6,6,6,6,0,0,6,6,6,6,17,0,0,0,0,0,0
0,0,0,0,0,0,11,6,0,0,0,6,6,0,0,0,6,31,0,0,0,0,0,0
0,0,0,0,0,33,33,6,0,0,0,6,6,0,0,0,6,0,0,0,0,0,0,0
0,0,0,0,0,0,0,6,0,0,6,0,0,6,0,0,6,0,0,0,0,0,0,0
0,0,0,0,0,0,0,0,6,6,0,0,0,0,6,6,0,0,0,0,0,0,0,0
0,0,0,0,0,0,0,0,6,6,0,0,0,0,6,6,0,0,0,0,0,0,0,0
0,0,0,0,0,0,0,6,0,0,6,0,0,6,0,0,6,0,0,0,0,0,0,0
0,0,0,0,0,0,0,6,0,0,0,6,6,0,0,0,6,17,0,0,0,0,0,0
0,0,0,0,0,0,0,6,0,0,0,6,6,0,0,0,6,0,0,0,0,0,0,0
0,0,0,0,0,0,0,6,6,6,6,0,0,6,6,6,6,17,0,0,0,0,0,0
0,0,0,0,0,0,0,0,0,0,0,18,0,0,0,0,0,0,0,0,0,0,0,0
0,0,0,0,0,0,0,0,0,0,0,0,0,0,0,0,18,0,0,0,0,0,0,0
0,0,0,0,0,0,0,0,0,0,0,0,0,0,18,0,0,0,0,0,0,0,0,0
0,0,0,0,0,0,0,0,0,0,0,0,0,0,0,0,0,0,0,0,0,0,0,0
0,0,0,0,0,0,0,0,0,0,0,0,0,0,0,0,0,0,0,0,0,0,0,0
0,0,0,0,0,0,0,0,0,0,0,0,0,0,0,0,0,0,0,0,0,0,0,0
0,0,0,0,0,0,0,0,0,0,0,0,0,0,0,0,0,0,0,0,0,0,0,0
0,0,0,0,0,0,0,0,0,0,0,0,0,0,0,0,0,0,0,0,0,0,0,0
0,0,0,0,0,0,0,0,0,0,0,0,0,0,0,0,0,0,0,0,0,0,0,0
0,0,0,0,0,0,0,0,0,0,0,0,0,0,0,0,0,0,0,0,0,0,0,0
0,0,0,0,0,0,0,0,0,0,0,6,6,0,0,0,0,0,0,0,0,0,0,0
0,0,0,0,0,0,0,0,0,0,6,6,6,6,0,0,0,0,0,0,0,0,0,0
0,0,0,0,0,0,0,0,0,0,6,0,0,6,0,0,0,0,0,0,0,0,0,0
0,0,0,0,0,0,0,0,0,6,0,0,0,0,6,0,0,0,0,0,0,0,0,0
0,0,0,0,0,0,0,0,6,6,6,6,6,6,6,6,0,0,0,0,0,0,0,0
0,0,0,0,0,0,0,6,0,0,6,0,0,6,0,0,6,0,0,0,0,0,0,0
0,0,0,0,0,0,0,6,0,0,6,40,0,6,0,0,6,0,0,0,0,0,0,0
0,0,0,0,0,0,0,0,6,6,6,6,6,6,6,6,0,0,0,0,0,0,0,0
0,0,0,0,0,0,0,0,0,0,13,42,42,13,0,0,0,0,0,0,0,0,0,0
0,0,0,0,0,0,0,0,0,0,0,0,0,0,0,0,0,0,0,0,0,0,0,0
0,0,0,0,0,0,0,0,0,0,0,0,0,0,0,0,0,0,0,0,0,0,0,0
0,0,0,0,0,0,0,0,0,0,0,0,0,0,0,0,0,0,0,0,0,0,0,0
0,0,0,0,0,0,0,0,0,0,0,0,0,0,0,0,0,0,0,0,0,0,0,0
:endlayer
layer: 12
0,0,0,0,0,0,0,0,0,0,0,0,0,0,0,0,0,0,0,0,0,0,0,0
0,0,0,0,0,0,0,0,0,0,0,0,0,0,0,0,0,0,0,0,0,0,0,0
0,0,0,0,0,0,0,0,0,0,0,0,0,0,0,0,0,0,0,0,0,0,0,0
0,0,0,0,0,0,0,0,0,0,0,0,0,0,0,31,0,0,0,0,0,0,0,0
0,0,0,0,0,0,0,6,6,6,6,6,6,6,6,6,6,17,0,0,0,0,0,0
0,0,0,0,0,0,11,6,6,6,6,6,6,6,6,6,6,31,0,0,0,0,0,0
0,0,0,0,0,33,33,6,6,0,6,0,0,6,0,6,6,0,0,0,17,0,0,0
0,0,0,0,0,0,0,6,6,6,39,0,0,39,6,6,6,0,0,0,0,0,0,0
0,0,0,0,0,0,0,6,6,0,0,0,0,0,0,6,6,0,0,0,0,0,0,0
0,0,0,0,0,0,0,6,6,0,0,0,0,0,0,6,6,0,0,0,0,0,0,0
0,0,0,0,0,0,0,6,6,6,39,0,0,39,6,6,6,0,0,0,0,0,0,0
0,0,0,0,0,0,0,6,6,0,6,0,0,6,0,6,6,17,0,0,0,0,0,0
0,0,0,0,0,0,0,6,6,6,6,6,6,6,6,6,6,0,0,0,0,0,0,0
0,0,0,0,0,0,0,6,6,6,6,6,6,6,6,6,6,17,0,0,0,0,0,0
0,0,0,0,0,0,0,0,0,0,0,18,0,0,0,0,0,0,0,0,0,0,0,0
0,0,0,0,0,0,0,0,0,0,0,0,0,0,0,0,18,0,0,0,0,0,0,0
0,0,0,0,0,0,0,0,0,0,0,0,0,0,18,0,0,0,0,0,0,0,0,0
0,0,0,0,0,0,0,0,0,0,0,0,0,0,0,0,0,0,0,0,0,0,0,0
0,0,0,0,0,0,0,0,0,0,0,0,0,0,0,0,0,0,0,0,0,0,0,0
0,0,0,0,0,0,0,0,0,0,0,0,0,0,0,0,0,0,0,0,0,0,0,0
0,0,0,0,0,0,0,0,0,0,0,0,0,0,0,0,0,0,0,0,0,0,0,0
0,0,0,0,0,0,0,0,0,0,0,0,0,0,0,0,0,0,0,0,0,0,0,0
0,0,0,0,0,0,0,0,0,0,0,0,0,0,0,0,0,0,0,0,0,0,0,0
0,0,0,0,0,0,0,0,0,0,0,0,0,0,0,0,0,0,0,0,0,0,0,0
0,0,0,0,0,0,0,0,0,0,0,6,6,0,0,0,0,0,0,0,0,0,0,0
0,0,0,0,0,0,0,0,0,0,39,6,6,39,0,0,0,0,0,0,0,0,0,0
0,0,0,0,0,0,0,0,0,0,6,0,0,6,0,0,0,0,0,0,0,0,0,0
0,0,0,0,0,0,0,0,0,6,0,0,0,0,6,0,0,0,0,0,0,0,0,0
0,0,0,0,0,0,0,0,0,6,6,6,6,6,6,0,0,0,0,0,0,0,0,0
0,0,0,0,0,0,0,6,6,6,6,0,0,6,6,6,6,0,0,0,0,0,0,0
0,0,0,0,0,0,0,6,6,6,6,0,41,6,6,6,6,0,0,0,0,0,0,0
0,0,0,0,0,0,0,0,0,6,6,8,8,6,6,0,0,0,0,0,0,0,0,0
0,0,0,0,0,0,0,0,0,0,32,0,0,32,0,0,0,0,0,0,0,0,0,0
0,0,0,0,0,0,0,0,0,0,0,0,0,0,0,0,0,0,0,0,0,0,0,0
0,0,0,0,0,0,0,0,0,0,0,0,0,0,0,0,0,0,0,0,0,0,0,0
0,0,0,0,0,0,0,0,0,0,0,0,0,0,0,0,0,0,0,0,0,0,0,0
0,0,0,0,0,0,0,0,0,0,0,0,0,0,0,0,0,0,0,0,0,0,0,0
:endlayer
layer: 13
0,0,0,0,0,0,0,0,0,0,0,0,0,0,0,0,0,0,0,0,0,0,0,0
0,0,0,0,0,0,0,0,0,0,0,0,0,0,0,0,0,0,0,0,0,0,0,0
0,0,0,0,0,0,0,0,0,0,0,0,0,0,0,0,0,0,0,0,0,0,0,0
0,0,0,0,0,0,0,0,0,0,0,0,0,0,0,0,0,0,0,0,0,0,0,0
0,0,0,0,0,0,0,39,0,31,43,0,0,44,0,0,39,0,0,0,0,0,0,0
0,0,0,0,0,0,31,31,6,6,45,6,6,46,6,6,0,31,0,0,0,0,0,0
0,0,0,0,0,33,0,0,6,0,6,0,0,6,0,6,17,0,0,0,17,0,0,0
0,0,0,0,0,0,0,47,48,6,0,0,0,0,6,17,49,0,0,0,0,0,0,0
0,0,0,0,0,0,0,0,6,0,0,0,0,0,0,6,0,0,0,0,0,0,0,0
0,0,0,0,0,0,0,0,6,0,0,0,0,0,0,6,17,0,0,0,0,0,0,0
0,0,0,0,0,0,0,50,48,6,0,0,0,0,6,17,51,0,0,0,0,0,0,0
0,0,0,0,0,0,0,0,6,0,6,0,0,6,0,6,17,0,0,0,0,0,0,0
0,0,0,0,0,0,0,0,6,6,18,6,6,18,6,6,17,0,0,0,0,0,0,0
0,0,0,0,0,0,0,39,0,18,52,18,18,53,0,18,39,0,0,0,0,0,0,0
0,0,0,0,0,0,0,0,0,0,0,0,0,0,0,0,0,0,0,0,0,0,0,0
0,0,0,0,0,0,0,0,0,0,0,0,0,0,0,0,18,0,0,0,0,0,0,0
0,0,0,0,0,0,0,0,0,0,0,0,0,0,18,0,0,0,0,0,0,0,0,0
0,0,0,0,0,0,0,0,0,0,0,0,0,0,0,0,0,0,0,0,0,0,0,0
0,0,0,0,0,0,0,0,0,0,0,0,0,0,0,0,0,0,0,0,0,0,0,0
0,0,0,0,0,0,0,0,0,0,0,0,0,0,0,0,0,0,0,0,0,0,0,0
0,0,0,0,0,0,0,0,0,0,0,0,0,0,0,0,0,0,0,0,0,0,0,0
0,0,0,0,0,0,0,0,0,0,0,0,0,0,0,0,0,0,0,0,0,0,0,0
0,0,0,0,0,0,0,0,0,0,0,0,0,0,0,0,0,0,0,0,0,0,0,0
0,0,0,0,0,0,0,0,0,0,0,0,0,0,0,0,0,0,0,0,0,0,0,0
0,0,0,0,0,0,0,0,0,0,0,6,6,0,0,0,0,0,0,0,0,0,0,0
0,0,0,0,0,0,0,0,0,0,0,6,6,0,0,0,0,0,0,0,0,0,0,0
0,0,0,0,0,0,0,0,0,0,6,0,0,6,0,0,0,0,0,0,0,0,0,0
0,0,0,0,0,0,0,0,0,6,0,0,0,0,6,0,0,0,0,0,0,0,0,0
0,0,0,0,0,0,0,0,0,6,6,6,6,6,6,0,0,0,0,0,0,0,0,0
0,0,0,0,0,0,0,54,0,0,6,0,24,6,0,0,0,0,0,0,0,0,0,0
0,0,0,0,0,0,0,0,0,0,6,0,0,6,0,0,55,0,0,0,0,0,0,0
0,0,0,0,0,0,0,0,0,6,6,6,6,6,6,0,0,0,0,0,0,0,0,0
0,0,0,0,0,0,0,0,0,0,32,0,0,32,0,0,0,0,0,0,0,0,0,0
0,0,0,0,0,0,0,0,0,0,0,0,0,0,0,0,0,0,0,0,0,0,0,0
0,0,0,0,0,0,0,0,0,0,0,0,0,0,0,0,0,0,0,0,0,0,0,0
0,0,0,0,0,0,0,0,0,0,0,0,0,0,0,0,0,0,0,0,0,0,0,0
0,0,0,0,0,0,0,0,0,0,0,0,0,0,0,0,0,0,0,0,0,0,0,0
:endlayer
layer: 14
0,0,0,0,0,0,0,0,0,0,0,0,0,0,0,0,0,0,0,0,0,0,0,0
0,0,0,0,0,0,0,0,0,0,0,0,0,0,0,0,0,0,0,0,0,0,0,0
0,0,0,0,0,0,0,0,0,0,0,0,0,0,0,0,0,0,0,0,0,0,0,0
0,0,0,0,0,0,0,0,0,0,0,0,0,0,0,0,0,0,0,0,0,0,0,0
0,0,0,0,0,0,0,0,0,0,0,0,0,0,0,0,0,0,0,0,0,0,0,0
0,0,0,0,0,0,31,31,39,31,45,6,6,46,31,39,17,31,0,31,0,0,0,0
0,0,0,0,0,33,0,0,33,6,6,0,0,6,6,17,17,0,0,0,17,0,0,0
0,0,0,0,0,0,0,0,48,6,0,0,0,0,6,17,0,0,0,0,0,0,0,0
0,0,0,0,0,0,0,0,6,0,0,0,0,0,0,6,0,0,0,0,0,0,0,0
0,0,0,0,0,0,0,0,6,0,0,0,0,0,0,6,17,0,0,0,17,0,0,0
0,0,0,0,0,0,0,0,48,6,0,0,0,0,6,17,0,0,0,0,0,0,0,0
0,0,0,0,0,0,0,0,0,6,6,0,0,6,6,17,17,0,0,0,0,0,0,0
0,0,0,0,0,0,0,0,39,0,18,6,6,18,0,39,17,0,0,0,0,0,0,0
0,0,0,0,0,0,0,0,0,0,0,18,18,0,0,18,0,0,0,0,0,0,0,0
0,0,0,0,0,0,0,0,0,0,0,0,0,0,0,0,0,0,0,0,0,0,0,0
0,0,0,0,0,0,0,0,0,0,0,0,0,0,0,0,18,0,0,0,0,0,0,0
0,0,0,0,0,0,0,0,0,0,0,0,0,0,18,0,0,0,0,0,0,0,0,0
0,0,0,0,0,0,0,0,0,0,0,0,0,0,0,0,0,0,0,0,0,0,0,0
0,0,0,0,0,0,0,0,0,0,0,0,0,0,0,0,0,0,0,0,0,0,0,0
0,0,0,0,0,0,0,0,0,0,0,0,0,0,0,0,0,0,0,0,0,0,0,0
0,0,0,0,0,0,0,0,0,0,0,0,0,0,0,0,0,0,0,0,0,0,0,0
0,0,0,0,0,0,0,0,0,0,0,0,0,0,0,0,0,0,0,0,0,0,0,0
0,0,0,0,0,0,0,0,0,0,0,0,0,0,0,0,0,0,0,0,0,0,0,0
0,0,0,0,0,0,0,0,0,0,0,0,0,0,0,0,0,0,0,0,0,0,0,0
0,0,0,0,0,0,0,0,0,0,0,39,39,0,0,0,0,0,0,0,0,0,0,0
0,0,0,0,0,0,0,0,0,0,0,6,6,0,0,0,0,0,0,0,0,0,0,0
0,0,0,0,0,0,0,0,0,0,6,0,0,6,0,0,0,0,0,0,0,0,0,0
0,0,0,0,0,0,0,0,0,6,0,0,0,0,6,0,0,0,0,0,0,0,0,0
0,0,0,0,0,0,0,0,0,6,6,6,6,6,6,0,0,0,0,0,0,0,0,0
0,0,0,0,0,0,0,0,0,0,6,34,0,6,0,0,0,0,0,0,0,0,0,0
0,0,0,0,0,0,0,0,0,0,6,0,0,6,0,0,0,0,0,0,0,0,0,0
0,0,0,0,0,0,0,0,0,6,6,6,6,6,6,0,0,0,0,0,0,0,0,0
0,0,0,0,0,0,0,0,0,0,32,0,0,32,0,0,0,0,0,0,0,0,0,0
0,0,0,0,0,0,0,0,0,0,0,0,0,0,0,0,0,0,0,0,0,0,0,0
0,0,0,0,0,0,0,0,0,0,0,0,0,0,0,0,0,0,0,0,0,0,0,0
0,0,0,0,0,0,0,0,0,0,0,0,0,0,0,0,0,0,0,0,0,0,0,0
0,0,0,0,0,0,0,0,0,0,0,0,0,0,0,0,0,0,0,0,0,0,0,0
:endlayer
layer: 15
0,0,0,0,0,0,0,0,0,0,0,0,0,0,0,0,0,0,0,0,0,0,0,0
0,0,0,0,0,0,0,0,0,0,0,0,0,0,0,0,0,0,0,0,0,0,0,0
0,0,0,0,0,0,0,0,0,0,0,0,0,0,0,0,0,0,0,0,0,0,0,0
0,0,0,0,0,0,0,0,0,0,0,0,0,0,0,0,0,0,0,0,0,0,0,0
0,0,0,0,0,0,0,0,0,0,0,0,0,0,0,0,0,0,0,0,0,0,0,0
0,0,0,0,0,0,31,31,0,31,45,6,6,46,31,0,17,31,0,31,0,0,0,0
0,0,0,0,0,33,0,0,33,6,6,0,0,6,6,17,17,0,0,0,17,0,0,0
0,0,0,0,0,0,0,0,48,6,0,0,0,0,6,17,0,0,0,0,0,0,0,0
0,0,0,0,0,0,0,0,6,0,0,0,0,0,0,6,0,0,0,0,0,0,0,0
0,0,0,0,0,0,0,0,6,0,0,0,0,0,0,6,17,0,0,0,17,0,0,0
0,0,0,0,0,0,0,0,48,6,0,0,0,0,6,17,0,0,0,0,17,0,0,0
0,0,0,0,0,0,0,0,0,6,6,0,0,6,6,17,17,0,0,0,0,0,0,0
0,0,0,0,0,0,0,0,0,0,18,6,6,18,0,0,17,0,0,0,0,0,0,0
0,0,0,0,0,0,0,0,0,0,0,18,18,0,0,18,0,0,0,0,0,0,0,0
0,0,0,0,0,0,0,0,0,0,0,0,0,0,0,0,0,0,0,0,0,0,0,0
0,0,0,0,0,0,0,0,0,0,0,0,0,0,0,0,18,0,0,0,0,0,0,0
0,0,0,0,0,0,0,0,0,0,0,0,0,0,18,0,0,0,0,0,0,0,0,0
0,0,0,0,0,0,0,0,0,0,0,0,0,0,0,0,0,0,0,0,0,0,0,0
0,0,0,0,0,0,0,0,0,0,0,0,0,0,0,0,0,0,0,0,0,0,0,0
0,0,0,0,0,0,0,0,0,0,0,0,0,0,0,0,0,0,0,0,0,0,0,0
0,0,0,0,0,0,0,0,0,0,0,0,0,0,0,0,0,0,0,0,0,0,0,0
0,0,0,0,0,0,0,0,0,0,0,0,0,0,0,0,0,0,0,0,0,0,0,0
0,0,0,0,0,0,0,0,0,0,0,0,0,0,0,0,0,0,0,0,0,0,0,0
0,0,0,0,0,0,0,0,0,0,0,0,0,0,0,0,0,0,0,0,0,0,0,0
0,0,0,0,0,0,0,0,0,0,0,0,0,0,0,0,0,0,0,0,0,0,0,0
0,0,0,0,0,0,0,0,0,0,0,6,6,0,0,0,0,0,0,0,0,0,0,0
0,0,0,0,0,0,0,0,0,0,6,0,0,6,0,0,0,0,0,0,0,0,0,0
0,0,0,0,0,0,0,0,0,0,6,0,0,6,0,0,0,0,0,0,0,0,0,0
0,0,0,0,0,0,0,0,0,6,6,6,6,6,6,0,0,0,0,0,0,0,0,0
0,0,0,0,0,0,0,0,0,0,6,0,0,6,0,0,0,0,0,0,0,0,0,0
0,0,0,0,0,0,0,0,0,0,6,40,0,6,0,0,0,0,0,0,0,0,0,0
0,0,0,0,0,0,0,0,0,6,6,6,6,6,6,0,0,0,0,0,0,0,0,0
0,0,0,0,0,0,0,0,0,0,0,0,0,0,0,0,0,0,0,0,0,0,0,0
0,0,0,0,0,0,0,0,0,0,0,0,0,0,0,0,0,0,0,0,0,0,0,0
0,0,0,0,0,0,0,0,0,0,0,0,0,0,0,0,0,0,0,0,0,0,0,0
0,0,0,0,0,0,0,0,0,0,0,0,0,0,0,0,0,0,0,0,0,0,0,0
0,0,0,0,0,0,0,0,0,0,0,0,0,0,0,0,0,0,0,0,0,0,0,0
:endlayer
layer: 16
0,0,0,0,0,0,0,0,0,0,0,0,0,0,0,0,0,0,0,0,0,0,0,0
0,0,0,0,0,0,0,0,0,0,0,0,0,0,0,0,0,0,0,0,0,0,0,0
0,0,0,0,0,0,0,0,0,0,0,0,0,0,0,0,0,0,0,0,0,0,0,0
0,0,0,0,0,0,0,0,0,0,0,0,0,0,0,0,0,0,0,0,0,0,0,0
0,0,0,0,0,0,0,0,0,0,0,0,0,0,0,0,0,0,0,0,0,0,0,0
0,0,0,0,0,0,31,31,0,31,45,31,0,46,0,0,17,31,0,31,0,0,0,0
0,0,0,0,0,33,0,0,33,11,6,6,6,6,0,17,17,0,0,0,17,0,0,0
0,0,0,0,0,0,0,0,48,6,0,0,0,0,6,17,0,0,0,0,0,0,0,0
0,0,0,0,0,0,0,0,0,6,0,0,0,0,6,0,0,0,0,0,0,0,0,0
0,0,0,0,0,0,0,0,0,6,0,0,0,0,6,0,17,0,0,0,17,0,0,0
0,0,0,0,0,0,0,0,48,6,0,0,0,0,6,17,0,0,31,0,17,0,0,0
0,0,0,0,0,0,0,0,0,0,6,6,6,6,17,17,17,17,0,0,0,0,0,0
0,0,0,0,0,0,0,0,0,0,18,18,0,18,0,0,17,0,0,18,0,0,0,0
0,0,0,0,0,0,0,0,0,0,0,0,0,0,0,18,0,0,18,0,0,0,0,0
0,0,0,0,0,0,0,0,0,0,0,0,0,0,0,0,0,17,0,0,0,0,0,0
0,0,0,0,0,0,0,0,0,0,0,0,0,0,0,0,18,0,0,0,0,0,0,0
0,0,0,0,0,0,0,0,0,0,0,0,0,0,18,0,0,0,0,0,0,0,0,0
0,0,0,0,0,0,0,0,0,0,0,0,0,0,0,0,0,0,0,0,0,0,0,0
0,0,0,0,0,0,0,0,0,0,0,0,0,0,0,0,0,0,0,0,0,0,0,0
0,0,0,0,0,0,0,0,0,0,0,0,0,0,0,0,0,0,0,0,0,0,0,0
0,0,0,0,0,0,0,0,0,0,0,0,0,0,0,0,0,0,0,0,0,0,0,0
0,0,0,0,0,0,0,0,0,0,0,0,0,0,0,0,0,0,0,0,0,0,0,0
0,0,0,0,0,0,0,0,0,0,0,0,0,0,0,0,0,0,0,0,0,0,0,0
0,0,0,0,0,0,0,0,0,0,0,0,0,0,0,0,0,0,0,0,0,0,0,0
0,0,0,0,0,0,0,0,0,0,0,0,0,0,0,0,0,0,0,0,0,0,0,0
0,0,0,0,0,0,0,0,0,0,0,6,6,0,0,0,0,0,0,0,0,0,0,0
0,0,0,0,0,0,0,0,0,0,0,6,6,0,0,0,0,0,0,0,0,0,0,0
0,0,0,0,0,0,0,0,0,0,0,6,6,0,0,0,0,0,0,0,0,0,0,0
0,0,0,0,0,0,0,0,0,6,6,6,6,6,6,0,0,0,0,0,0,0,0,0
0,0,0,0,0,0,0,0,0,0,6,0,0,6,0,0,0,0,0,0,0,0,0,0
0,0,0,0,0,0,0,0,0,0,6,0,41,6,0,0,0,0,0,0,0,0,0,0
0,0,0,0,0,0,0,0,0,6,6,8,8,6,6,0,0,0,0,0,0,0,0,0
0,0,0,0,0,0,0,0,0,0,35,0,0,35,0,0,0,0,0,0,0,0,0,0
0,0,0,0,0,0,0,0,0,0,0,0,0,0,0,0,0,0,0,0,0,0,0,0
0,0,0,0,0,0,0,0,0,0,0,0,0,0,0,0,0,0,0,0,0,0,0,0
0,0,0,0,0,0,0,0,0,0,0,0,0,0,0,0,0,0,0,0,0,0,0,0
0,0,0,0,0,0,0,0,0,0,0,0,0,0,0,0,0,0,0,0,0,0,0,0
:endlayer
layer: 17
0,0,0,0,0,0,0,0,0,0,0,0,0,0,0,0,0,0,0,0,0,0,0,0
0,0,0,0,0,0,0,0,0,31,0,0,0,0,0,0,0,0,0,0,0,0,0,0
0,0,0,0,0,0,0,0,0,0,0,0,0,0,0,0,0,0,0,0,0,0,0,0
0,0,0,0,0,0,0,0,0,0,0,0,0,0,0,0,0,0,0,0,0,0,0,0
0,0,0,0,0,0,0,0,0,0,0,0,0,0,0,0,0,0,0,0,0,0,0,0
0,0,0,0,0,0,31,31,0,31,45,31,0,46,0,0,17,31,0,31,0,0,0,0
0,0,0,0,0,33,0,0,33,33,6,6,6,6,0,17,17,0,0,0,17,0,0,0
0,0,0,0,0,0,0,0,48,6,0,0,0,0,6,17,0,0,0,0,0,0,0,0
0,0,0,0,0,0,0,0,0,6,0,0,0,0,6,0,0,0,0,0,0,0,0,0
0,0,0,0,0,0,0,0,0,6,0,0,0,0,6,0,17,0,0,0,17,0,0,0
0,0,0,0,0,0,0,0,48,6,0,0,0,0,6,17,0,0,31,0,17,0,0,0
0,0,0,0,0,0,0,0,0,0,6,6,6,6,17,17,17,17,0,0,0,0,0,0
0,0,0,0,0,0,0,0,0,0,18,18,0,18,0,0,17,0,0,18,0,0,0,0
0,0,0,0,0,0,0,0,0,0,0,0,0,0,0,18,0,0,18,0,0,0,0,0
0,0,0,0,0,0,0,0,0,0,0,0,0,0,0,0,0,17,0,0,0,0,0,0
0,0,0,0,0,0,0,0,0,0,0,0,0,0,0,0,18,0,0,0,0,0,0,0
0,0,0,0,0,0,0,0,0,0,0,0,0,0,18,0,0,0,0,0,0,0,0,0
0,0,0,0,0,0,0,0,0,18,0,0,0,0,0,0,0,0,0,0,0,0,0,0
0,0,0,0,0,0,0,0,0,0,0,0,0,0,0,0,0,0,0,0,0,0,0,0
0,0,0,0,0,0,0,0,0,0,0,0,0,0,0,0,0,0,0,0,0,0,0,0
0,0,0,0,0,0,0,0,0,0,0,0,0,0,0,0,0,0,0,0,0,0,0,0
0,0,0,0,0,0,0,0,0,0,0,0,0,0,0,0,0,0,0,0,0,0,0,0
0,0,0,0,0,0,0,0,0,0,0,0,0,0,0,0,0,0,0,0,0,0,0,0
0,0,0,0,0,0,0,0,0,0,0,0,0,0,0,0,0,0,0,0,0,0,0,0
0,0,0,0,0,0,0,0,0,0,0,0,0,0,0,0,0,0,0,0,0,0,0,0
0,0,0,0,0,0,0,0,0,0,0,6,6,0,0,0,0,0,0,0,0,0,0,0
0,0,0,0,0,0,0,0,0,0,0,32,32,0,0,0,0,0,0,0,0,0,0,0
0,0,0,0,0,0,0,0,0,0,0,32,32,0,0,0,0,0,0,0,0,0,0,0
0,0,0,0,0,0,0,0,0,39,6,6,6,6,39,0,0,0,0,0,0,0,0,0
0,0,0,0,0,0,0,0,0,6,6,0,24,6,6,0,0,0,0,0,0,0,0,0
0,0,0,0,0,0,0,0,0,6,6,0,0,6,6,0,0,0,0,0,0,0,0,0
0,0,0,0,0,0,0,0,0,39,6,6,6,6,39,0,0,0,0,0,0,0,0,0
0,0,0,0,0,0,0,0,0,0,0,0,0,0,0,0,0,0,0,0,0,0,0,0
0,0,0,0,0,0,0,0,0,0,0,0,0,0,0,0,0,0,0,0,0,0,0,0
0,0,0,0,0,0,0,0,0,0,0,0,0,0,0,0,0,0,0,0,0,0,0,0
0,0,0,0,0,0,0,0,0,0,0,0,0,0,0,0,0,0,0,0,0,0,0,0
0,0,0,0,0,0,0,0,0,0,0,0,0,0,0,0,0,0,0,0,0,0,0,0
:endlayer
layer: 18
0,0,0,0,0,0,0,0,0,0,0,0,0,0,0,0,0,0,0,0,0,0,0,0
0,0,0,0,0,0,0,0,0,31,0,0,0,0,0,0,0,0,0,0,0,0,0,0
0,0,0,0,0,0,0,31,0,0,0,0,0,0,0,0,0,0,0,0,0,0,0,0
0,0,0,0,0,0,0,0,0,0,0,0,0,0,0,0,0,0,0,0,0,0,0,0
0,0,0,0,0,0,0,0,0,0,0,0,0,0,0,0,0,0,0,0,0,0,0,0
0,0,0,0,0,31,31,31,0,31,45,6,6,46,0,0,17,31,0,31,0,0,0,0
0,0,0,0,0,33,0,0,33,6,6,6,6,6,6,17,17,0,0,0,17,0,0,0
0,0,0,0,0,0,0,0,48,6,0,0,0,0,6,17,0,0,0,0,0,0,0,0
0,0,0,0,0,0,0,0,6,6,0,0,0,0,6,6,0,0,0,0,0,0,0,0
0,0,0,0,0,0,0,0,6,6,0,0,0,0,6,6,17,0,0,0,17,0,0,0
0,0,0,0,0,0,0,0,48,6,0,0,0,0,6,17,0,0,31,0,17,0,0,0
0,0,0,0,0,0,0,0,0,6,6,6,6,6,6,17,17,17,0,0,0,0,0,0
0,0,0,0,0,0,0,0,0,0,18,6,6,18,0,0,17,0,0,18,0,0,0,0
0,0,0,0,0,0,0,0,0,0,0,0,0,0,0,18,0,0,18,0,0,0,0,0
0,0,0,0,0,0,0,0,0,0,0,0,0,0,0,0,0,56,0,0,0,0,0,0
0,0,0,0,0,0,0,0,0,0,0,0,0,0,18,0,18,0,0,0,0,0,0,0
0,0,0,0,0,0,0,0,0,0,0,0,0,0,18,0,0,0,0,0,0,0,0,0
0,0,0,0,0,0,0,0,0,18,0,0,0,0,18,0,0,0,0,0,0,0,0,0
0,0,0,0,0,0,0,0,0,0,0,0,0,0,0,0,0,0,0,0,0,0,0,0
0,0,0,0,0,0,0,0,0,0,0,0,0,0,0,0,0,0,0,0,0,0,0,0
0,0,0,0,0,0,0,0,0,0,0,0,0,0,0,0,0,0,0,0,0,0,0,0
0,0,0,0,0,0,0,0,0,0,0,0,0,0,0,0,0,0,0,0,0,0,0,0
0,0,0,0,0,0,0,0,0,0,0,0,0,0,0,0,0,0,0,0,0,0,0,0
0,0,0,0,0,0,0,0,0,0,0,0,0,0,0,0,0,0,0,0,0,0,0,0
0,0,0,0,0,0,0,0,0,0,0,0,0,0,0,0,0,0,0,0,0,0,0,0
0,0,0,0,0,0,0,0,0,0,0,6,6,0,0,0,0,0,0,0,0,0,0,0
0,0,0,0,0,0,0,0,0,0,0,32,32,0,0,0,0,0,0,0,0,0,0,0
0,0,0,0,0,0,0,0,0,0,0,32,32,0,0,0,0,0,0,0,0,0,0,0
0,0,0,0,0,0,0,0,0,0,6,6,6,6,0,0,0,0,0,0,0,0,0,0
0,0,0,0,0,0,0,0,0,0,6,34,0,6,0,0,0,0,0,0,0,0,0,0
0,0,0,0,0,0,0,0,0,0,6,0,0,6,0,0,0,0,0,0,0,0,0,0
0,0,0,0,0,0,0,0,0,0,6,8,8,6,0,0,0,0,0,0,0,0,0,0
0,0,0,0,0,0,0,0,0,0,35,0,0,35,0,0,0,0,0,0,0,0,0,0
0,0,0,0,0,0,0,0,0,0,0,0,0,0,0,0,0,0,0,0,0,0,0,0
0,0,0,0,0,0,0,0,0,0,0,0,0,0,0,0,0,0,0,0,0,0,0,0
0,0,0,0,0,0,0,0,0,0,0,0,0,0,0,0,0,0,0,0,0,0,0,0
0,0,0,0,0,0,0,0,0,0,0,0,0,0,0,0,0,0,0,0,0,0,0,0
:endlayer
layer: 19
0,0,0,0,0,0,0,0,0,0,0,0,0,0,0,0,0,0,0,0,0,0,0,0
0,0,0,0,0,0,0,0,0,31,0,0,0,0,0,0,0,0,0,0,0,0,0,0
0,0,0,0,0,0,0,31,0,0,0,0,0,0,0,0,0,0,0,0,0,0,0,0
0,0,0,0,0,0,0,0,0,0,0,0,0,0,0,0,0,0,0,0,0,0,0,0
0,0,0,0,0,0,0,0,0,0,0,0,0,0,0,0,0,0,0,0,0,0,0,0
0,0,0,0,0,31,31,31,57,31,45,6,6,46,0,0,17,31,0,31,0,0,0,0
0,0,0,0,0,33,0,0,33,6,6,6,6,6,6,17,17,0,0,0,17,0,0,0
0,0,0,0,0,0,0,0,58,6,0,0,0,0,6,17,0,0,0,0,17,0,0,0
0,0,0,0,0,0,0,0,6,6,0,0,0,0,6,6,0,0,0,0,0,0,0,0
0,0,0,0,0,0,0,0,6,6,0,0,0,0,6,6,17,0,0,0,17,0,0,0
0,0,0,0,0,0,0,0,48,6,0,0,0,0,6,17,0,0,31,0,17,0,0,0
0,0,0,0,0,0,0,0,0,6,6,6,6,6,6,17,17,17,0,17,0,0,0,0
0,0,0,0,0,0,0,0,0,0,18,6,6,18,0,0,17,0,0,18,0,0,0,0
0,0,0,0,0,0,0,0,0,0,0,0,0,0,0,18,0,0,18,0,0,0,0,0
0,0,0,0,0,0,0,0,0,0,0,0,0,0,0,0,0,56,0,0,0,0,0,0
0,0,0,0,0,0,0,0,0,0,0,0,0,0,18,0,18,0,0,0,0,0,0,0
0,0,0,0,0,0,0,0,0,0,0,0,0,0,18,0,0,0,0,0,0,0,0,0
0,0,0,0,0,0,0,0,0,18,0,0,0,18,18,0,0,0,0,0,0,0,0,0
0,0,0,0,0,0,0,0,0,0,0,0,0,0,0,0,0,0,0,0,0,0,0,0
0,0,0,0,0,0,0,0,0,0,0,0,0,0,0,0,0,0,0,0,0,0,0,0
0,0,0,0,0,0,0,0,0,0,0,0,0,0,0,0,0,0,0,0,0,0,0,0
0,0,0,0,0,0,0,0,0,0,0,0,0,0,0,0,0,0,0,0,0,0,0,0
0,0,0,0,0,0,0,0,0,0,0,0,0,0,0,0,0,0,0,0,0,0,0,0
0,0,0,0,0,0,0,0,0,0,0,0,0,0,0,0,0,0,0,0,0,0,0,0
0,0,0,0,0,0,0,0,0,0,0,0,0,0,0,0,0,0,0,0,0,0,0,0
0,0,0,0,0,0,0,0,0,0,0,0,0,0,0,0,0,0,0,0,0,0,0,0
0,0,0,0,0,0,0,0,0,0,0,6,6,0,0,0,0,0,0,0,0,0,0,0
0,0,0,0,0,0,0,0,0,0,0,32,32,0,0,0,0,0,0,0,0,0,0,0
0,0,0,0,0,0,0,0,0,0,6,6,6,6,0,0,0,0,0,0,0,0,0,0
0,0,0,0,0,0,0,0,0,0,6,0,0,6,0,0,0,0,0,0,0,0,0,0
0,0,0,0,0,0,0,0,0,0,6,40,0,6,0,0,0,0,0,0,0,0,0,0
0,0,0,0,0,0,0,0,0,0,6,6,6,6,0,0,0,0,0,0,0,0,0,0
0,0,0,0,0,0,0,0,0,0,0,0,0,0,0,0,0,0,0,0,0,0,0,0
0,0,0,0,0,0,0,0,0,0,0,0,0,0,0,0,0,0,0,0,0,0,0,0
0,0,0,0,0,0,0,0,0,0,0,0,0,0,0,0,0,0,0,0,0,0,0,0
0,0,0,0,0,0,0,0,0,0,0,0,0,0,0,0,0,0,0,0,0,0,0,0
0,0,0,0,0,0,0,0,0,0,0,0,0,0,0,0,0,0,0,0,0,0,0,0
:endlayer
layer: 20
0,0,0,0,0,0,0,0,0,0,0,0,0,0,0,0,0,0,0,0,0,0,0,0
0,0,0,0,0,0,0,0,0,31,0,0,0,0,0,0,0,0,0,0,0,0,0,0
0,0,0,0,0,0,0,31,0,0,0,0,0,0,0,0,0,0,0,0,0,0,0,0
0,0,0,0,0,0,0,0,0,0,0,0,0,0,0,0,0,0,0,0,0,0,0,0
0,0,0,0,0,0,0,0,0,0,0,0,0,0,0,0,0,0,0,0,0,0,0,0
0,0,0,0,0,31,31,31,6,6,45,6,6,31,6,6,46,31,0,31,0,0,0,0
0,0,0,0,0,33,0,0,6,6,6,6,6,6,6,6,17,0,0,0,17,0,0,0
0,0,0,0,0,0,0,0,58,6,6,6,6,6,6,17,0,0,0,0,17,0,0,0
0,0,0,0,0,0,0,0,6,6,6,6,6,6,6,6,0,0,0,0,0,0,0,0
0,0,0,0,0,0,0,0,6,6,6,6,6,6,6,6,17,0,0,0,17,0,0,0
0,0,0,0,0,0,0,0,31,6,6,6,6,6,6,17,0,0,31,0,17,0,0,0
0,0,0,0,0,0,0,0,6,6,6,6,6,6,6,6,17,17,0,17,0,0,0,0
0,0,0,0,0,0,0,0,6,6,17,6,6,18,6,6,17,0,0,18,0,0,0,0
0,0,0,0,0,0,0,0,0,0,0,0,0,0,0,18,0,0,18,0,0,0,0,0
0,0,0,0,0,0,0,0,0,0,0,0,0,0,0,0,0,56,0,0,0,0,0,0
0,0,0,0,0,0,0,0,0,0,0,0,0,0,18,0,18,0,0,0,0,0,0,0
0,0,0,0,0,0,0,0,0,0,0,0,0,0,18,0,0,0,0,0,0,0,0,0
0,0,0,0,0,0,0,0,0,18,0,0,0,18,18,0,0,0,0,0,0,0,0,0
0,0,0,0,0,0,0,0,0,0,0,0,0,0,0,0,0,0,0,0,0,0,0,0
0,0,0,0,0,0,0,0,0,0,0,0,0,0,0,0,0,0,0,0,0,0,0,0
0,0,0,0,0,0,0,0,0,0,0,0,0,0,0,0,0,0,0,0,0,0,0,0
0,0,0,0,0,0,0,0,0,0,0,0,0,0,0,0,0,0,0,0,0,0,0,0
0,0,0,0,0,0,0,0,0,0,0,0,0,0,0,0,0,0,0,0,0,0,0,0
0,0,0,0,0,0,0,0,0,0,0,0,0,0,0,0,0,0,0,0,0,0,0,0
0,0,0,0,0,0,0,0,0,0,0,0,0,0,0,0,0,0,0,0,0,0,0,0
0,0,0,0,0,0,0,0,0,0,0,0,0,0,0,0,0,0,0,0,0,0,0,0
0,0,0,0,0,0,0,0,0,0,0,0,0,0,0,0,0,0,0,0,0,0,0,0
0,0,0,0,0,0,0,0,0,0,0,6,6,0,0,0,0,0,0,0,0,0,0,0
0,0,0,0,0,0,0,0,0,0,6,6,6,6,0,0,0,0,0,0,0,0,0,0
0,0,0,0,0,0,0,0,0,0,6,0,0,6,0,0,0,0,0,0,0,0,0,0
0,0,0,0,0,0,0,0,0,0,6,0,41,6,0,0,0,0,0,0,0,0,0,0
0,0,0,0,0,0,0,0,0,0,6,8,8,6,0,0,0,0,0,0,0,0,0,0
0,0,0,0,0,0,0,0,0,0,35,0,0,35,0,0,0,0,0,0,0,0,0,0
0,0,0,0,0,0,0,0,0,0,0,0,0,0,0,0,0,0,0,0,0,0,0,0
0,0,0,0,0,0,0,0,0,0,0,0,0,0,0,0,0,0,0,0,0,0,0,0
0,0,0,0,0,0,0,0,0,0,0,0,0,0,0,0,0,0,0,0,0,0,0,0
0,0,0,0,0,0,0,0,0,0,0,0,0,0,0,0,0,0,0,0,0,0,0,0
:endlayer
layer: 21
0,0,0,0,0,0,0,0,0,0,0,0,0,0,0,0,0,0,0,0,0,0,0,0
0,0,0,0,0,0,0,0,0,31,0,0,0,0,0,0,0,0,0,0,0,0,0,0
0,0,0,0,0,0,0,31,0,0,0,0,0,0,0,0,0,0,0,0,0,0,0,0
0,0,0,0,0,0,0,0,0,0,0,0,0,0,0,0,0,0,0,0,0,0,0,0
0,0,0,0,0,0,0,0,0,0,0,0,0,0,0,0,0,0,0,0,0,0,0,0
0,0,0,0,0,31,31,31,39,31,31,31,31,0,31,39,31,31,31,31,0,0,0,0
0,0,0,0,0,33,0,37,6,6,6,6,6,6,6,0,0,0,0,0,17,0,0,0
0,0,0,0,0,0,0,0,58,6,6,6,6,6,6,17,0,0,0,0,17,0,0,0
0,0,0,0,0,0,0,0,0,6,6,6,6,6,6,17,0,0,0,0,0,0,0,0
0,0,0,0,0,0,0,0,0,6,6,6,6,6,6,17,0,0,0,0,17,0,0,0
0,0,0,0,0,0,0,0,31,6,6,6,6,6,6,17,0,0,31,0,17,0,0,0
0,0,0,0,0,0,0,37,6,6,6,6,6,6,6,17,0,17,0,17,0,0,0,0
0,0,0,0,0,0,0,18,39,0,13,42,42,13,0,39,0,0,0,18,0,0,0,0
0,0,0,0,0,0,0,0,0,0,13,42,42,13,0,0,0,0,18,0,0,0,0,0
0,0,0,0,0,0,0,0,0,0,13,42,42,13,0,0,0,56,0,0,0,0,0,0
0,0,0,0,0,0,0,0,0,0,13,42,42,13,18,0,18,0,0,0,0,0,0,0
0,0,0,0,0,0,0,0,0,0,13,13,13,13,18,0,0,0,0,0,0,0,0,0
0,0,0,0,0,0,0,0,0,18,0,42,42,18,18,0,0,0,0,0,0,0,0,0
0,0,0,0,0,0,0,0,0,0,0,42,42,0,0,0,0,0,0,0,0,0,0,0
0,0,0,0,0,0,0,0,0,0,0,42,42,0,0,0,0,0,0,0,0,0,0,0
0,0,0,0,0,0,0,0,0,0,0,42,42,0,0,0,0,0,0,0,0,0,0,0
0,0,0,0,0,0,0,0,0,0,0,42,42,0,0,0,0,0,0,0,0,0,0,0
0,0,0,0,0,0,0,0,0,0,13,13,13,13,0,0,0,0,0,0,0,0,0,0
0,0,0,0,0,0,0,0,0,0,13,42,42,13,0,0,0,0,0,0,0,0,0,0
0,0,0,0,0,0,0,0,0,0,13,42,42,13,0,0,0,0,0,0,0,0,0,0
0,0,0,0,0,0,0,0,0,0,13,42,42,13,0,0,0,0,0,0,0,0,0,0
0,0,0,0,0,0,0,0,0,0,13,42,42,13,0,0,0,0,0,0,0,0,0,0
0,0,0,0,0,0,0,0,0,0,13,42,42,13,0,0,0,0,0,0,0,0,0,0
0,0,0,0,0,0,0,0,0,0,6,6,6,6,0,0,0,0,0,0,0,0,0,0
0,0,0,0,0,0,0,0,0,0,6,0,24,6,0,0,0,0,0,0,0,0,0,0
0,0,0,0,0,0,0,0,0,0,6,0,0,6,0,0,0,0,0,0,0,0,0,0
0,0,0,0,0,0,0,0,0,0,6,6,6,6,0,0,0,0,0,0,0,0,0,0
0,0,0,0,0,0,0,0,0,0,0,0,0,0,0,0,0,0,0,0,0,0,0,0
0,0,0,0,0,0,0,0,0,0,0,0,0,0,0,0,0,0,0,0,0,0,0,0
0,0,0,0,0,0,0,0,0,0,0,0,0,0,0,0,0,0,0,0,0,0,0,0
0,0,0,0,0,0,0,0,0,0,0,0,0,0,0,0,0,0,0,0,0,0,0,0
0,0,0,0,0,0,0,0,0,0,0,0,0,0,0,0,0,0,0,0,0,0,0,0
:endlayer
layer: 22
0,0,0,0,0,0,0,0,0,0,0,0,0,0,0,0,0,0,0,0,0,0,0,0
0,0,0,0,0,0,0,0,0,31,31,0,0,0,0,0,0,0,0,0,0,0,0,0
0,0,0,0,0,0,0,31,31,0,0,0,0,0,0,0,0,0,0,0,0,0,0,0
0,0,0,0,0,0,0,0,0,0,0,0,0,0,0,0,0,0,0,0,0,0,0,0
0,0,0,0,0,0,0,0,0,0,0,0,0,0,0,0,0,0,0,0,0,0,0,0
0,0,0,0,0,31,31,31,31,31,31,31,31,0,31,0,31,31,31,31,0,0,0,0
0,0,0,0,0,33,0,6,32,6,6,6,6,6,6,0,0,0,0,0,17,17,0,0
0,0,0,0,0,0,0,0,0,6,59,0,0,6,6,17,0,0,0,0,17,0,0,0
0,0,0,0,0,0,0,0,0,6,0,0,0,24,6,17,0,0,0,0,0,0,0,0
0,0,0,0,0,0,0,0,0,6,0,0,0,0,6,17,0,0,0,0,17,0,0,0
0,0,0,0,0,0,0,0,33,6,0,0,0,0,6,17,0,0,31,0,17,0,0,0
0,0,0,0,0,0,0,6,32,6,6,0,0,6,6,17,0,17,0,17,0,0,0,0
0,0,0,0,0,0,0,18,0,0,32,0,18,32,0,0,0,0,0,18,0,0,0,0
0,0,0,0,0,0,0,0,0,0,32,0,0,32,0,0,0,0,18,0,0,0,0,0
0,0,0,0,0,0,0,0,0,0,32,0,0,32,0,0,0,56,0,0,0,0,0,0
0,0,0,0,0,0,0,0,0,0,60,61,62,63,18,0,18,0,0,0,0,0,0,0
0,0,0,0,0,0,0,0,0,0,0,0,0,0,18,0,0,0,0,0,0,0,0,0
0,0,0,0,0,0,0,0,0,18,0,0,0,18,18,0,0,0,0,0,0,0,0,0
0,0,0,0,0,0,0,0,0,0,0,0,0,0,0,0,0,0,0,0,0,0,0,0
0,0,0,0,0,0,0,0,0,0,0,0,0,0,0,0,0,0,0,0,0,0,0,0
0,0,0,0,0,0,0,0,0,0,0,0,0,0,0,0,0,0,0,0,0,0,0,0
0,0,0,0,0,0,0,0,0,0,0,0,0,0,0,0,0,0,0,0,0,0,0,0
0,0,0,0,0,0,0,0,0,0,0,0,0,0,0,0,0,0,0,0,0,0,0,0
0,0,0,0,0,0,0,0,0,0,0,0,0,0,0,0,0,0,0,0,0,0,0,0
0,0,0,0,0,0,0,0,0,0,0,0,0,0,0,0,0,0,0,0,0,0,0,0
0,0,0,0,0,0,0,0,0,0,32,0,0,32,0,0,0,0,0,0,0,0,0,0
0,0,0,0,0,0,0,0,0,0,32,0,0,32,0,0,0,0,0,0,0,0,0,0
0,0,0,0,0,0,0,0,0,0,32,0,0,32,0,0,0,0,0,0,0,0,0,0
0,0,0,0,0,0,0,0,0,0,6,0,64,6,0,0,0,0,0,0,0,0,0,0
0,0,0,0,0,0,0,0,0,0,8,0,0,8,0,0,0,0,0,0,0,0,0,0
0,0,0,0,0,0,0,0,0,0,8,0,0,8,0,0,0,0,0,0,0,0,0,0
0,0,0,0,0,0,0,0,0,0,6,8,8,6,0,0,0,0,0,0,0,0,0,0
0,0,0,0,0,0,0,0,0,0,0,0,0,0,0,0,0,0,0,0,0,0,0,0
0,0,0,0,0,0,0,0,0,0,0,0,0,0,0,0,0,0,0,0,0,0,0,0
0,0,0,0,0,0,0,0,0,0,0,0,0,0,0,0,0,0,0,0,0,0,0,0
0,0,0,0,0,0,0,0,0,0,0,0,0,0,0,0,0,0,0,0,0,0,0,0
0,0,0,0,0,0,0,0,0,0,0,0,0,0,0,0,0,0,0,0,0,0,0,0
:endlayer
layer: 23
0,0,0,0,0,0,0,0,0,0,0,0,0,0,0,0,0,0,0,0,0,0,0,0
0,0,0,0,0,0,0,0,0,31,31,0,0,0,0,0,0,0,0,0,0,0,0,0
0,0,0,0,0,0,0,31,31,0,0,0,0,0,0,0,0,0,0,0,0,0,0,0
0,0,0,0,0,0,0,0,0,0,0,0,0,0,0,0,0,0,0,0,0,0,0,0
0,0,0,0,0,0,0,0,0,0,0,0,0,0,0,0,0,0,0,0,0,0,0,0
0,0,0,0,0,31,31,31,31,31,31,31,31,0,31,0,31,31,31,31,0,0,0,0
0,0,0,0,0,33,6,32,32,6,6,6,6,6,6,0,0,0,0,0,17,17,0,0
0,0,0,0,0,0,0,0,0,6,0,0,34,0,6,17,0,0,0,0,17,0,0,0
0,0,0,0,0,0,0,0,0,6,0,0,0,0,6,17,0,0,0,0,0,0,0,0
0,0,0,0,0,0,0,0,0,6,36,0,0,0,6,17,0,0,0,0,17,0,0,0
0,0,0,0,0,0,0,0,33,6,0,0,0,0,6,17,0,0,31,0,17,0,0,0
0,0,0,0,0,0,6,32,32,6,6,0,0,6,6,17,0,17,0,17,0,0,0,0
0,0,0,0,0,0,18,0,0,0,32,0,18,32,0,0,0,0,0,18,0,0,0,0
0,0,0,0,0,0,0,0,0,0,32,0,0,32,0,0,0,0,18,18,0,0,0,0
0,0,0,0,0,0,0,0,0,0,39,0,0,39,0,0,0,56,0,0,0,0,0,0
0,0,0,0,0,0,0,0,0,0,0,0,0,0,18,0,56,0,0,0,0,0,0,0
0,0,0,0,0,0,0,0,0,0,0,0,0,0,18,0,0,0,0,0,0,0,0,0
0,0,0,0,0,0,0,0,0,18,0,0,0,18,18,0,0,0,0,0,0,0,0,0
0,0,0,0,0,0,0,0,0,0,0,0,0,0,0,0,0,0,0,0,0,0,0,0
0,0,0,0,0,0,0,0,0,0,0,0,0,0,0,0,0,0,0,0,0,0,0,0
0,0,0,0,0,0,0,0,0,0,0,0,0,0,0,0,0,0,0,0,0,0,0,0
0,0,0,0,0,0,0,0,0,0,0,0,0,0,0,0,0,0,0,0,0,0,0,0
0,0,0,0,0,0,0,0,0,0,0,0,0,0,0,0,0,0,0,0,0,0,0,0
0,0,0,0,0,0,0,0,0,0,0,0,0,0,0,0,0,0,0,0,0,0,0,0
0,0,0,0,0,0,0,0,0,0,0,0,0,0,0,0,0,0,0,0,0,0,0,0
0,0,0,0,0,0,0,0,0,0,0,0,0,0,0,0,0,0,0,0,0,0,0,0
0,0,0,0,0,0,0,0,0,0,32,0,0,32,0,0,0,0,0,0,0,0,0,0
0,0,0,0,0,0,0,0,0,0,32,0,0,32,0,0,0,0,0,0,0,0,0,0
0,0,0,0,0,0,0,0,0,37,6,0,0,6,36,0,0,0,0,0,0,0,0,0
0,0,0,0,0,0,0,0,0,0,8,0,0,8,0,0,0,0,0,0,0,0,0,0
0,0,0,0,0,0,0,0,0,0,8,0,0,8,0,0,0,0,0,0,0,0,0,0
0,0,0,0,0,0,0,0,0,37,6,8,8,6,36,0,0,0,0,0,0,0,0,0
0,0,0,0,0,0,0,0,0,0,35,0,0,35,0,0,0,0,0,0,0,0,0,0
0,0,0,0,0,0,0,0,0,0,0,0,0,0,0,0,0,0,0,0,0,0,0,0
0,0,0,0,0,0,0,0,0,0,0,0,0,0,0,0,0,0,0,0,0,0,0,0
0,0,0,0,0,0,0,0,0,0,0,0,0,0,0,0,0,0,0,0,0,0,0,0
0,0,0,0,0,0,0,0,0,0,0,0,0,0,0,0,0,0,0,0,0,0,0,0
:endlayer
layer: 24
0,0,0,0,0,0,0,0,0,0,0,0,0,0,0,0,0,0,0,0,0,0,0,0
0,0,0,0,0,0,0,0,0,31,31,0,0,0,0,0,0,0,0,0,0,0,0,0
0,0,0,0,0,0,0,31,31,0,0,0,0,0,0,0,0,0,0,0,0,0,0,0
0,0,0,0,0,0,0,0,0,0,0,0,0,0,0,0,0,0,0,0,0,0,0,0
0,0,0,0,0,0,0,0,0,0,0,0,0,0,0,0,0,0,0,0,0,0,0,0
0,0,0,0,0,11,0,31,31,31,31,31,31,0,31,0,31,31,31,31,0,0,0,0
0,0,0,0,0,6,32,32,32,6,6,6,6,6,6,0,0,0,0,0,17,17,0,0
0,0,0,0,0,0,0,0,0,6,6,34,0,0,6,17,0,0,0,0,17,0,0,0
0,0,0,0,0,0,0,0,0,6,0,0,0,0,6,17,0,0,0,0,0,0,0,0
0,0,0,0,0,0,0,0,0,6,0,0,0,0,6,17,0,0,0,0,17,0,0,0
0,0,0,0,0,0,0,0,0,6,0,0,0,0,6,17,0,0,31,0,17,0,0,0
0,0,0,0,0,6,32,32,32,6,6,32,32,6,6,17,0,17,0,17,0,0,0,0
0,0,0,0,0,0,0,0,0,0,32,0,18,32,0,0,0,0,0,56,0,0,0,0
0,0,0,0,0,0,0,0,0,0,0,0,0,0,0,0,0,0,18,18,0,0,0,0
0,0,0,0,0,0,0,0,0,0,0,0,0,0,0,0,0,56,0,0,0,0,0,0
0,0,0,0,0,0,0,0,0,0,0,0,0,0,18,0,56,0,0,0,0,0,0,0
0,0,0,0,0,0,0,0,0,0,0,0,0,0,18,0,0,0,0,0,0,0,0,0
0,0,0,0,0,0,0,0,0,18,0,18,0,18,18,0,0,0,0,0,0,0,0,0
0,0,0,0,0,0,0,0,0,0,0,0,0,0,0,0,0,0,0,0,0,0,0,0
0,0,0,0,0,0,0,0,0,0,0,0,0,0,0,0,0,0,0,0,0,0,0,0
0,0,0,0,0,0,0,0,0,0,0,0,0,0,0,0,0,0,0,0,0,0,0,0
0,0,0,0,0,0,0,0,0,0,0,0,0,0,0,0,0,0,0,0,0,0,0,0
0,0,0,0,0,0,0,0,0,0,0,0,0,0,0,0,0,0,0,0,0,0,0,0
0,0,0,0,0,0,0,0,0,0,0,0,0,0,0,0,0,0,0,0,0,0,0,0
0,0,0,0,0,0,0,0,0,0,0,0,0,0,0,0,0,0,0,0,0,0,0,0
0,0,0,0,0,0,0,0,0,0,0,0,0,0,0,0,0,0,0,0,0,0,0,0
0,0,0,0,0,0,0,0,0,0,39,0,0,39,0,0,0,0,0,0,0,0,0,0
0,0,0,0,0,0,0,0,0,0,32,0,0,32,0,0,0,0,0,0,0,0,0,0
0,0,0,0,0,0,0,0,0,0,6,0,0,6,0,0,0,0,0,0,0,0,0,0
0,0,0,0,0,0,0,0,0,0,8,0,0,8,0,0,0,0,0,0,0,0,0,0
0,0,0,0,0,0,0,0,0,0,8,0,0,8,0,0,0,0,0,0,0,0,0,0
0,0,0,0,0,0,0,0,0,0,6,8,8,6,0,0,0,0,0,0,0,0,0,0
0,0,0,0,0,0,0,0,0,0,0,0,0,0,0,0,0,0,0,0,0,0,0,0
0,0,0,0,0,0,0,0,0,0,0,0,0,0,0,0,0,0,0,0,0,0,0,0
0,0,0,0,0,0,0,0,0,0,0,0,0,0,0,0,0,0,0,0,0,0,0,0
0,0,0,0,0,0,0,0,0,0,0,0,0,0,0,0,0,0,0,0,0,0,0,0
0,0,0,0,0,0,0,0,0,0,0,0,0,0,0,0,0,0,0,0,0,0,0,0
:endlayer
layer: 25
0,0,0,0,0,0,0,0,0,0,0,0,0,0,0,0,0,0,0,0,0,0,0,0
0,0,0,0,0,0,0,0,0,31,31,0,0,0,0,0,0,0,0,0,0,0,0,0
0,0,0,0,0,0,0,31,31,0,0,0,0,33,0,0,0,0,0,0,0,0,0,0
0,0,0,0,0,0,0,0,0,0,0,0,0,0,0,0,0,0,0,0,0,0,0,0
0,0,0,0,0,0,0,0,0,0,0,0,0,0,0,0,0,0,0,0,0,0,0,0
0,0,0,0,0,11,0,31,31,31,31,31,31,0,31,0,31,31,31,31,0,0,0,0
0,0,0,0,6,32,32,32,32,6,6,6,6,6,6,0,0,0,0,0,17,17,0,0
0,0,0,0,0,0,0,0,0,6,0,0,0,0,6,17,0,0,0,0,17,0,0,0
0,0,0,33,0,0,0,0,0,6,40,0,0,0,6,17,0,0,0,0,0,0,0,0
0,0,0,0,0,0,0,0,0,6,6,0,0,0,6,17,0,0,0,0,17,0,0,0
0,0,0,33,0,0,0,0,0,6,6,0,0,0,6,17,0,0,31,0,17,0,0,0
0,0,0,0,6,32,32,32,32,6,6,6,6,6,6,17,0,17,0,17,0,0,0,0
0,0,0,0,0,0,0,18,0,0,0,18,18,18,0,0,0,0,0,56,0,0,0,0
0,0,0,0,0,0,0,0,0,0,0,0,0,0,0,0,0,0,56,18,0,0,0,0
0,0,0,0,0,0,0,0,0,0,0,0,0,0,0,0,0,56,0,0,0,0,0,0
0,0,0,0,0,0,0,0,0,0,0,0,0,0,18,0,56,0,0,0,0,0,0,0
0,0,0,0,0,0,0,0,0,0,0,0,0,0,18,0,0,0,0,0,0,0,0,0
0,0,0,0,0,0,0,0,0,18,0,18,0,18,18,0,0,0,0,0,0,0,0,0
0,0,0,0,0,0,0,0,0,0,0,0,0,0,0,0,0,0,0,0,0,0,0,0
0,0,0,0,0,0,0,0,0,0,0,0,0,0,0,0,0,0,0,0,0,0,0,0
0,0,0,0,0,0,0,0,0,0,0,0,0,0,0,0,0,0,0,0,0,0,0,0
0,0,0,0,0,0,0,0,0,0,0,0,0,0,0,0,0,0,0,0,0,0,0,0
0,0,0,0,0,0,0,0,0,0,0,0,0,0,0,0,0,0,0,0,0,0,0,0
0,0,0,0,0,0,0,0,0,0,0,0,0,0,0,0,0,0,0,0,0,0,0,0
0,0,0,0,0,0,0,0,0,0,0,0,0,0,0,0,0,0,0,0,0,0,0,0
0,0,0,0,0,0,0,0,0,0,0,0,0,0,0,0,0,0,0,0,0,0,0,0
0,0,0,0,0,0,0,0,0,0,0,0,0,0,0,0,0,0,0,0,0,0,0,0
0,0,0,0,0,0,0,0,0,0,0,0,0,0,0,0,0,0,0,0,0,0,0,0
0,0,0,0,0,0,0,0,0,0,6,6,6,6,0,0,0,0,0,0,0,0,0,0
0,0,0,0,0,0,0,0,0,0,6,0,0,6,0,0,0,0,0,0,0,0,0,0
0,0,0,0,0,0,0,0,0,0,6,0,0,6,0,0,0,0,0,0,0,0,0,0
0,0,0,0,0,0,0,0,0,0,6,6,6,6,0,0,0,0,0,0,0,0,0,0
0,0,0,0,0,0,0,0,0,0,0,0,0,0,0,0,0,0,0,0,0,0,0,0
0,0,0,0,0,0,0,0,0,0,0,0,0,0,0,0,0,0,0,0,0,0,0,0
0,0,0,0,0,0,0,0,0,0,0,0,0,0,0,0,0,0,0,0,0,0,0,0
0,0,0,0,0,0,0,0,0,0,0,0,0,0,0,0,0,0,0,0,0,0,0,0
0,0,0,0,0,0,0,0,0,0,0,0,0,0,0,0,0,0,0,0,0,0,0,0
:endlayer
layer: 26
0,0,0,0,0,0,0,0,0,0,0,0,0,0,0,0,0,0,0,0,0,0,0,0
0,0,0,0,0,0,0,0,0,31,31,31,0,0,31,0,0,0,0,0,0,0,0,0
0,0,0,0,0,0,0,31,31,0,0,0,0,33,0,0,0,0,0,0,0,0,0,0
0,0,0,0,0,0,0,0,0,0,0,0,0,0,0,0,0,0,0,0,0,0,0,0
0,0,0,0,0,0,0,0,0,0,0,0,0,0,0,0,0,0,0,0,0,0,0,0
0,0,0,0,31,11,0,31,31,31,31,31,31,0,31,0,31,31,31,31,0,0,0,0
0,0,0,33,6,6,6,6,6,6,6,6,6,6,6,6,36,0,0,0,17,17,0,0
0,0,0,0,6,6,6,6,6,6,0,0,0,0,6,17,0,0,0,0,17,0,0,0
0,0,0,33,6,6,6,6,6,34,0,0,0,0,6,17,0,0,0,0,0,0,0,0
0,0,0,33,6,6,6,6,6,34,0,0,0,0,6,17,0,0,0,0,17,0,0,0
0,0,0,33,6,6,6,6,6,6,0,41,0,0,6,17,0,0,31,0,17,0,0,0
0,0,0,33,6,6,6,6,6,6,6,6,6,6,6,6,36,17,0,17,17,0,0,0
0,0,0,0,0,0,0,18,0,6,0,18,18,18,6,0,0,0,0,56,0,0,0,0
0,0,0,0,0,0,0,0,0,35,0,0,0,0,35,0,0,0,56,18,0,0,18,0
0,0,0,0,0,0,0,0,0,0,0,0,0,0,0,0,0,56,0,0,0,0,0,0
0,0,0,0,0,0,0,0,0,0,0,0,0,0,18,0,56,0,0,0,0,0,0,0
0,0,0,0,0,0,0,0,0,0,0,0,0,0,18,0,0,0,0,0,0,0,0,0
0,0,0,0,0,0,0,0,0,18,0,18,0,18,18,0,0,0,0,0,0,0,0,0
0,0,0,0,0,0,0,0,0,0,0,0,0,0,0,0,0,0,0,0,0,0,0,0
0,0,0,0,0,0,0,0,0,0,0,0,0,0,0,0,0,0,0,0,0,0,0,0
0,0,0,0,0,0,0,0,0,0,0,0,0,0,0,0,0,0,0,0,0,0,0,0
0,0,0,0,0,0,0,0,0,0,0,0,0,0,0,0,0,0,0,0,0,0,0,0
0,0,0,0,0,0,0,0,0,0,0,0,0,0,0,0,0,0,0,0,0,0,0,0
0,0,0,0,0,0,0,0,0,0,0,0,0,0,0,0,0,0,0,0,0,0,0,0
0,0,0,0,0,0,0,0,0,0,0,0,0,0,0,0,0,0,0,0,0,0,0,0
0,0,0,0,0,0,0,0,0,0,0,0,0,0,0,0,0,0,0,0,0,0,0,0
0,0,0,0,0,0,0,0,0,0,0,0,0,0,0,0,0,0,0,0,0,0,0,0
0,0,0,0,0,0,0,0,0,0,0,0,0,0,0,0,0,0,0,0,0,0,0,0
0,0,0,0,0,0,0,0,0,0,6,65,66,6,0,0,0,0,0,0,0,0,0,0
0,0,0,0,0,0,0,0,0,0,0,6,6,0,0,0,0,0,0,0,0,0,0,0
0,0,0,0,0,0,0,0,0,0,0,6,6,0,0,0,0,0,0,0,0,0,0,0
0,0,0,0,0,0,0,0,0,0,6,0,0,6,0,0,0,0,0,0,0,0,0,0
0,0,0,0,0,0,0,0,0,0,0,0,0,0,0,0,0,0,0,0,0,0,0,0
0,0,0,0,0,0,0,0,0,0,0,0,0,0,0,0,0,0,0,0,0,0,0,0
0,0,0,0,0,0,0,0,0,0,0,0,0,0,0,0,0,0,0,0,0,0,0,0
0,0,0,0,0,0,0,0,0,0,0,0,0,0,0,0,0,0,0,0,0,0,0,0
0,0,0,0,0,0,0,0,0,0,0,0,0,0,0,0,0,0,0,0,0,0,0,0
:endlayer
layer: 27
0,0,0,0,0,0,0,0,0,0,0,0,0,0,0,0,0,0,0,0,0,0,0,0
0,0,0,0,0,0,0,0,0,31,31,31,31,0,31,0,0,0,0,0,0,0,0,0
0,0,0,0,0,0,0,31,31,0,0,0,0,33,0,0,0,0,0,0,0,0,0,0
0,0,0,0,0,0,0,0,0,0,0,0,0,0,0,0,0,0,0,0,0,0,0,0
0,0,0,0,0,0,0,0,0,0,0,0,0,0,0,0,0,0,0,0,0,0,0,0
0,0,0,0,31,11,0,31,31,31,31,31,31,0,31,0,31,31,31,31,0,0,0,0
0,0,0,33,6,6,6,6,6,6,6,6,6,6,6,32,6,0,0,0,17,17,0,0
0,0,0,0,6,67,68,69,70,6,0,0,0,0,6,17,0,0,0,0,17,0,0,0
0,0,0,33,6,0,71,0,0,0,0,0,0,37,6,17,0,0,0,0,0,0,0,0
0,0,0,33,6,0,0,0,0,0,0,0,0,0,6,17,0,0,0,0,17,0,0,0
0,0,0,33,6,72,73,0,74,6,0,0,41,6,6,17,0,0,31,0,17,0,0,0
0,0,0,0,6,6,6,6,6,6,6,6,6,6,6,32,6,17,0,17,17,0,0,0
0,0,0,0,0,0,18,18,0,0,0,18,18,18,32,0,0,0,0,56,0,0,0,0
0,0,0,0,0,0,0,0,0,6,0,0,0,0,6,0,0,0,56,18,0,0,18,0
0,0,0,0,0,0,0,0,0,0,0,0,0,0,0,0,0,56,0,0,0,0,0,0
0,0,0,0,0,0,0,0,0,0,0,0,0,0,18,0,56,0,0,0,0,0,0,0
0,0,0,0,0,0,0,0,0,18,0,0,0,0,18,0,0,0,0,0,0,0,0,0
0,0,0,0,0,0,0,0,0,18,0,18,0,18,18,0,0,0,0,0,0,0,0,0
0,0,0,0,0,0,0,0,0,0,0,0,0,0,0,0,0,0,0,0,0,0,0,0
0,0,0,0,0,0,0,0,0,0,0,0,0,0,0,0,0,0,0,0,0,0,0,0
0,0,0,0,0,0,0,0,0,0,0,0,0,0,0,0,0,0,0,0,0,0,0,0
0,0,0,0,0,0,0,0,0,0,0,0,0,0,0,0,0,0,0,0,0,0,0,0
0,0,0,0,0,0,0,0,0,0,0,0,0,0,0,0,0,0,0,0,0,0,0,0
0,0,0,0,0,0,0,0,0,0,0,0,0,0,0,0,0,0,0,0,0,0,0,0
0,0,0,0,0,0,0,0,0,0,0,0,0,0,0,0,0,0,0,0,0,0,0,0
0,0,0,0,0,0,0,0,0,0,0,0,0,0,0,0,0,0,0,0,0,0,0,0
0,0,0,0,0,0,0,0,0,0,0,0,0,0,0,0,0,0,0,0,0,0,0,0
0,0,0,0,0,0,0,0,0,0,0,0,0,0,0,0,0,0,0,0,0,0,0,0
0,0,0,0,0,0,0,0,0,0,39,0,0,39,0,0,0,0,0,0,0,0,0,0
0,0,0,0,0,0,0,0,0,0,0,6,6,0,0,0,0,0,0,0,0,0,0,0
0,0,0,0,0,0,0,0,0,0,0,6,6,0,0,0,0,0,0,0,0,0,0,0
0,0,0,0,0,0,0,0,0,0,39,0,0,39,0,0,0,0,0,0,0,0,0,0
0,0,0,0,0,0,0,0,0,0,0,0,0,0,0,0,0,0,0,0,0,0,0,0
0,0,0,0,0,0,0,0,0,0,0,0,0,0,0,0,0,0,0,0,0,0,0,0
0,0,0,0,0,0,0,0,0,0,0,0,0,0,0,0,0,0,0,0,0,0,0,0
0,0,0,0,0,0,0,0,0,0,0,0,0,0,0,0,0,0,0,0,0,0,0,0
0,0,0,0,0,0,0,0,0,0,0,0,0,0,0,0,0,0,0,0,0,0,0,0
:endlayer
layer: 28
0,0,0,0,0,0,0,0,0,0,0,0,0,0,0,0,0,0,0,0,0,0,0,0
0,0,0,0,0,0,0,0,0,31,31,31,31,0,31,0,0,0,0,0,0,0,0,0
0,0,0,0,0,0,0,31,31,0,0,0,0,33,0,0,0,0,0,0,0,0,0,0
0,0,0,0,0,0,0,0,0,0,0,0,0,0,0,0,0,0,0,0,0,0,0,0
0,0,0,0,0,0,11,0,0,0,0,0,0,0,0,0,0,0,0,0,0,0,0,0
0,0,0,0,31,11,0,0,31,31,31,31,31,0,31,0,0,31,31,31,0,0,0,0
0,0,0,33,6,8,6,8,6,6,6,6,6,6,6,32,32,6,0,0,17,17,0,0
0,0,0,0,8,0,35,0,0,6,0,0,0,0,6,0,0,0,0,0,17,0,0,0
0,0,0,33,6,0,0,0,0,0,0,0,0,0,6,17,0,0,0,0,0,0,0,0
0,0,0,33,6,0,0,0,0,0,0,0,0,24,6,17,0,0,0,0,17,0,0,0
0,0,0,0,8,0,38,0,0,6,0,0,0,0,6,17,0,0,31,0,17,0,0,0
0,0,0,33,6,8,6,8,6,6,6,6,6,6,6,32,32,6,0,17,17,0,0,0
0,0,0,0,0,0,18,0,0,32,0,18,18,18,32,0,0,0,0,56,0,0,0,0
0,0,0,0,0,0,0,0,0,32,0,0,0,0,32,0,0,0,56,18,0,0,18,0
0,0,0,0,0,0,0,0,33,6,0,0,0,0,6,0,0,56,0,0,0,0,0,0
0,0,0,0,0,0,0,0,0,0,0,0,0,0,18,0,56,0,0,0,0,0,0,0
0,0,0,0,0,0,0,0,33,18,0,0,0,0,18,0,0,0,0,0,0,0,0,0
0,0,0,0,0,0,0,0,0,18,0,18,0,18,18,0,0,0,0,0,0,0,0,0
0,0,0,0,0,0,0,0,0,0,0,0,0,0,0,0,0,0,0,0,0,0,0,0
0,0,0,0,0,0,0,0,0,0,0,0,0,0,0,0,0,0,0,0,0,0,0,0
0,0,0,0,0,0,0,0,0,0,0,0,0,0,0,0,0,0,0,0,0,0,0,0
0,0,0,0,0,0,0,0,0,0,0,0,0,0,0,0,0,0,0,0,0,0,0,0
0,0,0,0,0,0,0,0,0,0,0,0,0,0,0,0,0,0,0,0,0,0,0,0
0,0,0,0,0,0,0,0,0,0,0,0,0,0,0,0,0,0,0,0,0,0,0,0
0,0,0,0,0,0,0,0,0,0,0,0,0,0,0,0,0,0,0,0,0,0,0,0
0,0,0,0,0,0,0,0,0,0,0,0,0,0,0,0,0,0,0,0,0,0,0,0
0,0,0,0,0,0,0,0,0,0,0,0,0,0,0,0,0,0,0,0,0,0,0,0
0,0,0,0,0,0,0,0,0,0,0,0,0,0,0,0,0,0,0,0,0,0,0,0
0,0,0,0,0,0,0,0,0,0,0,0,0,0,0,0,0,0,0,0,0,0,0,0
0,0,0,0,0,0,0,0,0,0,0,6,6,0,0,0,0,0,0,0,0,0,0,0
0,0,0,0,0,0,0,0,0,0,0,6,6,0,0,0,0,0,0,0,0,0,0,0
0,0,0,0,0,0,0,0,0,0,0,0,0,0,0,0,0,0,0,0,0,0,0,0
0,0,0,0,0,0,0,0,0,0,0,0,0,0,0,0,0,0,0,0,0,0,0,0
0,0,0,0,0,0,0,0,0,0,0,0,0,0,0,0,0,0,0,0,0,0,0,0
0,0,0,0,0,0,0,0,0,0,0,0,0,0,0,0,0,0,0,0,0,0,0,0
0,0,0,0,0,0,0,0,0,0,0,0,0,0,0,0,0,0,0,0,0,0,0,0
0,0,0,0,0,0,0,0,0,0,0,0,0,0,0,0,0,0,0,0,0,0,0,0
:endlayer
layer: 29
0,0,0,0,0,0,0,0,0,0,0,0,0,0,0,0,0,0,0,0,0,0,0,0
0,0,0,0,0,0,0,0,33,31,31,31,31,0,31,0,0,0,0,0,0,0,0,0
0,0,0,0,0,0,33,31,31,0,0,0,0,33,0,0,0,0,0,0,0,0,0,0
0,0,0,0,0,0,0,0,0,0,0,0,0,0,0,0,0,0,0,0,0,0,0,0
0,0,0,0,0,0,11,0,0,0,0,0,0,0,0,0,0,0,0,0,0,0,0,0
0,0,0,0,31,11,0,0,31,31,31,31,31,0,31,0,0,31,31,31,0,0,0,0
0,0,0,33,6,8,6,8,6,6,6,6,6,6,6,32,32,32,6,0,17,17,0,0
0,0,0,0,8,0,0,0,75,6,0,0,0,6,6,0,0,0,0,0,17,0,0,0
0,0,0,0,6,0,0,0,75,0,0,0,0,24,6,17,0,0,0,0,0,0,0,0
0,0,0,33,6,0,0,0,75,0,0,0,0,0,6,17,0,0,0,0,17,0,0,0
0,0,0,0,8,0,0,0,75,6,0,38,0,0,6,17,0,0,31,0,17,0,0,0
0,0,0,33,6,8,6,8,6,6,6,6,6,6,6,32,32,32,6,17,17,0,0,0
0,0,0,0,0,0,18,0,0,32,0,18,18,18,32,0,0,0,0,56,0,0,0,0
0,0,0,0,0,0,0,0,0,32,0,0,0,0,32,0,0,0,56,18,0,0,18,0
0,0,0,0,0,0,0,0,33,32,0,0,0,0,32,0,0,56,0,0,0,0,0,0
0,0,0,0,0,0,0,0,0,6,0,0,0,0,6,0,56,0,0,0,0,0,0,0
0,0,0,0,0,0,0,0,33,18,0,0,0,0,18,0,0,0,0,0,0,0,0,0
0,0,0,0,0,0,0,0,0,18,0,18,0,18,18,0,0,0,0,0,0,0,0,0
0,0,0,0,0,0,0,0,0,0,0,0,0,0,0,0,0,0,0,0,0,0,0,0
0,0,0,0,0,0,0,0,0,0,0,0,0,0,0,0,0,0,0,0,0,0,0,0
0,0,0,0,0,0,0,0,0,0,0,0,0,0,0,0,0,0,0,0,0,0,0,0
0,0,0,0,0,0,0,0,0,0,0,0,0,0,0,0,0,0,0,0,0,0,0,0
0,0,0,0,0,0,0,0,0,0,0,0,0,0,0,0,0,0,0,0,0,0,0,0
0,0,0,0,0,0,0,0,0,0,0,0,0,0,0,0,0,0,0,0,0,0,0,0
0,0,0,0,0,0,0,0,0,0,0,0,0,0,0,0,0,0,0,0,0,0,0,0
0,0,0,0,0,0,0,0,0,0,0,0,0,0,0,0,0,0,0,0,0,0,0,0
0,0,0,0,0,0,0,0,0,0,0,0,0,0,0,0,0,0,0,0,0,0,0,0
0,0,0,0,0,0,0,0,0,0,0,0,0,0,0,0,0,0,0,0,0,0,0,0
0,0,0,0,0,0,0,0,0,0,0,0,0,0,0,0,0,0,0,0,0,0,0,0
0,0,0,0,0,0,0,0,0,0,0,39,39,0,0,0,0,0,0,0,0,0,0,0
0,0,0,0,0,0,0,0,0,0,0,39,39,0,0,0,0,0,0,0,0,0,0,0
0,0,0,0,0,0,0,0,0,0,0,0,0,0,0,0,0,0,0,0,0,0,0,0
0,0,0,0,0,0,0,0,0,0,0,0,0,0,0,0,0,0,0,0,0,0,0,0
0,0,0,0,0,0,0,0,0,0,0,0,0,0,0,0,0,0,0,0,0,0,0,0
0,0,0,0,0,0,0,0,0,0,0,0,0,0,0,0,0,0,0,0,0,0,0,0
0,0,0,0,0,0,0,0,0,0,0,0,0,0,0,0,0,0,0,0,0,0,0,0
0,0,0,0,0,0,0,0,0,0,0,0,0,0,0,0,0,0,0,0,0,0,0,0
:endlayer
layer: 30
0,0,0,0,0,0,0,0,0,31,0,0,0,0,0,0,31,0,0,0,0,0,0,0
0,0,0,0,0,0,0,0,11,31,31,31,31,0,31,0,0,0,0,0,0,0,0,0
0,0,0,0,0,0,33,31,31,0,0,0,0,33,0,0,0,0,0,0,0,0,0,0
0,0,0,0,0,0,0,0,0,0,0,0,0,0,0,0,0,0,0,0,0,0,0,0
0,0,0,0,0,0,11,0,0,0,0,0,0,0,0,0,0,0,0,0,0,0,0,0
0,0,0,0,31,11,0,0,31,31,31,31,31,0,31,0,0,31,31,31,31,0,0,0
0,0,0,33,6,6,6,6,6,6,6,6,6,6,6,32,32,32,32,6,17,17,0,0
0,0,0,0,6,6,6,6,6,6,10,0,34,0,41,0,0,0,0,0,17,0,0,0
0,0,0,0,6,6,6,6,6,6,10,0,0,0,41,0,0,0,0,0,0,0,0,0
0,0,0,33,6,6,6,6,6,6,10,0,0,0,41,0,0,0,0,0,17,0,0,0
0,0,0,0,6,6,6,6,6,6,10,0,0,0,41,0,0,0,0,0,17,0,0,0
0,0,0,33,6,6,6,6,6,6,10,40,40,40,6,32,32,32,32,6,17,0,0,0
0,0,0,0,0,0,18,0,0,32,0,0,0,0,32,0,0,0,0,56,0,0,0,0
0,0,0,0,0,0,0,0,0,32,0,0,0,0,32,0,0,0,56,18,0,0,18,0
0,0,0,0,0,0,0,0,33,32,0,0,0,0,32,0,0,56,0,0,0,0,0,0
0,0,0,0,0,0,0,0,0,32,0,0,0,0,32,0,56,0,0,0,0,0,0,0
0,0,0,0,0,0,0,0,33,6,0,0,0,0,6,0,0,0,0,0,0,0,0,0
0,0,0,0,0,0,0,0,0,18,0,18,0,18,18,0,0,0,0,0,0,0,0,0
0,0,0,0,0,0,0,0,0,0,0,0,0,0,0,0,0,0,0,0,0,0,0,0
0,0,0,0,0,0,0,0,0,0,0,0,0,0,0,0,0,0,0,0,0,0,0,0
0,0,0,0,0,0,0,0,0,0,0,0,0,0,0,0,0,0,0,0,0,0,0,0
0,0,0,0,0,0,0,0,0,0,0,0,0,0,0,0,0,0,0,0,0,0,0,0
0,0,0,0,0,0,0,0,0,0,0,0,0,0,0,0,0,0,0,0,0,0,0,0
0,0,0,0,0,0,0,0,0,0,0,0,0,0,0,0,0,0,0,0,0,0,0,0
0,0,0,0,0,0,0,0,0,0,0,0,0,0,0,0,0,0,0,0,0,0,0,0
0,0,0,0,0,0,0,0,0,0,0,0,0,0,0,0,0,0,0,0,0,0,0,0
0,0,0,0,0,0,0,0,0,0,0,0,0,0,0,0,0,0,0,0,0,0,0,0
0,0,0,0,0,0,0,0,0,0,0,0,0,0,0,0,0,0,0,0,0,0,0,0
0,0,0,0,0,0,0,0,0,0,0,0,0,0,0,0,0,0,0,0,0,0,0,0
0,0,0,0,0,0,0,0,0,0,0,0,0,0,0,0,0,0,0,0,0,0,0,0
0,0,0,0,0,0,0,0,0,0,0,0,0,0,0,0,0,0,0,0,0,0,0,0
0,0,0,0,0,0,0,0,0,0,0,0,0,0,0,0,0,0,0,0,0,0,0,0
0,0,0,0,0,0,0,0,0,0,0,0,0,0,0,0,0,0,0,0,0,0,0,0
0,0,0,0,0,0,0,0,0,0,0,0,0,0,0,0,0,0,0,0,0,0,0,0
0,0,0,0,0,0,0,0,0,0,0,0,0,0,0,0,0,0,0,0,0,0,0,0
0,0,0,0,0,0,0,0,0,0,0,0,0,0,0,0,0,0,0,0,0,0,0,0
0,0,0,0,0,0,0,0,0,0,0,0,0,0,0,0,0,0,0,0,0,0,0,0
:endlayer
layer: 31
0,0,0,0,0,0,0,0,0,31,0,0,0,0,0,0,31,0,0,0,0,0,0,0
0,0,0,0,0,0,0,0,11,31,31,31,31,0,31,0,0,0,0,0,0,0,0,0
0,0,0,0,0,0,33,31,31,0,0,0,0,33,0,0,0,0,0,0,0,0,0,0
0,0,0,0,0,0,0,0,0,0,0,0,0,0,0,0,0,0,0,0,0,0,0,0
0,0,0,0,0,0,11,0,0,0,0,0,0,0,0,0,0,0,0,0,0,0,0,0
0,0,0,0,31,11,0,0,31,31,31,31,31,0,31,0,0,31,31,31,31,0,0,0
0,0,0,0,6,33,6,0,6,6,6,6,6,6,6,6,6,6,6,6,17,17,0,0
0,0,0,0,76,0,18,0,33,6,6,34,0,0,0,41,6,6,6,6,17,0,0,0
0,0,0,0,6,0,0,0,33,6,0,0,0,0,0,41,6,6,6,6,0,0,0,0
0,0,0,33,6,0,0,0,0,77,0,0,0,0,0,41,6,6,6,6,17,0,0,0
0,0,0,0,0,0,0,0,0,6,0,0,0,0,0,41,6,6,6,6,17,0,0,0
0,0,0,33,6,0,6,0,6,6,0,0,0,0,6,41,6,6,6,6,17,0,0,0
0,0,0,0,0,0,0,0,0,6,40,40,40,40,40,6,6,6,6,56,0,0,0,0
0,0,0,0,0,0,0,17,0,6,6,6,6,6,6,6,6,6,56,58,0,0,18,0
0,0,0,0,0,0,0,0,33,6,6,6,6,6,6,6,6,56,0,0,0,0,0,0
0,0,0,0,0,0,0,0,0,6,6,6,6,6,6,6,56,0,0,0,0,0,0,0
0,0,0,0,0,0,0,0,33,6,6,6,6,6,6,0,0,0,0,0,0,0,0,0
0,0,0,0,0,0,0,0,0,18,0,18,0,18,18,0,0,0,0,0,0,0,0,0
0,0,0,0,0,0,0,0,0,0,0,0,0,0,0,0,0,0,0,0,0,0,0,0
0,0,0,0,0,0,0,0,0,0,0,0,0,0,0,0,0,0,0,0,0,0,0,0
0,0,0,0,0,0,0,0,0,0,0,0,0,0,0,0,0,0,0,0,0,0,0,0
0,0,0,0,0,0,0,0,0,0,0,0,0,0,0,0,0,0,0,0,0,0,0,0
0,0,0,0,0,0,0,0,0,0,0,0,0,0,0,0,0,0,0,0,0,0,0,0
0,0,0,0,0,0,0,0,0,0,0,0,0,0,0,0,0,0,0,0,0,0,0,0
0,0,0,0,0,0,0,0,0,0,0,0,0,0,0,0,0,0,0,0,0,0,0,0
0,0,0,0,0,0,0,0,0,0,0,0,0,0,0,0,0,0,0,0,0,0,0,0
0,0,0,0,0,0,0,0,0,0,0,0,0,0,0,0,0,0,0,0,0,0,0,0
0,0,0,0,0,0,0,0,0,0,0,0,0,0,0,0,0,0,0,0,0,0,0,0
0,0,0,0,0,0,0,0,0,0,0,0,0,0,0,0,0,0,0,0,0,0,0,0
0,0,0,0,0,0,0,0,0,0,0,0,0,0,0,0,0,0,0,0,0,0,0,0
0,0,0,0,0,0,0,0,0,0,0,0,0,0,0,0,0,0,0,0,0,0,0,0
0,0,0,0,0,0,0,0,0,0,0,0,0,0,0,0,0,0,0,0,0,0,0,0
0,0,0,0,0,0,0,0,0,0,0,0,0,0,0,0,0,0,0,0,0,0,0,0
0,0,0,0,0,0,0,0,0,0,0,0,0,0,0,0,0,0,0,0,0,0,0,0
0,0,0,0,0,0,0,0,0,0,0,0,0,0,0,0,0,0,0,0,0,0,0,0
0,0,0,0,0,0,0,0,0,0,0,0,0,0,0,0,0,0,0,0,0,0,0,0
0,0,0,0,0,0,0,0,0,0,0,0,0,0,0,0,0,0,0,0,0,0,0,0
:endlayer
layer: 32
0,0,0,0,0,0,0,0,0,31,0,0,0,0,0,0,31,0,0,0,0,0,0,0
0,0,0,0,0,0,0,0,11,31,46,31,31,0,31,0,31,0,0,0,0,0,0,0
0,0,0,0,0,0,33,31,11,0,0,0,0,33,0,0,0,0,0,0,0,0,0,0
0,0,0,0,0,0,33,0,0,0,0,0,0,0,0,0,0,0,0,0,0,0,0,0
0,0,0,0,0,0,11,0,0,0,0,0,0,0,0,0,0,0,0,31,0,0,0,0
0,0,0,0,0,11,0,0,0,31,31,31,31,0,0,0,0,0,31,31,31,0,0,0
0,0,0,0,39,33,0,0,39,6,6,6,6,6,6,6,6,6,6,6,17,17,0,0
0,0,0,0,33,0,18,0,33,6,0,0,0,0,0,0,78,79,75,6,17,0,0,0
0,0,0,0,33,0,0,0,33,6,40,0,0,0,0,0,0,0,80,6,0,0,0,0
0,0,0,0,0,0,0,0,33,81,0,0,0,0,0,0,0,32,80,6,17,0,0,0
0,0,0,0,0,0,0,0,0,6,0,0,0,0,0,0,0,0,80,6,17,0,0,0
0,0,0,0,39,0,0,0,39,6,0,0,0,0,6,0,82,83,75,6,17,0,0,0
0,0,0,0,0,0,0,0,0,6,0,0,0,0,0,0,0,0,6,56,0,0,0,0
0,0,0,0,0,0,0,17,0,6,0,84,79,79,85,0,74,6,56,58,0,18,18,0
0,0,0,0,0,0,0,0,33,6,75,0,0,0,0,0,6,56,0,0,18,0,0,0
0,0,0,0,0,0,0,0,0,6,75,86,83,83,75,6,56,0,0,0,0,0,0,0
0,0,0,0,0,0,0,0,33,6,6,6,6,6,6,0,0,0,0,0,0,0,0,0
0,0,0,0,0,0,0,0,0,18,0,18,0,18,18,0,0,0,0,0,0,0,0,0
0,0,0,0,0,0,0,0,0,0,0,0,0,0,0,0,0,0,0,0,0,0,0,0
0,0,0,0,0,0,0,0,0,0,0,0,0,0,0,0,0,0,0,0,0,0,0,0
0,0,0,0,0,0,0,0,0,0,0,0,0,0,0,0,0,0,0,0,0,0,0,0
0,0,0,0,0,0,0,0,0,0,0,0,0,0,0,0,0,0,0,0,0,0,0,0
0,0,0,0,0,0,0,0,0,0,0,0,0,0,0,0,0,0,0,0,0,0,0,0
0,0,0,0,0,0,0,0,0,0,0,0,0,0,0,0,0,0,0,0,0,0,0,0
0,0,0,0,0,0,0,0,0,0,0,0,0,0,0,0,0,0,0,0,0,0,0,0
0,0,0,0,0,0,0,0,0,0,0,0,0,0,0,0,0,0,0,0,0,0,0,0
0,0,0,0,0,0,0,0,0,0,0,0,0,0,0,0,0,0,0,0,0,0,0,0
0,0,0,0,0,0,0,0,0,0,0,0,0,0,0,0,0,0,0,0,0,0,0,0
0,0,0,0,0,0,0,0,0,0,0,0,0,0,0,0,0,0,0,0,0,0,0,0
0,0,0,0,0,0,0,0,0,0,0,0,0,0,0,0,0,0,0,0,0,0,0,0
0,0,0,0,0,0,0,0,0,0,0,0,0,0,0,0,0,0,0,0,0,0,0,0
0,0,0,0,0,0,0,0,0,0,0,0,0,0,0,0,0,0,0,0,0,0,0,0
0,0,0,0,0,0,0,0,0,0,0,0,0,0,0,0,0,0,0,0,0,0,0,0
0,0,0,0,0,0,0,0,0,0,0,0,0,0,0,0,0,0,0,0,0,0,0,0
0,0,0,0,0,0,0,0,0,0,0,0,0,0,0,0,0,0,0,0,0,0,0,0
0,0,0,0,0,0,0,0,0,0,0,0,0,0,0,0,0,0,0,0,0,0,0,0
0,0,0,0,0,0,0,0,0,0,0,0,0,0,0,0,0,0,0,0,0,0,0,0
:endlayer
layer: 33
0,0,0,0,0,0,0,0,0,31,0,0,0,0,0,0,31,0,0,0,0,0,0,0
0,0,0,0,0,0,0,0,11,31,46,31,31,0,31,31,31,0,0,0,0,0,0,0
0,0,0,0,0,0,33,31,11,0,0,0,0,33,0,0,0,0,0,0,0,0,0,0
0,0,0,0,0,0,33,0,0,0,0,0,0,0,0,0,0,0,0,0,0,0,0,0
0,0,0,0,0,0,11,0,0,0,0,0,0,0,0,0,0,0,0,31,0,0,0,0
0,0,0,0,0,11,0,0,0,31,0,31,31,0,0,0,0,0,31,31,31,0,0,0
0,0,0,0,33,33,0,0,0,6,8,6,6,6,6,8,8,6,8,6,17,17,0,0
0,0,0,0,33,0,18,0,33,6,0,0,0,0,0,0,0,0,0,8,17,0,0,0
0,0,0,0,33,0,0,0,33,6,0,0,0,0,0,0,0,0,0,6,0,0,0,0
0,0,0,0,0,0,0,0,33,6,40,0,0,0,0,0,0,87,0,8,0,0,0,0
0,0,0,0,0,0,0,0,0,6,6,0,0,0,0,0,0,0,0,6,17,0,0,0
0,0,0,0,0,0,0,0,0,8,0,0,0,0,6,0,0,0,75,6,17,0,0,0
0,0,0,0,0,0,0,0,0,6,0,0,0,0,0,0,0,0,6,56,0,0,0,17
0,0,0,0,0,0,0,17,0,6,0,0,0,0,0,0,0,6,56,58,0,18,18,0
0,0,0,0,0,0,0,0,33,6,75,0,0,0,0,0,6,56,0,0,18,0,0,0
0,0,0,0,0,0,0,0,0,8,75,0,0,0,75,6,56,0,0,0,0,0,0,0
0,0,0,0,0,0,0,0,33,6,8,6,8,8,6,0,0,0,0,0,0,0,0,0
0,0,0,0,0,0,0,0,0,18,0,18,0,0,18,0,0,0,0,0,0,0,0,0
0,0,0,0,0,0,0,0,0,0,0,0,0,0,0,0,0,0,0,0,0,0,0,0
0,0,0,0,0,0,0,0,0,0,0,0,0,0,0,0,0,0,0,0,0,0,0,0
0,0,0,0,0,0,0,0,0,0,0,0,0,0,0,0,0,0,0,0,0,0,0,0
0,0,0,0,0,0,0,0,0,0,0,0,0,0,0,0,0,0,0,0,0,0,0,0
0,0,0,0,0,0,0,0,0,0,0,0,0,0,0,0,0,0,0,0,0,0,0,0
0,0,0,0,0,0,0,0,0,0,0,0,0,0,0,0,0,0,0,0,0,0,0,0
0,0,0,0,0,0,0,0,0,0,0,0,0,0,0,0,0,0,0,0,0,0,0,0
0,0,0,0,0,0,0,0,0,0,0,0,0,0,0,0,0,0,0,0,0,0,0,0
0,0,0,0,0,0,0,0,0,0,0,0,0,0,0,0,0,0,0,0,0,0,0,0
0,0,0,0,0,0,0,0,0,0,0,0,0,0,0,0,0,0,0,0,0,0,0,0
0,0,0,0,0,0,0,0,0,0,0,0,0,0,0,0,0,0,0,0,0,0,0,0
0,0,0,0,0,0,0,0,0,0,0,0,0,0,0,0,0,0,0,0,0,0,0,0
0,0,0,0,0,0,0,0,0,0,0,0,0,0,0,0,0,0,0,0,0,0,0,0
0,0,0,0,0,0,0,0,0,0,0,0,0,0,0,0,0,0,0,0,0,0,0,0
0,0,0,0,0,0,0,0,0,0,0,0,0,0,0,0,0,0,0,0,0,0,0,0
0,0,0,0,0,0,0,0,0,0,0,0,0,0,0,0,0,0,0,0,0,0,0,0
0,0,0,0,0,0,0,0,0,0,0,0,0,0,0,0,0,0,0,0,0,0,0,0
0,0,0,0,0,0,0,0,0,0,0,0,0,0,0,0,0,0,0,0,0,0,0,0
0,0,0,0,0,0,0,0,0,0,0,0,0,0,0,0,0,0,0,0,0,0,0,0
:endlayer
layer: 34
0,0,0,0,0,0,0,0,0,31,0,0,0,0,0,0,31,0,0,0,0,0,0,0
0,0,0,0,0,0,0,0,11,31,46,31,31,0,31,31,31,0,0,0,0,0,0,0
0,0,0,0,0,0,33,31,11,0,0,0,0,33,0,0,0,0,0,0,0,0,0,0
0,0,0,0,0,0,33,0,0,0,0,0,0,0,0,0,0,0,0,0,0,0,0,0
0,0,0,0,0,0,11,0,0,0,0,0,0,0,0,0,0,0,0,31,0,0,0,0
0,0,0,0,0,11,0,0,0,31,0,31,31,0,0,0,0,0,31,31,31,0,0,0
0,0,0,0,33,33,0,0,0,6,8,6,6,6,6,8,8,6,8,6,17,17,0,0
0,0,0,0,33,0,18,0,33,6,0,0,0,0,0,0,0,0,0,8,17,0,0,0
0,0,0,0,33,0,0,0,33,6,0,0,0,0,0,0,0,0,0,6,0,0,0,0
0,0,0,0,0,0,0,0,33,6,0,0,0,0,0,0,0,0,0,8,0,0,0,0
0,0,0,0,0,0,0,0,0,8,0,41,0,0,6,36,0,0,0,6,17,0,0,0
0,0,0,0,0,0,0,0,0,8,0,0,0,6,6,0,0,0,37,6,17,0,0,0
0,0,0,0,0,0,0,0,0,6,0,0,0,35,0,0,0,0,6,17,0,0,0,17
0,0,0,0,0,0,88,17,0,6,0,0,0,0,0,0,0,6,17,58,0,18,18,0
0,0,0,0,0,0,0,0,33,6,0,0,0,0,0,0,6,56,0,0,18,0,0,0
0,0,0,0,0,0,0,0,0,8,75,0,0,0,38,6,18,0,0,0,0,0,0,0
0,0,0,0,0,0,0,0,33,6,8,6,8,8,6,0,0,0,0,0,0,0,0,0
0,0,0,0,0,0,0,0,0,18,0,0,0,0,18,0,0,0,0,0,0,0,0,0
0,0,0,0,0,0,0,0,0,0,0,0,0,0,0,0,0,0,0,0,0,0,0,0
0,0,0,0,0,0,0,0,0,0,0,0,0,0,0,0,0,0,0,0,0,0,0,0
0,0,0,0,0,0,0,0,0,0,0,0,0,0,0,0,0,0,0,0,0,0,0,0
0,0,0,0,0,0,0,0,0,0,0,0,0,0,0,0,0,0,0,0,0,0,0,0
0,0,0,0,0,0,0,0,0,0,0,0,0,0,0,0,0,0,0,0,0,0,0,0
0,0,0,0,0,0,0,0,0,0,0,0,0,0,0,0,0,0,0,0,0,0,0,0
0,0,0,0,0,0,0,0,0,0,0,0,0,0,0,0,0,0,0,0,0,0,0,0
0,0,0,0,0,0,0,0,0,0,0,0,0,0,0,0,0,0,0,0,0,0,0,0
0,0,0,0,0,0,0,0,0,0,0,0,0,0,0,0,0,0,0,0,0,0,0,0
0,0,0,0,0,0,0,0,0,0,0,0,0,0,0,0,0,0,0,0,0,0,0,0
0,0,0,0,0,0,0,0,0,0,0,0,0,0,0,0,0,0,0,0,0,0,0,0
0,0,0,0,0,0,0,0,0,0,0,0,0,0,0,0,0,0,0,0,0,0,0,0
0,0,0,0,0,0,0,0,0,0,0,0,0,0,0,0,0,0,0,0,0,0,0,0
0,0,0,0,0,0,0,0,0,0,0,0,0,0,0,0,0,0,0,0,0,0,0,0
0,0,0,0,0,0,0,0,0,0,0,0,0,0,0,0,0,0,0,0,0,0,0,0
0,0,0,0,0,0,0,0,0,0,0,0,0,0,0,0,0,0,0,0,0,0,0,0
0,0,0,0,0,0,0,0,0,0,0,0,0,0,0,0,0,0,0,0,0,0,0,0
0,0,0,0,0,0,0,0,0,0,0,0,0,0,0,0,0,0,0,0,0,0,0,0
0,0,0,0,0,0,0,0,0,0,0,0,0,0,0,0,0,0,0,0,0,0,0,0
:endlayer
layer: 35
0,0,0,0,0,0,0,0,0,31,0,0,0,0,0,0,31,0,0,0,0,0,0,0
0,0,0,0,0,0,0,0,11,31,46,31,31,0,31,31,31,0,0,0,0,0,0,0
0,0,0,0,0,0,33,31,11,0,0,0,0,33,0,0,0,0,0,0,0,0,0,0
0,0,0,0,0,0,33,0,0,0,0,0,0,0,0,0,0,0,17,0,0,0,0,0
0,0,0,0,0,0,11,0,0,0,0,0,0,0,0,0,0,0,0,31,0,0,0,0
0,0,0,0,0,11,0,0,0,31,0,31,31,0,0,0,0,0,31,31,31,0,0,0
0,0,0,0,33,33,0,0,0,6,6,6,6,6,6,40,40,40,40,89,17,17,0,0
0,0,0,0,33,0,18,0,33,6,0,0,0,0,6,0,0,0,0,34,17,0,0,0
0,0,0,0,33,0,0,0,33,8,0,0,0,0,6,0,0,0,0,34,0,0,0,0
0,0,0,0,0,0,0,0,33,6,0,0,0,0,6,0,0,0,0,34,0,0,0,0
0,0,0,0,0,0,0,0,0,6,0,0,41,6,6,0,0,0,0,34,0,0,0,0
0,0,0,0,0,0,0,0,0,6,6,6,6,6,6,0,0,0,0,34,0,0,0,0
0,0,0,0,0,0,0,0,0,41,0,0,0,0,0,0,0,0,6,17,0,0,0,17
0,0,0,0,0,0,0,0,0,41,0,0,0,0,0,0,0,6,56,58,0,18,18,0
0,0,0,0,0,0,18,18,0,41,0,0,0,0,0,0,6,18,0,0,18,0,0,0
0,0,0,0,0,0,0,0,0,41,0,0,0,0,0,6,18,0,0,0,0,0,0,0
0,0,0,0,0,0,0,0,0,89,24,24,24,24,24,0,0,0,0,0,0,0,0,0
0,0,0,0,0,0,0,0,0,0,0,0,0,0,0,0,0,0,0,0,0,0,0,0
0,0,0,0,0,0,0,0,0,0,0,0,0,0,0,0,0,0,0,0,0,0,0,0
0,0,0,0,0,0,0,0,0,0,0,0,0,0,0,0,0,0,0,0,0,0,0,0
0,0,0,0,0,0,0,0,0,0,0,0,0,0,0,0,0,0,0,0,0,0,0,0
0,0,0,0,0,0,0,0,0,0,0,0,0,0,0,0,0,0,0,0,0,0,0,0
0,0,0,0,0,0,0,0,0,0,0,0,0,0,0,0,0,0,0,0,0,0,0,0
0,0,0,0,0,0,0,0,0,0,0,0,0,0,0,0,0,0,0,0,0,0,0,0
0,0,0,0,0,0,0,0,0,0,0,0,0,0,0,0,0,0,0,0,0,0,0,0
0,0,0,0,0,0,0,0,0,0,0,0,0,0,0,0,0,0,0,0,0,0,0,0
0,0,0,0,0,0,0,0,0,0,0,0,0,0,0,0,0,0,0,0,0,0,0,0
0,0,0,0,0,0,0,0,0,0,0,0,0,0,0,0,0,0,0,0,0,0,0,0
0,0,0,0,0,0,0,0,0,0,0,0,0,0,0,0,0,0,0,0,0,0,0,0
0,0,0,0,0,0,0,0,0,0,0,0,0,0,0,0,0,0,0,0,0,0,0,0
0,0,0,0,0,0,0,0,0,0,0,0,0,0,0,0,0,0,0,0,0,0,0,0
0,0,0,0,0,0,0,0,0,0,0,0,0,0,0,0,0,0,0,0,0,0,0,0
0,0,0,0,0,0,0,0,0,0,0,0,0,0,0,0,0,0,0,0,0,0,0,0
0,0,0,0,0,0,0,0,0,0,0,0,0,0,0,0,0,0,0,0,0,0,0,0
0,0,0,0,0,0,0,0,0,0,0,0,0,0,0,0,0,0,0,0,0,0,0,0
0,0,0,0,0,0,0,0,0,0,0,0,0,0,0,0,0,0,0,0,0,0,0,0
0,0,0,0,0,0,0,0,0,0,0,0,0,0,0,0,0,0,0,0,0,0,0,0
:endlayer
layer: 36
0,0,0,0,0,0,0,0,0,31,0,0,0,0,0,0,31,0,0,0,0,0,0,0
0,0,0,0,0,0,0,0,11,31,46,31,31,0,31,31,31,0,0,0,0,0,0,0
0,0,0,0,0,0,33,31,11,0,0,0,0,33,0,0,0,0,0,0,0,0,0,0
0,0,0,0,0,0,33,0,0,0,0,0,0,0,0,0,0,0,17,0,0,0,0,0
0,0,0,0,0,0,11,0,0,0,0,0,0,0,0,0,0,0,0,31,0,0,0,0
0,0,0,0,0,11,0,0,0,31,0,0,31,0,0,0,0,0,31,31,31,0,0,0
0,0,0,0,33,33,0,0,0,6,6,8,6,6,6,0,0,0,0,0,17,17,0,0
0,0,0,0,33,0,18,0,33,6,0,0,0,0,6,40,40,40,89,0,17,0,0,0
0,0,0,0,33,0,0,0,33,6,0,0,0,0,6,0,0,0,34,56,0,0,0,0
0,0,0,0,0,0,0,0,33,6,0,0,0,24,6,0,0,0,34,17,0,0,0,0
0,0,0,0,0,0,0,0,0,6,0,0,0,0,6,0,0,0,34,17,0,0,0,0
0,0,0,0,0,0,0,0,0,6,6,6,6,6,6,0,0,0,34,17,0,0,0,0
0,0,0,0,0,0,0,0,0,0,41,0,0,0,0,0,0,6,90,0,0,0,0,17
0,0,0,0,0,0,0,0,0,0,41,0,0,0,0,0,6,56,0,58,0,18,18,0
0,0,0,0,0,18,18,18,0,0,41,0,0,0,0,6,56,0,0,0,18,0,0,0
0,0,0,0,0,0,0,0,0,0,89,24,24,24,24,56,0,0,0,0,0,0,0,0
0,0,0,0,0,0,0,0,0,18,18,18,18,18,18,0,0,0,0,0,0,0,0,0
0,0,0,0,0,0,0,0,0,0,0,0,0,0,0,0,0,0,0,0,0,0,0,0
0,0,0,0,0,0,0,0,0,0,0,0,0,0,0,0,0,0,0,0,0,0,0,0
0,0,0,0,0,0,0,0,0,0,0,0,0,0,0,0,0,0,0,0,0,0,0,0
0,0,0,0,0,0,0,0,0,0,0,0,0,0,0,0,0,0,0,0,0,0,0,0
0,0,0,0,0,0,0,0,0,0,0,0,0,0,0,0,0,0,0,0,0,0,0,0
0,0,0,0,0,0,0,0,0,0,0,0,0,0,0,0,0,0,0,0,0,0,0,0
0,0,0,0,0,0,0,0,0,0,0,0,0,0,0,0,0,0,0,0,0,0,0,0
0,0,0,0,0,0,0,0,0,0,0,0,0,0,0,0,0,0,0,0,0,0,0,0
0,0,0,0,0,0,0,0,0,0,0,0,0,0,0,0,0,0,0,0,0,0,0,0
0,0,0,0,0,0,0,0,0,0,0,0,0,0,0,0,0,0,0,0,0,0,0,0
0,0,0,0,0,0,0,0,0,0,0,0,0,0,0,0,0,0,0,0,0,0,0,0
0,0,0,0,0,0,0,0,0,0,0,0,0,0,0,0,0,0,0,0,0,0,0,0
0,0,0,0,0,0,0,0,0,0,0,0,0,0,0,0,0,0,0,0,0,0,0,0
0,0,0,0,0,0,0,0,0,0,0,0,0,0,0,0,0,0,0,0,0,0,0,0
0,0,0,0,0,0,0,0,0,0,0,0,0,0,0,0,0,0,0,0,0,0,0,0
0,0,0,0,0,0,0,0,0,0,0,0,0,0,0,0,0,0,0,0,0,0,0,0
0,0,0,0,0,0,0,0,0,0,0,0,0,0,0,0,0,0,0,0,0,0,0,0
0,0,0,0,0,0,0,0,0,0,0,0,0,0,0,0,0,0,0,0,0,0,0,0
0,0,0,0,0,0,0,0,0,0,0,0,0,0,0,0,0,0,0,0,0,0,0,0
0,0,0,0,0,0,0,0,0,0,0,0,0,0,0,0,0,0,0,0,0,0,0,0
:endlayer
layer: 37
0,0,0,0,0,0,0,0,0,31,0,0,0,0,0,0,31,0,0,0,0,0,0,0
0,0,0,0,0,0,0,0,11,31,46,31,31,0,31,31,31,0,0,0,0,0,0,0
0,0,0,0,0,0,33,31,11,0,0,0,0,33,0,0,0,0,0,0,0,0,0,0
0,0,0,0,0,0,33,0,0,0,0,0,0,0,0,0,0,0,17,0,0,0,0,0
0,0,0,0,0,0,11,0,0,38,0,0,0,0,38,0,0,0,0,31,0,0,0,0
0,0,0,0,0,11,0,0,0,6,0,0,31,0,6,0,0,0,45,31,31,0,0,0
0,0,0,0,33,33,0,37,6,6,6,6,6,6,6,6,36,0,0,0,17,17,0,0
0,0,0,0,33,0,18,0,33,6,0,0,0,6,6,0,0,0,0,0,17,0,0,0
0,0,0,0,33,0,0,0,33,6,0,0,0,24,6,40,40,89,0,56,0,0,0,0
0,0,0,0,0,0,0,0,0,8,0,0,0,0,6,0,0,34,0,17,0,0,0,0
0,0,0,0,0,0,0,0,0,6,0,38,0,0,6,0,0,34,0,17,0,0,0,0
0,0,0,0,0,0,33,37,6,6,6,6,6,6,6,0,0,34,0,17,0,0,0,0
0,0,0,0,0,0,0,0,0,6,0,41,0,0,0,0,6,0,90,0,0,0,0,17
0,0,0,0,33,58,32,0,0,35,0,41,0,0,0,6,0,56,0,58,0,18,18,0
0,0,0,0,0,18,18,18,0,0,0,89,24,24,24,0,56,0,0,0,18,0,0,0
0,0,0,0,0,0,0,0,0,0,0,0,0,0,0,56,0,0,0,0,0,0,0,0
0,0,0,0,0,0,0,0,0,18,18,18,18,18,18,0,0,0,0,0,0,0,0,0
0,0,0,0,0,0,0,0,0,0,0,0,0,0,0,0,0,0,0,0,0,0,0,0
0,0,0,0,0,0,0,0,0,0,0,0,0,0,0,0,0,0,0,0,0,0,0,0
0,0,0,0,0,0,0,0,0,0,0,0,0,0,0,0,0,0,0,0,0,0,0,0
0,0,0,0,0,0,0,0,0,0,0,0,0,0,0,0,0,0,0,0,0,0,0,0
0,0,0,0,0,0,0,0,0,0,0,0,0,0,0,0,0,0,0,0,0,0,0,0
0,0,0,0,0,0,0,0,0,0,0,0,0,0,0,0,0,0,0,0,0,0,0,0
0,0,0,0,0,0,0,0,0,0,0,0,0,0,0,0,0,0,0,0,0,0,0,0
0,0,0,0,0,0,0,0,0,0,0,0,0,0,0,0,0,0,0,0,0,0,0,0
0,0,0,0,0,0,0,0,0,0,0,0,0,0,0,0,0,0,0,0,0,0,0,0
0,0,0,0,0,0,0,0,0,0,0,0,0,0,0,0,0,0,0,0,0,0,0,0
0,0,0,0,0,0,0,0,0,0,0,0,0,0,0,0,0,0,0,0,0,0,0,0
0,0,0,0,0,0,0,0,0,0,0,0,0,0,0,0,0,0,0,0,0,0,0,0
0,0,0,0,0,0,0,0,0,0,0,0,0,0,0,0,0,0,0,0,0,0,0,0
0,0,0,0,0,0,0,0,0,0,0,0,0,0,0,0,0,0,0,0,0,0,0,0
0,0,0,0,0,0,0,0,0,0,0,0,0,0,0,0,0,0,0,0,0,0,0,0
0,0,0,0,0,0,0,0,0,0,0,0,0,0,0,0,0,0,0,0,0,0,0,0
0,0,0,0,0,0,0,0,0,0,0,0,0,0,0,0,0,0,0,0,0,0,0,0
0,0,0,0,0,0,0,0,0,0,0,0,0,0,0,0,0,0,0,0,0,0,0,0
0,0,0,0,0,0,0,0,0,0,0,0,0,0,0,0,0,0,0,0,0,0,0,0
0,0,0,0,0,0,0,0,0,0,0,0,0,0,0,0,0,0,0,0,0,0,0,0
:endlayer
layer: 38
0,0,0,0,0,0,0,0,0,31,0,0,0,0,0,0,31,0,0,0,0,0,0,0
0,0,0,0,0,0,0,0,11,31,46,31,31,0,31,31,31,0,0,0,0,0,0,0
0,0,0,0,0,0,33,31,11,0,0,0,0,33,0,0,0,0,31,0,0,0,0,0
0,0,0,0,0,0,33,88,0,0,0,0,0,0,0,0,0,0,17,0,0,0,0,0
0,0,0,0,0,0,11,0,0,6,0,0,0,0,6,0,0,0,0,31,0,0,0,0
0,0,0,0,0,11,0,0,0,32,0,0,31,0,32,0,0,0,45,31,46,0,0,0
0,0,0,0,33,33,0,6,32,6,8,6,6,6,6,32,6,0,0,0,17,17,0,0
0,0,0,0,33,0,18,0,33,6,0,0,34,0,6,0,0,0,0,0,17,0,0,0
0,0,0,0,33,0,0,0,33,6,0,0,0,0,6,0,0,0,0,56,0,0,0,0
0,0,0,0,0,0,0,0,0,8,0,0,0,0,6,40,89,0,0,17,0,0,0,0
0,0,0,0,0,0,0,0,0,6,0,0,0,0,6,0,34,0,0,17,0,0,0,0
0,0,0,0,0,0,33,6,32,6,6,6,6,6,6,0,34,0,0,17,0,0,0,0
0,0,0,0,0,18,0,0,0,32,0,0,41,0,0,6,0,0,90,0,0,0,0,17
0,0,0,0,33,58,32,0,0,6,0,0,89,24,24,0,0,56,0,58,0,18,18,0
0,0,0,0,0,18,18,18,0,0,0,0,0,0,0,0,56,0,0,0,18,0,0,0
0,0,0,0,0,0,0,0,0,0,0,0,0,0,0,56,0,0,0,0,0,0,0,0
0,0,0,0,0,0,0,0,0,18,18,18,18,18,18,0,0,0,0,0,0,0,0,0
0,0,0,0,0,0,0,0,0,0,0,0,0,0,0,0,0,0,0,0,0,0,0,0
0,0,0,0,0,0,0,0,0,0,0,0,0,0,0,0,0,0,0,0,0,0,0,0
0,0,0,0,0,0,0,0,0,0,0,0,0,0,0,0,0,0,0,0,0,0,0,0
0,0,0,0,0,0,0,0,0,0,0,0,0,0,0,0,0,0,0,0,0,0,0,0
0,0,0,0,0,0,0,0,0,0,0,0,0,0,0,0,0,0,0,0,0,0,0,0
0,0,0,0,0,0,0,0,0,0,0,0,0,0,0,0,0,0,0,0,0,0,0,0
0,0,0,0,0,0,0,0,0,0,0,0,0,0,0,0,0,0,0,0,0,0,0,0
0,0,0,0,0,0,0,0,0,0,0,0,0,0,0,0,0,0,0,0,0,0,0,0
0,0,0,0,0,0,0,0,0,0,0,0,0,0,0,0,0,0,0,0,0,0,0,0
0,0,0,0,0,0,0,0,0,0,0,0,0,0,0,0,0,0,0,0,0,0,0,0
0,0,0,0,0,0,0,0,0,0,0,0,0,0,0,0,0,0,0,0,0,0,0,0
0,0,0,0,0,0,0,0,0,0,0,0,0,0,0,0,0,0,0,0,0,0,0,0
0,0,0,0,0,0,0,0,0,0,0,0,0,0,0,0,0,0,0,0,0,0,0,0
0,0,0,0,0,0,0,0,0,0,0,0,0,0,0,0,0,0,0,0,0,0,0,0
0,0,0,0,0,0,0,0,0,0,0,0,0,0,0,0,0,0,0,0,0,0,0,0
0,0,0,0,0,0,0,0,0,0,0,0,0,0,0,0,0,0,0,0,0,0,0,0
0,0,0,0,0,0,0,0,0,0,0,0,0,0,0,0,0,0,0,0,0,0,0,0
0,0,0,0,0,0,0,0,0,0,0,0,0,0,0,0,0,0,0,0,0,0,0,0
0,0,0,0,0,0,0,0,0,0,0,0,0,0,0,0,0,0,0,0,0,0,0,0
0,0,0,0,0,0,0,0,0,0,0,0,0,0,0,0,0,0,0,0,0,0,0,0
:endlayer
layer: 39
0,0,0,0,0,0,0,0,0,31,0,0,0,0,0,0,31,0,0,0,0,0,0,0
0,0,0,0,0,0,0,0,11,31,46,31,31,0,31,31,31,0,0,0,0,0,0,0
0,0,0,0,0,0,33,31,11,0,0,0,0,33,0,0,0,0,31,0,0,0,0,0
0,0,0,0,0,0,33,32,0,6,0,0,0,0,6,0,0,0,17,0,0,0,0,0
0,0,0,0,0,0,11,0,0,32,0,0,0,0,32,0,0,0,0,31,0,0,0,0
0,0,0,0,0,11,0,0,0,32,0,0,0,0,32,0,0,0,45,31,46,0,0,0
0,0,0,0,33,33,6,32,32,6,6,6,8,6,6,32,32,6,0,0,17,17,0,0
0,0,0,0,33,0,18,0,33,6,6,34,0,0,6,0,0,0,0,0,17,0,0,0
0,0,0,0,33,0,0,0,33,6,6,0,0,0,6,0,0,0,0,56,0,0,0,0
0,0,0,0,0,0,0,0,0,6,6,0,0,0,6,0,0,0,0,17,0,0,0,0
0,0,0,0,0,0,0,0,0,6,6,6,6,6,6,89,0,0,0,17,0,0,0,0
0,0,0,0,0,0,6,32,32,6,6,6,6,6,6,89,0,0,0,17,0,0,0,0
0,0,0,33,33,58,0,0,0,32,0,0,0,89,89,0,0,0,91,0,0,0,0,17
0,0,0,0,33,58,32,0,0,32,0,0,0,0,0,0,0,56,0,58,0,18,18,0
0,0,0,0,0,18,18,18,0,6,0,0,0,0,0,0,56,0,0,0,18,0,0,0
0,0,0,0,0,0,0,0,0,0,0,0,0,0,0,56,0,0,0,0,0,0,0,0
0,0,0,0,0,0,0,0,0,18,18,18,18,18,18,0,0,0,0,0,0,0,0,0
0,0,0,0,0,0,0,0,0,0,0,0,0,0,0,0,0,0,0,0,0,0,0,0
0,0,0,0,0,0,0,0,0,0,0,0,0,0,0,0,0,0,0,0,0,0,0,0
0,0,0,0,0,0,0,0,0,0,0,0,0,0,0,0,0,0,0,0,0,0,0,0
0,0,0,0,0,0,0,0,0,0,0,0,0,0,0,0,0,0,0,0,0,0,0,0
0,0,0,0,0,0,0,0,0,0,0,0,0,0,0,0,0,0,0,0,0,0,0,0
0,0,0,0,0,0,0,0,0,0,0,0,0,0,0,0,0,0,0,0,0,0,0,0
0,0,0,0,0,0,0,0,0,0,0,0,0,0,0,0,0,0,0,0,0,0,0,0
0,0,0,0,0,0,0,0,0,0,0,0,0,0,0,0,0,0,0,0,0,0,0,0
0,0,0,0,0,0,0,0,0,0,0,0,0,0,0,0,0,0,0,0,0,0,0,0
0,0,0,0,0,0,0,0,0,0,0,0,0,0,0,0,0,0,0,0,0,0,0,0
0,0,0,0,0,0,0,0,0,0,0,0,0,0,0,0,0,0,0,0,0,0,0,0
0,0,0,0,0,0,0,0,0,0,0,0,0,0,0,0,0,0,0,0,0,0,0,0
0,0,0,0,0,0,0,0,0,0,0,0,0,0,0,0,0,0,0,0,0,0,0,0
0,0,0,0,0,0,0,0,0,0,0,0,0,0,0,0,0,0,0,0,0,0,0,0
0,0,0,0,0,0,0,0,0,0,0,0,0,0,0,0,0,0,0,0,0,0,0,0
0,0,0,0,0,0,0,0,0,0,0,0,0,0,0,0,0,0,0,0,0,0,0,0
0,0,0,0,0,0,0,0,0,0,0,0,0,0,0,0,0,0,0,0,0,0,0,0
0,0,0,0,0,0,0,0,0,0,0,0,0,0,0,0,0,0,0,0,0,0,0,0
0,0,0,0,0,0,0,0,0,0,0,0,0,0,0,0,0,0,0,0,0,0,0,0
0,0,0,0,0,0,0,0,0,0,0,0,0,0,0,0,0,0,0,0,0,0,0,0
:endlayer
layer: 40
0,0,0,0,0,0,0,0,0,31,0,0,0,0,0,0,31,0,0,0,0,0,0,0
0,0,0,0,0,0,0,0,11,31,46,31,31,0,31,31,31,0,0,0,0,0,0,0
0,0,0,0,0,0,33,31,11,6,0,0,0,33,6,0,0,0,31,0,0,0,0,0
0,0,0,0,0,0,33,32,0,32,0,0,0,0,32,0,0,0,17,0,0,0,0,0
0,0,0,0,0,0,11,0,0,32,0,0,0,0,32,0,0,0,0,31,0,0,0,0
0,0,0,0,0,11,0,0,0,32,0,0,0,0,32,0,0,0,45,31,46,0,0,0
0,0,0,0,33,6,32,32,32,6,6,6,6,6,6,32,32,32,6,0,17,17,0,0
0,0,0,0,33,0,0,0,0,34,0,0,0,0,6,0,0,0,0,0,17,0,0,0
0,0,0,0,33,0,0,0,0,34,0,0,0,0,6,0,0,0,0,56,0,0,0,0
0,0,0,0,33,0,0,0,0,34,0,0,0,0,6,0,0,0,0,17,0,0,0,0
0,0,0,0,0,0,0,0,0,34,92,0,0,0,6,0,0,0,0,17,0,0,0,0
0,0,0,0,33,6,32,32,32,6,40,40,40,40,6,6,0,0,0,17,0,0,0,0
0,0,0,33,33,58,0,0,0,32,0,0,0,0,6,0,0,0,91,0,0,0,0,17
0,0,0,0,33,58,32,0,0,32,0,0,0,0,0,0,0,56,0,58,0,18,18,0
0,0,0,0,0,18,18,18,0,32,0,0,0,0,0,0,56,0,0,0,18,0,0,0
0,0,0,0,0,0,0,0,0,6,0,0,0,0,0,56,0,0,0,0,0,0,0,0
0,0,0,0,0,0,0,0,0,18,18,18,18,18,18,0,0,0,0,0,0,0,0,0
0,0,0,0,0,0,0,0,0,0,0,0,0,0,0,0,0,0,0,0,0,0,0,0
0,0,0,0,0,0,0,0,0,0,0,0,0,0,0,0,0,0,0,0,0,0,0,0
0,0,0,0,0,0,0,0,0,0,0,0,0,0,0,0,0,0,0,0,0,0,0,0
0,0,0,0,0,0,0,0,0,0,0,0,0,0,0,0,0,0,0,0,0,0,0,0
0,0,0,0,0,0,0,0,0,0,0,0,0,0,0,0,0,0,0,0,0,0,0,0
0,0,0,0,0,0,0,0,0,0,0,0,0,0,0,0,0,0,0,0,0,0,0,0
0,0,0,0,0,0,0,0,0,0,0,0,0,0,0,0,0,0,0,0,0,0,0,0
0,0,0,0,0,0,0,0,0,0,0,0,0,0,0,0,0,0,0,0,0,0,0,0
0,0,0,0,0,0,0,0,0,0,0,0,0,0,0,0,0,0,0,0,0,0,0,0
0,0,0,0,0,0,0,0,0,0,0,0,0,0,0,0,0,0,0,0,0,0,0,0
0,0,0,0,0,0,0,0,0,0,0,0,0,0,0,0,0,0,0,0,0,0,0,0
0,0,0,0,0,0,0,0,0,0,0,0,0,0,0,0,0,0,0,0,0,0,0,0
0,0,0,0,0,0,0,0,0,0,0,0,0,0,0,0,0,0,0,0,0,0,0,0
0,0,0,0,0,0,0,0,0,0,0,0,0,0,0,0,0,0,0,0,0,0,0,0
0,0,0,0,0,0,0,0,0,0,0,0,0,0,0,0,0,0,0,0,0,0,0,0
0,0,0,0,0,0,0,0,0,0,0,0,0,0,0,0,0,0,0,0,0,0,0,0
0,0,0,0,0,0,0,0,0,0,0,0,0,0,0,0,0,0,0,0,0,0,0,0
0,0,0,0,0,0,0,0,0,0,0,0,0,0,0,0,0,0,0,0,0,0,0,0
0,0,0,0,0,0,0,0,0,0,0,0,0,0,0,0,0,0,0,0,0,0,0,0
0,0,0,0,0,0,0,0,0,0,0,0,0,0,0,0,0,0,0,0,0,0,0,0
:endlayer
layer: 41
0,0,0,0,0,0,0,0,0,31,0,0,0,0,0,0,31,0,0,0,0,0,0,0
0,0,0,0,0,0,0,0,11,31,46,31,31,0,31,31,31,0,0,0,0,0,0,0
0,0,0,0,0,0,33,31,11,6,6,6,6,6,6,0,88,0,31,0,0,0,0,0
0,0,0,0,0,0,33,32,6,6,6,6,6,6,6,6,0,0,17,0,0,0,0,0
0,0,0,0,0,0,11,6,6,6,6,6,6,6,6,6,6,0,0,31,0,0,0,0
0,0,0,0,0,11,6,6,6,6,6,6,6,6,6,6,6,6,45,31,46,0,0,0
0,0,0,0,33,6,6,6,6,6,6,6,6,6,6,6,6,6,6,0,17,17,0,0
0,0,0,0,33,6,6,6,34,0,0,35,0,0,6,6,6,6,6,0,17,0,0,0
0,0,0,0,33,6,6,6,34,0,0,0,0,0,6,6,6,6,6,56,0,0,0,0
0,0,0,0,33,6,6,6,34,0,0,0,0,37,6,6,6,6,6,17,0,0,0,0
0,0,0,0,0,6,6,6,34,0,69,0,0,0,6,6,6,6,6,17,0,0,0,0
0,0,0,0,33,6,6,6,6,6,0,0,93,0,6,6,6,6,6,17,0,0,0,0
0,0,0,33,33,58,6,6,6,6,40,40,40,40,6,6,6,6,91,0,88,0,0,17
0,0,0,0,33,58,32,6,6,6,6,6,6,6,6,6,6,56,0,58,0,18,18,0
0,0,0,0,0,18,18,18,6,6,6,6,6,6,6,6,56,0,0,0,18,0,0,0
0,0,0,0,0,0,0,0,0,6,6,6,6,6,6,56,0,0,0,0,0,0,0,0
0,0,0,0,0,0,0,0,0,18,18,18,18,18,18,0,0,0,0,0,0,0,0,0
0,0,0,0,0,0,0,0,0,0,0,0,0,0,0,0,0,0,0,0,0,0,0,0
0,0,0,0,0,0,0,0,0,0,0,0,0,0,0,0,0,0,0,0,0,0,0,0
0,0,0,0,0,0,0,0,0,0,0,0,0,0,0,0,0,0,0,0,0,0,0,0
0,0,0,0,0,0,0,0,0,0,0,0,0,0,0,0,0,0,0,0,0,0,0,0
0,0,0,0,0,0,0,0,0,0,0,0,0,0,0,0,0,0,0,0,0,0,0,0
0,0,0,0,0,0,0,0,0,0,0,0,0,0,0,0,0,0,0,0,0,0,0,0
0,0,0,0,0,0,0,0,0,0,0,0,0,0,0,0,0,0,0,0,0,0,0,0
0,0,0,0,0,0,0,0,0,0,0,0,0,0,0,0,0,0,0,0,0,0,0,0
0,0,0,0,0,0,0,0,0,0,0,0,0,0,0,0,0,0,0,0,0,0,0,0
0,0,0,0,0,0,0,0,0,0,0,0,0,0,0,0,0,0,0,0,0,0,0,0
0,0,0,0,0,0,0,0,0,0,0,0,0,0,0,0,0,0,0,0,0,0,0,0
0,0,0,0,0,0,0,0,0,0,0,0,0,0,0,0,0,0,0,0,0,0,0,0
0,0,0,0,0,0,0,0,0,0,0,0,0,0,0,0,0,0,0,0,0,0,0,0
0,0,0,0,0,0,0,0,0,0,0,0,0,0,0,0,0,0,0,0,0,0,0,0
0,0,0,0,0,0,0,0,0,0,0,0,0,0,0,0,0,0,0,0,0,0,0,0
0,0,0,0,0,0,0,0,0,0,0,0,0,0,0,0,0,0,0,0,0,0,0,0
0,0,0,0,0,0,0,0,0,0,0,0,0,0,0,0,0,0,0,0,0,0,0,0
0,0,0,0,0,0,0,0,0,0,0,0,0,0,0,0,0,0,0,0,0,0,0,0
0,0,0,0,0,0,0,0,0,0,0,0,0,0,0,0,0,0,0,0,0,0,0,0
0,0,0,0,0,0,0,0,0,0,0,0,0,0,0,0,0,0,0,0,0,0,0,0
:endlayer
layer: 42
0,0,0,0,0,0,0,0,0,31,0,0,0,0,0,0,31,0,0,0,0,0,0,0
0,0,0,0,0,0,0,0,11,31,46,31,31,0,31,31,31,0,0,0,0,0,0,0
0,0,0,0,0,0,33,31,11,6,6,6,6,6,6,0,32,0,31,0,0,0,0,0
0,0,0,0,0,0,33,32,6,0,0,0,75,13,13,6,0,0,17,0,0,0,0,0
0,0,0,0,0,0,11,6,94,0,95,0,75,13,13,13,6,0,0,31,0,0,0,0
0,0,0,0,0,11,6,96,0,0,0,0,75,13,13,13,13,6,45,31,46,0,0,0
0,0,0,0,33,6,97,0,0,75,75,75,75,13,13,13,13,13,6,0,17,17,0,0
0,0,0,0,33,6,98,0,0,0,0,0,0,0,13,13,13,13,6,0,17,0,0,0
0,0,0,0,33,6,99,100,0,0,0,0,0,0,13,13,13,0,6,56,0,0,0,0
0,0,0,0,33,6,101,0,0,0,0,0,0,31,13,13,13,13,6,17,0,0,0,0
0,0,0,0,33,6,102,0,0,0,0,0,0,0,74,31,13,103,6,17,0,0,0,0
0,0,0,0,33,6,104,0,0,6,0,0,0,0,0,0,31,0,6,17,0,0,0,0
0,0,0,33,33,58,6,105,0,0,0,0,0,0,0,0,106,6,91,0,32,0,0,17
0,0,0,0,33,58,32,6,0,107,0,0,0,0,0,108,6,56,0,58,0,18,18,0
0,0,0,0,0,18,18,18,6,109,110,106,106,111,112,6,56,0,0,0,18,0,0,0
0,0,0,0,0,0,0,0,0,6,6,6,6,6,6,56,0,0,0,0,0,0,0,0
0,0,0,0,0,0,0,0,0,18,18,18,18,18,18,0,0,0,0,0,0,0,0,0
0,0,0,0,0,0,0,0,0,0,0,0,0,0,0,0,0,0,0,0,0,0,0,0
0,0,0,0,0,0,0,0,0,0,0,0,0,0,0,0,0,0,0,0,0,0,0,0
0,0,0,0,0,0,0,0,0,0,0,0,0,0,0,0,0,0,0,0,0,0,0,0
0,0,0,0,0,0,0,0,0,0,0,0,0,0,0,0,0,0,0,0,0,0,0,0
0,0,0,0,0,0,0,0,0,0,0,0,0,0,0,0,0,0,0,0,0,0,0,0
0,0,0,0,0,0,0,0,0,0,0,0,0,0,0,0,0,0,0,0,0,0,0,0
0,0,0,0,0,0,0,0,0,0,0,0,0,0,0,0,0,0,0,0,0,0,0,0
0,0,0,0,0,0,0,0,0,0,0,0,0,0,0,0,0,0,0,0,0,0,0,0
0,0,0,0,0,0,0,0,0,0,0,0,0,0,0,0,0,0,0,0,0,0,0,0
0,0,0,0,0,0,0,0,0,0,0,0,0,0,0,0,0,0,0,0,0,0,0,0
0,0,0,0,0,0,0,0,0,0,0,0,0,0,0,0,0,0,0,0,0,0,0,0
0,0,0,0,0,0,0,0,0,0,0,0,0,0,0,0,0,0,0,0,0,0,0,0
0,0,0,0,0,0,0,0,0,0,0,0,0,0,0,0,0,0,0,0,0,0,0,0
0,0,0,0,0,0,0,0,0,0,0,0,0,0,0,0,0,0,0,0,0,0,0,0
0,0,0,0,0,0,0,0,0,0,0,0,0,0,0,0,0,0,0,0,0,0,0,0
0,0,0,0,0,0,0,0,0,0,0,0,0,0,0,0,0,0,0,0,0,0,0,0
0,0,0,0,0,0,0,0,0,0,0,0,0,0,0,0,0,0,0,0,0,0,0,0
0,0,0,0,0,0,0,0,0,0,0,0,0,0,0,0,0,0,0,0,0,0,0,0
0,0,0,0,0,0,0,0,0,0,0,0,0,0,0,0,0,0,0,0,0,0,0,0
0,0,0,0,0,0,0,0,0,0,0,0,0,0,0,0,0,0,0,0,0,0,0,0
:endlayer
layer: 43
0,0,0,0,0,0,0,0,0,31,0,0,0,0,0,0,31,0,0,0,0,0,0,0
0,0,0,0,0,0,0,0,11,31,46,31,31,0,31,31,31,0,0,0,0,0,0,0
0,0,0,0,0,0,33,31,11,6,8,6,6,8,6,0,32,0,31,0,0,0,0,0
0,0,0,0,0,0,33,32,6,35,0,0,75,0,13,6,0,0,17,0,0,0,0,0
0,0,0,0,0,0,11,6,0,0,0,0,75,13,13,13,6,0,0,31,0,0,0,0
0,0,0,0,0,11,6,0,0,0,0,0,75,13,13,13,13,6,45,31,46,0,0,0
0,0,0,0,33,6,36,0,0,75,75,75,75,13,13,13,13,13,6,0,17,17,0,0
0,0,0,0,33,6,0,0,0,0,0,0,0,0,13,13,13,0,8,0,17,0,0,0
0,0,0,0,33,6,0,0,0,0,0,0,0,0,17,13,13,0,6,18,0,0,0,0
0,0,0,0,33,6,0,0,0,0,0,0,0,31,113,0,114,0,6,17,0,0,0,0
0,0,0,0,33,6,0,0,0,38,0,0,0,0,0,31,0,0,8,0,0,0,0,0
0,0,0,0,33,6,36,0,0,6,36,0,0,0,0,0,31,37,6,17,0,0,0,0
0,0,0,33,33,58,6,0,0,0,0,0,0,0,0,0,0,6,58,0,32,0,0,17
0,0,0,0,33,58,32,6,0,0,0,0,0,0,0,0,6,56,0,58,0,18,18,0
0,0,0,0,0,18,18,18,6,38,0,0,0,0,38,6,56,0,0,0,18,0,0,0
0,0,0,0,0,0,0,0,0,6,8,6,6,8,6,56,0,0,0,0,0,0,0,0
0,0,0,0,0,0,0,0,0,18,18,18,18,0,18,0,0,0,0,0,0,0,0,0
0,0,0,0,0,0,0,0,0,0,0,0,0,0,0,0,0,0,0,0,0,0,0,0
0,0,0,0,0,0,0,0,0,0,0,0,0,0,0,0,0,0,0,0,0,0,0,0
0,0,0,0,0,0,0,0,0,0,0,0,0,0,0,0,0,0,0,0,0,0,0,0
0,0,0,0,0,0,0,0,0,0,0,0,0,0,0,0,0,0,0,0,0,0,0,0
0,0,0,0,0,0,0,0,0,0,0,0,0,0,0,0,0,0,0,0,0,0,0,0
0,0,0,0,0,0,0,0,0,0,0,0,0,0,0,0,0,0,0,0,0,0,0,0
0,0,0,0,0,0,0,0,0,0,0,0,0,0,0,0,0,0,0,0,0,0,0,0
0,0,0,0,0,0,0,0,0,0,0,0,0,0,0,0,0,0,0,0,0,0,0,0
0,0,0,0,0,0,0,0,0,0,0,0,0,0,0,0,0,0,0,0,0,0,0,0
0,0,0,0,0,0,0,0,0,0,0,0,0,0,0,0,0,0,0,0,0,0,0,0
0,0,0,0,0,0,0,0,0,0,0,0,0,0,0,0,0,0,0,0,0,0,0,0
0,0,0,0,0,0,0,0,0,0,0,0,0,0,0,0,0,0,0,0,0,0,0,0
0,0,0,0,0,0,0,0,0,0,0,0,0,0,0,0,0,0,0,0,0,0,0,0
0,0,0,0,0,0,0,0,0,0,0,0,0,0,0,0,0,0,0,0,0,0,0,0
0,0,0,0,0,0,0,0,0,0,0,0,0,0,0,0,0,0,0,0,0,0,0,0
0,0,0,0,0,0,0,0,0,0,0,0,0,0,0,0,0,0,0,0,0,0,0,0
0,0,0,0,0,0,0,0,0,0,0,0,0,0,0,0,0,0,0,0,0,0,0,0
0,0,0,0,0,0,0,0,0,0,0,0,0,0,0,0,0,0,0,0,0,0,0,0
0,0,0,0,0,0,0,0,0,0,0,0,0,0,0,0,0,0,0,0,0,0,0,0
0,0,0,0,0,0,0,0,0,0,0,0,0,0,0,0,0,0,0,0,0,0,0,0
:endlayer
layer: 44
0,0,0,0,0,0,0,0,0,31,0,0,0,0,0,0,31,0,0,0,0,0,0,0
0,0,0,0,0,0,0,0,11,31,46,31,31,0,31,31,31,0,0,0,0,0,0,0
0,0,0,0,0,0,33,31,11,6,8,6,6,8,6,0,115,0,31,0,0,0,0,0
0,0,0,0,0,0,33,115,6,0,0,0,0,0,0,6,0,0,17,0,0,0,0,0
0,0,0,0,0,0,11,6,0,0,0,0,0,13,13,0,6,0,0,31,0,0,0,0
0,0,0,0,0,11,6,0,0,0,0,0,13,13,13,13,0,6,45,31,46,0,0,0
0,0,0,0,33,6,0,0,0,6,116,0,13,13,13,13,13,0,6,0,17,17,0,0
0,0,0,0,33,6,0,0,0,0,0,0,0,13,13,13,0,0,8,0,17,0,0,0
0,0,0,0,33,6,0,0,0,0,0,0,0,0,17,56,117,0,6,18,0,0,0,0
0,0,0,0,33,6,0,0,0,0,0,0,0,31,113,0,33,0,6,17,0,0,0,0
0,0,0,0,0,6,0,0,0,0,0,0,0,0,0,31,0,0,8,0,0,0,0,0
0,0,0,0,33,6,0,0,0,6,0,0,0,0,0,0,31,0,6,17,0,0,0,0
0,0,0,33,33,18,6,0,0,0,0,0,0,0,0,0,0,6,58,0,32,0,0,17
0,0,0,0,33,58,32,6,0,0,0,0,0,0,0,0,6,56,0,58,0,56,18,0
0,0,0,0,0,18,18,18,6,0,0,0,0,0,0,6,56,0,0,0,18,0,0,0
0,0,0,0,0,0,0,0,0,6,8,6,6,8,6,56,0,0,0,0,0,0,0,0
0,0,0,0,0,0,0,0,0,18,18,18,18,0,18,0,0,0,0,0,0,0,0,0
0,0,0,0,0,0,0,0,0,0,0,0,0,0,0,0,0,0,0,0,0,0,0,0
0,0,0,0,0,0,0,0,0,0,0,0,0,0,0,0,0,0,0,0,0,0,0,0
0,0,0,0,0,0,0,0,0,0,0,0,0,0,0,0,0,0,0,0,0,0,0,0
0,0,0,0,0,0,0,0,0,0,0,0,0,0,0,0,0,0,0,0,0,0,0,0
0,0,0,0,0,0,0,0,0,0,0,0,0,0,0,0,0,0,0,0,0,0,0,0
0,0,0,0,0,0,0,0,0,0,0,0,0,0,0,0,0,0,0,0,0,0,0,0
0,0,0,0,0,0,0,0,0,0,0,0,0,0,0,0,0,0,0,0,0,0,0,0
0,0,0,0,0,0,0,0,0,0,0,0,0,0,0,0,0,0,0,0,0,0,0,0
0,0,0,0,0,0,0,0,0,0,0,0,0,0,0,0,0,0,0,0,0,0,0,0
0,0,0,0,0,0,0,0,0,0,0,0,0,0,0,0,0,0,0,0,0,0,0,0
0,0,0,0,0,0,0,0,0,0,0,0,0,0,0,0,0,0,0,0,0,0,0,0
0,0,0,0,0,0,0,0,0,0,0,0,0,0,0,0,0,0,0,0,0,0,0,0
0,0,0,0,0,0,0,0,0,0,0,0,0,0,0,0,0,0,0,0,0,0,0,0
0,0,0,0,0,0,0,0,0,0,0,0,0,0,0,0,0,0,0,0,0,0,0,0
0,0,0,0,0,0,0,0,0,0,0,0,0,0,0,0,0,0,0,0,0,0,0,0
0,0,0,0,0,0,0,0,0,0,0,0,0,0,0,0,0,0,0,0,0,0,0,0
0,0,0,0,0,0,0,0,0,0,0,0,0,0,0,0,0,0,0,0,0,0,0,0
0,0,0,0,0,0,0,0,0,0,0,0,0,0,0,0,0,0,0,0,0,0,0,0
0,0,0,0,0,0,0,0,0,0,0,0,0,0,0,0,0,0,0,0,0,0,0,0
0,0,0,0,0,0,0,0,0,0,0,0,0,0,0,0,0,0,0,0,0,0,0,0
:endlayer
layer: 45
0,0,0,0,0,0,0,0,0,31,0,0,0,0,0,0,31,0,0,0,0,0,0,0
0,0,0,0,0,0,0,0,11,0,46,31,31,0,0,31,31,0,0,0,0,0,0,0
0,0,0,0,0,0,33,31,11,6,6,6,6,6,6,0,115,0,31,0,0,0,0,0
0,0,0,0,0,0,33,115,6,6,6,6,6,6,6,6,0,0,17,0,0,0,0,0
0,0,0,0,0,0,33,6,6,6,6,0,0,0,6,6,6,0,0,31,0,0,0,0
0,0,0,0,0,11,6,6,6,6,0,0,13,13,13,13,6,6,45,31,46,0,0,0
0,0,0,0,0,6,6,6,6,6,0,13,13,13,13,13,6,6,6,115,17,17,0,0
0,0,0,0,33,6,6,6,6,6,6,13,13,13,13,13,6,6,6,0,17,0,0,0
0,0,0,0,33,6,6,6,6,6,6,6,13,13,17,56,18,6,6,18,0,0,0,0
0,0,0,0,33,6,6,6,6,6,6,6,6,31,113,0,33,6,6,17,0,0,0,0
0,0,0,0,0,6,6,6,6,6,6,6,6,6,6,31,0,6,6,0,0,0,0,0
0,0,0,0,0,6,6,6,6,6,6,6,6,6,6,6,31,6,6,0,0,0,0,0
0,0,0,33,33,18,6,6,6,6,6,6,6,6,6,6,6,6,58,0,32,0,0,17
0,0,0,0,33,58,118,6,6,6,6,6,6,6,6,6,6,56,0,58,0,56,18,0
0,0,0,0,0,18,18,18,6,6,6,6,6,6,6,6,18,0,0,0,18,0,0,0
0,0,0,0,0,0,0,0,0,6,6,6,6,6,6,17,0,0,0,0,0,0,0,0
0,0,0,0,0,0,0,0,0,0,18,18,18,0,0,0,0,0,0,0,0,0,0,0
0,0,0,0,0,0,0,0,0,0,0,0,0,0,0,0,0,0,0,0,0,0,0,0
0,0,0,0,0,0,0,0,0,0,0,0,0,0,0,0,0,0,0,0,0,0,0,0
0,0,0,0,0,0,0,0,0,0,0,0,0,0,0,0,0,0,0,0,0,0,0,0
0,0,0,0,0,0,0,0,0,0,0,0,0,0,0,0,0,0,0,0,0,0,0,0
0,0,0,0,0,0,0,0,0,0,0,0,0,0,0,0,0,0,0,0,0,0,0,0
0,0,0,0,0,0,0,0,0,0,0,0,0,0,0,0,0,0,0,0,0,0,0,0
0,0,0,0,0,0,0,0,0,0,0,0,0,0,0,0,0,0,0,0,0,0,0,0
0,0,0,0,0,0,0,0,0,0,0,0,0,0,0,0,0,0,0,0,0,0,0,0
0,0,0,0,0,0,0,0,0,0,0,0,0,0,0,0,0,0,0,0,0,0,0,0
0,0,0,0,0,0,0,0,0,0,0,0,0,0,0,0,0,0,0,0,0,0,0,0
0,0,0,0,0,0,0,0,0,0,0,0,0,0,0,0,0,0,0,0,0,0,0,0
0,0,0,0,0,0,0,0,0,0,0,0,0,0,0,0,0,0,0,0,0,0,0,0
0,0,0,0,0,0,0,0,0,0,0,0,0,0,0,0,0,0,0,0,0,0,0,0
0,0,0,0,0,0,0,0,0,0,0,0,0,0,0,0,0,0,0,0,0,0,0,0
0,0,0,0,0,0,0,0,0,0,0,0,0,0,0,0,0,0,0,0,0,0,0,0
0,0,0,0,0,0,0,0,0,0,0,0,0,0,0,0,0,0,0,0,0,0,0,0
0,0,0,0,0,0,0,0,0,0,0,0,0,0,0,0,0,0,0,0,0,0,0,0
0,0,0,0,0,0,0,0,0,0,0,0,0,0,0,0,0,0,0,0,0,0,0,0
0,0,0,0,0,0,0,0,0,0,0,0,0,0,0,0,0,0,0,0,0,0,0,0
0,0,0,0,0,0,0,0,0,0,0,0,0,0,0,0,0,0,0,0,0,0,0,0
:endlayer
layer: 46
0,0,0,0,0,0,0,0,0,31,0,0,0,0,0,0,31,0,0,0,0,0,0,0
0,0,0,0,0,0,0,0,11,38,46,31,31,0,38,31,31,17,0,0,0,0,0,0
0,0,0,0,0,0,33,31,33,6,0,6,6,119,6,0,115,0,31,0,0,0,0,0
0,0,0,0,0,0,33,115,0,0,0,0,31,0,0,0,0,0,17,0,0,0,0,0
0,0,0,0,0,0,33,6,0,0,0,13,13,13,0,0,6,0,0,31,0,0,0,0
0,0,0,0,0,31,120,0,0,0,13,13,13,13,13,0,0,0,11,115,46,0,0,0
0,0,0,0,37,6,0,0,0,0,13,13,13,13,13,13,0,31,6,13,115,17,0,0
0,0,0,0,0,0,0,0,0,0,0,13,13,13,13,13,0,0,0,115,17,0,0,0
0,0,0,0,33,6,0,0,0,0,0,0,0,13,13,56,0,0,6,18,0,0,0,0
0,0,0,0,33,6,0,0,0,0,0,0,0,13,18,0,0,0,6,0,0,0,0,0
0,0,0,0,0,0,0,0,0,0,0,0,0,0,0,0,0,0,0,0,0,0,0,0
0,0,0,0,37,6,0,0,121,0,0,0,0,0,0,18,0,0,6,36,115,0,0,0
0,0,0,33,33,0,0,0,17,0,0,0,56,0,0,0,18,0,58,115,32,0,118,17
0,0,0,0,33,58,118,6,0,0,0,18,0,0,0,0,6,17,0,58,0,56,18,0
0,0,0,0,0,18,18,18,122,0,0,18,0,0,0,123,18,0,0,0,18,0,0,0
0,0,0,0,0,0,0,0,0,6,0,6,6,0,6,17,0,0,0,0,0,0,0,0
0,0,0,0,0,0,0,0,0,35,0,18,18,0,35,0,0,0,0,0,0,0,0,0
0,0,0,0,0,0,0,0,0,0,0,0,0,0,0,0,0,0,0,0,0,0,0,0
0,0,0,0,0,0,0,0,0,0,0,0,0,0,0,0,0,0,0,0,0,0,0,0
0,0,0,0,0,0,0,0,0,0,0,0,0,0,0,0,0,0,0,0,0,0,0,0
0,0,0,0,0,0,0,0,0,0,0,0,0,0,0,0,0,0,0,0,0,0,0,0
0,0,0,0,0,0,0,0,0,0,0,0,0,0,0,0,0,0,0,0,0,0,0,0
0,0,0,0,0,0,0,0,0,0,0,0,0,0,0,0,0,0,0,0,0,0,0,0
0,0,0,0,0,0,0,0,0,0,0,0,0,0,0,0,0,0,0,0,0,0,0,0
0,0,0,0,0,0,0,0,0,0,0,0,0,0,0,0,0,0,0,0,0,0,0,0
0,0,0,0,0,0,0,0,0,0,0,0,0,0,0,0,0,0,0,0,0,0,0,0
0,0,0,0,0,0,0,0,0,0,0,0,0,0,0,0,0,0,0,0,0,0,0,0
0,0,0,0,0,0,0,0,0,0,0,0,0,0,0,0,0,0,0,0,0,0,0,0
0,0,0,0,0,0,0,0,0,0,0,0,0,0,0,0,0,0,0,0,0,0,0,0
0,0,0,0,0,0,0,0,0,0,0,0,0,0,0,0,0,0,0,0,0,0,0,0
0,0,0,0,0,0,0,0,0,0,0,0,0,0,0,0,0,0,0,0,0,0,0,0
0,0,0,0,0,0,0,0,0,0,0,0,0,0,0,0,0,0,0,0,0,0,0,0
0,0,0,0,0,0,0,0,0,0,0,0,0,0,0,0,0,0,0,0,0,0,0,0
0,0,0,0,0,0,0,0,0,0,0,0,0,0,0,0,0,0,0,0,0,0,0,0
0,0,0,0,0,0,0,0,0,0,0,0,0,0,0,0,0,0,0,0,0,0,0,0
0,0,0,0,0,0,0,0,0,0,0,0,0,0,0,0,0,0,0,0,0,0,0,0
0,0,0,0,0,0,0,0,0,0,0,0,0,0,0,0,0,0,0,0,0,0,0,0
:endlayer
layer: 47
0,0,0,0,0,0,0,0,0,31,0,0,0,0,0,0,31,0,0,0,0,0,0,0
0,0,0,0,0,0,0,0,11,0,46,0,0,0,31,31,31,17,0,0,0,0,0,0
0,0,0,0,0,0,33,31,0,0,0,0,0,0,0,0,115,0,31,0,0,0,0,0
0,0,0,0,0,0,33,118,0,88,0,0,31,0,0,0,0,0,17,0,0,0,0,0
0,0,0,0,0,0,0,39,0,0,0,0,13,13,13,0,39,0,0,31,0,0,0,0
0,0,0,0,0,0,0,0,0,0,0,13,13,13,13,13,0,0,33,115,46,0,0,0
0,0,0,0,0,0,0,0,0,0,0,13,13,13,13,13,13,124,115,13,115,17,0,0
0,0,0,0,0,0,0,0,0,0,0,13,13,13,13,13,13,0,0,115,17,0,0,0
0,0,0,0,0,0,0,0,0,0,0,0,13,13,13,13,0,0,0,18,0,0,0,0
0,0,0,0,0,0,0,0,0,0,0,0,0,13,13,0,0,0,125,0,0,0,0,0
0,0,0,0,0,0,0,0,0,0,0,0,0,0,0,0,0,0,0,0,0,0,0,0
0,0,0,0,0,0,0,0,0,0,0,0,0,0,0,18,0,0,0,0,115,0,0,0
0,0,0,33,33,0,0,0,17,0,0,118,56,0,0,0,18,0,58,115,13,118,118,17
0,0,0,0,33,58,118,39,0,0,0,18,0,0,0,0,39,0,0,58,118,56,18,0
0,0,0,0,0,18,18,18,0,0,0,18,0,0,0,0,0,0,0,0,18,0,0,0
0,0,0,0,0,0,0,0,0,0,0,0,0,0,0,0,0,0,0,0,0,0,0,0
0,0,0,0,0,0,0,0,0,0,0,0,0,0,0,0,0,0,0,0,0,0,0,0
0,0,0,0,0,0,0,0,0,0,0,0,0,0,0,0,0,0,0,0,0,0,0,0
0,0,0,0,0,0,0,0,0,0,0,0,0,0,0,0,0,0,0,0,0,0,0,0
0,0,0,0,0,0,0,0,0,0,0,0,0,0,0,0,0,0,0,0,0,0,0,0
0,0,0,0,0,0,0,0,0,0,0,0,0,0,0,0,0,0,0,0,0,0,0,0
0,0,0,0,0,0,0,0,0,0,0,0,0,0,0,0,0,0,0,0,0,0,0,0
0,0,0,0,0,0,0,0,0,0,0,0,0,0,0,0,0,0,0,0,0,0,0,0
0,0,0,0,0,0,0,0,0,0,0,0,0,0,0,0,0,0,0,0,0,0,0,0
0,0,0,0,0,0,0,0,0,0,0,0,0,0,0,0,0,0,0,0,0,0,0,0
0,0,0,0,0,0,0,0,0,0,0,0,0,0,0,0,0,0,0,0,0,0,0,0
0,0,0,0,0,0,0,0,0,0,0,0,0,0,0,0,0,0,0,0,0,0,0,0
0,0,0,0,0,0,0,0,0,0,0,0,0,0,0,0,0,0,0,0,0,0,0,0
0,0,0,0,0,0,0,0,0,0,0,0,0,0,0,0,0,0,0,0,0,0,0,0
0,0,0,0,0,0,0,0,0,0,0,0,0,0,0,0,0,0,0,0,0,0,0,0
0,0,0,0,0,0,0,0,0,0,0,0,0,0,0,0,0,0,0,0,0,0,0,0
0,0,0,0,0,0,0,0,0,0,0,0,0,0,0,0,0,0,0,0,0,0,0,0
0,0,0,0,0,0,0,0,0,0,0,0,0,0,0,0,0,0,0,0,0,0,0,0
0,0,0,0,0,0,0,0,0,0,0,0,0,0,0,0,0,0,0,0,0,0,0,0
0,0,0,0,0,0,0,0,0,0,0,0,0,0,0,0,0,0,0,0,0,0,0,0
0,0,0,0,0,0,0,0,0,0,0,0,0,0,0,0,0,0,0,0,0,0,0,0
0,0,0,0,0,0,0,0,0,0,0,0,0,0,0,0,0,0,0,0,0,0,0,0
:endlayer
layer: 48
0,0,0,0,0,0,0,0,0,31,0,0,0,0,0,0,31,0,0,0,0,0,0,0
0,0,0,0,0,0,0,0,11,0,46,0,0,0,31,31,31,17,0,0,0,0,0,0
0,0,0,0,0,0,33,31,0,0,0,0,0,0,0,0,115,0,31,0,0,0,0,0
0,0,0,0,0,0,33,118,0,32,0,0,31,0,0,0,115,0,17,0,0,0,0,0
0,0,0,0,0,0,0,0,0,0,0,0,31,31,0,0,0,0,0,31,0,0,0,0
0,0,0,0,0,0,0,0,0,0,0,13,13,13,13,0,0,0,0,115,31,0,0,0
0,0,0,0,0,0,0,0,0,0,13,13,13,13,13,13,0,124,115,13,115,17,0,0
0,0,0,0,0,0,0,0,0,0,13,13,13,13,0,13,126,0,0,115,17,0,0,0
0,0,0,0,0,0,0,0,0,0,13,13,0,0,13,13,0,0,0,18,0,0,0,0
0,0,0,0,0,0,0,0,0,0,0,13,13,13,13,13,13,0,0,0,0,0,0,0
0,0,0,0,0,0,0,0,0,0,0,0,13,13,13,115,115,0,0,0,0,0,0,0
0,0,0,0,0,0,0,0,0,0,0,0,115,115,115,18,0,0,0,0,115,118,0,0
0,0,0,33,33,0,0,0,17,0,0,118,56,0,0,0,18,0,58,118,13,118,118,17
0,0,0,0,33,58,118,56,0,0,0,18,0,0,0,0,0,0,0,58,118,56,18,0
0,0,0,0,0,18,18,18,0,0,0,18,0,0,0,0,0,0,0,0,18,0,0,0
0,0,0,0,0,0,0,0,0,0,0,0,0,0,0,0,0,0,0,0,0,0,0,0
0,0,0,0,0,0,0,0,0,0,0,0,0,0,0,0,0,0,0,0,0,0,0,0
0,0,0,0,0,0,0,0,0,0,0,0,0,0,0,0,0,0,0,0,0,0,0,0
0,0,0,0,0,0,0,0,0,0,0,0,0,0,0,0,0,0,0,0,0,0,0,0
0,0,0,0,0,0,0,0,0,0,0,0,0,0,0,0,0,0,0,0,0,0,0,0
0,0,0,0,0,0,0,0,0,0,0,0,0,0,0,0,0,0,0,0,0,0,0,0
0,0,0,0,0,0,0,0,0,0,0,0,0,0,0,0,0,0,0,0,0,0,0,0
0,0,0,0,0,0,0,0,0,0,0,0,0,0,0,0,0,0,0,0,0,0,0,0
0,0,0,0,0,0,0,0,0,0,0,0,0,0,0,0,0,0,0,0,0,0,0,0
0,0,0,0,0,0,0,0,0,0,0,0,0,0,0,0,0,0,0,0,0,0,0,0
0,0,0,0,0,0,0,0,0,0,0,0,0,0,0,0,0,0,0,0,0,0,0,0
0,0,0,0,0,0,0,0,0,0,0,0,0,0,0,0,0,0,0,0,0,0,0,0
0,0,0,0,0,0,0,0,0,0,0,0,0,0,0,0,0,0,0,0,0,0,0,0
0,0,0,0,0,0,0,0,0,0,0,0,0,0,0,0,0,0,0,0,0,0,0,0
0,0,0,0,0,0,0,0,0,0,0,0,0,0,0,0,0,0,0,0,0,0,0,0
0,0,0,0,0,0,0,0,0,0,0,0,0,0,0,0,0,0,0,0,0,0,0,0
0,0,0,0,0,0,0,0,0,0,0,0,0,0,0,0,0,0,0,0,0,0,0,0
0,0,0,0,0,0,0,0,0,0,0,0,0,0,0,0,0,0,0,0,0,0,0,0
0,0,0,0,0,0,0,0,0,0,0,0,0,0,0,0,0,0,0,0,0,0,0,0
0,0,0,0,0,0,0,0,0,0,0,0,0,0,0,0,0,0,0,0,0,0,0,0
0,0,0,0,0,0,0,0,0,0,0,0,0,0,0,0,0,0,0,0,0,0,0,0
0,0,0,0,0,0,0,0,0,0,0,0,0,0,0,0,0,0,0,0,0,0,0,0
:endlayer
layer: 49
0,0,0,0,0,0,0,0,0,31,0,0,0,0,0,0,31,0,0,0,0,0,0,0
0,0,0,0,0,0,0,0,11,0,46,0,0,0,31,31,115,17,0,0,0,0,0,0
0,0,0,0,0,0,33,118,118,0,0,0,0,0,0,0,115,115,31,0,0,0,0,0
0,0,0,0,0,0,33,118,118,32,0,0,31,0,0,0,13,115,17,0,0,0,0,0
0,0,0,0,0,0,0,0,118,0,0,0,13,31,0,0,115,0,0,0,0,0,0,0
0,0,0,0,0,0,0,0,0,0,0,13,13,13,31,0,0,0,0,0,0,0,0,0
0,0,0,0,0,0,0,0,0,0,13,13,13,13,13,31,0,124,115,13,17,0,0,0
0,0,0,0,0,0,0,0,0,13,13,13,13,13,13,13,126,0,0,115,17,0,0,0
0,0,0,0,0,0,0,0,0,0,13,13,13,13,13,11,0,0,0,0,0,0,0,0
0,0,0,0,0,0,0,0,0,0,0,13,13,13,46,13,13,115,0,0,0,0,0,0
0,0,0,0,0,0,0,0,0,0,0,0,13,115,115,115,13,115,115,115,0,0,0,0
0,0,0,0,0,0,115,115,0,0,0,0,118,56,0,18,118,0,0,118,118,118,0,0
0,0,0,33,33,115,13,115,17,0,0,118,56,0,0,0,18,0,58,118,13,118,118,0
0,0,0,0,33,58,115,56,0,0,0,18,0,0,0,0,0,0,0,58,118,56,18,0
0,0,0,0,0,18,18,18,0,0,0,18,0,0,0,0,0,0,0,0,18,0,0,0
0,0,0,0,0,0,0,0,0,0,0,0,0,0,0,0,0,0,0,0,0,0,0,0
0,0,0,0,0,0,0,0,0,0,0,0,0,0,0,0,0,0,0,0,0,0,0,0
0,0,0,0,0,0,0,0,0,0,0,0,0,0,0,0,0,0,0,0,0,0,0,0
0,0,0,0,0,0,0,0,0,0,0,0,0,0,0,0,0,0,0,0,0,0,0,0
0,0,0,0,0,0,0,0,0,0,0,0,0,0,0,0,0,0,0,0,0,0,0,0
0,0,0,0,0,0,0,0,0,0,0,0,0,0,0,0,0,0,0,0,0,0,0,0
0,0,0,0,0,0,0,0,0,0,0,0,0,0,0,0,0,0,0,0,0,0,0,0
0,0,0,0,0,0,0,0,0,0,0,0,0,0,0,0,0,0,0,0,0,0,0,0
0,0,0,0,0,0,0,0,0,0,0,0,0,0,0,0,0,0,0,0,0,0,0,0
0,0,0,0,0,0,0,0,0,0,0,0,0,0,0,0,0,0,0,0,0,0,0,0
0,0,0,0,0,0,0,0,0,0,0,0,0,0,0,0,0,0,0,0,0,0,0,0
0,0,0,0,0,0,0,0,0,0,0,0,0,0,0,0,0,0,0,0,0,0,0,0
0,0,0,0,0,0,0,0,0,0,0,0,0,0,0,0,0,0,0,0,0,0,0,0
0,0,0,0,0,0,0,0,0,0,0,0,0,0,0,0,0,0,0,0,0,0,0,0
0,0,0,0,0,0,0,0,0,0,0,0,0,0,0,0,0,0,0,0,0,0,0,0
0,0,0,0,0,0,0,0,0,0,0,0,0,0,0,0,0,0,0,0,0,0,0,0
0,0,0,0,0,0,0,0,0,0,0,0,0,0,0,0,0,0,0,0,0,0,0,0
0,0,0,0,0,0,0,0,0,0,0,0,0,0,0,0,0,0,0,0,0,0,0,0
0,0,0,0,0,0,0,0,0,0,0,0,0,0,0,0,0,0,0,0,0,0,0,0
0,0,0,0,0,0,0,0,0,0,0,0,0,0,0,0,0,0,0,0,0,0,0,0
0,0,0,0,0,0,0,0,0,0,0,0,0,0,0,0,0,0,0,0,0,0,0,0
0,0,0,0,0,0,0,0,0,0,0,0,0,0,0,0,0,0,0,0,0,0,0,0
:endlayer
layer: 50
0,0,0,0,0,0,0,0,0,31,0,0,0,0,0,0,31,0,0,0,0,0,0,0
0,0,0,0,0,0,0,0,33,118,46,0,0,0,31,31,115,17,0,0,0,0,0,0
0,0,0,0,0,0,0,0,118,118,0,0,0,0,118,115,115,31,31,0,0,0,0,0
0,0,0,0,0,0,0,0,118,13,118,0,0,0,0,115,13,115,17,0,0,0,0,0
0,0,0,0,0,0,0,0,0,118,0,0,0,0,0,0,115,115,0,0,0,0,0,0
0,0,0,0,0,0,0,0,0,118,0,118,13,46,0,0,0,0,0,0,0,0,0,0
0,0,0,0,0,0,0,0,0,0,115,13,13,13,0,0,0,124,0,13,17,0,0,0
0,0,0,0,0,0,0,0,0,115,13,13,13,13,13,17,126,13,13,118,17,0,0,0
0,0,0,0,0,0,0,0,0,0,115,13,13,13,118,11,13,115,118,0,0,0,0,0
0,0,0,0,0,0,0,0,88,0,0,0,13,115,46,118,13,13,115,118,0,0,0,0
0,0,0,0,0,115,0,0,0,0,0,0,118,115,115,115,13,13,13,13,118,0,0,0
0,0,0,0,0,115,115,115,0,0,0,0,0,56,0,18,118,118,118,13,13,118,0,0
0,0,0,33,33,115,13,115,17,0,0,118,17,0,0,0,18,0,58,118,13,0,0,0
0,0,0,0,33,33,115,18,0,0,0,18,0,0,0,0,0,0,0,58,118,17,0,0
0,0,0,0,0,18,115,18,0,0,0,18,0,0,0,0,0,0,0,0,18,0,0,0
0,0,0,0,0,0,0,0,0,0,0,0,0,0,0,0,0,0,0,0,0,0,0,0
0,0,0,0,0,0,0,0,0,0,0,0,0,0,0,0,0,0,0,0,0,0,0,0
0,0,0,0,0,0,0,0,0,0,0,0,0,0,0,0,0,0,0,0,0,0,0,0
0,0,0,0,0,0,0,0,0,0,0,0,0,0,0,0,0,0,0,0,0,0,0,0
0,0,0,0,0,0,0,0,0,0,0,0,0,0,0,0,0,0,0,0,0,0,0,0
0,0,0,0,0,0,0,0,0,0,0,0,0,0,0,0,0,0,0,0,0,0,0,0
0,0,0,0,0,0,0,0,0,0,0,0,0,0,0,0,0,0,0,0,0,0,0,0
0,0,0,0,0,0,0,0,0,0,0,0,0,0,0,0,0,0,0,0,0,0,0,0
0,0,0,0,0,0,0,0,0,0,0,0,0,0,0,0,0,0,0,0,0,0,0,0
0,0,0,0,0,0,0,0,0,0,0,0,0,0,0,0,0,0,0,0,0,0,0,0
0,0,0,0,0,0,0,0,0,0,0,0,0,0,0,0,0,0,0,0,0,0,0,0
0,0,0,0,0,0,0,0,0,0,0,0,0,0,0,0,0,0,0,0,0,0,0,0
0,0,0,0,0,0,0,0,0,0,0,0,0,0,0,0,0,0,0,0,0,0,0,0
0,0,0,0,0,0,0,0,0,0,0,0,0,0,0,0,0,0,0,0,0,0,0,0
0,0,0,0,0,0,0,0,0,0,0,0,0,0,0,0,0,0,0,0,0,0,0,0
0,0,0,0,0,0,0,0,0,0,0,0,0,0,0,0,0,0,0,0,0,0,0,0
0,0,0,0,0,0,0,0,0,0,0,0,0,0,0,0,0,0,0,0,0,0,0,0
0,0,0,0,0,0,0,0,0,0,0,0,0,0,0,0,0,0,0,0,0,0,0,0
0,0,0,0,0,0,0,0,0,0,0,0,0,0,0,0,0,0,0,0,0,0,0,0
0,0,0,0,0,0,0,0,0,0,0,0,0,0,0,0,0,0,0,0,0,0,0,0
0,0,0,0,0,0,0,0,0,0,0,0,0,0,0,0,0,0,0,0,0,0,0,0
0,0,0,0,0,0,0,0,0,0,0,0,0,0,0,0,0,0,0,0,0,0,0,0
:endlayer
layer: 51
0,0,0,0,0,0,0,0,0,31,0,0,0,0,0,0,31,0,0,0,0,0,0,0
0,0,0,0,0,0,0,0,33,118,46,0,0,0,0,31,31,17,0,0,0,0,0,0
0,0,0,0,0,0,0,0,33,118,0,0,0,0,0,115,115,31,31,0,0,0,0,0
0,0,0,0,0,0,0,0,115,13,118,0,0,0,0,115,13,115,17,0,0,0,0,0
0,0,0,0,0,0,0,0,0,0,0,0,0,0,0,0,115,31,0,0,0,0,0,0
0,0,0,0,0,0,0,0,0,0,0,118,0,46,0,0,0,0,0,0,0,0,0,0
0,0,0,0,0,0,0,0,0,0,0,0,13,13,0,0,0,124,0,118,17,0,0,0
0,0,0,0,0,0,0,0,0,0,115,13,13,13,17,17,126,13,118,0,0,0,0,0
0,0,0,0,0,0,0,0,0,0,0,13,13,115,0,33,13,118,0,0,0,0,0,0
0,0,0,0,0,0,0,0,32,0,0,118,118,0,46,0,0,13,0,0,0,0,0,0
0,0,0,0,0,0,0,0,0,0,0,0,0,0,118,17,0,118,118,118,0,0,0,0
0,0,0,0,0,115,115,0,0,0,0,0,0,56,0,0,0,118,0,118,118,118,0,0
0,0,0,33,33,115,13,115,115,0,0,118,17,0,0,0,0,0,0,0,118,0,0,0
0,0,0,0,33,115,115,115,0,0,0,18,0,0,0,0,0,0,0,0,0,0,0,0
0,0,0,0,0,18,56,18,0,0,0,18,0,0,0,0,0,0,0,0,0,0,0,0
0,0,0,0,0,0,0,0,0,0,0,0,0,0,0,0,0,0,0,0,0,0,0,0
0,0,0,0,0,0,0,0,0,0,0,0,0,0,0,0,0,0,0,0,0,0,0,0
0,0,0,0,0,0,0,0,0,0,0,0,0,0,0,0,0,0,0,0,0,0,0,0
0,0,0,0,0,0,0,0,0,0,0,0,0,0,0,0,0,0,0,0,0,0,0,0
0,0,0,0,0,0,0,0,0,0,0,0,0,0,0,0,0,0,0,0,0,0,0,0
0,0,0,0,0,0,0,0,0,0,0,0,0,0,0,0,0,0,0,0,0,0,0,0
0,0,0,0,0,0,0,0,0,0,0,0,0,0,0,0,0,0,0,0,0,0,0,0
0,0,0,0,0,0,0,0,0,0,0,0,0,0,0,0,0,0,0,0,0,0,0,0
0,0,0,0,0,0,0,0,0,0,0,0,0,0,0,0,0,0,0,0,0,0,0,0
0,0,0,0,0,0,0,0,0,0,0,0,0,0,0,0,0,0,0,0,0,0,0,0
0,0,0,0,0,0,0,0,0,0,0,0,0,0,0,0,0,0,0,0,0,0,0,0
0,0,0,0,0,0,0,0,0,0,0,0,0,0,0,0,0,0,0,0,0,0,0,0
0,0,0,0,0,0,0,0,0,0,0,0,0,0,0,0,0,0,0,0,0,0,0,0
0,0,0,0,0,0,0,0,0,0,0,0,0,0,0,0,0,0,0,0,0,0,0,0
0,0,0,0,0,0,0,0,0,0,0,0,0,0,0,0,0,0,0,0,0,0,0,0
0,0,0,0,0,0,0,0,0,0,0,0,0,0,0,0,0,0,0,0,0,0,0,0
0,0,0,0,0,0,0,0,0,0,0,0,0,0,0,0,0,0,0,0,0,0,0,0
0,0,0,0,0,0,0,0,0,0,0,0,0,0,0,0,0,0,0,0,0,0,0,0
0,0,0,0,0,0,0,0,0,0,0,0,0,0,0,0,0,0,0,0,0,0,0,0
0,0,0,0,0,0,0,0,0,0,0,0,0,0,0,0,0,0,0,0,0,0,0,0
0,0,0,0,0,0,0,0,0,0,0,0,0,0,0,0,0,0,0,0,0,0,0,0
0,0,0,0,0,0,0,0,0,0,0,0,0,0,0,0,0,0,0,0,0,0,0,0
:endlayer
layer: 52
0,0,0,0,0,0,0,0,0,0,0,0,0,0,0,0,31,0,0,0,0,0,0,0
0,0,0,0,0,0,0,0,0,31,31,0,0,0,0,0,31,17,0,0,0,0,0,0
0,0,0,0,0,0,0,0,33,118,0,0,0,0,0,0,115,31,31,0,0,0,0,0
0,0,0,0,0,0,0,0,115,13,118,0,0,0,0,115,13,115,17,0,0,0,0,0
0,0,0,0,0,0,0,0,0,0,0,118,118,0,0,0,0,31,0,0,0,0,0,0
0,0,0,0,0,0,0,0,0,0,118,118,0,46,0,0,0,0,0,0,0,0,0,0
0,0,0,0,0,0,0,0,0,0,0,0,0,13,0,0,0,124,0,0,0,0,0,0
0,0,0,0,0,0,0,0,0,0,115,13,13,13,13,17,91,118,0,0,0,0,0,0
0,0,0,0,0,0,0,0,0,0,118,13,13,115,0,0,0,0,0,0,0,0,0,0
0,0,0,0,0,0,0,0,32,118,118,118,118,115,17,0,0,0,0,0,0,0,0,0
0,0,0,0,0,0,0,0,0,0,118,0,0,0,17,0,0,0,0,0,0,0,0,0
0,0,0,0,0,0,115,115,0,0,0,0,0,56,0,0,0,0,0,0,0,0,0,0
0,0,0,33,115,115,13,115,115,0,0,13,115,0,0,0,0,0,0,0,0,0,0,0
0,0,0,0,33,115,115,0,0,0,0,115,0,0,0,0,0,0,0,0,0,0,0,0
0,0,0,0,0,118,56,0,0,0,0,18,0,0,0,0,0,0,0,0,0,0,0,0
0,0,0,0,0,0,0,0,0,0,0,0,0,0,0,0,0,0,0,0,0,0,0,0
0,0,0,0,0,0,0,0,0,0,0,0,0,0,0,0,0,0,0,0,0,0,0,0
0,0,0,0,0,0,0,0,0,0,0,0,0,0,0,0,0,0,0,0,0,0,0,0
0,0,0,0,0,0,0,0,0,0,0,0,0,0,0,0,0,0,0,0,0,0,0,0
0,0,0,0,0,0,0,0,0,0,0,0,0,0,0,0,0,0,0,0,0,0,0,0
0,0,0,0,0,0,0,0,0,0,0,0,0,0,0,0,0,0,0,0,0,0,0,0
0,0,0,0,0,0,0,0,0,0,0,0,0,0,0,0,0,0,0,0,0,0,0,0
0,0,0,0,0,0,0,0,0,0,0,0,0,0,0,0,0,0,0,0,0,0,0,0
0,0,0,0,0,0,0,0,0,0,0,0,0,0,0,0,0,0,0,0,0,0,0,0
0,0,0,0,0,0,0,0,0,0,0,0,0,0,0,0,0,0,0,0,0,0,0,0
0,0,0,0,0,0,0,0,0,0,0,0,0,0,0,0,0,0,0,0,0,0,0,0
0,0,0,0,0,0,0,0,0,0,0,0,0,0,0,0,0,0,0,0,0,0,0,0
0,0,0,0,0,0,0,0,0,0,0,0,0,0,0,0,0,0,0,0,0,0,0,0
0,0,0,0,0,0,0,0,0,0,0,0,0,0,0,0,0,0,0,0,0,0,0,0
0,0,0,0,0,0,0,0,0,0,0,0,0,0,0,0,0,0,0,0,0,0,0,0
0,0,0,0,0,0,0,0,0,0,0,0,0,0,0,0,0,0,0,0,0,0,0,0
0,0,0,0,0,0,0,0,0,0,0,0,0,0,0,0,0,0,0,0,0,0,0,0
0,0,0,0,0,0,0,0,0,0,0,0,0,0,0,0,0,0,0,0,0,0,0,0
0,0,0,0,0,0,0,0,0,0,0,0,0,0,0,0,0,0,0,0,0,0,0,0
0,0,0,0,0,0,0,0,0,0,0,0,0,0,0,0,0,0,0,0,0,0,0,0
0,0,0,0,0,0,0,0,0,0,0,0,0,0,0,0,0,0,0,0,0,0,0,0
0,0,0,0,0,0,0,0,0,0,0,0,0,0,0,0,0,0,0,0,0,0,0,0
:endlayer
layer: 53
0,0,0,0,0,0,0,0,0,0,0,0,0,0,0,0,31,0,0,0,0,0,0,0
0,0,0,0,0,0,0,0,0,31,31,0,0,0,0,0,118,17,0,0,0,0,0,0
0,0,0,0,0,0,0,0,33,118,118,118,0,0,0,0,118,31,31,0,0,0,0,0
0,0,0,0,0,0,0,0,115,13,118,118,0,0,0,115,13,115,17,0,0,0,0,0
0,0,0,0,0,0,0,115,115,13,13,13,115,0,0,0,0,31,0,0,0,0,0,0
0,0,0,0,0,0,0,0,118,0,13,13,13,46,0,13,13,115,0,0,0,0,0,0
0,0,0,0,0,0,0,0,0,0,118,13,13,13,13,13,115,56,0,0,0,0,0,0
0,0,0,0,0,0,0,0,0,0,0,0,13,115,115,115,56,0,0,0,0,0,0,0
0,0,0,0,0,0,0,0,0,13,13,13,13,115,115,0,0,0,0,0,0,0,0,0
0,0,0,0,0,0,0,115,13,13,13,118,118,0,17,0,0,0,0,0,0,0,0,0
0,0,0,0,0,0,0,0,0,0,0,0,0,0,17,0,0,0,0,0,0,0,0,0
0,0,0,0,0,115,115,0,0,0,0,0,0,56,0,0,0,0,0,0,0,0,0,0
0,0,0,0,33,115,13,115,115,0,0,13,0,0,0,0,0,0,0,0,0,0,0,0
